
# Created by Ruins mod version 17.0 Ingame Parser
# authoring Player: ST753M

weight=3
embed_into_distance=256
acceptable_target_blocks=grass,dirt,coarse_dirt,podzol,stone,gravel,mycelium,clay,mud,sand,sandstone,red_sand,terracotta,dried_clay,ice,snow,water,stained_hardened_clay,hardened_clay,biomesoplenty:grass,biomesoplenty:dirt
unacceptable_target_blocks=end_stone,netherrack
dimensions=13,15,15
allowable_overhang=999
max_leveling=0
leveling_buffer=0
preserve_water=0
preserve_lava=0

rule1=0,100,minecraft:cobblestone_wall-0
rule2=0,100,minecraft:cobblestone-0,minecraft:monster_egg-1,minecraft:mossy_cobblestone-0
rule3=0,100,minecraft:stone_stairs-1
rule4=0,100,minecraft:stone_stairs-0
rule5=0,100,minecraft:stone_stairs-3
rule6=0,100,minecraft:stone_stairs-2
rule7=0,100,ChestGenHook:chests/simple_dungeon:5-5,air,air
rule8=0,100,minecraft:stone_slab-3
rule9=0,100,ChestGenHook:chests/simple_dungeon:5-3,air,air
rule10=0,100,ChestGenHook:chests/simple_dungeon:5-2,air,air,air
rule11=0,100,ChestGenHook:chests/simple_dungeon:5-4
rule12=0,100,minecraft:stone_stairs-5
rule13=0,100,minecraft:stone_stairs-7
rule14=0,100,minecraft:stone_stairs-6
rule15=0,100,MobSpawner:skeleton,MobSpawner:zombie,MobSpawner:spider,MobSpawner:silverfish,MobSpawner:skeleton,MobSpawner:zombie,MobSpawner:skeleton,MobSpawner:zombie
rule16=0,100,minecraft:stone_stairs-4
rule17=0,100,preserveBlock
rule18=0,100,minecraft:stone_slab-11

layer
1,2,2,2,2,2,2,2,2,2,2,2,2,2,1
2,2,2,2,2,2,2,2,2,2,2,2,2,2,2
2,2,2,2,2,2,2,2,2,2,2,2,2,2,2
2,2,2,2,2,2,2,3,2,2,2,2,2,2,2
2,2,2,2,2,2,2,4,2,2,2,2,2,2,2
2,2,2,2,2,2,2,2,2,2,2,2,2,2,2
2,2,2,2,2,2,2,2,2,2,2,2,2,2,2
2,2,2,6,5,2,2,2,2,2,6,5,2,2,2
2,2,2,2,2,2,2,2,2,2,2,2,2,2,2
2,2,2,2,2,2,2,2,2,2,2,2,2,2,2
2,2,2,2,2,2,2,3,2,2,2,2,2,2,2
2,2,2,2,2,2,2,4,2,2,2,2,2,2,2
2,2,2,2,2,2,2,2,2,2,2,2,2,2,2
2,2,2,2,2,2,2,2,2,2,2,2,2,2,2
1,2,2,2,2,2,2,2,2,2,2,2,2,2,1
endlayer

layer
2,2,1,2,2,1,2,2,2,1,2,2,1,2,2
2,2,2,2,2,2,2,2,2,2,2,2,2,2,2
1,2,0,0,0,0,0,0,0,0,0,0,0,2,1
2,2,0,4,4,4,0,0,0,4,4,6,0,2,2
2,2,0,5,2,6,0,0,0,5,2,6,0,2,2
1,2,0,3,3,3,0,0,0,3,3,3,0,2,1
2,2,0,0,0,0,4,4,4,0,0,0,0,2,2
2,2,0,0,0,0,5,2,6,0,0,0,0,2,2
2,2,0,0,0,0,3,3,3,0,0,0,0,2,2
1,2,0,5,4,6,0,0,0,5,4,6,0,2,1
2,2,0,5,2,6,0,0,0,5,2,6,0,2,2
2,2,0,5,3,3,0,0,0,3,3,3,0,2,2
1,2,0,0,0,0,0,0,0,0,0,0,0,2,1
2,2,2,2,2,2,2,2,2,2,2,2,2,2,2
2,2,1,2,2,1,2,2,2,1,2,2,1,2,2
endlayer

layer
1,2,1,2,2,1,2,2,2,1,2,2,1,2,1
2,2,2,3,2,2,6,7,5,2,2,3,2,2,2
1,2,0,0,0,0,0,0,0,0,0,0,0,2,1
2,6,0,8,8,8,0,0,0,8,8,8,0,5,2
2,2,0,8,2,8,0,0,0,8,2,8,0,2,2
1,2,0,8,8,8,0,0,0,8,8,8,0,2,1
2,3,0,0,0,0,0,0,0,0,0,0,0,3,2
2,10,0,0,0,0,0,2,0,0,0,0,0,9,2
2,4,0,0,0,0,0,0,0,0,0,0,0,4,2
1,2,0,8,8,8,0,0,0,8,8,8,0,2,1
2,2,0,8,2,8,0,0,0,8,2,8,0,2,2
2,6,0,8,8,8,0,0,0,8,8,8,0,5,2
1,2,0,0,0,0,0,0,0,0,0,0,0,2,1
2,2,2,4,2,2,6,11,5,2,2,4,2,2,2
1,2,1,2,2,1,2,2,2,1,2,2,1,2,1
endlayer

layer
2,2,1,2,2,1,2,2,2,1,2,2,1,2,2
2,2,2,0,2,2,0,0,0,2,2,0,2,2,2
1,2,0,0,0,0,0,0,0,0,0,0,0,2,1
2,0,0,0,0,0,0,0,0,0,0,0,0,0,2
2,2,0,0,2,0,0,0,0,0,2,0,0,2,2
1,2,0,0,0,0,0,0,0,0,0,0,0,2,1
2,0,0,0,0,0,0,0,0,0,0,0,0,0,2
2,0,0,0,0,0,0,1,0,0,0,0,0,0,2
2,0,0,0,0,0,0,0,0,0,0,0,0,0,2
1,2,0,0,0,0,0,0,0,0,0,0,0,2,1
2,2,0,0,2,0,0,0,0,0,2,0,0,2,2
2,0,0,0,0,0,0,0,0,0,0,0,0,0,2
1,2,0,0,0,0,0,0,0,0,0,0,0,2,1
2,2,2,0,2,2,0,0,0,2,2,0,2,2,2
2,2,1,2,2,1,2,2,2,1,2,2,1,2,2
endlayer

layer
1,2,1,2,2,1,2,2,2,1,2,2,1,2,1
2,2,2,12,2,2,14,0,13,2,2,12,2,2,2
1,2,0,0,0,0,0,0,0,0,0,0,0,2,1
2,14,0,0,0,0,0,0,0,0,0,0,0,13,2
2,2,0,0,1,0,0,0,0,0,1,0,0,2,2
1,2,0,0,0,0,0,0,0,0,0,0,0,2,1
2,12,0,0,0,0,0,0,0,0,0,0,0,12,2
2,0,0,0,0,0,0,15,0,0,0,0,0,0,2
2,16,0,0,0,0,0,0,0,0,0,0,0,16,2
1,2,0,0,0,0,0,0,0,0,0,0,0,2,1
2,2,0,0,1,0,0,0,0,0,1,0,0,2,2
2,14,0,0,0,0,0,0,0,0,0,0,0,13,2
1,2,0,0,0,0,0,0,0,0,0,0,0,2,1
2,2,2,16,2,2,14,0,13,2,2,16,2,2,2
1,2,1,2,2,1,2,2,2,1,2,2,1,2,1
endlayer

layer
2,2,2,2,2,2,4,2,4,2,2,2,2,2,2
2,2,2,2,2,2,2,2,2,2,2,2,2,2,2
2,2,0,0,0,0,0,0,0,0,0,0,0,2,2
2,2,0,0,0,0,0,0,0,0,0,0,0,2,2
2,2,0,0,1,0,0,0,0,0,1,0,0,2,2
2,2,0,0,0,0,0,0,0,0,0,0,0,2,2
5,2,0,0,0,0,0,0,0,0,0,0,0,2,6
2,2,0,0,0,0,0,1,0,0,0,0,0,2,2
5,2,0,0,0,0,0,0,0,0,0,0,0,2,6
2,2,0,0,0,0,0,0,0,0,0,0,0,2,2
2,2,0,0,1,0,0,0,0,0,1,0,0,2,2
2,2,0,0,0,0,0,0,0,0,0,0,0,2,2
2,2,0,0,0,0,0,0,0,0,0,0,0,2,2
2,2,2,2,2,2,2,2,2,2,2,2,2,2,2
2,2,2,2,2,2,3,2,3,2,2,2,2,2,2
endlayer

layer
17,4,17,17,4,17,17,4,17,17,4,17,17,4,17
5,2,2,2,2,2,4,2,4,2,2,2,2,2,6
17,2,12,12,12,18,0,12,0,18,12,12,13,2,17
17,2,14,0,0,0,0,0,0,0,0,0,13,2,17
5,2,14,0,2,0,0,0,0,0,2,0,13,2,6
17,2,18,0,0,0,0,0,0,0,0,0,18,2,17
17,5,0,0,0,0,0,0,0,0,0,0,0,6,17
5,2,14,0,0,0,0,2,0,0,0,0,13,2,6
17,5,0,0,0,0,0,0,0,0,0,0,0,6,17
17,2,18,0,0,0,0,0,0,0,0,0,18,2,17
5,2,14,0,2,0,0,0,0,0,2,0,13,2,6
17,2,14,0,0,0,0,0,0,0,0,0,13,2,17
17,2,14,16,16,18,0,16,0,18,16,16,16,2,17
5,2,2,2,2,2,3,2,3,2,2,2,2,2,6
17,3,17,17,3,17,17,3,17,17,3,17,17,3,17
endlayer

layer
17,17,17,17,17,17,17,17,17,17,17,17,17,17,17
17,2,17,17,4,17,17,4,17,17,4,17,17,2,17
17,17,2,2,2,2,4,2,4,2,2,2,2,17,17
17,17,2,12,12,18,0,12,0,18,12,13,2,17,17
17,5,2,14,2,0,0,0,0,0,2,13,2,6,17
17,17,2,18,0,0,0,0,0,0,0,18,2,17,17
17,17,5,0,0,0,0,0,0,0,0,0,6,17,17
17,5,2,14,0,0,0,2,0,0,0,13,2,6,17
17,17,5,0,0,0,0,0,0,0,0,0,6,17,17
17,17,2,18,0,0,0,0,0,0,0,18,2,17,17
17,5,2,14,2,0,0,0,0,0,2,13,2,6,17
17,17,2,16,16,18,0,16,0,18,16,16,2,17,17
17,17,2,2,2,2,3,2,3,2,2,2,2,17,17
17,2,17,17,3,17,17,3,17,17,3,17,17,2,17
17,17,17,17,17,17,17,17,17,17,17,17,17,17,17
endlayer

layer
17,17,17,17,17,17,17,17,17,17,17,17,17,17,17
17,2,17,17,17,17,17,17,17,17,17,17,17,2,17
17,17,17,17,4,17,17,4,17,17,4,17,17,17,17
17,17,17,2,2,2,4,2,4,2,2,2,17,17,17
17,17,5,2,2,14,0,12,0,13,2,2,6,17,17
17,17,17,2,12,0,0,0,0,0,12,2,17,17,17
17,17,17,5,0,0,0,0,0,0,0,6,17,17,17
17,17,5,2,14,0,0,2,0,0,13,2,6,17,17
17,17,17,5,0,0,0,0,0,0,0,6,17,17,17
17,17,17,2,16,0,0,0,0,0,16,2,17,17,17
17,17,5,2,2,14,0,16,0,13,2,2,6,17,17
17,17,17,2,2,2,3,2,3,2,2,2,17,17,17
17,17,17,17,3,17,17,3,17,17,3,17,17,17,17
17,2,17,17,17,17,17,17,17,17,17,17,17,2,17
17,17,17,17,17,17,17,17,17,17,17,17,17,17,17
endlayer

layer
17,17,17,17,17,17,17,17,17,17,17,17,17,17,17
17,17,17,17,17,17,17,17,17,17,17,17,17,17,17
17,17,17,17,17,17,17,17,17,17,17,17,17,17,17
17,17,17,17,4,17,17,4,17,17,4,17,17,17,17
17,17,17,5,2,2,4,2,4,2,2,6,17,17,17
17,17,17,17,2,18,0,12,0,18,2,17,17,17,17
17,17,17,17,5,0,0,0,0,0,6,17,17,17,17
17,17,17,5,2,14,0,2,0,13,2,6,17,17,17
17,17,17,17,5,0,0,0,0,0,6,17,17,17,17
17,17,17,17,2,18,0,16,0,18,2,17,17,17,17
17,17,17,5,2,2,3,2,3,2,2,6,17,17,17
17,17,17,17,3,17,17,3,17,17,3,17,17,17,17
17,17,17,17,17,17,17,17,17,17,17,17,17,17,17
17,17,17,17,17,17,17,17,17,17,17,17,17,17,17
17,17,17,17,17,17,17,17,17,17,17,17,17,17,17
endlayer

layer
17,17,17,17,17,17,17,17,17,17,17,17,17,17,17
17,17,17,17,17,17,17,17,17,17,17,17,17,17,17
17,17,17,17,17,17,17,17,17,17,17,17,17,17,17
17,17,17,17,17,17,17,17,17,17,17,17,17,17,17
17,17,17,17,2,17,17,4,17,17,2,17,17,17,17
17,17,17,17,17,2,4,2,4,2,17,17,17,17,17
17,17,17,17,17,5,0,12,0,6,17,17,17,17,17
17,17,17,17,5,2,14,2,13,2,6,17,17,17,17
17,17,17,17,17,5,0,16,0,6,17,17,17,17,17
17,17,17,17,17,2,3,2,3,2,17,17,17,17,17
17,17,17,17,2,17,17,3,17,17,2,17,17,17,17
17,17,17,17,17,17,17,17,17,17,17,17,17,17,17
17,17,17,17,17,17,17,17,17,17,17,17,17,17,17
17,17,17,17,17,17,17,17,17,17,17,17,17,17,17
17,17,17,17,17,17,17,17,17,17,17,17,17,17,17
endlayer

layer
17,17,17,17,17,17,17,17,17,17,17,17,17,17,17
17,17,17,17,17,17,17,17,17,17,17,17,17,17,17
17,17,17,17,17,17,17,17,17,17,17,17,17,17,17
17,17,17,17,17,17,17,17,17,17,17,17,17,17,17
17,17,17,17,2,17,17,17,17,17,2,17,17,17,17
17,17,17,17,17,17,17,4,17,17,17,17,17,17,17
17,17,17,17,17,17,2,2,2,17,17,17,17,17,17
17,17,17,17,17,5,2,2,2,6,17,17,17,17,17
17,17,17,17,17,17,2,2,2,17,17,17,17,17,17
17,17,17,17,17,17,17,3,17,17,17,17,17,17,17
17,17,17,17,2,17,17,17,17,17,2,17,17,17,17
17,17,17,17,17,17,17,17,17,17,17,17,17,17,17
17,17,17,17,17,17,17,17,17,17,17,17,17,17,17
17,17,17,17,17,17,17,17,17,17,17,17,17,17,17
17,17,17,17,17,17,17,17,17,17,17,17,17,17,17
endlayer

layer
17,17,17,17,17,17,17,17,17,17,17,17,17,17,17
17,17,17,17,17,17,17,17,17,17,17,17,17,17,17
17,17,17,17,17,17,17,17,17,17,17,17,17,17,17
17,17,17,17,17,17,17,17,17,17,17,17,17,17,17
17,17,17,17,17,17,17,17,17,17,17,17,17,17,17
17,17,17,17,17,17,17,17,17,17,17,17,17,17,17
17,17,17,17,17,17,0,4,17,17,17,17,17,17,17
17,17,17,17,17,17,5,2,6,17,17,17,17,17,17
17,17,17,17,17,17,17,3,17,17,17,17,17,17,17
17,17,17,17,17,17,17,17,17,17,17,17,17,17,17
17,17,17,17,17,17,17,17,17,17,17,17,17,17,17
17,17,17,17,17,17,17,17,17,17,17,17,17,17,17
17,17,17,17,17,17,17,17,17,17,17,17,17,17,17
17,17,17,17,17,17,17,17,17,17,17,17,17,17,17
17,17,17,17,17,17,17,17,17,17,17,17,17,17,17
endlayer

