
# Created by Ruins mod version 17.0 Ingame Parser
# authoring Player: ST753M

weight=1
embed_into_distance=256
acceptable_target_blocks=grass,dirt,coarse_dirt,podzol,stone,gravel,mycelium,clay,mud,sand,sandstone,red_sand,terracotta,dried_clay,ice,snow,water,stained_hardened_clay,hardened_clay,biomesoplenty:grass,biomesoplenty:dirt
unacceptable_target_blocks=
uniqueMinDistance=200
dimensions=16,25,25
allowable_overhang=999
max_leveling=0
leveling_buffer=0
preserve_water=0
preserve_lava=0

=0,100,air
rule1=0,100,preserveBlock
rule2=0,100,?minecraft:stone-0
rule3=0,100,minecraft:grass-0,minecraft:dirt-0
rule4=0,100,minecraft:dirt-0
rule5=0,100,quark:limestone-1
rule6=0,100,minecraft:farmland-7
rule7=0,100,minecraft:grass_path-0
rule8=0,100,minecraft:water-0
rule9=0,100,quark:world_stone_bricks-5
rule10=0,100,quark:stained_clay_tiles_brown_stairs-1
rule11=0,100,minecraft:dark_oak_fence-0
rule12=0,100,minecraft:crafting_table-0
rule13=0,100,quark:stained_clay_tiles_brown_stairs-0
rule14=0,100,quark:limestone_wall-0
rule15=0,100,minecraft:ladder-3
rule16=1,100,minecraft:potatoes-7
rule17=0,100,minecraft:spruce_door-3
rule18=0,100,ChestGenHook:chests/village_blacksmith:3-5,ChestGenHook:chests/abandoned_mineshaft:4-5
rule19=0,100,CommandBlock:RUINSTRIGGER /summon villager ~ ~1 ~:@-1
rule20=0,100,minecraft:spruce_door-1
rule21=0,100,minecraft:spruce_door-2
rule22=0,100,CommandBlock:RUINSTRIGGER /summon villager_golem ~ ~1 ~:@-1
rule23=0,100,minecraft:ladder-2
rule24=0,100,minecraft:spruce_door-0
rule25=0,100,minecraft:ladder-5
rule26=0,100,minecraft:bed-3
rule27=0,100,minecraft:bed-11
rule28=0,100,minecraft:stained_glass_pane-12
rule29=0,100,minecraft:carpet-12
rule30=1,100,minecraft:torch-5
rule31=0,100,minecraft:spruce_door-8
rule32=0,100,minecraft:spruce_door-9
rule33=2,100,minecraft:torch-4
rule34=2,100,minecraft:torch-2
rule35=2,100,minecraft:torch-3
rule36=2,100,minecraft:torch-1
rule37=0,100,quark:stone_limestone_stairs-0
rule38=0,100,quark:stone_limestone_stairs-3
rule39=0,100,quark:stone_limestone_stairs-1
rule40=0,100,quark:stone_limestone_stairs-2
rule41=0,100,IInventory;minecraft:brown_shulker_box;minecraft:rabbit_hide#5#0#1+minecraft:rotten_flesh#5#0#3+minecraft:planks#6#0#6+minecraft:iron_shovel#{"Quark:RuneColor":12,ench:[{lvl:3s,id:35s},{lvl:3s,id:34s}],RepairCost:3,"Quark:ItemNameDye":3,display:{Name:"The Brown Shovel"},"Quark:RuneAttached":1b}#0#13+minecraft:rabbit_hide#2#0#16+minecraft:planks#4#0#17+minecraft:planks#9#0#19+minecraft:rabbit_hide#4#0#21+minecraft:gold_ingot#3#0#24-1

layer
1,1,1,1,1,1,2,2,2,2,2,2,2,2,2,2,2,2,2,1,1,1,1,1,1
1,1,1,1,1,3,4,5,5,5,5,5,5,5,5,5,5,5,4,3,1,1,1,1,1
1,1,1,1,3,3,4,5,5,5,5,5,5,5,5,5,5,5,4,3,3,1,1,1,1
1,1,1,3,3,3,4,5,5,5,5,5,5,5,5,5,5,5,4,3,3,3,1,1,1
1,1,3,3,3,3,3,4,4,4,5,5,5,5,5,4,4,4,3,3,3,4,4,1,1
1,3,3,3,3,3,3,3,3,3,4,5,5,5,4,3,3,3,3,3,4,5,5,5,1
2,3,3,3,3,3,3,3,7,7,5,5,5,5,4,3,6,6,6,3,4,5,5,5,2
2,3,3,4,4,4,3,3,7,3,4,5,5,5,4,3,6,6,6,3,4,5,5,5,2
2,3,4,5,5,5,4,3,7,3,3,4,4,4,3,3,6,6,6,3,4,5,5,5,2
2,3,4,5,5,5,4,3,7,3,3,3,3,3,3,9,8,8,8,3,4,5,5,5,2
2,3,4,5,5,5,4,3,7,3,3,3,6,6,6,8,6,6,6,3,4,5,5,5,2
2,3,4,5,5,5,5,7,7,3,3,3,6,6,6,8,6,6,6,3,4,5,5,5,2
2,3,4,5,5,5,4,3,7,3,4,3,6,6,6,8,6,6,6,3,3,4,5,4,2
2,3,4,5,5,5,4,3,7,3,3,3,3,3,3,3,3,3,3,3,3,3,7,3,2
2,3,4,5,5,5,4,3,7,7,7,7,7,7,7,7,7,7,7,7,7,7,7,3,2
2,3,3,4,4,4,3,3,3,3,3,3,7,3,3,3,3,3,3,3,3,7,3,3,2
2,3,3,3,3,3,3,3,3,3,3,4,5,4,4,4,3,3,3,3,4,5,4,4,2
2,3,3,3,3,3,3,3,3,3,4,5,5,5,5,5,4,3,3,4,5,5,5,4,2
2,3,3,3,3,4,4,4,4,4,5,5,5,5,5,5,4,3,3,4,5,5,5,4,2
1,3,3,3,4,5,5,5,5,5,5,5,5,5,5,5,4,3,3,4,5,5,5,4,1
1,1,3,3,4,5,5,5,5,5,5,5,5,5,5,5,4,3,3,4,5,5,5,1,1
1,1,1,3,4,5,5,5,5,5,5,5,5,5,5,5,4,3,3,4,5,5,5,1,1
1,1,1,1,4,5,5,5,5,5,5,5,5,5,5,5,4,3,3,3,4,1,1,1,1
1,1,1,1,1,5,5,5,5,5,5,5,5,5,5,5,4,3,3,3,1,1,1,1,1
1,1,1,1,1,1,2,2,2,2,2,2,2,2,2,2,2,2,2,1,1,1,1,1,1
endlayer

layer
1,1,1,1,1,2,2,9,9,9,9,9,9,9,9,9,9,9,2,2,1,1,1,1,1
1,1,1,1,2,0,9,10,0,0,0,0,0,0,0,0,0,10,9,0,2,1,1,1,1
1,1,1,2,0,0,9,11,0,0,0,12,12,12,0,0,0,11,9,0,0,2,1,1,1
1,1,2,0,0,0,9,13,0,0,0,0,0,0,0,0,0,13,9,0,0,0,2,1,1
1,2,0,0,0,14,0,9,9,9,0,0,0,0,0,9,9,9,0,0,0,9,9,9,1
2,0,0,0,0,0,0,0,0,0,9,0,0,15,9,0,0,0,14,0,9,0,0,0,9
2,0,14,0,0,0,0,0,0,0,17,0,0,0,9,0,16,16,16,0,9,0,0,0,9
2,0,0,9,9,9,0,0,0,0,9,0,0,0,9,0,16,16,16,0,9,0,10,0,9
2,0,9,0,18,0,9,0,0,0,0,9,9,9,0,0,16,16,16,0,9,0,11,0,9
2,0,9,0,0,0,9,0,0,0,0,0,0,0,0,14,0,0,0,0,9,0,13,0,9
2,0,9,0,0,0,9,0,0,0,19,19,16,16,16,0,16,16,16,0,9,0,0,0,9
2,0,9,0,0,0,20,0,0,0,19,19,16,16,16,0,16,16,16,0,9,0,0,0,9
2,0,9,23,0,0,9,0,0,0,22,19,16,16,16,0,16,16,16,0,0,9,21,9,2
2,0,9,0,0,0,9,0,0,0,0,14,0,0,0,0,0,0,0,14,0,0,0,0,2
2,0,9,0,0,0,9,0,0,0,0,0,0,0,0,0,0,0,0,0,0,0,0,0,2
2,0,0,9,9,9,0,14,0,0,0,0,0,0,0,0,0,22,0,0,0,0,0,0,2
2,0,0,0,0,0,0,0,0,0,0,9,24,9,9,9,0,0,0,0,9,24,9,2,2
2,0,0,0,0,0,0,0,0,0,9,0,0,25,0,12,9,0,0,9,0,0,0,9,2
2,0,0,0,0,9,9,9,9,9,0,0,0,0,0,12,9,0,0,9,0,0,0,9,2
2,0,14,0,9,0,0,0,0,0,0,0,0,0,0,12,9,0,0,9,0,0,0,9,2
1,2,0,0,9,0,10,0,10,0,10,0,0,0,0,12,9,0,0,9,0,0,26,9,1
1,1,2,0,9,0,11,11,11,11,11,0,0,0,0,12,9,0,0,9,11,0,27,9,1
1,1,1,2,9,0,13,0,13,0,13,0,0,0,0,12,9,0,14,0,9,9,9,1,1
1,1,1,1,9,0,0,0,0,0,0,0,0,0,0,12,9,0,0,0,2,1,1,1,1
1,1,1,1,1,9,9,9,9,9,9,9,9,9,9,9,2,2,2,2,1,1,1,1,1
endlayer

layer
1,1,1,1,2,2,2,9,28,9,28,9,28,9,28,9,28,9,2,2,2,1,1,1,1
1,1,1,2,0,0,9,0,0,0,0,0,0,0,0,0,0,0,9,0,0,2,1,1,1
1,1,2,0,0,0,28,29,0,0,0,29,29,29,0,0,0,29,28,0,0,0,2,1,1
1,2,0,0,0,0,9,0,0,0,0,0,0,0,0,0,0,0,9,0,0,0,0,2,1
2,0,0,0,0,30,0,9,28,9,0,0,0,0,0,9,28,9,0,0,0,9,28,9,2
2,0,0,0,0,0,0,0,0,0,9,0,0,15,9,0,0,0,30,0,9,0,0,0,9
2,0,30,0,0,0,0,0,0,0,31,0,0,0,28,0,0,0,0,0,28,0,0,0,28
2,0,0,9,28,9,0,0,0,0,9,0,0,0,9,0,0,0,0,0,9,0,0,0,9
2,0,9,0,0,0,9,0,0,0,0,9,28,9,0,0,0,0,0,0,28,0,29,0,28
2,0,28,0,0,0,28,0,0,0,0,0,0,0,0,30,0,0,0,0,9,0,0,0,9
2,0,9,0,0,0,9,0,0,0,0,0,0,0,0,0,0,0,0,0,28,0,0,0,28
2,0,28,0,0,0,31,0,0,0,0,0,0,0,0,0,0,0,0,0,9,0,0,0,9
2,0,9,23,0,0,9,0,0,0,0,0,0,0,0,0,0,0,0,0,0,9,31,9,2
2,0,28,0,0,0,28,0,0,0,0,30,0,0,0,0,0,0,0,30,0,0,0,0,2
2,0,9,0,0,0,9,0,0,0,0,0,0,0,0,0,0,0,0,0,0,0,0,0,2
2,0,0,9,28,9,0,30,0,0,0,0,0,0,0,0,0,0,0,0,0,0,0,0,2
2,0,0,0,0,0,0,0,0,0,0,9,31,9,28,9,0,0,0,0,9,32,9,2,2
2,0,0,0,0,0,0,0,0,0,9,0,0,25,0,29,9,0,0,9,0,0,0,9,2
2,0,0,0,0,9,28,9,28,9,0,0,0,0,0,29,28,0,0,28,0,0,0,28,0
2,0,30,0,9,0,0,0,0,0,0,0,0,0,0,29,9,0,0,9,0,0,0,9,2
2,0,0,0,28,0,0,0,0,0,0,0,0,0,0,29,28,0,0,28,0,0,0,28,0
1,2,0,0,9,0,29,29,29,29,29,0,0,0,0,29,9,0,0,9,29,0,0,9,1
1,1,2,0,28,0,0,0,0,0,0,0,0,0,0,29,28,0,30,0,9,28,9,1,1
1,1,1,2,9,0,0,0,0,0,0,0,0,0,0,29,9,0,0,0,0,0,1,1,1
1,1,1,1,2,9,28,9,28,9,28,9,28,9,28,9,2,2,2,2,2,1,1,1,1
endlayer

layer
1,1,1,1,2,2,2,9,28,9,28,9,28,9,28,9,28,9,2,2,2,1,1,1,1
1,1,1,2,0,0,9,0,0,0,0,0,0,0,0,0,0,0,9,0,0,2,1,1,1
1,1,2,0,0,0,28,0,0,0,0,0,0,0,0,0,0,0,28,0,0,0,2,1,1
1,2,0,0,0,0,9,0,0,0,0,0,0,0,0,0,0,0,9,0,0,0,0,2,1
2,0,0,0,0,0,0,9,28,9,0,0,0,0,0,9,28,9,0,0,0,9,28,9,2
2,0,0,0,0,0,0,0,0,0,9,0,0,15,9,0,0,0,0,0,9,0,0,0,9
2,0,0,0,0,0,0,0,0,0,9,33,0,0,28,0,0,0,0,0,28,0,0,0,28
2,0,0,9,28,9,0,0,0,0,9,0,0,0,9,0,0,0,0,0,9,0,0,0,9
2,0,9,0,0,0,9,0,0,0,0,9,28,9,0,0,0,0,0,0,28,0,0,0,28
2,0,28,0,0,0,28,0,0,0,0,0,0,0,0,0,0,0,0,0,9,0,0,0,9
2,0,9,0,0,0,9,0,0,0,0,0,0,0,0,0,0,0,0,0,28,0,0,0,28
2,0,28,0,0,35,9,0,0,0,0,0,0,0,0,0,0,0,0,0,9,0,34,0,9
2,0,9,23,0,0,9,0,0,0,0,0,0,0,0,0,0,0,0,0,0,9,9,9,2
2,0,28,0,0,0,28,0,0,0,0,0,0,0,0,0,0,0,0,0,0,0,0,0,2
2,0,9,0,0,0,9,0,0,0,0,0,0,0,0,0,0,0,0,0,0,0,0,0,2
2,0,0,9,28,9,0,0,0,0,0,0,0,0,0,0,0,0,0,0,0,0,0,0,2
2,0,0,0,0,0,0,0,0,0,0,9,9,9,28,9,0,0,0,0,9,9,9,2,2
2,0,0,0,0,0,0,0,0,0,9,0,36,25,0,0,9,0,0,9,0,36,0,9,2
2,0,0,0,0,9,28,9,28,9,0,0,0,0,0,0,28,0,0,28,0,0,0,28,0
2,0,0,0,9,0,0,0,0,0,0,0,0,0,0,0,9,0,0,9,0,0,0,9,2
2,0,0,0,28,0,0,0,0,0,0,0,0,0,0,0,28,0,0,28,0,0,0,28,0
1,2,0,0,9,0,0,0,0,0,0,0,0,0,0,0,9,0,0,9,0,0,0,9,1
1,1,2,0,28,0,0,0,0,0,0,0,0,0,0,0,28,0,0,0,9,28,9,1,1
1,1,1,2,9,0,0,0,0,0,0,0,0,0,0,0,9,0,0,0,0,0,1,1,1
1,1,1,1,2,9,28,9,28,9,28,9,28,9,28,9,2,2,2,2,2,1,1,1,1
endlayer

layer
1,1,1,1,2,2,2,9,9,9,9,9,9,9,9,9,9,9,2,2,2,1,1,1,1
1,1,1,2,0,0,9,0,0,0,0,0,36,0,0,0,0,0,9,0,0,2,1,1,1
1,1,2,0,0,0,9,0,0,0,0,0,0,0,0,0,0,0,9,0,0,0,2,1,1
1,2,0,0,0,0,9,0,0,0,0,0,0,0,0,0,0,0,9,0,38,37,37,2,1
2,0,0,0,0,0,0,9,9,9,0,0,0,0,0,9,9,9,0,38,37,9,9,9,2
2,0,0,0,0,0,0,0,0,0,9,0,0,15,9,0,0,0,0,38,9,0,0,0,9
2,0,0,0,0,0,0,0,0,0,9,0,0,0,9,0,0,0,0,38,9,0,0,0,9
2,0,0,9,9,9,0,0,0,0,9,0,0,0,9,0,0,0,0,38,9,0,0,0,9
2,0,9,0,0,0,9,0,0,0,0,9,9,9,0,0,0,0,0,38,9,0,0,0,9
2,0,9,0,0,0,9,0,0,0,0,0,0,0,0,0,0,0,0,38,9,0,0,0,9
2,0,9,0,0,0,9,0,0,0,0,0,0,0,0,0,0,0,0,38,9,0,0,0,9
2,0,9,0,0,0,9,0,0,0,0,0,0,0,0,0,0,0,0,38,9,0,0,0,9
2,0,9,23,0,0,9,0,0,0,0,0,0,0,0,0,0,0,0,39,38,9,9,9,2
2,0,9,0,0,0,9,0,0,0,0,0,0,0,0,0,0,0,0,0,39,39,39,39,2
2,0,9,0,0,0,9,0,0,0,0,0,0,0,0,0,0,0,0,0,0,0,0,0,2
2,0,0,9,9,9,0,0,0,0,0,0,0,0,0,0,0,0,0,38,37,37,37,37,2
2,0,0,0,0,0,0,0,0,0,0,9,9,9,9,9,0,0,37,38,9,9,9,2,2
2,0,0,0,0,0,0,0,0,0,9,0,0,25,0,0,9,0,38,9,0,0,0,9,2
2,0,0,0,0,9,9,9,9,9,0,0,0,0,0,0,9,0,38,9,0,0,0,9,2
2,0,0,0,9,0,0,0,0,0,0,0,0,0,0,0,9,0,38,9,0,0,0,9,2
2,0,0,0,9,0,0,0,0,0,0,0,0,0,0,0,9,0,38,9,0,0,0,9,2
1,2,0,0,9,0,0,0,0,0,0,0,0,0,0,0,9,0,38,9,0,0,0,9,1
1,1,2,0,9,0,0,0,0,0,0,0,0,0,0,0,9,0,39,38,9,9,9,1,1
1,1,1,2,9,0,0,0,0,0,0,0,0,0,0,0,9,0,0,39,39,2,1,1,1
1,1,1,1,2,9,9,9,9,9,9,9,9,9,9,9,2,2,2,2,2,1,1,1,1
endlayer

layer
1,1,1,1,2,2,2,2,2,2,2,2,2,2,2,2,2,2,2,2,2,1,1,1,1
1,1,1,2,0,0,0,9,9,9,9,9,9,9,9,9,9,9,0,0,0,2,1,1,1
1,1,2,0,0,0,38,9,9,9,9,9,9,9,9,9,9,9,40,0,0,0,2,1,1
1,2,0,0,0,0,0,9,9,9,9,9,9,9,9,9,9,9,0,0,0,0,0,2,1
2,0,0,0,0,0,0,0,39,0,9,9,9,9,9,0,39,0,0,0,0,37,37,37,2
2,0,0,0,0,0,0,0,0,0,0,9,9,15,9,0,0,0,0,0,38,9,9,9,2
2,0,0,0,0,0,0,0,0,0,14,9,9,9,14,0,0,0,0,0,38,9,9,9,2
2,0,0,37,37,37,0,0,0,0,0,9,9,9,0,0,0,0,0,0,38,9,9,9,2
2,0,38,9,9,9,40,0,0,0,0,0,14,0,0,0,0,0,0,0,38,9,9,9,2
2,0,38,9,9,9,40,0,0,0,0,0,0,0,0,0,0,0,0,0,38,9,9,9,2
2,0,38,9,9,9,40,0,0,0,0,0,0,0,0,0,0,0,0,0,38,9,9,9,2
2,0,38,9,9,9,40,0,0,0,0,0,0,0,0,0,0,0,0,0,38,9,9,9,2
2,0,9,23,9,9,0,0,0,0,0,0,0,0,0,0,0,0,0,0,0,39,39,39,2
2,0,0,9,9,9,14,0,0,0,0,0,0,0,0,0,0,0,0,0,0,0,0,0,2
2,0,0,9,9,9,0,0,0,0,0,0,0,0,0,0,0,0,0,0,0,0,0,0,2
2,0,0,0,14,0,0,0,0,0,0,0,0,0,0,0,0,0,0,0,0,0,0,0,2
2,0,0,0,0,0,0,0,0,0,0,14,0,9,0,14,0,0,0,0,0,0,0,0,2
2,0,0,0,0,0,0,0,0,0,14,9,9,25,9,9,14,0,0,0,9,9,9,0,2
2,0,0,0,0,37,0,0,0,0,9,9,9,9,9,9,0,0,0,0,9,9,9,0,2
2,0,0,0,38,9,9,9,9,9,9,9,9,9,9,9,14,0,0,0,9,9,9,0,2
2,0,0,0,0,9,9,9,9,9,9,9,9,9,9,9,0,0,0,0,9,9,9,0,2
1,2,0,0,0,9,9,9,9,9,9,9,9,9,9,9,14,0,0,0,9,9,9,2,1
1,1,2,0,0,9,9,9,9,9,9,9,9,9,9,9,0,0,0,0,0,0,2,1,1
1,1,1,2,0,9,9,9,9,9,9,9,9,9,9,9,14,0,0,0,0,2,1,1,1
1,1,1,1,2,2,2,2,2,2,2,2,2,2,2,2,2,2,2,2,2,1,1,1,1
endlayer

layer
1,1,1,1,1,2,2,2,2,2,2,9,9,9,2,2,2,2,2,2,1,1,1,1,1
1,1,1,2,2,0,0,0,0,0,9,0,0,12,9,0,0,0,0,0,2,2,1,1,1
1,1,2,0,0,0,0,0,0,0,17,0,0,0,20,0,0,0,0,0,0,0,2,1,1
1,2,0,0,0,0,0,14,0,0,9,0,0,0,9,0,0,14,0,0,0,0,0,2,1
1,2,0,0,0,0,0,0,0,0,9,0,0,0,9,0,0,0,0,0,0,0,0,2,1
2,0,0,0,0,0,0,0,0,0,9,0,0,0,9,0,0,0,0,0,0,14,0,0,2
2,0,0,0,0,0,0,0,0,0,9,26,0,0,9,0,0,0,0,0,0,0,0,0,2
2,0,0,0,0,0,0,0,0,0,9,27,11,0,9,0,0,0,0,0,0,0,0,0,2
2,0,0,14,0,14,0,0,0,0,0,9,9,9,0,0,0,0,0,0,0,0,0,0,2
2,0,0,0,0,0,0,0,0,0,0,0,0,0,0,0,0,0,0,0,0,0,0,0,2
2,0,0,0,0,0,0,0,0,0,0,0,0,0,0,0,0,0,0,0,0,0,0,0,2
2,0,0,9,24,9,0,0,0,0,0,0,0,0,0,0,0,0,0,0,0,14,0,0,2
2,0,9,0,0,0,9,0,0,0,0,0,0,0,0,0,0,0,0,0,0,0,0,0,2
2,0,9,0,0,0,9,0,0,0,0,0,0,0,0,0,0,0,0,0,0,0,0,0,2
2,0,9,0,0,0,9,0,0,0,0,0,0,0,0,0,0,0,0,0,0,0,0,0,2
2,0,0,9,9,9,0,0,0,0,0,0,0,0,0,0,0,0,0,0,0,0,0,0,2
2,0,0,0,0,0,0,0,0,0,0,9,9,9,9,9,0,0,0,0,0,0,0,0,2
2,0,0,0,0,0,0,0,0,0,9,41,0,0,0,0,9,0,0,0,14,0,14,0,2
2,0,0,0,0,0,0,0,0,0,9,0,0,0,0,0,9,0,0,0,0,0,0,0,2
2,0,0,0,0,14,0,0,0,0,9,0,0,0,0,0,9,0,0,0,0,0,0,0,2
1,2,0,0,0,0,0,0,0,0,17,0,0,0,0,0,9,0,0,0,0,0,0,2,1
1,2,0,0,0,0,0,0,0,0,9,0,0,0,0,0,9,0,0,0,14,0,0,2,1
1,1,2,0,0,0,0,0,0,0,9,0,0,26,26,0,9,0,0,0,0,0,2,1,1
1,1,1,2,2,0,0,0,0,0,9,0,12,27,27,0,9,0,0,0,2,2,1,1,1
1,1,1,1,1,2,2,2,2,2,2,9,9,9,9,9,2,2,2,2,1,1,1,1,1
endlayer

layer
1,1,1,1,1,1,2,2,2,2,2,9,28,9,2,2,2,2,2,1,1,1,1,1,1
1,1,1,1,2,2,0,0,0,0,9,0,0,0,9,0,0,0,0,2,2,1,1,1,1
1,1,1,2,0,0,0,0,0,0,32,0,0,0,31,0,0,0,0,0,0,2,1,1,1
1,1,2,0,0,0,0,30,0,0,9,0,0,0,9,0,0,30,0,0,0,0,2,1,1
1,2,0,0,0,0,0,0,0,0,28,0,0,0,28,0,0,0,0,0,0,0,0,2,1
1,2,0,0,0,0,0,0,0,0,9,0,0,0,9,0,0,0,0,0,0,30,0,2,1
2,0,0,0,0,0,0,0,0,0,28,0,0,0,28,0,0,0,0,0,0,0,0,0,2
2,0,0,0,0,0,0,0,0,0,9,0,29,0,9,0,0,0,0,0,0,0,0,0,2
2,0,0,30,0,30,0,0,0,0,0,9,28,9,0,0,0,0,0,0,0,0,0,0,2
2,0,0,0,0,0,0,0,0,0,0,0,0,0,0,0,0,0,0,0,0,0,0,0,2
2,0,0,0,0,0,0,0,0,0,0,0,0,0,0,0,0,0,0,0,0,0,0,0,2
2,0,0,9,31,9,0,0,0,0,0,0,0,0,0,0,0,0,0,0,0,30,0,0,2
2,0,9,0,0,0,9,0,0,0,0,0,0,0,0,0,0,0,0,0,0,0,0,0,2
2,0,28,0,0,0,28,0,0,0,0,0,0,0,0,0,0,0,0,0,0,0,0,0,2
2,0,9,0,0,0,9,0,0,0,0,0,0,0,0,0,0,0,0,0,0,0,0,0,2
2,0,0,9,28,9,0,0,0,0,0,0,0,0,0,0,0,0,0,0,0,0,0,0,2
2,0,0,0,0,0,0,0,0,0,0,9,28,9,28,9,0,0,0,0,0,0,0,0,2
2,0,0,0,0,0,0,0,0,0,9,0,0,0,0,0,9,0,0,0,30,0,30,0,2
2,0,0,0,0,0,0,0,0,0,28,0,0,0,0,0,28,0,0,0,0,0,0,0,2
1,2,0,0,0,30,0,0,0,0,9,0,0,0,0,0,9,0,0,0,0,0,0,2,1
1,2,0,0,0,0,0,0,0,0,32,0,0,0,0,0,28,0,0,0,0,0,0,2,1
1,1,2,0,0,0,0,0,0,0,9,0,0,0,0,0,9,0,0,0,30,0,2,1,1
1,1,1,2,0,0,0,0,0,0,28,0,0,0,0,0,28,0,0,0,0,2,1,1,1
1,1,1,1,2,2,0,0,0,0,9,0,0,0,0,0,9,0,0,2,2,1,1,1,1
1,1,1,1,1,1,2,2,2,2,2,9,28,9,28,9,2,2,2,1,1,1,1,1,1
endlayer

layer
1,1,1,1,1,1,1,2,2,2,2,9,28,9,2,2,2,2,1,1,1,1,1,1,1
1,1,1,1,1,2,2,0,0,0,9,0,0,0,9,0,0,0,2,2,1,1,1,1,1
1,1,1,1,2,0,0,0,0,0,9,0,0,0,9,0,0,0,0,0,2,1,1,1,1
1,1,1,2,0,0,0,0,0,0,9,0,0,0,9,0,0,0,0,0,0,2,1,1,1
1,1,2,0,0,0,0,0,0,0,28,0,0,0,28,0,0,0,0,0,0,0,2,1,1
1,2,0,0,0,0,0,0,0,0,9,0,0,0,9,0,0,0,0,0,0,0,0,2,1
1,2,0,0,0,0,0,0,0,0,28,0,0,0,28,0,0,0,0,0,0,0,0,2,1
2,0,0,0,0,0,0,0,0,0,9,0,0,0,9,0,0,0,0,0,0,0,0,0,2
2,0,0,0,0,0,0,0,0,0,0,9,28,9,0,0,0,0,0,0,0,0,0,0,2
2,0,0,0,0,0,0,0,0,0,0,0,0,0,0,0,0,0,0,0,0,0,0,0,2
2,0,0,0,0,0,0,0,0,0,0,0,0,0,0,0,0,0,0,0,0,0,0,0,2
2,0,0,9,9,9,0,0,0,0,0,0,0,0,0,0,0,0,0,0,0,0,0,0,2
2,0,9,0,0,0,9,0,0,0,0,0,0,0,0,0,0,0,0,0,0,0,0,0,2
2,0,28,0,0,0,28,0,0,0,0,0,0,0,0,0,0,0,0,0,0,0,0,0,2
2,0,9,0,0,0,9,0,0,0,0,0,0,0,0,0,0,0,0,0,0,0,0,0,2
2,0,0,9,28,9,0,0,0,0,0,0,0,0,0,0,0,0,0,0,0,0,0,0,2
2,0,0,0,0,0,0,0,0,0,0,9,28,9,28,9,0,0,0,0,0,0,0,0,2
2,0,0,0,0,0,0,0,0,0,9,0,0,0,0,0,9,0,0,0,0,0,0,0,2
1,2,0,0,0,0,0,0,0,0,28,0,0,0,0,0,28,0,0,0,0,0,0,2,1
1,2,0,0,0,0,0,0,0,0,9,0,0,0,0,0,9,0,0,0,0,0,0,2,1
1,1,2,0,0,0,0,0,0,0,9,0,0,0,0,0,28,0,0,0,0,0,2,1,1
1,1,1,2,0,0,0,0,0,0,9,0,0,0,0,0,9,0,0,0,0,2,1,1,1
1,1,1,1,2,0,0,0,0,0,28,0,0,0,0,0,28,0,0,0,2,1,1,1,1
1,1,1,1,1,2,2,0,0,0,9,0,0,0,0,0,9,0,2,2,1,1,1,1,1
1,1,1,1,1,1,1,2,2,2,2,9,28,9,28,9,2,2,1,1,1,1,1,1,1
endlayer

layer
1,1,1,1,1,1,1,1,1,2,2,9,9,9,2,2,1,1,1,1,1,1,1,1,1
1,1,1,1,1,1,2,2,2,38,9,0,0,0,9,40,2,2,2,1,1,1,1,1,1
1,1,1,1,1,2,0,0,0,38,9,0,0,0,9,40,0,0,0,2,1,1,1,1,1
1,1,1,1,2,0,0,0,0,38,9,0,0,0,9,40,0,0,0,0,2,1,1,1,1
1,1,1,2,0,0,0,0,0,38,9,0,0,0,9,40,0,0,0,0,0,2,1,1,1
1,1,2,0,0,0,0,0,0,38,9,0,0,0,9,40,0,0,0,0,0,0,2,1,1
1,2,0,0,0,0,0,0,0,38,9,0,0,0,9,40,0,0,0,0,0,0,0,2,1
1,2,0,0,0,0,0,0,0,38,9,0,0,0,9,40,0,0,0,0,0,0,0,2,1
1,2,0,0,0,0,0,0,0,39,38,9,9,9,39,40,0,0,0,0,0,0,0,2,1
2,0,0,0,0,0,0,0,0,0,39,39,39,39,40,0,0,0,0,0,0,0,0,0,2
2,0,0,0,0,0,0,0,0,0,0,0,0,0,0,0,0,0,0,0,0,0,0,0,2
2,0,0,9,9,9,0,0,0,0,0,0,0,0,0,0,0,0,0,0,0,0,0,0,2
2,0,9,0,0,0,9,0,0,0,0,0,0,0,0,0,0,0,0,0,0,0,0,0,2
2,0,9,0,0,0,9,0,0,0,0,0,0,0,0,0,0,0,0,0,0,0,0,0,2
2,0,9,0,0,0,9,0,0,0,0,0,0,0,0,0,0,0,0,0,0,0,0,0,2
2,0,0,9,9,9,0,0,0,0,0,0,0,0,0,0,0,0,0,0,0,0,0,0,2
1,2,0,0,0,0,0,0,0,0,0,9,9,9,9,9,0,0,0,0,0,0,0,2,1
1,2,0,0,0,0,0,0,0,0,9,0,0,0,0,0,9,0,0,0,0,0,0,2,1
1,2,0,0,0,0,0,0,0,0,9,0,0,0,0,0,9,0,0,0,0,0,0,2,1
1,1,2,0,0,0,0,0,0,0,9,0,0,0,0,0,9,0,0,0,0,0,2,1,1
1,1,1,2,0,0,0,0,0,0,9,0,0,0,0,0,9,0,0,0,0,2,1,1,1
1,1,1,1,2,0,0,0,0,0,9,0,0,0,0,0,9,0,0,0,2,1,1,1,1
1,1,1,1,1,2,0,0,0,0,9,0,0,0,0,0,9,0,0,2,1,1,1,1,1
1,1,1,1,1,1,2,2,2,0,9,0,0,0,0,0,9,0,2,1,1,1,1,1,1
1,1,1,1,1,1,1,1,1,2,2,9,9,9,9,9,1,1,1,1,1,1,1,1,1
endlayer

layer
1,1,1,1,1,1,1,1,1,1,1,1,1,1,1,1,1,1,1,1,1,1,1,1,1
1,1,1,1,1,1,1,1,2,2,2,9,9,9,2,2,2,1,1,1,1,1,1,1,1
1,1,1,1,1,1,2,2,0,0,38,9,9,9,40,0,0,2,2,1,1,1,1,1,1
1,1,1,1,1,2,0,0,0,0,38,9,9,9,40,0,0,0,0,2,1,1,1,1,1
1,1,1,1,2,0,0,0,0,0,38,9,9,9,40,0,0,0,0,0,2,1,1,1,1
1,1,1,2,0,0,0,0,0,0,38,9,9,9,40,0,0,0,0,0,0,2,1,1,1
1,1,2,0,0,0,0,0,0,0,38,9,9,9,40,0,0,0,0,0,0,0,2,1,1
1,1,2,0,0,0,0,0,0,0,38,9,9,9,40,0,0,0,0,0,0,0,2,1,1
1,2,0,0,0,0,0,0,0,0,0,39,39,39,0,0,0,0,0,0,0,0,0,2,1
1,2,0,0,0,0,0,0,0,0,0,0,0,0,0,0,0,0,0,0,0,0,0,2,1
1,2,0,0,0,0,0,0,0,0,0,0,0,0,0,0,0,0,0,0,0,0,0,2,1
1,2,0,37,37,37,0,0,0,0,0,0,0,0,0,0,0,0,0,0,0,0,0,2,1
1,2,0,9,9,9,0,0,0,0,0,0,0,0,0,0,0,0,0,0,0,0,0,2,1
1,2,0,9,9,9,40,0,0,0,0,0,0,0,0,0,0,0,0,0,0,0,0,2,1
1,2,0,9,9,9,0,0,0,0,0,0,0,0,0,0,0,0,0,0,0,0,0,2,1
1,2,0,39,39,39,0,0,0,0,0,0,0,0,0,0,0,0,0,0,0,0,0,2,1
1,2,0,0,0,0,0,0,0,0,0,37,0,0,0,37,0,0,0,0,0,0,0,2,1
1,1,2,0,0,0,0,0,0,0,38,9,9,9,9,9,40,0,0,0,0,0,2,1,1
1,1,2,0,0,0,0,0,0,0,0,9,9,9,9,9,0,0,0,0,0,0,2,1,1
1,1,1,2,0,0,0,0,0,0,0,9,9,9,9,9,0,0,0,0,0,2,1,1,1
1,1,1,1,2,0,0,0,0,0,0,9,9,9,9,9,0,0,0,0,2,1,1,1,1
1,1,1,1,1,2,0,0,0,0,0,9,9,9,9,9,0,0,0,2,1,1,1,1,1
1,1,1,1,1,1,2,2,0,0,0,9,9,9,9,9,0,2,2,1,1,1,1,1,1
1,1,1,1,1,1,1,1,2,2,38,9,9,9,9,9,2,1,1,1,1,1,1,1,1
1,1,1,1,1,1,1,1,1,1,1,1,1,1,1,1,1,1,1,1,1,1,1,1,1
endlayer

layer
1,1,1,1,1,1,1,1,1,1,1,1,1,1,1,1,1,1,1,1,1,1,1,1,1
1,1,1,1,1,1,1,1,1,1,1,1,1,1,1,1,1,1,1,1,1,1,1,1,1
1,1,1,1,1,1,1,1,2,2,2,2,2,2,2,2,2,1,1,1,1,1,1,1,1
1,1,1,1,1,1,2,2,2,0,0,0,0,0,0,0,2,2,2,1,1,1,1,1,1
1,1,1,1,1,2,2,0,0,0,0,0,0,0,0,0,0,0,2,2,1,1,1,1,1
1,1,1,1,2,2,0,0,0,0,0,0,0,0,0,0,0,0,0,2,2,1,1,1,1
1,1,1,2,2,0,0,0,0,0,0,0,0,0,0,0,0,0,0,0,2,2,1,1,1
1,1,1,2,0,0,0,0,0,0,0,14,0,14,0,0,0,0,0,0,0,2,1,1,1
1,1,2,2,0,0,0,0,0,0,0,0,0,0,0,0,0,0,0,0,0,2,2,1,1
1,1,2,0,0,0,0,0,0,0,0,0,0,0,0,0,0,0,0,0,0,0,2,1,1
1,1,2,0,0,0,0,0,0,0,0,0,0,0,0,0,0,0,0,0,0,0,2,1,1
1,1,2,0,0,0,0,0,0,0,0,0,0,0,0,0,0,0,0,0,0,0,2,1,1
1,1,2,0,0,14,0,0,0,0,0,0,0,0,0,0,0,0,0,0,0,0,2,1,1
1,1,2,0,0,0,0,0,0,0,0,0,0,0,0,0,0,0,0,0,0,0,2,1,1
1,1,2,0,0,14,0,0,0,0,0,0,0,0,0,0,0,0,0,0,0,0,2,1,1
1,1,2,0,0,0,0,0,0,0,0,0,0,0,0,0,0,0,0,0,0,0,2,1,1
1,1,2,2,0,0,0,0,0,0,0,0,0,0,0,0,0,0,0,0,0,2,2,1,1
1,1,1,2,0,0,0,0,0,0,0,14,0,0,0,14,0,0,0,0,0,2,1,1,1
1,1,1,2,2,0,0,0,0,0,0,0,0,0,0,0,0,0,0,0,2,2,1,1,1
1,1,1,1,2,2,0,0,0,0,0,0,0,0,0,0,0,0,0,2,2,1,1,1,1
1,1,1,1,1,2,2,0,0,0,0,0,0,0,0,0,0,0,2,2,1,1,1,1,1
1,1,1,1,1,1,2,2,2,0,0,0,0,0,0,0,2,2,2,1,1,1,1,1,1
1,1,1,1,1,1,1,1,2,2,2,2,2,2,2,2,2,1,1,1,1,1,1,1,1
1,1,1,1,1,1,1,1,1,1,1,1,1,1,1,1,1,1,1,1,1,1,1,1,1
1,1,1,1,1,1,1,1,1,1,1,1,1,1,1,1,1,1,1,1,1,1,1,1,1
endlayer

layer
1,1,1,1,1,1,1,1,1,1,1,1,1,1,1,1,1,1,1,1,1,1,1,1,1
1,1,1,1,1,1,1,1,1,1,1,1,1,1,1,1,1,1,1,1,1,1,1,1,1
1,1,1,1,1,1,1,1,1,1,1,1,1,1,1,1,1,1,1,1,1,1,1,1,1
1,1,1,1,1,1,1,1,1,2,2,2,2,2,2,2,1,1,1,1,1,1,1,1,1
1,1,1,1,1,1,1,2,2,2,0,0,0,0,0,2,2,2,1,1,1,1,1,1,1
1,1,1,1,1,1,2,2,0,0,0,0,0,0,0,0,0,2,2,1,1,1,1,1,1
1,1,1,1,1,2,2,0,0,0,0,0,0,0,0,0,0,0,2,2,1,1,1,1,1
1,1,1,1,2,2,0,0,0,0,0,30,0,30,0,0,0,0,0,2,2,1,1,1,1
1,1,1,1,2,0,0,0,0,0,0,0,0,0,0,0,0,0,0,0,2,1,1,1,1
1,1,1,2,2,0,0,0,0,0,0,0,0,0,0,0,0,0,0,0,2,2,1,1,1
1,1,1,2,0,0,0,0,0,0,0,0,0,0,0,0,0,0,0,0,0,2,1,1,1
1,1,1,2,0,0,0,0,0,0,0,0,0,0,0,0,0,0,0,0,0,2,1,1,1
1,1,1,2,0,30,0,0,0,0,0,0,0,0,0,0,0,0,0,0,0,2,1,1,1
1,1,1,2,0,0,0,0,0,0,0,0,0,0,0,0,0,0,0,0,0,2,1,1,1
1,1,1,2,0,30,0,0,0,0,0,0,0,0,0,0,0,0,0,0,0,2,1,1,1
1,1,1,2,2,0,0,0,0,0,0,0,0,0,0,0,0,0,0,0,2,2,1,1,1
1,1,1,1,2,0,0,0,0,0,0,0,0,0,0,0,0,0,0,0,2,1,1,1,1
1,1,1,1,2,2,0,0,0,0,0,30,0,0,0,30,0,0,0,2,2,1,1,1,1
1,1,1,1,1,2,2,0,0,0,0,0,0,0,0,0,0,0,2,2,1,1,1,1,1
1,1,1,1,1,1,2,2,0,0,0,0,0,0,0,0,0,2,2,1,1,1,1,1,1
1,1,1,1,1,1,1,2,2,2,0,0,0,0,0,2,2,2,1,1,1,1,1,1,1
1,1,1,1,1,1,1,1,1,2,2,2,2,2,2,2,1,1,1,1,1,1,1,1,1
1,1,1,1,1,1,1,1,1,1,1,1,1,1,1,1,1,1,1,1,1,1,1,1,1
1,1,1,1,1,1,1,1,1,1,1,1,1,1,1,1,1,1,1,1,1,1,1,1,1
1,1,1,1,1,1,1,1,1,1,1,1,1,1,1,1,1,1,1,1,1,1,1,1,1
endlayer

layer
1,1,1,1,1,1,1,1,1,1,1,1,1,1,1,1,1,1,1,1,1,1,1,1,1
1,1,1,1,1,1,1,1,1,1,1,1,1,1,1,1,1,1,1,1,1,1,1,1,1
1,1,1,1,1,1,1,1,1,1,1,1,1,1,1,1,1,1,1,1,1,1,1,1,1
1,1,1,1,1,1,1,1,1,1,1,1,1,1,1,1,1,1,1,1,1,1,1,1,1
1,1,1,1,1,1,1,1,1,1,2,2,2,2,2,1,1,1,1,1,1,1,1,1,1
1,1,1,1,1,1,1,1,2,2,2,2,2,2,2,2,2,1,1,1,1,1,1,1,1
1,1,1,1,1,1,1,2,2,2,0,0,0,0,0,2,2,2,1,1,1,1,1,1,1
1,1,1,1,1,1,2,2,0,0,0,0,0,0,0,0,0,2,2,1,1,1,1,1,1
1,1,1,1,1,2,2,0,0,0,0,0,0,0,0,0,0,0,2,2,1,1,1,1,1
1,1,1,1,1,2,2,0,0,0,0,0,0,0,0,0,0,0,2,2,1,1,1,1,1
1,1,1,1,2,2,0,0,0,0,0,0,0,0,0,0,0,0,0,2,2,1,1,1,1
1,1,1,1,2,2,0,0,0,0,0,0,0,0,0,0,0,0,0,2,2,1,1,1,1
1,1,1,1,2,2,0,0,0,0,0,0,0,0,0,0,0,0,0,2,2,1,1,1,1
1,1,1,1,2,2,0,0,0,0,0,0,0,0,0,0,0,0,0,2,2,1,1,1,1
1,1,1,1,2,2,0,0,0,0,0,0,0,0,0,0,0,0,0,2,2,1,1,1,1
1,1,1,1,1,2,2,0,0,0,0,0,0,0,0,0,0,0,2,2,1,1,1,1,1
1,1,1,1,1,2,2,0,0,0,0,0,0,0,0,0,0,0,2,2,1,1,1,1,1
1,1,1,1,1,1,2,2,0,0,0,0,0,0,0,0,0,2,2,1,1,1,1,1,1
1,1,1,1,1,1,1,2,2,2,0,0,0,0,0,2,2,2,1,1,1,1,1,1,1
1,1,1,1,1,1,1,1,2,2,2,2,2,2,2,2,2,1,1,1,1,1,1,1,1
1,1,1,1,1,1,1,1,1,1,2,2,2,2,2,1,1,1,1,1,1,1,1,1,1
1,1,1,1,1,1,1,1,1,1,1,1,1,1,1,1,1,1,1,1,1,1,1,1,1
1,1,1,1,1,1,1,1,1,1,1,1,1,1,1,1,1,1,1,1,1,1,1,1,1
1,1,1,1,1,1,1,1,1,1,1,1,1,1,1,1,1,1,1,1,1,1,1,1,1
1,1,1,1,1,1,1,1,1,1,1,1,1,1,1,1,1,1,1,1,1,1,1,1,1
endlayer

layer
1,1,1,1,1,1,1,1,1,1,1,1,1,1,1,1,1,1,1,1,1,1,1,1,1
1,1,1,1,1,1,1,1,1,1,1,1,1,1,1,1,1,1,1,1,1,1,1,1,1
1,1,1,1,1,1,1,1,1,1,1,1,1,1,1,1,1,1,1,1,1,1,1,1,1
1,1,1,1,1,1,1,1,1,1,1,1,1,1,1,1,1,1,1,1,1,1,1,1,1
1,1,1,1,1,1,1,1,1,1,1,1,1,1,1,1,1,1,1,1,1,1,1,1,1
1,1,1,1,1,1,1,1,1,1,1,1,1,1,1,1,1,1,1,1,1,1,1,1,1
1,1,1,1,1,1,1,1,1,1,2,2,2,2,2,1,1,1,1,1,1,1,1,1,1
1,1,1,1,1,1,1,1,2,2,2,2,2,2,2,2,2,1,1,1,1,1,1,1,1
1,1,1,1,1,1,1,2,2,2,2,2,2,2,2,2,2,2,1,1,1,1,1,1,1
1,1,1,1,1,1,1,2,2,2,0,0,0,0,0,2,2,2,1,1,1,1,1,1,1
1,1,1,1,1,1,2,2,2,0,0,0,0,0,0,0,2,2,2,1,1,1,1,1,1
1,1,1,1,1,1,2,2,2,0,0,0,0,0,0,0,2,2,2,1,1,1,1,1,1
1,1,1,1,1,1,2,2,2,0,0,0,0,0,0,0,2,2,2,1,1,1,1,1,1
1,1,1,1,1,1,2,2,2,0,0,0,0,0,0,0,2,2,2,1,1,1,1,1,1
1,1,1,1,1,1,2,2,2,0,0,0,0,0,0,0,2,2,2,1,1,1,1,1,1
1,1,1,1,1,1,1,2,2,2,0,0,0,0,0,2,2,2,1,1,1,1,1,1,1
1,1,1,1,1,1,1,2,2,2,2,2,2,2,2,2,2,2,1,1,1,1,1,1,1
1,1,1,1,1,1,1,1,2,2,2,2,2,2,2,2,2,1,1,1,1,1,1,1,1
1,1,1,1,1,1,1,1,1,1,2,2,2,2,2,1,1,1,1,1,1,1,1,1,1
1,1,1,1,1,1,1,1,1,1,1,1,1,1,1,1,1,1,1,1,1,1,1,1,1
1,1,1,1,1,1,1,1,1,1,1,1,1,1,1,1,1,1,1,1,1,1,1,1,1
1,1,1,1,1,1,1,1,1,1,1,1,1,1,1,1,1,1,1,1,1,1,1,1,1
1,1,1,1,1,1,1,1,1,1,1,1,1,1,1,1,1,1,1,1,1,1,1,1,1
1,1,1,1,1,1,1,1,1,1,1,1,1,1,1,1,1,1,1,1,1,1,1,1,1
1,1,1,1,1,1,1,1,1,1,1,1,1,1,1,1,1,1,1,1,1,1,1,1,1
endlayer

layer
1,1,1,1,1,1,1,1,1,1,1,1,1,1,1,1,1,1,1,1,1,1,1,1,1
1,1,1,1,1,1,1,1,1,1,1,1,1,1,1,1,1,1,1,1,1,1,1,1,1
1,1,1,1,1,1,1,1,1,1,1,1,1,1,1,1,1,1,1,1,1,1,1,1,1
1,1,1,1,1,1,1,1,1,1,1,1,1,1,1,1,1,1,1,1,1,1,1,1,1
1,1,1,1,1,1,1,1,1,1,1,1,1,1,1,1,1,1,1,1,1,1,1,1,1
1,1,1,1,1,1,1,1,1,1,1,1,1,1,1,1,1,1,1,1,1,1,1,1,1
1,1,1,1,1,1,1,1,1,1,1,1,1,1,1,1,1,1,1,1,1,1,1,1,1
1,1,1,1,1,1,1,1,1,1,1,1,1,1,1,1,1,1,1,1,1,1,1,1,1
1,1,1,1,1,1,1,1,1,1,1,1,1,1,1,1,1,1,1,1,1,1,1,1,1
1,1,1,1,1,1,1,1,1,1,2,2,2,2,2,1,1,1,1,1,1,1,1,1,1
1,1,1,1,1,1,1,1,1,2,2,2,2,2,2,2,1,1,1,1,1,1,1,1,1
1,1,1,1,1,1,1,1,1,2,2,2,2,2,2,2,1,1,1,1,1,1,1,1,1
1,1,1,1,1,1,1,1,1,2,2,2,2,2,2,2,1,1,1,1,1,1,1,1,1
1,1,1,1,1,1,1,1,1,2,2,2,2,2,2,2,1,1,1,1,1,1,1,1,1
1,1,1,1,1,1,1,1,1,2,2,2,2,2,2,2,1,1,1,1,1,1,1,1,1
1,1,1,1,1,1,1,1,1,1,2,2,2,2,2,1,1,1,1,1,1,1,1,1,1
1,1,1,1,1,1,1,1,1,1,1,1,1,1,1,1,1,1,1,1,1,1,1,1,1
1,1,1,1,1,1,1,1,1,1,1,1,1,1,1,1,1,1,1,1,1,1,1,1,1
1,1,1,1,1,1,1,1,1,1,1,1,1,1,1,1,1,1,1,1,1,1,1,1,1
1,1,1,1,1,1,1,1,1,1,1,1,1,1,1,1,1,1,1,1,1,1,1,1,1
1,1,1,1,1,1,1,1,1,1,1,1,1,1,1,1,1,1,1,1,1,1,1,1,1
1,1,1,1,1,1,1,1,1,1,1,1,1,1,1,1,1,1,1,1,1,1,1,1,1
1,1,1,1,1,1,1,1,1,1,1,1,1,1,1,1,1,1,1,1,1,1,1,1,1
1,1,1,1,1,1,1,1,1,1,1,1,1,1,1,1,1,1,1,1,1,1,1,1,1
1,1,1,1,1,1,1,1,1,1,1,1,1,1,1,1,1,1,1,1,1,1,1,1,1
endlayer

