
# Created by Ruins mod version 17.0 Ingame Parser
# authoring Player: ST753M

# A 17x17x17 sphere lined with ores, usually underground

weight=1
embed_into_distance=40
random_height_offset=-32,32
acceptable_target_blocks=grass,dirt,podzol,mycelium,stone,biomesoplenty:grass,biomesoplenty:dirt,gravel,terracotta,stained_terracotta,hardened_clay,hardened_sand,mud,coarse_dirt,clay,red_sand
unacceptable_target_blocks=
dimensions=17,17,17
allowable_overhang=999
max_leveling=0
leveling_buffer=0
preserve_water=0
preserve_lava=0

rule1=0,100,preserveBlock
rule2=0,100,?minecraft:stone-0
rule3=0,100,?minecraft:iron_ore-0
^0,100,?minecraft:iron_ore-0,?minecraft:stone-0,?minecraft:stone-0
^0,100,?minecraft:iron_ore-0,?minecraft:stone-0,?minecraft:stone-0
^0,100,?minecraft:iron_ore-0,?minecraft:stone-0
^0,100,?minecraft:iron_ore-0,?minecraft:stone-0
^0,100,?minecraft:coal_ore-0
^0,100,?minecraft:coal_ore-0,?minecraft:stone-0
^0,100,?minecraft:coal_ore-0
^0,100,?minecraft:coal_ore-0,?minecraft:stone-0
^0,100,?minecraft:coal_ore-0
^0,100,?minecraft:coal_ore-0,?minecraft:stone-0
^0,100,?minecraft:gold_ore-0,?minecraft:iron_ore-0,?minecraft:iron_ore-0,?minecraft:iron_ore-0,?minecraft:iron_ore-0,?minecraft:iron_ore-0,?minecraft:stone-0,?minecraft:stone-0


layer
1,1,1,1,1,1,1,1,1,1,1,1,1,1,1,1,1
1,1,1,1,1,1,1,1,1,1,1,1,1,1,1,1,1
1,1,1,1,1,1,1,1,1,1,1,1,1,1,1,1,1
1,1,1,1,1,1,1,1,1,1,1,1,1,1,1,1,1
1,1,1,1,1,1,1,1,1,1,1,1,1,1,1,1,1
1,1,1,1,1,1,1,1,1,1,1,1,1,1,1,1,1
1,1,1,1,1,1,1,2,2,2,1,1,1,1,1,1,1
1,1,1,1,1,1,2,2,2,2,2,1,1,1,1,1,1
1,1,1,1,1,1,2,2,2,2,2,1,1,1,1,1,1
1,1,1,1,1,1,2,2,2,2,2,1,1,1,1,1,1
1,1,1,1,1,1,1,2,2,2,1,1,1,1,1,1,1
1,1,1,1,1,1,1,1,1,1,1,1,1,1,1,1,1
1,1,1,1,1,1,1,1,1,1,1,1,1,1,1,1,1
1,1,1,1,1,1,1,1,1,1,1,1,1,1,1,1,1
1,1,1,1,1,1,1,1,1,1,1,1,1,1,1,1,1
1,1,1,1,1,1,1,1,1,1,1,1,1,1,1,1,1
1,1,1,1,1,1,1,1,1,1,1,1,1,1,1,1,1
endlayer

layer
1,1,1,1,1,1,1,1,1,1,1,1,1,1,1,1,1
1,1,1,1,1,1,1,1,1,1,1,1,1,1,1,1,1
1,1,1,1,1,1,1,1,1,1,1,1,1,1,1,1,1
1,1,1,1,1,1,1,1,1,1,1,1,1,1,1,1,1
1,1,1,1,1,1,2,2,2,2,2,1,1,1,1,1,1
1,1,1,1,1,2,2,2,2,2,2,2,1,1,1,1,1
1,1,1,1,2,2,2,3,3,3,2,2,2,1,1,1,1
1,1,1,1,2,2,3,3,3,3,3,2,2,1,1,1,1
1,1,1,1,2,2,3,3,3,3,3,2,2,1,1,1,1
1,1,1,1,2,2,3,3,3,3,3,2,2,1,1,1,1
1,1,1,1,2,2,2,3,3,3,2,2,2,1,1,1,1
1,1,1,1,1,2,2,2,2,2,2,2,1,1,1,1,1
1,1,1,1,1,1,2,2,2,2,2,1,1,1,1,1,1
1,1,1,1,1,1,1,1,1,1,1,1,1,1,1,1,1
1,1,1,1,1,1,1,1,1,1,1,1,1,1,1,1,1
1,1,1,1,1,1,1,1,1,1,1,1,1,1,1,1,1
1,1,1,1,1,1,1,1,1,1,1,1,1,1,1,1,1
endlayer

layer
1,1,1,1,1,1,1,1,1,1,1,1,1,1,1,1,1
1,1,1,1,1,1,1,1,1,1,1,1,1,1,1,1,1
1,1,1,1,1,1,1,1,1,1,1,1,1,1,1,1,1
1,1,1,1,1,2,2,2,2,2,2,2,1,1,1,1,1
1,1,1,1,2,2,3,3,3,3,3,2,2,1,1,1,1
1,1,1,2,2,3,3,3,3,3,3,3,2,2,1,1,1
1,1,1,2,3,3,3,0,0,0,3,3,3,2,1,1,1
1,1,1,2,3,3,0,0,0,0,0,3,3,2,1,1,1
1,1,1,2,3,3,0,0,0,0,0,3,3,2,1,1,1
1,1,1,2,3,3,0,0,0,0,0,3,3,2,1,1,1
1,1,1,2,3,3,3,0,0,0,3,3,3,2,1,1,1
1,1,1,2,2,3,3,3,3,3,3,3,2,2,1,1,1
1,1,1,1,2,2,3,3,3,3,3,2,2,1,1,1,1
1,1,1,1,1,2,2,2,2,2,2,2,1,1,1,1,1
1,1,1,1,1,1,1,1,1,1,1,1,1,1,1,1,1
1,1,1,1,1,1,1,1,1,1,1,1,1,1,1,1,1
1,1,1,1,1,1,1,1,1,1,1,1,1,1,1,1,1
endlayer

layer
1,1,1,1,1,1,1,1,1,1,1,1,1,1,1,1,1
1,1,1,1,1,1,1,1,1,1,1,1,1,1,1,1,1
1,1,1,1,1,2,2,2,2,2,2,2,1,1,1,1,1
1,1,1,1,2,3,3,3,3,3,3,3,2,1,1,1,1
1,1,1,2,3,3,0,0,0,0,0,3,3,2,1,1,1
1,1,2,3,3,0,0,0,0,0,0,0,3,3,2,1,1
1,1,2,3,0,0,0,0,0,0,0,0,0,3,2,1,1
1,1,2,3,0,0,0,0,0,0,0,0,0,3,2,1,1
1,1,2,3,0,0,0,0,0,0,0,0,0,3,2,1,1
1,1,2,3,0,0,0,0,0,0,0,0,0,3,2,1,1
1,1,2,3,0,0,0,0,0,0,0,0,0,3,2,1,1
1,1,2,3,3,0,0,0,0,0,0,0,3,3,2,1,1
1,1,1,2,3,0,0,0,0,0,0,3,3,2,1,1,1
1,1,1,1,2,3,3,3,3,3,3,3,2,1,1,1,1
1,1,1,1,1,2,2,2,2,2,2,2,1,1,1,1,1
1,1,1,1,1,1,1,1,1,1,1,1,1,1,1,1,1
1,1,1,1,1,1,1,1,1,1,1,1,1,1,1,1,1
endlayer

layer
1,1,1,1,1,1,1,1,1,1,1,1,1,1,1,1,1
1,1,1,1,1,1,2,2,2,2,2,1,1,1,1,1,1
1,1,1,1,2,2,3,3,3,3,3,2,2,1,1,1,1
1,1,1,2,3,3,0,0,0,0,0,0,3,2,1,1,1
1,1,2,3,0,0,0,0,0,0,0,0,0,3,2,1,1
1,1,2,3,0,0,0,0,0,0,0,0,0,3,2,1,1
1,2,3,0,0,0,0,0,0,0,0,0,0,0,3,2,1
1,2,3,0,0,0,0,0,0,0,0,0,0,0,3,2,1
1,2,3,0,0,0,0,0,0,0,0,0,0,0,3,2,1
1,2,3,0,0,0,0,0,0,0,0,0,0,0,3,2,1
1,2,3,0,0,0,0,0,0,0,0,0,0,0,3,2,1
1,1,2,3,0,0,0,0,0,0,0,0,0,3,2,1,1
1,1,2,3,0,0,0,0,0,0,0,0,0,3,2,1,1
1,1,1,2,3,3,0,0,0,0,0,3,3,2,1,1,1
1,1,1,1,2,2,3,3,3,3,3,2,2,1,1,1,1
1,1,1,1,1,1,2,2,2,2,2,1,1,1,1,1,1
1,1,1,1,1,1,1,1,1,1,1,1,1,1,1,1,1
endlayer

layer
1,1,1,1,1,1,1,1,1,1,1,1,1,1,1,1,1
1,1,1,1,1,2,2,2,2,2,2,2,1,1,1,1,1
1,1,1,2,2,3,3,3,3,3,3,3,2,2,1,1,1
1,1,2,3,3,0,0,0,0,0,0,0,0,3,2,1,1
1,1,2,3,0,0,0,0,0,0,0,0,0,3,2,1,1
1,2,3,0,0,0,0,0,0,0,0,0,0,0,3,2,1
1,2,3,0,0,0,0,0,0,0,0,0,0,0,3,2,1
1,2,3,0,0,0,0,0,0,0,0,0,0,0,3,2,1
1,2,3,0,0,0,0,0,0,0,0,0,0,0,3,2,1
1,2,3,0,0,0,0,0,0,0,0,0,0,0,3,2,1
1,2,3,0,0,0,0,0,0,0,0,0,0,0,3,2,1
1,2,3,0,0,0,0,0,0,0,0,0,0,0,3,2,1
1,1,2,3,0,0,0,0,0,0,0,0,0,3,2,1,1
1,1,2,3,3,0,0,0,0,0,0,0,3,3,2,1,1
1,1,1,2,2,3,3,3,3,3,3,3,2,2,1,1,1
1,1,1,1,1,2,2,2,2,2,2,2,1,1,1,1,1
1,1,1,1,1,1,1,1,1,1,1,1,1,1,1,1,1
endlayer

layer
1,1,1,1,1,1,1,2,2,2,1,1,1,1,1,1,1
1,1,1,1,2,2,2,3,3,3,2,2,2,1,1,1,1
1,1,1,2,3,3,3,0,0,0,3,3,3,2,1,1,1
1,1,2,3,0,0,0,0,0,0,0,0,0,3,2,1,1
1,2,3,0,0,0,0,0,0,0,0,0,0,0,3,2,1
1,2,3,0,0,0,0,0,0,0,0,0,0,0,3,2,1
1,2,3,0,0,0,0,0,0,0,0,0,0,0,3,2,1
2,3,0,0,0,0,0,0,0,0,0,0,0,0,0,3,2
2,3,0,0,0,0,0,0,0,0,0,0,0,0,0,3,2
2,3,0,0,0,0,0,0,0,0,0,0,0,0,0,3,2
1,2,3,0,0,0,0,0,0,0,0,0,0,0,3,2,1
1,2,3,0,0,0,0,0,0,0,0,0,0,0,3,2,1
1,2,3,0,0,0,0,0,0,0,0,0,0,0,3,2,1
1,1,2,3,0,0,0,0,0,0,0,0,0,3,2,1,1
1,1,1,2,3,3,3,0,0,0,3,3,3,2,1,1,1
1,1,1,1,2,2,2,3,3,3,2,2,2,1,1,1,1
1,1,1,1,1,1,1,2,2,2,1,1,1,1,1,1,1
endlayer

layer
1,1,1,1,1,1,2,2,2,2,2,1,1,1,1,1,1
1,1,1,1,2,2,3,3,3,3,3,2,2,1,1,1,1
1,1,1,2,3,3,0,0,0,0,0,3,3,2,1,1,1
1,1,2,3,0,0,0,0,0,0,0,0,0,3,2,1,1
1,2,3,0,0,0,0,0,0,0,0,0,0,0,3,2,1
1,2,3,0,0,0,0,0,0,0,0,0,0,0,3,2,1
2,3,0,0,0,0,0,0,0,0,0,0,0,0,0,3,2
2,3,0,0,0,0,0,0,0,0,0,0,0,0,0,3,2
2,3,0,0,0,0,0,0,0,0,0,0,0,0,0,3,2
2,3,0,0,0,0,0,0,0,0,0,0,0,0,0,3,2
2,3,0,0,0,0,0,0,0,0,0,0,0,0,0,3,2
1,2,3,0,0,0,0,0,0,0,0,0,0,0,3,2,1
1,2,3,0,0,0,0,0,0,0,0,0,0,0,3,2,1
1,1,2,3,0,0,0,0,0,0,0,0,0,3,2,1,1
1,1,1,2,3,3,0,0,0,0,0,3,3,2,1,1,1
1,1,1,1,2,2,3,3,3,3,3,2,2,1,1,1,1
1,1,1,1,1,1,2,2,2,2,2,1,1,1,1,1,1
endlayer

layer
1,1,1,1,1,1,2,2,2,2,2,1,1,1,1,1,1
1,1,1,1,2,2,3,3,3,3,3,2,2,1,1,1,1
1,1,1,2,3,3,0,0,0,0,0,3,3,2,1,1,1
1,1,2,3,0,0,0,0,0,0,0,0,0,3,2,1,1
1,2,3,0,0,0,0,0,0,0,0,0,0,0,3,2,1
1,2,3,0,0,0,0,0,0,0,0,0,0,0,3,2,1
2,3,0,0,0,0,0,0,0,0,0,0,0,0,0,3,2
2,3,0,0,0,0,0,0,0,0,0,0,0,0,0,3,2
2,3,0,0,0,0,0,0,0,0,0,0,0,0,0,3,2
2,3,0,0,0,0,0,0,0,0,0,0,0,0,0,3,2
2,3,0,0,0,0,0,0,0,0,0,0,0,0,0,3,2
1,2,3,0,0,0,0,0,0,0,0,0,0,0,3,2,1
1,2,3,0,0,0,0,0,0,0,0,0,0,0,3,2,1
1,1,2,3,0,0,0,0,0,0,0,0,0,3,2,1,1
1,1,1,2,3,3,0,0,0,0,0,3,3,2,1,1,1
1,1,1,1,2,2,3,3,3,3,3,2,2,1,1,1,1
1,1,1,1,1,1,2,2,2,2,2,1,1,1,1,1,1
endlayer

layer
1,1,1,1,1,1,2,2,2,2,2,1,1,1,1,1,1
1,1,1,1,2,2,3,3,3,3,3,2,2,1,1,1,1
1,1,1,2,3,3,0,0,0,0,0,3,3,2,1,1,1
1,1,2,3,0,0,0,0,0,0,0,0,0,3,2,1,1
1,2,3,0,0,0,0,0,0,0,0,0,0,0,3,2,1
1,2,3,0,0,0,0,0,0,0,0,0,0,0,3,2,1
2,3,0,0,0,0,0,0,0,0,0,0,0,0,0,3,2
2,3,0,0,0,0,0,0,0,0,0,0,0,0,0,3,2
2,3,0,0,0,0,0,0,0,0,0,0,0,0,0,3,2
2,3,0,0,0,0,0,0,0,0,0,0,0,0,0,3,2
2,3,0,0,0,0,0,0,0,0,0,0,0,0,0,3,2
1,2,3,0,0,0,0,0,0,0,0,0,0,0,3,2,1
1,2,3,0,0,0,0,0,0,0,0,0,0,0,3,2,1
1,1,2,3,0,0,0,0,0,0,0,0,0,3,2,1,1
1,1,1,2,3,3,0,0,0,0,0,3,3,2,1,1,1
1,1,1,1,2,2,3,3,3,3,3,2,2,1,1,1,1
1,1,1,1,1,1,2,2,2,2,2,1,1,1,1,1,1
endlayer

layer
1,1,1,1,1,1,1,2,2,2,1,1,1,1,1,1,1
1,1,1,1,2,2,2,3,3,3,2,2,2,1,1,1,1
1,1,1,2,3,3,3,0,0,0,3,3,3,2,1,1,1
1,1,2,3,0,0,0,0,0,0,0,0,0,3,2,1,1
1,2,3,0,0,0,0,0,0,0,0,0,0,0,3,2,1
1,2,3,0,0,0,0,0,0,0,0,0,0,0,3,2,1
1,2,3,0,0,0,0,0,0,0,0,0,0,0,3,2,1
2,3,0,0,0,0,0,0,0,0,0,0,0,0,0,3,2
2,3,0,0,0,0,0,0,0,0,0,0,0,0,0,3,2
2,3,0,0,0,0,0,0,0,0,0,0,0,0,0,3,2
1,2,3,0,0,0,0,0,0,0,0,0,0,0,3,2,1
1,2,3,0,0,0,0,0,0,0,0,0,0,0,3,2,1
1,2,3,0,0,0,0,0,0,0,0,0,0,0,3,2,1
1,1,2,3,0,0,0,0,0,0,0,0,0,3,2,1,1
1,1,1,2,3,3,3,0,0,0,3,3,3,2,1,1,1
1,1,1,1,2,2,2,3,3,3,2,2,2,1,1,1,1
1,1,1,1,1,1,1,2,2,2,1,1,1,1,1,1,1
endlayer

layer
1,1,1,1,1,1,1,1,1,1,1,1,1,1,1,1,1
1,1,1,1,1,2,2,2,2,2,2,2,1,1,1,1,1
1,1,1,2,2,3,3,3,3,3,3,3,2,2,1,1,1
1,1,2,3,3,0,0,0,0,0,0,0,3,3,2,1,1
1,1,2,3,0,0,0,0,0,0,0,0,0,3,2,1,1
1,2,3,0,0,0,0,0,0,0,0,0,0,0,3,2,1
1,2,3,0,0,0,0,0,0,0,0,0,0,0,3,2,1
1,2,3,0,0,0,0,0,0,0,0,0,0,0,3,2,1
1,2,3,0,0,0,0,0,0,0,0,0,0,0,3,2,1
1,2,3,0,0,0,0,0,0,0,0,0,0,0,3,2,1
1,2,3,0,0,0,0,0,0,0,0,0,0,0,3,2,1
1,2,3,0,0,0,0,0,0,0,0,0,0,0,3,2,1
1,1,2,3,0,0,0,0,0,0,0,0,0,3,2,1,1
1,1,2,3,3,0,0,0,0,0,0,0,3,3,2,1,1
1,1,1,2,2,3,3,3,3,3,3,3,2,2,1,1,1
1,1,1,1,1,2,2,2,2,2,2,2,1,1,1,1,1
1,1,1,1,1,1,1,1,1,1,1,1,1,1,1,1,1
endlayer

layer
1,1,1,1,1,1,1,1,1,1,1,1,1,1,1,1,1
1,1,1,1,1,1,2,2,2,2,2,1,1,1,1,1,1
1,1,1,1,2,2,3,3,3,3,3,2,2,1,1,1,1
1,1,1,2,3,3,0,0,0,0,0,3,3,2,1,1,1
1,1,2,3,0,0,0,0,0,0,0,0,0,3,2,1,1
1,1,2,3,0,0,0,0,0,0,0,0,0,3,2,1,1
1,2,3,0,0,0,0,0,0,0,0,0,0,0,3,2,1
1,2,3,0,0,0,0,0,0,0,0,0,0,0,3,2,1
1,2,3,0,0,0,0,0,0,0,0,0,0,0,3,2,1
1,2,3,0,0,0,0,0,0,0,0,0,0,0,3,2,1
1,2,3,0,0,0,0,0,0,0,0,0,0,0,3,2,1
1,1,2,3,0,0,0,0,0,0,0,0,0,3,2,1,1
1,1,2,3,0,0,0,0,0,0,0,0,0,3,2,1,1
1,1,1,2,3,3,0,0,0,0,0,3,3,2,1,1,1
1,1,1,1,2,2,3,3,3,3,3,2,2,1,1,1,1
1,1,1,1,1,1,2,2,2,2,2,1,1,1,1,1,1
1,1,1,1,1,1,1,1,1,1,1,1,1,1,1,1,1
endlayer

layer
1,1,1,1,1,1,1,1,1,1,1,1,1,1,1,1,1
1,1,1,1,1,1,1,1,1,1,1,1,1,1,1,1,1
1,1,1,1,1,2,2,2,2,2,2,2,1,1,1,1,1
1,1,1,1,2,3,3,3,3,3,3,3,2,1,1,1,1
1,1,1,2,3,3,0,0,0,0,0,3,3,2,1,1,1
1,1,2,3,3,0,0,0,0,0,0,0,3,3,2,1,1
1,1,2,3,0,0,0,0,0,0,0,0,0,3,2,1,1
1,1,2,3,0,0,0,0,0,0,0,0,0,3,2,1,1
1,1,2,3,0,0,0,0,0,0,0,0,0,3,2,1,1
1,1,2,3,0,0,0,0,0,0,0,0,0,3,2,1,1
1,1,2,3,0,0,0,0,0,0,0,0,0,3,2,1,1
1,1,2,3,3,0,0,0,0,0,0,0,3,3,2,1,1
1,1,1,2,3,3,0,0,0,0,0,3,3,2,1,1,1
1,1,1,1,2,3,3,3,3,3,3,3,2,1,1,1,1
1,1,1,1,1,2,2,2,2,2,2,2,1,1,1,1,1
1,1,1,1,1,1,1,1,1,1,1,1,1,1,1,1,1
1,1,1,1,1,1,1,1,1,1,1,1,1,1,1,1,1
endlayer

layer
1,1,1,1,1,1,1,1,1,1,1,1,1,1,1,1,1
1,1,1,1,1,1,1,1,1,1,1,1,1,1,1,1,1
1,1,1,1,1,1,1,1,1,1,1,1,1,1,1,1,1
1,1,1,1,1,2,2,2,2,2,2,2,1,1,1,1,1
1,1,1,1,2,2,3,3,3,3,3,2,2,1,1,1,1
1,1,1,2,2,3,3,3,3,3,3,3,2,2,1,1,1
1,1,1,2,3,3,3,0,0,0,3,3,3,2,1,1,1
1,1,1,2,3,3,0,0,0,0,0,3,3,2,1,1,1
1,1,1,2,3,3,0,0,0,0,0,3,3,2,1,1,1
1,1,1,2,3,3,0,0,0,0,0,3,3,2,1,1,1
1,1,1,2,3,3,3,0,0,0,3,3,3,2,1,1,1
1,1,1,2,2,3,3,3,3,3,3,3,2,2,1,1,1
1,1,1,1,2,2,3,3,3,3,3,2,2,1,1,1,1
1,1,1,1,1,2,2,2,2,2,2,2,1,1,1,1,1
1,1,1,1,1,1,1,1,1,1,1,1,1,1,1,1,1
1,1,1,1,1,1,1,1,1,1,1,1,1,1,1,1,1
1,1,1,1,1,1,1,1,1,1,1,1,1,1,1,1,1
endlayer

layer
1,1,1,1,1,1,1,1,1,1,1,1,1,1,1,1,1
1,1,1,1,1,1,1,1,1,1,1,1,1,1,1,1,1
1,1,1,1,1,1,1,1,1,1,1,1,1,1,1,1,1
1,1,1,1,1,1,1,1,1,1,1,1,1,1,1,1,1
1,1,1,1,1,1,2,2,2,2,2,1,1,1,1,1,1
1,1,1,1,1,2,2,2,2,2,2,2,1,1,1,1,1
1,1,1,1,2,2,2,3,3,3,2,2,2,1,1,1,1
1,1,1,1,2,2,3,3,3,3,3,2,2,1,1,1,1
1,1,1,1,2,2,3,3,3,3,3,2,2,1,1,1,1
1,1,1,1,2,2,3,3,3,3,3,2,2,1,1,1,1
1,1,1,1,2,2,2,3,3,3,2,2,2,1,1,1,1
1,1,1,1,1,2,2,2,2,2,2,2,1,1,1,1,1
1,1,1,1,1,1,2,2,2,2,2,1,1,1,1,1,1
1,1,1,1,1,1,1,1,1,1,1,1,1,1,1,1,1
1,1,1,1,1,1,1,1,1,1,1,1,1,1,1,1,1
1,1,1,1,1,1,1,1,1,1,1,1,1,1,1,1,1
1,1,1,1,1,1,1,1,1,1,1,1,1,1,1,1,1
endlayer

layer
1,1,1,1,1,1,1,1,1,1,1,1,1,1,1,1,1
1,1,1,1,1,1,1,1,1,1,1,1,1,1,1,1,1
1,1,1,1,1,1,1,1,1,1,1,1,1,1,1,1,1
1,1,1,1,1,1,1,1,1,1,1,1,1,1,1,1,1
1,1,1,1,1,1,1,1,1,1,1,1,1,1,1,1,1
1,1,1,1,1,1,1,1,1,1,1,1,1,1,1,1,1
1,1,1,1,1,1,1,2,2,2,1,1,1,1,1,1,1
1,1,1,1,1,1,2,2,2,2,2,1,1,1,1,1,1
1,1,1,1,1,1,2,2,2,2,2,1,1,1,1,1,1
1,1,1,1,1,1,2,2,2,2,2,1,1,1,1,1,1
1,1,1,1,1,1,1,2,2,2,1,1,1,1,1,1,1
1,1,1,1,1,1,1,1,1,1,1,1,1,1,1,1,1
1,1,1,1,1,1,1,1,1,1,1,1,1,1,1,1,1
1,1,1,1,1,1,1,1,1,1,1,1,1,1,1,1,1
1,1,1,1,1,1,1,1,1,1,1,1,1,1,1,1,1
1,1,1,1,1,1,1,1,1,1,1,1,1,1,1,1,1
1,1,1,1,1,1,1,1,1,1,1,1,1,1,1,1,1
endlayer

