
# Created by Ruins mod version 17.0 Ingame Parser
# authoring Player: ST753M

weight=1
embed_into_distance=256
acceptable_target_blocks=grass,dirt,coarse_dirt,podzol,stone,gravel,mycelium,clay,mud,sand,sandstone,red_sand,terracotta,dried_clay,ice,snow,water,stained_hardened_clay,hardened_clay,mud,red_sand,biomesoplenty:grass,biomesoplenty:dirt
uniqueMinDistance=200
unacceptable_target_blocks=
dimensions=6,11,11
allowable_overhang=999
max_leveling=0
leveling_buffer=0
preserve_water=0
preserve_lava=0

rule1=0,100,chisel:energizedvoidstone-3
rule2=0,100,chisel:tyrian-3
rule3=0,100,minecraft:tnt-0
rule4=0,100,chisel:voidstone-1
rule5=0,100,chisel:voidstone-7
rule6=0,100,chisel:voidstone-6
rule7=0,100,chisel:obsidian-1
rule8=0,100,chisel:tyrian-2
rule9=0,100,chisel:obsidian-13
rule10=0,100,IInventory;minecraft:trapped_chest;minecraft:minecart#2#0#0+minecraft:redstone#2#0#6+minecraft:redstone#1#0#11+minecraft:skull#1#0#12+minecraft:ender_chest#1#0#14+minecraft:redstone#4#0#20+minecraft:redstone#2#0#25-5,air
rule11=0,100,IInventory;minecraft:trapped_chest;minecraft:coal#3#0#1+chisel:carpet_purple#5#1#4+minecraft:diamond#2#0#5+chisel:carpet_purple#7#1#11+chisel:carpet_purple#3#1#15+minecraft:coal#6#0#21+minecraft:coal#4#0#25-3,air
rule12=0,100,IInventory;minecraft:trapped_chest;minecraft:concrete#5#10#4+minecraft:hopper#1#0#8+minecraft:concrete#4#10#9+minecraft:concrete#7#10#11+minecraft:dye#5#0#23+minecraft:concrete#4#10#25-2,air
rule13=0,100,IInventory;minecraft:trapped_chest;minecraft:potion#{Potion:"minecraft:strong_regeneration"}#0#5+chisel:voidstone#3#4#7+chisel:chisel_iron#{chiseldata:{}}#0#10+chisel:voidstone#4#4#12+minecraft:dye#5#5#16+minecraft:dye#3#5#19+chisel:voidstone#2#4#23-4,air
rule14=0,100,chisel:wool_purple-1
rule15=0,100,MobSpawner:vex,MobSpawner:skeleton,MobSpawner:spider,MobSpawner:spider,MobSpawner:witch,MobSpawner:witch,MobSpawner:witch,MobSpawner:enderman,MobSpawner:silverfish,MobSpawner:silverfish

layer
1,1,1,1,1,1,1,1,1,1,1
1,2,2,2,2,3,2,2,2,2,1
1,2,4,4,5,4,5,4,4,2,1
1,2,4,5,5,5,5,5,4,2,1
1,2,5,5,6,5,6,5,5,2,1
1,3,4,5,5,6,5,5,4,3,1
1,2,5,5,6,5,6,5,5,2,1
1,2,4,5,5,5,5,5,4,2,1
1,2,4,4,5,4,5,4,4,2,1
1,2,2,2,2,3,2,2,2,2,1
1,1,1,1,1,1,1,1,1,1,1
endlayer

layer
7,8,8,8,8,8,8,8,8,8,7
8,0,0,0,0,9,0,0,0,0,8
8,0,0,0,0,0,0,0,0,0,8
8,0,0,0,0,0,0,0,0,0,8
8,0,0,0,0,0,0,0,0,0,8
8,9,0,0,0,7,0,0,0,9,8
8,0,0,0,0,0,0,0,0,0,8
8,0,0,0,0,0,0,0,0,0,8
8,0,0,0,0,0,0,0,0,0,8
8,0,0,0,0,9,0,0,0,0,8
7,8,8,8,8,8,8,8,8,8,7
endlayer

layer
7,8,6,8,8,8,8,8,6,8,7
8,0,0,0,0,10,0,0,0,0,8
6,0,0,0,0,0,0,0,0,0,6
8,0,0,0,0,0,0,0,0,0,8
8,0,0,0,0,0,0,0,0,0,8
8,12,0,0,0,7,0,0,0,11,8
8,0,0,0,0,0,0,0,0,0,8
8,0,0,0,0,0,0,0,0,0,8
6,0,0,0,0,0,0,0,0,0,6
8,0,0,0,0,13,0,0,0,0,8
7,8,6,8,8,8,8,8,6,8,7
endlayer

layer
7,8,8,8,14,14,14,8,8,8,7
8,0,0,0,0,0,0,0,0,0,8
8,0,0,0,0,0,0,0,0,0,8
8,0,0,0,0,0,0,0,0,0,8
14,0,0,0,0,0,0,0,0,0,14
14,0,0,0,0,15,0,0,0,0,14
14,0,0,0,0,0,0,0,0,0,14
8,0,0,0,0,0,0,0,0,0,8
8,0,0,0,0,0,0,0,0,0,8
8,0,0,0,0,0,0,0,0,0,8
7,8,8,8,14,14,14,8,8,8,7
endlayer

layer
7,14,14,14,14,14,14,14,14,14,7
14,0,0,0,0,0,0,0,0,0,14
14,0,0,0,0,0,0,0,0,0,14
14,0,0,0,0,0,0,0,0,0,14
14,0,0,0,0,0,0,0,0,0,14
14,0,0,0,0,7,0,0,0,0,14
14,0,0,0,0,0,0,0,0,0,14
14,0,0,0,0,0,0,0,0,0,14
14,0,0,0,0,0,0,0,0,0,14
14,0,0,0,0,0,0,0,0,0,14
7,14,14,14,14,14,14,14,14,14,7
endlayer

layer
1,1,1,1,1,1,1,1,1,1,1
1,2,2,2,2,2,2,2,2,2,1
1,2,2,2,2,2,2,2,2,2,1
1,2,2,2,2,2,2,2,2,2,1
1,2,2,2,2,2,2,2,2,2,1
1,2,2,2,2,2,2,2,2,2,1
1,2,2,2,2,2,2,2,2,2,1
1,2,2,2,2,2,2,2,2,2,1
1,2,2,2,2,2,2,2,2,2,1
1,2,2,2,2,2,2,2,2,2,1
1,1,1,1,1,1,1,1,1,1,1
endlayer

