
# Created by Ruins mod version 16.7 Ingame Parser
# authoring Player: ST753M

weight=1
embed_into_distance=256
acceptable_target_blocks=grass,dirt,coarse_dirt,podzol,stone,gravel,mycelium,clay,mud,sand,sandstone,red_sand,terracotta,dried_clay,ice,snow,water,stained_hardened_clay,hardened_clay,mud,red_sand,biomesoplenty:grass,biomesoplenty:dirt
unacceptable_target_blocks=
uniqueMinDistance=200
dimensions=16,11,11
allowable_overhang=999
max_leveling=0
leveling_buffer=0
preserve_water=0
preserve_lava=0

rule1=0,100,preserveBlock
rule2=0,100,quark:sandstone_new-5
rule3=0,100,quark:soul_sandstone-0
rule4=0,100,quark:soul_sandstone_wall-0
rule5=0,100,quark:soul_sandstone_stairs-0
rule6=0,100,quark:soul_sandstone_stairs-5
rule7=0,100,quark:soul_sandstone_stairs-1
rule8=0,100,quark:soul_sandstone_stairs-2
rule9=0,100,quark:soul_sandstone_stairs-3
rule10=0,100,MobSpawner:quark:ashen,MobSpawner:quark:dweller
rule11=0,100,quark:soul_sandstone_stairs-4
rule12=0,100,quark:soul_sandstone_stairs-7
rule13=0,100,quark:soul_sandstone_stairs-6
rule14=0,100,ChestGenHook:chests/simple_dungeon:5-5
rule15=0,100,quark:soul_sandstone-1
rule16=0,100,quark:soul_sandstone_slab-8

layer
1,1,1,1,2,2,2,1,1,1,1
1,1,2,2,3,3,3,2,2,1,1
1,2,3,3,3,3,3,3,3,2,1
1,2,3,3,3,3,3,3,3,2,1
2,3,3,3,3,3,3,3,3,3,2
2,3,3,3,3,3,3,3,3,3,2
2,3,3,3,3,3,3,3,3,3,2
1,2,3,3,3,3,3,3,3,2,1
1,2,3,3,3,3,3,3,3,2,1
1,1,2,2,3,3,3,2,2,1,1
1,1,1,1,2,2,2,1,1,1,1
endlayer

layer
1,1,1,1,2,2,2,1,1,1,1
1,1,2,2,3,3,3,2,2,1,1
1,2,4,0,0,0,0,0,4,2,1
1,2,0,0,0,0,0,0,0,2,1
2,3,0,0,0,0,0,0,5,3,2
2,7,0,0,0,4,0,0,6,3,2
2,0,0,0,0,0,0,0,0,3,2
1,2,0,0,0,0,0,0,0,2,1
1,2,4,0,0,0,0,0,4,2,1
1,1,2,2,3,3,8,2,2,1,1
1,1,1,1,2,2,2,1,1,1,1
endlayer

layer
1,1,1,1,2,2,2,1,1,1,1
1,1,2,2,9,3,3,2,2,1,1
1,2,4,0,0,0,0,0,4,2,1
1,2,0,0,0,0,0,0,0,2,1
2,7,0,0,0,0,0,0,0,3,2
2,0,0,0,0,10,0,0,5,3,2
2,0,0,0,0,0,0,0,6,3,2
1,2,0,0,0,0,0,0,0,2,1
1,2,4,0,0,0,0,0,4,2,1
1,1,2,2,3,8,0,2,2,1,1
1,1,1,1,2,2,2,1,1,1,1
endlayer

layer
1,1,1,1,2,2,2,1,1,1,1
1,1,2,2,0,9,3,2,2,1,1
1,2,4,0,0,0,0,0,4,2,1
1,2,0,0,0,0,0,0,0,2,1
2,0,0,0,0,0,0,0,0,5,2
2,0,0,0,0,0,0,0,0,3,2
2,11,0,0,0,0,0,0,5,3,2
1,2,0,0,0,0,0,0,6,2,1
1,2,4,0,0,0,0,0,4,2,1
1,1,2,2,8,0,0,2,2,1,1
1,1,1,1,2,2,2,1,1,1,1
endlayer

layer
1,1,1,1,2,2,2,1,1,1,1
1,1,2,2,0,0,9,2,2,1,1
1,2,4,0,0,0,0,0,4,2,1
1,2,0,0,0,0,0,0,0,2,1
2,0,0,0,0,0,0,0,0,0,2
2,11,0,0,0,0,0,0,0,5,2
2,7,0,0,0,0,0,0,0,3,2
1,2,0,0,0,0,0,0,5,2,1
1,2,4,0,0,0,0,0,6,2,1
1,1,2,2,0,0,12,2,2,1,1
1,1,1,1,2,2,2,1,1,1,1
endlayer

layer
1,1,1,1,2,2,2,1,1,1,1
1,1,2,2,13,0,0,2,2,1,1
1,2,4,0,0,0,0,0,4,2,1
1,2,0,0,0,0,0,0,0,2,1
2,11,0,0,0,0,0,0,0,0,2
2,7,0,0,0,0,0,0,0,0,2
2,0,0,0,0,0,0,0,0,5,2
1,2,0,0,0,0,0,0,0,2,1
1,2,4,0,0,0,0,12,5,2,1
1,1,2,2,0,12,3,2,2,1,1
1,1,1,1,2,2,2,1,1,1,1
endlayer

layer
1,1,1,1,2,2,2,1,1,1,1
1,1,2,2,3,13,0,2,2,1,1
1,2,4,0,0,0,0,0,4,2,1
1,2,0,0,0,0,0,0,0,2,1
2,7,0,0,0,0,0,0,0,6,2
2,0,0,0,0,0,0,0,0,0,2
2,0,0,0,0,0,0,0,0,0,2
1,2,0,0,0,0,0,0,0,2,1
1,2,4,0,0,0,12,8,0,2,1
1,1,2,2,12,3,3,2,2,1,1
1,1,1,1,2,2,2,1,1,1,1
endlayer

layer
1,1,1,1,2,2,2,1,1,1,1
1,1,2,2,3,3,13,2,2,1,1
1,2,4,0,0,0,0,0,4,2,1
1,2,0,0,0,0,0,0,0,2,1
2,0,0,0,0,0,0,0,0,3,2
2,0,0,0,0,0,0,0,0,6,2
2,11,0,0,0,0,0,0,0,0,2
1,2,0,0,0,0,0,0,0,2,1
1,2,4,0,0,12,8,0,0,2,1
1,1,2,2,3,3,3,2,2,1,1
1,1,1,1,2,2,2,1,1,1,1
endlayer

layer
1,1,1,1,2,2,2,1,1,1,1
1,1,2,2,3,3,3,2,2,1,1
1,2,4,0,0,0,0,0,4,2,1
1,2,0,0,0,0,0,0,0,2,1
2,0,0,0,0,0,0,0,0,3,2
2,11,0,0,0,0,0,0,0,3,2
2,3,0,0,0,0,0,0,0,6,2
1,2,0,0,0,0,0,0,0,2,1
1,2,4,0,12,8,0,0,0,2,1
1,1,2,2,3,3,3,2,2,1,1
1,1,1,1,2,2,2,1,1,1,1
endlayer

layer
1,1,1,1,2,2,2,1,1,1,1
1,1,2,2,3,3,3,2,2,1,1
1,2,3,3,6,6,6,3,3,2,1
1,2,3,0,0,0,0,0,3,2,1
2,3,13,0,0,0,0,0,12,3,2
2,3,13,0,0,0,0,0,12,3,2
2,3,13,0,0,0,0,0,12,3,2
1,2,3,0,0,0,0,0,12,2,1
1,2,3,3,8,0,0,0,12,2,1
1,1,2,2,3,3,3,2,2,1,1
1,1,1,1,2,2,2,1,1,1,1
endlayer

layer
1,1,1,1,2,2,2,1,1,1,1
1,1,2,2,3,3,3,2,2,1,1
1,2,3,3,3,3,3,3,3,2,1
1,2,3,3,3,3,3,3,3,2,1
2,3,3,3,0,0,0,3,3,3,2
2,3,3,3,0,0,0,3,3,3,2
2,3,3,3,0,0,0,3,3,3,2
1,2,3,3,3,3,3,3,3,2,1
1,2,3,8,0,0,0,3,3,2,1
1,1,2,2,3,3,3,2,2,1,1
1,1,1,1,2,2,2,1,1,1,1
endlayer

layer
1,1,1,1,2,2,2,1,1,1,1
1,1,2,2,0,14,0,2,2,1,1
1,2,0,0,0,0,0,0,0,2,1
1,2,0,4,4,4,4,4,0,2,1
2,0,0,4,0,0,0,4,0,0,2
2,0,0,4,0,0,0,4,0,0,2
2,0,0,4,0,0,0,4,0,0,2
1,2,0,4,4,4,4,4,0,2,1
1,2,0,0,0,0,0,4,0,2,1
1,1,2,2,0,0,0,2,2,1,1
1,1,1,1,2,2,2,1,1,1,1
endlayer

layer
1,1,1,1,2,15,2,1,1,1,1
1,1,2,2,0,0,0,2,2,1,1
1,2,0,0,0,0,0,0,0,2,1
1,2,0,0,0,0,0,0,0,2,1
2,0,0,0,0,0,0,0,0,0,2
15,0,0,0,0,0,0,0,0,0,15
2,0,0,0,0,0,0,0,0,0,2
1,2,0,0,0,0,0,0,0,2,1
1,2,0,0,0,0,0,0,0,2,1
1,1,2,2,0,0,0,2,2,1,1
1,1,1,1,2,15,2,1,1,1,1
endlayer

layer
1,1,1,1,2,2,2,1,1,1,1
1,1,2,2,0,0,0,2,2,1,1
1,2,16,0,0,0,0,0,16,2,1
1,2,0,0,0,0,0,0,0,2,1
2,0,0,0,0,0,0,0,0,0,2
2,0,0,0,0,0,0,0,0,0,2
2,0,0,0,0,0,0,0,0,0,2
1,2,0,0,0,0,0,0,0,2,1
1,2,16,0,0,0,0,0,16,2,1
1,1,2,2,0,0,0,2,2,1,1
1,1,1,1,2,2,2,1,1,1,1
endlayer

layer
1,1,1,1,1,1,1,1,1,1,1
1,1,1,1,3,3,3,1,1,1,1
1,1,3,3,6,0,6,3,3,1,1
1,1,3,0,0,0,0,0,3,1,1
1,3,13,0,0,0,0,0,12,3,1
1,3,0,0,0,0,0,0,0,3,1
1,3,13,0,0,0,0,0,12,3,1
1,1,3,0,0,0,0,0,3,1,1
1,1,3,3,11,0,11,3,3,1,1
1,1,1,1,3,3,3,1,1,1,1
1,1,1,1,1,1,1,1,1,1,1
endlayer

layer
1,1,1,1,1,1,1,1,1,1,1
1,1,1,1,1,1,1,1,1,1,1
1,1,1,1,3,3,3,1,1,1,1
1,1,1,3,3,3,3,3,1,1,1
1,1,3,3,3,3,3,3,3,1,1
1,1,3,3,3,3,3,3,3,1,1
1,1,3,3,3,3,3,3,3,1,1
1,1,1,3,3,3,3,3,1,1,1
1,1,1,1,3,3,3,1,1,1,1
1,1,1,1,1,1,1,1,1,1,1
1,1,1,1,1,1,1,1,1,1,1
endlayer

