
# Created by Ruins mod version 16.7 Ingame Parser
# authoring Player: ST753M

weight=1
embed_into_distance=256
acceptable_target_blocks=grass,dirt,coarse_dirt,podzol,stone,gravel,mycelium,clay,mud,sand,sandstone,red_sand,terracotta,dried_clay,ice,snow,water,stained_hardened_clay,hardened_clay,biomesoplenty:grass,biomesoplenty:dirt
unacceptable_target_blocks=
dimensions=6,16,13
allowable_overhang=999
max_leveling=0
leveling_buffer=0
preserve_water=0
preserve_lava=0

rule1=0,100,quark:soul_sandstone-0
rule2=0,100,minecraft:soul_sand-0
rule3=0,100,quark:sandstone_new-5
rule4=0,100,IInventory;minecraft:chest;minecraft:rotten_flesh#1#0#0+minecraft:dye#3#3#3+minecraft:gold_ingot#1#0#5+minecraft:rotten_flesh#2#0#7+minecraft:dye#2#3#10+minecraft:rotten_flesh#3#0#11+minecraft:cooked_fish#2#1#13+minecraft:melon_seeds#1#0#15+minecraft:rotten_flesh#1#0#16+minecraft:dye#2#3#17+minecraft:gold_ingot#2#0#19+minecraft:rotten_flesh#1#0#21+minecraft:dye#1#3#22+minecraft:wooden_axe#{"Quark:RuneColor":12,ench:[{lvl:1s,id:70s},{lvl:5s,id:16s},{lvl:2s,id:19s},{lvl:2s,id:20s}],RepairCost:15,"Quark:ItemNameDye":3,display:{Name:"Dweller's Axe"},"Quark:RuneAttached":1b}#0#24-3
rule5=0,100,quark:soul_sandstone-2
rule6=0,100,quark:soul_sandstone-1
rule7=0,100,MobSpawner:quark:dweller,MobSpawner:quark:ashen

layer
1,1,1,1,1,1,1,1,1,1,1,1,1
1,1,1,1,1,1,1,1,1,1,1,1,1
1,1,1,1,1,1,1,1,1,1,1,1,1
1,1,1,1,1,1,1,1,1,1,1,1,1
1,1,1,1,1,1,1,1,1,1,1,1,1
1,1,1,1,1,1,1,1,1,1,1,1,1
1,1,1,1,1,1,1,1,1,1,1,1,1
1,1,1,1,1,1,1,1,1,1,1,1,1
1,1,1,1,1,1,1,1,1,1,1,1,1
1,1,1,1,1,1,1,1,1,1,1,1,1
1,1,1,1,1,1,1,1,1,1,1,1,1
1,1,1,1,1,1,1,1,1,1,1,1,1
1,1,1,1,1,1,1,1,1,1,1,1,1
1,1,1,1,1,1,1,1,1,1,1,1,1
1,1,1,1,1,1,1,1,1,1,1,1,1
1,1,1,1,1,1,1,1,1,1,1,1,1
endlayer

layer
1,1,1,1,1,1,1,1,1,1,1,1,1
1,2,2,2,2,2,2,2,2,2,2,2,1
1,2,2,2,2,2,2,2,2,2,2,2,1
1,2,2,2,2,2,2,2,2,2,2,2,1
1,2,2,2,2,2,2,2,2,2,2,2,1
1,2,2,2,2,2,2,2,2,2,2,2,1
1,2,2,2,2,2,2,2,2,2,2,2,1
1,2,2,2,2,2,2,2,2,2,2,2,1
1,2,2,2,2,2,2,2,2,2,2,2,1
1,2,2,2,2,2,2,2,2,2,2,2,1
1,2,2,2,2,2,2,2,2,2,2,2,1
1,2,2,2,2,2,2,2,2,2,2,2,1
1,2,2,2,2,2,2,2,2,2,2,2,1
1,2,2,2,2,2,2,2,2,2,2,2,1
1,2,2,2,2,2,2,2,2,2,2,2,1
1,1,1,1,1,1,1,1,1,1,1,1,1
endlayer

layer
3,3,3,3,3,3,3,3,3,3,3,3,3
3,0,0,3,0,0,0,0,0,0,0,0,3
3,0,0,3,0,0,0,0,0,0,0,0,3
3,0,0,3,0,0,3,0,0,3,3,3,3
3,0,0,0,0,0,3,0,0,0,0,0,3
3,0,0,0,0,0,3,0,0,0,0,0,3
3,0,0,3,3,3,3,3,3,3,0,0,3
3,0,0,0,0,0,3,0,0,0,0,0,3
3,0,0,0,0,4,3,0,0,0,0,0,3
3,0,0,3,3,3,3,0,0,3,3,3,3
3,0,0,0,0,0,0,0,0,0,0,0,3
3,0,0,0,0,0,0,0,0,0,0,0,3
3,3,3,3,3,3,3,0,0,3,0,0,3
3,0,0,0,0,0,0,0,0,3,0,0,3
3,0,0,0,0,0,0,0,0,3,0,0,3
3,3,3,3,3,3,3,3,3,3,3,3,3
endlayer

layer
5,6,5,6,5,6,5,6,5,6,5,6,5
6,0,0,5,0,0,0,0,0,0,0,0,6
5,0,0,6,0,0,0,0,0,0,0,0,5
6,0,0,5,0,0,6,0,0,5,6,5,6
5,0,0,0,0,0,5,0,0,0,0,0,5
6,0,0,0,0,0,6,0,0,0,0,0,6
5,0,0,6,5,6,7,6,5,6,0,0,5
6,0,0,0,0,0,6,0,0,0,0,0,6
5,0,0,0,0,0,5,0,0,0,0,0,5
6,0,0,5,6,5,6,0,0,5,6,5,6
5,0,0,0,0,0,0,0,0,0,0,0,5
6,0,0,0,0,0,0,0,0,0,0,0,6
5,6,5,6,5,6,5,0,0,6,0,0,5
6,0,0,0,0,0,0,0,0,5,0,0,6
5,0,0,0,0,0,0,0,0,6,0,0,5
6,5,6,5,6,5,6,5,6,5,6,5,6
endlayer

layer
3,3,3,3,3,3,3,3,3,3,3,3,3
3,0,0,3,0,0,0,0,0,0,0,0,3
3,0,0,3,0,0,0,0,0,0,0,0,3
3,0,0,3,0,0,3,0,0,3,3,3,3
3,0,0,0,0,0,3,0,0,0,0,0,3
3,0,0,0,0,0,3,0,0,0,0,0,3
3,0,0,3,3,3,3,3,3,3,0,0,3
3,0,0,0,0,0,3,0,0,0,0,0,3
3,0,0,0,0,0,3,0,0,0,0,0,3
3,0,0,3,3,3,3,0,0,3,3,3,3
3,0,0,0,0,0,0,0,0,0,0,0,3
3,0,0,0,0,0,0,0,0,0,0,0,3
3,3,3,3,3,3,3,0,0,3,0,0,3
3,0,0,0,0,0,0,0,0,3,0,0,3
3,0,0,0,0,0,0,0,0,3,0,0,3
3,3,3,3,3,3,3,3,3,3,3,3,3
endlayer

layer
1,1,1,1,1,1,1,1,1,1,1,1,1
1,1,1,1,1,1,1,1,1,1,1,1,1
1,1,1,1,1,1,1,1,1,1,1,1,1
1,1,1,1,1,1,1,1,1,1,1,1,1
1,1,1,1,1,1,1,1,1,1,1,1,1
1,1,1,1,1,1,1,1,1,1,1,1,1
1,1,1,1,1,1,1,1,1,1,1,1,1
1,1,1,1,1,1,1,1,1,1,1,1,1
1,1,1,1,1,1,1,1,1,1,1,1,1
1,1,1,1,1,1,1,1,1,1,1,1,1
1,1,1,1,1,1,1,1,1,1,1,1,1
1,1,1,1,1,1,1,1,1,1,1,1,1
1,1,1,1,1,1,1,1,1,1,1,1,1
1,1,1,1,1,1,1,1,1,1,1,1,1
1,1,1,1,1,1,1,1,1,1,1,1,1
1,1,1,1,1,1,1,1,1,1,1,1,1
endlayer

