
# Created by Ruins mod version 17.1 Ingame Parser
# authoring Player: ST753M

weight=3
uniqueMinDistance=1000
embed_into_distance=200
acceptable_target_blocks=grass,dirt,podzol,mycelium,stone,biomesoplenty:grass,biomesoplenty:dirt,sand,sandstone,gravel,terracotta,stained_terracotta,hardened_clay,hardened_sand,mud,coarse_dirt,clay,red_sand,netherrack,quartz_ore,lava,nex:block_netherrack,water
unacceptable_target_blocks=
dimensions=12,23,23
allowable_overhang=999
max_leveling=0
leveling_buffer=0
preserve_water=1
preserve_lava=1

biomesToSpawnIn=ocean,deep_ocean,plains,savanna,ice_flats

=0,100,air
rule1=0,100,chisel:technical-15
rule2=0,100,preserveBlock
rule3=0,100,chisel:technical-0
rule4=0,100,chisel:factory-1
rule5=0,100,chisel:brownstone-5
rule6=0,100,chisel:factory-6
rule7=0,100,CommandBlock:RUINSTRIGGER /fill ~-1 ~-8 ~-1 ~1 ~-1 ~1 air:@-1
rule8=0,100,CommandBlock:RUINSTRIGGER /fill ~-1 ~-8 ~-1 ~1 ~-2 ~1 obsidian 0:@-1
rule9=0,100,chisel:technical-14
rule10=0,100,chisel:diamond-6,chisel:blockiron-3,chisel:blockinvar-3,chisel:blockcopper-3,chisel:blockbronze-3,chisel:blockcobalt-3,chisel:blockaluminum-3,chisel:blocklead-3,chisel:blocknickel-3,chisel:blockuranium-3,chisel:blocksteel-3,chisel:blocksilver-3,chisel:blockplatinum-3,chisel:blocklead-5,chisel:blockplatinum-5,chisel:blockuranium-5,chisel:blocktin-3,chisel:blockcobalt-5
rule11=0,100,minecraft:iron_bars-0
rule12=0,100,minecraft:quartz_stairs-4
rule13=0,100,minecraft:quartz_stairs-6
rule14=0,100,chisel:futura-4
^0,100,chisel:futura-2
rule15=0,100,minecraft:quartz_stairs-7
rule16=0,100,minecraft:quartz_stairs-5
rule17=0,100,chisel:glass-12
^0,100,minecraft:iron_bars-0
rule18=0,100,chisel:futura-3

layer
1,2,2,2,2,2,2,2,2,2,2,2,2,2,2,2,2,2,2,2,2,2,1
2,2,2,2,2,2,2,2,2,2,2,2,2,2,2,2,2,2,2,2,2,2,2
2,2,1,2,2,2,2,2,2,2,2,2,2,2,2,2,2,2,2,2,1,2,2
2,2,2,3,3,3,3,3,3,3,3,3,3,3,3,3,3,3,3,3,2,2,2
2,2,2,3,4,5,5,5,5,5,5,5,5,5,5,5,5,5,4,3,2,2,2
2,2,2,3,5,5,5,5,5,5,5,5,5,5,5,5,5,5,5,3,2,2,2
2,2,2,3,5,5,5,5,5,5,5,5,5,5,5,5,5,5,5,3,2,2,2
2,2,2,3,5,5,5,5,5,5,5,5,5,5,5,5,5,5,5,3,2,2,2
2,2,2,3,5,5,5,5,5,5,5,5,5,5,5,5,5,5,5,3,2,2,2
2,2,2,3,5,5,5,5,5,6,6,6,6,6,5,5,5,5,5,3,2,2,2
2,2,2,3,5,5,5,5,5,6,0,0,0,6,5,5,5,5,5,3,2,2,2
2,2,2,3,5,5,5,5,5,6,0,7,0,6,5,5,5,5,5,3,2,2,2
2,2,2,3,5,5,5,5,5,6,0,0,0,6,5,5,5,5,5,3,2,2,2
2,2,2,3,5,5,5,5,5,6,6,6,6,6,5,5,5,5,5,3,2,2,2
2,2,2,3,5,5,5,5,5,5,5,5,5,5,5,5,5,5,5,3,2,2,2
2,2,2,3,5,5,5,5,5,5,5,5,5,5,5,5,5,5,5,3,2,2,2
2,2,2,3,5,5,5,5,5,5,5,5,5,5,5,5,5,5,5,3,2,2,2
2,2,2,3,5,5,5,5,5,5,5,5,5,5,5,5,5,5,5,3,2,2,2
2,2,2,3,4,5,5,5,5,5,5,5,5,5,5,5,5,5,4,3,2,2,2
2,2,2,3,3,3,3,3,3,3,3,3,3,3,3,3,3,3,3,3,2,2,2
2,2,1,2,2,2,2,2,2,2,2,2,2,2,2,2,2,2,2,2,1,2,2
2,2,2,2,2,2,2,2,2,2,2,2,2,2,2,2,2,2,2,2,2,2,2
1,2,2,2,2,2,2,2,2,2,2,2,2,2,2,2,2,2,2,2,2,2,1
endlayer

layer
1,2,2,2,2,2,2,2,2,2,2,2,2,2,2,2,2,2,2,2,2,2,1
2,2,2,2,2,2,2,2,2,2,2,2,2,2,2,2,2,2,2,2,2,2,2
2,2,1,5,5,5,5,5,5,5,5,5,5,5,5,5,5,5,5,5,1,2,2
2,2,5,1,1,1,1,1,1,1,1,1,1,1,1,1,1,1,1,1,5,2,2
2,2,5,1,4,4,3,0,0,0,0,0,0,0,0,0,3,4,4,1,5,2,2
2,2,5,1,4,1,4,1,0,0,0,0,0,0,0,1,4,1,4,1,5,2,2
2,2,5,1,3,4,4,0,0,0,0,0,0,0,0,0,4,4,3,1,5,2,2
2,2,5,1,0,1,0,0,0,0,0,0,0,0,0,0,0,1,0,1,5,2,2
2,2,5,1,0,0,0,0,8,0,0,8,0,0,8,0,0,0,0,1,5,2,2
2,2,5,1,0,0,0,0,0,6,6,6,6,6,0,0,0,0,0,1,5,2,2
2,2,5,1,0,0,0,0,0,6,0,0,0,6,0,0,0,0,0,1,5,2,2
2,2,5,1,0,0,0,0,8,6,0,0,0,6,8,0,0,0,0,1,5,2,2
2,2,5,1,0,0,0,0,0,6,0,0,0,6,0,0,0,0,0,1,5,2,2
2,2,5,1,0,0,0,0,0,6,6,6,6,6,0,0,0,0,0,1,5,2,2
2,2,5,1,0,0,0,0,8,0,0,8,0,0,8,0,0,0,0,1,5,2,2
2,2,5,1,0,1,0,0,0,0,0,0,0,0,0,0,0,1,0,1,5,2,2
2,2,5,1,3,4,4,0,0,0,0,0,0,0,0,0,4,4,3,1,5,2,2
2,2,5,1,4,1,4,1,0,0,0,0,0,0,0,1,4,1,4,1,5,2,2
2,2,5,1,4,4,3,0,0,0,0,0,0,0,0,0,3,4,4,1,5,2,2
2,2,5,1,1,1,1,1,1,1,1,1,1,1,1,1,1,1,1,1,5,2,2
2,2,1,5,5,5,5,5,5,5,5,5,5,5,5,5,5,5,5,5,1,2,2
2,2,2,2,2,2,2,2,2,2,2,2,2,2,2,2,2,2,2,2,2,2,2
1,2,2,2,2,2,2,2,2,2,2,2,2,2,2,2,2,2,2,2,2,2,1
endlayer

layer
1,2,2,2,2,2,2,2,2,2,2,2,2,2,2,2,2,2,2,2,2,2,1
2,2,2,2,2,2,2,2,2,2,2,2,2,2,2,2,2,2,2,2,2,2,2
2,2,1,5,5,5,5,5,5,5,5,5,5,5,5,5,5,5,5,5,1,2,2
2,2,5,1,1,1,1,1,1,1,1,1,1,1,1,1,1,1,1,1,5,2,2
2,2,5,1,4,4,4,0,0,0,0,0,0,0,0,0,4,4,4,1,5,2,2
2,2,5,1,4,1,4,1,0,0,0,0,0,0,0,1,4,1,4,1,5,2,2
2,2,5,1,4,4,0,0,0,0,0,0,0,0,0,0,0,4,4,1,5,2,2
2,2,5,1,0,1,0,0,0,0,0,0,0,0,0,0,0,1,0,1,5,2,2
2,2,5,1,0,0,0,0,0,0,0,0,0,0,0,0,0,0,0,1,5,2,2
2,2,5,1,0,0,0,0,0,0,0,0,0,0,0,0,0,0,0,1,5,2,2
2,2,5,1,0,0,0,0,0,0,0,0,0,0,0,0,0,0,0,1,5,2,2
2,2,5,1,0,0,0,0,0,0,0,0,0,0,0,0,0,0,0,1,5,2,2
2,2,5,1,0,0,0,0,0,0,0,0,0,0,0,0,0,0,0,1,5,2,2
2,2,5,1,0,0,0,0,0,0,0,0,0,0,0,0,0,0,0,1,5,2,2
2,2,5,1,0,0,0,0,0,0,0,0,0,0,0,0,0,0,0,1,5,2,2
2,2,5,1,0,1,0,0,0,0,0,0,0,0,0,0,0,1,0,1,5,2,2
2,2,5,1,4,4,0,0,0,0,0,0,0,0,0,0,0,4,4,1,5,2,2
2,2,5,1,4,1,4,1,0,0,0,0,0,0,0,1,4,1,4,1,5,2,2
2,2,5,1,4,4,4,0,0,0,0,0,0,0,0,0,4,4,4,1,5,2,2
2,2,5,1,1,1,1,1,1,1,1,1,1,1,1,1,1,1,1,1,5,2,2
2,2,1,5,5,5,5,5,5,5,5,5,5,5,5,5,5,5,5,5,1,2,2
2,2,2,2,2,2,2,2,2,2,2,2,2,2,2,2,2,2,2,2,2,2,2
1,2,2,2,2,2,2,2,2,2,2,2,2,2,2,2,2,2,2,2,2,2,1
endlayer

layer
1,2,2,2,2,2,2,2,2,2,2,2,2,2,2,2,2,2,2,2,2,2,1
2,3,3,3,3,3,3,3,3,3,3,3,3,3,3,3,3,3,3,3,3,3,2
2,3,4,4,4,4,5,5,5,5,5,5,5,5,5,5,5,4,4,4,4,3,2
2,3,4,9,3,4,5,5,5,5,5,5,5,5,5,5,5,4,3,9,4,3,2
2,3,4,3,4,4,4,5,5,5,5,5,5,5,5,5,4,4,4,3,4,3,2
2,3,4,4,4,1,0,1,0,0,0,0,0,0,0,1,0,1,4,4,4,3,2
2,3,5,5,4,0,0,0,0,0,0,0,0,0,0,0,0,0,4,5,5,3,2
2,3,5,5,5,1,0,0,0,0,0,0,0,0,0,0,0,1,5,5,5,3,2
2,3,5,5,5,0,0,0,0,0,0,0,0,0,0,0,0,0,5,5,5,3,2
2,3,5,5,5,0,0,0,0,0,0,0,0,0,0,0,0,0,5,5,5,3,2
2,3,5,5,5,0,0,0,0,0,0,0,0,0,0,0,0,0,5,5,5,3,2
2,3,5,5,5,0,0,0,0,0,0,10,0,0,0,0,0,0,5,5,5,3,2
2,3,5,5,5,0,0,0,0,0,0,0,0,0,0,0,0,0,5,5,5,3,2
2,3,5,5,5,0,0,0,0,0,0,0,0,0,0,0,0,0,5,5,5,3,2
2,3,5,5,5,0,0,0,0,0,0,0,0,0,0,0,0,0,5,5,5,3,2
2,3,5,5,5,1,0,0,0,0,0,0,0,0,0,0,0,1,5,5,5,3,2
2,3,5,5,4,0,0,0,0,0,0,0,0,0,0,0,0,0,4,5,5,3,2
2,3,4,4,4,1,0,1,0,0,0,0,0,0,0,1,0,1,4,4,4,3,2
2,3,4,3,4,4,4,5,5,5,5,5,5,5,5,5,4,4,4,3,4,3,2
2,3,4,9,3,4,5,5,5,5,5,5,5,5,5,5,5,4,3,9,4,3,2
2,3,4,4,4,4,5,5,5,5,5,5,5,5,5,5,5,4,4,4,4,3,2
2,3,3,3,3,3,3,3,3,3,3,3,3,3,3,3,3,3,3,3,3,3,2
1,2,2,2,2,2,2,2,2,2,2,2,2,2,2,2,2,2,2,2,2,2,1
endlayer

layer
1,5,6,5,5,5,5,5,5,5,3,5,3,5,5,5,5,5,5,5,6,5,1
5,1,1,1,1,1,1,1,1,1,1,1,1,1,1,1,1,1,1,1,1,1,5
6,1,0,0,0,0,0,0,0,0,0,0,0,0,0,0,0,0,0,0,0,1,6
5,1,0,0,0,0,0,0,0,0,0,0,0,0,0,0,0,0,0,0,0,1,5
5,1,0,0,0,0,0,11,11,11,11,11,11,11,11,11,0,0,0,0,0,1,5
5,1,0,0,0,1,0,1,0,0,0,0,0,0,0,1,0,1,0,0,0,1,5
5,1,0,0,0,0,0,0,0,0,0,0,0,0,0,0,0,0,0,0,0,1,5
5,1,0,0,11,1,0,0,0,0,0,0,0,0,0,0,0,1,11,0,0,1,5
5,1,0,0,11,0,0,0,0,0,0,0,0,0,0,0,0,0,11,0,0,1,5
5,1,0,0,11,0,0,0,0,0,0,0,0,0,0,0,0,0,11,0,0,1,5
3,1,0,0,11,0,0,0,0,0,12,12,12,0,0,0,0,0,11,0,0,1,3
5,1,0,0,11,0,0,0,0,0,15,14,13,0,0,0,0,0,11,0,0,1,5
3,1,0,0,11,0,0,0,0,0,15,16,16,0,0,0,0,0,11,0,0,1,3
5,1,0,0,11,0,0,0,0,0,0,0,0,0,0,0,0,0,11,0,0,1,5
5,1,0,0,11,0,0,0,0,0,0,0,0,0,0,0,0,0,11,0,0,1,5
5,1,0,0,11,1,0,0,0,0,0,0,0,0,0,0,0,1,11,0,0,1,5
5,1,0,0,0,0,0,0,0,0,0,0,0,0,0,0,0,0,0,0,0,1,5
5,1,0,0,0,1,0,1,0,0,0,0,0,0,0,1,0,1,0,0,0,1,5
5,1,0,0,0,0,0,11,11,11,11,11,11,11,11,11,0,0,0,0,0,1,5
5,1,0,0,0,0,0,0,0,0,0,0,0,0,0,0,0,0,0,0,0,1,5
6,1,0,0,0,0,0,0,0,0,0,0,0,0,0,0,0,0,0,0,0,1,6
5,1,1,1,1,1,1,1,1,1,1,1,1,1,1,1,1,1,1,1,1,1,5
1,5,6,5,5,5,5,5,5,5,3,5,3,5,5,5,5,5,5,5,6,5,1
endlayer

layer
1,5,6,5,5,5,5,5,5,5,3,5,3,5,5,5,5,5,5,5,6,5,1
5,1,1,4,4,1,1,1,4,4,1,1,1,4,4,1,1,1,4,4,1,1,5
6,1,0,0,0,0,0,0,0,0,0,0,0,0,0,0,0,0,0,0,0,1,6
5,4,0,0,0,0,0,0,0,0,0,0,0,0,0,0,0,0,0,0,0,4,5
5,4,0,0,0,0,0,0,0,0,0,0,0,0,0,0,0,0,0,0,0,4,5
5,1,0,0,0,1,0,1,0,0,0,0,0,0,0,1,0,1,0,0,0,1,5
5,1,0,0,0,0,0,0,0,0,0,0,0,0,0,0,0,0,0,0,0,1,5
5,1,0,0,0,1,0,0,0,0,0,0,0,0,0,0,0,1,0,0,0,1,5
5,4,0,0,0,0,0,0,0,0,0,0,0,0,0,0,0,0,0,0,0,4,5
5,4,0,0,0,0,0,0,0,0,0,0,0,0,0,0,0,0,0,0,0,4,5
3,1,0,0,0,0,0,0,0,0,17,17,17,0,0,0,0,0,0,0,0,1,3
5,1,0,0,0,0,0,0,0,0,17,14,17,0,0,0,0,0,0,0,0,1,5
3,1,0,0,0,0,0,0,0,0,17,17,17,0,0,0,0,0,0,0,0,1,3
5,4,0,0,0,0,0,0,0,0,0,0,0,0,0,0,0,0,0,0,0,4,5
5,4,0,0,0,0,0,0,0,0,0,0,0,0,0,0,0,0,0,0,0,4,5
5,1,0,0,0,1,0,0,0,0,0,0,0,0,0,0,0,1,0,0,0,1,5
5,1,0,0,0,0,0,0,0,0,0,0,0,0,0,0,0,0,0,0,0,1,5
5,1,0,0,0,1,0,1,0,0,0,0,0,0,0,1,0,1,0,0,0,1,5
5,4,0,0,0,0,0,0,0,0,0,0,0,0,0,0,0,0,0,0,0,4,5
5,4,0,0,0,0,0,0,0,0,0,0,0,0,0,0,0,0,0,0,0,4,5
6,1,0,0,0,0,0,0,0,0,0,0,0,0,0,0,0,0,0,0,0,1,6
5,1,1,4,4,1,1,1,4,4,1,1,1,4,4,1,1,1,4,4,1,1,5
1,5,6,5,5,5,5,5,5,5,3,5,3,5,5,5,5,5,5,5,6,5,1
endlayer

layer
1,5,6,5,5,5,5,5,5,5,3,5,3,5,5,5,5,5,5,5,6,5,1
5,3,3,4,4,3,9,3,4,4,3,9,3,4,4,3,9,3,4,4,3,3,5
6,3,0,0,0,0,0,0,0,0,0,0,0,0,0,0,0,0,0,0,0,3,6
5,4,0,0,0,0,0,0,0,0,0,0,0,0,0,0,0,0,0,0,0,4,5
5,4,0,0,0,0,0,0,0,0,0,0,0,0,0,0,0,0,0,0,0,4,5
5,3,0,0,0,1,1,1,0,0,0,0,0,0,0,1,1,1,0,0,0,3,5
5,9,0,0,0,1,0,0,0,0,0,0,0,0,0,0,0,1,0,0,0,9,5
5,3,0,0,0,1,0,0,0,0,0,14,0,0,0,0,0,1,0,0,0,3,5
5,4,0,0,0,0,0,0,0,0,0,14,0,0,0,0,0,0,0,0,0,4,5
5,4,0,0,0,0,0,0,0,0,0,14,0,0,0,0,0,0,0,0,0,4,5
3,3,0,0,0,0,0,0,0,0,17,14,17,0,0,0,0,0,0,0,0,3,3
5,9,0,0,0,0,0,14,14,14,14,14,14,14,14,14,0,0,0,0,0,9,5
3,3,0,0,0,0,0,0,0,0,17,14,17,0,0,0,0,0,0,0,0,3,3
5,4,0,0,0,0,0,0,0,0,0,14,0,0,0,0,0,0,0,0,0,4,5
5,4,0,0,0,0,0,0,0,0,0,14,0,0,0,0,0,0,0,0,0,4,5
5,3,0,0,0,1,0,0,0,0,0,14,0,0,0,0,0,1,0,0,0,3,5
5,9,0,0,0,1,0,0,0,0,0,0,0,0,0,0,0,1,0,0,0,9,5
5,3,0,0,0,1,1,1,0,0,0,0,0,0,0,1,1,1,0,0,0,3,5
5,4,0,0,0,0,0,0,0,0,0,0,0,0,0,0,0,0,0,0,0,4,5
5,4,0,0,0,0,0,0,0,0,0,0,0,0,0,0,0,0,0,0,0,4,5
6,3,0,0,0,0,0,0,0,0,0,0,0,0,0,0,0,0,0,0,0,3,6
5,3,3,4,4,3,9,3,4,4,3,9,3,4,4,3,9,3,4,4,3,3,5
1,5,6,5,5,5,5,5,5,5,3,5,3,5,5,5,5,5,5,5,6,5,1
endlayer

layer
1,5,6,5,9,5,5,9,5,5,3,5,3,5,5,9,5,5,9,5,6,5,1
5,1,1,4,4,1,1,1,4,4,1,1,1,4,4,1,1,1,4,4,1,1,5
6,1,0,0,0,0,0,0,0,0,0,0,0,0,0,0,0,0,0,0,0,1,6
5,4,0,0,0,0,0,0,0,0,0,0,0,0,0,0,0,0,0,0,0,4,5
9,4,0,0,0,0,0,0,0,0,0,0,0,0,0,0,0,0,0,0,0,4,9
5,1,0,0,0,1,11,0,0,0,0,0,0,0,0,0,11,1,0,0,0,1,5
5,1,0,0,0,11,0,0,0,0,0,0,0,0,0,0,0,11,0,0,0,1,5
9,1,0,0,0,0,0,0,0,0,0,14,0,0,0,0,0,0,0,0,0,1,9
5,4,0,0,0,0,0,0,0,0,0,0,0,0,0,0,0,0,0,0,0,4,5
5,4,0,0,0,0,0,0,0,0,0,0,0,0,0,0,0,0,0,0,0,4,5
3,1,0,0,0,0,0,0,0,0,18,18,18,0,0,0,0,0,0,0,0,1,3
5,1,0,0,0,0,0,14,0,0,18,14,18,0,0,14,0,0,0,0,0,1,5
3,1,0,0,0,0,0,0,0,0,18,18,18,0,0,0,0,0,0,0,0,1,3
5,4,0,0,0,0,0,0,0,0,0,0,0,0,0,0,0,0,0,0,0,4,5
5,4,0,0,0,0,0,0,0,0,0,0,0,0,0,0,0,0,0,0,0,4,5
9,1,0,0,0,0,0,0,0,0,0,14,0,0,0,0,0,0,0,0,0,1,9
5,1,0,0,0,11,0,0,0,0,0,0,0,0,0,0,0,11,0,0,0,1,5
5,1,0,0,0,1,11,0,0,0,0,0,0,0,0,0,11,1,0,0,0,1,5
9,4,0,0,0,0,0,0,0,0,0,0,0,0,0,0,0,0,0,0,0,4,9
5,4,0,0,0,0,0,0,0,0,0,0,0,0,0,0,0,0,0,0,0,4,5
6,1,0,0,0,0,0,0,0,0,0,0,0,0,0,0,0,0,0,0,0,1,6
5,1,1,4,4,1,1,1,4,4,1,1,1,4,4,1,1,1,4,4,1,1,5
1,5,6,5,9,5,5,9,5,5,3,5,3,5,5,9,5,5,9,5,6,5,1
endlayer

layer
1,5,6,5,5,5,5,5,5,1,1,1,1,1,5,5,5,5,5,5,6,5,1
5,1,1,1,1,1,1,1,1,1,1,1,1,1,1,1,1,1,1,1,1,1,5
6,1,0,0,0,0,0,0,0,0,0,0,0,0,0,0,0,0,0,0,0,1,6
5,1,0,0,0,0,0,0,0,0,0,0,0,0,0,0,0,0,0,0,0,1,5
5,1,0,0,0,0,0,0,0,0,0,0,0,0,0,0,0,0,0,0,0,1,5
5,1,0,0,0,1,0,0,0,0,0,0,0,0,0,0,0,1,0,0,0,1,5
5,1,0,0,0,0,0,0,0,0,0,0,0,0,0,0,0,0,0,0,0,1,5
5,1,0,0,0,0,0,0,0,0,0,14,0,0,0,0,0,0,0,0,0,1,5
5,1,0,0,0,0,0,0,0,0,0,14,0,0,0,0,0,0,0,0,0,1,5
1,1,0,0,0,0,0,0,0,0,0,14,0,0,0,0,0,0,0,0,0,1,1
1,1,0,0,0,0,0,0,0,0,17,14,17,0,0,0,0,0,0,0,0,1,1
1,1,0,0,0,0,0,14,14,14,14,14,14,14,14,14,0,0,0,0,0,1,1
1,1,0,0,0,0,0,0,0,0,17,14,17,0,0,0,0,0,0,0,0,1,1
1,1,0,0,0,0,0,0,0,0,0,14,0,0,0,0,0,0,0,0,0,1,1
5,1,0,0,0,0,0,0,0,0,0,14,0,0,0,0,0,0,0,0,0,1,5
5,1,0,0,0,0,0,0,0,0,0,14,0,0,0,0,0,0,0,0,0,1,5
5,1,0,0,0,0,0,0,0,0,0,0,0,0,0,0,0,0,0,0,0,1,5
5,1,0,0,0,1,0,0,0,0,0,0,0,0,0,0,0,1,0,0,0,1,5
5,1,0,0,0,0,0,0,0,0,0,0,0,0,0,0,0,0,0,0,0,1,5
5,1,0,0,0,0,0,0,0,0,0,0,0,0,0,0,0,0,0,0,0,1,5
6,1,0,0,0,0,0,0,0,0,0,0,0,0,0,0,0,0,0,0,0,1,6
5,1,1,1,1,1,1,1,1,1,1,1,1,1,1,1,1,1,1,1,1,1,5
1,5,6,5,5,5,5,5,5,1,1,1,1,1,5,5,5,5,5,5,6,5,1
endlayer

layer
3,1,1,2,2,2,2,2,2,1,2,2,2,1,2,2,2,2,2,2,1,1,3
1,3,3,3,3,3,3,3,3,3,5,5,5,3,3,3,3,3,3,3,3,3,1
1,3,5,5,5,4,5,5,5,5,5,5,5,5,5,5,5,5,5,5,5,3,1
2,3,5,0,0,4,0,0,0,0,0,0,0,0,0,0,0,0,0,0,5,3,2
2,3,5,0,0,4,0,0,0,0,0,0,0,0,0,0,0,0,0,0,5,3,2
2,3,4,4,4,1,0,0,0,0,0,0,0,0,0,0,0,1,0,0,5,3,2
2,3,5,0,0,0,0,0,0,0,0,0,0,0,0,0,0,0,0,0,5,3,2
2,3,5,0,0,0,0,0,0,0,0,14,0,0,0,0,0,0,0,0,5,3,2
2,3,5,0,0,0,0,0,0,0,0,0,0,0,0,0,0,0,0,0,5,3,2
1,3,5,0,0,0,0,0,0,0,0,0,0,0,0,0,0,0,0,0,5,3,1
2,5,5,0,0,0,0,0,0,0,17,17,17,0,0,0,0,0,0,0,5,5,2
2,5,5,0,0,0,0,14,0,0,17,14,17,0,0,14,0,0,0,0,5,5,2
2,5,5,0,0,0,0,0,0,0,17,17,17,0,0,0,0,0,0,0,5,5,2
1,3,5,0,0,0,0,0,0,0,0,0,0,0,0,0,0,0,0,0,5,3,1
2,3,5,0,0,0,0,0,0,0,0,0,0,0,0,0,0,0,0,0,5,3,2
2,3,5,0,0,0,0,0,0,0,0,14,0,0,0,0,0,0,0,0,5,3,2
2,3,5,0,0,0,0,0,0,0,0,0,0,0,0,0,0,0,0,0,5,3,2
2,3,4,4,4,1,0,0,0,0,0,0,0,0,0,0,0,1,4,4,4,3,2
2,3,5,0,0,4,0,0,0,0,0,0,0,0,0,0,0,4,0,0,5,3,2
2,3,5,0,0,4,0,0,0,0,0,0,0,0,0,0,0,4,0,0,5,3,2
1,3,5,5,5,4,5,5,5,5,5,5,5,5,5,5,5,4,5,5,5,3,1
1,3,3,3,3,3,3,3,3,3,5,5,5,3,3,3,3,3,3,3,3,3,1
3,1,1,2,2,2,2,2,2,1,2,2,2,1,2,2,2,2,2,2,1,1,3
endlayer

layer
2,2,2,2,2,2,2,2,2,1,2,2,2,1,2,2,2,2,2,2,2,2,2
2,3,1,1,2,2,2,2,2,1,2,2,2,1,2,2,2,2,2,1,1,3,2
2,1,5,5,5,5,5,5,5,1,1,1,1,1,5,5,5,5,5,5,5,1,2
2,1,5,5,5,5,5,5,5,5,5,5,5,5,5,5,5,5,5,5,5,1,2
2,2,5,5,5,5,5,5,5,5,5,5,5,5,5,5,5,5,5,5,5,2,2
2,2,5,5,5,3,4,4,4,4,4,4,4,4,4,4,4,3,5,5,5,2,2
2,2,5,5,5,4,0,0,0,0,0,0,0,0,0,0,0,4,5,5,5,2,2
2,2,5,5,5,4,0,0,0,0,0,14,0,0,0,0,0,4,5,5,5,2,2
2,2,5,5,5,4,0,0,0,0,0,0,0,0,0,0,0,4,5,5,5,2,2
1,1,1,5,5,4,0,0,0,6,6,6,6,6,0,0,0,4,5,5,1,1,1
2,2,1,5,5,4,0,0,0,6,17,17,17,6,0,0,0,4,5,5,1,2,2
2,2,1,5,5,4,0,14,0,6,17,14,17,6,0,14,0,4,5,5,1,2,2
2,2,1,5,5,4,0,0,0,6,17,17,17,6,0,0,0,4,5,5,1,2,2
1,1,1,5,5,4,0,0,0,6,6,6,6,6,0,0,0,4,5,5,1,1,1
2,2,5,5,5,4,0,0,0,0,0,0,0,0,0,0,0,4,5,5,5,2,2
2,2,5,5,5,4,0,0,0,0,0,14,0,0,0,0,0,4,5,5,5,2,2
2,2,5,5,5,4,0,0,0,0,0,0,0,0,0,0,0,4,5,5,5,2,2
2,2,5,5,5,3,4,4,4,4,4,4,4,4,4,4,4,3,5,5,5,2,2
2,2,5,5,5,5,5,5,5,5,5,5,5,5,5,5,5,5,5,5,5,2,2
2,1,5,5,5,5,5,5,5,5,5,5,5,5,5,5,5,5,5,5,5,1,2
2,1,5,5,5,5,5,5,5,1,1,1,1,1,5,5,5,5,5,5,5,1,2
2,3,1,1,2,2,2,2,2,1,2,2,2,1,2,2,2,2,2,1,1,3,2
2,2,2,2,2,2,2,2,2,1,2,2,2,1,2,2,2,2,2,2,2,2,2
endlayer

layer
2,2,2,2,2,2,2,2,2,2,2,2,2,2,2,2,2,2,2,2,2,2,2
2,2,2,2,2,2,2,2,2,2,2,2,2,2,2,2,2,2,2,2,2,2,2
2,2,3,1,1,2,2,2,2,2,2,2,2,2,2,2,2,2,1,1,3,2,2
2,2,1,3,1,1,2,2,2,2,2,2,2,2,2,2,2,1,1,3,1,2,2
2,2,1,1,3,1,1,2,2,2,2,2,2,2,2,2,1,1,3,1,1,2,2
2,2,2,1,1,3,3,3,3,3,3,3,3,3,3,3,3,3,1,1,2,2,2
2,2,2,2,1,3,5,5,5,5,5,5,5,5,5,5,5,3,1,2,2,2,2
2,2,2,2,2,3,5,5,5,5,5,5,5,5,5,5,5,3,2,2,2,2,2
2,2,2,2,2,3,5,5,5,5,5,5,5,5,5,5,5,3,2,2,2,2,2
2,2,2,2,2,3,5,5,5,5,5,5,5,5,5,5,5,3,2,2,2,2,2
2,2,2,2,2,3,5,5,5,5,5,5,5,5,5,5,5,3,2,2,2,2,2
2,2,2,2,2,3,5,5,5,5,5,5,5,5,5,5,5,3,2,2,2,2,2
2,2,2,2,2,3,5,5,5,5,5,5,5,5,5,5,5,3,2,2,2,2,2
2,2,2,2,2,3,5,5,5,5,5,5,5,5,5,5,5,3,2,2,2,2,2
2,2,2,2,2,3,5,5,5,5,5,5,5,5,5,5,5,3,2,2,2,2,2
2,2,2,2,2,3,5,5,5,5,5,5,5,5,5,5,5,3,2,2,2,2,2
2,2,2,2,1,3,5,5,5,5,5,5,5,5,5,5,5,3,1,2,2,2,2
2,2,2,1,1,3,3,3,3,3,3,3,3,3,3,3,3,3,1,1,2,2,2
2,2,1,1,3,1,1,2,2,2,2,2,2,2,2,2,1,1,3,1,1,2,2
2,2,1,3,1,1,2,2,2,2,2,2,2,2,2,2,2,1,1,3,1,2,2
2,2,3,1,1,2,2,2,2,2,2,2,2,2,2,2,2,2,1,1,3,2,2
2,2,2,2,2,2,2,2,2,2,2,2,2,2,2,2,2,2,2,2,2,2,2
2,2,2,2,2,2,2,2,2,2,2,2,2,2,2,2,2,2,2,2,2,2,2
endlayer

