
# Created by Ruins mod version 16.7 Ingame Parser
# authoring Player: ST753M

weight=3
embed_into_distance=256
acceptable_target_blocks=grass,dirt,coarse_dirt,podzol,stone,gravel,mycelium,clay,mud,sand,sandstone,red_sand,terracotta,dried_clay,ice,snow,water,stained_hardened_clay,hardened_clay,biomesoplenty:grass,biomesoplenty:dirt
unacceptable_target_blocks=
uniqueMinDistance=200
dimensions=13,12,11
allowable_overhang=999
max_leveling=0
leveling_buffer=0
preserve_water=0
preserve_lava=0

rule1=0,100,preserveBlock
rule2=0,100,minecraft:stone-0
rule3=0,100,quark:iron_plate-1
rule4=0,100,minecraft:water-0
^0,100,minecraft:lava-0
rule5=0,100,quark:iron_rod-3
rule6=0,100,quark:iron_rod-2
rule7=0,100,quark:iron_plate_stairs-2
rule8=0,100,quark:iron_plate_stairs-7
rule9=0,100,IInventory;minecraft:chest;minecraft:chainmail_helmet#{"Quark:RuneColor":7,ench:[{lvl:3s,id:5s},{lvl:1s,id:6s}],RepairCost:1,"Quark:ItemNameDye":7,"Quark:RuneAttached":1b}#0#10+minecraft:chainmail_chestplate#{"Quark:RuneColor":7,ench:[{lvl:4s,id:3s}],RepairCost:1,"Quark:ItemNameDye":7,"Quark:RuneAttached":1b}#0#12+minecraft:chainmail_leggings#{"Quark:RuneColor":7,ench:[{lvl:4s,id:1s}],RepairCost:1,"Quark:ItemNameDye":7,"Quark:RuneAttached":1b}#0#14+minecraft:chainmail_boots#{"Quark:RuneColor":7,ench:[{lvl:3s,id:8s}],RepairCost:1,"Quark:ItemNameDye":7,"Quark:RuneAttached":1b}#0#16-4
rule10=0,100,minecraft:anvil-0
rule11=0,100,quark:iron_plate-0,quark:iron_plate-1
rule12=0,100,quark:iron_plate_slab-8
rule13=0,100,minecraft:rail-6
rule14=0,100,minecraft:rail-0
rule15=0,100,minecraft:rail-9
rule16=0,100,minecraft:rail-1
rule17=0,100,minecraft:iron_bars-0
rule18=0,100,minecraft:rail-7
rule19=0,100,minecraft:rail-8
rule20=0,100,Skull:0:10-1
rule21=0,100,quark:iron_ladder-4
rule22=0,100,minecraft:lever-0
rule23=0,100,minecraft:iron_trapdoor-3

layer
1,1,1,1,1,1,1,1,1,1,1
1,1,1,1,1,1,1,1,1,1,1
1,1,2,2,2,2,2,2,2,1,1
1,1,2,2,2,2,2,2,2,1,1
1,1,2,2,2,2,2,2,2,1,1
1,1,2,2,2,2,2,2,2,1,1
1,1,2,2,2,2,2,2,2,1,1
1,1,2,2,2,2,2,2,2,1,1
1,1,2,2,2,2,2,2,2,1,1
1,1,1,1,1,1,1,1,1,1,1
1,1,1,1,1,1,1,1,1,1,1
1,1,1,1,1,1,1,1,1,1,1
endlayer

layer
1,1,1,1,1,1,1,1,1,1,1
1,1,2,2,2,2,2,2,2,2,1
1,2,3,3,3,3,3,3,3,2,1
1,2,3,3,3,3,3,3,3,2,1
1,2,3,3,3,3,3,3,3,2,1
1,2,3,3,3,3,3,3,3,2,1
1,2,3,3,3,3,3,3,3,2,1
1,2,3,3,3,3,3,3,3,2,1
1,2,3,3,3,3,3,3,3,2,1
1,1,2,2,2,2,2,2,2,1,1
1,1,1,1,1,1,1,1,1,1,1
1,1,1,1,1,1,1,1,1,1,1
endlayer

layer
1,1,2,2,2,2,2,2,2,1,1
1,2,3,3,3,3,3,3,3,2,1
2,3,4,4,4,4,4,4,4,3,2
2,3,4,4,4,4,4,4,4,3,2
2,3,4,4,4,4,4,4,4,3,2
2,3,4,4,4,4,4,4,4,3,2
2,3,4,4,4,4,4,4,4,3,2
2,3,4,4,4,4,4,4,4,3,2
2,3,4,4,4,4,4,4,4,3,2
1,2,3,3,3,3,3,3,3,2,1
1,1,2,2,2,2,2,2,2,1,1
1,1,1,1,1,1,1,1,1,1,1
endlayer

layer
1,1,2,2,2,2,2,2,2,1,1
1,2,3,3,3,3,3,3,3,2,1
2,3,4,4,4,4,4,4,4,3,2
2,3,4,4,4,4,4,4,4,3,2
2,3,4,4,4,4,4,4,4,3,2
2,3,4,4,4,4,4,4,4,3,2
2,3,4,4,4,4,4,4,4,3,2
2,3,4,4,4,4,4,4,4,3,2
2,3,4,4,4,4,4,4,4,3,2
1,2,3,3,3,3,3,3,3,2,1
1,1,2,2,2,2,2,2,2,1,1
1,1,1,1,1,1,1,1,1,1,1
endlayer

layer
3,3,3,3,3,3,3,3,3,3,3
3,3,3,3,3,3,3,3,3,3,3
3,3,6,6,6,6,6,6,5,3,3
3,3,6,6,6,6,6,6,5,3,3
3,3,6,6,6,6,6,6,5,3,3
3,3,6,6,6,6,6,6,5,3,3
3,3,6,6,6,6,6,6,5,3,3
3,3,6,6,6,6,6,6,5,3,3
3,3,6,6,6,6,6,6,5,3,3
3,3,3,3,3,3,3,3,3,3,3
3,3,3,3,3,3,3,3,3,3,3
3,3,3,3,3,3,3,3,3,3,3
endlayer

layer
3,3,3,3,3,3,3,3,3,3,3
3,0,0,0,0,0,0,0,0,0,3
3,0,0,0,0,0,0,0,0,0,3
3,0,0,0,0,0,0,0,0,0,3
3,0,0,0,0,0,0,0,0,0,3
3,0,0,0,0,0,0,0,0,0,3
3,0,0,0,0,0,0,0,0,0,3
3,0,0,0,0,0,0,0,0,0,3
3,0,0,0,0,0,0,0,0,0,3
3,0,0,0,0,0,0,0,0,0,3
3,0,10,9,0,0,8,7,0,0,3
3,3,3,3,3,3,3,3,3,3,3
endlayer

layer
11,11,11,11,11,3,11,11,3,11,11
11,0,0,0,0,0,0,0,0,0,3
11,0,0,0,0,0,0,0,0,0,3
3,0,0,0,0,0,0,0,0,0,3
11,0,0,0,0,0,0,0,0,0,11
11,0,0,0,0,0,0,0,0,0,11
11,0,0,0,0,0,0,0,0,0,11
11,0,0,0,0,0,0,0,0,0,11
3,0,0,0,0,0,0,0,0,0,11
3,0,0,0,0,0,0,0,0,0,11
11,0,0,0,0,8,7,0,0,0,11
11,11,11,11,11,11,11,11,11,11,11
endlayer

layer
11,11,11,11,11,11,11,11,11,11,11
11,0,0,0,0,0,0,0,0,0,11
11,0,0,0,0,0,0,0,0,0,3
11,0,0,0,0,0,0,0,0,0,11
11,0,0,0,0,0,0,0,0,0,11
11,0,0,0,0,0,0,0,0,0,11
11,0,0,0,0,0,0,0,0,0,11
11,0,0,0,0,0,0,0,0,0,11
11,0,0,0,0,0,0,0,0,0,11
11,0,0,0,0,0,0,0,0,0,11
11,0,0,0,8,7,0,0,0,0,11
11,11,11,11,11,11,11,11,11,11,11
endlayer

layer
11,11,11,11,11,11,11,11,11,11,11
11,11,11,11,11,11,11,11,11,11,11
11,11,12,12,12,12,12,12,12,11,11
11,11,12,0,0,0,0,0,12,11,11
11,11,12,0,0,0,0,0,12,11,11
11,11,12,0,0,0,0,0,12,11,11
11,11,12,0,0,0,0,0,12,11,11
11,11,12,0,0,0,0,0,12,11,11
11,11,12,12,12,12,12,12,12,11,11
11,11,11,11,11,11,11,11,11,11,11
11,11,11,11,7,0,0,0,8,11,11
11,11,11,11,11,11,11,11,11,11,11
endlayer

layer
11,11,11,11,11,11,11,11,11,11,11
11,15,14,14,14,14,14,14,14,13,11
11,16,17,17,17,17,17,17,17,16,11
11,16,17,0,0,0,0,0,17,16,11
11,16,17,0,0,0,0,0,17,16,11
11,16,17,0,0,0,0,0,17,16,11
11,16,17,0,0,0,0,0,17,16,11
11,16,17,0,0,0,0,0,17,16,11
11,16,17,17,17,17,17,17,17,16,11
11,19,14,14,14,14,14,14,14,18,11
11,21,0,0,0,0,0,0,0,20,11
11,11,11,11,11,11,11,11,11,11,11
endlayer

layer
11,11,11,11,11,11,11,11,11,11,11
11,0,0,0,0,0,0,0,0,0,11
11,0,17,17,17,17,17,17,17,0,11
11,0,17,0,0,0,0,0,17,0,11
11,0,17,0,0,0,0,0,17,0,11
11,0,17,0,0,0,0,0,17,0,11
11,0,17,0,0,0,0,0,17,0,11
11,0,17,0,0,0,0,0,17,0,11
11,0,17,17,17,17,17,17,17,0,11
11,0,0,0,0,0,0,0,0,0,11
11,21,0,0,0,0,0,0,0,0,11
11,11,11,11,11,11,11,11,11,11,11
endlayer

layer
11,11,11,11,11,11,11,11,11,11,11
11,0,0,0,0,0,0,0,0,0,11
11,0,17,17,17,17,17,17,17,0,11
11,0,17,0,0,0,0,0,17,0,11
11,0,17,0,0,0,0,0,17,0,11
11,0,17,0,0,0,0,0,17,0,11
11,0,17,0,0,0,0,0,17,0,11
11,0,17,0,0,0,0,0,17,0,11
11,0,17,17,17,17,17,17,17,0,11
11,0,0,0,0,0,0,0,0,0,11
11,21,22,0,0,0,0,0,0,0,11
11,11,11,11,11,11,11,11,11,11,11
endlayer

layer
11,11,11,11,11,11,11,11,11,11,11
11,11,11,11,11,11,11,11,11,11,11
11,11,11,11,11,11,11,11,11,11,11
11,11,11,11,11,11,11,11,11,11,11
11,11,11,11,11,11,11,11,11,11,11
11,11,11,11,11,11,11,11,11,11,11
11,11,11,11,11,11,11,11,11,11,11
11,11,11,11,11,11,11,11,11,11,11
11,11,11,11,11,11,11,11,11,11,11
11,11,11,11,11,11,11,11,11,11,11
11,23,11,11,11,11,11,11,11,11,11
11,11,11,11,11,11,11,11,11,11,11
endlayer

