
# Created by Ruins mod version 17.1 Ingame Parser
# authoring Player: ST753M

weight=1
uniqueMinDistance=1000
random_height_offset=-4,4
embed_into_distance=6
acceptable_target_blocks=
unacceptable_target_blocks=flowing_water,water,flowing_lava,lava,ice,bedrock,netherrack,nether_brick,nether_brick_fence,soul_sand,quartz_ore,end_stone,obsidian,iron_bars,Natura:Cloud,slime_grass,slime_congealed,slime_dirt,clouds,natura:clouds,twilightforest:wispy_cloud,twilightforest:fluffy_cloud
dimensions=33,10,11
allowable_overhang=4
max_leveling=0
leveling_buffer=0
preserve_water=0
preserve_lava=0

biomesToSpawnIn=taiga,taiga_hills,mutated_redwood_taiga,mutated_redwood_taiga_hills,redwood_taiga,mutated_taiga,redwood_taiga_hills

=0,100,preserveBlock
rule1=0,100,minecraft:stone-6
rule2=0,100,minecraft:concrete-7
rule3=0,100,minecraft:stone_slab-0
rule4=0,100,minecraft:iron_bars-0
rule5=0,100,minecraft:stone_slab-8
rule6=0,100,minecraft:quartz_stairs-6
rule7=0,100,minecraft:quartz_stairs-7
rule8=0,100,minecraft:quartz_block-0
rule9=0,100,minecraft:quartz_stairs-5
rule10=0,100,minecraft:quartz_stairs-4
rule11=0,100,minecraft:stone_slab-7
rule12=0,100,minecraft:quartz_stairs-1
rule13=0,100,minecraft:quartz_stairs-3
rule14=0,100,minecraft:quartz_stairs-2
rule15=0,100,minecraft:redstone_block-0

layer
0,0,1,2,2,2,2,2,1,0,0
0,0,2,2,2,2,2,2,2,0,0
0,0,2,2,2,2,2,2,2,0,0
0,0,2,2,2,2,2,2,2,0,0
0,0,2,2,2,2,2,2,2,0,0
0,0,2,2,2,2,2,2,2,0,0
0,0,1,2,2,2,2,2,1,0,0
0,0,0,0,0,0,0,0,0,0,0
0,0,0,0,0,0,0,0,0,0,0
0,0,0,0,0,0,0,0,0,0,0
endlayer

layer
0,0,1,2,2,2,2,2,1,0,0
0,0,2,2,2,2,2,2,2,0,0
0,0,2,2,2,2,2,2,2,0,0
0,0,2,2,2,2,2,2,2,0,0
0,0,2,2,2,2,2,2,2,0,0
0,0,2,2,2,2,2,2,2,0,0
0,0,1,2,2,2,2,2,1,0,0
0,0,0,0,0,0,0,0,0,0,0
0,0,0,0,0,0,0,0,0,0,0
0,0,0,0,0,0,0,0,0,0,0
endlayer

layer
0,0,1,2,2,2,2,2,1,0,0
0,0,2,2,2,2,2,2,2,0,0
0,0,2,2,2,2,2,2,2,0,0
0,0,2,2,2,2,2,2,2,0,0
0,0,2,2,2,2,2,2,2,0,0
0,0,2,2,2,2,2,2,2,0,0
0,0,1,2,2,2,2,2,1,0,0
0,0,0,0,0,0,0,0,0,0,0
0,0,0,0,0,0,0,0,0,0,0
0,0,0,0,0,0,0,0,0,0,0
endlayer

layer
0,0,1,2,2,2,2,2,1,0,0
0,0,2,2,2,2,2,2,2,0,0
0,0,2,2,2,2,2,2,2,0,0
0,0,2,2,2,2,2,2,2,0,0
0,0,2,2,2,2,2,2,2,0,0
0,0,2,2,2,2,2,2,2,0,0
0,0,1,2,2,2,2,2,1,0,0
0,0,0,0,0,0,0,0,0,0,0
0,0,0,0,0,0,0,0,0,0,0
0,0,0,0,0,0,0,0,0,0,0
endlayer

layer
0,0,1,2,2,2,2,2,1,0,0
0,0,2,2,2,2,2,2,2,0,0
0,0,2,2,2,2,2,2,2,0,0
0,0,2,2,2,2,2,2,2,0,0
0,0,2,2,2,2,2,2,2,0,0
0,0,2,2,2,2,2,2,2,0,0
0,0,1,2,2,2,2,2,1,0,0
0,0,0,0,0,0,0,0,0,0,0
0,0,0,0,0,0,0,0,0,0,0
0,0,0,0,0,0,0,0,0,0,0
endlayer

layer
0,0,1,2,2,2,2,2,1,0,0
0,0,2,2,2,2,2,2,2,0,0
0,0,2,2,2,2,2,2,2,0,0
0,0,2,2,2,2,2,2,2,0,0
0,0,2,2,2,2,2,2,2,0,0
0,0,2,2,2,2,2,2,2,0,0
0,0,1,2,2,2,2,2,1,0,0
0,0,0,0,0,0,0,0,0,0,0
0,0,0,0,0,0,0,0,0,0,0
0,0,0,0,0,0,0,0,0,0,0
endlayer

layer
0,0,1,1,1,1,1,1,1,0,0
0,0,1,1,1,1,1,1,1,0,0
0,0,1,1,1,1,1,1,1,0,0
0,0,1,1,1,1,1,1,1,0,0
0,0,1,1,1,1,1,1,1,0,0
0,0,1,1,1,1,1,1,1,0,0
0,0,1,1,1,1,1,1,1,0,0
0,0,0,0,0,0,0,0,0,0,0
0,0,0,0,0,0,0,0,0,0,0
0,0,0,0,0,0,0,0,0,0,0
endlayer

layer
0,0,2,1,2,2,2,1,2,0,0
0,0,1,2,2,2,2,2,1,0,0
0,0,2,2,2,2,2,2,2,0,0
0,0,2,2,2,2,2,2,2,0,0
0,0,2,2,2,2,2,2,2,0,0
0,0,1,2,2,2,2,2,1,0,0
0,0,2,1,2,2,2,1,2,0,0
0,0,0,0,0,0,0,0,0,0,0
0,0,0,0,0,0,0,0,0,0,0
0,0,0,0,0,0,0,0,0,0,0
endlayer

layer
0,0,2,1,2,2,2,1,2,0,0
0,0,1,2,2,2,2,2,1,0,0
0,0,2,2,2,2,2,2,2,0,0
0,0,2,2,2,2,2,2,2,0,0
0,0,2,2,2,2,2,2,2,0,0
0,0,1,2,2,2,2,2,1,0,0
0,0,2,1,2,2,2,1,2,0,0
0,0,0,0,0,0,0,0,0,0,0
0,0,0,0,0,0,0,0,0,0,0
0,0,0,0,0,0,0,0,0,0,0
endlayer

layer
0,0,2,1,2,2,2,1,2,0,0
0,0,1,2,2,2,2,2,1,0,0
0,0,2,2,2,2,2,2,2,0,0
0,0,2,2,2,2,2,2,2,0,0
0,0,2,2,2,2,2,2,2,0,0
0,0,1,2,2,2,2,2,1,0,0
0,0,2,1,2,2,2,1,2,0,0
0,0,0,0,0,0,0,0,0,0,0
0,0,0,0,0,0,0,0,0,0,0
0,0,0,0,0,0,0,0,0,0,0
endlayer

layer
0,0,2,1,2,2,2,1,2,0,0
0,0,1,2,2,2,2,2,1,0,0
0,0,2,2,2,2,2,2,2,0,0
0,0,2,2,2,2,2,2,2,0,0
0,0,2,2,2,2,2,2,2,0,0
0,0,1,2,2,2,2,2,1,0,0
0,0,2,1,2,2,2,1,2,0,0
0,0,0,0,0,0,0,0,0,0,0
0,0,0,0,0,0,0,0,0,0,0
0,0,0,0,0,0,0,0,0,0,0
endlayer

layer
0,0,3,1,3,3,3,1,3,0,0
0,0,1,2,2,2,2,2,1,0,0
0,0,3,2,2,2,2,2,3,0,0
0,0,3,2,2,2,2,2,3,0,0
0,0,3,2,2,2,2,2,3,0,0
0,0,1,2,2,2,2,2,1,0,0
0,0,3,1,3,3,3,1,3,0,0
0,0,0,0,0,0,0,0,0,0,0
0,0,0,0,0,0,0,0,0,0,0
0,0,0,0,0,0,0,0,0,0,0
endlayer

layer
0,0,0,4,0,0,0,4,0,0,0
0,0,4,2,2,2,2,2,4,0,0
0,0,0,2,2,2,2,2,0,0,0
0,0,0,2,2,2,2,2,0,0,0
0,0,0,2,2,2,2,2,0,0,0
0,0,4,2,2,2,2,2,4,0,0
0,0,0,4,0,0,0,4,0,0,0
0,0,0,0,0,0,0,0,0,0,0
0,0,0,0,0,0,0,0,0,0,0
0,0,0,0,0,0,0,0,0,0,0
endlayer

layer
0,0,4,4,0,0,0,4,4,0,0
0,0,4,2,2,2,2,2,4,0,0
0,0,0,2,2,2,2,2,0,0,0
0,0,0,2,2,2,2,2,0,0,0
0,0,0,2,2,2,2,2,0,0,0
0,0,4,2,2,2,2,2,4,0,0
0,0,4,4,0,0,0,4,4,0,0
0,0,0,0,0,0,0,0,0,0,0
0,0,0,0,0,0,0,0,0,0,0
0,0,0,0,0,0,0,0,0,0,0
endlayer

layer
0,0,0,4,0,0,0,4,0,0,0
0,0,4,2,2,2,2,2,4,0,0
0,0,0,2,2,2,2,2,0,0,0
0,0,0,2,2,2,2,2,0,0,0
0,0,0,2,2,2,2,2,0,0,0
0,0,4,2,2,2,2,2,4,0,0
0,0,0,4,0,0,0,4,0,0,0
0,0,0,0,0,0,0,0,0,0,0
0,0,0,0,0,0,0,0,0,0,0
0,0,0,0,0,0,0,0,0,0,0
endlayer

layer
0,0,5,1,5,5,5,1,5,0,0
0,0,1,2,2,2,2,2,1,0,0
0,0,5,2,2,2,2,2,5,0,0
0,0,5,2,2,2,2,2,5,0,0
0,0,5,2,2,2,2,2,5,0,0
0,0,1,2,2,2,2,2,1,0,0
0,0,5,1,5,5,5,1,5,0,0
0,0,0,0,0,0,0,0,0,0,0
0,0,0,0,0,0,0,0,0,0,0
0,0,0,0,0,0,0,0,0,0,0
endlayer

layer
0,0,1,1,1,1,1,1,1,0,0
0,0,1,2,2,2,2,2,1,0,0
0,0,1,2,2,2,2,2,1,0,0
0,0,1,2,2,2,2,2,1,0,0
0,0,1,2,2,2,2,2,1,0,0
0,0,1,2,2,2,2,2,1,0,0
0,0,1,1,1,1,1,1,1,0,0
0,0,0,0,0,0,0,0,0,0,0
0,0,0,0,0,0,0,0,0,0,0
0,0,0,0,0,0,0,0,0,0,0
endlayer

layer
0,0,3,3,3,3,3,3,3,0,0
0,0,3,4,4,4,4,4,3,0,0
0,0,3,4,0,4,0,4,3,0,0
0,0,3,4,4,1,4,4,3,0,0
0,0,3,4,0,4,0,4,3,0,0
0,0,3,4,4,4,4,4,3,0,0
0,0,3,3,3,3,3,3,3,0,0
0,0,0,0,0,0,0,0,0,0,0
0,0,0,0,0,0,0,0,0,0,0
0,0,0,0,0,0,0,0,0,0,0
endlayer

layer
0,0,0,0,0,0,0,0,0,0,0
0,0,0,4,4,0,4,4,0,0,0
0,0,0,4,0,4,0,4,0,0,0
0,0,0,0,4,1,4,0,0,0,0
0,0,0,4,0,4,0,4,0,0,0
0,0,0,4,4,0,4,4,0,0,0
0,0,0,0,0,0,0,0,0,0,0
0,0,0,0,0,0,0,0,0,0,0
0,0,0,0,0,0,0,0,0,0,0
0,0,0,0,0,0,0,0,0,0,0
endlayer

layer
0,0,0,0,0,0,0,0,0,0,0
0,0,0,4,0,0,0,4,0,0,0
0,0,0,0,0,4,0,0,0,0,0
0,0,0,0,4,1,4,0,0,0,0
0,0,0,0,0,4,0,0,0,0,0
0,0,0,4,0,0,0,4,0,0,0
0,0,0,0,0,0,0,0,0,0,0
0,0,0,0,0,0,0,0,0,0,0
0,0,0,0,0,0,0,0,0,0,0
0,0,0,0,0,0,0,0,0,0,0
endlayer

layer
0,0,0,0,0,0,0,0,0,0,0
0,0,0,0,0,0,0,0,0,0,0
0,0,0,0,0,4,0,0,0,0,0
0,0,0,0,4,1,4,0,0,0,0
0,0,0,0,0,4,0,0,0,0,0
0,0,0,0,0,0,0,0,0,0,0
0,0,0,0,0,0,0,0,0,0,0
0,0,0,0,0,0,0,0,0,0,0
0,0,0,0,0,0,0,0,0,0,0
0,0,0,0,0,0,0,0,0,0,0
endlayer

layer
0,0,0,0,0,0,0,0,0,0,0
0,0,0,0,0,4,0,0,0,0,0
0,0,0,0,0,4,0,0,0,0,0
0,0,0,4,4,1,4,4,0,0,0
0,0,0,0,0,4,0,0,0,0,0
0,0,0,0,0,4,0,0,0,0,0
0,0,0,0,0,0,0,0,0,0,0
0,0,0,0,0,0,0,0,0,0,0
0,0,0,0,0,0,0,0,0,0,0
0,0,0,0,0,0,0,0,0,0,0
endlayer

layer
0,0,0,0,0,0,0,0,0,0,0
0,0,0,0,0,4,0,0,0,0,0
0,0,0,0,5,5,5,0,0,0,0
0,0,0,4,5,1,5,4,0,0,0
0,0,0,0,5,5,5,0,0,0,0
0,0,0,0,0,4,0,0,0,0,0
0,0,0,0,0,0,0,0,0,0,0
0,0,0,0,0,0,0,0,0,0,0
0,0,0,0,0,0,0,0,0,0,0
0,0,0,0,0,0,0,0,0,0,0
endlayer

layer
0,0,0,0,0,0,0,0,0,0,0
0,0,0,0,0,4,0,0,0,0,0
0,0,0,0,2,2,2,0,0,0,0
0,0,0,4,2,2,2,4,0,0,0
0,0,0,0,2,2,2,0,0,0,0
0,0,0,0,0,4,0,0,0,0,0
0,0,0,0,0,0,0,0,0,0,0
0,0,0,0,0,0,0,0,0,0,0
0,0,0,0,0,0,0,0,0,0,0
0,0,0,0,0,0,0,0,0,0,0
endlayer

layer
0,0,0,0,0,0,0,0,0,0,0
0,0,0,0,0,0,0,0,0,0,0
0,0,0,0,2,2,2,0,0,0,0
0,0,0,0,2,2,2,0,0,0,0
0,0,0,7,2,2,2,6,0,0,0
0,0,0,8,8,8,8,8,0,0,0
0,0,0,7,8,8,8,6,0,0,0
0,0,0,0,8,8,8,0,0,0,0
0,0,0,0,0,9,0,0,0,0,0
0,0,0,0,0,0,0,0,0,0,0
endlayer

layer
0,0,0,0,0,0,0,0,0,0,0
0,0,0,0,0,10,0,0,0,0,0
0,0,0,10,8,8,8,10,0,0,0
0,0,7,8,11,1,11,8,6,0,0
0,0,8,11,0,0,0,11,8,0,0
0,0,8,0,0,0,0,0,8,0,0
0,0,8,11,0,0,0,11,8,0,0
0,0,7,8,11,0,11,8,6,0,0
0,0,0,8,8,8,8,8,0,0,0
0,0,0,0,9,8,9,0,0,0,0
endlayer

layer
0,0,0,0,0,0,0,0,0,0,0
0,0,0,10,8,8,8,10,0,0,0
0,0,8,11,0,0,0,11,8,0,0
0,7,11,0,0,1,0,0,11,6,0
0,8,0,0,0,4,0,0,0,8,0
0,8,0,0,0,0,0,0,0,8,0
0,8,0,0,0,0,0,0,0,8,0
0,7,11,0,0,0,0,0,11,6,0
0,0,11,11,0,0,0,11,11,0,0
0,0,0,0,0,0,0,0,0,0,0
endlayer

layer
0,0,0,0,10,8,10,0,0,0,0
0,0,10,12,0,0,0,12,10,0,0
0,7,0,0,0,0,0,0,0,6,0
0,14,0,0,0,1,0,0,0,13,0
7,0,0,0,0,1,0,0,0,0,6
8,0,0,0,0,0,0,0,0,0,8
11,0,0,0,0,0,0,0,0,0,11
0,0,0,0,0,0,0,0,0,0,0
0,0,0,0,0,0,0,0,0,0,0
0,0,0,0,0,0,0,0,0,0,0
endlayer

layer
0,0,0,10,8,8,8,10,0,0,0
0,0,8,0,0,0,0,0,8,0,0
0,8,0,0,0,0,0,0,0,8,0
8,0,0,0,0,4,0,0,0,0,8
11,0,0,0,0,1,0,0,0,0,11
0,0,0,0,0,4,0,0,0,0,0
0,0,0,0,0,0,0,0,0,0,0
0,0,0,0,0,0,0,0,0,0,0
0,0,0,0,0,0,0,0,0,0,0
0,0,0,0,0,0,0,0,0,0,0
endlayer

layer
0,0,0,8,8,8,8,8,0,0,0
0,0,8,0,0,0,0,0,8,0,0
0,11,0,0,0,0,0,0,0,11,0
0,0,0,0,0,0,0,0,0,0,0
0,0,0,0,0,1,0,0,0,0,0
0,0,0,0,0,1,0,0,0,0,0
0,0,0,0,0,0,0,0,0,0,0
0,0,0,0,0,0,0,0,0,0,0
0,0,0,0,0,0,0,0,0,0,0
0,0,0,0,0,0,0,0,0,0,0
endlayer

layer
0,0,0,11,8,8,8,11,0,0,0
0,0,0,0,0,0,0,0,0,0,0
0,0,0,0,0,0,0,0,0,0,0
0,0,0,0,0,0,0,0,0,0,0
0,0,0,0,0,4,0,0,0,0,0
0,0,0,0,0,1,0,0,0,0,0
0,0,0,0,0,4,0,0,0,0,0
0,0,0,0,0,0,0,0,0,0,0
0,0,0,0,0,0,0,0,0,0,0
0,0,0,0,0,0,0,0,0,0,0
endlayer

layer
0,0,0,0,0,0,0,0,0,0,0
0,0,0,0,0,0,0,0,0,0,0
0,0,0,0,0,0,0,0,0,0,0
0,0,0,0,0,0,0,0,0,0,0
0,0,0,0,0,0,0,0,0,0,0
0,0,0,0,0,1,0,0,0,0,0
0,0,0,0,0,1,0,0,0,0,0
0,0,0,0,0,0,0,0,0,0,0
0,0,0,0,0,0,0,0,0,0,0
0,0,0,0,0,0,0,0,0,0,0
endlayer

layer
0,0,0,0,0,0,0,0,0,0,0
0,0,0,0,0,0,0,0,0,0,0
0,0,0,0,0,0,0,0,0,0,0
0,0,0,0,0,0,0,0,0,0,0
0,0,0,0,0,0,0,0,0,0,0
0,0,0,0,0,0,0,0,0,0,0
0,0,0,0,0,15,0,0,0,0,0
0,0,0,0,0,0,0,0,0,0,0
0,0,0,0,0,0,0,0,0,0,0
0,0,0,0,0,0,0,0,0,0,0
endlayer

