
# Created by Ruins mod version 17.1 Ingame Parser
# authoring Player: ST753M

weight=1
uniqueMinDistance=1000
spawnMinDistance=400
embed_into_distance=6
acceptable_target_blocks=
unacceptable_target_blocks=flowing_water,water,flowing_lava,lava,ice,bedrock,netherrack,nether_brick,nether_brick_fence,soul_sand,quartz_ore,end_stone,obsidian,iron_bars,Natura:Cloud,slime_grass,slime_congealed,slime_dirt,clouds,natura:clouds,twilightforest:wispy_cloud,twilightforest:fluffy_cloud
dimensions=13,21,13
allowable_overhang=6
max_leveling=0
leveling_buffer=0
preserve_water=0
preserve_lava=0
preventRotation=1

adjoining_template=ST753M/753_Lab_Sidemachine_CB;24;99;6;20
adjoining_template=ST753M/753_Lab_Sidemachine_CB;25;99;-11;20
adjoining_template=ST753M/753_Lab_Sidemachine_CB;-26;99;-7;20
adjoining_template=ST753M/753_Lab_Sidemachine_CB;-24;99;12;20

biomesToSpawnIn=taiga,taiga_hills,mutated_redwood_taiga,mutated_redwood_taiga_hills,redwood_taiga,mutated_taiga,redwood_taiga_hills,dead_swamp,coralium_infested_swamp,bog,dead_forest,shield,extreme_hills,smaller_extreme_hills,mutated_extreme_hills,mutated_extreme_hills_with_trees,extreme_hills_with_trees,rocky_plateau,steppe,wasteland,darklands,darklands_forest,darklands_hills,darklands_mountains,darklands_plains,ominous_woods,eerie,swamp_defiled,desert_defiled,plains_defiled,ice_plains_defiled,hills_defiled,forest_tenebra,forest_vilespine

=0,100,air
rule1=0,100,preserveBlock
rule2=0,100,minecraft:concrete-7
rule3=0,100,minecraft:stone-6,minecraft:stone-6,minecraft:stone-6,minecraft:stone-6,minecraft:stone-6,minecraft:gravel-0,minecraft:stone-0
rule4=0,100,minecraft:obsidian-0
rule5=0,100,minecraft:netherrack-0
rule6=0,100,minecraft:double_stone_slab-0
rule7=0,100,minecraft:stonebrick-0
rule8=0,100,minecraft:portal-2
rule9=0,100,minecraft:fire-15
rule10=0,100,minecraft:gravel-0
rule11=0,100,minecraft:iron_bars-0
rule12=0,100,minecraft:stone_slab-0
rule13=0,100,minecraft:stone_brick_stairs-6
rule14=0,100,minecraft:stone_brick_stairs-3
rule15=0,100,minecraft:stone_slab-8

layer
1,1,1,2,1,1,1,1,1,2,1,1,1
1,2,2,2,2,2,2,2,2,2,2,2,1
1,2,3,3,3,3,3,3,3,3,3,2,1
2,2,3,3,4,4,4,4,4,3,3,2,2
1,2,3,3,5,5,4,4,4,3,3,2,1
1,2,3,3,5,5,5,5,5,3,3,2,1
1,2,3,5,5,5,5,5,5,5,3,2,1
1,5,3,5,3,3,5,5,5,5,3,2,1
1,2,5,3,3,5,5,5,3,5,5,2,1
1,2,3,3,5,5,3,5,3,3,5,5,1
1,2,3,5,5,5,3,3,5,3,3,5,1
1,2,5,5,3,5,3,3,3,3,3,5,1
1,5,5,3,3,5,5,3,3,3,3,2,1
1,5,3,3,3,3,5,5,3,3,3,2,1
1,2,3,3,3,3,5,3,5,3,3,2,1
1,2,3,5,3,5,5,3,3,3,3,2,1
1,2,3,3,5,5,3,3,3,3,3,2,1
2,2,3,3,3,3,5,5,3,3,3,2,2
1,2,3,3,3,3,3,3,3,3,3,2,1
1,2,2,2,2,2,2,2,2,2,2,2,1
1,1,1,2,1,1,1,1,1,2,1,1,1
endlayer

layer
1,1,1,2,1,1,1,1,1,2,1,1,1
1,6,7,7,5,5,5,5,5,7,7,6,1
1,7,7,7,4,4,4,4,4,7,7,7,1
2,7,7,4,8,8,8,8,8,4,7,7,2
1,7,7,5,0,0,0,0,0,5,7,7,1
1,7,5,5,0,0,0,0,0,5,5,7,1
1,7,0,0,9,0,0,0,9,0,5,7,1
1,7,0,9,0,0,0,0,0,0,0,7,1
1,5,9,0,0,0,0,0,0,0,9,7,1
1,7,0,0,0,0,0,0,10,0,0,5,1
1,7,0,0,0,0,0,10,9,0,0,5,1
1,7,9,0,0,0,10,10,10,0,0,7,1
1,5,0,0,0,0,0,10,10,0,10,5,1
1,7,11,0,0,0,0,10,10,0,0,7,1
1,7,11,0,0,0,10,10,9,0,0,7,1
1,7,0,0,0,0,9,0,0,0,0,7,1
1,7,0,0,0,0,0,0,0,0,12,7,1
2,7,0,0,0,0,0,9,0,12,6,7,2
1,7,11,0,14,13,0,0,5,6,3,7,1
1,6,7,7,7,7,7,7,7,7,7,6,1
1,1,1,2,1,1,1,1,1,2,1,1,1
endlayer

layer
1,1,1,2,1,1,1,1,1,2,1,1,1
1,6,7,7,5,5,5,5,5,7,7,6,1
1,7,7,7,4,4,4,4,4,7,7,7,1
2,7,7,4,8,8,8,8,8,4,7,7,2
1,7,7,5,0,0,0,0,0,4,7,7,1
1,7,5,9,0,0,0,0,0,9,5,7,1
1,7,0,0,0,0,0,0,0,0,0,7,1
1,7,0,0,0,0,0,0,0,0,0,7,1
1,7,0,0,0,0,0,0,0,0,0,7,1
1,5,0,0,0,0,0,0,0,0,0,7,1
1,7,0,0,0,0,0,10,0,0,0,5,1
1,7,0,0,0,0,0,10,0,0,0,5,1
1,5,0,0,0,0,0,10,10,0,0,7,1
1,5,11,0,0,0,0,0,0,0,0,7,1
1,7,11,0,0,0,0,10,0,0,0,5,1
1,7,0,0,0,0,0,0,0,0,0,7,1
1,7,0,0,0,0,0,0,0,0,11,7,1
2,7,0,0,0,0,0,0,0,0,6,7,2
1,7,11,0,0,14,13,0,11,6,3,7,1
1,6,7,7,7,7,7,7,7,7,7,6,1
1,1,1,2,1,1,1,1,1,2,1,1,1
endlayer

layer
1,1,1,2,1,1,1,1,1,2,1,1,1
1,6,7,7,5,5,5,5,5,7,7,6,1
1,7,7,7,4,4,4,4,4,7,7,7,1
2,7,7,4,8,8,8,8,8,4,7,7,2
1,7,7,4,0,0,0,0,0,4,7,7,1
1,7,5,0,0,0,0,0,0,5,5,7,1
1,7,5,0,0,0,0,0,0,0,5,5,1
1,7,5,0,0,0,0,0,0,0,0,5,1
1,7,0,0,0,0,0,0,0,0,0,7,1
1,7,0,0,0,0,0,0,0,0,0,7,1
1,7,0,0,0,0,0,0,0,0,0,7,1
1,5,0,0,0,0,0,10,0,0,0,5,1
1,7,0,0,0,0,0,0,10,0,0,5,1
1,5,11,0,0,0,0,0,0,0,0,5,1
1,5,11,0,0,0,0,0,0,0,0,7,1
1,7,0,0,0,0,0,0,0,0,0,7,1
1,7,0,0,0,0,0,0,0,0,15,7,1
2,7,0,0,0,0,0,0,0,15,6,7,2
1,7,11,0,0,0,14,13,15,6,3,7,1
1,6,7,7,7,7,7,7,7,7,7,6,1
1,1,1,2,1,1,1,1,1,2,1,1,1
endlayer

layer
1,1,1,2,2,2,2,2,2,2,1,1,1
1,6,7,7,7,7,7,7,7,7,7,6,1
1,7,7,7,7,7,7,7,7,7,7,7,1
2,7,7,4,4,4,4,4,4,4,7,7,2
1,7,2,2,4,4,5,5,4,2,2,7,1
1,7,2,5,5,5,5,5,5,2,2,7,1
1,7,5,5,5,0,0,0,5,5,2,7,1
1,7,0,0,5,0,0,0,0,5,5,7,1
1,7,0,0,0,0,0,0,0,0,5,7,1
1,7,2,0,0,0,0,0,0,0,5,7,1
1,7,2,0,0,0,0,0,0,0,2,7,1
1,7,2,0,0,0,0,10,0,0,2,7,1
1,7,2,0,0,0,0,0,0,0,2,7,1
1,7,2,0,0,0,0,0,0,0,2,7,1
1,7,2,0,0,0,0,0,0,0,2,7,1
1,7,2,0,0,0,0,0,0,2,2,7,1
1,7,2,2,0,0,0,0,2,2,2,7,1
2,7,3,2,2,2,2,2,2,2,2,7,2
1,7,3,13,0,0,0,14,2,2,2,7,1
1,6,7,7,7,7,7,7,7,7,7,6,1
1,1,1,2,1,1,1,1,1,2,1,1,1
endlayer

layer
1,1,1,10,10,10,6,5,6,2,1,1,1
1,6,3,3,2,2,5,5,3,3,3,6,1
1,3,5,5,3,5,5,3,3,3,3,3,1
2,3,3,3,5,5,5,5,3,3,3,3,2
1,3,3,3,5,5,5,5,5,3,3,3,1
1,3,3,5,5,5,5,5,5,5,3,3,1
1,3,5,5,5,5,5,0,5,5,3,3,1
1,3,5,5,0,0,0,0,0,5,5,3,1
1,3,5,5,0,0,0,0,5,5,5,3,1
1,3,5,0,0,0,0,0,0,5,5,3,1
1,3,3,0,0,0,0,0,0,5,3,3,1
1,3,3,0,0,0,0,0,0,5,3,3,1
1,3,3,3,0,0,0,0,3,3,5,3,1
1,3,3,3,0,0,0,0,3,3,5,3,1
1,3,3,3,3,3,3,3,3,5,3,3,1
1,3,3,3,3,3,3,3,3,3,3,3,1
1,3,3,3,3,3,3,3,3,3,3,3,1
2,3,3,3,3,3,3,3,3,3,3,3,2
1,3,3,3,0,0,0,0,14,3,3,3,1
1,6,3,3,3,3,3,3,3,3,3,6,1
1,1,1,2,1,1,1,1,1,2,1,1,1
endlayer

layer
1,1,1,10,10,1,1,1,1,2,1,1,1
1,6,7,7,2,1,1,1,1,7,7,6,1
1,7,9,1,6,1,1,1,6,11,1,7,1
1,7,0,1,1,1,1,1,1,1,1,7,1
1,7,0,0,1,1,1,1,1,0,10,7,1
1,1,1,9,1,1,1,1,1,9,10,7,1
1,1,1,1,1,0,0,0,1,1,1,1,1
1,10,1,1,0,0,0,0,0,1,9,7,1
1,7,1,1,0,0,0,0,9,0,0,7,1
1,7,1,0,0,0,0,0,0,9,0,7,1
1,7,1,0,0,0,0,0,0,1,10,7,1
1,7,1,0,0,0,0,0,0,1,1,7,1
1,7,1,1,0,0,0,0,1,10,1,7,1
1,7,1,1,0,0,0,0,10,0,9,7,1
1,7,10,1,1,10,1,1,10,0,0,7,1
1,7,10,1,1,0,10,10,10,0,0,7,1
1,7,10,10,10,0,0,0,0,0,0,7,1
2,7,0,10,0,0,0,0,0,0,0,7,2
1,7,0,0,0,0,0,0,0,0,0,7,1
1,6,7,7,3,7,7,7,3,7,7,6,1
1,1,1,2,1,1,1,1,1,2,1,1,1
endlayer

layer
1,1,1,10,1,1,1,1,1,2,1,1,1
1,6,1,1,1,1,1,1,1,7,7,6,1
1,1,1,1,6,1,1,1,1,11,1,7,1
1,7,1,1,1,1,1,1,1,1,1,7,1
1,1,1,1,1,1,1,1,1,1,10,1,1
1,1,1,1,1,1,1,1,1,1,1,7,1
1,1,1,1,1,0,0,0,1,1,1,1,1
1,1,1,1,0,0,0,0,0,1,1,1,1
1,7,1,1,0,0,0,0,0,1,1,1,1
1,7,1,1,0,0,0,0,0,1,1,7,1
1,7,1,1,0,0,0,0,0,1,10,7,1
1,7,1,1,0,0,0,0,0,1,0,7,1
1,7,1,1,0,0,0,0,1,1,0,7,1
1,7,1,1,0,0,0,0,1,1,0,7,1
1,7,10,1,1,1,1,1,10,1,0,7,1
1,7,10,1,1,1,1,10,0,1,0,7,1
1,7,0,10,1,1,1,0,0,1,0,7,1
2,7,0,0,1,1,1,0,0,1,0,7,2
1,7,0,0,1,1,1,0,0,1,0,7,1
1,6,7,7,3,7,7,7,3,7,7,6,1
1,1,1,2,1,1,1,1,1,2,1,1,1
endlayer

layer
1,1,1,1,1,1,1,1,1,2,1,1,1
1,1,1,1,1,1,1,1,1,7,1,6,1
1,1,1,1,1,1,1,1,1,1,1,7,1
1,1,1,1,1,1,1,1,1,1,1,1,1
1,1,1,1,1,1,1,1,1,1,1,1,1
1,1,1,1,1,1,1,1,1,1,1,1,1
1,1,1,1,1,0,0,0,1,1,1,1,1
1,1,1,1,0,0,0,0,0,1,1,1,1
1,1,1,1,0,0,0,0,0,1,1,1,1
1,1,1,1,0,0,0,0,0,1,1,1,1
1,7,1,1,0,0,0,0,0,1,1,7,1
1,1,1,1,0,0,0,0,0,1,1,11,1
1,1,1,1,0,0,0,0,1,1,1,11,1
1,7,1,1,0,0,0,0,1,1,1,7,1
1,11,10,1,1,1,1,1,1,1,1,11,1
1,11,0,1,1,1,1,1,1,1,1,11,1
1,7,0,10,1,1,1,1,1,1,1,7,1
2,7,0,0,1,1,1,1,1,1,1,7,2
1,7,0,0,1,1,1,1,1,1,1,7,1
1,6,7,7,3,0,0,0,3,7,7,6,1
1,1,1,2,1,1,1,1,1,2,1,1,1
endlayer

layer
1,1,1,1,1,1,1,1,1,1,1,1,1
1,1,1,1,1,1,1,1,1,7,1,12,1
1,1,1,1,1,1,1,1,1,1,1,1,1
1,1,1,1,1,1,1,1,1,1,1,1,1
1,1,1,1,1,1,1,1,1,1,1,1,1
1,1,1,1,1,1,1,1,1,1,1,1,1
1,1,1,1,1,0,0,0,1,1,1,1,1
1,1,1,1,0,0,0,0,0,1,1,1,1
1,1,1,1,0,0,0,0,0,1,1,1,1
1,1,1,1,0,0,0,0,0,1,1,1,1
1,1,1,1,0,0,0,0,0,1,1,12,1
1,1,1,1,0,0,0,0,0,1,1,7,1
1,1,1,1,0,0,0,0,1,1,1,7,15
15,7,1,1,0,0,0,0,1,1,1,7,15
15,7,1,1,1,1,1,1,1,1,1,7,15
15,7,1,1,1,1,1,1,1,1,1,7,15
15,7,1,1,1,1,1,1,1,1,1,7,15
2,7,1,1,1,1,1,1,1,1,1,7,2
15,7,1,1,1,1,1,1,1,1,1,7,15
15,6,7,7,3,7,7,7,3,7,7,6,15
15,15,15,2,15,15,15,15,15,2,15,15,15
endlayer

layer
1,1,1,1,1,1,1,1,1,1,1,1,1
1,1,1,1,1,1,1,1,1,1,1,1,1
1,1,1,1,1,1,1,1,1,1,1,1,1
1,1,1,1,1,1,1,1,1,1,1,1,1
1,1,1,1,1,1,1,1,1,1,1,1,1
1,1,1,1,1,1,1,1,1,1,1,1,1
1,1,1,1,1,0,0,0,1,1,1,1,1
1,1,1,1,0,0,0,0,0,1,1,1,1
1,1,1,1,0,0,0,0,0,1,1,1,1
1,1,1,1,0,0,0,0,0,1,1,1,1
1,1,1,1,0,0,0,0,0,1,1,1,1
1,1,1,1,0,0,0,0,0,1,1,3,1
1,1,1,1,0,0,0,0,1,1,1,3,3
1,1,1,1,0,0,0,0,1,1,3,3,3
1,1,1,1,1,1,1,1,1,1,0,3,3
3,1,3,1,1,1,1,3,1,1,3,3,3
3,3,3,1,3,1,1,0,1,3,3,3,3
2,3,3,3,3,3,1,3,3,3,3,3,2
3,3,3,3,3,3,1,3,3,3,3,3,3
3,3,3,3,3,3,3,3,3,3,3,3,3
15,3,3,2,3,3,3,3,3,2,3,3,15
endlayer

layer
1,1,1,1,1,1,1,1,1,1,1,1,1
1,1,1,1,1,1,1,1,1,1,1,1,1
1,1,1,1,1,1,1,1,1,1,1,1,1
1,1,1,1,1,1,1,1,1,1,1,1,1
1,1,1,1,1,1,1,1,1,1,1,1,1
1,1,1,1,1,1,1,1,1,1,1,1,1
1,1,1,1,1,0,0,0,1,1,1,1,1
1,1,1,1,0,0,0,0,0,1,1,1,1
1,1,1,1,0,0,0,0,0,1,1,1,1
1,1,1,1,0,0,0,0,0,1,1,1,1
1,1,1,1,0,0,0,0,0,1,1,1,1
1,1,1,1,0,0,0,0,0,1,1,1,1
1,1,1,1,0,0,0,0,1,1,1,1,1
1,1,1,1,0,0,0,0,1,1,1,1,1
1,1,1,1,1,1,1,1,1,1,1,1,12
1,1,1,1,1,1,1,1,1,1,1,1,12
12,1,1,1,1,1,1,1,1,1,1,1,12
2,11,11,11,1,1,1,1,1,11,11,11,2
3,3,3,11,1,1,1,1,1,11,3,3,3
3,3,3,11,1,1,1,1,1,11,3,3,3
12,3,3,2,12,12,12,12,12,2,3,3,12
endlayer

layer
1,1,1,1,1,1,1,1,1,1,1,1,1
1,1,1,1,1,1,1,1,1,1,1,1,1
1,1,1,1,1,1,1,1,1,1,1,1,1
1,1,1,1,1,1,1,1,1,1,1,1,1
1,1,1,1,1,1,1,1,1,1,1,1,1
1,1,1,1,1,1,1,1,1,1,1,1,1
1,1,1,1,1,0,0,0,1,1,1,1,1
1,1,1,1,0,0,0,0,0,1,1,1,1
1,1,1,1,0,0,0,0,0,1,1,1,1
1,1,1,1,0,0,0,0,0,1,1,1,1
1,1,1,1,0,0,0,0,0,1,1,1,1
1,1,1,1,0,0,0,0,0,1,1,1,1
1,1,1,1,0,0,0,0,1,1,1,1,1
1,1,1,1,0,0,0,0,1,1,1,1,1
1,1,1,1,1,1,1,1,1,1,1,1,1
1,1,1,1,1,1,1,1,1,1,1,1,1
1,1,1,1,1,1,1,1,1,1,1,1,1
2,12,12,12,1,1,1,1,1,12,12,12,2
12,1,1,12,1,1,1,1,1,12,1,1,12
12,1,1,12,1,1,1,1,1,12,1,1,12
12,12,12,2,1,1,1,1,1,2,12,12,12
endlayer

