
# Created by Ruins mod version 17.1 Ingame Parser
# authoring Player: ST753M

weight=1
uniqueMinDistance=2000
spawnMinDistance=2000
embed_into_distance=8
acceptable_target_blocks=grass,dirt,podzol,mycelium,stone,biomesoplenty:grass,biomesoplenty:dirt,sand,sandstone,gravel,terracotta,stained_terracotta,hardened_clay,hardened_sand,mud,coarse_dirt,clay,red_sand,sand,sandstone
unacceptable_target_blocks=flowing_water,water,flowing_lava,lava
dimensions=28,21,11
allowable_overhang=8
max_leveling=2
leveling_buffer=0
preserve_water=0
preserve_lava=0

adjoining_template=ST753M/753_Lab_Sidemachine_CB;24;99;6;30
adjoining_template=ST753M/753_Lab_Sidemachine_CB;25;99;-11;30
adjoining_template=ST753M/753_Lab_Sidemachine_CB;-26;99;-7;30
adjoining_template=ST753M/753_Lab_Sidemachine_CB;-24;99;12;30
adjoining_template=taiga/753_Lab_Dish;12;99;26;30
adjoining_template=taiga/753_Lab_Dish;-8;99;27;30
adjoining_template=taiga/753_Lab_Dish;-10;99;-25;30
adjoining_template=taiga/753_Lab_Dish;9;99;-24;30

biomesToSpawnIn=taiga,taiga_hills,mutated_redwood_taiga,mutated_redwood_taiga_hills,redwood_taiga,mutated_taiga,redwood_taiga_hills,mesa,mesa_clear_rock

=0,100,air
rule1=0,100,minecraft:double_stone_slab-0
rule2=0,100,minecraft:stone-6
rule3=0,100,minecraft:stonebrick-0
rule4=0,100,minecraft:stone_slab-8
rule5=0,100,minecraft:stone_slab-0
rule6=0,100,minecraft:stained_glass-8
rule7=0,100,minecraft:water-0
rule8=0,100,CommandBlock:RUINSTRIGGER /summon iceandfire:siren ~ ~1 ~:@-1
rule9=0,100,minecraft:iron_door-0
rule10=0,100,minecraft:iron_bars-0
rule11=0,100,Skull:0:2-1
rule12=0,100,minecraft:lever-2
rule13=0,100,minecraft:iron_door-8
rule14=0,100,minecraft:end_rod-3
rule15=0,100,minecraft:end_rod-2
rule16=0,100,minecraft:noteblock-0
rule17=0,100,minecraft:spruce_stairs-0
rule18=0,100,iceandfire:lectern-2
rule19=0,100,CommandBlock:RUINSTRIGGER /summon cave_spider ~ ~1 ~ {PersistenceRequired:1}:@-1
rule20=0,100,teBlock;minecraft:flower_pot;{Item:"minecraft:yellow_flower",x:1181,y:96,z:47,Data:0,id:"minecraft:flower_pot"}-0
rule21=0,100,minecraft:stonebrick-3
rule22=0,100,minecraft:iron_door-9
rule23=0,100,minecraft:lever-1
rule24=0,100,minecraft:web-0
rule25=0,40,CommandBlock:RUINSTRIGGER /summon villager_golem ~ ~1 ~:@-1
rule26=0,100,minecraft:concrete-7
rule27=0,100,IInventory;minecraft:chest;iceandfire:manuscript#3#0#2+minecraft:book#1#0#5+iceandfire:bestiary#{Pages:[I;0]}#0#9+iceandfire:manuscript#2#0#17+minecraft:written_book#{title:"Captured",author:"Scientist",pages:["'It took a great deal of work, but we have finally aquired a specimen.'","'The creature appears to be unable to be reasoned with, despite its visual similarity to civilized beings.'","'All researchers are to wear suitable ear protection when handling specimen.'"]}#0#0#19+iceandfire:earplugs#1#0#22-4
rule28=0,100,minecraft:redstone_block-0
rule29=0,100,minecraft:cobblestone_wall-0
rule30=0,100,minecraft:end_rod-1

layer
1,2,2,2,2,2,2,2,2,2,1
2,2,2,2,2,2,2,2,2,2,2
2,2,2,2,2,2,2,2,2,2,2
2,2,2,2,2,2,2,2,2,2,2
2,2,2,2,2,2,2,2,2,2,2
2,2,2,2,2,2,2,2,2,2,2
2,2,2,2,2,2,2,2,2,2,2
2,2,2,2,2,2,2,2,2,2,2
2,2,2,2,2,2,2,2,2,2,2
2,2,2,2,2,2,2,2,2,2,2
2,2,2,2,2,2,2,2,2,2,2
2,2,2,2,2,2,2,2,2,2,2
2,2,2,2,2,2,2,2,2,2,2
2,2,2,2,2,2,2,2,2,2,2
2,2,2,2,2,2,2,2,2,2,2
2,2,2,2,2,2,2,2,2,2,2
2,2,2,2,2,2,2,2,2,2,2
2,2,2,2,2,2,2,2,2,2,2
2,2,2,2,2,2,2,2,2,2,2
2,2,2,2,2,2,2,2,2,2,2
1,2,2,2,2,2,2,2,2,2,1
endlayer

layer
1,3,3,3,3,3,3,3,3,3,1
3,0,0,0,0,0,0,0,0,0,3
3,0,1,4,1,0,0,0,0,0,3
3,0,4,4,4,0,0,0,0,0,3
3,0,1,4,1,0,0,0,0,4,3
3,0,0,0,0,0,0,0,0,1,3
3,0,0,0,0,0,0,0,0,5,3
3,5,0,0,0,0,0,0,0,0,3
3,1,0,0,0,0,0,0,0,0,3
3,4,0,0,0,0,0,0,0,0,3
3,0,0,0,0,0,0,0,0,0,3
3,0,0,0,0,0,0,0,0,0,3
3,0,0,0,0,0,0,0,0,0,3
3,0,0,0,0,0,0,0,0,0,3
3,6,6,6,6,6,6,6,6,6,3
3,7,7,7,7,7,7,7,7,7,3
3,7,7,7,7,7,7,7,7,7,3
3,7,7,7,7,7,7,7,7,7,3
3,7,7,7,7,7,7,7,7,7,3
3,7,7,7,7,7,7,7,7,7,3
1,3,3,3,3,3,3,3,3,3,1
endlayer

layer
1,3,3,3,3,3,3,3,3,3,1
3,0,6,6,6,0,0,0,0,0,3
3,6,7,7,7,6,0,0,0,4,3
3,6,7,7,7,6,0,0,0,1,3
3,6,7,7,7,6,0,0,0,5,3
3,0,6,6,6,0,0,0,0,0,3
3,0,0,0,0,0,0,0,0,0,3
3,0,0,0,0,0,0,0,0,0,3
3,0,0,0,0,0,0,0,0,0,3
3,5,0,0,0,0,0,0,0,0,3
3,1,0,0,0,0,0,0,0,0,3
3,4,0,0,0,0,0,0,0,0,3
3,0,0,0,0,0,0,0,0,0,3
3,0,0,0,0,0,0,0,0,0,3
3,6,6,6,6,6,6,6,6,6,3
3,7,7,7,7,7,7,7,7,7,3
3,7,7,7,7,7,7,7,7,7,3
3,7,7,7,7,7,7,7,7,7,3
3,7,7,7,7,7,7,7,7,7,3
3,7,7,7,7,7,7,7,7,7,3
1,3,3,3,3,3,3,3,3,3,1
endlayer

layer
1,3,3,3,3,3,3,3,3,3,1
3,0,6,6,6,0,0,0,4,1,3
3,6,7,7,7,6,0,0,0,5,3
3,6,7,7,7,6,0,0,0,0,3
3,6,7,7,7,6,0,0,0,0,3
3,0,6,6,6,0,0,0,0,0,3
3,0,0,0,0,0,0,0,0,0,3
3,0,0,0,0,0,0,0,0,0,3
3,0,0,0,0,0,0,0,0,0,3
3,0,0,0,0,0,0,0,0,0,3
3,0,0,0,0,0,0,0,0,0,3
3,5,0,0,0,0,0,0,0,0,3
3,1,4,4,4,4,4,4,4,4,3
3,4,4,4,4,4,4,4,4,4,3
3,1,1,1,1,1,1,1,1,1,3
3,7,7,7,7,7,7,7,7,7,3
3,7,7,7,7,7,7,7,7,7,3
3,7,7,7,7,8,7,7,7,7,3
3,7,7,7,7,7,7,7,7,7,3
3,7,7,7,7,7,7,7,7,7,3
1,3,3,3,3,3,3,3,3,3,1
endlayer

layer
1,3,3,3,3,3,3,3,3,3,1
3,0,5,5,5,0,4,1,5,0,3
3,5,0,0,0,5,0,0,0,0,3
3,5,0,0,0,5,0,0,0,0,3
3,5,0,0,0,5,0,0,0,0,3
3,0,5,5,5,0,0,0,0,0,3
3,0,0,0,0,0,0,0,0,0,3
3,0,0,0,0,0,0,0,0,0,3
3,0,0,0,0,0,0,0,0,0,3
3,0,0,0,0,0,0,0,0,0,3
3,0,0,0,0,0,0,0,0,0,3
3,0,0,0,0,0,0,0,0,0,3
3,0,0,0,0,0,0,0,0,0,3
3,10,10,10,10,10,10,10,1,9,3
3,0,0,0,11,0,0,0,0,0,3
3,0,0,0,0,0,0,0,0,0,3
3,0,0,0,0,0,0,0,0,0,3
3,0,0,0,0,0,0,0,0,0,3
3,0,0,0,0,0,0,0,0,0,3
3,0,0,0,0,0,0,0,0,0,3
1,3,3,3,3,3,3,3,3,3,1
endlayer

layer
1,3,3,3,3,1,3,3,3,3,1
3,0,0,0,4,1,5,0,0,0,3
3,0,0,0,0,0,0,0,0,0,3
3,0,0,0,0,0,0,0,0,0,3
3,0,0,0,0,0,0,0,0,0,3
3,0,0,0,0,0,0,0,0,0,3
3,0,0,0,0,0,0,0,0,0,3
3,0,0,0,0,0,0,0,0,0,3
3,0,0,0,0,0,0,0,0,0,3
3,0,0,0,0,0,0,0,0,0,3
3,0,0,0,0,0,0,0,0,0,3
3,0,0,0,0,0,0,0,0,0,3
3,0,0,0,0,0,0,0,12,0,3
3,10,10,10,10,10,10,10,1,13,3
3,0,0,0,0,0,0,0,0,0,3
3,0,0,0,0,0,0,0,0,0,3
3,0,0,0,0,0,0,0,0,0,3
3,0,0,0,0,0,0,0,0,0,3
3,0,0,0,0,0,0,0,0,0,3
3,0,0,0,0,0,0,0,0,0,3
1,3,3,3,3,3,3,3,3,3,1
endlayer

layer
1,2,2,2,2,1,2,2,2,2,1
2,2,3,3,5,0,0,0,0,4,2
2,2,2,2,2,2,2,2,2,2,2
2,2,2,2,2,2,2,2,2,2,2
2,2,2,2,2,2,2,2,2,2,2
2,2,15,14,2,2,2,15,14,2,2
2,2,2,2,2,2,2,2,2,2,2
2,2,2,2,2,2,2,2,2,2,2
2,2,2,2,2,2,2,2,2,2,2
2,2,2,2,2,2,2,2,2,2,2
2,2,15,14,2,2,2,15,14,2,2
2,2,2,2,2,2,2,2,2,2,2
2,2,2,2,2,2,2,2,2,2,2
2,2,2,2,2,2,2,2,2,2,2
2,2,2,2,2,2,2,2,2,2,2
2,2,15,14,2,2,2,15,14,2,2
2,2,2,2,2,2,2,2,2,2,2
2,2,2,2,2,2,2,2,2,2,2
2,2,2,2,2,2,2,2,2,2,2
2,2,2,2,2,2,2,2,2,2,2
1,2,2,2,2,2,2,2,2,2,1
endlayer

layer
1,2,2,2,2,1,2,2,2,2,1
2,4,5,0,0,0,0,4,2,2,3
2,1,2,2,2,2,2,2,2,2,2
2,2,2,2,2,2,2,2,2,2,2
2,2,2,2,2,2,2,2,2,2,2
2,2,2,2,2,2,2,2,2,2,2
2,2,2,2,2,2,2,2,2,2,2
2,2,2,2,2,2,2,2,2,2,2
2,2,2,2,2,2,2,2,2,2,2
2,2,2,2,2,2,2,2,2,2,2
2,2,2,2,2,2,2,2,2,2,2
2,2,2,2,2,2,2,2,2,2,2
2,2,2,2,2,2,2,2,2,2,2
2,2,2,2,2,2,2,2,2,2,2
2,2,2,2,2,2,2,2,2,2,2
2,2,2,2,2,2,2,2,2,2,2
2,2,2,2,2,5,0,16,0,16,2
2,2,2,2,2,5,0,0,0,0,2
2,2,2,2,2,5,0,0,16,0,2
2,2,2,2,2,5,16,0,0,16,2
1,2,2,2,2,2,2,2,2,2,1
endlayer

layer
1,3,3,3,3,1,5,5,5,5,1
3,0,0,0,0,4,2,2,2,2,3
3,0,5,1,1,1,3,2,2,3,2
3,0,0,0,0,5,2,2,2,2,3
3,0,0,0,0,5,2,2,2,2,3
3,0,0,0,0,5,2,2,2,2,3
3,0,0,0,0,5,2,2,2,2,3
3,0,0,0,0,5,5,5,5,5,3
3,0,0,0,0,0,0,0,0,0,3
3,0,0,0,0,0,0,0,0,0,3
3,1,4,4,1,4,4,1,0,0,3
3,4,4,4,4,4,4,4,0,0,3
3,18,0,17,0,0,4,4,0,0,3
3,18,0,0,0,0,4,1,0,0,3
3,18,0,0,0,0,0,0,0,0,3
3,3,9,9,3,3,3,3,3,3,3
3,0,0,0,0,0,0,16,0,0,3
3,0,0,0,0,19,0,0,0,0,3
3,16,0,0,0,19,0,0,16,0,3
3,0,16,0,0,0,0,0,0,0,3
1,3,3,3,3,3,3,3,3,3,1
endlayer

layer
1,3,3,3,3,1,0,0,0,0,1
3,0,0,4,1,3,0,0,0,0,3
3,0,0,0,5,1,3,9,9,3,2
3,0,0,0,0,0,0,0,0,0,3
3,0,0,0,0,0,0,0,0,0,3
3,0,0,0,0,0,0,0,0,0,3
3,0,0,0,0,0,0,0,0,0,3
3,0,0,0,0,0,0,0,0,0,3
3,0,0,0,0,0,0,0,0,0,3
3,0,0,0,0,0,0,0,0,0,3
3,0,0,0,0,0,0,0,0,0,3
3,0,0,21,0,0,20,0,0,0,3
3,0,0,0,0,0,0,0,0,0,3
3,0,0,0,0,0,0,0,0,0,3
3,12,0,0,12,0,0,0,0,0,3
3,3,22,13,3,3,3,3,3,3,3
3,23,0,0,23,0,0,0,0,0,3
3,0,0,0,0,0,0,0,0,0,3
3,16,0,0,0,0,0,0,0,0,3
3,0,0,0,0,0,0,0,0,0,3
1,3,3,3,3,3,3,3,3,3,1
endlayer

layer
1,3,3,3,3,1,0,0,0,0,1
3,4,1,5,0,3,12,0,0,12,3
3,0,0,0,0,1,3,22,13,3,2
3,0,0,0,0,0,23,0,0,23,3
3,0,0,0,0,0,0,0,0,0,3
3,0,0,0,0,0,0,0,0,0,3
3,0,0,0,0,0,0,0,0,0,3
3,0,0,0,0,0,0,0,0,0,3
3,0,0,0,0,0,0,0,0,0,3
3,0,0,0,0,0,0,0,0,0,3
3,0,0,0,0,0,0,0,0,0,3
3,0,0,0,0,0,0,0,0,0,3
3,0,0,0,0,0,0,0,0,0,3
3,0,0,0,0,0,0,0,0,0,3
3,0,0,0,0,0,0,0,0,0,3
3,3,3,3,3,3,3,3,3,3,3
3,0,0,0,0,0,0,0,0,0,3
3,0,0,0,0,0,0,0,0,0,3
3,0,0,0,0,0,0,0,0,0,3
3,0,0,0,0,0,0,0,0,0,3
1,3,3,3,3,3,3,3,3,3,1
endlayer

layer
1,3,10,10,3,1,0,0,0,0,1
3,5,0,0,0,3,0,0,0,0,3
10,1,4,0,0,1,3,3,3,3,2
10,0,0,0,0,0,0,0,0,0,3
3,0,0,0,0,0,0,0,0,0,3
3,0,0,0,0,0,0,0,0,0,3
3,0,0,0,0,0,0,0,0,0,3
10,0,0,0,0,0,0,0,0,0,10
10,0,0,0,0,0,0,0,0,0,10
3,0,0,0,0,0,0,0,0,0,3
3,0,0,0,0,0,0,0,0,0,3
3,0,0,0,0,0,0,0,0,0,3
10,0,0,0,0,0,0,0,0,0,10
10,0,0,0,0,0,0,0,0,0,10
3,0,0,0,0,0,0,0,0,0,3
3,2,2,2,2,2,2,2,2,2,3
3,0,0,0,0,0,0,0,0,0,3
10,0,0,0,0,0,0,0,0,0,10
10,0,0,0,0,0,0,0,0,0,10
3,0,0,0,0,0,0,0,0,24,3
1,3,10,10,3,3,3,10,10,3,1
endlayer

layer
1,3,3,3,3,1,0,0,0,0,1
3,0,0,0,0,3,0,0,0,0,3
3,0,5,1,4,1,3,3,3,3,2
3,0,0,0,0,0,0,0,0,0,3
3,0,0,0,0,0,0,0,0,0,3
3,0,0,0,0,0,0,0,0,0,3
3,0,0,0,0,0,0,0,0,0,3
3,0,0,0,0,0,0,0,0,0,3
3,0,0,0,0,0,0,0,0,0,3
3,0,0,0,0,0,0,0,0,0,3
3,0,0,0,0,0,0,0,0,0,3
3,0,0,0,0,0,0,0,0,0,3
3,0,0,0,0,0,0,0,0,0,3
3,0,0,0,0,0,0,0,0,0,3
3,0,0,0,0,0,0,0,0,0,3
3,3,3,3,3,3,3,3,3,3,3
3,24,0,0,0,0,0,0,0,0,3
3,0,0,0,0,0,0,0,0,0,3
3,0,0,0,0,0,0,0,0,0,3
3,0,0,0,0,0,0,0,24,0,3
1,3,3,3,3,3,3,3,3,3,1
endlayer

layer
1,2,2,2,2,1,1,1,1,1,1
2,0,0,2,2,2,1,1,1,1,3
2,0,0,0,5,1,2,2,2,2,2
2,2,2,2,2,2,2,2,2,2,2
2,2,2,2,2,2,2,2,2,2,2
2,2,15,14,2,2,2,15,14,2,2
2,2,2,2,2,2,2,2,2,2,2
2,2,2,2,2,2,2,2,2,2,2
2,2,2,2,2,2,2,2,2,2,2
2,2,2,2,2,2,2,2,2,2,2
2,2,15,14,2,2,2,15,14,2,2
2,2,2,2,2,2,2,2,2,2,2
2,2,2,2,2,2,2,2,2,2,2
2,2,2,2,2,2,2,2,2,2,2
2,2,2,2,2,2,2,2,2,2,2
2,2,2,2,2,2,2,2,2,2,2
2,2,2,2,2,2,2,2,2,2,2
2,2,2,2,2,2,2,2,2,2,2
2,2,2,2,2,2,2,2,2,2,2
2,2,2,2,2,2,2,2,2,2,2
1,2,2,2,2,2,2,2,2,2,1
endlayer

layer
1,2,2,2,2,2,2,2,2,2,1
2,2,2,2,2,2,2,2,2,4,2
2,0,0,0,0,0,5,2,2,2,2
2,2,2,2,2,2,2,2,2,2,2
2,2,2,2,2,2,2,2,2,2,2
2,2,2,2,2,2,1,2,2,2,2
2,2,2,2,2,1,2,1,2,2,2
2,2,2,2,2,2,1,2,2,2,2
2,2,2,2,2,1,2,1,2,2,2
2,2,2,2,2,2,1,2,2,2,2
2,2,2,2,2,1,2,1,2,2,2
2,2,2,2,2,2,1,2,2,2,2
2,2,2,2,2,1,2,1,2,2,2
2,2,2,2,2,2,1,2,2,2,2
2,2,2,2,2,1,2,1,2,2,2
2,2,2,2,2,2,1,2,2,2,2
2,2,2,2,2,1,2,1,2,2,2
2,2,2,2,2,2,1,2,2,2,2
2,2,2,2,2,2,2,2,2,2,2
2,2,2,2,2,2,2,2,2,2,2
1,2,2,2,2,2,2,2,2,2,1
endlayer

layer
1,3,3,3,3,3,3,3,3,3,1
3,2,2,2,2,5,0,4,1,5,3
3,0,0,0,0,0,0,0,0,0,3
3,10,10,10,10,10,10,10,0,0,3
3,0,0,0,0,0,0,0,0,0,3
3,0,0,0,0,0,0,0,0,0,3
3,0,10,10,0,0,0,0,0,0,3
3,0,10,10,0,0,0,0,0,0,3
3,0,0,0,0,0,0,0,0,0,3
3,4,4,1,0,0,0,0,0,1,3
3,0,17,0,0,0,0,0,0,4,3
3,0,0,0,0,0,0,0,0,1,3
3,0,0,0,0,0,0,0,0,0,3
3,4,4,1,0,0,25,0,0,0,3
3,0,17,0,0,0,0,0,0,1,3
3,0,0,0,0,0,0,0,0,4,3
3,0,0,0,0,0,0,0,0,1,3
3,4,4,1,0,0,0,0,0,0,3
3,0,17,0,0,0,0,0,21,0,3
3,0,0,0,0,26,26,0,0,0,3
1,3,3,3,3,3,3,3,3,3,1
endlayer

layer
1,3,3,3,3,3,3,3,3,3,1
3,2,2,5,0,4,1,5,0,0,3
3,0,0,0,0,0,0,0,0,0,3
3,0,0,0,0,0,0,0,0,0,3
3,0,0,0,0,0,0,0,0,0,3
3,0,0,0,0,0,0,0,0,0,3
3,0,10,10,0,0,0,0,0,0,3
3,0,10,10,0,0,0,0,0,0,3
3,0,0,0,0,0,0,0,0,12,3
3,10,21,0,0,0,0,0,0,26,3
3,0,0,0,0,0,0,0,0,26,3
3,0,0,0,0,0,0,0,0,26,3
3,0,0,0,0,0,0,0,0,23,3
3,10,21,0,0,0,0,0,0,12,3
3,0,0,0,0,0,0,0,0,26,3
3,0,0,0,0,0,0,0,0,26,3
3,0,0,0,0,0,0,0,0,26,3
3,10,21,0,0,0,0,0,0,23,3
3,0,0,0,0,0,0,0,27,0,3
3,0,0,0,0,10,10,0,0,0,3
1,3,3,3,3,3,3,3,3,3,1
endlayer

layer
1,3,3,3,3,3,3,3,3,3,1
3,5,0,4,1,5,0,0,0,0,3
3,0,0,0,0,0,0,0,0,0,3
3,0,0,0,0,0,0,0,0,0,3
3,0,0,0,0,0,0,0,0,0,3
3,0,0,0,0,0,0,0,0,0,3
3,0,26,26,0,0,0,0,0,0,3
3,0,26,26,0,0,0,0,0,0,3
3,0,0,0,0,0,0,0,0,12,3
3,0,0,0,0,0,0,0,0,26,3
3,0,0,0,0,0,0,0,0,26,3
3,0,0,0,0,0,0,0,0,26,3
3,0,0,0,0,0,0,0,0,23,3
3,0,0,0,0,0,0,0,0,12,3
3,0,0,0,0,0,0,0,0,26,3
3,0,0,0,0,0,0,0,0,26,3
3,0,0,0,0,0,0,0,0,26,3
3,0,0,0,0,0,0,0,0,23,3
3,0,0,0,0,0,0,0,0,0,3
3,0,0,0,10,10,10,0,0,0,3
1,3,3,3,3,3,3,3,3,3,1
endlayer

layer
1,3,10,10,3,3,3,10,10,3,1
3,4,1,5,0,0,0,0,0,0,3
10,0,0,0,0,0,0,0,0,0,10
10,0,0,0,0,0,0,0,0,0,10
3,0,0,0,0,0,0,0,0,0,3
3,0,0,0,0,0,0,0,0,0,3
3,0,10,10,0,0,0,0,0,0,3
10,0,10,10,0,0,0,0,0,0,10
10,0,0,0,0,0,0,0,0,0,10
3,0,0,0,0,0,0,0,0,5,3
3,0,0,0,0,0,0,0,0,5,3
3,0,0,0,0,0,0,0,0,5,3
10,0,0,0,0,0,0,0,0,0,10
10,0,0,0,0,0,0,0,0,0,10
3,0,0,0,0,0,0,0,0,5,3
3,0,0,0,0,0,0,0,0,5,3
3,0,0,0,0,0,0,0,0,5,3
10,0,0,0,0,0,0,0,0,0,10
10,0,0,0,0,0,0,0,0,0,10
3,0,0,0,10,10,0,0,0,0,3
1,3,10,10,3,3,3,10,10,3,1
endlayer

layer
1,3,3,3,3,3,3,3,3,3,1
3,5,0,0,0,0,0,0,0,0,3
3,4,0,0,0,0,0,0,0,0,3
3,0,0,0,0,0,0,0,0,0,3
3,0,0,0,0,0,0,0,0,0,3
3,0,0,0,0,0,0,0,0,0,3
3,0,10,10,0,0,0,0,0,0,3
3,0,10,10,0,0,0,0,0,0,3
3,0,0,0,0,0,0,0,0,0,3
3,0,0,0,0,0,0,0,0,0,3
3,0,0,0,0,0,0,0,0,0,3
3,0,0,0,0,0,0,0,0,0,3
3,0,0,0,0,0,0,0,0,0,3
3,0,0,0,0,0,0,0,0,0,3
3,0,0,0,0,0,0,0,0,0,3
3,0,0,0,0,0,0,0,0,0,3
3,0,0,0,0,0,0,0,0,0,3
3,0,0,0,0,0,0,0,0,0,3
3,0,0,0,0,0,0,0,0,0,3
3,0,0,0,26,26,0,0,0,0,3
1,3,3,3,3,3,3,3,3,3,1
endlayer

layer
1,2,2,2,2,2,2,2,2,2,1
2,0,0,0,0,2,2,2,2,2,2
2,0,2,2,2,2,2,2,2,2,2
2,5,2,2,2,2,2,2,2,2,2
2,2,2,2,2,2,2,2,2,2,2
2,2,15,14,2,2,2,15,14,2,2
2,2,2,2,2,2,2,2,2,2,2
2,2,2,2,2,2,2,2,2,2,2
2,2,2,2,2,2,2,2,2,2,2
2,2,2,2,2,2,2,2,2,2,2
2,2,15,14,2,2,2,15,14,2,2
2,2,2,2,2,2,2,2,2,2,2
2,2,2,2,2,2,2,2,2,2,2
2,2,2,2,2,2,2,2,2,2,2
2,2,2,2,2,2,2,2,2,2,2
2,2,15,14,2,2,2,15,14,2,2
2,2,2,2,2,2,2,2,2,2,2
2,2,2,2,2,2,2,2,2,2,2
2,2,2,2,2,2,2,2,2,2,2
2,2,2,2,2,2,2,2,2,2,2
1,2,2,2,2,2,2,2,2,2,1
endlayer

layer
1,1,1,1,1,1,1,1,1,1,1
1,0,0,0,0,0,0,10,10,0,1
1,0,0,0,0,0,0,0,10,10,1
1,0,0,0,0,0,0,0,0,0,1
1,0,10,10,0,0,0,10,10,0,1
1,0,26,26,0,0,0,26,26,0,1
1,0,10,10,0,0,0,10,10,0,1
1,0,0,0,0,0,0,0,0,0,1
1,0,0,0,0,0,0,0,0,0,1
1,0,10,10,0,0,0,10,10,0,1
1,0,26,26,0,0,0,26,26,0,1
1,0,10,10,0,0,0,10,10,0,1
1,0,0,0,0,0,0,0,0,0,1
1,0,0,0,0,0,0,0,0,0,1
1,0,10,10,0,0,0,10,10,0,1
1,0,26,26,0,0,0,26,26,0,1
1,0,10,10,0,0,0,10,10,0,1
1,0,0,0,26,26,26,0,0,0,1
1,0,0,0,26,3,26,0,0,0,1
1,0,0,0,26,26,26,0,0,0,1
1,1,1,1,1,1,1,1,1,1,1
endlayer

layer
0,0,0,0,0,0,0,0,0,0,0
0,0,0,0,0,0,0,10,0,0,0
0,0,0,0,0,0,0,0,10,0,0
0,0,0,0,0,0,0,0,0,0,0
0,0,0,0,0,0,0,0,0,0,0
0,0,0,0,0,0,0,0,0,0,0
0,0,0,0,0,0,0,0,0,0,0
0,0,0,0,0,0,0,0,0,0,0
0,0,0,0,0,0,0,0,0,0,0
0,0,0,0,0,0,0,0,0,0,0
0,0,0,0,0,0,0,0,0,0,0
0,0,0,0,0,0,0,0,0,0,0
0,0,0,0,0,0,0,0,0,0,0
0,0,0,0,0,0,0,0,0,0,0
0,0,0,0,0,0,0,0,0,0,0
0,0,0,0,0,0,0,0,0,0,0
0,0,0,0,0,0,0,0,0,0,0
0,0,0,0,10,10,10,0,0,0,0
0,0,0,0,10,28,10,0,0,0,0
0,0,0,0,10,10,10,0,0,0,0
0,0,0,0,0,0,0,0,0,0,0
endlayer

layer
0,0,0,0,0,0,0,0,0,0,0
0,0,0,0,0,0,0,10,0,0,0
0,0,0,0,0,0,0,0,10,0,0
0,0,0,0,0,0,0,0,0,0,0
0,0,0,0,0,0,0,0,0,0,0
0,0,0,0,0,0,0,0,0,0,0
0,0,0,0,0,0,0,0,0,0,0
0,0,0,0,0,0,0,0,0,0,0
0,0,0,0,0,0,0,0,0,0,0
0,0,0,0,0,0,0,0,0,0,0
0,0,0,0,0,0,0,0,0,0,0
0,0,0,0,0,0,0,0,0,0,0
0,0,0,0,0,0,0,0,0,0,0
0,0,0,0,0,0,0,0,0,0,0
0,0,0,0,0,0,0,0,0,0,0
0,0,0,0,0,0,0,0,0,0,0
0,0,0,0,0,0,0,0,0,0,0
0,0,0,0,0,10,0,0,0,0,0
0,0,0,0,10,10,10,0,0,0,0
0,0,0,0,0,10,0,0,0,0,0
0,0,0,0,0,0,0,0,0,0,0
endlayer

layer
0,0,0,0,0,0,0,0,0,0,0
0,0,0,0,0,0,0,10,0,0,0
0,0,0,0,0,0,0,0,10,0,0
0,0,0,0,0,0,0,0,0,0,0
0,0,0,0,0,0,0,0,0,0,0
0,0,0,0,0,0,0,0,0,0,0
0,0,0,0,0,0,0,0,0,0,0
0,0,0,0,0,0,0,0,0,0,0
0,0,0,0,0,0,0,0,0,0,0
0,0,0,0,0,0,0,0,0,0,0
0,0,0,0,0,0,0,0,0,0,0
0,0,0,0,0,0,0,0,0,0,0
0,0,0,0,0,0,0,0,0,0,0
0,0,0,0,0,0,0,0,0,0,0
0,0,0,0,0,0,0,0,0,0,0
0,0,0,0,0,0,0,0,0,0,0
0,0,0,0,0,0,0,0,0,0,0
0,0,0,0,0,0,0,0,0,0,0
0,0,0,0,0,29,0,0,0,0,0
0,0,0,0,0,0,0,0,0,0,0
0,0,0,0,0,0,0,0,0,0,0
endlayer

layer
0,0,0,0,0,0,0,0,0,0,0
0,0,0,0,0,0,0,0,0,0,0
0,0,0,0,0,0,0,0,10,0,0
0,0,0,0,0,0,0,0,0,0,0
0,0,0,0,0,0,0,0,0,0,0
0,0,0,0,0,0,0,0,0,0,0
0,0,0,0,0,0,0,0,0,0,0
0,0,0,0,0,0,0,0,0,0,0
0,0,0,0,0,0,0,0,0,0,0
0,0,0,0,0,0,0,0,0,0,0
0,0,0,0,0,0,0,0,0,0,0
0,0,0,0,0,0,0,0,0,0,0
0,0,0,0,0,0,0,0,0,0,0
0,0,0,0,0,0,0,0,0,0,0
0,0,0,0,0,0,0,0,0,0,0
0,0,0,0,0,0,0,0,0,0,0
0,0,0,0,0,0,0,0,0,0,0
0,0,0,0,0,0,0,0,0,0,0
0,0,0,0,0,10,0,0,0,0,0
0,0,0,0,0,0,0,0,0,0,0
0,0,0,0,0,0,0,0,0,0,0
endlayer

layer
0,0,0,0,0,0,0,0,0,0,0
0,0,0,0,0,0,0,0,0,0,0
0,0,0,0,0,0,0,0,0,0,0
0,0,0,0,0,0,0,0,0,0,0
0,0,0,0,0,0,0,0,0,0,0
0,0,0,0,0,0,0,0,0,0,0
0,0,0,0,0,0,0,0,0,0,0
0,0,0,0,0,0,0,0,0,0,0
0,0,0,0,0,0,0,0,0,0,0
0,0,0,0,0,0,0,0,0,0,0
0,0,0,0,0,0,0,0,0,0,0
0,0,0,0,0,0,0,0,0,0,0
0,0,0,0,0,0,0,0,0,0,0
0,0,0,0,0,0,0,0,0,0,0
0,0,0,0,0,0,0,0,0,0,0
0,0,0,0,0,0,0,0,0,0,0
0,0,0,0,0,0,0,0,0,0,0
0,0,0,0,0,10,0,0,0,0,0
0,0,0,0,10,10,10,0,0,0,0
0,0,0,0,0,10,0,0,0,0,0
0,0,0,0,0,0,0,0,0,0,0
endlayer

layer
0,0,0,0,0,0,0,0,0,0,0
0,0,0,0,0,0,0,0,0,0,0
0,0,0,0,0,0,0,0,0,0,0
0,0,0,0,0,0,0,0,0,0,0
0,0,0,0,0,0,0,0,0,0,0
0,0,0,0,0,0,0,0,0,0,0
0,0,0,0,0,0,0,0,0,0,0
0,0,0,0,0,0,0,0,0,0,0
0,0,0,0,0,0,0,0,0,0,0
0,0,0,0,0,0,0,0,0,0,0
0,0,0,0,0,0,0,0,0,0,0
0,0,0,0,0,0,0,0,0,0,0
0,0,0,0,0,0,0,0,0,0,0
0,0,0,0,0,0,0,0,0,0,0
0,0,0,0,0,0,0,0,0,0,0
0,0,0,0,0,0,0,0,0,0,0
0,0,0,0,0,0,0,0,0,0,0
0,0,0,0,0,30,0,0,0,0,0
0,0,0,0,30,0,30,0,0,0,0
0,0,0,0,0,30,0,0,0,0,0
0,0,0,0,0,0,0,0,0,0,0
endlayer

