
# Created by Ruins mod version 17.1 Ingame Parser
# authoring Player: ST753M

weight=1
uniqueMinDistance=1000
embed_into_distance=6
acceptable_target_blocks=
unacceptable_target_blocks=flowing_water,water,flowing_lava,lava,ice,bedrock,netherrack,nether_brick,nether_brick_fence,soul_sand,quartz_ore,end_stone,obsidian,iron_bars,Natura:Cloud,slime_grass,slime_congealed,slime_dirt,clouds,natura:clouds,twilightforest:wispy_cloud,twilightforest:fluffy_cloud
dimensions=15,21,13
allowable_overhang=6
max_leveling=0
leveling_buffer=0
preserve_water=0
preserve_lava=0
preventRotation=1

adjoining_template=ST753M/753_Lab_Sidemachine_CB;24;99;6;30
adjoining_template=ST753M/753_Lab_Sidemachine_CB;25;99;-11;30
adjoining_template=ST753M/753_Lab_Sidemachine_CB;-26;99;-7;30
adjoining_template=ST753M/753_Lab_Sidemachine_CB;-24;99;12;30
adjoining_template=taiga/753_Lab_Dish;12;99;26;25
adjoining_template=taiga/753_Lab_Dish;-8;99;27;25
adjoining_template=taiga/753_Lab_Dish;-10;99;-25;25
adjoining_template=taiga/753_Lab_Dish;9;99;-24;25

biomesToSpawnIn=taiga,taiga_hills,mutated_redwood_taiga,mutated_redwood_taiga_hills,redwood_taiga,mutated_taiga,redwood_taiga_hills

=0,100,air
rule1=0,100,preserveBlock
rule2=0,100,minecraft:concrete-7
rule3=0,100,minecraft:stone-6
rule4=0,100,minecraft:obsidian-0
rule5=0,100,minecraft:double_stone_slab-0
rule6=0,100,minecraft:stonebrick-0
rule7=0,100,minecraft:iron_bars-0
rule8=0,100,minecraft:stone_slab-0
rule9=0,100,minecraft:quartz_stairs-6
rule10=0,100,minecraft:double_stone_slab-7
rule11=0,100,minecraft:quartz_stairs-7
rule12=0,100,minecraft:stone_slab-15
rule13=0,100,minecraft:stone_brick_stairs-6
rule14=0,100,minecraft:stone_brick_stairs-3
rule15=0,100,IInventory;minecraft:dispenser;minecraft:fire_charge#10#0#4-4
rule16=0,100,minecraft:redstone_wire-0
rule17=0,100,minecraft:lever-1
rule18=0,100,minecraft:stone_slab-8
rule19=0,100,minecraft:quartz_stairs-2
rule20=0,100,minecraft:quartz_stairs-3
rule21=0,100,minecraft:stone_slab-7
rule22=0,100,minecraft:iron_door-2
rule23=0,100,teBlock;minecraft:flower_pot;{Item:"minecraft:sapling",x:304520,y:92,z:32151,Data:1,id:"minecraft:flower_pot"}-0
rule24=0,100,minecraft:lever-2
rule25=0,100,minecraft:iron_door-9

layer
1,1,1,2,1,1,1,1,1,2,1,1,1
1,2,2,2,2,2,2,2,2,2,2,2,1
1,2,3,3,3,3,3,3,3,3,3,2,1
2,2,3,3,4,4,4,4,4,3,3,2,2
1,2,3,3,4,4,4,4,4,3,3,2,1
1,2,3,3,3,3,3,3,3,3,3,2,1
1,2,3,3,3,3,3,3,3,3,3,2,1
1,2,3,3,3,3,3,3,3,3,3,2,1
1,2,3,3,3,3,3,3,3,3,3,2,1
1,2,3,3,3,3,3,3,3,3,3,2,1
1,2,3,3,3,3,3,3,3,3,3,2,1
1,2,3,3,3,3,3,3,3,3,3,2,1
1,2,3,3,3,3,3,3,3,3,3,2,1
1,2,3,3,3,3,3,3,3,3,3,2,1
1,2,3,3,3,3,3,3,3,3,3,2,1
1,2,3,3,3,3,3,3,3,3,3,2,1
1,2,3,3,3,3,3,3,3,3,3,2,1
2,2,3,3,3,3,3,3,3,3,3,2,2
1,2,3,3,3,3,3,3,3,3,3,2,1
1,2,2,2,2,2,2,2,2,2,2,2,1
1,1,1,2,1,1,1,1,1,2,1,1,1
endlayer

layer
1,1,1,2,1,1,1,1,1,2,1,1,1
1,5,6,6,6,6,6,6,6,6,6,5,1
1,6,6,6,4,4,4,4,4,6,6,6,1
2,6,6,4,0,0,0,0,0,4,6,6,2
1,6,6,4,7,0,0,0,7,4,6,6,1
1,6,5,8,0,0,0,0,0,8,5,6,1
1,6,8,0,0,0,0,0,0,0,8,6,1
1,6,0,0,0,0,0,0,0,0,0,6,1
1,6,7,0,0,0,11,10,9,0,0,6,1
1,6,7,0,0,0,12,4,12,0,0,6,1
1,6,0,0,0,0,11,4,9,0,0,6,1
1,6,0,0,0,0,12,4,12,0,0,6,1
1,6,0,0,0,0,11,4,9,0,0,6,1
1,6,7,0,0,0,12,4,12,0,0,6,1
1,6,7,0,0,0,11,10,9,0,0,6,1
1,6,0,0,0,0,0,0,0,0,0,6,1
1,6,0,0,0,0,0,0,0,0,8,6,1
2,6,0,0,0,0,0,0,0,8,5,6,2
1,6,7,0,14,13,0,0,8,5,3,6,1
1,5,6,6,6,6,6,6,6,6,6,5,1
1,1,1,2,1,1,1,1,1,2,1,1,1
endlayer

layer
1,1,1,2,1,1,1,1,1,2,1,1,1
1,5,6,6,6,6,6,6,6,6,6,5,1
1,6,6,6,4,4,4,4,4,6,6,6,1
2,6,6,4,0,0,0,0,0,4,6,6,2
1,6,6,4,7,0,0,0,7,4,6,6,1
1,6,5,0,0,0,0,0,0,0,5,6,1
1,6,7,0,0,0,0,0,0,0,7,6,1
1,6,0,0,0,0,0,0,0,0,0,6,1
1,6,7,0,0,0,10,15,10,0,0,6,1
1,6,7,0,0,0,4,16,4,0,0,6,1
1,6,0,0,0,0,10,16,10,0,0,6,1
1,6,0,0,0,0,4,16,4,0,0,6,1
1,6,0,0,0,0,10,16,10,0,0,6,1
1,6,7,0,0,0,4,16,4,0,0,6,1
1,6,7,0,0,0,10,4,10,0,0,6,1
1,6,0,0,0,0,0,17,0,0,0,6,1
1,6,0,0,0,0,0,0,0,0,7,6,1
2,6,0,0,0,0,0,0,0,0,5,6,2
1,6,7,0,0,14,13,0,7,5,3,6,1
1,5,6,6,6,6,6,6,6,6,6,5,1
1,1,1,2,1,1,1,1,1,2,1,1,1
endlayer

layer
1,1,1,2,1,1,1,1,1,2,1,1,1
1,5,6,6,6,6,6,6,6,6,6,5,1
1,6,6,6,4,4,4,4,4,6,6,6,1
2,6,6,4,0,0,0,0,0,4,6,6,2
1,6,6,4,7,0,0,0,7,4,6,6,1
1,6,5,18,0,0,0,0,0,18,5,6,1
1,6,18,0,0,0,0,0,0,0,18,6,1
1,6,0,0,0,0,0,0,0,0,0,6,1
1,6,7,0,0,0,20,10,19,0,0,6,1
1,6,7,0,0,0,21,4,21,0,0,6,1
1,6,0,0,0,0,20,10,19,0,0,6,1
1,6,0,0,0,0,21,4,21,0,0,6,1
1,6,0,0,0,0,20,10,19,0,0,6,1
1,6,7,0,0,0,21,4,21,0,0,6,1
1,6,7,0,0,0,20,10,19,0,0,6,1
1,6,0,0,0,0,0,0,0,0,0,6,1
1,6,0,0,0,0,0,0,0,0,18,6,1
2,6,0,0,0,0,0,0,0,18,5,6,2
1,6,7,0,0,0,14,13,18,5,3,6,1
1,5,6,6,6,6,6,6,6,6,6,5,1
1,1,1,2,1,1,1,1,1,2,1,1,1
endlayer

layer
1,1,1,2,2,2,2,2,2,2,1,1,1
1,5,6,6,6,6,6,6,6,6,6,5,1
1,6,6,6,6,6,6,6,6,6,6,6,1
2,6,6,4,4,4,4,4,4,4,6,6,2
1,6,2,2,4,4,4,4,4,2,2,6,1
1,6,2,2,2,2,2,2,2,2,2,6,1
1,6,2,2,2,0,0,0,2,2,2,6,1
1,6,2,2,0,0,0,0,0,2,2,6,1
1,6,2,0,0,0,0,0,0,0,2,6,1
1,6,2,0,0,0,0,7,0,0,2,6,1
1,6,2,0,0,0,0,0,0,0,2,6,1
1,6,2,0,0,0,0,7,0,0,2,6,1
1,6,2,0,0,0,0,0,0,0,2,6,1
1,6,2,0,0,0,0,7,0,0,2,6,1
1,6,2,0,0,0,0,0,0,0,2,6,1
1,6,2,0,0,0,0,0,0,2,2,6,1
1,6,2,2,0,0,0,0,2,2,2,6,1
2,6,3,2,2,2,2,2,2,2,2,6,2
1,6,3,13,0,0,0,14,2,2,2,6,1
1,5,6,6,6,6,6,6,6,6,6,5,1
1,1,1,2,1,1,1,1,1,2,1,1,1
endlayer

layer
1,1,1,2,5,5,5,5,5,2,1,1,1
1,5,3,3,3,2,2,2,3,3,3,5,1
1,3,3,3,3,3,3,3,3,3,3,3,1
2,3,3,3,3,3,3,3,3,3,3,3,2
1,3,3,3,3,3,3,3,3,3,3,3,1
1,3,3,3,3,3,3,3,3,3,3,3,1
1,3,3,3,3,3,3,3,3,3,3,3,1
1,3,3,3,3,3,3,3,3,3,3,3,1
1,3,3,3,3,3,3,3,3,3,3,3,1
1,3,3,3,3,3,3,3,3,3,3,3,1
1,3,3,3,3,3,3,3,3,3,3,3,1
1,3,3,3,3,3,3,3,3,3,3,3,1
1,3,3,3,3,3,3,3,3,3,3,3,1
1,3,3,3,3,3,3,3,3,3,3,3,1
1,3,3,3,3,3,3,3,3,3,3,3,1
1,3,3,3,3,3,3,3,3,3,3,3,1
1,3,3,3,3,3,3,3,3,3,3,3,1
2,3,3,3,3,3,3,3,3,3,3,3,2
1,3,3,3,0,0,0,0,14,3,3,3,1
1,5,3,3,3,3,3,3,3,3,3,5,1
1,1,1,2,1,1,1,1,1,2,1,1,1
endlayer

layer
1,1,1,2,5,0,0,0,5,2,1,1,1
1,5,6,6,2,7,0,7,2,6,6,5,1
1,6,0,7,5,0,0,0,5,7,0,6,1
2,6,0,0,18,0,0,0,0,0,0,6,2
1,6,0,0,18,0,0,0,0,0,0,6,1
1,6,18,18,5,0,0,0,0,0,0,6,1
1,6,0,0,0,0,0,0,0,0,0,6,1
1,6,0,0,0,0,0,0,0,0,0,6,1
1,6,0,0,0,0,0,0,0,0,0,6,1
1,6,0,0,0,0,0,0,0,0,0,6,1
1,6,0,0,0,0,0,7,7,0,0,6,1
1,6,0,0,0,0,7,2,2,7,0,6,1
1,6,0,0,0,0,7,2,2,7,0,6,1
1,6,0,0,0,0,0,7,7,0,0,6,1
1,6,0,0,0,0,0,0,0,0,0,6,1
1,6,0,0,0,0,0,0,0,0,0,6,1
1,6,0,0,0,0,0,0,0,0,0,6,1
2,6,18,5,7,7,7,7,7,5,22,6,2
1,6,0,7,0,0,0,0,0,0,0,6,1
1,5,6,6,3,6,6,6,3,6,6,5,1
1,1,1,2,1,1,1,1,1,2,1,1,1
endlayer

layer
1,1,1,2,5,0,0,0,5,2,1,1,1
1,5,6,6,2,7,0,7,2,6,6,5,1
1,6,0,7,5,0,0,0,5,7,0,6,1
2,6,0,0,0,0,0,0,0,0,0,6,2
1,6,0,0,0,0,0,0,0,0,0,6,1
1,6,0,23,0,0,0,0,0,0,0,6,1
1,6,0,0,0,0,0,0,0,0,0,6,1
1,6,0,0,0,0,0,0,0,0,0,6,1
1,6,0,0,0,0,0,0,0,0,0,6,1
1,6,0,0,0,0,0,0,0,0,0,6,1
1,6,0,0,0,0,0,0,0,0,0,6,1
1,6,0,0,0,0,0,7,7,0,0,6,1
1,6,0,0,0,0,0,7,7,0,0,6,1
1,6,0,0,0,0,0,0,0,0,0,6,1
1,6,0,0,0,0,0,0,0,0,0,6,1
1,6,0,0,0,0,0,0,0,0,0,6,1
1,6,0,0,0,0,0,0,0,24,0,6,1
2,6,18,5,7,7,7,7,7,5,25,6,2
1,6,0,7,0,0,0,0,0,17,0,6,1
1,5,6,6,3,6,6,6,3,6,6,5,1
1,1,1,2,1,1,1,1,1,2,1,1,1
endlayer

layer
1,1,1,2,5,0,0,0,5,2,1,1,1
1,5,6,6,2,7,0,7,2,6,6,5,1
1,6,0,7,5,0,0,0,5,7,0,6,1
2,6,0,0,0,0,0,0,0,0,0,6,2
1,6,0,0,0,0,0,0,0,0,0,6,1
1,7,0,0,0,0,0,0,0,0,0,7,1
1,7,0,0,0,0,0,0,0,0,0,7,1
1,6,0,0,0,0,0,0,0,0,0,6,1
1,7,0,0,0,0,0,0,0,0,0,7,1
1,7,0,0,0,0,0,0,0,0,0,7,1
1,6,0,0,0,0,0,0,0,0,0,6,1
1,7,0,0,0,0,0,7,7,0,0,7,1
1,7,0,0,0,0,0,7,7,0,0,7,1
1,6,0,0,0,0,0,0,0,0,0,6,1
1,7,0,0,0,0,0,0,0,0,0,7,1
1,7,0,0,0,0,0,0,0,0,0,7,1
1,6,0,0,0,0,0,0,0,0,0,6,1
2,6,18,5,7,7,7,7,7,5,8,6,2
1,6,0,7,0,0,0,0,0,0,0,6,1
1,5,6,6,3,7,7,7,3,6,6,5,1
1,1,1,2,1,1,1,1,1,2,1,1,1
endlayer

layer
18,18,18,2,5,18,18,18,5,2,18,18,18
18,5,6,6,3,2,2,2,3,6,6,5,18
18,6,0,7,5,18,18,18,5,7,0,6,18
2,6,0,0,0,0,0,0,0,0,0,6,2
18,6,0,0,0,0,0,0,0,0,0,6,18
18,6,0,0,0,0,0,0,0,0,0,6,18
18,6,0,0,0,0,0,0,0,0,0,6,18
18,6,0,0,0,0,0,0,0,0,0,6,18
18,6,0,0,0,0,0,0,0,0,0,6,18
18,6,0,0,0,0,0,0,0,0,0,6,18
18,6,0,0,0,0,0,7,7,0,0,6,18
18,6,0,0,0,0,7,2,2,7,0,6,18
18,6,0,0,0,0,7,2,2,7,0,6,18
18,6,0,0,0,0,0,7,7,0,0,6,18
18,6,0,0,0,0,0,0,0,0,0,6,18
18,6,0,0,0,0,0,0,0,0,0,6,18
18,6,0,0,0,0,0,0,0,0,0,6,18
2,6,18,5,8,8,8,8,8,5,18,6,2
18,6,0,8,0,0,0,0,0,0,0,6,18
18,5,6,6,3,6,6,6,3,6,6,5,18
18,18,18,2,18,18,18,18,18,2,18,18,18
endlayer

layer
18,3,3,2,3,3,3,3,3,2,3,3,18
3,3,3,3,3,3,3,3,3,3,3,3,3
3,3,3,3,3,3,3,3,3,3,3,3,3
2,3,3,3,3,3,3,3,3,3,3,3,2
3,3,3,3,3,3,3,3,3,3,3,3,3
3,3,3,3,3,3,3,3,3,3,3,3,3
3,3,3,3,3,3,3,3,3,3,3,3,3
3,3,3,3,3,3,3,3,3,3,3,3,3
3,3,3,3,3,3,3,3,3,3,3,3,3
3,3,3,3,3,3,3,3,3,3,3,3,3
3,3,3,3,3,3,3,3,3,3,3,3,3
3,3,3,3,3,3,3,2,2,3,3,3,3
3,3,3,3,3,3,3,2,2,3,3,3,3
3,3,3,3,3,3,3,3,3,3,3,3,3
3,3,3,3,3,3,3,3,3,3,3,3,3
3,3,3,3,3,3,3,3,3,3,3,3,3
3,3,3,3,3,3,3,3,3,3,3,3,3
2,3,3,3,3,3,3,3,3,3,3,3,2
3,3,3,3,3,3,3,3,3,3,3,3,3
3,3,3,3,3,3,3,3,3,3,3,3,3
18,3,3,2,3,3,3,3,3,2,3,3,18
endlayer

layer
8,3,3,2,8,8,8,8,8,2,3,3,8
3,3,3,7,0,0,0,0,0,7,3,3,3
3,3,3,7,0,0,0,0,0,7,3,3,3
2,7,7,7,0,0,0,0,0,7,7,7,2
8,0,0,0,0,0,0,0,0,0,0,0,8
8,0,0,0,0,0,0,0,0,0,0,0,8
8,0,0,0,0,0,0,0,0,0,0,0,8
8,0,0,0,0,0,0,0,0,0,0,0,8
8,0,0,0,0,0,0,0,0,0,0,0,8
8,0,0,0,0,0,0,0,0,0,0,0,8
8,0,0,0,0,0,0,7,7,0,0,0,8
8,0,0,0,0,0,7,2,2,7,0,0,8
8,0,0,0,0,0,7,2,2,7,0,0,8
8,0,0,0,0,0,0,7,7,0,0,0,8
8,0,0,0,0,0,0,0,0,0,0,0,8
8,0,0,0,0,0,0,0,0,0,0,0,8
8,0,0,0,0,0,0,0,0,0,0,0,8
2,7,7,7,0,0,0,0,0,7,7,7,2
3,3,3,7,0,0,0,0,0,7,3,3,3
3,3,3,7,0,0,0,0,0,7,3,3,3
8,3,3,2,8,8,8,8,8,2,3,3,8
endlayer

layer
8,8,8,2,1,1,1,1,1,2,8,8,8
8,0,0,8,0,0,0,0,0,8,0,0,8
8,0,0,8,0,0,0,0,0,8,0,0,8
2,8,8,8,0,0,0,0,0,8,8,8,2
1,0,0,0,0,0,0,0,0,0,0,0,1
1,0,0,0,0,0,0,0,0,0,0,0,1
1,0,0,0,0,0,0,0,0,0,0,0,1
1,0,0,0,0,0,0,0,0,0,0,0,1
1,0,0,0,0,0,0,0,0,0,0,0,1
1,0,0,0,0,0,0,0,0,0,0,0,1
1,0,0,0,0,0,0,0,0,0,0,0,1
1,0,0,0,0,0,0,7,7,0,0,0,1
1,0,0,0,0,0,0,7,7,0,0,0,1
1,0,0,0,0,0,0,0,0,0,0,0,1
1,0,0,0,0,0,0,0,0,0,0,0,1
1,0,0,0,0,0,0,0,0,0,0,0,1
1,0,0,0,0,0,0,0,0,0,0,0,1
2,8,8,8,0,0,0,0,0,8,8,8,2
8,0,0,8,0,0,0,0,0,8,0,0,8
8,0,0,8,0,0,0,0,0,8,0,0,8
8,8,8,2,1,1,1,1,1,2,8,8,8
endlayer

layer
1,1,1,1,1,1,1,1,1,1,1,1,1
1,0,0,0,0,0,0,0,0,0,0,0,1
1,0,0,0,0,0,0,0,0,0,0,0,1
1,0,0,0,0,0,0,0,0,0,0,0,1
1,0,0,0,0,0,0,0,0,0,0,0,1
1,0,0,0,0,0,0,0,0,0,0,0,1
1,0,0,0,0,0,0,0,0,0,0,0,1
1,0,0,0,0,0,0,0,0,0,0,0,1
1,0,0,0,0,0,0,0,0,0,0,0,1
1,0,0,0,0,0,0,0,0,0,0,0,1
1,0,0,0,0,0,0,7,0,0,0,0,1
1,0,0,0,0,0,0,7,7,7,0,0,1
1,0,0,0,0,0,7,7,7,0,0,0,1
1,0,0,0,0,0,0,0,7,0,0,0,1
1,0,0,0,0,0,0,0,0,0,0,0,1
1,0,0,0,0,0,0,0,0,0,0,0,1
1,0,0,0,0,0,0,0,0,0,0,0,1
1,0,0,0,0,0,0,0,0,0,0,0,1
1,0,0,0,0,0,0,0,0,0,0,0,1
1,0,0,0,0,0,0,0,0,0,0,0,1
1,1,1,1,1,1,1,1,1,1,1,1,1
endlayer

layer
1,1,1,1,1,1,1,1,1,1,1,1,1
1,0,0,0,0,0,0,0,0,0,0,0,1
1,0,0,0,0,0,0,0,0,0,0,0,1
1,0,0,0,0,0,0,0,0,0,0,0,1
1,0,0,0,0,0,0,0,0,0,0,0,1
1,0,0,0,0,0,0,0,0,0,0,0,1
1,0,0,0,0,0,0,0,0,0,0,0,1
1,0,0,0,0,0,0,0,0,0,0,0,1
1,0,0,0,0,0,0,0,0,0,0,0,1
1,0,0,0,0,0,0,0,0,0,0,0,1
1,0,0,0,0,0,0,7,0,0,0,0,1
1,0,0,0,0,0,0,0,0,7,0,0,1
1,0,0,0,0,0,7,0,0,0,0,0,1
1,0,0,0,0,0,0,0,7,0,0,0,1
1,0,0,0,0,0,0,0,0,0,0,0,1
1,0,0,0,0,0,0,0,0,0,0,0,1
1,0,0,0,0,0,0,0,0,0,0,0,1
1,0,0,0,0,0,0,0,0,0,0,0,1
1,0,0,0,0,0,0,0,0,0,0,0,1
1,0,0,0,0,0,0,0,0,0,0,0,1
1,1,1,1,1,1,1,1,1,1,1,1,1
endlayer

