
# Created by Ruins mod version 17.1 Ingame Parser
# authoring Player: ST753M

weight=1
uniqueMinDistance=1500
spawnMinDistance=500
embed_into_distance=3
acceptable_target_blocks=
unacceptable_target_blocks=flowing_water,water,flowing_lava,lava,ice,bedrock,netherrack,nether_brick,nether_brick_fence,soul_sand,quartz_ore,end_stone,obsidian,iron_bars,Natura:Cloud,slime_grass,slime_congealed,slime_dirt,clouds,natura:clouds,twilightforest:wispy_cloud,twilightforest:fluffy_cloud
dimensions=34,21,21
allowable_overhang=3
max_leveling=0
leveling_buffer=0
preserve_water=0
preserve_lava=0

adjoining_template=ST753M/753_Lab_Sidemachine_CB;24;99;6;30
adjoining_template=ST753M/753_Lab_Sidemachine_CB;25;99;-11;30
adjoining_template=ST753M/753_Lab_Sidemachine_CB;-26;99;-7;30
adjoining_template=ST753M/753_Lab_Sidemachine_CB;-24;99;12;30
adjoining_template=taiga/753_Lab_Dish;12;99;26;30
adjoining_template=taiga/753_Lab_Dish;-8;99;27;30
adjoining_template=taiga/753_Lab_Dish;-10;99;-25;30
adjoining_template=taiga/753_Lab_Dish;9;99;-24;30

biomesToSpawnIn=taiga,taiga_hills,mutated_redwood_taiga,mutated_redwood_taiga_hills,redwood_taiga,mutated_taiga,redwood_taiga_hills,mesa,mesa_clear_rock

=0,100,air
rule1=0,100,minecraft:concrete-7
rule2=0,100,preserveBlock
rule3=0,100,minecraft:double_stone_slab-0
rule4=0,100,minecraft:stone-6
rule5=0,100,minecraft:iron_bars-0
rule6=0,100,minecraft:stone_slab-0
rule7=0,100,minecraft:stonebrick-0
rule8=0,100,minecraft:noteblock-0
rule9=0,100,minecraft:log-0
rule10=0,100,minecraft:spruce_stairs-1
rule11=0,100,minecraft:cobblestone_wall-0
rule12=0,100,minecraft:spruce_stairs-3
rule13=0,100,minecraft:spruce_stairs-2
rule14=0,100,minecraft:spruce_stairs-0
rule15=0,100,minecraft:iron_trapdoor-11
rule16=0,100,minecraft:iron_trapdoor-9
rule17=0,100,minecraft:stone_slab-8
rule18=0,100,minecraft:leaves-5
rule19=0,100,minecraft:iron_trapdoor-2
rule20=0,100,minecraft:iron_trapdoor-0
rule21=0,100,minecraft:iron_trapdoor-1
rule22=0,100,minecraft:iron_trapdoor-3
rule23=0,100,teBlock;minecraft:flower_pot;{Item:"minecraft:sapling",x:6453,y:126,z:-975,Data:1,id:"minecraft:flower_pot"}-0
rule24=0,100,minecraft:leaves-13
rule25=0,100,minecraft:stonebrick-3
rule26=0,100,teBlock;minecraft:flower_pot;{Item:"minecraft:sapling",x:6452,y:132,z:-977,Data:1,id:"minecraft:flower_pot"}-0
rule27=0,100,minecraft:cauldron-0

rule28=0,100,CommandBlock:RUINSTRIGGER /summon snowman ~ ~1 ~ {PersistenceRequired:1}:@-1,CommandBlock:RUINSTRIGGER /summon wolf ~ ~1 ~ {PersistenceRequired:1}:@-1,CommandBlock:RUINSTRIGGER /summon ocelot ~ ~1 ~ {PersistenceRequired:1}:@-1,CommandBlock:RUINSTRIGGER /summon blaze ~ ~1 ~ {PersistenceRequired:1}:@-1,CommandBlock:RUINSTRIGGER /summon bat ~ ~1 ~ {PersistenceRequired:1}:@-1,CommandBlock:RUINSTRIGGER /summon blaze ~ ~1 ~ {PersistenceRequired:1}:@-1,CommandBlock:RUINSTRIGGER /summon zombie_villager ~ ~1 ~ {PersistenceRequired:1}:@-1

rule29=0,100,minecraft:ladder-5
rule30=0,100,IInventory;minecraft:hopper;minecraft:ghast_tear#1#0#0+minecraft:spider_eye#4#0#2+minecraft:potion#{Potion:"minecraft:water_breathing"}#0#4-0
rule31=0,100,minecraft:lever-15
rule32=0,100,minecraft:iron_trapdoor-14
rule33=0,100,minecraft:redstone_block-0

layer
1,1,1,1,1,2,2,2,2,2,2,2,2,2,2,2,1,1,1,1,1
1,1,1,1,1,1,1,1,1,1,1,1,1,1,1,1,1,1,1,1,1
1,1,1,1,1,1,1,1,1,1,1,1,1,1,1,1,1,1,1,1,1
1,1,1,1,1,1,1,1,1,1,1,1,1,1,1,1,1,1,1,1,1
1,1,1,1,1,1,1,1,1,1,1,1,1,1,1,1,1,1,1,1,1
2,1,1,1,1,1,1,1,1,1,1,1,1,1,1,1,1,1,1,1,2
2,1,1,1,1,1,1,1,1,1,1,1,1,1,1,1,1,1,1,1,2
2,1,1,1,1,1,1,1,1,1,1,1,1,1,1,1,1,1,1,1,2
2,1,1,1,1,1,1,1,1,1,1,1,1,1,1,1,1,1,1,1,2
2,3,1,1,1,1,1,1,1,1,1,1,1,1,1,1,1,1,1,1,2
2,4,1,1,1,1,1,1,1,1,1,1,1,1,1,1,1,1,1,1,2
2,3,1,1,1,1,1,1,1,1,1,1,1,1,1,1,1,1,1,1,2
2,1,1,1,1,1,1,1,1,1,1,1,1,1,1,1,1,1,1,1,2
2,1,1,1,1,1,1,1,1,1,1,1,1,1,1,1,1,1,1,1,2
2,1,1,1,1,1,1,1,1,1,1,1,1,1,1,1,1,1,1,1,2
2,1,1,1,1,1,1,1,1,1,1,1,1,1,1,1,1,1,1,1,2
1,1,1,1,1,1,1,1,1,1,1,1,1,1,1,1,1,1,1,1,1
1,1,1,1,1,1,1,1,1,1,1,1,1,1,1,1,1,1,1,1,1
1,1,1,1,1,1,1,1,1,1,1,1,1,1,1,1,1,1,1,1,1
1,1,1,1,1,1,1,1,1,1,1,1,1,1,1,1,1,1,1,1,1
1,1,1,1,1,2,2,2,2,2,2,2,2,2,2,2,1,1,1,1,1
endlayer

layer
1,1,1,1,1,2,2,2,2,2,2,2,2,2,2,2,1,1,1,1,1
1,1,1,1,1,1,1,1,1,1,1,1,1,1,1,1,1,1,1,1,1
1,1,1,1,1,1,1,1,1,1,1,1,1,1,1,1,1,1,1,1,1
1,1,1,1,1,1,1,1,1,1,1,1,1,1,1,1,1,1,1,1,1
1,1,1,1,1,1,1,1,1,1,1,1,1,1,1,1,1,1,1,1,1
2,1,1,1,1,1,1,1,1,1,1,1,1,1,1,1,1,1,1,1,2
2,1,1,1,1,1,1,1,1,1,1,1,1,1,1,1,1,1,1,1,2
2,1,1,1,1,1,1,1,1,1,1,1,1,1,1,1,1,1,1,1,2
2,1,1,1,1,1,1,1,1,1,1,1,1,1,1,1,1,1,1,1,2
2,3,1,1,1,1,1,1,1,1,1,1,1,1,1,1,1,1,1,1,2
2,4,1,1,1,1,1,1,1,1,1,1,1,1,1,1,1,1,1,1,2
2,3,1,1,1,1,1,1,1,1,1,1,1,1,1,1,1,1,1,1,2
2,1,1,1,1,1,1,1,1,1,1,1,1,1,1,1,1,1,1,1,2
2,1,1,1,1,1,1,1,1,1,1,1,1,1,1,1,1,1,1,1,2
2,1,1,1,1,1,1,1,1,1,1,1,1,1,1,1,1,1,1,1,2
2,1,1,1,1,1,1,1,1,1,1,1,1,1,1,1,1,1,1,1,2
1,1,1,1,1,1,1,1,1,1,1,1,1,1,1,1,1,1,1,1,1
1,1,1,1,1,1,1,1,1,1,1,1,1,1,1,1,1,1,1,1,1
1,1,1,1,1,1,1,1,1,1,1,1,1,1,1,1,1,1,1,1,1
1,1,1,1,1,1,1,1,1,1,1,1,1,1,1,1,1,1,1,1,1
1,1,1,1,1,2,2,2,2,2,2,2,2,2,2,2,1,1,1,1,1
endlayer

layer
1,1,1,1,1,2,2,2,2,2,2,2,2,2,2,2,1,1,1,1,1
1,1,1,1,1,1,1,1,1,1,1,1,1,1,1,1,1,1,1,1,1
1,1,1,1,1,1,1,1,1,1,1,1,1,1,1,1,1,1,1,1,1
1,1,1,1,1,1,1,1,1,1,1,1,1,1,1,1,1,1,1,1,1
1,1,1,1,1,1,1,1,1,1,1,1,1,1,1,1,1,1,1,1,1
2,1,1,1,1,1,1,1,1,1,1,1,1,1,1,1,1,1,1,1,2
2,1,1,1,1,1,1,1,1,1,1,1,1,1,1,1,1,1,1,1,2
2,1,1,1,1,1,1,1,1,1,1,1,1,1,1,1,1,1,1,1,2
2,1,1,1,1,1,1,1,1,1,1,1,1,1,1,1,1,1,1,1,2
2,3,1,1,1,1,1,1,1,1,1,1,1,1,1,1,1,1,1,1,2
2,3,1,1,1,1,1,1,1,1,1,1,1,1,1,1,1,1,1,1,2
2,3,1,1,1,1,1,1,1,1,1,1,1,1,1,1,1,1,1,1,2
2,1,1,1,1,1,1,1,1,1,1,1,1,1,1,1,1,1,1,1,2
2,1,1,1,1,1,1,1,1,1,1,1,1,1,1,1,1,1,1,1,2
2,1,1,1,1,1,1,1,1,1,1,1,1,1,1,1,1,1,1,1,2
2,1,1,1,1,1,1,1,1,1,1,1,1,1,1,1,1,1,1,1,2
1,1,1,1,1,1,1,1,1,1,1,1,1,1,1,1,1,1,1,1,1
1,1,1,1,1,1,1,1,1,1,1,1,1,1,1,1,1,1,1,1,1
1,1,1,1,1,1,1,1,1,1,1,1,1,1,1,1,1,1,1,1,1
1,1,1,1,1,1,1,1,1,1,1,1,1,1,1,1,1,1,1,1,1
1,1,1,1,1,2,2,2,2,2,2,2,2,2,2,2,1,1,1,1,1
endlayer

layer
2,2,2,2,2,2,2,2,2,2,2,2,2,2,2,2,2,2,2,2,2
2,2,2,1,2,2,2,2,2,2,2,2,2,2,2,2,2,1,2,2,2
2,2,3,4,4,4,4,4,4,4,4,4,4,4,4,4,4,4,3,2,2
2,1,4,4,4,4,4,4,4,4,4,4,4,4,4,4,4,4,4,1,2
2,2,4,4,4,4,4,4,4,4,4,4,4,4,4,4,4,4,4,2,2
2,1,4,4,4,4,4,4,4,4,4,4,4,4,4,4,4,4,4,2,2
2,5,4,4,4,4,4,4,4,4,4,4,4,4,4,4,4,4,4,2,2
2,5,4,4,4,4,4,4,4,4,4,4,4,4,4,4,4,4,4,2,2
2,1,1,4,4,4,4,4,4,4,4,4,4,4,4,4,4,4,4,2,2
2,2,6,4,4,4,4,4,4,4,4,4,4,4,4,4,4,4,4,2,2
2,2,6,4,4,4,4,4,4,4,4,4,4,4,4,4,4,4,4,2,2
2,2,6,4,4,4,4,4,4,4,4,4,4,4,4,4,4,4,4,2,2
2,1,1,4,4,4,4,4,4,4,4,4,4,4,4,4,4,4,4,2,2
2,5,4,4,4,4,4,4,4,4,4,4,4,4,4,4,4,4,4,2,2
2,5,4,4,4,4,4,4,4,4,4,4,4,4,4,4,4,4,4,2,2
2,1,4,4,4,4,4,4,4,4,4,4,4,4,4,4,4,4,4,2,2
2,2,4,4,4,4,4,4,4,4,4,4,4,4,4,4,4,4,4,2,2
2,1,4,4,4,4,4,4,4,4,4,4,4,4,4,4,4,4,4,1,2
2,2,3,4,4,4,4,4,4,4,4,4,4,4,4,4,4,4,3,2,2
2,2,2,1,2,2,2,2,2,2,2,2,2,2,2,1,2,1,2,2,2
2,2,2,2,2,2,2,2,2,2,2,2,2,2,2,2,2,2,2,2,2
endlayer

layer
2,2,2,2,2,2,2,2,2,2,2,2,2,2,2,2,2,2,2,2,2
2,2,2,1,2,2,2,2,2,2,2,2,2,2,2,2,2,1,2,2,2
2,2,3,7,7,7,7,7,7,7,7,7,7,7,7,7,7,7,3,2,2
2,1,7,9,0,0,0,0,0,9,7,0,0,8,0,0,0,8,7,1,2
2,2,7,0,0,0,10,0,0,0,7,8,0,0,0,0,8,0,7,2,2
2,1,7,3,0,11,0,11,0,0,7,0,8,0,0,0,0,0,7,2,2
2,6,7,0,13,0,0,0,12,1,7,0,0,0,8,0,0,0,7,2,2
2,6,7,0,0,11,0,11,0,0,3,7,7,7,7,0,7,7,7,2,2
2,1,1,3,0,0,14,0,0,0,9,1,0,0,0,0,0,0,7,2,2
2,2,0,0,0,0,0,0,0,0,0,15,0,0,0,0,0,0,7,2,2
2,2,0,0,0,0,0,0,0,0,0,15,0,12,0,0,0,0,7,2,2
2,2,0,0,0,0,0,0,0,0,0,15,0,0,0,0,0,0,7,2,2
2,1,1,3,0,0,0,0,0,0,0,3,16,16,16,3,0,0,7,2,2
2,6,7,13,0,0,0,0,0,0,9,0,0,0,0,0,0,0,7,2,2
2,6,7,13,0,0,0,0,0,0,0,0,0,0,0,0,0,0,7,2,2
2,1,7,3,0,0,0,0,0,0,0,0,0,0,0,0,0,0,7,2,2
2,2,7,0,0,0,0,0,0,0,0,0,0,0,0,0,0,0,7,2,2
2,1,7,9,0,14,14,14,0,0,0,0,0,17,3,6,0,0,7,1,2
2,2,3,7,7,7,7,7,7,7,7,7,7,7,7,7,7,7,3,2,2
2,2,2,1,2,2,2,2,2,2,2,2,2,2,2,1,2,1,2,2,2
2,2,2,2,2,2,2,2,2,2,2,2,2,2,2,2,2,2,2,2,2
endlayer

layer
2,2,2,2,2,2,2,2,2,2,2,2,2,2,2,2,2,2,2,2,2
2,2,2,1,2,2,2,2,2,2,2,2,2,2,2,2,2,1,2,2,2
2,2,3,7,7,7,7,7,7,7,7,7,7,7,7,7,7,7,3,2,2
2,1,7,18,0,0,0,0,0,18,7,0,0,0,0,0,0,8,7,1,2
2,2,7,0,0,0,0,0,0,0,7,0,0,0,0,0,0,0,7,2,2
2,1,7,3,0,19,19,19,0,0,7,0,8,0,0,0,0,0,7,2,2
2,2,7,0,0,21,19,20,0,1,7,0,0,0,0,0,0,0,7,2,2
2,2,7,0,0,21,21,22,0,0,3,7,7,7,7,0,7,7,7,2,2
2,1,1,3,0,0,0,0,0,0,18,1,0,0,0,0,0,0,7,2,2
2,2,0,0,0,0,0,0,0,0,0,0,0,0,0,0,0,0,7,2,2
2,2,0,0,0,0,0,0,0,0,0,0,0,0,0,0,0,0,7,2,2
2,2,0,0,0,0,0,0,0,0,0,23,0,0,0,0,0,0,7,2,2
2,1,1,3,0,0,0,0,0,0,0,0,0,0,0,0,0,0,7,2,2
2,2,7,0,0,0,0,0,0,0,18,0,0,0,0,0,0,0,7,2,2
2,2,7,0,0,0,0,0,0,0,0,0,0,0,0,0,0,0,7,2,2
2,1,7,3,0,0,0,0,0,0,0,0,0,0,0,0,0,0,7,2,2
2,2,7,0,0,0,0,0,0,0,0,0,0,0,0,0,0,0,7,2,2
2,1,7,24,0,0,0,0,0,0,0,17,3,6,0,0,0,0,7,1,2
2,2,3,7,7,7,7,7,7,7,7,7,7,7,7,7,7,7,3,2,2
2,2,2,1,2,2,2,2,2,2,2,2,2,2,2,1,2,1,2,2,2
2,2,2,2,2,2,2,2,2,2,2,2,2,2,2,2,2,2,2,2,2
endlayer

layer
2,2,2,2,2,2,2,2,2,2,2,2,2,2,2,2,2,2,2,2,2
2,2,2,1,2,2,2,2,2,2,2,2,2,2,2,2,2,1,2,2,2
2,2,3,7,7,7,5,5,5,7,7,7,5,5,5,7,7,7,3,2,2
2,1,7,18,0,0,0,0,0,18,7,0,0,0,0,0,0,0,7,1,2
2,2,7,0,0,0,0,0,0,0,7,0,0,0,0,0,0,0,7,2,2
2,1,7,3,0,0,0,0,0,0,7,0,0,0,0,0,0,0,5,2,2
2,2,5,0,0,0,0,0,0,1,7,0,0,0,0,0,0,0,5,2,2
2,2,5,0,0,0,0,0,0,0,3,7,7,7,7,7,7,7,7,2,2
2,1,1,3,0,0,0,0,0,0,18,1,0,0,0,0,0,0,7,2,2
2,2,0,0,0,0,0,0,0,0,0,0,0,0,0,0,0,0,5,2,2
2,2,0,0,0,0,0,0,0,0,0,0,0,0,0,0,0,0,5,2,2
2,2,0,0,0,0,0,0,0,0,0,0,0,0,0,0,0,0,7,2,2
2,1,1,3,0,0,0,0,0,0,0,0,0,0,0,0,0,0,7,2,2
2,2,5,0,0,0,0,0,0,0,18,0,0,0,0,0,0,0,5,2,2
2,2,5,0,0,0,0,0,0,0,0,0,0,0,0,0,0,0,5,2,2
2,1,7,3,0,0,0,0,0,0,0,0,0,0,0,0,0,0,7,2,2
2,2,7,0,0,0,0,0,0,0,0,0,0,0,0,0,0,0,7,2,2
2,1,7,24,0,0,0,0,0,17,3,6,0,0,0,0,0,0,7,1,2
2,2,3,7,7,5,5,5,7,7,7,5,5,5,7,7,7,7,3,2,2
2,2,2,1,2,2,2,2,2,2,2,2,2,2,2,1,2,1,2,2,2
2,2,2,2,2,2,2,2,2,2,2,2,2,2,2,2,2,2,2,2,2
endlayer

layer
2,2,2,2,2,2,2,2,2,2,2,2,2,2,2,2,2,2,2,2,2
2,2,2,1,2,2,2,2,2,2,2,2,2,2,2,2,2,1,2,2,2
2,2,3,1,1,1,1,1,1,1,1,1,1,1,1,1,1,1,3,2,2
2,1,1,0,0,0,0,0,0,0,1,0,0,0,0,0,0,0,1,1,2
2,2,1,0,0,0,0,0,0,0,1,0,0,0,0,0,0,0,1,2,2
2,1,1,3,0,0,0,0,0,0,1,0,0,0,0,0,0,0,1,2,2
2,2,1,0,0,0,0,0,0,1,1,0,0,0,0,0,0,0,1,2,2
2,2,1,0,0,0,0,0,0,0,3,1,1,1,1,1,1,1,1,2,2
2,1,1,3,0,0,0,0,0,0,0,1,0,0,0,0,0,0,1,2,2
2,2,17,0,0,0,0,0,0,0,0,0,0,0,0,0,0,0,1,2,2
2,2,17,0,0,0,0,0,0,0,0,0,0,0,0,0,0,0,1,2,2
2,2,17,0,0,0,0,0,0,0,0,0,0,0,0,0,0,0,1,2,2
2,1,1,3,0,0,0,0,0,0,0,0,0,0,0,0,0,0,1,2,2
2,2,1,0,0,0,0,0,0,0,0,0,0,0,0,0,0,0,1,2,2
2,2,1,0,0,0,0,0,0,0,0,0,0,0,0,0,0,0,1,2,2
2,1,1,3,0,0,0,0,0,0,0,0,0,0,0,0,0,0,1,2,2
2,2,1,0,0,0,0,0,0,0,0,0,0,0,0,0,0,0,1,2,2
2,1,1,0,0,0,0,17,3,6,0,0,0,0,0,0,0,0,1,1,2
2,2,3,1,1,1,1,1,1,1,1,1,1,1,1,1,1,1,3,2,2
2,2,2,1,2,2,2,2,2,2,2,2,2,2,2,1,2,1,2,2,2
2,2,2,2,2,2,2,2,2,2,2,2,2,2,2,2,2,2,2,2,2
endlayer

layer
17,17,17,17,17,2,2,2,2,2,2,2,2,2,2,2,17,17,17,17,17
17,1,1,1,17,2,2,2,2,2,2,2,2,2,2,2,17,1,1,1,17
17,1,3,4,4,4,4,4,4,4,4,4,4,4,4,4,4,4,3,1,17
17,1,4,4,4,4,4,4,4,4,4,17,17,17,17,17,17,17,4,1,17
17,17,4,4,17,17,17,17,17,4,4,17,0,0,0,0,0,17,4,17,17
2,1,4,3,17,0,0,0,17,4,4,17,0,0,0,0,0,17,4,2,2
2,3,4,4,17,0,0,0,17,1,4,17,17,17,17,17,17,17,4,2,2
2,17,4,4,17,0,0,0,17,4,4,4,4,4,4,4,4,4,4,2,2
2,1,1,3,17,0,0,0,17,4,4,1,4,4,4,4,4,4,4,2,2
2,1,1,1,17,0,0,0,17,17,17,17,17,17,17,17,17,4,4,2,2
2,1,1,1,17,0,0,0,0,0,0,0,0,0,0,0,17,4,4,2,2
2,1,1,1,17,0,0,0,0,0,0,0,0,0,0,0,17,4,4,2,2
2,1,1,3,17,0,0,0,0,0,0,0,0,0,0,0,17,4,4,2,2
2,17,4,4,17,0,0,0,0,0,0,0,0,0,0,0,17,4,4,2,2
2,3,4,4,17,0,0,0,0,0,0,0,0,0,0,0,17,4,4,2,2
2,1,4,3,17,0,0,0,0,0,0,0,0,0,0,0,17,4,4,2,2
2,2,4,4,17,17,17,17,17,17,17,17,17,17,17,17,17,4,4,17,17
2,1,4,4,4,4,3,6,0,0,0,0,0,17,4,4,4,4,4,1,17
2,2,3,4,4,4,4,4,4,4,4,4,4,4,4,4,4,4,3,1,17
2,2,2,1,2,2,2,2,2,2,2,2,2,2,2,1,17,1,1,1,17
2,2,2,2,2,2,2,2,2,2,2,2,2,2,2,2,17,17,17,17,17
endlayer

layer
4,4,4,4,4,2,2,2,2,2,2,2,2,2,2,2,4,4,4,4,4
4,4,4,4,4,2,2,2,2,2,2,2,2,2,2,2,4,4,4,4,4
4,4,4,4,4,4,4,4,4,4,4,4,4,4,4,4,4,4,4,4,4
4,4,4,4,4,4,4,4,4,4,4,4,4,4,4,4,4,4,4,4,4
4,4,4,4,4,4,4,4,4,4,4,4,4,4,4,4,4,4,4,4,4
2,1,4,4,4,4,4,4,4,4,4,4,4,4,4,4,4,4,4,2,2
2,6,4,4,4,4,4,4,4,4,4,4,4,4,4,4,4,4,4,2,2
2,3,4,4,4,4,4,4,4,4,4,4,4,4,4,4,4,4,4,2,2
2,3,4,4,4,4,4,4,4,4,4,4,4,4,4,4,4,4,4,2,2
2,6,4,4,4,4,4,4,4,4,4,4,4,4,4,4,4,4,4,2,2
2,6,4,4,4,4,4,4,4,4,4,4,4,4,4,4,4,4,4,2,2
2,6,4,4,4,4,4,4,4,4,4,4,4,4,4,4,4,4,4,2,2
2,3,4,4,4,4,4,4,4,4,4,4,4,4,4,4,4,4,4,2,2
2,3,4,4,4,4,4,4,4,4,4,4,4,4,4,4,4,4,4,2,2
2,6,4,4,4,4,4,4,4,4,4,4,4,4,4,4,4,4,4,2,2
2,1,4,4,4,4,4,4,4,4,4,4,4,4,4,4,4,4,4,2,2
2,2,4,4,4,4,4,4,4,4,4,4,4,4,4,4,4,4,4,4,4
2,1,4,4,4,6,0,0,0,0,0,0,4,4,4,4,4,4,4,4,4
2,2,3,4,4,4,4,4,4,4,4,4,4,4,4,4,4,4,4,4,4
2,2,2,1,2,2,2,2,2,2,2,2,2,2,2,1,4,4,4,4,4
2,2,2,2,2,2,2,2,2,2,2,2,2,2,2,2,4,4,4,4,4
endlayer

layer
6,6,6,6,6,2,2,2,2,2,2,2,2,2,2,2,6,6,6,6,6
6,0,0,0,6,6,6,6,6,6,6,6,6,6,6,6,6,0,0,1,6
6,0,0,0,0,0,0,0,0,0,0,0,0,0,0,0,0,0,0,0,6
6,0,0,1,0,1,0,0,0,0,0,0,0,1,0,1,0,0,0,0,6
6,6,3,7,7,7,7,7,7,7,7,7,7,7,7,7,3,0,0,6,6
2,1,7,0,17,17,17,0,0,0,11,0,0,0,0,0,7,1,0,6,2
2,2,7,0,0,0,0,0,0,0,11,0,0,0,10,0,7,0,0,6,2
2,2,7,0,0,0,0,0,0,0,11,0,0,3,17,17,7,0,0,6,2
2,6,7,0,0,0,0,0,0,0,11,0,0,0,0,0,7,0,0,6,2
2,3,7,0,0,0,0,0,0,0,11,0,0,0,10,0,7,0,0,6,2
2,17,7,0,0,0,0,0,0,0,11,0,0,3,17,17,7,0,0,6,2
2,3,7,0,0,0,0,0,0,0,11,0,0,0,0,0,7,0,0,6,2
2,6,7,0,0,0,0,0,0,0,11,0,0,0,10,0,7,0,0,6,2
2,2,7,17,0,0,0,0,0,0,9,0,0,3,17,17,7,0,0,6,2
2,2,7,3,0,0,0,0,0,0,0,0,0,0,0,0,7,0,0,6,2
2,1,7,6,0,0,0,0,0,0,0,0,0,0,0,0,7,0,0,6,2
2,2,7,0,0,0,5,5,5,5,5,5,5,0,0,0,7,0,0,6,6
2,1,7,0,0,0,0,0,0,0,0,0,5,0,0,0,7,1,0,0,6
2,2,3,7,7,7,7,7,7,7,7,7,7,7,7,7,3,0,0,0,6
2,2,2,1,2,2,2,2,2,2,2,2,2,2,2,1,6,0,0,0,6
2,2,2,2,2,2,2,2,2,2,2,2,2,2,2,2,6,6,6,6,6
endlayer

layer
2,2,2,2,2,2,2,2,2,2,2,2,2,2,2,2,2,2,2,2,2
2,2,2,2,2,2,2,2,2,2,2,2,2,2,2,2,2,2,2,11,2
2,2,2,2,2,2,2,2,2,2,2,2,2,2,2,2,2,2,2,2,2
2,2,2,1,0,1,2,2,2,2,2,2,2,1,0,1,2,2,2,2,2
2,2,3,7,7,7,7,7,7,7,7,7,7,7,7,7,3,2,2,2,2
2,1,7,0,8,8,8,0,0,0,6,0,0,0,0,0,7,1,2,2,2
2,2,7,0,0,0,0,0,0,0,6,0,0,0,0,0,7,2,2,2,2
2,2,7,0,0,0,0,0,0,0,6,0,0,0,25,5,7,2,2,2,2
2,2,7,0,0,0,0,0,0,0,6,0,0,0,0,0,7,2,2,2,2
2,2,7,0,0,0,0,0,0,0,6,0,0,0,0,0,7,2,2,2,2
2,6,7,0,0,0,0,0,0,0,6,0,0,26,25,5,7,2,2,2,2
2,2,7,17,0,0,0,0,0,0,6,0,0,0,0,0,7,2,2,2,2
2,2,7,3,0,0,0,0,0,0,6,0,0,0,0,0,7,2,2,2,2
2,2,7,6,0,0,0,0,0,0,24,0,0,0,25,5,7,2,2,2,2
2,2,7,0,0,0,0,0,0,0,0,0,0,0,0,0,7,2,2,2,2
2,1,7,0,0,0,0,0,0,0,0,0,0,0,0,0,7,2,2,2,2
2,2,7,0,0,0,0,0,0,0,0,0,0,0,0,0,7,2,2,2,2
2,1,7,0,0,0,0,0,0,0,0,0,0,0,0,0,7,1,2,2,2
2,2,3,7,7,7,7,7,7,7,7,7,7,7,7,7,3,2,2,2,2
2,2,2,1,2,2,2,2,2,2,2,2,2,2,2,1,2,2,2,2,2
2,2,2,2,2,2,2,2,2,2,2,2,2,2,2,2,2,2,2,2,2
endlayer

layer
2,2,2,2,2,2,2,2,2,2,2,2,2,2,2,2,2,2,2,2,2
2,2,2,2,2,2,2,2,2,2,2,2,2,2,2,2,2,2,2,5,2
2,2,2,2,2,2,2,2,2,2,2,2,2,2,2,2,2,2,2,2,2
2,2,2,1,0,1,2,2,2,2,2,2,2,1,0,1,2,2,2,2,2
2,2,3,7,7,7,7,7,5,5,5,7,7,7,7,7,3,2,2,2,2
2,1,7,0,8,8,8,0,0,0,0,0,0,0,0,0,7,1,2,2,2
2,2,7,0,0,0,0,0,0,0,0,0,0,0,0,0,7,2,2,2,2
2,2,5,0,0,0,0,0,0,0,0,0,0,0,0,0,7,2,2,2,2
2,2,5,0,0,0,0,0,0,0,0,0,0,0,0,0,5,2,2,2,2
2,2,7,17,0,0,0,0,0,0,0,0,0,0,0,0,5,2,2,2,2
2,2,7,3,0,0,0,0,0,0,0,0,0,0,0,0,7,2,2,2,2
2,2,7,6,0,0,0,0,0,0,0,0,0,0,0,0,7,2,2,2,2
2,2,5,0,0,0,0,0,0,0,0,0,0,0,0,0,7,2,2,2,2
2,2,5,0,0,0,0,0,0,0,18,0,0,0,0,0,5,2,2,2,2
2,2,7,0,0,0,0,0,0,0,0,0,0,0,0,0,5,2,2,2,2
2,1,7,0,0,0,0,0,0,0,0,0,0,0,0,0,7,2,2,2,2
2,2,7,0,0,0,0,0,0,0,0,0,0,0,0,0,7,2,2,2,2
2,1,7,0,0,0,0,0,0,0,0,0,0,0,0,0,7,1,2,2,2
2,2,3,7,7,5,5,5,7,7,7,5,5,5,7,7,3,2,2,2,2
2,2,2,1,2,2,2,2,2,2,2,2,2,2,2,1,2,2,2,2,2
2,2,2,2,2,2,2,2,2,2,2,2,2,2,2,2,2,2,2,2,2
endlayer

layer
2,2,2,2,2,2,2,2,2,2,2,2,2,2,2,2,2,2,2,5,2
2,2,2,2,2,2,2,2,2,2,2,2,2,2,2,2,2,2,2,5,5
2,2,2,2,2,2,2,2,2,2,2,2,2,2,2,2,2,2,2,2,2
2,2,2,1,0,1,2,2,2,2,2,2,2,1,0,1,2,2,2,2,2
2,2,3,1,1,1,1,1,1,1,1,1,1,1,1,1,3,2,2,2,2
2,1,1,0,6,6,6,0,0,0,0,0,0,0,0,0,1,1,2,2,2
2,2,1,0,0,0,0,0,0,0,0,0,0,0,0,0,1,2,2,2,2
2,2,1,17,0,0,0,0,0,0,0,0,0,0,0,0,1,2,2,2,2
2,2,1,3,0,0,0,0,0,0,0,0,0,0,0,0,1,2,2,2,2
2,2,1,6,0,0,0,0,0,0,0,0,0,0,0,0,1,2,2,2,2
2,2,1,0,0,0,0,0,0,0,0,0,0,0,0,0,1,2,2,2,2
2,2,1,0,0,0,0,0,0,0,0,0,0,0,0,0,1,2,2,2,2
2,2,1,0,0,0,0,0,0,0,0,0,0,0,0,0,1,2,2,2,2
2,2,1,0,0,0,0,0,0,0,0,0,0,0,0,0,1,2,2,2,2
2,2,1,0,0,0,0,0,0,0,0,0,0,0,0,0,1,2,2,2,2
2,1,1,0,0,0,0,0,0,0,0,0,0,0,0,0,1,2,2,2,2
2,2,1,0,0,0,0,0,0,0,0,0,0,0,0,0,1,2,2,2,2
2,1,1,0,0,0,0,0,0,0,0,0,0,0,0,0,1,1,2,2,2
2,2,3,1,1,1,1,1,1,1,1,1,1,1,1,1,3,2,2,2,2
2,2,2,1,2,2,2,2,2,2,2,2,2,2,2,1,2,2,2,2,2
2,2,2,2,2,2,2,2,2,2,2,2,2,2,2,2,2,2,2,2,2
endlayer

layer
2,2,2,2,2,2,2,2,2,2,2,2,2,2,2,2,2,2,2,5,2
2,2,2,2,2,2,2,2,2,2,2,2,2,2,2,2,2,2,2,0,5
2,2,2,2,2,2,2,2,2,2,2,2,2,2,17,17,17,17,17,2,2
2,2,2,1,0,1,2,2,2,2,2,2,2,1,17,1,1,1,17,2,2
2,2,3,4,4,4,4,4,4,4,4,4,4,4,4,4,3,1,17,2,2
2,1,4,4,4,4,4,4,4,4,4,4,4,4,4,4,4,1,17,2,2
2,2,4,3,17,17,17,17,17,17,17,17,17,17,17,4,4,17,17,2,2
2,2,4,6,17,0,0,0,0,0,0,0,0,0,17,4,4,2,2,2,2
2,2,4,0,17,0,0,0,0,0,0,0,0,0,17,4,4,2,2,2,2
2,2,4,0,17,0,0,0,0,0,0,0,0,0,17,4,4,2,2,2,2
2,2,4,0,17,0,0,0,0,0,0,0,0,0,17,4,4,2,2,2,2
2,2,4,0,17,0,0,0,0,0,0,0,0,0,17,4,4,2,2,2,2
2,2,4,0,17,0,0,0,0,0,0,0,0,0,17,4,4,2,2,2,2
2,2,4,17,17,0,0,0,0,0,0,0,0,0,17,4,4,2,2,2,2
2,2,4,4,17,0,0,0,0,0,0,0,0,0,17,4,4,2,2,2,2
2,1,4,4,17,0,0,0,0,0,0,0,0,0,17,4,4,2,2,2,2
17,17,4,4,17,17,17,17,17,17,17,17,17,17,17,4,4,17,17,2,2
17,1,4,4,4,4,4,4,4,4,4,4,4,4,4,4,4,1,17,2,2
17,1,3,4,4,4,4,4,4,4,4,4,4,4,4,4,3,1,17,2,2
17,1,1,1,17,2,2,2,2,2,2,2,2,2,17,1,1,1,17,2,2
17,17,17,17,17,2,2,2,2,2,2,2,2,2,17,17,17,17,17,2,2
endlayer

layer
2,2,2,2,2,2,2,2,2,2,2,2,2,2,2,2,2,2,2,2,2
2,2,2,2,2,2,2,2,2,2,2,2,2,2,2,2,2,2,2,2,2
2,2,2,2,2,2,2,2,2,2,2,2,2,2,4,4,4,4,4,2,2
2,2,2,1,0,1,2,2,2,2,2,2,2,1,4,4,4,4,4,2,2
2,2,3,4,4,4,4,4,4,4,4,4,4,4,4,4,4,4,4,2,2
2,1,4,6,4,4,4,4,4,4,4,4,4,4,4,4,4,4,4,2,2
2,2,4,0,4,4,4,4,4,4,4,4,4,4,4,4,4,4,4,2,2
2,2,4,0,4,4,4,4,4,4,4,4,4,4,4,4,4,2,2,2,2
2,2,4,0,4,4,4,4,4,4,4,4,4,4,4,4,4,2,2,2,2
2,2,4,0,4,4,4,4,4,4,4,4,4,4,4,4,4,2,2,2,2
2,2,4,0,4,4,4,4,4,4,4,4,4,4,4,4,4,2,2,2,2
2,2,4,0,4,4,4,4,4,4,4,4,4,4,4,4,4,2,2,2,2
2,2,4,4,4,4,4,4,4,4,4,4,4,4,4,4,4,2,2,2,2
2,2,4,4,4,4,4,4,4,4,4,4,4,4,4,4,4,2,2,2,2
2,2,4,4,4,4,4,4,4,4,4,4,4,4,4,4,4,2,2,2,2
2,1,4,4,4,4,4,4,4,4,4,4,4,4,4,4,4,2,2,2,2
4,4,4,4,4,4,4,4,4,4,4,4,4,4,4,4,4,4,4,2,2
4,4,4,4,4,4,4,4,4,4,4,4,4,4,4,4,4,4,4,2,2
4,4,4,4,4,4,4,4,4,4,4,4,4,4,4,4,4,4,4,2,2
4,4,4,4,4,2,2,2,2,2,2,2,2,2,4,4,4,4,4,2,2
4,4,4,4,4,2,2,2,2,2,2,2,2,2,4,4,4,4,4,2,2
endlayer

layer
2,2,2,2,2,2,2,2,2,2,2,2,2,2,2,2,2,2,2,2,2
2,2,2,2,2,2,2,2,2,2,2,2,2,2,2,2,2,2,2,2,2
2,2,2,2,2,2,2,2,2,2,2,2,2,2,6,6,6,6,6,2,2
2,2,2,1,0,1,2,2,2,2,2,2,2,1,6,0,0,0,6,2,2
2,2,3,7,7,7,7,7,7,7,7,7,7,7,3,0,0,0,6,2,2
2,1,7,0,0,0,6,3,17,0,0,0,0,0,7,1,0,0,6,2,2
2,2,7,0,0,0,0,0,0,0,0,0,0,0,7,0,0,6,6,2,2
2,2,7,0,5,0,0,0,27,0,27,0,27,0,1,1,0,6,2,2,2
2,2,7,0,5,0,0,0,0,0,0,0,0,0,0,0,0,6,2,2,2
2,2,7,0,5,0,0,5,5,5,5,5,0,0,0,0,0,6,2,2,2
2,2,7,0,5,0,0,5,0,0,0,5,0,0,0,0,0,6,2,2,2
2,2,7,0,5,0,0,5,0,28,0,5,0,0,1,1,0,6,2,2,2
2,2,7,5,5,0,0,5,0,0,0,5,0,0,7,0,0,6,2,2,2
2,2,7,0,0,0,0,5,5,5,5,5,0,0,7,1,0,6,2,2,2
2,2,7,0,0,0,0,0,0,0,0,0,0,0,7,0,0,6,2,2,2
2,1,7,0,0,0,0,0,0,0,0,0,0,0,7,1,0,6,2,2,2
6,6,3,7,7,7,7,7,7,7,7,7,7,7,3,0,0,6,6,2,2
6,0,0,1,0,0,0,0,0,0,0,0,0,1,0,0,0,0,6,2,2
6,0,0,0,0,0,0,0,0,0,0,0,0,0,0,0,0,0,6,2,2
6,0,0,0,6,6,6,6,6,6,6,6,6,6,6,0,0,1,6,2,2
6,6,6,6,6,2,2,2,2,2,2,2,2,2,6,6,6,6,6,2,2
endlayer

layer
2,2,2,2,2,2,2,2,2,2,2,2,2,2,2,2,2,2,2,2,2
2,2,2,2,2,2,2,2,2,2,2,2,2,2,2,2,2,2,2,2,2
2,2,2,2,2,2,2,2,2,2,2,2,2,2,2,2,2,2,2,2,2
2,2,2,1,0,1,2,2,2,2,2,2,2,1,0,0,2,2,2,2,2
2,2,3,7,7,7,7,7,7,7,7,7,7,7,3,0,2,2,2,2,2
2,1,7,0,0,0,0,0,6,3,17,0,0,0,7,1,2,2,2,2,2
2,2,7,0,0,0,0,0,0,0,0,0,0,0,7,0,2,2,2,2,2
2,2,7,0,0,0,0,0,21,0,21,0,21,0,1,1,2,2,2,2,2
2,2,7,0,0,0,0,0,0,0,0,0,0,0,0,0,2,2,2,2,2
2,2,7,0,0,0,0,5,5,5,5,5,0,0,0,0,2,2,2,2,2
2,2,7,0,0,0,0,5,0,0,0,5,0,0,0,0,2,2,2,2,2
2,2,7,0,0,0,0,5,0,0,0,5,0,0,1,1,2,2,2,2,2
2,2,7,0,0,0,0,5,0,0,0,5,0,0,7,0,2,2,2,2,2
2,2,7,0,0,0,0,5,5,5,5,5,0,0,7,1,2,2,2,2,2
2,2,7,0,0,0,0,0,0,0,0,0,0,0,7,0,2,2,2,2,2
2,1,7,0,0,0,0,0,0,0,0,0,0,0,7,1,2,2,2,2,2
2,2,3,7,7,7,7,7,7,7,7,7,7,7,3,0,2,2,2,2,2
2,2,0,1,0,0,0,0,0,0,0,0,0,1,0,0,2,2,2,2,2
2,2,2,2,2,2,2,2,2,2,2,2,2,2,0,0,2,2,2,2,2
2,2,2,2,2,2,2,2,2,2,2,2,2,2,2,2,2,11,2,2,2
2,2,2,2,2,2,2,2,2,2,2,2,2,2,2,2,2,2,2,2,2
endlayer

layer
2,2,2,2,2,2,2,2,2,2,2,2,2,2,2,2,2,2,2,2,2
2,2,2,2,2,2,2,2,2,2,2,2,2,2,2,2,2,2,2,2,2
2,2,2,2,2,2,2,2,2,2,2,2,2,2,2,2,2,2,2,2,2
2,2,2,1,0,1,2,2,2,2,2,2,2,1,0,0,2,2,2,2,2
2,2,3,7,7,7,7,7,5,5,5,7,7,7,3,0,2,2,2,2,2
2,1,7,0,0,0,0,0,0,0,6,3,17,0,7,1,2,2,2,2,2
2,2,7,0,0,0,0,0,0,0,0,0,0,0,7,0,2,2,2,2,2
2,2,5,0,0,0,0,0,0,0,0,0,0,0,1,1,2,2,2,2,2
2,2,5,0,0,0,0,0,0,0,0,0,0,0,0,0,2,2,2,2,2
2,2,7,0,0,0,0,5,5,5,5,5,0,0,0,0,2,2,2,2,2
2,2,7,0,0,0,0,5,0,0,0,5,0,0,0,0,2,2,2,2,2
2,2,7,0,0,0,0,5,0,0,0,5,0,0,1,1,2,2,2,2,2
2,2,5,0,0,0,0,5,0,0,0,5,0,0,7,0,2,2,2,2,2
2,2,5,0,0,0,0,5,5,5,5,5,0,0,7,1,2,2,2,2,2
2,2,7,0,0,0,0,0,0,0,0,0,0,0,7,0,2,2,2,2,2
2,1,7,0,0,0,0,0,0,0,0,0,0,0,7,1,2,2,2,2,2
2,2,3,7,7,5,5,7,7,7,5,5,7,7,3,0,2,2,2,2,2
2,2,0,1,0,0,0,0,0,0,0,0,0,1,0,0,2,2,2,2,2
2,2,2,2,2,2,2,2,2,2,2,2,2,2,0,0,2,2,2,2,2
2,2,2,2,2,2,2,2,2,2,2,2,2,2,2,2,2,5,2,2,2
2,2,2,2,2,2,2,2,2,2,2,2,2,2,2,2,2,2,2,2,2
endlayer

layer
2,2,2,2,2,2,2,2,2,2,2,2,2,2,2,2,2,2,2,2,2
2,2,2,2,2,2,2,2,2,2,2,2,2,2,2,2,2,2,2,2,2
2,2,2,2,2,2,2,2,2,2,2,2,2,2,2,2,2,2,2,2,2
2,2,2,1,0,1,2,2,2,2,2,2,2,1,0,0,2,2,2,2,2
2,2,3,1,1,1,1,1,1,1,1,1,1,1,3,0,2,2,2,2,2
2,1,1,0,0,0,0,0,0,0,0,0,6,3,1,1,2,2,2,2,2
2,2,1,0,0,0,0,0,0,0,0,0,0,17,1,17,2,2,2,2,2
2,2,1,0,0,0,0,0,0,0,0,0,0,0,1,1,2,2,2,2,2
2,2,1,0,0,0,0,0,0,0,0,0,0,0,1,1,2,2,2,2,2
2,2,1,0,0,0,0,6,6,6,6,6,0,0,1,1,2,2,2,2,2
2,2,1,0,0,0,0,6,17,17,17,6,0,0,1,1,2,2,2,2,2
2,2,1,0,0,0,0,6,17,17,17,6,0,0,1,1,2,2,2,2,2
2,2,1,0,0,0,0,6,17,17,17,6,0,0,1,17,2,2,2,2,2
2,2,1,0,0,0,0,6,6,6,6,6,0,0,1,1,2,2,2,2,2
2,2,1,0,0,0,0,0,0,0,0,0,0,0,1,0,2,2,2,2,2
2,1,1,0,0,0,0,0,0,0,0,0,0,0,1,1,2,2,2,2,2
2,2,3,1,1,1,1,1,1,1,1,1,1,1,3,0,2,2,2,2,2
2,2,0,1,0,0,0,0,0,0,0,0,0,1,0,0,2,2,2,2,2
2,2,2,2,2,2,2,2,2,2,2,2,2,2,0,0,2,2,2,2,2
2,2,2,2,2,2,2,2,2,2,2,2,2,2,2,2,2,5,5,2,2
2,2,2,2,2,2,2,2,2,2,2,2,2,2,2,2,2,5,2,2,2
endlayer

layer
2,2,2,2,2,2,2,2,2,2,2,2,2,2,2,2,2,2,2,2,2
2,2,2,2,2,2,2,2,2,2,2,2,2,2,2,2,2,2,2,2,2
17,17,17,17,17,2,2,2,2,2,2,2,2,2,2,2,2,2,2,2,2
17,1,1,1,17,1,2,2,2,2,2,2,2,1,0,0,2,2,2,2,2
17,1,3,4,4,4,4,4,4,4,4,4,4,4,3,0,2,2,2,2,2
17,1,4,4,4,4,4,4,17,0,0,0,0,0,4,1,2,2,2,2,2
17,17,4,4,17,17,17,17,17,17,17,17,17,6,4,3,2,2,2,2,2
2,2,4,4,17,0,0,0,0,0,0,0,17,3,4,3,2,2,2,2,2
2,2,4,4,17,0,0,0,0,0,0,0,17,4,4,6,2,2,2,2,2
2,2,4,4,17,0,0,0,0,0,0,0,17,4,4,6,2,2,2,2,2
2,2,4,4,17,0,0,0,0,0,0,0,17,4,4,6,2,2,2,2,2
2,2,4,4,17,0,0,0,0,0,0,0,17,4,4,3,2,2,2,2,2
2,2,4,4,17,0,0,0,0,0,0,0,17,4,4,3,2,2,2,2,2
2,2,4,4,17,0,0,0,0,0,0,0,17,4,4,1,2,2,2,2,2
17,17,4,4,17,17,17,17,17,17,17,17,17,4,4,17,17,2,2,2,2
17,1,4,4,4,4,4,4,4,4,4,4,4,4,4,1,17,2,2,2,2
17,1,3,4,4,4,4,4,4,4,4,4,4,4,3,1,17,2,2,2,2
17,1,1,1,17,0,0,0,0,0,0,0,17,1,1,1,17,2,2,2,2
17,17,17,17,17,2,2,2,2,2,2,2,17,17,17,17,17,2,2,2,2
2,2,2,2,2,2,2,2,2,2,2,2,2,2,2,2,2,0,5,2,2
2,2,2,2,2,2,2,2,2,2,2,2,2,2,2,2,2,5,2,2,2
endlayer

layer
2,2,2,2,2,2,2,2,2,2,2,2,2,2,2,2,2,2,2,2,2
2,2,2,2,2,2,2,2,2,2,2,2,2,2,2,2,2,2,2,2,2
4,4,4,4,4,2,2,2,2,2,2,2,2,2,2,2,2,2,2,2,2
4,4,4,4,4,1,2,2,2,2,2,2,2,1,0,0,2,2,2,2,2
4,4,4,4,4,4,4,4,4,4,4,4,4,4,3,0,2,2,2,2,2
4,4,4,4,4,4,4,4,4,4,0,0,0,0,4,1,2,2,2,2,2
4,4,4,4,4,4,4,4,4,4,4,4,4,0,4,0,2,2,2,2,2
2,2,4,4,4,4,4,4,4,4,4,4,4,0,4,6,2,2,2,2,2
2,2,4,4,4,4,4,4,4,4,4,4,4,6,4,3,2,2,2,2,2
2,2,4,4,4,4,4,4,4,4,4,4,4,4,4,17,2,2,2,2,2
2,2,4,4,4,4,4,4,4,4,4,4,4,4,4,3,2,2,2,2,2
2,2,4,4,4,4,4,4,4,4,4,4,4,4,4,6,2,2,2,2,2
2,2,4,4,4,4,4,4,4,4,4,4,4,4,4,0,2,2,2,2,2
2,2,4,4,4,4,4,4,4,4,4,4,4,4,4,1,2,2,2,2,2
4,4,4,4,4,4,4,4,4,4,4,4,4,4,4,4,4,2,2,2,2
4,4,4,4,4,4,4,4,4,4,4,4,4,4,4,4,4,2,2,2,2
4,4,4,4,4,4,4,4,4,4,4,4,4,4,4,4,4,2,2,2,2
4,4,4,4,4,0,0,0,0,0,0,0,4,4,4,4,4,2,2,2,2
4,4,4,4,4,2,2,2,2,2,2,2,4,4,4,4,4,2,2,2,2
2,2,2,2,2,2,2,2,2,2,2,2,2,2,2,2,2,2,2,2,2
2,2,2,2,2,2,2,2,2,2,2,2,2,2,2,2,2,2,2,2,2
endlayer

layer
2,2,2,2,2,2,2,2,2,2,2,2,2,2,2,2,2,2,2,2,2
2,2,2,2,2,2,2,2,2,2,2,2,2,2,2,2,2,2,2,2,2
6,6,6,6,6,2,2,2,2,2,2,2,2,2,2,2,2,2,2,2,2
6,0,0,0,6,1,2,2,2,2,2,2,2,1,0,0,2,2,2,2,2
6,0,0,0,3,7,7,7,7,7,7,7,7,7,3,0,2,2,2,2,2
6,0,0,1,7,3,29,3,0,5,0,0,0,0,7,1,2,2,2,2,2
6,6,0,0,7,0,0,0,0,5,5,5,5,0,7,0,2,2,2,2,2
2,6,0,0,7,0,0,0,0,0,0,0,5,0,7,0,2,2,2,2,2
2,6,0,0,7,0,0,0,0,0,30,0,5,0,7,0,2,2,2,2,2
2,6,0,0,7,0,0,0,0,0,0,0,0,0,7,6,2,2,2,2,2
2,6,0,0,7,0,1,1,0,0,0,0,0,0,7,0,2,2,2,2,2
2,6,0,0,7,0,1,1,0,0,0,0,0,0,7,0,2,2,2,2,2
2,6,0,0,7,0,0,0,0,0,0,0,0,0,7,0,2,2,2,2,2
2,6,0,1,7,0,0,3,0,0,0,3,0,0,7,1,2,2,2,2,2
6,6,0,0,3,7,7,1,0,0,0,1,7,7,3,6,6,2,2,2,2
6,0,0,0,0,1,0,1,0,0,0,1,0,1,0,0,6,2,2,2,2
6,0,0,0,0,0,0,0,0,0,0,0,0,0,0,0,6,2,2,2,2
6,1,0,0,6,6,6,6,6,6,6,6,6,0,0,0,6,2,2,2,2
6,6,6,6,6,2,2,2,2,2,2,2,6,6,6,6,6,2,2,2,2
2,2,2,2,2,2,2,2,2,2,2,2,2,2,2,2,2,2,2,2,2
2,2,2,2,2,2,2,2,2,2,2,2,2,2,2,2,2,2,2,2,2
endlayer

layer
2,2,2,2,2,2,2,2,2,2,2,2,2,2,2,2,2,2,2,2,2
2,2,2,2,2,2,2,2,2,2,2,2,2,2,2,2,2,2,2,2,2
2,2,2,0,0,2,2,2,2,2,2,2,2,2,2,2,2,2,2,2,2
2,2,2,0,0,1,2,2,2,2,2,2,2,1,0,0,2,2,2,2,2
2,2,2,0,3,7,7,7,7,7,7,7,7,7,3,0,2,2,2,2,2
2,2,2,1,7,3,29,3,0,0,0,0,0,0,7,1,2,2,2,2,2
2,2,2,0,7,0,0,0,0,0,0,0,0,0,7,0,2,2,2,2,2
2,2,2,0,7,0,0,0,0,0,0,0,0,0,7,0,2,2,2,2,2
2,2,2,0,7,0,0,0,0,0,27,0,0,0,7,0,2,2,2,2,2
2,2,2,0,7,0,0,0,0,0,0,0,0,0,7,0,2,2,2,2,2
2,2,2,0,7,0,5,5,0,0,0,0,0,0,7,0,2,2,2,2,2
2,2,2,0,7,0,5,5,0,0,0,0,0,0,7,0,2,2,2,2,2
2,2,2,0,7,0,0,0,0,0,0,0,0,0,7,0,2,2,2,2,2
2,2,2,1,7,0,0,3,0,0,0,3,0,0,7,1,2,2,2,2,2
2,2,2,0,3,7,7,1,0,0,0,1,7,7,3,0,2,2,2,2,2
2,2,2,0,0,1,0,1,0,0,0,1,0,1,0,0,2,2,2,2,2
2,2,2,0,0,0,0,0,0,0,0,0,0,0,0,0,2,2,2,2,2
2,11,2,2,2,2,2,2,2,2,2,2,2,2,2,2,2,2,2,2,2
2,2,2,2,2,2,2,2,2,2,2,2,2,2,2,2,2,2,2,2,2
2,2,2,2,2,2,2,2,2,2,2,2,2,2,2,2,2,2,2,2,2
2,2,2,2,2,2,2,2,2,2,2,2,2,2,2,2,2,2,2,2,2
endlayer

layer
2,2,2,2,2,2,2,2,2,2,2,2,2,2,2,2,2,2,2,2,2
2,2,2,2,2,2,2,2,2,2,2,2,2,2,2,2,2,2,2,2,2
2,2,2,0,0,2,2,2,2,2,2,2,2,2,2,2,2,2,2,2,2
2,2,2,0,0,1,2,2,2,2,2,2,2,1,0,0,2,2,2,2,2
2,2,2,0,3,7,7,7,5,5,5,7,7,7,3,0,2,2,2,2,2
2,2,2,1,7,3,29,3,0,0,0,0,0,0,7,1,2,2,2,2,2
2,2,2,0,7,0,0,0,0,0,0,0,0,0,7,0,2,2,2,2,2
2,2,2,0,7,0,0,0,0,0,0,0,0,0,7,0,2,2,2,2,2
2,2,2,0,5,0,0,0,0,0,20,0,0,0,5,0,2,2,2,2,2
2,2,2,0,5,0,0,0,0,0,0,0,0,0,5,0,2,2,2,2,2
2,2,2,0,5,0,5,5,0,0,0,0,0,0,5,0,2,2,2,2,2
2,2,2,0,7,0,5,5,0,0,0,0,0,0,7,0,2,2,2,2,2
2,2,2,0,7,0,0,0,0,0,0,0,0,0,7,0,2,2,2,2,2
2,2,2,1,7,0,0,3,0,0,0,3,0,0,7,1,2,2,2,2,2
2,2,2,0,3,7,7,1,0,0,0,1,7,7,3,0,2,2,2,2,2
2,2,2,0,0,1,0,1,0,0,0,1,0,1,0,0,2,2,2,2,2
2,2,2,0,0,0,0,0,0,0,0,0,0,0,0,0,2,2,2,2,2
2,5,2,2,2,2,2,2,2,2,2,2,2,2,2,2,2,2,2,2,2
2,2,2,2,2,2,2,2,2,2,2,2,2,2,2,2,2,2,2,2,2
2,2,2,2,2,2,2,2,2,2,2,2,2,2,2,2,2,2,2,2,2
2,2,2,2,2,2,2,2,2,2,2,2,2,2,2,2,2,2,2,2,2
endlayer

layer
2,2,2,2,2,2,2,2,2,2,2,2,2,2,2,2,2,2,2,2,2
2,2,2,2,2,2,2,2,2,2,2,2,2,2,2,2,2,2,2,2,2
2,2,2,0,0,2,2,2,2,2,2,2,2,2,2,2,2,2,2,2,2
2,2,2,0,0,1,2,2,2,2,2,2,2,1,0,0,2,2,2,2,2
2,2,2,0,3,1,1,1,1,1,1,1,1,1,3,0,2,2,2,2,2
2,2,2,1,1,3,29,3,0,0,0,0,0,0,1,1,2,2,2,2,2
2,2,2,0,1,0,0,0,0,0,0,0,0,0,1,0,2,2,2,2,2
2,2,2,0,1,0,0,0,0,0,0,0,0,0,1,0,2,2,2,2,2
2,2,2,0,1,0,0,0,0,0,0,0,0,0,1,0,2,2,2,2,2
2,2,2,0,1,0,0,0,0,0,0,0,0,0,1,0,2,2,2,2,2
2,2,2,0,1,0,5,5,0,0,0,0,0,0,1,0,2,2,2,2,2
2,2,2,0,1,0,5,5,0,0,0,0,0,0,1,0,2,2,2,2,2
2,2,2,0,1,0,0,0,0,0,0,0,0,0,1,0,2,2,2,2,2
2,2,2,1,1,0,0,3,0,0,0,3,0,0,1,1,2,2,2,2,2
2,2,2,0,3,1,1,1,1,1,1,1,1,1,3,0,2,2,2,2,2
2,2,2,0,0,1,17,1,1,1,1,1,17,1,0,0,2,2,2,2,2
2,2,2,0,0,17,17,17,17,17,17,17,17,17,0,0,2,2,2,2,2
5,5,2,2,2,2,2,2,2,2,2,2,2,2,2,2,2,2,2,2,2
2,5,2,2,2,2,2,2,2,2,2,2,2,2,2,2,2,2,2,2,2
2,2,2,2,2,2,2,2,2,2,2,2,2,2,2,2,2,2,2,2,2
2,2,2,2,2,2,2,2,2,2,2,2,2,2,2,2,2,2,2,2,2
endlayer

layer
2,2,2,2,2,2,2,2,2,2,2,2,2,2,2,2,2,2,2,2,2
2,2,2,2,2,2,2,2,2,2,2,2,2,2,2,2,2,2,2,2,2
2,2,17,17,17,17,17,2,2,2,2,2,17,17,17,17,17,2,2,2,2
2,2,17,1,1,1,17,2,2,2,2,2,17,1,1,1,17,2,2,2,2
2,2,17,1,3,4,4,4,4,4,4,4,4,4,3,1,17,2,2,2,2
2,2,17,1,4,3,29,3,4,4,4,4,4,4,4,1,17,2,2,2,2
2,2,17,17,4,4,31,17,17,17,17,17,17,4,4,17,17,2,2,2,2
2,2,2,0,4,4,17,0,0,0,0,0,17,4,4,0,2,2,2,2,2
2,2,2,0,4,4,17,0,0,0,0,0,17,4,4,0,2,2,2,2,2
2,2,2,0,4,4,17,0,0,0,0,0,17,4,4,0,2,2,2,2,2
2,2,2,0,4,4,1,1,0,0,0,0,17,4,4,0,2,2,2,2,2
2,2,2,0,4,4,1,1,0,0,0,0,17,4,4,0,2,2,2,2,2
2,2,17,17,4,4,17,17,17,17,17,17,17,4,4,17,17,2,2,2,2
2,2,17,1,4,4,4,3,4,4,4,3,4,4,4,1,17,2,2,2,2
2,2,17,1,3,4,4,4,4,4,4,4,4,4,3,1,17,2,2,2,2
2,2,17,1,1,1,3,6,6,6,6,6,3,1,1,1,17,2,2,2,2
2,2,17,17,17,17,17,2,2,2,2,2,17,17,17,17,17,2,2,2,2
5,0,2,2,2,2,2,2,2,2,2,2,2,2,2,2,2,2,2,2,2
2,5,2,2,2,2,2,2,2,2,2,2,2,2,2,2,2,2,2,2,2
2,2,2,2,2,2,2,2,2,2,2,2,2,2,2,2,2,2,2,2,2
2,2,2,2,2,2,2,2,2,2,2,2,2,2,2,2,2,2,2,2,2
endlayer

layer
2,2,2,2,2,2,2,2,2,2,2,2,2,2,2,2,2,2,2,2,2
2,2,2,2,2,2,2,2,2,2,2,2,2,2,2,2,2,2,2,2,2
2,2,4,4,4,4,4,2,2,2,2,2,4,4,4,4,4,2,2,2,2
2,2,4,4,4,4,4,2,2,2,2,2,4,4,4,4,4,2,2,2,2
2,2,4,4,4,4,4,4,4,4,4,4,4,4,4,4,4,2,2,2,2
2,2,4,4,4,4,32,4,4,4,4,4,4,4,4,4,4,2,2,2,2
2,2,4,4,4,4,4,4,4,4,4,4,4,4,4,4,4,2,2,2,2
2,2,2,0,4,4,4,4,4,4,4,4,4,4,4,0,2,2,2,2,2
2,2,2,0,4,4,4,4,4,4,4,4,4,4,4,0,2,2,2,2,2
2,2,2,0,4,4,4,4,4,4,4,4,4,4,4,0,2,2,2,2,2
2,2,2,0,4,4,4,4,4,4,4,4,4,4,4,0,2,2,2,2,2
2,2,2,0,4,4,4,4,4,4,4,4,4,4,4,0,2,2,2,2,2
2,2,4,4,4,4,4,4,4,4,4,4,4,4,4,4,4,2,2,2,2
2,2,4,4,4,4,4,4,4,4,4,4,4,4,4,4,4,2,2,2,2
2,2,4,4,4,4,4,4,4,4,4,4,4,4,4,4,4,2,2,2,2
2,2,4,4,4,4,4,6,6,6,6,6,4,4,4,4,4,2,2,2,2
2,2,4,4,4,4,4,2,2,2,2,2,4,4,4,4,4,2,2,2,2
2,2,2,2,2,2,2,2,2,2,2,2,2,2,2,2,2,2,2,2,2
2,2,2,2,2,2,2,2,2,2,2,2,2,2,2,2,2,2,2,2,2
2,2,2,2,2,2,2,2,2,2,2,2,2,2,2,2,2,2,2,2,2
2,2,2,2,2,2,2,2,2,2,2,2,2,2,2,2,2,2,2,2,2
endlayer

layer
2,2,2,2,2,2,2,2,2,2,2,2,2,2,2,2,2,2,2,2,2
2,2,2,2,2,2,2,2,2,2,2,2,2,2,2,2,2,2,2,2,2
2,2,6,6,6,6,6,2,2,2,2,2,6,6,6,6,6,2,2,2,2
2,2,6,1,0,0,6,6,6,6,6,6,6,0,0,0,6,2,2,2,2
2,2,6,0,0,0,0,0,0,0,0,0,0,0,0,0,6,2,2,2,2
2,2,6,0,0,0,0,0,0,0,5,1,1,1,5,0,6,2,2,2,2
2,2,6,6,0,0,0,0,0,0,5,1,1,1,5,6,6,2,2,2,2
2,2,2,6,0,0,0,0,0,0,0,0,0,0,0,6,2,2,2,2,2
2,2,2,6,0,0,0,0,0,0,5,1,1,1,5,6,2,2,2,2,2
2,2,2,6,0,0,0,0,0,0,5,1,1,1,5,6,2,2,2,2,2
2,2,2,6,0,5,5,5,0,0,0,0,0,0,0,6,2,2,2,2,2
2,2,2,6,5,1,1,1,5,0,5,1,1,1,5,6,2,2,2,2,2
2,2,6,6,5,1,1,1,5,0,5,1,1,1,5,6,6,2,2,2,2
2,2,6,0,5,1,1,1,5,0,0,0,0,0,0,0,6,2,2,2,2
2,2,6,0,0,5,5,5,0,0,0,0,0,0,0,0,6,2,2,2,2
2,2,6,0,0,0,6,6,6,6,6,6,6,0,0,0,6,2,2,2,2
2,2,6,6,6,6,6,2,2,2,2,2,6,6,6,6,6,2,2,2,2
2,2,2,2,2,2,2,2,2,2,2,2,2,2,2,2,2,2,2,2,2
2,2,2,2,2,2,2,2,2,2,2,2,2,2,2,2,2,2,2,2,2
2,2,2,2,2,2,2,2,2,2,2,2,2,2,2,2,2,2,2,2,2
2,2,2,2,2,2,2,2,2,2,2,2,2,2,2,2,2,2,2,2,2
endlayer

layer
2,2,2,2,2,2,2,2,2,2,2,2,2,2,2,2,2,2,2,2,2
2,2,2,2,2,2,2,2,2,2,2,2,2,2,2,2,2,2,2,2,2
2,2,2,2,2,2,2,2,2,2,2,2,2,2,2,2,2,2,2,2,2
2,2,2,11,2,2,2,2,2,2,2,2,2,2,2,2,2,2,2,2,2
2,2,2,2,0,0,0,0,0,0,0,0,0,0,0,2,2,2,2,2,2
2,2,2,2,0,0,0,0,0,0,5,5,0,5,5,2,2,2,2,2,2
2,2,2,2,0,0,0,0,0,0,5,5,0,5,5,2,2,2,2,2,2
2,2,2,2,0,0,0,0,0,0,0,0,0,0,0,2,2,2,2,2,2
2,2,2,2,0,0,0,0,0,0,5,5,0,5,5,2,2,2,2,2,2
2,2,2,2,0,0,0,0,0,0,5,5,0,5,5,2,2,2,2,2,2
2,2,2,2,0,0,5,0,0,0,0,0,0,0,0,2,2,2,2,2,2
2,2,2,2,0,0,5,0,0,0,5,5,0,5,5,2,2,2,2,2,2
2,2,2,2,5,5,33,5,5,0,5,5,0,5,5,2,2,2,2,2,2
2,2,2,2,0,0,5,0,0,0,0,0,0,0,0,2,2,2,2,2,2
2,2,2,2,0,0,5,0,0,0,0,0,0,0,0,2,2,2,2,2,2
2,2,2,2,2,2,2,2,2,2,2,2,2,2,2,2,2,2,2,2,2
2,2,2,2,2,2,2,2,2,2,2,2,2,2,2,2,2,2,2,2,2
2,2,2,2,2,2,2,2,2,2,2,2,2,2,2,2,2,2,2,2,2
2,2,2,2,2,2,2,2,2,2,2,2,2,2,2,2,2,2,2,2,2
2,2,2,2,2,2,2,2,2,2,2,2,2,2,2,2,2,2,2,2,2
2,2,2,2,2,2,2,2,2,2,2,2,2,2,2,2,2,2,2,2,2
endlayer

layer
2,2,2,2,2,2,2,2,2,2,2,2,2,2,2,2,2,2,2,2,2
2,2,2,2,2,2,2,2,2,2,2,2,2,2,2,2,2,2,2,2,2
2,2,2,2,2,2,2,2,2,2,2,2,2,2,2,2,2,2,2,2,2
2,2,2,5,2,2,2,2,2,2,2,2,2,2,2,2,2,2,2,2,2
2,2,2,2,0,0,0,0,0,0,0,0,0,0,0,2,2,2,2,2,2
2,2,2,2,0,0,0,0,0,0,0,0,0,0,0,2,2,2,2,2,2
2,2,2,2,0,0,0,0,0,0,0,0,0,0,0,2,2,2,2,2,2
2,2,2,2,0,0,0,0,0,0,0,0,0,0,0,2,2,2,2,2,2
2,2,2,2,0,0,0,0,0,0,0,0,0,0,0,2,2,2,2,2,2
2,2,2,2,0,0,0,0,0,0,0,0,0,0,0,2,2,2,2,2,2
2,2,2,2,0,0,0,0,0,0,0,0,0,0,0,2,2,2,2,2,2
2,2,2,2,0,0,0,0,0,0,0,0,0,0,0,2,2,2,2,2,2
2,2,2,2,0,0,11,0,0,0,0,0,0,0,0,2,2,2,2,2,2
2,2,2,2,0,0,0,0,0,0,0,0,0,0,0,2,2,2,2,2,2
2,2,2,2,0,0,0,0,0,0,0,0,0,0,0,2,2,2,2,2,2
2,2,2,2,2,2,2,2,2,2,2,2,2,2,2,2,2,2,2,2,2
2,2,2,2,2,2,2,2,2,2,2,2,2,2,2,2,2,2,2,2,2
2,2,2,2,2,2,2,2,2,2,2,2,2,2,2,2,2,2,2,2,2
2,2,2,2,2,2,2,2,2,2,2,2,2,2,2,2,2,2,2,2,2
2,2,2,2,2,2,2,2,2,2,2,2,2,2,2,2,2,2,2,2,2
2,2,2,2,2,2,2,2,2,2,2,2,2,2,2,2,2,2,2,2,2
endlayer

layer
2,2,2,2,2,2,2,2,2,2,2,2,2,2,2,2,2,2,2,2,2
2,2,2,2,2,2,2,2,2,2,2,2,2,2,2,2,2,2,2,2,2
2,2,2,5,2,2,2,2,2,2,2,2,2,2,2,2,2,2,2,2,2
2,2,5,5,2,2,2,2,2,2,2,2,2,2,2,2,2,2,2,2,2
2,2,2,2,0,0,0,0,0,0,0,0,0,0,0,2,2,2,2,2,2
2,2,2,2,0,0,0,0,0,0,0,0,0,0,0,2,2,2,2,2,2
2,2,2,2,0,0,0,0,0,0,0,0,0,0,0,2,2,2,2,2,2
2,2,2,2,0,0,0,0,0,0,0,0,0,0,0,2,2,2,2,2,2
2,2,2,2,0,0,0,0,0,0,0,0,0,0,0,2,2,2,2,2,2
2,2,2,2,0,0,0,0,0,0,0,0,0,0,0,2,2,2,2,2,2
2,2,2,2,0,0,0,0,0,0,0,0,0,0,0,2,2,2,2,2,2
2,2,2,2,0,0,0,0,0,0,0,0,0,0,0,2,2,2,2,2,2
2,2,2,2,0,0,5,0,0,0,0,0,0,0,0,2,2,2,2,2,2
2,2,2,2,0,0,0,0,0,0,0,0,0,0,0,2,2,2,2,2,2
2,2,2,2,0,0,0,0,0,0,0,0,0,0,0,2,2,2,2,2,2
2,2,2,2,2,2,2,2,2,2,2,2,2,2,2,2,2,2,2,2,2
2,2,2,2,2,2,2,2,2,2,2,2,2,2,2,2,2,2,2,2,2
2,2,2,2,2,2,2,2,2,2,2,2,2,2,2,2,2,2,2,2,2
2,2,2,2,2,2,2,2,2,2,2,2,2,2,2,2,2,2,2,2,2
2,2,2,2,2,2,2,2,2,2,2,2,2,2,2,2,2,2,2,2,2
2,2,2,2,2,2,2,2,2,2,2,2,2,2,2,2,2,2,2,2,2
endlayer

layer
2,2,2,2,2,2,2,2,2,2,2,2,2,2,2,2,2,2,2,2,2
2,2,2,2,2,2,2,2,2,2,2,2,2,2,2,2,2,2,2,2,2
2,2,2,5,2,2,2,2,2,2,2,2,2,2,2,2,2,2,2,2,2
2,2,5,0,2,2,2,2,2,2,2,2,2,2,2,2,2,2,2,2,2
2,2,2,2,0,0,0,0,0,0,0,0,0,0,0,2,2,2,2,2,2
2,2,2,2,0,0,0,0,0,0,0,0,0,0,0,2,2,2,2,2,2
2,2,2,2,0,0,0,0,0,0,0,0,0,0,0,2,2,2,2,2,2
2,2,2,2,0,0,0,0,0,0,0,0,0,0,0,2,2,2,2,2,2
2,2,2,2,0,0,0,0,0,0,0,0,0,0,0,2,2,2,2,2,2
2,2,2,2,0,0,0,0,0,0,0,0,0,0,0,2,2,2,2,2,2
2,2,2,2,0,0,0,0,0,0,0,0,0,0,0,2,2,2,2,2,2
2,2,2,2,0,0,5,0,0,0,0,0,0,0,0,2,2,2,2,2,2
2,2,2,2,0,5,5,5,0,0,0,0,0,0,0,2,2,2,2,2,2
2,2,2,2,0,0,5,0,0,0,0,0,0,0,0,2,2,2,2,2,2
2,2,2,2,0,0,0,0,0,0,0,0,0,0,0,2,2,2,2,2,2
2,2,2,2,2,2,2,2,2,2,2,2,2,2,2,2,2,2,2,2,2
2,2,2,2,2,2,2,2,2,2,2,2,2,2,2,2,2,2,2,2,2
2,2,2,2,2,2,2,2,2,2,2,2,2,2,2,2,2,2,2,2,2
2,2,2,2,2,2,2,2,2,2,2,2,2,2,2,2,2,2,2,2,2
2,2,2,2,2,2,2,2,2,2,2,2,2,2,2,2,2,2,2,2,2
2,2,2,2,2,2,2,2,2,2,2,2,2,2,2,2,2,2,2,2,2
endlayer

layer
2,2,2,2,2,2,2,2,2,2,2,2,2,2,2,2,2,2,2,2,2
2,2,2,2,2,2,2,2,2,2,2,2,2,2,2,2,2,2,2,2,2
2,2,2,2,2,2,2,2,2,2,2,2,2,2,2,2,2,2,2,2,2
2,2,2,2,2,2,2,2,2,2,2,2,2,2,2,2,2,2,2,2,2
2,2,2,2,0,0,0,0,0,0,0,0,0,0,0,2,2,2,2,2,2
2,2,2,2,0,0,0,0,0,0,0,0,0,0,0,2,2,2,2,2,2
2,2,2,2,0,0,0,0,0,0,0,0,0,0,0,2,2,2,2,2,2
2,2,2,2,0,0,0,0,0,0,0,0,0,0,0,2,2,2,2,2,2
2,2,2,2,0,0,0,0,0,0,0,0,0,0,0,2,2,2,2,2,2
2,2,2,2,0,0,0,0,0,0,0,0,0,0,0,2,2,2,2,2,2
2,2,2,2,0,0,0,0,0,0,0,0,0,0,0,2,2,2,2,2,2
2,2,2,2,0,0,5,0,0,0,0,0,0,0,0,2,2,2,2,2,2
2,2,2,2,0,5,0,5,0,0,0,0,0,0,0,2,2,2,2,2,2
2,2,2,2,0,0,5,0,0,0,0,0,0,0,0,2,2,2,2,2,2
2,2,2,2,0,0,0,0,0,0,0,0,0,0,0,2,2,2,2,2,2
2,2,2,2,2,2,2,2,2,2,2,2,2,2,2,2,2,2,2,2,2
2,2,2,2,2,2,2,2,2,2,2,2,2,2,2,2,2,2,2,2,2
2,2,2,2,2,2,2,2,2,2,2,2,2,2,2,2,2,2,2,2,2
2,2,2,2,2,2,2,2,2,2,2,2,2,2,2,2,2,2,2,2,2
2,2,2,2,2,2,2,2,2,2,2,2,2,2,2,2,2,2,2,2,2
2,2,2,2,2,2,2,2,2,2,2,2,2,2,2,2,2,2,2,2,2
endlayer

