
# Created by Ruins mod version 17.0 Ingame Parser
# authoring Player: ST753M

weight=1
embed_into_distance=8
acceptable_target_blocks=grass,dirt,podzol,biomesoplenty:grass,biomesoplenty:dirt
unacceptable_target_blocks=flowing_water,water,flowing_lava,lava
dimensions=8,17,14
allowable_overhang=8
max_leveling=0
leveling_buffer=0
preserve_water=0
preserve_lava=0

biomesToSpawnIn=taiga,taiga_hills,mutated_redwood_taiga,mutated_redwood_taiga_hills,redwood_taiga,mutated_taiga,redwood_taiga_hills,redwood_forest,coniferous_forest,shield,dead_forest,autumnal_wooded_hills,autumnal_woods,seasonal_forest,temperate_rainforest,snowy_forest,mutated_taiga_cold,snowy_coniferous_forest,taiga_cold,taiga_cold_hills

rule1=0,100,preserveBlock
rule2=0,100,minecraft:dirt-0
rule3=0,100,minecraft:grass-0
rule4=0,100,Skull:0:13-1
rule5=0,100,minecraft:bone_block-0
rule6=0,100,minecraft:red_mushroom-0
rule7=0,100,Skull:0:7-1
rule8=0,100,minecraft:brown_mushroom-0
rule9=0,100,minecraft:tallgrass-2
rule10=2,50,minecraft:torch-1
rule11=0,80,MobSpawner:wolf,MobSpawner:skeleton,MobSpawner:cave_spider,MobSpawner:spider,MobSpawner:bat,MobSpawner:silverfish,MobSpawner:rabbit
rule12=0,100,minecraft:web-0

layer
1,1,1,1,1,1,1,1,1,1,1,1,1,1
1,1,1,1,1,1,1,1,1,1,1,1,1,1
1,1,1,1,1,1,1,1,1,1,1,1,1,1
1,1,1,1,1,1,1,1,1,1,1,1,1,1
1,1,1,1,1,1,1,1,1,1,1,1,1,1
1,1,1,1,1,2,2,2,2,1,1,1,1,1
1,1,1,2,2,2,2,2,2,2,2,1,1,1
1,1,1,2,2,2,2,2,2,2,2,1,1,1
1,1,1,2,2,2,2,2,2,2,2,2,1,1
1,1,1,2,2,2,2,2,2,2,2,2,1,1
1,1,1,2,2,2,2,2,2,2,2,2,1,1
1,1,1,2,2,2,2,2,2,2,2,2,1,1
1,1,1,2,2,2,2,2,2,2,2,1,1,1
1,1,1,2,2,2,2,2,2,2,2,1,1,1
1,1,1,1,2,2,1,2,2,2,1,1,1,1
1,1,1,1,1,1,1,1,1,1,1,1,1,1
1,1,1,1,1,1,1,1,1,1,1,1,1,1
endlayer

layer
1,1,1,1,1,1,1,1,1,1,1,1,1,1
1,1,1,1,1,1,1,1,1,1,1,1,1,1
1,1,1,1,1,1,1,1,1,1,1,1,1,1
1,1,1,1,1,1,1,1,1,1,1,1,1,1
1,1,2,2,2,2,2,2,2,1,1,1,1,1
1,1,3,3,3,2,2,2,2,2,2,1,1,1
1,2,3,3,2,2,2,2,2,2,2,2,1,1
1,2,3,3,2,3,2,2,2,2,3,2,2,1
1,2,2,2,2,2,3,2,3,3,3,2,2,1
1,2,2,2,2,2,2,3,0,0,2,2,2,1
1,1,2,2,2,0,0,0,0,0,0,2,2,1
1,1,2,2,0,0,0,0,0,0,0,2,2,1
1,1,2,2,2,4,0,0,0,0,0,2,2,1
1,1,1,2,2,2,0,0,5,0,2,2,1,1
1,1,1,1,2,2,2,0,2,2,2,2,1,1
1,1,1,1,1,1,2,2,2,2,2,1,1,1
1,1,1,1,1,1,1,1,1,1,1,1,1,1
endlayer

layer
1,1,1,1,1,1,1,1,1,1,1,1,1,1
1,1,1,1,2,2,1,1,1,1,1,1,1,1
1,1,2,2,3,3,1,1,1,1,1,1,1,1
1,1,2,3,3,3,2,1,1,1,1,1,1,1
1,1,2,2,2,3,2,2,2,2,2,2,1,1
1,2,0,0,0,3,2,2,2,2,2,2,1,1
1,2,0,0,0,0,2,2,3,3,5,3,2,1
1,3,0,0,0,0,2,3,3,3,0,0,2,1
1,3,0,0,0,0,0,0,0,0,0,0,2,2
1,3,0,0,0,0,0,0,0,0,0,0,6,2
1,2,0,0,0,0,0,0,0,0,0,0,7,2
1,2,2,8,0,0,0,0,0,0,0,0,0,2
1,2,2,0,0,0,0,0,0,0,0,0,2,2
1,1,2,2,0,0,0,0,5,0,0,0,2,1
1,1,1,2,2,0,0,0,0,0,0,2,2,1
1,1,1,1,2,2,2,0,0,2,2,2,1,1
1,1,1,1,1,1,2,2,2,2,1,1,1,1
endlayer

layer
1,1,1,1,1,1,1,1,1,1,1,1,1,1
1,1,1,1,2,3,2,1,1,1,1,1,1,1
1,1,2,2,0,0,2,2,2,1,1,1,1,1
1,1,2,0,0,0,3,2,2,2,1,1,1,1
2,2,3,0,0,0,3,2,2,2,2,2,1,1
2,0,0,0,0,0,3,2,2,2,2,2,1,1
2,0,0,0,0,0,2,2,0,0,5,0,2,1
2,0,0,0,0,0,2,0,0,0,0,0,2,1
2,0,0,0,0,0,0,0,0,0,0,0,0,2
2,0,0,0,0,0,0,0,0,0,0,0,0,2
2,2,0,0,0,0,0,0,0,0,0,0,0,2
2,2,0,0,0,0,0,0,0,0,0,0,0,2
1,2,0,0,0,0,0,0,0,0,0,0,0,2
1,1,2,0,0,0,0,0,0,0,0,0,2,1
1,1,1,2,6,0,0,0,0,0,0,8,2,1
1,1,1,1,2,2,0,0,0,0,2,2,1,1
1,1,1,1,1,1,2,2,2,2,1,1,1,1
endlayer

layer
1,1,1,2,2,2,1,1,1,1,1,1,1,1
1,1,2,2,0,9,2,2,2,1,1,1,1,1
1,2,2,0,0,0,0,3,3,3,2,1,1,1
1,2,0,0,0,0,0,3,3,3,2,3,1,1
2,0,0,0,0,0,0,2,3,3,2,3,1,1
2,0,0,0,0,0,0,3,3,2,2,2,1,1
2,0,0,0,0,0,2,11,10,0,0,2,2,1
3,0,0,0,0,0,3,2,0,0,0,0,2,1
2,0,0,0,0,0,0,0,0,0,0,0,2,2
3,0,0,0,0,0,0,0,0,0,0,0,3,2
3,0,0,0,0,0,0,0,0,0,0,0,0,2
2,0,0,0,0,0,0,0,0,0,0,0,0,2
1,2,0,0,0,0,0,0,0,0,0,0,0,3
1,1,3,0,0,0,0,0,0,0,0,12,2,1
1,1,1,2,0,0,0,0,0,0,0,2,2,1
1,1,1,1,2,3,2,0,12,2,2,2,1,1
1,1,1,1,1,1,2,3,3,1,1,1,1,1
endlayer

layer
1,1,1,2,2,2,2,1,1,1,1,1,1,1
1,1,2,0,0,0,0,2,3,2,1,1,1,1
1,2,0,0,0,0,0,0,0,0,2,1,1,1
1,2,0,0,0,0,0,9,0,9,3,1,1,1
2,0,0,0,0,0,0,0,0,0,3,1,1,1
2,0,0,0,0,0,0,0,0,3,3,3,1,1
2,0,0,0,0,0,2,3,2,2,3,3,1,1
1,2,0,0,0,0,0,2,0,0,2,3,1,1
1,2,0,0,0,0,0,0,0,0,3,2,2,1
1,3,0,0,0,0,0,0,0,0,2,2,2,1
1,2,0,0,0,0,0,0,0,0,0,3,3,1
1,2,0,0,0,0,0,0,0,0,0,2,2,1
1,1,3,2,0,0,0,0,0,0,0,0,2,1
1,1,1,2,2,0,0,0,0,0,0,0,2,1
1,1,1,1,3,2,2,0,0,0,12,2,1,1
1,1,1,1,1,1,3,3,2,3,3,1,1,1
1,1,1,1,1,1,1,1,1,1,1,1,1,1
endlayer

layer
1,1,1,2,2,2,2,2,2,2,1,1,1,1
1,1,2,0,0,0,0,9,0,1,1,1,1,1
1,1,3,0,0,0,0,0,0,0,1,1,1,1
1,1,3,0,0,0,0,0,0,0,0,1,1,1
1,2,0,0,0,0,0,0,0,0,9,1,1,1
1,2,0,0,0,0,0,0,0,0,0,0,1,1
1,3,0,0,0,2,2,9,0,0,0,9,1,1
1,1,2,0,0,2,2,2,2,3,1,1,1,1
1,1,2,0,0,0,2,2,3,2,1,1,1,1
1,1,2,2,0,0,0,0,2,3,1,1,1,1
1,1,2,2,2,0,0,3,2,2,2,1,1,1
1,1,2,2,2,3,2,2,2,2,2,1,1,1
1,1,1,1,2,2,3,3,2,2,3,2,1,1
1,1,1,1,1,2,3,2,3,2,2,2,1,1
1,1,1,1,1,1,1,3,2,2,2,1,1,1
1,1,1,1,1,1,1,1,1,1,1,1,1,1
1,1,1,1,1,1,1,1,1,1,1,1,1,1
endlayer

layer
1,1,1,1,1,1,2,3,1,1,1,1,1,1
1,1,1,3,3,3,0,0,0,0,1,1,1,1
1,1,1,2,0,0,0,0,0,0,0,1,1,1
1,1,1,3,0,0,0,0,0,0,0,0,1,1
1,1,3,2,0,0,0,0,0,0,0,0,0,1
1,1,3,3,3,0,0,0,0,0,0,0,0,1
1,1,2,3,2,3,9,0,0,0,0,0,0,1
1,1,1,2,3,3,3,3,9,0,0,0,0,1
1,1,1,3,2,3,3,2,1,9,0,0,1,1
1,1,1,1,3,3,3,3,1,0,0,1,1,1
1,1,1,1,1,3,3,1,1,1,1,1,1,1
1,1,1,1,1,1,1,1,1,1,1,1,1,1
1,1,1,1,1,1,1,1,1,1,1,1,1,1
1,1,1,1,1,1,1,1,1,1,1,1,1,1
1,1,1,1,1,1,1,1,1,1,1,1,1,1
1,1,1,1,1,1,1,1,1,1,1,1,1,1
1,1,1,1,1,1,1,1,1,1,1,1,1,1
endlayer

