
# Created by Ruins mod version 17.1 Ingame Parser
# authoring Player: ST753M

weight=2
uniqueMinDistance=2000
spawnMinDistance=2000
embed_into_distance=4
acceptable_target_blocks=
unacceptable_target_blocks=flowing_water,water,flowing_lava,lava,ice,bedrock,netherrack,nether_brick,nether_brick_fence,soul_sand,quartz_ore,end_stone,obsidian,iron_bars,Natura:Cloud,slime_grass,slime_congealed,slime_dirt,clouds,natura:clouds,twilightforest:wispy_cloud,twilightforest:fluffy_cloud
dimensions=26,21,21
allowable_overhang=4
max_leveling=0
leveling_buffer=0
preserve_water=0
preserve_lava=0
preventRotation=1

adjoining_template=ST753M/753_Lab_Sidemachine_CB;24;99;6;30
adjoining_template=ST753M/753_Lab_Sidemachine_CB;25;99;-11;30
adjoining_template=ST753M/753_Lab_Sidemachine_CB;-26;99;-7;30
adjoining_template=ST753M/753_Lab_Sidemachine_CB;-24;99;12;30
adjoining_template=taiga/753_Lab_Dish;12;99;26;30
adjoining_template=taiga/753_Lab_Dish;-8;99;27;30
adjoining_template=taiga/753_Lab_Dish;-10;99;-25;30
adjoining_template=taiga/753_Lab_Dish;9;99;-24;30

biomesToSpawnIn=redwood_taiga,dead_forest,darklands,darklands_hills,darklands_plains,ominous_woods,eerie,swamp_defiled,desert_defiled,plains_defiled,hills_defiled,forest_tenebra,forest_vilespine

=0,100,air
rule1=0,100,minecraft:concrete-7
rule2=0,100,minecraft:gravel-0
rule3=0,100,preserveBlock
rule4=0,100,thaumcraft:taint_rock-0
rule5=0,100,minecraft:double_stone_slab-0,minecraft:double_stone_slab-0,minecraft:double_stone_slab-0,minecraft:double_stone_slab-0,minecraft:double_stone_slab-0,minecraft:gravel-0,minecraft:stone-6
rule6=0,100,minecraft:stone-6,minecraft:stone-6,minecraft:stone-6,minecraft:stone-6,minecraft:stone-6,minecraft:stone-6,minecraft:stone-6,minecraft:gravel-0
rule7=0,100,thaumcraft:flux_goo-7
rule8=0,100,thaumcraft:stone_arcane-0
rule9=0,100,thaumcraft:taint_crust-0
rule10=0,100,minecraft:stone_slab-0
rule11=0,100,minecraft:stonebrick-0,minecraft:stonebrick-0,minecraft:stonebrick-0,minecraft:gravel-0
rule12=0,100,thaumcraft:taint_feature-1
rule13=0,100,thaumcraft:crystal_vitium-0
rule14=0,100,thaumcraft:loot_crate_common-0
rule15=0,100,thaumcraft:table_wood-0
rule16=0,100,minecraft:stone_slab-8
rule17=0,100,minecraft:iron_bars-0
rule18=0,100,thaumcraft:taint_geyser-0
rule19=0,100,minecraft:anvil-9
rule20=0,100,thaumcraft:loot_urn_common-0
rule21=0,100,thaumcraft:pillar_arcane-1
rule22=0,100,minecraft:iron_trapdoor-10
rule23=0,100,minecraft:iron_trapdoor-9
rule24=0,100,thaumcraft:pillar_arcane-3
rule25=0,100,thaumcraft:pillar_arcane-0
rule26=0,100,minecraft:iron_block-0
rule27=0,100,minecraft:iron_trapdoor-11
rule28=0,100,minecraft:cobblestone_wall-0
rule29=0,100,thaumcraft:tube-0
rule30=0,100,IInventory;minecraft:chest;thaumcraft:crystal_essence#{Aspects:[{amount:1,key:"ordo"}]}#0#0+thaumcraft:crystal_essence#{Aspects:[{amount:1,key:"victus"}]}#0#6+thaumcraft:grapple_gun#1#0#11+thaumcraft:loot_bag#1#1#13+thaumcraft:ingot#4#2#17+thaumcraft:crystal_essence#{Aspects:[{amount:1,key:"humanus"}]}#0#19+thaumcraft:baubles#1#2#23+thaumcraft:crystal_essence#{Aspects:[{amount:1,key:"auram"}]}#0#25-5
rule31=0,100,minecraft:cauldron-3
rule32=0,100,minecraft:iron_trapdoor-2
rule33=0,100,IInventory;minecraft:chest;thaumcraft:crystal_essence#{Aspects:[{amount:1,key:"permutatio"}]}#0#4+thaumcraft:alumentum#3#0#6+thaumcraft:brain#2#0#9+thaumcraft:loot_bag#1#1#12+thaumcraft:crystal_essence#{Aspects:[{amount:1,key:"vitium"}]}#0#19+thaumcraft:bottle_taint#1#0#23+thaumcraft:crystal_essence#{Aspects:[{amount:1,key:"praecantatio"}]}#0#25-4

layer
1,1,1,1,1,3,3,3,3,3,3,3,3,2,2,2,1,1,1,1,1
1,1,1,1,1,1,1,1,1,1,1,1,1,1,1,1,1,1,1,1,1
1,1,1,1,1,1,1,1,1,1,1,1,1,1,1,1,1,1,1,1,1
1,1,1,1,1,1,1,1,1,1,1,1,1,1,1,1,1,1,1,1,1
1,1,1,1,1,1,1,1,1,1,1,1,1,1,1,1,1,1,1,1,1
2,1,1,1,1,1,1,1,1,1,1,1,1,1,1,1,1,1,1,1,2
2,1,1,1,1,1,1,1,1,1,1,1,1,4,1,1,1,1,1,1,2
2,1,1,1,1,1,1,1,1,1,1,4,4,4,4,1,1,1,1,1,4
2,1,1,1,1,1,1,1,1,1,1,1,4,4,4,4,1,1,1,1,4
3,5,1,1,1,1,1,1,1,1,1,1,4,4,4,1,1,1,1,1,4
3,6,1,1,1,1,1,1,1,1,1,1,4,1,1,1,1,1,1,1,2
2,5,1,1,1,1,1,1,1,1,1,1,1,1,1,1,1,1,1,1,2
2,1,1,1,1,1,1,1,1,1,1,1,1,1,1,1,1,1,1,1,2
2,1,1,1,1,1,1,1,1,1,1,1,1,1,1,1,1,1,1,1,2
2,1,1,1,1,1,1,1,1,1,1,1,1,1,1,1,1,1,1,1,2
2,1,1,1,1,1,1,1,1,1,1,1,1,1,1,1,1,1,1,1,2
1,1,1,1,1,1,1,1,1,1,1,1,1,1,1,1,1,1,1,1,1
1,1,1,1,1,1,1,1,1,1,1,1,1,1,1,1,1,1,1,1,1
1,1,1,1,1,1,1,1,1,1,1,1,1,1,1,1,1,1,1,1,1
1,1,1,1,1,1,1,1,1,1,1,1,1,1,1,1,1,1,1,1,1
1,1,1,1,1,2,2,2,2,2,2,3,3,3,3,2,1,1,1,1,1
endlayer

layer
1,1,1,1,1,3,3,3,3,3,3,3,3,2,2,2,1,1,1,1,1
1,1,1,1,1,1,1,1,1,1,1,1,1,1,1,1,1,1,1,1,1
1,1,1,1,1,1,1,1,1,1,1,1,1,1,1,1,1,1,1,1,1
1,1,1,1,1,1,1,1,1,1,1,1,1,1,1,1,1,1,1,1,1
1,1,1,1,1,1,1,1,1,1,1,1,1,1,1,1,1,1,1,1,1
2,1,1,1,1,1,1,1,1,1,1,1,4,4,1,1,1,1,1,1,4
2,1,1,1,1,1,1,1,1,1,1,4,4,7,4,4,1,1,1,1,4
2,1,1,1,1,1,1,1,1,1,4,7,2,7,7,4,4,1,1,1,4
3,1,1,1,1,1,1,1,1,1,1,4,2,2,7,7,4,1,1,1,4
3,5,1,1,1,1,1,1,1,1,1,4,2,2,2,4,4,1,1,1,4
3,6,1,1,1,1,1,1,1,1,1,1,4,4,4,4,1,1,1,1,4
2,5,1,1,1,1,1,1,1,1,1,1,1,1,4,1,1,1,1,1,2
2,1,1,1,1,1,1,1,1,1,1,1,1,1,1,1,1,1,1,1,2
2,1,1,1,1,1,1,1,1,1,1,1,1,1,1,1,1,1,1,1,3
2,1,1,1,1,1,1,1,1,1,1,1,1,1,1,1,1,1,1,1,2
2,1,1,1,1,1,1,1,1,1,1,1,1,1,1,1,1,1,1,1,2
1,1,1,1,1,1,1,1,1,1,1,1,1,1,1,1,1,1,1,1,1
1,1,1,1,1,1,1,1,1,1,1,1,1,1,1,1,1,1,1,1,1
1,1,1,1,1,1,1,1,1,1,1,1,1,1,1,1,1,1,1,1,1
1,1,1,1,1,1,1,1,1,1,1,1,1,1,1,1,1,1,1,1,1
1,1,1,1,1,2,2,2,2,2,3,3,3,3,3,3,1,1,1,1,1
endlayer

layer
1,1,1,1,1,3,3,3,3,3,3,3,3,2,2,2,1,1,1,1,1
1,1,1,1,1,1,1,1,1,1,1,1,1,1,1,1,1,1,1,1,1
1,1,1,1,4,1,1,1,1,1,1,1,1,1,1,1,1,1,1,1,1
1,1,1,1,1,4,1,1,1,1,1,1,4,1,1,1,1,1,1,1,1
1,1,1,1,1,4,1,1,1,1,1,4,4,4,4,1,1,1,1,1,1
2,1,1,1,1,1,1,1,1,1,4,4,7,4,4,4,4,1,1,1,2
2,1,1,1,1,1,1,1,1,1,4,7,7,7,7,7,4,1,1,1,4
2,1,1,1,1,1,1,1,1,4,7,7,2,7,7,7,7,4,1,1,4
3,1,1,1,1,1,1,1,1,4,4,2,2,2,7,7,7,4,1,1,4
3,5,1,1,1,1,1,1,1,1,4,2,2,2,2,7,7,4,1,1,4
3,5,1,1,1,1,1,1,1,1,4,4,2,2,2,7,4,1,1,1,4
3,5,1,1,1,1,1,1,1,1,1,8,8,4,7,4,4,1,1,1,4
2,1,1,1,1,1,1,1,1,1,1,8,8,4,4,4,1,1,1,1,2
2,1,1,1,1,1,1,1,1,1,1,1,1,1,1,4,1,1,1,1,3
2,1,1,1,1,1,1,1,1,1,1,1,1,1,1,1,1,1,1,1,3
2,1,1,1,1,1,1,1,1,1,1,1,1,1,1,1,1,1,1,1,2
1,1,1,1,1,1,1,1,1,1,1,1,1,1,1,1,1,1,1,1,1
1,1,1,1,1,1,1,1,1,1,1,1,1,1,1,1,1,1,1,1,1
1,1,1,1,1,1,1,1,1,1,1,1,1,1,1,1,1,1,1,1,1
1,1,1,1,1,1,1,1,1,1,1,1,1,1,1,1,1,1,1,1,1
1,1,1,1,1,2,2,3,2,3,3,3,3,3,3,3,1,1,1,1,1
endlayer

layer
3,3,2,2,3,3,3,3,3,3,3,3,3,3,2,2,2,2,3,3,3
3,2,2,4,9,3,3,3,3,3,3,2,2,2,2,2,2,1,4,3,3
2,2,5,4,9,0,3,6,6,6,6,4,4,6,6,6,6,6,5,3,3
2,1,6,6,6,0,9,6,6,6,4,4,7,4,4,4,4,4,6,1,3
2,2,6,6,6,9,6,6,6,4,4,7,7,7,7,4,4,4,4,2,2
3,1,6,6,6,6,4,4,6,4,7,7,7,7,7,7,7,4,6,2,2
2,2,6,6,6,6,6,6,4,4,7,7,7,7,7,7,7,4,4,2,2
3,2,6,6,6,6,6,6,4,7,7,7,2,7,7,7,7,7,4,4,4
3,1,1,6,6,6,6,6,4,7,7,7,2,2,7,7,7,7,4,4,4
3,3,10,6,6,6,6,6,4,4,7,7,2,2,7,7,7,4,4,4,4
3,3,10,6,6,4,4,6,6,4,7,2,2,7,7,7,7,4,6,4,4
3,3,10,6,6,6,6,4,4,4,4,8,8,7,7,7,7,4,6,4,3
3,1,1,6,6,6,4,4,6,6,4,8,8,7,7,7,4,4,6,2,3
2,2,6,6,4,4,4,6,6,6,6,4,4,4,4,7,4,6,6,2,3
2,2,6,4,6,6,4,4,6,6,4,4,6,6,4,4,4,6,6,2,3
2,1,6,6,6,6,6,4,6,4,4,6,6,4,6,6,4,4,6,2,2
2,2,6,6,6,6,4,4,6,6,6,4,6,6,6,6,6,4,6,2,2
2,1,6,6,6,4,4,6,6,6,4,6,6,6,6,6,6,6,6,1,2
3,2,5,6,6,6,6,6,6,6,6,6,6,6,6,6,6,6,5,2,2
3,3,3,1,2,2,2,2,2,2,2,2,3,3,3,1,2,1,2,2,3
3,3,3,2,2,3,2,3,3,3,3,3,3,3,3,3,3,3,3,3,3
endlayer

layer
3,3,2,3,3,3,3,3,3,3,3,3,3,3,3,2,2,2,3,3,3
3,2,2,4,3,3,3,3,3,3,3,3,3,2,2,2,2,1,4,3,3
2,2,5,11,12,0,3,11,11,11,4,4,4,11,11,4,4,11,4,3,3
2,1,11,9,0,0,0,0,0,9,9,13,0,9,0,9,9,9,11,1,3
3,2,11,9,9,0,0,0,0,0,13,0,0,0,0,13,0,9,11,2,2
3,1,11,14,0,0,0,0,0,0,0,0,0,0,0,0,0,0,11,2,3
2,2,11,0,0,0,0,0,0,13,0,0,0,0,0,0,0,13,12,3,3
3,2,11,0,0,0,0,0,0,0,0,0,0,0,0,0,0,0,9,3,3
3,1,2,0,0,0,0,0,0,0,0,0,2,2,0,0,0,0,4,9,3
3,3,0,0,0,0,0,0,0,13,0,0,2,0,0,0,0,9,4,9,3
3,3,0,0,0,0,0,0,0,0,0,0,0,0,0,0,0,13,9,9,3
3,3,0,0,0,0,0,0,0,0,0,9,8,0,0,0,0,0,11,3,3
3,1,1,0,9,0,0,12,0,0,0,8,8,0,0,0,13,9,11,3,3
3,2,11,9,9,0,9,0,0,0,0,9,9,9,13,0,0,0,11,2,3
2,2,4,9,14,0,9,0,0,0,0,0,9,9,0,0,0,15,11,2,3
2,1,11,9,9,9,9,9,0,0,0,0,0,0,0,0,0,15,11,2,2
2,2,11,9,9,9,9,4,9,0,0,0,0,0,0,0,0,0,4,2,2
2,1,11,9,9,4,4,9,9,0,8,0,14,16,5,10,0,0,11,1,2
3,3,5,11,11,4,11,11,11,4,11,11,11,11,11,11,11,11,5,2,3
3,3,3,1,2,2,2,2,3,2,2,3,3,3,3,1,2,1,3,3,3
3,3,3,3,2,3,3,3,3,3,3,3,3,3,3,3,3,3,3,3,3
endlayer

layer
3,3,3,3,3,3,3,3,3,3,3,3,3,3,3,2,2,3,3,3,3
3,3,2,1,3,3,3,3,3,3,3,3,3,3,2,2,2,1,3,3,3
2,2,5,4,4,0,3,11,11,4,4,4,11,11,11,11,4,4,4,3,3
3,1,11,4,0,0,0,0,0,0,9,0,0,0,0,9,9,9,11,1,3
3,3,11,12,0,0,0,0,0,0,0,0,0,0,0,0,0,9,11,2,3
3,1,11,0,0,0,0,0,0,0,0,0,0,0,0,0,0,0,3,3,3
3,3,11,0,0,0,0,0,0,0,0,0,0,0,0,0,0,0,3,3,3
3,3,11,0,0,0,0,0,0,0,0,0,0,0,0,0,0,0,3,3,3
3,1,1,0,0,0,0,0,0,0,0,0,0,0,0,0,0,0,4,3,3
3,3,0,0,0,0,0,0,0,0,0,0,0,0,0,0,0,9,9,9,3
3,3,0,0,0,0,0,0,0,0,0,0,0,0,0,0,0,0,9,3,3
3,3,0,0,0,0,0,0,0,0,0,9,9,0,0,0,0,0,3,3,3
3,1,1,0,0,0,0,0,0,0,0,8,8,0,0,0,0,12,9,3,3
3,3,11,0,0,0,0,0,0,0,0,12,9,9,0,0,0,0,11,3,3
3,2,11,0,0,0,0,0,0,0,0,0,0,0,0,0,0,0,11,2,3
2,1,4,9,12,0,9,0,0,0,0,0,0,0,0,0,0,0,4,2,3
2,2,11,9,9,0,9,12,0,0,0,0,0,0,0,0,0,0,4,2,2
2,1,11,9,9,4,9,9,0,0,8,16,5,10,0,0,0,0,11,1,2
3,3,5,11,4,4,11,11,11,11,11,11,11,11,11,11,11,11,5,3,3
3,3,3,1,2,2,3,3,3,2,3,3,3,3,3,1,3,1,3,3,3
3,3,3,3,3,3,3,3,3,3,3,3,3,3,3,3,3,3,3,3,3
endlayer

layer
3,3,3,3,3,3,3,3,3,3,3,3,3,3,3,3,3,3,3,3,3
3,3,3,1,9,3,3,3,3,3,3,3,3,3,3,3,2,1,3,3,3
3,2,5,11,4,0,3,9,17,4,4,11,17,17,17,11,11,4,5,3,3
3,1,11,9,0,0,0,0,0,0,0,0,0,0,0,12,9,9,11,1,3
3,3,11,0,0,0,0,0,0,0,0,0,0,0,0,0,0,0,11,3,3
3,1,11,0,0,0,0,0,0,0,0,0,0,0,0,0,0,0,11,3,3
3,3,17,0,0,0,0,0,0,0,0,0,0,0,0,0,0,0,3,3,3
3,3,17,0,0,0,0,0,0,0,0,0,0,0,0,0,0,0,3,3,3
3,1,1,0,0,0,0,0,0,0,0,0,0,0,0,0,0,0,9,3,3
3,3,0,0,0,0,0,0,0,0,0,0,0,0,0,0,0,0,9,3,3
3,3,0,0,0,0,0,0,0,0,0,0,0,0,0,0,0,0,12,3,3
3,3,0,0,0,0,0,0,0,0,0,0,0,0,0,0,0,0,3,3,3
3,1,1,0,0,0,0,0,0,0,0,9,18,0,0,0,0,0,11,3,3
3,3,17,0,0,0,0,0,0,0,0,0,9,0,0,0,0,9,11,3,3
3,3,17,0,0,0,0,0,0,0,0,0,0,0,0,0,0,0,4,2,3
3,1,11,0,0,0,0,0,0,0,0,0,0,0,0,0,0,0,11,2,3
2,2,11,9,0,0,9,0,0,0,0,0,0,0,0,0,0,0,4,2,2
3,1,11,9,9,9,9,0,0,16,5,10,0,0,0,0,0,0,4,1,3
3,3,5,4,11,17,17,17,11,11,11,17,17,17,11,11,11,11,5,3,3
3,3,3,1,2,3,3,3,3,2,3,3,3,3,3,1,3,1,3,3,3
3,3,3,3,3,3,3,3,3,3,3,3,3,3,3,3,3,3,3,3,3
endlayer

layer
3,3,3,3,3,3,3,3,3,3,3,3,3,3,3,3,3,3,3,3,3
3,3,3,1,9,3,3,3,3,3,3,3,3,3,3,3,2,1,3,3,3
3,3,5,1,1,1,3,3,4,4,1,1,1,1,1,1,1,1,5,3,3
3,1,1,9,9,0,0,0,0,0,0,0,0,0,0,0,9,9,1,1,3
3,3,1,0,0,0,0,0,0,0,0,0,0,0,0,0,0,0,1,3,3
3,1,1,0,0,0,0,0,0,0,0,0,0,0,0,0,0,0,9,3,3
3,3,1,0,0,0,0,0,0,0,0,0,0,0,0,0,0,0,3,3,3
3,3,1,0,0,0,0,0,0,0,0,0,0,0,0,0,0,0,3,3,3
3,1,1,0,0,0,0,0,0,0,0,0,0,0,0,0,0,0,9,3,3
3,3,0,0,0,0,0,0,0,0,0,0,0,0,0,0,0,0,3,3,3
3,3,0,0,0,0,0,0,0,0,0,0,0,0,0,0,0,3,3,3,3
3,3,0,0,0,0,0,0,0,0,0,0,0,0,0,0,0,3,3,3,3
3,1,1,0,0,0,0,0,0,0,0,0,0,0,0,0,0,9,1,3,3
3,3,1,0,0,0,0,0,0,0,0,0,0,0,0,0,0,9,1,3,3
3,3,1,0,0,0,0,0,0,0,0,0,0,0,0,0,0,9,1,3,3
3,1,1,0,0,0,0,0,0,0,0,0,0,0,0,0,0,0,1,2,3
3,2,1,12,0,0,0,0,0,0,0,0,0,0,0,0,0,0,1,2,3
3,1,1,9,9,0,9,16,5,10,0,0,0,0,0,0,0,0,4,1,3
3,3,5,1,1,1,1,1,1,1,1,1,1,1,1,1,1,1,5,3,3
3,3,3,1,2,3,3,3,3,3,3,3,3,3,3,1,3,1,3,3,3
3,3,3,3,3,3,3,3,3,3,3,3,3,3,3,3,3,3,3,3,3
endlayer

layer
3,16,16,3,3,3,3,3,3,3,3,3,3,3,3,3,16,16,16,16,16
3,1,1,1,3,3,3,3,3,3,3,3,3,3,3,3,16,1,1,1,16
16,1,5,6,6,4,4,3,3,4,4,6,6,6,6,6,6,6,5,1,16
16,1,6,6,6,6,6,9,0,4,4,6,6,6,6,6,4,6,6,1,16
16,16,6,6,6,6,6,4,0,0,4,4,4,4,6,4,4,6,4,16,3
3,1,6,4,6,6,6,4,9,4,4,4,0,4,4,9,4,4,3,3,3
3,5,6,6,4,4,6,4,4,4,4,4,0,0,0,0,0,0,3,3,3
3,16,6,6,6,4,4,4,4,9,0,0,0,0,0,0,0,0,3,3,3
3,1,1,6,6,6,4,4,9,0,0,0,0,0,0,0,0,0,3,3,3
3,3,1,6,6,6,4,9,0,0,0,0,0,0,0,0,0,3,3,3,3
3,16,16,6,6,4,4,4,0,0,0,0,0,0,0,0,0,3,3,3,3
3,1,1,6,4,4,6,4,9,0,0,0,0,0,0,0,0,3,3,3,3
3,1,1,4,6,6,6,4,4,0,0,0,0,0,0,9,4,9,3,3,3
3,16,6,6,6,6,4,4,9,0,0,0,0,0,0,9,4,6,6,3,3
3,5,6,6,6,6,6,6,4,9,4,0,9,4,9,4,4,6,6,3,3
3,1,6,6,6,6,6,4,4,4,4,4,4,4,4,4,6,6,6,3,3
3,2,6,6,6,4,4,6,6,6,6,4,4,6,6,4,4,6,6,16,3
3,1,6,6,6,6,5,10,0,0,0,0,0,16,6,6,4,4,6,1,16
3,3,5,6,6,6,6,6,6,6,6,6,6,6,6,6,6,6,5,1,16
3,3,3,1,3,3,3,3,3,3,3,3,3,3,3,1,16,1,1,1,16
3,3,3,3,3,3,3,3,3,3,3,3,3,3,3,3,16,16,16,16,16
endlayer

layer
3,6,3,3,3,3,3,3,3,3,3,3,3,3,3,3,6,6,6,6,6
6,6,6,6,3,3,3,3,3,3,3,3,3,3,3,3,6,6,6,6,6
6,6,6,6,6,6,9,3,3,3,9,6,6,6,6,6,6,6,6,6,6
6,6,6,6,6,6,6,4,0,9,6,6,6,6,6,6,6,6,6,6,6
6,6,6,6,6,6,6,4,9,0,9,6,6,6,4,4,6,4,6,6,3
3,1,6,6,6,6,6,4,9,9,9,4,4,4,9,0,4,9,9,3,3
3,10,6,6,6,4,6,6,4,9,4,9,4,0,0,0,0,3,3,3,3
3,10,6,6,6,6,4,4,4,4,4,0,0,0,0,0,0,3,3,3,3
3,5,6,6,6,6,6,4,4,9,0,0,0,0,0,0,0,3,3,3,3
3,3,6,6,6,4,4,4,4,9,0,0,0,0,0,0,0,3,3,3,3
3,3,6,6,4,6,6,6,4,4,4,0,0,0,0,9,0,3,3,3,3
3,10,6,6,6,6,4,6,4,4,9,0,0,0,9,4,9,3,3,3,3
3,5,6,6,6,6,6,4,4,9,9,0,9,9,4,4,4,3,3,3,3
3,5,6,6,6,6,4,4,4,4,9,9,4,4,4,4,6,4,3,3,3
3,10,6,6,6,4,6,6,6,4,4,4,4,4,4,6,6,6,6,3,3
3,1,6,6,6,6,6,6,4,6,4,6,6,4,4,6,6,6,6,3,3
3,3,6,6,6,6,6,6,6,6,4,4,6,6,6,6,6,6,6,6,6
3,1,6,6,6,10,0,0,0,0,0,0,4,6,6,6,6,6,6,6,6
3,3,5,6,6,6,6,6,6,6,6,6,6,6,6,6,6,6,6,6,6
3,3,3,1,3,3,3,3,3,3,3,3,3,3,3,1,6,6,6,6,6
3,3,3,3,3,3,3,3,3,3,3,3,3,3,3,3,6,6,6,6,6
endlayer

layer
3,3,3,3,3,3,3,3,3,3,3,3,3,3,3,3,10,10,10,10,10
3,3,3,3,3,3,3,3,3,3,3,3,3,10,10,10,10,3,3,1,10
10,3,2,3,3,3,3,3,3,3,3,3,3,3,2,2,3,3,3,3,10
10,2,2,1,2,1,3,3,0,0,0,0,0,1,2,1,2,3,3,3,3
3,10,5,11,11,11,11,11,0,0,0,11,11,4,11,11,5,2,3,3,3
3,1,11,0,0,15,15,0,0,12,0,0,0,0,12,0,4,1,3,3,3
3,3,11,0,0,0,0,0,0,0,0,0,0,0,0,0,0,3,3,3,3
3,3,11,0,0,19,0,0,0,0,0,0,0,0,0,0,0,3,3,3,3
3,3,11,20,0,19,0,19,0,0,0,0,0,0,0,0,0,3,3,3,3
3,3,11,0,0,0,0,0,0,9,0,0,0,0,0,0,0,3,3,3,3
3,3,11,0,0,0,0,0,0,9,0,0,0,0,0,0,0,3,3,3,3
3,3,11,0,0,0,0,21,0,0,9,0,0,0,0,12,0,3,3,3,3
3,10,11,0,0,0,0,0,0,0,12,0,0,0,0,0,11,3,3,3,3
3,2,11,16,0,0,0,0,0,0,0,0,0,0,0,0,11,3,3,3,3
3,3,11,5,0,0,0,25,0,0,24,0,23,23,22,0,11,3,3,3,3
3,1,11,10,0,0,0,0,0,0,0,0,23,26,23,0,11,0,0,10,3
3,3,11,0,0,0,0,17,17,17,17,0,23,23,27,0,11,0,0,10,10
3,1,11,0,0,0,0,0,0,0,0,0,0,0,0,0,11,1,0,0,10
3,3,5,11,11,11,11,11,11,11,11,11,11,11,11,11,5,0,0,0,10
3,3,3,1,3,3,3,3,3,3,3,3,3,3,3,1,10,0,0,0,10
3,3,3,3,3,3,3,3,3,3,3,3,3,3,3,3,10,10,10,10,10
endlayer

layer
3,3,3,3,3,3,3,3,3,3,3,3,3,3,3,3,3,3,3,3,3
3,3,3,3,3,3,3,3,3,3,3,3,3,3,3,3,3,3,3,28,3
3,3,3,3,3,3,3,3,3,3,3,3,3,3,0,0,3,3,3,3,3
3,3,2,1,3,1,3,3,0,0,0,0,0,1,2,1,2,3,3,3,3
3,3,5,11,11,4,11,11,0,0,0,11,11,4,11,11,5,0,3,3,3
3,1,11,0,0,0,0,0,0,0,0,0,0,0,0,0,11,1,3,3,3
3,3,11,0,0,0,0,0,0,0,0,0,0,0,0,0,11,3,3,3,3
3,3,11,0,0,0,0,0,0,0,0,0,0,0,0,0,0,3,3,3,3
3,3,11,0,0,0,0,0,0,0,0,0,0,0,0,0,0,3,3,3,3
3,3,11,0,0,0,0,0,0,0,0,0,0,0,0,0,0,3,3,3,3
3,3,11,0,0,0,0,0,0,9,0,0,0,0,0,0,0,3,3,3,3
3,3,11,16,0,0,0,0,0,0,0,29,29,0,0,0,11,3,3,3,3
3,3,11,5,0,0,0,0,0,0,0,29,29,0,0,0,11,3,3,3,3
3,3,11,10,0,0,0,0,0,0,0,0,0,0,0,0,11,3,3,3,3
3,3,11,0,0,0,0,0,0,0,0,0,0,0,0,0,11,3,3,3,3
3,1,11,0,0,0,0,0,0,0,0,0,0,0,0,0,11,3,3,3,3
3,3,11,0,0,0,0,0,0,0,0,0,17,0,20,0,11,3,3,3,3
3,1,11,0,0,0,0,0,0,0,0,0,0,0,0,0,11,1,3,3,3
3,3,5,11,11,11,11,11,11,11,11,11,11,11,11,11,5,0,3,3,3
3,3,3,1,3,3,3,3,3,3,3,3,3,3,3,1,0,0,3,3,3
3,3,3,3,3,3,3,3,3,3,3,3,3,3,3,3,3,3,3,3,3
endlayer

layer
3,3,3,3,3,3,3,3,3,3,3,3,3,3,3,3,3,3,3,3,3
3,3,3,3,3,3,3,3,3,3,3,3,3,3,3,3,3,3,3,17,3
3,3,3,3,3,3,3,3,3,3,3,3,3,3,0,0,3,3,3,3,3
3,3,2,1,3,3,3,3,0,0,0,0,0,1,2,1,0,3,3,3,3
3,3,5,11,11,11,11,11,11,0,0,0,11,11,4,11,5,0,3,3,3
3,1,11,0,0,0,0,0,0,0,0,0,0,0,0,0,11,1,3,3,3
3,3,11,0,0,0,0,0,0,0,0,0,0,0,0,0,11,3,3,3,3
3,3,17,0,0,0,0,0,0,0,0,0,0,0,0,0,11,3,3,3,3
3,3,17,0,0,0,0,0,0,0,0,0,0,0,0,0,0,3,3,3,3
3,3,11,16,0,0,0,0,0,0,0,0,0,0,0,0,11,3,3,3,3
3,3,11,5,0,0,0,0,0,0,0,29,29,0,0,0,11,3,3,3,3
3,3,11,10,0,0,0,0,0,0,29,29,29,29,0,0,11,3,3,3,3
3,3,17,0,0,0,0,0,0,0,29,29,29,29,0,0,11,3,3,3,3
3,3,17,0,0,0,0,0,0,0,0,29,29,0,0,0,17,3,3,3,3
3,3,11,0,0,0,0,0,0,0,0,0,0,0,0,0,17,3,3,3,3
3,1,11,0,0,0,0,0,0,0,0,0,0,0,0,0,17,3,3,3,3
3,3,11,0,0,0,0,0,0,0,0,0,0,0,0,0,11,3,3,3,3
3,1,11,0,0,0,0,0,0,0,0,0,0,0,0,0,11,1,3,3,3
3,3,5,11,11,17,17,17,11,11,11,17,17,17,11,11,5,0,3,3,3
3,3,3,1,3,3,3,3,3,3,3,3,3,3,3,1,0,0,3,3,3
3,3,3,3,3,3,3,3,3,3,3,3,3,3,3,3,3,3,3,3,3
endlayer

layer
3,3,3,3,3,3,3,3,3,3,3,3,3,3,3,3,3,3,3,17,3
3,3,3,3,3,3,3,3,3,3,3,3,3,3,3,3,3,3,3,17,17
3,3,3,3,3,3,3,3,3,3,3,3,3,3,0,0,3,3,3,3,3
3,3,3,1,3,3,3,3,0,0,0,0,0,1,0,1,0,3,3,3,3
3,3,5,1,1,1,1,1,1,0,0,1,1,1,1,1,5,0,3,3,3
3,1,1,0,0,0,0,0,0,0,0,0,0,0,0,0,1,1,3,3,3
3,3,1,0,0,0,0,0,0,0,0,0,0,0,0,0,1,3,3,3,3
3,3,1,16,0,0,0,0,0,0,0,0,0,0,0,0,1,3,3,3,3
3,3,1,5,0,0,0,0,0,0,0,0,0,0,0,0,1,3,3,3,3
3,3,1,10,0,0,0,0,0,0,0,29,0,0,0,0,1,3,3,3,3
3,3,1,0,0,0,0,0,0,0,0,29,29,0,0,0,1,3,3,3,3
3,3,1,0,0,0,0,0,0,0,29,8,8,29,0,0,1,3,3,3,3
3,3,1,0,0,0,0,0,0,0,29,8,8,29,0,0,1,3,3,3,3
3,3,1,0,0,0,0,0,0,0,0,29,29,0,0,0,1,3,3,3,3
3,3,1,0,0,0,0,0,0,0,0,0,0,0,0,0,1,3,3,3,3
3,1,1,0,0,0,0,0,0,0,0,0,0,0,0,0,1,3,3,3,3
3,3,1,0,0,0,0,0,0,0,0,0,0,0,0,0,1,3,3,3,3
3,1,1,0,0,0,0,0,0,0,0,0,0,0,0,0,1,1,3,3,3
3,3,5,1,1,1,1,1,1,1,1,1,1,1,1,1,5,0,3,3,3
3,3,3,1,3,3,3,3,3,3,3,3,3,3,3,1,0,0,3,3,3
3,3,3,3,3,3,3,3,3,3,3,3,3,3,3,3,3,3,3,3,3
endlayer

layer
3,3,3,3,3,3,3,3,3,3,3,3,3,3,3,3,3,3,3,17,3
3,3,3,3,3,3,3,3,3,3,3,3,3,3,3,3,3,3,3,0,17
3,3,3,3,3,3,3,3,3,3,3,3,3,3,16,16,16,16,16,3,3
3,3,3,3,3,3,3,3,0,0,0,0,0,1,16,1,1,1,16,3,3
3,3,5,6,6,6,6,6,6,0,0,6,6,6,6,6,5,1,16,3,3
3,1,6,6,6,6,6,6,6,4,0,4,6,6,6,6,6,1,16,3,3
3,3,6,5,4,6,6,4,4,0,0,0,4,6,6,6,6,16,16,3,3
3,3,6,10,6,4,4,4,0,0,0,0,0,4,6,6,6,3,3,3,3
3,3,6,0,0,6,4,0,0,0,0,0,0,4,4,6,6,3,3,3,3
3,3,3,0,0,6,4,0,0,0,0,29,0,4,6,4,6,3,3,3,3
3,3,3,0,6,4,4,4,0,0,0,4,4,6,6,6,6,3,3,3,3
3,3,6,0,4,6,6,6,4,0,4,1,1,6,6,6,6,3,3,3,3
3,3,6,0,6,6,6,4,4,4,6,1,1,6,6,6,6,3,3,3,3
3,3,6,16,6,6,4,4,6,6,4,6,6,6,6,6,6,3,3,3,3
3,3,6,6,6,6,4,6,6,6,4,6,6,6,6,6,6,3,3,3,3
3,1,6,6,6,6,6,6,6,6,6,4,6,6,6,6,6,3,3,3,3
3,16,6,6,6,6,6,6,6,6,6,6,6,6,6,6,6,16,16,3,3
16,1,6,6,6,6,6,6,6,6,6,6,6,6,6,6,6,1,16,3,3
16,1,5,6,6,6,6,6,6,6,6,6,6,6,6,6,5,1,16,3,3
16,1,1,1,16,3,3,3,3,3,3,3,3,3,16,1,1,1,16,3,3
3,3,16,16,3,3,3,3,3,3,3,3,3,3,16,16,16,16,16,3,3
endlayer

layer
3,3,3,3,3,3,3,3,3,3,3,3,3,3,3,3,3,3,3,0,3
3,3,3,3,3,3,3,3,3,3,3,3,3,3,3,3,3,3,3,0,0
3,3,3,3,3,3,3,3,3,3,3,3,3,3,6,6,6,6,6,3,3
3,3,3,3,3,3,3,3,0,0,0,0,0,1,6,6,6,6,6,3,3
3,3,5,6,6,0,0,6,6,6,0,0,6,6,6,6,6,6,6,3,3
3,3,6,10,6,6,6,6,6,6,6,9,6,6,6,6,6,6,6,3,3
3,3,6,0,6,6,6,6,4,4,4,4,6,6,6,6,6,6,6,3,3
3,3,3,0,6,6,4,9,9,0,0,9,4,6,6,6,6,3,3,3,3
3,3,3,0,6,6,9,0,0,0,0,0,4,4,6,6,6,3,3,3,3
3,3,3,0,6,4,9,0,0,0,0,29,4,6,6,6,6,3,3,3,3
3,3,6,0,6,4,9,9,0,0,0,9,4,6,6,6,6,3,3,3,3
3,3,6,0,4,4,4,4,9,0,4,1,1,6,6,6,6,3,3,3,3
3,3,6,6,4,6,4,9,9,4,6,1,1,6,6,6,6,3,3,3,3
3,3,6,4,6,6,9,9,4,4,6,6,6,6,6,6,6,3,3,3,3
3,3,6,6,6,4,9,4,6,6,4,6,6,6,6,6,6,3,3,3,3
3,1,6,6,4,9,4,6,6,6,4,6,4,6,6,6,6,3,3,3,3
3,6,6,6,6,4,6,6,6,6,6,6,6,6,6,6,6,6,6,3,3
6,6,6,6,6,6,6,6,6,6,6,6,6,6,6,6,6,6,6,3,3
6,6,6,6,6,6,6,6,6,6,6,6,6,6,6,6,6,6,6,3,3
3,6,6,6,6,3,3,3,3,3,3,3,3,3,6,6,6,6,6,3,3
3,3,3,6,6,3,3,3,3,3,3,3,3,3,6,6,6,6,6,3,3
endlayer

layer
3,3,3,3,3,3,3,3,3,3,3,3,3,3,3,3,3,3,3,0,3
3,3,3,3,3,3,3,3,3,3,3,3,3,3,3,3,3,3,3,0,0
3,3,3,3,3,3,3,3,3,3,3,3,3,3,10,10,10,10,10,3,3
3,3,3,3,3,3,3,3,0,0,0,0,0,1,10,0,0,0,10,3,3
3,3,5,0,0,0,0,0,11,11,11,0,11,11,5,0,0,0,10,3,3
3,3,3,0,0,0,10,5,16,9,9,12,0,30,11,1,0,0,10,3,3
3,3,3,0,0,0,0,0,9,9,9,9,0,0,11,0,0,10,10,3,3
3,3,3,0,17,0,0,0,9,9,0,0,0,2,11,2,0,10,3,3,3
3,3,3,0,17,0,0,0,0,0,0,0,0,2,4,2,0,10,3,3,3
3,3,3,0,17,0,12,0,0,0,0,29,0,0,4,2,0,10,3,3,3
3,3,3,0,17,0,0,0,0,0,0,0,0,0,11,2,0,10,3,3,3
3,3,11,0,17,0,0,18,0,0,0,8,8,0,11,2,0,10,3,3,3
3,3,4,17,17,0,0,0,0,0,0,8,8,0,11,0,0,10,3,3,3
3,3,11,2,2,0,0,0,0,0,0,0,0,0,11,1,0,10,3,3,3
3,3,11,2,2,0,12,0,0,0,0,0,0,0,11,2,0,10,3,3,3
3,1,11,2,2,0,0,25,31,31,24,0,2,2,11,1,2,10,3,3,3
3,10,5,11,4,4,11,11,11,11,11,4,11,11,5,0,0,10,10,3,3
10,2,2,1,2,2,2,0,2,2,2,2,2,1,0,0,0,0,10,3,3
10,3,2,2,2,2,0,0,2,0,0,2,2,2,0,0,0,0,10,3,3
3,3,3,2,10,10,10,10,10,10,10,10,10,10,10,0,0,1,10,3,3
3,3,3,10,10,3,3,3,3,3,3,3,3,3,10,10,10,10,10,3,3
endlayer

layer
3,3,3,3,3,3,3,3,3,3,3,3,3,3,3,3,3,3,3,0,3
3,3,3,3,3,3,3,3,3,3,3,3,3,3,3,3,3,3,3,0,0
3,3,3,3,3,3,3,3,3,3,3,3,3,3,0,0,0,0,3,3,3
3,3,3,3,3,3,3,3,0,0,0,0,0,1,0,0,0,0,3,3,3
3,3,0,0,0,0,0,11,11,11,11,0,0,0,5,0,0,0,3,3,3
3,3,3,0,0,0,0,0,10,5,16,0,0,0,11,1,0,0,3,3,3
3,3,3,0,0,0,0,0,0,9,9,0,0,0,11,0,0,0,3,3,3
3,3,3,0,0,0,0,0,0,0,0,0,0,2,11,0,0,0,3,3,3
3,3,3,0,0,0,0,0,0,0,0,0,0,0,11,2,0,0,3,3,3
3,3,3,0,0,0,0,0,0,0,0,29,0,0,4,2,0,0,3,3,3
3,3,11,0,0,0,0,0,0,0,0,0,0,0,11,2,0,0,3,3,3
3,3,11,0,0,0,0,0,0,0,0,17,17,0,11,2,0,0,3,3,3
3,3,4,0,0,0,0,0,0,0,0,17,17,0,11,0,0,0,3,3,3
3,3,11,0,0,0,0,0,0,0,0,0,0,0,11,1,0,0,3,3,3
3,3,11,2,0,0,0,0,0,0,0,0,0,0,11,0,0,0,3,3,3
3,1,11,2,2,0,0,0,32,32,0,0,0,2,11,1,0,0,3,3,3
3,0,5,11,11,4,11,11,11,11,11,4,11,11,5,0,0,0,3,3,3
3,0,2,1,2,2,2,0,2,0,2,2,2,1,0,0,0,0,3,3,3
3,3,0,2,2,2,0,0,0,0,0,0,0,0,0,0,0,0,3,3,3
3,3,3,0,0,0,0,0,0,0,0,0,0,0,0,0,0,28,3,3,3
3,3,3,3,3,3,3,3,3,3,3,3,3,3,0,0,0,0,3,3,3
endlayer

layer
3,3,3,3,3,3,3,3,3,3,3,3,3,3,3,3,3,3,3,0,3
3,3,3,3,3,3,3,3,3,3,3,3,3,3,3,3,3,3,3,0,0
3,3,3,3,3,3,3,3,3,3,3,3,3,3,0,0,0,0,3,3,3
3,3,3,3,3,3,3,3,0,0,0,0,0,0,0,0,0,0,3,3,3
3,3,0,0,0,0,11,11,0,11,11,0,0,0,5,0,0,0,3,3,3
3,3,3,0,0,0,0,0,0,0,10,5,16,0,11,1,0,0,3,3,3
3,3,3,0,0,0,0,0,0,9,0,0,0,0,11,0,0,0,3,3,3
3,3,3,0,0,0,0,0,0,0,0,0,0,0,11,0,0,0,3,3,3
3,3,11,0,0,0,0,0,0,0,0,0,0,0,17,0,0,0,3,3,3
3,3,11,0,0,0,0,0,0,0,0,29,0,0,2,2,0,0,3,3,3
3,3,11,0,0,0,0,0,0,0,0,0,0,0,0,2,0,0,3,3,3
3,3,17,0,0,0,0,0,0,0,0,17,17,0,11,0,0,0,3,3,3
3,3,17,0,0,0,0,0,0,0,0,17,17,0,11,0,0,0,3,3,3
3,3,17,0,0,0,0,0,0,0,0,0,0,0,11,1,0,0,3,3,3
3,3,11,0,0,0,0,0,0,0,0,0,0,0,11,0,0,0,3,3,3
3,1,11,2,0,0,0,0,0,0,0,0,0,0,11,1,0,0,3,3,3
3,0,5,11,11,11,4,17,17,17,11,11,4,11,5,0,0,0,3,3,3
3,0,0,1,2,2,2,0,0,0,0,2,2,1,0,0,0,0,3,3,3
3,3,0,0,0,0,0,0,0,0,0,0,0,0,0,0,0,0,3,3,3
3,3,3,0,0,0,0,0,0,0,0,0,0,0,0,0,0,17,3,3,3
3,3,3,3,3,3,3,3,3,3,3,3,3,3,0,0,0,0,3,3,3
endlayer

layer
3,3,3,3,3,3,3,3,3,3,3,3,3,3,3,3,3,3,3,0,3
3,3,3,3,3,3,3,3,3,3,3,3,3,3,3,3,3,3,3,0,0
3,3,3,3,3,3,3,3,3,3,3,3,3,3,0,0,0,0,3,3,3
3,3,3,3,3,3,3,3,0,0,0,0,0,0,0,0,0,0,3,3,3
3,3,0,0,0,0,0,0,0,11,0,0,0,0,5,0,0,0,3,3,3
3,3,3,0,0,0,0,0,0,0,0,0,10,5,1,1,0,0,3,3,3
3,3,3,0,0,0,0,0,0,0,0,0,0,16,1,0,0,0,3,3,3
3,3,3,0,0,0,0,0,0,0,0,0,0,0,1,0,0,0,3,3,3
3,3,1,0,0,0,0,0,0,0,0,0,0,0,1,0,0,0,3,3,3
3,3,1,0,0,0,0,0,0,0,0,29,0,0,1,2,0,0,3,3,3
3,3,1,0,0,0,0,0,0,0,0,0,0,0,1,0,0,0,3,3,3
3,3,1,0,0,0,0,0,0,0,0,8,8,0,1,0,0,0,3,3,3
3,3,1,0,0,0,0,0,0,0,0,8,8,0,1,0,0,0,3,3,3
3,3,1,0,0,0,0,0,0,0,0,0,0,0,1,1,0,0,3,3,3
3,3,1,0,0,0,0,0,0,0,0,0,0,0,1,0,0,0,3,3,3
3,1,1,0,0,0,0,0,0,0,0,0,0,0,1,1,0,0,3,3,3
3,0,5,1,1,1,1,1,1,1,1,1,1,1,5,0,0,0,3,3,3
3,0,0,1,0,2,2,0,0,0,0,2,0,1,0,0,0,0,3,3,3
3,3,0,0,0,0,0,0,0,0,0,0,0,0,0,0,0,0,3,3,3
3,3,3,0,0,0,0,0,0,0,0,0,0,0,0,0,0,17,17,3,3
3,3,3,3,3,3,3,3,3,3,3,3,3,3,0,0,0,17,3,3,3
endlayer

layer
3,3,3,3,3,3,3,3,3,3,3,3,3,3,3,3,3,3,3,0,3
3,3,3,3,3,3,3,3,3,3,3,3,3,3,3,3,3,3,3,0,0
3,3,3,3,3,3,3,3,3,3,3,3,3,3,0,0,0,0,3,3,3
3,3,3,3,3,3,3,3,0,0,0,0,0,0,0,0,0,0,3,3,3
3,3,0,0,0,0,0,0,0,0,0,0,0,0,5,0,0,0,3,3,3
3,3,3,0,0,0,0,0,0,0,0,0,0,0,6,1,0,0,3,3,3
3,3,3,0,0,0,0,0,0,0,0,0,0,10,6,0,0,0,3,3,3
3,3,3,0,0,0,0,0,0,0,0,0,0,5,6,0,0,0,3,3,3
3,3,2,4,9,0,0,0,0,0,0,0,0,4,6,0,0,0,3,3,3
3,3,6,9,0,0,0,0,0,0,0,29,0,4,6,0,0,0,3,3,3
3,3,2,0,0,0,0,0,0,0,29,29,4,6,6,0,0,0,3,3,3
3,3,2,0,4,9,0,0,0,0,29,1,1,6,6,0,0,0,3,3,3
3,3,2,6,6,4,9,0,0,0,9,1,1,6,6,0,0,0,3,3,3
3,3,6,6,6,6,4,9,0,9,4,6,6,6,6,1,0,0,3,3,3
3,16,6,6,6,6,6,4,4,4,6,6,6,6,6,16,16,0,3,3,3
16,1,6,6,6,6,6,6,6,6,6,6,6,6,6,1,16,0,3,3,3
16,1,5,6,6,6,6,6,6,6,6,6,6,6,5,1,16,0,3,3,3
16,1,1,1,16,0,2,0,0,0,0,0,16,1,0,0,0,0,3,3,3
3,16,16,16,16,0,0,0,0,0,0,0,16,16,0,0,0,0,3,3,3
3,3,3,0,0,0,0,0,0,0,0,0,0,0,0,0,0,0,17,3,3
3,3,3,3,3,3,3,3,3,3,3,3,3,3,0,0,0,17,3,3,3
endlayer

layer
3,3,3,3,3,3,3,3,3,3,3,3,3,3,3,3,3,3,3,0,3
3,3,3,3,3,3,3,3,3,3,3,3,3,3,3,3,3,3,3,0,0
3,3,3,3,3,3,3,3,3,3,3,3,3,3,0,0,0,0,3,3,3
3,3,3,3,3,3,3,3,0,0,0,0,0,0,0,0,0,0,3,3,3
3,3,0,0,0,0,0,0,0,0,0,0,0,0,0,0,0,0,3,3,3
3,3,3,0,0,0,0,0,0,0,0,0,0,0,0,0,0,0,3,3,3
3,3,3,0,0,0,0,0,0,0,0,0,0,0,0,0,0,0,3,3,3
3,3,3,0,11,0,0,0,0,0,0,0,0,0,6,0,0,0,3,3,3
3,3,0,6,4,0,0,0,0,0,0,0,0,10,6,0,0,0,3,3,3
3,3,2,2,4,9,0,0,0,0,0,0,4,6,6,0,0,0,3,3,3
3,3,2,6,4,4,9,0,0,0,0,4,6,6,6,0,0,0,3,3,3
3,3,6,6,6,4,4,0,0,4,29,1,1,6,6,0,0,0,3,3,3
3,3,6,6,6,6,4,4,9,4,4,1,1,6,6,0,0,0,3,3,3
3,3,6,6,6,6,6,4,4,4,6,6,6,6,6,1,0,0,3,3,3
6,6,6,6,6,6,6,6,6,6,6,6,6,6,6,6,0,0,3,3,3
6,6,6,6,6,6,6,6,6,6,6,6,6,6,6,6,6,0,3,3,3
6,6,6,6,6,6,6,6,6,6,6,6,6,6,6,6,6,0,3,3,3
6,6,6,6,6,0,0,0,0,0,0,0,6,6,6,0,6,0,3,3,3
3,6,6,6,6,0,0,0,0,0,0,0,6,6,0,0,0,0,3,3,3
3,3,3,0,0,0,0,0,0,0,0,0,0,0,0,0,0,0,3,3,3
3,3,3,3,3,3,3,3,3,3,3,3,3,3,0,0,0,0,3,3,3
endlayer

layer
3,3,3,3,3,3,3,3,3,3,3,3,3,3,3,3,3,3,3,0,3
3,3,3,3,3,3,3,3,3,3,3,3,3,3,3,3,3,3,3,0,0
3,3,3,3,3,3,3,3,3,3,3,3,3,3,0,0,0,0,3,3,3
3,3,3,3,3,3,3,3,0,0,0,0,0,0,0,0,0,0,3,3,3
3,3,0,0,0,0,0,0,0,0,0,0,0,0,0,0,0,0,3,3,3
3,3,3,0,0,0,0,0,0,0,0,0,0,0,0,0,0,0,3,3,3
3,3,3,0,0,0,0,0,0,0,0,0,0,0,0,0,0,0,3,3,3
3,3,3,0,11,0,0,0,0,0,0,0,0,0,11,0,0,0,3,3,3
3,3,0,0,11,0,0,0,0,0,0,0,0,0,11,0,0,0,3,3,3
3,3,2,0,11,0,0,0,0,0,0,0,0,0,11,0,0,0,3,3,3
3,3,2,2,2,0,0,0,0,0,0,0,18,0,0,0,0,0,3,3,3
3,3,2,2,11,21,0,0,0,0,29,8,8,0,11,0,0,0,3,3,3
3,10,0,0,11,2,0,0,12,0,0,8,8,29,11,0,0,0,3,3,3
3,10,0,1,4,25,33,24,2,0,0,0,29,29,11,1,0,0,3,3,3
10,10,0,2,5,11,11,2,11,11,11,0,29,11,5,10,0,0,3,3,3
10,0,0,0,0,1,0,2,0,0,0,0,29,1,29,0,10,0,3,3,3
0,2,0,0,0,0,0,0,0,0,0,0,29,29,29,0,10,0,3,3,3
0,0,2,0,10,10,10,0,0,0,10,10,10,0,0,0,10,0,3,3,3
3,0,0,10,10,0,0,0,0,0,0,0,10,0,0,0,0,0,3,3,3
3,3,3,0,0,0,0,0,0,0,0,0,0,0,0,0,0,0,3,3,3
3,3,3,3,3,3,3,3,3,3,3,3,3,3,0,0,0,0,3,3,3
endlayer

layer
3,3,3,3,3,3,3,3,3,3,3,3,3,3,3,3,3,3,3,0,3
3,3,3,3,3,3,3,3,3,3,3,3,3,3,3,3,3,3,3,0,0
3,3,3,3,3,3,3,3,3,3,3,3,3,3,0,0,0,0,3,3,3
3,3,3,3,3,3,3,3,0,0,0,0,0,0,0,0,0,0,3,3,3
3,3,0,0,0,0,0,0,0,0,0,0,0,0,0,0,0,0,3,3,3
3,3,3,0,0,0,0,0,0,0,0,0,0,0,0,0,0,0,3,3,3
3,3,3,0,0,0,0,0,0,0,0,0,0,0,0,0,0,0,3,3,3
3,3,3,0,0,0,0,0,0,0,0,0,0,0,0,0,0,0,3,3,3
3,3,0,0,11,0,0,0,0,0,0,0,0,0,0,0,0,0,3,3,3
3,3,0,0,0,0,0,0,0,0,0,0,0,0,0,0,0,0,3,3,3
3,3,2,2,0,0,0,0,0,0,0,0,0,0,0,0,0,0,3,3,3
3,3,0,2,11,0,0,0,0,0,29,29,29,0,0,0,0,0,3,3,3
3,0,0,0,11,2,0,0,0,0,0,29,29,29,11,0,0,0,3,3,3
3,0,0,1,11,0,0,0,2,0,0,0,0,0,0,0,0,0,3,3,3
0,0,0,0,5,2,2,2,11,11,0,0,0,0,0,0,0,0,3,3,3
0,0,0,0,0,1,0,0,0,0,0,0,0,1,0,0,0,0,3,3,3
0,0,0,0,0,0,0,0,0,0,0,0,0,0,0,0,0,0,3,3,3
0,0,0,0,0,0,0,0,0,0,0,0,0,0,0,0,0,0,3,3,3
3,0,0,0,0,0,0,0,0,0,0,0,0,0,0,0,0,0,3,3,3
3,3,3,0,0,0,0,0,0,0,0,0,0,0,0,0,0,0,3,3,3
3,3,3,3,3,3,3,3,3,3,3,3,3,3,0,0,0,0,3,3,3
endlayer

layer
3,3,3,3,3,3,3,3,3,3,3,3,3,3,3,3,3,3,3,0,3
3,3,3,3,3,3,3,3,3,3,3,3,3,3,3,3,3,3,3,0,0
3,3,3,3,3,3,3,3,3,3,3,3,3,3,0,0,0,0,3,3,3
3,3,3,3,3,3,3,3,0,0,0,0,0,0,0,0,0,0,3,3,3
3,3,0,0,0,0,0,0,0,0,0,0,0,0,0,0,0,0,3,3,3
3,3,3,0,0,0,0,0,0,0,0,0,0,0,0,0,0,0,3,3,3
3,3,3,0,0,0,0,0,0,0,0,0,0,0,0,0,0,0,3,3,3
3,3,3,0,0,0,0,0,0,0,0,0,0,0,0,0,0,0,3,3,3
3,3,0,0,0,0,0,0,0,0,0,0,0,0,0,0,0,0,3,3,3
3,3,0,0,0,0,0,0,0,0,0,0,0,0,0,0,0,0,3,3,3
3,3,0,0,0,0,0,0,0,0,0,29,0,0,0,0,0,0,3,3,3
3,3,0,0,0,0,0,0,0,0,0,29,0,0,0,0,0,0,3,3,3
3,0,0,0,11,0,0,0,0,0,0,0,29,0,0,0,0,0,3,3,3
3,0,0,0,2,0,0,0,0,0,0,29,29,0,0,0,0,0,3,3,3
0,0,0,0,0,2,2,2,0,11,0,0,0,0,0,0,0,0,3,3,3
0,0,0,0,0,0,0,0,0,0,0,0,0,0,0,0,0,0,3,3,3
0,0,0,0,0,0,0,0,0,0,0,0,0,0,0,0,0,0,3,3,3
0,0,0,0,0,0,0,0,0,0,0,0,0,0,0,0,0,0,3,3,3
3,0,0,0,0,0,0,0,0,0,0,0,0,0,0,0,0,0,3,3,3
3,3,3,0,0,0,0,0,0,0,0,0,0,0,0,0,0,0,3,3,3
3,3,3,3,3,3,3,3,3,3,3,3,3,3,0,0,0,0,3,3,3
endlayer

layer
3,3,3,3,3,3,3,3,3,3,3,3,3,3,3,3,3,3,3,0,3
3,3,3,3,3,3,3,3,3,3,3,3,3,3,3,3,3,3,3,0,0
3,3,3,3,3,3,3,3,3,3,3,3,3,3,0,0,0,0,3,3,3
3,3,3,3,3,3,3,3,0,0,0,0,0,0,0,0,0,0,3,3,3
3,3,0,0,0,0,0,0,0,0,0,0,0,0,0,0,0,0,3,3,3
3,3,3,0,0,0,0,0,0,0,0,0,0,0,0,0,0,0,3,3,3
3,3,3,0,0,0,0,0,0,0,0,0,0,0,0,0,0,0,3,3,3
3,3,3,0,0,0,0,0,0,0,0,0,0,0,0,0,0,0,3,3,3
3,3,0,0,0,0,0,0,0,0,0,0,0,0,0,0,0,0,3,3,3
3,3,0,0,0,0,0,0,0,0,0,0,0,0,0,0,0,0,3,3,3
3,3,0,0,0,0,0,0,0,0,0,29,0,0,0,0,0,0,3,3,3
3,3,0,0,0,0,0,0,0,0,0,0,0,0,0,0,0,0,3,3,3
3,0,0,0,0,0,0,0,0,0,0,0,0,0,0,0,0,0,3,3,3
3,0,0,0,0,0,0,0,0,0,0,0,0,0,0,0,0,0,3,3,3
0,0,0,0,0,2,2,0,0,0,0,0,0,0,0,0,0,0,3,3,3
0,0,0,0,0,0,0,0,0,0,0,0,0,0,0,0,0,0,3,3,3
0,0,0,0,0,0,0,0,0,0,0,0,0,0,0,0,0,0,3,3,3
0,0,0,0,0,0,0,0,0,0,0,0,0,0,0,0,0,0,3,3,3
3,0,0,0,0,0,0,0,0,0,0,0,0,0,0,0,0,0,3,3,3
3,3,3,0,0,0,0,0,0,0,0,0,0,0,0,0,0,0,3,3,3
3,3,3,3,3,3,3,3,3,3,3,3,3,3,0,0,0,0,3,3,3
endlayer

