
# Created by Ruins mod version 17.1 Ingame Parser
# authoring Player: ST753M

weight=1
embed_into_distance=3
acceptable_target_blocks=
unacceptable_target_blocks=flowing_water,water,flowing_lava,lava,ice,bedrock,netherrack,nether_brick,nether_brick_fence,soul_sand,quartz_ore,end_stone,obsidian,iron_bars,Natura:Cloud,slime_grass,slime_congealed,slime_dirt,clouds,natura:clouds,twilightforest:wispy_cloud,twilightforest:fluffy_cloud
dimensions=15,16,16
allowable_overhang=3
max_leveling=0
leveling_buffer=0
preserve_water=0
preserve_lava=0

biomesToSpawnIn=eucalyptus_forest

=0,100,air
rule1=0,100,preserveBlock
rule2=0,100,biomesoplenty:log_3-7
rule3=0,100,biomesoplenty:log_3-3
rule4=0,100,biomesoplenty:planks_0-15
rule5=0,100,biomesoplenty:log_3-11
rule6=0,100,minecraft:spruce_fence-0
rule7=0,100,biomesoplenty:eucalyptus_door_block-2
rule8=0,100,biomesoplenty:eucalyptus_stairs-0

rule9=0,50,minecraft:crafting_table-0,minecraft:furnace-2,minecraft:redstone_lamp-0,minecraft:trapped_chest-2,minecraft:anvil-0,minecraft:lit_pumpkin-2,biomesoplenty:eucalyptus_fence-0,minecraft:anvil-5,minecraft:jukebox-0,biomesoplenty:planks_0-15,minecraft:anvil-9,minecraft:enchanting_table-0,biomesoplenty:wood_slab_1-15,minecraft:ender_chest-2,minecraft:bookshelf-0,biomesoplenty:log_3-7,minecraft:noteblock-0,minecraft:piston-1,minecraft:cobblestone_wall-0,minecraft:crafting_table-0,minecraft:crafting_table-0,minecraft:anvil-5,minecraft:bookshelf-0,minecraft:bookshelf-0,minecraft:bookshelf-0,minecraft:bookshelf-0

rule10=0,100,biomesoplenty:eucalyptus_door_block-9
rule11=0,100,biomesoplenty:eucalyptus_door_block-8
rule12=0,100,minecraft:stained_glass_pane-1
rule13=0,100,biomesoplenty:eucalyptus_stairs-7
rule14=1,100,minecraft:carpet-1
rule15=0,100,biomesoplenty:eucalyptus_stairs-2
rule16=0,100,biomesoplenty:eucalyptus_stairs-4
rule17=0,100,biomesoplenty:mud_brick_stairs-4
rule18=0,100,biomesoplenty:eucalyptus_stairs-6
rule19=0,100,biomesoplenty:mud_brick_stairs-6
rule20=0,100,biomesoplenty:mud_brick_stairs-7
rule21=0,100,biomesoplenty:mud_brick_stairs-5
rule22=0,100,biomesoplenty:eucalyptus_stairs-5
rule23=0,100,teBlock;minecraft:bed;{color:14,x:-3517,y:120,z:-1566,id:"minecraft:bed"}-9
rule24=0,100,teBlock;minecraft:bed;{color:14,x:-3516,y:120,z:-1566,id:"minecraft:bed"}-1
rule25=0,100,teBlock;minecraft:bed;{color:5,x:-3516,y:120,z:-1557,id:"minecraft:bed"}-0
rule26=0,100,teBlock;minecraft:bed;{color:5,x:-3516,y:120,z:-1556,id:"minecraft:bed"}-8
rule27=0,90,ChestGenHook:chests/spawn_bonus_chest:3-2
rule28=0,100,teBlock;minecraft:bed;{color:9,x:-3507,y:120,z:-1567,id:"minecraft:bed"}-10
rule29=0,100,teBlock;minecraft:bed;{color:9,x:-3507,y:120,z:-1566,id:"minecraft:bed"}-2
rule30=0,10,ChestGenHook:chests/jungle_temple:3-4
rule31=0,100,minecraft:furnace-4
rule32=1,100,minecraft:brewing_stand-0
rule33=1,100,teBlock;minecraft:flower_pot;{Item:"minecraft:cactus",Data:0,id:"minecraft:flower_pot"}-0
rule34=1,100,minecraft:cake-0,air
rule35=0,100,biomesoplenty:mud_brick_stairs-2
rule36=0,100,biomesoplenty:mud_brick_stairs-0
rule37=0,100,biomesoplenty:mud_brick_stairs-3
rule38=0,100,biomesoplenty:mud_brick_stairs-1
rule39=0,100,biomesoplenty:mud_brick_block-0

layer
1,1,1,1,1,1,1,1,1,1,1,1,1,1,1,1
1,1,1,1,1,1,1,1,1,1,1,1,1,1,1,1
1,1,2,1,1,1,1,1,1,1,1,1,1,2,1,1
1,1,1,1,1,2,1,1,1,1,2,1,1,1,1,1
1,1,1,1,1,1,1,3,3,1,1,1,1,1,1,1
1,1,1,2,1,2,1,3,3,1,2,1,2,1,1,1
1,1,1,1,1,1,4,4,4,4,1,1,1,1,1,1
1,1,1,1,1,1,4,4,4,4,1,1,1,1,1,1
1,1,1,1,1,1,4,4,4,4,1,1,1,1,1,1
1,1,1,1,1,1,4,4,4,4,1,1,1,1,1,1
1,1,1,2,1,2,1,1,1,1,2,1,2,1,1,1
1,1,1,1,1,1,1,1,1,1,1,1,1,1,1,1
1,1,1,1,1,2,1,1,1,1,2,1,1,1,1,1
1,1,2,1,1,1,1,1,1,1,1,1,1,2,1,1
1,1,1,1,1,1,1,1,1,1,1,1,1,1,1,1
1,1,1,1,1,1,1,1,1,1,1,1,1,1,1,1
endlayer

layer
1,1,1,1,1,1,1,1,1,1,1,1,1,1,1,1
1,1,1,1,1,1,1,1,1,1,1,1,1,1,1,1
1,1,2,1,1,1,1,1,1,1,1,1,1,2,1,1
1,1,1,1,1,2,1,1,1,1,2,1,1,1,1,1
1,1,1,1,1,1,1,5,5,1,1,1,1,1,1,1
1,1,1,2,1,2,1,3,3,1,2,1,2,1,1,1
1,1,1,1,1,1,4,4,4,4,1,1,1,1,1,1
1,1,1,1,1,1,4,4,4,4,1,1,1,1,1,1
1,1,1,1,1,1,4,4,4,4,1,1,1,1,1,1
1,1,1,1,1,1,4,4,4,4,1,1,1,1,1,1
1,1,1,2,1,2,1,1,1,1,2,1,2,1,1,1
1,1,1,1,1,1,1,1,1,1,1,1,1,1,1,1
1,1,1,1,1,2,1,1,1,1,2,1,1,1,1,1
1,1,2,1,1,1,1,1,1,1,1,1,1,2,1,1
1,1,1,1,1,1,1,1,1,1,1,1,1,1,1,1
1,1,1,1,1,1,1,1,1,1,1,1,1,1,1,1
endlayer

layer
1,1,1,1,1,1,1,1,1,1,1,1,1,1,1,1
1,1,1,1,1,1,1,1,1,1,1,1,1,1,1,1
1,1,2,1,1,1,1,1,1,1,1,1,1,2,1,1
1,1,1,1,1,2,1,1,1,1,2,1,1,1,1,1
1,1,1,1,1,3,1,1,1,1,3,1,1,1,1,1
1,1,1,2,5,2,5,5,5,5,2,5,2,1,1,1
1,1,1,1,1,3,4,4,4,4,3,1,1,1,1,1
1,1,1,1,1,3,4,4,4,4,3,1,1,1,1,1
1,1,1,1,1,3,4,4,4,4,3,1,1,1,1,1
1,1,1,1,1,3,4,4,4,4,3,1,1,1,1,1
1,1,1,2,5,2,5,5,5,5,2,5,2,1,1,1
1,1,1,1,1,3,1,1,1,1,3,1,1,1,1,1
1,1,1,1,1,2,1,1,1,1,2,1,1,1,1,1
1,1,2,1,1,1,1,1,1,1,1,1,1,2,1,1
1,1,1,1,1,1,1,1,1,1,1,1,1,1,1,1
1,1,1,1,1,1,1,1,1,1,1,1,1,1,1,1
endlayer

layer
1,1,1,1,1,1,1,1,1,1,1,1,1,1,1,1
1,1,1,1,1,1,1,1,1,1,1,1,1,1,1,1
1,1,2,1,1,1,1,1,1,1,1,1,1,2,1,1
1,1,1,1,1,2,1,1,1,1,2,1,1,1,1,1
1,1,1,1,1,6,1,1,1,1,6,1,1,1,1,1
1,1,1,2,6,2,4,7,7,4,2,6,2,1,1,1
1,1,1,1,1,4,0,0,0,0,4,1,1,1,1,1
1,1,1,1,1,4,0,0,0,0,4,1,1,1,1,1
1,1,1,1,1,4,0,0,0,8,4,1,1,1,1,1
1,1,1,1,1,4,9,0,0,4,4,1,1,1,1,1
1,1,1,2,6,2,4,4,4,4,2,6,2,1,1,1
1,1,1,1,1,6,1,1,1,1,6,1,1,1,1,1
1,1,1,1,1,2,1,1,1,1,2,1,1,1,1,1
1,1,2,1,1,1,1,1,1,1,1,1,1,2,1,1
1,1,1,1,1,1,1,1,1,1,1,1,1,1,1,1
1,1,1,1,1,1,1,1,1,1,1,1,1,1,1,1
endlayer

layer
1,1,1,1,1,1,1,1,1,1,1,1,1,1,1,1
1,1,1,1,1,1,1,1,1,1,1,1,1,1,1,1
1,1,2,1,1,1,1,1,1,1,1,1,1,2,1,1
1,1,1,1,1,2,1,1,1,1,2,1,1,1,1,1
1,1,1,1,1,6,1,1,1,1,6,1,1,1,1,1
1,1,1,2,6,2,4,11,10,4,2,6,2,1,1,1
1,1,1,1,1,4,0,0,0,0,4,1,1,1,1,1
1,1,1,1,1,12,0,0,0,0,12,1,1,1,1,1
1,1,1,1,1,12,0,0,0,0,12,1,1,1,1,1
1,1,1,1,1,4,14,0,13,8,4,1,1,1,1,1
1,1,1,2,6,2,4,12,12,4,2,6,2,1,1,1
1,1,1,1,1,6,1,1,1,1,6,1,1,1,1,1
1,1,1,1,1,2,1,1,1,1,2,1,1,1,1,1
1,1,2,1,1,1,1,1,1,1,1,1,1,2,1,1
1,1,1,1,1,1,1,1,1,1,1,1,1,1,1,1
1,1,1,1,1,1,1,1,1,1,1,1,1,1,1,1
endlayer

layer
1,1,1,1,1,1,1,1,1,1,1,1,1,1,1,1
1,1,1,1,1,1,1,1,1,1,1,1,1,1,1,1
1,1,2,1,1,1,1,1,1,1,1,1,1,2,1,1
1,1,1,1,1,2,1,1,1,1,2,1,1,1,1,1
1,1,1,1,1,6,1,1,1,1,6,1,1,1,1,1
1,1,1,2,6,2,4,4,4,4,2,6,2,1,1,1
1,1,1,1,1,4,0,0,0,0,4,1,1,1,1,1
1,1,1,1,1,4,0,0,0,0,4,1,1,1,1,1
1,1,1,1,1,4,0,0,0,0,4,1,1,1,1,1
1,1,1,1,1,4,0,13,15,0,4,1,1,1,1,1
1,1,1,2,6,2,4,4,4,4,2,6,2,1,1,1
1,1,1,1,1,6,1,1,1,1,6,1,1,1,1,1
1,1,1,1,1,2,1,1,1,1,2,1,1,1,1,1
1,1,2,1,1,1,1,1,1,1,1,1,1,2,1,1
1,1,1,1,1,1,1,1,1,1,1,1,1,1,1,1
1,1,1,1,1,1,1,1,1,1,1,1,1,1,1,1
endlayer

layer
1,1,1,1,1,1,1,1,1,1,1,1,1,1,1,1
1,1,1,1,1,1,1,1,1,1,1,1,1,1,1,1
1,1,2,1,1,16,1,1,1,1,16,1,1,2,1,1
1,1,1,1,1,3,1,1,1,1,3,1,1,1,1,1
1,1,1,1,1,3,17,17,17,17,3,1,1,1,1,1
1,1,13,5,5,2,4,4,4,4,2,5,5,18,1,1
1,1,1,1,20,4,0,0,0,0,4,19,1,1,1,1
1,1,1,1,20,4,0,0,0,0,4,19,1,1,1,1
1,1,1,1,20,4,0,0,0,0,4,19,1,1,1,1
1,1,1,1,20,4,13,15,0,0,4,19,1,1,1,1
1,1,13,5,5,2,4,4,4,4,2,5,5,18,1,1
1,1,1,1,1,3,21,21,21,21,3,1,1,1,1,1
1,1,1,1,1,3,1,1,1,1,3,1,1,1,1,1
1,1,2,1,1,22,1,1,1,1,22,1,1,2,1,1
1,1,1,1,1,1,1,1,1,1,1,1,1,1,1,1
1,1,1,1,1,1,1,1,1,1,1,1,1,1,1,1
endlayer

layer
1,1,1,1,1,1,1,1,1,1,1,1,1,1,1,1
1,16,17,17,17,3,1,1,1,1,3,17,17,17,16,1
1,20,3,5,5,3,5,5,5,5,3,5,5,5,19,1
1,20,3,4,4,3,4,4,4,4,3,4,4,3,19,1
1,20,3,4,4,3,4,4,4,4,3,4,4,3,19,1
1,5,5,5,5,2,5,5,5,5,2,5,5,5,5,1
1,1,3,4,4,3,4,4,4,4,3,4,4,3,1,1
1,1,3,4,4,3,4,4,4,4,3,4,4,3,1,1
1,1,3,4,4,3,4,4,4,4,3,4,4,3,1,1
1,1,3,4,4,3,15,0,0,0,3,4,4,3,1,1
1,5,5,5,5,2,5,5,5,5,2,5,5,5,5,1
1,20,3,4,4,3,4,4,4,4,3,4,4,3,19,1
1,20,3,4,4,3,4,4,4,4,3,4,4,3,19,1
1,20,3,5,5,3,5,5,5,5,3,5,5,3,19,1
1,13,21,21,21,3,1,1,1,1,3,21,21,21,18,1
1,1,1,1,1,1,1,1,1,1,1,1,1,1,1,1
endlayer

layer
1,1,1,1,1,1,1,1,1,1,1,1,1,1,1,1
1,2,4,4,4,2,1,1,1,1,2,4,4,4,2,1
1,4,0,0,0,2,4,4,4,4,2,0,23,0,4,1
1,4,26,25,0,0,0,0,0,0,0,0,24,0,4,1
1,4,0,0,0,0,0,0,0,0,0,0,0,0,4,1
1,2,2,0,0,2,6,6,6,6,2,0,0,2,2,1
1,1,4,0,0,6,9,9,9,9,6,0,0,4,1,1
1,1,4,0,0,0,0,0,0,0,0,0,0,4,1,1
1,1,4,0,0,0,0,0,0,0,0,0,0,4,1,1
1,1,4,0,0,6,0,0,0,0,6,0,0,4,1,1
1,2,2,0,0,2,6,6,6,6,2,0,0,2,2,1
1,4,27,0,0,0,0,0,0,0,0,0,0,0,4,1
1,4,9,0,0,0,0,0,0,0,0,0,29,28,4,1
1,4,4,31,30,2,4,4,4,4,2,0,0,0,4,1
1,2,4,4,4,2,1,1,1,1,2,4,4,4,2,1
1,1,1,1,1,1,1,1,1,1,1,1,1,1,1,1
endlayer

layer
1,1,1,1,1,1,1,1,1,1,1,1,1,1,1,1
1,2,4,12,4,2,1,1,1,1,2,4,12,4,2,1
1,4,0,0,0,2,4,12,12,4,2,0,0,0,4,1
1,12,0,0,0,0,0,0,0,0,0,0,0,0,12,1
1,4,0,0,0,0,0,0,0,0,0,0,0,0,4,1
1,2,2,0,0,2,0,0,0,0,2,0,0,2,2,1
1,1,4,0,0,0,33,0,32,0,0,0,0,4,1,1
1,1,12,0,0,0,0,0,0,0,0,0,0,12,1,1
1,1,12,0,0,0,0,0,0,0,0,0,0,12,1,1
1,1,4,0,0,0,0,0,0,0,0,0,0,4,1,1
1,2,2,0,0,2,0,0,0,0,2,0,0,2,2,1
1,4,0,0,0,0,0,0,0,0,0,0,0,0,4,1
1,12,34,0,0,0,0,0,0,0,0,0,0,0,12,1
1,4,14,14,0,2,4,12,12,4,2,0,0,0,4,1
1,2,4,12,4,2,1,1,1,1,2,4,12,4,2,1
1,1,1,1,1,1,1,1,1,1,1,1,1,1,1,1
endlayer

layer
1,1,1,1,1,1,1,1,1,1,1,1,1,1,1,1
1,2,4,12,4,2,1,1,1,1,2,4,12,4,2,1
1,4,0,0,0,2,4,12,12,4,2,0,0,0,4,1
1,12,0,0,0,0,0,0,0,0,0,0,0,0,12,1
1,4,0,0,0,0,0,0,0,0,0,0,0,0,4,1
1,2,2,0,0,2,0,0,0,0,2,0,0,2,2,1
1,1,4,0,0,0,0,0,0,0,0,0,0,4,1,1
1,1,12,0,0,0,0,0,0,0,0,0,0,12,1,1
1,1,12,0,0,0,0,0,0,0,0,0,0,12,1,1
1,1,4,0,0,0,0,0,0,0,0,0,0,4,1,1
1,2,2,0,0,2,0,0,0,0,2,0,0,2,2,1
1,4,0,0,0,0,0,0,0,0,0,0,0,0,4,1
1,12,0,0,0,0,0,0,0,0,0,0,0,0,12,1
1,4,0,0,0,2,4,12,12,4,2,0,0,0,4,1
1,2,4,12,4,2,1,1,1,1,2,4,12,4,2,1
1,1,1,1,1,1,1,1,1,1,1,1,1,1,1,1
endlayer

layer
1,1,1,1,1,1,1,1,1,1,1,1,1,1,1,1
1,2,4,4,4,2,1,1,1,1,2,4,4,4,2,1
1,4,0,0,0,2,4,4,4,4,2,0,0,0,4,1
1,4,0,0,0,3,0,0,0,0,3,0,0,0,4,1
1,4,0,0,0,3,0,0,0,0,3,0,0,0,4,1
1,2,2,5,5,2,0,0,0,0,2,5,5,2,2,1
1,1,4,0,0,0,0,0,0,0,0,0,0,4,1,1
1,1,4,0,0,0,0,0,0,0,0,0,0,4,1,1
1,1,4,0,0,0,0,0,0,0,0,0,0,4,1,1
1,1,4,0,0,0,0,0,0,0,0,0,0,4,1,1
1,2,2,5,5,2,0,0,0,0,2,5,5,2,2,1
1,4,0,0,0,3,0,0,0,0,3,0,0,0,4,1
1,4,0,0,0,3,0,0,0,0,3,0,0,0,4,1
1,4,0,0,0,2,4,4,4,4,2,0,0,0,4,1
1,2,4,4,4,2,1,1,1,1,2,4,4,4,2,1
1,1,1,1,1,1,1,1,1,1,1,1,1,1,1,1
endlayer

layer
37,36,36,36,36,36,35,1,1,37,36,36,36,36,36,35
37,2,5,5,5,2,36,36,36,36,2,5,5,5,2,35
37,3,0,0,0,2,4,4,4,4,2,0,0,0,3,35
37,3,0,0,0,6,0,0,0,0,6,0,0,0,3,35
37,3,0,0,0,6,0,0,0,0,6,0,0,0,3,35
37,2,2,6,6,2,0,0,0,0,2,6,6,2,2,35
38,37,4,0,0,0,0,0,0,0,0,0,0,4,35,38
1,37,4,0,0,0,0,0,0,0,0,0,0,4,35,1
1,37,4,0,0,0,0,0,0,0,0,0,0,4,35,1
36,37,4,0,0,0,0,0,0,0,0,0,0,4,35,36
37,2,2,6,6,2,0,0,0,0,2,6,6,2,2,35
37,3,0,0,0,6,0,0,0,0,6,0,0,0,3,35
37,3,0,0,0,6,0,0,0,0,6,0,0,0,3,35
37,3,0,0,0,2,4,4,4,4,2,0,0,0,3,35
37,2,5,5,5,2,38,38,38,38,2,5,5,5,2,35
37,38,38,38,38,38,35,1,1,37,38,38,38,38,38,38
endlayer

layer
1,1,1,1,1,1,1,1,1,1,1,1,1,1,1,1
1,37,36,36,36,36,1,1,1,1,37,36,36,36,36,1
1,37,21,21,20,35,36,36,36,36,36,21,21,21,35,1
1,37,19,0,20,3,39,39,39,39,3,19,0,20,35,1
1,37,17,17,17,3,39,39,39,39,3,17,17,20,35,1
1,37,38,5,5,2,39,39,39,39,2,5,5,38,35,1
1,1,37,39,39,39,39,5,3,39,39,39,39,35,1,1
1,1,37,39,39,39,5,3,5,3,39,39,39,35,1,1
1,1,37,39,39,39,3,5,3,5,39,39,39,35,1,1
1,1,37,39,39,39,39,3,5,39,39,39,39,35,1,1
1,37,36,5,5,2,39,39,39,39,2,5,5,36,35,1
1,37,21,21,21,3,39,39,39,39,3,21,21,20,35,1
1,37,19,0,20,3,39,39,39,39,3,19,0,20,35,1
1,37,17,17,17,38,38,38,38,38,37,17,17,20,35,1
1,38,38,38,38,35,1,1,1,1,38,38,38,38,38,1
1,1,1,1,1,1,1,1,1,1,1,1,1,1,1,1
endlayer

layer
1,1,1,1,1,1,1,1,1,1,1,1,1,1,1,1
1,1,1,1,1,1,1,1,1,1,1,1,1,1,1,1
1,1,37,36,35,1,1,1,1,1,1,36,36,35,1,1
1,1,37,39,35,0,0,0,0,0,0,37,39,35,1,1
1,1,37,38,35,0,0,0,0,0,0,37,38,35,1,1
1,1,1,0,0,0,0,0,0,0,0,0,0,1,1,1
1,1,1,0,0,0,0,0,0,0,0,0,0,1,1,1
1,1,1,0,0,0,0,0,0,0,0,0,0,1,1,1
1,1,1,0,0,0,0,0,0,0,0,0,0,1,1,1
1,1,1,0,0,0,0,0,0,0,0,0,0,1,1,1
1,1,1,0,0,0,0,0,0,0,0,0,0,1,1,1
1,1,37,36,35,0,0,0,0,0,0,36,36,36,1,1
1,1,37,39,35,0,0,0,0,0,0,37,39,35,1,1
1,1,37,38,38,1,1,1,1,1,1,37,38,38,1,1
1,1,1,1,1,1,1,1,1,1,1,1,1,1,1,1
1,1,1,1,1,1,1,1,1,1,1,1,1,1,1,1
endlayer

