
# Created by Ruins mod version 16.7 Ingame Parser
# authoring Player: lafuller

weight=1
embed_into_distance=10
random_height_offset=-1,1
acceptable_target_blocks=grass,stone,dirt,gravel
unacceptable_target_blocks=
dimensions=14,6,6
allowable_overhang=0
max_leveling=8
leveling_buffer=-1
preserve_water=1
preserve_lava=0

rule1=0,100,preserveBlock
rule2=0,100,minecraft:stone-5

layer
1,1,1,1,1,1
1,2,2,1,1,1
1,2,2,2,2,1
1,1,2,2,2,1
1,1,2,2,1,1
1,1,1,1,1,1
endlayer

layer
1,1,1,1,1,1
1,2,2,2,1,1
2,2,2,2,2,1
1,2,2,2,2,2
1,1,2,2,2,1
1,1,1,1,1,1
endlayer

layer
1,1,2,1,1,1
1,2,2,2,1,1
2,2,2,2,2,1
1,2,2,2,2,2
1,1,2,2,2,1
1,1,1,2,1,1
endlayer

layer
1,1,2,1,1,1
1,2,2,2,1,1
2,2,2,2,2,1
1,2,2,2,2,2
1,1,2,2,2,1
1,1,1,2,1,1
endlayer

layer
1,1,2,1,1,1
1,2,2,2,1,1
1,2,2,2,2,1
1,2,2,2,2,2
1,1,2,2,2,1
1,1,1,2,1,1
endlayer

layer
1,1,1,1,1,1
1,2,2,2,1,1
1,2,2,2,2,1
1,2,2,2,2,1
1,1,2,2,2,1
1,1,1,2,1,1
endlayer

layer
1,1,1,1,1,1
1,2,2,1,1,1
1,2,2,2,2,1
1,1,2,2,2,1
1,1,2,2,2,1
1,1,1,2,1,1
endlayer

layer
1,1,1,1,1,1
1,2,2,1,1,1
1,2,2,2,2,1
1,1,2,2,2,1
1,1,2,2,2,1
1,1,1,1,1,1
endlayer

layer
1,1,1,1,1,1
1,2,2,1,1,1
1,2,2,2,2,1
1,1,2,2,2,1
1,1,2,2,1,1
1,1,1,1,1,1
endlayer

layer
1,1,1,1,1,1
1,2,2,1,1,1
1,2,2,2,2,1
1,1,2,2,2,1
1,1,2,2,1,1
1,1,1,1,1,1
endlayer

layer
1,1,1,1,1,1
1,1,1,1,1,1
1,1,2,2,2,1
1,1,2,2,2,1
1,1,2,2,1,1
1,1,1,1,1,1
endlayer

layer
1,1,1,1,1,1
1,1,1,1,1,1
1,1,2,2,2,1
1,1,2,2,2,1
1,1,2,2,1,1
1,1,1,1,1,1
endlayer

layer
1,1,1,1,1,1
1,1,1,1,1,1
1,1,1,2,2,1
1,1,2,2,2,1
1,1,2,2,1,1
1,1,1,1,1,1
endlayer

layer
1,1,1,1,1,1
1,1,1,1,1,1
1,1,1,1,1,1
1,1,2,2,1,1
1,1,2,2,1,1
1,1,1,1,1,1
endlayer

