
# Created by Ruins mod version 16.7 Ingame Parser
# authoring Player: lafuller

weight=1
embed_into_distance=5
acceptable_target_blocks=
unacceptable_target_blocks=flowing_water,water,flowing_lava,lava,ice,bedrock,netherrack,nether_brick,nether_brick_fence,soul_sand,quartz_ore,end_stone,obsidian,iron_bars,cloud,flesh,ash_block,slime_grass,slime_congealed,slime_dirt
dimensions=12,17,23
allowable_overhang=0
max_leveling=7
leveling_buffer=-1
preserve_water=0
preserve_lava=0

rule1=0,100,preserveBlock
rule2=0,100,minecraft:sandstone-2
rule3=0,100,minecraft:sandstone-0
rule4=0,100,minecraft:double_stone_slab-9
rule5=0,100,minecraft:sandstone_stairs-0
rule6=0,100,minecraft:sandstone_stairs-2
rule7=0,100,minecraft:sandstone_stairs-1
rule8=0,100,minecraft:trapdoor-11
rule9=0,100,bookshelf,pumpkin,melon_block,hay_block,ChestGenHook:chests/spawn_bonus_chest:5-5,ChestGenHook:chests/village_blacksmith:5-5,ChestGenHook:chests/stronghold_library:5-5,ChestGenHook:chests/simple_dungeon:5-5
rule10=0,100,minecraft:stone_slab-1
rule11=0,100,minecraft:sandstone_stairs-3
rule12=0,100,minecraft:trapdoor-8
rule13=0,100,bookshelf,pumpkin,melon_block,hay_block,ChestGenHook:chests/spawn_bonus_chest:5-2,ChestGenHook:chests/village_blacksmith:5-2,ChestGenHook:chests/stronghold_library:5-2,ChestGenHook:chests/simple_dungeon:5-2
rule14=0,100,minecraft:dirt-0
rule15=0,100,minecraft:trapdoor-10
rule16=0,100,minecraft:wooden_slab-9
rule17=0,100,minecraft:trapdoor-3
rule18=0,100,minecraft:spruce_stairs-6
rule19=0,100,minecraft:spruce_stairs-3
rule20=0,100,minecraft:carpet-8
rule21=0,100,minecraft:carpet-7
rule22=0,100,minecraft:sandstone_stairs-4
rule23=0,100,minecraft:trapdoor-2
rule24=0,100,minecraft:jungle_door-5
rule25=0,100,minecraft:jungle_door-6
rule26=0,100,minecraft:stone_slab-9
rule27=0,100,minecraft:jungle_door-9
rule28=0,100,minecraft:ladder-4
rule29=0,100,minecraft:sandstone_stairs-7
rule30=0,100,minecraft:jungle_door-4
rule31=0,100,minecraft:jungle_door-8
rule32=0,100,minecraft:ladder-3
rule33=0,100,minecraft:jungle_door-7
rule34=0,100,minecraft:hay_block-0
rule35=0,100,minecraft:sandstone_stairs-6
rule36=0,100,minecraft:spruce_fence_gate-0
rule37=0,100,minecraft:spruce_fence-0
rule38=0,100,minecraft:trapdoor-0
rule39=0,100,minecraft:wooden_slab-1
rule40=0,100,minecraft:trapdoor-1
rule41=0,100,minecraft:trapdoor-9

layer
1,1,1,1,1,1,1,1,1,1,1,1,1,4,4,4,3,3,2,2,1,1,1
1,1,1,1,1,1,1,1,3,4,3,3,3,3,3,3,3,3,2,4,1,1,5
1,1,1,3,2,2,4,5,3,4,3,3,3,3,3,3,3,3,2,2,4,2,4
1,1,5,4,3,3,3,3,3,4,3,3,3,3,3,3,3,4,2,2,2,2,2
1,1,4,3,4,4,4,4,4,4,3,3,3,3,3,4,2,2,3,2,2,2,2
1,1,3,3,3,3,3,3,3,4,3,3,3,3,3,4,3,3,3,3,3,4,4
1,1,4,3,3,3,3,3,3,4,4,4,4,4,4,4,3,3,3,3,3,4,4
1,1,3,3,3,3,3,3,3,4,4,4,4,4,4,4,3,3,3,3,3,4,4
1,1,3,4,3,3,3,3,3,4,4,4,4,4,4,4,3,3,3,3,3,4,4
1,1,3,4,3,3,3,3,3,4,4,2,3,4,4,4,4,4,4,4,4,4,4
3,3,3,4,3,3,3,3,4,4,4,4,4,3,3,3,3,3,3,3,3,4,4
4,3,4,3,3,3,3,3,3,4,4,2,2,2,3,3,3,3,3,3,3,4,6
4,3,3,2,2,2,2,2,2,4,4,3,3,7,6,1,1,1,1,1,1,1,1
4,3,3,3,3,3,3,3,3,4,4,3,3,1,1,1,1,1,1,1,1,1,1
4,3,3,3,3,3,3,3,3,3,3,3,2,1,1,1,1,1,1,1,1,1,1
4,3,3,3,3,3,3,3,3,3,3,1,1,1,1,1,1,1,1,1,1,1,1
1,1,1,1,4,4,4,4,4,4,3,1,1,1,1,1,1,1,1,1,1,1,1
endlayer

layer
1,1,1,1,1,1,1,1,1,1,1,1,1,4,4,4,3,3,2,2,1,1,1
1,1,1,1,1,1,1,1,3,4,3,3,3,3,8,8,8,3,2,4,1,1,1
1,1,1,3,2,2,6,1,3,4,3,3,3,9,0,0,0,3,2,2,4,2,6
1,1,1,4,3,3,3,3,3,4,10,0,0,0,0,0,0,4,2,2,2,2,2
1,1,5,3,4,4,4,4,4,4,0,0,0,0,0,0,2,2,3,2,2,2,2
1,1,3,3,3,3,3,3,3,4,0,0,0,0,0,4,3,3,3,3,3,4,4
1,1,4,3,3,3,3,3,3,4,4,4,4,4,4,4,3,3,3,3,3,4,4
1,1,3,3,3,3,3,3,3,4,4,4,4,4,4,4,3,3,3,3,3,4,4
1,1,3,4,3,3,3,3,3,4,4,4,4,4,4,4,3,3,3,3,3,4,4
1,1,3,4,3,3,3,3,3,4,4,2,3,4,4,4,4,4,4,4,4,4,4
3,3,3,4,3,3,3,3,4,4,4,2,2,3,3,3,3,3,3,3,3,4,4
4,3,4,3,3,3,3,3,3,4,4,3,2,7,7,3,3,3,3,3,3,6,1
4,3,3,2,2,2,2,2,2,4,4,3,3,1,1,1,1,1,1,1,1,1,1
4,3,3,3,3,3,3,3,3,4,4,3,3,1,1,1,1,1,1,1,1,1,1
4,3,3,3,3,3,3,3,3,3,3,2,2,1,1,1,1,1,1,1,1,1,1
4,3,3,3,3,3,3,3,3,3,3,1,1,1,1,1,1,1,1,1,1,1,1
1,1,1,1,4,4,4,4,4,4,3,1,1,1,1,1,1,1,1,1,1,1,1
endlayer

layer
1,1,1,1,1,1,1,1,1,1,1,1,1,4,4,4,3,3,2,2,1,1,1
1,1,1,1,1,1,1,1,3,4,3,3,3,3,0,0,0,3,2,4,1,1,1
1,1,1,3,3,6,1,1,3,2,0,11,2,0,0,0,0,3,2,2,4,6,1
1,1,1,3,3,3,3,3,3,4,0,0,0,0,0,0,0,4,2,2,2,2,2
1,1,1,3,4,3,3,3,3,4,0,0,0,0,0,0,2,2,3,2,2,2,2
1,1,5,3,3,12,0,0,10,4,0,0,0,0,0,4,8,8,9,3,3,4,4
1,1,4,3,3,0,0,0,0,4,4,4,4,4,4,4,0,0,0,0,0,3,4
1,1,4,2,13,0,0,0,0,4,4,4,4,4,4,4,0,0,0,0,0,3,4
1,1,3,4,0,0,0,0,3,4,3,3,3,4,4,4,0,0,0,0,0,3,4
1,1,3,4,0,0,0,0,3,4,3,2,2,3,4,4,4,4,0,0,10,3,4
3,3,3,4,0,0,0,15,4,4,4,3,6,7,7,2,14,2,3,3,3,4,2
3,3,4,3,3,3,3,3,3,4,4,3,6,1,1,2,2,2,3,3,6,1,1
4,12,0,0,0,0,0,0,16,4,4,14,2,1,1,1,1,1,1,1,1,1,1
4,12,0,0,0,0,0,0,16,4,4,14,2,1,1,1,1,1,1,1,1,1,1
2,13,0,0,0,0,0,0,16,3,3,2,2,1,1,1,1,1,1,1,1,1,1
4,3,4,3,3,5,3,3,3,3,3,1,1,1,1,1,1,1,1,1,1,1,1
1,1,1,1,4,4,4,4,4,4,3,1,1,1,1,1,1,1,1,1,1,1,1
endlayer

layer
1,1,1,1,1,1,1,1,1,1,1,1,1,4,4,4,3,3,2,4,1,1,1
1,1,1,1,1,1,1,1,3,4,3,3,3,3,17,17,17,3,2,4,1,1,1
1,1,1,2,6,1,1,1,3,2,0,0,19,18,0,0,0,3,2,2,6,1,1
1,1,1,2,3,3,3,3,3,4,0,0,0,0,0,0,0,4,2,14,2,2,2
1,1,1,3,4,3,3,6,0,4,0,0,0,0,0,0,2,2,3,2,2,2,2
1,1,1,4,3,0,0,0,0,4,0,0,0,0,0,4,0,0,0,3,3,4,4
1,1,5,3,3,0,0,0,0,4,4,4,4,4,4,4,0,0,0,0,0,3,4
1,1,2,2,0,0,0,0,0,4,14,14,14,4,4,4,0,0,0,0,0,3,4
1,1,3,4,0,0,0,0,3,2,14,2,2,2,4,4,0,0,0,0,0,7,4
1,1,4,4,0,0,0,0,3,2,6,7,7,7,4,4,4,4,0,0,0,0,4
3,4,3,3,0,0,0,0,4,4,6,1,1,1,1,1,1,2,3,3,4,4,2
4,3,4,3,3,3,3,3,3,4,2,1,1,1,1,1,1,2,3,6,1,1,1
4,0,0,0,0,0,0,0,20,4,4,1,1,1,1,1,1,1,1,1,1,1,1
4,0,0,0,0,0,0,0,21,4,3,1,1,1,1,1,1,1,1,1,1,1,1
4,0,0,0,0,0,0,0,21,3,3,1,1,1,1,1,1,1,1,1,1,1,1
4,3,4,4,3,0,11,2,2,4,3,1,1,1,1,1,1,1,1,1,1,1,1
1,1,1,1,4,4,4,4,4,4,3,1,1,1,1,1,1,1,1,1,1,1,1
endlayer

layer
1,1,1,1,1,1,1,1,1,1,1,1,1,4,4,4,3,4,2,3,1,1,1
1,1,1,1,1,1,1,1,3,4,3,3,3,3,16,16,16,3,2,7,1,1,1
1,1,1,1,1,1,1,1,3,4,0,0,0,19,16,16,16,3,4,1,1,1,1
1,1,1,5,3,3,3,3,3,4,16,16,16,16,16,16,16,4,4,1,1,11,3
1,1,1,4,4,3,6,0,0,4,16,16,16,16,16,2,2,2,3,2,2,2,2
1,1,1,4,3,17,0,0,0,4,2,3,2,2,2,4,17,17,17,3,3,4,2
1,1,1,2,3,0,0,0,0,3,4,4,4,4,4,4,0,0,0,0,0,3,4
1,1,1,11,0,0,0,0,22,2,1,1,1,7,4,4,0,0,0,0,0,7,2
1,1,5,4,0,0,0,0,3,2,1,1,1,1,4,4,0,0,0,0,0,0,2
1,1,4,4,0,0,0,0,3,2,1,1,1,1,11,4,4,4,0,0,0,0,2
3,3,3,4,0,0,0,23,4,7,1,1,1,1,1,1,1,3,4,4,4,4,4
3,3,4,3,3,3,3,3,3,1,1,1,1,1,1,1,1,3,6,1,1,1,1
3,0,0,0,0,0,0,0,0,4,5,1,1,1,1,1,1,1,1,1,1,1,1
4,0,0,0,0,0,0,0,0,4,3,1,1,1,1,1,1,1,1,1,1,1,1
4,0,0,0,0,0,0,0,0,4,3,1,1,1,1,1,1,1,1,1,1,1,1
4,4,3,3,3,0,0,11,2,4,3,1,1,1,1,1,1,1,1,1,1,1,1
1,1,1,1,4,4,4,4,4,3,7,1,1,1,1,1,1,1,1,1,1,1,1
endlayer

layer
1,1,1,1,1,1,1,1,1,1,1,1,1,4,4,3,4,3,1,1,1,1,1
1,1,1,1,1,1,1,1,3,4,4,2,4,4,0,0,0,3,1,1,1,1,1
1,1,1,1,1,1,1,1,3,2,0,0,0,0,0,0,0,24,1,1,1,1,1
1,1,1,1,3,3,3,3,3,2,0,0,0,0,0,0,0,4,1,1,1,1,1
1,1,1,5,2,10,0,0,0,4,0,0,0,0,0,4,4,4,4,3,3,6,1
1,1,1,2,4,16,16,16,26,4,4,25,4,4,4,4,16,16,4,4,4,4,3
1,1,1,7,4,16,16,16,22,6,1,1,1,1,4,4,16,16,16,16,16,10,3
1,1,1,1,4,16,16,16,4,5,1,1,1,1,4,4,16,16,16,16,16,0,4
1,1,1,4,4,16,16,4,4,2,1,1,1,1,3,4,4,4,16,16,16,0,4
1,1,5,4,16,16,16,4,4,7,1,1,1,1,1,11,4,4,4,16,16,0,4
11,2,2,4,16,16,16,4,4,1,1,1,1,1,1,1,1,7,4,4,4,4,4
3,3,4,4,16,16,16,4,4,1,1,1,1,1,1,1,1,1,1,1,1,1,1
4,16,16,16,4,4,4,4,4,4,1,1,1,1,1,1,1,1,1,1,1,1,1
4,16,16,16,16,16,16,16,16,4,5,1,1,1,1,1,1,1,1,1,1,1,1
4,16,16,16,16,16,16,16,16,4,2,1,1,1,1,1,1,1,1,1,1,1,1
4,3,3,3,4,0,0,0,10,3,7,1,1,1,1,1,1,1,1,1,1,1,1
1,1,1,1,4,2,4,4,2,3,1,1,1,1,1,1,1,1,1,1,1,1,1
endlayer

layer
1,1,1,1,1,1,1,1,1,1,1,1,1,2,4,3,4,2,1,1,1,1,1
1,1,1,1,1,1,1,1,2,4,3,3,3,3,0,0,0,3,1,1,1,1,1
1,1,1,1,1,1,1,1,3,21,0,0,0,0,0,0,0,27,1,1,1,1,1
1,1,1,1,2,3,3,3,3,21,0,0,0,0,0,0,0,4,1,1,1,1,1
1,1,1,1,4,0,0,0,29,21,28,0,0,0,0,4,3,3,2,1,1,1,1
1,1,1,1,33,0,0,32,3,4,3,31,3,3,3,16,0,0,2,3,30,4,2
1,1,1,1,3,0,0,0,3,1,1,1,1,1,4,16,0,0,0,0,0,0,3
1,1,1,1,3,0,0,0,3,1,1,1,1,1,3,16,0,0,0,0,0,0,3
1,1,1,2,3,0,0,3,2,1,1,1,1,1,2,4,25,3,0,0,0,0,4
1,1,1,4,0,0,0,3,1,1,1,1,1,1,1,1,1,1,3,0,0,0,4
1,1,1,4,0,0,0,24,1,1,1,1,1,1,1,1,1,1,2,3,3,4,2
2,30,3,3,0,0,0,3,1,1,1,1,1,1,1,1,1,1,1,1,1,1,1
4,0,0,0,3,3,3,3,2,2,1,1,1,1,1,1,1,1,1,1,1,1,1
4,0,0,0,0,0,0,0,0,3,1,1,1,1,1,1,1,1,1,1,1,1,1
3,0,0,0,0,0,0,0,0,24,1,1,1,1,1,1,1,1,1,1,1,1,1
2,4,3,3,3,0,0,0,0,3,1,1,1,1,1,1,1,1,1,1,1,1,1
1,1,1,1,2,4,4,4,4,2,1,1,1,1,1,1,1,1,1,1,1,1,1
endlayer

layer
1,1,1,1,1,1,1,1,1,1,1,1,1,2,4,1,3,2,1,1,1,1,1
1,1,1,1,1,1,1,1,2,4,1,3,3,3,0,0,0,4,1,1,1,1,1
1,1,1,1,1,1,1,1,3,0,0,0,0,0,0,0,0,2,1,1,1,1,1
1,1,1,1,2,3,1,3,3,0,0,0,0,0,0,0,0,3,1,1,1,1,1
1,1,1,1,4,0,0,0,4,0,28,0,0,0,0,4,3,3,2,1,1,1,1
1,1,1,1,31,0,0,32,3,4,3,2,3,3,3,20,0,0,2,3,31,3,2
1,1,1,1,3,0,0,0,1,1,1,1,1,1,4,21,0,0,0,0,0,0,3
1,1,1,1,3,0,0,0,3,1,1,1,1,1,3,21,0,0,0,0,0,0,1
1,1,1,2,3,0,0,3,2,1,1,1,1,1,2,4,27,3,0,0,0,0,3
1,1,1,4,0,0,0,3,1,1,1,1,1,1,1,1,1,1,3,0,0,0,4
1,1,1,1,0,0,0,31,1,1,1,1,1,1,1,1,1,1,2,3,1,4,2
2,31,3,3,0,0,0,3,1,1,1,1,1,1,1,1,1,1,1,1,1,1,1
3,0,0,0,3,3,3,3,2,2,1,1,1,1,1,1,1,1,1,1,1,1,1
1,0,0,0,0,0,0,0,0,3,1,1,1,1,1,1,1,1,1,1,1,1,1
3,0,0,0,0,0,0,0,0,31,1,1,1,1,1,1,1,1,1,1,1,1,1
2,3,1,3,3,0,0,0,0,3,1,1,1,1,1,1,1,1,1,1,1,1,1
1,1,1,1,2,4,1,4,2,2,1,1,1,1,1,1,1,1,1,1,1,1,1
endlayer

layer
1,1,1,1,1,1,1,1,1,1,1,1,1,4,4,2,3,3,1,1,1,1,1
1,1,1,1,1,1,1,1,3,4,2,3,3,3,0,0,0,4,1,1,1,1,1
1,1,1,1,1,1,1,1,3,16,0,0,0,0,0,0,0,4,1,1,1,1,1
1,1,1,1,3,2,2,2,3,16,0,0,0,0,0,0,0,4,1,1,1,1,1
1,1,1,1,4,17,17,17,4,16,28,0,0,0,0,4,3,3,3,1,1,1,1
1,1,1,1,3,0,0,0,3,4,2,2,2,3,3,0,0,0,2,4,3,4,3
1,1,1,1,3,0,0,0,3,1,1,1,1,1,4,0,0,0,0,0,0,0,3
1,1,1,1,3,0,0,0,3,1,1,1,1,1,3,0,0,0,0,0,0,0,3
1,1,1,4,3,0,0,3,3,1,1,1,1,1,3,4,3,3,0,0,0,0,3
1,1,1,4,0,0,0,3,1,1,1,1,1,1,1,1,1,1,2,0,0,0,4
1,1,1,2,0,0,0,4,1,1,1,1,1,1,1,1,1,1,3,4,4,4,3
3,3,3,3,0,0,0,3,1,1,1,1,1,1,1,1,1,1,1,1,1,1,1
2,0,0,0,3,3,3,3,4,3,1,1,1,1,1,1,1,1,1,1,1,1,1
2,0,0,0,0,0,0,0,0,3,1,1,1,1,1,1,1,1,1,1,1,1,1
2,0,0,0,0,0,0,0,0,2,1,1,1,1,1,1,1,1,1,1,1,1,1
3,2,2,2,3,0,0,0,0,3,1,1,1,1,1,1,1,1,1,1,1,1,1
1,1,1,1,4,4,4,4,4,3,1,1,1,1,1,1,1,1,1,1,1,1,1
endlayer

layer
1,1,1,1,1,1,1,1,1,1,1,1,1,11,5,5,5,5,1,1,1,1,1
1,1,1,1,1,1,1,1,2,4,3,3,3,3,26,26,26,6,1,1,1,1,1
1,1,1,1,1,1,1,1,3,21,0,0,0,29,26,0,26,6,1,1,1,1,1
1,1,1,1,2,3,3,3,3,21,0,0,0,29,26,26,26,6,1,1,1,1,1
1,1,1,1,4,0,0,0,4,20,0,0,0,29,3,3,3,3,2,1,1,1,1
1,1,1,1,3,0,0,0,3,3,3,3,3,3,3,34,34,34,2,4,3,3,2
1,1,1,1,3,0,0,0,3,36,36,36,36,36,3,34,12,34,35,0,0,0,3
1,1,1,1,3,26,26,26,3,36,36,36,36,36,3,34,34,34,35,0,0,0,3
1,1,1,2,3,22,22,3,2,37,37,37,37,37,2,3,3,3,35,0,0,0,4
1,1,1,3,26,26,26,3,38,1,1,1,1,1,1,1,1,1,3,0,0,0,3
1,1,1,3,26,15,26,3,38,1,1,1,1,1,1,1,1,1,11,3,3,4,6
2,5,5,3,26,26,26,3,38,1,1,1,1,1,1,1,1,1,1,1,1,1,1
11,16,16,16,3,3,3,3,3,2,1,1,1,1,1,1,1,1,1,1,1,1,1
11,16,12,16,35,0,0,0,0,3,1,1,1,1,1,1,1,1,1,1,1,1,1
11,16,16,16,35,0,0,0,0,3,1,1,1,1,1,1,1,1,1,1,1,1,1
2,7,7,7,3,0,0,0,0,3,1,1,1,1,1,1,1,1,1,1,1,1,1
1,1,1,1,2,2,4,4,2,2,1,1,1,1,1,1,1,1,1,1,1,1,1
endlayer

layer
1,1,1,1,1,1,1,1,1,1,1,1,1,1,1,1,1,1,1,1,1,1,1
1,1,1,1,1,1,1,1,2,5,2,2,5,2,10,10,10,1,1,1,1,1,1
1,1,1,1,1,1,1,1,11,0,0,0,0,6,10,23,10,1,1,1,1,1,1
1,1,1,1,1,10,10,10,2,0,0,0,0,2,10,10,10,1,1,1,1,1,1
1,1,1,1,10,39,39,39,11,0,0,0,0,6,1,10,10,10,1,1,1,1,1
1,1,1,1,10,39,17,39,2,7,2,2,7,2,10,1,1,1,10,5,5,5,1
1,1,1,1,10,39,39,39,10,1,1,1,1,1,10,1,1,1,11,39,39,39,6
1,1,1,1,10,10,10,10,10,1,1,1,1,1,10,1,1,1,11,39,40,39,6
1,1,1,1,1,10,10,10,1,1,1,1,1,1,1,10,10,10,11,39,39,39,6
1,1,1,1,1,1,1,1,1,1,1,1,1,1,1,1,1,1,10,7,7,7,10
1,1,1,1,1,1,1,1,1,1,1,1,1,1,1,1,1,1,1,1,1,1,1
1,1,1,1,1,1,1,1,1,1,1,1,1,1,1,1,1,1,1,1,1,1,1
1,1,1,1,5,2,5,5,2,5,1,1,1,1,1,1,1,1,1,1,1,1,1
1,1,1,1,2,26,26,26,26,2,1,1,1,1,1,1,1,1,1,1,1,1,1
1,1,1,1,11,26,12,41,26,6,1,1,1,1,1,1,1,1,1,1,1,1,1
1,1,1,1,2,26,26,26,26,2,1,1,1,1,1,1,1,1,1,1,1,1,1
1,1,1,1,7,2,7,7,2,7,1,1,1,1,1,1,1,1,1,1,1,1,1
endlayer

layer
1,1,1,1,1,1,1,1,1,1,1,1,1,1,1,1,1,1,1,1,1,1,1
1,1,1,1,1,1,1,1,1,1,1,1,1,1,1,1,1,1,1,1,1,1,1
1,1,1,1,1,1,1,1,1,10,10,10,10,1,1,1,1,1,1,1,1,1,1
1,1,1,1,1,1,1,1,1,10,10,40,10,1,1,1,1,1,1,1,1,1,1
1,1,1,1,1,1,1,1,1,10,10,10,10,1,1,1,1,1,1,1,1,1,1
1,1,1,1,1,1,1,1,1,1,1,1,1,1,1,1,1,1,1,1,1,1,1
1,1,1,1,1,1,1,1,1,1,1,1,1,1,1,1,1,1,1,1,1,1,1
1,1,1,1,1,1,1,1,1,1,1,1,1,1,1,1,1,1,1,1,1,1,1
1,1,1,1,1,1,1,1,1,1,1,1,1,1,1,1,1,1,1,1,1,1,1
1,1,1,1,1,1,1,1,1,1,1,1,1,1,1,1,1,1,1,1,1,1,1
1,1,1,1,1,1,1,1,1,1,1,1,1,1,1,1,1,1,1,1,1,1,1
1,1,1,1,1,1,1,1,1,1,1,1,1,1,1,1,1,1,1,1,1,1,1
1,1,1,1,1,1,1,1,1,1,1,1,1,1,1,1,1,1,1,1,1,1,1
1,1,1,1,1,10,10,10,10,1,1,1,1,1,1,1,1,1,1,1,1,1,1
1,1,1,1,1,10,1,1,10,1,1,1,1,1,1,1,1,1,1,1,1,1,1
1,1,1,1,1,10,10,10,10,1,1,1,1,1,1,1,1,1,1,1,1,1,1
1,1,1,1,1,1,1,1,1,1,1,1,1,1,1,1,1,1,1,1,1,1,1
endlayer

