
# Created by Ruins mod version 16.7 Ingame Parser
# authoring Player: lafuller

weight=1
embed_into_distance=4
acceptable_target_blocks=
unacceptable_target_blocks=flowing_water,water,flowing_lava,lava,ice,bedrock,netherrack,nether_brick,nether_brick_fence,soul_sand,quartz_ore,end_stone,obsidian,iron_bars,cloud,flesh,ash_block,slime_grass,slime_congealed,slime_dirt
biomesToSpawnIn=plains,forest,prarie,meadow,tundra,brushland,shrubland,woodland,woodlands,birch_forestlavender_fields,flower_field,sunflower_plains,ice_flats,ice_plains
dimensions=15,13,11
allowable_overhang=0
max_leveling=4
leveling_buffer=-1
preserve_water=0
preserve_lava=0

rule1=0,100,preserveBlock
rule2=0,100,stonebrick-0,stonebrick-0,stonebrick-0,stonebrick-0,stonebrick-1,stonebrick-2,stonebrick-2,stone-5,stone-6,cobblestone
rule3=0,100,stonebrick-0,stonebrick-2,stonebrick-1,stonebrick-1,stonebrick-1,cobblestone
rule4=0,100,stonebrick-0,stonebrick-1,stonebrick-2,stonebrick-2,stone-5,stone-5,stone-6,stone-6
rule5=0,100,stonebrick-0,stonebrick-2,stonebrick-0,stonebrick-1,stonebrick-1,cobblestone
rule6=0,100,minecraft:stone_brick_stairs-0
rule7=0,100,minecraft:stone_brick_stairs-1
rule8=0,100,minecraft:stone_brick_stairs-2
rule9=0,100,minecraft:stone_brick_stairs-3
rule10=0,100,air
rule11=0,100,stonebrick-0,stonebrick-0,stonebrick-0,stonebrick-0,stonebrick-1,stonebrick-2,stonebrick-2,stone-5,stone-6,cobblestone,gravel
rule12=0,100,minecraft:cobblestone_wall-0
rule13=0,100,minecraft:log-0
rule14=0,100,minecraft:wooden_slab-9
rule15=0,100,minecraft:web-0,air,air,air
rule16=0,100,minecraft:ladder-2
rule17=0,100,bookshelf,hay_block,ChestGenHook:chests/spawn_bonus_chest:5-2,ChestGenHook:chests/village_blacksmith:5-2,ChestGenHook:chests/simple_dungeon:5-2,ChestGenHook:chests/abandoned_mineshaft:5-2,ChestGenHook:chests/stronghold_library:5-2,ChestGenHook:chests/stronghold_corridor:5-2,ChestGenHook:chests/stronghold_crossing:5-2,ChestGenHook:chests/igloo_chest:5-2
rule18=0,100,minecraft:stone_brick_stairs-6
rule19=0,100,minecraft:planks-1
rule20=0,100,minecraft:planks-0
rule21=0,100,minecraft:log-11
rule22=0,100,minecraft:oak_stairs-6
rule23=0,100,minecraft:oak_stairs-4
rule24=0,100,minecraft:oak_stairs-7
rule25=0,100,minecraft:oak_stairs-2
rule26=0,100,minecraft:oak_stairs-0
rule27=0,100,minecraft:oak_stairs-3
rule28=0,100,minecraft:oak_stairs-1
rule29=0,100,minecraft:jungle_door-3
rule30=0,100,minecraft:stone_brick_stairs-4
rule31=0,100,minecraft:stone_brick_stairs-5
rule32=0,100,minecraft:fence-0
rule33=0,100,minecraft:oak_stairs-5
rule34=0,100,minecraft:jungle_door-8
rule35=0,100,minecraft:furnace-4
rule36=0,100,minecraft:wooden_slab-13
rule37=0,100,minecraft:dark_oak_stairs-0
rule38=0,100,minecraft:spruce_stairs-4
rule39=0,100,minecraft:spruce_stairs-7
rule40=0,100,minecraft:spruce_stairs-6
rule41=0,100,minecraft:spruce_stairs-5
rule42=0,100,minecraft:dark_oak_stairs-4
rule43=0,100,minecraft:spruce_stairs-1
rule44=0,100,minecraft:dark_oak_stairs-5
rule45=0,100,minecraft:spruce_fence_gate-2
rule46=0,100,minecraft:spruce_stairs-3
rule47=0,100,minecraft:planks-5
rule48=0,100,minecraft:dark_oak_stairs-7
rule49=0,100,minecraft:dark_oak_stairs-2
rule50=0,100,minecraft:dark_oak_stairs-3
rule51=0,100,minecraft:wooden_slab-5
rule52=0,100,minecraft:log-7
rule53=0,100,minecraft:dark_oak_stairs-1
rule54=0,100,minecraft:dark_oak_fence-0
rule55=0,100,minecraft:stone_slab-0

layer
1,1,1,1,1,1,1,1,1,1,1
1,1,1,1,2,2,2,2,2,1,1
1,2,2,2,2,3,3,3,3,2,1
1,2,3,3,3,4,4,4,3,2,1
6,2,3,4,4,5,5,4,3,2,1
2,2,3,4,5,5,4,4,3,2,1
2,2,2,3,4,5,5,4,3,2,1
2,2,2,3,4,4,5,4,3,2,1
2,2,2,3,4,5,5,4,3,2,1
2,2,2,3,3,4,4,3,3,2,1
2,2,2,2,2,3,3,3,2,2,1
7,2,2,2,2,2,2,2,2,2,1
10,9,2,2,2,8,1,1,1,1,1
endlayer

layer
1,1,1,1,1,1,1,1,1,1,1
1,1,1,1,11,11,12,11,11,1,1
1,11,11,12,11,14,14,14,13,11,1
1,11,13,15,10,10,10,10,15,11,1
1,11,16,10,10,10,10,10,10,12,1
6,11,16,10,10,10,10,10,10,11,1
11,11,11,10,10,10,10,10,10,12,1
11,11,11,10,10,10,10,10,10,11,1
11,11,11,10,10,10,10,10,10,12,1
11,11,11,17,15,10,10,10,15,11,1
7,11,11,11,11,13,10,15,11,11,1
1,11,11,11,11,11,12,11,11,11,1
1,1,9,11,8,1,1,1,1,1,1
endlayer

layer
1,1,1,1,1,1,1,1,1,1,1
1,1,1,1,11,11,12,11,11,1,1
1,11,11,12,11,15,10,15,13,11,1
1,11,13,15,15,10,10,10,15,11,1
1,11,16,10,10,10,10,10,15,12,1
1,11,16,10,10,10,10,10,10,11,1
6,11,11,10,10,10,10,10,10,12,1
11,11,11,10,10,10,10,10,10,11,1
11,11,11,10,10,10,10,10,15,12,1
7,11,11,15,15,10,10,10,15,11,1
1,11,11,11,11,13,15,15,11,11,1
1,1,7,7,7,11,12,11,11,11,1
1,1,1,1,1,1,1,1,1,1,1
endlayer

layer
1,1,1,1,1,1,1,1,1,1,1
1,1,1,1,11,11,12,11,11,1,1
1,11,11,12,11,15,15,15,13,11,1
1,11,13,15,15,15,10,15,15,11,1
1,11,16,10,10,10,10,10,15,12,1
1,11,16,10,10,10,10,10,15,11,1
1,9,11,15,10,10,10,10,10,12,1
1,9,11,18,10,10,10,10,15,11,1
1,9,11,18,15,10,10,10,15,12,1
1,9,11,18,15,15,10,15,15,11,1
1,1,7,7,11,13,15,15,11,11,1
1,1,1,1,1,11,12,11,11,11,1
1,1,1,1,1,1,1,1,1,1,1
endlayer

layer
1,1,1,1,1,1,1,1,1,1,1
1,1,1,1,2,2,2,2,2,1,1
1,2,2,2,2,19,19,19,19,2,1
1,2,19,19,19,20,20,20,19,2,1
1,2,16,19,19,20,20,20,19,2,1
1,2,16,19,19,19,19,19,19,2,1
1,1,2,2,21,21,21,21,21,2,1
1,1,9,2,2,19,20,20,19,2,1
1,1,9,2,2,19,20,19,19,2,1
1,1,9,7,2,19,20,19,19,11,1
1,1,1,1,2,19,19,19,11,11,1
1,1,1,1,1,2,2,11,11,11,1
1,1,1,1,1,1,1,1,1,1,1
endlayer

layer
1,1,1,1,1,1,1,1,1,1,1
1,1,1,1,24,23,23,23,22,1,1
1,10,13,26,13,10,10,10,13,25,1
1,27,10,10,10,10,10,10,10,25,1
1,26,16,10,10,10,10,10,10,25,1
1,13,16,10,10,10,10,10,10,25,1
1,1,28,27,10,10,10,10,10,13,1
1,1,10,10,13,10,10,10,10,25,1
1,1,10,10,29,10,10,10,10,25,1
1,1,1,10,28,10,10,10,10,25,1
1,1,1,1,27,10,10,10,30,11,1
1,1,1,1,10,28,28,13,11,31,1
1,1,1,1,1,1,1,1,1,1,1
endlayer

layer
1,1,1,1,1,1,1,1,1,1,1
1,1,1,1,32,32,10,32,32,1,1
1,10,13,23,13,10,10,10,13,32,1
1,24,10,10,10,10,10,10,10,32,1
1,24,10,10,10,10,10,10,10,10,1
1,13,10,10,10,10,10,10,10,32,1
1,10,33,24,10,10,10,10,10,13,1
1,10,10,10,13,10,10,10,10,32,1
1,1,10,10,34,10,10,10,10,10,1
1,1,10,10,28,10,10,10,10,32,1
1,1,1,10,27,10,10,10,35,11,1
1,1,1,1,10,32,32,13,11,8,1
1,1,1,1,1,1,1,1,1,1,1
endlayer

layer
1,1,1,1,36,1,1,1,36,1,1
1,36,1,36,39,38,38,38,38,37,1
36,42,13,41,13,10,10,10,13,40,36
1,39,10,10,10,10,10,10,10,40,1
1,39,10,10,10,10,10,10,10,40,1
1,13,10,10,10,10,10,10,10,40,1
36,36,43,38,10,10,10,10,10,13,36
1,10,10,44,13,10,10,10,10,40,1
1,1,10,10,45,10,10,10,10,40,1
1,1,10,10,46,10,10,10,10,40,36
1,1,1,10,46,10,10,10,6,11,1
1,1,1,36,47,41,41,13,11,31,1
1,1,1,1,36,1,1,48,1,1,1
endlayer

layer
1,1,1,1,1,50,37,49,1,1,1
1,1,50,37,50,21,21,21,49,1,1
1,37,13,19,13,41,14,41,13,37,1
50,47,40,14,14,10,10,10,39,52,51
50,47,40,14,14,10,10,10,14,52,49
51,47,40,38,10,10,10,10,14,52,51
1,53,47,47,52,21,21,21,21,21,49
1,51,50,53,52,40,10,10,14,52,51
1,1,1,50,52,14,10,10,14,52,49
1,1,1,50,52,38,10,10,39,52,51
1,1,1,53,52,40,38,38,11,11,1
1,1,1,1,53,47,19,13,11,8,1
1,1,1,1,1,53,53,49,1,1,1
endlayer

layer
1,1,1,1,1,1,1,1,1,1,1
1,1,1,1,1,51,49,37,1,1,1
1,1,51,49,47,47,47,47,37,1,1
1,37,47,47,47,19,19,47,47,49,1
1,53,47,47,47,19,19,19,47,37,1
1,50,47,47,47,19,19,19,47,53,1
1,1,50,50,47,47,47,47,47,49,1
1,1,1,1,53,47,19,19,47,37,1
1,1,1,1,53,47,19,19,47,53,1
1,1,1,1,53,47,19,19,47,49,1
1,1,1,1,51,50,47,47,11,1,1
1,1,1,1,1,50,49,53,11,1,1
1,1,1,1,1,1,1,1,1,1,1
endlayer

layer
1,1,1,1,1,1,1,1,1,1,1
1,1,1,1,1,1,1,1,1,1,1
1,1,1,1,54,54,54,54,1,1,1
1,1,54,54,54,51,51,54,54,1,1
1,1,54,51,51,51,51,51,54,1,1
1,1,54,54,54,51,51,51,54,1,1
1,1,1,1,54,54,51,51,54,1,1
1,1,1,1,1,54,51,51,54,1,1
1,1,1,1,1,54,51,51,54,1,1
1,1,1,1,1,54,51,51,54,1,1
1,1,1,1,1,1,54,54,11,1,1
1,1,1,1,1,1,1,1,11,1,1
1,1,1,1,1,1,1,1,1,1,1
endlayer

layer
1,1,1,1,1,1,1,1,1,1,1
1,1,1,1,1,1,1,1,1,1,1
1,1,1,1,1,1,1,1,1,1,1
1,1,1,1,1,1,1,1,1,1,1
1,1,1,1,1,1,1,1,1,1,1
1,1,1,1,1,1,1,1,1,1,1
1,1,1,1,1,1,1,1,1,1,1
1,1,1,1,1,1,1,1,1,1,1
1,1,1,1,1,1,1,1,1,1,1
1,1,1,1,1,1,1,1,1,1,1
1,1,1,1,1,1,1,1,11,1,1
1,1,1,1,1,1,1,1,31,1,1
1,1,1,1,1,1,1,1,1,1,1
endlayer

layer
1,1,1,1,1,1,1,1,1,1,1
1,1,1,1,1,1,1,1,1,1,1
1,1,1,1,1,1,1,1,1,1,1
1,1,1,1,1,1,1,1,1,1,1
1,1,1,1,1,1,1,1,1,1,1
1,1,1,1,1,1,1,1,1,1,1
1,1,1,1,1,1,1,1,1,1,1
1,1,1,1,1,1,1,1,1,1,1
1,1,1,1,1,1,1,1,1,1,1
1,1,1,1,1,1,1,1,1,1,1
1,1,1,1,1,1,1,1,11,1,1
1,1,1,1,1,1,1,1,11,1,1
1,1,1,1,1,1,1,1,1,1,1
endlayer

layer
1,1,1,1,1,1,1,1,1,1,1
1,1,1,1,1,1,1,1,1,1,1
1,1,1,1,1,1,1,1,1,1,1
1,1,1,1,1,1,1,1,1,1,1
1,1,1,1,1,1,1,1,1,1,1
1,1,1,1,1,1,1,1,1,1,1
1,1,1,1,1,1,1,1,1,1,1
1,1,1,1,1,1,1,1,1,1,1
1,1,1,1,1,1,1,1,1,1,1
1,1,1,1,1,1,1,1,1,1,1
1,1,1,1,1,1,1,1,12,1,1
1,1,1,1,1,1,1,1,12,1,1
1,1,1,1,1,1,1,1,1,1,1
endlayer

layer
1,1,1,1,1,1,1,1,1,1,1
1,1,1,1,1,1,1,1,1,1,1
1,1,1,1,1,1,1,1,1,1,1
1,1,1,1,1,1,1,1,1,1,1
1,1,1,1,1,1,1,1,1,1,1
1,1,1,1,1,1,1,1,1,1,1
1,1,1,1,1,1,1,1,1,1,1
1,1,1,1,1,1,1,1,1,1,1
1,1,1,1,1,1,1,1,1,1,1
1,1,1,1,1,1,1,1,1,1,1
1,1,1,1,1,1,1,1,55,1,1
1,1,1,1,1,1,1,1,55,1,1
1,1,1,1,1,1,1,1,1,1,1
endlayer

