
# Created by Ruins mod version 16.7 Ingame Parser
# authoring Player: lafuller

weight=1
embed_into_distance=33
acceptable_target_blocks=
unacceptable_target_blocks=
dimensions=32,5,5
allowable_overhang=0
max_leveling=10
leveling_buffer=-1
preserve_water=0
preserve_lava=0

rule1=0,100,stonebrick-0,stonebrick-1,stonebrick-2,stone-5,stone-5,stone-6,stone-6,cobblestone,stone_brick_stairs-0,stone_brick_stairs-1,stone_brick_stairs-2,stone_brick_stairs-3,stone_brick_stairs-4,stone_brick_stairs-5,stone_brick_stairs-6,stone_brick_stairs-7
rule2=1,30,stonebrick-0,stonebrick-1,stonebrick-2,stone-5,stone-5,stone-6,stone-6,cobblestone
rule3=1,15,stonebrick-0,stonebrick-1,stonebrick-2,stone-5,stone-5,stone-6,stone-6,cobblestone

layer
1,1,1,1,1
1,1,1,1,1
1,1,1,1,1
1,1,1,1,1
1,1,1,1,1
endlayer

layer
1,1,1,1,1
1,1,1,1,1
1,1,1,1,1
1,1,1,1,1
1,1,1,1,1
endlayer

layer
1,0,1,1,1
0,3,2,1,0
1,2,2,2,1
1,1,2,3,1
1,0,1,0,1
endlayer

layer
1,1,1,0,1
0,1,1,3,1
1,1,1,1,1
0,3,1,3,0
1,1,1,0,1
endlayer

layer
1,0,1,0,1
1,3,2,3,0
1,2,2,2,1
0,3,2,1,0
1,0,1,1,1
endlayer

layer
1,0,1,1,1
0,3,1,1,0
1,1,1,1,1
1,1,1,3,1
1,0,1,0,1
endlayer

layer
1,1,1,0,1
0,1,2,3,1
1,2,2,2,1
0,3,2,3,0
1,1,1,0,1
endlayer

layer
1,0,1,0,1
1,3,1,3,0
1,1,1,1,1
0,3,1,1,0
1,0,1,1,1
endlayer

layer
1,0,1,1,1
0,3,2,1,0
1,2,2,2,1
1,1,2,3,1
1,0,1,0,1
endlayer

layer
1,1,1,0,1
0,1,1,3,1
1,1,1,1,1
0,3,1,3,0
1,1,1,0,1
endlayer

layer
1,0,1,0,1
1,3,2,3,0
1,2,2,2,1
0,3,2,1,0
1,0,1,1,1
endlayer

layer
1,0,1,1,1
0,3,1,1,0
1,1,1,1,1
1,1,1,3,1
1,0,1,0,1
endlayer

layer
1,1,1,0,1
0,1,2,3,1
1,2,2,2,1
0,3,2,3,0
1,1,1,0,1
endlayer

layer
1,0,1,0,1
1,3,1,3,0
1,1,1,1,1
0,3,1,1,0
1,0,1,1,1
endlayer

layer
1,0,1,1,1
0,3,2,1,0
1,2,2,2,1
1,1,2,3,1
1,0,1,0,1
endlayer

layer
1,1,1,0,1
0,1,1,3,1
1,1,1,1,1
0,3,1,3,0
1,1,1,0,1
endlayer

layer
1,0,1,0,1
1,3,2,3,0
1,2,2,2,1
0,3,2,1,0
1,0,1,1,1
endlayer

layer
1,0,1,1,1
0,3,1,1,0
1,1,1,1,1
1,1,1,3,1
1,0,1,0,1
endlayer

layer
1,1,1,0,1
0,1,2,3,1
1,2,2,2,1
0,3,2,3,0
1,1,1,0,1
endlayer

layer
1,0,1,0,1
1,3,1,3,0
1,1,1,1,1
0,3,1,1,0
1,0,1,1,1
endlayer

layer
1,0,1,1,1
0,3,2,1,0
1,2,2,2,1
1,1,2,3,1
1,0,1,0,1
endlayer

layer
1,1,1,0,1
0,1,1,3,1
1,1,1,1,1
0,3,1,3,0
1,1,1,0,1
endlayer

layer
1,0,1,0,1
1,3,2,3,0
1,2,2,2,1
0,3,2,1,0
1,0,1,1,1
endlayer

layer
1,0,1,1,1
0,3,1,1,0
1,1,1,1,1
1,1,1,3,1
1,0,1,0,1
endlayer

layer
1,1,1,0,1
0,1,2,3,1
1,2,2,2,1
0,3,2,3,0
1,1,1,0,1
endlayer

layer
1,0,1,0,1
1,3,1,3,0
1,1,1,1,1
0,3,1,1,0
1,0,1,1,1
endlayer

layer
1,0,1,1,1
0,3,2,1,0
1,2,2,2,1
1,1,2,3,1
1,0,1,0,1
endlayer

layer
1,1,1,0,1
0,1,1,3,1
1,1,1,1,1
0,3,1,3,0
1,1,1,0,1
endlayer

layer
1,0,1,0,1
1,3,2,3,0
1,2,2,2,1
0,3,2,1,0
1,0,1,1,1
endlayer

layer
1,0,1,1,1
0,3,1,1,0
1,1,1,1,1
1,1,1,3,1
1,0,1,0,1
endlayer

layer
1,1,1,0,1
0,1,2,3,1
1,2,2,2,1
0,3,2,3,0
1,1,1,0,1
endlayer

layer
1,0,1,0,1
1,3,1,3,0
1,1,1,1,1
0,3,1,1,0
1,0,1,1,1
endlayer


