
# Created by Ruins mod version 16.7 Ingame Parser
# authoring Player: lafuller

weight=1
embed_into_distance=13
acceptable_target_blocks=water,waterlily
unacceptable_target_blocks=
biomesToSpawnIn=swampland,jungle,marsh,bog,wetland,mini_jungle,lush_swamp,green_swamp,dead_swamp,tropical_island,land_of_lakes
dimensions=24,11,11
allowable_overhang=0
max_leveling=2
leveling_buffer=-1
preserve_water=0
preserve_lava=0

rule1=0,100,preserveBlock
rule2=0,100,minecraft:log2-1
rule3=0,100,minecraft:log2-9
rule4=0,100,minecraft:log2-5
rule5=0,100,minecraft:spruce_fence-0
rule6=0,100,minecraft:ladder-4
rule7=0,100,minecraft:wooden_slab-9
rule8=0,100,minecraft:spruce_stairs-6
rule9=0,100,minecraft:spruce_stairs-7
rule10=0,100,minecraft:wooden_slab-8
rule11=0,100,minecraft:double_wooden_slab-1
rule12=0,100,minecraft:spruce_stairs-5
rule13=0,100,minecraft:spruce_stairs-4
rule14=0,100,minecraft:spruce_stairs-0
rule15=0,100,minecraft:wooden_slab-1
rule16=0,100,minecraft:ladder-5
rule17=0,100,minecraft:trapdoor-8
rule18=0,100,minecraft:dark_oak_stairs-7
rule19=0,100,minecraft:spruce_stairs-2
rule20=0,100,minecraft:trapdoor-6
rule21=0,100,minecraft:spruce_fence_gate-3
rule22=0,100,minecraft:planks-5
rule23=0,100,minecraft:dark_oak_stairs-5
rule24=0,100,minecraft:dark_oak_stairs-4
rule25=0,100,minecraft:dark_oak_stairs-3
rule26=0,100,minecraft:double_wooden_slab-5
rule27=0,100,minecraft:spruce_fence_gate-7
rule28=0,100,minecraft:wooden_slab-13
rule29=0,100,minecraft:dark_oak_stairs-6
rule30=0,100,minecraft:spruce_fence_gate-0
rule31=0,100,minecraft:dark_oak_stairs-1
rule32=0,100,minecraft:wooden_slab-5
rule33=0,100,minecraft:dark_oak_stairs-2
rule34=0,100,minecraft:dark_oak_stairs-0

layer
1,1,1,1,1,1,1,1,1,1,1
1,1,1,1,1,1,1,1,1,1,1
1,1,2,1,1,1,2,1,1,1,1
1,1,1,1,1,1,1,1,1,1,1
1,1,1,1,1,1,1,1,2,1,1
1,1,1,1,1,1,1,1,1,1,1
1,1,1,1,1,1,1,1,1,1,1
1,1,2,1,1,1,1,1,1,1,1
1,1,1,1,1,1,1,2,1,1,1
1,1,1,1,1,1,1,1,1,1,1
1,1,1,1,1,1,1,1,1,1,1
endlayer

layer
1,1,1,1,1,1,1,1,1,1,1
1,1,1,1,1,1,1,1,1,1,1
1,1,2,1,1,1,2,1,1,1,1
1,1,1,1,1,1,1,1,1,1,1
1,1,1,1,1,1,1,1,2,1,1
1,1,1,1,1,1,1,1,1,1,1
1,1,1,1,1,1,1,1,1,1,1
1,1,2,1,1,1,1,1,1,1,1
1,1,1,1,1,1,1,2,1,1,1
1,1,1,1,1,1,1,1,1,1,1
1,1,1,1,1,1,1,1,1,1,1
endlayer

layer
1,1,1,1,1,1,1,1,1,1,1
1,1,1,1,1,1,1,1,1,1,1
1,1,2,1,1,1,2,1,1,1,1
1,1,1,1,1,1,1,1,1,1,1
1,1,1,1,1,1,1,1,2,1,1
1,1,1,1,1,1,1,1,1,1,1
1,1,1,1,1,1,1,1,1,1,1
1,1,2,1,1,1,1,1,1,1,1
1,1,1,1,1,1,1,2,1,1,1
1,1,1,1,1,1,1,1,1,1,1
1,1,1,1,1,1,1,1,1,1,1
endlayer

layer
1,1,1,1,1,1,1,1,1,1,1
1,1,1,1,1,1,1,1,1,1,1
1,1,2,1,1,1,2,1,1,1,1
1,1,1,1,1,1,1,1,1,1,1
1,1,1,1,1,1,1,1,2,1,1
1,1,1,1,1,1,1,1,1,1,1
1,1,1,1,1,1,1,1,1,1,1
1,1,2,1,1,1,1,1,1,1,1
1,1,1,1,1,1,1,2,1,1,1
1,1,1,1,1,1,1,1,1,1,1
1,1,1,1,1,1,1,1,1,1,1
endlayer

layer
1,1,1,1,1,1,1,1,1,1,1
1,1,1,1,1,1,1,1,1,1,1
1,1,2,1,1,1,2,1,1,1,1
1,1,1,1,1,1,1,1,1,1,1
1,1,1,1,1,1,1,1,2,1,1
1,1,1,1,1,1,1,1,1,1,1
1,1,1,1,1,1,1,1,1,1,1
1,1,2,1,1,1,1,1,1,1,1
1,1,1,1,1,1,1,2,1,1,1
1,1,1,1,1,1,1,1,1,1,1
1,1,1,1,1,1,1,1,1,1,1
endlayer

layer
1,1,1,1,1,1,1,1,1,1,1
1,1,1,1,1,1,1,1,1,1,1
1,1,2,1,1,1,2,1,1,1,1
1,1,1,1,1,1,1,1,1,1,1
1,1,1,1,1,1,1,1,2,1,1
1,1,1,1,1,1,1,1,1,1,1
1,1,1,1,1,1,1,1,1,1,1
1,1,2,1,1,1,1,1,1,1,1
1,1,1,1,1,1,1,2,1,1,1
1,1,1,1,1,1,1,1,1,1,1
1,1,1,1,1,1,1,1,1,1,1
endlayer

layer
1,1,1,1,1,1,1,1,1,1,1
1,1,1,1,1,1,1,1,1,1,1
1,1,2,1,1,1,2,1,1,1,1
1,1,1,1,1,1,1,1,1,1,1
1,1,1,1,1,1,1,1,2,1,1
1,1,1,1,1,1,1,1,1,1,1
1,1,1,1,1,1,1,1,1,1,1
1,1,2,1,1,1,1,1,1,1,1
1,1,1,1,1,1,1,2,1,1,1
1,1,1,1,1,1,1,1,1,1,1
1,1,1,1,1,1,1,1,1,1,1
endlayer

layer
1,1,1,1,1,1,1,1,1,1,1
1,1,1,1,1,1,1,1,1,1,1
1,1,2,1,1,1,2,1,1,1,1
1,1,1,1,1,1,1,1,1,1,1
1,1,1,1,1,1,1,1,2,1,1
1,1,1,1,1,1,1,1,1,1,1
1,1,1,1,1,1,1,1,1,1,1
1,1,2,1,1,1,1,1,1,1,1
1,1,1,1,1,1,1,2,1,1,1
1,1,1,1,1,1,1,1,1,1,1
1,1,1,1,1,1,1,1,1,1,1
endlayer

layer
1,1,1,1,1,1,1,1,1,1,1
1,1,1,1,1,1,1,1,1,1,1
1,1,2,1,1,1,2,1,1,1,1
1,1,1,1,1,1,1,1,1,1,1
1,1,1,1,1,1,1,1,2,1,1
1,1,1,1,1,1,1,1,1,1,1
1,1,1,1,1,1,1,1,1,1,1
1,1,2,1,1,1,1,1,1,1,1
1,1,1,1,1,1,1,2,1,1,1
1,1,1,1,1,1,1,1,1,1,1
1,1,1,1,1,1,1,1,1,1,1
endlayer

layer
1,1,1,1,1,1,1,1,1,1,1
1,1,1,1,1,1,1,1,1,1,1
1,1,2,1,1,1,2,1,1,1,1
1,1,1,1,1,1,1,1,1,1,1
1,1,1,1,1,1,1,1,2,1,1
1,1,1,1,1,1,1,1,1,1,1
1,1,1,1,1,1,1,1,1,1,1
1,1,2,1,1,1,1,1,1,1,1
1,1,1,1,1,1,1,2,1,1,1
1,1,1,1,1,1,1,1,1,1,1
1,1,1,1,1,1,1,1,1,1,1
endlayer

layer
1,1,1,1,1,1,1,1,1,1,1
1,1,1,1,1,1,1,1,1,1,1
1,1,2,1,1,1,2,1,1,1,1
1,1,1,1,1,1,1,1,1,1,1
1,1,1,1,1,1,1,1,2,1,1
1,1,1,1,1,1,1,1,1,1,1
1,1,1,1,1,1,1,1,1,1,1
1,1,2,1,1,1,1,1,1,1,1
1,1,1,1,1,1,1,2,1,1,1
1,1,1,1,1,1,1,1,1,1,1
1,1,1,1,1,1,1,1,1,1,1
endlayer

layer
1,1,1,1,1,1,1,1,1,1,1
1,1,1,1,1,1,1,1,1,1,1
1,1,2,1,1,1,2,1,1,1,1
1,1,1,1,1,1,1,1,1,1,1
1,1,1,1,1,1,1,1,2,1,1
1,1,1,1,1,1,1,1,1,1,1
1,1,1,1,1,1,1,1,1,1,1
1,3,3,3,3,3,3,3,3,1,1
1,1,1,1,1,1,1,2,1,1,1
1,1,1,1,1,1,1,1,1,1,1
1,1,1,1,1,1,1,1,1,1,1
endlayer

layer
1,1,1,1,1,1,1,1,1,1,1
1,1,4,1,1,1,1,4,1,1,1
1,1,4,1,1,1,2,4,1,1,1
1,1,4,1,1,1,1,4,1,1,1
1,1,4,1,1,1,1,4,2,1,1
1,1,4,1,1,1,1,4,1,1,1
1,1,4,1,1,1,1,4,1,1,1
1,1,4,1,1,1,1,4,1,1,1
1,1,4,1,1,1,1,4,1,1,1
1,1,1,1,1,1,1,4,1,1,1
1,1,1,1,1,1,1,1,1,1,1
endlayer

layer
1,1,1,1,1,1,1,1,1,1,1
1,1,1,1,1,1,1,1,1,1,1
1,1,2,1,1,1,2,1,1,1,1
5,3,3,3,3,3,3,3,3,3,5
1,1,1,1,1,1,1,1,2,1,1
1,1,1,1,1,1,1,1,1,1,1
1,1,1,1,1,1,1,1,1,1,1
1,1,2,1,1,1,1,6,1,1,1
1,1,1,1,1,1,1,2,1,1,1
1,1,1,1,1,1,1,1,1,1,1
1,1,1,1,1,1,1,1,1,1,1
endlayer

layer
1,1,1,5,1,1,1,1,5,1,1
1,1,1,4,5,1,1,1,4,1,1
1,1,2,4,5,1,2,1,4,1,1
1,1,1,4,1,1,1,1,4,1,1
1,1,1,4,1,1,1,1,4,1,1
1,1,1,4,1,1,1,1,4,1,1
1,1,1,4,1,1,1,1,4,1,1
1,1,2,4,1,1,1,6,4,1,1
1,1,1,4,1,1,1,2,4,1,1
1,1,1,4,1,1,1,1,4,1,1
1,1,1,5,1,1,1,1,5,1,1
endlayer

layer
1,1,1,1,1,1,1,1,1,1,1
1,1,7,7,9,7,7,8,7,1,1
5,3,3,3,3,3,3,3,3,3,5
1,7,7,7,7,7,7,7,7,7,1
1,7,7,10,7,10,7,10,7,7,1
5,3,3,3,3,3,3,3,3,3,1
1,7,7,10,7,10,7,10,7,7,1
1,7,2,7,11,7,7,6,8,1,1
5,3,3,3,3,3,3,3,3,3,5
1,1,1,12,1,1,1,1,1,1,1
1,1,1,1,1,1,1,1,1,1,1
endlayer

layer
1,1,1,1,1,1,1,1,1,1,1
1,1,9,13,14,15,14,13,5,1,1
1,13,2,11,0,0,0,0,2,5,1
1,18,17,16,0,0,0,0,0,8,1
1,9,17,0,0,0,0,0,0,8,1
1,9,17,0,0,0,0,0,0,8,1
1,9,12,0,0,0,0,0,0,8,1
1,9,7,0,0,0,0,20,19,5,1
1,7,11,0,0,0,0,2,5,1,1
1,1,5,12,11,12,12,5,1,1,1
1,1,1,1,1,1,1,1,1,1,1
endlayer

layer
1,1,1,1,1,1,1,1,1,1,1
1,1,13,9,5,21,5,8,13,1,1
1,24,23,11,0,0,0,0,22,8,1
18,0,0,16,0,0,0,0,0,8,1
18,0,0,0,0,0,0,0,0,19,1
25,0,0,0,0,0,0,0,0,15,1
1,26,12,0,0,0,0,0,0,19,1
1,11,7,0,0,0,0,0,26,8,1
1,9,11,0,0,0,0,2,12,1,1
1,1,12,14,15,15,14,5,1,1,1
1,1,1,1,1,1,1,1,1,1,1
endlayer

layer
1,1,1,1,1,1,1,1,1,1,1
1,1,5,24,24,24,24,24,5,1,1
27,22,22,11,0,0,0,0,22,8,1
28,26,17,16,0,0,0,0,0,13,1
25,29,17,0,0,0,0,0,0,5,1
18,29,17,0,0,0,0,0,0,30,1
23,26,12,0,0,0,0,0,0,5,1
1,26,7,0,0,0,0,0,29,12,1
1,5,11,0,0,0,0,2,13,1,1
1,1,23,24,28,28,24,15,1,1,1
1,1,1,1,1,1,1,1,1,1,1
endlayer

layer
1,1,1,1,1,1,1,1,1,1,1
1,28,24,24,24,23,24,24,24,1,1
24,31,31,11,0,0,0,0,18,5,1
25,0,0,0,0,0,0,0,0,8,1
32,0,0,0,0,0,0,0,0,8,1
32,0,0,0,0,0,0,0,0,8,1
25,22,12,0,0,0,0,0,0,8,1
32,26,7,0,0,0,0,0,26,12,1
1,25,13,0,0,0,0,2,26,1,1
1,1,31,31,23,23,23,26,1,1,1
1,1,1,1,1,1,1,1,1,1,1
endlayer

layer
1,1,1,1,1,1,1,1,1,1,1
1,1,25,26,34,34,24,34,33,1,1
18,34,23,11,29,0,0,23,26,32,1
24,0,0,0,0,0,0,0,23,26,1
5,0,0,0,0,0,0,0,0,29,1
5,0,0,0,0,0,0,0,0,29,1
23,18,29,0,0,0,0,0,24,29,1
1,25,28,0,0,0,0,18,26,32,1
1,1,32,24,24,24,18,31,32,1,1
1,1,1,1,31,26,31,1,1,1,1
1,1,1,1,1,1,1,1,1,1,1
endlayer

layer
1,1,1,1,1,1,1,1,1,1,1
1,1,1,1,32,34,34,1,1,1,1
1,32,34,26,22,22,26,33,1,1,1
32,32,18,12,12,12,12,18,34,1,1
26,18,18,8,0,0,0,9,22,33,1
26,28,26,8,0,0,0,9,26,32,1
32,25,26,8,0,0,0,9,33,1,1
1,1,32,29,24,24,24,31,1,1,1
1,1,1,1,32,31,33,1,1,1,1
1,1,1,1,1,1,1,1,1,1,1
1,1,1,1,1,1,1,1,1,1,1
endlayer

layer
1,1,1,1,1,1,1,1,1,1,1
1,1,1,1,1,1,1,1,1,1,1
1,1,1,1,32,32,32,1,1,1,1
1,1,1,25,34,26,34,34,1,1,1
1,1,34,26,12,12,12,26,22,1,1
1,1,31,31,8,17,9,22,33,1,1
1,1,1,25,13,13,13,33,1,1,1
1,1,1,1,31,31,31,1,1,1,1
1,1,1,1,1,1,1,1,1,1,1
1,1,1,1,1,1,1,1,1,1,1
1,1,1,1,1,1,1,1,1,1,1
endlayer

layer
1,1,1,1,1,1,1,1,1,1,1
1,1,1,1,1,1,1,1,1,1,1
1,1,1,1,1,1,1,1,1,1,1
1,1,1,1,1,1,1,1,1,1,1
1,1,1,32,32,32,32,32,1,1,1
1,1,1,1,32,0,32,32,1,1,1
1,1,1,1,32,32,32,1,1,1,1
1,1,1,1,1,1,1,1,1,1,1
1,1,1,1,1,1,1,1,1,1,1
1,1,1,1,1,1,1,1,1,1,1
1,1,1,1,1,1,1,1,1,1,1
endlayer

