
# Created by Ruins mod version 16.7 Ingame Parser
# authoring Player: lafuller

weight=1
embed_into_distance=41
acceptable_target_blocks=
unacceptable_target_blocks=ice,bedrock,netherrack,nether_brick,nether_brick_fence,soul_sand,quartz_ore,end_stone,obsidian,iron_bars,cloud,flesh,ash_block,slime_grass,slime_congealed,slime_dirt
dimensions=25,17,17
allowable_overhang=0
max_leveling=80
leveling_buffer=-1
preserve_water=0
preserve_lava=0

rule1=0,100,preserveBlock
rule2=0,100,stonebrick-0,stonebrick-0,stonebrick-1,stonebrick-1,stonebrick-2,stonebrick-2,stone-5,cobblestone
rule3=0,100,minecraft:cobblestone_wall-0
rule4=0,100,minecraft:stone_slab-5
rule5=0,100,stonebrick-0,stonebrick-1,stonebrick-2,stonebrick-2,stone-5,stone-5,stone-6,stone-6,cobblestone
rule6=0,100,minecraft:stone_brick_stairs-0
rule7=0,100,minecraft:stone_slab-8
rule8=0,100,minecraft:stone_brick_stairs-3
rule9=0,100,minecraft:stone_brick_stairs-1
rule10=0,100,minecraft:stone_brick_stairs-2
rule11=0,100,minecraft:stone_slab-13
rule12=0,100,minecraft:stone_brick_stairs-7
rule13=0,100,minecraft:stone_brick_stairs-5
rule14=0,100,minecraft:stone_brick_stairs-4
rule15=0,100,minecraft:stone_brick_stairs-6
rule16=0,100,sponge-0,diamond_ore-0,lapis_block-0,gold_block-0,emerald_block-0,iron_block-0,coal_block-0,gold_ore-0,redstone_ore-0,lapis_ore-0,emerald_ore-0,lapis_block-0,gold_block-0,gold_ore-0,redstone_ore-0,lapis_ore-0,emerald_ore-0
rule17=0,100,minecraft:sea_lantern-0

layer
1,1,2,2,2,2,2,2,2,2,1,1,1,1,1,1,1
1,1,2,2,2,2,2,2,2,2,2,2,2,1,1,1,1
1,1,2,2,2,2,2,2,2,2,2,2,2,2,2,2,2
1,1,2,2,2,2,2,2,2,2,2,2,2,2,2,2,2
1,2,2,2,2,2,2,2,2,2,2,2,2,2,2,2,2
1,2,2,2,2,2,2,2,2,2,2,2,2,2,2,2,2
1,2,2,2,2,2,2,2,2,2,2,2,2,2,2,2,2
2,2,2,2,2,2,2,2,2,2,2,2,2,2,2,2,2
2,2,2,2,2,2,2,2,2,2,2,2,2,2,2,2,2
2,2,2,2,2,2,2,2,2,2,2,2,2,2,2,2,2
2,2,2,2,2,2,2,2,2,2,2,2,2,2,2,2,1
2,2,2,2,2,2,2,2,2,2,2,2,2,2,2,2,1
2,2,2,2,2,2,2,2,2,2,2,2,2,2,2,2,1
2,2,2,2,2,2,2,2,2,2,2,2,2,2,2,1,1
2,2,2,2,2,2,2,2,2,2,2,2,2,2,2,1,1
1,1,1,1,2,2,2,2,2,2,2,2,2,2,2,1,1
1,1,1,1,1,1,1,2,2,2,2,2,2,2,2,1,1
endlayer

layer
1,1,2,2,2,2,2,2,2,2,1,1,1,1,1,1,1
1,1,0,3,0,2,2,2,2,2,2,2,2,1,1,1,1
1,1,4,2,2,2,2,2,2,2,2,2,2,2,4,0,2
1,1,2,2,0,2,0,2,2,2,2,2,2,2,2,3,2
1,2,2,2,0,2,0,2,0,2,2,2,0,0,2,0,2
1,2,2,2,2,2,2,2,0,2,0,2,2,2,2,2,2
1,2,2,2,2,0,0,2,2,2,0,2,0,0,2,2,2
2,2,2,2,2,2,2,2,2,2,2,2,2,2,2,2,2
2,2,2,2,0,0,2,2,2,2,2,0,0,2,2,2,2
2,2,2,2,2,2,2,2,2,2,2,2,2,2,2,2,2
2,2,2,0,0,2,0,2,2,2,0,0,2,2,2,2,1
2,2,2,2,2,2,0,2,0,2,2,2,2,2,2,2,1
2,0,2,0,0,2,2,2,0,2,0,2,0,2,2,2,1
2,3,2,2,2,2,2,2,2,2,0,2,0,2,2,1,1
2,0,4,2,2,2,2,2,2,2,2,2,2,2,4,1,1
1,1,1,1,2,2,2,2,2,2,2,2,0,3,0,1,1
1,1,1,1,1,1,1,2,2,2,2,2,2,2,2,1,1
endlayer

layer
1,1,2,2,2,2,2,2,2,2,1,1,1,1,1,1,1
1,1,0,3,0,5,5,5,5,5,5,5,4,1,1,1,1
1,1,0,2,5,5,5,5,5,5,5,5,4,0,0,0,2
1,1,0,8,7,5,7,5,5,5,5,5,6,6,2,3,2
1,4,4,8,7,5,7,5,7,5,5,5,7,7,5,0,2
1,5,5,5,5,5,5,5,7,5,7,5,5,5,5,5,2
1,5,5,5,5,7,7,5,5,5,7,5,7,7,5,5,2
2,5,5,5,5,5,5,9,9,9,5,5,5,5,5,5,2
2,5,5,5,7,7,5,10,0,8,5,7,7,5,5,5,2
2,5,5,5,5,5,5,6,6,6,5,5,5,5,5,5,2
2,5,5,7,7,5,7,5,5,5,7,7,5,5,5,5,1
2,5,5,5,5,5,7,5,7,5,5,5,5,5,5,5,1
2,0,5,7,7,5,5,5,7,5,7,5,7,10,4,4,1
2,3,2,9,9,5,5,5,5,5,7,5,7,10,0,1,1
2,0,0,0,4,5,5,5,5,5,5,5,5,2,0,1,1
1,1,1,1,4,5,5,5,5,5,5,5,0,3,0,1,1
1,1,1,1,1,1,1,2,2,2,2,2,2,2,2,1,1
endlayer

layer
1,1,2,2,2,2,2,2,2,2,1,1,1,1,1,1,1
1,1,0,2,2,0,2,2,2,2,4,0,0,1,1,1,1
1,1,0,2,2,3,2,9,9,9,4,0,0,0,0,0,2
1,1,0,0,0,0,0,0,0,0,0,0,0,0,2,2,2
1,0,0,0,0,0,0,0,0,0,0,0,0,0,2,2,2
1,0,0,0,0,0,0,0,0,0,0,0,0,0,3,0,2
1,4,4,0,0,0,0,0,0,0,0,0,0,0,2,2,2
2,2,10,0,0,0,0,0,0,0,0,0,0,0,8,2,2
2,2,10,0,0,0,0,0,0,0,0,0,0,0,8,2,2
2,2,10,0,0,0,0,0,0,0,0,0,0,0,8,2,2
2,2,2,0,0,0,0,0,0,0,0,0,0,0,4,4,1
2,0,3,0,0,0,0,0,0,0,0,0,0,0,0,0,1
2,2,2,0,0,0,0,0,0,0,0,0,0,0,0,0,1
2,2,2,0,0,0,0,0,0,0,0,0,0,0,0,1,1
2,0,0,0,0,0,4,6,6,6,2,3,2,2,0,1,1
1,1,1,1,0,0,4,2,2,2,2,0,2,2,0,1,1
1,1,1,1,1,1,1,2,2,2,2,2,2,2,2,1,1
endlayer

layer
1,1,2,2,2,2,2,2,4,0,1,1,1,1,1,1,1
1,1,0,2,2,0,2,9,4,0,0,0,0,1,1,1,1
1,1,0,2,2,3,2,0,0,0,0,0,0,0,0,0,2
1,1,0,0,0,0,0,0,0,0,0,0,0,0,2,2,2
1,0,0,0,0,0,0,0,0,0,0,0,0,0,2,2,2
1,0,0,0,0,0,0,0,0,0,0,0,0,0,3,0,2
1,0,0,0,0,0,0,0,0,0,0,0,0,0,2,2,2
0,0,0,0,0,0,0,0,0,0,0,0,0,0,0,8,2
4,4,0,0,0,0,0,0,0,0,0,0,0,0,0,4,4
2,10,0,0,0,0,0,0,0,0,0,0,0,0,0,0,0
2,2,2,0,0,0,0,0,0,0,0,0,0,0,0,0,1
2,0,3,0,0,0,0,0,0,0,0,0,0,0,0,0,1
2,2,2,0,0,0,0,0,0,0,0,0,0,0,0,0,1
2,2,2,0,0,0,0,0,0,0,0,0,0,0,0,1,1
2,0,0,0,0,0,0,0,0,0,2,3,2,2,0,1,1
1,1,1,1,0,0,0,0,4,6,2,0,2,2,0,1,1
1,1,1,1,1,1,1,0,4,2,2,2,2,2,2,1,1
endlayer

layer
1,1,2,2,2,2,2,0,0,0,1,1,1,1,1,1,1
1,1,11,2,2,2,4,0,0,0,0,0,0,1,1,1,1
1,1,0,2,2,2,0,0,0,0,0,0,0,0,0,11,2
1,1,0,0,0,0,0,0,0,0,0,0,0,0,2,2,2
1,0,0,0,0,0,0,0,0,0,0,0,0,0,2,2,2
1,0,0,0,0,0,0,0,0,0,0,0,0,0,2,2,2
1,0,0,0,0,0,0,0,0,0,0,0,0,0,0,4,2
0,0,0,0,0,0,0,0,0,0,0,0,0,0,0,0,0
0,0,0,0,0,0,0,0,0,0,0,0,0,0,0,0,0
0,0,0,0,0,0,0,0,0,0,0,0,0,0,0,0,0
2,4,0,0,0,0,0,0,0,0,0,0,0,0,0,0,1
2,2,2,0,0,0,0,0,0,0,0,0,0,0,0,0,1
2,2,2,0,0,0,0,0,0,0,0,0,0,0,0,0,1
2,2,2,0,0,0,0,0,0,0,0,0,0,0,0,1,1
2,11,0,0,0,0,0,0,0,0,0,2,2,2,0,1,1
1,1,1,1,0,0,0,0,0,0,4,2,2,2,11,1,1
1,1,1,1,1,1,1,0,0,0,2,2,2,2,2,1,1
endlayer

layer
1,1,2,2,2,2,2,0,0,0,1,1,1,1,1,1,1
1,1,2,2,4,0,0,0,0,0,0,0,0,1,1,1,1
1,1,13,2,2,2,0,0,0,0,0,0,0,0,12,2,2
1,1,0,0,0,0,0,0,0,0,0,0,0,0,2,2,2
1,0,0,0,0,0,0,0,0,0,0,0,0,0,2,4,2
1,0,0,0,0,0,0,0,0,0,0,0,0,0,2,0,2
1,0,0,0,0,0,0,0,0,0,0,0,0,0,0,0,2
0,0,0,0,0,0,0,0,0,0,0,0,0,0,0,0,0
0,0,0,0,0,0,0,0,0,0,0,0,0,0,0,0,0
0,0,0,0,0,0,0,0,0,0,0,0,0,0,0,0,0
2,0,0,0,0,0,0,0,0,0,0,0,0,0,0,0,1
2,0,2,0,0,0,0,0,0,0,0,0,0,0,0,0,1
2,4,2,0,0,0,0,0,0,0,0,0,0,0,0,0,1
2,2,2,0,0,0,0,0,0,0,0,0,0,0,0,1,1
2,2,15,0,0,0,0,0,0,0,0,2,2,2,14,1,1
1,1,1,1,0,0,0,0,0,0,0,0,4,2,2,1,1
1,1,1,1,1,1,1,0,0,0,2,2,2,2,2,1,1
endlayer

layer
1,1,2,2,2,2,2,0,0,0,1,1,1,1,1,1,1
1,1,0,0,0,0,0,0,0,0,0,0,0,1,1,1,1
1,1,4,4,3,2,0,0,0,0,0,0,0,12,4,0,2
1,1,13,13,13,11,0,0,0,0,0,0,0,12,4,0,2
1,0,0,0,0,0,0,0,0,0,0,0,0,12,3,0,2
1,0,0,0,0,0,0,0,0,0,0,0,0,11,2,0,2
1,0,0,0,0,0,0,0,0,0,0,0,0,0,0,0,2
0,0,0,0,0,0,0,0,0,0,0,0,0,0,0,0,0
0,0,0,0,0,0,0,0,0,0,0,0,0,0,0,0,0
0,0,0,0,0,0,0,0,0,0,0,0,0,0,0,0,0
2,0,0,0,0,0,0,0,0,0,0,0,0,0,0,0,1
2,0,2,15,0,0,0,0,0,0,0,0,0,0,0,0,1
2,0,3,15,0,0,0,0,0,0,0,0,0,0,0,0,1
2,0,4,15,0,0,0,0,0,0,0,11,14,14,14,1,1
2,0,4,15,0,0,0,0,0,0,0,2,3,4,4,1,1
1,1,1,1,0,0,0,0,0,0,0,0,0,0,0,1,1
1,1,1,1,1,1,1,0,0,0,2,2,2,2,2,1,1
endlayer

layer
1,1,2,2,2,2,2,5,5,5,1,1,1,1,1,1,1
1,1,0,0,0,0,0,11,5,5,5,5,4,1,1,1,1
1,1,0,0,3,5,5,5,5,5,5,5,4,0,0,0,2
1,1,0,0,4,5,5,5,5,5,5,5,4,0,0,0,2
1,4,4,4,4,5,5,5,5,5,5,5,4,4,3,0,2
1,5,5,5,5,5,5,5,5,5,5,5,5,5,5,0,2
1,5,5,5,5,5,5,5,5,5,5,5,5,5,5,0,2
5,5,5,5,5,5,5,10,9,8,5,5,5,5,5,11,5
5,5,5,5,5,5,5,10,16,8,5,5,5,5,5,5,5
5,11,5,5,5,5,5,10,6,8,5,5,5,5,5,5,5
2,0,5,5,5,5,5,5,5,5,5,5,5,5,5,5,1
2,0,5,5,5,5,5,5,5,5,5,5,5,5,5,5,1
2,0,3,4,4,5,5,5,5,5,5,5,4,4,4,4,1
2,0,0,0,4,5,5,5,5,5,5,5,4,0,0,1,1
2,0,0,0,4,5,5,5,5,5,5,5,3,0,0,1,1
1,1,1,1,4,5,5,5,5,11,0,0,0,0,0,1,1
1,1,1,1,1,1,1,5,5,5,2,2,2,2,2,1,1
endlayer

layer
1,1,2,2,2,2,2,2,2,2,1,1,1,1,1,1,1
1,1,0,0,0,11,2,2,2,2,4,0,0,1,1,1,1
1,1,0,0,3,2,2,2,2,2,4,0,0,0,0,0,2
1,1,0,0,0,0,8,9,9,9,4,0,0,0,0,0,2
1,0,0,0,0,0,0,0,0,0,0,0,0,0,3,0,2
1,0,0,0,0,0,0,0,0,0,0,0,0,0,2,11,2
1,4,4,4,0,0,0,0,0,0,0,0,0,6,2,2,2
2,2,2,10,0,0,0,0,0,0,0,0,0,8,2,2,2
2,2,2,10,0,0,0,0,0,0,0,0,0,8,2,2,2
2,2,2,10,0,0,0,0,0,0,0,0,0,8,2,2,2
2,2,2,9,0,0,0,0,0,0,0,0,0,4,4,4,1
2,11,2,0,0,0,0,0,0,0,0,0,0,0,0,0,1
2,0,3,0,0,0,0,0,0,0,0,0,0,0,0,0,1
2,0,0,0,0,0,4,6,6,6,10,0,0,0,0,1,1
2,0,0,0,0,0,4,2,2,2,2,2,3,0,0,1,1
1,1,1,1,0,0,4,2,2,2,2,11,0,0,0,1,1
1,1,1,1,1,1,1,2,2,2,2,2,2,2,2,1,1
endlayer

layer
1,1,2,2,2,2,2,2,4,0,1,1,1,1,1,1,1
1,1,0,0,12,2,2,2,4,0,0,0,0,1,1,1,1
1,1,0,0,3,2,2,9,4,0,0,0,0,0,0,0,2
1,1,0,0,0,0,0,0,0,0,0,0,0,0,0,0,2
1,0,0,0,0,0,0,0,0,0,0,0,0,0,3,14,2
1,0,0,0,0,0,0,0,0,0,0,0,0,0,2,2,2
1,0,0,0,0,0,0,0,0,0,0,0,0,0,2,2,2
0,0,0,0,0,0,0,0,0,0,0,0,0,0,8,2,2
4,4,4,0,0,0,0,0,0,0,0,0,0,0,4,4,4
2,2,10,0,0,0,0,0,0,0,0,0,0,0,0,0,0
2,2,2,0,0,0,0,0,0,0,0,0,0,0,0,0,1
2,2,2,0,0,0,0,0,0,0,0,0,0,0,0,0,1
2,13,3,0,0,0,0,0,0,0,0,0,0,0,0,0,1
2,0,0,0,0,0,0,0,0,0,0,0,0,0,0,1,1
2,0,0,0,0,0,0,0,4,6,2,2,3,0,0,1,1
1,1,1,1,0,0,0,0,4,2,2,2,15,0,0,1,1
1,1,1,1,1,1,1,0,4,2,2,2,2,2,2,1,1
endlayer

layer
1,1,2,2,2,2,2,0,0,0,1,1,1,1,1,1,1
1,1,2,2,2,2,4,0,0,0,0,0,0,1,1,1,1
1,1,11,11,2,2,4,0,0,0,0,0,0,0,11,2,2
1,1,0,0,0,0,0,0,0,0,0,0,0,0,11,2,2
1,0,0,0,0,0,0,0,0,0,0,0,0,0,2,2,2
1,0,0,0,0,0,0,0,0,0,0,0,0,0,2,2,2
1,0,0,0,0,0,0,0,0,0,0,0,0,0,4,4,2
0,0,0,0,0,0,0,0,0,0,0,0,0,0,0,0,0
0,0,0,0,0,0,0,0,0,0,0,0,0,0,0,0,0
0,0,0,0,0,0,0,0,0,0,0,0,0,0,0,0,0
2,4,4,0,0,0,0,0,0,0,0,0,0,0,0,0,1
2,2,2,0,0,0,0,0,0,0,0,0,0,0,0,0,1
2,2,2,0,0,0,0,0,0,0,0,0,0,0,0,0,1
2,2,11,0,0,0,0,0,0,0,0,0,0,0,0,1,1
2,2,11,0,0,0,0,0,0,0,4,2,2,11,11,1,1
1,1,1,1,0,0,0,0,0,0,4,2,2,2,2,1,1
1,1,1,1,1,1,1,0,0,0,2,2,2,2,2,1,1
endlayer

layer
1,1,2,2,2,2,2,0,0,0,1,1,1,1,1,1,1
1,1,2,2,2,2,0,0,0,0,0,0,0,1,1,1,1
1,1,2,2,4,0,0,0,0,0,0,0,0,0,2,2,2
1,1,0,0,0,0,0,0,0,0,0,0,0,0,2,2,2
1,0,0,0,0,0,0,0,0,0,0,0,0,0,4,2,2
1,0,0,0,0,0,0,0,0,0,0,0,0,0,0,2,2
1,0,0,0,0,0,0,0,0,0,0,0,0,0,0,0,2
0,0,0,0,0,0,0,0,0,0,0,0,0,0,0,0,0
0,0,0,0,0,0,0,0,0,0,0,0,0,0,0,0,0
0,0,0,0,0,0,0,0,0,0,0,0,0,0,0,0,0
2,0,0,0,0,0,0,0,0,0,0,0,0,0,0,0,1
2,2,0,0,0,0,0,0,0,0,0,0,0,0,0,0,1
2,2,4,0,0,0,0,0,0,0,0,0,0,0,0,0,1
2,2,2,0,0,0,0,0,0,0,0,0,0,0,0,1,1
2,2,2,0,0,0,0,0,0,0,0,0,4,2,2,1,1
1,1,1,1,0,0,0,0,0,0,0,2,2,2,2,1,1
1,1,1,1,1,1,1,0,0,0,2,2,2,2,2,1,1
endlayer

layer
1,1,2,2,2,2,2,0,0,0,1,1,1,1,1,1,1
1,1,9,9,2,2,0,0,0,0,0,0,0,1,1,1,1
1,1,0,0,0,0,0,0,0,0,0,0,0,0,0,8,2
1,1,0,0,0,0,0,0,0,0,0,0,0,0,0,8,2
1,0,0,0,0,0,0,0,0,0,0,0,0,0,0,2,2
1,0,0,0,0,0,0,0,0,0,0,0,0,0,0,2,2
1,0,0,0,0,0,0,0,0,0,0,0,0,0,0,0,2
0,0,0,0,0,0,0,0,0,0,0,0,0,0,0,0,0
0,0,0,0,0,0,0,0,0,0,0,0,0,0,0,0,0
0,0,0,0,0,0,0,0,0,0,0,0,0,0,0,0,0
2,0,0,0,0,0,0,0,0,0,0,0,0,0,0,0,1
2,2,0,0,0,0,0,0,0,0,0,0,0,0,0,0,1
2,2,0,0,0,0,0,0,0,0,0,0,0,0,0,0,1
2,10,0,0,0,0,0,0,0,0,0,0,0,0,0,1,1
2,10,0,0,0,0,0,0,0,0,0,0,0,0,0,1,1
1,1,1,1,0,0,0,0,0,0,0,2,2,6,6,1,1
1,1,1,1,1,1,1,0,0,0,2,2,2,2,2,1,1
endlayer

layer
1,1,2,2,2,2,2,0,0,0,1,1,1,1,1,1,1
1,1,0,0,8,2,0,0,0,0,0,0,0,1,1,1,1
1,1,0,0,0,0,0,0,0,0,0,0,0,0,0,0,2
1,1,0,0,0,0,0,0,0,0,0,0,0,0,0,0,2
1,0,0,0,0,0,0,0,0,0,0,0,0,0,0,6,2
1,0,0,0,0,0,0,0,0,0,0,0,0,0,0,2,2
1,0,0,0,0,0,0,0,0,0,0,0,0,0,0,0,2
0,0,0,0,0,0,0,0,0,0,0,0,0,0,0,0,0
0,0,0,0,0,0,0,0,0,0,0,0,0,0,0,0,0
0,0,0,0,0,0,0,0,0,0,0,0,0,0,0,0,0
2,0,0,0,0,0,0,0,0,0,0,0,0,0,0,0,1
2,2,0,0,0,0,0,0,0,0,0,0,0,0,0,0,1
2,9,0,0,0,0,0,0,0,0,0,0,0,0,0,0,1
2,0,0,0,0,0,0,0,0,0,0,0,0,0,0,1,1
2,0,0,0,0,0,0,0,0,0,0,0,0,0,0,1,1
1,1,1,1,0,0,0,0,0,0,0,2,10,0,0,1,1
1,1,1,1,1,1,1,0,0,0,2,2,2,2,2,1,1
endlayer

layer
1,1,2,2,2,2,2,2,2,2,1,1,1,1,1,1,1
1,1,0,0,0,8,13,11,11,11,13,13,11,1,1,1,1
1,1,0,0,11,11,0,0,0,0,0,0,0,0,0,0,2
1,1,0,0,0,0,0,0,0,0,0,0,0,0,0,0,2
1,11,0,0,0,0,0,0,0,0,0,0,0,0,11,0,2
1,15,0,0,0,0,0,0,0,0,0,0,0,0,11,6,2
1,15,0,0,0,0,0,0,0,0,0,0,0,0,0,12,2
2,11,0,0,0,0,0,0,0,0,0,0,0,0,0,11,2
2,11,0,0,0,0,0,0,0,0,0,0,0,0,0,11,2
2,11,0,0,0,0,0,0,0,0,0,0,0,0,0,11,2
2,15,0,0,0,0,0,0,0,0,0,0,0,0,0,12,1
2,9,11,0,0,0,0,0,0,0,0,0,0,0,0,12,1
2,0,11,0,0,0,0,0,0,0,0,0,0,0,0,11,1
2,0,0,0,0,0,0,0,0,0,0,0,0,0,0,1,1
2,0,0,0,0,0,0,0,0,0,0,11,11,0,0,1,1
1,1,1,1,11,14,14,11,11,11,14,10,0,0,0,1,1
1,1,1,1,1,1,1,2,2,2,2,2,2,2,2,1,1
endlayer

layer
1,1,2,2,2,2,2,2,2,2,1,1,1,1,1,1,1
1,1,0,0,0,0,8,2,2,2,2,2,2,1,1,1,1
1,1,0,0,2,2,13,13,13,13,13,2,2,15,0,0,2
1,1,14,14,2,13,11,0,0,0,11,13,2,15,0,0,2
1,2,2,2,11,0,0,0,0,0,0,0,11,2,2,0,2
1,2,2,15,0,0,0,0,0,0,0,0,0,12,2,0,2
1,2,15,11,0,0,0,0,0,0,0,0,0,11,12,6,2
2,2,15,0,0,0,0,0,0,0,0,0,0,0,12,2,2
2,2,15,0,0,0,0,0,0,0,0,0,0,0,12,2,2
2,2,15,0,0,0,0,0,0,0,0,0,0,0,12,2,2
2,9,15,11,0,0,0,0,0,0,0,0,0,11,12,2,1
2,0,2,15,0,0,0,0,0,0,0,0,0,12,2,2,1
2,0,2,2,11,0,0,0,0,0,0,0,11,2,2,2,1
2,0,0,12,2,14,11,0,0,0,11,14,2,13,13,1,1
2,0,0,12,2,2,14,14,14,14,14,2,2,0,0,1,1
1,1,1,1,2,2,2,2,2,2,10,0,0,0,0,1,1
1,1,1,1,1,1,1,2,2,2,2,2,2,2,2,1,1
endlayer

layer
1,1,2,2,2,2,2,2,2,2,1,1,1,1,1,1,1
1,1,0,0,0,0,0,8,2,2,2,2,2,1,1,1,1
1,1,14,14,10,6,6,8,2,2,2,2,2,2,15,0,2
1,1,2,2,2,2,2,2,2,2,2,2,2,2,15,0,2
1,2,2,2,2,13,13,11,11,11,13,13,2,2,9,0,2
1,2,2,2,15,11,0,0,0,0,0,11,12,2,10,0,2
1,2,2,2,15,0,0,0,0,0,0,0,12,2,10,0,2
2,2,2,2,11,0,0,0,0,0,0,0,11,2,6,6,2
2,2,2,2,11,0,0,0,0,0,0,0,11,2,2,2,2
2,9,9,2,11,0,0,0,0,0,0,0,11,2,2,2,2
2,0,8,2,15,0,0,0,0,0,0,0,12,2,2,2,1
2,0,8,2,15,11,0,0,0,0,0,11,12,2,2,2,1
2,0,6,2,2,14,14,11,11,11,14,14,2,2,2,2,1
2,0,12,2,2,2,2,2,2,2,2,2,2,2,2,1,1
2,0,12,2,2,2,2,2,2,2,9,9,8,13,13,1,1
1,1,1,1,2,2,2,2,2,10,0,0,0,0,0,1,1
1,1,1,1,1,1,1,2,2,2,2,2,2,2,2,1,1
endlayer

layer
1,1,2,2,2,2,2,2,2,2,1,1,1,1,1,1,1
1,1,2,0,0,0,0,0,0,0,2,2,2,1,1,1,1
1,1,2,0,0,0,0,0,0,0,0,0,0,2,2,2,2
1,1,2,0,0,0,0,0,0,0,0,0,0,0,0,0,2
1,2,0,0,0,0,8,6,6,6,2,0,0,0,0,0,2
1,2,0,0,0,2,2,13,13,13,2,2,0,0,0,0,2
1,2,0,0,2,2,11,0,0,0,11,2,6,0,0,0,2
2,0,0,0,8,15,0,0,0,0,0,12,10,0,0,0,2
2,0,0,0,8,15,0,0,17,0,0,12,10,0,0,0,2
2,0,0,0,8,15,0,0,0,0,0,12,10,0,0,0,2
2,0,0,0,9,2,11,0,0,0,11,2,2,0,0,2,1
2,0,0,0,0,2,2,14,14,14,2,2,0,0,0,2,1
2,0,0,0,0,0,2,9,9,9,10,0,0,0,0,2,1
2,0,0,0,0,0,0,0,0,0,0,0,0,0,2,1,1
2,2,2,2,0,0,0,0,0,0,0,0,0,0,2,1,1
1,1,1,1,2,2,2,0,0,0,0,0,0,0,2,1,1
1,1,1,1,1,1,1,2,2,2,2,2,2,2,2,1,1
endlayer

layer
1,1,2,2,2,0,2,2,0,2,1,1,1,1,1,1,1
1,1,2,0,0,0,0,0,0,0,2,0,2,1,1,1,1
1,1,0,0,0,0,0,0,0,0,0,0,0,2,0,2,2
1,1,2,0,0,0,0,0,0,0,0,0,0,0,0,0,2
1,2,0,0,0,0,0,0,0,0,2,0,0,0,0,0,2
1,0,0,0,0,2,2,6,6,6,2,2,0,0,0,0,0
1,2,0,0,2,2,2,2,2,2,2,2,0,0,0,0,2
2,0,0,0,0,8,2,15,13,12,2,10,0,0,0,0,2
0,0,0,0,0,8,2,15,2,12,2,10,0,0,0,0,0
2,0,0,0,0,8,2,14,14,12,2,10,0,0,0,0,2
2,0,0,0,0,2,2,2,2,2,2,2,2,0,0,2,1
0,0,0,0,0,2,2,9,9,9,2,2,0,0,0,0,1
2,0,0,0,0,0,2,0,0,0,0,0,0,0,0,2,1
2,0,0,0,0,0,0,0,0,0,0,0,0,0,2,1,1
2,2,0,2,0,0,0,0,0,0,0,0,0,0,0,1,1
1,1,1,1,2,0,2,0,0,0,0,0,0,0,2,1,1
1,1,1,1,1,1,1,2,0,2,2,0,2,2,2,1,1
endlayer

layer
1,1,2,2,2,0,2,2,0,2,1,1,1,1,1,1,1
1,1,2,0,0,0,0,0,0,0,2,0,2,1,1,1,1
1,1,0,0,0,0,0,0,0,0,0,0,0,2,0,2,2
1,1,2,0,0,0,0,0,0,0,0,0,0,0,0,0,2
1,2,0,0,0,0,0,0,0,0,2,0,0,0,0,0,2
1,0,0,0,0,2,2,0,0,0,2,2,0,0,0,0,0
1,2,0,0,2,2,2,0,0,0,2,2,0,0,0,0,2
2,0,0,0,0,0,0,0,0,0,0,0,0,0,0,0,2
0,0,0,0,0,0,0,0,0,0,0,0,0,0,0,0,0
2,0,0,0,0,0,0,0,0,0,0,0,0,0,0,0,2
2,0,0,0,0,2,2,0,0,0,2,2,2,0,0,2,1
0,0,0,0,0,2,2,0,0,0,2,2,0,0,0,0,1
2,0,0,0,0,0,2,0,0,0,0,0,0,0,0,2,1
2,0,0,0,0,0,0,0,0,0,0,0,0,0,2,1,1
2,2,0,2,0,0,0,0,0,0,0,0,0,0,0,1,1
1,1,1,1,2,0,2,0,0,0,0,0,0,0,2,1,1
1,1,1,1,1,1,1,2,0,2,2,0,2,2,2,1,1
endlayer

layer
1,1,2,2,2,2,2,2,2,2,1,1,1,1,1,1,1
1,1,2,0,0,0,0,0,0,0,2,2,2,1,1,1,1
1,1,2,0,0,0,0,0,0,0,0,0,0,2,2,2,2
1,1,2,0,0,0,0,0,0,0,0,0,0,0,0,0,2
1,2,0,0,0,0,0,0,0,0,2,0,0,0,0,0,2
1,2,0,0,12,2,2,0,0,0,2,2,0,0,0,0,2
1,2,0,0,2,2,2,0,0,0,2,2,0,0,0,0,2
2,0,0,0,0,0,0,0,0,0,0,0,0,0,0,0,2
2,0,0,0,0,0,0,0,0,0,0,0,0,0,0,0,2
2,0,0,0,0,0,0,0,0,0,0,0,0,0,0,0,2
2,0,0,0,0,2,2,0,0,0,2,2,2,0,0,2,1
2,0,0,0,0,2,2,0,0,0,2,2,15,0,0,2,1
2,0,0,0,0,0,2,0,0,0,0,0,0,0,0,2,1
2,0,0,0,0,0,0,0,0,0,0,0,0,0,2,1,1
2,2,2,2,0,0,0,0,0,0,0,0,0,0,2,1,1
1,1,1,1,2,2,2,0,0,0,0,0,0,0,2,1,1
1,1,1,1,1,1,1,2,2,2,2,2,2,2,2,1,1
endlayer

layer
1,1,2,2,2,2,2,2,2,2,1,1,1,1,1,1,1
1,1,2,13,13,13,13,13,13,13,2,2,2,1,1,1,1
1,1,2,15,11,11,11,0,0,0,0,0,0,2,2,2,2
1,1,2,13,11,11,11,0,0,0,0,0,0,0,13,12,2
1,2,15,11,12,14,14,0,0,0,2,14,0,0,0,12,2
1,2,15,12,2,2,2,0,0,0,2,2,15,0,0,12,2
1,2,15,12,2,2,2,0,0,0,2,2,15,0,0,12,2
2,15,0,0,0,0,0,0,0,0,0,0,0,0,0,12,2
2,15,0,0,0,0,0,0,0,0,0,0,0,0,0,12,2
2,15,0,0,0,0,0,0,0,0,0,0,0,0,0,12,2
2,15,0,0,12,2,2,0,0,0,2,2,2,15,12,2,1
2,15,0,0,12,2,2,0,0,0,2,2,2,15,12,2,1
2,15,0,0,0,13,2,0,0,0,13,13,15,11,12,2,1
2,14,14,0,0,0,0,0,0,0,11,11,11,14,2,1,1
2,2,2,2,0,0,0,0,0,0,11,11,11,12,2,1,1
1,1,1,1,2,2,2,14,14,14,14,14,14,14,2,1,1
1,1,1,1,1,1,1,2,2,2,2,2,2,2,2,1,1
endlayer

layer
1,1,2,2,2,2,2,2,2,2,1,1,1,1,1,1,1
1,1,2,2,2,2,2,2,2,2,2,2,2,1,1,1,1
1,1,2,2,2,2,2,15,13,12,2,2,2,2,2,2,2
1,1,2,2,2,2,2,15,0,12,2,2,2,2,2,2,2
1,2,2,2,2,2,2,15,0,12,2,2,2,2,2,2,2
1,2,2,2,2,2,2,15,0,12,2,2,2,2,2,2,2
1,2,2,2,2,2,2,15,0,12,2,2,2,2,2,2,2
2,2,13,13,13,13,13,15,0,13,13,13,13,13,12,2,2
2,2,15,0,0,0,0,0,0,0,0,0,0,0,12,2,2
2,2,15,14,14,14,14,14,0,14,14,14,14,14,12,2,2
2,2,2,2,2,2,2,15,0,12,2,2,2,2,2,2,1
2,2,2,2,2,2,2,15,0,12,2,2,2,2,2,2,1
2,2,2,2,2,2,2,15,0,12,2,2,2,2,2,2,1
2,2,2,2,2,2,2,15,0,12,2,2,2,2,2,1,1
2,2,2,2,2,2,2,14,14,12,2,2,2,2,2,1,1
1,1,1,1,2,2,2,2,2,2,2,2,2,2,2,1,1
1,1,1,1,1,1,1,2,2,2,2,2,2,2,2,1,1
endlayer

layer
1,1,1,1,1,1,1,1,1,1,1,1,1,1,1,1,1
1,1,1,2,1,1,2,1,1,2,1,1,1,1,1,1,1
1,1,1,2,1,1,2,2,2,2,1,1,2,1,1,1,1
1,1,1,2,1,1,2,2,2,2,1,1,2,2,2,2,1
1,1,2,2,2,2,2,2,2,2,2,2,2,1,1,1,1
1,1,1,1,2,2,2,2,2,2,2,2,2,1,1,1,1
1,1,1,1,2,2,2,2,2,2,2,2,2,2,2,2,1
1,2,2,2,2,2,2,2,2,2,2,2,2,2,2,1,1
1,1,2,2,2,2,2,2,2,2,2,2,2,2,2,1,1
1,1,2,2,2,2,2,2,2,2,2,2,2,2,2,2,1
1,2,2,2,2,2,2,2,2,2,2,2,2,1,1,1,1
1,1,1,1,2,2,2,2,2,2,2,2,2,1,1,1,1
1,1,1,1,2,2,2,2,2,2,2,2,2,2,2,1,1
1,2,2,2,2,1,1,2,2,2,2,1,1,2,1,1,1
1,1,1,1,2,1,1,2,2,2,2,1,1,2,1,1,1
1,1,1,1,1,1,1,2,1,1,2,1,1,2,1,1,1
1,1,1,1,1,1,1,1,1,1,1,1,1,1,1,1,1
endlayer

