# Gilly's Sliding Catacombs #2

weight=1
embed_into_distance=30
acceptable_target_blocks=
unacceptable_target_blocks=
dimensions=20,11,11
allowable_overhang=0
max_leveling=3
leveling_buffer=-1
preserve_water=0
preserve_lava=0

rule1=0,100,stonebrick,stonebrick,stonebrick,stonebrick,stonebrick,stonebrick,stonebrick-2,stonebrick-1
rule2=0,100,minecraft:stone_slab-5
rule3=0,100,minecraft:stone_brick_stairs-7
rule4=0,100,minecraft:stone_slab-13
rule5=0,100,minecraft:stone_brick_stairs-4
rule6=0,100,minecraft:stone_brick_stairs-5
rule7=0,100,minecraft:stone_brick_stairs-6
rule8=0,100,minecraft:stone_brick_stairs-3
rule9=0,100,minecraft:stone_brick_stairs-1
rule10=0,100,lapis_block-0,gold_block-0,emerald_block-0,iron_block-0,coal_block-0,sponge-0,gold_ore-0,diamond_ore-0,redstone_ore-0,lapis_ore-0,emerald_ore-0
rule11=0,100,minecraft:stone_brick_stairs-2
rule12=0,100,minecraft:stone_brick_stairs-0

layer
1,1,1,1,1,1,1,1,1,1,1
1,1,1,1,1,1,1,1,1,1,1
1,1,1,1,1,1,1,1,1,1,1
1,1,1,1,2,2,2,1,1,1,1
1,1,1,2,2,2,2,2,1,1,1
1,1,1,2,2,2,2,2,1,1,1
1,1,1,2,2,2,2,2,1,1,1
1,1,1,1,2,2,2,1,1,1,1
1,1,1,1,1,1,1,1,1,1,1
1,1,1,1,1,1,1,1,1,1,1
1,1,1,1,1,1,1,1,1,1,1
endlayer

layer
1,0,0,0,0,0,1,1,1,1,1
1,1,0,0,0,0,0,1,0,1,0
1,0,0,0,0,0,0,0,0,0,0
1,1,0,0,0,0,0,0,0,0,0
1,0,0,0,0,0,0,0,0,0,0
0,0,0,0,0,0,0,0,0,0,0
0,0,0,0,0,0,0,0,0,0,1
0,0,0,0,0,0,0,0,0,1,1
0,0,0,0,0,0,0,0,0,0,1
0,1,0,1,0,0,0,0,0,1,1
1,1,1,1,1,0,0,0,0,0,1
endlayer

layer
1,0,0,0,0,0,1,1,1,1,1
1,1,0,0,0,0,0,1,0,1,0
1,0,0,0,0,0,0,0,0,0,0
1,1,0,0,0,0,0,0,0,0,0
1,0,0,0,0,0,0,0,0,0,0
0,0,0,0,0,0,0,0,0,0,0
0,0,0,0,0,0,0,0,0,0,1
0,0,0,0,0,0,0,0,0,1,1
0,0,0,0,0,0,0,0,0,0,1
0,1,0,1,0,0,0,0,0,1,1
1,1,1,1,1,0,0,0,0,0,1
endlayer

layer
1,0,0,0,0,0,1,1,1,1,1
1,1,0,0,0,0,0,1,0,1,0
1,0,0,0,0,0,0,0,0,0,0
1,1,0,0,0,0,0,0,0,0,0
1,0,0,0,0,0,0,0,0,0,0
0,0,0,0,0,0,0,0,0,0,0
0,0,0,0,0,0,0,0,0,0,1
0,0,0,0,0,0,0,0,0,1,1
0,0,0,0,0,0,0,0,0,0,1
0,1,0,1,0,0,0,0,0,1,1
1,1,1,1,1,0,0,0,0,0,1
endlayer

layer
1,0,0,0,4,3,1,1,1,1,1
1,1,0,0,0,0,0,1,0,1,0
1,0,0,0,0,0,0,0,0,0,0
1,1,0,0,0,0,0,0,0,0,0
1,0,0,0,0,0,0,0,0,0,4
6,0,0,0,0,0,0,0,0,0,5
4,0,0,0,0,0,0,0,0,0,1
0,0,0,0,0,0,0,0,0,1,1
0,0,0,0,0,0,0,0,0,0,1
0,1,0,1,0,0,0,0,0,1,1
1,1,1,1,1,7,4,0,0,0,1
endlayer

layer
1,1,1,1,1,1,1,1,1,1,1
1,1,1,1,1,1,1,1,1,1,1
1,1,1,1,1,1,1,1,1,1,1
1,1,1,1,1,1,1,1,1,1,1
1,1,1,1,9,9,8,1,1,1,1
1,1,1,1,11,10,8,1,1,1,1
1,1,1,1,11,12,12,1,1,1,1
1,1,1,1,1,1,1,1,1,1,1
1,1,1,1,1,1,1,1,1,1,1
1,1,1,1,1,1,1,1,1,1,1
1,1,1,1,1,1,1,1,1,1,1
endlayer

layer
1,1,1,1,1,0,0,0,2,1,1
1,0,0,0,0,0,0,0,0,0,1
2,0,0,0,0,0,0,0,0,0,1
0,0,0,0,0,0,0,0,0,0,1
0,0,0,0,0,0,0,0,0,0,1
0,0,0,0,0,0,0,0,0,0,0
1,0,0,0,0,0,0,0,0,0,0
1,0,0,0,0,0,0,0,0,0,0
1,0,0,0,0,0,0,0,0,0,2
1,0,0,0,0,0,0,0,0,0,1
1,1,2,0,0,0,1,1,1,1,1
endlayer

layer
1,1,1,1,1,0,0,0,0,0,1
0,0,0,0,0,0,0,0,0,0,1
0,0,0,0,0,0,0,0,0,0,1
0,0,0,0,0,0,0,0,0,0,1
0,0,0,0,0,0,0,0,0,0,1
0,0,0,0,0,0,0,0,0,0,0
1,0,0,0,0,0,0,0,0,0,0
1,0,0,0,0,0,0,0,0,0,0
1,0,0,0,0,0,0,0,0,0,0
1,0,0,0,0,0,0,0,0,0,0
1,0,0,0,0,0,1,1,1,1,1
endlayer

layer
1,1,1,1,1,0,0,0,0,0,1
0,0,0,0,0,0,0,0,0,0,1
0,0,0,0,0,0,0,0,0,0,1
0,0,0,0,0,0,0,0,0,0,1
0,0,0,0,0,0,0,0,0,0,1
0,0,0,0,0,0,0,0,0,0,0
1,0,0,0,0,0,0,0,0,0,0
1,0,0,0,0,0,0,0,0,0,0
1,0,0,0,0,0,0,0,0,0,0
1,0,0,0,0,0,0,0,0,0,0
1,0,0,0,0,0,1,1,1,1,1
endlayer

layer
1,0,2,1,1,7,4,0,0,0,1
0,6,6,6,0,0,0,0,0,3,0
0,0,0,0,0,0,0,0,0,3,2
0,0,0,0,0,0,0,0,0,3,1
4,0,0,0,0,0,0,0,0,0,1
5,0,0,0,0,0,0,0,0,0,6
1,0,0,0,0,0,0,0,0,0,4
1,7,0,0,0,0,0,0,0,0,0
2,7,0,0,0,0,0,0,0,0,0
0,7,0,0,0,0,0,5,5,5,0
1,0,0,0,4,3,1,1,2,0,1
endlayer

layer
1,0,0,0,2,1,1,1,1,1,1
1,1,1,1,1,1,1,1,1,1,0
1,1,1,1,1,1,1,1,1,1,0
1,1,1,1,1,1,1,1,1,1,0
1,1,1,1,9,9,8,1,1,1,2
1,1,1,1,11,0,8,1,1,1,1
2,1,1,1,11,12,12,1,1,1,1
0,1,1,1,1,1,1,1,1,1,1
0,1,1,1,1,1,1,1,1,1,1
0,1,1,1,1,1,1,1,1,1,1
1,1,1,1,1,1,2,0,0,0,1
endlayer

layer
1,0,0,0,0,0,2,1,1,1,1
1,1,0,0,0,0,0,0,0,1,0
1,0,0,0,0,0,0,0,0,0,0
1,0,0,0,0,0,0,0,0,0,0
2,0,0,0,0,0,0,0,0,0,0
0,0,0,0,0,0,0,0,0,0,0
0,0,0,0,0,0,0,0,0,0,2
0,0,0,0,0,0,0,0,0,0,1
0,0,0,0,0,0,0,0,0,0,1
0,1,0,0,0,0,0,0,0,1,1
1,1,1,1,2,0,0,0,0,0,1
endlayer

layer
1,0,0,0,0,0,0,0,2,1,1
1,1,0,0,0,0,0,0,0,1,0
2,0,0,0,0,0,0,0,0,0,0
0,0,0,0,0,0,0,0,0,0,0
0,0,0,0,0,0,0,0,0,0,0
0,0,0,0,0,0,0,0,0,0,0
0,0,0,0,0,0,0,0,0,0,0
0,0,0,0,0,0,0,0,0,0,0
0,0,0,0,0,0,0,0,0,0,2
0,1,0,0,0,0,0,0,0,1,1
1,1,2,0,0,0,0,0,0,0,1
endlayer

layer
1,0,0,0,0,0,0,0,0,0,1
0,1,0,0,0,0,0,0,0,1,0
0,0,0,0,0,0,0,0,0,0,0
0,0,0,0,0,0,0,0,0,0,0
0,0,0,0,0,0,0,0,0,0,0
0,0,0,0,0,0,0,0,0,0,0
0,0,0,0,0,0,0,0,0,0,0
0,0,0,0,0,0,0,0,0,0,0
0,0,0,0,0,0,0,0,0,0,0
0,1,0,0,0,0,0,0,0,1,0
1,0,0,0,0,0,0,0,0,0,1
endlayer

layer
1,0,0,0,0,0,0,0,0,0,1
0,1,0,0,0,0,0,0,0,1,0
0,0,0,0,0,0,0,0,0,0,0
0,0,0,0,0,0,0,0,0,0,0
0,0,0,0,0,0,0,0,0,0,0
0,0,0,0,0,0,0,0,0,0,0
0,0,0,0,0,0,0,0,0,0,0
0,0,0,0,0,0,0,0,0,0,0
0,0,0,0,0,0,0,0,0,0,0
0,1,0,0,0,0,0,0,0,1,0
1,0,0,0,0,0,0,0,0,0,1
endlayer

layer
1,7,0,0,0,0,0,0,0,0,1
0,1,0,0,0,0,0,0,0,1,6
0,0,0,0,0,0,0,0,0,0,0
0,0,0,0,0,0,0,0,0,0,0
0,0,0,0,0,0,0,0,0,0,0
0,0,0,0,0,0,0,0,0,0,0
0,0,0,0,0,0,0,0,0,0,0
0,0,0,0,0,0,0,0,0,0,0
0,0,0,0,0,0,0,0,0,0,0
5,1,0,0,0,0,0,0,0,1,0
1,0,0,0,0,0,0,0,0,3,1
endlayer

layer
1,0,1,1,1,1,1,1,1,1,1
1,1,4,0,0,0,0,0,4,1,0
1,4,0,0,0,0,0,0,0,4,1
1,0,0,0,0,0,0,0,0,0,1
1,0,0,0,0,0,0,0,0,0,1
1,0,0,0,0,0,0,0,0,0,1
1,0,0,0,0,0,0,0,0,0,1
1,0,0,0,0,0,0,0,0,0,1
1,4,0,0,0,0,0,0,0,4,1
0,1,4,0,0,0,0,0,4,1,1
1,1,1,1,1,1,1,1,1,0,1
endlayer

layer
1,0,1,1,1,1,1,1,1,1,1
1,0,8,1,7,6,3,1,11,0,0
1,12,1,4,0,0,0,4,1,12,1
1,1,4,0,0,0,0,0,4,1,1
1,6,0,0,0,0,0,0,0,6,1
1,7,0,0,0,0,0,0,0,3,1
1,5,0,0,0,0,0,0,0,5,1
1,1,4,0,0,0,0,0,4,1,1
1,9,1,4,0,0,0,4,1,9,1
0,0,8,1,7,5,3,1,11,0,1
1,1,1,1,1,1,1,1,1,0,1
endlayer

layer
1,0,1,1,1,1,1,1,1,1,1
1,0,0,0,0,0,0,0,0,0,0
1,0,0,1,1,1,1,1,0,0,1
1,0,1,1,4,4,4,1,1,0,1
1,0,1,4,0,0,0,4,1,0,1
1,0,1,4,0,0,0,4,1,0,1
1,0,1,4,0,0,0,4,1,0,1
1,0,1,1,4,4,4,1,1,0,1
1,0,0,1,1,1,1,1,0,0,1
0,0,0,0,0,0,0,0,0,0,1
1,1,1,1,1,1,1,1,1,0,1
endlayer

layer
1,1,1,1,1,1,1,1,1,1,1
1,0,0,0,0,0,0,0,0,0,1
1,0,0,0,0,0,0,0,0,0,1
1,0,0,0,1,1,1,0,0,0,1
1,0,0,1,6,6,6,1,0,0,1
1,0,0,1,7,0,3,1,0,0,1
1,0,0,1,5,5,5,1,0,0,1
1,0,0,0,1,1,1,0,0,0,1
1,0,0,0,0,0,0,0,0,0,1
1,0,0,0,0,0,0,0,0,0,1
1,1,1,1,1,1,1,1,1,1,1
endlayer

