
# Created by Ruins mod version 16.7 Ingame Parser
# authoring Player: lafuller

weight=1
embed_into_distance=4
acceptable_target_blocks=
unacceptable_target_blocks=flowing_water,water,flowing_lava,lava,ice,bedrock,netherrack,nether_brick,nether_brick_fence,soul_sand,quartz_ore,gravel,end_stone,obsidian,iron_bars,cloud,flesh,ash_block,slime_grass,slime_congealed,slime_dirt
dimensions=30,4,4
allowable_overhang=0
max_leveling=4
leveling_buffer=-4
preserve_water=0
preserve_lava=0

rule1=0,100,stonebrick-0,stonebrick-1,stonebrick-2,stone-5,stone-6,cobblestone
rule2=0,100,minecraft:stone_brick_stairs-0
rule3=0,100,minecraft:stone_brick_stairs-2
rule4=0,100,minecraft:stone_brick_stairs-3
rule5=0,100,minecraft:stone_brick_stairs-1
rule6=0,100,minecraft:stone_brick_stairs-4
rule7=0,100,minecraft:stone_brick_stairs-5
rule8=0,100,minecraft:stone_brick_stairs-6
rule9=0,100,minecraft:stone_brick_stairs-7
rule10=0,100,preserveBlock

layer
10,1,1,10
1,1,1,1
1,1,1,1
10,1,1,10
endlayer

layer
10,1,1,10
1,1,1,1
1,1,1,1
10,1,1,10
endlayer

layer
10,1,1,10
1,1,1,1
1,1,1,1
10,1,1,10
endlayer

layer
10,1,1,10
1,1,1,1
1,1,1,1
10,1,1,10
endlayer

layer
10,2,2,10
4,1,1,3
4,1,1,3
10,5,5,10
endlayer

layer
10,10,10,10
10,6,2,10
10,5,7,10
10,10,10,10
endlayer

layer
10,10,10,10
10,4,8,10
10,9,3,10
10,10,10,10
endlayer

layer
10,10,10,10
10,6,2,10
10,5,7,10
10,10,10,10
endlayer

layer
0,0,0,0
0,4,8,0
0,9,3,0
0,0,0,0
endlayer

layer
0,0,0,0
0,6,2,0
0,5,7,0
0,0,0,0
endlayer

layer
0,0,0,0
0,4,8,0
0,9,3,0
0,0,0,0
endlayer

layer
0,0,0,0
0,6,2,0
0,5,7,0
0,0,0,0
endlayer

layer
0,0,0,0
0,4,8,0
0,9,3,0
0,0,0,0
endlayer

layer
0,0,0,0
0,6,2,0
0,5,7,0
0,0,0,0
endlayer

layer
0,0,0,0
0,4,8,0
0,9,3,0
0,0,0,0
endlayer

layer
0,0,0,0
0,6,2,0
0,5,7,0
0,0,0,0
endlayer

layer
0,0,0,0
0,4,8,0
0,9,3,0
0,0,0,0
endlayer

layer
0,0,0,0
0,6,2,0
0,5,7,0
0,0,0,0
endlayer

layer
0,0,0,0
0,4,8,0
0,9,3,0
0,0,0,0
endlayer

layer
0,0,0,0
0,6,2,0
0,5,7,0
0,0,0,0
endlayer

layer
0,0,0,0
0,4,8,0
0,9,3,0
0,0,0,0
endlayer

layer
0,0,0,0
0,6,2,0
0,5,7,0
0,0,0,0
endlayer

layer
0,0,0,0
0,4,8,0
0,9,3,0
0,0,0,0
endlayer

layer
0,0,0,0
0,6,2,0
0,5,7,0
0,0,0,0
endlayer

layer
0,0,0,0
0,4,8,0
0,9,3,0
0,0,0,0
endlayer

layer
0,0,0,0
0,6,2,0
0,5,7,0
0,0,0,0
endlayer

layer
0,0,0,0
0,1,1,0
0,1,1,0
0,0,0,0
endlayer

layer
0,0,6,0
0,1,1,8
9,1,1,7
0,0,7,0
endlayer

layer
0,6,1,0
9,1,1,1
1,1,1,1
0,7,1,0
endlayer

layer
0,0,0,0
0,1,1,0
0,1,1,0
0,0,0,0
endlayer

