
# Created by Ruins mod version 16.7 Ingame Parser
# authoring Player: lafuller

weight=1
embed_into_distance=13
acceptable_target_blocks=flowing_water,water
unacceptable_target_blocks=
biomesToSpawnIn=river,swampland,lush swamp,marsh
dimensions=17,14,14
allowable_overhang=0
max_leveling=5
leveling_buffer=-1
preserve_water=0
preserve_lava=0

rule1=0,100,preserveBlock
rule2=0,100,minecraft:log2-1
rule3=0,100,minecraft:log2-5
rule4=0,100,minecraft:log2-9
rule5=0,100,minecraft:spruce_fence-0
rule6=0,100,minecraft:log-4
rule7=0,100,minecraft:planks-1
rule8=0,100,minecraft:ladder-5
rule9=0,100,minecraft:fence-0
rule10=0,100,minecraft:log-8
rule11=0,100,minecraft:wooden_slab-9
rule12=0,100,minecraft:log-0
rule13=0,100,minecraft:spruce_stairs-1
rule14=0,100,minecraft:spruce_fence_gate-3
rule15=0,100,minecraft:spruce_fence_gate-1
rule16=0,100,minecraft:spruce_fence_gate-0
rule17=0,100,minecraft:spruce_fence_gate-2

layer
1,1,1,1,1,1,1,1,1,1,1,1,1,1
1,1,1,1,1,1,1,1,1,1,1,1,1,1
1,1,1,1,1,1,1,2,1,1,1,1,1,1
1,1,1,1,1,1,1,1,1,1,1,1,1,1
1,1,1,2,1,2,1,1,1,1,2,1,1,1
1,1,1,1,1,1,1,1,1,1,1,1,1,1
1,1,1,1,1,1,1,1,1,1,1,1,1,1
1,1,1,1,1,1,1,1,1,1,1,1,1,1
1,1,1,1,1,1,1,1,1,1,1,1,1,1
1,1,1,1,1,2,1,1,1,1,2,1,1,1
1,1,1,1,1,1,1,1,1,1,1,1,1,1
1,1,1,2,1,1,1,2,1,1,1,1,1,1
1,1,1,1,1,1,1,1,1,1,1,1,1,1
1,1,1,1,1,1,1,1,1,1,1,1,1,1
endlayer

layer
1,1,1,1,1,1,1,1,1,1,1,1,1,1
1,1,1,1,1,1,1,1,1,1,1,1,1,1
1,1,1,1,1,1,1,2,1,1,1,1,1,1
1,1,1,1,1,1,1,1,1,1,1,1,1,1
1,1,1,2,1,2,1,1,1,1,2,1,1,1
1,1,1,1,1,1,1,1,1,1,1,1,1,1
1,1,1,1,1,1,1,1,1,1,1,1,1,1
1,1,1,1,1,1,1,1,1,1,1,1,1,1
1,1,1,1,1,1,1,1,1,1,1,1,1,1
1,1,1,1,1,2,1,1,1,1,2,1,1,1
1,1,1,1,1,1,1,1,1,1,1,1,1,1
1,1,1,2,1,1,1,2,1,1,1,1,1,1
1,1,1,1,1,1,1,1,1,1,1,1,1,1
1,1,1,1,1,1,1,1,1,1,1,1,1,1
endlayer

layer
1,1,1,1,1,1,1,1,1,1,1,1,1,1
1,1,1,1,1,1,1,1,1,1,1,1,1,1
1,1,1,1,1,1,1,2,1,1,1,1,1,1
1,1,1,1,1,1,1,1,1,1,1,1,1,1
1,1,1,2,1,2,1,1,1,1,2,1,1,1
1,1,1,1,1,1,1,1,1,1,1,1,1,1
1,1,1,1,1,1,1,1,1,1,1,1,1,1
1,1,1,1,1,1,1,1,1,1,1,1,1,1
1,1,1,1,1,1,1,1,1,1,1,1,1,1
1,1,1,1,1,2,1,1,1,1,2,1,1,1
1,1,1,1,1,1,1,1,1,1,1,1,1,1
1,1,1,2,1,1,1,2,1,1,1,1,1,1
1,1,1,1,1,1,1,1,1,1,1,1,1,1
1,1,1,1,1,1,1,1,1,1,1,1,1,1
endlayer

layer
1,1,1,1,1,1,1,1,1,1,1,1,1,1
1,1,1,1,1,1,1,1,1,1,1,1,1,1
1,1,1,1,1,1,1,2,1,1,1,1,1,1
1,1,1,1,1,1,1,1,1,1,1,1,1,1
1,1,1,2,1,2,1,1,1,1,2,1,1,1
1,1,1,1,1,1,1,1,1,1,1,1,1,1
1,1,1,1,1,1,1,1,1,1,1,1,1,1
1,1,1,1,1,1,1,1,1,1,1,1,1,1
1,1,1,1,1,1,1,1,1,1,1,1,1,1
1,1,1,1,1,2,1,1,1,1,2,1,1,1
1,1,1,1,1,1,1,1,1,1,1,1,1,1
1,1,1,2,1,1,1,2,1,1,1,1,1,1
1,1,1,1,1,1,1,1,1,1,1,1,1,1
1,1,1,1,1,1,1,1,1,1,1,1,1,1
endlayer

layer
1,1,1,1,1,1,1,1,1,1,1,1,1,1
1,1,1,1,1,1,1,1,1,1,1,1,1,1
1,1,1,1,1,1,1,2,1,1,1,1,1,1
1,1,1,1,1,1,1,1,1,1,1,1,1,1
1,1,1,2,1,2,1,1,1,1,2,1,1,1
1,1,1,1,1,1,1,1,1,1,1,1,1,1
1,1,1,1,1,1,1,1,1,1,1,1,1,1
1,1,1,1,1,1,1,1,1,1,1,1,1,1
1,1,1,1,1,1,1,1,1,1,1,1,1,1
1,1,1,1,1,2,1,1,1,1,2,1,1,1
1,1,1,1,1,1,1,1,1,1,1,1,1,1
1,1,1,2,1,1,1,2,1,1,1,1,1,1
1,1,1,1,1,1,1,1,1,1,1,1,1,1
1,1,1,1,1,1,1,1,1,1,1,1,1,1
endlayer

layer
1,1,1,1,1,1,1,1,1,1,1,1,1,1
1,1,1,1,1,1,1,1,1,1,1,1,1,1
1,1,1,1,1,1,1,2,1,1,1,1,1,1
1,1,1,1,1,1,1,1,1,1,1,1,1,1
1,1,1,2,1,2,1,1,1,1,2,1,1,1
1,1,1,1,1,1,1,1,1,1,1,1,1,1
1,1,1,1,1,1,1,1,1,1,1,1,1,1
1,1,1,1,1,1,1,1,1,1,1,1,1,1
1,1,1,1,1,1,1,1,1,1,1,1,1,1
1,1,1,1,1,2,1,1,1,1,2,1,1,1
1,1,1,1,1,1,1,1,1,1,1,1,1,1
1,1,1,2,1,1,1,2,1,1,1,1,1,1
1,1,1,1,1,1,1,1,1,1,1,1,1,1
1,1,1,1,1,1,1,1,1,1,1,1,1,1
endlayer

layer
1,1,1,1,1,1,1,1,1,1,1,1,1,1
1,1,1,1,1,1,1,1,1,1,1,1,1,1
1,1,1,1,1,1,1,2,1,1,1,1,1,1
1,1,1,1,1,1,1,1,1,1,1,1,1,1
1,1,1,2,1,2,1,1,1,1,2,1,1,1
1,1,1,1,1,1,1,1,1,1,1,1,1,1
1,1,1,1,1,1,1,1,1,1,1,1,1,1
1,1,1,1,1,1,1,1,1,1,1,1,1,1
1,1,1,1,1,1,1,1,1,1,1,1,1,1
1,1,1,1,1,2,1,1,1,1,2,1,1,1
1,1,1,1,1,1,1,1,1,1,1,1,1,1
1,1,1,2,1,1,1,2,1,1,1,1,1,1
1,1,1,1,1,1,1,1,1,1,1,1,1,1
1,1,1,1,1,1,1,1,1,1,1,1,1,1
endlayer

layer
1,1,1,1,1,1,1,1,1,1,1,1,1,1
1,1,1,1,1,1,1,1,1,1,1,1,1,1
1,1,1,1,1,1,1,2,1,1,1,1,1,1
1,1,1,1,1,1,1,1,1,1,1,1,1,1
1,1,1,2,1,2,1,1,1,1,2,1,1,1
1,1,1,1,1,1,1,1,1,1,1,1,1,1
1,1,1,1,1,1,1,1,1,1,1,1,1,1
1,1,1,1,1,1,1,1,1,1,1,1,1,1
1,1,1,1,1,1,1,1,1,1,1,1,1,1
1,1,1,1,1,2,1,1,1,1,2,1,1,1
1,1,1,1,1,1,1,1,1,1,1,1,1,1
1,1,1,2,1,1,1,2,1,1,1,1,1,1
1,1,1,1,1,1,1,1,1,1,1,1,1,1
1,1,1,1,1,1,1,1,1,1,1,1,1,1
endlayer

layer
1,1,1,1,1,1,1,1,1,1,1,1,1,1
1,1,1,1,1,1,1,1,1,1,1,1,1,1
1,1,1,1,1,1,1,2,1,1,1,1,1,1
1,1,1,1,1,1,1,1,1,1,1,1,1,1
1,1,1,2,1,2,1,1,1,1,2,1,1,1
1,1,1,1,1,1,1,1,1,1,1,1,1,1
1,1,1,1,1,1,1,1,1,1,1,1,1,1
1,1,1,1,1,1,1,1,1,1,1,1,1,1
1,1,1,1,1,1,1,1,1,1,1,1,1,1
1,1,1,1,1,2,1,1,1,1,2,1,1,1
1,1,1,1,1,1,1,1,1,1,1,1,1,1
1,1,1,2,1,1,1,2,1,1,1,1,1,1
1,1,1,1,1,1,1,1,1,1,1,1,1,1
1,1,1,1,1,1,1,1,1,1,1,1,1,1
endlayer

layer
1,1,1,1,1,1,1,1,1,1,1,1,1,1
1,1,1,1,1,1,1,1,1,1,1,1,1,1
1,1,1,1,1,1,1,2,1,1,1,1,1,1
1,1,1,1,1,1,1,1,1,1,1,1,1,1
1,1,1,2,1,2,1,1,1,1,2,1,1,1
1,1,1,1,1,1,1,1,1,1,1,1,1,1
1,1,1,1,1,1,1,1,1,1,1,1,1,1
1,1,1,1,1,1,1,1,1,1,1,1,1,1
1,1,1,1,1,1,1,1,1,1,1,1,1,1
1,1,1,1,1,2,1,1,1,1,2,1,1,1
1,1,1,1,1,1,1,1,1,1,1,1,1,1
1,1,1,2,1,1,1,2,1,1,1,1,1,1
1,1,1,1,1,1,1,1,1,1,1,1,1,1
1,1,1,1,1,1,1,1,1,1,1,1,1,1
endlayer

layer
1,1,1,1,1,1,1,1,1,1,1,1,1,1
1,1,1,1,1,1,1,1,1,1,1,1,1,1
1,1,1,1,1,1,1,2,1,1,1,1,1,1
1,1,1,1,1,1,1,1,1,1,1,1,1,1
1,1,1,2,1,2,1,1,1,1,2,1,1,1
1,1,1,1,1,1,1,1,1,1,1,1,1,1
1,1,1,1,1,1,1,1,1,1,1,1,1,1
1,1,1,1,1,1,1,1,1,1,1,1,1,1
1,1,1,1,1,1,1,1,1,1,1,1,1,1
1,1,1,1,1,2,1,1,1,1,2,1,1,1
1,1,1,1,1,1,1,1,1,1,1,1,1,1
1,1,1,2,1,1,1,2,1,1,1,1,1,1
1,1,1,1,1,1,1,1,1,1,1,1,1,1
1,1,1,1,1,1,1,1,1,1,1,1,1,1
endlayer

layer
1,1,1,1,1,1,1,1,1,1,1,1,1,1
1,1,1,1,1,1,1,1,1,1,1,1,1,1
1,1,1,1,1,1,3,2,1,3,1,1,1,1
1,1,1,1,3,1,3,1,1,3,1,1,1,1
1,1,1,2,3,2,3,1,1,3,2,1,1,1
1,1,1,1,3,1,3,1,1,3,1,1,1,1
1,1,1,1,3,1,3,1,1,3,1,1,1,1
1,1,1,1,3,1,3,1,1,3,1,1,1,1
1,1,1,1,3,1,3,1,1,3,1,1,1,1
1,1,1,1,3,2,3,1,1,3,2,1,1,1
1,1,1,1,3,1,3,1,1,3,1,1,1,1
1,1,1,2,3,1,3,2,1,3,1,1,1,1
1,1,1,1,1,1,1,1,1,1,1,1,1,1
1,1,1,1,1,1,1,1,1,1,1,1,1,1
endlayer

layer
1,1,1,1,1,1,1,1,1,1,1,1,1,1
1,1,1,1,1,1,1,1,1,1,1,1,1,1
1,1,1,1,1,1,1,2,1,1,1,1,1,1
1,1,4,4,4,4,4,4,4,4,4,4,1,1
1,1,1,2,1,2,1,1,1,1,2,1,1,1
1,1,4,4,4,4,4,4,4,4,4,4,1,1
1,1,1,1,1,1,1,1,1,1,1,1,1,1
1,1,1,1,1,1,1,1,1,1,1,1,1,1
1,1,1,1,1,1,1,1,1,1,1,1,1,1
1,1,1,1,1,2,1,1,1,1,2,1,1,1
1,1,4,4,4,4,4,4,4,4,4,4,1,1
1,1,1,2,1,1,1,2,1,1,1,1,1,1
1,1,1,1,1,1,1,1,1,1,1,1,1,1
1,1,1,1,1,1,1,1,1,1,1,1,1,1
endlayer

layer
1,1,1,1,1,5,1,1,5,1,1,1,1,1
1,1,1,5,1,6,1,1,6,1,5,1,1,1
1,1,1,6,1,6,1,2,6,1,6,1,1,1
1,1,1,6,1,6,1,1,6,1,6,1,1,1
1,1,1,6,1,6,7,7,6,1,6,1,1,1
1,1,1,6,1,1,1,8,8,1,6,1,1,1
1,1,1,1,1,1,1,1,1,1,1,1,1,1
1,1,1,1,1,1,1,1,1,1,1,1,1,1
1,1,1,1,1,1,1,1,1,1,1,1,1,1
1,1,1,6,1,6,1,1,6,1,6,1,1,1
1,1,1,6,1,6,1,1,6,1,6,1,1,1
1,1,1,6,1,6,1,2,6,1,6,1,1,1
1,1,1,5,1,6,1,1,6,1,5,1,1,1
1,1,1,1,1,5,1,1,5,1,1,1,1,1
endlayer

layer
1,1,1,1,1,1,1,1,1,1,1,1,1,1
1,1,1,9,1,1,1,1,1,1,9,1,1,1
5,10,10,10,10,10,10,10,10,10,10,10,10,5
1,1,1,1,1,1,1,1,1,1,1,1,1,1
5,10,10,10,10,10,10,10,10,10,10,10,10,5
1,1,1,8,8,8,8,8,8,8,8,1,1,1
1,1,1,1,1,1,1,1,1,1,1,1,1,1
1,1,1,1,1,1,1,1,1,1,1,1,1,1
1,1,1,1,1,1,1,1,1,1,1,1,1,1
5,10,10,10,10,10,10,10,10,10,10,10,10,5
1,1,1,1,1,1,1,1,1,1,1,1,1,1
5,10,10,10,10,10,10,10,10,10,10,10,10,5
1,1,1,9,1,1,1,1,1,1,9,1,1,1
1,1,1,1,1,1,1,1,1,1,1,1,1,1
endlayer

layer
1,1,5,1,5,1,5,1,1,5,1,5,1,1
1,1,6,11,6,11,6,11,11,6,11,6,1,1
9,12,6,11,6,11,6,11,11,6,11,6,12,9
1,11,6,11,6,11,6,11,11,6,11,6,11,1
9,12,6,11,6,11,6,13,13,6,11,6,12,9
1,11,6,11,6,11,6,1,1,6,11,6,11,1
1,11,6,11,6,11,6,1,1,6,11,6,11,1
1,11,6,11,6,11,6,11,11,6,11,6,11,1
1,11,6,11,6,11,6,11,11,6,11,6,11,1
9,12,6,11,6,11,6,11,11,6,11,6,12,9
1,11,6,11,6,11,6,11,11,6,11,6,11,1
9,12,6,11,6,11,6,11,11,6,7,6,12,9
1,1,6,11,6,11,6,11,11,6,11,6,1,1
1,1,5,1,5,1,5,1,1,5,1,5,1,1
endlayer

layer
1,1,1,1,1,1,1,1,1,1,1,1,1,1
1,1,5,15,15,5,14,14,5,14,14,5,1,1
1,5,5,1,1,1,1,1,1,1,1,5,5,1
1,17,1,1,1,1,1,1,1,1,1,1,16,1
1,17,1,1,1,1,1,1,1,1,1,1,16,1
1,5,1,1,1,1,1,1,1,1,1,1,5,1
1,17,1,1,1,1,5,1,1,5,1,1,16,1
1,17,1,1,1,1,5,15,15,5,1,1,16,1
1,5,1,1,1,1,1,1,1,1,1,1,5,1
1,17,1,1,1,1,1,1,1,1,1,1,16,1
1,17,1,1,1,1,1,1,1,1,1,1,16,1
1,5,5,1,1,1,1,1,1,1,1,5,5,1
1,1,5,15,15,5,15,15,5,15,15,5,1,1
1,1,1,1,1,1,1,1,1,1,1,1,1,1
endlayer

