# Gilly's Adobe Well #2

# template generated with Ruins mod version 16.5 Ingame Parser
# Structure created and developed by Gilly

weight=1
embed_into_distance=19
acceptable_target_blocks=
unacceptable_target_blocks=flowing_water,water,flowing_lava,lava,ice,bedrock,netherrack,nether_brick,nether_brick_fence,soul_sand,quartz_ore,end_stone,obsidian,iron_bars,cloud,flesh,ash_block,slime_grass,slime_congealed,slime_dirt
dimensions=24,8,8
allowable_overhang=0
max_leveling=7
leveling_buffer=-1
preserve_water=0
preserve_lava=0

rule1=0,100,minecraft:double_stone_slab-9
rule2=0,100,minecraft:water-0
rule3=0,100,minecraft:stone_slab-1
rule4=0,100,minecraft:sandstone_stairs-0
rule5=0,100,minecraft:sandstone-2
rule6=0,100,minecraft:sandstone-1
rule7=0,100,minecraft:stone_slab-9
rule8=0,100,minecraft:sandstone_stairs-5
rule9=0,100,minecraft:sandstone_stairs-2
rule10=0,100,minecraft:sandstone_stairs-7
rule11=0,100,minecraft:sandstone_stairs-1
rule12=0,100,minecraft:sandstone-0
rule13=0,100,minecraft:sandstone_stairs-3
rule14=0,100,preserveBlock
rule15=0,100,minecraft:sandstone_stairs-4
rule16=0,100,minecraft:wooden_slab-1
rule17=0,100,minecraft:spruce_stairs-0
rule18=0,100,minecraft:spruce_stairs-1
rule19=0,100,minecraft:spruce_stairs-3
rule20=0,100,minecraft:spruce_stairs-2
rule21=0,100,minecraft:trapdoor-3
rule22=0,100,minecraft:trapdoor-2

layer
1,1,1,1,1,1,1,1
1,1,1,1,1,1,1,1
1,1,1,1,1,1,1,1
1,1,1,1,1,1,1,1
1,1,1,1,1,1,1,1
1,1,1,1,1,1,1,1
1,1,1,1,1,1,1,1
1,1,1,1,1,1,1,1
endlayer

layer
1,1,1,1,1,1,1,1
1,1,1,1,1,1,1,1
1,1,1,1,1,1,1,1
1,1,1,2,2,1,1,1
1,1,1,2,2,1,1,1
1,1,1,1,1,1,1,1
1,1,1,1,1,1,1,1
1,1,1,1,1,1,1,1
endlayer

layer
1,1,1,1,1,1,1,1
1,1,1,1,1,1,1,1
1,1,1,1,1,1,1,1
1,1,1,2,2,1,1,1
1,1,1,2,2,1,1,1
1,1,1,1,1,1,1,1
1,1,1,1,1,1,1,1
1,1,1,1,1,1,1,1
endlayer

layer
1,1,1,1,1,1,1,1
1,1,1,1,1,1,1,1
1,1,1,1,1,1,1,1
1,1,1,2,2,1,1,1
1,1,1,2,2,1,1,1
1,1,1,1,1,1,1,1
1,1,1,1,1,1,1,1
1,1,1,1,1,1,1,1
endlayer

layer
1,1,1,1,1,1,1,1
1,1,1,1,1,1,1,1
1,1,1,1,1,1,1,1
1,1,1,2,2,1,1,1
1,1,1,2,2,1,1,1
1,1,1,1,1,1,1,1
1,1,1,1,1,1,1,1
1,1,1,1,1,1,1,1
endlayer

layer
1,1,1,1,1,1,1,1
1,1,1,3,3,3,3,1
1,1,1,3,3,3,4,1
1,1,1,0,0,5,1,1
1,1,1,0,0,1,1,1
1,1,1,1,1,1,1,1
1,1,1,1,1,1,1,1
1,1,1,1,1,1,1,1
endlayer

layer
1,1,1,1,1,1,1,1
1,1,1,0,0,0,0,1
1,1,1,0,0,0,0,1
1,1,1,0,0,6,4,1
1,1,1,0,0,1,1,1
1,1,1,1,1,1,1,1
1,1,1,1,1,1,1,1
1,1,1,1,1,1,1,1
endlayer

layer
1,1,1,1,1,1,1,1
1,1,1,0,0,0,0,1
1,1,1,0,0,0,0,1
1,1,1,0,0,6,0,1
1,1,1,0,0,1,4,1
1,1,1,1,1,1,1,1
1,1,1,1,1,1,1,1
1,1,1,1,1,1,1,1
endlayer

layer
1,1,1,1,1,1,1,1
1,1,1,7,7,7,7,1
1,1,1,7,7,7,0,1
1,1,1,0,0,5,0,1
1,1,1,0,0,1,0,1
1,1,1,1,1,1,4,1
1,1,1,1,1,1,1,1
1,1,1,1,1,1,1,1
endlayer

layer
1,1,1,1,1,1,1,1
1,1,1,1,1,1,1,1
1,1,1,1,1,1,8,1
1,1,1,0,0,1,0,1
1,1,1,0,0,5,0,1
1,1,5,3,3,3,0,1
1,1,1,9,3,3,3,1
1,1,1,1,1,1,1,1
endlayer

layer
1,1,1,1,1,1,1,1
1,1,1,1,1,1,1,1
1,1,1,1,1,1,1,1
1,1,1,0,0,1,8,1
1,1,1,0,0,6,0,1
1,1,6,0,0,0,0,1
1,1,9,0,0,0,0,1
1,1,1,1,1,1,1,1
endlayer

layer
1,1,1,1,1,1,1,1
1,1,1,1,1,1,1,1
1,1,1,1,1,1,1,1
1,1,1,0,0,1,1,1
1,1,1,0,0,6,8,1
1,1,6,0,0,0,0,1
1,9,0,0,0,0,0,1
1,1,1,1,1,1,1,1
endlayer

layer
1,1,1,1,1,1,1,1
1,1,1,1,1,1,1,1
1,1,1,1,1,1,1,1
1,1,1,0,0,1,1,1
1,1,1,0,0,5,1,1
1,11,5,7,7,10,1,1
1,0,0,0,7,10,1,1
1,1,1,1,1,1,1,1
endlayer

layer
1,1,1,1,1,1,1,1
1,1,1,1,1,1,1,1
1,1,1,1,1,1,1,1
1,1,1,0,0,1,1,1
1,11,1,0,0,1,1,1
1,0,1,1,1,1,1,1
1,0,0,10,1,1,1,1
1,1,1,1,1,1,1,1
endlayer

layer
1,1,1,1,1,1,1,1
1,1,1,1,1,1,1,1
1,1,1,1,1,1,1,1
12,11,1,0,0,1,1,1
12,0,1,0,0,1,1,1
1,0,1,1,1,1,1,1
1,0,10,1,1,1,1,1
1,1,1,1,1,1,1,1
endlayer

layer
1,1,9,14,14,13,1,1
1,1,1,1,1,1,1,1
11,1,1,1,1,1,1,11
14,0,1,0,0,1,1,14
14,0,1,0,0,1,1,14
4,0,1,1,1,1,1,4
1,15,1,1,1,1,1,1
1,1,9,14,14,13,1,1
endlayer

layer
6,9,14,14,14,14,13,6
11,1,1,1,1,1,1,11
14,1,1,1,1,1,1,14
14,0,1,0,0,1,1,14
14,0,1,0,0,1,1,14
14,15,1,1,1,1,1,14
4,12,1,1,1,1,1,4
6,9,14,14,14,14,13,6
endlayer

layer
14,14,14,14,14,14,14,14
14,4,6,12,12,12,4,14
14,6,1,1,1,1,12,14
14,10,1,0,0,1,1,14
14,10,1,0,0,1,12,14
14,6,1,1,1,1,12,14
14,11,12,12,12,12,11,14
14,14,14,14,14,14,14,14
endlayer

layer
14,14,14,14,14,14,14,14
14,14,13,12,12,9,14,14
14,4,5,11,11,5,4,14
14,12,9,0,0,13,12,14
14,12,9,0,0,13,12,14
14,11,5,4,4,5,11,14
14,14,13,12,12,9,14,14
14,14,14,14,14,14,14,14
endlayer

layer
14,14,14,14,14,14,14,14
14,14,14,4,4,14,14,14
14,14,6,11,11,6,14,14
14,13,9,0,0,13,9,14
14,13,9,0,0,13,9,14
14,14,6,4,4,6,14,14
14,14,14,11,11,14,14,14
14,14,14,14,14,14,14,14
endlayer

layer
14,14,14,14,14,14,14,14
14,14,14,14,14,14,14,14
14,14,5,0,0,5,14,14
14,14,0,0,0,0,14,14
14,14,0,0,0,0,14,14
14,14,5,0,0,5,14,14
14,14,14,14,14,14,14,14
14,14,14,14,14,14,14,14
endlayer

layer
14,14,14,14,14,14,14,14
14,14,14,14,14,14,14,14
14,14,5,0,0,5,14,14
14,14,0,0,0,0,14,14
14,14,0,0,0,0,14,14
14,14,5,0,0,5,14,14
14,14,14,14,14,14,14,14
14,14,14,14,14,14,14,14
endlayer

layer
14,14,14,14,14,14,14,14
14,14,14,14,14,14,14,14
14,14,6,0,0,6,14,14
14,14,0,0,0,0,14,14
14,14,0,0,0,0,14,14
14,14,6,0,0,6,14,14
14,14,14,14,14,14,14,14
14,14,14,14,14,14,14,14
endlayer

layer
14,14,14,14,14,14,14,14
14,16,17,17,16,16,16,14
14,19,17,17,18,18,16,14
14,16,17,21,21,18,20,14
14,19,17,22,22,18,16,14
14,16,17,17,18,18,20,14
14,16,16,16,18,18,16,14
14,14,14,14,14,14,14,14
endlayer

