
# Created by Ruins mod version 16.7 Ingame Parser
# authoring Player: lafuller

weight=1
embed_into_distance=4
acceptable_target_blocks=
unacceptable_target_blocks=flowing_water,water,flowing_lava,lava,ice,bedrock,netherrack,nether_brick,nether_brick_fence,soul_sand,quartz_ore,end_stone,obsidian,iron_bars,cloud,flesh,ash_block,slime_grass,slime_congealed,slime_dirt
biomesToSpawnIn=plains,forest,prarie,meadow,tundra,brushland,shrubland,woodland,woodlands,birch_forestlavender_fields,flower_field,sunflower_plains,ice_flats,ice_plains
dimensions=13,10,12
allowable_overhang=0
max_leveling=4
leveling_buffer=-1
preserve_water=0
preserve_lava=0

rule1=0,100,preserveBlock
rule2=0,100,stonebrick-0,stonebrick-0,stonebrick-0,stonebrick-0,stonebrick-1,stonebrick-2,stonebrick-2,stone-5,stone-6,cobblestone
rule3=0,100,minecraft:stone-6
rule4=0,100,minecraft:dirt-0
rule5=0,100,minecraft:stone_brick_stairs-0
rule6=0,100,air
rule7=0,100,minecraft:stone_brick_stairs-2
rule8=0,100,stonebrick-0,stonebrick-0,stonebrick-0,stonebrick-0,stonebrick-1,stonebrick-2,stonebrick-2,stone-5,stone-6,cobblestone,gravel
rule9=0,100,minecraft:stone-5
rule10=0,100,minecraft:stone_brick_stairs-7
rule11=0,100,minecraft:stone_brick_stairs-6
rule12=0,100,minecraft:stone_brick_stairs-3
rule13=0,100,minecraft:planks-0
rule14=0,100,minecraft:planks-1
rule15=0,100,minecraft:oak_stairs-0
rule16=0,100,minecraft:stone_brick_stairs-4
rule17=0,100,minecraft:log-0
rule18=0,100,minecraft:stone_brick_stairs-5
rule19=0,100,minecraft:cauldron-0
rule20=0,100,minecraft:oak_stairs-3
rule21=0,100,minecraft:oak_stairs-2
rule22=0,100,bookshelf,hay_block,ChestGenHook:chests/spawn_bonus_chest:5-3,ChestGenHook:chests/village_blacksmith:5-3,ChestGenHook:chests/simple_dungeon:5-3,ChestGenHook:chests/abandoned_mineshaft:5-3,ChestGenHook:chests/stronghold_library:5-3,ChestGenHook:chests/stronghold_corridor:5-3,ChestGenHook:chests/stronghold_crossing:5-2,ChestGenHook:chests/igloo_chest:5-3
rule23=0,100,minecraft:fence-0
rule24=0,100,minecraft:oak_stairs-1
rule25=0,100,minecraft:jungle_door-2
rule26=0,100,IInventory;minecraft:furnace;minecraft:coal#2#0#1-5
rule27=0,100,minecraft:oak_stairs-5
rule28=0,100,minecraft:jungle_door-9
rule29=0,100,minecraft:dark_oak_stairs-2
rule30=0,100,minecraft:spruce_stairs-4
rule31=0,100,minecraft:dark_oak_stairs-7
rule32=0,100,minecraft:wooden_slab-13
rule33=0,100,minecraft:dark_oak_stairs-4
rule34=0,100,minecraft:dark_oak_stairs-0
rule35=0,100,minecraft:cobblestone_wall-0
rule36=0,100,minecraft:spruce_stairs-7
rule37=0,100,minecraft:spruce_stairs-6
rule38=0,100,minecraft:dark_oak_stairs-1
rule39=0,100,minecraft:spruce_stairs-5
rule40=0,100,minecraft:spruce_fence_gate-1
rule41=0,100,minecraft:wooden_slab-5
rule42=0,100,minecraft:planks-5
rule43=0,100,minecraft:dark_oak_stairs-3
rule44=0,100,minecraft:stone_stairs-5
rule45=0,100,minecraft:dark_oak_stairs-6
rule46=0,100,minecraft:stone_stairs-2
rule47=0,100,minecraft:dark_oak_fence-0

layer
1,1,1,1,1,1,1,1,1,1,1,1
1,1,1,2,2,2,1,1,1,1,1,1
1,1,3,4,4,4,3,2,2,1,1,1
1,2,4,4,4,4,4,2,2,3,1,1
1,2,4,4,4,4,4,4,4,4,2,1
1,2,4,4,4,4,4,4,4,4,2,1
5,2,4,4,4,4,4,4,4,4,2,1
2,3,4,4,4,4,4,4,4,3,2,1
2,2,2,2,2,3,2,2,2,1,1,1
3,1,3,1,3,1,3,2,7,1,1,6
endlayer

layer
1,1,1,1,1,1,1,1,1,1,1,1
1,1,1,8,8,8,1,1,1,1,1,1
1,1,9,4,4,4,9,8,8,1,1,1
1,8,4,4,4,4,4,8,8,9,1,1
1,8,4,4,4,4,4,4,4,4,8,1
1,8,4,4,4,4,4,4,4,4,8,1
1,8,4,4,4,4,4,4,4,4,8,1
5,9,4,4,4,4,4,4,4,9,8,1
8,8,8,8,8,9,8,8,8,1,1,1
8,1,8,1,8,1,8,7,1,1,1,1
endlayer

layer
1,1,1,1,1,1,1,1,1,1,1,1
1,1,1,8,8,8,1,1,1,1,1,1
1,1,3,4,4,4,3,8,8,1,1,1
1,8,4,4,4,4,4,8,8,3,1,1
1,8,4,4,4,4,4,4,4,4,8,1
1,8,4,4,4,4,4,4,4,4,8,1
1,8,4,4,4,4,4,4,4,4,8,1
1,3,4,4,4,4,4,4,4,3,8,1
5,8,8,8,8,3,8,8,8,1,1,1
12,11,8,1,8,10,7,1,1,1,1,1
endlayer

layer
1,1,1,1,1,1,1,1,1,1,1,1
1,1,1,8,8,8,1,1,1,1,1,1
1,1,9,4,4,4,9,8,8,1,1,1
1,8,4,4,4,4,4,8,8,9,1,1
1,8,4,4,4,4,4,4,4,4,8,1
1,8,4,4,4,4,4,4,4,4,8,1
1,8,4,4,4,4,4,4,4,4,8,1
1,9,4,4,4,4,4,4,4,9,8,1
1,8,8,8,8,9,8,8,8,1,1,1
1,12,8,8,8,7,1,1,1,1,1,1
endlayer

layer
1,1,1,1,1,1,1,1,1,1,1,1
1,1,1,2,2,2,1,1,1,1,1,1
1,1,3,13,13,13,3,8,8,1,1,1
1,2,13,14,14,14,13,8,8,3,1,1
1,2,13,14,13,13,14,14,13,13,2,1
1,2,13,13,14,14,13,13,14,13,2,1
1,2,13,14,14,13,14,14,14,13,2,1
1,3,13,13,13,13,13,13,13,3,2,1
1,2,2,8,2,3,2,2,2,1,1,1
1,1,12,8,7,1,1,1,1,1,1,1
endlayer

layer
1,1,1,1,1,1,1,1,1,1,1,1
1,1,1,15,15,15,1,1,1,1,1,1
1,1,17,6,6,6,17,5,16,1,1,1
1,20,6,6,6,6,6,19,18,17,1,1
1,20,6,6,6,6,6,6,6,6,21,1
1,20,6,6,6,6,6,6,6,6,21,1
1,20,6,6,6,6,6,6,6,22,21,1
1,17,6,6,6,6,6,6,6,17,21,1
1,1,24,25,24,17,24,24,24,23,1,1
1,1,1,6,1,1,1,1,1,1,1,1
endlayer

layer
1,1,1,1,1,1,1,1,1,1,1,1
1,1,1,23,6,23,1,1,1,1,1,1
1,1,17,6,6,6,17,7,5,1,1,1
1,23,6,6,6,6,6,26,8,17,23,1
1,6,6,6,6,6,6,6,6,6,23,1
1,23,6,6,6,6,6,6,6,6,6,1
1,23,6,6,6,6,6,6,6,6,23,1
1,17,6,6,6,6,6,6,6,17,23,1
1,1,27,28,27,17,23,6,23,23,1,1
1,1,1,6,1,1,1,1,1,1,1,1
endlayer

layer
1,1,1,1,1,1,1,1,1,1,1,1
1,32,31,30,30,30,29,1,1,1,1,1
1,33,17,6,6,6,17,5,16,32,1,1
1,36,6,6,6,6,6,35,7,17,34,1
1,36,6,6,6,6,6,6,6,6,37,1
1,36,6,6,6,6,6,6,6,6,37,1
1,36,6,6,6,6,6,6,6,6,37,1
1,17,6,6,6,6,6,6,6,17,37,1
1,31,39,40,39,17,39,39,39,29,38,1
1,1,1,6,1,32,1,1,1,1,1,1
endlayer

layer
1,1,41,32,32,32,41,1,1,1,1,1
1,1,41,42,42,42,34,1,1,1,1,1
41,43,17,39,39,39,17,7,5,29,1,1
32,42,37,6,6,6,6,35,44,17,41,41
32,42,37,6,6,6,6,6,6,36,42,32
32,42,37,6,6,6,6,6,6,36,42,32
32,42,37,6,6,6,6,6,6,36,42,32
41,17,37,30,30,30,30,30,30,17,42,41
1,41,42,42,42,17,42,42,42,41,1,1
1,41,32,32,31,41,45,32,32,41,1,1
endlayer

layer
1,1,1,1,1,1,1,1,1,1,1,1
1,1,1,34,34,34,1,1,1,1,1,1
1,1,34,42,42,42,34,1,1,1,1,1
1,34,42,14,14,14,42,2,46,34,1,1
1,43,42,14,14,14,14,14,42,42,41,1
1,43,42,14,14,14,14,14,14,42,29,1
1,43,42,14,14,14,14,14,14,42,29,1
1,38,42,42,42,42,42,42,42,29,1,1
1,1,43,38,29,41,43,38,41,1,1,1
1,1,1,1,1,1,1,1,1,1,1,1
endlayer

layer
1,1,1,1,1,1,1,1,1,1,1,1
1,1,1,1,1,1,1,1,1,1,1,1
1,1,1,47,47,47,1,1,1,1,1,1
1,1,47,41,41,41,47,35,1,1,1,1
1,1,47,41,41,41,41,41,47,47,1,1
1,1,47,41,41,41,41,41,41,47,1,1
1,1,47,41,41,41,41,41,41,47,1,1
1,1,47,47,47,47,47,47,47,1,1,1
1,1,1,1,1,1,1,1,1,1,1,1
1,1,1,1,1,1,1,1,1,1,1,1
endlayer

layer
1,1,1,1,1,1,1,1,1,1,1,1
1,1,1,1,1,1,1,1,1,1,1,1
1,1,1,1,1,1,1,1,1,1,1,1
1,1,1,1,1,1,1,35,1,1,1,1
1,1,1,1,1,1,1,1,1,1,1,1
1,1,1,1,1,1,1,1,1,1,1,1
1,1,1,1,1,1,1,1,1,1,1,1
1,1,1,1,1,1,1,1,1,1,1,1
1,1,1,1,1,1,1,1,1,1,1,1
1,1,1,1,1,1,1,1,1,1,1,1
endlayer

layer
1,1,1,1,1,1,1,1,1,1,1,1
1,1,1,1,1,1,1,1,1,1,1,1
1,1,1,1,1,1,1,1,1,1,1,1
1,1,1,1,1,1,1,35,1,1,1,1
1,1,1,1,1,1,1,1,1,1,1,1
1,1,1,1,1,1,1,1,1,1,1,1
1,1,1,1,1,1,1,1,1,1,1,1
1,1,1,1,1,1,1,1,1,1,1,1
1,1,1,1,1,1,1,1,1,1,1,1
1,1,1,1,1,1,1,1,1,1,1,1
endlayer

