
# Created by Ruins mod version 16.5 Ingame Parser
# authoring Player: lafuller

weight=1
embed_into_distance=16
acceptable_target_blocks=
unacceptable_target_blocks=flowing_water,water,flowing_lava,lava,ice,bedrock,netherrack,nether_brick,nether_brick_fence,soul_sand,quartz_ore,end_stone,obsidian,iron_bars,cloud,flesh,ash_block,slime_grass,slime_congealed,slime_dirt
dimensions=21,9,9
allowable_overhang=0
max_leveling=3
leveling_buffer=-1
preserve_water=0
preserve_lava=0

rule1=0,100,minecraft:double_stone_slab-9
rule2=0,100,minecraft:sandstone-1
rule3=0,100,minecraft:water-0
rule4=0,100,minecraft:sandstone_stairs-0
rule5=0,100,air,ChestGenHook:chests/desert_pyramid:5-3
rule6=0,100,minecraft:sandstone_stairs-5
rule7=0,100,minecraft:sandstone_stairs-1
rule8=0,100,minecraft:stone_slab-1
rule9=0,100,minecraft:sandstone-2
rule10=0,100,preserveBlock
rule11=0,100,minecraft:sandstone_stairs-2
rule12=0,100,minecraft:sandstone-0
rule13=0,100,minecraft:sandstone_stairs-3
rule14=0,100,minecraft:sandstone_stairs-7
rule15=0,100,minecraft:sandstone_stairs-6
rule16=0,100,minecraft:sandstone_stairs-4
rule17=0,100,minecraft:fence-0
rule18=0,100,minecraft:wooden_slab-9
rule19=0,100,minecraft:spruce_stairs-6
rule20=0,100,minecraft:spruce_stairs-2
rule21=0,100,minecraft:wooden_slab-1
rule22=0,100,minecraft:spruce_stairs-3
rule23=0,100,minecraft:spruce_stairs-0
rule24=0,100,minecraft:planks-1
rule25=0,100,minecraft:spruce_stairs-4
rule26=0,100,minecraft:spruce_stairs-7
rule27=0,100,minecraft:spruce_stairs-1
rule28=0,100,minecraft:spruce_stairs-5

layer
1,1,1,1,1,1,1,1,1
1,1,1,1,1,1,1,1,1
1,1,1,1,1,1,1,1,1
1,1,1,1,1,1,1,1,1
1,1,1,1,2,2,1,1,1
1,1,1,1,2,2,1,1,1
1,1,1,1,1,1,1,1,1
1,1,1,1,1,1,1,1,1
1,1,1,1,1,1,1,1,1
endlayer

layer
1,1,1,1,1,1,1,1,1
1,1,3,3,3,3,3,1,1
1,1,3,3,3,3,3,1,1
1,1,3,1,3,1,3,1,1
1,1,3,3,3,3,3,1,1
1,1,4,1,3,3,1,1,1
1,1,1,1,1,1,1,1,1
1,1,1,1,1,1,1,1,1
1,1,1,1,1,1,1,1,1
endlayer

layer
1,1,1,1,1,1,1,1,1
1,1,3,3,3,3,3,1,1
1,1,3,3,3,3,3,1,1
1,1,3,1,3,1,3,1,1
1,1,3,3,3,3,3,1,1
1,1,3,1,3,3,1,1,1
1,1,4,1,1,1,1,1,1
1,1,1,1,1,1,1,1,1
1,1,1,1,1,1,1,1,1
endlayer

layer
1,1,1,1,1,1,1,1,1
1,1,0,0,0,0,0,1,1
1,1,0,0,0,0,0,1,1
1,1,0,1,2,1,2,1,1
1,1,0,2,3,3,2,1,1
1,1,0,1,3,3,1,1,1
1,1,0,1,1,1,1,1,1
1,1,0,0,0,5,1,1,1
1,1,1,1,1,1,1,1,1
endlayer

layer
1,1,1,1,1,1,1,1,1
1,1,1,1,1,1,1,1,1
1,1,1,1,1,1,1,1,1
1,1,1,1,1,1,1,1,1
1,1,6,1,3,3,1,1,1
1,1,0,1,3,3,1,1,1
1,1,0,1,1,1,1,1,1
1,1,0,0,0,0,1,1,1
1,1,1,1,1,1,1,1,1
endlayer

layer
1,1,1,1,1,1,1,1,1
1,1,1,1,1,1,1,1,1
1,1,1,1,1,1,1,1,1
1,1,1,1,1,1,1,1,1
1,1,1,1,3,3,1,1,1
1,1,6,1,3,3,1,1,1
1,1,0,1,1,1,1,1,1
1,1,0,0,0,0,1,1,1
1,1,1,1,1,1,1,1,1
endlayer

layer
1,1,1,1,1,1,1,1,1
1,1,1,1,1,1,1,1,1
1,1,1,1,1,1,1,1,1
1,1,1,1,1,1,1,1,1
1,1,1,1,3,3,1,1,1
1,1,1,1,3,3,1,1,1
1,1,1,1,1,1,1,1,1
1,1,1,1,1,1,1,1,1
1,1,1,1,1,1,1,1,1
endlayer

layer
1,1,1,1,1,1,1,1,1
1,1,1,1,1,1,1,1,1
1,1,1,1,1,1,1,1,1
1,1,1,1,1,1,1,1,1
1,1,1,1,3,3,1,1,1
1,1,1,1,3,3,1,1,1
1,1,1,1,1,1,1,1,1
1,1,1,1,1,1,1,1,1
1,1,1,1,1,1,1,1,1
endlayer

layer
1,1,1,1,1,1,1,1,1
1,1,1,1,1,1,1,1,1
1,1,1,1,1,1,1,1,1
1,1,1,1,1,1,1,1,1
1,1,1,1,0,0,1,1,1
1,1,1,7,0,0,1,1,1
1,1,1,8,8,8,1,1,1
1,9,9,8,8,8,9,1,1
1,1,1,1,1,1,1,1,1
endlayer

layer
9,12,12,12,12,11,10,10,10
12,12,9,12,12,12,12,9,10
12,12,12,12,12,12,12,12,4
12,12,12,12,1,1,12,12,12
12,12,12,7,0,0,1,12,12
7,12,12,0,0,0,1,12,12
10,12,12,0,0,0,1,12,12
10,9,9,0,0,0,9,12,12
10,13,12,12,12,12,12,12,9
endlayer

layer
9,12,12,12,11,10,10,10,10
12,12,9,12,12,12,12,9,10
12,12,9,1,1,1,12,12,10
12,12,8,8,13,1,12,12,4
7,12,8,0,0,0,1,12,12
10,12,8,0,0,0,1,12,12
10,12,8,0,0,0,1,12,12
10,9,9,0,0,0,9,12,12
10,10,13,12,12,12,12,12,9
endlayer

layer
9,12,12,11,10,10,10,10,10
12,12,9,12,12,12,12,9,10
12,12,9,1,1,1,12,12,10
7,12,0,0,0,13,12,12,10
10,12,0,0,0,0,9,12,4
10,12,0,0,0,0,9,12,12
10,12,0,0,0,0,9,12,12
10,9,9,15,0,14,9,12,12
10,10,10,13,12,12,12,12,9
endlayer

layer
10,10,10,10,10,10,10,10,10
10,4,9,12,12,12,12,9,10
10,12,9,8,8,8,8,12,10
10,12,0,0,0,0,8,12,10
10,12,0,0,0,0,4,12,10
10,12,0,0,0,0,12,12,4
10,12,0,0,0,0,12,12,12
10,9,2,2,2,2,12,12,12
10,10,10,10,13,12,12,12,9
endlayer

layer
10,10,10,10,10,10,10,10,10
10,10,9,12,11,13,12,9,10
10,4,9,0,0,0,0,12,10
10,12,6,0,0,0,0,12,10
10,12,0,0,0,0,0,12,10
10,12,0,0,0,0,4,12,10
10,12,16,0,0,0,12,12,4
10,9,12,11,13,9,12,12,12
10,10,10,10,10,13,12,12,9
endlayer

layer
10,10,10,10,10,10,10,10,10
10,10,9,12,11,13,12,9,10
10,10,2,0,0,0,0,12,10
10,4,2,0,0,0,0,12,10
10,12,2,0,0,0,0,12,10
10,12,2,0,0,0,0,7,10
10,12,2,0,0,0,10,10,10
10,9,12,11,13,9,10,10,10
10,10,10,10,10,10,10,10,10
endlayer

layer
10,10,10,10,10,10,10,10,10
10,10,2,9,9,9,9,2,10
10,10,12,15,0,17,14,12,10
10,10,12,0,0,17,0,12,10
10,4,12,0,0,17,0,7,10
10,12,12,0,0,17,0,10,10
10,12,12,0,0,17,0,10,10
10,2,12,11,13,2,10,10,10
10,10,10,10,10,10,10,10,10
endlayer

layer
10,10,10,10,10,10,10,10,10
10,10,9,16,14,15,16,9,10
10,10,12,2,2,2,2,15,10
10,10,14,19,18,19,18,7,10
10,10,16,19,0,19,0,10,10
10,4,12,19,0,19,0,10,10
10,12,12,19,18,19,0,10,10
10,9,9,9,9,9,0,10,10
10,10,10,10,10,10,10,10,10
endlayer

layer
10,10,10,10,10,10,10,10,10
10,10,10,0,0,10,10,10,10
10,10,12,0,0,12,10,10,10
10,0,0,0,0,0,0,10,10
10,0,0,0,0,0,0,10,10
10,0,0,0,0,0,0,10,10
10,0,0,0,0,0,0,10,10
10,10,12,0,0,12,0,10,10
10,10,10,0,0,10,10,10,10
endlayer

layer
10,10,10,10,10,10,10,10,10
10,10,0,0,0,0,10,10,10
10,0,12,0,0,12,0,10,10
10,0,0,0,0,0,0,10,10
10,0,0,0,0,0,0,10,10
10,0,0,0,0,0,0,10,10
10,0,0,0,0,0,0,10,10
10,0,12,0,0,12,0,10,10
10,10,0,0,0,0,10,10,10
endlayer

layer
10,10,10,10,10,10,10,10,10
10,0,0,0,0,0,0,10,10
10,0,12,0,0,12,0,10,10
10,0,0,0,0,0,0,10,10
10,0,0,0,0,0,0,10,10
10,0,0,0,0,0,0,10,10
10,0,0,0,0,0,0,10,10
10,0,12,0,0,12,0,10,10
10,0,0,0,0,0,0,10,10
endlayer

layer
10,10,10,10,10,10,10,10,10
10,0,22,21,21,20,0,10,10
10,23,24,25,25,24,23,10,10
10,21,26,18,18,19,21,10,10
10,27,26,18,18,19,27,10,10
10,23,26,18,18,19,23,10,10
10,21,26,18,18,19,21,10,10
10,27,24,28,28,24,27,10,10
10,0,22,21,21,20,0,10,10
endlayer

