# Gilly's Fort of Defense

# template generated by Ruins mod version 14.6 Ingame Parser
# Structure created by Gilly

weight=1
embed_into_distance=4
acceptable_target_blocks=
unacceptable_target_blocks=flowing_water,water,flowing_lava,lava,ice,bedrock,netherrack,nether_brick,nether_brick_fence,soul_sand,quartz_ore,end_stone,obsidian,iron_bars,cloud,flesh,ash_block,slime_grass,slime_congealed,slime_dirt
dimensions=10,13,13
allowable_overhang=0
max_leveling=4
leveling_buffer=-1
preserve_water=0
preserve_lava=0

rule1=0,100,stone_brick_stairs-4,stone_brick_stairs-0,stone_brick_stairs-2,stone_brick_stairs-6,stonebrick,stonebrick,stonebrick,stonebrick,stonebrick,stonebrick-2
rule2=0,100,stone_brick_stairs-0,stone_brick_stairs-4,stonebrick,stonebrick,stonebrick,stonebrick,stonebrick,stonebrick-2
rule3=0,100,stone_brick_stairs-7,stone_brick_stairs-3,stone_brick_stairs-0,stone_brick_stairs-4,stonebrick,stonebrick,stonebrick,stonebrick,stonebrick,stonebrick-2
rule4=0,100,preserveBlock
rule5=0,100,stone_brick_stairs-2,stone_brick_stairs-6,stonebrick,stonebrick,stonebrick,stonebrick,stonebrick,stonebrick-2
rule6=0,100,stonebrick-0
rule7=0,100,stone_brick_stairs-3,stone_brick_stairs-7,stonebrick,stonebrick,stonebrick,stonebrick,stonebrick,stonebrick-2
rule8=0,100,stone_brick_stairs-6,stone_brick_stairs-2,stone_brick_stairs-1,stone_brick_stairs-5,stonebrick,stonebrick,stonebrick,stonebrick,stonebrick,stonebrick-2
rule9=0,100,dirt
rule10=0,100,stone_brick_stairs-5,stone_brick_stairs-1,stone_brick_stairs-3,stone_brick_stairs-7,stonebrick,stonebrick,stonebrick,stonebrick,stonebrick,stonebrick-2
rule11=0,100,stone_brick_stairs-1,stone_brick_stairs-5,stonebrick,stonebrick,stonebrick,stonebrick,stonebrick,stonebrick-2
rule12=0,90,planks-0,planks-0,planks-0,planks-0,planks-0,oak_stairs-0,planks-0,oak_stairs-1,oak_stairs-4,oak_stairs-5
rule13=0,100,oak_stairs-1
rule14=0,100,oak_stairs-3
rule15=0,100,oak_stairs-7
rule16=0,100,oak_stairs-2
rule17=0,100,oak_stairs-0
rule18=0,100,oak_stairs-6
rule19=0,100,oak_stairs-4
rule20=0,100,fence
rule21=0,100,wooden_slab-1

layer
3,2,2,1,4,3,2,2,2,2,2,2,1
7,6,6,8,4,7,6,6,6,6,6,6,5
7,6,8,4,4,7,6,9,9,9,9,6,5
10,8,4,4,3,6,9,9,9,9,9,6,5
4,4,4,3,6,9,9,9,9,9,9,6,5
3,2,2,6,9,9,9,9,9,9,9,6,5
7,6,6,9,9,9,9,9,9,9,9,6,5
7,6,9,9,9,9,9,9,9,9,9,6,5
7,6,9,9,9,9,9,9,9,9,9,6,5
7,6,9,9,9,9,9,9,9,9,9,6,5
7,6,9,9,9,9,9,9,9,9,9,6,5
7,6,6,6,6,6,6,6,6,6,6,6,5
10,11,11,11,11,11,11,11,11,11,11,11,8
endlayer

layer
3,2,2,1,4,3,2,2,2,2,2,2,1
7,6,6,8,4,7,6,6,6,6,6,6,5
7,6,8,4,4,7,6,0,0,12,12,6,5
10,8,4,4,3,6,0,0,0,12,12,6,5
4,4,4,3,6,0,0,0,12,12,12,6,5
3,2,2,6,0,0,0,0,14,13,13,6,5
7,6,6,0,0,0,0,0,0,0,0,7,5
7,5,0,0,0,0,0,0,0,0,0,7,5
7,5,0,0,0,0,0,0,0,0,0,7,5
7,5,0,0,0,0,0,0,0,0,0,7,5
7,5,0,0,0,0,0,0,0,0,0,7,5
7,6,2,2,2,2,2,2,2,2,2,6,5
10,11,11,11,11,11,11,11,11,11,11,11,8
endlayer

layer
3,2,2,1,4,3,2,2,2,2,2,1,4
7,6,6,8,4,7,6,6,6,6,6,6,1
7,6,8,4,4,7,6,0,15,12,12,6,5
10,8,4,4,3,6,0,0,15,12,12,6,5
4,4,4,3,6,0,0,0,12,13,13,6,5
3,2,2,6,0,0,0,0,0,0,0,7,5
7,6,6,0,0,0,0,0,0,0,0,7,5
7,5,0,0,0,0,0,0,0,0,0,7,5
7,5,0,0,0,0,0,0,0,0,0,7,5
7,5,0,0,0,0,0,0,0,0,0,7,5
7,5,0,0,0,0,0,0,0,0,0,7,5
10,6,2,2,2,2,2,2,2,2,2,6,8
4,10,11,11,11,11,11,11,11,11,11,8,4
endlayer

layer
4,3,2,1,4,4,4,4,4,4,4,4,4
3,6,6,8,4,3,2,2,2,2,2,1,4
7,6,8,4,4,7,6,12,16,0,0,5,4
10,8,4,4,3,6,0,0,16,0,0,5,4
4,4,4,3,6,0,0,0,12,0,0,1,4
4,3,2,6,0,0,0,0,0,0,0,5,4
4,7,6,0,0,0,0,0,0,0,0,5,4
4,7,0,0,0,0,0,0,0,0,0,5,4
4,7,0,0,0,0,0,0,0,0,0,8,4
4,10,0,0,0,0,0,0,0,0,0,5,4
4,3,0,0,0,0,0,0,0,0,0,5,4
4,10,11,11,11,11,10,11,11,8,11,8,4
4,4,4,4,4,4,4,4,4,4,4,4,4
endlayer

layer
4,4,4,4,0,0,0,0,0,0,0,0,0
4,4,3,6,0,3,2,2,2,2,2,1,0
4,3,6,0,0,7,6,16,0,0,0,5,0
4,6,0,0,3,6,12,16,0,0,0,5,0
0,0,0,3,6,12,12,17,17,0,0,5,0
0,3,2,6,12,12,12,12,18,0,0,5,0
0,7,6,12,12,12,12,12,18,19,19,5,0
0,7,12,12,12,12,12,12,12,12,12,5,0
0,7,12,12,12,12,12,12,12,12,12,5,0
0,7,12,12,12,12,12,12,12,12,12,5,0
0,7,12,12,12,12,12,12,12,12,12,5,0
0,10,11,11,11,11,11,11,11,11,11,8,0
0,0,0,0,0,0,0,0,0,0,0,0,0
endlayer

layer
4,4,0,0,0,0,0,0,0,0,0,0,0
4,0,0,0,0,3,2,2,2,2,2,1,0
0,0,0,0,0,7,6,0,0,0,0,5,0
0,0,0,0,3,6,0,0,0,0,0,5,0
0,0,0,3,6,0,0,0,0,0,0,5,0
0,3,2,6,0,0,0,0,0,0,0,5,0
0,7,6,0,0,0,0,0,0,0,0,5,0
0,7,0,0,0,0,0,0,0,0,0,5,0
0,7,0,0,0,0,0,0,0,0,0,5,0
0,7,0,0,0,0,0,0,0,0,0,5,0
0,7,0,0,0,0,0,0,0,0,0,5,0
0,10,6,6,6,6,6,6,6,6,6,8,0
0,0,0,0,0,0,0,0,0,0,0,0,0
endlayer

layer
0,0,0,0,0,0,0,0,0,0,0,0,0
0,0,0,0,0,20,6,20,20,20,20,20,0
0,0,0,0,0,20,0,0,0,0,0,20,0
0,0,0,0,20,0,0,0,0,0,0,20,0
0,0,0,20,0,0,0,0,0,0,0,20,0
0,20,20,0,0,0,0,0,0,0,0,20,0
0,6,0,0,0,0,0,0,0,0,0,20,0
0,20,0,0,0,0,0,0,0,0,0,20,0
0,20,0,0,0,0,0,0,0,0,0,20,0
0,20,0,0,0,0,0,0,0,0,0,20,0
0,20,0,0,0,0,0,0,0,0,0,20,0
0,20,20,20,20,20,20,20,20,20,20,20,0
0,0,0,0,0,0,0,0,0,0,0,0,0
endlayer

layer
0,0,0,0,0,0,0,0,0,0,0,0,0
0,0,0,0,0,20,6,20,20,20,20,20,0
0,0,0,0,0,20,0,0,0,0,0,20,0
0,0,0,0,20,0,0,0,0,0,0,20,0
0,0,0,20,0,0,0,0,0,0,0,20,0
0,20,20,0,0,0,0,0,0,0,0,20,0
0,6,0,0,0,0,0,0,0,0,0,20,0
0,20,0,0,0,0,0,0,0,0,0,20,0
0,20,0,0,0,0,0,0,0,0,0,20,0
0,20,0,0,0,0,0,0,0,0,0,20,0
0,20,0,0,0,0,0,0,0,0,0,20,0
0,20,20,20,20,20,20,20,20,20,20,20,0
0,0,0,0,0,0,0,0,0,0,0,0,0
endlayer

layer
0,0,0,0,0,0,0,0,0,0,0,0,0
0,0,0,0,0,20,6,20,20,20,20,21,0
0,0,0,0,0,20,0,0,0,0,0,21,0
0,0,0,0,20,0,0,0,0,0,0,21,0
0,0,0,20,0,0,0,0,0,0,0,21,0
0,20,20,0,0,0,0,0,0,0,0,21,0
0,6,0,0,0,0,0,0,0,0,0,21,0
0,20,0,0,0,0,0,0,0,0,0,21,0
0,20,0,0,0,0,0,0,0,0,0,21,0
0,20,0,0,0,0,0,0,0,0,0,21,0
0,20,0,0,0,0,0,0,0,0,0,21,0
0,21,21,21,21,21,21,21,21,21,21,21,0
0,0,0,0,0,0,0,0,0,0,0,0,0
endlayer

layer
0,0,0,0,0,0,21,21,0,0,0,0,0
0,0,0,0,0,21,21,21,21,21,21,0,0
0,0,0,0,0,21,21,0,0,0,0,0,0
0,0,0,0,21,21,0,0,0,0,0,0,0
0,0,0,21,21,0,0,0,0,0,0,0,0
0,21,21,21,0,0,0,0,0,0,0,0,0
21,21,21,0,0,0,0,0,0,0,0,0,0
21,21,0,0,0,0,0,0,0,0,0,0,0
0,21,0,0,0,0,0,0,0,0,0,0,0
0,21,0,0,0,0,0,0,0,0,0,0,0
0,21,0,0,0,0,0,0,0,0,0,0,0
0,0,0,0,0,0,0,0,0,0,0,0,0
0,0,0,0,0,0,0,0,0,0,0,0,0
endlayer

