
# Created by Ruins mod version 16.7 Ingame Parser
# authoring Player: lafuller

weight=1
embed_into_distance=4
acceptable_target_blocks=
unacceptable_target_blocks=flowing_water,water,flowing_lava,lava,ice,bedrock,netherrack,nether_brick,nether_brick_fence,soul_sand,quartz_ore,gravel,end_stone,obsidian,iron_bars,cloud,flesh,ash_block,slime_grass,slime_congealed,slime_dirt
dimensions=17,11,11
allowable_overhang=0
max_leveling=4
leveling_buffer=-1
preserve_water=0
preserve_lava=0

rule1=0,100,preserveBlock
rule2=0,100,minecraft:dirt-1
rule3=0,100,minecraft:dirt-0
rule4=0,100,minecraft:dirt-2
rule5=0,100,minecraft:spruce_stairs-0
rule6=0,100,minecraft:log-1
rule7=0,100,minecraft:tallgrass-1,air,air,air
rule8=0,100,minecraft:spruce_stairs-2
rule9=0,100,minecraft:spruce_stairs-3
rule10=0,100,minecraft:spruce_fence_gate-1
rule11=0,100,minecraft:dark_oak_fence-0
rule12=0,100,minecraft:spruce_stairs-4
rule13=0,100,minecraft:spruce_stairs-6
rule14=0,100,minecraft:spruce_stairs-7
rule15=0,100,minecraft:planks-1
rule16=0,100,minecraft:log-5
rule17=0,100,minecraft:wooden_slab-9
rule18=0,100,minecraft:log-9
rule19=0,100,minecraft:spruce_stairs-5
rule20=0,100,minecraft:spruce_fence-0
rule21=0,100,minecraft:wooden_slab-1

layer
1,1,1,1,1,1,1,1,1,1,1
1,1,1,2,2,2,2,2,1,1,1
1,1,2,3,3,3,3,3,2,1,1
1,2,3,3,3,3,3,3,3,2,1
1,2,3,3,3,3,3,3,3,2,1
1,2,3,3,3,3,3,3,3,2,1
1,2,3,3,3,3,3,3,3,2,1
1,2,3,3,3,3,3,3,3,2,1
1,1,2,3,3,3,3,3,2,1,1
1,1,1,2,2,2,2,2,1,1,1
1,1,1,1,2,2,2,1,1,1,1
endlayer

layer
1,1,1,1,1,1,1,1,1,1,1
1,1,1,1,2,2,2,1,1,1,1
1,1,2,2,3,3,3,2,2,1,1
1,1,2,3,3,3,3,3,2,1,1
1,2,3,3,3,3,3,3,3,2,1
1,2,3,3,3,3,3,3,3,2,1
1,2,3,3,3,3,3,3,3,2,1
1,1,2,3,3,3,3,3,2,1,1
1,1,1,2,3,3,3,2,1,1,1
1,1,1,2,2,2,2,2,1,1,1
1,1,1,1,1,2,1,1,1,1,1
endlayer

layer
1,1,1,1,1,1,1,1,1,1,1
1,1,1,1,2,2,1,1,1,1,1
1,1,1,2,3,3,2,2,1,1,1
1,1,2,3,3,3,3,3,2,1,1
1,1,2,3,3,3,3,3,3,2,1
1,2,3,3,3,3,3,3,3,2,1
1,2,3,3,3,3,3,3,2,1,1
1,1,2,3,3,3,3,3,2,1,1
1,1,1,2,3,3,3,2,1,1,1
1,1,1,1,2,2,2,1,1,1,1
1,1,1,1,1,1,1,1,1,1,1
endlayer

layer
1,1,1,1,1,1,1,1,1,1,1
1,1,1,1,1,2,1,1,1,1,1
1,1,1,2,2,3,2,1,1,1,1
1,1,1,2,3,3,3,2,1,1,1
1,1,2,3,3,3,3,3,2,1,1
1,2,3,3,3,3,3,3,2,2,1
1,1,2,3,3,3,3,3,2,1,1
1,1,1,2,3,3,3,2,1,1,1
1,1,1,2,2,3,2,2,1,1,1
1,1,1,1,1,2,1,1,1,1,1
1,1,1,1,1,1,1,1,1,1,1
endlayer

layer
1,1,1,1,1,1,1,1,1,1,1
1,1,1,1,1,1,1,1,1,1,1
1,1,1,1,2,2,2,1,1,1,1
1,1,1,2,4,4,4,2,1,1,1
1,1,2,4,4,2,4,4,2,1,1
1,1,2,4,2,2,2,4,2,1,1
1,1,2,4,4,2,2,4,2,1,1
1,1,1,2,4,2,4,2,1,1,1
1,1,1,1,2,2,2,1,1,1,1
1,1,1,1,1,1,1,1,1,1,1
1,1,1,1,1,1,1,1,1,1,1
endlayer

layer
1,1,1,1,1,1,1,1,1,1,1
1,1,1,1,1,1,1,1,1,1,1
1,1,1,0,5,6,5,0,1,1,1
1,1,0,6,7,7,7,6,0,1,1
1,1,9,7,7,0,7,7,8,1,1
1,1,9,7,0,0,0,7,8,1,1
1,1,6,7,0,0,0,7,6,1,1
1,1,0,9,7,0,7,8,0,1,1
1,1,1,0,6,10,6,0,1,1,1
1,1,1,1,1,1,1,1,1,1,1
1,1,1,1,1,1,1,1,1,1,1
endlayer

layer
1,1,1,1,1,1,1,1,1,1,1
1,1,1,1,1,1,1,1,1,1,1
1,1,1,0,11,6,11,0,1,1,1
1,1,0,6,0,0,0,6,0,1,1
1,1,11,0,0,0,0,0,11,1,1
1,1,11,0,0,0,0,0,11,1,1
1,1,6,0,0,0,0,0,6,1,1
1,1,11,11,0,0,0,11,11,1,1
1,1,1,0,6,0,6,0,1,1,1
1,1,1,1,1,1,1,1,1,1,1
1,1,1,1,1,1,1,1,1,1,1
endlayer

layer
1,1,1,1,1,1,1,1,1,1,1
1,1,1,1,1,1,1,1,1,1,1
1,1,1,0,12,6,12,0,1,1,1
1,1,0,6,0,0,0,6,0,1,1
1,1,14,0,0,0,0,0,13,1,1
1,1,14,0,0,0,0,0,13,1,1
1,1,6,0,0,0,0,0,6,1,1
1,1,0,14,0,0,0,13,11,1,1
1,1,1,0,6,10,6,13,1,1,1
1,1,1,1,1,1,1,1,1,1,1
1,1,1,1,1,1,1,1,1,1,1
endlayer

layer
1,1,1,1,1,1,1,1,1,1,1
1,1,1,1,1,12,1,1,1,1,1
1,1,1,16,15,6,15,13,1,1,1
1,1,12,6,0,0,0,6,17,1,1
1,1,15,13,0,0,0,14,15,1,1
1,14,15,17,0,0,0,0,15,13,1
1,18,6,13,0,0,0,14,6,17,1
1,1,19,15,12,0,12,15,19,1,1
1,1,1,14,6,18,6,18,11,1,1
1,1,1,1,1,1,1,1,1,1,1
1,1,1,1,1,1,1,1,1,1,1
endlayer

layer
1,1,1,1,1,1,1,1,1,1,1
1,1,1,1,1,16,1,1,1,1,1
1,1,14,6,20,6,20,16,13,1,1
1,1,16,6,0,0,0,6,15,12,1
1,12,16,15,0,0,0,15,8,8,1
1,9,16,0,0,0,0,17,20,20,1
1,6,6,15,0,0,0,15,6,18,1
1,19,15,15,15,17,15,15,16,19,1
1,1,17,18,6,0,6,6,17,1,1
1,1,1,1,1,1,1,1,1,1,1
1,1,1,1,1,1,1,1,1,1,1
endlayer

layer
1,1,1,1,1,1,1,1,1,1,1
1,1,1,11,18,6,1,1,1,1,1
1,1,1,6,15,15,15,6,11,21,1
1,1,11,15,19,0,19,15,11,1,1
1,1,6,15,0,0,0,15,16,1,1
1,1,11,17,17,0,17,15,16,1,1
1,6,6,15,12,0,12,15,6,6,1
1,11,16,18,18,18,18,15,0,11,1
1,1,17,6,6,19,6,6,17,1,1
1,1,1,1,11,1,11,1,1,1,1
1,1,1,1,1,1,1,1,1,1,1
endlayer

layer
1,1,1,1,1,1,1,1,1,1,1
1,1,1,11,1,6,18,11,1,1,1
1,1,1,6,11,11,11,6,1,1,1
1,1,1,11,11,17,11,11,11,1,1
1,1,6,11,17,0,17,11,6,1,1
1,1,11,11,11,17,11,11,11,11,1
11,6,11,11,11,21,11,11,11,6,1
1,1,11,11,1,6,11,16,18,11,1
1,1,17,6,11,11,6,6,17,1,1
1,1,1,11,14,19,13,11,1,1,1
1,1,1,1,1,1,1,1,1,1,1
endlayer

layer
1,1,1,1,1,11,1,1,1,1,1
1,1,1,1,1,6,1,11,1,1,1
1,1,11,6,11,11,11,6,1,1,1
1,1,1,1,11,11,11,11,16,1,1
1,18,6,11,11,17,11,11,6,1,1
1,1,11,1,11,11,11,11,1,1,1
11,6,1,11,11,11,11,11,11,6,11
1,1,1,1,11,6,1,11,11,1,1
1,1,1,6,18,18,18,6,1,1,1
1,1,1,14,21,1,21,13,1,1,1
1,1,1,1,1,1,1,1,1,1,1
endlayer

layer
1,1,1,1,1,11,1,1,1,1,1
1,1,1,11,18,6,1,1,1,1,1
1,1,11,6,1,11,1,6,11,1,1
1,1,1,1,11,11,11,1,1,1,1
1,1,6,1,11,11,11,11,6,11,1
1,1,1,1,11,11,11,1,1,1,1
1,6,1,1,1,11,1,1,1,6,11
1,16,1,1,1,6,1,1,1,1,1
1,11,1,6,1,11,11,6,1,1,1
1,1,21,11,1,1,1,1,21,1,1
1,1,1,1,1,1,1,1,1,1,1
endlayer

layer
1,1,1,1,1,1,1,11,1,1,1
1,1,1,11,11,6,1,16,1,1,1
1,1,1,6,1,1,1,6,11,1,1
1,1,1,1,1,1,1,1,1,1,1
1,11,6,1,1,11,11,1,6,11,1
1,1,1,1,1,1,11,1,1,1,1
1,1,1,1,1,11,1,1,1,6,11
1,6,1,1,1,6,1,1,1,1,1
1,11,1,6,11,1,11,6,1,1,1
1,1,1,11,1,1,1,11,1,1,1
1,1,1,1,1,1,1,1,1,1,1
endlayer

layer
1,1,1,1,1,11,1,11,1,1,1
1,1,1,1,11,6,1,6,1,1,1
1,1,1,1,1,1,1,1,1,1,1
1,1,1,1,1,1,1,1,1,1,1
1,11,6,1,1,1,1,1,6,11,1
1,1,1,1,1,1,1,1,1,1,1
1,1,1,1,1,1,1,1,1,1,1
1,1,1,1,1,1,1,1,1,1,1
1,1,1,6,11,1,11,6,11,1,1
1,1,1,1,1,1,1,11,1,1,1
1,1,1,1,1,1,1,1,1,1,1
endlayer

layer
1,1,1,1,1,11,1,1,1,1,1
1,1,1,1,1,6,1,1,1,1,1
1,1,1,1,1,1,1,1,1,1,1
1,1,1,1,1,1,1,1,1,1,1
1,1,1,1,1,1,1,1,1,1,1
1,1,1,1,1,1,1,1,1,1,1
1,1,1,1,1,1,1,1,1,1,1
1,1,1,1,1,1,1,1,1,1,1
1,1,1,1,1,1,1,6,11,1,1
1,1,1,1,1,1,1,11,1,1,1
1,1,1,1,1,1,1,1,1,1,1
endlayer

