
# Created by Ruins mod version 16.7 Ingame Parser
# authoring Player: lafuller

weight=1
embed_into_distance=5
acceptable_target_blocks=
unacceptable_target_blocks=flowing_water,water,flowing_lava,lava,ice,bedrock,netherrack,nether_brick,nether_brick_fence,soul_sand,quartz_ore,end_stone,obsidian,iron_bars,cloud,flesh,ash_block,slime_grass,slime_congealed,slime_dirt
dimensions=12,26,17
allowable_overhang=0
max_leveling=7
leveling_buffer=-1
preserve_water=0
preserve_lava=0

rule1=0,100,preserveBlock
rule2=0,100,minecraft:sandstone_stairs-2
rule3=0,100,minecraft:sandstone-0
rule4=0,100,minecraft:sandstone-2
rule5=0,100,minecraft:double_stone_slab-9
rule6=0,100,minecraft:sandstone_stairs-0
rule7=0,100,minecraft:sandstone_stairs-1
rule8=0,100,minecraft:sandstone_stairs-3
rule9=0,100,minecraft:dirt-0
rule10=0,100,bookshelf,pumpkin,melon_block,hay_block,ChestGenHook:chests/spawn_bonus_chest:5-5,ChestGenHook:chests/village_blacksmith:5-5,ChestGenHook:chests/stronghold_library:5-5,ChestGenHook:chests/simple_dungeon:5-5
rule11=0,100,minecraft:wooden_slab-9
rule12=0,100,minecraft:ladder-4
rule13=0,100,minecraft:trapdoor-11
rule14=0,100,minecraft:trapdoor-8
rule15=0,100,bookshelf,pumpkin,melon_block,hay_block,ChestGenHook:chests/spawn_bonus_chest:5-3,ChestGenHook:chests/village_blacksmith:5-3,ChestGenHook:chests/stronghold_library:5-3,ChestGenHook:chests/simple_dungeon:5-3
rule16=0,100,minecraft:trapdoor-10
rule17=0,100,bookshelf,pumpkin,melon_block,hay_block,ChestGenHook:chests/spawn_bonus_chest:5-2,ChestGenHook:chests/village_blacksmith:5-2,ChestGenHook:chests/stronghold_library:5-2,ChestGenHook:chests/simple_dungeon:5-2
rule18=0,100,minecraft:ladder-3
rule19=0,100,minecraft:carpet-7
rule20=0,100,minecraft:sandstone_stairs-6
rule21=0,100,minecraft:trapdoor-0
rule22=0,100,minecraft:trapdoor-3
rule23=0,100,minecraft:trapdoor-2
rule24=0,100,minecraft:spruce_stairs-4
rule25=0,100,minecraft:ladder-5
rule26=0,100,minecraft:jungle_door-5
rule27=0,100,minecraft:jungle_door-6
rule28=0,100,minecraft:jungle_door-7
rule29=0,100,minecraft:ladder-2
rule30=0,100,minecraft:jungle_door-3
rule31=0,100,minecraft:jungle_door-4
rule32=0,100,minecraft:jungle_door-8
rule33=0,100,minecraft:trapdoor-9
rule34=0,100,minecraft:jungle_door-2
rule35=0,100,minecraft:jungle_door-9
rule36=0,100,minecraft:trapdoor-1
rule37=0,100,minecraft:carpet-8
rule38=0,100,minecraft:wooden_slab-1
rule39=0,100,minecraft:stone_slab-9
rule40=0,100,minecraft:spruce_fence_gate-1
rule41=0,100,minecraft:spruce_fence-0
rule42=0,100,minecraft:sandstone_stairs-7
rule43=0,100,minecraft:sandstone_stairs-4
rule44=0,100,minecraft:sandstone_stairs-5
rule45=0,100,minecraft:spruce_stairs-3
rule46=0,100,minecraft:spruce_stairs-2
rule47=0,100,minecraft:spruce_stairs-1
rule48=0,100,minecraft:spruce_stairs-0
rule49=0,100,minecraft:stone_slab-1
rule50=0,100,minecraft:hay_block-0

layer
1,3,4,3,3,3,4,4,3,3,2,1,1,1,1,1,1
1,3,5,5,5,5,5,5,5,5,5,1,1,1,1,1,1
1,3,5,3,3,3,3,3,5,3,4,1,1,1,1,1,1
1,3,5,3,3,3,3,3,5,3,3,4,6,1,1,1,1
1,3,5,3,3,3,3,3,5,3,3,4,5,1,1,1,1
1,4,4,3,3,3,3,3,5,3,4,4,4,1,1,1,1
6,4,3,3,3,3,3,3,5,5,5,5,5,1,1,1,1
5,4,3,5,5,5,5,5,5,5,5,5,5,6,1,1,1
5,3,3,3,4,5,3,3,3,3,3,5,3,5,1,1,1
5,3,3,3,4,5,3,3,3,3,3,5,3,3,1,1,1
3,3,3,3,4,5,3,3,3,3,3,5,3,3,1,1,1
5,5,5,5,5,5,3,3,3,3,3,5,5,5,4,6,6
5,3,3,3,3,3,5,3,3,3,3,5,5,5,5,5,2
5,3,3,3,3,3,5,5,5,5,5,5,5,5,4,4,2
5,3,3,3,3,3,5,3,3,3,3,3,5,5,5,4,2
5,3,3,3,3,3,5,3,3,3,3,3,5,5,3,4,7
5,3,3,3,3,3,5,3,3,3,3,3,5,3,3,3,1
5,5,5,5,5,5,5,3,3,3,3,3,5,3,3,3,1
5,3,3,3,3,5,5,3,3,3,3,3,5,5,5,5,3
3,3,4,4,4,5,5,5,5,5,5,5,5,5,5,5,3
3,3,4,4,4,5,5,5,5,5,3,3,3,3,3,5,3
5,3,4,3,3,4,4,3,3,5,3,3,3,3,3,5,3
3,4,4,3,3,4,4,3,3,5,3,3,3,3,3,5,3
7,7,8,3,3,4,3,3,3,5,3,3,3,3,3,5,2
1,1,8,3,3,4,3,3,3,5,3,3,3,4,4,5,3
1,1,8,3,5,4,3,3,5,5,5,5,5,5,5,5,3
endlayer

layer
1,3,4,3,3,3,6,4,3,3,1,1,1,1,1,1,1
1,3,5,5,5,5,5,5,5,5,6,1,1,1,1,1,1
1,3,5,3,3,3,3,3,5,3,4,1,1,1,1,1,1
1,3,5,3,3,3,3,3,5,3,3,4,1,1,1,1,1
1,3,5,3,3,3,3,3,5,3,3,4,6,1,1,1,1
1,4,4,3,3,3,3,3,5,3,4,4,4,1,1,1,1
1,4,3,3,3,3,3,3,5,5,5,5,5,1,1,1,1
6,4,3,5,5,5,5,5,5,5,5,5,5,1,1,1,1
8,3,3,3,4,5,3,3,3,3,3,5,3,6,1,1,1
8,3,3,3,4,5,3,3,3,3,3,5,3,3,1,1,1
3,3,3,3,4,5,3,3,3,3,3,5,3,3,1,1,1
5,5,5,5,5,5,3,3,3,3,3,5,5,5,4,1,1
5,3,3,3,3,3,5,3,3,3,3,5,5,5,4,6,1
5,3,3,3,3,3,5,5,5,5,5,5,5,5,9,2,1
5,3,3,3,3,3,5,0,0,0,0,10,5,5,5,2,1
8,3,3,3,3,3,5,0,0,0,0,0,5,5,3,4,1
5,3,3,3,3,3,11,0,0,0,0,0,5,3,3,3,1
5,5,5,5,5,5,11,0,0,0,0,0,5,3,3,3,1
5,3,3,3,3,5,11,0,0,0,0,0,5,5,5,5,3
3,3,4,4,4,5,5,5,5,12,0,0,5,5,5,5,3
3,3,4,4,4,5,5,5,5,5,3,3,3,3,3,5,3
3,9,9,3,3,4,4,3,3,5,3,3,3,3,3,5,3
7,7,4,4,9,4,4,3,3,5,3,3,3,3,3,5,3
1,1,1,4,9,4,3,3,3,5,3,3,3,3,3,5,1
1,1,1,8,4,4,3,3,3,5,3,3,3,4,4,5,6
1,1,1,8,3,4,3,3,5,5,5,5,5,5,5,5,2
endlayer

layer
1,3,4,3,3,4,1,8,4,4,1,1,1,1,1,1,1
1,3,5,5,5,5,5,5,5,5,1,1,1,1,1,1,1
1,3,5,13,0,0,0,0,5,3,6,1,1,1,1,1,1
1,3,5,14,0,0,0,0,5,3,4,4,1,1,1,1,1
1,4,5,3,0,0,0,0,5,3,3,4,1,1,1,1,1
1,4,4,3,0,0,0,0,5,3,4,4,6,1,1,1,1
1,4,3,3,12,0,0,15,3,5,5,5,5,1,1,1,1
1,3,3,5,5,5,3,3,13,13,4,5,5,1,1,1,1
1,7,3,3,3,11,0,0,0,0,0,0,3,1,1,1,1
1,8,3,3,3,11,0,0,0,0,0,0,3,6,1,1,1
3,3,3,3,3,11,0,0,0,0,0,0,3,3,1,1,1
5,5,5,5,5,5,12,0,0,0,0,0,5,5,1,1,1
5,14,0,0,0,0,5,16,0,0,0,15,5,5,1,1,1
5,14,0,0,0,0,5,5,3,3,3,3,5,5,1,1,1
5,17,0,0,0,0,5,0,0,0,0,0,5,5,5,1,1
1,3,0,0,0,18,5,0,0,0,0,0,5,5,3,6,1
6,3,0,0,0,4,19,0,0,0,0,0,5,3,3,3,1
5,5,5,5,5,5,19,0,0,0,0,0,5,3,3,3,1
5,3,3,3,3,5,19,0,0,0,0,0,5,5,5,5,4
4,3,4,4,4,5,5,5,5,12,0,0,4,5,5,5,3
7,3,4,4,4,5,5,5,5,5,3,3,13,13,13,5,3
1,1,1,3,3,4,4,3,3,0,0,0,0,0,0,5,3
1,1,1,1,1,4,4,3,3,0,0,0,0,0,0,5,4
1,1,1,1,1,4,4,3,3,0,0,0,0,0,15,5,1
1,1,1,1,1,4,3,3,3,12,0,0,0,4,4,5,1
1,1,1,1,1,8,3,3,5,5,5,5,5,5,5,2,1
endlayer

layer
1,3,4,3,3,3,1,1,8,4,1,1,1,1,1,1,1
1,3,5,5,5,5,5,5,5,4,1,1,1,1,1,1,1
1,3,5,0,0,0,0,0,5,5,1,1,1,1,1,1,1
1,3,5,0,0,0,0,0,5,3,6,4,1,1,1,1,1
1,4,5,3,0,0,0,0,5,3,9,4,1,1,1,1,1
1,4,9,3,0,0,0,0,5,3,9,4,1,1,1,1,1
1,4,9,3,12,0,0,0,3,5,5,4,6,1,1,1,1
1,7,3,5,5,5,3,3,0,0,4,5,5,1,1,1,1
1,1,7,3,3,0,0,0,0,0,0,0,5,1,1,1,1
1,1,8,3,3,0,0,0,0,0,0,0,3,1,1,1,1
4,4,4,4,3,0,0,0,0,0,0,0,3,6,1,1,1
5,5,5,5,5,5,12,0,0,0,0,0,5,3,1,1,1
5,0,0,0,0,0,5,0,0,0,0,0,5,5,1,1,1
5,0,0,0,0,0,5,5,3,3,3,3,5,5,1,1,1
5,0,0,0,0,0,5,20,0,0,0,0,5,5,3,1,1
1,3,0,0,0,18,5,20,0,0,0,0,5,5,3,1,1
1,3,0,0,0,4,0,0,0,0,0,0,5,3,3,6,1
6,5,5,5,5,5,0,0,0,0,0,0,5,3,9,3,1
5,5,3,3,3,5,0,0,0,0,0,0,5,5,5,3,3
7,8,9,9,4,5,5,5,5,12,0,0,5,5,5,5,3
1,8,4,4,4,4,3,5,5,5,3,3,0,0,0,5,3
1,1,1,4,4,3,9,3,3,0,0,0,0,0,0,5,3
1,1,1,1,1,3,9,3,3,0,0,0,0,0,0,5,4
1,1,1,1,1,3,3,4,3,0,0,0,0,0,0,5,1
1,1,1,1,1,7,7,4,5,12,0,0,0,4,4,5,1
1,1,1,1,1,1,8,4,5,5,5,5,5,5,2,1,1
endlayer

layer
1,6,3,3,4,4,1,1,1,1,1,1,1,1,1,1,1
1,4,5,5,5,5,5,5,5,1,1,1,1,1,1,1,1
1,3,5,21,0,0,0,0,5,6,1,1,1,1,1,1,1
1,3,5,21,0,0,0,0,5,5,1,1,1,1,1,1,1
1,7,5,3,0,0,0,0,5,5,1,1,1,1,1,1,1
1,1,1,3,0,0,0,0,5,5,1,1,1,1,1,1,1
1,1,1,3,12,0,0,0,3,5,2,1,1,1,1,1,1
1,1,1,5,5,5,3,3,22,22,4,5,6,1,1,1,1
1,1,1,8,3,0,0,0,0,0,0,0,5,1,1,1,1
1,1,1,4,3,0,0,0,0,0,0,0,5,1,1,1,1
8,4,4,4,3,0,0,0,0,0,0,0,5,1,1,1,1
5,5,5,5,5,5,12,0,0,0,0,0,5,6,1,1,1
5,21,0,0,0,0,4,23,11,11,11,11,5,3,1,1,1
5,21,0,0,0,0,5,5,24,24,24,24,5,4,1,1,1
5,21,0,0,0,0,5,3,20,11,11,11,5,2,1,1,1
1,3,0,0,0,18,4,3,20,11,11,11,5,5,1,1,1
1,3,0,0,0,4,11,11,11,11,11,11,5,5,1,1,1
1,5,5,5,5,5,11,11,11,11,11,11,5,5,1,1,1
1,8,5,5,5,5,11,11,11,11,11,11,5,5,3,3,4
1,1,1,1,4,3,5,5,5,12,11,11,5,5,5,5,3
1,1,1,1,8,4,3,3,5,5,3,3,22,22,22,5,3
1,1,1,1,1,1,1,3,5,0,0,0,0,0,0,5,3
1,1,1,1,1,1,1,3,5,0,0,0,0,0,0,5,4
1,1,1,1,1,1,1,4,5,0,0,0,0,0,0,5,1
1,1,1,1,1,1,1,7,5,12,0,0,0,4,4,5,1
1,1,1,1,1,1,1,1,3,5,5,5,5,2,1,1,1
endlayer

layer
1,1,3,3,3,3,1,1,1,1,1,1,1,1,1,1,1
1,6,4,5,5,4,5,5,4,1,1,1,1,1,1,1,1
1,3,5,11,11,11,11,11,5,1,1,1,1,1,1,1,1
1,7,5,11,11,11,11,11,5,6,1,1,1,1,1,1,1
1,1,4,5,11,11,11,5,5,5,1,1,1,1,1,1,1
1,1,1,5,11,11,11,5,5,2,1,1,1,1,1,1,1
1,1,1,5,12,11,11,5,5,2,1,1,1,1,1,1,1
1,1,1,5,5,5,5,5,5,5,5,4,1,1,1,1,1
1,1,1,1,8,20,11,11,11,11,11,5,6,1,1,1,1
1,1,1,4,4,20,11,11,11,11,11,4,5,1,1,1,1
1,8,3,3,3,20,11,11,11,11,11,4,5,1,1,1,1
4,5,5,4,5,5,12,11,3,3,3,4,5,1,1,1,1
5,11,11,11,5,5,5,3,0,25,0,0,3,1,1,1,1
5,11,11,11,11,11,5,5,0,0,0,0,26,1,1,1,1
4,11,11,11,11,11,5,3,6,0,0,0,5,1,1,1,1
1,5,11,11,11,18,5,3,4,0,0,0,5,5,1,1,1
1,5,11,11,11,5,0,0,0,0,0,0,4,5,1,1,1
1,5,5,5,5,5,0,0,0,0,0,0,4,5,1,1,1
1,1,8,5,7,3,0,0,0,0,0,0,4,3,3,3,4
1,1,1,1,1,3,27,5,5,12,0,0,5,11,11,4,3
1,1,1,1,1,1,1,8,3,5,5,5,11,11,11,5,3
1,1,1,1,1,1,1,6,5,11,11,11,11,11,11,5,3
1,1,1,1,1,1,1,3,5,11,11,11,11,11,11,4,3
1,1,1,1,1,1,1,7,5,11,11,11,11,5,5,5,1
1,1,1,1,1,1,1,1,3,12,11,11,5,7,5,5,1
1,1,1,1,1,1,1,1,3,4,5,5,4,1,1,1,1
endlayer

layer
1,1,4,3,3,4,1,1,1,1,1,1,1,1,1,1,1
1,1,5,0,0,5,5,5,5,1,1,1,1,1,1,1,1
1,1,28,0,0,0,0,0,8,1,1,1,1,1,1,1,1
1,1,5,0,0,0,0,0,3,1,1,1,1,1,1,1,1
1,1,5,3,0,0,0,3,4,1,1,1,1,1,1,1,1
1,1,1,3,29,0,0,26,1,1,1,1,1,1,1,1,1
1,1,1,3,12,0,0,3,1,1,1,1,1,1,1,1,1
1,1,1,5,5,5,5,5,5,5,5,5,1,1,1,1,1
1,1,1,1,1,5,0,0,0,0,0,5,1,1,1,1,1
1,1,1,1,1,30,0,0,0,0,0,26,1,1,1,1,1
1,1,1,1,1,5,0,0,0,12,0,4,1,1,1,1,1
5,5,31,5,5,4,12,0,3,3,3,4,4,1,1,1,1
5,0,0,0,3,3,3,4,0,25,0,0,3,1,1,1,1
5,0,0,0,0,0,33,3,0,0,0,0,32,1,1,1,1
5,0,0,0,0,0,33,3,0,0,0,0,5,1,1,1,1
1,3,0,0,0,18,5,3,4,0,0,0,4,4,1,1,1
1,3,0,0,0,3,0,0,0,0,0,0,19,8,1,1,1
1,5,4,34,4,5,0,0,0,0,0,0,19,3,1,1,1
1,1,1,1,1,3,0,0,0,0,0,0,19,3,3,3,4
1,1,1,1,1,4,32,4,5,12,0,0,5,13,0,0,4
1,1,1,1,1,1,1,1,3,5,3,3,0,0,0,0,8
1,1,1,1,1,1,1,1,3,0,0,0,0,0,0,0,3
1,1,1,1,1,1,1,1,28,0,0,0,0,0,0,5,4
1,1,1,1,1,1,1,1,3,29,0,0,0,4,27,5,1
1,1,1,1,1,1,1,1,3,12,0,0,3,1,1,1,1
1,1,1,1,1,1,1,1,4,5,5,5,5,1,1,1,1
endlayer

layer
1,1,4,1,3,4,1,1,1,1,1,1,1,1,1,1,1
1,1,4,0,0,5,1,5,4,1,1,1,1,1,1,1,1
1,1,32,0,0,0,0,0,1,1,1,1,1,1,1,1,1
1,1,3,0,0,0,0,0,3,1,1,1,1,1,1,1,1
1,1,5,3,0,0,0,3,4,1,1,1,1,1,1,1,1
1,1,1,3,29,0,0,32,1,1,1,1,1,1,1,1,1
1,1,1,1,0,0,0,3,1,1,1,1,1,1,1,1,1
1,1,1,5,5,3,5,5,5,5,5,4,1,1,1,1,1
1,1,1,1,1,5,0,0,0,0,0,5,1,1,1,1,1
1,1,1,1,1,32,0,0,0,0,0,32,1,1,1,1,1
1,1,1,1,1,5,0,0,0,12,0,4,1,1,1,1,1
4,5,32,5,5,4,0,0,4,3,3,4,4,1,1,1,1
5,0,0,0,3,3,3,4,11,25,0,0,3,1,1,1,1
1,0,0,0,0,0,0,3,11,0,0,0,4,1,1,1,1
5,0,0,0,0,0,0,3,11,0,0,0,5,1,1,1,1
1,3,0,0,0,0,5,3,4,0,0,0,4,4,1,1,1
1,1,0,0,0,3,0,0,0,0,0,0,0,1,1,1,1
1,5,4,35,4,5,0,0,0,0,0,0,0,3,1,1,1
1,1,1,1,1,3,0,0,0,0,0,0,0,3,3,3,4
1,1,1,1,1,4,4,4,5,0,0,0,5,0,0,0,4
1,1,1,1,1,1,1,1,3,5,3,3,0,0,0,0,1
1,1,1,1,1,1,1,1,3,0,0,0,0,0,0,0,3
1,1,1,1,1,1,1,1,32,0,0,0,0,0,0,5,4
1,1,1,1,1,1,1,1,3,29,0,0,0,4,32,3,1
1,1,1,1,1,1,1,1,3,0,0,0,3,1,1,1,1
1,1,1,1,1,1,1,1,4,4,1,4,5,1,1,1,1
endlayer

layer
1,1,4,3,3,4,1,1,1,1,1,1,1,1,1,1,1
1,1,5,0,0,5,5,5,5,1,1,1,1,1,1,1,1
1,1,5,0,0,0,0,0,3,1,1,1,1,1,1,1,1
1,1,5,0,0,0,0,0,3,1,1,1,1,1,1,1,1
1,1,5,3,0,0,0,3,3,1,1,1,1,1,1,1,1
1,1,1,3,0,0,0,3,1,1,1,1,1,1,1,1,1
1,1,1,3,23,23,23,3,1,1,1,1,1,1,1,1,1
1,1,1,5,5,5,5,5,5,5,5,5,1,1,1,1,1
1,1,1,1,1,5,0,0,0,0,36,4,1,1,1,1,1
1,1,1,1,1,5,0,0,0,0,36,4,1,1,1,1,1
1,1,1,1,1,5,0,0,0,0,36,4,1,1,1,1,1
5,5,5,5,5,4,0,0,4,3,3,5,3,1,1,1,1
5,0,0,0,3,3,3,4,37,0,0,0,3,1,1,1,1
5,0,0,0,0,0,36,3,19,0,0,0,5,1,1,1,1
5,0,0,0,0,0,36,3,19,0,0,0,5,1,1,1,1
1,3,0,0,0,0,5,3,4,0,0,0,5,3,1,1,1
1,3,0,0,0,3,0,0,0,0,0,0,0,3,1,1,1
1,5,5,4,5,5,0,0,0,0,0,0,0,3,1,1,1
1,1,1,1,1,3,0,0,0,0,0,0,0,3,4,4,3
1,1,1,1,1,3,5,5,5,0,0,0,5,22,0,0,4
1,1,1,1,1,1,1,1,3,3,3,3,0,0,0,0,3
1,1,1,1,1,1,1,1,3,0,0,0,0,0,0,0,3
1,1,1,1,1,1,1,1,3,0,0,0,0,0,0,5,3
1,1,1,1,1,1,1,1,3,0,0,0,0,4,4,5,1
1,1,1,1,1,1,1,1,3,38,38,38,3,1,1,1,1
1,1,1,1,1,1,1,1,3,5,5,5,5,1,1,1,1
endlayer

layer
1,1,6,6,6,2,1,1,1,1,1,1,1,1,1,1,1
1,1,8,39,39,4,5,5,4,1,1,1,1,1,1,1,1
1,1,8,13,39,39,0,0,3,1,1,1,1,1,1,1,1
1,1,8,39,39,39,0,0,3,1,1,1,1,1,1,1,1
1,1,7,3,39,39,39,3,4,1,1,1,1,1,1,1,1
1,1,1,3,0,0,0,3,38,1,1,1,1,1,1,1,1
1,1,1,3,0,0,0,3,38,1,1,1,1,1,1,1,1
1,1,1,4,5,5,5,5,5,5,5,4,1,1,1,1,1
1,1,1,41,40,5,0,0,20,0,0,5,1,1,1,1,1
1,1,1,41,40,5,0,0,20,0,0,5,1,1,1,1,1
1,1,1,41,40,5,0,0,20,0,0,5,1,1,1,1,1
4,6,6,4,5,3,0,0,4,3,3,5,4,1,1,1,1
8,0,0,0,3,3,3,4,0,0,0,0,3,1,1,1,1
8,0,0,0,42,0,0,4,0,0,0,0,4,1,1,1,1
4,43,43,43,43,0,0,4,0,0,0,0,3,1,1,1,1
1,4,0,0,42,3,5,3,3,44,44,44,3,4,1,1,1
1,3,0,0,42,3,39,39,39,20,0,0,0,3,1,1,1
1,4,5,5,5,5,39,14,39,20,0,0,0,3,1,1,1
1,1,1,1,1,8,39,39,39,20,0,0,0,3,6,6,4
1,1,1,1,1,8,7,7,8,20,39,39,4,39,39,39,2
1,1,1,1,1,1,1,1,4,3,3,3,44,39,13,39,2
1,1,1,1,1,1,1,1,3,0,0,0,0,39,39,39,2
1,1,1,1,1,1,1,1,3,0,0,0,0,39,42,4,4
1,1,1,1,1,1,1,1,3,0,0,0,0,4,7,3,1
1,1,1,1,1,1,1,1,3,0,0,0,3,1,1,1,1
1,1,1,1,1,1,1,1,4,4,5,5,4,1,1,1,1
endlayer

layer
1,1,1,1,1,1,1,1,1,1,1,1,1,1,1,1,1
1,1,1,1,1,4,46,45,4,1,1,1,1,1,1,1,1
1,1,1,1,1,47,0,0,47,1,1,1,1,1,1,1,1
1,1,1,1,1,48,0,0,48,1,1,1,1,1,1,1,1
1,1,1,49,49,4,46,45,4,1,1,1,1,1,1,1,1
1,1,1,49,49,49,49,49,1,1,1,1,1,1,1,1,1
1,1,1,49,21,49,36,49,1,1,1,1,1,1,1,1,1
1,1,1,49,49,4,6,6,4,6,6,2,1,1,1,1,1
1,1,1,1,1,8,39,39,2,49,49,2,1,1,1,1,1
1,1,1,1,1,4,39,39,6,21,49,2,1,1,1,1,1
1,1,1,1,1,4,39,33,4,49,49,2,1,1,1,1,1
4,7,7,4,49,8,39,39,4,7,7,7,1,1,1,1,1
2,22,22,8,8,4,4,4,7,49,49,49,49,1,1,1,1
2,23,23,8,8,50,50,2,49,49,22,49,49,1,1,1,1
4,6,6,4,8,50,50,2,49,49,49,49,49,1,1,1,1
1,1,49,22,49,7,7,49,49,4,7,7,7,4,1,1,1
1,1,49,49,49,1,1,1,1,2,38,38,38,8,1,1,1
1,1,1,1,1,1,1,1,1,2,38,22,38,8,1,1,1
1,1,1,1,1,1,1,1,1,2,38,38,38,8,1,1,1
1,1,1,1,1,1,1,1,1,4,6,6,6,4,1,1,1
1,1,1,1,1,1,1,1,3,4,3,4,3,1,1,1,1
1,1,1,1,1,1,1,1,4,0,0,0,4,1,1,1,1
1,1,1,1,1,1,1,1,3,0,0,0,3,1,1,1,1
1,1,1,1,1,1,1,1,3,0,0,0,3,1,1,1,1
1,1,1,1,1,1,1,1,4,0,0,0,4,1,1,1,1
1,1,1,1,1,1,1,1,3,4,3,4,3,1,1,1,1
endlayer

layer
1,1,1,1,1,1,1,1,1,1,1,1,1,1,1,1,1
1,1,1,1,1,48,48,48,46,1,1,1,1,1,1,1,1
1,1,1,1,1,45,50,50,46,1,1,1,1,1,1,1,1
1,1,1,1,1,45,50,50,46,1,1,1,1,1,1,1,1
1,1,1,1,1,45,47,47,47,1,1,1,1,1,1,1,1
1,1,1,1,1,1,1,1,1,1,1,1,1,1,1,1,1
1,1,1,1,1,1,1,1,1,1,1,1,1,1,1,1,1
1,1,1,1,1,1,1,1,1,1,1,1,1,1,1,1,1
1,1,1,1,1,1,49,49,1,1,1,1,1,1,1,1,1
1,1,1,1,1,1,49,49,1,1,1,1,1,1,1,1,1
1,1,1,1,1,1,49,1,49,1,1,1,1,1,1,1,1
1,1,1,1,1,1,49,49,49,1,1,1,1,1,1,1,1
1,1,1,1,1,1,1,1,1,1,1,1,1,1,1,1,1
1,1,1,1,1,1,1,1,1,1,1,1,1,1,1,1,1
1,1,1,1,1,1,1,1,1,1,1,1,1,1,1,1,1
1,1,1,1,1,1,1,1,1,1,1,1,1,1,1,1,1
1,1,1,1,1,1,1,1,1,1,1,1,1,1,1,1,1
1,1,1,1,1,1,1,1,1,1,1,1,1,1,1,1,1
1,1,1,1,1,1,1,1,1,1,1,1,1,1,1,1,1
1,1,1,1,1,1,1,1,1,1,1,1,1,1,1,1,1
1,1,1,1,1,1,1,1,49,4,6,4,49,1,1,1,1
1,1,1,1,1,1,1,1,4,3,3,3,4,1,1,1,1
1,1,1,1,1,1,1,1,8,3,22,3,2,1,1,1,1
1,1,1,1,1,1,1,1,8,3,23,3,2,1,1,1,1
1,1,1,1,1,1,1,1,4,3,3,3,4,1,1,1,1
1,1,1,1,1,1,1,1,49,4,7,4,49,1,1,1,1
endlayer

