# Gilly's Encrusted Portal Tower

# template generated with Ruins mod version 16.5 Ingame Parser
# Structure created and developed by Gilly

weight=1
embed_into_distance=6
uniqueMinDistance=700
acceptable_target_blocks=
unacceptable_target_blocks=flowing_water,water,flowing_lava,lava,ice,bedrock,netherrack,nether_brick,nether_brick_fence,soul_sand,quartz_ore,end_stone,obsidian,iron_bars,cloud,flesh,ash_block,slime_grass,slime_congealed,slime_dirt
biomesToSpawnIn=plains,mutated_plains,ice_flats,meadow,forest,taiga,woodland,woodlands,fen,brushland,shrubland,outback,chaparral,savanna,badlands,tundra,desert,jungle,mini jungle,birch forest,red desert,autumnal forest,rocky plateau,ice plains,cold taiga,mega taiga
dimensions=34,15,15
allowable_overhang=0
max_leveling=4
leveling_buffer=-1
preserve_water=0
preserve_lava=0

rule1=0,100,preserveBlock
rule2=0,100,minecraft:stone_brick_stairs-2
rule3=0,100,stonebrick,stonebrick,stonebrick,stonebrick,stonebrick,stonebrick-2,stonebrick-2
rule4=0,100,minecraft:stone_brick_stairs-3
rule5=0,100,minecraft:stone_brick_stairs-0
rule6=0,100,minecraft:stone_brick_stairs-1
rule7=0,100,minecraft:stone_brick_stairs-7
rule8=0,100,minecraft:stone_brick_stairs-4
rule9=0,100,minecraft:stone_brick_stairs-6
rule10=1,100,minecraft:torch-5
rule11=0,100,minecraft:stone_brick_stairs-5
rule12=0,100,minecraft:quartz_block-0
rule13=0,100,minecraft:stone_slab-8
rule14=0,100,minecraft:quartz_block-1
rule15=0,100,minecraft:obsidian-0
rule16=0,100,minecraft:stone_slab-15
rule17=0,100,minecraft:double_stone_slab-7
rule18=0,100,minecraft:quartz_stairs-7
rule19=0,100,minecraft:quartz_stairs-6
rule20=0,100,minecraft:quartz_stairs-4
rule21=0,100,minecraft:stained_glass_pane-3
rule22=0,100,minecraft:quartz_stairs-5
rule23=0,100,minecraft:fence-0
rule24=0,100,minecraft:stone_slab-7
rule25=0,100,minecraft:quartz_stairs-0
rule26=0,100,minecraft:quartz_stairs-3
rule27=0,100,minecraft:quartz_stairs-2
rule28=0,100,minecraft:quartz_stairs-1

layer
1,1,4,3,3,3,3,3,3,3,3,3,2,1,1
1,1,4,3,3,3,3,3,3,3,3,3,2,1,1
5,5,3,3,3,3,3,3,3,3,3,3,3,5,5
3,3,3,3,3,3,3,3,3,3,3,3,3,3,3
3,3,3,3,3,3,3,3,3,3,3,3,3,3,3
3,3,3,3,3,3,3,3,3,3,3,3,3,3,3
3,3,3,3,3,3,3,3,3,3,3,3,3,3,3
3,3,3,3,3,3,3,3,3,3,3,3,3,3,3
3,3,3,3,3,3,3,3,3,3,3,3,3,3,3
3,3,3,3,3,3,3,3,3,3,3,3,3,3,3
3,3,3,3,3,3,3,3,3,3,3,3,3,3,3
3,3,3,3,3,3,3,3,3,3,3,3,3,3,3
6,6,3,3,3,3,3,3,3,3,3,3,3,6,6
1,1,4,3,3,3,3,3,3,3,3,3,2,1,1
1,1,4,3,3,3,3,3,3,3,3,3,2,1,1
endlayer

layer
1,1,1,4,3,3,9,8,7,3,3,2,1,1,1
1,1,1,4,3,3,0,10,0,3,3,2,1,1,1
1,1,3,3,3,3,3,3,3,3,3,3,3,1,1
5,5,3,3,3,3,3,3,3,3,3,3,3,5,5
3,3,3,3,3,3,3,3,3,3,3,3,3,3,3
3,3,3,3,3,3,3,3,3,3,3,3,3,3,3
11,0,3,3,3,3,3,3,3,3,3,3,3,0,11
7,10,3,3,3,3,3,3,3,3,3,3,3,10,9
8,0,3,3,3,3,3,3,3,3,3,3,3,0,8
3,3,3,3,3,3,3,3,3,3,3,3,3,3,3
3,3,3,3,3,3,3,3,3,3,3,3,3,3,3
6,6,3,3,3,3,3,3,3,3,3,3,3,6,6
1,1,3,3,3,3,3,3,3,3,3,3,3,1,1
1,1,1,4,3,3,0,10,0,3,3,2,1,1,1
1,1,1,4,3,3,9,11,7,3,3,2,1,1,1
endlayer

layer
1,1,1,1,5,5,5,5,5,5,5,1,1,1,1
1,1,1,1,4,3,3,3,3,3,2,1,1,1,1
1,1,7,8,3,3,3,3,3,3,3,8,8,1,1
1,1,7,3,3,3,3,3,3,3,3,3,9,1,1
4,5,3,3,3,3,3,3,3,3,3,3,3,5,2
4,3,3,3,3,3,3,3,3,3,3,3,3,3,2
4,3,3,3,3,3,3,3,3,3,3,3,3,3,2
4,3,3,3,3,3,3,3,3,3,3,3,3,3,2
4,3,3,3,3,3,3,3,3,3,3,3,3,3,2
4,3,3,3,3,3,3,3,3,3,3,3,3,3,2
4,6,3,3,3,3,3,3,3,3,3,3,3,6,2
1,1,7,3,3,3,3,3,3,3,3,3,9,1,1
1,1,7,11,3,3,3,3,3,3,3,11,9,1,1
1,1,1,1,4,3,3,3,3,3,2,1,1,1,1
1,1,1,1,6,6,6,6,6,6,6,1,1,1,1
endlayer

layer
1,1,1,1,1,1,1,1,1,1,1,1,1,1,1
1,1,1,1,1,4,5,5,5,2,1,1,1,1,1
1,1,1,7,3,3,3,3,3,3,3,9,1,1,1
1,1,8,3,3,3,3,3,3,3,3,3,8,1,1
1,1,3,3,3,3,3,3,3,3,3,3,3,1,1
1,5,3,3,3,3,3,3,3,3,3,3,3,5,1
1,4,3,3,3,3,3,3,3,3,3,3,3,2,1
1,4,3,3,3,3,3,3,3,3,3,3,3,2,1
1,4,3,3,3,3,3,3,3,3,3,3,3,2,1
1,6,3,3,3,3,3,3,3,3,3,3,3,6,1
1,1,3,3,3,3,3,3,3,3,3,3,3,1,1
1,1,11,3,3,3,3,3,3,3,3,3,11,1,1
1,1,1,7,3,3,3,3,3,3,3,9,1,1,1
1,1,1,1,1,4,6,6,6,2,1,1,1,1,1
1,1,1,1,1,1,1,1,1,1,1,1,1,1,1
endlayer

layer
1,1,1,1,1,1,1,1,1,1,1,1,1,1,1
1,1,1,1,1,1,1,1,1,1,1,1,1,1,1
1,1,1,7,3,3,5,5,5,3,3,9,1,1,1
1,1,8,3,3,3,3,3,3,3,3,3,8,1,1
1,1,3,3,3,3,3,3,3,3,3,3,3,1,1
1,1,3,3,3,3,3,3,3,3,3,3,6,1,1
1,1,4,3,3,3,3,3,3,3,3,3,2,1,1
1,1,4,3,3,3,3,3,3,3,3,3,2,1,1
1,1,4,3,3,3,3,3,3,3,3,3,2,1,1
1,1,5,4,3,3,3,3,3,3,3,2,5,1,1
1,1,3,3,3,3,3,3,3,3,3,3,3,1,1
1,1,11,3,3,3,3,3,3,3,3,3,11,1,1
1,1,1,7,3,3,6,6,6,3,3,9,1,1,1
1,1,1,1,1,1,1,1,1,1,1,1,1,1,1
1,1,1,1,1,1,1,1,1,1,1,1,1,1,1
endlayer

layer
1,1,1,1,1,1,1,1,1,1,1,1,1,1,1
1,1,1,1,1,1,1,1,1,1,1,1,1,1,1
1,1,1,3,3,3,1,1,1,3,3,3,1,1,1
1,1,3,3,3,3,5,5,5,3,3,3,3,1,1
1,1,3,3,3,3,3,3,3,3,3,3,3,1,1
1,1,3,3,3,3,3,3,3,3,3,3,3,1,1
1,1,1,4,3,3,3,3,3,3,3,2,1,1,1
1,1,1,4,3,3,3,3,3,3,3,2,1,1,1
1,1,1,4,3,3,3,3,3,3,3,2,1,1,1
1,1,3,3,3,3,3,3,3,3,3,3,3,1,1
1,1,3,3,3,3,3,3,3,3,3,3,3,1,1
1,1,3,3,3,3,6,6,6,3,3,3,3,1,1
1,1,1,3,3,3,1,1,1,3,3,3,1,1,1
1,1,1,1,1,1,1,1,1,1,1,1,1,1,1
1,1,1,1,1,1,1,1,1,1,1,1,1,1,1
endlayer

layer
1,1,1,1,1,1,1,1,1,1,1,1,1,1,1
1,1,1,1,1,1,1,1,1,1,1,1,1,1,1
1,1,1,1,12,12,1,1,1,12,12,1,1,1,1
1,1,1,13,12,12,1,1,1,12,12,13,1,1,1
1,1,12,12,14,12,5,5,5,12,14,12,12,1,1
1,1,12,12,12,12,15,15,15,12,12,12,12,1,1
1,1,1,1,4,14,14,12,14,14,2,1,1,1,1
1,1,1,1,4,12,12,12,12,12,2,1,1,1,1
1,1,1,1,4,14,14,12,14,14,2,1,1,1,1
1,1,12,12,12,12,14,12,14,12,12,12,12,1,1
1,1,12,12,14,12,6,6,6,12,14,12,12,1,1
1,1,1,13,12,12,1,1,1,12,12,13,1,1,1
1,1,1,1,12,12,1,1,1,12,12,1,1,1,1
1,1,1,1,1,1,1,1,1,1,1,1,1,1,1
1,1,1,1,1,1,1,1,1,1,1,1,1,1,1
endlayer

layer
1,1,1,1,1,1,0,0,0,1,1,1,1,1,1
1,1,1,1,0,0,0,0,0,0,0,1,1,1,1
1,1,1,0,16,17,0,0,0,17,16,0,1,1,1
1,1,0,13,13,0,0,0,0,0,13,13,0,1,1
1,0,16,13,0,0,0,0,0,0,0,13,16,0,1
1,0,12,0,0,15,0,0,0,15,0,0,12,0,1
0,0,0,0,0,0,0,0,0,0,0,0,0,0,0
0,0,0,0,0,0,0,0,0,0,0,0,0,0,0
0,0,0,0,0,0,0,0,0,0,0,0,0,0,0
1,0,12,0,0,0,0,0,0,0,0,0,12,0,1
1,0,16,13,0,0,0,0,0,0,0,13,16,0,1
1,1,0,13,13,0,0,0,0,0,13,13,0,1,1
1,1,1,0,16,17,0,0,0,17,16,0,1,1,1
1,1,1,1,0,0,0,0,0,0,0,1,1,1,1
1,1,1,1,1,1,0,0,0,1,1,1,1,1,1
endlayer

layer
1,1,1,1,0,0,0,0,0,0,0,1,1,1,1
1,1,1,0,0,0,0,0,0,0,0,0,1,1,1
1,1,0,0,16,17,0,0,0,17,16,0,0,1,1
1,0,0,13,13,0,0,0,0,0,13,13,0,0,1
0,0,16,13,0,0,0,0,0,0,0,13,16,0,0
0,0,12,0,0,15,0,0,0,15,0,0,12,0,0
0,0,0,0,0,0,0,0,0,0,0,0,0,0,0
0,0,0,0,0,0,0,0,0,0,0,0,0,0,0
0,0,0,0,0,0,0,0,0,0,0,0,0,0,0
0,0,12,0,0,0,0,0,0,0,0,0,12,0,0
0,0,16,13,0,0,0,0,0,0,0,13,16,0,0
1,0,0,13,13,0,0,0,0,0,13,13,0,0,1
1,1,0,0,16,17,0,0,0,17,16,0,0,1,1
1,1,1,0,0,0,0,0,0,0,0,0,1,1,1
1,1,1,1,0,0,0,0,0,0,0,1,1,1,1
endlayer

layer
1,1,1,0,0,0,0,0,0,0,0,0,1,1,1
1,1,0,0,0,0,0,0,0,0,0,0,0,1,1
1,0,0,0,16,17,0,0,0,17,16,0,0,0,1
0,0,0,13,13,0,0,0,0,0,13,13,0,0,0
0,0,16,13,0,0,0,0,0,0,0,13,16,0,0
0,0,12,0,0,15,0,0,0,15,0,0,12,0,0
0,0,0,0,0,0,0,0,0,0,0,0,0,0,0
0,0,0,0,0,0,0,0,0,0,0,0,0,0,0
0,0,0,0,0,0,0,0,0,0,0,0,0,0,0
0,0,12,0,0,0,0,0,0,0,0,0,12,0,0
0,0,16,13,0,0,0,0,0,0,0,13,16,0,0
0,0,0,13,13,0,0,0,0,0,13,13,0,0,0
1,0,0,0,16,17,0,0,0,17,16,0,0,0,1
1,1,0,0,0,0,0,0,0,0,0,0,0,1,1
1,1,1,0,0,0,0,0,0,0,0,0,1,1,1
endlayer

layer
1,1,0,0,0,0,0,0,0,0,0,0,0,1,1
1,0,0,0,0,0,0,0,0,0,0,0,0,0,1
0,0,0,0,16,12,0,0,0,17,16,0,0,0,0
0,0,0,16,0,16,0,0,0,16,16,16,0,0,0
0,0,16,0,0,0,0,0,0,0,0,16,16,0,0
0,0,12,16,0,15,0,0,0,15,0,16,12,0,0
0,0,0,0,0,0,0,0,0,0,0,0,0,0,0
0,0,0,0,0,0,0,0,0,0,0,0,0,0,0
0,0,0,0,0,0,0,0,0,0,0,0,0,0,0
0,0,12,16,0,0,0,0,0,0,0,16,12,0,0
0,0,16,16,0,0,0,0,0,0,0,16,16,0,0
0,0,0,16,16,16,0,0,0,16,16,16,0,0,0
0,0,0,0,16,17,0,0,0,17,16,0,0,0,0
1,0,0,0,0,0,0,0,0,0,0,0,0,0,1
1,1,0,0,0,0,0,0,0,0,0,0,0,1,1
endlayer

layer
1,0,0,0,0,0,0,0,0,0,0,0,0,0,1
0,0,0,0,0,0,0,0,0,0,0,0,0,0,0
0,0,16,16,16,12,19,16,18,12,16,16,16,0,0
0,0,20,0,0,0,16,16,16,0,0,16,16,0,0
0,0,16,21,21,12,0,0,0,12,21,0,16,0,0
0,0,12,0,12,0,15,15,15,0,12,0,12,0,0
0,0,22,16,0,0,0,0,0,0,0,16,22,0,0
0,0,16,16,0,0,0,0,0,0,0,16,16,0,0
0,0,20,16,0,0,0,0,0,0,0,16,20,0,0
0,0,12,0,12,0,0,0,0,0,12,0,12,0,0
0,0,16,21,21,12,0,0,0,12,21,21,16,0,0
0,0,16,0,0,0,16,16,16,0,0,16,16,0,0
0,0,16,16,16,17,19,16,18,17,16,16,16,0,0
0,0,0,0,0,0,0,0,0,0,0,0,0,0,0
1,0,0,0,0,0,0,0,0,0,0,0,0,0,1
endlayer

layer
0,0,0,0,0,0,0,0,0,0,0,0,0,0,0
0,0,0,0,0,0,0,0,0,0,0,0,0,0,0
0,0,0,0,0,16,17,16,17,16,0,0,0,0,0
0,0,0,16,16,21,21,21,21,21,16,16,0,0,0
0,0,0,16,21,21,0,0,0,21,21,16,0,0,0
0,0,16,21,21,0,0,0,0,0,21,21,16,0,0
0,0,12,21,0,0,0,0,0,0,0,21,12,0,0
0,0,16,21,0,0,0,0,0,0,0,21,16,0,0
0,0,12,21,0,0,0,0,0,0,0,21,12,0,0
0,0,16,21,21,0,0,0,0,0,21,21,16,0,0
0,0,0,16,21,21,0,0,0,21,21,16,0,0,0
0,0,0,16,16,21,21,21,21,21,16,16,0,0,0
0,0,0,0,0,16,17,16,17,16,0,0,0,0,0
0,0,0,0,0,0,0,0,0,0,0,0,0,0,0
0,0,0,0,0,0,0,0,0,0,0,0,0,0,0
endlayer

layer
0,0,0,0,0,0,0,0,0,0,0,0,0,0,0
0,0,0,0,0,0,0,0,0,0,0,0,0,0,0
0,0,0,0,0,16,17,0,17,16,0,0,0,0,0
0,0,0,16,16,21,21,21,21,21,16,16,0,0,0
0,0,0,16,21,21,0,23,0,21,21,16,0,0,0
0,0,16,21,21,0,0,0,0,0,21,21,16,0,0
0,0,12,21,0,0,0,0,0,0,0,21,12,0,0
0,0,0,21,23,0,0,0,0,0,23,21,0,0,0
0,0,12,21,0,0,0,0,0,0,0,21,12,0,0
0,0,16,21,21,0,0,0,0,0,21,21,16,0,0
0,0,0,16,21,21,0,23,0,21,21,16,0,0,0
0,0,0,16,16,21,21,21,21,21,16,16,0,0,0
0,0,0,0,0,16,17,0,17,16,0,0,0,0,0
0,0,0,0,0,0,0,0,0,0,0,0,0,0,0
0,0,0,0,0,0,0,0,0,0,0,0,0,0,0
endlayer

layer
0,0,0,0,0,0,0,0,0,0,0,0,0,0,0
0,0,0,0,0,0,0,0,0,0,0,0,0,0,0
0,0,16,16,16,16,17,16,17,16,16,16,16,0,0
0,0,16,0,0,21,21,21,21,21,0,16,16,0,0
0,0,16,0,21,21,0,10,0,21,21,0,16,0,0
0,0,16,21,21,0,0,0,0,0,21,21,16,0,0
0,0,12,21,0,0,0,0,0,0,0,21,12,0,0
0,0,16,21,10,0,0,0,0,0,10,21,16,0,0
0,0,12,21,0,0,0,0,0,0,0,21,12,0,0
0,0,16,21,21,0,0,0,0,0,21,21,16,0,0
0,0,16,0,21,21,0,10,0,21,21,0,16,0,0
0,0,16,0,0,21,21,21,21,21,0,16,16,0,0
0,0,16,16,16,16,17,16,17,16,16,16,16,0,0
0,0,0,0,0,0,0,0,0,0,0,0,0,0,0
0,0,0,0,0,0,0,0,0,0,0,0,0,0,0
endlayer

layer
0,0,0,0,0,0,0,0,0,0,0,0,0,0,0
0,0,0,0,0,0,0,0,0,0,0,0,0,0,0
0,0,0,0,0,16,17,16,17,16,0,0,0,0,0
0,0,0,13,13,21,21,21,21,21,13,13,0,0,0
0,0,0,13,21,21,0,0,0,21,21,13,0,0,0
0,0,16,21,21,23,0,0,0,23,21,21,16,0,0
0,0,12,21,0,0,0,0,0,0,0,21,12,0,0
0,0,16,21,0,0,0,0,0,0,0,21,16,0,0
0,0,12,21,0,0,0,0,0,0,0,21,12,0,0
0,0,16,21,21,23,0,0,0,23,21,21,16,0,0
0,0,0,13,21,21,0,0,0,21,21,13,0,0,0
0,0,0,13,13,21,21,21,21,21,13,13,0,0,0
0,0,0,0,0,16,17,16,17,16,0,0,0,0,0
0,0,0,0,0,0,0,0,0,0,0,0,0,0,0
0,0,0,0,0,0,0,0,0,0,0,0,0,0,0
endlayer

layer
0,0,0,0,0,0,0,0,0,0,0,0,0,0,0
0,0,0,0,0,0,0,0,0,0,0,0,0,0,0
0,0,0,0,0,16,17,0,17,16,0,0,0,0,0
0,0,0,13,13,21,21,21,21,21,13,13,0,0,0
0,0,0,13,21,21,0,0,0,21,21,13,0,0,0
0,0,16,21,21,10,0,0,0,10,21,21,16,0,0
0,0,12,21,0,0,0,0,0,0,0,21,12,0,0
0,0,0,21,0,0,0,0,0,0,0,21,0,0,0
0,0,12,21,0,0,0,0,0,0,0,21,12,0,0
0,0,16,21,21,10,0,0,0,10,21,21,16,0,0
0,0,0,13,21,21,0,0,0,21,21,13,0,0,0
0,0,0,13,13,21,21,21,21,21,13,13,0,0,0
0,0,0,0,0,16,17,0,17,16,0,0,0,0,0
0,0,0,0,0,0,0,0,0,0,0,0,0,0,0
0,0,0,0,0,0,0,0,0,0,0,0,0,0,0
endlayer

layer
0,0,0,0,0,0,0,0,0,0,0,0,0,0,0
0,0,0,0,0,0,0,0,0,0,0,0,0,0,0
0,0,0,0,0,16,17,24,17,16,0,0,0,0,0
0,0,0,13,13,21,21,21,21,21,13,13,0,0,0
0,0,0,13,21,21,0,23,0,21,21,13,0,0,0
0,0,16,21,21,0,0,0,0,0,21,21,16,0,0
0,0,12,21,0,0,0,0,0,0,0,21,12,0,0
0,0,24,21,23,0,0,0,0,0,23,21,24,0,0
0,0,12,21,0,0,0,0,0,0,0,21,12,0,0
0,0,16,21,21,0,0,0,0,0,21,21,16,0,0
0,0,0,13,21,21,0,23,0,21,21,13,0,0,0
0,0,0,13,13,21,21,21,21,21,13,13,0,0,0
0,0,0,0,0,16,17,24,17,16,0,0,0,0,0
0,0,0,0,0,0,0,0,0,0,0,0,0,0,0
0,0,0,0,0,0,0,0,0,0,0,0,0,0,0
endlayer

layer
0,0,0,0,0,0,0,0,0,0,0,0,0,0,0
0,0,0,0,0,0,0,0,0,0,0,0,0,0,0
0,0,0,0,16,16,17,24,17,16,16,0,0,0,0
0,0,0,13,13,21,21,21,21,21,13,13,0,0,0
0,0,16,13,21,21,0,10,0,21,21,13,16,0,0
0,0,16,21,21,0,0,0,0,0,21,21,16,0,0
0,0,12,21,0,0,0,0,0,0,0,21,12,0,0
0,0,24,21,10,0,0,0,0,0,10,21,24,0,0
0,0,12,21,0,0,0,0,0,0,0,21,12,0,0
0,0,16,21,21,0,0,0,0,0,21,21,16,0,0
0,0,16,13,21,21,0,10,0,21,21,13,16,0,0
0,0,0,13,13,21,21,21,21,21,13,13,0,0,0
0,0,0,0,16,16,17,24,17,16,16,0,0,0,0
0,0,0,0,0,0,0,0,0,0,0,0,0,0,0
0,0,0,0,0,0,0,0,0,0,0,0,0,0,0
endlayer

layer
0,0,0,0,0,0,0,0,0,0,0,0,0,0,0
0,0,0,0,0,0,0,24,0,0,0,0,0,0,0
0,0,0,0,16,16,17,0,17,16,16,0,0,0,0
0,0,0,13,13,21,21,21,21,21,13,13,0,0,0
0,0,16,13,21,21,0,0,0,21,21,13,16,0,0
0,0,16,21,21,23,0,0,0,23,21,21,16,0,0
0,0,12,21,0,0,0,0,0,0,0,21,12,0,0
0,24,0,21,0,0,0,0,0,0,0,21,0,24,0
0,0,12,21,0,0,0,0,0,0,0,21,12,0,0
0,0,16,21,21,23,0,0,0,23,21,21,16,0,0
0,0,16,13,21,21,0,0,0,21,21,13,16,0,0
0,0,0,13,13,21,21,21,21,21,13,13,0,0,0
0,0,0,0,16,16,17,0,17,16,16,0,0,0,0
0,0,0,0,0,0,0,24,0,0,0,0,0,0,0
0,0,0,0,0,0,0,0,0,0,0,0,0,0,0
endlayer

layer
0,0,0,0,0,0,0,0,0,0,0,0,0,0,0
0,0,0,0,0,0,18,16,19,0,0,0,0,0,0
0,0,0,0,16,16,17,0,17,16,16,0,0,0,0
0,0,0,13,13,21,21,21,21,21,13,13,0,0,0
0,0,16,13,21,21,0,0,0,21,21,13,16,0,0
0,0,16,21,21,10,0,0,0,10,21,21,16,0,0
0,20,12,21,0,0,0,0,0,0,0,21,12,20,0
0,16,0,21,0,0,0,0,0,0,0,21,0,16,0
0,22,12,21,0,0,0,0,0,0,0,21,12,22,0
0,0,16,21,21,10,0,0,0,10,21,21,16,0,0
0,0,16,13,21,21,0,0,0,21,21,13,16,0,0
0,0,0,13,13,21,21,21,21,21,13,13,0,0,0
0,0,0,0,16,16,17,0,17,16,16,0,0,0,0
0,0,0,0,0,0,18,16,19,0,0,0,0,0,0
0,0,0,0,0,0,0,0,0,0,0,0,0,0,0
endlayer

layer
0,0,0,0,0,0,0,0,0,0,0,0,0,0,0
0,0,0,0,0,16,16,16,16,16,0,0,0,0,0
0,0,0,16,16,16,17,0,17,16,16,16,0,0,0
0,0,16,13,21,21,21,21,21,21,21,13,16,0,0
0,0,16,21,21,21,0,23,0,21,21,21,16,0,0
0,16,16,21,21,0,0,0,0,0,21,21,16,16,0
0,16,12,21,0,0,0,0,0,0,0,21,12,16,0
0,16,0,21,23,0,0,0,0,0,23,21,0,16,0
0,16,12,21,0,0,0,0,0,0,0,21,12,16,0
0,16,16,21,21,0,0,0,0,0,21,21,16,16,0
0,0,16,21,21,21,0,23,0,21,21,21,16,0,0
0,0,16,13,21,21,21,21,21,21,21,13,16,0,0
0,0,0,16,16,16,17,0,17,16,16,16,0,0,0
0,0,0,0,0,16,16,16,16,16,0,0,0,0,0
0,0,0,0,0,0,0,0,0,0,0,0,0,0,0
endlayer

layer
0,0,0,0,0,0,0,0,0,0,0,0,0,0,0
0,0,0,0,16,0,0,0,0,0,16,0,0,0,0
0,0,0,16,16,16,12,0,12,16,16,16,0,0,0
0,0,16,13,21,21,21,21,21,21,21,13,16,0,0
0,16,16,21,21,0,0,10,0,0,21,21,16,16,0
0,0,16,21,0,0,0,0,0,0,0,21,16,0,0
0,0,12,21,0,0,0,0,0,0,0,21,12,0,0
0,0,0,21,10,0,0,0,0,0,10,21,0,0,0
0,0,12,21,0,0,0,0,0,0,0,21,12,0,0
0,0,16,21,0,0,0,0,0,0,0,21,16,0,0
0,16,16,21,21,0,0,10,0,0,21,21,16,16,0
0,0,16,13,21,21,21,21,21,21,21,13,16,0,0
0,0,0,16,16,16,17,0,17,16,16,16,0,0,0
0,0,0,0,16,0,0,0,0,0,16,0,0,0,0
0,0,0,0,0,0,0,0,0,0,0,0,0,0,0
endlayer

layer
0,0,0,0,0,0,0,0,0,0,0,0,0,0,0
0,0,0,18,0,16,24,24,24,16,0,19,0,0,0
0,0,16,16,16,18,12,0,12,19,16,16,16,0,0
0,20,20,21,21,21,21,21,21,21,21,21,0,20,0
0,0,16,21,23,0,0,0,0,0,23,21,16,0,0
0,16,22,21,0,0,0,0,0,0,0,21,22,16,0
0,24,12,21,0,0,0,0,0,0,0,21,12,24,0
0,24,0,21,0,0,0,0,0,0,0,21,0,24,0
0,24,12,21,0,0,0,0,0,0,0,21,12,24,0
0,16,20,21,0,0,0,0,0,0,0,21,20,16,0
0,0,16,21,23,0,0,0,0,0,23,21,16,0,0
0,22,22,21,21,21,21,21,21,21,21,21,0,22,0
0,0,16,16,16,16,17,0,17,16,16,16,16,0,0
0,0,0,18,0,16,24,24,24,16,0,19,0,0,0
0,0,0,0,0,0,0,0,0,0,0,0,0,0,0
endlayer

layer
0,0,0,0,0,0,0,0,0,0,0,0,0,0,0
0,0,0,25,0,16,16,0,16,16,0,25,0,0,0
0,0,16,27,0,19,0,24,0,18,0,26,16,0,0
0,26,28,21,21,21,21,21,21,21,21,21,28,27,0
0,0,0,21,10,0,0,0,0,0,10,21,0,0,0
0,16,22,21,0,0,0,0,0,0,0,21,22,16,0
0,16,0,21,0,0,0,0,0,0,0,21,0,16,0
0,0,24,21,0,0,0,0,0,0,0,21,24,0,0
0,16,0,21,0,0,0,0,0,0,0,21,0,16,0
0,16,20,21,0,0,0,0,0,0,0,21,20,16,0
0,0,0,21,10,0,0,23,0,0,10,21,0,0,0
0,26,25,21,21,21,21,21,21,21,21,21,25,27,0
0,0,16,27,0,19,0,24,0,18,0,26,16,0,0
0,0,0,28,0,16,16,0,16,16,0,28,0,0,0
0,0,0,0,0,0,0,0,0,0,0,0,0,0,0
endlayer

layer
0,0,0,0,0,0,0,0,0,0,0,0,0,0,0
0,0,0,16,12,16,27,24,26,16,12,16,0,0,0
0,0,16,19,16,0,0,0,0,0,16,18,16,0,0
0,16,22,21,21,21,21,21,21,21,21,21,22,16,0
0,12,17,21,0,0,0,23,0,0,0,21,12,12,0
0,16,0,21,0,0,0,0,0,0,0,21,0,16,0
0,28,0,21,0,0,0,0,0,0,0,21,0,24,0
0,24,0,21,23,0,0,0,0,0,23,21,0,24,0
0,25,0,21,0,0,0,0,0,0,0,21,0,24,0
0,16,0,21,0,0,0,0,0,0,0,21,0,16,0
0,12,12,21,0,0,0,10,0,0,0,21,17,12,0
0,16,20,21,21,21,21,21,21,21,21,21,20,16,0
0,0,16,19,16,0,0,0,0,0,12,18,16,0,0
0,0,0,16,17,16,27,24,26,16,12,16,0,0,0
0,0,0,0,0,0,0,0,0,0,0,0,0,0,0
endlayer

layer
0,0,0,0,0,0,0,0,0,0,0,0,0,0,0
0,0,0,0,16,16,24,12,24,16,16,0,0,0,0
0,0,0,16,16,16,0,0,0,16,16,16,0,0,0
0,0,16,21,21,21,21,21,21,21,21,21,16,0,0
0,16,0,21,0,0,0,10,0,0,0,21,0,16,0
0,20,0,21,0,0,0,0,0,0,0,21,0,20,0
0,24,0,21,0,0,0,0,0,0,0,21,0,24,0
0,12,0,21,10,0,0,0,0,0,10,21,0,12,0
0,24,0,21,0,0,0,0,0,0,0,21,0,24,0
0,22,0,21,0,0,0,0,0,0,0,21,0,22,0
0,16,0,21,0,0,0,0,0,0,0,21,0,16,0
0,0,16,21,21,21,21,21,21,21,21,21,16,0,0
0,0,0,16,16,16,0,0,0,16,16,16,0,0,0
0,0,0,0,16,18,24,17,24,19,16,0,0,0,0
0,0,0,0,0,0,0,0,0,0,0,0,0,0,0
endlayer

layer
0,0,0,0,0,0,0,0,0,0,0,0,0,0,0
0,0,18,16,18,0,27,0,26,0,19,16,19,0,0
0,20,19,0,16,0,0,0,0,0,16,0,18,20,0
0,16,0,21,21,21,21,21,21,21,21,21,0,16,0
0,20,16,21,23,0,0,0,0,0,23,21,16,20,0
0,0,0,21,0,0,0,0,0,0,0,21,0,0,0
0,28,0,21,0,0,0,0,0,0,0,21,0,28,0
0,0,0,21,0,0,0,0,0,0,0,21,0,0,0
0,25,0,21,0,0,0,0,0,0,0,21,0,25,0
0,0,0,21,0,0,0,0,0,0,0,21,0,0,0
0,22,16,21,23,0,0,0,0,0,23,21,16,22,0
0,16,0,21,21,21,21,21,21,21,21,21,0,16,0
0,22,12,0,16,0,0,0,0,0,16,0,12,22,0
0,0,18,16,18,0,27,0,26,0,19,16,19,0,0
0,0,0,0,0,0,0,0,0,0,0,0,0,0,0
endlayer

layer
0,0,0,0,0,0,0,0,0,0,0,0,0,0,0
0,0,16,16,16,24,19,16,18,24,16,16,16,0,0
0,16,19,16,0,0,0,0,0,0,0,0,18,16,0
0,16,0,21,21,21,21,21,21,21,21,21,0,16,0
0,16,0,21,10,0,0,0,0,0,10,21,0,16,0
0,24,0,21,0,0,0,0,0,0,0,21,0,24,0
0,22,0,21,0,0,0,0,0,0,0,21,0,22,0
0,16,0,21,0,0,0,0,0,0,0,21,0,16,0
0,20,0,21,0,0,0,0,0,0,0,21,0,20,0
0,24,0,21,0,0,0,0,0,0,0,21,0,24,0
0,16,0,21,10,0,0,0,0,0,10,21,0,16,0
0,16,0,21,21,21,21,21,21,21,21,21,0,16,0
0,16,19,0,0,0,0,0,0,0,0,0,0,16,0
0,0,16,16,16,24,19,16,18,24,16,16,16,0,0
0,0,0,0,0,0,0,0,0,0,0,0,0,0,0
endlayer

layer
0,0,0,0,0,0,0,0,0,0,0,0,0,0,0
0,0,20,0,19,0,18,0,19,0,18,0,20,0,0
0,18,16,19,16,0,21,0,21,0,16,18,16,19,0
0,0,0,21,16,21,21,21,21,21,16,21,22,0,0
0,22,16,16,16,16,0,0,0,16,16,16,16,22,0
0,0,0,21,16,0,0,0,0,0,16,21,0,0,0
0,20,0,21,0,0,0,0,0,0,0,21,0,20,0
0,0,0,21,0,0,0,0,0,0,0,21,0,0,0
0,22,0,21,0,0,0,0,0,0,0,21,0,22,0
0,0,0,21,16,0,0,0,0,0,16,21,0,21,0
0,20,16,16,16,16,0,0,0,16,16,16,16,20,0
0,0,0,21,16,21,21,21,21,21,16,21,22,0,0
0,18,0,18,16,0,21,0,21,0,16,19,0,19,0
0,0,22,0,19,0,18,0,19,0,18,0,22,0,0
0,0,0,0,0,0,0,0,0,0,0,0,0,0,0
endlayer

layer
0,0,0,0,0,0,0,0,0,0,0,0,0,0,0
0,0,12,0,26,16,19,0,18,16,27,0,12,0,0
0,12,16,18,0,16,0,16,0,16,0,19,16,17,0
0,0,20,0,0,17,24,24,24,17,0,0,20,0,0
0,25,0,0,0,10,0,17,0,10,0,0,0,25,0
0,16,16,12,10,17,24,24,24,17,10,12,16,16,0
0,22,0,24,0,24,0,0,0,24,0,24,0,22,0
0,0,0,24,12,24,0,0,0,24,12,24,0,0,0
0,20,0,24,0,24,0,0,0,24,0,24,0,20,0
0,16,16,12,10,17,24,24,24,17,10,12,16,16,0
0,28,0,17,0,10,0,17,0,10,0,0,0,28,0
0,0,22,0,0,17,24,24,24,17,0,0,22,0,0
0,12,16,18,0,16,0,16,0,16,0,19,22,17,0
0,0,12,0,26,16,19,0,18,16,27,0,12,0,0
0,0,0,0,0,0,0,0,0,0,0,0,0,0,0
endlayer

layer
0,0,0,0,0,0,0,0,0,0,0,0,0,0,0
0,0,0,0,18,0,12,16,12,0,19,0,0,0,0
0,0,24,0,0,0,0,24,0,0,0,0,24,0,0
0,0,0,0,0,17,0,0,0,17,0,0,0,0,0
0,20,0,0,0,24,0,17,0,24,0,0,0,20,0
0,0,0,12,24,17,0,0,0,17,24,12,0,0,0
0,12,0,0,0,0,0,0,0,0,0,0,0,12,0
0,16,0,0,12,0,0,0,0,0,12,0,0,16,0
0,12,0,0,0,0,0,0,0,0,0,0,0,12,0
0,0,0,12,24,17,0,0,0,17,24,12,0,0,0
0,22,0,0,0,24,0,17,0,24,0,0,0,22,0
0,0,0,0,0,17,0,0,0,17,0,0,0,0,0
0,0,24,0,0,0,0,24,0,0,0,0,24,0,0
0,0,0,0,18,0,17,16,17,0,19,0,0,0,0
0,0,0,0,0,0,0,0,0,0,0,0,0,0,0
endlayer

layer
0,0,0,0,0,0,0,0,0,0,0,0,0,0,0
0,0,0,0,24,0,17,0,17,0,24,0,0,0,0
0,0,0,0,0,0,0,0,0,0,0,0,0,0,0
0,0,0,0,0,0,0,0,0,0,0,0,0,0,0
0,24,0,0,0,0,0,24,0,0,0,0,0,24,0
0,0,0,0,0,0,0,0,0,0,0,0,0,0,0
0,12,0,0,0,0,0,0,0,0,0,0,0,12,0
0,0,0,0,24,0,0,0,0,0,24,0,0,0,0
0,12,0,0,0,0,0,0,0,0,0,0,0,12,0
0,0,0,0,0,0,0,0,0,0,0,0,0,0,0
0,24,0,0,0,0,0,24,0,0,0,0,0,24,0
0,0,0,0,0,0,0,0,0,0,0,0,0,0,0
0,0,0,0,0,0,0,0,0,0,0,0,0,0,0
0,0,0,0,24,0,17,0,17,0,24,0,0,0,0
0,0,0,0,0,0,0,0,0,0,0,0,0,0,0
endlayer

layer
0,0,0,0,0,0,0,0,0,0,0,0,0,0,0
0,0,0,0,0,0,24,0,24,0,0,0,0,0,0
0,0,0,0,0,0,0,0,0,0,0,0,0,0,0
0,0,0,0,0,0,0,0,0,0,0,0,0,0,0
0,0,0,0,0,0,0,0,0,0,0,0,0,0,0
0,0,0,0,0,0,0,0,0,0,0,0,0,0,0
0,24,0,0,0,0,0,0,0,0,0,0,0,24,0
0,0,0,0,0,0,0,0,0,0,0,0,0,0,0
0,24,0,0,0,0,0,0,0,0,0,0,0,24,0
0,0,0,0,0,0,0,0,0,0,0,0,0,0,0
0,0,0,0,0,0,0,0,0,0,0,0,0,0,0
0,0,0,0,0,0,0,0,0,0,0,0,0,0,0
0,0,0,0,0,0,0,0,0,0,0,0,0,0,0
0,0,0,0,0,0,24,0,24,0,0,0,0,0,0
0,0,0,0,0,0,0,0,0,0,0,0,0,0,0
endlayer

