
# Created by Ruins mod version 16.7 Ingame Parser
# authoring Player: lafuller

weight=1
embed_into_distance=4
acceptable_target_blocks=
unacceptable_target_blocks=flowing_water,water,flowing_lava,lava,ice,bedrock,netherrack,nether_brick,nether_brick_fence,soul_sand,quartz_ore,gravel,end_stone,obsidian,iron_bars,cloud,flesh,ash_block,slime_grass,slime_congealed,slime_dirt
biomesToSpawnIn=plains,prarie,meadow
dimensions=14,18,13
allowable_overhang=0
max_leveling=4
leveling_buffer=-1
preserve_water=0
preserve_lava=0

rule1=0,100,preserveBlock
rule2=0,100,stonebrick-0,stonebrick-0,stonebrick-0,stonebrick-1,stonebrick-2,stonebrick-2,stone-5,stone-6,cobblestone
rule3=0,100,minecraft:stained_hardened_clay-8
rule4=0,100,minecraft:hardened_clay-0
rule5=0,100,minecraft:stone_brick_stairs-0
rule6=0,100,stonebrick-0,stonebrick-0,stonebrick-0,stonebrick-0,stonebrick-1,stonebrick-2,stonebrick-2,stone-5,stone-6,cobblestone,gravel
rule7=0,100,minecraft:dirt-0
rule8=0,100,minecraft:stone_brick_stairs-1
rule9=0,100,minecraft:stone_brick_stairs-3
rule10=0,100,minecraft:cobblestone_wall-0
rule11=0,100,minecraft:log-0
rule12=0,100,minecraft:trapdoor-11
rule13=0,100,minecraft:ladder-5
rule14=0,100,minecraft:wooden_slab-9
rule15=0,100,web,air,air,air,air
rule16=0,100,minecraft:stone_brick_stairs-2
rule17=0,100,minecraft:grass-0
rule18=0,100,minecraft:stone_brick_stairs-6
rule19=0,100,minecraft:planks-1
rule20=0,100,minecraft:planks-0
rule21=0,100,minecraft:oak_stairs-0
rule22=0,100,minecraft:spruce_stairs-0
rule23=0,100,minecraft:fence-0
rule24=0,100,minecraft:stone_brick_stairs-5
rule25=0,100,minecraft:birch_stairs-0
rule26=0,100,minecraft:planks-2
rule27=0,100,minecraft:birch_stairs-1
rule28=0,100,minecraft:birch_stairs-4
rule29=0,100,minecraft:birch_stairs-6
rule30=0,100,minecraft:birch_stairs-7
rule31=0,100,minecraft:birch_stairs-3
rule32=0,100,minecraft:cauldron-0
rule33=0,100,minecraft:birch_stairs-2
rule34=0,100,ChestGenHook:chests/spawn_bonus_chest:5-3
rule35=0,100,ChestGenHook:chests/stronghold_library:5-3
rule36=0,100,minecraft:crafting_table-0
rule37=0,100,minecraft:birch_stairs-5
rule38=0,100,minecraft:stone-4
rule39=0,100,minecraft:trapdoor-10
rule40=0,100,minecraft:birch_door-2
rule41=0,100,minecraft:stone_brick_stairs-7
rule42=0,100,minecraft:spruce_fence_gate-1
rule43=0,100,minecraft:carpet-8
rule44=0,100,minecraft:spruce_fence_gate-2
rule45=0,100,IInventory;furnace;coal#2#0#1-5
rule46=0,100,minecraft:spruce_fence_gate-0
rule47=0,100,minecraft:birch_door-9
rule48=0,100,minecraft:birch_door-8
rule49=0,100,minecraft:spruce_fence_gate-3
rule50=0,100,minecraft:oak_stairs-3
rule51=0,100,minecraft:oak_stairs-2
rule52=0,100,minecraft:oak_stairs-5
rule53=0,100,minecraft:fence_gate-0
rule54=0,100,minecraft:fence_gate-1
rule55=0,100,minecraft:spruce_stairs-6
rule56=0,100,minecraft:spruce_stairs-7
rule57=0,100,minecraft:carpet-7
rule58=0,100,minecraft:spruce_stairs-4
rule59=0,100,minecraft:spruce_fence-0
rule60=0,100,minecraft:dark_oak_stairs-6
rule61=0,100,minecraft:spruce_stairs-5
rule62=0,100,minecraft:double_wooden_slab-1
rule63=0,100,minecraft:spruce_stairs-2
rule64=0,100,minecraft:wooden_slab-1
rule65=0,100,minecraft:spruce_stairs-1
rule66=0,100,minecraft:fence_gate-2
rule67=0,100,minecraft:fence_gate-3
rule68=0,100,minecraft:wooden_slab-5
rule69=0,100,minecraft:dark_oak_stairs-4
rule70=0,100,minecraft:planks-5
rule71=0,100,minecraft:dark_oak_stairs-7
rule72=0,100,minecraft:dark_oak_stairs-2
rule73=0,100,minecraft:wooden_slab-13
rule74=0,100,minecraft:dark_oak_stairs-5
rule75=0,100,minecraft:spruce_stairs-3
rule76=0,100,minecraft:dark_oak_stairs-1
rule77=0,100,minecraft:trapdoor-3
rule78=0,100,minecraft:dark_oak_stairs-0
rule79=0,100,minecraft:dark_oak_stairs-3
rule80=0,100,minecraft:double_wooden_slab-5

layer
1,1,1,1,1,1,1,1,1,1,1,1,1
1,1,1,1,2,2,2,2,2,1,1,1,1
1,1,2,2,3,3,3,3,3,2,1,1,1
1,1,2,3,3,4,4,4,3,2,1,1,1
1,2,3,3,4,4,3,4,3,2,1,1,1
1,2,3,4,3,3,3,4,3,2,2,1,1
1,2,3,4,3,3,3,4,3,3,3,2,1
1,2,3,4,3,4,4,3,4,4,3,2,1
5,2,3,4,4,4,3,4,3,4,3,2,5
6,2,3,3,3,3,3,4,4,4,3,2,6
6,2,2,2,2,2,3,3,3,3,3,2,6
6,2,2,7,7,7,2,2,2,2,2,2,6
6,2,2,7,7,7,7,7,7,7,2,2,6
6,2,2,7,7,7,7,7,7,7,2,2,6
6,2,2,7,7,7,7,7,7,7,2,2,6
6,2,2,2,2,2,2,2,2,2,2,2,6
6,2,2,2,2,2,2,2,2,2,2,2,6
8,8,1,1,1,1,1,1,1,1,9,8,8
endlayer

layer
1,1,1,1,1,1,1,1,1,1,1,1,1
1,1,1,1,6,10,6,10,6,1,1,1,1
1,1,6,6,11,12,12,12,11,6,1,1,1
1,1,6,13,13,0,0,0,0,10,1,1,1
1,6,11,0,0,0,0,0,0,6,1,1,1
1,10,0,0,0,0,0,0,0,6,6,1,1
1,6,0,0,0,0,0,0,0,0,11,6,1
1,10,0,0,0,0,0,0,0,0,0,10,1
1,6,0,0,0,0,0,0,0,0,0,6,1
5,6,11,0,0,0,0,0,0,0,0,6,5
6,6,6,6,6,6,11,14,14,14,11,6,6
6,6,6,7,7,7,6,6,6,6,6,6,6
6,6,6,7,7,7,7,7,7,7,6,6,6
6,6,6,7,7,7,7,7,7,7,6,6,6
6,6,6,7,7,7,7,7,7,7,6,6,6
6,6,6,6,6,6,6,6,6,6,6,6,6
8,8,6,6,6,6,6,6,6,6,6,8,8
1,1,1,1,1,1,1,1,1,1,1,1,1
endlayer

layer
1,1,1,1,1,1,1,1,1,1,1,1,1
1,1,1,1,6,10,6,10,6,1,1,1,1
1,1,6,6,11,15,0,15,11,6,1,1,1
1,1,6,13,13,0,0,0,15,10,1,1,1
1,6,11,0,0,0,0,0,0,6,1,1,1
1,10,15,0,0,0,0,0,0,6,6,1,1
1,6,0,0,0,0,0,0,0,0,11,6,1
1,10,0,0,0,0,0,0,0,0,15,10,1
1,6,15,0,0,0,0,0,0,0,0,6,1
1,6,11,15,0,0,0,0,0,0,15,10,1
5,6,6,6,6,6,11,15,0,15,11,6,5
9,6,6,7,7,7,6,6,6,6,6,6,16
9,6,6,7,7,7,7,7,7,7,6,6,16
9,6,6,7,7,7,7,7,7,7,6,6,16
9,6,6,7,7,7,7,7,7,7,6,6,16
9,8,6,6,6,6,6,6,6,6,6,8,8
1,1,6,10,10,10,6,10,10,10,10,1,1
1,1,1,1,1,1,1,1,1,1,1,1,1
endlayer

layer
1,1,1,1,1,1,1,1,1,1,1,1,1
1,1,1,1,6,10,6,10,6,1,1,1,1
1,1,6,6,11,15,15,15,11,6,1,1,1
1,1,6,13,13,0,0,15,15,10,1,1,1
1,6,11,0,0,0,0,0,15,6,1,1,1
1,10,15,0,0,0,0,0,0,6,6,1,1
1,6,15,0,0,0,0,0,0,15,11,6,1
1,10,15,0,0,0,0,0,0,0,15,10,1
1,6,15,15,0,0,0,0,0,0,15,6,1
1,6,11,15,15,0,0,0,0,15,15,10,1
1,6,6,6,6,6,11,15,15,15,11,6,1
1,9,6,7,7,7,6,6,6,6,6,16,1
1,9,6,7,7,7,7,17,17,17,6,16,1
1,9,6,7,7,7,7,17,17,17,6,16,1
1,8,6,7,7,7,7,17,17,17,6,8,1
1,1,6,6,6,6,6,17,17,17,18,1,1
1,1,6,8,8,8,6,8,8,8,18,1,1
1,1,1,1,1,1,1,1,1,1,1,1,1
endlayer

layer
1,1,1,1,1,1,1,1,1,1,1,1,1
1,1,1,1,6,6,6,6,6,1,1,1,1
1,1,6,6,11,19,19,19,19,6,1,1,1
1,1,6,13,13,20,20,20,19,6,1,1,1
1,6,20,22,21,20,19,20,19,6,1,1,1
1,6,19,20,19,19,19,20,19,6,6,1,1
1,6,19,20,19,19,19,20,19,19,19,6,1
1,6,19,20,19,20,20,19,20,20,19,6,1
1,6,19,20,20,20,19,20,19,20,19,6,1
1,6,19,19,19,19,19,20,20,20,19,6,1
1,23,6,6,6,6,19,19,19,19,19,6,1
1,1,9,17,17,17,6,6,6,6,6,23,1
1,1,9,17,17,17,16,0,0,0,0,1,1
1,1,9,17,17,17,16,0,0,0,0,1,1
1,1,9,17,17,17,16,0,0,0,0,1,1
1,1,6,17,17,17,6,0,0,0,18,1,1
1,1,6,24,24,24,6,24,24,24,6,1,1
1,1,1,1,1,1,1,1,1,1,1,1,1
endlayer

layer
1,1,1,1,0,0,0,0,0,1,1,1,1
1,1,1,0,28,26,27,26,25,0,1,1,1
1,1,30,26,11,0,0,0,11,29,0,1,1
1,0,26,13,13,0,23,23,0,26,0,0,1
0,26,11,0,0,0,23,23,0,31,0,0,1
0,26,0,0,0,0,0,0,0,26,26,0,0
0,33,0,0,0,0,0,0,0,32,11,29,0
0,33,0,0,0,0,0,0,0,0,34,26,0
0,26,0,0,0,0,0,0,0,0,35,31,0
0,37,11,0,0,0,0,0,0,0,36,26,0
0,23,26,40,40,26,11,38,39,38,11,37,0
0,0,0,0,0,0,31,26,25,26,27,23,0
0,0,0,0,0,0,0,0,0,0,0,0,0
0,0,0,0,0,0,0,0,0,0,0,0,0
1,0,0,0,0,0,0,0,0,0,0,0,1
1,1,41,0,0,0,18,0,0,0,23,1,1
1,1,6,24,24,24,6,0,0,0,1,1,1
1,1,1,1,1,1,1,1,1,1,1,1,1
endlayer

layer
1,1,1,0,0,0,0,0,0,0,1,1,1
1,1,0,0,26,26,42,26,26,0,0,1,1
1,0,26,26,11,0,0,0,11,26,0,0,1
0,0,26,13,13,0,43,43,0,26,0,0,0
0,26,11,0,0,0,43,43,0,44,0,0,0
0,26,0,0,0,0,0,0,0,26,26,0,0
0,46,0,0,0,0,0,0,0,45,11,26,0
0,46,0,0,0,0,0,0,0,0,0,26,0
0,26,0,0,0,0,0,0,0,0,0,44,0
0,26,11,0,0,0,0,0,0,0,0,26,0
0,23,26,48,47,26,11,0,0,0,11,26,0
0,0,0,0,0,0,26,26,49,26,26,23,0
0,0,0,0,0,0,0,0,0,0,0,0,0
0,0,0,0,0,0,0,0,0,0,0,0,0
0,0,0,0,0,0,0,0,0,0,0,0,0
1,0,23,0,0,0,23,0,0,0,23,0,1
1,1,23,0,0,0,23,0,0,0,0,1,1
1,1,1,0,0,0,0,0,0,0,1,1,1
endlayer

layer
1,1,0,0,0,0,0,0,0,0,0,1,1
1,0,0,0,26,26,23,26,26,0,0,0,1
0,0,26,26,11,0,0,0,11,26,0,0,0
0,0,26,13,13,0,0,0,0,26,0,0,0
0,26,11,0,0,0,0,0,0,23,0,0,0
0,26,0,0,0,0,0,0,0,26,26,0,0
0,23,0,0,0,0,0,0,0,10,11,26,0
0,23,0,0,0,0,0,0,0,0,0,26,0
0,26,0,0,0,0,0,0,0,0,0,23,0
0,26,11,0,0,0,0,0,0,0,0,26,0
0,23,26,23,23,26,11,0,0,0,11,26,0
0,0,0,0,0,0,26,26,23,26,26,23,0
0,0,0,0,0,0,0,0,0,0,0,0,0
0,0,0,0,0,0,0,0,0,0,0,0,0
0,0,0,0,0,0,0,0,0,0,0,0,0
0,0,23,0,0,0,23,0,0,0,23,0,0
1,0,23,0,0,0,23,0,0,0,0,0,1
1,1,0,0,0,0,0,0,0,0,0,1,1
endlayer

layer
1,0,0,0,0,0,0,0,0,0,0,0,1
0,0,0,0,50,20,20,20,21,0,0,0,0
0,0,50,20,11,14,14,14,11,51,0,0,0
0,0,20,13,13,14,14,14,14,26,0,0,0
0,20,11,14,14,14,14,14,14,26,0,0,0
0,20,0,0,0,0,0,0,0,26,26,0,0
0,26,0,0,0,0,0,0,0,10,11,29,0
0,26,0,0,0,0,0,0,0,0,0,26,0
0,26,0,0,0,0,0,0,0,0,0,26,0
0,26,11,0,0,0,0,0,0,0,0,20,0
0,23,26,26,26,26,11,0,0,0,11,52,0
0,0,0,0,0,0,26,26,26,20,51,23,0
0,0,0,0,0,0,0,0,0,0,53,0,0
0,0,0,0,0,0,0,0,0,0,53,0,0
0,0,0,0,0,0,0,0,0,0,53,0,0
0,0,23,0,0,0,23,54,54,54,23,0,0
0,0,23,0,0,0,23,0,0,0,0,0,0
1,0,0,0,0,0,0,0,0,0,0,0,1
endlayer

layer
0,0,0,0,0,0,0,0,0,0,0,0,0
0,0,0,56,20,20,19,19,55,0,0,0,0
0,0,19,20,11,57,57,43,11,55,0,0,0
0,56,20,13,13,57,57,43,0,20,14,0,0
0,56,11,59,59,59,59,59,59,20,58,0,0
56,20,0,0,0,0,0,0,0,20,20,60,0
61,20,0,0,0,0,0,0,0,10,11,55,0
61,20,0,0,0,0,0,0,0,0,0,19,60
0,20,0,0,0,0,0,0,0,0,0,19,14
0,20,11,0,0,0,0,0,0,0,0,19,14
0,62,20,20,20,20,11,0,0,0,11,19,0
0,14,53,0,0,0,20,19,19,19,19,63,0
0,14,53,0,0,0,66,56,62,63,65,64,0
0,14,66,0,0,0,66,56,62,64,64,64,0
0,14,53,0,0,0,66,56,64,64,64,64,0
0,14,23,0,0,0,23,56,64,64,64,0,0
0,0,23,67,67,54,23,65,64,0,0,0,0
0,0,0,0,0,0,0,0,0,0,0,0,0
endlayer

layer
0,0,0,0,68,68,68,68,0,0,0,0,0
0,0,69,70,71,70,69,70,69,68,0,0,0
0,56,19,19,19,0,0,0,19,70,68,0,0
73,19,19,0,0,0,0,0,56,19,72,72,0
73,19,19,0,0,0,0,0,56,19,60,60,0
71,19,0,0,0,0,0,0,61,19,19,60,0
71,19,0,0,0,0,0,0,0,10,19,60,0
71,19,0,0,0,0,0,0,0,0,56,70,60
73,19,55,0,0,0,0,0,0,0,56,19,74
73,19,19,58,58,55,0,0,0,0,56,19,0
0,75,19,19,19,19,19,58,58,58,19,72,0
0,0,62,62,62,62,62,19,72,76,76,0,0
0,0,64,65,62,62,65,64,0,0,0,0,0
0,0,64,64,77,64,64,64,0,0,0,0,0
0,0,64,64,64,64,64,0,0,0,0,0,0
0,0,64,64,64,64,64,0,0,0,0,0,0
0,0,64,64,64,64,64,0,0,0,0,0,0
0,0,0,0,0,0,0,0,0,0,0,0,0
endlayer

layer
0,0,0,0,0,0,0,0,0,0,0,0,0
0,0,0,68,78,78,78,68,0,0,0,0,0
0,68,68,70,70,70,70,78,78,0,0,0,0
0,79,70,73,73,73,73,73,69,78,68,0,0
68,79,70,0,0,0,0,0,80,69,68,0,0
78,80,60,0,0,0,0,0,80,69,72,0,0
79,70,60,0,0,0,0,0,73,70,60,72,0
79,79,60,0,0,0,0,0,0,73,60,60,72
0,79,70,0,0,0,0,0,0,73,60,60,72
0,79,71,71,74,74,69,73,73,73,60,72,0
0,0,76,76,73,74,80,72,76,76,68,0,0
0,0,0,68,68,68,68,0,0,0,0,0,0
0,0,0,0,0,0,0,0,0,0,0,0,0
0,0,0,0,0,0,0,0,0,0,0,0,0
0,0,0,0,0,0,0,0,0,0,0,0,0
0,0,0,0,0,0,0,0,0,0,0,0,0
0,0,0,0,0,0,0,0,0,0,0,0,0
0,0,0,0,0,0,0,0,0,0,0,0,0
endlayer

layer
0,0,0,0,0,0,0,0,0,0,0,0,0
0,0,0,0,0,0,0,0,0,0,0,0,0
0,0,0,0,0,0,0,0,0,0,0,0,0
0,0,0,68,78,68,0,0,0,0,0,0,0
0,0,68,74,74,74,78,68,0,0,0,0,0
0,0,79,73,73,73,71,80,68,0,0,0,0
0,68,79,73,39,73,71,80,68,10,0,0,0
0,0,68,73,73,73,71,80,80,68,0,0,0
0,0,68,79,69,69,69,80,68,68,0,0,0
0,0,0,68,76,76,76,68,68,0,0,0,0
0,0,0,0,0,0,0,0,0,0,0,0,0
0,0,0,0,0,0,0,0,0,0,0,0,0
0,0,0,0,0,0,0,0,0,0,0,0,0
0,0,0,0,0,0,0,0,0,0,0,0,0
0,0,0,0,0,0,0,0,0,0,0,0,0
0,0,0,0,0,0,0,0,0,0,0,0,0
0,0,0,0,0,0,0,0,0,0,0,0,0
0,0,0,0,0,0,0,0,0,0,0,0,0
endlayer

layer
0,0,0,0,0,0,0,0,0,0,0,0,0
0,0,0,0,0,0,0,0,0,0,0,0,0
0,0,0,0,0,0,0,0,0,0,0,0,0
0,0,0,0,0,0,0,0,0,0,0,0,0
0,0,0,0,0,0,0,0,0,0,0,0,0
0,0,0,0,0,0,0,0,0,0,0,0,0
0,0,0,0,0,0,0,0,0,10,0,0,0
0,0,0,0,0,0,0,0,0,0,0,0,0
0,0,0,0,0,0,0,0,0,0,0,0,0
0,0,0,0,0,0,0,0,0,0,0,0,0
0,0,0,0,0,0,0,0,0,0,0,0,0
0,0,0,0,0,0,0,0,0,0,0,0,0
0,0,0,0,0,0,0,0,0,0,0,0,0
0,0,0,0,0,0,0,0,0,0,0,0,0
0,0,0,0,0,0,0,0,0,0,0,0,0
0,0,0,0,0,0,0,0,0,0,0,0,0
0,0,0,0,0,0,0,0,0,0,0,0,0
0,0,0,0,0,0,0,0,0,0,0,0,0
endlayer

