
# Created by Ruins mod version 16.7 Ingame Parser
# authoring Player: lafuller

weight=1
embed_into_distance=4
acceptable_target_blocks=
unacceptable_target_blocks=flowing_water,water,flowing_lava,lava,ice,bedrock,netherrack,nether_brick,nether_brick_fence,soul_sand,quartz_ore,gravel,end_stone,obsidian,iron_bars,cloud,flesh,ash_block,slime_grass,slime_congealed,slime_dirt
biomesToSpawnIn=plains,forest,prarie,meadow,tundra,brushland,shrubland,woodland,woodlands,birch_forest,lavender_fields,flower_field,sunflower_plains,ice_flats,ice_plains
dimensions=17,14,14
allowable_overhang=0
max_leveling=4
leveling_buffer=-1
preserve_water=0
preserve_lava=0

rule1=0,100,air
rule2=0,100,preserveBlock
rule3=0,100,minecraft:stone_brick_stairs-2
rule4=0,100,minecraft:stone-6
rule5=0,100,stonebrick-0,stonebrick-1,stonebrick-1,stonebrick-1,stonebrick-2,stonebrick-2,stone-5,stone-5,stone-6,cobblestone,cobblestone
rule6=0,100,stonebrick-0,stonebrick-2,stonebrick-1,stonebrick-1,stonebrick-1,cobblestone
rule7=0,100,stonebrick-0,stonebrick-1,stonebrick-2,stonebrick-2,stone-5,stone-5,stone-6,stone-6
rule8=0,100,stonebrick-0,stonebrick-2,stonebrick-0,stonebrick-1,stonebrick-1,cobblestone
rule9=0,100,minecraft:stone-5
rule10=0,100,minecraft:cobblestone_wall-0
rule11=0,100,minecraft:stone_stairs-7
rule12=0,100,minecraft:log-0
rule13=0,100,minecraft:wooden_slab-9
rule14=0,100,web-0,air,air,air
rule15=0,100,minecraft:spruce_stairs-0
rule16=0,100,minecraft:spruce_stairs-7
rule17=0,100,bookshelf,hay_block,ChestGenHook:chests/spawn_bonus_chest:5-4,ChestGenHook:chests/village_blacksmith:4-4,ChestGenHook:chests/simple_dungeon:5-4,ChestGenHook:chests/abandoned_mineshaft:4-4,ChestGenHook:chests/stronghold_library:3-4,ChestGenHook:chests/stronghold_corridor:2-4,ChestGenHook:chests/stronghold_crossing:2-3,ChestGenHook:chests/igloo_chest:4-4
rule18=0,100,minecraft:stone_stairs-5
rule19=0,100,minecraft:stone_brick_stairs-0
rule20=0,100,minecraft:stone_stairs-4
rule21=0,100,minecraft:spruce_stairs-2
rule22=0,100,minecraft:spruce_stairs-4
rule23=0,100,minecraft:stone_brick_stairs-1
rule24=0,100,magma-0,mycelium-0
rule25=0,100,stonebrick-0,stonebrick-1,stonebrick-1,stonebrick-1,stonebrick-2,stonebrick-2,stone-5,stone-5,stone-6,cobblestone,cobblestone,gravel
rule26=0,100,minecraft:planks-1
rule27=0,100,minecraft:planks-0
rule28=0,100,minecraft:oak_stairs-5
rule29=0,100,minecraft:spruce_stairs-1
rule30=0,100,minecraft:stone_brick_stairs-4
rule31=0,100,minecraft:log2-1
rule32=0,100,minecraft:oak_stairs-0
rule33=0,100,minecraft:stone_stairs-1
rule34=0,100,minecraft:fence-0
rule35=0,100,minecraft:stone_brick_stairs-3
rule36=0,100,minecraft:oak_stairs-3
rule37=0,100,minecraft:oak_stairs-2
rule38=0,100,minecraft:jungle_door-3
rule39=0,100,minecraft:oak_stairs-1
rule40=0,100,minecraft:spruce_fence-0
rule41=0,100,minecraft:spruce_fence_gate-3
rule42=0,100,minecraft:furnace-3
rule43=0,100,minecraft:jungle_door-8
rule44=0,100,minecraft:jungle_door-9
rule45=0,100,minecraft:wooden_slab-13
rule46=0,100,minecraft:dark_oak_stairs-4
rule47=0,100,minecraft:spruce_stairs-6
rule48=0,100,minecraft:spruce_fence_gate-2
rule49=0,100,minecraft:spruce_stairs-5
rule50=0,100,minecraft:dark_oak_stairs-2
rule51=0,100,minecraft:dark_oak_stairs-7
rule52=0,100,minecraft:dark_oak_stairs-3
rule53=0,100,minecraft:double_wooden_slab-5
rule54=0,100,minecraft:wooden_slab-5
rule55=0,100,minecraft:dark_oak_stairs-0
rule56=0,100,minecraft:dark_oak_stairs-5
rule57=0,100,minecraft:dark_oak_stairs-1
rule58=0,100,minecraft:planks-5
rule59=0,100,minecraft:dark_oak_fence-0
rule60=0,100,minecraft:dark_oak_fence_gate-2
rule61=0,100,minecraft:dark_oak_fence_gate-0
rule62=0,100,minecraft:dark_oak_fence_gate-1
rule63=0,100,minecraft:dark_oak_fence_gate-3
rule64=0,100,minecraft:trapdoor-2
rule65=0,100,minecraft:stone_slab-0

layer
4,5,5,4,3,2,2,2,2,2,2,2,2,2
2,5,5,5,5,5,5,4,5,5,2,2,2,2
4,5,5,4,4,6,6,4,5,5,5,2,2,2
2,5,5,6,6,7,7,6,6,5,5,2,2,2
2,5,5,6,7,7,8,7,7,6,4,4,2,2
4,4,4,6,7,8,8,8,7,7,6,6,5,2
2,5,6,7,7,7,8,8,8,7,7,6,5,2
2,5,6,7,8,8,8,8,8,7,6,4,4,2
4,5,6,6,7,8,8,7,7,7,6,5,2,2
2,5,4,6,7,7,8,8,7,6,6,5,2,2
2,5,5,4,6,7,4,7,6,4,4,2,2,2
4,5,5,5,4,6,6,6,6,5,5,2,2,2
2,5,5,5,5,5,5,5,4,2,2,2,2,2
4,2,4,5,3,2,2,2,2,2,2,2,2,2
endlayer

layer
5,5,5,3,2,2,2,2,2,2,2,2,2,2
11,5,5,5,5,10,5,9,5,5,2,2,2,2
5,5,5,9,12,13,13,12,5,5,5,2,2,2
2,5,5,14,1,1,1,1,14,5,5,2,2,2
2,5,5,14,1,1,1,1,1,14,12,9,2,2
5,9,12,1,1,1,1,1,1,1,1,13,5,2
2,10,13,1,1,1,1,1,1,1,1,13,10,2
2,10,13,1,1,1,1,1,1,1,1,12,9,2
5,5,13,1,1,1,1,1,1,1,14,5,2,2
2,5,9,14,1,1,1,1,1,1,14,5,2,2
2,5,5,12,14,1,12,1,1,12,9,2,2,2
5,5,5,5,9,17,16,15,15,5,5,2,2,2
11,5,5,5,5,5,10,5,9,2,2,2,2,2
5,18,5,3,2,2,2,2,2,2,2,2,2,2
endlayer

layer
2,2,2,2,2,2,2,2,2,2,2,2,2,2
19,19,19,19,5,10,5,9,5,5,2,2,2,2
5,5,5,9,12,14,14,12,5,5,5,2,2,2
18,5,5,14,14,1,1,14,14,5,5,2,2,2
20,5,5,14,1,1,1,1,1,14,12,9,2,2
5,9,12,14,1,1,1,1,1,1,14,14,5,2
2,10,14,1,1,1,1,1,1,1,1,14,10,2
2,10,1,1,1,1,1,1,1,1,14,12,9,2
5,5,14,1,1,1,1,1,1,1,14,5,2,2
18,5,9,14,1,1,1,1,1,1,14,5,2,2
20,5,5,12,14,1,12,1,1,12,9,2,2,2
5,5,5,5,9,22,21,1,1,5,5,2,2,2
5,5,5,5,5,5,10,5,9,2,2,2,2,2
23,23,3,2,2,2,2,2,2,2,2,2,2,2
endlayer

layer
2,2,2,2,2,2,2,2,2,2,2,2,2,2
2,2,2,2,5,10,5,4,5,5,2,2,2,2
19,19,19,4,12,14,14,12,5,5,5,2,2,2
5,5,5,14,14,14,14,14,14,5,5,2,2,2
5,5,5,14,14,14,1,14,14,14,12,4,2,2
5,4,12,14,14,1,1,1,1,14,14,14,5,2
18,10,14,14,1,1,1,1,1,1,14,14,10,2
20,10,14,1,1,1,1,1,1,14,14,12,4,2
5,5,14,14,1,1,1,1,1,1,14,5,2,2
5,5,4,14,14,14,1,1,1,14,14,5,2,2
5,5,5,12,22,22,12,1,1,12,4,2,2,2
5,5,5,5,4,21,1,1,1,5,5,2,2,2
23,23,3,2,2,5,10,5,4,2,2,2,2,2
2,2,2,2,2,2,2,2,2,2,2,2,2,2
endlayer

layer
2,2,2,2,2,2,2,2,2,2,2,2,2,2
2,2,2,2,5,5,5,4,5,5,2,2,2,2
2,2,2,4,26,26,26,25,25,24,5,2,2,2
2,2,5,26,27,27,26,25,4,5,5,2,2,2
2,2,5,26,27,26,27,26,26,26,26,4,2,2
19,4,26,26,27,26,26,27,27,27,26,26,5,2
5,26,26,27,26,26,26,27,26,26,27,26,5,2
5,26,26,27,26,26,26,26,26,26,27,26,4,2
23,5,26,27,27,26,27,26,26,27,26,5,2,2
2,2,4,26,26,27,27,28,28,26,26,5,2,2
2,2,5,26,29,29,12,13,13,26,4,2,2,2
2,2,2,5,4,1,1,1,1,5,5,2,2,2
2,2,2,2,2,5,5,5,4,2,2,2,2,2
2,2,2,2,2,2,2,2,2,2,2,2,2,2
endlayer

layer
2,2,2,2,2,2,2,2,2,2,2,2,2,2
2,2,2,2,32,32,32,31,30,4,2,2,2,2
2,2,34,31,1,1,1,10,33,1,4,2,2,2
2,2,36,1,1,1,1,1,1,35,5,2,2,2
2,2,32,1,1,1,1,1,1,1,1,31,2,2
2,31,1,1,1,1,1,1,1,1,1,1,37,2
1,38,1,1,1,1,1,1,1,1,1,1,37,2
1,38,1,1,1,1,1,1,1,1,1,1,31,2
2,27,1,1,1,1,1,1,1,1,1,39,2,2
2,2,31,1,1,1,1,1,1,1,1,37,2,2
2,2,36,1,1,1,12,41,41,40,31,2,2,2
2,2,2,39,31,1,1,1,1,37,39,2,2,2
2,2,2,2,2,39,39,39,31,2,2,2,2,2
2,2,2,2,2,2,2,2,2,2,2,2,2,2
endlayer

layer
2,2,2,2,2,2,2,2,2,2,2,2,2,2
2,2,2,2,34,1,34,31,25,4,2,2,2,2
2,2,34,31,1,1,1,10,1,1,4,2,2,2
2,2,1,1,1,1,1,1,1,1,42,2,2,2
2,2,34,1,1,1,1,1,1,1,1,31,34,2
2,31,1,1,1,1,1,1,1,1,1,1,34,2
1,43,1,1,1,1,1,1,1,1,1,1,1,2
1,44,1,1,1,1,1,1,1,1,1,1,31,2
2,27,1,1,1,1,1,1,1,1,1,34,2,2
2,2,31,1,1,1,1,1,1,1,1,1,2,2
2,2,34,1,1,1,12,1,1,1,31,2,2,2
2,2,2,34,31,1,1,1,1,34,34,2,2,2
2,2,2,2,34,34,2,34,31,2,2,2,2,2
2,2,2,2,2,2,2,2,2,2,2,2,2,2
endlayer

layer
2,2,2,2,2,2,2,2,45,2,2,2,2,2
2,2,45,16,22,22,22,31,25,5,2,2,2,2
2,45,22,31,1,1,1,10,18,1,25,2,2,2
45,45,16,1,1,1,1,1,1,11,5,46,45,2
45,16,22,1,1,1,1,1,1,1,1,31,22,2
2,31,1,1,1,1,1,1,1,1,1,1,47,2
1,48,1,1,1,1,1,1,1,1,1,1,47,2
1,48,1,1,1,1,1,1,1,1,1,1,31,2
2,26,1,1,1,1,1,1,1,1,1,49,47,45
2,16,31,1,1,1,1,1,1,1,1,47,45,2
45,45,16,1,1,1,12,1,1,1,31,49,45,2
2,45,45,49,31,1,1,1,1,47,49,2,2,2
2,2,45,45,16,49,49,49,31,2,45,2,2,2
2,2,2,2,2,2,2,2,2,2,2,2,2,2
endlayer

layer
2,2,2,52,45,45,51,50,2,2,2,2,2,2
2,2,54,53,26,26,26,31,25,19,2,2,2,2
2,2,53,31,49,49,49,11,5,10,25,54,2,2
2,53,26,49,1,1,1,1,18,25,25,50,55,2
52,26,26,1,1,1,1,1,1,13,49,31,53,50
56,31,47,1,1,1,1,1,1,1,1,16,26,45
45,26,47,1,1,1,1,1,1,1,1,16,26,45
45,26,47,1,1,1,1,1,1,1,16,26,31,57
46,26,47,1,1,1,1,1,1,1,16,26,53,2
54,53,31,47,1,1,1,1,1,22,26,26,50,2
2,52,26,26,22,22,12,1,22,26,31,58,2,2
2,2,58,26,31,26,22,22,26,26,53,54,2,2
2,2,2,57,53,26,26,26,53,53,54,2,2,2
2,2,2,2,52,45,45,51,54,2,2,2,2,2
endlayer

layer
2,2,2,2,2,54,2,2,2,2,2,2,2,2
2,2,2,2,52,55,55,55,19,2,2,2,2,2
2,2,59,52,58,58,58,58,5,5,19,2,2,2
2,59,58,58,47,49,16,26,5,5,5,2,2,2
2,52,58,49,13,13,13,49,16,58,58,55,54,2
2,52,58,47,13,1,1,1,13,49,49,58,50,2
52,58,58,47,13,1,1,1,13,13,16,58,50,2
52,58,58,47,13,1,1,1,13,16,58,58,57,2
2,57,58,22,13,13,13,13,13,22,58,50,2,2
2,59,52,58,47,22,13,13,22,58,50,54,2,2
2,2,57,58,58,58,12,26,58,58,57,2,2,2
2,2,2,54,57,57,58,58,58,57,2,2,2,2
2,2,2,2,2,54,57,57,2,2,2,2,2,2
2,2,2,2,2,2,54,2,2,2,2,2,2,2
endlayer

layer
2,2,2,2,2,2,2,2,2,2,2,2,2,2
2,2,2,2,2,2,2,2,2,2,2,2,2,2
2,2,2,2,59,59,59,59,5,5,2,2,2,2
2,2,59,59,54,52,55,54,5,5,3,2,2,2
2,2,60,54,52,58,58,58,54,59,59,2,2,2
2,2,59,55,58,26,49,26,58,54,54,59,2,2
2,59,54,58,58,47,1,16,58,50,54,61,2,2
2,59,59,58,58,26,22,26,58,57,59,59,2,2
2,2,59,54,57,58,58,58,57,54,59,2,2,2
2,2,2,59,54,52,58,57,54,59,2,2,2,2
2,2,2,59,62,59,54,54,59,59,2,2,2,2
2,2,2,2,2,2,59,62,59,2,2,2,2,2
2,2,2,2,2,2,2,2,2,2,2,2,2,2
2,2,2,2,2,2,2,2,2,2,2,2,2,2
endlayer

layer
2,2,2,2,2,2,2,2,2,2,2,2,2,2
2,2,2,2,2,2,2,2,2,2,2,2,2,2
2,2,2,2,2,2,2,2,5,19,2,2,2,2
2,2,2,2,2,2,2,2,33,5,2,2,2,2
2,2,2,2,2,59,63,59,2,2,2,2,2,2
2,2,2,2,59,54,54,54,59,2,2,2,2,2
2,2,2,59,59,54,64,54,59,2,2,2,2,2
2,2,2,59,59,54,54,54,59,2,2,2,2,2
2,2,2,2,2,59,59,59,2,2,2,2,2,2
2,2,2,2,2,2,59,2,2,2,2,2,2,2
2,2,2,2,2,2,2,2,2,2,2,2,2,2
2,2,2,2,2,2,2,2,2,2,2,2,2,2
2,2,2,2,2,2,2,2,2,2,2,2,2,2
2,2,2,2,2,2,2,2,2,2,2,2,2,2
endlayer

layer
2,2,2,2,2,2,2,2,2,2,2,2,2,2
2,2,2,2,2,2,2,2,2,2,2,2,2,2
2,2,2,2,2,2,2,2,5,2,2,2,2,2
2,2,2,2,2,2,2,2,11,5,2,2,2,2
2,2,2,2,2,2,2,2,2,2,2,2,2,2
2,2,2,2,2,2,2,2,2,2,2,2,2,2
2,2,2,2,2,2,2,2,2,2,2,2,2,2
2,2,2,2,2,2,2,2,2,2,2,2,2,2
2,2,2,2,2,2,2,2,2,2,2,2,2,2
2,2,2,2,2,2,2,2,2,2,2,2,2,2
2,2,2,2,2,2,2,2,2,2,2,2,2,2
2,2,2,2,2,2,2,2,2,2,2,2,2,2
2,2,2,2,2,2,2,2,2,2,2,2,2,2
2,2,2,2,2,2,2,2,2,2,2,2,2,2
endlayer

layer
2,2,2,2,2,2,2,2,2,2,2,2,2,2
2,2,2,2,2,2,2,2,2,2,2,2,2,2
2,2,2,2,2,2,2,2,10,2,2,2,2,2
2,2,2,2,2,2,2,2,5,3,2,2,2,2
2,2,2,2,2,2,2,2,2,2,2,2,2,2
2,2,2,2,2,2,2,2,2,2,2,2,2,2
2,2,2,2,2,2,2,2,2,2,2,2,2,2
2,2,2,2,2,2,2,2,2,2,2,2,2,2
2,2,2,2,2,2,2,2,2,2,2,2,2,2
2,2,2,2,2,2,2,2,2,2,2,2,2,2
2,2,2,2,2,2,2,2,2,2,2,2,2,2
2,2,2,2,2,2,2,2,2,2,2,2,2,2
2,2,2,2,2,2,2,2,2,2,2,2,2,2
2,2,2,2,2,2,2,2,2,2,2,2,2,2
endlayer

layer
2,2,2,2,2,2,2,2,2,2,2,2,2,2
2,2,2,2,2,2,2,2,2,2,2,2,2,2
2,2,2,2,2,2,2,2,10,2,2,2,2,2
2,2,2,2,2,2,2,2,5,2,2,2,2,2
2,2,2,2,2,2,2,2,2,2,2,2,2,2
2,2,2,2,2,2,2,2,2,2,2,2,2,2
2,2,2,2,2,2,2,2,2,2,2,2,2,2
2,2,2,2,2,2,2,2,2,2,2,2,2,2
2,2,2,2,2,2,2,2,2,2,2,2,2,2
2,2,2,2,2,2,2,2,2,2,2,2,2,2
2,2,2,2,2,2,2,2,2,2,2,2,2,2
2,2,2,2,2,2,2,2,2,2,2,2,2,2
2,2,2,2,2,2,2,2,2,2,2,2,2,2
2,2,2,2,2,2,2,2,2,2,2,2,2,2
endlayer

layer
2,2,2,2,2,2,2,2,2,2,2,2,2,2
2,2,2,2,2,2,2,2,2,2,2,2,2,2
2,2,2,2,2,2,2,2,65,2,2,2,2,2
2,2,2,2,2,2,2,2,10,2,2,2,2,2
2,2,2,2,2,2,2,2,2,2,2,2,2,2
2,2,2,2,2,2,2,2,2,2,2,2,2,2
2,2,2,2,2,2,2,2,2,2,2,2,2,2
2,2,2,2,2,2,2,2,2,2,2,2,2,2
2,2,2,2,2,2,2,2,2,2,2,2,2,2
2,2,2,2,2,2,2,2,2,2,2,2,2,2
2,2,2,2,2,2,2,2,2,2,2,2,2,2
2,2,2,2,2,2,2,2,2,2,2,2,2,2
2,2,2,2,2,2,2,2,2,2,2,2,2,2
2,2,2,2,2,2,2,2,2,2,2,2,2,2
endlayer

layer
2,2,2,2,2,2,2,2,2,2,2,2,2,2
2,2,2,2,2,2,2,2,2,2,2,2,2,2
2,2,2,2,2,2,2,2,2,2,2,2,2,2
2,2,2,2,2,2,2,2,65,2,2,2,2,2
2,2,2,2,2,2,2,2,2,2,2,2,2,2
2,2,2,2,2,2,2,2,2,2,2,2,2,2
2,2,2,2,2,2,2,2,2,2,2,2,2,2
2,2,2,2,2,2,2,2,2,2,2,2,2,2
2,2,2,2,2,2,2,2,2,2,2,2,2,2
2,2,2,2,2,2,2,2,2,2,2,2,2,2
2,2,2,2,2,2,2,2,2,2,2,2,2,2
2,2,2,2,2,2,2,2,2,2,2,2,2,2
2,2,2,2,2,2,2,2,2,2,2,2,2,2
2,2,2,2,2,2,2,2,2,2,2,2,2,2
endlayer

