
# Created by Ruins mod version 16.7 Ingame Parser
# authoring Player: lafuller

weight=1
embed_into_distance=0
acceptable_target_blocks=
unacceptable_target_blocks=flowing_water,water,flowing_lava,lava
dimensions=33,17,17
allowable_overhang=0
max_leveling=4
leveling_buffer=-1
preserve_water=0
preserve_lava=0

rule1=0,100,preserveBlock
rule2=0,100,minecraft:stained_hardened_clay-9
rule3=0,100,minecraft:iron_bars-0
rule4=0,100,minecraft:sea_lantern-0
rule5=0,100,minecraft:stained_glass-8
rule6=0,100,minecraft:quartz_block-1
rule7=0,100,minecraft:stone_brick_stairs-1
rule8=0,100,minecraft:stone_brick_stairs-2
rule9=0,100,minecraft:stone_brick_stairs-3
rule10=0,100,minecraft:stone_brick_stairs-0
rule11=0,100,minecraft:prismarine-1
rule12=0,100,minecraft:prismarine-2
rule13=0,100,minecraft:stone_brick_stairs-7
rule14=0,100,minecraft:stone_brick_stairs-5
rule15=0,100,minecraft:stonebrick-0
rule16=0,100,minecraft:stone_brick_stairs-6
rule17=0,100,minecraft:stone_brick_stairs-4

layer
1,1,1,1,1,2,2,2,2,2,2,2,2,1,1,1,1
1,1,2,2,2,2,2,2,2,2,2,2,2,2,2,1,1
1,2,3,2,2,0,0,0,0,0,0,0,2,2,3,2,1
1,2,2,2,0,0,0,0,0,0,0,0,0,2,2,2,1
1,2,2,0,0,0,0,0,0,0,0,0,0,0,2,2,1
2,2,0,0,0,0,0,0,0,0,0,0,0,0,0,2,2
2,2,0,0,0,0,0,0,0,0,0,0,0,0,0,2,2
2,2,0,0,0,0,0,0,0,0,0,0,0,0,0,2,2
2,2,0,0,0,0,0,0,0,0,0,0,0,0,0,2,2
2,2,0,0,0,0,0,0,0,0,0,0,0,0,0,2,2
2,2,0,0,0,0,0,0,0,0,0,0,0,0,0,2,2
2,2,0,0,0,0,0,0,0,0,0,0,0,0,0,2,2
1,2,2,0,0,0,0,0,0,0,0,0,0,0,2,2,1
1,2,2,2,0,0,0,0,0,0,0,0,0,2,2,2,1
1,2,3,2,2,0,0,0,0,0,0,0,2,2,3,2,1
1,1,2,2,2,2,2,2,2,2,2,2,2,2,2,1,1
1,1,1,1,1,2,2,2,2,2,2,2,1,1,1,1,1
endlayer

layer
1,1,1,1,1,1,2,2,4,2,2,2,1,1,1,1,1
1,1,1,2,2,2,0,0,0,0,0,2,2,2,1,1,1
1,1,4,2,2,0,0,0,0,0,0,0,2,2,4,1,1
1,2,2,2,0,0,0,0,0,0,0,0,0,2,2,2,1
1,2,2,0,0,0,0,0,0,0,0,0,0,0,2,2,1
1,2,0,0,0,0,0,0,0,0,0,0,0,0,0,2,1
2,0,0,0,0,0,0,0,0,0,0,0,0,0,0,0,2
2,0,0,0,0,0,0,0,0,0,0,0,0,0,0,0,2
4,0,0,0,0,0,0,0,0,0,0,0,0,0,0,0,4
2,0,0,0,0,0,0,0,0,0,0,0,0,0,0,0,2
2,0,0,0,0,0,0,0,0,0,0,0,0,0,0,0,2
1,2,0,0,0,0,0,0,0,0,0,0,0,0,0,2,1
1,2,2,0,0,0,0,0,0,0,0,0,0,0,2,2,1
1,2,2,2,0,0,0,0,0,0,0,0,0,2,2,2,1
1,1,4,2,2,0,0,0,0,0,0,0,2,2,4,1,1
1,1,1,2,2,2,0,0,0,0,0,2,2,2,1,1,1
1,1,1,1,1,1,2,2,4,2,2,1,1,1,1,1,1
endlayer

layer
1,1,1,1,1,1,1,2,2,2,1,1,1,1,1,1,1
1,1,1,1,1,2,2,5,5,5,2,2,1,1,1,1,1
1,1,2,2,2,0,0,0,0,0,3,0,2,2,2,1,1
1,1,2,2,0,0,0,0,0,0,0,0,0,2,2,1,1
1,1,2,0,0,0,0,0,0,0,0,0,0,0,2,1,1
1,2,0,0,0,0,0,0,0,0,0,0,0,0,0,2,1
1,2,0,0,0,0,0,0,0,0,0,0,0,0,0,2,1
2,5,0,0,0,0,0,0,0,0,0,0,0,0,0,5,2
6,5,0,0,0,0,0,0,0,0,0,0,0,0,0,5,6
2,5,0,0,0,0,0,0,0,0,0,0,0,0,0,5,2
1,2,3,0,0,0,0,0,0,0,0,0,0,0,0,2,1
1,2,0,0,0,0,0,0,0,0,0,0,0,0,0,2,1
1,1,2,0,0,0,0,0,0,0,0,0,0,0,2,1,1
1,1,2,2,0,0,0,0,0,0,0,0,0,2,2,1,1
1,1,2,2,2,0,0,0,0,0,0,0,2,2,2,1,1
1,1,1,1,1,2,2,5,5,5,2,2,1,1,1,1,1
1,1,1,1,1,1,1,2,2,2,1,1,1,1,1,1,1
endlayer

layer
1,1,1,1,1,1,1,2,2,2,1,1,1,1,1,1,1
1,1,1,1,1,2,2,5,5,5,2,2,1,1,1,1,1
1,1,1,2,2,0,3,0,0,0,0,0,2,2,1,1,1
1,1,2,2,0,0,0,0,0,0,0,0,0,2,2,1,1
1,1,2,0,0,0,0,0,0,0,0,0,0,0,2,1,1
1,2,0,0,0,0,0,0,0,0,0,0,0,0,0,2,1
1,2,0,0,0,0,0,0,0,0,0,0,0,0,0,2,1
6,5,0,0,0,0,0,0,0,0,0,0,0,0,0,5,2
6,5,0,0,0,0,0,0,0,0,0,0,0,0,0,5,6
2,5,0,0,0,0,0,0,0,0,0,0,0,0,0,5,6
1,2,0,0,0,0,0,0,0,0,0,0,0,0,0,2,1
1,2,0,0,0,0,0,0,0,0,0,0,0,0,0,2,1
1,1,2,0,0,0,0,0,0,0,0,0,0,0,2,1,1
1,1,2,2,0,0,0,0,0,0,0,0,0,2,2,1,1
1,1,1,2,2,0,3,0,0,0,0,0,2,2,1,1,1
1,1,1,1,1,2,2,5,5,5,2,2,1,1,1,1,1
1,1,1,1,1,1,1,2,2,2,1,1,1,1,1,1,1
endlayer

layer
1,1,1,1,1,1,1,2,6,2,1,1,1,1,1,1,1
1,1,1,1,1,2,2,5,5,5,2,2,1,1,1,1,1
1,1,1,1,2,0,0,0,0,0,0,0,2,1,1,1,1
1,1,1,2,0,0,0,0,0,0,0,0,0,2,1,1,1
1,1,2,0,0,0,0,0,0,0,0,0,0,0,2,1,1
1,2,0,0,0,0,0,0,0,0,0,0,0,0,0,2,1
1,2,0,0,0,0,0,0,0,0,0,0,0,0,0,2,1
6,5,0,0,0,0,0,0,0,0,0,0,0,0,0,5,2
6,5,0,0,0,0,0,0,0,0,0,0,0,0,0,5,6
2,5,0,0,0,0,0,0,0,0,0,0,0,0,0,5,6
1,2,0,0,0,0,0,0,0,0,0,0,0,0,0,2,1
1,2,0,0,0,0,0,0,0,0,0,0,0,0,0,2,1
1,1,2,0,0,0,0,0,0,0,0,0,0,0,2,1,1
1,1,1,2,0,0,0,0,0,0,0,0,0,2,1,1,1
1,1,1,1,2,0,3,0,0,0,0,0,2,1,1,1,1
1,1,1,1,1,2,2,5,5,5,2,2,1,1,1,1,1
1,1,1,1,1,1,1,2,6,2,1,1,1,1,1,1,1
endlayer

layer
1,1,1,1,1,1,1,6,6,6,1,1,1,1,1,1,1
1,1,1,1,1,2,2,5,5,5,2,2,1,1,1,1,1
1,1,1,1,2,0,0,0,0,0,0,0,2,1,1,1,1
1,1,1,2,0,0,0,0,0,0,0,0,0,2,1,1,1
1,1,2,0,0,0,0,0,0,0,0,0,0,0,2,1,1
1,2,0,0,0,0,0,0,0,0,0,0,0,0,0,2,1
1,2,3,0,0,0,0,0,0,0,0,0,0,0,0,2,1
2,5,0,0,0,0,0,0,0,0,0,0,0,0,0,5,6
6,5,0,0,0,0,0,0,0,0,0,0,0,0,0,5,6
6,5,0,0,0,0,0,0,0,0,0,0,0,0,0,5,2
1,2,0,0,0,0,0,0,0,0,0,0,0,0,0,2,1
1,2,0,0,0,0,0,0,0,0,0,0,0,0,0,2,1
1,1,2,0,0,0,0,0,0,0,0,0,0,0,2,1,1
1,1,1,2,0,0,0,0,0,0,0,0,0,2,1,1,1
1,1,1,1,2,0,0,0,0,0,3,0,2,1,1,1,1
1,1,1,1,1,2,2,5,5,5,2,2,1,1,1,1,1
1,1,1,1,1,1,1,6,6,6,1,1,1,1,1,1,1
endlayer

layer
1,1,1,1,1,1,2,2,4,2,2,1,1,1,1,1,1
1,1,1,1,1,2,0,0,0,0,0,2,1,1,1,1,1
1,1,1,1,2,0,0,0,0,0,0,0,2,1,1,1,1
1,1,1,2,0,0,0,0,0,0,0,0,0,2,1,1,1
1,1,2,0,0,0,0,0,0,0,0,0,0,0,2,1,1
1,2,0,0,0,0,0,0,0,0,0,0,0,0,0,2,1
2,0,0,0,0,0,0,0,0,0,0,0,0,0,0,0,2
2,0,0,0,0,0,0,0,0,0,0,0,0,0,0,0,2
4,0,0,0,0,0,0,0,0,0,0,0,0,0,0,0,4
2,0,0,0,0,0,0,0,0,0,0,0,0,0,0,0,2
2,0,0,0,0,0,0,0,0,0,0,0,0,0,0,0,2
1,2,0,0,0,0,0,0,0,0,0,0,0,0,0,2,1
1,1,2,0,0,0,0,0,0,0,0,0,0,0,2,1,1
1,1,1,2,0,0,0,0,0,0,0,0,0,2,1,1,1
1,1,1,1,2,0,0,0,0,0,0,0,2,1,1,1,1
1,1,1,1,1,2,0,0,0,0,0,2,1,1,1,1,1
1,1,1,1,1,1,2,2,4,2,2,1,1,1,1,1,1
endlayer

layer
1,1,1,1,1,1,1,2,6,2,1,1,1,1,1,1,1
1,1,1,1,1,2,2,5,5,5,2,2,1,1,1,1,1
1,1,1,1,2,0,0,0,0,0,0,0,2,1,1,1,1
1,1,1,2,0,0,0,0,0,0,0,0,0,2,1,1,1
1,1,2,0,0,0,0,0,0,0,0,0,0,0,2,1,1
1,2,0,0,0,0,0,0,0,0,0,0,0,0,0,2,1
1,2,0,0,0,0,0,0,0,0,0,0,0,0,0,2,1
2,5,0,0,0,0,0,0,0,0,0,0,0,0,0,5,2
6,5,0,0,0,0,0,0,0,0,0,0,0,0,0,5,6
2,5,0,0,0,0,0,0,0,0,0,0,0,0,0,5,2
1,2,0,0,0,0,0,0,0,0,0,0,0,0,3,2,1
1,2,0,0,0,0,0,0,0,0,0,0,0,0,0,2,1
1,1,2,0,0,0,0,0,0,0,0,0,0,0,2,1,1
1,1,1,2,0,0,0,0,0,0,0,0,0,2,1,1,1
1,1,1,1,2,0,0,0,0,0,0,0,2,1,1,1,1
1,1,1,1,1,2,2,5,5,5,2,2,1,1,1,1,1
1,1,1,1,1,1,1,2,6,2,1,1,1,1,1,1,1
endlayer

layer
1,1,1,1,1,1,1,2,2,6,1,1,1,1,1,1,1
1,1,1,1,1,2,2,5,5,5,2,2,1,1,1,1,1
1,1,1,1,2,0,0,0,0,0,0,0,2,1,1,1,1
1,1,1,2,0,0,0,0,0,0,0,0,0,2,1,1,1
1,1,2,0,0,0,0,0,0,0,0,0,0,0,2,1,1
1,2,0,0,0,0,0,0,0,0,0,0,0,0,0,2,1
1,2,0,0,0,0,0,0,0,0,0,0,0,0,3,2,1
6,5,0,0,0,0,0,0,0,0,0,0,0,0,0,5,6
2,5,0,0,0,0,0,0,0,0,0,0,0,0,0,5,2
6,5,0,0,0,0,0,0,0,0,0,0,0,0,0,5,6
1,2,3,0,0,0,0,0,0,0,0,0,0,0,0,2,1
1,2,0,0,0,0,0,0,0,0,0,0,0,0,0,2,1
1,1,2,0,0,0,0,0,0,0,0,0,0,0,2,1,1
1,1,1,2,0,0,0,0,0,0,0,0,0,2,1,1,1
1,1,1,1,2,0,0,0,0,0,0,0,2,1,1,1,1
1,1,1,1,1,2,2,5,5,5,2,2,1,1,1,1,1
1,1,1,1,1,1,1,6,2,2,1,1,1,1,1,1,1
endlayer

layer
1,1,1,1,1,1,1,2,2,2,1,1,1,1,1,1,1
1,1,1,1,1,2,2,5,5,5,2,2,1,1,1,1,1
1,1,1,1,2,0,0,0,0,0,0,0,2,1,1,1,1
1,1,1,2,0,0,0,0,0,0,0,0,0,2,1,1,1
1,1,2,0,0,0,0,0,0,0,0,0,0,0,2,1,1
1,2,0,0,0,0,0,0,0,0,0,0,0,0,0,2,1
1,2,0,0,0,0,0,0,0,0,0,0,0,0,0,2,1
6,5,0,0,0,0,0,0,0,0,0,0,0,0,0,5,2
2,5,0,0,0,0,0,0,0,0,0,0,0,0,0,5,2
2,5,0,0,0,0,0,0,0,0,0,0,0,0,0,5,6
1,2,0,0,0,0,0,0,0,0,0,0,0,0,0,2,1
1,2,0,0,0,0,0,0,0,0,0,0,0,0,0,2,1
1,1,2,0,0,0,0,0,0,0,0,0,0,0,2,1,1
1,1,1,2,0,0,0,0,0,0,0,0,0,2,1,1,1
1,1,1,1,2,0,0,0,0,0,0,0,2,1,1,1,1
1,1,1,1,1,2,2,5,5,5,2,2,1,1,1,1,1
1,1,1,1,1,1,1,2,2,2,1,1,1,1,1,1,1
endlayer

layer
1,1,1,1,1,1,1,6,6,6,1,1,1,1,1,1,1
1,1,1,1,1,2,2,5,5,5,2,2,1,1,1,1,1
1,1,1,1,2,0,0,0,0,0,0,0,2,1,1,1,1
1,1,1,2,0,0,0,0,0,0,0,0,0,2,1,1,1
1,1,2,0,0,0,0,0,0,0,0,0,0,0,2,1,1
1,2,0,0,0,0,0,0,0,0,0,0,0,0,0,2,1
1,2,0,0,0,0,0,0,0,0,0,0,0,0,0,2,1
6,5,0,0,0,0,0,0,0,0,0,0,0,0,0,5,6
2,5,0,0,0,0,0,0,0,0,0,0,0,0,0,5,2
6,5,0,0,0,0,0,0,0,0,0,0,0,0,0,5,6
1,2,0,0,0,0,0,0,0,0,0,0,0,0,0,2,1
1,2,0,0,0,0,0,0,0,0,0,0,0,0,0,2,1
1,1,2,0,0,0,0,0,0,0,0,0,0,0,2,1,1
1,1,1,2,0,0,0,0,0,0,0,0,0,2,1,1,1
1,1,1,1,2,0,3,0,0,0,0,0,2,1,1,1,1
1,1,1,1,1,2,2,5,5,5,2,2,1,1,1,1,1
1,1,1,1,1,1,1,6,6,6,1,1,1,1,1,1,1
endlayer

layer
1,1,1,1,1,1,2,2,4,2,2,1,1,1,1,1,1
1,1,1,1,1,2,0,0,0,0,0,2,1,1,1,1,1
1,1,1,1,2,0,0,0,0,0,0,0,2,1,1,1,1
1,1,1,2,0,0,0,0,0,0,0,0,0,2,1,1,1
1,1,2,0,0,0,0,0,0,0,0,0,0,0,2,1,1
1,2,0,0,0,0,0,0,0,0,0,0,0,0,0,2,1
2,0,0,0,0,0,0,0,0,0,0,0,0,0,0,0,2
2,0,0,0,0,0,0,0,0,0,0,0,0,0,0,0,2
4,0,0,0,0,0,0,0,0,0,0,0,0,0,0,0,4
2,0,0,0,0,0,0,0,0,0,0,0,0,0,0,0,2
2,0,0,0,0,0,0,0,0,0,0,0,0,0,0,0,2
1,2,0,0,0,0,0,0,0,0,0,0,0,0,0,2,1
1,1,2,0,0,0,0,0,0,0,0,0,0,0,2,1,1
1,1,1,2,0,0,0,0,0,0,0,0,0,2,1,1,1
1,1,1,1,2,0,0,0,0,0,0,0,2,1,1,1,1
1,1,1,1,1,2,0,0,0,0,0,2,1,1,1,1,1
1,1,1,1,1,1,2,2,4,2,2,1,1,1,1,1,1
endlayer

layer
1,1,1,1,1,1,1,2,2,2,1,1,1,1,1,1,1
1,1,1,1,1,2,2,5,5,5,2,2,1,1,1,1,1
1,1,1,1,2,0,3,0,0,0,0,0,2,1,1,1,1
1,1,1,2,0,0,0,0,0,0,0,0,0,2,1,1,1
1,1,2,0,0,0,0,0,0,0,0,0,0,0,2,1,1
1,2,0,0,0,0,0,0,0,0,0,0,0,0,0,2,1
1,2,0,0,0,0,0,0,0,0,0,0,0,0,0,2,1
6,5,0,0,0,0,0,0,0,0,0,0,0,0,0,5,6
6,5,0,0,0,0,0,0,0,0,0,0,0,0,0,5,6
6,5,0,0,0,0,0,0,0,0,0,0,0,0,0,5,6
1,2,0,0,0,0,0,0,0,0,0,0,0,0,0,2,1
1,2,0,0,0,0,0,0,0,0,0,0,0,0,0,2,1
1,1,2,0,0,0,0,0,0,0,0,0,0,0,2,1,1
1,1,1,2,0,0,0,0,0,0,0,0,0,2,1,1,1
1,1,1,1,2,0,0,0,0,0,0,0,2,1,1,1,1
1,1,1,1,1,2,2,5,5,5,2,2,1,1,1,1,1
1,1,1,1,1,1,1,2,2,2,1,1,1,1,1,1,1
endlayer

layer
1,1,1,1,1,1,1,6,6,6,1,1,1,1,1,1,1
1,1,1,1,1,2,2,5,5,5,2,2,1,1,1,1,1
1,1,1,1,2,0,0,0,0,0,0,0,2,1,1,1,1
1,1,1,2,0,0,0,0,0,0,0,0,0,2,1,1,1
1,1,2,0,0,0,0,0,0,0,0,0,0,0,2,1,1
1,2,0,0,0,0,0,0,0,0,0,0,0,0,0,2,1
1,2,0,0,0,0,0,0,0,0,0,0,0,0,0,2,1
6,5,0,0,0,0,0,0,0,0,0,0,0,0,0,5,6
2,5,0,0,0,0,0,0,0,0,0,0,0,0,0,5,2
6,5,0,0,0,0,0,0,0,0,0,0,0,0,0,5,6
1,2,0,0,0,0,0,0,0,0,0,0,0,0,0,2,1
1,2,0,0,0,0,0,0,0,0,0,0,0,0,0,2,1
1,1,2,0,0,0,0,0,0,0,0,0,0,0,2,1,1
1,1,1,2,0,0,0,0,0,0,0,0,0,2,1,1,1
1,1,1,1,2,0,0,0,0,0,0,0,2,1,1,1,1
1,1,1,1,1,2,2,5,0,5,2,2,1,1,1,1,1
1,1,1,1,1,1,1,6,6,6,1,1,1,1,1,1,1
endlayer

layer
1,1,1,1,1,1,1,6,2,2,1,1,1,1,1,1,1
1,1,1,1,1,2,2,5,5,5,2,2,1,1,1,1,1
1,1,1,1,2,0,0,0,0,0,0,0,2,1,1,1,1
1,1,1,2,0,0,0,0,0,0,0,0,0,2,1,1,1
1,1,2,0,0,0,0,0,0,0,0,0,0,0,2,1,1
1,2,0,0,0,0,0,0,0,0,0,0,0,0,0,2,1
1,2,0,0,0,0,0,0,0,0,0,0,0,0,0,2,1
2,5,0,0,0,0,0,0,0,0,0,0,0,0,0,5,2
2,5,0,0,0,0,0,0,0,0,0,0,0,0,0,5,2
2,5,0,0,0,0,0,0,0,0,0,0,0,0,0,5,2
1,2,0,0,0,0,0,0,0,0,0,0,0,0,0,2,1
1,2,0,0,0,0,0,0,0,0,0,0,0,0,0,2,1
1,1,2,0,0,0,0,0,0,0,0,0,0,0,2,1,1
1,1,1,2,0,0,0,0,0,0,0,0,0,2,1,1,1
1,1,1,1,2,0,3,0,0,0,0,0,2,1,1,1,1
1,1,1,1,1,2,2,5,5,5,2,2,1,1,1,1,1
1,1,1,1,1,1,1,2,2,6,1,1,1,1,1,1,1
endlayer

layer
1,1,1,1,1,1,1,6,2,6,1,1,1,1,1,1,1
1,1,1,1,1,2,2,5,5,5,2,2,1,1,1,1,1
1,1,1,1,2,0,0,0,0,0,0,0,2,1,1,1,1
1,1,1,2,0,0,0,0,0,0,0,0,0,2,1,1,1
1,1,2,0,0,0,0,0,0,0,0,0,0,0,2,1,1
1,2,0,0,0,0,0,0,0,0,0,0,0,0,0,2,1
1,2,3,0,0,0,0,0,0,0,0,0,0,0,0,2,1
6,5,0,0,0,0,0,0,0,0,0,0,0,0,0,5,6
6,5,0,0,0,0,0,0,0,0,0,0,0,0,0,5,6
6,5,0,0,0,0,0,0,0,0,0,0,0,0,0,5,6
1,2,0,0,0,0,0,0,0,0,0,0,0,0,0,2,1
1,2,0,0,0,0,0,0,0,0,0,0,0,0,0,2,1
1,1,2,0,0,0,0,0,0,0,0,0,0,0,2,1,1
1,1,1,2,0,0,0,0,0,0,0,0,0,2,1,1,1
1,1,1,1,2,0,0,0,0,0,3,0,2,1,1,1,1
1,1,1,1,1,2,2,5,5,5,2,2,1,1,1,1,1
1,1,1,1,1,1,1,6,2,6,1,1,1,1,1,1,1
endlayer

layer
1,1,1,1,1,1,2,2,4,2,2,1,1,1,1,1,1
1,1,1,1,1,2,0,0,0,0,0,2,1,1,1,1,1
1,1,1,1,2,0,0,0,0,0,0,0,2,1,1,1,1
1,1,1,2,0,0,0,0,0,0,0,0,0,2,1,1,1
1,1,2,0,0,0,0,0,0,0,0,0,0,0,2,1,1
1,2,0,0,0,0,0,0,0,0,0,0,0,0,0,2,1
2,0,0,0,0,0,0,0,0,0,0,0,0,0,0,0,2
2,0,0,0,0,0,0,0,0,0,0,0,0,0,0,0,2
4,0,0,0,0,0,0,0,0,0,0,0,0,0,0,0,4
2,0,0,0,0,0,0,0,0,0,0,0,0,0,0,0,2
2,0,0,0,0,0,0,0,0,0,0,0,0,0,0,0,2
1,2,0,0,0,0,0,0,0,0,0,0,0,0,0,2,1
1,1,2,0,0,0,0,0,0,0,0,0,0,0,2,1,1
1,1,1,2,0,0,0,0,0,0,0,0,0,2,1,1,1
1,1,1,1,2,0,0,0,0,0,0,0,2,1,1,1,1
1,1,1,1,1,2,0,0,0,0,0,2,1,1,1,1,1
1,1,1,1,1,1,2,2,4,2,2,1,1,1,1,1,1
endlayer

layer
1,1,1,1,1,1,1,2,2,6,1,1,1,1,1,1,1
1,1,1,1,1,2,2,5,5,5,2,2,1,1,1,1,1
1,1,1,1,2,0,0,0,0,0,0,0,2,1,1,1,1
1,1,1,2,0,0,0,0,0,0,0,0,0,2,1,1,1
1,1,2,0,0,0,0,0,0,0,0,0,0,0,2,1,1
1,2,0,0,0,0,0,0,0,0,0,0,0,0,0,2,1
1,2,0,0,0,0,0,0,0,0,0,0,0,0,0,2,1
2,5,0,0,0,0,0,0,0,0,0,0,0,0,0,5,2
2,5,0,0,0,0,0,0,0,0,0,0,0,0,0,5,2
2,5,0,0,0,0,0,0,0,0,0,0,0,0,0,5,2
1,2,0,0,0,0,0,0,0,0,0,0,0,0,3,2,1
1,2,0,0,0,0,0,0,0,0,0,0,0,0,0,2,1
1,1,2,0,0,0,0,0,0,0,0,0,0,0,2,1,1
1,1,1,2,0,0,0,0,0,0,0,0,0,2,1,1,1
1,1,1,1,2,0,0,0,0,0,0,0,2,1,1,1,1
1,1,1,1,1,2,2,5,5,5,2,2,1,1,1,1,1
1,1,1,1,1,1,1,6,2,2,1,1,1,1,1,1,1
endlayer

layer
1,1,1,1,1,1,1,2,6,6,1,1,1,1,1,1,1
1,1,1,1,1,2,2,5,5,5,2,2,1,1,1,1,1
1,1,1,1,2,0,0,0,0,0,0,0,2,1,1,1,1
1,1,1,2,0,0,0,0,0,0,0,0,0,2,1,1,1
1,1,2,0,0,0,0,0,0,0,0,0,0,0,2,1,1
1,2,0,0,0,0,0,0,0,0,0,0,0,0,0,2,1
1,2,0,0,0,0,0,0,0,0,0,0,0,0,3,2,1
6,5,0,0,0,0,0,0,0,0,0,0,0,0,0,5,6
6,5,0,0,0,0,0,0,0,0,0,0,0,0,0,5,6
6,5,0,0,0,0,0,0,0,0,0,0,0,0,0,5,6
1,2,3,0,0,0,0,0,0,0,0,0,0,0,0,2,1
1,2,0,0,0,0,0,0,0,0,0,0,0,0,0,2,1
1,1,2,0,0,0,0,0,0,0,0,0,0,0,2,1,1
1,1,1,2,0,0,0,0,0,0,0,0,0,2,1,1,1
1,1,1,1,2,0,0,0,0,0,0,0,2,1,1,1,1
1,1,1,1,1,2,2,5,5,5,2,2,1,1,1,1,1
1,1,1,1,1,1,1,6,6,2,1,1,1,1,1,1,1
endlayer

layer
1,1,1,1,1,1,1,2,2,2,1,1,1,1,1,1,1
1,1,1,1,1,2,2,5,5,5,2,2,1,1,1,1,1
1,1,1,1,2,0,0,0,0,0,0,0,2,1,1,1,1
1,1,1,2,0,0,0,0,0,0,0,0,0,2,1,1,1
1,1,2,0,0,0,0,0,0,0,0,0,0,0,2,1,1
1,2,0,0,0,0,0,0,0,0,0,0,0,0,0,2,1
1,2,0,0,0,0,0,0,0,0,0,0,0,0,0,2,1
6,5,0,0,0,0,0,0,0,0,0,0,0,0,0,5,2
2,5,0,0,0,0,0,0,0,0,0,0,0,0,0,5,2
2,5,0,0,0,0,0,0,0,0,0,0,0,0,0,5,6
1,2,0,0,0,0,0,0,0,0,0,0,0,0,0,2,1
1,2,0,0,0,0,0,0,0,0,0,0,0,0,0,2,1
1,1,2,0,0,0,0,0,0,0,0,0,0,0,2,1,1
1,1,1,2,0,0,0,0,0,0,0,0,0,2,1,1,1
1,1,1,1,2,0,0,0,0,0,0,0,2,1,1,1,1
1,1,1,1,1,2,2,5,5,5,2,2,1,1,1,1,1
1,1,1,1,1,1,1,2,2,2,1,1,1,1,1,1,1
endlayer

layer
1,1,1,1,1,1,1,2,2,6,1,1,1,1,1,1,1
1,1,1,1,1,2,2,5,5,5,2,2,1,1,1,1,1
1,1,1,1,2,0,0,0,0,0,0,0,2,1,1,1,1
1,1,1,2,0,0,0,0,0,0,0,0,0,2,1,1,1
1,1,2,0,0,0,0,0,0,0,0,0,0,0,2,1,1
1,2,0,0,0,0,0,0,0,0,0,0,0,0,0,2,1
1,2,0,0,0,0,0,0,0,0,0,0,0,0,0,2,1
2,5,0,0,0,0,0,0,0,0,0,0,0,0,0,5,2
6,5,0,0,0,0,0,0,0,0,0,0,0,0,0,5,6
2,5,0,0,0,0,0,0,0,0,0,0,0,0,0,5,2
1,2,0,0,0,0,0,0,0,0,0,0,0,0,0,2,1
1,2,0,0,0,0,0,0,0,0,0,0,0,0,0,2,1
1,1,2,0,0,0,0,0,0,0,0,0,0,0,2,1,1
1,1,1,2,0,0,0,0,0,0,0,0,0,2,1,1,1
1,1,1,1,2,0,3,0,0,0,0,0,2,1,1,1,1
1,1,1,1,1,2,2,5,5,5,2,2,1,1,1,1,1
1,1,1,1,1,1,1,6,2,2,1,1,1,1,1,1,1
endlayer

layer
1,1,1,1,1,1,2,2,4,2,2,1,1,1,1,1,1
1,1,1,1,1,2,0,0,0,0,0,2,1,1,1,1,1
1,1,1,1,2,0,0,0,0,0,0,0,2,1,1,1,1
1,1,1,2,0,0,0,0,0,0,0,0,0,2,1,1,1
1,1,2,0,0,0,0,0,0,0,0,0,0,0,2,1,1
1,2,0,0,0,0,0,0,0,0,0,0,0,0,0,2,1
2,0,0,0,0,0,0,0,0,0,0,0,0,0,0,0,2
2,0,0,0,0,0,0,0,0,0,0,0,0,0,0,0,2
4,0,0,0,0,0,0,0,0,0,0,0,0,0,0,0,4
2,0,0,0,0,0,0,0,0,0,0,0,0,0,0,0,2
2,0,0,0,0,0,0,0,0,0,0,0,0,0,0,0,2
1,2,0,0,0,0,0,0,0,0,0,0,0,0,0,2,1
1,1,2,0,0,0,0,0,0,0,0,0,0,0,2,1,1
1,1,1,2,0,0,0,0,0,0,0,0,0,2,1,1,1
1,1,1,1,2,0,0,0,0,0,0,0,2,1,1,1,1
1,1,1,1,1,2,0,0,0,0,0,2,1,1,1,1,1
1,1,1,1,1,1,2,2,4,2,2,1,1,1,1,1,1
endlayer

layer
1,1,1,1,1,1,1,2,2,2,1,1,1,1,1,1,1
1,1,1,1,1,2,2,5,5,5,2,2,1,1,1,1,1
1,1,1,1,2,0,3,0,0,0,0,0,2,1,1,1,1
1,1,1,2,0,0,0,0,0,0,0,0,0,2,1,1,1
1,1,2,0,0,0,0,0,0,0,0,0,0,0,2,1,1
1,2,0,0,0,0,0,0,0,0,0,0,0,0,0,2,1
1,2,0,0,0,0,0,0,0,0,0,0,0,0,0,2,1
6,5,0,0,0,0,0,0,0,0,0,0,0,0,0,5,2
6,5,0,0,0,0,0,0,0,0,0,0,0,0,0,5,6
2,5,0,0,0,0,0,0,0,0,0,0,0,0,0,5,6
1,2,0,0,0,0,0,0,0,0,0,0,0,0,0,2,1
1,2,0,0,0,0,0,0,0,0,0,0,0,0,0,2,1
1,1,2,0,0,0,0,0,0,0,0,0,0,0,2,1,1
1,1,1,2,0,0,0,0,0,0,0,0,0,2,1,1,1
1,1,1,1,2,0,0,0,0,0,0,0,2,1,1,1,1
1,1,1,1,1,2,2,5,5,5,2,2,1,1,1,1,1
1,1,1,1,1,1,1,2,2,2,1,1,1,1,1,1,1
endlayer

layer
1,1,1,1,1,1,1,6,6,6,1,1,1,1,1,1,1
1,1,1,1,1,2,2,5,5,5,2,2,1,1,1,1,1
1,1,1,1,2,0,0,0,0,0,0,0,2,1,1,1,1
1,1,1,2,0,0,0,0,0,0,0,0,0,2,1,1,1
1,1,2,0,0,0,0,0,0,0,0,0,0,0,2,1,1
1,2,0,0,0,0,0,0,0,0,0,0,0,0,0,2,1
1,2,0,0,0,0,0,0,0,0,0,0,0,0,0,2,1
6,5,0,0,0,0,0,0,0,0,0,0,0,0,0,5,2
6,5,0,0,0,0,0,0,0,0,0,0,0,0,0,5,6
2,5,0,0,0,0,0,0,0,0,0,0,0,0,0,5,6
1,2,0,0,0,0,0,0,0,0,0,0,0,0,0,2,1
1,2,0,0,0,0,0,0,0,0,0,0,0,0,0,2,1
1,1,2,0,0,0,0,0,0,0,0,0,0,0,2,1,1
1,1,1,2,0,0,0,0,0,0,0,0,0,2,1,1,1
1,1,1,1,2,0,0,0,0,0,0,0,2,1,1,1,1
1,1,1,1,1,2,2,5,5,5,2,2,1,1,1,1,1
1,1,1,1,1,1,1,6,6,6,1,1,1,1,1,1,1
endlayer

layer
1,1,1,1,1,1,1,2,2,2,1,1,1,1,1,1,1
1,1,1,1,1,2,2,5,5,5,2,2,1,1,1,1,1
1,1,1,1,2,0,0,0,0,0,0,0,2,1,1,1,1
1,1,1,2,0,0,0,0,0,0,0,0,0,2,1,1,1
1,1,2,0,0,0,0,0,0,0,0,0,0,0,2,1,1
1,2,0,0,0,0,0,0,0,0,0,0,0,0,0,2,1
1,2,0,0,0,0,0,0,0,0,0,0,0,0,0,2,1
2,5,0,0,0,0,0,0,0,0,0,0,0,0,0,5,2
2,5,0,0,0,0,0,0,0,0,0,0,0,0,0,5,2
2,5,0,0,0,0,0,0,0,0,0,0,0,0,0,5,2
1,2,3,0,0,0,0,0,0,0,0,0,0,0,3,2,1
1,2,0,0,0,0,0,0,0,0,0,0,0,0,0,2,1
1,1,2,0,0,0,0,0,0,0,0,0,0,0,2,1,1
1,1,1,2,0,0,0,0,0,0,0,0,0,2,1,1,1
1,1,1,1,2,0,0,0,0,0,0,0,2,1,1,1,1
1,1,1,1,1,2,2,5,5,5,2,2,1,1,1,1,1
1,1,1,1,1,1,1,2,2,2,1,1,1,1,1,1,1
endlayer

layer
1,1,1,1,1,1,1,2,2,2,1,1,1,1,1,1,1
1,1,1,1,1,2,2,5,5,5,2,2,1,1,1,1,1
1,1,1,1,2,0,0,0,0,0,0,0,2,1,1,1,1
1,1,1,2,0,0,0,0,0,0,0,0,0,2,1,1,1
1,1,2,0,0,0,0,0,0,0,0,0,0,0,2,1,1
1,2,0,0,0,0,0,0,0,0,0,0,0,0,0,2,1
1,2,0,0,0,0,0,0,0,0,0,0,0,0,0,2,1
2,5,0,0,0,0,0,0,0,0,0,0,0,0,0,5,2
2,5,0,0,0,0,0,0,0,0,0,0,0,0,0,5,2
2,5,0,0,0,0,0,0,0,0,0,0,0,0,0,5,2
1,2,3,0,0,0,0,0,0,0,0,0,0,0,0,2,1
1,2,0,0,0,0,0,0,0,0,0,0,0,0,0,2,1
1,1,2,0,0,0,0,0,0,0,0,0,0,0,2,1,1
1,1,1,2,0,0,0,0,0,0,0,0,0,2,1,1,1
1,1,1,1,2,0,0,0,0,0,0,0,2,1,1,1,1
1,1,1,1,1,2,2,5,5,5,2,2,1,1,1,1,1
1,1,1,1,1,1,1,2,2,2,1,1,1,1,1,1,1
endlayer

layer
1,1,1,1,1,1,2,2,4,2,2,1,1,1,1,1,1
1,1,1,1,1,2,0,0,0,0,0,2,1,1,1,1,1
1,1,1,1,2,0,0,0,0,0,0,0,2,1,1,1,1
1,1,1,2,0,0,0,0,0,0,0,0,0,2,1,1,1
1,1,2,0,0,0,0,0,0,0,0,0,0,0,2,1,1
1,2,0,0,0,0,0,0,0,0,0,0,0,0,0,2,1
2,0,0,0,0,0,0,0,0,0,0,0,0,0,0,0,2
2,0,0,0,0,0,0,0,0,0,0,0,0,0,0,0,2
4,0,0,0,0,0,0,0,0,0,0,0,0,0,0,0,4
2,0,0,0,0,0,0,0,0,0,0,0,0,0,0,0,2
2,0,0,0,0,0,0,0,0,0,0,0,0,0,0,0,2
1,2,0,0,0,0,0,0,0,0,0,0,0,0,0,2,1
1,1,2,0,0,0,0,0,0,0,0,0,0,0,2,1,1
1,1,1,2,0,0,0,0,0,0,0,0,0,2,1,1,1
1,1,1,1,2,0,0,0,0,0,0,0,2,1,1,1,1
1,1,1,1,1,2,0,0,0,0,0,2,1,1,1,1,1
1,1,1,1,1,1,2,2,4,2,2,1,1,1,1,1,1
endlayer

layer
1,1,1,1,1,1,1,1,2,1,1,1,1,1,1,1,1
1,1,1,1,1,2,2,2,2,2,2,2,1,1,1,1,1
1,1,1,1,2,0,0,0,0,0,3,0,2,1,1,1,1
1,1,1,2,0,0,0,0,0,0,0,0,0,2,1,1,1
1,1,2,0,0,0,0,0,0,0,0,0,0,0,2,1,1
1,2,0,0,0,0,0,0,0,0,0,0,0,0,0,2,1
1,2,3,0,0,0,0,0,0,0,0,0,0,0,0,2,1
1,2,0,0,0,0,0,0,0,0,0,0,0,0,0,2,1
2,2,0,0,0,0,0,0,0,0,0,0,0,0,0,2,2
1,2,0,0,0,0,0,0,0,0,0,0,0,0,0,2,1
1,2,0,0,0,0,0,0,0,0,0,0,0,0,0,2,1
1,2,0,0,0,0,0,0,0,0,0,0,0,0,0,2,1
1,1,2,0,0,0,0,0,0,0,0,0,0,0,2,1,1
1,1,1,2,0,0,0,0,0,0,0,0,0,2,1,1,1
1,1,1,1,2,0,0,0,0,0,3,0,2,1,1,1,1
1,1,1,1,1,2,2,2,2,2,2,2,1,1,1,1,1
1,1,1,1,1,1,1,1,2,1,1,1,1,1,1,1,1
endlayer

layer
1,1,1,1,1,1,1,1,1,1,1,1,1,1,1,1,1
1,1,1,1,1,2,2,2,2,2,2,2,1,1,1,1,1
1,1,1,1,2,0,0,0,0,0,0,0,2,1,1,1,1
1,1,1,2,0,0,0,0,0,0,0,0,0,2,1,1,1
1,1,2,0,0,0,0,0,0,0,0,0,0,0,2,1,1
1,2,0,0,0,0,0,0,0,0,0,0,0,0,0,2,1
1,2,0,0,0,0,0,0,0,0,0,0,0,0,3,2,1
1,2,0,0,0,0,0,0,0,0,0,0,0,0,0,2,1
1,2,0,0,0,0,0,0,0,0,0,0,0,0,0,2,1
1,2,0,0,0,0,0,0,0,0,0,0,0,0,0,2,1
1,2,0,0,0,0,0,0,0,0,0,0,0,0,0,2,1
1,2,0,0,0,0,0,0,0,0,0,0,0,0,0,2,1
1,1,2,0,0,0,0,0,0,0,0,0,0,0,2,1,1
1,1,1,2,0,0,0,0,0,0,0,0,0,2,1,1,1
1,1,1,1,2,0,0,0,0,0,0,0,2,1,1,1,1
1,1,1,1,1,2,2,2,2,2,2,2,1,1,1,1,1
1,1,1,1,1,1,1,1,1,1,1,1,1,1,1,1,1
endlayer

layer
1,1,1,1,1,1,1,1,1,1,1,1,1,1,1,1,1
1,1,1,2,8,7,7,7,7,7,7,7,7,2,1,1,1
1,1,2,8,7,0,0,0,0,0,0,0,9,7,2,1,1
1,2,8,7,0,0,0,0,0,0,0,0,0,9,7,2,1
1,8,7,0,0,0,0,0,0,0,0,0,0,0,9,7,1
1,8,0,0,0,0,0,0,0,0,0,0,0,0,0,9,1
1,8,0,0,0,0,0,0,0,0,0,0,0,0,0,9,1
1,8,0,0,0,0,0,0,0,0,0,0,0,0,0,9,1
1,8,0,0,0,0,0,0,0,0,0,0,0,0,0,9,1
1,8,0,0,0,0,0,0,0,0,0,0,0,0,0,9,1
1,8,0,0,0,0,0,0,0,0,0,0,0,0,0,9,1
1,8,0,0,0,0,0,0,0,0,0,0,0,0,0,9,1
1,10,8,0,0,0,0,0,0,0,0,0,0,0,10,9,1
1,2,10,8,0,0,0,0,0,0,0,0,0,10,9,2,1
1,1,2,10,8,0,0,0,0,0,0,0,10,9,2,1,1
1,1,1,2,10,10,10,10,10,10,10,10,9,2,1,1,1
1,1,1,1,1,1,1,1,1,1,1,1,1,1,1,1,1
endlayer

layer
1,1,1,1,1,4,1,1,4,1,1,4,1,1,1,1,1
1,1,1,2,2,12,11,11,11,11,11,11,11,2,4,1,1
1,4,12,0,0,0,12,11,11,11,11,11,11,12,12,2,1
1,2,12,0,0,0,12,11,11,11,11,12,12,0,0,2,1
1,11,11,12,0,0,0,12,11,12,12,0,0,0,0,2,1
4,11,11,12,0,0,0,12,12,0,0,0,0,0,0,12,4
1,11,11,11,12,0,0,0,0,0,0,0,0,12,12,11,1
1,11,11,11,12,0,0,0,0,0,0,12,12,11,11,11,1
4,11,11,11,11,12,0,0,0,0,0,12,11,11,11,11,4
1,11,11,11,12,12,0,0,0,0,0,0,12,11,11,11,1
1,11,12,12,0,0,0,0,0,0,0,0,12,11,11,11,1
4,12,0,0,0,0,0,0,12,12,0,0,0,12,11,11,4
1,2,0,0,0,0,12,12,11,12,0,0,0,12,11,11,1
1,2,0,0,12,12,11,11,11,11,12,0,0,0,12,11,1
1,1,12,12,11,11,11,11,11,11,12,0,0,0,12,4,1
1,1,4,2,11,11,11,11,11,11,11,12,2,2,1,1,1
1,1,1,1,1,4,1,1,4,1,1,4,1,1,1,1,1
endlayer

layer
1,1,1,12,12,3,12,12,3,12,12,3,12,12,2,1,1
1,2,12,2,14,14,14,14,14,14,14,14,13,2,3,2,1
2,3,15,14,16,0,0,0,0,0,0,0,14,13,15,2,12
12,2,14,16,0,0,0,0,0,0,0,0,0,14,13,2,12
12,14,16,0,0,0,0,0,0,0,0,0,0,0,14,13,12
3,16,0,0,0,0,0,0,0,0,0,0,0,0,0,13,3
12,16,0,0,0,0,0,0,0,0,0,0,0,0,0,13,12
12,16,0,0,0,0,0,0,0,0,0,0,0,0,0,13,12
3,16,0,0,0,0,0,0,0,0,0,0,0,0,0,13,3
12,16,0,0,0,0,0,0,0,0,0,0,0,0,0,13,12
12,16,0,0,0,0,0,0,0,0,0,0,0,0,0,13,12
3,16,0,0,0,0,0,0,0,0,0,0,0,0,0,13,3
12,16,17,0,0,0,0,0,0,0,0,0,0,0,13,17,12
12,2,16,17,0,0,0,0,0,0,0,0,0,13,17,15,12
1,12,15,16,17,0,0,0,0,0,0,0,13,17,15,3,2
1,2,3,2,16,17,17,17,17,17,17,17,17,2,12,2,1
1,1,2,12,12,3,12,12,3,12,12,3,12,12,1,1,1
endlayer

layer
1,1,9,10,10,3,10,10,3,10,10,3,10,10,10,8,1
9,10,10,12,8,7,7,7,7,7,7,7,9,12,3,8,1
9,3,12,8,7,0,0,0,0,0,0,0,7,9,12,8,10
9,12,7,7,0,0,0,0,0,0,0,0,0,9,7,12,8
9,7,8,0,0,0,0,0,0,0,0,0,0,0,9,7,8
3,8,0,0,0,0,0,0,0,0,0,0,0,0,0,9,3
9,8,0,0,0,0,0,0,0,0,0,0,0,0,0,9,8
9,8,0,0,0,0,0,0,0,0,0,0,0,0,0,9,8
3,8,0,0,0,0,0,0,0,0,0,0,0,0,0,9,3
9,8,0,0,0,0,0,0,0,0,0,0,0,0,0,9,8
9,8,0,0,0,0,0,0,0,0,0,0,0,0,0,9,8
3,8,0,0,0,0,0,0,0,0,0,0,0,0,0,9,3
9,10,8,0,0,0,0,0,0,0,0,0,0,0,9,10,8
9,12,10,8,0,0,0,0,0,0,0,0,0,10,10,12,8
7,9,12,10,8,0,0,0,0,0,0,0,10,9,12,3,8
1,9,3,12,10,10,10,10,10,10,10,10,9,12,7,7,8
1,9,7,7,7,3,7,7,3,7,7,3,7,7,8,1,1
endlayer

