
# Created by Ruins mod version 16.7 Ingame Parser
# authoring Player: lafuller

weight=1
embed_into_distance=6
acceptable_target_blocks=
unacceptable_target_blocks=flowing_water,water,flowing_lava,lava,ice,bedrock,netherrack,nether_brick,nether_brick_fence,soul_sand,quartz_ore,end_stone,obsidian,iron_bars,cloud,flesh,ash_block,slime_grass,slime_congealed,slime_dirt
dimensions=24,23,23
allowable_overhang=0
max_leveling=6
leveling_buffer=-1
preserve_water=0
preserve_lava=0

rule1=0,100,preserveBlock
rule2=0,100,minecraft:sandstone_stairs-2
rule3=0,100,minecraft:double_stone_slab-9
rule4=0,100,minecraft:sandstone_stairs-3
rule5=0,100,minecraft:sandstone_stairs-0
rule6=0,100,minecraft:sandstone_stairs-1
rule7=0,100,minecraft:sandstone-2
rule8=0,100,minecraft:spruce_door-2
rule9=0,100,minecraft:sandstone-1
rule10=0,100,minecraft:sandstone_stairs-5
rule11=0,100,minecraft:sandstone_stairs-7
rule12=0,100,minecraft:sandstone_stairs-6
rule13=0,100,minecraft:sandstone_stairs-4
rule14=0,100,minecraft:spruce_door-9
rule15=0,100,minecraft:spruce_door-8
rule16=0,100,minecraft:sandstone-0
rule17=0,100,minecraft:trapdoor-8
rule18=0,100,minecraft:trapdoor-3
rule19=0,100,minecraft:trapdoor-2
rule20=0,100,minecraft:trapdoor-0
rule21=0,100,minecraft:spruce_fence_gate-1
rule22=0,100,minecraft:stone_slab-9
rule23=0,100,minecraft:stone_slab-1
rule24=0,100,minecraft:trapdoor-11
rule25=0,100,minecraft:trapdoor-10
rule26=0,100,minecraft:double_stone_slab-1
rule27=0,100,minecraft:spruce_fence-0
rule28=0,100,minecraft:spruce_stairs-3
rule29=0,100,minecraft:spruce_stairs-0
rule30=0,100,minecraft:spruce_stairs-2
rule31=0,100,minecraft:planks-1
rule32=0,100,minecraft:spruce_stairs-1
rule33=0,100,minecraft:wooden_slab-1
rule34=0,100,minecraft:spruce_stairs-5
rule35=0,100,minecraft:spruce_stairs-7
rule36=0,100,minecraft:spruce_stairs-6
rule37=0,100,minecraft:spruce_stairs-4
rule38=0,100,minecraft:wooden_slab-9

layer
1,1,1,1,1,4,3,3,3,3,3,3,3,3,3,3,3,2,1,1,1,1,1
1,1,1,1,1,4,3,3,3,3,3,3,3,3,3,3,3,2,1,1,1,1,1
1,1,1,1,1,4,3,3,3,3,3,3,3,3,3,3,3,2,1,1,1,1,1
1,1,1,1,3,3,3,3,3,3,3,3,3,3,3,3,3,3,3,1,1,1,1
1,1,1,3,3,3,3,3,3,3,3,3,3,3,3,3,3,3,3,3,1,1,1
5,5,5,3,3,3,3,3,3,3,3,3,3,3,3,3,3,3,3,3,5,5,5
3,3,3,3,3,3,3,3,3,3,3,3,3,3,3,3,3,3,3,3,3,3,3
3,3,3,3,3,3,3,3,3,3,3,3,3,3,3,3,3,3,3,3,3,3,3
3,3,3,3,3,3,3,3,3,3,3,3,3,3,3,3,3,3,3,3,3,3,3
3,3,3,3,3,3,3,3,3,3,3,3,3,3,3,3,3,3,3,3,3,3,3
3,3,3,3,3,3,3,3,3,3,3,3,3,3,3,3,3,3,3,3,3,3,3
3,3,3,3,3,3,3,3,3,3,3,3,3,3,3,3,3,3,3,3,3,3,3
3,3,3,3,3,3,3,3,3,3,3,3,3,3,3,3,3,3,3,3,3,3,3
3,3,3,3,3,3,3,3,3,3,3,3,3,3,3,3,3,3,3,3,3,3,3
3,3,3,3,3,3,3,3,3,3,3,3,3,3,3,3,3,3,3,3,3,3,3
3,3,3,3,3,3,3,3,3,3,3,3,3,3,3,3,3,3,3,3,3,3,3
3,3,3,3,3,3,3,3,3,3,3,3,3,3,3,3,3,3,3,3,3,3,3
6,6,6,3,3,3,3,3,3,3,3,3,3,3,3,3,3,3,3,3,6,6,6
1,1,1,3,3,3,3,3,3,3,3,3,3,3,3,3,3,3,3,3,1,1,1
1,1,1,1,3,3,3,3,3,3,3,3,3,3,3,3,3,3,3,1,1,1,1
1,1,1,1,1,4,3,3,3,3,3,3,3,3,3,3,3,2,1,1,1,1,1
1,1,1,1,1,4,3,3,3,3,3,3,3,3,3,3,3,2,1,1,1,1,1
1,1,1,1,1,4,3,3,3,3,3,3,3,3,3,3,3,2,1,1,1,1,1
endlayer

layer
1,1,1,1,1,1,4,3,3,3,3,3,3,3,3,3,2,1,1,1,1,1,1
1,1,1,1,1,1,4,3,3,3,3,3,3,3,3,3,2,1,1,1,1,1,1
1,1,1,1,1,1,4,3,3,3,3,3,3,3,3,3,2,1,1,1,1,1,1
1,1,1,1,3,3,3,3,3,3,3,3,3,3,3,3,3,3,3,1,1,1,1
1,1,1,3,3,3,6,6,3,6,6,3,6,6,3,3,3,3,3,3,1,1,1
1,1,1,3,3,0,0,0,0,0,0,0,0,0,0,4,3,3,3,3,1,1,1
5,5,5,3,2,0,0,0,0,0,0,0,0,0,0,4,6,6,4,3,5,5,5
3,3,3,3,2,0,0,0,0,0,0,0,0,0,0,0,0,0,4,3,3,3,3
3,3,3,3,3,0,0,0,0,0,0,0,0,0,0,0,0,0,3,3,3,3,3
3,3,3,3,2,0,0,0,0,0,0,0,0,0,0,0,0,0,4,3,3,3,3
3,3,3,3,2,0,0,0,0,0,0,0,0,0,0,0,0,0,4,3,3,3,3
3,3,3,3,3,0,0,0,0,0,0,0,0,0,0,0,0,0,3,3,3,3,3
3,3,3,3,2,0,0,0,0,0,0,0,0,0,0,0,0,0,4,3,3,3,3
3,3,3,3,2,0,0,0,0,0,0,0,0,0,0,0,0,0,4,3,3,3,3
3,3,3,3,3,0,0,0,0,0,0,0,0,0,0,0,0,0,3,3,3,3,3
3,3,3,3,2,0,0,0,0,0,0,0,0,0,0,0,0,0,4,3,3,3,3
6,6,6,3,2,0,0,0,0,0,0,0,0,0,0,0,0,0,4,3,6,6,6
1,1,1,3,3,0,0,0,0,0,0,0,0,0,0,0,0,0,3,3,1,1,1
1,1,1,3,3,3,5,5,3,5,5,3,5,5,3,5,5,3,3,3,1,1,1
1,1,1,1,3,3,3,3,3,3,3,3,3,3,3,3,3,3,3,1,1,1,1
1,1,1,1,1,1,4,3,3,3,3,3,3,3,3,3,2,1,1,1,1,1,1
1,1,1,1,1,1,4,3,3,3,3,3,3,3,3,3,2,1,1,1,1,1,1
1,1,1,1,1,1,4,3,3,3,3,3,3,3,3,3,2,1,1,1,1,1,1
endlayer

layer
1,1,1,1,1,1,1,4,3,3,3,3,3,3,3,2,1,1,1,1,1,1,1
1,1,1,1,1,1,1,4,3,3,3,3,3,3,3,2,1,1,1,1,1,1,1
1,1,1,1,1,1,1,3,3,3,3,3,3,3,3,3,1,1,1,1,1,1,1
1,1,1,1,3,3,3,3,3,3,3,3,3,3,3,3,3,3,3,1,1,1,1
1,1,1,3,3,7,0,0,7,0,0,7,0,0,7,3,3,3,3,3,1,1,1
1,1,1,3,7,0,0,0,0,0,0,0,0,0,0,0,6,6,7,3,1,1,1
1,1,1,3,0,0,0,0,0,0,0,0,0,0,0,0,0,0,0,3,1,1,1
5,5,3,3,0,0,0,0,0,0,0,0,0,0,0,0,0,0,0,3,3,5,5
3,3,3,3,7,0,0,0,0,0,0,0,0,0,0,0,0,0,7,3,3,3,3
3,3,3,3,0,0,0,0,0,0,0,0,0,0,0,0,0,0,0,3,3,3,3
3,3,3,3,0,0,0,0,0,0,0,0,0,0,0,0,0,0,0,3,3,3,3
3,3,3,3,7,0,0,0,0,0,0,0,0,0,0,0,0,0,7,3,3,3,3
3,3,3,3,0,0,0,0,0,0,0,0,0,0,0,0,0,0,0,3,3,3,3
3,3,3,3,0,0,0,0,0,0,0,0,0,0,0,0,0,0,0,3,3,3,3
3,3,3,3,7,0,0,0,0,0,0,0,0,0,0,0,0,0,7,3,3,3,3
6,6,3,3,0,0,0,0,0,0,0,0,0,0,0,0,0,0,0,3,3,6,6
1,1,1,3,0,0,0,0,0,0,0,0,0,0,0,0,0,0,0,3,1,1,1
1,1,1,3,7,0,0,0,0,0,0,0,0,0,0,0,0,0,7,3,1,1,1
1,1,1,3,3,7,0,0,7,0,0,7,0,0,7,0,0,7,3,3,1,1,1
1,1,1,1,3,3,3,3,3,3,3,3,3,3,3,3,3,3,3,1,1,1,1
1,1,1,1,1,1,1,3,3,3,3,3,3,3,3,3,1,1,1,1,1,1,1
1,1,1,1,1,1,1,4,3,3,3,3,3,3,3,2,1,1,1,1,1,1,1
1,1,1,1,1,1,1,4,3,3,3,3,3,3,3,2,1,1,1,1,1,1,1
endlayer

layer
1,1,1,1,1,1,1,1,5,5,5,5,5,5,5,1,1,1,1,1,1,1,1
1,1,1,1,1,1,1,1,4,3,3,3,3,3,2,1,1,1,1,1,1,1,1
1,1,1,1,1,1,1,3,3,3,3,3,3,3,3,3,1,1,1,1,1,1,1
1,1,1,1,3,3,3,3,3,3,3,3,3,3,3,3,3,3,3,1,1,1,1
1,1,1,3,3,7,0,0,7,0,0,7,0,0,7,3,6,6,3,3,1,1,1
1,1,1,3,7,0,0,0,0,0,0,0,0,0,0,0,0,0,7,3,1,1,1
1,1,1,3,0,0,0,0,0,0,0,0,0,0,0,0,0,0,0,3,1,1,1
1,1,3,3,0,0,0,0,0,0,0,0,0,0,0,0,0,0,0,3,3,1,1
4,5,3,3,7,0,0,0,0,0,0,0,0,0,0,0,0,0,7,3,3,5,2
4,3,3,3,0,0,0,0,0,0,0,0,0,0,0,0,0,0,0,3,3,3,2
4,3,3,3,0,0,0,0,0,0,0,0,0,0,0,0,0,0,0,3,3,3,2
4,3,3,3,7,0,0,0,0,0,0,0,0,0,0,0,0,0,7,3,3,3,2
4,3,3,3,0,0,0,0,0,0,0,0,0,0,0,0,0,0,0,3,3,3,2
4,3,3,3,0,0,0,0,0,0,0,0,0,0,0,0,0,0,0,3,3,3,2
4,6,3,3,7,0,0,0,0,0,0,0,0,0,0,0,0,0,7,3,3,6,2
1,1,3,3,0,0,0,0,0,0,0,0,0,0,0,0,0,0,0,3,3,1,1
1,1,1,3,0,0,0,0,0,0,0,0,0,0,0,0,0,0,0,3,1,1,1
1,1,1,3,7,0,0,0,0,0,0,0,0,0,0,0,0,0,7,3,1,1,1
1,1,1,3,3,7,0,0,7,0,0,7,0,0,7,0,0,7,3,3,1,1,1
1,1,1,1,3,3,3,3,3,3,3,3,3,3,3,3,3,3,3,1,1,1,1
1,1,1,1,1,1,1,3,3,3,3,3,3,3,3,3,1,1,1,1,1,1,1
1,1,1,1,1,1,1,1,4,3,3,3,3,3,2,1,1,1,1,1,1,1,1
1,1,1,1,1,1,1,1,6,6,6,6,6,6,6,1,1,1,1,1,1,1,1
endlayer

layer
1,1,1,1,1,1,1,1,1,1,1,1,1,1,1,1,1,1,1,1,1,1,1
1,1,1,1,1,1,1,1,1,4,5,5,5,2,1,1,1,1,1,1,1,1,1
1,1,1,1,1,1,1,3,3,3,3,3,3,3,3,3,1,1,1,1,1,1,1
1,1,1,1,3,1,1,3,3,3,3,3,3,3,3,3,8,8,3,1,1,1,1
1,1,1,3,3,9,10,10,9,10,10,9,10,10,9,3,0,0,3,3,1,1,1
1,1,1,1,9,0,0,0,0,0,0,0,0,0,0,0,0,0,9,1,1,1,1
1,1,1,1,12,0,0,0,0,0,0,0,0,0,0,0,0,0,11,1,1,1,1
1,1,3,3,12,0,0,0,0,0,0,0,0,0,0,0,0,0,11,3,3,1,1
1,1,3,3,9,0,0,0,0,0,0,0,0,0,0,0,0,0,9,3,3,1,1
1,5,3,3,12,0,0,0,0,0,0,0,0,0,0,0,0,0,11,3,3,5,1
1,4,3,3,12,0,0,0,0,0,0,0,0,0,0,0,0,0,11,3,3,2,1
1,4,3,3,9,0,0,0,0,0,0,0,0,0,0,0,0,0,9,3,3,2,1
1,4,3,3,12,0,0,0,0,0,0,0,0,0,0,0,0,0,11,3,3,2,1
1,6,3,3,12,0,0,0,0,0,0,0,0,0,0,0,0,0,11,3,3,6,1
1,1,3,3,9,0,0,0,0,0,0,0,0,0,0,0,0,0,9,3,3,1,1
1,1,3,3,12,0,0,0,0,0,0,0,0,0,0,0,0,0,11,3,3,1,1
1,1,1,1,12,0,0,0,0,0,0,0,0,0,0,0,0,0,11,1,1,1,1
1,1,1,1,9,0,0,0,0,0,0,0,0,0,0,0,0,0,9,1,1,1,1
1,1,1,3,3,9,13,13,9,13,13,9,13,13,9,13,13,9,3,3,1,1,1
1,1,1,1,3,1,1,3,3,3,3,3,3,3,3,3,1,1,3,1,1,1,1
1,1,1,1,1,1,1,3,3,3,3,3,3,3,3,3,1,1,1,1,1,1,1
1,1,1,1,1,1,1,1,1,4,6,6,6,2,1,1,1,1,1,1,1,1,1
1,1,1,1,1,1,1,1,1,1,1,1,1,1,1,1,1,1,1,1,1,1,1
endlayer

layer
1,1,1,1,1,1,1,1,1,1,1,1,1,1,1,1,1,1,1,1,1,1,1
1,1,1,1,1,1,1,1,1,1,1,1,1,1,1,1,1,1,1,1,1,1,1
1,1,1,1,1,1,1,3,3,3,5,5,5,3,3,3,1,1,1,1,1,1,1
1,1,1,1,3,1,1,3,3,3,3,3,3,3,3,3,15,14,3,1,1,1,1
1,1,1,3,3,3,3,3,3,3,3,3,3,3,3,3,0,0,3,3,1,1,1
1,1,1,1,3,3,3,3,3,3,3,3,3,3,12,0,0,0,3,1,1,1,1
1,1,1,1,3,3,3,3,3,3,3,16,3,3,12,0,0,0,3,1,1,1,1
1,1,3,3,3,3,3,18,3,3,3,3,3,3,12,17,0,0,3,3,3,1,1
1,1,3,3,3,3,3,3,3,3,3,3,3,3,3,13,13,13,3,3,3,1,1
1,1,3,3,3,3,3,3,3,3,3,3,3,3,3,3,3,3,3,3,3,1,1
1,1,4,3,3,3,3,3,3,3,3,3,3,3,3,3,3,3,3,3,2,1,1
1,1,4,3,3,3,3,3,3,3,3,3,3,3,3,3,16,3,3,3,2,1,1
1,1,4,3,3,3,3,3,3,3,3,3,3,3,3,3,3,3,3,3,2,1,1
1,1,3,3,3,3,3,3,3,3,3,3,3,3,3,3,3,3,3,3,3,1,1
1,1,3,3,3,3,3,3,3,3,3,3,3,3,3,3,3,3,3,3,3,1,1
1,1,3,3,3,3,3,20,3,3,3,3,3,3,3,19,3,3,3,3,3,1,1
1,1,1,1,3,3,3,3,3,3,3,3,3,3,3,3,3,3,3,1,1,1,1
1,1,1,1,3,3,3,3,3,3,3,3,3,3,3,3,3,3,3,1,1,1,1
1,1,1,3,3,3,3,3,3,3,3,3,3,3,3,3,3,3,3,3,1,1,1
1,1,1,1,3,1,1,3,3,3,3,3,3,3,3,3,1,1,3,1,1,1,1
1,1,1,1,1,1,1,3,3,3,6,6,6,3,3,3,1,1,1,1,1,1,1
1,1,1,1,1,1,1,1,1,1,1,1,1,1,1,1,1,1,1,1,1,1,1
1,1,1,1,1,1,1,1,1,1,1,1,1,1,1,1,1,1,1,1,1,1,1
endlayer

layer
1,1,1,1,1,1,1,1,1,1,1,1,1,1,1,1,1,1,1,1,1,1,1
1,1,1,1,1,1,1,1,1,1,1,1,1,1,1,1,1,1,1,1,1,1,1
1,1,1,1,1,1,1,3,3,3,1,1,1,3,3,3,1,1,1,1,1,1,1
1,1,1,1,3,1,1,3,3,3,5,5,5,3,3,3,21,21,3,1,1,1,1
1,1,1,3,3,3,3,3,3,3,3,3,3,3,3,3,0,0,3,3,1,1,1
1,1,1,1,3,3,3,3,3,3,3,3,3,3,3,3,22,22,3,1,1,1,1
1,1,1,1,3,3,3,3,3,3,3,16,3,3,3,3,13,13,3,1,1,1,1
1,1,3,3,3,3,3,24,2,6,23,23,23,6,4,17,3,3,3,3,3,1,1
1,1,3,3,3,3,3,6,2,0,0,0,0,0,4,6,3,3,3,3,3,1,1
1,1,3,3,3,3,3,2,0,0,23,23,23,0,0,4,3,3,3,3,3,1,1
1,1,1,4,3,3,3,23,0,23,23,23,23,23,0,23,3,3,3,2,1,1,1
1,1,1,4,3,3,3,23,0,23,23,23,23,23,0,23,16,3,3,2,1,1,1
1,1,1,4,3,3,3,23,0,23,23,23,23,23,0,23,3,3,3,2,1,1,1
1,1,3,3,3,3,3,2,0,0,23,23,23,0,0,4,3,3,3,3,3,1,1
1,1,3,3,3,3,3,5,2,0,0,0,0,0,5,4,3,3,3,3,3,1,1
1,1,3,3,3,3,3,17,5,5,23,23,23,5,4,25,3,3,3,3,3,1,1
1,1,1,1,3,3,3,3,3,3,3,3,3,3,3,3,3,3,3,1,1,1,1
1,1,1,1,3,3,3,3,3,3,3,3,3,3,3,3,3,3,3,1,1,1,1
1,1,1,3,3,3,3,3,3,3,3,3,3,3,3,3,3,3,3,3,1,1,1
1,1,1,1,3,1,1,3,3,3,6,6,6,3,3,3,1,1,3,1,1,1,1
1,1,1,1,1,1,1,3,3,3,1,1,1,3,3,3,1,1,1,1,1,1,1
1,1,1,1,1,1,1,1,1,1,1,1,1,1,1,1,1,1,1,1,1,1,1
1,1,1,1,1,1,1,1,1,1,1,1,1,1,1,1,1,1,1,1,1,1,1
endlayer

layer
1,1,1,1,1,1,1,1,1,0,0,0,0,0,1,1,1,1,1,1,1,1,1
1,1,1,1,1,1,11,13,13,12,0,0,0,11,13,13,12,1,1,1,1,1,1
1,1,1,1,1,1,11,3,3,3,0,0,0,3,3,3,12,1,1,1,1,1,1
1,1,1,1,3,12,22,3,3,2,0,0,0,4,3,3,22,11,3,1,1,1,1
1,1,1,3,3,3,3,3,3,2,0,0,0,4,3,3,3,3,3,3,1,1,1
1,1,1,10,3,3,3,3,3,3,0,0,0,3,3,3,3,3,3,10,1,1,1
1,13,13,22,3,3,6,6,23,0,0,0,0,0,23,6,6,3,3,22,13,13,1
1,11,3,3,3,3,2,0,0,0,0,0,0,0,0,0,4,3,3,3,3,12,1
1,11,3,3,3,3,23,0,0,0,0,0,0,0,0,0,23,3,3,3,3,12,1
0,10,3,6,6,3,0,0,0,0,0,0,0,0,0,0,0,3,6,6,3,10,0
0,0,0,0,0,0,0,0,0,0,0,0,0,0,0,0,0,0,0,0,0,0,0
0,0,0,0,0,0,0,0,0,0,0,0,0,0,0,0,0,0,0,0,0,0,0
0,0,0,0,0,0,0,0,0,0,0,0,0,0,0,0,0,0,0,0,0,0,0
0,13,3,5,5,3,0,0,0,0,0,0,0,0,0,0,0,3,5,5,3,13,0
1,11,3,3,3,3,23,0,0,0,0,0,0,0,0,0,23,3,3,3,3,12,1
1,11,3,3,3,3,2,0,0,0,0,0,0,0,0,0,4,3,3,3,3,12,1
1,10,10,22,3,3,5,5,23,0,0,0,0,0,23,5,26,3,3,22,10,10,1
1,1,1,13,3,3,3,3,3,3,0,0,0,3,3,3,3,3,3,13,1,1,1
1,1,1,3,3,3,3,3,3,2,0,0,0,4,3,3,3,3,3,3,1,1,1
1,1,1,1,3,12,22,3,3,2,0,0,0,4,3,3,22,11,3,1,1,1,1
1,1,1,1,1,1,11,3,3,3,0,0,0,3,3,3,12,1,1,1,1,1,1
1,1,1,1,1,1,11,10,10,12,0,0,0,11,10,10,12,1,1,1,1,1,1
1,1,1,1,1,1,1,1,1,0,0,0,0,0,1,1,1,1,1,1,1,1,1
endlayer

layer
1,1,1,1,1,1,1,1,0,0,0,0,0,0,0,1,1,1,1,1,1,1,1
1,1,1,1,1,1,1,1,0,0,0,0,0,0,0,1,1,1,1,1,1,1,1
1,1,1,1,1,1,1,3,3,0,0,0,0,0,3,3,1,1,1,1,1,1,1
1,1,1,1,3,2,4,3,3,0,0,0,0,0,3,3,2,4,3,1,1,1,1
1,1,1,3,3,3,3,3,2,0,0,0,0,0,4,3,3,3,3,3,1,1,1
1,1,1,6,3,3,6,6,6,9,0,0,0,9,6,6,6,3,3,6,1,1,1
1,1,1,5,3,2,0,0,0,0,0,0,0,0,0,0,0,4,3,5,1,1,1
1,1,3,3,3,2,0,0,0,0,0,0,0,0,0,0,0,4,3,3,3,1,1
0,0,3,3,6,2,0,0,0,0,0,0,0,0,0,0,0,4,6,3,3,0,0
0,0,0,0,0,9,0,0,0,0,0,0,0,0,0,0,0,9,0,0,0,0,0
0,0,0,0,0,0,0,0,0,0,0,0,0,0,0,0,0,0,0,0,0,0,0
0,0,0,0,0,0,0,0,0,0,0,0,0,0,0,0,0,0,0,0,0,0,0
0,0,0,0,0,0,0,0,0,0,0,0,0,0,0,0,0,0,0,0,0,0,0
0,0,0,0,0,9,0,0,0,0,0,0,0,0,0,0,0,9,0,0,0,0,0
0,0,3,3,5,2,0,0,0,0,0,0,0,0,0,0,0,5,5,3,3,0,0
1,1,3,3,3,2,0,0,0,0,0,0,0,0,0,0,0,4,3,3,3,1,1
1,1,1,6,3,2,0,0,0,0,0,0,0,0,0,0,0,4,3,6,1,1,1
1,1,1,5,3,3,5,5,5,9,0,0,0,9,5,5,5,3,3,5,1,1,1
1,1,1,3,3,3,3,3,2,0,0,0,0,0,4,3,3,3,3,3,1,1,1
1,1,1,1,3,2,4,3,3,0,0,0,0,0,3,3,2,4,3,1,1,1,1
1,1,1,1,1,1,1,3,3,0,0,0,0,0,3,3,1,1,1,1,1,1,1
1,1,1,1,1,1,1,1,0,0,0,0,0,0,0,1,1,1,1,1,1,1,1
1,1,1,1,1,1,1,1,0,0,0,0,0,0,0,1,1,1,1,1,1,1,1
endlayer

layer
1,1,1,1,1,1,1,0,0,0,0,0,0,0,0,0,1,1,1,1,1,1,1
1,1,1,1,1,1,1,0,0,0,0,0,0,0,0,0,1,1,1,1,1,1,1
1,1,1,1,1,1,1,3,3,0,0,0,0,0,3,3,1,1,1,1,1,1,1
1,1,1,1,3,12,11,3,3,0,0,0,0,0,3,3,12,11,3,1,1,1,1
1,1,1,3,3,6,6,2,0,0,0,0,0,0,0,4,6,6,3,3,1,1,1
1,1,1,10,2,0,0,0,0,23,0,0,0,23,0,0,0,0,4,10,1,1,1
1,1,1,13,2,0,0,0,0,0,0,0,0,0,0,0,0,0,4,13,1,1,1
0,0,3,3,6,0,0,0,0,0,0,0,0,0,0,0,0,0,6,3,3,0,0
0,0,3,3,0,0,0,0,0,0,0,0,0,0,0,0,0,0,0,3,3,0,0
0,0,0,0,0,23,0,0,0,0,0,0,0,0,0,0,0,23,0,0,0,0,0
0,0,0,0,0,0,0,0,0,0,0,0,0,0,0,0,0,0,0,0,0,0,0
0,0,0,0,0,0,0,0,0,0,0,0,0,0,0,0,0,0,0,0,0,0,0
0,0,0,0,0,0,0,0,0,0,0,0,0,0,0,0,0,0,0,0,0,0,0
0,0,0,0,0,23,0,0,0,0,0,0,0,0,0,0,0,23,0,0,0,0,0
0,0,3,3,0,0,0,0,0,0,0,0,0,0,0,0,0,0,0,3,3,0,0
0,0,3,3,5,0,0,0,0,0,0,0,0,0,0,0,0,0,4,3,3,0,0
1,1,1,10,2,0,0,0,0,0,0,0,0,0,0,0,0,0,4,10,1,1,1
1,1,1,13,2,0,0,0,0,23,0,0,0,23,0,0,0,0,4,13,1,1,1
1,1,1,3,3,5,5,2,0,0,0,0,0,0,0,4,5,5,3,3,1,1,1
1,1,1,1,3,12,11,3,3,0,0,0,0,0,3,3,12,11,3,1,1,1,1
1,1,1,1,1,1,1,3,3,0,0,0,0,0,3,3,1,1,1,1,1,1,1
1,1,1,1,1,1,1,0,0,0,0,0,0,0,0,0,1,1,1,1,1,1,1
1,1,1,1,1,1,1,0,0,0,0,0,0,0,0,0,1,1,1,1,1,1,1
endlayer

layer
1,1,1,1,1,1,1,0,0,0,0,0,0,0,0,0,1,1,1,1,1,1,1
1,1,1,1,1,1,1,0,0,0,0,0,0,0,0,0,1,1,1,1,1,1,1
1,1,1,1,1,1,1,3,3,0,0,0,0,0,3,3,1,1,1,1,1,1,1
1,1,1,1,6,6,6,3,3,0,0,0,0,0,3,3,6,6,4,1,1,1,1
1,1,1,6,2,0,0,0,0,0,0,0,0,0,0,0,0,0,6,4,1,1,1
1,1,1,2,0,0,0,0,0,0,0,0,0,0,0,0,0,0,0,4,1,1,1
1,1,1,2,0,0,0,0,0,0,0,0,0,0,0,0,0,0,0,4,1,1,1
0,0,3,3,0,0,0,0,0,0,0,0,0,0,0,0,0,0,0,3,3,0,0
0,0,3,3,0,0,0,0,0,0,0,0,0,0,0,0,0,0,0,3,3,0,0
0,0,0,0,0,0,0,0,0,0,0,0,0,0,0,0,0,0,0,0,0,0,0
0,0,0,0,0,0,0,0,0,0,0,0,0,0,0,0,0,0,0,0,0,0,0
0,0,0,0,0,0,0,0,0,0,0,0,0,0,0,0,0,0,0,0,0,0,0
0,0,0,0,0,0,0,0,0,0,0,0,0,0,0,0,0,0,0,0,0,0,0
0,0,0,0,0,0,0,0,0,0,0,0,0,0,0,0,0,0,0,0,0,0,0
0,0,3,3,0,0,0,0,0,0,0,0,0,0,0,0,0,0,0,3,3,0,0
0,0,3,3,0,0,0,0,0,0,0,0,0,0,0,0,0,0,0,3,3,0,0
1,1,1,2,0,0,0,0,0,0,0,0,0,0,0,0,0,0,0,4,1,1,1
1,1,1,2,0,0,0,0,0,0,0,0,0,0,0,0,0,0,0,4,1,1,1
1,1,1,5,2,0,0,0,0,0,0,0,0,0,0,0,0,0,5,4,1,1,1
1,1,1,1,5,5,5,3,3,0,0,0,0,0,3,3,5,5,4,1,1,1,1
1,1,1,1,1,1,1,3,3,0,0,0,0,0,3,3,1,1,1,1,1,1,1
1,1,1,1,1,1,1,0,0,0,0,0,0,0,0,0,1,1,1,1,1,1,1
1,1,1,1,1,1,1,0,0,0,0,0,0,0,0,0,1,1,1,1,1,1,1
endlayer

layer
1,1,1,1,1,1,0,0,0,0,0,0,0,0,0,0,0,1,1,1,1,1,1
1,1,1,1,1,0,0,0,0,0,0,0,0,0,0,0,0,0,1,1,1,1,1
1,1,1,1,0,0,0,3,3,0,0,0,0,0,3,3,0,0,0,1,1,1,1
1,1,1,0,27,27,27,3,3,0,0,0,0,0,3,3,27,27,27,0,1,1,1
1,1,0,27,27,0,0,0,0,0,0,0,0,0,0,0,0,0,27,27,0,1,1
1,0,0,27,0,0,0,0,0,0,0,0,0,0,0,0,0,0,0,27,0,0,1
0,0,0,27,0,0,0,0,0,0,0,0,0,0,0,0,0,0,0,27,0,0,0
0,0,3,3,0,0,0,0,0,0,0,0,0,0,0,0,0,0,0,3,3,0,0
0,0,3,3,0,0,0,0,0,0,0,0,0,0,0,0,0,0,0,3,3,0,0
0,0,0,0,0,0,0,0,0,0,0,0,0,0,0,0,0,0,0,0,0,0,0
0,0,0,0,0,0,0,0,0,0,0,0,0,0,0,0,0,0,0,0,0,0,0
0,0,0,0,0,0,0,0,0,0,0,0,0,0,0,0,0,0,0,0,0,0,0
0,0,0,0,0,0,0,0,0,0,0,0,0,0,0,0,0,0,0,0,0,0,0
0,0,0,0,0,0,0,0,0,0,0,0,0,0,0,0,0,0,0,0,0,0,0
0,0,3,3,0,0,0,0,0,0,0,0,0,0,0,0,0,0,0,3,3,0,0
0,0,3,3,0,0,0,0,0,0,0,0,0,0,0,0,0,0,0,3,3,0,0
0,0,0,27,0,0,0,0,0,0,0,0,0,0,0,0,0,0,0,27,0,0,0
1,0,0,27,0,0,0,0,0,0,0,0,0,0,0,0,0,0,0,27,0,0,1
1,1,0,27,27,0,0,0,0,0,0,0,0,0,0,0,0,0,27,27,0,1,1
1,1,1,0,27,27,27,3,3,0,0,0,0,0,3,3,27,27,27,0,1,1,1
1,1,1,1,0,0,0,3,3,0,0,0,0,0,3,3,0,0,0,1,1,1,1
1,1,1,1,1,0,0,0,0,0,0,0,0,0,0,0,0,0,1,1,1,1,1
1,1,1,1,1,1,0,0,0,0,0,0,0,0,0,0,0,1,1,1,1,1,1
endlayer

layer
1,1,1,1,1,0,0,0,0,0,0,0,0,0,0,0,0,0,1,1,1,1,1
1,1,1,1,0,0,0,0,0,0,0,0,0,0,0,0,0,0,0,1,1,1,1
1,1,1,0,0,0,0,3,3,0,0,0,0,0,3,3,0,0,0,0,1,1,1
1,1,0,0,0,0,0,3,3,0,0,0,0,0,3,3,0,0,0,0,0,1,1
1,0,0,0,0,0,0,0,0,0,0,0,0,0,0,0,0,0,0,0,0,0,1
0,0,0,0,0,0,0,0,0,0,0,0,0,0,0,0,0,0,0,0,0,0,0
0,0,0,0,0,0,0,0,0,0,0,0,0,0,0,0,0,0,0,0,0,0,0
0,0,3,3,0,0,0,0,0,0,0,0,0,0,0,0,0,0,0,3,3,0,0
0,0,3,3,0,0,0,0,0,0,0,0,0,0,0,0,0,0,0,3,3,0,0
0,0,0,0,0,0,0,0,0,0,0,0,0,0,0,0,0,0,0,0,0,0,0
0,0,0,0,0,0,0,0,0,0,0,0,0,0,0,0,0,0,0,0,0,0,0
0,0,0,0,0,0,0,0,0,0,0,0,0,0,0,0,0,0,0,0,0,0,0
0,0,0,0,0,0,0,0,0,0,0,0,0,0,0,0,0,0,0,0,0,0,0
0,0,0,0,0,0,0,0,0,0,0,0,0,0,0,0,0,0,0,0,0,0,0
0,0,3,3,0,0,0,0,0,0,0,0,0,0,0,0,0,0,0,3,3,0,0
0,0,3,3,0,0,0,0,0,0,0,0,0,0,0,0,0,0,0,3,3,0,0
0,0,0,0,0,0,0,0,0,0,0,0,0,0,0,0,0,0,0,0,0,0,0
0,0,0,0,0,0,0,0,0,0,0,0,0,0,0,0,0,0,0,0,0,0,0
1,0,0,0,0,0,0,0,0,0,0,0,0,0,0,0,0,0,0,0,0,0,1
1,1,0,0,0,0,0,3,3,0,0,0,0,0,3,3,0,0,0,0,0,1,1
1,1,1,0,0,0,0,3,3,0,0,0,0,0,3,3,0,0,0,0,1,1,1
1,1,1,1,0,0,0,0,0,0,0,0,0,0,0,0,0,0,0,1,1,1,1
1,1,1,1,1,0,0,0,0,0,0,0,0,0,0,0,0,0,1,1,1,1,1
endlayer

layer
1,1,1,1,0,0,0,0,0,0,0,0,0,0,0,0,0,0,0,1,1,1,1
1,1,1,0,0,0,0,0,0,0,0,0,0,0,0,0,0,0,0,0,1,1,1
1,1,0,0,0,0,0,9,3,0,0,0,0,0,3,9,0,0,0,0,0,1,1
1,0,0,0,0,0,0,3,3,0,0,0,0,0,3,3,0,0,0,0,0,0,1
0,0,0,0,0,0,0,0,0,0,0,0,0,0,0,0,0,0,0,0,0,0,0
0,0,0,0,0,0,0,0,0,0,0,0,0,0,0,0,0,0,0,0,0,0,0
0,0,0,0,0,0,0,0,0,0,0,0,0,0,0,0,0,0,0,0,0,0,0
0,0,9,3,0,0,0,0,0,0,0,0,0,0,0,0,0,0,0,3,9,0,0
0,0,3,3,0,0,0,0,0,0,0,0,0,0,0,0,0,0,0,3,3,0,0
0,0,0,0,0,0,0,0,0,0,0,0,0,0,0,0,0,0,0,0,0,0,0
0,0,0,0,0,0,0,0,0,0,0,0,0,0,0,0,0,0,0,0,0,0,0
0,0,0,0,0,0,0,0,0,0,0,0,0,0,0,0,0,0,0,0,0,0,0
0,0,0,0,0,0,0,0,0,0,0,0,0,0,0,0,0,0,0,0,0,0,0
0,0,0,0,0,0,0,0,0,0,0,0,0,0,0,0,0,0,0,0,0,0,0
0,0,3,3,0,0,0,0,0,0,0,0,0,0,0,0,0,0,0,3,3,0,0
0,0,9,3,0,0,0,0,0,0,0,0,0,0,0,0,0,0,0,3,9,0,0
0,0,0,0,0,0,0,0,0,0,0,0,0,0,0,0,0,0,0,0,0,0,0
0,0,0,0,0,0,0,0,0,0,0,0,0,0,0,0,0,0,0,0,0,0,0
0,0,0,0,0,0,0,0,0,0,0,0,0,0,0,0,0,0,0,0,0,0,0
1,0,0,0,0,0,0,3,3,0,0,0,0,0,3,3,0,0,0,0,0,0,1
1,1,0,0,0,0,0,9,3,0,0,0,0,0,3,9,0,0,0,0,0,1,1
1,1,1,0,0,0,0,0,0,0,0,0,0,0,0,0,0,0,0,0,1,1,1
1,1,1,1,0,0,0,0,0,0,0,0,0,0,0,0,0,0,0,1,1,1,1
endlayer

layer
1,1,1,0,0,0,0,0,0,22,22,22,22,22,0,0,0,0,0,0,1,1,1
1,1,0,0,0,0,0,13,13,22,22,22,22,22,13,13,0,0,0,0,0,1,1
1,0,0,0,0,22,11,3,3,12,22,22,22,11,3,3,12,22,0,0,0,0,1
0,0,0,0,22,22,11,3,3,12,0,0,0,11,3,3,12,22,22,0,0,0,0
0,0,0,22,22,22,22,10,10,0,0,0,0,0,10,10,22,22,22,22,0,0,0
0,0,22,22,22,22,0,0,0,0,0,0,0,0,0,0,0,0,22,22,22,0,0
0,0,13,13,22,0,0,0,0,0,0,0,0,0,0,0,0,0,22,13,13,0,0
0,11,3,3,12,0,0,0,0,0,0,0,0,0,0,0,0,0,11,3,3,12,0
0,11,3,3,12,0,0,0,0,0,0,0,0,0,0,0,0,0,11,3,3,12,0
22,22,10,10,0,0,0,0,0,0,0,0,0,0,0,0,0,0,0,10,10,22,22
22,22,22,0,0,0,0,0,0,0,0,0,0,0,0,0,0,0,0,0,22,22,22
22,22,22,0,0,0,0,0,0,0,0,0,0,0,0,0,0,0,0,0,22,22,22
22,22,22,0,0,0,0,0,0,0,0,0,0,0,0,0,0,0,0,0,22,22,22
22,22,13,13,0,0,0,0,0,0,0,0,0,0,0,0,0,0,0,13,13,22,22
0,11,3,3,12,0,0,0,0,0,0,0,0,0,0,0,0,0,11,3,3,12,0
0,11,3,3,12,0,0,0,0,0,0,0,0,0,0,0,0,0,11,3,3,12,0
0,0,10,10,22,0,0,0,0,0,0,0,0,0,0,0,0,0,22,10,10,0,0
0,0,22,22,22,22,0,0,0,0,0,0,0,0,0,0,0,22,22,22,22,0,0
0,0,0,22,22,22,22,13,13,0,0,0,0,0,13,13,22,22,22,22,0,0,0
0,0,0,0,22,22,11,3,3,12,0,0,0,11,3,3,12,22,22,0,0,0,0
1,0,0,0,0,22,11,3,3,12,22,22,22,11,3,3,12,22,0,0,0,0,1
1,1,0,0,0,0,0,10,10,22,22,22,22,22,10,10,0,0,0,0,0,1,1
1,1,1,0,0,0,0,0,0,22,22,22,22,22,0,0,0,0,0,0,1,1,1
endlayer

layer
1,1,0,0,0,0,0,0,0,0,2,0,4,0,0,0,0,0,0,0,0,1,1
1,0,0,0,0,0,0,22,22,0,0,0,0,0,22,22,0,0,0,0,0,0,1
0,0,0,0,0,0,22,3,3,22,0,0,0,22,3,3,22,0,0,0,0,0,0
0,0,0,0,4,0,22,3,3,22,0,0,0,22,3,3,22,0,2,0,0,0,0
0,0,0,5,0,0,0,22,22,0,0,0,0,0,22,22,0,0,0,5,0,0,0
0,0,0,0,0,0,0,0,0,0,0,0,0,0,0,0,0,0,0,0,0,0,0
0,0,22,22,0,0,0,0,0,0,0,0,0,0,0,0,0,0,0,22,22,0,0
0,22,3,3,22,0,0,0,0,0,0,0,0,0,0,0,0,0,22,3,3,22,0
0,22,3,3,22,0,0,0,0,0,0,0,0,0,0,0,0,0,22,3,3,22,0
0,0,22,22,0,0,0,0,0,0,0,0,0,0,0,0,0,0,0,22,22,0,0
6,0,0,0,0,0,0,0,0,0,0,0,0,0,0,0,0,0,0,0,0,0,6
0,0,0,0,0,0,0,0,0,0,0,0,0,0,0,0,0,0,0,0,0,0,0
5,0,0,0,0,0,0,0,0,0,0,0,0,0,0,0,0,0,0,0,0,0,5
0,0,22,22,0,0,0,0,0,0,0,0,0,0,0,0,0,0,0,22,22,0,0
0,22,3,3,22,0,0,0,0,0,0,0,0,0,0,0,0,0,22,3,3,22,0
0,22,3,3,22,0,0,0,0,0,0,0,0,0,0,0,0,0,22,3,3,22,0
0,0,22,22,0,0,0,0,0,0,0,0,0,0,0,0,0,0,0,22,22,0,0
0,0,0,0,0,0,0,0,0,0,0,0,0,0,0,0,0,0,0,0,0,0,0
0,0,0,6,0,0,0,22,22,0,0,0,0,0,22,22,0,0,0,6,0,0,0
0,0,0,0,4,0,22,3,3,22,0,0,0,22,3,3,22,0,2,0,0,0,0
0,0,0,0,0,0,22,3,3,22,0,0,0,22,3,3,22,0,0,0,0,0,0
1,0,0,0,0,0,0,22,22,0,0,0,0,0,22,22,0,0,0,0,0,0,1
1,1,0,0,0,0,0,0,0,0,2,0,4,0,0,0,0,0,0,0,0,1,1
endlayer

layer
1,0,0,0,0,0,0,0,0,11,22,22,22,12,0,0,0,0,0,0,0,0,1
0,0,0,0,0,0,0,11,13,3,3,3,3,3,13,12,0,0,0,0,0,0,0
0,0,0,0,0,13,13,3,3,3,3,3,3,3,3,3,13,13,0,0,0,0,0
0,0,0,0,22,3,3,3,3,3,3,9,3,3,3,3,3,3,22,0,0,0,0
0,0,0,22,3,3,3,9,3,0,0,0,0,0,3,9,3,3,3,22,0,0,0
0,0,11,3,3,3,0,0,0,0,0,0,0,0,0,0,0,3,3,3,12,0,0
0,0,11,3,3,0,0,0,0,0,0,0,0,0,0,0,0,0,3,3,12,0,0
0,13,3,3,9,0,0,0,0,0,0,0,0,0,0,0,0,0,9,3,3,13,0
0,11,3,3,3,0,0,0,0,0,0,0,0,0,0,0,0,0,3,3,3,12,0
13,3,3,3,0,0,0,0,0,0,0,0,0,0,0,0,0,0,0,3,3,3,13
22,3,3,3,0,0,0,0,0,0,0,0,0,0,0,0,0,0,0,3,3,3,22
22,3,3,9,0,0,0,0,0,0,0,0,0,0,0,0,0,0,0,9,3,3,22
22,3,3,3,0,0,0,0,0,0,0,0,0,0,0,0,0,0,0,3,3,3,22
10,3,3,3,0,0,0,0,0,0,0,0,0,0,0,0,0,0,0,3,3,3,10
0,11,3,3,3,0,0,0,0,0,0,0,0,0,0,0,0,0,3,3,3,12,0
0,10,3,3,9,0,0,0,0,0,0,0,0,0,0,0,0,0,9,3,3,10,0
0,0,11,3,3,0,0,0,0,0,0,0,0,0,0,0,0,0,3,3,12,0,0
0,0,11,3,3,3,0,0,0,0,0,0,0,0,0,0,0,3,3,3,12,0,0
0,0,0,22,3,3,3,9,3,0,0,0,0,0,3,9,3,3,3,22,0,0,0
0,0,0,0,22,3,3,3,3,3,3,9,3,3,3,3,3,3,22,0,0,0,0
0,0,0,0,0,10,10,3,3,3,3,3,3,3,3,3,10,10,0,0,0,0,0
0,0,0,0,0,0,0,11,10,3,3,3,3,3,10,12,0,0,0,0,0,0,0
1,0,0,0,0,0,0,0,0,11,22,22,22,12,0,0,0,0,0,0,0,0,1
endlayer

layer
0,0,0,0,0,0,0,0,0,0,0,0,0,0,0,0,0,0,0,0,0,0,0
0,0,0,0,0,0,0,5,5,30,30,29,28,28,5,5,0,0,0,0,0,0,0
0,0,0,0,0,0,4,3,3,31,31,31,31,31,3,3,2,0,0,0,0,0,0
0,0,0,0,0,28,31,3,3,2,0,0,0,4,3,3,31,30,0,0,0,0,0
0,0,0,0,31,31,31,6,6,0,0,0,0,0,6,6,31,31,31,0,0,0,0
0,0,0,29,31,31,0,0,0,0,0,0,0,0,0,0,0,31,31,29,0,0,0
0,0,5,31,31,0,0,0,0,0,0,0,0,0,0,0,0,0,31,31,5,0,0
0,4,3,3,2,0,0,0,0,0,0,0,0,0,0,0,0,0,4,3,3,2,0
0,4,3,3,2,0,0,0,0,0,0,0,0,0,0,0,0,0,4,3,3,2,0
0,32,31,6,0,0,0,0,0,0,0,0,0,0,0,0,0,0,0,6,31,32,0
0,32,31,0,0,0,0,0,0,0,0,0,0,0,0,0,0,0,0,0,31,32,0
0,28,31,0,0,0,0,0,0,0,0,0,0,0,0,0,0,0,0,0,31,30,0
0,29,31,0,0,0,0,0,0,0,0,0,0,0,0,0,0,0,0,0,31,29,0
0,29,31,5,0,0,0,0,0,0,0,0,0,0,0,0,0,0,0,5,31,29,0
0,4,3,3,2,0,0,0,0,0,0,0,0,0,0,0,0,0,4,3,3,2,0
0,4,3,3,2,0,0,0,0,0,0,0,0,0,0,0,0,0,4,3,3,2,0
0,0,6,31,31,0,0,0,0,0,0,0,0,0,0,0,0,0,31,31,6,0,0
0,0,0,32,31,31,0,0,0,0,0,0,0,0,0,0,0,31,31,32,0,0,0
0,0,0,0,31,31,31,5,5,0,0,0,0,0,5,5,31,31,31,0,0,0,0
0,0,0,0,0,28,31,3,3,2,0,0,0,4,3,3,31,30,0,0,0,0,0
0,0,0,0,0,0,4,3,3,31,31,31,31,31,3,3,2,0,0,0,0,0,0
0,0,0,0,0,0,0,6,6,30,30,32,28,28,6,6,0,0,0,0,0,0,0
0,0,0,0,0,0,0,0,0,0,0,0,0,0,0,0,0,0,0,0,0,0,0
endlayer

layer
0,0,0,0,0,0,0,0,0,0,0,0,0,0,0,0,0,0,0,0,0,0,0
0,0,0,0,0,0,0,0,0,0,0,0,0,0,0,0,0,0,0,0,0,0,0
0,0,0,0,0,0,0,7,5,30,28,33,30,28,5,7,0,0,0,0,0,0,0
0,0,0,0,0,0,33,3,31,34,34,34,34,34,31,3,33,0,0,0,0,0,0
0,0,0,0,0,28,28,34,10,0,0,0,0,0,10,34,30,30,0,0,0,0,0
0,0,0,0,29,31,34,0,0,0,0,0,0,0,0,0,34,31,29,0,0,0,0
0,0,0,33,29,36,0,0,0,0,0,0,0,0,0,0,0,35,29,33,0,0,0
0,0,7,3,36,0,0,0,0,0,0,0,0,0,0,0,0,0,35,3,7,0,0
0,0,4,31,12,0,0,0,0,0,0,0,0,0,0,0,0,0,11,31,2,0,0
0,0,32,36,0,0,0,0,0,0,0,0,0,0,0,0,0,0,0,35,32,0,0
0,0,29,36,0,0,0,0,0,0,0,0,0,0,0,0,0,0,0,35,29,0,0
0,0,33,36,0,0,0,0,0,0,0,0,0,0,0,0,0,0,0,35,33,0,0
0,0,32,36,0,0,0,0,0,0,0,0,0,0,0,0,0,0,0,35,32,0,0
0,0,29,36,0,0,0,0,0,0,0,0,0,0,0,0,0,0,0,35,29,0,0
0,0,4,31,12,0,0,0,0,0,0,0,0,0,0,0,0,0,11,31,2,0,0
0,0,7,3,36,0,0,0,0,0,0,0,0,0,0,0,0,0,35,3,7,0,0
0,0,0,33,32,36,0,0,0,0,0,0,0,0,0,0,0,35,32,33,0,0,0
0,0,0,0,32,31,37,0,0,0,0,0,0,0,0,0,37,31,32,0,0,0,0
0,0,0,0,0,28,28,37,13,0,0,0,0,0,13,37,30,30,0,0,0,0,0
0,0,0,0,0,0,33,3,31,37,37,37,37,37,31,3,33,0,0,0,0,0,0
0,0,0,0,0,0,0,7,6,30,28,33,30,28,6,7,0,0,0,0,0,0,0
0,0,0,0,0,0,0,0,0,0,0,0,0,0,0,0,0,0,0,0,0,0,0
0,0,0,0,0,0,0,0,0,0,0,0,0,0,0,0,0,0,0,0,0,0,0
endlayer

layer
0,0,0,0,0,0,0,0,0,0,0,0,0,0,0,0,0,0,0,0,0,0,0
0,0,0,0,0,0,0,0,0,0,0,0,0,0,0,0,0,0,0,0,0,0,0
0,0,0,0,0,0,0,13,0,0,0,0,0,0,0,13,0,0,0,0,0,0,0
0,0,0,0,0,0,0,23,3,33,30,33,28,33,3,23,0,0,0,0,0,0,0
0,0,0,0,0,0,0,33,3,3,34,34,34,3,3,33,0,0,0,0,0,0,0
0,0,0,0,0,0,28,34,34,10,0,0,0,10,34,34,30,0,0,0,0,0,0
0,0,0,0,0,29,38,0,0,0,0,0,0,0,0,0,38,29,0,0,0,0,0
0,0,11,23,33,36,0,0,0,0,0,0,0,0,0,0,0,35,33,23,12,0,0
0,0,0,3,3,36,0,0,0,0,0,0,0,0,0,0,0,35,3,3,0,0,0
0,0,0,33,3,12,0,0,0,0,0,0,0,0,0,0,0,11,3,33,0,0,0
0,0,0,32,36,0,0,0,0,0,0,0,0,0,0,0,0,0,35,32,0,0,0
0,0,0,33,36,0,0,0,0,0,0,0,0,0,0,0,0,0,35,33,0,0,0
0,0,0,29,36,0,0,0,0,0,0,0,0,0,0,0,0,0,35,29,0,0,0
0,0,0,33,3,12,0,0,0,0,0,0,0,0,0,0,0,11,3,33,0,0,0
0,0,0,3,3,36,0,0,0,0,0,0,0,0,0,0,0,35,3,3,0,0,0
0,0,11,23,33,36,0,0,0,0,0,0,0,0,0,0,0,35,33,23,12,0,0
0,0,0,0,0,32,38,0,0,0,0,0,0,0,0,0,38,32,0,0,0,0,0
0,0,0,0,0,0,28,37,37,13,0,0,0,13,37,37,30,0,0,0,0,0,0
0,0,0,0,0,0,0,33,3,3,37,37,37,3,3,33,0,0,0,0,0,0,0
0,0,0,0,0,0,0,23,3,33,30,33,28,33,3,23,0,0,0,0,0,0,0
0,0,0,0,0,0,0,10,0,0,0,0,0,0,0,10,0,0,0,0,0,0,0
0,0,0,0,0,0,0,0,0,0,0,0,0,0,0,0,0,0,0,0,0,0,0
0,0,0,0,0,0,0,0,0,0,0,0,0,0,0,0,0,0,0,0,0,0,0
endlayer

layer
0,0,0,0,0,0,0,0,0,0,0,0,0,0,0,0,0,0,0,0,0,0,0
0,0,0,0,0,0,0,0,0,0,0,0,0,0,0,0,0,0,0,0,0,0,0
0,0,0,0,0,0,0,0,0,0,0,0,0,0,0,0,0,0,0,0,0,0,0
0,0,0,0,0,0,0,0,0,0,0,0,0,0,0,0,0,0,0,0,0,0,0
0,0,0,0,0,0,0,0,7,5,0,0,0,5,7,0,0,0,0,0,0,0,0
0,0,0,0,0,0,0,0,33,3,29,33,29,3,33,0,0,0,0,0,0,0,0
0,0,0,0,0,0,0,29,31,3,28,0,30,3,31,29,0,0,0,0,0,0,0
0,0,0,0,0,0,28,0,31,10,38,38,38,10,31,0,30,0,0,0,0,0,0
0,0,0,0,7,33,31,31,38,0,22,0,22,0,38,31,31,33,7,0,0,0,0
0,0,0,0,4,3,3,12,0,0,22,22,22,0,0,11,3,3,2,0,0,0,0
0,0,0,0,0,28,29,38,22,22,0,0,0,22,22,38,29,30,0,0,0,0,0
0,0,0,0,0,33,0,38,0,22,0,0,0,22,0,38,0,33,0,0,0,0,0
0,0,0,0,0,28,32,38,22,22,0,0,0,22,22,38,32,30,0,0,0,0,0
0,0,0,0,4,3,3,12,0,0,22,22,22,0,0,11,3,3,2,0,0,0,0
0,0,0,0,7,33,31,31,38,0,22,0,22,0,38,31,31,33,7,0,0,0,0
0,0,0,0,0,0,28,0,31,13,38,38,38,13,31,0,30,0,0,0,0,0,0
0,0,0,0,0,0,0,32,31,3,28,0,30,3,31,32,0,0,0,0,0,0,0
0,0,0,0,0,0,0,0,33,3,32,33,32,3,33,0,0,0,0,0,0,0,0
0,0,0,0,0,0,0,0,7,6,0,0,0,6,7,0,0,0,0,0,0,0,0
0,0,0,0,0,0,0,0,0,0,0,0,0,0,0,0,0,0,0,0,0,0,0
0,0,0,0,0,0,0,0,0,0,0,0,0,0,0,0,0,0,0,0,0,0,0
0,0,0,0,0,0,0,0,0,0,0,0,0,0,0,0,0,0,0,0,0,0,0
0,0,0,0,0,0,0,0,0,0,0,0,0,0,0,0,0,0,0,0,0,0,0
endlayer

layer
0,0,0,0,0,0,0,0,0,0,0,0,0,0,0,0,0,0,0,0,0,0,0
0,0,0,0,0,0,0,0,0,0,0,0,0,0,0,0,0,0,0,0,0,0,0
0,0,0,0,0,0,0,0,0,0,0,0,0,0,0,0,0,0,0,0,0,0,0
0,0,0,0,0,0,0,0,0,0,0,0,0,0,0,0,0,0,0,0,0,0,0
0,0,0,0,0,0,0,0,13,0,0,0,0,0,13,0,0,0,0,0,0,0,0
0,0,0,0,0,0,0,0,0,0,0,0,0,0,0,0,0,0,0,0,0,0,0
0,0,0,0,0,0,0,0,0,5,0,0,0,5,0,0,0,0,0,0,0,0,0
0,0,0,0,0,0,0,0,33,3,0,0,0,3,33,0,0,0,0,0,0,0,0
0,0,0,0,11,0,0,33,33,31,3,33,3,31,33,33,0,0,12,0,0,0,0
0,0,0,0,0,0,4,3,31,31,3,3,3,31,31,3,2,0,0,0,0,0,0
0,0,0,0,0,0,0,0,3,3,34,34,34,3,3,0,0,0,0,0,0,0,0
0,0,0,0,0,0,0,0,33,3,36,0,35,3,33,0,0,0,0,0,0,0,0
0,0,0,0,0,0,0,0,3,3,37,37,37,3,3,0,0,0,0,0,0,0,0
0,0,0,0,0,0,4,3,31,31,3,3,3,31,31,3,2,0,0,0,0,0,0
0,0,0,0,11,0,0,33,33,31,3,33,3,31,33,33,0,0,12,0,0,0,0
0,0,0,0,0,0,0,0,33,3,0,0,0,3,33,0,0,0,0,0,0,0,0
0,0,0,0,0,0,0,0,0,6,0,0,0,6,0,0,0,0,0,0,0,0,0
0,0,0,0,0,0,0,0,0,0,0,0,0,0,0,0,0,0,0,0,0,0,0
0,0,0,0,0,0,0,0,10,0,0,0,0,0,10,0,0,0,0,0,0,0,0
0,0,0,0,0,0,0,0,0,0,0,0,0,0,0,0,0,0,0,0,0,0,0
0,0,0,0,0,0,0,0,0,0,0,0,0,0,0,0,0,0,0,0,0,0,0
0,0,0,0,0,0,0,0,0,0,0,0,0,0,0,0,0,0,0,0,0,0,0
0,0,0,0,0,0,0,0,0,0,0,0,0,0,0,0,0,0,0,0,0,0,0
endlayer

layer
0,0,0,0,0,0,0,0,0,0,0,0,0,0,0,0,0,0,0,0,0,0,0
0,0,0,0,0,0,0,0,0,0,0,0,0,0,0,0,0,0,0,0,0,0,0
0,0,0,0,0,0,0,0,0,0,0,0,0,0,0,0,0,0,0,0,0,0,0
0,0,0,0,0,0,0,0,0,0,0,0,0,0,0,0,0,0,0,0,0,0,0
0,0,0,0,0,0,0,0,0,0,0,0,0,0,0,0,0,0,0,0,0,0,0
0,0,0,0,0,0,0,0,0,0,0,0,0,0,0,0,0,0,0,0,0,0,0
0,0,0,0,0,0,0,0,0,0,0,0,0,0,0,0,0,0,0,0,0,0,0
0,0,0,0,0,0,0,0,0,13,0,0,0,13,0,0,0,0,0,0,0,0,0
0,0,0,0,0,0,0,0,0,0,23,0,23,0,0,0,0,0,0,0,0,0,0
0,0,0,0,0,0,0,11,0,0,3,0,3,0,0,12,0,0,0,0,0,0,0
0,0,0,0,0,0,0,0,23,3,0,0,0,3,23,0,0,0,0,0,0,0,0
0,0,0,0,0,0,0,0,0,0,0,0,0,0,0,0,0,0,0,0,0,0,0
0,0,0,0,0,0,0,0,23,3,0,0,0,3,23,0,0,0,0,0,0,0,0
0,0,0,0,0,0,0,11,0,0,3,0,3,0,0,12,0,0,0,0,0,0,0
0,0,0,0,0,0,0,0,0,0,23,0,23,0,0,0,0,0,0,0,0,0,0
0,0,0,0,0,0,0,0,0,10,0,0,0,10,0,0,0,0,0,0,0,0,0
0,0,0,0,0,0,0,0,0,0,0,0,0,0,0,0,0,0,0,0,0,0,0
0,0,0,0,0,0,0,0,0,0,0,0,0,0,0,0,0,0,0,0,0,0,0
0,0,0,0,0,0,0,0,0,0,0,0,0,0,0,0,0,0,0,0,0,0,0
0,0,0,0,0,0,0,0,0,0,0,0,0,0,0,0,0,0,0,0,0,0,0
0,0,0,0,0,0,0,0,0,0,0,0,0,0,0,0,0,0,0,0,0,0,0
0,0,0,0,0,0,0,0,0,0,0,0,0,0,0,0,0,0,0,0,0,0,0
0,0,0,0,0,0,0,0,0,0,0,0,0,0,0,0,0,0,0,0,0,0,0
endlayer

layer
0,0,0,0,0,0,0,0,0,0,0,0,0,0,0,0,0,0,0,0,0,0,0
0,0,0,0,0,0,0,0,0,0,0,0,0,0,0,0,0,0,0,0,0,0,0
0,0,0,0,0,0,0,0,0,0,0,0,0,0,0,0,0,0,0,0,0,0,0
0,0,0,0,0,0,0,0,0,0,0,0,0,0,0,0,0,0,0,0,0,0,0
0,0,0,0,0,0,0,0,0,0,0,0,0,0,0,0,0,0,0,0,0,0,0
0,0,0,0,0,0,0,0,0,0,0,0,0,0,0,0,0,0,0,0,0,0,0
0,0,0,0,0,0,0,0,0,0,0,0,0,0,0,0,0,0,0,0,0,0,0
0,0,0,0,0,0,0,0,0,0,0,0,0,0,0,0,0,0,0,0,0,0,0
0,0,0,0,0,0,0,0,0,0,0,0,0,0,0,0,0,0,0,0,0,0,0
0,0,0,0,0,0,0,0,0,0,11,23,12,0,0,0,0,0,0,0,0,0,0
0,0,0,0,0,0,0,0,0,13,0,0,0,13,0,0,0,0,0,0,0,0,0
0,0,0,0,0,0,0,0,0,23,0,0,0,23,0,0,0,0,0,0,0,0,0
0,0,0,0,0,0,0,0,0,10,0,0,0,10,0,0,0,0,0,0,0,0,0
0,0,0,0,0,0,0,0,0,0,11,23,12,0,0,0,0,0,0,0,0,0,0
0,0,0,0,0,0,0,0,0,0,0,0,0,0,0,0,0,0,0,0,0,0,0
0,0,0,0,0,0,0,0,0,0,0,0,0,0,0,0,0,0,0,0,0,0,0
0,0,0,0,0,0,0,0,0,0,0,0,0,0,0,0,0,0,0,0,0,0,0
0,0,0,0,0,0,0,0,0,0,0,0,0,0,0,0,0,0,0,0,0,0,0
0,0,0,0,0,0,0,0,0,0,0,0,0,0,0,0,0,0,0,0,0,0,0
0,0,0,0,0,0,0,0,0,0,0,0,0,0,0,0,0,0,0,0,0,0,0
0,0,0,0,0,0,0,0,0,0,0,0,0,0,0,0,0,0,0,0,0,0,0
0,0,0,0,0,0,0,0,0,0,0,0,0,0,0,0,0,0,0,0,0,0,0
0,0,0,0,0,0,0,0,0,0,0,0,0,0,0,0,0,0,0,0,0,0,0
endlayer

