
# Created by Ruins mod version 16.5 Ingame Parser
# authoring Player: lafuller

weight=1
embed_into_distance=4
acceptable_target_blocks=
unacceptable_target_blocks=flowing_water,water,flowing_lava,lava,ice,bedrock,netherrack,nether_brick,nether_brick_fence,soul_sand,quartz_ore,gravel,end_stone,obsidian,iron_bars,cloud,flesh,ash_block,slime_grass,slime_congealed,slime_dirt
biomesToSpawnIn=desert
dimensions=14,11,11
allowable_overhang=0
max_leveling=7
leveling_buffer=-1
preserve_water=0
preserve_lava=0

rule1=0,100,preserveBlock
rule2=0,100,minecraft:sandstone-1
rule3=0,100,minecraft:sandstone-0
rule4=0,100,minecraft:double_stone_slab-9
rule5=0,100,minecraft:ladder-5
rule6=1,100,minecraft:hay_block-0,air,air,air
rule7=1,100,minecraft:hay_block-8,air,air,air
rule8=1,100,minecraft:hay_block-4,air,air,air
rule9=0,100,minecraft:iron_bars-0
rule10=0,100,minecraft:sandstone_stairs-0
rule11=0,100,minecraft:sandstone_stairs-2
rule12=0,100,minecraft:sandstone_stairs-3
rule13=0,100,minecraft:sandstone_stairs-1
rule14=0,100,minecraft:sandstone_stairs-6
rule15=0,100,minecraft:sandstone_stairs-7
rule16=0,100,minecraft:sandstone_stairs-5
rule17=0,100,minecraft:stone_slab-1
rule18=0,100,minecraft:sandstone-2
rule19=0,100,minecraft:spruce_fence-0
rule20=0,100,minecraft:sandstone_stairs-4
rule21=0,100,minecraft:wooden_slab-1

layer
1,1,1,2,3,3,3,2,1,1,1
1,3,3,3,3,3,3,3,3,3,1
1,3,3,3,3,3,3,3,3,3,1
2,3,3,3,3,3,3,3,3,3,2
3,3,3,3,3,3,3,3,3,3,3
3,3,3,3,3,3,3,3,3,3,3
3,3,3,3,3,3,3,3,3,3,3
2,3,3,3,3,3,3,3,3,3,2
1,3,3,3,3,3,3,3,3,3,1
1,3,3,3,3,3,3,3,3,3,1
1,1,1,2,3,3,3,2,1,1,1
endlayer

layer
1,1,1,4,3,3,3,4,1,1,1
1,4,4,4,0,5,0,4,4,4,1
1,4,7,0,0,0,0,0,6,4,1
4,4,0,0,0,0,0,0,7,4,4
3,7,6,0,0,0,0,0,0,8,3
3,6,0,0,0,0,0,0,0,0,3
3,8,0,0,0,0,0,0,0,6,3
4,4,0,0,0,0,0,0,6,4,4
1,4,6,0,0,0,6,7,6,4,1
1,4,4,4,0,7,8,4,4,4,1
1,1,1,4,3,3,3,4,1,1,1
endlayer

layer
1,1,1,4,3,3,3,4,1,1,1
1,4,4,4,0,5,0,4,4,4,1
1,4,6,0,0,0,0,0,8,4,1
4,4,0,0,0,0,0,0,0,4,4
3,0,0,0,0,0,0,0,0,6,3
3,7,0,0,0,0,0,0,0,0,3
3,0,0,0,0,0,0,0,0,0,3
4,4,0,0,0,0,0,0,0,4,4
1,4,0,0,0,0,0,0,8,4,1
1,4,4,4,0,0,6,4,4,4,1
1,1,1,4,3,3,3,4,1,1,1
endlayer

layer
1,1,1,4,3,3,3,4,1,1,1
1,4,4,4,0,5,0,4,4,4,1
1,4,0,0,0,0,0,0,0,4,1
4,4,0,0,0,0,0,0,0,4,4
3,0,0,0,0,0,0,0,0,0,3
3,0,0,0,0,0,0,0,0,0,3
3,0,0,0,0,0,0,0,0,0,3
4,4,0,0,0,0,0,0,0,4,4
1,4,0,0,0,0,0,0,0,4,1
1,4,4,4,0,0,0,4,4,4,1
1,1,1,4,3,3,3,4,1,1,1
endlayer

layer
1,1,1,4,3,3,3,4,1,1,1
1,4,4,4,0,5,0,4,4,4,1
1,4,0,0,0,0,0,0,0,4,1
4,4,0,0,0,0,0,0,0,4,4
3,0,0,0,0,0,0,0,0,0,3
3,0,0,0,0,0,0,0,0,0,3
3,0,0,0,0,0,0,0,0,0,3
4,4,0,0,0,0,0,0,0,4,4
1,4,0,0,0,0,0,0,0,4,1
1,4,4,4,0,0,0,4,4,4,1
1,1,1,4,3,3,3,4,1,1,1
endlayer

layer
1,1,1,4,4,4,4,4,1,1,1
1,4,4,4,4,5,4,4,4,4,1
1,4,4,4,9,9,9,4,4,4,1
4,4,4,9,0,0,0,9,4,4,4
4,4,9,0,0,0,0,0,9,4,4
4,4,9,0,0,0,0,0,9,4,4
4,4,9,0,0,0,0,0,9,4,4
4,4,4,9,0,0,0,9,4,4,4
1,4,4,4,9,9,9,4,4,4,1
1,4,4,4,4,4,4,4,4,4,1
1,1,1,4,4,4,4,4,1,1,1
endlayer

layer
1,1,1,4,4,0,4,4,1,1,1
1,2,4,4,0,0,0,4,4,2,1
1,4,4,0,0,0,0,0,4,4,1
4,4,0,0,0,0,0,0,0,4,4
4,0,0,0,0,0,0,0,0,0,4
4,0,0,0,0,0,0,0,0,0,4
4,0,0,0,0,0,0,0,0,0,4
4,4,0,0,0,0,0,0,0,4,4
1,4,4,0,0,0,0,0,4,4,1
1,2,4,4,0,0,0,4,4,2,1
1,1,1,4,4,4,4,4,1,1,1
endlayer

layer
1,1,1,2,4,0,4,2,1,1,1
1,4,10,4,0,0,0,4,10,4,1
1,12,4,0,0,0,0,0,4,11,1
2,4,0,0,0,0,0,0,0,4,2
4,0,0,0,0,0,0,0,0,0,4
4,0,0,0,0,0,0,0,0,0,4
4,0,0,0,0,0,0,0,0,0,4
2,4,0,0,0,0,0,0,0,4,2
1,12,4,0,0,0,0,0,4,11,1
1,4,13,4,0,0,0,4,13,4,1
1,1,1,2,4,4,4,2,1,1,1
endlayer

layer
1,1,1,4,4,4,4,4,1,1,1
1,4,10,4,0,0,0,4,10,4,1
1,12,4,0,0,0,0,0,4,11,1
4,4,0,0,0,0,0,0,0,4,4
15,0,0,0,0,0,0,0,0,0,14
4,0,0,0,0,0,0,0,0,0,4
15,0,0,0,0,0,0,0,0,0,14
4,4,0,0,0,0,0,0,0,4,4
1,12,4,0,0,0,0,0,4,11,1
1,4,13,4,0,0,0,4,13,4,1
1,1,1,4,16,4,16,4,1,1,1
endlayer

layer
1,1,1,4,2,2,2,4,1,1,1
1,4,4,4,4,4,4,4,4,4,1
1,4,2,0,0,0,0,0,2,4,1
4,4,0,0,0,0,0,0,0,4,4
2,4,0,0,0,0,0,0,0,4,2
2,4,0,0,0,0,0,0,0,4,2
2,4,0,0,0,0,0,0,0,4,2
4,4,0,0,0,0,0,0,0,4,4
1,4,2,0,0,0,0,0,2,4,1
1,4,4,4,4,4,4,4,4,4,1
1,1,1,4,2,2,2,4,1,1,1
endlayer

layer
1,1,1,1,17,1,17,1,1,1,1
1,18,10,2,4,4,4,2,10,18,1
1,12,18,16,19,0,19,16,18,11,1
1,2,14,0,0,0,0,0,15,2,1
17,4,19,0,0,0,0,0,19,4,17
1,4,0,0,0,0,0,0,0,4,1
17,4,19,0,0,0,0,0,19,4,17
1,2,14,0,0,0,0,0,15,2,1
1,12,18,20,19,0,19,20,18,11,1
1,18,13,2,4,4,4,2,13,18,1
1,1,1,1,17,1,17,1,1,1,1
endlayer

layer
1,1,1,1,1,1,1,1,1,1,1
1,1,1,12,11,10,12,11,1,1,1
1,1,2,13,19,19,19,13,2,1,1
1,10,11,19,19,0,19,19,12,10,1
1,13,19,19,0,0,0,19,19,13,1
1,12,19,0,0,0,0,0,19,11,1
1,10,19,19,0,0,0,19,19,10,1
1,13,11,19,19,0,19,19,12,13,1
1,1,2,10,19,19,19,10,2,1,1
1,1,1,12,11,13,12,11,1,1,1
1,1,1,1,1,1,1,1,1,1,1
endlayer

layer
1,1,1,1,1,1,1,1,1,1,1
1,1,1,1,12,10,11,1,1,1,1
1,1,18,10,19,19,19,10,18,1,1
1,1,12,18,19,19,19,18,11,1,1
1,10,19,19,19,19,19,19,19,10,1
1,12,19,19,19,0,19,19,19,11,1
1,13,19,19,19,19,19,19,19,13,1
1,1,12,18,19,19,19,18,11,1,1
1,1,18,13,19,19,19,13,18,1,1
1,1,1,1,12,13,11,1,1,1,1
1,1,1,1,1,1,1,1,1,1,1
endlayer

layer
1,1,1,1,1,1,1,1,1,1,1
1,1,1,1,1,1,1,1,1,1,1
1,1,1,10,12,18,11,10,1,1,1
1,1,12,2,21,21,21,2,11,1,1
1,1,10,21,21,21,21,21,10,1,1
1,1,18,21,21,0,21,21,18,1,1
1,1,13,21,21,21,21,21,13,1,1
1,1,12,2,21,21,21,2,11,1,1
1,1,1,13,12,18,11,13,1,1,1
1,1,1,1,1,1,1,1,1,1,1
1,1,1,1,1,1,1,1,1,1,1
endlayer

