
# Created by Ruins mod version 16.7 Ingame Parser
# authoring Player: lafuller

weight=1
embed_into_distance=13
acceptable_target_blocks=water,waterlily
unacceptable_target_blocks=
biomesToSpawnIn=swampland,jungle,marsh,bog,wetland,mini_jungle,lush_swamp,green_swamp,dead_swamp,tropical_island,land_of_lakes
dimensions=23,11,10
allowable_overhang=0
max_leveling=2
leveling_buffer=-1
preserve_water=0
preserve_lava=0

rule1=0,100,preserveBlock
rule2=0,100,minecraft:log2-1
rule3=0,100,minecraft:log2-9
rule4=0,100,minecraft:log2-5
rule5=0,100,minecraft:spruce_fence-0
rule6=0,100,minecraft:ladder-5
rule7=0,100,minecraft:log-3
rule8=0,100,minecraft:log-7
rule9=0,100,minecraft:spruce_stairs-7
rule10=0,100,minecraft:wooden_slab-9
rule11=0,100,minecraft:log-11
rule12=0,100,minecraft:spruce_stairs-4
rule13=0,100,minecraft:planks-1
rule14=0,100,minecraft:spruce_stairs-5
rule15=0,100,minecraft:spruce_stairs-0
rule16=0,100,minecraft:wooden_slab-1
rule17=0,100,minecraft:spruce_stairs-6
rule18=0,100,minecraft:spruce_stairs-3
rule19=0,100,minecraft:trapdoor-7
rule20=0,100,minecraft:spruce_stairs-1
rule21=0,100,minecraft:spruce_stairs-2
rule22=0,100,minecraft:spruce_fence_gate-2
rule23=0,100,minecraft:ladder-4
rule24=0,100,minecraft:spruce_fence_gate-3
rule25=0,100,minecraft:carpet-7
rule26=0,100,minecraft:carpet-8
rule27=0,100,minecraft:dark_oak_fence-0
rule28=0,100,minecraft:spruce_fence_gate-1
rule29=0,100,minecraft:wooden_slab-13
rule30=0,100,minecraft:dark_oak_stairs-4
rule31=0,100,minecraft:dark_oak_stairs-7
rule32=0,100,minecraft:dark_oak_stairs-5
rule33=0,100,minecraft:planks-5
rule34=0,100,minecraft:wooden_slab-5
rule35=0,100,minecraft:dark_oak_stairs-0
rule36=0,100,minecraft:dark_oak_stairs-3
rule37=0,100,minecraft:dark_oak_stairs-2
rule38=0,100,minecraft:trapdoor-9
rule39=0,100,minecraft:dark_oak_stairs-1

layer
1,1,1,1,1,1,1,1,1,1
1,1,1,1,1,1,1,1,1,1
1,1,1,2,1,1,1,1,1,1
1,1,1,1,1,1,1,2,1,1
1,1,1,1,1,1,1,1,1,1
1,1,1,1,1,1,1,1,1,1
1,1,2,1,1,1,1,1,1,1
1,1,1,1,1,1,1,2,1,1
1,1,1,2,1,2,1,1,1,1
1,1,1,1,1,1,1,1,1,1
1,1,1,1,1,1,1,1,1,1
endlayer

layer
1,1,1,1,1,1,1,1,1,1
1,1,1,1,1,1,1,1,1,1
1,1,1,2,1,1,1,1,1,1
1,1,1,1,1,1,1,2,1,1
1,1,1,1,1,1,1,1,1,1
1,1,1,1,1,1,1,1,1,1
1,1,2,1,1,1,1,1,1,1
1,1,1,1,1,1,1,2,1,1
1,1,1,2,1,2,1,1,1,1
1,1,1,1,1,1,1,1,1,1
1,1,1,1,1,1,1,1,1,1
endlayer

layer
1,1,1,1,1,1,1,1,1,1
1,1,1,1,1,1,1,1,1,1
1,1,1,2,1,1,1,1,1,1
1,1,1,1,1,1,1,2,1,1
1,1,1,1,1,1,1,1,1,1
1,1,1,1,1,1,1,1,1,1
1,1,2,1,1,1,1,1,1,1
1,1,1,1,1,1,1,2,1,1
1,1,1,2,1,2,1,1,1,1
1,1,1,1,1,1,1,1,1,1
1,1,1,1,1,1,1,1,1,1
endlayer

layer
1,1,1,1,1,1,1,1,1,1
1,1,1,1,1,1,1,1,1,1
1,1,1,2,1,1,1,1,1,1
1,1,1,1,1,1,1,2,1,1
1,1,1,1,1,1,1,1,1,1
1,1,1,1,1,1,1,1,1,1
1,1,2,1,1,1,1,1,1,1
1,1,1,1,1,1,1,2,1,1
1,1,1,2,1,2,1,1,1,1
1,1,1,1,1,1,1,1,1,1
1,1,1,1,1,1,1,1,1,1
endlayer

layer
1,1,1,1,1,1,1,1,1,1
1,1,1,1,1,1,1,1,1,1
1,1,1,2,1,1,1,1,1,1
1,1,1,1,1,1,1,2,1,1
1,1,1,1,1,1,1,1,1,1
1,1,1,1,1,1,1,1,1,1
1,1,2,1,1,1,1,1,1,1
1,1,1,1,1,1,1,2,1,1
1,1,1,2,1,2,1,1,1,1
1,1,1,1,1,1,1,1,1,1
1,1,1,1,1,1,1,1,1,1
endlayer

layer
1,1,1,1,1,1,1,1,1,1
1,1,1,1,1,1,1,1,1,1
1,1,1,2,1,1,1,1,1,1
1,1,1,1,1,1,1,2,1,1
1,1,1,1,1,1,1,1,1,1
1,1,1,1,1,1,1,1,1,1
1,1,2,1,1,1,1,1,1,1
1,1,1,1,1,1,1,2,1,1
1,1,1,2,1,2,1,1,1,1
1,1,1,1,1,1,1,1,1,1
1,1,1,1,1,1,1,1,1,1
endlayer

layer
1,1,1,1,1,1,1,1,1,1
1,1,1,1,1,1,1,1,1,1
1,1,1,2,1,1,1,1,1,1
1,1,1,1,1,1,1,2,1,1
1,1,1,1,1,1,1,1,1,1
1,1,1,1,1,1,1,1,1,1
1,1,2,1,1,1,1,1,1,1
1,1,1,1,1,1,1,2,1,1
1,1,1,2,1,2,1,1,1,1
1,1,1,1,1,1,1,1,1,1
1,1,1,1,1,1,1,1,1,1
endlayer

layer
1,1,1,1,1,1,1,1,1,1
1,1,1,1,1,1,1,1,1,1
1,1,1,2,1,1,1,1,1,1
1,1,1,1,1,1,1,2,1,1
1,1,1,1,1,1,1,1,1,1
1,1,1,1,1,1,1,1,1,1
1,1,2,1,1,1,1,1,1,1
1,1,1,1,1,1,1,2,1,1
1,1,1,2,1,2,1,1,1,1
1,1,1,1,1,1,1,1,1,1
1,1,1,1,1,1,1,1,1,1
endlayer

layer
1,1,1,1,1,1,1,1,1,1
1,1,1,1,1,1,1,1,1,1
1,1,1,2,1,1,1,1,1,1
1,1,1,1,1,1,1,2,1,1
1,1,1,1,1,1,1,1,1,1
1,1,1,1,1,1,1,1,1,1
1,1,2,1,1,1,1,1,1,1
1,1,1,1,1,1,1,2,1,1
1,1,1,2,1,2,1,1,1,1
1,1,1,1,1,1,1,1,1,1
1,1,1,1,1,1,1,1,1,1
endlayer

layer
1,1,1,1,1,1,1,1,1,1
1,1,1,1,1,1,1,1,1,1
1,1,1,2,1,1,1,1,1,1
1,1,1,1,1,1,1,2,1,1
1,1,1,1,1,1,1,1,1,1
1,1,1,1,1,1,1,1,1,1
1,1,2,1,1,1,1,1,1,1
1,1,1,1,1,1,1,2,1,1
1,1,1,2,1,2,1,1,1,1
1,1,1,1,1,1,1,1,1,1
1,1,1,1,1,1,1,1,1,1
endlayer

layer
1,1,1,1,1,1,1,1,1,1
1,1,1,1,1,1,1,1,1,1
1,1,1,2,1,1,1,1,1,1
1,1,1,1,1,1,1,2,1,1
1,1,1,1,1,1,1,1,1,1
1,1,1,1,1,1,1,1,1,1
1,1,2,3,3,3,3,3,3,1
1,1,1,1,1,1,1,2,1,1
1,1,1,2,1,2,1,1,1,1
1,1,1,1,1,1,1,1,1,1
1,1,1,1,1,1,1,1,1,1
endlayer

layer
1,1,1,1,1,1,1,1,1,1
1,1,1,1,1,1,1,1,1,1
1,1,1,2,1,1,4,1,1,1
1,1,3,3,3,3,3,3,3,1
1,1,1,1,1,1,4,1,1,1
1,1,1,1,1,1,4,1,1,1
1,1,2,1,1,1,4,1,1,1
1,1,1,1,1,1,4,2,1,1
1,1,1,2,1,2,4,1,1,1
1,1,1,1,1,1,1,1,1,1
1,1,1,1,1,1,1,1,1,1
endlayer

layer
1,1,1,1,1,1,1,1,1,1
1,1,1,1,1,1,1,1,1,1
1,1,1,2,4,1,1,1,1,1
1,1,1,1,4,1,1,2,1,1
1,1,1,1,4,1,1,1,1,1
1,1,1,1,4,1,1,1,1,1
1,1,2,1,4,1,1,1,1,1
1,1,1,1,4,1,1,2,1,1
1,1,1,2,4,2,1,1,1,1
1,1,1,1,4,1,1,1,1,1
1,1,1,1,1,1,1,1,1,1
endlayer

layer
1,1,5,1,1,1,1,1,1,1
1,1,4,1,1,1,1,1,1,1
1,1,4,2,1,1,1,1,1,1
1,1,4,1,2,1,1,2,1,1
1,1,4,1,6,1,1,1,1,1
1,1,4,1,1,1,1,1,1,1
1,1,4,1,1,1,1,1,1,1
5,3,3,3,3,3,3,3,3,5
1,1,4,2,1,2,1,1,1,1
1,1,5,1,1,1,1,1,1,1
1,1,1,1,1,1,1,1,1,1
endlayer

layer
1,1,1,1,1,1,1,1,1,1
1,1,1,1,1,1,1,1,1,1
5,3,3,3,3,3,3,3,3,5
1,1,1,1,7,1,1,2,1,1
1,1,1,1,6,1,1,1,1,1
1,1,1,1,1,1,1,1,1,1
1,1,7,1,1,1,1,1,1,1
1,1,1,1,1,1,1,2,1,1
1,1,2,2,1,2,1,1,1,1
1,1,1,1,1,1,1,1,1,1
1,1,1,1,1,1,1,1,1,1
endlayer

layer
1,1,1,5,1,5,1,1,1,1
1,1,1,8,1,8,1,1,1,1
1,1,1,8,7,8,1,1,1,1
1,1,9,8,7,8,1,2,1,1
1,1,10,8,6,8,1,1,1,1
1,1,9,8,10,8,1,1,1,1
5,11,11,11,11,11,11,11,11,5
1,1,12,8,10,8,1,2,1,1
1,9,13,8,10,8,1,1,1,1
1,10,14,8,1,8,1,1,1,1
1,1,1,5,1,5,1,1,1,1
endlayer

layer
1,1,1,1,1,1,1,1,1,1
1,1,1,16,15,1,1,1,1,1
1,1,1,5,7,12,17,1,1,1
5,11,11,11,11,11,11,11,11,5
1,1,18,0,19,18,10,8,1,1
1,1,18,0,0,20,10,8,1,1
1,15,7,0,0,0,17,8,1,1
1,18,0,0,0,0,17,8,1,1
1,18,0,0,0,7,1,8,1,1
1,5,20,16,20,1,1,5,1,1
1,1,1,1,1,1,1,1,1,1
endlayer

layer
1,1,1,1,1,1,1,1,1,1
1,1,1,1,1,1,1,1,1,1
1,1,1,16,7,15,15,16,1,1
1,1,5,5,7,0,0,21,1,1
1,1,22,0,0,0,0,16,1,1
1,1,5,0,0,0,0,21,1,1
1,5,7,0,0,0,23,7,1,1
1,5,0,0,0,0,7,5,1,1
1,5,0,0,0,7,17,1,1,1
1,5,5,24,5,5,1,1,1,1
1,1,1,1,1,1,1,1,1,1
endlayer

layer
1,1,1,1,1,1,1,1,1,1
1,1,1,1,1,1,1,1,1,1
1,1,1,5,7,5,5,1,1,1
1,1,15,12,7,0,0,5,1,1
1,1,9,0,0,0,0,22,1,1
1,10,9,0,0,0,0,5,1,1
1,12,7,0,0,0,23,7,1,1
1,9,10,10,10,10,7,5,1,1
1,9,10,10,10,7,20,5,1,1
1,12,14,14,14,1,1,1,1,1
1,1,1,1,1,1,1,1,1,1
endlayer

layer
1,1,1,1,1,1,1,1,1,1
1,1,1,1,12,10,1,1,1,1
1,1,1,18,7,12,12,10,1,1
1,1,16,15,7,0,0,17,1,1
1,1,18,0,0,0,0,17,1,1
1,1,18,0,0,0,0,17,1,1
1,15,7,0,0,0,0,7,1,1
1,18,26,25,25,0,0,17,1,1
1,18,26,25,25,7,20,16,1,1
1,1,20,16,20,21,1,1,1,1
1,1,1,1,1,1,1,1,1,1
endlayer

layer
1,1,1,1,1,1,1,1,1,1
1,1,1,1,5,1,1,1,1,1
1,1,1,5,7,15,15,1,1,1
1,5,5,5,7,27,27,21,1,1
1,1,22,0,0,0,0,10,1,1
1,1,5,0,0,0,0,12,1,1
1,5,7,0,0,0,0,7,1,1
1,5,0,0,0,0,0,5,1,1
1,5,0,0,0,7,5,1,1,1
1,1,5,28,28,5,1,1,1,1
1,1,1,1,1,1,1,1,1,1
endlayer

layer
1,1,1,1,1,1,1,1,1,1
1,1,1,29,29,5,1,1,1,1
1,31,30,29,7,8,5,5,1,1
5,11,11,11,11,11,11,11,27,1
29,5,33,29,29,29,29,13,32,1
1,30,33,0,0,0,0,17,1,1
1,9,7,0,0,0,0,7,11,5
1,9,0,0,0,0,0,14,1,1
29,9,0,0,0,7,14,17,29,1
1,29,14,14,14,8,5,1,1,1
1,1,1,1,1,5,5,1,1,1
endlayer

layer
1,1,1,1,1,1,1,1,1,1
1,1,1,1,1,34,34,1,1,1
1,1,1,34,34,34,35,34,1,1
1,34,34,36,35,33,33,34,34,1
1,34,34,33,33,33,33,37,34,1
34,34,36,33,33,33,33,37,34,1
34,34,33,33,38,33,33,37,34,1
34,34,36,33,33,33,33,37,34,1
1,34,39,36,33,33,33,34,1,1
1,1,34,34,39,39,34,34,1,1
1,1,1,34,34,34,34,1,1,1
endlayer

