
# Created by Ruins mod version 16.7 Ingame Parser
# authoring Player: lafuller

weight=1
embed_into_distance=5
acceptable_target_blocks=
unacceptable_target_blocks=flowing_water,water,flowing_lava,lava,ice,bedrock,netherrack,nether_brick,nether_brick_fence,soul_sand,quartz_ore,end_stone,obsidian,iron_bars,cloud,flesh,ash_block,slime_grass,slime_congealed,slime_dirt
dimensions=12,22,21
allowable_overhang=0
max_leveling=7
leveling_buffer=-1
preserve_water=0
preserve_lava=0

rule1=0,100,preserveBlock
rule2=0,100,minecraft:sandstone-2
rule3=0,100,minecraft:sandstone-0
rule4=0,100,minecraft:sandstone_stairs-2
rule5=0,100,minecraft:double_stone_slab-9
rule6=0,100,minecraft:sandstone_stairs-0
rule7=0,100,minecraft:sandstone_stairs-1
rule8=0,100,minecraft:sandstone_stairs-3
rule9=0,100,minecraft:dirt-0
rule10=0,100,minecraft:trapdoor-8
rule11=0,100,minecraft:wooden_slab-9
rule12=0,100,bookshelf,pumpkin,melon_block,hay_block,ChestGenHook:chests/spawn_bonus_chest:5-5,ChestGenHook:chests/village_blacksmith:5-5,ChestGenHook:chests/stronghold_library:5-5,ChestGenHook:chests/simple_dungeon:5-5
rule13=0,100,minecraft:trapdoor-11
rule14=0,100,bookshelf,pumpkin,melon_block,hay_block,ChestGenHook:chests/spawn_bonus_chest:5-2,ChestGenHook:chests/village_blacksmith:5-2,ChestGenHook:chests/stronghold_library:5-2,ChestGenHook:chests/simple_dungeon:5-2
rule15=0,100,minecraft:trapdoor-9
rule16=0,100,minecraft:trapdoor-10
rule17=0,100,minecraft:carpet-7
rule18=0,100,minecraft:sandstone_stairs-5
rule19=0,100,minecraft:trapdoor-0
rule20=0,100,minecraft:trapdoor-3
rule21=0,100,minecraft:sandstone_stairs-4
rule22=0,100,minecraft:trapdoor-1
rule23=0,100,minecraft:trapdoor-2
rule24=0,100,minecraft:stone_slab-9
rule25=0,100,minecraft:sandstone_stairs-6
rule26=0,100,minecraft:jungle_door-7
rule27=0,100,minecraft:jungle_door-4
rule28=0,100,minecraft:ladder-5
rule29=0,100,minecraft:jungle_door-2
rule30=0,100,minecraft:ladder-3
rule31=0,100,minecraft:jungle_door-5
rule32=0,100,bookshelf,pumpkin,melon_block,hay_block,ChestGenHook:chests/spawn_bonus_chest:5-3,ChestGenHook:chests/village_blacksmith:5-3,ChestGenHook:chests/stronghold_library:5-3,ChestGenHook:chests/simple_dungeon:5-3
rule33=0,100,minecraft:jungle_door-6
rule34=0,100,minecraft:ladder-2
rule35=0,100,minecraft:jungle_door-8
rule36=0,100,minecraft:jungle_door-9
rule37=0,100,minecraft:carpet-8
rule38=0,100,minecraft:spruce_fence_gate-1
rule39=0,100,minecraft:spruce_fence-0
rule40=0,100,minecraft:stone_slab-1
rule41=0,100,minecraft:spruce_stairs-3
rule42=0,100,minecraft:spruce_stairs-0
rule43=0,100,minecraft:spruce_stairs-2
rule44=0,100,minecraft:spruce_stairs-1
rule45=0,100,minecraft:hay_block-0
rule46=0,100,minecraft:wooden_slab-1

layer
2,2,2,3,3,3,3,3,2,3,3,2,1,1,1,1,1,1,1,1,1
5,5,5,5,5,5,5,5,3,3,3,3,3,3,2,2,4,1,1,1,1
5,2,2,3,3,3,5,5,3,3,3,3,5,5,2,5,3,3,3,2,1
5,2,2,3,3,3,5,5,5,5,5,5,5,5,3,3,3,3,5,3,1
5,3,3,3,3,3,5,3,3,3,3,3,5,5,5,5,5,5,5,3,6
5,3,3,3,3,3,5,3,3,3,3,3,5,3,3,3,3,3,5,2,2
5,3,3,3,3,3,5,3,3,3,3,3,5,3,3,3,3,3,5,5,3
5,5,5,5,5,5,5,3,3,3,3,3,5,3,3,3,3,3,5,3,3
5,2,2,5,5,5,5,3,3,3,3,3,5,3,3,3,3,3,5,3,2
2,2,2,5,5,5,5,5,5,5,5,5,5,3,3,3,3,3,5,3,2
3,3,3,3,5,5,5,5,3,3,3,3,3,5,5,5,5,5,5,5,7
2,3,3,3,5,5,5,5,3,3,3,3,3,5,3,3,3,3,3,5,4
2,3,3,3,5,5,5,5,3,3,3,3,3,5,3,3,3,3,3,2,2
8,7,3,3,5,5,5,5,3,3,3,3,3,5,3,3,3,3,3,5,3
1,1,3,2,5,5,5,5,3,3,3,3,3,5,3,3,3,3,3,5,3
1,1,2,5,5,5,5,5,5,5,5,5,5,5,3,3,3,3,3,5,3
1,1,7,5,5,3,3,3,3,3,5,5,5,5,5,5,5,5,5,5,2
1,1,1,5,5,3,3,3,3,3,5,5,5,5,3,3,3,3,3,5,3
1,1,1,2,5,3,3,3,3,3,5,5,5,5,3,3,3,3,3,3,3
1,1,1,5,5,3,3,3,3,3,5,3,3,3,3,3,2,2,2,1,1
1,1,1,5,5,3,3,3,3,3,5,3,3,3,3,3,2,2,2,4,1
1,1,1,2,5,5,5,5,5,5,5,5,3,3,3,3,3,2,2,4,1
endlayer

layer
2,2,2,3,3,3,3,3,2,3,3,2,1,1,1,1,1,1,1,1,1
5,5,5,5,5,5,5,5,3,3,3,3,3,3,2,4,1,1,1,1,1
5,2,2,3,3,3,5,5,3,3,3,3,5,5,2,3,3,3,3,2,1
5,2,2,3,3,3,5,5,5,5,5,5,5,5,3,3,3,3,5,3,1
5,3,3,3,3,3,5,3,3,3,3,3,5,5,5,5,5,5,5,3,1
5,3,3,3,3,3,5,3,3,3,3,3,5,3,3,3,3,3,5,3,6
5,3,3,3,3,3,5,3,3,3,3,3,5,3,3,3,3,3,5,2,3
5,5,5,5,5,5,5,3,3,3,3,3,5,3,3,3,3,3,5,3,3
5,2,2,5,5,5,5,3,3,3,3,3,5,3,3,3,3,3,5,3,2
5,5,5,5,5,5,5,5,5,5,5,5,5,3,3,3,3,3,5,3,7
3,3,3,3,5,5,5,5,3,3,3,3,3,5,5,5,5,5,5,5,1
2,3,3,3,5,5,5,5,3,3,3,3,3,5,3,3,3,3,3,5,1
7,7,3,3,5,5,5,5,3,3,3,3,3,5,3,3,3,3,3,2,2
1,1,3,3,5,5,5,5,3,3,3,3,3,5,3,3,3,3,3,5,3
1,1,2,5,5,5,5,5,3,3,3,3,3,5,3,3,3,3,3,5,3
1,1,7,5,5,5,5,5,5,5,5,5,5,5,3,3,3,3,3,5,3
1,1,1,5,5,3,3,3,3,3,5,5,5,5,5,5,5,5,5,5,2
1,1,1,5,5,3,3,3,3,3,5,5,5,5,3,3,3,3,3,5,3
1,1,1,2,5,3,3,3,3,3,5,5,5,5,3,3,3,3,3,3,3
1,1,1,5,5,3,3,3,3,3,5,3,3,3,3,3,9,9,2,1,1
1,1,1,5,5,3,3,3,3,3,5,3,3,3,3,2,2,2,4,1,1
1,1,1,2,5,5,5,5,5,5,5,5,3,2,2,3,2,2,4,1,1
endlayer

layer
2,2,3,3,3,3,3,2,2,3,3,2,1,1,1,1,1,1,1,1,1
5,5,5,5,5,5,5,5,3,3,3,3,2,2,4,1,1,1,1,1,1
5,2,2,10,0,0,5,5,3,3,3,3,5,5,3,3,3,3,3,2,1
8,2,0,0,0,0,7,2,5,5,5,5,5,5,3,3,3,3,5,2,1
5,14,0,0,0,0,0,3,13,13,12,3,5,5,11,11,11,5,5,2,1
5,10,0,0,0,0,0,3,0,0,0,3,5,10,0,0,0,3,5,2,1
5,10,0,0,0,0,0,3,0,0,0,3,5,10,0,0,0,3,5,2,6
5,10,0,0,0,0,0,3,0,0,0,8,3,0,0,0,0,3,5,2,2
2,2,2,0,0,0,0,3,0,0,0,8,3,0,0,0,0,7,5,3,7
5,5,5,5,11,11,11,5,3,3,3,2,5,14,0,0,0,0,5,3,1
3,2,9,9,5,5,5,10,10,0,0,0,12,3,0,0,0,0,5,5,1
7,8,2,9,5,5,11,0,0,0,0,0,0,3,11,11,11,2,2,5,1
1,1,2,9,5,5,11,0,0,0,0,0,0,0,3,3,3,3,3,5,3
1,1,8,2,5,5,11,0,0,0,0,0,0,0,0,0,0,0,15,5,3
1,1,7,2,5,5,5,16,0,0,0,0,0,0,0,0,0,0,15,5,3
1,1,1,5,5,5,5,5,5,5,0,0,0,0,0,0,0,0,15,5,3
1,1,1,5,5,0,12,3,3,3,5,0,0,8,2,5,5,5,5,5,2
1,1,1,5,5,0,0,3,3,2,5,5,5,5,3,3,3,3,3,5,3
1,1,1,5,0,0,0,0,8,7,5,5,5,5,3,3,3,3,3,3,3
1,1,1,5,0,0,0,0,0,0,5,3,3,3,3,3,1,1,1,1,1
1,1,1,5,5,10,0,0,0,0,5,3,3,3,4,1,1,1,1,1,1
1,1,1,2,5,5,5,5,5,5,5,3,3,2,4,1,1,1,1,1,1
endlayer

layer
2,2,2,3,3,3,3,2,2,2,2,6,1,1,1,1,1,1,1,1,1
2,5,5,5,5,5,5,5,3,9,9,2,4,1,1,1,1,1,1,1,1
7,2,2,0,0,0,7,5,3,3,3,5,5,4,1,1,1,1,1,1,1
1,2,0,0,0,0,0,2,2,2,2,5,5,5,3,3,3,5,4,1,1
5,0,0,0,0,0,0,3,0,0,0,3,5,5,17,17,17,5,5,1,1
2,0,0,0,0,0,0,3,0,0,0,3,5,0,0,0,0,3,5,1,1
2,0,0,0,0,0,0,3,0,0,0,7,2,0,0,0,0,3,5,1,1
5,0,0,0,0,0,0,3,0,0,0,0,3,0,0,0,0,7,5,1,1
2,5,2,0,0,0,0,3,0,0,0,0,3,0,0,0,0,0,5,6,1
7,2,2,2,17,17,17,2,3,3,3,2,5,0,0,0,0,0,5,3,1
1,1,1,1,2,2,2,0,0,0,0,0,0,3,0,0,0,0,5,5,1
1,1,1,1,5,5,17,0,0,0,0,0,0,3,0,0,0,2,2,5,1
1,1,1,1,2,5,17,0,0,0,0,0,0,0,3,3,3,3,3,5,2
1,1,1,1,2,5,17,0,0,0,0,0,0,0,0,0,0,0,0,5,2
1,1,1,1,8,5,5,0,0,0,0,0,0,0,0,0,0,0,0,5,3
1,1,1,5,5,5,5,5,5,5,0,0,0,0,0,0,0,0,0,5,3
1,1,1,3,5,18,18,3,3,3,5,0,0,0,8,3,5,5,5,5,3
1,1,1,3,5,0,0,3,4,0,5,5,5,5,5,3,3,3,5,5,3
1,1,1,5,0,0,0,0,0,0,5,5,9,9,9,2,3,2,2,2,3
1,1,1,5,0,0,0,0,0,0,5,3,9,3,3,2,1,1,1,1,1
1,1,1,2,5,0,0,0,0,0,5,3,3,4,1,1,1,1,1,1,1
1,1,1,2,5,5,5,5,5,5,5,3,3,4,1,1,1,1,1,1,1
endlayer

layer
2,2,3,3,3,3,3,3,1,1,1,1,1,1,1,1,1,1,1,1,1
7,5,5,5,5,5,7,3,6,1,1,1,1,1,1,1,1,1,1,1,1
1,2,2,19,0,0,0,5,5,5,5,5,4,1,1,1,1,1,1,1,1
1,2,0,0,0,0,0,2,5,5,5,5,5,5,5,5,5,4,1,1,1
5,0,0,0,0,0,0,3,20,20,20,3,5,5,0,0,0,5,2,1,1
5,0,0,0,0,0,0,3,0,0,0,7,5,19,0,0,0,3,5,1,1
5,0,0,0,0,0,0,3,0,0,0,0,5,19,0,0,0,7,5,1,1
5,0,0,0,0,0,0,3,0,0,0,0,3,0,0,0,0,0,5,1,1
2,5,5,0,0,0,0,3,0,0,0,0,3,0,0,0,0,0,5,1,1
1,8,2,2,0,0,0,2,3,3,3,2,5,0,0,0,0,0,5,6,1
1,1,1,1,2,2,2,19,19,0,0,0,0,3,0,0,0,21,5,2,1
1,1,1,1,2,5,0,0,0,0,0,0,0,3,0,0,0,2,2,5,1
1,1,1,1,7,2,0,0,0,0,0,0,0,0,3,3,3,3,3,5,3
1,1,1,1,1,2,0,0,0,0,0,0,0,0,0,0,0,0,22,5,3
1,1,1,1,1,8,5,23,0,0,0,0,0,0,0,0,0,0,22,5,3
1,1,1,2,5,5,5,5,5,5,0,0,0,0,0,0,0,0,22,5,3
1,1,1,3,5,3,3,3,3,3,5,0,0,0,0,8,5,5,5,5,3
1,1,1,5,5,18,18,4,0,0,5,5,3,3,5,5,5,5,5,3,7
1,1,1,5,0,0,0,0,0,0,5,5,1,1,1,1,1,1,1,1,1
1,1,1,5,0,0,0,0,0,0,5,5,1,1,1,1,1,1,1,1,1
1,1,1,2,5,19,0,0,0,0,5,5,1,1,1,1,1,1,1,1,1
1,1,1,8,5,5,5,5,5,5,5,5,4,1,1,1,1,1,1,1,1
endlayer

layer
1,1,3,3,3,3,3,3,1,1,1,1,1,1,1,1,1,1,1,1,1
1,6,5,2,3,4,0,3,1,1,1,1,1,1,1,1,1,1,1,1,1
1,2,5,5,5,6,0,3,6,3,2,4,1,1,1,1,1,1,1,1,1
1,5,5,5,5,5,0,2,5,5,2,5,2,3,5,5,4,1,1,1,1
2,5,5,5,5,5,21,5,11,11,11,7,5,5,5,5,5,5,2,1,1
5,5,5,5,5,5,5,11,11,11,11,0,5,5,5,5,4,0,5,1,1
5,5,5,5,5,5,5,11,11,11,11,0,5,5,5,5,6,0,5,1,1
2,5,5,5,5,5,5,11,11,11,24,0,5,5,5,5,5,0,2,1,1
3,3,5,5,5,5,5,21,21,21,21,21,5,5,5,5,5,0,5,1,1
1,1,8,2,2,2,5,5,5,5,5,5,5,5,5,5,5,21,3,1,1
1,1,1,1,2,3,5,5,5,5,5,5,5,5,5,5,5,5,3,6,1
1,1,1,1,7,3,5,5,5,5,5,5,5,5,5,3,5,5,3,2,1
1,1,1,1,1,1,5,5,5,5,5,5,5,5,5,5,5,5,5,5,3
1,1,1,1,1,1,5,5,5,5,5,5,5,5,5,5,5,5,5,2,3
1,1,1,1,1,1,8,5,5,5,5,5,5,5,5,5,5,5,5,5,3
1,1,1,5,2,5,5,5,5,5,5,5,2,2,2,7,7,5,5,5,3
1,1,1,3,5,5,5,5,5,5,5,3,25,0,0,0,8,5,5,2,3
1,1,1,3,5,5,4,0,0,0,5,3,3,3,3,5,5,5,3,4,1
1,1,1,3,11,11,11,11,11,11,5,5,1,1,1,1,1,1,1,1,1
1,1,1,3,11,11,11,11,11,11,5,5,1,1,1,1,1,1,1,1,1
1,1,1,5,5,5,25,11,11,11,5,7,1,1,1,1,1,1,1,1,1
1,1,1,1,8,5,5,2,5,5,2,1,1,1,1,1,1,1,1,1,1
endlayer

layer
1,1,2,3,3,2,3,2,1,1,1,1,1,1,1,1,1,1,1,1,1
1,1,3,0,0,0,0,3,1,1,1,1,1,1,1,1,1,1,1,1,1
1,1,26,0,0,0,0,3,1,1,1,1,1,1,1,1,1,1,1,1,1
1,1,3,0,0,0,16,2,2,3,27,5,5,1,1,1,1,1,1,1,1
5,3,3,0,0,0,5,3,0,0,0,0,5,5,2,27,2,5,5,1,1
5,0,28,0,0,0,5,0,0,0,0,0,5,11,0,0,0,0,5,1,1
5,0,0,0,0,0,5,0,0,0,0,0,5,11,0,0,0,0,5,1,1
5,0,0,0,0,16,5,0,0,0,3,21,5,11,0,0,0,0,3,1,1
2,3,3,29,3,3,0,0,0,3,11,11,11,3,0,0,0,21,5,1,1
1,1,1,1,1,26,0,0,30,3,0,0,0,3,0,0,0,3,1,1,1
1,1,1,1,1,3,0,0,0,3,0,0,0,3,0,0,0,31,1,1,1
1,1,1,1,1,3,3,2,3,0,0,0,32,3,16,0,0,3,1,1,1
1,1,1,1,1,1,1,3,0,0,0,0,3,5,3,3,3,3,3,5,2
1,1,1,1,1,1,1,26,0,0,0,0,3,0,0,0,0,0,28,0,3
1,1,1,1,1,1,1,5,0,0,0,0,3,0,0,0,0,0,0,0,3
1,1,1,2,5,5,5,5,16,0,0,0,5,0,0,0,0,0,0,0,3
1,1,1,3,0,0,0,3,3,3,5,33,3,0,0,0,0,2,33,5,2
1,1,1,2,34,0,0,0,0,0,5,1,1,2,3,2,2,1,1,1,1
1,1,1,3,0,0,0,0,0,0,2,1,1,1,1,1,1,1,1,1,1
1,1,1,3,0,0,0,0,0,0,31,1,1,1,1,1,1,1,1,1,1
1,1,1,2,5,33,3,0,0,0,2,1,1,1,1,1,1,1,1,1,1
1,1,1,1,1,1,1,2,5,5,2,1,1,1,1,1,1,1,1,1,1
endlayer

layer
1,1,2,3,2,1,2,2,1,1,1,1,1,1,1,1,1,1,1,1,1
1,1,3,0,0,0,0,3,1,1,1,1,1,1,1,1,1,1,1,1,1
1,1,35,0,0,0,0,1,1,1,1,1,1,1,1,1,1,1,1,1,1
1,1,3,0,0,0,0,2,2,3,36,5,2,1,1,1,1,1,1,1,1
5,3,3,0,0,0,5,3,0,0,0,0,5,5,2,35,2,5,2,1,1
3,0,28,0,0,0,5,0,0,0,0,0,5,17,0,0,0,0,5,1,1
1,0,0,0,0,0,5,0,0,0,0,0,5,37,0,0,0,0,1,1,1
2,0,0,0,0,0,5,0,0,0,3,2,5,37,0,0,0,0,5,1,1
2,3,3,36,3,3,0,0,0,3,17,17,37,3,0,0,0,3,3,1,1
1,1,1,1,1,36,0,0,30,3,0,0,0,3,0,0,0,3,1,1,1
1,1,1,1,1,3,11,11,11,3,0,0,0,3,0,0,0,35,1,1,1
1,1,1,1,1,3,3,2,3,0,0,0,0,3,0,0,0,3,1,1,1
1,1,1,1,1,1,1,3,0,0,0,0,3,5,3,3,3,3,3,3,2
1,1,1,1,1,1,1,35,0,0,0,0,3,0,0,0,0,0,28,0,3
1,1,1,1,1,1,1,5,0,0,0,0,3,0,0,0,0,0,0,0,1
1,1,1,2,2,5,5,5,0,0,0,0,5,0,0,0,0,0,0,0,3
1,1,1,3,11,11,11,3,3,3,5,36,3,0,0,0,0,2,36,2,2
1,1,1,2,34,0,0,0,0,0,5,1,1,3,2,1,3,1,1,1,1
1,1,1,1,0,0,0,0,0,0,2,1,1,1,1,1,1,1,1,1,1
1,1,1,3,0,0,0,0,0,0,35,1,1,1,1,1,1,1,1,1,1
1,1,1,2,5,36,3,0,0,0,2,1,1,1,1,1,1,1,1,1,1
1,1,1,1,1,1,1,5,1,5,2,1,1,1,1,1,1,1,1,1,1
endlayer

layer
1,1,3,3,2,2,2,3,1,1,1,1,1,1,1,1,1,1,1,1,1
1,1,5,0,0,0,0,3,1,1,1,1,1,1,1,1,1,1,1,1,1
1,1,3,0,0,0,0,3,1,1,1,1,1,1,1,1,1,1,1,1,1
1,1,3,0,0,0,23,2,5,2,5,5,5,1,1,1,1,1,1,1,1
5,3,3,0,0,0,5,3,0,0,0,0,5,5,5,2,5,5,5,1,1
5,19,0,0,0,0,5,0,0,0,0,0,5,0,0,0,0,0,5,1,1
5,19,0,0,0,0,5,0,0,0,0,0,5,0,0,0,0,0,5,1,1
5,19,0,0,0,23,5,0,0,0,3,2,5,0,0,0,0,0,5,1,1
3,3,3,3,3,3,0,0,0,3,0,0,0,3,0,0,0,3,5,1,1
1,1,1,1,1,3,0,0,0,3,0,0,0,3,0,0,0,3,11,1,1
1,1,1,1,1,3,37,17,17,3,0,0,0,3,0,0,0,3,11,1,1
1,1,1,1,1,3,3,5,3,0,0,0,22,3,23,0,0,3,11,1,1
1,1,1,1,1,1,1,2,0,0,0,0,3,5,3,3,3,3,3,3,3
1,1,1,1,1,1,1,5,0,0,0,0,3,0,0,0,0,0,28,11,2
1,1,1,1,1,1,1,5,0,0,0,0,3,0,0,0,0,0,0,11,2
1,1,1,5,5,5,5,5,23,0,0,0,5,0,0,0,0,0,0,11,3
1,1,1,3,37,17,17,3,3,3,5,3,3,0,0,0,0,5,5,5,3
1,1,1,3,0,0,0,0,0,0,5,1,1,3,2,2,2,1,1,1,1
1,1,1,3,0,0,0,0,0,0,5,1,1,1,1,1,1,1,1,1,1
1,1,1,3,0,0,0,0,0,0,2,1,1,1,1,1,1,1,1,1,1
1,1,1,5,5,3,3,0,0,0,5,1,1,1,1,1,1,1,1,1,1
1,1,1,1,1,1,1,5,5,5,5,1,1,1,1,1,1,1,1,1,1
endlayer

layer
1,1,2,3,3,3,3,2,1,1,1,1,1,1,1,1,1,1,1,1,1
1,1,5,0,0,0,0,3,1,1,1,1,1,1,1,1,1,1,1,1,1
1,1,3,0,0,0,0,3,1,1,1,1,1,1,1,1,1,1,1,1,1
1,1,3,0,0,0,0,2,5,5,5,5,2,1,1,1,1,1,1,1,1
6,3,3,18,18,18,5,3,24,24,24,24,5,5,5,5,5,5,2,1,1
5,0,0,0,0,24,5,24,24,0,24,24,5,0,0,0,0,22,5,1,1
5,0,0,0,0,24,5,24,24,24,24,24,5,0,0,0,0,22,5,1,1
3,0,0,0,0,24,5,21,21,21,3,2,5,0,0,0,0,22,2,1,1
7,3,3,3,3,3,0,0,0,3,24,24,24,3,3,3,3,3,3,1,1
1,1,1,1,1,3,0,0,0,3,24,16,24,3,0,0,0,3,1,1,1
1,1,1,1,1,3,0,0,0,3,24,24,24,5,0,0,0,3,1,1,1
1,1,1,1,1,3,3,5,3,3,3,3,3,5,0,0,0,3,1,1,1
1,1,1,1,1,39,38,5,0,0,0,0,3,5,3,3,3,3,3,5,2
1,1,1,1,1,39,38,5,0,0,0,0,3,0,0,0,25,0,0,37,3
1,1,1,1,1,39,38,5,0,0,0,0,3,0,0,0,25,0,0,17,3
1,1,1,2,2,5,5,5,0,0,0,0,5,0,0,0,25,0,0,17,3
1,1,1,3,0,0,0,3,3,3,5,3,3,21,21,21,5,5,5,2,2
1,1,1,3,0,0,0,0,0,0,2,20,20,2,3,3,2,1,1,1,1
1,1,1,3,0,0,0,0,0,0,5,1,1,1,1,1,1,1,1,1,1
1,1,1,3,0,0,0,0,0,0,5,1,1,1,1,1,1,1,1,1,1
1,1,1,2,5,3,3,0,0,0,5,1,1,1,1,1,1,1,1,1,1
1,1,1,1,1,1,1,2,5,5,2,1,1,1,1,1,1,1,1,1,1
endlayer

layer
1,1,1,40,40,40,40,1,1,1,1,1,1,1,1,1,1,1,1,1,1
1,1,1,40,40,40,40,40,1,1,1,1,1,1,1,1,1,1,1,1,1
1,1,1,40,19,22,40,40,1,1,1,1,1,1,1,1,1,1,1,1,1
1,1,1,40,40,40,40,40,1,1,1,1,1,1,1,1,1,1,1,1,1
1,1,43,42,41,40,40,40,40,40,40,1,1,6,6,6,6,6,1,1,1
1,44,45,45,45,44,40,40,40,20,40,1,8,24,24,24,24,24,4,1,1
1,41,45,10,45,43,40,40,40,40,40,1,8,24,24,16,24,24,4,1,1
1,42,45,45,45,43,6,6,6,6,1,1,8,24,24,24,24,24,4,1,1
1,1,43,44,41,8,40,40,40,4,1,1,1,7,7,7,7,7,1,1,1
1,1,1,1,1,8,40,23,40,4,1,1,1,40,46,46,46,40,1,1,1
1,1,1,1,1,8,40,40,40,4,1,1,1,40,46,23,46,40,1,1,1
1,1,1,1,1,40,7,7,2,4,6,6,6,40,46,46,46,40,1,1,1
1,1,1,1,1,1,1,8,46,46,46,46,4,40,40,40,40,2,6,2,40
1,1,1,1,1,1,1,8,46,20,20,46,4,40,40,40,2,0,0,0,2
1,1,1,1,1,1,1,8,46,23,23,46,4,40,19,40,8,0,0,0,4
1,1,1,1,40,40,40,8,46,46,46,46,4,40,40,40,2,0,0,0,2
1,1,1,40,40,40,40,7,7,7,7,7,7,40,40,40,40,2,7,2,40
1,1,1,40,40,40,18,18,18,18,3,1,1,1,1,1,1,1,1,1,1
1,1,1,40,40,19,25,0,0,0,2,1,1,1,1,1,1,1,1,1,1
1,1,1,40,40,40,25,0,0,0,3,1,1,1,1,1,1,1,1,1,1
1,1,1,1,40,40,2,0,0,0,2,1,1,1,1,1,1,1,1,1,1
1,1,1,1,1,1,1,2,3,2,3,1,1,1,1,1,1,1,1,1,1
endlayer

layer
1,1,1,1,1,1,1,1,1,1,1,1,1,1,1,1,1,1,1,1,1
1,1,1,1,1,1,1,1,1,1,1,1,1,1,1,1,1,1,1,1,1
1,1,1,1,1,1,1,1,1,1,1,1,1,1,1,1,1,1,1,1,1
1,1,1,1,1,1,1,1,1,1,1,1,1,1,1,1,1,1,1,1,1
1,1,1,1,1,1,1,1,1,1,1,1,1,1,1,1,1,1,1,1,1
1,1,1,1,1,1,1,1,1,1,1,1,1,40,40,40,40,40,1,1,1
1,1,1,1,1,1,1,1,1,1,1,1,1,40,1,1,1,40,1,1,1
1,1,1,1,1,1,1,1,1,1,1,1,1,40,40,40,40,40,1,1,1
1,1,1,1,1,1,1,1,1,1,1,1,1,1,1,1,1,1,1,1,1
1,1,1,1,1,1,1,1,1,1,1,1,1,1,1,1,1,1,1,1,1
1,1,1,1,1,1,1,1,1,1,1,1,1,1,1,1,1,1,1,1,1
1,1,1,1,1,1,1,1,1,1,1,1,1,1,1,1,1,1,1,1,1
1,1,1,1,1,1,1,1,1,1,1,1,1,1,1,1,1,1,1,1,1
1,1,1,1,1,1,1,1,1,1,1,1,1,1,1,1,1,40,40,40,1
1,1,1,1,1,1,1,1,1,1,1,1,1,1,1,1,1,40,23,40,1
1,1,1,1,1,1,1,1,1,1,1,1,1,1,1,1,1,40,40,40,1
1,1,1,1,1,1,1,1,1,1,1,1,1,1,1,1,1,1,1,1,1
1,1,1,1,1,1,1,40,1,40,1,1,1,1,1,1,1,1,1,1,1
1,1,1,1,1,1,40,7,7,7,40,1,1,1,1,1,1,1,1,1,1
1,1,1,1,1,1,1,4,19,8,1,1,1,1,1,1,1,1,1,1,1
1,1,1,1,1,1,40,6,6,6,40,1,1,1,1,1,1,1,1,1,1
1,1,1,1,1,1,1,40,1,40,1,1,1,1,1,1,1,1,1,1,1
endlayer

