# Gilly's Brickyard

weight=1
embed_into_distance=4
unacceptable_target_blocks=flowing_water,water,flowing_lava,lava,ice,bedrock,netherrack,nether_brick,nether_brick_fence,soul_sand,quartz_ore,end_stone,obsidian,iron_bars,cloud,flesh,ash_block,slime_grass,slime_congealed,slime_dirt
dimensions=14,11,15
cut_in_buffer=0
max_leveling=4
leveling_buffer=-1
preserve_water=0
preserve_lava=0
preserve_plants=0

rule1=0,100,preserveBlock
rule2=0,100,stonebrick-0,stonebrick-0,stonebrick-0,stonebrick-0,stonebrick-1,stonebrick-2,stonebrick-2,stone-5,stone-6,cobblestone,gravel
rule3=0,100,brick_block
rule4=0,100,log
rule5=0,100,planks
rule6=0,100,planks-1
rule7=0,100,planks-5
rule8=0,100,iron_bars
rule9=0,100,wooden_slab-5

rule10=0,100,wooden_door-2
rule11=0,100,wooden_door-8
rule12=0,100,torch-5
rule13=0,100,IInventory;furnace;coal#5#0#1-2
rule14=0,100,cobblestone_wall
rule15=0,100,cauldron
rule16=0,100,fence
rule17=0,100,dark_oak_fence
rule18=0,100,wooden_door-9
rule19=0,100,wooden_door-0
rule20=0,100,ChestGenHook:chests/village_blacksmith:5-2
rule21=0,100,ChestGenHook:chests/spawn_bonus_chest:4-2
rule22=0,100,dirt

layer
1,1,1,1,2,2,1,1,1,1,1,1,2,2,1
1,2,2,2,2,2,2,2,2,2,2,2,2,2,1
1,2,22,22,22,22,22,22,22,22,22,22,22,2,1
1,14,22,22,22,22,22,22,22,22,22,22,22,14,1
1,2,22,22,22,22,22,22,22,22,22,22,22,2,1
1,2,22,22,22,22,22,22,22,22,22,22,22,14,1
1,2,22,22,22,22,22,22,22,22,22,22,22,2,2
1,14,22,22,22,22,22,22,2,2,2,2,2,2,2
1,2,22,22,22,22,22,22,2,22,22,22,22,22,2
1,2,2,2,2,14,2,2,2,22,22,22,22,22,2
1,1,1,1,1,1,1,2,2,2,2,2,2,2,2
endlayer

layer
1,1,1,1,2,2,1,1,1,1,1,1,2,2,1
1,2,2,2,2,2,2,2,2,2,2,2,2,2,1
1,2,22,22,22,22,22,22,22,22,22,22,22,2,1
1,14,22,22,22,22,22,22,22,22,22,22,22,14,1
1,2,22,22,22,22,22,22,22,22,22,22,22,2,1
1,2,22,22,22,22,22,22,22,22,22,22,22,14,1
1,2,22,22,22,22,22,22,22,22,22,22,22,2,2
1,14,22,22,22,22,22,22,2,2,2,2,2,2,2
1,2,22,22,22,22,22,22,2,22,22,22,22,22,2
1,2,2,2,2,14,2,2,2,22,22,22,22,22,2
1,1,1,1,1,1,1,2,2,2,2,2,2,2,2
endlayer

layer
1,1,1,1,1,2,2,1,1,1,1,2,2,1,1
1,2,2,2,2,2,2,2,2,2,2,2,2,2,1
1,2,22,22,22,22,22,22,22,22,22,22,22,2,1
1,14,22,22,22,22,22,22,22,22,22,22,22,14,1
1,2,22,22,22,22,22,22,22,22,22,22,22,2,1
1,2,22,22,22,22,22,22,22,22,22,22,22,14,1
1,2,22,22,22,22,22,22,22,22,22,22,22,2,1
1,14,22,22,22,22,22,22,2,2,2,2,2,2,2
1,2,22,22,22,22,22,22,2,22,22,22,22,22,2
1,2,2,2,2,14,2,2,2,22,22,22,22,22,2
1,1,1,1,1,1,1,1,2,2,2,2,2,2,2
endlayer

layer
1,1,1,1,1,1,2,2,1,1,2,2,1,1,1
1,2,2,2,2,2,2,2,2,2,2,2,2,2,1
1,2,22,22,22,22,22,22,22,22,22,22,22,2,1
1,14,22,22,22,22,22,22,22,22,22,22,22,14,1
1,2,22,22,22,22,22,22,22,22,22,22,22,2,1
1,2,22,22,22,22,22,22,22,22,22,22,22,14,1
1,2,22,22,22,22,22,22,22,22,22,22,22,2,1
1,14,22,22,22,22,22,22,2,2,2,2,2,2,1
1,2,22,22,22,22,22,22,2,2,2,2,2,2,2
1,2,2,2,2,14,2,2,2,2,2,2,2,2,2
1,1,1,1,1,1,1,1,1,2,2,2,2,2,2
endlayer

layer
1,1,1,1,1,1,1,2,2,2,2,1,1,1,1
1,2,2,2,2,2,2,2,2,2,2,2,2,2,1
1,2,2,2,2,2,2,2,2,2,2,2,2,2,1
1,2,2,2,2,2,2,2,2,2,2,2,2,2,1
1,2,2,2,2,2,2,2,2,2,2,2,2,2,1
1,2,2,2,2,2,2,2,2,2,2,2,2,2,1
1,2,2,2,2,2,2,2,2,2,2,2,2,2,1
1,2,2,2,2,2,2,2,2,2,2,2,2,2,1
1,2,2,2,2,2,2,2,2,2,2,2,2,2,1
1,2,2,2,2,2,2,2,2,2,2,2,2,2,1
1,1,1,1,1,1,1,1,1,1,1,1,1,1,1
endlayer

layer
0,0,0,0,0,0,0,0,0,0,0,0,0,0,0
1,4,3,4,3,3,3,3,19,19,3,4,3,4,0
1,3,20,0,0,0,0,0,0,0,0,0,0,3,0
1,3,21,0,0,0,0,0,0,0,0,0,0,3,0
1,3,0,0,0,0,0,0,0,0,12,0,0,3,0
1,4,15,0,12,0,0,0,0,0,0,0,0,3,0
1,3,0,0,0,0,0,0,0,0,0,0,0,3,0
1,3,0,0,0,0,0,0,4,3,10,10,3,4,0
1,3,0,0,0,0,0,0,3,0,0,0,0,0,0
1,4,3,4,3,3,3,3,4,0,0,0,0,0,0
0,0,0,0,0,0,0,0,0,0,0,0,0,0,0
endlayer

layer
0,0,0,0,0,0,0,0,0,0,0,0,0,0,0
1,4,5,4,5,0,0,5,18,11,5,4,5,4,0
1,5,0,0,0,0,0,0,0,0,0,0,0,5,0
1,0,0,0,0,0,0,0,0,0,0,0,0,0,0
1,5,0,0,0,0,0,0,0,0,0,0,0,0,0
1,4,13,0,0,0,0,0,0,0,0,0,0,0,0
1,5,0,0,0,0,0,0,0,0,0,0,0,5,0
1,0,0,0,0,0,0,0,4,5,11,18,5,4,0
1,5,0,0,0,0,0,0,5,0,0,0,0,0,0
1,4,5,4,5,5,5,5,4,0,0,0,0,0,0
0,0,0,0,0,0,0,0,0,0,0,0,0,0,0
endlayer

layer
0,0,0,0,0,0,0,0,0,0,0,0,0,0,0
1,4,5,4,5,8,8,5,16,16,5,4,5,4,0
1,5,0,0,0,0,0,0,0,0,0,0,0,5,0
1,8,0,0,0,0,0,0,0,0,0,0,0,8,0
1,5,0,0,0,0,0,0,0,0,0,0,0,8,0
1,4,14,0,0,0,0,0,0,0,0,0,0,8,0
1,5,0,0,0,0,0,0,0,0,0,0,0,5,0
1,8,0,0,0,0,0,0,4,5,16,16,5,4,0
1,5,0,0,0,0,0,0,5,0,0,0,0,0,0
1,4,5,4,5,8,8,5,4,0,0,0,0,0,0
0,0,0,0,0,0,0,0,0,0,0,0,0,0,0
endlayer

layer
0,0,0,0,0,0,0,0,0,0,0,0,0,0,0
1,4,5,4,5,5,5,5,5,5,5,4,5,4,0
1,5,0,0,0,0,0,0,0,0,0,0,0,5,0
1,5,0,0,0,0,0,0,0,0,0,0,0,5,0
1,5,0,0,0,0,0,0,0,0,0,0,0,5,0
1,4,14,0,0,0,0,0,0,0,0,0,0,5,0
1,5,0,0,0,0,0,0,0,0,0,0,0,5,0
1,5,0,0,0,0,0,0,4,5,5,5,5,4,0
1,5,0,0,0,0,0,0,5,0,0,0,0,0,0
1,4,5,4,5,5,5,5,4,0,0,0,0,0,0
0,0,0,0,0,0,0,0,0,0,0,0,0,0,0
endlayer

layer
9,9,9,9,9,9,9,9,9,9,9,9,9,9,9
9,7,7,7,7,7,7,7,7,7,7,7,7,7,9
9,7,6,6,6,6,6,6,6,6,6,6,6,7,9
9,7,6,6,6,6,6,6,6,6,6,6,6,7,9
9,7,6,6,6,6,6,6,6,6,6,6,6,7,9
9,7,6,6,6,6,6,6,6,6,6,6,6,7,9
9,7,6,6,6,6,6,6,6,6,6,6,6,7,9
9,7,6,6,6,6,6,6,7,7,7,7,7,7,9
9,7,6,6,6,6,6,6,7,9,9,9,9,9,9
9,7,7,7,7,7,7,7,7,9,0,0,0,0,0
9,9,9,9,9,9,9,9,9,9,0,0,0,0,0
endlayer

layer
0,0,0,0,0,0,0,0,0,0,0,0,0,0,0
0,17,17,17,17,17,17,17,17,17,17,17,17,17,0
0,17,9,9,9,9,9,9,9,9,9,9,9,17,0
0,17,9,9,9,9,9,9,9,9,9,9,9,17,0
0,17,9,9,9,9,9,9,9,9,9,9,9,17,0
0,17,14,9,9,9,9,9,9,9,9,9,9,17,0
0,17,9,9,9,9,9,9,9,9,9,9,9,17,0
0,17,9,9,9,9,9,9,17,17,17,17,17,17,0
0,17,9,9,9,9,9,9,17,0,0,0,0,0,0
0,17,17,17,17,17,17,17,17,0,0,0,0,0,0
0,0,0,0,0,0,0,0,0,0,0,0,0,0,0
endlayer

layer
0,0,0,0,0,0,0,0,0,0,0,0,0,0,0
0,0,0,0,0,0,0,0,0,0,0,0,0,0,0
0,0,0,0,0,0,0,0,0,0,0,0,0,0,0
0,0,0,0,0,0,0,0,0,0,0,0,0,0,0
0,0,0,0,0,0,0,0,0,0,0,0,0,0,0
0,0,14,0,0,0,0,0,0,0,0,0,0,0,0
0,0,0,0,0,0,0,0,0,0,0,0,0,0,0
0,0,0,0,0,0,0,0,0,0,0,0,0,0,0
0,0,0,0,0,0,0,0,0,0,0,0,0,0,0
0,0,0,0,0,0,0,0,0,0,0,0,0,0,0
0,0,0,0,0,0,0,0,0,0,0,0,0,0,0
endlayer

layer
0,0,0,0,0,0,0,0,0,0,0,0,0,0,0
0,0,0,0,0,0,0,0,0,0,0,0,0,0,0
0,0,0,0,0,0,0,0,0,0,0,0,0,0,0
0,0,0,0,0,0,0,0,0,0,0,0,0,0,0
0,0,0,0,0,0,0,0,0,0,0,0,0,0,0
0,0,14,0,0,0,0,0,0,0,0,0,0,0,0
0,0,0,0,0,0,0,0,0,0,0,0,0,0,0
0,0,0,0,0,0,0,0,0,0,0,0,0,0,0
0,0,0,0,0,0,0,0,0,0,0,0,0,0,0
0,0,0,0,0,0,0,0,0,0,0,0,0,0,0
0,0,0,0,0,0,0,0,0,0,0,0,0,0,0
endlayer

layer
0,0,0,0,0,0,0,0,0,0,0,0,0,0,0
0,0,0,0,0,0,0,0,0,0,0,0,0,0,0
0,0,0,0,0,0,0,0,0,0,0,0,0,0,0
0,0,0,0,0,0,0,0,0,0,0,0,0,0,0
0,0,0,0,0,0,0,0,0,0,0,0,0,0,0
0,0,14,0,0,0,0,0,0,0,0,0,0,0,0
0,0,0,0,0,0,0,0,0,0,0,0,0,0,0
0,0,0,0,0,0,0,0,0,0,0,0,0,0,0
0,0,0,0,0,0,0,0,0,0,0,0,0,0,0
0,0,0,0,0,0,0,0,0,0,0,0,0,0,0
0,0,0,0,0,0,0,0,0,0,0,0,0,0,0
endlayer

