
# Created by Ruins mod version 16.7 Ingame Parser
# authoring Player: lafuller

weight=1
embed_into_distance=6
acceptable_target_blocks=
unacceptable_target_blocks=flowing_water,water,flowing_lava,lava
dimensions=10,3,21
allowable_overhang=0
max_leveling=10
leveling_buffer=-1
preserve_water=0
preserve_lava=0

rule1=0,100,preserveBlock
rule2=0,100,minecraft:dark_oak_fence-0
rule3=0,100,CommandBlock:RUINSTRIGGER /testruin Gilly/GillyNarrowCorridor ~2 ~-5 ~2 0:@,CommandBlock:RUINSTRIGGER /testruin Gilly/GillyNarrowCorridor ~2 ~-5 ~2 1:@,CommandBlock:RUINSTRIGGER /testruin Gilly/GillyNarrowCorridor ~-2 ~-5 ~-2 2:@,CommandBlock:RUINSTRIGGER /testruin Gilly/GillyNarrowCorridor ~-2 ~-5 ~-2 3:@

layer
1,1,1,1,1,1,1,1,1,1,1,1,1,1,1,1,1,1,0,0,0
1,1,1,1,1,1,1,1,1,1,1,1,0,0,2,0,0,0,0,0,0
1,1,1,1,1,1,1,1,1,1,1,1,0,0,0,2,0,0,0,0,0
endlayer

layer
1,1,1,1,1,1,1,1,1,1,1,1,1,1,1,1,1,1,0,0,0
1,1,1,1,1,1,1,1,1,1,1,0,0,0,2,0,0,0,0,0,0
1,1,1,1,1,1,1,1,1,1,1,0,0,0,0,2,0,0,0,0,0
endlayer

layer
1,1,1,1,1,1,1,1,1,1,1,1,1,1,1,1,1,1,0,0,0
1,1,1,1,1,1,1,1,1,1,0,0,0,0,2,0,0,0,0,0,0
1,1,1,1,1,1,1,1,1,1,0,0,0,0,0,2,0,0,0,0,0
endlayer

layer
1,1,1,1,1,1,1,1,1,1,1,1,1,1,1,1,1,1,0,0,0
1,1,1,1,1,1,1,1,1,0,0,0,0,0,2,2,0,0,0,0,0
1,1,1,1,1,1,1,1,1,0,0,0,0,0,2,2,0,0,0,0,0
endlayer

layer
1,1,1,1,1,1,1,1,1,1,1,1,1,1,1,1,1,1,1,1,1
1,1,1,1,1,1,1,1,0,0,0,0,0,1,1,1,1,1,1,1,1
1,1,1,1,1,1,1,1,0,0,0,0,0,1,1,1,1,1,1,1,1
endlayer

layer
1,1,1,1,1,1,1,1,1,1,1,1,1,1,1,1,1,1,1,1,1
1,1,1,1,1,1,1,0,0,0,0,0,1,1,1,1,1,1,1,3,1
1,1,1,1,1,1,1,0,0,0,0,0,1,1,1,1,1,1,1,1,1
endlayer

layer
0,0,0,1,1,1,1,1,1,1,1,1,1,1,1,1,1,1,1,1,1
0,0,0,0,0,2,0,0,0,0,0,1,1,1,1,1,1,1,1,1,1
0,0,0,0,2,0,0,0,0,0,0,1,1,1,1,1,1,1,1,1,1
endlayer

layer
0,0,0,1,1,1,1,1,1,1,1,1,1,1,1,1,1,1,1,1,1
0,0,0,0,0,2,0,0,0,0,1,1,1,1,1,1,1,1,1,1,1
0,0,0,0,2,0,0,0,0,0,1,1,1,1,1,1,1,1,1,1,1
endlayer

layer
0,0,0,1,1,1,1,1,1,1,1,1,1,1,1,1,1,1,1,1,1
0,0,0,0,0,2,0,0,0,1,1,1,1,1,1,1,1,1,1,1,1
0,0,0,0,2,0,0,0,0,1,1,1,1,1,1,1,1,1,1,1,1
endlayer

layer
0,0,0,1,1,1,1,1,1,1,1,1,1,1,1,1,1,1,1,1,1
0,0,0,0,2,2,0,0,1,1,1,1,1,1,1,1,1,1,1,1,1
0,0,0,0,2,2,0,0,1,1,1,1,1,1,1,1,1,1,1,1,1
endlayer

