
# Created by Ruins mod version 16.7 Ingame Parser
# authoring Player: lafuller

weight=1
embed_into_distance=4
acceptable_target_blocks=
unacceptable_target_blocks=flowing_water,water,flowing_lava,lava,ice,bedrock,netherrack,nether_brick,nether_brick_fence,soul_sand,quartz_ore,end_stone,obsidian,iron_bars,cloud,flesh,ash_block,slime_grass,slime_congealed,slime_dirt
dimensions=21,16,16
allowable_overhang=0
max_leveling=4
leveling_buffer=-1
preserve_water=0
preserve_lava=0

rule1=0,100,preserveBlock
rule2=0,100,stonebrick,stonebrick,stonebrick,stonebrick-1,stonebrick-2,stonebrick-2,stone-5,stone-6,cobblestone
rule3=0,100,minecraft:stone_brick_stairs-0
rule4=0,100,minecraft:dirt-0
rule5=0,100,minecraft:stone_brick_stairs-1
rule6=0,100,stonebrick,stonebrick,stonebrick,stonebrick-1,stonebrick-2,stonebrick-2,stone-5,stone-6,cobblestone,gravel
rule7=0,100,minecraft:cobblestone_wall-0
rule8=0,100,minecraft:stone-6
rule9=0,100,minecraft:double_stone_slab-8
rule10=0,100,minecraft:stained_hardened_clay-9
rule11=0,100,minecraft:stone_brick_stairs-3
rule12=1,100,minecraft:torch-5
rule13=0,100,minecraft:stone-5
rule14=0,100,minecraft:log-0
rule15=0,100,minecraft:trapdoor-9
rule16=0,100,minecraft:spruce_fence_gate-6
rule17=0,100,minecraft:acacia_door-1
rule18=0,100,minecraft:spruce_fence_gate-7
rule19=0,100,minecraft:nether_brick-0
rule20=0,100,minecraft:nether_brick_stairs-5
rule21=0,100,minecraft:nether_brick_stairs-6
rule22=0,100,minecraft:stone_slab-14
rule23=0,100,minecraft:wooden_slab-2
rule24=0,100,minecraft:planks-2
rule25=0,100,IInventory;minecraft:furnace;minecraft:coal#2#1#1-3
rule26=0,100,minecraft:furnace-3
rule27=0,100,minecraft:cake-0
rule28=0,100,minecraft:birch_stairs-1
rule29=0,100,minecraft:acacia_door-9
rule30=0,100,minecraft:acacia_door-8
rule31=0,100,minecraft:birch_stairs-0
rule32=0,100,minecraft:stone_slab-5
rule33=0,100,minecraft:stone_stairs-7
rule34=0,100,minecraft:stone_stairs-6
rule35=0,100,minecraft:spruce_fence_gate-0
rule36=0,100,minecraft:wooden_slab-9
rule37=0,100,minecraft:birch_stairs-5
rule38=0,100,minecraft:spruce_fence_gate-2
rule39=0,100,minecraft:birch_stairs-4
rule40=0,100,minecraft:spruce_fence_gate-3
rule41=0,100,stonebrick,stonebrick,stonebrick-1,stonebrick-2,stonebrick-2,stone-5,stone-6,cobblestone,stone_brick_stairs-0,stone_brick_stairs-4
rule42=0,100,stonebrick,stonebrick,stonebrick-1,stonebrick-2,stonebrick-2,stone-5,stone-6,cobblestone,stone_brick_stairs-3,stone_brick_stairs-7
rule43=0,100,minecraft:stone_stairs-5
rule44=0,100,minecraft:spruce_fence-0
rule45=0,100,minecraft:birch_stairs-7
rule46=0,100,minecraft:birch_stairs-6
rule47=0,100,stonebrick,stonebrick,stonebrick-1,stonebrick-2,stonebrick-2,stone-5,stone-6,cobblestone,stone_brick_stairs-2,stone_brick_stairs-6
rule48=0,100,minecraft:dark_oak_stairs-2
rule49=0,100,minecraft:dark_oak_stairs-0
rule50=0,100,minecraft:wooden_slab-5
rule51=0,100,minecraft:planks-5
rule52=0,100,minecraft:spruce_stairs-5
rule53=0,100,minecraft:dark_oak_stairs-5
rule54=0,100,minecraft:wooden_slab-13
rule55=0,100,minecraft:dark_oak_stairs-6
rule56=0,100,minecraft:dark_oak_stairs-4
rule57=0,100,minecraft:planks-1
rule58=0,100,minecraft:dark_oak_stairs-7
rule59=0,100,minecraft:spruce_stairs-4
rule60=0,100,minecraft:spruce_stairs-7
rule61=0,100,minecraft:spruce_stairs-6
rule62=0,100,minecraft:dark_oak_stairs-1
rule63=0,100,minecraft:dark_oak_stairs-3
rule64=0,100,stonebrick,stonebrick,stonebrick-1,stonebrick-2,stonebrick-2,stone-5,stone-6,cobblestone,stone_brick_stairs-1,stone_brick_stairs-5
rule65=0,100,minecraft:double_wooden_slab-5
rule66=0,100,minecraft:double_wooden_slab-1
rule67=0,100,minecraft:stone_brick_stairs-2
rule68=0,100,minecraft:dark_oak_fence-0
rule69=0,100,minecraft:trapdoor-1
rule70=0,100,minecraft:trapdoor-0
rule71=0,100,minecraft:iron_bars-0
rule72=0,100,minecraft:carpet-7

layer
1,1,1,1,2,2,2,2,2,2,2,1,1,1,1,1
1,1,1,2,2,2,2,2,2,2,2,2,1,1,1,1
1,1,1,2,2,2,2,2,2,2,2,2,1,1,1,1
3,3,2,2,2,2,2,2,2,2,2,2,1,1,1,1
2,2,2,4,4,4,4,4,4,4,4,2,2,1,1,1
2,2,2,4,4,4,4,4,4,4,4,4,4,2,1,1
2,2,2,4,4,4,4,4,4,4,4,4,4,2,1,1
2,2,2,4,4,4,4,4,4,4,4,4,4,2,2,1
2,2,2,4,4,4,4,4,4,4,4,4,4,4,2,1
2,2,2,4,4,4,4,4,4,4,4,4,4,4,2,1
2,2,2,4,4,4,4,4,4,4,4,4,4,4,2,1
2,2,2,4,4,4,4,4,4,4,4,4,4,2,2,1
2,2,2,2,2,2,2,2,4,4,4,4,4,2,1,1
2,2,2,2,1,1,1,2,2,4,4,4,4,2,1,1
5,5,5,1,1,1,1,1,2,2,2,2,2,2,1,1
1,1,1,1,1,1,1,1,1,1,1,1,1,1,1,1
endlayer

layer
1,1,1,1,6,6,6,6,6,6,6,1,1,1,1,1
1,1,1,6,6,6,6,6,6,6,6,6,1,1,1,1
1,1,1,6,6,6,6,6,6,6,6,6,1,1,1,1
1,1,6,6,6,6,6,6,6,6,6,6,1,1,1,1
3,3,6,4,4,4,4,4,4,4,4,6,6,1,1,1
6,6,6,4,4,4,4,4,4,4,4,4,4,6,1,1
6,6,6,4,4,4,4,4,4,4,4,4,4,7,1,1
6,6,6,4,4,4,4,4,4,4,4,4,4,6,6,1
6,6,6,4,4,4,4,4,4,4,4,4,4,4,7,1
6,6,6,4,4,4,4,4,4,4,4,4,4,4,6,1
6,6,6,4,4,4,4,4,4,4,4,4,4,4,7,1
6,6,6,4,4,4,4,4,4,4,4,4,4,6,6,1
6,6,6,6,7,6,7,6,4,4,4,4,4,6,1,1
5,5,5,6,1,1,1,6,6,4,4,4,4,7,1,1
1,1,1,1,1,1,1,1,6,7,6,6,7,6,1,1
1,1,1,1,1,1,1,1,1,1,1,1,1,1,1,1
endlayer

layer
1,1,1,1,6,6,6,6,6,6,6,1,1,1,1,1
1,1,1,6,6,6,6,6,6,6,6,6,1,1,1,1
1,1,1,6,6,6,6,6,6,6,6,6,1,1,1,1
1,1,6,6,6,6,6,6,6,6,6,6,1,1,1,1
1,1,7,4,4,4,4,4,4,4,4,6,6,1,1,1
3,3,6,4,4,4,4,4,4,4,4,4,4,6,1,1
6,6,6,4,4,4,4,4,4,4,4,4,4,7,1,1
6,6,6,4,4,4,4,4,4,4,4,4,4,6,6,1
6,6,6,4,4,4,4,4,4,4,4,4,4,4,7,1
6,6,6,4,4,4,4,4,4,4,4,4,4,4,6,1
6,6,6,4,4,4,4,4,4,4,4,4,4,4,7,1
6,6,6,4,4,4,4,4,4,4,4,4,4,6,6,1
5,5,6,6,7,6,7,6,4,4,4,4,4,6,1,1
1,1,1,6,1,1,1,6,6,4,4,4,4,7,1,1
1,1,1,1,1,1,1,1,6,7,6,6,7,6,1,1
1,1,1,1,1,1,1,1,1,1,1,1,1,1,1,1
endlayer

layer
1,1,1,1,6,6,6,6,6,6,6,1,1,1,1,1
1,1,1,6,6,6,6,6,6,6,6,6,1,1,1,1
1,1,1,6,6,6,6,6,6,6,6,6,1,1,1,1
1,1,6,6,6,6,6,6,6,6,6,6,1,1,1,1
1,1,7,4,4,4,4,4,4,4,4,6,6,1,1,1
1,1,6,4,4,4,4,4,4,4,4,4,4,6,1,1
3,6,6,4,4,4,4,4,4,4,4,4,4,7,1,1
6,6,6,4,4,4,4,4,4,4,4,4,4,6,6,1
6,6,6,4,4,4,4,4,4,4,4,4,4,4,7,1
6,6,6,4,4,4,4,4,4,4,4,4,4,4,6,1
6,6,6,4,4,4,4,4,4,4,4,4,4,4,7,1
5,6,6,4,4,4,4,4,4,4,4,4,4,6,6,1
1,1,6,6,7,6,7,6,4,4,4,4,4,6,1,1
1,1,1,6,1,1,1,6,6,4,4,4,4,7,1,1
1,1,1,1,1,1,1,1,6,7,6,6,7,6,1,1
1,1,1,1,1,1,1,1,1,1,1,1,1,1,1,1
endlayer

layer
1,1,1,1,6,6,6,6,6,6,6,1,1,1,1,1
1,1,1,6,6,6,6,6,6,6,6,6,1,1,1,1
1,1,1,6,6,6,6,6,6,6,6,6,1,1,1,1
1,1,6,6,8,8,8,8,8,8,6,6,1,1,1,1
1,1,6,9,9,8,9,8,9,9,8,9,6,1,1,1
1,1,6,8,8,8,8,8,8,8,8,8,6,6,1,1
1,6,6,9,9,8,9,8,9,9,8,9,9,6,1,1
3,6,6,8,9,8,8,9,9,9,8,9,9,6,6,1
11,6,6,10,8,10,10,8,10,10,8,10,10,8,6,1
11,6,6,10,8,10,10,8,10,10,8,10,10,8,6,1
5,6,6,8,9,8,8,9,8,8,9,8,8,9,6,1
1,6,6,10,8,10,10,8,10,10,8,10,10,8,6,1
1,1,6,6,6,6,6,6,10,10,8,10,10,6,1,1
1,1,1,6,1,1,1,6,8,8,9,8,8,6,1,1
1,1,1,1,1,1,1,1,6,6,6,6,6,6,1,1
1,1,1,1,1,1,1,1,1,1,1,1,1,1,1,1
endlayer

layer
1,1,1,1,6,6,6,6,6,6,6,1,1,1,1,1
1,1,1,6,12,9,12,9,12,9,12,6,1,1,1,1
1,1,1,6,13,9,13,9,13,9,6,6,1,1,1,1
1,1,14,13,0,0,0,0,0,0,0,13,1,1,1,1
1,1,6,0,0,0,0,0,0,0,0,0,14,1,1,1
1,1,6,0,0,0,0,0,0,0,0,0,6,6,1,1
1,14,6,15,9,9,9,0,0,0,0,0,6,6,1,1
1,1,6,0,0,0,0,9,9,9,9,15,9,9,14,1
1,1,17,0,0,0,0,0,0,0,0,0,0,16,6,1
1,1,17,0,0,0,0,0,0,0,0,0,0,16,6,1
1,1,6,0,0,0,0,0,0,0,0,0,0,16,6,1
1,14,6,18,18,18,18,0,0,0,0,0,0,16,14,1
1,1,6,6,6,6,6,6,0,0,0,0,0,6,1,1
1,1,1,14,1,1,1,14,18,18,18,18,18,6,1,1
1,1,1,1,1,1,1,1,6,6,6,6,6,14,1,1
1,1,1,1,1,1,1,1,1,1,1,1,1,1,1,1
endlayer

layer
1,1,1,1,6,6,6,6,6,6,6,1,1,1,1,1
1,1,1,6,21,20,20,20,20,20,19,6,1,1,1,1
1,1,1,6,19,22,19,22,19,22,19,6,1,1,1,1
1,1,14,13,0,0,0,0,0,0,0,13,1,1,1,1
1,1,23,0,0,0,0,0,0,0,0,0,14,1,1,1
1,1,23,0,0,0,0,0,0,0,0,0,25,24,1,1
1,14,24,0,0,0,0,0,0,0,0,0,26,24,1,1
1,1,24,0,0,0,0,27,0,0,0,0,0,0,14,1
1,1,29,0,0,0,0,0,0,0,0,0,0,72,28,1
1,1,30,0,0,0,0,0,0,0,0,0,0,72,23,1
1,1,24,0,0,0,0,0,0,0,0,0,0,72,31,1
1,14,24,72,72,72,72,0,0,0,0,0,0,72,14,1
1,1,24,24,23,23,23,24,0,0,0,0,0,24,1,1
1,1,1,14,1,1,1,14,72,72,72,72,72,24,1,1
1,1,1,1,1,1,1,1,24,23,23,23,24,14,1,1
1,1,1,1,1,1,1,1,1,1,1,1,1,1,1,1
endlayer

layer
1,1,1,1,32,32,32,32,32,6,6,1,1,1,1,1
1,1,1,11,6,6,6,6,6,6,1,6,1,1,1,1
1,1,1,11,19,19,19,19,19,19,19,6,1,1,1,1
1,1,14,6,34,0,0,0,0,0,33,6,1,1,1,1
1,1,35,0,0,0,0,0,0,0,0,0,14,1,1,1
1,1,35,0,0,0,0,0,0,0,0,0,7,24,1,1
1,14,24,36,36,36,36,36,0,0,0,0,0,24,1,1
1,1,24,0,0,0,0,36,36,36,36,36,36,36,14,1
1,1,35,0,0,0,0,0,0,0,0,0,0,0,37,1
1,1,35,0,0,0,0,0,0,0,0,0,0,0,38,1
1,1,24,0,0,0,0,0,0,0,0,0,0,0,39,1
1,14,24,0,0,0,0,0,0,0,0,0,0,0,14,1
1,1,24,24,40,40,40,24,0,0,0,0,0,24,1,1
1,1,1,14,1,1,1,14,0,0,0,0,0,24,1,1
1,1,1,1,1,1,1,1,24,40,40,40,24,14,1,1
1,1,1,1,1,1,1,1,1,1,1,1,1,1,1,1
endlayer

layer
1,1,1,1,1,1,1,1,1,41,41,1,1,1,1,1
1,1,1,1,1,1,1,1,1,42,1,6,1,1,1,1
1,1,1,1,32,32,32,32,32,6,6,6,1,1,1,1
1,1,14,6,6,43,43,43,43,43,6,6,1,1,1,1
1,1,24,0,0,0,0,0,0,0,0,0,14,1,1,1
1,1,24,0,0,0,0,0,0,0,0,0,7,24,1,1
1,14,24,0,44,0,0,0,0,0,0,0,0,24,1,1
1,1,24,0,0,0,0,44,0,0,0,44,0,37,14,1
1,1,24,0,0,0,0,0,0,0,0,0,0,0,24,1
1,1,24,0,0,0,0,0,0,0,0,0,0,0,45,1
1,1,24,0,0,0,0,0,0,0,0,0,0,0,24,1
1,14,24,0,0,0,0,0,0,0,0,0,0,39,14,1
1,1,24,24,46,39,45,24,0,0,0,0,0,24,1,1
1,1,1,14,1,1,1,14,0,0,0,0,0,24,1,1
1,1,1,1,1,1,1,1,24,46,39,45,24,14,1,1
1,1,1,1,1,1,1,1,1,1,1,1,1,1,1,1
endlayer

layer
1,1,1,1,1,1,1,1,1,41,41,1,1,1,1,1
1,1,1,1,1,1,1,1,1,42,1,47,1,1,1,1
1,1,1,1,1,1,1,1,1,42,6,47,1,1,1,1
1,50,49,49,49,49,49,49,49,49,49,49,49,48,1,1
54,53,24,52,52,52,52,52,52,52,52,52,14,51,49,1
1,54,24,0,0,0,0,0,0,0,0,0,7,24,55,1
1,14,24,0,44,0,0,0,0,0,0,0,0,24,56,1
1,54,24,0,0,0,0,44,0,0,0,44,0,24,51,48
1,54,24,0,0,0,0,0,0,0,0,0,0,37,57,48
1,54,24,0,0,0,0,0,0,0,0,0,0,45,57,48
58,56,24,0,0,0,0,0,0,0,0,0,0,39,57,48
58,14,24,59,59,59,59,59,59,0,0,0,59,24,14,48
1,53,51,51,51,51,51,51,61,0,0,0,60,24,55,1
1,1,63,62,62,62,62,51,61,0,0,0,60,24,48,1
1,1,1,1,1,1,1,63,24,24,24,24,24,14,62,1
1,1,1,1,1,1,1,62,55,1,1,1,58,62,1,1
endlayer

layer
1,1,1,1,1,1,1,1,1,41,41,1,1,1,1,1
1,1,1,1,1,1,1,1,1,42,1,47,1,1,1,1
1,1,1,1,1,1,1,1,1,42,64,47,1,1,1,1
1,1,1,1,1,1,1,1,1,1,1,1,1,1,1,1
1,63,49,49,49,49,49,49,49,49,49,49,49,49,1,1
50,51,24,36,36,36,36,36,36,36,36,36,57,24,48,1
50,51,24,36,44,0,0,0,0,0,0,0,60,24,48,1
58,51,24,36,0,0,0,44,0,0,0,44,60,24,48,1
63,51,24,36,0,0,0,0,0,0,0,0,60,24,48,1
63,51,24,36,0,0,0,0,0,0,0,0,60,24,48,1
63,51,24,59,59,59,59,59,59,61,36,60,59,24,48,1
63,62,51,51,51,51,51,51,51,61,36,60,51,51,50,1
1,1,62,62,62,62,62,62,51,61,36,60,51,51,1,1
1,1,1,1,1,1,1,63,51,61,36,60,51,65,1,1
1,1,1,1,1,1,1,63,51,24,24,24,51,50,1,1
1,1,1,1,1,1,1,63,62,62,62,62,62,48,1,1
endlayer

layer
1,1,1,1,1,1,1,1,1,3,41,1,1,1,1,1
1,1,1,1,1,1,1,1,1,42,1,47,1,1,1,1
1,1,1,1,1,1,1,1,1,42,64,47,1,1,1,1
1,1,1,1,1,1,1,1,1,1,1,1,1,1,1,1
1,1,1,1,1,1,1,1,1,1,1,1,1,1,1,1
1,49,49,49,49,49,49,49,49,49,49,49,51,49,1,1
1,63,51,51,57,57,57,57,57,57,57,57,51,51,1,1
1,63,51,57,36,36,36,57,36,36,36,66,51,51,1,1
1,63,51,57,36,0,36,57,36,0,36,66,51,51,1,1
1,62,63,51,61,59,59,57,59,59,59,57,51,51,1,1
1,1,62,51,51,51,51,51,51,51,51,51,62,62,1,1
1,1,1,63,62,62,62,62,62,63,51,48,50,50,1,1
1,1,1,1,1,1,1,1,50,63,51,48,50,1,1,1
1,1,1,1,1,1,1,1,50,63,51,48,50,1,1,1
1,1,1,1,1,1,1,1,1,50,50,50,1,1,1,1
1,1,1,1,1,1,1,1,1,1,1,1,1,1,1,1
endlayer

layer
1,1,1,1,1,1,1,1,1,1,41,1,1,1,1,1
1,1,1,1,1,1,1,1,1,42,1,47,1,1,1,1
1,1,1,1,1,1,1,1,1,42,64,67,1,1,1,1
1,1,1,1,1,1,1,1,1,1,1,1,1,1,1,1
1,1,1,1,1,1,1,1,1,1,1,1,1,1,1,1
1,1,1,68,68,68,68,68,68,68,68,68,7,1,1,1
1,1,68,68,50,50,50,50,50,50,50,50,68,68,1,1
1,1,68,50,50,50,50,50,50,50,50,50,50,68,1,1
1,1,68,50,50,70,50,50,50,69,50,50,50,68,1,1
1,1,68,68,50,50,50,50,50,50,50,50,68,68,1,1
1,1,1,68,68,68,68,68,68,68,68,68,68,1,1,1
1,1,1,1,1,1,1,1,1,1,1,1,1,1,1,1
1,1,1,1,1,1,1,1,1,1,1,1,1,1,1,1
1,1,1,1,1,1,1,1,1,1,1,1,1,1,1,1
1,1,1,1,1,1,1,1,1,1,1,1,1,1,1,1
1,1,1,1,1,1,1,1,1,1,1,1,1,1,1,1
endlayer

layer
1,1,1,1,1,1,1,1,1,1,41,1,1,1,1,1
1,1,1,1,1,1,1,1,1,42,1,47,1,1,1,1
1,1,1,1,1,1,1,1,1,5,64,1,1,1,1,1
1,1,1,1,1,1,1,1,1,1,1,1,1,1,1,1
1,1,1,1,1,1,1,1,1,1,1,1,1,1,1,1
1,1,1,1,1,1,1,1,1,1,1,1,7,1,1,1
1,1,1,1,1,1,1,1,1,1,1,1,1,1,1,1
1,1,1,1,1,1,1,1,1,1,1,1,1,1,1,1
1,1,1,1,1,1,1,1,1,1,1,1,1,1,1,1
1,1,1,1,1,1,1,1,1,1,1,1,1,1,1,1
1,1,1,1,1,1,1,1,1,1,1,1,1,1,1,1
1,1,1,1,1,1,1,1,1,1,1,1,1,1,1,1
1,1,1,1,1,1,1,1,1,1,1,1,1,1,1,1
1,1,1,1,1,1,1,1,1,1,1,1,1,1,1,1
1,1,1,1,1,1,1,1,1,1,1,1,1,1,1,1
1,1,1,1,1,1,1,1,1,1,1,1,1,1,1,1
endlayer

layer
1,1,1,1,1,1,1,1,1,1,41,1,1,1,1,1
1,1,1,1,1,1,1,1,1,42,1,47,1,1,1,1
1,1,1,1,1,1,1,1,1,1,64,1,1,1,1,1
1,1,1,1,1,1,1,1,1,1,1,1,1,1,1,1
1,1,1,1,1,1,1,1,1,1,1,1,1,1,1,1
1,1,1,1,1,1,1,1,1,1,1,1,1,1,1,1
1,1,1,1,1,1,1,1,1,1,1,1,1,1,1,1
1,1,1,1,1,1,1,1,1,1,1,1,1,1,1,1
1,1,1,1,1,1,1,1,1,1,1,1,1,1,1,1
1,1,1,1,1,1,1,1,1,1,1,1,1,1,1,1
1,1,1,1,1,1,1,1,1,1,1,1,1,1,1,1
1,1,1,1,1,1,1,1,1,1,1,1,1,1,1,1
1,1,1,1,1,1,1,1,1,1,1,1,1,1,1,1
1,1,1,1,1,1,1,1,1,1,1,1,1,1,1,1
1,1,1,1,1,1,1,1,1,1,1,1,1,1,1,1
1,1,1,1,1,1,1,1,1,1,1,1,1,1,1,1
endlayer

layer
1,1,1,1,1,1,1,1,1,1,41,1,1,1,1,1
1,1,1,1,1,1,1,1,1,42,1,47,1,1,1,1
1,1,1,1,1,1,1,1,1,1,64,1,1,1,1,1
1,1,1,1,1,1,1,1,1,1,1,1,1,1,1,1
1,1,1,1,1,1,1,1,1,1,1,1,1,1,1,1
1,1,1,1,1,1,1,1,1,1,1,1,1,1,1,1
1,1,1,1,1,1,1,1,1,1,1,1,1,1,1,1
1,1,1,1,1,1,1,1,1,1,1,1,1,1,1,1
1,1,1,1,1,1,1,1,1,1,1,1,1,1,1,1
1,1,1,1,1,1,1,1,1,1,1,1,1,1,1,1
1,1,1,1,1,1,1,1,1,1,1,1,1,1,1,1
1,1,1,1,1,1,1,1,1,1,1,1,1,1,1,1
1,1,1,1,1,1,1,1,1,1,1,1,1,1,1,1
1,1,1,1,1,1,1,1,1,1,1,1,1,1,1,1
1,1,1,1,1,1,1,1,1,1,1,1,1,1,1,1
1,1,1,1,1,1,1,1,1,1,1,1,1,1,1,1
endlayer

layer
1,1,1,1,1,1,1,1,1,1,41,1,1,1,1,1
1,1,1,1,1,1,1,1,1,42,1,47,1,1,1,1
1,1,1,1,1,1,1,1,1,1,64,1,1,1,1,1
1,1,1,1,1,1,1,1,1,1,1,1,1,1,1,1
1,1,1,1,1,1,1,1,1,1,1,1,1,1,1,1
1,1,1,1,1,1,1,1,1,1,1,1,1,1,1,1
1,1,1,1,1,1,1,1,1,1,1,1,1,1,1,1
1,1,1,1,1,1,1,1,1,1,1,1,1,1,1,1
1,1,1,1,1,1,1,1,1,1,1,1,1,1,1,1
1,1,1,1,1,1,1,1,1,1,1,1,1,1,1,1
1,1,1,1,1,1,1,1,1,1,1,1,1,1,1,1
1,1,1,1,1,1,1,1,1,1,1,1,1,1,1,1
1,1,1,1,1,1,1,1,1,1,1,1,1,1,1,1
1,1,1,1,1,1,1,1,1,1,1,1,1,1,1,1
1,1,1,1,1,1,1,1,1,1,1,1,1,1,1,1
1,1,1,1,1,1,1,1,1,1,1,1,1,1,1,1
endlayer

layer
1,1,1,1,1,1,1,1,1,1,41,1,1,1,1,1
1,1,1,1,1,1,1,1,1,42,71,47,1,1,1,1
1,1,1,1,1,1,1,1,1,1,64,1,1,1,1,1
1,1,1,1,1,1,1,1,1,1,1,1,1,1,1,1
1,1,1,1,1,1,1,1,1,1,1,1,1,1,1,1
1,1,1,1,1,1,1,1,1,1,1,1,1,1,1,1
1,1,1,1,1,1,1,1,1,1,1,1,1,1,1,1
1,1,1,1,1,1,1,1,1,1,1,1,1,1,1,1
1,1,1,1,1,1,1,1,1,1,1,1,1,1,1,1
1,1,1,1,1,1,1,1,1,1,1,1,1,1,1,1
1,1,1,1,1,1,1,1,1,1,1,1,1,1,1,1
1,1,1,1,1,1,1,1,1,1,1,1,1,1,1,1
1,1,1,1,1,1,1,1,1,1,1,1,1,1,1,1
1,1,1,1,1,1,1,1,1,1,1,1,1,1,1,1
1,1,1,1,1,1,1,1,1,1,1,1,1,1,1,1
1,1,1,1,1,1,1,1,1,1,1,1,1,1,1,1
endlayer

layer
1,1,1,1,1,1,1,1,1,1,41,1,1,1,1,1
1,1,1,1,1,1,1,1,1,42,1,47,1,1,1,1
1,1,1,1,1,1,1,1,1,1,64,1,1,1,1,1
1,1,1,1,1,1,1,1,1,1,1,1,1,1,1,1
1,1,1,1,1,1,1,1,1,1,1,1,1,1,1,1
1,1,1,1,1,1,1,1,1,1,1,1,1,1,1,1
1,1,1,1,1,1,1,1,1,1,1,1,1,1,1,1
1,1,1,1,1,1,1,1,1,1,1,1,1,1,1,1
1,1,1,1,1,1,1,1,1,1,1,1,1,1,1,1
1,1,1,1,1,1,1,1,1,1,1,1,1,1,1,1
1,1,1,1,1,1,1,1,1,1,1,1,1,1,1,1
1,1,1,1,1,1,1,1,1,1,1,1,1,1,1,1
1,1,1,1,1,1,1,1,1,1,1,1,1,1,1,1
1,1,1,1,1,1,1,1,1,1,1,1,1,1,1,1
1,1,1,1,1,1,1,1,1,1,1,1,1,1,1,1
1,1,1,1,1,1,1,1,1,1,1,1,1,1,1,1
endlayer

layer
1,1,1,1,1,1,1,1,1,1,41,1,1,1,1,1
1,1,1,1,1,1,1,1,1,42,1,47,1,1,1,1
1,1,1,1,1,1,1,1,1,1,64,1,1,1,1,1
1,1,1,1,1,1,1,1,1,1,1,1,1,1,1,1
1,1,1,1,1,1,1,1,1,1,1,1,1,1,1,1
1,1,1,1,1,1,1,1,1,1,1,1,1,1,1,1
1,1,1,1,1,1,1,1,1,1,1,1,1,1,1,1
1,1,1,1,1,1,1,1,1,1,1,1,1,1,1,1
1,1,1,1,1,1,1,1,1,1,1,1,1,1,1,1
1,1,1,1,1,1,1,1,1,1,1,1,1,1,1,1
1,1,1,1,1,1,1,1,1,1,1,1,1,1,1,1
1,1,1,1,1,1,1,1,1,1,1,1,1,1,1,1
1,1,1,1,1,1,1,1,1,1,1,1,1,1,1,1
1,1,1,1,1,1,1,1,1,1,1,1,1,1,1,1
1,1,1,1,1,1,1,1,1,1,1,1,1,1,1,1
1,1,1,1,1,1,1,1,1,1,1,1,1,1,1,1
endlayer

layer
1,1,1,1,1,1,1,1,1,1,41,1,1,1,1,1
1,1,1,1,1,1,1,1,1,42,1,47,1,1,1,1
1,1,1,1,1,1,1,1,1,1,64,1,1,1,1,1
1,1,1,1,1,1,1,1,1,1,1,1,1,1,1,1
1,1,1,1,1,1,1,1,1,1,1,1,1,1,1,1
1,1,1,1,1,1,1,1,1,1,1,1,1,1,1,1
1,1,1,1,1,1,1,1,1,1,1,1,1,1,1,1
1,1,1,1,1,1,1,1,1,1,1,1,1,1,1,1
1,1,1,1,1,1,1,1,1,1,1,1,1,1,1,1
1,1,1,1,1,1,1,1,1,1,1,1,1,1,1,1
1,1,1,1,1,1,1,1,1,1,1,1,1,1,1,1
1,1,1,1,1,1,1,1,1,1,1,1,1,1,1,1
1,1,1,1,1,1,1,1,1,1,1,1,1,1,1,1
1,1,1,1,1,1,1,1,1,1,1,1,1,1,1,1
1,1,1,1,1,1,1,1,1,1,1,1,1,1,1,1
1,1,1,1,1,1,1,1,1,1,1,1,1,1,1,1
endlayer

