
# Created by Ruins mod version 16.7 Ingame Parser
# authoring Player: lafuller

weight=1
embed_into_distance=4
acceptable_target_blocks=
unacceptable_target_blocks=flowing_water,water,flowing_lava,lava
dimensions=20,11,11
allowable_overhang=0
max_leveling=20
leveling_buffer=-1
preserve_water=0
preserve_lava=0
preventRotation=1

rule1=0,100,preserveBlock
rule2=0,100,minecraft:stone_brick_stairs-2
rule3=0,100,stonebrick-0,stonebrick-0,stonebrick-0,stonebrick-0,stonebrick-1,stonebrick-2,stonebrick-2,stone-5,stone-6,cobblestone,stone_brick_stairs-0,stone_brick_stairs-1,stone_brick_stairs-2,stone_brick_stairs-3,stone_brick_stairs-4,stone_brick_stairs-5,stone_brick_stairs-6,stone_brick_stairs-7
rule4=0,100,minecraft:stone_brick_stairs-3
rule5=0,100,minecraft:stone_brick_stairs-1
rule6=0,100,minecraft:stone_brick_stairs-6
rule7=0,100,minecraft:stone_slab-13
rule8=0,100,minecraft:stone_brick_stairs-7
rule9=0,100,minecraft:stone_slab-5
rule10=0,100,minecraft:stone_brick_stairs-0

layer
1,4,3,3,3,3,3,3,2,1,1
1,3,3,3,3,3,3,3,3,1,1
1,3,3,3,3,3,3,3,3,3,1
1,3,3,3,3,3,3,3,3,3,1
1,3,3,3,3,3,3,3,3,3,1
1,3,3,3,3,5,5,5,5,3,3
1,3,3,3,3,3,1,1,1,1,3
1,5,5,5,5,3,1,1,1,1,1
1,1,1,1,1,3,1,1,1,1,1
3,1,1,1,1,1,1,1,1,1,1
3,3,1,1,1,1,1,1,1,1,1
endlayer

layer
1,1,4,3,3,3,3,2,1,1,1
1,3,3,3,3,3,3,3,3,1,1
1,3,3,3,3,3,3,3,3,3,1
1,3,3,3,3,3,3,3,3,3,1
1,3,3,3,5,5,5,5,5,3,1
1,3,3,3,3,1,1,1,1,3,3
1,5,5,5,3,3,1,1,1,1,3
1,1,1,1,1,3,1,1,1,1,1
1,1,1,1,1,3,1,1,1,1,1
3,1,1,1,1,1,1,1,1,1,1
3,3,1,1,1,1,1,1,1,1,1
endlayer

layer
1,1,1,4,3,3,2,1,1,1,1
1,3,3,3,3,3,3,3,3,1,1
1,3,3,3,3,3,3,3,3,3,1
1,3,3,3,5,5,5,3,3,3,1
1,3,3,3,1,1,1,1,1,3,1
1,5,3,3,3,1,1,1,1,3,3
1,1,1,1,3,3,1,1,1,1,3
1,1,1,1,1,3,1,1,1,1,1
1,1,1,1,1,3,1,1,1,1,1
3,1,1,1,1,1,1,1,1,1,1
1,1,1,1,1,1,1,1,1,1,1
endlayer

layer
1,1,1,1,1,1,1,1,1,1,1
1,3,3,2,1,1,3,3,3,1,1
1,3,3,3,1,1,1,3,3,3,1
1,3,3,3,1,1,1,3,3,3,1
1,5,3,3,1,1,1,1,1,3,1
1,1,3,3,3,1,1,1,1,3,3
1,1,1,1,3,3,1,1,1,1,3
1,1,1,1,1,3,1,1,1,1,1
1,1,1,1,1,3,1,1,1,1,1
1,1,1,1,1,1,1,1,1,1,1
1,1,1,1,1,1,1,1,1,1,1
endlayer

layer
1,1,1,1,1,1,1,1,1,1,1
1,3,2,1,1,1,3,3,3,1,1
1,3,3,3,1,1,1,3,3,3,1
1,5,3,3,1,1,1,3,3,3,1
1,1,3,3,1,1,1,1,1,3,1
1,1,3,3,3,1,1,1,1,3,3
1,1,1,1,3,3,1,1,1,1,1
1,1,1,1,1,3,1,1,1,1,1
1,1,1,1,1,1,1,1,1,1,1
1,1,1,1,1,1,1,1,1,1,1
1,1,1,1,1,1,1,1,1,1,1
endlayer

layer
1,1,1,1,1,1,1,1,1,1,1
1,1,1,1,1,1,3,3,3,1,1
1,1,4,3,1,1,1,3,3,3,1
1,1,3,3,1,1,1,3,3,3,1
1,1,3,3,1,1,1,1,1,3,1
1,1,3,3,3,1,1,1,1,1,1
1,1,1,1,3,3,1,1,1,1,1
1,1,1,1,1,1,1,1,1,1,1
1,1,1,1,1,1,1,1,1,1,1
1,1,1,1,1,1,1,1,1,1,1
1,1,1,1,1,1,1,1,1,1,1
endlayer

layer
1,1,1,1,1,1,1,1,1,1,1
1,1,1,1,1,1,3,3,3,1,1
1,1,1,4,6,1,1,3,3,3,1
1,1,3,3,1,1,1,3,3,3,1
1,1,3,3,1,1,1,1,1,1,1
1,1,3,3,3,1,1,1,1,1,1
1,1,1,1,1,1,1,1,1,1,1
1,1,1,1,1,1,1,1,1,1,1
1,1,1,1,1,1,1,1,1,1,1
1,1,1,1,1,1,1,1,1,1,1
1,1,1,1,1,1,1,1,1,1,1
endlayer

layer
1,1,1,1,1,1,1,1,1,1,1
1,1,1,1,1,1,3,3,3,1,1
1,1,1,1,4,6,1,3,3,3,1
1,1,3,3,1,1,1,3,3,1,1
1,1,3,3,1,1,1,1,1,1,1
1,1,3,3,1,1,1,1,1,1,1
1,1,1,1,1,1,1,1,1,1,1
1,1,1,1,1,1,1,1,1,1,1
1,1,1,1,1,1,1,1,1,1,1
1,1,1,1,1,1,1,1,1,1,1
1,1,1,1,1,1,1,1,1,1,1
endlayer

layer
1,1,1,1,1,1,1,1,1,1,1
1,1,1,1,1,1,3,3,3,1,1
1,1,1,1,1,4,3,3,3,3,1
1,1,3,3,1,1,1,3,3,6,1
1,1,3,3,1,1,1,1,1,1,1
1,1,3,3,1,1,1,1,1,1,1
1,1,1,1,1,1,1,1,1,1,1
1,1,1,1,1,1,1,1,1,1,1
1,1,1,1,1,1,1,1,1,1,1
1,1,1,1,1,1,1,1,1,1,1
1,1,1,1,1,1,1,1,1,1,1
endlayer

layer
1,1,1,1,1,1,1,1,7,7,3
1,1,1,1,1,7,7,3,3,3,3
1,1,1,1,1,1,4,3,3,3,3
1,1,3,3,3,3,3,3,3,3,7
7,3,3,3,3,3,7,7,7,7,1
3,3,3,3,7,7,7,1,1,1,1
3,3,3,7,7,1,1,1,1,1,1
3,7,7,1,1,1,1,1,1,1,1
7,1,1,1,1,1,1,1,1,1,1
1,1,1,1,1,1,1,1,1,1,1
1,1,1,1,1,1,1,1,1,1,1
endlayer

layer
1,1,1,1,1,1,1,1,1,1,1
1,1,1,1,1,1,1,3,1,1,1
1,1,1,1,1,1,1,1,3,3,1
1,1,3,1,1,1,1,1,3,1,1
1,1,3,3,1,8,2,1,1,1,1
1,1,3,3,1,1,1,1,1,1,1
1,1,1,1,1,1,1,1,1,1,1
1,1,1,1,1,1,1,1,1,1,1
1,1,1,1,1,1,1,1,1,1,1
1,1,1,1,1,1,1,1,1,1,1
1,1,1,1,1,1,1,1,1,1,1
endlayer

layer
1,1,1,1,1,1,1,1,1,1,1
1,1,1,1,1,1,1,3,1,1,1
1,1,1,1,1,1,1,1,3,3,1
1,1,3,1,1,1,1,1,3,1,1
1,1,3,3,8,2,1,1,1,1,1
1,1,3,3,1,1,1,1,1,1,1
1,1,1,1,1,1,1,1,1,1,1
1,1,1,1,1,1,1,1,1,1,1
1,1,1,1,1,1,1,1,1,1,1
1,1,1,1,1,1,1,1,1,1,1
1,1,1,1,1,1,1,1,1,1,1
endlayer

layer
1,1,1,1,1,1,1,1,1,1,1
1,1,1,1,1,1,1,3,1,1,1
1,1,1,1,1,1,1,1,3,3,1
1,1,3,1,1,1,1,1,3,1,1
1,1,3,3,2,1,1,1,1,1,1
1,1,3,3,1,1,1,1,1,1,1
1,1,1,1,1,1,1,1,1,1,1
1,1,1,1,1,1,1,1,1,1,1
1,1,1,1,1,1,1,1,1,1,1
1,1,1,1,1,1,1,1,1,1,1
1,1,1,1,1,1,1,1,1,1,1
endlayer

layer
1,1,1,1,1,1,1,1,1,1,1
1,1,1,1,1,1,1,3,1,1,1
1,1,1,1,1,1,1,1,3,3,1
1,1,3,1,1,1,1,1,3,1,1
1,1,3,2,1,1,1,1,1,1,1
1,1,3,3,1,1,1,1,1,1,1
1,1,1,1,1,1,1,1,1,1,1
1,1,1,1,1,1,1,1,1,1,1
1,1,1,1,1,1,1,1,1,1,1
1,1,1,1,1,1,1,1,1,1,1
1,1,1,1,1,1,1,1,1,1,1
endlayer

layer
1,1,1,1,1,1,1,1,3,3,3
1,1,1,1,1,3,3,3,3,3,3
1,1,1,3,3,3,3,3,3,3,3
1,1,3,3,3,3,3,3,3,3,3
3,3,2,1,1,1,1,8,3,1,1
3,3,3,3,3,3,1,1,1,1,1
3,3,3,3,1,1,1,1,1,1,1
3,3,3,1,1,1,1,1,1,1,1
3,1,1,1,1,1,1,1,1,1,1
1,1,1,1,1,1,1,1,1,1,1
1,1,1,1,1,1,1,1,1,1,1
endlayer

layer
1,1,1,1,1,1,1,1,1,1,1
1,1,1,1,1,1,1,1,1,1,1
1,1,1,1,1,1,1,3,3,1,1
1,1,1,1,4,6,1,3,3,1,1
1,1,1,1,1,1,1,1,3,9,9
1,1,3,3,1,1,9,9,9,9,9
1,1,1,3,9,9,9,9,1,1,1
1,1,1,9,9,9,1,1,1,1,1
1,9,9,9,1,1,1,1,1,1,1
9,9,1,1,1,1,1,1,1,1,1
9,1,1,1,1,1,1,1,1,1,1
endlayer

layer
1,1,1,1,1,1,1,1,1,1,1
1,1,1,1,1,1,1,1,1,1,1
1,1,1,1,1,1,1,3,3,1,1
1,1,1,1,1,4,6,3,3,1,1
1,1,1,1,1,1,1,1,3,1,1
1,1,3,3,1,1,1,1,1,1,1
1,1,1,3,1,1,1,1,1,1,1
1,1,1,1,1,1,1,1,1,1,1
1,1,1,1,1,1,1,1,1,1,1
1,1,1,1,1,1,1,1,1,1,1
1,1,1,1,1,1,1,1,1,1,1
endlayer

layer
1,1,1,1,1,1,1,1,1,1,1
1,1,1,1,1,1,1,1,1,1,1
1,1,1,1,1,1,1,3,3,1,1
1,1,1,1,1,1,4,3,3,1,1
1,1,1,1,1,1,1,1,3,1,1
1,1,3,3,1,1,1,1,1,1,1
1,1,1,3,1,1,1,1,1,1,1
1,1,1,1,1,1,1,1,1,1,1
1,1,1,1,1,1,1,1,1,1,1
1,1,1,1,1,1,1,1,1,1,1
1,1,1,1,1,1,1,1,1,1,1
endlayer

layer
1,1,1,1,1,1,1,1,1,1,1
1,1,1,1,1,1,1,1,1,1,1
1,1,1,1,1,1,1,4,10,1,1
1,1,1,1,1,1,1,4,3,3,3
1,1,10,3,3,3,3,3,3,3,3
1,1,3,3,3,3,3,3,3,3,3
1,3,3,3,3,3,3,3,7,7,7
3,3,3,3,3,3,7,7,1,1,1
3,3,3,3,7,7,1,1,1,1,1
3,3,7,7,1,1,1,1,1,1,1
3,7,1,1,1,1,1,1,1,1,1
endlayer

layer
1,1,1,1,1,1,1,1,1,1,1
1,1,1,1,1,1,1,1,1,1,1
1,1,1,1,1,1,1,1,1,1,1
1,1,1,1,1,1,1,1,3,1,1
1,1,1,1,1,1,1,1,3,3,1
1,1,3,3,1,1,1,1,1,3,1
1,1,1,3,3,1,1,1,1,1,1
1,1,1,1,3,1,1,1,1,1,1
1,1,1,1,1,1,1,1,1,1,1
3,1,1,1,1,1,1,1,1,1,1
3,1,1,1,1,1,1,1,1,1,1
endlayer

