
# Created by Ruins mod version 16.7 Ingame Parser
# authoring Player: lafuller

weight=1
embed_into_distance=5
acceptable_target_blocks=
unacceptable_target_blocks=flowing_water,water,flowing_lava,lava,ice,bedrock,netherrack,nether_brick,nether_brick_fence,soul_sand,quartz_ore,end_stone,obsidian,iron_bars,cloud,flesh,ash_block,slime_grass,slime_congealed,slime_dirt
dimensions=12,20,23
allowable_overhang=0
max_leveling=7
leveling_buffer=-1
preserve_water=0
preserve_lava=0

rule1=0,100,preserveBlock
rule2=0,100,minecraft:sandstone_stairs-0
rule3=0,100,minecraft:sandstone-2
rule4=0,100,minecraft:sandstone-0
rule5=0,100,minecraft:double_stone_slab-9
rule6=0,100,minecraft:sandstone_stairs-2
rule7=0,100,minecraft:sandstone_stairs-1
rule8=0,100,minecraft:sandstone_stairs-3
rule9=0,100,minecraft:wooden_slab-9
rule10=0,100,minecraft:dirt-0
rule11=0,100,minecraft:ladder-3
rule12=0,100,bookshelf,pumpkin,melon_block,hay_block,ChestGenHook:chests/spawn_bonus_chest:5-4,ChestGenHook:chests/village_blacksmith:5-4,ChestGenHook:chests/stronghold_library:5-4,ChestGenHook:chests/simple_dungeon:5-4
rule13=0,100,bookshelf,pumpkin,melon_block,hay_block,ChestGenHook:chests/spawn_bonus_chest:5-5,ChestGenHook:chests/village_blacksmith:5-5,ChestGenHook:chests/stronghold_library:5-5,ChestGenHook:chests/simple_dungeon:5-5
rule14=0,100,minecraft:spruce_stairs-7
rule15=0,100,minecraft:spruce_stairs-6
rule16=0,100,minecraft:trapdoor-11
rule17=0,100,bookshelf,pumpkin,melon_block,hay_block,ChestGenHook:chests/spawn_bonus_chest:5-3,ChestGenHook:chests/village_blacksmith:5-3,ChestGenHook:chests/stronghold_library:5-3,ChestGenHook:chests/simple_dungeon:5-3
rule18=0,100,minecraft:spruce_stairs-5
rule19=0,100,minecraft:stone_slab-1
rule20=0,100,minecraft:spruce_stairs-4
rule21=0,100,minecraft:carpet-8
rule22=0,100,minecraft:carpet-7
rule23=0,100,minecraft:sandstone_stairs-7
rule24=0,100,minecraft:sandstone_stairs-4
rule25=0,100,minecraft:sandstone_stairs-6
rule26=0,100,minecraft:sandstone_stairs-5
rule27=0,100,minecraft:jungle_door-5
rule28=0,100,minecraft:jungle_door-7
rule29=0,100,minecraft:jungle_door-6
rule30=0,100,minecraft:jungle_door-4
rule31=0,100,minecraft:ladder-2
rule32=0,100,minecraft:jungle_door-9
rule33=0,100,minecraft:jungle_door-8
rule34=0,100,minecraft:trapdoor-9
rule35=0,100,minecraft:wooden_slab-1
rule36=0,100,minecraft:stone_slab-9
rule37=0,100,minecraft:trapdoor-0
rule38=0,100,minecraft:trapdoor-10
rule39=0,100,minecraft:trapdoor-8
rule40=0,100,minecraft:trapdoor-1
rule41=0,100,minecraft:hay_block-0
rule42=0,100,minecraft:trapdoor-3
rule43=0,100,minecraft:trapdoor-2

layer
1,1,4,4,4,4,4,3,2,1,1,1,1,1,1,1,1,1,1,1,1,1,1
1,1,5,5,5,5,5,5,3,1,1,1,1,1,1,1,1,1,1,1,1,1,1
1,1,3,4,4,4,5,4,4,1,1,1,1,1,1,1,1,1,1,1,1,1,1
1,1,3,4,4,4,5,4,4,4,1,1,1,1,1,1,1,1,1,1,1,1,1
5,3,3,4,4,4,5,4,5,4,4,3,2,6,1,1,1,1,1,1,1,1,1
5,4,4,4,4,3,5,4,3,3,3,4,4,4,3,3,4,5,6,1,1,1,1
5,4,4,4,4,3,5,5,5,5,3,3,3,3,4,4,4,4,6,1,1,1,1
5,5,5,5,5,5,5,5,5,5,5,5,3,3,4,5,5,4,4,4,4,4,1
3,5,5,5,5,4,4,4,4,4,5,5,3,3,4,5,5,5,5,5,4,5,1
4,4,3,4,5,4,4,4,4,4,5,5,4,4,4,4,5,4,4,4,4,4,1
4,4,3,4,5,4,4,4,4,4,5,5,5,5,5,5,5,4,4,4,4,4,5
1,4,4,4,5,4,4,4,4,4,5,4,4,4,4,4,5,4,4,4,4,4,5
1,4,5,5,5,4,4,4,4,4,5,4,4,4,4,4,5,4,4,4,4,4,5
1,5,5,5,5,5,5,5,5,5,5,4,4,4,4,4,5,4,4,4,4,4,5
1,7,5,5,5,5,4,4,4,4,4,5,4,4,4,4,5,5,5,5,5,5,5
1,8,5,3,5,5,4,4,4,4,4,5,4,4,4,4,5,4,4,4,4,4,4
1,8,5,3,4,5,4,4,4,4,4,5,5,5,5,5,5,4,4,4,4,4,4
1,7,7,3,4,5,4,4,4,4,4,5,4,4,4,4,4,4,3,3,1,1,1
1,1,1,3,4,5,3,3,3,4,4,5,4,4,4,4,4,4,4,5,1,1,1
1,1,1,3,5,5,5,5,5,5,5,5,4,4,4,4,4,5,6,7,1,1,1
endlayer

layer
1,1,4,4,4,4,4,3,1,1,1,1,1,1,1,1,1,1,1,1,1,1,1
1,1,5,5,5,5,5,5,2,1,1,1,1,1,1,1,1,1,1,1,1,1,1
1,1,3,4,4,4,5,4,3,1,1,1,1,1,1,1,1,1,1,1,1,1,1
1,1,3,4,4,4,5,4,4,3,1,1,1,1,1,1,1,1,1,1,1,1,1
5,3,3,4,4,4,5,4,4,4,4,6,1,1,1,1,1,1,1,1,1,1,1
5,4,4,4,4,3,5,4,3,3,3,4,4,4,3,3,4,6,1,1,1,1,1
5,4,4,4,4,3,5,5,5,5,3,3,3,3,4,4,4,4,1,1,1,1,1
5,5,5,5,5,5,5,5,5,5,5,5,3,3,4,5,5,4,4,4,4,4,1
3,5,5,5,5,4,4,4,4,4,5,5,3,3,4,5,5,5,5,5,4,5,1
4,4,3,4,5,4,4,4,4,4,5,5,4,4,4,4,5,4,4,4,4,4,1
4,4,3,4,5,4,4,4,4,4,5,5,5,5,5,5,5,4,4,4,4,4,5
1,4,4,4,5,4,4,4,4,4,5,4,4,4,4,4,5,4,4,4,4,4,5
1,4,5,5,5,4,4,4,4,4,5,4,4,4,4,4,5,4,4,4,4,4,5
1,7,5,5,5,5,5,5,5,5,5,4,4,4,4,4,5,4,4,4,4,4,5
1,1,5,5,5,5,4,4,4,4,4,5,4,4,4,4,5,5,5,5,5,5,5
1,1,8,3,5,5,4,4,4,4,4,5,4,4,4,4,5,4,4,4,4,4,4
1,1,7,3,4,5,4,4,4,4,4,5,5,5,5,5,5,4,4,4,4,4,4
1,1,1,3,4,5,4,4,4,4,4,5,4,4,4,4,4,4,3,3,1,1,1
1,1,1,3,4,5,3,3,3,4,4,5,4,4,4,4,4,4,4,7,1,1,1
1,1,1,3,5,5,5,7,5,5,5,5,4,4,4,4,4,6,1,1,1,1,1
endlayer

layer
1,1,4,4,4,4,4,3,1,1,1,1,1,1,1,1,1,1,1,1,1,1,1
1,1,5,5,5,5,5,5,1,1,1,1,1,1,1,1,1,1,1,1,1,1,1
1,1,3,9,9,9,5,4,2,1,1,1,1,1,1,1,1,1,1,1,1,1,1
1,1,3,0,0,0,5,4,3,3,1,1,1,1,1,1,1,1,1,1,1,1,1
5,3,0,0,0,11,5,4,10,3,6,1,1,1,1,1,1,1,1,1,1,1,1
5,0,0,0,0,3,5,4,10,10,4,4,4,4,3,4,6,1,1,1,1,1,1
5,0,0,0,0,3,5,5,5,5,3,3,3,3,4,4,4,4,1,1,1,1,1
5,0,0,0,12,5,5,5,5,5,5,5,3,3,4,5,5,4,4,4,4,4,1
3,5,5,5,5,3,3,6,0,0,5,5,3,3,4,5,5,5,5,5,4,5,1
4,4,3,4,5,0,0,0,0,0,5,5,16,16,16,4,4,15,9,14,13,4,1
3,4,3,4,5,0,0,0,0,0,5,5,0,0,0,5,4,0,0,0,0,4,5
1,4,4,4,5,0,0,0,0,0,5,4,0,0,0,17,4,0,0,0,0,11,5
1,7,5,5,5,12,0,0,0,0,5,4,0,0,0,0,4,0,0,0,0,0,5
1,1,5,5,5,5,5,4,4,4,5,4,19,0,0,18,4,0,0,0,0,0,5
1,1,5,5,5,5,0,0,0,0,11,4,0,0,0,9,5,5,5,5,5,5,5
1,1,1,1,5,9,0,0,0,0,0,5,0,0,0,20,5,4,4,4,4,4,4
1,1,1,1,4,9,0,0,0,0,0,0,5,5,5,5,5,4,4,3,4,4,4
1,1,1,2,4,9,0,0,0,0,0,0,4,4,4,4,4,4,3,7,1,1,1
1,1,1,3,4,5,3,3,0,0,0,12,4,4,4,4,4,4,4,1,1,1,1
1,1,1,3,5,5,6,1,5,5,5,5,4,4,4,4,6,1,1,1,1,1,1
endlayer

layer
1,1,4,4,4,4,4,3,1,1,1,1,1,1,1,1,1,1,1,1,1,1,1
1,1,5,5,5,5,5,5,1,1,1,1,1,1,1,1,1,1,1,1,1,1,1
1,1,3,22,22,21,5,5,1,1,1,1,1,1,1,1,1,1,1,1,1,1,1
1,1,3,0,0,0,5,4,1,1,1,1,1,1,1,1,1,1,1,1,1,1,1
5,3,0,0,0,11,5,4,1,1,1,1,1,1,1,1,1,1,1,1,1,1,1
5,0,0,0,0,3,5,4,1,1,2,2,4,4,4,6,1,1,1,1,1,1,1
5,0,0,0,0,3,5,5,5,3,3,3,10,3,4,4,4,4,1,1,1,1,1
5,0,0,0,0,5,5,5,5,5,5,3,10,3,4,4,5,5,4,4,4,5,1
3,3,3,3,3,3,6,0,0,0,5,5,3,3,4,5,5,5,5,5,4,5,1
3,4,3,4,19,0,0,0,0,0,5,5,0,0,0,4,4,21,22,22,0,4,1
3,4,3,4,19,0,0,0,0,0,5,5,0,0,0,3,4,0,0,0,0,4,5
1,7,4,4,19,0,0,0,0,0,5,4,0,0,0,0,4,0,0,0,0,11,5
1,1,4,5,19,0,0,0,0,0,5,7,0,0,0,0,4,0,0,0,0,0,5
1,1,4,5,5,5,5,4,3,4,5,0,0,0,0,22,4,0,0,0,0,0,5
1,1,4,5,5,5,0,0,0,0,11,4,0,0,0,22,5,3,5,5,5,5,5
1,1,1,1,4,22,0,0,0,0,0,3,0,0,0,21,5,4,4,4,4,4,4
1,1,1,1,3,22,0,0,0,0,0,0,3,3,5,5,5,4,4,1,8,4,4
1,1,1,1,4,22,0,0,0,0,0,0,3,3,3,3,3,3,3,1,1,1,1
1,1,1,2,5,5,3,3,0,0,0,0,3,10,10,3,3,3,4,1,1,1,1
1,1,1,3,3,6,1,1,5,3,3,5,3,3,3,6,1,1,1,1,1,1,1
endlayer

layer
1,1,4,4,4,4,4,6,1,1,1,1,1,1,1,1,1,1,1,1,1,1,1
1,1,5,22,22,21,5,3,1,1,1,1,1,1,1,1,1,1,1,1,1,1,1
1,1,3,0,0,0,5,5,1,1,1,1,1,1,1,1,1,1,1,1,1,1,1
1,1,3,0,0,0,5,5,1,1,1,1,1,1,1,1,1,1,1,1,1,1,1
5,3,0,0,0,11,5,5,1,1,1,1,1,1,1,1,1,1,1,1,1,1,1
5,0,0,0,0,3,10,5,1,1,1,1,8,3,6,1,1,1,1,1,1,1,1
5,0,0,0,0,3,10,5,6,1,1,1,1,3,4,4,4,4,1,1,1,1,1
5,0,0,0,0,5,5,5,5,5,5,2,1,3,4,4,4,5,5,5,5,5,1
3,3,3,3,3,6,0,0,0,0,5,3,3,3,4,4,0,0,0,0,0,5,1
3,10,3,5,0,0,0,0,0,0,5,5,0,0,0,4,0,0,0,0,0,4,1
3,7,3,5,0,0,0,0,0,0,5,3,0,0,0,3,0,0,0,0,0,4,5
1,1,4,5,0,0,0,0,0,0,5,7,0,0,0,0,4,0,0,0,0,11,5
1,1,4,5,0,0,0,0,0,0,5,0,0,0,0,0,4,0,0,0,0,0,5
1,1,4,4,5,5,3,4,4,4,4,0,0,0,0,0,4,0,0,0,0,0,5
1,1,4,4,5,5,0,0,0,0,11,4,0,0,0,0,5,3,5,5,5,5,5
1,1,1,1,5,0,0,0,0,0,0,3,0,0,0,0,5,3,4,4,4,4,3
1,1,1,1,5,0,0,0,0,0,0,0,3,3,5,5,5,4,4,1,1,8,3
1,1,1,1,5,0,0,0,0,0,0,0,3,3,3,3,3,3,3,1,1,1,1
1,1,1,1,7,5,3,3,0,0,0,0,3,1,1,1,1,8,3,1,1,1,1
1,1,1,1,1,1,1,1,5,5,5,5,6,1,1,1,1,1,1,1,1,1,1
endlayer

layer
1,1,4,4,4,4,4,1,1,1,1,1,1,1,1,1,1,1,1,1,1,1,1
1,1,5,9,9,9,3,2,1,1,1,1,1,1,1,1,1,1,1,1,1,1,1
1,1,5,9,9,9,5,3,1,1,1,1,1,1,1,1,1,1,1,1,1,1,1
1,1,5,9,9,9,5,5,1,1,1,1,1,1,1,1,1,1,1,1,1,1,1
3,5,9,9,9,11,5,7,1,1,1,1,1,1,1,1,1,1,1,1,1,1,1
5,18,18,18,18,5,1,1,1,1,1,1,1,1,1,1,1,1,1,1,1,1,1
5,9,9,9,9,5,1,1,1,1,1,1,1,2,4,4,4,4,1,1,1,1,1
3,4,4,4,4,5,5,5,5,5,6,1,1,3,4,4,4,4,5,5,5,4,1
7,8,3,4,6,0,0,0,23,5,5,2,3,3,4,9,9,9,9,9,9,5,1
1,1,7,5,9,9,9,9,9,9,5,4,5,5,5,9,9,9,9,9,9,5,1
1,1,8,5,18,18,18,18,18,18,5,7,9,15,9,5,9,9,9,9,9,5,5
1,1,4,5,9,9,9,24,24,24,5,0,9,15,9,9,5,24,9,9,9,11,3
1,1,4,9,9,9,23,5,5,5,5,0,9,15,9,9,9,3,25,9,9,9,5
1,1,4,9,9,9,5,18,18,15,5,0,9,15,9,9,9,3,25,9,9,9,5
1,1,4,4,4,5,26,15,9,15,11,5,9,15,9,9,9,3,5,3,5,5,3
1,1,1,1,5,5,9,15,9,15,9,5,24,25,24,9,9,3,4,4,4,6,1
1,1,1,1,5,5,9,15,9,15,9,5,10,10,10,5,3,4,4,1,1,1,1
1,1,1,1,7,5,9,15,9,15,9,5,4,4,4,4,4,6,1,1,1,1,1
1,1,1,1,1,5,5,5,5,5,5,5,7,1,1,1,1,1,1,1,1,1,1
1,1,1,1,1,1,1,1,3,5,5,3,1,1,1,1,1,1,1,1,1,1,1
endlayer

layer
1,1,3,4,4,4,3,1,1,1,1,1,1,1,1,1,1,1,1,1,1,1,1
1,1,5,0,0,0,5,1,1,1,1,1,1,1,1,1,1,1,1,1,1,1,1
1,1,4,0,0,0,27,1,1,1,1,1,1,1,1,1,1,1,1,1,1,1,1
1,1,4,0,0,0,3,1,1,1,1,1,1,1,1,1,1,1,1,1,1,1,1
5,3,0,0,0,11,4,1,1,1,1,1,1,1,1,1,1,1,1,1,1,1,1
5,0,0,0,0,4,1,1,1,1,1,1,1,1,1,1,1,1,1,1,1,1,1
5,0,0,0,0,4,1,1,1,1,1,1,1,1,3,4,4,3,1,1,1,1,1
5,29,5,5,5,5,5,5,1,1,1,1,1,1,28,0,0,0,4,4,4,3,1
1,1,1,4,0,0,0,0,4,30,5,1,1,1,4,0,0,0,0,0,0,4,1
1,1,1,28,0,0,0,0,0,0,5,4,30,4,4,0,0,0,0,0,0,4,1
1,1,1,4,0,0,0,0,0,0,5,0,0,0,0,5,0,0,0,0,0,4,5
1,1,3,4,0,0,0,4,4,4,5,0,0,0,0,0,4,4,0,0,0,11,5
1,1,4,0,0,11,4,9,9,9,5,0,0,0,0,0,0,0,4,31,0,0,5
1,1,4,0,0,0,4,0,0,0,5,0,0,0,0,0,0,0,4,0,0,0,5
1,1,3,4,4,5,4,0,0,0,11,5,0,0,0,0,0,0,5,5,29,5,5
1,1,1,1,1,3,0,0,0,0,0,5,4,4,4,0,0,0,4,1,1,1,1
1,1,1,1,1,28,0,0,0,0,0,5,1,1,1,5,29,4,3,1,1,1,1
1,1,1,1,1,3,0,0,0,0,0,27,1,1,1,1,1,1,1,1,1,1,1
1,1,1,1,1,5,4,4,0,0,0,5,1,1,1,1,1,1,1,1,1,1,1
1,1,1,1,1,1,1,1,5,5,5,5,1,1,1,1,1,1,1,1,1,1,1
endlayer

layer
1,1,3,4,1,4,3,1,1,1,1,1,1,1,1,1,1,1,1,1,1,1,1
1,1,4,0,0,0,3,1,1,1,1,1,1,1,1,1,1,1,1,1,1,1,1
1,1,1,0,0,0,32,1,1,1,1,1,1,1,1,1,1,1,1,1,1,1,1
1,1,4,0,0,0,3,1,1,1,1,1,1,1,1,1,1,1,1,1,1,1,1
5,3,0,0,0,0,4,1,1,1,1,1,1,1,1,1,1,1,1,1,1,1,1
1,0,0,0,0,4,1,1,1,1,1,1,1,1,1,1,1,1,1,1,1,1,1
5,0,0,0,0,4,1,1,1,1,1,1,1,1,3,4,1,3,1,1,1,1,1
3,32,3,5,5,5,5,5,1,1,1,1,1,1,32,0,0,0,4,1,4,3,1
1,1,1,4,0,0,0,0,4,33,5,1,1,1,4,0,0,0,0,0,0,1,1
1,1,1,33,0,0,0,0,0,0,5,4,33,4,4,0,0,0,0,0,0,4,1
1,1,1,4,0,0,0,0,0,0,5,0,0,0,0,5,0,0,0,0,0,4,4
1,1,3,4,0,0,0,4,4,4,5,0,0,0,0,0,4,4,0,0,0,0,5
1,1,1,0,0,11,4,22,22,21,5,0,0,0,0,0,0,0,4,31,0,0,1
1,1,3,9,9,9,4,0,0,0,5,0,0,0,0,0,0,0,4,0,0,0,5
1,1,3,4,4,5,4,0,0,0,0,5,0,0,0,0,0,0,4,5,33,5,3
1,1,1,1,1,3,0,0,0,0,0,5,4,1,4,0,0,0,4,1,1,1,1
1,1,1,1,1,33,0,0,0,0,0,5,1,1,1,5,33,4,3,1,1,1,1
1,1,1,1,1,3,0,0,0,0,0,32,1,1,1,1,1,1,1,1,1,1,1
1,1,1,1,1,5,1,4,0,0,0,5,1,1,1,1,1,1,1,1,1,1,1
1,1,1,1,1,1,1,1,5,1,5,3,1,1,1,1,1,1,1,1,1,1,1
endlayer

layer
1,1,4,4,4,4,4,1,1,1,1,1,1,1,1,1,1,1,1,1,1,1,1
1,1,5,0,0,0,5,1,1,1,1,1,1,1,1,1,1,1,1,1,1,1,1
1,1,4,0,0,0,5,1,1,1,1,1,1,1,1,1,1,1,1,1,1,1,1
1,1,4,0,0,0,5,1,1,1,1,1,1,1,1,1,1,1,1,1,1,1,1
5,3,0,0,0,0,3,1,1,1,1,1,1,1,1,1,1,1,1,1,1,1,1
5,0,0,0,0,4,1,1,1,1,1,1,1,1,1,1,1,1,1,1,1,1,1
5,0,0,0,0,4,1,1,1,1,1,1,1,1,4,4,4,4,1,1,1,1,1
5,5,5,5,5,5,5,5,9,9,9,9,9,9,3,0,0,0,4,4,4,4,1
1,1,34,4,0,0,0,0,3,3,5,1,1,1,4,0,0,0,0,0,0,4,1
1,1,34,4,0,0,0,0,0,0,5,4,3,3,4,0,0,0,0,0,0,4,1
1,1,34,4,0,0,0,0,0,0,5,0,0,0,0,5,0,0,0,0,0,4,5
1,1,4,4,0,0,0,4,4,4,5,0,0,0,0,0,4,4,0,0,0,0,5
1,1,3,0,0,0,4,0,0,0,5,0,0,0,0,0,0,0,4,0,0,0,5
1,1,4,21,22,22,4,0,0,0,5,0,0,0,0,0,0,0,4,35,35,35,5
1,1,4,4,4,5,4,0,0,0,0,5,0,0,0,0,0,0,5,5,5,5,5
1,1,1,1,1,5,0,0,0,0,0,5,4,4,4,0,0,0,4,1,1,1,1
1,1,1,1,1,3,0,0,0,0,0,5,9,9,9,5,5,4,4,1,1,1,1
1,1,1,1,1,5,0,0,0,0,0,5,1,1,1,1,1,1,1,1,1,1,1
1,1,1,1,1,5,4,4,0,0,0,5,1,1,1,1,1,1,1,1,1,1,1
1,1,1,1,1,1,1,1,5,5,5,5,1,1,1,1,1,1,1,1,1,1,1
endlayer

layer
1,1,3,4,4,4,3,1,1,1,1,1,1,1,1,1,1,1,1,1,1,1,1
1,1,5,0,0,0,3,1,1,1,1,1,1,1,1,1,1,1,1,1,1,1,1
1,1,4,0,0,0,5,1,1,1,1,1,1,1,1,1,1,1,1,1,1,1,1
1,1,4,0,0,0,5,1,1,1,1,1,1,1,1,1,1,1,1,1,1,1,1
2,2,25,36,36,36,5,1,1,1,1,1,1,1,1,1,1,1,1,1,1,1,1
8,36,36,38,36,4,37,1,1,1,1,1,1,1,1,1,1,1,1,1,1,1,1
8,36,36,36,36,4,37,1,1,1,1,1,1,1,3,4,4,3,1,1,1,1,1
7,7,7,5,5,5,5,5,1,1,1,1,1,1,4,0,0,25,4,4,4,3,1
1,1,1,4,0,0,0,23,4,4,3,35,35,35,4,0,0,25,36,36,36,4,1
1,1,1,4,0,0,0,23,9,9,5,2,2,2,4,0,0,25,36,38,36,4,1
1,1,1,4,0,0,0,23,9,9,5,25,36,16,36,4,24,25,24,24,24,4,5
1,1,3,4,0,0,24,4,4,4,5,25,36,36,36,36,4,4,25,0,0,0,3
1,1,4,0,0,0,4,0,0,0,5,25,0,0,0,36,36,36,4,0,0,0,5
1,1,4,0,0,0,4,0,0,0,5,25,0,0,0,36,39,36,4,0,0,0,5
1,1,3,4,4,4,4,26,25,26,26,5,0,0,0,36,36,36,5,3,5,5,3
1,1,1,1,1,8,36,36,25,0,0,5,4,4,3,24,36,36,6,1,1,1,1
1,1,1,1,1,8,38,36,25,0,0,5,1,1,1,8,7,7,7,1,1,1,1
1,1,1,1,1,8,36,36,25,0,0,5,1,1,1,1,1,1,1,1,1,1,1
1,1,1,1,1,8,7,7,25,0,0,5,1,1,1,1,1,1,1,1,1,1,1
1,1,1,1,1,1,1,1,3,3,5,3,1,1,1,1,1,1,1,1,1,1,1
endlayer

layer
1,1,19,3,2,3,19,1,1,1,1,1,1,1,1,1,1,1,1,1,1,1,1
1,1,3,9,9,9,3,1,1,1,1,1,1,1,1,1,1,1,1,1,1,1,1
1,1,8,9,16,9,6,1,1,1,1,1,1,1,1,1,1,1,1,1,1,1,1
1,1,3,9,9,9,3,1,1,1,1,1,1,1,1,1,1,1,1,1,1,1,1
1,1,19,3,7,3,19,1,1,1,1,1,1,1,1,1,1,1,1,1,1,1,1
1,1,1,1,1,1,1,1,1,1,1,1,1,1,1,1,1,1,1,1,1,1,1
1,1,1,1,1,1,1,1,1,1,1,1,1,1,19,19,19,19,1,1,1,1,1
1,1,1,19,2,3,2,19,1,1,1,1,1,1,19,37,40,19,1,1,1,1,1
1,1,1,8,0,0,0,6,1,1,1,1,1,1,19,37,40,19,1,1,1,1,1
1,1,1,3,0,0,0,3,1,1,1,1,1,1,19,37,40,19,1,1,1,1,1
1,1,1,8,0,0,0,6,1,1,1,1,1,1,19,19,19,19,3,2,2,2,3
1,1,1,2,3,3,7,19,19,19,19,4,4,4,4,4,1,1,8,41,41,41,6
1,1,8,3,38,3,6,19,42,42,19,4,0,0,0,4,1,1,8,41,16,41,6
1,1,8,3,3,3,6,19,43,43,19,4,0,0,0,4,1,1,8,41,41,41,6
1,1,1,7,7,7,19,19,19,19,19,4,0,0,0,4,1,1,3,7,7,7,3
1,1,1,1,1,1,1,1,19,2,2,4,6,19,8,4,1,1,1,1,1,1,1
1,1,1,1,1,1,1,1,3,36,36,3,1,1,1,1,1,1,1,1,1,1,1
1,1,1,1,1,1,1,1,3,39,36,3,1,1,1,1,1,1,1,1,1,1,1
1,1,1,1,1,1,1,1,3,36,36,3,1,1,1,1,1,1,1,1,1,1,1
1,1,1,1,1,1,1,1,19,7,7,19,1,1,1,1,1,1,1,1,1,1,1
endlayer

layer
1,1,1,1,1,1,1,1,1,1,1,1,1,1,1,1,1,1,1,1,1,1,1
1,1,1,1,1,1,1,1,1,1,1,1,1,1,1,1,1,1,1,1,1,1,1
1,1,1,1,1,1,1,1,1,1,1,1,1,1,1,1,1,1,1,1,1,1,1
1,1,1,1,1,1,1,1,1,1,1,1,1,1,1,1,1,1,1,1,1,1,1
1,1,1,1,1,1,1,1,1,1,1,1,1,1,1,1,1,1,1,1,1,1,1
1,1,1,1,1,1,1,1,1,1,1,1,1,1,1,1,1,1,1,1,1,1,1
1,1,1,1,1,1,1,1,1,1,1,1,1,1,1,1,1,1,1,1,1,1,1
1,1,1,1,1,19,1,1,1,1,1,1,1,1,1,1,1,1,1,1,1,1,1
1,1,1,1,19,19,19,1,1,1,1,1,1,1,1,1,1,1,1,1,1,1,1
1,1,1,19,19,43,19,19,1,1,1,1,1,1,1,1,1,1,1,1,1,1,1
1,1,1,1,19,19,19,1,1,1,1,1,1,1,1,1,1,1,1,1,1,1,1
1,1,1,1,1,19,1,1,1,1,1,8,2,2,2,2,1,1,1,1,1,1,1
1,1,1,1,1,1,1,1,1,1,1,8,35,35,35,6,1,1,1,1,1,1,1
1,1,1,1,1,1,1,1,1,1,1,8,35,42,35,6,1,1,1,1,1,1,1
1,1,1,1,1,1,1,1,1,1,1,8,35,35,35,6,1,1,1,1,1,1,1
1,1,1,1,1,1,1,1,1,1,1,7,7,7,7,6,1,1,1,1,1,1,1
1,1,1,1,1,1,1,1,1,1,1,1,1,1,1,1,1,1,1,1,1,1,1
1,1,1,1,1,1,1,1,1,1,1,1,1,1,1,1,1,1,1,1,1,1,1
1,1,1,1,1,1,1,1,1,1,1,1,1,1,1,1,1,1,1,1,1,1,1
1,1,1,1,1,1,1,1,1,1,1,1,1,1,1,1,1,1,1,1,1,1,1
endlayer

