# Gilly's Gazebo "Za-Bee-Go" house for beekeeping

# template generated by Ruins mod version 14.6 Ingame Parser
# Structure created by Gilly

weight=1
embed_into_distance=3
acceptable_target_blocks=
unacceptable_target_blocks=flowing_water,water,flowing_lava,lava,ice,bedrock,netherrack,nether_brick,nether_brick_fence,soul_sand,quartz_ore,gravel,end_stone,obsidian,iron_bars,cloud,flesh,ash_block,slime_grass,slime_congealed,slime_dirt
biomesToSpawnIn=plains,mutated_plains,mutated_forest,prarie,meadow,badlands,lavender fields,flower field,sunflower plains
dimensions=13,14,13
allowable_overhang=0
max_leveling=3
leveling_buffer=-1
preserve_water=0
preserve_lava=0

rule1=0,100,preserveBlock
rule2=0,100,double_stone_slab-8
rule3=0,100,stonebrick-0,stonebrick-0,stonebrick-0,stonebrick-0,stonebrick-1,stonebrick-2,stonebrick-2,stone-5,stone-6,cobblestone,gravel
rule4=0,100,stone_brick_stairs-0
rule5=0,100,stone_brick_stairs-1
rule6=0,100,stone_brick_stairs-2
rule7=0,100,stone_brick_stairs-3
rule8=0,100,planks-1
rule9=0,100,fence-0
rule10=0,100,grass-0
rule11=0,100,dirt-0
rule12=0,100,stone_brick_stairs-6
rule13=0,100,stone_brick_stairs-7
rule14=0,100,stone_brick_stairs-5
rule15=0,100,log-0
rule16=0,100,planks-2
rule17=0,100,cauldron-0
rule18=0,100,ChestGenHook:chests/spawn_bonus_chest:4-2
rule19=0,100,wooden_door-2
rule20=0,100,birch_stairs-0
rule21=0,100,birch_stairs-3
rule22=0,100,birch_stairs-2
rule23=0,100,IInventory;furnace;coal#1#0#1-2
rule24=0,100,wooden_door-9
rule25=0,100,wooden_door-8
rule26=0,100,fence_gate-1
rule27=0,100,fence_gate-3
rule28=0,100,iron_bars-0
rule29=2,100,torch-3
rule30=0,100,cobblestone_wall-0
rule31=2,100,torch-2
rule32=0,100,fence_gate-0
rule33=0,100,fence_gate-2
rule34=0,100,wooden_slab-5
rule35=0,100,planks-5
rule36=0,100,dark_oak_stairs-1
rule37=0,100,wooden_slab-2
rule38=0,100,dark_oak_fence

layer
1,1,1,1,1,1,1,1,1,1,1,1,1
1,1,1,2,3,3,3,3,3,2,1,1,1
1,1,1,3,1,1,1,1,1,3,1,1,1
1,1,2,1,1,1,1,1,1,1,2,1,1
1,1,3,1,1,1,1,1,1,1,3,1,1
4,4,3,1,1,1,1,1,1,1,3,4,4
3,2,3,1,1,1,1,1,1,1,3,2,3
3,2,3,1,1,1,1,1,1,1,3,2,3
3,3,1,1,1,1,1,1,1,1,1,3,3
3,3,1,1,1,1,1,1,1,1,1,3,3
3,3,1,1,1,1,1,1,1,1,1,3,3
3,3,3,1,1,1,1,1,1,1,3,3,3
3,3,3,3,1,1,1,1,1,3,3,3,3
5,5,5,3,3,3,3,3,3,3,5,5,5
endlayer

layer
1,1,1,1,1,1,1,1,1,1,1,1,1
1,1,1,2,3,3,3,3,3,2,1,1,1
1,1,1,3,1,1,1,1,1,3,1,1,1
1,1,2,1,1,1,1,1,1,1,2,1,1
1,1,3,1,1,1,1,1,1,1,3,1,1
1,1,3,1,1,1,1,1,1,1,3,1,1
4,2,3,1,1,1,1,1,1,1,3,2,4
3,2,3,1,1,1,1,1,1,1,3,2,3
3,3,1,1,1,1,1,1,1,1,1,3,3
3,3,1,1,1,1,1,1,1,1,1,3,3
3,3,1,1,1,1,1,1,1,1,1,3,3
3,3,3,1,1,1,1,1,1,1,3,3,3
5,5,3,3,1,1,1,1,1,3,3,5,5
1,1,1,3,3,3,3,3,3,3,1,1,1
endlayer

layer
1,1,1,1,1,1,1,1,1,1,1,1,1
1,1,1,2,3,3,3,3,3,2,1,1,1
1,1,1,3,1,1,1,1,1,3,1,1,1
1,1,2,1,1,1,1,1,1,1,2,1,1
1,1,3,1,1,1,1,1,1,1,3,1,1
1,1,3,1,1,1,1,1,1,1,3,1,1
1,2,3,1,1,1,1,1,1,1,3,2,1
1,2,3,1,1,1,1,1,1,1,3,2,1
1,7,3,1,1,1,1,1,1,1,3,6,1
1,7,3,1,1,1,1,1,1,1,3,6,1
1,7,3,1,1,1,1,1,1,1,3,6,1
1,5,3,1,1,1,1,1,1,1,3,5,1
1,1,3,3,1,1,1,1,1,3,3,1,1
1,1,1,3,3,3,3,3,3,3,1,1,1
endlayer

layer
1,1,1,1,1,1,1,1,1,1,1,1,1
1,1,1,2,3,3,3,3,3,2,1,1,1
1,1,1,3,8,8,8,8,8,3,1,1,1
1,1,2,8,8,8,8,8,8,8,2,1,1
1,1,3,8,8,8,8,8,8,8,3,1,1
1,1,3,8,8,8,8,8,8,8,3,1,1
1,9,3,8,8,8,8,8,8,8,3,9,1
1,9,3,8,8,8,8,8,8,8,3,9,1
1,1,7,10,10,10,10,10,10,10,6,1,1
1,1,7,10,10,10,10,10,10,10,6,1,1
1,1,7,10,10,10,10,10,10,10,6,1,1
1,1,3,10,10,10,10,10,10,11,3,1,1
1,1,13,10,11,10,10,11,10,10,12,1,1
1,1,1,14,14,14,14,14,14,14,1,1,1
endlayer

layer
1,1,1,0,0,0,0,0,0,0,1,1,1
1,1,0,15,16,16,16,16,16,15,0,1,1
1,0,0,16,0,0,0,0,0,16,0,0,1
1,0,15,17,0,0,0,0,0,0,15,0,1
0,0,16,0,0,0,0,0,0,0,16,0,0
0,0,16,18,0,0,0,0,0,0,16,0,0
0,9,16,18,0,0,0,0,0,0,16,9,0
0,9,15,16,16,16,16,19,19,16,15,9,0
0,0,0,0,0,0,0,0,0,0,0,0,0
0,0,0,0,0,0,0,0,0,0,0,0,0
0,0,0,0,0,0,0,0,0,0,0,0,0
1,0,16,0,0,0,0,0,0,8,16,0,1
1,0,16,20,8,0,0,8,0,20,16,0,1
1,1,0,22,20,20,20,20,20,21,0,1,1
endlayer

layer
1,1,0,0,0,0,0,0,0,0,0,1,1
1,0,0,15,16,0,0,0,16,15,0,0,1
0,0,0,16,0,0,0,0,0,16,0,0,0
0,0,15,23,0,0,0,0,0,0,15,0,0
0,0,16,0,0,0,0,0,0,0,16,0,0
0,0,0,0,0,0,0,0,0,0,0,0,0
0,9,16,0,0,0,0,0,0,0,16,9,0
0,9,15,16,0,0,16,25,24,16,15,9,0
0,0,0,0,0,0,0,0,0,0,0,0,0
0,0,0,0,0,0,0,0,0,0,0,0,0
0,0,0,0,0,0,0,0,0,0,0,0,0
0,0,9,0,0,0,0,0,0,0,9,0,0
0,0,9,0,0,0,0,0,0,0,9,0,0
1,0,0,9,26,9,27,9,26,9,0,0,1
endlayer

layer
1,0,0,0,0,0,0,0,0,0,0,0,1
0,0,0,15,16,28,28,28,16,15,0,0,0
0,0,0,16,0,0,0,0,0,16,0,0,0
0,0,15,30,0,0,0,0,0,29,15,0,0
0,0,16,0,0,0,0,0,0,0,16,0,0
0,0,28,0,0,0,0,0,0,0,28,0,0
0,9,16,0,0,0,31,0,0,0,16,9,0
0,9,15,16,28,28,16,9,9,16,15,9,0
0,0,0,0,0,0,0,0,0,0,0,0,0
0,0,0,0,0,0,0,0,0,0,0,0,0
0,0,0,0,0,0,0,0,0,0,0,0,0
0,0,9,0,0,0,0,0,0,0,9,0,0
0,0,0,0,0,0,0,0,0,0,0,0,0
0,0,0,9,0,0,0,0,0,9,0,0,0
endlayer

layer
0,0,0,0,0,0,0,0,0,0,0,0,0
0,0,0,15,16,16,16,16,16,15,0,0,0
0,0,0,16,0,0,0,0,0,16,0,0,0
0,0,15,30,0,0,0,0,0,0,15,0,0
0,0,16,0,0,0,0,0,0,0,16,0,0
0,0,16,0,0,0,0,0,0,0,16,0,0
0,9,16,0,0,0,0,0,0,0,16,9,0
0,9,15,16,16,16,16,16,16,16,15,9,0
0,0,0,0,0,0,0,0,0,0,0,0,0
0,0,0,0,0,0,0,0,0,0,0,0,0
0,0,0,0,0,0,0,0,0,0,0,0,0
0,0,9,0,0,0,0,0,0,0,9,0,0
0,0,0,33,0,0,0,0,0,32,0,0,0
0,0,0,9,26,26,26,26,26,9,0,0,0
endlayer

layer
0,0,0,34,34,34,34,34,34,34,0,0,0
0,0,34,35,35,35,35,35,35,35,34,0,0
0,0,34,35,8,8,8,8,8,35,34,0,0
0,34,35,8,8,8,8,8,8,8,35,34,0
0,34,35,8,8,8,8,8,8,8,35,34,0
0,34,35,8,8,8,8,8,8,8,35,34,0
0,34,35,8,8,8,8,8,8,8,35,34,0
0,9,36,36,36,36,36,36,36,36,36,9,0
0,0,0,0,0,0,0,0,0,0,0,0,0
0,0,0,0,0,0,0,0,0,0,0,0,0
0,0,32,0,0,0,0,0,0,0,33,0,0
0,0,9,27,27,27,27,27,27,27,9,0,0
0,0,34,34,37,37,37,37,37,34,34,0,0
0,0,0,34,34,34,34,34,34,34,0,0,0
endlayer

layer
0,0,0,0,0,0,0,0,0,0,0,0,0
0,0,0,38,38,38,38,38,38,38,0,0,0
0,0,0,38,34,34,34,34,34,38,0,0,0
0,0,38,30,34,34,34,34,34,34,38,0,0
0,0,38,34,34,34,34,34,34,34,38,0,0
0,0,38,34,34,34,34,34,34,34,38,0,0
0,0,38,34,34,34,34,34,34,34,38,0,0
0,9,38,38,38,38,38,38,38,38,38,9,0
0,32,0,0,0,0,0,0,0,0,0,32,0
0,9,27,27,27,27,27,27,27,27,27,9,0
0,34,34,37,37,37,37,37,37,37,34,34,0
0,0,34,34,34,34,34,34,34,34,34,0,0
0,0,0,0,0,0,0,0,0,0,0,0,0
0,0,0,0,0,0,0,0,0,0,0,0,0
endlayer

layer
0,0,0,0,0,0,0,0,0,0,0,0,0
0,0,0,0,0,0,0,0,0,0,0,0,0
0,0,0,0,0,0,0,0,0,0,0,0,0
0,0,0,30,0,0,0,0,0,0,0,0,0
0,0,0,0,0,0,0,0,0,0,0,0,0
0,0,0,0,0,0,0,0,0,0,0,0,0
0,0,0,0,0,0,0,0,0,0,0,0,0
34,34,34,34,34,34,34,34,34,34,34,34,34
34,34,37,37,37,37,37,37,37,37,37,34,34
0,34,34,34,34,34,34,34,34,34,34,34,0
0,0,0,0,0,0,0,0,0,0,0,0,0
0,0,0,0,0,0,0,0,0,0,0,0,0
0,0,0,0,0,0,0,0,0,0,0,0,0
0,0,0,0,0,0,0,0,0,0,0,0,0
endlayer

layer
0,0,0,0,0,0,0,0,0,0,0,0,0
0,0,0,0,0,0,0,0,0,0,0,0,0
0,0,0,0,0,0,0,0,0,0,0,0,0
0,0,0,30,0,0,0,0,0,0,0,0,0
0,0,0,0,0,0,0,0,0,0,0,0,0
0,0,0,0,0,0,0,0,0,0,0,0,0
0,0,0,0,0,0,0,0,0,0,0,0,0
0,0,0,0,0,0,0,0,0,0,0,0,0
0,0,0,0,0,0,0,0,0,0,0,0,0
0,0,0,0,0,0,0,0,0,0,0,0,0
0,0,0,0,0,0,0,0,0,0,0,0,0
0,0,0,0,0,0,0,0,0,0,0,0,0
0,0,0,0,0,0,0,0,0,0,0,0,0
0,0,0,0,0,0,0,0,0,0,0,0,0
endlayer

layer
0,0,0,0,0,0,0,0,0,0,0,0,0
0,0,0,0,0,0,0,0,0,0,0,0,0
0,0,0,0,0,0,0,0,0,0,0,0,0
0,0,0,30,0,0,0,0,0,0,0,0,0
0,0,0,0,0,0,0,0,0,0,0,0,0
0,0,0,0,0,0,0,0,0,0,0,0,0
0,0,0,0,0,0,0,0,0,0,0,0,0
0,0,0,0,0,0,0,0,0,0,0,0,0
0,0,0,0,0,0,0,0,0,0,0,0,0
0,0,0,0,0,0,0,0,0,0,0,0,0
0,0,0,0,0,0,0,0,0,0,0,0,0
0,0,0,0,0,0,0,0,0,0,0,0,0
0,0,0,0,0,0,0,0,0,0,0,0,0
0,0,0,0,0,0,0,0,0,0,0,0,0
endlayer

