
# Created by Ruins mod version 16.7 Ingame Parser
# authoring Player: lafuller

weight=1
embed_into_distance=4
acceptable_target_blocks=
unacceptable_target_blocks=flowing_water,water,flowing_lava,lava,ice,bedrock,netherrack,nether_brick,nether_brick_fence,soul_sand,quartz_ore,end_stone,obsidian,iron_bars,cloud,flesh,ash_block,slime_grass,slime_congealed,slime_dirt
dimensions=17,9,12
allowable_overhang=0
max_leveling=7
leveling_buffer=-1
preserve_water=0
preserve_lava=0

rule1=0,100,preserveBlock
rule2=0,100,minecraft:sandstone-0
rule3=0,100,minecraft:double_stone_slab-9
rule4=0,100,minecraft:sandstone_stairs-0
rule5=0,100,minecraft:sandstone_stairs-3
rule6=0,100,minecraft:sandstone_stairs-1
rule7=0,100,minecraft:sandstone_stairs-2
rule8=0,100,ChestGenHook:chests/village_blacksmith:5-3
rule9=0,100,minecraft:stone_slab-1
rule10=0,100,minecraft:sandstone-2
rule11=0,100,minecraft:iron_bars-0
rule12=0,100,minecraft:ladder-5
rule13=0,100,minecraft:jungle_door-7
rule14=0,100,minecraft:jungle_door-2
rule15=0,100,minecraft:jungle_door-8
rule16=0,100,minecraft:jungle_door-9
rule17=0,100,minecraft:sandstone-1
rule18=0,100,minecraft:spruce_fence-0
rule19=0,100,minecraft:sandstone_stairs-4
rule20=0,100,minecraft:sandstone_stairs-7
rule21=0,100,minecraft:sandstone_stairs-6
rule22=0,100,minecraft:sandstone_stairs-5

layer
1,1,5,4,3,3,3,2,3,3,2,1
2,2,2,3,3,3,3,3,3,3,2,1
2,2,3,3,3,3,3,3,3,3,3,1
1,3,3,3,3,3,3,3,3,3,3,1
1,3,3,3,3,3,3,3,3,3,3,1
1,3,3,3,3,3,3,3,3,3,3,1
1,2,3,3,3,3,3,3,3,3,3,1
1,2,3,3,3,3,3,3,3,2,2,2
1,2,2,3,3,3,3,3,6,2,2,2
endlayer

layer
1,1,1,1,3,3,2,2,2,3,3,1
3,2,7,1,3,0,0,0,0,0,3,1
3,3,3,3,3,0,0,0,0,0,3,1
1,2,3,3,3,0,0,0,0,0,3,1
1,2,0,0,0,0,0,0,0,0,2,1
1,2,0,0,0,0,0,0,0,8,2,1
1,2,0,0,0,0,0,3,3,3,2,1
1,3,9,5,3,3,3,3,3,3,2,2
1,3,3,3,2,2,3,3,1,5,2,2
endlayer

layer
1,1,1,1,2,2,2,3,3,2,3,1
3,7,1,1,3,0,0,0,0,0,2,1
3,3,3,3,3,0,0,0,0,0,2,1
1,3,3,3,3,0,0,0,0,0,3,1
1,3,0,0,0,0,0,0,0,0,3,1
1,3,0,0,0,0,0,0,0,0,3,1
1,3,0,0,0,0,0,3,3,3,3,1
1,3,0,0,5,3,3,3,3,3,3,3
1,3,2,2,2,3,3,3,1,1,5,3
endlayer

layer
1,1,1,1,2,3,3,3,2,2,2,1
1,1,1,1,3,0,0,0,0,0,3,1
1,5,3,3,3,0,0,0,0,0,2,1
1,3,3,3,3,0,0,0,0,0,2,1
1,2,0,0,0,0,0,0,0,0,2,1
1,2,0,0,0,0,0,0,0,0,3,1
1,2,0,0,0,0,0,3,3,3,3,1
1,2,0,0,0,5,3,3,3,3,7,1
1,3,3,3,3,2,2,3,1,1,1,1
endlayer

layer
1,1,1,1,10,3,2,2,3,3,10,1
1,1,1,1,3,3,3,3,3,3,3,1
1,1,5,3,3,3,3,3,3,3,3,1
1,10,3,3,3,3,3,11,3,3,3,1
1,3,3,3,3,3,3,3,3,3,3,1
1,2,3,3,3,3,3,3,3,3,3,1
1,3,3,3,3,3,3,3,3,3,10,1
1,3,0,0,0,0,9,3,3,7,1,1
1,10,3,3,3,3,3,10,1,1,1,1
endlayer

layer
1,1,1,1,10,3,3,3,3,3,10,1
1,1,1,1,3,0,12,0,0,0,3,1
1,1,1,1,13,0,0,0,0,0,3,1
1,10,3,3,3,0,0,0,0,0,3,1
1,3,0,0,0,0,0,0,0,0,3,1
1,3,0,0,0,0,0,0,0,0,3,1
1,3,0,0,0,0,0,3,14,3,10,1
1,3,0,0,0,0,0,3,1,1,1,1
1,10,3,3,3,3,3,10,1,1,1,1
endlayer

layer
1,1,1,1,3,3,3,0,3,3,3,1
1,1,1,1,3,0,12,0,0,0,3,1
1,1,1,1,15,0,0,0,0,0,3,1
1,3,10,3,3,0,0,0,0,0,0,1
1,3,0,0,0,0,0,0,0,0,3,1
1,10,0,0,0,0,0,0,0,0,3,1
1,0,0,0,0,0,0,3,16,3,3,1
1,10,0,0,0,0,0,3,1,1,1,1
1,3,10,0,10,0,10,3,1,1,1,1
endlayer

layer
1,1,1,1,10,3,10,10,10,3,10,1
1,1,1,1,3,0,12,0,0,0,3,1
1,1,1,1,3,0,0,0,0,0,3,1
1,10,10,3,3,0,0,0,0,0,10,1
1,3,0,0,0,0,0,0,0,0,3,1
1,3,0,0,0,0,0,0,0,0,3,1
1,10,0,0,0,0,0,3,3,3,10,1
1,3,0,0,0,0,0,3,1,1,1,1
1,10,3,10,10,10,3,10,1,1,1,1
endlayer

layer
1,1,1,1,10,3,3,3,3,3,10,1
1,1,1,1,3,0,12,0,0,0,3,1
1,1,1,1,3,0,0,0,0,0,3,1
1,10,3,3,3,0,0,0,0,0,3,1
1,3,0,0,0,0,0,0,0,0,3,1
1,3,0,0,0,0,0,0,0,0,3,1
1,3,0,0,0,0,0,3,3,3,10,1
1,3,0,0,0,0,0,3,1,1,1,1
1,10,3,3,3,3,3,10,1,1,1,1
endlayer

layer
1,1,1,1,3,3,3,3,3,3,3,1
1,1,1,1,3,0,12,0,0,0,3,1
1,1,1,1,3,0,0,0,0,0,3,1
1,3,3,3,3,0,0,0,0,0,3,1
1,3,0,0,0,0,0,0,0,0,3,1
1,3,0,0,0,0,0,0,0,0,3,1
1,3,0,0,0,0,0,3,3,3,3,1
1,3,0,0,0,0,0,3,1,1,1,1
1,3,3,3,3,3,3,3,1,1,1,1
endlayer

layer
1,1,1,1,17,10,10,10,10,10,17,1
1,1,1,1,10,3,12,3,3,3,10,1
1,1,1,1,10,3,3,3,3,3,10,1
1,17,4,4,10,3,3,3,3,3,10,1
1,5,3,3,3,3,3,3,3,3,10,1
1,5,3,3,3,3,3,3,3,3,10,1
1,5,3,3,3,3,3,3,10,10,17,1
1,5,3,3,3,3,3,3,1,1,1,1
1,17,6,6,17,6,6,17,1,1,1,1
endlayer

layer
1,1,1,1,3,3,3,4,3,3,3,1
1,1,1,1,3,0,12,0,0,0,3,1
1,1,1,1,5,0,0,0,0,0,3,1
1,18,18,18,3,0,0,0,0,0,7,1
1,18,0,0,0,0,0,0,0,0,3,1
1,18,0,0,2,0,0,0,0,0,3,1
1,18,0,0,3,3,3,3,6,3,3,1
1,18,0,0,0,0,0,18,1,1,1,1
1,18,18,18,18,18,18,18,1,1,1,1
endlayer

layer
1,1,1,1,3,3,3,0,3,3,3,1
1,1,1,1,10,0,12,0,0,0,3,1
1,1,1,1,0,0,0,0,0,0,3,1
1,0,0,0,10,0,0,0,0,0,0,1
1,0,0,0,0,0,0,0,0,0,3,1
1,0,0,0,2,0,0,0,0,0,3,1
1,0,0,0,3,3,3,3,0,3,3,1
1,0,0,0,0,0,0,0,1,1,1,1
1,0,0,0,0,0,0,0,1,1,1,1
endlayer

layer
1,1,1,1,2,3,2,19,2,3,2,1
1,1,1,1,3,0,12,0,0,0,3,1
1,1,1,1,20,0,0,0,0,0,2,1
1,0,0,0,2,0,0,0,0,0,21,1
1,0,0,0,20,0,0,0,0,0,2,1
1,0,0,0,3,0,0,0,0,0,3,1
1,0,0,0,2,3,2,2,22,3,2,1
1,0,0,0,0,0,0,0,1,1,1,1
1,0,0,0,0,0,0,0,1,1,1,1
endlayer

layer
1,1,1,1,20,2,4,4,4,2,19,1
1,1,1,1,2,0,12,0,0,0,2,1
1,1,1,1,5,0,0,0,0,0,7,1
1,0,0,0,5,0,0,0,0,0,7,1
1,0,0,0,5,0,0,0,0,0,7,1
1,0,0,0,2,0,0,0,0,0,2,1
1,0,0,0,22,2,6,6,6,2,21,1
1,0,0,0,0,0,0,0,1,1,1,1
1,0,0,0,0,0,0,0,1,1,1,1
endlayer

layer
1,1,1,1,17,4,4,4,4,4,17,1
1,1,1,1,5,9,0,9,9,9,7,1
1,1,1,1,5,9,9,9,9,9,7,1
1,0,0,0,5,9,9,9,9,9,7,1
1,0,0,0,5,9,9,9,9,9,7,1
1,0,0,0,5,9,9,9,9,9,7,1
1,0,0,0,17,6,6,6,6,6,17,1
1,0,0,0,0,0,0,0,1,1,1,1
1,0,0,0,0,0,0,0,1,1,1,1
endlayer

layer
1,1,1,1,10,18,18,18,18,18,10,1
1,1,1,1,18,0,0,0,0,0,18,1
1,1,1,1,18,0,0,0,0,0,18,1
1,0,0,0,18,0,0,0,0,0,18,1
1,0,0,0,18,0,0,0,0,0,18,1
1,0,0,0,18,0,0,0,0,0,18,1
1,0,0,0,10,18,18,18,18,18,10,1
1,0,0,0,0,0,0,0,1,1,1,1
1,0,0,0,0,0,0,0,1,1,1,1
endlayer

