
# Created by Ruins mod version 16.7 Ingame Parser
# authoring Player: lafuller

weight=1
embed_into_distance=0
acceptable_target_blocks=
unacceptable_target_blocks=flowing_water,water,flowing_lava,lava,ice,bedrock,netherrack,nether_brick,nether_brick_fence,soul_sand,quartz_ore,gravel,end_stone,obsidian,iron_bars,cloud,flesh,ash_block,slime_grass,slime_congealed,slime_dirt
dimensions=5,13,13
allowable_overhang=0
max_leveling=2
leveling_buffer=-1
preserve_water=0
preserve_lava=0

rule1=0,100,minecraft:planks-1
rule2=0,100,CommandBlock:RUINSTRIGGER /testruin Gilly/GillyMineshackElevator ~0 ~1 ~0 0:@,CommandBlock:RUINSTRIGGER /testruin Gilly/GillyMineshackElevator ~0 ~1 ~0 1:@,CommandBlock:RUINSTRIGGER /testruin Gilly/GillyMineshackElevator ~0 ~1 ~0 2:@,CommandBlock:RUINSTRIGGER /testruin Gilly/GillyMineshackElevator ~0 ~1 ~0 3:@
rule3=0,100,minecraft:dark_oak_fence-0

layer
1,1,1,1,1,1,1,1,1,1,1,1,1
1,1,1,1,1,1,1,1,1,1,1,1,1
1,1,1,1,1,1,1,1,1,1,1,1,1
1,1,1,1,1,1,1,1,1,1,1,1,1
1,1,1,1,1,1,1,1,1,1,1,1,1
1,1,1,1,1,1,1,1,1,1,1,1,1
1,1,1,1,1,1,1,1,1,1,1,1,1
1,1,1,1,1,1,1,1,1,1,1,1,1
1,1,1,1,1,1,1,1,0,0,0,1,1
1,1,1,1,1,1,1,1,0,2,0,1,1
1,1,1,1,1,1,1,1,0,0,0,1,1
1,1,1,1,1,1,1,1,1,1,1,1,1
1,1,1,1,1,1,1,1,1,1,1,1,1
endlayer

layer
0,0,0,0,0,0,0,0,0,0,0,0,0
0,0,0,0,0,0,0,0,0,0,0,0,0
0,0,3,3,0,0,0,0,0,3,3,0,0
0,0,3,3,0,0,0,0,0,3,3,0,0
0,0,0,0,0,0,0,0,0,0,0,0,0
0,0,0,0,0,0,0,0,0,0,0,0,0
0,0,0,0,0,0,0,0,0,0,0,0,0
0,0,0,0,0,0,0,3,0,0,0,3,0
0,0,0,0,0,0,0,0,0,0,0,0,0
0,0,3,3,0,0,0,0,0,0,0,0,0
0,0,3,3,0,0,0,0,0,0,0,0,0
0,0,0,0,0,0,0,3,0,0,0,3,0
0,0,0,0,0,0,0,0,0,0,0,0,0
endlayer

layer
0,0,0,0,0,0,0,0,0,0,0,0,0
0,0,0,0,0,0,0,0,0,0,0,0,0
0,0,3,3,0,0,0,0,0,3,3,0,0
0,0,3,3,0,0,0,0,0,3,3,0,0
0,0,0,0,0,0,0,0,0,0,0,0,0
0,0,0,0,0,0,0,0,0,0,0,0,0
0,0,0,0,0,0,0,0,0,0,0,0,0
0,0,0,0,0,0,0,3,0,0,0,3,0
0,0,0,0,0,0,0,0,0,0,0,0,0
0,0,3,3,0,0,0,0,0,0,0,0,0
0,0,3,3,0,0,0,0,0,0,0,0,0
0,0,0,0,0,0,0,3,0,0,0,3,0
0,0,0,0,0,0,0,0,0,0,0,0,0
endlayer

layer
0,0,0,0,0,0,0,0,0,0,0,0,0
0,0,0,0,0,0,0,0,0,0,0,0,0
0,0,3,3,0,0,0,0,0,3,3,0,0
0,0,3,3,0,0,0,0,0,3,3,0,0
0,0,0,0,0,0,0,0,0,0,0,0,0
0,0,0,0,0,0,0,0,0,0,0,0,0
0,0,0,0,0,0,0,0,0,0,0,0,0
0,0,0,0,0,0,0,3,0,0,0,3,0
0,0,0,0,0,0,0,0,0,0,0,0,0
0,0,3,3,0,0,0,0,0,0,0,0,0
0,0,3,3,0,0,0,0,0,0,0,0,0
0,0,0,0,0,0,0,3,0,0,0,3,0
0,0,0,0,0,0,0,0,0,0,0,0,0
endlayer

layer
0,0,0,0,0,0,0,0,0,0,0,0,0
0,0,0,0,0,0,0,0,0,0,0,0,0
0,0,3,3,0,0,0,0,0,3,3,0,0
0,0,3,3,0,0,0,0,0,3,3,0,0
0,0,0,0,0,0,0,0,0,0,0,0,0
0,0,0,0,0,0,0,0,0,0,0,0,0
0,0,0,0,0,0,0,0,0,0,0,0,0
0,0,0,0,0,0,0,3,0,0,0,3,0
0,0,0,0,0,0,0,0,0,0,0,0,0
0,0,3,3,0,0,0,0,0,0,0,0,0
0,0,3,3,0,0,0,0,0,0,0,0,0
0,0,0,0,0,0,0,3,0,0,0,3,0
0,0,0,0,0,0,0,0,0,0,0,0,0
endlayer

