
# Created by Ruins mod version 16.7 Ingame Parser
# authoring Player: lafuller

weight=1
embed_into_distance=34
random_height_offset=-20,4
acceptable_target_blocks=grass,dirt,stone,sand
unacceptable_target_blocks=flowing_water,water,flowing_lava,lava,ice,bedrock,netherrack,nether_brick,nether_brick_fence,soul_sand,quartz_ore,gravel,end_stone,obsidian,iron_bars,cloud,flesh,ash_block,slime_grass,slime_congealed,slime_dirt
dimensions=19,17,17
allowable_overhang=0
max_leveling=20
leveling_buffer=-1
preserve_water=0
preserve_lava=0

rule1=0,100,preserveBlock
rule2=0,100,stonebrick-0,stonebrick-0,stonebrick-1,stonebrick-1,stonebrick-2,stonebrick-2,stonebrick-3,cobblestone,stone-5,stone-6
rule3=0,100,minecraft:stone_brick_stairs-3
rule4=0,100,minecraft:stone_brick_stairs-1
rule5=0,100,minecraft:stone_brick_stairs-2
rule6=0,100,minecraft:stone_brick_stairs-0
rule7=0,100,minecraft:stone_slab-5
rule8=0,100,MobSpawner:Skeleton,MobSpawner:Zombie
rule9=0,100,minecraft:stone_brick_stairs-5
rule10=0,100,minecraft:stone_brick_stairs-7
rule11=0,100,minecraft:stone_brick_stairs-6
rule12=0,100,minecraft:stone_brick_stairs-4
rule13=0,100,minecraft:stone_slab-13

layer
1,1,1,1,1,1,1,1,1,1,1,1,1,1,1,1,1
1,1,1,1,1,1,1,1,1,1,1,1,1,1,1,1,1
1,1,1,1,1,1,1,1,1,1,1,1,1,1,1,1,1
1,1,1,1,1,1,1,1,1,1,1,1,1,1,1,1,1
1,1,1,1,1,1,1,1,1,1,1,1,1,1,1,1,1
1,1,1,1,1,1,1,1,1,1,1,1,1,1,1,1,1
1,1,1,1,1,1,1,2,2,2,1,1,1,1,1,1,1
1,1,1,1,1,1,2,2,2,2,2,1,1,1,1,1,1
1,1,1,1,1,1,2,2,2,2,2,1,1,1,1,1,1
1,1,1,1,1,1,2,2,2,2,2,1,1,1,1,1,1
1,1,1,1,1,1,1,2,2,2,1,1,1,1,1,1,1
1,1,1,1,1,1,1,1,1,1,1,1,1,1,1,1,1
1,1,1,1,1,1,1,1,1,1,1,1,1,1,1,1,1
1,1,1,1,1,1,1,1,1,1,1,1,1,1,1,1,1
1,1,1,1,1,1,1,1,1,1,1,1,1,1,1,1,1
1,1,1,1,1,1,1,1,1,1,1,1,1,1,1,1,1
1,1,1,1,1,1,1,1,1,1,1,1,1,1,1,1,1
endlayer

layer
1,1,1,1,1,1,1,1,1,1,1,1,1,1,1,1,1
1,1,1,1,1,1,1,1,1,1,1,1,1,1,1,1,1
1,1,1,1,1,1,1,1,1,1,1,1,1,1,1,1,1
1,1,1,1,1,1,1,1,1,1,1,1,1,1,1,1,1
1,1,1,1,1,1,1,2,2,2,1,1,1,1,1,1,1
1,1,1,1,1,2,2,2,2,2,2,2,1,1,1,1,1
1,1,1,1,1,2,2,2,2,2,2,2,1,1,1,1,1
1,1,1,1,2,2,2,5,4,3,2,2,2,1,1,1,1
1,1,1,1,2,2,2,5,0,3,2,2,2,1,1,1,1
1,1,1,1,2,2,2,5,6,3,2,2,2,1,1,1,1
1,1,1,1,1,2,2,2,2,2,2,2,1,1,1,1,1
1,1,1,1,1,2,2,2,2,2,2,2,1,1,1,1,1
1,1,1,1,1,1,1,2,2,2,1,1,1,1,1,1,1
1,1,1,1,1,1,1,1,1,1,1,1,1,1,1,1,1
1,1,1,1,1,1,1,1,1,1,1,1,1,1,1,1,1
1,1,1,1,1,1,1,1,1,1,1,1,1,1,1,1,1
1,1,1,1,1,1,1,1,1,1,1,1,1,1,1,1,1
endlayer

layer
1,1,1,1,1,1,1,1,1,1,1,1,1,1,1,1,1
1,1,1,1,1,1,1,1,1,1,1,1,1,1,1,1,1
1,1,1,1,1,1,1,2,2,2,1,1,1,1,1,1,1
1,1,1,2,2,2,2,2,2,2,2,2,2,2,1,1,1
1,1,1,2,2,2,2,2,2,2,2,2,2,2,1,1,1
1,1,1,2,2,0,0,2,0,2,0,0,2,2,1,1,1
1,1,1,2,2,0,0,3,0,5,0,0,2,2,1,1,1
1,1,2,2,2,2,6,0,0,0,6,2,2,2,2,1,1
1,1,2,2,2,0,0,0,0,0,0,0,2,2,2,1,1
1,1,2,2,2,2,4,0,0,0,4,2,2,2,2,1,1
1,1,1,2,2,0,0,3,0,5,0,0,2,2,1,1,1
1,1,1,2,2,0,0,2,0,2,0,0,2,2,1,1,1
1,1,1,2,2,2,2,2,2,2,2,2,2,2,1,1,1
1,1,1,2,2,2,2,2,2,2,2,2,2,2,1,1,1
1,1,1,1,1,1,1,2,2,2,1,1,1,1,1,1,1
1,1,1,1,1,1,1,1,1,1,1,1,1,1,1,1,1
1,1,1,1,1,1,1,1,1,1,1,1,1,1,1,1,1
endlayer

layer
1,1,1,1,1,1,1,1,1,1,1,1,1,1,1,1,1
1,1,1,1,1,1,2,2,2,2,2,1,1,1,1,1,1
1,1,2,2,2,2,2,4,4,4,2,2,2,2,2,1,1
1,1,2,2,4,4,2,0,0,0,2,4,4,2,2,1,1
1,1,2,5,0,0,2,2,0,2,2,0,0,3,2,1,1
1,1,2,5,0,0,0,4,0,4,0,0,0,3,2,1,1
1,2,2,2,2,0,0,0,0,0,0,0,2,2,2,2,1
1,2,5,0,2,5,0,0,0,0,0,3,2,0,3,2,1
1,2,5,0,0,0,0,0,0,0,0,0,0,0,3,2,1
1,2,5,0,2,5,0,0,0,0,0,3,2,0,3,2,1
1,2,2,2,2,0,0,0,0,0,0,0,2,2,2,2,1
1,1,2,5,0,0,0,6,0,6,0,0,0,3,2,1,1
1,1,2,5,0,0,2,2,0,2,2,0,0,3,2,1,1
1,1,2,2,6,6,2,0,0,0,2,6,6,2,2,1,1
1,1,2,2,2,2,2,6,6,6,2,2,2,2,1,1,1
1,1,1,1,1,1,2,2,2,2,2,1,1,1,1,1,1
1,1,1,1,1,1,1,1,1,1,1,1,1,1,1,1,1
endlayer

layer
1,1,1,1,1,2,2,2,2,2,2,2,1,1,1,1,1
1,1,1,2,2,2,2,4,4,4,2,2,2,2,1,1,1
1,1,2,4,4,4,2,0,0,0,2,4,4,4,2,1,1
1,2,5,0,0,0,2,0,0,0,2,0,0,0,3,2,1
1,2,5,0,0,0,3,5,0,3,5,0,0,0,3,2,1
2,2,5,0,0,0,0,0,0,0,0,0,0,0,3,2,2
2,2,2,2,6,0,0,0,0,0,0,0,6,2,2,2,2
2,5,0,0,4,0,0,0,0,0,0,0,4,0,0,3,2
2,5,0,0,0,0,0,0,0,0,0,0,0,0,0,3,2
2,5,0,0,6,0,0,0,0,0,0,0,6,0,0,3,2
2,2,2,2,4,0,0,0,0,0,0,0,4,2,2,2,2
2,2,5,0,0,0,0,0,0,0,0,0,0,0,3,2,2
1,2,5,0,0,0,3,5,0,3,5,0,0,0,3,2,1
1,2,5,0,0,0,2,0,0,0,2,0,0,0,3,2,1
1,1,2,6,6,6,2,0,0,0,2,6,6,6,2,1,1
1,1,1,2,2,2,2,6,6,6,2,2,2,2,1,1,1
1,1,1,1,1,2,2,2,2,2,2,2,1,1,1,1,1
endlayer

layer
1,1,1,1,1,2,2,0,0,0,2,2,1,1,1,1,1
1,1,1,2,0,0,7,0,0,0,7,0,0,2,1,1,1
1,1,0,0,0,0,2,0,0,0,2,0,0,0,0,1,1
1,2,0,0,0,0,2,0,0,0,2,0,0,0,0,2,1
1,0,0,0,0,0,0,0,0,0,0,0,0,0,0,0,1
2,0,0,0,0,0,0,0,0,0,0,0,0,0,0,0,2
2,7,2,2,0,0,0,0,0,0,0,0,0,2,2,7,2
0,0,0,0,0,0,0,0,0,0,0,0,0,0,0,0,0
0,0,0,0,0,0,0,0,0,0,0,0,0,0,0,0,0
0,0,0,0,0,0,0,0,0,0,0,0,0,0,0,0,0
2,7,2,2,0,0,0,0,0,0,0,0,0,2,2,7,2
2,0,0,0,0,0,0,0,0,0,0,0,0,0,0,0,2
1,0,0,0,0,0,0,0,0,0,0,0,0,0,0,0,1
1,2,0,0,0,0,2,0,0,0,2,0,0,0,0,2,1
1,1,0,0,0,0,2,0,0,0,2,0,0,0,0,1,1
1,1,1,2,0,0,7,0,0,0,7,0,0,2,1,1,1
1,1,1,1,1,2,2,0,0,0,2,2,1,1,1,1,1
endlayer

layer
1,1,1,1,1,2,2,0,0,0,2,2,1,1,1,1,1
1,1,1,2,0,0,0,0,0,0,0,0,0,2,1,1,1
1,1,0,0,0,0,2,0,0,0,2,0,0,0,0,1,1
1,2,0,0,0,0,0,0,0,0,0,0,0,0,0,2,1
1,0,0,0,0,0,0,0,0,0,0,0,0,0,0,0,1
2,0,0,0,0,0,0,0,0,0,0,0,0,0,0,0,2
2,0,2,0,0,0,0,0,0,0,0,0,0,0,2,0,2
0,0,0,0,0,0,0,0,0,0,0,0,0,0,0,0,0
0,0,0,0,0,0,0,0,0,0,0,0,0,0,0,0,0
0,0,0,0,0,0,0,0,0,0,0,0,0,0,0,0,0
2,0,2,0,0,0,0,0,0,0,0,0,0,0,2,0,2
2,0,0,0,0,0,0,0,0,0,0,0,0,0,0,0,2
1,0,0,0,0,0,0,0,0,0,0,0,0,0,0,0,1
1,2,0,0,0,0,0,0,0,0,0,0,0,0,0,2,1
1,1,0,0,0,0,2,0,0,0,2,0,0,0,0,1,1
1,1,1,2,0,0,0,0,0,0,0,0,0,2,1,1,1
1,1,1,1,1,2,2,0,0,0,2,2,1,1,1,1,1
endlayer

layer
1,1,1,1,1,2,2,0,0,0,2,2,1,1,1,1,1
1,1,1,2,0,0,7,0,0,0,7,0,0,2,1,1,1
1,1,0,0,0,0,4,0,0,0,4,0,0,0,0,1,1
1,2,0,0,0,0,0,0,0,0,0,0,0,0,0,2,1
1,0,0,0,0,0,0,0,0,0,0,0,0,0,0,0,1
2,0,0,0,0,0,0,0,0,0,0,0,0,0,0,0,2
2,7,5,0,0,0,0,0,0,0,0,0,0,0,3,7,2
0,0,0,0,0,0,0,0,0,0,0,0,0,0,0,0,0
0,0,0,0,0,0,0,0,8,0,0,0,0,0,0,0,0
0,0,0,0,0,0,0,0,0,0,0,0,0,0,0,0,0
2,7,5,0,0,0,0,0,0,0,0,0,0,0,3,7,2
2,0,0,0,0,0,0,0,0,0,0,0,0,0,0,0,2
1,0,0,0,0,0,0,0,0,0,0,0,0,0,0,0,1
1,2,0,0,0,0,0,0,0,0,0,0,0,0,0,2,1
1,1,0,0,0,0,6,0,0,0,6,0,0,0,0,1,1
1,1,1,2,0,0,7,0,0,0,7,0,0,2,1,1,1
1,1,1,1,1,2,2,0,0,0,2,2,1,1,1,1,1
endlayer

layer
1,1,1,1,1,2,2,0,0,0,2,2,1,1,1,1,1
1,1,1,2,0,0,0,0,0,0,0,0,0,2,1,1,1
1,1,0,0,0,0,0,0,0,0,0,0,0,0,0,1,1
1,2,0,0,0,0,0,0,0,0,0,0,0,0,0,2,1
1,0,0,0,0,0,0,0,0,0,0,0,0,0,0,0,1
2,0,0,0,0,0,0,0,0,0,0,0,0,0,0,0,2
2,0,0,0,0,0,0,0,0,0,0,0,0,0,0,0,2
0,0,0,0,0,0,0,0,0,0,0,0,0,0,0,0,0
0,0,0,0,0,0,0,0,2,0,0,0,0,0,0,0,0
0,0,0,0,0,0,0,0,0,0,0,0,0,0,0,0,0
2,0,0,0,0,0,0,0,0,0,0,0,0,0,0,0,2
2,0,0,0,0,0,0,0,0,0,0,0,0,0,0,0,2
1,0,0,0,0,0,0,0,0,0,0,0,0,0,0,0,1
1,2,0,0,0,0,0,0,0,0,0,0,0,0,0,2,1
1,1,0,0,0,0,0,0,0,0,0,0,0,0,0,1,1
1,1,1,2,0,0,0,0,0,0,0,0,0,2,1,1,1
1,1,1,1,1,2,2,0,0,0,2,2,1,1,1,1,1
endlayer

layer
1,1,1,1,1,2,2,0,0,0,2,2,1,1,1,1,1
1,1,1,2,0,9,0,0,0,0,0,9,0,2,1,1,1
1,1,0,0,0,0,0,0,0,0,0,0,0,0,0,1,1
1,2,0,0,0,0,0,0,0,0,0,0,0,0,0,2,1
1,0,0,0,0,0,0,0,0,0,0,0,0,0,0,0,1
2,11,0,0,0,0,0,0,0,0,0,0,0,0,0,10,2
2,0,0,0,0,0,0,0,0,0,0,0,0,0,0,0,2
0,0,0,0,0,0,0,0,0,0,0,0,0,0,0,0,0
0,0,0,0,0,0,0,0,2,0,0,0,0,0,0,0,0
0,0,0,0,0,0,0,0,0,0,0,0,0,0,0,0,0
2,0,0,0,0,0,0,0,0,0,0,0,0,0,0,0,2
2,11,0,0,0,0,0,0,0,0,0,0,0,0,0,10,2
1,0,0,0,0,0,0,0,0,0,0,0,0,0,0,0,1
1,2,0,0,0,0,0,0,0,0,0,0,0,0,0,2,1
1,1,0,0,0,0,0,0,0,0,0,0,0,0,0,1,1
1,1,1,2,0,12,0,0,0,0,0,12,0,2,1,1,1
1,1,1,1,1,2,2,0,0,0,2,2,1,1,1,1,1
endlayer

layer
1,1,1,1,1,2,2,11,0,10,2,2,1,1,1,1,1
1,1,1,2,2,2,0,0,0,0,0,2,2,2,1,1,1
1,1,0,0,0,0,0,0,0,0,0,0,0,0,0,1,1
1,2,0,0,0,0,0,0,0,0,0,0,0,0,0,2,1
1,2,0,0,0,0,0,0,0,0,0,0,0,0,0,2,1
2,2,0,0,0,0,0,0,0,0,0,0,0,0,0,2,2
2,0,0,0,0,0,0,0,0,0,0,0,0,0,0,0,2
9,0,0,0,0,0,0,0,0,0,0,0,0,0,0,0,9
0,0,0,0,0,0,0,0,2,0,0,0,0,0,0,0,0
12,0,0,0,0,0,0,0,0,0,0,0,0,0,0,0,12
2,0,0,0,0,0,0,0,0,0,0,0,0,0,0,0,2
2,2,0,0,0,0,0,0,0,0,0,0,0,0,0,2,2
1,2,0,0,0,0,0,0,0,0,0,0,0,0,0,2,1
1,2,0,0,0,0,0,0,0,0,0,0,0,0,0,2,1
1,1,0,0,0,0,0,0,0,0,0,0,0,0,0,1,1
1,1,1,2,2,2,0,0,0,0,0,2,2,2,1,1,1
1,1,1,1,1,2,2,11,0,10,2,2,1,1,1,1,1
endlayer

layer
1,1,1,1,1,2,2,2,2,2,2,2,1,1,1,1,1
1,1,1,2,2,2,0,0,0,0,0,2,2,2,1,1,1
1,1,0,0,2,0,0,0,0,0,0,0,2,0,0,1,1
1,2,0,0,0,0,0,0,0,0,0,0,0,0,0,2,1
1,2,2,0,0,0,0,0,0,0,0,0,0,0,2,2,1
2,2,0,0,0,0,0,0,0,0,0,0,0,0,0,2,2
2,0,0,0,0,0,0,0,0,0,0,0,0,0,0,0,2
2,0,0,0,0,0,0,0,0,0,0,0,0,0,0,0,2
2,0,0,0,0,0,0,0,2,0,0,0,0,0,0,0,2
2,0,0,0,0,0,0,0,0,0,0,0,0,0,0,0,2
2,0,0,0,0,0,0,0,0,0,0,0,0,0,0,0,2
2,2,0,0,0,0,0,0,0,0,0,0,0,0,0,2,2
1,2,2,0,0,0,0,0,0,0,0,0,0,0,2,2,1
1,2,0,0,0,0,0,0,0,0,0,0,0,0,0,2,1
1,1,0,0,2,0,0,0,0,0,0,0,2,0,0,1,1
1,1,1,2,2,2,0,0,0,0,0,2,2,2,1,1,1
1,1,1,1,1,2,2,2,2,2,2,2,1,1,1,1,1
endlayer

layer
1,1,1,1,1,2,2,2,2,2,2,2,1,1,1,1,1
1,1,1,2,2,2,0,9,0,9,0,2,2,2,1,1,1
1,1,2,2,2,0,0,0,0,0,0,0,2,2,2,1,1
1,2,2,0,0,0,0,0,0,0,0,0,0,0,2,2,1
1,2,2,0,0,0,0,0,0,0,0,0,0,0,2,2,1
2,2,0,0,0,0,0,0,0,0,0,0,0,0,0,2,2
2,0,0,0,0,0,0,0,0,0,0,0,0,0,0,0,2
2,11,0,0,0,0,0,0,0,0,0,0,0,0,0,10,2
2,0,0,0,0,0,0,0,2,0,0,0,0,0,0,0,2
2,11,0,0,0,0,0,0,0,0,0,0,0,0,0,10,2
2,0,0,0,0,0,0,0,0,0,0,0,0,0,0,0,2
2,2,0,0,0,0,0,0,0,0,0,0,0,0,0,2,2
1,2,2,0,0,0,0,0,0,0,0,0,0,0,2,2,1
1,2,2,0,0,0,0,0,0,0,0,0,0,0,2,2,1
1,1,2,2,2,0,0,0,0,0,0,0,2,2,2,1,1
1,1,1,2,2,2,0,12,0,12,0,2,2,2,1,1,1
1,1,1,1,1,2,2,2,2,2,2,2,1,1,1,1,1
endlayer

layer
1,1,1,1,1,2,2,2,2,2,2,2,1,1,1,1,1
1,1,1,2,2,2,0,2,0,2,0,2,2,2,1,1,1
1,1,2,2,2,0,0,0,0,0,0,0,2,2,2,1,1
1,2,2,0,0,0,0,0,0,0,0,0,0,0,2,2,1
1,2,2,0,0,0,0,0,0,0,0,0,0,0,2,2,1
2,2,0,0,0,0,0,0,0,0,0,0,0,0,0,2,2
2,0,0,0,0,0,0,0,0,0,0,0,0,0,0,0,2
2,2,0,0,0,0,0,0,0,0,0,0,0,0,0,2,2
2,0,0,0,0,0,0,0,2,0,0,0,0,0,0,0,2
2,2,0,0,0,0,0,0,0,0,0,0,0,0,0,2,2
2,0,0,0,0,0,0,0,0,0,0,0,0,0,0,0,2
2,2,0,0,0,0,0,0,0,0,0,0,0,0,0,2,2
1,2,2,0,0,0,0,0,0,0,0,0,0,0,2,2,1
1,2,2,0,0,0,0,0,0,0,0,0,0,0,2,2,1
1,1,2,2,2,0,0,0,0,0,0,0,2,2,2,1,1
1,1,1,2,2,2,0,2,0,2,0,2,2,2,1,1,1
1,1,1,1,1,2,2,2,2,2,2,2,1,1,1,1,1
endlayer

layer
1,1,1,1,1,1,2,2,2,2,2,1,1,1,1,1,1
1,1,1,1,2,2,2,2,0,2,2,2,2,1,1,1,1
1,1,1,2,2,0,0,0,0,0,0,0,2,2,1,1,1
1,1,2,2,0,0,0,0,0,0,0,0,0,2,2,1,1
1,2,2,0,0,0,0,0,0,0,0,0,0,0,2,2,1
1,2,0,0,0,0,0,0,0,0,0,0,0,0,0,2,1
2,2,0,0,0,0,0,0,0,0,0,0,0,0,0,2,2
2,2,0,0,0,0,0,0,0,0,0,0,0,0,0,2,2
2,0,0,0,0,0,0,0,2,0,0,0,0,0,0,0,2
2,2,0,0,0,0,0,0,0,0,0,0,0,0,0,2,2
2,2,0,0,0,0,0,0,0,0,0,0,0,0,0,2,2
1,2,0,0,0,0,0,0,0,0,0,0,0,0,0,2,1
1,2,2,0,0,0,0,0,0,0,0,0,0,0,2,2,1
1,1,2,2,0,0,0,0,0,0,0,0,0,2,2,1,1
1,1,1,2,2,0,0,0,0,0,0,0,2,2,1,1,1
1,1,1,1,2,2,2,2,0,2,2,2,2,1,1,1,1
1,1,1,1,1,1,2,2,2,2,2,1,1,1,1,1,1
endlayer

layer
1,1,1,1,1,1,1,2,2,2,1,1,1,1,1,1,1
1,1,1,1,1,2,2,2,0,2,2,2,1,1,1,1,1
1,1,1,2,2,2,0,13,0,13,0,2,2,2,1,1,1
1,1,2,2,0,0,0,0,0,0,0,0,0,2,2,1,1
1,1,2,0,0,0,13,0,0,0,13,0,0,0,2,1,1
1,2,2,0,0,0,0,0,0,0,0,0,0,0,2,2,1
1,2,0,0,13,0,0,0,0,0,0,0,13,0,0,2,1
2,2,13,0,0,0,0,0,0,0,0,0,0,0,13,2,2
2,0,0,0,0,0,0,0,2,0,0,0,0,0,0,0,2
2,2,13,0,0,0,0,0,0,0,0,0,0,0,13,2,2
1,2,0,0,13,0,0,0,0,0,0,0,13,0,0,2,1
1,2,2,0,0,0,0,0,0,0,0,0,0,0,2,2,1
1,1,2,0,0,0,13,0,0,0,13,0,0,0,2,1,1
1,1,2,2,0,0,0,0,0,0,0,0,0,2,2,1,1
1,1,1,2,2,2,0,13,0,13,0,2,2,2,1,1,1
1,1,1,1,1,2,2,2,0,2,2,2,1,1,1,1,1
1,1,1,1,1,1,1,2,2,2,1,1,1,1,1,1,1
endlayer

layer
1,1,1,1,1,1,1,1,2,1,1,1,1,1,1,1,1
1,1,1,1,1,1,2,2,2,2,2,1,1,1,1,1,1
1,1,1,1,2,2,13,2,0,2,13,2,2,1,1,1,1
1,1,1,2,2,0,0,0,0,0,0,0,2,2,1,1,1
1,1,2,2,13,0,2,0,0,0,2,0,13,2,2,1,1
1,1,2,0,0,0,0,0,2,0,0,0,0,0,2,1,1
1,2,13,0,2,0,13,0,0,0,13,0,2,0,13,2,1
1,2,2,0,0,0,0,0,0,0,0,0,0,0,2,2,1
2,2,0,0,0,2,0,0,2,0,0,2,0,0,0,2,2
1,2,2,0,0,0,0,0,0,0,0,0,0,0,2,2,1
1,2,13,0,2,0,13,0,0,0,13,0,2,0,13,2,1
1,1,2,0,0,0,0,0,2,0,0,0,0,0,2,1,1
1,1,2,2,13,0,2,0,0,0,2,0,13,2,2,1,1
1,1,1,2,2,0,0,0,0,0,0,0,2,2,1,1,1
1,1,1,1,2,2,13,2,0,2,13,2,2,1,1,1,1
1,1,1,1,1,1,2,2,2,2,2,1,1,1,1,1,1
1,1,1,1,1,1,1,1,2,1,1,1,1,1,1,1,1
endlayer

layer
1,1,1,1,1,1,1,1,1,1,1,1,1,1,1,1,1
1,1,1,1,1,1,1,2,2,2,1,1,1,1,1,1,1
1,1,1,1,1,2,2,2,13,2,2,2,1,1,1,1,1
1,1,1,1,2,2,2,0,0,0,2,2,2,1,1,1,1
1,1,1,2,2,2,2,2,0,2,2,2,2,2,1,1,1
1,1,2,2,2,13,0,0,2,0,0,13,2,2,2,1,1
1,1,2,2,2,0,2,0,0,0,2,0,2,2,2,1,1
1,2,2,0,2,0,0,0,2,0,0,0,2,0,2,2,1
1,2,13,0,0,2,0,2,2,2,0,2,0,0,13,2,1
1,2,2,0,2,0,0,0,2,0,0,0,2,0,2,2,1
1,1,2,2,2,0,2,0,0,0,2,0,2,2,2,1,1
1,1,2,2,2,13,0,0,2,0,0,13,2,2,2,1,1
1,1,1,2,2,2,2,2,0,2,2,2,2,2,1,1,1
1,1,1,1,2,2,2,0,0,0,2,2,2,1,1,1,1
1,1,1,1,1,2,2,2,13,2,2,2,1,1,1,1,1
1,1,1,1,1,1,1,2,2,2,1,1,1,1,1,1,1
1,1,1,1,1,1,1,1,1,1,1,1,1,1,1,1,1
endlayer

layer
1,1,1,1,1,1,1,1,1,1,1,1,1,1,1,1,1
1,1,1,1,1,1,1,1,1,1,1,1,1,1,1,1,1
1,1,1,1,1,1,1,2,2,2,1,1,1,1,1,1,1
1,1,1,1,1,2,2,2,2,2,2,2,1,1,1,1,1
1,1,1,1,2,2,2,2,2,2,2,2,2,1,1,1,1
1,1,1,2,2,2,2,2,2,2,2,2,2,2,1,1,1
1,1,1,2,2,2,2,2,2,2,2,2,2,2,1,1,1
1,1,2,2,2,2,2,2,2,2,2,2,2,2,2,1,1
1,1,2,2,2,2,2,2,2,2,2,2,2,2,2,1,1
1,1,2,2,2,2,2,2,2,2,2,2,2,2,2,1,1
1,1,1,2,2,2,2,2,2,2,2,2,2,2,1,1,1
1,1,1,2,2,2,2,2,2,2,2,2,2,2,1,1,1
1,1,1,1,2,2,2,2,2,2,2,2,2,1,1,1,1
1,1,1,1,1,2,2,2,2,2,2,2,1,1,1,1,1
1,1,1,1,1,1,1,2,2,2,1,1,1,1,1,1,1
1,1,1,1,1,1,1,1,1,1,1,1,1,1,1,1,1
1,1,1,1,1,1,1,1,1,1,1,1,1,1,1,1,1
endlayer

