
# Created by Ruins mod version 16.7 Ingame Parser
# authoring Player: lafuller

weight=1
embed_into_distance=30
acceptable_target_blocks=water
unacceptable_target_blocks=flowing_lava,lava
dimensions=72,11,17
allowable_overhang=0
max_leveling=0
leveling_buffer=-1
preserve_water=0
preserve_lava=0

rule1=0,100,preserveBlock
rule2=0,100,minecraft:prismarine-0
rule3=0,100,air
rule4=0,100,minecraft:ladder-2
rule5=0,100,minecraft:stonebrick-0
rule6=0,100,minecraft:stone_brick_stairs-4
rule7=0,100,minecraft:stone_brick_stairs-6
rule8=0,100,minecraft:stone_brick_stairs-7
rule9=0,100,minecraft:stone_brick_stairs-5
rule10=0,100,minecraft:stone_brick_stairs-2
rule11=0,100,minecraft:stone_brick_stairs-0
rule12=0,100,minecraft:stone_brick_stairs-1
rule13=0,100,minecraft:stone_brick_stairs-3
rule14=0,100,minecraft:stone_slab-5
rule15=0,100,minecraft:stone_slab-13
rule16=0,100,minecraft:ladder-3
rule17=0,100,minecraft:prismarine-1
rule18=0,100,minecraft:double_stone_slab-5
rule19=0,100,minecraft:trapdoor-13
rule20=0,100,minecraft:stained_glass-1

layer
1,1,1,1,1,1,1,1,1,1,1,1,1,1,1,1,1
1,1,1,1,1,1,1,1,1,1,1,1,1,1,1,1,1
1,1,1,1,1,1,1,1,1,1,1,1,1,1,1,1,1
1,1,1,1,1,1,1,1,1,1,1,1,1,1,1,1,1
1,1,1,2,2,1,1,1,1,1,1,1,1,1,1,1,1
1,1,2,2,2,2,1,1,1,1,1,1,1,1,1,1,1
1,1,2,2,2,2,1,1,1,1,1,1,1,1,1,1,1
1,1,1,2,2,2,1,1,1,1,1,1,1,1,1,1,1
1,1,1,1,1,1,1,1,1,1,1,1,1,1,1,1,1
1,1,1,1,1,1,1,1,1,1,1,1,1,1,1,1,1
1,1,1,1,1,1,1,1,1,1,1,1,1,1,1,1,1
endlayer

layer
1,1,1,1,1,1,1,1,1,1,1,1,1,1,1,1,1
1,1,1,1,1,1,1,1,1,1,1,1,1,1,1,1,1
1,1,1,1,1,1,1,1,1,1,1,1,1,1,1,1,1
1,1,1,2,2,1,1,1,1,1,1,1,1,1,1,1,1
1,1,2,2,2,2,1,1,1,1,1,1,1,1,1,1,1
1,2,2,2,2,2,2,1,1,1,1,1,1,1,1,1,1
1,2,2,2,2,2,2,1,1,1,1,1,1,1,1,1,1
1,1,2,2,2,2,2,1,1,1,1,1,1,1,1,1,1
1,1,1,2,2,2,1,1,1,1,1,1,1,1,1,1,1
1,1,1,1,1,1,1,1,1,1,1,1,1,1,1,1,1
1,1,1,1,1,1,1,1,1,1,1,1,1,1,1,1,1
endlayer

layer
1,1,1,1,1,1,1,1,1,1,1,1,1,1,1,1,1
1,1,1,1,1,1,1,1,1,1,1,1,1,1,1,1,1
1,1,1,1,1,1,1,1,1,1,1,1,1,1,1,1,1
1,1,2,2,2,2,1,1,1,1,1,1,1,1,1,1,1
1,2,2,2,2,2,2,1,1,1,1,1,1,1,1,1,1
2,2,2,2,2,2,2,2,1,1,1,1,1,1,1,1,1
2,2,2,2,2,2,2,2,1,1,1,1,1,1,1,1,1
1,2,2,2,2,2,2,2,1,1,1,1,1,1,1,1,1
1,1,2,2,2,2,2,1,1,1,1,1,1,1,1,1,1
1,1,1,2,2,2,1,1,1,1,1,1,1,1,1,1,1
1,1,1,1,1,1,1,1,1,1,1,1,1,1,1,1,1
endlayer

layer
1,1,1,1,1,1,1,1,1,1,1,1,1,1,1,1,1
1,1,1,1,1,1,1,1,1,1,1,1,1,1,1,1,1
1,1,1,2,2,1,1,1,1,1,1,1,1,1,1,1,1
1,2,2,2,2,2,2,1,1,1,1,1,1,1,1,1,1
2,2,2,2,2,2,2,2,1,1,1,1,1,1,1,1,1
2,2,2,2,2,2,2,2,1,1,1,1,1,1,1,1,1
2,2,2,2,2,2,2,2,1,1,1,1,1,1,1,1,1
2,2,2,2,2,2,2,2,1,1,1,1,1,1,1,1,1
1,2,2,2,2,2,2,2,1,1,1,1,1,1,1,1,1
1,1,2,2,2,2,2,1,1,1,1,1,1,1,1,1,1
1,1,1,1,1,1,1,1,1,1,1,1,1,1,1,1,1
endlayer

layer
1,1,1,1,1,1,1,1,1,1,1,1,1,1,1,1,1
1,1,1,1,1,1,1,1,1,1,1,1,1,1,1,1,1
1,1,2,2,2,2,1,1,1,1,1,1,1,1,1,1,1
1,2,2,2,2,2,2,1,1,1,1,1,1,1,1,1,1
2,2,2,2,2,2,2,2,1,1,1,1,1,1,1,1,1
2,2,2,2,2,2,2,2,2,1,1,1,1,1,1,1,1
2,2,2,2,2,2,2,2,2,1,1,1,1,1,1,1,1
2,2,2,2,2,2,2,2,2,1,1,1,1,1,1,1,1
1,2,2,2,2,2,2,2,1,1,1,1,1,1,1,1,1
1,1,2,2,2,2,2,1,1,1,1,1,1,1,1,1,1
1,1,1,1,1,1,1,1,1,1,1,1,1,1,1,1,1
endlayer

layer
1,1,1,1,1,1,1,1,1,1,1,1,1,1,1,1,1
1,1,1,1,1,1,1,1,1,1,1,1,1,1,1,1,1
1,1,2,2,2,2,1,1,1,1,1,1,1,1,1,1,1
2,2,2,2,2,2,2,2,1,1,1,1,1,1,1,1,1
2,2,2,2,2,2,2,2,1,1,1,1,1,1,1,1,1
2,2,2,2,2,2,2,2,2,1,1,1,1,1,1,1,1
2,2,2,2,2,2,2,2,2,1,1,1,1,1,1,1,1
2,2,2,2,2,2,2,2,2,1,1,1,1,1,1,1,1
1,2,2,2,2,2,2,2,1,1,1,1,1,1,1,1,1
1,2,2,2,2,2,2,2,1,1,1,1,1,1,1,1,1
1,1,1,2,2,1,1,1,1,1,1,1,1,1,1,1,1
endlayer

layer
1,1,1,1,1,1,1,1,1,1,1,1,1,1,1,1,1
1,1,1,1,1,1,1,1,1,1,1,1,1,1,1,1,1
1,2,2,2,2,2,1,1,1,1,1,1,1,1,1,1,1
2,2,2,2,2,2,2,2,1,1,1,1,1,1,1,1,1
2,2,2,2,2,2,2,2,2,1,1,1,1,1,1,1,1
2,2,2,2,2,2,2,2,2,1,1,1,1,1,1,1,1
2,2,2,2,2,2,2,2,2,1,1,1,1,1,1,1,1
2,2,2,2,2,2,2,2,2,1,1,1,1,1,1,1,1
2,2,2,2,2,2,2,2,2,1,1,1,1,1,1,1,1
1,2,2,2,2,2,2,2,1,1,1,1,1,1,1,1,1
1,1,1,2,2,2,1,1,1,1,1,1,1,1,1,1,1
endlayer

layer
1,1,1,1,1,1,1,1,1,1,1,1,1,1,1,1,1
1,1,1,1,1,1,1,1,1,1,1,1,1,1,1,1,1
1,2,2,2,2,2,2,1,1,1,1,1,1,1,1,1,1
2,2,2,2,2,2,2,2,1,1,1,1,1,1,1,1,1
2,2,2,2,2,2,2,2,2,1,1,1,1,1,1,1,1
2,2,2,2,2,2,2,2,2,1,1,1,1,1,1,1,1
2,2,2,2,2,2,2,2,2,1,1,1,1,1,1,1,1
2,2,2,2,2,2,2,2,2,1,1,1,1,1,1,1,1
2,2,2,2,2,2,2,2,2,1,1,1,1,1,1,1,1
1,2,2,2,2,2,2,2,1,1,1,1,1,1,1,1,1
1,1,1,2,2,2,1,1,1,1,1,1,1,1,1,1,1
endlayer

layer
1,1,1,1,1,1,1,1,1,1,1,1,1,1,1,1,1
1,1,1,1,1,1,1,1,1,1,1,1,1,1,1,1,1
1,2,2,2,2,2,2,1,1,1,1,1,1,1,1,1,1
1,2,2,2,2,2,2,2,1,1,1,1,1,1,1,1,1
2,2,2,2,2,2,2,2,2,1,1,1,1,1,1,1,1
2,2,2,2,2,2,2,2,2,1,1,1,1,1,1,1,1
2,2,2,2,2,2,2,2,2,1,1,1,1,1,1,1,1
2,2,2,2,2,2,2,2,2,1,1,1,1,1,1,1,1
2,2,2,2,2,2,2,2,2,1,1,1,1,1,1,1,1
1,2,2,2,2,2,2,2,1,1,1,1,1,1,1,1,1
1,1,2,2,2,2,1,1,1,1,1,1,1,1,1,1,1
endlayer

layer
1,1,1,1,1,1,1,1,1,1,1,1,1,1,1,1,1
1,1,1,1,1,1,1,1,1,1,1,1,1,1,1,1,1
1,2,2,2,2,2,2,1,1,1,1,1,1,1,1,1,1
1,2,2,2,2,2,2,2,1,1,1,1,1,1,1,1,1
2,2,2,2,2,2,2,2,2,1,1,1,1,1,1,1,1
2,2,2,2,2,2,2,2,2,1,1,1,1,1,1,1,1
2,2,2,2,2,2,2,2,2,1,1,1,1,1,1,1,1
2,2,2,2,2,2,2,2,2,1,1,1,1,1,1,1,1
2,2,2,2,2,2,2,2,2,1,1,1,1,1,1,1,1
1,2,2,2,2,2,2,2,2,1,1,1,1,1,1,1,1
1,1,2,2,2,2,1,1,1,1,1,1,1,1,1,1,1
endlayer

layer
1,1,1,1,1,1,1,1,1,1,1,1,1,1,1,1,1
1,1,1,1,1,1,1,1,1,1,1,1,1,1,1,1,1
1,2,2,2,2,2,2,2,1,1,1,1,1,1,1,1,1
1,2,2,2,2,2,2,2,1,1,1,1,1,1,1,1,1
2,2,2,2,2,2,2,2,2,1,1,1,1,1,1,1,1
2,2,2,2,2,2,2,2,2,1,1,1,1,1,1,1,1
2,2,2,2,2,2,2,2,2,2,1,1,1,1,1,1,1
2,2,2,2,2,2,2,2,2,1,1,1,1,1,1,1,1
2,2,2,2,2,2,2,2,2,1,1,1,1,1,1,1,1
1,2,2,2,2,2,2,2,2,1,1,1,1,1,1,1,1
1,1,2,2,2,2,1,1,1,1,1,1,1,1,1,1,1
endlayer

layer
1,1,1,1,1,1,1,1,1,1,1,1,1,1,1,1,1
1,1,1,1,1,1,1,1,1,1,1,1,1,1,1,1,1
1,2,2,2,2,2,2,2,1,1,1,1,1,1,1,1,1
1,2,2,2,2,2,2,2,1,1,1,1,1,1,1,1,1
2,2,2,2,2,2,2,2,2,1,1,1,1,1,1,1,1
2,2,2,2,2,2,2,2,2,2,1,1,1,1,1,1,1
2,2,2,2,2,2,2,2,2,2,1,1,1,1,1,1,1
2,2,2,2,2,2,2,2,2,2,1,1,1,1,1,1,1
2,2,2,2,2,2,2,2,2,1,1,1,1,1,1,1,1
1,2,2,2,2,2,2,2,2,1,1,1,1,1,1,1,1
1,1,2,2,2,2,2,1,1,1,1,1,1,1,1,1,1
endlayer

layer
1,1,1,1,1,1,1,1,1,1,1,1,1,1,1,1,1
1,1,1,1,1,1,1,1,1,1,1,1,1,1,1,1,1
1,2,2,2,2,2,2,2,1,1,1,1,1,1,1,1,1
1,2,2,2,2,2,2,2,2,1,1,1,1,1,1,1,1
2,2,2,2,2,2,2,2,2,1,1,1,1,1,1,1,1
2,2,2,2,2,2,2,2,2,2,1,1,1,1,1,1,1
2,2,2,2,2,2,2,2,2,2,1,1,1,1,1,1,1
2,2,2,2,2,2,2,2,2,2,1,1,1,1,1,1,1
1,2,2,2,2,2,2,2,2,1,1,1,1,1,1,1,1
1,2,2,2,2,2,2,2,2,1,1,1,1,1,1,1,1
1,1,2,2,2,2,2,1,1,1,1,1,1,1,1,1,1
endlayer

layer
1,1,1,1,1,1,1,1,1,1,1,1,1,1,1,1,1
1,1,1,1,1,1,1,1,1,1,1,1,1,1,1,1,1
1,2,2,2,2,2,2,2,1,1,1,1,1,1,1,1,1
1,2,2,2,2,2,2,2,2,1,1,1,1,1,1,1,1
2,2,2,2,2,2,2,2,2,2,1,1,1,1,1,1,1
2,2,2,2,2,2,2,2,2,2,1,1,1,1,1,1,1
2,2,2,2,2,2,2,2,2,2,1,1,1,1,1,1,1
2,2,2,2,2,2,2,2,2,2,1,1,1,1,1,1,1
1,2,2,2,2,2,2,2,2,1,1,1,1,1,1,1,1
1,2,2,2,2,2,2,2,2,1,1,1,1,1,1,1,1
1,1,2,2,2,2,2,1,1,1,1,1,1,1,1,1,1
endlayer

layer
1,1,1,1,1,1,1,1,1,1,1,1,1,1,1,1,1
1,1,1,1,1,1,1,1,1,1,1,1,1,1,1,1,1
1,2,2,2,2,2,2,2,2,1,1,1,1,1,1,1,1
1,2,2,2,2,2,2,2,2,1,1,1,1,1,1,1,1
1,2,2,2,2,2,2,2,2,2,1,1,1,1,1,1,1
2,2,2,2,2,2,2,2,2,2,1,1,1,1,1,1,1
2,2,2,2,2,2,2,2,2,2,1,1,1,1,1,1,1
2,2,2,2,2,2,2,2,2,2,1,1,1,1,1,1,1
1,2,2,2,2,2,2,2,2,1,1,1,1,1,1,1,1
1,2,2,2,2,2,2,2,2,1,1,1,1,1,1,1,1
1,1,2,2,2,2,2,2,1,1,1,1,1,1,1,1,1
endlayer

layer
1,1,1,1,1,1,1,1,1,1,1,1,1,1,1,1,1
1,1,1,1,1,1,1,1,1,1,1,1,1,1,1,1,1
1,1,2,2,2,2,2,2,2,1,1,1,1,1,1,1,1
1,2,2,2,2,2,2,2,2,1,1,1,1,1,1,1,1
1,2,2,2,2,2,2,2,2,2,1,1,1,1,1,1,1
2,2,2,2,2,2,2,2,2,2,1,1,1,1,1,1,1
2,2,2,2,2,2,2,2,2,2,1,1,1,1,1,1,1
2,2,2,2,2,2,2,2,2,2,1,1,1,1,1,1,1
1,2,2,2,2,2,2,2,2,1,1,1,1,1,1,1,1
1,2,2,2,2,2,2,2,2,1,1,1,1,1,1,1,1
1,1,2,2,2,2,2,2,1,1,1,1,1,1,1,1,1
endlayer

layer
1,1,1,1,1,1,1,1,1,1,1,1,1,1,1,1,1
1,1,1,1,1,1,1,1,1,1,1,1,1,1,1,1,1
1,1,2,2,2,2,2,2,2,1,1,1,1,1,1,1,1
1,2,2,2,2,2,2,2,2,2,1,1,1,1,1,1,1
1,2,2,2,2,2,2,2,2,2,1,1,1,1,1,1,1
2,2,2,2,2,2,2,2,2,2,1,1,1,1,1,1,1
2,2,2,2,2,2,2,2,2,2,1,1,1,1,1,1,1
1,2,2,2,2,2,2,2,2,2,1,1,1,1,1,1,1
1,2,2,2,2,2,2,2,2,2,1,1,1,1,1,1,1
1,2,2,2,2,2,2,2,2,1,1,1,1,1,1,1,1
1,1,2,2,2,2,2,2,1,1,1,1,1,1,1,1,1
endlayer

layer
1,1,1,1,1,1,1,1,1,1,1,1,1,1,1,1,1
1,1,1,1,1,1,1,1,1,1,1,1,1,1,1,1,1
1,1,2,2,2,2,2,2,2,1,1,1,1,1,1,1,1
1,2,2,2,2,2,2,2,2,2,1,1,1,1,1,1,1
1,2,2,2,2,2,2,2,2,2,1,1,1,1,1,1,1
1,2,2,2,2,2,2,2,2,2,1,1,1,1,1,1,1
1,2,2,2,2,2,2,2,2,2,1,1,1,1,1,1,1
1,2,2,2,2,2,2,2,2,2,1,1,1,1,1,1,1
1,2,2,2,2,2,2,2,2,2,1,1,1,1,1,1,1
1,2,2,2,2,2,2,2,2,1,1,1,1,1,1,1,1
1,1,2,2,2,2,2,2,1,1,1,1,1,1,1,1,1
endlayer

layer
1,1,1,1,1,1,1,1,1,1,1,1,1,1,1,1,1
1,1,1,1,1,1,1,1,1,1,1,1,1,1,1,1,1
1,1,2,2,2,2,2,2,2,1,1,1,1,1,1,1,1
1,2,2,2,2,2,2,2,2,2,1,1,1,1,1,1,1
1,2,2,2,2,2,2,2,2,2,1,1,1,1,1,1,1
1,2,2,2,2,2,2,2,2,2,1,1,1,1,1,1,1
1,2,2,2,2,2,2,2,2,2,1,1,1,1,1,1,1
1,2,2,2,2,2,2,2,2,2,1,1,1,1,1,1,1
1,2,2,2,2,2,2,2,2,2,1,1,1,1,1,1,1
1,2,2,2,2,2,2,2,2,1,1,1,1,1,1,1,1
1,1,1,2,2,2,2,2,1,1,1,1,1,1,1,1,1
endlayer

layer
1,1,1,1,1,1,1,1,1,1,1,1,1,1,1,1,1
1,1,1,1,1,1,1,1,1,1,1,1,1,1,1,1,1
1,1,2,2,2,2,2,2,1,1,1,1,1,1,1,1,1
1,2,2,2,2,2,2,2,2,2,1,1,1,1,1,1,1
1,2,2,2,2,2,2,2,2,2,1,1,1,1,1,1,1
1,2,2,2,2,2,2,2,2,2,1,1,1,1,1,1,1
1,2,2,2,2,2,2,2,2,2,1,1,1,1,1,1,1
1,2,2,2,2,2,2,2,2,2,1,1,1,1,1,1,1
1,2,2,2,2,2,2,2,2,2,1,1,1,1,1,1,1
1,2,2,2,2,2,2,2,2,1,1,1,1,1,1,1,1
1,1,1,2,2,2,2,2,1,1,1,1,1,1,1,1,1
endlayer

layer
1,1,1,1,1,1,1,1,1,1,1,1,1,1,1,1,1
1,1,1,1,1,1,1,1,1,1,1,1,1,1,1,1,1
1,1,1,2,2,2,2,2,1,1,1,1,1,1,1,1,1
1,2,2,2,2,2,2,2,2,2,1,1,1,1,1,1,1
1,2,2,2,2,2,2,2,2,2,1,1,1,1,1,1,1
1,2,2,2,2,2,2,2,2,2,1,1,1,1,1,1,1
1,2,2,2,2,2,2,2,2,2,1,1,1,1,1,1,1
1,2,2,2,2,2,2,2,2,2,1,1,1,1,1,1,1
1,2,2,2,2,2,2,2,2,2,1,1,1,1,1,1,1
1,2,2,2,2,2,2,2,2,1,1,1,1,1,1,1,1
1,1,1,2,2,2,2,2,1,1,1,1,1,1,1,1,1
endlayer

layer
1,1,1,1,1,1,1,1,1,1,1,1,1,1,1,1,1
1,1,1,1,1,1,1,1,1,1,1,1,1,1,1,1,1
1,1,1,2,2,2,2,2,1,1,1,1,1,1,1,1,1
1,2,2,2,2,2,2,2,2,2,1,1,1,1,1,1,1
1,2,2,2,2,2,2,2,2,2,1,1,1,1,1,1,1
1,2,2,2,2,2,2,2,2,2,1,1,1,1,1,1,1
1,2,2,2,2,2,2,2,2,2,1,1,1,1,1,1,1
1,2,2,2,2,2,2,2,2,2,1,1,1,1,1,1,1
1,2,2,2,2,2,2,2,2,2,1,1,1,1,1,1,1
1,1,2,2,2,2,2,2,2,1,1,1,1,1,1,1,1
1,1,1,1,2,2,2,2,1,1,1,1,1,1,1,1,1
endlayer

layer
1,1,1,1,1,1,1,1,1,1,1,1,1,1,1,1,1
1,1,1,1,1,1,1,1,1,1,1,1,1,1,1,1,1
1,1,1,2,2,2,2,2,1,1,1,1,1,1,1,1,1
1,2,2,2,2,2,2,2,2,1,1,1,1,1,1,1,1
1,2,2,2,2,2,2,2,2,2,1,1,1,1,1,1,1
1,2,2,2,2,2,2,2,2,2,1,1,1,1,1,1,1
1,2,2,2,2,2,2,2,2,2,1,1,1,1,1,1,1
1,2,2,2,2,2,2,2,2,2,1,1,1,1,1,1,1
1,2,2,2,2,2,2,2,2,2,1,1,1,1,1,1,1
1,1,2,2,2,2,2,2,2,1,1,1,1,1,1,1,1
1,1,1,1,2,2,2,2,1,1,1,1,1,1,1,1,1
endlayer

layer
1,1,1,1,1,1,1,1,1,1,1,1,1,1,1,1,1
1,1,1,1,1,1,1,1,1,1,1,1,1,1,1,1,1
1,1,1,1,2,2,2,2,1,1,1,1,1,1,1,1,1
1,1,2,2,2,2,2,2,2,1,1,1,1,1,1,1,1
1,2,2,2,2,2,2,2,2,2,1,1,1,1,1,1,1
1,2,2,2,2,2,2,2,2,2,1,1,1,1,1,1,1
1,2,2,2,2,2,2,2,2,2,1,1,1,1,1,1,1
1,2,2,2,2,2,2,2,2,2,1,1,1,1,1,1,1
1,2,2,2,2,2,2,2,2,2,1,1,1,1,1,1,1
1,1,2,2,2,2,2,2,2,1,1,1,1,1,1,1,1
1,1,1,1,2,2,2,1,1,1,1,1,1,1,1,1,1
endlayer

layer
1,1,1,1,1,1,1,1,1,1,1,1,1,1,1,1,1
1,1,1,1,1,1,1,1,1,1,1,1,1,1,1,1,1
1,1,1,1,2,2,2,2,1,1,1,1,1,1,1,1,1
1,1,2,2,2,2,2,2,2,1,1,1,1,1,1,1,1
1,2,2,2,2,2,2,2,2,2,1,1,1,1,1,1,1
1,2,2,2,2,2,2,2,2,2,1,1,1,1,1,1,1
1,2,2,2,2,2,2,2,2,2,1,1,1,1,1,1,1
1,2,2,2,2,2,2,2,2,2,1,1,1,1,1,1,1
1,2,2,2,2,2,2,2,2,2,1,1,1,1,1,1,1
1,1,1,2,2,2,2,2,2,1,1,1,1,1,1,1,1
1,1,1,1,2,2,2,1,1,1,1,1,1,1,1,1,1
endlayer

layer
1,1,1,1,1,1,1,1,1,1,1,1,1,1,1,1,1
1,1,1,1,1,1,1,1,1,1,1,1,1,1,1,1,1
1,1,1,1,1,2,2,2,1,1,1,1,1,1,1,1,1
1,1,2,2,2,2,2,2,2,1,1,1,1,1,1,1,1
1,2,2,2,2,2,2,2,2,2,1,1,1,1,1,1,1
1,2,2,2,2,2,2,2,2,2,1,1,1,1,1,1,1
1,2,2,2,2,2,2,2,2,2,1,1,1,1,1,1,1
1,2,2,2,2,2,2,2,2,2,1,1,1,1,1,1,1
1,1,2,2,2,2,2,2,2,2,1,1,1,1,1,1,1
1,1,1,2,2,2,2,2,2,1,1,1,1,1,1,1,1
1,1,1,1,2,2,2,1,1,1,1,1,1,1,1,1,1
endlayer

layer
1,1,1,1,1,1,1,1,1,1,1,1,1,1,1,1,1
1,1,1,1,1,1,1,1,1,1,1,1,1,1,1,1,1
1,1,1,1,1,2,2,2,1,1,1,1,1,1,1,1,1
1,1,1,2,2,2,2,2,2,1,1,1,1,1,1,1,1
1,1,2,2,2,2,2,2,2,1,1,1,1,1,1,1,1
1,2,2,2,2,2,2,2,2,2,1,1,1,1,1,1,1
1,2,2,2,2,2,2,2,2,2,1,1,1,1,1,1,1
1,2,2,2,2,2,2,2,2,2,1,1,1,1,1,1,1
1,1,2,2,2,2,2,2,2,2,1,1,1,1,1,1,1
1,1,1,2,2,2,2,2,2,1,1,1,1,1,1,1,1
1,1,1,1,1,2,1,1,1,1,1,1,1,1,1,1,1
endlayer

layer
1,1,1,1,1,1,1,1,1,1,1,1,1,1,1,1,1
1,1,1,1,1,1,1,1,1,1,1,1,1,1,1,1,1
1,1,1,1,1,1,2,1,1,1,1,1,1,1,1,1,1
1,1,1,2,2,2,2,2,2,1,1,1,1,1,1,1,1
1,1,2,2,2,2,2,2,2,1,1,1,1,1,1,1,1
1,2,2,2,2,2,2,2,2,2,1,1,1,1,1,1,1
1,2,2,2,2,2,2,2,2,2,1,1,1,1,1,1,1
1,2,2,2,2,2,2,2,2,2,1,1,1,1,1,1,1
1,1,2,2,2,2,2,2,2,1,1,1,1,1,1,1,1
1,1,1,2,2,2,2,2,2,1,1,1,1,1,1,1,1
1,1,1,1,1,1,1,1,1,1,1,1,1,1,1,1,1
endlayer

layer
1,1,1,1,1,1,1,1,1,1,1,1,1,1,1,1,1
1,1,1,1,1,1,1,1,1,1,1,1,1,1,1,1,1
1,1,1,1,1,1,1,1,1,1,1,1,1,1,1,1,1
1,1,1,1,2,2,2,2,1,1,1,1,1,1,1,1,1
1,1,2,2,2,2,2,2,2,1,1,1,1,1,1,1,1
1,2,2,2,2,2,2,2,2,2,1,1,1,1,1,1,1
1,2,2,2,2,2,2,2,2,2,1,1,1,1,1,1,1
1,1,2,2,2,2,2,2,2,2,1,1,1,1,1,1,1
1,1,2,2,2,2,2,2,2,1,1,1,1,1,1,1,1
1,1,1,1,2,2,2,2,2,1,1,1,1,1,1,1,1
1,1,1,1,1,1,1,1,1,1,1,1,1,1,1,1,1
endlayer

layer
1,1,1,1,1,1,1,1,1,1,1,1,1,1,1,1,1
1,1,1,1,1,1,1,1,1,1,1,1,1,1,1,1,1
1,1,1,1,1,1,1,1,1,1,1,1,1,1,1,1,1
1,1,1,1,2,2,2,2,1,1,1,1,1,1,1,1,1
1,1,2,2,2,2,2,2,2,1,1,1,1,1,1,1,1
1,1,2,2,2,2,2,2,2,2,1,1,1,1,1,1,1
1,2,2,2,2,2,2,2,2,2,1,1,1,1,1,1,1
1,1,2,2,2,2,2,2,2,2,1,1,1,1,1,1,1
1,1,1,2,2,2,2,2,2,1,1,1,1,1,1,1,1
1,1,1,1,2,2,2,2,1,1,1,1,1,1,1,1,1
1,1,1,1,1,1,1,1,1,1,1,1,1,1,1,1,1
endlayer

layer
1,1,1,1,1,1,1,1,1,1,1,1,1,1,1,1,1
1,1,1,1,1,1,1,1,1,1,1,1,1,1,1,1,1
1,1,1,1,1,1,1,1,1,1,1,1,1,1,1,1,1
1,1,1,1,1,2,2,1,1,1,1,1,1,1,1,1,1
1,1,1,2,2,2,2,2,2,1,1,1,1,1,1,1,1
1,1,2,2,2,2,2,2,2,2,1,1,1,1,1,1,1
1,1,2,2,2,2,4,3,3,3,1,1,1,1,1,1,1
1,1,2,2,2,2,2,2,2,2,1,1,1,1,1,1,1
1,1,1,2,2,2,2,2,2,1,1,1,1,1,1,1,1
1,1,1,1,1,2,2,2,1,1,1,1,1,1,1,1,1
1,1,1,1,1,1,1,1,1,1,1,1,1,1,1,1,1
endlayer

layer
1,1,1,1,1,1,1,1,1,1,1,1,1,1,1,1,1
1,1,1,1,1,1,1,1,1,1,1,1,1,1,1,1,1
1,1,1,1,1,1,1,1,1,1,1,1,1,1,1,1,1
1,1,1,1,1,2,2,1,1,1,1,1,1,1,1,1,1
1,1,1,2,2,2,2,2,2,1,1,1,1,1,1,1,1
1,1,1,2,2,2,2,2,2,2,1,1,1,1,1,1,1
1,1,2,2,2,2,4,3,3,3,1,1,1,1,1,1,1
1,1,2,2,2,2,2,2,2,2,1,1,1,1,1,1,1
1,1,1,2,2,2,2,2,2,1,1,1,1,1,1,1,1
1,1,1,1,1,2,2,2,1,1,1,1,1,1,1,1,1
1,1,1,1,1,1,1,1,1,1,1,1,1,1,1,1,1
endlayer

layer
1,1,1,1,1,1,1,1,1,1,1,1,1,1,1,1,1
1,1,1,1,1,1,1,1,1,1,1,1,1,1,1,1,1
1,1,1,1,1,1,1,1,1,1,1,1,1,1,1,1,1
1,1,1,1,1,1,2,1,1,1,1,1,1,1,1,1,1
1,1,1,1,2,2,2,2,2,1,1,1,1,1,1,1,1
1,1,1,2,2,2,2,2,2,2,1,1,1,1,1,1,1
1,1,2,2,2,2,4,3,3,2,1,1,1,1,1,1,1
1,1,1,2,2,2,2,2,2,2,1,1,1,1,1,1,1
1,1,1,2,2,2,2,2,2,1,1,1,1,1,1,1,1
1,1,1,1,1,1,2,2,1,1,1,1,1,1,1,1,1
1,1,1,1,1,1,1,1,1,1,1,1,1,1,1,1,1
endlayer

layer
1,1,1,1,1,1,1,1,1,1,1,1,1,1,1,1,1
1,1,1,1,1,1,1,1,1,1,1,1,1,1,1,1,1
1,1,1,1,1,1,1,1,1,1,1,1,1,1,1,1,1
1,1,1,1,1,1,1,1,1,1,1,1,1,1,1,1,1
1,1,1,1,2,2,2,2,1,1,1,1,1,1,1,1,1
1,1,1,2,2,2,2,2,2,1,1,1,1,1,1,1,1
1,1,1,2,2,2,4,2,2,2,1,1,1,1,1,1,1
1,1,1,2,2,2,2,2,2,1,1,1,1,1,1,1,1
1,1,1,1,2,2,2,2,2,1,1,1,1,1,1,1,1
1,1,1,1,1,1,2,2,1,1,1,1,1,1,1,1,1
1,1,1,1,1,1,1,1,1,1,1,1,1,1,1,1,1
endlayer

layer
1,1,1,1,1,1,1,1,1,1,1,1,1,1,1,1,1
1,1,1,1,1,1,1,1,1,1,1,1,1,1,1,1,1
1,1,1,1,1,1,1,1,1,1,1,1,1,1,1,1,1
1,1,1,1,1,1,1,1,1,1,1,1,1,1,1,1,1
1,1,1,1,2,2,2,2,1,1,1,1,1,1,1,1,1
1,1,1,1,2,2,2,2,2,1,1,5,1,1,1,1,1
1,1,1,2,2,2,4,2,2,2,1,1,1,1,1,1,1
1,1,1,2,2,2,2,2,2,1,1,1,1,1,1,1,1
1,1,1,1,2,2,2,2,2,1,1,1,1,1,1,1,1
1,1,1,1,1,1,2,2,1,1,1,1,1,1,1,1,1
1,1,1,1,1,1,1,1,1,1,1,1,1,1,1,1,1
endlayer

layer
1,1,1,1,1,1,1,1,1,1,1,1,1,1,1,1,1
1,1,1,1,1,1,1,1,1,1,1,1,1,1,1,1,1
1,1,1,1,1,1,1,1,1,1,1,1,1,1,1,1,1
1,1,1,1,1,1,1,1,1,1,1,1,1,1,1,1,1
1,1,1,1,2,2,2,2,1,1,1,6,1,1,1,1,1
1,1,1,1,2,2,2,2,2,1,8,5,7,1,1,1,1
1,1,1,2,2,2,4,2,2,1,1,9,1,1,1,1,1
1,1,1,2,2,2,2,2,2,1,1,1,1,1,1,1,1
1,1,1,1,2,2,2,2,2,1,1,1,1,1,1,1,1
1,1,1,1,1,1,1,2,1,1,1,1,1,1,1,1,1
1,1,1,1,1,1,1,1,1,1,1,1,1,1,1,1,1
endlayer

layer
1,1,1,1,1,1,1,1,1,1,1,1,1,1,1,1,1
1,1,1,1,1,1,1,1,1,1,1,1,1,1,1,1,1
1,1,1,1,1,1,1,1,1,1,1,1,1,1,1,1,1
1,1,1,1,1,1,1,1,1,1,1,1,1,1,1,1,1
1,1,1,1,1,2,2,1,1,1,6,5,7,1,1,1,1
1,1,1,1,2,2,2,2,2,1,5,5,5,1,1,1,1
1,1,1,1,2,2,4,2,2,1,8,5,9,1,1,1,1
1,1,1,2,2,2,2,2,2,1,1,1,1,1,1,1,1
1,1,1,1,1,2,2,2,2,1,1,1,1,1,1,1,1
1,1,1,1,1,1,1,1,1,1,1,1,1,1,1,1,1
1,1,1,1,1,1,1,1,1,1,1,1,1,1,1,1,1
endlayer

layer
1,1,1,1,1,1,1,1,1,1,1,1,1,1,1,1,1
1,1,1,1,1,1,1,1,1,1,1,1,1,1,1,1,1
1,1,1,1,1,1,1,1,1,1,1,1,1,1,1,1,1
1,1,1,1,1,1,1,1,1,1,1,1,1,1,1,1,1
1,1,1,1,1,1,1,1,1,1,8,5,6,1,1,1,1
1,1,1,1,2,2,2,2,1,1,5,5,5,1,1,1,1
1,1,1,1,2,2,4,2,2,1,9,5,7,1,1,1,1
1,1,1,1,2,2,2,2,2,1,1,1,1,1,1,1,1
1,1,1,1,1,2,2,2,1,1,1,1,1,1,1,1,1
1,1,1,1,1,1,1,1,1,1,1,1,1,1,1,1,1
1,1,1,1,1,1,1,1,1,1,1,1,1,1,1,1,1
endlayer

layer
1,1,1,1,1,1,1,1,1,1,1,1,1,1,1,1,1
1,1,1,1,1,1,1,1,1,1,1,1,1,1,1,1,1
1,1,1,1,1,1,1,1,1,1,1,1,1,1,1,1,1
1,1,1,1,1,1,1,1,1,1,1,1,1,1,1,1,1
1,1,1,1,1,1,1,1,1,1,11,5,10,1,1,1,1
1,1,1,1,1,2,2,2,1,1,5,5,5,1,1,1,1
1,1,1,1,2,2,4,2,2,1,13,5,12,1,1,1,1
1,1,1,1,2,2,2,2,2,1,1,1,1,1,1,1,1
1,1,1,1,1,2,2,2,1,1,1,1,1,1,1,1,1
1,1,1,1,1,1,1,1,1,1,1,1,1,1,1,1,1
1,1,1,1,1,1,1,1,1,1,1,1,1,1,1,1,1
endlayer

layer
1,1,1,1,1,1,1,1,1,1,1,1,1,1,1,1,1
1,1,1,1,1,1,1,1,1,1,1,1,1,1,1,1,1
1,1,1,1,1,1,1,1,1,1,1,1,1,1,1,1,1
1,1,1,1,1,1,1,1,1,1,8,6,7,1,1,1,1
1,1,1,1,1,1,1,1,1,6,5,5,5,6,1,1,1
1,1,1,1,1,2,2,2,1,8,5,5,5,7,1,1,1
1,1,1,1,2,2,4,2,2,9,5,5,5,9,1,1,1
1,1,1,1,2,2,2,2,2,2,8,9,7,1,1,1,1
1,1,1,1,1,1,2,2,2,1,1,1,1,1,1,1,1
1,1,1,1,1,1,1,1,1,1,1,1,1,1,1,1,1
1,1,1,1,1,1,1,1,1,1,1,1,1,1,1,1,1
endlayer

layer
1,1,1,1,1,1,1,1,1,1,1,1,1,1,1,1,1
1,1,1,1,1,1,1,1,1,1,1,1,1,1,1,1,1
1,1,1,1,1,1,1,1,1,1,1,1,1,1,1,1,1
1,1,1,1,1,1,1,1,1,1,1,14,1,1,1,1,1
1,1,1,1,1,1,1,1,1,1,5,5,10,1,1,1,1
1,1,1,1,1,2,2,2,2,14,5,5,5,14,1,1,1
1,1,1,1,2,2,4,2,2,2,5,5,5,1,1,1,1
1,1,1,1,1,2,2,2,2,2,2,14,1,1,1,1,1
1,1,1,1,1,1,2,2,2,2,2,1,1,1,1,1,1
1,1,1,1,1,1,1,1,2,1,1,1,1,1,1,1,1
1,1,1,1,1,1,1,1,1,1,1,1,1,1,1,1,1
endlayer

layer
1,1,1,1,1,1,1,1,1,1,1,1,1,1,1,1,1
1,1,1,1,1,1,1,1,1,1,1,1,1,1,1,1,1
1,1,1,1,1,1,1,1,1,1,1,1,1,1,1,1,1
1,1,1,1,1,1,1,1,1,1,1,1,1,1,1,1,1
1,1,1,1,1,1,2,2,1,1,11,11,6,1,1,1,1
1,1,1,1,1,2,2,2,2,1,5,5,5,1,1,1,1
1,1,1,1,1,2,4,2,2,2,5,5,15,1,1,1,1
1,1,1,1,1,2,2,2,2,2,2,2,1,1,1,1,1
1,1,1,1,1,1,2,2,2,2,2,1,1,1,1,1,1
1,1,1,1,1,1,1,1,2,2,1,1,1,1,1,1,1
1,1,1,1,1,1,1,1,1,1,1,1,1,1,1,1,1
endlayer

layer
1,1,1,1,1,1,1,1,1,1,1,1,1,1,1,1,1
1,1,1,1,1,1,1,1,1,1,1,1,1,1,1,1,1
1,1,1,1,1,1,1,1,1,1,1,1,1,1,1,1,1
1,1,1,1,1,1,1,1,1,1,1,1,1,1,1,1,1
1,1,1,1,1,2,2,2,2,1,8,14,10,1,1,1,1
1,1,1,1,1,2,3,13,2,2,5,5,5,1,1,1,1
1,1,1,1,1,2,4,2,2,2,5,5,10,1,1,1,1
1,1,1,1,1,1,2,2,2,2,2,2,2,1,1,1,1
1,1,1,1,1,1,1,2,2,2,2,2,1,1,1,1,1
1,1,1,1,1,1,1,1,2,2,1,1,1,1,1,1,1
1,1,1,1,1,1,1,1,1,1,1,1,1,1,1,1,1
endlayer

layer
1,1,1,1,1,1,1,1,1,1,1,1,1,1,1,1,1
1,1,1,1,1,1,1,1,1,1,1,1,1,1,1,1,1
1,1,1,1,1,1,1,1,1,1,1,1,1,1,1,1,1
1,1,1,1,1,1,1,2,2,1,1,6,1,1,1,1,1
1,1,1,1,1,2,2,2,2,2,8,5,6,1,1,1,1
1,1,1,1,1,2,3,3,13,5,5,5,5,7,1,1,1
1,1,1,1,1,2,3,2,2,2,5,5,5,2,1,1,1
1,1,1,1,1,1,2,2,2,2,2,5,2,1,1,1,1
1,1,1,1,1,1,1,2,2,2,2,2,2,1,1,1,1
1,1,1,1,1,1,1,1,2,2,2,1,1,1,1,1,1
1,1,1,1,1,1,1,1,1,1,1,1,1,1,1,1,1
endlayer

layer
1,1,1,1,1,1,1,1,1,1,1,1,1,1,1,1,1
1,1,1,1,1,1,1,1,1,1,1,1,1,1,1,1,1
1,1,1,1,1,1,1,1,1,1,1,1,1,1,1,1,1
1,1,1,1,1,1,2,2,2,1,1,6,1,1,1,1,1
1,1,1,1,1,1,2,2,2,2,13,5,10,1,1,1,1
1,1,1,1,1,2,3,3,3,13,5,5,5,7,1,1,1
1,1,1,1,1,2,3,2,2,2,5,5,5,2,1,1,1
1,1,1,1,1,1,2,2,2,2,2,5,2,2,1,1,1
1,1,1,1,1,1,1,2,2,2,2,2,2,1,1,1,1
1,1,1,1,1,1,1,1,2,2,2,2,1,1,1,1,1
1,1,1,1,1,1,1,1,1,1,1,1,1,1,1,1,1
endlayer

layer
1,1,1,1,1,1,1,1,1,1,1,1,1,1,1,1,1
1,1,1,1,1,1,1,1,1,1,1,1,1,1,1,1,1
1,1,1,1,1,1,1,1,1,1,1,1,1,1,1,1,1
1,1,1,1,1,1,2,2,2,1,8,6,7,1,1,1,1
1,1,1,1,1,1,2,2,2,8,5,5,5,7,1,1,1
1,1,1,1,1,2,3,3,3,3,13,5,5,5,2,1,1
1,1,1,1,1,1,2,2,2,5,5,5,5,5,2,1,1
1,1,1,1,1,1,1,2,2,2,5,5,5,2,1,1,1
1,1,1,1,1,1,1,2,2,2,2,2,2,1,1,1,1
1,1,1,1,1,1,1,1,2,2,2,2,1,1,1,1,1
1,1,1,1,1,1,1,1,1,1,1,1,1,1,1,1,1
endlayer

layer
1,1,1,1,1,1,1,1,1,1,1,1,1,1,1,1,1
1,1,1,1,1,1,1,1,1,1,1,1,1,1,1,1,1
1,1,1,1,1,1,1,1,1,1,1,1,1,1,1,1,1
1,1,1,1,1,1,2,2,2,1,6,6,7,1,1,1,1
1,1,1,1,1,1,2,2,2,8,5,5,5,6,2,1,1
1,1,1,1,1,1,2,3,3,3,3,16,5,5,2,2,1
1,1,1,1,1,1,2,2,2,5,5,5,5,5,2,1,1
1,1,1,1,1,1,1,2,2,2,5,5,5,2,2,1,1
1,1,1,1,1,1,1,1,2,2,2,2,2,2,1,1,1
1,1,1,1,1,1,1,1,1,2,2,2,1,1,1,1,1
1,1,1,1,1,1,1,1,1,1,1,1,1,1,1,1,1
endlayer

layer
1,1,1,1,1,1,1,1,1,1,1,1,1,1,1,1,1
1,1,1,1,1,1,1,1,1,1,1,1,1,1,1,1,1
1,1,1,1,1,1,1,1,1,1,1,1,1,1,1,1,1
1,1,1,1,1,1,1,2,2,1,6,6,6,17,2,1,1
1,1,1,1,1,1,2,2,2,8,5,5,5,5,2,2,1
1,1,1,1,1,1,2,2,3,3,3,16,5,5,2,2,1
1,1,1,1,1,1,1,2,2,5,18,18,5,5,2,2,1
1,1,1,1,1,1,1,2,2,2,5,5,5,2,2,1,1
1,1,1,1,1,1,1,1,2,2,2,2,2,2,1,1,1
1,1,1,1,1,1,1,1,1,1,2,2,2,1,1,1,1
1,1,1,1,1,1,1,1,1,1,1,1,1,1,1,1,1
endlayer

layer
1,1,1,1,1,1,1,1,1,1,1,1,1,1,1,1,1
1,1,1,1,1,1,1,1,1,1,1,1,1,1,1,1,1
1,1,1,1,1,1,1,1,1,1,1,1,1,1,1,1,1
1,1,1,1,1,1,1,2,2,1,6,11,6,1,1,1,1
1,1,1,1,1,1,2,2,2,8,5,5,5,5,2,1,1
1,1,1,1,1,1,1,2,2,3,3,16,5,5,2,2,1
1,1,1,1,1,1,1,2,2,5,5,5,5,5,2,2,1
1,1,1,1,1,1,1,1,2,2,5,5,5,2,2,2,1
1,1,1,1,1,1,1,1,1,2,2,2,2,2,2,1,1
1,1,1,1,1,1,1,1,1,1,1,2,2,1,1,1,1
1,1,1,1,1,1,1,1,1,1,1,1,1,1,1,1,1
endlayer

layer
1,1,1,1,1,1,1,1,1,1,1,1,1,1,1,1,1
1,1,1,1,1,1,1,1,1,1,1,1,1,1,1,1,1
1,1,1,1,1,1,1,1,1,1,1,1,17,2,1,1,1
1,1,1,1,1,1,1,2,2,1,11,1,11,1,2,2,1
1,1,1,1,1,1,1,2,2,13,5,11,5,5,2,2,1
1,1,1,1,1,1,1,2,2,5,5,16,5,5,2,2,1
1,1,1,1,1,1,1,1,2,5,5,5,5,5,2,2,1
1,1,1,1,1,1,1,1,1,2,5,5,5,2,2,2,1
1,1,1,1,1,1,1,1,1,1,2,2,2,2,2,1,1
1,1,1,1,1,1,1,1,1,1,1,1,1,1,1,1,1
1,1,1,1,1,1,1,1,1,1,1,1,1,1,1,1,1
endlayer

layer
1,1,1,1,1,1,1,1,1,1,1,1,1,1,1,1,1
1,1,1,1,1,1,1,1,1,1,1,1,1,1,1,1,1
1,1,1,1,1,1,1,1,1,1,1,1,1,1,1,1,1
1,1,1,1,1,1,1,1,17,2,1,15,6,2,2,1,1
1,1,1,1,1,1,1,1,2,5,6,5,5,5,2,2,1
1,1,1,1,1,1,1,1,1,11,5,16,5,5,2,2,1
1,1,1,1,1,1,1,1,1,5,5,5,5,5,2,2,1
1,1,1,1,1,1,1,1,1,1,9,15,5,2,2,2,1
1,1,1,1,1,1,1,1,1,1,1,1,2,2,1,1,1
1,1,1,1,1,1,1,1,1,1,1,1,1,1,1,1,1
1,1,1,1,1,1,1,1,1,1,1,1,1,1,1,1,1
endlayer

layer
1,1,1,1,1,1,1,1,1,1,1,1,1,1,1,1,1
1,1,1,1,1,1,1,1,1,1,1,1,1,1,1,1,1
1,1,1,1,1,1,1,1,1,1,1,17,2,2,1,1,1
1,1,1,1,1,1,1,1,1,2,5,5,5,2,2,2,1
1,1,1,1,1,1,1,1,1,8,5,5,5,1,1,1,1
1,1,1,1,1,1,1,1,1,15,5,16,5,15,2,2,1
1,1,1,1,1,1,1,1,1,1,5,5,5,5,2,2,1
1,1,1,1,1,1,1,1,1,1,14,13,5,2,2,1,1
1,1,1,1,1,1,1,1,1,1,1,1,1,1,1,1,1
1,1,1,1,1,1,1,1,1,1,1,1,1,1,1,1,1
1,1,1,1,1,1,1,1,1,1,1,1,1,1,1,1,1
endlayer

layer
1,1,1,1,1,1,1,1,1,1,1,1,1,1,1,1,1
1,1,1,1,1,1,1,1,1,1,1,1,1,1,1,1,1
1,1,1,1,1,1,1,1,1,1,1,1,1,1,1,1,1
1,1,1,1,1,1,1,1,1,1,1,15,6,5,1,1,1
1,1,1,1,1,1,1,1,1,14,5,5,5,5,2,1,1
1,1,1,1,1,1,1,1,1,11,5,16,5,5,2,2,1
1,1,1,1,1,1,1,1,1,5,5,5,5,9,2,1,1
1,1,1,1,1,1,1,1,1,1,9,15,1,1,1,1,1
1,1,1,1,1,1,1,1,1,1,1,1,1,1,1,1,1
1,1,1,1,1,1,1,1,1,1,1,1,1,1,1,1,1
1,1,1,1,1,1,1,1,1,1,1,1,1,1,1,1,1
endlayer

layer
1,1,1,1,1,1,1,1,1,1,1,1,1,1,1,1,1
1,1,1,1,1,1,1,1,1,1,1,1,1,1,1,1,1
1,1,1,1,1,1,1,1,1,1,6,6,6,17,1,1,1
1,1,1,1,1,1,1,1,1,8,5,5,5,5,2,1,1
1,1,1,1,1,1,1,1,8,5,5,5,5,5,2,1,1
1,1,1,1,1,1,1,1,8,5,5,16,5,5,7,1,1
1,1,1,1,1,1,1,1,8,5,5,5,5,5,7,1,1
1,1,1,1,1,1,1,1,1,8,5,5,5,9,1,1,1
1,1,1,1,1,1,1,1,1,1,9,9,9,1,1,1,1
1,1,1,1,1,1,1,1,1,1,1,1,1,1,1,1,1
1,1,1,1,1,1,1,1,1,1,1,1,1,1,1,1,1
endlayer

layer
1,1,1,1,1,1,1,1,1,1,1,1,1,1,1,1,1
1,1,1,1,1,1,1,1,1,1,1,1,1,1,1,1,1
1,1,1,1,1,1,1,1,1,1,11,11,11,1,1,1,1
1,1,1,1,1,1,1,1,1,11,5,5,5,6,1,1,1
1,1,1,1,1,1,1,1,13,5,5,5,5,5,10,1,1
1,1,1,1,1,1,1,1,13,5,5,16,5,5,10,1,1
1,1,1,1,1,1,1,1,13,5,5,5,5,5,10,1,1
1,1,1,1,1,1,1,1,1,12,5,5,5,10,1,1,1
1,1,1,1,1,1,1,1,1,1,12,12,12,1,1,1,1
1,1,1,1,1,1,1,1,1,1,1,1,1,1,1,1,1
1,1,1,1,1,1,1,1,1,1,1,1,1,1,1,1,1
endlayer

layer
1,1,1,1,1,1,1,1,1,1,1,15,1,1,1,1,1
1,1,1,1,1,1,1,1,8,6,5,5,5,6,7,1,1
1,1,1,1,1,1,1,6,5,5,5,5,5,5,5,6,1
1,1,1,1,1,1,1,8,5,5,5,5,5,5,5,7,1
1,1,1,1,1,1,1,5,5,5,5,5,5,5,5,5,7
1,1,1,1,1,1,15,5,5,5,5,16,5,5,5,5,7
1,1,1,1,1,1,1,5,5,5,5,5,5,5,5,5,7
1,1,1,1,1,1,1,8,5,5,5,5,5,5,5,7,1
1,1,1,1,1,1,1,9,5,5,5,5,5,5,5,9,1
1,1,1,1,1,1,1,1,8,9,5,5,5,9,7,1,1
1,1,1,1,1,1,1,1,1,1,1,15,1,1,1,1,1
endlayer

layer
1,1,1,1,1,1,1,1,1,8,11,11,11,7,1,1,1
1,1,1,1,1,1,1,1,13,3,3,3,3,3,10,1,1
1,1,1,1,1,1,1,11,3,3,3,3,3,3,3,11,1
1,1,1,1,1,1,6,3,3,3,3,3,3,3,3,3,6
1,1,1,1,1,1,13,3,3,3,5,3,5,3,3,3,10
1,1,1,1,1,1,13,3,3,3,5,16,5,3,3,3,10
1,1,1,1,1,1,13,3,3,3,5,5,5,3,3,3,10
1,1,1,1,1,1,9,3,3,3,3,3,3,3,3,3,9
1,1,1,1,1,1,1,12,3,3,3,3,3,3,3,12,1
1,1,1,1,1,1,1,1,13,3,3,3,3,3,10,1,1
1,1,1,1,1,1,1,1,1,8,12,12,12,7,1,1,1
endlayer

layer
1,1,1,1,1,1,1,1,1,11,11,11,11,11,1,1,1
1,1,1,1,1,1,1,1,13,3,3,3,3,3,10,1,1
1,1,1,1,1,1,1,11,3,3,3,3,3,3,3,11,1
1,1,1,1,1,1,13,3,3,3,3,3,3,3,3,3,10
1,1,1,1,1,1,13,3,3,3,5,3,5,3,3,3,10
1,1,1,1,1,1,13,3,3,3,5,16,5,3,3,3,10
1,1,1,1,1,1,13,3,3,3,5,5,5,3,3,3,10
1,1,1,1,1,1,13,3,3,3,3,3,3,3,3,3,10
1,1,1,1,1,1,1,12,3,3,3,3,3,3,3,12,1
1,1,1,1,1,1,1,1,13,3,3,3,3,3,10,1,1
1,1,1,1,1,1,1,1,1,12,12,12,12,12,1,1,1
endlayer

layer
1,1,1,1,1,1,1,1,1,1,1,1,1,1,1,1,1
1,1,1,1,1,1,1,1,1,11,12,12,12,11,1,1,1
1,1,1,1,1,1,1,1,12,12,1,1,1,12,13,1,1
1,1,1,1,1,1,1,13,10,1,1,15,6,1,13,10,1
1,1,1,1,1,1,1,10,1,14,5,5,5,5,1,13,1
1,1,1,1,1,1,1,10,1,11,5,16,5,12,1,13,1
1,1,1,1,1,1,1,10,1,5,5,5,5,14,1,13,1
1,1,1,1,1,1,1,13,10,1,9,15,1,1,13,10,1
1,1,1,1,1,1,1,1,10,11,1,1,1,11,13,1,1
1,1,1,1,1,1,1,1,1,12,11,11,11,12,1,1,1
1,1,1,1,1,1,1,1,1,1,1,1,1,1,1,1,1
endlayer

layer
1,1,1,1,1,1,1,1,1,1,1,1,1,1,1,1,1
1,1,1,1,1,1,1,1,1,1,1,1,1,1,1,1,1
1,1,1,1,1,1,1,1,1,1,1,1,1,1,1,1,1
1,1,1,1,1,1,1,1,1,1,5,5,5,1,1,1,1
1,1,1,1,1,1,1,1,1,5,5,5,5,5,1,1,1
1,1,1,1,1,1,1,1,1,5,5,19,5,5,1,1,1
1,1,1,1,1,1,1,1,1,5,5,5,5,5,1,1,1
1,1,1,1,1,1,1,1,1,1,9,5,5,1,1,1,1
1,1,1,1,1,1,1,1,1,1,1,1,1,1,1,1,1
1,1,1,1,1,1,1,1,1,1,1,1,1,1,1,1,1
1,1,1,1,1,1,1,1,1,1,1,1,1,1,1,1,1
endlayer

layer
1,1,1,1,1,1,1,1,1,1,1,1,1,1,1,1,1
1,1,1,1,1,1,1,1,1,1,1,1,1,1,1,1,1
1,1,1,1,1,1,1,1,1,1,1,1,1,1,1,1,1
1,1,1,1,1,1,1,1,1,1,11,5,11,1,1,1,1
1,1,1,1,1,1,1,1,1,13,3,3,3,10,1,1,1
1,1,1,1,1,1,1,1,1,5,3,3,3,5,1,1,1
1,1,1,1,1,1,1,1,1,13,3,3,3,10,1,1,1
1,1,1,1,1,1,1,1,1,1,12,5,12,1,1,1,1
1,1,1,1,1,1,1,1,1,1,1,1,1,1,1,1,1
1,1,1,1,1,1,1,1,1,1,1,1,1,1,1,1,1
1,1,1,1,1,1,1,1,1,1,1,1,1,1,1,1,1
endlayer

layer
1,1,1,1,1,1,1,1,1,1,1,1,1,1,1,1,1
1,1,1,1,1,1,1,1,1,1,1,1,1,1,1,1,1
1,1,1,1,1,1,1,1,1,1,1,20,1,1,1,1,1
1,1,1,1,1,1,1,1,1,1,20,20,20,1,1,1,1
1,1,1,1,1,1,1,1,1,20,3,3,3,20,1,1,1
1,1,1,1,1,1,1,1,20,20,3,3,3,20,20,1,1
1,1,1,1,1,1,1,1,1,20,3,3,3,20,1,1,1
1,1,1,1,1,1,1,1,1,1,20,20,20,1,1,1,1
1,1,1,1,1,1,1,1,1,1,1,20,1,1,1,1,1
1,1,1,1,1,1,1,1,1,1,1,1,1,1,1,1,1
1,1,1,1,1,1,1,1,1,1,1,1,1,1,1,1,1
endlayer

layer
1,1,1,1,1,1,1,1,1,1,1,1,1,1,1,1,1
1,1,1,1,1,1,1,1,1,1,1,1,1,1,1,1,1
1,1,1,1,1,1,1,1,1,1,20,20,20,1,1,1,1
1,1,1,1,1,1,1,1,1,20,3,3,3,20,1,1,1
1,1,1,1,1,1,1,1,20,3,3,3,3,3,20,1,1
1,1,1,1,1,1,1,1,20,3,3,3,3,3,20,1,1
1,1,1,1,1,1,1,1,20,3,3,3,3,3,20,1,1
1,1,1,1,1,1,1,1,1,20,3,3,3,20,1,1,1
1,1,1,1,1,1,1,1,1,1,20,20,20,1,1,1,1
1,1,1,1,1,1,1,1,1,1,1,1,1,1,1,1,1
1,1,1,1,1,1,1,1,1,1,1,1,1,1,1,1,1
endlayer

layer
1,1,1,1,1,1,1,1,1,1,1,1,1,1,1,1,1
1,1,1,1,1,1,1,1,1,1,1,1,1,1,1,1,1
1,1,1,1,1,1,1,1,1,20,20,20,20,20,1,1,1
1,1,1,1,1,1,1,1,20,20,3,3,3,20,20,1,1
1,1,1,1,1,1,1,1,20,3,3,3,3,3,20,1,1
1,1,1,1,1,1,1,1,20,3,3,3,3,3,20,1,1
1,1,1,1,1,1,1,1,20,3,3,3,3,3,20,1,1
1,1,1,1,1,1,1,1,20,20,3,3,3,20,20,1,1
1,1,1,1,1,1,1,1,1,20,20,20,20,20,1,1,1
1,1,1,1,1,1,1,1,1,1,1,1,1,1,1,1,1
1,1,1,1,1,1,1,1,1,1,1,1,1,1,1,1,1
endlayer

layer
1,1,1,1,1,1,1,1,1,1,1,1,1,1,1,1,1
1,1,1,1,1,1,1,1,1,1,1,1,1,1,1,1,1
1,1,1,1,1,1,1,1,1,1,20,20,20,1,1,1,1
1,1,1,1,1,1,1,1,1,20,3,3,3,20,1,1,1
1,1,1,1,1,1,1,1,20,3,3,3,3,3,20,1,1
1,1,1,1,1,1,1,1,20,3,3,3,3,3,20,1,1
1,1,1,1,1,1,1,1,20,3,3,3,3,3,20,1,1
1,1,1,1,1,1,1,1,1,20,3,3,3,20,1,1,1
1,1,1,1,1,1,1,1,1,1,20,20,20,1,1,1,1
1,1,1,1,1,1,1,1,1,1,1,1,1,1,1,1,1
1,1,1,1,1,1,1,1,1,1,1,1,1,1,1,1,1
endlayer

layer
1,1,1,1,1,1,1,1,1,1,1,1,1,1,1,1,1
1,1,1,1,1,1,1,1,1,1,1,1,1,1,1,1,1
1,1,1,1,1,1,1,1,1,20,20,20,1,1,1,1,1
1,1,1,1,1,1,1,1,1,20,20,3,20,20,20,1,1
1,1,1,1,1,1,1,1,1,20,3,3,3,20,20,1,1
1,1,1,1,1,1,1,1,20,3,3,3,3,3,20,1,1
1,1,1,1,1,1,1,1,20,20,3,3,3,20,1,1,1
1,1,1,1,1,1,1,1,20,20,20,3,20,20,1,1,1
1,1,1,1,1,1,1,1,1,1,1,20,20,20,1,1,1
1,1,1,1,1,1,1,1,1,1,1,1,1,1,1,1,1
1,1,1,1,1,1,1,1,1,1,1,1,1,1,1,1,1
endlayer

layer
1,1,1,1,1,1,1,1,1,1,1,1,1,1,1,1,1
1,1,1,1,1,1,1,1,1,1,1,1,1,1,1,1,1
1,1,1,1,1,1,1,1,1,1,20,1,1,1,1,1,1
1,1,1,1,1,1,1,1,1,20,20,20,20,20,1,1,1
1,1,1,1,1,1,1,1,1,20,3,3,3,20,20,1,1
1,1,1,1,1,1,1,1,1,20,3,3,3,20,1,1,1
1,1,1,1,1,1,1,1,20,20,3,3,3,20,1,1,1
1,1,1,1,1,1,1,1,1,20,20,20,20,20,1,1,1
1,1,1,1,1,1,1,1,1,1,1,1,20,1,1,1,1
1,1,1,1,1,1,1,1,1,1,1,1,1,1,1,1,1
1,1,1,1,1,1,1,1,1,1,1,1,1,1,1,1,1
endlayer

layer
1,1,1,1,1,1,1,1,1,1,1,1,1,1,1,1,1
1,1,1,1,1,1,1,1,1,1,1,1,1,1,1,1,1
1,1,1,1,1,1,1,1,1,1,20,1,1,1,1,1,1
1,1,1,1,1,1,1,1,1,1,20,20,20,1,1,1,1
1,1,1,1,1,1,1,1,1,20,20,3,20,20,20,1,1
1,1,1,1,1,1,1,1,1,20,3,3,3,20,1,1,1
1,1,1,1,1,1,1,1,20,20,20,3,20,20,1,1,1
1,1,1,1,1,1,1,1,1,1,20,20,20,1,1,1,1
1,1,1,1,1,1,1,1,1,1,1,1,20,1,1,1,1
1,1,1,1,1,1,1,1,1,1,1,1,1,1,1,1,1
1,1,1,1,1,1,1,1,1,1,1,1,1,1,1,1,1
endlayer

layer
1,1,1,1,1,1,1,1,1,1,1,1,1,1,1,1,1
1,1,1,1,1,1,1,1,1,1,1,1,1,1,1,1,1
1,1,1,1,1,1,1,1,1,1,1,1,1,1,1,1,1
1,1,1,1,1,1,1,1,1,1,20,20,1,1,1,1,1
1,1,1,1,1,1,1,1,1,1,20,3,20,20,1,1,1
1,1,1,1,1,1,1,1,1,20,3,3,3,20,1,1,1
1,1,1,1,1,1,1,1,1,20,20,3,20,1,1,1,1
1,1,1,1,1,1,1,1,1,1,1,20,20,1,1,1,1
1,1,1,1,1,1,1,1,1,1,1,1,1,1,1,1,1
1,1,1,1,1,1,1,1,1,1,1,1,1,1,1,1,1
1,1,1,1,1,1,1,1,1,1,1,1,1,1,1,1,1
endlayer

layer
1,1,1,1,1,1,1,1,1,1,1,1,1,1,1,1,1
1,1,1,1,1,1,1,1,1,1,1,1,1,1,1,1,1
1,1,1,1,1,1,1,1,1,1,1,1,1,1,1,1,1
1,1,1,1,1,1,1,1,1,1,1,1,1,1,1,1,1
1,1,1,1,1,1,1,1,1,1,20,20,20,1,1,1,1
1,1,1,1,1,1,1,1,1,1,20,20,20,1,1,1,1
1,1,1,1,1,1,1,1,1,1,20,20,20,1,1,1,1
1,1,1,1,1,1,1,1,1,1,1,1,1,1,1,1,1
1,1,1,1,1,1,1,1,1,1,1,1,1,1,1,1,1
1,1,1,1,1,1,1,1,1,1,1,1,1,1,1,1,1
1,1,1,1,1,1,1,1,1,1,1,1,1,1,1,1,1
endlayer

layer
1,1,1,1,1,1,1,1,1,1,1,1,1,1,1,1,1
1,1,1,1,1,1,1,1,1,1,1,1,1,1,1,1,1
1,1,1,1,1,1,1,1,1,1,1,1,1,1,1,1,1
1,1,1,1,1,1,1,1,1,1,1,1,1,1,1,1,1
1,1,1,1,1,1,1,1,1,1,1,20,1,1,1,1,1
1,1,1,1,1,1,1,1,1,1,20,20,20,1,1,1,1
1,1,1,1,1,1,1,1,1,1,1,20,1,1,1,1,1
1,1,1,1,1,1,1,1,1,1,1,1,1,1,1,1,1
1,1,1,1,1,1,1,1,1,1,1,1,1,1,1,1,1
1,1,1,1,1,1,1,1,1,1,1,1,1,1,1,1,1
1,1,1,1,1,1,1,1,1,1,1,1,1,1,1,1,1
endlayer

layer
1,1,1,1,1,1,1,1,1,1,1,1,1,1,1,1,1
1,1,1,1,1,1,1,1,1,1,1,1,1,1,1,1,1
1,1,1,1,1,1,1,1,1,1,1,1,1,1,1,1,1
1,1,1,1,1,1,1,1,1,1,1,1,1,1,1,1,1
1,1,1,1,1,1,1,1,1,1,1,1,1,1,1,1,1
1,1,1,1,1,1,1,1,1,1,1,20,1,1,1,1,1
1,1,1,1,1,1,1,1,1,1,1,1,1,1,1,1,1
1,1,1,1,1,1,1,1,1,1,1,1,1,1,1,1,1
1,1,1,1,1,1,1,1,1,1,1,1,1,1,1,1,1
1,1,1,1,1,1,1,1,1,1,1,1,1,1,1,1,1
1,1,1,1,1,1,1,1,1,1,1,1,1,1,1,1,1
endlayer

