
# Created by Ruins mod version 16.7 Ingame Parser
# authoring Player: lafuller

weight=1
embed_into_distance=13
acceptable_target_blocks=water,waterlily
unacceptable_target_blocks=
biomesToSpawnIn=swampland,jungle,marsh,bog,wetland,mini_jungle,lush_swamp,green_swamp,dead_swamp,tropical_island,land_of_lakes
dimensions=22,12,13
allowable_overhang=0
max_leveling=2
leveling_buffer=-1
preserve_water=0
preserve_lava=0

rule1=0,100,preserveBlock
rule2=0,100,minecraft:log2-1
rule3=0,100,minecraft:log2-9
rule4=0,100,minecraft:log2-5
rule5=0,100,minecraft:spruce_fence-0
rule6=0,100,minecraft:ladder-2
rule7=0,100,minecraft:log-3
rule8=0,100,minecraft:log-7
rule9=0,100,minecraft:wooden_slab-9
rule10=0,100,minecraft:spruce_stairs-4
rule11=0,100,minecraft:spruce_stairs-6
rule12=0,100,minecraft:spruce_stairs-7
rule13=0,100,minecraft:spruce_stairs-5
rule14=0,100,minecraft:spruce_stairs-0
rule15=0,100,minecraft:spruce_stairs-3
rule16=0,100,minecraft:spruce_stairs-2
rule17=0,100,minecraft:wooden_slab-1
rule18=0,100,minecraft:trapdoor-4
rule19=0,100,minecraft:spruce_stairs-1
rule20=0,100,minecraft:spruce_fence_gate-3
rule21=0,100,minecraft:spruce_fence_gate-0
rule22=0,100,minecraft:spruce_fence_gate-2
rule23=0,100,minecraft:spruce_fence_gate-1
rule24=0,100,minecraft:wooden_slab-13
rule25=0,100,minecraft:wooden_slab-5
rule26=0,100,minecraft:double_wooden_slab-5
rule27=0,100,minecraft:log-11
rule28=0,100,minecraft:dark_oak_stairs-2
rule29=0,100,minecraft:dark_oak_stairs-7
rule30=0,100,minecraft:dark_oak_stairs-3
rule31=0,100,minecraft:dark_oak_stairs-0
rule32=0,100,minecraft:trapdoor-8
rule33=0,100,minecraft:dark_oak_stairs-1

layer
1,1,1,1,1,1,1,1,1,1,1,1,1
1,1,1,1,1,1,1,1,1,1,1,1,1
1,1,1,1,1,1,1,1,1,1,1,1,1
1,1,1,1,1,1,1,2,1,1,1,1,1
1,1,1,1,1,1,1,1,1,1,1,1,1
1,1,1,2,1,1,1,1,1,1,2,1,1
1,1,1,1,1,1,1,1,1,1,1,1,1
1,1,1,1,1,1,1,1,1,1,1,1,1
1,1,1,1,1,1,2,1,1,1,1,1,1
1,1,1,2,1,1,1,1,1,1,2,1,1
1,1,1,1,1,1,1,1,1,1,1,1,1
1,1,1,1,1,1,1,1,1,1,1,1,1
endlayer

layer
1,1,1,1,1,1,1,1,1,1,1,1,1
1,1,1,1,1,1,1,1,1,1,1,1,1
1,1,1,1,1,1,1,1,1,1,1,1,1
1,1,1,1,1,1,1,2,1,1,1,1,1
1,1,1,1,1,1,1,1,1,1,1,1,1
1,1,1,2,1,1,1,1,1,1,2,1,1
1,1,1,1,1,1,1,1,1,1,1,1,1
1,1,1,1,1,1,1,1,1,1,1,1,1
1,1,1,1,1,1,2,1,1,1,1,1,1
1,1,1,2,1,1,1,1,1,1,2,1,1
1,1,1,1,1,1,1,1,1,1,1,1,1
1,1,1,1,1,1,1,1,1,1,1,1,1
endlayer

layer
1,1,1,1,1,1,1,1,1,1,1,1,1
1,1,1,1,1,1,1,1,1,1,1,1,1
1,1,1,1,1,1,1,1,1,1,1,1,1
1,1,1,1,1,1,1,2,1,1,1,1,1
1,1,1,1,1,1,1,1,1,1,1,1,1
1,1,1,2,1,1,1,1,1,1,2,1,1
1,1,1,1,1,1,1,1,1,1,1,1,1
1,1,1,1,1,1,1,1,1,1,1,1,1
1,1,1,1,1,1,2,1,1,1,1,1,1
1,1,1,2,1,1,1,1,1,1,2,1,1
1,1,1,1,1,1,1,1,1,1,1,1,1
1,1,1,1,1,1,1,1,1,1,1,1,1
endlayer

layer
1,1,1,1,1,1,1,1,1,1,1,1,1
1,1,1,1,1,1,1,1,1,1,1,1,1
1,1,1,1,1,1,1,1,1,1,1,1,1
1,1,1,1,1,1,1,2,1,1,1,1,1
1,1,1,1,1,1,1,1,1,1,1,1,1
1,1,1,2,1,1,1,1,1,1,2,1,1
1,1,1,1,1,1,1,1,1,1,1,1,1
1,1,1,1,1,1,1,1,1,1,1,1,1
1,1,1,1,1,1,2,1,1,1,1,1,1
1,1,1,2,1,1,1,1,1,1,2,1,1
1,1,1,1,1,1,1,1,1,1,1,1,1
1,1,1,1,1,1,1,1,1,1,1,1,1
endlayer

layer
1,1,1,1,1,1,1,1,1,1,1,1,1
1,1,1,1,1,1,1,1,1,1,1,1,1
1,1,1,1,1,1,1,1,1,1,1,1,1
1,1,1,1,1,1,1,2,1,1,1,1,1
1,1,1,1,1,1,1,1,1,1,1,1,1
1,1,1,2,1,1,1,1,1,1,2,1,1
1,1,1,1,1,1,1,1,1,1,1,1,1
1,1,1,1,1,1,1,1,1,1,1,1,1
1,1,1,1,1,1,2,1,1,1,1,1,1
1,1,1,2,1,1,1,1,1,1,2,1,1
1,1,1,1,1,1,1,1,1,1,1,1,1
1,1,1,1,1,1,1,1,1,1,1,1,1
endlayer

layer
1,1,1,1,1,1,1,1,1,1,1,1,1
1,1,1,1,1,1,1,1,1,1,1,1,1
1,1,1,1,1,1,1,1,1,1,1,1,1
1,1,1,1,1,1,1,2,1,1,1,1,1
1,1,1,1,1,1,1,1,1,1,1,1,1
1,1,1,2,1,1,1,1,1,1,2,1,1
1,1,1,1,1,1,1,1,1,1,1,1,1
1,1,1,1,1,1,1,1,1,1,1,1,1
1,1,1,1,1,1,2,1,1,1,1,1,1
1,1,1,2,1,1,1,1,1,1,2,1,1
1,1,1,1,1,1,1,1,1,1,1,1,1
1,1,1,1,1,1,1,1,1,1,1,1,1
endlayer

layer
1,1,1,1,1,1,1,1,1,1,1,1,1
1,1,1,1,1,1,1,1,1,1,1,1,1
1,1,1,1,1,1,1,1,1,1,1,1,1
1,1,1,1,1,1,1,2,1,1,1,1,1
1,1,1,1,1,1,1,1,1,1,1,1,1
1,1,1,2,1,1,1,1,1,1,2,1,1
1,1,1,1,1,1,1,1,1,1,1,1,1
1,1,1,1,1,1,1,1,1,1,1,1,1
1,1,1,1,1,1,2,1,1,1,1,1,1
1,1,1,2,1,1,1,1,1,1,2,1,1
1,1,1,1,1,1,1,1,1,1,1,1,1
1,1,1,1,1,1,1,1,1,1,1,1,1
endlayer

layer
1,1,1,1,1,1,1,1,1,1,1,1,1
1,1,1,1,1,1,1,1,1,1,1,1,1
1,1,1,1,1,1,1,1,1,1,1,1,1
1,1,1,1,1,1,1,2,1,1,1,1,1
1,1,1,1,1,1,1,1,1,1,1,1,1
1,1,1,2,1,1,1,1,1,1,2,1,1
1,1,1,1,1,1,1,1,1,1,1,1,1
1,1,1,1,1,1,1,1,1,1,1,1,1
1,1,1,1,1,1,2,1,1,1,1,1,1
1,1,1,2,1,1,1,1,1,1,2,1,1
1,1,1,1,1,1,1,1,1,1,1,1,1
1,1,1,1,1,1,1,1,1,1,1,1,1
endlayer

layer
1,1,1,1,1,1,1,1,1,1,1,1,1
1,1,1,1,1,1,1,1,1,1,1,1,1
1,1,1,1,1,1,1,1,1,1,1,1,1
1,1,1,1,1,1,1,2,1,1,1,1,1
1,1,1,1,1,1,1,1,1,1,1,1,1
1,1,1,2,1,1,1,1,1,1,2,1,1
1,1,1,1,1,1,1,1,1,1,1,1,1
1,1,1,1,1,1,1,1,1,1,1,1,1
1,1,1,1,1,1,2,1,1,1,1,1,1
1,1,1,2,1,1,1,1,1,1,2,1,1
1,1,1,1,1,1,1,1,1,1,1,1,1
1,1,1,1,1,1,1,1,1,1,1,1,1
endlayer

layer
1,1,1,1,1,1,1,1,1,1,1,1,1
1,1,1,1,1,1,1,1,1,1,1,1,1
1,1,1,1,1,1,1,1,1,1,1,1,1
1,1,1,1,1,1,1,2,1,1,1,1,1
1,1,1,1,1,1,1,1,1,1,1,1,1
1,1,1,2,1,1,1,1,1,1,2,1,1
1,1,1,1,1,1,1,1,1,1,1,1,1
1,1,1,1,1,1,1,1,1,1,1,1,1
1,1,1,1,1,1,2,1,1,1,1,1,1
1,1,1,2,1,1,1,1,1,1,2,1,1
1,1,1,1,1,1,1,1,1,1,1,1,1
1,1,1,1,1,1,1,1,1,1,1,1,1
endlayer

layer
1,1,1,1,1,1,1,1,1,1,1,1,1
1,1,1,1,1,1,1,1,1,1,1,1,1
1,1,1,1,1,1,1,1,1,1,1,1,1
1,1,1,1,1,1,1,2,1,1,1,1,1
1,1,1,1,1,1,1,1,1,1,1,1,1
1,1,1,2,1,1,1,1,1,1,2,1,1
1,1,3,3,3,3,3,3,3,3,3,3,1
1,1,1,1,1,1,1,1,1,1,1,1,1
1,1,1,1,1,1,2,1,1,1,1,1,1
1,1,1,2,1,1,1,1,1,1,2,1,1
1,1,1,1,1,1,1,1,1,1,1,1,1
1,1,1,1,1,1,1,1,1,1,1,1,1
endlayer

layer
1,1,1,1,1,1,1,1,1,1,1,1,1
1,1,1,1,1,1,1,1,1,1,1,1,1
1,1,1,1,1,1,1,1,1,4,1,1,1
1,1,1,4,1,1,1,2,1,4,1,1,1
1,1,1,4,1,1,1,4,1,4,1,1,1
1,1,1,4,1,1,1,4,1,4,2,1,1
1,1,1,4,1,1,1,4,1,4,1,1,1
1,1,1,4,1,1,1,4,1,4,1,1,1
1,1,1,4,1,1,2,4,1,4,1,1,1
1,1,1,4,1,1,1,4,1,4,2,1,1
1,1,1,4,1,1,1,4,1,1,1,1,1
1,1,1,1,1,1,1,1,1,1,1,1,1
endlayer

layer
1,1,1,1,1,1,1,1,1,1,1,1,1
1,1,1,1,1,1,1,1,1,1,1,1,1
1,1,1,1,1,1,1,1,1,1,1,1,1
1,1,1,1,1,1,1,2,1,2,1,1,1
1,3,3,3,3,3,3,3,3,3,3,3,1
1,1,1,2,1,1,1,1,1,1,2,1,1
1,1,1,1,1,1,1,1,1,1,1,1,1
1,1,1,1,1,1,1,1,1,1,1,1,1
1,3,3,3,3,3,3,3,3,3,3,3,1
1,1,1,2,1,1,1,1,1,1,2,1,1
1,1,1,1,1,1,1,1,1,1,1,1,1
1,1,1,1,1,1,1,1,1,1,1,1,1
endlayer

layer
1,1,1,1,1,1,5,1,1,1,1,1,1
1,1,1,1,1,1,4,1,1,1,1,1,1
1,1,5,1,1,1,4,1,1,1,1,1,1
1,1,4,1,1,1,4,2,1,2,1,1,1
1,1,4,1,1,1,4,1,1,1,1,1,1
1,1,4,2,1,1,4,1,1,1,2,1,1
1,1,4,1,1,1,1,1,1,1,1,1,1
1,1,4,1,1,1,1,1,1,1,1,1,1
1,1,4,1,1,1,4,6,1,1,1,1,1
1,1,4,2,1,1,4,1,1,1,2,1,1
1,1,4,1,1,1,4,1,1,1,1,1,1
1,1,5,1,1,1,5,1,1,1,1,1,1
endlayer

layer
1,1,1,1,1,1,1,1,1,1,1,1,1
1,1,1,1,1,1,1,1,1,1,1,1,1
1,1,1,1,1,1,7,1,1,1,1,1,1
5,3,3,3,3,3,3,3,3,3,3,5,1
1,1,1,1,1,1,1,1,1,1,1,1,1
5,3,3,3,3,3,3,3,3,3,3,3,5
1,1,1,1,1,1,1,1,1,1,1,1,1
1,1,1,1,1,1,1,1,1,1,1,1,1
1,1,7,1,1,1,7,6,1,1,1,1,1
5,3,3,3,3,3,3,3,3,3,3,3,5
1,1,1,1,1,1,1,1,1,1,1,1,1
1,1,1,1,1,1,1,1,1,1,1,1,1
endlayer

layer
1,1,1,1,1,5,1,1,5,1,1,1,1
1,1,1,5,1,8,10,9,8,1,1,1,1
1,1,5,8,1,8,7,9,8,9,1,1,1
1,5,5,8,9,8,9,9,8,11,1,1,1
1,1,9,8,9,8,9,9,8,9,1,1,1
1,1,12,8,9,8,9,9,8,7,10,1,1
1,1,9,8,9,8,9,9,8,13,9,1,1
1,1,10,8,9,8,9,9,8,9,9,1,1
1,1,7,8,9,8,7,6,8,9,10,1,1
1,1,9,8,9,8,7,9,8,7,13,1,1
1,1,9,8,9,8,9,9,8,9,1,1,1
1,1,1,5,1,5,1,1,5,1,1,1,1
endlayer

layer
1,1,1,1,1,1,1,1,1,1,1,1,1
1,1,1,1,1,1,15,14,14,1,1,1,1
1,1,1,1,14,14,7,0,0,16,1,1,1
1,1,1,15,0,0,0,0,0,17,1,1,1
1,1,15,7,0,0,0,0,0,16,1,1,1
1,1,15,0,0,0,0,0,0,7,14,1,1
1,1,17,0,0,0,0,0,0,0,16,1,1
1,1,15,0,0,0,0,0,0,0,17,1,1
1,1,7,19,0,19,7,18,0,0,16,1,1
1,1,1,1,1,5,15,0,0,7,19,1,1
1,1,1,1,1,5,5,19,19,5,1,1,1
1,1,1,1,1,1,1,1,1,1,1,1,1
endlayer

layer
1,1,1,1,1,1,1,1,1,1,1,1,1
1,1,1,1,1,1,5,20,5,1,1,1,1
1,1,1,1,5,5,7,0,0,5,1,1,1
1,1,1,5,0,0,0,0,0,21,1,1,1
1,1,5,7,0,0,0,0,0,5,1,1,1
1,1,5,0,0,0,0,0,0,7,1,1,1
1,1,22,0,0,0,0,0,0,0,5,1,1
1,1,5,0,0,0,0,0,0,0,22,1,1
1,1,7,5,23,5,7,0,0,0,5,1,1
1,1,1,1,1,1,5,0,0,7,5,1,1
1,1,1,1,1,1,1,5,5,5,1,1,1
1,1,1,1,1,1,1,1,1,1,1,1,1
endlayer

layer
1,1,1,1,1,1,1,1,1,1,1,1,1
1,1,1,1,1,1,12,10,10,1,1,1,1
1,1,1,1,10,10,7,9,9,11,1,1,1
1,1,1,12,0,0,0,0,0,11,1,1,1
1,1,10,7,0,0,0,0,0,11,1,1,1
1,1,12,0,0,0,0,0,0,7,1,1,1
1,1,12,0,0,0,0,0,0,0,11,1,1
1,1,12,0,0,0,0,0,0,0,11,1,1
1,1,7,0,0,0,7,0,0,0,11,1,1
1,1,5,13,13,13,12,0,0,7,13,1,1
1,1,1,1,1,1,13,13,13,13,1,1,1
1,1,1,1,1,1,1,1,1,1,1,1,1
endlayer

layer
1,1,1,1,1,24,5,5,24,1,1,1,1
1,1,1,1,24,24,8,26,26,25,1,1,1
1,1,1,24,10,10,7,27,27,8,25,1,1
1,1,24,12,5,5,0,0,5,8,25,1,1
1,24,26,7,0,0,0,0,0,8,28,1,1
1,24,12,5,0,0,0,0,0,8,27,5,1
1,5,12,5,0,0,0,0,0,8,25,1,1
1,5,12,5,0,0,0,0,0,8,28,1,1
5,27,7,5,5,5,7,0,0,8,25,1,1
1,5,12,13,13,13,8,27,27,27,27,5,1
1,1,1,1,5,5,8,5,29,26,24,1,1
1,1,1,1,1,1,5,1,1,24,1,1,1
endlayer

layer
1,1,1,1,1,1,25,25,1,1,1,1,1
1,1,1,1,1,25,25,25,1,1,1,1,1
1,1,1,1,25,25,30,28,25,1,1,1,1
1,1,1,25,25,31,26,26,31,25,1,1,1
1,1,25,25,24,24,24,0,0,21,1,1,1
1,25,25,31,24,24,24,0,0,5,1,1,1
1,25,26,26,24,32,24,0,0,21,1,1,1
1,25,25,30,24,24,24,0,0,5,1,1,1
1,25,30,26,26,26,7,0,0,21,1,1,1
1,25,25,26,25,26,26,26,33,25,1,1,1
1,1,25,25,25,26,25,33,25,25,1,1,1
1,1,1,1,25,25,25,25,25,1,1,1,1
endlayer

layer
1,1,1,1,1,1,1,1,1,1,1,1,1
1,1,1,1,1,1,1,1,1,1,1,1,1
1,1,1,1,1,1,1,1,1,1,1,1,1
1,1,1,1,1,1,1,1,1,1,1,1,1
1,1,1,1,1,1,25,25,25,25,1,1,1
1,1,1,1,1,1,25,25,25,25,1,1,1
1,1,1,1,1,1,25,25,25,25,1,1,1
1,1,1,1,1,1,25,25,25,25,1,1,1
1,1,1,1,1,1,25,25,25,25,1,1,1
1,1,1,1,1,1,1,1,1,1,1,1,1
1,1,1,1,1,1,1,1,1,1,1,1,1
1,1,1,1,1,1,1,1,1,1,1,1,1
endlayer

