
# Created by Ruins mod version 16.7 Ingame Parser
# authoring Player: lafuller

weight=1
embed_into_distance=4
acceptable_target_blocks=
unacceptable_target_blocks=flowing_water,water,flowing_lava,lava,ice,bedrock,netherrack,nether_brick,nether_brick_fence,soul_sand,quartz_ore,end_stone,obsidian,iron_bars,cloud,flesh,ash_block,slime_grass,slime_congealed,slime_dirt
biomesToSpawnIn=plains,forest,prarie,meadow,tundra,brushland,shrubland,woodland,woodlands,birch_forestlavender_fields,flower_field,sunflower_plains,ice_flats,ice_plains
dimensions=13,9,10
allowable_overhang=0
max_leveling=4
leveling_buffer=-1
preserve_water=0
preserve_lava=0

rule1=0,100,preserveBlock
rule2=0,100,minecraft:stone-6
rule3=0,100,stonebrick-0,stonebrick-0,stonebrick-0,stonebrick-0,stonebrick-1,stonebrick-2,stonebrick-2,stone-5,stone-6,cobblestone
rule4=0,100,minecraft:dirt-0
rule5=0,100,minecraft:stone_brick_stairs-0
rule6=0,100,minecraft:stone_brick_stairs-3
rule7=0,100,air
rule8=0,100,minecraft:stone-5
rule9=0,100,stonebrick-0,stonebrick-0,stonebrick-0,stonebrick-0,stonebrick-1,stonebrick-2,stonebrick-2,stone-5,stone-6,cobblestone,gravel
rule10=0,100,minecraft:stone_brick_stairs-2
rule11=0,100,minecraft:stone_brick_stairs-7
rule12=0,100,minecraft:stone_brick_stairs-6
rule13=0,100,minecraft:planks-0
rule14=0,100,minecraft:planks-1
rule15=0,100,minecraft:fence-0
rule16=0,100,minecraft:log-0
rule17=0,100,minecraft:oak_stairs-0
rule18=0,100,minecraft:oak_stairs-2
rule19=0,100,minecraft:stone_brick_stairs-5
rule20=0,100,minecraft:oak_stairs-3
rule21=0,100,bookshelf,hay_block,ChestGenHook:chests/spawn_bonus_chest:5-2,ChestGenHook:chests/village_blacksmith:5-2,ChestGenHook:chests/simple_dungeon:5-2,ChestGenHook:chests/abandoned_mineshaft:5-2,ChestGenHook:chests/stronghold_library:5-2,ChestGenHook:chests/stronghold_corridor:5-2,ChestGenHook:chests/stronghold_crossing:5-2,ChestGenHook:chests/igloo_chest:5-2
rule22=0,100,minecraft:oak_stairs-1
rule23=0,100,minecraft:jungle_door-2
rule24=0,100,minecraft:furnace-5
rule25=0,100,minecraft:oak_stairs-7
rule26=0,100,minecraft:oak_stairs-5
rule27=0,100,minecraft:jungle_door-8
rule28=0,100,minecraft:wooden_slab-13
rule29=0,100,minecraft:dark_oak_stairs-6
rule30=0,100,minecraft:spruce_stairs-4
rule31=0,100,minecraft:dark_oak_stairs-7
rule32=0,100,minecraft:spruce_stairs-6
rule33=0,100,minecraft:cobblestone_wall-0
rule34=0,100,minecraft:spruce_stairs-7
rule35=0,100,minecraft:spruce_stairs-5
rule36=0,100,minecraft:spruce_fence_gate-1
rule37=0,100,minecraft:dark_oak_stairs-5
rule38=0,100,minecraft:dark_oak_stairs-1
rule39=0,100,minecraft:wooden_slab-5
rule40=0,100,minecraft:dark_oak_stairs-0
rule41=0,100,minecraft:planks-5
rule42=0,100,minecraft:spruce_stairs-3
rule43=0,100,minecraft:wooden_slab-9
rule44=0,100,minecraft:dark_oak_stairs-2
rule45=0,100,minecraft:dark_oak_stairs-3
rule46=0,100,minecraft:dark_oak_fence-0

layer
1,1,1,1,1,1,1,1,1,1
1,1,1,2,3,3,3,2,1,1
1,1,3,4,4,4,4,3,3,1
1,1,2,4,4,4,4,4,3,1
1,3,4,4,4,4,4,4,3,1
1,3,4,4,4,4,4,4,3,5
1,2,4,4,4,4,4,4,2,3
1,6,3,3,3,2,3,3,3,3
7,6,3,2,1,2,1,2,1,2
endlayer

layer
1,1,1,1,1,1,1,1,1,1
1,1,1,8,9,9,9,8,1,1
1,1,9,4,4,4,4,9,9,1
1,1,8,4,4,4,4,4,9,1
1,9,4,4,4,4,4,4,9,1
1,9,4,4,4,4,4,4,9,1
1,8,4,4,4,4,4,4,8,5
1,1,9,9,9,8,9,9,9,9
1,1,6,9,1,9,1,9,1,9
endlayer

layer
1,1,1,1,1,1,1,1,1,1
1,1,1,2,9,9,9,2,1,1
1,1,9,4,4,4,4,9,9,1
1,1,2,4,4,4,4,4,9,1
1,9,4,4,4,4,4,4,9,1
1,9,4,4,4,4,4,4,9,1
1,2,4,4,4,4,4,4,2,1
1,1,9,9,9,2,9,9,9,5
1,1,1,6,12,9,1,9,11,10
endlayer

layer
1,1,1,1,1,1,1,1,1,1
1,1,1,8,9,9,9,8,1,1
1,1,9,4,4,4,4,9,9,1
1,1,8,4,4,4,4,4,9,1
1,9,4,4,4,4,4,4,9,1
1,9,4,4,4,4,4,4,9,1
1,8,4,4,4,4,4,4,8,1
1,1,9,9,9,8,9,9,10,1
1,1,1,1,6,9,9,9,10,1
endlayer

layer
1,1,1,1,1,1,1,1,1,1
1,1,1,2,3,3,3,2,1,1
1,1,3,13,13,13,13,9,3,1
1,1,2,14,14,14,14,13,3,1
1,3,13,14,13,13,14,13,3,1
1,3,13,14,14,14,14,13,3,1
1,2,13,13,13,13,13,13,2,1
1,1,3,3,3,2,9,3,1,1
1,1,1,1,1,6,9,10,1,1
endlayer

layer
1,1,1,1,1,1,1,1,1,1
1,1,15,16,17,17,17,16,15,1
1,1,20,7,7,7,7,19,18,1
1,15,16,7,7,7,7,7,18,1
1,20,7,7,7,7,7,7,18,1
1,20,7,7,7,7,7,7,18,1
1,16,21,7,7,7,7,7,16,1
1,15,22,22,22,16,23,22,1,1
1,1,1,1,1,1,7,1,1,1
endlayer

layer
1,1,1,1,1,1,1,1,1,1
1,1,15,16,15,7,15,16,15,1
1,1,25,7,7,7,7,24,15,1
1,15,16,7,7,7,7,7,7,1
1,7,7,7,7,7,7,7,15,1
1,15,7,7,7,7,7,7,15,1
1,16,7,7,7,7,7,7,16,1
1,15,15,7,15,16,27,26,1,1
1,1,1,1,1,1,7,1,1,1
endlayer

layer
1,1,28,1,1,1,1,1,28,1
1,1,31,16,30,30,30,16,29,28
1,31,14,7,7,7,7,33,32,1
1,28,16,7,7,7,7,7,32,1
1,34,7,7,7,7,7,7,32,1
1,34,7,7,7,7,7,7,32,1
1,16,7,7,7,7,7,7,16,28
38,37,35,35,35,16,36,35,28,1
1,28,1,1,1,1,7,1,28,1
endlayer

layer
1,1,1,39,28,28,28,39,1,1
1,1,40,16,41,41,41,16,40,1
1,1,42,35,35,35,35,33,41,39
39,40,16,43,7,7,7,34,41,28
28,41,32,7,7,7,7,34,41,28
28,41,32,7,7,7,43,34,41,39
39,16,30,30,30,30,30,34,41,1
1,45,41,41,41,16,41,41,44,1
1,39,29,28,28,28,37,44,1,1
endlayer

layer
1,1,1,1,1,1,1,1,1,1
1,1,1,39,40,40,40,39,1,1
1,1,40,41,41,41,41,41,39,1
1,1,45,41,14,14,14,41,44,1
1,39,41,14,14,14,14,41,44,1
1,45,41,14,14,14,41,41,38,1
1,45,41,41,41,41,41,38,1,1
1,1,38,45,44,44,38,44,1,1
1,1,1,38,38,39,1,1,1,1
endlayer

layer
1,1,1,1,1,1,1,1,1,1
1,1,1,1,1,1,1,1,1,1
1,1,1,46,46,46,46,33,1,1
1,1,1,46,39,39,39,46,1,1
1,1,46,39,39,39,39,46,1,1
1,1,46,39,39,39,46,46,1,1
1,1,46,46,46,46,46,1,1,1
1,1,1,1,1,1,1,1,1,1
1,1,1,1,1,1,1,1,1,1
endlayer

layer
1,1,1,1,1,1,1,1,1,1
1,1,1,1,1,1,1,1,1,1
1,1,1,1,1,1,1,33,1,1
1,1,1,1,1,1,1,1,1,1
1,1,1,1,1,1,1,1,1,1
1,1,1,1,1,1,1,1,1,1
1,1,1,1,1,1,1,1,1,1
1,1,1,1,1,1,1,1,1,1
1,1,1,1,1,1,1,1,1,1
endlayer

layer
1,1,1,1,1,1,1,1,1,1
1,1,1,1,1,1,1,1,1,1
1,1,1,1,1,1,1,33,1,1
1,1,1,1,1,1,1,1,1,1
1,1,1,1,1,1,1,1,1,1
1,1,1,1,1,1,1,1,1,1
1,1,1,1,1,1,1,1,1,1
1,1,1,1,1,1,1,1,1,1
1,1,1,1,1,1,1,1,1,1
endlayer

