# Gilly's Plaza water feature

weight=1
embed_into_distance=5
unacceptable_target_blocks=flowing_water,water,flowing_lava,lava,ice,bedrock,netherrack,nether_brick,nether_brick_fence,soul_sand,quartz_ore,end_stone,obsidian,iron_bars,cloud,flesh,ash_block,slime_grass,slime_congealed,slime_dirt
dimensions=7,15,15
max_leveling=5
leveling_buffer=-1
preserve_water=0
preserve_lava=0
preserve_plants=0

rule1=0,100,preserveBlock
rule2=0,100,stonebrick,stonebrick,stonebrick,stonebrick,stonebrick,stonebrick-2,stonebrick-2
rule3=0,100,double_stone_slab
rule4=0,100,stained_hardened_clay-9
rule5=0,100,stone_slab-5
rule6=0,100,stone_brick_stairs
rule7=0,100,stone_brick_stairs-1
rule8=0,100,stone_brick_stairs-2
rule9=0,100,stone_brick_stairs-3

rule10=0,100,flowing_water
rule11=0,100,glowstone
rule12=0,100,stained_glass_pane-3

layer
2,2,2,2,2,2,2,2,2,2,2,2,2,2,2
2,2,2,2,2,2,2,2,2,2,2,2,2,2,2
2,2,2,2,2,2,2,2,2,2,2,2,2,2,2
2,2,2,2,2,2,2,2,2,2,2,2,2,2,2
2,2,2,2,2,2,2,2,2,2,2,2,2,2,2
2,2,2,2,2,2,2,2,2,2,2,2,2,2,2
2,2,2,2,2,2,2,2,2,2,2,2,2,2,2
2,2,2,2,2,2,2,2,2,2,2,2,2,2,2
2,2,2,2,2,2,2,2,2,2,2,2,2,2,2
2,2,2,2,2,2,2,2,2,2,2,2,2,2,2
2,2,2,2,2,2,2,2,2,2,2,2,2,2,2
2,2,2,2,2,2,2,2,2,2,2,2,2,2,2
2,2,2,2,2,2,2,2,2,2,2,2,2,2,2
2,2,2,2,2,2,2,2,2,2,2,2,2,2,2
2,2,2,2,2,2,2,2,2,2,2,2,2,2,2
endlayer

layer
2,2,2,2,2,2,2,2,2,2,2,2,2,2,2
2,2,2,2,2,2,2,2,2,2,2,2,2,2,2
2,2,2,2,2,2,2,2,2,2,2,2,2,2,2
2,2,2,2,2,2,2,2,2,2,2,2,2,2,2
2,2,2,2,2,2,2,2,2,2,2,2,2,2,2
2,2,2,2,2,2,2,2,2,2,2,2,2,2,2
2,2,2,2,2,2,2,2,2,2,2,2,2,2,2
2,2,2,2,2,2,2,2,2,2,2,2,2,2,2
2,2,2,2,2,2,2,2,2,2,2,2,2,2,2
2,2,2,2,2,2,2,2,2,2,2,2,2,2,2
2,2,2,2,2,2,2,2,2,2,2,2,2,2,2
2,2,2,2,2,2,2,2,2,2,2,2,2,2,2
2,2,2,2,2,2,2,2,2,2,2,2,2,2,2
2,2,2,2,2,2,2,2,2,2,2,2,2,2,2
2,2,2,2,2,2,2,2,2,2,2,2,2,2,2
endlayer

layer
2,2,2,2,2,2,2,2,2,2,2,2,2,2,2
2,2,2,2,2,2,2,2,2,2,2,2,2,2,2
2,2,2,2,2,2,2,2,2,2,2,2,2,2,2
2,2,2,2,2,2,2,2,2,2,2,2,2,2,2
2,2,2,2,2,2,2,2,2,2,2,2,2,2,2
2,2,2,2,2,2,2,2,2,2,2,2,2,2,2
2,2,2,2,2,2,2,2,2,2,2,2,2,2,2
2,2,2,2,2,2,2,2,2,2,2,2,2,2,2
2,2,2,2,2,2,2,2,2,2,2,2,2,2,2
2,2,2,2,2,2,2,2,2,2,2,2,2,2,2
2,2,2,2,2,2,2,2,2,2,2,2,2,2,2
2,2,2,2,2,2,2,2,2,2,2,2,2,2,2
2,2,2,2,2,2,2,2,2,2,2,2,2,2,2
2,2,2,2,2,2,2,2,2,2,2,2,2,2,2
2,2,2,2,2,2,2,2,2,2,2,2,2,2,2
endlayer

layer
2,2,2,2,2,2,2,2,2,2,2,2,2,2,2
2,2,0,2,2,2,2,2,2,2,2,2,0,2,2
2,0,11,2,2,2,2,0,2,2,2,2,11,0,2
2,2,2,2,2,2,2,11,2,2,2,2,2,2,2
2,2,2,2,2,2,2,2,2,2,2,2,2,2,2
2,2,2,2,2,2,2,2,2,2,2,2,2,2,2
2,2,2,2,2,2,2,2,2,2,2,2,2,2,2
2,2,0,11,2,2,2,2,2,2,2,11,0,2,2
2,2,2,2,2,2,2,2,2,2,2,2,2,2,2
2,2,2,2,2,2,2,2,2,2,2,2,2,2,2
2,2,2,2,2,2,2,2,2,2,2,2,2,2,2
2,2,2,2,2,2,2,11,2,2,2,2,2,2,2
2,0,11,2,2,2,2,0,2,2,2,2,11,0,2
2,2,0,2,2,2,2,2,2,2,2,2,0,2,2
2,2,2,2,2,2,2,2,2,2,2,2,2,2,2
endlayer

layer
2,2,2,2,2,6,6,2,6,6,2,2,2,2,2
2,12,12,12,12,12,0,0,0,12,12,12,12,12,2
2,12,6,6,8,12,12,12,12,12,9,6,6,12,2
2,12,9,4,6,6,6,6,6,6,6,4,8,12,2
2,12,7,9,3,3,2,4,2,3,3,8,7,12,2
9,12,12,9,3,4,4,2,4,4,3,8,12,12,8
9,0,12,9,2,4,4,2,4,4,2,8,12,0,8
2,0,12,9,4,2,2,3,2,2,4,8,12,0,2
9,0,12,9,2,4,4,2,4,4,2,8,12,0,8
9,12,12,9,3,4,4,2,4,4,3,8,12,12,8
2,12,6,9,3,3,2,4,2,3,3,8,6,12,2
2,12,9,4,7,7,7,7,7,7,7,4,8,12,2
2,12,7,7,8,12,12,12,12,12,9,7,7,12,2
2,12,12,12,12,12,0,0,0,12,12,12,12,12,2
2,2,2,2,2,7,7,2,7,7,2,2,2,2,2
endlayer

layer
1,1,1,5,2,8,6,2,6,9,2,5,1,1,1
1,9,6,6,2,0,0,0,0,0,2,6,6,8,1
1,9,10,10,10,2,2,2,2,2,10,10,10,8,1
5,9,10,10,10,10,10,10,10,10,10,10,10,8,5
2,2,10,10,10,10,10,10,10,10,10,10,10,2,2
7,0,2,10,10,10,10,10,10,10,10,10,2,0,7
9,0,2,10,10,10,10,10,10,10,10,10,2,0,8
2,0,2,10,10,10,10,10,10,10,10,10,2,0,2
9,0,2,10,10,10,10,10,10,10,10,10,2,0,8
6,0,2,10,10,10,10,10,10,10,10,10,2,0,6
2,2,10,10,10,10,10,10,10,10,10,10,10,2,2
5,9,10,10,10,10,10,10,10,10,10,10,10,8,5
1,9,10,10,10,2,2,2,2,2,10,10,10,8,1
1,9,7,7,2,0,0,0,0,0,2,7,7,8,1
1,1,1,5,2,8,7,2,7,9,2,5,1,1,1
endlayer

layer
0,0,0,0,0,5,2,2,2,5,0,0,0,0,0
0,0,0,0,0,5,5,5,5,5,0,0,0,0,0
0,0,0,0,0,0,0,0,0,0,0,0,0,0,0
0,0,0,0,0,0,0,0,0,0,0,0,0,0,0
0,0,0,0,0,0,0,0,0,0,0,0,0,0,0
5,5,0,0,0,0,0,0,0,0,0,0,0,5,5
2,5,0,0,0,0,0,0,0,0,0,0,0,5,2
2,5,0,0,0,0,0,0,0,0,0,0,0,5,2
2,5,0,0,0,0,0,0,0,0,0,0,0,5,2
5,5,0,0,0,0,0,0,0,0,0,0,0,5,5
0,0,0,0,0,0,0,0,0,0,0,0,0,0,0
0,0,0,0,0,0,0,0,0,0,0,0,0,0,0
0,0,0,0,0,0,0,0,0,0,0,0,0,0,0
0,0,0,0,0,5,5,5,5,5,0,0,0,0,0
0,0,0,0,0,5,2,2,2,5,0,0,0,0,0
endlayer








