
# Created by Ruins mod version 16.7 Ingame Parser
# authoring Player: lafuller

weight=1
embed_into_distance=13
acceptable_target_blocks=water,waterlily
unacceptable_target_blocks=
biomesToSpawnIn=swampland,jungle,marsh,bog,wetland,mini_jungle,lush_swamp,green_swamp,dead_swamp,tropical_island,land_of_lakes
dimensions=23,11,11
allowable_overhang=0
max_leveling=2
leveling_buffer=-1
preserve_water=0
preserve_lava=0

rule1=0,100,preserveBlock
rule2=0,100,minecraft:log2-1
rule3=0,100,minecraft:log2-5
rule4=0,100,minecraft:log2-9
rule5=0,100,minecraft:spruce_fence-0
rule6=0,100,minecraft:ladder-2
rule7=0,100,minecraft:log-3
rule8=0,100,minecraft:log-7
rule9=0,100,minecraft:wooden_slab-9
rule10=0,100,minecraft:spruce_stairs-4
rule11=0,100,minecraft:spruce_stairs-5
rule12=0,100,minecraft:spruce_stairs-0
rule13=0,100,minecraft:planks-1
rule14=0,100,minecraft:trapdoor-4
rule15=0,100,minecraft:spruce_stairs-2
rule16=0,100,minecraft:spruce_stairs-3
rule17=0,100,minecraft:ladder-3
rule18=0,100,minecraft:spruce_stairs-1
rule19=0,100,minecraft:spruce_fence_gate-2
rule20=0,100,minecraft:spruce_fence_gate-3
rule21=0,100,minecraft:spruce_fence_gate-0
rule22=0,100,minecraft:spruce_stairs-7
rule23=0,100,minecraft:spruce_stairs-6
rule24=0,100,minecraft:dark_oak_stairs-4
rule25=0,100,minecraft:wooden_slab-1
rule26=0,100,minecraft:carpet-7
rule27=0,100,minecraft:carpet-8
rule28=0,100,minecraft:wooden_slab-13
rule29=0,100,minecraft:dark_oak_stairs-6
rule30=0,100,minecraft:wooden_slab-5
rule31=0,100,minecraft:dark_oak_stairs-0
rule32=0,100,minecraft:double_wooden_slab-5
rule33=0,100,minecraft:spruce_fence_gate-1
rule34=0,100,minecraft:dark_oak_fence-0
rule35=0,100,minecraft:dark_oak_stairs-2
rule36=0,100,minecraft:dark_oak_stairs-1
rule37=0,100,minecraft:dark_oak_stairs-3

layer
1,1,1,1,1,1,1,1,1,1,1
1,1,1,1,1,1,1,1,1,1,1
1,1,2,1,1,1,1,2,1,1,1
1,1,1,1,1,1,1,1,1,1,1
1,1,1,1,1,1,1,1,1,1,1
1,1,1,1,1,1,1,1,2,1,1
1,1,1,1,1,1,1,1,1,1,1
1,1,1,1,1,1,1,1,1,1,1
1,1,1,2,1,1,1,2,1,1,1
1,1,1,1,1,1,1,1,1,1,1
1,1,1,1,1,1,1,1,1,1,1
endlayer

layer
1,1,1,1,1,1,1,1,1,1,1
1,1,1,1,1,1,1,1,1,1,1
1,1,2,1,1,1,1,2,1,1,1
1,1,1,1,1,1,1,1,1,1,1
1,1,1,1,1,1,1,1,1,1,1
1,1,1,1,1,1,1,1,2,1,1
1,1,1,1,1,1,1,1,1,1,1
1,1,1,1,1,1,1,1,1,1,1
1,1,1,2,1,1,1,2,1,1,1
1,1,1,1,1,1,1,1,1,1,1
1,1,1,1,1,1,1,1,1,1,1
endlayer

layer
1,1,1,1,1,1,1,1,1,1,1
1,1,1,1,1,1,1,1,1,1,1
1,1,2,1,1,1,1,2,1,1,1
1,1,1,1,1,1,1,1,1,1,1
1,1,1,1,1,1,1,1,1,1,1
1,1,1,1,1,1,1,1,2,1,1
1,1,1,1,1,1,1,1,1,1,1
1,1,1,1,1,1,1,1,1,1,1
1,1,1,2,1,1,1,2,1,1,1
1,1,1,1,1,1,1,1,1,1,1
1,1,1,1,1,1,1,1,1,1,1
endlayer

layer
1,1,1,1,1,1,1,1,1,1,1
1,1,1,1,1,1,1,1,1,1,1
1,1,2,1,1,1,1,2,1,1,1
1,1,1,1,1,1,1,1,1,1,1
1,1,1,1,1,1,1,1,1,1,1
1,1,1,1,1,1,1,1,2,1,1
1,1,1,1,1,1,1,1,1,1,1
1,1,1,1,1,1,1,1,1,1,1
1,1,1,2,1,1,1,2,1,1,1
1,1,1,1,1,1,1,1,1,1,1
1,1,1,1,1,1,1,1,1,1,1
endlayer

layer
1,1,1,1,1,1,1,1,1,1,1
1,1,1,1,1,1,1,1,1,1,1
1,1,2,1,1,1,1,2,1,1,1
1,1,1,1,1,1,1,1,1,1,1
1,1,1,1,1,1,1,1,1,1,1
1,1,1,1,1,1,1,1,2,1,1
1,1,1,1,1,1,1,1,1,1,1
1,1,1,1,1,1,1,1,1,1,1
1,1,1,2,1,1,1,2,1,1,1
1,1,1,1,1,1,1,1,1,1,1
1,1,1,1,1,1,1,1,1,1,1
endlayer

layer
1,1,1,1,1,1,1,1,1,1,1
1,1,1,1,1,1,1,1,1,1,1
1,1,2,1,1,1,1,2,1,1,1
1,1,1,1,1,1,1,1,1,1,1
1,1,1,1,1,1,1,1,1,1,1
1,1,1,1,1,1,1,1,2,1,1
1,1,1,1,1,1,1,1,1,1,1
1,1,1,1,1,1,1,1,1,1,1
1,1,1,2,1,1,1,2,1,1,1
1,1,1,1,1,1,1,1,1,1,1
1,1,1,1,1,1,1,1,1,1,1
endlayer

layer
1,1,1,1,1,1,1,1,1,1,1
1,1,1,1,1,1,1,1,1,1,1
1,1,2,1,1,1,1,2,1,1,1
1,1,1,1,1,1,1,1,1,1,1
1,1,1,1,1,1,1,1,1,1,1
1,1,1,1,1,1,1,1,2,1,1
1,1,1,1,1,1,1,1,1,1,1
1,1,1,1,1,1,1,1,1,1,1
1,1,1,2,1,1,1,2,1,1,1
1,1,1,1,1,1,1,1,1,1,1
1,1,1,1,1,1,1,1,1,1,1
endlayer

layer
1,1,1,1,1,1,1,1,1,1,1
1,1,1,1,1,1,1,1,1,1,1
1,1,2,1,1,1,1,2,1,1,1
1,1,1,1,1,1,1,1,1,1,1
1,1,1,1,1,1,1,1,1,1,1
1,1,1,1,1,1,1,1,2,1,1
1,1,1,1,1,1,1,1,1,1,1
1,1,1,1,1,1,1,1,1,1,1
1,1,1,2,1,1,1,2,1,1,1
1,1,1,1,1,1,1,1,1,1,1
1,1,1,1,1,1,1,1,1,1,1
endlayer

layer
1,1,1,1,1,1,1,1,1,1,1
1,1,1,1,1,1,1,1,1,1,1
1,1,2,1,1,1,1,2,1,1,1
1,1,1,1,1,1,1,1,1,1,1
1,1,1,1,1,1,1,1,1,1,1
1,1,1,1,1,1,1,1,2,1,1
1,1,1,1,1,1,1,1,1,1,1
1,1,1,1,1,1,1,1,1,1,1
1,1,1,2,1,1,1,2,1,1,1
1,1,1,1,1,1,1,1,1,1,1
1,1,1,1,1,1,1,1,1,1,1
endlayer

layer
1,1,1,1,1,1,1,1,1,1,1
1,1,1,1,1,1,1,1,1,1,1
1,1,2,1,1,1,1,2,1,1,1
1,1,1,1,1,1,1,1,1,1,1
1,1,1,1,1,1,1,1,1,1,1
1,1,1,1,1,1,1,1,2,1,1
1,1,1,1,1,1,1,1,1,1,1
1,1,1,1,1,1,1,1,1,1,1
1,1,1,2,1,1,1,2,1,1,1
1,1,1,1,1,1,1,1,1,1,1
1,1,1,1,1,1,1,1,1,1,1
endlayer

layer
1,1,1,1,1,1,1,1,1,1,1
1,1,1,1,1,1,1,1,1,1,1
1,1,2,1,1,1,1,2,1,1,1
1,1,1,1,1,1,1,1,1,1,1
1,1,1,1,1,1,1,1,1,1,1
1,1,1,1,1,1,1,1,2,1,1
1,1,1,1,1,1,1,1,1,1,1
1,1,1,1,1,1,1,1,1,1,1
1,1,1,2,1,1,1,2,1,1,1
1,1,1,1,1,1,1,1,1,1,1
1,1,1,1,1,1,1,1,1,1,1
endlayer

layer
1,1,1,1,1,1,1,1,1,1,1
1,1,1,3,1,1,1,1,1,1,1
1,1,2,3,1,1,1,2,1,1,1
1,1,1,3,1,1,1,1,1,1,1
1,1,1,3,1,1,1,1,1,1,1
1,1,1,3,1,1,1,1,2,1,1
1,1,1,3,1,1,1,1,1,1,1
1,1,1,3,1,1,1,1,1,1,1
1,1,1,2,1,1,1,2,1,1,1
1,1,1,1,1,1,1,1,1,1,1
1,1,1,1,1,1,1,1,1,1,1
endlayer

layer
1,1,1,1,1,1,1,1,1,1,1
1,1,1,1,1,1,1,1,1,1,1
1,1,2,1,1,1,1,2,1,1,1
1,4,4,4,4,4,4,4,4,4,1
1,1,1,1,1,1,1,1,1,1,1
1,1,1,1,1,1,1,1,2,1,1
1,1,1,1,1,1,1,1,1,1,1
1,4,4,4,4,4,4,4,4,4,1
1,1,1,2,1,1,1,2,1,1,1
1,1,1,1,1,1,1,1,1,1,1
1,1,1,1,1,1,1,1,1,1,1
endlayer

layer
1,1,1,1,1,1,5,1,1,1,1
1,1,1,1,1,1,3,1,5,1,1
1,1,2,1,1,1,3,2,3,1,1
1,1,2,6,1,1,3,1,3,1,1
1,1,1,1,1,1,3,1,3,1,1
1,1,1,1,1,1,3,1,2,1,1
1,1,3,1,1,1,3,1,3,1,1
1,1,3,1,1,1,3,1,3,1,1
1,1,3,2,1,1,3,2,3,1,1
1,1,3,1,1,1,3,1,3,1,1
1,1,5,1,1,1,5,1,5,1,1
endlayer

layer
1,1,1,1,1,1,1,1,1,1,1
1,1,5,1,1,1,1,1,1,1,1
5,4,4,4,4,4,4,4,4,4,5
1,1,7,6,1,1,1,1,1,1,1
1,1,1,1,1,1,1,1,1,1,1
1,1,1,1,1,1,1,1,7,1,1
5,4,4,4,4,4,4,4,4,4,5
1,1,1,1,1,1,1,1,1,1,1
5,4,4,4,4,4,4,4,4,4,5
1,1,1,1,1,1,1,1,1,1,1
1,1,1,1,1,1,1,1,1,1,1
endlayer

layer
1,1,1,5,1,5,1,1,1,1,1
1,5,5,8,1,8,1,5,1,1,1
1,5,5,8,9,8,7,8,1,1,1
1,1,7,6,9,8,9,8,9,1,1
1,1,9,9,9,8,9,8,10,1,1
1,9,10,9,9,8,9,8,7,5,1
1,9,11,8,9,8,9,8,10,9,1
1,9,9,8,9,8,9,8,9,9,1
1,9,9,8,7,8,9,8,11,9,1
1,1,9,8,1,8,1,8,1,1,1
1,1,1,5,1,5,1,5,1,1,1
endlayer

layer
1,1,1,1,1,1,1,1,1,1,1
1,1,1,1,1,1,1,1,1,1,1
1,1,1,12,12,12,7,1,1,1,1
1,1,7,14,0,0,0,13,1,1,1
1,1,16,0,0,0,0,0,15,1,1
1,1,16,0,0,0,0,17,7,5,1
1,1,18,7,0,0,0,0,0,15,1
1,1,1,19,0,0,0,0,0,15,1
1,1,1,16,7,18,18,7,18,1,1
1,1,1,1,1,1,1,1,1,1,1
1,1,1,1,1,1,1,1,1,1,1
endlayer

layer
1,1,1,1,1,1,1,1,1,1,1
1,1,1,1,1,1,1,1,1,1,1
1,1,5,5,20,5,7,5,1,1,1
1,1,7,0,0,0,0,5,5,1,1
1,1,5,0,0,0,0,0,5,5,1
1,1,19,0,0,0,0,17,7,5,1
1,1,5,7,0,0,0,0,0,21,1
1,1,1,0,0,0,0,0,0,1,1
1,1,1,5,7,5,5,7,5,1,1
1,1,1,1,5,1,1,1,1,1,1
1,1,1,1,1,1,1,1,1,1,1
endlayer

layer
1,1,1,1,1,1,1,1,1,1,1
1,1,1,1,1,1,1,1,1,1,1
1,1,5,10,10,10,7,10,1,1,1
1,1,7,0,0,0,0,11,9,1,1
1,1,22,0,0,0,0,0,22,15,1
1,1,22,0,0,0,0,17,7,23,1
1,1,11,7,9,9,9,9,9,23,1
1,1,9,22,9,9,9,9,9,23,1
1,1,1,11,7,11,11,7,11,1,1
1,1,1,1,22,9,9,11,1,1,1
1,1,1,1,1,1,1,1,1,1,1
endlayer

layer
1,1,1,1,1,1,1,1,1,1,1
1,1,1,1,1,1,24,1,1,1,1
1,1,22,12,12,12,7,10,1,1,1
1,1,7,0,0,0,0,15,1,1,1
1,1,16,0,0,0,0,0,12,15,1
1,1,16,0,0,0,0,0,7,25,1
1,1,16,7,27,26,26,0,0,15,1
1,1,1,16,27,26,26,0,0,15,1
1,1,1,5,7,18,18,7,18,1,1
1,1,1,1,1,1,25,18,1,1,1
1,1,1,1,1,1,1,1,1,1,1
endlayer

layer
1,1,1,1,1,1,1,1,1,1,1
1,1,31,30,24,29,24,28,1,1,1
1,28,32,32,32,32,32,32,28,1,1
1,28,32,5,33,33,5,23,1,1,1
1,28,9,0,0,0,0,0,10,1,1
1,1,10,0,0,0,0,0,7,5,1
1,1,5,7,0,0,0,0,0,21,1
1,1,1,19,0,0,0,0,0,5,1
1,1,1,5,7,33,33,7,0,1,1
1,1,1,1,1,1,1,5,1,1,1
1,1,1,1,1,1,1,1,1,1,1
endlayer

layer
1,1,1,1,1,1,1,1,1,1,1
1,1,1,1,1,30,1,1,1,1,1
1,1,1,30,30,30,31,30,30,1,1
1,1,30,30,32,30,32,32,31,30,1
1,30,31,28,28,28,28,28,32,32,1
1,30,32,28,28,28,28,28,7,23,28
1,28,32,7,0,0,0,0,0,23,28
1,1,34,22,0,0,0,0,0,23,28
1,1,1,28,7,11,11,7,11,28,1
1,1,1,1,5,1,1,5,1,1,1
1,1,1,1,1,1,1,1,1,1,1
endlayer

layer
1,1,1,1,1,1,1,1,1,1,1
1,1,1,1,1,1,1,1,1,1,1
1,1,1,1,1,1,1,1,1,1,1
1,1,1,1,1,1,1,1,1,1,1
1,1,1,1,1,1,30,1,30,1,1
1,1,1,30,1,30,30,30,30,30,1
1,1,1,30,30,30,32,30,32,30,30
1,1,30,30,32,31,32,32,32,35,30
1,1,30,30,37,32,32,36,30,30,30
1,1,1,30,30,30,30,30,30,1,1
1,1,1,1,1,1,1,1,1,1,1
endlayer

