# Gilly's House/Kitchen

# template generated by Ruins mod version 14.6 Ingame Parser
# Structure created by Gilly

weight=1
embed_into_distance=3
acceptable_target_blocks=
unacceptable_target_blocks=flowing_water,water,flowing_lava,lava,ice,bedrock,netherrack,nether_brick,nether_brick_fence,soul_sand,quartz_ore,end_stone,obsidian,iron_bars,cloud,flesh,ash_block,slime_grass,slime_congealed,slime_dirt
dimensions=19,15,14
allowable_overhang=0
max_leveling=3
leveling_buffer=-1
preserve_water=0
preserve_lava=0

rule1=0,100,double_stone_slab-8
rule2=0,100,stonebrick,stonebrick,stonebrick,stonebrick,stonebrick-2,stonebrick-2,stonebrick-1,stone-5,stone-6,cobblestone,gravel
rule3=0,100,cobblestone_wall-0
rule4=0,100,preserveBlock
rule5=0,100,hardened_clay-0
rule6=0,100,stained_hardened_clay-6
rule7=0,100,mycelium-0
rule8=0,100,lit_pumpkin-1
rule9=0,100,log-0
rule10=0,100,sandstone-2
rule11=0,100,bookshelf-0
rule12=0,100,planks-0
rule13=0,100,fence-0
rule14=0,100,fence_gate-0
rule15=0,100,fence_gate-2
rule16=0,100,oak_stairs-2
rule17=0,100,oak_stairs-1
rule18=0,100,spruce_stairs-5
rule19=0,100,wooden_slab-9
rule20=0,100,spruce_stairs-4
rule21=0,100,wooden_door-2
rule22=0,100,cauldron-0
rule23=0,100,hopper-2
rule24=0,100,planks-2
rule25=0,100,carpet-8
rule26=0,100,carpet-9
rule27=0,100,cake-0
rule28=0,100,IInventory;furnace;coal#2#0#1-3
rule29=0,100,wooden_door-9
rule30=0,100,wooden_door-8
rule31=0,100,iron_bars-0
rule32=0,100,oak_stairs-6
rule33=0,100,oak_stairs-3
rule34=2,100,torch-4
rule35=2,100,torch-1
rule36=2,100,torch-3
rule37=0,100,ladder-3
rule38=0,100,tripwire_hook-1
rule39=0,100,stone_slab-13
rule40=0,100,stone_brick_stairs-2
rule41=0,100,stone_brick_stairs-7
rule42=0,100,stone_brick_stairs-5
rule43=0,100,stone_brick_stairs-6
rule44=0,100,log-8
rule45=0,100,log-4
rule46=0,100,oak_stairs-0
rule47=0,100,planks-1
rule48=0,100,ChestGenHook:chests/spawn_bonus_chest:4-3
rule49=0,100,bed-3
rule50=0,100,wooden_door-3
rule51=0,100,bed-11
rule52=0,100,carpet-7
rule53=0,100,stone_brick_stairs-1
rule54=0,100,wooden_slab-5
rule55=0,100,planks-5
rule56=0,100,stone_brick_stairs-0
rule57=0,100,stone_brick_stairs-3
rule58=0,100,dark_oak_fence
rule59=0,100,stone_brick_stairs-4
rule60=0,100,stone_slab-0
rule61=0,100,double_stone_slab-9
rule62=0,100,ChestGenHook:chests/stronghold_library:4-3

layer
4,4,4,4,4,4,4,1,2,3,2,3,2,1
4,4,4,1,2,3,2,2,4,4,4,4,4,2
4,4,4,2,4,4,4,4,4,4,4,4,4,3
4,4,4,3,4,4,4,4,4,4,4,4,4,2
4,4,4,2,4,4,4,4,4,4,4,4,4,2
4,1,2,2,4,4,4,4,4,4,4,4,4,3
4,2,4,4,4,4,4,4,4,4,4,4,4,2
4,3,4,4,4,4,4,4,4,4,4,4,2,1
4,2,4,4,4,4,4,4,4,4,4,4,2,4
4,3,4,4,4,4,4,4,4,4,4,4,2,4
2,2,4,4,4,4,4,4,4,4,4,2,2,2
2,1,2,2,2,2,2,4,4,4,2,2,2,2
2,2,2,2,2,2,2,4,4,4,2,2,2,2
2,2,2,2,2,2,1,2,3,2,2,2,2,2
2,2,2,2,2,2,2,2,4,4,4,4,4,4
endlayer

layer
4,4,4,4,4,4,4,1,2,3,2,3,2,1
4,4,4,1,2,3,2,2,4,4,4,4,4,2
4,4,4,2,4,4,4,4,4,4,4,4,4,3
4,4,4,3,4,4,4,4,4,4,4,4,4,2
4,4,4,2,4,4,4,4,4,4,4,4,4,2
4,1,2,2,4,4,4,4,4,4,4,4,4,3
4,2,4,4,4,4,4,4,4,4,4,4,4,2
4,3,4,4,4,4,4,4,4,4,4,4,2,1
4,2,4,4,4,4,4,4,4,4,4,4,2,4
4,3,4,4,4,4,4,4,4,4,4,4,2,4
4,2,4,4,4,4,4,4,4,4,4,2,2,2
2,1,2,2,2,2,2,4,4,4,2,2,2,2
2,2,2,2,2,2,2,4,4,4,2,2,2,2
2,2,2,2,2,2,1,2,3,2,2,2,2,2
2,2,2,2,2,2,2,4,4,4,4,4,4,4
endlayer

layer
4,4,4,4,4,4,4,1,2,3,2,3,2,1
4,4,4,1,2,3,2,2,4,4,4,4,4,2
4,4,4,2,4,4,4,4,4,4,4,4,4,3
4,4,4,3,4,4,4,4,4,4,4,4,4,2
4,4,4,2,4,4,4,4,4,4,4,4,4,2
4,1,2,2,4,4,4,4,4,4,4,4,4,3
4,2,4,4,4,4,4,4,4,4,4,4,4,2
4,3,4,4,4,4,4,4,4,4,4,4,2,1
4,2,4,4,4,4,4,4,4,4,4,4,2,4
4,3,4,4,4,4,4,4,4,4,4,4,2,4
4,2,4,4,4,4,4,4,4,4,4,2,2,2
4,1,2,2,2,2,2,4,4,4,2,2,2,2
4,2,2,2,2,2,2,4,4,4,2,2,2,2
4,2,2,2,2,2,1,2,3,2,2,2,2,2
4,4,4,4,4,4,4,4,4,4,4,4,4,4
endlayer

layer
4,4,4,4,4,4,4,1,2,2,2,2,2,1
4,4,4,1,2,2,2,2,5,5,5,5,5,2
4,4,4,2,5,5,5,5,6,6,6,5,5,2
4,4,4,2,5,5,5,5,6,5,5,6,5,2
4,4,4,2,5,5,5,5,6,5,5,6,5,2
4,1,2,2,5,5,5,5,6,5,5,6,5,2
4,2,5,5,5,5,5,5,5,6,6,6,5,2
4,2,5,6,6,5,5,5,5,5,5,5,2,1
4,2,5,6,5,6,5,5,5,5,5,5,2,4
4,2,5,6,6,6,5,6,6,6,6,6,2,4
4,2,5,5,5,5,5,6,5,5,6,2,2,2
4,1,2,5,5,2,2,6,6,6,2,7,7,2
4,4,2,2,2,2,2,5,5,5,2,7,8,2
4,4,4,4,4,4,1,2,2,2,2,2,2,2
4,4,4,4,4,4,4,4,4,4,4,4,4,4
endlayer

layer
4,4,4,4,0,0,0,9,10,61,61,61,10,9
4,4,4,9,10,10,10,9,0,0,0,0,0,10
4,4,0,10,12,12,11,0,0,0,0,0,0,61
4,4,0,10,12,12,11,0,0,13,13,0,0,61
4,0,0,10,5,5,9,0,0,15,14,0,0,61
0,9,10,9,17,17,16,0,0,13,13,0,0,61
0,10,18,0,0,0,0,0,0,0,0,0,0,10
0,61,19,0,0,0,0,0,0,0,0,0,9,9
0,61,20,0,0,0,0,0,0,1,1,1,10,4
0,61,0,0,0,0,0,0,0,0,0,1,10,4
0,10,0,0,0,0,0,0,0,0,0,0,2,2
0,9,10,21,21,10,9,0,0,0,0,0,0,2
4,4,0,0,0,0,10,23,22,1,2,0,22,2
4,4,4,4,0,0,9,10,61,10,2,2,2,2
4,4,4,4,4,4,0,0,0,4,4,4,4,4
endlayer

layer
4,4,0,0,0,0,0,9,24,0,0,0,24,9
4,4,0,9,24,24,24,9,0,0,0,0,0,24
4,0,0,24,12,12,11,0,0,0,0,0,0,0
4,0,0,24,12,12,11,0,0,25,25,0,0,0
0,0,0,24,17,17,9,0,0,26,26,0,0,0
0,9,24,9,0,0,0,0,0,25,25,0,0,0
0,24,25,0,0,0,0,0,0,0,0,0,0,24
0,0,26,0,0,0,0,0,0,0,0,0,9,9
0,0,25,0,0,0,0,0,0,0,0,27,24,0
0,0,0,0,0,0,0,0,0,0,0,0,24,0
0,24,0,0,0,0,0,0,0,0,0,0,28,2
0,9,24,30,29,24,9,0,0,0,0,0,0,2
0,0,0,0,0,0,24,0,0,0,3,0,0,2
4,4,0,0,0,0,9,24,0,24,2,2,2,2
4,4,4,0,0,0,0,0,0,0,0,4,4,4
endlayer

layer
4,0,0,0,0,0,0,9,24,31,31,31,24,9
4,0,0,9,24,24,24,9,0,0,0,0,0,24
0,0,0,24,0,0,33,32,0,0,0,0,0,31
0,0,0,24,0,0,33,32,0,0,0,0,0,31
0,0,0,24,0,0,9,34,0,0,0,0,0,31
0,9,24,9,0,0,0,0,0,0,0,0,0,31
0,24,0,35,0,0,0,0,0,0,0,0,0,24
0,31,0,0,0,0,0,0,0,0,0,36,9,9
0,31,0,0,0,0,0,0,0,0,0,37,24,0
0,31,0,0,0,0,0,0,0,0,0,37,24,0
0,24,38,0,0,0,0,0,0,0,0,0,28,2
0,9,24,13,13,24,9,34,0,0,0,39,0,2
0,35,0,0,0,0,24,0,0,0,3,0,0,2
0,0,0,0,0,36,9,24,31,24,2,2,2,2
4,0,0,0,0,0,0,0,0,0,0,0,0,4
endlayer

layer
0,0,0,0,0,0,0,9,24,24,24,24,24,9
0,0,0,9,24,24,24,9,0,0,0,0,0,24
0,0,0,24,0,0,0,33,32,0,0,0,0,24
0,0,0,24,0,0,0,33,32,0,0,0,0,24
0,0,0,24,0,0,9,0,0,0,0,0,0,24
0,9,24,9,0,0,0,0,0,0,0,0,0,24
0,24,0,0,0,0,0,0,0,0,0,0,0,24
0,24,0,0,0,0,0,0,0,0,0,0,9,9
0,24,0,0,0,0,0,0,0,0,0,0,24,0
0,24,0,0,0,0,0,0,0,0,0,0,24,0
0,24,0,0,0,0,0,0,0,0,0,41,2,40
0,9,24,24,24,24,9,0,0,0,0,2,42,2
0,0,0,0,0,0,24,0,0,0,2,43,0,2
0,0,0,0,0,0,9,24,24,24,2,2,2,2
0,0,0,0,0,0,0,0,0,0,0,0,0,0
endlayer

layer
0,0,0,0,0,0,0,9,44,44,44,44,44,9
0,0,0,9,44,44,44,44,44,44,44,44,44,45
0,0,0,45,0,0,0,0,33,12,12,12,12,45
0,0,0,45,0,0,0,0,33,12,12,12,12,45
0,0,0,45,0,0,9,46,46,12,12,12,12,45
0,9,44,9,0,0,45,47,47,47,47,47,12,45
0,45,12,12,12,12,45,47,47,12,12,47,12,45
0,45,12,47,47,12,45,47,12,47,12,47,9,9
0,45,12,47,47,12,45,47,12,47,12,47,45,0
0,45,12,47,47,12,45,47,12,12,47,47,45,0
0,45,12,12,12,12,45,47,47,47,47,47,45,0
0,9,44,44,44,44,9,47,47,47,47,2,2,2
0,0,0,0,0,0,45,12,12,12,12,2,0,2
0,0,0,0,0,0,9,44,44,44,44,2,2,2
0,0,0,0,0,0,0,0,0,0,0,0,0,0
endlayer

layer
0,0,0,0,0,0,0,13,13,13,13,13,13,13
0,0,0,9,24,24,9,24,24,24,24,24,9,13
0,0,0,24,0,0,0,0,0,0,0,18,24,13
0,0,0,24,0,0,0,0,0,0,0,19,24,13
0,0,0,24,0,36,9,0,0,0,0,20,24,13
0,13,13,9,24,24,24,0,0,0,0,0,24,13
0,13,0,0,0,0,24,0,0,0,0,48,24,13
0,13,0,0,0,0,24,0,0,0,0,62,9,13
0,13,0,0,0,0,50,0,0,49,0,13,24,0
0,13,0,0,0,0,24,0,0,51,0,0,24,0
0,13,0,0,0,0,24,0,0,0,0,11,24,0
0,13,13,13,13,13,9,24,24,24,24,24,2,2
0,0,0,0,0,0,13,0,0,0,0,2,0,2
0,0,0,0,0,0,13,13,13,13,13,2,2,2
0,0,0,0,0,0,0,0,0,0,0,0,0,0
endlayer

layer
0,0,0,0,0,0,0,0,0,0,0,0,0,0
0,0,0,9,24,24,9,24,0,0,0,24,9,0
0,0,0,24,0,0,0,0,0,0,0,0,24,0
0,0,0,0,0,0,0,0,0,0,0,0,0,0
0,0,0,24,0,0,9,0,0,0,0,0,0,0
0,0,0,9,24,24,24,0,0,0,0,0,0,0
0,0,0,0,0,0,24,0,0,0,0,0,24,0
0,0,0,0,0,0,24,0,0,0,0,0,9,0
0,0,0,0,0,0,30,0,0,0,0,52,24,0
0,0,0,0,0,0,24,0,0,0,0,0,0,0
0,0,0,0,0,0,24,0,0,0,0,11,24,0
0,0,0,0,0,0,9,24,0,0,24,24,2,2
0,0,0,0,0,0,0,0,0,0,0,2,0,2
0,0,0,0,0,0,0,0,0,0,0,2,2,2
0,0,0,0,0,0,0,0,0,0,0,0,0,0
endlayer

layer
0,0,0,0,0,0,0,0,0,0,0,0,0,0
0,0,0,9,24,24,9,24,31,31,31,24,9,0
0,0,0,24,0,0,0,0,0,0,0,0,24,0
0,0,0,31,0,0,0,0,0,0,0,0,31,0
0,0,0,24,0,0,9,34,0,0,0,0,31,0
0,0,0,9,24,24,24,0,0,0,0,0,31,0
0,0,0,35,0,0,24,0,0,0,0,0,24,0
0,0,0,0,0,0,24,0,0,0,0,36,9,0
0,0,0,0,0,0,13,0,0,0,0,0,24,0
0,0,0,0,0,0,24,0,0,0,0,0,31,0
0,0,0,0,0,0,24,0,0,0,0,0,24,0
0,0,0,0,0,36,9,24,31,31,24,24,2,2
0,0,0,0,0,0,0,0,0,0,0,2,0,2
0,0,0,0,0,0,0,0,0,0,0,2,2,53
0,0,0,0,0,0,0,0,0,0,0,0,0,0
endlayer

layer
0,0,0,0,0,0,0,0,0,0,0,0,0,0
0,0,0,9,24,24,9,24,24,24,24,24,9,0
0,0,0,24,0,0,0,0,0,0,0,0,24,0
0,0,0,24,0,0,0,0,0,0,0,0,24,0
0,0,0,24,0,0,9,0,0,0,0,0,24,0
0,0,0,9,24,24,24,0,0,0,0,0,24,0
0,0,0,0,0,0,24,0,0,0,0,0,24,0
0,0,0,0,0,0,24,0,0,0,0,0,9,0
0,0,0,0,0,0,24,0,0,0,0,0,24,0
0,0,0,0,0,0,24,0,0,0,0,0,24,0
0,0,0,0,0,0,24,0,0,0,0,0,24,0
0,0,0,0,0,0,9,24,24,24,24,24,2,2
0,0,0,0,0,0,0,0,0,0,0,2,0,2
0,0,0,0,0,0,0,0,0,0,0,2,2,0
0,0,0,0,0,0,0,0,0,0,0,0,0,0
endlayer

layer
0,0,0,54,54,54,54,54,54,54,54,54,54,0
0,0,54,55,55,55,55,55,55,55,55,55,55,54
0,0,54,55,47,47,47,47,47,47,47,47,55,54
0,0,54,55,47,13,47,47,47,47,47,47,55,54
0,0,54,55,47,47,47,47,47,47,47,47,55,54
0,0,54,55,55,55,55,47,47,47,47,47,55,54
0,0,54,54,54,54,55,47,47,47,47,47,55,54
0,0,0,0,0,54,55,47,47,47,47,47,55,54
0,0,0,0,0,54,55,47,47,47,47,47,55,54
0,0,0,0,0,54,55,47,47,47,47,47,55,54
0,0,0,0,0,54,55,47,47,47,47,47,55,54
0,0,0,0,0,54,55,55,55,55,55,55,2,56
0,0,0,0,0,0,54,54,54,54,54,2,0,2
0,0,0,0,0,0,0,0,0,0,0,57,2,0
0,0,0,0,0,0,0,0,0,0,0,0,0,0
endlayer

layer
0,0,0,0,0,0,0,0,0,0,0,0,0,0
0,0,0,58,58,58,58,58,58,58,58,58,58,0
0,0,0,58,54,54,54,54,54,54,54,54,58,0
0,0,0,58,54,31,54,54,54,54,54,54,58,0
0,0,0,58,54,54,54,54,54,54,54,54,58,0
0,0,0,58,58,58,58,54,54,54,54,54,58,0
0,0,0,0,0,0,58,54,54,54,54,54,58,0
0,0,0,0,0,0,58,54,54,54,54,54,58,0
0,0,0,0,0,0,58,54,54,54,54,54,58,0
0,0,0,0,0,0,58,54,54,54,54,54,58,0
0,0,0,0,0,0,58,54,54,54,54,54,58,0
0,0,0,0,0,0,58,58,58,58,58,58,2,0
0,0,0,0,0,0,0,0,0,0,0,2,0,2
0,0,0,0,0,0,0,0,0,0,0,0,2,0
0,0,0,0,0,0,0,0,0,0,0,0,0,0
endlayer

layer
0,0,0,0,0,0,0,0,0,0,0,0,0,0
0,0,0,0,0,0,0,0,0,0,0,0,0,0
0,0,0,0,0,0,0,0,0,0,0,0,0,0
0,0,0,0,0,52,0,0,0,0,0,0,0,0
0,0,0,0,0,0,0,0,0,0,0,0,0,0
0,0,0,0,0,0,0,0,0,0,0,0,0,0
0,0,0,0,0,0,0,0,0,0,0,0,0,0
0,0,0,0,0,0,0,0,0,0,0,0,0,0
0,0,0,0,0,0,0,0,0,0,0,0,0,0
0,0,0,0,0,0,0,0,0,0,0,0,0,0
0,0,0,0,0,0,0,0,0,0,0,0,0,0
0,0,0,0,0,0,0,0,0,0,0,0,2,0
0,0,0,0,0,0,0,0,0,0,0,2,0,2
0,0,0,0,0,0,0,0,0,0,0,0,2,0
0,0,0,0,0,0,0,0,0,0,0,0,0,0
endlayer

layer
0,0,0,0,0,0,0,0,0,0,0,0,0,0
0,0,0,0,0,0,0,0,0,0,0,0,0,0
0,0,0,0,0,0,0,0,0,0,0,0,0,0
0,0,0,0,0,0,0,0,0,0,0,0,0,0
0,0,0,0,0,0,0,0,0,0,0,0,0,0
0,0,0,0,0,0,0,0,0,0,0,0,0,0
0,0,0,0,0,0,0,0,0,0,0,0,0,0
0,0,0,0,0,0,0,0,0,0,0,0,0,0
0,0,0,0,0,0,0,0,0,0,0,0,0,0
0,0,0,0,0,0,0,0,0,0,0,0,0,0
0,0,0,0,0,0,0,0,0,0,0,0,0,0
0,0,0,0,0,0,0,0,0,0,0,0,2,0
0,0,0,0,0,0,0,0,0,0,0,2,0,2
0,0,0,0,0,0,0,0,0,0,0,0,2,0
0,0,0,0,0,0,0,0,0,0,0,0,0,0
endlayer

layer
0,0,0,0,0,0,0,0,0,0,0,0,0,0
0,0,0,0,0,0,0,0,0,0,0,0,0,0
0,0,0,0,0,0,0,0,0,0,0,0,0,0
0,0,0,0,0,0,0,0,0,0,0,0,0,0
0,0,0,0,0,0,0,0,0,0,0,0,0,0
0,0,0,0,0,0,0,0,0,0,0,0,0,0
0,0,0,0,0,0,0,0,0,0,0,0,0,0
0,0,0,0,0,0,0,0,0,0,0,0,0,0
0,0,0,0,0,0,0,0,0,0,0,0,0,0
0,0,0,0,0,0,0,0,0,0,0,0,0,0
0,0,0,0,0,0,0,0,0,0,0,0,0,0
0,0,0,0,0,0,0,0,0,0,0,0,59,0
0,0,0,0,0,0,0,0,0,0,0,41,31,43
0,0,0,0,0,0,0,0,0,0,0,0,42,0
0,0,0,0,0,0,0,0,0,0,0,0,0,0
endlayer

layer
0,0,0,0,0,0,0,0,0,0,0,0,0,0
0,0,0,0,0,0,0,0,0,0,0,0,0,0
0,0,0,0,0,0,0,0,0,0,0,0,0,0
0,0,0,0,0,0,0,0,0,0,0,0,0,0
0,0,0,0,0,0,0,0,0,0,0,0,0,0
0,0,0,0,0,0,0,0,0,0,0,0,0,0
0,0,0,0,0,0,0,0,0,0,0,0,0,0
0,0,0,0,0,0,0,0,0,0,0,0,0,0
0,0,0,0,0,0,0,0,0,0,0,0,0,0
0,0,0,0,0,0,0,0,0,0,0,0,0,0
0,0,0,0,0,0,0,0,0,0,0,0,0,0
0,0,0,0,0,0,0,0,0,0,0,0,60,0
0,0,0,0,0,0,0,0,0,0,0,60,0,60
0,0,0,0,0,0,0,0,0,0,0,0,60,0
0,0,0,0,0,0,0,0,0,0,0,0,0,0
endlayer

