
# Created by Ruins mod version 16.7 Ingame Parser
# authoring Player: lafuller

weight=1
embed_into_distance=38
acceptable_target_blocks=
unacceptable_target_blocks=flowing_lava,lava,ice,bedrock,netherrack,nether_brick,nether_brick_fence,soul_sand,quartz_ore,end_stone,obsidian,iron_bars,cloud,flesh,ash_block,slime_grass,slime_congealed,slime_dirt
dimensions=38,17,17
allowable_overhang=0
max_leveling=38
leveling_buffer=-1
preserve_water=0
preserve_lava=0

adjoining_template=Gilly/GillyCatacomb1;6;80;-14;100
adjoining_template=Gilly/GillyCatacomb1;12;80;-28;100
adjoining_template=Gilly/GillyCatacomb1;20;80;-8;100
adjoining_template=Gilly/GillyCatacomb1;26;80;-22;100

adjoining_template=Gilly/GillyCatacomb1;-14;80;-6;100
adjoining_template=Gilly/GillyCatacomb1;-20;80;8;100
adjoining_template=Gilly/GillyCatacomb1;-28;80;-12;100
adjoining_template=Gilly/GillyCatacomb1;-34;80;2;100

adjoining_template=Gilly/GillyCatacomb1;-8;80;-20;100
adjoining_template=Gilly/GillyCatacomb1;-22;80;-26;100
adjoining_template=Gilly/GillyCatacomb1;-2;80;-34;100
adjoining_template=Gilly/GillyCatacomb1;-16;80;-40;100

adjoining_template=Gilly/GillyCatacomb1;14;70;6;100
adjoining_template=Gilly/GillyCatacomb1;-6;70;14;100
adjoining_template=Gilly/GillyCatacomb1;8;70;20;100

rule1=0,100,preserveBlock
rule2=0,100,stonebrick-0,stonebrick-1,stonebrick-2,stone-5,stone-5,stone-6,stone-6,cobblestone
rule3=0,100,minecraft:cobblestone_wall-0
rule4=0,100,stonebrick-0,stonebrick-1,stonebrick-1,stonebrick-2,stonebrick-2,stone-5,stone-6,cobblestone
rule5=0,100,minecraft:water-0
rule6=0,100,minecraft:stone_brick_stairs-2
rule7=0,100,minecraft:stone_brick_stairs-1
rule8=0,100,minecraft:stone_brick_stairs-3
rule9=0,100,minecraft:stone_brick_stairs-0
rule10=0,100,minecraft:stone_brick_stairs-7
rule11=0,100,minecraft:stone_brick_stairs-5
rule12=0,100,minecraft:stone_brick_stairs-4
rule13=0,100,minecraft:stone_brick_stairs-6
rule14=0,100,minecraft:stone_slab-13
rule15=0,100,minecraft:iron_bars-0
rule16=0,100,minecraft:stone_slab-5

layer
1,1,2,2,2,2,2,2,2,2,1,1,1,1,1,1,1
1,1,2,2,2,2,2,2,2,2,2,2,2,1,1,1,1
1,1,2,2,2,2,2,2,2,2,2,2,2,2,2,2,2
1,1,2,2,2,2,2,2,2,2,2,2,2,2,2,2,2
1,2,2,2,2,2,2,2,2,2,2,2,2,2,2,2,2
1,2,2,2,2,2,2,2,2,2,2,2,2,2,2,2,2
1,2,2,2,2,2,2,2,2,2,2,2,2,2,2,2,2
2,2,2,2,2,2,2,2,2,2,2,2,2,2,2,2,2
2,2,2,2,2,2,2,2,2,2,2,2,2,2,2,2,2
2,2,2,2,2,2,2,2,2,2,2,2,2,2,2,2,2
2,2,2,2,2,2,2,2,2,2,2,2,2,2,2,2,1
2,2,2,2,2,2,2,2,2,2,2,2,2,2,2,2,1
2,2,2,2,2,2,2,2,2,2,2,2,2,2,2,2,1
2,2,2,2,2,2,2,2,2,2,2,2,2,2,2,1,1
2,2,2,2,2,2,2,2,2,2,2,2,2,2,2,1,1
1,1,1,1,2,2,2,2,2,2,2,2,2,2,2,1,1
1,1,1,1,1,1,1,2,2,2,2,2,2,2,2,1,1
endlayer

layer
1,1,2,2,2,2,2,2,2,2,1,1,1,1,1,1,1
1,1,2,2,2,2,2,2,2,2,2,2,2,1,1,1,1
1,1,2,2,2,2,2,2,2,2,2,2,2,2,2,2,2
1,1,2,2,2,2,2,2,2,2,2,2,2,2,2,2,2
1,2,2,2,2,2,2,2,2,2,2,2,2,2,2,2,2
1,2,2,2,2,2,3,3,3,3,3,2,2,2,2,2,2
1,2,2,2,2,3,3,3,3,3,3,3,2,2,2,2,2
2,2,2,2,2,3,3,3,3,3,3,3,2,2,2,2,2
2,2,2,2,2,3,3,3,3,3,3,3,2,2,2,2,2
2,2,2,2,2,3,3,3,3,3,3,3,2,2,2,2,2
2,2,2,2,2,3,3,3,3,3,3,3,2,2,2,2,1
2,2,2,2,2,2,3,3,3,3,3,2,2,2,2,2,1
2,2,2,2,2,2,2,2,2,2,2,2,2,2,2,2,1
2,2,2,2,2,2,2,2,2,2,2,2,2,2,2,1,1
2,2,2,2,2,2,2,2,2,2,2,2,2,2,2,1,1
1,1,1,1,2,2,2,2,2,2,2,2,2,2,2,1,1
1,1,1,1,1,1,1,2,2,2,2,2,2,2,2,1,1
endlayer

layer
1,1,4,4,4,4,4,2,2,2,1,1,1,1,1,1,1
1,1,4,4,4,4,4,2,2,2,2,2,2,1,1,1,1
1,1,4,4,4,4,4,2,2,2,2,2,2,4,4,4,4
1,1,4,4,4,2,2,2,2,2,2,2,2,4,4,4,4
1,2,2,2,2,2,2,2,2,2,2,2,2,4,4,4,4
1,2,2,2,2,2,5,5,5,5,5,2,2,2,4,4,4
1,2,2,2,2,5,5,5,5,5,5,5,2,2,4,4,4
2,2,2,2,2,5,5,5,5,5,5,5,2,2,2,2,2
2,2,2,2,2,5,5,5,5,5,5,5,2,2,2,2,2
2,2,2,2,2,5,5,5,5,5,5,5,2,2,2,2,2
4,4,4,2,2,5,5,5,5,5,5,5,2,2,2,2,1
4,4,4,2,2,2,5,5,5,5,5,2,2,2,2,2,1
4,4,4,4,2,2,2,2,2,2,2,2,2,2,2,2,1
4,4,4,4,2,2,2,2,2,2,2,2,4,4,4,1,1
4,4,4,4,2,2,2,2,2,2,4,4,4,4,4,1,1
1,1,1,1,2,2,2,2,2,2,4,4,4,4,4,1,1
1,1,1,1,1,1,1,2,2,2,4,4,4,4,4,1,1
endlayer

layer
1,1,4,4,4,4,4,0,0,0,1,1,1,1,1,1,1
1,1,4,4,4,4,6,0,0,0,0,0,0,1,1,1,1
1,1,4,4,4,4,7,0,0,0,0,0,0,4,4,4,4
1,1,4,4,4,0,0,0,0,0,0,0,0,4,4,4,4
1,0,0,0,0,0,0,0,0,0,0,0,0,4,4,4,4
1,0,0,0,0,0,0,0,0,0,0,0,0,0,4,4,4
1,0,0,0,0,0,0,0,0,0,0,0,0,0,8,7,4
0,0,0,0,0,0,0,0,0,0,0,0,0,0,0,0,0
0,0,0,0,0,0,0,0,0,0,0,0,0,0,0,0,0
0,0,0,0,0,0,0,0,0,0,0,0,0,0,0,0,0
4,9,6,0,0,0,0,0,0,0,0,0,0,0,0,0,1
4,4,4,0,0,0,0,0,0,0,0,0,0,0,0,0,1
4,4,4,4,0,0,0,0,0,0,0,0,0,0,0,0,1
4,4,4,4,0,0,0,0,0,0,0,0,4,4,4,1,1
4,4,4,4,0,0,0,0,0,0,9,4,4,4,4,1,1
1,1,1,1,0,0,0,0,0,0,8,4,4,4,4,1,1
1,1,1,1,1,1,1,0,0,0,4,4,4,4,4,1,1
endlayer

layer
1,1,4,4,4,4,4,0,0,0,1,1,1,1,1,1,1
1,1,4,4,4,6,0,0,0,0,0,0,0,1,1,1,1
1,1,4,4,4,6,0,0,0,0,0,0,0,4,4,4,4
1,1,4,4,4,0,0,0,0,0,0,0,0,4,4,4,4
1,0,0,0,0,0,0,0,0,0,0,0,0,4,4,4,4
1,0,0,0,0,0,0,0,0,0,0,0,0,0,7,7,4
1,0,0,0,0,0,0,0,0,0,0,0,0,0,0,0,4
0,0,0,0,0,0,0,0,0,0,0,0,0,0,0,0,0
0,0,0,0,0,0,0,0,0,0,0,0,0,0,0,0,0
0,0,0,0,0,0,0,0,0,0,0,0,0,0,0,0,0
4,0,0,0,0,0,0,0,0,0,0,0,0,0,0,0,1
4,9,9,0,0,0,0,0,0,0,0,0,0,0,0,0,1
4,4,4,4,0,0,0,0,0,0,0,0,0,0,0,0,1
4,4,4,4,0,0,0,0,0,0,0,0,4,4,4,1,1
4,4,4,4,0,0,0,0,0,0,0,8,4,4,4,1,1
1,1,1,1,0,0,0,0,0,0,0,8,4,4,4,1,1
1,1,1,1,1,1,1,0,0,0,4,4,4,4,4,1,1
endlayer

layer
1,1,4,4,4,4,4,0,0,0,1,1,1,1,1,1,1
1,1,2,2,6,0,0,0,0,0,0,0,0,1,1,1,1
1,1,2,2,6,0,0,0,0,0,0,0,0,4,2,2,4
1,1,4,4,3,0,0,0,0,0,0,0,0,4,2,2,4
1,0,0,0,0,0,0,0,0,0,0,0,0,3,7,7,4
1,0,0,0,0,0,0,0,0,0,0,0,0,0,0,0,4
1,0,0,0,0,0,0,0,0,0,0,0,0,0,0,0,4
0,0,0,0,0,0,0,0,0,0,0,0,0,0,0,0,0
0,0,0,0,0,0,0,0,0,0,0,0,0,0,0,0,0
0,0,0,0,0,0,0,0,0,0,0,0,0,0,0,0,0
4,0,0,0,0,0,0,0,0,0,0,0,0,0,0,0,1
4,0,0,0,0,0,0,0,0,0,0,0,0,0,0,0,1
4,9,9,3,0,0,0,0,0,0,0,0,0,0,0,0,1
4,2,2,4,0,0,0,0,0,0,0,0,3,4,4,1,1
4,2,2,4,0,0,0,0,0,0,0,0,8,2,2,1,1
1,1,1,1,0,0,0,0,0,0,0,0,8,2,2,1,1
1,1,1,1,1,1,1,0,0,0,4,4,4,4,4,1,1
endlayer

layer
1,1,4,4,4,4,4,0,0,0,1,1,1,1,1,1,1
1,1,0,0,0,0,0,0,0,0,0,0,10,1,1,1,1
1,1,0,0,0,0,0,0,0,0,0,0,10,6,0,0,4
1,1,9,9,3,0,0,0,0,0,0,0,10,6,0,0,4
1,11,11,11,0,0,0,0,0,0,0,0,0,3,0,0,4
1,0,0,0,0,0,0,0,0,0,0,0,0,0,0,0,4
1,0,0,0,0,0,0,0,0,0,0,0,0,0,0,0,4
0,0,0,0,0,0,0,0,0,0,0,0,0,0,0,0,0
0,0,0,0,0,0,0,0,0,0,0,0,0,0,0,0,0
0,0,0,0,0,0,0,0,0,0,0,0,0,0,0,0,0
4,0,0,0,0,0,0,0,0,0,0,0,0,0,0,0,1
4,0,0,0,0,0,0,0,0,0,0,0,0,0,0,0,1
4,0,0,3,0,0,0,0,0,0,0,0,0,12,12,12,1
4,0,0,8,13,0,0,0,0,0,0,0,3,7,7,1,1
4,0,0,8,13,0,0,0,0,0,0,0,0,0,0,1,1
1,1,1,1,13,0,0,0,0,0,0,0,0,0,0,1,1
1,1,1,1,1,1,1,0,0,0,4,4,4,4,4,1,1
endlayer

layer
1,1,4,4,4,4,4,0,0,0,1,1,1,1,1,1,1
1,1,0,0,0,0,0,0,0,0,0,10,6,1,1,1,1
1,1,0,0,0,0,0,0,0,0,0,10,6,0,0,0,4
1,1,0,0,3,0,0,0,0,0,0,10,6,0,0,0,4
1,9,9,9,0,0,0,0,0,0,0,0,0,3,0,0,4
1,11,11,11,0,0,0,0,0,0,0,0,0,0,0,0,4
1,0,0,0,0,0,0,0,0,0,0,0,0,0,0,0,4
0,0,0,0,0,0,0,0,0,0,0,0,0,0,0,0,0
0,0,0,0,0,0,0,0,0,0,0,0,0,0,0,0,0
0,0,0,0,0,0,0,0,0,0,0,0,0,0,0,0,0
4,0,0,0,0,0,0,0,0,0,0,0,0,0,0,0,1
4,0,0,0,0,0,0,0,0,0,0,0,0,12,12,12,1
4,0,0,3,0,0,0,0,0,0,0,0,0,7,7,7,1
4,0,0,0,8,13,0,0,0,0,0,0,3,0,0,1,1
4,0,0,0,8,13,0,0,0,0,0,0,0,0,0,1,1
1,1,1,1,8,13,0,0,0,0,0,0,0,0,0,1,1
1,1,1,1,1,1,1,0,0,0,4,4,4,4,4,1,1
endlayer

layer
1,1,4,4,4,4,4,2,2,2,1,1,1,1,1,1,1
1,1,0,0,0,14,14,2,2,2,2,6,0,1,1,1,1
1,1,0,0,0,14,14,2,7,2,2,6,0,0,0,0,4
1,1,0,0,3,2,2,2,2,2,2,6,0,0,0,0,4
1,0,0,0,8,2,7,9,9,9,7,9,9,3,0,0,4
1,9,9,9,8,2,2,9,2,9,2,2,2,2,14,14,4
1,2,2,2,6,2,14,0,0,0,14,2,8,2,14,14,4
2,2,2,2,8,8,0,0,0,0,0,6,6,2,2,2,2
2,2,6,2,8,2,0,0,0,0,0,2,6,2,8,2,2
2,2,2,2,8,8,0,0,0,0,0,6,6,2,2,2,2
4,14,14,2,6,2,14,0,0,0,14,2,8,2,2,2,1
4,14,14,2,2,2,2,7,2,7,2,2,6,7,7,7,1
4,0,0,3,7,7,9,7,7,7,9,2,6,0,0,0,1
4,0,0,0,0,8,2,2,2,2,2,2,3,0,0,1,1
4,0,0,0,0,8,2,2,9,2,14,14,0,0,0,1,1
1,1,1,1,0,8,2,2,2,2,14,14,0,0,0,1,1
1,1,1,1,1,1,1,2,2,2,4,4,4,4,4,1,1
endlayer

layer
1,1,4,4,4,4,4,0,0,0,1,1,1,1,1,1,1
1,1,0,0,10,4,0,0,0,0,0,0,0,1,1,1,1
1,1,0,0,10,6,0,0,0,0,0,0,0,0,0,0,4
1,1,0,0,0,0,0,0,0,0,0,0,0,0,0,0,4
1,0,0,0,0,0,0,0,0,0,0,0,0,0,12,12,4
1,0,0,0,0,0,0,0,0,0,0,0,0,0,7,4,4
1,0,0,0,0,0,0,0,0,0,0,0,0,0,0,0,4
0,0,0,0,0,0,0,0,0,0,0,0,0,0,0,0,0
0,0,0,0,0,0,0,0,0,0,0,0,0,0,0,0,0
0,0,0,0,0,0,0,0,0,0,0,0,0,0,0,0,0
4,0,0,0,0,0,0,0,0,0,0,0,0,0,0,0,1
4,4,9,0,0,0,0,0,0,0,0,0,0,0,0,0,1
4,11,11,0,0,0,0,0,0,0,0,0,0,0,0,0,1
4,0,0,0,0,0,0,0,0,0,0,0,0,0,0,1,1
4,0,0,0,0,0,0,0,0,0,0,8,13,0,0,1,1
1,1,1,1,0,0,0,0,0,0,0,4,13,0,0,1,1
1,1,1,1,1,1,1,0,0,0,4,4,4,4,4,1,1
endlayer

layer
1,1,4,4,4,4,4,0,0,0,1,1,1,1,1,1,1
1,1,11,10,4,4,0,0,0,0,0,0,0,1,1,1,1
1,1,0,10,6,0,0,0,0,0,0,0,0,0,0,10,4
1,1,0,0,0,0,0,0,0,0,0,0,0,0,12,10,4
1,0,0,0,0,0,0,0,0,0,0,0,0,0,7,4,4
1,0,0,0,0,0,0,0,0,0,0,0,0,0,0,4,4
1,0,0,0,0,0,0,0,0,0,0,0,0,0,0,0,4
0,0,0,0,0,0,0,0,0,0,0,0,0,0,0,0,0
0,0,0,0,0,0,0,0,0,0,0,0,0,0,0,0,0
0,0,0,0,0,0,0,0,0,0,0,0,0,0,0,0,0
4,0,0,0,0,0,0,0,0,0,0,0,0,0,0,0,1
4,4,0,0,0,0,0,0,0,0,0,0,0,0,0,0,1
4,4,9,0,0,0,0,0,0,0,0,0,0,0,0,0,1
4,11,11,0,0,0,0,0,0,0,0,0,0,0,0,1,1
4,13,0,0,0,0,0,0,0,0,0,0,8,13,0,1,1
1,1,1,1,0,0,0,0,0,0,0,4,4,4,12,1,1
1,1,1,1,1,1,1,0,0,0,4,4,4,4,4,1,1
endlayer

layer
1,1,4,4,4,4,4,0,0,0,1,1,1,1,1,1,1
1,1,4,4,4,4,0,0,0,0,0,0,0,1,1,1,1
1,1,11,6,0,0,0,0,0,0,0,0,0,0,10,4,4
1,1,0,0,0,0,0,0,0,0,0,0,0,0,7,4,4
1,0,0,0,0,0,0,0,0,0,0,0,0,0,0,4,4
1,0,0,0,0,0,0,0,0,0,0,0,0,0,0,4,4
1,0,0,0,0,0,0,0,0,0,0,0,0,0,0,0,4
0,0,0,0,0,0,0,0,0,0,0,0,0,0,0,0,0
0,0,0,0,0,0,0,0,0,0,0,0,0,0,0,0,0
0,0,0,0,0,0,0,0,0,0,0,0,0,0,0,0,0
4,0,0,0,0,0,0,0,0,0,0,0,0,0,0,0,1
4,4,0,0,0,0,0,0,0,0,0,0,0,0,0,0,1
4,4,0,0,0,0,0,0,0,0,0,0,0,0,0,0,1
4,4,9,0,0,0,0,0,0,0,0,0,0,0,0,1,1
4,4,13,0,0,0,0,0,0,0,0,0,0,8,12,1,1
1,1,1,1,0,0,0,0,0,0,0,4,4,4,4,1,1
1,1,1,1,1,1,1,0,0,0,4,4,4,4,4,1,1
endlayer

layer
1,1,4,4,4,4,4,0,0,0,1,1,1,1,1,1,1
1,1,7,7,4,4,0,0,0,0,0,0,0,1,1,1,1
1,1,0,0,0,0,0,0,0,0,0,0,0,0,0,8,4
1,1,0,0,0,0,0,0,0,0,0,0,0,0,0,8,4
1,0,0,0,0,0,0,0,0,0,0,0,0,0,0,4,4
1,0,0,0,0,0,0,0,0,0,0,0,0,0,0,4,4
1,0,0,0,0,0,0,0,0,0,0,0,0,0,0,0,4
0,0,0,0,0,0,0,0,0,0,0,0,0,0,0,0,0
0,0,0,0,0,0,0,0,0,0,0,0,0,0,0,0,0
0,0,0,0,0,0,0,0,0,0,0,0,0,0,0,0,0
4,0,0,0,0,0,0,0,0,0,0,0,0,0,0,0,1
4,4,0,0,0,0,0,0,0,0,0,0,0,0,0,0,1
4,4,0,0,0,0,0,0,0,0,0,0,0,0,0,0,1
4,6,0,0,0,0,0,0,0,0,0,0,0,0,0,1,1
4,6,0,0,0,0,0,0,0,0,0,0,0,0,0,1,1
1,1,1,1,0,0,0,0,0,0,0,4,4,9,9,1,1
1,1,1,1,1,1,1,0,0,0,4,4,4,4,4,1,1
endlayer

layer
1,1,4,4,4,4,4,0,0,0,1,1,1,1,1,1,1
1,1,0,0,8,4,0,0,0,0,0,0,0,1,1,1,1
1,1,0,0,0,0,0,0,0,0,0,0,0,0,0,0,4
1,1,0,0,0,0,0,0,0,0,0,0,0,0,0,0,4
1,0,0,0,0,0,0,0,0,0,0,0,0,0,0,9,4
1,0,0,0,0,0,0,0,0,0,0,0,0,0,0,4,4
1,0,0,0,0,0,0,0,0,0,0,0,0,0,0,0,4
0,0,0,0,0,0,0,0,0,0,0,0,0,0,0,0,0
0,0,0,0,0,0,0,0,0,0,0,0,0,0,0,0,0
0,0,0,0,0,0,0,0,0,0,0,0,0,0,0,0,0
4,0,0,0,0,0,0,0,0,0,0,0,0,0,0,0,1
4,4,0,0,0,0,0,0,0,0,0,0,0,0,0,0,1
4,7,0,0,0,0,0,0,0,0,0,0,0,0,0,0,1
4,0,0,0,0,0,0,0,0,0,0,0,0,0,0,1,1
4,0,0,0,0,0,0,0,0,0,0,0,0,0,0,1,1
1,1,1,1,0,0,0,0,0,0,0,4,6,0,0,1,1
1,1,1,1,1,1,1,0,0,0,4,4,4,4,4,1,1
endlayer

layer
1,1,4,4,4,4,4,0,0,0,1,1,1,1,1,1,1
1,1,0,0,0,8,13,0,0,0,0,0,0,1,1,1,1
1,1,0,0,0,0,0,0,0,0,0,0,0,0,0,0,4
1,1,0,0,0,0,0,0,0,0,0,0,0,0,0,0,4
1,0,0,0,0,0,0,0,0,0,0,0,0,0,0,0,4
1,0,0,0,0,0,0,0,0,0,0,0,0,0,0,9,4
1,0,0,0,0,0,0,0,0,0,0,0,0,0,0,11,4
0,0,0,0,0,0,0,0,0,0,0,0,0,0,0,0,0
0,0,0,0,0,0,0,0,0,0,0,0,0,0,0,0,0
0,0,0,0,0,0,0,0,0,0,0,0,0,0,0,0,0
4,12,0,0,0,0,0,0,0,0,0,0,0,0,0,0,1
4,7,0,0,0,0,0,0,0,0,0,0,0,0,0,0,1
4,0,0,0,0,0,0,0,0,0,0,0,0,0,0,0,1
4,0,0,0,0,0,0,0,0,0,0,0,0,0,0,1,1
4,0,0,0,0,0,0,0,0,0,0,0,0,0,0,1,1
1,1,1,1,0,0,0,0,0,0,10,6,0,0,0,1,1
1,1,1,1,1,1,1,0,0,0,4,4,4,4,4,1,1
endlayer

layer
1,1,4,4,4,4,4,4,4,4,1,1,1,1,1,1,1
1,1,0,0,0,0,8,13,14,14,11,11,14,1,1,1,1
1,1,0,0,0,0,0,0,0,0,0,0,0,0,0,0,4
1,1,0,0,0,0,0,0,0,0,0,0,0,0,0,0,4
1,14,0,0,0,0,0,0,0,0,0,0,0,0,0,0,4
1,13,0,0,0,0,0,0,0,0,0,0,0,0,0,0,4
1,13,0,0,0,0,0,0,0,0,0,0,0,0,0,9,4
4,14,0,0,0,0,0,0,0,0,0,0,0,0,0,11,4
4,14,0,0,0,0,0,0,0,0,0,0,0,0,0,14,4
4,12,0,0,0,0,0,0,0,0,0,0,0,0,0,14,4
4,7,0,0,0,0,0,0,0,0,0,0,0,0,0,10,1
4,0,0,0,0,0,0,0,0,0,0,0,0,0,0,10,1
4,0,0,0,0,0,0,0,0,0,0,0,0,0,0,14,1
4,0,0,0,0,0,0,0,0,0,0,0,0,0,0,1,1
4,0,0,0,0,0,0,0,0,0,0,0,0,0,0,1,1
1,1,1,1,14,12,12,14,14,10,6,0,0,0,0,1,1
1,1,1,1,1,1,1,4,4,4,4,4,4,4,4,1,1
endlayer

layer
1,1,4,4,4,4,4,4,4,4,1,1,1,1,1,1,1
1,1,0,0,0,0,0,8,4,4,4,4,4,1,1,1,1
1,1,12,12,12,12,11,11,11,11,11,4,4,4,13,0,4
1,1,4,4,4,11,14,0,0,0,14,11,4,4,13,0,4
1,4,4,4,14,0,0,0,0,0,0,0,14,4,13,0,4
1,4,4,13,0,0,0,0,0,0,0,0,0,10,13,0,4
1,4,13,14,0,0,0,0,0,0,0,0,0,14,4,0,4
4,4,13,0,0,0,0,0,0,0,0,0,0,0,10,9,4
4,4,13,0,0,0,0,0,0,0,0,0,0,0,10,4,4
4,7,13,0,0,0,0,0,0,0,0,0,0,0,10,4,4
4,0,13,14,0,0,0,0,0,0,0,0,0,14,10,4,1
4,0,10,13,0,0,0,0,0,0,0,0,0,10,4,4,1
4,0,10,4,14,0,0,0,0,0,0,0,14,4,4,4,1
4,0,10,4,4,12,14,0,0,0,14,12,4,4,4,1,1
4,0,10,4,4,4,12,12,12,12,12,11,11,11,11,1,1
1,1,1,1,4,4,4,4,4,6,0,0,0,0,0,1,1
1,1,1,1,1,1,1,4,4,4,4,4,4,4,4,1,1
endlayer

layer
1,1,4,4,4,4,4,4,4,4,1,1,1,1,1,1,1
1,1,0,0,0,0,0,0,8,4,4,4,4,1,1,1,1
1,1,4,9,9,9,9,9,9,4,4,4,4,4,4,0,4
1,1,4,4,4,4,4,4,4,4,4,4,4,4,6,0,4
1,4,4,4,4,11,11,14,14,14,11,11,4,4,6,0,4
1,4,4,4,13,14,0,0,0,0,0,14,10,4,6,0,4
1,4,4,4,13,0,0,0,0,0,0,0,10,4,6,0,4
4,4,4,4,14,0,0,0,0,0,0,0,14,4,6,0,4
4,7,8,4,14,0,0,0,0,0,0,0,14,4,9,9,4
4,0,8,4,14,0,0,0,0,0,0,0,14,4,4,4,4
4,0,8,4,13,0,0,0,0,0,0,0,10,4,4,4,1
4,0,8,4,13,14,0,0,0,0,0,14,10,4,4,4,1
4,0,8,4,4,12,12,14,14,14,12,12,4,4,4,4,1
4,0,8,4,4,4,4,4,4,4,4,4,4,4,4,1,1
4,0,4,4,4,4,4,4,7,7,7,7,7,7,4,1,1
1,1,1,1,4,4,4,4,6,0,0,0,0,0,4,1,1
1,1,1,1,1,1,1,4,4,4,4,4,4,4,4,1,1
endlayer

layer
1,1,4,4,4,4,4,4,4,4,1,1,1,1,1,1,1
1,1,4,0,0,0,0,0,0,0,4,4,4,1,1,1,1
1,1,4,0,0,0,0,0,0,0,0,0,0,4,4,4,4
1,1,4,0,0,0,0,0,0,0,0,0,0,0,0,0,4
1,4,4,4,4,4,9,9,9,9,4,9,0,0,0,0,4
1,4,4,4,4,4,4,11,11,11,4,4,6,0,0,0,4
1,4,4,4,4,4,14,0,0,0,14,4,4,0,0,0,4
4,7,7,7,8,13,0,0,0,0,0,10,6,0,0,0,4
4,0,0,0,8,13,0,0,0,0,0,10,6,0,0,0,4
4,0,0,0,8,13,0,0,0,0,0,10,6,9,9,9,4
4,0,0,0,4,4,14,0,0,0,14,4,4,4,4,4,1
4,0,0,0,8,4,4,12,12,12,4,4,4,4,4,4,1
4,0,0,0,0,7,4,7,7,7,7,4,4,4,4,4,1
4,0,0,0,0,0,0,0,0,0,0,0,0,0,4,1,1
4,4,4,4,0,0,0,0,0,0,0,0,0,0,4,1,1
1,1,1,1,4,4,4,0,0,0,0,0,0,0,4,1,1
1,1,1,1,1,1,1,4,4,4,4,4,4,4,4,1,1
endlayer

layer
1,1,4,4,4,0,4,4,0,4,1,1,1,1,1,1,1
1,1,4,0,0,0,0,0,0,0,4,0,4,1,1,1,1
1,1,0,0,0,0,0,0,0,0,0,0,0,4,0,4,4
1,1,4,0,0,0,0,0,0,0,0,0,0,0,0,0,4
1,4,4,4,4,4,0,0,0,0,4,0,0,0,0,0,4
1,4,4,4,4,4,4,9,9,9,4,4,0,0,0,0,0
1,4,7,7,4,4,4,4,4,4,4,4,4,0,0,0,4
4,0,0,0,0,8,4,15,15,15,4,6,0,0,0,0,4
0,0,0,0,0,8,4,15,0,15,4,6,0,0,0,0,0
4,0,0,0,0,8,4,15,15,15,4,6,0,0,0,0,4
4,0,0,0,4,4,4,4,4,4,4,4,4,9,9,4,1
0,0,0,0,0,4,4,7,7,7,4,4,4,4,4,4,1
4,0,0,0,0,0,4,0,0,0,0,4,4,4,4,4,1
4,0,0,0,0,0,0,0,0,0,0,0,0,0,4,1,1
4,4,0,4,0,0,0,0,0,0,0,0,0,0,0,1,1
1,1,1,1,4,0,4,0,0,0,0,0,0,0,4,1,1
1,1,1,1,1,1,1,4,0,4,4,0,4,4,4,1,1
endlayer

layer
1,1,4,4,4,0,4,4,0,4,1,1,1,1,1,1,1
1,1,4,0,0,0,0,0,0,0,4,0,4,1,1,1,1
1,1,0,0,0,0,0,0,0,0,0,0,0,4,0,4,4
1,1,4,0,0,0,0,0,0,0,0,0,0,0,0,0,4
1,4,4,4,4,4,0,0,0,0,4,0,0,0,0,0,4
1,4,7,7,8,4,4,0,0,0,4,4,0,0,0,0,0
1,4,0,0,8,4,4,0,0,0,4,4,4,0,0,0,4
4,0,0,0,0,0,0,0,0,0,0,0,0,0,0,0,4
0,0,0,0,0,0,0,0,0,0,0,0,0,0,0,0,0
4,0,0,0,0,0,0,0,0,0,0,0,0,0,0,0,4
4,0,0,0,4,4,4,0,0,0,4,4,6,0,0,4,1
0,0,0,0,0,4,4,0,0,0,4,4,6,9,9,4,1
4,0,0,0,0,0,4,0,0,0,0,4,4,4,4,4,1
4,0,0,0,0,0,0,0,0,0,0,0,0,0,4,1,1
4,4,0,4,0,0,0,0,0,0,0,0,0,0,0,1,1
1,1,1,1,4,0,4,0,0,0,0,0,0,0,4,1,1
1,1,1,1,1,1,1,4,0,4,4,0,4,4,4,1,1
endlayer

layer
1,1,4,4,4,4,4,4,4,4,1,1,1,1,1,1,1
1,1,4,0,0,0,0,0,0,0,4,4,4,1,1,1,1
1,1,4,0,0,0,0,0,0,0,0,0,0,4,4,4,4
1,1,4,12,12,12,0,0,0,0,0,0,0,0,0,0,4
1,4,16,16,16,8,0,0,0,0,4,12,0,0,0,0,4
1,4,0,0,0,8,4,0,0,0,4,4,13,0,0,0,4
1,4,0,0,0,8,4,0,0,0,4,4,4,0,0,0,4
4,0,0,0,0,0,0,0,0,0,0,0,0,0,0,0,4
4,0,0,0,0,0,0,0,0,0,0,0,0,0,0,0,4
4,0,0,0,0,0,0,0,0,0,0,0,0,0,0,0,4
4,0,0,0,4,4,4,0,0,0,4,6,0,0,0,4,1
4,0,0,0,10,4,4,0,0,0,4,6,0,0,0,4,1
4,0,0,0,0,11,4,0,0,0,0,6,16,16,16,4,1
4,0,0,0,0,0,0,0,0,0,0,10,11,11,4,1,1
4,4,4,4,0,0,0,0,0,0,0,0,0,0,4,1,1
1,1,1,1,4,4,4,0,0,0,0,0,0,0,4,1,1
1,1,1,1,1,1,1,4,4,4,4,4,4,4,4,1,1
endlayer

layer
1,1,4,4,4,4,4,4,4,4,1,1,1,1,1,1,1
1,1,4,4,4,4,11,11,11,11,4,4,4,1,1,1,1
1,1,4,4,4,4,13,0,0,0,11,11,11,4,4,4,4
1,1,4,4,4,4,13,0,0,0,12,12,0,11,11,10,4
1,4,0,0,0,0,8,0,0,0,4,4,12,0,0,10,4
1,4,0,0,0,0,8,0,0,0,4,4,4,13,0,10,4
1,4,0,0,0,0,8,0,0,0,4,4,4,13,0,10,4
4,13,0,0,0,0,0,0,0,0,0,0,0,0,0,10,4
4,13,0,0,0,0,0,0,0,0,0,0,0,0,0,10,4
4,13,0,0,0,0,0,0,0,0,0,0,0,0,0,10,4
4,13,0,10,4,4,4,0,0,0,6,0,0,0,0,4,1
4,13,0,10,4,4,4,0,0,0,6,0,0,0,0,4,1
4,13,0,0,11,4,4,0,0,0,6,0,0,0,0,4,1
4,13,12,12,0,11,11,0,0,0,10,4,4,4,4,1,1
4,4,4,4,12,12,12,0,0,0,10,4,4,4,4,1,1
1,1,1,1,4,4,4,12,12,12,4,4,4,4,4,1,1
1,1,1,1,1,1,1,4,4,4,4,4,4,4,4,1,1
endlayer

layer
1,1,4,4,4,4,4,4,4,4,1,1,1,1,1,1,1
1,1,4,4,4,4,4,4,4,4,4,4,4,1,1,1,1
1,1,4,4,4,4,4,4,4,4,4,4,4,4,4,4,4
1,1,4,4,4,4,4,4,4,4,4,4,4,4,4,4,4
1,4,0,0,0,0,0,8,4,4,4,4,4,4,4,4,4
1,4,0,0,0,0,0,8,4,4,4,4,4,4,4,4,4
1,4,0,0,0,0,0,8,4,4,4,4,4,4,4,4,4
4,4,0,0,0,0,0,11,11,11,11,11,11,11,11,4,4
4,4,0,0,0,0,0,0,0,0,0,0,0,0,0,4,4
4,4,12,12,12,12,12,12,12,12,0,0,0,0,0,4,4
4,4,4,4,4,4,4,4,4,6,0,0,0,0,0,4,1
4,4,4,4,4,4,4,4,4,6,0,0,0,0,0,4,1
4,4,4,4,4,4,4,4,4,6,0,0,0,0,0,4,1
4,4,4,4,4,4,4,4,4,4,4,4,4,4,4,1,1
4,4,4,4,4,4,4,4,4,4,4,4,4,4,4,1,1
1,1,1,1,4,4,4,4,4,4,4,4,4,4,4,1,1
1,1,1,1,1,1,1,4,4,4,4,4,4,4,4,1,1
endlayer

layer
1,1,1,1,1,1,1,1,1,1,1,1,1,1,1,1,1
1,1,1,4,4,4,4,4,4,4,4,4,4,1,1,1,1
1,1,1,4,4,4,4,4,4,4,4,4,4,1,1,1,1
1,1,1,4,4,4,4,4,4,4,4,4,4,4,4,4,1
1,4,4,0,0,0,0,0,8,4,4,4,4,4,4,4,1
1,4,13,0,0,0,0,0,8,4,4,4,4,4,4,4,1
1,4,13,0,0,0,0,0,8,4,4,4,4,4,4,4,1
1,4,13,0,0,0,10,4,4,4,4,4,4,4,4,4,1
1,4,12,12,12,12,4,4,0,4,11,11,11,11,11,4,1
1,4,4,4,4,4,4,4,4,4,13,0,0,0,10,4,1
1,4,4,4,4,4,4,4,6,0,0,0,0,0,10,4,1
1,4,4,4,4,4,4,4,6,0,0,0,0,0,10,4,1
1,4,4,4,4,4,4,4,6,0,0,0,0,0,4,4,1
1,4,4,4,4,4,4,4,4,4,4,4,4,4,1,1,1
1,1,1,1,4,4,4,4,4,4,4,4,4,4,1,1,1
1,1,1,1,4,4,4,4,4,4,4,4,4,4,1,1,1
1,1,1,1,1,1,1,1,1,1,1,1,1,1,1,1,1
endlayer

layer
1,1,1,1,1,1,1,1,1,1,1,1,1,1,1,1,1
1,1,1,1,1,1,1,1,1,1,1,1,1,1,1,1,1
1,1,1,1,1,1,4,4,4,4,4,4,4,1,1,1,1
1,1,1,4,4,4,4,4,4,4,4,4,4,4,1,1,1
1,1,4,13,0,0,0,0,0,8,4,4,4,4,1,1,1
1,1,4,13,0,0,0,0,0,8,4,4,4,4,1,1,1
1,1,4,13,0,0,0,0,0,8,4,4,4,4,4,1,1
1,1,4,4,4,4,9,9,9,9,4,4,4,4,4,1,1
1,1,4,4,4,4,4,4,15,4,4,4,4,4,4,1,1
1,1,4,4,4,4,4,4,7,7,7,11,11,11,4,1,1
1,1,4,4,4,4,4,6,0,0,0,0,0,10,4,1,1
1,1,1,4,4,4,4,6,0,0,0,0,0,10,4,1,1
1,1,1,4,4,4,4,6,0,0,0,0,0,4,4,1,1
1,1,1,4,4,4,4,4,4,4,4,4,4,4,1,1,1
1,1,1,1,4,4,4,4,4,4,4,1,1,1,1,1,1
1,1,1,1,1,1,1,1,1,1,1,1,1,1,1,1,1
1,1,1,1,1,1,1,1,1,1,1,1,1,1,1,1,1
endlayer

layer
1,1,1,1,1,1,1,1,1,1,1,1,1,1,1,1,1
1,1,1,1,1,1,1,1,1,1,1,1,1,1,1,1,1
1,1,1,1,1,1,4,4,4,4,4,1,1,1,1,1,1
1,1,1,1,4,4,0,0,0,0,10,4,4,1,1,1,1
1,1,1,4,13,0,0,0,0,0,0,0,0,4,1,1,1
1,1,1,4,13,0,0,0,0,0,0,0,0,4,1,1,1
1,1,4,4,13,0,0,0,0,0,0,0,0,0,4,1,1
1,1,4,4,4,4,0,0,0,0,0,0,0,0,4,1,1
1,1,4,4,4,4,0,0,0,0,0,0,0,0,4,1,1
1,1,4,4,4,4,9,0,0,0,0,0,0,0,4,1,1
1,1,4,4,4,4,6,0,0,0,0,0,0,4,4,1,1
1,1,1,4,4,4,6,0,0,0,0,0,0,4,1,1,1
1,1,1,4,4,4,6,0,0,0,0,0,10,4,1,1,1
1,1,1,1,4,4,6,0,0,0,0,4,4,1,1,1,1
1,1,1,1,1,1,4,4,4,4,4,1,1,1,1,1,1
1,1,1,1,1,1,1,1,1,1,1,1,1,1,1,1,1
1,1,1,1,1,1,1,1,1,1,1,1,1,1,1,1,1
endlayer

layer
1,1,1,1,1,1,1,1,1,1,1,1,1,1,1,1,1
1,1,1,1,1,1,1,1,1,1,1,1,1,1,1,1,1
1,1,1,1,1,1,4,4,0,4,4,1,1,1,1,1,1
1,1,1,1,4,4,0,0,0,0,4,4,4,1,1,1,1
1,1,1,4,4,13,0,0,0,0,0,0,10,4,1,1,1
1,1,1,4,4,13,0,0,0,0,0,0,0,4,1,1,1
1,1,4,4,4,13,0,0,0,0,0,0,0,0,4,1,1
1,1,4,4,4,4,0,0,0,0,0,0,0,0,4,1,1
1,1,4,4,4,4,0,0,0,0,0,0,0,0,0,1,1
1,1,4,4,4,6,0,0,0,0,0,0,0,0,4,1,1
1,1,4,16,16,16,0,0,0,0,0,0,0,0,4,1,1
1,1,1,4,16,0,0,0,0,0,0,0,0,4,1,1,1
1,1,1,4,0,0,0,0,0,0,0,0,4,4,1,1,1
1,1,1,1,4,4,0,0,0,0,10,4,4,1,1,1,1
1,1,1,1,1,1,4,4,0,4,4,1,1,1,1,1,1
1,1,1,1,1,1,1,1,1,1,1,1,1,1,1,1,1
1,1,1,1,1,1,1,1,1,1,1,1,1,1,1,1,1
endlayer

layer
1,1,1,1,1,1,1,1,1,1,1,1,1,1,1,1,1
1,1,1,1,1,1,1,1,1,1,1,1,1,1,1,1,1
1,1,1,1,1,1,4,4,0,4,4,1,1,1,1,1,1
1,1,1,1,4,4,0,0,0,0,0,4,4,1,1,1,1
1,1,1,4,4,4,0,0,0,0,0,0,4,4,1,1,1
1,1,1,4,4,4,0,0,0,0,0,0,0,4,1,1,1
1,1,4,4,4,4,0,0,0,0,0,0,0,11,4,1,1
1,1,4,4,4,7,0,0,0,0,0,0,0,0,4,1,1
1,1,16,16,16,0,0,0,0,0,0,0,0,0,0,1,1
1,1,4,0,0,0,0,0,0,0,0,0,0,0,4,1,1
1,1,4,0,0,0,0,0,0,0,0,0,0,0,4,1,1
1,1,1,4,0,0,0,0,0,0,0,0,0,4,1,1,1
1,1,1,4,0,0,0,0,0,0,0,0,0,4,1,1,1
1,1,1,1,4,4,0,0,0,0,4,4,4,1,1,1,1
1,1,1,1,1,1,4,4,0,4,4,1,1,1,1,1,1
1,1,1,1,1,1,1,1,1,1,1,1,1,1,1,1,1
1,1,1,1,1,1,1,1,1,1,1,1,1,1,1,1,1
endlayer

layer
1,1,1,1,1,1,1,1,1,1,1,1,1,1,1,1,1
1,1,1,1,1,1,1,1,1,1,1,1,1,1,1,1,1
1,1,1,1,1,1,4,4,0,4,4,1,1,1,1,1,1
1,1,1,1,4,4,4,14,0,0,0,4,4,1,1,1,1
1,1,1,4,4,4,4,14,0,0,0,0,0,4,1,1,1
1,1,1,4,4,4,4,0,0,0,0,0,0,4,1,1,1
1,1,4,16,16,7,7,0,0,0,0,0,0,4,4,1,1
1,1,4,0,0,0,0,0,0,0,0,0,0,0,4,1,1
1,1,0,0,0,0,0,0,0,0,0,0,0,0,0,1,1
1,1,4,0,0,0,0,0,0,0,0,0,0,0,4,1,1
1,1,4,0,0,0,0,0,0,0,0,0,0,12,4,1,1
1,1,1,4,0,0,0,0,0,0,0,0,0,4,1,1,1
1,1,1,4,0,0,0,0,0,0,0,0,0,4,1,1,1
1,1,1,1,4,4,0,0,0,0,0,4,4,1,1,1,1
1,1,1,1,1,1,4,4,0,4,4,1,1,1,1,1,1
1,1,1,1,1,1,1,1,1,1,1,1,1,1,1,1,1
1,1,1,1,1,1,1,1,1,1,1,1,1,1,1,1,1
endlayer

layer
1,1,1,1,1,1,1,1,1,1,1,1,1,1,1,1,1
1,1,1,1,1,1,1,1,1,1,1,1,1,1,1,1,1
1,1,1,1,1,1,4,4,4,4,4,1,1,1,1,1,1
1,1,1,1,4,4,16,4,4,14,14,4,4,1,1,1,1
1,1,1,4,0,0,16,4,4,14,0,0,0,4,1,1,1
1,1,1,4,0,0,16,8,14,0,0,0,0,4,1,1,1
1,1,4,0,0,0,0,0,0,0,0,0,0,0,4,1,1
1,1,4,0,0,0,0,0,0,0,0,0,0,0,4,1,1
1,1,0,0,0,0,0,0,0,0,0,0,0,0,0,1,1
1,1,4,0,0,0,0,0,0,0,0,0,0,0,4,1,1
1,1,4,0,0,0,0,0,0,0,0,0,0,4,4,1,1
1,1,1,4,0,0,0,0,0,0,0,0,0,4,1,1,1
1,1,1,4,0,0,0,0,0,0,0,0,10,4,1,1,1
1,1,1,1,4,4,0,0,0,0,0,4,4,1,1,1,1
1,1,1,1,1,1,4,4,0,4,4,1,1,1,1,1,1
1,1,1,1,1,1,1,1,1,1,1,1,1,1,1,1,1
1,1,1,1,1,1,1,1,1,1,1,1,1,1,1,1,1
endlayer

layer
1,1,1,1,1,1,1,1,1,1,1,1,1,1,1,1,1
1,1,1,1,1,1,1,1,1,1,1,1,1,1,1,1,1
1,1,1,1,1,1,4,4,4,4,4,1,1,1,1,1,1
1,1,1,1,4,4,0,0,16,4,4,4,4,1,1,1,1
1,1,1,4,0,0,0,0,16,4,4,4,4,4,1,1,1
1,1,1,4,0,0,0,0,16,4,14,14,14,4,1,1,1
1,1,4,0,0,0,0,0,0,0,0,0,0,0,4,1,1
1,1,4,0,0,0,0,0,0,0,0,0,0,0,4,1,1
1,1,0,0,0,0,0,0,0,0,0,0,0,0,0,1,1
1,1,4,0,0,0,0,0,0,0,0,0,0,0,4,1,1
1,1,4,0,0,0,0,0,0,0,0,0,0,0,4,1,1
1,1,1,4,0,0,0,0,0,0,0,0,0,4,1,1,1
1,1,1,4,0,0,0,0,0,0,0,0,4,4,1,1,1
1,1,1,1,4,4,0,0,0,0,12,4,4,1,1,1,1
1,1,1,1,1,1,4,4,0,4,4,1,1,1,1,1,1
1,1,1,1,1,1,1,1,1,1,1,1,1,1,1,1,1
1,1,1,1,1,1,1,1,1,1,1,1,1,1,1,1,1
endlayer

layer
1,1,1,1,1,1,1,1,1,1,1,1,1,1,1,1,1
1,1,1,1,1,1,1,1,1,1,1,1,1,1,1,1,1
1,1,1,1,1,1,4,4,4,4,4,1,1,1,1,1,1
1,1,1,1,4,4,0,0,0,0,16,4,4,1,1,1,1
1,1,1,4,0,0,0,0,0,0,16,4,4,4,1,1,1
1,1,1,4,0,0,0,0,0,0,8,4,4,4,1,1,1
1,1,4,0,0,0,0,0,0,0,8,4,4,4,4,1,1
1,1,4,0,0,0,0,0,0,0,0,0,14,14,4,1,1
1,1,4,0,0,0,0,0,0,0,0,0,0,0,4,1,1
1,1,4,0,0,0,0,0,0,0,0,0,0,0,4,1,1
1,1,4,0,0,0,0,0,0,0,0,0,0,0,4,1,1
1,1,1,4,0,0,0,0,0,0,0,0,0,4,1,1,1
1,1,1,4,0,0,0,0,0,0,0,0,0,4,1,1,1
1,1,1,1,4,4,13,0,0,0,4,4,4,1,1,1,1
1,1,1,1,1,1,4,4,4,4,4,1,1,1,1,1,1
1,1,1,1,1,1,1,1,1,1,1,1,1,1,1,1,1
1,1,1,1,1,1,1,1,1,1,1,1,1,1,1,1,1
endlayer

layer
1,1,1,1,1,1,1,1,1,1,1,1,1,1,1,1,1
1,1,1,1,1,1,1,1,1,1,1,1,1,1,1,1,1
1,1,1,1,1,1,4,4,4,4,4,1,1,1,1,1,1
1,1,1,1,4,4,0,0,0,0,0,4,4,1,1,1,1
1,1,1,4,0,0,0,0,0,0,0,0,0,4,1,1,1
1,1,1,4,0,0,0,0,0,0,0,0,0,4,1,1,1
1,1,4,0,0,0,0,0,0,0,0,16,16,16,4,1,1
1,1,4,0,0,0,0,0,0,0,0,9,4,4,4,1,1
1,1,4,0,0,0,0,0,0,0,0,14,4,4,4,1,1
1,1,4,0,0,0,0,0,0,0,0,0,14,14,4,1,1
1,1,4,0,0,0,0,0,0,0,0,0,0,14,4,1,1
1,1,1,4,0,0,0,0,0,0,0,0,0,4,1,1,1
1,1,1,4,12,0,0,0,0,0,0,0,0,4,1,1,1
1,1,1,1,4,4,4,0,0,0,0,4,4,1,1,1,1
1,1,1,1,1,1,4,4,4,4,4,1,1,1,1,1,1
1,1,1,1,1,1,1,1,1,1,1,1,1,1,1,1,1
1,1,1,1,1,1,1,1,1,1,1,1,1,1,1,1,1
endlayer

layer
1,1,1,1,1,1,1,1,1,1,1,1,1,1,1,1,1
1,1,1,1,1,1,1,1,1,1,1,1,1,1,1,1,1
1,1,1,1,1,1,4,4,4,4,4,4,1,1,1,1,1
1,1,1,1,4,4,0,0,0,0,0,4,4,1,1,1,1
1,1,1,4,0,0,0,0,0,0,0,0,0,4,1,1,1
1,1,1,4,0,0,0,0,0,0,0,0,0,4,4,1,1
1,1,4,11,0,0,0,0,0,0,0,0,0,0,4,1,1
1,1,4,0,0,0,0,0,0,0,0,0,0,0,4,1,1
1,1,4,0,0,0,0,0,0,0,0,16,16,16,4,1,1
1,1,4,0,0,0,0,0,0,0,0,4,4,4,4,1,1
1,1,4,12,0,0,0,0,0,0,0,14,4,4,4,1,1
1,1,1,4,0,0,0,0,0,0,0,14,4,4,1,1,1
1,1,1,4,4,0,0,0,0,0,0,14,4,4,1,1,1
1,1,1,1,4,4,0,0,0,0,0,4,4,1,1,1,1
1,1,1,1,1,4,4,4,4,4,4,1,1,1,1,1,1
1,1,1,1,1,1,1,1,1,1,1,1,1,1,1,1,1
1,1,1,1,1,1,1,1,1,1,1,1,1,1,1,1,1
endlayer

layer
1,1,1,1,1,1,1,1,1,1,1,1,1,1,1,1,1
1,1,1,1,1,1,1,1,1,1,1,1,1,1,1,1,1
1,1,1,1,1,4,4,4,4,4,4,4,4,1,1,1,1
1,1,1,1,4,4,0,0,0,0,0,4,4,1,1,1,1
1,1,1,4,13,0,0,0,0,0,0,0,0,4,4,1,1
1,1,4,4,0,0,0,0,0,0,0,0,0,4,4,1,1
1,1,4,4,0,0,0,0,0,0,0,0,0,0,4,1,1
1,1,4,0,0,0,0,0,0,0,0,0,0,0,4,1,1
1,1,4,0,0,0,0,0,0,0,0,0,0,0,4,1,1
1,1,4,0,0,0,0,0,0,0,0,0,0,0,4,1,1
1,1,4,4,0,0,0,0,0,0,9,9,16,16,4,1,1
1,1,4,4,0,0,0,0,0,0,4,4,4,4,1,1,1
1,1,4,4,0,0,0,0,0,14,4,4,4,4,1,1,1
1,1,1,1,4,4,0,0,0,14,4,4,4,1,1,1,1
1,1,1,1,4,4,4,4,4,4,4,1,1,1,1,1,1
1,1,1,1,1,1,1,1,1,1,1,1,1,1,1,1,1
1,1,1,1,1,1,1,1,1,1,1,1,1,1,1,1,1
endlayer

layer
1,1,1,1,1,1,1,1,1,1,1,1,1,1,1,1,1
1,1,1,1,1,1,1,1,1,1,1,1,1,1,1,1,1
1,1,1,1,4,4,4,4,4,4,4,4,4,4,1,1,1
1,1,1,4,4,4,13,0,0,0,4,4,4,4,4,1,1
1,1,4,4,4,0,0,0,0,0,0,0,10,4,4,1,1
1,1,4,4,0,0,0,0,0,0,0,0,0,4,4,1,1
1,1,4,0,0,0,0,0,0,0,0,0,0,0,4,1,1
1,1,4,0,0,0,0,0,0,0,0,0,0,0,4,1,1
1,1,4,0,0,0,0,0,0,0,0,0,0,0,4,1,1
1,1,4,0,0,0,0,0,0,0,0,0,0,0,4,1,1
1,1,4,0,0,0,0,0,0,0,0,0,0,0,4,1,1
1,1,4,4,0,0,0,0,14,6,16,0,0,4,4,1,1
1,1,4,4,0,0,0,14,4,4,16,0,0,4,1,1,1
1,1,1,4,4,4,14,14,4,4,16,4,4,1,1,1,1
1,1,1,4,4,4,4,4,4,4,4,4,1,1,1,1,1
1,1,1,1,1,1,1,1,1,1,1,1,1,1,1,1,1
1,1,1,1,1,1,1,1,1,1,1,1,1,1,1,1,1
endlayer

layer
1,1,1,1,1,1,1,1,1,1,1,1,1,1,1,1,1
1,1,1,1,4,4,4,4,4,4,4,4,4,4,4,1,1
1,1,4,4,4,4,4,4,4,4,4,4,4,4,4,1,1
1,1,4,4,4,4,4,0,0,0,0,4,4,4,4,1,1
1,4,4,4,0,0,0,0,0,0,0,0,4,4,4,1,1
1,4,4,4,0,0,0,0,0,0,0,0,0,4,4,1,1
1,4,4,0,0,0,0,0,0,0,0,0,0,4,4,1,1
1,4,4,0,0,0,0,0,0,0,0,0,0,0,4,1,1
1,4,4,0,0,0,0,0,0,0,0,0,0,0,4,1,1
1,4,4,0,0,0,0,0,0,0,0,0,0,0,4,1,1
1,4,4,0,0,0,0,0,0,0,0,0,0,0,4,1,1
1,4,4,4,14,14,14,4,16,0,0,0,0,4,4,1,1
1,4,4,4,4,4,4,4,16,0,0,0,0,4,4,1,1
1,4,4,4,4,4,4,4,16,0,0,4,4,4,1,1,1
1,1,4,4,4,4,4,4,4,4,4,4,4,1,1,1,1
1,1,1,1,1,1,1,1,1,1,1,1,1,1,1,1,1
1,1,1,1,1,1,1,1,1,1,1,1,1,1,1,1,1
endlayer

