
# Created by Ruins mod version 16.7 Ingame Parser
# authoring Player: lafuller

weight=1
embed_into_distance=0
acceptable_target_blocks=
unacceptable_target_blocks=flowing_water,water,flowing_lava,lava
dimensions=11,11,11
allowable_overhang=0
max_leveling=0
leveling_buffer=-1
preserve_water=0
preserve_lava=0

rule1=0,100,minecraft:sandstone-0
rule2=0,100,minecraft:sandstone_stairs-7
rule3=0,100,minecraft:sandstone_stairs-6
rule4=0,100,minecraft:double_stone_slab-9
rule5=0,100,minecraft:sandstone_stairs-5
rule6=0,100,minecraft:sandstone_stairs-4
rule7=0,100,minecraft:stone_slab-9
rule8=0,100,minecraft:stone_slab-1

layer
0,1,3,0,0,0,0,0,2,1,0
1,4,4,4,4,4,4,4,4,4,1
5,4,1,1,1,1,1,1,1,4,5
0,4,1,1,1,1,1,1,1,4,0
0,4,1,1,1,1,1,1,1,4,0
0,4,1,1,1,1,1,1,1,4,0
0,4,1,1,1,1,1,1,1,4,0
0,4,1,1,1,1,1,1,1,4,0
6,4,1,1,1,1,1,1,1,4,6
1,4,4,4,4,4,4,4,4,4,1
0,1,3,0,0,0,0,0,2,1,0
endlayer

layer
0,1,1,3,7,0,7,2,1,1,0
1,4,4,4,4,4,4,4,4,4,1
1,4,1,1,1,1,1,1,1,4,1
5,4,1,1,1,1,1,1,1,4,5
7,4,1,1,1,1,1,1,1,4,7
0,4,1,1,1,1,1,1,1,4,0
7,4,1,1,1,1,1,1,1,4,7
6,4,1,1,1,1,1,1,1,4,6
1,4,1,1,1,1,1,1,1,4,1
1,4,4,4,4,4,4,4,4,4,1
0,1,1,3,7,0,7,2,1,1,0
endlayer

layer
0,8,8,1,1,1,1,1,8,8,0
8,4,4,4,4,4,4,4,4,4,8
8,4,1,1,1,1,1,1,1,4,8
1,4,1,1,1,1,1,1,1,4,1
1,4,1,1,1,1,1,1,1,4,1
1,4,1,1,1,1,1,1,1,4,1
1,4,1,1,1,1,1,1,1,4,1
1,4,1,1,1,1,1,1,1,4,1
8,4,1,1,1,1,1,1,1,4,8
8,4,4,4,4,4,4,4,4,4,8
0,8,8,1,1,1,1,1,8,8,0
endlayer

layer
1,1,1,1,1,1,1,1,1,1,1
1,4,4,4,4,4,4,4,4,4,1
1,4,1,1,1,1,1,1,1,4,1
1,4,1,1,1,1,1,1,1,4,1
1,4,1,1,1,1,1,1,1,4,1
1,4,1,1,1,1,1,1,1,4,1
1,4,1,1,1,1,1,1,1,4,1
1,4,1,1,1,1,1,1,1,4,1
1,4,1,1,1,1,1,1,1,4,1
1,4,4,4,4,4,4,4,4,4,1
1,1,1,1,1,1,1,1,1,1,1
endlayer

layer
7,7,7,7,1,1,1,7,7,7,7
7,4,4,4,4,4,4,4,4,4,7
7,4,1,1,1,1,1,1,1,4,7
7,4,1,1,1,1,1,1,1,4,7
1,4,1,1,1,1,1,1,1,4,1
1,4,1,1,1,1,1,1,1,4,1
1,4,1,1,1,1,1,1,1,4,1
7,4,1,1,1,1,1,1,1,4,7
7,4,1,1,1,1,1,1,1,4,7
7,4,4,4,4,4,4,4,4,4,7
7,7,7,7,1,1,1,7,7,7,7
endlayer

layer
8,8,8,8,1,1,1,8,8,8,8
8,4,4,4,4,4,4,4,4,4,8
8,4,1,1,1,1,1,1,1,4,8
8,4,1,1,1,1,1,1,1,4,8
1,4,1,1,1,1,1,1,1,4,1
1,4,1,1,1,1,1,1,1,4,1
1,4,1,1,1,1,1,1,1,4,1
8,4,1,1,1,1,1,1,1,4,8
8,4,1,1,1,1,1,1,1,4,8
8,4,4,4,4,4,4,4,4,4,8
8,8,8,8,1,1,1,8,8,8,8
endlayer

layer
1,1,1,1,1,1,1,1,1,1,1
1,4,4,4,4,4,4,4,4,4,1
1,4,1,1,1,1,1,1,1,4,1
1,4,1,1,1,1,1,1,1,4,1
1,4,1,1,1,1,1,1,1,4,1
1,4,1,1,1,1,1,1,1,4,1
1,4,1,1,1,1,1,1,1,4,1
1,4,1,1,1,1,1,1,1,4,1
1,4,1,1,1,1,1,1,1,4,1
1,4,4,4,4,4,4,4,4,4,1
1,1,1,1,1,1,1,1,1,1,1
endlayer

layer
7,7,7,1,1,1,1,1,7,7,7
7,4,4,4,4,4,4,4,4,4,7
7,4,1,1,1,1,1,1,1,4,7
1,4,1,1,1,1,1,1,1,4,1
1,4,1,1,1,1,1,1,1,4,1
1,4,1,1,1,1,1,1,1,4,1
1,4,1,1,1,1,1,1,1,4,1
1,4,1,1,1,1,1,1,1,4,1
7,4,1,1,1,1,1,1,1,4,7
7,4,4,4,4,4,4,4,4,4,7
7,7,7,1,1,1,1,1,7,7,7
endlayer

layer
8,8,1,1,1,1,1,1,1,8,8
8,4,4,4,4,4,4,4,4,4,8
1,4,1,1,1,1,1,1,1,4,1
1,4,1,1,1,1,1,1,1,4,1
1,4,1,1,1,1,1,1,1,4,1
1,4,1,1,1,1,1,1,1,4,1
1,4,1,1,1,1,1,1,1,4,1
1,4,1,1,1,1,1,1,1,4,1
1,4,1,1,1,1,1,1,1,4,1
8,4,4,4,4,4,4,4,4,4,8
8,8,1,1,1,1,1,1,1,8,8
endlayer

layer
1,1,1,1,8,8,8,1,1,1,1
1,4,4,4,4,4,4,4,4,4,1
1,4,1,1,1,1,1,1,1,4,1
1,4,1,1,1,1,1,1,1,4,1
8,4,1,1,1,1,1,1,1,4,8
8,4,1,1,1,1,1,1,1,4,8
8,4,1,1,1,1,1,1,1,4,8
1,4,1,1,1,1,1,1,1,4,1
1,4,1,1,1,1,1,1,1,4,1
1,4,4,4,4,4,4,4,4,4,1
1,1,1,1,8,8,8,1,1,1,1
endlayer

layer
0,8,0,0,0,0,0,0,0,8,0
8,8,8,0,0,0,0,0,8,8,8
0,8,8,0,0,0,0,0,8,8,0
0,0,0,0,0,0,0,0,0,0,0
0,0,0,0,0,0,0,0,0,0,0
0,0,0,0,0,0,0,0,0,0,0
0,0,0,0,0,0,0,0,0,0,0
0,0,0,0,0,0,0,0,0,0,0
0,8,8,0,0,0,0,0,8,8,0
8,8,8,0,0,0,0,0,8,8,8
0,8,0,0,0,0,0,0,0,8,0
endlayer

