
# Created by Ruins mod version 16.7 Ingame Parser
# authoring Player: lafuller

weight=1
embed_into_distance=4
acceptable_target_blocks=
unacceptable_target_blocks=flowing_water,water,flowing_lava,lava,ice,bedrock,netherrack,nether_brick,nether_brick_fence,soul_sand,quartz_ore,end_stone,obsidian,iron_bars,cloud,flesh,ash_block,slime_grass,slime_congealed,slime_dirt
biomesToSpawnIn=plains,forest,prarie,meadow,tundra,brushland,shrubland,woodland,woodlands,birch_forestlavender_fields,flower_field,sunflower_plains,ice_flats,ice_plains
dimensions=21,16,16
allowable_overhang=0
max_leveling=4
leveling_buffer=-1
preserve_water=0
preserve_lava=0

rule1=0,100,preserveBlock
rule2=0,100,minecraft:stone-6
rule3=0,100,stonebrick-0,stonebrick-0,stonebrick-0,stonebrick-0,stonebrick-1,stonebrick-2,stonebrick-2,stone-5,stone-6,cobblestone
rule4=0,100,stonebrick-0,stonebrick-2,stonebrick-1,stonebrick-1,stonebrick-1,cobblestone
rule5=0,100,stonebrick-0,stonebrick-1,stonebrick-2,stonebrick-2,stone-5,stone-5,stone-6,stone-6
rule6=0,100,minecraft:stone_brick_stairs-0
rule7=0,100,stonebrick-0,stonebrick-2,stonebrick-0,stonebrick-1,stonebrick-1,cobblestone
rule8=0,100,minecraft:dirt-0
rule9=0,100,minecraft:stone_brick_stairs-3
rule10=0,100,minecraft:stone-5
rule11=0,100,minecraft:stone_brick_stairs-1
rule12=0,100,air
rule13=0,100,stonebrick-0,stonebrick-0,stonebrick-0,stonebrick-0,stonebrick-1,stonebrick-2,stonebrick-2,stone-5,stone-6,cobblestone,gravel
rule14=0,100,minecraft:cobblestone_wall-0
rule15=0,100,minecraft:log-0
rule16=0,100,minecraft:wooden_slab-9
rule17=0,100,minecraft:web-0
rule18=0,100,minecraft:wooden_slab-1
rule19=0,100,minecraft:spruce_stairs-0
rule20=0,100,minecraft:planks-1
rule21=0,100,bookshelf,hay_block,ChestGenHook:chests/spawn_bonus_chest:5-2,ChestGenHook:chests/village_blacksmith:5-2,ChestGenHook:chests/simple_dungeon:5-2,ChestGenHook:chests/abandoned_mineshaft:5-2,ChestGenHook:chests/stronghold_library:5-2,ChestGenHook:chests/stronghold_corridor:5-2,ChestGenHook:chests/stronghold_crossing:5-2,ChestGenHook:chests/igloo_chest:5-2
rule22=0,100,minecraft:stone_brick_stairs-4
rule23=0,100,minecraft:stone_brick_stairs-5
rule24=0,100,minecraft:stone_brick_stairs-7
rule25=0,100,minecraft:stone_brick_stairs-6
rule26=0,100,minecraft:spruce_stairs-2
rule27=0,100,minecraft:spruce_stairs-7
rule28=0,100,minecraft:log-7
rule29=0,100,minecraft:log-11
rule30=0,100,minecraft:planks-0
rule31=0,100,minecraft:wooden_slab-8
rule32=0,100,minecraft:oak_stairs-5
rule33=0,100,minecraft:spruce_stairs-5
rule34=0,100,minecraft:mycelium-0
rule35=0,100,minecraft:oak_stairs-4
rule36=0,100,minecraft:spruce_stairs-4
rule37=0,100,minecraft:stone-2
rule38=0,100,minecraft:stone-1
rule39=0,100,minecraft:spruce_fence_gate-5
rule40=0,100,minecraft:spruce_fence_gate-6
rule41=0,100,minecraft:spruce_door-1
rule42=0,100,minecraft:spruce_door-3
rule43=0,100,minecraft:spruce_fence-0
rule44=0,100,minecraft:fence-0
rule45=0,100,minecraft:carpet-7
rule46=0,100,minecraft:stone_brick_stairs-2
rule47=0,100,IInventory;minecraft:furnace;minecraft:coal#2#1#1-2
rule48=0,100,minecraft:spruce_door-8
rule49=0,100,minecraft:oak_stairs-7
rule50=0,100,minecraft:oak_stairs-6
rule51=0,100,minecraft:trapdoor-0
rule52=0,100,minecraft:stone_slab-13
rule53=0,100,minecraft:spruce_fence_gate-0
rule54=0,100,minecraft:spruce_fence_gate-2
rule55=0,100,minecraft:wooden_slab-13
rule56=0,100,minecraft:dark_oak_stairs-6
rule57=0,100,minecraft:dark_oak_stairs-4
rule58=0,100,minecraft:double_wooden_slab-5
rule59=0,100,minecraft:dark_oak_stairs-3
rule60=0,100,minecraft:dark_oak_stairs-7
rule61=0,100,minecraft:dark_oak_fence-0
rule62=0,100,minecraft:spruce_stairs-3
rule63=0,100,minecraft:dark_oak_stairs-5
rule64=0,100,minecraft:spruce_stairs-1
rule65=0,100,minecraft:dark_oak_stairs-2
rule66=0,100,minecraft:dark_oak_stairs-0
rule67=0,100,minecraft:wooden_slab-5
rule68=0,100,minecraft:planks-5
rule69=0,100,minecraft:spruce_stairs-6
rule70=0,100,minecraft:dark_oak_stairs-1
rule71=0,100,minecraft:trapdoor-11
rule72=0,100,minecraft:stone_slab-5
rule73=0,100,minecraft:iron_bars-0
rule74=0,100,minecraft:stone_slab-0

layer
1,1,1,1,1,1,1,1,1,1,1,1,1,1,1,1
1,1,1,1,1,1,1,1,3,3,3,2,1,1,1,1
1,1,1,1,3,3,3,2,2,4,4,2,2,1,1,1
1,1,1,3,3,2,4,4,4,5,4,4,3,1,1,1
1,1,1,3,4,4,5,5,5,5,4,4,3,6,6,6
1,1,1,3,4,2,7,5,7,7,5,4,3,3,3,3
1,2,1,3,4,5,7,7,7,5,5,4,2,3,3,2
2,3,3,8,3,4,5,7,7,7,5,5,4,3,2,1
1,3,8,8,3,2,4,5,7,7,7,7,5,4,3,2
2,8,8,3,3,3,3,4,5,5,7,7,5,4,3,1
1,3,8,8,8,3,3,4,5,7,7,7,5,4,3,2
2,3,3,3,3,3,3,4,5,7,7,5,4,3,2,1
9,3,3,3,3,3,3,2,4,5,5,5,4,3,3,2
9,3,10,1,10,1,10,3,4,4,4,4,4,3,3,3
1,1,1,1,1,1,1,3,3,3,3,3,3,3,11,11
12,1,1,1,1,1,1,1,1,1,1,1,1,1,1,1
endlayer

layer
1,1,1,1,1,1,1,1,1,1,1,1,1,1,1,1
1,1,1,1,1,1,1,1,13,14,13,10,1,1,1,1
1,1,1,1,13,13,13,10,15,16,16,15,10,1,1,1
1,1,1,13,13,15,17,12,12,12,12,17,14,1,1,1
1,1,1,14,16,12,12,12,12,12,12,12,13,1,1,1
1,1,1,13,16,12,12,12,12,12,12,12,13,13,6,6
1,13,1,13,16,12,12,12,12,12,12,12,15,13,13,13
13,13,13,8,13,17,12,12,12,12,12,12,17,13,10,1
1,13,8,8,13,15,17,12,12,12,12,12,12,16,14,13
13,8,8,13,13,13,13,12,12,12,12,12,12,16,13,1
1,13,8,8,8,13,13,12,12,12,12,12,12,15,13,13
13,13,13,13,13,13,13,17,12,12,12,12,12,13,10,1
1,9,13,13,13,13,13,15,12,12,12,12,12,13,13,13
1,9,13,1,13,1,13,13,21,12,20,19,18,13,11,11
1,1,1,1,1,1,1,13,14,13,14,13,14,13,1,1
1,1,1,1,1,1,1,1,1,1,1,1,1,1,1,1
endlayer

layer
1,1,1,1,1,1,1,1,1,1,1,1,1,1,1,1
1,1,1,1,1,1,1,1,13,14,13,2,1,1,1,1
1,1,1,1,13,13,13,2,15,17,17,15,2,1,1,1
1,1,1,13,13,15,17,17,12,12,12,17,14,1,1,1
1,1,1,14,17,17,12,12,12,12,12,17,13,1,1,1
1,1,1,13,17,12,12,12,12,12,12,12,13,13,1,1
1,13,22,13,17,17,12,12,12,12,12,12,15,13,6,6
13,13,13,8,13,17,12,12,12,12,12,12,17,13,2,23
24,13,8,8,13,15,17,12,12,12,12,12,12,17,14,13
13,8,8,13,13,13,13,12,12,12,12,12,12,17,13,25
24,13,8,8,8,13,13,17,12,12,12,12,12,15,13,13
13,13,13,13,13,13,13,17,12,12,12,12,12,13,2,22
1,1,9,13,13,13,13,15,17,12,12,12,12,13,11,11
1,1,9,23,13,23,13,13,12,27,26,12,12,14,1,1
1,1,1,1,1,1,1,13,14,13,14,13,14,13,1,1
1,1,1,1,1,1,1,1,1,1,1,1,1,1,1,1
endlayer

layer
1,1,1,1,1,1,1,1,1,1,1,1,1,1,1,1
1,1,1,1,1,1,1,1,13,14,13,10,1,1,1,1
1,1,1,1,13,13,13,10,15,17,17,15,10,1,1,1
1,1,1,13,13,28,17,17,17,12,17,17,14,1,1,1
1,1,1,14,17,28,17,12,12,12,12,17,13,1,1,1
1,1,1,13,29,28,12,12,12,12,12,17,13,13,1,1
1,13,2,13,17,28,17,12,12,12,12,17,15,13,1,1
13,13,8,8,13,28,17,17,12,12,12,17,17,13,10,6
2,8,8,8,13,28,17,12,12,12,12,12,17,17,14,13
13,8,8,13,13,13,13,17,17,12,12,12,12,17,13,13
2,8,8,8,8,13,13,17,12,12,12,12,17,15,13,13
13,2,13,13,13,13,13,17,17,12,12,12,12,13,10,11
1,1,1,9,13,13,13,15,17,12,12,12,12,13,1,1
1,1,1,9,13,13,13,13,27,26,12,12,12,14,1,1
1,1,1,1,1,1,1,13,14,13,14,13,13,13,1,1
1,1,1,1,1,1,1,1,1,1,1,1,1,1,1,1
endlayer

layer
1,1,1,1,1,1,1,1,1,1,1,1,1,1,1,1
1,1,1,1,1,1,1,1,13,13,13,2,1,1,1,1
1,1,1,1,1,13,13,2,30,31,31,30,2,1,1,1
1,1,1,1,2,10,10,32,32,33,33,32,13,1,1,1
1,1,1,13,10,10,10,16,16,16,31,31,13,1,1,1
1,1,1,13,10,10,10,16,31,31,16,31,2,13,1,1
1,10,10,10,10,10,10,31,31,16,16,31,30,13,1,1
13,10,34,34,10,10,10,32,32,32,33,33,32,2,2,1
13,2,34,34,10,10,10,16,31,31,16,31,16,31,13,6
9,2,2,10,10,10,2,35,36,35,35,35,36,35,13,2
9,3,3,3,10,3,3,31,16,16,31,31,16,30,13,11
13,11,11,11,11,3,3,35,36,35,35,36,35,2,2,1
1,1,1,1,9,2,13,30,31,16,16,16,31,13,1,1
1,1,1,1,9,2,2,2,18,12,12,12,12,13,1,1
1,1,1,1,1,1,1,13,13,13,13,13,13,13,1,1
1,1,1,1,1,1,1,1,1,1,1,1,1,1,1,1
endlayer

layer
1,1,1,1,1,1,1,1,1,1,1,1,1,1,1,1
1,1,1,1,1,1,1,1,37,38,37,2,1,1,1,1
1,1,1,1,1,37,38,2,12,39,39,12,37,1,1,1
1,1,1,1,2,12,39,39,12,12,12,12,38,1,1,1
1,1,1,37,37,12,12,12,12,12,12,40,37,1,1,1
1,1,1,2,37,12,12,12,12,12,12,40,2,1,1,1
1,2,2,2,6,12,12,12,12,12,12,12,12,37,1,1
2,2,12,12,25,12,12,12,12,12,12,12,12,2,38,1
2,2,12,12,13,37,37,37,37,12,12,12,12,12,37,1
1,12,12,12,2,2,2,12,12,12,12,12,12,12,41,12
1,12,12,12,12,12,37,12,12,12,12,12,12,12,37,1
1,1,1,12,12,12,42,12,12,12,12,12,12,37,38,1
1,1,1,1,12,12,37,12,12,12,43,43,43,38,1,1
1,1,1,1,1,1,1,2,12,12,12,12,12,37,1,1
1,1,1,1,1,1,1,1,37,38,38,37,2,1,1,1
1,1,1,1,1,1,1,1,1,1,1,1,1,1,1,1
endlayer

layer
1,1,1,1,1,1,1,1,1,1,1,1,1,1,1,1
1,1,1,1,1,1,1,1,44,12,44,15,43,1,1,1
1,1,1,1,44,12,44,15,12,45,45,12,44,1,1,1
1,1,1,44,15,12,45,45,12,12,12,12,12,1,1,1
1,1,1,44,12,12,12,12,12,12,12,45,44,1,1,1
1,1,24,6,12,12,12,12,12,12,12,45,15,1,1,1
1,6,25,13,46,12,12,12,12,12,12,12,12,44,1,1
1,14,12,12,47,12,12,12,12,12,12,12,12,15,1,1
1,12,12,12,25,12,12,12,12,12,12,12,12,12,30,1
1,12,12,12,9,14,15,12,12,12,12,12,12,12,48,12
1,12,12,12,12,12,30,12,12,12,12,12,12,12,30,1
1,1,1,12,12,12,48,12,12,12,12,12,12,15,1,1
1,1,1,1,12,12,30,12,12,12,12,12,12,44,1,1
1,1,1,1,1,1,1,15,12,12,12,12,12,44,1,1
1,1,1,1,1,1,1,43,44,44,12,44,15,1,1,1
1,1,1,1,1,1,1,1,1,1,1,1,1,1,1,1
endlayer

layer
1,1,1,1,1,1,1,1,1,1,1,1,1,1,1,1
1,1,1,1,1,1,1,49,35,35,35,15,1,1,1,1
1,1,1,1,49,35,35,15,12,12,12,12,50,1,1,1
1,1,1,1,15,12,12,12,12,12,12,12,50,1,1,1
1,1,1,49,51,12,12,12,12,12,12,12,50,1,1,1
1,1,6,13,51,12,12,12,12,12,12,12,15,1,1,1
1,9,13,13,22,12,12,12,12,12,12,12,1,50,1,1
1,13,12,12,46,12,12,12,12,12,12,12,12,15,35,1
1,52,12,12,9,12,16,16,16,12,12,12,12,12,50,1
1,12,52,52,13,14,15,12,12,12,12,12,12,12,53,12
1,12,12,12,12,12,49,12,12,12,12,12,12,12,50,1
1,1,1,12,12,12,54,12,12,12,12,12,12,15,32,1
1,1,1,1,12,12,49,12,12,12,12,12,12,50,1,1
1,1,1,1,1,1,1,15,12,12,12,12,12,50,1,1
1,1,1,1,1,1,1,1,32,32,32,32,15,1,1,1
1,1,1,1,1,1,1,1,1,1,1,1,1,1,1,1
endlayer

layer
1,1,1,1,1,1,1,55,1,1,1,55,55,1,1,1
1,1,1,1,55,1,1,57,19,19,19,15,56,1,1,1
1,1,1,59,58,19,19,15,43,43,43,43,26,1,1,1
1,1,55,27,15,43,43,12,12,12,12,12,26,1,1,1
1,1,60,20,43,12,12,12,12,12,12,12,26,1,1,1
1,1,6,13,12,12,12,12,12,12,12,12,15,36,55,1
1,22,13,13,52,12,12,12,12,12,12,12,43,26,1,1
1,9,25,12,25,12,12,12,12,12,12,12,12,15,57,55
1,9,52,22,46,12,61,12,61,12,12,12,12,43,26,1
1,1,11,11,9,14,15,12,12,12,12,12,12,43,26,1
1,1,12,12,12,12,62,12,12,12,12,12,12,43,26,1
1,1,1,1,12,12,62,12,12,12,12,12,12,15,63,55
1,1,1,1,12,27,20,12,12,12,12,12,12,26,1,1
1,1,1,1,1,1,63,15,43,43,43,43,43,26,1,1
1,1,1,1,1,1,55,60,20,64,64,64,15,63,1,1
1,1,1,1,1,1,1,1,55,1,1,1,55,1,1,1
endlayer

layer
1,1,1,1,1,1,1,1,67,66,66,65,1,1,1,1
1,1,1,1,1,67,66,68,68,68,68,15,65,1,1,1
1,1,1,1,66,68,68,15,33,33,33,33,68,67,1,1
1,1,1,59,15,33,33,12,12,12,12,27,68,65,1,1
1,1,67,68,69,12,12,12,12,12,12,33,68,66,1,1
1,1,1,25,22,12,12,12,12,12,12,12,15,68,1,1
1,1,24,13,13,25,12,12,12,12,12,12,33,68,67,1
1,1,24,12,13,25,12,12,12,12,12,12,12,15,65,1
1,1,11,11,13,25,61,12,61,12,12,12,12,27,68,67
1,1,1,1,67,70,15,12,12,12,12,12,12,27,68,65
1,1,1,1,67,59,68,36,12,12,12,12,12,27,68,67
1,1,1,1,67,68,68,69,12,12,12,12,12,15,65,1
1,1,1,1,67,59,68,69,12,12,12,12,36,68,67,1
1,1,1,1,1,67,70,15,36,36,36,36,27,68,67,1
1,1,1,1,1,1,1,59,68,68,68,68,70,1,1,1
1,1,1,1,1,1,1,1,1,67,70,67,1,1,1,1
endlayer

layer
1,1,1,1,1,1,1,1,1,1,1,1,1,1,1,1
1,1,1,1,1,1,1,1,59,66,66,66,1,1,1,1
1,1,1,1,1,1,66,66,68,68,68,68,66,1,1,1
1,1,1,1,67,59,68,33,33,33,33,68,65,1,1,1
1,1,1,1,67,59,68,69,16,16,27,68,65,1,1,1
1,1,1,1,67,59,68,69,12,12,12,27,68,65,1,1
1,1,52,22,13,59,68,69,12,12,12,27,68,65,1,1
1,1,9,12,13,59,68,69,12,12,12,33,27,65,1,1
1,1,9,23,23,70,68,69,61,12,12,16,27,68,1,1
1,1,1,1,1,1,70,36,36,36,36,36,36,68,65,1
1,1,1,1,1,1,59,68,69,16,16,16,27,68,70,1
1,1,1,1,1,1,59,68,69,16,12,16,36,65,1,1
1,1,1,1,1,1,67,59,36,36,36,27,68,65,1,1
1,1,1,1,1,1,1,59,68,68,68,68,65,1,1,1
1,1,1,1,1,1,1,1,70,70,70,70,1,1,1,1
1,1,1,1,1,1,1,1,1,1,1,1,1,1,1,1
endlayer

layer
1,1,1,1,1,1,1,1,1,1,1,1,1,1,1,1
1,1,1,1,1,1,1,1,1,1,1,1,1,1,1,1
1,1,1,1,1,1,1,1,67,66,67,1,1,1,1,1
1,1,1,1,1,1,1,66,68,68,68,67,1,1,1,1
1,1,1,1,1,1,67,68,68,68,68,65,1,1,1,1
1,1,1,1,1,1,59,68,68,68,68,68,67,1,1,1
1,1,9,22,22,1,59,68,68,71,68,68,65,1,1,1
1,1,9,12,46,1,59,68,68,68,68,68,65,1,1,1
1,1,23,11,23,1,1,68,68,68,68,68,68,1,1,1
1,1,1,1,1,1,1,68,68,68,68,68,68,67,1,1
1,1,1,1,1,1,1,59,68,68,68,68,68,1,1,1
1,1,1,1,1,1,1,1,68,68,43,68,68,1,1,1
1,1,1,1,1,1,1,1,70,68,68,68,67,1,1,1
1,1,1,1,1,1,1,1,1,70,70,67,1,1,1,1
1,1,1,1,1,1,1,1,1,1,1,1,1,1,1,1
1,1,1,1,1,1,1,1,1,1,1,1,1,1,1,1
endlayer

layer
1,1,1,1,1,1,1,1,1,1,1,1,1,1,1,1
1,1,1,1,1,1,1,1,1,1,1,1,1,1,1,1
1,1,1,1,1,1,1,1,1,1,1,1,1,1,1,1
1,1,1,1,1,1,1,1,61,61,61,1,1,1,1,1
1,1,1,1,1,1,1,61,61,1,61,1,1,1,1,1
1,1,1,1,1,1,1,61,1,1,1,61,1,1,1,1
1,1,6,6,25,1,1,61,1,1,1,61,1,1,1,1
1,1,24,12,25,1,1,61,1,1,1,61,1,1,1,1
1,1,24,11,11,1,1,61,1,1,1,61,61,1,1,1
1,1,1,1,1,1,1,61,61,1,1,1,61,1,1,1
1,1,1,1,1,1,1,1,61,1,1,1,61,1,1,1
1,1,1,1,1,1,1,1,61,61,1,61,1,1,1,1
1,1,1,1,1,1,1,1,1,61,61,61,1,1,1,1
1,1,1,1,1,1,1,1,1,1,1,1,1,1,1,1
1,1,1,1,1,1,1,1,1,1,1,1,1,1,1,1
1,1,1,1,1,1,1,1,1,1,1,1,1,1,1,1
endlayer

layer
1,1,1,1,1,1,1,1,1,1,1,1,1,1,1,1
1,1,1,1,1,1,1,1,1,1,1,1,1,1,1,1
1,1,1,1,1,1,1,1,1,1,1,1,1,1,1,1
1,1,1,1,1,1,1,1,1,1,1,1,1,1,1,1
1,1,1,1,1,1,1,1,1,1,1,1,1,1,1,1
1,1,1,1,1,1,1,1,1,1,1,1,1,1,1,1
1,1,1,13,6,1,1,1,1,1,1,1,1,1,1,1
1,1,9,12,13,1,1,1,1,1,1,1,1,1,1,1
1,1,23,13,11,1,1,1,1,1,1,1,1,1,1,1
1,1,1,1,1,1,1,1,1,1,1,1,1,1,1,1
1,1,1,1,1,1,1,1,1,1,1,1,1,1,1,1
1,1,1,1,1,1,1,1,1,1,1,1,1,1,1,1
1,1,1,1,1,1,1,1,1,1,1,1,1,1,1,1
1,1,1,1,1,1,1,1,1,1,1,1,1,1,1,1
1,1,1,1,1,1,1,1,1,1,1,1,1,1,1,1
1,1,1,1,1,1,1,1,1,1,1,1,1,1,1,1
endlayer

layer
1,1,1,1,1,1,1,1,1,1,1,1,1,1,1,1
1,1,1,1,1,1,1,1,1,1,1,1,1,1,1,1
1,1,1,1,1,1,1,1,1,1,1,1,1,1,1,1
1,1,1,1,1,1,1,1,1,1,1,1,1,1,1,1
1,1,1,1,1,1,1,1,1,1,1,1,1,1,1,1
1,1,1,1,1,1,1,1,1,1,1,1,1,1,1,1
1,1,24,13,46,1,1,1,1,1,1,1,1,1,1,1
1,1,9,12,13,1,1,1,1,1,1,1,1,1,1,1
1,1,1,11,1,1,1,1,1,1,1,1,1,1,1,1
1,1,1,1,1,1,1,1,1,1,1,1,1,1,1,1
1,1,1,1,1,1,1,1,1,1,1,1,1,1,1,1
1,1,1,1,1,1,1,1,1,1,1,1,1,1,1,1
1,1,1,1,1,1,1,1,1,1,1,1,1,1,1,1
1,1,1,1,1,1,1,1,1,1,1,1,1,1,1,1
1,1,1,1,1,1,1,1,1,1,1,1,1,1,1,1
1,1,1,1,1,1,1,1,1,1,1,1,1,1,1,1
endlayer

layer
1,1,1,1,1,1,1,1,1,1,1,1,1,1,1,1
1,1,1,1,1,1,1,1,1,1,1,1,1,1,1,1
1,1,1,1,1,1,1,1,1,1,1,1,1,1,1,1
1,1,1,1,1,1,1,1,1,1,1,1,1,1,1,1
1,1,1,1,1,1,1,1,1,1,1,1,1,1,1,1
1,1,1,1,1,1,1,1,1,1,1,1,1,1,1,1
1,1,6,13,1,1,1,1,1,1,1,1,1,1,1,1
1,1,13,12,46,1,1,1,1,1,1,1,1,1,1,1
1,1,1,23,1,1,1,1,1,1,1,1,1,1,1,1
1,1,1,1,1,1,1,1,1,1,1,1,1,1,1,1
1,1,1,1,1,1,1,1,1,1,1,1,1,1,1,1
1,1,1,1,1,1,1,1,1,1,1,1,1,1,1,1
1,1,1,1,1,1,1,1,1,1,1,1,1,1,1,1
1,1,1,1,1,1,1,1,1,1,1,1,1,1,1,1
1,1,1,1,1,1,1,1,1,1,1,1,1,1,1,1
1,1,1,1,1,1,1,1,1,1,1,1,1,1,1,1
endlayer

layer
1,1,1,1,1,1,1,1,1,1,1,1,1,1,1,1
1,1,1,1,1,1,1,1,1,1,1,1,1,1,1,1
1,1,1,1,1,1,1,1,1,1,1,1,1,1,1,1
1,1,1,1,1,1,1,1,1,1,1,1,1,1,1,1
1,1,1,1,1,1,1,1,1,1,1,1,1,1,1,1
1,1,1,1,1,1,1,1,1,1,1,1,1,1,1,1
1,1,1,22,1,1,1,1,1,1,1,1,1,1,1,1
1,1,13,12,25,1,1,1,1,1,1,1,1,1,1,1
1,1,9,13,1,1,1,1,1,1,1,1,1,1,1,1
1,1,1,1,1,1,1,1,1,1,1,1,1,1,1,1
1,1,1,1,1,1,1,1,1,1,1,1,1,1,1,1
1,1,1,1,1,1,1,1,1,1,1,1,1,1,1,1
1,1,1,1,1,1,1,1,1,1,1,1,1,1,1,1
1,1,1,1,1,1,1,1,1,1,1,1,1,1,1,1
1,1,1,1,1,1,1,1,1,1,1,1,1,1,1,1
1,1,1,1,1,1,1,1,1,1,1,1,1,1,1,1
endlayer

layer
1,1,1,1,1,1,1,1,1,1,1,1,1,1,1,1
1,1,1,1,1,1,1,1,1,1,1,1,1,1,1,1
1,1,1,1,1,1,1,1,1,1,1,1,1,1,1,1
1,1,1,1,1,1,1,1,1,1,1,1,1,1,1,1
1,1,1,1,1,1,1,1,1,1,1,1,1,1,1,1
1,1,1,1,1,1,1,1,1,1,1,1,1,1,1,1
1,1,1,22,1,1,1,1,1,1,1,1,1,1,1,1
1,1,9,12,13,1,1,1,1,1,1,1,1,1,1,1
1,1,1,13,72,1,1,1,1,1,1,1,1,1,1,1
1,1,1,1,1,1,1,1,1,1,1,1,1,1,1,1
1,1,1,1,1,1,1,1,1,1,1,1,1,1,1,1
1,1,1,1,1,1,1,1,1,1,1,1,1,1,1,1
1,1,1,1,1,1,1,1,1,1,1,1,1,1,1,1
1,1,1,1,1,1,1,1,1,1,1,1,1,1,1,1
1,1,1,1,1,1,1,1,1,1,1,1,1,1,1,1
1,1,1,1,1,1,1,1,1,1,1,1,1,1,1,1
endlayer

layer
1,1,1,1,1,1,1,1,1,1,1,1,1,1,1,1
1,1,1,1,1,1,1,1,1,1,1,1,1,1,1,1
1,1,1,1,1,1,1,1,1,1,1,1,1,1,1,1
1,1,1,1,1,1,1,1,1,1,1,1,1,1,1,1
1,1,1,1,1,1,1,1,1,1,1,1,1,1,1,1
1,1,1,1,1,1,1,1,1,1,1,1,1,1,1,1
1,1,1,13,1,1,1,1,1,1,1,1,1,1,1,1
1,1,24,12,46,1,1,1,1,1,1,1,1,1,1,1
1,1,1,23,1,1,1,1,1,1,1,1,1,1,1,1
1,1,1,1,1,1,1,1,1,1,1,1,1,1,1,1
1,1,1,1,1,1,1,1,1,1,1,1,1,1,1,1
1,1,1,1,1,1,1,1,1,1,1,1,1,1,1,1
1,1,1,1,1,1,1,1,1,1,1,1,1,1,1,1
1,1,1,1,1,1,1,1,1,1,1,1,1,1,1,1
1,1,1,1,1,1,1,1,1,1,1,1,1,1,1,1
1,1,1,1,1,1,1,1,1,1,1,1,1,1,1,1
endlayer

layer
1,1,1,1,1,1,1,1,1,1,1,1,1,1,1,1
1,1,1,1,1,1,1,1,1,1,1,1,1,1,1,1
1,1,1,1,1,1,1,1,1,1,1,1,1,1,1,1
1,1,1,1,1,1,1,1,1,1,1,1,1,1,1,1
1,1,1,1,1,1,1,1,1,1,1,1,1,1,1,1
1,1,1,1,1,1,1,1,1,1,1,1,1,1,1,1
1,1,1,6,1,1,1,1,1,1,1,1,1,1,1,1
1,1,9,73,46,1,1,1,1,1,1,1,1,1,1,1
1,1,1,23,1,1,1,1,1,1,1,1,1,1,1,1
1,1,1,1,1,1,1,1,1,1,1,1,1,1,1,1
1,1,1,1,1,1,1,1,1,1,1,1,1,1,1,1
1,1,1,1,1,1,1,1,1,1,1,1,1,1,1,1
1,1,1,1,1,1,1,1,1,1,1,1,1,1,1,1
1,1,1,1,1,1,1,1,1,1,1,1,1,1,1,1
1,1,1,1,1,1,1,1,1,1,1,1,1,1,1,1
1,1,1,1,1,1,1,1,1,1,1,1,1,1,1,1
endlayer

layer
1,1,1,1,1,1,1,1,1,1,1,1,1,1,1,1
1,1,1,1,1,1,1,1,1,1,1,1,1,1,1,1
1,1,1,1,1,1,1,1,1,1,1,1,1,1,1,1
1,1,1,1,1,1,1,1,1,1,1,1,1,1,1,1
1,1,1,1,1,1,1,1,1,1,1,1,1,1,1,1
1,1,1,1,1,1,1,1,1,1,1,1,1,1,1,1
1,1,1,74,1,1,1,1,1,1,1,1,1,1,1,1
1,1,74,12,74,1,1,1,1,1,1,1,1,1,1,1
1,1,1,74,1,1,1,1,1,1,1,1,1,1,1,1
1,1,1,1,1,1,1,1,1,1,1,1,1,1,1,1
1,1,1,1,1,1,1,1,1,1,1,1,1,1,1,1
1,1,1,1,1,1,1,1,1,1,1,1,1,1,1,1
1,1,1,1,1,1,1,1,1,1,1,1,1,1,1,1
1,1,1,1,1,1,1,1,1,1,1,1,1,1,1,1
1,1,1,1,1,1,1,1,1,1,1,1,1,1,1,1
1,1,1,1,1,1,1,1,1,1,1,1,1,1,1,1
endlayer

