# Gilly's Reactor ControlRoom
# vanilla blocks only

# template generated with Ruins mod version 16.7 Ingame Parser
# Structure created and developed by Gilly

weight=1
embed_into_distance=33
acceptable_target_blocks=
unacceptable_target_blocks=flowing_water,water,flowing_lava,lava,ice,bedrock,netherrack,nether_brick,nether_brick_fence,soul_sand,quartz_ore,end_stone,obsidian,iron_bars,cloud,flesh,ash_block,slime_grass,slime_congealed,slime_dirt
dimensions=19,29,39
allowable_overhang=0
max_leveling=4
leveling_buffer=-1
preserve_water=0
preserve_lava=0

rule1=0,100,preserveBlock
rule2=0,100,minecraft:stained_hardened_clay-9
rule3=0,100,minecraft:stained_hardened_clay-8
rule4=0,0,minecraft:sea_lantern-0
rule5=0,100,minecraft:cauldron-0
rule6=0,100,minecraft:water-0
rule7=0,100,minecraft:stained_hardened_clay-4
rule8=0,100,minecraft:stone_brick_stairs-1
rule9=0,100,minecraft:stained_hardened_clay-7
rule10=0,100,minecraft:stone_brick_stairs-0
rule11=0,100,minecraft:ladder-2
rule12=0,100,minecraft:double_stone_slab-0
rule13=0,100,minecraft:stained_glass-7
rule14=0,100,minecraft:iron_bars-0
rule15=0,100,minecraft:stained_glass-8
rule16=0,100,minecraft:stone_slab-8
rule17=0,100,minecraft:stone_brick_stairs-4
rule18=0,100,minecraft:stone_brick_stairs-5
rule19=0,100,minecraft:stained_hardened_clay-13
rule20=0,100,minecraft:stone_brick_stairs-2
rule21=0,100,minecraft:stone_slab-0
rule22=0,100,minecraft:ladder-3
rule23=0,100,minecraft:web-0
rule24=0,100,minecraft:stone_brick_stairs-6
rule25=0,100,minecraft:double_stone_slab-8

layer
1,1,1,1,1,1,1,1,1,1,1,1,1,1,1,1,1,1,1,1,1,1,1,1,1,1,1,1,1,1,1,1,1,1,1,1,1,1,1
1,1,1,1,1,1,1,1,1,1,1,1,1,1,1,1,1,1,1,1,1,1,1,1,1,1,1,1,1,1,1,1,1,1,1,1,1,1,1
1,1,1,1,1,1,1,1,1,1,1,1,1,1,1,1,1,1,1,1,1,1,1,1,1,1,1,1,1,1,1,1,1,1,1,1,1,1,1
1,1,1,1,1,1,1,1,1,1,1,1,1,1,1,1,1,1,1,1,1,1,1,1,1,1,1,1,1,1,1,1,1,1,1,1,1,1,1
1,1,1,1,1,2,2,2,2,1,1,1,1,1,1,1,1,1,1,1,1,1,1,1,1,1,1,1,1,1,1,1,1,1,1,1,1,1,1
1,1,1,1,1,2,2,2,2,1,1,1,1,1,1,1,1,2,2,2,2,2,2,2,2,2,2,2,2,1,1,1,1,1,1,1,1,1,1
1,1,1,1,1,2,2,2,2,1,1,1,1,1,1,1,2,2,2,2,2,2,2,2,2,2,2,2,2,2,1,1,1,1,1,1,1,1,1
3,3,3,4,3,3,3,3,4,3,3,4,3,3,3,2,2,2,2,2,2,2,2,2,2,2,2,2,2,2,2,1,1,1,1,1,1,1,1
3,3,3,5,3,3,3,3,5,3,3,5,3,3,3,2,2,2,2,2,2,2,2,2,2,2,2,2,2,2,2,2,1,1,1,1,1,1,1
3,3,3,3,3,3,3,3,3,3,3,3,3,3,3,2,2,2,2,2,2,2,2,2,2,2,2,2,2,2,2,2,2,1,1,1,1,1,1
3,3,3,3,3,3,3,3,3,3,3,3,3,3,3,2,2,2,2,2,2,2,2,2,2,2,2,2,2,2,2,2,2,2,1,1,1,1,1
3,3,3,3,3,3,3,3,3,3,3,3,3,3,3,2,2,2,2,2,2,2,2,2,2,2,2,2,2,2,2,2,2,2,1,1,1,1,1
3,3,4,5,3,3,3,3,3,3,3,3,3,3,5,4,2,2,2,2,2,2,2,2,2,2,2,2,2,2,2,2,2,2,1,1,1,1,1
3,3,3,3,3,3,3,3,3,3,3,3,3,3,3,2,2,2,2,2,2,2,2,2,2,2,2,2,2,2,2,2,2,2,1,1,1,1,1
3,3,3,3,3,3,3,3,3,3,3,3,3,3,3,2,2,2,2,2,2,2,2,2,2,2,2,2,2,2,2,2,2,2,1,1,1,1,1
3,3,3,3,3,3,3,3,3,3,3,3,3,3,3,2,2,2,2,2,2,2,2,2,2,2,2,2,2,2,2,2,2,2,1,1,1,1,1
3,3,4,5,3,3,3,3,3,3,3,3,3,3,5,4,2,2,2,2,2,2,2,2,2,2,2,2,2,2,2,2,2,2,1,1,1,1,1
3,3,3,3,3,3,3,3,3,3,3,3,3,3,3,2,2,2,2,2,2,2,2,2,2,2,2,2,2,2,2,2,2,2,1,1,1,1,1
3,3,3,3,3,3,3,3,3,3,3,3,3,3,3,2,2,2,2,2,2,2,2,2,2,2,2,2,2,2,2,2,2,2,1,1,1,1,1
3,3,3,3,3,3,3,3,3,3,3,3,3,3,3,2,2,2,2,2,2,2,2,2,2,2,2,2,2,2,2,2,2,1,1,1,1,1,1
3,3,3,5,3,3,3,3,5,3,3,3,3,3,3,2,2,2,2,2,2,2,2,2,2,2,2,2,2,2,2,2,1,1,1,1,1,1,1
3,3,3,4,3,3,3,3,4,3,3,3,3,3,3,2,2,2,2,2,2,2,2,2,2,2,2,2,2,2,2,1,1,1,1,1,1,1,1
1,1,1,1,1,2,2,2,2,1,1,1,1,1,1,1,2,2,2,2,2,2,2,2,2,2,2,2,2,2,1,1,1,1,1,1,1,1,1
1,1,1,1,1,2,2,2,2,1,1,1,1,1,1,1,1,2,2,2,2,2,2,2,2,2,2,2,2,1,1,1,1,1,1,1,1,1,1
1,1,1,1,1,2,2,2,2,1,1,1,1,1,1,1,1,1,1,1,1,1,1,1,1,1,1,1,1,1,1,1,1,1,1,1,1,1,1
1,1,1,1,1,1,1,1,1,1,1,1,1,1,1,1,1,1,1,1,1,1,1,1,1,1,1,1,1,1,1,1,1,1,1,1,1,1,1
1,1,1,1,1,1,1,1,1,1,1,1,1,1,1,1,1,1,1,1,1,1,1,1,1,1,1,1,1,1,1,1,1,1,1,1,1,1,1
1,1,1,1,1,1,1,1,1,1,1,1,1,1,1,1,1,1,1,1,1,1,1,1,1,1,1,1,1,1,1,1,1,1,1,1,1,1,1
1,1,1,1,1,1,1,1,1,1,1,1,1,1,1,1,1,1,1,1,1,1,1,1,1,1,1,1,1,1,1,1,1,1,1,1,1,1,1
endlayer

layer
1,1,1,1,1,1,1,1,1,1,1,1,1,1,1,1,1,1,1,1,1,1,1,1,1,1,1,1,1,1,1,1,1,1,1,1,1,1,1
1,1,1,1,1,1,1,1,1,1,1,1,1,1,1,1,1,1,1,1,1,1,1,1,1,1,1,1,1,1,1,1,1,1,1,1,1,1,1
1,1,1,1,1,1,1,1,1,1,1,1,1,1,1,1,1,1,1,1,1,1,1,1,1,1,1,1,1,1,1,1,1,1,1,1,1,1,1
1,1,1,1,1,1,1,1,1,1,1,1,1,1,1,1,1,1,1,1,1,1,1,1,1,1,1,1,1,1,1,1,1,1,1,1,1,1,1
1,1,1,1,2,2,2,2,2,1,1,1,1,1,1,1,1,1,1,1,1,1,1,1,1,1,1,1,1,1,1,1,1,1,1,1,1,1,1
1,1,1,1,2,2,2,2,2,1,1,1,1,1,1,1,1,2,2,2,2,2,2,2,2,2,2,2,2,1,1,1,1,1,1,1,1,1,1
1,1,1,1,2,8,8,2,2,1,1,1,1,1,1,1,2,7,7,7,6,6,6,6,6,6,6,6,6,2,1,1,1,1,1,1,1,1,1
3,3,3,2,2,0,0,2,2,2,2,2,2,2,2,2,2,7,7,7,6,6,6,6,6,6,6,6,6,6,2,1,1,1,1,1,1,1,1
3,3,3,0,0,0,0,0,0,0,0,0,0,0,0,2,6,6,6,6,6,6,6,6,6,6,6,6,6,6,6,2,1,1,1,1,1,1,1
3,3,3,0,0,0,0,0,0,0,0,0,0,0,0,2,6,6,6,6,6,6,6,6,6,6,6,6,6,6,6,6,2,1,1,1,1,1,1
3,3,3,0,0,0,0,0,0,0,0,0,0,2,0,2,6,6,6,6,6,6,6,6,6,6,6,6,6,6,6,6,6,2,1,1,1,1,1
3,3,3,0,0,0,0,0,0,0,2,0,0,0,0,2,6,6,6,6,6,9,9,9,9,9,9,9,6,6,6,6,6,2,1,1,1,1,1
3,3,3,0,0,0,0,0,0,0,0,0,0,0,0,2,6,6,6,6,6,9,9,9,9,9,9,9,6,6,6,6,6,2,1,1,1,1,1
3,3,3,0,0,0,0,0,0,0,0,0,0,0,0,2,6,6,6,6,6,9,9,9,9,9,9,9,6,6,6,6,6,2,1,1,1,1,1
3,3,3,0,0,0,0,0,0,0,0,0,0,0,0,2,6,6,6,6,6,9,9,9,9,9,9,9,6,6,6,6,6,2,1,1,1,1,1
3,3,3,0,0,0,0,0,0,0,0,0,0,0,0,2,6,6,6,6,6,9,9,9,9,9,9,9,6,6,6,6,6,2,1,1,1,1,1
3,3,3,0,0,0,0,0,0,0,0,0,0,0,0,2,6,6,6,6,6,9,9,9,9,9,9,9,6,6,6,6,6,2,1,1,1,1,1
3,3,3,0,0,0,0,0,0,0,2,0,0,0,0,2,6,6,6,6,6,9,9,9,9,9,9,9,6,6,6,6,6,2,1,1,1,1,1
3,3,3,0,0,0,0,0,0,0,0,0,0,2,0,2,6,6,6,6,6,6,6,6,6,6,6,6,6,6,6,6,6,2,1,1,1,1,1
3,3,3,0,0,0,0,0,0,2,2,0,0,0,0,2,6,6,6,6,6,6,6,6,6,6,6,6,6,6,6,6,2,1,1,1,1,1,1
3,3,3,0,0,0,0,0,0,2,2,0,0,0,0,2,6,6,6,6,6,6,6,6,6,6,6,6,6,6,6,2,1,1,1,1,1,1,1
3,3,3,2,2,0,0,2,2,2,2,2,2,2,2,2,2,7,7,7,6,6,6,6,6,6,6,6,6,6,2,1,1,1,1,1,1,1,1
1,1,1,1,2,10,10,2,2,1,1,1,1,1,1,1,2,7,7,7,6,6,6,6,6,6,6,6,6,2,1,1,1,1,1,1,1,1,1
1,1,1,1,2,2,2,2,2,1,1,1,1,1,1,1,1,2,2,2,2,2,2,2,2,2,2,2,2,1,1,1,1,1,1,1,1,1,1
1,1,1,1,2,2,2,2,2,1,1,1,1,1,1,1,1,1,1,1,1,1,1,1,1,1,1,1,1,1,1,1,1,1,1,1,1,1,1
1,1,1,1,1,1,1,1,1,1,1,1,1,1,1,1,1,1,1,1,1,1,1,1,1,1,1,1,1,1,1,1,1,1,1,1,1,1,1
1,1,1,1,1,1,1,1,1,1,1,1,1,1,1,1,1,1,1,1,1,1,1,1,1,1,1,1,1,1,1,1,1,1,1,1,1,1,1
1,1,1,1,1,1,1,1,1,1,1,1,1,1,1,1,1,1,1,1,1,1,1,1,1,1,1,1,1,1,1,1,1,1,1,1,1,1,1
1,1,1,1,1,1,1,1,1,1,1,1,1,1,1,1,1,1,1,1,1,1,1,1,1,1,1,1,1,1,1,1,1,1,1,1,1,1,1
endlayer

layer
1,1,1,1,1,1,1,1,1,1,1,1,1,1,1,1,1,1,1,1,1,1,1,1,1,1,1,1,1,1,1,1,1,1,1,1,1,1,1
1,1,1,1,1,1,1,1,1,1,1,1,1,1,1,1,1,1,1,1,1,1,1,1,1,1,1,1,1,1,1,1,1,1,1,1,1,1,1
1,1,1,1,1,1,1,1,1,3,1,1,1,1,1,1,1,1,1,1,1,1,1,1,1,1,1,1,1,1,1,1,1,1,1,1,1,1,1
1,1,1,1,1,1,1,1,1,1,1,1,1,1,1,1,1,1,1,1,1,1,1,1,1,1,1,1,1,1,1,1,1,1,1,1,1,1,1
1,1,1,2,2,2,2,2,2,1,1,1,1,1,1,1,1,1,1,1,1,1,1,1,1,1,1,1,1,1,1,1,1,1,1,1,1,1,1
1,1,1,2,2,8,8,2,2,1,1,1,1,1,1,1,1,2,2,2,2,2,2,2,2,2,2,2,2,1,1,1,1,1,1,1,1,1,1
1,1,1,2,2,0,0,2,2,1,1,1,1,1,1,1,2,6,6,6,6,6,6,6,6,6,6,6,6,2,1,1,1,1,1,1,1,1,1
3,3,3,2,2,0,0,2,2,2,2,2,2,2,2,2,2,6,6,6,6,6,6,6,6,6,6,6,6,6,2,1,1,1,1,1,1,1,1
3,3,3,0,0,0,0,0,0,0,0,0,0,0,0,2,6,6,6,6,6,6,6,6,6,6,6,6,6,6,6,2,1,1,1,1,1,1,1
3,1,3,0,0,0,0,0,0,0,0,0,0,0,0,2,6,6,6,6,6,6,6,6,6,6,6,6,6,6,6,6,2,1,1,1,1,1,1
3,3,3,0,0,0,0,0,0,0,0,0,0,2,0,2,6,6,6,6,6,6,6,6,6,6,6,6,6,6,6,6,6,2,1,1,1,1,1
3,3,3,0,0,0,0,0,0,0,2,0,0,0,0,2,6,6,6,6,6,9,9,9,9,9,9,9,6,6,6,6,6,2,1,1,1,1,1
3,3,3,0,0,0,0,0,0,0,0,0,0,0,0,2,6,6,6,6,6,9,9,9,4,9,9,9,6,6,6,6,6,2,1,1,1,1,1
3,3,3,0,0,0,0,0,0,0,0,0,0,0,0,2,6,6,6,6,6,9,9,9,9,9,9,9,6,6,6,6,6,2,1,1,1,1,1
3,3,3,0,0,0,0,0,0,0,0,0,0,0,0,2,6,6,6,6,6,9,4,9,9,9,4,9,6,6,6,6,6,2,1,1,1,1,1
3,3,3,0,0,0,0,0,0,0,0,0,0,0,0,2,6,6,6,6,6,9,9,9,9,9,9,9,6,6,6,6,6,2,1,1,1,1,1
3,3,3,0,0,0,0,0,0,0,0,0,0,0,0,2,6,6,6,6,6,9,9,9,4,9,9,9,6,6,6,6,6,2,1,1,1,1,1
3,3,3,0,0,0,0,0,0,0,2,0,0,0,0,2,6,6,6,6,6,9,9,9,9,9,9,9,6,6,6,6,6,2,1,1,1,1,1
3,3,3,0,0,0,0,0,0,0,0,0,0,2,0,2,6,6,6,6,6,6,6,6,6,6,6,6,6,6,6,6,6,2,1,1,1,1,1
3,1,3,0,0,0,0,0,0,2,2,0,0,0,0,2,6,6,6,6,6,6,6,6,6,6,6,6,6,6,6,6,2,1,1,1,1,1,1
3,3,3,0,0,0,0,0,0,2,2,0,0,0,0,2,6,6,6,6,6,6,6,6,6,6,6,6,6,6,6,2,1,1,1,1,1,1,1
3,3,3,2,2,0,0,2,2,2,2,2,2,2,2,2,2,6,6,6,6,6,6,6,6,6,6,6,6,6,2,1,1,1,1,1,1,1,1
1,1,1,2,2,0,0,2,2,1,1,1,1,1,1,1,2,6,6,6,6,6,6,6,6,6,6,6,6,2,1,1,1,1,1,1,1,1,1
1,1,1,2,2,10,10,2,2,1,1,1,1,1,1,1,1,2,2,2,2,2,2,2,2,2,2,2,2,1,1,1,1,1,1,1,1,1,1
1,1,1,2,2,2,2,2,2,1,1,1,1,1,1,1,1,1,1,1,1,1,1,1,1,1,1,1,1,1,1,1,1,1,1,1,1,1,1
1,1,1,1,1,1,1,1,1,1,1,1,1,1,1,1,1,1,1,1,1,1,1,1,1,1,1,1,1,1,1,1,1,1,1,1,1,1,1
1,1,1,1,1,1,1,1,1,1,1,1,1,1,1,1,1,1,1,1,1,1,1,1,1,1,1,1,1,1,1,1,1,1,1,1,1,1,1
1,1,1,1,1,1,1,1,1,1,1,1,1,1,1,1,1,1,1,1,1,1,1,1,1,1,1,1,1,1,1,1,1,1,1,1,1,1,1
1,1,1,1,1,1,1,1,1,1,1,1,1,1,1,1,1,1,1,1,1,1,1,1,1,1,1,1,1,1,1,1,1,1,1,1,1,1,1
endlayer

layer
2,2,2,2,2,2,2,2,2,2,2,2,2,2,2,2,2,2,2,2,2,2,2,2,2,2,2,2,2,2,2,2,2,2,2,2,2,2,2
2,3,3,3,3,3,3,3,3,3,3,3,3,3,3,3,3,3,3,3,3,3,3,3,3,3,3,3,3,3,3,3,3,3,3,3,3,3,2
2,3,4,3,3,3,3,3,4,3,3,3,3,3,3,3,3,3,4,3,3,3,3,3,4,3,3,3,3,4,3,3,3,3,3,3,4,3,2
2,3,3,1,2,2,2,2,3,1,1,1,3,4,3,1,1,1,3,1,1,1,1,1,3,1,1,1,1,3,1,1,1,1,1,1,3,3,2
2,3,3,2,2,8,8,2,2,1,1,1,1,3,3,1,1,1,1,1,1,1,1,1,3,1,1,1,1,1,1,1,1,1,1,1,3,3,2
2,3,3,2,2,0,0,2,2,1,1,1,1,3,3,1,1,2,2,2,2,2,2,2,2,2,2,2,2,1,1,1,1,1,1,1,3,3,2
2,3,3,2,2,0,0,2,2,1,1,1,1,1,1,1,7,11,0,0,0,0,0,0,0,0,0,0,0,2,1,1,1,1,1,1,3,3,2
2,3,3,2,2,0,0,2,2,2,2,2,2,4,2,2,7,0,0,0,0,0,0,0,0,0,0,0,0,0,2,1,1,1,1,1,3,3,2
2,3,3,0,0,0,0,0,0,0,0,0,0,0,0,2,0,0,0,0,0,0,0,0,0,0,0,0,0,0,0,2,1,1,1,1,3,3,2
2,4,3,0,0,0,0,0,0,0,0,0,0,0,0,2,0,0,0,0,0,0,0,0,0,0,0,0,0,0,0,0,2,1,1,3,4,3,2
2,3,3,0,0,0,0,0,0,0,0,0,0,4,0,2,0,0,0,0,0,0,0,0,0,0,0,0,0,0,0,0,0,2,1,1,3,3,2
2,3,3,0,0,0,0,0,0,0,4,0,0,0,0,2,0,0,0,0,0,2,12,12,12,12,12,2,0,0,0,0,0,2,1,1,3,3,2
2,3,3,0,0,0,0,0,0,0,0,0,0,0,0,2,0,0,0,0,0,12,13,13,5,13,13,12,0,0,0,0,0,2,1,1,3,3,2
2,3,3,0,0,0,0,0,0,0,0,0,0,0,0,2,0,0,0,0,0,12,13,13,2,13,13,12,0,0,0,0,0,2,1,1,3,3,2
2,4,3,0,0,0,0,0,0,0,0,0,0,0,0,2,0,0,0,0,0,12,5,2,2,2,5,12,0,0,0,0,0,2,3,3,4,3,2
2,3,3,0,0,0,0,0,0,0,0,0,0,0,0,2,0,0,0,0,0,12,13,13,2,13,13,12,0,0,0,0,0,2,1,1,3,3,2
2,3,3,0,0,0,0,0,0,0,0,0,0,0,0,2,0,0,0,0,0,12,13,13,5,13,13,12,0,0,0,0,0,2,1,1,3,3,2
2,3,3,0,0,0,0,0,0,0,4,0,0,0,0,2,0,0,0,0,0,2,12,12,12,12,12,2,0,0,0,0,0,2,1,1,3,3,2
2,3,3,0,0,0,0,0,0,0,0,0,0,4,0,2,0,0,0,0,0,0,0,0,0,0,0,0,0,0,0,0,0,2,1,1,3,3,2
2,4,3,0,0,0,0,0,0,2,2,0,0,0,0,2,0,0,0,0,0,0,0,0,0,0,0,0,0,0,0,0,2,1,1,3,4,3,2
2,3,3,0,0,0,0,0,0,2,2,0,0,0,0,2,0,0,0,0,0,0,0,0,0,0,0,0,0,0,0,2,1,1,1,1,3,3,2
2,3,3,2,2,0,0,2,2,2,2,2,2,4,2,2,7,0,0,0,0,0,0,0,0,0,0,0,0,0,2,1,1,1,1,1,3,3,2
2,3,3,2,2,0,0,2,2,1,1,1,1,1,1,1,7,11,0,0,0,0,0,0,0,0,0,0,0,2,1,1,1,1,1,1,3,3,2
2,3,3,2,2,0,0,2,2,1,1,1,1,3,3,1,1,2,2,2,2,2,2,2,2,2,2,2,2,1,1,1,1,1,1,1,3,3,2
2,3,3,2,2,10,10,2,2,1,1,1,1,3,3,1,1,1,1,1,1,1,1,1,3,1,1,1,1,1,1,1,1,1,1,1,3,3,2
2,3,3,1,2,2,2,2,3,1,1,1,3,4,3,1,1,1,3,1,1,1,1,1,3,1,1,1,1,3,1,1,1,1,1,1,3,3,2
2,3,4,3,3,3,3,3,4,3,3,3,3,3,3,3,3,3,4,3,3,3,3,3,4,3,3,3,3,4,3,3,3,3,3,3,4,3,2
2,3,3,3,3,3,3,3,3,3,3,3,3,3,3,3,3,3,3,3,3,3,3,3,3,3,3,3,3,3,3,3,3,3,3,3,3,3,2
2,2,2,2,2,2,2,2,2,2,2,2,2,2,2,2,2,2,2,2,2,2,2,2,2,2,2,2,2,2,2,2,2,2,2,2,2,2,2
endlayer

layer
2,2,2,2,2,2,2,2,2,2,2,2,2,2,2,2,2,2,2,2,2,2,2,2,2,2,2,2,2,2,2,2,2,2,2,2,2,2,2
2,3,3,3,3,3,3,3,3,3,3,3,3,3,3,3,3,3,3,3,3,3,3,3,3,3,3,3,3,3,3,3,3,3,3,3,3,3,2
2,3,13,3,3,3,3,3,13,3,3,3,3,3,3,3,3,3,13,3,3,3,3,3,13,3,3,3,3,13,3,3,3,3,3,3,13,3,2
2,3,3,2,2,8,8,2,2,2,2,2,2,13,3,2,2,2,2,2,2,2,2,2,2,2,2,2,2,2,2,2,2,2,2,2,3,3,2
2,3,3,2,2,0,0,2,2,1,2,2,2,3,3,2,2,1,2,2,2,2,2,2,2,2,2,2,2,2,1,1,1,1,1,2,3,3,2
2,3,3,2,2,0,0,2,2,1,2,2,2,3,3,2,7,2,2,2,2,2,2,2,2,2,2,2,2,2,1,1,1,1,1,2,3,3,2
2,3,3,2,2,0,0,2,2,1,2,2,2,3,3,3,7,11,0,0,0,0,0,14,13,14,0,0,0,2,1,1,1,1,1,2,3,3,2
2,3,3,2,2,0,0,2,2,2,2,2,3,15,3,3,7,0,0,0,0,0,0,14,13,14,0,0,0,0,2,1,1,1,1,2,3,3,2
2,3,3,2,2,0,0,2,3,3,3,3,3,3,3,3,16,0,0,0,0,0,0,14,13,14,0,0,0,0,0,2,1,1,1,2,3,3,2
2,13,3,2,2,17,17,2,3,3,3,3,3,3,3,3,16,0,0,0,0,14,14,14,13,14,14,14,0,0,0,0,2,1,1,2,13,3,2
2,3,3,2,3,3,3,3,3,3,3,3,3,15,3,3,16,0,0,0,14,14,7,7,7,7,7,14,14,0,0,0,0,2,2,2,3,3,2
2,3,3,2,14,3,3,3,3,3,15,3,3,3,3,3,12,14,14,14,14,7,0,0,0,0,0,7,14,14,0,0,0,2,2,2,3,3,2
2,3,3,2,3,3,3,3,3,3,3,3,3,3,3,3,13,13,13,13,7,0,0,0,0,0,0,0,7,14,0,0,0,2,2,2,3,3,2
2,3,3,2,3,3,3,3,3,3,3,15,15,15,3,3,13,13,13,13,7,0,0,0,0,0,0,0,7,14,14,14,14,2,2,2,3,3,2
2,13,3,2,2,3,14,3,3,3,3,15,15,15,3,3,13,13,13,13,7,0,0,0,0,0,0,0,7,13,13,13,13,2,2,2,13,3,2
2,3,3,2,3,3,3,3,3,3,3,15,15,15,3,3,13,13,13,13,7,0,0,0,0,0,0,0,7,14,14,14,14,2,2,2,3,3,2
2,3,3,2,3,3,3,3,3,3,3,3,3,3,3,3,13,13,13,13,7,0,0,0,0,0,0,0,7,14,0,0,0,2,2,2,3,3,2
2,3,3,2,14,3,3,3,3,3,15,3,3,3,3,3,12,14,14,14,14,7,0,0,0,0,0,7,14,14,0,0,0,2,2,2,3,3,2
2,3,3,2,3,3,3,3,3,3,3,3,3,15,3,3,16,0,0,0,14,14,7,7,7,7,7,14,14,0,0,0,0,2,2,2,3,3,2
2,13,3,2,2,18,18,2,2,3,3,3,3,3,3,3,16,0,0,0,0,14,14,14,13,14,14,14,0,0,0,0,2,1,1,2,13,3,2
2,3,3,2,2,0,0,2,2,3,2,3,3,3,3,3,16,0,0,0,0,0,0,14,13,14,0,0,0,0,0,2,1,1,1,2,3,3,2
2,3,3,2,2,0,0,2,2,2,2,2,3,15,3,3,7,0,0,0,0,0,0,14,13,14,0,0,0,0,2,1,1,1,1,2,3,3,2
2,3,3,2,2,0,0,2,2,2,2,2,3,3,3,3,7,11,0,0,0,0,0,14,13,14,0,0,0,2,1,1,1,1,1,2,3,3,2
2,3,3,2,2,0,0,2,2,2,2,2,2,3,3,2,7,2,2,2,2,2,2,2,2,2,2,2,2,2,1,1,1,1,1,2,3,3,2
2,3,3,2,2,0,0,2,2,2,2,2,2,3,3,2,2,2,2,2,2,2,2,2,2,2,2,2,2,2,1,1,1,1,1,2,3,3,2
2,3,3,2,2,10,10,2,2,2,2,2,2,13,3,2,2,2,2,2,2,2,2,2,2,2,2,2,2,2,2,2,2,2,2,2,3,3,2
2,3,13,3,3,3,3,3,13,3,3,3,3,3,3,3,3,3,13,3,3,3,3,3,13,3,3,3,3,13,3,3,3,3,3,3,13,3,2
2,3,3,3,3,3,3,3,3,3,3,3,3,3,3,3,3,3,3,3,3,3,3,3,3,3,3,3,3,3,3,3,3,3,3,3,3,3,2
2,2,2,2,2,2,2,2,2,2,2,2,2,2,2,2,2,2,2,2,2,2,2,2,2,2,2,2,2,2,2,2,2,2,2,2,2,2,2
endlayer

layer
2,2,2,2,2,2,2,2,2,2,2,2,2,2,2,2,2,2,2,2,2,2,2,2,2,2,2,2,2,2,2,2,2,2,2,2,2,2,2
2,0,0,0,0,0,0,0,0,0,0,0,0,0,0,0,0,0,0,0,0,0,0,0,0,0,0,0,0,0,0,0,0,0,0,0,0,0,2
2,0,0,0,0,0,0,0,0,0,0,0,0,0,0,0,0,0,0,0,0,0,0,0,0,0,0,0,0,0,0,0,0,0,0,0,0,0,2
2,0,0,2,2,0,0,2,2,2,2,13,2,0,0,2,13,2,2,2,2,13,2,2,0,2,13,2,2,2,2,13,2,2,2,2,0,0,2
2,0,0,2,2,0,0,2,2,1,2,2,2,0,0,2,2,2,2,2,2,2,2,2,0,2,2,2,2,2,1,2,1,1,1,2,0,0,2
2,0,0,2,2,0,0,2,2,1,2,2,2,0,0,2,7,19,19,19,19,19,19,19,0,19,19,19,19,2,1,1,1,1,1,2,0,0,2
2,0,0,2,2,0,0,2,2,1,2,2,2,0,0,0,0,0,0,0,0,0,0,0,0,0,0,0,0,19,1,1,1,1,1,2,0,0,2
2,0,0,2,2,0,0,2,2,2,2,2,0,0,0,0,7,0,0,0,0,0,0,0,0,0,0,0,0,0,19,1,1,1,2,13,0,0,2
2,0,0,2,2,17,17,2,2,2,2,2,0,0,0,0,0,0,0,0,0,0,0,0,0,0,0,0,0,0,0,19,1,1,1,2,0,0,2
2,0,0,2,2,2,2,2,2,2,0,0,0,0,0,0,0,0,0,0,0,0,0,0,0,0,0,0,0,0,0,0,19,1,1,2,0,0,2
2,0,0,2,2,2,2,2,2,20,0,0,0,0,0,0,0,0,0,0,0,0,0,0,0,0,0,0,0,0,0,0,0,19,2,2,0,0,2
2,0,0,2,4,2,2,2,2,20,0,0,0,0,0,0,0,0,0,0,0,0,0,0,0,0,0,0,0,0,0,0,0,19,2,2,0,0,2
2,0,0,13,2,2,2,2,2,20,0,0,0,0,0,0,0,0,0,0,0,0,0,0,0,0,0,0,0,0,0,0,0,19,2,13,0,0,2
2,0,0,2,2,2,2,2,2,20,0,0,0,0,0,0,0,0,0,0,0,0,0,0,0,0,0,0,0,0,0,0,0,19,2,2,0,0,2
2,0,0,2,2,2,4,2,2,20,0,0,0,0,0,0,0,0,0,0,0,0,0,0,0,0,0,0,0,0,0,0,0,0,0,0,0,0,2
2,0,0,2,2,2,2,2,2,20,0,0,0,0,0,0,0,0,0,0,0,0,0,0,0,0,0,0,0,0,0,0,0,19,2,2,0,0,2
2,0,0,13,2,2,2,2,2,20,0,0,0,0,0,0,0,0,0,0,0,0,0,0,0,0,0,0,0,0,0,0,0,19,2,13,0,0,2
2,0,0,2,4,2,2,2,8,8,0,0,0,0,0,0,0,0,0,0,0,0,0,0,0,0,0,0,0,0,0,0,0,19,2,2,0,0,2
2,0,0,2,2,2,2,2,21,21,21,21,0,0,0,0,0,0,0,0,0,0,0,0,0,0,0,0,0,0,0,0,0,19,2,2,0,0,2
2,0,0,2,2,2,2,2,21,6,6,21,0,0,0,0,0,0,0,0,0,0,0,0,0,0,0,0,0,0,0,0,19,1,1,2,0,0,2
2,0,0,2,2,18,18,2,3,6,6,3,0,0,0,0,0,0,0,0,0,0,0,0,0,0,0,0,0,0,0,19,1,1,1,2,0,0,2
2,0,0,2,2,0,0,2,2,2,2,2,0,0,0,0,7,0,0,0,0,0,0,0,0,0,0,0,0,0,19,1,1,1,2,13,0,0,2
2,0,0,2,2,0,0,2,2,2,2,2,2,0,0,0,0,0,0,0,0,0,0,0,0,0,0,0,0,19,1,1,1,1,1,2,0,0,2
2,0,0,2,2,0,0,2,2,2,2,2,2,0,0,2,7,19,19,19,19,19,19,19,0,19,19,19,19,2,1,1,1,1,1,2,0,0,2
2,0,0,2,2,0,0,2,2,2,2,2,2,0,0,2,2,2,2,2,2,2,2,2,0,2,2,2,2,2,1,2,1,1,1,2,0,0,2
2,0,0,2,2,0,0,2,2,2,2,13,2,0,0,2,13,2,2,2,2,13,2,2,0,2,13,2,2,2,2,13,2,2,2,2,0,0,2
2,0,0,0,0,0,0,0,0,0,0,0,0,0,0,0,0,0,0,0,0,0,0,0,0,0,0,0,0,0,0,0,0,0,0,0,0,0,2
2,0,0,0,0,0,0,0,0,0,0,0,0,0,0,0,0,0,0,0,0,0,0,0,0,0,0,0,0,0,0,0,0,0,0,0,0,0,2
2,2,2,2,2,2,2,2,2,2,2,2,2,2,2,2,2,2,2,2,2,2,2,2,2,2,2,2,2,2,2,2,2,2,2,2,2,2,2
endlayer

layer
2,2,2,2,2,2,2,2,2,2,2,2,2,2,2,2,2,2,2,2,2,2,2,2,2,2,2,2,2,2,2,2,2,2,2,2,2,2,2
2,0,0,0,0,0,0,0,0,0,0,0,0,0,0,0,0,0,0,0,0,0,0,0,0,0,0,0,0,0,0,0,0,0,0,0,0,0,2
2,0,0,0,0,0,0,0,0,0,0,0,0,0,0,0,0,0,0,0,0,0,0,0,0,0,0,0,0,0,0,0,0,0,0,0,0,0,2
2,0,0,2,2,0,0,2,2,2,2,2,2,0,0,2,2,2,2,2,2,2,2,2,0,2,2,2,2,2,2,2,2,2,2,2,0,0,2
2,0,0,2,2,0,0,2,2,1,2,2,2,0,0,2,2,2,2,2,2,2,2,2,0,2,2,2,2,2,1,1,1,1,1,2,0,0,2
2,0,0,2,2,0,0,2,2,1,2,2,2,0,0,2,7,2,2,2,2,2,2,19,0,19,2,2,2,2,1,1,1,1,1,2,0,0,2
2,0,0,2,2,0,0,2,2,1,2,2,2,0,0,0,0,0,0,0,0,0,0,0,0,0,0,0,0,2,1,1,1,1,1,2,0,0,2
2,0,0,2,2,17,17,2,2,2,2,2,0,0,0,0,7,0,0,0,0,0,0,0,0,0,0,0,0,0,2,1,1,1,1,2,0,0,2
2,0,0,2,2,2,2,2,2,2,2,2,0,0,0,0,0,0,0,0,0,0,0,0,0,0,0,0,0,0,0,2,1,1,1,2,0,0,2
2,0,0,2,2,2,2,2,2,2,0,0,0,0,0,0,0,0,0,0,0,0,0,0,0,0,0,0,0,0,0,0,2,1,1,2,0,0,2
2,0,0,2,2,2,2,2,2,0,0,0,0,0,0,0,0,0,0,0,0,0,0,0,0,0,0,0,0,0,0,0,0,2,2,2,0,0,2
2,0,0,2,4,2,2,2,20,0,0,0,0,0,0,0,0,0,0,0,0,0,0,0,0,0,0,0,0,0,0,0,0,2,2,2,0,0,2
2,0,0,2,2,2,2,2,20,0,0,0,0,0,0,0,0,0,0,0,0,0,0,0,0,0,0,0,0,0,0,0,0,2,2,2,0,0,2
2,0,0,2,2,2,2,2,20,0,0,0,0,0,0,0,0,0,0,0,0,0,0,0,0,0,0,0,0,0,0,0,0,19,2,2,0,0,2
2,0,0,2,2,2,4,2,20,0,0,0,0,0,0,0,0,0,0,0,0,0,0,0,0,0,0,0,0,0,0,0,0,0,0,0,0,0,2
2,0,0,2,2,2,2,2,20,0,0,0,0,0,0,0,0,0,0,0,0,0,0,0,0,0,0,0,0,0,0,0,0,19,2,2,0,0,2
2,0,0,2,2,2,2,2,8,0,0,0,0,0,0,0,0,0,0,0,0,0,0,0,0,0,0,0,0,0,0,0,0,2,2,2,0,0,2
2,0,0,2,4,2,2,2,0,0,0,0,0,0,0,0,0,0,0,0,0,0,0,0,0,0,0,0,0,0,0,0,0,2,2,2,0,0,2
2,0,0,2,2,2,2,2,0,0,0,0,0,0,0,0,0,0,0,0,0,0,0,0,0,0,0,0,0,0,0,0,0,2,2,2,0,0,2
2,0,0,2,2,2,2,2,0,0,0,0,0,0,0,0,0,0,0,0,0,0,0,0,0,0,0,0,0,0,0,0,2,1,1,2,0,0,2
2,0,0,2,2,2,2,2,3,11,22,3,0,0,0,0,0,0,0,0,0,0,0,0,0,0,0,0,0,0,0,2,1,1,1,2,0,0,2
2,0,0,2,2,18,18,2,2,2,2,2,0,0,0,0,7,0,0,0,0,0,0,0,0,0,0,0,0,0,2,1,1,1,1,2,0,0,2
2,0,0,2,2,0,0,2,2,2,2,2,2,0,0,0,0,0,0,0,0,0,0,0,0,0,0,0,0,2,1,1,1,1,1,2,0,0,2
2,0,0,2,2,0,0,2,2,2,2,2,2,0,0,2,7,2,2,2,2,2,2,19,0,19,2,2,2,2,1,1,1,1,1,2,0,0,2
2,0,0,2,2,0,0,2,2,2,2,2,2,0,0,2,2,2,2,2,2,2,2,2,0,2,2,2,2,2,1,1,1,1,1,2,0,0,2
2,0,0,2,2,0,0,2,2,2,2,2,2,0,0,2,2,2,2,2,2,2,2,2,0,2,2,2,2,2,2,2,2,2,2,2,0,0,2
2,0,0,0,0,0,0,0,0,0,0,0,0,0,0,0,0,0,0,0,0,0,0,0,0,0,0,0,0,0,0,0,0,0,0,0,0,0,2
2,0,0,0,0,0,0,0,0,0,0,0,0,0,0,0,0,0,0,0,0,0,0,0,0,0,0,0,0,0,0,0,0,0,0,0,0,0,2
2,2,2,2,2,2,2,2,2,2,2,2,2,2,2,2,2,2,2,2,2,2,2,2,2,2,2,2,2,2,2,2,2,2,2,2,2,2,2
endlayer

layer
7,7,7,7,7,7,7,7,7,7,7,7,7,7,7,7,7,7,7,7,7,7,7,7,7,7,7,7,7,7,7,7,7,7,7,7,7,7,7
7,0,0,0,0,0,0,0,0,0,0,0,0,0,0,0,0,0,0,0,0,0,0,0,0,0,0,0,0,0,0,0,0,0,0,0,0,0,7
7,0,0,0,0,0,0,0,0,0,0,0,0,0,0,0,0,0,0,0,0,0,0,0,0,0,0,0,0,0,0,0,0,0,0,0,0,0,7
7,0,0,7,7,0,0,7,7,7,7,7,7,0,0,7,7,7,7,7,7,7,7,7,0,7,7,7,7,7,7,7,7,7,7,7,0,0,7
7,0,0,7,7,0,0,7,1,1,2,7,7,0,0,7,7,2,2,2,2,0,2,7,0,7,0,2,2,2,1,1,1,1,1,7,0,0,7
7,0,0,7,7,0,0,7,1,1,2,7,7,0,0,7,7,2,2,2,2,14,2,19,0,19,14,2,2,2,1,1,1,1,1,7,0,0,7
7,0,0,7,7,17,17,7,1,1,2,7,7,0,0,0,0,0,0,0,0,0,0,0,0,0,0,0,0,2,1,1,1,1,1,7,0,0,7
7,0,0,7,13,2,2,2,2,2,2,7,0,0,0,0,7,0,0,0,0,0,0,0,0,0,0,0,0,0,2,1,1,1,1,7,0,0,7
7,0,0,7,2,2,2,2,2,2,19,7,0,0,0,0,0,0,0,0,0,0,0,0,0,0,0,0,0,0,0,2,1,1,1,7,0,0,7
7,0,0,7,2,2,2,2,2,19,0,0,0,0,0,0,0,0,0,0,0,0,0,0,0,0,0,0,0,0,0,0,2,1,1,7,0,0,7
7,0,0,7,2,2,2,2,19,0,0,0,0,0,0,0,0,0,0,0,0,0,0,0,0,0,0,0,0,0,0,0,0,2,2,7,0,0,7
7,0,0,7,2,2,2,19,0,0,0,0,0,0,0,0,0,0,0,0,0,0,0,0,0,0,0,0,0,0,0,0,0,2,2,7,0,0,7
7,0,0,7,2,2,2,20,0,0,0,0,0,0,0,0,0,0,0,0,0,0,0,0,0,0,0,0,0,0,0,0,0,14,0,7,0,0,7
7,0,0,7,2,2,2,20,0,0,0,0,0,0,0,0,0,0,0,0,0,0,0,0,0,0,0,0,0,0,0,0,0,19,7,7,0,0,7
7,0,0,7,2,2,2,20,0,0,0,0,0,0,0,0,0,0,0,0,0,0,0,0,0,0,0,0,0,0,0,0,0,0,0,0,0,0,7
7,0,0,7,2,2,2,20,0,0,0,0,0,0,0,0,0,0,0,0,0,0,0,0,0,0,0,0,0,0,0,0,0,19,7,7,0,0,7
7,0,0,7,2,2,2,20,0,0,0,0,0,0,0,0,0,0,0,0,0,0,0,0,0,0,0,0,0,0,0,0,0,14,0,7,0,0,7
7,0,0,7,2,2,2,19,0,0,0,0,0,0,0,0,0,0,0,0,0,0,0,0,0,0,0,0,0,0,0,0,0,2,2,7,0,0,7
7,0,0,7,2,2,2,19,0,0,0,0,0,0,0,0,0,0,0,0,0,0,0,0,0,0,0,0,0,0,0,0,0,2,2,7,0,0,7
7,0,0,7,2,2,2,19,0,0,0,0,0,0,0,0,0,0,0,0,0,0,0,0,0,0,0,0,0,0,0,0,2,1,1,7,0,0,7
7,0,0,7,2,2,2,2,3,11,22,3,0,0,0,0,0,0,0,0,0,0,0,0,0,0,0,0,0,0,0,2,1,1,1,7,0,0,7
7,0,0,7,13,2,2,2,2,19,19,7,0,0,0,0,7,0,0,0,0,0,0,0,0,0,0,0,0,0,2,1,1,1,1,7,0,0,7
7,0,0,7,7,18,18,7,2,2,2,7,7,0,0,0,0,0,0,0,0,0,0,0,0,0,0,0,0,2,1,1,1,1,1,7,0,0,7
7,0,0,7,7,0,0,7,2,2,2,7,7,0,0,7,7,2,2,2,2,14,2,19,0,19,14,2,2,2,1,1,1,1,1,7,0,0,7
7,0,0,7,7,0,0,7,2,2,2,7,7,0,0,7,7,2,2,2,2,0,2,7,0,7,0,2,2,2,1,1,1,1,1,7,0,0,7
7,0,0,7,7,0,0,7,7,7,7,7,7,0,0,7,7,7,7,7,7,7,7,7,0,7,7,7,7,7,7,7,7,7,7,7,0,0,7
7,0,0,0,0,0,0,0,0,0,0,0,0,0,0,0,0,0,0,0,0,0,0,0,0,0,0,0,0,0,0,0,0,0,0,0,0,0,7
7,0,0,0,0,0,0,0,0,0,0,0,0,0,0,0,0,0,0,0,0,0,0,0,0,0,0,0,0,0,0,0,0,0,0,0,0,0,7
7,7,7,7,7,7,7,7,7,7,7,7,7,7,7,7,7,7,7,7,7,7,7,7,7,7,7,7,7,7,7,7,7,7,7,7,7,7,7
endlayer

layer
2,2,2,2,2,2,2,2,2,2,2,2,2,2,2,2,2,2,2,2,2,2,2,2,2,2,2,2,2,2,2,2,2,2,2,2,2,2,2
2,0,0,0,0,0,0,0,0,0,0,0,0,0,0,0,0,0,0,0,0,0,0,0,0,0,0,0,0,0,0,0,0,0,0,0,0,0,2
2,0,0,0,0,0,0,0,0,0,0,0,0,0,0,0,0,0,0,0,0,0,0,0,0,0,0,0,0,0,0,0,0,0,0,0,0,0,2
2,0,0,2,2,2,2,2,2,2,2,14,2,2,2,2,14,2,2,2,2,14,2,2,0,2,14,2,2,2,2,14,2,2,2,2,0,0,2
2,0,0,2,2,2,4,2,2,2,2,4,14,13,13,14,4,2,2,2,2,4,2,2,0,2,4,2,2,2,2,4,2,2,2,2,0,0,2
2,0,0,2,2,2,2,2,2,2,2,2,2,2,2,2,2,2,2,2,2,2,2,19,0,19,2,2,2,2,2,2,2,2,2,2,0,0,2
2,0,0,2,2,2,2,2,2,2,2,2,2,2,2,2,2,2,2,2,0,0,0,0,0,0,0,0,2,2,2,2,2,2,2,2,0,0,2
2,0,0,14,4,2,2,2,2,2,2,2,0,0,0,0,7,2,2,2,2,2,2,2,2,2,2,2,2,2,2,4,2,2,4,14,0,0,2
2,0,0,2,2,2,2,2,4,2,2,7,0,0,0,0,0,0,0,0,0,0,0,0,0,0,0,0,0,2,2,2,2,2,2,2,0,0,2
2,0,0,2,2,2,2,2,2,2,0,0,0,0,0,0,0,0,0,0,0,0,0,0,0,0,0,0,0,0,2,2,2,2,2,2,0,0,2
2,0,0,2,2,2,2,2,2,0,0,0,0,0,0,0,0,0,0,0,0,0,0,0,0,0,0,0,0,0,0,2,2,2,2,2,0,0,2
2,0,0,2,2,2,2,2,0,0,0,0,0,0,0,0,0,0,0,0,0,0,0,0,0,0,0,0,0,0,0,2,0,2,2,2,0,0,2
2,0,0,14,4,2,20,0,0,0,0,0,0,0,0,0,0,0,0,0,0,0,0,0,0,0,0,0,0,0,0,2,0,2,4,14,0,0,2
2,0,0,2,2,2,20,0,0,0,0,0,0,0,0,0,0,0,0,0,0,0,0,0,0,0,0,0,0,0,0,2,0,19,2,2,0,0,2
2,0,0,2,2,2,20,0,0,0,0,0,0,0,0,0,0,0,0,0,0,0,0,0,0,0,0,0,0,0,0,2,0,0,0,0,0,0,2
2,0,0,2,2,2,20,0,0,0,0,0,0,0,0,0,0,0,0,0,0,0,0,0,0,0,0,0,0,0,0,2,0,19,2,2,0,0,2
2,0,0,14,4,2,20,0,0,0,0,0,0,0,0,0,0,0,0,0,0,0,0,0,0,0,0,0,0,0,0,2,0,2,4,14,0,0,2
2,0,0,2,2,2,2,2,0,0,0,0,0,0,0,0,0,0,0,0,0,0,0,0,0,0,0,0,0,0,0,2,0,2,2,2,0,0,2
2,0,0,2,2,2,2,2,0,0,0,0,0,0,0,0,0,0,0,0,0,0,0,0,0,0,0,0,0,0,0,2,2,2,2,2,0,0,2
2,0,0,2,2,2,2,2,0,0,0,0,0,0,0,0,0,0,0,0,0,0,0,0,0,0,0,0,0,0,2,2,2,2,2,2,0,0,2
2,0,0,2,2,2,2,2,3,11,22,3,0,0,0,0,0,0,0,0,0,0,0,0,0,0,0,0,0,2,2,2,2,2,2,2,0,0,2
2,0,0,14,4,2,2,2,2,2,2,7,0,0,0,0,7,2,2,2,2,2,2,2,2,2,2,2,2,2,2,4,2,2,4,14,0,0,2
2,0,0,2,2,2,2,2,2,2,2,2,2,2,2,2,2,2,2,2,0,0,0,0,0,0,0,0,2,2,2,2,2,2,2,2,0,0,2
2,0,0,2,2,2,2,2,2,2,2,2,2,2,2,2,2,2,2,2,2,2,2,19,0,19,2,2,2,2,2,2,2,2,2,2,0,0,2
2,0,0,2,2,2,4,2,2,2,2,4,14,13,13,14,4,2,2,2,2,4,2,2,0,2,4,2,2,2,2,4,2,2,2,2,0,0,2
2,0,0,2,2,2,2,2,2,2,2,14,2,2,2,2,14,2,2,2,2,14,2,2,0,2,14,2,2,2,2,14,2,2,2,2,0,0,2
2,0,0,0,0,0,0,0,0,0,0,0,0,0,0,0,0,0,0,0,0,0,0,0,0,0,0,0,0,0,0,0,0,0,0,0,0,0,2
2,0,0,0,0,0,0,0,0,0,0,0,0,0,0,0,0,0,0,0,0,0,0,0,0,0,0,0,0,0,0,0,0,0,0,0,0,0,2
2,2,2,2,2,2,2,2,2,2,2,2,2,2,2,2,2,2,2,2,2,2,2,2,2,2,2,2,2,2,2,2,2,2,2,2,2,2,2
endlayer

layer
1,1,1,1,1,1,2,2,2,2,2,2,2,2,2,2,2,2,2,2,2,2,2,2,2,2,2,2,2,2,2,2,1,1,1,1,1,1,1
1,2,2,2,2,2,2,2,13,2,2,2,13,2,13,2,2,2,13,2,13,2,2,2,13,2,13,2,2,2,13,2,2,2,2,2,2,2,1
1,2,2,2,2,2,2,2,13,2,2,2,13,2,13,2,2,2,13,2,13,2,2,2,13,2,13,2,2,2,13,2,2,2,2,2,2,2,1
1,2,2,2,2,2,2,2,2,2,2,2,2,2,2,2,2,2,2,2,2,2,2,2,2,2,2,2,2,2,2,2,2,2,2,2,2,2,1
1,2,2,2,2,2,15,2,2,2,2,15,2,2,2,2,15,2,2,2,2,15,2,2,2,2,15,2,2,2,2,15,2,2,2,2,2,2,1
1,2,2,2,2,2,2,2,2,2,2,2,2,2,2,2,2,2,2,2,2,2,2,2,2,2,2,2,2,2,2,2,2,2,2,2,2,2,1
2,2,2,2,2,2,2,2,2,2,2,2,2,2,2,2,2,2,2,2,2,2,2,2,2,2,2,2,2,2,2,2,2,2,2,2,2,2,2
2,13,13,2,15,2,2,2,2,2,2,2,7,7,7,7,7,7,7,7,7,7,7,7,7,7,7,7,7,2,2,15,2,2,15,2,13,13,2
2,2,2,2,2,2,2,2,15,2,7,7,0,0,0,0,0,14,13,14,0,0,0,0,0,0,0,0,0,7,2,2,2,2,2,2,2,2,2
2,2,2,2,2,2,2,2,2,7,0,0,0,0,0,0,0,14,13,14,0,0,0,0,0,0,0,0,0,0,7,2,2,2,2,2,2,2,2
2,13,13,2,2,2,2,2,7,0,0,0,0,0,0,0,0,14,13,14,0,0,0,0,0,0,0,0,0,0,0,7,2,2,2,2,13,13,2
2,2,2,2,2,8,8,7,0,0,0,0,0,0,0,0,0,14,13,14,0,0,0,0,0,0,0,0,0,0,0,7,2,2,2,2,2,2,2
2,13,13,2,15,20,0,0,0,0,0,0,0,0,0,0,0,14,13,14,0,0,0,0,0,0,0,0,0,0,0,7,2,2,15,2,13,13,2
2,2,2,2,2,20,0,0,0,0,0,0,0,0,0,0,0,14,13,14,0,0,0,0,0,0,0,0,0,0,0,7,2,2,2,2,2,2,2
2,2,2,2,2,20,0,0,0,0,0,0,0,0,0,0,0,14,4,14,0,0,0,0,0,0,0,0,0,0,0,7,2,2,2,2,2,2,2
2,2,2,2,2,20,0,0,0,0,0,0,0,0,0,0,0,14,13,14,0,0,0,0,0,0,0,0,0,0,0,7,2,2,2,2,2,2,2
2,13,13,2,15,20,0,0,0,0,0,0,0,0,0,0,0,14,13,14,0,0,0,0,0,0,0,0,0,0,0,7,2,2,15,2,13,13,2
2,2,2,2,2,10,10,7,0,0,0,0,0,0,0,0,0,14,13,14,0,0,0,0,0,0,0,0,0,0,0,7,2,2,2,2,2,2,2
2,13,13,2,2,2,2,7,0,0,0,0,0,0,0,0,0,14,13,14,0,0,0,0,0,0,0,0,0,0,0,7,2,2,2,2,13,13,2
2,2,2,2,2,2,2,7,14,14,14,14,0,0,0,0,0,14,13,14,0,0,0,0,0,0,0,0,0,0,7,2,2,2,2,2,2,2,2
2,2,2,2,2,2,2,7,3,11,22,3,0,0,0,0,0,14,13,14,0,0,0,0,0,0,0,0,0,7,2,2,2,2,2,2,2,2,2
2,13,13,2,15,2,2,7,7,7,7,7,7,7,7,7,7,7,7,7,7,7,7,7,7,7,7,7,7,2,2,15,2,2,15,2,13,13,2
2,2,2,2,2,2,2,2,2,2,2,2,2,2,2,2,2,2,2,2,2,2,2,2,2,2,2,2,2,2,2,2,2,2,2,2,2,2,2
1,2,2,7,7,7,2,2,2,2,2,2,2,2,2,2,2,2,2,2,2,2,2,2,2,2,2,2,2,2,2,2,2,2,2,2,2,2,1
1,2,2,7,12,7,15,2,2,2,2,15,2,2,2,2,15,2,2,2,2,15,2,2,2,2,15,2,2,2,2,15,2,2,2,2,2,2,1
1,2,2,7,12,7,2,2,2,2,2,2,2,2,2,2,2,2,2,2,2,2,2,2,2,2,2,2,2,2,2,2,2,2,2,2,2,2,1
1,2,2,7,7,7,2,2,13,2,2,2,13,2,13,2,2,2,13,2,13,2,2,2,13,2,13,2,2,2,13,2,2,2,2,2,2,2,1
1,2,2,2,2,2,2,2,13,2,2,2,13,2,13,2,2,2,13,2,13,2,2,2,13,2,13,2,2,2,13,2,2,2,2,2,2,2,1
1,1,1,1,1,1,2,2,2,2,2,2,2,2,2,2,2,2,2,2,2,2,2,2,2,2,2,2,2,2,2,2,1,1,1,1,1,1,1
endlayer

layer
1,1,1,1,1,1,2,2,2,2,2,2,2,2,2,2,2,2,2,2,2,2,2,2,2,2,2,2,2,2,2,2,1,1,1,1,1,1,1
1,1,1,1,1,1,2,3,0,0,0,0,0,3,0,0,0,0,0,3,0,0,0,0,0,3,0,0,0,0,0,3,2,1,1,1,1,1,1
1,1,1,1,1,2,0,0,0,0,0,0,0,0,0,0,0,0,0,0,0,0,0,0,0,0,0,0,0,0,0,0,0,2,1,1,1,1,1
1,1,1,1,2,0,0,0,0,0,0,0,0,0,0,0,0,0,0,0,0,0,0,0,0,0,0,0,0,0,0,0,0,0,2,1,1,1,1
1,1,1,2,0,0,0,0,0,0,0,0,0,0,0,0,0,0,0,0,0,0,0,0,0,0,0,0,0,0,0,0,0,0,0,2,1,1,1
1,2,2,0,0,0,0,0,0,0,0,0,0,0,0,0,0,0,0,0,0,0,0,0,0,0,0,0,0,0,0,0,0,0,0,0,2,2,1
2,3,0,0,0,0,0,0,0,0,0,0,0,0,0,0,0,0,0,0,0,0,0,0,0,0,0,0,0,0,0,0,0,0,0,0,0,3,2
2,0,0,0,0,0,0,0,0,0,0,0,0,0,0,0,0,0,0,0,0,0,0,0,0,0,0,0,0,0,0,0,0,0,0,0,0,0,2
2,0,0,0,0,0,0,0,0,0,0,0,0,0,0,0,0,0,0,0,0,0,0,0,0,0,0,0,0,0,0,0,0,0,0,0,0,0,2
2,0,0,0,0,0,0,0,0,0,0,0,0,0,0,0,0,0,0,0,0,0,0,0,0,0,0,0,0,0,0,0,0,0,0,0,0,0,2
2,0,0,0,0,0,0,0,0,0,0,0,0,0,0,0,0,0,0,0,0,0,0,0,0,0,0,0,0,0,0,0,0,0,0,0,0,0,2
2,3,0,0,0,0,0,0,0,0,0,0,0,0,0,0,0,0,0,0,0,0,0,0,0,0,0,0,0,0,0,0,0,0,0,0,0,3,2
2,0,0,0,0,0,0,0,0,0,0,0,0,0,0,0,0,0,0,0,0,0,0,0,0,0,0,0,0,0,0,0,0,0,0,0,0,0,2
2,0,0,0,0,0,0,0,0,0,0,0,0,0,0,0,0,0,0,0,0,0,0,0,0,0,0,0,0,0,0,0,0,0,0,0,0,0,2
2,0,0,0,0,0,0,0,0,0,0,0,0,0,0,0,0,0,0,0,0,0,0,0,0,0,0,0,0,0,0,0,0,0,0,0,0,0,2
2,0,0,0,0,0,0,0,0,0,0,0,0,0,0,0,0,0,0,0,0,0,0,0,0,0,0,0,0,0,0,0,0,0,0,0,0,0,2
2,0,0,0,0,0,0,0,0,0,0,0,0,0,0,0,0,0,0,0,0,0,0,0,0,0,0,0,0,0,0,0,0,0,0,0,0,0,2
2,3,0,0,0,0,0,0,0,0,0,0,0,0,0,0,0,0,0,0,0,0,0,0,0,0,0,0,0,0,0,0,0,0,0,0,0,3,2
2,0,0,0,0,0,0,0,0,0,0,0,0,0,0,0,0,0,0,0,0,0,0,0,0,0,0,0,0,0,0,0,0,0,0,0,0,0,2
2,0,0,0,0,0,0,0,0,14,14,0,0,0,0,0,0,0,0,0,0,0,0,0,0,0,0,0,0,0,0,0,0,0,0,0,0,0,2
2,0,0,0,0,0,0,0,3,11,22,3,0,0,0,0,0,0,0,0,0,0,0,0,0,0,0,0,0,0,0,0,0,0,0,0,0,0,2
2,0,0,0,0,0,0,0,3,0,0,3,0,0,0,0,0,0,0,0,0,0,0,0,0,0,0,0,0,0,0,0,0,0,0,0,0,0,2
2,3,0,0,0,0,0,0,0,0,0,0,0,0,0,0,0,0,0,0,0,0,0,0,0,0,0,0,0,0,0,0,0,0,0,0,0,3,2
1,2,2,0,0,0,0,0,0,0,0,0,0,0,0,0,0,0,0,0,0,0,0,0,0,0,0,0,0,0,0,0,0,0,0,0,2,2,1
1,1,2,14,0,0,0,0,0,0,0,0,0,0,0,0,0,0,0,0,0,0,0,0,0,0,0,0,0,0,0,0,0,0,0,2,1,1,1
1,1,2,14,0,0,0,0,0,0,0,0,0,0,0,0,0,0,0,0,0,0,0,0,0,0,0,0,0,0,0,0,0,0,2,1,1,1,1
1,1,2,14,14,14,0,0,0,0,0,0,0,0,0,0,0,0,0,0,0,0,0,0,0,0,0,0,0,0,0,0,0,2,1,1,1,1,1
1,1,3,2,2,2,2,3,0,0,0,0,0,3,0,0,0,0,0,3,0,0,0,0,0,3,0,0,0,0,0,3,2,1,1,1,1,1,1
1,1,1,1,1,1,2,2,2,2,2,2,2,2,2,2,2,2,2,2,2,2,2,2,2,2,2,2,2,2,2,2,1,1,1,1,1,1,1
endlayer

layer
1,1,1,1,1,1,2,2,2,2,2,2,2,2,2,2,2,2,2,2,2,2,2,2,2,2,2,2,2,2,2,2,1,1,1,1,1,1,1
1,1,1,1,1,1,2,3,0,0,0,0,0,3,0,0,0,0,0,3,0,0,0,0,0,3,0,0,0,0,0,3,2,1,1,1,1,1,1
1,1,1,1,1,2,0,0,0,0,0,0,0,0,0,0,0,0,0,0,0,0,0,0,0,0,0,0,0,0,0,0,0,2,1,1,1,1,1
1,1,1,1,2,0,0,0,0,0,0,0,0,0,0,0,0,0,0,0,0,0,0,0,0,0,0,0,0,0,0,0,0,0,2,1,1,1,1
1,1,1,2,0,0,0,0,0,0,0,0,0,0,0,0,0,0,0,0,0,0,0,0,0,0,0,0,0,0,0,0,0,0,0,2,1,1,1
1,2,2,0,0,0,0,0,0,0,0,0,0,0,0,0,0,0,0,0,0,0,0,0,0,0,0,0,0,0,0,0,0,0,0,0,2,2,1
2,3,0,0,0,0,0,0,0,0,0,0,0,0,0,0,0,0,0,0,0,0,0,0,0,0,0,0,0,0,0,0,0,0,0,0,0,3,2
2,0,0,0,0,0,0,0,0,0,0,0,0,0,0,0,0,0,0,0,0,0,0,0,0,0,0,0,0,0,0,0,0,0,0,0,0,0,2
2,0,0,0,0,0,0,0,0,0,0,0,0,0,0,0,0,0,0,0,0,0,0,0,0,0,0,0,0,0,0,0,0,0,0,0,0,0,2
2,0,0,0,0,0,0,0,0,0,0,0,0,0,0,0,0,0,0,0,0,0,0,0,0,0,0,0,0,0,0,0,0,0,0,0,0,0,2
2,0,0,0,0,0,0,0,0,0,0,0,0,0,0,0,0,0,0,0,0,0,0,0,0,0,0,0,0,0,0,0,0,0,0,0,0,0,2
2,3,0,0,0,0,0,0,0,0,0,0,0,0,0,0,0,0,0,0,0,0,0,0,0,0,0,0,0,0,0,0,0,0,0,0,0,3,2
2,0,0,0,0,0,0,0,0,0,0,0,0,0,0,0,0,0,0,0,0,0,0,0,0,0,0,0,0,0,0,0,0,0,0,0,0,0,2
2,0,0,0,0,0,0,0,0,0,0,0,0,0,0,0,0,0,0,0,0,0,0,0,0,0,0,0,0,0,0,0,0,0,0,0,0,0,2
2,0,0,0,0,0,0,0,0,0,0,0,0,0,0,0,0,0,0,0,0,0,0,0,0,0,0,0,0,0,0,0,0,0,0,0,0,0,2
2,0,0,0,0,0,0,0,0,0,0,0,0,0,0,0,0,0,0,0,0,0,0,0,0,0,0,0,0,0,0,0,0,0,0,0,0,0,2
2,0,0,0,0,0,0,0,0,0,0,0,0,0,0,0,0,0,0,0,0,0,0,0,0,0,0,0,0,0,0,0,0,0,0,0,0,0,2
2,3,0,0,0,0,0,0,0,0,0,0,0,0,0,0,0,0,0,0,0,0,0,0,0,0,0,0,0,0,0,0,0,0,0,0,0,3,2
2,0,0,0,0,0,0,0,0,0,0,0,0,0,0,0,0,0,0,0,0,0,0,0,0,0,0,0,0,0,0,0,0,0,0,0,0,0,2
2,0,0,0,0,0,0,0,0,14,14,0,0,0,0,0,0,0,0,0,0,0,0,0,0,0,0,0,0,0,0,0,0,0,0,0,0,0,2
2,0,0,0,0,0,0,0,3,11,22,3,0,0,0,0,0,0,0,0,0,0,0,0,0,0,0,0,0,0,0,0,0,0,0,0,0,0,2
2,0,0,0,0,0,0,0,3,0,0,3,0,0,0,0,0,0,0,0,0,0,0,0,0,0,0,0,0,0,0,0,0,0,0,0,0,0,2
2,3,0,0,0,0,0,0,0,0,0,0,0,0,0,0,0,0,0,0,0,0,0,0,0,0,0,0,0,0,0,0,0,0,0,0,0,3,2
1,2,2,0,0,0,0,0,0,0,0,0,0,0,0,0,0,0,0,0,0,0,0,0,0,0,0,0,0,0,0,0,0,0,0,0,2,2,1
1,1,3,14,0,0,0,0,0,0,0,0,0,0,0,0,0,0,0,0,0,0,0,0,0,0,0,0,0,0,0,0,0,0,0,2,1,1,1
1,1,3,14,0,0,0,0,0,0,0,0,0,0,0,0,0,0,0,0,0,0,0,0,0,0,0,0,0,0,0,0,0,0,2,1,1,1,1
1,1,3,14,14,14,0,0,0,0,0,0,0,0,0,0,0,0,0,0,0,0,0,0,0,0,0,0,0,0,0,0,0,2,1,1,1,1,1
1,1,3,3,3,3,2,3,0,0,0,0,0,3,0,0,0,0,0,3,0,0,0,0,0,3,0,0,0,0,0,3,2,1,1,1,1,1,1
1,1,1,1,1,1,2,2,2,2,2,2,2,2,2,2,2,2,2,2,2,2,2,2,2,2,2,2,2,2,2,2,1,1,1,1,1,1,1
endlayer

layer
1,1,1,1,1,1,9,9,9,9,9,9,9,9,9,9,9,9,9,9,9,9,9,9,9,9,9,9,9,9,9,9,1,1,1,1,1,1,1
1,1,1,1,1,1,9,3,0,0,0,0,0,3,0,0,0,0,0,3,0,0,0,0,0,3,0,0,0,0,0,3,9,1,1,1,1,1,1
1,1,1,1,1,9,0,0,0,0,0,0,0,0,0,0,0,0,0,0,0,0,0,0,0,0,0,0,0,0,0,0,0,9,1,1,1,1,1
1,1,1,1,9,0,0,0,0,0,0,0,0,0,0,0,0,0,0,0,0,0,0,0,0,0,0,0,0,0,0,0,0,0,9,1,1,1,1
1,1,1,9,0,0,0,0,0,0,0,0,0,0,0,0,0,0,0,0,0,0,0,0,0,0,0,0,0,0,0,0,0,0,0,9,1,1,1
1,9,9,0,0,0,0,0,0,0,0,0,0,0,0,0,0,0,0,0,0,0,0,0,0,0,0,0,0,0,0,0,0,0,0,0,9,9,1
9,3,0,0,0,0,0,0,0,0,0,0,0,0,0,0,0,0,0,0,0,0,0,0,0,0,0,0,0,0,0,0,0,0,0,0,0,3,9
9,0,0,0,0,0,0,0,0,0,0,0,0,0,0,0,0,0,0,0,0,0,0,0,0,0,0,0,0,0,0,0,0,0,0,0,0,0,9
9,0,0,0,0,0,0,0,0,0,0,0,0,0,0,0,0,0,0,0,0,0,0,0,0,0,0,0,0,0,0,0,0,0,0,0,0,0,9
9,0,0,0,0,0,0,0,0,0,0,0,0,0,0,0,0,0,0,0,0,0,0,0,0,0,0,0,0,0,0,0,0,0,0,0,0,0,9
9,0,0,0,0,0,0,0,0,0,0,0,0,0,0,0,0,0,0,0,0,0,0,0,0,0,0,0,0,0,0,0,0,0,0,0,0,0,9
9,3,0,0,0,0,0,0,0,0,0,0,0,0,0,0,0,0,0,0,0,0,0,0,0,0,0,0,0,0,0,0,0,0,0,0,0,3,9
9,0,0,0,0,0,0,0,0,0,0,0,0,0,0,0,0,0,0,0,0,0,0,0,0,0,0,0,0,0,0,0,0,0,0,0,0,0,9
9,0,0,0,0,0,0,0,0,0,0,0,0,0,0,0,0,0,0,0,0,0,0,0,0,0,0,0,0,0,0,0,0,0,0,0,0,0,9
9,0,0,0,0,0,0,0,0,0,0,0,0,0,0,0,0,0,0,0,0,0,0,0,0,0,0,0,0,0,0,0,0,0,0,0,0,0,9
9,0,0,0,0,0,0,0,0,0,0,0,0,0,0,0,0,0,0,0,0,0,0,0,0,0,0,0,0,0,0,0,0,0,0,0,0,0,9
9,0,0,0,0,0,0,0,0,0,0,0,0,0,0,0,0,0,0,0,0,0,0,0,0,0,0,0,0,0,0,0,0,0,0,0,0,0,9
9,3,0,0,0,0,0,0,0,0,0,0,0,0,0,0,0,0,0,0,0,0,0,0,0,0,0,0,0,0,0,0,0,0,0,0,0,3,9
9,0,0,0,0,0,0,0,0,0,0,0,0,0,0,0,0,0,0,0,0,0,0,0,0,0,0,0,0,0,0,0,0,0,0,0,0,0,9
9,0,0,0,0,0,0,0,0,14,14,0,0,0,0,0,0,0,0,0,0,0,0,0,0,0,0,0,0,0,0,0,0,0,0,0,0,0,9
9,0,0,0,0,0,0,0,3,11,22,3,0,0,0,0,0,0,0,0,0,0,0,0,0,0,0,0,0,0,0,0,0,0,0,0,0,0,9
9,0,0,0,0,0,0,0,3,0,0,3,0,0,0,0,0,0,0,0,0,0,0,0,0,0,0,0,0,0,0,0,0,0,0,0,0,0,9
9,3,0,0,0,0,0,0,0,0,0,0,0,0,0,0,0,0,0,0,0,0,0,0,0,0,0,0,0,0,0,0,0,0,0,0,0,3,9
1,9,9,0,0,0,0,0,0,0,0,0,0,0,0,0,0,0,0,0,0,0,0,0,0,0,0,0,0,0,0,0,0,0,0,0,9,9,1
1,1,3,14,0,0,0,0,0,0,0,0,0,0,0,0,0,0,0,0,0,0,0,0,0,0,0,0,0,0,0,0,0,0,0,9,1,1,1
1,1,3,14,0,0,0,0,0,0,0,0,0,0,0,0,0,0,0,0,0,0,0,0,0,0,0,0,0,0,0,0,0,0,9,1,1,1,1
1,1,3,14,14,14,0,0,0,0,0,0,0,0,0,0,0,0,0,0,0,0,0,0,0,0,0,0,0,0,0,0,0,9,1,1,1,1,1
1,1,3,3,3,3,9,3,0,0,0,0,0,3,0,0,0,0,0,3,0,0,0,0,0,3,0,0,0,0,0,3,9,1,1,1,1,1,1
1,1,1,1,1,1,9,9,9,9,9,9,9,9,9,9,9,9,9,9,9,9,9,9,9,9,9,9,9,9,9,9,1,1,1,1,1,1,1
endlayer

layer
1,1,1,1,1,1,2,2,2,2,2,2,2,2,2,2,2,2,2,2,2,2,2,2,2,2,2,2,2,2,2,2,1,1,1,1,1,1,1
1,1,1,1,1,1,2,3,0,0,0,0,0,3,0,0,0,0,0,3,0,0,0,0,0,3,0,0,0,0,0,3,2,1,1,1,1,1,1
1,1,1,1,1,2,0,0,0,0,0,0,0,0,0,0,0,0,0,0,0,0,0,0,0,0,0,0,0,0,0,0,0,2,1,1,1,1,1
1,1,1,1,2,0,0,0,0,0,0,0,0,0,0,0,0,0,0,0,0,0,0,0,0,0,0,0,0,0,0,0,0,0,2,1,1,1,1
1,1,1,2,0,0,0,0,0,0,0,0,0,0,0,0,0,0,0,0,0,0,0,0,0,0,0,0,0,0,0,0,0,0,0,2,1,1,1
1,2,2,0,0,0,0,0,0,0,0,0,0,0,0,0,0,0,0,0,0,0,0,0,0,0,0,0,0,0,0,0,0,0,0,0,2,2,1
2,3,0,0,0,0,0,0,0,0,0,0,0,0,0,0,0,0,0,0,0,0,0,0,0,0,0,0,0,0,0,0,0,0,0,0,0,3,2
2,0,0,0,0,0,0,0,0,0,0,0,0,0,0,0,0,0,0,0,0,0,0,0,0,0,0,0,0,0,0,0,0,0,0,0,0,0,2
2,0,0,0,0,0,0,0,0,0,0,0,0,0,0,0,0,0,0,0,0,0,0,0,0,0,0,0,0,0,0,0,0,0,0,0,0,0,2
2,0,0,0,0,0,0,0,0,0,0,0,0,0,0,0,0,0,0,0,0,0,0,0,0,0,0,0,0,0,0,0,0,0,0,0,0,0,2
2,0,0,0,0,0,0,0,0,0,0,0,0,0,0,0,0,0,0,0,0,0,0,0,0,0,0,0,0,0,0,0,0,0,0,0,0,0,2
2,3,0,0,0,0,0,0,0,0,0,0,0,0,0,0,0,0,0,0,0,0,0,0,0,0,0,0,0,0,0,0,0,0,0,0,0,3,2
2,0,0,0,0,0,0,0,0,0,0,0,0,0,0,0,0,0,0,0,0,0,0,0,0,0,0,0,0,0,0,0,0,0,0,0,0,0,2
2,0,0,0,0,0,0,0,0,0,0,0,0,0,0,0,0,0,0,0,0,0,0,0,0,0,0,0,0,0,0,0,0,0,0,0,0,0,2
2,0,0,0,0,0,0,0,0,0,0,0,0,0,0,0,0,0,0,0,0,0,0,0,0,0,0,0,0,0,0,0,0,0,0,0,0,0,2
2,0,0,0,0,0,0,0,0,0,0,0,0,0,0,0,0,0,0,0,0,0,0,0,0,0,0,0,0,0,0,0,0,0,0,0,0,0,2
2,0,0,0,0,0,0,0,0,0,0,0,0,0,0,0,0,0,0,0,0,0,0,0,0,0,0,0,0,0,0,0,0,0,0,0,0,0,2
2,3,0,0,0,0,0,0,0,0,0,0,0,0,0,0,0,0,0,0,0,0,0,0,0,0,0,0,0,0,0,0,0,0,0,0,0,3,2
2,0,0,0,0,0,0,0,0,0,0,0,0,0,0,0,0,0,0,0,0,0,0,0,0,0,0,0,0,0,0,0,0,0,0,0,0,0,2
2,0,0,0,0,0,0,0,0,14,14,0,0,0,0,0,0,0,0,0,0,0,0,0,0,0,0,0,0,0,0,0,0,0,0,0,0,0,2
2,0,0,0,0,0,0,0,3,11,22,3,0,0,0,0,0,0,0,0,0,0,0,0,0,0,0,0,0,0,0,0,0,0,0,0,0,0,2
2,0,0,0,0,0,0,0,3,0,0,3,0,0,0,0,0,0,0,0,0,0,0,0,0,0,0,0,0,0,0,0,0,0,0,0,0,0,2
2,3,0,0,0,0,0,0,0,0,0,0,0,0,0,0,0,0,0,0,0,0,0,0,0,0,0,0,0,0,0,0,0,0,0,0,0,3,2
1,2,2,0,0,0,0,0,0,0,0,0,0,0,0,0,0,0,0,0,0,0,0,0,0,0,0,0,0,0,0,0,0,0,0,0,2,2,1
1,1,3,14,14,14,0,0,0,0,0,0,0,0,0,0,0,0,0,0,0,0,0,0,0,0,0,0,0,0,0,0,0,0,0,2,1,1,1
1,1,3,14,23,14,0,0,0,0,0,0,0,0,0,0,0,0,0,0,0,0,0,0,0,0,0,0,0,0,0,0,0,0,2,1,1,1,1
1,1,3,14,14,14,0,0,0,0,0,0,0,0,0,0,0,0,0,0,0,0,0,0,0,0,0,0,0,0,0,0,0,2,1,1,1,1,1
1,1,3,3,3,3,2,3,0,0,0,0,0,3,0,0,0,0,0,3,0,0,0,0,0,3,0,0,0,0,0,3,2,1,1,1,1,1,1
1,1,1,1,1,1,2,2,2,2,2,2,2,2,2,2,2,2,2,2,2,2,2,2,2,2,2,2,2,2,2,2,1,1,1,1,1,1,1
endlayer

layer
1,1,1,1,1,1,2,2,2,2,2,2,2,2,2,2,2,2,2,2,2,2,2,2,2,2,2,2,2,2,2,2,1,1,1,1,1,1,1
1,1,1,1,1,1,2,3,3,3,3,3,3,3,3,3,3,3,3,3,3,3,3,3,3,3,3,3,3,3,3,3,2,1,1,1,1,1,1
1,1,1,1,1,2,0,0,0,0,0,0,0,0,0,0,0,0,0,0,0,0,0,0,0,0,0,0,0,0,0,0,0,2,1,1,1,1,1
1,1,1,1,2,0,0,0,0,0,0,0,0,0,0,0,0,0,0,0,0,0,0,0,0,0,0,0,0,0,0,0,0,0,2,1,1,1,1
1,1,1,2,0,0,0,0,0,0,0,0,0,0,0,0,0,0,0,0,0,0,0,0,0,0,0,0,0,0,0,0,0,0,0,2,1,1,1
1,2,2,0,0,0,0,0,0,0,0,0,0,0,0,0,0,0,0,0,0,0,0,0,0,0,0,0,0,0,0,0,0,0,0,0,2,2,1
2,3,0,0,0,0,0,0,0,0,0,0,0,0,0,0,0,0,0,0,0,0,0,0,0,0,0,0,0,0,0,0,0,0,0,0,0,3,2
2,3,0,0,0,0,0,0,0,0,0,0,0,0,0,0,0,0,0,0,0,0,0,0,0,0,0,0,0,0,0,0,0,0,0,0,0,3,2
2,3,0,0,0,0,0,0,0,0,0,0,0,0,0,0,0,0,0,0,0,0,0,0,0,0,0,0,0,0,0,0,0,0,0,0,0,3,2
2,3,0,0,0,0,0,0,0,0,0,0,0,0,0,0,0,0,0,0,0,0,0,0,0,0,0,0,0,0,0,0,0,0,0,0,0,3,2
2,3,0,0,0,0,0,0,0,0,0,0,0,0,0,0,0,0,0,0,0,0,0,0,0,0,0,0,0,0,0,0,0,0,0,0,0,3,2
2,3,0,0,0,0,0,0,0,0,0,0,0,0,0,0,0,0,0,0,0,0,0,0,0,0,0,0,0,0,0,0,0,0,0,0,0,3,2
2,3,0,0,0,0,0,0,0,0,0,0,0,0,0,0,0,0,0,0,0,0,0,0,0,0,0,0,0,0,0,0,0,0,0,0,0,3,2
2,3,0,0,0,0,0,0,0,0,0,0,0,0,0,0,0,0,0,0,0,0,0,0,0,0,0,0,0,0,0,0,0,0,0,0,0,3,2
2,3,0,0,0,0,0,0,0,0,0,0,0,0,0,0,0,0,0,0,0,0,0,0,0,0,0,0,0,0,0,0,0,0,0,0,0,3,2
2,3,0,0,0,0,0,0,0,0,0,0,0,0,0,0,0,0,0,0,0,0,0,0,0,0,0,0,0,0,0,0,0,0,0,0,0,3,2
2,3,0,0,0,0,0,0,0,0,0,0,0,0,0,0,0,0,0,0,0,0,0,0,0,0,0,0,0,0,0,0,0,0,0,0,0,3,2
2,3,0,0,0,0,0,0,0,0,0,0,0,0,0,0,0,0,0,0,0,0,0,0,0,0,0,0,0,0,0,0,0,0,0,0,0,3,2
2,3,0,0,0,0,0,0,0,0,0,0,0,0,0,0,0,0,0,0,0,0,0,0,0,0,0,0,0,0,0,0,0,0,0,0,0,3,2
2,3,0,0,0,0,0,0,0,14,14,0,0,0,0,0,0,0,0,0,0,0,0,0,0,0,0,0,0,0,0,0,0,0,0,0,0,3,2
2,3,0,0,0,0,0,0,3,11,22,3,0,0,0,0,0,0,0,0,0,0,0,0,0,0,0,0,0,0,0,0,0,0,0,0,0,3,2
2,3,0,0,0,0,0,0,3,0,0,3,0,0,0,0,0,0,0,0,0,0,0,0,0,0,0,0,0,0,0,0,0,0,0,0,0,3,2
2,3,0,0,0,0,0,0,0,0,0,0,0,0,0,0,0,0,0,0,0,0,0,0,0,0,0,0,0,0,0,0,0,0,0,0,0,3,2
1,2,2,17,17,17,24,0,0,0,0,0,0,0,0,0,0,0,0,0,0,0,0,0,0,0,0,0,0,0,0,0,0,0,0,0,2,2,1
1,1,3,14,14,14,24,0,0,0,0,0,0,0,0,0,0,0,0,0,0,0,0,0,0,0,0,0,0,0,0,0,0,0,0,2,1,1,1
1,1,3,14,0,14,24,0,0,0,0,0,0,0,0,0,0,0,0,0,0,0,0,0,0,0,0,0,0,0,0,0,0,0,2,1,1,1,1
1,1,3,14,14,14,24,0,0,0,0,0,0,0,0,0,0,0,0,0,0,0,0,0,0,0,0,0,0,0,0,0,0,2,1,1,1,1,1
1,1,3,3,3,3,2,3,3,3,3,3,3,3,3,3,3,3,3,3,3,3,3,3,3,3,3,3,3,3,3,3,2,1,1,1,1,1,1
1,1,1,1,1,1,2,2,2,2,2,2,2,2,2,2,2,2,2,2,2,2,2,2,2,2,2,2,2,2,2,2,1,1,1,1,1,1,1
endlayer

layer
1,1,1,1,1,1,3,3,3,3,3,3,3,3,3,3,3,3,3,3,3,3,3,3,3,3,3,3,3,3,3,3,1,1,1,1,1,1,1
1,1,1,1,1,1,3,4,3,3,3,3,3,4,3,3,3,3,3,4,3,3,3,3,3,4,3,3,3,3,3,4,3,1,1,1,1,1,1
1,1,1,1,1,3,25,5,25,25,25,25,25,5,25,25,25,25,25,5,25,25,25,25,25,5,25,25,25,25,25,5,25,3,1,1,1,1,1
1,1,1,1,4,25,25,25,25,25,25,25,25,25,25,25,25,25,25,25,25,25,25,25,25,25,25,25,25,25,25,25,25,25,4,1,1,1,1
1,1,1,3,5,25,25,25,25,25,25,25,25,25,25,25,25,25,25,25,25,25,25,25,25,25,25,25,25,25,25,25,25,25,5,3,1,1,1
1,1,3,25,25,25,25,25,25,25,25,25,25,25,25,25,25,25,25,25,25,25,25,25,25,25,25,25,25,25,25,25,25,25,25,25,3,1,1
3,3,25,25,25,25,25,25,25,25,25,25,25,25,25,25,25,25,25,25,25,25,25,25,25,25,25,25,25,25,25,25,25,25,25,25,25,3,3
3,3,25,25,25,25,25,25,25,3,3,3,3,3,3,3,3,3,3,3,3,3,3,3,3,3,3,3,3,3,25,25,25,25,25,25,25,3,3
3,3,25,25,25,25,25,25,3,3,0,0,0,0,0,0,0,0,0,0,0,0,0,0,0,0,0,0,0,3,3,25,25,25,25,25,25,3,3
3,4,5,25,25,25,25,3,3,0,0,0,0,0,0,0,0,0,0,0,0,0,0,0,0,0,0,0,0,0,3,3,25,25,25,25,5,4,3
3,3,25,25,25,25,25,3,0,0,0,0,0,0,0,0,0,0,0,0,0,0,0,0,0,0,0,0,0,0,0,3,25,25,25,25,25,3,3
3,3,25,25,25,25,25,3,0,0,0,0,0,0,0,0,0,0,0,0,0,0,0,0,0,0,0,0,0,0,0,3,25,25,25,25,25,3,3
3,3,25,25,25,25,25,3,0,0,0,0,0,0,0,0,0,0,0,0,0,0,0,0,0,0,0,0,0,0,0,3,25,25,25,25,25,3,3
3,3,25,25,25,25,25,3,0,0,0,0,0,0,0,0,0,0,0,0,0,0,0,0,0,0,0,0,0,0,0,3,25,25,25,25,25,3,3
3,4,5,25,25,25,25,3,0,0,0,0,0,0,0,0,0,0,0,0,0,0,0,0,0,0,0,0,0,0,0,3,25,25,25,25,5,4,3
3,3,25,25,25,25,25,3,0,0,0,0,0,0,0,0,0,0,0,0,0,0,0,0,0,0,0,0,0,0,0,3,25,25,25,25,25,3,3
3,3,25,25,25,25,25,3,0,0,0,0,0,0,0,0,0,0,0,0,0,0,0,0,0,0,0,0,0,0,0,3,25,25,25,25,25,3,3
3,3,25,25,25,25,25,3,0,0,0,0,0,0,0,0,0,0,0,0,0,0,0,0,0,0,0,0,0,0,0,3,25,25,25,25,25,3,3
3,3,25,25,25,25,25,3,0,0,0,0,0,0,0,0,0,0,0,0,0,0,0,0,0,0,0,0,0,0,0,3,25,25,25,25,25,3,3
3,4,5,25,25,25,25,3,0,14,14,0,0,0,0,0,0,0,0,0,0,0,0,0,0,0,0,0,0,0,3,3,25,25,25,25,5,4,3
3,3,25,25,25,25,25,3,3,11,22,3,0,0,0,0,0,0,0,0,0,0,0,0,0,0,0,0,0,3,3,25,25,25,25,25,25,3,3
3,3,25,25,25,25,25,3,3,3,3,3,3,3,3,3,3,3,3,3,3,3,3,3,3,3,3,3,3,3,25,25,25,25,25,25,25,3,3
3,3,25,25,25,25,25,25,25,25,25,25,25,25,25,25,25,25,25,25,25,25,25,25,25,25,25,25,25,25,25,25,25,25,25,25,25,3,3
1,3,3,3,3,3,3,25,25,25,25,25,25,25,25,25,25,25,25,25,25,25,25,25,25,25,25,25,25,25,25,25,25,25,25,25,3,1,1
1,1,3,14,14,14,3,25,25,25,25,25,25,25,25,25,25,25,25,25,25,25,25,25,25,25,25,25,25,25,25,25,25,25,5,3,1,1,1
1,1,3,14,0,14,3,25,25,25,25,25,25,25,25,25,25,25,25,25,25,25,25,25,25,25,25,25,25,25,25,25,25,25,4,1,1,1,1
1,1,3,14,14,14,3,5,25,25,25,25,25,5,25,25,25,25,25,5,25,25,25,25,25,5,25,25,25,25,25,5,25,3,1,1,1,1,1
1,1,3,3,3,3,3,4,3,3,3,3,3,4,3,3,3,3,3,4,3,3,3,3,3,4,3,3,3,3,3,4,3,1,1,1,1,1,1
1,1,1,1,1,1,3,3,3,3,3,3,3,3,3,3,3,3,3,3,3,3,3,3,3,3,3,3,3,3,3,3,1,1,1,1,1,1,1
endlayer

layer
1,1,1,1,1,1,1,1,1,1,1,1,1,1,1,1,1,1,1,1,1,1,1,1,1,1,1,1,1,1,1,1,1,1,1,1,1,1,1
1,1,1,1,1,1,3,3,3,3,3,3,3,3,3,3,3,3,3,3,3,3,3,3,3,3,3,3,3,3,3,3,3,1,1,1,1,1,1
1,1,1,1,1,3,3,3,3,3,3,3,3,3,3,3,3,3,3,3,3,3,3,3,3,3,3,3,3,3,3,3,3,3,1,1,1,1,1
1,1,1,1,3,3,3,3,3,3,3,3,3,3,3,3,3,3,3,3,3,3,3,3,3,3,3,3,3,3,3,3,3,3,3,1,1,1,1
1,1,1,3,3,3,3,3,3,3,3,3,3,3,3,3,3,3,3,3,3,3,3,3,3,3,3,3,3,3,3,3,3,3,3,3,1,1,1
1,1,3,3,3,3,3,3,3,3,3,3,3,3,3,3,3,3,3,3,3,3,3,3,3,3,3,3,3,3,3,3,3,3,3,3,3,1,1
1,3,3,3,3,3,3,3,3,3,3,3,3,3,3,3,3,3,3,3,3,3,3,3,3,3,3,3,3,3,3,3,3,3,3,3,3,3,1
1,3,3,3,3,3,3,3,3,3,3,3,3,3,3,3,3,3,3,3,3,3,3,3,3,3,3,3,3,3,3,3,3,3,3,3,3,3,1
1,3,3,3,3,3,3,3,3,3,3,3,3,3,3,3,3,3,3,3,3,3,3,3,3,3,3,3,3,3,3,3,3,3,3,3,3,3,1
1,3,3,3,3,3,3,3,3,3,0,0,3,0,0,0,0,3,0,0,0,3,0,0,0,0,3,0,0,3,3,3,3,3,3,3,3,3,1
1,3,3,3,3,3,3,3,3,0,0,0,3,0,0,0,0,3,0,0,0,3,0,0,0,0,3,0,0,0,3,3,3,3,3,3,3,3,1
1,3,3,3,3,3,3,3,3,3,3,3,3,3,3,3,3,3,3,3,3,3,3,3,3,3,3,3,3,3,3,3,3,3,3,3,3,3,1
1,3,3,3,3,3,3,3,3,0,0,0,3,0,0,0,0,3,0,0,0,3,0,0,0,0,3,0,0,0,3,3,3,3,3,3,3,3,1
1,3,3,3,3,3,3,3,3,0,0,0,3,0,0,0,0,3,0,0,0,3,0,0,0,0,3,0,0,0,3,3,3,3,3,3,3,3,1
1,3,3,3,3,3,3,3,3,3,3,3,3,3,3,3,3,3,3,3,3,3,3,3,3,3,3,3,3,3,3,3,3,3,3,3,3,3,1
1,3,3,3,3,3,3,3,3,0,0,0,3,0,0,0,0,3,0,0,0,3,0,0,0,0,3,0,0,0,3,3,3,3,3,3,3,3,1
1,3,3,3,3,3,3,3,3,0,0,0,3,0,0,0,0,3,0,0,0,3,0,0,0,0,3,0,0,0,3,3,3,3,3,3,3,3,1
1,3,3,3,3,3,3,3,3,3,3,3,3,3,3,3,3,3,3,3,3,3,3,3,3,3,3,3,3,3,3,3,3,3,3,3,3,3,1
1,3,3,3,3,3,3,3,0,0,0,0,3,0,0,0,0,3,0,0,0,3,0,0,0,0,3,0,0,0,3,3,3,3,3,3,3,3,1
1,3,3,3,3,3,3,3,0,14,14,0,3,0,0,0,0,3,0,0,0,3,0,0,0,0,3,0,0,3,3,3,3,3,3,3,3,3,1
1,3,3,3,3,3,3,3,3,11,22,3,3,3,3,3,3,3,3,3,3,3,3,3,3,3,3,3,3,3,3,3,3,3,3,3,3,3,1
1,3,3,3,3,3,3,3,3,3,3,3,3,3,3,3,3,3,3,3,3,3,3,3,3,3,3,3,3,3,3,3,3,3,3,3,3,3,1
1,3,3,3,3,3,3,3,3,3,3,3,3,3,3,3,3,3,3,3,3,3,3,3,3,3,3,3,3,3,3,3,3,3,3,3,3,3,1
1,3,3,3,3,3,3,3,3,3,3,3,3,3,3,3,3,3,3,3,3,3,3,3,3,3,3,3,3,3,3,3,3,3,3,3,3,1,1
1,1,3,14,14,14,3,3,3,3,3,3,3,3,3,3,3,3,3,3,3,3,3,3,3,3,3,3,3,3,3,3,3,3,3,3,1,1,1
1,1,3,14,0,14,3,3,3,3,3,3,3,3,3,3,3,3,3,3,3,3,3,3,3,3,3,3,3,3,3,3,3,3,3,1,1,1,1
1,1,3,14,14,14,3,3,3,3,3,3,3,3,3,3,3,3,3,3,3,3,3,3,3,3,3,3,3,3,3,3,3,3,1,1,1,1,1
1,1,3,3,3,3,3,3,3,3,3,3,3,3,3,3,3,3,3,3,3,3,3,3,3,3,3,3,3,3,3,3,3,1,1,1,1,1,1
1,1,1,1,1,1,1,1,1,1,1,1,1,1,1,1,1,1,1,1,1,1,1,1,1,1,1,1,1,1,1,1,1,1,1,1,1,1,1
endlayer

layer
1,1,1,1,1,1,1,1,1,1,1,1,1,1,1,1,1,1,1,1,1,1,1,1,1,1,1,1,1,1,1,1,1,1,1,1,1,1,1
1,1,1,1,1,1,1,1,1,1,1,1,1,1,1,1,1,1,1,1,1,1,1,1,1,1,1,1,1,1,1,1,1,1,1,1,1,1,1
1,1,1,1,1,1,1,1,1,1,1,1,1,1,1,1,1,1,1,1,1,1,1,1,1,1,1,1,1,1,1,1,1,1,1,1,1,1,1
1,1,1,1,1,1,1,1,1,1,2,2,1,2,2,1,2,1,2,2,2,2,2,1,1,2,2,1,1,1,1,1,1,1,1,1,1,1,1
1,1,1,1,1,1,1,1,1,1,2,2,2,1,2,1,2,1,1,2,1,1,1,2,2,2,2,2,1,1,1,1,1,1,1,1,1,1,1
1,1,1,1,1,1,1,1,1,1,1,1,1,1,2,1,2,1,2,2,2,1,2,1,2,1,1,1,1,1,1,1,1,1,1,1,1,1,1
1,1,1,1,2,2,1,1,1,1,1,1,1,1,1,1,1,1,1,1,1,1,1,1,1,1,1,1,1,1,1,1,1,1,1,1,1,1,1
1,1,1,1,1,2,1,1,1,1,1,1,1,1,1,1,1,1,1,1,1,1,1,1,1,1,1,1,1,1,1,1,1,1,1,1,1,1,1
1,1,1,1,1,2,1,1,1,3,3,3,3,3,3,3,3,3,3,3,3,3,3,3,3,3,3,3,3,3,1,1,1,2,2,2,1,1,1
1,1,1,1,1,1,1,1,3,3,25,25,3,25,25,25,25,3,25,25,25,3,25,25,25,25,3,25,25,3,3,1,1,1,1,1,1,1,1
1,1,1,1,1,2,1,1,3,25,5,25,3,25,5,25,25,3,25,5,25,3,25,25,5,25,3,25,5,25,3,1,1,2,1,2,1,1,1
1,1,1,1,1,2,1,1,3,3,4,3,3,3,4,3,3,3,3,4,3,3,3,3,4,3,3,3,4,3,3,1,1,1,2,1,1,1,1
1,1,1,1,2,1,1,1,3,25,5,25,3,25,5,25,25,3,25,5,25,3,25,25,5,25,3,25,5,25,3,1,1,2,2,2,1,1,1
1,1,1,1,1,2,1,1,3,25,25,25,3,25,25,25,25,3,25,25,25,3,25,25,25,25,3,25,25,25,3,1,1,1,2,1,1,1,1
1,1,1,2,2,2,1,1,3,3,4,3,3,3,3,3,3,3,3,3,3,3,3,3,3,3,3,3,3,3,3,1,1,1,2,1,1,1,1
1,1,1,1,1,1,1,1,3,25,5,25,3,25,25,25,25,3,25,25,25,3,25,25,25,25,3,25,25,25,3,1,1,1,1,2,1,1,1
1,1,1,1,2,1,1,1,3,25,25,25,3,25,5,25,25,3,25,5,25,3,25,25,5,25,3,25,5,25,3,1,1,1,2,2,1,1,1
1,1,1,1,1,2,1,3,3,3,3,3,3,3,4,3,3,3,3,4,3,3,3,3,4,3,3,3,4,3,3,1,1,1,1,2,1,1,1
1,1,1,2,2,1,1,3,0,0,0,0,3,25,5,25,25,3,25,5,25,3,25,25,5,25,3,25,5,25,3,1,1,2,1,1,1,1,1
1,1,1,1,2,2,1,3,0,14,14,0,3,25,25,25,25,3,25,25,25,3,25,25,25,25,3,25,25,3,3,1,1,2,1,2,1,1,1
1,1,1,2,1,2,1,3,3,11,22,3,3,3,3,3,3,3,3,3,3,3,3,3,3,3,3,3,3,3,1,1,1,2,2,2,1,1,1
1,1,1,2,2,2,1,3,3,3,3,3,3,1,1,1,1,1,1,1,1,1,1,1,1,1,1,1,1,1,1,1,1,1,1,1,1,1,1
1,1,1,1,1,1,1,1,1,1,1,1,1,1,1,1,1,1,1,1,1,1,1,1,1,1,1,1,1,1,1,1,1,1,1,1,1,1,1
1,1,3,3,3,3,3,1,1,1,1,1,1,1,1,1,1,1,1,1,1,1,1,1,1,1,1,1,1,1,1,1,1,1,1,1,1,1,1
1,1,3,14,14,14,3,1,1,1,1,1,1,2,1,1,1,2,1,2,2,2,1,1,1,1,1,2,1,1,1,1,1,1,1,1,1,1,1
1,1,3,14,0,14,3,1,1,1,1,1,2,2,2,1,1,2,1,2,1,1,1,2,1,1,1,2,1,1,1,1,1,1,1,1,1,1,1
1,1,3,14,14,14,3,1,1,1,1,1,1,2,1,2,1,2,1,2,2,1,2,2,1,2,1,2,1,1,1,1,1,1,1,1,1,1,1
1,1,3,3,3,3,3,3,1,1,1,1,1,1,1,1,1,1,1,1,1,1,1,1,1,1,1,1,1,1,1,1,1,1,1,1,1,1,1
1,1,1,1,1,1,1,1,1,1,1,1,1,1,1,1,1,1,1,1,1,1,1,1,1,1,1,1,1,1,1,1,1,1,1,1,1,1,1
endlayer

layer
1,1,1,1,1,1,1,1,1,1,1,1,1,1,1,1,1,1,1,1,1,1,1,1,1,1,1,1,1,1,1,1,1,1,1,1,1,1,1
1,1,1,1,1,1,1,1,1,1,1,1,1,1,1,1,1,1,1,1,1,1,1,1,1,1,1,1,1,1,1,1,1,1,1,1,1,1,1
1,1,1,1,1,1,1,1,1,1,1,1,1,1,1,1,1,1,1,1,1,1,1,1,1,1,1,1,1,1,1,1,1,1,1,1,1,1,1
1,1,1,1,1,1,1,1,1,1,1,1,1,1,1,1,1,1,1,1,1,1,1,1,1,1,1,1,1,1,1,1,1,1,1,1,1,1,1
1,1,1,1,1,1,1,1,1,1,1,1,1,1,1,1,1,1,1,1,1,1,1,1,1,1,1,1,1,1,1,1,1,1,1,1,1,1,1
1,1,1,1,1,1,1,1,1,1,1,1,1,1,1,1,1,1,1,1,1,1,1,1,1,1,1,1,1,1,1,1,1,1,1,1,1,1,1
1,1,1,1,1,1,1,1,1,1,1,1,1,1,1,1,1,1,1,1,1,1,1,1,1,1,1,1,1,1,1,1,1,1,1,1,1,1,1
1,1,1,1,1,1,1,1,1,1,1,1,1,1,1,1,1,1,1,1,1,1,1,1,1,1,1,1,1,1,1,1,1,1,1,1,1,1,1
1,1,1,1,1,1,1,1,1,1,1,1,1,1,1,1,1,1,1,1,1,1,1,1,1,1,1,1,1,1,1,1,1,1,1,1,1,1,1
1,1,1,1,1,1,1,1,1,3,3,3,1,3,3,3,3,1,3,3,3,1,3,3,3,3,1,3,3,3,1,1,1,1,1,1,1,1,1
1,1,1,1,1,1,1,1,1,3,3,3,1,3,3,3,3,1,3,3,3,1,3,3,3,3,1,3,3,3,1,1,1,1,1,1,1,1,1
1,1,1,1,1,1,1,1,1,1,3,1,1,1,3,1,1,1,1,3,1,1,1,1,3,1,1,1,3,1,1,1,1,1,1,1,1,1,1
1,1,1,1,1,1,1,1,1,3,3,3,1,3,3,3,3,1,3,3,3,1,3,3,3,3,1,3,3,3,1,1,1,1,1,1,1,1,1
1,1,1,1,1,1,1,1,1,3,3,3,1,3,3,3,3,1,3,3,3,1,3,3,3,3,1,3,3,3,1,1,1,1,1,1,1,1,1
1,1,1,1,1,1,1,1,1,1,3,1,1,1,1,1,1,1,1,1,1,1,1,1,1,1,1,1,1,1,1,1,1,1,1,1,1,1,1
1,1,1,1,1,1,1,1,1,3,3,3,1,3,3,3,3,1,3,3,3,1,3,3,3,3,1,3,3,3,1,1,1,1,1,1,1,1,1
1,1,1,1,1,1,1,1,1,3,3,3,1,3,3,3,3,1,3,3,3,1,3,3,3,3,1,3,3,3,1,1,1,1,1,1,1,1,1
1,1,1,1,1,1,1,3,3,3,3,3,3,1,3,1,1,1,1,3,1,1,1,1,3,1,1,1,3,1,1,1,1,1,1,1,1,1,1
1,1,1,1,1,1,1,3,0,0,0,0,3,3,3,3,3,1,3,3,3,1,3,3,3,3,1,3,3,3,1,1,1,1,1,1,1,1,1
1,1,1,1,1,1,1,3,0,14,14,0,3,3,3,3,3,1,3,3,3,1,3,3,3,3,1,3,3,3,1,1,1,1,1,1,1,1,1
1,1,1,1,1,1,1,3,3,11,22,3,3,1,1,1,1,1,1,1,1,1,1,1,1,1,1,1,1,1,1,1,1,1,1,1,1,1,1
1,1,1,1,1,1,1,3,3,3,3,3,3,1,1,1,1,1,1,1,1,1,1,1,1,1,1,1,1,1,1,1,1,1,1,1,1,1,1
1,1,1,1,1,1,1,1,1,1,1,1,1,1,1,1,1,1,1,1,1,1,1,1,1,1,1,1,1,1,1,1,1,1,1,1,1,1,1
1,1,3,3,3,3,3,1,1,1,1,1,1,1,1,1,1,1,1,1,1,1,1,1,1,1,1,1,1,1,1,1,1,1,1,1,1,1,1
1,1,3,14,14,14,3,1,1,1,1,1,1,1,1,1,1,1,1,1,1,1,1,1,1,1,1,1,1,1,1,1,1,1,1,1,1,1,1
1,1,3,14,0,14,3,1,1,1,1,1,1,1,1,1,1,1,1,1,1,1,1,1,1,1,1,1,1,1,1,1,1,1,1,1,1,1,1
1,1,3,14,14,14,3,1,1,1,1,1,1,1,1,1,1,1,1,1,1,1,1,1,1,1,1,1,1,1,1,1,1,1,1,1,1,1,1
1,1,3,3,3,3,3,3,1,1,1,1,1,1,1,1,1,1,1,1,1,1,1,1,1,1,1,1,1,1,1,1,1,1,1,1,1,1,1
1,1,1,1,1,1,1,1,1,1,1,1,1,1,1,1,1,1,1,1,1,1,1,1,1,1,1,1,1,1,1,1,1,1,1,1,1,1,1
endlayer

