# Gilly's Encrusted Portal Tower

# template generated with Ruins mod version 16.5 Ingame Parser
# Structure created and developed by Gilly

weight=1
embed_into_distance=4
uniqueMinDistance=700
acceptable_target_blocks=
unacceptable_target_blocks=flowing_water,water,flowing_lava,lava,ice,bedrock,netherrack,nether_brick,nether_brick_fence,soul_sand,quartz_ore,end_stone,obsidian,iron_bars,cloud,flesh,ash_block,slime_grass,slime_congealed,slime_dirt
biomesToSpawnIn=plains,mutated_plains,ice_flats,meadow,forest,taiga,woodland,woodlands,fen,brushland,shrubland,outback,chaparral,savanna,badlands,tundra,desert,jungle,mini jungle,birch forest,red desert,autumnal forest,rocky plateau,ice plains,cold taiga,mega taiga
dimensions=32,9,23
allowable_overhang=0
max_leveling=3
leveling_buffer=-1
preserve_water=0
preserve_lava=0

rule1=0,100,preserveBlock
rule2=0,100,minecraft:stone_brick_stairs-2
rule3=0,100,stonebrick,stonebrick,stonebrick,stonebrick,stonebrick,stonebrick-2,stonebrick-2
rule4=0,100,minecraft:stone_brick_stairs-3
rule5=0,100,minecraft:stone_brick_stairs-4
rule6=1,100,minecraft:torch-5
rule7=0,100,minecraft:stone_brick_stairs-5
rule8=0,100,minecraft:stone_brick_stairs-0
rule9=0,100,minecraft:stone_brick_stairs-1
rule10=0,100,minecraft:quartz_block-0
rule11=0,100,minecraft:stone_slab-8
rule12=0,100,minecraft:obsidian-0
rule13=0,100,minecraft:stone_slab-15
rule14=0,100,minecraft:double_stone_slab-7
rule15=0,100,minecraft:quartz_stairs-4
rule16=0,100,minecraft:quartz_stairs-5
rule17=0,100,minecraft:stained_glass_pane-3
rule18=0,100,minecraft:quartz_stairs-6
rule19=0,100,minecraft:quartz_stairs-7
rule20=0,100,minecraft:fence-0
rule21=0,100,minecraft:stone_slab-13
rule22=0,100,minecraft:stone_slab-7
rule23=0,100,minecraft:quartz_stairs-2
rule24=0,100,minecraft:quartz_stairs-3
rule25=0,100,minecraft:quartz_stairs-0
rule26=0,100,minecraft:quartz_stairs-1

layer
1,1,1,1,1,1,4,3,3,3,3,3,3,3,3,3,2,1,1,1,1,1,1
1,1,1,1,1,1,4,3,3,3,3,3,3,3,3,3,2,1,1,1,1,1,1
1,1,1,1,1,1,4,3,3,3,3,3,3,3,3,3,2,1,1,1,1,1,1
1,1,1,1,1,1,3,3,3,3,3,3,3,3,3,3,3,1,1,1,1,1,1
1,1,1,1,1,1,3,3,3,3,3,3,3,3,3,3,3,1,1,1,1,1,1
1,1,1,1,1,1,3,3,3,3,3,3,3,3,3,3,3,1,1,1,1,1,1
1,1,1,1,1,1,4,3,3,3,3,3,3,3,3,3,2,1,1,1,1,1,1
1,1,1,1,1,1,4,3,3,3,3,3,3,3,3,3,2,1,1,1,1,1,1
1,1,1,1,1,1,4,3,3,3,3,3,3,3,3,3,2,1,1,1,1,1,1
endlayer

layer
1,1,1,1,1,1,1,4,3,3,5,5,5,3,3,2,1,1,1,1,1,1,1
1,1,1,1,1,1,1,4,3,3,0,6,0,3,3,2,1,1,1,1,1,1,1
1,1,1,1,1,1,1,4,3,3,3,3,3,3,3,2,1,1,1,1,1,1,1
1,1,1,1,1,1,3,3,3,3,3,3,3,3,3,3,3,1,1,1,1,1,1
1,1,1,1,1,1,3,3,3,3,3,3,3,3,3,3,3,1,1,1,1,1,1
1,1,1,1,1,1,3,3,3,3,3,3,3,3,3,3,3,1,1,1,1,1,1
1,1,1,1,1,1,1,4,3,3,3,3,3,3,3,2,1,1,1,1,1,1,1
1,1,1,1,1,1,1,4,3,3,0,6,0,3,3,2,1,1,1,1,1,1,1
1,1,1,1,1,1,1,4,3,3,7,7,7,3,3,2,1,1,1,1,1,1,1
endlayer

layer
1,1,1,1,1,1,1,1,4,8,8,8,8,8,2,1,1,1,1,1,1,1,1
1,1,1,1,1,1,1,1,4,3,3,3,3,3,2,1,1,1,1,1,1,1,1
1,1,1,1,1,1,1,1,3,3,3,3,3,3,3,1,1,1,1,1,1,1,1
1,1,1,1,1,1,8,4,3,3,3,3,3,3,3,2,8,1,1,1,1,1,1
1,1,1,1,1,1,3,6,3,3,3,3,3,3,3,6,3,1,1,1,1,1,1
1,1,1,1,1,1,9,4,3,3,3,3,3,3,3,2,9,1,1,1,1,1,1
1,1,1,1,1,1,1,1,3,3,3,3,3,3,3,1,1,1,1,1,1,1,1
1,1,1,1,1,1,1,1,4,3,3,3,3,3,2,1,1,1,1,1,1,1,1
1,1,1,1,1,1,1,1,4,9,9,9,9,9,2,1,1,1,1,1,1,1,1
endlayer

layer
1,1,1,1,1,1,1,1,1,1,1,1,1,1,1,1,1,1,1,1,1,1,1
1,1,1,1,1,1,1,1,1,4,8,8,8,2,1,1,1,1,1,1,1,1,1
1,1,1,1,1,1,1,1,3,3,3,3,3,3,3,1,1,1,1,1,1,1,1
1,1,1,1,1,1,3,3,3,3,3,3,3,3,3,3,3,1,1,1,1,1,1
1,1,1,1,1,1,3,0,3,3,3,3,3,3,3,0,3,1,1,1,1,1,1
1,1,1,1,1,1,3,3,3,3,3,3,3,3,3,3,3,1,1,1,1,1,1
1,1,1,1,1,1,1,1,3,3,3,3,3,3,3,1,1,1,1,1,1,1,1
1,1,1,1,1,1,1,1,1,4,9,9,9,2,1,1,1,1,1,1,1,1,1
1,1,1,1,1,1,1,1,1,1,1,1,1,1,1,1,1,1,1,1,1,1,1
endlayer

layer
1,1,1,1,1,1,1,1,1,1,1,1,1,1,1,1,1,1,1,1,1,1,1
1,1,1,1,1,1,1,1,1,1,1,1,1,1,1,1,1,1,1,1,1,1,1
1,1,1,1,1,1,1,1,10,10,8,8,8,10,10,1,1,1,1,1,1,1,1
1,1,1,1,1,1,10,11,0,10,10,10,10,10,0,11,10,1,1,1,1,1,1
1,1,1,1,1,1,1,10,10,10,12,12,12,10,10,10,1,1,1,1,1,1,1
1,1,1,1,1,1,10,11,0,10,10,10,10,10,0,11,10,1,1,1,1,1,1
1,1,1,1,1,1,1,1,10,10,9,9,9,10,10,1,1,1,1,1,1,1,1
1,1,1,1,1,1,1,1,1,1,1,1,1,1,1,1,1,1,1,1,1,1,1
1,1,1,1,1,1,1,1,1,1,1,1,1,1,1,1,1,1,1,1,1,1,1
endlayer

layer
1,1,1,1,1,1,1,1,1,1,0,0,0,1,1,1,1,1,1,1,1,1,1
1,1,1,1,1,1,1,1,0,0,0,0,0,0,0,1,1,1,1,1,1,1,1
1,1,1,1,1,1,1,0,13,14,0,0,0,14,13,0,1,1,1,1,1,1,1
1,1,1,1,1,1,15,11,0,0,0,0,0,0,0,11,15,1,1,1,1,1,1
1,1,1,1,1,1,1,11,0,12,0,0,0,12,0,11,1,1,1,1,1,1,1
1,1,1,1,1,1,16,11,0,0,0,0,0,0,0,11,16,1,1,1,1,1,1
1,1,1,1,1,1,1,0,13,14,0,0,0,14,13,0,1,1,1,1,1,1,1
1,1,1,1,1,1,1,1,0,0,0,0,0,0,0,1,1,1,1,1,1,1,1
1,1,1,1,1,1,1,1,1,1,0,0,0,1,1,1,1,1,1,1,1,1,1
endlayer

layer
1,1,1,1,1,1,1,1,0,0,0,0,0,0,0,1,1,1,1,1,1,1,1
1,1,1,1,1,1,1,0,0,0,0,0,0,0,0,0,1,1,1,1,1,1,1
1,1,1,1,1,1,0,0,13,14,0,0,0,14,13,0,0,1,1,1,1,1,1
1,1,1,1,1,1,15,11,0,0,0,0,0,0,0,11,15,1,1,1,1,1,1
1,1,1,1,1,1,0,11,0,12,0,0,0,12,0,11,0,1,1,1,1,1,1
1,1,1,1,1,1,16,11,0,0,0,0,0,0,0,11,16,1,1,1,1,1,1
1,1,1,1,1,1,0,0,13,14,0,0,0,14,13,0,0,1,1,1,1,1,1
1,1,1,1,1,1,1,0,0,0,0,0,0,0,0,0,1,1,1,1,1,1,1
1,1,1,1,1,1,1,1,0,0,0,0,0,0,0,1,1,1,1,1,1,1,1
endlayer

layer
1,1,1,1,1,1,0,0,0,0,0,0,0,0,0,0,0,1,1,1,1,1,1
1,1,1,1,1,0,0,0,0,0,0,0,0,0,0,0,0,0,1,1,1,1,1
1,1,1,1,0,0,0,0,13,14,0,0,0,14,13,0,0,0,0,1,1,1,1
1,1,1,1,0,0,15,11,0,0,0,0,0,0,0,11,15,0,0,1,1,1,1
1,1,1,0,0,0,0,11,0,12,0,0,0,12,0,11,0,0,0,0,1,1,1
1,1,1,1,0,0,16,11,0,0,0,0,0,0,0,11,16,0,0,1,1,1,1
1,1,1,1,0,0,0,0,13,14,0,0,0,14,13,0,0,0,0,1,1,1,1
1,1,1,1,1,0,0,0,0,0,0,0,0,0,0,0,0,0,1,1,1,1,1
1,1,1,1,1,1,0,0,0,0,0,0,0,0,0,0,0,1,1,1,1,1,1
endlayer

layer
1,1,1,1,0,0,0,0,0,0,0,0,0,0,0,0,0,0,0,1,1,1,1
1,1,1,0,0,0,0,0,0,0,0,0,0,0,0,0,0,0,0,0,1,1,1
1,1,0,0,0,0,0,0,13,14,0,0,0,14,13,0,0,0,0,0,0,1,1
1,1,0,0,0,0,15,13,0,13,0,0,0,13,0,13,15,0,0,0,0,1,1
1,0,0,0,0,0,0,17,17,12,0,0,0,12,17,17,0,0,0,0,0,0,1
1,1,0,0,0,0,16,13,0,13,0,0,0,13,0,13,16,0,0,0,0,1,1
1,1,0,0,0,0,0,0,13,14,0,0,0,14,13,0,0,0,0,0,0,1,1
1,1,1,0,0,0,0,0,0,0,0,0,0,0,0,0,0,0,0,0,1,1,1
1,1,1,1,0,0,0,0,0,0,0,0,0,0,0,0,0,0,0,1,1,1,1
endlayer

layer
1,1,1,0,0,0,0,0,0,0,0,0,0,0,0,0,0,0,0,0,1,1,1
1,1,0,0,0,0,0,0,0,0,0,0,0,0,0,0,0,0,0,0,0,1,1
1,0,0,0,0,0,13,13,13,19,18,13,19,18,13,13,13,0,0,0,0,0,1
0,0,0,0,0,0,15,0,0,0,13,13,13,0,0,13,15,0,0,0,0,0,0
0,0,0,0,0,0,13,17,17,10,12,12,12,10,17,17,13,0,0,0,0,0,0
0,0,0,0,0,0,16,0,0,0,13,13,13,0,0,13,16,0,0,0,0,0,0
1,0,0,0,0,0,13,13,13,14,18,13,19,14,13,13,13,0,0,0,0,0,1
1,1,0,0,0,0,0,0,0,0,0,0,0,0,0,0,0,0,0,0,0,1,1
1,1,1,0,0,0,0,0,0,0,0,0,0,0,0,0,0,0,0,0,1,1,1
endlayer

layer
1,1,0,0,0,0,0,0,0,0,0,0,0,0,0,0,0,0,0,0,0,1,1
1,0,0,0,0,0,0,0,0,0,0,0,0,0,0,0,0,0,0,0,0,0,1
0,0,0,0,0,0,0,0,0,13,14,13,14,13,0,0,0,0,0,0,0,0,0
0,0,0,0,0,0,15,13,13,17,17,17,17,17,13,13,15,0,0,0,0,0,0
0,0,0,0,0,0,13,17,17,17,6,0,6,17,17,17,13,0,0,0,0,0,0
0,0,0,0,0,0,16,13,13,17,17,17,17,17,13,13,16,0,0,0,0,0,0
0,0,0,0,0,0,0,0,0,13,14,13,14,13,0,0,0,0,0,0,0,0,0
1,0,0,0,0,0,0,0,0,0,0,0,0,0,0,0,0,0,0,0,0,0,1
1,1,0,0,0,0,0,0,0,0,0,0,0,0,0,0,0,0,0,0,0,1,1
endlayer

layer
1,0,0,0,0,0,0,0,0,0,0,0,0,0,0,0,0,0,0,0,0,0,1
0,0,0,0,0,0,0,0,0,0,0,0,0,0,0,0,0,0,0,0,0,0,0
0,0,0,0,0,0,0,0,0,13,14,0,14,13,0,0,0,0,0,0,0,0,0
0,0,0,0,0,0,15,13,13,17,17,17,17,17,13,13,15,0,0,0,0,0,0
0,0,0,0,0,0,0,17,17,17,20,0,20,17,17,17,0,0,0,0,0,0,0
0,0,0,0,0,0,16,13,13,17,17,17,17,17,13,13,16,0,0,0,0,0,0
0,0,0,0,0,0,0,0,0,13,14,0,14,13,0,0,0,0,0,0,0,0,0
0,0,0,0,0,0,0,0,0,0,0,0,0,0,0,0,0,0,0,0,0,0,0
1,0,0,0,0,0,0,0,0,0,0,0,0,0,0,0,0,0,0,0,0,0,1
endlayer

layer
0,0,0,0,0,0,0,0,0,0,0,0,0,0,0,0,0,0,0,0,0,0,0
0,0,0,0,0,0,0,0,0,0,0,0,0,0,0,0,0,0,0,0,0,0,0
0,0,0,0,0,0,13,13,13,13,14,13,14,13,13,13,13,0,0,0,0,0,0
0,0,0,0,0,0,15,0,0,17,17,17,17,17,0,13,15,0,0,0,0,0,0
0,0,0,0,0,0,13,17,17,17,6,0,6,17,17,17,13,0,0,0,0,0,0
0,0,0,0,0,0,16,0,0,17,17,17,17,17,0,13,16,0,0,0,0,0,0
0,0,0,0,0,0,13,13,13,13,14,13,14,13,13,13,13,0,0,0,0,0,0
0,0,0,0,0,0,0,0,0,0,0,0,0,0,0,0,0,0,0,0,0,0,0
0,0,0,0,0,0,0,0,0,0,0,0,0,0,0,0,0,0,0,0,0,0,0
endlayer

layer
0,0,0,0,0,0,0,0,0,0,0,0,0,0,0,0,0,0,0,0,0,0,0
0,0,0,0,0,0,0,0,0,0,0,0,0,0,0,0,0,0,0,0,0,0,0
0,0,0,0,0,0,0,0,0,13,14,13,14,13,0,0,0,0,0,0,0,0,0
0,0,0,0,0,0,15,11,11,17,17,17,17,17,11,11,15,0,0,0,0,0,0
0,0,0,0,0,21,21,17,17,17,20,0,20,17,17,17,21,21,0,0,0,0,0
0,0,0,0,0,0,16,11,11,17,17,17,17,17,11,11,16,0,0,0,0,0,0
0,0,0,0,0,0,0,0,0,13,14,13,14,13,0,0,0,0,0,0,0,0,0
0,0,0,0,0,0,0,0,0,0,0,0,0,0,0,0,0,0,0,0,0,0,0
0,0,0,0,0,0,0,0,0,0,0,0,0,0,0,0,0,0,0,0,0,0,0
endlayer

layer
0,0,0,0,0,0,0,0,0,0,0,0,0,0,0,0,0,0,0,0,0,0,0
0,0,0,0,0,0,0,0,0,0,0,0,0,0,0,0,0,0,0,0,0,0,0
0,0,0,0,0,0,0,0,0,13,14,0,14,13,0,0,0,0,0,0,0,0,0
0,0,0,0,0,0,15,11,11,17,17,17,17,17,11,11,15,0,0,0,0,0,0
0,0,0,0,0,21,21,21,17,17,6,0,6,17,17,21,21,21,0,0,0,0,0
0,0,0,0,0,0,16,11,11,17,17,17,17,17,11,11,16,0,0,0,0,0,0
0,0,0,0,0,0,0,0,0,13,14,0,14,13,0,0,0,0,0,0,0,0,0
0,0,0,0,0,0,0,0,0,0,0,0,0,0,0,0,0,0,0,0,0,0,0
0,0,0,0,0,0,0,0,0,0,0,0,0,0,0,0,0,0,0,0,0,0,0
endlayer

layer
0,0,0,0,0,0,0,0,0,0,0,0,0,0,0,0,0,0,0,0,0,0,0
0,0,0,0,0,0,0,0,0,0,0,0,0,0,0,0,0,0,0,0,0,0,0
0,0,0,0,0,0,0,0,0,13,14,22,14,13,0,0,0,0,0,0,0,0,0
0,0,0,0,0,0,15,11,11,17,17,17,17,17,11,11,15,0,0,0,0,0,0
0,0,0,0,0,0,0,17,17,17,20,0,20,17,17,17,0,0,0,0,0,0,0
0,0,0,0,0,0,16,11,11,17,17,17,17,17,11,11,16,0,0,0,0,0,0
0,0,0,0,0,0,0,0,0,13,14,22,14,13,0,0,0,0,0,0,0,0,0
0,0,0,0,0,0,0,0,0,0,0,0,0,0,0,0,0,0,0,0,0,0,0
0,0,0,0,0,0,0,0,0,0,0,0,0,0,0,0,0,0,0,0,0,0,0
endlayer

layer
0,0,0,0,0,0,0,0,0,0,0,0,0,0,0,0,0,0,0,0,0,0,0
0,0,0,0,0,0,0,0,0,0,0,0,0,0,0,0,0,0,0,0,0,0,0
0,0,0,0,0,0,0,0,13,13,14,22,14,13,13,0,0,0,0,0,0,0,0
0,0,0,0,0,0,15,11,11,17,17,17,17,17,11,11,15,0,0,0,0,0,0
0,0,0,0,21,21,21,17,17,17,6,0,6,17,17,17,21,21,21,0,0,0,0
0,0,0,0,0,0,16,11,11,17,17,17,17,17,11,11,16,0,0,0,0,0,0
0,0,0,0,0,0,0,0,13,13,14,22,14,13,13,0,0,0,0,0,0,0,0
0,0,0,0,0,0,0,0,0,0,0,0,0,0,0,0,0,0,0,0,0,0,0
0,0,0,0,0,0,0,0,0,0,0,0,0,0,0,0,0,0,0,0,0,0,0
endlayer

layer
0,0,0,0,0,0,0,0,0,0,0,0,0,0,0,0,0,0,0,0,0,0,0
0,0,0,0,0,0,0,0,0,0,0,22,0,0,0,0,0,0,0,0,0,0,0
0,0,0,0,0,0,0,0,13,13,14,0,14,13,13,0,0,0,0,0,0,0,0
0,0,0,0,0,0,15,11,11,17,17,17,17,17,11,11,15,0,0,0,0,0,0
0,0,0,0,0,0,0,17,17,17,20,0,20,17,17,17,0,0,0,0,0,0,0
0,0,0,0,0,0,16,11,11,17,17,17,17,17,11,11,16,0,0,0,0,0,0
0,0,0,0,0,0,0,0,13,13,14,0,14,13,13,0,0,0,0,0,0,0,0
0,0,0,0,0,0,0,0,0,0,0,22,0,0,0,0,0,0,0,0,0,0,0
0,0,0,0,0,0,0,0,0,0,0,0,0,0,0,0,0,0,0,0,0,0,0
endlayer

layer
0,0,0,0,0,0,0,0,0,0,0,0,0,0,0,0,0,0,0,0,0,0,0
0,0,0,0,0,0,0,0,0,0,19,13,18,0,0,0,0,0,0,0,0,0,0
0,0,0,0,0,0,0,0,13,13,14,0,14,13,13,0,0,0,0,0,0,0,0
0,0,0,0,0,0,15,11,11,17,17,17,17,17,11,11,15,0,0,0,0,0,0
0,0,0,0,0,21,21,17,17,17,6,0,6,17,17,17,21,21,0,0,0,0,0
0,0,0,0,0,0,16,11,11,17,17,17,17,17,11,11,16,0,0,0,0,0,0
0,0,0,0,0,0,0,0,13,13,14,0,14,13,13,0,0,0,0,0,0,0,0
0,0,0,0,0,0,0,0,0,0,13,13,13,0,0,0,0,0,0,0,0,0,0
0,0,0,0,0,0,0,0,0,0,0,0,0,0,0,0,0,0,0,0,0,0,0
endlayer

layer
0,0,0,0,0,0,0,0,0,0,0,0,0,0,0,0,0,0,0,0,0,0,0
0,0,0,0,0,0,0,0,0,14,13,13,13,14,0,0,0,0,0,0,0,0,0
0,0,0,0,0,0,0,13,13,13,14,0,14,13,13,13,0,0,0,0,0,0,0
0,0,0,0,0,0,15,11,17,17,17,17,17,17,17,11,15,0,0,0,0,0,0
0,0,0,0,21,21,6,17,17,17,20,0,0,20,17,17,6,21,21,0,0,0,0
0,0,0,0,0,0,16,11,17,17,17,17,17,17,17,11,16,0,0,0,0,0,0
0,0,0,0,0,0,0,13,13,13,14,0,14,13,13,13,0,0,0,0,0,0,0
0,0,0,0,0,0,0,0,0,13,13,13,13,13,0,0,0,0,0,0,0,0,0
0,0,0,0,0,0,0,0,0,0,0,0,0,0,0,0,0,0,0,0,0,0,0
endlayer

layer
0,0,0,0,0,0,0,0,0,0,0,0,0,0,0,0,0,0,0,0,0,0,0
0,0,0,0,0,0,0,0,19,0,0,0,0,0,18,0,0,0,0,0,0,0,0
0,0,0,0,0,0,0,13,13,13,24,0,23,13,13,13,0,0,0,0,0,0,0
0,0,0,0,0,0,15,11,17,17,17,17,17,17,17,11,15,0,0,0,0,0,0
0,0,0,0,0,0,0,0,17,0,6,20,0,6,17,0,0,0,0,0,0,0,0
0,0,0,0,0,0,16,11,17,17,17,17,17,17,17,11,16,0,0,0,0,0,0
0,0,0,0,0,0,0,13,13,13,14,0,14,13,13,13,0,0,0,0,0,0,0
0,0,0,0,0,0,0,0,13,0,0,0,0,0,13,0,0,0,0,0,0,0,0
0,0,0,0,0,0,0,0,0,0,0,0,0,0,0,0,0,0,0,0,0,0,0
endlayer

layer
0,0,0,0,0,0,0,0,0,0,0,0,0,0,0,0,0,0,0,0,0,0,0
0,0,0,0,0,0,0,19,0,13,22,22,22,13,0,18,0,0,0,0,0,0,0
0,0,0,0,0,0,13,13,13,19,19,0,18,18,13,13,13,0,0,0,0,0,0
0,0,0,0,0,11,15,17,17,17,17,17,17,17,17,17,15,11,0,0,0,0,0
0,0,0,21,21,21,0,0,17,20,0,6,0,20,17,0,0,0,21,21,0,0,0
0,0,0,0,0,11,16,17,17,17,17,17,17,17,17,17,16,11,0,0,0,0,0
0,0,0,0,0,0,13,13,13,13,14,0,14,13,13,13,13,0,0,0,0,0,0
0,0,0,0,0,0,0,19,0,0,22,22,22,0,0,18,0,0,0,0,0,0,0
0,0,0,0,0,0,0,0,0,0,0,0,0,0,0,0,0,0,0,0,0,0,0
endlayer

layer
0,0,0,0,0,0,0,0,0,0,0,0,0,0,0,0,0,0,0,0,0,0,0
0,0,0,0,0,0,0,25,0,0,13,13,13,0,0,25,0,0,0,0,0,0,0
0,0,0,0,0,0,13,23,0,18,0,22,0,19,0,24,13,0,0,0,0,0,0
0,0,0,0,0,11,11,17,17,17,17,17,17,17,17,17,11,11,11,0,0,0,0
0,0,21,21,21,21,14,17,0,6,0,20,0,6,0,17,14,0,0,21,21,0,0
0,0,0,0,0,11,11,17,17,17,17,17,17,17,17,17,11,11,11,0,0,0,0
0,0,0,0,0,0,13,23,0,18,0,22,0,19,0,24,13,0,0,0,0,0,0
0,0,0,0,0,0,0,26,0,13,13,0,13,13,0,26,0,0,0,0,0,0,0
0,0,0,0,0,0,0,0,0,0,0,0,0,0,0,0,0,0,0,0,0,0,0
endlayer

layer
0,0,0,0,0,0,0,0,0,0,0,0,0,0,0,0,0,0,0,0,0,0,0
0,0,0,0,0,0,0,0,19,22,24,0,23,22,18,0,0,0,0,0,0,0,0
0,0,0,0,0,13,13,18,13,0,0,0,0,0,13,19,13,13,0,0,0,0,0
0,0,0,0,11,11,17,17,17,17,17,17,17,17,17,17,17,11,11,0,0,0,0
0,0,0,21,21,0,14,17,20,0,0,6,0,0,20,17,14,0,0,21,0,0,0
0,0,0,0,11,11,17,17,17,17,17,17,17,17,17,17,17,11,11,0,0,0,0
0,0,0,0,0,13,13,18,13,0,0,0,0,0,13,19,13,13,0,0,0,0,0
0,0,0,0,0,0,0,0,14,13,23,22,24,13,14,0,0,0,0,0,0,0,0
0,0,0,0,0,0,0,0,0,0,0,0,0,0,0,0,0,0,0,0,0,0,0
endlayer

layer
0,0,0,0,0,0,0,0,0,0,0,0,0,0,0,0,0,0,0,0,0,0,0
0,0,0,0,0,0,0,13,23,0,18,13,19,0,24,13,0,0,0,0,0,0,0
0,0,0,0,0,19,0,13,13,13,0,0,0,13,13,13,0,18,0,0,0,0,0
0,0,0,0,11,11,17,17,17,17,17,17,17,17,17,17,17,11,11,0,0,0,0
0,0,21,21,11,0,6,17,6,0,0,0,0,0,6,17,6,0,11,21,21,0,0
0,0,0,0,11,11,17,17,17,17,17,17,17,17,17,17,17,11,11,0,0,0,0
0,0,0,0,0,19,0,13,13,13,0,0,0,13,13,13,0,18,0,0,0,0,0
0,0,0,0,0,0,0,0,13,19,22,14,22,18,13,0,0,0,0,0,0,0,0
0,0,0,0,0,0,0,0,0,0,0,0,0,0,0,0,0,0,0,0,0,0,0
endlayer

layer
0,0,0,0,0,0,0,0,0,0,0,0,0,0,0,0,0,0,0,0,0,0,0
0,0,0,0,0,0,19,13,18,0,23,0,24,0,19,13,18,0,0,0,0,0,0
0,0,0,0,0,13,18,0,13,0,0,0,0,0,13,0,19,13,0,0,0,0,0
0,0,0,0,19,13,17,17,17,17,17,17,17,17,17,17,17,13,18,0,0,0,0
0,21,21,11,11,14,17,20,0,0,0,0,0,0,0,20,17,14,11,11,21,21,0
0,0,0,0,19,13,17,17,17,17,17,17,17,17,17,17,17,13,18,0,0,0,0
0,0,0,0,0,13,18,0,13,0,0,0,0,0,13,0,19,13,0,0,0,0,0
0,0,0,0,0,0,19,13,19,0,23,0,24,0,18,13,18,0,0,0,0,0,0
0,0,0,0,0,0,0,0,0,0,0,0,0,0,0,0,0,0,0,0,0,0,0
endlayer

layer
0,0,0,0,0,0,0,0,0,0,0,0,0,0,0,0,0,0,0,0,0,0,0
0,0,0,0,0,0,13,13,18,22,18,13,19,22,19,13,13,0,0,0,0,0,0
0,0,0,0,0,13,18,13,0,0,0,0,0,0,0,0,19,13,0,0,0,0,0
0,0,0,13,13,17,17,17,17,17,17,17,17,17,17,17,17,17,13,13,0,0,0
0,21,11,13,6,14,17,6,0,0,0,0,0,0,0,6,17,14,6,13,11,21,0
0,0,0,13,13,17,17,17,17,17,17,17,17,17,17,17,17,17,13,13,0,0,0
0,0,0,0,0,13,18,0,0,0,0,0,0,0,0,0,19,13,0,0,0,0,0
0,0,0,0,0,0,13,13,13,22,18,13,19,22,13,13,13,0,0,0,0,0,0
0,0,0,0,0,0,0,0,0,0,0,0,0,0,0,0,0,0,0,0,0,0,0
endlayer

layer
0,0,0,0,0,0,0,0,0,0,0,0,0,0,0,0,0,0,0,0,0,0,0
0,0,0,0,0,0,0,13,18,0,19,0,18,0,19,13,0,0,0,0,0,0,0
0,0,0,0,0,19,13,18,17,0,17,0,17,0,17,19,13,18,0,0,0,0,0
0,0,0,19,13,17,17,17,17,17,17,17,17,17,17,17,17,17,13,18,0,0,0
21,11,13,0,17,6,13,13,13,13,17,0,17,13,13,13,13,6,17,0,13,11,21
0,0,0,19,13,17,17,17,17,17,17,17,17,17,17,17,17,17,13,13,0,0,0
0,0,0,0,0,19,0,19,17,0,17,0,17,0,17,18,0,18,0,0,0,0,0
0,0,0,0,0,0,0,0,18,0,19,0,18,0,19,0,0,0,0,0,0,0,0
0,0,0,0,0,0,0,0,0,0,0,0,0,0,0,0,0,0,0,0,0,0,0
endlayer

layer
0,0,0,0,0,0,0,0,0,0,0,0,0,0,0,0,0,0,0,0,0,0,0
0,0,0,0,0,0,0,0,24,13,23,0,24,13,23,0,0,0,0,0,0,0,0
0,0,0,0,0,14,13,19,0,13,0,13,0,13,0,18,13,14,0,0,0,0,0
0,0,0,0,19,0,0,0,0,14,22,22,22,14,0,0,0,0,18,0,0,0,0
0,0,19,22,0,22,0,14,0,6,0,14,0,6,0,14,0,22,0,22,18,0,0
0,0,0,0,19,0,0,0,0,14,22,22,22,14,0,0,0,0,18,0,0,0,0
0,0,0,0,0,14,13,19,0,13,0,13,0,13,0,18,13,14,0,0,0,0,0
0,0,0,0,0,0,0,0,24,13,18,0,19,13,23,0,0,0,0,0,0,0,0
0,0,0,0,0,0,0,0,0,0,0,0,0,0,0,0,0,0,0,0,0,0,0
endlayer

layer
0,0,0,0,0,0,0,0,0,0,0,0,0,0,0,0,0,0,0,0,0,0,0
0,0,0,0,0,0,0,0,19,0,18,13,19,0,18,0,0,0,0,0,0,0,0
0,0,0,0,0,0,22,0,0,0,0,22,0,0,0,0,22,0,0,0,0,0,0
0,0,0,0,14,0,0,0,0,14,0,0,0,14,0,0,0,0,14,0,0,0,0
0,0,0,0,0,0,0,0,0,22,0,14,0,22,0,0,0,0,0,0,0,0,0
0,0,0,0,14,0,0,0,0,14,0,0,0,14,0,0,0,0,14,0,0,0,0
0,0,0,0,0,0,22,0,0,0,0,22,0,0,0,0,22,0,0,0,0,0,0
0,0,0,0,0,0,0,0,19,0,14,13,14,0,18,0,0,0,0,0,0,0,0
0,0,0,0,0,0,0,0,0,0,0,0,0,0,0,0,0,0,0,0,0,0,0
endlayer

layer
0,0,0,0,0,0,0,0,0,0,0,0,0,0,0,0,0,0,0,0,0,0,0
0,0,0,0,0,0,0,0,22,0,14,0,14,0,22,0,0,0,0,0,0,0,0
0,0,0,0,0,0,0,0,0,0,0,0,0,0,0,0,0,0,0,0,0,0,0
0,0,0,0,0,0,0,0,0,0,0,0,0,0,0,0,0,0,0,0,0,0,0
0,0,0,0,0,0,0,0,0,0,0,22,0,0,0,0,0,0,0,0,0,0,0
0,0,0,0,0,0,0,0,0,0,0,0,0,0,0,0,0,0,0,0,0,0,0
0,0,0,0,0,0,0,0,0,0,0,0,0,0,0,0,0,0,0,0,0,0,0
0,0,0,0,0,0,0,0,22,0,14,0,14,0,22,0,0,0,0,0,0,0,0
0,0,0,0,0,0,0,0,0,0,0,0,0,0,0,0,0,0,0,0,0,0,0
endlayer

layer
0,0,0,0,0,0,0,0,0,0,0,0,0,0,0,0,0,0,0,0,0,0,0
0,0,0,0,0,0,0,0,0,0,22,0,22,0,0,0,0,0,0,0,0,0,0
0,0,0,0,0,0,0,0,0,0,0,0,0,0,0,0,0,0,0,0,0,0,0
0,0,0,0,0,0,0,0,0,0,0,0,0,0,0,0,0,0,0,0,0,0,0
0,0,0,0,0,0,0,0,0,0,0,0,0,0,0,0,0,0,0,0,0,0,0
0,0,0,0,0,0,0,0,0,0,0,0,0,0,0,0,0,0,0,0,0,0,0
0,0,0,0,0,0,0,0,0,0,0,0,0,0,0,0,0,0,0,0,0,0,0
0,0,0,0,0,0,0,0,0,0,22,0,22,0,0,0,0,0,0,0,0,0,0
0,0,0,0,0,0,0,0,0,0,0,0,0,0,0,0,0,0,0,0,0,0,0
endlayer

