
# Created by Ruins mod version 16.7 Ingame Parser
# authoring Player: lafuller

weight=1
embed_into_distance=28
acceptable_target_blocks=
unacceptable_target_blocks=flowing_water,water,flowing_lava,lava,ice,bedrock,netherrack,nether_brick,nether_brick_fence,soul_sand,quartz_ore,gravel,end_stone,obsidian,iron_bars,cloud,flesh,ash_block,slime_grass,slime_congealed,slime_dirt
dimensions=34,9,9
allowable_overhang=0
max_leveling=6
leveling_buffer=-1
preserve_water=0
preserve_lava=0

rule1=0,100,stonebrick-0,stonebrick-0,stonebrick-1,stonebrick-1,stonebrick-2,stonebrick-2,stone-5,stone-6,cobblestone
rule2=0,100,minecraft:stone-0
rule3=0,100,minecraft:water-0
rule4=0,100,minecraft:stone_slab-5
rule5=0,100,minecraft:stone_slab-0
rule6=0,100,minecraft:iron_bars-0
rule7=0,100,minecraft:stone_brick_stairs-2
rule8=0,100,minecraft:stone_brick_stairs-1
rule9=2,100,minecraft:torch-1
rule10=0,100,minecraft:stone_brick_stairs-5
rule11=0,100,minecraft:stone_brick_stairs-7
rule12=0,100,minecraft:stone_brick_stairs-3
rule13=0,100,minecraft:stone_brick_stairs-4
rule14=0,100,minecraft:stone_brick_stairs-0
rule15=0,100,minecraft:stone_brick_stairs-6
rule16=0,100,preserveBlock
rule17=0,100,minecraft:wooden_slab-9
rule18=0,100,minecraft:log-1
rule19=0,100,minecraft:spruce_fence_gate-2
rule20=0,100,minecraft:spruce_fence_gate-1
rule21=0,100,minecraft:spruce_fence-0
rule22=0,100,minecraft:wooden_slab-1
rule23=0,100,minecraft:wooden_slab-5

layer
1,1,1,1,1,1,1,1,1
1,1,1,1,1,1,1,1,1
1,1,2,2,2,2,2,1,1
1,1,2,2,2,2,2,1,1
1,1,2,2,2,2,2,1,1
1,1,2,2,2,2,2,1,1
1,1,2,2,2,2,2,1,1
1,1,1,1,1,1,1,1,1
1,1,1,1,1,1,1,1,1
endlayer

layer
1,1,1,1,1,1,1,1,1
1,1,1,1,1,1,1,1,1
1,1,2,2,2,2,2,1,1
1,1,2,3,3,3,2,1,1
1,1,2,3,3,3,2,1,1
1,1,2,3,3,3,2,1,1
1,1,2,2,2,2,2,1,1
1,1,1,1,1,1,1,1,1
1,1,1,1,1,1,1,1,1
endlayer

layer
1,1,1,1,1,1,1,1,1
1,1,1,1,1,1,1,1,1
1,1,2,2,2,2,2,1,1
1,1,2,3,3,3,2,1,1
1,1,2,3,3,3,2,1,1
1,1,2,3,3,3,2,1,1
1,1,2,2,2,2,2,1,1
1,1,1,1,1,1,1,1,1
1,1,1,1,1,1,1,1,1
endlayer

layer
1,1,1,1,1,1,1,1,1
1,1,1,1,1,1,1,1,1
1,1,2,2,2,2,2,1,1
1,1,2,3,3,3,2,1,1
1,1,2,3,3,3,2,1,1
1,1,2,3,3,3,2,1,1
1,1,2,2,2,2,2,1,1
1,1,1,1,1,1,1,1,1
1,1,1,1,1,1,1,1,1
endlayer

layer
1,1,1,1,1,1,1,1,1
1,1,1,4,4,4,4,4,1
1,1,1,5,5,5,1,4,1
1,1,2,0,0,0,5,4,1
1,1,2,0,6,0,5,4,1
1,1,2,0,0,0,5,4,1
1,1,2,2,2,2,1,4,1
1,1,1,1,1,1,1,7,1
1,1,1,1,1,1,1,1,1
endlayer

layer
1,1,1,2,2,2,1,1,1
1,1,1,0,0,0,0,0,1
1,1,1,0,0,0,1,0,1
1,1,2,0,0,0,0,0,2
1,1,2,0,6,0,0,0,2
1,1,2,0,0,0,0,0,2
1,1,2,2,2,2,1,0,1
1,1,1,1,1,1,7,0,1
1,1,1,1,1,1,1,1,1
endlayer

layer
1,1,1,2,2,2,1,1,1
1,1,1,0,0,0,0,0,1
1,1,1,0,0,0,1,0,1
1,1,2,0,0,0,0,0,2
1,1,2,0,6,0,0,0,2
1,1,2,0,0,0,0,0,2
1,1,2,2,2,2,1,0,1
1,1,1,1,1,7,0,0,1
1,1,1,1,1,1,1,1,1
endlayer

layer
1,1,1,2,2,2,1,1,1
1,1,1,0,0,0,0,0,1
1,1,1,0,0,0,1,0,1
1,1,2,0,0,0,0,0,2
1,1,2,0,6,0,0,0,2
1,1,2,0,0,0,0,0,2
1,1,1,5,5,5,1,0,1
1,8,4,4,4,0,0,0,1
1,1,1,1,1,1,1,1,1
endlayer

layer
1,1,1,1,1,1,1,1,1
1,1,1,0,9,0,0,0,1
1,1,1,0,0,0,1,0,1
1,1,2,0,0,0,0,0,1
1,1,2,0,6,0,0,0,1
1,1,2,0,0,0,0,0,1
1,8,1,0,0,0,1,0,1
1,0,0,0,0,0,0,0,1
1,1,1,2,2,2,1,1,1
endlayer

layer
1,1,1,1,1,1,1,1,1
1,1,1,1,1,1,1,1,1
1,1,1,10,10,10,1,1,1
1,1,2,0,0,0,11,1,1
1,1,2,0,6,0,11,1,1
1,8,2,0,0,0,11,1,1
1,0,1,0,0,0,1,10,1
1,0,0,0,0,0,0,0,1
1,1,1,2,2,2,1,1,1
endlayer

layer
1,1,1,1,1,1,1,1,1
1,12,1,1,1,1,1,1,1
1,4,1,1,2,2,1,1,1
1,4,5,0,0,0,11,1,1
1,4,5,0,6,0,11,1,1
1,0,5,0,0,0,11,1,1
1,0,1,0,0,0,1,1,1
1,0,0,0,0,0,0,11,1
1,1,1,2,2,2,1,1,1
endlayer

layer
1,1,1,1,1,1,1,1,1
1,0,12,1,1,1,1,1,1
1,0,1,2,2,2,1,1,1
2,0,0,0,0,0,11,1,1
2,0,0,0,6,0,11,1,1
2,0,0,0,0,0,11,1,1
1,0,1,0,0,0,1,1,1
1,0,0,0,0,0,11,1,1
1,1,1,1,1,1,1,1,1
endlayer

layer
1,1,1,1,1,1,1,1,1
1,0,0,12,1,1,1,1,1
1,0,1,2,2,2,1,1,1
2,0,0,0,0,0,11,1,1
2,0,0,0,6,0,11,1,1
2,0,0,0,0,0,11,1,1
1,0,1,13,13,13,1,1,1
1,0,11,1,1,1,1,1,1
1,1,1,1,1,1,1,1,1
endlayer

layer
1,1,1,1,1,1,1,1,1
1,0,0,0,4,4,4,14,1
1,0,1,5,5,5,1,1,1
2,0,0,0,0,0,2,1,1
2,0,0,0,6,0,2,1,1
2,0,0,0,0,0,2,1,1
1,0,1,13,13,13,1,1,1
1,13,1,1,1,1,1,1,1
1,1,1,1,1,1,1,1,1
endlayer

layer
1,1,1,2,2,2,1,1,1
1,0,0,0,0,0,0,0,1
1,0,1,0,0,0,1,14,1
1,0,0,0,0,0,2,1,1
1,0,0,0,6,0,2,1,1
1,0,0,0,0,0,2,1,1
1,13,1,13,13,13,1,1,1
1,1,1,1,1,1,1,1,1
1,1,1,1,1,1,1,1,1
endlayer

layer
1,1,1,2,2,2,1,1,1
1,0,0,0,0,0,0,0,1
1,13,1,0,0,0,1,0,1
1,1,15,0,0,0,2,14,1
1,1,15,0,6,0,2,1,1
1,1,15,0,0,0,2,1,1
1,1,1,13,13,13,1,1,1
1,1,1,1,1,1,1,1,1
1,1,1,1,1,1,1,1,1
endlayer

layer
1,1,1,2,2,2,1,1,1
1,15,0,0,0,0,0,0,1
1,1,1,0,0,0,1,0,1
1,1,15,0,0,0,5,0,1
1,1,15,0,6,0,5,4,1
1,1,15,0,0,0,5,4,1
1,1,1,2,2,2,1,4,1
1,1,1,1,1,1,1,7,1
1,1,1,1,1,1,1,1,1
endlayer

layer
1,1,1,1,1,1,1,1,1
1,1,15,0,0,0,0,0,1
1,1,1,0,0,0,1,0,1
1,1,15,0,0,0,0,0,2
1,1,15,0,6,0,0,0,2
1,1,15,0,0,0,0,0,2
1,1,1,2,2,2,1,0,1
1,1,1,1,1,1,7,0,1
1,1,1,1,1,1,1,1,1
endlayer

layer
1,1,1,1,1,1,1,1,1
1,1,1,1,1,1,15,0,1
1,1,1,10,10,10,1,0,1
1,1,15,0,0,0,0,0,2
1,1,15,0,6,0,0,0,2
1,1,15,0,0,0,0,0,2
1,1,1,2,2,2,1,0,1
1,1,1,1,1,7,0,0,1
1,1,1,1,1,1,1,1,1
endlayer

layer
1,1,1,1,1,1,1,1,1
1,1,1,1,1,1,1,10,1
1,1,1,10,10,10,1,0,1
1,1,1,0,0,0,0,0,2
1,1,1,0,6,0,0,0,2
1,1,1,0,0,0,0,0,2
1,1,1,5,5,5,1,0,1
1,8,4,4,4,0,0,0,1
1,1,1,1,1,1,1,1,1
endlayer

layer
1,1,1,1,1,1,1,1,1
1,1,1,1,1,1,1,1,1
1,1,1,10,10,10,1,10,1
1,1,1,0,0,0,0,0,1
1,1,1,0,6,0,0,0,1
1,1,1,0,0,0,0,0,1
1,8,1,0,0,0,1,0,1
1,0,0,0,0,0,0,0,1
1,1,1,2,2,2,1,1,1
endlayer

layer
1,1,1,1,1,1,1,1,1
1,1,1,1,1,1,1,1,1
1,1,1,10,10,10,1,1,1
1,1,1,0,0,0,11,1,1
1,1,1,0,6,0,11,1,1
1,8,1,0,0,0,11,1,1
1,0,1,0,0,0,1,10,1
1,0,0,0,0,0,0,0,1
1,1,1,2,2,2,1,1,1
endlayer

layer
1,1,1,1,1,1,1,1,1
1,4,12,1,1,1,1,1,1
1,4,1,1,1,1,1,1,1
1,4,5,0,0,0,11,1,1
1,4,5,0,6,0,11,1,1
1,0,5,0,0,0,11,1,1
1,0,1,0,0,0,1,1,8
1,0,0,0,0,0,0,11,16
1,1,1,2,2,2,1,7,16
endlayer

layer
1,1,1,1,1,1,1,1,1
1,0,0,12,1,1,1,1,1
1,0,1,1,1,1,1,1,1
2,0,0,0,0,0,11,1,1
2,0,0,0,6,0,11,1,1
2,0,0,0,0,0,11,1,8
1,0,1,0,0,0,1,1,16
1,0,0,0,0,0,11,1,16
1,1,1,1,1,1,7,16,16
endlayer

layer
1,1,1,1,1,1,1,1,7
1,0,0,0,12,1,1,1,1
1,0,1,1,1,1,1,1,1
2,0,0,0,0,0,11,1,1
2,0,0,0,6,0,11,1,8
2,0,0,0,0,0,11,1,16
1,0,1,13,13,13,1,1,16
1,0,11,1,1,1,1,7,16
1,1,1,1,1,7,16,16,16
endlayer

layer
14,14,16,16,16,16,16,16,16
1,0,0,0,0,12,14,14,7
1,0,1,1,1,1,1,1,7
2,0,0,0,0,0,1,1,8
2,0,0,0,6,0,1,1,16
2,0,0,0,0,0,1,1,16
1,0,1,13,13,13,1,1,16
1,13,1,1,1,1,1,8,16
8,8,1,1,7,16,16,16,16
endlayer

layer
16,16,16,16,16,16,16,16,16
12,14,0,0,0,0,16,16,16
12,1,1,1,1,1,1,16,16
12,1,15,0,0,0,1,16,16
12,1,15,0,6,0,1,14,16
12,1,15,0,0,0,1,1,16
12,1,1,13,13,13,1,1,16
12,8,8,8,12,1,1,15,16
16,16,16,16,16,16,16,16,16
endlayer

layer
16,16,16,16,16,16,16,16,16
16,16,0,0,0,0,16,16,16
16,14,1,1,1,1,1,16,16
16,12,15,0,0,0,1,16,16
16,12,15,0,6,0,1,16,16
16,12,15,0,0,0,1,14,16
16,8,1,13,13,13,1,1,16
16,16,16,16,16,12,1,1,16
16,16,16,16,16,16,16,16,16
endlayer

layer
16,16,16,16,16,16,16,16,16
16,16,0,0,0,0,16,16,16
16,16,12,1,1,1,7,16,16
16,16,12,17,17,17,7,16,16
16,16,1,17,6,17,1,16,16
16,16,12,17,17,17,7,16,16
16,16,12,1,1,8,7,16,16
16,16,16,16,16,16,16,16,16
16,16,16,16,16,16,16,16,16
endlayer

layer
16,16,16,16,16,16,16,16,16
16,16,0,0,0,0,16,16,16
16,16,0,0,18,0,0,16,16
16,16,0,0,0,0,0,16,16
16,16,18,0,6,0,18,16,16
16,16,0,0,0,0,0,16,16
16,16,0,0,18,0,0,16,16
16,16,16,16,16,16,16,16,16
16,16,16,16,16,16,16,16,16
endlayer

layer
16,16,16,16,16,16,16,16,16
16,16,0,0,0,0,16,16,16
16,16,0,0,18,0,0,16,16
16,16,0,0,0,0,0,16,16
16,16,18,0,6,0,18,16,16
16,16,0,0,0,0,0,16,16
16,16,0,0,18,0,0,16,16
16,16,16,16,16,16,16,16,16
16,16,16,16,16,16,16,16,16
endlayer

layer
16,16,16,16,16,16,16,16,16
16,16,0,0,0,0,16,16,16
16,16,0,0,18,0,0,16,16
16,16,0,0,19,0,0,16,16
16,16,18,20,21,20,18,16,16
16,16,0,0,19,0,0,16,16
16,16,0,0,18,0,0,16,16
16,16,16,16,16,16,16,16,16
16,16,16,16,16,16,16,16,16
endlayer

layer
16,16,16,16,16,16,16,16,16
16,16,16,22,22,22,16,16,16
16,16,22,22,18,22,22,16,16
16,22,22,0,0,0,22,22,16
16,22,18,0,0,0,18,22,16
16,22,22,0,0,0,22,22,16
16,16,22,22,18,22,22,16,16
16,16,16,22,22,22,16,16,16
16,16,16,16,16,16,16,16,16
endlayer

layer
16,16,16,16,16,16,16,16,16
16,16,16,16,16,16,16,16,16
16,16,16,16,23,16,16,16,16
16,16,16,0,0,0,16,16,16
16,16,23,0,0,0,23,16,16
16,16,16,0,0,0,16,16,16
16,16,16,16,23,16,16,16,16
16,16,16,16,16,16,16,16,16
16,16,16,16,16,16,16,16,16
endlayer

