# Gilly's garden

weight=1
embed_into_distance=3
unacceptable_target_blocks=flowing_water,water,flowing_lava,lava,ice,bedrock,netherrack,nether_brick,nether_brick_fence,soul_sand,quartz_ore,end_stone,obsidian,iron_bars,cloud,flesh,ash_block,slime_grass,slime_congealed,slime_dirt,wooden_slab,fence,dark_oak_fence,cobblestone_wall
dimensions=7,7,9
max_leveling=3
leveling_buffer=-1
preserve_water=0
preserve_lava=0
preserve_plants=0

rule1=0,100,grass
rule2=0,100,stonebrick,stonebrick,stonebrick,stonebrick,stonebrick,stonebrick-2,stonebrick-2
rule3=0,100,farmland
rule4=0,100,flowing_water
rule5=0,85,potatoes-5
rule6=0,85,carrots-5
rule7=0,85,wheat-7
rule8=0,100,reeds
rule9=0,100,fence
rule10=0,100,torch

layer
2,2,2,2,2,2,2,2,2
2,1,1,1,1,1,1,1,2
2,1,1,1,1,1,1,1,2
2,1,1,1,2,1,1,1,2
2,1,1,1,1,1,1,1,2
2,1,1,1,1,1,1,1,2
2,2,2,2,2,2,2,2,2
endlayer

layer
2,2,2,2,2,2,2,2,2
2,1,1,1,1,1,1,1,2
2,1,1,1,1,1,1,1,2
2,1,1,1,2,1,1,1,2
2,1,1,1,1,1,1,1,2
2,1,1,1,1,1,1,1,2
2,2,2,2,2,2,2,2,2
endlayer

layer
2,2,2,2,2,2,2,2,2
2,1,1,1,1,1,1,1,2
2,1,1,1,1,1,1,1,2
2,1,1,1,2,1,1,1,2
2,1,1,1,1,1,1,1,2
2,1,1,1,1,1,1,1,2
2,2,2,2,2,2,2,2,2
endlayer

layer
2,2,2,2,2,2,2,2,2
2,3,3,3,3,3,3,3,2
2,3,3,3,1,3,3,3,2
2,3,3,1,4,1,3,3,2
2,3,3,3,1,3,3,3,2
2,3,3,3,3,3,3,3,2
2,2,2,2,2,2,2,2,2
endlayer

layer
0,0,0,0,0,0,0,0,0
0,6,6,7,7,7,5,5,0
0,6,6,7,8,7,5,5,0
0,6,6,8,9,8,5,5,0
0,6,6,7,8,7,5,5,0
0,6,6,7,7,7,5,5,0
0,0,0,0,0,0,0,0,0
endlayer

layer
0,0,0,0,0,0,0,0,0
0,0,0,0,0,0,0,0,0
0,0,0,0,8,0,0,0,0
0,0,0,8,9,8,0,0,0
0,0,0,0,8,0,0,0,0
0,0,0,0,0,0,0,0,0
0,0,0,0,0,0,0,0,0
endlayer

layer
0,0,0,0,0,0,0,0,0
0,0,0,0,0,0,0,0,0
0,0,0,0,8,0,0,0,0
0,0,0,8,10,8,0,0,0
0,0,0,0,8,0,0,0,0
0,0,0,0,0,0,0,0,0
0,0,0,0,0,0,0,0,0
endlayer
