
# Created by Ruins mod version 16.7 Ingame Parser
# authoring Player: lafuller

weight=1
embed_into_distance=13
acceptable_target_blocks=water,waterlily
unacceptable_target_blocks=
biomesToSpawnIn=swampland,jungle,marsh,bog,wetland,mini_jungle,lush_swamp,green_swamp,dead_swamp,tropical_island,land_of_lakes
dimensions=25,10,11
allowable_overhang=0
max_leveling=2
leveling_buffer=-1
preserve_water=0
preserve_lava=0

rule1=0,100,preserveBlock
rule2=0,100,minecraft:log2-1
rule3=0,100,minecraft:log2-9
rule4=0,100,minecraft:log2-5
rule5=0,100,minecraft:spruce_fence-0
rule6=0,100,minecraft:ladder-2
rule7=0,100,minecraft:spruce_stairs-4
rule8=0,100,minecraft:fence-0
rule9=0,100,minecraft:oak_stairs-6
rule10=0,100,minecraft:oak_stairs-4
rule11=0,100,minecraft:planks-0
rule12=0,100,minecraft:oak_stairs-7
rule13=0,100,minecraft:oak_stairs-5
rule14=0,100,minecraft:wooden_slab-9
rule15=0,100,minecraft:wooden_slab-8
rule16=0,100,minecraft:planks-1
rule17=0,100,minecraft:oak_stairs-2
rule18=0,100,minecraft:trapdoor-8
rule19=0,100,minecraft:wooden_slab-0
rule20=0,100,minecraft:trapdoor-4
rule21=0,100,minecraft:spruce_stairs-6
rule22=0,100,minecraft:spruce_stairs-0
rule23=0,100,minecraft:oak_stairs-1
rule24=0,100,minecraft:carpet-7
rule25=0,100,minecraft:spruce_stairs-3
rule26=0,100,minecraft:spruce_fence_gate-0
rule27=0,100,minecraft:spruce_stairs-7
rule28=0,100,minecraft:spruce_stairs-2
rule29=0,100,minecraft:ladder-3
rule30=0,100,minecraft:spruce_stairs-5
rule31=0,100,minecraft:bookshelf-0
rule32=0,100,minecraft:spruce_fence_gate-1
rule33=0,100,minecraft:spruce_fence_gate-2
rule34=0,100,minecraft:spruce_stairs-1
rule35=0,100,minecraft:wooden_slab-1
rule36=0,100,minecraft:dark_oak_stairs-4
rule37=0,100,minecraft:dark_oak_stairs-7
rule38=0,100,minecraft:dark_oak_stairs-6
rule39=0,100,minecraft:dark_oak_stairs-5
rule40=0,100,minecraft:planks-5
rule41=0,100,minecraft:wooden_slab-5
rule42=0,100,minecraft:double_wooden_slab-5
rule43=0,100,minecraft:dark_oak_stairs-0
rule44=0,100,minecraft:double_wooden_slab-1
rule45=0,100,minecraft:dark_oak_stairs-3
rule46=0,100,minecraft:dark_oak_stairs-1
rule47=0,100,minecraft:dark_oak_stairs-2
rule48=0,100,minecraft:trapdoor-0
rule49=0,100,minecraft:spruce_fence_gate-3
rule50=0,100,minecraft:wooden_slab-13
rule51=0,100,minecraft:trapdoor-1

layer
1,1,1,1,1,1,1,1,1,1,1
1,1,1,1,1,1,1,1,1,1,1
1,1,2,1,1,1,2,1,1,1,1
1,1,1,1,1,1,1,1,1,1,1
1,1,1,1,1,1,1,1,1,1,1
1,1,1,1,1,1,1,1,1,1,1
1,1,1,2,1,1,1,2,1,1,1
1,1,1,1,1,1,1,1,1,1,1
1,1,1,1,1,1,1,1,1,1,1
1,1,1,1,1,1,1,1,1,1,1
endlayer

layer
1,1,1,1,1,1,1,1,1,1,1
1,1,1,1,1,1,1,1,1,1,1
1,1,2,1,1,1,2,1,1,1,1
1,1,1,1,1,1,1,1,1,1,1
1,1,1,1,1,1,1,1,1,1,1
1,1,1,1,1,1,1,1,1,1,1
1,1,1,2,1,1,1,2,1,1,1
1,1,1,1,1,1,1,1,1,1,1
1,1,1,1,1,1,1,1,1,1,1
1,1,1,1,1,1,1,1,1,1,1
endlayer

layer
1,1,1,1,1,1,1,1,1,1,1
1,1,1,1,1,1,1,1,1,1,1
1,1,2,1,1,1,2,1,1,1,1
1,1,1,1,1,1,1,1,1,1,1
1,1,1,1,1,1,1,1,1,1,1
1,1,1,1,1,1,1,1,1,1,1
1,1,1,2,1,1,1,2,1,1,1
1,1,1,1,1,1,1,1,1,1,1
1,1,1,1,1,1,1,1,1,1,1
1,1,1,1,1,1,1,1,1,1,1
endlayer

layer
1,1,1,1,1,1,1,1,1,1,1
1,1,1,1,1,1,1,1,1,1,1
1,1,2,1,1,1,2,1,1,1,1
1,1,1,1,1,1,1,1,1,1,1
1,1,1,1,1,1,1,1,1,1,1
1,1,1,1,1,1,1,1,1,1,1
1,1,1,2,1,1,1,2,1,1,1
1,1,1,1,1,1,1,1,1,1,1
1,1,1,1,1,1,1,1,1,1,1
1,1,1,1,1,1,1,1,1,1,1
endlayer

layer
1,1,1,1,1,1,1,1,1,1,1
1,1,1,1,1,1,1,1,1,1,1
1,1,2,1,1,1,2,1,1,1,1
1,1,1,1,1,1,1,1,1,1,1
1,1,1,1,1,1,1,1,1,1,1
1,1,1,1,1,1,1,1,1,1,1
1,1,1,2,1,1,1,2,1,1,1
1,1,1,1,1,1,1,1,1,1,1
1,1,1,1,1,1,1,1,1,1,1
1,1,1,1,1,1,1,1,1,1,1
endlayer

layer
1,1,1,1,1,1,1,1,1,1,1
1,1,1,1,1,1,1,1,1,1,1
1,1,2,1,1,1,2,1,1,1,1
1,1,1,1,1,1,1,1,1,1,1
1,1,1,1,1,1,1,1,1,1,1
1,1,1,1,1,1,1,1,1,1,1
1,1,1,2,1,1,1,2,1,1,1
1,1,1,1,1,1,1,1,1,1,1
1,1,1,1,1,1,1,1,1,1,1
1,1,1,1,1,1,1,1,1,1,1
endlayer

layer
1,1,1,1,1,1,1,1,1,1,1
1,1,1,1,1,1,1,1,1,1,1
1,1,2,1,1,1,2,1,1,1,1
1,1,1,1,1,1,1,1,1,1,1
1,1,1,1,1,1,1,1,1,1,1
1,1,1,1,1,1,1,1,1,1,1
1,1,1,2,1,1,1,2,1,1,1
1,1,1,1,1,1,1,1,1,1,1
1,1,1,1,1,1,1,1,1,1,1
1,1,1,1,1,1,1,1,1,1,1
endlayer

layer
1,1,1,1,1,1,1,1,1,1,1
1,1,1,1,1,1,1,1,1,1,1
1,1,2,1,1,1,2,1,1,1,1
1,1,1,1,1,1,1,1,1,1,1
1,1,1,1,1,1,1,1,1,1,1
1,1,1,1,1,1,1,1,1,1,1
1,1,1,2,1,1,1,2,1,1,1
1,1,1,1,1,1,1,1,1,1,1
1,1,1,1,1,1,1,1,1,1,1
1,1,1,1,1,1,1,1,1,1,1
endlayer

layer
1,1,1,1,1,1,1,1,1,1,1
1,1,1,1,1,1,1,1,1,1,1
1,1,2,1,1,1,2,1,1,1,1
1,1,1,1,1,1,1,1,1,1,1
1,1,1,1,1,1,1,1,1,1,1
1,1,1,1,1,1,1,1,1,1,1
1,1,1,2,1,1,1,2,1,1,1
1,1,1,1,1,1,1,1,1,1,1
1,1,1,1,1,1,1,1,1,1,1
1,1,1,1,1,1,1,1,1,1,1
endlayer

layer
1,1,1,1,1,1,1,1,1,1,1
1,1,1,1,1,1,1,1,1,1,1
1,1,2,1,1,1,2,1,1,1,1
1,1,1,1,1,1,1,1,1,1,1
1,1,1,1,1,1,1,1,1,1,1
1,1,1,1,1,1,1,1,1,1,1
1,1,1,2,1,1,1,2,1,1,1
1,1,1,1,1,1,1,1,1,1,1
1,1,1,1,1,1,1,1,1,1,1
1,1,1,1,1,1,1,1,1,1,1
endlayer

layer
1,1,1,1,1,1,1,1,1,1,1
1,1,1,1,1,1,1,1,1,1,1
1,1,2,1,1,1,2,1,1,1,1
1,1,1,1,1,1,1,1,1,1,1
1,1,1,1,1,1,1,1,1,1,1
1,1,1,1,1,1,1,1,1,1,1
1,1,1,2,1,1,1,2,1,1,1
1,1,1,1,1,1,1,1,1,1,1
1,1,1,1,1,1,1,1,1,1,1
1,1,1,1,1,1,1,1,1,1,1
endlayer

layer
1,1,1,1,1,1,1,1,1,1,1
1,1,1,1,1,1,1,1,1,1,1
1,1,2,1,1,1,2,1,1,1,1
1,1,1,1,1,1,1,1,1,1,1
1,1,1,1,1,1,1,1,1,1,1
1,1,1,1,1,1,1,1,1,1,1
1,3,3,3,3,3,3,3,3,1,1
1,1,1,1,1,1,1,1,1,1,1
1,1,1,1,1,1,1,1,1,1,1
1,1,1,1,1,1,1,1,1,1,1
endlayer

layer
1,1,1,1,1,1,1,1,1,1,1
1,1,1,1,1,1,1,1,1,1,1
1,1,2,1,1,1,2,1,1,1,1
1,1,1,1,1,1,4,1,1,1,1
1,1,1,1,1,1,4,1,1,1,1
1,1,1,1,1,1,4,1,1,1,1
1,1,2,2,1,1,4,2,1,1,1
1,1,1,1,1,1,4,1,1,1,1
1,1,1,1,1,1,4,1,1,1,1
1,1,1,1,1,1,1,1,1,1,1
endlayer

layer
1,1,1,1,1,1,1,1,1,1,1
1,1,1,1,1,1,1,1,1,1,1
1,1,2,1,1,1,2,1,1,1,1
5,3,3,3,3,3,3,3,3,3,5
1,1,1,1,1,1,1,1,1,1,1
1,1,1,1,1,1,1,1,1,1,1
1,1,2,2,6,1,1,2,1,1,1
1,5,3,3,3,3,3,3,3,5,1
1,1,1,1,1,1,1,1,1,1,1
1,1,1,1,1,1,1,1,1,1,1
endlayer

layer
1,1,1,5,1,1,1,5,1,1,1
1,1,7,4,5,5,1,4,1,1,1
1,1,2,4,5,5,2,4,5,1,1
1,1,8,4,5,5,5,4,5,1,1
1,1,5,4,1,1,1,4,5,1,1
1,1,5,4,1,1,1,4,5,1,1
1,1,2,4,6,1,1,4,1,1,1
1,1,1,4,1,1,1,4,1,1,1
1,1,1,4,1,1,1,4,1,1,1
1,1,1,5,1,1,1,5,1,1,1
endlayer

layer
1,1,5,5,1,1,1,1,1,1,1
1,1,5,5,10,9,1,1,1,1,1
5,3,3,3,3,3,3,3,3,3,5
1,1,14,13,13,13,13,12,11,1,1
1,1,14,9,14,14,15,12,11,1,1
5,3,3,3,3,3,3,3,3,3,5
1,5,2,16,6,15,12,2,5,1,1
1,5,5,2,9,15,15,5,1,1,1
1,1,1,5,1,1,1,1,1,1,1
1,1,1,1,1,1,1,1,1,1,1
endlayer

layer
1,1,1,1,7,5,1,1,1,1,1
1,1,1,16,16,16,16,10,1,1,1
1,8,2,0,0,0,0,2,10,1,1
1,12,18,0,0,0,0,0,17,1,1
1,12,18,0,0,0,0,0,19,1,1
1,12,18,0,0,0,0,0,17,1,1
1,8,2,16,20,0,0,2,9,1,1
1,1,8,2,0,0,16,21,1,1,1
1,1,1,12,13,13,13,1,1,1,1
1,1,1,1,1,1,1,1,1,1,1
endlayer

layer
1,1,1,1,22,7,5,1,1,1,1
1,1,8,16,23,23,10,22,1,1,1
1,10,2,0,0,0,0,2,21,1,1
1,25,24,0,0,0,0,0,5,1,1
1,27,24,0,0,0,0,0,26,1,1
1,25,24,0,0,0,0,0,5,1,1
1,30,2,0,0,0,29,2,28,1,1
1,1,30,2,0,0,31,21,1,1,1
1,1,1,5,32,32,30,5,1,1,1
1,1,1,1,1,1,1,1,1,1,1
endlayer

layer
1,1,1,1,1,1,28,1,1,1,1
1,1,8,5,32,32,5,5,1,1,1
1,25,2,0,0,0,0,2,28,1,1
1,5,0,0,0,0,0,0,9,1,1
1,33,0,0,0,0,0,0,9,1,1
1,5,0,0,0,0,0,0,9,1,1
1,16,2,0,0,0,29,2,21,1,1
1,5,34,2,0,0,16,30,1,1,1
1,1,1,27,30,30,30,21,1,1,1
1,1,1,1,1,1,1,1,1,1,1
endlayer

layer
1,1,1,14,1,1,7,1,1,1,1
1,1,36,36,30,30,7,35,1,1,1
1,37,2,0,0,0,30,2,22,1,1
1,36,0,0,0,0,0,0,16,1,1
1,16,0,0,0,0,0,0,26,1,1
1,37,0,0,0,0,0,27,16,1,1
1,25,2,0,0,0,29,2,38,1,1
1,1,30,2,0,0,16,40,39,1,1
1,1,1,30,32,32,34,21,1,1,1
1,1,1,1,1,1,1,1,1,1,1
endlayer

layer
1,1,41,25,22,35,1,1,1,1,1
1,1,42,16,40,40,40,1,1,1,1
1,45,40,44,35,35,40,43,1,1,1
41,40,39,35,35,35,35,36,42,41,1
41,40,40,35,19,19,35,40,42,41,1
41,34,36,35,19,19,35,40,42,41,1
1,41,16,25,35,35,29,40,46,1,1
1,1,45,16,35,35,44,40,47,1,1
1,1,1,45,30,34,39,47,1,1,1
1,1,1,1,1,1,1,1,1,1,1
endlayer

layer
1,1,1,1,1,1,1,1,1,1,1
1,1,43,40,5,5,47,1,1,1,1
1,1,37,34,0,0,40,1,1,1,1
1,1,40,48,0,0,0,47,43,1,1
1,43,40,48,0,0,0,40,47,1,1
1,1,37,48,0,0,0,40,46,1,1
1,1,39,22,0,0,29,40,1,1,1
1,1,45,40,36,36,36,47,1,1,1
1,1,1,46,39,39,46,1,1,1,1
1,1,1,1,1,1,1,1,1,1,1
endlayer

layer
1,1,1,1,1,1,1,1,1,1,1
1,1,1,1,36,43,1,1,1,1,1
1,1,41,39,39,39,47,1,1,1,1
1,1,45,0,0,0,37,43,1,1,1
1,1,37,0,0,0,0,26,1,1,1
1,1,45,0,0,0,0,45,1,1,1
1,1,1,38,0,0,0,47,1,1,1
1,1,1,45,49,39,46,47,1,1,1
1,1,1,1,1,1,1,1,1,1,1
1,1,1,1,1,1,1,1,1,1,1
endlayer

layer
1,1,1,1,1,1,1,1,1,1,1
1,1,1,1,1,1,1,1,1,1,1
1,1,1,45,36,47,1,1,1,1,1
1,1,1,40,0,50,47,1,1,1,1
1,1,1,50,0,0,50,43,1,1,1
1,1,1,46,0,0,50,47,1,1,1
1,1,1,45,50,39,47,1,1,1,1
1,1,1,1,41,46,47,1,1,1,1
1,1,1,1,1,1,1,1,1,1,1
1,1,1,1,1,1,1,1,1,1,1
endlayer

layer
1,1,1,1,1,1,1,1,1,1,1
1,1,1,1,1,1,1,1,1,1,1
1,1,1,1,41,1,1,1,1,1,1
1,1,1,1,41,41,1,1,1,1,1
1,1,1,41,51,41,41,1,1,1,1
1,1,1,1,41,41,41,1,1,1,1
1,1,1,1,41,41,1,1,1,1,1
1,1,1,1,1,1,1,1,1,1,1
1,1,1,1,1,1,1,1,1,1,1
1,1,1,1,1,1,1,1,1,1,1
endlayer

