
# Created by Ruins mod version 16.7 Ingame Parser
# authoring Player: lafuller

weight=1
embed_into_distance=5
acceptable_target_blocks=
unacceptable_target_blocks=flowing_water,water,flowing_lava,lava,ice,bedrock,netherrack,nether_brick,nether_brick_fence,soul_sand,quartz_ore,end_stone,obsidian,iron_bars,cloud,flesh,ash_block,slime_grass,slime_congealed,slime_dirt
dimensions=12,20,20
allowable_overhang=0
max_leveling=7
leveling_buffer=-1
preserve_water=0
preserve_lava=0

rule1=0,100,preserveBlock
rule2=0,100,minecraft:double_stone_slab-9
rule3=0,100,minecraft:sandstone_stairs-0
rule4=0,100,minecraft:sandstone-0
rule5=0,100,minecraft:sandstone_stairs-2
rule6=0,100,minecraft:sandstone_stairs-3
rule7=0,100,minecraft:sandstone_stairs-1
rule8=0,100,minecraft:sandstone-2
rule9=0,100,minecraft:trapdoor-11
rule10=0,100,bookshelf,pumpkin,melon_block,hay_block,ChestGenHook:chests/spawn_bonus_chest:5-5,ChestGenHook:chests/village_blacksmith:5-5,ChestGenHook:chests/stronghold_library:5-5,ChestGenHook:chests/simple_dungeon:5-5
rule11=0,100,minecraft:stone-4
rule12=0,100,minecraft:stone_slab-1
rule13=0,100,minecraft:trapdoor-8
rule14=0,100,minecraft:wooden_slab-9
rule15=0,100,minecraft:trapdoor-10
rule16=0,100,minecraft:dirt-0
rule17=0,100,minecraft:ladder-4
rule18=0,100,minecraft:ladder-3
rule19=0,100,bookshelf,pumpkin,melon_block,hay_block,ChestGenHook:chests/spawn_bonus_chest:5-3,ChestGenHook:chests/village_blacksmith:5-3,ChestGenHook:chests/stronghold_library:5-3,ChestGenHook:chests/simple_dungeon:5-3
rule20=0,100,minecraft:spruce_stairs-6
rule21=0,100,bookshelf,pumpkin,melon_block,hay_block,ChestGenHook:chests/spawn_bonus_chest:5-4,ChestGenHook:chests/village_blacksmith:5-4,ChestGenHook:chests/stronghold_library:5-4,ChestGenHook:chests/simple_dungeon:5-4
rule22=0,100,minecraft:crafting_table-0
rule23=0,100,minecraft:carpet-7
rule24=0,100,minecraft:sandstone_stairs-5
rule25=0,100,minecraft:trapdoor-1
rule26=0,100,minecraft:sandstone_stairs-4
rule27=0,100,minecraft:spruce_stairs-7
rule28=0,100,minecraft:spruce_fence-0
rule29=0,100,minecraft:jungle_door-5
rule30=0,100,minecraft:jungle_door-7
rule31=0,100,minecraft:spruce_stairs-3
rule32=0,100,minecraft:spruce_stairs-2
rule33=0,100,minecraft:jungle_door-9
rule34=0,100,minecraft:jungle_door-8
rule35=0,100,minecraft:trapdoor-3
rule36=0,100,minecraft:wooden_slab-1
rule37=0,100,minecraft:double_stone_slab-1
rule38=0,100,minecraft:stone_slab-9
rule39=0,100,minecraft:sandstone_stairs-6
rule40=0,100,minecraft:trapdoor-0
rule41=0,100,minecraft:trapdoor-2
rule42=0,100,minecraft:sandstone_stairs-7
rule43=0,100,minecraft:hay_block-0
rule44=0,100,minecraft:trapdoor-9

layer
1,1,2,2,2,2,1,1,1,1,1,1,1,1,1,1,1,1,1,1
1,1,2,2,2,2,2,2,2,1,1,1,1,1,1,1,1,1,1,1
3,2,2,2,2,2,2,2,2,2,2,2,1,1,1,1,1,1,1,1
4,2,2,2,2,2,2,2,2,2,2,2,4,1,1,1,1,1,1,1
4,2,2,2,2,2,2,2,2,2,2,2,4,3,3,3,3,5,1,1
4,2,2,2,2,2,2,2,2,2,2,2,4,4,4,4,4,5,1,1
4,4,2,2,2,2,2,2,2,2,2,4,4,4,4,4,4,5,1,1
4,4,2,2,2,2,2,2,2,2,4,4,4,4,4,4,4,5,1,1
2,2,2,2,2,2,2,2,2,2,4,4,4,4,4,2,2,2,2,1
2,2,2,2,2,2,2,4,4,4,4,4,4,4,2,2,2,2,2,1
2,2,2,2,2,2,2,4,4,4,4,4,4,4,2,2,2,2,2,2
2,2,2,2,2,4,4,4,4,4,4,4,4,4,2,2,2,2,2,2
2,2,2,2,2,4,4,4,4,4,4,4,4,2,2,2,2,2,2,2
1,2,2,2,2,4,4,4,4,4,4,4,4,2,2,2,2,2,2,2
1,2,2,2,2,4,4,4,4,4,2,2,2,2,2,2,2,2,2,2
1,1,1,1,6,7,7,6,4,4,2,2,2,2,2,2,2,2,2,1
1,1,1,1,1,1,1,6,4,4,2,2,2,2,2,2,2,2,2,1
1,1,1,1,1,1,1,7,4,4,2,2,2,2,2,2,2,2,2,1
1,1,1,1,1,1,1,1,4,4,2,2,2,2,2,2,2,1,1,1
1,1,1,1,1,1,1,1,4,4,4,4,2,2,2,2,2,1,1,1
endlayer

layer
1,1,8,8,8,2,1,1,1,1,1,1,1,1,1,1,1,1,1,1
1,1,2,2,2,2,2,2,2,1,1,1,1,1,1,1,1,1,1,1
1,2,2,2,2,2,2,2,2,2,2,2,1,1,1,1,1,1,1,1
3,2,2,2,2,2,2,2,2,2,2,2,4,1,1,1,1,1,1,1
4,2,2,2,2,2,2,2,2,2,2,2,4,1,1,1,1,1,1,1
4,2,2,2,2,2,2,2,2,2,2,2,4,3,3,3,5,1,1,1
4,4,2,2,2,2,2,2,2,2,2,4,4,4,4,4,5,1,1,1
4,4,2,2,2,2,2,2,2,2,4,4,4,4,4,4,5,1,1,1
2,2,2,2,2,2,2,2,2,2,4,4,4,4,4,2,2,2,2,1
2,2,2,2,2,2,2,4,4,4,4,4,4,4,2,2,2,2,2,1
2,2,2,2,2,2,2,4,4,4,4,4,4,4,2,2,2,2,2,2
2,2,2,2,2,4,4,4,4,4,4,4,4,4,2,2,2,2,2,2
2,2,2,2,2,4,4,4,4,4,4,4,4,2,2,2,2,2,2,2
1,2,2,2,2,4,4,4,4,4,4,4,4,2,2,2,2,2,2,2
1,2,2,2,2,7,7,7,7,4,2,2,2,2,2,2,2,2,2,2
1,1,1,1,1,1,1,1,6,4,2,2,2,2,2,2,2,2,2,1
1,1,1,1,1,1,1,1,6,4,2,2,2,2,2,2,2,2,2,1
1,1,1,1,1,1,1,1,3,4,2,2,2,2,2,2,2,2,8,1
1,1,1,1,1,1,1,1,4,4,2,2,2,2,2,2,2,1,1,1
1,1,1,1,1,1,1,1,4,4,4,4,2,2,2,2,2,1,1,1
endlayer

layer
1,1,2,2,2,2,1,1,1,1,1,1,1,1,1,1,1,1,1,1
1,1,2,10,9,2,4,4,4,1,1,1,1,1,1,1,1,1,1,1
1,2,13,0,0,12,4,11,10,2,2,2,1,1,1,1,1,1,1,1
1,2,13,0,0,6,4,0,0,0,14,2,4,1,1,1,1,1,1,1
3,2,13,0,0,4,4,0,0,0,14,2,4,1,1,1,1,1,1,1
4,2,2,0,0,4,0,0,0,0,14,2,4,1,1,1,1,1,1,1
4,4,2,15,15,4,0,0,0,0,2,4,4,3,3,5,1,1,1,1
4,4,2,4,4,4,0,17,0,2,4,4,16,4,4,5,1,1,1,1
2,2,2,4,4,4,2,2,2,2,4,4,4,4,16,2,2,2,2,1
2,14,0,0,6,4,2,16,16,16,4,4,4,4,2,14,0,18,2,1
2,14,0,0,7,2,2,16,16,4,4,16,16,4,2,14,0,0,11,2
2,14,0,0,0,4,4,16,4,4,4,4,4,4,2,14,0,0,19,2
2,2,0,0,0,4,4,8,4,4,4,4,4,2,2,4,4,4,4,2
1,2,22,21,2,4,7,7,7,4,4,4,4,2,10,0,20,14,14,2
1,2,2,2,2,1,1,1,1,4,2,2,2,2,0,0,0,0,0,2
1,1,1,1,1,1,1,1,1,4,2,14,0,10,4,17,0,0,2,1
1,1,1,1,1,1,1,1,1,4,2,14,0,0,12,4,0,0,2,1
1,1,1,1,1,1,1,1,1,4,2,14,0,0,12,8,2,2,8,1
1,1,1,1,1,1,1,1,3,4,2,2,2,4,4,8,2,1,1,1
1,1,1,1,1,1,1,1,4,4,4,4,8,2,2,2,2,1,1,1
endlayer

layer
1,1,8,8,2,2,1,1,1,1,1,1,1,1,1,1,1,1,1,1
1,1,2,0,0,2,4,4,4,1,1,1,1,1,1,1,1,1,1,1
1,2,23,0,0,0,4,0,0,2,2,2,1,1,1,1,1,1,1,1
1,2,23,0,0,0,8,0,0,0,23,2,4,1,1,1,1,1,1,1
1,2,23,0,0,3,8,0,0,0,23,2,4,1,1,1,1,1,1,1
3,2,2,0,0,4,0,0,0,0,23,2,4,1,1,1,1,1,1,1
4,4,2,15,15,4,0,0,0,0,2,4,4,1,1,1,1,1,1,1
4,4,2,4,4,4,0,17,0,2,4,4,1,1,1,1,1,1,1,1
2,2,2,4,5,12,2,2,2,2,7,7,1,1,1,2,2,2,2,1
2,23,0,0,0,12,2,1,1,1,1,1,1,4,2,23,0,18,2,1
2,23,0,0,0,2,2,1,1,1,1,1,1,4,2,23,0,0,0,8
2,23,0,0,0,4,4,1,1,1,1,6,4,4,2,23,0,0,0,2
2,2,0,0,0,4,7,1,1,12,12,6,4,2,2,4,4,4,4,2
1,2,0,0,2,4,1,1,1,4,4,4,4,2,0,0,0,0,0,2
1,2,2,2,2,1,1,1,1,4,2,2,2,2,0,0,0,0,0,8
1,1,1,1,1,1,1,1,1,4,2,23,0,0,4,17,0,0,2,1
1,1,1,1,1,1,1,1,1,4,2,23,0,0,0,4,0,0,2,1
1,1,1,1,1,1,1,1,1,4,2,23,0,0,0,0,2,2,2,1
1,1,1,1,1,1,1,1,1,4,2,2,2,4,5,0,2,1,1,1
1,1,1,1,1,1,1,1,1,6,4,8,8,2,2,2,2,1,1,1
endlayer

layer
1,1,2,2,2,2,1,1,1,1,1,1,1,1,1,1,1,1,1,1
1,1,2,0,0,2,4,4,4,1,1,1,1,1,1,1,1,1,1,1
1,2,0,0,0,0,4,0,0,2,2,2,1,1,1,1,1,1,1,1
1,2,0,0,0,0,4,0,0,0,0,2,4,1,1,1,1,1,1,1
1,2,0,0,0,0,8,0,0,0,0,2,4,1,1,1,1,1,1,1
1,2,2,0,0,3,24,0,0,0,0,2,4,1,1,1,1,1,1,1
3,4,2,0,0,4,0,0,0,0,2,4,4,1,1,1,1,1,1,1
4,4,2,4,4,4,0,17,0,2,7,7,1,1,1,1,1,1,1,1
2,2,2,5,0,0,2,2,2,2,1,1,1,1,1,2,2,2,2,1
2,0,0,0,0,0,2,1,1,1,1,1,1,4,2,0,0,18,2,1
2,0,0,0,0,2,2,1,1,1,1,1,1,4,2,0,0,0,25,2
2,0,0,0,0,4,7,1,1,1,1,1,6,4,2,0,0,0,25,2
2,3,0,0,26,4,1,1,1,1,1,1,6,2,2,4,4,4,4,2
1,2,0,0,2,4,1,1,1,1,6,4,4,2,0,0,0,0,0,2
1,2,2,2,2,1,1,1,1,3,4,2,2,2,0,0,0,0,0,8
1,1,1,1,1,1,1,1,1,4,2,0,0,0,4,17,0,0,2,1
1,1,1,1,1,1,1,1,1,4,2,0,0,0,0,4,0,0,2,1
1,1,1,1,1,1,1,1,1,4,2,0,0,0,0,0,2,2,2,1
1,1,1,1,1,1,1,1,1,7,2,2,2,5,0,0,2,1,1,1
1,1,1,1,1,1,1,1,1,1,1,1,2,2,2,8,8,1,1,1
endlayer

layer
1,1,2,2,2,8,1,1,1,1,1,1,1,1,1,1,1,1,1,1
1,1,2,14,14,2,4,4,4,1,1,1,1,1,1,1,1,1,1,1
1,2,14,14,14,0,4,14,14,2,2,2,1,1,1,1,1,1,1,1
1,2,14,14,14,0,4,14,14,14,14,2,4,1,1,1,1,1,1,1
1,2,14,14,14,0,4,14,14,14,14,2,4,1,1,1,1,1,1,1
1,2,2,14,14,0,4,14,14,14,14,2,7,1,1,1,1,1,1,1
1,4,2,14,14,12,4,14,14,14,2,1,1,1,1,1,1,1,1,1
1,6,2,4,4,4,4,17,14,2,1,1,1,1,1,1,1,1,1,1
2,2,12,0,0,0,2,2,2,2,1,1,1,1,1,2,2,2,8,1
2,14,14,14,14,14,2,1,1,1,1,1,1,4,2,14,14,18,2,1
2,14,14,14,14,2,2,1,1,1,1,1,1,4,2,14,14,14,14,2
2,14,14,14,26,5,1,1,1,1,1,1,1,6,2,14,14,14,14,2
8,14,14,14,2,4,1,1,1,1,1,1,1,2,2,4,4,4,4,2
1,2,14,14,2,8,1,1,1,1,1,6,4,2,14,14,14,14,14,2
1,2,2,2,2,1,1,1,1,1,2,2,2,2,14,14,14,14,14,2
1,1,1,1,1,1,1,1,1,3,2,14,27,14,4,17,14,14,2,1
1,1,1,1,1,1,1,1,1,4,2,14,27,14,14,4,14,14,2,1
1,1,1,1,1,1,1,1,1,7,2,14,27,14,14,14,2,2,8,1
1,1,1,1,1,1,1,1,1,1,2,2,12,0,0,0,2,1,1,1
1,1,1,1,1,1,1,1,1,1,1,1,2,2,2,2,2,1,1,1
endlayer

layer
1,1,8,2,2,8,1,1,1,1,1,1,1,1,1,1,1,1,1,1
1,1,4,9,9,9,4,4,4,1,1,1,1,1,1,1,1,1,1,1
1,8,0,0,0,0,4,14,14,2,2,8,1,1,1,1,1,1,1,1
1,2,0,0,0,0,4,0,0,0,0,2,28,1,1,1,1,1,1,1
1,2,0,0,0,0,4,0,0,0,0,29,1,1,1,1,1,1,1,1
1,8,2,0,0,0,4,0,0,0,0,8,1,1,1,1,1,1,1,1
1,1,30,0,0,0,4,0,0,0,4,1,1,1,1,1,1,1,1,1
1,1,4,4,8,8,8,17,0,4,1,1,1,1,1,1,1,1,1,1
8,2,0,0,0,0,2,2,2,8,1,1,1,1,1,8,2,2,8,1
2,0,0,0,0,28,2,1,1,1,1,1,1,28,8,0,0,18,2,1
2,0,0,0,0,2,8,1,1,1,1,1,1,1,30,0,0,0,0,8
2,0,0,0,8,1,1,1,1,1,1,1,1,1,2,0,0,0,0,2
8,0,0,0,29,1,1,1,1,1,1,1,1,8,2,4,4,4,4,2
1,2,14,14,8,28,1,1,1,1,1,1,1,30,0,0,0,0,0,2
1,8,2,4,4,1,1,1,1,1,8,2,2,2,0,0,0,0,0,8
1,1,1,1,1,1,1,1,1,1,2,32,28,31,4,17,0,0,4,1
1,1,1,1,1,1,1,1,1,1,30,0,0,0,0,8,0,0,4,1
1,1,1,1,1,1,1,1,1,1,2,0,0,0,0,0,2,4,4,1
1,1,1,1,1,1,1,1,1,1,8,2,0,0,0,0,2,1,1,1
1,1,1,1,1,1,1,1,1,1,1,1,8,2,2,2,8,1,1,1
endlayer

layer
1,1,4,2,1,2,1,1,1,1,1,1,1,1,1,1,1,1,1,1
1,1,4,0,0,0,4,1,4,1,1,1,1,1,1,1,1,1,1,1
1,2,0,0,0,0,8,0,0,2,1,2,1,1,1,1,1,1,1,1
1,1,0,0,0,0,4,0,0,0,0,2,1,1,1,1,1,1,1,1
1,2,0,0,0,0,4,0,0,0,0,33,1,1,1,1,1,1,1,1
1,2,2,0,0,0,4,0,0,0,0,2,1,1,1,1,1,1,1,1
1,1,34,0,0,0,4,0,0,0,4,1,1,1,1,1,1,1,1,1
1,1,4,8,8,8,8,17,0,4,1,1,1,1,1,1,1,1,1,1
2,2,0,0,0,0,2,4,1,2,1,1,1,1,1,2,1,2,2,1
2,0,0,0,0,23,1,1,1,1,1,1,1,28,2,0,0,18,2,1
1,0,0,0,0,2,2,1,1,1,1,1,1,1,33,0,0,0,0,2
2,0,0,0,2,1,1,1,1,1,1,1,1,1,2,0,0,0,0,2
2,0,0,0,34,1,1,1,1,1,1,1,1,8,2,4,4,4,4,4
1,4,0,0,8,28,1,1,1,1,1,1,1,34,0,0,0,0,0,1
1,4,4,1,4,1,1,1,1,1,2,2,2,2,0,0,0,0,0,4
1,1,1,1,1,1,1,1,1,1,2,0,23,0,8,17,0,0,4,1
1,1,1,1,1,1,1,1,1,1,34,0,0,0,0,8,0,0,1,1
1,1,1,1,1,1,1,1,1,1,2,0,0,0,0,0,2,4,4,1
1,1,1,1,1,1,1,1,1,1,2,2,0,0,0,0,2,1,1,1
1,1,1,1,1,1,1,1,1,1,1,1,2,2,1,2,2,1,1,1
endlayer

layer
1,1,4,2,2,8,1,1,1,1,1,1,1,1,1,1,1,1,1,1
1,1,8,35,35,35,4,4,4,1,1,1,1,1,1,1,1,1,1,1
1,8,0,0,0,0,8,0,0,2,2,8,1,1,1,1,1,1,1,1
1,2,0,0,0,0,8,0,0,0,0,2,1,1,1,1,1,1,1,1
1,2,0,0,0,0,4,0,0,0,0,2,1,1,1,1,1,1,1,1
1,8,2,0,0,0,4,0,0,0,0,8,1,1,1,1,1,1,1,1
1,1,4,0,0,0,4,0,0,0,4,1,1,1,1,1,1,1,1,1
1,1,4,8,8,8,8,0,0,4,1,1,1,1,1,1,1,1,1,1
8,2,0,0,0,0,2,2,2,8,1,1,1,1,1,8,2,2,8,1
2,0,0,0,0,0,2,1,1,1,1,1,1,36,8,0,0,0,2,1
2,0,0,0,0,2,8,1,1,1,1,1,1,36,2,0,0,0,0,8
2,0,0,0,8,1,1,1,1,1,1,1,1,36,2,0,0,0,0,2
8,0,0,0,8,1,1,1,1,1,1,1,1,4,2,4,4,4,4,2
1,4,0,0,2,28,1,1,1,1,1,1,1,4,0,0,0,0,0,2
1,4,4,4,8,1,1,1,1,1,8,2,2,2,0,0,0,0,0,8
1,1,1,1,1,1,1,1,1,1,2,0,0,0,4,0,0,0,4,1
1,1,1,1,1,1,1,1,1,1,2,0,0,0,0,8,0,0,4,1
1,1,1,1,1,1,1,1,1,1,2,0,0,0,0,0,2,4,4,1
1,1,1,1,1,1,1,1,1,1,8,2,0,0,0,0,2,1,1,1
1,1,1,1,1,1,1,1,1,1,1,1,8,2,2,2,8,1,1,1
endlayer

layer
1,1,6,4,4,4,1,1,1,1,1,1,1,1,1,1,1,1,1,1
1,1,4,0,0,0,4,12,12,1,1,1,1,1,1,1,1,1,1,1
1,2,0,0,0,0,8,38,38,37,8,12,1,1,1,1,1,1,1,1
1,2,0,0,0,0,8,38,9,9,38,12,1,1,1,1,1,1,1,1
1,2,0,0,0,0,8,38,15,15,38,12,1,1,1,1,1,1,1,1
1,2,2,0,0,0,8,38,38,38,5,1,1,1,1,1,1,1,1,1
1,36,4,0,0,0,8,38,0,38,5,1,1,1,1,1,1,1,1,1
1,36,4,8,8,4,8,38,38,37,1,1,1,1,1,1,1,1,1,1
3,2,0,0,0,0,2,7,7,7,1,1,1,1,1,8,2,2,2,1
2,0,0,0,0,0,2,1,1,1,1,1,1,1,2,0,0,0,2,1
2,0,0,0,0,2,7,1,1,1,1,1,1,1,2,0,0,0,38,5
2,0,0,0,2,36,1,1,1,1,1,1,1,1,2,0,0,0,38,5
2,0,0,0,2,36,1,1,1,1,1,1,1,12,2,8,8,8,8,2
1,4,0,0,2,36,1,1,1,1,1,1,1,12,4,39,0,0,0,4
1,6,4,4,4,1,1,1,1,1,8,8,8,8,8,39,0,0,0,4
1,1,1,1,1,1,1,1,1,1,8,0,0,0,8,39,0,0,4,1
1,1,1,1,1,1,1,1,1,1,8,0,0,0,38,2,0,0,4,1
1,1,1,1,1,1,1,1,1,1,8,0,0,0,38,2,4,4,4,1
1,1,1,1,1,1,1,1,1,1,8,8,38,38,38,8,5,1,1,1
1,1,1,1,1,1,1,1,1,1,1,1,7,7,7,7,7,1,1,1
endlayer

layer
1,1,1,3,3,1,1,1,1,1,1,1,1,1,1,1,1,1,1,1
1,1,4,0,0,5,1,1,1,1,1,1,1,1,1,1,1,1,1,1
1,6,24,0,0,24,5,1,1,1,1,1,1,1,1,1,1,1,1,1
1,6,0,0,0,0,8,1,1,1,1,1,1,1,1,1,1,1,1,1
1,6,26,0,0,0,4,1,1,1,1,1,1,1,1,1,1,1,1,1
1,7,4,0,0,0,4,12,12,12,1,1,1,1,1,1,1,1,1,1
1,1,4,0,0,0,4,12,40,12,1,1,1,1,1,1,1,1,1,1
1,1,8,4,8,4,8,12,12,12,1,1,1,1,1,1,1,1,1,1
1,6,38,38,38,5,12,1,1,1,1,1,1,1,1,3,3,3,5,1
12,6,38,9,38,5,12,1,1,1,1,1,1,1,6,36,36,36,5,1
12,6,38,38,38,5,1,1,1,1,1,1,1,1,6,36,41,36,5,1
12,5,7,7,5,1,1,1,1,1,1,1,1,1,6,36,36,36,5,1
12,5,40,6,5,1,1,1,1,1,1,1,1,1,7,8,4,4,8,12
1,3,3,3,12,1,1,1,1,1,1,1,1,1,1,8,0,0,7,12
1,1,12,12,1,1,1,1,1,1,1,3,3,3,1,3,0,0,42,1
1,1,1,1,1,1,1,1,1,1,6,43,43,43,5,3,0,0,3,1
1,1,1,1,1,1,1,1,1,1,6,43,25,43,5,8,4,4,8,1
1,1,1,1,1,1,1,1,1,1,6,43,43,43,5,12,7,7,5,1
1,1,1,1,1,1,1,1,1,1,1,7,7,7,1,1,1,1,1,1
1,1,1,1,1,1,1,1,1,1,1,1,1,1,1,1,1,1,1,1
endlayer

layer
1,1,1,1,1,1,1,1,1,1,1,1,1,1,1,1,1,1,1,1
1,1,12,12,12,1,1,1,1,1,1,1,1,1,1,1,1,1,1,1
1,1,12,40,12,1,1,1,1,1,1,1,1,1,1,1,1,1,1,1
1,1,3,3,3,3,3,1,1,1,1,1,1,1,1,1,1,1,1,1
1,1,6,14,14,14,5,1,1,1,1,1,1,1,1,1,1,1,1,1
1,1,6,14,44,14,5,1,1,1,1,1,1,1,1,1,1,1,1,1
1,1,6,14,14,14,5,1,1,1,1,1,1,1,1,1,1,1,1,1
1,1,7,7,7,7,7,1,1,1,1,1,1,1,1,1,1,1,1,1
1,1,1,1,1,1,1,1,1,1,1,1,1,1,1,1,1,1,1,1
1,1,1,1,1,1,1,1,1,1,1,1,1,1,1,1,1,1,1,1
1,1,1,1,1,1,1,1,1,1,1,1,1,1,1,1,1,1,1,1
1,1,1,1,1,1,1,1,1,1,1,1,1,1,1,1,1,1,1,1
1,1,1,1,1,1,1,1,1,1,1,1,1,1,1,12,12,12,12,1
1,1,1,1,1,1,1,1,1,1,1,1,1,1,1,6,7,7,6,1
1,1,1,1,1,1,1,1,1,1,1,1,1,1,1,6,12,25,6,1
1,1,1,1,1,1,1,1,1,1,1,1,1,1,1,6,12,12,6,1
1,1,1,1,1,1,1,1,1,1,1,1,1,1,1,6,7,7,5,1
1,1,1,1,1,1,1,1,1,1,1,1,1,1,1,1,1,1,1,1
1,1,1,1,1,1,1,1,1,1,1,1,1,1,1,1,1,1,1,1
1,1,1,1,1,1,1,1,1,1,1,1,1,1,1,1,1,1,1,1
endlayer

