# Gilly's Readymade underground survival base

# template generated with Ruins mod version 16.5 Ingame Parser
# Structure created and developed by Gilly

weight=1
embed_into_distance=32
acceptable_target_blocks=
unacceptable_target_blocks=flowing_water,water,flowing_lava,lava,ice,bedrock,netherrack,nether_brick,nether_brick_fence,soul_sand,quartz_ore,end_stone,obsidian,iron_bars,cloud,flesh,ash_block,slime_grass,slime_congealed,slime_dirt
dimensions=18,27,27
allowable_overhang=0
max_leveling=3
leveling_buffer=-1
preserve_water=0
preserve_lava=0

rule1=0,100,preserveBlock
rule2=0,0,minecraft:sea_lantern-0
rule3=0,100,minecraft:stained_hardened_clay-9
rule4=0,100,minecraft:stone-3
rule5=0,100,minecraft:stone-5
rule6=0,100,minecraft:double_stone_slab-0
rule7=0,100,minecraft:iron_bars-0
rule8=0,100,minecraft:stained_hardened_clay-4
rule9=0,100,minecraft:cobblestone_wall-0
rule10=0,100,minecraft:water-0
rule11=0,100,minecraft:stone_slab-0
rule12=0,100,minecraft:stone_brick_stairs-1
rule13=0,100,minecraft:stained_hardened_clay-13
rule14=0,100,minecraft:ladder-3
rule15=0,100,minecraft:ladder-2
rule16=0,100,minecraft:stone_brick_stairs-3
rule17=0,100,minecraft:stone_brick_stairs-2
rule18=0,100,minecraft:stained_hardened_clay-8
rule19=0,100,minecraft:stone_slab-8
rule20=0,100,minecraft:cauldron-0
rule21=0,100,minecraft:stonebrick-0
rule22=0,100,minecraft:stone_brick_stairs-7
rule23=0,100,minecraft:stone_brick_stairs-6
rule24=0,100,minecraft:stone_brick_stairs-4

layer
1,1,1,1,1,1,1,1,1,1,1,1,1,1,1,1,1,1,1,1,1,1,1,1,1,1,1
1,1,1,1,1,1,1,1,1,1,1,1,1,1,1,1,1,1,1,1,1,1,1,1,1,1,1
1,1,1,1,1,1,1,1,1,1,1,1,1,1,1,1,1,1,1,1,1,1,1,1,1,1,1
1,1,1,1,1,1,1,1,1,1,1,1,1,1,1,1,1,1,1,1,1,1,1,1,1,1,1
1,1,1,2,1,1,1,2,1,1,1,1,2,1,1,1,1,1,1,1,1,2,1,1,1,1,1
1,1,1,1,1,1,1,1,1,1,1,1,1,1,1,1,2,1,1,1,1,1,1,1,1,1,1
1,1,1,1,1,1,1,1,1,1,1,1,1,1,1,1,1,1,1,1,1,1,1,1,1,1,1
1,1,1,1,1,1,1,1,1,1,1,1,2,2,1,1,1,1,1,1,1,1,1,1,1,1,1
1,1,1,1,1,1,1,1,1,1,1,1,2,2,1,1,1,1,1,1,1,1,1,2,1,1,1
1,1,1,2,1,1,1,1,1,1,1,1,1,1,1,1,1,2,1,1,1,1,1,1,1,1,1
1,1,1,1,1,1,1,1,1,1,1,1,1,1,1,1,1,1,1,1,1,1,1,1,1,1,1
1,1,1,1,1,1,1,1,1,1,1,1,1,1,1,1,1,1,1,1,1,1,1,1,1,1,1
1,1,1,1,1,1,1,1,1,1,1,1,1,1,1,1,1,1,1,1,1,1,1,1,1,1,1
1,1,1,2,1,1,1,1,2,1,1,1,1,2,1,1,1,1,2,1,1,1,1,2,1,1,1
1,1,1,1,1,1,1,1,1,1,1,1,1,1,1,1,1,1,1,1,1,1,1,1,1,1,1
1,1,1,1,1,1,1,1,1,1,1,1,1,1,1,1,1,1,1,1,1,1,1,1,1,1,1
1,1,1,1,1,1,1,1,1,1,1,1,1,1,1,1,1,1,1,1,1,1,1,1,1,1,1
1,1,1,1,1,1,1,1,1,2,1,1,1,1,1,1,1,2,1,1,1,1,1,1,1,1,1
1,1,1,2,1,1,1,1,1,1,1,1,1,2,1,1,1,1,1,1,1,1,1,2,1,1,1
1,1,1,1,1,1,1,1,1,1,1,1,1,1,1,1,1,1,1,1,1,1,1,1,1,1,1
1,1,1,1,1,1,1,1,1,1,1,1,1,1,1,1,1,1,1,1,1,1,1,1,1,1,1
1,1,1,1,1,1,1,1,1,1,1,1,1,1,1,1,1,1,1,1,1,1,1,1,1,1,1
1,1,1,1,2,1,1,1,1,1,1,1,1,1,1,1,1,1,1,1,1,1,2,1,1,1,1
1,1,1,1,1,1,1,1,2,1,1,1,1,2,1,1,1,1,2,1,1,1,1,1,1,1,1
1,1,1,1,1,1,1,1,1,1,1,1,1,1,1,1,1,1,1,1,1,1,1,1,1,1,1
1,1,1,1,1,1,1,1,1,1,1,1,1,1,1,1,1,1,1,1,1,1,1,1,1,1,1
1,1,1,1,1,1,1,1,1,1,1,1,1,1,1,1,1,1,1,1,1,1,1,1,1,1,1
endlayer

layer
1,1,1,1,1,1,1,1,1,1,1,1,1,1,1,1,1,1,1,1,1,1,1,1,1,1,1
1,1,1,1,1,1,1,1,1,1,1,1,1,1,1,1,1,1,1,3,3,3,1,1,1,1,1
1,1,1,1,1,1,1,1,1,1,1,1,1,1,1,1,1,1,6,4,5,4,4,1,1,1,1
1,3,3,3,3,3,3,3,3,3,3,3,3,3,3,3,5,5,6,5,5,4,5,5,1,1,1
1,3,3,7,3,3,3,7,3,3,3,3,7,3,3,3,3,3,6,4,5,7,4,5,4,1,1
1,3,3,3,3,3,3,3,3,3,3,3,3,3,3,3,7,5,6,4,4,4,4,5,4,4,1
1,3,3,3,3,3,3,3,3,3,3,3,3,3,3,3,3,5,6,4,5,4,5,5,5,4,1
1,3,3,3,3,3,3,3,3,3,3,3,9,9,3,8,5,3,6,4,5,5,4,4,5,5,1
1,3,3,3,3,3,3,3,3,3,3,3,9,9,3,8,3,5,5,6,4,4,5,7,5,4,1
1,3,3,7,3,3,3,3,3,3,3,3,3,3,3,8,3,7,5,3,6,4,5,4,4,4,1
1,3,3,3,3,3,3,3,3,3,3,8,8,8,8,8,3,3,3,3,5,6,6,6,6,6,1
3,5,3,5,5,3,3,5,5,5,3,3,5,5,5,3,3,5,5,5,3,3,5,5,3,5,3
3,5,3,3,3,5,3,5,3,5,5,3,3,3,3,3,5,5,3,5,3,5,3,3,3,5,3
3,3,3,7,3,5,3,3,7,3,3,3,5,7,5,3,3,3,7,3,3,5,3,7,3,3,3
3,5,3,3,5,3,5,5,3,5,3,5,5,5,5,5,3,5,3,5,5,3,5,3,3,5,3
3,5,3,5,5,3,3,3,5,5,3,3,3,5,3,3,3,5,5,3,3,3,5,5,3,5,3
1,6,6,6,6,6,5,3,3,3,5,3,5,5,5,3,5,3,3,3,5,6,6,6,6,6,1
1,5,5,4,5,4,6,3,5,7,3,3,3,5,3,3,3,7,5,3,6,4,4,4,5,5,1
1,4,5,7,5,5,4,6,5,5,3,5,3,7,3,5,3,5,5,6,4,5,5,7,5,4,1
1,4,5,4,4,4,5,5,6,3,3,5,3,3,3,5,3,3,6,5,5,4,5,4,4,4,1
1,5,4,5,5,4,4,5,4,6,5,3,3,5,3,3,5,6,4,5,4,4,5,5,5,4,1
1,5,4,4,5,5,4,4,5,4,6,3,5,5,5,3,6,4,5,4,4,5,4,4,4,5,1
1,1,4,5,7,5,5,4,5,5,6,5,3,5,3,5,6,5,5,5,5,4,7,5,4,1,1
1,1,1,4,5,4,5,4,7,4,6,5,3,7,3,5,6,4,7,4,5,4,5,4,1,1,1
1,1,1,1,4,4,4,5,5,5,6,3,3,3,3,3,6,5,5,4,5,4,4,1,1,1,1
1,1,1,1,1,5,5,4,4,5,6,5,5,3,5,5,6,5,4,4,4,5,1,1,1,1,1
1,1,1,1,1,1,1,1,1,1,1,3,3,3,3,3,1,1,1,1,1,1,1,1,1,1,1
endlayer

layer
1,1,1,1,1,1,1,1,1,1,1,1,1,1,1,1,1,1,1,1,1,1,1,1,1,1,1
1,1,1,1,1,1,1,1,1,1,1,1,1,1,1,1,1,1,6,6,6,6,5,1,1,1,1
3,3,3,3,3,3,3,3,3,3,3,3,3,3,3,3,3,3,0,0,0,0,0,6,1,1,1
3,3,0,0,0,0,0,0,0,0,0,0,0,0,0,0,0,0,0,0,0,0,0,0,6,1,1
3,3,0,0,0,0,0,0,0,0,0,0,0,0,0,0,0,0,0,0,0,0,0,0,0,6,1
3,3,0,0,0,0,0,0,0,0,0,0,0,0,0,0,0,0,0,0,0,0,0,0,0,5,5
3,3,0,0,0,3,3,3,3,3,3,3,3,3,3,0,0,0,0,0,0,0,0,0,0,0,6
3,3,0,0,0,3,3,3,3,3,3,3,10,10,3,0,0,0,0,0,0,0,0,0,0,0,6
3,3,0,0,0,3,3,3,3,3,3,11,10,10,11,0,0,0,0,0,0,0,0,0,0,0,6
3,3,0,0,0,3,3,3,3,3,3,11,11,11,11,0,0,0,0,0,0,0,0,0,0,0,6
5,5,0,0,0,3,3,12,12,12,12,0,0,0,0,0,0,0,0,0,0,0,0,0,0,5,5
13,0,0,0,0,0,0,0,0,0,0,0,0,0,0,0,0,0,0,0,0,0,0,0,0,0,13
3,0,0,0,0,0,0,0,0,0,0,0,0,0,0,0,0,0,0,0,0,0,0,0,0,0,3
3,0,0,0,0,0,0,0,0,0,0,0,0,0,0,0,0,0,0,0,0,0,0,0,0,0,3
3,0,0,0,0,0,0,0,0,0,0,0,0,0,0,0,0,0,0,0,0,0,0,0,0,0,3
13,0,0,0,0,0,0,0,0,0,0,0,0,0,0,0,0,0,0,0,0,0,0,0,0,0,13
5,5,0,0,0,0,0,0,0,0,0,0,0,0,0,0,0,0,0,0,0,0,0,0,0,5,5
6,0,0,0,0,0,0,0,0,0,0,0,0,0,0,0,0,0,0,0,0,0,0,0,0,0,6
6,0,0,0,0,0,0,0,0,0,0,0,0,0,0,0,0,0,0,0,0,0,0,0,0,0,6
6,0,0,0,0,0,0,0,0,0,0,0,0,0,0,0,0,0,0,0,0,0,0,0,0,0,6
6,0,0,0,0,0,0,0,0,0,0,0,0,0,0,0,0,0,0,0,0,0,0,0,0,0,6
5,5,0,0,0,0,0,0,0,0,0,0,0,0,0,0,0,0,0,0,0,0,0,0,0,5,5
1,6,0,0,0,0,0,0,0,0,0,0,0,0,0,0,0,0,0,0,0,0,0,0,0,6,1
1,1,6,0,0,0,0,0,0,0,0,0,0,0,0,0,0,0,0,0,0,0,0,0,6,1,1
1,1,1,6,0,0,0,0,0,0,0,0,0,0,0,0,0,0,0,0,0,0,0,6,1,1,1
1,1,1,1,6,5,0,0,0,0,5,0,0,0,0,0,5,0,0,0,0,5,6,1,1,1,1
1,1,1,1,1,5,6,6,6,6,5,13,3,3,3,13,5,6,6,6,6,5,1,1,1,1,1
endlayer

layer
1,1,1,1,1,1,1,1,1,1,1,1,1,1,1,1,1,1,1,1,1,1,1,1,1,1,1
1,1,1,1,1,1,1,1,1,1,1,1,1,1,1,1,1,1,6,6,6,6,5,1,1,1,1
13,13,13,13,13,13,13,13,13,13,13,13,13,13,13,13,13,13,0,0,0,0,0,6,1,1,1
13,13,0,0,0,0,0,0,0,0,0,0,0,0,0,0,0,0,0,0,0,0,0,0,6,1,1
13,13,0,0,0,0,0,0,0,0,0,0,0,0,0,0,0,0,0,0,0,0,0,0,0,6,1
13,13,0,0,0,0,0,0,0,0,0,0,0,0,0,0,0,0,0,0,0,0,0,0,0,5,5
13,13,0,0,0,13,13,13,13,13,13,13,13,13,13,0,0,0,0,0,0,0,0,0,0,0,6
13,13,0,0,0,13,3,3,3,3,13,13,15,14,13,0,0,0,0,0,0,0,0,0,0,0,6
13,13,0,0,0,13,3,3,3,3,13,0,0,0,0,0,0,0,0,0,0,0,0,0,0,0,6
13,13,0,0,0,13,13,12,12,12,12,0,0,0,0,0,0,0,0,0,0,0,0,0,0,0,6
5,5,0,0,0,13,13,0,0,0,0,0,0,0,0,0,0,0,0,0,0,0,0,0,0,5,5
13,0,0,0,0,0,0,0,0,0,0,0,0,0,0,0,0,0,0,0,0,0,0,0,0,0,13
13,0,0,0,0,0,0,0,0,0,0,0,0,0,0,0,0,0,0,0,0,0,0,0,0,0,13
13,0,0,0,0,0,0,0,0,0,0,0,0,0,0,0,0,0,0,0,0,0,0,0,0,0,13
13,0,0,0,0,0,0,0,0,0,0,0,0,0,0,0,0,0,0,0,0,0,0,0,0,0,13
13,0,0,0,0,0,0,0,0,0,0,0,0,0,0,0,0,0,0,0,0,0,0,0,0,0,13
5,5,0,0,0,0,0,0,0,0,0,0,0,0,0,0,0,0,0,0,0,0,0,0,0,5,5
6,0,0,0,0,0,0,0,0,0,0,0,0,0,0,0,0,0,0,0,0,0,0,0,0,0,6
6,0,0,0,0,0,0,0,0,0,0,0,0,0,0,0,0,0,0,0,0,0,0,0,0,0,6
6,0,0,0,0,0,0,0,0,0,0,0,0,0,0,0,0,0,0,0,0,0,0,0,0,0,6
6,0,0,0,0,0,0,0,0,0,0,0,0,0,0,0,0,0,0,0,0,0,0,0,0,0,6
5,5,0,0,0,0,0,0,0,0,0,0,0,0,0,0,0,0,0,0,0,0,0,0,0,5,5
1,6,0,0,0,0,0,0,0,0,0,0,0,0,0,0,0,0,0,0,0,0,0,0,0,6,1
1,1,6,0,0,0,0,0,0,0,0,0,0,0,0,0,0,0,0,0,0,0,0,0,6,1,1
1,1,1,6,0,0,0,0,0,0,0,0,0,0,0,0,0,0,0,0,0,0,0,6,1,1,1
1,1,1,1,6,5,0,0,0,0,5,0,0,0,0,0,5,0,0,0,0,5,6,1,1,1,1
1,1,1,1,1,5,6,6,6,6,5,13,13,13,13,13,5,6,6,6,6,5,1,1,1,1,1
endlayer

layer
1,1,1,1,1,1,1,1,1,1,1,1,1,1,1,1,1,1,1,1,1,1,1,1,1,1,1
1,1,1,1,1,1,1,1,1,1,1,1,1,1,1,1,1,1,6,6,6,6,5,1,1,1,1
3,3,3,3,3,3,3,3,3,3,3,3,3,3,3,3,3,3,0,0,0,0,0,6,1,1,1
3,3,0,0,0,0,0,0,0,0,0,0,0,0,0,0,0,0,0,0,0,0,0,0,6,1,1
3,3,0,0,0,0,0,0,0,0,0,0,0,0,0,0,0,0,0,0,0,0,0,0,0,6,1
3,3,0,0,0,0,0,0,0,0,0,0,0,0,0,0,0,0,0,0,0,0,0,0,0,5,5
3,3,0,0,0,3,3,3,3,3,3,3,3,3,3,0,0,0,0,0,0,0,0,0,0,0,6
3,3,0,0,0,3,3,3,3,3,3,3,15,14,3,0,0,0,0,0,0,0,0,0,0,0,6
3,3,0,0,0,3,3,12,12,12,12,0,0,0,0,0,0,0,0,0,0,0,0,0,0,0,6
3,3,0,0,0,3,3,0,0,0,0,0,0,0,0,0,0,0,0,0,0,0,0,0,0,0,6
5,5,0,0,0,3,3,0,0,0,0,0,0,0,0,0,0,0,0,0,0,0,0,0,0,5,5
13,0,0,0,0,0,0,0,0,0,0,0,0,0,0,0,0,0,0,0,0,0,0,0,0,0,13
3,0,0,0,0,0,0,0,0,0,0,0,0,0,0,0,0,0,0,0,0,0,0,0,0,0,3
3,0,0,0,0,0,0,0,0,0,0,0,0,0,0,0,0,0,0,0,0,0,0,0,0,0,3
3,0,0,0,0,0,0,0,0,0,0,0,0,0,0,0,0,0,0,0,0,0,0,0,0,0,3
13,0,0,0,0,0,0,0,0,0,0,0,0,0,0,0,0,0,0,0,0,0,0,0,0,0,13
5,5,0,0,0,0,0,0,0,0,0,0,0,0,0,0,0,0,0,0,0,0,0,0,0,5,5
6,0,0,0,0,0,0,0,0,0,0,0,0,0,0,0,0,0,0,0,0,0,0,0,0,0,6
6,0,0,0,0,0,0,0,0,0,0,0,0,0,0,0,0,0,0,0,0,0,0,0,0,0,6
6,0,0,0,0,0,0,0,0,0,0,0,0,0,0,0,0,0,0,0,0,0,0,0,0,0,6
6,0,0,0,0,0,0,0,0,0,0,0,0,0,0,0,0,0,0,0,0,0,0,0,0,0,6
5,5,0,0,0,0,0,0,0,0,0,0,0,0,0,0,0,0,0,0,0,0,0,0,0,5,5
1,6,0,0,0,0,0,0,0,0,0,0,0,0,0,0,0,0,0,0,0,0,0,0,0,6,1
1,1,6,0,0,0,0,0,0,0,0,0,0,0,0,0,0,0,0,0,0,0,0,0,6,1,1
1,1,1,6,0,0,0,0,0,0,0,0,0,0,0,0,0,0,0,0,0,0,0,6,1,1,1
1,1,1,1,6,5,0,0,0,0,5,0,0,0,0,0,5,0,0,0,0,5,6,1,1,1,1
1,1,1,1,1,5,6,6,6,6,5,13,3,3,3,13,5,6,6,6,6,5,1,1,1,1,1
endlayer

layer
1,1,1,1,1,1,1,1,1,1,1,1,1,1,1,1,1,1,1,1,1,1,1,1,1,1,1
1,1,1,1,1,1,1,1,1,1,1,1,1,1,1,1,1,1,13,13,13,13,5,1,1,1,1
3,3,3,3,3,3,3,3,3,3,3,3,3,3,3,3,3,3,0,0,0,0,0,13,1,1,1
3,3,0,0,0,0,0,0,0,0,0,0,0,0,0,0,0,0,0,0,0,0,0,0,13,1,1
3,3,0,0,0,0,0,0,0,0,0,0,0,0,0,0,0,0,0,0,0,0,0,0,0,13,1
3,3,0,0,0,0,0,0,0,0,0,0,0,0,0,0,0,0,0,0,0,0,0,0,0,5,5
3,3,0,0,0,3,3,3,3,3,3,3,3,3,3,0,0,0,0,0,0,0,0,0,0,0,13
3,3,0,0,0,3,3,12,12,12,12,3,15,14,3,0,0,0,0,0,0,0,0,0,0,0,13
3,3,0,0,0,3,3,0,0,0,0,0,0,0,0,0,0,0,0,0,0,0,0,0,0,0,13
3,3,0,0,0,3,3,0,0,0,0,0,0,0,0,0,0,0,0,0,0,0,0,0,0,0,13
5,5,0,0,0,3,3,0,0,0,0,0,0,0,0,0,0,0,0,0,0,0,0,0,0,5,5
13,0,0,0,0,0,0,0,0,0,0,0,0,0,0,0,0,0,0,0,0,0,0,0,0,0,13
3,0,0,0,0,0,0,0,0,0,0,0,0,0,0,0,0,0,0,0,0,0,0,0,0,0,3
3,0,0,0,0,0,0,0,0,0,0,0,0,0,0,0,0,0,0,0,0,0,0,0,0,0,3
3,0,0,0,0,0,0,0,0,0,0,0,0,0,0,0,0,0,0,0,0,0,0,0,0,0,3
13,0,0,0,0,0,0,0,0,0,0,0,0,0,0,0,0,0,0,0,0,0,0,0,0,0,13
5,5,0,0,0,0,0,0,0,0,0,0,0,0,0,0,0,0,0,0,0,0,0,0,0,5,5
13,0,0,0,0,0,0,0,0,0,0,0,0,0,0,0,0,0,0,0,0,0,0,0,0,0,13
13,0,0,0,0,0,0,0,0,0,0,0,0,0,0,0,0,0,0,0,0,0,0,0,0,0,13
13,0,0,0,0,0,0,0,0,0,0,0,0,0,0,0,0,0,0,0,0,0,0,0,0,0,13
13,0,0,0,0,0,0,0,0,0,0,0,0,0,0,0,0,0,0,0,0,0,0,0,0,0,13
5,5,0,0,0,0,0,0,0,0,0,0,0,0,0,0,0,0,0,0,0,0,0,0,0,5,5
1,13,0,0,0,0,0,0,0,0,0,0,0,0,0,0,0,0,0,0,0,0,0,0,0,13,1
1,1,13,0,0,0,0,0,0,0,0,0,0,0,0,0,0,0,0,0,0,0,0,0,13,1,1
1,1,1,13,0,0,0,0,0,0,0,0,0,0,0,0,0,0,0,0,0,0,0,13,1,1,1
1,1,1,1,13,5,0,0,0,0,5,0,0,0,0,0,5,0,0,0,0,5,13,1,1,1,1
1,1,1,1,1,5,13,13,13,13,5,13,3,3,3,13,5,13,13,13,13,5,1,1,1,1,1
endlayer

layer
1,1,1,1,1,1,1,1,1,1,1,1,1,1,1,1,1,1,1,1,1,1,1,1,1,1,1
1,1,1,1,1,1,1,1,1,1,1,1,1,1,1,1,1,1,13,3,3,3,3,1,1,1,1
3,3,3,3,3,3,3,3,3,3,3,3,3,3,3,3,3,3,13,3,3,3,3,3,1,1,1
3,3,3,3,3,3,3,3,3,3,3,3,3,2,3,3,3,3,13,3,3,3,3,3,3,1,1
3,3,3,3,3,3,3,3,2,3,3,3,3,3,3,3,3,3,2,3,3,3,3,3,3,3,1
3,3,3,3,3,3,3,3,3,3,3,3,3,3,3,3,3,3,13,3,3,3,3,3,3,3,3
3,3,3,3,3,3,3,12,12,12,12,3,3,3,3,3,3,3,13,3,3,3,3,3,3,3,3
3,3,3,3,3,3,3,0,0,0,0,3,15,14,3,0,0,0,0,3,3,3,3,3,3,3,3
3,3,3,3,2,3,3,0,0,0,0,0,0,0,0,0,0,0,0,0,3,3,2,3,3,3,3
3,3,3,3,3,3,3,0,0,0,0,0,0,0,0,0,0,0,0,0,0,3,3,3,3,3,3
3,3,3,3,3,3,3,0,0,0,0,0,0,0,0,0,0,0,0,0,0,0,3,3,3,3,3
3,13,13,13,13,0,0,0,0,0,0,0,0,0,0,0,0,0,0,0,0,0,13,13,13,13,3
3,3,3,3,3,0,0,0,0,0,0,0,0,0,0,0,0,0,0,0,0,0,3,3,3,3,3
3,3,3,2,3,0,0,0,0,0,0,0,0,0,0,0,0,0,0,0,0,0,3,2,3,3,3
3,3,3,3,3,0,0,0,0,0,0,0,0,0,0,0,0,0,0,0,0,0,3,3,3,3,3
3,13,13,13,13,0,0,0,0,0,0,0,0,0,0,0,0,0,0,0,0,0,13,13,13,13,3
3,3,3,3,3,0,0,0,0,0,0,0,0,0,0,0,0,0,0,0,0,0,3,3,3,3,3
3,3,3,3,3,3,0,0,0,0,0,0,0,0,0,0,0,0,0,0,0,3,3,3,3,3,3
3,3,3,3,2,3,3,0,0,0,0,0,0,0,0,0,0,0,0,0,3,3,2,3,3,3,3
3,3,3,3,3,3,3,3,0,0,0,0,0,0,0,0,0,0,0,3,3,3,3,3,3,3,3
3,3,3,3,3,3,3,3,3,0,0,0,0,0,0,0,0,0,3,3,3,3,3,3,3,3,3
3,3,3,3,3,3,3,3,3,3,0,0,0,0,0,0,0,3,3,3,3,3,3,3,3,3,3
1,3,3,3,3,3,3,3,2,3,3,13,3,3,3,13,3,3,2,3,3,3,3,3,3,3,1
1,1,3,3,3,3,3,3,3,3,3,13,3,2,3,13,3,3,3,3,3,3,3,3,3,1,1
1,1,1,3,3,3,3,3,3,3,3,13,3,3,3,13,3,3,3,3,3,3,3,3,1,1,1
1,1,1,1,3,3,3,3,3,3,3,13,3,3,3,13,3,3,3,3,3,3,3,1,1,1,1
1,1,1,1,1,3,3,3,3,3,3,3,3,3,3,3,3,3,3,3,3,3,1,1,1,1,1
endlayer

layer
1,1,1,1,1,1,1,1,1,1,1,1,1,1,1,1,1,1,1,1,1,1,1,1,1,1,1
1,1,1,1,1,3,3,3,3,3,3,3,3,3,3,3,3,3,3,3,3,3,1,1,1,1,1
1,1,1,1,1,3,3,3,3,3,3,3,3,3,3,3,3,3,3,3,3,3,3,1,1,1,1
1,3,3,3,3,3,3,3,3,3,3,3,3,7,3,3,3,3,3,3,3,3,3,3,1,1,1
1,3,3,3,3,3,3,3,7,3,3,3,3,3,3,3,3,3,7,3,3,3,3,3,3,1,1
1,3,3,3,3,3,17,12,12,12,12,16,3,3,3,3,3,3,3,3,3,3,3,3,3,3,1
1,3,3,3,3,3,17,0,0,0,0,16,8,8,8,3,3,3,3,3,3,3,3,3,3,3,1
1,3,3,3,3,3,8,0,0,0,0,3,15,14,3,8,8,8,3,3,3,3,3,3,3,3,1
1,3,3,3,7,3,8,0,0,0,0,0,0,0,0,0,0,0,8,3,3,3,7,3,3,3,1
1,3,3,3,3,3,8,0,0,0,0,0,0,0,0,0,0,0,0,8,3,3,3,3,3,3,1
1,3,3,3,3,3,8,0,0,0,0,0,0,0,0,0,0,0,0,0,8,3,3,3,3,3,1
1,3,3,3,3,3,8,0,0,0,0,0,0,0,0,0,0,0,0,0,8,3,3,3,3,3,1
1,3,3,3,3,3,8,0,0,0,0,0,0,0,0,0,0,0,0,0,8,3,3,3,3,3,1
1,3,3,7,3,3,8,0,0,0,0,0,0,0,0,0,0,0,0,0,8,3,3,7,3,3,1
1,3,3,3,3,3,8,0,0,0,0,0,0,0,0,0,0,0,0,0,8,3,3,3,3,3,1
1,3,3,3,3,3,8,0,0,0,0,0,0,0,0,0,0,0,0,0,8,3,3,3,3,3,1
1,3,3,3,3,3,8,0,0,0,0,0,0,0,0,0,0,0,0,0,8,3,3,3,3,3,1
1,3,3,3,3,3,3,8,0,0,0,0,0,0,0,0,0,0,0,8,3,3,3,3,3,3,1
1,3,3,3,7,3,3,3,8,0,0,0,0,0,0,0,0,0,8,3,3,3,7,3,3,3,1
1,3,3,3,3,3,3,3,3,8,0,0,0,0,0,0,0,8,3,3,3,3,3,3,3,3,1
1,3,3,3,3,3,3,3,3,3,8,8,8,8,8,8,8,3,3,3,3,3,3,3,3,3,1
1,3,3,3,3,3,3,3,3,3,3,3,3,3,3,3,3,3,3,3,3,3,3,3,3,3,1
1,1,3,3,3,3,3,3,7,3,3,3,3,3,3,3,3,3,7,3,3,3,3,3,3,1,1
1,1,1,3,3,3,3,3,3,3,3,3,3,7,3,3,3,3,3,3,3,3,3,3,1,1,1
1,1,1,1,3,3,3,3,3,3,3,3,3,3,3,3,3,3,3,3,3,3,3,1,1,1,1
1,1,1,1,1,3,3,3,3,3,3,3,3,3,3,3,3,3,3,3,3,3,1,1,1,1,1
1,1,1,1,1,1,1,1,1,1,1,1,1,1,1,1,1,1,1,1,1,1,1,1,1,1,1
endlayer

layer
1,1,1,1,1,1,3,3,3,3,3,3,3,3,3,3,3,3,3,3,3,1,1,1,1,1,1
1,1,1,1,1,5,0,0,0,0,5,0,0,0,0,0,5,0,0,0,0,5,1,1,1,1,1
1,1,1,1,3,0,0,0,0,0,0,0,0,0,0,0,0,0,0,0,0,0,3,1,1,1,1
1,1,1,3,0,0,0,0,0,0,0,0,0,0,0,0,0,0,0,0,0,0,0,3,1,1,1
1,1,3,0,0,0,0,0,0,0,0,0,0,0,0,0,0,0,0,0,0,0,0,0,3,1,1
1,5,0,0,0,0,0,0,0,0,0,0,0,0,0,0,0,0,0,0,0,0,0,0,0,5,1
3,0,0,0,0,0,0,0,0,0,0,0,0,0,0,0,0,0,0,0,0,0,0,0,0,0,3
3,0,0,0,0,0,0,0,0,0,0,3,15,14,3,0,0,0,0,0,0,0,0,0,0,0,3
3,0,0,0,0,0,0,0,0,0,0,7,7,7,7,0,0,0,0,0,0,0,0,0,0,0,3
3,0,0,0,0,0,0,0,0,0,0,0,0,0,0,0,0,0,0,0,0,0,0,0,0,0,3
3,5,0,0,0,0,0,0,0,0,0,0,0,0,0,0,0,0,0,0,0,0,0,0,0,5,3
3,0,0,0,0,0,0,0,0,0,0,0,0,0,0,0,0,0,0,0,0,0,0,0,0,0,3
3,0,0,0,0,0,0,0,0,0,0,0,0,0,0,0,0,0,0,0,0,0,0,0,0,0,3
3,0,0,0,0,0,0,0,0,0,0,0,0,0,0,0,0,0,0,0,0,0,0,0,0,0,3
3,0,0,0,0,0,0,0,0,0,0,0,0,0,0,0,0,0,0,0,0,0,0,0,0,0,3
3,0,0,0,0,0,0,0,0,0,0,0,0,0,0,0,0,0,0,0,0,0,0,0,0,0,3
3,5,0,0,0,0,0,0,0,0,0,0,0,0,0,0,0,0,0,0,0,0,0,0,0,5,3
3,0,0,0,0,0,0,0,0,0,0,0,0,0,0,0,0,0,0,0,0,0,0,0,0,0,3
3,0,0,0,0,0,0,0,0,0,0,0,0,0,0,0,0,0,0,0,0,0,0,0,0,0,3
3,0,0,0,0,0,0,0,0,0,0,0,0,0,0,0,0,0,0,0,0,0,0,0,0,0,3
3,0,0,0,0,0,0,0,0,0,0,0,0,0,0,0,0,0,0,0,0,0,0,0,0,0,3
1,5,0,0,0,0,0,0,0,0,0,0,0,0,0,0,0,0,0,0,0,0,0,0,0,5,1
1,1,3,0,0,0,0,0,0,0,0,0,0,0,0,0,0,0,0,0,0,0,0,0,3,1,1
1,1,1,3,0,0,0,0,0,0,0,0,0,0,0,0,0,0,0,0,0,0,0,3,1,1,1
1,1,1,1,3,0,0,0,0,0,0,0,0,0,0,0,0,0,0,0,0,0,3,1,1,1,1
1,1,1,1,1,5,0,0,0,0,5,0,0,0,0,0,5,0,0,0,0,5,1,1,1,1,1
1,1,1,1,1,1,3,3,3,3,3,3,3,3,3,3,3,3,3,3,3,1,1,1,1,1,1
endlayer

layer
1,1,1,1,1,1,3,3,3,3,3,3,3,3,3,3,3,3,3,3,3,1,1,1,1,1,1
1,1,1,1,1,5,0,0,0,0,5,0,0,0,0,0,5,0,0,0,0,5,1,1,1,1,1
1,1,1,1,3,0,0,0,0,0,0,0,0,0,0,0,0,0,0,0,0,0,3,1,1,1,1
1,1,1,3,0,0,0,0,0,0,0,0,0,0,0,0,0,0,0,0,0,0,0,3,1,1,1
1,1,3,0,0,0,0,0,0,0,0,0,0,0,0,0,0,0,0,0,0,0,0,0,3,1,1
1,5,0,0,0,0,0,0,0,0,0,0,0,0,0,0,0,0,0,0,0,0,0,0,0,5,1
3,0,0,0,0,0,0,0,0,0,0,0,0,0,0,0,0,0,0,0,0,0,0,0,0,0,3
3,0,0,0,0,0,0,0,0,0,0,3,15,14,3,0,0,0,0,0,0,0,0,0,0,0,3
3,0,0,0,0,0,0,0,0,0,0,0,7,7,0,0,0,0,0,0,0,0,0,0,0,0,3
3,0,0,0,0,0,0,0,0,0,0,0,0,0,0,0,0,0,0,0,0,0,0,0,0,0,3
3,5,0,0,0,0,0,0,0,0,0,0,0,0,0,0,0,0,0,0,0,0,0,0,0,5,3
3,0,0,0,0,0,0,0,0,0,0,0,0,0,0,0,0,0,0,0,0,0,0,0,0,0,3
3,0,0,0,0,0,0,0,0,0,0,0,0,0,0,0,0,0,0,0,0,0,0,0,0,0,3
3,0,0,0,0,0,0,0,0,0,0,0,0,0,0,0,0,0,0,0,0,0,0,0,0,0,3
3,0,0,0,0,0,0,0,0,0,0,0,0,0,0,0,0,0,0,0,0,0,0,0,0,0,3
3,0,0,0,0,0,0,0,0,0,0,0,0,0,0,0,0,0,0,0,0,0,0,0,0,0,3
3,5,0,0,0,0,0,0,0,0,0,0,0,0,0,0,0,0,0,0,0,0,0,0,0,5,3
3,0,0,0,0,0,0,0,0,0,0,0,0,0,0,0,0,0,0,0,0,0,0,0,0,0,3
3,0,0,0,0,0,0,0,0,0,0,0,0,0,0,0,0,0,0,0,0,0,0,0,0,0,3
3,0,0,0,0,0,0,0,0,0,0,0,0,0,0,0,0,0,0,0,0,0,0,0,0,0,3
3,0,0,0,0,0,0,0,0,0,0,0,0,0,0,0,0,0,0,0,0,0,0,0,0,0,3
1,5,0,0,0,0,0,0,0,0,0,0,0,0,0,0,0,0,0,0,0,0,0,0,0,5,1
1,1,3,0,0,0,0,0,0,0,0,0,0,0,0,0,0,0,0,0,0,0,0,0,3,1,1
1,1,1,3,0,0,0,0,0,0,0,0,0,0,0,0,0,0,0,0,0,0,0,3,1,1,1
1,1,1,1,3,0,0,0,0,0,0,0,0,0,0,0,0,0,0,0,0,0,3,1,1,1,1
1,1,1,1,1,5,0,0,0,0,5,0,0,0,0,0,5,0,0,0,0,5,1,1,1,1,1
1,1,1,1,1,1,3,3,3,3,3,3,3,3,3,3,3,3,3,3,3,1,1,1,1,1,1
endlayer

layer
1,1,1,1,1,1,13,13,13,13,13,13,13,13,13,13,13,13,13,13,13,1,1,1,1,1,1
1,1,1,1,1,5,0,0,0,0,5,0,0,0,0,0,5,0,0,0,0,5,1,1,1,1,1
1,1,1,1,13,0,0,0,0,0,0,0,0,0,0,0,0,0,0,0,0,0,13,1,1,1,1
1,1,1,13,0,0,0,0,0,0,0,0,0,0,0,0,0,0,0,0,0,0,0,13,1,1,1
1,1,13,0,0,0,0,0,0,0,0,0,0,0,0,0,0,0,0,0,0,0,0,0,13,1,1
1,5,0,0,0,0,0,0,0,0,0,0,0,0,0,0,0,0,0,0,0,0,0,0,0,5,1
13,0,0,0,0,0,0,0,0,0,0,0,0,0,0,0,0,0,0,0,0,0,0,0,0,0,13
13,0,0,0,0,0,0,0,0,0,0,3,15,14,3,0,0,0,0,0,0,0,0,0,0,0,13
13,0,0,0,0,0,0,0,0,0,0,0,7,7,0,0,0,0,0,0,0,0,0,0,0,0,13
13,0,0,0,0,0,0,0,0,0,0,0,0,0,0,0,0,0,0,0,0,0,0,0,0,0,13
13,5,0,0,0,0,0,0,0,0,0,0,0,0,0,0,0,0,0,0,0,0,0,0,0,5,13
13,0,0,0,0,0,0,0,0,0,0,0,0,0,0,0,0,0,0,0,0,0,0,0,0,0,13
13,0,0,0,0,0,0,0,0,0,0,0,0,0,0,0,0,0,0,0,0,0,0,0,0,0,13
13,0,0,0,0,0,0,0,0,0,0,0,0,0,0,0,0,0,0,0,0,0,0,0,0,0,13
13,0,0,0,0,0,0,0,0,0,0,0,0,0,0,0,0,0,0,0,0,0,0,0,0,0,13
13,0,0,0,0,0,0,0,0,0,0,0,0,0,0,0,0,0,0,0,0,0,0,0,0,0,13
13,5,0,0,0,0,0,0,0,0,0,0,0,0,0,0,0,0,0,0,0,0,0,0,0,5,13
13,0,0,0,0,0,0,0,0,0,0,0,0,0,0,0,0,0,0,0,0,0,0,0,0,0,13
13,0,0,0,0,0,0,0,0,0,0,0,0,0,0,0,0,0,0,0,0,0,0,0,0,0,13
13,0,0,0,0,0,0,0,0,0,0,0,0,0,0,0,0,0,0,0,0,0,0,0,0,0,13
13,0,0,0,0,0,0,0,0,0,0,0,0,0,0,0,0,0,0,0,0,0,0,0,0,0,13
1,5,0,0,0,0,0,0,0,0,0,0,0,0,0,0,0,0,0,0,0,0,0,0,0,5,1
1,1,13,0,0,0,0,0,0,0,0,0,0,0,0,0,0,0,0,0,0,0,0,0,13,1,1
1,1,1,13,0,0,0,0,0,0,0,0,0,0,0,0,0,0,0,0,0,0,0,13,1,1,1
1,1,1,1,13,0,0,0,0,0,0,0,0,0,0,0,0,0,0,0,0,0,13,1,1,1,1
1,1,1,1,1,5,0,0,0,0,5,0,0,0,0,0,5,0,0,0,0,5,1,1,1,1,1
1,1,1,1,1,1,13,13,13,13,13,13,13,13,13,13,13,13,13,13,13,1,1,1,1,1,1
endlayer

layer
1,1,1,1,1,1,3,3,3,3,3,3,3,3,3,3,3,3,3,3,3,1,1,1,1,1,1
1,1,1,1,1,5,0,0,0,0,5,0,0,0,0,0,5,0,0,0,0,5,1,1,1,1,1
1,1,1,1,3,0,0,0,0,0,0,0,0,0,0,0,0,0,0,0,0,0,3,1,1,1,1
1,1,1,3,0,0,0,0,0,0,0,0,0,0,0,0,0,0,0,0,0,0,0,3,1,1,1
1,1,3,0,0,0,0,0,0,0,0,0,0,0,0,0,0,0,0,0,0,0,0,0,3,1,1
1,5,0,0,0,0,0,0,0,0,0,0,0,0,0,0,0,0,0,0,0,0,0,0,0,5,1
3,0,0,0,0,0,0,0,0,0,0,0,0,0,0,0,0,0,0,0,0,0,0,0,0,0,3
3,0,0,0,0,0,0,0,0,0,0,3,15,14,3,0,0,0,0,0,0,0,0,0,0,0,3
3,0,0,0,0,0,0,0,0,0,0,0,7,7,0,0,0,0,0,0,0,0,0,0,0,0,3
3,0,0,0,0,0,0,0,0,0,0,0,0,0,0,0,0,0,0,0,0,0,0,0,0,0,3
3,5,0,0,0,0,0,0,0,0,0,0,0,0,0,0,0,0,0,0,0,0,0,0,0,5,3
3,0,0,0,0,0,0,0,0,0,0,0,0,0,0,0,0,0,0,0,0,0,0,0,0,0,3
3,0,0,0,0,0,0,0,0,0,0,0,0,0,0,0,0,0,0,0,0,0,0,0,0,0,3
3,0,0,0,0,0,0,0,0,0,0,0,0,0,0,0,0,0,0,0,0,0,0,0,0,0,3
3,0,0,0,0,0,0,0,0,0,0,0,0,0,0,0,0,0,0,0,0,0,0,0,0,0,3
3,0,0,0,0,0,0,0,0,0,0,0,0,0,0,0,0,0,0,0,0,0,0,0,0,0,3
3,5,0,0,0,0,0,0,0,0,0,0,0,0,0,0,0,0,0,0,0,0,0,0,0,5,3
3,0,0,0,0,0,0,0,0,0,0,0,0,0,0,0,0,0,0,0,0,0,0,0,0,0,3
3,0,0,0,0,0,0,0,0,0,0,0,0,0,0,0,0,0,0,0,0,0,0,0,0,0,3
3,0,0,0,0,0,0,0,0,0,0,0,0,0,0,0,0,0,0,0,0,0,0,0,0,0,3
3,0,0,0,0,0,0,0,0,0,0,0,0,0,0,0,0,0,0,0,0,0,0,0,0,0,3
1,5,0,0,0,0,0,0,0,0,0,0,0,0,0,0,0,0,0,0,0,0,0,0,0,5,1
1,1,3,0,0,0,0,0,0,0,0,0,0,0,0,0,0,0,0,0,0,0,0,0,3,1,1
1,1,1,3,0,0,0,0,0,0,0,0,0,0,0,0,0,0,0,0,0,0,0,3,1,1,1
1,1,1,1,3,0,0,0,0,0,0,0,0,0,0,0,0,0,0,0,0,0,3,1,1,1,1
1,1,1,1,1,5,0,0,0,0,5,0,0,0,0,0,5,0,0,0,0,5,1,1,1,1,1
1,1,1,1,1,1,3,3,3,3,3,3,3,3,3,3,3,3,3,3,3,1,1,1,1,1,1
endlayer

layer
1,1,1,1,1,1,1,1,1,1,1,1,1,1,1,1,1,1,1,1,1,1,1,1,1,1,1
1,1,1,1,1,5,5,5,5,5,5,5,5,5,5,5,5,5,5,5,5,5,1,1,1,1,1
1,1,1,1,3,0,0,0,0,0,0,0,0,0,0,0,0,0,0,0,0,0,3,1,1,1,1
1,1,1,3,0,0,0,0,0,0,0,0,0,0,0,0,0,0,0,0,0,0,0,3,1,1,1
1,1,3,0,0,0,0,0,0,0,0,0,0,0,0,0,0,0,0,0,0,0,0,0,3,1,1
1,5,0,0,0,0,0,0,0,0,0,0,0,0,0,0,0,0,0,0,0,0,0,0,0,5,1
1,5,0,0,0,0,0,0,0,0,0,0,0,0,0,0,0,0,0,0,0,0,0,0,0,5,1
1,5,0,0,0,0,0,0,0,0,0,3,15,14,3,0,0,0,0,0,0,0,0,0,0,5,1
1,5,0,0,0,0,0,0,0,0,0,0,7,7,0,0,0,0,0,0,0,0,0,0,0,5,1
1,5,0,0,0,0,0,0,0,0,0,0,0,0,0,0,0,0,0,0,0,0,0,0,0,5,1
1,5,0,0,0,0,0,0,0,0,0,0,0,0,0,0,0,0,0,0,0,0,0,0,0,5,1
1,5,0,0,0,0,0,0,0,0,0,0,0,0,0,0,0,0,0,0,0,0,0,0,0,5,1
1,5,0,0,0,0,0,0,0,0,0,0,0,0,0,0,0,0,0,0,0,0,0,0,0,5,1
1,5,0,0,0,0,0,0,0,0,0,0,0,0,0,0,0,0,0,0,0,0,0,0,0,5,1
1,5,0,0,0,0,0,0,0,0,0,0,0,0,0,0,0,0,0,0,0,0,0,0,0,5,1
1,5,0,0,0,0,0,0,0,0,0,0,0,0,0,0,0,0,0,0,0,0,0,0,0,5,1
1,5,0,0,0,0,0,0,0,0,0,0,0,0,0,0,0,0,0,0,0,0,0,0,0,5,1
1,5,0,0,0,0,0,0,0,0,0,0,0,0,0,0,0,0,0,0,0,0,0,0,0,5,1
1,5,0,0,0,0,0,0,0,0,0,0,0,0,0,0,0,0,0,0,0,0,0,0,0,5,1
1,5,0,0,0,0,0,0,0,0,0,0,0,0,0,0,0,0,0,0,0,0,0,0,0,5,1
1,5,0,0,0,0,0,0,0,0,0,0,0,0,0,0,0,0,0,0,0,0,0,0,0,5,1
1,5,0,0,0,0,0,0,0,0,0,0,0,0,0,0,0,0,0,0,0,0,0,0,0,5,1
1,1,3,0,0,0,0,0,0,0,0,0,0,0,0,0,0,0,0,0,0,0,0,0,3,1,1
1,1,1,3,0,0,0,0,0,0,0,0,0,0,0,0,0,0,0,0,0,0,0,3,1,1,1
1,1,1,1,3,0,0,0,0,0,0,0,0,0,0,0,0,0,0,0,0,0,3,1,1,1,1
1,1,1,1,1,5,5,5,5,5,5,5,5,5,5,5,5,5,5,5,5,5,1,1,1,1,1
1,1,1,1,1,1,1,1,1,1,1,1,1,1,1,1,1,1,1,1,1,1,1,1,1,1,1
endlayer

layer
1,1,1,1,1,1,1,1,1,1,1,1,1,1,1,1,1,1,1,1,1,1,1,1,1,1,1
1,1,1,1,1,3,3,3,3,3,3,3,3,3,3,3,3,3,3,3,3,3,1,1,1,1,1
1,1,1,1,3,3,3,18,18,18,18,18,18,18,18,18,18,18,18,18,3,3,3,1,1,1,1
1,1,1,3,3,3,18,19,19,19,19,19,19,19,19,19,19,19,19,19,18,3,3,3,1,1,1
1,1,3,3,3,18,19,0,0,0,0,0,0,0,0,0,0,0,0,19,19,18,3,3,3,1,1
1,3,3,3,18,19,0,0,0,0,0,0,0,0,0,0,0,0,0,0,19,19,18,3,3,3,1
1,3,3,18,19,0,0,0,0,0,0,0,0,0,0,0,0,0,0,0,0,19,19,18,3,3,1
1,3,18,19,19,0,0,0,0,0,0,3,15,14,3,0,0,0,0,0,0,0,19,19,18,3,1
1,3,18,19,19,0,0,0,0,0,0,0,7,7,0,0,0,0,0,0,0,0,0,19,18,3,1
1,3,18,19,19,0,0,0,0,0,0,0,0,0,0,0,0,0,0,0,0,0,0,19,18,3,1
1,3,18,19,19,0,0,0,0,0,0,0,0,0,0,0,0,0,0,0,0,0,0,19,18,3,1
1,3,18,19,19,0,0,0,0,0,0,0,0,0,0,0,0,0,0,0,0,0,0,19,18,3,1
1,3,18,19,19,0,0,0,0,0,0,0,0,0,0,0,0,0,0,0,0,0,0,19,18,3,1
1,3,18,19,19,0,0,0,0,0,0,0,0,0,0,0,0,0,0,0,0,0,0,19,18,3,1
1,3,18,19,19,0,0,0,0,0,0,0,0,0,0,0,0,0,0,0,0,0,0,19,18,3,1
1,3,18,19,19,0,0,0,0,0,0,0,0,0,0,0,0,0,0,0,0,0,0,19,18,3,1
1,3,18,19,19,0,0,0,0,0,0,0,0,0,0,0,0,0,0,0,0,0,0,19,18,3,1
1,3,18,19,19,0,0,0,0,0,0,0,0,0,0,0,0,0,0,0,0,0,0,19,18,3,1
1,3,18,19,19,0,0,0,0,0,0,0,0,0,0,0,0,0,0,0,0,0,0,19,18,3,1
1,3,18,19,19,19,0,0,0,0,0,0,0,0,0,0,0,0,0,0,0,0,19,19,18,3,1
1,3,3,18,19,19,19,0,0,0,0,0,0,0,0,0,0,0,0,0,0,19,19,18,3,3,1
1,3,3,3,18,19,19,19,0,0,0,0,0,0,0,0,0,0,0,0,19,19,18,3,3,3,1
1,1,3,3,3,18,19,19,19,19,19,19,19,19,19,19,19,19,19,19,19,18,3,3,3,1,1
1,1,1,3,3,3,18,19,19,19,19,19,19,19,19,19,19,19,19,19,18,3,3,3,1,1,1
1,1,1,1,3,3,3,18,18,18,18,18,18,18,18,18,18,18,18,18,3,3,3,1,1,1,1
1,1,1,1,1,3,3,3,3,3,3,3,3,3,3,3,3,3,3,3,3,3,1,1,1,1,1
1,1,1,1,1,1,1,1,1,1,1,1,1,1,1,1,1,1,1,1,1,1,1,1,1,1,1
endlayer

layer
1,1,1,1,1,1,1,1,1,1,1,1,1,1,1,1,1,1,1,1,1,1,1,1,1,1,1
1,1,1,1,1,1,3,3,3,3,3,3,3,3,3,3,3,3,3,3,3,1,1,1,1,1,1
1,1,1,1,1,3,3,18,18,18,18,18,18,18,18,18,18,18,18,18,3,3,1,1,1,1,1
1,1,1,1,3,3,18,0,0,0,0,0,0,0,0,0,0,0,0,0,18,3,3,1,1,1,1
1,1,1,3,3,18,0,11,20,11,11,11,11,20,11,11,11,11,20,0,0,18,3,3,1,1,1
1,1,3,3,18,0,11,19,19,19,19,19,19,19,19,11,11,11,11,11,0,0,18,3,3,1,1
1,3,3,18,0,11,19,5,5,5,5,5,5,5,5,19,19,19,19,11,11,0,0,18,3,3,1
1,3,18,0,0,20,19,5,0,0,0,3,15,14,3,5,5,5,19,19,11,11,0,0,18,3,1
1,3,18,0,0,11,19,5,0,0,0,0,7,7,0,0,0,0,5,19,19,11,20,0,18,3,1
1,3,18,0,0,11,19,5,0,0,0,0,0,0,0,0,0,0,0,5,19,19,11,0,18,3,1
1,3,18,0,0,11,19,5,0,0,0,0,0,0,0,0,0,0,0,0,5,19,11,0,18,3,1
1,3,18,0,0,11,19,5,0,0,0,0,0,0,0,0,0,0,0,0,5,19,11,0,18,3,1
1,3,18,0,0,20,19,5,0,0,0,0,0,0,0,0,0,0,0,0,5,19,11,0,18,3,1
1,3,18,0,0,11,19,5,0,0,0,0,0,0,0,0,0,0,0,0,5,19,20,0,18,3,1
1,3,18,0,0,11,19,5,0,0,0,0,0,0,0,0,0,0,0,0,5,19,11,0,18,3,1
1,3,18,0,0,11,19,5,0,0,0,0,0,0,0,0,0,0,0,0,5,19,11,0,18,3,1
1,3,18,0,0,11,19,5,0,0,0,0,0,0,0,0,0,0,0,0,5,19,11,0,18,3,1
1,3,18,0,0,20,19,19,5,0,0,0,0,0,0,0,0,0,0,5,19,19,11,0,18,3,1
1,3,18,0,0,11,11,19,19,5,0,0,0,0,0,0,0,0,5,19,19,11,20,0,18,3,1
1,3,18,0,0,0,11,11,19,19,5,5,5,5,5,5,5,5,19,19,11,11,0,0,18,3,1
1,3,3,18,0,0,0,11,11,19,19,19,19,19,19,19,19,19,19,6,11,0,0,18,3,3,1
1,1,3,3,18,0,0,0,11,20,11,11,11,11,20,11,11,11,11,20,0,0,18,3,3,1,1
1,1,1,3,3,18,0,0,0,0,0,0,0,0,0,0,0,0,0,0,0,18,3,3,1,1,1
1,1,1,1,3,3,18,0,0,0,0,0,0,0,0,0,0,0,0,0,18,3,3,1,1,1,1
1,1,1,1,1,3,3,18,18,18,18,18,18,18,18,18,18,18,18,18,3,3,1,1,1,1,1
1,1,1,1,1,1,3,3,3,3,3,3,3,3,3,3,3,3,3,3,3,1,1,1,1,1,1
1,1,1,1,1,1,1,1,1,1,1,1,1,1,1,1,1,1,1,1,1,1,1,1,1,1,1
endlayer

layer
1,1,1,1,1,1,1,1,1,1,1,1,1,1,1,1,1,1,1,1,1,1,1,1,1,1,1
1,1,1,1,1,1,1,1,1,1,1,1,1,1,1,1,1,1,1,1,1,1,1,1,1,1,1
1,1,1,1,1,1,1,3,3,3,3,3,3,3,3,3,3,3,3,3,1,1,1,1,1,1,1
1,1,1,1,1,1,3,3,3,3,3,3,3,3,3,3,3,3,3,3,3,1,1,1,1,1,1
1,1,1,1,1,3,3,3,2,3,3,3,3,2,3,3,3,3,2,3,3,3,1,1,1,1,1
1,1,1,1,3,3,3,3,3,3,3,3,3,3,3,3,3,3,3,3,3,3,3,1,1,1,1
1,1,1,3,3,3,3,3,3,3,3,3,18,18,3,3,3,3,3,3,3,3,3,3,1,1,1
1,1,3,3,3,2,3,3,18,18,18,3,15,14,3,3,3,3,3,3,3,3,3,3,3,1,1
1,1,3,3,3,3,3,3,18,0,18,0,7,7,0,18,18,18,3,3,3,3,2,3,3,1,1
1,1,3,3,3,3,3,3,18,0,18,0,0,0,0,18,0,0,18,3,3,3,3,3,3,1,1
1,1,3,3,3,3,3,3,18,0,18,0,0,0,0,18,0,0,0,18,3,3,3,3,3,1,1
1,1,3,3,3,3,3,3,18,18,18,18,18,18,18,18,18,18,18,18,3,3,3,3,3,1,1
1,1,3,3,3,2,3,3,18,0,18,0,0,0,0,18,0,0,0,18,3,3,3,3,3,1,1
1,1,3,3,3,3,3,3,18,0,18,0,0,0,0,18,0,0,0,18,3,3,2,3,3,1,1
1,1,3,3,3,3,3,3,18,0,18,0,0,0,0,18,0,0,0,18,3,3,3,3,3,1,1
1,1,3,3,3,3,3,3,18,0,18,0,0,0,0,18,0,0,0,18,3,3,3,3,3,1,1
1,1,3,3,3,3,3,3,18,18,18,18,18,18,18,18,18,18,18,18,3,3,3,3,3,1,1
1,1,3,3,3,2,3,3,3,18,18,0,0,0,0,18,0,0,18,3,3,3,3,3,3,1,1
1,1,3,3,3,3,3,3,3,3,18,18,18,18,18,18,18,18,3,3,3,3,2,3,3,1,1
1,1,3,3,3,3,3,3,3,3,3,3,3,3,3,3,3,3,3,3,3,3,3,3,3,1,1
1,1,1,3,3,3,3,3,3,3,3,3,3,3,3,3,3,3,3,3,3,3,3,3,1,1,1
1,1,1,1,3,3,3,3,3,2,3,3,3,3,2,3,3,3,3,2,3,3,3,1,1,1,1
1,1,1,1,1,3,3,3,3,3,3,3,3,3,3,3,3,3,3,3,3,3,1,1,1,1,1
1,1,1,1,1,1,3,3,3,3,3,3,3,3,3,3,3,3,3,3,3,1,1,1,1,1,1
1,1,1,1,1,1,1,3,3,3,3,3,3,3,3,3,3,3,3,3,1,1,1,1,1,1,1
1,1,1,1,1,1,1,1,1,1,1,1,1,1,1,1,1,1,1,1,1,1,1,1,1,1,1
1,1,1,1,1,1,1,1,1,1,1,1,1,1,1,1,1,1,1,1,1,1,1,1,1,1,1
endlayer

layer
1,1,1,1,1,1,1,1,1,1,1,1,1,1,1,1,1,1,1,1,1,1,1,1,1,1,1
1,1,1,1,1,1,1,1,1,1,1,1,1,1,1,1,1,1,1,1,1,1,1,1,1,1,1
1,1,1,1,1,1,1,1,1,1,1,1,1,1,1,1,1,1,1,1,1,1,1,1,1,1,1
1,1,1,1,1,1,1,1,1,1,5,5,1,5,1,1,1,1,1,1,1,1,1,1,1,1,1
1,1,1,1,1,1,1,1,3,1,5,1,5,5,1,5,1,1,3,1,1,1,1,1,1,1,1
1,1,1,1,1,1,1,1,1,1,5,5,5,1,5,1,5,5,1,1,1,5,1,1,1,1,1
1,1,1,1,1,1,5,1,1,3,1,1,21,21,1,1,1,1,1,1,5,5,1,1,1,1,1
1,1,1,1,1,5,5,5,3,11,21,3,15,14,3,21,1,1,1,1,5,5,1,1,1,1,1
1,1,1,1,1,1,5,1,3,11,21,0,7,7,0,21,3,3,1,1,1,5,5,1,1,1,1
1,1,1,1,1,5,1,3,2,20,21,0,0,0,0,21,11,11,3,1,1,5,1,1,1,1,1
1,1,1,1,1,1,1,1,3,11,21,0,0,0,0,21,11,20,11,3,5,1,5,1,1,1,1
1,1,1,1,1,5,5,5,3,3,21,21,21,21,21,21,3,2,3,3,5,1,1,1,1,1,1
1,1,1,1,1,3,1,1,3,11,3,11,11,11,11,3,11,11,11,3,5,1,5,1,1,1,1
1,1,1,1,1,5,5,5,3,11,3,11,11,11,11,3,11,11,11,3,5,5,5,1,1,1,1
1,1,1,1,1,1,1,5,3,20,2,11,20,11,11,2,11,20,11,3,5,1,5,1,1,1,1
1,1,1,1,1,5,1,5,3,11,3,11,11,11,11,3,11,11,11,3,1,1,1,1,1,1,1
1,1,1,1,1,5,1,1,3,3,3,3,2,3,3,3,3,2,3,3,5,5,5,1,1,1,1
1,1,1,1,1,5,5,1,1,3,3,11,20,11,11,3,11,20,3,1,1,1,1,1,1,1,1
1,1,1,1,1,1,1,1,1,1,3,3,3,3,3,3,3,3,1,1,5,5,5,1,1,1,1
1,1,1,1,1,5,1,1,1,1,1,1,1,1,1,1,1,1,1,1,5,1,1,1,1,1,1
1,1,1,1,1,1,1,1,1,1,1,1,1,1,1,1,1,1,1,1,1,5,1,1,1,1,1
1,1,1,1,1,5,5,5,1,3,5,5,5,1,5,5,5,1,1,3,5,5,1,1,1,1,1
1,1,1,1,1,1,1,1,1,1,1,5,1,5,1,1,1,5,1,1,5,5,1,1,1,1,1
1,1,1,1,1,1,1,1,1,1,1,1,5,1,5,1,1,1,1,1,1,1,1,1,1,1,1
1,1,1,1,1,1,1,1,1,1,1,1,1,1,1,1,1,1,1,1,1,1,1,1,1,1,1
1,1,1,1,1,1,1,1,1,1,1,1,1,1,1,1,1,1,1,1,1,1,1,1,1,1,1
1,1,1,1,1,1,1,1,1,1,1,1,1,1,1,1,1,1,1,1,1,1,1,1,1,1,1
endlayer

layer
1,1,1,1,1,1,1,1,1,1,1,1,1,1,1,1,1,1,1,1,1,1,1,1,1,1,1
1,1,1,1,1,1,1,1,1,1,1,1,1,1,1,1,1,1,1,1,1,1,1,1,1,1,1
1,1,1,1,1,1,1,1,1,1,1,1,1,1,1,1,1,1,1,1,1,1,1,1,1,1,1
1,1,1,1,1,1,1,1,1,1,1,1,1,1,1,1,1,1,1,1,1,1,1,1,1,1,1
1,1,1,1,1,1,1,1,1,1,1,1,1,1,1,1,1,1,1,1,1,1,1,1,1,1,1
1,1,1,1,1,1,1,1,1,1,1,1,1,1,1,1,1,1,1,1,1,1,1,1,1,1,1
1,1,1,1,1,1,1,1,1,1,1,1,21,21,1,1,1,1,1,1,1,1,1,1,1,1,1
1,1,1,1,1,1,1,1,1,3,21,3,15,14,3,21,1,1,1,1,1,1,1,1,1,1,1
1,1,1,1,1,1,1,1,1,3,23,0,7,7,0,22,1,1,1,1,1,1,1,1,1,1,1
1,1,1,1,1,1,1,1,3,3,23,0,0,0,0,22,3,3,1,1,1,1,1,1,1,1,1
1,1,1,1,1,1,1,1,1,3,23,0,0,0,0,22,3,3,3,1,1,1,1,1,1,1,1
1,1,1,1,1,1,1,1,1,1,21,23,24,24,22,21,1,3,1,1,1,1,1,1,1,1,1
1,1,1,1,1,1,1,1,1,3,1,3,3,3,3,1,3,3,3,1,1,1,1,1,1,1,1
1,1,1,1,1,1,1,1,1,3,1,3,3,3,3,1,3,3,3,1,1,1,1,1,1,1,1
1,1,1,1,1,1,1,1,1,3,3,3,2,3,3,3,3,2,3,1,1,1,1,1,1,1,1
1,1,1,1,1,1,1,1,1,3,1,3,3,3,3,1,3,3,3,1,1,1,1,1,1,1,1
1,1,1,1,1,1,1,1,1,1,1,1,3,1,1,1,1,3,1,1,1,1,1,1,1,1,1
1,1,1,1,1,1,1,1,1,1,1,3,3,3,3,1,3,3,1,1,1,1,1,1,1,1,1
1,1,1,1,1,1,1,1,1,1,1,1,1,1,1,1,1,1,1,1,1,1,1,1,1,1,1
1,1,1,1,1,1,1,1,1,1,1,1,1,1,1,1,1,1,1,1,1,1,1,1,1,1,1
1,1,1,1,1,1,1,1,1,1,1,1,1,1,1,1,1,1,1,1,1,1,1,1,1,1,1
1,1,1,1,1,1,1,1,1,1,1,1,1,1,1,1,1,1,1,1,1,1,1,1,1,1,1
1,1,1,1,1,1,1,1,1,1,1,1,1,1,1,1,1,1,1,1,1,1,1,1,1,1,1
1,1,1,1,1,1,1,1,1,1,1,1,1,1,1,1,1,1,1,1,1,1,1,1,1,1,1
1,1,1,1,1,1,1,1,1,1,1,1,1,1,1,1,1,1,1,1,1,1,1,1,1,1,1
1,1,1,1,1,1,1,1,1,1,1,1,1,1,1,1,1,1,1,1,1,1,1,1,1,1,1
1,1,1,1,1,1,1,1,1,1,1,1,1,1,1,1,1,1,1,1,1,1,1,1,1,1,1
endlayer

