
# Created by Ruins mod version 16.7 Ingame Parser
# authoring Player: lafuller

weight=1
embed_into_distance=3
acceptable_target_blocks=
unacceptable_target_blocks=dirt,sand,stone,flowing_water,water,flowing_lava,lava,ice,bedrock,netherrack,nether_brick,nether_brick_fence,soul_sand,quartz_ore,gravel,end_stone,obsidian,iron_bars,cloud,flesh,ash_block,slime_grass,slime_congealed,slime_dirt
biomesToSpawnIn=plains,prarie,meadow
dimensions=24,15,12
allowable_overhang=0
max_leveling=3
leveling_buffer=-1
preserve_water=0
preserve_lava=0

rule1=0,100,preserveBlock
rule2=0,100,stonebrick,stonebrick-1,stonebrick-2,stone-5,stone-6,cobblestone,gravel
rule3=0,100,minecraft:cobblestone_wall-0
rule4=0,100,minecraft:dirt-0
rule5=0,100,minecraft:stained_hardened_clay-8
rule6=0,100,minecraft:hardened_clay-0
rule7=0,100,stonebrick-0,stonebrick-0,stonebrick-0,stonebrick-0,stonebrick-1,stonebrick-2,stonebrick-2,stone-5,stone-6,cobblestone,stone_brick_stairs-0,stone_brick_stairs-1,stone_brick_stairs-2,stone_brick_stairs-3,stone_brick_stairs-4,stone_brick_stairs-5,stone_brick_stairs-6,stone_brick_stairs-7
rule8=0,100,minecraft:log-0
rule9=0,100,minecraft:log-8
rule10=1,100,hay_block-0,air,air
rule11=1,100,hay_block-8,air,air
rule12=1,100,hay_block-4,air,air
rule13=0,100,minecraft:stone_slab-3
rule14=0,100,minecraft:log-4
rule15=0,100,minecraft:hay_block-0
rule16=1,100,minecraft:torch-5
rule17=0,100,minecraft:ladder-2
rule18=0,100,minecraft:fence-0
rule19=0,100,minecraft:stone_brick_stairs-0
rule20=0,100,minecraft:stone_brick_stairs-2
rule21=0,100,minecraft:stone_brick_stairs-3
rule22=0,100,minecraft:stone_slab-0
rule23=0,100,minecraft:double_stone_slab-0
rule24=0,100,minecraft:stone_brick_stairs-1
rule25=0,100,minecraft:iron_bars-0
rule26=0,100,minecraft:stone_brick_stairs-4
rule27=0,100,minecraft:stone_brick_stairs-6
rule28=0,100,minecraft:stone_brick_stairs-7
rule29=0,100,minecraft:stone_brick_stairs-5
rule30=0,100,minecraft:stone_slab-13
rule31=0,100,minecraft:planks-0
rule32=0,100,minecraft:oak_stairs-4
rule33=0,100,minecraft:wooden_slab-8
rule34=0,100,minecraft:oak_stairs-0
rule35=0,100,minecraft:hay_block-4
rule36=0,100,minecraft:hay_block-8
rule37=0,100,minecraft:oak_stairs-5
rule38=0,100,minecraft:oak_stairs-1

layer
1,1,1,1,1,1,1,1,1,1,1,1
1,1,1,1,1,1,1,1,1,1,1,1
1,2,3,2,3,2,3,2,3,2,1,1
2,2,2,4,4,4,4,4,2,2,2,1
3,2,4,4,4,4,4,4,4,2,3,1
2,4,4,4,4,4,4,4,4,4,2,1
3,4,4,4,4,4,4,4,4,4,3,1
2,4,4,4,4,4,4,4,4,4,2,1
3,4,4,4,4,4,4,4,4,4,3,1
2,4,4,4,4,4,4,4,4,4,2,1
3,2,4,4,4,4,4,4,4,2,3,1
2,2,2,4,4,4,4,4,2,2,2,1
2,2,2,2,2,2,2,2,2,2,2,1
1,2,2,2,2,2,2,2,2,2,1,1
1,2,2,2,3,2,3,2,2,2,1,1
endlayer

layer
1,1,1,1,1,1,1,1,1,1,1,1
1,1,1,1,1,1,1,1,1,1,1,1
1,2,3,2,3,2,3,2,3,2,1,1
2,2,2,4,4,4,4,4,2,2,2,1
3,2,4,4,4,4,4,4,4,2,3,1
2,4,4,4,4,4,4,4,4,4,2,1
3,4,4,4,4,4,4,4,4,4,3,1
2,4,4,4,4,4,4,4,4,4,2,1
3,4,4,4,4,4,4,4,4,4,3,1
2,4,4,4,4,4,4,4,4,4,2,1
3,2,4,4,4,4,4,4,4,2,3,1
2,2,2,4,4,4,4,4,2,2,2,1
1,2,2,2,2,2,2,2,2,2,1,1
1,1,2,2,2,2,2,2,2,1,1,1
1,1,2,2,3,2,3,2,2,1,1,1
endlayer

layer
1,1,1,1,1,1,1,1,1,1,1,1
1,1,1,1,1,1,1,1,1,1,1,1
1,2,2,2,3,2,3,2,2,2,1,1
2,2,2,4,4,4,4,4,2,2,2,1
2,2,4,4,4,4,4,4,4,2,2,1
2,4,4,4,4,4,4,4,4,4,2,1
3,4,4,4,4,4,4,4,4,4,3,1
2,4,4,4,4,4,4,4,4,4,2,1
3,4,4,4,4,4,4,4,4,4,3,1
2,4,4,4,4,4,4,4,4,4,2,1
2,2,4,4,4,4,4,4,4,2,2,1
2,2,2,4,4,4,4,4,2,2,2,1
1,2,2,2,2,2,2,2,2,2,1,1
1,1,1,2,2,2,2,2,1,1,1,1
1,1,1,2,2,2,2,2,1,1,1,1
endlayer

layer
1,1,1,1,1,1,1,1,1,1,1,1
1,1,1,1,1,1,1,1,1,1,1,1
1,1,2,2,2,2,2,2,2,1,1,1
1,2,2,5,5,5,5,5,2,2,1,1
2,2,5,5,5,5,6,5,5,2,2,1
2,5,5,5,5,6,5,6,5,5,2,1
2,5,5,5,6,6,6,6,6,5,2,1
2,5,6,5,6,5,5,6,5,5,2,1
2,5,5,6,6,6,5,5,6,6,2,1
2,5,5,6,6,6,6,6,6,5,2,1
2,2,5,5,6,6,6,5,5,2,2,1
1,2,2,5,5,6,5,5,2,2,1,1
1,1,2,2,2,2,2,2,2,1,1,1
1,1,1,1,2,2,2,1,1,1,1,1
1,1,1,1,1,1,1,1,1,1,1,1
endlayer

layer
1,1,1,1,0,0,0,1,1,1,1,1
1,1,0,0,0,0,0,0,0,1,1,1
1,0,7,8,9,9,9,8,7,0,1,1
1,7,7,10,12,10,11,10,7,7,0,1
7,7,12,11,0,0,0,0,0,7,7,1
8,10,11,12,0,0,0,13,0,0,8,0
14,12,10,0,0,0,13,15,13,0,14,0
14,11,0,0,16,0,0,13,0,0,14,0
14,12,0,0,0,0,0,0,0,0,14,0
8,9,8,17,0,0,0,0,0,10,8,0
7,7,0,0,0,0,0,0,12,7,7,1
1,7,7,0,0,0,0,0,7,7,0,1
1,0,7,8,18,0,18,8,7,0,1,1
1,1,0,0,0,0,0,0,0,1,1,1
1,1,1,1,0,0,0,1,1,1,1,1
endlayer

layer
1,1,0,0,0,0,0,0,0,1,1,1
1,0,0,0,0,0,0,0,0,0,1,1
0,0,19,8,18,0,18,8,19,0,0,1
0,3,7,12,11,0,0,12,7,3,0,0
21,7,10,0,0,0,0,0,0,7,20,0
8,12,0,0,0,0,0,22,0,0,8,0
18,0,0,0,0,0,22,23,22,0,18,0
0,0,0,0,0,0,0,22,0,0,0,0
18,10,0,0,0,0,0,0,0,0,18,0
8,0,8,17,0,0,0,0,0,0,8,0
21,7,0,0,0,0,0,0,11,7,20,0
0,3,7,0,0,0,0,0,7,3,0,0
0,0,24,8,18,0,18,8,24,0,0,1
1,0,0,0,0,0,0,0,0,0,1,1
1,1,0,0,0,0,0,0,0,1,1,1
endlayer

layer
1,0,0,0,0,0,0,0,0,0,1,1
0,0,0,0,0,0,0,0,0,0,0,1
0,0,0,8,18,0,18,8,0,0,0,0
0,3,7,10,0,0,0,0,7,3,0,0
0,7,12,0,0,0,0,0,0,7,0,0
8,0,0,0,0,0,0,0,0,0,8,0
18,0,0,0,0,0,0,3,0,0,18,0
0,0,0,0,0,0,0,0,0,0,0,0
18,0,0,0,0,0,0,0,0,0,18,0
8,0,8,17,0,0,0,0,0,0,8,0
0,7,0,0,0,0,0,0,0,7,0,0
0,3,7,0,0,0,0,0,7,3,0,0
0,0,0,8,18,0,18,8,0,0,0,0
0,0,0,0,0,0,0,0,0,0,0,1
1,0,0,0,0,0,0,0,0,0,1,1
endlayer

layer
0,0,0,0,0,0,0,0,0,0,0,1
0,0,0,0,0,0,0,0,0,0,0,0
0,0,0,8,18,18,18,8,0,0,0,0
0,3,21,0,0,0,0,0,20,3,0,0
0,19,0,0,0,0,0,0,0,19,0,0
8,0,0,0,0,0,0,0,0,0,8,0
18,0,0,0,0,0,0,3,0,0,18,0
18,0,0,0,0,0,0,0,0,0,18,0
18,0,0,0,0,0,0,0,0,0,18,0
8,0,8,17,0,0,0,0,0,0,8,0
0,24,0,0,0,0,0,0,0,24,0,0
0,3,21,0,0,0,0,0,20,3,0,0
0,0,0,8,18,18,18,8,0,0,0,0
0,0,0,0,0,0,0,0,0,0,0,0
0,0,0,0,0,0,0,0,0,0,0,1
endlayer

layer
0,0,0,0,0,0,0,0,0,0,0,0
0,0,0,0,0,0,0,0,0,0,0,0
0,0,0,8,25,25,25,8,0,0,0,0
0,7,26,0,0,0,0,0,26,7,0,0
0,28,7,0,0,0,0,0,7,27,0,0
8,0,0,0,0,0,0,0,0,0,8,0
25,0,0,0,0,0,0,3,0,0,25,0
25,0,0,0,0,0,0,0,0,0,25,0
25,0,0,0,0,0,0,0,0,0,25,0
8,0,8,17,0,0,0,0,0,0,8,0
0,28,7,0,0,0,0,0,7,27,0,0
0,7,29,0,0,0,0,0,29,7,0,0
0,0,0,8,18,18,18,8,0,0,0,0
0,0,0,0,0,0,0,0,0,0,0,0
0,0,0,0,0,0,0,0,0,0,0,0
endlayer

layer
0,0,0,0,0,0,0,0,0,0,0,0
0,0,0,0,0,0,0,0,0,0,0,0
0,0,0,8,9,9,9,8,0,0,0,0
0,21,19,0,30,0,30,0,19,19,0,0
0,21,7,9,9,9,9,9,7,20,0,0
8,0,14,0,0,0,0,0,14,0,8,0
14,30,14,0,0,0,0,3,14,30,14,0
14,0,14,0,0,0,0,0,14,0,14,25
14,30,14,0,0,0,0,0,14,30,14,25
8,0,14,17,0,0,0,0,14,0,8,25
0,21,7,9,9,9,9,9,7,20,0,0
0,24,24,0,30,0,30,0,24,20,0,0
0,0,0,8,9,9,9,8,0,0,0,0
0,0,0,0,0,0,0,0,0,0,0,0
0,0,0,0,0,0,0,0,0,0,0,0
endlayer

layer
0,0,0,0,0,0,0,0,0,0,0,0
0,0,0,0,0,0,0,0,0,0,0,0
0,0,0,18,18,18,18,18,0,0,0,0
0,0,0,21,19,7,19,20,0,0,0,0
0,0,7,8,31,31,31,8,7,0,0,0
18,19,8,31,31,31,31,31,8,19,18,0
18,21,31,31,31,31,31,3,31,20,18,0
18,7,31,31,31,31,31,31,31,7,18,32
18,21,31,31,31,31,31,31,31,20,18,25
18,24,8,17,31,31,31,31,8,24,18,25
0,0,7,8,31,31,31,8,7,0,0,0
0,0,0,21,24,7,24,20,0,0,0,0
0,0,0,18,18,18,18,18,0,0,0,0
0,0,0,0,0,0,0,0,0,0,0,0
0,0,0,0,0,0,0,0,0,0,0,0
endlayer

layer
0,0,0,0,0,0,0,0,0,0,0,0
0,0,0,0,0,0,0,0,0,0,0,0
0,0,0,0,0,0,0,0,0,0,0,0
0,0,0,0,0,0,0,0,0,0,0,0
0,0,7,8,9,9,9,8,7,0,0,0
0,0,8,12,10,0,0,0,8,0,0,0
0,0,14,11,0,0,0,3,14,0,0,0
0,0,14,0,0,16,0,0,14,0,0,32
0,0,14,0,0,0,0,11,14,0,0,25
0,0,8,17,0,0,0,12,8,0,0,25
0,0,7,8,9,9,9,8,7,0,0,0
0,0,0,0,0,0,0,0,0,0,0,0
0,0,0,0,0,0,0,0,0,0,0,0
0,0,0,0,0,0,0,0,0,0,0,0
0,0,0,0,0,0,0,0,0,0,0,0
endlayer

layer
0,0,0,0,0,0,0,0,0,0,0,0
0,0,0,0,0,0,0,0,0,0,0,0
0,0,0,0,0,0,0,0,0,0,0,0
0,0,0,0,0,0,0,0,0,0,0,0
0,0,18,8,0,0,0,8,18,0,0,0
0,0,8,11,0,0,0,0,8,0,0,0
0,0,0,0,0,0,0,3,0,0,0,0
0,0,0,0,0,0,0,0,0,0,0,32
0,0,0,0,0,0,0,0,0,0,0,25
0,0,8,17,0,0,0,10,8,0,0,25
0,0,18,8,0,0,0,8,18,0,0,0
0,0,0,0,0,0,0,0,0,0,0,0
0,0,0,0,0,0,0,0,0,0,0,0
0,0,0,0,0,0,0,0,0,0,0,0
0,0,0,0,0,0,0,0,0,0,0,0
endlayer

layer
0,0,0,0,0,0,0,0,0,0,0,0
0,0,0,0,0,0,0,0,0,0,0,0
0,0,0,0,0,0,0,0,0,0,0,0
0,0,0,0,0,0,0,0,0,0,0,0
0,0,18,8,0,0,0,8,18,0,0,0
0,0,8,12,0,0,0,0,8,0,0,0
0,0,0,0,0,0,0,3,0,0,0,0
0,0,0,0,0,0,0,0,0,0,0,32
0,0,0,0,0,0,0,0,0,0,0,25
0,0,8,17,0,0,0,0,8,0,0,25
0,0,18,8,0,0,0,8,18,0,0,0
0,0,0,0,0,0,0,0,0,0,0,0
0,0,0,0,0,0,0,0,0,0,0,0
0,0,0,0,0,0,0,0,0,0,0,0
0,0,0,0,0,0,0,0,0,0,0,0
endlayer

layer
0,0,0,0,0,0,0,0,0,0,0,25
0,0,0,0,0,0,0,0,0,0,0,25
0,0,0,0,0,0,0,0,0,0,0,25
0,0,0,0,0,0,0,0,0,0,0,25
0,0,18,8,25,25,25,8,18,0,0,25
0,0,8,0,0,0,0,0,8,0,0,25
0,0,25,0,0,0,0,3,25,0,0,25
0,0,25,0,0,0,0,0,25,0,0,31
0,0,25,0,0,0,0,0,25,0,0,25
0,0,8,17,0,0,0,0,8,0,0,25
0,0,18,8,25,25,25,8,18,0,0,0
0,0,0,0,0,0,0,0,0,0,0,0
0,0,0,0,0,0,0,0,0,0,0,0
0,0,0,0,0,0,0,0,0,0,0,0
0,0,0,0,0,0,0,0,0,0,0,0
endlayer

layer
0,0,0,0,0,0,0,0,0,0,0,25
0,0,0,0,0,0,0,0,0,0,0,25
0,0,0,0,0,0,0,0,0,0,0,25
0,0,0,0,0,0,0,0,0,0,0,25
0,0,18,8,9,9,9,8,18,0,0,25
0,0,8,0,0,0,0,0,8,0,0,25
0,0,14,0,0,0,0,3,14,0,0,25
0,0,14,0,0,0,0,0,14,0,0,31
0,0,14,33,33,33,33,33,14,0,0,25
0,0,8,17,33,33,33,33,8,0,0,25
0,0,18,8,9,9,9,8,18,0,0,0
0,0,0,0,0,0,0,0,0,0,0,0
0,0,0,0,0,0,0,0,0,0,0,0
0,0,0,0,0,0,0,0,0,0,0,0
0,0,0,0,0,0,0,0,0,0,0,0
endlayer

layer
0,0,0,0,0,0,0,0,0,0,0,0
0,0,0,0,0,0,0,0,0,0,0,34
0,0,0,0,0,0,0,0,0,0,0,34
0,0,0,35,0,0,0,35,0,0,0,34
0,0,35,8,18,18,18,8,36,0,0,34
0,36,8,0,0,0,0,0,8,36,0,31
0,0,26,0,0,0,0,3,26,0,0,31
0,9,9,9,9,9,9,9,9,9,9,9
0,0,29,0,0,16,0,0,29,0,0,31
0,36,8,17,0,0,0,0,8,36,0,31
0,0,35,8,18,18,18,8,36,0,0,37
0,0,0,35,0,0,0,35,0,0,0,37
0,0,0,0,0,0,0,0,0,0,0,37
0,0,0,0,0,0,0,0,0,0,0,37
0,0,0,0,0,0,0,0,0,0,0,0
endlayer

layer
0,0,0,0,0,0,0,0,0,0,0,0
0,0,0,0,0,0,0,0,0,0,0,0
0,0,0,0,0,0,0,0,0,0,0,0
0,0,0,35,35,35,35,35,0,0,0,0
0,0,36,8,9,9,9,8,35,0,0,0
0,36,8,0,0,0,0,26,8,36,0,25
0,36,14,0,0,0,28,3,14,36,0,25
0,36,14,0,0,0,0,29,14,36,0,31
0,36,14,0,0,0,0,0,14,36,0,25
0,36,8,0,0,0,0,0,8,36,0,25
0,0,36,8,9,9,9,8,36,0,0,25
0,0,0,35,35,35,35,35,0,0,0,25
0,0,0,0,0,0,0,0,0,0,0,25
0,0,0,0,0,0,0,0,0,0,0,25
0,0,0,0,0,0,0,0,0,0,0,25
endlayer

layer
0,0,0,0,0,0,0,0,0,0,0,0
0,0,0,0,0,0,0,0,0,0,0,0
0,0,0,0,0,0,0,0,0,0,0,0
0,0,0,0,0,35,0,0,0,0,0,0
0,0,0,35,35,35,35,35,0,0,0,0
0,0,36,0,0,0,0,0,36,0,0,25
0,0,36,0,0,0,0,0,36,0,0,25
0,36,36,0,0,0,0,0,36,36,0,31
0,0,36,0,0,0,0,0,36,0,0,25
0,0,36,0,0,0,0,0,36,0,0,25
0,0,0,35,35,35,35,35,0,0,0,25
0,0,0,0,0,35,0,0,0,0,0,25
0,0,0,0,0,0,0,0,0,0,0,25
0,0,0,0,0,0,0,0,0,0,0,25
0,0,0,0,0,0,0,0,0,0,0,25
endlayer

layer
0,0,0,0,0,0,0,0,0,0,0,0
0,0,0,0,0,0,0,0,0,0,0,0
0,0,0,0,0,0,0,0,0,0,0,0
0,0,0,0,0,0,0,0,0,0,0,0
0,0,0,0,35,35,35,0,0,0,0,0
0,0,0,35,15,0,15,36,0,0,0,25
0,0,36,15,0,0,0,15,36,0,0,25
0,0,36,0,0,0,0,0,36,0,0,38
0,0,36,15,0,0,0,15,36,0,0,0
0,0,0,35,15,0,15,36,0,0,0,0
0,0,0,0,35,35,35,0,0,0,0,0
0,0,0,0,0,0,0,0,0,0,0,0
0,0,0,0,0,0,0,0,0,0,0,0
0,0,0,0,0,0,0,0,0,0,0,0
0,0,0,0,0,0,0,0,0,0,0,0
endlayer

layer
0,0,0,0,0,0,0,0,0,0,0,0
0,0,0,0,0,0,0,0,0,0,0,0
0,0,0,0,0,0,0,0,0,0,0,0
0,0,0,0,0,0,0,0,0,0,0,0
0,0,0,0,0,0,0,0,0,0,0,0
0,0,0,0,0,35,0,0,0,0,0,25
0,0,0,0,15,15,15,0,0,0,0,25
0,0,0,36,15,15,15,36,0,0,0,38
0,0,0,0,15,15,15,0,0,0,0,0
0,0,0,0,0,35,0,0,0,0,0,0
0,0,0,0,0,0,0,0,0,0,0,0
0,0,0,0,0,0,0,0,0,0,0,0
0,0,0,0,0,0,0,0,0,0,0,0
0,0,0,0,0,0,0,0,0,0,0,0
0,0,0,0,0,0,0,0,0,0,0,0
endlayer

layer
0,0,0,0,0,0,0,0,0,0,0,0
0,0,0,0,0,0,0,0,0,0,0,0
0,0,0,0,0,0,0,0,0,0,0,0
0,0,0,0,0,0,0,0,0,0,0,0
0,0,0,0,0,0,0,0,0,0,0,0
0,0,0,0,0,0,0,0,0,0,0,25
0,0,0,0,0,0,0,0,0,0,0,25
0,0,0,0,0,0,0,0,0,0,0,38
0,0,0,0,0,0,0,0,0,0,0,0
0,0,0,0,0,0,0,0,0,0,0,0
0,0,0,0,0,0,0,0,0,0,0,0
0,0,0,0,0,0,0,0,0,0,0,0
0,0,0,0,0,0,0,0,0,0,0,0
0,0,0,0,0,0,0,0,0,0,0,0
0,0,0,0,0,0,0,0,0,0,0,0
endlayer

layer
0,0,0,0,0,0,0,0,0,0,0,0
0,0,0,0,0,0,0,0,0,0,0,0
0,0,0,0,0,0,0,0,0,0,0,0
0,0,0,0,0,0,0,0,0,0,0,0
0,0,0,0,0,0,0,0,0,0,0,0
0,0,0,0,0,0,0,0,0,0,0,25
0,0,0,0,0,0,0,0,0,0,0,25
0,0,0,0,0,0,0,0,0,0,0,38
0,0,0,0,0,0,0,0,0,0,0,0
0,0,0,0,0,0,0,0,0,0,0,0
0,0,0,0,0,0,0,0,0,0,0,0
0,0,0,0,0,0,0,0,0,0,0,0
0,0,0,0,0,0,0,0,0,0,0,0
0,0,0,0,0,0,0,0,0,0,0,0
0,0,0,0,0,0,0,0,0,0,0,0
endlayer

layer
0,0,0,0,0,0,0,0,0,0,0,0
0,0,0,0,0,0,0,0,0,0,0,0
0,0,0,0,0,0,0,0,0,0,0,0
0,0,0,0,0,0,0,0,0,0,0,0
0,0,0,0,0,0,0,0,0,0,0,0
0,0,0,0,0,0,0,0,0,0,0,25
0,0,0,0,0,0,0,0,0,0,0,25
0,0,0,0,0,0,0,0,0,0,0,25
0,0,0,0,0,0,0,0,0,0,0,0
0,0,0,0,0,0,0,0,0,0,0,0
0,0,0,0,0,0,0,0,0,0,0,0
0,0,0,0,0,0,0,0,0,0,0,0
0,0,0,0,0,0,0,0,0,0,0,0
0,0,0,0,0,0,0,0,0,0,0,0
0,0,0,0,0,0,0,0,0,0,0,0
endlayer

