
# Created by Ruins mod version 16.7 Ingame Parser
# authoring Player: lafuller

weight=1
embed_into_distance=8
acceptable_target_blocks=
unacceptable_target_blocks=flowing_water,water,flowing_lava,lava
dimensions=20,11,11
allowable_overhang=0
max_leveling=24
leveling_buffer=-1
preserve_water=0
preserve_lava=0
preventRotation=1

rule1=0,100,stonebrick-0,stonebrick-0,stonebrick-0,stonebrick-0,stonebrick-1,stonebrick-2,stonebrick-2,stone-5,stone-6,cobblestone,stone_brick_stairs-0,stone_brick_stairs-1,stone_brick_stairs-2,stone_brick_stairs-3,stone_brick_stairs-4,stone_brick_stairs-5,stone_brick_stairs-6,stone_brick_stairs-7
rule2=0,100,preserveBlock
rule3=0,100,minecraft:stone_slab-13
rule4=0,100,minecraft:stone_slab-5
rule5=0,100,minecraft:stone_brick_stairs-2
rule6=0,100,minecraft:stone_brick_stairs-1

layer
2,2,2,2,2,2,2,2,2,2,1
2,2,2,2,1,1,2,2,2,2,2
2,2,2,2,2,1,1,2,2,2,2
2,2,2,2,2,2,1,1,1,2,2
2,1,2,2,2,2,2,1,1,1,2
2,1,1,2,2,2,2,2,1,1,2
2,2,1,1,2,2,2,2,2,2,2
2,2,2,1,1,2,2,2,2,2,2
2,2,2,1,1,1,2,2,2,2,2
2,2,2,2,1,1,2,2,2,2,2
1,2,2,2,2,2,2,2,2,2,2
endlayer

layer
2,2,2,2,2,2,2,2,2,2,1
2,2,2,2,1,1,2,2,2,2,2
2,2,2,2,2,1,1,2,2,2,2
2,2,2,2,2,2,1,1,1,2,2
2,1,2,2,2,2,2,1,1,1,2
2,1,1,2,2,2,2,2,1,1,2
2,2,1,1,2,2,2,2,2,2,2
2,2,2,1,1,2,2,2,2,2,2
2,2,2,1,1,1,2,2,2,2,2
2,2,2,2,1,1,2,2,2,2,2
1,2,2,2,2,2,2,2,2,2,2
endlayer

layer
2,2,2,2,2,2,2,2,2,2,1
2,2,2,2,1,1,2,2,2,2,2
2,2,2,2,2,1,1,2,2,2,2
2,2,2,2,2,2,1,1,1,2,2
2,1,2,2,2,2,2,1,1,1,2
2,1,1,2,2,2,2,2,1,1,2
2,2,1,1,2,2,2,2,2,2,2
2,2,2,1,1,2,2,2,2,2,2
2,2,2,1,1,1,2,2,2,2,2
2,2,2,2,1,1,2,2,2,2,2
1,2,2,2,2,2,2,2,2,2,2
endlayer

layer
2,2,2,2,2,2,2,2,2,2,1
2,2,2,2,1,1,2,2,2,2,2
2,2,2,2,2,1,1,2,2,2,2
2,2,2,2,2,2,1,1,1,2,2
2,1,2,2,2,2,2,1,1,1,2
2,1,1,2,2,2,2,2,1,1,2
2,2,1,1,2,2,2,2,2,2,2
2,2,2,1,1,2,2,2,2,2,2
2,2,2,1,1,1,2,2,2,2,2
2,2,2,2,1,1,2,2,2,2,2
1,2,2,2,2,2,2,2,2,2,2
endlayer

layer
2,2,2,2,2,2,2,2,2,2,1
2,2,2,2,1,1,2,2,2,2,2
2,2,2,2,2,1,1,2,2,2,2
2,2,2,2,2,2,1,1,1,2,2
2,1,2,2,2,2,2,1,1,1,2
2,1,1,2,2,2,2,2,1,1,2
2,2,1,1,2,2,2,2,2,2,2
2,2,2,1,1,2,2,2,2,2,2
2,2,2,1,1,1,2,2,2,2,2
2,2,2,2,1,1,2,2,2,2,2
1,2,2,2,2,2,2,2,2,2,2
endlayer

layer
2,2,2,2,2,2,2,2,2,2,1
2,2,2,2,2,1,2,2,2,2,2
2,2,2,2,2,1,1,2,2,2,2
2,2,2,2,2,2,1,1,1,2,2
2,2,2,2,2,2,2,1,1,1,2
2,1,1,2,2,2,2,2,1,1,2
2,2,1,1,2,2,2,2,2,2,2
2,2,2,1,1,2,2,2,2,2,2
2,2,2,1,1,1,2,2,2,2,2
2,2,2,2,1,1,2,2,2,2,2
1,2,2,2,2,2,2,2,2,2,2
endlayer

layer
2,2,2,2,2,2,2,2,2,2,1
2,2,2,2,2,2,2,2,2,2,2
2,2,2,2,2,2,1,2,2,2,2
2,2,2,2,2,2,1,1,1,2,2
2,2,2,2,2,2,2,1,1,1,2
2,2,2,2,2,2,2,2,1,1,2
2,2,1,1,2,2,2,2,2,2,2
2,2,2,1,1,2,2,2,2,2,2
2,2,2,1,1,1,2,2,2,2,2
2,2,2,2,1,1,2,2,2,2,2
1,2,2,2,2,2,2,2,2,2,2
endlayer

layer
2,2,2,2,2,2,2,2,2,2,1
2,2,2,2,2,2,2,2,2,2,2
2,2,2,2,2,2,2,2,2,2,2
2,2,2,2,2,2,1,1,1,2,2
2,2,2,2,2,2,2,1,1,1,2
2,2,2,2,2,2,2,2,1,1,2
2,2,2,1,2,2,2,2,2,2,2
2,2,2,1,1,2,2,2,2,2,2
2,2,2,1,1,1,2,2,2,2,2
2,2,2,2,1,1,2,2,2,2,2
1,2,2,2,2,2,2,2,2,2,2
endlayer

layer
2,2,2,2,2,2,2,2,2,2,1
2,2,2,2,2,2,2,2,2,2,2
2,2,2,2,2,2,2,2,2,2,2
2,2,2,2,2,2,2,1,1,2,2
2,2,2,2,2,2,2,1,1,1,2
2,2,2,2,2,2,2,2,1,1,2
2,2,2,2,2,2,2,2,2,2,2
2,2,2,1,1,2,2,2,2,2,2
2,2,2,1,1,1,2,2,2,2,2
2,2,2,2,1,1,2,2,2,2,2
1,2,2,2,2,2,2,2,2,2,2
endlayer

layer
2,2,2,2,2,2,2,2,2,2,1
2,2,2,2,2,2,2,2,2,2,2
2,2,2,2,2,2,2,2,2,2,2
2,2,2,2,2,2,2,1,1,2,2
2,2,2,2,2,2,2,1,1,1,2
2,2,2,2,2,2,2,2,1,1,2
2,2,2,2,2,2,2,2,2,2,2
2,2,2,1,1,2,2,2,2,2,2
2,2,2,1,1,1,2,2,2,2,2
2,2,2,2,1,1,2,2,2,2,2
1,2,2,2,2,2,2,2,2,2,2
endlayer

layer
2,2,2,2,2,2,2,2,2,2,1
2,2,2,2,2,2,2,2,2,2,2
2,2,2,2,2,2,2,2,2,2,2
2,2,2,2,2,2,2,1,1,2,2
2,2,2,2,2,2,2,1,1,1,2
2,2,2,2,2,2,2,2,1,1,2
2,2,2,2,2,2,2,2,2,2,2
2,2,2,1,1,2,2,2,2,2,2
2,2,2,1,1,1,2,2,2,2,2
2,2,2,2,1,1,2,2,2,2,2
1,2,2,2,2,2,2,2,2,2,2
endlayer

layer
2,2,2,2,2,2,2,2,2,2,1
2,2,2,2,2,2,2,2,2,2,2
2,2,2,2,2,2,2,2,2,2,2
2,2,2,2,2,2,2,1,1,2,2
2,2,2,2,2,2,2,1,1,1,2
2,2,2,2,2,2,2,2,1,1,2
2,2,2,2,2,2,2,2,2,2,2
2,2,2,1,1,2,2,2,2,2,2
2,2,2,1,1,1,2,2,2,2,2
2,2,2,2,1,1,2,2,2,2,2
1,2,2,2,2,2,2,2,2,2,2
endlayer

layer
2,2,2,2,2,2,2,2,2,2,1
2,2,2,2,2,2,2,2,2,2,2
2,2,2,2,2,2,2,2,2,2,2
2,2,2,2,2,2,2,1,1,2,2
2,2,2,2,2,2,2,1,1,1,2
2,2,2,2,2,2,2,2,1,1,2
2,2,2,2,2,2,2,2,2,2,2
2,2,2,1,1,2,2,2,2,2,2
2,2,2,1,1,1,2,2,2,2,2
2,2,2,2,1,1,2,2,2,2,2
1,2,2,2,2,2,2,2,2,2,2
endlayer

layer
2,2,2,2,2,2,2,2,3,1,1
2,2,2,2,2,2,2,3,1,1,1
2,2,2,2,2,2,2,3,1,1,1
2,2,2,2,2,2,3,1,1,1,3
2,2,2,2,2,3,1,1,1,1,2
2,2,2,2,3,1,1,1,1,1,2
2,2,2,3,1,1,1,1,3,2,2
2,2,3,1,1,1,1,3,2,2,2
3,3,1,1,1,1,3,2,2,2,2
1,1,1,1,1,1,2,2,2,2,2
1,1,1,3,2,2,2,2,2,2,2
endlayer

layer
2,2,2,2,2,2,2,2,2,2,1
2,2,2,2,2,2,2,2,2,2,2
2,2,2,2,2,2,2,2,2,2,2
2,2,2,2,2,2,2,1,2,2,2
2,2,2,2,2,2,2,2,1,1,2
2,2,2,2,2,2,2,2,1,1,2
2,2,2,2,2,2,2,2,2,2,2
2,2,2,1,2,2,2,2,2,2,2
2,2,2,2,1,1,2,2,2,2,2
2,2,2,2,1,1,2,2,2,2,2
1,2,2,2,2,2,2,2,2,2,2
endlayer

layer
2,2,2,2,2,2,2,2,2,2,1
2,2,2,2,2,2,2,2,2,2,2
2,2,2,2,2,2,2,2,2,2,2
2,2,2,2,2,2,2,1,2,2,2
2,2,2,2,2,2,2,2,1,1,2
2,2,2,2,2,2,2,2,1,1,2
2,2,2,2,2,2,2,2,2,2,2
2,2,2,1,2,2,2,2,2,2,2
2,2,2,2,1,1,2,2,2,2,2
2,2,2,2,1,1,2,2,2,2,2
1,2,2,2,2,2,2,2,2,2,2
endlayer

layer
2,2,2,2,2,2,2,2,2,2,1
2,2,2,2,2,2,2,2,2,2,2
2,2,2,2,2,2,2,2,2,2,2
2,2,2,2,2,2,2,1,2,2,2
2,2,2,2,2,2,2,2,1,1,2
2,2,2,2,2,2,2,2,1,1,2
2,2,2,2,2,2,2,2,2,2,2
2,2,2,1,2,2,2,2,2,2,2
2,2,2,2,1,1,2,2,2,2,2
2,2,2,2,1,1,2,2,2,2,2
1,2,2,2,2,2,2,2,2,2,2
endlayer

layer
2,2,2,2,2,2,2,2,2,2,1
2,2,2,2,2,2,2,2,2,2,2
2,2,2,2,2,2,2,2,2,2,2
2,2,2,2,2,2,2,1,2,2,2
2,2,2,2,2,2,2,2,1,1,2
2,2,2,2,2,2,2,2,1,1,2
2,2,2,2,2,2,2,2,2,2,2
2,2,2,1,2,2,2,2,2,2,2
2,2,2,2,1,1,2,2,2,2,2
2,2,2,2,1,1,2,2,2,2,2
1,2,2,2,2,2,2,2,2,2,2
endlayer

layer
2,2,2,2,2,2,2,2,1,1,1
2,2,2,2,2,2,2,1,1,1,1
2,2,2,2,2,2,2,1,1,1,1
2,2,2,2,2,2,1,1,1,1,1
2,2,2,2,2,1,1,1,1,1,2
2,2,2,2,1,1,1,1,1,1,2
2,2,2,1,1,1,1,1,1,2,2
2,2,1,1,1,1,1,1,2,2,2
1,1,1,1,1,1,1,2,2,2,2
1,1,1,1,1,1,2,2,2,2,2
1,1,1,1,2,2,2,2,2,2,2
endlayer

layer
2,2,2,2,2,2,4,4,2,2,1
2,2,2,2,2,2,4,2,2,2,2
2,2,2,2,2,4,4,2,2,2,2
2,2,2,2,4,4,1,1,1,2,2
2,2,2,4,4,2,2,1,1,2,2
2,2,4,4,2,2,2,2,2,2,2
2,4,4,1,2,2,2,2,2,2,2
4,4,2,1,1,2,2,2,2,2,2
2,2,2,1,1,2,2,2,2,2,2
2,2,2,2,2,2,2,2,2,2,2
1,2,2,2,2,2,2,2,2,2,2
endlayer

layer
2,2,2,2,2,2,2,2,2,2,1
2,2,2,2,2,2,2,2,2,2,2
2,2,2,2,2,2,2,2,2,2,2
2,2,2,2,2,2,1,1,1,2,2
2,2,2,2,2,2,2,1,1,2,2
2,2,2,2,2,2,2,2,2,2,2
2,2,2,1,2,2,2,2,2,2,2
2,2,2,1,1,2,2,2,2,2,2
2,2,2,1,1,2,2,2,2,2,2
2,2,2,2,2,2,2,2,2,2,2
1,2,2,2,2,2,2,2,2,2,2
endlayer

layer
2,2,2,2,2,2,2,2,2,2,1
2,2,2,2,2,2,2,2,2,2,2
2,2,2,2,2,2,2,2,2,2,2
2,2,2,2,2,2,1,1,1,2,2
2,2,2,2,2,2,2,1,1,2,2
2,2,2,2,2,2,2,2,2,2,2
2,2,2,1,2,2,2,2,2,2,2
2,2,2,1,1,2,2,2,2,2,2
2,2,2,1,1,2,2,2,2,2,2
2,2,2,2,2,2,2,2,2,2,2
1,2,2,2,2,2,2,2,2,2,2
endlayer

layer
2,2,2,2,2,3,1,1,1,1,1
2,2,2,2,2,3,1,1,1,1,2
2,2,2,2,3,1,1,1,1,2,2
2,2,2,3,1,1,1,1,1,2,2
2,2,3,1,1,1,1,1,5,2,2
2,3,1,1,1,1,1,2,2,2,2
3,1,1,1,1,1,2,2,2,2,2
1,1,1,1,1,2,2,2,2,2,2
1,1,1,1,6,2,2,2,2,2,2
1,1,2,2,2,2,2,2,2,2,2
1,2,2,2,2,2,2,2,2,2,2
endlayer

layer
2,2,2,2,2,2,2,2,2,2,1
2,2,2,2,2,2,2,2,2,2,2
2,2,2,2,2,1,1,2,2,2,2
2,2,2,2,2,2,1,1,2,2,2
2,2,2,2,2,2,2,1,2,2,2
2,2,1,2,2,2,2,2,2,2,2
2,2,1,1,2,2,2,2,2,2,2
2,2,2,1,1,2,2,2,2,2,2
2,2,2,2,2,2,2,2,2,2,2
2,2,2,2,2,2,2,2,2,2,2
1,2,2,2,2,2,2,2,2,2,2
endlayer

