
# Created by Ruins mod version 16.7 Ingame Parser
# authoring Player: lafuller

weight=1
embed_into_distance=4
acceptable_target_blocks=
unacceptable_target_blocks=flowing_water,water,flowing_lava,lava,ice,bedrock,netherrack,nether_brick,nether_brick_fence,soul_sand,quartz_ore,end_stone,obsidian,iron_bars,cloud,flesh,ash_block,slime_grass,slime_congealed,slime_dirt
biomesToSpawnIn=plains,forest,prarie,meadow,tundra,brushland,shrubland,woodland,woodlands,birch_forestlavender_fields,flower_field,sunflower_plains,ice_flats,ice_plains
dimensions=18,16,17
allowable_overhang=0
max_leveling=4
leveling_buffer=-4
preserve_water=0
preserve_lava=0

rule1=0,100,preserveBlock
rule2=0,100,minecraft:stone-6
rule3=0,100,stonebrick-0,stonebrick-0,stonebrick-0,stonebrick-0,stonebrick-1,stonebrick-2,stonebrick-2,stone-5,stone-6,cobblestone
rule4=0,100,stonebrick-0,stonebrick-2,stonebrick-1,stonebrick-1,stonebrick-1,cobblestone
rule5=0,100,stonebrick-0,stonebrick-1,stonebrick-2,stonebrick-2,stone-5,stone-5,stone-6,stone-6
rule6=0,100,stonebrick-0,stonebrick-2,stonebrick-0,stonebrick-1,stonebrick-1,cobblestone
rule7=0,100,minecraft:stone_brick_stairs-0
rule8=0,100,minecraft:stone_brick_stairs-3
rule9=0,100,minecraft:stone-5
rule10=0,100,minecraft:cobblestone_wall-0
rule11=0,100,stonebrick-0,stonebrick-0,stonebrick-0,stonebrick-0,stonebrick-1,stonebrick-2,stonebrick-2,stone-5,stone-6,cobblestone,gravel
rule12=0,100,minecraft:planks-1
rule13=0,100,minecraft:spruce_stairs-1
rule14=0,100,bookshelf,hay_block,ChestGenHook:chests/spawn_bonus_chest:5-5,ChestGenHook:chests/village_blacksmith:5-5,ChestGenHook:chests/simple_dungeon:5-5,ChestGenHook:chests/abandoned_mineshaft:5-5,ChestGenHook:chests/stronghold_library:5-5,ChestGenHook:chests/stronghold_corridor:5-5,ChestGenHook:chests/stronghold_crossing:5-5,ChestGenHook:chests/igloo_chest:5-5
rule15=0,100,minecraft:log-0
rule16=0,100,minecraft:wooden_slab-9
rule17=0,100,air
rule18=0,100,minecraft:web-0,air,air,air
rule19=0,100,minecraft:stone_brick_stairs-2
rule20=0,100,minecraft:log2-1
rule21=0,100,minecraft:stone_brick_stairs-7
rule22=0,100,minecraft:stone_brick_stairs-6
rule23=0,100,minecraft:oak_stairs-2
rule24=0,100,minecraft:planks-0
rule25=0,100,minecraft:spruce_stairs-2
rule26=0,100,minecraft:oak_stairs-5
rule27=0,100,minecraft:stone_brick_stairs-4
rule28=0,100,minecraft:oak_stairs-0
rule29=0,100,minecraft:spruce_stairs-0
rule30=0,100,minecraft:stone_brick_stairs-1
rule31=0,100,minecraft:fence-0
rule32=0,100,minecraft:oak_stairs-7
rule33=0,100,minecraft:oak_stairs-1
rule34=0,100,minecraft:trapdoor-8
rule35=0,100,minecraft:oak_stairs-3
rule36=0,100,minecraft:spruce_stairs-3
rule37=0,100,minecraft:spruce_stairs-5
rule38=0,100,minecraft:spruce_stairs-6
rule39=0,100,minecraft:spruce_fence_gate-6
rule40=0,100,minecraft:spruce_fence_gate-2
rule41=0,100,minecraft:spruce_fence-0
rule42=0,100,minecraft:spruce_fence_gate-3
rule43=0,100,minecraft:jungle_door-2
rule44=0,100,minecraft:spruce_fence_gate-7
rule45=0,100,minecraft:oak_stairs-4
rule46=0,100,minecraft:furnace-2
rule47=0,100,minecraft:oak_stairs-6
rule48=0,100,minecraft:spruce_stairs-4
rule49=0,100,minecraft:carpet-7
rule50=0,100,minecraft:jungle_door-9
rule51=0,100,minecraft:jungle_door-8
rule52=0,100,minecraft:wooden_slab-13
rule53=0,100,minecraft:dark_oak_stairs-7
rule54=0,100,minecraft:wooden_slab-0
rule55=0,100,minecraft:planks-5
rule56=0,100,minecraft:ladder-5
rule57=0,100,minecraft:spruce_stairs-7
rule58=0,100,minecraft:ladder-2
rule59=0,100,minecraft:dark_oak_stairs-0
rule60=0,100,minecraft:bookshelf-0
rule61=0,100,minecraft:dark_oak_stairs-1
rule62=0,100,minecraft:dark_oak_stairs-2
rule63=0,100,minecraft:spruce_fence_gate-1
rule64=0,100,minecraft:dark_oak_stairs-3
rule65=0,100,minecraft:wooden_slab-5
rule66=0,100,minecraft:stone_brick_stairs-5
rule67=0,100,minecraft:dark_oak_stairs-5
rule68=0,100,minecraft:dark_oak_stairs-4
rule69=0,100,minecraft:trapdoor-12
rule70=0,100,minecraft:log-11
rule71=0,100,minecraft:trapdoor-13
rule72=0,100,minecraft:log-7
rule73=0,100,minecraft:spruce_fence_gate-5
rule74=0,100,minecraft:dark_oak_fence-0
rule75=0,100,minecraft:jungle_door-1
rule76=0,100,minecraft:spruce_fence_gate-4
rule77=0,100,minecraft:carpet-8
rule78=0,100,minecraft:dark_oak_stairs-6
rule79=0,100,minecraft:spruce_fence_gate-0

layer
1,1,1,1,1,1,1,1,1,1,1,1,1,1,1,1,1
1,1,1,1,1,1,3,3,3,3,3,2,1,1,1,1,1
1,1,3,3,3,2,4,4,4,4,4,4,3,1,1,1,1
1,2,4,4,4,4,4,4,4,4,4,4,3,1,1,1,1
1,3,4,5,5,5,4,5,4,4,4,4,3,1,1,1,1
1,3,4,5,6,6,5,5,4,4,5,4,3,1,1,1,1
1,3,4,5,5,6,6,5,5,4,5,5,2,3,3,1,1
1,1,2,4,4,5,5,6,6,5,6,5,5,4,4,3,1
1,1,3,4,5,5,6,6,5,5,6,6,6,5,4,3,1
1,1,3,4,5,6,6,5,6,6,5,6,6,5,4,3,1
1,1,2,4,5,5,6,6,5,5,4,5,5,5,4,3,1
1,1,3,4,5,6,6,6,5,4,4,4,4,4,4,3,7
1,1,3,4,4,5,5,5,4,3,3,3,3,3,3,3,3
1,1,3,4,4,4,4,4,4,3,3,3,3,3,3,3,3
1,1,1,3,3,3,3,3,3,3,3,3,3,3,3,3,3
1,1,1,8,2,1,1,2,1,1,2,1,1,2,1,1,2
endlayer

layer
1,1,1,1,1,1,1,1,1,1,1,1,1,1,1,1,1
1,1,1,1,1,1,11,10,11,11,10,9,1,1,1,1,1
1,1,11,11,10,9,12,12,12,12,12,12,11,1,1,1,1
1,9,15,16,16,16,15,14,12,12,13,13,10,1,1,1,1
1,11,16,17,17,17,17,17,17,15,17,17,11,1,1,1,1
1,10,16,17,17,17,17,17,17,17,17,17,11,1,1,1,1
1,11,15,17,17,17,17,17,17,17,17,17,9,11,11,1,1
1,1,9,18,17,17,17,17,17,17,17,17,17,18,15,11,1
1,1,11,15,12,12,12,17,17,17,17,17,17,17,16,10,1
1,1,10,16,17,17,17,17,17,17,17,17,17,17,16,11,1
1,1,9,16,17,17,17,17,17,17,17,17,17,17,16,10,1
1,1,11,16,17,17,17,17,17,15,17,17,17,17,15,11,1
1,1,10,16,17,17,17,17,18,11,18,17,17,18,11,11,7
1,1,11,15,16,16,16,16,15,11,20,17,17,20,11,11,19
1,1,1,11,11,11,11,11,11,11,11,10,10,11,11,11,19
1,1,1,1,8,22,1,11,1,1,11,1,1,11,1,21,19
endlayer

layer
1,1,1,1,1,1,1,1,1,1,1,1,1,1,1,1,1
1,1,1,1,1,1,11,10,11,11,10,2,1,1,1,1,1
1,1,11,11,10,2,24,24,24,23,17,17,11,1,1,1,1
1,2,15,18,17,18,15,26,24,25,17,17,10,1,1,1,1
1,11,18,17,17,17,18,17,17,15,17,17,11,1,1,1,1
1,10,18,17,17,17,17,17,17,17,17,17,11,1,1,1,1
1,11,15,18,17,17,17,17,17,17,17,17,2,11,11,1,1
1,1,2,18,17,17,17,17,17,17,17,17,17,18,15,11,1
1,1,11,15,17,17,17,17,17,17,17,17,17,17,18,10,1
1,1,10,18,17,17,17,17,17,17,17,17,17,17,17,11,1
1,1,2,17,17,17,17,17,17,17,17,17,17,17,18,10,1
1,1,11,17,17,17,17,17,18,15,17,17,17,17,15,11,1
1,1,10,18,17,17,17,17,18,11,18,17,17,18,11,19,1
1,1,11,15,18,17,17,18,15,11,20,18,18,20,11,19,1
1,1,1,11,11,11,11,11,11,11,11,10,10,11,11,19,1
1,1,1,1,1,8,11,11,22,21,11,1,1,11,11,19,1
endlayer

layer
1,1,1,1,1,1,1,1,1,1,1,1,1,1,1,1,1
1,1,1,1,1,1,11,10,11,11,10,9,1,1,1,1,1
1,1,11,11,10,9,24,24,23,17,17,17,11,1,1,1,1
1,9,15,18,18,17,15,12,25,17,17,17,10,1,1,1,1
1,11,18,18,17,18,18,18,17,15,17,17,11,1,1,1,1
1,10,18,17,17,17,18,17,17,17,17,17,11,1,1,1,1
1,11,15,18,17,17,17,17,17,17,17,17,9,11,11,1,1
1,1,9,18,18,17,17,17,17,17,17,17,18,18,15,11,1
1,1,11,15,16,16,16,17,17,17,17,17,17,18,18,10,1
1,1,10,18,18,17,17,17,17,17,17,17,17,17,18,11,1
1,1,9,18,17,17,17,17,17,18,17,17,17,18,18,10,1
1,1,11,18,18,17,17,18,18,15,18,17,17,18,15,11,1
1,1,10,18,18,18,17,18,18,11,18,18,18,18,11,1,1
1,1,11,15,17,18,18,18,15,11,20,18,18,20,19,1,1
1,1,1,11,11,11,11,11,11,11,11,27,27,11,19,1,1
1,1,1,1,1,1,8,11,11,11,11,22,21,11,19,1,1
endlayer

layer
1,1,1,1,1,1,1,1,1,1,1,1,1,1,1,1,1
1,1,1,1,1,1,11,11,11,11,11,2,1,1,1,1,1
1,1,11,11,11,2,25,17,17,17,17,17,11,1,1,1,1
1,2,24,24,24,24,25,17,17,17,17,17,11,1,1,1,1
1,11,12,12,12,12,28,29,28,15,16,16,11,1,1,1,1
1,11,12,24,24,24,12,12,24,24,12,24,11,1,1,1,1
1,11,12,12,12,24,24,12,12,24,12,12,2,11,1,1,1
1,1,2,24,24,12,12,24,24,12,24,12,12,24,2,11,1
1,1,11,24,12,12,24,24,12,12,24,24,24,12,24,11,1
1,1,11,24,12,24,24,12,24,24,12,24,24,12,24,11,1
1,1,2,24,12,12,24,24,12,12,24,12,12,12,24,11,1
1,1,11,24,12,24,24,24,12,24,24,24,24,24,15,11,1
1,1,11,24,24,12,12,12,24,24,11,24,24,11,11,1,1
1,1,11,15,24,24,24,24,15,11,11,11,11,19,1,1,1
1,1,1,11,11,11,11,11,11,11,11,11,11,19,1,1,1
1,1,1,1,1,1,1,1,1,1,8,30,30,19,1,1,1
endlayer

layer
1,1,1,1,1,1,1,1,1,1,1,1,1,1,1,1,1
1,1,1,1,1,31,28,28,28,28,28,15,1,1,1,1,1
1,1,27,28,28,15,17,17,17,17,17,32,31,1,1,1,1
1,15,11,9,9,17,17,17,17,17,17,32,33,1,1,1,1
1,35,34,17,17,17,17,17,17,15,24,24,23,1,1,1,1
1,35,9,17,17,17,17,17,17,36,13,33,28,1,1,1,1
1,35,9,17,17,17,17,17,17,17,17,17,15,28,1,1,1
1,31,15,16,16,38,17,17,17,17,17,17,17,37,15,23,1
1,1,35,17,17,17,17,17,17,17,17,17,17,17,39,23,1
1,1,35,17,17,17,17,17,17,17,17,17,17,17,40,23,1
1,1,15,17,41,42,41,17,17,17,17,17,17,17,39,23,1
1,1,35,17,41,42,41,17,17,17,17,17,17,17,15,33,1
1,1,35,17,17,17,17,17,17,17,15,43,43,33,23,1,1
1,1,31,15,44,44,44,44,15,33,17,17,17,17,1,1,1
1,1,1,31,33,33,33,33,31,1,1,1,1,1,1,1,1
1,1,1,1,1,1,1,1,1,1,1,1,1,1,1,1,1
endlayer

layer
1,1,1,1,1,1,1,1,1,1,1,1,1,1,1,1,1
1,1,1,1,1,31,31,17,31,31,45,15,1,1,1,1,1
1,1,11,17,31,15,17,17,17,17,32,24,31,1,1,1,1
1,15,46,17,17,17,17,17,17,17,32,24,45,1,1,1,1
1,31,17,17,17,17,17,17,17,15,13,33,47,1,1,1,1
1,17,17,17,17,17,17,17,17,17,17,17,47,1,1,1,1
1,31,17,17,17,17,17,17,17,17,17,17,15,48,1,1,1
1,31,15,17,17,17,17,17,17,17,17,17,17,16,15,31,1
1,1,17,17,17,17,17,17,17,17,17,17,17,17,49,31,1
1,1,31,17,17,17,17,17,17,17,17,17,17,17,49,17,1
1,1,15,17,49,49,49,17,17,17,17,17,17,17,49,31,1
1,1,31,17,49,49,49,17,17,17,17,17,17,17,15,31,1
1,1,17,17,17,17,17,17,17,17,15,51,50,26,31,1,1
1,1,31,15,49,49,49,49,15,31,17,17,17,17,1,1,1
1,1,1,31,31,17,17,31,31,1,1,1,1,1,1,1,1
1,1,1,1,1,1,1,1,1,1,1,1,1,1,1,1,1
endlayer

layer
1,1,1,1,1,1,1,1,1,1,52,52,1,1,1,1,1
1,52,1,1,1,53,48,48,48,48,24,15,1,1,1,1,1
52,55,7,48,48,15,17,17,17,32,25,54,47,1,1,1,1
1,15,10,17,56,17,17,17,17,32,13,54,47,1,1,1,1
1,57,17,17,17,17,17,17,17,15,17,17,47,1,1,1,1
1,57,58,17,17,17,17,17,17,17,17,17,38,52,1,1,1
1,57,58,17,17,17,17,17,17,17,17,17,15,12,52,59,1
1,61,15,17,17,17,17,17,17,17,17,17,17,60,15,38,1
1,1,57,17,17,17,17,17,17,17,17,17,17,17,17,38,1
1,1,57,17,17,17,17,17,17,17,17,17,17,17,17,38,1
1,1,15,17,17,17,17,17,17,17,17,17,17,17,17,38,1
1,1,57,17,17,17,17,17,17,17,17,17,17,17,15,61,1
1,1,57,17,17,17,17,17,17,17,15,63,63,37,62,1,1
1,1,61,15,17,17,17,17,15,37,17,17,17,17,1,1,1
1,1,52,64,37,37,37,37,62,1,1,1,1,1,1,1,1
1,1,1,1,1,1,1,1,1,1,1,1,1,1,1,1,1
endlayer

layer
1,1,1,1,1,1,64,52,52,62,65,1,1,1,1,1,1
1,1,64,52,53,59,12,12,12,24,28,15,45,1,1,1,1
1,64,11,55,55,15,37,37,57,23,17,17,23,1,1,1,1
64,15,66,37,37,38,16,16,57,25,17,17,23,1,1,1,1
67,55,38,17,17,17,17,17,37,15,17,17,25,1,1,1,1
52,55,38,17,17,17,17,17,17,17,17,17,25,59,1,1,1
68,55,38,17,17,17,17,17,17,17,17,17,15,55,68,62,1
64,55,15,48,17,17,17,17,17,17,17,17,57,37,15,55,65
1,64,55,38,17,17,17,17,17,17,17,17,17,17,57,55,52
1,52,55,38,17,17,17,17,17,17,17,17,17,17,57,55,52
1,53,15,17,17,17,17,17,17,17,17,17,17,17,57,55,65
1,52,55,38,17,17,17,17,17,17,48,48,48,48,15,61,1
1,65,55,38,17,17,17,17,48,48,15,55,55,55,62,1,1
1,1,64,15,48,48,48,48,15,61,52,52,52,65,1,1,1
1,1,1,67,55,55,55,55,62,1,1,1,1,1,1,1,1
1,1,1,1,65,52,52,65,1,1,1,1,1,1,1,1,1
endlayer

layer
1,1,1,1,1,1,1,1,65,1,1,1,1,1,1,1,1
1,1,1,65,1,71,70,70,70,70,70,70,70,69,1,1,1
1,1,8,70,70,70,24,24,23,17,17,17,72,1,1,1,1
1,59,11,24,24,24,12,12,25,17,17,17,72,1,1,1,1
1,64,24,24,12,12,12,24,29,15,17,17,72,1,1,1,1
65,55,24,24,12,24,24,12,24,24,17,17,72,1,1,1,1
1,64,24,24,24,12,24,12,12,12,48,48,12,65,1,1,1
1,65,15,24,12,24,24,24,12,24,12,24,12,55,59,65,1
1,1,64,24,12,24,24,24,12,12,12,12,24,12,55,59,1
1,1,55,24,12,24,12,12,24,12,12,24,24,12,55,62,1
1,65,55,24,12,12,12,24,24,12,24,12,12,12,55,65,1
1,1,55,24,24,24,24,24,12,12,12,12,55,55,61,1,1
1,1,64,55,24,24,24,24,72,55,55,55,61,62,1,1,1
1,1,1,61,64,55,55,62,61,61,65,65,1,1,1,1,1
1,1,1,1,65,64,61,65,1,1,1,1,1,1,1,1,1
1,1,1,1,1,1,1,1,1,1,1,1,1,1,1,1,1
endlayer

layer
1,1,1,1,1,1,1,1,1,1,1,1,1,1,1,1,1
1,1,1,1,1,1,31,28,28,28,28,15,31,1,1,1,1
1,1,7,35,28,28,15,17,17,17,17,17,23,1,1,1,1
1,1,11,15,73,73,17,17,17,17,17,17,23,1,1,1,1
1,1,35,17,17,17,17,17,17,15,17,17,23,1,1,1,1
1,1,35,17,17,17,17,17,17,24,17,17,15,1,1,1,1
1,1,35,17,17,17,17,17,17,24,33,33,31,1,1,1,1
1,1,15,38,57,38,17,17,17,15,17,17,17,74,1,1,1
1,1,35,38,57,38,17,17,17,75,17,17,17,17,74,1,1
1,1,35,17,17,17,17,17,17,15,17,17,17,17,74,1,1
1,1,35,76,17,17,17,17,17,23,17,17,17,17,74,1,1
1,1,33,15,17,17,44,44,15,17,17,17,74,74,1,1,1
1,1,1,31,33,33,33,33,41,74,74,74,1,1,1,1,1
1,1,1,1,1,1,1,1,1,1,1,1,1,1,1,1,1
1,1,1,1,1,1,1,1,1,1,1,1,1,1,1,1,1
1,1,1,1,1,1,1,1,1,1,1,1,1,1,1,1,1
endlayer

layer
1,1,1,1,1,1,1,1,1,1,1,1,1,1,1,1,1
1,1,1,1,1,1,31,17,31,17,31,15,31,1,1,1,1
1,1,1,31,17,31,15,17,17,17,17,17,17,1,1,1,1
1,1,11,15,49,49,17,17,17,17,17,17,31,1,1,1,1
1,1,31,17,17,17,17,17,17,15,17,17,31,1,1,1,1
1,1,17,17,17,17,17,17,17,24,17,17,15,1,1,1,1
1,1,31,17,17,17,17,17,17,24,31,31,31,1,1,1,1
1,1,15,77,49,49,17,17,17,15,17,17,17,17,1,1,1
1,1,31,77,49,49,17,17,17,50,17,17,17,17,17,1,1
1,1,17,17,17,17,17,17,17,15,17,17,17,17,17,1,1
1,1,31,49,17,17,17,17,17,31,17,17,17,17,1,1,1
1,1,31,15,17,17,49,49,15,17,17,17,17,1,1,1,1
1,1,1,31,17,31,31,17,31,17,17,17,1,1,1,1,1
1,1,1,1,1,1,1,1,1,1,1,1,1,1,1,1,1
1,1,1,1,1,1,1,1,1,1,1,1,1,1,1,1,1
1,1,1,1,1,1,1,1,1,1,1,1,1,1,1,1,1
endlayer

layer
1,1,1,1,1,1,1,1,1,1,1,1,1,1,1,1,1
1,1,1,1,1,52,59,48,48,48,48,15,78,1,1,1,1
1,1,52,64,48,48,15,17,17,17,17,17,38,1,1,1,1
1,1,11,15,17,17,17,17,17,17,17,17,38,1,1,1,1
1,1,57,17,17,17,17,17,17,15,17,17,38,1,1,1,1
1,1,57,17,17,17,17,17,17,12,17,17,15,1,1,1,1
1,1,57,17,17,17,17,17,17,12,37,37,62,1,1,1,1
1,1,15,17,17,17,17,17,17,15,17,17,17,1,1,1,1
1,1,57,17,17,17,17,17,17,79,17,17,17,17,1,1,1
1,1,57,17,17,17,17,17,17,15,17,17,17,17,1,1,1
1,1,57,17,17,17,17,17,17,38,17,17,17,1,1,1,1
1,1,61,15,17,17,17,17,15,61,17,17,1,1,1,1,1
1,1,1,64,37,37,37,37,62,1,1,1,1,1,1,1,1
1,1,1,1,1,1,1,1,1,1,1,1,1,1,1,1,1
1,1,1,1,1,1,1,1,1,1,1,1,1,1,1,1,1
1,1,1,1,1,1,1,1,1,1,1,1,1,1,1,1,1
endlayer

layer
1,1,1,1,1,1,1,65,52,52,53,59,1,1,1,1,1
1,1,1,1,1,1,59,55,55,55,55,15,59,65,1,1,1
1,1,1,59,55,55,15,37,37,37,37,57,55,52,1,1,1
1,65,11,15,37,37,38,17,17,17,17,57,55,52,1,1,1
1,53,55,38,17,17,17,17,17,15,48,57,55,52,1,1,1
1,52,55,38,17,17,17,17,48,12,12,12,15,65,1,1,1
1,53,55,37,17,17,17,17,57,55,55,55,61,1,1,1,1
1,65,15,17,17,17,17,17,57,15,55,52,17,1,1,1,1
1,52,55,48,17,17,17,17,57,55,52,17,17,1,1,1,1
1,52,55,38,17,17,17,17,57,15,52,17,17,1,1,1,1
1,65,61,38,17,17,17,17,57,55,65,17,1,1,1,1,1
1,1,64,15,48,48,48,48,15,62,1,1,1,1,1,1,1
1,1,52,61,55,55,55,55,67,52,1,1,1,1,1,1,1
1,1,1,1,65,52,52,65,1,1,1,1,1,1,1,1,1
1,1,1,1,1,1,1,1,1,1,1,1,1,1,1,1,1
1,1,1,1,1,1,1,1,1,1,1,1,1,1,1,1,1
endlayer

layer
1,1,1,1,1,1,1,1,1,1,1,1,1,1,1,1,1
1,1,1,1,1,1,1,1,59,55,55,59,1,1,1,1,1
1,1,1,1,59,59,55,55,55,55,55,55,62,1,1,1,1
1,1,10,55,37,37,37,37,57,12,41,55,55,65,1,1,1
1,1,64,38,17,17,17,17,57,55,55,55,55,1,1,1,1
1,1,64,38,17,17,17,17,57,55,55,55,62,1,1,1,1
1,1,64,38,17,17,17,17,57,55,55,61,1,1,1,1,1
1,1,64,38,17,17,17,17,57,55,62,1,1,1,1,1,1
1,1,64,38,17,17,17,17,57,55,65,1,1,1,1,1,1
1,1,64,38,17,17,17,17,57,62,1,1,1,1,1,1,1
1,1,64,38,17,17,17,17,57,62,1,1,1,1,1,1,1
1,1,61,15,48,48,48,48,15,61,1,1,1,1,1,1,1
1,1,1,64,61,61,61,61,62,1,1,1,1,1,1,1,1
1,1,1,1,1,1,1,1,1,1,1,1,1,1,1,1,1
1,1,1,1,1,1,1,1,1,1,1,1,1,1,1,1,1
1,1,1,1,1,1,1,1,1,1,1,1,1,1,1,1,1
endlayer

layer
1,1,1,1,1,1,1,1,1,1,1,1,1,1,1,1,1
1,1,1,1,1,1,1,1,1,1,1,1,1,1,1,1,1
1,1,1,1,1,1,1,64,55,55,55,59,1,1,1,1,1
1,1,10,1,59,55,55,55,55,55,74,55,1,1,1,1,1
1,1,1,64,38,37,37,37,55,55,55,55,65,1,1,1,1
1,1,1,64,38,17,17,57,55,55,55,62,1,1,1,1,1
1,1,1,64,37,17,17,37,55,55,62,1,1,1,1,1,1
1,1,1,64,38,17,17,57,55,62,1,1,1,1,1,1,1
1,1,1,64,48,17,17,48,55,65,1,1,1,1,1,1,1
1,1,1,64,38,17,17,57,55,1,1,1,1,1,1,1,1
1,1,1,61,48,48,48,48,62,1,1,1,1,1,1,1,1
1,1,1,61,61,61,61,61,65,1,1,1,1,1,1,1,1
1,1,1,1,1,1,1,1,1,1,1,1,1,1,1,1,1
1,1,1,1,1,1,1,1,1,1,1,1,1,1,1,1,1
1,1,1,1,1,1,1,1,1,1,1,1,1,1,1,1,1
1,1,1,1,1,1,1,1,1,1,1,1,1,1,1,1,1
endlayer

layer
1,1,1,1,1,1,1,1,1,1,1,1,1,1,1,1,1
1,1,1,1,1,1,1,1,1,1,1,1,1,1,1,1,1
1,1,1,1,1,1,1,1,74,74,74,1,1,1,1,1,1
1,1,10,1,1,74,74,74,65,65,1,74,1,1,1,1,1
1,1,1,1,64,55,55,55,65,65,65,74,1,1,1,1,1
1,1,1,1,55,37,37,55,55,65,74,1,1,1,1,1,1
1,1,1,1,55,12,12,55,55,74,1,1,1,1,1,1,1
1,1,1,1,55,38,57,55,55,1,1,1,1,1,1,1,1
1,1,1,1,55,12,12,55,55,1,1,1,1,1,1,1,1
1,1,1,1,55,48,48,55,1,1,1,1,1,1,1,1,1
1,1,1,1,61,55,55,62,1,1,1,1,1,1,1,1,1
1,1,1,1,1,1,1,1,1,1,1,1,1,1,1,1,1
1,1,1,1,1,1,1,1,1,1,1,1,1,1,1,1,1
1,1,1,1,1,1,1,1,1,1,1,1,1,1,1,1,1
1,1,1,1,1,1,1,1,1,1,1,1,1,1,1,1,1
1,1,1,1,1,1,1,1,1,1,1,1,1,1,1,1,1
endlayer

layer
1,1,1,1,1,1,1,1,1,1,1,1,1,1,1,1,1
1,1,1,1,1,1,1,1,1,1,1,1,1,1,1,1,1
1,1,1,1,1,1,1,1,1,1,1,1,1,1,1,1,1
1,1,1,1,1,1,1,1,1,1,1,1,1,1,1,1,1
1,1,1,1,1,74,74,74,1,1,1,1,1,1,1,1,1
1,1,1,1,74,65,65,65,74,1,1,1,1,1,1,1,1
1,1,1,1,74,65,65,65,74,1,1,1,1,1,1,1,1
1,1,1,1,74,65,65,65,74,1,1,1,1,1,1,1,1
1,1,1,1,74,65,65,65,74,1,1,1,1,1,1,1,1
1,1,1,1,74,65,65,74,1,1,1,1,1,1,1,1,1
1,1,1,1,1,74,74,1,1,1,1,1,1,1,1,1,1
1,1,1,1,1,1,1,1,1,1,1,1,1,1,1,1,1
1,1,1,1,1,1,1,1,1,1,1,1,1,1,1,1,1
1,1,1,1,1,1,1,1,1,1,1,1,1,1,1,1,1
1,1,1,1,1,1,1,1,1,1,1,1,1,1,1,1,1
1,1,1,1,1,1,1,1,1,1,1,1,1,1,1,1,1
endlayer

