
# Created by Ruins mod version 16.7 Ingame Parser
# authoring Player: lafuller

weight=1
embed_into_distance=13
acceptable_target_blocks=water,waterlily
unacceptable_target_blocks=
biomesToSpawnIn=swampland,jungle,marsh,bog,wetland,mini_jungle,lush_swamp,green_swamp,dead_swamp,tropical_island,land_of_lakes
dimensions=27,11,11
allowable_overhang=0
max_leveling=13
leveling_buffer=-1
preserve_water=0
preserve_lava=0

rule1=0,100,preserveBlock
rule2=0,100,minecraft:log2-1
rule3=0,100,minecraft:log2-5
rule4=0,100,minecraft:log2-9
rule5=0,100,minecraft:spruce_fence-0
rule6=0,100,minecraft:log-3
rule7=0,100,minecraft:ladder-4
rule8=0,100,minecraft:log-7
rule9=0,100,minecraft:wooden_slab-9
rule10=0,100,minecraft:spruce_stairs-4
rule11=0,100,minecraft:planks-1
rule12=0,100,minecraft:log-11
rule13=0,100,minecraft:spruce_stairs-5
rule14=0,100,minecraft:spruce_stairs-0
rule15=0,100,minecraft:spruce_fence_gate-0
rule16=0,100,minecraft:spruce_stairs-3
rule17=0,100,minecraft:spruce_stairs-2
rule18=0,100,minecraft:spruce_stairs-1
rule19=0,100,minecraft:spruce_stairs-7
rule20=0,100,minecraft:spruce_stairs-6
rule21=0,100,minecraft:dark_oak_stairs-6
rule22=0,100,minecraft:dark_oak_stairs-4
rule23=0,100,minecraft:wooden_slab-13
rule24=0,100,minecraft:dark_oak_stairs-7
rule25=0,100,minecraft:dark_oak_stairs-5
rule26=0,100,minecraft:dark_oak_stairs-0
rule27=0,100,minecraft:dark_oak_stairs-2
rule28=0,100,minecraft:dark_oak_stairs-3
rule29=0,100,minecraft:wooden_slab-5
rule30=0,100,minecraft:planks-5
rule31=0,100,minecraft:dark_oak_stairs-1
rule32=0,100,minecraft:trapdoor-2
rule33=0,100,minecraft:double_wooden_slab-5

layer
1,1,1,1,1,1,1,1,1,1,1
1,1,1,1,1,1,1,1,1,1,1
1,1,1,1,2,1,1,1,1,1,1
1,1,1,1,1,1,1,2,1,1,1
1,1,1,1,1,1,1,1,1,1,1
1,1,1,1,1,1,1,1,1,1,1
1,1,1,2,1,1,1,2,1,1,1
1,1,1,1,1,1,1,1,1,1,1
1,1,1,1,2,1,1,1,1,1,1
1,1,1,1,1,1,1,1,1,1,1
1,1,1,1,1,1,1,1,1,1,1
endlayer

layer
1,1,1,1,1,1,1,1,1,1,1
1,1,1,1,1,1,1,1,1,1,1
1,1,1,1,2,1,1,1,1,1,1
1,1,1,1,1,1,1,2,1,1,1
1,1,1,1,1,1,1,1,1,1,1
1,1,1,1,1,1,1,1,1,1,1
1,1,1,2,1,1,1,2,1,1,1
1,1,1,1,1,1,1,1,1,1,1
1,1,1,1,2,1,1,1,1,1,1
1,1,1,1,1,1,1,1,1,1,1
1,1,1,1,1,1,1,1,1,1,1
endlayer

layer
1,1,1,1,1,1,1,1,1,1,1
1,1,1,1,1,1,1,1,1,1,1
1,1,1,1,2,1,1,1,1,1,1
1,1,1,1,1,1,1,2,1,1,1
1,1,1,1,1,1,1,1,1,1,1
1,1,1,1,1,1,1,1,1,1,1
1,1,1,2,1,1,1,2,1,1,1
1,1,1,1,1,1,1,1,1,1,1
1,1,1,1,2,1,1,1,1,1,1
1,1,1,1,1,1,1,1,1,1,1
1,1,1,1,1,1,1,1,1,1,1
endlayer

layer
1,1,1,1,1,1,1,1,1,1,1
1,1,1,1,1,1,1,1,1,1,1
1,1,1,1,2,1,1,1,1,1,1
1,1,1,1,1,1,1,2,1,1,1
1,1,1,1,1,1,1,1,1,1,1
1,1,1,1,1,1,1,1,1,1,1
1,1,1,2,1,1,1,2,1,1,1
1,1,1,1,1,1,1,1,1,1,1
1,1,1,1,2,1,1,1,1,1,1
1,1,1,1,1,1,1,1,1,1,1
1,1,1,1,1,1,1,1,1,1,1
endlayer

layer
1,1,1,1,1,1,1,1,1,1,1
1,1,1,1,1,1,1,1,1,1,1
1,1,1,1,2,1,1,1,1,1,1
1,1,1,1,1,1,1,2,1,1,1
1,1,1,1,1,1,1,1,1,1,1
1,1,1,1,1,1,1,1,1,1,1
1,1,1,2,1,1,1,2,1,1,1
1,1,1,1,1,1,1,1,1,1,1
1,1,1,1,2,1,1,1,1,1,1
1,1,1,1,1,1,1,1,1,1,1
1,1,1,1,1,1,1,1,1,1,1
endlayer

layer
1,1,1,1,1,1,1,1,1,1,1
1,1,1,1,1,1,1,1,1,1,1
1,1,1,1,2,1,1,1,1,1,1
1,1,1,1,1,1,1,2,1,1,1
1,1,1,1,1,1,1,1,1,1,1
1,1,1,1,1,1,1,1,1,1,1
1,1,1,2,1,1,1,2,1,1,1
1,1,1,1,1,1,1,1,1,1,1
1,1,1,1,2,1,1,1,1,1,1
1,1,1,1,1,1,1,1,1,1,1
1,1,1,1,1,1,1,1,1,1,1
endlayer

layer
1,1,1,1,1,1,1,1,1,1,1
1,1,1,1,1,1,1,1,1,1,1
1,1,1,1,2,1,1,1,1,1,1
1,1,1,1,1,1,1,2,1,1,1
1,1,1,1,1,1,1,1,1,1,1
1,1,1,1,1,1,1,1,1,1,1
1,1,1,2,1,1,1,2,1,1,1
1,1,1,1,1,1,1,1,1,1,1
1,1,1,1,2,1,1,1,1,1,1
1,1,1,1,1,1,1,1,1,1,1
1,1,1,1,1,1,1,1,1,1,1
endlayer

layer
1,1,1,1,1,1,1,1,1,1,1
1,1,1,1,1,1,1,1,1,1,1
1,1,1,1,2,1,1,1,1,1,1
1,1,1,1,1,1,1,2,1,1,1
1,1,1,1,1,1,1,1,1,1,1
1,1,1,1,1,1,1,1,1,1,1
1,1,1,2,1,1,1,2,1,1,1
1,1,1,1,1,1,1,1,1,1,1
1,1,1,1,2,1,1,1,1,1,1
1,1,1,1,1,1,1,1,1,1,1
1,1,1,1,1,1,1,1,1,1,1
endlayer

layer
1,1,1,1,1,1,1,1,1,1,1
1,1,1,1,1,1,1,1,1,1,1
1,1,1,1,2,1,1,1,1,1,1
1,1,1,1,1,1,1,2,1,1,1
1,1,1,1,1,1,1,1,1,1,1
1,1,1,1,1,1,1,1,1,1,1
1,1,1,2,1,1,1,2,1,1,1
1,1,1,1,1,1,1,1,1,1,1
1,1,1,1,2,1,1,1,1,1,1
1,1,1,1,1,1,1,1,1,1,1
1,1,1,1,1,1,1,1,1,1,1
endlayer

layer
1,1,1,1,1,1,1,1,1,1,1
1,1,1,1,1,1,1,1,1,1,1
1,1,1,1,2,1,1,1,1,1,1
1,1,1,1,1,1,1,2,1,1,1
1,1,1,1,1,1,1,1,1,1,1
1,1,1,1,1,1,1,1,1,1,1
1,1,1,2,1,1,1,2,1,1,1
1,1,1,1,1,1,1,1,1,1,1
1,1,1,1,2,1,1,1,1,1,1
1,1,1,1,1,1,1,1,1,1,1
1,1,1,1,1,1,1,1,1,1,1
endlayer

layer
1,1,1,1,1,1,1,1,1,1,1
1,1,1,3,1,1,1,1,1,1,1
1,1,1,3,2,1,1,3,1,1,1
1,1,1,3,1,1,1,3,1,1,1
1,1,1,3,1,1,1,3,1,1,1
1,1,1,3,1,1,1,3,1,1,1
1,1,1,3,1,1,1,3,1,1,1
1,1,1,3,1,1,1,3,1,1,1
1,1,1,3,2,1,1,3,1,1,1
1,1,1,3,1,1,1,1,1,1,1
1,1,1,1,1,1,1,1,1,1,1
endlayer

layer
1,1,1,1,1,1,1,1,1,1,1
1,1,1,1,1,1,1,1,1,1,1
1,1,1,1,2,1,1,1,1,1,1
1,1,4,4,4,4,4,4,4,1,1
1,1,1,1,1,1,1,1,1,1,1
1,1,1,1,1,1,1,1,1,1,1
1,1,1,1,1,1,1,1,1,1,1
1,4,4,4,4,4,4,4,4,4,1
1,1,1,1,2,1,1,1,1,1,1
1,1,1,1,1,1,1,1,1,1,1
1,1,1,1,1,1,1,1,1,1,1
endlayer

layer
1,1,1,1,1,1,1,1,1,1,1
1,1,1,1,3,1,1,1,1,1,1
1,1,3,1,3,1,1,1,1,1,1
1,1,3,2,3,1,1,2,1,1,1
1,1,3,1,3,1,1,1,1,1,1
1,1,3,1,3,1,1,1,1,1,1
1,1,3,1,3,1,1,1,1,1,1
1,1,3,1,3,1,1,1,2,1,1
1,1,3,1,3,1,1,1,1,1,1
1,1,1,1,3,1,1,1,1,1,1
1,1,1,1,1,1,1,1,1,1,1
endlayer

layer
1,1,1,1,1,1,1,1,1,1,1
1,1,1,1,1,1,1,1,5,1,1
1,5,4,4,4,4,4,4,4,5,1
1,1,1,2,1,1,1,2,1,1,1
5,4,4,4,4,4,4,4,4,5,1
1,1,2,1,1,1,1,1,1,1,1
1,1,1,1,1,1,1,1,1,1,1
1,1,1,1,7,1,1,1,6,5,1
1,1,1,1,6,1,1,1,5,1,1
1,1,1,1,5,1,1,1,1,1,1
1,1,1,1,1,1,1,1,1,1,1
endlayer

layer
1,1,1,5,1,1,5,1,1,1,1
1,1,1,8,1,1,8,1,1,1,1
1,1,1,8,1,1,8,1,1,1,1
1,1,1,8,1,1,8,2,1,1,1
1,1,1,8,1,1,8,6,1,1,1
1,1,6,8,1,1,1,1,1,1,1
1,1,1,8,1,1,1,1,1,1,1
1,1,1,8,7,1,1,1,6,5,1
1,1,5,8,6,1,1,1,5,5,1
1,1,5,8,5,1,1,1,1,1,1
1,1,1,5,1,1,1,1,1,1,1
endlayer

layer
1,1,1,1,1,1,1,1,1,1,1
1,1,1,5,9,9,9,9,9,1,1
1,1,1,6,10,9,11,9,10,9,1
5,12,12,12,12,12,12,12,12,12,5
1,1,9,9,9,9,13,6,13,9,1
1,1,6,10,9,9,9,9,9,9,1
5,12,12,12,12,12,12,12,12,12,5
1,1,1,13,7,9,9,9,6,1,1
1,1,5,5,6,9,9,9,5,5,1
1,1,1,5,1,1,1,1,1,1,1
1,1,1,1,1,1,1,1,1,1,1
endlayer

layer
1,1,1,1,1,1,1,1,1,1,1
1,1,1,5,1,1,1,1,1,1,1
1,1,5,6,14,14,6,5,1,1,1
1,1,16,0,0,0,0,15,1,1,1
1,1,16,0,0,0,0,6,5,1,1
1,1,6,0,0,0,0,0,17,1,1
1,1,1,18,0,0,0,0,17,1,1
1,1,1,16,7,0,0,0,6,1,1
1,1,1,5,6,18,18,18,5,1,1
1,1,1,1,1,1,1,1,1,1,1
1,1,1,1,1,1,1,1,1,1,1
endlayer

layer
1,1,1,1,1,1,1,1,1,1,1
1,1,5,5,1,1,1,1,1,1,1
1,1,5,6,5,0,6,5,1,1,1
1,1,0,0,0,0,0,0,1,1,1
1,1,5,0,0,0,0,6,5,1,1
1,1,6,0,0,0,0,0,0,1,1
1,1,5,5,0,0,0,0,5,1,1
1,1,1,0,7,0,0,0,6,1,1
1,1,1,5,6,5,0,5,5,1,1
1,1,1,1,1,1,1,1,1,1,1
1,1,1,1,1,1,1,1,1,1,1
endlayer

layer
1,1,1,5,1,1,1,1,1,1,1
1,1,5,8,1,1,1,1,1,1,1
1,1,5,8,10,10,6,5,1,1,1
1,1,19,8,9,9,9,5,1,1,1
1,1,19,8,9,0,0,6,5,1,1
5,12,12,8,9,0,0,9,20,1,1
1,1,5,8,9,0,0,9,20,1,1
1,1,5,8,7,9,9,9,6,1,1
1,5,12,12,12,12,12,12,12,12,5
1,1,1,8,13,9,13,20,1,1,1
1,1,1,5,1,1,1,1,1,1,1
endlayer

layer
1,1,1,1,1,1,1,1,1,1,1
1,1,1,5,1,1,1,5,1,1,1
1,5,12,6,12,12,12,12,5,1,1
1,1,16,0,0,0,0,20,1,1,1
1,1,16,0,0,0,0,6,14,1,1
1,1,6,0,0,0,0,0,17,1,1
1,1,5,18,0,0,0,0,17,1,1
1,1,1,16,7,0,0,0,6,1,1
1,1,1,18,6,0,0,0,17,1,1
1,1,1,1,5,18,18,18,5,1,1
1,1,1,1,1,1,1,1,1,1,1
endlayer

layer
1,1,1,1,1,1,1,1,1,1,1
1,1,5,5,1,1,5,5,1,1,1
1,1,5,6,5,0,6,5,1,1,1
1,1,0,0,0,0,0,5,1,1,1
1,1,5,0,0,0,0,6,5,1,1
1,1,6,0,0,0,0,0,0,1,1
1,1,5,5,0,0,0,0,5,1,1
1,1,1,0,7,0,0,0,6,1,1
1,1,1,5,6,0,0,0,5,1,1
1,1,1,1,5,5,1,5,5,1,1
1,1,1,1,1,1,1,1,1,1,1
endlayer

layer
1,1,1,1,1,1,1,5,1,1,1
1,1,5,19,10,10,10,8,1,1,1
1,1,13,6,12,12,12,8,1,1,1
1,1,19,12,9,9,9,8,10,1,1
1,1,19,8,9,9,9,8,20,1,1
1,1,6,8,9,9,9,8,11,9,1
5,12,12,12,12,12,12,12,12,12,5
1,1,9,19,7,9,9,8,6,9,1
1,1,1,13,6,9,9,8,20,1,1
1,1,1,1,19,13,13,8,1,1,1
1,1,1,1,1,1,1,5,1,1,1
endlayer

layer
1,1,1,1,1,1,1,1,1,1,1
1,1,1,14,14,14,14,17,1,1,1
1,1,16,6,0,0,0,17,1,1,1
1,1,16,0,0,0,0,6,14,1,1
1,1,16,0,0,0,0,0,0,17,1
1,1,6,0,0,0,0,0,0,17,1
1,1,16,0,0,0,0,0,0,17,1
1,1,16,0,7,0,0,0,6,17,1
1,1,18,16,6,0,0,0,18,17,1
1,1,1,1,18,18,18,18,17,1,1
1,1,1,1,1,1,1,1,1,1,1
endlayer

layer
1,1,1,1,1,1,1,1,1,1,1
1,1,1,5,5,0,5,5,1,1,1
1,1,5,6,0,0,0,0,1,1,1
1,1,0,0,0,0,0,6,5,1,1
1,1,5,0,0,0,0,0,0,5,1
1,1,6,0,0,0,0,0,0,0,1
1,1,5,0,0,0,0,0,0,5,1
1,1,0,0,7,0,0,0,6,5,1
1,1,5,5,6,0,0,0,5,1,1
1,1,1,1,5,5,5,1,1,1,1
1,1,1,1,1,1,1,1,1,1,1
endlayer

layer
1,1,1,1,1,1,1,1,1,1,1
1,1,23,22,22,22,22,21,1,1,1
1,23,24,6,0,0,0,21,23,1,1
1,23,24,0,0,0,0,21,22,22,1
1,23,24,0,0,0,0,0,0,21,1
1,23,6,0,0,0,0,0,0,21,1
1,1,24,0,0,0,0,0,0,21,1
1,1,24,0,0,0,0,0,6,21,1
1,1,25,24,6,0,0,0,25,1,1
1,1,1,1,25,25,25,25,23,1,1
1,1,1,1,1,23,23,1,1,1,1
endlayer

layer
1,1,1,1,1,1,1,1,1,1,1
1,1,1,26,26,26,26,1,1,1,1
1,1,28,6,13,13,13,27,1,1,1
1,1,28,20,0,0,19,30,29,1,1
1,1,28,20,0,0,13,6,27,1,1
1,1,28,20,0,0,0,16,30,29,1
1,1,28,20,0,0,0,19,30,29,1
1,1,28,10,0,0,0,19,30,1,1
1,1,1,31,6,10,10,10,27,1,1
1,1,1,1,31,30,30,31,1,1,1
1,1,1,1,1,1,1,1,1,1,1
endlayer

layer
1,1,1,1,1,1,1,1,1,1,1
1,1,1,1,1,1,1,1,1,1,1
1,1,1,29,26,26,1,1,1,1,1
1,1,1,28,30,30,26,27,1,1,1
1,1,1,28,30,30,30,27,1,1,1
1,1,1,28,30,32,30,27,1,1,1
1,1,1,28,30,30,30,29,1,1,1
1,1,1,31,31,33,33,29,1,1,1
1,1,1,1,29,29,29,29,1,1,1
1,1,1,1,1,1,1,1,1,1,1
1,1,1,1,1,1,1,1,1,1,1
endlayer

