
# Created by Ruins mod version 16.7 Ingame Parser
# authoring Player: lafuller

weight=1
embed_into_distance=18
acceptable_target_blocks=
unacceptable_target_blocks=flowing_water,water,flowing_lava,lava,ice,bedrock,netherrack,nether_brick,nether_brick_fence,soul_sand,quartz_ore,end_stone,obsidian,iron_bars,cloud,flesh,ash_block,slime_grass,slime_congealed,slime_dirt
dimensions=23,9,10
allowable_overhang=0
max_leveling=4
leveling_buffer=-1
preserve_water=0
preserve_lava=0

rule1=0,100,minecraft:stonebrick-0
rule2=0,100,minecraft:water-0
rule3=0,100,minecraft:stone_brick_stairs-0
rule4=0,100,minecraft:stone_slab-0
rule5=0,100,minecraft:stone_brick_stairs-2
rule6=0,100,minecraft:stone_brick_stairs-1
rule7=0,100,preserveBlock
rule8=0,100,minecraft:stone-6
rule9=0,100,minecraft:stone_brick_stairs-3
rule10=0,100,minecraft:stone_brick_stairs-5
rule11=0,100,minecraft:stone_brick_stairs-4
rule12=0,100,minecraft:stone-5
rule13=0,100,minecraft:stone_brick_stairs-7
rule14=0,100,minecraft:stone_brick_stairs-6
rule15=0,100,minecraft:spruce_fence_gate-0
rule16=0,100,minecraft:wooden_slab-5
rule17=0,100,minecraft:log-3
rule18=0,100,minecraft:spruce_stairs-2
rule19=0,100,minecraft:wooden_slab-1
rule20=0,100,minecraft:spruce_stairs-3
rule21=0,100,minecraft:spruce_stairs-0
rule22=0,100,minecraft:planks-1
rule23=0,100,minecraft:spruce_stairs-1

layer
1,1,1,1,1,1,1,1,1,1
1,1,1,1,1,1,1,1,1,1
1,1,1,1,1,1,1,1,1,1
1,1,1,1,1,1,1,1,1,1
1,1,1,1,1,1,1,1,1,1
1,1,1,1,1,1,1,1,1,1
1,1,1,1,1,1,1,1,1,1
1,1,1,1,1,1,1,1,1,1
1,1,1,1,1,1,1,1,1,1
endlayer

layer
1,1,1,1,1,1,1,1,1,1
1,1,1,1,1,1,1,1,1,1
1,1,1,1,1,1,1,1,1,1
1,1,1,1,1,1,1,1,1,1
1,1,1,1,2,2,1,1,1,1
1,1,1,1,2,2,1,1,1,1
1,1,1,1,1,1,1,1,1,1
1,1,1,1,1,1,1,1,1,1
1,1,1,1,1,1,1,1,1,1
endlayer

layer
1,1,1,1,1,1,1,1,1,1
1,1,1,1,1,1,1,1,1,1
1,1,1,1,1,1,1,1,1,1
1,1,1,1,1,1,1,1,1,1
1,1,1,1,2,2,1,1,1,1
1,1,1,1,2,2,1,1,1,1
1,1,1,1,1,1,1,1,1,1
1,1,1,1,1,1,1,1,1,1
1,1,1,1,1,1,1,1,1,1
endlayer

layer
1,1,1,1,1,1,1,1,1,1
1,1,1,1,1,1,1,1,1,1
1,1,1,1,1,1,1,1,1,1
1,1,1,1,1,1,1,1,1,1
1,1,1,1,2,2,1,1,1,1
1,1,1,1,2,2,1,1,1,1
1,1,1,1,1,1,1,1,1,1
1,1,1,1,1,1,1,1,1,1
1,1,1,1,1,1,1,1,1,1
endlayer

layer
1,1,1,1,1,1,1,1,1,1
1,1,1,1,1,1,1,1,1,1
1,1,1,1,1,1,1,1,1,1
1,1,1,1,1,1,1,1,1,1
1,1,1,1,2,2,1,1,1,1
1,1,1,1,2,2,1,1,1,1
1,1,1,3,1,1,1,1,1,1
1,1,1,1,1,1,1,1,1,1
1,1,1,1,1,1,1,1,1,1
endlayer

layer
1,1,1,1,1,1,1,1,1,1
1,1,1,1,1,1,1,1,1,1
1,1,1,1,1,1,1,1,1,1
1,1,1,1,1,1,1,1,1,1
1,1,1,1,2,2,1,1,1,1
1,1,1,1,2,2,1,1,1,1
1,1,1,1,1,1,1,1,1,1
1,1,1,1,1,1,1,1,1,1
1,1,1,1,1,1,1,1,1,1
endlayer

layer
1,1,1,1,1,1,1,1,1,1
1,1,1,1,1,1,1,1,1,1
1,1,1,1,1,1,1,1,1,1
1,1,1,1,1,1,1,1,1,1
1,1,1,1,2,2,1,1,1,1
1,1,1,1,2,2,1,1,1,1
1,1,1,1,1,1,1,1,1,1
1,1,1,1,1,1,1,1,1,1
1,1,1,1,1,1,1,1,1,1
endlayer

layer
1,1,1,1,1,1,1,1,1,1
1,1,1,1,1,1,1,1,1,1
1,1,1,1,1,1,1,1,1,1
1,1,1,1,1,1,1,1,1,1
1,1,1,1,2,2,1,1,1,1
1,1,1,1,2,2,1,1,1,1
1,1,1,1,1,1,1,1,1,1
1,1,1,1,1,1,1,1,1,1
1,1,1,1,1,1,1,1,1,1
endlayer

layer
1,1,1,1,1,1,1,1,1,1
1,1,1,1,1,1,1,1,1,1
1,1,1,1,1,1,1,1,1,1
1,1,1,1,1,1,1,1,1,1
1,1,1,1,0,0,4,4,1,1
1,1,1,1,0,0,4,4,1,1
1,1,1,1,1,5,4,4,1,1
1,1,1,1,1,1,1,1,1,1
1,1,1,1,1,1,1,1,1,1
endlayer

layer
1,1,1,1,1,1,1,1,1,1
1,1,1,1,1,1,1,1,1,1
1,1,1,1,1,1,1,1,1,1
1,1,1,1,1,1,1,1,1,1
1,1,1,1,0,0,0,0,1,1
1,1,1,1,0,0,0,0,1,1
1,1,1,1,5,0,0,0,1,1
1,1,1,1,1,1,1,1,1,1
1,1,1,1,1,1,1,1,1,1
endlayer

layer
1,1,1,1,1,1,1,1,1,1
1,1,1,1,1,1,1,1,1,1
1,1,1,1,1,1,1,1,1,1
1,1,1,1,1,1,1,1,1,1
1,1,1,1,0,0,0,0,1,1
1,1,1,6,0,0,0,0,1,1
1,1,1,4,0,0,0,0,1,1
1,1,1,4,4,4,4,1,1,1
1,1,1,1,1,1,1,1,1,1
endlayer

layer
1,1,1,1,1,1,1,1,1,1
1,1,1,1,1,1,1,1,1,1
1,1,1,1,1,1,1,1,1,1
1,1,1,1,1,1,1,1,1,1
1,1,1,6,0,0,0,0,1,1
1,1,1,0,0,0,0,0,1,1
1,1,1,0,0,0,0,0,1,1
1,1,1,0,0,0,0,1,1,1
1,1,1,1,1,1,1,1,1,1
endlayer

layer
1,1,1,1,1,5,7,7,7,7
1,1,1,1,1,1,1,1,1,3
1,1,8,1,1,1,1,1,1,1
1,1,4,4,4,9,1,1,1,1
6,1,4,0,0,0,0,10,1,1
7,1,4,0,0,0,0,0,1,1
7,1,4,0,0,0,0,11,1,1
7,1,1,0,0,0,0,1,1,1
7,9,1,1,1,1,1,1,1,1
endlayer

layer
1,1,1,1,5,7,7,7,7,7
1,1,1,1,1,1,1,1,1,7
1,1,12,4,4,4,4,1,1,3
6,1,0,0,0,0,9,1,1,1
7,1,0,0,0,0,0,1,1,1
7,1,0,0,0,0,0,1,1,1
7,1,0,0,0,0,0,1,1,1
7,1,1,14,0,0,13,1,1,1
7,7,9,1,1,1,1,1,1,1
endlayer

layer
1,1,1,5,7,7,7,7,7,7
1,1,1,1,1,1,1,1,1,7
6,1,8,0,0,0,0,8,1,7
7,1,0,0,0,0,0,4,1,3
7,1,0,0,0,0,0,3,1,1
7,1,0,0,0,0,0,1,1,1
7,1,0,0,0,0,0,1,1,1
7,1,1,1,1,1,1,1,1,1
7,7,7,9,1,1,1,1,1,1
endlayer

layer
7,7,7,7,7,7,7,7,7,7
7,7,1,1,1,1,1,1,1,7
7,3,12,0,0,0,0,12,1,7
7,1,10,0,0,0,0,0,1,7
7,1,0,0,0,0,0,0,1,3
7,1,0,0,0,0,0,3,1,1
7,1,11,0,0,0,0,1,1,1
7,1,1,1,1,1,1,12,6,6
7,7,7,7,7,7,7,7,7,7
endlayer

layer
7,7,7,7,7,7,7,7,7,7
7,7,1,1,1,1,1,1,1,7
7,7,8,0,0,0,0,8,1,7
7,7,1,0,0,0,0,0,6,7
7,7,1,0,0,0,0,0,7,7
7,7,1,0,0,0,0,0,7,7
7,7,1,0,0,0,0,0,7,7
7,7,8,1,5,9,1,8,7,7
7,7,7,7,7,7,7,7,7,7
endlayer

layer
7,7,7,7,7,7,7,7,7,7
7,7,1,1,1,1,1,1,1,7
7,7,12,1,1,1,1,12,6,7
7,7,1,0,15,15,15,0,7,7
7,7,1,0,15,15,15,0,7,7
7,7,1,0,15,15,15,0,7,7
7,7,1,0,15,15,15,0,7,7
7,7,12,1,5,9,1,12,7,7
7,7,7,7,7,7,7,7,7,7
endlayer

layer
7,7,7,7,7,7,7,7,7,7
7,7,1,1,1,1,1,5,7,7
7,7,8,1,1,1,1,8,7,7
7,7,1,16,16,16,16,0,7,7
7,7,1,16,0,0,16,0,7,7
7,7,1,16,0,0,16,0,7,7
7,7,1,16,16,16,16,0,7,7
7,7,8,1,1,1,1,8,7,7
7,7,7,7,7,7,7,7,7,7
endlayer

layer
7,7,7,7,7,7,7,7,7,7
7,7,7,7,7,7,7,7,7,7
7,7,17,0,0,0,0,17,7,7
7,7,0,0,0,0,0,0,7,7
7,7,0,0,0,0,0,0,7,7
7,7,0,0,0,0,0,0,7,7
7,7,0,0,0,0,0,0,7,7
7,7,17,0,0,0,0,17,7,7
7,7,7,7,7,7,7,7,7,7
endlayer

layer
7,7,7,7,7,7,7,7,7,7
7,7,7,7,7,7,7,7,7,7
7,7,17,0,0,0,0,17,7,7
7,7,0,0,0,0,0,0,7,7
7,7,0,0,0,0,0,0,7,7
7,7,0,0,0,0,0,0,7,7
7,7,0,0,0,0,0,0,7,7
7,7,17,0,0,0,0,17,7,7
7,7,7,7,7,7,7,7,7,7
endlayer

layer
7,7,7,7,7,7,7,7,7,7
7,7,7,7,7,7,7,7,7,7
7,7,17,0,0,0,0,17,7,7
7,7,0,0,0,0,0,0,7,7
7,7,0,0,0,0,0,0,7,7
7,7,0,0,0,0,0,0,7,7
7,7,0,0,0,0,0,0,7,7
7,7,17,0,0,0,0,17,7,7
7,7,7,7,7,7,7,7,7,7
endlayer

layer
7,7,7,7,7,7,7,7,7,7
7,7,20,19,18,20,19,18,7,7
7,21,22,23,23,23,23,22,21,7
7,19,18,0,0,0,0,20,19,7
7,23,18,0,0,0,0,20,23,7
7,21,18,0,0,0,0,20,21,7
7,19,18,0,0,0,0,20,19,7
7,23,22,21,21,21,21,22,23,7
7,7,20,19,18,20,19,18,7,7
endlayer

