
# Created by Ruins mod version 16.5 Ingame Parser
# authoring Player: lafuller

weight=1
embed_into_distance=26
acceptable_target_blocks=
unacceptable_target_blocks=flowing_water,water,flowing_lava,lava
dimensions=32,10,8
allowable_overhang=0
max_leveling=7
leveling_buffer=-1
preserve_water=0
preserve_lava=0

rule1=0,100,minecraft:double_stone_slab-9
rule2=0,100,minecraft:sandstone-0
rule3=0,100,minecraft:water-0
rule4=0,100,minecraft:stone_slab-1
rule5=0,100,minecraft:sandstone_stairs-1
rule6=0,100,minecraft:sandstone-2
rule7=2,100,minecraft:torch-3
rule8=0,100,minecraft:sandstone-1
rule9=0,100,minecraft:sandstone_stairs-7
rule10=0,100,minecraft:spruce_fence-0
rule11=0,100,minecraft:sandstone_stairs-3
rule12=2,100,minecraft:torch-4
rule13=0,100,minecraft:sandstone_stairs-0
rule14=0,100,minecraft:sandstone_stairs-4
rule15=2,100,minecraft:torch-1
rule16=0,100,minecraft:sandstone_stairs-6
rule17=0,100,preserveBlock
rule18=0,100,minecraft:sandstone_stairs-2
rule19=0,100,minecraft:sandstone_stairs-5
rule20=0,100,minecraft:wooden_slab-9
rule21=0,100,minecraft:spruce_stairs-7
rule22=0,100,minecraft:wooden_slab-1
rule23=0,100,minecraft:spruce_stairs-0
rule24=0,100,minecraft:spruce_stairs-3
rule25=0,100,minecraft:spruce_stairs-2
rule26=0,100,minecraft:spruce_stairs-1

layer
1,1,1,1,1,1,1,1
1,2,2,2,2,2,2,1
1,2,2,2,2,2,2,1
1,2,2,2,2,2,2,1
1,2,2,2,2,2,2,1
1,2,2,2,2,2,2,1
1,2,2,2,2,2,2,1
1,2,2,2,2,2,2,1
1,2,2,2,2,2,2,1
1,1,1,1,1,1,1,1
endlayer

layer
1,1,1,1,1,1,1,1
1,2,2,2,2,2,2,1
1,2,2,2,2,2,2,1
1,2,2,3,3,2,2,1
1,2,2,3,3,2,2,1
1,2,2,3,3,2,2,1
1,2,2,3,3,2,2,1
1,2,2,2,2,2,2,1
1,2,2,2,2,2,2,1
1,1,1,1,1,1,1,1
endlayer

layer
1,1,1,1,1,1,1,1
1,2,2,2,2,2,2,1
1,2,2,2,2,2,2,1
1,2,2,3,3,2,2,1
1,2,2,3,3,2,2,1
1,2,2,3,3,2,2,1
1,2,2,3,3,2,2,1
1,2,2,2,2,2,2,1
1,2,2,2,2,2,2,1
1,1,1,1,1,1,1,1
endlayer

layer
1,1,1,1,1,1,1,1
1,2,2,2,2,2,2,1
1,2,2,2,2,2,2,1
1,2,2,3,3,2,2,1
1,2,2,3,3,2,2,1
1,2,2,3,3,2,2,1
1,2,2,3,3,2,2,1
1,2,2,2,2,2,2,1
1,2,2,2,2,2,2,1
1,1,1,1,1,1,1,1
endlayer

layer
1,1,1,1,1,1,1,1
1,2,2,2,2,2,2,1
1,2,2,2,2,2,2,1
1,2,2,3,3,2,2,1
1,2,2,3,3,2,2,1
1,2,2,3,3,2,2,1
1,2,2,3,3,2,2,1
1,2,2,2,2,2,2,1
1,2,2,2,2,2,2,1
1,1,1,1,1,1,1,1
endlayer

layer
1,1,1,1,1,1,1,1
1,2,2,2,2,2,2,1
1,2,2,2,2,2,2,1
1,2,2,0,0,4,4,1
1,2,2,0,0,4,4,1
1,2,1,0,0,4,4,1
1,2,1,0,0,4,4,1
1,2,5,4,4,4,4,1
1,6,4,4,4,4,6,1
1,1,1,1,1,1,1,1
endlayer

layer
1,1,1,1,1,1,1,1
1,2,2,2,2,2,2,1
1,2,2,2,2,2,2,1
1,2,2,0,0,0,0,1
1,2,1,0,0,0,0,1
1,2,1,0,0,0,0,1
1,2,5,0,0,0,0,1
1,2,0,0,0,0,0,1
1,6,0,0,0,0,6,1
1,1,1,1,1,1,1,1
endlayer

layer
1,1,1,1,1,1,1,1
1,2,2,2,2,2,2,1
1,2,2,2,2,2,2,1
1,2,1,0,0,0,0,1
1,2,1,0,0,0,0,1
1,2,5,0,0,0,0,1
1,2,0,0,0,0,0,1
1,2,0,0,0,0,0,1
1,6,0,0,0,0,6,1
1,1,1,1,1,1,1,1
endlayer

layer
1,1,1,1,1,1,1,1
1,2,2,2,2,2,2,1
1,2,1,2,2,2,2,1
1,2,1,0,0,0,0,1
1,2,5,0,0,0,0,1
1,2,0,0,0,0,7,1
1,2,0,0,0,0,0,1
1,2,0,0,0,0,0,1
1,8,0,0,0,0,8,1
1,1,1,1,1,1,1,1
endlayer

layer
1,1,1,1,1,1,1,1
1,2,2,2,2,2,2,1
1,2,1,1,2,2,2,1
1,2,5,10,0,9,1,1
1,2,0,10,0,9,1,1
1,2,0,10,0,9,1,1
1,2,0,10,0,9,1,1
1,2,0,10,0,9,1,1
1,2,1,1,1,1,2,1
1,1,1,1,1,1,1,1
endlayer

layer
1,1,1,1,1,1,1,1
1,6,2,2,2,2,2,1
1,4,5,1,1,2,2,1
1,4,0,10,0,2,2,1
1,4,0,10,0,2,2,1
1,4,0,10,0,2,2,1
1,4,0,10,0,2,2,1
1,4,0,10,0,2,2,1
1,6,2,2,2,2,2,1
1,1,1,1,1,1,1,1
endlayer

layer
1,1,1,1,1,1,1,1
1,6,2,2,2,2,2,1
1,0,0,11,1,1,2,1
1,0,0,0,0,2,2,1
1,0,0,0,0,2,2,1
1,0,0,0,0,2,2,1
1,0,0,0,0,2,2,1
1,0,0,0,0,2,2,1
1,6,2,2,2,2,2,1
1,1,1,1,1,1,1,1
endlayer

layer
1,1,1,1,1,1,1,1
1,6,2,2,2,2,2,1
1,0,0,0,11,1,2,1
1,0,0,0,0,1,2,1
1,0,0,0,0,2,2,1
1,0,0,0,0,2,2,1
1,0,0,0,0,2,2,1
1,0,0,0,0,2,2,1
1,6,2,2,2,2,2,1
1,1,1,1,1,1,1,1
endlayer

layer
1,1,1,1,1,1,1,1
1,8,4,4,4,4,6,1
1,0,0,0,0,11,2,1
1,10,10,10,10,1,2,1
1,12,0,0,0,1,2,1
1,0,0,0,0,2,2,1
1,0,0,0,0,2,2,1
1,0,0,0,0,2,2,1
1,8,2,2,2,2,2,1
1,1,1,1,1,1,1,1
endlayer

layer
1,1,1,1,1,1,1,1
1,6,0,0,0,0,6,1
1,1,0,0,0,0,2,1
1,1,0,0,0,13,2,1
1,1,0,0,0,1,2,1
1,1,0,0,0,1,2,1
1,1,0,0,0,2,2,1
1,1,14,14,14,2,2,1
1,2,2,2,2,2,2,1
1,1,1,1,1,1,1,1
endlayer

layer
1,1,1,1,1,1,1,1
1,6,0,0,0,0,6,1
1,1,0,0,0,0,2,1
1,1,0,0,0,0,2,1
1,1,0,0,0,13,2,1
1,1,0,0,0,1,2,1
1,1,0,0,0,1,2,1
1,1,2,2,2,2,2,1
1,1,2,2,2,2,2,1
1,1,1,1,1,1,1,1
endlayer

layer
1,1,1,1,1,1,1,1
1,8,0,0,15,0,8,1
1,1,0,0,0,0,2,1
1,1,0,0,0,0,2,1
1,1,0,0,0,0,2,1
1,1,0,0,0,13,2,1
1,1,0,0,0,1,2,1
1,1,2,2,2,1,2,1
1,1,2,2,2,2,2,1
1,1,1,1,1,1,1,1
endlayer

layer
1,1,1,1,1,1,1,1
1,6,1,1,1,1,2,1
1,1,16,0,10,0,2,1
1,1,16,0,10,0,2,1
1,1,16,0,10,0,2,1
1,1,16,0,10,0,2,1
1,1,16,0,10,13,2,1
1,1,2,2,1,1,2,1
1,1,2,2,2,2,2,1
1,1,1,1,1,1,1,1
endlayer

layer
17,17,17,11,1,1,1,1
1,6,1,1,1,1,6,1
1,1,2,0,10,0,4,1
1,1,1,0,10,0,4,1
1,1,1,0,10,0,4,1
1,1,1,0,10,0,4,1
1,1,1,0,10,0,4,1
1,1,2,2,1,13,4,1
1,1,2,2,2,2,6,1
1,1,1,1,1,1,1,1
endlayer

layer
17,17,17,17,11,1,1,1
1,1,1,1,1,1,6,1
1,1,2,0,0,0,0,1
1,1,2,0,0,0,0,1
1,1,2,0,0,0,0,1
1,2,2,0,0,0,0,1
1,2,1,0,0,0,0,1
1,2,2,1,18,0,0,1
1,2,2,2,2,2,6,1
1,1,1,1,1,1,1,1
endlayer

layer
17,17,17,17,17,11,1,1
1,1,1,1,1,1,6,1
1,1,2,0,0,0,0,1
1,1,2,0,0,0,0,1
1,1,2,0,0,0,0,1
1,2,2,0,0,0,0,1
1,2,1,0,0,0,0,1
1,2,1,18,0,0,0,1
1,2,2,2,2,2,6,1
1,1,1,1,1,1,1,1
endlayer

layer
17,17,17,17,17,17,11,1
1,1,1,1,1,1,8,1
1,1,2,0,0,0,0,1
1,1,2,0,0,0,0,1
1,1,2,0,0,0,0,1
1,6,1,0,0,0,7,1
1,6,1,10,10,10,10,1
1,6,18,0,0,0,0,1
1,6,4,4,4,4,8,1
1,1,1,1,1,1,1,1
endlayer

layer
17,17,17,17,17,17,17,17
1,1,1,1,1,1,18,17
1,1,2,19,19,19,1,13
1,1,2,0,0,0,1,1
1,1,1,0,0,0,1,1
1,1,1,0,0,0,1,1
5,1,5,0,0,0,1,1
17,1,0,0,0,0,1,1
17,1,0,0,0,0,6,1
17,1,1,1,1,1,1,1
endlayer

layer
17,17,17,17,17,17,17,17
1,1,1,1,1,18,17,17
1,1,1,1,1,1,1,17
1,1,1,0,0,0,1,13
1,1,1,0,0,0,1,1
5,1,5,0,0,0,1,1
17,1,0,0,0,0,1,1
17,1,0,0,0,0,1,1
17,1,0,0,0,0,6,1
17,1,1,1,1,1,1,1
endlayer

layer
17,17,17,17,17,17,17,17
17,17,17,17,17,17,17,17
17,17,17,1,1,1,1,17
17,17,17,0,0,0,1,17
17,17,17,0,0,0,1,13
17,17,0,0,0,0,1,1
17,13,0,0,0,0,1,1
17,1,0,0,0,0,1,1
17,1,0,0,0,0,8,1
17,1,1,1,1,1,1,1
endlayer

layer
17,17,17,17,17,17,17,17
17,17,17,17,17,17,17,17
17,17,17,1,1,1,1,17
17,17,17,10,0,0,1,17
17,17,0,10,0,0,1,17
17,17,0,10,0,0,1,13
17,17,0,10,0,0,1,1
17,13,0,10,0,0,1,1
17,1,1,1,1,1,6,1
17,1,1,1,1,1,1,1
endlayer

layer
17,17,17,17,17,17,17,17
17,17,17,17,17,17,17,17
17,17,17,8,1,1,8,17
17,17,0,21,20,20,2,17
17,17,0,21,20,20,2,17
17,17,0,21,0,20,2,17
17,17,0,21,20,20,2,17
17,17,0,21,20,20,2,17
17,17,6,1,1,1,8,17
17,17,17,17,17,17,17,17
endlayer

layer
17,17,17,17,17,17,17,17
17,17,17,0,0,0,0,17
17,17,0,6,0,0,6,17
17,17,0,0,0,0,0,17
17,17,0,0,0,0,0,17
17,17,0,0,0,0,0,17
17,17,0,0,0,0,0,17
17,17,0,0,0,0,0,17
17,17,6,0,0,0,6,17
17,17,17,17,17,17,17,17
endlayer

layer
17,17,17,17,17,17,17,17
17,17,0,0,0,0,0,17
17,17,0,6,0,0,6,17
17,17,0,0,0,0,0,17
17,17,0,0,0,0,0,17
17,17,0,0,0,0,0,17
17,17,0,0,0,0,0,17
17,17,0,0,0,0,0,17
17,17,6,0,0,0,6,17
17,17,17,17,17,17,17,17
endlayer

layer
17,17,17,17,17,17,17,17
17,17,0,0,0,0,0,17
17,17,0,6,0,0,6,17
17,17,0,0,0,0,0,17
17,17,0,0,0,0,0,17
17,17,0,0,0,0,0,17
17,17,0,0,0,0,0,17
17,17,0,0,0,0,0,17
17,17,6,0,0,0,6,17
17,17,17,17,17,17,17,17
endlayer

layer
17,17,17,17,17,17,17,17
17,17,0,0,0,0,0,17
17,17,0,8,0,0,8,17
17,17,0,0,0,0,0,17
17,17,0,0,0,0,0,17
17,17,0,0,0,0,0,17
17,17,0,0,0,0,0,17
17,17,0,0,0,0,0,17
17,17,8,0,0,0,8,17
17,17,17,17,17,17,17,17
endlayer

layer
17,17,17,17,17,17,17,17
17,17,22,22,22,22,22,22
17,17,22,23,23,23,23,22
17,17,22,25,22,22,24,22
17,17,22,25,22,0,24,22
17,17,22,25,22,22,24,22
17,17,22,25,0,22,24,22
17,17,22,25,22,22,24,22
17,17,22,26,26,26,26,22
17,17,22,22,22,22,22,22
endlayer

