
# Created by Ruins mod version 16.7 Ingame Parser
# authoring Player: lafuller

weight=1
embed_into_distance=4
acceptable_target_blocks=
unacceptable_target_blocks=flowing_water,water,flowing_lava,lava,ice,bedrock,netherrack,nether_brick,nether_brick_fence,soul_sand,quartz_ore,end_stone,obsidian,iron_bars,cloud,flesh,ash_block,slime_grass,slime_congealed,slime_dirt
biomesToSpawnIn=plains,mutated_plains,forest,birch forest,taiga,woodland,woodlands,prarie,meadow,badlands,lavender fields,flower field,sunflower plains
dimensions=10,10,13
allowable_overhang=0
max_leveling=4
leveling_buffer=-1
preserve_water=0
preserve_lava=0

rule1=0,100,minecraft:stone-6
rule2=0,100,stonebrick-0,stonebrick-0,stonebrick-0,stonebrick-0,stonebrick-1,stonebrick-2,stonebrick-2,stone-5,stone-6,cobblestone
rule3=0,100,stonebrick-0,stonebrick-2,stonebrick-2,stonebrick-1,stonebrick-1,cobblestone
rule4=0,100,stonebrick-0,stonebrick-1,stonebrick-2,stone-5,stone-5,stone-6,mycelium-0,mycelium
rule5=0,100,stonebrick-0,stonebrick-0,stonebrick-2,mycelium-0,mycelium-0,mycelium-0,mycelium
rule6=0,100,preserveBlock
rule7=0,100,minecraft:stone-5
rule8=0,100,stonebrick-0,stonebrick-0,stonebrick-0,stonebrick-0,stonebrick-1,stonebrick-2,stonebrick-2,stone-5,stone-6,cobblestone,gravel
rule9=0,100,minecraft:cobblestone_wall-0
rule10=0,100,minecraft:stone_brick_stairs-3
rule11=0,100,minecraft:log-0
rule12=0,100,minecraft:wooden_slab-9
rule13=0,100,ChestGenHook:chests/stronghold_corridor:5-2
rule14=0,100,minecraft:ladder-4
rule15=0,100,minecraft:stone_brick_stairs-0
rule16=0,100,planks-0
rule17=0,100,planks-0,oak_stairs-0,oak_stairs-1,oak_stairs-4,oak_stairs-5,air
rule18=0,100,planks-1,spruce_stairs-0,spruce_stairs-1,spruce_stairs-4,spruce_stairs-5,air,air,air
rule19=0,100,planks-5,dark_oak_stairs-0,dark_oak_stairs-1,dark_oak_stairs-4,dark_oak_stairs-5,air,air,air,air,air,air
rule20=0,100,minecraft:log2-1
rule21=0,100,minecraft:cauldron-0
rule22=0,100,minecraft:furnace-3
rule23=0,100,minecraft:log-1
rule24=0,100,minecraft:log-9
rule25=0,100,minecraft:log-5
rule26=0,100,minecraft:log2-9

layer
2,2,2,2,2,1,2,2,2,2,2,2,1
2,2,2,2,2,2,3,3,3,3,3,3,2
2,2,2,2,2,2,3,4,4,4,3,3,2
1,2,2,2,2,1,3,4,5,5,4,3,2
2,3,3,3,3,3,3,4,5,5,4,3,2
2,3,3,4,5,4,4,5,5,4,4,3,2
2,3,4,5,5,5,5,4,4,3,3,3,2
2,3,4,4,4,5,4,4,3,1,2,2,1
2,3,3,3,3,3,3,3,3,2,6,6,6
1,2,2,2,2,2,2,2,2,1,6,6,6
endlayer

layer
10,8,8,8,8,7,8,8,8,9,8,8,7
10,8,8,8,8,8,11,12,12,12,12,11,8
10,8,8,8,8,8,1,0,0,0,0,12,8
7,8,8,8,8,7,13,0,0,0,0,12,8
8,11,12,12,12,11,0,0,0,0,0,12,9
8,12,0,0,0,0,0,0,0,0,0,12,8
9,12,0,0,0,0,0,0,0,0,0,11,8
8,12,0,0,0,0,0,0,0,7,9,8,7
8,11,0,0,14,14,0,0,11,8,6,6,6
7,8,8,9,8,8,9,8,8,7,6,6,6
endlayer

layer
6,10,8,8,8,1,8,8,8,9,8,8,1
6,10,8,8,8,8,11,0,0,0,0,11,8
6,10,8,8,8,8,0,0,0,0,0,0,8
1,8,8,8,8,1,0,0,0,0,0,0,8
8,11,0,0,0,11,0,0,0,0,0,0,9
8,0,0,0,0,0,0,0,0,0,0,0,8
9,0,0,0,0,0,0,0,0,0,0,11,8
8,0,0,0,0,0,0,0,0,1,9,8,1
8,11,0,0,14,14,0,0,11,8,6,6,6
1,8,8,9,8,8,9,8,8,1,6,6,6
endlayer

layer
6,6,10,15,15,7,8,8,8,9,8,8,7
6,6,10,8,8,8,11,0,0,0,0,11,8
6,6,10,8,8,8,0,0,0,0,0,0,8
7,8,8,8,8,7,0,0,0,0,0,0,8
8,11,0,0,0,11,0,0,0,0,0,0,9
8,0,0,0,0,0,0,0,0,0,0,0,8
9,0,0,0,0,0,0,0,0,0,0,11,8
8,0,0,0,0,0,0,0,0,7,9,8,7
8,11,0,0,14,14,0,0,11,8,6,6,6
7,8,8,9,8,8,9,8,8,7,6,6,6
endlayer

layer
6,6,6,6,6,1,8,8,8,8,8,8,1
6,6,6,15,15,8,17,18,18,18,17,16,8
6,6,6,10,8,8,18,19,19,18,18,16,8
1,8,8,17,18,1,19,19,19,19,18,16,8
8,17,17,18,19,19,0,0,19,19,18,18,8
8,17,18,19,0,0,0,0,19,19,18,17,8
8,17,18,19,19,0,0,19,19,18,17,17,8
8,17,17,18,19,19,19,18,18,1,8,8,1
8,17,17,17,14,14,18,17,17,8,6,6,6
1,8,8,8,8,8,8,8,8,1,6,6,6
endlayer

layer
6,6,6,6,6,20,0,0,6,6,6,6,20
6,6,6,6,0,0,0,0,0,0,6,1,6
6,6,0,0,0,0,0,0,0,0,0,1,6
20,0,0,0,0,20,0,0,0,0,0,21,6
6,0,0,0,0,0,0,0,0,0,0,0,0
6,0,0,0,0,0,0,0,0,0,0,0,6
6,0,0,0,0,0,0,0,0,0,0,0,6
6,0,0,0,0,0,0,0,0,20,0,6,20
6,6,0,0,0,0,0,0,0,0,6,6,6
20,6,6,6,6,20,0,6,6,20,6,6,6
endlayer

layer
6,6,6,6,0,20,0,0,0,0,6,6,20
6,6,0,0,0,0,0,0,0,0,0,6,6
6,0,0,0,0,0,0,0,0,0,0,0,6
20,0,0,0,0,20,0,0,0,0,0,22,0
0,0,0,0,0,0,0,0,0,0,0,0,0
0,0,0,0,0,0,0,0,0,0,0,0,0
0,0,0,0,0,0,0,0,0,0,0,0,6
6,0,0,0,0,0,0,0,0,23,0,0,20
6,0,0,0,0,0,0,0,0,0,0,6,6
20,6,6,0,0,20,0,0,0,20,6,6,6
endlayer

layer
6,6,6,0,0,20,0,0,0,0,0,6,23
6,0,0,0,0,0,0,0,0,0,0,0,6
0,0,0,0,0,0,0,0,0,0,0,0,0
20,0,0,0,0,20,0,0,0,0,0,0,0
0,0,0,0,0,0,0,0,0,0,0,0,0
0,0,0,0,0,0,0,0,0,0,0,0,0
0,0,0,0,0,0,0,0,0,0,0,0,0
0,0,0,0,0,0,0,0,0,23,0,0,20
6,0,0,0,0,0,0,0,0,0,0,0,6
23,6,0,0,0,23,0,0,0,20,0,6,6
endlayer

layer
6,6,0,0,0,20,0,0,0,0,0,0,23
0,0,0,0,0,0,0,0,0,0,0,0,0
0,0,0,0,0,0,0,0,0,0,0,0,0
20,0,0,0,0,23,0,0,0,0,0,0,0
0,0,0,0,0,0,0,0,0,0,0,0,0
0,0,0,0,0,0,0,0,0,0,0,0,0
0,0,0,0,0,0,0,0,0,0,0,0,0
0,0,0,0,0,0,0,0,0,0,0,0,23
0,0,0,0,0,0,0,0,0,0,0,0,0
6,0,0,0,0,23,0,0,0,20,0,0,6
endlayer

layer
6,0,0,0,0,20,24,0,0,0,0,0,0
0,0,0,0,0,25,0,0,0,0,0,0,0
0,0,0,0,0,25,0,0,0,0,0,0,0
20,26,24,24,24,23,0,0,0,0,0,0,0
25,0,0,0,0,25,0,0,0,0,0,0,0
25,0,0,0,0,0,0,0,0,0,0,0,0
0,0,0,0,0,0,0,0,0,0,0,0,0
0,0,0,0,0,0,0,0,0,0,0,0,0
0,0,0,0,0,0,0,0,0,25,0,0,0
0,0,0,0,0,0,0,0,24,20,0,0,0
endlayer

