
# Created by Ruins mod version 16.7 Ingame Parser
# authoring Player: lafuller

weight=1
embed_into_distance=7
acceptable_target_blocks=
unacceptable_target_blocks=flowing_water,water,flowing_lava,lava,ice,bedrock,netherrack,nether_brick,nether_brick_fence,soul_sand,quartz_ore,gravel,end_stone,obsidian,iron_bars,cloud,flesh,ash_block,slime_grass,slime_congealed,slime_dirt
dimensions=18,9,9
allowable_overhang=0
max_leveling=7
leveling_buffer=-1
preserve_water=0
preserve_lava=0

rule1=0,100,stonebrick-0,stonebrick-1,stonebrick-1,stonebrick-1,stonebrick-2,stonebrick-2,stone-5,stone-5,stone-6,cobblestone,cobblestone
rule2=0,100,minecraft:stone_brick_stairs-0
rule3=0,100,minecraft:stone_brick_stairs-2
rule4=0,100,minecraft:stone_brick_stairs-3
rule5=0,100,minecraft:sea_lantern-0
rule6=0,100,minecraft:stone_brick_stairs-1
rule7=0,100,minecraft:stone_brick_stairs-6
rule8=0,100,minecraft:stone_brick_stairs-4
rule9=0,100,preserveBlock
rule10=0,100,minecraft:stone_brick_stairs-7
rule11=0,100,minecraft:cobblestone_wall-0
rule12=0,100,minecraft:stone_brick_stairs-5
rule13=0,100,minecraft:stone_slab-5
rule14=0,100,minecraft:water-0
rule15=0,100,minecraft:stone_slab-13
rule16=0,100,minecraft:double_stone_slab-5

layer
1,1,1,1,1,1,1,1,1
1,1,1,1,1,1,1,1,1
1,1,1,1,1,1,1,1,1
1,1,1,1,1,1,1,1,1
1,1,1,1,1,1,1,1,1
1,1,1,1,1,1,1,1,1
1,1,1,1,1,1,1,1,1
1,1,1,1,1,1,1,1,1
1,1,1,1,1,1,1,1,1
endlayer

layer
1,1,1,1,1,1,1,1,1
1,1,1,1,1,1,1,1,1
1,1,1,1,1,1,1,1,1
1,1,1,1,1,1,1,1,1
1,1,1,1,1,1,1,1,1
1,1,1,1,1,1,1,1,1
1,1,1,1,1,1,1,1,1
1,1,1,1,1,1,1,1,1
1,1,1,1,1,1,1,1,1
endlayer

layer
1,1,1,1,1,1,1,1,1
1,1,1,1,1,1,1,1,1
1,1,1,1,1,1,1,1,1
1,1,1,1,1,1,1,1,1
1,1,1,1,1,1,1,1,1
1,1,1,1,1,1,1,1,1
1,1,1,1,1,1,1,1,1
1,1,1,1,1,1,1,1,1
1,1,1,1,1,1,1,1,1
endlayer

layer
1,1,1,1,1,1,1,1,1
1,1,1,1,1,1,1,1,1
1,1,1,1,1,1,1,1,1
1,1,1,1,1,1,1,1,1
1,1,1,1,1,1,1,1,1
1,1,1,1,1,1,1,1,1
1,1,1,1,1,1,1,1,1
1,1,1,1,1,1,1,1,1
1,1,1,1,1,1,1,1,1
endlayer

layer
1,1,1,1,1,1,1,1,1
1,1,1,1,1,1,1,1,1
1,1,1,1,1,1,1,1,1
1,1,1,1,1,1,1,1,1
1,1,1,1,1,1,1,1,1
1,1,1,1,1,1,1,1,1
1,1,1,1,1,1,1,1,1
1,1,1,1,1,1,1,1,1
1,1,1,1,1,1,1,1,1
endlayer

layer
1,1,1,1,1,1,1,1,1
1,1,1,1,1,1,1,1,1
1,1,1,1,1,1,1,1,1
1,1,1,1,1,1,1,1,1
1,1,1,1,1,1,1,1,1
1,1,1,1,1,1,1,1,1
1,1,1,1,1,1,1,1,1
1,1,1,1,1,1,1,1,1
1,1,1,1,1,1,1,1,1
endlayer

layer
1,1,1,2,2,2,1,1,1
1,1,1,1,1,1,1,1,1
1,1,1,1,1,1,1,1,1
4,1,1,1,1,1,1,1,3
4,1,1,1,5,1,1,1,3
4,1,1,1,1,1,1,1,3
1,1,1,1,1,1,1,1,1
1,1,1,1,1,1,1,1,1
1,1,1,6,6,6,1,1,1
endlayer

layer
8,8,10,9,9,9,7,8,7
10,1,1,3,2,4,1,1,7
8,1,1,1,1,1,1,1,8
9,6,1,11,11,11,1,6,9
9,4,1,11,11,11,1,3,9
9,2,1,11,11,11,1,2,9
12,1,1,1,1,1,1,1,12
10,1,1,3,6,4,1,1,7
10,12,10,9,9,9,7,12,7
endlayer

layer
10,8,10,9,9,9,7,8,8
10,1,1,9,9,9,1,1,7
8,1,1,3,13,4,1,1,8
9,9,6,14,14,14,6,9,9
9,9,13,14,14,14,13,9,9
9,9,2,14,14,14,2,9,9
12,1,1,3,13,4,1,1,12
10,1,1,9,9,9,1,1,7
12,12,10,9,9,9,7,12,7
endlayer

layer
13,15,8,9,9,9,10,2,13
4,1,3,9,9,9,15,1,15
12,15,13,9,9,9,13,6,7
9,9,9,9,9,9,9,9,9
9,9,9,9,9,9,9,9,9
9,9,9,9,9,9,9,9,9
10,2,13,9,9,9,13,15,8
15,1,15,9,9,9,4,1,3
13,6,7,9,9,9,12,15,13
endlayer

layer
2,13,15,9,9,9,15,8,3
10,1,7,9,9,9,13,1,13
15,13,6,9,9,9,4,12,15
9,9,9,9,9,9,9,9,9
9,9,9,9,9,9,9,9,9
9,9,9,9,9,9,9,9,9
15,8,3,9,9,9,2,13,15
13,1,13,9,9,9,10,1,7
4,12,15,9,9,9,15,13,6
endlayer

layer
10,2,13,9,9,9,13,15,8
15,1,15,9,9,9,4,1,3
13,6,7,9,9,9,12,15,13
9,9,9,9,9,9,9,9,9
9,9,9,9,9,9,9,9,9
9,9,9,9,9,9,9,9,9
13,15,8,9,9,9,10,2,13
4,1,3,9,9,9,15,1,15
12,15,13,9,9,9,13,6,7
endlayer

layer
15,8,3,9,9,9,2,13,15
13,1,13,9,9,9,10,1,7
13,12,15,9,9,9,15,13,13
9,9,9,9,9,9,9,9,9
9,9,9,9,9,9,9,9,9
9,9,9,9,9,9,9,9,9
13,13,15,9,9,9,15,8,13
10,1,7,9,9,9,13,1,13
15,13,6,9,9,9,4,12,15
endlayer

layer
13,15,8,9,9,9,10,2,13
4,1,3,15,9,15,1,1,15
12,1,13,7,9,10,13,6,7
9,15,12,9,9,9,12,15,9
9,9,9,9,9,9,9,9,9
9,15,8,9,9,9,8,15,9
10,2,13,7,9,10,13,1,8
15,1,1,15,9,15,4,1,3
13,6,7,9,9,9,12,15,13
endlayer

layer
2,13,15,9,9,9,15,8,3
10,1,1,13,16,13,1,1,13
15,1,1,1,1,1,1,1,15
9,13,1,15,9,15,1,13,9
9,16,1,9,9,9,1,16,9
9,13,1,15,9,15,1,13,9
15,1,1,1,1,1,1,1,15
13,1,1,13,16,13,1,1,7
4,12,15,9,9,9,15,13,6
endlayer

layer
10,2,13,9,9,9,13,15,8
15,1,15,9,9,9,15,1,3
13,15,1,2,13,2,1,15,13
9,9,4,9,9,9,3,9,9
9,9,13,9,9,9,13,9,9
9,9,4,9,9,9,3,9,9
13,15,1,6,13,6,1,15,13
4,1,15,9,9,9,1,1,15
12,15,13,9,9,9,13,6,7
endlayer

layer
15,8,3,9,9,9,2,13,15
13,1,13,9,9,9,10,1,7
4,12,15,8,15,8,15,13,6
9,9,10,1,15,1,7,9,9
9,9,15,15,9,15,15,9,9
9,9,10,1,15,1,7,9,9
2,13,15,12,15,12,15,8,3
10,1,7,9,9,9,13,1,13
15,13,6,9,9,9,4,12,15
endlayer

layer
9,9,9,9,9,9,9,9,9
9,9,9,9,9,9,9,9,9
9,9,9,9,9,9,9,9,9
9,9,9,1,2,1,9,9,9
9,9,9,4,9,3,9,9,9
9,9,9,1,6,1,9,9,9
9,9,9,9,9,9,9,9,9
9,9,9,9,9,9,9,9,9
9,9,9,9,9,9,9,9,9
endlayer

