# Gilly's Adobe Well #3

# template generated with Ruins mod version 16.5 Ingame Parser
# Structure created and developed by Gilly

weight=1
embed_into_distance=19
acceptable_target_blocks=
unacceptable_target_blocks=flowing_water,water,flowing_lava,lava
dimensions=24,8,8
allowable_overhang=0
max_leveling=7
leveling_buffer=-1
preserve_water=0
preserve_lava=0

rule1=0,100,minecraft:double_stone_slab-9
rule2=0,100,minecraft:water-0
rule3=0,100,minecraft:stone_slab-1
rule4=0,100,minecraft:sandstone_stairs-0
rule5=0,100,minecraft:sandstone-2
rule6=0,100,minecraft:sandstone-1
rule7=0,100,minecraft:stone_slab-9
rule8=0,100,minecraft:sandstone_stairs-5
rule9=0,100,minecraft:sandstone_stairs-2
rule10=0,100,minecraft:sandstone_stairs-7
rule11=0,100,minecraft:sandstone_stairs-1
rule12=0,100,minecraft:sandstone-0
rule13=0,100,preserveBlock
rule14=0,100,minecraft:sandstone_stairs-4
rule15=0,100,minecraft:sandstone_stairs-3
rule16=0,100,minecraft:iron_bars-0
rule17=0,100,minecraft:spruce_fence-0
rule18=0,100,minecraft:spruce_fence_gate-0
rule19=0,100,minecraft:wooden_slab-1

layer
1,1,1,1,1,1,1,1
1,1,1,1,1,1,1,1
1,1,1,1,1,1,1,1
1,1,1,1,1,1,1,1
1,1,1,1,1,1,1,1
1,1,1,1,1,1,1,1
1,1,1,1,1,1,1,1
1,1,1,1,1,1,1,1
endlayer

layer
1,1,1,1,1,1,1,1
1,1,1,1,1,1,1,1
1,1,1,1,1,1,1,1
1,1,1,2,2,1,1,1
1,1,1,2,2,1,1,1
1,1,1,1,1,1,1,1
1,1,1,1,1,1,1,1
1,1,1,1,1,1,1,1
endlayer

layer
1,1,1,1,1,1,1,1
1,1,1,1,1,1,1,1
1,1,1,1,1,1,1,1
1,1,1,2,2,1,1,1
1,1,1,2,2,1,1,1
1,1,1,1,1,1,1,1
1,1,1,1,1,1,1,1
1,1,1,1,1,1,1,1
endlayer

layer
1,1,1,1,1,1,1,1
1,1,1,1,1,1,1,1
1,1,1,1,1,1,1,1
1,1,1,2,2,1,1,1
1,1,1,2,2,1,1,1
1,1,1,1,1,1,1,1
1,1,1,1,1,1,1,1
1,1,1,1,1,1,1,1
endlayer

layer
1,1,1,1,1,1,1,1
1,1,1,1,1,1,1,1
1,1,1,1,1,1,1,1
1,1,1,2,2,1,1,1
1,1,1,2,2,1,1,1
1,1,1,1,1,1,1,1
1,1,1,1,1,1,1,1
1,1,1,1,1,1,1,1
endlayer

layer
1,1,1,1,1,1,1,1
1,1,1,3,3,3,3,1
1,1,1,3,3,3,4,1
1,1,1,0,0,5,1,1
1,1,1,0,0,1,1,1
1,1,1,1,1,1,1,1
1,1,1,1,1,1,1,1
1,1,1,1,1,1,1,1
endlayer

layer
1,1,1,1,1,1,1,1
1,1,1,0,0,0,0,1
1,1,1,0,0,0,0,1
1,1,1,0,0,6,4,1
1,1,1,0,0,1,1,1
1,1,1,1,1,1,1,1
1,1,1,1,1,1,1,1
1,1,1,1,1,1,1,1
endlayer

layer
1,1,1,1,1,1,1,1
1,1,1,0,0,0,0,1
1,1,1,0,0,0,0,1
1,1,1,0,0,6,0,1
1,1,1,0,0,1,4,1
1,1,1,1,1,1,1,1
1,1,1,1,1,1,1,1
1,1,1,1,1,1,1,1
endlayer

layer
1,1,1,1,1,1,1,1
1,1,1,7,7,7,7,1
1,1,1,7,7,7,0,1
1,1,1,0,0,5,0,1
1,1,1,0,0,1,0,1
1,1,1,1,1,1,4,1
1,1,1,1,1,1,1,1
1,1,1,1,1,1,1,1
endlayer

layer
1,1,1,1,1,1,1,1
1,1,1,1,1,1,1,1
1,1,1,1,1,1,8,1
1,1,1,0,0,1,0,1
1,1,1,0,0,5,0,1
1,1,5,3,3,3,0,1
1,1,1,9,3,3,3,1
1,1,1,1,1,1,1,1
endlayer

layer
1,1,1,1,1,1,1,1
1,1,1,1,1,1,1,1
1,1,1,1,1,1,1,1
1,1,1,0,0,1,8,1
1,1,1,0,0,6,0,1
1,1,6,0,0,0,0,1
1,1,9,0,0,0,0,1
1,1,1,1,1,1,1,1
endlayer

layer
1,1,1,1,1,1,1,1
1,1,1,1,1,1,1,1
1,1,1,1,1,1,1,1
1,1,1,0,0,1,1,1
1,1,1,0,0,6,8,1
1,1,6,0,0,0,0,1
1,9,0,0,0,0,0,1
1,1,1,1,1,1,1,1
endlayer

layer
1,1,1,1,1,1,1,1
1,1,1,1,1,1,1,1
1,1,1,1,1,1,1,1
1,1,1,0,0,1,1,1
1,1,1,0,0,5,1,1
1,11,5,7,7,10,1,1
1,0,0,0,7,10,1,1
1,1,1,1,1,1,1,1
endlayer

layer
1,1,1,1,1,1,1,1
1,1,1,1,1,1,1,1
1,1,1,1,1,1,1,1
1,1,1,0,0,1,1,1
1,11,1,0,0,1,1,1
1,0,1,1,1,1,1,1
1,0,0,10,1,1,1,1
1,1,1,1,1,1,1,1
endlayer

layer
1,1,1,1,1,1,1,1
1,1,1,1,1,1,1,1
1,1,1,1,1,1,1,1
12,11,1,0,0,1,1,1
12,0,1,0,0,1,1,1
1,0,1,1,1,1,1,1
1,0,10,1,1,1,1,1
1,1,1,1,1,1,1,1
endlayer

layer
1,1,1,1,1,1,1,1
1,1,1,1,1,1,1,1
11,11,1,1,1,1,1,11
13,0,1,0,0,1,1,13
13,0,1,0,0,1,1,13
4,0,1,1,1,1,1,4
1,14,1,1,1,1,1,1
1,1,9,13,13,15,1,1
endlayer

layer
6,1,1,1,1,1,1,6
11,11,1,1,1,1,1,11
13,0,1,1,1,1,1,13
13,0,1,0,0,1,1,13
13,0,1,0,0,1,1,13
13,14,1,1,1,1,1,13
4,12,1,1,1,1,1,4
6,9,13,13,13,13,15,6
endlayer

layer
13,0,15,1,1,9,13,13
13,0,6,12,12,12,4,13
13,0,1,1,1,1,12,13
13,0,1,0,0,1,1,13
13,14,1,0,0,1,12,13
13,6,1,1,1,1,12,13
13,11,12,12,12,12,11,13
13,13,13,13,13,13,13,13
endlayer

layer
13,0,0,15,9,13,13,13
13,0,4,12,12,4,13,13
13,0,5,11,11,5,4,13
13,14,9,16,0,15,12,13
13,12,9,0,0,15,12,13
13,11,5,4,4,5,11,13
13,13,15,12,12,9,13,13
13,13,13,13,13,13,13,13
endlayer

layer
13,0,0,0,13,13,13,13
13,0,0,4,4,13,13,13
13,0,6,11,11,6,13,13
13,15,9,16,0,15,9,13
13,15,9,0,0,15,9,13
13,13,6,4,4,6,13,13
13,13,13,11,11,13,13,13
13,13,13,13,13,13,13,13
endlayer

layer
13,0,0,0,0,13,13,13
13,0,0,17,17,0,13,13
13,0,17,0,0,17,0,13
0,17,0,16,0,0,17,0
0,17,0,0,0,0,17,0
13,0,17,0,0,17,0,13
13,13,0,17,17,0,13,13
13,13,13,0,0,13,13,13
endlayer

layer
13,0,0,0,0,0,13,13
13,0,0,17,17,0,0,13
0,0,0,0,0,0,0,0
0,0,0,16,0,0,0,0
0,0,0,0,0,0,0,0
0,0,0,0,0,0,0,0
13,0,0,17,17,0,0,13
13,13,0,0,0,0,13,13
endlayer

layer
13,0,0,0,0,0,0,13
0,0,0,17,17,0,0,0
0,0,0,18,0,0,0,0
0,0,0,17,0,0,0,0
0,0,0,18,0,0,0,0
0,0,0,18,0,0,0,0
0,0,0,17,17,0,0,0
13,0,0,0,0,0,0,13
endlayer

layer
0,0,0,0,0,0,0,0
0,0,0,19,19,0,0,0
0,0,0,19,19,0,0,0
0,0,0,19,19,0,0,0
0,0,0,19,19,0,0,0
0,0,0,19,19,0,0,0
0,0,0,19,19,0,0,0
0,0,0,0,0,0,0,0
endlayer

