
# Created by Ruins mod version 16.5 Ingame Parser
# authoring Player: lafuller

weight=1
embed_into_distance=4
acceptable_target_blocks=
unacceptable_target_blocks=flowing_water,water,flowing_lava,lava,ice,bedrock,netherrack,nether_brick,nether_brick_fence,soul_sand,quartz_ore,end_stone,obsidian,iron_bars,cloud,flesh,ash_block,slime_grass,slime_congealed,slime_dirt
dimensions=16,8,10
allowable_overhang=0
max_leveling=7
leveling_buffer=-1
preserve_water=0
preserve_lava=0

rule1=0,100,minecraft:sandstone-2
rule2=0,100,minecraft:double_stone_slab-9
rule3=0,100,minecraft:sandstone-0
rule4=0,100,preserveBlock
rule5=0,100,minecraft:ladder-2
rule6=0,100,minecraft:sandstone_stairs-3
rule7=0,100,minecraft:iron_bars-0
rule8=0,100,minecraft:sandstone_stairs-2
rule9=0,100,minecraft:sandstone-1
rule10=0,100,minecraft:sandstone_stairs-0
rule11=0,100,minecraft:sandstone_stairs-1
rule12=0,100,minecraft:sandstone_stairs-7
rule13=0,100,minecraft:sandstone_stairs-4
rule14=0,100,minecraft:sandstone_stairs-6
rule15=0,100,minecraft:sandstone_stairs-5
rule16=0,100,minecraft:spruce_fence-0
rule17=0,100,minecraft:spruce_stairs-0
rule18=0,100,minecraft:spruce_stairs-2
rule19=0,100,minecraft:wooden_slab-9
rule20=0,100,minecraft:spruce_stairs-3
rule21=0,100,minecraft:spruce_stairs-1
rule22=0,100,minecraft:wooden_slab-1

layer
2,2,2,2,2,1,3,2,2,1
2,3,3,3,3,3,3,3,3,3
3,3,3,3,3,3,3,3,3,3
2,3,3,3,3,3,3,3,3,3
2,3,3,3,3,3,3,3,3,3
3,3,3,3,3,3,3,3,3,3
4,3,3,3,3,3,3,3,3,3
4,3,2,2,2,2,3,2,3,2
endlayer

layer
2,2,2,2,2,1,2,3,3,3
2,3,3,3,3,3,0,0,0,3
2,0,0,0,0,0,0,0,0,2
3,0,0,0,0,0,0,0,0,2
2,5,0,0,0,0,0,0,0,3
2,3,0,0,0,3,3,3,3,3
4,3,0,0,0,3,3,3,3,3
4,2,2,2,2,2,3,2,2,2
endlayer

layer
6,3,2,1,2,3,3,1,1,1
2,3,3,3,3,3,0,0,0,3
2,0,0,0,0,0,0,0,0,2
2,0,0,0,0,0,0,0,0,3
2,5,0,0,0,0,0,0,0,3
2,3,0,0,0,3,3,3,3,2
4,2,0,0,0,3,3,3,3,3
4,2,3,2,3,3,4,6,2,2
endlayer

layer
4,6,3,3,3,1,3,2,3,1
1,3,3,3,3,3,0,0,0,2
2,0,0,0,0,0,0,0,0,3
2,0,0,0,0,0,0,0,0,3
3,5,0,0,0,0,0,0,0,3
1,3,0,0,0,3,3,3,3,1
4,2,0,0,0,3,3,3,3,1
4,2,2,2,2,1,4,4,6,1
endlayer

layer
4,4,6,1,1,1,1,2,2,1
1,2,3,1,3,3,3,3,3,2
2,3,3,1,3,3,3,3,3,2
3,3,3,3,3,7,3,3,3,2
2,5,3,3,3,3,3,3,3,3
1,3,3,3,3,3,3,3,3,1
4,3,3,3,3,3,3,3,8,4
4,1,2,2,2,1,4,4,4,4
endlayer

layer
4,4,4,4,4,2,3,3,3,2
3,2,2,0,2,2,0,0,0,3
2,0,0,0,0,0,0,0,0,2
2,0,0,0,0,0,0,0,0,1
2,5,0,0,0,0,0,0,0,3
3,2,0,0,0,1,3,0,3,2
4,2,0,0,0,2,4,4,4,4
4,2,2,3,2,2,4,4,4,4
endlayer

layer
4,4,4,4,4,1,1,0,3,1
1,2,1,0,2,2,0,0,0,3
2,0,0,0,0,0,0,0,0,0
0,0,0,0,0,0,0,0,0,1
2,5,0,0,0,0,0,0,0,3
2,2,0,0,0,9,3,0,3,1
4,2,0,0,0,2,4,4,4,4
4,1,2,0,3,2,4,4,4,4
endlayer

layer
4,4,4,4,4,1,2,2,1,1
3,2,1,9,1,2,0,0,0,3
3,0,0,0,0,0,0,0,0,2
2,0,0,0,0,0,0,0,0,2
2,5,0,0,0,0,0,0,0,3
1,2,0,0,0,1,3,1,1,1
4,2,0,0,0,2,4,4,4,4
4,1,2,2,2,1,4,4,4,4
endlayer

layer
4,4,4,4,4,2,10,3,10,2
2,2,2,2,2,2,0,0,0,8
2,0,0,0,0,0,0,0,0,10
2,0,0,0,0,0,0,0,0,11
2,5,0,0,0,0,0,0,0,8
2,2,0,0,0,1,11,3,11,2
4,2,0,0,0,3,4,4,4,4
4,3,3,3,2,2,4,4,4,4
endlayer

layer
4,4,4,4,4,1,3,9,3,1
13,12,14,13,12,3,3,3,3,3
12,0,0,0,0,12,3,2,3,9
3,0,0,0,0,12,3,2,3,9
12,5,0,0,0,12,3,3,3,3
15,2,0,0,0,1,3,9,3,1
4,12,0,0,0,14,4,4,4,4
4,15,12,2,14,15,4,4,4,4
endlayer

layer
4,4,4,4,4,16,16,16,16,16
1,1,10,9,10,1,0,0,0,16
6,2,2,2,2,8,0,0,0,16
9,2,3,3,2,8,0,0,0,16
6,5,3,3,2,8,0,0,0,16
1,3,3,3,2,1,16,16,16,16
4,3,2,2,2,8,4,4,4,4
4,1,11,9,11,1,4,4,4,4
endlayer

layer
4,4,4,4,4,4,4,4,4,4
16,1,16,16,16,1,0,0,0,4
16,0,0,0,0,0,0,0,0,4
16,0,0,0,0,0,0,0,0,4
16,0,0,0,0,0,0,0,0,4
16,1,0,0,0,1,0,4,4,4
4,16,0,0,0,16,4,4,4,4
4,16,16,16,16,16,4,4,4,4
endlayer

layer
4,4,4,4,4,4,4,4,4,4
0,2,0,0,0,2,0,0,0,4
0,0,0,0,0,0,0,0,0,4
0,0,0,0,0,0,0,0,0,4
0,0,0,0,0,0,0,0,0,4
0,2,0,0,0,2,0,4,4,4
4,0,0,0,0,0,4,4,4,4
4,4,4,4,4,4,4,4,4,4
endlayer

layer
4,4,4,4,4,4,4,4,4,4
0,9,0,0,0,9,0,0,0,4
0,0,0,0,0,0,0,0,0,4
0,0,0,0,0,0,0,0,0,4
0,0,0,0,0,0,0,0,0,4
0,9,0,0,0,9,0,4,4,4
4,0,0,0,0,0,4,4,4,4
4,4,4,4,4,4,4,4,4,4
endlayer

layer
4,17,17,17,17,17,4,4,4,4
20,9,19,19,19,9,18,0,0,4
20,19,19,19,19,19,18,0,0,4
20,19,19,0,19,19,18,0,0,4
20,19,19,19,19,19,18,0,0,4
20,9,19,19,19,9,18,4,4,4
4,21,21,21,21,21,4,4,4,4
4,4,4,4,4,4,4,4,4,4
endlayer

layer
4,0,0,0,0,0,4,4,4,4
0,22,22,0,22,22,0,0,0,4
0,22,0,0,0,22,0,0,0,4
0,0,0,0,0,0,0,0,0,4
0,22,0,0,0,22,0,0,0,4
0,22,22,0,22,22,0,4,4,4
4,0,0,0,0,0,4,4,4,4
4,4,4,4,4,4,4,4,4,4
endlayer

