
# Created by Ruins mod version 16.7 Ingame Parser
# authoring Player: lafuller

weight=1
embed_into_distance=5
acceptable_target_blocks=
unacceptable_target_blocks=flowing_water,water,flowing_lava,lava,ice,bedrock,netherrack,nether_brick,nether_brick_fence,soul_sand,quartz_ore,end_stone,obsidian,iron_bars,cloud,flesh,ash_block,slime_grass,slime_congealed,slime_dirt
dimensions=12,24,23
allowable_overhang=0
max_leveling=7
leveling_buffer=-1
preserve_water=0
preserve_lava=0

rule1=0,100,preserveBlock
rule2=0,100,minecraft:sandstone_stairs-2
rule3=0,100,minecraft:double_stone_slab-9
rule4=0,100,minecraft:sandstone_stairs-3
rule5=0,100,minecraft:sandstone-0
rule6=0,100,minecraft:sandstone-2
rule7=0,100,minecraft:sandstone_stairs-0
rule8=0,100,minecraft:trapdoor-8
rule9=0,100,minecraft:ladder-3
rule10=0,100,minecraft:trapdoor-9
rule11=0,100,bookshelf,pumpkin,melon_block,hay_block,ChestGenHook:chests/spawn_bonus_chest:5-4,ChestGenHook:chests/village_blacksmith:5-4,ChestGenHook:chests/stronghold_library:5-4,ChestGenHook:chests/simple_dungeon:5-4
rule12=0,100,bookshelf,pumpkin,melon_block,hay_block,ChestGenHook:chests/spawn_bonus_chest:5-3,ChestGenHook:chests/village_blacksmith:5-3,ChestGenHook:chests/stronghold_library:5-3,ChestGenHook:chests/simple_dungeon:5-3
rule13=0,100,minecraft:trapdoor-10
rule14=0,100,minecraft:dirt-0
rule15=0,100,bookshelf,pumpkin,melon_block,hay_block,ChestGenHook:chests/spawn_bonus_chest:5-5,ChestGenHook:chests/village_blacksmith:5-5,ChestGenHook:chests/stronghold_library:5-5,ChestGenHook:chests/simple_dungeon:5-5
rule16=0,100,minecraft:trapdoor-11
rule17=0,100,minecraft:wooden_slab-9
rule18=0,100,minecraft:ladder-2
rule19=0,100,minecraft:stone_slab-1
rule20=0,100,minecraft:carpet-7
rule21=0,100,minecraft:carpet-8
rule22=0,100,minecraft:sandstone_stairs-1
rule23=0,100,minecraft:trapdoor-0
rule24=0,100,minecraft:trapdoor-2
rule25=0,100,minecraft:trapdoor-1
rule26=0,100,minecraft:trapdoor-3
rule27=0,100,minecraft:spruce_stairs-6
rule28=0,100,minecraft:sandstone_stairs-6
rule29=0,100,minecraft:sandstone_stairs-4
rule30=0,100,minecraft:spruce_stairs-5
rule31=0,100,minecraft:spruce_stairs-7
rule32=0,100,minecraft:ladder-5
rule33=0,100,minecraft:jungle_door-5
rule34=0,100,minecraft:jungle_door-4
rule35=0,100,minecraft:jungle_door-6
rule36=0,100,minecraft:spruce_fence-0
rule37=0,100,minecraft:jungle_door-7
rule38=0,100,minecraft:jungle_door-9
rule39=0,100,minecraft:jungle_door-8
rule40=0,100,minecraft:wooden_slab-1
rule41=0,100,minecraft:spruce_fence_gate-3
rule42=0,100,minecraft:spruce_stairs-1
rule43=0,100,minecraft:stone_slab-9
rule44=0,100,minecraft:sandstone_stairs-5
rule45=0,100,minecraft:sandstone_stairs-7
rule46=0,100,minecraft:hay_block-0

layer
1,1,5,3,3,3,3,1,1,1,1,1,1,4,3,3,3,3,2,1,1,1,1
1,1,5,3,5,5,5,6,6,3,5,5,5,6,5,5,6,5,6,6,5,5,6
1,1,5,3,5,5,5,5,5,3,5,5,5,5,5,3,3,3,3,3,3,3,5
1,1,5,3,5,5,5,5,5,3,5,5,5,5,5,3,5,5,5,5,5,5,5
1,1,5,3,5,5,5,5,5,3,5,5,5,5,5,3,5,5,5,5,5,5,5
1,1,5,3,5,5,5,5,5,3,3,3,3,3,3,3,5,5,5,5,5,3,5
1,1,5,3,3,3,3,3,3,3,5,5,5,5,5,3,5,5,5,5,5,3,5
7,7,3,3,3,3,3,3,3,3,5,5,5,5,5,3,5,5,5,5,5,3,5
3,3,5,5,5,3,3,3,3,3,5,5,5,5,5,3,3,3,3,3,3,3,5
5,5,5,5,5,3,3,3,3,3,5,5,5,5,5,3,3,5,5,5,5,3,5
5,5,5,5,5,3,3,3,3,3,5,5,5,5,5,3,3,5,5,5,3,2,1
5,5,5,5,5,3,3,3,3,3,3,3,3,3,3,3,3,5,5,6,1,1,1
3,5,5,5,5,3,3,5,5,5,5,5,3,3,3,6,6,5,3,2,1,1,1
3,3,3,3,3,3,3,5,5,5,5,5,3,3,6,5,5,5,3,2,1,1,1
3,5,5,5,5,5,3,5,5,5,5,5,3,3,5,5,5,5,3,1,1,1,1
3,5,5,5,5,5,3,5,5,5,5,5,3,3,3,3,3,3,3,1,1,1,1
3,6,5,5,5,5,3,5,5,5,5,5,3,5,5,5,5,6,3,1,1,1,1
1,1,6,5,5,5,3,3,3,3,3,3,3,5,5,5,5,6,3,1,1,1,1
1,1,6,5,5,5,3,3,5,5,5,3,3,5,5,5,5,5,3,6,1,1,1
1,1,3,3,3,3,3,3,5,5,5,3,3,5,5,5,5,5,3,5,1,1,1
1,1,1,1,1,4,3,5,5,5,5,3,3,5,5,5,5,5,3,5,1,1,1
1,1,1,1,1,1,1,1,1,1,5,5,3,3,3,3,3,3,3,5,1,1,1
1,1,1,1,1,1,1,1,1,1,5,5,5,5,5,5,5,5,5,5,1,1,1
1,1,1,1,1,1,1,1,1,1,5,5,5,5,5,5,1,1,1,1,1,1,1
endlayer

layer
1,1,6,3,3,3,3,1,1,1,1,1,1,1,4,7,7,2,1,1,1,1,1
1,1,5,3,5,5,5,6,6,3,5,5,5,6,5,5,6,5,6,6,5,5,6
1,1,5,3,5,5,5,5,5,3,5,5,5,5,5,3,3,3,3,3,3,3,5
1,1,5,3,5,5,5,5,5,3,5,5,5,5,5,3,5,5,5,5,5,5,5
1,1,5,3,5,5,5,5,5,3,5,5,5,5,5,3,5,5,5,5,5,5,5
1,1,6,3,5,5,5,5,5,3,3,3,3,3,3,3,5,5,5,5,5,3,5
1,1,5,3,3,3,3,3,3,3,5,5,5,5,5,3,5,5,5,5,5,3,5
1,1,3,3,3,3,3,3,3,3,5,5,5,5,5,3,5,5,5,5,5,3,5
7,7,5,5,5,3,3,3,3,3,5,5,5,5,5,3,3,3,3,3,3,3,5
5,5,5,5,5,3,3,3,3,3,5,5,5,5,5,3,3,5,5,5,5,3,5
5,5,5,5,5,3,3,3,3,3,5,5,5,5,5,3,3,5,5,5,2,1,1
5,5,5,5,5,3,3,3,3,3,3,3,3,3,3,3,3,5,5,6,1,1,1
3,5,5,5,5,3,3,5,5,5,5,5,3,3,3,6,6,5,2,1,1,1,1
3,3,3,3,3,3,3,5,5,5,5,5,3,3,6,5,5,5,2,1,1,1,1
3,5,5,5,5,5,3,5,5,5,5,5,3,3,5,5,5,5,3,1,1,1,1
3,5,5,5,5,5,3,5,5,5,5,5,3,3,3,3,3,3,3,1,1,1,1
3,6,5,5,5,5,3,5,5,5,5,5,3,5,5,5,5,6,3,1,1,1,1
1,1,6,5,5,5,3,3,3,3,3,3,3,5,5,5,5,6,3,1,1,1,1
1,1,6,5,5,5,3,3,5,5,5,3,3,5,5,5,5,5,3,6,1,1,1
1,1,3,3,3,3,3,3,5,5,5,3,3,5,5,5,5,5,3,5,1,1,1
1,1,1,1,1,1,4,5,5,5,5,3,3,5,5,5,5,5,3,5,1,1,1
1,1,1,1,1,1,1,1,1,1,5,5,3,3,3,3,3,3,3,5,1,1,1
1,1,1,1,1,1,1,1,1,1,5,5,5,5,5,5,5,5,5,5,1,1,1
1,1,1,1,1,1,1,1,1,1,5,5,5,5,5,5,1,1,1,1,1,1,1
endlayer

layer
1,1,6,3,3,3,3,1,1,1,1,1,1,1,1,1,1,1,1,1,1,1,1
1,1,5,2,0,0,0,6,6,3,6,5,5,5,2,1,1,5,5,5,5,5,5
1,1,6,5,0,0,0,0,0,3,5,5,5,5,5,3,3,3,3,3,3,3,5
1,1,6,5,0,0,0,0,0,3,5,5,5,5,5,3,8,0,0,0,0,0,5
1,1,5,5,0,0,0,0,0,3,5,5,5,5,5,3,0,0,0,0,0,9,6
1,1,5,3,11,0,0,0,10,3,3,3,3,3,3,3,0,0,0,0,0,3,6
1,1,5,3,3,13,13,3,3,3,0,0,0,0,12,5,0,0,0,0,0,3,5
1,1,5,3,3,3,3,3,3,3,0,0,0,0,0,5,0,0,0,0,11,3,5
1,1,6,5,5,3,3,3,3,6,0,0,0,0,0,3,3,3,3,3,3,3,5
7,7,5,5,5,3,3,3,3,3,0,0,0,0,10,3,3,5,5,5,5,3,6
5,14,14,14,6,3,3,3,3,3,0,4,5,5,5,3,3,5,5,2,1,1,1
5,5,5,5,5,3,3,15,0,0,5,3,3,3,3,3,3,5,6,6,1,1,1
3,5,5,5,5,3,5,0,0,0,0,16,3,3,3,6,6,2,1,1,1,1,1
3,3,3,3,3,3,5,0,0,0,0,0,0,3,6,5,5,2,1,1,1,1,1
5,0,0,0,0,5,5,0,0,0,0,0,0,17,5,5,5,5,3,1,1,1,1
3,18,0,0,0,5,2,0,0,0,0,0,0,17,3,3,3,3,3,1,1,1,1
3,6,0,0,0,5,19,0,0,0,0,0,0,17,5,5,5,6,3,1,1,1,1
1,1,6,0,0,0,5,0,0,0,0,0,0,5,0,0,0,6,3,1,1,1,1
1,1,6,11,0,0,3,3,5,6,5,3,3,18,0,0,0,0,3,6,1,1,1
1,1,3,3,3,3,3,3,5,5,5,3,3,0,0,0,0,0,12,6,1,1,1
1,1,1,1,1,1,1,4,5,5,5,3,3,0,0,0,0,0,0,5,1,1,1
1,1,1,1,1,1,1,1,1,1,5,5,3,3,3,3,17,17,17,5,1,1,1
1,1,1,1,1,1,1,1,1,1,5,5,5,5,5,5,5,5,5,5,1,1,1
1,1,1,1,1,1,1,1,1,1,5,6,5,5,5,6,1,1,1,1,1,1,1
endlayer

layer
1,1,5,3,3,6,3,1,1,1,1,1,1,1,1,1,1,1,1,1,1,1,1
1,1,6,0,0,0,0,6,6,3,6,6,6,2,1,1,1,6,5,6,6,6,6
1,1,5,7,0,0,0,0,0,20,5,5,5,5,6,3,3,3,20,20,20,20,5
1,1,6,5,0,0,0,0,0,20,5,5,5,5,5,3,0,0,0,0,0,0,5
1,1,5,5,0,0,0,0,0,20,5,5,5,5,5,3,0,0,0,0,0,9,5
1,1,5,3,0,0,0,0,0,3,3,20,20,21,3,3,0,0,0,0,0,3,6
1,1,6,3,6,0,0,6,3,3,0,0,0,0,0,5,0,0,0,0,0,3,1
1,1,6,14,14,3,3,3,6,6,0,0,0,0,0,5,0,0,0,0,0,3,1
1,1,22,4,6,5,3,3,3,6,0,0,0,0,0,6,3,3,3,3,3,3,7
1,1,1,1,1,4,3,3,3,3,0,0,0,0,0,3,3,5,5,5,3,3,6
1,1,1,1,5,6,3,3,3,3,0,0,4,5,5,3,3,5,2,1,1,1,1
7,5,5,5,6,3,3,0,0,0,5,3,3,3,3,3,5,5,6,1,1,1,1
3,3,5,5,5,3,5,0,0,0,0,0,3,3,6,6,2,1,1,1,1,1,1
3,3,3,3,3,3,5,0,0,0,0,0,0,3,14,14,2,1,1,1,1,1,1
5,0,0,0,0,5,22,0,0,0,0,0,0,20,5,5,5,7,3,1,1,1,1
5,18,0,0,0,5,0,0,0,0,0,0,0,20,3,3,3,3,3,1,1,1,1
3,6,0,0,0,5,0,0,0,0,0,0,0,20,5,5,5,6,3,1,1,1,1
1,1,6,0,0,0,5,0,0,0,0,0,0,5,0,0,0,6,3,1,1,1,1
1,1,6,0,0,0,3,3,6,6,6,3,3,18,0,0,0,0,3,5,1,1,1
1,1,3,3,3,3,3,3,6,6,6,3,3,0,0,0,0,0,0,5,1,1,1
1,1,1,1,1,1,1,1,4,6,5,5,3,0,0,0,0,0,0,5,1,1,1
1,1,1,1,1,1,1,1,1,1,5,5,3,0,0,3,20,20,21,5,1,1,1
1,1,1,1,1,1,1,1,1,1,6,5,5,5,5,5,6,6,5,6,1,1,1
1,1,1,1,1,1,1,1,1,1,5,5,5,5,5,6,1,1,1,1,1,1,1
endlayer

layer
1,1,5,3,3,3,3,1,1,1,1,1,1,1,1,1,1,1,1,1,1,1,1
1,1,6,0,0,0,0,6,6,3,5,5,2,1,1,1,1,6,5,5,5,5,5
1,1,5,0,0,0,0,0,0,0,5,5,5,5,5,3,3,3,0,0,0,0,6
1,1,5,7,0,0,0,0,0,0,5,5,5,5,5,3,23,0,0,0,0,0,6
1,1,5,5,0,0,0,0,0,0,5,5,5,5,5,3,0,0,0,0,0,9,5
1,1,5,3,0,0,0,0,24,3,3,0,0,0,3,3,0,0,0,0,0,3,6
1,1,22,3,3,24,24,6,3,3,0,0,0,0,0,5,0,0,0,0,0,3,1
1,1,1,1,1,3,3,14,14,3,0,0,0,0,0,5,0,0,0,0,0,3,1
1,1,1,1,1,1,4,14,14,6,0,0,0,0,0,3,3,3,3,3,3,3,1
1,1,1,1,1,1,4,6,6,5,0,0,0,0,25,3,3,3,3,3,3,2,1
1,1,1,1,6,6,6,3,3,3,0,0,0,4,5,3,6,2,1,1,1,1,1
1,4,5,5,6,5,3,0,0,0,5,3,3,3,3,3,1,1,1,1,1,1,1
5,3,3,3,3,3,5,0,0,0,0,26,3,5,2,1,1,1,1,1,1,1,1
3,0,0,0,0,3,22,0,0,0,0,0,0,5,1,1,1,1,1,1,1,1,1
3,0,0,0,0,5,0,0,0,0,0,0,0,0,3,3,3,1,1,1,1,1,1
3,18,0,0,0,5,0,0,0,0,0,0,0,0,3,3,3,7,1,1,1,1,1
3,6,0,0,0,5,0,0,0,0,0,0,0,0,5,5,5,6,1,1,1,1,1
1,1,6,0,0,0,5,0,0,0,0,0,0,5,0,0,0,6,1,1,1,1,1
1,1,6,0,0,0,3,3,22,6,6,3,3,18,0,0,0,0,3,5,1,1,1
1,1,3,3,3,3,3,1,1,1,4,5,0,0,0,0,0,0,0,5,1,1,1
1,1,1,1,1,1,1,1,1,1,5,5,0,0,0,0,0,0,0,5,1,1,1
1,1,1,1,1,1,1,1,1,1,5,5,0,0,0,3,0,0,0,5,1,1,1
1,1,1,1,1,1,1,1,1,1,6,5,5,5,5,5,5,5,5,6,1,1,1
1,1,1,1,1,1,1,1,1,1,22,6,5,5,5,5,1,1,1,1,1,1,1
endlayer

layer
1,1,5,6,3,3,6,1,1,1,1,1,1,1,1,1,1,1,1,1,1,1,1
1,1,5,0,17,27,3,3,3,3,5,2,1,1,1,1,1,5,6,6,5,5,6
1,1,5,0,17,27,17,17,17,17,5,6,1,1,4,6,3,3,27,17,17,17,5
1,1,5,0,17,27,17,17,17,17,5,6,6,7,5,3,28,17,27,17,17,17,5
1,1,5,7,17,27,17,17,17,17,5,5,5,5,5,17,17,17,27,17,17,9,5
1,1,5,3,3,3,17,17,17,3,3,17,17,17,3,17,17,17,27,17,17,6,5
1,1,1,4,3,22,3,3,3,3,17,17,17,17,3,17,17,17,27,17,17,3,1
1,1,1,1,1,1,1,1,1,3,17,17,17,17,3,3,29,28,27,17,17,3,1
1,1,1,1,1,1,1,1,1,3,30,30,30,30,30,3,3,22,3,3,3,6,1
1,1,1,1,1,1,1,1,1,1,28,17,17,17,17,3,6,1,4,3,2,1,1
1,1,1,1,1,1,1,6,3,7,28,0,0,0,4,3,6,1,1,1,1,1,1
1,1,4,5,7,5,6,3,3,3,3,3,3,3,3,6,1,1,1,1,1,1,1
5,5,3,3,3,5,19,17,17,27,17,17,3,2,1,1,1,1,1,1,1,1,1
6,17,17,17,17,3,0,17,17,27,17,17,3,5,1,1,1,1,1,1,1,1,1
3,17,17,17,17,3,0,17,17,27,17,17,6,3,3,3,6,1,1,1,1,1,1
3,18,17,17,17,3,0,17,17,27,17,17,3,3,3,3,2,1,1,1,1,1,1
6,3,30,30,30,30,29,29,28,27,17,17,3,3,3,3,3,3,1,1,1,1,1
1,1,3,17,17,17,3,3,22,3,3,3,3,3,17,31,17,3,1,1,1,1,1
1,1,3,17,17,17,3,6,1,3,3,5,6,18,17,31,17,17,6,5,1,1,1
1,1,3,6,3,3,6,1,1,1,1,5,17,17,17,31,17,17,17,5,1,1,1
1,1,1,1,1,1,1,1,1,1,7,5,17,17,17,31,17,17,17,5,1,1,1
1,1,1,1,1,1,1,1,1,1,6,5,17,17,17,6,17,17,17,5,1,1,1
1,1,1,1,1,1,1,1,1,1,22,5,5,5,5,5,5,5,5,5,1,1,1
1,1,1,1,1,1,1,1,1,1,1,5,5,6,6,6,1,1,1,1,1,1,1
endlayer

layer
1,1,6,3,3,3,3,1,1,1,1,1,1,1,1,1,1,1,1,1,1,1,1
1,1,5,0,0,0,5,5,5,3,6,1,1,1,1,1,1,6,5,5,5,5,6
1,1,5,0,0,0,0,0,0,0,33,1,1,1,1,1,1,3,0,0,32,0,5
1,1,5,0,0,0,0,0,0,0,5,1,1,1,6,34,5,0,0,0,0,0,5
1,1,5,0,0,0,0,0,0,0,5,5,34,5,5,0,0,0,0,0,0,0,5
1,1,6,3,35,5,0,0,0,3,6,0,0,0,5,0,0,0,0,0,0,3,6
1,1,1,1,1,1,5,6,3,3,0,0,0,9,5,0,0,0,0,0,0,3,1
1,1,1,1,1,1,1,1,1,3,0,0,0,0,5,3,5,5,0,0,0,3,1
1,1,1,1,1,1,1,1,1,6,0,0,0,0,0,3,1,1,6,35,5,3,1
1,1,1,1,1,1,1,1,1,1,5,0,0,0,0,33,1,1,1,1,1,1,1
1,1,1,1,1,1,1,36,1,1,5,0,0,0,0,3,36,1,1,1,1,1,1
1,1,1,1,1,6,3,6,34,3,3,3,3,3,3,3,1,1,1,1,1,1,1
6,5,6,34,5,5,0,0,0,0,0,0,3,1,1,1,1,1,1,1,1,1,1
3,0,32,0,0,3,0,0,0,0,0,0,33,1,1,1,1,1,1,1,1,1,1
3,0,0,0,0,5,0,0,0,0,0,0,3,1,1,1,1,1,1,1,1,1,1
5,18,0,0,0,5,0,0,0,0,0,0,17,3,1,1,1,1,1,1,1,1,1
3,5,0,0,0,0,3,5,5,0,0,0,17,5,5,34,5,6,1,1,1,1,1
1,1,5,0,0,9,3,1,1,6,0,0,17,5,0,0,0,5,1,1,1,1,1
1,1,5,0,0,0,33,1,1,5,5,5,3,18,0,0,0,0,3,6,1,1,1
1,1,3,3,3,3,3,1,1,1,1,5,0,0,0,0,0,0,0,5,1,1,1
1,1,1,1,1,1,1,1,1,1,1,5,0,0,0,0,0,0,0,5,1,1,1
1,1,1,1,1,1,1,1,1,1,1,37,0,0,9,3,0,0,0,5,1,1,1
1,1,1,1,1,1,1,1,1,1,1,5,0,0,0,5,5,5,5,6,1,1,1
1,1,1,1,1,1,1,1,1,1,1,6,5,5,5,6,1,1,1,1,1,1,1
endlayer

layer
1,1,6,6,3,1,3,1,1,1,1,1,1,1,1,1,1,1,1,1,1,1,1
1,1,5,0,0,0,5,5,1,3,6,1,1,1,1,1,1,6,5,1,6,5,6
1,1,6,0,0,0,0,0,0,0,38,1,1,1,1,1,1,5,0,0,32,0,5
1,1,1,0,0,0,0,0,0,0,5,1,1,1,6,39,5,0,0,0,0,0,1
1,1,5,0,0,0,0,0,0,0,5,5,38,5,5,0,0,0,0,0,0,0,5
1,1,6,3,39,5,0,0,0,3,3,0,0,0,5,0,0,0,0,0,0,3,6
1,1,1,1,1,1,5,1,3,3,0,0,0,9,5,0,0,0,0,0,0,1,1
1,1,1,1,1,1,1,1,1,3,0,0,0,0,5,3,5,5,0,0,0,3,1
1,1,1,1,1,1,1,1,1,6,0,0,0,0,0,3,1,1,6,39,5,6,1
1,1,1,1,1,1,1,1,1,1,5,0,0,0,0,39,1,1,1,1,1,1,1
1,1,1,1,1,1,1,36,1,1,5,0,0,0,0,3,36,1,1,1,1,1,1
1,1,1,1,1,6,6,6,39,3,3,3,3,3,1,6,1,1,1,1,1,1,1
6,5,6,38,5,5,0,0,0,0,0,0,3,1,1,1,1,1,1,1,1,1,1
6,0,32,0,0,3,0,0,0,0,0,0,39,1,1,1,1,1,1,1,1,1,1
1,0,0,0,0,5,0,0,0,0,0,0,3,1,1,1,1,1,1,1,1,1,1
5,0,0,0,0,5,0,0,0,0,0,0,20,3,1,1,1,1,1,1,1,1,1
3,5,0,0,0,0,3,5,6,0,0,0,20,5,5,38,5,6,1,1,1,1,1
1,1,5,0,0,9,3,1,1,6,0,0,21,5,0,0,0,5,1,1,1,1,1
1,1,1,0,0,0,38,1,1,5,5,5,3,0,0,0,0,0,3,6,1,1,1
1,1,5,3,1,3,6,1,1,1,1,5,0,0,0,0,0,0,0,5,1,1,1
1,1,1,1,1,1,1,1,1,1,1,5,0,0,0,0,0,0,0,1,1,1,1
1,1,1,1,1,1,1,1,1,1,1,38,0,0,9,3,0,0,0,5,1,1,1
1,1,1,1,1,1,1,1,1,1,1,5,17,17,17,5,5,1,5,6,1,1,1
1,1,1,1,1,1,1,1,1,1,1,6,5,5,5,6,1,1,1,1,1,1,1
endlayer

layer
1,1,5,3,3,3,3,1,1,1,1,1,1,1,1,1,1,1,1,1,1,1,1
1,1,5,0,0,0,5,5,5,3,5,1,1,1,1,1,1,5,5,5,5,5,5
1,1,6,0,0,0,0,0,0,0,6,1,1,1,1,1,1,3,0,0,0,25,5
1,1,6,0,0,0,0,0,0,0,5,17,17,17,5,3,5,0,0,0,0,25,5
1,1,6,0,0,0,0,0,0,0,5,6,6,6,5,0,0,0,0,0,0,25,5
1,1,5,3,5,5,0,0,0,3,3,40,40,40,5,0,0,0,0,0,0,3,5
1,1,1,1,1,1,6,3,3,3,0,0,0,0,5,0,0,0,0,0,0,3,1
1,1,1,1,1,1,1,36,41,3,0,0,0,0,5,3,5,5,0,0,0,3,1
1,1,1,1,1,1,1,36,41,3,0,0,0,0,0,3,17,17,6,5,5,3,1
1,1,1,1,1,1,1,36,41,41,5,0,0,0,0,3,17,1,1,1,1,1,1
1,1,1,1,1,1,1,36,41,41,5,0,0,0,0,3,42,1,1,1,1,1,1
1,1,1,1,1,5,3,3,3,3,3,3,3,3,3,3,1,1,1,1,1,1,1
5,5,5,6,5,5,0,0,0,0,0,0,3,8,1,1,1,1,1,1,1,1,1
3,17,0,0,0,3,0,0,0,0,0,0,3,8,1,1,1,1,1,1,1,1,1
3,17,0,0,0,5,0,0,0,0,0,0,3,8,1,1,1,1,1,1,1,1,1
3,17,0,0,0,5,0,0,0,0,0,0,0,3,1,1,1,1,1,1,1,1,1
3,5,0,0,0,0,3,5,5,0,0,0,0,5,5,5,5,5,1,1,1,1,1
1,1,5,0,0,0,3,1,1,6,0,0,0,5,0,0,0,5,1,1,1,1,1
1,1,5,24,24,25,3,1,1,5,5,5,3,0,0,0,0,0,3,5,1,1,1
1,1,3,3,3,3,3,1,1,1,1,5,0,0,0,0,0,0,0,5,1,1,1
1,1,1,1,1,1,1,1,1,1,1,5,0,0,0,0,0,0,0,5,1,1,1
1,1,1,1,1,1,1,1,1,1,1,5,0,0,0,3,0,0,0,5,1,1,1
1,1,1,1,1,1,1,1,1,1,1,5,21,20,20,5,5,5,5,5,1,1,1
1,1,1,1,1,1,1,1,1,1,1,5,5,5,5,5,1,1,1,1,1,1,1
endlayer

layer
1,1,6,6,3,3,6,1,1,1,1,1,1,1,1,1,1,1,1,1,1,1,1
1,1,5,0,0,0,5,7,7,7,7,1,1,1,1,1,1,6,5,5,5,5,6
1,1,5,0,0,0,28,43,43,43,2,1,1,1,1,1,1,5,28,0,0,0,5
1,1,5,0,0,0,28,43,8,43,2,1,1,1,6,5,5,44,28,0,0,0,5
1,1,5,0,0,0,28,43,43,43,5,5,5,5,5,0,0,0,28,0,0,0,5
1,1,6,3,5,5,28,43,43,3,6,0,0,0,5,0,0,0,44,44,44,6,6
1,1,1,1,1,1,4,22,22,3,17,0,0,0,5,0,0,0,28,0,0,3,1
1,1,1,1,1,1,1,1,1,3,17,0,0,0,5,5,5,5,28,0,0,3,1
1,1,1,1,1,1,1,1,1,22,6,44,44,44,44,2,1,1,3,5,5,6,1
1,1,1,1,1,1,1,1,1,1,4,43,43,16,43,2,1,1,1,1,1,1,1
1,1,1,1,1,1,1,1,1,1,4,43,43,43,43,2,1,1,1,1,1,1,1
1,1,1,1,1,6,6,3,3,3,3,3,2,22,22,22,1,1,1,1,1,1,1
6,5,5,5,5,5,0,0,0,45,0,0,3,1,1,1,1,1,1,1,1,1,1
6,21,0,0,0,3,0,0,0,45,0,0,3,1,1,1,1,1,1,1,1,1,1
3,20,0,0,0,5,0,0,0,45,0,0,6,1,1,1,1,1,1,1,1,1,1
3,20,0,0,0,5,0,0,0,29,44,44,44,3,1,1,1,1,1,1,1,1,1
6,5,44,44,44,44,3,5,5,5,0,0,0,5,7,5,7,6,1,1,1,1,1
1,1,4,0,0,0,2,40,40,3,0,0,0,5,0,0,0,2,1,1,1,1,1
1,1,4,0,0,0,2,40,40,5,5,5,6,28,0,0,0,5,7,6,1,1,1
1,1,22,22,22,22,2,1,1,1,1,6,44,44,44,45,44,44,44,2,1,1,1
1,1,1,1,1,1,1,1,1,1,1,45,0,0,0,45,43,10,43,2,1,1,1
1,1,1,1,1,1,1,1,1,1,1,45,0,0,0,6,43,43,43,2,1,1,1
1,1,1,1,1,1,1,1,1,1,1,45,0,0,0,5,22,22,22,6,1,1,1
1,1,1,1,1,1,1,1,1,1,1,6,44,44,44,6,1,1,1,1,1,1,1
endlayer

layer
1,1,1,19,19,19,1,1,1,1,1,1,1,1,1,1,1,1,1,1,1,1,1
1,1,6,43,43,43,6,1,1,1,1,1,1,1,1,1,1,1,2,22,22,22,1
1,1,45,0,0,0,5,1,1,1,1,1,1,1,1,1,1,19,2,26,26,4,19
1,1,45,0,0,0,5,1,1,1,1,1,1,1,1,1,1,19,2,24,24,4,19
1,1,45,0,0,0,6,1,1,1,7,7,7,7,7,19,19,19,7,7,7,4,19
1,1,6,6,44,6,6,1,1,1,4,40,40,40,2,19,23,19,19,19,19,19,1
1,1,1,1,1,1,1,1,1,1,4,40,26,40,2,19,19,19,19,23,19,19,1
1,1,1,1,1,1,1,1,1,1,4,40,40,40,2,1,1,1,19,19,19,19,1
1,1,1,1,1,1,1,1,1,1,4,22,22,22,2,1,1,1,1,19,19,1,1
1,1,1,1,1,1,1,1,1,1,1,1,1,1,1,1,1,1,1,1,1,1,1
1,1,1,1,1,1,1,1,1,1,1,1,1,1,1,1,1,1,1,1,1,1,1
1,1,1,1,1,4,7,7,7,7,7,7,1,1,1,1,1,1,1,1,1,1,1
7,6,6,6,6,6,19,19,19,19,43,43,2,1,1,1,1,1,1,1,1,1,1
5,0,0,0,0,6,19,23,25,19,43,10,2,1,1,1,1,1,1,1,1,1,1
6,0,0,0,0,6,19,23,25,19,43,43,2,1,1,1,1,1,1,1,1,1,1
6,0,0,0,0,6,19,19,19,19,2,22,19,1,1,1,1,1,1,1,1,1,1
22,6,6,6,6,6,22,22,22,22,2,26,19,1,1,1,1,1,1,1,1,1,1
1,1,1,19,26,19,1,1,1,1,19,19,19,1,19,19,19,1,1,1,1,1,1
1,1,1,19,19,19,1,1,1,1,1,1,1,1,19,24,19,1,1,1,1,1,1
1,1,1,1,1,1,1,1,1,1,1,6,6,6,6,6,19,1,1,1,1,1,1
1,1,1,1,1,1,1,1,1,1,1,6,46,46,46,6,1,1,1,1,1,1,1
1,1,1,1,1,1,1,1,1,1,1,6,46,13,46,6,1,1,1,1,1,1,1
1,1,1,1,1,1,1,1,1,1,1,6,46,46,46,6,1,1,1,1,1,1,1
1,1,1,1,1,1,1,1,1,1,1,6,6,6,6,6,1,1,1,1,1,1,1
endlayer

layer
1,1,1,1,1,1,1,1,1,1,1,1,1,1,1,1,1,1,1,1,1,1,1
1,1,1,19,1,19,1,1,1,1,1,1,1,1,1,1,1,1,1,1,1,1,1
1,1,19,19,19,19,19,1,1,1,1,1,1,1,1,1,1,1,1,1,1,1,1
1,1,1,19,26,19,1,1,1,1,1,1,1,1,1,1,1,1,1,1,1,1,1
1,1,19,19,19,19,19,1,1,1,1,1,1,1,1,1,1,1,1,1,1,1,1
1,1,1,19,1,19,1,1,1,1,1,1,1,1,1,1,1,1,1,1,1,1,1
1,1,1,1,1,1,1,1,1,1,1,1,1,1,1,1,1,1,1,1,1,1,1
1,1,1,1,1,1,1,1,1,1,1,1,1,1,1,1,1,1,1,1,1,1,1
1,1,1,1,1,1,1,1,1,1,1,1,1,1,1,1,1,1,1,1,1,1,1
1,1,1,1,1,1,1,1,1,1,1,1,1,1,1,1,1,1,1,1,1,1,1
1,1,1,1,1,1,1,1,1,1,1,1,1,1,1,1,1,1,1,1,1,1,1
1,1,1,1,1,1,1,1,1,1,1,1,1,1,1,1,1,1,1,1,1,1,1
1,19,6,7,6,19,1,1,1,1,1,1,1,1,1,1,1,1,1,1,1,1,1
1,6,40,40,40,6,1,1,1,1,1,1,1,1,1,1,1,1,1,1,1,1,1
1,4,40,23,40,2,1,1,1,1,1,1,1,1,1,1,1,1,1,1,1,1,1
1,6,40,40,40,6,1,1,1,1,1,1,1,1,1,1,1,1,1,1,1,1,1
1,19,6,22,6,19,1,1,1,1,1,1,1,1,1,1,1,1,1,1,1,1,1
1,1,1,1,1,1,1,1,1,1,1,1,1,1,1,1,1,1,1,1,1,1,1
1,1,1,1,1,1,1,1,1,1,1,1,1,1,1,1,1,1,1,1,1,1,1
1,1,1,1,1,1,1,1,1,1,1,1,1,1,1,1,1,1,1,1,1,1,1
1,1,1,1,1,1,1,1,1,1,1,1,1,1,1,1,1,1,1,1,1,1,1
1,1,1,1,1,1,1,1,1,1,1,1,1,1,1,1,1,1,1,1,1,1,1
1,1,1,1,1,1,1,1,1,1,1,1,1,1,1,1,1,1,1,1,1,1,1
1,1,1,1,1,1,1,1,1,1,1,1,1,1,1,1,1,1,1,1,1,1,1
endlayer

