
# Created by Ruins mod version 16.7 Ingame Parser
# authoring Player: lafuller

weight=1
embed_into_distance=4
acceptable_target_blocks=
unacceptable_target_blocks=flowing_water,water,flowing_lava,lava,ice,bedrock,netherrack,nether_brick,nether_brick_fence,soul_sand,quartz_ore,end_stone,obsidian,iron_bars,cloud,flesh,ash_block,slime_grass,slime_congealed,slime_dirt
dimensions=18,18,18
allowable_overhang=0
max_leveling=4
leveling_buffer=-1
preserve_water=0
preserve_lava=0

rule1=0,100,preserveBlock
rule2=0,100,minecraft:stone-6
rule3=0,100,stonebrick-0,stonebrick-2,stonebrick-2,stonebrick-1,stonebrick-1,cobblestone
rule4=0,100,stonebrick-0,stonebrick-1,stonebrick-2,stonebrick-2,stone-5,stone-5,stone-6,stone-6
rule5=0,100,stonebrick-0,stonebrick-1,stonebrick-2
rule6=0,100,minecraft:stone-5
rule7=0,100,stonebrick-0,stonebrick-0,stonebrick-0,stonebrick-0,stonebrick-1,stonebrick-2,stonebrick-2,stone-5,stone-6,cobblestone,gravel
rule8=0,100,minecraft:cobblestone_wall-0
rule9=0,100,minecraft:oak_stairs-2
rule10=0,100,minecraft:planks-0
rule11=0,100,minecraft:spruce_stairs-2
rule12=0,100,minecraft:log-0
rule13=0,100,minecraft:wooden_slab-9
rule14=0,100,minecraft:stone_brick_stairs-2
rule15=0,100,web,air,air,air
rule16=0,100,minecraft:oak_stairs-4
rule17=0,100,minecraft:oak_stairs-3
rule18=0,100,minecraft:spruce_stairs-0
rule19=0,100,minecraft:oak_stairs-0
rule20=0,100,minecraft:planks-1
rule21=0,100,minecraft:stone_brick_stairs-1
rule22=0,100,minecraft:planks-2
rule23=0,100,minecraft:birch_stairs-0,birch_stairs-4,planks-2,planks-2,planks-2,planks-2
rule24=0,100,minecraft:birch_stairs-2,birch_stairs-6,planks-2,planks-2,planks-2,planks-2
rule25=0,100,minecraft:oak_stairs-7
rule26=0,100,minecraft:birch_stairs-3,birch_stairs-7,planks-2,planks-2,planks-2,planks-2
rule27=0,100,minecraft:cauldron-0
rule28=0,100,minecraft:oak_stairs-1
rule29=0,100,minecraft:stone-3
rule30=0,100,minecraft:birch_stairs-1,birch_stairs-5,planks-2,planks-2,planks-2,planks-2
rule31=0,100,minecraft:spruce_fence_gate-6
rule32=0,100,minecraft:spruce_fence-0
rule33=0,100,minecraft:spruce_fence_gate-0
rule34=0,100,minecraft:spruce_fence_gate-2
rule35=0,100,minecraft:spruce_fence_gate-4
rule36=0,100,minecraft:jungle_door-2
rule37=0,100,minecraft:spruce_fence_gate-7
rule38=0,100,minecraft:wooden_slab-2
rule39=0,100,minecraft:furnace-2
rule40=0,100,minecraft:bookshelf-0
rule41=0,100,minecraft:carpet-12
rule42=0,100,minecraft:carpet-8
rule43=0,100,minecraft:jungle_door-9
rule44=0,100,minecraft:jungle_door-8
rule45=0,100,minecraft:spruce_fence_gate-1
rule46=0,100,minecraft:ladder-5
rule47=0,100,minecraft:trapdoor-8
rule48=0,100,minecraft:spruce_fence_gate-3
rule49=0,100,minecraft:wooden_slab-0
rule50=0,100,minecraft:wooden_slab-5
rule51=0,100,minecraft:dark_oak_stairs-0
rule52=0,100,minecraft:dark_oak_stairs-3
rule53=0,100,minecraft:planks-5
rule54=0,100,minecraft:double_wooden_slab-5
rule55=0,100,minecraft:log-8
rule56=0,100,minecraft:log-4
rule57=0,100,minecraft:dark_oak_stairs-1
rule58=0,100,minecraft:dark_oak_stairs-2
rule59=0,100,minecraft:fence-0
rule60=0,100,minecraft:jungle_door-1
rule61=0,100,minecraft:wooden_slab-8
rule62=0,100,minecraft:oak_stairs-6
rule63=0,100,ChestGenHook:chests/spawn_bonus_chest:5-4
rule64=0,100,minecraft:carpet-7
rule65=0,100,minecraft:wooden_slab-13
rule66=0,100,minecraft:dark_oak_stairs-4
rule67=0,100,minecraft:spruce_stairs-7
rule68=0,100,minecraft:spruce_stairs-5
rule69=0,100,minecraft:dark_oak_stairs-6
rule70=0,100,minecraft:spruce_stairs-6
rule71=0,100,minecraft:dark_oak_stairs-7
rule72=0,100,minecraft:spruce_stairs-4
rule73=0,100,minecraft:dark_oak_stairs-5
rule74=0,100,minecraft:trapdoor-0
rule75=0,100,minecraft:dark_oak_fence-0
rule76=0,100,piston-1

layer
1,1,1,1,1,1,1,1,1,1,1,1,1,1,1,1,1,1
1,1,1,1,1,1,1,2,1,1,1,1,2,1,1,1,1,1
1,1,1,2,1,1,3,3,3,3,3,3,3,3,1,1,1,1
1,3,3,3,3,3,3,3,3,3,3,3,3,3,1,1,1,1
1,3,3,3,3,3,3,3,3,3,3,3,3,3,1,1,1,1
1,3,3,4,4,3,3,3,3,3,3,4,3,3,1,1,1,1
1,3,3,4,5,4,4,4,4,4,4,4,3,3,2,1,1,1
1,3,3,4,4,5,5,5,4,5,5,4,3,3,3,3,3,1
1,3,3,3,3,4,4,4,5,5,4,4,5,4,3,3,3,2
1,3,3,3,3,4,5,5,5,5,5,4,4,4,3,3,3,1
1,1,2,3,3,4,4,5,4,5,5,5,5,5,4,3,3,1
1,1,1,3,3,3,4,5,4,5,5,4,4,5,4,3,3,1
1,1,1,3,3,4,5,5,4,4,4,4,3,4,4,3,3,1
1,1,1,3,3,4,5,5,4,3,3,3,3,3,3,3,3,2
1,1,1,3,3,3,4,4,4,3,3,3,3,3,3,3,3,3
1,1,2,3,3,3,3,3,3,3,3,3,3,3,3,3,3,3
1,1,1,3,3,3,3,3,3,3,3,3,3,3,3,3,3,3
1,1,1,1,2,1,1,1,1,2,3,3,3,3,3,3,3,3
endlayer

layer
1,1,1,1,1,1,1,1,1,1,1,1,1,1,1,1,1,1
1,1,1,1,1,1,1,6,1,1,1,1,6,1,1,1,1,1
1,1,1,6,1,1,7,7,8,7,7,8,7,7,1,1,1,1
1,6,7,7,8,7,7,10,10,10,9,0,0,7,1,1,1,1
1,7,12,13,13,13,12,10,10,10,11,0,0,8,1,1,1,1
1,8,13,0,0,0,0,0,0,0,12,0,0,7,1,1,1,1
1,7,13,0,0,0,0,0,0,0,0,0,0,7,6,1,1,1
1,8,13,0,0,0,0,0,0,0,0,0,0,2,7,7,7,1
1,7,12,0,0,0,0,0,0,0,0,0,0,0,0,12,7,6
1,7,7,2,0,0,0,0,0,0,0,0,0,0,0,13,8,1
1,1,6,7,12,20,20,20,0,0,0,0,0,0,0,13,7,1
1,1,1,8,13,0,0,0,0,0,0,0,0,0,0,13,7,1
1,1,1,7,13,0,0,0,0,0,0,0,0,0,0,13,8,1
1,1,1,7,13,0,0,0,0,0,12,13,13,13,13,12,7,6
1,1,1,8,13,0,0,0,0,0,2,7,7,7,7,7,7,14
1,1,6,7,12,13,13,13,13,12,7,7,7,7,7,6,7,14
1,1,1,7,7,8,7,7,8,7,2,7,7,7,7,7,7,14
1,1,1,1,6,1,1,1,1,6,7,7,7,7,7,7,7,14
endlayer

layer
1,1,1,1,1,1,1,1,1,1,1,1,1,1,1,1,1,1
1,1,1,1,1,1,1,2,1,1,1,1,2,1,1,1,1,1
1,1,1,2,1,1,7,7,8,7,7,8,7,7,1,1,1,1
1,2,7,7,8,7,7,10,10,9,0,0,0,7,1,1,1,1
1,7,12,15,0,15,12,10,10,11,0,0,0,8,1,1,1,1
1,8,15,0,0,0,0,0,0,15,12,0,0,7,1,1,1,1
1,7,0,0,0,0,0,0,0,0,0,0,0,7,2,1,1,1
1,8,15,0,0,0,0,0,0,0,0,0,0,6,7,7,7,1
1,7,12,15,0,0,0,0,0,0,0,0,0,0,15,12,7,2
1,7,7,6,15,0,0,0,0,0,0,0,0,0,0,15,8,1
1,1,2,7,12,0,0,0,0,0,0,0,0,0,0,0,7,1
1,1,1,8,15,0,0,0,0,0,0,0,0,0,0,0,7,1
1,1,1,7,0,0,0,0,0,0,0,0,0,0,0,15,8,1
1,1,1,7,0,0,0,0,0,0,12,15,0,0,15,12,7,2
1,1,1,8,15,0,0,0,0,15,6,7,7,7,7,7,7,1
1,1,2,7,12,15,0,0,15,12,7,7,7,7,7,2,14,1
1,1,1,7,7,8,7,7,8,7,6,7,7,7,7,7,14,1
1,1,1,1,2,1,1,1,1,2,7,7,7,7,7,7,14,1
endlayer

layer
1,1,1,1,1,1,1,1,1,1,1,1,1,1,1,1,1,1
1,1,1,1,1,1,1,6,1,1,1,1,6,1,1,1,1,1
1,1,1,6,1,1,7,7,8,7,7,8,7,7,1,1,1,1
1,6,7,7,8,7,7,10,9,0,0,0,15,7,1,1,1,1
1,7,12,0,15,15,12,10,11,0,0,0,0,8,1,1,1,1
1,8,15,15,0,15,15,0,15,15,12,0,0,7,1,1,1,1
1,7,15,0,0,0,0,0,0,0,0,0,0,7,6,1,1,1
1,8,15,15,0,0,0,0,0,0,0,0,15,2,7,7,7,1
1,7,12,15,15,0,0,0,0,0,0,0,0,15,15,12,7,6
1,7,7,2,15,0,0,0,0,0,0,0,0,0,15,15,8,1
1,1,6,7,12,13,13,13,0,0,0,0,0,0,0,15,7,1
1,1,1,8,15,15,0,0,0,0,0,0,0,0,0,15,7,1
1,1,1,7,15,0,0,0,0,0,15,15,0,0,15,15,8,1
1,1,1,7,15,0,0,0,0,15,12,15,15,15,15,12,7,6
1,1,1,8,15,15,0,0,15,15,2,7,7,7,7,7,7,1
1,1,6,7,12,15,15,15,15,12,7,7,7,7,7,6,1,1
1,1,1,7,7,8,7,7,8,7,2,7,7,7,7,14,1,1
1,1,1,1,6,1,1,1,1,6,7,7,7,7,7,14,1,1
endlayer

layer
1,1,1,1,1,1,1,1,1,1,1,1,1,1,1,1,1,1
1,1,1,1,1,1,1,2,1,1,1,1,2,1,1,1,1,1
1,1,1,2,1,1,1,7,7,7,7,7,7,1,1,1,1,1
1,2,7,7,7,7,7,0,0,0,0,0,15,7,1,1,1,1
1,7,12,10,10,10,9,0,0,0,0,0,15,7,1,1,1,1
1,7,10,20,20,20,11,19,18,17,12,16,16,7,1,1,1,1
1,7,10,20,10,10,10,20,20,10,10,10,10,7,2,1,1,1
1,7,10,20,20,20,10,10,20,20,10,10,10,2,7,7,1,1
1,7,12,10,10,10,20,10,20,10,20,20,20,10,10,12,7,2
1,1,7,6,10,10,20,20,10,10,20,10,20,20,10,10,7,1
1,1,2,7,10,20,20,10,10,10,10,10,10,10,20,10,7,1
1,1,1,7,10,20,10,10,20,10,20,20,10,10,20,10,7,1
1,1,1,7,10,20,10,10,20,20,10,10,20,20,20,10,7,1
1,1,1,7,10,20,10,10,20,10,10,10,10,10,10,12,7,2
1,1,1,7,10,10,20,20,20,10,6,7,10,10,7,7,1,1
1,1,2,7,12,10,10,10,10,12,7,7,7,7,7,2,1,1
1,1,1,1,7,7,7,7,7,7,6,7,7,7,14,1,1,1
1,1,1,1,2,1,1,1,1,2,21,21,21,21,14,1,1,1
endlayer

layer
1,1,1,1,1,1,1,0,0,0,0,1,1,1,1,1,1,1
1,1,1,1,1,0,0,12,0,0,0,0,12,0,1,1,1,1
1,1,1,12,0,0,0,23,23,23,23,23,22,0,0,1,1,1
1,12,23,22,23,23,12,0,0,0,0,25,10,24,0,0,1,1
1,26,12,76,2,0,0,0,0,0,0,25,10,24,0,0,1,1
1,26,27,0,0,0,0,0,0,0,12,10,10,24,0,0,0,1
1,26,29,0,0,0,0,0,0,0,17,28,28,22,12,0,0,1
0,26,29,0,0,0,0,0,0,0,0,0,0,12,23,23,0,0
0,30,12,0,0,0,0,0,0,0,0,0,0,0,10,12,24,12
0,0,26,12,0,0,0,0,0,0,0,0,0,0,0,0,24,0
0,0,12,26,0,0,0,0,0,0,0,0,0,0,0,31,24,0
1,0,0,26,0,0,32,32,0,0,0,0,0,0,0,31,24,0
1,0,0,26,35,0,34,33,0,0,0,0,0,0,0,0,24,1
1,1,0,26,35,0,32,32,0,0,0,0,0,0,0,12,24,12
1,1,0,26,0,0,0,0,0,0,12,30,36,36,30,24,0,1
1,1,12,30,12,0,37,37,0,12,30,12,0,0,0,12,1,1
1,1,1,1,26,30,30,30,30,24,0,0,0,0,0,1,1,1
1,1,1,1,12,1,1,0,0,12,0,0,1,1,1,1,1,1
endlayer

layer
1,1,1,1,1,0,0,0,0,0,0,0,0,1,1,1,1,1
1,1,1,0,0,0,0,12,0,0,0,0,12,0,0,1,1,1
1,1,1,12,0,0,0,23,23,23,23,23,22,0,0,0,1,1
1,12,23,22,38,23,12,0,0,0,25,10,10,24,0,0,0,1
1,26,12,0,0,0,0,0,0,0,25,10,10,24,0,0,0,1
0,26,39,0,0,0,0,0,0,0,12,28,28,24,0,0,0,0
0,38,0,0,0,0,0,0,0,0,0,0,0,24,12,0,0,0
0,38,0,0,0,0,0,0,0,0,0,0,0,12,23,23,0,0
0,30,12,0,0,0,0,0,0,0,0,0,0,0,40,12,24,12
0,0,26,12,0,0,0,0,0,0,0,0,0,0,0,0,24,0
0,0,12,26,0,0,0,0,0,0,0,0,0,0,0,41,38,0
0,0,0,26,0,0,42,42,0,0,0,0,0,0,0,41,38,0
0,0,0,38,41,0,42,42,0,0,0,0,0,0,0,0,24,0
1,0,0,38,41,0,42,42,0,0,0,0,0,0,0,12,24,12
1,0,0,26,0,0,0,0,0,0,12,30,44,43,30,24,0,0
1,1,12,30,12,0,41,41,0,12,30,12,0,0,0,12,0,1
1,1,1,0,26,30,38,38,30,24,0,0,0,0,0,0,1,1
1,1,1,1,12,0,0,0,0,12,0,0,0,0,1,1,1,1
endlayer

layer
1,1,1,0,0,0,0,0,0,0,0,0,0,0,0,1,1,1
1,1,0,0,0,0,0,12,0,0,0,0,12,0,0,0,1,1
1,0,0,12,0,0,0,23,23,23,23,23,22,0,0,0,0,1
0,12,23,22,45,23,12,0,0,25,9,0,0,24,0,0,0,0
0,26,12,46,0,46,0,0,0,25,9,0,0,24,0,0,0,0
0,26,8,0,0,0,0,0,0,0,12,0,0,24,0,0,0,0
0,33,47,0,0,0,0,0,0,0,0,0,0,24,12,0,0,0
0,33,47,0,0,0,0,0,0,0,0,0,0,12,23,23,0,0
0,30,12,0,0,0,0,0,0,0,0,0,0,0,40,12,24,12
0,0,26,12,0,0,0,0,0,0,0,0,0,0,0,0,24,0
0,0,12,26,0,0,0,0,0,0,0,0,0,0,0,0,34,0
0,0,0,26,0,0,0,0,0,0,0,0,0,0,0,0,34,0
0,0,0,33,0,0,0,0,0,0,0,0,0,0,0,0,24,0
0,0,0,33,0,0,0,0,0,0,0,0,0,0,0,12,24,12
0,0,0,26,0,0,0,0,0,0,12,30,48,48,30,24,0,0
1,0,12,30,12,0,0,0,0,12,30,12,0,0,0,12,0,0
1,1,0,0,26,30,48,48,30,24,0,0,0,0,0,0,0,1
1,1,1,0,12,0,0,0,0,12,0,0,0,0,0,1,1,1
endlayer

layer
1,1,0,0,0,0,0,0,0,0,0,0,0,0,0,0,1,1
1,0,0,0,0,0,0,12,0,0,0,0,12,0,0,0,0,1
0,0,0,12,0,0,0,23,23,23,23,23,22,0,0,0,0,0
0,12,23,22,23,23,12,0,25,9,0,0,0,24,0,0,0,0
0,26,12,0,0,0,0,0,25,9,0,0,0,24,0,0,0,0
0,26,8,0,0,0,0,0,0,0,12,0,0,24,0,0,0,0
0,26,0,0,0,0,0,0,0,0,0,0,0,24,12,0,0,0
0,26,0,0,0,0,0,0,0,0,0,0,0,12,23,23,0,0
0,30,12,0,0,0,0,0,0,0,0,0,0,0,49,12,24,12
0,0,26,12,0,0,0,0,0,0,0,0,0,0,0,0,24,0
0,0,12,26,0,0,0,0,0,0,0,0,0,0,0,0,24,0
0,0,0,26,0,0,0,0,0,0,0,0,0,0,0,0,24,0
0,0,0,26,0,0,0,0,0,0,0,0,0,0,0,0,24,0
0,0,0,26,0,0,0,0,0,0,0,0,0,0,0,12,24,12
0,0,0,26,0,0,0,0,0,0,12,30,30,30,30,24,0,0
0,0,12,30,12,0,0,0,0,12,30,12,0,0,0,12,0,0
1,0,0,0,26,30,30,30,30,24,0,0,0,0,0,0,0,0
1,1,0,0,12,0,0,0,0,12,0,0,0,0,0,0,1,1
endlayer

layer
1,0,0,0,0,0,0,0,0,0,0,0,0,0,0,0,0,1
0,0,0,50,51,52,53,12,51,52,51,50,12,50,0,0,0,0
0,50,53,53,53,53,53,55,55,55,55,55,55,54,50,0,0,0
50,53,51,56,55,55,10,10,9,0,0,0,0,56,50,0,0,0
50,53,10,10,10,10,10,20,9,0,0,0,0,56,50,0,0,0
53,53,10,10,10,20,20,20,19,19,12,0,0,56,50,0,0,0
53,53,10,10,10,20,10,10,20,10,10,0,0,56,12,50,0,0
53,53,10,10,10,10,20,10,20,20,20,0,0,12,53,51,51,50
50,53,53,10,10,10,20,10,10,10,20,20,10,10,10,10,53,50
50,52,53,12,10,20,10,10,10,20,10,20,10,20,20,10,53,50
0,57,56,56,10,20,10,10,10,20,20,20,20,10,20,10,53,50
0,50,56,56,10,20,10,20,20,10,20,20,10,10,20,10,53,50
0,50,56,56,10,20,20,20,10,10,20,10,20,20,20,10,53,50
0,50,56,56,10,10,10,10,10,10,10,10,10,10,10,10,53,50
0,50,56,53,10,10,10,10,10,10,12,53,51,51,51,53,58,0
0,50,53,53,10,10,10,10,10,53,53,53,57,50,50,50,50,0
0,0,50,57,53,53,53,53,53,53,57,57,50,0,0,0,0,0
1,0,0,50,50,52,57,53,57,50,50,0,0,0,0,0,0,1
endlayer

layer
0,0,0,0,0,0,0,0,0,0,0,0,0,0,0,0,0,0
0,0,0,0,0,0,0,12,0,0,0,0,12,0,0,0,0,0
0,0,0,0,0,50,50,22,23,23,23,23,22,0,0,0,0,0
0,0,0,12,23,23,23,12,0,0,0,0,0,24,0,0,0,0
0,50,50,22,12,0,0,0,0,0,0,0,0,24,0,0,0,0
0,50,8,22,0,0,0,0,0,0,12,0,0,24,0,0,0,0
0,50,52,22,35,0,0,0,0,0,22,0,0,22,12,0,0,0
0,50,51,22,35,0,0,0,0,0,22,22,22,50,59,59,59,0
0,0,57,22,0,0,0,0,0,0,24,12,0,0,0,0,59,0
0,0,52,12,0,0,0,0,0,0,24,0,0,0,0,0,59,0
0,0,50,22,62,61,25,0,0,0,60,0,0,0,0,0,59,0
0,0,0,22,62,61,25,0,0,0,24,0,0,0,0,0,59,0
0,0,12,22,10,0,0,0,0,10,24,0,0,0,0,0,59,0
0,0,0,26,12,63,37,37,0,12,22,12,0,0,0,0,59,0
0,0,0,50,22,22,22,22,22,22,30,59,59,59,59,59,59,0
0,0,0,50,12,53,53,53,53,12,50,0,0,0,0,0,0,0
0,0,0,0,50,50,52,57,50,0,0,0,0,0,0,0,0,0
0,0,0,0,0,0,0,0,0,0,0,0,0,0,0,0,0,0
endlayer

layer
0,0,0,0,0,0,0,0,0,0,0,0,0,0,0,0,0,0
0,0,0,0,0,0,0,12,0,0,0,0,12,0,0,0,0,0
0,0,0,0,0,0,0,22,23,38,38,23,22,0,0,0,0,0
0,0,0,12,23,38,23,12,0,0,0,0,0,24,0,0,0,0
0,0,0,26,12,0,0,0,0,0,0,0,0,38,0,0,0,0
0,0,8,26,0,0,0,0,0,0,12,0,0,38,0,0,0,0
0,0,0,38,41,0,0,0,0,0,22,0,0,22,12,0,0,0
0,0,0,38,41,0,0,0,0,0,22,22,30,0,0,0,0,0
0,0,0,26,0,0,0,0,0,0,24,12,0,0,0,0,0,0
0,0,0,12,0,0,0,0,0,0,24,0,0,0,0,0,0,0
0,0,0,26,42,64,64,0,0,0,43,0,0,0,0,0,0,0
0,0,0,26,42,64,64,0,0,0,24,0,0,0,0,0,0,0
0,0,12,22,40,0,0,0,0,40,24,0,0,0,0,0,0,0
0,0,0,26,12,0,41,41,0,12,22,12,0,0,0,0,0,0
0,0,0,0,22,30,38,38,30,22,24,0,0,0,0,0,0,0
0,0,0,0,12,0,0,0,0,12,0,0,0,0,0,0,0,0
0,0,0,0,0,0,0,0,0,0,0,0,0,0,0,0,0,0
0,0,0,0,0,0,0,0,0,0,0,0,0,0,0,0,0,0
endlayer

layer
0,0,0,0,0,0,0,0,0,0,0,0,0,0,0,0,0,0
0,0,0,0,0,0,0,12,0,0,0,0,12,0,0,0,0,0
0,0,0,0,0,0,0,22,23,45,45,23,22,0,0,0,0,0
0,0,0,12,23,45,23,12,0,0,0,0,0,24,0,0,0,0
0,0,0,26,12,0,0,0,0,0,0,0,0,34,0,0,0,0
0,0,8,26,0,0,0,0,0,0,12,0,0,34,0,0,0,0
0,0,0,33,0,0,0,0,0,0,22,0,0,22,12,0,0,0
0,0,0,33,0,0,0,0,0,0,22,22,30,0,0,0,0,0
0,0,0,26,0,0,0,0,0,0,24,12,0,0,0,0,0,0
0,0,0,12,0,0,0,0,0,0,24,0,0,0,0,0,0,0
0,0,0,26,0,0,0,0,0,0,24,0,0,0,0,0,0,0
0,0,0,26,0,0,0,0,0,0,24,0,0,0,0,0,0,0
0,0,12,22,49,0,0,0,0,49,24,0,0,0,0,0,0,0
0,0,0,26,12,0,0,0,0,12,22,12,0,0,0,0,0,0
0,0,0,0,22,30,48,48,30,22,30,0,0,0,0,0,0,0
0,0,0,0,12,0,0,0,0,12,0,0,0,0,0,0,0,0
0,0,0,0,0,0,0,0,0,0,0,0,0,0,0,0,0,0
0,0,0,0,0,0,0,0,0,0,0,0,0,0,0,0,0,0
endlayer

layer
0,0,0,0,0,0,0,0,0,0,0,0,0,0,0,0,0,0
0,0,0,0,0,0,0,12,0,0,0,0,12,0,0,0,0,0
0,0,0,0,0,0,0,22,23,23,23,23,22,0,0,0,0,0
0,0,0,12,23,23,23,12,0,0,0,0,0,24,0,0,0,0
0,0,0,26,12,0,0,0,0,0,0,0,0,24,0,0,0,0
0,0,8,26,0,0,0,0,0,0,12,0,0,24,0,0,0,0
0,0,0,26,0,0,0,0,0,0,22,0,0,22,12,0,0,0
0,0,0,26,0,0,0,0,0,0,22,22,30,0,0,0,0,0
0,0,0,26,0,0,0,0,0,0,24,12,0,0,0,0,0,0
0,0,0,12,0,0,0,0,0,0,24,0,0,0,0,0,0,0
0,0,0,26,0,0,0,0,0,0,24,0,0,0,0,0,0,0
0,0,0,26,0,0,0,0,0,0,24,0,0,0,0,0,0,0
0,0,12,22,0,0,0,0,0,0,24,0,0,0,0,0,0,0
0,0,0,26,12,0,0,0,0,12,22,12,0,0,0,0,0,0
0,0,0,0,22,30,30,30,30,22,24,0,0,0,0,0,0,0
0,0,0,0,12,0,0,0,0,12,0,0,0,0,0,0,0,0
0,0,0,0,0,0,0,0,0,0,0,0,0,0,0,0,0,0
0,0,0,0,0,0,0,0,0,0,0,0,0,0,0,0,0,0
endlayer

layer
0,0,0,0,0,65,65,65,65,65,65,65,0,0,0,0,0,0
0,0,0,65,65,65,66,53,66,53,66,66,53,65,0,0,0,0
0,0,66,66,66,66,53,53,53,53,53,53,53,53,58,0,0,0
0,0,52,12,53,53,20,20,20,20,20,20,20,53,53,0,0,0
0,0,53,53,20,68,68,68,68,67,20,32,20,53,65,65,0,0
0,0,71,53,70,0,0,0,0,67,20,20,20,53,69,65,0,0
0,65,71,51,70,0,0,0,0,67,20,20,20,51,12,54,0,0
0,65,71,53,70,0,0,0,0,67,53,53,53,53,51,65,0,0
0,65,53,53,70,0,0,0,0,67,53,12,53,69,65,0,0,0
0,65,71,12,70,0,0,0,0,67,53,51,69,65,65,0,0,0
0,65,53,53,70,0,0,0,0,67,53,69,65,65,0,0,0,0
0,65,53,53,70,0,0,0,0,67,53,69,65,0,0,0,0,0
0,65,53,53,70,0,0,0,0,67,53,54,65,0,0,0,0,0
0,0,53,53,12,72,72,72,72,20,51,12,69,0,0,0,0,0
0,0,71,0,53,53,53,53,53,53,53,73,65,0,0,0,0,0
0,0,0,71,53,53,53,53,53,53,65,65,0,0,0,0,0,0
0,0,0,0,52,65,65,65,57,50,0,0,0,0,0,0,0,0
0,0,0,0,0,0,0,0,0,0,0,0,0,0,0,0,0,0
endlayer

layer
0,0,0,0,0,0,0,0,0,0,0,0,0,0,0,0,0,0
0,0,0,0,0,51,51,58,50,52,51,51,0,0,0,0,0,0
0,0,0,50,51,53,53,53,53,53,53,53,51,50,0,0,0,0
0,0,0,52,53,53,53,53,53,53,53,53,53,58,0,0,0,0
0,0,0,51,53,53,53,53,53,53,53,0,53,53,58,0,0,0
0,0,8,52,53,70,68,68,68,53,53,53,53,50,0,0,0,0
0,0,52,53,53,70,0,0,67,53,53,53,53,51,50,0,0,0
0,0,57,53,53,68,0,0,68,53,53,53,53,53,58,0,0,0
0,0,50,53,53,70,0,0,67,53,53,53,53,58,0,0,0,0
0,0,52,53,53,70,0,0,67,53,53,53,54,50,0,0,0,0
0,0,52,51,53,72,0,0,72,53,53,58,57,0,0,0,0,0
0,0,52,53,53,70,0,0,67,53,53,50,0,0,0,0,0,0
0,0,50,53,53,72,72,72,72,53,53,58,0,0,0,0,0,0
0,0,0,52,53,53,53,53,51,51,51,53,0,0,0,0,0,0
0,0,0,50,53,53,53,53,53,53,53,58,0,0,0,0,0,0
0,0,0,0,57,50,50,57,50,0,50,0,0,0,0,0,0,0
0,0,0,0,0,0,0,0,0,0,0,0,0,0,0,0,0,0
0,0,0,0,0,0,0,0,0,0,0,0,0,0,0,0,0,0
endlayer

layer
0,0,0,0,0,0,0,0,0,0,0,0,0,0,0,0,0,0
0,0,0,0,0,0,0,0,0,0,0,0,0,0,0,0,0,0
0,0,0,0,0,0,50,0,0,50,50,0,0,0,0,0,0,0
0,0,0,0,50,50,51,53,58,51,53,58,50,0,0,0,0,0
0,0,0,0,52,53,53,53,53,53,53,74,50,0,0,0,0,0
0,0,8,0,51,53,53,53,53,53,53,53,50,0,0,0,0,0
0,0,0,52,53,53,68,68,53,53,53,58,50,0,0,0,0,0
0,0,0,51,53,53,20,20,51,51,51,53,58,0,0,0,0,0
0,0,0,53,53,53,70,67,53,53,53,53,50,0,0,0,0,0
0,0,0,52,53,53,70,67,53,53,57,58,0,0,0,0,0,0
0,0,0,50,53,53,20,20,53,53,58,0,0,0,0,0,0,0
0,0,0,0,57,53,72,72,53,53,57,0,0,0,0,0,0,0
0,0,0,0,52,53,53,53,53,53,50,0,0,0,0,0,0,0
0,0,0,0,50,57,53,53,53,53,58,0,0,0,0,0,0,0
0,0,0,0,0,0,50,57,57,50,0,0,0,0,0,0,0,0
0,0,0,0,0,0,0,0,0,0,0,0,0,0,0,0,0,0
0,0,0,0,0,0,0,0,0,0,0,0,0,0,0,0,0,0
0,0,0,0,0,0,0,0,0,0,0,0,0,0,0,0,0,0
endlayer

layer
0,0,0,0,0,0,0,0,0,0,0,0,0,0,0,0,0,0
0,0,0,0,0,0,0,0,0,0,0,0,0,0,0,0,0,0
0,0,0,0,0,0,0,0,0,0,0,0,0,0,0,0,0,0
0,0,0,0,0,0,75,75,75,75,75,0,0,0,0,0,0,0
0,0,0,0,75,75,75,50,50,50,75,0,0,0,0,0,0,0
0,0,8,0,75,50,50,50,50,50,75,75,0,0,0,0,0,0
0,0,0,75,75,50,50,51,53,50,0,75,0,0,0,0,0,0
0,0,0,75,50,50,52,53,53,50,50,75,0,0,0,0,0,0
0,0,0,75,50,50,53,53,53,50,50,75,0,0,0,0,0,0
0,0,0,75,50,50,53,53,58,50,75,75,0,0,0,0,0,0
0,0,0,75,75,50,52,53,50,50,75,0,0,0,0,0,0,0
0,0,0,0,75,50,50,50,50,75,75,0,0,0,0,0,0,0
0,0,0,0,75,75,50,50,75,75,0,0,0,0,0,0,0,0
0,0,0,0,0,75,75,75,75,0,0,0,0,0,0,0,0,0
0,0,0,0,0,0,0,0,0,0,0,0,0,0,0,0,0,0
0,0,0,0,0,0,0,0,0,0,0,0,0,0,0,0,0,0
0,0,0,0,0,0,0,0,0,0,0,0,0,0,0,0,0,0
0,0,0,0,0,0,0,0,0,0,0,0,0,0,0,0,0,0
endlayer

