
# Created by Ruins mod version 16.7 Ingame Parser
# authoring Player: lafuller

weight=1
embed_into_distance=5
acceptable_target_blocks=
unacceptable_target_blocks=flowing_water,water,flowing_lava,lava,ice,bedrock,netherrack,nether_brick,nether_brick_fence,soul_sand,quartz_ore,end_stone,obsidian,iron_bars,cloud,flesh,ash_block,slime_grass,slime_congealed,slime_dirt
dimensions=12,22,21
allowable_overhang=0
max_leveling=7
leveling_buffer=-1
preserve_water=0
preserve_lava=0

rule1=0,100,preserveBlock
rule2=0,100,minecraft:sandstone-0
rule3=0,100,minecraft:double_stone_slab-9
rule4=0,100,minecraft:sandstone_stairs-3
rule5=0,100,minecraft:sandstone_stairs-2
rule6=0,100,minecraft:sandstone-2
rule7=0,100,minecraft:sandstone_stairs-0
rule8=0,100,minecraft:sandstone_stairs-1
rule9=0,100,bookshelf,pumpkin,melon_block,hay_block,ChestGenHook:chests/spawn_bonus_chest:5-5,ChestGenHook:chests/village_blacksmith:5-5,ChestGenHook:chests/stronghold_library:5-5,ChestGenHook:chests/simple_dungeon:5-5
rule10=0,100,minecraft:trapdoor-11
rule11=0,100,minecraft:trapdoor-8
rule12=0,100,minecraft:wooden_slab-9
rule13=0,100,bookshelf,pumpkin,melon_block,hay_block,ChestGenHook:chests/spawn_bonus_chest:5-2,ChestGenHook:chests/village_blacksmith:5-2,ChestGenHook:chests/stronghold_library:5-2,ChestGenHook:chests/simple_dungeon:5-2
rule14=0,100,minecraft:ladder-2
rule15=0,100,minecraft:dirt-0
rule16=0,100,minecraft:spruce_fence-0
rule17=0,100,bookshelf,pumpkin,melon_block,hay_block,ChestGenHook:chests/spawn_bonus_chest:5-3,ChestGenHook:chests/village_blacksmith:5-3,ChestGenHook:chests/stronghold_library:5-3,ChestGenHook:chests/simple_dungeon:5-3
rule18=0,100,minecraft:carpet-7
rule19=0,100,minecraft:carpet-8
rule20=0,100,minecraft:trapdoor-10
rule21=0,100,minecraft:ladder-3
rule22=0,100,minecraft:trapdoor-9
rule23=0,100,minecraft:trapdoor-3
rule24=0,100,minecraft:trapdoor-0
rule25=0,100,minecraft:trapdoor-1
rule26=0,100,minecraft:stone_slab-9
rule27=0,100,minecraft:trapdoor-2
rule28=0,100,minecraft:stone_slab-1
rule29=0,100,minecraft:sandstone_stairs-5
rule30=0,100,minecraft:jungle_door-4
rule31=0,100,minecraft:sandstone_stairs-4
rule32=0,100,minecraft:ladder-5
rule33=0,100,minecraft:jungle_door-7
rule34=0,100,minecraft:sandstone_stairs-6
rule35=0,100,minecraft:spruce_stairs-4
rule36=0,100,minecraft:jungle_door-5
rule37=0,100,minecraft:sandstone_stairs-7
rule38=0,100,minecraft:jungle_door-8
rule39=0,100,minecraft:jungle_door-6
rule40=0,100,minecraft:jungle_door-9
rule41=0,100,bookshelf,pumpkin,melon_block,hay_block,ChestGenHook:chests/spawn_bonus_chest:5-4,ChestGenHook:chests/village_blacksmith:5-4,ChestGenHook:chests/stronghold_library:5-4,ChestGenHook:chests/simple_dungeon:5-4
rule42=0,100,minecraft:spruce_stairs-3
rule43=0,100,minecraft:wooden_slab-1
rule44=0,100,minecraft:spruce_fence_gate-0
rule45=0,100,minecraft:spruce_stairs-0
rule46=0,100,minecraft:spruce_stairs-2
rule47=0,100,minecraft:hay_block-0
rule48=0,100,minecraft:spruce_stairs-1
rule49=0,100,minecraft:planks-1
rule50=0,100,minecraft:double_stone_slab-1

layer
1,1,1,1,4,3,2,3,3,3,3,3,3,3,3,2,1,1,1,1,1
1,3,2,2,2,2,2,3,3,2,2,2,2,2,3,2,1,1,1,1,1
1,3,3,3,3,3,3,3,3,2,2,2,2,2,3,2,6,6,5,1,1
1,2,3,2,2,2,2,2,2,2,2,2,2,2,3,2,2,6,2,2,6
1,6,3,2,2,2,2,2,2,2,2,2,2,2,3,2,2,2,2,2,2
7,6,3,2,2,2,2,2,2,2,2,2,2,2,3,2,2,2,2,2,2
3,6,3,2,2,2,2,2,2,3,3,3,3,3,3,3,3,3,3,3,6
2,2,3,2,2,2,2,2,2,2,2,2,2,3,2,2,2,2,2,3,6
3,3,3,3,3,3,3,3,3,2,2,2,2,3,2,2,2,2,2,3,6
3,6,6,6,6,6,3,2,2,2,2,2,2,3,2,2,2,2,2,3,2
3,6,6,6,6,6,3,2,2,2,3,6,2,6,2,2,2,2,2,3,2
3,6,6,6,6,6,3,2,2,2,2,2,2,6,2,2,2,2,2,3,2
3,6,6,6,6,6,3,2,2,2,2,2,2,6,6,2,2,2,2,2,3
3,6,6,6,6,6,3,2,2,2,2,2,2,2,6,2,2,2,2,2,3
3,3,3,3,3,3,3,3,2,2,2,6,2,2,3,2,2,2,2,2,3
2,3,6,6,6,6,6,3,2,2,2,2,2,2,3,2,2,2,2,2,3
2,3,6,6,6,6,6,3,2,2,2,2,2,2,3,2,2,2,2,2,3
6,3,6,6,6,6,6,3,2,6,2,2,2,2,3,2,2,2,2,2,3
1,3,6,6,6,6,6,3,2,2,2,2,2,3,6,3,3,3,3,3,3
1,3,6,6,6,6,6,3,2,2,8,8,2,3,3,2,2,2,2,2,2
1,3,3,3,3,3,3,3,3,2,1,1,1,1,4,3,3,2,5,1,1
1,2,2,2,2,1,1,1,1,1,1,1,1,1,1,1,1,1,1,1,1
endlayer

layer
1,1,1,1,1,4,2,3,3,3,3,3,3,3,3,2,1,1,1,1,1
1,3,2,2,2,2,2,3,3,2,2,2,2,2,3,2,1,1,1,1,1
1,3,3,3,3,3,3,3,3,2,2,2,2,2,3,2,6,5,1,1,1
1,2,3,2,2,2,2,2,2,2,2,2,2,2,3,2,2,2,2,2,6
1,6,3,2,2,2,2,2,2,2,2,2,2,2,3,2,2,2,6,2,2
1,6,3,2,2,2,2,2,2,2,2,2,2,2,3,2,2,2,2,2,2
7,6,3,2,2,2,2,2,2,3,3,3,3,3,10,0,0,9,3,3,5
2,2,3,2,2,2,2,2,2,2,2,2,2,11,0,0,0,0,2,3,5
3,3,3,3,3,3,3,3,3,2,2,2,2,0,0,0,0,0,2,3,5
3,6,6,6,6,6,3,2,2,2,2,2,2,0,0,0,0,0,8,3,2
3,0,0,0,0,0,0,2,2,2,6,6,2,0,0,0,0,0,0,3,2
3,0,0,0,0,0,0,2,2,2,2,2,2,0,0,0,0,0,0,12,2
3,0,0,0,0,0,0,2,2,2,2,2,2,0,0,0,0,0,0,12,3
3,13,0,0,0,0,0,2,2,2,2,2,2,0,0,0,0,0,0,12,3
3,3,0,0,0,0,0,3,2,2,2,2,2,2,3,2,2,2,2,2,3
2,3,6,0,0,0,6,3,2,2,2,2,2,2,3,2,2,2,2,2,3
2,3,6,7,7,7,6,3,2,2,2,2,2,2,3,2,2,2,2,2,3
3,3,6,6,6,6,6,3,2,2,2,2,2,2,3,2,2,2,2,2,3
1,3,6,6,6,6,6,3,2,2,8,8,2,3,6,3,3,3,3,3,3
1,3,6,6,6,6,6,3,2,2,1,1,2,3,3,2,2,2,2,2,2
1,3,3,3,3,3,3,3,3,2,1,1,1,1,1,4,6,5,1,1,1
1,2,2,2,2,1,1,1,1,1,1,1,1,1,1,1,1,1,1,1,1
endlayer

layer
1,1,1,1,1,1,4,3,3,3,3,3,3,3,3,2,1,1,1,1,1
1,3,2,2,2,2,2,3,3,14,0,0,0,0,3,2,1,1,1,1,1
1,3,3,3,3,3,3,3,3,14,0,0,0,0,3,2,5,1,1,1,1
1,8,3,10,10,9,6,6,6,2,0,0,0,0,3,15,6,6,6,6,6
1,1,3,0,0,0,0,16,8,2,0,0,0,0,3,2,2,2,2,2,2
1,1,3,0,0,0,0,0,0,2,0,0,0,17,3,2,2,2,2,2,8
1,1,3,0,0,0,0,0,0,6,12,12,12,3,0,0,0,0,2,3,1
7,7,3,0,0,0,0,0,0,6,2,2,2,0,0,0,0,0,2,3,1
3,3,3,0,0,0,0,6,6,2,2,2,6,0,0,0,0,0,8,3,1
3,6,6,2,2,2,6,2,2,2,2,2,2,0,0,0,0,0,0,3,7
3,0,0,0,0,0,0,2,2,2,6,6,6,0,0,0,0,0,0,3,2
6,0,0,0,0,0,0,2,15,6,6,15,6,0,0,0,0,0,0,18,2
3,0,0,0,0,0,0,2,15,6,6,15,2,0,0,0,0,0,0,18,3
3,0,0,0,0,0,0,2,2,6,6,15,6,20,0,0,0,0,0,19,3
3,3,0,0,0,0,0,3,2,6,6,15,2,2,3,2,2,2,2,2,3
2,8,16,0,0,0,3,3,6,15,6,6,2,2,3,12,0,0,0,0,3
2,0,0,0,0,0,0,3,2,15,2,6,2,2,3,12,0,0,0,0,3
3,0,0,0,0,0,0,3,2,6,8,8,2,2,3,12,0,0,0,0,3
1,3,0,0,0,0,0,3,2,6,1,1,2,2,6,3,3,3,14,21,3
1,3,0,0,0,0,22,3,2,2,1,1,6,3,2,5,1,2,2,2,2
1,3,0,0,0,3,3,3,3,6,1,1,1,1,1,1,1,1,1,1,1
1,2,2,2,2,1,1,1,1,1,1,1,1,1,1,1,1,1,1,1,1
endlayer

layer
1,1,1,1,1,1,1,7,3,3,6,3,3,3,3,2,1,1,1,1,1
1,2,3,2,2,2,3,3,3,14,0,0,0,0,3,8,1,1,1,1,1
1,8,3,3,3,3,3,3,3,14,0,0,0,0,6,1,1,1,1,1,1
1,1,3,0,0,0,6,6,8,2,0,0,0,0,3,1,1,1,1,1,1
1,1,3,0,0,0,0,16,0,2,0,0,0,0,3,2,2,2,2,5,1
1,1,3,0,0,0,0,0,0,2,0,0,0,0,3,2,2,2,2,2,1
1,1,3,0,0,0,0,0,0,6,18,18,18,3,23,0,0,0,2,3,1
1,1,6,0,0,0,0,0,0,6,6,6,2,24,0,0,0,0,8,3,1
7,3,3,0,0,0,0,6,6,3,2,2,6,0,0,0,0,0,0,3,1
3,6,6,2,2,2,3,15,15,6,3,2,6,0,0,0,0,0,0,3,1
3,0,0,0,0,0,0,2,6,8,8,6,6,0,0,0,0,0,0,3,7
3,0,0,0,0,0,0,2,1,1,1,1,6,0,0,0,0,0,0,0,2
3,0,0,0,0,0,0,2,1,1,1,1,6,0,0,0,0,0,0,0,3
3,0,0,0,0,0,0,3,7,1,1,1,6,0,0,0,0,0,0,0,3
3,8,0,0,0,0,0,3,5,1,1,1,6,6,3,2,2,2,2,2,3
2,0,16,0,0,0,3,3,3,1,1,1,8,2,3,19,0,0,0,0,3
2,0,0,0,0,0,0,3,2,1,1,1,4,2,3,18,0,0,0,0,3
3,0,0,0,0,0,0,3,2,1,1,1,7,3,3,18,0,0,0,0,3
1,3,0,0,0,0,0,3,2,1,1,1,6,3,3,3,3,3,14,21,3
1,3,0,0,0,0,0,3,3,7,1,1,6,2,5,1,1,2,2,2,2
1,3,0,0,0,6,3,3,3,6,1,1,1,1,1,1,1,1,1,1,1
1,2,2,2,2,1,1,1,1,1,1,1,1,1,1,1,1,1,1,1,1
endlayer

layer
1,1,1,1,1,1,1,1,3,3,3,3,3,3,5,1,1,1,1,1,1
1,1,4,3,3,3,5,1,3,14,0,0,0,0,3,1,1,1,1,1,1
1,1,3,3,3,3,3,3,3,14,0,0,0,0,3,1,1,1,1,1,1
1,1,3,23,23,23,6,5,0,2,0,0,0,0,3,1,1,1,1,1,1
1,1,3,0,0,0,0,16,0,2,0,0,0,0,3,2,2,2,5,1,1
1,1,3,0,0,0,0,0,0,2,0,0,0,25,3,2,2,2,2,2,1
1,1,3,0,0,0,0,0,0,6,0,0,0,3,12,12,12,12,8,3,1
1,1,3,0,0,0,0,0,0,3,6,6,2,12,12,12,12,12,0,3,1
1,3,3,0,0,0,0,3,3,3,3,3,3,12,12,12,12,12,0,3,1
7,2,6,6,6,6,3,1,1,1,4,8,3,12,12,12,12,12,0,3,1
2,2,6,6,6,6,3,1,1,1,1,1,3,12,12,12,12,12,0,3,1
2,2,6,6,6,6,3,1,1,1,1,1,2,0,0,0,0,0,0,26,7
3,6,6,6,6,6,3,2,1,1,1,1,6,0,0,0,0,0,0,26,3
3,28,6,6,6,6,3,5,1,1,1,1,6,27,0,0,0,0,0,26,3
3,0,29,29,29,29,3,5,1,1,1,1,8,3,3,2,2,2,2,2,3
3,0,16,26,26,26,6,7,7,1,1,1,1,3,3,0,0,0,0,0,3
3,0,0,0,0,0,0,3,3,1,1,1,1,3,3,0,0,0,0,0,3
3,0,0,0,0,0,0,3,3,1,1,1,1,3,3,0,0,0,0,0,3
1,3,0,0,0,0,0,3,3,1,1,1,1,8,3,3,3,3,14,21,3
1,3,0,0,0,0,25,3,2,1,1,1,1,1,1,1,1,2,2,2,2
1,3,0,0,0,3,3,3,8,1,1,1,1,1,1,1,1,1,1,1,1
1,2,2,2,2,1,1,1,1,1,1,1,1,1,1,1,1,1,1,1,1
endlayer

layer
1,1,1,1,1,1,1,1,6,3,3,6,3,6,1,1,1,1,1,1,1
1,1,1,4,3,5,1,1,3,14,12,12,12,3,7,1,1,1,1,1,1
1,1,6,3,3,3,3,3,3,14,12,12,12,3,2,1,1,1,1,1,1
1,1,3,3,3,3,5,0,0,3,12,12,12,3,6,1,1,1,1,1,1
1,1,3,3,3,3,7,16,0,3,12,12,12,12,3,1,1,1,1,1,1
1,1,6,3,3,3,3,31,31,3,12,12,12,12,3,2,30,2,2,6,1
1,1,3,3,3,3,3,3,3,3,3,3,3,3,2,0,0,0,0,2,1
1,1,3,3,3,3,3,3,3,3,3,3,3,0,32,0,0,0,0,3,1
1,3,3,3,3,3,3,6,6,2,8,8,3,0,0,0,0,0,0,3,1
1,3,0,0,0,12,3,1,1,1,1,1,3,0,0,0,0,0,0,6,1
1,33,0,0,0,12,2,1,1,1,1,1,3,6,2,2,2,2,31,3,1
1,3,0,0,0,12,2,1,1,1,1,1,2,34,12,12,12,12,2,3,1
3,3,0,0,0,2,3,1,1,1,1,1,2,34,12,12,12,12,2,2,7
3,0,0,0,0,3,1,1,1,1,1,1,8,34,12,12,12,12,2,2,2
2,0,0,0,0,36,1,1,1,1,1,1,1,3,3,35,35,35,2,2,3
2,0,16,0,0,3,1,1,1,1,1,1,1,6,3,12,12,12,12,12,6
2,31,37,3,3,3,3,3,1,1,1,1,1,6,6,12,12,12,12,12,3
1,6,3,3,3,3,3,3,7,1,1,1,1,8,3,12,12,12,12,12,3
1,3,3,3,3,3,3,3,2,1,1,1,1,1,6,3,3,6,14,21,6
1,3,3,3,3,3,3,3,8,1,1,1,1,1,1,1,1,2,2,2,6
1,6,3,3,6,3,3,6,1,1,1,1,1,1,1,1,1,1,1,1,1
1,6,2,2,2,1,1,1,1,1,1,1,1,1,1,1,1,1,1,1,1
endlayer

layer
1,1,1,1,1,1,1,1,2,3,3,3,3,6,1,1,1,1,1,1,1
1,1,1,1,1,1,1,1,2,14,0,0,0,2,1,1,1,1,1,1,1
1,1,16,1,1,6,3,3,2,14,0,0,0,36,1,1,1,1,1,1,1
1,1,3,2,30,2,0,0,0,2,0,0,0,2,6,1,1,1,1,1,1
1,1,3,11,0,0,0,16,16,2,0,0,0,12,2,1,1,1,1,1,1
1,1,3,0,0,0,0,0,0,2,0,0,0,12,2,6,38,6,28,2,1
1,1,3,0,0,0,0,0,0,6,2,39,3,3,2,0,0,0,0,2,1
1,1,3,12,12,12,2,2,39,2,1,1,2,0,32,0,0,0,0,3,1
1,3,3,3,3,3,3,1,1,1,1,1,28,0,0,0,0,0,0,28,1
1,2,0,0,0,19,3,1,1,1,1,1,2,0,0,0,0,0,0,3,1
1,38,0,0,0,18,2,1,1,1,1,1,2,6,2,2,2,2,2,3,1
1,2,0,0,0,18,2,1,1,1,1,1,1,3,0,0,0,0,2,1,1
3,2,0,0,0,2,6,1,1,1,1,1,1,6,0,0,0,0,36,1,1
3,0,0,0,0,2,1,1,1,1,1,1,1,2,13,0,0,0,2,1,1
28,0,0,0,0,40,1,1,1,1,1,1,1,6,6,0,0,0,2,2,3
2,0,0,0,0,2,1,1,1,1,1,1,1,1,2,0,0,0,0,0,3
2,2,2,2,2,2,2,6,1,1,1,1,1,1,33,0,0,0,0,0,3
1,3,11,0,0,0,0,2,1,1,1,1,1,1,3,0,0,0,0,0,3
1,3,0,0,0,0,0,36,1,1,1,1,1,1,3,3,3,3,14,21,3
1,3,0,0,0,0,0,3,1,1,1,1,1,1,1,1,1,2,2,2,6
1,3,41,21,3,3,3,3,1,1,1,1,1,1,1,1,1,1,1,1,1
1,2,2,2,2,1,1,1,1,1,1,1,1,1,1,1,1,1,1,1,1
endlayer

layer
1,1,1,1,1,1,1,1,2,3,2,1,2,3,1,1,1,1,1,1,1
1,1,1,1,1,1,1,1,2,0,0,0,0,2,1,1,1,1,1,1,1
1,1,16,1,1,6,1,2,2,0,0,0,0,40,1,1,1,1,1,1,1
1,1,3,2,38,2,0,0,0,2,0,0,0,2,6,1,1,1,1,1,1
1,1,2,0,0,0,0,0,0,2,0,0,0,0,2,1,1,1,1,1,1
1,1,1,0,0,0,0,0,0,2,0,0,0,0,2,6,6,6,1,2,1
1,1,2,0,0,0,0,0,0,6,2,38,3,3,3,0,0,0,0,2,1
1,1,3,19,18,18,2,2,38,2,1,1,2,0,32,0,0,0,0,3,1
1,3,3,3,3,3,3,1,1,1,1,1,1,0,0,0,0,0,0,1,1
1,2,0,0,0,0,3,1,1,1,1,1,2,0,0,0,0,0,0,3,1
1,2,0,0,0,0,1,1,1,1,1,1,2,6,2,2,2,2,2,2,1
1,2,0,0,0,0,2,1,1,1,1,1,1,3,0,0,0,0,2,1,1
2,2,0,0,0,2,6,1,1,1,1,1,1,1,0,0,0,0,38,1,1
3,0,0,0,0,2,1,1,1,1,1,1,1,2,0,0,0,0,2,1,1
1,0,0,0,0,2,1,1,1,1,1,1,1,2,6,0,0,0,2,2,2
2,0,0,0,0,2,1,1,1,1,1,1,1,1,6,0,0,0,0,0,3
2,2,2,2,2,2,2,6,1,1,1,1,1,1,38,0,0,0,0,0,2
1,3,0,0,0,0,0,2,1,1,1,1,1,1,3,0,0,0,0,0,1
1,1,0,0,0,0,0,38,1,1,1,1,1,1,6,3,1,3,0,0,6
1,3,0,0,0,0,0,3,1,1,1,1,1,1,1,1,1,2,2,2,2
1,2,0,21,3,1,3,6,1,1,1,1,1,1,1,1,1,1,1,1,1
1,2,2,1,2,1,1,1,1,1,1,1,1,1,1,1,1,1,1,1,1
endlayer

layer
1,1,1,1,1,1,1,1,2,3,3,3,3,3,1,1,1,1,1,1,1
1,1,1,1,1,1,1,1,2,0,0,0,0,2,1,1,1,1,1,1,1
1,1,42,35,35,3,3,3,3,0,0,0,0,2,1,1,1,1,1,1,1
1,1,3,2,2,2,0,0,0,2,0,0,0,2,6,1,1,1,1,1,1
1,1,3,0,0,0,0,0,0,2,0,0,0,0,2,1,1,1,1,1,1
1,1,3,0,0,0,0,0,0,2,0,0,0,0,2,2,6,2,2,6,1
1,1,3,0,0,0,0,0,0,3,6,3,3,3,3,0,0,0,0,2,1
1,1,3,0,0,0,2,2,2,2,1,1,2,24,0,0,0,0,0,3,1
1,3,3,3,3,3,3,1,1,1,1,1,2,24,0,0,0,0,0,3,1
1,2,0,0,0,0,3,1,1,1,1,1,2,24,0,0,0,0,0,3,1
1,2,0,0,0,0,3,1,1,1,1,1,2,3,2,2,2,2,2,3,1
1,2,0,0,0,0,6,1,1,1,1,1,1,3,0,0,0,0,2,1,1
3,2,0,0,0,2,3,1,1,1,1,1,1,3,0,0,0,0,3,1,1
3,0,0,0,0,2,43,1,1,1,1,1,1,2,0,0,0,0,2,1,1
3,0,0,0,0,2,43,1,1,1,1,1,1,2,3,0,0,0,2,2,3
2,0,0,0,0,2,43,1,1,1,1,1,1,1,6,0,0,0,0,0,3
2,2,2,2,2,2,2,3,1,1,1,1,1,1,3,0,0,0,0,0,3
1,3,43,0,0,0,0,6,1,1,1,1,1,1,3,0,0,0,0,0,3
1,3,43,0,0,0,0,3,1,1,1,1,1,1,3,3,3,3,0,0,3
1,3,43,0,0,0,0,3,1,1,1,1,1,1,1,1,1,2,2,2,2
1,3,43,21,3,3,3,3,1,1,1,1,1,1,1,1,1,1,1,1,1
1,2,2,2,2,1,1,1,1,1,1,1,1,1,1,1,1,1,1,1,1
endlayer

layer
1,1,1,1,1,1,1,1,7,7,3,6,3,6,1,1,1,1,1,1,1
1,1,1,1,1,1,1,1,4,34,0,0,0,6,1,1,1,1,1,1,1
1,1,1,1,1,2,6,3,3,34,0,0,0,2,1,1,1,1,1,1,1
1,1,3,2,2,2,26,26,26,2,0,0,0,2,5,1,1,1,1,1,1
1,1,3,0,0,37,26,26,26,2,26,26,26,26,5,1,1,1,1,1,1
1,1,2,0,0,37,26,20,26,2,26,26,26,26,2,7,7,7,7,5,1
1,1,2,26,26,37,26,26,26,3,3,3,3,3,2,0,0,26,26,5,1
1,1,2,31,31,37,2,2,2,2,44,44,6,0,0,0,0,26,26,5,1
1,3,3,3,3,3,3,44,44,44,44,44,6,0,0,0,0,26,26,5,1
1,2,0,0,0,0,3,16,16,16,16,16,6,0,0,0,0,26,26,5,1
1,2,0,0,0,0,3,1,1,1,1,1,8,3,29,29,29,6,2,8,1
1,2,0,0,0,0,3,1,1,1,1,1,1,3,0,0,0,37,2,24,1
7,2,31,31,31,2,3,1,1,1,1,1,1,6,0,0,0,37,2,24,1
4,26,26,26,26,5,1,1,1,1,1,1,1,2,0,0,0,37,2,24,1
4,26,10,26,26,5,1,1,1,1,1,1,1,2,2,31,31,31,2,2,3
4,26,26,26,26,5,1,1,1,1,1,1,1,1,3,26,26,0,0,0,6
8,2,2,2,2,2,6,7,1,1,1,1,1,1,3,26,26,0,0,0,3
1,6,0,0,0,0,0,2,1,1,1,1,1,1,3,26,26,0,0,0,3
1,3,0,0,0,0,0,3,1,1,1,1,1,1,6,3,3,6,0,0,6
1,3,0,0,0,0,0,3,1,1,1,1,1,1,1,1,1,2,2,2,6
1,6,0,0,6,3,3,8,1,1,1,1,1,1,1,1,1,1,1,1,1
1,4,2,2,5,1,1,1,1,1,1,1,1,1,1,1,1,1,1,1,1
endlayer

layer
1,1,1,1,1,1,1,1,1,1,28,28,28,1,1,1,1,1,1,1,1
1,1,1,1,1,1,1,1,1,28,43,43,43,28,1,1,1,1,1,1,1
1,1,1,1,1,1,1,1,1,28,43,27,43,28,1,1,1,1,1,1,1
1,1,1,45,45,1,1,1,1,28,43,43,43,28,1,1,1,1,1,1,1
1,1,42,47,47,46,1,1,1,4,8,8,8,5,1,1,1,1,1,1,1
1,1,42,47,47,46,1,1,1,4,28,28,28,5,1,1,1,1,1,1,1
1,1,1,48,48,1,1,1,1,4,8,8,8,5,28,28,28,1,1,1,1
1,1,7,28,28,7,1,1,1,1,1,1,1,28,28,28,28,1,1,1,1
1,4,2,8,8,2,5,1,1,1,1,1,1,28,28,27,28,1,1,1,1
1,28,5,24,25,4,28,1,1,1,1,1,1,28,28,28,28,1,1,1,1
1,28,5,24,25,4,28,1,1,1,1,1,1,49,46,43,42,49,1,1,1
1,4,50,7,7,50,5,1,1,1,1,1,1,48,0,0,0,48,1,1,1
1,1,8,28,28,8,1,1,1,1,1,1,1,43,0,0,0,43,1,1,1
1,1,1,1,1,1,1,1,1,1,1,1,1,45,0,0,0,45,1,1,1
1,1,1,1,1,1,1,1,1,1,1,1,1,49,49,49,49,49,1,1,1
1,1,1,1,1,1,1,1,1,1,1,1,1,1,28,50,50,50,50,7,28
1,28,6,7,28,7,6,1,1,1,1,1,1,1,28,50,2,16,16,50,28
1,28,4,0,0,0,5,28,1,1,1,1,1,1,28,50,50,16,16,50,28
1,28,28,0,0,0,28,28,1,1,1,1,1,1,1,28,50,50,50,2,28
1,28,4,0,0,0,5,28,1,1,1,1,1,1,1,1,1,8,8,28,1
1,28,6,8,28,8,6,1,1,1,1,1,1,1,1,1,1,1,1,1,1
1,1,28,28,1,1,1,1,1,1,1,1,1,1,1,1,1,1,1,1,1
endlayer

layer
1,1,1,1,1,1,1,1,1,1,1,1,1,1,1,1,1,1,1,1,1
1,1,1,1,1,1,1,1,1,1,1,1,1,1,1,1,1,1,1,1,1
1,1,1,1,1,1,1,1,1,1,1,1,1,1,1,1,1,1,1,1,1
1,1,1,1,1,1,1,1,1,1,1,1,1,1,1,1,1,1,1,1,1
1,1,1,1,1,1,1,1,1,1,1,1,1,1,1,1,1,1,1,1,1
1,1,1,1,1,1,1,1,1,1,1,1,1,1,1,1,1,1,1,1,1
1,1,1,1,1,1,1,1,1,1,1,1,1,1,1,1,1,1,1,1,1
1,1,1,1,1,1,1,1,1,1,1,1,1,1,1,1,1,1,1,1,1
1,1,1,1,1,1,1,1,1,1,1,1,1,1,1,1,1,1,1,1,1
1,1,1,1,1,1,1,1,1,1,1,1,1,1,1,1,1,1,1,1,1
1,1,1,1,1,1,1,1,1,1,1,1,1,1,46,45,42,1,1,1,1
1,1,1,1,1,1,1,1,1,1,1,1,1,48,47,47,47,48,1,1,1
1,1,1,1,1,1,1,1,1,1,1,1,1,42,47,27,47,46,1,1,1
1,1,1,1,1,1,1,1,1,1,1,1,1,45,47,47,47,45,1,1,1
1,1,1,1,1,1,1,1,1,1,1,1,1,1,46,48,42,1,1,1,1
1,1,1,1,1,1,1,1,1,1,1,1,1,1,1,1,1,1,1,1,1
1,1,4,7,7,7,7,1,1,1,1,1,1,1,1,1,1,1,1,1,1
1,1,4,43,43,43,5,1,1,1,1,1,1,1,1,1,1,1,1,1,1
1,1,4,43,23,43,5,1,1,1,1,1,1,1,1,1,1,1,1,1,1
1,1,4,43,43,43,5,1,1,1,1,1,1,1,1,1,1,1,1,1,1
1,1,8,8,8,8,5,1,1,1,1,1,1,1,1,1,1,1,1,1,1
1,1,1,1,1,1,1,1,1,1,1,1,1,1,1,1,1,1,1,1,1
endlayer

