
# Created by Ruins mod version 16.7 Ingame Parser
# authoring Player: lafuller

weight=1
embed_into_distance=5
acceptable_target_blocks=
unacceptable_target_blocks=flowing_water,water,flowing_lava,lava,ice,bedrock,netherrack,nether_brick,nether_brick_fence,soul_sand,quartz_ore,gravel,end_stone,obsidian,iron_bars,cloud,flesh,ash_block,slime_grass,slime_congealed,slime_dirt
biomesToSpawnIn=forest,fen,taiga,woodland,woodlands,orchard,eucalyptus_forest,birch forest,cold taiga
dimensions=24,10,12
allowable_overhang=0
max_leveling=5
leveling_buffer=-1
preserve_water=0
preserve_lava=0

rule1=0,100,air
rule2=0,100,preserveBlock
rule3=0,100,minecraft:log2-1
rule4=0,100,minecraft:log-1
rule5=0,100,minecraft:ladder-2
rule6=0,100,minecraft:log-5
rule7=0,100,minecraft:spruce_fence-0
rule8=0,100,minecraft:log-9
rule9=0,100,minecraft:wooden_slab-9
rule10=0,100,minecraft:wooden_slab-8
rule11=0,100,minecraft:spruce_stairs-6
rule12=0,100,minecraft:trapdoor-9
rule13=0,100,minecraft:wooden_slab-1
rule14=0,100,minecraft:planks-1
rule15=0,100,minecraft:spruce_stairs-0
rule16=0,100,minecraft:spruce_stairs-3
rule17=0,100,minecraft:spruce_stairs-2
rule18=0,100,minecraft:trapdoor-0
rule19=0,100,minecraft:spruce_stairs-1
rule20=0,100,minecraft:spruce_stairs-5
rule21=0,100,minecraft:spruce_fence_gate-2
rule22=0,100,minecraft:spruce_fence_gate-0
rule23=0,100,minecraft:spruce_fence_gate-3
rule24=0,100,minecraft:spruce_fence_gate-1
rule25=0,100,minecraft:spruce_stairs-4
rule26=0,100,minecraft:spruce_stairs-7
rule27=0,100,minecraft:wooden_slab-13
rule28=0,100,minecraft:dark_oak_stairs-6
rule29=0,100,minecraft:dark_oak_stairs-4
rule30=0,100,minecraft:wooden_slab-5
rule31=0,100,minecraft:double_wooden_slab-5
rule32=0,100,minecraft:dark_oak_stairs-7
rule33=0,100,minecraft:trapdoor-8
rule34=0,100,minecraft:dark_oak_stairs-1
rule35=0,100,minecraft:dark_oak_stairs-5

layer
2,2,2,2,2,2,2,2,2,2,2,2
2,2,2,2,2,2,2,2,2,2,2,2
2,2,2,3,2,2,2,2,2,2,2,2
2,2,2,2,2,2,3,2,2,2,2,2
2,2,2,3,2,2,2,2,2,3,2,2
2,2,2,2,2,2,2,2,2,2,2,2
2,2,2,2,2,4,2,2,2,2,2,2
2,2,3,2,2,2,2,3,2,2,2,2
2,2,2,2,2,2,2,2,2,2,2,2
2,2,2,2,2,2,2,2,2,2,2,2
endlayer

layer
2,2,2,2,2,2,2,2,2,2,2,2
2,2,2,2,2,2,2,2,2,2,2,2
2,2,2,3,2,2,2,2,2,2,2,2
2,2,2,2,2,2,3,2,2,2,2,2
2,2,2,3,2,2,2,2,2,3,2,2
2,2,2,2,2,2,2,2,2,2,2,2
2,2,2,2,2,4,2,2,2,2,2,2
2,2,3,2,2,2,2,3,2,2,2,2
2,2,2,2,2,2,2,2,2,2,2,2
2,2,2,2,2,2,2,2,2,2,2,2
endlayer

layer
2,2,2,2,2,2,2,2,2,2,2,2
2,2,2,2,2,2,2,2,2,2,2,2
2,2,2,3,2,2,2,2,2,2,2,2
2,2,2,2,2,2,3,2,2,2,2,2
2,2,2,3,2,2,2,2,2,3,2,2
2,2,2,2,2,2,2,2,2,2,2,2
2,2,2,2,2,4,2,2,2,2,2,2
2,2,3,2,2,2,2,3,2,2,2,2
2,2,2,2,2,2,2,2,2,2,2,2
2,2,2,2,2,2,2,2,2,2,2,2
endlayer

layer
2,2,2,2,2,2,2,2,2,2,2,2
2,2,2,2,2,2,2,2,2,2,2,2
2,2,2,3,2,2,2,2,2,2,2,2
2,2,2,2,2,2,3,2,2,2,2,2
2,2,2,3,2,2,2,2,2,3,2,2
2,2,2,2,2,2,2,2,2,2,2,2
2,2,2,2,2,4,2,2,2,2,2,2
2,2,3,2,2,2,2,3,2,2,2,2
2,2,2,2,2,2,2,2,2,2,2,2
2,2,2,2,2,2,2,2,2,2,2,2
endlayer

layer
2,2,2,2,2,2,2,2,2,2,2,2
2,2,2,2,2,2,2,2,2,2,2,2
2,2,2,3,2,2,2,2,2,2,2,2
2,2,2,2,2,2,3,2,2,2,2,2
2,2,2,3,2,2,2,2,2,3,2,2
2,2,2,2,2,2,2,2,2,2,2,2
2,2,2,2,2,4,2,2,2,2,2,2
2,2,3,2,2,2,2,3,2,2,2,2
2,2,2,2,2,2,2,2,2,2,2,2
2,2,2,2,2,2,2,2,2,2,2,2
endlayer

layer
2,2,2,2,2,2,2,2,2,2,2,2
2,2,2,2,2,2,2,2,2,2,2,2
2,2,2,3,2,2,2,2,2,2,2,2
2,2,2,2,2,2,3,2,2,2,2,2
2,2,2,3,2,2,2,2,2,3,2,2
2,2,2,2,2,1,1,2,2,2,2,2
2,2,2,2,2,4,5,1,2,2,2,2
2,2,3,2,2,2,2,3,2,2,2,2
2,2,2,2,2,2,2,2,2,2,2,2
2,2,2,2,2,2,2,2,2,2,2,2
endlayer

layer
2,2,2,2,2,2,2,2,2,2,2,2
2,2,2,2,2,2,2,2,2,2,2,2
2,2,2,3,2,2,2,2,2,2,2,2
2,2,2,2,2,2,3,2,2,2,2,2
2,2,2,3,2,1,1,2,2,3,2,2
2,2,2,2,1,1,1,1,2,2,2,2
2,2,2,2,1,4,5,1,1,2,2,2
2,2,3,2,2,1,1,3,2,2,2,2
2,2,2,2,2,2,2,2,2,2,2,2
2,2,2,2,2,2,2,2,2,2,2,2
endlayer

layer
2,2,2,2,2,2,2,2,2,2,2,2
2,2,2,2,2,6,2,2,2,2,2,2
2,2,2,3,2,6,2,2,2,2,2,2
2,2,2,2,2,6,4,2,2,2,2,2
2,2,2,3,2,6,1,1,2,3,2,2
2,2,2,2,1,6,1,1,1,2,2,2
2,2,2,2,1,6,5,1,1,2,2,2
2,2,3,2,2,6,1,4,2,2,2,2
2,2,2,2,2,6,2,2,2,2,2,2
2,2,2,2,2,2,2,2,2,2,2,2
endlayer

layer
2,2,2,7,2,2,2,2,2,2,2,2
2,2,2,6,2,2,2,2,2,2,2,2
7,8,8,6,8,8,8,8,8,7,2,2
2,2,9,6,10,10,4,9,9,1,2,2
7,8,8,6,8,8,8,8,8,4,11,2
2,2,9,6,10,10,10,10,6,9,9,2
2,2,9,6,10,4,5,12,6,9,9,2
7,8,8,6,8,8,8,4,6,11,2,2
2,2,2,6,2,1,1,1,6,2,2,2
2,2,2,7,2,2,2,2,7,2,2,2
endlayer

layer
2,2,2,2,2,2,2,2,2,2,2,2
2,2,13,13,13,13,13,13,2,2,2,2
2,13,14,4,15,15,14,13,13,13,2,2
2,13,16,1,1,1,4,15,15,13,13,2
2,13,16,1,1,1,1,1,1,4,14,2
2,13,16,1,1,1,1,1,1,1,17,2
2,13,16,1,1,4,18,1,1,1,17,2
2,13,4,1,1,17,19,19,4,14,2,2
2,2,13,19,19,20,13,13,13,2,2,2
2,2,2,2,2,2,2,2,2,2,2,2
endlayer

layer
2,2,2,2,2,2,2,2,2,2,2,2
2,2,2,2,2,2,2,2,2,2,2,2
2,2,7,4,7,7,1,1,1,2,2,2
2,1,21,1,1,1,4,7,7,1,2,2
2,1,7,1,1,1,1,1,1,4,7,2
2,1,21,1,1,1,1,1,1,1,22,2
2,1,7,1,1,4,5,1,1,1,7,2
2,2,4,1,1,7,23,7,4,7,2,2
2,2,2,7,24,19,1,1,1,2,2,2
2,2,2,2,2,2,2,2,2,2,2,2
endlayer

layer
2,2,2,2,2,2,2,2,2,2,2,2
2,2,2,2,2,2,2,2,2,2,2,2
2,2,7,4,7,7,7,1,1,2,2,2
2,1,21,1,1,1,4,7,7,7,2,2
2,1,7,1,1,1,1,1,1,4,7,2
2,1,21,1,1,1,1,1,1,1,22,2
2,1,7,1,1,4,5,1,1,1,7,2
2,2,4,1,1,7,23,7,4,7,7,2
2,2,7,7,24,19,1,1,1,2,2,2
2,2,2,2,2,2,2,2,2,2,2,2
endlayer

layer
2,2,2,2,2,2,2,2,2,2,2,2
2,2,2,2,2,2,2,2,2,2,2,2
2,2,15,4,25,25,11,1,2,2,2,2
2,7,8,8,8,8,4,8,8,8,7,2
2,1,26,1,1,1,1,1,1,4,25,2
2,1,26,1,1,1,1,1,1,1,11,2
2,1,26,1,1,4,5,1,1,1,20,2
7,8,8,8,8,8,8,8,8,8,8,7
2,2,7,20,20,14,7,1,1,2,2,2
2,2,2,2,2,2,2,2,2,2,2,2
endlayer

layer
2,2,7,2,2,7,2,2,2,2,2,2
2,2,6,25,9,6,2,2,2,2,2,2
2,2,6,4,14,6,15,13,1,2,2,2
2,1,6,9,9,6,4,14,17,15,2,2
2,1,6,9,9,6,9,9,9,4,17,2
2,1,6,9,9,6,9,1,1,1,17,2
2,1,6,9,9,6,5,1,1,1,17,2
2,2,6,9,9,6,19,19,4,19,1,2
2,2,6,19,19,6,1,1,1,2,2,2
2,2,7,2,2,7,2,2,2,2,2,2
endlayer

layer
2,2,2,2,2,2,2,2,2,2,2,2
2,2,2,2,2,1,1,2,2,2,2,2
2,2,15,4,15,13,7,1,1,2,2,2
2,1,16,1,1,1,4,15,17,1,2,2
2,1,13,1,1,1,1,1,1,4,7,2
2,1,16,1,1,1,1,1,1,1,7,2
2,1,16,1,1,4,5,1,1,1,7,2
2,2,4,19,19,4,24,7,4,7,1,2
2,2,2,1,1,1,1,1,1,2,2,2
2,2,2,2,2,2,2,2,2,2,2,2
endlayer

layer
2,2,2,2,2,2,2,2,2,2,2,2
2,2,2,2,1,1,1,2,2,2,2,2
2,2,1,4,23,24,7,1,1,2,2,2
2,1,7,1,1,1,4,7,7,1,2,2
2,1,22,1,1,1,1,1,1,4,7,2
2,1,7,1,1,1,1,1,1,1,7,2
2,1,22,1,1,4,5,1,1,1,7,2
2,2,4,23,23,4,24,7,4,7,7,2
2,2,2,1,1,1,1,1,1,2,2,2
2,2,2,2,2,2,2,2,2,2,2,2
endlayer

layer
2,2,2,2,2,2,2,2,2,2,2,2
2,2,2,27,27,27,27,2,2,2,2,2
2,2,29,4,25,25,28,27,27,2,2,2
2,27,28,1,1,1,4,25,25,11,27,2
2,27,28,1,1,1,1,1,1,4,11,2
2,27,28,1,1,1,1,1,1,1,11,2
2,27,28,1,1,4,5,1,1,1,11,2
2,27,4,20,20,4,20,20,4,20,11,2
2,2,27,27,27,1,1,1,1,2,2,2
2,2,2,2,2,2,2,2,2,2,2,2
endlayer

layer
2,2,2,2,2,2,2,2,2,2,2,2
2,2,2,2,2,2,2,2,2,2,2,2
2,2,2,30,30,30,30,30,1,2,2,2
2,2,2,30,27,6,4,31,31,30,2,2
2,2,30,30,27,6,1,1,1,4,30,2
2,2,30,30,27,6,1,1,1,31,30,2
2,2,30,30,27,4,5,1,1,31,30,2
2,2,30,30,31,31,31,31,4,31,30,2
2,2,2,30,30,30,30,30,30,30,2,2
2,2,2,2,2,2,2,2,2,2,2,2
endlayer

layer
2,2,2,2,2,2,2,2,2,2,2,2
2,2,2,2,2,2,2,2,2,2,2,2
2,2,2,2,1,1,1,1,1,2,2,2
2,2,2,1,1,1,4,15,15,1,2,2
2,2,2,1,1,16,1,1,1,4,1,2
2,2,2,1,1,16,1,1,1,17,1,2
2,2,2,1,1,4,5,1,1,17,1,2
2,2,2,1,1,7,24,7,4,7,2,2
2,2,2,2,1,1,1,1,1,2,2,2
2,2,2,2,2,2,2,2,2,2,2,2
endlayer

layer
2,2,2,2,2,2,2,2,2,2,2,2
2,2,2,2,2,2,2,2,2,2,2,2
2,2,2,2,2,1,1,1,1,2,2,2
2,2,2,2,1,1,4,7,7,1,2,2
2,2,2,1,1,7,1,1,1,4,1,2
2,2,2,1,1,7,1,1,1,7,1,2
2,2,2,1,1,4,5,1,1,7,1,2
2,2,2,1,1,7,24,7,4,7,2,2
2,2,2,2,1,1,1,1,1,2,2,2
2,2,2,2,2,2,2,2,2,2,2,2
endlayer

layer
2,2,2,2,2,2,2,2,2,2,2,2
2,2,2,2,2,2,2,2,2,2,2,2
2,2,2,2,2,1,2,2,7,2,2,2
2,2,2,2,1,7,4,25,6,7,2,2
2,2,2,1,1,26,1,1,6,4,1,2
2,2,2,1,1,26,1,1,6,11,1,2
2,2,2,1,1,4,5,1,6,11,1,2
2,2,2,2,1,7,24,7,4,20,2,2
2,2,2,2,2,1,1,1,1,2,2,2
2,2,2,2,2,2,2,2,2,2,2,2
endlayer

layer
2,2,2,2,2,2,2,2,2,2,2,2
2,2,2,2,2,2,2,2,2,2,2,2
2,2,2,2,2,27,29,27,29,2,2,2
2,2,2,2,32,29,4,14,11,28,2,2
2,2,2,2,27,8,8,8,8,4,27,2
2,2,2,2,32,14,9,9,9,14,28,2
2,2,2,2,27,4,33,9,9,14,27,2
2,2,2,2,32,35,20,11,4,34,2,2
2,2,2,2,2,27,27,27,27,2,2,2
2,2,2,2,2,2,2,2,2,2,2,2
endlayer

layer
2,2,2,2,2,2,2,2,2,2,2,2
2,2,2,2,2,2,2,2,2,2,2,2
2,2,2,2,2,2,2,2,2,2,2,2
2,2,2,2,2,7,23,7,23,7,2,2
2,2,2,2,2,21,1,1,1,22,2,2
2,2,2,2,2,7,1,1,1,7,2,2
2,2,2,2,2,21,1,1,1,22,2,2
2,2,2,2,2,7,24,7,24,7,2,2
2,2,2,2,2,2,2,2,2,2,2,2
2,2,2,2,2,2,2,2,2,2,2,2
endlayer

layer
2,2,2,2,2,2,2,2,2,2,2,2
2,2,2,2,2,2,2,2,2,2,2,2
2,2,2,2,2,2,2,2,2,2,2,2
2,2,2,2,2,2,1,1,1,2,2,2
2,2,2,2,2,1,1,1,1,1,2,2
2,2,2,2,2,1,1,1,1,1,2,2
2,2,2,2,2,1,1,1,1,1,2,2
2,2,2,2,2,2,1,1,1,2,2,2
2,2,2,2,2,2,2,2,2,2,2,2
2,2,2,2,2,2,2,2,2,2,2,2
endlayer

