
# Created by Ruins mod version 16.7 Ingame Parser
# authoring Player: lafuller

weight=1
embed_into_distance=5
acceptable_target_blocks=mycelium,grass
unacceptable_target_blocks=
biomesToSpawnIn=mushroom_island,fungi_forest,roofed_forest,swampland
dimensions=46,9,9
allowable_overhang=0
max_leveling=5
leveling_buffer=-1
preserve_water=0
preserve_lava=0

rule1=0,100,preserveBlock
rule2=0,100,minecraft:brown_mushroom_block-10
rule3=0,100,minecraft:brown_mushroom_block-15
rule4=0,100,minecraft:ladder-4

layer
1,1,2,2,2,2,2,1,1
3,2,2,2,2,2,2,2,1
2,2,2,2,2,2,2,2,3
2,2,2,2,2,2,2,2,2
2,2,2,2,2,2,2,2,2
2,2,2,2,2,2,2,2,2
3,2,2,2,2,2,2,2,3
1,2,2,2,2,2,2,2,1
1,1,2,2,2,2,2,1,1
endlayer

layer
1,1,3,2,2,2,2,1,1
1,2,2,2,2,2,2,3,1
3,2,2,2,2,2,2,2,1
2,2,2,2,2,2,2,2,2
2,2,2,2,2,2,2,2,2
2,2,2,2,2,2,2,2,2
1,2,2,2,2,2,2,2,1
1,2,2,2,2,2,2,2,1
1,1,3,2,2,2,3,1,1
endlayer

layer
1,1,2,2,2,2,3,1,1
1,3,2,2,2,2,2,1,1
1,2,2,2,2,2,2,2,1
3,2,2,2,2,2,2,2,3
2,2,2,2,2,2,2,2,2
3,2,2,2,2,2,2,2,2
1,2,2,2,2,2,2,2,1
1,2,2,2,2,2,2,3,1
1,1,1,3,2,2,1,1,1
endlayer

layer
1,1,3,2,2,3,1,1,1
1,1,2,2,2,2,2,1,1
1,2,2,2,2,2,2,2,1
1,2,2,2,2,2,2,2,1
2,2,2,2,2,2,2,2,2
1,2,2,2,2,2,2,2,2
1,2,2,2,2,2,2,2,1
1,3,2,2,2,2,2,1,1
1,1,1,1,2,2,1,1,1
endlayer

layer
1,1,1,3,3,1,1,1,1
1,1,2,2,2,2,2,1,1
1,2,2,2,2,2,2,2,1
1,2,2,2,2,2,2,2,1
2,2,2,2,2,2,2,2,2
1,2,2,2,2,2,2,2,3
1,2,2,2,2,2,2,2,1
1,1,2,2,2,2,2,1,1
1,1,1,1,2,3,1,1,1
endlayer

layer
1,1,1,1,1,1,1,1,1
1,1,2,2,1,2,3,1,1
1,2,2,2,1,2,2,2,1
1,2,2,2,0,2,2,2,1
3,2,2,2,4,2,2,2,3
1,2,2,2,2,2,2,2,1
1,2,2,2,2,2,2,2,1
1,1,2,2,2,2,2,1,1
1,1,1,1,2,1,1,1,1
endlayer

layer
1,1,1,1,1,1,1,1,1
1,1,2,2,1,2,1,1,1
1,2,2,2,0,2,2,2,1
1,2,2,2,0,2,2,2,1
1,2,2,2,4,2,2,2,1
1,2,2,2,2,2,2,2,1
1,2,2,2,2,2,2,2,1
1,1,2,2,2,2,2,1,1
1,1,1,1,3,1,1,1,1
endlayer

layer
1,1,1,1,1,1,1,1,1
1,1,2,2,0,2,1,1,1
1,2,2,2,0,2,2,3,1
1,2,2,2,0,2,2,2,1
1,2,2,2,4,2,2,2,1
1,2,2,2,2,2,2,2,1
1,2,2,2,2,2,2,2,1
1,1,3,2,2,2,2,1,1
1,1,1,1,1,1,1,1,1
endlayer

layer
1,1,1,1,1,1,1,1,1
1,1,2,2,0,2,1,1,1
1,3,2,2,0,2,2,1,1
1,2,2,2,0,2,2,2,1
1,2,2,2,4,2,2,2,1
1,2,2,2,2,2,2,2,1
1,2,2,2,2,2,2,2,1
1,1,1,2,2,2,3,1,1
1,1,1,1,1,1,1,1,1
endlayer

layer
1,1,1,1,1,1,1,1,1
1,1,2,2,2,2,1,1,1
1,1,2,2,2,2,2,1,1
1,2,2,2,2,2,2,2,1
1,2,2,2,4,2,2,2,1
1,2,2,2,2,2,2,2,1
1,3,2,2,2,2,2,3,1
1,1,1,2,2,2,1,1,1
1,1,1,1,1,1,1,1,1
endlayer

layer
1,1,1,1,1,1,1,1,1
1,1,3,2,2,2,1,1,1
1,1,2,2,2,2,2,1,1
1,2,2,2,2,2,2,2,1
1,2,2,2,4,2,2,2,1
1,2,2,2,2,2,2,2,1
1,1,2,2,2,2,2,1,1
1,1,1,2,2,2,1,1,1
1,1,1,1,1,1,1,1,1
endlayer

layer
1,1,1,1,1,1,1,1,1
1,1,1,2,2,3,1,1,1
1,1,2,2,2,2,2,1,1
1,2,2,2,2,2,2,2,1
1,2,2,2,4,2,2,2,1
1,3,2,2,2,2,2,3,1
1,1,2,2,2,2,2,1,1
1,1,1,2,2,2,1,1,1
1,1,1,1,1,1,1,1,1
endlayer

layer
1,1,1,1,1,1,1,1,1
1,1,1,2,2,1,1,1,1
1,1,2,2,2,2,2,1,1
1,2,2,2,2,2,2,3,1
1,2,2,2,4,2,2,2,1
1,1,2,2,2,2,2,1,1
1,1,2,2,2,2,2,1,1
1,1,1,2,2,2,1,1,1
1,1,1,1,1,1,1,1,1
endlayer

layer
1,1,1,1,1,1,1,1,1
1,1,1,2,2,1,1,1,1
1,1,2,2,2,2,3,1,1
1,2,2,2,2,2,2,1,1
1,2,2,2,4,2,2,2,1
1,1,2,2,2,2,2,1,1
1,1,2,2,2,2,2,1,1
1,1,1,3,2,2,1,1,1
1,1,1,1,1,1,1,1,1
endlayer

layer
1,1,1,1,1,1,1,1,1
1,1,1,3,2,1,1,1,1
1,1,2,2,2,2,1,1,1
1,2,2,2,2,2,2,1,1
1,2,2,2,4,2,2,2,1
1,1,2,2,2,2,2,1,1
1,1,2,2,2,2,2,1,1
1,1,1,1,2,2,1,1,1
1,1,1,1,1,1,1,1,1
endlayer

layer
1,1,1,1,1,1,1,1,1
1,1,1,1,2,1,1,1,1
1,1,2,2,2,2,1,1,1
1,2,2,2,2,2,2,1,1
1,2,2,2,4,2,2,2,1
1,1,2,2,2,2,2,1,1
1,1,3,2,2,2,3,1,1
1,1,1,1,2,2,1,1,1
1,1,1,1,1,1,1,1,1
endlayer

layer
1,1,1,1,1,1,1,1,1
1,1,1,1,2,1,1,1,1
1,1,2,2,2,2,1,1,1
1,3,2,2,2,2,2,1,1
1,2,2,2,4,2,2,2,1
1,1,2,2,2,2,2,1,1
1,1,1,2,2,2,1,1,1
1,1,1,1,2,3,1,1,1
1,1,1,1,1,1,1,1,1
endlayer

layer
1,1,1,1,1,1,1,1,1
1,1,1,1,2,1,1,1,1
1,1,2,2,2,2,1,1,1
1,1,2,2,2,2,2,1,1
1,2,2,2,4,2,2,3,1
1,1,2,2,2,2,3,1,1
1,1,1,2,2,2,1,1,1
1,1,1,1,2,1,1,1,1
1,1,1,1,1,1,1,1,1
endlayer

layer
1,1,1,1,1,1,1,1,1
1,1,1,1,3,1,1,1,1
1,1,2,2,2,2,1,1,1
1,1,2,2,2,2,2,1,1
1,2,2,2,4,2,2,1,1
1,1,2,2,2,2,2,1,1
1,1,1,2,2,2,1,1,1
1,1,1,1,2,1,1,1,1
1,1,1,1,1,1,1,1,1
endlayer

layer
1,1,1,1,1,1,1,1,1
1,1,1,1,1,1,1,1,1
1,1,3,2,2,2,1,1,1
1,1,2,2,2,2,2,1,1
1,2,2,2,4,2,2,1,1
1,1,2,2,2,2,2,1,1
1,1,1,2,2,2,1,1,1
1,1,1,1,3,1,1,1,1
1,1,1,1,1,1,1,1,1
endlayer

layer
1,1,1,1,1,1,1,1,1
1,1,1,1,1,1,1,1,1
1,1,1,2,2,2,1,1,1
1,1,2,2,2,2,2,1,1
1,3,2,2,4,2,2,1,1
1,1,2,2,2,2,3,1,1
1,1,1,2,2,2,1,1,1
1,1,1,1,1,1,1,1,1
1,1,1,1,1,1,1,1,1
endlayer

layer
1,1,1,1,1,1,1,1,1
1,1,1,1,1,1,1,1,1
1,1,1,2,2,2,1,1,1
1,1,2,2,2,2,2,1,1
1,1,2,2,4,2,2,1,1
1,1,2,2,2,2,1,1,1
1,1,1,2,2,2,1,1,1
1,1,1,1,1,1,1,1,1
1,1,1,1,1,1,1,1,1
endlayer

layer
1,1,1,1,1,1,1,1,1
1,1,1,1,1,1,1,1,1
1,1,1,2,2,2,1,1,1
1,1,3,2,2,2,3,1,1
1,1,2,2,4,2,2,1,1
1,1,2,2,2,2,1,1,1
1,1,1,2,2,3,1,1,1
1,1,1,1,1,1,1,1,1
1,1,1,1,1,1,1,1,1
endlayer

layer
1,1,1,1,1,1,1,1,1
1,1,1,1,1,1,1,1,1
1,1,1,3,2,2,1,1,1
1,1,1,2,2,2,1,1,1
1,1,2,2,4,2,2,1,1
1,1,2,2,2,2,1,1,1
1,1,1,2,2,1,1,1,1
1,1,1,1,1,1,1,1,1
1,1,1,1,1,1,1,1,1
endlayer

layer
1,1,1,1,1,1,1,1,1
1,1,1,1,1,1,1,1,1
1,1,1,1,2,3,1,1,1
1,1,1,2,2,2,1,1,1
1,1,2,2,4,2,2,1,1
1,1,2,2,2,2,1,1,1
1,1,1,3,2,1,1,1,1
1,1,1,1,1,1,1,1,1
1,1,1,1,1,1,1,1,1
endlayer

layer
1,1,1,1,1,1,1,1,1
1,1,1,1,1,1,1,1,1
1,1,1,1,2,1,1,1,1
1,1,1,2,2,2,1,1,1
1,1,2,2,4,2,2,1,1
1,1,2,2,2,2,1,1,1
1,1,1,1,2,1,1,1,1
1,1,1,1,1,1,1,1,1
1,1,1,1,1,1,1,1,1
endlayer

layer
1,1,1,1,1,1,1,1,1
1,1,1,1,1,1,1,1,1
1,1,1,1,2,1,1,1,1
1,1,1,2,2,2,1,1,1
1,1,2,2,4,2,2,1,1
1,1,2,2,2,2,1,1,1
1,1,1,1,2,1,1,1,1
1,1,1,1,1,1,1,1,1
1,1,1,1,1,1,1,1,1
endlayer

layer
1,1,1,1,1,1,1,1,1
1,1,1,1,1,1,1,1,1
1,1,1,1,2,1,1,1,1
1,1,1,2,2,2,1,1,1
1,1,2,2,4,2,3,1,1
1,1,3,2,2,2,1,1,1
1,1,1,1,2,1,1,1,1
1,1,1,1,1,1,1,1,1
1,1,1,1,1,1,1,1,1
endlayer

layer
1,1,1,1,1,1,1,1,1
1,1,1,1,1,1,1,1,1
1,1,1,1,2,1,1,1,1
1,1,1,2,2,2,1,1,1
1,1,2,2,4,2,1,1,1
1,1,1,2,2,2,1,1,1
1,1,1,1,3,1,1,1,1
1,1,1,1,1,1,1,1,1
1,1,1,1,1,1,1,1,1
endlayer

layer
1,1,1,1,1,1,1,1,1
1,1,1,1,1,1,1,1,1
1,1,1,1,2,1,1,1,1
1,1,1,2,2,2,1,1,1
1,1,3,2,4,2,1,1,1
1,1,1,2,2,2,1,1,1
1,1,1,1,1,1,1,1,1
1,1,1,1,1,1,1,1,1
1,1,1,1,1,1,1,1,1
endlayer

layer
1,1,1,1,1,1,1,1,1
1,1,1,1,1,1,1,1,1
1,1,1,1,3,1,1,1,1
1,1,1,2,2,2,1,1,1
1,1,1,2,4,2,1,1,1
1,1,1,2,2,2,1,1,1
1,1,1,1,1,1,1,1,1
1,1,1,1,1,1,1,1,1
1,1,1,1,1,1,1,1,1
endlayer

layer
1,1,1,1,1,1,1,1,1
1,1,1,1,1,1,1,1,1
1,1,1,1,1,1,1,1,1
1,1,1,2,2,2,1,1,1
1,1,1,2,4,2,1,1,1
1,1,1,2,2,2,1,1,1
1,1,1,1,1,1,1,1,1
1,1,1,1,1,1,1,1,1
1,1,1,1,1,1,1,1,1
endlayer

layer
1,1,1,1,1,1,1,1,1
1,1,1,1,1,1,1,1,1
1,1,1,1,1,1,1,1,1
1,1,1,2,2,2,1,1,1
1,1,1,2,4,2,1,1,1
1,1,1,2,2,2,1,1,1
1,1,1,1,1,1,1,1,1
1,1,1,1,1,1,1,1,1
1,1,1,1,1,1,1,1,1
endlayer

layer
1,1,1,1,1,1,1,1,1
1,1,1,1,1,1,1,1,1
1,1,1,1,1,1,1,1,1
1,1,1,2,2,2,1,1,1
1,1,1,2,4,2,3,1,1
1,1,1,2,2,2,1,1,1
1,1,1,1,1,1,1,1,1
1,1,1,1,1,1,1,1,1
1,1,1,1,1,1,1,1,1
endlayer

layer
1,1,1,1,1,1,1,1,1
1,1,1,1,1,1,1,1,1
1,1,1,1,1,1,1,1,1
1,1,1,2,2,2,1,1,1
1,1,1,2,4,2,2,1,1
1,1,1,2,2,2,1,1,1
1,1,1,1,3,1,1,1,1
1,1,1,1,1,1,1,1,1
1,1,1,1,1,1,1,1,1
endlayer

layer
1,1,1,1,1,1,1,1,1
1,1,1,1,1,1,1,1,1
1,1,1,1,1,1,1,1,1
1,1,1,2,2,2,1,1,1
1,1,3,2,4,2,2,1,1
1,1,1,2,2,2,3,1,1
1,1,1,1,2,1,1,1,1
1,1,1,1,1,1,1,1,1
1,1,1,1,1,1,1,1,1
endlayer

layer
1,1,1,1,1,1,1,1,1
1,1,1,1,1,1,1,1,1
1,1,1,1,1,1,1,1,1
1,1,1,2,2,2,3,1,1
1,1,2,2,4,2,2,1,1
1,1,1,2,2,2,2,1,1
1,1,1,1,2,3,1,1,1
1,1,1,1,1,1,1,1,1
1,1,1,1,1,1,1,1,1
endlayer

layer
1,1,1,1,1,1,1,1,1
1,1,1,1,1,1,1,1,1
1,1,1,1,3,1,1,1,1
1,1,1,2,2,2,2,1,1
1,1,2,2,4,2,2,1,1
1,1,1,2,2,2,2,1,1
1,1,1,3,2,2,1,1,1
1,1,1,1,1,1,1,1,1
1,1,1,1,1,1,1,1,1
endlayer

layer
1,1,1,1,1,1,1,1,1
1,1,1,1,1,1,1,1,1
1,1,1,1,2,1,1,1,1
1,1,3,2,2,2,2,1,1
1,1,2,2,4,2,2,1,1
1,1,1,2,2,2,2,1,1
1,1,1,2,2,2,1,1,1
1,1,1,1,1,1,1,1,1
1,1,1,1,1,1,1,1,1
endlayer

layer
1,1,1,1,1,1,1,1,1
1,1,1,1,1,1,1,1,1
1,1,1,3,2,1,1,1,1
1,1,2,2,2,2,2,1,1
1,1,2,2,4,2,2,1,1
1,1,1,2,2,2,2,1,1
1,1,1,2,2,2,1,1,1
1,1,1,1,3,1,1,1,1
1,1,1,1,1,1,1,1,1
endlayer

layer
1,1,1,1,1,1,1,1,1
1,1,1,1,1,1,1,1,1
1,1,1,2,2,3,1,1,1
1,1,2,2,2,2,2,1,1
1,1,2,2,4,2,2,3,1
1,1,3,2,2,2,2,1,1
1,1,1,2,2,2,3,1,1
1,1,1,1,2,1,1,1,1
1,1,1,1,1,1,1,1,1
endlayer

layer
1,1,1,1,1,1,1,1,1
1,1,1,1,3,1,1,1,1
1,1,1,2,2,2,1,1,1
1,1,2,2,2,2,2,1,1
1,3,2,2,4,2,2,2,1
1,1,2,2,2,2,2,3,1
1,1,3,2,2,2,2,1,1
1,1,1,3,2,1,1,1,1
1,1,1,1,1,1,1,1,1
endlayer

layer
1,1,1,1,1,1,1,1,1
1,1,1,3,2,3,1,1,1
1,1,3,2,2,2,3,1,1
1,3,2,2,2,2,2,3,1
1,2,2,2,4,2,2,2,1
1,3,2,2,2,2,2,2,1
1,1,2,2,2,2,2,3,1
1,1,1,2,2,3,1,1,1
1,1,1,1,3,1,1,1,1
endlayer

layer
1,1,1,1,3,1,1,1,1
1,1,3,2,2,2,3,1,1
1,3,2,2,2,2,2,3,1
1,2,2,2,2,2,2,2,1
3,2,2,2,4,2,2,2,3
1,2,2,2,2,2,2,2,1
1,3,2,2,2,2,2,2,1
1,1,3,2,2,2,3,1,1
1,1,1,1,2,3,1,1,1
endlayer

layer
1,1,1,3,3,3,1,1,1
1,3,3,0,0,0,3,3,1
1,3,0,0,0,0,0,3,1
3,0,0,0,0,0,0,0,3
3,0,0,0,0,0,0,0,3
3,0,0,0,0,0,0,0,3
1,3,0,0,0,0,0,3,1
1,3,3,0,0,0,3,3,1
1,1,1,3,3,3,1,1,1
endlayer

layer
1,1,1,3,0,3,1,1,1
1,3,0,0,0,0,0,3,1
1,0,0,0,0,0,0,0,1
3,0,0,0,0,0,0,0,3
0,0,0,0,0,0,0,0,0
3,0,0,0,0,0,0,0,3
1,0,0,0,0,0,0,0,1
1,3,0,0,0,0,0,3,1
1,1,1,3,0,3,1,1,1
endlayer

