
# Created by Ruins mod version 16.7 Ingame Parser
# authoring Player: lafuller

weight=1
embed_into_distance=5
acceptable_target_blocks=
unacceptable_target_blocks=flowing_water,water,flowing_lava,lava,ice,bedrock,netherrack,nether_brick,nether_brick_fence,soul_sand,quartz_ore,end_stone,obsidian,iron_bars,cloud,flesh,ash_block,slime_grass,slime_congealed,slime_dirt
dimensions=12,16,20
allowable_overhang=0
max_leveling=7
leveling_buffer=-1
preserve_water=0
preserve_lava=0

rule1=0,100,preserveBlock
rule2=0,100,minecraft:sandstone_stairs-2
rule3=0,100,minecraft:double_stone_slab-9
rule4=0,100,minecraft:sandstone_stairs-0
rule5=0,100,minecraft:sandstone-2
rule6=0,100,minecraft:sandstone-0
rule7=0,100,minecraft:sandstone_stairs-3
rule8=0,100,minecraft:sandstone_stairs-1
rule9=0,100,minecraft:dirt-0
rule10=0,100,bookshelf,pumpkin,melon_block,hay_block,ChestGenHook:chests/spawn_bonus_chest:5-5,ChestGenHook:chests/village_blacksmith:5-5,ChestGenHook:chests/stronghold_library:5-5,ChestGenHook:chests/simple_dungeon:5-5
rule11=0,100,minecraft:wooden_slab-9
rule12=0,100,minecraft:trapdoor-11
rule13=0,100,minecraft:ladder-3
rule14=0,100,minecraft:ladder-2
rule15=0,100,minecraft:trapdoor-10
rule16=0,100,minecraft:ladder-5
rule17=0,100,minecraft:ladder-4
rule18=0,100,minecraft:carpet-7
rule19=0,100,minecraft:trapdoor-9
rule20=0,100,minecraft:trapdoor-3
rule21=0,100,minecraft:trapdoor-2
rule22=0,100,minecraft:spruce_stairs-5
rule23=0,100,minecraft:spruce_stairs-4
rule24=0,100,minecraft:sandstone_stairs-4
rule25=0,100,minecraft:sandstone_stairs-6
rule26=0,100,minecraft:spruce_stairs-6
rule27=0,100,minecraft:spruce_stairs-7
rule28=0,100,minecraft:spruce_fence-0
rule29=0,100,minecraft:jungle_door-5
rule30=0,100,minecraft:jungle_door-4
rule31=0,100,minecraft:jungle_door-6
rule32=0,100,minecraft:jungle_door-7
rule33=0,100,minecraft:jungle_door-8
rule34=0,100,minecraft:jungle_door-9
rule35=0,100,minecraft:carpet-8
rule36=0,100,minecraft:trapdoor-8
rule37=0,100,minecraft:wooden_slab-1
rule38=0,100,minecraft:stone_slab-9
rule39=0,100,minecraft:sandstone_stairs-7
rule40=0,100,minecraft:sandstone_stairs-5
rule41=0,100,minecraft:stone_slab-1
rule42=0,100,minecraft:hay_block-0
rule43=0,100,minecraft:trapdoor-0
rule44=0,100,minecraft:spruce_stairs-0
rule45=0,100,minecraft:spruce_stairs-2
rule46=0,100,minecraft:spruce_stairs-3
rule47=0,100,minecraft:spruce_stairs-1

layer
7,3,6,5,6,5,6,6,6,6,5,4,4,3,3,3,2,1,1,1
6,6,6,6,6,6,6,6,6,6,6,6,6,6,6,6,5,5,1,1
6,6,6,6,6,6,6,6,6,3,3,3,3,3,3,6,6,6,1,1
6,6,6,6,6,6,6,6,6,6,5,5,5,3,3,6,6,6,1,1
6,3,6,6,6,3,6,6,6,6,5,5,5,3,6,6,6,5,2,1
6,3,6,6,6,5,6,6,6,6,5,5,5,3,6,6,6,3,3,5
6,3,6,6,6,5,6,6,6,6,6,6,5,3,3,3,3,3,3,6
5,3,6,6,6,5,6,6,6,6,6,6,6,6,6,6,6,6,3,5
1,1,5,6,6,5,6,3,3,3,3,5,6,6,6,6,6,6,3,5
1,1,5,6,6,5,3,6,6,6,6,5,6,6,6,6,6,6,3,6
1,1,6,6,6,3,3,6,6,6,6,6,6,6,6,6,6,6,3,1
1,4,6,6,6,6,3,6,6,6,6,6,6,6,6,6,6,6,3,1
1,7,3,6,6,6,3,6,6,6,6,6,6,6,6,6,6,6,3,1
1,7,3,6,6,3,3,6,6,6,6,6,6,6,6,6,6,6,5,4
1,8,6,6,6,3,3,3,3,3,3,3,3,6,6,6,6,6,6,6
1,1,6,6,6,6,5,6,6,6,5,6,6,6,6,6,6,6,6,6
endlayer

layer
1,7,6,5,6,5,6,6,6,6,5,1,1,7,4,2,1,1,1,1
6,6,6,6,6,6,6,6,6,6,6,6,6,6,6,6,5,5,1,1
6,6,6,6,6,6,6,6,6,3,3,3,3,3,3,6,9,5,1,1
6,6,6,6,6,6,6,6,6,6,5,5,5,3,3,6,9,8,1,1
6,3,6,6,6,3,6,6,6,6,5,5,5,3,6,6,6,2,1,1
6,3,6,6,6,5,6,6,6,6,5,5,5,3,6,6,6,3,3,5
6,3,6,6,6,5,6,6,6,6,6,6,5,3,3,3,3,3,3,6
5,3,6,6,6,5,6,6,6,6,6,6,6,6,6,6,6,6,3,5
1,1,5,6,6,5,6,3,3,3,3,5,6,6,6,6,6,6,3,5
1,1,5,6,6,5,3,6,6,6,6,5,6,6,6,6,6,6,3,6
1,1,6,6,6,3,3,6,6,6,6,6,6,6,6,6,6,6,3,1
1,1,6,6,6,6,3,6,6,6,6,6,6,6,6,6,6,6,3,1
1,1,7,6,6,6,3,6,6,6,6,6,6,6,6,6,6,6,3,1
1,1,7,6,6,3,3,6,6,6,6,6,6,6,6,6,6,6,5,1
1,1,6,6,6,3,3,3,3,3,3,3,3,6,6,6,6,6,6,4
1,1,6,6,6,6,5,6,6,6,5,6,6,6,6,6,6,6,6,5
endlayer

layer
1,1,7,6,5,5,6,5,6,6,6,1,1,1,1,1,1,1,1,1
5,6,6,6,6,6,11,0,0,10,6,6,5,4,4,2,1,1,1,1
5,6,6,6,6,6,11,0,0,0,3,3,3,3,3,5,1,1,1,1
6,10,0,12,12,6,11,0,0,0,5,5,5,3,3,6,1,1,1,1
5,0,0,0,0,6,5,0,0,0,5,5,5,3,6,6,2,1,1,1
5,0,0,0,0,0,6,0,0,0,13,5,5,3,6,6,6,3,3,6
6,14,0,0,0,0,6,0,0,0,0,6,5,3,3,3,3,3,3,6
6,3,0,0,0,0,6,15,0,0,0,6,11,0,0,0,0,10,3,6
1,1,5,0,0,0,6,6,6,6,3,5,11,0,0,0,0,0,3,6
1,1,6,0,0,0,6,10,0,0,16,5,11,0,0,0,0,0,3,5
1,1,6,11,11,11,6,0,0,0,0,0,6,5,0,0,0,0,3,1
1,1,6,6,6,6,11,0,0,0,0,0,0,6,6,0,0,0,3,1
1,1,1,6,6,6,11,0,0,0,0,0,0,11,6,17,0,15,3,1
1,1,1,6,6,3,11,0,0,0,0,0,0,11,5,6,6,6,6,1
1,1,4,6,6,3,3,0,0,0,0,0,0,11,6,6,6,6,6,1
1,1,5,5,6,6,6,6,6,6,5,6,6,6,6,6,6,6,2,1
endlayer

layer
1,1,1,7,6,6,5,5,5,6,5,1,1,1,1,1,1,1,1,1
5,6,6,6,6,6,18,0,0,0,6,6,1,1,1,1,1,1,1,1
5,6,6,6,6,6,18,0,0,0,3,3,3,4,4,1,1,1,1,1
6,0,0,0,0,6,18,0,0,0,5,6,5,3,5,4,1,1,1,1
5,0,0,0,0,6,5,0,0,0,5,5,5,9,9,2,1,1,1,1
6,0,0,0,0,0,6,0,0,0,13,5,5,3,6,6,6,3,3,5
6,14,0,0,0,0,6,0,0,0,0,6,5,3,3,3,5,3,3,6
5,6,0,0,0,0,6,0,0,0,0,6,18,0,0,0,0,19,3,6
1,1,5,0,0,0,6,6,6,6,3,5,18,0,0,0,0,0,5,6
1,1,5,0,0,0,6,0,0,0,16,5,18,0,0,0,0,0,3,5
1,1,6,18,18,18,6,0,0,0,0,0,6,5,0,0,0,0,3,1
1,1,3,6,6,6,18,0,0,0,0,0,0,6,6,0,0,0,3,1
1,1,1,6,6,6,18,0,0,0,0,0,0,18,6,17,0,0,3,1
1,1,1,5,9,3,18,0,0,0,0,0,0,18,5,6,6,6,5,1
1,1,1,5,9,3,5,0,0,0,0,0,0,18,5,6,6,6,6,1
1,1,1,7,5,6,6,5,5,5,6,5,5,5,6,6,6,2,1,1
endlayer

layer
1,1,1,1,7,6,5,6,6,5,5,1,1,1,1,1,1,1,1,1
7,6,6,6,5,6,0,0,0,0,6,5,1,1,1,1,1,1,1,1
5,6,6,6,6,6,0,0,0,0,3,6,2,1,1,1,1,1,1,1
6,0,0,20,20,6,0,0,0,0,5,6,4,1,1,1,1,1,1,1
6,0,0,0,0,6,5,0,0,0,5,5,5,1,1,1,1,1,1,1
6,0,0,0,0,0,6,0,0,0,13,5,5,3,3,3,3,3,3,6
6,14,0,0,0,0,6,0,0,0,0,6,5,3,3,3,5,3,3,5
6,6,0,0,0,0,6,21,0,0,0,6,0,0,0,0,0,0,3,5
1,1,6,0,0,0,6,6,6,6,3,5,0,0,0,0,0,0,5,6
1,1,5,0,0,0,6,0,0,0,16,5,0,0,0,0,0,0,3,5
1,1,5,0,0,0,6,0,0,0,0,0,6,5,0,0,0,0,3,1
1,1,3,3,3,3,0,0,0,0,0,0,0,6,6,0,0,0,3,1
1,1,1,6,6,3,0,0,0,0,0,0,0,0,6,17,0,21,3,1
1,1,1,8,1,3,0,0,0,0,0,0,0,0,5,6,6,6,5,1
1,1,1,1,1,3,5,0,0,0,0,0,0,0,6,6,6,6,1,1
1,1,1,1,1,7,6,6,6,6,5,6,6,5,5,5,2,1,1,1
endlayer

layer
1,1,1,1,1,6,6,6,6,6,6,1,1,1,1,1,1,1,1,1
1,7,5,2,1,6,11,11,11,11,6,5,1,1,1,1,1,1,1,1
6,6,6,6,6,6,11,11,11,11,5,6,1,1,1,1,1,1,1,1
6,11,11,11,11,6,22,22,22,22,3,2,1,1,1,1,1,1,1,1
6,23,23,23,23,3,5,11,11,11,3,3,1,1,1,1,1,1,1,1
5,11,11,11,11,11,3,24,11,11,13,3,4,3,3,3,3,3,6,6
5,14,11,11,11,11,3,25,11,11,11,3,3,3,3,3,5,3,5,5
6,5,24,11,11,11,3,25,11,11,11,3,11,11,26,11,11,11,3,6
1,1,3,23,23,23,3,3,3,3,3,3,11,11,26,11,11,11,5,6
1,1,3,11,11,11,3,11,27,11,16,3,11,11,26,11,11,11,5,6
1,1,3,11,11,11,3,11,27,11,11,27,3,3,26,11,11,11,3,1
1,1,6,3,3,3,3,11,27,11,11,27,11,11,6,11,11,11,3,1
1,1,1,8,5,3,3,11,27,11,11,27,11,11,3,17,11,11,5,1
1,1,1,1,1,3,3,11,27,11,11,27,11,11,6,6,6,6,6,1
1,1,1,1,1,8,5,3,3,5,3,3,5,6,6,8,7,6,1,1
1,1,1,1,1,1,5,6,6,6,5,5,5,2,1,1,1,1,1,1
endlayer

layer
1,1,1,1,1,5,5,5,6,6,5,1,1,1,1,1,1,1,1,1
1,1,1,1,1,6,0,0,0,0,6,28,1,1,1,1,1,1,1,1
5,6,30,6,6,6,0,0,0,0,29,1,1,1,1,1,1,1,1,1
6,0,0,0,0,6,0,0,0,0,6,1,1,1,1,1,1,1,1,1
6,0,0,0,0,3,6,0,0,0,6,5,1,1,1,1,1,1,1,1
6,0,0,0,0,0,11,6,0,0,13,6,1,1,1,5,6,5,6,5
6,14,0,0,0,0,11,6,14,0,0,6,6,30,3,5,0,0,0,6
5,3,6,0,0,0,11,6,0,0,0,6,0,0,0,0,0,0,0,6
1,1,6,0,0,0,6,3,3,3,3,3,0,0,0,0,0,0,0,6
1,1,6,0,0,0,6,0,0,0,16,6,0,17,0,0,0,0,3,5
1,1,6,0,0,0,6,0,0,0,0,0,6,6,0,0,0,0,3,1
1,1,5,6,31,6,5,0,0,0,0,0,16,0,6,0,0,0,3,1
1,1,1,1,1,1,6,0,0,0,0,0,0,0,3,17,0,0,3,1
1,1,1,1,1,1,32,0,0,0,0,0,0,0,6,6,31,6,5,1
1,1,1,1,1,1,6,0,0,0,3,3,31,6,6,1,1,28,1,1
1,1,1,1,1,1,5,5,4,6,5,1,1,1,1,1,1,1,1,1
endlayer

layer
1,1,1,1,1,5,6,6,1,6,5,1,1,1,1,1,1,1,1,1
1,1,1,1,1,6,0,0,0,0,6,28,1,1,1,1,1,1,1,1
5,6,34,6,6,6,0,0,0,0,33,1,1,1,1,1,1,1,1,1
6,0,0,0,0,6,0,0,0,0,6,1,1,1,1,1,1,1,1,1
5,0,0,0,0,6,6,0,0,0,6,5,1,1,1,1,1,1,1,1
1,0,0,0,0,0,35,6,0,0,0,5,1,1,1,5,6,1,6,5
6,0,0,0,0,0,18,6,14,0,0,6,6,33,3,5,0,0,0,6
5,3,6,0,0,0,18,6,11,11,11,6,36,0,0,0,0,0,0,1
1,1,6,0,0,0,6,3,3,3,3,3,36,0,0,0,0,0,0,6
1,1,1,0,0,0,6,0,0,0,0,6,36,17,0,0,0,0,3,5
1,1,6,0,0,0,6,0,0,0,0,0,6,6,0,0,0,0,6,1
1,1,5,6,34,6,5,0,0,0,0,0,16,19,6,0,0,0,1,1
1,1,1,1,1,1,6,0,0,0,0,0,0,19,6,0,0,0,5,1
1,1,1,1,1,1,33,0,0,0,0,0,0,19,6,6,33,6,5,1
1,1,1,1,1,1,6,0,0,0,6,3,34,6,6,1,1,28,1,1
1,1,1,1,1,1,6,6,1,6,6,1,1,1,1,1,1,1,1,1
endlayer

layer
1,1,1,1,1,6,6,5,5,5,6,1,1,1,1,1,1,1,1,1
1,1,1,1,1,6,0,0,0,0,6,28,1,1,1,1,1,1,1,1
6,6,6,6,6,6,0,0,0,0,6,1,1,1,1,1,1,1,1,1
6,0,0,0,0,6,0,0,0,0,6,1,1,1,1,1,1,1,1,1
5,0,0,0,0,3,6,0,0,0,6,6,1,1,1,1,1,1,1,1
5,0,0,0,0,0,0,6,0,0,0,6,15,15,15,6,6,6,6,5
5,0,0,0,0,0,0,6,0,0,0,6,6,3,3,3,0,0,0,6
6,3,6,0,0,0,0,6,18,18,35,6,0,0,0,0,0,0,0,6
1,1,6,0,0,0,6,3,3,3,3,3,0,0,0,0,0,0,0,6
1,1,5,0,0,0,6,0,0,0,0,6,0,0,0,0,0,0,3,6
1,1,6,0,0,0,6,0,0,0,0,0,6,6,0,0,0,0,3,1
1,1,6,6,5,6,3,0,0,0,0,0,0,18,6,0,0,0,3,1
1,1,1,1,1,1,5,0,0,0,0,0,0,18,3,0,0,0,3,1
1,1,1,1,1,1,5,0,0,0,0,0,0,18,6,6,5,6,6,1
1,1,1,1,1,1,6,0,0,0,3,3,3,6,6,1,1,28,1,1
1,1,1,1,1,1,5,6,6,6,5,1,1,1,1,1,1,1,1,1
endlayer

layer
1,1,1,1,1,5,6,6,6,6,5,1,1,1,1,1,1,1,1,1
1,1,1,1,1,6,0,0,0,0,6,37,1,1,1,1,1,1,1,1
5,6,6,6,6,6,0,0,0,0,6,37,1,1,1,1,1,1,1,1
6,0,0,0,38,6,0,0,0,0,6,37,1,1,1,1,1,1,1,1
6,0,0,0,38,6,6,24,24,24,6,5,1,1,1,1,1,1,1,1
6,0,0,0,38,0,0,6,0,0,0,5,1,1,1,7,4,4,4,2
6,0,0,0,38,0,0,6,0,0,0,6,6,3,3,3,0,0,0,2
5,6,6,38,38,38,38,6,0,0,0,6,38,38,38,25,0,0,0,2
1,1,6,0,0,0,6,3,3,3,3,6,38,19,38,25,0,0,0,2
1,1,6,0,0,0,5,0,0,0,39,6,38,38,38,24,24,24,5,2
1,1,6,0,0,0,5,0,0,0,39,40,6,6,6,25,0,0,3,1
1,1,5,6,6,6,3,0,0,0,39,0,0,0,6,25,0,0,3,1
1,1,1,1,1,1,7,40,40,40,40,0,0,0,3,25,0,0,5,1
1,1,1,1,1,1,7,38,12,38,39,0,0,0,6,6,6,6,5,1
1,1,1,1,1,1,7,38,38,38,3,5,6,6,5,37,37,37,1,1
1,1,1,1,1,1,8,8,8,8,2,1,1,1,1,1,1,1,1,1
endlayer

layer
1,1,1,1,1,5,5,5,5,5,1,1,1,1,1,1,1,1,1,1
1,1,1,1,1,5,38,38,38,5,41,1,1,1,1,1,1,1,1,1
4,4,4,4,4,5,38,15,38,5,41,1,1,1,1,1,1,1,1,1
7,0,0,0,2,5,38,38,38,5,41,1,1,1,1,1,1,1,1,1
7,0,0,0,2,5,5,5,5,5,4,4,1,1,1,1,1,1,1,1
7,0,0,0,2,41,41,7,37,37,37,2,1,1,1,1,1,1,1,1
7,0,0,0,2,21,41,7,37,20,37,2,1,1,1,1,41,41,41,1
7,8,5,5,5,5,5,7,37,37,37,2,1,1,1,1,41,20,41,1
1,1,5,0,0,0,5,8,8,8,8,8,1,1,1,1,41,41,41,1
1,1,5,0,0,0,5,2,8,8,41,1,1,1,4,4,4,4,4,1
1,1,5,0,0,0,5,2,20,7,41,1,1,1,7,42,42,42,2,1
1,1,5,5,5,5,5,4,4,7,41,44,44,44,7,42,43,42,2,1
1,1,1,1,1,1,1,41,41,41,41,46,36,45,7,42,42,42,2,1
1,1,1,1,1,1,1,1,1,1,41,47,47,47,7,8,8,8,8,1
1,1,1,1,1,1,1,1,1,1,1,1,1,1,1,1,1,1,1,1
1,1,1,1,1,1,1,1,1,1,1,1,1,1,1,1,1,1,1,1
endlayer

layer
1,1,1,1,1,1,41,41,41,1,1,1,1,1,1,1,1,1,1,1
1,1,1,1,1,41,1,1,1,41,1,1,1,1,1,1,1,1,1,1
1,1,1,1,1,41,1,1,1,41,1,1,1,1,1,1,1,1,1,1
1,41,41,41,1,41,1,1,1,41,1,1,1,1,1,1,1,1,1,1
1,41,43,41,1,1,41,41,41,1,1,1,1,1,1,1,1,1,1,1
1,41,41,41,1,1,1,1,1,1,1,1,1,1,1,1,1,1,1,1
1,41,41,41,1,1,1,1,1,1,1,1,1,1,1,1,1,1,1,1
1,1,1,4,4,4,1,1,1,1,1,1,1,1,1,1,1,1,1,1
1,1,7,37,37,37,2,1,1,1,1,1,1,1,1,1,1,1,1,1
1,1,7,37,43,37,2,1,1,1,1,1,1,1,1,1,1,1,1,1
1,1,7,37,37,37,2,1,1,1,1,1,1,1,1,1,1,1,1,1
1,1,1,8,8,8,1,1,1,1,1,1,1,1,1,1,1,1,1,1
1,1,1,1,1,1,1,1,1,1,1,1,1,1,1,1,1,1,1,1
1,1,1,1,1,1,1,1,1,1,1,1,1,1,1,1,1,1,1,1
1,1,1,1,1,1,1,1,1,1,1,1,1,1,1,1,1,1,1,1
1,1,1,1,1,1,1,1,1,1,1,1,1,1,1,1,1,1,1,1
endlayer

