
# Created by Ruins mod version 16.7 Ingame Parser
# authoring Player: lafuller

weight=1
embed_into_distance=39
random_height_offset=-3,3
acceptable_target_blocks=
unacceptable_target_blocks=ice,bedrock,netherrack,nether_brick,nether_brick_fence,soul_sand,quartz_ore,end_stone,obsidian,iron_bars,cloud,flesh,ash_block,slime_grass,slime_congealed,slime_dirt
dimensions=23,17,17
allowable_overhang=0
max_leveling=80
leveling_buffer=-1
preserve_water=0
preserve_lava=0

rule1=0,100,preserveBlock
rule2=0,100,stonebrick-0,stonebrick-0,stonebrick-1,stonebrick-1,stonebrick-2,stonebrick-2,stone-5,cobblestone
rule3=0,100,stonebrick-0,stonebrick-1,stonebrick-2,stone-5,stone-5,stone-6,stone-6,cobblestone
rule4=0,100,minecraft:stone_brick_stairs-1
rule5=0,100,minecraft:stone_brick_stairs-3
rule6=0,100,minecraft:stone_brick_stairs-2
rule7=0,100,minecraft:stone_brick_stairs-0
rule8=0,100,minecraft:cobblestone_wall-0
rule9=0,100,minecraft:stone_brick_stairs-7
rule10=0,100,minecraft:stone_brick_stairs-5
rule11=0,100,minecraft:stone_brick_stairs-4
rule12=0,100,minecraft:stone_brick_stairs-6
rule13=0,100,minecraft:stone_slab-13
rule14=0,100,minecraft:sea_lantern-0
rule15=0,100,sponge-0,diamond_ore-0,lapis_block-0,gold_block-0,emerald_block-0,iron_block-0,coal_block-0,gold_ore-0,redstone_ore-0,lapis_ore-0,emerald_ore-0,lapis_block-0,gold_block-0,gold_ore-0,redstone_ore-0,lapis_ore-0,emerald_ore-0


layer
1,1,2,2,2,2,2,2,2,2,1,1,1,1,1,1,1
1,1,2,2,2,2,2,2,3,3,2,2,2,1,1,1,1
1,1,2,2,2,2,2,2,3,3,2,3,3,2,2,2,2
1,1,2,2,2,2,2,2,2,2,2,3,3,2,2,2,2
1,2,3,3,2,2,3,3,3,3,3,2,2,2,2,2,2
1,2,3,3,2,3,3,2,2,2,3,3,2,2,2,2,2
1,2,2,2,3,3,2,2,2,2,2,3,3,2,2,2,2
2,3,3,2,3,2,2,4,4,4,2,2,3,2,2,2,2
2,3,3,2,3,2,2,6,0,5,2,2,3,2,3,3,2
2,2,2,2,3,2,2,7,7,7,2,2,3,2,3,3,2
2,2,2,2,3,3,2,2,2,2,2,3,3,2,2,2,1
2,2,2,2,2,3,3,2,2,2,3,3,2,3,3,2,1
2,2,2,2,2,2,3,3,3,3,3,2,2,3,3,2,1
2,2,2,2,3,3,2,2,2,2,2,2,2,2,2,1,1
2,2,2,2,3,3,2,3,3,2,2,2,2,2,2,1,1
1,1,1,1,2,2,2,3,3,2,2,2,2,2,2,1,1
1,1,1,1,1,1,1,2,2,2,2,2,2,2,2,1,1
endlayer

layer
1,1,2,2,2,2,2,0,0,0,1,1,1,1,1,1,1
1,1,2,2,2,2,6,0,0,0,0,0,0,1,1,1,1
1,1,2,2,2,2,4,0,0,0,0,0,0,2,2,2,2
1,1,2,2,2,0,0,0,0,0,0,0,0,2,2,2,2
1,0,0,0,0,0,0,0,0,0,0,0,0,2,2,2,2
1,0,0,0,0,0,0,0,0,0,0,0,0,0,2,2,2
1,0,0,0,0,0,0,0,0,0,0,0,0,0,5,4,2
0,0,0,0,0,0,0,0,0,0,0,0,0,0,0,0,0
0,0,0,0,0,0,0,0,0,0,0,0,0,0,0,0,0
0,0,0,0,0,0,0,0,0,0,0,0,0,0,0,0,0
2,7,6,0,0,0,0,0,0,0,0,0,0,0,0,0,1
2,2,2,0,0,0,0,0,0,0,0,0,0,0,0,0,1
2,2,2,2,0,0,0,0,0,0,0,0,0,0,0,0,1
2,2,2,2,0,0,0,0,0,0,0,0,2,2,2,1,1
2,2,2,2,0,0,0,0,0,0,7,2,2,2,2,1,1
1,1,1,1,0,0,0,0,0,0,5,2,2,2,2,1,1
1,1,1,1,1,1,1,0,0,0,2,2,2,2,2,1,1
endlayer

layer
1,1,2,2,2,2,2,0,0,0,1,1,1,1,1,1,1
1,1,2,2,2,6,0,0,0,0,0,0,0,1,1,1,1
1,1,2,2,2,6,0,0,0,0,0,0,0,2,2,2,2
1,1,2,2,2,0,0,0,0,0,0,0,0,2,2,2,2
1,0,0,0,0,0,0,0,0,0,0,0,0,2,2,2,2
1,0,0,0,0,0,0,0,0,0,0,0,0,0,4,4,2
1,0,0,0,0,0,0,0,0,0,0,0,0,0,0,0,2
0,0,0,0,0,0,0,0,0,0,0,0,0,0,0,0,0
0,0,0,0,0,0,0,0,0,0,0,0,0,0,0,0,0
0,0,0,0,0,0,0,0,0,0,0,0,0,0,0,0,0
2,0,0,0,0,0,0,0,0,0,0,0,0,0,0,0,1
2,7,7,0,0,0,0,0,0,0,0,0,0,0,0,0,1
2,2,2,2,0,0,0,0,0,0,0,0,0,0,0,0,1
2,2,2,2,0,0,0,0,0,0,0,0,2,2,2,1,1
2,2,2,2,0,0,0,0,0,0,0,5,2,2,2,1,1
1,1,1,1,0,0,0,0,0,0,0,5,2,2,2,1,1
1,1,1,1,1,1,1,0,0,0,2,2,2,2,2,1,1
endlayer

layer
1,1,2,2,2,2,2,0,0,0,1,1,1,1,1,1,1
1,1,2,2,6,0,0,0,0,0,0,0,0,1,1,1,1
1,1,2,2,6,0,0,0,0,0,0,0,0,2,2,2,2
1,1,2,2,8,0,0,0,0,0,0,0,0,2,2,2,2
1,0,0,0,0,0,0,0,0,0,0,0,0,8,4,4,2
1,0,0,0,0,0,0,0,0,0,0,0,0,0,0,0,2
1,0,0,0,0,0,0,0,0,0,0,0,0,0,0,0,2
0,0,0,0,0,0,0,0,0,0,0,0,0,0,0,0,0
0,0,0,0,0,0,0,0,0,0,0,0,0,0,0,0,0
0,0,0,0,0,0,0,0,0,0,0,0,0,0,0,0,0
2,0,0,0,0,0,0,0,0,0,0,0,0,0,0,0,1
2,0,0,0,0,0,0,0,0,0,0,0,0,0,0,0,1
2,7,7,8,0,0,0,0,0,0,0,0,0,0,0,0,1
2,2,2,2,0,0,0,0,0,0,0,0,8,2,2,1,1
2,2,2,2,0,0,0,0,0,0,0,0,5,2,2,1,1
1,1,1,1,0,0,0,0,0,0,0,0,5,2,2,1,1
1,1,1,1,1,1,1,0,0,0,2,2,2,2,2,1,1
endlayer

layer
1,1,2,2,2,2,2,0,0,0,1,1,1,1,1,1,1
1,1,0,0,0,0,0,0,0,0,0,0,9,1,1,1,1
1,1,0,0,0,0,0,0,0,0,0,0,9,6,0,0,2
1,1,7,7,8,0,0,0,0,0,0,0,9,6,0,0,2
1,10,10,10,0,0,0,0,0,0,0,0,0,8,0,0,2
1,0,0,0,0,0,0,0,0,0,0,0,0,0,0,0,2
1,0,0,0,0,0,0,0,0,0,0,0,0,0,0,0,2
0,0,0,0,0,0,0,0,0,0,0,0,0,0,0,0,0
0,0,0,0,0,0,0,0,0,0,0,0,0,0,0,0,0
0,0,0,0,0,0,0,0,0,0,0,0,0,0,0,0,0
2,0,0,0,0,0,0,0,0,0,0,0,0,0,0,0,1
2,0,0,0,0,0,0,0,0,0,0,0,0,0,0,0,1
2,0,0,8,0,0,0,0,0,0,0,0,0,11,11,11,1
2,0,0,5,12,0,0,0,0,0,0,0,8,4,4,1,1
2,0,0,5,12,0,0,0,0,0,0,0,0,0,0,1,1
1,1,1,1,12,0,0,0,0,0,0,0,0,0,0,1,1
1,1,1,1,1,1,1,0,0,0,2,2,2,2,2,1,1
endlayer

layer
1,1,2,2,2,2,2,0,0,0,1,1,1,1,1,1,1
1,1,0,0,0,0,0,0,0,0,0,9,6,1,1,1,1
1,1,0,0,0,0,0,0,0,0,0,9,6,0,0,0,2
1,1,0,0,8,0,0,0,0,0,0,9,6,0,0,0,2
1,7,7,7,0,0,0,0,0,0,0,0,0,8,0,0,2
1,10,10,10,0,0,0,0,0,0,0,0,0,0,0,0,2
1,0,0,0,0,0,0,0,0,0,0,0,0,0,0,0,2
0,0,0,0,0,0,0,0,0,0,0,0,0,0,0,0,0
0,0,0,0,0,0,0,0,0,0,0,0,0,0,0,0,0
0,0,0,0,0,0,0,0,0,0,0,0,0,0,0,0,0
2,0,0,0,0,0,0,0,0,0,0,0,0,0,0,0,1
2,0,0,0,0,0,0,0,0,0,0,0,0,11,11,11,1
2,0,0,8,0,0,0,0,0,0,0,0,0,4,4,4,1
2,0,0,0,5,12,0,0,0,0,0,0,8,0,0,1,1
2,0,0,0,5,12,0,0,0,0,0,0,0,0,0,1,1
1,1,1,1,5,12,0,0,0,0,0,0,0,0,0,1,1
1,1,1,1,1,1,1,0,0,0,2,2,2,2,2,1,1
endlayer

layer
1,1,2,2,2,2,2,2,2,2,1,1,1,1,1,1,1
1,1,0,0,0,13,13,2,4,2,2,6,0,1,1,1,1
1,1,0,0,0,13,13,2,4,2,2,6,0,0,0,0,2
1,1,0,0,8,2,2,7,10,7,2,6,0,0,0,0,2
1,0,0,0,5,2,4,7,7,7,4,7,7,8,0,0,2
1,7,7,7,5,2,3,3,3,3,3,2,2,2,13,13,2
1,2,2,2,6,3,3,3,3,3,3,3,5,2,13,13,2
2,2,2,5,5,3,3,4,4,4,3,3,6,6,2,2,2
2,6,6,12,5,3,3,6,15,5,3,3,6,9,5,5,2
2,2,2,5,5,3,3,7,7,7,3,3,6,6,2,2,2
2,13,13,2,6,3,3,3,3,3,3,3,5,2,2,2,1
2,13,13,2,2,2,3,3,3,3,3,2,6,4,4,4,1
2,0,0,8,4,4,7,4,4,4,7,2,6,0,0,0,1
2,0,0,0,0,5,2,4,11,4,2,2,8,0,0,1,1
2,0,0,0,0,5,2,2,7,2,13,13,0,0,0,1,1
1,1,1,1,0,5,2,2,7,2,13,13,0,0,0,1,1
1,1,1,1,1,1,1,2,2,2,2,2,2,2,2,1,1
endlayer

layer
1,1,2,2,2,2,2,0,0,0,1,1,1,1,1,1,1
1,1,0,0,9,2,0,0,0,0,0,0,0,1,1,1,1
1,1,0,0,9,6,0,0,0,0,0,0,0,0,0,0,2
1,1,0,0,0,0,0,0,0,0,0,0,0,0,0,0,2
1,0,0,0,0,0,0,0,0,0,0,0,0,0,11,11,2
1,0,0,0,0,0,0,0,0,0,0,0,0,0,4,2,2
1,0,0,0,0,0,0,0,0,0,0,0,0,0,0,0,2
0,0,0,0,0,0,0,0,0,0,0,0,0,0,0,0,0
0,0,0,0,0,0,0,0,0,0,0,0,0,0,0,0,0
0,0,0,0,0,0,0,0,0,0,0,0,0,0,0,0,0
2,0,0,0,0,0,0,0,0,0,0,0,0,0,0,0,1
2,2,7,0,0,0,0,0,0,0,0,0,0,0,0,0,1
2,10,10,0,0,0,0,0,0,0,0,0,0,0,0,0,1
2,0,0,0,0,0,0,0,0,0,0,0,0,0,0,1,1
2,0,0,0,0,0,0,0,0,0,0,5,12,0,0,1,1
1,1,1,1,0,0,0,0,0,0,0,2,12,0,0,1,1
1,1,1,1,1,1,1,0,0,0,2,2,2,2,2,1,1
endlayer

layer
1,1,2,2,2,2,2,0,0,0,1,1,1,1,1,1,1
1,1,10,10,2,2,0,0,0,0,0,0,0,1,1,1,1
1,1,0,9,6,0,0,0,0,0,0,0,0,0,0,9,2
1,1,0,0,0,0,0,0,0,0,0,0,0,0,11,2,2
1,0,0,0,0,0,0,0,0,0,0,0,0,0,4,2,2
1,0,0,0,0,0,0,0,0,0,0,0,0,0,0,2,2
1,0,0,0,0,0,0,0,0,0,0,0,0,0,0,0,2
0,0,0,0,0,0,0,0,0,0,0,0,0,0,0,0,0
0,0,0,0,0,0,0,0,0,0,0,0,0,0,0,0,0
0,0,0,0,0,0,0,0,0,0,0,0,0,0,0,0,0
2,0,0,0,0,0,0,0,0,0,0,0,0,0,0,0,1
2,2,0,0,0,0,0,0,0,0,0,0,0,0,0,0,1
2,2,7,0,0,0,0,0,0,0,0,0,0,0,0,0,1
2,10,10,0,0,0,0,0,0,0,0,0,0,0,0,1,1
2,12,0,0,0,0,0,0,0,0,0,0,5,12,0,1,1
1,1,1,1,0,0,0,0,0,0,0,2,2,12,11,1,1
1,1,1,1,1,1,1,0,0,0,2,2,2,2,2,1,1
endlayer

layer
1,1,2,2,2,2,2,0,0,0,1,1,1,1,1,1,1
1,1,2,2,2,2,0,0,0,0,0,0,0,1,1,1,1
1,1,10,6,0,0,0,0,0,0,0,0,0,0,9,2,2
1,1,0,0,0,0,0,0,0,0,0,0,0,0,4,2,2
1,0,0,0,0,0,0,0,0,0,0,0,0,0,0,2,2
1,0,0,0,0,0,0,0,0,0,0,0,0,0,0,2,2
1,0,0,0,0,0,0,0,0,0,0,0,0,0,0,0,2
0,0,0,0,0,0,0,0,0,0,0,0,0,0,0,0,0
0,0,0,0,0,0,0,0,0,0,0,0,0,0,0,0,0
0,0,0,0,0,0,0,0,0,0,0,0,0,0,0,0,0
2,0,0,0,0,0,0,0,0,0,0,0,0,0,0,0,1
2,2,0,0,0,0,0,0,0,0,0,0,0,0,0,0,1
2,2,0,0,0,0,0,0,0,0,0,0,0,0,0,0,1
2,2,7,0,0,0,0,0,0,0,0,0,0,0,0,1,1
2,2,12,0,0,0,0,0,0,0,0,0,0,5,11,1,1
1,1,1,1,0,0,0,0,0,0,0,2,2,2,2,1,1
1,1,1,1,1,1,1,0,0,0,2,2,2,2,2,1,1
endlayer

layer
1,1,2,2,2,2,2,0,0,0,1,1,1,1,1,1,1
1,1,2,2,2,2,0,0,0,0,0,0,0,1,1,1,1
1,1,6,0,0,0,0,0,0,0,0,0,0,0,4,2,2
1,1,0,0,0,0,0,0,0,0,0,0,0,0,0,2,2
1,0,0,0,0,0,0,0,0,0,0,0,0,0,0,2,2
1,0,0,0,0,0,0,0,0,0,0,0,0,0,0,2,2
1,0,0,0,0,0,0,0,0,0,0,0,0,0,0,0,2
0,0,0,0,0,0,0,0,0,0,0,0,0,0,0,0,0
0,0,0,0,0,0,0,0,0,0,0,0,0,0,0,0,0
0,0,0,0,0,0,0,0,0,0,0,0,0,0,0,0,0
2,0,0,0,0,0,0,0,0,0,0,0,0,0,0,0,1
2,2,0,0,0,0,0,0,0,0,0,0,0,0,0,0,1
2,2,0,0,0,0,0,0,0,0,0,0,0,0,0,0,1
2,2,0,0,0,0,0,0,0,0,0,0,0,0,0,1,1
2,2,7,0,0,0,0,0,0,0,0,0,0,0,5,1,1
1,1,1,1,0,0,0,0,0,0,0,2,2,2,2,1,1
1,1,1,1,1,1,1,0,0,0,2,2,2,2,2,1,1
endlayer

layer
1,1,2,2,2,2,2,0,0,0,1,1,1,1,1,1,1
1,1,4,2,2,2,0,0,0,0,0,0,0,1,1,1,1
1,1,0,0,0,0,0,0,0,0,0,0,0,0,0,5,2
1,1,0,0,0,0,0,0,0,0,0,0,0,0,0,2,2
1,0,0,0,0,0,0,0,0,0,0,0,0,0,0,2,2
1,0,0,0,0,0,0,0,0,0,0,0,0,0,0,2,2
1,0,0,0,0,0,0,0,0,0,0,0,0,0,0,0,2
0,0,0,0,0,0,0,0,0,0,0,0,0,0,0,0,0
0,0,0,0,0,0,0,0,0,0,0,0,0,0,0,0,0
0,0,0,0,0,0,0,0,0,0,0,0,0,0,0,0,0
2,0,0,0,0,0,0,0,0,0,0,0,0,0,0,0,1
2,2,0,0,0,0,0,0,0,0,0,0,0,0,0,0,1
2,2,0,0,0,0,0,0,0,0,0,0,0,0,0,0,1
2,2,0,0,0,0,0,0,0,0,0,0,0,0,0,1,1
2,6,0,0,0,0,0,0,0,0,0,0,0,0,0,1,1
1,1,1,1,0,0,0,0,0,0,0,2,2,2,7,1,1
1,1,1,1,1,1,1,0,0,0,2,2,2,2,2,1,1
endlayer

layer
1,1,2,2,2,2,2,0,0,0,1,1,1,1,1,1,1
1,1,0,5,2,2,0,0,0,0,0,0,0,1,1,1,1
1,1,0,0,0,0,0,0,0,0,0,0,0,0,0,0,2
1,1,0,0,0,0,0,0,0,0,0,0,0,0,0,7,2
1,0,0,0,0,0,0,0,0,0,0,0,0,0,0,2,2
1,0,0,0,0,0,0,0,0,0,0,0,0,0,0,2,2
1,0,0,0,0,0,0,0,0,0,0,0,0,0,0,0,2
0,0,0,0,0,0,0,0,0,0,0,0,0,0,0,0,0
0,0,0,0,0,0,0,0,0,0,0,0,0,0,0,0,0
0,0,0,0,0,0,0,0,0,0,0,0,0,0,0,0,0
2,0,0,0,0,0,0,0,0,0,0,0,0,0,0,0,1
2,2,0,0,0,0,0,0,0,0,0,0,0,0,0,0,1
2,2,0,0,0,0,0,0,0,0,0,0,0,0,0,0,1
2,4,0,0,0,0,0,0,0,0,0,0,0,0,0,1,1
2,0,0,0,0,0,0,0,0,0,0,0,0,0,0,1,1
1,1,1,1,0,0,0,0,0,0,0,2,2,6,0,1,1
1,1,1,1,1,1,1,0,0,0,2,2,2,2,2,1,1
endlayer

layer
1,1,2,2,2,2,2,2,2,2,1,1,1,1,1,1,1
1,1,0,0,5,2,10,13,13,13,10,10,2,1,1,1,1
1,1,0,0,13,0,0,0,0,0,0,0,13,0,0,0,2
1,1,0,0,0,0,0,0,0,0,0,0,0,0,0,0,2
1,2,13,0,0,0,0,0,0,0,0,0,0,0,13,7,2
1,12,0,0,0,0,0,0,0,0,0,0,0,0,0,2,2
1,12,0,0,0,0,0,0,0,0,0,0,0,0,0,9,2
2,13,0,0,0,0,0,0,0,0,0,0,0,0,0,13,2
2,13,0,0,0,0,0,0,0,0,0,0,0,0,0,13,2
2,13,0,0,0,0,0,0,0,0,0,0,0,0,0,13,2
2,12,0,0,0,0,0,0,0,0,0,0,0,0,0,9,1
2,2,0,0,0,0,0,0,0,0,0,0,0,0,0,9,1
2,4,13,0,0,0,0,0,0,0,0,0,0,0,13,2,1
2,0,0,0,0,0,0,0,0,0,0,0,0,0,0,1,1
2,0,0,0,13,0,0,0,0,0,0,0,13,0,0,1,1
1,1,1,1,2,11,11,13,13,13,11,2,6,0,0,1,1
1,1,1,1,1,1,1,2,2,2,2,2,2,2,2,1,1
endlayer

layer
1,1,2,2,2,2,2,2,2,2,1,1,1,1,1,1,1
1,1,0,0,0,5,2,2,2,2,2,2,2,1,1,1,1
1,1,11,9,2,2,10,10,10,10,10,2,2,2,12,0,2
1,1,2,2,2,10,13,0,0,0,13,10,2,2,11,0,2
1,2,2,2,13,0,0,0,0,0,0,0,13,2,2,0,2
1,2,2,12,0,0,0,0,0,0,0,0,0,9,2,7,2
1,2,12,13,0,0,0,0,0,0,0,0,0,13,9,2,2
2,2,12,0,0,0,0,0,0,0,0,0,0,0,9,2,2
2,2,12,0,0,0,0,0,0,0,0,0,0,0,9,2,2
2,2,12,0,0,0,0,0,0,0,0,0,0,0,9,2,2
2,2,12,13,0,0,0,0,0,0,0,0,0,13,9,2,1
2,4,2,12,0,0,0,0,0,0,0,0,0,9,2,2,1
2,0,2,2,13,0,0,0,0,0,0,0,13,2,2,2,1
2,0,10,2,2,11,13,0,0,0,13,11,2,2,2,1,1
2,0,9,2,2,2,11,11,11,11,11,2,2,12,10,1,1
1,1,1,1,2,2,2,2,2,2,2,6,0,0,0,1,1
1,1,1,1,1,1,1,2,2,2,2,2,2,2,2,1,1
endlayer

layer
1,1,2,2,2,2,2,2,2,2,1,1,1,1,1,1,1
1,1,0,0,0,0,5,2,2,2,2,2,2,1,1,1,1
1,1,2,7,7,7,7,2,2,2,2,2,2,2,2,2,2
1,1,2,2,2,2,2,2,2,2,2,2,2,2,6,0,2
1,2,2,2,2,10,10,13,13,13,10,10,2,2,6,0,2
1,2,2,2,12,13,0,0,0,0,0,13,9,2,6,0,2
1,2,2,2,12,0,0,0,0,0,0,0,9,2,6,7,2
2,2,2,2,13,0,0,0,0,0,0,0,13,2,2,2,2
2,2,2,2,13,0,0,0,0,0,0,0,13,2,2,2,2
2,2,2,2,13,0,0,0,0,0,0,0,13,2,2,2,2
2,4,5,2,12,0,0,0,0,0,0,0,9,2,2,2,1
2,0,5,2,12,13,0,0,0,0,0,13,9,2,2,2,1
2,0,5,2,2,11,11,13,13,13,11,11,2,2,2,2,1
2,0,5,2,2,2,2,2,2,2,2,2,2,2,2,1,1
2,0,2,2,2,2,2,2,2,2,4,4,4,4,2,1,1
1,1,1,1,2,2,2,2,2,2,6,0,0,0,0,1,1
1,1,1,1,1,1,1,2,2,2,2,2,2,2,2,1,1
endlayer

layer
1,1,2,2,2,2,2,2,2,2,1,1,1,1,1,1,1
1,1,2,0,0,0,0,0,0,0,2,2,2,1,1,1,1
1,1,2,0,0,0,0,0,0,0,0,0,2,2,2,2,2
1,1,2,0,0,0,0,0,0,0,0,0,0,0,0,0,2
1,2,0,0,0,0,5,7,7,7,2,0,0,0,0,0,2
1,2,0,0,0,2,2,10,10,10,2,2,0,0,0,0,2
1,2,0,0,2,2,13,0,0,0,13,2,7,0,0,0,2
2,0,0,0,5,12,0,0,0,0,0,9,6,0,0,0,2
2,0,0,0,5,12,0,0,14,0,0,9,6,0,0,0,2
2,0,0,0,5,12,0,0,0,0,0,9,6,0,0,0,2
2,0,0,0,4,2,13,0,0,0,13,2,2,0,0,2,1
2,0,0,0,0,2,2,11,11,11,2,2,0,0,0,2,1
2,0,0,0,0,0,2,4,4,4,6,0,0,0,0,2,1
2,0,0,0,0,0,0,0,0,0,0,0,0,0,2,1,1
2,2,2,2,0,0,0,0,0,0,0,0,0,0,2,1,1
1,1,1,1,2,2,2,0,0,0,0,0,0,0,2,1,1
1,1,1,1,1,1,1,2,2,2,2,2,2,2,2,1,1
endlayer

layer
1,1,2,2,2,2,2,2,2,2,1,1,1,1,1,1,1
1,1,2,0,0,0,0,0,0,0,2,2,2,1,1,1,1
1,1,2,0,0,0,0,0,0,0,0,0,2,2,2,2,2
1,1,2,0,0,0,0,0,0,0,0,0,0,0,0,0,2
1,2,0,0,0,0,0,0,0,0,2,0,0,0,0,0,2
1,2,0,0,0,2,2,7,7,7,2,2,0,0,0,0,2
1,2,0,0,2,2,2,2,2,2,2,2,0,0,0,0,2
2,0,0,0,0,5,2,12,10,9,2,6,0,0,0,0,2
2,0,0,0,0,5,2,12,2,9,2,6,0,0,0,0,2
2,0,0,0,0,5,2,11,11,9,2,6,0,0,0,0,2
2,0,0,0,0,2,2,2,2,2,2,2,2,0,0,2,1
2,0,0,0,0,2,2,4,4,4,2,2,0,0,0,2,1
2,0,0,0,0,0,2,0,0,0,0,0,0,0,0,2,1
2,0,0,0,0,0,0,0,0,0,0,0,0,0,2,1,1
2,2,2,2,0,0,0,0,0,0,0,0,0,0,2,1,1
1,1,1,1,2,2,2,0,0,0,0,0,0,0,2,1,1
1,1,1,1,1,1,1,2,2,2,2,2,2,2,2,1,1
endlayer

layer
1,1,2,2,2,2,2,2,2,2,1,1,1,1,1,1,1
1,1,2,0,0,0,0,0,0,0,2,2,2,1,1,1,1
1,1,2,0,0,0,0,0,0,0,0,0,2,2,2,2,2
1,1,2,0,0,0,0,0,0,0,0,0,0,0,0,0,2
1,2,0,0,0,0,0,0,0,0,2,0,0,0,0,0,2
1,2,0,0,0,2,2,0,0,0,2,2,0,0,0,0,2
1,2,0,0,2,2,2,0,0,0,2,2,0,0,0,0,2
2,0,0,0,0,0,0,0,0,0,0,0,0,0,0,0,2
2,0,0,0,0,0,0,0,0,0,0,0,0,0,0,0,2
2,0,0,0,0,0,0,0,0,0,0,0,0,0,0,0,2
2,0,0,0,0,2,2,0,0,0,2,2,2,0,0,2,1
2,0,0,0,0,2,2,0,0,0,2,2,0,0,0,2,1
2,0,0,0,0,0,2,0,0,0,0,0,0,0,0,2,1
2,0,0,0,0,0,0,0,0,0,0,0,0,0,2,1,1
2,2,2,2,0,0,0,0,0,0,0,0,0,0,2,1,1
1,1,1,1,2,2,2,0,0,0,0,0,0,0,2,1,1
1,1,1,1,1,1,1,2,2,2,2,2,2,2,2,1,1
endlayer

layer
1,1,2,2,2,2,2,2,2,2,1,1,1,1,1,1,1
1,1,2,0,0,0,0,0,0,0,2,2,2,1,1,1,1
1,1,2,0,0,0,0,0,0,0,0,0,2,2,2,2,2
1,1,2,0,0,0,0,0,0,0,0,0,0,0,0,0,2
1,2,0,0,0,0,0,0,0,0,2,0,0,0,0,0,2
1,2,0,0,9,2,2,0,0,0,2,2,0,0,0,0,2
1,2,0,0,2,2,2,0,0,0,2,2,0,0,0,0,2
2,0,0,0,0,0,0,0,0,0,0,0,0,0,0,0,2
2,0,0,0,0,0,0,0,0,0,0,0,0,0,0,0,2
2,0,0,0,0,0,0,0,0,0,0,0,0,0,0,0,2
2,0,0,0,0,2,2,0,0,0,2,2,2,0,0,2,1
2,0,0,0,0,2,2,0,0,0,2,2,12,0,0,2,1
2,0,0,0,0,0,2,0,0,0,0,0,0,0,0,2,1
2,0,0,0,0,0,0,0,0,0,0,0,0,0,2,1,1
2,2,2,2,0,0,0,0,0,0,0,0,0,0,2,1,1
1,1,1,1,2,2,2,0,0,0,0,0,0,0,2,1,1
1,1,1,1,1,1,1,2,2,2,2,2,2,2,2,1,1
endlayer

layer
1,1,2,2,2,2,2,2,2,2,1,1,1,1,1,1,1
1,1,2,10,10,10,10,10,10,10,2,2,2,1,1,1,1
1,1,2,12,13,13,13,0,0,0,0,0,2,2,2,2,2
1,1,2,10,13,13,13,0,0,0,0,0,0,0,10,9,2
1,2,12,13,9,11,11,0,0,0,2,11,0,0,0,9,2
1,2,12,9,2,2,2,0,0,0,2,2,12,0,0,9,2
1,2,12,9,2,2,2,0,0,0,2,2,12,0,0,9,2
2,12,0,0,0,0,0,0,0,0,0,0,0,0,0,9,2
2,12,0,0,0,0,0,0,0,0,0,0,0,0,0,9,2
2,12,0,0,0,0,0,0,0,0,0,0,0,0,0,9,2
2,12,0,0,9,2,2,0,0,0,2,2,2,12,9,2,1
2,12,0,0,9,2,2,0,0,0,2,2,2,12,9,2,1
2,12,0,0,0,10,2,0,0,0,10,10,12,13,9,2,1
2,11,11,0,0,0,0,0,0,0,13,13,13,11,2,1,1
2,2,2,2,0,0,0,0,0,0,13,13,13,9,2,1,1
1,1,1,1,2,2,2,11,11,11,11,11,11,11,2,1,1
1,1,1,1,1,1,1,2,2,2,2,2,2,2,2,1,1
endlayer

layer
1,1,2,2,2,2,2,2,2,2,1,1,1,1,1,1,1
1,1,2,2,2,2,2,2,2,2,2,2,2,1,1,1,1
1,1,2,2,2,2,2,12,10,9,2,2,2,2,2,2,2
1,1,2,2,2,2,2,12,0,9,2,2,2,2,2,2,2
1,2,2,2,2,2,2,12,0,9,2,2,2,2,2,2,2
1,2,2,2,2,2,2,12,0,9,2,2,2,2,2,2,2
1,2,2,2,2,2,2,12,0,9,2,2,2,2,2,2,2
2,2,10,10,10,10,10,12,0,10,10,10,10,10,9,2,2
2,2,12,0,0,0,0,0,0,0,0,0,0,0,9,2,2
2,2,12,11,11,11,11,11,0,11,11,11,11,11,9,2,2
2,2,2,2,2,2,2,12,0,9,2,2,2,2,2,2,1
2,2,2,2,2,2,2,12,0,9,2,2,2,2,2,2,1
2,2,2,2,2,2,2,12,0,9,2,2,2,2,2,2,1
2,2,2,2,2,2,2,12,0,9,2,2,2,2,2,1,1
2,2,2,2,2,2,2,11,11,9,2,2,2,2,2,1,1
1,1,1,1,2,2,2,2,2,2,2,2,2,2,2,1,1
1,1,1,1,1,1,1,2,2,2,2,2,2,2,2,1,1
endlayer

layer
1,1,1,1,1,1,1,1,1,1,1,1,1,1,1,1,1
1,1,1,2,1,1,2,1,1,2,1,1,1,1,1,1,1
1,1,1,2,1,1,2,2,2,2,1,1,2,1,1,1,1
1,1,1,2,1,1,2,2,2,2,1,1,2,2,2,2,1
1,1,2,2,2,2,2,2,2,2,2,2,2,1,1,1,1
1,1,1,1,2,2,2,2,2,2,2,2,2,1,1,1,1
1,1,1,1,2,2,2,2,2,2,2,2,2,2,2,2,1
1,2,2,2,2,2,2,2,2,2,2,2,2,2,2,1,1
1,1,2,2,2,2,2,2,2,2,2,2,2,2,2,1,1
1,1,2,2,2,2,2,2,2,2,2,2,2,2,2,2,1
1,2,2,2,2,2,2,2,2,2,2,2,2,1,1,1,1
1,1,1,1,2,2,2,2,2,2,2,2,2,1,1,1,1
1,1,1,1,2,2,2,2,2,2,2,2,2,2,2,1,1
1,2,2,2,2,1,1,2,2,2,2,1,1,2,1,1,1
1,1,1,1,2,1,1,2,2,2,2,1,1,2,1,1,1
1,1,1,1,1,1,1,2,1,1,2,1,1,2,1,1,1
1,1,1,1,1,1,1,1,1,1,1,1,1,1,1,1,1
endlayer

