
# Created by Ruins mod version 16.7 Ingame Parser
# authoring Player: lafuller

weight=1
embed_into_distance=5
uniqueMinDistance=800
acceptable_target_blocks=gravel
unacceptable_target_blocks=
dimensions=19,27,27
allowable_overhang=0
max_leveling=5
leveling_buffer=-1
preserve_water=1
preserve_lava=0

rule1=0,100,preserveBlock
rule2=0,100,minecraft:stone-6
rule3=0,100,minecraft:stonebrick-0
rule4=0,100,minecraft:stained_hardened_clay-9
rule5=0,100,minecraft:prismarine-1
rule6=0,100,minecraft:prismarine-2
rule7=0,100,minecraft:sea_lantern-0
rule8=0,100,air,air
rule9=0,100,minecraft:stone_brick_stairs-2
rule10=0,100,minecraft:stone_slab-5
rule11=0,100,minecraft:stone_slab-8
rule12=0,100,minecraft:stone_slab-0
rule13=0,100,minecraft:double_stone_slab-0
rule14=0,100,minecraft:stone_brick_stairs-1
rule15=0,100,minecraft:stone_slab-13
rule16=0,100,minecraft:stained_glass-8
rule17=0,100,minecraft:stone_brick_stairs-3
rule18=0,100,minecraft:stone_brick_stairs-0
rule19=0,100,minecraft:ladder-3
rule20=0,100,minecraft:ladder-2
rule21=0,100,minecraft:stone-4
rule22=0,100,minecraft:ladder-5
rule23=0,100,minecraft:ladder-4
rule24=0,100,minecraft:stone_brick_stairs-5
rule25=0,100,minecraft:stone_brick_stairs-7
rule26=0,100,minecraft:stone_brick_stairs-6
rule27=0,100,minecraft:stone_brick_stairs-4
rule28=0,100,minecraft:stone-5

layer
1,1,1,1,1,1,1,1,1,1,1,1,1,1,1,1,1,1,1,1,1,1,1,1,1,1,1
1,1,1,1,1,1,1,1,1,1,1,1,1,1,1,1,1,1,1,1,1,1,1,1,1,1,1
1,1,1,1,1,1,1,1,1,1,1,1,1,1,1,1,1,1,1,1,1,1,1,1,1,1,1
1,1,1,1,1,1,1,1,1,1,1,1,2,1,2,1,1,1,1,1,1,1,1,1,1,1,1
1,1,1,1,1,1,1,1,1,2,1,2,2,2,2,2,1,2,1,1,1,1,1,1,1,1,1
1,1,1,1,1,1,1,1,2,2,2,1,1,2,1,1,2,2,2,1,1,1,1,1,1,1,1
1,1,1,1,1,1,2,2,1,2,1,1,1,2,1,1,1,2,1,2,2,1,1,1,1,1,1
1,1,1,1,1,1,2,1,1,2,1,1,2,1,2,1,1,2,1,1,2,1,1,1,1,1,1
1,1,1,1,1,2,1,1,1,1,2,2,2,1,2,2,2,1,1,1,1,2,1,1,1,1,1
1,1,1,1,2,2,2,2,1,1,2,1,2,1,2,1,2,1,1,2,2,2,2,1,1,1,1
1,1,1,1,1,2,1,1,2,2,1,1,1,2,1,1,1,2,2,1,1,2,1,1,1,1,1
1,1,1,1,2,1,1,1,2,1,1,1,2,1,2,1,1,1,2,1,1,1,2,1,1,1,1
1,1,1,2,2,1,1,2,2,2,1,2,2,1,2,2,1,2,2,2,1,1,2,2,1,1,1
1,1,1,1,2,2,2,1,1,1,2,1,1,1,1,1,2,1,1,1,2,2,2,1,1,1,1
1,1,1,2,2,1,1,2,2,2,1,2,2,1,2,2,1,2,2,2,1,1,2,2,1,1,1
1,1,1,1,2,1,1,1,2,1,1,1,2,1,2,1,1,1,2,1,1,1,2,1,1,1,1
1,1,1,1,1,2,1,1,2,2,1,1,1,2,1,1,1,2,2,1,1,2,1,1,1,1,1
1,1,1,1,2,2,2,2,1,1,2,1,2,1,2,1,2,1,1,2,2,2,2,1,1,1,1
1,1,1,1,1,2,1,1,1,1,2,2,2,1,2,2,2,1,1,1,1,2,1,1,1,1,1
1,1,1,1,1,1,2,1,1,2,1,1,2,1,2,1,1,2,1,1,2,1,1,1,1,1,1
1,1,1,1,1,1,2,2,1,2,1,1,1,2,1,1,1,2,1,2,2,1,1,1,1,1,1
1,1,1,1,1,1,1,1,2,2,2,1,1,2,1,1,2,2,2,1,1,1,1,1,1,1,1
1,1,1,1,1,1,1,1,1,2,1,2,2,2,2,2,1,2,1,1,1,1,1,1,1,1,1
1,1,1,1,1,1,1,1,1,1,1,1,2,1,2,1,1,1,1,1,1,1,1,1,1,1,1
1,1,1,1,1,1,1,1,1,1,1,1,1,1,1,1,1,1,1,1,1,1,1,1,1,1,1
1,1,1,1,1,1,1,1,1,1,1,1,1,1,1,1,1,1,1,1,1,1,1,1,1,1,1
1,1,1,1,1,1,1,1,1,1,1,1,1,1,1,1,1,1,1,1,1,1,1,1,1,1,1
endlayer

layer
1,1,1,1,1,1,1,1,1,1,1,1,1,1,1,1,1,1,1,1,1,1,1,1,1,1,1
1,1,1,1,1,1,1,1,1,1,1,1,1,1,1,1,1,1,1,1,1,1,1,1,1,1,1
1,1,1,1,1,1,1,1,1,1,1,1,1,1,1,1,1,1,1,1,1,1,1,1,1,1,1
1,1,1,1,1,1,1,1,1,1,2,1,2,2,2,1,2,1,1,1,1,1,1,1,1,1,1
1,1,1,1,1,1,1,2,1,2,2,3,4,4,4,3,2,2,1,2,1,1,1,1,1,1,1
1,1,1,1,1,1,1,2,3,4,4,4,5,4,5,4,4,4,3,2,1,1,1,1,1,1,1
1,1,1,1,1,1,2,4,6,4,4,5,5,4,5,5,4,4,6,4,2,1,1,1,1,1,1
1,1,1,1,2,2,4,4,6,6,5,4,5,5,5,4,5,6,6,4,4,2,2,1,1,1,1
1,1,1,1,1,2,6,6,4,6,4,7,5,6,5,7,4,6,4,6,6,3,1,1,1,1,1
1,1,1,1,2,4,4,6,6,4,4,4,4,5,4,4,4,4,6,6,4,4,2,1,1,1,1
1,1,1,2,2,4,4,5,4,4,5,5,6,5,6,5,5,4,4,5,4,4,2,2,1,1,1
1,1,1,1,3,4,5,4,7,4,5,5,6,6,6,5,5,4,7,4,5,4,3,1,1,1,1
1,1,1,2,4,5,5,5,5,4,6,6,6,4,6,6,6,4,5,5,5,5,4,2,1,1,1
1,1,1,2,4,4,4,5,6,5,5,6,4,7,4,6,5,5,6,5,4,4,4,2,1,1,1
1,1,1,2,4,5,5,5,5,4,6,6,6,4,6,6,6,4,5,5,5,5,4,2,1,1,1
1,1,1,1,3,4,5,4,7,4,5,5,6,6,6,5,5,4,7,4,5,4,3,1,1,1,1
1,1,1,2,2,4,4,5,4,4,5,5,6,5,6,5,5,4,4,5,4,4,2,2,1,1,1
1,1,1,1,2,4,4,6,6,4,4,4,4,5,4,4,4,4,6,6,4,4,2,1,1,1,1
1,1,1,1,1,3,6,6,4,6,4,7,5,6,5,7,4,6,4,6,6,3,1,1,1,1,1
1,1,1,1,2,2,4,4,6,6,5,4,5,5,5,4,5,6,6,4,4,2,2,1,1,1,1
1,1,1,1,1,1,2,4,6,4,4,5,5,4,5,5,4,4,6,4,2,1,1,1,1,1,1
1,1,1,1,1,1,1,2,3,4,4,4,5,4,5,4,4,4,3,2,1,1,1,1,1,1,1
1,1,1,1,1,1,1,2,1,2,2,3,4,4,4,3,2,2,1,2,1,1,1,1,1,1,1
1,1,1,1,1,1,1,1,1,1,2,1,2,2,2,1,2,1,1,1,1,1,1,1,1,1,1
1,1,1,1,1,1,1,1,1,1,1,1,1,1,1,1,1,1,1,1,1,1,1,1,1,1,1
1,1,1,1,1,1,1,1,1,1,1,1,1,1,1,1,1,1,1,1,1,1,1,1,1,1,1
1,1,1,1,1,1,1,1,1,1,1,1,1,1,1,1,1,1,1,1,1,1,1,1,1,1,1
endlayer

layer
1,1,1,1,1,1,1,1,1,1,1,1,1,1,1,1,1,1,1,1,1,1,1,1,1,1,1
1,1,1,1,1,1,1,1,1,1,1,1,1,1,1,1,1,1,1,1,1,1,1,1,1,1,1
1,1,1,1,1,1,1,1,1,1,2,1,1,2,1,1,2,1,1,1,1,1,1,1,1,1,1
1,1,1,1,1,1,2,1,2,1,2,2,2,8,2,2,2,1,2,1,2,1,1,1,1,1,1
1,1,1,1,1,1,1,5,2,2,8,8,8,8,8,8,8,2,2,5,1,1,1,1,1,1,1
1,1,1,1,1,1,2,2,8,8,8,8,8,8,8,8,8,8,8,8,2,1,1,1,1,1,1
1,1,1,2,1,2,2,2,8,8,8,8,8,8,8,8,8,8,8,8,8,2,1,2,1,1,1
1,1,1,1,5,2,2,2,2,8,8,8,8,8,8,8,8,8,8,8,8,8,5,1,1,1,1
1,1,1,2,2,1,1,2,8,8,8,8,8,8,8,8,8,8,8,8,8,8,2,2,1,1,1
1,1,1,1,2,1,4,9,8,8,8,8,8,8,8,8,8,8,8,8,8,8,2,1,1,1,1
1,1,2,2,1,1,4,9,8,8,8,8,8,8,8,8,8,8,8,8,8,8,8,2,2,1,1
1,1,1,2,11,5,2,10,8,8,8,8,8,8,8,8,8,8,8,8,8,8,8,2,1,1,1
1,1,1,2,12,10,10,8,8,8,8,8,8,8,8,8,8,8,8,8,8,8,8,2,1,1,1
1,1,2,8,8,8,8,8,8,8,8,8,8,8,8,8,8,8,8,8,8,8,8,8,2,1,1
1,1,1,2,8,8,8,8,8,8,8,8,8,8,8,8,8,8,8,8,8,8,8,2,1,1,1
1,1,1,2,8,8,8,8,8,8,8,8,8,8,8,8,8,8,8,8,8,8,8,2,1,1,1
1,1,2,2,8,8,8,8,8,8,8,8,8,8,8,8,8,8,8,8,8,8,8,2,2,1,1
1,1,1,1,2,8,8,8,8,8,8,8,8,8,8,8,8,8,8,8,8,8,2,1,1,1,1
1,1,1,2,2,8,8,8,8,8,8,8,8,8,8,8,8,8,8,8,8,8,2,2,1,1,1
1,1,1,1,5,8,8,8,8,8,8,8,8,8,8,8,8,8,8,8,8,8,5,1,1,1,1
1,1,1,2,1,2,8,8,8,8,8,8,8,8,8,8,8,8,8,8,8,2,1,2,1,1,1
1,1,1,1,1,1,2,8,8,8,8,8,8,8,8,8,8,8,8,8,2,1,1,1,1,1,1
1,1,1,1,1,1,1,5,2,2,8,8,8,8,8,8,8,2,2,5,1,1,1,1,1,1,1
1,1,1,1,1,1,2,1,2,1,2,2,2,8,2,2,2,1,2,1,2,1,1,1,1,1,1
1,1,1,1,1,1,1,1,1,1,2,1,1,2,1,1,2,1,1,1,1,1,1,1,1,1,1
1,1,1,1,1,1,1,1,1,1,1,1,1,1,1,1,1,1,1,1,1,1,1,1,1,1,1
1,1,1,1,1,1,1,1,1,1,1,1,1,1,1,1,1,1,1,1,1,1,1,1,1,1,1
endlayer

layer
1,1,1,1,1,1,1,1,1,1,1,1,1,1,1,1,1,1,1,1,1,1,1,1,1,1,1
1,1,1,1,1,1,1,1,1,1,1,1,2,1,2,1,1,1,1,1,1,1,1,1,1,1,1
1,1,1,1,1,1,1,1,1,1,2,2,2,5,2,2,2,1,1,1,1,1,1,1,1,1,1
1,1,1,1,1,1,2,1,2,2,2,8,8,8,8,8,2,2,2,1,2,1,1,1,1,1,1
1,1,1,1,2,1,2,2,8,8,8,8,8,8,8,8,8,8,8,2,2,1,2,1,1,1,1
1,1,1,1,1,2,2,5,8,8,8,8,8,8,8,8,8,8,8,8,2,2,1,1,1,1,1
1,1,1,2,2,2,2,2,8,8,8,8,8,8,8,8,8,8,8,8,8,2,2,2,1,1,1
1,1,1,1,2,2,2,2,2,8,8,8,8,8,8,8,8,8,8,8,8,8,2,1,1,1,1
1,1,1,2,5,5,5,2,8,8,8,8,8,8,8,8,8,8,8,8,8,8,8,2,1,1,1
1,1,1,2,3,5,9,8,8,8,8,8,8,8,8,8,8,8,8,8,8,8,8,2,1,1,1
1,1,2,2,12,12,12,8,8,8,8,8,8,8,8,8,8,8,8,8,8,8,8,2,2,1,1
1,1,2,8,8,8,8,8,8,8,8,8,8,8,8,8,8,8,8,8,8,8,8,8,2,1,1
1,2,2,8,8,8,8,8,8,8,8,8,8,8,8,8,8,8,8,8,8,8,8,8,2,2,1
1,1,5,8,8,8,8,8,8,8,8,8,8,8,8,8,8,8,8,8,8,8,8,8,5,1,1
1,2,2,8,8,8,8,8,8,8,8,8,8,8,8,8,8,8,8,8,8,8,8,8,2,2,1
1,1,2,8,8,8,8,8,8,8,8,8,8,8,8,8,8,8,8,8,8,8,8,8,2,1,1
1,1,2,2,8,8,8,8,8,8,8,8,8,8,8,8,8,8,8,8,8,8,8,2,2,1,1
1,1,1,2,8,8,8,8,8,8,8,8,8,8,8,8,8,8,8,8,8,8,8,2,1,1,1
1,1,1,2,8,8,8,8,8,8,8,8,8,8,8,8,8,8,8,8,8,8,8,2,1,1,1
1,1,1,1,2,8,8,8,8,8,8,8,8,8,8,8,8,8,8,8,8,8,2,1,1,1,1
1,1,1,2,2,2,8,8,8,8,8,8,8,8,8,8,8,8,8,8,8,2,2,2,1,1,1
1,1,1,1,1,2,2,8,8,8,8,8,8,8,8,8,8,8,8,8,2,2,1,1,1,1,1
1,1,1,1,2,1,2,2,8,8,8,8,8,8,8,8,8,8,8,2,2,1,2,1,1,1,1
1,1,1,1,1,1,2,1,2,2,2,8,8,8,8,8,2,2,2,1,2,1,1,1,1,1,1
1,1,1,1,1,1,1,1,1,1,2,2,2,5,2,2,2,1,1,1,1,1,1,1,1,1,1
1,1,1,1,1,1,1,1,1,1,1,1,2,1,2,1,1,1,1,1,1,1,1,1,1,1,1
1,1,1,1,1,1,1,1,1,1,1,1,1,1,1,1,1,1,1,1,1,1,1,1,1,1,1
endlayer

layer
1,1,1,1,1,1,1,1,1,1,1,1,1,1,1,1,1,1,1,1,1,1,1,1,1,1,1
1,1,1,1,1,1,1,1,2,1,1,2,2,2,2,2,1,1,2,1,1,1,1,1,1,1,1
1,1,1,1,1,2,1,2,2,7,2,2,5,4,5,2,2,7,2,2,1,2,1,1,1,1,1
1,1,1,1,1,2,2,2,2,8,8,8,8,8,8,8,8,8,2,2,2,2,1,1,1,1,1
1,1,1,1,2,2,8,5,8,8,8,8,8,8,8,8,8,8,8,8,8,2,2,1,1,1,1
1,1,2,2,2,7,8,8,8,8,8,8,8,8,8,8,8,8,8,8,8,7,2,2,2,1,1
1,1,1,2,11,11,8,5,8,8,8,8,8,8,8,8,8,8,8,8,8,8,8,2,1,1,1
1,1,2,2,11,11,11,2,2,8,8,8,8,8,8,8,8,8,8,8,8,8,8,2,2,1,1
1,2,2,2,12,12,12,2,8,8,8,8,8,8,8,8,8,8,8,8,8,8,8,2,2,2,1
1,1,7,8,8,8,8,8,8,8,8,8,8,8,8,8,8,8,8,8,8,8,8,8,7,1,1
1,1,2,8,8,8,8,8,8,8,8,8,8,8,8,8,8,8,8,8,8,8,8,8,2,1,1
1,2,2,8,8,8,8,8,8,8,8,8,8,8,8,8,8,8,8,8,8,8,8,8,2,2,1
1,2,5,8,8,8,8,8,8,8,8,8,8,8,8,8,8,8,8,8,8,8,8,8,5,2,1
1,2,4,8,8,8,8,8,8,8,8,8,8,8,8,8,8,8,8,8,8,8,8,8,4,2,1
1,2,5,8,8,8,8,8,8,8,8,8,8,8,8,8,8,8,8,8,8,8,8,8,5,2,1
1,2,2,8,8,8,8,8,8,8,8,8,8,8,8,8,8,8,8,8,8,8,8,8,2,2,1
1,1,2,8,8,8,8,8,8,8,8,8,8,8,8,8,8,8,8,8,8,8,8,8,2,1,1
1,1,7,8,8,8,8,8,8,8,8,8,8,8,8,8,8,8,8,8,8,8,8,8,7,1,1
1,2,2,2,8,8,8,8,8,8,8,8,8,8,8,8,8,8,8,8,8,8,8,2,2,2,1
1,1,2,2,8,8,8,8,8,8,8,8,8,8,8,8,8,8,8,8,8,8,8,2,2,1,1
1,1,1,2,8,8,8,8,8,8,8,8,8,8,8,8,8,8,8,8,8,8,8,2,1,1,1
1,1,2,2,2,7,8,8,8,8,8,8,8,8,8,8,8,8,8,8,8,7,2,2,2,1,1
1,1,1,1,2,2,8,8,8,8,8,8,8,8,8,8,8,8,8,8,8,2,2,1,1,1,1
1,1,1,1,1,2,2,2,2,8,8,8,8,8,8,8,8,8,2,2,2,2,1,1,1,1,1
1,1,1,1,1,2,1,2,2,7,2,2,5,4,5,2,2,7,2,2,1,2,1,1,1,1,1
1,1,1,1,1,1,1,1,2,1,1,2,2,2,2,2,1,1,2,1,1,1,1,1,1,1,1
1,1,1,1,1,1,1,1,1,1,1,1,1,1,1,1,1,1,1,1,1,1,1,1,1,1,1
endlayer

layer
1,1,1,1,1,1,1,1,1,1,1,2,1,1,1,2,1,1,1,1,1,1,1,1,1,1,1
1,1,1,1,1,1,1,1,2,2,2,2,2,2,2,2,2,2,2,1,1,1,1,1,1,1,1
1,1,1,1,1,2,2,2,2,5,5,2,5,5,5,2,5,5,2,2,2,2,1,1,1,1,1
1,1,1,1,2,2,2,13,8,8,8,8,8,8,8,8,8,8,8,8,8,2,2,1,1,1,1
1,1,1,2,2,8,12,2,8,8,8,8,8,8,8,8,8,8,8,8,8,8,2,2,1,1,1
1,1,2,2,8,8,12,5,8,8,8,8,8,8,8,8,8,8,8,8,8,8,8,2,2,1,1
1,1,2,2,8,8,12,2,8,8,8,8,8,8,8,8,8,8,8,8,8,8,8,8,2,1,1
1,1,2,8,8,8,8,12,2,8,8,8,8,8,8,8,8,8,8,8,8,8,8,8,2,1,1
1,2,2,8,8,8,8,2,8,8,8,8,8,8,8,8,8,8,8,8,8,8,8,8,2,2,1
1,2,5,8,8,8,8,8,8,8,8,8,8,8,8,8,8,8,8,8,8,8,8,8,5,2,1
1,2,5,8,8,8,8,8,8,8,8,8,8,8,8,8,8,8,8,8,8,8,8,8,5,2,1
2,2,2,8,8,8,8,8,8,8,8,8,8,8,8,8,8,8,8,8,8,8,8,8,2,2,2
1,2,5,8,8,8,8,8,8,8,8,8,8,8,8,8,8,8,8,8,8,8,8,8,5,2,1
1,2,5,8,8,8,8,8,8,8,8,8,8,8,8,8,8,8,8,8,8,8,8,8,5,2,1
1,2,5,8,8,8,8,8,8,8,8,8,8,8,8,8,8,8,8,8,8,8,8,8,5,2,1
2,2,2,8,8,8,8,8,8,8,8,8,8,8,8,8,8,8,8,8,8,8,8,8,2,2,2
1,2,5,8,8,8,8,8,8,8,8,8,8,8,8,8,8,8,8,8,8,8,8,8,5,2,1
1,2,5,8,8,8,8,8,8,8,8,8,8,8,8,8,8,8,8,8,8,8,8,8,5,2,1
1,2,2,8,8,8,8,8,8,8,8,8,8,8,8,8,8,8,8,8,8,8,8,8,2,2,1
1,1,2,8,8,8,8,8,8,8,8,8,8,8,8,8,8,8,8,8,8,8,8,8,2,1,1
1,1,2,8,8,8,8,8,8,8,8,8,8,8,8,8,8,8,8,8,8,8,8,8,2,1,1
1,1,2,2,8,8,8,8,8,8,8,8,8,8,8,8,8,8,8,8,8,8,8,2,2,1,1
1,1,1,2,2,8,8,8,8,8,8,8,8,8,8,8,8,8,8,8,8,8,2,2,1,1,1
1,1,1,1,2,2,8,8,8,8,8,8,8,8,8,8,8,8,8,8,8,2,2,1,1,1,1
1,1,1,1,1,2,2,2,2,5,5,2,5,5,5,2,5,5,2,2,2,2,1,1,1,1,1
1,1,1,1,1,1,1,1,2,2,2,2,2,2,2,2,2,2,2,1,1,1,1,1,1,1,1
1,1,1,1,1,1,1,1,1,1,1,2,1,1,1,2,1,1,1,1,1,1,1,1,1,1,1
endlayer

layer
1,1,1,1,1,1,1,1,1,1,1,2,1,1,1,2,1,1,1,1,1,1,1,1,1,1,1
1,1,1,1,1,1,1,2,1,1,1,2,1,1,1,2,1,1,1,2,1,1,1,1,1,1,1
1,1,1,1,2,1,1,2,5,5,5,2,5,5,5,2,5,5,5,2,1,1,2,1,1,1,1
1,1,1,1,1,5,5,8,12,11,8,8,8,8,8,8,8,8,8,8,5,5,1,1,1,1,1
1,1,2,1,5,8,8,8,12,11,8,8,8,8,8,8,8,8,8,8,8,8,5,1,2,1,1
1,1,1,5,8,8,8,8,12,11,8,8,8,8,8,8,8,8,8,8,8,8,8,5,1,1,1
1,1,1,5,8,8,8,8,2,8,8,8,8,8,8,8,8,8,8,8,8,8,8,5,1,1,1
1,2,2,8,8,8,8,8,2,8,8,8,8,8,8,8,8,8,8,8,8,8,8,8,2,2,1
1,1,5,8,8,8,8,2,8,8,8,8,8,8,8,8,8,8,8,8,8,8,8,8,5,1,1
1,1,5,8,8,8,8,8,8,8,8,8,8,8,8,8,8,8,8,8,8,8,8,8,5,1,1
1,1,5,8,8,8,8,8,8,8,8,8,8,8,8,8,8,8,8,8,8,8,8,8,5,1,1
2,2,2,8,8,8,8,8,8,8,8,8,8,8,8,8,8,8,8,8,8,8,8,8,2,2,2
1,1,5,8,8,8,8,8,8,8,8,8,8,8,8,8,8,8,8,8,8,8,8,8,5,1,1
1,1,5,8,8,8,8,8,8,8,8,8,8,8,8,8,8,8,8,8,8,8,8,8,5,1,1
1,1,5,8,8,8,8,8,8,8,8,8,8,8,8,8,8,8,8,8,8,8,8,8,5,1,1
2,2,2,8,8,8,8,8,8,8,8,8,8,8,8,8,8,8,8,8,8,8,8,8,2,2,2
1,1,5,8,8,8,8,8,8,8,8,8,8,8,8,8,8,8,8,8,8,8,8,8,5,1,1
1,1,5,8,8,8,8,8,8,8,8,8,8,8,8,8,8,8,8,8,8,8,8,8,5,1,1
1,1,5,8,8,8,8,8,8,8,8,8,8,8,8,8,8,8,8,8,8,8,8,8,5,1,1
1,2,2,8,8,8,8,8,8,8,8,8,8,8,8,8,8,8,8,8,8,8,8,8,2,2,1
1,1,1,5,8,8,8,8,8,8,8,8,8,8,8,8,8,8,8,8,8,8,8,5,1,1,1
1,1,1,5,8,8,8,8,8,8,8,8,8,8,8,8,8,8,8,8,8,8,8,5,1,1,1
1,1,2,1,5,8,8,8,8,8,8,8,8,8,8,8,8,8,8,8,8,8,5,1,2,1,1
1,1,1,1,1,5,5,8,8,8,8,8,8,8,8,8,8,8,8,8,5,5,1,1,1,1,1
1,1,1,1,2,1,1,2,5,5,5,2,5,5,5,2,5,5,5,2,1,1,2,1,1,1,1
1,1,1,1,1,1,1,2,1,1,1,2,1,1,1,2,1,1,1,2,1,1,1,1,1,1,1
1,1,1,1,1,1,1,1,1,1,1,2,1,1,1,2,1,1,1,1,1,1,1,1,1,1,1
endlayer

layer
1,1,1,1,1,1,1,1,1,1,2,2,2,2,2,2,2,1,1,1,1,1,1,1,1,1,1
1,1,1,1,1,1,1,2,2,2,2,14,14,2,14,14,2,2,2,2,1,1,1,1,1,1,1
1,1,1,1,2,2,2,2,2,2,2,2,2,15,2,2,2,2,2,2,2,2,2,1,1,1,1
1,1,1,1,2,2,2,8,8,8,12,2,2,15,2,2,15,15,2,2,2,2,2,1,1,1,1
1,1,2,2,2,8,8,8,8,8,12,15,15,7,15,15,15,2,16,16,2,2,2,2,2,1,1
1,1,2,2,8,8,8,8,8,8,12,2,2,2,2,2,15,2,16,16,2,15,2,2,2,1,1
1,1,2,2,8,8,8,8,2,2,2,2,11,2,11,16,16,15,2,11,11,2,2,2,2,1,1
1,2,2,8,8,8,8,8,2,15,15,15,11,2,11,16,16,15,15,11,11,16,16,2,2,2,1
1,2,2,8,8,8,8,2,7,15,15,2,11,2,11,2,15,15,7,15,2,16,16,2,2,2,1
1,2,2,8,8,8,8,2,15,11,2,2,2,15,2,2,2,11,15,15,15,2,2,15,2,2,1
2,2,2,11,11,11,11,2,15,2,16,16,2,15,2,16,16,2,15,16,16,15,15,15,2,2,2
2,9,2,2,15,2,2,15,2,2,16,16,2,11,2,16,16,2,2,16,16,2,15,2,2,17,2
2,9,2,2,15,2,11,11,11,2,2,2,15,11,15,2,2,2,11,11,11,2,15,2,2,17,2
2,2,15,15,7,2,2,2,2,15,15,11,11,7,11,11,15,15,2,2,2,2,7,15,15,2,2
2,9,2,2,15,2,11,11,11,2,2,2,15,11,15,2,2,2,11,11,11,2,15,2,2,17,2
2,9,2,2,15,2,16,16,2,2,16,16,2,11,2,16,16,2,2,16,16,2,15,2,2,17,2
2,2,2,15,15,2,16,16,15,2,16,16,2,15,2,16,16,2,15,16,16,2,15,15,2,2,2
1,2,2,15,2,2,2,2,15,11,2,2,2,15,2,2,2,11,15,2,2,2,2,15,2,2,1
1,2,2,2,16,16,2,15,7,15,15,2,11,2,11,2,15,15,7,15,2,16,16,2,2,2,1
1,2,2,2,16,16,11,11,15,2,16,16,11,2,11,16,16,2,15,11,11,16,16,2,2,2,1
1,1,2,2,2,2,11,11,2,2,16,16,11,2,11,16,16,2,2,11,11,2,2,2,2,1,1
1,1,2,2,2,15,2,16,16,2,2,2,2,2,2,2,2,2,16,16,2,15,2,2,2,1,1
1,1,2,2,2,2,2,16,16,2,15,15,15,7,15,15,15,2,16,16,2,2,2,2,2,1,1
1,1,1,1,2,2,2,2,2,15,15,2,2,15,2,2,15,15,2,2,2,2,2,1,1,1,1
1,1,1,1,2,2,2,2,2,2,2,2,2,15,2,2,2,2,2,2,2,2,2,1,1,1,1
1,1,1,1,1,1,1,2,2,2,2,18,18,2,18,18,2,2,2,2,1,1,1,1,1,1,1
1,1,1,1,1,1,1,1,1,1,2,2,2,2,2,2,2,1,1,1,1,1,1,1,1,1,1
endlayer

layer
1,1,1,1,1,1,1,1,1,1,1,1,1,1,1,1,1,1,1,1,1,1,1,1,1,1,1
1,1,1,1,1,1,1,2,1,1,2,20,19,2,20,19,2,1,1,2,1,1,1,1,1,1,1
1,1,1,1,2,1,1,21,21,21,2,8,8,8,8,8,2,21,21,21,1,1,2,1,1,1,1
1,1,1,1,1,21,21,8,8,8,8,8,8,8,8,8,8,8,8,8,21,21,1,1,1,1,1
1,1,2,1,2,8,8,8,8,8,8,8,8,8,8,8,8,8,8,8,8,8,2,1,2,1,1
1,1,1,21,8,8,8,8,8,8,8,8,8,8,8,8,8,8,8,8,8,8,8,21,1,1,1
1,1,1,21,8,8,8,8,8,8,8,8,8,8,8,8,8,8,8,8,8,8,8,21,1,1,1
1,2,21,8,8,8,8,8,8,8,8,8,8,8,8,8,8,8,8,8,8,8,8,8,21,2,1
1,1,21,8,8,8,8,8,8,8,8,8,8,8,8,8,8,8,8,8,8,8,8,8,21,1,1
1,1,21,8,8,8,8,8,8,8,8,8,8,8,8,8,8,8,8,8,8,8,8,8,21,1,1
1,2,2,8,8,8,8,8,8,8,8,8,8,8,8,8,8,8,8,8,8,8,8,8,2,2,1
1,22,8,8,8,8,8,8,8,8,8,8,8,8,8,8,8,8,8,8,8,8,8,8,8,22,1
1,23,8,8,8,8,8,8,8,8,8,8,8,8,8,8,8,8,8,8,8,8,8,8,8,23,1
1,2,8,8,8,8,8,8,8,8,8,8,8,8,8,8,8,8,8,8,8,8,8,8,8,2,1
1,22,8,8,8,8,8,8,8,8,8,8,8,8,8,8,8,8,8,8,8,8,8,8,8,22,1
1,23,8,8,8,8,8,8,8,8,8,8,8,8,8,8,8,8,8,8,8,8,8,8,8,23,1
1,2,2,8,8,8,8,8,8,8,8,8,8,8,8,8,8,8,8,8,8,8,8,8,2,2,1
1,1,21,8,8,8,8,8,8,8,8,8,8,8,8,8,8,8,8,8,8,8,8,8,21,1,1
1,1,21,8,8,8,8,8,8,8,8,8,8,8,8,8,8,8,8,8,8,8,8,8,21,1,1
1,2,21,8,8,8,8,8,8,8,8,8,8,8,8,8,8,8,8,8,8,8,8,8,21,2,1
1,1,1,21,8,8,8,8,8,8,8,8,8,8,8,8,8,8,8,8,8,8,8,21,1,1,1
1,1,1,21,8,8,8,8,8,8,8,8,8,8,8,8,8,8,8,8,8,8,8,21,1,1,1
1,1,2,1,2,8,8,8,8,8,8,8,8,8,8,8,8,8,8,8,8,8,2,1,2,1,1
1,1,1,1,1,21,21,8,8,8,8,8,8,8,8,8,8,8,8,8,21,21,1,1,1,1,1
1,1,1,1,2,1,1,21,21,21,2,8,8,8,8,8,2,21,21,21,1,1,2,1,1,1,1
1,1,1,1,1,1,1,2,1,1,2,20,19,2,20,19,2,1,1,2,1,1,1,1,1,1,1
1,1,1,1,1,1,1,1,1,1,1,1,1,1,1,1,1,1,1,1,1,1,1,1,1,1,1
endlayer

layer
1,1,1,1,1,1,1,1,1,1,1,1,1,1,1,1,1,1,1,1,1,1,1,1,1,1,1
1,1,1,1,1,1,1,2,1,1,2,20,19,2,20,19,2,1,1,2,1,1,1,1,1,1,1
1,1,1,1,2,1,1,21,21,21,2,8,8,8,8,8,2,21,21,21,1,1,2,1,1,1,1
1,1,1,1,1,21,21,8,8,8,8,8,8,8,8,8,8,8,8,8,21,21,1,1,1,1,1
1,1,2,1,2,8,8,8,8,8,8,8,8,8,8,8,8,8,8,8,8,8,2,1,2,1,1
1,1,1,21,8,8,8,8,8,8,8,8,8,8,8,8,8,8,8,8,8,8,8,21,1,1,1
1,1,1,21,8,8,8,8,8,8,8,8,8,8,8,8,8,8,8,8,8,8,8,21,1,1,1
1,2,21,8,8,8,8,8,8,8,8,8,8,8,8,8,8,8,8,8,8,8,8,8,21,2,1
1,1,21,8,8,8,8,8,8,8,8,8,8,8,8,8,8,8,8,8,8,8,8,8,21,1,1
1,1,21,8,8,8,8,8,8,8,8,8,8,8,8,8,8,8,8,8,8,8,8,8,21,1,1
1,2,2,8,8,8,8,8,8,8,8,8,8,8,8,8,8,8,8,8,8,8,8,8,2,2,1
1,22,8,8,8,8,8,8,8,8,8,8,8,8,8,8,8,8,8,8,8,8,8,8,8,22,1
1,23,8,8,8,8,8,8,8,8,8,8,8,8,8,8,8,8,8,8,8,8,8,8,8,23,1
1,2,8,8,8,8,8,8,8,8,8,8,8,8,8,8,8,8,8,8,8,8,8,8,8,2,1
1,22,8,8,8,8,8,8,8,8,8,8,8,8,8,8,8,8,8,8,8,8,8,8,8,22,1
1,23,8,8,8,8,8,8,8,8,8,8,8,8,8,8,8,8,8,8,8,8,8,8,8,23,1
1,2,2,8,8,8,8,8,8,8,8,8,8,8,8,8,8,8,8,8,8,8,8,8,2,2,1
1,1,21,8,8,8,8,8,8,8,8,8,8,8,8,8,8,8,8,8,8,8,8,8,21,1,1
1,1,21,8,8,8,8,8,8,8,8,8,8,8,8,8,8,8,8,8,8,8,8,8,21,1,1
1,2,21,8,8,8,8,8,8,8,8,8,8,8,8,8,8,8,8,8,8,8,8,8,21,2,1
1,1,1,21,8,8,8,8,8,8,8,8,8,8,8,8,8,8,8,8,8,8,8,21,1,1,1
1,1,1,21,8,8,8,8,8,8,8,8,8,8,8,8,8,8,8,8,8,8,8,21,1,1,1
1,1,2,1,2,8,8,8,8,8,8,8,8,8,8,8,8,8,8,8,8,8,2,1,2,1,1
1,1,1,1,1,21,21,8,8,8,8,8,8,8,8,8,8,8,8,8,21,21,1,1,1,1,1
1,1,1,1,2,1,1,21,21,21,2,8,8,8,8,8,2,21,21,21,1,1,2,1,1,1,1
1,1,1,1,1,1,1,2,1,1,2,20,19,2,20,19,2,1,1,2,1,1,1,1,1,1,1
1,1,1,1,1,1,1,1,1,1,1,1,1,1,1,1,1,1,1,1,1,1,1,1,1,1,1
endlayer

layer
1,1,1,1,1,1,1,1,1,1,1,1,1,1,1,1,1,1,1,1,1,1,1,1,1,1,1
1,1,1,1,1,1,1,2,1,1,2,20,19,2,20,19,2,1,1,2,1,1,1,1,1,1,1
1,1,1,1,2,1,1,7,21,21,2,8,8,8,8,8,2,21,21,7,1,1,2,1,1,1,1
1,1,1,1,1,21,21,8,8,8,8,8,8,8,8,8,8,8,8,8,21,21,1,1,1,1,1
1,1,2,1,2,8,8,8,8,8,8,8,8,8,8,8,8,8,8,8,8,8,2,1,2,1,1
1,1,1,21,8,8,8,8,8,8,8,8,8,8,8,8,8,8,8,8,8,8,8,21,1,1,1
1,1,1,21,8,8,8,8,8,8,8,8,8,8,8,8,8,8,8,8,8,8,8,21,1,1,1
1,2,7,8,8,8,8,8,8,8,8,8,8,8,8,8,8,8,8,8,8,8,8,8,7,2,1
1,1,21,8,8,8,8,8,8,8,8,8,8,8,8,8,8,8,8,8,8,8,8,8,21,1,1
1,1,21,8,8,8,8,8,8,8,8,8,8,8,8,8,8,8,8,8,8,8,8,8,21,1,1
1,2,2,8,8,8,8,8,8,8,8,8,8,8,8,8,8,8,8,8,8,8,8,8,2,2,1
1,22,8,8,8,8,8,8,8,8,8,8,8,8,8,8,8,8,8,8,8,8,8,8,8,22,1
1,23,8,8,8,8,8,8,8,8,8,8,8,8,8,8,8,8,8,8,8,8,8,8,8,23,1
1,2,8,8,8,8,8,8,8,8,8,8,8,8,8,8,8,8,8,8,8,8,8,8,8,2,1
1,22,8,8,8,8,8,8,8,8,8,8,8,8,8,8,8,8,8,8,8,8,8,8,8,22,1
1,23,8,8,8,8,8,8,8,8,8,8,8,8,8,8,8,8,8,8,8,8,8,8,8,23,1
1,2,2,8,8,8,8,8,8,8,8,8,8,8,8,8,8,8,8,8,8,8,8,8,2,2,1
1,1,21,8,8,8,8,8,8,8,8,8,8,8,8,8,8,8,8,8,8,8,8,8,21,1,1
1,1,21,8,8,8,8,8,8,8,8,8,8,8,8,8,8,8,8,8,8,8,8,8,21,1,1
1,2,7,8,8,8,8,8,8,8,8,8,8,8,8,8,8,8,8,8,8,8,8,8,7,2,1
1,1,1,21,8,8,8,8,8,8,8,8,8,8,8,8,8,8,8,8,8,8,8,21,1,1,1
1,1,1,21,8,8,8,8,8,8,8,8,8,8,8,8,8,8,8,8,8,8,8,21,1,1,1
1,1,2,1,2,8,8,8,8,8,8,8,8,8,8,8,8,8,8,8,8,8,2,1,2,1,1
1,1,1,1,1,21,21,8,8,8,8,8,8,8,8,8,8,8,8,8,21,21,1,1,1,1,1
1,1,1,1,2,1,1,7,21,21,2,8,8,8,8,8,2,21,21,7,1,1,2,1,1,1,1
1,1,1,1,1,1,1,2,1,1,2,20,19,2,20,19,2,1,1,2,1,1,1,1,1,1,1
1,1,1,1,1,1,1,1,1,1,1,1,1,1,1,1,1,1,1,1,1,1,1,1,1,1,1
endlayer

layer
1,1,1,1,1,1,1,1,1,1,1,1,1,1,1,1,1,1,1,1,1,1,1,1,1,1,1
1,1,1,1,1,1,1,2,1,1,2,20,19,2,20,19,2,1,1,2,1,1,1,1,1,1,1
1,1,1,1,2,1,1,21,21,2,8,8,8,8,8,8,8,2,21,21,1,1,2,1,1,1,1
1,1,1,1,1,21,21,8,8,8,8,8,8,8,8,8,8,8,8,8,21,21,1,1,1,1,1
1,1,2,1,2,8,8,8,8,8,8,8,8,8,8,8,8,8,8,8,8,8,2,1,2,1,1
1,1,1,21,8,8,8,8,8,8,8,8,8,8,8,8,8,8,8,8,8,8,8,21,1,1,1
1,1,1,21,8,8,8,8,8,8,8,8,8,8,8,8,8,8,8,8,8,8,8,21,1,1,1
1,2,21,8,8,8,8,8,8,8,8,8,8,8,8,8,8,8,8,8,8,8,8,8,21,2,1
1,1,21,8,8,8,8,8,8,8,8,8,8,8,8,8,8,8,8,8,8,8,8,8,21,1,1
1,1,2,8,8,8,8,8,8,8,8,8,8,8,8,8,8,8,8,8,8,8,8,8,2,1,1
1,2,8,8,8,8,8,8,8,8,8,8,8,8,8,8,8,8,8,8,8,8,8,8,8,2,1
1,22,8,8,8,8,8,8,8,8,8,8,8,8,8,8,8,8,8,8,8,8,8,8,8,22,1
1,23,8,8,8,8,8,8,8,8,8,8,8,8,8,8,8,8,8,8,8,8,8,8,8,23,1
1,2,8,8,8,8,8,8,8,8,8,8,8,8,8,8,8,8,8,8,8,8,8,8,8,2,1
1,22,8,8,8,8,8,8,8,8,8,8,8,8,8,8,8,8,8,8,8,8,8,8,8,22,1
1,23,8,8,8,8,8,8,8,8,8,8,8,8,8,8,8,8,8,8,8,8,8,8,8,23,1
1,2,8,8,8,8,8,8,8,8,8,8,8,8,8,8,8,8,8,8,8,8,8,8,8,2,1
1,1,2,8,8,8,8,8,8,8,8,8,8,8,8,8,8,8,8,8,8,8,8,8,2,1,1
1,1,21,8,8,8,8,8,8,8,8,8,8,8,8,8,8,8,8,8,8,8,8,8,21,1,1
1,2,21,8,8,8,8,8,8,8,8,8,8,8,8,8,8,8,8,8,8,8,8,8,21,2,1
1,1,1,21,8,8,8,8,8,8,8,8,8,8,8,8,8,8,8,8,8,8,8,21,1,1,1
1,1,1,21,8,8,8,8,8,8,8,8,8,8,8,8,8,8,8,8,8,8,8,21,1,1,1
1,1,2,1,2,8,8,8,8,8,8,8,8,8,8,8,8,8,8,8,8,8,2,1,2,1,1
1,1,1,1,1,21,21,8,8,8,8,8,8,8,8,8,8,8,8,8,21,21,1,1,1,1,1
1,1,1,1,2,1,1,21,21,2,8,8,8,8,8,8,8,2,21,21,1,1,2,1,1,1,1
1,1,1,1,1,1,1,2,1,1,2,20,19,2,20,19,2,1,1,2,1,1,1,1,1,1,1
1,1,1,1,1,1,1,1,1,1,1,1,1,1,1,1,1,1,1,1,1,1,1,1,1,1,1
endlayer

layer
1,1,1,1,1,1,1,1,1,1,1,1,1,1,1,1,1,1,1,1,1,1,1,1,1,1,1
1,1,1,1,1,1,1,1,2,2,2,2,2,2,2,2,2,2,2,1,1,1,1,1,1,1,1
1,1,1,1,1,2,2,2,2,8,8,8,8,8,8,8,8,8,2,2,2,2,1,1,1,1,1
1,1,1,2,2,2,2,8,8,8,8,8,8,8,8,8,8,8,8,8,2,2,2,2,1,1,1
1,1,1,2,2,8,8,8,8,8,8,8,8,8,8,8,8,8,8,8,8,8,2,2,1,1,1
1,1,2,2,8,8,8,8,8,8,8,8,8,8,8,8,8,8,8,8,8,8,8,2,2,1,1
1,1,2,2,8,8,8,8,8,8,8,8,8,8,8,8,8,8,8,8,8,8,8,2,2,1,1
1,1,2,8,8,8,8,8,8,8,8,8,8,8,8,8,8,8,8,8,8,8,8,8,2,1,1
1,2,2,8,8,8,8,8,8,8,8,8,8,8,8,8,8,8,8,8,8,8,8,8,2,2,1
1,2,8,8,8,8,8,8,8,8,8,8,8,8,8,8,8,8,8,8,8,8,8,8,8,2,1
1,2,8,8,8,8,8,8,8,8,8,8,8,8,8,8,8,8,8,8,8,8,8,8,8,2,1
1,2,8,8,8,8,8,8,8,8,8,8,8,8,8,8,8,8,8,8,8,8,8,8,8,2,1
1,2,8,8,8,8,8,8,8,8,8,8,8,8,8,8,8,8,8,8,8,8,8,8,8,2,1
1,2,8,8,8,8,8,8,8,8,8,8,8,8,8,8,8,8,8,8,8,8,8,8,8,2,1
1,2,8,8,8,8,8,8,8,8,8,8,8,8,8,8,8,8,8,8,8,8,8,8,8,2,1
1,2,8,8,8,8,8,8,8,8,8,8,8,8,8,8,8,8,8,8,8,8,8,8,8,2,1
1,2,8,8,8,8,8,8,8,8,8,8,8,8,8,8,8,8,8,8,8,8,8,8,8,2,1
1,2,8,8,8,8,8,8,8,8,8,8,8,8,8,8,8,8,8,8,8,8,8,8,8,2,1
1,2,2,8,8,8,8,8,8,8,8,8,8,8,8,8,8,8,8,8,8,8,8,8,2,2,1
1,1,2,8,8,8,8,8,8,8,8,8,8,8,8,8,8,8,8,8,8,8,8,8,2,1,1
1,1,2,2,8,8,8,8,8,8,8,8,8,8,8,8,8,8,8,8,8,8,8,2,2,1,1
1,1,2,2,8,8,8,8,8,8,8,8,8,8,8,8,8,8,8,8,8,8,8,2,2,1,1
1,1,1,2,2,8,8,8,8,8,8,8,8,8,8,8,8,8,8,8,8,8,2,2,1,1,1
1,1,1,2,2,2,2,8,8,8,8,8,8,8,8,8,8,8,8,8,2,2,2,2,1,1,1
1,1,1,1,1,2,2,2,2,8,8,8,8,8,8,8,8,8,2,2,2,2,1,1,1,1,1
1,1,1,1,1,1,1,1,2,2,2,2,2,2,2,2,2,2,2,1,1,1,1,1,1,1,1
1,1,1,1,1,1,1,1,1,1,1,1,1,1,1,1,1,1,1,1,1,1,1,1,1,1,1
endlayer

layer
1,1,1,1,1,1,1,1,1,1,1,1,1,1,1,1,1,1,1,1,1,1,1,1,1,1,1
1,1,1,1,1,1,1,1,1,16,16,16,2,2,2,16,16,16,1,1,1,1,1,1,1,1,1
1,1,1,1,1,1,1,16,2,8,8,8,8,7,8,8,8,8,2,16,1,1,1,1,1,1,1
1,1,1,1,1,16,16,8,8,8,8,8,8,8,8,8,8,8,8,8,16,16,1,1,1,1,1
1,1,1,1,2,8,8,8,8,8,8,8,8,8,8,8,8,8,8,8,8,8,2,1,1,1,1
1,1,1,16,8,8,8,8,8,8,8,8,8,8,8,8,8,8,8,8,8,8,8,16,1,1,1
1,1,1,16,8,8,8,8,8,8,8,8,8,8,8,8,8,8,8,8,8,8,8,16,1,1,1
1,1,16,8,8,8,8,8,8,8,8,8,8,8,8,8,8,8,8,8,8,8,8,8,16,1,1
1,1,2,8,8,8,8,8,8,8,8,8,8,8,8,8,8,8,8,8,8,8,8,8,2,1,1
1,16,8,8,8,8,8,8,8,8,8,8,8,8,8,8,8,8,8,8,8,8,8,8,8,16,1
1,16,8,8,8,8,8,8,8,8,8,8,8,8,8,8,8,8,8,8,8,8,8,8,8,16,1
1,16,8,8,8,8,8,8,8,8,8,8,8,8,8,8,8,8,8,8,8,8,8,8,8,16,1
1,2,8,8,8,8,8,8,8,8,8,8,8,8,8,8,8,8,8,8,8,8,8,8,8,2,1
1,2,7,8,8,8,8,8,8,8,8,8,8,8,8,8,8,8,8,8,8,8,8,8,7,2,1
1,2,8,8,8,8,8,8,8,8,8,8,8,8,8,8,8,8,8,8,8,8,8,8,8,2,1
1,16,8,8,8,8,8,8,8,8,8,8,8,8,8,8,8,8,8,8,8,8,8,8,8,16,1
1,16,8,8,8,8,8,8,8,8,8,8,8,8,8,8,8,8,8,8,8,8,8,8,8,16,1
1,16,8,8,8,8,8,8,8,8,8,8,8,8,8,8,8,8,8,8,8,8,8,8,8,16,1
1,1,2,8,8,8,8,8,8,8,8,8,8,8,8,8,8,8,8,8,8,8,8,8,2,1,1
1,1,16,8,8,8,8,8,8,8,8,8,8,8,8,8,8,8,8,8,8,8,8,8,16,1,1
1,1,1,16,8,8,8,8,8,8,8,8,8,8,8,8,8,8,8,8,8,8,8,16,1,1,1
1,1,1,16,8,8,8,8,8,8,8,8,8,8,8,8,8,8,8,8,8,8,8,16,1,1,1
1,1,1,1,2,8,8,8,8,8,8,8,8,8,8,8,8,8,8,8,8,8,2,1,1,1,1
1,1,1,1,1,16,16,8,8,8,8,8,8,8,8,8,8,8,8,8,16,16,1,1,1,1,1
1,1,1,1,1,1,1,16,2,8,8,8,8,7,8,8,8,8,2,16,1,1,1,1,1,1,1
1,1,1,1,1,1,1,1,1,16,16,16,2,2,2,16,16,16,1,1,1,1,1,1,1,1,1
1,1,1,1,1,1,1,1,1,1,1,1,1,1,1,1,1,1,1,1,1,1,1,1,1,1,1
endlayer

layer
1,1,1,1,1,1,1,1,1,1,1,1,1,1,1,1,1,1,1,1,1,1,1,1,1,1,1
1,1,1,1,1,1,1,1,2,2,2,2,2,2,2,2,2,2,2,1,1,1,1,1,1,1,1
1,1,1,1,1,1,2,2,2,8,8,8,8,24,8,8,8,8,2,2,2,1,1,1,1,1,1
1,1,1,1,1,2,2,8,8,8,8,8,8,8,8,8,8,8,8,8,2,2,1,1,1,1,1
1,1,1,1,2,2,8,8,8,8,8,8,8,8,8,8,8,8,8,8,8,2,2,1,1,1,1
1,1,1,2,2,7,8,8,8,8,8,8,8,8,8,8,8,8,8,8,8,7,2,2,1,1,1
1,1,2,2,8,8,8,8,8,8,8,8,8,8,8,8,8,8,8,8,8,8,8,2,2,1,1
1,1,2,8,8,8,8,8,8,8,8,8,8,8,8,8,8,8,8,8,8,8,8,8,2,1,1
1,2,2,8,8,8,8,8,8,8,8,8,8,8,8,8,8,8,8,8,8,8,8,8,2,2,1
1,2,8,8,8,8,8,8,8,8,8,8,8,8,8,8,8,8,8,8,8,8,8,8,8,2,1
1,2,8,8,8,8,8,8,8,8,8,8,8,8,8,8,8,8,8,8,8,8,8,8,8,2,1
1,2,8,8,8,8,8,8,8,8,8,8,8,8,8,8,8,8,8,8,8,8,8,8,8,2,1
1,2,8,8,8,8,8,8,8,8,8,8,8,8,8,8,8,8,8,8,8,8,8,8,8,2,1
1,2,26,8,8,8,8,8,8,8,8,8,8,8,8,8,8,8,8,8,8,8,8,8,25,2,1
1,2,8,8,8,8,8,8,8,8,8,8,8,8,8,8,8,8,8,8,8,8,8,8,8,2,1
1,2,8,8,8,8,8,8,8,8,8,8,8,8,8,8,8,8,8,8,8,8,8,8,8,2,1
1,2,8,8,8,8,8,8,8,8,8,8,8,8,8,8,8,8,8,8,8,8,8,8,8,2,1
1,2,8,8,8,8,8,8,8,8,8,8,8,8,8,8,8,8,8,8,8,8,8,8,8,2,1
1,2,2,8,8,8,8,8,8,8,8,8,8,8,8,8,8,8,8,8,8,8,8,8,2,2,1
1,1,2,8,8,8,8,8,8,8,8,8,8,8,8,8,8,8,8,8,8,8,8,8,2,1,1
1,1,2,2,8,8,8,8,8,8,8,8,8,8,8,8,8,8,8,8,8,8,8,2,2,1,1
1,1,1,2,2,7,8,8,8,8,8,8,8,8,8,8,8,8,8,8,8,7,2,2,1,1,1
1,1,1,1,2,2,8,8,8,8,8,8,8,8,8,8,8,8,8,8,8,2,2,1,1,1,1
1,1,1,1,1,2,2,8,8,8,8,8,8,8,8,8,8,8,8,8,2,2,1,1,1,1,1
1,1,1,1,1,1,2,2,2,8,8,8,8,27,8,8,8,8,2,2,2,1,1,1,1,1,1
1,1,1,1,1,1,1,1,2,2,2,2,2,2,2,2,2,2,2,1,1,1,1,1,1,1,1
1,1,1,1,1,1,1,1,1,1,1,1,1,1,1,1,1,1,1,1,1,1,1,1,1,1,1
endlayer

layer
1,1,1,1,1,1,1,1,1,1,1,1,1,1,1,1,1,1,1,1,1,1,1,1,1,1,1
1,1,1,1,1,1,1,1,1,1,1,1,1,1,1,1,1,1,1,1,1,1,1,1,1,1,1
1,1,1,1,1,1,1,1,1,28,28,28,28,2,28,28,28,28,1,1,1,1,1,1,1,1,1
1,1,1,1,1,1,1,28,28,11,11,11,11,24,11,11,11,11,28,28,1,1,1,1,1,1,1
1,1,1,1,1,1,28,11,11,7,8,8,8,8,8,8,8,7,11,11,28,1,1,1,1,1,1
1,1,1,1,1,28,11,11,8,8,8,8,8,8,8,8,8,8,8,11,11,28,1,1,1,1,1
1,1,1,1,28,11,8,8,8,8,8,8,8,8,8,8,8,8,8,8,8,11,28,1,1,1,1
1,1,1,28,11,11,8,8,8,8,8,8,8,8,8,8,8,8,8,8,8,11,11,28,1,1,1
1,1,1,28,11,8,8,8,8,8,8,8,8,8,8,8,8,8,8,8,8,8,11,28,1,1,1
1,1,28,11,7,8,8,8,8,8,8,8,8,8,8,8,8,8,8,8,8,8,7,11,28,1,1
1,1,28,11,8,8,8,8,8,8,8,8,8,8,8,8,8,8,8,8,8,8,8,11,28,1,1
1,1,28,11,8,8,8,8,8,8,8,8,8,8,8,8,8,8,8,8,8,8,8,11,28,1,1
1,1,28,11,8,8,8,8,8,8,8,8,8,8,8,8,8,8,8,8,8,8,8,11,28,1,1
1,1,2,26,8,8,8,8,8,8,8,8,8,8,8,8,8,8,8,8,8,8,8,25,2,1,1
1,1,28,11,8,8,8,8,8,8,8,8,8,8,8,8,8,8,8,8,8,8,8,11,28,1,1
1,1,28,11,8,8,8,8,8,8,8,8,8,8,8,8,8,8,8,8,8,8,8,11,28,1,1
1,1,28,11,8,8,8,8,8,8,8,8,8,8,8,8,8,8,8,8,8,8,8,11,28,1,1
1,1,28,11,7,8,8,8,8,8,8,8,8,8,8,8,8,8,8,8,8,8,7,11,28,1,1
1,1,1,28,11,8,8,8,8,8,8,8,8,8,8,8,8,8,8,8,8,8,11,28,1,1,1
1,1,1,28,11,11,8,8,8,8,8,8,8,8,8,8,8,8,8,8,8,11,11,28,1,1,1
1,1,1,1,28,11,8,8,8,8,8,8,8,8,8,8,8,8,8,8,8,11,28,1,1,1,1
1,1,1,1,1,28,11,11,8,8,8,8,8,8,8,8,8,8,8,11,11,28,1,1,1,1,1
1,1,1,1,1,1,28,11,11,7,8,8,8,8,8,8,8,7,11,11,28,1,1,1,1,1,1
1,1,1,1,1,1,1,28,28,11,11,11,11,27,11,11,11,11,28,28,1,1,1,1,1,1,1
1,1,1,1,1,1,1,1,1,28,28,28,28,2,28,28,28,28,1,1,1,1,1,1,1,1,1
1,1,1,1,1,1,1,1,1,1,1,1,1,1,1,1,1,1,1,1,1,1,1,1,1,1,1
1,1,1,1,1,1,1,1,1,1,1,1,1,1,1,1,1,1,1,1,1,1,1,1,1,1,1
endlayer

layer
1,1,1,1,1,1,1,1,1,1,1,1,1,1,1,1,1,1,1,1,1,1,1,1,1,1,1
1,1,1,1,1,1,1,1,1,1,1,1,1,1,1,1,1,1,1,1,1,1,1,1,1,1,1
1,1,1,1,1,1,1,1,1,1,1,1,1,1,1,1,1,1,1,1,1,1,1,1,1,1,1
1,1,1,1,1,1,1,1,1,1,1,13,1,1,1,13,1,1,1,1,1,1,1,1,1,1,1
1,1,1,1,1,1,1,1,1,13,28,28,28,2,28,28,28,13,1,1,1,1,1,1,1,1,1
1,1,1,1,1,1,1,1,28,28,11,11,11,2,11,11,11,28,28,1,1,1,1,1,1,1,1
1,1,1,1,1,1,16,16,11,11,11,11,8,24,8,11,11,11,11,16,16,1,1,1,1,1,1
1,1,1,1,1,1,16,16,11,11,8,8,8,7,8,8,8,11,11,16,16,1,1,1,1,1,1
1,1,1,1,1,28,11,11,11,11,8,8,8,8,8,8,8,11,11,11,11,28,1,1,1,1,1
1,1,1,1,13,28,11,11,11,8,8,8,8,8,8,8,8,8,11,11,11,28,13,1,1,1,1
1,1,1,1,28,11,11,8,8,8,8,8,8,8,8,8,8,8,8,8,11,11,28,1,1,1,1
1,1,1,13,28,11,11,8,8,8,8,8,8,8,8,8,8,8,8,8,11,11,28,13,1,1,1
1,1,1,1,28,11,8,8,8,8,8,8,8,8,8,8,8,8,8,8,8,11,28,1,1,1,1
1,1,1,1,2,2,26,7,8,8,8,8,8,8,8,8,8,8,8,7,25,2,2,1,1,1,1
1,1,1,1,28,11,8,8,8,8,8,8,8,8,8,8,8,8,8,8,8,11,28,1,1,1,1
1,1,1,13,28,11,11,8,8,8,8,8,8,8,8,8,8,8,8,8,11,11,28,13,1,1,1
1,1,1,1,28,11,11,8,8,8,8,8,8,8,8,8,8,8,8,8,11,11,28,1,1,1,1
1,1,1,1,13,28,11,11,11,8,8,8,8,8,8,8,8,8,11,11,11,28,13,1,1,1,1
1,1,1,1,1,28,11,11,11,11,8,8,8,8,8,8,8,11,11,11,11,28,1,1,1,1,1
1,1,1,1,1,1,16,16,11,11,8,8,8,7,8,8,8,11,11,16,16,1,1,1,1,1,1
1,1,1,1,1,1,16,16,11,11,11,11,8,27,8,11,11,11,11,16,16,1,1,1,1,1,1
1,1,1,1,1,1,1,1,28,28,11,11,11,2,11,11,11,28,28,1,1,1,1,1,1,1,1
1,1,1,1,1,1,1,1,1,13,28,28,28,2,28,28,28,13,1,1,1,1,1,1,1,1,1
1,1,1,1,1,1,1,1,1,1,1,13,1,1,1,13,1,1,1,1,1,1,1,1,1,1,1
1,1,1,1,1,1,1,1,1,1,1,1,1,1,1,1,1,1,1,1,1,1,1,1,1,1,1
1,1,1,1,1,1,1,1,1,1,1,1,1,1,1,1,1,1,1,1,1,1,1,1,1,1,1
1,1,1,1,1,1,1,1,1,1,1,1,1,1,1,1,1,1,1,1,1,1,1,1,1,1,1
endlayer

layer
1,1,1,1,1,1,1,1,1,1,1,1,1,1,1,1,1,1,1,1,1,1,1,1,1,1,1
1,1,1,1,1,1,1,1,1,1,1,1,1,1,1,1,1,1,1,1,1,1,1,1,1,1,1
1,1,1,1,1,1,1,1,1,1,1,1,1,1,1,1,1,1,1,1,1,1,1,1,1,1,1
1,1,1,1,1,1,1,1,1,1,1,1,1,1,1,1,1,1,1,1,1,1,1,1,1,1,1
1,1,1,1,1,1,1,1,1,1,1,1,1,1,1,1,1,1,1,1,1,1,1,1,1,1,1
1,1,1,1,1,1,1,1,1,1,1,1,1,1,1,1,1,1,1,1,1,1,1,1,1,1,1
1,1,1,1,1,1,1,1,1,1,1,1,13,1,13,1,1,1,1,1,1,1,1,1,1,1,1
1,1,1,1,1,1,1,1,1,1,16,16,11,2,11,16,16,1,1,1,1,1,1,1,1,1,1
1,1,1,1,1,1,1,1,1,1,16,16,11,2,11,16,16,1,1,1,1,1,1,1,1,1,1
1,1,1,1,1,1,1,1,1,13,11,11,11,24,11,11,11,13,1,1,1,1,1,1,1,1,1
1,1,1,1,1,1,1,16,16,11,7,11,11,8,11,11,7,11,16,16,1,1,1,1,1,1,1
1,1,1,1,1,1,1,16,16,11,11,8,8,8,8,8,11,11,16,16,1,1,1,1,1,1,1
1,1,1,1,1,1,13,11,11,11,11,8,8,8,8,8,11,11,11,11,13,1,1,1,1,1,1
1,1,1,1,1,1,1,2,2,26,8,8,8,8,8,8,8,25,2,2,1,1,1,1,1,1,1
1,1,1,1,1,1,13,11,11,11,11,8,8,8,8,8,11,11,11,11,13,1,1,1,1,1,1
1,1,1,1,1,1,1,16,16,11,11,8,8,8,8,8,11,11,16,16,1,1,1,1,1,1,1
1,1,1,1,1,1,1,16,16,11,7,11,11,8,11,11,7,11,16,16,1,1,1,1,1,1,1
1,1,1,1,1,1,1,1,1,13,11,11,11,27,11,11,11,13,1,1,1,1,1,1,1,1,1
1,1,1,1,1,1,1,1,1,1,16,16,11,2,11,16,16,1,1,1,1,1,1,1,1,1,1
1,1,1,1,1,1,1,1,1,1,16,16,11,2,11,16,16,1,1,1,1,1,1,1,1,1,1
1,1,1,1,1,1,1,1,1,1,1,1,13,1,13,1,1,1,1,1,1,1,1,1,1,1,1
1,1,1,1,1,1,1,1,1,1,1,1,1,1,1,1,1,1,1,1,1,1,1,1,1,1,1
1,1,1,1,1,1,1,1,1,1,1,1,1,1,1,1,1,1,1,1,1,1,1,1,1,1,1
1,1,1,1,1,1,1,1,1,1,1,1,1,1,1,1,1,1,1,1,1,1,1,1,1,1,1
1,1,1,1,1,1,1,1,1,1,1,1,1,1,1,1,1,1,1,1,1,1,1,1,1,1,1
1,1,1,1,1,1,1,1,1,1,1,1,1,1,1,1,1,1,1,1,1,1,1,1,1,1,1
1,1,1,1,1,1,1,1,1,1,1,1,1,1,1,1,1,1,1,1,1,1,1,1,1,1,1
endlayer

layer
1,1,1,1,1,1,1,1,1,1,1,1,1,1,1,1,1,1,1,1,1,1,1,1,1,1,1
1,1,1,1,1,1,1,1,1,1,1,1,1,1,1,1,1,1,1,1,1,1,1,1,1,1,1
1,1,1,1,1,1,1,1,1,1,1,1,1,1,1,1,1,1,1,1,1,1,1,1,1,1,1
1,1,1,1,1,1,1,1,1,1,1,1,1,1,1,1,1,1,1,1,1,1,1,1,1,1,1
1,1,1,1,1,1,1,1,1,1,1,1,1,1,1,1,1,1,1,1,1,1,1,1,1,1,1
1,1,1,1,1,1,1,1,1,1,1,1,1,1,1,1,1,1,1,1,1,1,1,1,1,1,1
1,1,1,1,1,1,1,1,1,1,1,1,1,1,1,1,1,1,1,1,1,1,1,1,1,1,1
1,1,1,1,1,1,1,1,1,1,1,1,1,1,1,1,1,1,1,1,1,1,1,1,1,1,1
1,1,1,1,1,1,1,1,1,1,1,1,1,1,1,1,1,1,1,1,1,1,1,1,1,1,1
1,1,1,1,1,1,1,1,1,1,1,1,1,1,1,1,1,1,1,1,1,1,1,1,1,1,1
1,1,1,1,1,1,1,1,1,1,1,1,1,13,1,1,1,1,1,1,1,1,1,1,1,1,1
1,1,1,1,1,1,1,1,1,1,1,16,16,11,16,16,1,1,1,1,1,1,1,1,1,1,1
1,1,1,1,1,1,1,1,1,1,1,16,16,11,16,16,1,1,1,1,1,1,1,1,1,1,1
1,1,1,1,1,1,1,1,1,1,13,11,11,7,11,11,13,1,1,1,1,1,1,1,1,1,1
1,1,1,1,1,1,1,1,1,1,1,16,16,11,16,16,1,1,1,1,1,1,1,1,1,1,1
1,1,1,1,1,1,1,1,1,1,1,16,16,11,16,16,1,1,1,1,1,1,1,1,1,1,1
1,1,1,1,1,1,1,1,1,1,1,1,1,13,1,1,1,1,1,1,1,1,1,1,1,1,1
1,1,1,1,1,1,1,1,1,1,1,1,1,1,1,1,1,1,1,1,1,1,1,1,1,1,1
1,1,1,1,1,1,1,1,1,1,1,1,1,1,1,1,1,1,1,1,1,1,1,1,1,1,1
1,1,1,1,1,1,1,1,1,1,1,1,1,1,1,1,1,1,1,1,1,1,1,1,1,1,1
1,1,1,1,1,1,1,1,1,1,1,1,1,1,1,1,1,1,1,1,1,1,1,1,1,1,1
1,1,1,1,1,1,1,1,1,1,1,1,1,1,1,1,1,1,1,1,1,1,1,1,1,1,1
1,1,1,1,1,1,1,1,1,1,1,1,1,1,1,1,1,1,1,1,1,1,1,1,1,1,1
1,1,1,1,1,1,1,1,1,1,1,1,1,1,1,1,1,1,1,1,1,1,1,1,1,1,1
1,1,1,1,1,1,1,1,1,1,1,1,1,1,1,1,1,1,1,1,1,1,1,1,1,1,1
1,1,1,1,1,1,1,1,1,1,1,1,1,1,1,1,1,1,1,1,1,1,1,1,1,1,1
1,1,1,1,1,1,1,1,1,1,1,1,1,1,1,1,1,1,1,1,1,1,1,1,1,1,1
endlayer

