
# Created by Ruins mod version 16.7 Ingame Parser
# authoring Player: lafuller

weight=1
embed_into_distance=4
acceptable_target_blocks=
unacceptable_target_blocks=flowing_water,water,flowing_lava,lava,ice,bedrock,netherrack,nether_brick,nether_brick_fence,soul_sand,quartz_ore,gravel,end_stone,obsidian,iron_bars,cloud,flesh,ash_block,slime_grass,slime_congealed,slime_dirt
dimensions=16,13,12
allowable_overhang=0
max_leveling=4
leveling_buffer=-1
preserve_water=0
preserve_lava=0

rule1=0,100,preserveBlock
rule2=0,100,air
rule3=0,100,stonebrick-0,stonebrick-1,stonebrick-1,stonebrick-1,stonebrick-2,stonebrick-2,stone-5,stone-5,stone-6,cobblestone,cobblestone
rule4=0,100,minecraft:stone-6
rule5=0,100,stonebrick-0,stonebrick-2,stonebrick-1,stonebrick-1,stonebrick-1,cobblestone
rule6=0,100,stonebrick-0,stonebrick-1,stonebrick-2,stonebrick-2,stone-5,stone-5,stone-6,stone-6
rule7=0,100,stonebrick-0,stonebrick-2,stonebrick-0,stonebrick-1,stonebrick-1,cobblestone
rule8=0,100,minecraft:stone_brick_stairs-0
rule9=0,100,minecraft:stone_brick_stairs-3
rule10=0,100,minecraft:stone_brick_stairs-1
rule11=0,100,stonebrick-0,stonebrick-1,stonebrick-1,stonebrick-1,stonebrick-2,stonebrick-2,stone-5,stone-5,stone-6,cobblestone,cobblestone,gravel
rule12=0,100,minecraft:cobblestone_wall-0
rule13=0,100,minecraft:stone-5
rule14=0,100,minecraft:log-0
rule15=0,100,minecraft:wooden_slab-9
rule16=0,100,minecraft:web-0,air,air,air
rule17=0,100,minecraft:spruce_stairs-2
rule18=0,100,minecraft:planks-1
rule19=0,100,minecraft:stone_brick_stairs-2
rule20=0,100,bookshelf,hay_block,ChestGenHook:chests/spawn_bonus_chest:5-2,ChestGenHook:chests/village_blacksmith:4-2,ChestGenHook:chests/simple_dungeon:5-2,ChestGenHook:chests/abandoned_mineshaft:4-2,ChestGenHook:chests/stronghold_library:3-2,ChestGenHook:chests/stronghold_corridor:2-2,ChestGenHook:chests/stronghold_crossing:2-2,ChestGenHook:chests/igloo_chest:4-2
rule21=0,100,minecraft:wooden_slab-1
rule22=0,100,minecraft:spruce_stairs-6
rule23=0,100,minecraft:stone_brick_stairs-5
rule24=0,100,minecraft:spruce_stairs-3
rule25=0,100,minecraft:stone_brick_stairs-7
rule26=0,100,minecraft:stone_brick_stairs-6
rule27=0,100,minecraft:planks-0
rule28=0,100,minecraft:spruce_stairs-7
rule29=0,100,minecraft:spruce_stairs-5
rule30=0,100,minecraft:oak_stairs-7
rule31=0,100,minecraft:oak_stairs-0
rule32=0,100,minecraft:log2-1
rule33=0,100,minecraft:stone-3
rule34=0,100,minecraft:oak_stairs-2
rule35=0,100,minecraft:oak_stairs-3
rule36=0,100,minecraft:spruce_fence-0
rule37=0,100,minecraft:spruce_fence_gate-0
rule38=0,100,minecraft:oak_stairs-1
rule39=0,100,minecraft:jungle_door-2
rule40=0,100,minecraft:fence-0
rule41=0,100,minecraft:stone_brick_stairs-4
rule42=0,100,minecraft:furnace-5
rule43=0,100,minecraft:oak_stairs-5
rule44=0,100,minecraft:jungle_door-9
rule45=0,100,minecraft:jungle_door-8
rule46=0,100,minecraft:wooden_slab-13
rule47=0,100,minecraft:spruce_stairs-4
rule48=0,100,minecraft:trapdoor-11
rule49=0,100,minecraft:spruce_fence_gate-1
rule50=0,100,minecraft:dark_oak_stairs-2
rule51=0,100,minecraft:dark_oak_stairs-0
rule52=0,100,minecraft:wooden_slab-5
rule53=0,100,minecraft:planks-5
rule54=0,100,minecraft:dark_oak_stairs-6
rule55=0,100,minecraft:dark_oak_stairs-3
rule56=0,100,minecraft:dark_oak_stairs-4
rule57=0,100,minecraft:dark_oak_stairs-5
rule58=0,100,minecraft:dark_oak_stairs-1
rule59=0,100,minecraft:dark_oak_fence-0
rule60=0,100,minecraft:trapdoor-0
rule61=0,100,minecraft:stone_slab-0

layer
1,1,1,1,1,1,1,1,1,1,1,1
1,1,1,3,3,4,3,3,1,1,1,1
1,1,1,3,3,5,5,5,4,1,1,1
1,1,4,5,5,6,6,6,5,3,1,1
1,1,3,5,6,7,7,6,5,3,1,1
1,1,3,5,6,6,7,6,5,3,1,1
1,1,4,5,5,6,7,7,6,5,4,1
1,3,5,5,6,7,7,7,6,5,3,1
1,3,5,5,6,7,7,6,6,5,3,1
1,4,5,5,5,6,6,5,5,4,3,8
1,9,3,3,4,5,5,5,5,3,3,3
2,9,3,3,3,3,10,10,3,3,3,4
1,9,3,4,2,4,1,1,4,1,4,3
endlayer

layer
1,1,1,1,1,1,1,1,1,1,1,1
1,1,1,3,3,13,12,11,1,1,1,1
1,1,1,11,11,15,15,14,13,1,1,1
1,1,13,14,16,2,2,2,16,11,1,1
1,1,11,16,2,2,2,2,2,12,1,1
1,1,12,2,2,2,2,2,2,11,1,1
1,1,13,2,2,2,2,2,16,14,13,1
1,11,17,2,2,2,2,2,2,15,12,1
1,12,18,14,2,2,2,2,2,15,11,1
1,13,20,2,2,2,2,2,16,13,19,1
1,1,11,11,13,14,15,15,14,11,19,8
1,1,9,11,11,11,12,12,11,11,11,11
1,1,9,11,1,11,1,1,11,1,11,11
endlayer

layer
1,1,1,1,1,1,1,1,1,1,1,1
1,1,1,3,3,4,12,11,1,1,1,1
1,1,1,11,11,16,16,14,4,1,1,1
1,1,4,14,16,2,2,2,16,11,1,1
1,1,11,16,2,2,2,2,16,12,1,1
1,1,12,2,2,2,2,2,16,11,1,1
1,1,4,2,2,2,2,2,16,14,4,1
1,11,2,2,2,2,2,2,2,16,12,1
1,12,21,14,2,2,2,2,2,16,11,1
1,4,22,16,2,16,2,2,16,4,1,1
1,1,11,11,4,14,16,16,14,11,1,1
1,1,1,9,11,11,12,12,11,11,19,1
1,1,1,9,23,11,1,1,11,23,19,1
endlayer

layer
1,1,1,1,1,1,1,1,1,1,1,1
1,1,1,3,3,13,12,11,1,1,1,1
1,1,1,11,11,16,16,14,13,1,1,1
1,1,13,14,16,16,16,16,16,11,1,1
1,1,11,16,16,2,2,16,16,12,1,1
1,1,12,16,2,2,2,2,16,11,1,1
1,1,13,2,2,2,2,16,16,14,13,1
1,11,2,2,2,2,2,2,16,16,12,1
1,12,2,14,2,16,2,2,16,16,11,1
1,13,2,24,16,16,16,16,16,13,1,1
1,1,11,11,13,14,16,16,14,11,1,1
1,1,1,1,9,11,12,12,11,19,1,1
1,1,1,1,9,11,26,25,11,19,1,1
endlayer

layer
1,1,1,1,1,1,1,1,1,1,1,1
1,1,1,3,3,4,11,11,1,1,1,1
1,1,1,11,11,18,18,18,4,1,1,1
1,1,4,18,18,27,27,27,18,11,1,1
1,1,11,18,27,18,18,27,18,11,1,1
1,1,11,18,27,27,18,27,18,11,1,1
1,1,4,29,28,27,18,18,27,18,4,1
1,11,2,15,30,18,18,18,27,18,11,1
1,11,2,14,27,18,18,27,27,18,11,1
1,4,2,2,24,27,27,18,18,4,1,1
1,1,11,11,4,18,18,18,18,11,1,1
1,1,1,1,1,11,3,3,11,1,1,1
1,1,1,1,1,9,3,3,19,1,1,1
endlayer

layer
1,1,1,1,1,1,1,1,1,1,1,1
1,1,1,25,11,32,31,31,2,1,1,1
1,1,2,11,23,33,2,2,32,2,1,1
1,1,32,33,2,2,2,2,2,34,1,1
1,1,35,33,2,2,2,2,2,34,1,1
1,1,35,2,2,2,2,2,2,31,1,1
1,2,32,36,2,2,2,2,2,2,32,1
1,35,2,37,2,2,2,2,2,2,34,1
1,35,2,14,2,2,2,2,2,2,34,1
1,32,2,2,2,2,2,2,2,32,2,1
1,2,38,38,32,2,2,2,2,34,1,1
1,1,1,1,2,38,39,39,38,1,1,1
1,1,1,1,1,1,2,2,1,1,1,1
endlayer

layer
1,1,1,1,1,1,1,1,1,1,1,1
1,1,1,9,41,32,2,40,40,1,1,1
1,1,40,11,42,2,2,2,32,40,1,1
1,1,32,2,2,2,2,2,2,40,1,1
1,1,2,2,2,2,2,2,2,2,1,1
1,1,40,2,2,2,2,2,2,40,1,1
1,2,32,2,2,2,2,2,2,2,32,1
1,1,2,2,2,2,2,2,2,2,2,1
1,40,2,14,2,2,2,2,2,2,40,1
1,32,2,2,2,2,2,2,2,32,40,1
1,40,40,2,32,2,2,2,2,40,1,1
1,1,1,1,2,43,45,44,43,1,1,1
1,1,1,1,1,1,2,2,1,1,1,1
endlayer

layer
1,1,1,1,1,1,1,1,1,46,1,1
1,1,1,8,11,32,47,47,22,46,46,1
1,46,28,11,10,2,48,48,32,47,1,1
1,1,32,2,2,2,2,2,2,22,1,1
1,1,28,2,2,2,2,2,2,22,1,1
1,1,28,2,2,2,2,2,2,47,1,1
1,47,32,2,2,2,2,2,2,2,32,1
1,28,2,2,2,2,2,2,2,2,22,1
1,28,2,14,2,2,2,2,2,2,22,1
1,32,2,2,2,2,2,2,2,32,29,1
46,28,29,29,32,2,2,2,2,22,46,46
1,1,1,1,28,18,49,49,18,46,46,1
1,1,1,1,46,1,2,2,1,46,1,1
endlayer

layer
1,1,1,1,1,51,46,46,50,1,1,1
1,1,52,54,8,32,18,18,53,52,1,1
1,1,55,11,26,2,2,2,32,53,52,1
1,51,32,2,2,2,2,2,2,18,46,1
1,46,18,2,2,2,2,2,2,18,46,1
1,56,18,2,2,2,2,2,2,18,53,52
51,53,32,2,2,2,2,2,2,2,32,57
46,18,2,2,2,2,2,2,2,2,18,46
46,18,2,14,2,2,2,2,2,2,18,46
58,32,2,2,2,2,2,2,2,32,53,58
1,53,18,18,32,2,2,2,2,18,50,1
1,52,46,46,53,18,18,18,18,53,58,1
1,1,1,1,55,53,46,46,53,52,1,1
endlayer

layer
1,1,1,1,1,1,51,51,1,1,1,1
1,1,1,1,55,53,53,53,50,1,1,1
1,1,1,11,11,29,29,29,53,52,1,1
1,1,55,29,22,2,2,2,28,50,1,1
1,52,53,22,2,2,2,2,28,53,52,1
1,55,53,22,2,2,2,2,29,53,53,1
1,53,32,22,2,2,2,2,2,28,53,1
55,53,18,22,2,2,2,2,2,28,53,50
52,53,18,14,2,2,2,2,2,28,53,52
1,55,18,22,2,2,2,2,47,32,50,1
1,1,58,53,32,47,47,47,28,50,1,1
1,1,1,52,58,53,53,53,53,1,1,1
1,1,1,1,1,52,58,52,1,1,1,1
endlayer

layer
1,1,1,1,1,1,1,1,1,1,1,1
1,1,1,1,1,1,51,50,1,1,1,1
1,1,1,41,11,55,53,53,52,1,1,1
1,1,1,51,53,22,29,29,50,1,1,1
1,1,52,53,29,15,15,28,53,50,1,1
1,1,51,53,22,2,2,2,18,53,1,1
1,52,53,53,22,2,2,2,29,53,50,1
1,55,53,18,15,2,2,2,28,53,52,1
1,52,53,14,15,15,15,15,47,50,1,1
1,1,58,53,22,47,47,28,53,52,1,1
1,1,1,52,53,53,53,53,58,1,1,1
1,1,1,1,1,52,58,58,1,1,1,1
1,1,1,1,1,1,1,1,1,1,1,1
endlayer

layer
1,1,1,1,1,1,1,1,1,1,1,1
1,1,1,1,1,1,1,1,1,1,1,1
1,1,1,11,8,1,51,52,1,1,1,1
1,1,1,1,52,53,53,53,1,1,1,1
1,1,1,52,53,53,53,53,50,1,1,1
1,1,1,55,53,18,18,18,53,52,1,1
1,1,52,53,53,18,59,18,53,50,1,1
1,1,55,53,53,18,18,18,53,52,1,1
1,1,52,53,53,53,53,53,53,1,1,1
1,1,1,1,55,53,53,50,52,1,1,1
1,1,1,1,1,58,52,1,1,1,1,1
1,1,1,1,1,1,1,1,1,1,1,1
1,1,1,1,1,1,1,1,1,1,1,1
endlayer

layer
1,1,1,1,1,1,1,1,1,1,1,1
1,1,1,1,1,1,1,1,1,1,1,1
1,1,1,23,11,1,1,1,1,1,1,1
1,1,1,1,1,59,59,59,1,1,1,1
1,1,1,1,59,59,52,59,1,1,1,1
1,1,1,1,59,52,52,52,59,1,1,1
1,1,1,59,52,52,60,52,59,1,1,1
1,1,1,59,52,52,52,52,59,1,1,1
1,1,1,59,59,52,59,59,59,1,1,1
1,1,1,1,1,59,59,1,1,1,1,1
1,1,1,1,1,1,1,1,1,1,1,1
1,1,1,1,1,1,1,1,1,1,1,1
1,1,1,1,1,1,1,1,1,1,1,1
endlayer

layer
1,1,1,1,1,1,1,1,1,1,1,1
1,1,1,1,1,1,1,1,1,1,1,1
1,1,1,41,11,1,1,1,1,1,1,1
1,1,1,1,1,1,1,1,1,1,1,1
1,1,1,1,1,1,1,1,1,1,1,1
1,1,1,1,1,1,1,1,1,1,1,1
1,1,1,1,1,1,1,1,1,1,1,1
1,1,1,1,1,1,1,1,1,1,1,1
1,1,1,1,1,1,1,1,1,1,1,1
1,1,1,1,1,1,1,1,1,1,1,1
1,1,1,1,1,1,1,1,1,1,1,1
1,1,1,1,1,1,1,1,1,1,1,1
1,1,1,1,1,1,1,1,1,1,1,1
endlayer

layer
1,1,1,1,1,1,1,1,1,1,1,1
1,1,1,1,1,1,1,1,1,1,1,1
1,1,1,12,12,1,1,1,1,1,1,1
1,1,1,1,1,1,1,1,1,1,1,1
1,1,1,1,1,1,1,1,1,1,1,1
1,1,1,1,1,1,1,1,1,1,1,1
1,1,1,1,1,1,1,1,1,1,1,1
1,1,1,1,1,1,1,1,1,1,1,1
1,1,1,1,1,1,1,1,1,1,1,1
1,1,1,1,1,1,1,1,1,1,1,1
1,1,1,1,1,1,1,1,1,1,1,1
1,1,1,1,1,1,1,1,1,1,1,1
1,1,1,1,1,1,1,1,1,1,1,1
endlayer

layer
1,1,1,1,1,1,1,1,1,1,1,1
1,1,1,1,1,1,1,1,1,1,1,1
1,1,1,61,61,1,1,1,1,1,1,1
1,1,1,1,1,1,1,1,1,1,1,1
1,1,1,1,1,1,1,1,1,1,1,1
1,1,1,1,1,1,1,1,1,1,1,1
1,1,1,1,1,1,1,1,1,1,1,1
1,1,1,1,1,1,1,1,1,1,1,1
1,1,1,1,1,1,1,1,1,1,1,1
1,1,1,1,1,1,1,1,1,1,1,1
1,1,1,1,1,1,1,1,1,1,1,1
1,1,1,1,1,1,1,1,1,1,1,1
1,1,1,1,1,1,1,1,1,1,1,1
endlayer

