
# Created by Ruins mod version 16.7 Ingame Parser
# authoring Player: lafuller

weight=1
embed_into_distance=0
acceptable_target_blocks=
unacceptable_target_blocks=flowing_water,water,flowing_lava,lava
dimensions=5,11,11
allowable_overhang=0
max_leveling=0
leveling_buffer=-1
preserve_water=0
preserve_lava=0

rule1=0,100,minecraft:sandstone-0
rule2=0,100,minecraft:double_stone_slab-9
rule3=0,100,minecraft:planks-2

layer
0,1,0,0,0,0,0,0,0,1,0
1,2,2,2,2,0,0,0,2,2,1
0,2,3,3,3,3,3,3,3,2,0
0,0,3,1,1,1,1,1,3,0,0
0,2,3,1,1,1,1,1,3,0,0
0,2,3,1,1,1,1,1,3,2,0
0,2,3,1,1,1,1,1,3,2,0
0,0,3,1,1,1,1,1,3,2,0
0,2,3,3,3,3,3,3,3,2,0
1,2,2,0,2,2,2,2,2,2,1
0,1,0,0,0,0,0,0,0,1,0
endlayer

layer
0,1,0,0,0,0,0,0,0,1,0
1,2,2,2,2,2,0,0,2,2,1
0,2,3,3,3,3,3,3,3,2,0
0,0,3,1,1,1,1,1,3,0,0
0,0,3,1,1,1,1,1,3,0,0
0,2,3,1,1,1,1,1,3,2,0
0,0,3,1,1,1,1,1,3,2,0
0,2,3,1,1,1,1,1,3,2,0
0,2,3,3,3,3,3,3,3,2,0
1,2,2,0,0,0,0,2,2,2,1
0,1,0,0,0,0,0,0,0,1,0
endlayer

layer
0,1,0,0,0,0,0,0,0,1,0
1,2,2,2,0,2,0,2,2,2,1
0,2,3,3,3,3,3,3,3,2,0
0,2,3,1,1,1,1,1,3,2,0
0,2,3,1,1,1,1,1,3,2,0
0,0,3,1,1,1,1,1,3,0,0
0,0,3,1,1,1,1,1,3,0,0
0,2,3,1,1,1,1,1,3,2,0
0,2,3,3,3,3,3,3,3,2,0
1,2,2,0,0,2,0,0,2,2,1
0,1,0,0,0,0,0,0,0,1,0
endlayer

layer
0,1,0,0,0,0,0,0,0,1,0
1,2,2,2,0,0,2,2,2,2,1
0,2,3,3,3,3,3,3,3,2,0
0,2,3,1,1,1,1,1,3,2,0
0,0,3,1,1,1,1,1,3,0,0
0,0,3,1,1,1,1,1,3,0,0
0,2,3,1,1,1,1,1,3,0,0
0,2,3,1,1,1,1,1,3,2,0
0,2,3,3,3,3,3,3,3,2,0
1,2,2,2,0,2,2,2,2,2,1
0,1,0,0,0,0,0,0,0,1,0
endlayer

layer
0,1,0,0,0,0,0,0,0,1,0
1,2,2,2,2,2,2,2,2,2,1
0,2,3,3,3,3,3,3,3,2,0
0,2,3,1,1,1,1,1,3,2,0
0,2,3,1,1,1,1,1,3,2,0
0,2,3,1,1,1,1,1,3,2,0
0,2,3,1,1,1,1,1,3,2,0
0,2,3,1,1,1,1,1,3,2,0
0,2,3,3,3,3,3,3,3,2,0
1,2,2,2,2,2,2,2,2,2,1
0,1,0,0,0,0,0,0,0,1,0
endlayer

