
# Created by Ruins mod version 16.7 Ingame Parser
# authoring Player: lafuller

weight=1
embed_into_distance=35
random_height_offset=-3,3
acceptable_target_blocks=
unacceptable_target_blocks=flowing_lava,lava,ice,bedrock,netherrack,nether_brick,nether_brick_fence,soul_sand,quartz_ore,end_stone,obsidian,iron_bars,cloud,flesh,ash_block,slime_grass,slime_congealed,slime_dirt
dimensions=30,17,17
allowable_overhang=0
max_leveling=80
leveling_buffer=-1
preserve_water=0
preserve_lava=0

rule1=0,100,preserveBlock
rule2=0,100,stonebrick-0,stonebrick-1,stonebrick-1,stonebrick-2,stonebrick-2,stonebrick-3,stone-5,stone-5,stone-6,stone-6,cobblestone
rule3=0,100,minecraft:stone_slab-5
rule4=0,100,minecraft:double_stone_slab-5
rule5=0,100,minecraft:stone_brick_stairs-2
rule6=0,100,minecraft:stone_brick_stairs-0
rule7=0,100,stonebrick-0,stonebrick-1,stonebrick-1,stonebrick-1,stonebrick-2,stonebrick-2,stonebrick-3,stone-5,stone-6,cobblestone,cobblestone
rule8=0,100,minecraft:stone_slab-8
rule9=0,100,minecraft:stone_brick_stairs-3
rule10=0,100,minecraft:stone_brick_stairs-1
rule11=0,100,sponge-0,diamond_ore-0,lapis_block-0,gold_block-0,emerald_block-0,iron_block-0,coal_block-0,gold_ore-0,redstone_ore-0,lapis_ore-0,emerald_ore-0,lapis_block-0,gold_block-0,gold_ore-0,redstone_ore-0,lapis_ore-0,emerald_ore-0
rule12=0,100,minecraft:ladder-2
rule13=0,100,minecraft:ladder-5
rule14=0,100,minecraft:ladder-4
rule15=0,100,minecraft:ladder-3
rule16=0,100,minecraft:stone_brick_stairs-4
rule17=0,100,minecraft:stone_brick_stairs-5
rule18=0,100,minecraft:stone_brick_stairs-7
rule19=0,100,minecraft:stone_brick_stairs-6
rule20=0,100,minecraft:iron_bars-0
rule21=0,100,minecraft:stone_slab-13

layer
1,1,2,2,2,3,3,2,2,2,1,1,1,1,1,1,1
1,1,2,2,2,2,2,2,2,2,2,2,2,1,1,1,1
1,1,2,2,2,2,2,2,2,2,2,2,2,2,2,2,2
1,1,2,2,2,2,2,2,2,2,2,2,2,2,2,2,2
1,2,2,2,2,2,2,2,2,2,2,2,2,2,2,2,2
1,2,2,2,2,2,2,2,2,2,2,2,2,2,2,2,3
1,2,2,2,2,2,2,2,2,2,2,2,2,2,2,2,3
2,2,2,2,2,2,2,2,2,2,2,2,2,2,2,2,2
2,2,2,2,2,2,2,2,2,2,2,2,2,2,2,2,2
2,2,2,2,2,2,2,2,2,2,2,2,2,2,2,2,2
3,2,2,2,2,2,2,2,2,2,2,2,2,2,2,2,1
3,2,2,2,2,2,2,2,2,2,2,2,2,2,2,2,1
2,2,2,2,2,2,2,2,2,2,2,2,2,2,2,2,1
2,2,2,2,2,2,2,2,2,2,2,2,2,2,2,1,1
2,2,2,2,2,2,2,2,2,2,2,2,2,2,2,1,1
1,1,1,1,2,2,2,2,2,2,2,2,2,2,2,1,1
1,1,1,1,1,1,1,2,2,2,3,3,2,2,2,1,1
endlayer

layer
1,1,2,2,2,0,0,0,3,2,1,1,1,1,1,1,1
1,1,2,2,2,2,2,2,4,2,2,2,2,1,1,1,1
1,1,2,2,2,2,2,2,2,2,2,2,2,2,2,2,2
1,1,2,2,0,2,2,2,2,2,0,2,2,2,2,2,2
1,2,2,2,0,2,0,2,2,2,0,2,0,0,2,2,2
1,2,2,2,2,2,0,2,0,2,2,2,2,2,2,2,0
1,2,2,0,0,2,2,2,0,2,2,0,0,2,2,2,0
2,2,2,2,2,2,2,2,2,2,2,2,2,2,2,2,0
3,4,2,2,2,0,0,2,2,2,0,0,2,2,2,2,3
0,2,2,2,2,2,2,2,2,2,2,2,2,2,2,2,2
0,2,2,2,0,0,2,2,0,2,2,2,0,0,2,2,1
0,2,2,2,2,2,2,2,0,2,0,2,2,2,2,2,1
2,2,2,0,0,2,0,2,2,2,0,2,0,2,2,2,1
2,2,2,2,2,2,0,2,2,2,2,2,0,2,2,1,1
2,2,2,2,2,2,2,2,2,2,2,2,2,2,2,1,1
1,1,1,1,2,2,2,2,3,2,2,2,2,2,2,1,1
1,1,1,1,1,1,1,2,3,0,0,0,2,2,2,1,1
endlayer

layer
1,1,2,2,2,0,0,0,0,0,1,1,1,1,1,1,1
1,1,2,2,2,2,2,5,0,0,3,2,2,1,1,1,1
1,1,2,7,7,7,7,6,6,6,6,2,2,2,2,2,2
1,1,2,7,8,7,7,7,7,7,8,7,7,7,7,2,2
1,2,2,7,8,7,8,7,7,7,8,7,8,8,7,2,2
1,2,2,7,7,7,8,7,8,7,7,7,7,7,7,2,0
1,3,9,8,8,7,7,7,8,7,7,8,8,7,7,2,0
0,0,9,7,7,7,7,10,10,10,7,7,7,7,5,10,0
0,0,9,7,7,8,8,5,11,9,8,8,7,7,5,0,0
0,6,9,7,7,7,7,6,6,6,7,7,7,7,5,0,0
0,2,7,7,8,8,7,7,8,7,7,7,8,8,5,3,1
0,2,7,7,7,7,7,7,8,7,8,7,7,7,2,2,1
2,2,7,8,8,7,8,7,7,7,8,7,8,7,2,2,1
2,2,7,7,7,7,8,7,7,7,7,7,8,7,2,1,1
2,2,2,2,2,2,10,10,10,10,7,7,7,7,2,1,1
1,1,1,1,2,2,3,0,0,9,2,2,2,2,2,1,1
1,1,1,1,1,1,1,0,0,0,0,0,2,2,2,1,1
endlayer

layer
1,1,2,2,2,0,0,0,0,0,1,1,1,1,1,1,1
1,1,2,2,2,2,3,0,0,0,0,0,3,1,1,1,1
1,1,2,0,0,0,0,0,0,0,0,0,3,2,2,2,2
1,1,2,0,0,0,0,0,0,0,0,0,0,0,0,2,2
1,3,3,0,0,0,0,0,0,0,0,0,0,0,0,2,2
1,0,0,0,0,0,0,0,0,0,0,0,0,0,0,2,0
1,0,0,0,0,0,0,0,0,0,0,0,0,0,0,3,0
0,0,0,0,0,0,0,0,0,0,0,0,0,0,0,0,0
0,0,0,0,0,0,0,0,0,0,0,0,0,0,0,0,0
0,0,0,0,0,0,0,0,0,0,0,0,0,0,0,0,0
0,3,0,0,0,0,0,0,0,0,0,0,0,0,0,0,1
0,2,0,0,0,0,0,0,0,0,0,0,0,0,0,0,1
2,2,0,0,0,0,0,0,0,0,0,0,0,0,3,3,1
2,2,0,0,0,0,0,0,0,0,0,0,0,0,2,1,1
2,2,2,2,3,0,0,0,0,0,0,0,0,0,2,1,1
1,1,1,1,3,0,0,0,0,0,3,2,2,2,2,1,1
1,1,1,1,1,1,1,0,0,0,0,0,2,2,2,1,1
endlayer

layer
1,1,2,2,2,0,0,0,0,0,1,1,1,1,1,1,1
1,1,2,2,3,0,0,0,0,0,0,0,0,1,1,1,1
1,1,3,0,0,0,0,0,0,0,0,0,0,0,3,2,2
1,1,0,0,0,0,0,0,0,0,0,0,0,0,0,2,2
1,0,0,0,0,0,0,0,0,0,0,0,0,0,0,3,2
1,0,0,0,0,0,0,0,0,0,0,0,0,0,0,0,0
1,0,0,0,0,0,0,0,0,0,0,0,0,0,0,0,0
0,0,0,0,0,0,0,0,0,0,0,0,0,0,0,0,0
0,0,0,0,0,0,0,0,0,0,0,0,0,0,0,0,0
0,0,0,0,0,0,0,0,0,0,0,0,0,0,0,0,0
0,0,0,0,0,0,0,0,0,0,0,0,0,0,0,0,1
0,0,0,0,0,0,0,0,0,0,0,0,0,0,0,0,1
2,3,0,0,0,0,0,0,0,0,0,0,0,0,0,0,1
2,2,0,0,0,0,0,0,0,0,0,0,0,0,0,1,1
2,2,3,0,0,0,0,0,0,0,0,0,0,0,3,1,1
1,1,1,1,0,0,0,0,0,0,0,0,3,2,2,1,1
1,1,1,1,1,1,1,0,0,0,0,0,2,2,2,1,1
endlayer

layer
1,1,2,12,2,0,0,0,0,0,1,1,1,1,1,1,1
1,1,0,0,0,0,0,0,0,0,0,0,0,1,1,1,1
1,1,0,0,0,0,0,0,0,0,0,0,0,0,0,0,2
1,1,0,0,0,0,0,0,0,0,0,0,0,0,0,0,13
1,0,0,0,0,0,0,0,0,0,0,0,0,0,0,0,2
1,0,0,0,0,0,0,0,0,0,0,0,0,0,0,0,0
1,0,0,0,0,0,0,0,0,0,0,0,0,0,0,0,0
0,0,0,0,0,0,0,0,0,0,0,0,0,0,0,0,0
0,0,0,0,0,0,0,0,0,0,0,0,0,0,0,0,0
0,0,0,0,0,0,0,0,0,0,0,0,0,0,0,0,0
0,0,0,0,0,0,0,0,0,0,0,0,0,0,0,0,1
0,0,0,0,0,0,0,0,0,0,0,0,0,0,0,0,1
2,0,0,0,0,0,0,0,0,0,0,0,0,0,0,0,1
14,0,0,0,0,0,0,0,0,0,0,0,0,0,0,1,1
2,0,0,0,0,0,0,0,0,0,0,0,0,0,0,1,1
1,1,1,1,0,0,0,0,0,0,0,0,0,0,0,1,1
1,1,1,1,1,1,1,0,0,0,0,0,2,15,2,1,1
endlayer

layer
1,1,2,12,2,0,0,0,0,0,1,1,1,1,1,1,1
1,1,0,0,0,0,0,0,0,0,0,0,0,1,1,1,1
1,1,0,0,0,0,0,0,0,0,0,0,0,0,0,0,2
1,1,0,0,0,0,0,0,0,0,0,0,0,0,0,0,13
1,0,0,0,0,0,0,0,0,0,0,0,0,0,0,0,2
1,0,0,0,0,0,0,0,0,0,0,0,0,0,0,0,0
1,0,0,0,0,0,0,0,0,0,0,0,0,0,0,0,0
0,0,0,0,0,0,0,0,0,0,0,0,0,0,0,0,0
0,0,0,0,0,0,0,0,0,0,0,0,0,0,0,0,0
0,0,0,0,0,0,0,0,0,0,0,0,0,0,0,0,0
0,0,0,0,0,0,0,0,0,0,0,0,0,0,0,0,1
0,0,0,0,0,0,0,0,0,0,0,0,0,0,0,0,1
2,0,0,0,0,0,0,0,0,0,0,0,0,0,0,0,1
14,0,0,0,0,0,0,0,0,0,0,0,0,0,0,1,1
2,0,0,0,0,0,0,0,0,0,0,0,0,0,0,1,1
1,1,1,1,0,0,0,0,0,0,0,0,0,0,0,1,1
1,1,1,1,1,1,1,0,0,0,0,0,2,15,2,1,1
endlayer

layer
1,1,2,12,2,0,0,0,0,0,1,1,1,1,1,1,1
1,1,0,0,0,0,0,0,0,0,0,0,0,1,1,1,1
1,1,0,0,0,0,0,0,0,0,0,0,0,0,0,0,2
1,1,0,0,0,0,0,0,0,0,0,0,0,0,0,0,13
1,0,0,0,0,0,0,0,0,0,0,0,0,0,0,0,2
1,0,0,0,0,0,0,0,0,0,0,0,0,0,0,0,0
1,0,0,0,0,0,0,0,0,0,0,0,0,0,0,0,0
0,0,0,0,0,0,0,0,0,0,0,0,0,0,0,0,0
0,0,0,0,0,0,0,0,0,0,0,0,0,0,0,0,0
0,0,0,0,0,0,0,0,0,0,0,0,0,0,0,0,0
0,0,0,0,0,0,0,0,0,0,0,0,0,0,0,0,1
0,0,0,0,0,0,0,0,0,0,0,0,0,0,0,0,1
2,0,0,0,0,0,0,0,0,0,0,0,0,0,0,0,1
14,0,0,0,0,0,0,0,0,0,0,0,0,0,0,1,1
2,0,0,0,0,0,0,0,0,0,0,0,0,0,0,1,1
1,1,1,1,0,0,0,0,0,0,0,0,0,0,0,1,1
1,1,1,1,1,1,1,0,0,0,0,0,2,15,2,1,1
endlayer

layer
1,1,2,12,2,0,0,0,0,0,1,1,1,1,1,1,1
1,1,0,0,0,0,0,0,0,0,0,0,0,1,1,1,1
1,1,0,0,0,0,0,0,0,0,0,0,0,0,0,0,2
1,1,0,0,0,0,0,0,0,0,0,0,0,0,0,0,13
1,0,0,0,0,0,0,0,0,0,0,0,0,0,0,0,2
1,0,0,0,0,0,0,0,0,0,0,0,0,0,0,0,0
1,0,0,0,0,0,0,0,0,0,0,0,0,0,0,0,0
0,0,0,0,0,0,0,0,0,0,0,0,0,0,0,0,0
0,0,0,0,0,0,0,0,0,0,0,0,0,0,0,0,0
0,0,0,0,0,0,0,0,0,0,0,0,0,0,0,0,0
0,0,0,0,0,0,0,0,0,0,0,0,0,0,0,0,1
0,0,0,0,0,0,0,0,0,0,0,0,0,0,0,0,1
2,0,0,0,0,0,0,0,0,0,0,0,0,0,0,0,1
14,0,0,0,0,0,0,0,0,0,0,0,0,0,0,1,1
2,0,0,0,0,0,0,0,0,0,0,0,0,0,0,1,1
1,1,1,1,0,0,0,0,0,0,0,0,0,0,0,1,1
1,1,1,1,1,1,1,0,0,0,0,0,2,15,2,1,1
endlayer

layer
1,1,2,12,2,0,0,0,0,0,1,1,1,1,1,1,1
1,1,0,2,0,0,0,0,0,0,0,0,0,1,1,1,1
1,1,0,0,0,0,0,0,0,0,0,0,0,0,0,0,2
1,1,0,0,0,0,0,0,0,0,0,0,0,0,0,2,13
1,0,0,0,0,0,0,0,0,0,0,0,0,0,0,0,2
1,0,0,0,0,0,0,0,0,0,0,0,0,0,0,0,0
1,0,0,0,0,0,0,0,0,0,0,0,0,0,0,0,0
0,0,0,0,0,0,0,0,0,0,0,0,0,0,0,0,0
0,0,0,0,0,0,0,0,0,0,0,0,0,0,0,0,0
0,0,0,0,0,0,0,0,0,0,0,0,0,0,0,0,0
0,0,0,0,0,0,0,0,0,0,0,0,0,0,0,0,1
0,0,0,0,0,0,0,0,0,0,0,0,0,0,0,0,1
2,0,0,0,0,0,0,0,0,0,0,0,0,0,0,0,1
14,2,0,0,0,0,0,0,0,0,0,0,0,0,0,1,1
2,0,0,0,0,0,0,0,0,0,0,0,0,0,0,1,1
1,1,1,1,0,0,0,0,0,0,0,0,0,2,0,1,1
1,1,1,1,1,1,1,0,0,0,0,0,2,15,2,1,1
endlayer

layer
2,1,2,12,2,0,2,0,2,0,2,1,2,1,2,1,2
1,2,0,2,0,2,0,0,0,0,0,0,0,1,1,2,1
2,1,2,0,0,0,0,0,0,0,0,0,0,2,2,0,2
1,1,0,0,0,0,0,0,0,0,0,0,0,0,0,2,13
2,0,0,0,0,0,0,0,0,0,0,0,0,0,0,2,2
1,0,0,0,0,0,0,0,0,0,0,0,0,0,0,2,0
2,0,0,0,0,0,0,0,0,0,0,0,0,0,0,0,2
0,0,0,0,0,0,0,0,0,0,0,0,0,0,0,0,0
2,0,0,0,0,0,0,0,0,0,0,0,0,0,0,0,2
0,0,0,0,0,0,0,0,0,0,0,0,0,0,0,0,0
2,0,0,0,0,0,0,0,0,0,0,0,0,0,0,0,2
0,2,0,0,0,0,0,0,0,0,0,0,0,0,0,0,1
2,0,0,0,0,0,0,0,0,0,0,0,0,0,0,0,2
14,2,0,0,0,0,0,0,0,0,0,0,0,0,0,1,1
2,0,0,0,0,0,0,0,0,0,0,0,0,0,0,1,2
1,2,1,1,0,0,0,0,0,0,0,2,0,2,0,2,1
2,1,2,1,2,1,2,0,2,0,2,0,2,15,2,1,2
endlayer

layer
2,1,2,12,0,2,2,0,2,0,2,2,2,2,2,1,2
1,2,2,2,0,2,0,2,0,2,0,2,0,1,1,2,1
2,2,2,0,0,0,0,0,0,0,0,0,0,2,2,0,2
2,2,0,0,0,0,0,0,0,0,0,0,0,0,0,2,13
2,0,0,0,0,0,0,0,0,0,0,0,0,0,0,0,0
2,2,0,0,0,0,0,0,0,0,0,0,0,0,0,2,2
2,0,0,0,0,0,0,0,0,0,0,0,0,0,0,0,2
0,2,0,0,0,0,0,0,0,0,0,0,0,0,0,2,0
2,0,0,0,0,0,0,0,0,0,0,0,0,0,0,0,2
0,2,0,0,0,0,0,0,0,0,0,0,0,0,0,2,0
2,0,0,0,0,0,0,0,0,0,0,0,0,0,0,0,2
2,2,0,0,0,0,0,0,0,0,0,0,0,0,0,2,2
0,0,0,0,0,0,0,0,0,0,0,0,0,0,0,0,2
14,2,0,0,0,0,0,0,0,0,0,0,0,0,0,2,2
2,0,2,0,0,0,0,0,0,0,0,0,0,0,2,0,2
1,2,0,2,0,2,0,2,0,2,0,2,0,2,2,2,1
2,1,2,2,2,2,2,0,2,0,2,2,0,15,2,1,2
endlayer

layer
2,2,2,12,0,2,0,2,2,2,0,2,0,2,2,2,2
2,2,2,2,0,2,0,2,0,2,0,2,0,2,2,2,2
2,2,2,0,0,0,0,0,0,0,0,0,0,0,2,2,2
2,2,0,0,0,0,0,0,0,0,0,0,0,0,0,2,13
0,0,0,0,0,0,0,0,0,0,0,0,0,0,0,0,0
2,2,0,0,0,0,0,0,0,0,0,0,0,0,0,2,2
0,0,0,0,0,0,0,0,0,0,0,0,0,0,0,0,0
2,2,0,0,0,0,0,0,0,0,0,0,0,0,0,2,2
2,0,0,0,0,0,0,0,0,0,0,0,0,0,0,0,2
2,2,0,0,0,0,0,0,0,0,0,0,0,0,0,2,2
0,0,0,0,0,0,0,0,0,0,0,0,0,0,0,0,0
2,2,0,0,0,0,0,0,0,0,0,0,0,0,0,2,2
0,0,0,0,0,0,0,0,0,0,0,0,0,0,0,0,0
14,2,0,0,0,0,0,0,0,0,0,0,0,0,0,2,2
2,2,2,0,0,0,0,0,0,0,0,0,0,0,2,2,2
2,2,2,2,0,2,0,2,0,2,0,2,0,2,2,2,2
2,2,2,2,0,2,0,2,2,2,0,2,0,15,2,2,2
endlayer

layer
0,0,0,0,0,2,0,2,0,2,0,2,0,2,5,0,0
0,0,0,9,2,2,0,2,0,2,0,2,2,2,5,0,0
6,6,6,2,2,0,0,0,0,0,0,0,2,0,5,0,0
2,2,2,0,0,0,0,0,0,0,0,0,0,0,2,6,0
0,2,2,0,0,0,0,0,0,0,0,0,0,0,2,0,0
2,2,0,0,0,0,0,0,0,0,0,0,0,0,0,2,2
0,0,0,0,0,0,0,0,0,0,0,0,0,0,0,0,0
2,2,0,0,0,0,0,0,0,0,0,0,0,0,0,2,2
0,0,0,0,0,0,0,0,0,0,0,0,0,0,0,0,0
2,2,0,0,0,0,0,0,0,0,0,0,0,0,0,2,2
0,0,0,0,0,0,0,0,0,0,0,0,0,0,0,0,0
2,2,0,0,0,0,0,0,0,0,0,0,0,0,0,2,2
0,2,2,0,0,0,0,0,0,0,0,0,0,0,2,2,0
0,10,2,0,0,0,0,0,0,0,0,0,0,0,2,2,2
0,0,9,2,2,0,0,0,0,0,0,0,2,2,10,10,10
0,0,9,2,2,2,0,2,0,2,0,2,2,5,0,0,0
0,0,9,2,0,2,0,2,0,2,0,2,0,0,0,0,0
endlayer

layer
0,0,0,0,2,2,0,2,0,2,0,2,2,5,0,0,0
0,0,0,0,9,2,2,2,0,2,2,2,2,5,0,0,0
0,0,0,2,2,0,2,0,0,0,2,0,2,5,0,0,0
6,6,6,2,0,0,0,0,0,0,0,0,0,2,2,0,0
2,2,2,0,2,0,0,0,0,0,0,0,2,0,2,6,2
2,2,0,0,0,0,0,0,0,0,0,0,0,0,0,2,2
0,2,2,0,0,0,0,0,0,0,0,0,0,0,2,2,0
2,2,0,0,0,0,0,0,0,0,0,0,0,0,0,2,2
0,0,0,0,0,0,0,0,0,0,0,0,0,0,0,0,0
2,2,0,0,0,0,0,0,0,0,0,0,0,0,0,2,2
0,2,2,0,0,0,0,0,0,0,0,0,0,0,2,2,0
2,2,0,0,0,0,0,0,0,0,0,0,0,0,0,2,2
2,10,2,0,2,0,0,0,0,0,0,0,2,0,2,2,2
0,0,2,2,0,0,0,0,0,0,0,0,0,2,10,10,10
0,0,0,9,2,0,2,0,0,0,2,0,2,2,0,0,0
0,0,0,9,2,2,2,2,0,2,2,2,5,0,0,0,0
0,0,0,9,2,2,0,2,0,2,0,2,2,0,0,0,0
endlayer

layer
0,0,0,0,2,0,2,2,0,2,2,0,2,0,0,0,0
0,0,0,0,0,0,2,2,2,2,2,0,2,0,0,0,0
0,0,0,2,6,0,2,0,2,0,2,0,5,0,0,0,0
0,0,0,2,0,0,2,0,0,0,2,0,2,2,2,0,0
2,2,6,2,2,0,0,0,0,0,0,0,2,0,5,0,2
0,0,0,0,0,0,0,2,0,2,0,0,0,0,0,0,0
2,2,2,2,0,0,0,0,0,0,0,0,0,2,2,2,2
2,2,0,0,0,2,0,0,0,0,0,2,0,0,0,2,2
0,2,2,0,0,0,0,0,0,0,0,0,0,0,2,2,0
2,2,0,0,0,2,0,0,0,0,0,2,0,0,0,2,2
2,2,2,2,0,0,0,0,0,0,0,0,0,2,2,2,2
0,0,0,0,0,0,0,2,0,2,0,0,0,0,0,0,0
2,0,9,0,2,0,0,0,0,0,0,0,2,0,5,2,2
0,0,2,2,2,0,2,0,0,0,2,0,0,2,0,0,0
0,0,0,0,9,0,2,0,2,0,2,0,10,2,0,0,0
0,0,0,0,2,0,2,2,2,2,2,0,0,0,0,0,0
0,0,0,0,2,0,2,2,0,2,2,0,2,0,0,0,0
endlayer

layer
0,0,0,0,2,0,2,0,2,0,2,0,2,0,0,0,0
0,0,0,0,0,0,2,0,2,0,2,0,2,0,0,0,0
0,0,0,2,0,0,2,0,2,0,2,0,0,0,0,0,0
0,0,0,2,6,0,2,0,2,0,2,0,6,2,2,0,0
2,2,0,9,2,2,0,2,0,2,0,2,2,5,0,0,2
0,0,0,16,2,0,0,2,0,2,0,0,2,0,0,0,0
2,2,2,2,0,0,2,0,0,0,2,0,0,2,2,2,2
0,0,0,0,2,2,0,0,0,0,0,2,2,0,0,0,0
2,2,2,2,0,0,0,0,0,0,0,0,0,2,2,2,2
0,0,0,0,2,2,0,0,0,0,0,2,2,0,0,0,0
2,2,2,2,0,0,2,0,0,0,2,0,0,2,2,2,2
0,0,0,0,2,0,0,2,0,2,0,0,2,0,0,0,0
2,0,0,9,2,2,0,2,0,2,0,2,2,5,0,2,2
0,0,2,2,10,0,2,0,2,0,2,0,10,2,0,0,0
0,0,0,0,0,0,2,0,2,0,2,0,0,2,0,0,0
0,0,0,0,2,0,2,0,2,0,2,0,0,0,0,0,0
0,0,0,0,2,0,2,0,2,0,2,0,2,0,0,0,0
endlayer

layer
0,0,0,0,2,0,2,0,2,0,2,0,2,0,0,0,0
0,0,0,0,0,0,2,0,2,0,2,0,2,0,0,0,0
0,0,0,2,0,2,2,0,2,0,2,2,0,0,0,0,0
0,0,0,2,0,9,2,2,2,2,2,5,0,2,2,0,0
2,2,0,0,0,9,2,2,2,2,2,5,0,0,0,0,2
0,0,2,6,6,6,2,2,2,2,2,6,6,6,2,0,0
2,2,2,2,2,2,2,2,17,2,2,2,2,2,2,2,2
0,0,0,2,2,2,2,0,0,0,2,2,2,2,0,0,0
2,2,2,2,2,2,19,0,0,0,18,2,2,2,2,2,2
0,0,0,2,2,2,2,0,0,0,2,2,2,2,0,0,0
2,2,2,2,2,2,2,2,16,2,2,2,2,2,2,2,2
0,0,2,10,10,10,2,2,2,2,2,10,10,10,2,0,0
2,0,0,0,0,9,2,2,2,2,2,5,0,0,0,2,2
0,0,2,2,0,9,2,2,2,2,2,5,0,2,0,0,0
0,0,0,0,0,2,2,0,2,0,2,2,0,2,0,0,0
0,0,0,0,2,0,2,0,2,0,2,0,0,0,0,0,0
0,0,0,0,2,0,2,0,2,0,2,0,2,0,0,0,0
endlayer

layer
0,0,0,0,2,0,2,0,2,0,2,0,2,0,0,0,0
0,0,0,2,0,2,2,0,2,0,2,2,2,2,0,0,0
0,0,2,2,0,2,2,2,2,2,2,2,0,2,2,0,0
0,2,2,2,0,0,9,2,2,2,5,0,0,2,2,2,0
2,2,0,0,0,0,9,2,2,2,5,0,0,0,0,0,2
0,2,2,0,0,0,9,2,2,2,5,0,0,0,2,2,0
2,2,2,6,6,6,6,2,2,2,5,6,6,6,2,2,2
0,2,2,2,2,2,2,20,20,20,2,2,2,2,2,0,0
2,2,2,2,2,2,2,20,0,20,2,2,2,2,2,2,2
0,2,2,2,2,2,2,20,20,20,2,2,2,2,2,0,0
2,2,2,10,10,10,10,2,2,2,10,10,10,10,2,2,2
0,2,2,0,0,0,9,2,2,2,5,0,0,0,2,2,0
2,0,0,0,0,0,9,2,2,2,5,0,0,0,0,2,2
0,2,2,2,0,0,9,2,2,2,5,0,0,2,0,0,0
0,0,2,2,0,2,2,2,2,2,2,2,0,2,0,0,0
0,0,0,2,2,2,2,0,2,0,2,2,0,0,0,0,0
0,0,0,0,2,0,2,0,2,0,2,0,2,0,0,0,0
endlayer

layer
2,2,2,2,2,2,2,0,2,0,2,2,2,2,2,2,2
2,2,2,2,0,2,0,2,0,2,0,2,2,2,2,2,2
2,2,2,2,0,0,0,0,0,0,0,0,0,2,2,2,2
2,2,2,0,0,0,0,0,0,0,0,0,0,0,2,2,2
2,0,0,0,0,0,0,0,0,0,0,0,0,0,0,0,2
2,2,0,0,0,0,0,0,0,0,0,0,0,0,0,2,2
2,0,0,0,0,0,0,0,0,0,0,0,0,0,0,0,2
0,2,0,0,0,0,0,0,0,0,0,0,0,0,0,2,0
2,0,0,0,0,0,0,0,0,0,0,0,0,0,0,0,2
0,2,0,0,0,0,0,0,0,0,0,0,0,0,0,2,0
2,0,0,0,0,0,0,0,0,0,0,0,0,0,0,0,2
2,2,0,0,0,0,0,0,0,0,0,0,0,0,0,2,2
2,0,0,0,0,0,0,0,0,0,0,0,0,0,0,2,2
2,2,2,0,0,0,0,0,0,0,0,0,0,0,2,2,2
2,2,2,2,0,0,0,0,0,0,0,0,0,2,2,2,2
2,2,2,2,2,2,0,2,0,2,0,2,2,2,2,2,2
2,2,2,2,2,2,2,0,2,0,2,2,2,2,2,2,2
endlayer

layer
1,1,1,1,0,2,2,2,2,2,2,2,0,1,1,1,1
1,1,2,2,0,2,0,2,0,0,0,2,0,2,2,1,1
1,2,2,2,0,0,0,0,0,0,0,0,0,2,2,2,1
1,2,2,0,0,0,0,0,0,0,0,0,0,0,0,2,1
0,0,0,0,0,0,0,0,0,0,0,0,0,0,0,0,0
2,2,0,0,0,0,0,0,0,0,0,0,0,0,0,2,2
2,0,0,0,0,0,0,0,0,0,0,0,0,0,0,0,2
2,0,0,0,0,0,0,0,0,0,0,0,0,0,0,2,2
2,0,0,0,0,0,0,0,0,0,0,0,0,0,0,0,2
2,2,0,0,0,0,0,0,0,0,0,0,0,0,0,0,2
2,0,0,0,0,0,0,0,0,0,0,0,0,0,0,0,2
2,2,0,0,0,0,0,0,0,0,0,0,0,0,0,2,2
0,0,0,0,0,0,0,0,0,0,0,0,0,0,0,0,0
1,2,2,0,0,0,0,0,0,0,0,0,0,0,2,2,1
1,2,2,2,0,0,0,0,0,0,0,0,0,0,2,2,1
1,1,2,2,0,2,0,0,0,2,0,2,0,2,2,1,1
1,1,1,1,0,2,2,2,2,2,2,2,0,1,1,1,1
endlayer

layer
1,1,1,1,0,2,0,2,2,2,0,2,0,1,1,1,1
1,1,2,2,0,2,0,0,0,0,0,2,0,2,2,1,1
1,2,2,2,0,0,0,0,0,0,0,0,0,0,2,2,1
1,2,2,0,0,0,0,0,0,0,0,0,0,0,0,2,1
0,0,0,0,0,0,0,0,0,0,0,0,0,0,0,0,0
2,2,0,0,0,0,0,0,0,0,0,0,0,0,0,2,2
0,0,0,0,0,0,0,0,0,0,0,0,0,0,0,0,0
2,0,0,0,0,0,0,0,0,0,0,0,0,0,0,0,2
2,0,0,0,0,0,0,0,0,0,0,0,0,0,0,0,2
2,0,0,0,0,0,0,0,0,0,0,0,0,0,0,0,2
0,0,0,0,0,0,0,0,0,0,0,0,0,0,0,0,0
2,2,0,0,0,0,0,0,0,0,0,0,0,0,0,2,2
0,0,0,0,0,0,0,0,0,0,0,0,0,0,0,0,0
1,2,0,0,0,0,0,0,0,0,0,0,0,0,0,2,1
1,2,2,2,0,0,0,0,0,0,0,0,0,0,2,2,1
1,1,2,2,0,2,0,0,0,0,0,2,0,2,2,1,1
1,1,1,1,0,2,0,2,2,2,0,2,0,1,1,1,1
endlayer

layer
1,1,1,1,2,2,0,2,0,2,0,2,2,1,1,1,1
1,1,2,2,2,2,0,0,0,0,0,2,2,2,2,1,1
1,2,2,2,0,0,0,0,0,0,0,0,0,0,2,2,1
1,2,2,0,0,0,0,0,0,0,0,0,0,0,0,2,1
2,2,0,0,0,0,0,0,0,0,0,0,0,0,0,2,2
2,2,0,0,0,0,0,0,0,0,0,0,0,0,0,2,2
0,0,0,0,0,0,0,0,0,0,0,0,0,0,0,0,0
2,0,0,0,0,0,0,0,0,0,0,0,0,0,0,0,2
0,0,0,0,0,0,0,0,0,0,0,0,0,0,0,0,0
2,0,0,0,0,0,0,0,0,0,0,0,0,0,0,0,2
0,0,0,0,0,0,0,0,0,0,0,0,0,0,0,0,0
2,2,0,0,0,0,0,0,0,0,0,0,0,0,0,2,2
2,2,0,0,0,0,0,0,0,0,0,0,0,0,0,2,2
1,2,0,0,0,0,0,0,0,0,0,0,0,0,0,2,1
1,2,2,0,0,0,0,0,0,0,0,0,0,0,2,2,1
1,1,2,2,2,2,0,0,0,0,0,2,2,2,2,1,1
1,1,1,1,2,2,0,2,0,2,0,2,2,1,1,1,1
endlayer

layer
1,1,1,0,2,2,2,2,0,2,2,2,2,0,1,1,1
1,1,2,0,2,2,2,0,0,0,2,2,2,0,2,1,1
1,2,2,0,0,0,0,0,0,0,0,0,0,0,2,2,1
0,0,0,0,0,0,0,0,0,0,0,0,0,0,0,0,0
2,2,0,0,0,0,0,0,0,0,0,0,0,0,0,2,2
2,2,0,0,0,0,0,0,0,0,0,0,0,0,0,2,2
2,2,0,0,0,0,0,0,0,0,0,0,0,0,0,2,2
2,0,0,0,0,0,0,0,0,0,0,0,0,0,0,0,2
0,0,0,0,0,0,0,0,0,0,0,0,0,0,0,0,0
2,0,0,0,0,0,0,0,0,0,0,0,0,0,0,0,2
2,2,0,0,0,0,0,0,0,0,0,0,0,0,0,2,2
2,2,0,0,0,0,0,0,0,0,0,0,0,0,0,2,2
2,2,0,0,0,0,0,0,0,0,0,0,0,0,0,2,2
0,0,0,0,0,0,0,0,0,0,0,0,0,0,0,0,0
1,2,2,0,0,0,0,0,0,0,0,0,0,0,2,2,1
1,1,2,0,2,2,2,0,0,0,2,2,2,0,2,1,1
1,1,1,0,2,2,2,2,0,2,2,2,2,0,1,1,1
endlayer

layer
1,1,1,0,2,0,2,2,2,2,2,0,2,0,1,1,1
1,1,2,0,2,0,2,0,2,0,2,0,2,0,2,1,1
1,2,2,0,0,0,17,0,0,0,17,0,0,0,2,2,1
0,0,0,0,0,0,0,0,0,0,0,0,0,0,0,0,0
2,2,0,0,0,0,0,0,0,0,0,0,0,0,0,2,2
0,0,0,0,0,0,0,0,0,0,0,0,0,0,0,0,0
2,2,19,0,0,0,0,0,0,0,0,0,0,0,18,2,2
2,0,0,0,0,0,0,0,0,0,0,0,0,0,0,0,2
2,2,0,0,0,0,0,0,0,0,0,0,0,0,0,2,2
2,0,0,0,0,0,0,0,0,0,0,0,0,0,0,0,2
2,2,19,0,0,0,0,0,0,0,0,0,0,0,18,2,2
0,0,0,0,0,0,0,0,0,0,0,0,0,0,0,0,0
2,2,0,0,0,0,0,0,0,0,0,0,0,0,0,2,2
0,0,0,0,0,0,0,0,0,0,0,0,0,0,0,0,0
1,2,2,0,0,0,16,0,0,0,16,0,0,0,2,2,1
1,1,2,0,2,0,2,0,2,0,2,0,2,0,2,1,1
1,1,1,0,2,0,2,2,2,2,2,0,2,0,1,1,1
endlayer

layer
1,1,1,1,2,0,2,0,2,0,2,0,2,1,1,1,1
1,1,2,2,2,0,0,0,6,0,0,0,2,2,2,1,1
1,2,2,19,0,0,6,0,17,0,6,0,0,18,2,2,1
1,2,17,17,0,0,17,0,0,0,17,0,0,18,17,2,1
2,2,0,0,0,0,0,0,0,0,0,0,0,0,0,2,2
0,0,0,0,0,0,0,0,0,0,0,0,0,0,0,0,0
2,0,9,19,0,0,0,0,0,0,0,0,0,18,5,0,2
0,0,0,0,0,0,0,0,0,0,0,0,0,0,0,0,0
2,9,19,0,0,0,0,0,0,0,0,0,0,0,18,5,2
0,0,0,0,0,0,0,0,0,0,0,0,0,0,0,0,0
2,0,9,19,0,0,0,0,0,0,0,0,0,18,5,0,2
0,0,0,0,0,0,0,0,0,0,0,0,0,0,0,0,0
2,2,0,0,0,0,0,0,0,0,0,0,0,0,0,2,2
1,2,16,19,0,0,16,0,0,0,16,0,0,16,16,2,1
1,2,2,19,0,0,10,0,16,0,10,0,0,18,2,2,1
1,1,2,2,2,0,0,0,10,0,0,0,2,2,2,1,1
1,1,1,1,2,0,2,0,2,0,2,0,2,1,1,1,1
endlayer

layer
1,1,1,1,2,2,2,0,2,0,2,2,2,1,1,1,1
1,1,2,2,2,2,0,0,0,0,0,2,2,2,2,1,1
1,2,2,2,17,0,0,0,6,0,0,0,17,2,2,2,1
1,2,2,2,19,0,2,0,2,0,2,0,18,2,2,2,1
2,2,19,17,17,0,2,21,21,21,2,0,18,17,18,2,2
2,2,0,0,0,21,21,0,0,0,21,21,0,0,0,2,2
2,0,0,2,2,21,0,0,0,0,0,21,2,2,0,0,2
0,0,0,0,21,0,0,0,0,0,0,0,21,0,0,0,0
2,0,9,2,21,0,0,0,0,0,0,0,21,2,5,0,2
0,0,0,0,21,0,0,0,0,0,0,0,21,0,0,0,0
2,0,0,2,2,21,0,0,0,0,0,21,2,2,0,0,2
2,2,0,0,0,21,21,0,0,0,21,21,0,0,0,2,2
2,2,19,16,19,0,2,21,21,21,2,0,16,16,18,2,2
1,2,2,2,19,0,2,0,2,0,2,0,18,2,2,2,1
1,2,2,2,16,0,0,0,10,0,0,0,16,2,2,2,1
1,1,2,2,2,2,0,0,0,0,0,2,2,2,2,1,1
1,1,1,1,2,2,2,0,2,0,2,2,2,1,1,1,1
endlayer

layer
1,1,1,1,1,2,2,2,2,2,2,2,1,1,1,1,1
1,1,2,2,1,2,2,2,2,2,2,2,1,2,2,1,1
1,2,2,2,2,2,2,2,2,2,2,2,2,2,2,2,1
1,2,2,2,2,2,1,2,1,2,1,2,2,2,2,2,1
1,1,2,2,2,2,1,2,2,2,1,2,2,2,2,1,1
2,2,2,2,2,2,2,2,17,2,2,2,2,2,2,2,2
2,2,2,1,1,2,2,21,0,21,2,2,1,1,2,2,2
2,2,2,2,2,2,21,0,0,0,21,2,2,2,2,2,2
2,2,2,1,2,19,0,0,0,0,0,18,2,1,2,2,2
2,2,2,2,2,2,21,0,0,0,21,2,2,2,2,2,2
2,2,2,1,1,2,2,21,0,21,2,2,1,1,2,2,2
2,2,2,2,2,2,2,2,16,2,2,2,2,2,2,2,2
1,1,2,2,2,2,1,2,2,2,1,2,2,2,2,1,1
1,2,2,2,2,2,1,2,1,2,1,2,2,2,2,2,1
1,2,2,2,2,2,2,2,2,2,2,2,2,2,2,2,1
1,1,2,2,1,2,2,2,2,2,2,2,1,2,2,1,1
1,1,1,1,1,2,2,2,2,2,2,2,1,1,1,1,1
endlayer

layer
1,1,1,1,1,1,1,1,1,1,1,1,1,1,1,1,1
1,1,2,2,1,2,1,2,2,2,1,2,1,2,2,1,1
1,2,2,2,1,2,1,2,1,2,1,2,1,2,2,2,1
1,2,2,2,1,1,1,1,1,1,1,1,1,2,2,2,1
1,1,1,1,1,1,1,1,1,1,1,1,1,1,1,1,1
1,2,2,1,1,1,1,2,2,2,1,1,1,1,2,2,1
1,1,1,1,1,1,2,2,2,2,2,1,1,1,1,1,1
1,2,2,1,1,2,2,19,17,18,2,2,1,1,2,2,1
1,2,1,1,1,2,2,19,0,18,2,2,1,1,1,2,1
1,2,2,1,1,2,2,19,16,18,2,2,1,1,2,2,1
1,1,1,1,1,1,2,2,2,2,2,1,1,1,1,1,1
1,2,2,1,1,1,1,2,2,2,1,1,1,1,2,2,1
1,1,1,1,1,1,1,1,1,1,1,1,1,1,1,1,1
1,2,2,2,1,1,1,1,1,1,1,1,1,2,2,2,1
1,2,2,2,1,2,1,2,1,2,1,2,1,2,2,2,1
1,1,2,2,1,2,1,2,2,2,1,2,1,2,2,1,1
1,1,1,1,1,1,1,1,1,1,1,1,1,1,1,1,1
endlayer

layer
1,1,1,1,1,1,1,1,1,1,1,1,1,1,1,1,1
1,1,2,2,2,1,1,1,1,1,1,1,2,2,2,1,1
1,2,2,2,2,1,1,1,1,1,1,1,2,2,2,2,1
1,2,2,1,2,1,1,1,1,1,1,1,2,1,2,2,1
1,2,2,2,1,1,1,1,1,1,1,1,1,2,2,2,1
1,1,1,1,1,1,1,1,1,1,1,1,1,1,1,1,1
1,1,1,1,1,1,1,2,2,2,1,1,1,1,1,1,1
1,1,1,1,1,1,2,2,2,2,2,1,1,1,1,1,1
1,1,1,1,1,1,2,2,2,2,2,1,1,1,1,1,1
1,1,1,1,1,1,2,2,2,2,2,1,1,1,1,1,1
1,1,1,1,1,1,1,2,2,2,1,1,1,1,1,1,1
1,1,1,1,1,1,1,1,1,1,1,1,1,1,1,1,1
1,2,2,2,1,1,1,1,1,1,1,1,1,2,2,2,1
1,2,2,1,2,1,1,1,1,1,1,1,2,1,2,2,1
1,2,2,2,2,1,1,1,1,1,1,1,2,2,2,2,1
1,1,2,2,2,1,1,1,1,1,1,1,2,2,2,1,1
1,1,1,1,1,1,1,1,1,1,1,1,1,1,1,1,1
endlayer

