
# Created by Ruins mod version 16.5 Ingame Parser
# authoring Player: lafuller

weight=1
embed_into_distance=4
acceptable_target_blocks=
unacceptable_target_blocks=flowing_water,water,flowing_lava,lava,ice,bedrock,netherrack,nether_brick,nether_brick_fence,soul_sand,quartz_ore,end_stone,obsidian,iron_bars,cloud,flesh,ash_block,slime_grass,slime_congealed,slime_dirt
dimensions=15,7,9
allowable_overhang=0
max_leveling=7
leveling_buffer=-1
preserve_water=0
preserve_lava=0

rule1=0,100,minecraft:double_stone_slab-9
rule2=0,100,minecraft:sandstone-0
rule3=0,100,minecraft:ladder-5
rule4=0,100,minecraft:sandstone_stairs-3
rule5=0,100,preserveBlock
rule6=0,100,minecraft:sandstone-2
rule7=0,100,minecraft:sandstone_stairs-2
rule8=0,100,minecraft:jungle_door-0
rule9=0,100,minecraft:jungle_door-2
rule10=0,100,minecraft:jungle_door-8
rule11=0,100,minecraft:sandstone_stairs-7
rule12=0,100,minecraft:sandstone_stairs-0
rule13=0,100,minecraft:sandstone_stairs-1
rule14=0,100,minecraft:spruce_fence-0
rule15=0,100,minecraft:sandstone_stairs-4
rule16=0,100,minecraft:sandstone-1
rule17=0,100,minecraft:sandstone_stairs-6
rule18=0,100,minecraft:sandstone_stairs-5
rule19=0,100,minecraft:stone_slab-1

layer
1,1,2,2,1,1,1,1,1
1,1,1,1,1,1,1,1,1
1,1,1,1,1,1,1,1,1
1,1,1,1,1,1,1,1,1
1,1,1,1,1,1,1,1,1
1,1,1,1,2,2,2,1,1
1,1,1,1,2,1,1,1,1
endlayer

layer
2,1,1,2,1,1,1,1,1
1,1,1,1,1,3,0,0,1
1,0,0,0,0,0,0,0,1
1,0,0,0,0,0,0,0,1
2,0,0,0,0,2,1,1,1
2,0,0,0,2,2,1,2,1
1,1,1,1,6,5,4,1,1
endlayer

layer
2,1,2,6,1,1,1,1,1
6,1,1,1,1,3,0,0,1
1,0,0,0,0,0,0,0,1
1,0,0,0,0,0,0,0,1
2,0,0,0,0,1,1,1,1
2,0,0,0,1,1,1,2,2
2,1,1,2,1,5,5,4,1
endlayer

layer
4,2,2,6,1,1,1,1,1
1,1,2,2,1,3,0,0,1
1,0,0,0,0,0,0,0,1
1,0,0,0,0,0,0,0,1
1,0,0,0,0,1,1,1,1
1,0,0,0,1,1,1,1,7
1,1,2,2,1,5,5,5,5
endlayer

layer
5,4,2,2,6,1,1,1,6
6,2,2,2,1,3,1,1,1
2,2,2,2,1,1,1,1,1
2,2,2,2,1,1,1,1,1
2,2,2,2,6,6,6,6,6
2,2,2,2,2,1,1,7,5
6,1,2,2,6,5,5,5,5
endlayer

layer
5,5,5,5,1,1,1,1,1
6,2,8,2,2,3,0,0,1
1,0,0,0,0,0,0,0,1
2,0,0,0,0,0,0,0,1
2,0,0,0,0,6,9,6,1
1,0,0,0,1,5,5,5,5
1,1,1,1,6,5,5,5,5
endlayer

layer
5,5,5,5,6,1,0,1,6
1,2,10,2,2,3,0,0,1
1,0,0,0,0,0,0,0,0
0,0,0,0,0,0,0,0,1
2,0,0,0,0,6,10,6,6
1,0,0,0,2,5,5,5,5
1,1,0,1,1,5,5,5,5
endlayer

layer
5,5,5,5,1,1,1,1,1
2,6,6,6,2,3,0,0,1
1,0,0,0,0,0,0,0,1
6,0,0,0,0,0,0,0,1
6,0,0,0,0,1,6,1,1
2,0,0,0,2,5,5,5,5
1,2,1,1,2,5,5,5,5
endlayer

layer
5,5,5,5,1,1,1,1,1
6,2,2,2,2,3,0,0,1
1,0,0,0,11,0,0,0,1
1,0,0,0,11,0,0,0,1
2,0,0,0,11,1,1,1,1
2,0,0,0,1,5,5,5,5
6,1,6,1,6,5,5,5,5
endlayer

layer
5,5,5,5,6,2,6,2,6
2,12,2,12,2,3,6,6,2
4,2,2,2,6,6,6,6,6
2,2,1,2,2,6,6,6,2
2,2,1,2,6,2,6,2,6
4,2,2,2,7,5,5,5,5
2,13,2,13,2,5,5,5,5
endlayer

layer
5,5,5,5,2,1,1,1,2
14,14,14,14,1,3,0,0,1
14,0,0,0,0,0,0,0,1
14,0,0,0,1,0,0,0,1
14,0,0,0,2,1,1,1,2
14,0,0,0,14,5,5,5,5
14,14,14,14,14,5,5,5,5
endlayer

layer
5,5,5,5,1,12,6,12,1
0,0,0,0,1,0,0,0,7
0,0,0,0,0,0,0,0,6
0,0,0,0,1,0,0,0,7
0,0,0,0,1,13,6,13,1
0,0,0,0,0,5,5,5,5
0,0,0,0,0,5,5,5,5
endlayer

layer
5,5,5,5,6,1,1,1,6
0,0,0,0,1,0,0,0,1
0,0,0,0,1,0,0,0,1
0,0,0,0,1,0,0,0,1
0,0,0,0,6,1,1,1,6
0,0,0,0,0,5,5,5,5
0,0,0,0,0,5,5,5,5
endlayer

layer
5,5,5,5,6,15,16,15,6
0,0,0,0,11,1,1,1,17
0,0,0,0,16,1,14,1,16
0,0,0,0,11,1,1,1,17
0,0,0,0,6,18,16,18,6
0,0,0,0,0,5,5,5,5
0,0,0,0,0,5,5,5,5
endlayer

layer
5,5,5,5,5,19,19,19,5
0,0,0,0,19,19,19,19,19
0,0,0,0,19,19,0,19,19
0,0,0,0,19,19,19,19,19
0,0,0,0,5,19,19,19,5
0,0,0,0,0,5,5,5,5
0,0,0,0,0,5,5,5,5
endlayer

