
# Created by Ruins mod version 16.7 Ingame Parser
# authoring Player: lafuller

weight=1
embed_into_distance=4
acceptable_target_blocks=
unacceptable_target_blocks=flowing_water,water,flowing_lava,lava
dimensions=18,17,19
allowable_overhang=0
max_leveling=4
leveling_buffer=-1
preserve_water=0
preserve_lava=0

rule1=0,100,preserveBlock
rule2=0,100,minecraft:stone-6
rule3=0,100,stonebrick-0,stonebrick-0,stonebrick-0,stonebrick-0,stonebrick-1,stonebrick-2,stonebrick-2,stone-5,stone-6,cobblestone
rule4=0,100,stonebrick-0,stonebrick-2,stonebrick-2,stonebrick-1,stonebrick-1,cobblestone
rule5=0,100,stonebrick-0,stonebrick-1,stonebrick-2,stonebrick-2,stone-5,stone-5,stone-6,stone-6
rule6=0,100,stonebrick-0,stonebrick-1,stonebrick-2
rule7=0,100,minecraft:stone_brick_stairs-2
rule8=0,100,minecraft:stone_brick_stairs-3
rule9=0,100,stonebrick-0,stonebrick-0,stonebrick-0,stonebrick-0,stonebrick-1,stonebrick-2,stonebrick-2,stone-5,stone-6,cobblestone,gravel
rule10=0,100,minecraft:stone-5
rule11=0,100,minecraft:cobblestone_wall-0
rule12=0,100,minecraft:log-0
rule13=0,100,minecraft:wooden_slab-9
rule14=0,100,minecraft:oak_stairs-0
rule15=0,100,minecraft:planks-0
rule16=0,100,ChestGenHook:chests/spawn_bonus_chest:5-4
rule17=0,100,web,air,air,air
rule18=0,100,minecraft:oak_stairs-7
rule19=0,100,minecraft:oak_stairs-2
rule20=0,100,minecraft:planks-1
rule21=0,100,minecraft:oak_stairs-6
rule22=0,100,minecraft:stone_brick_stairs-1
rule23=0,100,minecraft:spruce_fence_gate-5
rule24=0,100,minecraft:stone-4
rule25=0,100,minecraft:stone-3
rule26=0,100,minecraft:spruce_fence-0
rule27=0,100,minecraft:spruce_fence_gate-3
rule28=0,100,minecraft:cauldron-0
rule29=0,100,minecraft:spruce_fence_gate-1
rule30=0,100,minecraft:oak_stairs-3
rule31=0,100,minecraft:trapdoor-8
rule32=0,100,minecraft:oak_stairs-5
rule33=0,100,minecraft:jungle_door-2
rule34=0,100,minecraft:wooden_slab-0
rule35=0,100,minecraft:carpet-7
rule36=0,100,minecraft:furnace-2
rule37=0,100,minecraft:bookshelf-0
rule38=0,100,minecraft:jungle_door-9
rule39=0,100,minecraft:jungle_door-8
rule40=0,100,minecraft:spruce_fence_gate-2
rule41=0,100,minecraft:ladder-5
rule42=0,100,minecraft:spruce_fence_gate-0
rule43=0,100,minecraft:ladder-2
rule44=0,100,minecraft:wooden_slab-13
rule45=0,100,minecraft:log-8
rule46=0,100,minecraft:log-4
rule47=0,100,minecraft:planks-2
rule48=0,100,minecraft:planks-5
rule49=0,100,minecraft:wooden_slab-5
rule50=0,100,minecraft:dark_oak_stairs-0
rule51=0,100,minecraft:dark_oak_stairs-3
rule52=0,100,minecraft:spruce_fence_gate-6
rule53=0,100,minecraft:spruce_fence_gate-4
rule54=0,100,minecraft:spruce_stairs-5
rule55=0,100,minecraft:spruce_stairs-6
rule56=0,100,minecraft:dark_oak_stairs-2
rule57=0,100,minecraft:spruce_stairs-4
rule58=0,100,minecraft:spruce_fence_gate-7
rule59=0,100,minecraft:dark_oak_stairs-1
rule60=0,100,minecraft:carpet-8
rule61=0,100,minecraft:oak_stairs-4
rule62=0,100,minecraft:spruce_stairs-7
rule63=0,100,minecraft:dark_oak_fence-0
rule64=0,100,minecraft:trapdoor-13

layer
1,1,1,1,1,1,1,1,1,1,1,1,1,1,1,1,1,1,1
1,1,1,1,1,2,3,3,3,3,3,2,1,1,1,1,1,1,1
1,1,1,1,3,3,4,4,4,4,4,3,1,1,1,1,1,1,1
1,1,1,2,3,2,4,5,5,5,4,3,1,1,1,1,1,1,1
1,1,3,3,4,4,5,6,6,5,4,3,1,1,1,1,1,1,1
1,2,3,4,4,5,5,6,5,5,4,3,2,1,1,2,1,1,1
1,1,3,4,5,6,6,6,6,5,4,2,3,3,3,3,3,1,1
1,1,3,4,5,5,6,6,6,5,4,4,4,4,4,4,3,2,1
1,1,3,4,5,6,6,6,6,6,5,6,5,5,4,4,3,1,1
1,1,3,4,5,5,6,6,6,6,5,6,6,6,5,4,3,1,1
1,2,3,4,4,5,5,6,6,6,6,5,5,5,5,4,3,1,1
1,1,1,3,4,4,5,5,6,6,5,4,4,4,4,4,3,2,1
1,1,1,3,2,3,4,5,5,5,5,4,2,3,3,3,3,1,1
1,1,1,1,3,3,4,4,4,4,4,4,3,3,3,2,1,1,1
1,1,1,1,8,3,3,3,3,3,3,3,2,3,3,7,1,1,1
1,1,1,1,8,9,2,3,3,3,3,3,3,3,3,7,1,1,1
1,1,1,1,8,3,3,3,3,3,3,3,3,3,3,7,1,1,1
endlayer

layer
1,1,1,1,1,1,1,1,1,1,1,1,1,1,1,1,1,1,1
1,1,1,1,1,10,9,11,9,11,9,10,1,1,1,1,1,1,1
1,1,1,1,9,9,12,13,13,13,12,9,1,1,1,1,1,1,1
1,1,1,10,9,10,0,0,0,0,0,9,1,1,1,1,1,1,1
1,1,9,9,0,0,0,0,0,0,0,11,1,1,1,1,1,1,1
1,10,9,12,0,0,0,0,0,0,0,9,10,1,1,10,1,1,1
1,1,11,13,0,0,0,0,0,0,0,10,9,9,11,9,9,1,1
1,1,9,13,0,0,0,0,0,0,0,0,0,0,0,0,9,10,1
1,1,9,13,0,0,0,0,0,0,0,0,0,0,0,0,11,1,1
1,1,11,13,0,0,0,0,0,0,0,0,0,12,14,14,9,1,1
1,10,9,12,0,0,0,0,0,0,0,0,0,0,15,15,9,1,1
1,1,1,9,0,0,0,0,0,0,0,0,0,16,15,15,9,10,1
1,1,1,9,10,9,0,0,0,0,0,0,10,9,11,9,9,1,1
1,1,1,1,9,9,12,13,13,13,13,12,9,9,7,10,1,1,1
1,1,1,1,1,9,9,9,9,9,9,9,10,9,7,1,1,1,1
1,1,1,1,1,8,10,9,9,9,9,9,9,9,7,1,1,1,1
1,1,1,1,1,8,9,9,9,9,9,9,9,9,7,1,1,1,1
endlayer

layer
1,1,1,1,1,1,1,1,1,1,1,1,1,1,1,1,1,1,1
1,1,1,1,1,2,9,11,9,11,9,2,1,1,1,1,1,1,1
1,1,1,1,9,9,12,17,0,17,12,9,1,1,1,1,1,1,1
1,1,1,2,9,2,17,0,0,0,17,9,1,1,1,1,1,1,1
1,1,9,9,17,0,0,0,0,0,0,11,1,1,1,1,1,1,1
1,2,9,12,0,0,0,0,0,0,0,9,2,1,1,2,1,1,1
1,1,11,17,0,0,0,0,0,0,0,2,9,9,11,9,9,1,1
1,1,9,0,0,0,0,0,0,0,0,0,0,0,0,0,9,2,1
1,1,9,0,0,0,0,0,0,0,0,0,0,0,0,0,11,1,1
1,1,11,17,0,0,0,0,0,0,0,0,0,12,0,0,9,1,1
1,2,9,12,0,0,0,0,0,0,0,0,0,18,14,14,11,1,1
1,1,1,9,17,0,0,0,0,0,0,0,17,18,15,15,9,2,1
1,1,1,9,2,9,17,0,0,0,0,17,2,9,11,9,9,1,1
1,1,1,1,9,9,12,17,0,0,17,12,9,7,1,2,1,1,1
1,1,1,1,1,9,9,9,9,9,9,9,2,7,1,1,1,1,1
1,1,1,1,1,1,2,9,9,9,9,9,9,7,1,1,1,1,1
1,1,1,1,1,1,8,9,9,9,9,9,9,7,1,1,1,1,1
endlayer

layer
1,1,1,1,1,1,1,1,1,1,1,1,1,1,1,1,1,1,1
1,1,1,1,1,10,9,11,9,11,9,10,1,1,1,1,1,1,1
1,1,1,1,9,9,12,17,17,17,12,9,1,1,1,1,1,1,1
1,1,1,10,9,10,17,17,0,17,17,9,1,1,1,1,1,1,1
1,1,9,9,17,17,0,0,0,0,17,11,1,1,1,1,1,1,1
1,10,9,12,17,0,0,0,0,0,0,9,10,1,1,10,1,1,1
1,1,11,17,17,0,0,0,0,0,0,10,9,9,11,9,9,1,1
1,1,9,17,0,0,0,0,0,0,0,0,0,0,0,17,9,10,1
1,1,9,17,0,0,0,0,0,0,0,0,0,0,0,0,11,1,1
1,1,11,17,17,0,0,0,0,0,0,0,0,12,0,0,9,1,1
1,10,9,12,17,0,0,0,0,0,0,0,17,19,0,0,11,1,1
1,1,1,9,17,17,17,0,0,0,0,17,17,19,0,0,9,10,1
1,1,1,9,10,9,17,17,0,0,17,17,10,9,11,9,9,1,1
1,1,1,1,9,9,12,17,17,17,17,12,9,1,1,10,1,1,1
1,1,1,1,1,9,9,9,9,9,9,9,10,1,1,1,1,1,1
1,1,1,1,1,1,10,9,9,9,9,9,7,1,1,1,1,1,1
1,1,1,1,1,1,1,8,9,9,9,9,7,1,1,1,1,1,1
endlayer

layer
1,1,1,1,1,1,1,1,1,1,1,1,1,1,1,1,1,1,1
1,1,1,1,1,2,9,9,9,9,9,2,1,1,1,1,1,1,1
1,1,1,1,1,9,15,15,15,15,15,9,1,1,1,1,1,1,1
1,1,1,2,9,2,15,20,20,20,15,9,1,1,1,1,1,1,1
1,1,1,9,15,15,15,20,15,15,15,9,1,1,1,1,1,1,1
1,2,9,15,15,20,20,15,15,20,15,9,2,1,1,2,1,1,1
1,1,9,15,20,20,15,15,15,20,15,2,9,9,9,9,9,1,1
1,1,9,15,20,15,15,15,20,20,15,15,15,21,17,17,9,2,1
1,1,9,15,20,15,20,15,15,20,20,20,15,21,0,0,9,1,1
1,1,9,15,15,20,20,15,15,15,15,20,20,12,0,0,9,1,1
1,2,9,15,15,15,20,15,20,15,15,20,19,0,0,0,9,1,1
1,1,1,9,15,15,20,20,20,15,20,15,19,0,0,0,9,2,1
1,1,1,1,2,9,15,15,20,20,20,15,2,9,9,9,9,1,1
1,1,1,1,1,9,15,15,15,15,15,15,9,1,1,2,1,1,1
1,1,1,1,1,9,9,9,9,15,15,9,2,1,1,1,1,1,1
1,1,1,1,1,1,2,1,8,9,9,7,1,1,1,1,1,1,1
1,1,1,1,1,1,1,1,8,22,22,22,1,1,1,1,1,1,1
endlayer

layer
1,1,1,1,1,1,1,1,1,1,1,1,1,1,1,1,1,1,1
1,1,1,1,1,12,15,15,15,15,15,12,1,1,1,1,1,1,1
1,1,1,1,1,15,0,23,23,0,12,15,1,1,1,1,1,1,1
1,1,1,12,15,12,0,0,0,0,0,15,1,1,1,1,1,1,1
1,1,1,15,25,24,0,0,0,0,0,15,1,1,1,1,1,1,1
1,12,15,28,0,0,0,0,26,27,26,15,12,1,1,12,1,1,1
1,1,15,2,0,0,0,0,26,29,26,12,15,15,15,15,15,1,1
1,1,15,31,0,0,0,0,0,0,0,0,30,15,15,15,15,12,1
1,1,15,31,0,0,0,0,0,0,0,0,30,15,32,32,15,1,1
1,1,15,2,0,0,0,0,0,0,0,0,0,12,0,0,15,1,1
1,12,15,12,0,0,0,0,0,0,0,0,0,0,0,0,15,1,1
1,1,1,15,15,0,0,0,0,0,0,0,0,0,0,17,15,12,1
1,1,1,1,12,15,0,0,0,0,0,0,12,15,15,15,15,1,1
1,1,1,1,1,15,12,15,0,0,0,0,15,1,1,12,1,1,1
1,1,1,1,1,15,15,15,15,33,33,15,12,1,1,1,1,1,1
1,1,1,1,1,1,12,1,1,1,1,1,1,1,1,1,1,1,1
1,1,1,1,1,1,1,1,1,1,1,1,1,1,1,1,1,1,1
endlayer

layer
1,1,1,1,1,1,1,1,1,1,1,1,1,1,1,1,1,1,1
1,1,1,1,1,12,15,34,34,15,15,12,1,1,1,1,1,1,1
1,1,1,1,1,15,0,35,35,0,12,15,1,1,1,1,1,1,1
1,1,1,12,15,12,0,0,0,0,0,34,1,1,1,1,1,1,1
1,1,1,15,0,0,0,0,0,0,0,34,1,1,1,1,1,1,1
1,12,15,36,0,0,0,0,35,35,35,15,12,1,1,12,1,1,1
1,1,15,0,0,0,0,0,35,35,35,12,15,15,15,15,15,1,1
1,1,34,0,0,0,0,0,0,0,0,0,0,30,15,15,15,12,1
1,1,34,0,0,0,0,0,0,0,0,0,0,30,15,15,15,1,1
1,1,15,0,0,0,0,0,0,0,0,0,0,12,32,32,15,1,1
1,12,15,12,0,0,0,0,0,0,0,0,0,0,0,17,15,1,1
1,1,1,15,15,0,0,0,0,0,0,0,0,0,0,17,15,12,1
1,1,1,1,12,15,0,0,0,0,0,0,12,15,15,15,15,1,1
1,1,1,1,1,15,12,37,0,0,0,0,15,1,1,12,1,1,1
1,1,1,1,1,15,15,15,15,39,38,15,12,1,1,1,1,1,1
1,1,1,1,1,1,12,1,1,1,1,1,1,1,1,1,1,1,1
1,1,1,1,1,1,1,1,1,1,1,1,1,1,1,1,1,1,1
endlayer

layer
1,1,1,1,1,1,1,1,1,1,1,1,1,1,1,1,1,1,1
1,1,1,1,1,12,15,29,29,15,15,12,1,1,1,1,1,1,1
1,1,1,1,1,15,0,0,0,0,12,15,1,1,1,1,1,1,1
1,1,1,12,15,12,0,0,0,0,0,40,1,1,1,1,1,1,1
1,1,1,15,41,0,0,0,0,0,0,40,1,1,1,1,1,1,1
1,12,15,0,0,0,0,0,0,0,0,15,12,1,1,12,1,1,1
1,1,15,0,0,0,0,0,0,0,0,12,15,15,15,15,15,1,1
1,1,42,0,0,0,0,0,0,0,0,0,0,0,0,0,15,12,1
1,1,42,0,0,0,0,0,0,0,0,0,0,0,0,0,15,1,1
1,1,15,43,0,0,0,0,0,0,0,0,0,12,14,14,15,1,1
1,12,15,12,0,0,0,0,0,0,0,0,0,0,18,15,15,1,1
1,1,1,15,15,0,0,0,0,0,0,0,0,0,18,15,15,12,1
1,1,1,1,12,15,0,0,0,0,0,0,12,15,15,15,15,1,1
1,1,1,1,1,15,12,37,0,0,0,0,15,1,1,12,1,1,1
1,1,1,1,1,15,15,15,15,27,27,15,12,1,1,1,1,1,1
1,1,1,1,1,1,12,1,1,1,1,1,1,1,1,1,1,1,1
1,1,1,1,1,1,1,1,1,1,1,1,1,1,1,1,1,1,1
endlayer

layer
1,1,1,1,1,1,1,1,1,1,1,1,1,1,1,1,1,1,1
1,1,1,1,1,12,15,32,32,15,15,12,1,1,1,1,1,1,1
1,1,1,1,1,15,0,0,0,0,12,15,1,1,1,1,1,1,1
1,1,1,12,15,12,0,0,0,0,0,18,1,1,1,1,1,1,1
1,1,1,15,0,0,0,0,0,0,0,18,1,1,1,1,1,1,1
1,12,15,0,0,0,0,0,0,0,0,15,12,1,1,12,1,1,1
1,1,15,0,0,0,0,0,0,0,0,12,15,15,15,15,15,1,1
1,1,21,0,0,0,0,0,0,0,0,0,0,0,0,0,15,12,1
1,1,21,0,0,0,0,0,0,0,0,0,0,0,0,0,15,1,1
1,1,15,0,0,0,0,0,0,0,0,0,0,12,0,0,15,1,1
1,12,15,12,0,0,0,0,0,0,0,0,0,18,14,14,15,1,1
1,1,1,15,15,0,0,0,0,0,0,0,0,18,15,15,15,12,1
1,1,1,1,12,15,0,0,0,0,0,0,12,15,15,15,15,1,1
1,1,1,1,1,15,12,34,0,0,0,0,15,1,1,12,1,1,1
1,1,1,1,1,15,15,15,15,15,15,15,12,1,1,1,1,1,1
1,1,1,1,1,1,12,1,1,1,1,1,1,1,1,1,1,1,1
1,1,1,1,1,1,1,1,1,1,1,1,1,1,1,1,1,1,1
endlayer

layer
1,1,1,1,1,44,44,44,44,44,44,44,1,1,1,1,1,1,1
1,1,1,44,44,12,45,45,45,45,45,12,44,1,1,1,1,1,1
1,1,44,44,44,46,47,47,47,47,47,46,44,1,1,1,1,1,1
1,44,44,12,45,46,47,47,47,47,46,46,44,44,1,1,1,1,1
1,44,44,15,47,46,47,47,47,47,46,46,44,44,44,44,1,1,1
44,12,15,47,47,46,47,47,47,47,46,46,12,44,44,12,44,44,1
44,44,46,47,47,46,45,45,45,45,45,12,45,45,45,45,48,44,44
44,44,46,47,47,46,47,47,47,47,47,47,46,0,0,0,12,12,44
44,44,46,47,47,46,47,47,47,47,47,47,46,0,0,0,46,44,44
44,44,46,47,47,46,47,47,47,47,47,47,46,12,0,0,46,44,44
44,12,15,45,45,45,45,45,45,45,45,45,46,19,0,0,46,44,44
1,44,44,15,15,47,46,47,47,47,47,47,46,19,0,0,46,12,44
1,1,44,44,12,46,46,47,47,47,47,47,12,45,45,45,12,44,1
1,1,1,44,44,15,46,47,47,47,47,47,46,44,44,12,44,1,1
1,1,1,1,44,15,45,48,45,45,45,45,12,44,44,44,1,1,1
1,1,1,1,44,44,12,44,44,44,44,44,44,1,1,1,1,1,1
1,1,1,1,1,44,44,44,44,44,1,1,1,1,1,1,1,1,1
endlayer

layer
1,1,1,1,1,1,1,1,1,1,1,1,1,1,1,1,1,1,1
1,1,1,1,49,49,49,49,49,49,49,49,1,1,1,1,1,1,1
1,1,1,49,49,51,48,48,48,48,50,49,1,1,1,1,1,1,1
1,1,1,49,48,12,15,15,15,15,15,12,49,1,1,1,1,1,1
1,1,49,50,15,0,0,0,0,0,0,15,50,49,1,1,1,1,1
1,49,50,48,15,53,0,0,0,0,52,15,48,48,50,49,1,1,1
1,49,51,48,15,53,0,0,0,0,52,12,15,15,15,15,49,1,1
1,49,48,48,15,0,0,0,0,0,0,0,15,0,0,0,12,49,1
1,49,48,12,15,55,13,54,0,0,0,0,15,0,0,0,15,50,1
1,49,48,48,15,55,13,57,0,0,0,0,0,12,0,0,15,56,1
1,49,51,48,48,12,15,0,0,0,0,0,0,0,0,0,15,56,1
1,1,49,51,48,48,15,15,0,0,0,0,0,0,0,0,15,49,1
1,1,1,49,59,48,48,15,0,58,58,0,12,15,15,15,12,1,1
1,1,1,1,49,51,48,12,15,15,15,15,12,48,59,49,1,1,1
1,1,1,1,1,49,49,59,51,48,48,56,59,49,49,1,1,1,1
1,1,1,1,1,1,49,49,49,49,49,49,1,1,1,1,1,1,1
1,1,1,1,1,1,1,1,1,1,1,1,1,1,1,1,1,1,1
endlayer

layer
1,1,1,1,1,1,1,1,1,1,1,1,1,1,1,1,1,1,1
1,1,1,1,1,1,1,1,1,1,1,1,1,1,1,1,1,1,1
1,1,1,1,1,1,1,1,1,1,1,1,1,1,1,1,1,1,1
1,1,1,1,1,12,15,34,34,34,15,12,1,1,1,1,1,1,1
1,1,1,1,15,0,0,0,0,0,0,15,1,1,1,1,1,1,1
1,1,1,1,34,35,0,0,0,0,35,15,1,1,1,1,1,1,1
1,1,1,1,34,35,0,0,0,0,35,12,15,34,34,15,1,1,1
1,1,1,1,15,0,0,0,0,0,0,0,15,0,0,0,12,1,1
1,1,1,12,15,60,35,35,0,0,0,0,15,0,0,0,15,1,1
1,1,1,49,15,60,35,35,0,0,0,0,0,12,0,0,34,1,1
1,1,1,1,49,12,37,0,0,0,0,0,0,0,0,0,34,1,1
1,1,1,1,1,49,15,37,0,0,0,0,0,0,0,0,15,1,1
1,1,1,1,1,1,49,15,0,35,35,0,12,15,34,15,12,1,1
1,1,1,1,1,1,1,12,15,34,34,15,12,1,1,1,1,1,1
1,1,1,1,1,1,1,1,1,1,1,1,1,1,1,1,1,1,1
1,1,1,1,1,1,1,1,1,1,1,1,1,1,1,1,1,1,1
1,1,1,1,1,1,1,1,1,1,1,1,1,1,1,1,1,1,1
endlayer

layer
1,1,1,1,1,1,1,1,1,1,1,1,1,1,1,1,1,1,1
1,1,1,1,1,1,1,1,1,1,1,1,1,1,1,1,1,1,1
1,1,1,1,1,1,1,1,1,1,1,1,1,1,1,1,1,1,1
1,1,1,1,1,12,15,29,29,29,15,12,1,1,1,1,1,1,1
1,1,1,1,15,0,0,0,0,0,0,15,1,1,1,1,1,1,1
1,1,1,1,42,0,0,0,0,0,0,15,1,1,1,1,1,1,1
1,1,1,1,42,0,0,0,0,0,0,12,15,29,29,15,1,1,1
1,1,1,1,15,0,0,0,0,0,0,0,15,0,0,0,12,1,1
1,1,1,12,15,0,0,0,0,0,0,0,15,0,0,0,15,1,1
1,1,1,1,15,0,0,0,0,0,0,0,0,12,0,0,40,1,1
1,1,1,1,1,12,34,0,0,0,0,0,0,0,0,0,40,1,1
1,1,1,1,1,1,15,34,0,0,0,0,0,0,0,0,15,1,1
1,1,1,1,1,1,1,15,0,0,0,0,12,15,27,15,12,1,1
1,1,1,1,1,1,1,12,15,27,27,15,12,1,1,1,1,1,1
1,1,1,1,1,1,1,1,1,1,1,1,1,1,1,1,1,1,1
1,1,1,1,1,1,1,1,1,1,1,1,1,1,1,1,1,1,1
1,1,1,1,1,1,1,1,1,1,1,1,1,1,1,1,1,1,1
endlayer

layer
1,1,1,1,1,1,1,1,1,1,1,1,1,1,1,1,1,1,1
1,1,1,1,1,1,1,1,1,1,1,1,1,1,1,1,1,1,1
1,1,1,1,1,1,1,1,1,1,1,1,1,1,1,1,1,1,1
1,1,1,1,1,12,15,32,32,32,15,12,1,1,1,1,1,1,1
1,1,1,1,15,0,0,0,0,0,0,15,1,1,1,1,1,1,1
1,1,1,1,21,0,0,0,0,0,0,15,1,1,1,1,1,1,1
1,1,1,1,21,0,0,0,0,0,0,12,15,32,32,15,1,1,1
1,1,1,1,15,0,0,0,0,0,0,0,15,0,0,0,12,1,1
1,1,1,12,15,0,0,0,0,0,0,0,15,0,0,0,15,1,1
1,1,1,1,15,0,0,0,0,0,0,0,0,12,0,0,18,1,1
1,1,1,1,1,12,0,0,0,0,0,0,0,0,0,0,18,1,1
1,1,1,1,1,1,15,0,0,0,0,0,0,0,0,0,15,1,1
1,1,1,1,1,1,1,15,0,0,0,0,12,15,61,15,12,1,1
1,1,1,1,1,1,1,12,15,61,61,15,12,1,1,1,1,1,1
1,1,1,1,1,1,1,1,1,1,1,1,1,1,1,1,1,1,1
1,1,1,1,1,1,1,1,1,1,1,1,1,1,1,1,1,1,1
1,1,1,1,1,1,1,1,1,1,1,1,1,1,1,1,1,1,1
endlayer

layer
1,1,1,1,1,1,1,1,1,1,1,1,1,1,1,1,1,1,1
1,1,1,1,1,1,1,1,1,1,1,1,1,1,1,1,1,1,1
1,1,1,1,1,44,44,44,44,44,44,44,44,1,1,1,1,1,1
1,1,1,1,44,12,15,15,15,15,15,12,44,44,1,1,1,1,1
1,1,1,44,15,54,54,54,54,54,54,15,44,44,44,1,1,1,1
1,1,1,44,15,55,0,0,0,0,0,15,44,44,44,44,1,1,1
1,1,1,44,15,55,0,0,0,0,0,12,15,15,15,15,44,1,1
1,1,44,44,15,55,0,0,0,0,0,0,15,55,54,62,12,44,1
1,1,44,12,15,55,0,0,0,0,0,0,15,55,0,62,15,44,1
1,1,44,44,15,55,0,0,0,0,0,0,0,12,0,62,15,44,1
1,1,1,44,44,12,57,0,0,0,0,0,0,46,0,62,15,44,1
1,1,1,44,44,44,15,55,0,0,0,0,0,46,57,57,15,44,1
1,1,1,1,44,44,44,15,57,57,57,57,12,15,15,15,12,44,1
1,1,1,1,1,44,44,12,45,45,45,45,12,44,44,44,44,1,1
1,1,1,1,1,1,44,44,44,44,44,44,44,1,1,1,1,1,1
1,1,1,1,1,1,1,1,1,1,1,1,1,1,1,1,1,1,1
1,1,1,1,1,1,1,1,1,1,1,1,1,1,1,1,1,1,1
endlayer

layer
1,1,1,1,1,1,1,1,1,1,1,1,1,1,1,1,1,1,1
1,1,1,1,1,1,1,1,1,1,1,1,1,1,1,1,1,1,1
1,1,1,1,1,1,51,50,50,50,56,1,1,1,1,1,1,1,1
1,1,1,1,1,50,50,48,48,48,48,48,49,1,1,1,1,1,1
1,1,1,1,51,20,20,20,20,20,20,20,48,48,1,1,1,1,1
1,1,1,1,48,20,54,54,54,54,54,20,48,48,49,1,1,1,1
1,1,1,49,48,20,55,0,0,0,0,12,48,48,48,50,1,1,1
1,1,1,49,48,20,55,0,0,0,0,0,20,20,20,20,56,1,1
1,1,1,51,48,20,55,0,0,0,0,0,20,20,26,20,48,49,1
1,1,1,51,48,20,55,57,0,0,0,0,62,12,20,20,48,49,1
1,1,1,49,48,12,20,55,57,0,0,0,62,20,20,20,48,49,1
1,1,1,1,59,48,20,20,55,57,57,57,62,20,20,20,56,1,1
1,1,1,1,1,59,48,20,20,20,20,20,12,48,48,59,56,1,1
1,1,1,1,1,1,49,48,48,48,48,48,48,59,56,49,1,1,1
1,1,1,1,1,1,1,51,59,59,59,1,1,1,1,1,1,1,1
1,1,1,1,1,1,1,1,1,1,1,1,1,1,1,1,1,1,1
1,1,1,1,1,1,1,1,1,1,1,1,1,1,1,1,1,1,1
endlayer

layer
1,1,1,1,1,1,1,1,1,1,1,1,1,1,1,1,1,1,1
1,1,1,1,1,1,1,1,1,1,1,1,1,1,1,1,1,1,1
1,1,1,1,1,1,1,1,1,1,1,1,1,1,1,1,1,1,1
1,1,1,1,1,1,1,50,50,50,50,49,1,1,1,1,1,1,1
1,1,1,1,1,49,48,48,48,48,48,48,48,1,1,1,1,1,1
1,1,1,1,1,48,48,48,48,20,48,48,48,48,1,1,1,1,1
1,1,1,1,50,48,48,20,20,20,20,48,48,48,50,1,1,1,1
1,1,1,1,51,48,48,20,54,54,62,20,48,48,48,50,1,1,1
1,1,1,1,51,48,20,20,55,64,62,20,20,48,63,48,49,1,1
1,1,1,1,51,48,48,20,57,57,62,20,20,48,48,48,49,1,1
1,1,1,1,49,48,48,48,48,20,20,20,48,48,48,48,1,1,1
1,1,1,1,1,51,48,48,48,48,20,48,48,48,48,56,1,1,1
1,1,1,1,1,1,59,48,48,48,48,48,48,48,49,1,1,1,1
1,1,1,1,1,1,1,1,49,59,59,59,49,1,1,1,1,1,1
1,1,1,1,1,1,1,1,1,1,1,1,1,1,1,1,1,1,1
1,1,1,1,1,1,1,1,1,1,1,1,1,1,1,1,1,1,1
1,1,1,1,1,1,1,1,1,1,1,1,1,1,1,1,1,1,1
endlayer

layer
1,1,1,1,1,1,1,1,1,1,1,1,1,1,1,1,1,1,1
1,1,1,1,1,1,1,1,1,1,1,1,1,1,1,1,1,1,1
1,1,1,1,1,1,1,1,1,1,1,1,1,1,1,1,1,1,1
1,1,1,1,1,1,1,1,1,1,1,1,1,1,1,1,1,1,1
1,1,1,1,1,1,1,63,63,63,63,63,1,1,1,1,1,1,1
1,1,1,1,1,1,63,63,49,49,49,63,63,63,1,1,1,1,1
1,1,1,1,1,63,63,49,49,49,49,49,63,63,1,1,1,1,1
1,1,1,1,1,63,49,49,49,49,49,49,49,63,63,1,1,1,1
1,1,1,1,1,63,49,49,49,1,49,49,49,49,63,1,1,1,1
1,1,1,1,1,63,49,49,49,49,49,49,49,49,63,1,1,1,1
1,1,1,1,1,63,63,49,49,49,49,49,49,63,63,1,1,1,1
1,1,1,1,1,1,63,63,63,49,49,49,63,63,1,1,1,1,1
1,1,1,1,1,1,1,1,63,63,63,63,63,1,1,1,1,1,1
1,1,1,1,1,1,1,1,1,1,1,1,1,1,1,1,1,1,1
1,1,1,1,1,1,1,1,1,1,1,1,1,1,1,1,1,1,1
1,1,1,1,1,1,1,1,1,1,1,1,1,1,1,1,1,1,1
1,1,1,1,1,1,1,1,1,1,1,1,1,1,1,1,1,1,1
endlayer


