# Gilly's Underground Mineshaft parts

# template generated with Ruins mod version 15.4 Ingame Parser
# Structure created and developed by Gilly

weight=1
embed_into_distance=0
acceptable_target_blocks=
unacceptable_target_blocks=flowing_water,water,flowing_lava,lava
dimensions=20,5,5
allowable_overhang=0
max_leveling=0
leveling_buffer=-1
preserve_water=0
preserve_lava=0

rule1=0,100,minecraft:planks-1
rule2=0,100,minecraft:ladder-3
rule3=0,100,CommandBlock:RUINSTRIGGER /testruin Gilly/GillyMH1 ~3 ~1 ~-3 0:@,CommandBlock:RUINSTRIGGER /testruin Gilly/GillyMH1 ~-3 ~1 ~3 1:@,CommandBlock:RUINSTRIGGER /testruin Gilly/GillyMH1 ~3 ~1 ~-3 0:@,CommandBlock:RUINSTRIGGER /testruin Gilly/GillyMH1 ~-3 ~1 ~3 1:@
rule4=0,100,minecraft:fence-0
rule5=2,100,minecraft:torch-1

layer
1,1,1,1,1
1,0,0,2,1
1,0,3,0,1
1,0,0,0,1
1,1,1,1,1
endlayer

layer
4,0,0,0,4
0,0,0,2,1
0,0,0,0,0
0,0,0,0,0
4,0,0,0,4
endlayer

layer
4,0,0,0,4
0,0,0,2,1
0,0,0,0,0
0,0,0,0,0
4,0,0,0,4
endlayer

layer
4,0,0,0,4
0,0,0,2,1
0,0,0,0,0
0,0,0,0,0
4,0,0,0,4
endlayer

layer
1,1,1,1,1
1,0,0,2,1
1,0,3,0,1
1,0,0,0,1
1,1,1,1,1
endlayer

layer
4,0,0,0,4
0,0,0,2,1
0,0,0,0,0
0,0,0,0,0
4,0,0,0,4
endlayer

layer
4,0,0,0,4
0,0,0,2,1
0,0,0,0,0
0,0,0,0,0
4,0,0,0,4
endlayer

layer
4,0,0,0,4
0,0,0,2,1
0,0,0,0,5
0,0,0,0,0
4,0,0,0,4
endlayer

layer
1,1,1,1,1
1,0,0,2,1
1,0,3,0,1
1,0,0,0,1
1,1,1,1,1
endlayer

layer
4,0,0,0,4
0,0,0,2,1
0,0,0,0,0
0,0,0,0,0
4,0,0,0,4
endlayer

layer
4,0,0,0,4
0,0,0,2,1
0,0,0,0,0
0,0,0,0,0
4,0,0,0,4
endlayer

layer
4,0,0,0,4
0,0,0,2,1
0,0,0,0,0
0,0,0,0,0
4,0,0,0,4
endlayer

layer
1,1,1,1,1
1,0,0,2,1
1,0,3,0,1
1,0,0,0,1
1,1,1,1,1
endlayer

layer
4,0,0,0,4
0,0,0,2,1
0,0,0,0,0
0,0,0,0,0
4,0,0,0,4
endlayer

layer
4,0,0,0,4
0,0,0,2,1
0,0,0,0,0
0,0,0,0,0
4,0,0,0,4
endlayer

layer
4,0,0,0,4
0,0,0,2,1
0,0,0,0,0
0,0,0,0,0
4,0,0,0,4
endlayer

layer
1,1,1,1,1
1,0,0,2,1
1,0,3,0,1
1,0,0,0,1
1,1,1,1,1
endlayer

layer
4,0,0,0,4
0,0,0,2,1
0,0,0,0,0
0,0,0,0,0
4,0,0,0,4
endlayer

layer
4,0,0,0,4
0,0,0,2,1
0,0,0,0,0
0,0,0,0,0
4,0,0,0,4
endlayer

layer
4,0,0,0,4
0,0,0,2,1
0,0,0,0,5
0,0,0,0,0
4,0,0,0,4
endlayer

