
# Created by Ruins mod version 16.7 Ingame Parser
# authoring Player: lafuller

weight=1
embed_into_distance=51
acceptable_target_blocks=
unacceptable_target_blocks=flowing_water,water,flowing_lava,lava,ice,bedrock,netherrack,nether_brick,nether_brick_fence,soul_sand,quartz_ore,gravel,end_stone,obsidian,iron_bars,cloud,flesh,ash_block,slime_grass,slime_congealed,slime_dirt
dimensions=53,7,7
allowable_overhang=0
max_leveling=2
leveling_buffer=-1
preserve_water=0
preserve_lava=0

rule1=0,100,preserveBlock
rule2=0,100,minecraft:planks-1
rule3=0,100,minecraft:dark_oak_fence-0
rule4=0,100,minecraft:spruce_stairs-1
rule5=0,100,minecraft:spruce_stairs-4
rule6=0,100,minecraft:spruce_stairs-2
rule7=0,100,minecraft:spruce_stairs-7
rule8=0,100,minecraft:spruce_stairs-0
rule9=0,100,minecraft:spruce_stairs-5
rule10=0,100,minecraft:spruce_stairs-3
rule11=0,100,minecraft:spruce_stairs-6
rule12=0,100,stonebrick-0,stonebrick-2,stonebrick-2,stonebrick-1,stonebrick-1,cobblestone
rule13=0,100,stonebrick-0,stonebrick-1,stonebrick-2,stonebrick-2,stone-5,stone-5,stone-6,stone-6
rule14=0,100,minecraft:stone_brick_stairs-2
rule15=0,100,stonebrick-0,stonebrick-1,stonebrick-2
rule16=0,100,minecraft:trapdoor-11
rule17=0,100,minecraft:trapdoor-9
rule18=0,100,minecraft:trapdoor-8
rule19=0,100,minecraft:trapdoor-10
rule20=0,100,minecraft:stone_brick_stairs-4
rule21=0,100,CommandBlock:RUINSTRIGGER /testruin Gilly/GillyNarrowCorridor ~5 ~1 ~0 0:@,CommandBlock:RUINSTRIGGER /testruin Gilly/GillyNarrowCorridor ~0 ~1 ~-5 1:@,CommandBlock:RUINSTRIGGER /testruin Gilly/GillyNarrowCorridor ~-5 ~1 ~0 2:@,CommandBlock:RUINSTRIGGER /testruin Gilly/GillyNarrowCorridor ~0 ~1 ~5 3:@,CommandBlock:RUINSTRIGGER /testruin Gilly/GillyNarrowHallway ~3 ~1 ~3 0:@,CommandBlock:RUINSTRIGGER /testruin Gilly/GillyNarrowHallway ~3 ~1 ~-3 1:@,CommandBlock:RUINSTRIGGER /testruin Gilly/GillyNarrowHallway ~-3 ~1 ~-3 2:@,CommandBlock:RUINSTRIGGER /testruin Gilly/GillyNarrowHallway ~-3 ~1 ~3 3:@


layer
1,1,1,1,1,1,1
1,1,1,1,1,1,1
1,1,1,1,1,1,1
1,1,1,1,1,1,1
1,1,1,1,1,1,1
1,1,1,1,1,1,1
1,1,1,1,1,1,1
endlayer

layer
2,2,2,2,2,2,2
2,2,2,2,2,2,2
2,2,0,0,0,2,2
2,2,0,21,0,2,2
2,2,0,0,0,2,2
2,2,2,2,2,2,2
2,2,2,2,2,2,2
endlayer

layer
3,3,0,0,0,3,3
3,3,0,0,0,3,3
0,0,0,0,0,0,3
0,0,0,0,0,0,3
0,0,0,0,0,0,2
3,3,0,0,0,0,4
3,3,0,0,0,0,0
endlayer

layer
3,3,0,0,0,3,3
3,3,0,0,0,3,3
0,0,0,0,0,0,3
0,0,0,0,0,0,2
0,0,0,0,0,0,4
3,3,0,0,0,0,0
3,3,0,0,0,0,0
endlayer

layer
3,3,0,0,0,3,3
3,3,0,0,0,3,3
0,0,0,0,0,0,2
0,0,0,0,0,0,4
0,0,0,0,0,0,0
3,3,0,0,0,0,0
3,3,0,0,0,0,0
endlayer

layer
3,3,0,0,0,3,3
3,3,0,0,0,3,2
0,0,0,0,0,0,4
0,0,0,0,0,0,0
0,0,0,0,0,0,0
3,3,0,0,0,0,0
3,3,0,0,0,0,0
endlayer

layer
2,2,2,2,2,2,2
2,2,2,2,2,2,4
2,2,0,0,0,2,0
2,2,0,21,0,2,0
2,2,0,0,0,2,0
2,2,2,2,2,2,0
2,2,2,2,2,2,5
endlayer

layer
3,3,3,3,2,6,0
3,3,0,0,0,0,0
0,0,0,0,0,0,0
0,0,0,0,0,0,0
0,0,0,0,0,0,0
3,3,0,0,0,3,3
3,3,0,0,0,3,3
endlayer

layer
3,3,3,2,6,0,0
3,3,0,0,0,0,0
0,0,0,0,0,0,0
0,0,0,0,0,0,0
0,0,0,0,0,0,0
3,3,0,0,0,3,3
3,3,0,0,0,3,3
endlayer

layer
3,3,2,6,0,0,0
3,3,0,0,0,0,0
0,0,0,0,0,0,0
0,0,0,0,0,0,0
0,0,0,0,0,0,0
3,3,0,0,0,3,3
3,3,0,0,0,3,3
endlayer

layer
3,2,6,0,0,0,0
3,3,0,0,0,0,0
0,0,0,0,0,0,0
0,0,0,0,0,0,0
0,0,0,0,0,0,0
3,3,0,0,0,3,3
3,3,0,0,0,3,3
endlayer

layer
2,6,0,0,0,0,7
2,2,2,2,2,2,2
2,2,0,0,0,2,2
2,2,0,21,0,2,2
2,2,0,0,0,2,2
2,2,2,2,2,2,2
2,2,2,2,2,2,2
endlayer

layer
0,0,0,0,0,3,3
8,0,0,0,0,3,3
2,0,0,0,0,0,0
3,0,0,0,0,0,0
3,0,0,0,0,0,0
3,3,0,0,0,3,3
3,3,0,0,0,3,3
endlayer

layer
0,0,0,0,0,3,3
0,0,0,0,0,3,3
8,0,0,0,0,0,0
2,0,0,0,0,0,0
3,0,0,0,0,0,0
3,3,0,0,0,3,3
3,3,0,0,0,3,3
endlayer

layer
0,0,0,0,0,3,3
0,0,0,0,0,3,3
0,0,0,0,0,0,0
8,0,0,0,0,0,0
2,0,0,0,0,0,0
3,3,0,0,0,3,3
3,3,0,0,0,3,3
endlayer

layer
0,0,0,0,0,3,3
0,0,0,0,0,3,3
0,0,0,0,0,0,0
0,0,0,0,0,0,0
8,0,0,0,0,0,0
2,3,0,0,0,3,3
3,3,0,0,0,3,3
endlayer

layer
9,2,2,2,2,2,2
0,2,2,2,2,2,2
0,2,0,0,0,2,2
0,2,0,21,0,2,2
0,2,0,0,0,2,2
8,2,2,2,2,2,2
2,2,2,2,2,2,2
endlayer

layer
3,3,0,0,0,3,3
3,3,0,0,0,3,3
0,0,0,0,0,0,0
0,0,0,0,0,0,0
0,0,0,0,0,0,0
0,0,0,0,0,3,3
0,10,2,3,3,3,3
endlayer

layer
3,3,0,0,0,3,3
3,3,0,0,0,3,3
0,0,0,0,0,0,0
0,0,0,0,0,0,0
0,0,0,0,0,0,0
0,0,0,0,0,3,3
0,0,10,2,3,3,3
endlayer

layer
3,3,0,0,0,3,3
3,3,0,0,0,3,3
0,0,0,0,0,0,0
0,0,0,0,0,0,0
0,0,0,0,0,0,0
0,0,0,0,0,3,3
0,0,0,10,2,3,3
endlayer

layer
3,3,0,0,0,3,3
3,3,0,0,0,3,3
0,0,0,0,0,0,0
0,0,0,0,0,0,0
0,0,0,0,0,0,0
0,0,0,0,0,3,3
0,0,0,0,10,2,3
endlayer

layer
2,2,2,2,2,2,2
2,2,2,2,2,2,2
2,2,0,0,0,2,2
2,2,0,21,0,2,2
2,2,0,0,0,2,2
2,2,2,2,2,2,2
11,0,0,0,0,10,2
endlayer

layer
3,3,0,0,0,3,3
3,3,0,0,0,3,3
0,0,0,0,0,0,3
0,0,0,0,0,0,3
0,0,0,0,0,0,2
3,3,0,0,0,0,4
3,3,0,0,0,0,0
endlayer

layer
3,3,0,0,0,3,3
3,3,0,0,0,3,3
0,0,0,0,0,0,3
0,0,0,0,0,0,2
0,0,0,0,0,0,4
3,3,0,0,0,0,0
3,3,0,0,0,0,0
endlayer

layer
3,3,0,0,0,3,3
3,3,0,0,0,3,3
0,0,0,0,0,0,2
0,0,0,0,0,0,4
0,0,0,0,0,0,0
3,3,0,0,0,0,0
3,3,0,0,0,0,0
endlayer

layer
3,3,0,0,0,3,3
3,3,0,0,0,3,2
0,0,0,0,0,0,4
0,0,0,0,0,0,0
0,0,0,0,0,0,0
3,3,0,0,0,0,0
3,3,0,0,0,0,0
endlayer

layer
2,2,2,2,2,2,2
2,2,2,2,2,2,4
2,2,0,0,0,2,0
2,2,0,21,0,2,0
2,2,0,0,0,2,0
2,2,2,2,2,2,0
2,2,2,2,2,2,5
endlayer

layer
3,3,3,3,2,6,0
3,3,0,0,0,0,0
0,0,0,0,0,0,0
0,0,0,0,0,0,0
0,0,0,0,0,0,0
3,3,0,0,0,3,3
3,3,0,0,0,3,3
endlayer

layer
3,3,3,2,6,0,0
3,3,0,0,0,0,0
0,0,0,0,0,0,0
0,0,0,0,0,0,0
0,0,0,0,0,0,0
3,3,0,0,0,3,3
3,3,0,0,0,3,3
endlayer

layer
3,3,2,6,0,0,0
3,3,0,0,0,0,0
0,0,0,0,0,0,0
0,0,0,0,0,0,0
0,0,0,0,0,0,0
3,3,0,0,0,3,3
3,3,0,0,0,3,3
endlayer

layer
3,2,6,0,0,0,0
3,3,0,0,0,0,0
0,0,0,0,0,0,0
0,0,0,0,0,0,0
0,0,0,0,0,0,0
3,3,0,0,0,3,3
3,3,0,0,0,3,3
endlayer

layer
2,6,0,0,0,0,7
2,2,2,2,2,2,2
2,2,0,0,0,2,2
2,2,0,21,0,2,2
2,2,0,0,0,2,2
2,2,2,2,2,2,2
2,2,2,2,2,2,2
endlayer

layer
0,0,0,0,0,3,3
8,0,0,0,0,3,3
2,0,0,0,0,0,0
3,0,0,0,0,0,0
3,0,0,0,0,0,0
3,3,0,0,0,3,3
3,3,0,0,0,3,3
endlayer

layer
0,0,0,0,0,3,3
0,0,0,0,0,3,3
8,0,0,0,0,0,0
2,0,0,0,0,0,0
3,0,0,0,0,0,0
3,3,0,0,0,3,3
3,3,0,0,0,3,3
endlayer

layer
0,0,0,0,0,3,3
0,0,0,0,0,3,3
0,0,0,0,0,0,0
8,0,0,0,0,0,0
2,0,0,0,0,0,0
3,3,0,0,0,3,3
3,3,0,0,0,3,3
endlayer

layer
0,0,0,0,0,3,3
0,0,0,0,0,3,3
0,0,0,0,0,0,0
0,0,0,0,0,0,0
8,0,0,0,0,0,0
2,3,0,0,0,3,3
3,3,0,0,0,3,3
endlayer

layer
9,2,2,2,2,2,2
0,2,2,2,2,2,2
0,2,0,0,0,2,2
0,2,0,21,0,2,2
0,2,0,0,0,2,2
8,2,2,2,2,2,2
2,2,2,2,2,2,2
endlayer

layer
3,3,0,0,0,3,3
3,3,0,0,0,3,3
0,0,0,0,0,0,0
0,0,0,0,0,0,0
0,0,0,0,0,0,0
0,0,0,0,0,3,3
0,10,2,3,3,3,3
endlayer

layer
3,3,0,0,0,3,3
3,3,0,0,0,3,3
0,0,0,0,0,0,0
0,0,0,0,0,0,0
0,0,0,0,0,0,0
0,0,0,0,0,3,3
0,0,10,2,3,3,3
endlayer

layer
3,3,0,0,0,3,3
3,3,0,0,0,3,3
0,0,0,0,0,0,0
0,0,0,0,0,0,0
0,0,0,0,0,0,0
0,0,0,0,0,3,3
0,0,0,10,2,3,3
endlayer

layer
3,3,0,0,0,3,3
3,3,0,0,0,3,3
0,0,0,0,0,0,0
0,0,0,0,0,0,0
0,0,0,0,0,0,0
0,0,0,0,0,3,3
0,0,0,0,10,2,3
endlayer

layer
2,2,2,2,2,2,2
2,2,2,2,2,2,2
2,2,0,0,0,2,2
2,2,0,0,0,2,2
2,2,0,0,0,2,2
2,2,2,2,2,2,2
11,0,0,0,0,10,2
endlayer

layer
3,3,0,0,0,3,3
3,3,0,0,0,3,3
0,0,0,0,0,0,3
0,0,0,0,0,0,3
0,0,0,0,0,0,2
3,3,0,0,0,0,4
3,3,0,0,0,0,0
endlayer

layer
3,3,0,0,0,3,3
3,3,0,0,0,3,3
0,0,0,0,0,0,3
0,0,0,0,0,0,2
0,0,0,0,0,0,4
3,3,0,0,0,0,0
3,3,0,0,0,0,0
endlayer

layer
3,3,0,0,0,3,3
3,3,0,0,0,3,3
0,0,0,0,0,0,2
0,0,0,0,0,0,4
0,0,0,0,0,0,0
3,3,0,0,0,0,0
3,3,0,0,0,0,0
endlayer

layer
3,3,0,0,0,3,3
3,3,0,0,0,3,2
0,0,0,0,0,0,4
0,0,0,0,0,0,0
0,0,0,0,0,0,0
3,3,0,0,0,0,0
3,3,0,0,0,0,0
endlayer

layer
12,12,13,13,13,13,12
13,13,13,15,15,14,4
13,15,16,16,16,14,0
13,15,18,0,17,13,0
13,15,19,19,19,13,0
13,13,13,15,13,13,0
12,12,13,13,13,12,20
endlayer

layer
1,0,0,0,2,6,0
0,0,0,0,0,0,0
0,0,0,0,0,0,0
0,0,0,0,0,0,0
0,0,0,0,0,0,0
0,0,0,0,0,0,0
1,0,0,0,0,0,1
endlayer

layer
1,0,0,2,6,0,0
0,0,0,0,0,0,0
0,0,0,0,0,0,0
0,0,0,0,0,0,0
0,0,0,0,0,0,0
0,0,0,0,0,0,0
1,0,0,0,0,0,1
endlayer

layer
1,0,2,6,0,0,0
0,0,0,0,0,0,0
0,0,0,0,0,0,0
0,0,0,0,0,0,0
0,0,0,0,0,0,0
0,0,0,0,0,0,0
1,0,0,0,0,0,1
endlayer

layer
1,2,6,0,0,0,0
0,0,0,0,0,0,0
0,0,0,0,0,0,0
0,0,0,0,0,0,0
0,0,0,0,0,0,0
0,0,0,0,0,0,0
1,0,0,0,0,0,1
endlayer

layer
2,6,0,0,0,0,7
2,8,8,2,2,2,2
2,2,16,16,16,2,2
2,2,18,0,17,2,2
2,2,19,19,19,2,2
2,2,2,2,2,2,2
2,2,2,2,2,2,2
endlayer

layer
1,0,0,0,0,0,1
0,0,0,3,3,3,3
0,0,0,0,0,0,0
0,0,0,0,0,0,0
0,0,0,0,0,0,0
0,0,0,0,0,0,0
1,0,0,0,0,0,1
endlayer

