# Gilly's Cabin

weight=1
embed_into_distance=3
unacceptable_target_blocks=flowing_water,water,flowing_lava,lava,ice,bedrock,netherrack,nether_brick,nether_brick_fence,soul_sand,quartz_ore,end_stone,obsidian,iron_bars,cloud,flesh,ash_block,slime_grass,slime_congealed,slime_dirt
dimensions=13,10,12
cut_in_buffer=0
max_leveling=3
leveling_buffer=-3
preserve_water=0
preserve_lava=0
preserve_plants=0

rule1=0,100,preserveBlock
rule2=0,100,log
rule3=0,100,planks
rule4=0,100,planks-1
rule5=0,100,planks-2
rule6=0,100,planks-5
rule7=0,100,wooden_slab-5
rule8=0,100,iron_bars
rule9=0,100,stonebrick-0,stonebrick-0,stonebrick-0,stonebrick-0,stonebrick-1,stonebrick-2,stonebrick-2,stone-5,stone-6,cobblestone,gravel
rule10=0,100,wooden_door-2
rule11=0,100,wooden_door-8
rule12=0,100,torch-5
rule13=0,100,IInventory;furnace;coal#2#0#1-5
rule14=0,100,cobblestone_wall
rule15=0,100,cauldron
rule16=0,100,dark_oak_fence

layer
1,1,1,1,1,1,1,1,1,1,1,1
1,9,9,9,9,9,9,9,1,1,1,1
1,9,1,1,1,1,1,9,1,1,1,1
1,9,1,1,1,1,1,9,9,9,9,1
1,9,1,1,1,1,1,1,1,1,9,1
1,9,1,1,1,1,1,1,1,1,9,1
1,9,1,1,1,1,1,1,1,1,9,1
1,9,1,1,1,1,1,1,1,1,9,1
1,9,9,9,9,9,9,9,9,9,9,1
9,1,1,1,1,1,1,9,1,1,1,1
endlayer

layer
1,1,1,1,1,1,1,1,1,1,1,1
1,9,9,9,9,9,9,9,1,1,1,1
1,9,1,1,1,1,1,9,1,1,1,1
1,9,1,1,1,1,1,9,9,9,9,1
1,9,1,1,1,1,1,1,1,1,9,1
1,9,1,1,1,1,1,1,1,1,9,1
1,9,1,1,1,1,1,1,1,1,9,1
1,9,1,1,1,1,1,1,1,1,9,1
1,9,9,9,9,9,9,9,9,9,9,1
9,1,1,1,1,1,9,1,1,1,1,1
endlayer

layer
1,1,1,1,1,1,1,1,1,1,1,1
1,9,9,9,9,9,9,9,1,1,1,1
1,9,1,1,1,1,1,9,1,1,1,1
1,9,1,1,1,1,1,9,9,9,9,1
1,9,1,1,1,1,1,1,1,1,9,1
1,9,1,1,1,1,1,1,1,1,9,1
1,9,1,1,1,1,1,1,1,1,9,1
1,9,1,1,1,1,1,1,1,1,9,1
1,9,9,9,9,9,9,9,9,9,9,1
1,9,9,9,9,9,1,1,1,1,1,1
endlayer

layer
1,1,1,1,1,1,1,1,1,1,1,1
1,9,9,9,9,9,9,9,1,1,1,1
1,9,3,3,3,3,3,9,1,1,1,1
1,9,3,3,3,3,3,9,9,9,9,1
1,9,3,3,3,3,3,3,3,3,9,1
1,9,3,3,3,3,3,3,3,3,9,1
1,9,3,3,3,3,3,3,3,3,9,1
1,9,3,3,3,3,3,3,3,3,9,1
1,9,9,9,9,9,9,9,9,9,9,1
1,1,9,9,9,1,1,1,1,1,1,1
endlayer

layer
0,0,0,0,0,0,0,0,0,0,0,0
0,2,5,5,5,5,5,2,0,0,0,0
0,5,0,0,0,0,0,5,0,0,0,0
0,5,0,0,0,0,0,15,5,5,2,0
0,5,0,0,0,0,0,0,0,0,5,0
0,5,0,0,0,0,12,0,0,0,5,0
0,5,0,0,0,0,0,0,0,0,5,0
0,5,0,0,0,0,0,0,0,0,5,0
0,2,5,10,5,2,5,5,5,5,2,0
0,0,0,0,0,0,0,0,0,0,0,0
endlayer

layer
0,0,0,0,0,0,0,0,0,0,0,0
0,2,5,0,5,0,5,2,0,0,0,0
0,5,0,0,0,0,0,5,0,0,0,0
0,0,0,0,0,0,0,13,5,5,2,0
0,0,0,0,0,0,0,0,0,0,5,0
0,5,0,0,0,0,0,0,0,0,0,0
0,0,0,0,0,0,0,0,0,0,0,0
0,5,0,0,0,0,0,0,0,0,5,0
0,2,5,11,5,2,5,0,0,5,2,0
0,0,0,0,0,0,0,0,0,0,0,0
endlayer

layer
0,0,0,0,0,0,0,0,0,0,0,0
0,2,5,8,5,8,5,2,0,0,0,0
0,5,0,0,0,0,0,5,0,0,0,0
0,8,0,0,0,0,0,14,5,5,2,0
0,8,0,0,0,0,0,0,0,0,5,0
0,5,0,0,0,0,0,0,0,0,8,0
0,8,0,0,0,0,0,0,0,0,8,0
0,5,0,0,0,0,0,0,0,0,5,0
0,2,5,5,5,2,5,8,8,5,2,0
0,0,0,0,0,0,0,0,0,0,0,0
endlayer


layer
0,0,0,0,0,0,0,0,0,0,0,0
0,2,5,5,5,5,5,2,0,0,0,0
0,5,0,0,0,0,0,5,0,0,0,0
0,5,0,0,0,0,0,14,5,5,2,0
0,5,0,0,0,0,0,0,0,0,5,0
0,5,0,0,0,0,0,0,0,0,5,0
0,5,0,0,0,0,0,0,0,0,5,0
0,5,0,0,0,0,0,0,0,0,5,0
0,2,5,5,5,2,5,5,5,5,2,0
0,0,0,0,0,0,0,0,0,0,0,0
endlayer

layer
7,7,7,7,7,7,7,7,7,0,0,0
7,6,6,6,6,6,6,6,7,0,0,0
7,6,4,4,4,4,4,6,7,7,7,7
7,6,4,4,4,4,4,6,6,6,6,7
7,6,4,4,4,4,4,4,4,4,6,7
7,6,4,4,4,4,4,4,4,4,6,7
7,6,4,4,4,4,4,4,4,4,6,7
7,6,4,4,4,4,4,4,4,4,6,7
7,6,6,6,6,6,6,6,6,6,6,7
7,7,7,7,7,7,7,7,7,7,7,7
endlayer

layer
0,0,0,0,0,0,0,0,0,0,0,0
0,16,16,16,16,16,16,16,0,0,0,0
0,16,7,7,7,7,7,16,0,0,0,0
0,16,7,7,7,7,7,14,16,16,16,0
0,16,7,7,7,7,7,7,7,7,16,0
0,16,7,7,7,7,7,7,7,7,16,0
0,16,7,7,7,7,7,7,7,7,16,0
0,16,7,7,7,7,7,7,7,7,16,0
0,16,16,16,16,16,16,16,16,16,16,0
0,0,0,0,0,0,0,0,0,0,0,0
endlayer

layer
0,0,0,0,0,0,0,0,0,0,0,0
0,0,0,0,0,0,0,0,0,0,0,0
0,0,0,0,0,0,0,0,0,0,0,0
0,0,0,0,0,0,0,14,0,0,0,0
0,0,0,0,0,0,0,0,0,0,0,0
0,0,0,0,0,0,0,0,0,0,0,0
0,0,0,0,0,0,0,0,0,0,0,0
0,0,0,0,0,0,0,0,0,0,0,0
0,0,0,0,0,0,0,0,0,0,0,0
0,0,0,0,0,0,0,0,0,0,0,0
endlayer

layer
0,0,0,0,0,0,0,0,0,0,0,0
0,0,0,0,0,0,0,0,0,0,0,0
0,0,0,0,0,0,0,0,0,0,0,0
0,0,0,0,0,0,0,14,0,0,0,0
0,0,0,0,0,0,0,0,0,0,0,0
0,0,0,0,0,0,0,0,0,0,0,0
0,0,0,0,0,0,0,0,0,0,0,0
0,0,0,0,0,0,0,0,0,0,0,0
0,0,0,0,0,0,0,0,0,0,0,0
0,0,0,0,0,0,0,0,0,0,0,0
endlayer

layer
0,0,0,0,0,0,0,0,0,0,0,0
0,0,0,0,0,0,0,0,0,0,0,0
0,0,0,0,0,0,0,0,0,0,0,0
0,0,0,0,0,0,0,14,0,0,0,0
0,0,0,0,0,0,0,0,0,0,0,0
0,0,0,0,0,0,0,0,0,0,0,0
0,0,0,0,0,0,0,0,0,0,0,0
0,0,0,0,0,0,0,0,0,0,0,0
0,0,0,0,0,0,0,0,0,0,0,0
0,0,0,0,0,0,0,0,0,0,0,0
endlayer
