
# Created by Ruins mod version 16.7 Ingame Parser
# authoring Player: lafuller

weight=1
embed_into_distance=4
acceptable_target_blocks=
unacceptable_target_blocks=flowing_water,water,flowing_lava,lava,ice,bedrock,netherrack,nether_brick,nether_brick_fence,soul_sand,quartz_ore,end_stone,obsidian,iron_bars,cloud,flesh,ash_block,slime_grass,slime_congealed,slime_dirt
biomesToSpawnIn=plains,forest,prarie,meadow,tundra,brushland,shrubland,woodland,woodlands,birch_forestlavender_fields,flower_field,sunflower_plains,ice_flats,ice_plains
dimensions=20,12,13
allowable_overhang=0
max_leveling=4
leveling_buffer=-1
preserve_water=0
preserve_lava=0

rule1=0,100,preserveBlock
rule2=0,100,stonebrick-0,stonebrick-0,stonebrick-0,stonebrick-0,stonebrick-1,stonebrick-2,stonebrick-2,stone-5,stone-6,cobblestone
rule3=0,100,minecraft:stone-6
rule4=0,100,stonebrick-0,stonebrick-2,stonebrick-1,stonebrick-1,stonebrick-1,cobblestone
rule5=0,100,stonebrick-0,stonebrick-1,stonebrick-2,stonebrick-2,stone-5,stone-5,stone-6,stone-6
rule6=0,100,stonebrick-0,stonebrick-2,stonebrick-0,stonebrick-1,stonebrick-1,cobblestone
rule7=0,100,minecraft:stone_brick_stairs-0
rule8=0,100,minecraft:stone_brick_stairs-3
rule9=0,100,air
rule10=0,100,stonebrick-0,stonebrick-0,stonebrick-0,stonebrick-0,stonebrick-1,stonebrick-2,stonebrick-2,stone-5,stone-6,cobblestone,gravel
rule11=0,100,minecraft:cobblestone_wall-0
rule12=0,100,minecraft:stone-5
rule13=0,100,minecraft:log-0
rule14=0,100,minecraft:wooden_slab-9
rule15=0,100,minecraft:stone_brick_stairs-1
rule16=0,100,minecraft:web-0,air,air,air
rule17=0,100,minecraft:stone_brick_stairs-2
rule18=0,100,minecraft:stone_brick_stairs-7
rule19=0,100,minecraft:stone_brick_stairs-6
rule20=0,100,minecraft:stone_brick_stairs-5
rule21=0,100,minecraft:lit_pumpkin-0
rule22=0,100,minecraft:mycelium-0
rule23=0,100,minecraft:stone-3
rule24=0,100,minecraft:stone-4
rule25=0,100,minecraft:oak_stairs-4
rule26=0,100,minecraft:stained_hardened_clay-9
rule27=0,100,minecraft:double_stone_slab-8
rule28=0,100,minecraft:stone_brick_stairs-4
rule29=0,100,minecraft:cauldron-0
rule30=0,100,minecraft:oak_stairs-1
rule31=0,100,minecraft:oak_stairs-0
rule32=0,100,minecraft:oak_stairs-3
rule33=0,100,bookshelf,hay_block,ChestGenHook:chests/spawn_bonus_chest:5-2,ChestGenHook:chests/village_blacksmith:5-2,ChestGenHook:chests/simple_dungeon:5-2,ChestGenHook:chests/abandoned_mineshaft:5-2,ChestGenHook:chests/stronghold_library:5-2,ChestGenHook:chests/stronghold_corridor:5-2,ChestGenHook:chests/stronghold_crossing:5-2,ChestGenHook:chests/igloo_chest:5-2
rule34=0,100,minecraft:oak_stairs-2
rule35=0,100,minecraft:planks-0
rule36=0,100,minecraft:jungle_door-2
rule37=0,100,minecraft:furnace-5
rule38=0,100,minecraft:oak_stairs-6
rule39=0,100,minecraft:fence-0
rule40=0,100,minecraft:oak_stairs-7
rule41=0,100,minecraft:oak_stairs-5
rule42=0,100,minecraft:jungle_door-9
rule43=0,100,minecraft:jungle_door-8
rule44=0,100,minecraft:wooden_slab-13
rule45=0,100,minecraft:dark_oak_stairs-3
rule46=0,100,minecraft:planks-1
rule47=0,100,minecraft:stone_slab-13
rule48=0,100,minecraft:wooden_slab-8
rule49=0,100,minecraft:wooden_slab-0
rule50=0,100,minecraft:dark_oak_stairs-7
rule51=0,100,minecraft:spruce_stairs-6
rule52=0,100,minecraft:spruce_stairs-7
rule53=0,100,minecraft:dark_oak_stairs-1
rule54=0,100,minecraft:dark_oak_stairs-2
rule55=0,100,minecraft:spruce_stairs-5
rule56=0,100,minecraft:spruce_fence_gate-1
rule57=0,100,minecraft:planks-5
rule58=0,100,minecraft:dark_oak_stairs-4
rule59=0,100,minecraft:wooden_slab-5
rule60=0,100,minecraft:spruce_stairs-4
rule61=0,100,minecraft:dark_oak_stairs-0
rule62=0,100,minecraft:dark_oak_stairs-5
rule63=0,100,minecraft:log-11
rule64=0,100,minecraft:trapdoor-13
rule65=0,100,minecraft:spruce_stairs-3
rule66=0,100,minecraft:log-7
rule67=0,100,minecraft:dark_oak_fence-0
rule68=0,100,minecraft:jungle_door-3
rule69=0,100,minecraft:spruce_fence_gate-2
rule70=0,100,minecraft:iron_bars-0
rule71=0,100,minecraft:stone_slab-0

layer
1,1,1,1,1,1,2,2,2,2,2,2,1
1,1,3,2,2,2,2,2,2,2,2,2,2
1,2,4,4,4,4,4,4,4,2,2,2,2
1,2,4,4,4,4,5,4,4,2,2,2,2
1,2,4,5,4,5,5,5,4,4,4,2,1
1,2,4,5,5,6,6,6,5,5,4,2,1
1,2,4,5,6,6,6,6,5,4,4,3,1
1,2,4,4,5,5,5,6,5,4,4,2,1
1,2,4,4,4,5,4,5,5,4,4,2,1
1,1,3,4,4,4,4,4,4,4,4,2,7
1,1,1,2,2,2,3,2,2,2,2,2,2
9,1,8,2,3,1,3,1,1,3,1,3,2
endlayer

layer
1,1,1,1,1,1,10,10,10,10,10,10,1
1,1,12,10,10,11,10,11,10,10,10,10,10
1,10,10,10,10,14,14,14,13,10,10,10,10
1,10,15,13,9,9,9,9,9,10,10,10,10
1,10,9,9,9,9,9,9,9,9,13,10,1
1,11,9,9,9,9,9,9,9,9,14,11,1
1,10,9,9,9,9,9,9,9,9,14,12,1
1,11,16,9,9,9,9,9,9,9,14,10,1
1,10,13,9,9,9,9,9,9,9,14,11,1
1,1,12,13,14,14,13,14,14,14,13,10,1
1,1,1,10,10,11,12,11,11,11,10,10,7
1,1,1,8,10,1,10,1,1,10,1,10,17
endlayer

layer
1,1,1,1,1,1,10,10,10,10,10,10,1
1,1,3,10,10,11,10,11,10,10,10,10,10
1,10,9,8,10,16,9,16,13,10,10,10,10
1,10,9,13,16,9,9,9,16,10,10,10,10
1,10,9,9,9,9,9,9,9,16,13,10,1
1,11,9,9,9,9,9,9,9,9,16,11,1
1,10,9,9,9,9,9,9,9,9,9,3,1
1,11,16,9,9,9,9,9,9,9,9,10,1
1,10,13,16,9,9,9,9,9,9,16,11,1
1,1,3,13,16,16,13,16,9,16,13,10,1
1,1,1,10,10,11,3,11,11,11,10,17,1
1,1,1,1,8,19,10,1,1,10,18,17,1
endlayer

layer
1,1,1,1,1,1,10,10,10,10,10,10,1
1,1,12,11,10,10,10,11,10,10,10,10,10
1,10,9,9,8,19,16,16,13,10,10,10,10
1,11,9,13,16,16,9,16,16,10,10,10,10
1,10,9,9,16,9,9,9,16,16,13,10,1
1,11,9,9,9,9,9,9,9,16,16,11,1
1,10,16,9,9,9,9,9,9,9,16,12,1
1,11,16,16,9,9,9,9,9,9,16,10,1
1,10,13,16,16,9,16,9,9,16,16,11,1
1,1,12,13,16,16,13,16,16,16,13,10,1
1,1,1,10,10,10,12,10,10,11,10,1,1
1,1,1,1,1,8,10,20,20,10,17,1,1
endlayer

layer
1,1,1,1,1,1,10,10,10,10,10,10,1
1,1,3,10,10,10,10,10,10,10,22,21,10
1,10,9,9,9,8,3,3,3,3,22,22,10
1,10,9,23,24,23,24,23,24,23,3,10,10
1,10,25,3,3,3,3,3,3,3,3,10,1
1,10,26,27,26,26,27,26,26,27,26,10,1
1,10,26,27,26,26,27,26,26,27,26,3,1
1,10,27,3,27,27,3,27,27,3,27,10,1
1,10,26,27,26,26,27,26,26,27,26,10,1
1,1,3,27,26,26,27,26,26,27,26,10,1
1,1,1,10,10,10,3,27,27,10,10,1,1
1,1,1,1,1,1,8,10,10,17,1,1,1
endlayer

layer
1,1,1,1,1,1,18,7,28,10,10,10,1
1,1,13,31,31,30,15,3,3,3,9,29,10
1,32,9,9,9,9,9,9,9,9,9,9,10
1,32,25,33,9,9,9,9,9,9,9,3,15
1,32,35,35,13,27,27,27,9,9,9,34,1
1,32,30,30,34,9,9,9,9,9,9,34,1
1,32,9,9,9,9,9,9,9,9,9,13,1
1,32,9,9,9,9,9,9,9,9,9,34,1
1,32,9,9,9,9,9,9,9,9,9,34,1
1,1,13,9,9,9,9,9,9,9,13,34,1
1,1,1,30,30,30,13,36,36,30,30,1,1
1,1,1,1,1,1,1,9,9,1,1,1,1
endlayer

layer
1,1,1,1,1,1,7,7,7,10,10,10,1
1,1,13,25,9,9,20,37,37,37,9,9,10
1,39,38,9,9,9,9,9,9,9,9,9,10
1,40,35,9,9,9,9,9,9,9,9,10,19
1,40,30,30,13,9,9,9,9,9,9,39,1
1,39,9,9,9,9,9,9,9,9,9,9,1
1,9,9,9,9,9,9,9,9,9,9,13,1
1,39,9,9,9,9,9,9,9,9,9,9,1
1,40,9,9,9,9,9,9,9,9,9,39,1
1,1,13,9,9,9,9,9,9,9,13,39,1
1,1,1,39,9,39,13,43,42,41,39,1,1
1,1,1,1,1,1,1,9,9,1,1,1,1
endlayer

layer
1,1,45,44,1,1,17,7,7,10,10,10,1
1,1,13,46,46,46,8,17,15,15,9,9,10
1,40,49,32,48,9,9,9,9,9,47,9,10
50,46,49,30,48,9,9,9,9,9,9,10,15
1,46,9,9,13,9,9,9,9,9,9,51,1
1,52,9,9,9,9,9,9,9,9,9,51,1
1,52,9,9,9,9,9,9,9,9,9,13,1
1,52,9,9,9,9,9,9,9,9,9,51,1
44,52,9,9,9,9,9,9,9,9,9,51,1
1,53,13,9,9,9,9,9,9,9,13,51,44
1,1,57,55,55,55,13,56,56,55,55,54,1
1,1,44,1,1,1,1,9,9,1,44,1,1
endlayer

layer
1,1,1,59,58,50,57,8,7,7,10,10,1
1,60,13,46,46,46,46,10,10,10,10,9,10
1,52,9,9,32,38,9,9,18,20,10,10,10
1,52,9,9,32,38,9,9,9,18,20,10,17
61,46,9,9,13,9,9,9,9,9,60,57,59
44,46,9,9,9,9,9,9,9,9,52,57,62
44,46,9,9,9,9,9,9,9,9,52,13,44
53,46,60,9,9,9,9,9,9,9,52,57,44
1,45,51,9,9,9,9,9,9,9,52,53,59
1,1,57,60,60,60,60,60,60,60,57,54,1
1,1,59,53,57,57,57,57,57,53,53,1,1
1,1,1,59,44,44,59,44,44,59,1,1,1
endlayer

layer
1,1,1,1,1,59,1,1,1,1,18,10,1
64,63,63,13,63,63,63,63,63,63,10,9,10
1,65,9,9,9,32,35,35,35,35,10,10,17
1,65,9,9,9,32,46,46,46,35,46,15,1
1,65,9,9,13,31,35,35,46,35,46,1,1
1,45,9,9,35,35,46,46,35,35,57,61,1
1,45,46,46,35,46,46,35,35,35,57,54,1
1,53,46,46,35,35,46,46,35,35,53,59,1
1,1,45,46,35,35,35,35,35,35,54,1,1
1,1,1,53,66,46,46,46,46,53,59,1,1
1,1,1,1,45,53,53,53,54,1,1,1,1
1,1,1,1,1,1,1,1,1,1,1,1,1
endlayer

layer
1,1,1,1,1,1,1,1,1,1,7,10,1
1,1,25,13,31,31,31,13,31,31,10,9,10
1,40,9,9,9,9,9,9,9,9,10,10,15
1,32,9,9,9,9,9,9,9,9,34,1,1
1,32,9,9,13,9,9,9,9,9,34,1,1
1,1,30,30,32,9,9,9,9,13,30,1,1
1,1,67,9,34,9,9,9,9,34,1,1,1
1,1,67,9,68,9,9,9,9,34,1,1,1
1,1,9,67,13,9,9,9,13,30,1,1,1
1,1,1,1,1,30,30,30,34,1,1,1,1
1,1,1,1,1,1,1,1,1,1,1,1,1
1,1,1,1,1,1,1,1,1,1,1,1,1
endlayer

layer
1,1,1,1,1,1,1,1,1,1,8,10,1
1,1,25,13,39,9,39,13,9,39,10,9,10
1,32,9,9,9,9,9,9,9,9,10,10,17
1,39,9,9,9,9,9,9,9,9,39,1,1
1,40,9,9,13,9,9,9,9,9,9,1,1
1,1,41,30,32,9,9,9,9,13,39,1,1
1,1,9,9,38,9,9,9,9,39,1,1,1
1,1,9,9,42,9,9,9,9,9,1,1,1
1,1,9,9,13,9,9,9,13,39,1,1,1
1,1,1,1,1,39,9,39,39,1,1,1,1
1,1,1,1,1,1,1,1,1,1,1,1,1
1,1,1,1,1,1,1,1,1,1,1,1,1
endlayer

layer
1,1,44,1,1,1,1,1,1,1,28,10,1
1,50,60,13,60,60,60,13,60,60,10,9,10
1,52,9,9,9,9,9,9,9,9,10,10,20
1,52,9,9,9,9,9,9,9,9,51,1,1
1,52,9,9,13,9,9,9,9,9,51,1,1
1,53,55,55,52,9,9,9,9,13,51,1,1
1,1,9,9,52,9,9,9,9,51,62,1,1
1,1,9,9,69,9,9,9,9,51,1,1,1
1,1,9,9,13,9,9,9,13,55,1,1,1
1,1,1,44,58,55,55,55,52,53,1,1,1
1,1,1,1,44,1,1,1,1,1,1,1,1
1,1,1,1,1,1,1,1,1,1,1,1,1
endlayer

layer
1,1,1,59,44,44,44,59,44,44,18,10,1
1,1,61,13,57,57,57,13,57,57,10,9,10
59,57,51,55,55,55,55,55,55,55,57,10,17
44,57,51,9,9,14,9,9,9,52,57,44,1
59,57,60,60,13,14,9,9,9,52,57,44,1
1,1,45,57,57,51,9,9,9,13,57,53,1
1,1,1,44,57,51,14,14,60,57,57,1,1
1,1,1,44,57,51,14,14,52,57,57,1,1
1,1,1,59,53,51,60,60,13,53,59,1,1
1,1,1,1,1,53,57,57,53,1,1,1,1
1,1,1,1,1,59,44,44,59,1,1,1,1
1,1,1,1,1,1,1,1,1,1,1,1,1
endlayer

layer
1,1,1,1,1,59,1,1,1,59,7,10,1
1,1,1,59,61,57,57,57,61,54,10,9,10
1,1,61,57,57,57,57,57,57,61,54,10,15
1,59,57,67,46,46,46,46,46,57,54,59,1
1,1,53,57,57,57,46,46,46,46,57,1,1
1,1,1,59,45,57,46,46,46,57,54,1,1
1,1,1,1,53,57,57,46,46,57,59,1,1
1,1,1,1,59,45,57,57,57,54,1,1,1
1,1,1,1,1,59,57,57,59,1,1,1,1
1,1,1,1,1,1,53,54,1,1,1,1,1
1,1,1,1,1,1,1,1,1,1,1,1,1
1,1,1,1,1,1,1,1,1,1,1,1,1
endlayer

layer
1,1,1,1,1,1,1,1,1,1,1,10,1
1,1,1,1,1,67,67,67,67,1,10,9,10
1,1,1,67,67,59,59,59,59,67,1,10,1
1,1,67,1,59,59,59,59,59,59,67,1,1
1,1,1,67,67,59,59,59,59,59,67,1,1
1,1,1,1,1,67,59,59,59,67,1,1,1
1,1,1,1,1,67,59,59,59,67,1,1,1
1,1,1,1,1,1,67,59,67,1,1,1,1
1,1,1,1,1,1,67,67,1,1,1,1,1
1,1,1,1,1,1,1,1,1,1,1,1,1
1,1,1,1,1,1,1,1,1,1,1,1,1
1,1,1,1,1,1,1,1,1,1,1,1,1
endlayer

layer
1,1,1,1,1,1,1,1,1,1,1,10,1
1,1,1,1,1,1,1,1,1,1,10,9,10
1,1,1,1,1,1,1,1,1,1,1,10,1
1,1,1,1,1,1,1,1,1,1,1,1,1
1,1,1,1,1,1,1,1,1,1,1,1,1
1,1,1,1,1,1,1,1,1,1,1,1,1
1,1,1,1,1,1,1,1,1,1,1,1,1
1,1,1,1,1,1,1,1,1,1,1,1,1
1,1,1,1,1,1,1,1,1,1,1,1,1
1,1,1,1,1,1,1,1,1,1,1,1,1
1,1,1,1,1,1,1,1,1,1,1,1,1
1,1,1,1,1,1,1,1,1,1,1,1,1
endlayer

layer
1,1,1,1,1,1,1,1,1,1,1,10,1
1,1,1,1,1,1,1,1,1,1,10,9,10
1,1,1,1,1,1,1,1,1,1,1,10,1
1,1,1,1,1,1,1,1,1,1,1,1,1
1,1,1,1,1,1,1,1,1,1,1,1,1
1,1,1,1,1,1,1,1,1,1,1,1,1
1,1,1,1,1,1,1,1,1,1,1,1,1
1,1,1,1,1,1,1,1,1,1,1,1,1
1,1,1,1,1,1,1,1,1,1,1,1,1
1,1,1,1,1,1,1,1,1,1,1,1,1
1,1,1,1,1,1,1,1,1,1,1,1,1
1,1,1,1,1,1,1,1,1,1,1,1,1
endlayer

layer
1,1,1,1,1,1,1,1,1,1,1,7,1
1,1,1,1,1,1,1,1,1,1,8,70,17
1,1,1,1,1,1,1,1,1,1,1,15,1
1,1,1,1,1,1,1,1,1,1,1,1,1
1,1,1,1,1,1,1,1,1,1,1,1,1
1,1,1,1,1,1,1,1,1,1,1,1,1
1,1,1,1,1,1,1,1,1,1,1,1,1
1,1,1,1,1,1,1,1,1,1,1,1,1
1,1,1,1,1,1,1,1,1,1,1,1,1
1,1,1,1,1,1,1,1,1,1,1,1,1
1,1,1,1,1,1,1,1,1,1,1,1,1
1,1,1,1,1,1,1,1,1,1,1,1,1
endlayer

layer
1,1,1,1,1,1,1,1,1,1,1,71,1
1,1,1,1,1,1,1,1,1,1,71,9,71
1,1,1,1,1,1,1,1,1,1,1,71,1
1,1,1,1,1,1,1,1,1,1,1,1,1
1,1,1,1,1,1,1,1,1,1,1,1,1
1,1,1,1,1,1,1,1,1,1,1,1,1
1,1,1,1,1,1,1,1,1,1,1,1,1
1,1,1,1,1,1,1,1,1,1,1,1,1
1,1,1,1,1,1,1,1,1,1,1,1,1
1,1,1,1,1,1,1,1,1,1,1,1,1
1,1,1,1,1,1,1,1,1,1,1,1,1
1,1,1,1,1,1,1,1,1,1,1,1,1
endlayer

