
# Created by Ruins mod version 16.7 Ingame Parser
# authoring Player: lafuller

weight=1
embed_into_distance=13
acceptable_target_blocks=flowing_water,water
unacceptable_target_blocks=
biomesToSpawnIn=river,swampland,lush swamp,marsh
dimensions=24,16,12
allowable_overhang=0
max_leveling=5
leveling_buffer=-1
preserve_water=0
preserve_lava=0

rule1=0,100,preserveBlock
rule2=0,100,minecraft:log2-1
rule3=0,100,minecraft:log2-5
rule4=0,100,minecraft:spruce_fence-0
rule5=0,100,minecraft:log-8
rule6=0,100,minecraft:planks-1
rule7=0,100,minecraft:log-4
rule8=0,100,minecraft:fence-0
rule9=0,100,minecraft:ladder-4
rule10=0,100,minecraft:log-0
rule11=0,100,minecraft:oak_stairs-4
rule12=0,100,minecraft:wooden_slab-9
rule13=0,100,minecraft:spruce_stairs-5
rule14=0,100,minecraft:oak_stairs-5
rule15=0,100,planks-0,planks-0,oak_stairs-0,oak_stairs-1,oak_stairs-4,oak_stairs-5
rule16=0,100,minecraft:oak_stairs-1
rule17=0,100,planks-0,planks-0,oak_stairs-2,oak_stairs-3,oak_stairs-6,oak_stairs-7
rule18=0,100,minecraft:spruce_fence_gate-5
rule19=0,100,minecraft:crafting_table-0
rule20=0,100,planks-0,planks-0,oak_stairs-3,oak_stairs-2,oak_stairs-6,oak_stairs-7
rule21=0,100,minecraft:stone-4

rule22=0,100,IInventory;hopper;bone#3#0#0+reeds#3#0#1-5,IInventory;hopper;dye#4#0#0-5,IInventory;hopper;name_tag#1#0#0-5,IInventory;hopper;shears#1#0#0-5,IInventory;hopper;flint_and_steel#1#0#0-5,IInventory;hopper;lead#1#0#0-5

rule23=0,100,IInventory;dropper;clay_ball#5#0#0-1,IInventory;dropper;coal#3#0#3-1,IInventory;dropper;cooked_fish#4#1#2+fishing_rod#1#0#7-1,IInventory;dropper;flint#4#0#2-1,IInventory;dropper;glass_bottle#5#0#5-1,IInventory;dropper;dark_oak_boat#1#0#4-1

rule24=0,100,planks-0,planks-0,oak_stairs-1,oak_stairs-0,oak_stairs-4,oak_stairs-5
rule25=0,100,minecraft:cauldron-0
rule26=0,100,minecraft:oak_stairs-2
rule27=0,100,minecraft:jungle_door-1
rule28=0,100,minecraft:spruce_fence_gate-7
rule29=0,100,minecraft:spruce_fence_gate-1
rule30=0,100,minecraft:spruce_fence_gate-3
rule31=0,100,minecraft:bookshelf-0
rule32=0,100,minecraft:trapdoor-3
rule33=0,100,minecraft:carpet-8
rule34=0,100,minecraft:carpet-7
rule35=0,100,minecraft:spruce_fence_gate-0
rule36=0,100,minecraft:furnace-2
rule37=0,100,minecraft:spruce_fence_gate-2
rule38=0,100,minecraft:jungle_door-9
rule39=0,100,minecraft:jungle_door-8
rule40=0,100,minecraft:oak_stairs-3
rule41=0,100,minecraft:oak_stairs-6
rule42=0,100,minecraft:cobblestone_wall-0
rule43=0,100,minecraft:oak_stairs-0
rule44=0,100,minecraft:spruce_stairs-4
rule45=0,100,minecraft:spruce_stairs-7
rule46=0,100,minecraft:planks-0
rule47=0,100,minecraft:spruce_stairs-2
rule48=0,100,minecraft:spruce_stairs-0
rule49=0,100,minecraft:dark_oak_stairs-4
rule50=0,100,minecraft:dark_oak_stairs-0
rule51=0,100,minecraft:wooden_slab-5
rule52=0,100,minecraft:dark_oak_stairs-2
rule53=0,100,minecraft:dark_oak_stairs-7
rule54=0,100,minecraft:spruce_stairs-6
rule55=0,100,minecraft:spruce_stairs-1
rule56=0,100,minecraft:wooden_slab-1
rule57=0,100,minecraft:dark_oak_stairs-5
rule58=0,100,minecraft:dark_oak_stairs-3
rule59=0,100,minecraft:dark_oak_stairs-1
rule60=0,100,minecraft:planks-5
rule61=0,100,minecraft:dark_oak_stairs-6
rule62=0,100,minecraft:spruce_stairs-3

layer
1,1,1,1,1,1,1,1,1,1,1,1
1,1,1,1,1,1,1,1,1,1,1,1
1,1,1,2,1,1,1,1,1,1,1,1
1,1,1,1,1,1,1,1,1,1,1,1
1,1,1,1,1,1,2,1,1,2,1,1
1,1,1,1,1,1,1,1,1,1,1,1
1,1,1,2,1,1,1,1,1,1,1,1
1,1,1,1,1,1,1,1,1,1,1,1
1,1,1,1,1,1,1,1,1,1,1,1
1,1,1,1,1,1,1,1,1,1,1,1
1,1,1,1,1,1,1,1,1,1,1,1
1,1,1,2,1,2,1,1,1,2,1,1
1,1,1,1,1,1,1,1,1,1,1,1
1,1,1,2,1,1,1,1,1,2,1,1
1,1,1,1,1,1,1,1,1,1,1,1
1,1,1,1,1,1,1,1,1,1,1,1
endlayer

layer
1,1,1,1,1,1,1,1,1,1,1,1
1,1,1,1,1,1,1,1,1,1,1,1
1,1,1,2,1,1,1,1,1,1,1,1
1,1,1,1,1,1,1,1,1,1,1,1
1,1,1,1,1,1,2,1,1,2,1,1
1,1,1,1,1,1,1,1,1,1,1,1
1,1,1,2,1,1,1,1,1,1,1,1
1,1,1,1,1,1,1,1,1,1,1,1
1,1,1,1,1,1,1,1,1,1,1,1
1,1,1,1,1,1,1,1,1,1,1,1
1,1,1,1,1,1,1,1,1,1,1,1
1,1,1,2,1,2,1,1,1,2,1,1
1,1,1,1,1,1,1,1,1,1,1,1
1,1,1,2,1,1,1,1,1,2,1,1
1,1,1,1,1,1,1,1,1,1,1,1
1,1,1,1,1,1,1,1,1,1,1,1
endlayer

layer
1,1,1,1,1,1,1,1,1,1,1,1
1,1,1,1,1,1,1,1,1,1,1,1
1,1,1,2,1,1,1,1,1,1,1,1
1,1,1,1,1,1,1,1,1,1,1,1
1,1,1,1,1,1,2,1,1,2,1,1
1,1,1,1,1,1,1,1,1,1,1,1
1,1,1,2,1,1,1,1,1,1,1,1
1,1,1,1,1,1,1,1,1,1,1,1
1,1,1,1,1,1,1,1,1,1,1,1
1,1,1,1,1,1,1,1,1,1,1,1
1,1,1,1,1,1,1,1,1,1,1,1
1,1,1,2,1,2,1,1,1,2,1,1
1,1,1,1,1,1,1,1,1,1,1,1
1,1,1,2,1,1,1,1,1,2,1,1
1,1,1,1,1,1,1,1,1,1,1,1
1,1,1,1,1,1,1,1,1,1,1,1
endlayer

layer
1,1,1,1,1,1,1,1,1,1,1,1
1,1,1,1,1,1,1,1,1,1,1,1
1,1,1,2,1,1,1,1,1,1,1,1
1,1,1,1,1,1,1,1,1,1,1,1
1,1,1,1,1,1,2,1,1,2,1,1
1,1,1,1,1,1,1,1,1,1,1,1
1,1,1,2,1,1,1,1,1,1,1,1
1,1,1,1,1,1,1,1,1,1,1,1
1,1,1,1,1,1,1,1,1,1,1,1
1,1,1,1,1,1,1,1,1,1,1,1
1,1,1,1,1,1,1,1,1,1,1,1
1,1,1,2,1,2,1,1,1,2,1,1
1,1,1,1,1,1,1,1,1,1,1,1
1,1,1,2,1,1,1,1,1,2,1,1
1,1,1,1,1,1,1,1,1,1,1,1
1,1,1,1,1,1,1,1,1,1,1,1
endlayer

layer
1,1,1,1,1,1,1,1,1,1,1,1
1,1,1,1,1,1,1,1,1,1,1,1
1,1,1,2,1,1,1,1,1,1,1,1
1,1,1,1,1,1,1,1,1,1,1,1
1,1,1,1,1,1,2,1,1,2,1,1
1,1,1,1,1,1,1,1,1,1,1,1
1,1,1,2,1,1,1,1,1,1,1,1
1,1,1,1,1,1,1,1,1,1,1,1
1,1,1,1,1,1,1,1,1,1,1,1
1,1,1,1,1,1,1,1,1,1,1,1
1,1,1,1,1,1,1,1,1,1,1,1
1,1,1,2,1,2,1,1,1,2,1,1
1,1,1,1,1,1,1,1,1,1,1,1
1,1,1,2,1,1,1,1,1,2,1,1
1,1,1,1,1,1,1,1,1,1,1,1
1,1,1,1,1,1,1,1,1,1,1,1
endlayer

layer
1,1,1,1,1,1,1,1,1,1,1,1
1,1,1,1,1,1,1,1,1,1,1,1
1,1,1,2,1,1,1,1,1,1,1,1
1,1,1,1,1,1,1,1,1,1,1,1
1,1,1,1,1,1,2,1,1,2,1,1
1,1,1,1,1,1,1,1,1,1,1,1
1,1,1,2,1,1,1,1,1,1,1,1
1,1,1,1,1,1,1,1,1,1,1,1
1,1,1,1,1,1,1,1,1,1,1,1
1,1,1,1,1,1,1,1,1,1,1,1
1,1,1,1,1,1,1,1,1,1,1,1
1,1,1,2,1,2,1,1,1,2,1,1
1,1,1,1,1,1,1,1,1,1,1,1
1,1,1,2,1,1,1,1,1,2,1,1
1,1,1,1,1,1,1,1,1,1,1,1
1,1,1,1,1,1,1,1,1,1,1,1
endlayer

layer
1,1,1,1,1,1,1,1,1,1,1,1
1,1,1,1,1,1,1,1,1,1,1,1
1,1,1,2,1,1,1,1,1,1,1,1
1,1,1,1,1,1,1,1,1,1,1,1
1,1,1,1,1,1,2,1,1,2,1,1
1,1,1,1,1,1,1,1,1,1,1,1
1,1,1,2,1,1,1,1,1,1,1,1
1,1,1,1,1,1,1,1,1,1,1,1
1,1,1,1,1,1,1,1,1,1,1,1
1,1,1,1,1,1,1,1,1,1,1,1
1,1,1,1,1,1,1,1,1,1,1,1
1,1,1,2,1,2,1,1,1,2,1,1
1,1,1,1,1,1,1,1,1,1,1,1
1,1,1,2,1,1,1,1,1,2,1,1
1,1,1,1,1,1,1,1,1,1,1,1
1,1,1,1,1,1,1,1,1,1,1,1
endlayer

layer
1,1,1,1,1,1,1,1,1,1,1,1
1,1,1,1,1,1,1,1,1,1,1,1
1,1,1,2,1,1,1,1,1,1,1,1
1,1,1,1,1,1,1,1,1,1,1,1
1,1,1,1,1,1,2,1,1,2,1,1
1,1,1,1,1,1,1,1,1,1,1,1
1,1,1,2,1,1,1,1,1,1,1,1
1,1,1,1,1,1,1,1,1,1,1,1
1,1,1,1,1,1,1,1,1,1,1,1
1,1,1,1,1,1,1,1,1,1,1,1
1,1,1,1,1,1,1,1,1,1,1,1
1,1,1,2,1,2,1,1,1,2,1,1
1,1,1,1,1,1,1,1,1,1,1,1
1,1,1,2,1,1,1,1,1,2,1,1
1,1,1,1,1,1,1,1,1,1,1,1
1,1,1,1,1,1,1,1,1,1,1,1
endlayer

layer
1,1,1,1,1,1,1,1,1,1,1,1
1,1,1,1,1,1,1,1,1,1,1,1
1,1,1,2,1,1,1,1,1,1,1,1
1,1,1,1,1,1,1,1,1,1,1,1
1,1,1,1,1,1,2,1,1,2,1,1
1,1,1,1,1,1,1,1,1,1,1,1
1,1,1,2,1,1,1,1,1,1,1,1
1,1,1,1,1,1,1,1,1,1,1,1
1,1,1,1,1,1,1,1,1,1,1,1
1,1,1,1,1,1,1,1,1,1,1,1
1,1,1,1,1,1,1,1,1,1,1,1
1,1,1,2,1,2,1,1,1,2,1,1
1,1,1,1,1,1,1,1,1,1,1,1
1,1,1,2,1,1,1,1,1,2,1,1
1,1,1,1,1,1,1,1,1,1,1,1
1,1,1,1,1,1,1,1,1,1,1,1
endlayer

layer
1,1,1,1,1,1,1,1,1,1,1,1
1,1,1,1,1,1,1,1,1,1,1,1
1,1,1,2,1,1,1,1,1,1,1,1
1,1,1,1,1,1,1,1,1,1,1,1
1,1,1,1,1,1,2,1,1,2,1,1
1,1,1,1,1,1,1,1,1,1,1,1
1,1,1,2,1,1,1,1,1,1,1,1
1,1,1,1,1,1,1,1,1,1,1,1
1,1,1,1,1,1,1,1,1,1,1,1
1,1,1,1,1,1,1,1,1,1,1,1
1,1,1,1,1,1,1,1,1,1,1,1
1,1,1,2,1,2,1,1,1,2,1,1
1,1,1,1,1,1,1,1,1,1,1,1
1,1,1,2,1,1,1,1,1,2,1,1
1,1,1,1,1,1,1,1,1,1,1,1
1,1,1,1,1,1,1,1,1,1,1,1
endlayer

layer
1,1,1,1,1,1,1,1,1,1,1,1
1,1,1,1,1,1,1,1,1,1,1,1
1,1,1,2,1,1,1,1,1,1,1,1
1,1,1,1,1,1,1,1,1,1,1,1
1,1,1,1,1,1,2,1,1,2,1,1
1,1,1,1,1,1,1,1,1,1,1,1
1,1,1,2,1,1,1,1,1,1,1,1
1,1,1,1,1,1,1,1,1,1,1,1
1,1,1,1,1,1,1,1,1,1,1,1
1,1,1,1,1,1,1,1,1,1,1,1
1,1,1,1,1,1,1,1,1,1,1,1
1,1,1,2,1,2,1,1,1,2,1,1
1,1,1,1,1,1,1,1,1,1,1,1
1,1,1,2,1,1,1,1,1,2,1,1
1,1,1,1,1,1,1,1,1,1,1,1
1,1,1,1,1,1,1,1,1,1,1,1
endlayer

layer
1,1,1,1,1,1,1,1,1,1,1,1
1,1,1,1,1,1,1,1,1,1,1,1
1,1,1,2,1,1,1,1,1,1,1,1
1,1,1,1,1,1,1,1,1,1,1,1
1,1,1,1,1,1,2,1,1,2,1,1
1,1,1,1,1,1,1,1,1,1,1,1
1,1,1,2,1,1,1,1,1,1,1,1
1,1,1,1,1,1,1,1,1,1,1,1
1,1,1,1,1,1,1,1,1,1,1,1
1,1,1,1,1,1,1,1,1,1,1,1
1,1,1,1,1,1,1,1,1,1,1,1
1,1,1,2,1,2,1,1,1,2,1,1
1,1,1,1,1,1,1,1,1,1,1,1
1,1,1,2,1,1,1,1,1,2,1,1
1,1,1,1,1,1,1,1,1,1,1,1
1,1,1,1,1,1,1,1,1,1,1,1
endlayer

layer
1,1,1,1,1,1,1,1,1,1,1,1
1,1,1,1,1,1,1,1,1,1,1,1
1,1,3,2,3,1,1,3,3,1,1,1
1,1,3,1,3,1,1,3,3,1,1,1
1,1,3,1,3,1,2,3,3,2,1,1
1,1,3,1,3,1,1,3,3,1,1,1
1,1,3,2,3,1,1,3,3,1,1,1
1,1,1,1,1,1,1,3,3,1,1,1
1,1,1,1,1,1,1,3,3,1,1,1
1,1,1,1,1,1,1,3,3,1,1,1
1,1,1,1,1,1,1,3,3,1,1,1
1,1,3,2,3,2,1,3,3,2,1,1
1,1,3,1,3,1,1,3,3,1,1,1
1,1,3,2,3,1,1,3,3,2,1,1
1,1,1,1,1,1,1,1,1,1,1,1
1,1,1,1,1,1,1,1,1,1,1,1
endlayer

layer
1,1,1,1,1,1,1,1,1,1,1,1
1,1,1,1,1,1,1,1,1,1,1,1
1,1,1,2,1,1,1,1,1,1,1,1
1,1,5,5,5,5,5,5,5,5,4,1
1,1,1,1,1,1,2,1,1,2,1,1
1,1,5,5,5,5,5,5,5,5,4,1
1,1,1,2,1,1,1,1,1,1,1,1
1,1,1,1,1,1,1,1,1,1,1,1
1,1,1,1,1,1,1,1,1,1,1,1
1,1,1,1,1,1,1,1,1,1,1,1
1,1,1,1,1,1,1,1,1,1,1,1
1,1,1,2,1,2,1,6,6,2,1,1
1,1,5,5,5,5,5,5,5,5,4,1
1,1,1,2,1,1,1,1,1,2,1,1
1,1,1,1,1,1,1,1,1,1,1,1
1,1,1,1,1,1,1,1,1,1,1,1
endlayer

layer
1,1,4,1,4,1,4,1,1,4,1,1
1,1,7,1,7,1,7,1,1,7,1,1
1,1,7,2,7,1,7,1,1,7,1,1
1,8,7,1,7,1,7,1,1,7,8,1
1,1,7,1,7,1,7,1,1,7,1,1
1,8,7,1,7,1,7,1,1,7,8,1
1,1,7,2,7,1,7,1,1,7,1,1
1,1,7,1,7,1,1,1,1,1,1,1
1,1,7,1,7,1,1,1,1,1,1,1
1,1,7,1,7,1,1,1,1,1,1,1
1,8,7,1,7,1,7,9,9,1,1,1
1,1,7,2,7,2,7,6,6,7,1,1
1,8,7,1,7,1,7,1,1,7,8,1
1,1,7,2,7,1,7,1,1,7,1,1
1,1,7,1,7,1,7,1,1,7,1,1
1,1,4,1,4,1,4,1,1,4,1,1
endlayer

layer
1,1,8,1,8,1,8,1,1,8,1,1
1,8,10,11,10,11,10,11,11,10,8,1
4,5,5,5,5,5,5,5,5,5,5,4
1,12,12,12,12,12,12,12,12,12,12,1
4,5,5,5,5,5,5,5,5,5,5,4
1,12,12,12,12,12,12,12,12,12,12,1
4,5,5,5,5,5,5,5,5,5,5,4
1,12,12,12,12,12,12,12,12,12,1,1
4,5,5,5,5,5,5,1,1,1,1,1
1,12,12,12,12,12,6,1,1,1,1,1
1,12,12,12,12,12,6,9,9,4,4,1
4,5,5,5,5,5,5,5,5,5,5,4
1,12,12,12,12,12,12,12,12,12,12,1
4,5,5,5,5,5,5,5,5,5,5,4
1,8,10,14,10,14,10,13,13,10,6,4
1,1,8,1,8,1,8,1,1,8,4,1
endlayer

layer
1,1,0,0,0,0,0,0,0,0,1,1
1,4,15,15,16,16,15,15,15,15,8,1
0,20,10,19,0,0,18,18,6,10,17,0
0,20,21,0,0,0,0,0,12,12,17,0
0,20,22,0,0,0,0,0,12,12,17,0
0,20,23,0,0,0,0,0,12,12,17,0
0,20,21,0,0,0,0,0,19,10,17,0
0,20,25,0,0,0,10,24,24,24,8,0
0,20,0,0,0,0,17,0,0,0,0,0
0,26,0,0,0,0,17,0,0,0,0,0
0,26,0,0,0,0,17,0,0,8,8,0
0,20,0,0,0,0,27,0,0,0,4,8
0,20,0,0,0,0,27,0,0,0,0,8
0,20,10,28,28,10,17,0,0,0,0,8
1,4,24,24,24,24,8,0,0,0,4,8
1,1,0,0,0,0,8,8,8,8,8,1
endlayer

layer
1,0,0,0,0,0,0,0,0,0,0,1
0,4,15,15,30,29,15,15,15,15,4,0
0,20,10,0,0,0,32,32,31,10,17,0
0,20,0,0,0,0,0,0,33,33,17,0
0,35,0,0,0,0,0,0,34,34,17,0
0,35,0,0,0,0,0,0,34,34,17,0
0,20,0,0,0,0,0,0,0,10,17,0
0,20,36,0,0,0,10,24,24,24,8,0
0,20,0,0,0,0,17,0,0,0,0,0
0,35,0,0,0,0,17,0,0,0,0,0
0,37,0,0,0,0,17,0,0,0,0,0
0,20,0,0,0,0,38,0,0,0,4,0
0,20,0,0,0,0,39,0,0,0,0,0
0,20,10,34,34,10,17,0,0,0,0,0
0,4,24,24,24,24,8,0,0,0,4,0
1,0,0,0,0,0,0,0,0,0,0,0
endlayer

layer
0,0,0,0,0,0,0,0,0,0,0,0
0,4,15,15,14,14,15,15,15,15,4,0
0,20,10,0,0,0,0,0,0,10,17,0
0,20,0,0,0,0,0,0,0,0,17,0
0,41,0,0,0,0,0,0,0,0,40,0
0,41,0,0,0,0,0,0,0,0,40,0
0,20,0,0,0,0,0,0,0,10,17,0
0,20,42,0,0,0,10,24,24,24,4,0
0,20,0,0,0,0,17,0,0,0,0,0
0,41,0,0,0,0,17,0,0,0,0,0
0,41,0,0,0,0,17,0,0,0,0,0
0,20,0,0,0,0,35,0,0,0,4,0
0,20,0,0,0,0,35,0,0,0,0,0
0,20,10,0,0,10,17,0,0,0,0,0
0,4,24,43,43,24,4,0,0,0,4,0
0,0,0,0,0,0,0,0,0,0,0,0
endlayer

layer
0,44,45,44,12,8,8,4,4,4,0,0
44,45,46,46,46,15,15,15,15,15,44,0
45,46,10,0,0,0,0,0,0,10,17,0
0,20,0,0,0,0,0,0,0,0,17,0
0,20,0,0,0,0,0,0,0,0,37,0
0,20,0,0,0,0,0,0,0,0,35,0
0,20,0,0,0,0,0,0,0,10,17,0
45,46,42,0,0,0,10,24,24,24,4,0
13,46,0,0,0,0,17,0,0,0,0,0
0,20,0,0,0,0,17,0,0,0,0,0
0,20,0,0,0,0,17,0,0,0,0,0
0,20,0,0,0,0,17,0,0,0,4,0
45,46,0,0,0,0,17,0,0,0,0,0
0,46,10,0,0,10,17,0,0,0,0,0
0,4,24,30,30,24,4,0,0,0,4,0
0,0,0,0,0,0,0,0,0,0,0,0
endlayer

layer
0,48,48,51,50,49,49,48,44,47,0,0
45,6,53,49,49,49,49,49,49,6,52,0
53,53,10,0,0,0,0,0,0,10,54,4
53,6,0,0,0,0,0,0,0,0,6,4
53,47,0,0,0,0,0,0,0,0,54,4
53,47,0,0,0,0,0,0,0,0,54,0
53,47,0,0,0,0,0,0,0,10,55,0
53,47,42,0,0,0,10,6,6,6,47,0
49,47,0,0,0,0,6,47,55,56,56,0
57,47,0,0,0,0,6,56,56,56,56,0
53,47,0,0,0,0,6,56,56,56,56,0
58,47,0,0,0,0,6,47,56,56,56,0
58,47,0,0,0,0,6,55,56,56,56,0
0,57,10,0,0,10,6,56,56,56,56,0
0,59,59,57,57,6,13,56,56,56,56,0
0,0,0,0,0,13,0,0,0,0,0,0
endlayer

layer
0,0,0,51,51,50,0,51,51,0,0,0
0,48,48,48,49,6,52,50,60,52,51,0
56,53,6,13,13,13,13,13,13,6,52,0
62,49,54,0,0,0,0,0,0,45,61,52
53,53,54,0,0,0,0,0,0,45,61,52
53,6,54,0,0,0,0,0,0,45,49,52
58,6,54,0,0,45,44,44,44,59,52,51
0,58,6,0,0,45,6,55,6,56,0,0
0,58,54,0,0,45,61,0,0,0,0,0
0,50,54,0,0,45,57,0,0,0,0,0
51,59,54,0,0,45,57,0,0,0,0,0
58,53,54,0,0,45,57,0,0,0,0,0
59,59,54,0,0,45,61,0,0,0,0,0
0,0,58,44,44,6,57,0,0,0,0,0
0,0,0,58,57,57,52,0,0,0,0,0
0,0,0,0,58,59,0,0,0,0,0,0
endlayer

layer
0,0,0,0,0,0,0,0,0,0,0,0
0,0,0,0,0,51,0,0,0,0,0,0
0,51,50,50,50,50,50,50,51,51,0,0
0,51,58,60,60,60,60,60,50,52,51,0
0,58,60,60,60,60,60,60,60,52,51,0
0,59,60,60,60,60,61,53,60,52,0,0
0,51,53,60,60,60,52,52,52,0,0,0
0,51,60,60,60,60,52,51,0,0,0,0
0,51,53,60,60,60,52,0,0,0,0,0
0,51,53,60,60,60,51,0,0,0,0,0
0,51,51,60,60,53,51,0,0,0,0,0
0,51,51,60,60,53,0,0,0,0,0,0
0,0,51,60,60,52,0,0,0,0,0,0
0,0,0,51,59,59,0,0,0,0,0,0
0,0,0,0,0,0,0,0,0,0,0,0
0,0,0,0,0,0,0,0,0,0,0,0
endlayer

layer
0,0,0,0,0,0,0,0,0,0,0,0
0,0,0,0,0,0,0,0,0,0,0,0
0,0,0,0,0,0,0,0,0,0,0,0
0,0,0,0,0,0,0,0,0,0,0,0
0,0,0,0,0,0,0,0,0,0,0,0
0,0,0,0,0,0,0,0,0,0,0,0
0,0,0,0,0,0,0,0,0,0,0,0
0,0,42,0,0,0,0,0,0,0,0,0
0,0,0,0,0,0,0,0,0,0,0,0
0,0,0,0,0,0,0,0,0,0,0,0
0,0,0,0,0,0,0,0,0,0,0,0
0,0,0,0,0,0,0,0,0,0,0,0
0,0,0,0,0,0,0,0,0,0,0,0
0,0,0,0,0,0,0,0,0,0,0,0
0,0,0,0,0,0,0,0,0,0,0,0
0,0,0,0,0,0,0,0,0,0,0,0
endlayer

