
# Created by Ruins mod version 16.7 Ingame Parser
# authoring Player: lafuller

weight=1
embed_into_distance=4
acceptable_target_blocks=
unacceptable_target_blocks=flowing_water,water,flowing_lava,lava,ice,bedrock,netherrack,nether_brick,nether_brick_fence,soul_sand,quartz_ore,gravel,end_stone,obsidian,iron_bars,cloud,flesh,ash_block,slime_grass,slime_congealed,slime_dirt
biomesToSpawnIn=plains,prarie,meadow
dimensions=14,18,14
allowable_overhang=0
max_leveling=4
leveling_buffer=-1
preserve_water=0
preserve_lava=0

rule1=0,100,preserveBlock
rule2=0,100,stonebrick-0,stonebrick-0,stonebrick-0,stonebrick-1,stonebrick-2,stonebrick-2,stone-5,stone-6,cobblestone
rule3=0,100,minecraft:stained_hardened_clay-8
rule4=0,100,minecraft:hardened_clay-0
rule5=0,100,minecraft:stone_brick_stairs-0
rule6=0,100,stonebrick-0,stonebrick-0,stonebrick-0,stonebrick-0,stonebrick-1,stonebrick-2,stonebrick-2,stone-5,stone-6,cobblestone,gravel
rule7=0,100,minecraft:dirt-0
rule8=0,100,minecraft:stone_brick_stairs-1
rule9=0,100,minecraft:cobblestone_wall-0
rule10=0,100,minecraft:log-0
rule11=0,100,minecraft:wooden_slab-8
rule12=0,100,minecraft:stone-4
rule13=0,100,minecraft:ladder-4
rule14=0,100,minecraft:stone_brick_stairs-2
rule15=0,100,minecraft:stone_brick_stairs-3
rule16=0,100,web,air,air,air,air
rule17=0,100,minecraft:grass-0
rule18=0,100,minecraft:stone_brick_stairs-5
rule19=0,100,minecraft:stone_brick_stairs-7
rule20=0,100,minecraft:planks-1
rule21=0,100,minecraft:planks-0
rule22=0,100,minecraft:oak_stairs-1
rule23=0,100,minecraft:trapdoor-7
rule24=0,100,minecraft:planks-2
rule25=0,100,minecraft:birch_stairs-1
rule26=0,100,minecraft:birch_stairs-0
rule27=0,100,minecraft:birch_stairs-7
rule28=0,100,minecraft:crafting_table-0
rule29=0,100,ChestGenHook:chests/spawn_bonus_chest:5-5
rule30=0,100,fence_gate-4
rule31=0,100,minecraft:cauldron-0
rule32=0,100,minecraft:birch_stairs-4
rule33=0,100,minecraft:birch_stairs-3
rule34=0,100,minecraft:stone-6
rule35=0,100,minecraft:birch_stairs-2
rule36=0,100,minecraft:trapdoor-9
rule37=0,100,minecraft:birch_stairs-5
rule38=0,100,minecraft:fence-0
rule39=0,100,minecraft:red_flower-3
rule40=0,100,minecraft:birch_door-2
rule41=0,100,minecraft:stone_brick_stairs-6
rule42=0,100,minecraft:spruce_fence_gate-1
rule43=0,100,IInventory;furnace;coal#1#1#1-3
rule44=0,100,minecraft:spruce_fence_gate-2
rule45=0,100,minecraft:spruce_fence_gate-0
rule46=0,100,minecraft:birch_door-9
rule47=0,100,minecraft:birch_door-8
rule48=0,100,minecraft:oak_stairs-2
rule49=0,100,minecraft:oak_stairs-3
rule50=0,100,minecraft:oak_stairs-7
rule51=0,100,minecraft:spruce_stairs-6
rule52=0,100,minecraft:wooden_slab-9
rule53=0,100,minecraft:oak_stairs-0
rule54=0,100,minecraft:fence_gate-2
rule55=0,100,minecraft:fence_gate-1
rule56=0,100,minecraft:wooden_slab-13
rule57=0,100,minecraft:spruce_stairs-4
rule58=0,100,minecraft:spruce_stairs-0
rule59=0,100,minecraft:spruce_stairs-7
rule60=0,100,minecraft:dark_oak_stairs-7
rule61=0,100,minecraft:carpet-8
rule62=0,100,minecraft:carpet-7
rule63=0,100,minecraft:spruce_stairs-5
rule64=0,100,minecraft:dark_oak_stairs-3
rule65=0,100,minecraft:double_wooden_slab-1
rule66=0,100,minecraft:spruce_stairs-3
rule67=0,100,minecraft:spruce_stairs-1
rule68=0,100,minecraft:fence_gate-0
rule69=0,100,minecraft:fence_gate-3
rule70=0,100,minecraft:wooden_slab-5
rule71=0,100,minecraft:double_wooden_slab-5
rule72=0,100,minecraft:dark_oak_stairs-4
rule73=0,100,minecraft:planks-5
rule74=0,100,minecraft:dark_oak_stairs-0
rule75=0,100,minecraft:dark_oak_stairs-1
rule76=0,100,minecraft:wooden_slab-1
rule77=0,100,minecraft:trapdoor-3
rule78=0,100,minecraft:dark_oak_stairs-5
rule79=0,100,minecraft:trapdoor-10
rule80=0,100,spruce_fence_gate-2
rule81=0,100,spruce_fence-0

layer
1,1,1,1,1,1,1,1,1,1,1,1,1,1
1,1,1,1,1,1,1,1,2,2,2,2,1,1
1,1,1,2,2,2,2,2,3,3,3,3,2,1
1,1,2,3,3,3,3,3,3,4,4,3,2,1
1,1,2,3,3,4,4,4,4,3,4,3,2,1
1,1,2,3,4,3,3,3,3,4,3,3,2,1
1,1,2,3,4,4,4,3,3,3,4,3,2,1
5,2,2,3,3,3,3,4,3,4,4,2,2,1
6,2,2,2,2,2,3,4,4,4,3,2,2,5
6,2,2,7,7,2,3,3,3,3,3,2,2,6
6,2,2,7,7,7,2,2,2,2,2,2,2,6
6,2,2,7,7,7,7,7,7,7,7,2,2,6
6,2,2,7,7,7,7,7,7,7,7,2,2,6
6,2,2,7,7,7,7,7,7,7,7,2,2,6
6,2,2,2,2,2,2,7,7,7,7,2,2,6
8,8,1,1,1,1,2,2,2,2,2,2,2,6
1,1,1,1,1,1,1,1,1,1,1,2,2,6
1,1,1,1,1,1,1,1,1,1,1,8,8,8
endlayer

layer
1,1,1,1,1,1,1,1,1,1,1,1,1,1
1,1,1,1,1,1,1,1,6,9,6,6,1,1
1,1,1,6,9,6,9,6,10,11,11,10,6,1
1,1,6,10,0,0,0,0,0,0,0,0,9,1
1,1,9,11,0,0,0,0,0,0,0,0,6,1
1,1,6,11,0,0,0,0,0,0,0,0,6,1
1,1,9,11,0,0,0,0,0,0,0,0,9,1
1,1,6,10,13,13,0,0,0,12,12,10,6,1
5,5,6,6,6,6,0,0,0,0,0,6,6,1
15,6,6,7,7,6,10,0,0,0,0,6,6,14
15,6,6,7,7,7,6,6,6,6,6,6,6,14
15,6,6,7,7,7,7,7,7,7,7,6,6,14
15,6,6,7,7,7,7,7,7,7,7,6,6,14
15,6,6,7,7,7,7,7,7,7,7,6,6,14
8,8,6,6,6,6,6,7,7,7,7,6,6,14
1,1,1,1,1,1,6,6,6,6,6,6,6,14
1,1,1,1,1,1,1,1,1,1,1,8,8,8
1,1,1,1,1,1,1,1,1,1,1,1,1,1
endlayer

layer
1,1,1,1,1,1,1,1,1,1,1,1,1,1
1,1,1,1,1,1,1,1,6,9,6,6,1,1
1,1,1,6,9,6,9,6,10,0,16,10,6,1
1,1,6,10,16,0,0,0,0,0,0,16,9,1
1,1,9,0,0,0,0,0,0,0,0,0,6,1
1,1,6,0,0,0,0,0,0,0,0,0,6,1
1,1,9,0,0,0,0,0,0,0,0,16,9,1
1,1,6,10,13,13,0,0,0,0,0,10,6,1
1,1,6,6,6,6,0,0,0,0,0,6,1,1
1,5,6,7,7,6,10,16,0,0,16,9,1,1
1,15,6,7,7,7,6,6,6,6,6,6,5,1
1,15,6,7,7,7,7,7,7,7,7,6,14,1
1,15,6,7,7,7,7,7,7,7,7,6,14,1
1,8,6,7,7,7,7,7,7,7,7,6,14,1
1,1,6,6,6,6,6,7,7,7,7,6,14,1
1,1,1,1,1,1,6,6,6,6,6,6,8,1
1,1,1,1,1,1,1,1,1,1,1,1,1,1
1,1,1,1,1,1,1,1,1,1,1,1,1,1
endlayer

layer
1,1,1,1,1,1,1,1,1,1,1,1,1,1
1,1,1,1,1,1,1,1,6,9,6,6,1,1
1,1,1,6,9,6,9,6,10,16,16,10,6,1
1,1,6,10,16,16,0,0,0,0,16,16,9,1
1,1,9,16,0,0,0,0,0,0,0,16,6,1
1,1,6,16,0,0,0,0,0,0,0,16,6,1
1,1,9,16,0,0,0,0,0,0,0,16,9,1
1,1,6,10,13,13,0,0,0,52,52,10,6,1
1,1,6,6,6,6,16,16,0,0,16,6,1,1
1,1,6,7,7,6,10,16,16,16,16,9,1,1
1,1,15,17,17,17,6,6,6,6,6,6,1,1
1,1,15,17,17,17,7,7,7,7,7,14,1,1
1,1,15,17,17,17,7,7,7,7,7,14,1,1
1,1,18,17,17,17,7,7,7,7,7,14,1,1
1,1,19,9,9,9,6,7,7,7,6,14,1,1
1,1,1,1,1,1,6,6,6,6,6,6,1,1
1,1,1,1,1,1,1,1,1,1,1,1,1,1
1,1,1,1,1,1,1,1,1,1,1,1,1,1
endlayer

layer
1,1,1,1,1,1,1,1,1,1,1,1,1,1
1,1,1,1,1,1,1,1,6,6,6,6,1,1
1,1,1,6,6,6,6,6,20,20,20,10,6,1
1,1,6,20,20,20,20,20,20,21,21,20,6,1
1,1,6,20,20,21,21,21,21,21,20,20,6,1
1,1,6,20,21,20,20,20,20,20,21,20,6,1
1,1,6,20,22,22,21,20,20,20,21,20,6,1
1,1,6,20,13,13,20,21,20,21,20,10,6,1
1,0,6,6,6,6,20,21,21,21,20,6,1,1
0,0,19,17,17,6,20,20,20,20,20,6,1,1
0,0,0,23,23,0,6,6,6,6,6,6,1,1
0,0,0,0,0,15,17,17,17,17,14,1,1,1
0,0,0,0,0,15,17,17,17,17,14,1,1,1
1,0,19,0,0,15,17,17,17,17,14,1,1,1
1,1,6,6,6,6,6,17,17,17,14,1,1,1
1,1,1,1,1,1,6,9,9,9,6,1,1,1
1,1,1,1,1,1,1,1,1,1,1,1,1,1
1,1,1,1,1,1,1,1,1,1,1,1,1,1
endlayer

layer
1,1,1,1,1,1,0,0,0,0,0,1,1,1
1,1,1,0,0,0,0,27,26,25,24,24,1,1
1,1,0,27,24,25,24,10,0,29,28,10,24,1
1,0,32,10,0,0,0,0,0,0,0,31,24,0
1,0,24,30,0,0,0,0,0,0,0,34,33,0
1,0,35,30,0,0,0,0,0,0,0,34,33,0
0,0,24,30,0,0,0,0,0,0,0,36,24,0
0,0,24,10,13,13,0,0,0,0,0,10,37,0
0,0,38,24,24,24,0,0,0,0,0,24,0,0
0,0,38,39,39,25,10,0,0,0,10,24,0,0
0,0,0,0,0,0,24,40,40,24,24,38,0,0
0,0,0,0,0,0,0,0,0,0,0,0,0,0
0,0,0,0,0,0,0,0,0,0,0,0,0,0
0,0,38,0,0,0,0,0,0,0,0,0,0,1
1,0,38,0,0,15,6,0,0,0,6,0,0,1
1,1,0,0,0,0,19,6,6,6,41,0,1,1
1,1,1,0,0,0,0,0,0,0,0,1,1,1
1,1,1,1,1,0,0,0,0,1,1,1,1,1
endlayer

layer
1,1,1,1,0,0,0,0,0,0,0,0,1,1
1,1,0,0,0,0,0,24,24,42,24,24,0,1
1,0,0,24,24,42,24,10,0,0,0,10,24,0
1,0,24,10,0,0,0,0,0,0,0,43,24,0
0,0,24,62,0,0,0,0,0,0,0,0,44,0
0,0,45,62,0,0,0,0,0,0,0,0,44,0
0,0,24,62,0,0,0,0,0,0,0,0,24,0
0,0,24,10,13,13,0,0,0,0,0,10,24,0
0,0,38,24,24,24,0,0,0,0,0,24,0,0
0,0,38,0,0,24,10,0,0,0,10,24,0,0
0,0,0,0,0,0,24,47,46,24,24,38,0,0
0,0,0,0,0,0,0,0,0,0,0,0,0,0
0,0,0,0,0,0,0,0,0,0,0,0,0,0
0,0,38,0,0,0,0,0,0,0,0,0,0,0
0,0,38,0,0,0,38,0,0,0,38,0,0,0
1,0,0,0,0,0,0,0,0,0,0,0,0,1
1,1,0,0,0,0,0,0,0,0,0,0,1,1
1,1,1,0,0,0,0,0,0,0,0,1,1,1
endlayer

layer
1,1,0,0,0,0,0,0,0,0,0,0,0,1
1,0,0,0,0,0,0,24,24,38,24,24,0,0
0,0,0,24,24,38,24,10,0,0,0,10,24,0
0,0,24,10,0,0,0,0,0,0,0,9,24,0
0,0,24,0,0,0,0,0,0,0,0,0,38,0
0,0,38,0,0,0,0,0,0,0,0,0,38,0
0,0,24,0,0,0,0,0,0,0,0,36,24,0
0,0,24,10,13,13,0,0,0,0,0,10,24,0
0,0,38,24,24,24,0,0,0,0,0,24,0,0
0,0,38,0,0,24,10,0,0,0,10,24,0,0
0,0,0,0,0,0,24,38,38,24,24,38,0,0
0,0,0,0,0,0,0,0,0,0,0,0,0,0
0,0,0,0,0,0,0,0,0,0,0,0,0,0
0,0,38,0,0,0,0,0,0,0,0,0,0,0
0,0,38,0,0,0,38,0,0,0,38,0,0,0
0,0,0,0,0,0,0,0,0,0,0,0,0,0
1,0,0,0,0,0,0,0,0,0,0,0,0,1
1,1,0,0,0,0,0,0,0,0,0,0,1,1
endlayer

layer
1,0,0,0,0,0,0,0,0,0,0,0,0,0
0,0,0,0,0,0,0,49,21,21,21,48,0,0
0,0,0,50,24,24,21,10,0,0,0,10,48,0
0,0,53,10,52,52,51,0,0,0,0,9,21,0
0,0,21,52,52,52,51,0,0,0,0,0,21,0
0,0,21,52,52,52,51,0,0,0,0,0,21,0
0,0,21,52,52,52,51,0,0,0,0,0,21,0
0,0,50,10,13,13,51,0,0,0,0,10,21,0
0,0,38,21,21,21,51,0,0,0,0,24,0,0
0,0,38,0,0,21,10,0,0,0,10,24,0,0
0,0,54,0,0,0,24,24,24,24,24,38,0,0
0,0,54,0,0,0,0,0,0,0,0,0,0,0
0,0,54,0,0,0,0,0,0,0,0,0,0,0
0,0,38,0,0,0,0,0,0,0,0,0,0,0
0,0,38,55,55,55,38,0,0,0,38,0,0,0
0,0,0,0,0,0,0,0,0,0,0,0,0,0
0,0,0,0,0,0,0,0,0,0,0,0,0,0
1,0,0,0,0,0,0,0,0,0,0,0,0,1
endlayer

layer
0,0,0,0,0,0,56,56,56,56,0,0,0,0
0,0,0,0,52,52,59,58,57,57,20,20,0,0
0,0,60,20,21,21,21,10,0,0,0,10,20,0
0,56,20,10,61,61,81,0,0,0,0,9,20,56
0,60,20,0,62,62,80,0,0,0,0,0,20,51
0,60,20,0,62,62,80,0,0,0,0,0,20,63
0,64,20,0,0,0,80,0,0,0,0,0,20,0
0,59,20,10,13,13,80,0,0,0,0,10,20,0
0,63,65,20,20,20,81,0,0,0,0,20,63,0
0,0,66,65,65,20,10,0,0,0,10,20,0,0
0,0,0,67,65,65,21,21,21,21,21,20,0,0
0,0,0,0,66,51,68,0,0,0,54,52,0,0
0,0,0,0,0,51,68,0,0,0,54,52,0,0
0,0,0,0,0,66,68,0,0,0,54,52,0,0
0,0,0,0,0,66,38,69,69,69,38,52,0,0
0,0,0,0,0,0,52,52,52,52,52,0,0,0
0,0,0,0,0,0,0,0,0,0,0,0,0,0
0,0,0,0,0,0,0,0,0,0,0,0,0,0
endlayer

layer
0,0,0,0,70,71,71,71,71,70,70,0,0,0
0,0,0,74,72,74,72,73,60,73,72,71,70,0
0,0,73,73,73,20,20,20,20,63,63,20,71,70
0,70,73,20,0,0,0,0,0,0,0,20,71,70
0,75,73,51,0,0,0,0,0,0,0,59,20,71
0,64,20,51,0,0,0,0,0,0,0,59,20,71
0,75,73,51,0,0,0,0,0,0,0,59,20,71
0,64,73,20,13,13,0,0,0,0,0,20,20,70
0,64,75,73,20,20,57,0,0,0,57,20,71,0
0,0,0,64,75,20,20,57,57,57,20,20,71,0
0,0,0,0,76,65,20,20,20,20,20,20,70,0
0,0,0,0,0,67,65,65,65,65,65,76,0,0
0,0,0,0,0,0,76,67,65,65,67,0,0,0
0,0,0,0,0,0,76,76,77,76,76,0,0,0
0,0,0,0,0,0,76,76,76,76,76,0,0,0
0,0,0,0,0,0,0,0,0,0,0,0,0,0
0,0,0,0,0,0,0,0,0,0,0,0,0,0
0,0,0,0,0,0,0,0,0,0,0,0,0,0
endlayer

layer
0,0,0,0,0,0,0,0,0,0,0,0,0,0
0,0,0,0,0,70,74,70,74,70,70,0,0,0
0,0,0,70,74,60,60,72,72,74,72,70,0,0
0,0,74,60,0,0,0,60,72,72,72,71,70,0
0,0,73,60,0,0,0,0,0,0,0,56,70,0
0,64,73,60,0,0,0,0,0,0,0,56,71,0
0,70,71,60,0,0,0,0,0,0,0,56,71,0
0,0,70,73,0,0,0,0,0,0,0,56,70,0
0,0,0,70,75,73,0,0,0,0,0,71,0,0
0,0,0,0,0,64,60,60,78,78,71,70,0,0
0,0,0,0,0,64,75,75,56,78,71,70,0,0
0,0,0,0,0,0,0,70,70,70,70,0,0,0
0,0,0,0,0,0,0,0,0,0,0,0,0,0
0,0,0,0,0,0,0,0,0,0,0,0,0,0
0,0,0,0,0,0,0,0,0,0,0,0,0,0
0,0,0,0,0,0,0,0,0,0,0,0,0,0
0,0,0,0,0,0,0,0,0,0,0,0,0,0
0,0,0,0,0,0,0,0,0,0,0,0,0,0
endlayer

layer
0,0,0,0,0,0,0,0,0,0,0,0,0,0
0,0,0,0,0,0,0,0,0,0,0,0,0,0
0,0,0,0,0,0,0,0,0,0,0,0,0,0
0,0,0,0,70,70,70,74,74,70,0,9,0,0
0,0,0,70,74,74,78,78,78,78,74,0,0,0
0,0,0,70,64,56,56,56,56,56,60,70,0,0
0,0,0,70,64,56,56,56,79,56,60,70,0,0
0,0,0,0,70,64,56,56,56,56,70,70,0,0
0,0,0,0,0,70,75,64,72,71,70,0,0,0
0,0,0,0,0,0,0,75,75,70,0,0,0,0
0,0,0,0,0,0,0,0,0,0,0,0,0,0
0,0,0,0,0,0,0,0,0,0,0,0,0,0
0,0,0,0,0,0,0,0,0,0,0,0,0,0
0,0,0,0,0,0,0,0,0,0,0,0,0,0
0,0,0,0,0,0,0,0,0,0,0,0,0,0
0,0,0,0,0,0,0,0,0,0,0,0,0,0
0,0,0,0,0,0,0,0,0,0,0,0,0,0
0,0,0,0,0,0,0,0,0,0,0,0,0,0
endlayer

layer
0,0,0,0,0,0,0,0,0,0,0,0,0,0
0,0,0,0,0,0,0,0,0,0,0,0,0,0
0,0,0,0,0,0,0,0,0,0,0,0,0,0
0,0,0,0,0,0,0,0,0,0,0,9,0,0
0,0,0,0,0,0,0,0,0,0,0,0,0,0
0,0,0,0,0,0,0,0,0,0,0,0,0,0
0,0,0,0,0,0,0,0,0,0,0,0,0,0
0,0,0,0,0,0,0,0,0,0,0,0,0,0
0,0,0,0,0,0,0,0,0,0,0,0,0,0
0,0,0,0,0,0,0,0,0,0,0,0,0,0
0,0,0,0,0,0,0,0,0,0,0,0,0,0
0,0,0,0,0,0,0,0,0,0,0,0,0,0
0,0,0,0,0,0,0,0,0,0,0,0,0,0
0,0,0,0,0,0,0,0,0,0,0,0,0,0
0,0,0,0,0,0,0,0,0,0,0,0,0,0
0,0,0,0,0,0,0,0,0,0,0,0,0,0
0,0,0,0,0,0,0,0,0,0,0,0,0,0
0,0,0,0,0,0,0,0,0,0,0,0,0,0
endlayer

