
# Created by Ruins mod version 16.7 Ingame Parser
# authoring Player: lafuller

weight=1
embed_into_distance=13
acceptable_target_blocks=water,waterlily
unacceptable_target_blocks=
biomesToSpawnIn=swampland,jungle,marsh,bog,wetland,mini_jungle,lush_swamp,green_swamp,dead_swamp,tropical_island,land_of_lakes
dimensions=24,13,12
allowable_overhang=0
max_leveling=2
leveling_buffer=-1
preserve_water=0
preserve_lava=0

rule1=0,100,preserveBlock
rule2=0,100,minecraft:log2-1
rule3=0,100,minecraft:log2-9
rule4=0,100,minecraft:planks-1
rule5=0,100,minecraft:log2-5
rule6=0,100,minecraft:wooden_slab-9
rule7=0,100,minecraft:spruce_fence-0
rule8=0,100,minecraft:log-3
rule9=0,100,minecraft:ladder-2
rule10=0,100,minecraft:log-7
rule11=0,100,minecraft:wooden_slab-11
rule12=0,100,minecraft:spruce_stairs-7
rule13=0,100,minecraft:spruce_stairs-0
rule14=0,100,minecraft:wooden_slab-1
rule15=0,100,minecraft:spruce_stairs-2
rule16=0,100,minecraft:spruce_stairs-1
rule17=0,100,minecraft:spruce_stairs-3
rule18=0,100,minecraft:spruce_fence_gate-2
rule19=0,100,minecraft:ladder-4
rule20=0,100,minecraft:trapdoor-4
rule21=0,100,minecraft:dark_oak_fence-0
rule22=0,100,minecraft:spruce_stairs-4
rule23=0,100,minecraft:spruce_stairs-6
rule24=0,100,minecraft:spruce_stairs-5
rule25=0,100,minecraft:wooden_slab-13
rule26=0,100,minecraft:log-11
rule27=0,100,minecraft:carpet-8
rule28=0,100,minecraft:carpet-7
rule29=0,100,minecraft:wooden_slab-5
rule30=0,100,minecraft:dark_oak_stairs-0
rule31=0,100,minecraft:planks-5
rule32=0,100,minecraft:spruce_fence_gate-3
rule33=0,100,minecraft:dark_oak_stairs-6
rule34=0,100,minecraft:spruce_fence_gate-1
rule35=0,100,minecraft:dark_oak_stairs-5
rule36=0,100,minecraft:dark_oak_stairs-7
rule37=0,100,minecraft:dark_oak_stairs-2
rule38=0,100,minecraft:dark_oak_stairs-1

layer
1,1,1,1,1,1,1,1,1,1,1,1
1,1,1,1,1,1,1,1,1,1,1,1
1,1,1,1,1,1,1,1,1,1,1,1
1,1,1,1,1,1,1,2,1,1,1,1
1,1,2,1,1,1,1,1,1,1,1,1
1,1,1,1,1,1,1,1,1,1,1,1
1,1,1,1,1,1,2,1,1,1,1,1
1,1,1,1,1,1,1,1,2,1,1,1
1,1,1,2,1,1,1,1,1,1,1,1
1,1,1,1,1,1,1,1,1,1,1,1
1,1,1,1,1,1,1,1,2,1,1,1
1,1,1,1,1,1,1,1,1,1,1,1
1,1,1,1,1,1,1,1,1,1,1,1
endlayer

layer
1,1,1,1,1,1,1,1,1,1,1,1
1,1,1,1,1,1,1,1,1,1,1,1
1,1,1,1,1,1,1,1,1,1,1,1
1,1,1,1,1,1,1,2,1,1,1,1
1,1,2,1,1,1,1,1,1,1,1,1
1,1,1,1,1,1,1,1,1,1,1,1
1,1,1,1,1,1,2,1,1,1,1,1
1,1,1,1,1,1,1,1,2,1,1,1
1,1,1,2,1,1,1,1,1,1,1,1
1,1,1,1,1,1,1,1,1,1,1,1
1,1,1,1,1,1,1,1,2,1,1,1
1,1,1,1,1,1,1,1,1,1,1,1
1,1,1,1,1,1,1,1,1,1,1,1
endlayer

layer
1,1,1,1,1,1,1,1,1,1,1,1
1,1,1,1,1,1,1,1,1,1,1,1
1,1,1,1,1,1,1,1,1,1,1,1
1,1,1,1,1,1,1,2,1,1,1,1
1,1,2,1,1,1,1,1,1,1,1,1
1,1,1,1,1,1,1,1,1,1,1,1
1,1,1,1,1,1,2,1,1,1,1,1
1,1,1,1,1,1,1,1,2,1,1,1
1,1,1,2,1,1,1,1,1,1,1,1
1,1,1,1,1,1,1,1,1,1,1,1
1,1,1,1,1,1,1,1,2,1,1,1
1,1,1,1,1,1,1,1,1,1,1,1
1,1,1,1,1,1,1,1,1,1,1,1
endlayer

layer
1,1,1,1,1,1,1,1,1,1,1,1
1,1,1,1,1,1,1,1,1,1,1,1
1,1,1,1,1,1,1,1,1,1,1,1
1,1,1,1,1,1,1,2,1,1,1,1
1,1,2,1,1,1,1,1,1,1,1,1
1,1,1,1,1,1,1,1,1,1,1,1
1,1,1,1,1,1,2,1,1,1,1,1
1,1,1,1,1,1,1,1,2,1,1,1
1,1,1,2,1,1,1,1,1,1,1,1
1,1,1,1,1,1,1,1,1,1,1,1
1,1,1,1,1,1,1,1,2,1,1,1
1,1,1,1,1,1,1,1,1,1,1,1
1,1,1,1,1,1,1,1,1,1,1,1
endlayer

layer
1,1,1,1,1,1,1,1,1,1,1,1
1,1,1,1,1,1,1,1,1,1,1,1
1,1,1,1,1,1,1,1,1,1,1,1
1,1,1,1,1,1,1,2,1,1,1,1
1,1,2,1,1,1,1,1,1,1,1,1
1,1,1,1,1,1,1,1,1,1,1,1
1,1,1,1,1,1,2,1,1,1,1,1
1,1,1,1,1,1,1,1,2,1,1,1
1,1,1,2,1,1,1,1,1,1,1,1
1,1,1,1,1,1,1,1,1,1,1,1
1,1,1,1,1,1,1,1,2,1,1,1
1,1,1,1,1,1,1,1,1,1,1,1
1,1,1,1,1,1,1,1,1,1,1,1
endlayer

layer
1,1,1,1,1,1,1,1,1,1,1,1
1,1,1,1,1,1,1,1,1,1,1,1
1,1,1,1,1,1,1,1,1,1,1,1
1,1,1,1,1,1,1,2,1,1,1,1
1,1,2,1,1,1,1,1,1,1,1,1
1,1,1,1,1,1,1,1,1,1,1,1
1,1,1,1,1,1,2,1,1,1,1,1
1,1,1,1,1,1,1,1,2,1,1,1
1,1,1,2,1,1,1,1,1,1,1,1
1,1,1,1,1,1,1,1,1,1,1,1
1,1,1,1,1,1,1,1,2,1,1,1
1,1,1,1,1,1,1,1,1,1,1,1
1,1,1,1,1,1,1,1,1,1,1,1
endlayer

layer
1,1,1,1,1,1,1,1,1,1,1,1
1,1,1,1,1,1,1,1,1,1,1,1
1,1,1,1,1,1,1,1,1,1,1,1
1,1,1,1,1,1,1,2,1,1,1,1
1,1,2,1,1,1,1,1,1,1,1,1
1,1,1,1,1,1,1,1,1,1,1,1
1,1,1,1,1,1,2,1,1,1,1,1
1,1,1,1,1,1,1,1,2,1,1,1
1,1,1,2,1,1,1,1,1,1,1,1
1,1,1,1,1,1,1,1,1,1,1,1
1,1,1,1,1,1,1,1,2,1,1,1
1,1,1,1,1,1,1,1,1,1,1,1
1,1,1,1,1,1,1,1,1,1,1,1
endlayer

layer
1,1,1,1,1,1,1,1,1,1,1,1
1,1,1,1,1,1,1,1,1,1,1,1
1,1,1,1,1,1,1,1,1,1,1,1
1,1,1,1,1,1,1,2,1,1,1,1
1,1,2,1,1,1,1,1,1,1,1,1
1,1,1,1,1,1,1,1,1,1,1,1
1,1,1,1,1,1,2,1,1,1,1,1
1,1,1,1,1,1,1,1,2,1,1,1
1,1,1,2,1,1,1,1,1,1,1,1
1,1,1,1,1,1,1,1,1,1,1,1
1,1,1,1,1,1,1,1,2,1,1,1
1,1,1,1,1,1,1,1,1,1,1,1
1,1,1,1,1,1,1,1,1,1,1,1
endlayer

layer
1,1,1,1,1,1,1,1,1,1,1,1
1,1,1,1,1,1,1,1,1,1,1,1
1,1,1,1,1,1,1,1,1,1,1,1
1,1,1,1,1,1,1,2,1,1,1,1
1,1,2,1,1,1,1,1,1,1,1,1
1,1,1,1,1,1,1,1,1,1,1,1
1,1,1,1,1,1,2,1,1,1,1,1
1,1,1,1,1,1,1,1,2,1,1,1
1,1,1,2,1,1,1,1,1,1,1,1
1,1,1,1,1,1,1,1,1,1,1,1
1,1,1,1,1,1,1,1,2,1,1,1
1,1,1,1,1,1,1,1,1,1,1,1
1,1,1,1,1,1,1,1,1,1,1,1
endlayer

layer
1,1,1,1,1,1,1,1,1,1,1,1
1,1,1,1,1,1,1,1,1,1,1,1
1,1,1,1,1,1,1,1,1,1,1,1
1,1,1,1,1,1,1,2,1,1,1,1
1,1,2,1,1,1,1,1,1,1,1,1
1,1,1,1,1,1,1,1,1,1,1,1
1,1,1,1,1,1,2,1,1,1,1,1
1,1,1,1,1,1,1,1,2,1,1,1
1,1,1,2,1,1,1,1,1,1,1,1
1,1,1,1,1,1,1,1,1,1,1,1
1,1,1,1,1,1,1,1,2,1,1,1
1,1,1,1,1,1,1,1,1,1,1,1
1,1,1,1,1,1,1,1,1,1,1,1
endlayer

layer
1,1,1,1,1,1,1,1,1,1,1,1
1,1,1,1,1,1,1,1,1,1,1,1
1,1,1,1,1,1,1,1,1,1,1,1
1,1,1,1,1,1,1,2,1,1,1,1
1,1,2,1,1,1,1,1,1,1,1,1
1,1,1,1,1,1,1,1,1,1,1,1
1,1,1,1,1,1,2,1,1,1,1,1
1,1,1,1,1,1,1,1,2,1,1,1
1,1,1,2,1,1,1,1,1,1,1,1
1,1,1,1,1,1,1,1,1,1,1,1
1,1,1,1,1,1,1,1,2,1,1,1
1,1,1,1,1,1,1,1,1,1,1,1
1,1,1,1,1,1,1,1,1,1,1,1
endlayer

layer
1,1,1,1,1,1,1,1,1,1,1,1
1,1,1,1,1,1,1,1,1,1,1,1
1,1,1,1,1,1,1,1,1,1,1,1
1,1,1,1,1,1,1,2,1,1,1,1
1,1,2,1,1,1,1,1,1,1,1,1
1,1,1,1,1,1,1,1,1,1,1,1
1,1,1,1,1,1,2,1,1,1,1,1
1,1,1,1,1,1,1,1,2,1,1,1
1,1,1,2,1,1,1,1,1,1,1,1
1,1,1,1,1,1,1,1,1,1,1,1
1,1,1,1,1,1,1,1,2,1,1,1
1,1,1,1,1,1,1,1,1,1,1,1
1,1,1,1,1,1,1,1,1,1,1,1
endlayer

layer
1,1,1,1,1,1,1,1,1,1,1,1
1,1,1,1,1,1,1,1,1,1,1,1
1,1,1,1,1,1,1,1,1,1,1,1
1,1,1,1,1,1,1,2,1,1,1,1
1,3,2,3,3,3,3,3,3,3,3,1
1,1,1,5,4,4,4,1,1,1,1,1
1,1,1,5,4,6,2,1,1,1,1,1
1,1,1,5,4,4,4,1,2,1,1,1
1,3,3,2,3,3,3,3,3,3,3,1
1,1,1,1,1,1,1,1,1,1,1,1
1,1,1,1,1,1,1,1,2,1,1,1
1,1,1,1,1,1,1,1,1,1,1,1
1,1,1,1,1,1,1,1,1,1,1,1
endlayer

layer
1,1,1,1,1,1,1,7,1,1,1,1
1,1,1,1,1,1,1,5,1,7,1,1
1,1,7,1,1,1,1,5,1,5,1,1
1,1,5,1,1,1,1,5,1,5,1,1
1,1,5,1,1,1,1,5,1,5,1,1
1,1,5,1,1,1,1,5,1,5,1,1
1,1,5,1,1,1,2,5,1,5,1,1
1,1,5,1,1,1,1,5,2,5,1,1
1,1,5,2,1,1,1,5,1,5,1,1
1,1,5,1,1,1,1,5,1,5,1,1
1,1,7,1,1,1,1,5,2,5,1,1
1,1,1,1,1,1,1,5,1,7,1,1
1,1,1,1,1,1,1,7,1,1,1,1
endlayer

layer
1,1,1,1,1,1,1,1,1,1,1,1
1,1,1,1,1,1,1,1,1,1,1,1
1,1,1,1,1,1,1,8,1,1,1,1
1,7,3,3,1,1,3,3,3,3,7,1
1,1,8,1,1,1,1,1,1,1,1,1
1,1,1,1,1,1,1,3,3,3,3,7
1,1,1,1,1,1,8,1,1,8,1,1
1,1,1,1,1,1,1,1,2,1,1,1
1,1,8,8,9,1,1,1,1,1,1,1
1,7,3,3,3,3,3,3,3,3,7,1
1,1,1,1,1,1,1,8,8,1,1,1
1,1,1,1,1,1,1,1,1,1,1,1
1,1,1,1,1,1,1,1,1,1,1,1
endlayer

layer
1,1,1,1,1,1,1,1,7,1,1,1
1,1,1,7,1,1,7,1,10,1,1,1
1,1,1,10,1,1,10,8,10,6,1,1
1,1,1,10,6,6,10,6,10,6,1,1
1,1,8,10,6,11,10,6,10,6,1,1
1,6,12,10,11,11,10,11,10,6,1,1
1,6,12,10,6,6,10,11,10,8,1,1
1,6,4,10,11,11,10,11,10,6,1,1
1,12,8,10,9,11,10,6,10,6,1,1
1,6,6,10,6,8,10,6,10,6,1,1
1,1,6,10,6,6,10,8,10,6,1,1
1,1,1,7,1,1,10,1,10,1,1,1
1,1,1,1,1,1,7,1,7,1,1,1
endlayer

layer
1,1,1,1,1,1,1,1,1,1,1,1
1,1,1,1,1,1,1,1,1,1,1,1
1,1,1,7,7,14,13,8,13,1,1,1
1,1,1,7,13,0,0,0,0,14,1,1
1,1,8,16,0,0,0,0,0,15,1,1
1,1,17,0,0,0,0,0,0,15,14,1
1,1,18,0,0,0,0,0,0,8,14,1
1,1,17,0,0,0,0,0,0,14,14,1
1,1,8,4,20,19,0,0,0,13,14,1
1,1,1,7,16,8,0,0,8,15,1,1
1,1,1,1,7,7,16,16,16,1,1,1
1,1,1,1,1,1,1,1,1,1,1,1
1,1,1,1,1,1,1,1,1,1,1,1
endlayer

layer
1,1,1,1,1,1,1,1,1,1,1,1
1,1,1,1,1,1,1,1,1,1,1,1
1,1,1,1,7,1,7,8,7,1,1,1
1,1,1,1,7,0,0,0,0,1,1,1
1,1,8,7,0,0,0,0,0,7,1,1
1,1,7,0,0,0,0,0,0,7,1,1
1,1,0,0,0,0,0,0,0,8,1,1
1,1,7,0,0,0,0,0,0,1,1,1
1,1,8,7,0,19,0,0,0,7,1,1
1,1,1,7,7,8,0,0,8,7,1,1
1,1,1,1,7,1,7,1,7,1,1,1
1,1,1,1,1,1,1,1,1,1,1,1
1,1,1,1,1,1,1,1,1,1,1,1
endlayer

layer
1,1,1,1,1,1,1,1,1,1,1,1
1,1,1,1,1,1,1,21,1,1,1,1
1,1,1,1,17,13,13,8,22,6,1,1
1,1,1,21,13,0,0,0,0,23,1,1
1,1,8,24,6,0,0,0,0,23,1,1
1,1,12,6,6,0,0,0,0,23,1,1
1,1,12,6,6,0,0,0,0,8,7,1
1,1,22,6,6,0,0,0,0,6,1,1
1,12,8,22,6,19,0,0,0,22,1,1
1,1,6,6,16,8,0,0,8,24,1,1
1,1,1,1,17,16,16,16,16,1,1,1
1,1,1,1,1,1,1,1,1,1,1,1
1,1,1,1,1,1,1,1,1,1,1,1
endlayer

layer
1,1,1,1,1,1,1,1,1,1,1,1
1,1,1,1,1,1,25,21,21,25,1,1
1,1,1,21,26,26,26,26,26,26,21,1
1,1,1,22,13,10,21,10,21,21,1,1
1,7,8,27,27,0,0,0,0,15,1,1
1,1,17,28,28,0,0,0,0,4,7,1
1,1,14,28,28,0,0,0,0,8,23,1
1,14,14,0,0,0,0,0,0,15,14,1
1,17,8,0,0,19,0,0,0,15,14,1
1,1,7,24,16,8,21,0,8,21,21,1
1,1,1,7,26,26,26,26,26,26,21,1
1,1,1,1,1,1,25,10,21,1,1,1
1,1,1,1,1,1,1,21,1,1,1,1
endlayer

layer
1,1,1,1,1,1,1,21,1,1,1,1
1,1,1,1,1,1,21,10,30,29,1,1
1,1,1,1,1,21,21,10,31,31,25,1
1,1,7,32,32,26,26,26,26,26,26,21
1,7,8,0,0,21,21,0,0,10,21,1
1,1,7,0,0,0,0,0,0,10,33,1
1,1,18,0,0,0,0,0,0,10,33,1
1,1,18,0,0,0,0,0,0,10,25,1
1,7,8,0,0,0,0,0,0,10,21,1
1,1,7,34,7,26,26,26,26,26,21,1
1,1,1,1,1,21,21,31,31,31,25,1
1,1,1,1,1,1,1,35,25,29,1,1
1,1,1,1,1,1,1,1,1,1,1,1
endlayer

layer
1,1,1,1,1,1,1,1,1,1,1,1
1,1,1,25,25,25,30,29,1,1,1,1
1,1,21,1,1,36,31,31,29,1,1,1
1,1,10,21,21,31,31,31,31,30,29,1
21,26,26,26,26,26,31,31,31,31,29,1
1,21,10,0,0,0,0,25,31,29,29,1
1,21,10,0,0,0,0,25,33,37,1,1
1,21,10,0,0,0,0,25,31,31,29,1
21,26,26,26,26,26,26,31,31,31,37,1
1,21,10,21,21,31,31,31,31,38,29,1
1,1,21,1,25,31,31,38,29,1,1,1
1,1,1,1,1,38,29,1,1,1,1,1
1,1,1,1,1,1,1,1,1,1,1,1
endlayer

layer
1,1,1,1,1,1,1,1,1,1,1,1
1,1,1,1,1,1,1,1,1,1,1,1
1,1,29,29,30,29,1,1,1,1,1,1
1,36,31,31,31,30,29,29,1,1,1,1
36,31,31,31,31,31,31,29,29,1,1,1
1,21,31,10,31,31,29,29,29,1,1,1
21,26,26,10,31,31,31,29,1,1,1,1
1,21,31,10,31,31,31,37,29,1,1,1
36,31,31,31,31,31,31,29,29,1,1,1
1,38,31,31,31,31,29,29,1,1,1,1
1,1,29,38,29,29,1,1,1,1,1,1
1,1,1,1,1,1,1,1,1,1,1,1
1,1,1,1,1,1,1,1,1,1,1,1
endlayer

layer
1,1,1,1,1,1,1,1,1,1,1,1
1,1,1,1,1,1,1,1,1,1,1,1
1,1,1,1,1,1,1,1,1,1,1,1
1,1,1,1,1,1,1,1,1,1,1,1
1,29,29,29,1,1,1,1,1,1,1,1
29,30,29,29,29,1,1,1,1,1,1,1
29,31,31,29,29,1,1,1,1,1,1,1
29,31,31,29,29,29,1,1,1,1,1,1
1,29,29,29,29,1,1,1,1,1,1,1
1,1,1,1,1,1,1,1,1,1,1,1
1,1,1,1,1,1,1,1,1,1,1,1
1,1,1,1,1,1,1,1,1,1,1,1
1,1,1,1,1,1,1,1,1,1,1,1
endlayer

