
# Created by Ruins mod version 16.7 Ingame Parser
# authoring Player: lafuller

weight=1
embed_into_distance=14
acceptable_target_blocks=flowing_water,water
unacceptable_target_blocks=
biomesToSpawnIn=river,swampland,wetland,marsh,lush swamp
dimensions=18,17,12
allowable_overhang=0
max_leveling=5
leveling_buffer=-1
preserve_water=0
preserve_lava=0

rule1=0,100,preserveBlock
rule2=0,100,minecraft:log2-1
rule3=0,100,minecraft:log2-5
rule4=0,100,minecraft:log2-9
rule5=0,100,minecraft:spruce_fence-0
rule6=0,100,minecraft:log-8
rule7=0,100,minecraft:log-4
rule8=0,100,minecraft:fence-0
rule9=0,100,minecraft:wooden_slab-9
rule10=0,100,minecraft:log-0
rule11=0,100,minecraft:trapdoor-11
rule12=0,100,minecraft:ladder-4
rule13=0,100,minecraft:spruce_fence_gate-3
rule14=0,100,minecraft:spruce_fence_gate-0
rule15=0,100,minecraft:spruce_fence_gate-2
rule16=0,100,minecraft:spruce_fence_gate-1

layer
1,1,1,1,1,1,1,1,1,1,1,1
1,1,1,1,1,1,1,1,1,1,1,1
1,1,2,1,1,1,1,1,2,1,1,1
1,1,1,1,1,1,1,1,1,1,1,1
1,1,1,1,2,1,2,1,1,1,1,1
1,1,1,1,1,1,1,1,1,1,1,1
1,1,1,1,1,1,1,1,1,1,1,1
1,1,1,1,1,1,1,1,1,1,1,1
1,1,1,1,1,1,1,1,1,1,1,1
1,1,1,1,1,1,1,1,1,1,1,1
1,1,2,1,1,1,1,1,2,1,1,1
1,1,1,1,1,1,1,1,1,1,1,1
1,1,1,1,1,2,1,1,1,2,1,1
1,1,1,1,1,1,1,1,1,1,1,1
1,1,1,2,1,1,1,1,1,1,1,1
1,1,1,1,1,1,1,1,1,1,1,1
1,1,1,1,1,1,1,1,1,1,1,1
endlayer

layer
1,1,1,1,1,1,1,1,1,1,1,1
1,1,1,1,1,1,1,1,1,1,1,1
1,1,2,1,1,1,1,1,2,1,1,1
1,1,1,1,1,1,1,1,1,1,1,1
1,1,1,1,2,1,2,1,1,1,1,1
1,1,1,1,1,1,1,1,1,1,1,1
1,1,1,1,1,1,1,1,1,1,1,1
1,1,1,1,1,1,1,1,1,1,1,1
1,1,1,1,1,1,1,1,1,1,1,1
1,1,1,1,1,1,1,1,1,1,1,1
1,1,2,1,1,1,1,1,2,1,1,1
1,1,1,1,1,1,1,1,1,1,1,1
1,1,1,1,1,2,1,1,1,2,1,1
1,1,1,1,1,1,1,1,1,1,1,1
1,1,1,2,1,1,1,1,1,1,1,1
1,1,1,1,1,1,1,1,1,1,1,1
1,1,1,1,1,1,1,1,1,1,1,1
endlayer

layer
1,1,1,1,1,1,1,1,1,1,1,1
1,1,1,1,1,1,1,1,1,1,1,1
1,1,2,1,1,1,1,1,2,1,1,1
1,1,1,1,1,1,1,1,1,1,1,1
1,1,1,1,2,1,2,1,1,1,1,1
1,1,1,1,1,1,1,1,1,1,1,1
1,1,1,1,1,1,1,1,1,1,1,1
1,1,1,1,1,1,1,1,1,1,1,1
1,1,1,1,1,1,1,1,1,1,1,1
1,1,1,1,1,1,1,1,1,1,1,1
1,1,2,1,1,1,1,1,2,1,1,1
1,1,1,1,1,1,1,1,1,1,1,1
1,1,1,1,1,2,1,1,1,2,1,1
1,1,1,1,1,1,1,1,1,1,1,1
1,1,1,2,1,1,1,1,1,1,1,1
1,1,1,1,1,1,1,1,1,1,1,1
1,1,1,1,1,1,1,1,1,1,1,1
endlayer

layer
1,1,1,1,1,1,1,1,1,1,1,1
1,1,1,1,1,1,1,1,1,1,1,1
1,1,2,1,1,1,1,1,2,1,1,1
1,1,1,1,1,1,1,1,1,1,1,1
1,1,1,1,2,1,2,1,1,1,1,1
1,1,1,1,1,1,1,1,1,1,1,1
1,1,1,1,1,1,1,1,1,1,1,1
1,1,1,1,1,1,1,1,1,1,1,1
1,1,1,1,1,1,1,1,1,1,1,1
1,1,1,1,1,1,1,1,1,1,1,1
1,1,2,1,1,1,1,1,2,1,1,1
1,1,1,1,1,1,1,1,1,1,1,1
1,1,1,1,1,2,1,1,1,2,1,1
1,1,1,1,1,1,1,1,1,1,1,1
1,1,1,2,1,1,1,1,1,1,1,1
1,1,1,1,1,1,1,1,1,1,1,1
1,1,1,1,1,1,1,1,1,1,1,1
endlayer

layer
1,1,1,1,1,1,1,1,1,1,1,1
1,1,1,1,1,1,1,1,1,1,1,1
1,1,2,1,1,1,1,1,2,1,1,1
1,1,1,1,1,1,1,1,1,1,1,1
1,1,1,1,2,1,2,1,1,1,1,1
1,1,1,1,1,1,1,1,1,1,1,1
1,1,1,1,1,1,1,1,1,1,1,1
1,1,1,1,1,1,1,1,1,1,1,1
1,1,1,1,1,1,1,1,1,1,1,1
1,1,1,1,1,1,1,1,1,1,1,1
1,1,2,1,1,1,1,1,2,1,1,1
1,1,1,1,1,1,1,1,1,1,1,1
1,1,1,1,1,2,1,1,1,2,1,1
1,1,1,1,1,1,1,1,1,1,1,1
1,1,1,2,1,1,1,1,1,1,1,1
1,1,1,1,1,1,1,1,1,1,1,1
1,1,1,1,1,1,1,1,1,1,1,1
endlayer

layer
1,1,1,1,1,1,1,1,1,1,1,1
1,1,1,1,1,1,1,1,1,1,1,1
1,1,2,1,1,1,1,1,2,1,1,1
1,1,1,1,1,1,1,1,1,1,1,1
1,1,1,1,2,1,2,1,1,1,1,1
1,1,1,1,1,1,1,1,1,1,1,1
1,1,1,1,1,1,1,1,1,1,1,1
1,1,1,1,1,1,1,1,1,1,1,1
1,1,1,1,1,1,1,1,1,1,1,1
1,1,1,1,1,1,1,1,1,1,1,1
1,1,2,1,1,1,1,1,2,1,1,1
1,1,1,1,1,1,1,1,1,1,1,1
1,1,1,1,1,2,1,1,1,2,1,1
1,1,1,1,1,1,1,1,1,1,1,1
1,1,1,2,1,1,1,1,1,1,1,1
1,1,1,1,1,1,1,1,1,1,1,1
1,1,1,1,1,1,1,1,1,1,1,1
endlayer

layer
1,1,1,1,1,1,1,1,1,1,1,1
1,1,1,1,1,1,1,1,1,1,1,1
1,1,2,1,1,1,1,1,2,1,1,1
1,1,1,1,1,1,1,1,1,1,1,1
1,1,1,1,2,1,2,1,1,1,1,1
1,1,1,1,1,1,1,1,1,1,1,1
1,1,1,1,1,1,1,1,1,1,1,1
1,1,1,1,1,1,1,1,1,1,1,1
1,1,1,1,1,1,1,1,1,1,1,1
1,1,1,1,1,1,1,1,1,1,1,1
1,1,2,1,1,1,1,1,2,1,1,1
1,1,1,1,1,1,1,1,1,1,1,1
1,1,1,1,1,2,1,1,1,2,1,1
1,1,1,1,1,1,1,1,1,1,1,1
1,1,1,2,1,1,1,1,1,1,1,1
1,1,1,1,1,1,1,1,1,1,1,1
1,1,1,1,1,1,1,1,1,1,1,1
endlayer

layer
1,1,1,1,1,1,1,1,1,1,1,1
1,1,1,1,1,1,1,1,1,1,1,1
1,1,2,1,1,1,1,1,2,1,1,1
1,1,1,1,1,1,1,1,1,1,1,1
1,1,1,1,2,1,2,1,1,1,1,1
1,1,1,1,1,1,1,1,1,1,1,1
1,1,1,1,1,1,1,1,1,1,1,1
1,1,1,1,1,1,1,1,1,1,1,1
1,1,1,1,1,1,1,1,1,1,1,1
1,1,1,1,1,1,1,1,1,1,1,1
1,1,2,1,1,1,1,1,2,1,1,1
1,1,1,1,1,1,1,1,1,1,1,1
1,1,1,1,1,2,1,1,1,2,1,1
1,1,1,1,1,1,1,1,1,1,1,1
1,1,1,2,1,1,1,1,1,1,1,1
1,1,1,1,1,1,1,1,1,1,1,1
1,1,1,1,1,1,1,1,1,1,1,1
endlayer

layer
1,1,1,1,1,1,1,1,1,1,1,1
1,1,1,1,1,1,1,1,1,1,1,1
1,1,2,1,1,1,1,1,2,1,1,1
1,1,1,1,1,1,1,1,1,1,1,1
1,1,1,1,2,1,2,1,1,1,1,1
1,1,1,1,1,1,1,1,1,1,1,1
1,1,1,1,1,1,1,1,1,1,1,1
1,1,1,1,1,1,1,1,1,1,1,1
1,1,1,1,1,1,1,1,1,1,1,1
1,1,1,1,1,1,1,1,1,1,1,1
1,1,2,1,1,1,1,1,2,1,1,1
1,1,1,1,1,1,1,1,1,1,1,1
1,1,1,1,1,2,1,1,1,2,1,1
1,1,1,1,1,1,1,1,1,1,1,1
1,1,1,2,1,1,1,1,1,1,1,1
1,1,1,1,1,1,1,1,1,1,1,1
1,1,1,1,1,1,1,1,1,1,1,1
endlayer

layer
1,1,1,1,1,1,1,1,1,1,1,1
1,1,1,1,1,1,1,1,1,1,1,1
1,1,2,1,1,1,1,1,2,1,1,1
1,1,1,1,1,1,1,1,1,1,1,1
1,1,1,1,2,1,2,1,1,1,1,1
1,1,1,1,1,1,1,1,1,1,1,1
1,1,1,1,1,1,1,1,1,1,1,1
1,1,1,1,1,1,1,1,1,1,1,1
1,1,1,1,1,1,1,1,1,1,1,1
1,1,1,1,1,1,1,1,1,1,1,1
1,1,2,1,1,1,1,1,2,1,1,1
1,1,1,1,1,1,1,1,1,1,1,1
1,1,1,1,1,2,1,1,1,2,1,1
1,1,1,1,1,1,1,1,1,1,1,1
1,1,1,2,1,1,1,1,1,1,1,1
1,1,1,1,1,1,1,1,1,1,1,1
1,1,1,1,1,1,1,1,1,1,1,1
endlayer

layer
1,1,1,1,1,1,1,1,1,1,1,1
1,1,1,1,1,1,1,1,1,1,1,1
1,1,2,1,1,1,1,1,2,1,1,1
1,1,1,1,1,1,1,1,1,1,1,1
1,1,1,1,2,1,2,1,1,1,1,1
1,1,1,1,1,1,1,1,1,1,1,1
1,1,1,1,1,1,1,1,1,1,1,1
1,1,1,1,1,1,1,1,1,1,1,1
1,1,1,1,1,1,1,1,1,1,1,1
1,1,1,1,1,1,1,1,1,1,1,1
1,1,2,1,1,1,1,1,2,1,1,1
1,1,1,1,1,1,1,1,1,1,1,1
1,1,1,1,1,2,1,1,1,2,1,1
1,1,1,1,1,1,1,1,1,1,1,1
1,1,1,2,1,1,1,1,1,1,1,1
1,1,1,1,1,1,1,1,1,1,1,1
1,1,1,1,1,1,1,1,1,1,1,1
endlayer

layer
1,1,1,1,1,1,1,1,1,1,1,1
1,1,1,1,1,1,1,1,1,1,1,1
1,1,2,1,1,1,1,1,2,1,1,1
1,1,1,1,1,1,1,1,1,1,1,1
1,1,1,1,2,1,2,1,1,1,1,1
1,1,1,1,1,1,1,1,1,1,1,1
1,1,1,1,1,1,1,1,1,1,1,1
1,1,1,1,1,1,1,1,1,1,1,1
1,1,1,1,1,1,1,1,1,1,1,1
1,1,1,1,1,1,1,1,1,1,1,1
1,1,2,1,1,1,1,1,2,1,1,1
1,1,1,1,1,1,1,1,1,1,1,1
1,1,1,1,1,2,1,1,1,2,1,1
1,1,1,1,1,1,1,1,1,1,1,1
1,1,1,2,1,1,1,1,1,1,1,1
1,1,1,1,1,1,1,1,1,1,1,1
1,1,1,1,1,1,1,1,1,1,1,1
endlayer

layer
1,1,1,1,1,1,1,1,1,1,1,1
1,1,1,1,1,1,1,1,1,1,1,1
1,1,2,1,1,1,1,1,2,1,1,1
1,1,1,1,1,1,1,1,1,1,1,1
1,1,1,1,2,1,2,1,1,1,1,1
1,1,1,1,3,1,3,1,1,1,1,1
1,1,1,1,3,1,3,1,1,1,1,1
1,1,1,1,3,1,3,1,1,1,1,1
1,1,1,1,3,1,3,1,1,1,1,1
1,1,1,1,3,1,3,1,3,1,1,1
1,1,2,1,3,1,3,1,2,1,1,1
1,1,1,1,3,1,3,1,3,1,1,1
1,1,1,1,3,2,3,1,3,2,1,1
1,1,1,1,3,1,1,1,1,1,1,1
1,1,1,2,3,1,1,1,1,1,1,1
1,1,1,1,1,1,1,1,1,1,1,1
1,1,1,1,1,1,1,1,1,1,1,1
endlayer

layer
1,1,1,1,1,1,1,1,1,1,1,1
1,1,1,1,1,1,1,1,1,1,1,1
1,1,2,3,1,1,1,3,2,1,1,1
1,1,1,3,1,1,1,3,1,1,1,1
1,1,1,3,2,1,2,3,1,1,1,1
1,1,1,1,1,1,1,1,1,1,1,1
1,1,1,1,1,1,1,1,1,1,1,1
1,1,1,1,1,1,1,1,1,1,1,1
1,1,1,1,1,1,1,1,1,1,1,1
1,1,4,4,4,4,4,4,4,1,1,1
1,1,2,4,4,4,4,4,2,1,1,1
1,1,3,4,4,4,4,4,4,1,1,1
1,1,3,1,1,2,1,1,1,2,1,1
1,1,3,1,1,1,1,1,1,1,1,1
1,1,1,2,1,1,1,1,1,1,1,1
1,1,1,1,1,1,1,1,1,1,1,1
1,1,1,1,1,1,1,1,1,1,1,1
endlayer

layer
1,1,1,1,1,1,1,1,1,1,1,1
1,1,1,1,1,1,1,1,1,1,1,1
1,1,2,1,1,1,1,1,2,1,1,1
5,6,6,6,6,6,6,6,6,6,5,1
1,1,1,1,2,1,2,1,1,1,1,1
1,1,1,1,1,1,1,1,1,1,1,1
1,1,1,1,1,1,1,1,1,1,1,1
1,1,1,1,1,1,1,1,1,1,1,1
1,1,1,1,1,1,1,1,1,1,1,1
1,1,1,1,1,1,1,1,1,1,1,1
1,1,2,1,1,1,1,1,2,1,1,1
5,6,6,6,6,6,6,6,6,6,6,5
1,1,1,1,1,2,1,1,1,2,1,1
5,6,6,6,6,6,6,6,6,6,6,5
1,1,1,2,1,1,1,1,1,1,1,1
1,1,1,1,1,1,1,1,1,1,1,1
1,1,1,1,1,1,1,1,1,1,1,1
endlayer

layer
1,1,5,1,5,1,5,1,5,1,1,1
1,1,7,1,7,1,7,1,7,1,1,1
1,1,7,1,7,1,7,1,7,1,1,1
1,1,7,1,7,1,7,1,7,1,1,1
1,1,7,1,7,1,7,1,7,1,1,1
1,1,7,1,1,1,1,1,7,1,1,1
1,1,7,1,1,1,1,1,7,1,1,1
1,1,7,1,1,1,1,1,7,1,1,1
1,1,7,1,1,1,1,1,7,1,1,1
1,1,7,1,1,1,1,1,7,1,1,1
1,1,7,1,1,1,1,1,7,1,1,1
1,1,7,1,1,1,1,1,7,1,1,1
1,1,7,1,1,2,1,1,7,2,1,1
1,1,7,1,1,1,1,1,7,1,1,1
1,1,7,2,1,1,1,1,7,1,1,1
1,1,7,1,1,1,1,1,7,1,1,1
1,1,5,1,1,1,1,1,5,1,1,1
endlayer

layer
1,1,8,1,8,1,8,1,8,1,1,1
1,9,10,9,10,9,10,9,10,9,1,1
5,6,6,6,6,6,6,6,6,6,5,1
1,9,9,9,9,9,9,9,9,9,1,1
5,6,6,6,6,6,6,6,6,6,5,1
1,9,9,9,9,9,9,9,9,9,1,1
5,6,6,6,6,6,6,6,6,6,5,1
1,9,9,9,9,9,9,9,9,9,1,1
5,6,6,6,6,6,6,6,6,6,6,5
1,9,9,9,9,11,11,9,9,9,9,1
1,9,9,9,9,1,1,9,9,9,9,1
1,9,9,9,9,12,12,9,9,9,9,1
5,6,6,6,6,6,6,6,6,6,6,5
1,9,9,9,9,9,9,9,9,9,9,1
5,6,6,6,6,6,6,6,6,6,6,5
1,9,10,9,9,9,9,9,10,9,9,1
1,1,8,1,1,1,1,1,8,1,1,1
endlayer

layer
1,1,1,1,1,1,1,1,1,1,1,1
1,5,13,13,5,13,5,13,13,5,1,1
1,15,1,1,1,1,1,1,1,14,1,1
1,15,1,1,1,1,1,1,1,14,1,1
1,5,1,1,1,1,1,1,1,5,1,1
1,15,1,1,1,1,1,1,1,14,1,1
1,15,1,1,1,1,1,1,1,5,1,1
1,15,1,1,1,1,1,1,1,14,1,1
1,5,1,1,1,1,1,1,1,5,5,1
1,15,1,1,1,1,1,1,1,1,14,1
1,15,1,1,1,1,1,1,1,1,14,1
1,15,1,1,1,1,1,1,1,1,14,1
1,5,1,1,1,1,1,1,1,1,5,1
1,15,1,1,1,1,1,1,1,1,14,1
1,15,1,1,1,1,1,1,1,1,14,1
1,5,16,16,5,16,16,5,16,16,5,1
1,1,1,1,1,1,1,1,1,1,1,1
endlayer

