# Gilly's Adobe tower

# template generated by Ruins mod version 14.6 Ingame Parser
# Structure created by Gilly

weight=1
embed_into_distance=5
acceptable_target_blocks=
unacceptable_target_blocks=flowing_water,water,flowing_lava,lava,ice,bedrock,netherrack,nether_brick,nether_brick_fence,soul_sand,quartz_ore,end_stone,obsidian,iron_bars,cloud,flesh,ash_block,slime_grass,slime_congealed,slime_dirt
dimensions=22,7,7
allowable_overhang=0
max_leveling=7
leveling_buffer=-1
preserve_water=0
preserve_lava=0

rule1=0,100,double_stone_slab-9
rule2=0,100,preserveBlock
rule3=0,100,sandstone-2
rule4=0,100,ladder-5
rule5=0,100,sandstone_stairs-0
rule6=0,100,sandstone_stairs-2
rule7=0,100,sandstone_stairs-3
rule8=0,100,sandstone-1
rule9=0,100,sandstone_stairs-1
rule10=0,100,sandstone_stairs-4
rule11=0,100,sandstone_stairs-6
rule12=0,100,sandstone_stairs-7
rule13=0,100,sandstone_stairs-5
rule14=0,100,stone_slab-1
rule15=0,100,fence-0
rule16=0,100,wooden_slab-1
rule17=0,100,spruce_stairs-3
rule18=0,100,spruce_stairs-0
rule19=0,100,spruce_stairs-2
rule20=0,100,spruce_stairs-1
rule21=0,100,hay_block-0

layer
2,3,1,3,1,3,2
3,2,2,2,2,2,3
1,2,2,2,2,2,1
3,2,2,2,2,2,3
1,2,2,2,2,2,1
3,2,2,2,2,2,3
2,3,1,3,1,3,2
endlayer

layer
2,1,1,1,1,1,2
1,2,2,2,2,2,1
1,2,2,2,2,2,1
1,2,2,2,2,2,1
1,2,2,2,2,2,1
1,2,2,2,2,2,1
2,1,1,1,1,1,2
endlayer

layer
2,3,1,1,1,3,2
3,2,2,2,2,2,3
1,2,2,2,2,2,1
1,2,2,2,2,2,1
1,2,2,2,2,2,1
3,2,2,2,2,2,3
2,3,1,1,1,3,2
endlayer

layer
2,1,1,1,1,1,2
1,2,2,2,2,2,1
1,2,2,2,2,2,1
1,2,2,2,2,2,1
1,2,2,2,2,2,1
1,2,2,2,2,2,1
2,1,1,1,1,1,2
endlayer

layer
2,3,1,3,1,3,2
3,1,1,1,1,1,3
1,1,1,1,1,1,1
3,1,1,1,1,1,3
1,1,1,1,1,1,1
3,1,1,1,1,1,3
2,3,1,3,1,3,2
endlayer

layer
2,2,1,1,1,2,2
2,1,1,1,1,1,2
1,1,0,4,0,1,1
1,1,0,0,0,1,1
1,1,0,0,0,1,1
2,1,1,0,1,1,2
2,2,1,0,1,2,2
endlayer

layer
2,2,1,1,1,2,2
2,3,1,1,1,3,2
1,1,0,4,0,1,1
1,1,0,0,0,1,1
1,1,0,0,0,1,1
2,3,1,0,1,3,2
2,2,1,0,1,2,2
endlayer

layer
2,2,1,1,1,2,2
2,1,1,1,1,1,2
1,1,0,4,0,1,1
1,1,0,0,0,1,1
1,1,0,0,0,1,1
2,1,1,0,1,1,2
2,2,1,0,1,2,2
endlayer

layer
2,2,3,8,3,2,2
2,3,1,1,1,3,2
3,1,0,4,0,1,3
8,1,0,0,0,1,8
3,1,0,0,0,1,3
2,3,1,1,1,3,2
2,2,3,8,3,2,2
endlayer

layer
2,2,5,2,5,2,2
2,1,1,1,1,1,2
7,1,0,4,0,1,6
2,1,0,0,0,1,2
7,1,0,0,0,1,6
2,1,1,1,1,1,2
2,2,9,2,9,2,2
endlayer

layer
2,2,2,2,2,2,2
2,3,5,1,5,3,2
2,7,0,4,0,6,2
2,1,0,0,0,1,2
2,7,0,0,0,6,2
2,3,9,1,9,3,2
2,2,2,2,2,2,2
endlayer

layer
0,0,0,0,0,0,0
0,1,10,1,10,1,0
0,12,0,4,0,11,0
0,1,0,0,0,1,0
0,12,0,0,0,11,0
0,1,13,1,13,1,0
0,0,0,0,0,0,0
endlayer

layer
0,0,0,0,0,0,0
0,3,1,3,1,3,0
0,1,0,4,0,1,0
0,3,0,0,0,3,0
0,1,0,0,0,1,0
0,3,1,3,1,3,0
0,0,0,0,0,0,0
endlayer

layer
0,0,0,0,0,0,0
0,14,1,5,1,14,0
0,1,0,4,0,1,0
0,7,0,0,0,6,0
0,1,0,0,0,1,0
0,14,1,9,1,14,0
0,0,0,0,0,0,0
endlayer

layer
0,0,0,0,0,0,0
0,0,1,10,1,0,0
0,1,0,4,0,1,0
0,12,0,0,0,11,0
0,1,0,0,0,1,0
0,0,1,13,1,0,0
0,0,0,0,0,0,0
endlayer

layer
0,0,0,0,0,0,0
0,0,3,1,3,0,0
0,3,0,4,0,3,0
0,1,0,0,0,1,0
0,3,0,0,0,3,0
0,0,3,1,3,0,0
0,0,0,0,0,0,0
endlayer

layer
0,0,0,0,0,0,0
0,7,5,1,5,6,0
0,7,0,4,0,6,0
0,1,0,0,0,1,0
0,7,0,0,0,6,0
0,7,9,1,9,9,0
0,0,0,0,0,0,0
endlayer

layer
0,0,0,0,0,0,0
0,12,10,8,10,11,0
0,12,1,0,1,11,0
0,8,1,1,1,8,0
0,12,1,1,1,11,0
0,12,13,8,13,11,0
0,0,0,0,0,0,0
endlayer

layer
0,0,0,0,0,0,0
0,3,9,9,9,3,0
0,6,0,0,0,7,0
0,6,0,0,0,7,0
0,6,0,0,0,7,0
0,3,5,5,5,3,0
0,0,0,0,0,0,0
endlayer

layer
0,0,0,0,0,0,0
0,15,0,0,0,15,0
0,0,0,0,0,0,0
0,0,0,0,0,0,0
0,0,0,0,0,0,0
0,15,0,0,0,15,0
0,0,0,0,0,0,0
endlayer

layer
0,0,0,0,0,0,0
0,15,0,0,0,15,0
0,0,0,0,0,0,0
0,0,0,0,0,0,0
0,0,0,0,0,0,0
0,15,0,0,0,15,0
0,0,0,0,0,0,0
endlayer

layer
0,0,0,0,0,0,0
0,16,19,18,17,16,0
0,20,21,21,21,20,0
0,17,21,15,21,19,0
0,18,21,21,21,18,0
0,16,19,20,17,16,0
0,0,0,0,0,0,0
endlayer

