
# Created by Ruins mod version 16.7 Ingame Parser
# authoring Player: lafuller

weight=1
embed_into_distance=4
acceptable_target_blocks=
unacceptable_target_blocks=flowing_water,water,flowing_lava,lava,ice,bedrock,netherrack,nether_brick,nether_brick_fence,soul_sand,quartz_ore,gravel,end_stone,obsidian,iron_bars,cloud,flesh,ash_block,slime_grass,slime_congealed,slime_dirt
biomesToSpawnIn=plains,forest,prarie,meadow,tundra,brushland,shrubland,woodland,woodlands,birch_forest,lavender_fields,flower_field,sunflower_plains,ice_flats,ice_plains
dimensions=16,13,13
allowable_overhang=0
max_leveling=4
leveling_buffer=-1
preserve_water=0
preserve_lava=0

rule1=0,100,air
rule2=0,100,preserveBlock
rule3=0,100,stonebrick-0,stonebrick-1,stonebrick-1,stonebrick-1,stonebrick-2,stonebrick-2,stone-5,stone-5,stone-6,cobblestone,cobblestone
rule4=0,100,minecraft:stone-6
rule5=0,100,minecraft:stone-5
rule6=0,100,minecraft:stonebrick-2
rule7=0,100,stonebrick-0,stonebrick-2,stonebrick-1,stonebrick-1,stonebrick-1,cobblestone
rule8=0,100,stonebrick-0,stonebrick-1,stonebrick-2,stonebrick-2,stone-5,stone-5,stone-6,stone-6
rule9=0,100,stonebrick-0,stonebrick-2,stonebrick-0,stonebrick-1,stonebrick-1,cobblestone
rule10=0,100,minecraft:stone_brick_stairs-0
rule11=0,100,stonebrick-0,stonebrick-1,stonebrick-1,stonebrick-1,stonebrick-2,stonebrick-2,stone-5,stone-5,stone-6,cobblestone,cobblestone,gravel
rule12=0,100,minecraft:cobblestone_wall-0
rule13=0,100,minecraft:log-0
rule14=0,100,minecraft:wooden_slab-9
rule15=0,100,web-0,air,air,air
rule16=0,100,minecraft:spruce_stairs-2
rule17=0,100,minecraft:spruce_stairs-5
rule18=0,100,bookshelf,hay_block,ChestGenHook:chests/spawn_bonus_chest:5-2,ChestGenHook:chests/village_blacksmith:4-2,ChestGenHook:chests/simple_dungeon:5-2,ChestGenHook:chests/abandoned_mineshaft:4-2,ChestGenHook:chests/stronghold_library:3-2,ChestGenHook:chests/stronghold_corridor:2-2,ChestGenHook:chests/stronghold_crossing:2-2,ChestGenHook:chests/igloo_chest:4-2
rule19=0,100,minecraft:stone_brick_stairs-2
rule20=0,100,minecraft:stone_brick_stairs-1
rule21=0,100,minecraft:stone_brick_stairs-5
rule22=0,100,minecraft:spruce_stairs-0
rule23=0,100,minecraft:spruce_stairs-6
rule24=0,100,minecraft:stone_brick_stairs-3
rule25=0,100,minecraft:stone_brick_stairs-7
rule26=0,100,minecraft:stone_brick_stairs-6
rule27=0,100,minecraft:planks-1
rule28=0,100,minecraft:planks-0
rule29=0,100,minecraft:spruce_stairs-7
rule30=0,100,minecraft:spruce_stairs-4
rule31=0,100,minecraft:spruce_stairs-3
rule32=0,100,minecraft:oak_stairs-0
rule33=0,100,minecraft:log2-1
rule34=0,100,minecraft:oak_stairs-3
rule35=0,100,minecraft:spruce_fence-0
rule36=0,100,minecraft:stone-4
rule37=0,100,minecraft:spruce_fence_gate-0
rule38=0,100,minecraft:oak_stairs-2
rule39=0,100,minecraft:trapdoor-9
rule40=0,100,minecraft:oak_stairs-1
rule41=0,100,minecraft:jungle_door-2
rule42=0,100,minecraft:fence-0
rule43=0,100,minecraft:stone_brick_stairs-4
rule44=0,100,minecraft:furnace-3
rule45=0,100,minecraft:jungle_door-9
rule46=0,100,minecraft:jungle_door-8
rule47=0,100,minecraft:wooden_slab-13
rule48=0,100,minecraft:stone_slab-13
rule49=0,100,minecraft:ladder-3
rule50=0,100,minecraft:spruce_fence_gate-1
rule51=0,100,minecraft:dark_oak_stairs-2
rule52=0,100,minecraft:dark_oak_stairs-3
rule53=0,100,minecraft:dark_oak_stairs-0
rule54=0,100,minecraft:planks-5
rule55=0,100,minecraft:wooden_slab-5
rule56=0,100,minecraft:dark_oak_stairs-7
rule57=0,100,minecraft:dark_oak_stairs-4
rule58=0,100,minecraft:dark_oak_stairs-1
rule59=0,100,minecraft:dark_oak_stairs-6
rule60=0,100,minecraft:dark_oak_fence-0
rule61=0,100,minecraft:trapdoor-2
rule62=0,100,minecraft:stone_slab-0

layer
2,2,2,2,2,2,2,2,2,2,2,2,2
2,2,2,2,2,4,3,3,2,2,2,2,2
2,2,2,3,3,7,7,7,4,6,5,2,2
2,2,4,7,7,8,8,8,7,6,3,2,2
2,3,7,8,8,8,9,9,8,8,7,4,2
2,3,7,8,9,9,9,9,9,8,7,3,2
2,3,7,8,9,9,9,9,9,8,7,3,2
2,4,7,8,8,9,9,9,9,8,7,3,2
10,3,3,7,8,9,9,8,8,7,4,3,10
3,3,3,7,7,8,8,8,7,3,3,3,3
3,3,3,3,4,7,7,7,7,3,3,3,3
3,3,3,3,3,3,3,3,4,3,3,3,3
4,2,4,2,2,4,2,2,4,2,4,3,3
endlayer

layer
2,2,2,2,2,2,2,2,2,2,2,2,2
2,2,2,2,2,5,12,11,2,2,2,2,2
2,2,2,11,11,14,14,13,5,11,4,2,2
2,2,5,13,15,1,1,1,15,6,11,2,2
2,11,16,1,1,1,1,1,1,15,13,5,2
2,3,16,1,1,1,1,1,1,1,14,11,2
2,12,17,13,1,1,1,1,1,1,14,12,2
2,5,18,1,1,1,1,1,1,1,13,11,2
2,3,11,1,1,1,1,1,1,15,5,3,2
10,3,11,13,15,1,1,1,15,11,3,3,10
3,3,3,11,5,14,14,14,13,11,3,3,19
3,3,3,3,3,11,12,12,5,3,3,3,19
20,21,6,2,2,6,2,2,6,2,6,20,20
endlayer

layer
2,2,2,2,2,2,2,2,2,2,2,2,2
2,2,2,2,2,4,12,11,2,2,2,2,2
2,2,2,11,11,15,15,13,4,11,6,2,2
2,2,4,13,15,1,1,1,15,6,11,2,2
2,11,1,1,1,1,1,1,1,15,13,4,2
2,3,1,1,1,1,1,1,1,1,15,11,2
2,12,22,13,1,1,1,1,1,1,15,12,2
2,4,23,1,1,1,1,1,1,15,13,11,2
2,2,11,15,1,1,1,1,1,15,4,2,2
2,2,11,13,15,1,1,1,15,11,19,2,2
2,10,3,11,4,15,1,15,13,11,19,2,2
2,24,3,3,3,11,12,12,4,3,19,2,2
2,24,6,21,21,6,2,2,6,21,19,2,2
endlayer

layer
2,2,2,2,2,2,2,2,2,2,2,2,2
2,2,2,2,2,5,12,11,2,2,2,2,2
2,2,2,11,11,15,15,13,5,11,5,2,2
2,2,5,13,15,15,15,15,15,6,11,2,2
2,11,1,1,1,1,1,15,15,15,13,5,2
2,3,1,1,1,1,1,1,1,15,15,11,2
2,12,1,13,15,1,1,1,1,1,15,12,2
2,5,22,23,15,1,1,1,15,15,13,11,2
2,2,11,15,15,1,1,1,15,15,5,2,2
2,2,11,13,15,15,1,15,15,11,2,2,2
2,2,24,11,5,15,15,15,13,11,2,2,2
2,2,24,3,3,11,11,11,5,19,2,2,2
2,2,24,3,3,3,26,25,3,19,2,2,2
endlayer

layer
2,2,2,2,2,2,2,2,2,2,2,2,2
2,2,2,2,2,4,3,3,2,2,2,2,2
2,2,2,3,3,27,27,27,4,6,6,2,2
2,2,4,27,27,28,28,28,27,4,4,2,2
2,3,1,14,29,28,27,27,28,28,27,4,2
2,3,1,14,29,28,27,27,27,28,27,3,2
2,3,1,13,30,28,28,27,27,28,27,3,2
2,4,1,31,28,27,27,28,28,28,27,3,2
2,2,3,27,28,28,27,27,28,27,4,2,2
2,2,3,27,27,28,28,28,27,3,2,2,2
2,2,2,3,4,27,27,27,27,3,2,2,2
2,2,2,2,2,3,27,27,4,2,2,2,2
2,2,2,2,2,24,3,3,19,2,2,2,2
endlayer

layer
2,2,2,2,2,2,2,2,2,2,2,2,2
2,2,2,2,2,33,32,32,2,2,2,2,2
2,2,2,32,34,1,1,1,33,4,19,2,2
2,1,33,35,1,1,1,1,1,4,6,2,2
2,34,1,37,1,1,1,1,1,1,36,33,2
2,34,1,37,1,1,1,1,1,1,39,38,2
2,34,1,13,1,1,1,1,1,1,39,38,2
2,33,1,1,1,1,1,1,1,1,36,38,2
2,1,40,1,1,1,1,1,1,1,33,1,2
2,2,34,1,1,1,1,1,1,40,2,2,2
2,2,2,40,33,1,1,1,1,38,2,2,2
2,2,2,2,1,28,41,41,33,1,2,2,2
2,2,2,2,2,2,1,1,2,2,2,2,2
endlayer

layer
2,2,2,2,2,2,2,2,2,2,2,2,2
2,2,2,2,2,33,1,42,2,2,2,2,2
2,2,2,42,1,1,1,1,33,21,43,2,2
2,42,33,1,1,1,1,1,1,1,44,2,2
2,42,1,1,1,1,1,1,1,1,1,33,2
2,1,1,1,1,1,1,1,1,1,1,42,2
2,42,1,13,1,1,1,1,1,1,1,1,2
2,33,1,1,1,1,1,1,1,1,1,42,2
2,42,42,1,1,1,1,1,1,1,33,42,2
2,2,1,1,1,1,1,1,1,1,2,2,2
2,2,2,42,33,1,1,1,1,42,2,2,2
2,2,2,2,1,28,46,45,33,42,2,2,2
2,2,2,2,2,2,1,1,2,2,2,2,2
endlayer

layer
2,2,2,2,2,2,2,2,2,2,2,2,2
2,2,47,2,30,33,30,30,23,2,2,2,2
2,47,29,30,29,1,1,1,33,3,6,2,2
2,30,33,1,1,1,1,1,1,48,6,47,47
2,29,1,1,1,1,1,1,1,1,49,33,2
2,29,1,1,1,1,1,1,1,1,1,23,2
2,29,1,13,1,1,1,1,1,1,1,23,2
2,33,1,1,1,1,1,1,1,1,49,23,2
2,29,17,1,1,1,1,1,1,1,33,17,2
47,47,29,1,1,1,1,1,1,17,23,2,2
2,2,2,17,33,1,1,1,1,23,2,2,2
2,2,2,2,29,27,50,50,33,17,2,2,2
2,2,2,2,2,2,1,1,2,2,2,2,2
endlayer

layer
2,2,2,2,2,52,47,47,51,2,2,2,2
2,2,2,55,54,33,27,54,53,51,2,2,2
2,55,54,54,27,23,17,17,33,4,19,2,2
55,54,33,17,17,14,14,14,17,6,5,53,2
56,54,23,14,1,1,1,14,14,14,27,33,53
47,27,23,1,1,1,1,1,1,1,29,27,47
47,27,23,13,1,1,1,1,1,1,29,27,47
57,27,23,1,1,1,1,1,1,1,29,27,47
55,54,27,1,1,1,1,1,1,14,27,54,58
2,54,27,30,1,1,1,14,30,27,54,58,2
2,58,54,27,33,30,14,14,29,54,54,2,2
2,2,55,58,54,27,27,27,27,54,55,2,2
2,2,2,2,55,59,47,47,56,55,2,2,2
endlayer

layer
2,2,2,2,2,2,2,2,2,2,2,2,2
2,2,2,2,60,55,55,60,2,2,2,2,2
2,2,60,60,53,52,54,53,51,6,2,2,2
2,60,52,54,54,54,54,54,54,5,6,2,2
2,60,54,54,23,17,29,54,54,54,54,55,2
55,52,54,27,14,14,1,17,17,29,54,53,2
55,52,54,13,14,1,1,1,14,29,54,54,55
2,58,54,23,14,1,1,1,14,30,54,51,2
2,55,54,30,14,14,14,30,29,54,54,60,2
2,60,54,54,23,30,29,54,54,54,60,2,2
2,2,52,58,54,54,54,54,54,51,60,2,2
2,2,2,2,60,52,54,58,55,60,2,2,2
2,2,2,2,2,2,55,55,2,2,2,2,2
endlayer

layer
2,2,2,2,2,2,2,2,2,2,2,2,2
2,2,2,2,2,2,2,2,2,2,2,2,2
2,2,2,2,60,2,60,2,2,10,2,2,2
2,2,2,60,60,60,60,55,60,6,4,2,2
2,2,2,60,55,54,54,60,60,60,2,2,2
2,2,60,55,53,54,27,54,55,55,60,2,2
2,60,60,52,54,27,35,27,54,54,60,60,2
2,2,55,54,54,27,27,27,54,55,60,2,2
2,2,60,55,54,54,54,58,55,60,2,2,2
2,2,60,60,55,54,55,60,60,60,2,2,2
2,2,2,2,60,60,60,2,60,2,2,2,2
2,2,2,2,2,2,60,2,2,2,2,2,2
2,2,2,2,2,2,2,2,2,2,2,2,2
endlayer

layer
2,2,2,2,2,2,2,2,2,2,2,2,2
2,2,2,2,2,2,2,2,2,2,2,2,2
2,2,2,2,2,2,2,2,2,2,2,2,2
2,2,2,2,2,2,2,2,2,21,3,2,2
2,2,2,2,2,60,60,2,2,2,2,2,2
2,2,2,2,2,60,55,60,2,2,2,2,2
2,2,2,2,60,55,61,55,60,60,2,2,2
2,2,2,60,60,55,55,55,60,2,2,2,2
2,2,2,2,60,60,60,60,2,2,2,2,2
2,2,2,2,2,60,2,2,2,2,2,2,2
2,2,2,2,2,2,2,2,2,2,2,2,2
2,2,2,2,2,2,2,2,2,2,2,2,2
2,2,2,2,2,2,2,2,2,2,2,2,2
endlayer

layer
2,2,2,2,2,2,2,2,2,2,2,2,2
2,2,2,2,2,2,2,2,2,2,2,2,2
2,2,2,2,2,2,2,2,2,2,2,2,2
2,2,2,2,2,2,2,2,2,6,19,2,2
2,2,2,2,2,2,2,2,2,2,2,2,2
2,2,2,2,2,2,2,2,2,2,2,2,2
2,2,2,2,2,2,2,2,2,2,2,2,2
2,2,2,2,2,2,2,2,2,2,2,2,2
2,2,2,2,2,2,2,2,2,2,2,2,2
2,2,2,2,2,2,2,2,2,2,2,2,2
2,2,2,2,2,2,2,2,2,2,2,2,2
2,2,2,2,2,2,2,2,2,2,2,2,2
2,2,2,2,2,2,2,2,2,2,2,2,2
endlayer

layer
2,2,2,2,2,2,2,2,2,2,2,2,2
2,2,2,2,2,2,2,2,2,2,2,2,2
2,2,2,2,2,2,2,2,2,2,2,2,2
2,2,2,2,2,2,2,2,2,3,6,2,2
2,2,2,2,2,2,2,2,2,2,2,2,2
2,2,2,2,2,2,2,2,2,2,2,2,2
2,2,2,2,2,2,2,2,2,2,2,2,2
2,2,2,2,2,2,2,2,2,2,2,2,2
2,2,2,2,2,2,2,2,2,2,2,2,2
2,2,2,2,2,2,2,2,2,2,2,2,2
2,2,2,2,2,2,2,2,2,2,2,2,2
2,2,2,2,2,2,2,2,2,2,2,2,2
2,2,2,2,2,2,2,2,2,2,2,2,2
endlayer

layer
2,2,2,2,2,2,2,2,2,2,2,2,2
2,2,2,2,2,2,2,2,2,2,2,2,2
2,2,2,2,2,2,2,2,2,2,2,2,2
2,2,2,2,2,2,2,2,2,12,12,2,2
2,2,2,2,2,2,2,2,2,2,2,2,2
2,2,2,2,2,2,2,2,2,2,2,2,2
2,2,2,2,2,2,2,2,2,2,2,2,2
2,2,2,2,2,2,2,2,2,2,2,2,2
2,2,2,2,2,2,2,2,2,2,2,2,2
2,2,2,2,2,2,2,2,2,2,2,2,2
2,2,2,2,2,2,2,2,2,2,2,2,2
2,2,2,2,2,2,2,2,2,2,2,2,2
2,2,2,2,2,2,2,2,2,2,2,2,2
endlayer

layer
2,2,2,2,2,2,2,2,2,2,2,2,2
2,2,2,2,2,2,2,2,2,2,2,2,2
2,2,2,2,2,2,2,2,2,2,2,2,2
2,2,2,2,2,2,2,2,2,62,62,2,2
2,2,2,2,2,2,2,2,2,2,2,2,2
2,2,2,2,2,2,2,2,2,2,2,2,2
2,2,2,2,2,2,2,2,2,2,2,2,2
2,2,2,2,2,2,2,2,2,2,2,2,2
2,2,2,2,2,2,2,2,2,2,2,2,2
2,2,2,2,2,2,2,2,2,2,2,2,2
2,2,2,2,2,2,2,2,2,2,2,2,2
2,2,2,2,2,2,2,2,2,2,2,2,2
2,2,2,2,2,2,2,2,2,2,2,2,2
endlayer

