
# Created by Ruins mod version 16.7 Ingame Parser
# authoring Player: lafuller

weight=1
embed_into_distance=17
acceptable_target_blocks=
unacceptable_target_blocks=flowing_water,water,flowing_lava,lava,ice,bedrock,netherrack,nether_brick,nether_brick_fence,soul_sand,quartz_ore,gravel,end_stone,obsidian,iron_bars,cloud,flesh,ash_block,slime_grass,slime_congealed,slime_dirt
biomesToSpawnIn=plains,prarie,meadow,tundra,brushland,shrubland,ice_flats,lavender fields,flower field,sunflower plains,ice plains
dimensions=24,15,17
allowable_overhang=0
max_leveling=10
leveling_buffer=-1
preserve_water=0
preserve_lava=0
preventRotation=1

rule1=0,100,preserveBlock
rule2=0,100,minecraft:stained_hardened_clay-9
rule3=0,100,minecraft:iron_bars-0
rule4=0,100,minecraft:ladder-5
rule5=0,100,minecraft:ladder-4
rule6=0,100,minecraft:stone_brick_stairs-0
rule7=0,100,minecraft:stone_brick_stairs-5
rule8=0,100,minecraft:stone_brick_stairs-7
rule9=0,100,minecraft:stone_brick_stairs-6
rule10=0,100,minecraft:stone_brick_stairs-4
rule11=0,100,minecraft:stone-5
rule12=0,100,minecraft:stone_slab-0
rule13=0,100,CommandBlock:RUINSTRIGGER /testruin Gilly/GillyHangarCore ~0 ~-13 ~8 0:@
rule14=0,100,CommandBlock:RUINSTRIGGER /testruin Gilly/GillyHangarCargo ~-18 ~-14 ~8 0:@,CommandBlock:RUINSTRIGGER /testruin Gilly/GillyHangarBay ~-20 ~-12 ~8 2:@
rule15=0,100,CommandBlock:RUINSTRIGGER /testruin Gilly/GillyHangarCargo ~18 ~-14 ~8 2:@,CommandBlock:RUINSTRIGGER /testruin Gilly/GillyHangarBay ~20 ~-12 ~8 0:@


layer
1,1,1,2,2,2,2,2,2,2,2,2,2,2,1,1,1
1,1,2,2,0,0,0,0,0,0,0,0,0,2,2,1,1
1,2,2,0,0,0,0,0,0,0,0,0,0,0,2,2,1
1,2,0,0,0,0,0,0,0,0,0,0,0,0,0,2,1
1,2,0,0,0,0,0,0,0,0,0,0,0,0,0,2,1
1,2,0,0,0,0,0,0,0,0,0,0,0,0,0,2,1
1,2,0,0,0,0,0,0,0,0,0,0,0,0,0,2,14
1,2,0,0,0,0,0,0,0,0,0,0,0,0,0,2,13
1,2,0,0,0,0,0,0,0,0,0,0,0,0,0,2,15
1,2,0,0,0,0,0,0,0,0,0,0,0,0,0,2,1
1,2,0,0,0,0,0,0,0,0,0,0,0,0,0,2,1
2,2,0,0,0,0,0,0,0,0,0,0,0,0,0,2,1
2,4,3,0,0,0,0,0,0,0,0,0,0,0,2,2,1
2,5,3,0,0,0,0,0,0,0,0,0,0,2,2,1,1
2,2,2,2,2,2,2,2,2,2,2,2,2,2,1,1,1
endlayer

layer
1,1,1,2,2,2,2,2,2,2,2,2,2,2,1,1,1
1,1,2,2,0,0,0,0,0,0,0,0,0,2,2,1,1
1,2,2,0,0,0,0,0,0,0,0,0,0,0,2,2,1
1,2,0,0,0,0,0,0,0,0,0,0,0,0,0,2,1
1,2,0,0,0,0,0,0,0,0,0,0,0,0,0,2,1
1,2,0,0,0,0,0,0,0,0,0,0,0,0,0,2,1
1,2,0,0,0,0,0,0,0,0,0,0,0,0,0,2,1
1,2,0,0,0,0,0,0,0,0,0,0,0,0,0,2,1
1,2,0,0,0,0,0,0,0,0,0,0,0,0,0,2,1
1,2,0,0,0,0,0,0,0,0,0,0,0,0,0,2,1
1,2,0,0,0,0,0,0,0,0,0,0,0,0,0,2,1
2,2,0,0,0,0,0,0,0,0,0,0,0,0,0,2,1
2,4,3,0,0,0,0,0,0,0,0,0,0,0,2,2,1
2,5,3,0,0,0,0,0,0,0,0,0,0,2,2,1,1
2,2,2,2,2,2,2,2,2,2,2,2,2,2,1,1,1
endlayer

layer
1,1,1,2,2,2,2,2,2,2,2,2,2,2,1,1,1
1,1,2,2,0,0,0,0,0,0,0,0,0,2,2,1,1
1,2,2,0,0,0,0,0,0,0,0,0,0,0,2,2,1
1,2,0,0,0,0,0,0,0,0,0,0,0,0,0,2,1
1,2,0,0,0,0,0,0,0,0,0,0,0,0,0,2,1
1,2,0,0,0,0,0,0,0,0,0,0,0,0,0,2,1
1,2,0,0,0,0,0,0,0,0,0,0,0,0,0,2,1
1,2,0,0,0,0,0,0,0,0,0,0,0,0,0,2,1
1,2,0,0,0,0,0,0,0,0,0,0,0,0,0,2,1
1,2,0,0,0,0,0,0,0,0,0,0,0,0,0,2,1
1,2,0,0,0,0,0,0,0,0,0,0,0,0,0,2,1
2,2,0,0,0,0,0,0,0,0,0,0,0,0,0,2,1
2,4,3,0,0,0,0,0,0,0,0,0,0,0,2,2,1
2,5,3,0,0,0,0,0,0,0,0,0,0,2,2,1,1
2,2,2,2,2,2,2,2,2,2,2,2,2,2,1,1,1
endlayer

layer
1,1,1,2,2,2,2,2,2,2,2,2,2,2,1,1,1
1,1,2,2,0,0,0,0,0,0,0,0,0,2,2,1,1
1,2,2,0,0,0,0,0,0,0,0,0,0,0,2,2,1
1,2,0,0,0,0,0,0,0,0,0,0,0,0,0,2,1
1,2,0,0,0,0,0,0,0,0,0,0,0,0,0,2,1
1,2,0,0,0,0,0,0,0,0,0,0,0,0,0,2,1
1,2,0,0,0,0,0,0,0,0,0,0,0,0,0,2,1
1,2,0,0,0,0,0,0,0,0,0,0,0,0,0,2,1
1,2,0,0,0,0,0,0,0,0,0,0,0,0,0,2,1
1,2,0,0,0,0,0,0,0,0,0,0,0,0,0,2,1
1,2,0,0,0,0,0,0,0,0,0,0,0,0,0,2,1
2,2,0,0,0,0,0,0,0,0,0,0,0,0,0,2,1
2,4,3,0,0,0,0,0,0,0,0,0,0,0,2,2,1
2,5,3,0,0,0,0,0,0,0,0,0,0,2,2,1,1
2,2,2,2,2,2,2,2,2,2,2,2,2,2,1,1,1
endlayer

layer
1,1,1,2,2,2,2,2,2,2,2,2,2,2,1,1,1
1,1,2,2,0,0,0,0,0,0,0,0,0,2,2,1,1
2,2,2,0,0,0,0,0,0,0,0,0,0,0,2,2,1
2,2,0,0,0,0,0,0,0,0,0,0,0,0,0,2,1
1,2,0,0,0,0,0,0,0,0,0,0,0,0,0,2,1
1,2,0,0,0,0,0,0,0,0,0,0,0,0,0,2,1
1,2,0,0,0,0,0,0,0,0,0,0,0,0,0,2,1
1,2,0,0,0,0,0,0,0,0,0,0,0,0,0,2,1
1,2,0,0,0,0,0,0,0,0,0,0,0,0,0,2,1
1,2,0,0,0,0,0,0,0,0,0,0,0,0,0,2,1
1,2,0,0,0,0,0,0,0,0,0,0,0,0,0,2,1
2,2,0,0,0,0,0,0,0,0,0,0,0,0,0,2,1
2,4,3,0,0,0,0,0,0,0,0,0,0,0,2,2,1
2,5,3,0,0,0,0,0,0,0,0,0,0,2,2,1,1
2,2,2,2,2,2,2,2,2,2,2,2,2,2,1,1,1
endlayer

layer
1,1,1,2,2,2,2,2,2,2,2,2,2,2,1,1,1
1,1,2,2,0,0,0,0,0,0,0,0,0,2,2,1,1
2,2,2,0,0,0,0,0,0,0,0,0,0,0,2,2,1
2,2,0,0,0,0,0,0,0,0,0,0,0,0,0,2,1
2,2,0,0,0,0,0,0,0,0,0,0,0,0,0,2,1
1,2,0,0,0,0,0,0,0,0,0,0,0,0,0,2,1
1,2,0,0,0,0,0,0,0,0,0,0,0,0,0,2,1
1,2,0,0,0,0,0,0,0,0,0,0,0,0,0,2,1
1,2,0,0,0,0,0,0,0,0,0,0,0,0,0,2,1
1,2,0,0,0,0,0,0,0,0,0,0,0,0,0,2,1
1,2,0,0,0,0,0,0,0,0,0,0,0,0,0,2,1
2,2,0,0,0,0,0,0,0,0,0,0,0,0,0,2,1
2,4,3,0,0,0,0,0,0,0,0,0,0,0,2,2,1
2,5,3,0,0,0,0,0,0,0,0,0,0,2,2,1,1
2,2,2,2,2,2,2,2,2,2,2,2,2,2,1,1,1
endlayer

layer
1,1,1,2,2,2,2,2,2,2,2,2,2,2,1,1,1
1,1,2,2,0,0,0,0,0,0,0,0,0,2,2,1,1
6,2,2,0,0,0,0,0,0,0,0,0,0,0,2,2,1
2,2,0,0,0,0,0,0,0,0,0,0,0,0,0,2,1
2,2,0,0,0,0,0,0,0,0,0,0,0,0,0,2,1
2,2,0,0,0,0,0,0,0,0,0,0,0,0,0,2,1
1,2,0,0,0,0,0,0,0,0,0,0,0,0,0,2,1
1,2,0,0,0,0,0,0,0,0,0,0,0,0,0,2,1
1,2,0,0,0,0,0,0,0,0,0,0,0,0,0,2,1
1,2,0,0,0,0,0,0,0,0,0,0,0,0,0,2,1
1,2,0,0,0,0,0,0,0,0,0,0,0,0,0,2,1
2,2,0,0,0,0,0,0,0,0,0,0,0,0,0,2,1
2,4,3,0,0,0,0,0,0,0,0,0,0,0,2,2,1
2,5,3,0,0,0,0,0,0,0,0,0,0,2,2,1,1
2,2,2,2,2,2,2,2,2,2,2,2,2,2,1,1,1
endlayer

layer
1,1,1,2,2,2,2,2,2,2,2,2,2,2,1,1,1
1,1,2,2,0,0,0,0,0,0,0,0,0,2,2,1,1
1,2,2,0,0,0,0,0,0,0,0,0,0,0,2,2,1
6,2,0,0,0,0,0,0,0,0,0,0,0,0,0,2,1
2,2,0,0,0,0,0,0,0,0,0,0,0,0,0,2,1
2,2,0,0,0,0,0,0,0,0,0,0,0,0,0,2,1
2,2,0,0,0,0,0,0,0,0,0,0,0,0,0,2,1
1,2,0,0,0,0,0,0,0,0,0,0,0,0,0,2,1
1,2,0,0,0,0,0,0,0,0,0,0,0,0,0,2,1
1,2,0,0,0,0,0,0,0,0,0,0,0,0,0,2,1
1,2,0,0,0,0,0,0,0,0,0,0,0,0,0,2,1
2,2,0,0,0,0,0,0,0,0,0,0,0,0,0,2,1
2,4,3,0,0,0,0,0,0,0,0,0,0,0,2,2,1
2,5,3,0,0,0,0,0,0,0,0,0,0,2,2,1,1
2,2,2,2,2,2,2,2,2,2,2,2,2,2,1,1,1
endlayer

layer
1,1,1,2,2,2,2,2,2,2,2,2,2,2,1,1,1
1,1,2,2,0,0,0,0,0,0,0,0,0,2,2,1,1
1,2,2,0,0,0,0,0,0,0,0,0,0,0,2,2,1
1,2,0,0,0,0,0,0,0,0,0,0,0,0,0,2,1
6,2,0,0,0,0,0,0,0,0,0,0,0,0,0,2,1
2,2,0,0,0,0,0,0,0,0,0,0,0,0,0,2,1
2,2,0,0,0,0,0,0,0,0,0,0,0,0,0,2,1
2,2,0,0,0,0,0,0,0,0,0,0,0,0,0,2,1
1,2,0,0,0,0,0,0,0,0,0,0,0,0,0,2,1
1,2,0,0,0,0,0,0,0,0,0,0,0,0,0,2,1
1,2,0,0,0,0,0,0,0,0,0,0,0,0,0,2,1
2,2,0,0,0,0,0,0,0,0,0,0,0,0,0,2,1
2,4,3,0,0,0,0,0,0,0,0,0,0,0,2,2,1
2,5,3,0,0,0,0,0,0,0,0,0,0,2,2,1,1
2,2,2,2,2,2,2,2,2,2,2,2,2,2,1,1,1
endlayer

layer
1,1,1,2,2,2,2,2,2,2,2,2,2,2,1,1,1
1,1,2,2,0,0,0,0,0,0,0,0,0,2,2,1,1
1,2,2,0,0,0,0,0,0,0,0,0,0,0,2,2,1
1,2,0,0,0,0,0,0,0,0,0,0,0,0,0,2,1
1,2,0,0,0,0,0,0,0,0,0,0,0,0,0,2,1
6,2,0,0,0,0,0,0,0,0,0,0,0,0,0,2,1
2,2,0,0,0,0,0,0,0,0,0,0,0,0,0,2,1
2,2,0,0,0,0,0,0,0,0,0,0,0,0,0,2,1
2,2,0,0,0,0,0,0,0,0,0,0,0,0,0,2,1
1,2,0,0,0,0,0,0,0,0,0,0,0,0,0,2,1
1,2,0,0,0,0,0,0,0,0,0,0,0,0,0,2,1
2,2,0,0,0,0,0,0,0,0,0,0,0,0,0,2,1
2,4,3,0,0,0,0,0,0,0,0,0,0,0,2,2,1
2,5,3,0,0,0,0,0,0,0,0,0,0,2,2,1,1
2,2,2,2,2,2,2,2,2,2,2,2,2,2,1,1,1
endlayer

layer
1,1,1,2,2,2,2,2,2,2,2,2,2,2,1,1,1
1,1,2,2,0,0,0,7,0,7,0,0,0,2,2,1,1
1,2,2,0,0,0,0,0,0,0,0,0,0,0,2,2,1
1,2,0,0,0,0,0,0,0,0,0,0,0,0,0,2,1
1,2,0,0,0,0,0,0,0,0,0,0,0,0,0,2,1
1,2,0,0,0,0,0,0,0,0,0,0,0,0,0,2,1
6,2,9,0,0,0,0,0,0,0,0,0,0,0,8,2,1
2,2,0,0,0,0,0,0,0,0,0,0,0,0,0,2,1
2,2,9,0,0,0,0,0,0,0,0,0,0,0,8,2,1
2,2,0,0,0,0,0,0,0,0,0,0,0,0,0,2,1
1,2,0,0,0,0,0,0,0,0,0,0,0,0,0,2,1
2,2,0,0,0,0,0,0,0,0,0,0,0,0,0,2,1
2,4,3,0,0,0,0,0,0,0,0,0,0,0,2,2,1
2,5,3,0,0,0,0,10,0,10,0,0,0,2,2,1,1
2,2,2,2,2,2,2,2,2,2,2,2,2,2,1,1,1
endlayer

layer
1,1,1,2,2,2,2,2,2,2,2,2,2,2,1,1,1
1,1,2,2,0,0,0,11,0,11,0,0,0,2,2,1,1
1,2,2,0,0,0,0,0,0,0,0,0,0,0,2,2,1
1,2,0,0,0,0,0,0,0,0,0,0,0,0,0,2,1
1,2,0,0,0,0,0,0,0,0,0,0,0,0,0,2,1
1,2,0,0,0,0,0,0,0,0,0,0,0,0,0,2,1
1,2,11,0,0,0,0,0,0,0,0,0,0,0,11,2,1
6,2,0,0,0,0,0,0,0,0,0,0,0,0,0,2,1
2,2,11,0,0,0,0,0,0,0,0,0,0,0,11,2,1
2,2,0,0,0,0,0,0,0,0,0,0,0,0,0,2,1
2,2,9,0,0,0,0,0,0,0,0,0,0,0,0,2,1
2,2,0,0,0,0,0,0,0,0,0,0,0,0,0,2,1
2,4,3,0,0,0,0,0,0,0,0,0,0,0,2,2,1
2,5,3,0,0,10,0,11,0,11,0,0,0,2,2,1,1
2,2,2,2,2,2,2,2,2,2,2,2,2,2,1,1,1
endlayer

layer
1,1,1,2,2,2,2,2,2,2,2,2,2,2,1,1,1
1,1,2,2,11,11,0,11,0,11,0,11,11,2,2,1,1
1,2,2,0,0,0,0,0,0,0,0,0,0,0,2,2,1
1,2,11,0,0,0,0,0,0,0,0,0,0,0,11,2,1
1,2,11,0,0,0,0,0,0,0,0,0,0,0,11,2,1
1,2,0,0,0,0,0,0,0,0,0,0,0,0,0,2,1
1,2,11,0,0,0,0,0,0,0,0,0,0,0,11,2,1
1,2,0,0,0,0,0,0,0,0,0,0,0,0,0,2,1
6,2,11,0,0,0,0,0,0,0,0,0,0,0,11,2,1
2,2,0,0,0,0,0,0,0,0,0,0,0,0,0,2,1
2,2,11,0,0,0,0,0,0,0,0,0,0,0,11,2,1
2,2,0,0,0,0,0,0,0,0,0,0,0,0,11,2,1
2,4,3,0,0,0,0,0,0,0,0,0,0,0,2,2,1
2,5,3,0,0,11,0,11,0,11,0,11,11,2,2,1,1
2,2,2,2,2,2,2,2,2,2,2,2,2,2,1,1,1
endlayer

layer
1,1,1,2,2,2,2,2,2,2,2,2,2,2,1,1,1
1,1,2,2,0,11,0,11,0,11,0,11,0,2,2,1,1
1,2,2,0,0,0,0,0,0,0,0,0,0,0,2,2,1
1,2,0,0,0,0,0,0,0,0,0,0,0,0,0,2,1
1,2,11,0,0,0,0,0,0,0,0,0,0,0,11,2,1
1,2,0,0,0,0,0,0,0,0,0,0,0,0,0,2,1
1,2,11,0,0,0,0,0,0,0,0,0,0,0,11,2,1
1,2,0,0,0,0,0,0,0,0,0,0,0,0,0,2,1
1,2,11,0,0,0,0,0,0,0,0,0,0,0,11,2,1
6,2,0,0,0,0,0,0,0,0,0,0,0,0,0,2,1
2,2,11,0,0,0,0,0,0,0,0,0,0,0,11,2,1
2,2,0,0,0,0,0,0,0,0,0,0,0,0,0,2,1
2,4,3,0,0,0,0,0,0,0,0,0,0,0,2,2,1
2,5,3,0,0,11,0,11,0,11,0,11,0,2,2,1,1
2,2,2,2,2,2,2,2,2,2,2,2,2,2,1,1,1
endlayer

layer
1,1,1,2,2,2,2,2,2,2,2,2,2,2,1,1,1
1,1,2,2,0,11,0,11,0,11,0,11,0,2,2,1,1
1,2,2,0,0,0,0,0,0,0,0,0,0,0,2,2,1
1,2,0,0,0,0,0,0,0,0,0,0,0,0,0,2,1
1,2,11,0,0,0,0,0,0,0,0,0,0,0,11,2,1
1,2,0,0,0,0,0,0,0,0,0,0,0,0,0,2,1
1,2,11,0,0,0,0,0,0,0,0,0,0,0,11,2,1
1,2,0,0,0,0,0,0,0,0,0,0,0,0,0,2,1
1,2,11,0,0,0,0,0,0,0,0,0,0,0,11,2,1
1,2,0,0,0,0,0,0,0,0,0,0,0,0,0,2,1
6,2,11,0,0,0,0,0,0,0,0,0,0,0,11,2,1
2,2,0,0,0,0,0,0,0,0,0,0,0,0,0,2,1
2,4,3,0,0,0,0,0,0,0,0,0,0,0,2,2,1
2,5,3,0,0,11,0,11,0,11,0,11,0,2,2,1,1
2,2,2,2,2,2,2,2,2,2,2,2,2,2,1,1,1
endlayer

layer
1,1,1,2,2,2,2,2,2,2,2,2,2,2,1,1,1
1,1,2,2,0,11,0,11,0,11,0,11,0,2,2,1,1
1,2,2,0,0,0,0,0,0,0,0,0,0,0,2,2,1
1,2,0,0,0,0,0,0,0,0,0,0,0,0,0,2,1
1,2,11,0,0,0,0,0,0,0,0,0,0,0,11,2,1
1,2,0,0,0,0,0,0,0,0,0,0,0,0,0,2,1
1,2,11,0,0,0,0,0,0,0,0,0,0,0,11,2,1
1,2,0,0,0,0,0,0,0,0,0,0,0,0,0,2,1
1,2,11,0,0,0,0,0,0,0,0,0,0,0,11,2,1
1,2,0,0,0,0,0,0,0,0,0,0,0,0,0,2,1
1,2,11,0,0,0,0,0,0,0,0,0,0,0,11,2,1
6,2,0,0,0,0,0,0,0,0,0,0,0,0,0,2,1
2,4,3,0,0,0,0,0,0,0,0,0,0,0,2,2,1
2,5,3,0,0,11,0,11,0,11,0,11,0,2,2,1,1
2,2,2,2,2,2,2,2,2,2,2,2,2,2,1,1,1
endlayer

layer
1,1,1,2,2,2,2,2,2,2,2,2,2,2,1,1,1
1,1,2,2,0,11,0,11,0,11,0,11,0,2,2,1,1
1,2,2,0,0,0,0,0,0,0,0,0,0,0,2,2,1
1,2,0,0,0,0,0,0,0,0,0,0,0,0,0,2,1
1,2,11,0,0,0,0,0,0,0,0,0,0,0,11,2,1
1,2,0,0,0,0,0,0,0,0,0,0,0,0,0,2,1
1,2,11,0,0,0,0,0,0,0,0,0,0,0,11,2,1
1,2,0,0,0,0,0,0,0,0,0,0,0,0,0,2,1
1,2,11,0,0,0,0,0,0,0,0,0,0,0,11,2,1
1,2,0,0,0,0,0,0,0,0,0,0,0,0,0,2,1
1,2,11,0,0,0,0,0,0,0,0,0,0,0,11,2,1
1,2,0,0,0,0,0,0,0,0,0,0,0,0,0,2,1
1,4,3,0,0,0,0,0,0,0,0,0,0,0,2,2,1
1,5,3,0,0,11,0,11,0,11,0,11,0,2,2,1,1
1,2,2,2,2,2,2,2,2,2,2,2,2,2,1,1,1
endlayer

layer
1,1,1,2,2,2,2,2,2,2,2,2,2,2,1,1,1
1,1,2,2,0,11,0,11,0,11,0,11,0,2,2,1,1
1,2,2,0,0,0,0,0,0,0,0,0,0,0,2,2,1
1,2,0,0,0,0,0,0,0,0,0,0,0,0,0,2,1
1,2,11,0,0,0,0,0,0,0,0,0,0,0,11,2,1
1,2,0,0,0,0,0,0,0,0,0,0,0,0,0,2,1
1,2,11,0,0,0,0,0,0,0,0,0,0,0,11,2,1
1,2,0,0,0,0,0,0,0,0,0,0,0,0,0,2,1
1,2,11,0,0,0,0,0,0,0,0,0,0,0,11,2,1
1,2,0,0,0,0,0,0,0,0,0,0,0,0,0,2,1
1,2,11,0,0,0,0,0,0,0,0,0,0,0,11,2,1
1,2,0,0,0,0,0,0,0,0,0,0,0,0,0,2,1
1,4,3,0,0,0,0,0,0,0,0,0,0,0,2,2,1
1,5,3,0,0,11,0,11,0,11,0,11,0,2,2,1,1
1,2,2,2,2,2,2,2,2,2,2,2,2,2,1,1,1
endlayer

layer
1,1,1,2,0,2,0,2,0,2,0,2,0,2,1,1,1
1,1,2,2,0,11,0,11,0,11,0,11,0,2,2,1,1
1,2,2,0,0,0,0,0,0,0,0,0,0,0,2,2,1
1,0,0,0,0,0,0,0,0,0,0,0,0,0,0,0,1
1,2,11,0,0,0,0,0,0,0,0,0,0,0,11,2,1
1,0,0,0,0,0,0,0,0,0,0,0,0,0,0,0,1
1,2,11,0,0,0,0,0,0,0,0,0,0,0,11,2,1
1,0,0,0,0,0,0,0,0,0,0,0,0,0,0,0,1
1,2,11,0,0,0,0,0,0,0,0,0,0,0,11,2,1
1,0,0,0,0,0,0,0,0,0,0,0,0,0,0,0,1
1,2,11,0,0,0,0,0,0,0,0,0,0,0,11,2,1
1,2,0,0,0,0,0,0,0,0,0,0,0,0,0,0,1
1,4,3,0,0,0,0,0,0,0,0,0,0,0,2,2,1
1,5,3,0,0,11,0,11,0,11,0,11,0,2,2,1,1
1,2,2,2,0,2,0,2,0,2,0,2,0,2,1,1,1
endlayer

layer
1,1,1,2,2,11,2,11,2,11,2,11,2,2,1,1,1
1,1,2,2,0,11,0,11,0,11,0,11,0,2,2,1,1
1,2,2,0,0,0,0,0,0,0,0,0,0,0,2,2,1
1,2,0,0,0,0,0,0,0,0,0,0,0,0,0,2,1
1,11,11,0,0,0,0,0,0,0,0,0,0,0,11,11,1
1,2,0,0,0,0,0,0,0,0,0,0,0,0,0,2,1
1,11,11,0,0,0,0,0,0,0,0,0,0,0,11,11,1
1,2,0,0,0,0,0,0,0,0,0,0,0,0,0,2,1
1,11,11,0,0,0,0,0,0,0,0,0,0,0,11,11,1
1,2,0,0,0,0,0,0,0,0,0,0,0,0,0,2,1
1,11,11,0,0,0,0,0,0,0,0,0,0,0,11,11,1
1,2,0,0,0,0,0,0,0,0,0,0,0,0,0,2,1
1,4,3,0,0,0,0,0,0,0,0,0,0,0,2,2,1
1,5,3,0,0,11,0,11,0,11,0,11,0,2,2,1,1
1,2,2,2,2,11,2,11,2,11,2,11,2,2,1,1,1
endlayer

layer
1,1,1,3,3,11,3,11,3,11,3,11,3,3,1,1,1
1,1,3,3,0,11,0,11,0,11,0,11,0,3,3,1,1
1,3,3,0,0,0,0,0,0,0,0,0,0,0,3,3,1
1,3,0,0,0,0,0,0,0,0,0,0,0,0,0,3,1
1,11,11,0,0,0,0,0,0,0,0,0,0,0,11,11,1
1,3,0,0,0,0,0,0,0,0,0,0,0,0,0,3,1
1,11,11,0,0,0,0,0,0,0,0,0,0,0,11,11,1
1,3,0,0,0,0,0,0,0,0,0,0,0,0,0,3,1
1,11,11,0,0,0,0,0,0,0,0,0,0,0,11,11,1
1,3,0,0,0,0,0,0,0,0,0,0,0,0,0,3,1
1,11,11,0,0,0,0,0,0,0,0,0,0,0,11,11,1
1,2,0,0,0,0,0,0,0,0,0,0,0,0,0,3,1
1,4,3,0,0,0,0,0,0,0,0,0,0,0,3,3,1
1,5,3,0,0,11,0,11,0,11,0,11,0,3,3,1,1
1,2,3,3,3,11,3,11,3,11,3,11,3,3,1,1,1
endlayer

layer
1,1,1,0,0,11,0,11,0,11,0,11,0,0,1,1,1
1,1,0,0,0,11,0,11,0,11,0,11,0,0,0,1,1
1,0,0,0,0,0,0,0,0,0,0,0,0,0,0,0,1
1,0,0,0,0,0,0,0,0,0,0,0,0,0,0,0,1
1,11,11,0,0,0,0,0,0,0,0,0,0,0,11,11,1
1,0,0,0,0,0,0,0,0,0,0,0,0,0,0,0,1
1,11,11,0,0,0,0,0,0,0,0,0,0,0,11,11,1
1,0,0,0,0,0,0,0,0,0,0,0,0,0,0,0,1
1,11,11,0,0,0,0,0,0,0,0,0,0,0,11,11,1
1,0,0,0,0,0,0,0,0,0,0,0,0,0,0,0,1
1,11,11,0,0,0,0,0,0,0,0,0,0,0,11,11,1
1,2,0,0,0,0,0,0,0,0,0,0,0,0,0,0,1
1,4,3,0,0,0,0,0,0,0,0,0,0,0,0,0,1
1,5,3,0,0,11,0,11,0,11,0,11,0,0,0,1,1
1,2,0,0,0,11,0,11,0,11,0,11,0,0,1,1,1
endlayer

layer
1,1,1,0,0,12,0,12,0,12,0,12,0,0,1,1,1
1,1,0,0,0,0,0,0,0,0,0,0,0,0,0,1,1
1,0,0,0,0,0,0,0,0,0,0,0,0,0,0,0,1
1,0,0,0,0,0,0,0,0,0,0,0,0,0,0,0,1
1,12,0,0,0,0,0,0,0,0,0,0,0,0,0,12,1
1,0,0,0,0,0,0,0,0,0,0,0,0,0,0,0,1
1,12,0,0,0,0,0,0,0,0,0,0,0,0,0,12,1
1,0,0,0,0,0,0,0,0,0,0,0,0,0,0,0,1
1,12,0,0,0,0,0,0,0,0,0,0,0,0,0,12,1
1,0,0,0,0,0,0,0,0,0,0,0,0,0,0,0,1
1,12,0,0,0,0,0,0,0,0,0,0,0,0,0,12,1
1,2,0,0,0,0,0,0,0,0,0,0,0,0,0,0,1
1,4,3,0,0,0,0,0,0,0,0,0,0,0,0,0,1
1,5,3,0,0,0,0,0,0,0,0,0,0,0,0,1,1
1,2,0,0,0,12,0,12,0,12,0,12,0,0,1,1,1
endlayer

layer
1,1,1,0,0,0,0,0,0,0,0,0,0,0,1,1,1
1,1,0,0,0,0,0,0,0,0,0,0,0,0,0,1,1
1,0,0,0,0,0,0,0,0,0,0,0,0,0,0,0,1
1,0,0,0,0,0,0,0,0,0,0,0,0,0,0,0,1
1,0,0,0,0,0,0,0,0,0,0,0,0,0,0,0,1
1,0,0,0,0,0,0,0,0,0,0,0,0,0,0,0,1
1,0,0,0,0,0,0,0,0,0,0,0,0,0,0,0,1
1,0,0,0,0,0,0,0,0,0,0,0,0,0,0,0,1
1,0,0,0,0,0,0,0,0,0,0,0,0,0,0,0,1
1,0,0,0,0,0,0,0,0,0,0,0,0,0,0,0,1
1,0,0,0,0,0,0,0,0,0,0,0,0,0,0,0,1
1,2,3,0,0,0,0,0,0,0,0,0,0,0,0,0,1
1,4,3,0,0,0,0,0,0,0,0,0,0,0,0,0,1
1,5,3,0,0,0,0,0,0,0,0,0,0,0,0,1,1
1,2,3,0,0,0,0,0,0,0,0,0,0,0,1,1,1
endlayer

