# Gilly's Sliding Catacombs

weight=1
embed_into_distance=26
acceptable_target_blocks=
unacceptable_target_blocks=
dimensions=16,11,11
allowable_overhang=0
max_leveling=3
leveling_buffer=-1
preserve_water=0
preserve_lava=0

rule1=0,100,stonebrick,stonebrick,stonebrick,stonebrick,stonebrick,stonebrick,stonebrick-2,stonebrick-1
rule2=0,100,stone_brick_stairs-3
rule3=0,100,stone_brick_stairs-1
rule4=0,100,stone_brick_stairs-2
rule5=0,100,stone_brick_stairs-0
rule6=0,100,stone_slab-5
rule7=0,100,stone_slab-13
rule8=0,100,stone_brick_stairs-7
rule9=0,100,stone_brick_stairs-5
rule10=0,100,stone_brick_stairs-6
rule11=0,100,stone_brick_stairs-4
rule12=0,100,sponge-0,diamond_ore-0,lapis_block-0,gold_block-0,emerald_block-0,iron_block-0,coal_block-0,gold_ore-0,redstone_ore-0,lapis_ore-0,emerald_ore-0,lapis_block-0,gold_block-0,gold_ore-0,redstone_ore-0,lapis_ore-0,emerald_ore-0

layer
1,1,1,1,1,1,1,1,1,1,1
1,0,0,0,0,1,0,0,0,0,1
1,0,0,0,0,0,0,0,0,0,1
1,0,0,0,0,1,0,0,0,0,1
1,0,0,0,0,1,0,0,0,0,1
1,1,1,1,1,1,1,1,1,1,1
1,0,0,0,0,1,0,0,0,0,1
1,0,0,0,0,1,0,0,0,0,1
1,0,0,0,0,1,0,0,0,0,1
1,0,0,0,0,1,0,0,0,0,1
1,1,1,1,1,1,1,1,1,1,1
endlayer

layer
1,1,1,1,1,1,1,1,1,1,1
1,1,1,1,1,1,1,1,1,1,1
1,1,1,1,1,1,1,1,1,1,1
1,1,1,1,1,1,1,1,1,1,1
1,1,1,1,3,3,2,1,1,1,1
1,1,1,1,4,12,2,1,1,1,1
1,1,1,1,4,5,5,1,1,1,1
1,1,1,1,1,1,1,1,1,1,1
1,1,1,1,1,1,1,1,1,1,1
1,1,1,1,1,1,1,1,1,1,1
1,1,1,1,1,1,1,1,1,1,1
endlayer

layer
1,1,1,1,1,0,0,0,6,1,1
1,0,0,0,0,0,0,0,0,0,1
6,0,0,0,0,0,0,0,0,0,1
0,0,0,0,0,0,0,0,0,0,1
0,0,0,0,0,0,0,0,0,0,1
0,0,0,0,0,0,0,0,0,0,0
1,0,0,0,0,0,0,0,0,0,0
1,0,0,0,0,0,0,0,0,0,0
1,0,0,0,0,0,0,0,0,0,6
1,0,0,0,0,0,0,0,0,0,1
1,1,6,0,0,0,1,1,1,1,1
endlayer

layer
1,1,1,1,1,0,0,0,0,0,1
0,0,0,0,0,0,0,0,0,0,1
0,0,0,0,0,0,0,0,0,0,1
0,0,0,0,0,0,0,0,0,0,1
0,0,0,0,0,0,0,0,0,0,1
0,0,0,0,0,0,0,0,0,0,0
1,0,0,0,0,0,0,0,0,0,0
1,0,0,0,0,0,0,0,0,0,0
1,0,0,0,0,0,0,0,0,0,0
1,0,0,0,0,0,0,0,0,0,0
1,0,0,0,0,0,1,1,1,1,1
endlayer

layer
1,1,1,1,1,0,0,0,0,0,1
0,0,0,0,0,0,0,0,0,0,1
0,0,0,0,0,0,0,0,0,0,1
0,0,0,0,0,0,0,0,0,0,1
0,0,0,0,0,0,0,0,0,0,1
0,0,0,0,0,0,0,0,0,0,0
1,0,0,0,0,0,0,0,0,0,0
1,0,0,0,0,0,0,0,0,0,0
1,0,0,0,0,0,0,0,0,0,0
1,0,0,0,0,0,0,0,0,0,0
1,0,0,0,0,0,1,1,1,1,1
endlayer

layer
1,0,6,1,1,1,1,7,7,0,1
0,9,9,9,0,0,0,0,0,8,0
7,0,0,0,0,0,0,0,0,8,6
7,0,0,0,0,0,0,0,0,8,1
1,0,0,0,0,0,0,0,0,0,1
1,0,0,0,0,0,0,0,0,0,1
1,0,0,0,0,0,0,0,0,0,1
1,10,0,0,0,0,0,0,0,0,7
6,10,0,0,0,0,0,0,0,0,7
0,10,0,0,0,0,0,11,11,11,0
1,0,7,7,1,1,1,1,6,0,1
endlayer

layer
1,0,0,0,6,1,1,1,1,1,1
1,1,1,1,1,1,1,1,1,1,0
1,1,1,1,1,1,1,1,1,1,0
1,1,1,1,1,1,1,1,1,1,0
1,1,1,1,3,3,2,1,1,1,6
1,1,1,1,4,0,2,1,1,1,1
6,1,1,1,4,5,5,1,1,1,1
0,1,1,1,1,1,1,1,1,1,1
0,1,1,1,1,1,1,1,1,1,1
0,1,1,1,1,1,1,1,1,1,1
1,1,1,1,1,1,6,0,0,0,1
endlayer

layer
1,0,0,0,0,0,6,1,1,1,1
1,1,0,0,0,0,0,0,0,1,0
1,0,0,0,0,0,0,0,0,0,0
1,0,0,0,0,0,0,0,0,0,0
6,0,0,0,0,0,0,0,0,0,0
0,0,0,0,0,0,0,0,0,0,0
0,0,0,0,0,0,0,0,0,0,6
0,0,0,0,0,0,0,0,0,0,1
0,0,0,0,0,0,0,0,0,0,1
0,1,0,0,0,0,0,0,0,1,1
1,1,1,1,6,0,0,0,0,0,1
endlayer

layer
1,0,0,0,0,0,0,0,6,1,1
1,1,0,0,0,0,0,0,0,1,0
6,0,0,0,0,0,0,0,0,0,0
0,0,0,0,0,0,0,0,0,0,0
0,0,0,0,0,0,0,0,0,0,0
0,0,0,0,0,0,0,0,0,0,0
0,0,0,0,0,0,0,0,0,0,0
0,0,0,0,0,0,0,0,0,0,0
0,0,0,0,0,0,0,0,0,0,6
0,1,0,0,0,0,0,0,0,1,1
1,1,6,0,0,0,0,0,0,0,1
endlayer

layer
1,0,0,0,0,0,0,0,0,0,1
0,1,0,0,0,0,0,0,0,1,0
0,0,0,0,0,0,0,0,0,0,0
0,0,0,0,0,0,0,0,0,0,0
0,0,0,0,0,0,0,0,0,0,0
0,0,0,0,0,0,0,0,0,0,0
0,0,0,0,0,0,0,0,0,0,0
0,0,0,0,0,0,0,0,0,0,0
0,0,0,0,0,0,0,0,0,0,0
0,1,0,0,0,0,0,0,0,1,0
1,0,0,0,0,0,0,0,0,0,1
endlayer

layer
1,0,0,0,0,0,0,0,0,0,1
0,1,0,0,0,0,0,0,0,1,0
0,0,0,0,0,0,0,0,0,0,0
0,0,0,0,0,0,0,0,0,0,0
0,0,0,0,0,0,0,0,0,0,0
0,0,0,0,0,0,0,0,0,0,0
0,0,0,0,0,0,0,0,0,0,0
0,0,0,0,0,0,0,0,0,0,0
0,0,0,0,0,0,0,0,0,0,0
0,1,0,0,0,0,0,0,0,1,0
1,0,0,0,0,0,0,0,0,0,1
endlayer

layer
1,10,0,0,0,0,0,0,0,0,1
0,1,0,0,0,0,0,0,0,1,9
0,0,0,0,0,0,0,0,0,0,0
0,0,0,0,0,0,0,0,0,0,0
0,0,0,0,0,0,0,0,0,0,0
0,0,0,0,0,0,0,0,0,0,0
0,0,0,0,0,0,0,0,0,0,0
0,0,0,0,0,0,0,0,0,0,0
0,0,0,0,0,0,0,0,0,0,0
11,1,0,0,0,0,0,0,0,1,0
1,0,0,0,0,0,0,0,0,8,1
endlayer

layer
1,0,1,1,1,1,1,1,1,1,1
1,1,7,0,0,0,0,0,7,1,0
1,7,0,0,0,0,0,0,0,7,1
1,0,0,0,0,0,0,0,0,0,1
1,0,0,0,0,0,0,0,0,0,1
1,0,0,0,0,0,0,0,0,0,1
1,0,0,0,0,0,0,0,0,0,1
1,0,0,0,0,0,0,0,0,0,1
1,7,0,0,0,0,0,0,0,7,1
0,1,7,0,0,0,0,0,7,1,1
1,1,1,1,1,1,1,1,1,0,1
endlayer

layer
1,0,1,1,1,1,1,1,1,1,1
1,0,1,1,10,9,8,1,1,0,0
1,1,1,7,0,0,0,7,1,1,1
1,1,7,0,0,0,0,0,7,1,1
1,9,0,0,0,0,0,0,0,9,1
1,10,0,0,0,0,0,0,0,8,1
1,11,0,0,0,0,0,0,0,11,1
1,1,7,0,0,0,0,0,7,1,1
1,1,1,7,0,0,0,7,1,1,1
0,0,1,1,10,11,8,1,1,0,1
1,1,1,1,1,1,1,1,1,0,1
endlayer

layer
1,0,1,1,1,1,1,1,1,1,1
1,0,0,0,0,0,0,0,0,0,0
1,0,0,1,1,9,1,1,0,0,1
1,0,1,1,7,7,7,1,1,0,1
1,0,1,7,0,0,0,7,1,0,1
1,0,10,7,0,0,0,7,8,0,1
1,0,1,7,0,0,0,7,1,0,1
1,0,1,1,7,7,7,1,1,0,1
1,0,0,1,1,11,1,1,0,0,1
0,0,0,0,0,0,0,0,0,0,1
1,1,1,1,1,1,1,1,1,0,1
endlayer

layer
1,1,1,1,1,1,1,1,1,1,1
1,0,0,0,0,0,0,0,0,0,1
1,0,0,0,0,0,0,0,0,0,1
1,0,0,0,1,1,1,0,0,0,1
1,0,0,1,3,3,2,1,0,0,1
1,0,0,1,4,0,2,1,0,0,1
1,0,0,1,4,5,5,1,0,0,1
1,0,0,0,1,1,1,0,0,0,1
1,0,0,0,0,0,0,0,0,0,1
1,0,0,0,0,0,0,0,0,0,1
1,1,1,1,1,1,1,1,1,1,1
endlayer

