
# Created by Ruins mod version 16.7 Ingame Parser
# authoring Player: lafuller

weight=1
embed_into_distance=34
acceptable_target_blocks=
unacceptable_target_blocks=flowing_lava,lava,ice,bedrock,netherrack,nether_brick,nether_brick_fence,soul_sand,quartz_ore,end_stone,obsidian,iron_bars,cloud,flesh,ash_block,slime_grass,slime_congealed,slime_dirt
dimensions=34,17,17
allowable_overhang=0
max_leveling=34
leveling_buffer=-1
preserve_water=0
preserve_lava=0

adjoining_template=Gilly/GillyAztecCatacombCrypt;6;80;-15;100
adjoining_template=Gilly/GillyAztecCatacombCrypt;12;80;-30;100
adjoining_template=Gilly/GillyAztecCatacombCrypt;21;80;-9;100
adjoining_template=Gilly/GillyAztecCatacombCrypt;27;80;-24;100

adjoining_template=Gilly/GillyAztecCatacombCrypt;-15;80;-6;100
adjoining_template=Gilly/GillyAztecCatacombCrypt;-21;80;9;100
adjoining_template=Gilly/GillyAztecCatacombCrypt;-30;80;-12;100
adjoining_template=Gilly/GillyAztecCatacombCrypt;-36;80;3;100

adjoining_template=Gilly/GillyAztecCatacombCrypt;-9;80;-21;100
adjoining_template=Gilly/GillyAztecCatacombCrypt;-24;80;-27;100
adjoining_template=Gilly/GillyAztecCatacombCrypt;-3;80;-36;100
adjoining_template=Gilly/GillyAztecCatacombCrypt;-18;80;-42;100

adjoining_template=Gilly/GillyAztecCatacombCrypt;15;80;6;100
adjoining_template=Gilly/GillyAztecCatacombCrypt;-6;80;15;100
adjoining_template=Gilly/GillyAztecCatacombCrypt;9;80;21;100

rule1=0,100,preserveBlock
rule2=0,100,stonebrick-0,stonebrick-1,stonebrick-1,stonebrick-2,stonebrick-2,stonebrick-3,stone-5,stone-5,stone-6,stone-6,cobblestone
rule3=0,100,minecraft:stone_slab-5
rule4=0,100,minecraft:double_stone_slab-5
rule5=0,100,minecraft:stone_brick_stairs-2
rule6=0,100,minecraft:stone_brick_stairs-0
rule7=0,100,stonebrick-0,stonebrick-1,stonebrick-1,stonebrick-1,stonebrick-2,stonebrick-2,stonebrick-3,stone-5,stone-6,cobblestone,cobblestone
rule8=0,100,minecraft:stone_slab-8
rule9=0,100,minecraft:stone-6
rule10=0,100,minecraft:stone_brick_stairs-3
rule11=0,100,minecraft:stone_brick_stairs-1
rule12=0,100,minecraft:cobblestone_wall-0
rule13=0,100,sponge-0,diamond_ore-0,lapis_block-0,gold_block-0,emerald_block-0,iron_block-0,coal_block-0,gold_ore-0,redstone_ore-0,lapis_ore-0,emerald_ore-0,lapis_block-0,gold_block-0,gold_ore-0,redstone_ore-0,lapis_ore-0,emerald_ore-0
rule14=0,100,minecraft:ladder-2
rule15=0,100,minecraft:ladder-5
rule16=0,100,minecraft:ladder-4
rule17=0,100,minecraft:ladder-3
rule18=0,100,minecraft:stone_brick_stairs-5
rule19=0,100,minecraft:stone_slab-13
rule20=0,100,minecraft:stone_brick_stairs-7
rule21=0,100,minecraft:stone_brick_stairs-6
rule22=0,100,minecraft:stone_brick_stairs-4
rule23=0,100,minecraft:iron_bars-0

layer
1,1,2,2,2,3,3,2,2,2,1,1,1,1,1,1,1
1,1,2,2,2,2,2,2,2,2,2,2,2,1,1,1,1
1,1,2,2,2,2,2,2,2,2,2,2,2,2,2,2,2
1,1,2,2,2,2,2,2,2,2,2,2,2,2,2,2,2
1,2,2,2,2,2,2,2,2,2,2,2,2,2,2,2,2
1,2,2,2,2,2,2,2,2,2,2,2,2,2,2,2,3
1,2,2,2,2,2,2,2,2,2,2,2,2,2,2,2,3
2,2,2,2,2,2,2,2,2,2,2,2,2,2,2,2,2
2,2,2,2,2,2,2,2,2,2,2,2,2,2,2,2,2
2,2,2,2,2,2,2,2,2,2,2,2,2,2,2,2,2
3,2,2,2,2,2,2,2,2,2,2,2,2,2,2,2,1
3,2,2,2,2,2,2,2,2,2,2,2,2,2,2,2,1
2,2,2,2,2,2,2,2,2,2,2,2,2,2,2,2,1
2,2,2,2,2,2,2,2,2,2,2,2,2,2,2,1,1
2,2,2,2,2,2,2,2,2,2,2,2,2,2,2,1,1
1,1,1,1,2,2,2,2,2,2,2,2,2,2,2,1,1
1,1,1,1,1,1,1,2,2,2,3,3,2,2,2,1,1
endlayer

layer
1,1,2,2,2,0,0,0,3,2,1,1,1,1,1,1,1
1,1,2,2,2,2,2,2,4,2,2,2,2,1,1,1,1
1,1,2,2,2,2,2,2,2,2,2,2,2,2,2,2,2
1,1,2,2,0,2,2,2,2,2,0,2,2,2,2,2,2
1,2,2,2,0,2,0,0,2,2,0,2,0,0,2,2,2
1,2,2,2,2,2,2,2,2,2,2,2,2,2,2,2,0
1,2,2,0,0,2,2,2,2,2,2,2,0,2,2,2,0
2,2,2,2,2,2,2,2,2,2,2,2,0,2,2,2,0
3,4,2,2,2,2,2,2,2,2,2,2,2,2,2,2,3
0,2,2,2,0,2,2,2,2,2,2,2,2,2,2,2,2
0,2,2,2,0,2,2,2,2,2,2,2,2,2,2,2,1
0,2,2,2,2,2,2,2,2,2,2,2,2,2,2,2,1
2,2,2,0,0,2,0,2,2,0,0,2,0,2,2,2,1
2,2,2,2,2,2,0,2,2,2,2,2,0,2,2,1,1
2,2,2,2,2,2,2,2,2,2,2,2,2,2,2,1,1
1,1,1,1,2,2,2,2,3,2,2,2,2,2,2,1,1
1,1,1,1,1,1,1,2,3,0,0,0,2,2,2,1,1
endlayer

layer
1,1,2,2,2,0,0,0,0,0,1,1,1,1,1,1,1
1,1,2,2,2,2,2,5,0,0,3,2,2,1,1,1,1
1,1,2,7,7,7,7,6,6,6,6,2,2,2,2,2,2
1,1,2,7,8,7,7,7,7,7,8,7,7,7,7,2,2
1,2,2,7,8,7,8,8,7,7,8,7,8,8,7,2,2
1,2,2,7,7,7,7,7,7,7,7,7,7,7,7,2,0
1,3,10,8,8,7,7,9,9,9,7,7,8,7,7,2,0
0,0,10,7,7,7,9,9,9,9,9,7,8,7,5,11,0
0,0,10,7,7,7,9,9,9,9,9,7,7,7,5,0,0
0,6,10,7,8,7,9,9,9,9,9,7,7,7,5,0,1
0,2,7,7,8,7,7,9,9,9,7,7,2,2,5,3,1
0,2,7,7,7,7,7,7,7,7,7,7,7,7,2,2,1
2,2,7,8,8,7,8,7,7,8,8,7,8,7,2,2,1
2,2,7,7,7,7,8,7,7,7,7,7,8,7,2,1,1
2,2,2,2,2,2,11,11,11,11,7,7,7,7,2,1,1
1,1,1,1,2,2,3,0,0,10,2,2,2,2,2,1,1
1,1,1,1,1,1,1,0,0,0,0,0,2,2,2,1,1
endlayer

layer
1,1,2,2,2,0,0,0,0,0,1,1,1,1,1,1,1
1,1,2,2,2,2,3,0,0,0,0,0,3,1,1,1,1
1,1,2,0,0,0,0,0,0,0,0,0,3,2,2,2,2
1,1,2,0,0,0,0,0,0,0,0,0,0,0,0,2,2
1,3,3,0,0,0,0,0,0,0,0,0,0,0,0,2,2
1,0,0,0,0,0,0,12,0,12,0,0,0,0,0,2,0
1,0,0,0,0,0,0,9,9,9,0,0,0,0,0,3,0
0,0,0,0,0,12,9,9,9,9,9,12,0,0,0,0,0
0,0,0,0,0,0,9,9,9,9,9,0,0,0,0,0,0
0,0,0,0,0,12,9,9,9,9,9,12,0,0,0,0,1
0,3,0,0,0,0,0,9,9,9,0,0,0,0,0,0,1
0,2,0,0,0,0,0,12,0,12,0,0,0,0,0,0,1
2,2,0,0,0,0,0,0,0,0,0,0,0,0,3,3,1
2,2,0,0,0,0,0,0,0,0,0,0,0,0,2,1,1
2,2,2,2,3,0,0,0,0,0,0,0,0,0,2,1,1
1,1,1,1,3,0,0,0,0,0,3,2,2,2,2,1,1
1,1,1,1,1,1,1,0,0,0,0,0,2,2,2,1,1
endlayer

layer
1,1,2,2,2,0,0,0,0,0,1,1,1,1,1,1,1
1,1,2,2,3,0,0,0,0,0,0,0,0,1,1,1,1
1,1,3,0,0,0,0,0,0,0,0,0,0,0,3,2,2
1,1,0,0,0,0,0,0,0,0,0,0,0,0,0,2,2
1,0,0,0,0,0,0,0,0,0,0,0,0,0,0,3,2
1,0,0,0,0,0,0,0,0,0,0,0,0,0,0,0,0
1,0,0,0,0,0,0,0,9,0,0,0,0,0,0,0,0
0,0,0,0,0,0,0,12,9,12,0,0,0,0,0,0,0
0,0,0,0,0,0,9,9,13,9,9,0,0,0,0,0,0
0,0,0,0,0,0,0,12,9,12,0,0,0,0,0,0,1
0,0,0,0,0,0,0,0,9,0,0,0,0,0,0,0,1
0,0,0,0,0,0,0,0,0,0,0,0,0,0,0,0,1
2,3,0,0,0,0,0,0,0,0,0,0,0,0,0,0,1
2,2,0,0,0,0,0,0,0,0,0,0,0,0,0,1,1
2,2,3,0,0,0,0,0,0,0,0,0,0,0,3,1,1
1,1,1,1,0,0,0,0,0,0,0,0,3,2,2,1,1
1,1,1,1,1,1,1,0,0,0,0,0,2,2,2,1,1
endlayer

layer
1,1,2,14,2,0,0,0,0,0,1,1,1,1,1,1,1
1,1,0,0,0,0,0,0,0,0,0,0,0,1,1,1,1
1,1,0,0,0,0,0,0,0,0,0,0,0,0,0,0,2
1,1,0,0,0,0,0,0,0,0,0,0,0,0,0,0,15
1,0,0,0,0,0,0,0,0,0,0,0,0,0,0,0,2
1,0,0,0,0,0,0,0,0,0,0,0,0,0,0,0,0
1,0,0,0,0,0,0,0,6,0,0,0,0,0,0,0,0
0,0,0,0,0,0,0,0,12,0,0,0,0,0,0,0,0
0,0,0,0,0,0,10,12,12,12,5,0,0,0,0,0,0
0,0,0,0,0,0,0,0,12,0,0,0,0,0,0,0,1
0,0,0,0,0,0,0,0,11,0,0,0,0,0,0,0,1
0,0,0,0,0,0,0,0,0,0,0,0,0,0,0,0,1
2,0,0,0,0,0,0,0,0,0,0,0,0,0,0,0,1
16,0,0,0,0,0,0,0,0,0,0,0,0,0,0,1,1
2,0,0,0,0,0,0,0,0,0,0,0,0,0,0,1,1
1,1,1,1,0,0,0,0,0,0,0,0,0,0,0,1,1
1,1,1,1,1,1,1,0,0,0,0,0,2,17,2,1,1
endlayer

layer
1,1,2,14,2,0,0,0,0,0,1,1,1,1,1,1,1
1,1,0,0,0,0,0,0,0,0,0,0,0,1,1,1,1
1,1,0,0,0,0,0,0,0,0,0,0,0,0,0,0,2
1,1,0,0,0,0,0,0,0,0,0,0,0,0,0,0,15
1,0,0,0,0,0,0,0,0,0,0,0,0,0,0,0,2
1,0,0,0,0,0,0,0,0,0,0,0,0,0,0,0,0
1,0,0,0,0,0,0,0,0,0,0,0,0,0,0,0,0
0,0,0,0,0,0,0,0,0,0,0,0,0,0,0,0,0
0,0,0,0,0,0,0,0,0,0,0,0,0,0,0,0,0
0,0,0,0,0,0,0,0,0,0,0,0,0,0,0,0,1
0,0,0,0,0,0,0,0,0,0,0,0,0,0,0,0,1
0,0,0,0,0,0,0,0,0,0,0,0,0,0,0,0,1
2,0,0,0,0,0,0,0,0,0,0,0,0,0,0,0,1
16,0,0,0,0,0,0,0,0,0,0,0,0,0,0,1,1
2,0,0,0,0,0,0,0,0,0,0,0,0,0,0,1,1
1,1,1,1,0,0,0,0,0,0,0,0,0,0,0,1,1
1,1,1,1,1,1,1,0,0,0,0,0,2,17,2,1,1
endlayer

layer
1,1,2,14,2,0,0,0,0,0,1,1,1,1,1,1,1
1,1,0,0,0,0,0,0,0,0,0,0,0,1,1,1,1
1,1,0,0,0,0,0,0,0,0,0,0,0,0,0,0,2
1,1,0,0,0,0,0,0,0,0,0,0,0,0,0,0,15
1,0,0,0,0,0,0,0,0,0,0,0,0,0,0,0,2
1,0,0,0,0,0,0,0,0,0,0,0,0,0,0,0,0
1,0,0,0,0,0,0,0,0,0,0,0,0,0,0,0,0
0,0,0,0,0,0,0,0,0,0,0,0,0,0,0,0,0
0,0,0,0,0,0,0,0,0,0,0,0,0,0,0,0,0
0,0,0,0,0,0,0,0,0,0,0,0,0,0,0,0,1
0,0,0,0,0,0,0,0,0,0,0,0,0,0,0,0,1
0,0,0,0,0,0,0,0,0,0,0,0,0,0,0,0,1
2,0,0,0,0,0,0,0,0,0,0,0,0,0,0,0,1
16,0,0,0,0,0,0,0,0,0,0,0,0,0,0,1,1
2,0,0,0,0,0,0,0,0,0,0,0,0,0,0,1,1
1,1,1,1,0,0,0,0,0,0,0,0,0,0,0,1,1
1,1,1,1,1,1,1,0,0,0,0,0,2,17,2,1,1
endlayer

layer
1,1,2,14,2,0,0,0,0,0,1,1,1,1,1,1,1
1,1,0,0,0,0,0,0,0,0,0,0,0,1,1,1,1
1,1,0,0,0,0,0,0,0,0,0,0,0,0,0,0,2
1,1,0,0,0,0,0,0,0,0,0,0,0,0,0,0,15
1,0,0,0,0,0,0,0,0,0,0,0,0,0,0,0,2
1,0,0,0,0,0,0,0,0,0,0,0,0,0,0,0,0
1,0,0,0,0,0,0,0,0,0,0,0,0,0,0,0,0
0,0,0,0,0,0,0,0,0,0,0,0,0,0,0,0,0
0,0,0,0,0,0,0,0,0,0,0,0,0,0,0,0,0
0,0,0,0,0,0,0,0,0,0,0,0,0,0,0,0,1
0,0,0,0,0,0,0,0,0,0,0,0,0,0,0,0,1
0,0,0,0,0,0,0,0,0,0,0,0,0,0,0,0,1
2,0,0,0,0,0,0,0,0,0,0,0,0,0,0,0,1
16,0,0,0,0,0,0,0,0,0,0,0,0,0,0,1,1
2,0,0,0,0,0,0,0,0,0,0,0,0,0,0,1,1
1,1,1,1,0,0,0,0,0,0,0,0,0,0,0,1,1
1,1,1,1,1,1,1,0,0,0,0,0,2,17,2,1,1
endlayer

layer
1,1,2,14,2,0,0,0,0,0,1,1,1,1,1,1,1
1,1,0,2,0,0,0,0,0,0,0,0,0,1,1,1,1
1,1,0,0,0,0,0,0,0,0,0,0,0,0,0,0,2
1,1,0,0,0,0,0,0,0,0,0,0,0,0,0,2,15
1,0,0,0,0,0,0,0,0,0,0,0,0,0,0,0,2
1,0,0,0,0,0,0,0,0,0,0,0,0,0,0,0,0
1,0,0,0,0,0,0,0,0,0,0,0,0,0,0,0,0
0,0,0,0,0,0,0,0,0,0,0,0,0,0,0,0,0
0,0,0,0,0,0,0,0,0,0,0,0,0,0,0,0,0
0,0,0,0,0,0,0,0,0,0,0,0,0,0,0,0,1
0,0,0,0,0,0,0,0,0,0,0,0,0,0,0,0,1
0,0,0,0,0,0,0,0,0,0,0,0,0,0,0,0,1
2,0,0,0,0,0,0,0,0,0,0,0,0,0,0,0,1
16,2,0,0,0,0,0,0,0,0,0,0,0,0,0,1,1
2,0,0,0,0,0,0,0,0,0,0,0,0,0,0,1,1
1,1,1,1,0,0,0,0,0,0,0,0,0,2,0,1,1
1,1,1,1,1,1,1,0,0,0,0,0,2,17,2,1,1
endlayer

layer
1,1,2,14,2,0,2,0,2,0,2,0,2,2,0,2,1
2,2,0,2,0,2,0,0,0,0,0,2,0,0,0,2,1
0,0,0,0,0,0,0,0,0,0,0,0,0,2,0,0,2
2,2,0,0,0,0,0,0,0,0,0,0,0,0,0,2,15
2,0,0,0,0,0,0,0,0,0,0,0,0,0,0,2,2
0,2,0,0,0,0,0,0,0,0,0,0,0,0,0,2,0
2,0,0,0,0,0,0,0,0,0,0,0,0,0,0,0,2
0,0,0,0,0,0,0,0,0,0,0,0,0,0,0,0,0
2,0,0,0,0,0,0,0,0,0,0,0,0,0,0,0,2
0,0,0,0,0,0,0,0,0,0,0,0,0,0,0,0,0
2,0,0,0,0,0,0,0,0,0,0,0,0,0,0,0,2
0,2,0,0,0,0,0,0,0,0,0,0,0,0,0,2,0
2,0,0,0,0,0,0,0,0,0,0,0,0,0,0,0,2
16,2,0,0,0,0,0,0,0,0,0,0,0,0,0,2,2
2,0,0,0,0,0,0,0,0,0,0,0,0,0,0,0,0
1,2,0,2,0,2,0,0,0,0,0,2,0,2,0,2,2
1,2,0,2,2,0,2,0,2,0,2,0,2,17,2,1,1
endlayer

layer
1,2,2,14,0,2,2,0,2,0,2,2,0,2,0,2,1
2,2,2,2,0,2,0,2,0,2,0,2,0,0,0,2,2
0,0,0,0,0,0,0,0,0,0,0,0,0,2,0,0,2
2,2,0,0,0,0,0,0,0,0,0,0,0,0,0,2,15
0,0,0,0,0,0,0,0,0,0,0,0,0,0,0,0,0
2,2,0,0,0,0,0,0,0,0,0,0,0,0,0,2,2
2,0,0,0,0,0,0,0,0,0,0,0,0,0,0,0,2
0,2,0,0,0,0,0,0,0,0,0,0,0,0,0,2,0
2,0,0,0,0,0,0,0,0,0,0,0,0,0,0,0,2
0,2,0,0,0,0,0,0,0,0,0,0,0,0,0,2,0
2,0,0,0,0,0,0,0,0,0,0,0,0,0,0,0,2
2,2,0,0,0,0,0,0,0,0,0,0,0,0,0,2,2
0,0,0,0,0,0,0,0,0,0,0,0,0,0,0,0,0
16,2,0,0,0,0,0,0,0,0,0,0,0,0,0,2,2
2,0,2,0,0,0,0,0,0,0,0,0,0,0,2,0,0
2,2,0,2,0,2,0,2,0,2,0,2,0,2,2,2,2
1,2,0,2,0,2,2,0,2,0,2,2,0,17,2,2,1
endlayer

layer
2,2,2,14,0,2,0,2,2,2,0,2,0,2,2,2,2
2,2,2,2,0,2,0,2,0,2,0,2,0,2,2,2,2
2,2,2,0,0,0,0,0,0,0,0,0,0,2,2,2,2
2,2,0,0,0,0,0,0,0,0,0,0,0,0,0,2,15
0,0,0,0,0,0,0,0,0,0,0,0,0,0,0,0,0
2,2,0,0,0,0,0,0,0,0,0,0,0,0,0,2,2
0,0,0,0,0,0,0,0,0,0,0,0,0,0,0,0,0
2,2,0,0,0,0,0,0,0,0,0,0,0,0,0,2,2
2,0,0,0,0,0,0,0,0,0,0,0,0,0,0,0,2
2,2,0,0,0,0,0,0,0,0,0,0,0,0,0,2,2
0,0,0,0,0,0,0,0,0,0,0,0,0,0,0,0,0
2,2,0,0,0,0,0,0,0,0,0,0,0,0,0,2,2
0,0,0,0,0,0,0,0,0,0,0,0,0,0,0,0,0
16,2,0,0,0,0,0,0,0,0,0,0,0,0,0,2,2
2,2,2,0,0,0,0,0,0,0,0,0,0,0,2,2,2
2,2,2,2,0,2,0,2,0,2,0,2,0,2,2,2,2
2,2,2,2,0,2,0,2,2,2,0,2,0,17,2,2,2
endlayer

layer
0,0,0,0,0,2,0,2,0,2,0,2,0,2,5,0,0
0,0,0,10,2,2,0,2,0,2,0,2,2,2,5,0,0
6,6,6,2,2,0,0,0,0,0,0,0,2,2,5,0,0
2,2,0,0,0,0,0,0,0,0,0,0,0,0,2,6,0
0,2,2,0,0,0,0,0,0,0,0,0,0,0,2,0,0
2,2,0,0,0,0,0,0,0,0,0,0,0,0,0,2,2
0,0,0,0,0,0,0,0,0,0,0,0,0,0,0,0,0
2,2,0,0,0,0,0,0,0,0,0,0,0,0,0,2,2
0,0,0,0,0,0,0,0,0,0,0,0,0,0,0,0,0
2,2,0,0,0,0,0,0,0,0,0,0,0,0,0,2,2
0,0,0,0,0,0,0,0,0,0,0,0,0,0,0,0,0
2,2,0,0,0,0,0,0,0,0,0,0,0,0,0,2,2
0,2,2,0,0,0,0,0,0,0,0,0,0,0,2,2,0
0,15,0,0,0,0,0,0,0,0,0,0,0,0,2,11,11
0,0,2,0,2,0,0,0,0,0,0,0,2,0,2,0,0
0,0,0,17,2,2,0,2,0,2,0,2,2,5,0,0,0
0,0,0,0,0,2,0,2,0,2,0,2,0,0,0,0,0
endlayer

layer
0,0,0,0,2,2,0,2,0,2,0,2,2,5,0,0,0
0,0,0,0,10,2,2,2,0,2,2,2,2,5,0,0,0
0,0,0,2,2,0,2,0,0,0,2,0,2,5,0,0,0
6,6,6,2,0,0,0,0,0,0,0,0,0,2,2,0,0
2,2,0,0,2,0,0,0,0,0,0,0,2,0,2,6,2
2,2,0,0,0,0,0,0,0,0,0,0,0,0,0,2,2
0,2,2,0,0,0,0,0,0,0,0,0,0,0,2,2,0
2,2,0,0,0,0,0,0,0,0,0,0,0,0,0,2,2
0,0,0,0,0,0,0,0,0,0,0,0,0,0,0,0,0
2,2,0,0,0,0,0,0,0,0,0,0,0,0,0,2,2
0,2,2,0,0,0,0,0,0,0,0,0,0,0,2,2,0
2,2,0,0,0,0,0,0,0,0,0,0,0,0,0,2,2
2,2,2,0,2,0,0,0,0,0,0,0,2,0,2,11,2
0,15,0,0,0,0,0,0,0,0,0,0,0,0,2,0,0
0,0,2,0,2,0,2,0,0,0,2,0,2,0,2,0,0
0,0,0,17,2,2,2,2,0,2,2,2,5,0,0,0,0
0,0,0,0,2,2,0,2,0,2,0,2,2,0,0,0,0
endlayer

layer
0,0,0,0,2,0,2,2,0,2,2,0,2,0,0,0,0
0,0,0,0,0,0,2,2,2,2,2,0,2,0,0,0,0
0,0,0,2,6,0,2,0,2,0,2,0,5,0,0,0,0
0,0,0,2,0,0,2,0,0,0,2,0,2,2,2,0,0
2,2,6,2,2,0,0,0,0,0,0,0,2,0,5,0,2
0,0,0,0,0,0,0,2,0,2,0,0,0,0,0,0,0
2,2,2,2,0,0,0,0,0,0,0,0,0,2,2,2,2
2,2,0,0,0,2,0,0,0,0,0,2,0,0,0,2,2
0,2,2,0,0,0,0,0,0,0,0,0,0,0,2,2,0
2,2,0,0,0,2,0,0,0,0,0,2,0,0,0,2,2
2,2,2,2,0,0,0,0,0,0,0,0,0,2,2,2,2
0,0,0,0,0,0,0,2,0,2,0,0,0,0,0,0,0
2,2,2,0,2,0,0,0,0,0,0,0,2,0,5,0,2
0,15,0,2,0,0,2,0,0,0,2,0,0,2,2,0,0
0,0,2,0,2,0,2,0,2,0,2,0,11,0,2,0,0
0,0,0,17,2,0,2,2,2,2,2,0,0,0,0,0,0
0,0,0,0,2,0,2,2,0,2,2,0,2,0,0,0,0
endlayer

layer
0,0,0,0,2,0,2,0,2,0,2,0,2,0,0,0,0
0,0,0,0,0,0,2,0,2,0,2,0,2,0,0,0,0
0,0,0,2,0,0,2,0,2,0,2,0,0,0,0,0,0
0,0,0,2,6,0,2,0,2,0,2,0,6,2,2,0,0
2,2,0,10,2,2,0,2,0,2,0,2,2,5,0,0,2
0,0,0,0,2,0,0,2,0,2,0,0,2,0,0,0,0
2,2,2,2,0,0,2,0,0,0,2,0,0,2,2,2,2
0,0,0,0,2,2,0,0,0,0,0,2,2,0,0,0,0
2,2,2,2,0,0,0,0,0,0,0,0,0,2,2,2,2
0,0,0,0,2,2,0,0,0,0,0,2,2,0,0,0,0
2,2,2,2,0,0,2,0,0,0,2,0,0,2,2,2,2
0,0,0,0,2,0,0,2,0,2,0,0,2,0,0,0,0
2,2,2,2,2,2,0,2,0,2,0,2,2,5,0,0,2
0,15,2,2,2,0,2,0,2,0,2,0,11,2,2,0,0
0,0,2,2,2,0,2,0,2,0,2,0,0,2,2,0,0
0,0,0,17,2,0,2,0,2,0,2,0,0,0,0,0,0
0,0,0,0,2,0,2,0,2,0,2,0,2,0,0,0,0
endlayer

layer
0,0,0,0,2,0,2,0,2,0,2,0,2,0,0,0,0
0,0,0,0,0,0,2,0,2,0,2,0,2,0,0,0,0
0,0,0,2,0,2,2,0,2,0,2,2,0,0,0,0,0
0,0,0,2,0,10,2,2,2,2,2,5,0,2,2,0,0
2,2,0,0,0,10,2,2,2,2,2,5,0,0,0,0,2
0,0,2,6,6,6,2,2,2,2,2,6,6,6,2,0,0
2,2,2,2,2,2,2,2,18,2,2,2,2,2,2,2,2
0,0,0,2,2,2,2,19,0,19,2,2,2,2,0,0,0
2,2,2,2,2,2,21,0,0,0,20,2,2,2,2,2,2
0,0,0,2,2,2,2,19,0,19,2,2,2,2,0,0,0
2,2,2,2,2,2,2,2,22,2,2,2,2,2,2,2,2
0,0,2,2,2,2,2,2,2,2,2,11,11,11,2,0,0
2,2,2,2,2,2,2,2,2,2,2,5,0,0,0,0,2
0,15,2,2,2,2,2,2,2,2,2,5,0,2,2,0,0
0,0,2,2,2,2,2,0,2,0,2,2,0,2,2,0,0
0,0,0,17,2,0,2,0,2,0,2,0,0,0,0,0,0
0,0,0,0,2,0,2,0,2,0,2,0,2,0,0,0,0
endlayer

layer
0,0,0,0,2,0,2,0,2,0,2,0,2,0,0,0,0
0,0,0,0,0,2,2,0,2,0,2,2,2,0,0,0,0
0,0,2,2,0,2,2,2,2,2,2,2,0,2,2,0,0
0,0,2,2,0,0,10,2,2,2,5,0,0,2,2,0,0
2,2,0,0,0,0,10,2,2,2,5,0,0,0,0,0,2
0,2,2,0,0,0,10,2,2,2,5,0,0,0,2,2,0
2,2,2,6,6,6,6,2,2,2,5,6,6,6,2,2,2
0,0,2,2,2,2,2,2,2,2,2,2,2,2,2,0,0
2,2,2,2,2,2,2,2,23,2,2,2,2,2,2,2,2
0,0,2,2,2,2,2,2,2,2,2,2,2,2,2,0,0
2,2,2,2,2,2,2,2,2,2,11,11,11,11,2,2,2
0,2,2,2,2,2,2,2,2,2,5,0,0,0,2,2,0
2,11,2,2,2,2,2,2,2,2,5,0,0,0,0,0,2
0,0,2,2,2,2,2,2,2,2,5,0,0,2,2,0,0
0,0,2,2,2,2,2,2,2,2,2,2,0,2,2,0,0
0,0,0,0,10,2,2,0,2,0,2,2,0,0,0,0,0
0,0,0,0,2,0,2,0,2,0,2,0,2,0,0,0,0
endlayer

layer
0,0,0,0,2,2,2,0,2,0,2,2,2,0,0,0,0
0,0,0,0,0,2,0,2,0,2,0,2,2,0,0,0,0
0,0,2,2,0,12,0,0,0,0,0,12,0,2,2,0,0
0,0,2,0,0,0,0,0,0,0,0,0,0,0,2,0,0
2,2,0,0,0,0,0,0,0,0,0,0,0,0,0,0,2
2,2,12,0,0,0,0,0,0,0,0,0,0,0,12,2,2
2,0,0,0,0,0,0,0,0,0,0,0,0,0,0,0,2
0,2,0,0,0,0,0,0,0,0,0,0,0,0,0,2,0
2,2,2,2,2,0,0,0,0,0,0,0,0,0,0,0,2
0,2,4,4,2,4,3,0,0,0,0,0,0,0,0,2,0
2,4,4,4,2,4,3,0,0,0,0,0,0,0,0,0,2
2,2,4,4,2,4,3,0,0,0,0,0,0,0,12,2,2
2,0,10,4,4,4,3,0,0,0,0,0,0,0,0,0,2
0,0,2,4,4,4,3,0,0,0,0,0,0,0,2,0,0
0,0,2,2,11,4,3,0,0,0,0,12,0,2,2,0,0
0,0,0,0,0,2,3,2,0,2,0,2,0,0,0,0,0
0,0,0,0,2,2,2,0,2,0,2,2,2,0,0,0,0
endlayer

layer
0,0,0,0,0,2,2,2,2,2,2,2,0,0,0,0,0
0,0,0,0,0,2,0,2,0,12,0,2,0,0,0,0,0
0,0,2,2,0,0,0,0,0,0,0,0,0,2,2,0,0
0,0,2,0,0,0,0,0,0,0,0,0,0,0,12,0,0
0,0,0,0,0,0,0,0,0,0,0,0,0,0,0,0,0
2,2,0,0,0,0,0,0,0,0,0,0,0,0,0,2,2
2,0,0,0,0,0,0,0,0,0,0,0,0,0,0,0,2
2,2,22,22,22,0,0,0,0,0,0,0,0,0,0,2,2
2,2,2,2,2,0,0,0,0,0,0,0,0,0,0,0,2
2,2,2,4,5,0,0,0,0,0,0,0,0,0,0,12,2
2,4,2,11,5,0,0,0,0,0,0,0,0,0,0,0,2
2,2,11,3,3,0,0,0,0,0,0,0,0,0,0,2,2
0,0,0,3,3,0,0,0,0,0,0,0,0,0,0,0,0
0,0,2,3,0,0,0,0,0,0,0,0,0,0,2,0,0
0,0,2,2,0,0,0,0,0,0,0,0,0,12,2,0,0
0,0,0,0,0,2,0,12,0,2,0,2,0,0,0,0,0
0,0,0,0,0,2,2,2,2,2,2,2,0,0,0,0,0
endlayer

layer
0,0,0,0,0,2,0,2,2,2,0,2,0,0,0,0,0
0,0,2,2,0,2,0,12,0,0,0,2,0,2,2,0,0
0,2,2,2,0,0,0,0,0,0,0,0,0,12,2,2,0
0,2,2,0,0,0,0,0,0,0,0,0,0,0,0,2,0
0,0,0,0,0,0,0,0,0,0,0,0,0,0,0,0,0
2,2,19,19,19,0,0,0,0,0,0,0,0,0,0,2,2
0,4,4,4,4,0,0,0,0,0,0,0,0,0,0,0,0
2,2,2,5,11,0,0,0,0,0,0,0,0,0,0,12,2
2,3,3,3,0,0,0,0,0,0,0,0,0,0,0,0,2
2,0,0,0,0,0,0,0,0,0,0,0,0,0,0,0,2
0,0,0,0,0,0,0,0,0,0,0,0,0,0,0,0,0
2,2,0,0,0,0,0,0,0,0,0,0,0,0,0,2,2
0,0,0,0,0,0,0,0,0,0,0,0,0,0,0,0,0
0,2,12,0,0,0,0,0,0,0,0,0,0,0,12,2,0
0,2,2,2,0,0,0,0,0,0,0,0,0,0,2,2,0
0,0,2,2,0,2,0,0,0,12,0,2,0,2,2,0,0
0,0,0,0,0,2,0,2,2,2,0,2,0,0,0,0,0
endlayer

layer
2,2,2,2,2,2,0,2,0,2,0,2,2,2,2,2,2
2,2,2,2,2,2,0,0,0,0,0,2,2,2,2,2,2
2,2,2,2,4,19,0,0,0,0,0,0,0,0,2,2,2
2,2,2,4,4,19,0,0,0,0,0,0,0,0,0,2,2
2,2,4,4,4,4,0,0,0,0,0,0,0,0,0,2,2
2,2,4,4,4,4,0,0,0,0,0,0,0,0,0,2,2
0,3,3,3,3,0,0,0,0,0,0,0,0,0,0,0,0
2,0,0,0,0,0,0,0,0,0,0,0,0,0,0,0,2
0,0,0,0,0,0,0,0,0,0,0,0,0,0,0,0,0
2,0,0,0,0,0,0,0,0,0,0,0,0,0,0,0,2
0,0,0,0,0,0,0,0,0,0,0,0,0,0,0,0,0
2,2,0,0,0,0,0,0,0,0,0,0,0,0,0,2,2
2,2,0,0,0,0,0,0,0,0,0,0,0,0,0,2,2
2,2,0,0,0,0,0,0,0,0,0,0,0,0,0,2,2
2,2,2,12,0,0,0,0,0,0,0,0,0,0,2,2,2
2,2,2,2,2,2,0,0,0,0,0,2,2,2,2,2,2
2,2,2,2,2,2,0,2,0,2,0,2,2,2,2,2,2
endlayer

layer
1,1,1,1,2,2,2,2,0,2,2,2,2,1,1,1,1
1,1,2,0,2,2,4,19,0,0,12,2,2,0,2,1,1
1,2,2,3,3,4,4,19,0,0,0,0,0,0,2,2,1
1,0,0,0,3,4,4,19,0,0,0,0,0,0,0,0,1
2,2,0,0,3,11,4,19,0,0,0,0,0,0,0,2,2
2,2,0,0,0,0,0,0,0,0,0,0,0,0,0,2,2
2,12,0,0,0,0,0,0,0,0,0,0,0,0,0,12,2
2,0,0,0,0,0,0,0,0,0,0,0,0,0,0,0,2
0,0,0,0,0,0,0,0,0,0,0,0,0,0,0,0,0
2,0,0,0,0,0,0,0,0,0,0,0,0,0,0,0,2
2,12,0,0,0,0,0,0,0,0,0,0,0,0,0,12,2
2,2,0,0,0,0,0,0,0,0,0,0,0,0,0,2,2
2,2,0,0,0,0,0,0,0,0,0,0,0,0,0,2,2
1,0,0,0,0,0,0,0,0,0,0,0,0,0,0,0,1
1,2,2,0,0,0,0,0,0,0,0,0,0,0,2,2,1
1,1,2,0,2,2,12,0,0,0,12,2,2,0,2,1,1
1,1,1,1,2,2,2,2,0,2,2,2,2,1,1,1,1
endlayer

layer
1,1,1,1,2,0,2,2,2,2,2,0,2,1,1,1,1
1,1,2,0,2,0,3,4,4,19,2,0,2,0,2,1,1
1,2,2,0,0,0,3,4,4,19,0,0,0,0,2,2,1
1,0,0,0,0,0,3,11,4,19,0,0,0,0,0,0,1
2,2,0,0,0,0,0,10,19,0,0,0,0,0,0,2,2
0,0,0,0,0,0,0,0,0,0,0,0,0,0,0,0,0
2,2,0,0,0,0,0,0,0,0,0,0,0,0,0,2,2
2,0,0,0,0,0,0,0,0,0,0,0,0,0,0,0,2
2,12,0,0,0,0,0,0,0,0,0,0,0,0,0,12,2
2,0,0,0,0,0,0,0,0,0,0,0,0,0,0,0,2
2,2,0,0,0,0,0,0,0,0,0,0,0,0,0,2,2
0,0,0,0,0,0,0,0,0,0,0,0,0,0,0,0,0
2,2,0,0,0,0,0,0,0,0,0,0,0,0,0,2,2
1,0,0,0,0,0,0,0,0,0,0,0,0,0,0,0,1
1,2,2,0,0,0,0,0,0,0,0,0,0,0,2,2,1
1,1,2,0,2,0,2,0,12,0,2,0,2,0,2,1,1
1,1,1,1,2,0,2,2,2,2,2,0,2,1,1,1,1
endlayer

layer
1,1,1,1,2,0,2,0,2,0,2,0,2,1,1,1,1
1,1,2,2,2,0,0,0,3,4,4,19,2,2,2,1,1
1,2,2,12,0,0,0,0,3,4,4,19,19,19,2,2,1
1,2,12,0,0,0,0,0,3,4,4,19,0,0,12,2,1
2,2,0,0,0,0,0,0,3,4,19,0,0,0,0,2,2
0,0,0,0,0,0,0,0,0,0,0,0,0,0,0,0,0
2,0,0,0,0,0,0,0,0,0,0,0,0,0,0,0,2
0,0,0,0,0,0,0,0,0,0,0,0,0,0,0,0,0
2,2,0,0,0,0,0,0,0,0,0,0,0,0,0,2,2
0,0,0,0,0,0,0,0,0,0,0,0,0,0,0,0,0
2,0,0,0,0,0,0,0,0,0,0,0,0,0,0,0,2
0,0,0,0,0,0,0,0,0,0,0,0,0,0,0,0,0
2,2,0,0,0,0,0,0,0,0,0,0,0,0,0,2,2
1,2,12,0,0,0,0,0,0,0,0,0,0,0,12,2,1
1,2,2,12,0,0,0,0,0,0,0,0,0,12,2,2,1
1,1,2,2,2,0,0,0,2,0,0,0,2,2,2,1,1
1,1,1,1,2,0,2,0,2,0,2,0,2,1,1,1,1
endlayer

layer
1,1,1,1,2,2,2,0,2,0,2,2,2,1,1,1,1
1,1,2,2,2,12,0,0,0,0,3,2,2,2,2,1,1
1,2,2,2,0,0,0,0,0,0,3,4,4,2,2,2,1
1,2,2,0,0,0,0,0,0,0,3,4,4,4,2,2,1
2,2,0,0,0,0,0,0,0,0,10,4,19,19,19,2,2
2,12,0,0,0,0,0,0,0,0,10,19,0,0,0,12,2
2,0,0,0,0,0,0,0,0,0,0,0,0,0,0,0,2
0,0,0,0,0,0,0,0,0,0,0,0,0,0,0,0,0
2,0,0,0,0,0,0,0,0,0,0,0,0,0,0,0,2
0,0,0,0,0,0,0,0,0,0,0,0,0,0,0,0,0
2,0,0,0,0,0,0,0,0,0,0,0,0,0,0,0,2
2,12,0,0,0,0,0,0,0,0,0,0,0,0,0,12,2
2,2,0,0,0,0,0,0,0,0,0,0,0,0,0,2,2
1,2,2,0,0,0,0,0,0,0,0,0,0,0,2,2,1
1,2,2,2,0,0,0,0,0,0,0,0,0,2,2,2,1
1,1,2,2,2,12,0,0,0,0,0,12,2,2,2,1,1
1,1,1,1,2,2,2,0,2,0,2,2,2,1,1,1,1
endlayer

layer
1,1,1,1,0,2,2,2,2,2,2,2,0,1,1,1,1
1,1,2,2,0,2,0,12,0,12,0,2,0,2,2,1,1
1,2,2,2,0,0,0,0,0,0,0,0,0,2,2,2,1
1,2,2,0,0,0,0,0,0,0,0,0,0,3,2,2,1
0,0,0,0,0,0,0,0,0,0,0,0,3,3,3,0,0
2,2,0,0,0,0,0,0,0,0,0,10,6,4,4,2,2
2,0,0,0,0,0,0,0,0,0,0,6,4,19,19,3,2
2,12,0,0,0,0,0,0,0,0,0,0,0,0,0,12,2
2,0,0,0,0,0,0,0,0,0,0,0,0,0,0,0,2
2,12,0,0,0,0,0,0,0,0,0,0,0,0,0,12,2
2,0,0,0,0,0,0,0,0,0,0,0,0,0,0,0,2
2,2,0,0,0,0,0,0,0,0,0,0,0,0,0,2,2
0,0,0,0,0,0,0,0,0,0,0,0,0,0,0,0,0
1,2,2,0,0,0,0,0,0,0,0,0,0,0,2,2,1
1,2,2,2,0,0,0,0,0,0,0,0,0,2,2,2,1
1,1,2,2,0,2,0,12,0,12,0,2,0,2,2,1,1
1,1,1,1,0,2,2,2,2,2,2,2,0,1,1,1,1
endlayer

layer
1,1,1,1,0,2,0,2,2,2,0,2,0,1,1,1,1
1,1,2,2,0,2,0,2,0,2,0,2,0,2,2,1,1
1,2,2,2,0,0,0,0,0,0,0,0,0,2,2,2,1
1,2,2,0,0,0,0,0,0,0,0,0,0,0,2,2,1
0,0,0,0,0,0,0,0,0,0,0,0,0,0,0,0,0
2,2,0,0,0,0,0,0,0,0,0,0,0,0,0,2,2
0,0,0,0,0,0,0,0,0,0,0,0,3,3,3,3,0
2,2,0,0,0,0,0,0,0,0,0,6,10,4,4,2,2
2,0,0,0,0,0,0,0,0,0,0,19,19,19,19,3,2
2,2,0,0,0,0,0,0,0,0,0,0,0,0,0,2,2
0,0,0,0,0,0,0,0,0,0,0,0,0,0,0,0,0
2,2,0,0,0,0,0,0,0,0,0,0,0,0,0,2,2
0,0,0,0,0,0,0,0,0,0,0,0,0,0,0,0,0
1,2,2,0,0,0,0,0,0,0,0,0,0,0,2,2,1
1,2,2,2,0,0,0,0,0,0,0,0,0,2,2,2,1
1,1,2,2,0,2,0,2,0,2,0,2,0,2,2,1,1
1,1,1,1,0,2,0,2,2,2,0,2,0,1,1,1,1
endlayer

layer
1,1,1,1,2,2,0,2,0,2,0,2,2,1,1,1,1
1,1,2,2,2,2,0,2,0,2,0,2,2,2,2,1,1
1,2,2,2,12,0,0,0,0,0,0,0,12,2,2,2,1
1,2,2,0,0,0,0,0,0,0,0,0,0,0,2,2,1
2,2,12,0,0,0,0,0,0,0,0,0,0,0,12,2,2
2,2,0,0,0,0,0,0,0,0,0,0,0,0,0,2,2
0,0,0,0,0,0,0,0,0,0,0,0,0,0,0,0,0
2,2,0,0,0,0,0,0,0,0,0,0,0,0,0,2,2
0,0,0,0,0,0,0,0,0,0,0,3,3,3,3,3,0
2,2,0,0,0,0,0,0,0,0,0,4,4,4,4,2,2
0,0,0,0,0,0,0,0,0,0,19,19,19,19,19,3,0
2,2,0,0,0,0,0,0,0,0,0,19,19,19,19,2,2
2,2,12,0,0,0,0,0,0,0,0,0,19,19,19,2,2
1,2,2,0,0,0,0,0,0,0,0,0,19,19,2,2,1
1,2,2,2,12,0,0,0,0,0,0,0,19,2,2,2,1
1,1,2,2,2,2,0,2,0,2,0,2,2,2,2,1,1
1,1,1,1,2,2,0,2,0,2,0,2,2,1,1,1,1
endlayer

layer
1,1,1,1,2,2,2,2,0,2,2,2,2,1,1,1,1
1,1,2,0,2,2,2,2,0,2,2,2,2,0,2,1,1
1,2,2,0,2,0,12,0,0,0,12,0,2,0,2,2,1
1,0,0,0,0,0,0,0,0,0,0,0,0,0,0,0,1
2,2,2,0,0,0,0,0,0,0,0,0,0,0,2,2,2
2,2,0,0,0,0,0,0,0,0,0,0,0,0,0,2,2
2,2,12,0,0,0,0,0,0,0,0,0,0,0,12,2,2
2,2,0,0,0,0,0,0,0,0,0,0,0,0,0,2,2
0,0,0,0,0,0,0,0,0,0,0,0,0,0,0,0,0
2,2,0,0,0,0,0,0,0,0,0,0,0,0,0,2,2
2,2,12,0,0,0,0,0,0,19,5,3,3,3,12,2,2
2,2,0,0,0,0,0,0,0,19,2,4,4,4,4,2,2
2,2,2,0,0,0,0,0,0,19,2,4,4,4,2,2,2
1,0,0,0,0,0,0,0,0,19,2,4,4,4,0,0,1
1,2,2,0,2,0,12,0,0,19,2,4,2,0,2,2,1
1,1,2,0,2,2,2,2,0,2,2,2,2,0,2,1,1
1,1,1,1,2,2,2,2,0,2,2,2,2,1,1,1,1
endlayer

layer
1,1,1,1,2,0,2,2,2,2,2,0,2,1,1,1,1
1,1,2,0,2,0,2,2,2,2,2,0,2,0,2,1,1
1,2,2,0,2,0,2,0,12,0,2,0,2,0,2,2,1
1,0,0,0,0,0,0,0,0,0,0,0,0,0,0,0,1
2,2,2,0,0,0,0,0,0,0,0,0,0,0,2,2,2
0,0,0,0,0,0,0,0,0,0,0,0,0,0,0,0,0
2,2,2,0,0,0,0,0,0,0,0,0,0,0,2,2,2
2,2,0,0,0,0,0,0,0,0,0,0,0,0,0,2,2
2,2,12,0,0,0,0,0,0,0,0,0,0,0,12,2,2
2,2,0,0,0,0,0,0,0,0,0,0,0,0,0,2,2
2,2,2,0,0,0,0,0,19,5,0,0,0,0,2,2,2
0,0,0,0,0,0,0,0,4,5,0,0,0,0,0,0,0
2,2,2,0,0,0,0,0,4,6,5,3,3,0,2,2,2
1,0,0,0,0,0,0,0,4,4,4,3,3,3,0,0,1
1,2,2,0,2,0,2,0,4,4,2,0,2,0,2,2,1
1,1,2,0,2,0,2,2,2,2,2,0,2,0,2,1,1
1,1,1,1,2,0,2,2,2,2,2,0,2,1,1,1,1
endlayer

layer
1,1,1,1,2,0,2,0,2,0,2,0,2,1,1,1,1
1,1,2,2,2,0,2,0,2,0,2,0,2,2,2,1,1
1,2,2,2,2,0,2,0,2,0,2,0,2,2,2,2,1
1,2,2,12,0,0,0,0,0,0,0,0,0,12,2,2,1
2,2,2,0,0,0,0,0,0,0,0,0,0,0,2,2,2
0,0,0,0,0,0,0,0,0,0,0,0,0,0,0,0,0
2,2,2,0,0,0,0,0,0,0,0,0,0,0,2,2,2
0,0,0,0,0,0,0,0,0,0,0,0,0,0,0,0,0
2,2,2,0,0,0,0,0,0,0,0,0,0,0,2,2,2
0,0,0,0,0,0,0,0,0,0,0,0,0,0,0,0,0
2,2,2,0,0,0,0,19,5,0,0,0,0,0,2,2,2
0,0,0,0,0,0,19,4,5,0,0,0,0,0,0,0,0
2,2,2,0,0,0,19,4,5,0,0,0,0,0,2,2,2
1,2,2,12,0,0,19,4,4,3,0,0,0,2,2,2,1
1,2,2,2,2,0,2,4,2,0,2,0,2,2,2,2,1
1,1,2,2,2,0,2,0,2,0,2,0,2,2,2,1,1
1,1,1,1,2,0,2,0,2,0,2,0,2,1,1,1,1
endlayer

layer
1,1,1,1,2,2,2,0,2,0,2,2,2,1,1,1,1
1,1,2,2,2,2,2,0,2,0,2,2,2,2,2,1,1
1,2,2,2,2,2,2,0,2,0,2,2,2,2,2,2,1
1,2,2,2,0,12,0,0,0,0,0,12,0,2,2,2,1
2,2,2,0,0,0,0,0,0,0,0,0,0,0,2,2,2
2,2,2,12,0,0,0,0,0,0,0,0,0,12,2,2,2
2,2,2,0,0,0,0,0,0,0,0,0,0,0,2,2,2
0,0,0,0,0,0,0,0,0,0,0,0,0,0,0,0,0
2,2,2,0,0,0,0,0,0,0,0,0,0,0,2,2,2
0,0,0,0,0,19,19,22,0,0,0,0,0,0,0,0,0
2,2,2,0,19,19,2,5,0,0,0,0,0,0,2,2,2
2,2,2,19,19,4,2,3,0,0,0,0,0,12,2,2,2
2,2,2,4,4,4,2,3,0,0,0,0,0,0,2,2,2
1,2,2,2,4,4,4,3,0,0,0,12,0,2,2,2,1
1,2,2,2,2,2,2,0,2,0,2,2,2,2,2,2,1
1,1,2,2,2,2,2,0,2,0,2,2,2,2,2,1,1
1,1,1,1,2,2,2,0,2,0,2,2,2,1,1,1,1
endlayer

