
# Created by Ruins mod version 16.7 Ingame Parser
# authoring Player: lafuller

weight=1
embed_into_distance=4
acceptable_target_blocks=
unacceptable_target_blocks=flowing_water,water,flowing_lava,lava,ice,bedrock,netherrack,nether_brick,nether_brick_fence,soul_sand,quartz_ore,end_stone,obsidian,iron_bars,cloud,flesh,ash_block,slime_grass,slime_congealed,slime_dirt
biomesToSpawnIn=plains,mutated_plains,forest,birch forest,taiga,woodland,woodlands,prarie,meadow,badlands,lavender fields,flower field,sunflower plains
dimensions=10,9,10
allowable_overhang=0
max_leveling=4
leveling_buffer=-1
preserve_water=0
preserve_lava=0

rule1=0,100,preserveBlock
rule2=0,100,minecraft:stone-6
rule3=0,100,stonebrick-0,stonebrick-0,stonebrick-0,stonebrick-0,stonebrick-1,stonebrick-2,stonebrick-2,stone-5,stone-6,cobblestone
rule4=0,100,stonebrick-0,stonebrick-2,stonebrick-2,stonebrick-1,stonebrick-1,cobblestone
rule5=0,100,stonebrick-0,stonebrick-1,stonebrick-2,stone-5,stone-5,stone-6,mycelium-0,mycelium
rule6=0,100,stonebrick-0,stonebrick-0,stonebrick-2,mycelium-0,mycelium-0,mycelium-0,mycelium
rule7=0,100,minecraft:stone_brick_stairs-1
rule8=0,100,minecraft:stone-5
rule9=0,100,stonebrick-0,stonebrick-0,stonebrick-0,stonebrick-0,stonebrick-1,stonebrick-2,stonebrick-2,stone-5,stone-6,cobblestone,gravel
rule10=0,100,minecraft:log-0
rule11=0,100,minecraft:wooden_slab-9
rule12=0,100,minecraft:ladder-3
rule13=0,100,ChestGenHook:chests/stronghold_corridor:5-2
rule14=0,100,minecraft:stone_brick_stairs-0
rule15=0,100,minecraft:planks-0,oak_stairs-0,oak_stairs-1,oak_stairs-4,oak_stairs-5,air
rule16=0,100,minecraft:planks-1,spruce_stairs-0,spruce_stairs-1,spruce_stairs-4,spruce_stairs-5,air,air,air
rule17=0,100,minecraft:planks-5,dark_oak_stairs-0,dark_oak_stairs-1,dark_oak_stairs-4,dark_oak_stairs-5,air,air,air,air,air,air
rule18=0,100,minecraft:log2-1

layer
3,2,3,3,3,3,3,3,2,1
3,3,4,4,4,4,4,4,3,1
3,3,4,5,5,5,5,4,2,2
3,3,4,5,6,6,5,4,4,3
3,3,4,5,5,6,6,5,4,3
3,3,4,4,5,6,6,5,4,3
3,2,3,2,4,5,5,5,4,3
3,3,3,3,4,4,4,4,4,3
7,7,7,2,3,3,3,3,3,2
endlayer

layer
9,8,9,9,9,9,9,9,8,1
9,9,10,11,11,11,11,10,9,1
9,9,11,0,0,0,0,12,8,8
9,9,11,0,0,0,0,0,10,9
9,9,11,0,0,0,0,0,11,9
9,9,10,0,0,0,0,0,11,9
9,8,9,8,13,0,0,0,11,9
7,7,7,9,10,11,11,11,10,9
1,1,1,8,9,9,9,9,9,8
endlayer

layer
14,2,9,9,9,9,9,9,2,1
9,9,10,0,0,0,0,10,9,1
9,9,0,0,0,0,0,12,2,2
9,9,0,0,0,0,0,0,10,9
9,9,0,0,0,0,0,0,0,9
9,9,10,0,0,0,0,0,0,9
7,2,9,2,0,0,0,0,0,9
1,1,1,9,10,0,0,0,10,9
1,1,1,2,9,9,9,9,9,2
endlayer

layer
1,8,9,9,9,9,9,9,8,1
14,9,10,0,0,0,0,10,9,1
9,9,0,0,0,0,0,12,8,8
9,9,0,0,0,0,0,0,10,9
9,9,0,0,0,0,0,0,0,9
7,9,10,0,0,0,0,0,0,9
1,8,9,8,0,0,0,0,0,9
1,1,1,9,10,0,0,0,10,9
1,1,1,8,9,9,9,9,9,8
endlayer

layer
1,2,9,9,9,9,9,9,2,1
1,9,15,15,16,16,16,15,9,1
14,9,15,16,17,17,17,12,2,2
9,15,16,17,17,17,17,17,15,9
7,9,16,17,17,17,17,17,16,9
1,9,15,16,17,17,17,17,16,9
1,2,9,2,16,16,17,16,15,9
1,1,1,9,15,16,16,15,15,9
1,1,1,2,9,9,9,9,9,2
endlayer

layer
1,18,1,1,0,0,1,1,18,1
1,1,1,0,0,0,0,0,1,1
1,1,0,0,0,0,0,0,18,18
1,0,0,0,0,0,0,0,0,1
1,0,0,0,0,0,0,0,0,1
1,1,0,0,0,0,0,0,0,1
1,18,1,18,0,0,0,0,1,1
1,1,1,1,0,0,0,1,1,1
1,1,1,18,1,1,1,1,1,18
endlayer

layer
1,18,1,0,0,0,0,1,18,1
1,1,0,0,0,0,0,0,1,1
1,0,0,0,0,0,0,0,18,18
0,0,0,0,0,0,0,0,0,1
0,0,0,0,0,0,0,0,0,0
0,0,0,0,0,0,0,0,0,0
1,18,0,18,0,0,0,0,0,1
1,1,0,0,0,0,0,0,1,1
1,1,1,18,1,0,0,1,1,18
endlayer

layer
1,18,0,0,0,0,0,1,18,1
1,0,0,0,0,0,0,0,0,1
0,0,0,0,0,0,0,0,18,18
0,0,0,0,0,0,0,0,0,0
0,0,0,0,0,0,0,0,0,0
0,0,0,0,0,0,0,0,0,0
0,18,0,0,0,0,0,0,0,0
1,0,0,0,0,0,0,0,0,1
1,1,0,18,0,0,0,0,1,18
endlayer

layer
1,0,0,0,0,0,0,0,18,1
0,0,0,0,0,0,0,0,0,0
0,0,0,0,0,0,0,0,0,18
0,0,0,0,0,0,0,0,0,0
0,0,0,0,0,0,0,0,0,0
0,0,0,0,0,0,0,0,0,0
0,18,0,0,0,0,0,0,0,0
0,0,0,0,0,0,0,0,0,0
1,0,0,0,0,0,0,0,0,18
endlayer

layer
0,0,0,0,0,0,0,0,0,0
0,0,0,0,0,0,0,0,0,0
0,0,0,0,0,0,0,0,0,18
0,0,0,0,0,0,0,0,0,0
0,0,0,0,0,0,0,0,0,0
0,0,0,0,0,0,0,0,0,0
0,18,0,0,0,0,0,0,0,0
0,0,0,0,0,0,0,0,0,0
0,0,0,0,0,0,0,0,0,0
endlayer

