
# Created by Ruins mod version 16.7 Ingame Parser
# authoring Player: lafuller

weight=1
embed_into_distance=4
acceptable_target_blocks=
unacceptable_target_blocks=flowing_water,water,flowing_lava,lava,ice,bedrock,netherrack,nether_brick,nether_brick_fence,soul_sand,quartz_ore,end_stone,obsidian,iron_bars,cloud,flesh,ash_block,slime_grass,slime_congealed,slime_dirt
biomesToSpawnIn=plains,mutated_plains,forest,birch forest,taiga,woodland,woodlands,prarie,meadow,badlands,lavender fields,flower field,sunflower plains
dimensions=16,13,14
allowable_overhang=0
max_leveling=4
leveling_buffer=-1
preserve_water=0
preserve_lava=0

rule1=0,100,preserveBlock
rule2=0,100,minecraft:stone-6
rule3=0,100,stonebrick-0,stonebrick-0,stonebrick-0,stonebrick-0,stonebrick-1,stonebrick-2,stonebrick-2,stone-5,stone-6,cobblestone
rule4=0,100,stonebrick-0,stonebrick-2,stonebrick-2,stonebrick-1,stonebrick-1,cobblestone
rule5=0,100,stonebrick-0,stonebrick-1,stonebrick-2,stone-5,stone-5,stone-6,mycelium-0,mycelium
rule6=0,100,stonebrick-0,stonebrick-0,stonebrick-2,mycelium-0,mycelium-0,mycelium-0,mycelium
rule7=0,100,minecraft:stone_stairs-2
rule8=0,100,minecraft:stone-5
rule9=0,100,stonebrick-0,stonebrick-0,stonebrick-0,stonebrick-0,stonebrick-1,stonebrick-2,stonebrick-2,stone-5,stone-6,cobblestone,gravel
rule10=0,100,minecraft:cobblestone_wall-0
rule11=0,100,minecraft:log-0
rule12=0,100,minecraft:wooden_slab-9
rule13=0,100,minecraft:oak_stairs-0,air
rule14=0,100,planks-0,oak_stairs-0,oak_stairs-1,oak_stairs-4,oak_stairs-5,air
rule15=0,100,ChestGenHook:chests/jungle_temple:5-4
rule16=0,100,minecraft:oak_stairs-7,air
rule17=0,100,minecraft:log2-1
rule18=0,100,minecraft:oak_stairs-2,air
rule19=0,100,planks-1,spruce_stairs-0,spruce_stairs-1,spruce_stairs-4,spruce_stairs-5,air,air,air
rule20=0,100,minecraft:spruce_stairs-6,air
rule21=0,100,planks-5,dark_oak_stairs-0,dark_oak_stairs-1,dark_oak_stairs-4,dark_oak_stairs-5,air,air,air,air,air,air
rule22=0,100,minecraft:stone_stairs-1
rule23=0,100,minecraft:spruce_stairs-3,air
rule24=0,100,minecraft:spruce_stairs-5,air
rule25=0,100,minecraft:spruce_stairs-0,air
rule26=0,100,minecraft:spruce_stairs-7,air
rule27=0,100,minecraft:log2-9
rule28=0,100,minecraft:log2-5
rule29=0,100,minecraft:spruce_stairs-2,air
rule30=0,100,minecraft:log-9
rule31=0,100,minecraft:log-5
rule32=0,100,minecraft:log-1

layer
1,1,2,3,3,3,3,3,2,1,1,1,1,1
1,1,3,4,4,4,4,4,3,1,1,1,1,1
1,1,3,4,4,5,5,4,2,3,3,3,3,2
1,1,3,4,5,6,5,4,4,4,4,4,4,3
1,1,3,4,4,5,6,5,6,5,5,4,4,3
1,1,3,4,5,6,6,5,6,6,6,5,4,3
2,3,2,4,5,6,6,6,5,5,5,5,4,3
3,4,4,5,6,6,6,5,4,4,4,4,4,3
3,4,5,6,6,5,5,5,4,2,3,3,3,2
3,4,5,5,4,4,4,4,4,3,1,1,1,1
3,4,4,4,4,2,3,3,3,2,1,1,1,1
3,3,3,3,3,3,3,3,3,3,3,3,7,1
2,3,3,3,3,2,3,3,3,3,3,3,7,1
endlayer

layer
1,1,8,9,10,9,10,9,8,1,1,1,1,1
1,1,9,11,12,12,12,11,9,1,1,1,1,1
1,1,10,12,0,0,0,0,8,9,10,9,10,8
1,1,9,12,0,0,0,0,0,0,0,0,0,9
1,1,10,12,0,0,0,0,0,0,0,0,0,10
1,1,9,11,0,0,0,0,0,0,11,13,13,9
8,9,8,0,0,0,0,0,0,0,0,14,14,9
9,11,0,0,0,0,0,0,0,0,15,14,14,9
10,12,0,0,0,0,0,0,0,8,9,10,9,8
9,12,0,0,0,11,12,12,11,9,1,1,1,1
10,12,0,0,0,8,9,9,9,8,1,1,1,1
9,11,12,12,11,9,9,9,9,9,9,7,1,1
8,9,10,9,9,8,9,9,9,9,9,7,1,1
endlayer

layer
1,1,2,9,10,9,10,9,2,1,1,1,1,1
1,1,9,11,0,0,0,11,9,1,1,1,1,1
1,1,10,0,0,0,0,0,2,9,10,9,10,2
1,1,9,0,0,0,0,0,0,0,0,0,0,9
1,1,10,0,0,0,0,0,0,0,0,0,0,10
1,1,9,11,0,0,0,0,0,0,11,0,0,9
2,9,2,0,0,0,0,0,0,0,16,13,13,10
9,11,0,0,0,0,0,0,0,0,16,14,14,9
10,0,0,0,0,0,0,0,0,2,9,10,9,2
9,0,0,0,0,11,0,0,11,9,1,1,1,1
10,0,0,0,0,2,9,9,9,2,1,1,1,1
9,11,0,0,11,9,9,9,9,9,7,1,1,1
2,9,10,9,9,2,9,9,9,9,7,1,1,1
endlayer

layer
1,1,8,9,10,9,10,9,8,1,1,1,1,1
1,1,9,11,0,0,0,11,9,1,1,1,1,1
1,1,10,0,0,0,0,0,8,9,10,9,10,8
1,1,9,0,0,0,0,0,0,0,0,0,0,9
1,1,10,0,0,0,0,0,0,0,0,0,0,10
1,1,9,11,0,0,0,0,0,0,17,0,0,9
8,9,8,0,0,0,0,0,0,0,18,0,0,10
9,11,0,0,0,0,0,0,0,0,18,0,0,9
10,0,0,0,0,0,0,0,0,8,9,10,9,8
9,0,0,0,0,11,0,0,11,9,1,1,1,1
10,0,0,0,0,8,9,9,9,8,1,1,1,1
9,11,0,0,11,9,9,9,9,7,1,1,1,1
8,9,10,9,9,8,9,9,9,7,1,1,1,1
endlayer

layer
1,1,2,9,9,9,9,9,2,1,1,1,1,1
1,1,9,14,14,14,14,14,9,1,1,1,1,1
1,1,9,14,14,19,19,14,2,9,9,9,9,2
1,1,9,14,19,21,19,19,14,14,20,0,0,9
1,1,9,14,19,21,21,19,19,19,20,0,0,9
1,1,9,14,21,21,21,21,19,19,17,0,0,9
2,9,2,14,21,21,21,21,19,18,0,0,0,9
9,14,14,19,21,21,21,19,14,18,0,0,0,9
9,14,19,19,19,21,19,19,14,2,9,9,9,2
9,14,19,19,19,19,14,14,14,9,1,1,1,1
9,14,14,19,14,2,9,14,9,2,1,1,1,1
9,14,14,14,14,9,9,9,7,1,1,1,1,1
2,9,9,9,9,2,22,22,7,1,1,1,1,1
endlayer

layer
1,1,17,1,1,0,0,0,17,1,1,1,1,1
1,1,1,0,0,0,0,0,0,0,1,1,1,1
1,1,1,0,0,0,0,0,17,0,0,1,1,17
1,1,0,0,0,0,0,0,0,23,14,14,14,1
1,1,0,0,0,0,0,0,0,23,14,24,24,1
1,0,0,0,0,0,0,0,0,0,17,0,0,0
17,0,17,0,0,0,0,0,0,0,0,0,0,0
1,0,0,0,0,0,0,0,0,0,0,0,0,1
1,0,0,0,0,0,0,0,0,17,0,0,0,17
1,1,0,0,0,0,0,0,0,0,0,0,1,1
1,1,1,0,0,17,0,0,0,17,0,1,1,1
1,1,1,1,0,0,0,0,0,0,1,1,1,1
17,1,1,1,1,17,0,0,1,1,1,1,1,1
endlayer

layer
1,1,17,1,0,0,0,0,17,0,1,1,1,1
1,1,0,0,0,0,0,0,0,0,0,1,1,1
1,1,0,0,0,0,0,0,17,0,0,0,1,17
1,0,0,0,0,0,0,0,0,0,23,14,14,1
0,0,0,0,0,0,0,0,0,0,23,19,14,0
0,0,0,0,0,0,0,0,0,0,17,24,24,0
17,0,17,0,0,0,0,0,0,0,0,0,0,0
0,0,0,0,0,0,0,0,0,0,0,0,0,0
1,0,0,0,0,0,0,0,0,17,0,0,0,17
1,0,0,0,0,0,0,0,0,0,0,0,0,1
1,1,0,0,0,17,0,0,0,17,0,0,1,1
1,1,1,0,0,0,0,0,0,0,0,1,1,1
17,1,1,1,0,17,0,0,0,0,1,1,1,1
endlayer

layer
1,1,17,0,0,0,0,0,17,0,0,1,1,1
1,0,0,0,0,0,0,0,0,0,0,0,1,1
1,0,0,0,0,0,0,0,17,0,0,0,0,17
0,0,0,0,0,0,0,0,0,0,0,0,0,0
0,0,0,0,0,0,0,0,0,0,0,0,0,0
0,0,0,0,0,0,0,0,0,0,17,25,13,0
17,0,17,0,0,0,0,0,0,0,0,26,24,0
0,0,0,0,0,0,0,0,0,0,0,0,0,0
0,0,0,0,0,0,0,0,0,17,0,0,0,17
0,0,0,0,0,0,0,0,0,0,0,0,0,0
1,0,0,0,0,17,0,0,0,17,0,0,0,1
1,1,0,0,0,0,0,0,0,0,0,0,1,1
17,1,1,0,0,17,0,0,0,0,0,1,1,1
endlayer

layer
1,0,17,0,0,0,0,0,17,0,0,0,1,1
1,0,0,0,0,0,0,0,0,0,0,0,0,1
0,0,0,0,0,0,0,0,17,0,0,0,0,17
0,0,0,0,0,0,0,0,0,0,0,0,0,0
0,0,0,0,0,0,0,0,0,0,0,0,0,0
0,0,0,0,0,0,0,0,0,0,17,0,0,0
17,0,17,0,0,0,0,0,0,0,16,25,13,0
0,0,0,0,0,0,0,0,0,0,0,14,14,0
0,0,0,0,0,0,0,0,0,17,0,0,0,17
0,0,0,0,0,0,0,0,0,0,0,0,0,0
0,0,0,0,0,17,0,0,0,17,0,0,0,0
1,0,0,0,0,0,0,0,0,0,0,0,0,1
17,0,0,0,0,17,0,0,0,0,0,0,1,1
endlayer

layer
1,0,17,27,27,27,27,27,17,0,0,0,0,1
0,0,28,14,14,19,19,14,28,0,0,0,0,0
0,0,28,14,19,0,0,19,17,27,27,27,27,17
0,0,28,19,0,0,0,0,21,28,0,0,0,28
0,0,28,21,0,0,0,0,21,28,0,0,0,28
0,0,28,21,0,0,0,0,21,28,17,0,0,28
17,27,17,30,0,0,0,0,30,28,29,0,0,28
28,14,19,0,0,0,0,0,21,28,29,0,0,28
28,19,0,0,0,0,0,0,19,17,27,27,27,17
28,19,0,0,0,31,19,19,14,28,0,0,0,0
28,14,19,0,21,17,27,27,27,17,0,0,0,0
28,14,14,19,19,28,0,0,0,0,0,0,0,0
17,27,27,27,27,17,0,0,0,0,0,0,0,1
endlayer

layer
0,0,17,0,0,0,0,0,17,0,0,0,0,0
0,0,0,0,0,0,0,0,0,0,0,0,0,0
0,0,0,0,0,0,0,0,17,0,0,0,0,17
0,0,0,0,0,0,0,0,0,0,0,0,0,0
0,0,0,0,0,0,0,0,0,0,0,0,0,0
0,0,0,0,0,0,0,0,0,0,17,0,0,0
17,0,17,0,0,0,0,0,0,0,0,0,0,0
0,0,0,0,0,0,0,0,0,0,0,0,0,0
0,0,0,0,0,0,0,0,0,17,0,0,0,17
0,0,0,0,0,0,0,0,0,0,0,0,0,0
0,0,0,0,0,17,0,0,0,17,0,0,0,0
0,0,0,0,0,0,0,0,0,0,0,0,0,0
17,0,0,0,0,17,0,0,0,0,0,0,0,0
endlayer

layer
0,0,17,0,0,0,0,0,17,0,0,0,0,0
0,0,0,0,0,0,0,0,0,0,0,0,0,0
0,0,0,0,0,0,0,0,32,0,0,0,0,17
0,0,0,0,0,0,0,0,0,0,0,0,0,0
0,0,0,0,0,0,0,0,0,0,0,0,0,0
0,0,0,0,0,0,0,0,0,0,17,0,0,0
32,0,17,0,0,0,0,0,0,0,0,0,0,0
0,0,0,0,0,0,0,0,0,0,0,0,0,0
0,0,0,0,0,0,0,0,0,32,0,0,0,32
0,0,0,0,0,0,0,0,0,0,0,0,0,0
0,0,0,0,0,17,0,0,0,17,0,0,0,0
0,0,0,0,0,0,0,0,0,0,0,0,0,0
32,0,0,0,0,32,0,0,0,0,0,0,0,0
endlayer

layer
0,0,32,0,0,0,0,0,32,0,0,0,0,0
0,0,0,0,0,0,0,0,0,0,0,0,0,0
0,0,0,0,0,0,0,0,0,0,0,0,0,17
0,0,0,0,0,0,0,0,0,0,0,0,0,0
0,0,0,0,0,0,0,0,0,0,0,0,0,0
0,0,0,0,0,0,0,0,0,0,17,0,0,0
0,0,32,0,0,0,0,0,0,0,0,0,0,0
0,0,0,0,0,0,0,0,0,0,0,0,0,0
0,0,0,0,0,0,0,0,0,0,0,0,0,0
0,0,0,0,0,0,0,0,0,0,0,0,0,0
0,0,0,0,0,17,0,0,0,32,0,0,0,0
0,0,0,0,0,0,0,0,0,0,0,0,0,0
0,0,0,0,0,32,0,0,0,0,0,0,0,0
endlayer

layer
0,0,0,0,0,0,0,0,0,0,0,0,0,0
0,0,0,0,0,0,0,0,0,0,0,0,0,0
0,0,0,0,0,0,0,0,0,0,0,0,0,32
0,0,0,0,0,0,0,0,0,0,0,0,0,0
0,0,0,0,0,0,0,0,0,0,0,0,0,0
0,0,0,0,0,0,0,0,0,0,32,0,0,0
0,0,32,0,0,0,0,0,0,0,0,0,0,0
0,0,0,0,0,0,0,0,0,0,0,0,0,0
0,0,0,0,0,0,0,0,0,0,0,0,0,0
0,0,0,0,0,0,0,0,0,0,0,0,0,0
0,0,0,0,0,32,0,0,0,0,0,0,0,0
0,0,0,0,0,0,0,0,0,0,0,0,0,0
0,0,0,0,0,0,0,0,0,0,0,0,0,0
endlayer

layer
0,0,0,0,0,0,0,0,0,0,0,0,0,0
0,0,0,0,0,0,0,0,0,0,0,0,0,0
0,0,0,0,0,0,0,0,0,0,0,0,0,0
0,0,0,0,0,0,0,0,0,0,0,0,0,0
0,0,0,0,0,0,0,0,0,0,0,0,0,0
0,0,0,0,0,0,0,0,0,0,32,0,0,0
0,0,32,0,0,0,0,0,0,0,0,0,0,0
0,0,0,0,0,0,0,0,0,0,0,0,0,0
0,0,0,0,0,0,0,0,0,0,0,0,0,0
0,0,0,0,0,0,0,0,0,0,0,0,0,0
0,0,0,0,0,0,0,0,0,0,0,0,0,0
0,0,0,0,0,0,0,0,0,0,0,0,0,0
0,0,0,0,0,0,0,0,0,0,0,0,0,0
endlayer

layer
0,0,0,0,0,0,0,0,0,0,0,0,0,0
0,0,0,0,0,0,0,0,0,0,0,0,0,0
0,0,0,0,0,0,0,0,0,0,0,0,0,0
0,0,0,0,0,0,0,0,0,0,0,0,0,0
0,0,0,0,0,0,0,0,0,0,0,0,0,0
0,0,0,0,0,0,0,0,0,0,32,0,0,0
0,0,0,0,0,0,0,0,0,0,0,0,0,0
0,0,0,0,0,0,0,0,0,0,0,0,0,0
0,0,0,0,0,0,0,0,0,0,0,0,0,0
0,0,0,0,0,0,0,0,0,0,0,0,0,0
0,0,0,0,0,0,0,0,0,0,0,0,0,0
0,0,0,0,0,0,0,0,0,0,0,0,0,0
0,0,0,0,0,0,0,0,0,0,0,0,0,0
endlayer

