
# Gilly's Underground Mineshaft Stairwell

# template generated with Ruins mod version 16.5 Ingame Parser
# Structure created and developed by Gilly

weight=1
embed_into_distance=49
acceptable_target_blocks=
unacceptable_target_blocks=flowing_water,water,flowing_lava,lava,ice,bedrock,netherrack,nether_brick,nether_brick_fence,soul_sand,quartz_ore,end_stone,obsidian,iron_bars,Natura:Cloud
dimensions=51,14,4
allowable_overhang=0
max_leveling=3
leveling_buffer=-1
preserve_water=0
preserve_lava=0

rule1=0,100,preserveBlock
rule2=0,100,CommandBlock:RUINSTRIGGER /testruin Gilly/GillyMH1 ~3 ~2 ~-3 0:@,CommandBlock:RUINSTRIGGER /testruin Gilly/GillyMH1 ~-3 ~2 ~3 1:@,CommandBlock:RUINSTRIGGER /testruin Gilly/GillyMH1 ~3 ~2 ~-3 0:@,CommandBlock:RUINSTRIGGER /testruin Gilly/GillyMH1 ~-3 ~2 ~3 1:@
rule3=0,100,minecraft:planks-1
rule4=0,100,minecraft:fence-0
rule5=0,100,minecraft:spruce_stairs-0
rule6=2,100,minecraft:torch-1
rule7=0,100,minecraft:spruce_stairs-1
rule8=2,100,minecraft:torch-2
rule9=0,100,CommandBlock:RUINSTRIGGER /testruin Gilly/GillyMH2 ~6 ~1 ~-6 0:@,CommandBlock:RUINSTRIGGER /testruin Gilly/GillyMH2 ~-6 ~1 ~6 1:@,CommandBlock:RUINSTRIGGER /testruin Gilly/GillyMH2 ~-6 ~1 ~-6 2:@,CommandBlock:RUINSTRIGGER /testruin Gilly/GillyMH2 ~6 ~1 ~6 3:@
rule10=0,100,minecraft:stonebrick-0
rule11=0,100,minecraft:stone_brick_stairs-0
rule12=0,100,minecraft:crafting_table-0
rule13=0,100,minecraft:stone_brick_stairs-5
rule14=0,100,IInventory;minecraft:hopper;minecraft:iron_ingot#5#0#0+minecraft:gold_ingot#3#0#1-2,IInventory;minecraft:hopper;minecraft:minecraft:cooked_fish#3#1#2+minecraft:leather#5#0#3+minecraft:water_bucket#1#0#4-2,IInventory;minecraft:hopper;minecraft:cooked_beef#3#0#1+minecraft:baked_potato#8#0#4-2,IInventory;minecraft:hopper;minecraft:cooked_mutton#3#0#0+minecraft:bread#5#0#2+minecraft:cooked_porkchop#7#0#3-2,IInventory;minecraft:hopper;minecraft:apple#3#0#0+minecraft:gunpowder#5#0#1+minecraft:bone#7#0#2-2
rule15=0,100,IInventory;minecraft:furnace;minecraft:coal#4#0#1-5
rule16=0,100,minecraft:furnace-5
rule17=0,100,ChestGenHook:chests/simple_dungeon:8-5
rule18=0,100,minecraft:stone_brick_stairs-4
rule19=0,100,minecraft:stone_brick_stairs-1
rule20=0,100,minecraft:hopper-3
rule21=0,100,IInventory;minecraft:furnace;minecraft:coal#12#1#1-5
rule22=0,100,IInventory;minecraft:furnace;minecraft:planks#8#1#1-5
rule23=0,100,minecraft:hopper-0
rule24=0,100,minecraft:stone_brick_stairs-3
rule25=0,100,minecraft:stone_brick_stairs-2

layer
1,1,1,1
1,1,1,1
1,1,1,1
1,1,1,1
1,1,2,1
1,1,1,1
1,1,1,1
1,1,1,1
1,1,1,1
1,1,1,1
1,1,1,1
1,1,1,1
1,1,1,1
1,1,1,1
endlayer

layer
3,3,3,3
3,3,3,3
3,3,3,3
3,3,3,3
3,3,3,3
3,3,3,3
3,3,3,3
1,1,1,1
1,1,1,1
1,1,1,1
1,1,1,1
1,1,1,1
1,1,1,1
1,1,1,1
endlayer

layer
4,0,0,4
0,0,0,0
0,0,0,0
4,0,5,0
0,0,3,0
0,0,3,0
0,0,3,0
1,1,1,1
1,1,1,1
1,1,1,1
1,1,1,1
1,1,1,1
1,1,1,1
1,1,1,1
endlayer

layer
4,0,0,4
0,0,0,0
0,0,0,0
4,0,0,0
0,0,5,0
0,0,3,0
0,0,3,0
1,1,1,1
1,1,1,1
1,1,1,1
1,1,1,1
1,1,1,1
1,1,1,1
1,1,1,1
endlayer

layer
4,0,0,4
0,0,0,0
0,0,0,0
4,0,0,0
0,0,0,0
0,0,5,0
0,0,3,0
1,1,1,1
1,1,1,1
1,1,1,1
1,1,1,1
1,1,1,1
1,1,1,1
1,1,1,1
endlayer

layer
3,3,3,3
3,3,3,3
3,3,6,3
3,3,0,3
3,3,0,3
3,3,0,3
3,3,5,3
3,1,3,3
3,1,1,3
3,1,1,3
3,1,1,3
3,1,1,3
3,1,1,3
3,3,3,3
endlayer

layer
1,1,1,1
1,1,1,1
1,4,0,1
1,4,0,1
1,4,0,1
1,4,0,1
1,4,0,1
1,4,5,1
1,1,3,1
1,1,1,1
1,1,1,1
1,1,1,1
1,1,1,1
1,1,1,1
endlayer

layer
1,1,1,1
1,1,1,1
1,1,1,1
1,4,0,1
1,4,0,1
1,4,0,1
1,4,0,1
1,4,0,1
1,4,5,1
1,1,3,1
1,1,1,1
1,1,1,1
1,1,1,1
1,1,1,1
endlayer

layer
1,1,1,1
1,1,1,1
1,1,1,1
1,1,1,1
1,4,0,1
1,4,0,1
1,4,0,1
1,4,0,1
1,4,0,1
1,2,5,1
1,1,3,1
1,1,1,1
1,1,1,1
1,1,1,1
endlayer

layer
3,3,3,3
3,3,3,3
3,1,1,3
3,1,1,3
3,1,1,3
3,4,0,3
3,4,0,3
3,4,0,3
3,4,0,3
3,4,0,3
3,3,5,3
3,3,3,3
3,3,3,3
3,3,3,3
endlayer

layer
1,1,1,1
1,1,1,1
1,1,1,1
1,1,1,1
1,1,1,1
1,1,1,1
1,4,0,1
0,4,0,0
0,4,0,0
0,3,0,0
0,7,0,4
0,0,0,0
0,0,0,0
4,0,0,4
endlayer

layer
1,1,1,1
1,1,1,1
1,1,1,1
1,1,1,1
1,1,1,1
1,1,1,1
1,1,1,1
0,4,0,0
0,3,0,0
0,7,0,0
0,0,0,4
0,0,0,0
0,0,0,0
4,0,0,4
endlayer

layer
1,1,1,1
1,1,1,1
1,1,1,1
1,1,1,1
1,1,1,1
1,1,1,1
1,1,1,1
0,3,0,0
0,7,0,0
0,0,0,0
0,0,0,4
0,0,0,0
0,0,0,0
4,0,0,4
endlayer

layer
3,3,3,3
3,3,3,3
3,1,1,3
3,1,1,3
3,1,1,3
3,1,1,3
3,3,1,3
3,7,3,3
3,0,3,3
3,0,3,3
3,0,3,3
3,8,3,3
3,3,3,3
3,3,3,3
endlayer

layer
1,1,1,1
1,1,1,1
1,1,1,1
1,1,1,1
1,1,1,1
1,3,1,1
1,7,4,1
1,0,4,1
1,0,4,1
1,0,4,1
1,0,4,1
1,0,4,1
1,1,1,1
3,1,1,3
endlayer

layer
1,1,1,1
1,1,1,1
1,1,1,1
1,1,1,1
1,3,1,1
1,7,4,1
1,0,4,1
1,0,4,1
1,0,4,1
1,0,4,1
1,0,4,1
1,1,1,1
1,1,1,1
3,1,1,3
endlayer

layer
1,1,1,1
1,1,1,1
1,1,1,1
1,3,1,1
1,7,2,1
1,0,4,1
1,0,4,1
1,0,4,1
1,0,4,1
1,0,4,1
1,1,1,1
1,1,1,1
1,1,1,1
3,1,1,3
endlayer

layer
3,3,3,3
3,3,3,3
3,3,3,3
3,7,3,3
3,0,4,3
3,0,4,3
3,0,4,3
3,0,4,3
3,0,4,3
3,1,1,3
3,1,1,3
3,1,1,3
3,1,1,3
3,3,3,3
endlayer

layer
4,0,0,4
0,0,0,0
0,0,0,0
4,0,5,0
0,0,3,0
0,0,4,0
0,0,4,0
1,0,4,1
1,1,1,1
1,1,1,1
1,1,1,1
1,1,1,1
1,1,1,1
3,1,1,3
endlayer

layer
4,0,0,4
0,0,0,0
0,0,0,0
4,0,0,0
0,0,5,0
0,0,3,0
0,0,4,0
1,1,4,1
1,1,1,1
1,1,1,1
1,1,1,1
1,1,1,1
1,1,1,1
3,1,1,3
endlayer

layer
4,0,0,4
0,0,0,0
0,0,0,0
4,0,0,0
0,0,0,0
0,0,5,0
0,0,3,0
1,1,4,1
1,1,1,1
1,1,1,1
1,1,1,1
1,1,1,1
1,1,1,1
3,1,1,3
endlayer

layer
3,3,3,3
3,3,3,3
3,3,6,3
3,3,0,3
3,3,0,3
3,3,0,3
3,3,5,3
3,1,3,3
3,1,1,3
3,1,1,3
3,1,1,3
3,1,1,3
3,1,1,3
3,3,3,3
endlayer

layer
3,1,1,3
1,1,1,1
1,4,0,1
1,4,0,1
1,4,0,1
1,4,0,1
1,4,0,1
1,4,5,1
1,1,3,1
1,1,1,1
1,1,1,1
1,1,1,1
1,1,1,1
3,1,1,3
endlayer

layer
3,1,1,3
1,1,1,1
1,1,1,1
1,4,0,1
1,4,0,1
1,4,0,1
1,4,0,1
1,4,0,1
1,4,5,1
1,1,3,1
1,1,1,1
1,1,1,1
1,1,1,1
3,1,1,3
endlayer

layer
3,1,1,3
1,1,1,1
1,1,1,1
1,1,1,1
1,4,0,1
1,4,0,1
1,4,0,1
1,4,0,1
1,9,0,1
1,2,5,1
1,1,3,1
1,1,1,1
1,1,1,1
3,1,1,3
endlayer

layer
3,3,3,3
3,3,3,3
3,1,1,3
3,1,1,3
3,1,1,3
3,4,0,3
3,4,0,3
3,4,0,3
3,4,0,3
3,4,0,3
3,3,5,3
3,3,3,3
3,3,3,3
3,3,3,3
endlayer

layer
3,1,1,3
1,1,1,1
1,1,1,1
1,1,1,1
1,1,1,1
1,1,1,1
1,4,0,1
0,4,0,0
0,4,0,0
0,3,0,0
0,7,0,4
0,0,0,0
0,0,0,0
4,0,0,4
endlayer

layer
3,1,1,3
1,1,1,1
1,1,1,1
1,1,1,1
1,1,1,1
1,1,1,1
1,4,1,1
0,4,0,0
0,3,0,0
0,7,0,0
0,0,0,4
0,0,0,0
0,0,0,0
4,0,0,4
endlayer

layer
3,1,1,3
1,1,1,1
1,1,1,1
1,1,1,1
1,1,1,1
1,1,1,1
1,4,1,1
0,3,0,0
0,7,0,0
0,0,0,0
0,0,0,4
0,0,0,0
0,0,0,0
4,0,0,4
endlayer

layer
3,3,3,3
3,3,3,3
3,1,1,3
3,1,1,3
3,1,1,3
3,1,1,3
3,3,3,3
3,7,3,3
3,0,3,3
3,0,3,3
3,0,3,3
3,8,3,3
3,3,3,3
3,3,3,3
endlayer

layer
3,1,1,3
1,1,1,1
1,1,1,1
1,1,1,1
1,1,1,1
1,3,3,1
1,7,4,1
1,0,4,1
1,0,4,1
1,0,4,1
1,0,4,1
1,0,4,1
1,1,1,1
3,1,1,3
endlayer

layer
3,1,1,3
1,1,1,1
1,1,1,1
1,1,1,1
1,3,3,1
1,7,4,1
1,0,4,1
1,0,4,1
1,0,4,1
1,0,4,1
1,0,4,1
1,1,1,1
1,1,1,1
3,1,1,3
endlayer

layer
3,1,1,3
1,1,1,1
1,1,1,1
1,3,3,1
1,7,2,1
1,0,9,1
1,0,4,1
1,0,4,1
1,0,4,1
1,0,4,1
1,1,1,1
1,1,1,1
1,1,1,1
3,1,1,3
endlayer

layer
10,10,10,10
10,10,10,10
10,10,10,10
10,7,10,10
10,0,4,10
10,0,4,10
10,0,4,10
10,0,4,10
10,0,4,10
10,1,1,10
10,1,1,10
10,1,1,10
10,1,1,10
10,10,10,10
endlayer

layer
4,0,0,4
0,0,0,0
0,0,0,0
4,0,11,0
0,0,10,0
0,0,4,0
0,0,4,0
1,0,4,1
1,1,4,1
1,1,1,1
1,1,1,1
1,1,1,1
1,1,1,1
3,1,1,3
endlayer

layer
4,0,0,4
0,0,0,0
0,0,0,0
4,0,0,0
0,0,11,0
0,0,10,0
0,0,4,0
1,1,4,1
1,1,4,1
1,1,1,1
1,1,1,1
1,1,1,1
1,1,1,1
3,1,1,3
endlayer

layer
4,0,0,4
0,0,0,0
0,0,0,0
4,0,0,0
0,0,0,0
0,0,11,0
0,0,10,0
1,1,4,1
1,1,4,1
1,1,1,1
1,1,1,1
1,1,1,1
1,1,1,1
3,1,1,3
endlayer

layer
3,3,3,3
3,3,3,3
3,3,6,3
3,3,0,3
3,3,0,3
3,3,0,3
3,3,11,3
3,10,10,3
3,1,1,3
3,1,1,3
3,1,1,3
3,1,1,3
3,1,1,3
3,3,3,3
endlayer

layer
3,1,1,3
1,1,1,1
1,4,0,1
1,4,0,1
1,4,0,1
1,4,0,1
1,4,0,1
1,4,11,1
1,10,10,1
1,1,1,1
1,1,1,1
1,1,1,1
1,1,1,1
3,1,1,3
endlayer

layer
3,1,1,3
1,1,1,1
1,1,1,1
1,4,0,1
1,4,0,1
1,4,0,1
1,4,0,1
1,4,0,1
1,4,11,1
1,10,10,1
1,1,1,1
1,1,1,1
1,1,1,1
3,1,1,3
endlayer

layer
3,1,1,3
1,1,1,1
1,1,1,1
1,1,1,1
1,4,0,1
1,4,0,1
1,4,0,1
1,4,0,1
1,4,0,1
1,4,11,1
1,10,10,1
1,1,1,1
1,1,1,1
3,1,1,3
endlayer

layer
10,10,10,10
10,10,10,10
10,10,12,10
10,10,10,10
10,4,13,10
10,4,0,10
10,4,0,10
10,4,0,10
10,4,0,10
10,4,0,10
10,10,11,10
10,10,10,10
10,10,10,10
10,10,10,10
endlayer

layer
16,15,14,17
0,0,0,0
0,0,0,0
0,0,0,0
0,4,0,0
0,4,13,10
0,4,0,0
0,4,0,0
0,4,0,0
0,18,0,4
0,19,0,0
0,0,0,0
0,0,0,0
10,0,0,10
endlayer

layer
16,22,21,20
0,0,0,0
0,0,0,0
0,0,0,0
0,4,0,0
0,4,10,10
0,4,13,0
0,4,0,0
0,18,0,0
0,19,0,4
0,0,0,0
0,0,0,0
0,0,0,0
10,0,0,10
endlayer

layer
16,16,23,0
0,0,0,0
0,0,0,0
0,0,0,0
0,4,8,0
0,4,10,10
0,4,10,0
0,18,13,0
0,19,0,0
0,0,0,4
0,0,0,0
0,0,0,0
0,0,0,0
10,0,0,10
endlayer

layer
10,10,10,10
10,10,10,10
10,10,10,10
10,10,10,10
10,10,10,10
10,10,10,10
10,10,10,10
10,19,10,10
10,0,10,10
10,0,10,10
10,0,10,10
10,8,10,10
10,10,10,10
10,10,10,10
endlayer

layer
1,1,1,1
10,10,10,10
10,10,10,10
10,10,10,10
10,10,10,10
10,10,10,10
10,19,10,10
10,0,10,10
10,0,10,10
10,0,10,10
10,0,10,10
10,18,10,10
1,1,1,1
1,1,1,1
endlayer

layer
1,1,1,1
10,10,10,10
10,10,10,10
10,10,10,10
10,10,10,10
10,19,10,10
10,0,10,10
10,0,10,10
10,0,10,10
10,0,10,10
10,18,10,10
1,1,1,1
1,1,1,1
1,1,1,1
endlayer

layer
1,1,1,1
1,1,1,1
10,10,10,10
10,10,10,10
10,19,10,10
10,0,10,10
10,0,10,10
10,0,10,10
10,0,10,10
10,18,10,10
1,1,1,1
1,1,1,1
1,1,1,1
1,1,1,1
endlayer

layer
1,1,1,1
1,1,1,1
10,10,10,10
19,19,19,10
25,0,24,10
11,0,11,10
10,0,10,10
10,0,10,10
10,18,10,10
1,1,1,1
1,1,1,1
1,1,1,1
1,1,1,1
1,1,1,1
endlayer

layer
1,1,1,1
1,1,1,1
1,1,1,1
1,1,1,1
1,1,1,1
4,0,4,1
4,0,4,1
4,0,4,1
4,4,4,1
1,1,1,1
1,1,1,1
1,1,1,1
1,1,1,1
1,1,1,1
endlayer

