
# Created by Ruins mod version 16.7 Ingame Parser
# authoring Player: lafuller

weight=1
embed_into_distance=51
acceptable_target_blocks=
unacceptable_target_blocks=flowing_water,water,flowing_lava,lava,ice,bedrock,netherrack,nether_brick,nether_brick_fence,soul_sand,quartz_ore,gravel,end_stone,obsidian,iron_bars,cloud,flesh,ash_block,slime_grass,slime_congealed,slime_dirt
dimensions=53,3,13
allowable_overhang=0
max_leveling=2
leveling_buffer=-1
preserve_water=0
preserve_lava=0

rule1=0,100,preserveBlock
rule2=0,100,CommandBlock:RUINSTRIGGER /testruin Gilly/GillyNarrowCorridor ~3 ~2 ~3 0:@,CommandBlock:RUINSTRIGGER /testruin Gilly/GillyNarrowCorridor ~3 ~2 ~-3 1:@,CommandBlock:RUINSTRIGGER /testruin Gilly/GillyNarrowCorridor ~-3 ~2 ~-3 2:@,CommandBlock:RUINSTRIGGER /testruin Gilly/GillyNarrowCorridor ~-3 ~2 ~3 3:@,CommandBlock:RUINSTRIGGER /testruin Gilly/GillyNarrowHallway ~3 ~2 ~3 0:@,CommandBlock:RUINSTRIGGER /testruin Gilly/GillyNarrowHallway ~3 ~2 ~-3 1:@,CommandBlock:RUINSTRIGGER /testruin Gilly/GillyNarrowHallway ~-3 ~2 ~-3 2:@,CommandBlock:RUINSTRIGGER /testruin Gilly/GillyNarrowHallway ~-3 ~2 ~3 3:@
rule3=0,100,minecraft:planks-1
rule4=0,100,minecraft:dark_oak_fence-0
rule5=0,100,minecraft:spruce_stairs-2
rule6=0,100,minecraft:spruce_stairs-7
rule7=0,100,minecraft:spruce_stairs-0
rule8=0,100,minecraft:spruce_stairs-6
rule9=0,100,minecraft:spruce_stairs-3
rule10=0,100,minecraft:spruce_stairs-1
rule11=0,100,CommandBlock:RUINSTRIGGER /testruin Gilly/GillyMineshackFloor ~8 ~-10 ~8 0:@,CommandBlock:RUINSTRIGGER /testruin Gilly/GillyMineshackFloor ~8 ~-10 ~-8 1:@,CommandBlock:RUINSTRIGGER /testruin Gilly/GillyMineshackFloor ~-8 ~-10 ~-8 2:@,CommandBlock:RUINSTRIGGER /testruin Gilly/GillyMineshackFloor ~-8 ~-10 ~8 3:@
rule12=0,100,stonebrick-0,stonebrick-0,stonebrick-0,stonebrick-0,stonebrick-1,stonebrick-2,stonebrick-2,stone-5,stone-6,cobblestone,gravel
rule13=0,100,stonebrick-0,stonebrick-2,stonebrick-2,stonebrick-1,stonebrick-1,cobblestone
rule14=0,100,stonebrick-0,stonebrick-1,stonebrick-2,stonebrick-2,stone-5,stone-5,stone-6,stone-6
rule15=0,100,stonebrick-0,stonebrick-1,stonebrick-2
rule16=0,100,minecraft:stone_brick_stairs-0
rule17=0,100,minecraft:cobblestone_wall-0
rule18=0,100,minecraft:iron_bars-0

layer
1,1,1,1,1,1,1,1,1,1,1,1,1
1,1,1,1,1,1,2,1,1,1,1,1,1
1,1,1,1,1,1,1,1,1,1,1,1,1
endlayer

layer
1,3,3,3,3,3,3,3,3,3,3,3,3
1,3,3,3,3,3,3,3,3,3,3,3,3
1,3,3,3,3,3,3,3,3,3,3,3,3
endlayer

layer
1,0,0,0,0,0,6,5,0,0,0,4,0
1,4,4,4,4,4,4,4,0,0,0,0,0
1,0,0,0,0,0,0,0,0,0,0,4,0
endlayer

layer
1,0,0,0,0,6,5,0,0,0,0,4,0
1,4,4,4,4,4,4,4,0,0,0,0,0
1,0,0,0,0,0,0,0,0,0,0,4,0
endlayer

layer
1,0,0,0,6,5,0,0,0,0,0,4,0
1,4,4,4,4,4,4,4,0,0,0,0,0
1,0,0,0,0,0,0,0,0,0,0,4,0
endlayer

layer
1,0,0,6,5,0,0,0,0,0,0,4,0
1,4,4,4,4,2,4,4,4,0,0,4,0
1,0,0,0,0,0,0,0,0,0,0,4,0
endlayer

layer
3,3,3,5,0,0,0,0,0,0,1,1,1
3,3,3,7,7,3,4,3,3,3,1,1,1
3,3,3,3,3,3,3,3,3,3,1,1,1
endlayer

layer
4,0,0,0,0,0,0,0,0,0,1,1,1
0,0,0,0,4,4,4,4,4,4,1,1,1
4,0,0,0,9,8,0,0,0,0,1,1,1
endlayer

layer
4,0,0,0,0,0,0,0,0,0,1,1,1
0,0,0,0,4,4,4,4,4,4,1,1,1
4,0,0,0,0,9,8,0,0,0,1,1,1
endlayer

layer
4,0,0,0,0,0,0,0,0,0,1,1,1
0,0,0,0,4,4,4,4,4,4,1,1,1
4,0,0,0,0,0,9,8,0,0,1,1,1
endlayer

layer
4,0,0,0,0,0,0,0,0,0,1,1,1
4,0,0,4,4,4,2,4,4,4,4,1,1
4,0,0,0,0,0,0,9,8,0,1,1,1
endlayer

layer
1,1,3,3,3,3,3,3,3,3,3,3,3
1,1,3,3,3,3,4,10,10,3,3,3,3
1,1,0,0,0,0,0,0,9,3,3,3,3
endlayer

layer
1,1,0,0,0,0,6,5,0,0,0,4,0
1,1,4,4,4,4,4,4,0,0,0,0,0
1,1,0,0,0,0,0,0,0,0,0,4,0
endlayer

layer
1,1,0,0,0,6,5,0,0,0,0,4,0
1,1,4,4,4,4,4,4,0,0,0,0,0
1,1,0,0,0,0,0,0,0,0,0,4,0
endlayer

layer
1,1,0,0,6,5,0,0,0,0,0,4,0
1,1,4,4,4,4,4,4,0,0,0,0,0
1,1,0,0,0,0,0,0,0,0,0,4,0
endlayer

layer
1,1,0,6,5,0,0,0,0,0,0,4,0
1,4,4,4,4,2,4,4,4,0,0,4,0
1,1,0,0,0,0,0,0,0,0,0,4,0
endlayer

layer
3,3,3,5,0,0,0,0,0,0,1,1,1
3,3,3,7,7,3,4,3,3,3,1,1,1
3,3,3,3,3,3,3,3,3,3,1,1,1
endlayer

layer
4,0,0,0,0,0,0,0,0,0,1,1,1
0,0,0,0,4,4,4,4,4,4,1,1,1
4,0,0,0,9,8,0,0,0,0,1,1,1
endlayer

layer
4,0,0,0,0,0,0,0,0,0,1,1,1
0,0,0,0,4,4,4,4,4,4,1,1,1
4,0,0,0,0,9,8,0,0,0,1,1,1
endlayer

layer
4,0,0,0,0,0,0,0,0,0,1,1,1
0,0,0,0,4,4,4,4,4,4,1,1,1
4,0,0,0,0,0,9,8,0,0,1,1,1
endlayer

layer
4,0,0,0,0,0,0,0,0,0,1,1,1
4,0,0,4,4,4,2,4,4,4,4,1,1
4,0,0,0,0,0,0,9,8,0,1,1,1
endlayer

layer
1,1,3,3,3,3,3,3,3,3,3,3,3
1,1,3,3,3,3,4,10,10,3,3,3,3
1,1,0,0,0,0,0,0,9,3,3,3,3
endlayer

layer
1,1,0,0,0,0,6,5,0,0,0,4,0
1,1,4,4,4,4,4,4,0,0,0,0,0
1,1,0,0,0,0,0,0,0,0,0,4,0
endlayer

layer
1,1,0,0,0,6,5,0,0,0,0,4,0
1,1,4,4,4,4,4,4,0,0,0,0,0
1,1,0,0,0,0,0,0,0,0,0,4,0
endlayer

layer
1,1,0,0,6,5,0,0,0,0,0,4,0
1,1,4,4,4,4,4,4,0,0,0,0,0
1,1,0,0,0,0,0,0,0,0,0,4,0
endlayer

layer
1,1,0,6,5,0,0,0,0,0,0,4,0
1,4,4,4,4,2,4,4,4,0,0,4,0
1,1,0,0,0,0,0,0,0,0,0,4,0
endlayer

layer
3,3,3,5,0,0,0,0,0,0,1,1,1
3,3,3,7,7,3,4,3,3,3,1,1,1
3,3,3,3,3,3,3,3,3,3,1,1,1
endlayer

layer
4,0,0,0,0,0,0,0,0,0,1,1,1
0,0,0,0,4,4,4,4,4,4,1,1,1
4,0,0,0,9,8,0,0,0,0,1,1,1
endlayer

layer
4,0,0,0,0,0,0,0,0,0,1,1,1
0,0,0,0,4,4,4,4,4,4,1,1,1
4,0,0,0,0,9,8,0,0,0,1,1,1
endlayer

layer
4,0,0,0,0,0,0,0,0,0,1,1,1
0,0,0,0,4,4,4,4,4,4,1,1,1
4,0,0,0,0,0,9,8,0,0,1,1,1
endlayer

layer
4,0,0,0,0,0,0,0,0,0,1,1,1
4,0,0,4,4,4,2,4,4,4,4,1,1
4,0,0,0,0,0,0,9,8,0,1,1,1
endlayer

layer
1,1,3,3,3,3,3,3,3,3,3,3,3
1,1,3,3,3,3,4,10,10,3,3,3,3
1,1,0,0,0,0,0,0,9,3,3,3,3
endlayer

layer
1,1,0,0,0,0,6,5,0,0,0,4,0
1,1,4,4,4,4,4,4,0,0,0,0,0
1,1,0,0,0,0,0,0,0,0,0,4,0
endlayer

layer
1,1,0,0,0,6,5,0,0,0,0,4,0
1,1,4,4,4,4,4,4,0,0,0,0,0
1,1,0,0,0,0,0,0,0,0,0,4,0
endlayer

layer
1,1,0,0,6,5,0,0,0,0,0,4,0
1,1,4,4,4,4,4,4,0,0,0,0,0
1,1,0,0,0,0,0,0,0,0,0,4,0
endlayer

layer
1,1,0,6,5,0,0,0,0,0,0,4,0
1,4,4,4,4,2,4,4,4,0,0,4,0
1,1,0,0,0,0,0,0,0,0,0,4,0
endlayer

layer
3,3,3,5,0,0,0,0,0,6,3,3,1
3,3,3,7,7,3,4,3,3,3,3,3,1
3,3,3,3,3,3,3,3,3,3,3,3,1
endlayer

layer
4,0,0,0,0,0,0,0,0,0,0,4,1
0,0,0,0,4,4,4,4,4,4,0,0,1
4,0,0,0,9,8,0,0,0,0,0,4,1
endlayer

layer
4,0,0,0,0,0,0,0,0,0,0,4,1
0,0,0,0,4,4,4,4,4,4,0,0,1
4,0,0,0,0,9,8,0,0,0,0,4,1
endlayer

layer
4,0,0,0,0,0,0,0,0,0,0,4,1
0,0,0,0,4,4,4,4,4,4,0,0,1
4,0,0,0,0,0,9,8,0,0,0,4,1
endlayer

layer
4,4,0,0,0,0,0,0,0,0,0,4,1
4,4,4,4,4,4,4,4,4,4,4,4,1
4,4,0,0,0,0,0,9,8,0,0,4,1
endlayer

layer
3,3,3,3,3,3,3,3,3,3,3,3,1
3,3,3,3,3,3,4,10,10,3,3,3,11
3,3,0,0,0,0,0,0,9,3,3,3,1
endlayer

layer
1,3,0,0,0,0,6,5,0,0,0,3,1
1,3,4,4,4,4,4,4,0,0,4,3,1
1,3,0,0,0,0,0,0,0,0,0,3,1
endlayer

layer
1,3,0,0,0,6,5,0,0,0,0,3,1
1,3,4,4,4,4,4,4,0,0,4,3,1
1,3,0,0,0,0,0,0,0,0,0,3,1
endlayer

layer
1,3,0,0,6,5,0,0,0,0,0,3,1
1,3,4,4,4,4,4,4,0,0,4,3,1
1,3,0,0,0,0,0,0,0,0,0,3,1
endlayer

layer
1,3,0,6,5,0,0,0,0,0,0,3,1
1,3,4,4,4,4,4,4,4,4,4,3,1
1,3,0,0,0,0,0,0,0,0,0,3,1
endlayer

layer
1,12,13,5,0,0,0,0,0,14,13,12,1
11,12,13,16,16,15,18,15,15,14,13,12,1
1,12,13,14,15,15,15,15,15,14,13,12,1
endlayer

layer
1,12,0,0,0,0,0,0,0,0,0,12,1
1,17,0,0,4,4,4,4,4,0,0,17,1
1,12,0,0,9,8,0,0,0,0,0,12,1
endlayer

layer
1,12,0,0,0,0,0,0,0,0,0,12,1
1,17,0,0,4,4,4,4,4,0,0,17,1
1,12,0,0,0,9,8,0,0,0,0,12,1
endlayer

layer
1,12,0,0,0,0,0,0,0,0,0,12,1
1,17,0,0,4,4,4,4,4,0,0,17,1
1,12,0,0,0,0,9,8,0,0,0,12,1
endlayer

layer
1,12,0,0,0,0,0,0,0,0,0,12,1
1,17,0,0,4,4,4,4,4,0,0,17,1
1,12,0,0,0,0,0,9,8,0,0,12,1
endlayer

layer
1,12,3,3,3,3,3,3,3,3,3,12,1
1,12,3,3,3,3,18,10,10,3,3,12,1
1,12,3,8,0,0,0,0,9,3,3,12,1
endlayer

layer
1,1,0,0,0,0,0,0,0,0,0,1,1
1,1,0,4,4,4,0,0,0,0,0,1,1
1,1,0,4,0,0,0,0,0,0,0,1,1
endlayer

