
# Created by Ruins mod version 16.7 Ingame Parser
# authoring Player: lafuller

weight=1
embed_into_distance=13
acceptable_target_blocks=flowing_water,water
unacceptable_target_blocks=
biomesToSpawnIn=river,swampland,lush swamp,marsh
dimensions=24,11,11
allowable_overhang=0
max_leveling=4
leveling_buffer=-1
preserve_water=0
preserve_lava=0

rule1=0,100,preserveBlock
rule2=0,100,minecraft:log2-1
rule3=0,100,minecraft:planks-1
rule4=0,100,minecraft:log2-9
rule5=0,100,minecraft:spruce_fence-0
rule6=0,100,minecraft:ladder-4
rule7=0,100,minecraft:log-4
rule8=0,100,minecraft:log-8
rule9=0,100,minecraft:fence-0
rule10=0,100,minecraft:wooden_slab-9
rule11=0,100,minecraft:log-0
rule12=0,100,minecraft:spruce_stairs-0
rule13=0,100,minecraft:spruce_stairs-7
rule14=0,100,minecraft:spruce_stairs-6
rule15=0,100,minecraft:oak_stairs-0
rule16=0,100,minecraft:planks-0
rule17=0,100,minecraft:oak_stairs-4
rule18=0,100,minecraft:oak_stairs-6
rule19=0,100,minecraft:bookshelf-0
rule20=0,100,minecraft:crafting_table-0
rule21=0,100,minecraft:oak_stairs-7
rule22=0,100,minecraft:carpet-7
rule23=0,100,minecraft:carpet-8
rule24=0,100,minecraft:jungle_door-0
rule25=0,100,minecraft:oak_stairs-2
rule26=0,100,minecraft:oak_stairs-3

rule27=0,100,IInventory;dropper;double_plant#1#1#2+fishing_rod#{ench:[{lvl:3s,id:62s},{lvl:3s,id:61s}],RepairCost:1}#0#4-1,IInventory;dropper;leather#2#0#0+feather#3#0#7-1,IInventory;dropper;glowstone_dust#4#0#6-1,IInventory;dropper;gunpowder#7#0#5-1,IInventory;dropper;clay_ball#3#0#1-1,IInventory;dropper;fish#3#0#6+bucket#1#0#8-1

rule28=0,100,IInventory;hopper;book#3#0#0+fish#1#3#1-2,IInventory;hopper;rabbit_stew#1#0#0-2,IInventory;hopper;apple#3#0#0-2,IInventory;hopper;coal#5#0#0+fish#2#1#1-2,IInventory;hopper;cooked_rabbit#2#0#0-2,IInventory;hopper;baked_potato#4#0#0-2

rule29=0,100,minecraft:stone-3
rule30=0,100,minecraft:cauldron-0
rule31=0,100,minecraft:oak_stairs-5
rule32=0,100,minecraft:oak_stairs-1
rule33=0,100,minecraft:jungle_door-8
rule34=0,100,minecraft:jungle_door-9
rule35=0,100,minecraft:fence_gate-0
rule36=0,100,minecraft:fence_gate-2
rule37=0,100,IInventory;furnace;coal#4#0#1-4
rule38=0,100,minecraft:fence_gate-3
rule39=0,100,minecraft:spruce_stairs-4
rule40=0,100,minecraft:spruce_fence_gate-3
rule41=0,100,minecraft:cobblestone_wall-0
rule42=0,100,minecraft:spruce_stairs-3
rule43=0,100,minecraft:spruce_stairs-1
rule44=0,100,minecraft:spruce_stairs-5
rule45=0,100,minecraft:wooden_slab-1
rule46=0,100,minecraft:dark_oak_stairs-4
rule47=0,100,minecraft:dark_oak_stairs-0
rule48=0,100,minecraft:dark_oak_stairs-3
rule49=0,100,minecraft:spruce_stairs-2
rule50=0,100,minecraft:dark_oak_stairs-7
rule51=0,100,minecraft:dark_oak_stairs-6
rule52=0,100,minecraft:dark_oak_stairs-1
rule53=0,100,minecraft:wooden_slab-5
rule54=0,100,minecraft:dark_oak_stairs-5
rule55=0,100,minecraft:dark_oak_stairs-2
rule56=0,100,minecraft:planks-5

layer
1,1,1,1,1,1,1,1,1,1,1
1,1,1,1,1,1,1,1,1,1,1
1,1,1,1,2,1,1,1,1,1,1
1,1,1,1,1,1,1,1,1,1,1
1,1,1,1,2,1,2,1,1,1,1
1,1,1,1,1,1,1,1,1,1,1
1,1,2,1,1,1,1,1,2,1,1
1,1,1,1,1,1,1,1,1,1,1
1,1,1,1,1,1,2,1,1,1,1
1,1,1,1,1,1,1,1,1,1,1
1,1,1,1,1,1,1,1,1,1,1
endlayer

layer
1,1,1,1,1,1,1,1,1,1,1
1,1,1,1,1,1,1,1,1,1,1
1,1,1,1,2,1,1,1,1,1,1
1,1,1,1,1,1,1,1,1,1,1
1,1,1,1,2,1,2,1,1,1,1
1,1,1,1,1,1,1,1,1,1,1
1,1,2,1,1,1,1,1,2,1,1
1,1,1,1,1,1,1,1,1,1,1
1,1,1,1,1,1,2,1,1,1,1
1,1,1,1,1,1,1,1,1,1,1
1,1,1,1,1,1,1,1,1,1,1
endlayer

layer
1,1,1,1,1,1,1,1,1,1,1
1,1,1,1,1,1,1,1,1,1,1
1,1,1,1,2,1,1,1,1,1,1
1,1,1,1,1,1,1,1,1,1,1
1,1,1,1,2,1,2,1,1,1,1
1,1,1,1,1,1,1,1,1,1,1
1,1,2,1,1,1,1,1,2,1,1
1,1,1,1,1,1,1,1,1,1,1
1,1,1,1,1,1,2,1,1,1,1
1,1,1,1,1,1,1,1,1,1,1
1,1,1,1,1,1,1,1,1,1,1
endlayer

layer
1,1,1,1,1,1,1,1,1,1,1
1,1,1,1,1,1,1,1,1,1,1
1,1,1,1,2,1,1,1,1,1,1
1,1,1,1,1,1,1,1,1,1,1
1,1,1,1,2,1,2,1,1,1,1
1,1,1,1,1,1,1,1,1,1,1
1,1,2,1,1,1,1,1,2,1,1
1,1,1,1,1,1,1,1,1,1,1
1,1,1,1,1,1,2,1,1,1,1
1,1,1,1,1,1,1,1,1,1,1
1,1,1,1,1,1,1,1,1,1,1
endlayer

layer
1,1,1,1,1,1,1,1,1,1,1
1,1,1,1,1,1,1,1,1,1,1
1,1,1,1,2,1,1,1,1,1,1
1,1,1,1,1,1,1,1,1,1,1
1,1,1,1,2,1,2,1,1,1,1
1,1,1,1,1,1,1,1,1,1,1
1,1,2,1,1,1,1,1,2,1,1
1,1,1,1,1,1,1,1,1,1,1
1,1,1,1,1,1,2,1,1,1,1
1,1,1,1,1,1,1,1,1,1,1
1,1,1,1,1,1,1,1,1,1,1
endlayer

layer
1,1,1,1,1,1,1,1,1,1,1
1,1,1,1,1,1,1,1,1,1,1
1,1,1,1,2,1,1,1,1,1,1
1,1,1,1,1,1,1,1,1,1,1
1,1,1,1,2,1,2,1,1,1,1
1,1,1,1,1,1,1,1,1,1,1
1,1,2,1,1,1,1,1,2,1,1
1,1,1,1,1,1,1,1,1,1,1
1,1,1,1,1,1,2,1,1,1,1
1,1,1,1,1,1,1,1,1,1,1
1,1,1,1,1,1,1,1,1,1,1
endlayer

layer
1,1,1,1,1,1,1,1,1,1,1
1,1,1,1,1,1,1,1,1,1,1
1,1,1,1,2,1,1,1,1,1,1
1,1,1,1,1,1,1,1,1,1,1
1,1,1,1,2,1,2,1,1,1,1
1,1,1,1,1,1,1,1,1,1,1
1,1,2,1,1,1,1,1,2,1,1
1,1,1,1,1,1,1,1,1,1,1
1,1,1,1,1,1,2,1,1,1,1
1,1,1,1,1,1,1,1,1,1,1
1,1,1,1,1,1,1,1,1,1,1
endlayer

layer
1,1,1,1,1,1,1,1,1,1,1
1,1,1,1,1,1,1,1,1,1,1
1,1,1,1,2,1,1,1,1,1,1
1,1,1,1,1,1,1,1,1,1,1
1,1,1,1,2,1,2,1,1,1,1
1,1,1,1,1,1,1,1,1,1,1
1,1,2,1,1,1,1,1,2,1,1
1,1,1,1,1,1,1,1,1,1,1
1,1,1,1,1,1,2,1,1,1,1
1,1,1,1,1,1,1,1,1,1,1
1,1,1,1,1,1,1,1,1,1,1
endlayer

layer
1,1,1,1,1,1,1,1,1,1,1
1,1,1,1,1,1,1,1,1,1,1
1,1,1,1,2,1,1,1,1,1,1
1,1,1,1,1,1,1,1,1,1,1
1,1,1,1,2,1,2,1,1,1,1
1,1,1,1,1,1,1,1,1,1,1
1,1,2,1,1,1,1,1,2,1,1
1,1,1,1,1,1,1,1,1,1,1
1,1,1,1,1,1,2,1,1,1,1
1,1,1,1,1,1,1,1,1,1,1
1,1,1,1,1,1,1,1,1,1,1
endlayer

layer
1,1,1,1,1,1,1,1,1,1,1
1,1,1,1,1,1,1,1,1,1,1
1,1,1,1,2,1,1,1,1,1,1
1,1,1,1,1,1,1,1,1,1,1
1,1,1,1,2,1,2,1,1,1,1
1,1,1,1,1,1,1,1,1,1,1
1,1,2,1,1,1,1,1,2,1,1
1,1,1,1,1,1,1,1,1,1,1
1,1,1,1,1,1,2,1,1,1,1
1,1,1,1,1,1,1,1,1,1,1
1,1,1,1,1,1,1,1,1,1,1
endlayer

layer
1,1,1,1,1,1,1,1,1,1,1
1,1,1,1,1,1,1,1,1,1,1
1,1,1,1,2,1,1,1,1,1,1
1,1,1,1,1,1,1,1,1,1,1
1,1,1,1,2,1,2,1,1,1,1
1,1,1,1,1,1,1,1,1,1,1
1,1,2,1,1,1,1,1,2,1,1
1,1,1,1,1,1,1,1,1,1,1
1,1,1,1,1,1,2,1,1,1,1
1,1,1,1,1,1,1,1,1,1,1
1,1,1,1,1,1,1,1,1,1,1
endlayer

layer
1,1,1,1,1,1,1,1,1,1,1
1,1,1,1,1,1,1,1,1,1,1
1,1,1,1,2,1,1,1,1,1,1
1,1,1,1,1,1,1,1,1,1,1
1,1,1,1,2,1,2,1,1,1,1
1,1,1,1,1,1,1,1,1,1,1
1,1,2,1,1,1,1,1,2,1,1
1,1,1,1,1,1,1,1,1,1,1
1,1,1,1,1,1,2,1,1,1,1
1,1,1,1,1,1,1,1,1,1,1
1,1,1,1,1,1,1,1,1,1,1
endlayer

layer
1,1,1,1,1,1,1,1,1,1,1
1,1,1,1,1,1,1,1,1,1,1
1,1,1,1,2,3,3,3,3,1,1
1,1,4,4,4,4,4,4,4,1,1
1,1,1,1,2,1,2,1,1,1,1
1,1,4,4,4,4,4,4,4,1,1
1,1,2,1,1,1,1,1,2,1,1
1,1,4,4,4,4,4,4,4,1,1
1,1,1,1,1,1,2,1,1,1,1
1,1,1,1,1,1,1,1,1,1,1
1,1,1,1,1,1,1,1,1,1,1
endlayer

layer
1,1,1,1,1,1,1,1,1,1,1
1,1,1,5,1,5,1,1,1,1,1
1,1,1,7,2,7,1,6,6,1,1
1,1,1,7,1,7,1,7,3,5,1
1,1,1,7,2,7,2,7,1,1,1
1,1,1,7,1,7,1,7,1,1,1
1,1,2,7,1,7,1,7,2,1,1
1,1,1,7,1,7,1,7,1,1,1
1,1,1,7,1,7,2,7,1,1,1
1,1,1,5,1,5,1,5,1,1,1
1,1,1,1,1,1,1,1,1,1,1
endlayer

layer
1,1,1,1,1,1,1,1,1,1,1
1,1,1,9,1,9,1,1,1,1,1
5,8,8,8,8,8,8,6,6,1,1
1,1,1,1,1,1,1,3,3,3,1
5,8,8,8,8,8,8,8,8,8,5
1,1,1,1,1,1,1,1,1,1,1
5,8,8,8,8,8,8,8,8,8,5
1,1,1,1,1,1,1,1,1,1,1
5,8,8,8,8,8,8,8,8,8,5
1,1,1,9,1,9,1,9,1,1,1
1,1,1,1,1,1,1,1,1,1,1
endlayer

layer
1,1,5,1,5,1,5,1,1,1,1
1,9,7,10,7,10,7,1,1,1,1
9,11,7,10,7,10,7,1,1,1,1
1,13,7,10,7,10,7,12,12,5,1
9,11,7,10,7,10,7,10,7,11,9
1,13,7,10,7,10,7,10,7,14,1
9,11,7,10,7,10,7,10,7,11,9
1,13,7,10,7,10,7,10,7,14,1
9,11,7,10,7,10,7,10,7,11,9
1,1,7,10,7,10,7,10,7,1,1
1,1,5,1,5,1,5,1,5,1,1
endlayer

layer
1,1,0,0,0,0,0,1,1,1,1
1,9,17,16,16,15,9,0,1,1,1
0,21,11,20,19,11,18,0,0,1,1
0,16,23,22,22,0,16,0,0,9,1
0,16,23,22,22,0,11,24,24,11,0
0,25,0,0,0,0,0,0,0,16,0
0,25,0,0,0,0,0,0,0,26,0
0,16,0,0,0,0,0,0,0,16,0
0,21,11,30,29,28,27,20,11,18,0
1,0,32,16,16,16,16,16,31,0,1
1,1,0,0,0,0,0,0,0,1,1
endlayer

layer
1,0,0,0,0,0,0,0,1,1,1
0,9,16,16,16,16,9,0,0,1,1
0,16,11,0,19,11,25,0,0,0,1
0,16,0,0,0,0,16,0,0,9,0
0,16,0,0,0,0,11,34,33,11,0
0,35,0,0,0,0,0,0,0,16,0
0,35,0,0,0,0,0,0,0,36,0
0,16,0,0,0,0,0,0,0,16,0
0,16,11,37,0,0,0,0,11,16,0
0,5,21,16,16,38,38,16,16,0,0
1,0,0,0,0,0,0,0,0,0,1
endlayer

layer
0,0,39,0,0,0,0,0,0,1,1
0,5,16,16,16,15,5,0,0,0,1
5,16,11,0,0,11,16,0,0,0,0
0,16,0,0,0,0,16,0,0,5,0
0,16,0,0,0,0,11,40,40,11,0
0,18,0,0,0,0,0,0,0,16,0
0,18,0,0,0,0,0,0,0,21,0
0,16,0,0,0,0,0,0,0,16,0
0,16,11,41,0,0,0,0,11,16,0
0,5,16,16,16,17,17,16,32,5,0
0,0,0,0,0,0,0,0,0,0,0
endlayer

layer
0,39,39,10,0,39,0,0,0,0,1
5,42,3,16,16,25,5,0,0,0,0
5,3,11,0,0,11,17,10,0,0,0
13,13,0,0,0,0,16,39,39,5,0
5,16,0,0,0,0,11,16,16,11,0
0,16,0,0,0,0,0,0,0,16,5
0,16,0,0,0,0,0,0,0,16,5
0,16,0,0,0,0,0,0,0,16,39
0,43,11,41,0,0,0,0,11,16,14
0,44,42,16,16,16,16,16,3,14,0
0,0,0,5,13,5,5,14,44,0,0
endlayer

layer
0,47,46,46,46,46,45,45,0,0,0
48,3,3,43,43,13,3,45,45,0,0
50,3,3,0,0,3,3,49,12,45,0
42,3,0,0,0,0,3,3,14,14,0
13,3,0,0,0,0,3,44,42,11,10
44,3,0,0,0,0,0,0,13,14,14
13,3,0,0,0,0,0,0,13,3,51
10,3,0,0,0,0,0,0,13,3,46
0,48,3,41,0,0,0,0,14,44,52
0,53,52,44,3,3,3,3,44,44,49
0,0,0,50,44,44,52,54,43,43,0
endlayer

layer
0,0,47,0,0,47,0,0,0,0,0
0,48,56,5,5,3,55,0,0,0,0
0,47,56,39,39,44,47,0,0,0,0
48,56,14,44,44,44,56,47,47,53,0
47,56,14,0,0,0,3,3,3,55,0
48,42,14,0,0,0,0,13,14,51,0
48,56,14,0,0,0,0,13,14,56,55
0,48,14,0,0,0,0,13,14,14,55
0,48,3,41,39,39,39,39,3,56,55
0,0,52,56,56,43,56,56,52,52,0
0,0,0,52,55,52,52,55,0,0,0
endlayer

layer
0,0,0,0,0,0,0,0,0,0,0
0,0,0,53,47,53,0,0,0,0,0
0,0,53,56,56,55,0,0,0,0,0
0,0,48,56,56,56,53,0,0,0,0
0,0,48,56,56,56,56,47,53,0,0
0,53,56,56,56,56,56,56,53,0,0
0,48,56,56,56,56,56,56,56,55,0
0,52,56,56,56,56,56,56,56,53,0
0,0,53,56,56,56,56,52,53,0,0
0,0,0,53,53,52,53,0,0,0,0
0,0,0,0,0,0,0,0,0,0,0
endlayer

layer
0,0,0,0,0,0,0,0,0,0,0
0,0,0,0,0,0,0,0,0,0,0
0,0,0,0,0,0,0,0,0,0,0
0,0,0,0,0,0,0,0,0,0,0
0,0,0,0,0,0,0,0,0,0,0
0,0,0,0,0,0,0,0,0,0,0
0,0,0,0,0,0,0,0,0,0,0
0,0,0,0,0,0,0,0,0,0,0
0,0,0,41,0,0,0,0,0,0,0
0,0,0,0,0,0,0,0,0,0,0
0,0,0,0,0,0,0,0,0,0,0
endlayer

