
# Created by Ruins mod version 16.7 Ingame Parser
# authoring Player: lafuller

weight=1
embed_into_distance=16
acceptable_target_blocks=
unacceptable_target_blocks=flowing_water,water,flowing_lava,lava,ice,bedrock,netherrack,nether_brick,nether_brick_fence,soul_sand,quartz_ore,end_stone,obsidian,iron_bars,cloud,flesh,ash_block,slime_grass,slime_congealed,slime_dirt
dimensions=16,29,29
allowable_overhang=0
max_leveling=16
leveling_buffer=-1
preserve_water=0
preserve_lava=0

rule1=0,100,preserveBlock
rule2=0,100,minecraft:sandstone-0
rule3=0,100,prismarine-0,prismarine-0,prismarine-1
rule4=0,100,minecraft:stone-3
rule5=0,100,minecraft:water-0
rule6=0,100,minecraft:sandstone_stairs-3
rule7=0,100,minecraft:stone_slab-1
rule8=0,100,minecraft:sandstone_stairs-2
rule9=0,100,minecraft:sandstone_stairs-1
rule10=0,100,minecraft:sandstone-2
rule11=1,100,minecraft:hay_block-4,air,air
rule12=1,100,minecraft:hay_block-8,air,air
rule13=1,100,minecraft:hay_block-0,air,air
rule14=0,100,minecraft:sandstone_stairs-0
rule15=0,100,minecraft:double_stone_slab-9
rule16=0,100,ChestGenHook:chests/desert_pyramid:5-5
rule17=0,100,minecraft:trapdoor-3
rule18=0,100,ChestGenHook:chests/desert_pyramid:5-3
rule19=0,100,ChestGenHook:chests/desert_pyramid:5-2
rule20=0,100,minecraft:trapdoor-2
rule21=0,100,ChestGenHook:chests/desert_pyramid:5-4
rule22=0,100,minecraft:sandstone_stairs-5
rule23=0,100,minecraft:sandstone_stairs-7
rule24=0,100,minecraft:sandstone_stairs-6
rule25=0,100,minecraft:sandstone_stairs-4
rule26=0,100,minecraft:sandstone-1
rule27=0,100,minecraft:stone_slab-9
rule28=0,100,minecraft:stone-5

layer
1,1,1,1,1,1,1,1,1,1,1,1,1,1,1,1,1,1,1,1,1,1,1,1,1,1,1,1,1
1,1,1,1,1,1,1,1,1,1,1,1,1,1,1,1,1,1,1,1,1,1,1,1,1,1,1,1,1
1,1,1,1,1,1,1,1,1,1,1,1,1,1,1,1,1,1,1,1,1,1,1,1,1,1,1,1,1
1,1,1,1,1,1,1,1,1,1,1,1,1,1,1,1,1,1,1,1,1,1,1,1,1,1,1,1,1
1,1,1,1,1,1,1,1,1,1,1,1,1,1,1,1,1,1,1,1,1,1,1,1,1,1,1,1,1
1,1,1,1,1,1,1,1,1,1,1,1,1,1,1,1,1,1,1,1,1,1,1,1,1,1,1,1,1
1,1,1,1,1,1,1,1,1,1,1,1,1,1,1,1,1,1,1,1,1,1,1,1,1,1,1,1,1
1,1,1,1,1,1,1,1,1,1,1,1,1,1,1,1,1,1,1,1,1,1,1,1,1,1,1,1,1
1,1,1,1,1,1,1,1,1,1,1,1,1,1,1,1,1,1,1,1,1,1,1,1,1,1,1,1,1
1,1,1,1,1,1,1,1,1,1,1,1,1,1,1,1,1,1,1,1,1,1,1,1,1,1,1,1,1
1,1,1,1,1,1,1,1,1,1,1,1,1,1,1,1,1,1,1,1,1,1,1,1,1,1,1,1,1
1,1,1,1,1,1,1,1,1,1,1,2,2,2,2,2,2,2,1,1,1,1,1,1,1,1,1,1,1
1,1,1,1,1,1,1,1,1,1,1,2,2,2,2,2,2,2,1,1,1,1,1,1,1,1,1,1,1
1,1,1,1,1,1,1,1,1,1,1,2,2,2,2,2,2,2,1,1,1,1,1,1,1,1,1,1,1
1,1,1,1,1,1,1,1,1,1,1,2,2,2,2,2,2,2,1,1,1,1,1,1,1,1,1,1,1
1,1,1,1,1,1,1,1,1,1,1,2,2,2,2,2,2,2,1,1,1,1,1,1,1,1,1,1,1
1,1,1,1,1,1,1,1,1,1,1,2,2,2,2,2,2,2,1,1,1,1,1,1,1,1,1,1,1
1,1,1,1,1,1,1,1,1,1,1,2,2,2,2,2,2,2,1,1,1,1,1,1,1,1,1,1,1
1,1,1,1,1,1,1,1,1,1,1,1,1,1,1,1,1,1,1,1,1,1,1,1,1,1,1,1,1
1,1,1,1,1,1,1,1,1,1,1,1,1,1,1,1,1,1,1,1,1,1,1,1,1,1,1,1,1
1,1,1,1,1,1,1,1,1,1,1,1,1,1,1,1,1,1,1,1,1,1,1,1,1,1,1,1,1
1,1,1,1,1,1,1,1,1,1,1,1,1,1,1,1,1,1,1,1,1,1,1,1,1,1,1,1,1
1,1,1,1,1,1,1,1,1,1,1,1,1,1,1,1,1,1,1,1,1,1,1,1,1,1,1,1,1
1,1,1,1,1,1,1,1,1,1,1,1,1,1,1,1,1,1,1,1,1,1,1,1,1,1,1,1,1
1,1,1,1,1,1,1,1,1,1,1,1,1,1,1,1,1,1,1,1,1,1,1,1,1,1,1,1,1
1,1,1,1,1,1,1,1,1,1,1,1,1,1,1,1,1,1,1,1,1,1,1,1,1,1,1,1,1
1,1,1,1,1,1,1,1,1,1,1,1,1,1,1,1,1,1,1,1,1,1,1,1,1,1,1,1,1
1,1,1,1,1,1,1,1,1,1,1,1,1,1,1,1,1,1,1,1,1,1,1,1,1,1,1,1,1
1,1,1,1,1,1,1,1,1,1,1,1,1,1,1,1,1,1,1,1,1,1,1,1,1,1,1,1,1
endlayer

layer
1,1,1,1,1,1,1,1,1,1,1,1,1,1,1,1,1,1,1,1,1,1,1,1,1,1,1,1,1
1,1,1,1,1,1,1,1,1,1,1,1,1,1,1,1,1,1,1,1,1,1,1,1,1,1,1,1,1
1,1,1,1,1,1,1,1,1,1,1,1,1,1,1,1,1,1,1,1,1,1,1,1,1,1,1,1,1
1,1,1,1,1,1,1,1,1,1,1,1,1,1,1,1,1,1,1,1,1,1,1,1,1,1,1,1,1
1,1,1,1,1,1,1,1,1,1,1,1,1,1,1,1,1,1,1,1,1,1,1,1,1,1,1,1,1
1,1,1,1,1,1,1,1,1,1,1,1,1,1,1,1,1,1,1,1,1,1,1,1,1,1,1,1,1
1,1,1,1,1,1,1,1,1,1,1,1,1,1,1,1,1,1,1,1,1,1,1,1,1,1,1,1,1
1,1,1,1,1,1,1,1,1,1,1,1,1,1,1,1,1,1,1,1,1,1,1,1,1,1,1,1,1
1,1,1,1,1,1,1,1,1,1,1,1,1,1,1,1,1,1,1,1,1,1,1,1,1,1,1,1,1
1,1,1,1,1,1,1,1,1,1,1,1,1,1,1,1,1,1,1,1,1,1,1,1,1,1,1,1,1
1,1,1,1,1,1,1,1,1,1,1,1,1,1,1,1,1,1,1,1,1,1,1,1,1,1,1,1,1
1,1,1,1,1,1,1,1,1,1,1,2,2,2,2,2,2,2,1,1,1,1,1,1,1,1,1,1,1
1,1,1,1,1,1,1,1,1,1,1,2,3,4,3,4,3,2,1,1,1,1,1,1,1,1,1,1,1
1,1,1,1,1,1,1,1,1,1,1,2,4,4,3,4,4,2,1,1,1,1,1,1,1,1,1,1,1
1,1,1,1,1,1,1,1,1,1,1,2,3,3,3,3,3,2,1,1,1,1,1,1,1,1,1,1,1
1,1,1,1,1,1,1,1,1,1,1,2,4,4,3,4,4,2,1,1,1,1,1,1,1,1,1,1,1
1,1,1,1,1,1,1,1,1,1,1,2,3,4,3,4,3,2,1,1,1,1,1,1,1,1,1,1,1
1,1,1,1,1,1,1,1,1,1,1,2,2,2,2,2,2,2,1,1,1,1,1,1,1,1,1,1,1
1,1,1,1,1,1,1,1,1,1,1,1,1,1,1,1,1,1,1,1,1,1,1,1,1,1,1,1,1
1,1,1,1,1,1,1,1,1,1,1,1,1,1,1,1,1,1,1,1,1,1,1,1,1,1,1,1,1
1,1,1,1,1,1,1,1,1,1,1,1,1,1,1,1,1,1,1,1,1,1,1,1,1,1,1,1,1
1,1,1,1,1,1,1,1,1,1,1,1,1,1,1,1,1,1,1,1,1,1,1,1,1,1,1,1,1
1,1,1,1,1,1,1,1,1,1,1,1,1,1,1,1,1,1,1,1,1,1,1,1,1,1,1,1,1
1,1,1,1,1,1,1,1,1,1,1,1,1,1,1,1,1,1,1,1,1,1,1,1,1,1,1,1,1
1,1,1,1,1,1,1,1,1,1,1,1,1,1,1,1,1,1,1,1,1,1,1,1,1,1,1,1,1
1,1,1,1,1,1,1,1,1,1,1,1,1,1,1,1,1,1,1,1,1,1,1,1,1,1,1,1,1
1,1,1,1,1,1,1,1,1,1,1,1,1,1,1,1,1,1,1,1,1,1,1,1,1,1,1,1,1
1,1,1,1,1,1,1,1,1,1,1,1,1,1,1,1,1,1,1,1,1,1,1,1,1,1,1,1,1
1,1,1,1,1,1,1,1,1,1,1,1,1,1,1,1,1,1,1,1,1,1,1,1,1,1,1,1,1
endlayer

layer
1,1,1,1,1,1,1,1,1,1,1,1,1,1,1,1,1,1,1,1,1,1,1,1,1,1,1,1,1
1,1,1,1,1,1,1,1,1,1,1,1,1,1,1,1,1,1,1,1,1,1,1,1,1,1,1,1,1
1,1,1,1,1,1,1,1,1,1,1,1,1,1,1,1,1,1,1,1,1,1,1,1,1,1,1,1,1
1,1,1,1,1,1,1,1,1,1,1,1,1,1,1,1,1,1,1,1,1,1,1,1,1,1,1,1,1
1,1,1,1,1,1,1,1,1,1,1,1,1,1,1,1,1,1,1,1,1,1,1,1,1,1,1,1,1
1,1,1,1,1,1,1,1,1,1,2,2,1,1,1,1,1,2,2,1,1,1,1,1,1,1,1,1,1
1,1,1,1,1,1,1,1,1,1,2,2,2,2,2,2,2,2,2,1,1,1,1,1,1,1,1,1,1
1,1,1,1,1,1,1,1,1,1,2,2,2,2,2,2,2,2,2,1,1,1,1,1,1,1,1,1,1
1,1,1,1,1,1,1,1,1,1,2,2,2,2,2,2,2,2,2,1,1,1,1,1,1,1,1,1,1
1,1,1,1,1,1,1,1,1,1,2,2,2,2,2,2,2,2,2,1,1,1,1,1,1,1,1,1,1
1,1,1,1,1,2,2,2,2,2,2,2,2,2,2,2,2,2,2,2,2,2,2,2,1,1,1,1,1
2,2,2,2,2,2,2,2,2,2,2,2,2,2,2,2,2,2,2,2,2,2,2,2,2,2,2,2,2
2,2,2,2,2,2,2,2,2,2,2,2,5,5,5,5,5,2,2,2,2,2,2,1,2,2,2,2,2
2,2,2,2,2,2,2,2,2,2,2,2,5,5,5,5,5,2,2,2,2,2,2,1,2,2,2,2,2
2,2,2,2,2,2,2,2,2,2,2,2,5,5,5,5,5,2,2,2,2,2,2,1,2,2,2,2,2
2,2,2,2,2,2,2,2,2,2,2,2,5,5,5,5,5,2,2,2,2,2,2,1,2,2,2,2,2
2,2,2,2,2,2,2,2,2,2,2,2,5,5,5,5,5,2,2,2,2,2,2,1,2,2,2,2,2
2,2,2,2,2,2,2,2,2,2,2,2,2,2,2,2,2,2,2,2,2,2,2,2,2,2,2,2,2
1,1,1,1,1,2,2,2,2,2,2,2,2,2,2,2,2,2,2,2,2,2,2,2,1,1,1,1,1
1,1,1,1,1,1,1,1,1,1,2,2,2,2,2,2,2,2,2,1,1,1,1,1,1,1,1,1,1
1,1,1,1,1,1,1,1,1,1,2,2,2,2,2,2,2,2,2,1,1,1,1,1,1,1,1,1,1
1,1,1,1,1,1,1,1,1,1,2,2,2,2,2,2,2,2,2,1,1,1,1,1,1,1,1,1,1
1,1,1,1,1,1,1,1,1,1,2,2,2,2,2,2,2,2,2,1,1,1,1,1,1,1,1,1,1
1,1,1,1,1,1,1,1,1,1,2,2,1,1,1,1,1,2,2,1,1,1,1,1,1,1,1,1,1
1,1,1,1,1,1,1,1,1,1,1,1,1,1,1,1,1,1,1,1,1,1,1,1,1,1,1,1,1
1,1,1,1,1,1,1,1,1,1,1,1,1,1,1,1,1,1,1,1,1,1,1,1,1,1,1,1,1
1,1,1,1,1,1,1,1,1,1,1,1,1,1,1,1,1,1,1,1,1,1,1,1,1,1,1,1,1
1,1,1,1,1,1,1,1,1,1,1,1,1,1,1,1,1,1,1,1,1,1,1,1,1,1,1,1,1
1,1,1,1,1,1,1,1,1,1,1,1,1,1,1,1,1,1,1,1,1,1,1,1,1,1,1,1,1
endlayer

layer
1,1,1,1,1,1,1,1,1,1,1,1,1,1,1,1,1,1,1,1,1,1,1,1,1,1,1,1,1
1,1,1,1,1,1,1,1,1,1,1,1,1,1,1,1,1,1,1,1,1,1,1,1,1,1,1,1,1
1,1,1,1,1,1,1,1,1,1,1,1,1,1,1,1,1,1,1,1,1,1,1,1,1,1,1,1,1
1,1,1,1,1,1,1,1,1,1,1,1,1,1,1,1,1,1,1,1,1,1,1,1,1,1,1,1,1
1,1,1,1,1,1,1,1,1,1,1,1,1,2,2,2,1,1,1,1,1,1,1,1,1,1,1,1,1
1,1,1,1,1,1,1,1,1,1,2,2,2,2,2,2,2,2,2,1,1,1,1,1,1,1,1,1,1
1,1,1,1,1,1,2,2,2,2,2,2,2,2,2,2,2,2,2,2,2,2,2,1,1,1,1,1,1
1,1,1,1,1,1,2,2,2,2,8,7,0,0,0,0,0,7,6,2,2,2,2,1,1,1,1,1,1
1,1,1,1,1,1,2,2,2,2,8,7,0,0,0,0,0,7,6,2,2,2,2,1,1,1,1,1,1
1,1,1,1,1,1,2,2,2,2,8,7,0,0,0,0,0,7,6,2,2,2,2,1,1,1,1,1,1
1,1,1,1,1,2,2,9,9,9,10,10,0,0,0,0,0,10,10,9,9,9,2,2,1,1,1,1,1
2,2,2,2,2,2,2,7,7,7,10,10,0,0,0,0,0,10,10,7,7,7,2,2,2,2,2,2,2
2,0,0,0,2,2,2,0,0,0,0,0,0,0,0,0,0,0,0,0,0,0,2,2,2,2,2,2,2
2,6,6,6,2,2,2,0,0,0,0,0,0,0,0,0,0,0,0,0,0,0,2,2,2,13,12,11,2
2,0,0,0,2,2,2,0,0,0,0,0,0,0,0,0,0,0,0,0,0,0,2,2,2,11,13,13,2
2,6,6,6,2,2,2,0,0,0,0,0,0,0,0,0,0,0,0,0,0,0,2,2,2,13,11,12,2
2,0,0,0,2,2,2,0,0,0,0,0,0,0,0,0,0,0,0,0,0,0,2,2,2,2,2,2,2
2,2,2,2,2,2,2,7,7,7,10,10,0,0,0,0,0,10,10,7,7,7,2,2,2,2,2,2,2
1,1,1,1,1,2,2,14,14,14,10,10,0,0,0,0,0,10,10,14,14,14,2,2,1,1,1,1,1
1,1,1,1,1,1,2,2,2,2,8,7,0,0,0,0,0,7,6,2,2,2,2,1,1,1,1,1,1
1,1,1,1,1,1,2,2,2,2,8,7,0,0,0,0,0,7,6,2,2,2,2,1,1,1,1,1,1
1,1,1,1,1,1,2,2,2,2,8,7,0,0,0,0,0,7,6,2,2,2,2,1,1,1,1,1,1
1,1,1,1,1,1,2,2,2,2,2,2,2,2,2,2,2,2,2,2,2,2,2,1,1,1,1,1,1
1,1,1,1,1,1,1,1,1,1,2,2,2,2,2,2,2,2,2,1,1,1,1,1,1,1,1,1,1
1,1,1,1,1,1,1,1,1,1,1,1,1,2,2,2,1,1,1,1,1,1,1,1,1,1,1,1,1
1,1,1,1,1,1,1,1,1,1,1,1,1,1,1,1,1,1,1,1,1,1,1,1,1,1,1,1,1
1,1,1,1,1,1,1,1,1,1,1,1,1,1,1,1,1,1,1,1,1,1,1,1,1,1,1,1,1
1,1,1,1,1,1,1,1,1,1,1,1,1,1,1,1,1,1,1,1,1,1,1,1,1,1,1,1,1
1,1,1,1,1,1,1,1,1,1,1,1,1,1,1,1,1,1,1,1,1,1,1,1,1,1,1,1,1
endlayer

layer
1,1,1,1,1,1,1,1,1,1,1,1,1,1,1,1,1,1,1,1,1,1,1,1,1,1,1,1,1
1,1,1,1,1,1,1,1,1,1,1,1,1,1,1,1,1,1,1,1,1,1,1,1,1,1,1,1,1
1,1,1,1,1,1,1,1,1,1,1,1,1,1,1,1,1,1,1,1,1,1,1,1,1,1,1,1,1
1,1,1,1,1,1,1,1,1,1,1,1,1,1,1,1,1,1,1,1,1,1,1,1,1,1,1,1,1
1,1,1,1,1,1,1,1,1,1,1,1,15,9,3,9,15,1,1,1,1,1,1,1,1,1,1,1,1
1,1,1,1,1,1,1,1,1,1,10,2,15,0,16,0,15,2,10,1,1,1,1,1,1,1,1,1,1
1,1,1,1,1,1,10,3,9,9,15,15,0,0,0,0,0,15,15,9,9,3,10,1,1,1,1,1,1
1,1,1,1,1,1,3,3,0,0,0,0,0,0,0,0,0,0,0,0,0,3,3,1,1,1,1,1,1
1,1,1,1,1,1,8,0,0,0,0,0,0,0,0,0,0,0,0,0,0,0,6,1,1,1,1,1,1
1,1,1,1,1,1,8,0,0,0,0,0,0,0,0,0,0,0,0,0,0,0,6,1,1,1,1,1,1
1,1,1,1,1,10,15,0,0,0,15,15,0,0,0,0,0,15,15,0,0,0,15,10,1,1,1,1,1
2,2,2,2,2,2,15,0,0,0,15,15,0,0,0,0,0,15,15,0,0,0,15,2,2,2,2,2,2
2,17,17,17,15,15,0,0,0,0,0,0,0,0,0,0,0,0,0,0,0,0,0,15,15,11,13,12,2
2,6,6,6,8,0,0,0,0,0,0,0,0,0,0,0,0,0,0,0,0,0,0,0,6,12,0,13,2
2,0,0,0,3,19,0,0,0,0,0,0,0,0,0,0,0,0,0,0,0,0,0,18,3,0,0,12,2
2,6,6,6,8,0,0,0,0,0,0,0,0,0,0,0,0,0,0,0,0,0,0,0,6,11,13,12,2
2,20,20,20,15,15,0,0,0,0,0,0,0,0,0,0,0,0,0,0,0,0,0,15,15,12,11,13,2
2,2,2,2,2,2,15,0,0,0,15,15,0,0,0,0,0,15,15,0,0,0,15,2,2,2,2,2,2
1,1,1,1,1,10,15,0,0,0,15,15,0,0,0,0,0,15,15,0,0,0,15,10,1,1,1,1,1
1,1,1,1,1,1,8,0,0,0,0,0,0,0,0,0,0,0,0,0,0,0,6,1,1,1,1,1,1
1,1,1,1,1,1,8,0,0,0,0,0,0,0,0,0,0,0,0,0,0,0,6,1,1,1,1,1,1
1,1,1,1,1,1,3,3,0,0,0,0,0,0,0,0,0,0,0,0,0,3,3,1,1,1,1,1,1
1,1,1,1,1,1,10,3,14,14,15,15,0,0,0,0,0,15,15,14,14,3,10,1,1,1,1,1,1
1,1,1,1,1,1,1,1,1,1,10,2,15,0,21,0,15,2,10,1,1,1,1,1,1,1,1,1,1
1,1,1,1,1,1,1,1,1,1,1,1,15,14,3,14,15,1,1,1,1,1,1,1,1,1,1,1,1
1,1,1,1,1,1,1,1,1,1,1,1,1,1,1,1,1,1,1,1,1,1,1,1,1,1,1,1,1
1,1,1,1,1,1,1,1,1,1,1,1,1,1,1,1,1,1,1,1,1,1,1,1,1,1,1,1,1
1,1,1,1,1,1,1,1,1,1,1,1,1,1,1,1,1,1,1,1,1,1,1,1,1,1,1,1,1
1,1,1,1,1,1,1,1,1,1,1,1,1,1,1,1,1,1,1,1,1,1,1,1,1,1,1,1,1
endlayer

layer
2,2,2,2,2,2,2,2,2,2,2,1,1,1,1,1,1,1,2,2,2,2,2,2,2,2,2,2,2
2,2,2,2,2,2,2,2,2,2,2,1,1,1,1,1,1,1,2,2,2,2,2,2,2,2,2,2,2
2,2,2,2,2,2,2,2,2,2,2,2,1,1,1,1,1,2,2,2,2,2,2,2,2,2,2,2,2
2,2,2,2,2,2,2,2,2,2,2,2,1,1,1,1,1,2,2,2,2,2,2,2,2,2,2,2,2
2,2,2,2,2,2,2,2,2,2,2,2,1,3,3,3,1,2,2,2,2,2,2,2,2,2,2,2,2
2,2,2,2,2,2,2,2,9,9,10,2,15,0,0,0,15,2,10,9,9,2,2,2,2,2,2,2,2
2,2,2,2,2,2,10,10,0,0,15,15,0,0,0,0,0,15,15,0,0,10,10,2,2,2,2,2,2
2,2,2,2,2,2,10,10,0,0,0,0,0,0,0,0,0,0,0,0,0,10,10,2,2,2,2,2,2
2,2,2,2,2,8,0,0,0,0,0,0,0,0,0,0,0,0,0,0,0,0,0,6,2,2,2,2,2
2,2,2,2,2,8,0,0,0,0,0,0,0,0,0,0,0,0,0,0,0,0,0,6,2,2,2,2,2
2,2,2,2,2,10,15,0,0,0,15,15,0,0,0,0,0,15,15,0,0,0,15,10,2,2,2,2,2
2,2,2,2,2,2,15,0,0,0,15,15,0,0,0,0,0,15,15,0,0,0,15,2,2,2,2,2,2
2,0,0,0,2,15,0,0,0,0,0,0,0,0,0,0,0,0,0,0,0,0,0,15,2,13,0,11,2
2,6,6,6,3,0,0,0,0,0,0,0,0,0,0,0,0,0,0,0,0,0,0,0,3,0,0,0,2
2,0,0,0,3,0,0,0,0,0,0,0,0,0,0,0,0,0,0,0,0,0,0,0,3,0,0,0,2
2,6,6,6,3,0,0,0,0,0,0,0,0,0,0,0,0,0,0,0,0,0,0,0,3,0,0,0,2
2,0,0,0,2,15,0,0,0,0,0,0,0,0,0,0,0,0,0,0,0,0,0,15,2,13,0,11,2
2,2,2,2,2,2,15,0,0,0,15,15,0,0,0,0,0,15,15,0,0,0,15,2,2,2,2,2,2
2,2,2,2,2,10,15,0,0,0,15,15,0,0,0,0,0,15,15,0,0,0,15,10,2,2,2,2,2
2,2,2,2,2,8,0,0,0,0,0,0,0,0,0,0,0,0,0,0,0,0,0,6,2,2,2,2,2
2,2,2,2,2,8,0,0,0,0,0,0,0,0,0,0,0,0,0,0,0,0,0,6,2,2,2,2,2
2,2,2,2,2,2,10,10,0,0,0,0,0,0,0,0,0,0,0,0,0,10,10,2,2,2,2,2,2
2,2,2,2,2,2,10,10,0,0,15,15,0,0,0,0,0,15,15,0,0,10,10,2,2,2,2,2,2
2,2,2,2,2,2,2,2,14,14,10,2,15,0,0,0,15,2,10,14,14,2,2,2,2,2,2,2,2
2,2,2,2,2,2,2,2,2,2,2,2,1,3,3,3,1,2,2,2,2,2,2,2,2,2,2,2,2
2,2,2,2,2,2,2,2,2,2,2,2,1,1,1,1,1,2,2,2,2,2,2,2,2,2,2,2,2
2,2,2,2,2,2,2,2,2,2,2,2,1,1,1,1,1,2,2,2,2,2,2,2,2,2,2,2,2
2,2,2,2,2,2,2,2,2,2,2,1,1,1,1,1,1,1,2,2,2,2,2,2,2,2,2,2,2
2,2,2,2,2,2,2,2,2,2,2,1,1,1,1,1,1,1,2,2,2,2,2,2,2,2,2,2,2
endlayer

layer
2,2,2,2,2,2,2,2,2,2,2,1,1,1,1,1,1,1,2,2,2,2,2,2,2,2,2,2,2
2,10,0,0,0,0,10,10,0,0,2,1,1,1,1,1,1,1,2,0,0,10,10,0,0,0,0,10,2
2,0,0,0,0,0,0,0,0,0,14,2,1,1,1,1,1,2,14,0,0,0,0,0,0,0,0,0,2
2,0,0,0,0,0,0,0,0,0,6,2,1,1,1,1,1,2,8,0,0,0,0,0,0,0,0,0,2
2,0,0,0,0,0,0,0,0,0,6,2,1,3,9,3,1,2,8,0,0,0,0,0,0,0,0,0,2
2,0,0,0,0,0,0,0,0,0,9,2,15,0,0,0,15,2,9,0,0,0,0,0,0,0,0,0,2
2,10,0,0,0,0,15,15,0,0,15,15,0,0,0,0,0,15,15,0,0,15,15,0,0,0,0,10,2
2,10,0,0,0,0,15,15,0,0,0,0,0,0,0,0,0,0,0,0,0,15,15,0,0,0,0,10,2
2,0,0,0,0,0,0,0,0,0,0,0,0,0,0,0,0,0,0,0,0,0,0,0,0,0,0,0,2
2,0,0,0,0,0,0,0,0,0,0,0,0,0,0,0,0,0,0,0,0,0,0,0,0,0,0,0,2
2,2,6,14,14,8,15,0,0,0,15,15,0,0,0,0,0,15,15,0,0,0,15,6,14,14,8,2,2
2,2,2,2,2,2,15,0,0,0,15,15,0,0,0,0,0,15,15,0,0,0,15,2,2,2,2,2,2
2,17,17,17,2,15,0,0,0,0,0,0,0,0,0,0,0,0,0,0,0,0,0,15,2,0,0,0,2
2,6,6,6,3,0,0,0,0,0,0,0,0,0,0,0,0,0,0,0,0,0,0,0,3,0,0,0,2
2,0,0,0,8,0,0,0,0,0,0,0,0,0,0,0,0,0,0,0,0,0,0,0,6,0,0,0,2
2,6,6,6,3,0,0,0,0,0,0,0,0,0,0,0,0,0,0,0,0,0,0,0,3,0,0,0,2
2,20,20,20,2,15,0,0,0,0,0,0,0,0,0,0,0,0,0,0,0,0,0,15,2,0,0,0,2
2,2,2,2,2,2,15,0,0,0,15,15,0,0,0,0,0,15,15,0,0,0,15,2,2,2,2,2,2
2,2,6,9,9,8,15,0,0,0,15,15,0,0,0,0,0,15,15,0,0,0,15,6,9,9,8,2,2
2,0,0,0,0,0,0,0,0,0,0,0,0,0,0,0,0,0,0,0,0,0,0,0,0,0,0,0,2
2,0,0,0,0,0,0,0,0,0,0,0,0,0,0,0,0,0,0,0,0,0,0,0,0,0,0,0,2
2,10,0,0,0,0,15,15,0,0,0,0,0,0,0,0,0,0,0,0,0,15,15,0,0,0,0,10,2
2,10,0,0,0,0,15,15,0,0,15,15,0,0,0,0,0,15,15,0,0,15,15,0,0,0,0,10,2
2,0,0,0,0,0,0,0,0,0,14,2,15,0,0,0,15,2,14,0,0,0,0,0,0,0,0,0,2
2,0,0,0,0,0,0,0,0,0,6,2,1,3,14,3,1,2,8,0,0,0,0,0,0,0,0,0,2
2,0,0,0,0,0,0,0,0,0,6,2,1,1,1,1,1,2,8,0,0,0,0,0,0,0,0,0,2
2,0,0,0,0,0,0,0,0,0,9,2,1,1,1,1,1,2,9,0,0,0,0,0,0,0,0,0,2
2,10,0,0,0,0,10,10,0,0,2,1,1,1,1,1,1,1,2,0,0,10,10,0,0,0,0,10,2
2,2,2,2,2,2,2,2,2,2,2,1,1,1,1,1,1,1,2,2,2,2,2,2,2,2,2,2,2
endlayer

layer
2,2,2,2,2,2,2,2,2,2,2,1,1,1,1,1,1,1,2,2,2,2,2,2,2,2,2,2,2
2,15,0,0,0,0,15,15,0,0,2,1,1,1,1,1,1,1,2,0,0,15,15,0,0,0,0,15,2
2,0,0,0,0,0,0,0,0,0,0,2,1,1,1,1,1,2,0,0,0,0,0,0,0,0,0,0,2
2,0,0,0,0,0,0,0,0,0,0,6,1,1,1,1,1,8,0,0,0,0,0,0,0,0,0,0,2
2,0,0,0,0,0,0,0,0,0,0,6,15,22,3,22,15,8,0,0,0,0,0,0,0,0,0,0,2
2,0,0,0,0,0,0,0,0,0,0,2,15,0,0,0,15,2,0,0,0,0,0,0,0,0,0,0,2
2,15,0,0,0,0,15,15,0,0,15,15,0,0,0,0,0,15,15,0,0,15,15,0,0,0,0,15,2
2,15,0,0,0,0,15,15,0,0,0,0,0,0,0,0,0,0,0,0,0,15,15,0,0,0,0,15,2
2,0,0,0,0,0,0,0,0,0,0,0,0,0,0,0,0,0,0,0,0,0,0,0,0,0,0,0,2
2,0,0,0,0,0,0,0,0,0,0,0,0,0,0,0,0,0,0,0,0,0,0,0,0,0,0,0,2
2,2,0,0,0,0,15,0,0,0,15,15,0,0,0,0,0,15,15,0,0,0,15,0,0,0,0,2,2
2,2,2,14,14,2,15,0,0,0,15,15,0,0,0,0,0,15,15,0,0,0,15,2,14,14,2,2,2
2,0,0,0,15,15,0,0,0,0,0,0,0,0,0,0,0,0,0,0,0,0,0,15,15,22,22,22,2
2,6,6,6,24,0,0,0,0,0,0,0,0,0,0,0,0,0,0,0,0,0,0,0,23,0,0,0,2
2,0,0,0,3,0,0,0,0,0,0,0,0,0,0,0,0,0,0,0,0,0,0,0,3,0,0,0,2
2,6,6,6,24,0,0,0,0,0,0,0,0,0,0,0,0,0,0,0,0,0,0,0,23,0,0,0,2
2,0,0,0,15,15,0,0,0,0,0,0,0,0,0,0,0,0,0,0,0,0,0,15,15,25,25,25,2
2,2,2,9,9,2,15,0,0,0,15,15,0,0,0,0,0,15,15,0,0,0,15,2,9,9,2,2,2
2,2,0,0,0,0,15,0,0,0,15,15,0,0,0,0,0,15,15,0,0,0,15,0,0,0,0,2,2
2,0,0,0,0,0,0,0,0,0,0,0,0,0,0,0,0,0,0,0,0,0,0,0,0,0,0,0,2
2,0,0,0,0,0,0,0,0,0,0,0,0,0,0,0,0,0,0,0,0,0,0,0,0,0,0,0,2
2,15,0,0,0,0,15,15,0,0,0,0,0,0,0,0,0,0,0,0,0,15,15,0,0,0,0,15,2
2,15,0,0,0,0,15,15,0,0,15,15,0,0,0,0,0,15,15,0,0,15,15,0,0,0,0,15,2
2,0,0,0,0,0,0,0,0,0,0,2,15,0,0,0,15,2,0,0,0,0,0,0,0,0,0,0,2
2,0,0,0,0,0,0,0,0,0,0,6,15,25,3,25,15,8,0,0,0,0,0,0,0,0,0,0,2
2,0,0,0,0,0,0,0,0,0,0,6,1,1,1,1,1,8,0,0,0,0,0,0,0,0,0,0,2
2,0,0,0,0,0,0,0,0,0,0,2,1,1,1,1,1,2,0,0,0,0,0,0,0,0,0,0,2
2,15,0,0,0,0,15,15,0,0,2,1,1,1,1,1,1,1,2,0,0,15,15,0,0,0,0,15,2
2,2,2,2,2,2,2,2,2,2,2,1,1,1,1,1,1,1,2,2,2,2,2,2,2,2,2,2,2
endlayer

layer
2,2,2,2,2,2,2,2,2,2,2,1,1,1,1,1,1,1,2,2,2,2,2,2,2,2,2,2,2
2,15,0,0,0,0,15,15,0,0,2,1,1,1,1,1,1,1,2,0,0,15,15,0,0,0,0,15,2
2,0,0,0,0,0,0,0,0,0,0,2,2,2,2,2,2,2,0,0,0,0,0,0,0,0,0,0,2
2,0,0,0,0,0,0,0,0,0,0,0,6,2,2,2,8,0,0,0,0,0,0,0,0,0,0,0,2
2,0,0,0,0,0,0,0,0,0,0,0,6,15,15,15,8,0,0,0,0,0,0,0,0,0,0,0,2
2,0,0,0,0,0,0,0,0,0,0,2,26,24,27,23,26,2,0,0,0,0,0,0,0,0,0,0,2
2,15,0,0,0,0,15,15,0,0,15,15,0,0,0,0,0,15,15,0,0,15,15,0,0,0,0,15,2
2,15,0,0,0,0,15,15,0,0,0,0,0,0,0,0,0,0,0,0,0,15,15,0,0,0,0,15,2
2,0,0,0,0,0,0,0,0,0,0,0,0,0,0,0,0,0,0,0,0,0,0,0,0,0,0,0,2
2,0,0,0,0,0,0,0,0,0,0,0,0,0,0,0,0,0,0,0,0,0,0,0,0,0,0,0,2
2,2,0,0,0,0,15,0,0,0,26,26,0,0,0,0,0,26,26,0,0,0,15,0,0,0,0,2,2
2,2,2,0,0,2,15,0,0,0,26,26,0,0,0,0,0,26,26,0,0,0,15,2,0,0,2,2,2
2,2,2,14,14,26,0,0,0,0,0,0,0,0,0,0,0,0,0,0,0,0,0,26,14,14,2,2,2
2,2,2,2,15,22,0,0,0,0,0,0,0,0,0,0,0,0,0,0,0,0,0,22,15,2,2,2,2
2,2,2,2,15,27,0,0,0,0,0,0,0,0,0,0,0,0,0,0,0,0,0,27,15,2,2,2,2
2,2,2,2,15,25,0,0,0,0,0,0,0,0,0,0,0,0,0,0,0,0,0,25,15,2,2,2,2
2,2,2,9,9,26,0,0,0,0,0,0,0,0,0,0,0,0,0,0,0,0,0,26,9,9,2,2,2
2,2,2,0,0,2,15,0,0,0,26,26,0,0,0,0,0,26,26,0,0,0,15,2,0,0,2,2,2
2,2,0,0,0,0,15,0,0,0,26,26,0,0,0,0,0,26,26,0,0,0,15,0,0,0,0,2,2
2,0,0,0,0,0,0,0,0,0,0,0,0,0,0,0,0,0,0,0,0,0,0,0,0,0,0,0,2
2,0,0,0,0,0,0,0,0,0,0,0,0,0,0,0,0,0,0,0,0,0,0,0,0,0,0,0,2
2,15,0,0,0,0,15,15,0,0,0,0,0,0,0,0,0,0,0,0,0,15,15,0,0,0,0,15,2
2,15,0,0,0,0,15,15,0,0,15,15,0,0,0,0,0,15,15,0,0,15,15,0,0,0,0,15,2
2,0,0,0,0,0,0,0,0,0,0,2,26,24,27,23,26,2,0,0,0,0,0,0,0,0,0,0,2
2,0,0,0,0,0,0,0,0,0,0,0,6,15,15,15,8,0,0,0,0,0,0,0,0,0,0,0,2
2,0,0,0,0,0,0,0,0,0,0,0,6,2,2,2,8,0,0,0,0,0,0,0,0,0,0,0,2
2,0,0,0,0,0,0,0,0,0,0,2,2,2,2,2,2,2,0,0,0,0,0,0,0,0,0,0,2
2,15,0,0,0,0,15,15,0,0,2,1,1,1,1,1,1,1,2,0,0,15,15,0,0,0,0,15,2
2,2,2,2,2,2,2,2,2,2,2,1,1,1,1,1,1,1,2,2,2,2,2,2,2,2,2,2,2
endlayer

layer
2,2,2,2,2,2,2,2,2,2,2,1,1,1,1,1,1,1,2,2,2,2,2,2,2,2,2,2,2
2,15,0,0,0,0,15,15,0,0,2,1,2,2,2,2,2,1,2,0,0,15,15,0,0,0,0,15,2
2,0,0,0,0,0,0,0,0,0,0,2,2,0,0,0,2,2,0,0,0,0,0,0,0,0,0,0,2
2,0,0,0,0,0,0,0,0,0,0,0,0,0,0,0,0,0,0,0,0,0,0,0,0,0,0,0,2
2,0,0,0,0,0,0,0,0,0,0,0,0,0,0,0,0,0,0,0,0,0,0,0,0,0,0,0,2
2,0,0,0,0,0,0,0,0,0,0,2,2,14,14,14,15,2,0,0,0,0,0,0,0,0,0,0,2
2,15,0,0,0,0,15,15,0,0,15,15,15,15,15,15,15,15,15,0,0,15,15,0,0,0,0,15,2
2,15,0,0,0,0,15,15,0,0,10,15,15,15,15,15,15,15,10,0,0,15,15,0,0,0,0,15,2
2,0,0,0,0,0,0,0,0,0,26,15,15,15,15,15,15,15,26,0,0,0,0,0,0,0,0,0,2
2,0,0,0,0,0,0,0,0,27,10,15,15,15,15,15,15,15,10,27,0,0,0,0,0,0,0,0,2
2,2,0,0,0,0,15,10,26,10,10,2,15,15,15,15,15,2,10,10,26,10,15,0,0,0,0,2,2
1,1,2,0,0,2,15,15,15,15,2,2,2,2,2,2,2,2,2,15,15,15,15,2,0,0,2,1,1
1,2,2,0,0,15,15,15,15,15,15,2,2,2,2,2,2,2,15,15,15,15,15,2,0,0,2,2,1
1,2,0,0,0,6,15,15,15,15,15,2,2,2,2,2,2,2,15,15,15,15,15,8,0,0,0,2,1
1,2,0,0,0,6,15,15,15,15,15,2,2,2,2,2,2,2,15,15,15,15,15,8,0,0,0,2,1
1,2,0,0,0,6,15,15,15,15,15,2,2,2,2,2,2,2,15,15,15,15,15,8,0,0,0,2,1
1,2,2,0,0,2,15,15,15,15,15,2,2,2,2,2,2,2,15,15,15,15,15,15,0,0,2,2,1
1,1,2,0,0,2,15,15,15,15,2,2,2,2,2,2,2,2,2,15,15,15,15,2,0,0,2,1,1
2,2,0,0,0,0,15,10,26,10,15,2,15,15,15,15,15,2,15,10,26,10,15,0,0,0,0,2,2
2,0,0,0,0,0,0,0,0,27,10,15,15,15,15,15,15,15,10,27,0,0,0,0,0,0,0,0,2
2,0,0,0,0,0,0,0,0,0,26,15,15,15,15,15,15,15,26,0,0,0,0,0,0,0,0,0,2
2,15,0,0,0,0,15,15,0,0,10,15,15,15,15,15,15,15,10,0,0,15,15,0,0,0,0,15,2
2,15,0,0,0,0,15,15,0,0,15,15,15,15,15,15,15,15,15,0,0,15,15,0,0,0,0,15,2
2,0,0,0,0,0,0,0,0,0,0,2,15,9,9,9,2,2,0,0,0,0,0,0,0,0,0,0,2
2,0,0,0,0,0,0,0,0,0,0,0,0,0,0,0,0,0,0,0,0,0,0,0,0,0,0,0,2
2,0,0,0,0,0,0,0,0,0,0,0,0,0,0,0,0,0,0,0,0,0,0,0,0,0,0,0,2
2,0,0,0,0,0,0,0,0,0,0,2,2,0,0,0,2,2,0,0,0,0,0,0,0,0,0,0,2
2,15,0,0,0,0,15,15,0,0,2,1,2,2,2,2,2,1,2,0,0,15,15,0,0,0,0,15,2
2,2,2,2,2,2,2,2,2,2,2,1,1,1,1,1,1,1,2,2,2,2,2,2,2,2,2,2,2
endlayer

layer
2,2,2,2,2,2,2,2,2,2,2,1,1,1,1,1,1,1,2,2,2,2,2,2,2,2,2,2,2
2,15,0,0,0,0,15,15,0,0,2,1,2,2,2,2,2,1,2,0,0,15,15,0,0,0,0,15,2
2,0,0,0,0,0,0,0,0,0,0,2,2,0,0,0,2,2,0,0,0,0,0,0,0,0,0,0,2
2,0,0,0,0,0,0,0,0,0,0,0,0,0,0,0,0,0,0,0,0,0,0,0,0,0,0,0,2
2,0,0,0,0,0,0,0,0,0,0,0,0,0,0,0,0,0,0,0,0,0,0,0,0,0,0,0,2
2,0,0,0,0,0,0,0,0,0,0,2,2,0,0,0,15,2,0,0,0,0,0,0,0,0,0,0,2
2,15,0,0,0,0,15,15,0,0,15,15,2,14,14,14,15,15,15,0,0,15,15,0,0,0,0,15,2
2,15,0,0,0,0,15,15,0,0,2,15,15,15,15,15,15,15,2,0,0,15,15,0,0,0,0,15,2
2,0,0,0,0,0,0,0,25,25,2,2,2,2,2,2,2,2,2,25,24,0,0,0,0,0,0,0,2
2,0,0,0,0,0,0,0,23,10,3,3,10,3,3,3,10,3,3,10,24,0,0,0,0,0,0,0,2
2,2,0,0,0,0,15,2,2,3,28,28,3,28,28,28,3,28,28,3,2,2,15,0,0,0,0,2,2
1,1,2,0,0,2,15,15,2,3,28,28,3,28,4,28,3,28,28,3,2,15,15,2,0,0,2,1,1
1,2,2,0,0,15,15,15,2,10,3,3,10,3,3,3,10,3,3,10,2,15,2,2,0,0,2,2,1
1,2,0,0,0,0,6,15,2,3,28,28,3,28,4,28,3,28,28,3,2,15,8,0,0,0,0,2,1
1,2,0,0,0,0,6,15,2,3,28,4,3,4,4,4,3,4,28,3,2,15,8,0,0,0,0,2,1
1,2,0,0,0,0,6,15,2,3,28,28,3,28,4,28,3,28,28,3,2,15,8,0,0,0,0,2,1
1,2,2,0,0,2,2,15,2,10,3,3,10,3,3,3,10,3,3,10,2,15,15,15,0,0,2,2,1
1,1,2,0,0,2,15,15,2,3,28,28,3,28,4,28,3,28,28,3,2,15,15,2,0,0,2,1,1
2,2,0,0,0,0,15,2,2,3,28,28,3,28,28,28,3,28,28,3,2,2,15,0,0,0,0,2,2
2,0,0,0,0,0,0,0,23,10,3,3,10,3,3,3,10,3,3,10,24,0,0,0,0,0,0,0,2
2,0,0,0,0,0,0,0,23,22,2,2,2,2,2,2,2,2,2,22,24,0,0,0,0,0,0,0,2
2,15,0,0,0,0,15,15,0,0,2,15,15,15,15,15,15,15,2,0,0,15,15,0,0,0,0,15,2
2,15,0,0,0,0,15,15,0,0,15,15,15,9,9,9,2,15,15,0,0,15,15,0,0,0,0,15,2
2,0,0,0,0,0,0,0,0,0,0,2,15,0,0,0,2,2,0,0,0,0,0,0,0,0,0,0,2
2,0,0,0,0,0,0,0,0,0,0,0,0,0,0,0,0,0,0,0,0,0,0,0,0,0,0,0,2
2,0,0,0,0,0,0,0,0,0,0,0,0,0,0,0,0,0,0,0,0,0,0,0,0,0,0,0,2
2,0,0,0,0,0,0,0,0,0,0,2,2,0,0,0,2,2,0,0,0,0,0,0,0,0,0,0,2
2,15,0,0,0,0,15,15,0,0,2,1,2,2,2,2,2,1,2,0,0,15,15,0,0,0,0,15,2
2,2,2,2,2,2,2,2,2,2,2,1,1,1,1,1,1,1,2,2,2,2,2,2,2,2,2,2,2
endlayer

layer
2,2,2,2,2,2,2,2,2,2,2,1,1,1,1,1,1,1,2,2,2,2,2,2,2,2,2,2,2
2,26,22,22,22,22,26,26,22,22,2,1,2,2,2,2,2,1,2,22,22,26,26,22,22,22,22,26,2
2,24,0,0,0,0,0,0,0,0,22,2,2,0,0,0,2,2,22,0,0,0,0,0,0,0,0,23,2
2,24,0,0,0,0,0,0,0,0,27,27,0,0,0,0,0,27,27,0,0,0,0,0,0,0,0,23,2
2,24,0,0,0,0,0,0,0,0,27,27,0,0,0,0,0,27,27,0,0,0,0,0,0,0,0,23,2
2,24,0,0,0,0,0,0,0,0,25,2,2,0,0,0,2,2,25,0,0,0,0,0,0,0,0,23,2
2,26,0,0,0,0,26,26,0,0,26,15,2,0,0,0,15,15,26,0,0,26,26,0,0,0,0,26,2
2,26,0,0,0,0,26,26,25,25,2,15,2,14,14,14,15,15,2,25,25,26,26,0,0,0,0,26,2
2,24,0,0,0,0,0,23,2,2,2,2,1,2,2,2,2,2,2,2,2,24,0,0,0,0,0,23,2
2,24,0,0,0,0,0,23,2,2,5,5,10,5,5,5,10,5,5,2,2,24,0,0,0,0,0,23,2
2,2,24,27,27,23,26,2,2,5,5,5,5,5,5,5,5,5,5,5,2,2,26,24,27,27,23,2,2
1,1,2,27,27,2,15,15,2,5,5,5,5,5,5,5,5,5,5,5,2,15,15,2,27,27,2,1,1
1,2,2,0,0,2,15,15,2,10,5,5,10,5,5,5,10,5,5,10,1,2,2,2,0,0,2,2,1
1,2,0,0,0,0,0,6,2,5,5,5,5,5,5,5,5,5,5,5,2,8,0,0,0,0,0,2,1
1,2,0,0,0,0,0,6,2,5,5,5,5,5,5,5,5,5,5,5,2,8,0,0,0,0,0,2,1
1,2,0,0,0,0,0,6,2,5,5,5,5,5,5,5,5,5,5,5,2,8,0,0,0,0,0,2,1
1,2,2,0,0,2,2,2,1,10,5,5,10,5,5,5,10,5,5,10,2,15,15,2,0,0,2,2,1
1,1,2,27,27,2,15,15,2,5,5,5,5,5,5,5,5,5,5,5,2,15,15,2,27,27,2,1,1
2,2,24,27,27,23,26,2,2,5,5,5,5,5,5,5,5,5,5,5,2,2,26,24,27,27,23,2,2
2,24,0,0,0,0,0,23,2,2,5,5,10,5,5,5,10,5,5,2,2,24,0,0,0,0,0,23,2
2,24,0,0,0,0,0,23,2,2,2,2,2,2,2,2,1,2,2,2,2,24,0,0,0,0,0,23,2
2,26,0,0,0,0,26,26,22,22,2,15,15,9,9,9,2,15,2,22,22,26,26,0,0,0,0,26,2
2,26,0,0,0,0,26,26,0,0,26,15,15,0,0,0,2,15,26,0,0,26,26,0,0,0,0,26,2
2,24,0,0,0,0,0,0,0,0,22,2,2,0,0,0,2,2,22,0,0,0,0,0,0,0,0,23,2
2,24,0,0,0,0,0,0,0,0,27,27,0,0,0,0,0,27,27,0,0,0,0,0,0,0,0,23,2
2,24,0,0,0,0,0,0,0,0,27,27,0,0,0,0,0,27,27,0,0,0,0,0,0,0,0,23,2
2,24,0,0,0,0,0,0,0,0,25,2,2,0,0,0,2,2,25,0,0,0,0,0,0,0,0,23,2
2,26,25,25,25,25,26,26,25,25,2,1,2,2,2,2,2,1,2,25,25,26,26,25,25,25,25,26,2
2,2,2,2,2,2,2,2,2,2,2,1,1,1,1,1,1,1,2,2,2,2,2,2,2,2,2,2,2
endlayer

layer
1,1,1,1,1,1,1,1,1,1,1,1,1,1,1,1,1,1,1,1,1,1,1,1,1,1,1,1,1
1,2,2,2,2,2,2,2,2,2,1,1,2,2,2,2,2,1,1,2,2,2,2,2,2,2,2,2,1
1,2,22,22,22,22,22,22,22,2,2,2,2,24,0,23,2,2,2,24,22,22,22,22,22,22,23,2,1
1,2,24,0,0,0,0,0,0,23,2,2,24,0,0,0,23,2,2,24,0,0,0,0,0,0,23,2,1
1,2,24,0,0,0,0,0,0,23,2,2,24,0,0,0,23,2,2,24,0,0,0,0,0,0,23,2,1
1,2,24,0,0,0,0,0,0,23,2,2,2,0,0,0,2,2,2,24,0,0,0,0,0,0,23,2,1
1,2,24,0,0,0,3,3,25,25,2,2,2,0,0,0,2,2,2,25,25,3,3,0,0,0,23,2,1
1,2,24,0,0,0,3,3,2,2,2,2,2,0,0,0,2,2,2,2,2,3,3,0,0,0,23,2,1
1,2,24,0,0,0,23,2,2,2,9,9,2,0,0,0,2,9,9,2,2,2,24,0,0,0,23,2,1
1,2,25,25,25,25,23,2,2,15,0,0,15,0,0,0,15,0,0,15,2,2,24,25,25,25,2,2,1
1,1,2,2,2,2,2,2,8,0,0,0,0,0,0,0,0,0,0,0,6,2,2,2,2,2,2,1,1
1,1,2,2,2,2,2,2,8,0,0,0,0,0,0,0,0,0,0,0,6,2,2,2,2,2,2,1,1
1,2,2,22,22,2,2,2,2,15,0,0,15,0,0,0,15,0,0,15,2,2,2,2,22,22,2,2,1
1,2,22,0,0,0,0,0,0,0,0,0,0,0,0,0,0,0,0,0,0,0,0,0,0,0,22,2,1
1,2,0,0,0,0,0,0,0,0,0,0,0,0,0,0,0,0,0,0,0,0,0,0,0,0,0,2,1
1,2,25,0,0,0,0,0,0,0,0,0,0,0,0,0,0,0,0,0,0,0,0,0,0,0,25,2,1
1,2,2,25,25,2,2,2,2,15,0,0,15,0,0,0,15,0,0,15,2,2,2,2,25,25,2,2,1
1,1,2,2,2,2,2,2,8,0,0,0,0,0,0,0,0,0,0,0,6,2,2,2,2,2,2,1,1
1,1,2,2,2,2,2,2,8,0,0,0,0,0,0,0,0,0,0,0,6,2,2,2,2,2,2,1,1
1,2,2,22,22,22,23,2,2,15,0,0,15,0,0,0,15,0,0,15,2,2,24,22,22,22,22,2,1
1,2,24,0,0,0,23,2,2,2,14,14,2,0,0,0,2,14,14,2,2,2,24,0,0,0,23,2,1
1,2,24,0,0,0,3,3,2,2,2,2,2,0,0,0,2,2,2,2,2,3,3,0,0,0,23,2,1
1,2,24,0,0,0,3,3,22,22,2,2,2,0,0,0,2,2,2,22,22,3,3,0,0,0,23,2,1
1,2,24,0,0,0,0,0,0,23,2,2,2,0,0,0,2,2,2,24,0,0,0,0,0,0,23,2,1
1,2,24,0,0,0,0,0,0,23,2,2,24,0,0,0,23,2,2,24,0,0,0,0,0,0,23,2,1
1,2,24,0,0,0,0,0,0,23,2,2,24,0,0,0,23,2,2,24,0,0,0,0,0,0,23,2,1
1,2,24,25,25,25,25,25,25,23,2,2,2,24,0,23,2,2,2,2,25,25,25,25,25,25,25,2,1
1,2,2,2,2,2,2,2,2,2,1,1,2,2,2,2,2,1,1,2,2,2,2,2,2,2,2,2,1
1,1,1,1,1,1,1,1,1,1,1,1,1,1,1,1,1,1,1,1,1,1,1,1,1,1,1,1,1
endlayer

layer
1,1,1,1,1,1,1,1,1,1,1,1,1,1,1,1,1,1,1,1,1,1,1,1,1,1,1,1,1
1,1,1,1,1,1,1,1,1,1,1,1,1,1,1,1,1,1,1,1,1,1,1,1,1,1,1,1,1
1,1,2,2,2,2,2,2,2,1,1,1,2,2,2,2,2,1,1,2,2,2,2,2,2,2,2,1,1
1,1,2,10,10,10,10,10,10,2,1,1,2,22,22,22,2,1,1,2,10,10,10,10,10,10,2,1,1
1,1,2,10,10,10,10,10,10,2,1,1,2,0,0,0,2,1,1,2,10,10,10,10,10,10,2,1,1
1,1,2,10,10,10,10,10,10,2,1,1,2,0,0,0,2,1,1,2,10,10,10,10,10,10,2,1,1
1,1,2,10,10,10,2,2,2,2,1,1,2,0,0,0,2,1,1,2,2,2,2,10,10,10,2,1,1
1,1,2,10,10,10,2,2,2,2,3,3,2,0,0,0,2,3,3,2,2,2,2,10,10,10,2,1,1
1,1,2,10,10,10,2,2,2,2,0,0,2,0,0,0,2,0,0,2,2,2,2,10,10,10,2,1,1
1,1,2,2,2,2,2,2,2,15,0,0,15,0,0,0,15,0,0,15,2,2,2,2,2,2,1,1,1
1,1,1,1,1,1,1,3,0,0,0,0,0,0,0,0,0,0,0,0,0,3,1,1,1,1,1,1,1
1,1,1,1,1,1,1,3,0,0,0,0,0,0,0,0,0,0,0,0,0,3,1,1,1,1,1,1,1
1,1,2,2,2,2,2,2,2,15,0,0,15,0,0,0,15,0,0,15,2,2,2,2,2,2,2,1,1
1,1,2,24,0,0,0,0,0,0,0,0,0,0,0,0,0,0,0,0,0,0,0,0,0,23,2,1,1
1,1,2,24,0,0,0,0,0,0,0,0,0,0,0,0,0,0,0,0,0,0,0,0,0,23,2,1,1
1,1,2,24,0,0,0,0,0,0,0,0,0,0,0,0,0,0,0,0,0,0,0,0,0,23,2,1,1
1,1,2,2,2,2,2,2,2,15,0,0,15,0,0,0,15,0,0,15,2,2,2,2,2,2,2,1,1
1,1,1,1,1,1,1,3,0,0,0,0,0,0,0,0,0,0,0,0,0,3,2,2,2,2,2,1,1
1,1,1,1,1,1,1,3,0,0,0,0,0,0,0,0,0,0,0,0,0,3,2,2,2,2,2,1,1
1,1,2,2,2,2,2,2,2,15,0,0,15,0,0,0,15,0,0,15,2,2,2,2,2,2,2,1,1
1,1,2,10,10,10,2,2,2,2,0,0,2,0,0,0,2,0,0,2,2,2,2,10,10,10,2,1,1
1,1,2,10,10,10,2,2,2,2,3,3,2,0,0,0,2,3,3,2,2,2,2,10,10,10,2,1,1
1,1,2,10,10,10,2,2,2,2,1,1,2,0,0,0,2,1,1,2,2,2,2,10,10,10,2,1,1
1,1,2,10,10,10,10,10,10,2,1,1,2,0,0,0,2,1,1,2,10,10,10,10,10,10,2,1,1
1,1,2,10,10,10,10,10,10,2,1,1,2,0,0,0,2,1,1,2,10,10,10,10,10,10,2,1,1
1,1,2,10,10,10,10,10,10,2,1,1,2,25,25,25,2,1,1,2,10,10,10,10,10,10,2,1,1
1,1,2,2,2,2,2,2,2,2,1,1,2,2,2,2,2,1,1,2,2,2,2,2,2,2,2,1,1
1,1,1,1,1,1,1,1,1,1,1,1,1,1,1,1,1,1,1,1,1,1,1,1,1,1,1,1,1
1,1,1,1,1,1,1,1,1,1,1,1,1,1,1,1,1,1,1,1,1,1,1,1,1,1,1,1,1
endlayer

layer
1,1,1,1,1,1,1,1,1,1,1,1,1,1,1,1,1,1,1,1,1,1,1,1,1,1,1,1,1
1,1,1,1,1,1,1,1,1,1,1,1,1,1,1,1,1,1,1,1,1,1,1,1,1,1,1,1,1
1,1,1,1,1,1,1,1,1,1,1,1,1,1,1,1,1,1,1,1,1,1,1,1,1,1,1,1,1
1,1,1,1,1,1,1,1,1,1,1,1,2,2,2,2,2,1,1,1,1,1,1,1,1,1,1,1,1
1,1,1,1,1,1,1,1,1,1,1,1,2,22,22,22,2,1,1,1,1,1,1,1,1,1,1,1,1
1,1,1,1,1,1,1,1,1,1,1,1,2,0,0,0,2,1,1,1,1,1,1,1,1,1,1,1,1
1,1,1,1,1,1,1,1,1,1,1,1,2,0,0,0,2,1,1,1,1,1,1,1,1,1,1,1,1
1,1,1,1,1,1,1,1,1,2,22,22,2,0,0,0,2,22,22,2,1,1,1,1,1,1,1,1,1
1,1,1,1,1,1,1,1,1,2,0,0,2,0,0,0,2,0,0,2,1,1,1,1,1,1,1,1,1
1,1,1,1,1,1,1,2,2,10,0,0,10,0,0,0,10,0,0,10,2,2,1,1,1,1,1,1,1
1,1,1,1,1,1,1,24,0,0,0,0,0,0,0,0,0,0,0,0,0,23,1,1,1,1,1,1,1
1,1,1,1,1,1,1,24,0,0,0,0,0,0,0,0,0,0,0,0,0,23,1,1,1,1,1,1,1
1,1,1,2,2,2,2,2,2,10,0,0,10,0,0,0,10,0,0,10,2,2,2,2,2,2,1,1,1
1,1,1,2,24,0,0,0,0,0,0,0,0,0,0,0,0,0,0,0,0,0,0,0,23,2,1,1,1
1,1,1,2,24,0,0,0,0,0,0,0,0,0,0,0,0,0,0,0,0,0,0,0,23,2,1,1,1
1,1,1,2,24,0,0,0,0,0,0,0,0,0,0,0,0,0,0,0,0,0,0,0,23,2,1,1,1
1,1,1,2,2,2,2,2,2,10,0,0,10,0,0,0,10,0,0,10,2,2,2,2,2,2,1,1,1
1,1,1,1,1,1,1,24,0,0,0,0,0,0,0,0,0,0,0,0,0,23,1,1,1,1,1,1,1
1,1,1,1,1,1,1,24,0,0,0,0,0,0,0,0,0,0,0,0,0,23,1,1,1,1,1,1,1
1,1,1,1,1,1,1,2,2,10,0,0,10,0,0,0,10,0,0,10,2,2,1,1,1,1,1,1,1
1,1,1,1,1,1,1,1,1,2,0,0,2,0,0,0,2,0,0,2,1,1,1,1,1,1,1,1,1
1,1,1,1,1,1,1,1,1,2,25,25,2,0,0,0,2,25,25,2,1,1,1,1,1,1,1,1,1
1,1,1,1,1,1,1,1,1,1,1,1,2,0,0,0,2,1,1,1,1,1,1,1,1,1,1,1,1
1,1,1,1,1,1,1,1,1,1,1,1,2,0,0,0,2,1,1,1,1,1,1,1,1,1,1,1,1
1,1,1,1,1,1,1,1,1,1,1,1,2,25,25,25,2,1,1,1,1,1,1,1,1,1,1,1,1
1,1,1,1,1,1,1,1,1,1,1,1,2,2,2,2,2,1,1,1,1,1,1,1,1,1,1,1,1
1,1,1,1,1,1,1,1,1,1,1,1,1,1,1,1,1,1,1,1,1,1,1,1,1,1,1,1,1
1,1,1,1,1,1,1,1,1,1,1,1,1,1,1,1,1,1,1,1,1,1,1,1,1,1,1,1,1
1,1,1,1,1,1,1,1,1,1,1,1,1,1,1,1,1,1,1,1,1,1,1,1,1,1,1,1,1
endlayer

layer
1,1,1,1,1,1,1,1,1,1,1,1,1,1,1,1,1,1,1,1,1,1,1,1,1,1,1,1,1
1,1,1,1,1,1,1,1,1,1,1,1,1,1,1,1,1,1,1,1,1,1,1,1,1,1,1,1,1
1,1,1,1,1,1,1,1,1,1,1,1,1,1,1,1,1,1,1,1,1,1,1,1,1,1,1,1,1
1,1,1,1,1,1,1,1,1,1,1,1,1,1,1,1,1,1,1,1,1,1,1,1,1,1,1,1,1
1,1,1,1,1,1,1,1,1,1,1,1,2,2,2,2,2,1,1,1,1,1,1,1,1,1,1,1,1
1,1,1,1,1,1,1,1,1,1,1,1,2,2,2,2,2,1,1,1,1,1,1,1,1,1,1,1,1
1,1,1,1,1,1,1,1,1,1,1,1,2,2,2,2,2,1,1,1,1,1,1,1,1,1,1,1,1
1,1,1,1,1,1,1,1,1,1,1,1,2,2,2,2,2,1,1,1,1,1,1,1,1,1,1,1,1
1,1,1,1,1,1,1,1,1,2,2,2,2,0,0,0,2,2,2,2,1,1,1,1,1,1,1,1,1
1,1,1,1,1,1,1,1,2,2,0,0,26,0,0,0,26,0,0,2,2,1,1,1,1,1,1,1,1
1,1,1,1,1,1,1,1,2,0,0,0,0,0,0,0,0,0,0,0,2,1,1,1,1,1,1,1,1
1,1,1,1,1,1,1,1,2,0,0,0,0,0,0,0,0,0,0,0,2,1,1,1,1,1,1,1,1
1,1,1,1,2,2,2,2,2,26,0,0,26,0,0,0,26,0,0,26,2,2,2,2,2,1,1,1,1
1,1,1,1,2,2,2,2,0,0,0,0,0,0,0,0,0,0,0,0,0,2,2,2,2,1,1,1,1
1,1,1,1,2,2,2,2,0,0,0,0,0,0,0,0,0,0,0,0,0,2,2,2,2,1,1,1,1
1,1,1,1,2,2,2,2,0,0,0,0,0,0,0,0,0,0,0,0,0,2,2,2,2,1,1,1,1
1,1,1,1,2,2,2,2,2,26,0,0,26,0,0,0,26,0,0,26,2,2,2,2,2,1,1,1,1
1,1,1,1,1,1,1,1,2,0,0,0,0,0,0,0,0,0,0,0,2,1,1,1,1,1,1,1,1
1,1,1,1,1,1,1,1,2,0,0,0,0,0,0,0,0,0,0,0,2,1,1,1,1,1,1,1,1
1,1,1,1,1,1,1,1,2,2,0,0,26,0,0,0,26,0,0,2,2,1,1,1,1,1,1,1,1
1,1,1,1,1,1,1,1,1,2,2,2,2,0,0,0,2,2,2,2,1,1,1,1,1,1,1,1,1
1,1,1,1,1,1,1,1,1,1,1,1,2,2,2,2,2,1,1,1,1,1,1,1,1,1,1,1,1
1,1,1,1,1,1,1,1,1,1,1,1,2,2,2,2,2,1,1,1,1,1,1,1,1,1,1,1,1
1,1,1,1,1,1,1,1,1,1,1,1,2,2,2,2,2,1,1,1,1,1,1,1,1,1,1,1,1
1,1,1,1,1,1,1,1,1,1,1,1,2,2,2,2,2,1,1,1,1,1,1,1,1,1,1,1,1
1,1,1,1,1,1,1,1,1,1,1,1,1,1,1,1,1,1,1,1,1,1,1,1,1,1,1,1,1
1,1,1,1,1,1,1,1,1,1,1,1,1,1,1,1,1,1,1,1,1,1,1,1,1,1,1,1,1
1,1,1,1,1,1,1,1,1,1,1,1,1,1,1,1,1,1,1,1,1,1,1,1,1,1,1,1,1
1,1,1,1,1,1,1,1,1,1,1,1,1,1,1,1,1,1,1,1,1,1,1,1,1,1,1,1,1
endlayer

