
# Created by Ruins mod version 16.7 Ingame Parser
# authoring Player: lafuller

weight=1
embed_into_distance=16
acceptable_target_blocks=
unacceptable_target_blocks=flowing_water,water,flowing_lava,lava
dimensions=16,29,29
allowable_overhang=0
max_leveling=16
leveling_buffer=-1
preserve_water=0
preserve_lava=0

rule1=0,100,preserveBlock
rule2=0,100,minecraft:sandstone-0
rule3=0,100,prismarine-0,prismarine-0,prismarine-1
rule4=0,100,minecraft:water-0
rule5=0,100,minecraft:sandstone_stairs-3
rule6=0,100,minecraft:stone_slab-1
rule7=0,100,minecraft:sandstone_stairs-2
rule8=0,100,minecraft:sandstone_stairs-1
rule9=0,100,minecraft:sandstone-2
rule10=0,100,minecraft:double_stone_slab-9
rule11=0,100,minecraft:sandstone_stairs-0
rule12=0,100,ChestGenHook:chests/desert_pyramid:5-5
rule13=0,100,ChestGenHook:chests/desert_pyramid:5-4
rule14=0,100,minecraft:sandstone-1
rule15=0,100,minecraft:sandstone_stairs-7
rule16=0,100,minecraft:stone_slab-9
rule17=0,100,minecraft:sandstone_stairs-6
rule18=0,100,minecraft:sandstone_stairs-4
rule19=0,100,minecraft:sandstone_stairs-5

layer
1,1,1,1,1,1,1,1,1,1,1,1,1,1,1,1,1,1,1,1,1,1,1,1,1,1,1,1,1
1,1,1,1,1,1,1,1,1,1,1,1,1,1,1,1,1,1,1,1,1,1,1,1,1,1,1,1,1
1,1,1,1,1,1,1,1,1,1,1,1,1,1,1,1,1,1,1,1,1,1,1,1,1,1,1,1,1
1,1,1,1,1,1,1,1,1,1,1,1,1,1,1,1,1,1,1,1,1,1,1,1,1,1,1,1,1
1,1,1,1,1,1,1,1,1,1,1,1,1,1,1,1,1,1,1,1,1,1,1,1,1,1,1,1,1
1,1,1,1,1,1,1,1,1,1,1,1,1,1,1,1,1,1,1,1,1,1,1,1,1,1,1,1,1
1,1,1,1,1,1,1,1,1,1,1,1,1,1,1,1,1,1,1,1,1,1,1,1,1,1,1,1,1
1,1,1,1,1,1,1,1,1,1,1,1,1,1,1,1,1,1,1,1,1,1,1,1,1,1,1,1,1
1,1,1,1,1,1,1,1,1,1,1,1,1,1,1,1,1,1,1,1,1,1,1,1,1,1,1,1,1
1,1,1,1,1,1,1,1,1,1,1,1,1,1,1,1,1,1,1,1,1,1,1,1,1,1,1,1,1
1,1,1,1,1,1,1,1,1,1,1,1,1,1,1,1,1,1,1,1,1,1,1,1,1,1,1,1,1
1,1,1,1,1,1,1,1,1,1,1,2,2,2,2,2,2,2,1,1,1,1,1,1,1,1,1,1,1
1,1,1,1,1,1,1,1,1,1,1,2,2,2,2,2,2,2,1,1,1,1,1,1,1,1,1,1,1
1,1,1,1,1,1,1,1,1,1,1,2,2,2,2,2,2,2,1,1,1,1,1,1,1,1,1,1,1
1,1,1,1,1,1,1,1,1,1,1,2,2,2,2,2,2,2,1,1,1,1,1,1,1,1,1,1,1
1,1,1,1,1,1,1,1,1,1,1,2,2,2,2,2,2,2,1,1,1,1,1,1,1,1,1,1,1
1,1,1,1,1,1,1,1,1,1,1,2,2,2,2,2,2,2,1,1,1,1,1,1,1,1,1,1,1
1,1,1,1,1,1,1,1,1,1,1,2,2,2,2,2,2,2,1,1,1,1,1,1,1,1,1,1,1
1,1,1,1,1,1,1,1,1,1,1,1,1,1,1,1,1,1,1,1,1,1,1,1,1,1,1,1,1
1,1,1,1,1,1,1,1,1,1,1,1,1,1,1,1,1,1,1,1,1,1,1,1,1,1,1,1,1
1,1,1,1,1,1,1,1,1,1,1,1,1,1,1,1,1,1,1,1,1,1,1,1,1,1,1,1,1
1,1,1,1,1,1,1,1,1,1,1,1,1,1,1,1,1,1,1,1,1,1,1,1,1,1,1,1,1
1,1,1,1,1,1,1,1,1,1,1,1,1,1,1,1,1,1,1,1,1,1,1,1,1,1,1,1,1
1,1,1,1,1,1,1,1,1,1,1,1,1,1,1,1,1,1,1,1,1,1,1,1,1,1,1,1,1
1,1,1,1,1,1,1,1,1,1,1,1,1,1,1,1,1,1,1,1,1,1,1,1,1,1,1,1,1
1,1,1,1,1,1,1,1,1,1,1,1,1,1,1,1,1,1,1,1,1,1,1,1,1,1,1,1,1
1,1,1,1,1,1,1,1,1,1,1,1,1,1,1,1,1,1,1,1,1,1,1,1,1,1,1,1,1
1,1,1,1,1,1,1,1,1,1,1,1,1,1,1,1,1,1,1,1,1,1,1,1,1,1,1,1,1
1,1,1,1,1,1,1,1,1,1,1,1,1,1,1,1,1,1,1,1,1,1,1,1,1,1,1,1,1
endlayer

layer
1,1,1,1,1,1,1,1,1,1,1,1,1,1,1,1,1,1,1,1,1,1,1,1,1,1,1,1,1
1,1,1,1,1,1,1,1,1,1,1,1,1,1,1,1,1,1,1,1,1,1,1,1,1,1,1,1,1
1,1,1,1,1,1,1,1,1,1,1,1,1,1,1,1,1,1,1,1,1,1,1,1,1,1,1,1,1
1,1,1,1,1,1,1,1,1,1,1,1,1,1,1,1,1,1,1,1,1,1,1,1,1,1,1,1,1
1,1,1,1,1,1,1,1,1,1,1,1,1,1,1,1,1,1,1,1,1,1,1,1,1,1,1,1,1
1,1,1,1,1,1,1,1,1,1,1,1,1,1,1,1,1,1,1,1,1,1,1,1,1,1,1,1,1
1,1,1,1,1,1,1,1,1,1,1,1,1,1,1,1,1,1,1,1,1,1,1,1,1,1,1,1,1
1,1,1,1,1,1,1,1,1,1,1,1,1,1,1,1,1,1,1,1,1,1,1,1,1,1,1,1,1
1,1,1,1,1,1,1,1,1,1,1,1,1,1,1,1,1,1,1,1,1,1,1,1,1,1,1,1,1
1,1,1,1,1,1,1,1,1,1,1,1,1,1,1,1,1,1,1,1,1,1,1,1,1,1,1,1,1
1,1,1,1,1,1,1,1,1,1,1,1,1,1,1,1,1,1,1,1,1,1,1,1,1,1,1,1,1
1,1,1,1,1,1,1,1,1,1,1,2,2,2,2,2,2,2,1,1,1,1,1,1,1,1,1,1,1
1,1,1,1,1,1,1,1,1,1,1,2,3,3,3,3,3,2,1,1,1,1,1,1,1,1,1,1,1
1,1,1,1,1,1,1,1,1,1,1,2,3,3,3,3,3,2,1,1,1,1,1,1,1,1,1,1,1
1,1,1,1,1,1,1,1,1,1,1,2,3,3,3,3,3,2,1,1,1,1,1,1,1,1,1,1,1
1,1,1,1,1,1,1,1,1,1,1,2,3,3,3,3,3,2,1,1,1,1,1,1,1,1,1,1,1
1,1,1,1,1,1,1,1,1,1,1,2,3,3,3,3,3,2,1,1,1,1,1,1,1,1,1,1,1
1,1,1,1,1,1,1,1,1,1,1,2,2,2,2,2,2,2,1,1,1,1,1,1,1,1,1,1,1
1,1,1,1,1,1,1,1,1,1,1,1,1,1,1,1,1,1,1,1,1,1,1,1,1,1,1,1,1
1,1,1,1,1,1,1,1,1,1,1,1,1,1,1,1,1,1,1,1,1,1,1,1,1,1,1,1,1
1,1,1,1,1,1,1,1,1,1,1,1,1,1,1,1,1,1,1,1,1,1,1,1,1,1,1,1,1
1,1,1,1,1,1,1,1,1,1,1,1,1,1,1,1,1,1,1,1,1,1,1,1,1,1,1,1,1
1,1,1,1,1,1,1,1,1,1,1,1,1,1,1,1,1,1,1,1,1,1,1,1,1,1,1,1,1
1,1,1,1,1,1,1,1,1,1,1,1,1,1,1,1,1,1,1,1,1,1,1,1,1,1,1,1,1
1,1,1,1,1,1,1,1,1,1,1,1,1,1,1,1,1,1,1,1,1,1,1,1,1,1,1,1,1
1,1,1,1,1,1,1,1,1,1,1,1,1,1,1,1,1,1,1,1,1,1,1,1,1,1,1,1,1
1,1,1,1,1,1,1,1,1,1,1,1,1,1,1,1,1,1,1,1,1,1,1,1,1,1,1,1,1
1,1,1,1,1,1,1,1,1,1,1,1,1,1,1,1,1,1,1,1,1,1,1,1,1,1,1,1,1
1,1,1,1,1,1,1,1,1,1,1,1,1,1,1,1,1,1,1,1,1,1,1,1,1,1,1,1,1
endlayer

layer
1,1,1,1,1,1,1,1,1,1,1,1,1,1,1,1,1,1,1,1,1,1,1,1,1,1,1,1,1
1,1,1,1,1,1,1,1,1,1,1,1,1,1,1,1,1,1,1,1,1,1,1,1,1,1,1,1,1
1,1,1,1,1,1,1,1,1,1,1,1,1,1,1,1,1,1,1,1,1,1,1,1,1,1,1,1,1
1,1,1,1,1,1,1,1,1,1,1,1,1,1,1,1,1,1,1,1,1,1,1,1,1,1,1,1,1
1,1,1,1,1,1,1,1,1,1,1,1,1,1,1,1,1,1,1,1,1,1,1,1,1,1,1,1,1
1,1,1,1,1,1,1,1,1,1,2,2,1,1,1,1,1,2,2,1,1,1,1,1,1,1,1,1,1
1,1,1,1,1,1,1,1,1,1,2,2,2,2,2,2,2,2,2,1,1,1,1,1,1,1,1,1,1
1,1,1,1,1,1,1,1,1,1,2,2,2,2,2,2,2,2,2,1,1,1,1,1,1,1,1,1,1
1,1,1,1,1,1,1,1,1,1,2,2,2,2,2,2,2,2,2,1,1,1,1,1,1,1,1,1,1
1,1,1,1,1,1,1,1,1,1,2,2,2,2,2,2,2,2,2,1,1,1,1,1,1,1,1,1,1
1,1,2,2,2,2,2,2,2,2,2,2,2,2,2,2,2,2,2,2,2,2,2,2,1,1,1,1,1
1,1,2,2,2,2,2,2,2,2,2,2,2,2,2,2,2,2,2,2,2,2,2,2,1,1,1,1,1
1,1,2,2,2,2,2,2,2,2,2,2,4,4,4,4,4,2,2,2,2,2,2,1,1,1,1,1,1
1,1,2,2,2,2,2,2,2,2,2,2,4,4,4,4,4,2,2,2,2,2,2,1,1,1,1,1,1
1,1,2,2,2,2,2,2,2,2,2,2,4,4,4,4,4,2,2,2,2,2,2,1,1,1,1,1,1
1,1,2,2,2,2,2,2,2,2,2,2,4,4,4,4,4,2,2,2,2,2,2,1,1,1,1,1,1
1,1,2,2,2,2,2,2,2,2,2,2,4,4,4,4,4,2,2,2,2,2,2,1,1,1,1,1,1
1,1,2,2,2,2,2,2,2,2,2,2,2,2,2,2,2,2,2,2,2,2,2,2,1,1,1,1,1
1,1,0,0,0,2,2,2,2,2,2,2,2,2,2,2,2,2,2,2,2,2,2,2,1,1,1,1,1
1,1,1,1,1,1,1,1,1,1,2,2,2,2,2,2,2,2,2,1,1,1,1,1,1,1,1,1,1
1,1,1,1,1,1,1,1,1,1,2,2,2,2,2,2,2,2,2,1,1,1,1,1,1,1,1,1,1
1,1,1,1,1,1,1,1,1,1,2,2,2,2,2,2,2,2,2,1,1,1,1,1,1,1,1,1,1
1,1,1,1,1,1,1,1,1,1,2,2,2,2,2,2,2,2,2,1,1,1,1,1,1,1,1,1,1
1,1,1,1,1,1,1,1,1,1,2,2,1,1,1,1,1,2,2,1,1,1,1,1,1,1,1,1,1
1,1,1,1,1,1,1,1,1,1,1,1,1,1,1,1,1,1,1,1,1,1,1,1,1,1,1,1,1
1,1,1,1,1,1,1,1,1,1,1,1,1,1,1,1,1,1,1,1,1,1,1,1,1,1,1,1,1
1,1,1,1,1,1,1,1,1,1,1,1,1,1,1,1,1,1,1,1,1,1,1,1,1,1,1,1,1
1,1,1,1,1,1,1,1,1,1,1,1,1,1,1,1,1,1,1,1,1,1,1,1,1,1,1,1,1
1,1,1,1,1,1,1,1,1,1,1,1,1,1,1,1,1,1,1,1,1,1,1,1,1,1,1,1,1
endlayer

layer
1,1,1,1,1,1,1,1,1,1,1,1,1,1,1,1,1,1,1,1,1,1,1,1,1,1,1,1,1
1,1,1,1,1,1,1,1,1,1,1,1,1,1,1,1,1,1,1,1,1,1,1,1,1,1,1,1,1
1,1,1,1,1,1,1,1,1,1,1,1,1,1,1,1,1,1,1,1,1,1,1,1,1,1,1,1,1
1,1,1,1,1,1,1,1,1,1,1,1,1,1,1,1,1,1,1,1,1,1,1,1,1,1,1,1,1
1,1,1,1,1,1,1,1,1,1,1,1,1,2,2,2,1,1,1,1,1,1,1,1,1,1,1,1,1
1,1,1,1,1,1,1,1,1,1,2,2,2,2,2,2,2,2,2,1,1,1,1,1,1,1,1,1,1
1,2,2,2,2,2,2,2,2,2,2,2,2,2,2,2,2,2,2,2,2,2,2,1,1,1,1,1,1
1,2,2,2,2,2,2,2,2,2,7,6,0,0,0,0,0,6,5,2,2,2,2,1,1,1,1,1,1
1,2,2,2,2,2,2,2,2,2,7,6,0,0,0,0,0,6,5,2,2,2,2,1,1,1,1,1,1
1,2,2,2,2,2,2,2,2,2,7,6,0,0,0,0,0,6,5,2,2,2,2,1,1,1,1,1,1
1,2,8,8,8,2,2,8,8,8,9,9,0,0,0,0,0,9,9,8,8,8,2,2,1,1,1,1,1
10,10,6,6,6,2,2,6,6,6,9,9,0,0,0,0,0,9,9,6,6,6,2,2,1,1,1,1,1
10,10,6,6,6,6,0,0,0,0,0,0,0,0,0,0,0,0,0,0,0,0,0,2,1,1,1,1,1
10,10,6,6,6,6,0,0,0,0,0,0,0,0,0,0,0,0,0,0,0,0,0,2,2,1,1,1,1
10,10,6,6,6,6,0,0,0,0,0,0,0,0,0,0,0,0,0,0,0,0,0,2,2,1,1,1,1
10,10,6,6,6,6,0,0,0,0,0,0,0,0,0,0,0,0,0,0,0,0,0,2,2,1,1,1,1
10,10,6,6,6,6,0,0,0,0,0,0,0,0,0,0,0,0,0,0,0,0,0,2,1,1,1,1,1
10,10,6,6,6,2,2,6,6,6,9,9,0,0,0,0,0,9,9,6,6,6,2,2,1,1,1,1,1
1,2,11,11,11,2,2,11,11,11,9,9,0,0,0,0,0,9,9,11,11,11,2,2,1,1,1,1,1
1,2,2,2,2,2,2,2,2,2,7,6,0,0,0,0,0,6,5,2,2,2,2,1,1,1,1,1,1
1,2,2,2,2,2,2,2,2,2,7,6,0,0,0,0,0,6,5,2,2,2,2,1,1,1,1,1,1
1,2,2,2,2,2,2,2,2,2,7,6,0,0,0,0,0,6,5,2,2,2,2,1,1,1,1,1,1
1,2,2,2,2,2,2,2,2,2,2,2,2,2,2,2,2,2,2,2,2,2,2,1,1,1,1,1,1
1,1,1,1,1,1,1,1,1,1,2,2,2,2,2,2,2,2,2,1,1,1,1,1,1,1,1,1,1
1,1,1,1,1,1,1,1,1,1,1,1,1,2,2,2,1,1,1,1,1,1,1,1,1,1,1,1,1
1,1,1,1,1,1,1,1,1,1,1,1,1,1,1,1,1,1,1,1,1,1,1,1,1,1,1,1,1
1,1,1,1,1,1,1,1,1,1,1,1,1,1,1,1,1,1,1,1,1,1,1,1,1,1,1,1,1
1,1,1,1,1,1,1,1,1,1,1,1,1,1,1,1,1,1,1,1,1,1,1,1,1,1,1,1,1
1,1,1,1,1,1,1,1,1,1,1,1,1,1,1,1,1,1,1,1,1,1,1,1,1,1,1,1,1
endlayer

layer
1,1,1,1,1,1,1,1,1,1,1,1,1,1,1,1,1,1,1,1,1,1,1,1,1,1,1,1,1
1,1,1,1,1,1,1,1,1,1,1,1,1,1,1,1,1,1,1,1,1,1,1,1,1,1,1,1,1
1,1,1,1,1,1,1,1,1,1,1,1,1,1,1,1,1,1,1,1,1,1,1,1,1,1,1,1,1
1,1,1,1,1,1,1,1,1,1,1,1,1,1,1,1,1,1,1,1,1,1,1,1,1,1,1,1,1
1,1,1,1,1,1,1,1,1,1,1,1,1,10,10,10,1,1,1,1,1,1,1,1,1,1,1,1,1
1,1,2,2,2,2,1,1,1,1,9,2,10,0,12,0,10,2,9,1,1,1,1,1,1,1,1,1,1
1,2,8,8,8,9,9,8,8,8,10,10,0,0,0,0,0,10,10,8,8,8,9,1,1,1,1,1,1
1,2,0,0,0,9,9,0,0,0,0,0,0,0,0,0,0,0,0,0,0,0,9,1,1,1,1,1,1
1,2,0,0,0,0,0,0,0,0,0,0,0,0,0,0,0,0,0,0,0,0,0,10,1,1,1,1,1
1,2,0,0,0,0,0,0,0,0,0,0,0,0,0,0,0,0,0,0,0,0,0,10,1,1,1,1,1
1,2,0,0,0,9,10,0,0,0,10,10,0,0,0,0,0,10,10,0,0,0,10,9,10,10,10,1,1
10,10,0,0,0,2,10,0,0,0,10,10,0,0,0,0,0,10,10,0,0,0,10,2,10,10,10,1,1
10,0,0,0,0,0,0,0,0,0,0,0,0,0,0,0,0,0,0,0,0,0,0,10,10,10,10,1,1
10,0,0,0,0,0,0,0,0,0,0,0,0,0,0,0,0,0,0,0,0,0,0,10,10,10,10,1,1
10,0,0,0,0,0,0,0,0,0,0,0,0,0,0,0,0,0,0,0,0,0,0,10,10,10,10,1,1
10,0,0,0,0,0,0,0,0,0,0,0,0,0,0,0,0,0,0,0,0,0,0,10,10,10,10,1,1
10,0,0,0,0,0,0,0,0,0,0,0,0,0,0,0,0,0,0,0,0,0,0,10,10,10,10,1,1
10,10,0,0,0,2,10,0,0,0,10,10,0,0,0,0,0,10,10,0,0,0,10,2,10,10,10,1,1
1,2,0,0,0,9,10,0,0,0,10,10,0,0,0,0,0,10,10,0,0,0,10,9,10,10,10,1,1
1,2,0,0,0,0,0,0,0,0,0,0,0,0,0,0,0,0,0,0,0,0,0,10,1,1,1,1,1
1,2,0,0,0,0,0,0,0,0,0,0,0,0,0,0,0,0,0,0,0,0,0,10,1,1,1,1,1
1,2,0,0,0,9,9,0,0,0,0,0,0,0,0,0,0,0,0,0,0,0,9,1,1,1,1,1,1
1,2,11,11,11,9,9,11,11,11,10,10,0,0,0,0,0,10,10,11,11,11,9,1,1,1,1,1,1
1,1,1,1,1,1,1,1,1,1,9,2,10,0,13,0,10,2,9,1,1,1,1,1,1,1,1,1,1
1,1,1,1,1,1,1,1,1,1,1,1,1,10,10,10,1,1,1,1,1,1,1,1,1,1,1,1,1
1,1,1,1,1,1,1,1,1,1,1,1,1,1,1,1,1,1,1,1,1,1,1,1,1,1,1,1,1
1,1,1,1,1,1,1,1,1,1,1,1,1,1,1,1,1,1,1,1,1,1,1,1,1,1,1,1,1
1,1,1,1,1,1,1,1,1,1,1,1,1,1,1,1,1,1,1,1,1,1,1,1,1,1,1,1,1
1,1,1,1,1,1,1,1,1,1,1,1,1,1,1,1,1,1,1,1,1,1,1,1,1,1,1,1,1
endlayer

layer
2,2,2,2,2,2,2,2,2,2,2,1,1,1,1,1,1,1,2,2,2,2,2,2,2,2,2,2,2
2,2,2,2,2,2,2,2,2,2,2,1,1,1,1,1,1,1,2,2,2,2,2,2,2,2,2,2,2
2,2,2,2,2,2,2,2,2,2,2,2,1,1,1,1,1,2,2,2,2,2,2,2,2,2,2,2,2
2,2,2,2,2,2,2,2,2,2,2,2,1,1,1,1,1,2,2,2,2,2,2,2,2,2,2,2,2
2,2,2,2,2,2,2,2,2,2,2,2,1,10,10,10,1,2,2,2,2,2,2,2,2,2,2,2,2
2,2,8,8,8,2,2,8,8,8,9,2,10,0,0,0,10,2,9,8,8,8,2,2,2,2,2,2,2
2,2,0,0,0,9,9,0,0,0,10,10,0,0,0,0,0,10,10,0,0,0,9,2,2,2,2,2,2
2,2,0,0,0,9,9,0,0,0,0,0,0,0,0,0,0,0,0,0,0,0,9,2,2,2,2,2,2
2,2,0,0,0,0,0,0,0,0,0,0,0,0,0,0,0,0,0,0,0,0,0,10,2,2,2,2,2
2,2,0,0,0,0,0,0,0,0,0,0,0,0,0,0,0,0,0,0,0,0,0,10,2,2,2,2,2
2,2,0,0,0,10,10,0,0,0,10,10,0,0,0,0,0,10,10,0,0,0,10,9,8,8,8,2,2
10,10,0,0,0,10,10,0,0,0,10,10,0,0,0,0,0,10,10,0,0,0,10,2,0,0,0,10,10
10,0,0,0,0,0,0,0,0,0,0,0,0,0,0,0,0,0,0,0,0,0,0,5,0,0,0,10,10
10,0,0,0,0,0,0,0,0,0,0,0,0,0,0,0,0,0,0,0,0,0,0,5,0,0,0,10,10
10,0,0,0,0,0,0,0,0,0,0,0,0,0,0,0,0,0,0,0,0,0,0,5,0,0,0,10,10
10,0,0,0,0,0,0,0,0,0,0,0,0,0,0,0,0,0,0,0,0,0,0,5,0,0,0,10,10
10,0,0,0,0,0,0,0,0,0,0,0,0,0,0,0,0,0,0,0,0,0,0,5,0,0,0,10,10
10,10,0,0,0,10,10,0,0,0,10,10,0,0,0,0,0,10,10,0,0,0,10,2,0,0,0,10,10
2,2,0,0,0,10,10,0,0,0,10,10,0,0,0,0,0,10,10,0,0,0,10,9,11,11,11,2,2
2,2,0,0,0,0,0,0,0,0,0,0,0,0,0,0,0,0,0,0,0,0,0,10,2,2,2,2,2
2,2,0,0,0,0,0,0,0,0,0,0,0,0,0,0,0,0,0,0,0,0,0,10,2,2,2,2,2
2,2,0,0,0,9,9,0,0,0,0,0,0,0,0,0,0,0,0,0,0,0,9,2,2,2,2,2,2
2,2,0,0,0,9,9,0,0,0,10,10,0,0,0,0,0,10,10,0,0,0,9,2,2,2,2,2,2
2,2,11,11,11,2,2,11,11,11,9,2,10,0,0,0,10,2,9,11,11,11,2,2,2,2,2,2,2
2,2,2,2,2,2,2,2,2,2,2,2,1,10,10,10,1,2,2,2,2,2,2,2,2,2,2,2,2
2,2,2,2,2,2,2,2,2,2,2,2,1,1,1,1,1,2,2,2,2,2,2,2,2,2,2,2,2
2,2,2,2,2,2,2,2,2,2,2,2,1,1,1,1,1,2,2,2,2,2,2,2,2,2,2,2,2
2,2,2,2,2,2,2,2,2,2,2,1,1,1,1,1,1,1,2,2,2,2,2,2,2,2,2,2,2
2,2,2,2,2,2,2,2,2,2,2,1,1,1,1,1,1,1,2,2,2,2,2,2,2,2,2,2,2
endlayer

layer
2,2,2,2,2,2,2,2,2,2,2,1,1,1,1,1,1,1,2,2,2,2,2,2,2,2,2,2,2
2,9,0,0,0,9,9,0,0,0,2,1,1,1,1,1,1,1,2,0,0,0,9,9,0,0,0,9,2
2,0,0,0,0,0,0,0,0,0,11,2,1,1,1,1,1,2,11,0,0,0,0,0,0,0,0,0,2
2,0,0,0,0,0,0,0,0,0,5,2,1,1,1,1,1,2,7,0,0,0,0,0,0,0,0,0,2
2,0,0,0,0,0,0,0,0,0,5,2,1,10,10,10,1,2,7,0,0,0,0,0,0,0,0,0,2
2,0,0,0,0,0,0,0,0,0,8,2,10,0,0,0,10,2,10,0,0,0,0,0,0,0,0,0,2
2,9,0,0,0,10,10,0,0,0,10,10,0,0,0,0,0,10,10,0,0,0,10,10,0,0,0,9,2
2,9,0,0,0,10,10,0,0,0,0,0,0,0,0,0,0,0,0,0,0,0,10,10,0,0,0,9,2
2,0,0,0,0,0,0,0,0,0,0,0,0,0,0,0,0,0,0,0,0,0,0,0,0,0,0,0,2
2,0,0,0,0,0,0,0,0,0,0,0,0,0,0,0,0,0,0,0,0,0,0,0,0,0,0,0,2
2,2,0,0,0,10,10,0,0,0,10,10,0,0,0,0,0,10,10,0,0,0,10,10,0,0,0,10,2
10,10,0,0,0,10,10,0,0,0,10,10,0,0,0,0,0,10,10,0,0,0,10,10,0,0,0,10,10
10,0,0,0,0,0,0,0,0,0,0,0,0,0,0,0,0,0,0,0,0,0,0,0,0,0,0,0,10
10,0,0,0,0,0,0,0,0,0,0,0,0,0,0,0,0,0,0,0,0,0,0,0,0,0,0,0,10
10,0,0,0,0,0,0,0,0,0,0,0,0,0,0,0,0,0,0,0,0,0,0,0,0,0,0,0,10
10,0,0,0,0,0,0,0,0,0,0,0,0,0,0,0,0,0,0,0,0,0,0,0,0,0,0,0,10
10,0,0,0,0,0,0,0,0,0,0,0,0,0,0,0,0,0,0,0,0,0,0,0,0,0,0,0,10
10,10,0,0,0,10,10,0,0,0,10,10,0,0,0,0,0,10,10,0,0,0,10,10,0,0,0,10,10
2,2,0,0,0,10,10,0,0,0,10,10,0,0,0,0,0,10,10,0,0,0,10,10,0,0,0,10,2
2,0,0,0,0,0,0,0,0,0,0,0,0,0,0,0,0,0,0,0,0,0,0,0,0,0,0,0,2
2,0,0,0,0,0,0,0,0,0,0,0,0,0,0,0,0,0,0,0,0,0,0,0,0,0,0,0,2
2,9,0,0,0,10,10,0,0,0,0,0,0,0,0,0,0,0,0,0,0,0,10,10,0,0,0,9,2
2,9,0,0,0,10,10,0,0,0,10,10,0,0,0,0,0,10,10,0,0,0,10,10,0,0,0,9,2
2,0,0,0,0,0,0,0,0,0,11,2,10,0,0,0,10,2,10,0,0,0,0,0,0,0,0,0,2
2,0,0,0,0,0,0,0,0,0,5,2,1,10,10,10,1,2,7,0,0,0,0,0,0,0,0,0,2
2,0,0,0,0,0,0,0,0,0,5,2,1,1,1,1,1,2,7,0,0,0,0,0,0,0,0,0,2
2,0,0,0,0,0,0,0,0,0,8,2,1,1,1,1,1,2,8,0,0,0,0,0,0,0,0,0,2
2,9,0,0,0,9,9,0,0,0,2,1,1,1,1,1,1,1,2,0,0,0,9,9,0,0,0,9,2
2,2,2,2,2,2,2,2,2,2,2,1,1,1,1,1,1,1,2,2,2,2,2,2,2,2,2,2,2
endlayer

layer
2,2,2,2,2,2,2,2,2,2,2,1,1,1,1,1,1,1,2,2,2,2,2,2,2,2,2,2,2
2,10,0,0,0,10,10,0,0,0,2,1,1,1,1,1,1,1,2,0,0,0,10,10,0,0,0,10,2
2,0,0,0,0,0,0,0,0,0,0,2,1,1,1,1,1,2,0,0,0,0,0,0,0,0,0,0,2
2,0,0,0,0,0,0,0,0,0,0,5,1,1,1,1,1,7,0,0,0,0,0,0,0,0,0,0,2
2,0,0,0,0,0,0,0,0,0,0,5,1,10,10,10,1,7,0,0,0,0,0,0,0,0,0,0,2
2,0,0,0,0,0,0,0,0,0,0,2,10,0,0,0,10,2,10,0,0,0,0,0,0,0,0,0,2
2,10,0,0,0,10,10,0,0,0,10,10,0,0,0,0,0,10,10,0,0,0,10,10,0,0,0,10,2
2,10,0,0,0,10,10,0,0,0,0,0,0,0,0,0,0,0,0,0,0,0,10,10,0,0,0,10,2
2,0,0,0,0,0,0,0,0,0,0,0,0,0,0,0,0,0,0,0,0,0,0,0,0,0,0,0,2
2,0,0,0,0,0,0,0,0,0,0,0,0,0,0,0,0,0,0,0,0,0,0,0,0,0,0,0,2
2,2,0,0,0,10,10,0,0,0,10,10,0,0,0,0,0,10,10,0,0,0,10,10,0,0,0,10,2
10,10,0,0,0,10,10,0,0,0,10,10,0,0,0,0,0,10,10,0,0,0,10,10,0,0,0,10,10
10,0,0,0,0,0,0,0,0,0,0,0,0,0,0,0,0,0,0,0,0,0,0,0,0,0,0,0,10
10,0,0,0,0,0,0,0,0,0,0,0,0,0,0,0,0,0,0,0,0,0,0,0,0,0,0,0,10
10,0,0,0,0,0,0,0,0,0,0,0,0,0,0,0,0,0,0,0,0,0,0,0,0,0,0,0,10
10,0,0,0,0,0,0,0,0,0,0,0,0,0,0,0,0,0,0,0,0,0,0,0,0,0,0,0,10
10,0,0,0,0,0,0,0,0,0,0,0,0,0,0,0,0,0,0,0,0,0,0,0,0,0,0,0,10
10,10,0,0,0,10,10,0,0,0,10,10,0,0,0,0,0,10,10,0,0,0,10,10,0,0,0,10,10
2,2,0,0,0,10,10,0,0,0,10,10,0,0,0,0,0,10,10,0,0,0,10,10,0,0,0,10,2
2,0,0,0,0,0,0,0,0,0,0,0,0,0,0,0,0,0,0,0,0,0,0,0,0,0,0,0,2
2,0,0,0,0,0,0,0,0,0,0,0,0,0,0,0,0,0,0,0,0,0,0,0,0,0,0,0,2
2,10,0,0,0,10,10,0,0,0,0,0,0,0,0,0,0,0,0,0,0,0,10,10,0,0,0,10,2
2,10,0,0,0,10,10,0,0,0,10,10,0,0,0,0,0,10,10,0,0,0,10,10,0,0,0,10,2
2,0,0,0,0,0,0,0,0,0,0,2,10,0,0,0,10,2,10,0,0,0,0,0,0,0,0,0,2
2,0,0,0,0,0,0,0,0,0,0,5,1,10,10,10,1,7,0,0,0,0,0,0,0,0,0,0,2
2,0,0,0,0,0,0,0,0,0,0,5,1,1,1,1,1,7,0,0,0,0,0,0,0,0,0,0,2
2,0,0,0,0,0,0,0,0,0,0,2,1,1,1,1,1,2,0,0,0,0,0,0,0,0,0,0,2
2,10,0,0,0,10,10,0,0,0,2,1,1,1,1,1,1,1,2,0,0,0,10,10,0,0,0,10,2
2,2,2,2,2,2,2,2,2,2,2,1,1,1,1,1,1,1,2,2,2,2,2,2,2,2,2,2,2
endlayer

layer
2,2,2,2,2,2,2,2,2,2,2,1,1,1,1,1,1,1,2,2,2,2,2,2,2,2,2,2,2
2,10,0,0,0,10,10,0,0,0,2,1,1,1,1,1,1,1,2,0,0,0,10,10,0,0,0,10,2
2,0,0,0,0,0,0,0,0,0,0,2,2,2,2,2,2,2,0,0,0,0,0,0,0,0,0,0,2
2,0,0,0,0,0,0,0,0,0,0,0,5,2,2,2,7,0,0,0,0,0,0,0,0,0,0,0,2
2,0,0,0,0,0,0,0,0,0,0,0,5,10,10,10,7,0,0,0,0,0,0,0,0,0,0,0,2
2,0,0,0,0,0,0,0,0,0,0,2,14,17,16,15,14,2,10,0,0,0,0,0,0,0,0,0,2
2,10,0,0,0,10,10,0,0,0,10,10,0,0,0,0,0,10,10,0,0,0,10,10,0,0,0,10,2
2,10,0,0,0,10,10,0,0,0,0,0,0,0,0,0,0,0,0,0,0,0,10,10,0,0,0,10,2
2,0,0,0,0,0,0,0,0,0,0,0,0,0,0,0,0,0,0,0,0,0,0,0,0,0,0,0,2
2,0,0,0,0,0,0,0,0,0,0,0,0,0,0,0,0,0,0,0,0,0,0,0,0,0,0,0,2
2,2,0,0,0,10,10,0,0,0,14,14,0,0,0,0,0,14,14,0,0,0,10,10,0,0,0,10,2
10,10,0,0,0,10,10,0,0,0,14,14,0,0,0,0,0,14,14,0,0,0,10,10,0,0,0,10,10
10,0,0,0,0,0,0,0,0,0,0,0,0,0,0,0,0,0,0,0,0,0,0,0,0,0,0,0,10
10,0,0,0,0,0,0,0,0,0,0,0,0,0,0,0,0,0,0,0,0,0,0,0,0,0,0,0,10
10,0,0,0,0,0,0,0,0,0,0,0,0,0,0,0,0,0,0,0,0,0,0,0,0,0,0,0,10
10,0,0,0,0,0,0,0,0,0,0,0,0,0,0,0,0,0,0,0,0,0,0,0,0,0,0,0,10
10,0,0,0,0,0,0,0,0,0,0,0,0,0,0,0,0,0,0,0,0,0,0,0,0,0,0,0,10
10,10,0,0,0,10,10,0,0,0,14,14,0,0,0,0,0,14,14,0,0,0,10,10,0,0,0,10,10
2,2,0,0,0,10,10,0,0,0,14,14,0,0,0,0,0,14,14,0,0,0,10,10,0,0,0,10,2
2,0,0,0,0,0,0,0,0,0,0,0,0,0,0,0,0,0,0,0,0,0,0,0,0,0,0,0,2
2,0,0,0,0,0,0,0,0,0,0,0,0,0,0,0,0,0,0,0,0,0,0,0,0,0,0,0,2
2,10,0,0,0,10,10,0,0,0,0,0,0,0,0,0,0,0,0,0,0,0,10,10,0,0,0,10,2
2,10,0,0,0,10,10,0,0,0,10,10,0,0,0,0,0,10,10,0,0,0,10,10,0,0,0,10,2
2,0,0,0,0,0,0,0,0,0,0,2,14,17,16,15,14,2,10,0,0,0,0,0,0,0,0,0,2
2,0,0,0,0,0,0,0,0,0,0,0,5,10,10,10,7,0,0,0,0,0,0,0,0,0,0,0,2
2,0,0,0,0,0,0,0,0,0,0,0,5,2,2,2,7,0,0,0,0,0,0,0,0,0,0,0,2
2,0,0,0,0,0,0,0,0,0,0,2,2,2,2,2,2,2,0,0,0,0,0,0,0,0,0,0,2
2,10,0,0,0,10,10,0,0,0,2,1,1,1,1,1,1,1,2,0,0,0,10,10,0,0,0,10,2
2,2,2,2,2,2,2,2,2,2,2,1,1,1,1,1,1,1,2,2,2,2,2,2,2,2,2,2,2
endlayer

layer
2,2,2,2,2,2,2,2,2,2,2,1,1,1,1,1,1,1,2,2,2,2,2,2,2,2,2,2,2
2,10,0,0,0,10,10,0,0,0,2,1,2,2,2,2,2,1,2,0,0,0,10,10,0,0,0,10,2
2,0,0,0,0,0,0,0,0,0,0,2,2,0,0,0,2,2,0,0,0,0,0,0,0,0,0,0,2
2,0,0,0,0,0,0,0,0,0,0,0,0,0,0,0,0,0,0,0,0,0,0,0,0,0,0,0,2
2,0,0,0,0,0,0,0,0,0,0,0,0,0,0,0,0,0,0,0,0,0,0,0,0,0,0,0,2
2,0,0,0,0,0,0,0,0,0,0,2,2,11,11,11,10,2,10,0,0,0,0,0,0,0,0,0,2
2,10,0,0,0,10,10,0,0,0,10,10,10,10,10,10,10,10,10,0,0,0,10,10,0,0,0,10,2
2,10,0,0,0,10,10,0,0,0,9,10,10,10,10,10,10,10,9,0,0,0,10,10,0,0,0,10,2
2,0,0,0,0,0,0,0,0,0,14,10,10,10,10,10,10,10,14,0,0,0,0,0,0,0,0,0,2
2,0,0,0,0,0,0,0,0,0,9,10,10,10,10,10,10,10,9,0,0,0,0,0,0,0,0,0,2
2,2,0,0,0,10,10,9,14,9,9,2,10,10,10,10,10,2,9,10,14,10,10,10,0,0,0,10,2
10,10,0,0,0,10,10,10,10,10,2,2,2,2,2,2,2,2,2,10,10,10,10,10,0,0,0,10,10
10,0,0,0,0,0,0,0,15,10,10,2,2,2,2,2,2,2,10,10,17,0,0,0,0,0,0,0,10
10,0,0,0,0,0,0,0,15,10,10,2,2,2,2,2,2,2,10,10,17,0,0,0,0,0,0,0,10
10,0,0,0,0,0,0,0,15,10,10,2,2,2,2,2,2,2,10,10,17,0,0,0,0,0,0,0,10
10,0,0,0,0,0,0,0,15,10,10,2,2,2,2,2,2,2,10,10,17,0,0,0,0,0,0,0,10
10,0,0,0,0,0,0,0,15,10,10,2,2,2,2,2,2,2,10,10,17,0,0,0,0,0,0,0,10
10,10,0,0,0,10,10,10,10,10,2,2,2,2,2,2,2,2,2,10,10,10,10,10,0,0,0,10,10
2,2,0,0,0,10,10,9,14,9,9,2,10,10,10,10,10,2,9,10,14,10,10,10,0,0,0,10,2
2,0,0,0,0,0,0,0,0,0,9,10,10,10,10,10,10,10,9,0,0,0,0,0,0,0,0,0,2
2,0,0,0,0,0,0,0,0,0,14,10,10,10,10,10,10,10,14,0,0,0,0,0,0,0,0,0,2
2,10,0,0,0,10,10,0,0,0,9,10,10,10,10,10,10,10,9,0,0,0,10,10,0,0,0,10,2
2,10,0,0,0,10,10,0,0,0,10,10,10,10,10,10,10,10,10,0,0,0,10,10,0,0,0,10,2
2,0,0,0,0,0,0,0,0,0,0,2,10,8,8,8,2,2,10,0,0,0,0,0,0,0,0,0,2
2,0,0,0,0,0,0,0,0,0,0,0,0,0,0,0,0,0,0,0,0,0,0,0,0,0,0,0,2
2,0,0,0,0,0,0,0,0,0,0,0,0,0,0,0,0,0,0,0,0,0,0,0,0,0,0,0,2
2,0,0,0,0,0,0,0,0,0,0,2,2,0,0,0,2,2,0,0,0,0,0,0,0,0,0,0,2
2,10,0,0,0,10,10,0,0,0,2,1,2,2,2,2,2,1,2,0,0,0,10,10,0,0,0,10,2
2,2,2,2,2,2,2,2,2,2,2,1,1,1,1,1,1,1,2,2,2,2,2,2,2,2,2,2,2
endlayer

layer
2,2,2,2,2,2,2,2,2,2,2,1,1,1,1,1,1,1,2,2,2,2,2,2,2,2,2,2,2
2,10,0,0,0,10,10,0,0,0,2,1,2,2,2,2,2,1,2,0,0,0,10,10,0,0,0,10,2
2,0,0,0,0,0,0,0,0,0,0,2,2,0,0,0,2,2,0,0,0,0,0,0,0,0,0,0,2
2,0,0,0,0,0,0,0,0,0,0,0,0,0,0,0,0,0,0,0,0,0,0,0,0,0,0,0,2
2,0,0,0,0,0,0,0,0,0,0,0,0,0,0,0,0,0,0,0,0,0,0,0,0,0,0,0,2
2,0,0,0,0,0,0,0,0,0,0,2,2,0,0,0,10,2,10,0,0,0,0,0,0,0,0,0,2
2,10,0,0,0,10,10,0,0,0,10,10,2,11,11,11,10,10,10,0,0,0,10,10,0,0,0,10,2
2,10,0,0,0,10,10,0,0,0,2,10,10,10,10,10,10,10,2,0,0,0,10,10,0,0,0,10,2
2,0,0,0,0,0,0,0,18,18,2,2,2,2,2,2,2,2,2,18,17,0,0,0,0,0,0,0,2
2,0,0,0,0,0,0,0,15,9,3,3,9,3,3,3,9,3,3,9,17,0,0,0,0,0,0,0,2
2,2,0,0,0,10,10,2,2,3,3,3,3,3,3,3,3,3,3,3,2,2,10,10,0,0,0,10,2
10,10,0,0,0,10,10,10,2,3,3,3,3,3,3,3,3,3,3,3,2,10,10,10,0,0,0,10,10
10,19,0,0,0,0,0,15,2,9,3,3,9,3,3,3,9,3,3,9,2,17,0,0,0,0,0,0,10
10,0,0,0,0,0,0,15,2,3,3,3,3,3,3,3,3,3,3,3,2,17,0,0,0,0,0,0,10
10,0,0,0,0,0,0,15,2,3,3,3,3,3,3,3,3,3,3,3,2,17,0,0,0,0,0,0,10
10,0,0,0,0,0,0,15,2,3,3,3,3,3,3,3,3,3,3,3,2,17,0,0,0,0,0,0,10
10,18,0,0,0,0,0,15,2,9,3,3,9,3,3,3,9,3,3,9,2,17,0,0,0,0,0,0,10
10,10,0,0,0,10,10,10,2,3,3,3,3,3,3,3,3,3,3,3,2,10,10,10,0,0,0,10,10
2,2,0,0,0,10,10,2,2,3,3,3,3,3,3,3,3,3,3,3,2,2,10,10,0,0,0,10,2
2,0,0,0,0,0,0,0,15,9,3,3,9,3,3,3,9,3,3,9,17,0,0,0,0,0,0,0,2
2,0,0,0,0,0,0,0,15,19,2,2,2,2,2,2,2,2,2,19,17,0,0,0,0,0,0,0,2
2,10,0,0,0,10,10,0,0,0,2,10,10,10,10,10,10,10,2,0,0,0,10,10,0,0,0,10,2
2,10,0,0,0,10,10,0,0,0,10,10,10,8,8,8,2,10,10,0,0,0,10,10,0,0,0,10,2
2,0,0,0,0,0,0,0,0,0,0,2,10,0,0,0,2,2,10,0,0,0,0,0,0,0,0,0,2
2,0,0,0,0,0,0,0,0,0,0,0,0,0,0,0,0,0,0,0,0,0,0,0,0,0,0,0,2
2,0,0,0,0,0,0,0,0,0,0,0,0,0,0,0,0,0,0,0,0,0,0,0,0,0,0,0,2
2,0,0,0,0,0,0,0,0,0,0,2,2,0,0,0,2,2,0,0,0,0,0,0,0,0,0,0,2
2,10,0,0,0,10,10,0,0,0,2,1,2,2,2,2,2,1,2,0,0,0,10,10,0,0,0,10,2
2,2,2,2,2,2,2,2,2,2,2,1,1,1,1,1,1,1,2,2,2,2,2,2,2,2,2,2,2
endlayer

layer
2,2,2,2,2,2,2,2,2,2,2,1,1,1,1,1,1,1,2,2,2,2,2,2,2,2,2,2,2
2,14,19,19,19,14,14,19,19,19,2,1,2,2,2,2,2,1,2,19,19,19,14,14,19,19,19,14,2
2,17,0,0,0,0,0,0,0,0,19,2,2,0,0,0,2,2,19,0,0,0,0,0,0,0,0,15,2
2,17,0,0,0,0,0,0,0,0,16,16,0,0,0,0,0,16,16,0,0,0,0,0,0,0,0,15,2
2,17,0,0,0,0,0,0,0,0,16,16,0,0,0,0,0,16,16,0,0,0,0,0,0,0,0,15,2
2,17,0,0,0,0,0,0,0,0,18,2,2,0,0,0,2,2,14,0,0,0,0,0,0,0,0,15,2
2,14,0,0,0,14,14,0,0,0,14,10,2,0,0,0,10,10,14,0,0,0,14,14,0,0,0,14,2
2,14,0,0,0,14,14,18,18,18,2,10,2,11,11,11,10,10,2,18,18,18,14,14,0,0,0,14,2
2,17,0,0,0,0,0,15,2,2,2,2,1,2,2,2,2,2,2,2,2,17,0,0,0,0,0,15,2
2,17,0,0,0,0,0,15,2,2,4,4,9,4,4,4,9,4,4,2,2,17,0,0,0,0,0,15,2
2,2,17,16,15,14,14,2,2,4,4,4,4,4,4,4,4,4,4,4,2,2,14,14,17,16,15,2,2
10,10,17,16,15,14,10,10,2,4,4,4,4,4,4,4,4,4,4,4,2,10,10,14,17,16,15,10,10
10,2,0,0,0,0,15,10,2,9,4,4,9,4,4,4,9,4,4,9,1,2,17,0,0,0,0,19,10
10,19,0,0,0,0,15,2,2,4,4,4,4,4,4,4,4,4,4,4,2,2,17,0,0,0,0,0,10
10,16,0,0,0,0,15,2,2,4,4,4,4,4,4,4,4,4,4,4,2,2,17,0,0,0,0,0,10
10,18,0,0,0,0,15,2,2,4,4,4,4,4,4,4,4,4,4,4,2,2,17,0,0,0,0,0,10
10,2,0,0,0,0,15,2,1,9,4,4,9,4,4,4,9,4,4,9,2,10,17,0,0,0,0,18,10
10,10,17,16,15,10,10,10,2,4,4,4,4,4,4,4,4,4,4,4,2,10,10,14,17,16,15,10,10
2,2,17,16,15,10,14,2,2,4,4,4,4,4,4,4,4,4,4,4,2,2,14,14,17,16,15,2,2
2,17,0,0,0,0,0,15,2,2,4,4,9,4,4,4,9,4,4,2,2,17,0,0,0,0,0,15,2
2,17,0,0,0,0,0,15,2,2,2,2,2,2,2,2,1,2,2,2,2,17,0,0,0,0,0,15,2
2,14,0,0,0,14,14,19,19,19,2,10,10,8,8,8,2,10,2,19,19,19,14,14,0,0,0,14,2
2,14,0,0,0,14,14,0,0,0,14,10,10,0,0,0,2,10,14,0,0,0,14,14,0,0,0,14,2
2,17,0,0,0,0,0,0,0,0,19,2,2,0,0,0,2,2,14,0,0,0,0,0,0,0,0,15,2
2,17,0,0,0,0,0,0,0,0,16,16,0,0,0,0,0,16,16,0,0,0,0,0,0,0,0,15,2
2,17,0,0,0,0,0,0,0,0,16,16,0,0,0,0,0,16,16,0,0,0,0,0,0,0,0,15,2
2,17,0,0,0,0,0,0,0,0,18,2,2,0,0,0,2,2,18,0,0,0,0,0,0,0,0,15,2
2,14,18,18,18,14,14,18,18,18,2,1,2,2,2,2,2,1,2,18,18,18,14,14,18,18,18,14,2
2,2,2,2,2,2,2,2,2,2,2,1,1,1,1,1,1,1,2,2,2,2,2,2,2,2,2,2,2
endlayer

layer
1,1,1,1,1,1,1,1,1,1,1,1,1,1,1,1,1,1,1,1,1,1,1,1,1,1,1,1,1
1,2,2,2,2,2,2,2,2,2,1,1,2,2,2,2,2,1,1,2,2,2,2,2,2,2,2,2,1
1,2,19,19,19,19,19,19,19,2,2,2,2,17,0,15,2,2,2,17,19,19,19,19,19,19,15,2,1
1,2,17,0,0,0,0,0,0,15,2,2,17,0,0,0,15,2,2,17,0,0,0,0,0,0,15,2,1
1,2,17,0,0,0,0,0,0,15,2,2,17,0,0,0,15,2,2,17,0,0,0,0,0,0,15,2,1
1,2,17,0,0,0,0,0,0,15,2,2,2,0,0,0,2,2,2,17,0,0,0,0,0,0,15,2,1
1,2,17,0,0,2,9,18,18,18,2,2,2,0,0,0,2,2,2,18,18,18,9,9,0,0,15,2,1
1,2,17,0,0,2,9,9,2,2,2,2,2,0,0,0,2,2,2,2,2,2,9,9,0,0,15,2,1
1,2,17,0,0,0,15,2,2,2,2,2,2,0,0,0,2,2,2,2,2,2,17,0,0,0,15,2,1
1,2,18,18,18,18,15,2,2,2,0,0,10,0,0,0,10,0,0,2,2,2,17,18,18,18,2,2,1
1,1,2,2,2,2,2,2,2,0,0,0,0,0,0,0,0,0,0,0,2,2,2,2,2,2,2,1,1
10,10,2,2,2,2,2,2,2,0,0,0,0,0,0,0,0,0,0,0,2,2,2,2,2,2,2,10,10
10,2,19,19,19,15,2,2,2,10,0,0,10,0,0,0,10,0,0,10,2,2,2,19,19,19,19,2,10
10,2,17,0,0,15,2,2,0,0,0,0,0,0,0,0,0,0,0,0,0,2,2,17,0,0,0,19,10
10,2,17,0,0,15,2,2,0,0,0,0,0,0,0,0,0,0,0,0,0,2,2,17,0,0,0,16,10
10,2,17,0,0,15,2,2,0,0,0,0,0,0,0,0,0,0,0,0,0,2,2,17,0,0,0,18,10
10,2,18,18,18,15,2,2,2,10,0,0,10,0,0,0,10,0,0,10,2,2,2,18,18,18,18,2,10
10,10,2,2,2,2,2,2,2,0,0,0,0,0,0,0,0,0,0,0,2,2,2,2,2,2,2,10,10
1,1,2,2,2,2,2,2,2,0,0,0,0,0,0,0,0,0,0,0,2,2,2,2,2,2,2,1,1
1,2,2,19,19,19,15,2,2,2,0,0,10,0,0,0,10,0,0,2,2,2,17,19,19,19,19,2,1
1,2,17,0,0,0,15,2,2,2,2,2,2,0,0,0,2,2,2,2,2,2,17,0,0,0,15,2,1
1,2,17,0,0,9,9,9,2,2,2,2,2,0,0,0,2,2,2,2,2,2,9,9,0,0,15,2,1
1,2,17,0,0,9,9,19,19,19,2,2,2,0,0,0,2,2,2,19,19,19,9,9,0,0,15,2,1
1,2,17,0,0,0,0,0,0,15,2,2,2,0,0,0,2,2,2,17,0,0,0,0,0,0,15,2,1
1,2,17,0,0,0,0,0,0,15,2,2,17,0,0,0,15,2,2,17,0,0,0,0,0,0,15,2,1
1,2,17,0,0,0,0,0,0,15,2,2,17,0,0,0,15,2,2,17,0,0,0,0,0,0,15,2,1
1,2,17,18,18,18,18,18,18,15,2,2,2,17,0,15,2,2,2,2,18,18,18,18,18,18,18,2,1
1,2,2,2,2,2,2,2,2,2,1,1,2,2,2,2,2,1,1,2,2,2,2,2,2,2,2,2,1
1,1,1,1,1,1,1,1,1,1,1,1,1,1,1,1,1,1,1,1,1,1,1,1,1,1,1,1,1
endlayer

layer
1,1,1,1,1,1,1,1,1,1,1,1,1,1,1,1,1,1,1,1,1,1,1,1,1,1,1,1,1
1,1,1,1,1,1,1,1,1,1,1,1,1,1,1,1,1,1,1,1,1,1,1,1,1,1,1,1,1
1,1,2,2,2,2,2,2,2,1,1,1,2,2,2,2,2,1,1,2,2,2,2,2,2,2,2,1,1
1,1,2,9,9,9,9,9,9,2,1,1,2,19,19,19,2,1,1,2,9,9,9,9,9,9,2,1,1
1,1,2,9,9,9,9,9,9,2,1,1,2,0,0,0,2,1,1,2,9,9,9,9,9,9,2,1,1
1,1,2,9,9,9,9,9,9,2,1,1,2,0,0,0,2,1,1,2,9,9,9,9,9,9,2,1,1
1,1,2,9,9,9,2,2,2,2,1,1,2,0,0,0,2,1,1,2,2,2,2,9,9,9,2,1,1
1,1,2,9,9,9,2,2,2,2,1,1,2,0,0,0,2,1,1,2,2,2,2,9,9,9,2,1,1
1,1,2,9,9,9,2,2,2,2,2,2,2,0,0,0,2,2,2,2,2,2,2,9,9,9,2,1,1
1,1,2,2,2,2,2,2,2,2,0,0,10,0,0,0,10,0,0,2,2,2,2,2,2,2,1,1,1
1,1,1,1,1,1,1,1,2,0,0,0,0,0,0,0,0,0,0,0,2,1,1,1,1,1,1,1,1
1,1,1,1,1,1,1,1,2,0,0,0,0,0,0,0,0,0,0,0,2,1,1,1,1,1,1,1,1
1,1,2,2,2,2,2,2,2,10,0,0,10,0,0,0,10,0,0,10,2,2,2,2,2,2,2,1,1
1,1,2,2,2,2,2,2,0,0,0,0,0,0,0,0,0,0,0,0,0,2,2,2,2,2,2,1,1
1,1,2,2,2,2,2,2,0,0,0,0,0,0,0,0,0,0,0,0,0,2,2,2,2,2,2,1,1
1,1,2,2,2,2,2,2,0,0,0,0,0,0,0,0,0,0,0,0,0,2,2,2,2,2,2,1,1
1,1,2,2,2,2,2,2,2,10,0,0,10,0,0,0,10,0,0,10,2,2,2,2,2,2,2,1,1
1,1,1,1,1,1,1,1,2,0,0,0,0,0,0,0,0,0,0,0,2,2,2,2,2,2,2,1,1
1,1,1,1,1,1,1,1,2,0,0,0,0,0,0,0,0,0,0,0,2,2,2,2,2,2,2,1,1
1,1,2,2,2,2,2,2,2,2,0,0,10,0,0,0,10,0,0,2,2,2,2,2,2,2,2,1,1
1,1,2,9,9,9,2,2,2,2,2,2,2,0,0,0,2,2,2,2,2,2,2,9,9,9,2,1,1
1,1,2,9,9,9,2,2,2,2,1,1,2,0,0,0,2,1,1,2,2,2,2,9,9,9,2,1,1
1,1,2,9,9,9,2,2,2,2,1,1,2,0,0,0,2,1,1,2,2,2,2,9,9,9,2,1,1
1,1,2,9,9,9,9,9,9,2,1,1,2,0,0,0,2,1,1,2,9,9,9,9,9,9,2,1,1
1,1,2,9,9,9,9,9,9,2,1,1,2,0,0,0,2,1,1,2,9,9,9,9,9,9,2,1,1
1,1,2,9,9,9,9,9,9,2,1,1,2,18,18,18,2,1,1,2,9,9,9,9,9,9,2,1,1
1,1,2,2,2,2,2,2,2,2,1,1,2,2,2,2,2,1,1,2,2,2,2,2,2,2,2,1,1
1,1,1,1,1,1,1,1,1,1,1,1,1,1,1,1,1,1,1,1,1,1,1,1,1,1,1,1,1
1,1,1,1,1,1,1,1,1,1,1,1,1,1,1,1,1,1,1,1,1,1,1,1,1,1,1,1,1
endlayer

layer
1,1,1,1,1,1,1,1,1,1,1,1,1,1,1,1,1,1,1,1,1,1,1,1,1,1,1,1,1
1,1,1,1,1,1,1,1,1,1,1,1,1,1,1,1,1,1,1,1,1,1,1,1,1,1,1,1,1
1,1,1,1,1,1,1,1,1,1,1,1,1,1,1,1,1,1,1,1,1,1,1,1,1,1,1,1,1
1,1,1,1,1,1,1,1,1,1,1,1,2,2,2,2,2,1,1,1,1,1,1,1,1,1,1,1,1
1,1,1,1,1,1,1,1,1,1,1,1,2,19,19,19,2,1,1,1,1,1,1,1,1,1,1,1,1
1,1,1,1,1,1,1,1,1,1,1,1,2,0,0,0,2,1,1,1,1,1,1,1,1,1,1,1,1
1,1,1,1,1,1,1,1,1,1,1,1,2,0,0,0,2,1,1,1,1,1,1,1,1,1,1,1,1
1,1,1,1,1,1,1,1,1,1,1,1,2,0,0,0,2,1,1,1,1,1,1,1,1,1,1,1,1
1,1,1,1,1,1,1,1,1,2,2,2,2,0,0,0,2,2,2,2,1,1,1,1,1,1,1,1,1
1,1,1,1,1,1,1,1,2,2,0,0,9,0,0,0,9,0,0,2,2,1,1,1,1,1,1,1,1
1,1,1,1,1,1,1,1,2,0,0,0,0,0,0,0,0,0,0,0,2,1,1,1,1,1,1,1,1
1,1,1,1,1,1,1,1,2,0,0,0,0,0,0,0,0,0,0,0,2,1,1,1,1,1,1,1,1
1,1,1,2,2,2,2,2,2,9,0,0,9,0,0,0,9,0,0,9,2,2,2,2,2,2,1,1,1
1,1,1,2,2,2,2,2,0,0,0,0,0,0,0,0,0,0,0,0,0,2,2,2,2,2,1,1,1
1,1,1,2,2,2,2,2,0,0,0,0,0,0,0,0,0,0,0,0,0,2,2,2,2,2,1,1,1
1,1,1,2,2,2,2,2,0,0,0,0,0,0,0,0,0,0,0,0,0,2,2,2,2,2,1,1,1
1,1,1,2,2,2,2,2,2,9,0,0,9,0,0,0,9,0,0,9,2,2,2,2,2,2,1,1,1
1,1,1,1,1,1,1,1,2,0,0,0,0,0,0,0,0,0,0,0,2,1,1,1,1,1,1,1,1
1,1,1,1,1,1,1,1,2,0,0,0,0,0,0,0,0,0,0,0,2,1,1,1,1,1,1,1,1
1,1,1,1,1,1,1,1,2,2,0,0,9,0,0,0,9,0,0,2,2,1,1,1,1,1,1,1,1
1,1,1,1,1,1,1,1,1,2,2,2,2,0,0,0,2,2,2,2,1,1,1,1,1,1,1,1,1
1,1,1,1,1,1,1,1,1,1,1,1,2,0,0,0,2,1,1,1,1,1,1,1,1,1,1,1,1
1,1,1,1,1,1,1,1,1,1,1,1,2,0,0,0,2,1,1,1,1,1,1,1,1,1,1,1,1
1,1,1,1,1,1,1,1,1,1,1,1,2,0,0,0,2,1,1,1,1,1,1,1,1,1,1,1,1
1,1,1,1,1,1,1,1,1,1,1,1,2,18,18,18,2,1,1,1,1,1,1,1,1,1,1,1,1
1,1,1,1,1,1,1,1,1,1,1,1,2,2,2,2,2,1,1,1,1,1,1,1,1,1,1,1,1
1,1,1,1,1,1,1,1,1,1,1,1,1,1,1,1,1,1,1,1,1,1,1,1,1,1,1,1,1
1,1,1,1,1,1,1,1,1,1,1,1,1,1,1,1,1,1,1,1,1,1,1,1,1,1,1,1,1
1,1,1,1,1,1,1,1,1,1,1,1,1,1,1,1,1,1,1,1,1,1,1,1,1,1,1,1,1
endlayer

layer
1,1,1,1,1,1,1,1,1,1,1,1,1,1,1,1,1,1,1,1,1,1,1,1,1,1,1,1,1
1,1,1,1,1,1,1,1,1,1,1,1,1,1,1,1,1,1,1,1,1,1,1,1,1,1,1,1,1
1,1,1,1,1,1,1,1,1,1,1,1,1,1,1,1,1,1,1,1,1,1,1,1,1,1,1,1,1
1,1,1,1,1,1,1,1,1,1,1,1,1,1,1,1,1,1,1,1,1,1,1,1,1,1,1,1,1
1,1,1,1,1,1,1,1,1,1,1,1,2,2,2,2,2,1,1,1,1,1,1,1,1,1,1,1,1
1,1,1,1,1,1,1,1,1,1,1,1,2,2,2,2,2,1,1,1,1,1,1,1,1,1,1,1,1
1,1,1,1,1,1,1,1,1,1,1,1,2,2,2,2,2,1,1,1,1,1,1,1,1,1,1,1,1
1,1,1,1,1,1,1,1,1,1,1,1,2,2,2,2,2,1,1,1,1,1,1,1,1,1,1,1,1
1,1,1,1,1,1,1,1,1,2,2,2,2,0,0,0,2,2,2,2,1,1,1,1,1,1,1,1,1
1,1,1,1,1,1,1,1,2,2,0,0,14,0,0,0,14,0,0,2,2,1,1,1,1,1,1,1,1
1,1,1,1,1,1,1,1,2,0,0,0,0,0,0,0,0,0,0,0,2,1,1,1,1,1,1,1,1
1,1,1,1,1,1,1,1,2,0,0,0,0,0,0,0,0,0,0,0,2,1,1,1,1,1,1,1,1
1,1,1,1,2,2,2,2,2,14,0,0,14,0,0,0,14,0,0,14,2,2,2,2,2,1,1,1,1
1,1,1,1,2,2,2,2,0,0,0,0,0,0,0,0,0,0,0,0,0,2,2,2,2,1,1,1,1
1,1,1,1,2,2,2,2,0,0,0,0,0,0,0,0,0,0,0,0,0,2,2,2,2,1,1,1,1
1,1,1,1,2,2,2,2,0,0,0,0,0,0,0,0,0,0,0,0,0,2,2,2,2,1,1,1,1
1,1,1,1,2,2,2,2,2,14,0,0,14,0,0,0,14,0,0,14,2,2,2,2,2,1,1,1,1
1,1,1,1,1,1,1,1,2,0,0,0,0,0,0,0,0,0,0,0,2,1,1,1,1,1,1,1,1
1,1,1,1,1,1,1,1,2,0,0,0,0,0,0,0,0,0,0,0,2,1,1,1,1,1,1,1,1
1,1,1,1,1,1,1,1,2,2,0,0,14,0,0,0,14,0,0,2,2,1,1,1,1,1,1,1,1
1,1,1,1,1,1,1,1,1,2,2,2,2,0,0,0,2,2,2,2,1,1,1,1,1,1,1,1,1
1,1,1,1,1,1,1,1,1,1,1,1,2,2,2,2,2,1,1,1,1,1,1,1,1,1,1,1,1
1,1,1,1,1,1,1,1,1,1,1,1,2,2,2,2,2,1,1,1,1,1,1,1,1,1,1,1,1
1,1,1,1,1,1,1,1,1,1,1,1,2,2,2,2,2,1,1,1,1,1,1,1,1,1,1,1,1
1,1,1,1,1,1,1,1,1,1,1,1,2,2,2,2,2,1,1,1,1,1,1,1,1,1,1,1,1
1,1,1,1,1,1,1,1,1,1,1,1,1,1,1,1,1,1,1,1,1,1,1,1,1,1,1,1,1
1,1,1,1,1,1,1,1,1,1,1,1,1,1,1,1,1,1,1,1,1,1,1,1,1,1,1,1,1
1,1,1,1,1,1,1,1,1,1,1,1,1,1,1,1,1,1,1,1,1,1,1,1,1,1,1,1,1
1,1,1,1,1,1,1,1,1,1,1,1,1,1,1,1,1,1,1,1,1,1,1,1,1,1,1,1,1
endlayer

