
# Created by Ruins mod version 16.7 Ingame Parser
# authoring Player: lafuller

weight=1
embed_into_distance=4
acceptable_target_blocks=
unacceptable_target_blocks=flowing_water,water,flowing_lava,lava,ice,bedrock,netherrack,nether_brick,nether_brick_fence,soul_sand,quartz_ore,end_stone,obsidian,iron_bars,cloud,flesh,ash_block,slime_grass,slime_congealed,slime_dirt
biomesToSpawnIn=plains,prarie,meadow,tundra,brushland,shrubland,woodland,woodlands,lavender_fields,flower_field,sunflower_plains,ice_flats,ice_plains
dimensions=15,13,13
allowable_overhang=0
max_leveling=4
leveling_buffer=-1
preserve_water=0
preserve_lava=0

rule1=0,100,preserveBlock
rule2=0,100,stonebrick-0,stonebrick-0,stonebrick-0,stonebrick-0,stonebrick-1,stonebrick-2,stonebrick-2,stone-5,stone-6,cobblestone
rule3=0,100,minecraft:stained_hardened_clay-8
rule4=0,100,minecraft:hardened_clay-0
rule5=0,100,minecraft:stone_brick_stairs-0
rule6=0,100,minecraft:stone_brick_stairs-3
rule7=0,100,stonebrick-0,stonebrick-0,stonebrick-0,stonebrick-0,stonebrick-1,stonebrick-2,stonebrick-2,stone-5,stone-6,cobblestone,gravel
rule8=0,100,minecraft:cobblestone_wall-0
rule9=0,100,minecraft:log-0
rule10=0,100,minecraft:trapdoor-11
rule11=0,100,minecraft:web-0,air,air,air
rule12=0,100,minecraft:ladder-5
rule13=0,100,minecraft:wooden_slab-9
rule14=0,100,minecraft:stone_brick_stairs-2
rule15=0,100,minecraft:planks-1
rule16=0,100,minecraft:planks-0
rule17=0,100,minecraft:oak_stairs-0
rule18=0,100,minecraft:spruce_stairs-0
rule19=0,100,minecraft:fence-0
rule20=0,100,minecraft:oak_stairs-2
rule21=0,100,minecraft:oak_stairs-3
rule22=0,100,minecraft:cauldron-0
rule23=0,100,minecraft:oak_stairs-1
rule24=0,100,minecraft:jungle_door-2
rule25=0,100,IInventory;minecraft:furnace;minecraft:coal#2#0#1-5
rule26=0,100,minecraft:jungle_door-8
rule27=0,100,minecraft:spruce_stairs-6
rule28=0,100,minecraft:spruce_stairs-4
rule29=0,100,minecraft:spruce_stairs-7
rule30=0,100,minecraft:spruce_stairs-5
rule31=0,100,minecraft:spruce_fence_gate-1
rule32=0,100,minecraft:dark_oak_stairs-6
rule33=0,100,minecraft:planks-5
rule34=0,100,minecraft:dark_oak_stairs-7
rule35=0,100,minecraft:dark_oak_stairs-4
rule36=0,100,minecraft:dark_oak_stairs-5
rule37=0,100,minecraft:dark_oak_stairs-2
rule38=0,100,minecraft:wooden_slab-13
rule39=0,100,minecraft:dark_oak_stairs-3
rule40=0,100,minecraft:carpet-8
rule41=0,100,minecraft:carpet-7
rule42=0,100,minecraft:spruce_fence-0
rule43=0,100,minecraft:spruce_fence_gate-0
rule44=0,100,minecraft:dark_oak_stairs-1
rule45=0,100,minecraft:wooden_slab-5
rule46=0,100,minecraft:dark_oak_fence-0
rule47=0,100,minecraft:dark_oak_stairs-0
rule48=0,100,minecraft:double_wooden_slab-5
rule49=0,100,minecraft:trapdoor-9
rule50=0,100,ChestGenHook:chests/spawn_bonus_chest:5-2

layer
1,1,1,1,1,1,1,1,1,1,1,1,1
1,1,1,1,2,2,2,2,2,1,1,1,1
1,1,2,2,3,3,3,3,3,2,1,1,1
1,1,2,3,3,4,4,4,3,2,1,1,1
1,2,3,3,4,4,3,4,3,2,1,1,1
1,2,3,4,3,3,3,4,3,2,2,1,1
1,2,3,4,3,3,3,4,3,3,3,2,1
1,2,3,4,3,4,4,3,4,4,3,2,1
1,2,3,4,4,4,3,4,3,4,3,2,1
1,2,3,3,3,3,3,4,4,4,3,2,1
1,1,2,2,2,2,3,3,3,3,3,2,5
1,1,1,6,2,2,2,2,2,2,2,2,2
1,1,1,6,2,2,2,2,2,2,2,2,2
endlayer

layer
1,1,1,1,1,1,1,1,1,1,1,1,1
1,1,1,1,7,8,7,8,7,1,1,1,1
1,1,7,7,9,10,10,10,9,7,1,1,1
1,1,7,12,12,0,0,0,11,8,1,1,1
1,7,9,0,0,0,0,0,0,7,1,1,1
1,8,13,0,0,0,0,0,0,7,7,1,1
1,7,13,0,0,0,0,0,0,11,9,7,1
1,8,13,0,0,0,0,0,0,0,13,8,1
1,7,13,0,0,0,0,0,0,0,13,7,1
1,7,9,11,0,0,0,0,0,50,13,7,1
1,1,7,7,7,7,9,13,13,13,9,7,1
1,1,1,1,6,7,7,7,7,7,7,7,14
1,1,1,1,6,7,7,7,7,7,7,7,14
endlayer

layer
1,1,1,1,1,1,1,1,1,1,1,1,1
1,1,1,1,7,8,7,8,7,1,1,1,1
1,1,7,7,9,11,0,11,9,7,1,1,1
1,1,7,12,12,0,0,0,11,8,1,1,1
1,7,9,0,0,0,0,0,11,7,1,1,1
1,8,11,0,0,0,0,0,0,7,7,1,1
1,7,0,0,0,0,0,0,0,11,9,7,1
1,8,0,0,0,0,0,0,0,0,11,8,1
1,7,11,0,0,0,0,0,0,0,0,7,1
1,7,9,11,11,0,0,0,0,0,11,8,1
1,1,7,7,7,7,9,11,0,11,9,7,1
1,1,1,1,1,6,7,7,7,7,7,14,1
1,1,1,1,1,6,7,7,7,7,7,14,1
endlayer

layer
1,1,1,1,1,1,1,1,1,1,1,1,1
1,1,1,1,7,8,7,8,7,1,1,1,1
1,1,7,7,9,11,11,11,9,7,1,1,1
1,1,7,12,12,0,0,11,11,8,1,1,1
1,7,9,0,0,0,0,0,11,7,1,1,1
1,8,11,11,0,0,0,0,11,7,7,1,1
1,7,11,0,0,0,0,0,11,11,9,7,1
1,8,11,0,0,0,0,0,0,11,11,8,1
1,7,11,11,0,0,11,0,0,0,11,7,1
1,7,9,11,11,11,11,11,0,11,11,8,1
1,1,7,7,7,7,9,11,11,11,9,7,1
1,1,1,1,1,1,7,7,7,7,7,1,1
1,1,1,1,1,1,6,7,7,7,14,1,1
endlayer

layer
1,1,1,1,1,1,1,1,1,1,1,1,1
1,1,1,1,7,7,7,7,7,1,1,1,1
1,1,7,7,9,15,15,15,15,7,1,1,1
1,1,7,12,12,16,16,16,15,7,1,1,1
1,7,16,18,17,16,15,16,15,7,1,1,1
1,7,15,16,15,15,15,16,15,7,7,1,1
1,7,15,16,15,15,15,16,15,15,15,7,1
1,7,15,16,15,16,16,15,16,16,15,7,1
1,7,15,16,16,16,15,16,15,16,15,7,1
1,7,15,15,15,15,15,16,16,16,15,7,1
1,1,7,7,7,7,15,15,15,15,15,7,1
1,1,1,1,1,1,7,7,7,7,7,1,1
1,1,1,1,1,1,1,6,7,14,1,1,1
endlayer

layer
1,1,1,1,1,1,1,1,1,1,1,1,1
1,1,1,1,19,17,17,17,19,1,1,1,1
1,1,1,17,9,0,0,0,9,19,1,1,1
1,1,21,12,12,0,0,0,0,20,1,1,1
1,19,9,0,0,0,0,0,0,17,1,1,1
1,21,0,0,0,0,0,0,0,0,20,1,1
1,21,0,0,0,0,0,0,0,22,9,19,1
1,21,0,0,0,0,0,0,0,0,0,20,1
1,21,0,0,0,0,0,0,0,0,0,20,1
1,19,9,0,0,0,0,0,0,0,0,20,1
1,1,19,23,23,23,9,19,0,19,9,19,1
1,1,1,1,1,1,19,9,24,9,19,1,1
1,1,1,1,1,1,1,1,1,1,1,1,1
endlayer

layer
1,1,1,1,1,1,1,1,1,1,1,1,1
1,1,1,1,19,19,1,19,19,1,1,1,1
1,1,1,17,9,0,0,0,9,19,1,1,1
1,1,21,12,12,0,0,0,0,19,1,1,1
1,19,9,0,0,0,0,0,0,0,1,1,1
1,19,0,0,0,0,0,0,0,0,19,1,1
1,0,0,0,0,0,0,0,0,25,9,19,1
1,0,0,0,0,0,0,0,0,0,0,19,1
1,19,0,0,0,0,0,0,0,0,0,0,1
1,19,9,0,0,0,0,0,0,0,0,19,1
1,1,19,19,0,19,9,19,0,19,9,19,1
1,1,1,1,1,1,19,9,26,9,19,1,1
1,1,1,1,1,1,1,1,1,1,1,1,1
endlayer

layer
1,1,1,1,1,1,1,1,1,1,1,1,1
1,1,1,1,29,28,28,28,27,1,1,1,1
1,1,1,28,9,0,0,0,9,28,1,1,1
1,1,29,12,12,0,0,0,0,27,1,1,1
1,18,9,0,0,0,0,0,0,28,1,1,1
1,29,0,0,0,0,0,0,0,0,27,1,1
1,29,0,0,0,0,0,0,0,8,9,27,1
1,29,0,0,0,0,0,0,0,0,0,27,1
1,29,0,0,0,0,0,0,0,0,0,27,1
1,30,9,0,0,0,0,0,0,0,0,27,1
1,1,29,30,30,30,9,19,0,19,9,30,1
1,1,1,1,1,1,29,9,31,9,27,1,1
1,1,1,1,1,1,1,1,1,1,1,1,1
endlayer

layer
1,1,1,1,1,1,1,1,1,1,1,1,1
1,1,1,1,34,33,33,33,32,1,1,1,1
1,1,35,33,9,13,13,13,9,1,1,1,1
1,1,33,12,12,13,13,13,13,32,1,1,1
1,34,9,18,18,13,13,13,13,33,1,1,1
1,33,13,13,13,0,0,0,0,33,32,1,1
1,33,13,13,0,0,0,0,0,8,9,32,1
1,33,13,13,0,0,0,0,0,0,0,33,1
1,33,13,13,0,0,0,0,0,0,0,33,1
1,36,9,13,0,0,0,0,0,0,0,33,1
1,1,29,15,15,15,9,0,0,0,9,32,1
1,1,1,1,1,34,33,9,15,9,33,37,1
1,1,1,1,1,1,38,1,1,1,38,1,1
endlayer

layer
1,1,1,1,1,1,1,1,1,1,1,1,1
1,1,1,39,33,33,33,33,35,1,1,1,1
1,1,34,33,9,41,41,40,9,35,1,1,1
1,35,33,12,12,41,41,40,42,33,35,1,1
1,33,9,0,0,0,0,0,42,33,33,35,1
1,39,41,41,42,31,31,31,42,33,33,32,1
1,39,41,41,43,0,0,0,0,8,9,33,38
1,39,41,41,43,0,0,0,0,0,0,33,32
1,39,41,41,43,0,0,0,0,0,0,33,33
1,33,9,42,42,0,0,0,0,0,0,33,32
1,34,36,33,33,15,9,0,0,0,9,33,38
1,1,1,1,36,33,33,9,15,9,33,37,1
1,1,1,1,1,1,1,44,33,44,1,1,1
endlayer

layer
1,1,1,1,45,45,45,45,1,1,1,1,1
1,1,35,33,33,33,35,33,35,45,1,1,1
1,35,33,33,9,0,0,0,15,33,45,1,1
38,33,33,0,0,0,0,0,29,33,33,1,1
34,33,9,0,0,0,0,0,29,15,33,45,1
36,46,0,0,0,0,0,0,30,15,33,37,1
1,46,0,0,0,0,0,0,0,8,15,33,1
1,46,0,0,0,0,0,0,0,0,29,33,45
35,46,0,0,0,0,0,0,0,0,29,33,37
34,33,9,28,28,27,0,0,0,0,29,33,44
1,33,15,15,15,15,9,28,28,28,9,37,1
1,1,36,33,33,33,33,33,37,44,44,1,1
1,1,1,1,1,1,1,1,1,1,1,1,1
endlayer

layer
1,1,1,1,1,1,1,1,1,1,1,1,1
1,1,1,45,47,47,47,45,1,1,1,1,1
1,45,45,33,33,33,33,47,47,1,1,1,1
1,39,33,38,38,38,38,38,35,47,1,1,1
45,39,9,0,0,0,0,0,48,37,37,1,1
47,48,32,0,0,0,0,0,48,37,37,1,1
39,33,32,0,0,0,0,0,38,33,37,1,1
39,39,32,0,0,0,0,0,0,38,37,1,1
45,39,33,0,0,0,0,0,0,38,37,1,1
1,39,33,34,36,36,35,38,38,38,37,1,1
1,1,44,44,38,36,48,37,44,44,45,1,1
1,1,1,45,45,45,45,1,1,1,1,1,1
1,1,1,1,1,1,1,1,1,1,1,1,1
endlayer

layer
1,1,1,1,1,1,1,1,1,1,1,1,1
1,1,1,1,1,1,1,1,1,1,1,1,1
1,1,1,1,1,1,1,1,1,1,1,1,1
1,1,1,45,47,45,1,1,1,1,1,1,1
1,1,45,36,36,36,47,45,1,1,1,1,1
1,1,39,38,38,38,34,48,45,1,1,1,1
1,45,39,38,38,49,34,48,45,8,1,1,1
1,1,45,38,38,38,34,48,48,45,1,1,1
1,1,45,39,35,35,35,48,45,45,1,1,1
1,1,1,45,44,44,44,45,45,1,1,1,1
1,1,1,1,1,1,1,1,1,1,1,1,1
1,1,1,1,1,1,1,1,1,1,1,1,1
1,1,1,1,1,1,1,1,1,1,1,1,1
endlayer

layer
1,1,1,1,1,1,1,1,1,1,1,1,1
1,1,1,1,1,1,1,1,1,1,1,1,1
1,1,1,1,1,1,1,1,1,1,1,1,1
1,1,1,1,1,1,1,1,1,1,1,1,1
1,1,1,1,1,1,1,1,1,1,1,1,1
1,1,1,1,1,1,1,1,1,1,1,1,1
1,1,1,1,1,1,1,1,1,8,1,1,1
1,1,1,1,1,1,1,1,1,1,1,1,1
1,1,1,1,1,1,1,1,1,1,1,1,1
1,1,1,1,1,1,1,1,1,1,1,1,1
1,1,1,1,1,1,1,1,1,1,1,1,1
1,1,1,1,1,1,1,1,1,1,1,1,1
1,1,1,1,1,1,1,1,1,1,1,1,1
endlayer

layer
1,1,1,1,1,1,1,1,1,1,1,1,1
1,1,1,1,1,1,1,1,1,1,1,1,1
1,1,1,1,1,1,1,1,1,1,1,1,1
1,1,1,1,1,1,1,1,1,1,1,1,1
1,1,1,1,1,1,1,1,1,1,1,1,1
1,1,1,1,1,1,1,1,1,1,1,1,1
1,1,1,1,1,1,1,1,1,8,1,1,1
1,1,1,1,1,1,1,1,1,1,1,1,1
1,1,1,1,1,1,1,1,1,1,1,1,1
1,1,1,1,1,1,1,1,1,1,1,1,1
1,1,1,1,1,1,1,1,1,1,1,1,1
1,1,1,1,1,1,1,1,1,1,1,1,1
1,1,1,1,1,1,1,1,1,1,1,1,1
endlayer

