
# Created by Ruins mod version 16.7 Ingame Parser
# authoring Player: lafuller

weight=1
embed_into_distance=4
acceptable_target_blocks=
unacceptable_target_blocks=flowing_water,water,flowing_lava,lava,ice,bedrock,netherrack,nether_brick,nether_brick_fence,soul_sand,quartz_ore,gravel,end_stone,obsidian,iron_bars,cloud,flesh,ash_block,slime_grass,slime_congealed,slime_dirt
dimensions=17,14,13
allowable_overhang=0
max_leveling=4
leveling_buffer=-1
preserve_water=0
preserve_lava=0

rule1=0,100,preserveBlock
rule2=0,100,minecraft:dirt-1
rule3=0,100,minecraft:dirt-0
rule4=0,100,minecraft:stone-1
rule5=0,100,minecraft:dirt-2
rule6=0,100,minecraft:mycelium-0
rule7=0,100,minecraft:spruce_fence-0
rule8=0,100,minecraft:spruce_stairs-0
rule9=0,100,minecraft:log2-1
rule10=0,100,brown_mushroom-0,brown_mushroom-0,red_mushroom-0,air,air,air,air,air,air,air,air,air,air,tallgrass-1
rule11=0,100,minecraft:spruce_stairs-2
rule12=0,100,minecraft:spruce_stairs-3
rule13=0,100,minecraft:spruce_stairs-1
rule14=0,100,minecraft:spruce_fence_gate-1
rule15=0,100,minecraft:dark_oak_fence-0
rule16=0,100,minecraft:spruce_stairs-6
rule17=0,100,minecraft:spruce_stairs-4
rule18=0,100,minecraft:spruce_stairs-7
rule19=0,100,minecraft:wooden_slab-13
rule20=0,100,minecraft:spruce_stairs-5
rule21=0,100,minecraft:planks-1
rule22=0,100,minecraft:log2-5
rule23=0,100,minecraft:log2-9
rule24=0,100,minecraft:wooden_slab-5
rule25=0,100,minecraft:wooden_slab-9
rule26=0,100,minecraft:double_wooden_slab-1
rule27=0,100,minecraft:wooden_slab-1

layer
1,1,1,1,1,1,1,1,1,1,1,1,1
1,1,1,1,1,2,2,2,2,1,1,1,1
1,1,1,2,2,3,3,3,2,2,1,1,1
1,1,2,2,3,3,3,3,3,3,2,1,1
1,1,2,3,3,3,3,3,3,3,2,1,1
1,2,2,3,3,3,3,3,3,3,3,2,1
1,2,3,3,3,3,3,3,3,3,3,2,1
1,2,3,3,3,3,3,3,3,3,3,2,1
1,2,3,3,3,3,3,3,3,3,3,2,1
1,2,3,3,3,3,3,3,3,3,3,2,1
1,2,3,3,3,3,3,3,3,3,3,2,1
1,1,2,3,3,3,3,3,3,3,2,1,1
1,1,1,2,3,3,3,3,2,2,1,1,1
1,1,1,1,2,2,2,2,1,1,1,1,1
endlayer

layer
1,1,1,1,1,1,1,1,1,1,1,1,1
1,1,1,1,1,1,2,2,1,1,1,1,1
1,1,1,1,2,2,2,2,2,1,1,1,1
1,1,1,2,3,3,3,3,3,2,1,1,1
1,1,2,3,3,3,3,3,3,3,2,1,1
1,1,2,3,3,3,3,3,3,3,2,1,1
1,2,2,3,3,3,3,3,3,3,2,1,1
1,2,2,3,3,3,3,3,3,3,3,2,1
1,2,2,3,3,3,3,3,3,3,3,2,1
1,1,2,3,3,3,3,3,3,3,2,1,1
1,1,2,3,3,3,3,3,3,3,2,1,1
1,1,2,2,3,3,3,3,3,2,2,1,1
1,1,1,2,2,3,3,2,2,1,1,1,1
1,1,1,1,1,2,2,1,1,1,1,1,1
endlayer

layer
1,1,1,1,1,1,1,1,1,1,1,1,1
1,1,1,1,1,1,2,1,1,1,1,1,1
1,1,1,1,1,2,2,2,2,1,1,1,1
1,1,1,2,2,3,3,3,3,2,1,1,1
1,1,1,2,3,3,3,3,3,2,1,1,1
1,1,2,3,3,3,3,3,3,3,2,1,1
1,1,2,3,3,3,3,3,3,3,2,1,1
1,2,2,3,3,3,3,3,3,3,2,1,1
1,1,2,3,3,3,3,3,3,3,2,1,1
1,1,2,3,3,3,3,3,3,2,2,1,1
1,1,1,2,3,3,3,3,3,2,1,1,1
1,1,1,2,2,3,3,3,2,2,1,1,1
1,1,1,1,2,2,2,2,1,1,1,1,1
1,1,1,1,1,1,1,1,1,1,1,1,1
endlayer

layer
1,1,1,1,1,1,1,1,1,1,1,1,1
1,1,1,1,1,1,1,1,1,1,1,1,1
1,1,1,1,1,2,2,2,1,1,1,1,1
1,1,1,2,2,3,3,3,2,2,1,1,1
1,1,1,2,3,3,3,3,3,2,1,1,1
1,1,1,2,3,3,3,3,3,2,1,1,1
1,1,2,3,3,3,3,3,3,3,2,1,1
1,1,2,3,3,3,3,3,3,3,2,1,1
1,1,2,3,3,3,3,3,3,2,2,1,1
1,1,1,2,3,3,3,3,3,2,1,1,1
1,1,1,1,2,3,3,3,2,1,1,1,1
1,1,1,1,2,2,2,2,2,1,1,1,1
1,1,1,1,1,2,2,1,1,1,1,1,1
1,1,1,1,1,1,1,1,1,1,1,1,1
endlayer

layer
1,1,1,1,1,1,1,1,1,1,1,1,1
1,1,1,1,1,1,1,1,1,1,1,1,1
1,1,1,1,1,2,2,2,1,1,1,1,1
1,1,1,1,2,4,5,4,2,1,1,1,1
1,1,1,2,5,2,5,5,5,2,1,1,1
1,1,1,4,5,5,2,2,5,4,1,1,1
1,1,2,5,2,2,2,5,5,5,2,1,1
1,1,2,5,5,2,6,2,5,5,2,1,1
1,1,1,4,5,5,2,2,5,4,1,1,1
1,1,1,2,5,5,2,5,5,2,1,1,1
1,1,1,1,2,4,2,4,2,1,1,1,1
1,1,1,1,1,2,2,2,1,1,1,1,1
1,1,1,1,1,1,1,1,1,1,1,1,1
1,1,1,1,1,1,1,1,1,1,1,1,1
endlayer

layer
1,1,1,1,1,1,1,1,1,1,1,1,1
1,1,1,1,1,1,1,1,1,1,1,1,1
1,1,1,1,0,7,8,7,0,1,1,1,1
1,1,1,0,8,9,10,9,8,0,1,1,1
1,1,0,12,10,10,10,10,10,11,0,1,1
1,1,0,9,10,10,0,10,10,9,0,1,1
1,1,12,10,10,0,0,10,10,10,11,1,1
1,1,12,10,10,0,0,0,10,10,11,1,1
1,1,0,9,10,10,0,0,10,9,0,1,1
1,1,0,12,10,10,0,10,10,11,0,1,1
1,1,1,0,13,9,14,9,13,0,1,1,1
1,1,1,1,0,0,0,0,0,1,1,1,1
1,1,1,1,1,1,1,1,1,1,1,1,1
1,1,1,1,1,1,1,1,1,1,1,1,1
endlayer

layer
1,1,1,1,1,1,1,1,1,1,1,1,1
1,1,1,1,1,1,1,1,1,1,1,1,1
1,1,1,1,0,15,15,15,0,1,1,1,1
1,1,1,0,15,9,0,9,15,0,1,1,1
1,1,0,15,0,0,0,0,0,15,0,1,1
1,1,7,9,0,0,0,0,0,9,7,1,1
1,1,15,0,0,0,0,0,0,0,15,1,1
1,1,15,0,0,0,0,0,0,0,15,1,1
1,1,7,9,0,0,0,0,0,9,7,1,1
1,1,0,15,0,0,0,0,0,15,0,1,1
1,1,1,0,15,9,0,9,15,0,1,1,1
1,1,1,1,0,0,0,0,0,1,1,1,1
1,1,1,1,1,1,1,1,1,1,1,1,1
1,1,1,1,1,1,1,1,1,1,1,1,1
endlayer

layer
1,1,1,1,1,1,1,1,1,1,1,1,1
1,1,1,1,1,1,1,1,1,1,1,1,1
1,1,1,1,0,18,17,16,0,1,1,1,1
1,1,1,0,12,9,0,9,11,0,1,1,1
1,1,0,8,19,0,0,0,19,8,0,1,1
1,1,17,9,0,0,0,0,0,9,17,1,1
1,1,18,0,0,0,0,0,0,0,16,1,1
1,1,18,0,0,0,0,0,0,0,16,1,1
1,1,20,9,0,0,0,0,0,9,20,1,1
1,1,0,13,19,0,0,0,19,13,0,1,1
1,1,1,0,12,9,14,9,11,0,1,1,1
1,1,1,1,0,0,0,0,0,1,1,1,1
1,1,1,1,1,1,1,1,1,1,1,1,1
1,1,1,1,1,1,1,1,1,1,1,1,1
endlayer

layer
1,1,1,1,1,1,1,1,1,1,1,1,1
1,1,1,1,1,1,17,1,1,1,1,1,1
1,1,1,1,15,21,21,21,15,1,1,1,1
1,1,1,0,22,9,20,9,22,0,1,1,1
1,1,17,17,9,0,0,0,9,17,17,1,1
1,15,23,9,0,0,0,0,0,9,23,15,1
1,17,21,16,0,0,0,0,0,18,21,17,1
1,20,21,16,0,0,0,0,0,18,21,20,1
1,15,23,21,0,0,0,0,0,9,23,15,1
1,1,20,20,9,0,0,0,9,20,16,1,1
1,1,1,15,23,9,24,9,23,15,1,1,1
1,1,1,1,0,20,19,20,0,1,1,1,1
1,1,1,1,1,1,1,1,1,1,1,1,1
1,1,1,1,1,1,1,1,1,1,1,1,1
endlayer

layer
1,1,1,1,1,1,1,1,1,1,1,1,1
1,1,1,1,1,1,15,1,1,1,1,1,1
1,1,1,1,18,11,22,12,16,1,1,1,1
1,1,1,17,9,21,21,21,9,17,1,1,1
1,25,13,21,9,20,0,20,9,21,13,1,1
1,13,9,21,16,0,0,0,18,21,9,8,1
1,8,21,21,0,0,0,0,0,21,26,11,1
1,12,21,21,0,0,0,0,0,21,21,11,1
1,21,9,21,16,0,0,0,18,21,9,13,1
1,1,21,21,9,0,0,0,9,21,8,1,1
1,1,15,23,9,16,0,18,9,23,15,1,1
1,1,1,1,27,9,19,9,27,1,1,1,1
1,1,1,1,1,15,1,15,1,1,1,1,1
1,1,1,1,1,1,1,1,1,1,1,1,1
endlayer

layer
1,1,1,1,1,1,1,1,1,1,1,1,1
1,1,1,1,1,1,15,1,1,1,1,1,1
1,1,1,11,24,15,9,1,24,12,1,1,1
1,1,27,24,9,23,21,23,9,24,27,1,1
1,1,0,21,21,21,20,21,21,21,0,1,1
1,1,9,21,21,0,0,0,21,26,9,1,1
1,1,0,21,16,0,0,0,18,26,8,1,1
1,1,0,21,16,0,0,0,18,26,13,1,1
15,23,9,21,21,0,0,0,21,26,9,23,15
1,1,22,21,9,0,0,0,9,21,22,1,1
1,1,27,9,9,11,14,12,9,9,27,1,1
1,1,1,1,27,9,0,9,27,1,1,1,1
1,1,1,1,1,22,15,22,1,1,1,1,1
1,1,1,1,1,15,1,15,1,1,1,1,1
endlayer

layer
1,1,1,1,1,1,1,1,1,1,1,1,1
1,1,1,1,15,1,1,1,15,1,1,1,1
1,1,1,1,22,1,9,1,22,1,1,1,1
1,1,15,0,9,0,0,0,9,15,15,1,1
1,1,22,0,12,8,0,8,11,0,22,1,1
15,23,9,12,19,20,19,20,19,11,9,23,15
1,1,0,12,21,24,0,24,21,11,15,1,1
1,1,15,0,19,0,0,0,19,0,0,1,1
1,15,9,12,13,24,0,24,13,13,9,1,1
1,1,0,24,9,17,19,17,9,24,15,1,1
1,15,23,9,19,0,0,0,19,9,23,15,1
1,1,1,25,27,9,23,9,27,1,1,1,1
1,1,1,15,15,15,1,15,15,15,1,1,1
1,1,1,1,1,1,1,1,1,1,1,1,1
endlayer

layer
1,1,1,1,1,1,1,1,1,1,1,1,1
1,1,1,1,15,1,15,1,15,1,1,1,1
1,1,1,15,9,15,9,1,9,15,1,1,1
1,1,1,1,0,15,15,15,0,1,1,1,1
1,1,15,0,15,15,15,15,15,0,1,1,1
1,1,9,15,15,15,8,15,15,15,9,15,1
1,1,15,0,15,15,20,15,15,0,0,1,1
1,1,22,15,15,16,0,18,15,15,15,1,1
15,23,9,15,15,15,17,15,15,15,9,23,15
1,1,15,15,9,15,15,15,9,15,1,1,1
1,1,1,9,0,15,0,0,0,9,1,1,1
1,1,1,1,23,9,0,9,23,27,1,1,1
1,1,1,1,15,15,1,15,15,1,1,1,1
1,1,1,1,1,1,1,1,1,1,1,1,1
endlayer

layer
1,1,1,1,1,1,15,1,1,1,1,1,1
1,1,1,1,1,15,22,1,1,1,1,1,1
1,1,1,1,9,1,9,15,9,1,1,1,1
1,1,15,1,15,1,1,1,15,1,1,1,1
1,1,22,15,1,1,15,1,1,1,15,1,1
1,15,9,15,15,15,15,15,1,15,9,1,1
1,1,1,15,1,15,15,15,1,15,1,1,1
1,1,1,1,15,15,15,15,15,1,1,1,1
15,9,1,1,15,15,15,1,1,15,1,9,15
1,1,1,15,9,1,1,15,9,1,1,1,1
1,1,1,1,15,1,1,1,15,1,1,1,1
1,1,1,1,1,9,24,9,1,1,1,1,1
1,1,1,1,1,1,1,1,1,1,1,1,1
1,1,1,1,1,1,1,1,1,1,1,1,1
endlayer

layer
1,1,1,1,1,1,15,1,1,1,1,1,1
1,1,1,1,1,1,9,1,1,1,1,1,1
1,1,1,1,1,1,15,1,1,1,1,1,1
1,1,1,1,1,1,1,1,1,1,1,1,1
1,1,1,1,1,1,1,1,1,1,1,1,1
1,15,9,15,1,1,1,15,1,1,9,15,1
1,1,1,1,1,15,1,1,1,1,1,1,1
1,1,1,1,1,1,15,1,1,1,1,1,1
1,9,1,1,1,1,1,1,15,1,1,9,1
1,1,1,1,9,1,1,1,9,1,1,1,1
1,1,1,1,15,1,1,1,15,1,1,1,1
1,1,1,1,1,1,1,9,1,1,1,1,1
1,1,1,1,1,1,1,1,1,1,1,1,1
1,1,1,1,1,1,1,1,1,1,1,1,1
endlayer

layer
1,1,1,1,1,1,1,1,1,1,1,1,1
1,1,1,1,1,1,9,1,1,1,1,1,1
1,1,1,1,1,1,1,1,1,1,1,1,1
1,1,1,1,1,1,1,1,1,1,1,1,1
1,1,1,1,1,1,1,1,1,1,1,1,1
1,1,9,1,1,1,1,1,1,1,9,15,1
1,1,1,1,1,1,1,1,1,1,1,1,1
1,1,1,1,1,1,1,1,1,1,1,1,1
1,1,1,1,1,1,1,1,1,1,1,1,1
1,1,1,1,9,1,1,1,9,1,1,1,1
1,1,1,1,15,1,1,1,1,1,1,1,1
1,1,1,1,1,1,1,1,1,1,1,1,1
1,1,1,1,1,1,1,1,1,1,1,1,1
1,1,1,1,1,1,1,1,1,1,1,1,1
endlayer

layer
1,1,1,1,1,1,1,1,1,1,1,1,1
1,1,1,1,1,1,1,1,1,1,1,1,1
1,1,1,1,1,1,1,1,1,1,1,1,1
1,1,1,1,1,1,1,1,1,1,1,1,1
1,1,1,1,1,1,1,1,1,1,1,1,1
1,1,1,1,1,1,1,1,1,1,9,1,1
1,1,1,1,1,1,1,1,1,1,1,1,1
1,1,1,1,1,1,1,1,1,1,1,1,1
1,1,1,1,1,1,1,1,1,1,1,1,1
1,1,1,1,9,1,1,1,1,1,1,1,1
1,1,1,1,1,1,1,1,1,1,1,1,1
1,1,1,1,1,1,1,1,1,1,1,1,1
1,1,1,1,1,1,1,1,1,1,1,1,1
1,1,1,1,1,1,1,1,1,1,1,1,1
endlayer

