
# Created by Ruins mod version 16.7 Ingame Parser
# authoring Player: lafuller

weight=1
embed_into_distance=-10
acceptable_target_blocks=
unacceptable_target_blocks=flowing_water,water,flowing_lava,lava
dimensions=16,27,27
allowable_overhang=0
max_leveling=5
leveling_buffer=-1
preserve_water=0
preserve_lava=0

rule1=0,100,preserveBlock
rule2=0,100,minecraft:stone-5
rule3=0,100,minecraft:stone_slab-13
rule4=0,100,minecraft:stone-6
rule5=0,100,minecraft:stone_slab-8
rule6=0,100,minecraft:stained_hardened_clay-9
rule7=0,100,minecraft:stained_glass-8
rule8=0,100,minecraft:stone_brick_stairs-1
rule9=0,100,minecraft:sea_lantern-0
rule10=0,100,minecraft:stone_brick_stairs-3
rule11=0,100,minecraft:stone_brick_stairs-2
rule12=0,100,minecraft:stone_brick_stairs-0
rule13=0,100,minecraft:stone-4
rule14=0,100,minecraft:stone_brick_stairs-5
rule15=0,100,minecraft:stone_brick_stairs-7
rule16=0,100,minecraft:stone_brick_stairs-6
rule17=0,100,minecraft:stone_brick_stairs-4
rule18=0,100,minecraft:stone_slab-0
rule19=0,100,minecraft:double_stone_slab-8

layer
1,1,1,1,1,1,1,1,1,1,2,2,2,2,2,2,2,1,1,1,1,1,1,1,1,1,1
1,1,1,1,1,1,1,2,2,2,3,3,3,4,3,3,3,2,2,2,1,1,1,1,1,1,1
1,1,1,1,2,2,2,4,5,3,3,3,6,4,6,3,3,3,5,4,2,2,2,1,1,1,1
1,1,1,2,2,5,5,4,7,7,6,6,6,4,6,6,6,7,7,4,5,5,2,2,1,1,1
1,1,2,2,3,5,5,4,6,7,5,5,6,4,6,5,5,7,6,4,5,5,3,2,2,1,1
1,1,2,5,5,3,3,4,6,6,6,5,6,4,6,5,6,6,6,4,3,3,5,5,2,1,1
1,1,2,5,5,3,4,4,5,6,7,3,6,4,6,3,7,6,5,4,4,3,5,5,2,1,1
1,2,4,4,4,4,4,4,4,7,7,3,3,4,3,3,7,7,4,4,4,4,4,4,4,2,1
1,2,5,7,6,6,5,4,5,5,7,7,6,4,6,7,7,5,5,4,5,6,6,7,5,2,1
1,2,3,7,7,6,6,7,5,5,7,5,5,4,5,5,7,5,5,7,6,6,7,7,3,2,1
2,3,3,6,5,6,7,7,7,7,7,7,5,4,5,7,7,7,7,7,7,6,5,6,3,3,2
2,3,3,6,5,5,3,3,7,5,7,7,5,4,5,7,7,5,7,3,3,5,5,6,3,3,2
2,3,6,6,6,6,6,3,6,5,5,5,7,4,7,5,5,5,6,3,6,6,6,6,6,3,2
2,4,4,4,4,4,4,4,4,4,4,4,4,4,4,4,4,4,4,4,4,4,4,4,4,4,2
2,3,6,6,6,6,6,3,6,5,5,5,7,4,7,5,5,5,6,3,6,6,6,6,6,3,2
2,3,3,6,5,5,3,3,7,5,7,7,5,4,5,7,7,5,7,3,3,5,5,6,3,3,2
2,3,3,6,5,6,7,7,7,7,7,7,5,4,5,7,7,7,7,7,7,6,5,6,3,3,2
1,2,3,7,7,6,6,7,5,5,7,5,5,4,5,5,7,5,5,7,6,6,7,7,3,2,1
1,2,5,7,6,6,5,4,5,5,7,7,6,4,6,7,7,5,5,4,5,6,6,7,5,2,1
1,2,4,4,4,4,4,4,4,7,7,3,3,4,3,3,7,7,4,4,4,4,4,4,4,2,1
1,1,2,5,5,3,4,4,5,6,7,3,6,4,6,3,7,6,5,4,4,3,5,5,2,1,1
1,1,2,5,5,3,3,4,6,6,6,5,6,4,6,5,6,6,6,4,3,3,5,5,2,1,1
1,1,2,2,3,5,5,4,6,7,5,5,6,4,6,5,5,7,6,4,5,5,3,2,2,1,1
1,1,1,2,2,5,5,4,7,7,6,6,6,4,6,6,6,7,7,4,5,5,2,2,1,1,1
1,1,1,1,2,2,2,4,5,3,3,3,6,4,6,3,3,3,5,4,2,2,2,1,1,1,1
1,1,1,1,1,1,1,2,2,2,3,3,3,4,3,3,3,2,2,2,1,1,1,1,1,1,1
1,1,1,1,1,1,1,1,1,1,2,2,2,2,2,2,2,1,1,1,1,1,1,1,1,1,1
endlayer

layer
1,1,1,1,1,1,1,1,1,1,2,2,2,2,2,2,2,1,1,1,1,1,1,1,1,1,1
1,1,1,1,1,1,1,2,2,2,0,0,0,0,0,0,0,2,2,2,1,1,1,1,1,1,1
1,1,1,1,2,2,2,0,0,0,0,0,0,0,0,0,0,0,0,0,2,2,2,1,1,1,1
1,1,1,2,2,0,0,0,0,0,0,0,0,0,0,0,0,0,0,0,0,0,2,2,1,1,1
1,1,2,2,0,0,0,0,0,0,0,0,0,0,0,0,0,0,0,0,0,0,0,2,2,1,1
1,1,2,0,0,0,0,0,0,0,0,0,0,0,0,0,0,0,0,0,0,0,0,0,2,1,1
1,1,2,0,0,0,0,0,0,0,0,0,0,0,0,0,0,0,0,0,0,0,0,0,2,1,1
1,2,0,0,0,0,0,0,0,0,0,0,0,0,0,0,0,0,0,0,0,0,0,0,0,2,1
1,2,0,0,0,0,0,0,0,0,0,0,0,0,0,0,0,0,0,0,0,0,0,0,0,2,1
1,2,0,0,0,0,0,0,0,0,0,0,0,0,0,0,0,0,0,0,0,0,0,0,0,2,1
2,0,0,0,0,0,0,0,0,0,0,0,0,0,0,0,0,0,0,0,0,0,0,0,0,0,2
2,0,0,0,0,0,0,0,0,0,0,0,0,0,0,0,0,0,0,0,0,0,0,0,0,0,2
2,0,0,0,0,0,0,0,0,0,0,0,0,0,0,0,0,0,0,0,0,0,0,0,0,0,2
2,0,0,0,0,0,0,0,0,0,0,0,0,0,0,0,0,0,0,0,0,0,0,0,0,0,2
2,0,0,0,0,0,0,0,0,0,0,0,0,0,0,0,0,0,0,0,0,0,0,0,0,0,2
2,0,0,0,0,0,0,0,0,0,0,0,0,0,0,0,0,0,0,0,0,0,0,0,0,0,2
2,0,0,0,0,0,0,0,0,0,0,0,0,0,0,0,0,0,0,0,0,0,0,0,0,0,2
1,2,0,0,0,0,0,0,0,0,0,0,0,0,0,0,0,0,0,0,0,0,0,0,0,2,1
1,2,0,0,0,0,0,0,0,0,0,0,0,0,0,0,0,0,0,0,0,0,0,0,0,2,1
1,2,0,0,0,0,0,0,0,0,0,0,0,0,0,0,0,0,0,0,0,0,0,0,0,2,1
1,1,2,0,0,0,0,0,0,0,0,0,0,0,0,0,0,0,0,0,0,0,0,0,2,1,1
1,1,2,0,0,0,0,0,0,0,0,0,0,0,0,0,0,0,0,0,0,0,0,0,2,1,1
1,1,2,2,0,0,0,0,0,0,0,0,0,0,0,0,0,0,0,0,0,0,0,2,2,1,1
1,1,1,2,2,0,0,0,0,0,0,0,0,0,0,0,0,0,0,0,0,0,2,2,1,1,1
1,1,1,1,2,2,2,0,0,0,0,0,0,0,0,0,0,0,0,0,2,2,2,1,1,1,1
1,1,1,1,1,1,1,2,2,2,0,0,0,0,0,0,0,2,2,2,1,1,1,1,1,1,1
1,1,1,1,1,1,1,1,1,1,2,2,2,2,2,2,2,1,1,1,1,1,1,1,1,1,1
endlayer

layer
1,1,1,1,1,1,1,1,1,1,2,2,2,2,2,2,2,1,1,1,1,1,1,1,1,1,1
1,1,1,1,1,1,1,2,2,2,0,0,0,0,0,0,0,2,2,2,1,1,1,1,1,1,1
1,1,1,1,2,2,2,0,0,0,0,0,0,0,0,0,0,0,0,0,2,2,2,1,1,1,1
1,1,1,2,2,0,0,0,0,0,0,0,0,0,0,0,0,0,0,0,0,0,2,2,1,1,1
1,1,2,2,0,0,0,0,0,0,0,0,0,0,0,0,0,0,0,0,0,0,0,2,2,1,1
1,1,2,0,0,0,0,0,0,0,0,0,0,0,0,0,0,0,0,0,0,0,0,0,2,1,1
1,1,2,0,0,0,0,0,0,0,0,0,0,0,0,0,0,0,0,0,0,0,0,0,2,1,1
1,2,0,0,0,0,0,0,0,0,0,0,0,0,0,0,0,0,0,0,0,0,0,0,0,2,1
1,2,0,0,0,0,0,0,0,0,0,0,0,0,0,0,0,0,0,0,0,0,0,0,0,2,1
1,2,0,0,0,0,0,0,0,0,0,0,0,0,0,0,0,0,0,0,0,0,0,0,0,2,1
2,0,0,0,0,0,0,0,0,0,0,0,0,0,0,0,0,0,0,0,0,0,0,0,0,0,2
2,0,0,0,0,0,0,0,0,0,0,0,0,0,0,0,0,0,0,0,0,0,0,0,0,0,2
2,0,0,0,0,0,0,0,0,0,0,0,0,0,0,0,0,0,0,0,0,0,0,0,0,0,2
2,0,0,0,0,0,0,0,0,0,0,0,0,0,0,0,0,0,0,0,0,0,0,0,0,0,2
2,0,0,0,0,0,0,0,0,0,0,0,0,0,0,0,0,0,0,0,0,0,0,0,0,0,2
2,0,0,0,0,0,0,0,0,0,0,0,0,0,0,0,0,0,0,0,0,0,0,0,0,0,2
2,0,0,0,0,0,0,0,0,0,0,0,0,0,0,0,0,0,0,0,0,0,0,0,0,0,2
1,2,0,0,0,0,0,0,0,0,0,0,0,0,0,0,0,0,0,0,0,0,0,0,0,2,1
1,2,0,0,0,0,0,0,0,0,0,0,0,0,0,0,0,0,0,0,0,0,0,0,0,2,1
1,2,0,0,0,0,0,0,0,0,0,0,0,0,0,0,0,0,0,0,0,0,0,0,0,2,1
1,1,2,0,0,0,0,0,0,0,0,0,0,0,0,0,0,0,0,0,0,0,0,0,2,1,1
1,1,2,0,0,0,0,0,0,0,0,0,0,0,0,0,0,0,0,0,0,0,0,0,2,1,1
1,1,2,2,0,0,0,0,0,0,0,0,0,0,0,0,0,0,0,0,0,0,0,2,2,1,1
1,1,1,2,2,0,0,0,0,0,0,0,0,0,0,0,0,0,0,0,0,0,2,2,1,1,1
1,1,1,1,2,2,2,0,0,0,0,0,0,0,0,0,0,0,0,0,2,2,2,1,1,1,1
1,1,1,1,1,1,1,2,2,2,0,0,0,0,0,0,0,2,2,2,1,1,1,1,1,1,1
1,1,1,1,1,1,1,1,1,1,2,2,2,2,2,2,2,1,1,1,1,1,1,1,1,1,1
endlayer

layer
1,1,1,1,1,1,1,1,1,1,2,2,2,2,2,2,2,1,1,1,1,1,1,1,1,1,1
1,1,1,1,1,1,1,2,2,2,0,0,0,0,0,0,0,2,2,2,1,1,1,1,1,1,1
1,1,1,1,2,2,2,0,0,0,0,0,0,0,0,0,0,0,0,0,2,2,2,1,1,1,1
1,1,1,2,2,0,0,0,0,0,0,0,0,0,0,0,0,0,0,0,0,0,2,2,1,1,1
1,1,2,2,0,0,0,0,0,0,0,0,0,0,0,0,0,0,0,0,0,0,0,2,2,1,1
1,1,2,0,0,0,0,0,0,0,0,0,0,0,0,0,0,0,0,0,0,0,0,0,2,1,1
1,1,2,0,0,0,0,0,0,0,0,0,0,0,0,0,0,0,0,0,0,0,0,0,2,1,1
1,2,0,0,0,0,0,0,0,0,0,0,0,0,0,0,0,0,0,0,0,0,0,0,0,2,1
1,2,0,0,0,0,0,0,0,0,0,0,0,0,0,0,0,0,0,0,0,0,0,0,0,2,1
1,2,0,0,0,0,0,0,0,0,0,0,0,0,0,0,0,0,0,0,0,0,0,0,0,2,1
2,0,0,0,0,0,0,0,0,0,0,0,0,0,0,0,0,0,0,0,0,0,0,0,0,0,2
2,0,0,0,0,0,0,0,0,0,0,0,0,0,0,0,0,0,0,0,0,0,0,0,0,0,2
2,0,0,0,0,0,0,0,0,0,0,0,0,0,0,0,0,0,0,0,0,0,0,0,0,0,2
2,0,0,0,0,0,0,0,0,0,0,0,0,0,0,0,0,0,0,0,0,0,0,0,0,0,2
2,0,0,0,0,0,0,0,0,0,0,0,0,0,0,0,0,0,0,0,0,0,0,0,0,0,2
2,0,0,0,0,0,0,0,0,0,0,0,0,0,0,0,0,0,0,0,0,0,0,0,0,0,2
2,0,0,0,0,0,0,0,0,0,0,0,0,0,0,0,0,0,0,0,0,0,0,0,0,0,2
1,2,0,0,0,0,0,0,0,0,0,0,0,0,0,0,0,0,0,0,0,0,0,0,0,2,1
1,2,0,0,0,0,0,0,0,0,0,0,0,0,0,0,0,0,0,0,0,0,0,0,0,2,1
1,2,0,0,0,0,0,0,0,0,0,0,0,0,0,0,0,0,0,0,0,0,0,0,0,2,1
1,1,2,0,0,0,0,0,0,0,0,0,0,0,0,0,0,0,0,0,0,0,0,0,2,1,1
1,1,2,0,0,0,0,0,0,0,0,0,0,0,0,0,0,0,0,0,0,0,0,0,2,1,1
1,1,2,2,0,0,0,0,0,0,0,0,0,0,0,0,0,0,0,0,0,0,0,2,2,1,1
1,1,1,2,2,0,0,0,0,0,0,0,0,0,0,0,0,0,0,0,0,0,2,2,1,1,1
1,1,1,1,2,2,2,0,0,0,0,0,0,0,0,0,0,0,0,0,2,2,2,1,1,1,1
1,1,1,1,1,1,1,2,2,2,0,0,0,0,0,0,0,2,2,2,1,1,1,1,1,1,1
1,1,1,1,1,1,1,1,1,1,2,2,2,2,2,2,2,1,1,1,1,1,1,1,1,1,1
endlayer

layer
1,1,1,1,1,1,1,1,1,1,4,4,4,4,4,4,4,1,1,1,1,1,1,1,1,1,1
1,1,1,1,1,1,1,4,4,4,4,8,8,4,8,8,4,4,4,4,1,1,1,1,1,1,1
1,1,1,1,4,4,4,4,4,4,4,4,4,3,4,4,4,4,4,4,4,4,4,1,1,1,1
1,1,1,1,4,4,4,4,4,3,3,4,4,3,4,4,3,3,4,4,4,4,4,1,1,1,1
1,1,4,4,4,4,4,7,7,4,3,3,3,9,3,3,3,4,7,7,4,4,4,4,4,1,1
1,1,4,4,4,3,4,7,7,4,3,4,4,4,4,4,3,4,7,7,4,3,4,4,4,1,1
1,1,4,4,4,4,5,5,4,4,7,7,5,4,5,7,7,4,4,5,5,4,4,4,4,1,1
1,4,4,4,7,7,5,5,3,4,7,7,5,4,5,7,7,4,3,5,5,7,7,4,4,4,1
1,4,4,4,7,7,4,3,9,3,3,4,5,4,5,4,3,3,9,3,4,7,7,4,4,4,1
1,4,4,3,4,4,4,4,3,5,4,4,4,3,4,4,4,5,3,4,4,4,4,3,4,4,1
4,4,4,3,3,3,7,7,3,4,7,7,4,3,4,7,7,4,3,7,7,3,3,3,4,4,4
4,11,4,4,3,4,7,7,4,4,7,7,4,5,4,7,7,4,4,7,7,4,3,4,4,10,4
4,11,4,4,3,4,5,5,5,4,4,4,3,5,3,4,4,4,5,5,5,4,3,4,4,10,4
4,4,3,3,9,4,4,4,4,3,3,5,5,9,5,5,3,3,4,4,4,4,9,3,3,4,4
4,11,4,4,3,4,5,5,5,4,4,4,3,5,3,4,4,4,5,5,5,4,3,4,4,10,4
4,11,4,4,3,4,7,7,4,4,7,7,4,5,4,7,7,4,4,7,7,4,3,4,4,10,4
4,4,4,3,3,3,7,7,3,4,7,7,4,3,4,7,7,4,3,7,7,3,3,3,4,4,4
1,4,4,3,4,4,4,4,3,5,4,4,4,3,4,4,4,5,3,4,4,4,4,3,4,4,1
1,4,4,4,7,7,4,3,9,3,3,4,5,4,5,4,3,3,9,3,4,7,7,4,4,4,1
1,4,4,4,7,7,5,5,3,4,7,7,5,4,5,7,7,4,3,5,5,7,7,4,4,4,1
1,1,4,4,4,4,5,5,4,4,7,7,5,4,5,7,7,4,4,5,5,4,4,4,4,1,1
1,1,4,4,4,3,4,7,7,4,3,4,4,4,4,4,3,4,7,7,4,3,4,4,4,1,1
1,1,4,4,4,4,4,7,7,4,3,3,3,9,3,3,3,4,7,7,4,4,4,4,4,1,1
1,1,1,2,4,4,4,4,4,3,3,4,4,3,4,4,3,3,4,4,4,4,4,1,1,1,1
1,1,1,1,4,4,4,4,4,4,4,4,4,3,4,4,4,4,4,4,4,4,4,1,1,1,1
1,1,1,1,1,1,1,4,4,4,4,12,12,4,12,12,4,4,4,4,1,1,1,1,1,1,1
1,1,1,1,1,1,1,1,1,1,4,4,4,4,4,4,4,1,1,1,1,1,1,1,1,1,1
endlayer

layer
1,1,1,1,1,1,1,1,1,1,4,0,0,0,0,0,4,1,1,1,1,1,1,1,1,1,1
1,1,1,1,1,1,1,4,1,1,4,0,0,0,0,0,4,1,1,4,1,1,1,1,1,1,1
1,1,1,1,4,1,1,13,13,13,0,0,0,0,0,0,0,13,13,13,1,1,4,1,1,1,1
1,1,1,1,1,13,4,0,0,0,0,0,0,0,0,0,0,0,0,0,4,13,1,1,1,1,1
1,1,4,1,13,0,0,0,0,0,0,0,0,0,0,0,0,0,0,0,0,0,13,1,4,1,1
1,1,1,13,0,0,0,0,0,0,0,0,0,0,0,0,0,0,0,0,0,0,0,13,1,1,1
1,1,1,4,0,0,0,0,0,0,0,0,0,0,0,0,0,0,0,0,0,0,0,4,1,1,1
1,4,13,0,0,0,0,0,0,0,0,0,0,0,0,0,0,0,0,0,0,0,0,0,13,4,1
1,1,13,0,0,0,0,0,0,0,0,0,0,0,0,0,0,0,0,0,0,0,0,0,13,1,1
1,1,13,0,0,0,0,0,0,0,0,0,0,0,0,0,0,0,0,0,0,0,0,0,13,1,1
4,4,0,0,0,0,0,0,0,0,0,0,0,0,0,0,0,0,0,0,0,0,0,0,0,4,4
0,0,0,0,0,0,0,0,0,0,0,0,0,0,0,0,0,0,0,0,0,0,0,0,0,0,0
0,0,0,0,0,0,0,0,0,0,0,0,0,0,0,0,0,0,0,0,0,0,0,0,0,0,0
0,0,0,0,0,0,0,0,0,0,0,0,0,0,0,0,0,0,0,0,0,0,0,0,0,0,0
0,0,0,0,0,0,0,0,0,0,0,0,0,0,0,0,0,0,0,0,0,0,0,0,0,0,0
0,0,0,0,0,0,0,0,0,0,0,0,0,0,0,0,0,0,0,0,0,0,0,0,0,0,0
4,4,0,0,0,0,0,0,0,0,0,0,0,0,0,0,0,0,0,0,0,0,0,0,0,4,4
1,1,13,0,0,0,0,0,0,0,0,0,0,0,0,0,0,0,0,0,0,0,0,0,13,1,1
1,1,13,0,0,0,0,0,0,0,0,0,0,0,0,0,0,0,0,0,0,0,0,0,13,1,1
1,4,13,0,0,0,0,0,0,0,0,0,0,0,0,0,0,0,0,0,0,0,0,0,13,4,1
1,1,1,4,0,0,0,0,0,0,0,0,0,0,0,0,0,0,0,0,0,0,0,4,1,1,1
1,1,1,13,0,0,0,0,0,0,0,0,0,0,0,0,0,0,0,0,0,0,0,13,1,1,1
1,1,4,1,13,0,0,0,0,0,0,0,0,0,0,0,0,0,0,0,0,0,13,1,4,1,1
1,1,1,1,1,13,4,0,0,0,0,0,0,0,0,0,0,0,0,0,4,13,1,1,1,1,1
1,1,1,1,4,1,1,13,13,13,0,0,0,0,0,0,0,13,13,13,1,1,4,1,1,1,1
1,1,1,1,1,1,1,4,1,1,4,0,0,0,0,0,4,1,1,4,1,1,1,1,1,1,1
1,1,1,1,1,1,1,1,1,1,4,0,0,0,0,0,4,1,1,1,1,1,1,1,1,1,1
endlayer

layer
1,1,1,1,1,1,1,1,1,1,4,0,0,0,0,0,4,1,1,1,1,1,1,1,1,1,1
1,1,1,1,1,1,1,4,1,1,4,0,0,0,0,0,4,1,1,4,1,1,1,1,1,1,1
1,1,1,1,4,1,1,13,13,13,0,0,0,0,0,0,0,13,13,13,1,1,4,1,1,1,1
1,1,1,1,1,13,4,0,0,0,0,0,0,0,0,0,0,0,0,0,4,13,1,1,1,1,1
1,1,4,1,13,0,0,0,0,0,0,0,0,0,0,0,0,0,0,0,0,0,13,1,4,1,1
1,1,1,13,0,0,0,0,0,0,0,0,0,0,0,0,0,0,0,0,0,0,0,13,1,1,1
1,1,1,4,0,0,0,0,0,0,0,0,0,0,0,0,0,0,0,0,0,0,0,4,1,1,1
1,4,13,0,0,0,0,0,0,0,0,0,0,0,0,0,0,0,0,0,0,0,0,0,13,4,1
1,1,13,0,0,0,0,0,0,0,0,0,0,0,0,0,0,0,0,0,0,0,0,0,13,1,1
1,1,13,0,0,0,0,0,0,0,0,0,0,0,0,0,0,0,0,0,0,0,0,0,13,1,1
4,4,0,0,0,0,0,0,0,0,0,0,0,0,0,0,0,0,0,0,0,0,0,0,0,4,4
0,0,0,0,0,0,0,0,0,0,0,0,0,0,0,0,0,0,0,0,0,0,0,0,0,0,0
0,0,0,0,0,0,0,0,0,0,0,0,0,0,0,0,0,0,0,0,0,0,0,0,0,0,0
0,0,0,0,0,0,0,0,0,0,0,0,0,0,0,0,0,0,0,0,0,0,0,0,0,0,0
0,0,0,0,0,0,0,0,0,0,0,0,0,0,0,0,0,0,0,0,0,0,0,0,0,0,0
0,0,0,0,0,0,0,0,0,0,0,0,0,0,0,0,0,0,0,0,0,0,0,0,0,0,0
4,4,0,0,0,0,0,0,0,0,0,0,0,0,0,0,0,0,0,0,0,0,0,0,0,4,4
1,1,13,0,0,0,0,0,0,0,0,0,0,0,0,0,0,0,0,0,0,0,0,0,13,1,1
1,1,13,0,0,0,0,0,0,0,0,0,0,0,0,0,0,0,0,0,0,0,0,0,13,1,1
1,4,13,0,0,0,0,0,0,0,0,0,0,0,0,0,0,0,0,0,0,0,0,0,13,4,1
1,1,1,4,0,0,0,0,0,0,0,0,0,0,0,0,0,0,0,0,0,0,0,4,1,1,1
1,1,1,13,0,0,0,0,0,0,0,0,0,0,0,0,0,0,0,0,0,0,0,13,1,1,1
1,1,4,1,13,0,0,0,0,0,0,0,0,0,0,0,0,0,0,0,0,0,13,1,4,1,1
1,1,1,1,1,13,4,0,0,0,0,0,0,0,0,0,0,0,0,0,4,13,1,1,1,1,1
1,1,1,1,4,1,1,13,13,13,0,0,0,0,0,0,0,13,13,13,1,1,4,1,1,1,1
1,1,1,1,1,1,1,4,1,1,4,0,0,0,0,0,4,1,1,4,1,1,1,1,1,1,1
1,1,1,1,1,1,1,1,1,1,4,0,0,0,0,0,4,1,1,1,1,1,1,1,1,1,1
endlayer

layer
1,1,1,1,1,1,1,1,1,1,4,0,0,0,0,0,4,1,1,1,1,1,1,1,1,1,1
1,1,1,1,1,1,1,4,1,1,4,0,0,0,0,0,4,1,1,4,1,1,1,1,1,1,1
1,1,1,1,4,1,1,9,13,13,0,0,0,0,0,0,0,13,13,9,1,1,4,1,1,1,1
1,1,1,1,1,13,4,0,0,0,0,0,0,0,0,0,0,0,0,0,4,13,1,1,1,1,1
1,1,4,1,13,0,0,0,0,0,0,0,0,0,0,0,0,0,0,0,0,0,13,1,4,1,1
1,1,1,13,0,0,0,0,0,0,0,0,0,0,0,0,0,0,0,0,0,0,0,13,1,1,1
1,1,1,4,0,0,0,0,0,0,0,0,0,0,0,0,0,0,0,0,0,0,0,4,1,1,1
1,4,9,0,0,0,0,0,0,0,0,0,0,0,0,0,0,0,0,0,0,0,0,0,9,4,1
1,1,13,0,0,0,0,0,0,0,0,0,0,0,0,0,0,0,0,0,0,0,0,0,13,1,1
1,1,13,0,0,0,0,0,0,0,0,0,0,0,0,0,0,0,0,0,0,0,0,0,13,1,1
4,4,0,0,0,0,0,0,0,0,0,0,0,0,0,0,0,0,0,0,0,0,0,0,0,4,4
0,0,0,0,0,0,0,0,0,0,0,0,0,0,0,0,0,0,0,0,0,0,0,0,0,0,0
0,0,0,0,0,0,0,0,0,0,0,0,0,0,0,0,0,0,0,0,0,0,0,0,0,0,0
0,0,0,0,0,0,0,0,0,0,0,0,0,0,0,0,0,0,0,0,0,0,0,0,0,0,0
0,0,0,0,0,0,0,0,0,0,0,0,0,0,0,0,0,0,0,0,0,0,0,0,0,0,0
0,0,0,0,0,0,0,0,0,0,0,0,0,0,0,0,0,0,0,0,0,0,0,0,0,0,0
4,4,0,0,0,0,0,0,0,0,0,0,0,0,0,0,0,0,0,0,0,0,0,0,0,4,4
1,1,13,0,0,0,0,0,0,0,0,0,0,0,0,0,0,0,0,0,0,0,0,0,13,1,1
1,1,13,0,0,0,0,0,0,0,0,0,0,0,0,0,0,0,0,0,0,0,0,0,13,1,1
1,4,9,0,0,0,0,0,0,0,0,0,0,0,0,0,0,0,0,0,0,0,0,0,9,4,1
1,1,1,4,0,0,0,0,0,0,0,0,0,0,0,0,0,0,0,0,0,0,0,4,1,1,1
1,1,1,13,0,0,0,0,0,0,0,0,0,0,0,0,0,0,0,0,0,0,0,13,1,1,1
1,1,4,1,13,0,0,0,0,0,0,0,0,0,0,0,0,0,0,0,0,0,13,1,4,1,1
1,1,1,1,1,13,4,0,0,0,0,0,0,0,0,0,0,0,0,0,4,13,1,1,1,1,1
1,1,1,1,4,1,1,9,13,13,0,0,0,0,0,0,0,13,13,9,1,1,4,1,1,1,1
1,1,1,1,1,1,1,4,1,1,4,0,0,0,0,0,4,1,1,4,1,1,1,1,1,1,1
1,1,1,1,1,1,1,1,1,1,4,0,0,0,0,0,4,1,1,1,1,1,1,1,1,1,1
endlayer

layer
1,1,1,1,1,1,1,1,1,1,4,0,0,0,0,0,4,1,1,1,1,1,1,1,1,1,1
1,1,1,1,1,1,1,4,1,1,4,0,0,0,0,0,4,1,1,4,1,1,1,1,1,1,1
1,1,1,1,4,1,1,13,13,4,0,0,0,0,0,0,0,4,13,13,1,1,4,1,1,1,1
1,1,1,1,1,13,4,0,0,0,0,0,0,0,0,0,0,0,0,0,4,13,1,1,1,1,1
1,1,4,1,13,0,0,0,0,0,0,0,0,0,0,0,0,0,0,0,0,0,13,1,4,1,1
1,1,1,13,0,0,0,0,0,0,0,0,0,0,0,0,0,0,0,0,0,0,0,13,1,1,1
1,1,1,4,0,0,0,0,0,0,0,0,0,0,0,0,0,0,0,0,0,0,0,4,1,1,1
1,4,13,0,0,0,0,0,0,0,0,0,0,0,0,0,0,0,0,0,0,0,0,0,13,4,1
1,1,13,0,0,0,0,0,0,0,0,0,0,0,0,0,0,0,0,0,0,0,0,0,13,1,1
1,1,4,0,0,0,0,0,0,0,0,0,0,0,0,0,0,0,0,0,0,0,0,0,4,1,1
4,4,0,0,0,0,0,0,0,0,0,0,0,0,0,0,0,0,0,0,0,0,0,0,0,4,4
0,0,0,0,0,0,0,0,0,0,0,0,0,0,0,0,0,0,0,0,0,0,0,0,0,0,0
0,0,0,0,0,0,0,0,0,0,0,0,0,0,0,0,0,0,0,0,0,0,0,0,0,0,0
0,0,0,0,0,0,0,0,0,0,0,0,0,0,0,0,0,0,0,0,0,0,0,0,0,0,0
0,0,0,0,0,0,0,0,0,0,0,0,0,0,0,0,0,0,0,0,0,0,0,0,0,0,0
0,0,0,0,0,0,0,0,0,0,0,0,0,0,0,0,0,0,0,0,0,0,0,0,0,0,0
4,4,0,0,0,0,0,0,0,0,0,0,0,0,0,0,0,0,0,0,0,0,0,0,0,4,4
1,1,4,0,0,0,0,0,0,0,0,0,0,0,0,0,0,0,0,0,0,0,0,0,4,1,1
1,1,13,0,0,0,0,0,0,0,0,0,0,0,0,0,0,0,0,0,0,0,0,0,13,1,1
1,4,13,0,0,0,0,0,0,0,0,0,0,0,0,0,0,0,0,0,0,0,0,0,13,4,1
1,1,1,4,0,0,0,0,0,0,0,0,0,0,0,0,0,0,0,0,0,0,0,4,1,1,1
1,1,1,13,0,0,0,0,0,0,0,0,0,0,0,0,0,0,0,0,0,0,0,13,1,1,1
1,1,4,1,13,0,0,0,0,0,0,0,0,0,0,0,0,0,0,0,0,0,13,1,4,1,1
1,1,1,1,1,13,4,0,0,0,0,0,0,0,0,0,0,0,0,0,4,13,1,1,1,1,1
1,1,1,1,4,1,1,13,13,4,0,0,0,0,0,0,0,4,13,13,1,1,4,1,1,1,1
1,1,1,1,1,1,1,4,1,1,4,0,0,0,0,0,4,1,1,4,1,1,1,1,1,1,1
1,1,1,1,1,1,1,1,1,1,4,0,0,0,0,0,4,1,1,1,1,1,1,1,1,1,1
endlayer

layer
1,1,1,1,1,1,1,1,1,1,1,4,0,0,0,4,1,1,1,1,1,1,1,1,1,1,1
1,1,1,1,1,1,1,1,4,4,4,4,0,0,0,4,4,4,4,1,1,1,1,1,1,1,1
1,1,1,1,1,4,4,4,4,0,0,0,0,0,0,0,0,0,4,4,4,4,1,1,1,1,1
1,1,1,4,4,4,4,0,0,0,0,0,0,0,0,0,0,0,0,0,4,4,4,4,1,1,1
1,1,1,4,4,0,0,0,0,0,0,0,0,0,0,0,0,0,0,0,0,0,4,4,1,1,1
1,1,4,4,0,0,0,0,0,0,0,0,0,0,0,0,0,0,0,0,0,0,0,4,4,1,1
1,1,4,4,0,0,0,0,0,0,0,0,0,0,0,0,0,0,0,0,0,0,0,4,4,1,1
1,1,4,0,0,0,0,0,0,0,0,0,0,0,0,0,0,0,0,0,0,0,0,0,4,1,1
1,4,4,0,0,0,0,0,0,0,0,0,0,0,0,0,0,0,0,0,0,0,0,0,4,4,1
1,4,0,0,0,0,0,0,0,0,0,0,0,0,0,0,0,0,0,0,0,0,0,0,0,4,1
1,4,0,0,0,0,0,0,0,0,0,0,0,0,0,0,0,0,0,0,0,0,0,0,0,4,1
4,4,0,0,0,0,0,0,0,0,0,0,0,0,0,0,0,0,0,0,0,0,0,0,0,4,4
0,0,0,0,0,0,0,0,0,0,0,0,0,0,0,0,0,0,0,0,0,0,0,0,0,0,0
0,0,0,0,0,0,0,0,0,0,0,0,0,0,0,0,0,0,0,0,0,0,0,0,0,0,0
0,0,0,0,0,0,0,0,0,0,0,0,0,0,0,0,0,0,0,0,0,0,0,0,0,0,0
4,4,0,0,0,0,0,0,0,0,0,0,0,0,0,0,0,0,0,0,0,0,0,0,0,4,4
1,4,0,0,0,0,0,0,0,0,0,0,0,0,0,0,0,0,0,0,0,0,0,0,0,4,1
1,4,0,0,0,0,0,0,0,0,0,0,0,0,0,0,0,0,0,0,0,0,0,0,0,4,1
1,4,4,0,0,0,0,0,0,0,0,0,0,0,0,0,0,0,0,0,0,0,0,0,4,4,1
1,1,4,0,0,0,0,0,0,0,0,0,0,0,0,0,0,0,0,0,0,0,0,0,4,1,1
1,1,4,4,0,0,0,0,0,0,0,0,0,0,0,0,0,0,0,0,0,0,0,4,4,1,1
1,1,4,4,0,0,0,0,0,0,0,0,0,0,0,0,0,0,0,0,0,0,0,4,4,1,1
1,1,1,4,4,0,0,0,0,0,0,0,0,0,0,0,0,0,0,0,0,0,4,4,1,1,1
1,1,1,4,4,4,4,0,0,0,0,0,0,0,0,0,0,0,0,0,4,4,4,4,1,1,1
1,1,1,1,1,4,4,4,4,0,0,0,0,0,0,0,0,0,4,4,4,4,1,1,1,1,1
1,1,1,1,1,1,1,1,4,4,4,4,0,0,0,4,4,4,4,1,1,1,1,1,1,1,1
1,1,1,1,1,1,1,1,1,1,1,4,0,0,0,4,1,1,1,1,1,1,1,1,1,1,1
endlayer

layer
1,1,1,1,1,1,1,1,1,1,1,1,4,4,4,1,1,1,1,1,1,1,1,1,1,1,1
1,1,1,1,1,1,1,1,1,7,7,7,4,4,4,7,7,7,1,1,1,1,1,1,1,1,1
1,1,1,1,1,1,1,7,4,0,0,0,0,0,0,0,0,0,4,7,1,1,1,1,1,1,1
1,1,1,1,1,7,7,0,0,0,0,0,0,0,0,0,0,0,0,0,7,7,1,1,1,1,1
1,1,1,1,4,0,0,0,0,0,0,0,0,0,0,0,0,0,0,0,0,0,4,1,1,1,1
1,1,1,7,0,0,0,0,0,0,0,0,0,0,0,0,0,0,0,0,0,0,0,7,1,1,1
1,1,1,7,0,0,0,0,0,0,0,0,0,0,0,0,0,0,0,0,0,0,0,7,1,1,1
1,1,7,0,0,0,0,0,0,0,0,0,0,0,0,0,0,0,0,0,0,0,0,0,7,1,1
1,1,4,0,0,0,0,0,0,0,0,0,0,0,0,0,0,0,0,0,0,0,0,0,4,1,1
1,7,0,0,0,0,0,0,0,0,0,0,0,0,0,0,0,0,0,0,0,0,0,0,0,7,1
1,7,0,0,0,0,0,0,0,0,0,0,0,0,0,0,0,0,0,0,0,0,0,0,0,7,1
1,7,0,0,0,0,0,0,0,0,0,0,0,0,0,0,0,0,0,0,0,0,0,0,0,7,1
4,4,0,0,0,0,0,0,0,0,0,0,0,0,0,0,0,0,0,0,0,0,0,0,0,4,4
4,4,0,0,0,0,0,0,0,0,0,0,0,0,0,0,0,0,0,0,0,0,0,0,0,4,4
4,4,0,0,0,0,0,0,0,0,0,0,0,0,0,0,0,0,0,0,0,0,0,0,0,4,4
1,7,0,0,0,0,0,0,0,0,0,0,0,0,0,0,0,0,0,0,0,0,0,0,0,7,1
1,7,0,0,0,0,0,0,0,0,0,0,0,0,0,0,0,0,0,0,0,0,0,0,0,7,1
1,7,0,0,0,0,0,0,0,0,0,0,0,0,0,0,0,0,0,0,0,0,0,0,0,7,1
1,1,4,0,0,0,0,0,0,0,0,0,0,0,0,0,0,0,0,0,0,0,0,0,4,1,1
1,1,7,0,0,0,0,0,0,0,0,0,0,0,0,0,0,0,0,0,0,0,0,0,7,1,1
1,1,1,7,0,0,0,0,0,0,0,0,0,0,0,0,0,0,0,0,0,0,0,7,1,1,1
1,1,1,7,0,0,0,0,0,0,0,0,0,0,0,0,0,0,0,0,0,0,0,7,1,1,1
1,1,1,1,4,0,0,0,0,0,0,0,0,0,0,0,0,0,0,0,0,0,4,1,1,1,1
1,1,1,1,1,7,7,0,0,0,0,0,0,0,0,0,0,0,0,0,7,7,1,1,1,1,1
1,1,1,1,1,1,1,7,4,0,0,0,0,0,0,0,0,0,4,7,1,1,1,1,1,1,1
1,1,1,1,1,1,1,1,1,7,7,7,4,4,4,7,7,7,1,1,1,1,1,1,1,1,1
1,1,1,1,1,1,1,1,1,1,1,1,4,4,4,1,1,1,1,1,1,1,1,1,1,1,1
endlayer

layer
1,1,1,1,1,1,1,1,1,1,1,1,1,1,1,1,1,1,1,1,1,1,1,1,1,1,1
1,1,1,1,1,1,1,1,4,4,4,4,4,4,4,4,4,4,4,1,1,1,1,1,1,1,1
1,1,1,1,1,1,4,4,4,0,0,0,0,14,0,0,0,0,4,4,4,1,1,1,1,1,1
1,1,1,1,1,4,4,5,5,0,0,0,0,0,0,0,0,0,5,5,4,4,1,1,1,1,1
1,1,1,1,4,4,0,0,0,0,0,0,0,0,0,0,0,0,0,0,0,4,4,1,1,1,1
1,1,1,4,4,9,0,0,0,0,0,0,0,0,0,0,0,0,0,0,0,9,4,4,1,1,1
1,1,4,4,0,0,0,0,0,0,0,0,0,0,0,0,0,0,0,0,0,0,0,4,4,1,1
1,1,4,5,0,0,0,0,0,0,0,0,0,0,0,0,0,0,0,0,0,0,0,5,4,1,1
1,4,4,5,0,0,0,0,0,0,0,0,0,0,0,0,0,0,0,0,0,0,0,5,4,4,1
1,4,0,0,0,0,0,0,0,0,0,0,0,0,0,0,0,0,0,0,0,0,0,0,0,4,1
1,4,0,0,0,0,0,0,0,0,0,0,0,0,0,0,0,0,0,0,0,0,0,0,0,4,1
1,4,0,0,0,0,0,0,0,0,0,0,0,0,0,0,0,0,0,0,0,0,0,0,0,4,1
1,4,0,0,0,0,0,0,0,0,0,0,0,0,0,0,0,0,0,0,0,0,0,0,0,4,1
1,4,16,0,0,0,0,0,0,0,0,0,0,0,0,0,0,0,0,0,0,0,0,0,15,4,1
1,4,0,0,0,0,0,0,0,0,0,0,0,0,0,0,0,0,0,0,0,0,0,0,0,4,1
1,4,0,0,0,0,0,0,0,0,0,0,0,0,0,0,0,0,0,0,0,0,0,0,0,4,1
1,4,0,0,0,0,0,0,0,0,0,0,0,0,0,0,0,0,0,0,0,0,0,0,0,4,1
1,4,0,0,0,0,0,0,0,0,0,0,0,0,0,0,0,0,0,0,0,0,0,0,0,4,1
1,4,4,5,0,0,0,0,0,0,0,0,0,0,0,0,0,0,0,0,0,0,0,5,4,4,1
1,1,4,5,0,0,0,0,0,0,0,0,0,0,0,0,0,0,0,0,0,0,0,5,4,1,1
1,1,4,4,0,0,0,0,0,0,0,0,0,0,0,0,0,0,0,0,0,0,0,4,4,1,1
1,1,1,4,4,9,0,0,0,0,0,0,0,0,0,0,0,0,0,0,0,9,4,4,1,1,1
1,1,1,1,4,4,0,0,0,0,0,0,0,0,0,0,0,0,0,0,0,4,4,1,1,1,1
1,1,1,1,1,4,4,5,5,0,0,0,0,0,0,0,0,0,5,5,4,4,1,1,1,1,1
1,1,1,1,1,1,4,4,4,0,0,0,0,17,0,0,0,0,4,4,4,1,1,1,1,1,1
1,1,1,1,1,1,1,1,4,4,4,4,4,4,4,4,4,4,4,1,1,1,1,1,1,1,1
1,1,1,1,1,1,1,1,1,1,1,1,1,1,1,1,1,1,1,1,1,1,1,1,1,1,1
endlayer

layer
1,1,1,1,1,1,1,1,1,1,1,1,1,1,1,1,1,1,1,1,1,1,1,1,1,1,1
1,1,1,1,1,1,1,1,1,1,1,18,18,1,18,18,1,1,1,1,1,1,1,1,1,1,1
1,1,1,1,1,1,1,1,1,7,7,5,5,4,5,5,7,7,1,1,1,1,1,1,1,1,1
1,1,1,1,1,1,1,1,1,7,7,5,5,14,5,5,7,7,1,1,1,1,1,1,1,1,1
1,1,1,1,1,1,2,2,2,5,5,0,0,9,0,0,5,5,2,2,2,1,1,1,1,1,1
1,1,1,1,1,2,5,5,0,0,0,0,0,0,0,0,0,0,0,5,5,2,1,1,1,1,1
1,1,1,1,2,5,0,0,0,0,0,0,0,0,0,0,0,0,0,0,0,5,2,1,1,1,1
1,1,1,1,2,5,0,0,0,0,0,0,0,0,0,0,0,0,0,0,0,5,2,1,1,1,1
1,1,1,1,2,0,0,0,0,0,0,0,0,0,0,0,0,0,0,0,0,0,2,1,1,1,1
1,1,7,7,5,0,0,0,0,0,0,0,0,0,0,0,0,0,0,0,0,0,5,7,7,1,1
1,1,7,7,5,0,0,0,0,0,0,0,0,0,0,0,0,0,0,0,0,0,5,7,7,1,1
1,18,5,5,0,0,0,0,0,0,0,0,0,0,0,0,0,0,0,0,0,0,0,5,5,18,1
1,18,5,5,0,0,0,0,0,0,0,0,0,0,0,0,0,0,0,0,0,0,0,5,5,18,1
1,1,4,16,9,0,0,0,0,0,0,0,0,0,0,0,0,0,0,0,0,0,9,15,4,1,1
1,18,5,5,0,0,0,0,0,0,0,0,0,0,0,0,0,0,0,0,0,0,0,5,5,18,1
1,18,5,5,0,0,0,0,0,0,0,0,0,0,0,0,0,0,0,0,0,0,0,5,5,18,1
1,1,7,7,5,0,0,0,0,0,0,0,0,0,0,0,0,0,0,0,0,0,5,7,7,1,1
1,1,7,7,5,0,0,0,0,0,0,0,0,0,0,0,0,0,0,0,0,0,5,7,7,1,1
1,1,1,1,2,0,0,0,0,0,0,0,0,0,0,0,0,0,0,0,0,0,2,1,1,1,1
1,1,1,1,2,5,0,0,0,0,0,0,0,0,0,0,0,0,0,0,0,5,2,1,1,1,1
1,1,1,1,2,5,0,0,0,0,0,0,0,0,0,0,0,0,0,0,0,5,2,1,1,1,1
1,1,1,1,1,2,5,5,0,0,0,0,0,0,0,0,0,0,0,5,5,2,1,1,1,1,1
1,1,1,1,1,1,2,2,2,5,5,0,0,9,0,0,5,5,2,2,2,1,1,1,1,1,1
1,1,1,1,1,1,1,1,1,7,7,5,5,17,5,5,7,7,1,1,1,1,1,1,1,1,1
1,1,1,1,1,1,1,1,1,7,7,5,5,4,5,5,7,7,1,1,1,1,1,1,1,1,1
1,1,1,1,1,1,1,1,1,1,1,18,18,1,18,18,1,1,1,1,1,1,1,1,1,1,1
1,1,1,1,1,1,1,1,1,1,1,1,1,1,1,1,1,1,1,1,1,1,1,1,1,1,1
endlayer

layer
1,1,1,1,1,1,1,1,1,1,1,1,1,1,1,1,1,1,1,1,1,1,1,1,1,1,1
1,1,1,1,1,1,1,1,1,1,1,1,1,1,1,1,1,1,1,1,1,1,1,1,1,1,1
1,1,1,1,1,1,1,1,1,1,1,1,1,1,1,1,1,1,1,1,1,1,1,1,1,1,1
1,1,1,1,1,1,1,1,1,1,1,19,1,1,1,19,1,1,1,1,1,1,1,1,1,1,1
1,1,1,1,1,1,1,1,1,19,2,2,2,4,2,2,2,19,1,1,1,1,1,1,1,1,1
1,1,1,1,1,1,1,1,2,2,5,5,5,4,5,5,5,2,2,1,1,1,1,1,1,1,1
1,1,1,1,1,1,7,7,5,5,5,5,0,14,0,5,5,5,5,7,7,1,1,1,1,1,1
1,1,1,1,1,1,7,7,5,5,0,0,0,0,0,0,0,5,5,7,7,1,1,1,1,1,1
1,1,1,1,1,2,5,5,5,5,0,0,0,0,0,0,0,5,5,5,5,2,1,1,1,1,1
1,1,1,1,19,2,5,5,5,0,0,0,0,0,0,0,0,0,5,5,5,2,19,1,1,1,1
1,1,1,1,2,5,5,0,0,0,0,0,0,0,0,0,0,0,0,0,5,5,2,1,1,1,1
1,1,1,19,2,5,5,0,0,0,0,0,0,0,0,0,0,0,0,0,5,5,2,19,1,1,1
1,1,1,1,2,5,0,0,0,0,0,0,0,0,0,0,0,0,0,0,0,5,2,1,1,1,1
1,1,1,1,4,4,16,0,0,0,0,0,0,0,0,0,0,0,0,0,15,4,4,1,1,1,1
1,1,1,1,2,5,0,0,0,0,0,0,0,0,0,0,0,0,0,0,0,5,2,1,1,1,1
1,1,1,19,2,5,5,0,0,0,0,0,0,0,0,0,0,0,0,0,5,5,2,19,1,1,1
1,1,1,1,2,5,5,0,0,0,0,0,0,0,0,0,0,0,0,0,5,5,2,1,1,1,1
1,1,1,1,19,2,5,5,5,0,0,0,0,0,0,0,0,0,5,5,5,2,19,1,1,1,1
1,1,1,1,1,2,5,5,5,5,0,0,0,0,0,0,0,5,5,5,5,2,1,1,1,1,1
1,1,1,1,1,1,7,7,5,5,0,0,0,0,0,0,0,5,5,7,7,1,1,1,1,1,1
1,1,1,1,1,1,7,7,5,5,5,5,0,17,0,5,5,5,5,7,7,1,1,1,1,1,1
1,1,1,1,1,1,1,1,2,2,5,5,5,4,5,5,5,2,2,1,1,1,1,1,1,1,1
1,1,1,1,1,1,1,1,1,19,2,2,2,4,2,2,2,19,1,1,1,1,1,1,1,1,1
1,1,1,1,1,1,1,1,1,1,1,19,1,1,1,19,1,1,1,1,1,1,1,1,1,1,1
1,1,1,1,1,1,1,1,1,1,1,1,1,1,1,1,1,1,1,1,1,1,1,1,1,1,1
1,1,1,1,1,1,1,1,1,1,1,1,1,1,1,1,1,1,1,1,1,1,1,1,1,1,1
1,1,1,1,1,1,1,1,1,1,1,1,1,1,1,1,1,1,1,1,1,1,1,1,1,1,1
endlayer

layer
1,1,1,1,1,1,1,1,1,1,1,1,1,1,1,1,1,1,1,1,1,1,1,1,1,1,1
1,1,1,1,1,1,1,1,1,1,1,1,1,1,1,1,1,1,1,1,1,1,1,1,1,1,1
1,1,1,1,1,1,1,1,1,1,1,1,1,1,1,1,1,1,1,1,1,1,1,1,1,1,1
1,1,1,1,1,1,1,1,1,1,1,1,1,1,1,1,1,1,1,1,1,1,1,1,1,1,1
1,1,1,1,1,1,1,1,1,1,1,1,1,1,1,1,1,1,1,1,1,1,1,1,1,1,1
1,1,1,1,1,1,1,1,1,1,1,1,1,1,1,1,1,1,1,1,1,1,1,1,1,1,1
1,1,1,1,1,1,1,1,1,1,1,1,19,1,19,1,1,1,1,1,1,1,1,1,1,1,1
1,1,1,1,1,1,1,1,1,1,7,7,5,4,5,7,7,1,1,1,1,1,1,1,1,1,1
1,1,1,1,1,1,1,1,1,1,7,7,5,4,5,7,7,1,1,1,1,1,1,1,1,1,1
1,1,1,1,1,1,1,1,1,19,5,5,5,14,5,5,5,19,1,1,1,1,1,1,1,1,1
1,1,1,1,1,1,1,7,7,5,9,5,5,0,5,5,9,5,7,7,1,1,1,1,1,1,1
1,1,1,1,1,1,1,7,7,5,5,0,0,0,0,0,5,5,7,7,1,1,1,1,1,1,1
1,1,1,1,1,1,19,5,5,5,5,0,0,0,0,0,5,5,5,5,19,1,1,1,1,1,1
1,1,1,1,1,1,1,4,4,16,0,0,0,0,0,0,0,15,4,4,1,1,1,1,1,1,1
1,1,1,1,1,1,19,5,5,5,5,0,0,0,0,0,5,5,5,5,19,1,1,1,1,1,1
1,1,1,1,1,1,1,7,7,5,5,0,0,0,0,0,5,5,7,7,1,1,1,1,1,1,1
1,1,1,1,1,1,1,7,7,5,9,5,5,0,5,5,9,5,7,7,1,1,1,1,1,1,1
1,1,1,1,1,1,1,1,1,19,5,5,5,17,5,5,5,19,1,1,1,1,1,1,1,1,1
1,1,1,1,1,1,1,1,1,1,7,7,5,4,5,7,7,1,1,1,1,1,1,1,1,1,1
1,1,1,1,1,1,1,1,1,1,7,7,5,4,5,7,7,1,1,1,1,1,1,1,1,1,1
1,1,1,1,1,1,1,1,1,1,1,1,19,1,19,1,1,1,1,1,1,1,1,1,1,1,1
1,1,1,1,1,1,1,1,1,1,1,1,1,1,1,1,1,1,1,1,1,1,1,1,1,1,1
1,1,1,1,1,1,1,1,1,1,1,1,1,1,1,1,1,1,1,1,1,1,1,1,1,1,1
1,1,1,1,1,1,1,1,1,1,1,1,1,1,1,1,1,1,1,1,1,1,1,1,1,1,1
1,1,1,1,1,1,1,1,1,1,1,1,1,1,1,1,1,1,1,1,1,1,1,1,1,1,1
1,1,1,1,1,1,1,1,1,1,1,1,1,1,1,1,1,1,1,1,1,1,1,1,1,1,1
1,1,1,1,1,1,1,1,1,1,1,1,1,1,1,1,1,1,1,1,1,1,1,1,1,1,1
endlayer

layer
1,1,1,1,1,1,1,1,1,1,1,1,1,1,1,1,1,1,1,1,1,1,1,1,1,1,1
1,1,1,1,1,1,1,1,1,1,1,1,1,1,1,1,1,1,1,1,1,1,1,1,1,1,1
1,1,1,1,1,1,1,1,1,1,1,1,1,1,1,1,1,1,1,1,1,1,1,1,1,1,1
1,1,1,1,1,1,1,1,1,1,1,1,1,1,1,1,1,1,1,1,1,1,1,1,1,1,1
1,1,1,1,1,1,1,1,1,1,1,1,1,1,1,1,1,1,1,1,1,1,1,1,1,1,1
1,1,1,1,1,1,1,1,1,1,1,1,1,1,1,1,1,1,1,1,1,1,1,1,1,1,1
1,1,1,1,1,1,1,1,1,1,1,1,1,1,1,1,1,1,1,1,1,1,1,1,1,1,1
1,1,1,1,1,1,1,1,1,1,1,1,1,1,1,1,1,1,1,1,1,1,1,1,1,1,1
1,1,1,1,1,1,1,1,1,1,1,1,1,1,1,1,1,1,1,1,1,1,1,1,1,1,1
1,1,1,1,1,1,1,1,1,1,1,1,1,1,1,1,1,1,1,1,1,1,1,1,1,1,1
1,1,1,1,1,1,1,1,1,1,1,1,1,19,1,1,1,1,1,1,1,1,1,1,1,1,1
1,1,1,1,1,1,1,1,1,1,1,7,7,5,7,7,1,1,1,1,1,1,1,1,1,1,1
1,1,1,1,1,1,1,1,1,1,1,7,7,5,7,7,1,1,1,1,1,1,1,1,1,1,1
1,1,1,1,1,1,1,1,1,1,19,5,5,9,5,5,19,1,1,1,1,1,1,1,1,1,1
1,1,1,1,1,1,1,1,1,1,1,7,7,5,7,7,1,1,1,1,1,1,1,1,1,1,1
1,1,1,1,1,1,1,1,1,1,1,7,7,5,7,7,1,1,1,1,1,1,1,1,1,1,1
1,1,1,1,1,1,1,1,1,1,1,1,1,19,1,1,1,1,1,1,1,1,1,1,1,1,1
1,1,1,1,1,1,1,1,1,1,1,1,1,1,1,1,1,1,1,1,1,1,1,1,1,1,1
1,1,1,1,1,1,1,1,1,1,1,1,1,1,1,1,1,1,1,1,1,1,1,1,1,1,1
1,1,1,1,1,1,1,1,1,1,1,1,1,1,1,1,1,1,1,1,1,1,1,1,1,1,1
1,1,1,1,1,1,1,1,1,1,1,1,1,1,1,1,1,1,1,1,1,1,1,1,1,1,1
1,1,1,1,1,1,1,1,1,1,1,1,1,1,1,1,1,1,1,1,1,1,1,1,1,1,1
1,1,1,1,1,1,1,1,1,1,1,1,1,1,1,1,1,1,1,1,1,1,1,1,1,1,1
1,1,1,1,1,1,1,1,1,1,1,1,1,1,1,1,1,1,1,1,1,1,1,1,1,1,1
1,1,1,1,1,1,1,1,1,1,1,1,1,1,1,1,1,1,1,1,1,1,1,1,1,1,1
1,1,1,1,1,1,1,1,1,1,1,1,1,1,1,1,1,1,1,1,1,1,1,1,1,1,1
1,1,1,1,1,1,1,1,1,1,1,1,1,1,1,1,1,1,1,1,1,1,1,1,1,1,1
endlayer

