
# Created by Ruins mod version 16.7 Ingame Parser
# authoring Player: lafuller

weight=1
embed_into_distance=13
acceptable_target_blocks=water,waterlily
unacceptable_target_blocks=
biomesToSpawnIn=swampland,jungle,marsh,bog,wetland,mini_jungle,lush_swamp,green_swamp,dead_swamp,tropical_island,land_of_lakes
dimensions=23,12,11
allowable_overhang=0
max_leveling=2
leveling_buffer=-1
preserve_water=0
preserve_lava=0

rule1=0,100,preserveBlock
rule2=0,100,minecraft:log2-1
rule3=0,100,minecraft:log2-9
rule4=0,100,minecraft:log2-5
rule5=0,100,minecraft:spruce_fence-0
rule6=0,100,minecraft:log-3
rule7=0,100,minecraft:ladder-4
rule8=0,100,minecraft:spruce_stairs-6
rule9=0,100,minecraft:spruce_stairs-4
rule10=0,100,minecraft:spruce_stairs-7
rule11=0,100,minecraft:wooden_slab-9
rule12=0,100,minecraft:log-11
rule13=0,100,minecraft:wooden_slab-11
rule14=0,100,minecraft:spruce_stairs-2
rule15=0,100,minecraft:wooden_slab-1
rule16=0,100,minecraft:spruce_stairs-0
rule17=0,100,minecraft:ladder-3
rule18=0,100,minecraft:spruce_stairs-3
rule19=0,100,minecraft:trapdoor-6
rule20=0,100,minecraft:spruce_stairs-1
rule21=0,100,minecraft:spruce_fence_gate-1
rule22=0,100,minecraft:double_wooden_slab-1
rule23=0,100,minecraft:dark_oak_stairs-7
rule24=0,100,minecraft:dark_oak_fence-0
rule25=0,100,minecraft:carpet-7
rule26=0,100,minecraft:carpet-8
rule27=0,100,minecraft:spruce_stairs-5
rule28=0,100,minecraft:dark_oak_stairs-5
rule29=0,100,minecraft:wooden_slab-13
rule30=0,100,minecraft:planks-5
rule31=0,100,minecraft:spruce_fence_gate-2
rule32=0,100,minecraft:spruce_fence_gate-3
rule33=0,100,minecraft:wooden_slab-5
rule34=0,100,minecraft:dark_oak_stairs-4
rule35=0,100,minecraft:log-7
rule36=0,100,minecraft:dark_oak_stairs-3
rule37=0,100,minecraft:dark_oak_stairs-6
rule38=0,100,minecraft:dark_oak_stairs-0
rule39=0,100,minecraft:dark_oak_stairs-2
rule40=0,100,minecraft:trapdoor-1
rule41=0,100,minecraft:dark_oak_stairs-1
rule42=0,100,minecraft:double_wooden_slab-5

layer
1,1,1,1,1,1,1,1,1,1,1
1,1,1,1,1,1,1,1,1,1,1
1,1,1,1,2,1,1,1,1,1,1
1,1,1,1,1,1,2,1,1,1,1
1,1,2,1,1,1,1,1,1,1,1
1,1,1,1,1,2,1,1,2,1,1
1,1,1,1,1,1,1,1,1,1,1
1,1,1,1,1,1,1,1,1,1,1
1,1,2,1,1,1,2,1,1,1,1
1,1,1,1,1,1,1,1,1,1,1
1,1,1,1,1,1,1,1,1,1,1
1,1,1,1,1,1,1,1,1,1,1
endlayer

layer
1,1,1,1,1,1,1,1,1,1,1
1,1,1,1,1,1,1,1,1,1,1
1,1,1,1,2,1,1,1,1,1,1
1,1,1,1,1,1,2,1,1,1,1
1,1,2,1,1,1,1,1,1,1,1
1,1,1,1,1,2,1,1,2,1,1
1,1,1,1,1,1,1,1,1,1,1
1,1,1,1,1,1,1,1,1,1,1
1,1,2,1,1,1,2,1,1,1,1
1,1,1,1,1,1,1,1,1,1,1
1,1,1,1,1,1,1,1,1,1,1
1,1,1,1,1,1,1,1,1,1,1
endlayer

layer
1,1,1,1,1,1,1,1,1,1,1
1,1,1,1,1,1,1,1,1,1,1
1,1,1,1,2,1,1,1,1,1,1
1,1,1,1,1,1,2,1,1,1,1
1,1,2,1,1,1,1,1,1,1,1
1,1,1,1,1,2,1,1,2,1,1
1,1,1,1,1,1,1,1,1,1,1
1,1,1,1,1,1,1,1,1,1,1
1,1,2,1,1,1,2,1,1,1,1
1,1,1,1,1,1,1,1,1,1,1
1,1,1,1,1,1,1,1,1,1,1
1,1,1,1,1,1,1,1,1,1,1
endlayer

layer
1,1,1,1,1,1,1,1,1,1,1
1,1,1,1,1,1,1,1,1,1,1
1,1,1,1,2,1,1,1,1,1,1
1,1,1,1,1,1,2,1,1,1,1
1,1,2,1,1,1,1,1,1,1,1
1,1,1,1,1,2,1,1,2,1,1
1,1,1,1,1,1,1,1,1,1,1
1,1,1,1,1,1,1,1,1,1,1
1,1,2,1,1,1,2,1,1,1,1
1,1,1,1,1,1,1,1,1,1,1
1,1,1,1,1,1,1,1,1,1,1
1,1,1,1,1,1,1,1,1,1,1
endlayer

layer
1,1,1,1,1,1,1,1,1,1,1
1,1,1,1,1,1,1,1,1,1,1
1,1,1,1,2,1,1,1,1,1,1
1,1,1,1,1,1,2,1,1,1,1
1,1,2,1,1,1,1,1,1,1,1
1,1,1,1,1,2,1,1,2,1,1
1,1,1,1,1,1,1,1,1,1,1
1,1,1,1,1,1,1,1,1,1,1
1,1,2,1,1,1,2,1,1,1,1
1,1,1,1,1,1,1,1,1,1,1
1,1,1,1,1,1,1,1,1,1,1
1,1,1,1,1,1,1,1,1,1,1
endlayer

layer
1,1,1,1,1,1,1,1,1,1,1
1,1,1,1,1,1,1,1,1,1,1
1,1,1,1,2,1,1,1,1,1,1
1,1,1,1,1,1,2,1,1,1,1
1,1,2,1,1,1,1,1,1,1,1
1,1,1,1,1,2,1,1,2,1,1
1,1,1,1,1,1,1,1,1,1,1
1,1,1,1,1,1,1,1,1,1,1
1,1,2,1,1,1,2,1,1,1,1
1,1,1,1,1,1,1,1,1,1,1
1,1,1,1,1,1,1,1,1,1,1
1,1,1,1,1,1,1,1,1,1,1
endlayer

layer
1,1,1,1,1,1,1,1,1,1,1
1,1,1,1,1,1,1,1,1,1,1
1,1,1,1,2,1,1,1,1,1,1
1,1,1,1,1,1,2,1,1,1,1
1,1,2,1,1,1,1,1,1,1,1
1,1,1,1,1,2,1,1,2,1,1
1,1,1,1,1,1,1,1,1,1,1
1,1,1,1,1,1,1,1,1,1,1
1,1,2,1,1,1,2,1,1,1,1
1,1,1,1,1,1,1,1,1,1,1
1,1,1,1,1,1,1,1,1,1,1
1,1,1,1,1,1,1,1,1,1,1
endlayer

layer
1,1,1,1,1,1,1,1,1,1,1
1,1,1,1,1,1,1,1,1,1,1
1,1,1,1,2,1,1,1,1,1,1
1,1,1,1,1,1,2,1,1,1,1
1,1,2,1,1,1,1,1,1,1,1
1,1,1,1,1,2,1,1,2,1,1
1,1,1,1,1,1,1,1,1,1,1
1,1,1,1,1,1,1,1,1,1,1
1,1,2,1,1,1,2,1,1,1,1
1,1,1,1,1,1,1,1,1,1,1
1,1,1,1,1,1,1,1,1,1,1
1,1,1,1,1,1,1,1,1,1,1
endlayer

layer
1,1,1,1,1,1,1,1,1,1,1
1,1,1,1,1,1,1,1,1,1,1
1,1,1,1,2,1,1,1,1,1,1
1,1,1,1,1,1,2,1,1,1,1
1,1,2,1,1,1,1,1,1,1,1
1,1,1,1,1,2,1,1,2,1,1
1,1,1,1,1,1,1,1,1,1,1
1,1,1,1,1,1,1,1,1,1,1
1,1,2,1,1,1,2,1,1,1,1
1,1,1,1,1,1,1,1,1,1,1
1,1,1,1,1,1,1,1,1,1,1
1,1,1,1,1,1,1,1,1,1,1
endlayer

layer
1,1,1,1,1,1,1,1,1,1,1
1,1,1,1,1,1,1,1,1,1,1
1,1,1,1,2,1,1,1,1,1,1
1,1,1,1,1,1,2,1,1,1,1
1,1,2,1,1,1,1,1,1,1,1
1,1,1,1,1,2,1,1,2,1,1
1,1,1,1,1,1,1,1,1,1,1
1,1,1,1,1,1,1,1,1,1,1
1,1,2,1,1,1,2,1,1,1,1
1,1,1,1,1,1,1,1,1,1,1
1,1,1,1,1,1,1,1,1,1,1
1,1,1,1,1,1,1,1,1,1,1
endlayer

layer
1,1,1,1,1,1,1,1,1,1,1
1,1,1,1,1,1,1,1,1,1,1
1,1,1,1,2,1,1,1,1,1,1
1,1,1,1,1,1,2,1,1,1,1
1,1,2,1,1,1,1,1,1,1,1
1,1,1,1,1,2,1,1,2,1,1
1,1,1,1,1,1,1,1,1,1,1
1,1,1,1,1,1,1,1,1,1,1
1,1,2,1,1,1,2,1,1,1,1
1,1,1,1,1,1,1,1,1,1,1
1,1,1,1,1,1,1,1,1,1,1
1,1,1,1,1,1,1,1,1,1,1
endlayer

layer
1,1,1,1,1,1,1,1,1,1,1
1,1,1,1,1,1,1,1,1,1,1
1,1,1,1,2,1,1,1,1,1,1
1,1,1,1,1,1,2,1,1,1,1
1,1,2,1,1,1,1,1,1,1,1
1,1,1,1,1,2,1,1,2,1,1
1,1,1,1,1,1,1,1,1,1,1
1,1,1,1,1,1,1,1,1,1,1
1,3,3,3,3,3,3,3,3,1,1
1,1,1,1,1,1,1,1,1,1,1
1,1,1,1,1,1,1,1,1,1,1
1,1,1,1,1,1,1,1,1,1,1
endlayer

layer
1,1,1,1,1,1,1,1,1,1,1
1,1,1,1,1,1,1,1,1,1,1
1,1,1,4,2,1,1,4,1,1,1
1,1,1,4,1,1,2,4,1,1,1
1,1,2,4,1,1,1,4,1,1,1
1,1,1,4,1,2,1,4,2,1,1
1,1,1,4,1,1,1,4,1,1,1
1,1,1,4,1,1,1,4,1,1,1
1,1,2,4,1,1,2,4,1,1,1
1,1,1,4,1,1,1,4,1,1,1
1,1,1,1,1,1,1,1,1,1,1
1,1,1,1,1,1,1,1,1,1,1
endlayer

layer
1,1,1,1,1,1,1,1,1,1,1
1,1,1,1,1,1,1,1,1,1,1
1,1,1,1,6,3,3,3,3,5,1
1,1,1,1,1,1,2,1,1,1,1
5,3,3,3,3,3,3,3,3,3,5
1,1,1,1,1,2,1,1,2,1,1
1,1,1,1,1,1,1,1,1,1,1
1,1,1,1,1,1,1,1,1,1,1
1,1,2,6,1,1,2,1,1,1,1
1,1,1,1,1,1,3,3,3,5,1
1,1,1,1,1,1,1,1,1,1,1
1,1,1,1,1,1,1,1,1,1,1
endlayer

layer
1,1,1,1,1,1,5,1,1,1,1
1,1,1,1,1,1,4,1,5,1,1
1,1,5,1,6,1,4,1,4,1,1
1,1,4,1,1,1,4,1,4,1,1
1,1,4,1,1,1,4,1,4,1,1
1,1,4,1,1,6,4,1,4,1,1
1,1,4,1,1,1,4,1,4,1,1
1,1,4,7,1,1,4,1,4,1,1
1,1,4,6,1,1,4,1,4,1,1
1,1,4,1,1,1,4,1,4,1,1
1,1,5,1,1,1,4,1,5,1,1
1,1,1,1,1,1,5,1,1,1,1
endlayer

layer
1,1,1,1,1,1,1,1,1,1,1
1,1,1,1,1,1,1,1,1,1,1
1,1,11,10,6,10,9,8,5,1,1
1,5,12,12,12,12,12,12,12,5,1
1,1,6,11,13,13,11,11,11,1,1
5,12,12,12,12,12,12,12,12,12,5
1,1,11,11,11,13,13,11,11,1,1
1,1,11,7,11,13,13,11,11,1,1
5,12,12,12,12,12,12,12,12,5,1
1,1,11,11,11,10,6,5,1,1,1
1,1,1,11,11,11,11,1,1,1,1
1,1,1,1,1,1,1,1,1,1,1
endlayer

layer
1,1,1,1,1,1,1,1,1,1,1
1,1,1,1,1,1,1,1,1,1,1
1,1,1,16,6,16,15,14,1,1,1
1,1,18,0,0,0,17,6,14,1,1
1,1,6,0,0,0,0,0,14,1,1
1,1,18,0,0,0,0,0,6,1,1
1,1,15,0,0,0,0,0,14,1,1
1,1,18,19,0,0,0,0,15,1,1
1,1,20,6,0,0,0,16,1,1,1
1,1,1,5,20,21,6,15,1,1,1
1,1,1,1,1,1,1,1,1,1,1
1,1,1,1,1,1,1,1,1,1,1
endlayer

layer
1,1,1,1,1,1,1,1,1,1,1
1,1,1,1,1,1,1,1,1,1,1
1,1,1,5,6,5,0,5,1,1,1
1,1,5,0,0,0,17,6,5,1,1
1,1,6,0,0,0,0,0,5,1,1
1,1,5,0,0,0,0,0,6,1,1
1,1,0,0,0,0,0,0,5,1,1
1,1,5,0,0,0,0,0,0,1,1
1,1,5,6,5,0,0,5,1,1,1
1,1,1,5,5,0,6,1,1,1,1
1,1,1,1,1,1,1,1,1,1,1
1,1,1,1,1,1,1,1,1,1,1
endlayer

layer
1,1,1,1,1,1,1,1,1,1,1
1,1,1,1,1,1,1,1,1,1,1
1,1,1,16,6,16,16,14,11,1,1
1,1,18,0,0,0,17,6,14,1,1
1,1,6,0,0,0,11,11,14,1,1
1,1,18,0,0,0,11,11,6,1,1
1,1,18,0,0,0,11,11,14,1,1
1,1,18,0,0,0,11,11,14,1,1
1,1,20,6,0,0,9,22,11,1,1
1,1,1,5,20,20,6,5,1,1,1
1,1,1,1,1,1,1,1,1,1,1
1,1,1,1,1,1,1,1,1,1,1
endlayer

layer
1,1,1,1,1,1,1,1,1,1,1
1,1,1,1,1,1,1,1,1,1,1
1,1,1,9,6,16,15,16,1,1,1
1,1,10,0,0,0,0,6,14,1,1
1,23,6,0,0,0,0,0,14,1,1
1,1,10,0,0,0,25,25,6,24,1
1,1,11,0,0,0,25,25,14,1,1
1,1,9,0,0,0,26,26,15,1,1
1,1,10,6,0,0,16,20,16,1,1
1,1,29,28,27,27,6,15,1,1,1
1,1,1,1,1,1,1,1,1,1,1
1,1,1,1,1,1,1,1,1,1,1
endlayer

layer
1,1,1,1,1,1,1,1,1,1,1
1,1,29,24,24,1,1,1,1,1,1
1,29,23,30,6,5,1,5,1,1,1
1,23,30,29,0,0,0,6,5,1,1
24,12,30,29,0,0,0,0,5,24,1
1,23,30,29,0,0,0,0,6,24,1
1,29,30,29,0,0,0,0,5,1,1
1,23,30,29,0,0,0,0,31,1,1
1,33,30,6,9,0,0,32,5,1,1
1,33,30,30,22,27,6,1,1,1,1
1,1,33,30,29,24,24,1,1,1,1
1,1,1,1,1,1,1,1,1,1,1
endlayer

layer
1,1,1,1,24,1,1,1,1,1,1
1,1,1,36,35,29,29,34,1,1,1
1,1,36,30,6,9,9,9,29,1,1
1,33,30,30,35,0,0,6,8,29,1
1,36,30,30,35,0,0,0,8,34,1
1,33,36,30,35,0,0,0,6,12,24
1,1,33,30,35,0,0,0,8,29,1
1,1,33,30,35,0,0,0,8,29,1
1,1,1,36,35,8,9,27,23,29,1
1,1,1,33,30,30,6,37,29,1,1
1,1,1,1,33,30,35,29,1,1,1
1,1,1,1,1,24,24,1,1,1,1
endlayer

layer
1,1,1,1,1,1,1,1,1,1,1
1,1,1,1,33,33,33,1,1,1,1
1,1,1,1,33,38,38,33,1,1,1
1,1,1,33,33,30,30,39,33,1,1
1,1,1,33,33,36,30,30,39,33,1
1,1,1,1,33,33,30,30,39,33,1
1,1,1,1,33,40,36,30,39,33,1
1,1,1,1,33,33,36,30,39,33,1
1,1,1,1,33,33,42,41,33,1,1
1,1,1,1,1,33,33,33,33,1,1
1,1,1,1,1,1,33,33,1,1,1
1,1,1,1,1,1,1,1,1,1,1
endlayer

