
# Created by Ruins mod version 16.7 Ingame Parser
# authoring Player: lafuller

weight=1
embed_into_distance=13
acceptable_target_blocks=water
unacceptable_target_blocks=
dimensions=18,7,8
allowable_overhang=0
max_leveling=20
leveling_buffer=-1
preserve_water=0
preserve_lava=0

rule1=0,100,preserveBlock
rule2=0,100,minecraft:log2-1
rule3=0,100,minecraft:log2-9
rule4=0,100,minecraft:log2-5
rule5=0,100,minecraft:spruce_fence-0
rule6=0,100,minecraft:wooden_slab-1

layer
1,1,1,1,1,1,1,1
1,1,1,1,1,1,1,1
1,1,1,2,1,1,2,1
1,1,1,1,1,1,1,1
1,1,1,1,1,1,1,1
1,1,2,1,1,2,1,1
1,1,1,1,1,1,1,1
endlayer

layer
1,1,1,1,1,1,1,1
1,1,1,1,1,1,1,1
1,1,1,2,1,1,2,1
1,1,1,1,1,1,1,1
1,1,1,1,1,1,1,1
1,1,2,1,1,2,1,1
1,1,1,1,1,1,1,1
endlayer

layer
1,1,1,1,1,1,1,1
1,1,1,1,1,1,1,1
1,1,1,2,1,1,2,1
1,1,1,1,1,1,1,1
1,1,1,1,1,1,1,1
1,1,2,1,1,2,1,1
1,1,1,1,1,1,1,1
endlayer

layer
1,1,1,1,1,1,1,1
1,1,1,1,1,1,1,1
1,1,1,2,1,1,2,1
1,1,1,1,1,1,1,1
1,1,1,1,1,1,1,1
1,1,2,1,1,2,1,1
1,1,1,1,1,1,1,1
endlayer

layer
1,1,1,1,1,1,1,1
1,1,1,1,1,1,1,1
1,1,1,2,1,1,2,1
1,1,1,1,1,1,1,1
1,1,1,1,1,1,1,1
1,1,2,1,1,2,1,1
1,1,1,1,1,1,1,1
endlayer

layer
1,1,1,1,1,1,1,1
1,1,1,1,1,1,1,1
1,1,1,2,1,1,2,1
1,1,1,1,1,1,1,1
1,1,1,1,1,1,1,1
1,1,2,1,1,2,1,1
1,1,1,1,1,1,1,1
endlayer

layer
1,1,1,1,1,1,1,1
1,1,1,1,1,1,1,1
1,1,1,2,1,1,2,1
1,1,1,1,1,1,1,1
1,1,1,1,1,1,1,1
1,1,2,1,1,2,1,1
1,1,1,1,1,1,1,1
endlayer

layer
1,1,1,1,1,1,1,1
1,1,1,1,1,1,1,1
1,1,1,2,1,1,2,1
1,1,1,1,1,1,1,1
1,1,1,1,1,1,1,1
1,1,2,1,1,2,1,1
1,1,1,1,1,1,1,1
endlayer

layer
1,1,1,1,1,1,1,1
1,1,1,1,1,1,1,1
1,1,1,2,1,1,2,1
1,1,1,1,1,1,1,1
1,1,1,1,1,1,1,1
1,1,2,1,1,2,1,1
1,1,1,1,1,1,1,1
endlayer

layer
1,1,1,1,1,1,1,1
1,1,1,1,1,1,1,1
1,1,3,3,3,3,3,3
1,1,1,1,1,1,1,1
1,1,1,1,1,1,1,1
1,1,2,1,1,2,1,1
1,1,1,1,1,1,1,1
endlayer

layer
1,1,1,1,1,1,1,1
1,1,4,1,1,1,4,1
1,1,4,2,1,1,4,1
1,1,4,1,1,1,4,1
1,1,4,1,1,1,4,1
1,1,4,1,1,2,4,1
1,1,4,1,1,1,4,1
endlayer

layer
1,1,1,1,1,1,1,1
1,1,1,1,1,1,1,1
1,1,1,2,1,1,2,1
1,3,3,3,3,3,3,3
1,1,1,1,1,1,1,1
1,1,2,1,1,2,1,1
1,1,1,1,1,1,1,1
endlayer

layer
1,1,1,1,4,1,1,1
1,3,3,3,4,3,3,3
1,1,1,2,4,1,2,1
1,1,1,1,4,5,5,1
1,1,1,1,4,1,1,1
1,1,2,1,4,2,1,1
1,1,1,1,4,1,1,1
endlayer

layer
1,1,1,1,1,1,1,1
1,1,6,6,6,6,1,1
1,1,6,6,6,6,2,1
1,1,6,6,6,6,5,1
1,1,6,6,6,6,5,1
1,1,2,1,1,2,5,1
1,1,1,1,1,1,1,1
endlayer

layer
1,1,1,1,1,1,1,1
1,1,1,1,1,1,1,1
1,1,1,1,1,1,2,5
1,1,1,1,1,1,6,1
1,1,1,1,1,1,6,1
5,3,3,3,3,2,5,1
1,1,1,1,1,5,1,1
endlayer

layer
1,1,1,1,1,1,1,1
1,1,1,1,1,1,1,1
1,1,1,1,1,1,2,1
1,1,1,1,1,1,1,1
1,1,1,1,1,1,1,1
1,1,1,1,1,2,6,1
1,1,1,1,1,1,1,1
endlayer

layer
1,1,1,1,1,1,1,1
1,1,1,1,1,1,1,1
1,1,1,1,1,1,2,1
1,1,1,1,1,1,1,1
1,1,1,1,1,1,1,1
1,1,1,1,1,1,1,1
1,1,1,1,1,1,1,1
endlayer

layer
1,1,1,1,1,1,1,1
1,1,1,1,1,1,1,1
1,1,1,1,1,1,2,1
1,1,1,1,1,1,1,1
1,1,1,1,1,1,1,1
1,1,1,1,1,1,1,1
1,1,1,1,1,1,1,1
endlayer

