
# Created by Ruins mod version 16.7 Ingame Parser
# authoring Player: lafuller

weight=1
embed_into_distance=37
acceptable_target_blocks=
unacceptable_target_blocks=flowing_water,water,flowing_lava,lava
dimensions=37,7,7
allowable_overhang=0
max_leveling=10
leveling_buffer=-1
preserve_water=0
preserve_lava=0

rule1=0,100,stonebrick-0,stonebrick-1,stonebrick-2,stonebrick-2,stone-5,stone-6,cobblestone
rule2=0,100,minecraft:log2-0
rule3=0,100,minecraft:stone_brick_stairs-3
rule4=0,100,minecraft:stone_brick_stairs-0
rule5=0,100,minecraft:stone_brick_stairs-7
rule6=0,100,minecraft:stone_brick_stairs-2
rule7=0,100,minecraft:stone_brick_stairs-4
rule8=0,100,minecraft:stone_brick_stairs-1
rule9=0,100,minecraft:stone_brick_stairs-6
rule10=0,100,minecraft:stone_brick_stairs-5
rule11=0,100,CommandBlock:RUINSTRIGGER /testruin Gilly/GillyLumberCatacombs ~6 ~37 ~0 0:@
rule12=0,100,CommandBlock:RUINSTRIGGER /testruin Gilly/GillyLumberCatacombs ~-6 ~36 ~0 0:@
rule13=0,100,CommandBlock:RUINSTRIGGER /testruin Gilly/GillyLumberCatacombs ~0 ~35 ~6 0:@
rule14=0,100,CommandBlock:RUINSTRIGGER /testruin Gilly/GillyLumberCatacombs ~0 ~34 ~-6 0:@

layer
1,1,1,1,1,1,1
1,1,1,1,1,1,1
1,1,1,1,1,1,1
1,1,1,11,1,1,1
1,1,1,1,1,1,1
1,1,1,1,1,1,1
1,1,1,1,1,1,1
endlayer

layer
1,1,1,1,1,1,1
1,1,1,1,1,1,1
1,1,1,1,1,1,1
1,1,1,12,1,1,1
1,1,1,1,1,1,1
1,1,1,1,1,1,1
1,1,1,1,1,1,1
endlayer

layer
1,1,1,1,1,1,1
1,1,1,1,1,1,1
1,1,1,1,1,1,1
1,1,1,13,1,1,1
1,1,1,1,1,1,1
1,1,1,1,1,1,1
1,1,1,1,1,1,1
endlayer

layer
1,1,1,1,1,1,1
1,1,1,1,1,1,1
1,1,1,1,1,1,1
1,1,1,14,1,1,1
1,1,1,1,1,1,1
1,1,1,1,1,1,1
1,1,1,1,1,1,1
endlayer

layer
1,1,1,1,1,1,1
1,1,1,1,1,1,1
1,1,1,1,1,1,1
1,1,1,1,1,1,1
1,1,1,1,1,1,1
1,1,1,1,1,1,1
1,1,1,1,1,1,1
endlayer

layer
2,0,0,3,1,1,2
0,0,0,3,1,1,1
0,0,0,3,1,1,1
0,0,0,2,1,1,1
0,0,0,0,1,1,1
0,0,0,0,1,1,1
2,0,0,0,1,1,2
endlayer

layer
2,0,0,0,0,0,2
0,0,0,0,3,4,1
0,0,0,0,3,1,1
0,0,0,2,1,1,1
0,0,0,0,1,1,1
0,0,0,0,1,1,1
2,0,0,0,1,1,2
endlayer

layer
2,0,0,0,0,0,2
0,0,0,0,0,0,3
0,0,0,0,0,0,3
0,0,0,2,4,4,3
0,0,0,0,1,1,1
0,0,0,0,1,1,1
2,0,0,0,1,1,2
endlayer

layer
2,0,0,0,0,0,2
0,0,0,0,0,0,0
0,0,0,0,0,0,0
0,0,0,2,0,0,0
0,0,0,5,4,4,0
0,0,0,5,1,6,0
2,0,0,5,1,1,2
endlayer

layer
2,0,0,0,0,0,2
0,0,0,0,0,0,0
0,0,0,0,0,0,0
0,0,0,2,0,0,0
0,0,0,6,0,0,0
7,7,7,6,0,0,0
2,1,1,4,4,4,2
endlayer

layer
2,0,0,0,0,0,2
0,0,0,0,0,0,0
0,0,0,0,0,0,0
7,7,7,2,0,0,0
1,1,6,0,0,0,0
1,8,6,0,0,0,0
2,0,0,0,0,0,2
endlayer

layer
2,9,0,0,0,0,2
1,9,0,0,0,0,0
1,9,0,0,0,0,0
6,8,8,2,0,0,0
6,0,0,0,0,0,0
6,0,0,0,0,0,0
2,0,0,0,0,0,2
endlayer

layer
2,1,1,9,0,0,2
0,3,1,9,0,0,0
0,3,8,9,0,0,0
0,0,0,2,0,0,0
0,0,0,0,0,0,0
0,0,0,0,0,0,0
2,0,0,0,0,0,2
endlayer

layer
2,8,8,8,1,1,2
0,0,0,3,10,10,10
0,0,0,3,0,0,0
0,0,0,2,0,0,0
0,0,0,0,0,0,0
0,0,0,0,0,0,0
2,0,0,0,0,0,2
endlayer

layer
2,0,0,0,0,0,2
0,0,0,0,4,4,1
0,0,0,0,3,1,1
0,0,0,2,10,10,10
0,0,0,0,0,0,0
0,0,0,0,0,0,0
2,0,0,0,0,0,2
endlayer

layer
2,0,0,0,0,0,2
0,0,0,0,0,0,3
0,0,0,0,0,0,3
0,0,0,2,4,4,3
0,0,0,0,0,5,1
0,0,0,0,0,5,1
2,0,0,0,0,5,2
endlayer

layer
2,0,0,0,0,0,2
0,0,0,0,0,0,0
0,0,0,0,0,0,0
0,0,0,2,0,0,0
0,0,0,5,4,6,0
0,0,0,5,1,6,0
2,0,0,5,1,1,2
endlayer

layer
2,0,0,0,0,0,2
0,0,0,0,0,0,0
0,0,0,0,0,0,0
0,0,0,2,0,0,0
0,0,0,6,0,0,0
7,7,7,6,0,0,0
2,1,1,4,4,4,2
endlayer

layer
2,0,0,0,0,0,2
0,0,0,0,0,0,0
0,0,0,0,0,0,0
7,7,7,2,0,0,0
1,1,6,0,0,0,0
1,8,8,0,0,0,0
2,0,0,0,0,0,2
endlayer

layer
2,9,0,0,0,0,2
1,9,0,0,0,0,0
1,9,0,0,0,0,0
6,8,8,2,0,0,0
6,0,0,0,0,0,0
6,0,0,0,0,0,0
2,0,0,0,0,0,2
endlayer

layer
2,1,1,9,0,0,2
0,3,1,9,0,0,0
0,3,8,9,0,0,0
0,0,0,2,0,0,0
0,0,0,0,0,0,0
0,0,0,0,0,0,0
2,0,0,0,0,0,2
endlayer

layer
2,8,8,8,1,1,2
0,0,0,3,10,10,10
0,0,0,3,0,0,0
0,0,0,2,0,0,0
0,0,0,0,0,0,0
0,0,0,0,0,0,0
2,0,0,0,0,0,2
endlayer

layer
2,0,0,0,0,0,2
0,0,0,0,4,4,1
0,0,0,0,3,1,1
0,0,0,2,10,10,10
0,0,0,0,0,0,0
0,0,0,0,0,0,0
2,0,0,0,0,0,2
endlayer

layer
2,0,0,0,0,0,2
0,0,0,0,0,0,3
0,0,0,0,0,0,3
0,0,0,2,4,4,3
0,0,0,0,0,5,1
0,0,0,0,0,5,1
2,0,0,0,0,5,2
endlayer

layer
2,0,0,0,0,0,2
0,0,0,0,0,0,0
0,0,0,0,0,0,0
0,0,0,2,0,0,0
0,0,0,5,4,6,0
0,0,0,5,1,6,0
2,0,0,5,1,1,2
endlayer

layer
2,0,0,0,0,0,2
0,0,0,0,0,0,0
0,0,0,0,0,0,0
0,0,0,2,0,0,0
0,0,0,6,0,0,0
7,7,7,6,0,0,0
2,1,1,4,4,4,2
endlayer

layer
2,0,0,0,0,0,2
0,0,0,0,0,0,0
0,0,0,0,0,0,0
7,7,7,2,0,0,0
1,1,6,0,0,0,0
1,8,6,0,0,0,0
2,0,0,0,0,0,2
endlayer

layer
2,9,0,0,0,0,2
1,9,0,0,0,0,0
1,9,0,0,0,0,0
6,8,8,2,0,0,0
6,0,0,0,0,0,0
6,0,0,0,0,0,0
2,0,0,0,0,0,2
endlayer

layer
2,1,1,9,0,0,2
0,3,1,9,0,0,0
0,8,8,9,0,0,0
0,0,0,2,0,0,0
0,0,0,0,0,0,0
0,0,0,0,0,0,0
2,0,0,0,0,0,2
endlayer

layer
2,8,8,8,1,1,2
0,0,0,3,10,10,10
0,0,0,3,0,0,0
0,0,0,2,0,0,0
0,0,0,0,0,0,0
0,0,0,0,0,0,0
2,0,0,0,0,0,2
endlayer

layer
2,0,0,0,0,0,2
0,0,0,0,4,4,1
0,0,0,0,3,1,1
0,0,0,2,10,10,10
0,0,0,0,0,0,0
0,0,0,0,0,0,0
2,0,0,0,0,0,2
endlayer

layer
2,0,0,0,0,0,2
0,0,0,0,0,0,3
0,0,0,0,0,0,3
0,0,0,2,4,4,3
0,0,0,0,0,5,1
0,0,0,0,0,5,1
2,0,0,0,0,5,2
endlayer

layer
2,0,0,0,0,0,2
0,0,0,0,0,0,0
0,0,0,0,0,0,0
0,0,0,2,0,0,0
0,0,0,5,4,4,0
0,0,0,5,1,6,0
2,0,0,5,1,1,2
endlayer

layer
2,0,0,0,0,0,2
0,0,0,0,0,0,0
0,0,0,0,0,0,0
0,0,0,2,0,0,0
0,0,0,6,0,0,0
7,7,7,6,0,0,0
2,1,1,1,1,1,2
endlayer

layer
2,0,0,0,0,0,2
0,0,0,0,0,0,0
0,0,0,0,0,0,0
7,7,7,2,0,0,0
1,1,6,0,0,0,0
1,1,6,0,0,0,0
2,1,1,1,1,1,2
endlayer

layer
2,9,0,0,0,0,2
1,9,0,0,0,0,0
1,9,0,0,0,0,0
1,6,8,2,0,0,0
1,6,0,0,0,0,0
1,6,0,0,0,0,0
2,1,1,1,1,1,2
endlayer

layer
1,1,1,1,1,1,1
1,1,1,1,1,1,1
6,8,8,1,1,1,1
6,0,0,1,10,10,1
6,0,0,0,0,5,1
6,0,0,0,0,5,1
4,4,3,1,1,1,1
endlayer

