
# Created by Ruins mod version 16.7 Ingame Parser
# authoring Player: lafuller

weight=1
embed_into_distance=3
acceptable_target_blocks=
unacceptable_target_blocks=stonebrick,cobblestone,stone,stone_brick_stairs,planks,wooden_slab,dark_oak_fence,dark_oak_stairs,flowing_water,water,flowing_lava,lava,ice,bedrock,netherrack,nether_brick,nether_brick_fence,soul_sand,quartz_ore,end_stone,obsidian,iron_bars,cloud,flesh,ash_block,slime_grass,slime_congealed,slime_dirt
dimensions=9,7,9
allowable_overhang=0
max_leveling=3
leveling_buffer=-1
preserve_water=0
preserve_lava=0

rule1=0,100,minecraft:stone_brick_stairs-0,stone_stairs-0
rule2=0,100,minecraft:stone_brick_stairs-2,stone_stairs-2
rule3=0,100,minecraft:stone-6
rule4=0,100,preserveBlock
rule5=0,100,minecraft:stone_brick_stairs-3,stone_stairs-3
rule6=0,100,stonebrick-0,stonebrick-1,stonebrick-1,stonebrick-2,stonebrick-2,stonebrick-2,stone-5,stone-5,stone-6,cobblestone,cobblestone
rule7=0,100,minecraft:dirt-0
rule8=0,100,minecraft:stone_brick_stairs-1,stone_stairs-1
rule9=0,100,minecraft:stone_brick_stairs-4,stone_stairs-4
rule10=0,100,stonebrick-0,stonebrick-1,stonebrick-1,stonebrick-1,stonebrick-2,stonebrick-2,stone-5,stone-5,stone-6,cobblestone,cobblestone,gravel
rule11=0,100,minecraft:stone-5
rule12=0,100,minecraft:stone_brick_stairs-6,stone_stairs-6
rule13=0,100,minecraft:stone_brick_stairs-7,stone_stairs-7
rule14=0,100,minecraft:stone_brick_stairs-5,stone_stairs-5
rule15=0,100,farmland-7
rule16=0,100,minecraft:dirt-2
rule17=0,100,minecraft:water-0
rule18=0,100,potatoes-3,carrots-3,wheat-3,potatoes-5,carrots-5,wheat-5
rule19=0,100,minecraft:cobblestone_wall-0
rule20=0,100,minecraft:fence-0
rule21=0,100,minecraft:fence_gate-1
rule22=0,100,minecraft:fence_gate-2

layer
1,5,3,4,3,4,3,2,1
3,6,6,6,6,6,6,6,3
4,6,7,7,7,7,7,6,4
3,6,7,7,7,7,7,6,3
4,6,7,7,7,7,7,6,4
3,6,6,6,6,6,6,6,3
8,5,3,4,3,4,3,2,8
endlayer

layer
4,4,5,9,10,9,2,4,4
1,11,10,10,10,10,10,11,1
13,10,7,7,7,7,7,10,12
10,10,7,7,7,7,7,10,10
13,10,7,7,7,7,7,10,12
8,11,10,10,10,10,10,11,8
4,4,5,14,10,14,2,4,4
endlayer

layer
4,4,4,5,1,2,4,4,4
4,11,10,10,10,10,10,11,4
1,10,10,10,10,10,10,10,1
5,10,10,10,10,10,10,10,2
8,10,10,10,10,10,10,10,8
4,11,10,10,10,10,10,11,4
4,4,4,5,8,2,4,4,4
endlayer

layer
4,4,4,4,4,4,4,4,4
4,11,1,1,1,1,1,11,4
4,5,15,16,15,16,15,2,4
4,5,15,16,15,17,15,2,4
4,5,15,16,15,16,15,2,4
4,11,8,8,8,8,8,11,4
4,4,4,4,4,4,4,4,4
endlayer

layer
4,4,4,4,4,4,4,4,4
4,3,4,4,4,4,4,3,4
4,4,18,4,18,4,18,4,4
4,4,18,4,18,4,18,4,4
4,4,18,4,18,4,18,4,4
4,3,4,4,4,4,4,3,4
4,4,4,4,4,4,4,4,4
endlayer

layer
4,4,4,4,4,4,4,4,4
4,19,4,4,4,4,4,19,4
4,4,4,4,4,4,4,4,4
4,4,4,4,4,4,4,4,4
4,4,4,4,4,4,4,4,4
4,19,4,4,4,4,4,19,4
4,4,4,4,4,4,4,4,4
endlayer

layer
4,4,4,4,4,4,4,4,4
4,20,4,4,4,4,4,20,4
4,4,4,4,4,4,4,4,4
4,4,4,4,4,4,4,4,4
4,4,4,4,4,4,4,4,4
4,20,4,4,4,4,4,20,4
4,4,4,4,4,4,4,4,4
endlayer

layer
4,4,4,4,4,4,4,4,4
4,20,21,21,21,21,21,20,4
4,22,4,4,4,4,4,22,4
4,22,4,4,4,4,4,22,4
4,22,4,4,4,4,4,22,4
4,20,21,21,21,21,21,20,4
4,4,4,4,4,4,4,4,4
endlayer

layer
22,22,22,22,22,22,22,22,22
20,20,20,20,20,20,20,20,20
22,22,22,22,22,22,22,22,22
22,22,22,22,22,22,22,22,22
22,22,22,22,22,22,22,22,22
20,20,20,20,20,20,20,20,20
22,22,22,22,22,22,22,22,22
endlayer

