# Gilly's Reactor Access Port
# vanilla blocks only

# template generated by Ruins mod version 16.5 Ingame Parser
# Structure created and developed by Gilly

weight=1
embed_into_distance=14
acceptable_target_blocks=
unacceptable_target_blocks=flowing_water,water,flowing_lava,lava,ice,bedrock,netherrack,nether_brick,nether_brick_fence,soul_sand,quartz_ore,end_stone,obsidian,iron_bars,cloud,flesh,ash_block,slime_grass,slime_congealed,slime_dirt
dimensions=25,11,11
allowable_overhang=0
max_leveling=4
leveling_buffer=-1
preserve_water=0
preserve_lava=0

rule1=0,100,minecraft:stained_hardened_clay-8
rule2=0,100,minecraft:stained_hardened_clay-9
rule3=0,100,preserveBlock
rule4=0,100,minecraft:iron_bars-0
rule5=0,100,minecraft:ladder-3
rule6=0,100,minecraft:ladder-2
rule7=0,0,minecraft:sea_lantern-0
rule8=0,100,minecraft:stained_glass-8
rule9=0,100,minecraft:stained_glass-7
rule10=0,100,ChestGenHook:chests/village_blacksmith:5-2
rule11=0,100,minecraft:stone_brick_stairs-2
rule12=0,100,minecraft:stone_brick_stairs-1
rule13=0,100,minecraft:cauldron-0
rule14=0,100,minecraft:double_stone_slab-8
rule15=0,100,minecraft:stained_hardened_clay-4
rule16=0,100,ChestGenHook:chests/stronghold_corridor:4-2

layer
3,3,1,3,3,1,2,2,2,2,1
3,3,1,3,3,2,0,0,0,0,2
3,3,1,3,3,2,0,4,4,0,2
3,1,1,3,3,2,1,6,5,1,2
3,3,1,3,3,1,2,2,2,2,1
3,3,1,3,2,2,2,2,2,2,2
1,2,2,2,1,2,2,2,2,2,2
2,4,4,4,2,2,2,7,2,2,2
2,4,0,4,2,2,2,2,2,2,2
2,4,4,4,2,2,2,2,2,2,2
1,2,2,2,1,1,2,2,2,2,2
endlayer

layer
3,3,3,3,3,1,2,2,2,2,1
3,1,1,1,1,2,0,0,0,0,2
3,3,3,3,3,2,0,4,4,0,2
3,1,3,3,3,2,1,6,5,1,2
3,1,3,3,3,1,2,2,2,2,1
3,1,1,1,2,1,1,1,1,1,2
1,2,2,2,1,1,1,1,1,1,3
2,4,4,4,2,1,1,8,1,1,3
2,4,0,4,2,1,1,1,1,1,3
2,4,4,4,2,1,1,1,1,1,2
1,2,2,2,1,1,3,3,3,2,3
endlayer

layer
3,3,1,3,3,1,2,2,2,2,1
3,3,1,3,3,2,0,0,0,0,2
3,3,1,3,3,2,0,4,4,0,2
3,1,1,3,3,2,1,6,5,1,2
3,3,1,3,3,2,2,9,9,2,1
3,3,1,3,2,16,0,0,0,0,2
1,2,2,2,2,10,0,0,0,0,2
2,4,4,4,2,0,0,0,0,0,2
2,4,0,4,2,0,0,0,0,0,2
2,4,4,4,2,0,0,0,0,0,2
1,2,2,2,1,2,2,2,2,2,2
endlayer

layer
3,3,3,3,3,1,2,2,2,2,1
3,1,1,1,1,2,0,0,0,0,2
3,3,3,3,3,2,0,4,4,0,2
3,1,3,3,3,2,1,6,5,1,2
3,1,3,3,3,2,2,9,9,2,1
3,1,1,1,2,0,0,0,0,0,2
1,2,2,2,2,0,0,0,0,0,2
2,4,4,4,2,0,0,0,0,0,2
2,4,0,4,2,0,0,0,0,0,2
2,4,4,4,2,0,0,0,0,0,2
1,2,2,2,1,2,2,2,2,2,3
endlayer

layer
3,3,1,3,3,1,2,2,2,2,1
3,3,1,3,3,2,0,0,0,0,2
3,3,1,3,3,2,0,4,4,0,2
3,1,1,3,3,2,1,6,5,1,2
3,3,1,3,3,2,2,9,9,2,1
3,3,1,3,2,0,0,0,0,0,2
1,2,2,2,2,0,0,0,0,0,2
2,4,4,4,2,0,0,0,0,0,2
2,4,0,4,2,0,0,0,0,0,2
2,4,4,4,2,0,0,0,0,0,2
1,2,2,2,1,2,2,2,2,2,2
endlayer

layer
3,3,3,3,3,1,2,2,2,2,1
3,1,1,1,1,2,0,0,0,0,2
3,3,3,3,3,2,0,4,4,0,2
3,1,3,3,3,2,1,6,5,1,2
3,1,3,3,3,2,2,2,2,2,1
3,1,1,1,2,0,0,0,0,0,2
1,2,2,2,2,0,0,0,0,0,2
2,4,4,4,2,0,0,0,0,0,2
2,4,0,4,2,0,0,0,0,0,2
2,4,4,4,2,0,0,0,0,0,2
1,2,2,2,1,2,2,2,2,2,3
endlayer

layer
3,3,1,3,3,1,2,2,2,2,1
3,3,1,3,3,2,0,0,0,0,2
3,3,1,3,3,2,0,4,4,0,2
3,1,1,3,3,2,1,6,5,1,2
3,3,1,3,3,1,2,2,2,2,1
3,3,1,3,2,2,2,2,2,2,2
1,2,2,2,1,2,0,0,0,2,3
2,4,4,4,2,2,0,0,0,2,3
2,4,0,0,2,2,0,0,0,2,3
2,4,4,4,2,2,2,2,2,2,3
1,2,2,2,1,1,3,3,3,3,2
endlayer

layer
3,3,3,3,3,1,2,2,2,2,1
3,1,1,1,1,2,0,0,0,0,2
3,3,3,3,3,2,4,4,4,4,2
3,1,3,3,3,2,1,6,5,1,2
3,1,3,3,3,1,2,2,2,2,1
3,1,1,1,2,2,2,2,2,2,2
1,2,2,2,1,2,2,2,2,2,2
2,4,4,4,2,2,2,9,2,2,2
2,4,0,4,2,2,2,2,2,2,2
2,4,4,4,2,2,2,2,2,2,2
1,2,2,2,1,1,2,2,2,2,2
endlayer

layer
3,3,1,3,3,1,2,2,2,2,1
3,3,1,3,3,2,0,0,0,0,2
3,3,1,3,3,2,0,4,4,0,2
3,1,1,3,3,2,1,6,5,1,2
3,3,1,3,3,1,2,2,2,2,1
3,3,1,3,2,2,2,2,2,2,2
1,2,2,2,1,2,2,2,2,2,3
2,4,4,4,2,2,2,7,2,2,3
2,4,0,4,2,2,2,2,2,2,2
2,4,4,4,2,2,2,2,2,2,2
1,2,2,2,1,1,12,12,12,12,11
endlayer

layer
3,3,3,3,3,1,2,2,2,2,1
3,1,1,1,1,2,0,0,0,0,2
3,1,2,2,2,2,0,4,4,0,2
1,1,2,2,2,2,1,6,5,1,2
1,2,2,2,2,1,2,2,2,2,1
1,2,2,2,2,2,2,2,2,2,2
1,2,2,2,1,2,2,2,2,2,3
2,4,4,4,2,2,2,2,2,2,2
2,4,0,4,2,2,2,2,2,2,2
2,4,4,4,2,2,12,12,12,12,11
1,2,2,2,1,1,3,3,3,3,3
endlayer

layer
3,3,3,3,3,1,2,2,2,2,1
3,3,3,3,3,2,0,0,0,0,2
3,3,2,2,2,2,0,4,4,0,2
3,1,2,2,2,2,1,6,5,1,2
3,2,2,2,2,1,7,13,13,7,1
3,2,2,2,2,2,2,2,2,2,2
1,2,2,2,1,2,2,2,2,2,2
2,4,4,4,2,2,2,2,2,2,2
2,4,0,4,2,2,12,12,12,12,11
2,4,4,4,2,2,3,3,3,3,3
1,2,2,2,1,1,3,3,3,3,3
endlayer

layer
3,3,3,3,3,1,2,2,2,2,1
3,1,1,1,1,2,0,0,0,0,2
3,1,2,2,2,2,0,4,4,0,2
1,1,2,2,2,2,1,6,5,1,2
1,2,2,2,2,1,2,2,2,2,1
1,2,2,2,2,2,2,2,2,2,2
1,2,2,2,1,1,2,2,2,2,2
2,4,4,4,2,3,12,12,12,12,11
2,4,0,4,2,3,3,3,3,3,3
2,4,4,4,2,1,3,3,3,3,3
1,1,1,1,1,3,3,3,3,3,3
endlayer

layer
3,3,3,3,3,1,2,2,2,2,1
3,3,3,3,3,2,0,0,0,0,2
3,3,2,2,2,2,0,4,4,0,2
3,1,2,2,2,2,1,6,5,1,2
3,2,2,2,2,1,2,2,2,2,1
3,2,2,2,2,2,2,2,2,2,2
1,2,2,2,1,1,12,12,12,12,11
1,4,4,4,1,3,3,3,3,3,3
1,4,0,4,1,3,3,3,3,3,3
1,4,4,4,1,1,3,3,3,3,3
1,2,2,2,1,3,3,3,3,3,3
endlayer

layer
3,3,3,3,3,1,1,1,1,1,1
3,1,1,1,1,2,0,0,0,0,2
3,1,2,2,2,2,0,4,4,0,2
1,1,14,14,14,2,1,6,5,1,2
1,14,14,14,14,1,15,15,15,15,1
1,14,14,14,14,1,12,12,12,12,11
1,2,2,2,1,1,3,3,3,3,3
2,4,4,4,2,3,3,3,3,3,3
2,4,0,4,2,3,3,3,3,3,3
2,4,4,4,2,1,3,3,3,3,3
1,1,1,1,1,3,3,3,3,3,3
endlayer

layer
3,3,3,3,3,1,1,3,3,1,1
3,3,3,3,3,2,0,0,0,0,2
3,3,2,2,2,2,0,4,4,0,2
3,1,1,1,1,1,1,6,5,1,2
2,3,3,3,3,3,3,3,3,3,3
2,3,3,3,3,3,3,3,3,3,3
1,2,3,3,1,1,3,3,3,3,3
1,4,4,4,1,3,3,3,3,3,3
1,4,0,4,1,3,3,3,3,3,3
1,4,4,4,1,1,3,3,3,3,3
1,3,3,3,1,3,3,3,3,3,3
endlayer

layer
3,3,3,3,3,1,1,1,1,1,1
3,1,1,1,1,2,0,0,0,0,3
3,1,2,2,2,2,0,4,4,1,1
1,1,3,3,3,3,15,6,5,15,3
1,1,3,3,3,3,3,3,3,3,3
1,1,3,3,3,3,3,3,3,3,3
1,1,3,3,3,1,3,3,3,3,3
3,4,4,4,0,3,3,3,3,3,3
3,4,0,4,0,3,3,3,3,3,3
3,4,4,4,0,1,3,3,3,3,3
1,1,1,1,1,3,3,3,3,3,3
endlayer

layer
3,3,3,3,3,1,1,3,3,1,1
3,3,3,3,3,2,1,0,0,1,3
3,3,2,2,2,2,1,4,4,1,3
3,1,1,1,1,1,1,6,5,1,3
3,3,3,3,3,3,3,3,3,3,3
3,3,3,3,3,3,3,3,3,3,3
1,1,3,3,1,1,3,3,3,3,3
1,4,4,4,1,3,3,3,3,3,3
1,4,0,4,1,3,3,3,3,3,3
1,4,4,4,1,1,3,3,3,3,3
1,3,3,3,1,3,3,3,3,3,3
endlayer

layer
3,3,3,3,3,1,1,1,1,1,1
3,1,1,1,1,2,0,0,0,0,3
3,1,2,2,2,2,0,4,4,1,1
1,1,3,3,3,3,1,6,5,1,3
1,1,3,3,3,3,3,3,3,3,3
1,1,3,3,3,3,3,3,3,3,3
1,1,3,3,3,1,3,3,3,3,3
3,4,4,4,0,3,3,3,3,3,3
3,4,0,4,0,3,3,3,3,3,3
3,4,4,4,0,1,3,3,3,3,3
1,1,1,1,1,3,3,3,3,3,3
endlayer

layer
3,3,3,3,3,1,1,3,3,1,1
3,3,3,3,3,2,1,0,0,1,3
3,3,2,2,2,2,1,4,4,1,3
3,1,1,1,1,1,1,6,5,1,3
3,3,3,3,3,3,3,3,3,3,3
3,3,3,3,3,3,3,3,3,3,3
1,1,1,1,1,1,3,3,3,3,3
1,4,4,4,1,3,3,3,3,3,3
1,4,0,4,1,3,3,3,3,3,3
1,4,4,4,1,1,3,3,3,3,3
1,3,3,3,1,3,3,3,3,3,3
endlayer

layer
3,3,3,3,3,1,1,1,1,1,1
3,1,1,1,1,2,0,0,0,0,3
3,1,2,2,2,2,0,4,4,1,1
1,1,3,3,3,3,1,6,5,1,3
1,1,3,3,3,3,3,3,3,3,3
1,1,3,3,3,3,3,3,3,3,3
1,1,3,3,3,1,3,3,3,3,3
3,4,4,4,0,3,3,3,3,3,3
3,4,0,4,0,3,3,3,3,3,3
3,4,4,4,0,1,3,3,3,3,3
1,1,1,1,1,3,3,3,3,3,3
endlayer

layer
3,3,3,3,3,1,1,3,3,1,1
3,3,3,3,3,2,1,0,0,1,3
3,3,3,3,3,2,1,4,4,1,3
3,1,1,1,1,1,1,6,5,1,3
3,3,3,3,1,0,0,0,0,0,3
3,3,3,3,1,0,0,0,0,3,3
1,1,0,0,1,1,0,0,0,3,3
1,0,0,0,1,3,0,0,3,3,3
1,0,0,0,1,3,3,3,3,3,3
1,0,0,0,1,1,3,3,3,3,3
1,3,3,3,1,3,3,3,3,3,3
endlayer

layer
3,3,3,3,3,1,1,1,1,1,1
3,3,3,0,0,0,0,0,0,0,3
3,3,0,0,0,0,0,4,4,1,1
0,1,0,0,0,0,1,6,5,1,3
0,1,0,0,0,0,0,0,0,0,0
0,1,0,0,0,0,0,0,0,0,0
1,1,1,1,1,1,0,0,0,0,3
0,0,0,0,0,0,0,0,0,0,3
0,0,0,0,0,0,0,0,0,3,3
0,0,0,0,0,1,0,0,3,3,3
1,1,1,1,1,0,3,3,3,3,3
endlayer

layer
3,3,3,0,0,1,1,0,0,1,1
3,3,0,0,0,0,1,0,0,1,3
3,0,0,0,0,0,1,4,4,1,3
1,1,1,1,1,1,1,6,5,1,0
1,0,0,0,0,0,0,0,0,0,0
1,0,0,0,0,0,0,0,0,0,0
1,0,0,0,0,1,0,0,0,0,0
1,0,0,0,0,1,0,0,0,0,0
1,0,0,0,0,1,0,0,0,0,3
1,0,0,0,0,1,0,0,0,3,3
1,0,0,0,1,1,0,0,3,3,3
endlayer

layer
3,3,0,0,0,1,0,0,0,0,1
3,0,0,0,0,1,1,1,1,1,1
0,0,0,0,0,0,0,0,0,0,0
0,0,0,0,0,0,1,6,5,1,0
0,0,0,0,0,0,0,0,0,0,0
0,0,0,0,0,0,0,0,0,0,0
1,1,1,1,1,1,0,0,0,0,0
0,0,0,0,0,0,0,0,0,0,0
0,0,0,0,0,0,0,0,0,0,0
0,0,0,0,0,0,0,0,0,0,3
1,1,1,1,1,1,0,0,0,3,3
endlayer

layer
3,0,0,0,0,0,0,0,0,0,0
0,0,0,0,0,0,1,0,0,1,0
0,0,0,0,0,0,1,0,0,1,0
0,0,0,0,0,0,1,6,5,1,0
0,0,0,0,0,0,0,0,0,0,0
0,0,0,0,0,0,0,0,0,0,0
0,0,0,0,0,0,0,0,0,0,0
0,0,0,0,0,0,0,0,0,0,0
0,0,0,0,0,0,0,0,0,0,0
0,0,0,0,0,0,0,0,0,0,0
0,0,0,0,0,0,0,0,0,0,3
endlayer

