
# Created by Ruins mod version 16.7 Ingame Parser
# authoring Player: lafuller

weight=1
embed_into_distance=5
acceptable_target_blocks=
unacceptable_target_blocks=flowing_water,water,flowing_lava,lava,ice,bedrock,netherrack,nether_brick,nether_brick_fence,soul_sand,quartz_ore,end_stone,obsidian,iron_bars,cloud,flesh,ash_block,slime_grass,slime_congealed,slime_dirt
dimensions=12,21,20
allowable_overhang=0
max_leveling=7
leveling_buffer=-1
preserve_water=0
preserve_lava=0

rule1=0,100,preserveBlock
rule2=0,100,minecraft:double_stone_slab-9
rule3=0,100,minecraft:sandstone_stairs-3
rule4=0,100,minecraft:sandstone-0
rule5=0,100,minecraft:sandstone-2
rule6=0,100,minecraft:sandstone_stairs-0
rule7=0,100,minecraft:sandstone_stairs-1
rule8=0,100,minecraft:sandstone_stairs-2
rule9=0,100,minecraft:dirt-0
rule10=0,100,bookshelf,pumpkin,melon_block,hay_block,ChestGenHook:chests/spawn_bonus_chest:5-5,ChestGenHook:chests/village_blacksmith:5-5,ChestGenHook:chests/stronghold_library:5-5,ChestGenHook:chests/simple_dungeon:5-5
rule11=0,100,minecraft:wooden_slab-9
rule12=0,100,minecraft:ladder-2
rule13=0,100,minecraft:spruce_stairs-7
rule14=0,100,minecraft:spruce_stairs-6
rule15=0,100,bookshelf,pumpkin,melon_block,hay_block,ChestGenHook:chests/spawn_bonus_chest:5-4,ChestGenHook:chests/village_blacksmith:5-4,ChestGenHook:chests/stronghold_library:5-4,ChestGenHook:chests/simple_dungeon:5-4
rule16=0,100,minecraft:ladder-3
rule17=0,100,minecraft:ladder-5
rule18=0,100,minecraft:trapdoor-8
rule19=0,100,minecraft:carpet-7
rule20=0,100,minecraft:carpet-8
rule21=0,100,minecraft:sandstone_stairs-6
rule22=0,100,minecraft:trapdoor-0
rule23=0,100,minecraft:sandstone_stairs-7
rule24=0,100,minecraft:spruce_stairs-5
rule25=0,100,minecraft:spruce_stairs-4
rule26=0,100,minecraft:spruce_fence-0
rule27=0,100,minecraft:jungle_door-5
rule28=0,100,minecraft:jungle_door-7
rule29=0,100,minecraft:jungle_door-6
rule30=0,100,minecraft:jungle_door-4
rule31=0,100,minecraft:ladder-4
rule32=0,100,minecraft:jungle_door-8
rule33=0,100,minecraft:jungle_door-9
rule34=0,100,minecraft:wooden_slab-1
rule35=0,100,minecraft:stone_slab-9
rule36=0,100,minecraft:trapdoor-9
rule37=0,100,minecraft:sandstone_stairs-5
rule38=0,100,minecraft:spruce_fence_gate-2
rule39=0,100,minecraft:stone_slab-1
rule40=0,100,minecraft:trapdoor-10
rule41=0,100,minecraft:trapdoor-1
rule42=0,100,minecraft:trapdoor-2
rule43=0,100,minecraft:hay_block-0
rule44=0,100,minecraft:trapdoor-3

layer
1,1,1,1,1,1,1,1,1,3,2,2,2,2,2,2,2,2,2,1
1,1,1,1,1,1,1,3,6,3,5,4,2,5,4,4,4,4,2,1
4,4,4,4,5,4,2,2,2,2,5,4,2,5,4,4,4,4,2,1
2,2,2,2,2,2,2,2,4,4,4,4,2,4,4,4,4,4,2,5
2,4,4,4,4,4,2,2,2,2,2,2,2,4,4,4,4,4,4,4
2,4,4,4,4,4,2,2,2,2,2,2,2,4,4,4,4,4,4,4
2,4,4,4,4,4,2,2,2,2,2,2,2,4,4,4,4,2,2,4
2,4,4,4,4,4,2,2,2,2,2,4,4,4,4,4,2,4,4,4
2,4,4,4,4,4,2,2,2,2,2,4,4,4,4,4,2,4,4,4
2,2,2,2,2,2,4,4,4,4,2,4,4,4,4,4,2,5,4,4
2,2,2,2,2,4,4,4,4,4,2,4,4,4,4,4,2,5,4,4
5,4,5,4,2,4,4,4,4,4,2,4,4,4,4,4,2,2,1,1
2,4,5,4,2,4,4,4,4,4,2,2,2,2,2,2,2,7,1,1
7,2,2,2,2,4,4,4,4,4,2,2,2,2,2,2,2,1,1,1
1,4,2,2,2,2,2,2,2,2,2,2,2,2,2,4,4,1,1,1
1,4,2,4,4,4,4,4,2,2,2,2,2,2,2,4,2,1,1,1
1,4,2,4,4,4,4,4,2,2,2,2,2,4,2,8,7,1,1,1
1,4,2,4,4,4,4,4,2,2,2,2,5,5,1,1,1,1,1,1
1,4,2,4,4,4,4,4,2,4,4,2,5,5,1,1,1,1,1,1
1,4,2,4,4,4,5,5,2,4,4,5,5,7,1,1,1,1,1,1
1,4,2,2,2,2,2,2,2,2,4,5,8,1,1,1,1,1,1,1
endlayer

layer
1,1,1,1,1,1,1,1,1,1,3,2,2,2,2,2,2,2,2,1
1,1,1,1,1,1,1,1,1,1,5,4,2,5,4,4,4,4,2,1
4,4,4,4,5,4,2,2,6,6,5,4,2,5,4,4,4,4,2,1
2,2,2,2,2,2,2,2,4,4,4,4,2,4,4,4,4,4,2,5
2,4,4,4,4,4,2,2,2,2,2,2,2,4,4,4,4,4,4,4
2,4,4,4,4,4,2,2,2,2,2,2,2,4,4,4,4,4,4,4
2,4,4,4,4,4,2,2,2,2,2,2,2,4,4,4,4,2,2,4
2,4,4,4,4,4,2,2,2,2,2,4,4,4,4,4,2,4,4,4
2,4,4,4,4,4,2,2,2,2,2,4,4,4,4,4,2,4,4,4
2,2,2,2,2,2,4,4,4,4,2,4,4,4,4,4,2,5,4,4
2,2,2,2,2,4,4,4,4,4,2,4,4,4,4,4,2,5,4,5
5,4,5,4,2,4,4,4,4,4,2,4,4,4,4,4,2,7,1,1
7,4,5,4,2,4,4,4,4,4,2,2,2,2,2,2,2,1,1,1
1,2,2,2,2,4,4,4,4,4,2,2,2,2,2,2,2,1,1,1
1,4,2,2,2,2,2,2,2,2,2,2,2,2,2,4,4,1,1,1
1,4,2,4,4,4,4,4,2,2,2,2,2,2,2,4,7,1,1,1
1,4,2,4,4,4,4,4,2,2,2,2,2,4,8,1,1,1,1,1
1,4,2,4,4,4,4,4,2,2,2,9,9,5,1,1,1,1,1,1
1,4,2,4,4,4,4,4,2,4,4,9,5,7,1,1,1,1,1,1
1,4,2,4,4,4,5,5,2,4,4,5,5,1,1,1,1,1,1,1
1,4,2,2,2,2,2,2,2,2,4,8,1,1,1,1,1,1,1,1
endlayer

layer
1,1,1,1,1,1,1,1,1,1,1,2,2,2,2,2,2,2,2,1
1,1,1,1,1,1,1,1,1,1,6,4,2,2,10,0,0,0,2,1
5,5,5,4,4,5,2,2,1,1,5,4,2,2,0,0,0,0,2,1
2,0,0,0,2,2,2,2,6,6,5,4,2,11,0,0,0,0,2,5
2,0,0,0,0,4,2,2,2,2,2,2,2,11,0,0,0,0,0,4
2,12,0,0,0,4,2,2,2,2,2,2,2,11,0,0,0,0,0,4
2,4,0,0,0,11,2,2,2,2,2,2,2,4,4,5,6,6,2,5
2,4,0,0,0,11,2,2,2,2,2,4,4,4,4,4,2,4,4,4
2,4,15,0,0,11,2,2,2,2,2,10,14,11,13,4,2,4,9,5
2,2,2,2,2,2,10,0,0,0,2,0,0,0,0,4,2,5,9,5
2,2,2,2,2,0,0,0,0,0,2,0,0,0,0,5,2,7,3,5
7,4,5,4,11,0,0,0,0,0,2,12,0,0,0,4,2,1,1,1
1,4,5,4,11,0,0,0,0,0,2,8,0,0,0,2,2,1,1,1
1,2,2,2,11,0,0,0,0,16,2,2,2,2,2,2,2,1,1,1
1,5,2,2,2,4,4,4,2,2,2,2,2,2,2,4,7,1,1,1
1,4,2,2,2,17,0,0,0,2,2,2,2,2,2,4,1,1,1,1
1,4,2,0,0,0,0,0,0,2,2,2,8,1,1,1,1,1,1,1
1,4,18,0,0,0,0,0,0,2,2,1,1,1,1,1,1,1,1,1
1,4,18,0,0,0,0,0,15,4,4,1,1,1,1,1,1,1,1,1
1,4,2,11,11,11,5,5,2,4,4,1,1,1,1,1,1,1,1,1
1,4,2,2,2,2,2,2,2,2,8,1,1,1,1,1,1,1,1,1
endlayer

layer
1,1,1,1,1,1,1,1,1,1,1,2,2,2,2,2,2,2,2,1
1,1,1,1,1,1,1,1,1,1,1,7,9,2,0,0,0,0,2,1
5,4,4,4,4,4,4,5,1,1,1,3,9,2,0,0,0,0,2,1
2,0,0,0,2,2,9,4,1,1,1,4,2,0,0,0,0,0,2,4
2,0,0,0,0,4,9,4,6,6,6,2,2,0,0,0,0,0,0,4
2,12,0,0,0,4,2,2,2,2,2,2,2,0,0,0,0,0,0,4
2,4,0,0,0,19,2,2,9,9,4,2,2,4,4,8,0,0,2,5
2,4,0,0,0,19,2,2,2,2,2,4,4,4,4,4,2,5,4,4
2,4,0,0,0,20,2,2,2,2,2,0,19,19,20,4,2,5,1,1
7,2,2,2,2,2,0,0,0,0,2,0,0,0,0,4,2,7,1,1
1,3,2,2,2,0,0,0,0,0,2,0,0,0,0,5,2,1,1,1
1,6,9,4,0,0,0,0,0,0,2,12,0,0,0,4,2,1,1,1
1,5,9,4,0,0,0,0,0,0,2,0,0,0,0,2,2,1,1,1
1,5,9,2,0,0,0,0,0,16,2,2,2,2,2,2,7,1,1,1
1,5,9,2,2,4,4,4,2,2,2,2,9,9,9,4,1,1,1,1
1,5,9,2,2,17,0,0,0,5,2,2,2,2,4,4,1,1,1,1
1,4,2,0,0,0,0,0,0,2,7,8,1,1,1,1,1,1,1,1
1,4,0,0,0,0,0,0,0,5,1,1,1,1,1,1,1,1,1,1
1,4,0,0,0,0,0,0,0,4,1,1,1,1,1,1,1,1,1,1
1,4,2,20,19,19,5,5,2,2,1,1,1,1,1,1,1,1,1,1
1,4,2,2,2,2,2,2,2,8,1,1,1,1,1,1,1,1,1,1
endlayer

layer
1,1,1,1,1,1,1,1,1,1,1,1,3,2,2,2,2,2,2,1
1,1,1,1,1,1,1,1,1,1,1,1,1,2,0,0,0,0,2,1
4,4,4,4,5,1,1,1,1,1,1,1,1,2,0,0,0,0,2,1
2,0,0,0,2,2,1,1,1,1,1,6,2,0,0,0,0,0,2,5
2,0,0,0,0,4,1,1,1,1,1,2,2,0,0,0,0,0,0,4
2,12,0,0,0,4,2,6,1,1,1,2,2,0,0,0,0,0,0,4
2,4,0,0,0,0,2,8,1,1,6,2,2,4,8,0,0,0,2,4
2,4,0,0,0,0,2,2,2,2,2,4,4,4,4,4,2,5,4,4
7,5,0,0,0,0,2,2,2,2,2,0,0,0,0,5,7,7,1,1
1,2,2,2,2,2,0,0,0,0,2,0,0,0,0,5,1,1,1,1
1,1,3,2,2,0,0,0,0,0,2,0,0,0,0,5,1,1,1,1
1,1,1,2,0,0,0,0,0,0,2,12,0,0,0,5,1,1,1,1
1,1,1,2,0,0,0,0,0,0,2,21,0,0,0,2,1,1,1,1
1,1,1,2,0,0,0,0,0,16,2,2,2,5,2,8,1,1,1,1
1,1,1,2,2,4,4,4,2,2,2,7,1,1,1,1,1,1,1,1
1,1,1,2,2,17,0,0,0,2,7,8,1,1,1,1,1,1,1,1
1,6,5,0,0,0,0,0,0,2,1,1,1,1,1,1,1,1,1,1
1,4,22,0,0,0,0,0,0,2,1,1,1,1,1,1,1,1,1,1
1,4,22,0,0,0,0,0,0,2,1,1,1,1,1,1,1,1,1,1
1,4,2,0,0,0,5,5,2,7,1,1,1,1,1,1,1,1,1,1
1,7,2,2,2,5,1,1,1,1,1,1,1,1,1,1,1,1,1,1
endlayer

layer
1,1,1,1,1,1,1,1,1,1,1,1,1,3,2,5,2,2,5,1
1,1,1,1,1,1,1,1,1,1,1,1,1,6,2,11,11,11,2,1
5,4,5,5,4,1,1,1,1,1,1,1,1,2,2,11,11,11,2,1
5,11,11,14,2,2,1,1,1,1,1,1,2,2,11,11,11,11,11,5
2,11,11,14,23,2,1,1,1,1,1,6,2,11,11,11,11,11,11,4
2,12,11,14,23,2,8,1,1,1,1,7,2,11,11,11,11,11,11,4
5,2,11,14,11,23,2,1,1,1,1,3,2,8,0,0,0,23,5,5
1,3,21,14,11,11,2,6,5,5,2,2,2,2,2,2,2,7,4,8
1,6,21,14,11,11,2,2,5,5,2,11,11,11,11,2,1,1,1,1
1,2,2,2,2,2,2,2,2,2,2,11,11,11,11,2,1,1,1,1
1,1,1,3,2,11,11,13,11,11,2,24,24,24,24,2,1,1,1,1
1,1,1,2,2,11,11,13,11,11,2,12,11,11,11,2,1,1,1,1
1,1,1,2,2,11,11,13,11,11,2,2,2,2,2,2,1,1,1,1
1,1,1,5,2,11,11,13,11,16,2,7,3,2,8,1,1,1,1,1
1,1,1,2,2,2,2,2,2,2,5,1,1,1,1,1,1,1,1,1
1,1,1,5,2,17,11,11,2,8,1,1,1,1,1,1,1,1,1,1
1,1,2,2,25,25,25,25,2,6,1,1,1,1,1,1,1,1,1,1
1,6,5,11,11,11,11,11,2,2,1,1,1,1,1,1,1,1,1,1
1,4,2,11,11,11,11,11,2,7,1,1,1,1,1,1,1,1,1,1
1,7,2,11,11,11,2,2,2,1,1,1,1,1,1,1,1,1,1,1
1,1,5,2,2,5,1,1,1,1,1,1,1,1,1,1,1,1,1,1
endlayer

layer
1,1,1,1,1,1,1,1,1,1,1,1,1,1,2,2,2,2,2,1
1,1,1,1,1,1,1,1,1,1,1,1,1,1,4,0,0,0,2,1
5,4,4,4,5,1,1,1,1,1,1,1,1,1,4,12,0,0,4,1
2,0,0,0,2,26,1,1,1,1,1,1,4,4,0,0,0,0,0,5
2,0,0,0,27,1,1,1,1,1,1,1,5,0,0,0,0,0,0,4
2,12,0,0,5,1,1,1,1,1,1,1,28,0,0,0,0,0,0,4
2,4,0,0,0,5,5,1,1,1,1,1,2,0,0,0,0,2,29,5
1,1,4,0,0,0,2,1,1,26,2,5,5,4,4,4,2,1,1,1
1,1,28,0,0,0,2,1,1,1,28,0,0,0,0,4,1,1,1,1
1,26,2,2,2,2,4,4,1,1,2,0,0,0,0,4,1,1,1,1
1,1,1,1,5,0,0,0,4,30,2,0,0,0,0,4,1,1,1,1
1,1,1,1,28,0,0,0,0,0,2,12,0,0,0,4,1,1,1,1
1,1,1,1,5,0,0,0,0,0,2,2,5,29,5,2,1,1,1,1
1,1,1,26,2,0,0,0,31,16,2,1,1,1,1,1,1,1,1,1
1,1,1,1,2,2,2,2,2,5,2,1,1,1,1,1,1,1,1,1
1,1,1,1,5,17,0,0,2,1,1,1,1,1,1,1,1,1,1,1
1,1,5,4,0,0,0,0,5,1,1,1,1,1,1,1,1,1,1,1
1,1,2,0,0,0,0,0,27,1,1,1,1,1,1,1,1,1,1,1
1,1,28,0,0,0,0,0,5,1,1,1,1,1,1,1,1,1,1,1
1,1,2,0,0,0,4,4,2,1,1,1,1,1,1,1,1,1,1,1
1,1,2,2,2,2,1,1,1,1,1,1,1,1,1,1,1,1,1,1
endlayer

layer
1,1,1,1,1,1,1,1,1,1,1,1,1,1,5,2,1,2,5,1
1,1,1,1,1,1,1,1,1,1,1,1,1,1,1,0,0,0,2,1
5,4,1,4,5,1,1,1,1,1,1,1,1,1,4,12,0,0,4,1
5,0,0,0,5,26,1,1,1,1,1,1,4,4,0,0,0,0,0,4
1,0,0,0,32,1,1,1,1,1,1,1,5,0,0,0,0,0,0,1
4,0,0,0,5,1,1,1,1,1,1,1,33,0,0,0,0,0,0,4
2,4,0,0,0,5,5,1,1,1,1,1,2,0,0,0,0,2,32,5
1,1,4,0,0,0,1,1,1,26,5,5,5,4,4,4,2,1,1,1
1,1,33,0,0,0,2,1,1,1,33,0,0,0,0,4,1,1,1,1
1,26,4,2,2,2,4,4,1,1,2,0,0,0,0,4,1,1,1,1
1,1,1,1,5,0,0,0,4,32,2,0,0,0,0,1,1,1,1,1
1,1,1,1,32,0,0,0,0,0,2,0,0,0,0,4,1,1,1,1
1,1,1,1,5,0,0,0,0,0,2,2,5,32,5,2,1,1,1,1
1,1,1,26,2,0,0,0,31,0,2,1,1,1,1,1,1,1,1,1
1,1,1,1,2,2,2,2,2,2,5,1,1,1,1,1,1,1,1,1
1,1,1,1,5,0,0,0,2,1,1,1,1,1,1,1,1,1,1,1
1,1,4,4,0,0,0,0,5,1,1,1,1,1,1,1,1,1,1,1
1,1,2,0,0,0,0,0,32,1,1,1,1,1,1,1,1,1,1,1
1,1,32,0,0,0,0,0,5,1,1,1,1,1,1,1,1,1,1,1
1,1,2,0,0,0,4,4,2,1,1,1,1,1,1,1,1,1,1,1
1,1,5,2,1,2,1,1,1,1,1,1,1,1,1,1,1,1,1,1
endlayer

layer
1,1,1,1,1,1,1,1,1,1,1,1,1,1,2,2,2,2,2,1
1,1,1,1,1,1,1,1,1,1,1,1,1,1,4,34,34,34,2,1
4,4,4,4,4,1,1,1,1,1,1,1,1,1,4,0,0,0,2,1
2,0,0,0,2,34,1,1,1,1,1,1,5,4,0,0,0,0,0,4
2,0,0,0,5,34,1,1,1,1,1,1,2,0,0,0,0,0,0,4
2,0,0,0,5,34,1,1,1,1,1,1,2,0,0,0,0,0,0,4
2,4,0,0,0,5,2,1,1,1,1,1,2,0,0,0,0,2,2,4
1,11,4,0,0,0,2,1,1,26,2,5,5,4,4,4,2,1,1,1
1,25,4,0,0,0,2,1,1,1,2,0,0,0,0,4,1,1,1,1
1,34,2,2,2,2,4,4,1,1,2,0,0,0,0,4,1,1,1,1
1,1,1,1,2,0,0,0,4,4,2,0,0,0,0,4,1,1,1,1
1,1,1,1,5,0,0,0,0,34,2,0,0,0,0,4,1,1,1,1
1,1,1,1,2,0,0,0,0,34,2,2,2,5,2,2,1,1,1,1
1,1,1,26,2,0,0,0,0,34,2,1,1,1,1,1,1,1,1,1
1,1,1,1,2,2,2,2,2,2,2,1,1,1,1,1,1,1,1,1
1,1,1,1,5,0,0,0,2,1,1,1,1,1,1,1,1,1,1,1
1,1,5,4,0,0,0,0,2,1,1,1,1,1,1,1,1,1,1,1
1,1,2,0,0,0,0,0,5,1,1,1,1,1,1,1,1,1,1,1
1,1,2,0,0,0,0,0,2,1,1,1,1,1,1,1,1,1,1,1
1,1,2,0,0,0,4,4,2,1,1,1,1,1,1,1,1,1,1,1
1,1,2,2,2,2,1,1,1,1,1,1,1,1,1,1,1,1,1,1
endlayer

layer
1,1,1,1,1,1,1,1,1,1,1,1,1,1,2,5,2,2,5,1
1,1,1,1,1,1,1,1,1,1,1,1,1,1,5,0,0,0,2,1
5,4,4,4,5,1,1,1,1,1,1,1,1,1,5,0,0,0,2,1
5,0,0,0,2,1,1,1,1,1,1,1,2,5,0,0,0,0,23,5
2,0,0,0,4,1,1,1,1,1,1,1,2,0,0,0,0,35,35,4
2,0,0,0,5,1,1,1,1,1,1,1,2,0,0,0,0,35,36,4
5,5,37,37,37,5,2,1,1,1,1,1,2,0,0,0,0,4,4,5
1,1,5,35,36,35,2,26,26,26,2,5,5,5,5,5,2,1,1,1
1,1,5,35,35,35,2,38,38,38,2,0,0,0,0,5,1,1,1,1
1,1,2,2,2,2,5,5,38,38,2,0,0,0,0,4,1,1,1,1
1,1,1,34,2,0,0,23,5,5,2,0,0,0,0,4,1,1,1,1
1,1,1,34,2,0,0,0,0,0,2,0,0,0,0,5,1,1,1,1
1,1,1,34,2,0,0,0,0,0,2,2,2,2,2,2,1,1,1,1
1,1,1,34,2,0,0,0,0,0,2,1,1,1,1,1,1,1,1,1
1,1,1,34,2,2,2,2,2,2,5,1,1,1,1,1,1,1,1,1
1,1,1,34,3,21,0,0,2,1,1,1,1,1,1,1,1,1,1,1
1,1,6,6,3,21,0,0,2,1,1,1,1,1,1,1,1,1,1,1
1,1,3,35,35,21,0,0,2,1,1,1,1,1,1,1,1,1,1,1
1,1,3,35,36,21,0,0,2,1,1,1,1,1,1,1,1,1,1,1
1,1,3,35,35,21,5,5,2,1,1,1,1,1,1,1,1,1,1,1
1,1,3,7,7,8,1,1,1,1,1,1,1,1,1,1,1,1,1,1
endlayer

layer
1,1,1,1,1,1,1,1,1,1,1,1,1,1,39,6,6,6,39,1
1,1,1,1,1,1,1,1,1,1,1,1,1,1,3,11,11,11,8,1
39,6,39,6,39,1,1,1,1,1,1,1,1,1,3,11,40,11,8,1
3,35,35,35,8,1,1,1,1,1,1,1,4,4,4,4,4,7,7,1
39,35,18,35,39,1,1,1,1,1,1,1,7,0,0,0,7,1,1,1
3,35,35,35,8,1,1,1,1,1,1,1,39,0,0,0,39,1,1,1
39,7,39,7,39,1,1,1,1,1,1,1,6,0,0,0,6,1,1,1
1,1,1,1,1,1,1,1,1,1,1,39,6,4,4,4,1,1,1,1
1,1,1,1,1,1,1,1,1,1,39,5,7,7,5,39,1,1,1,1
1,1,1,1,3,6,6,8,1,1,3,8,22,41,3,8,1,1,1,1
1,1,1,1,3,35,23,4,4,4,5,8,22,41,3,8,1,1,1,1
1,1,1,1,3,35,35,0,0,0,4,5,6,6,5,39,1,1,1,1
1,1,1,1,3,35,35,0,0,0,4,39,7,7,39,1,1,1,1,1
1,1,1,1,3,35,35,0,0,0,4,1,1,1,1,1,1,1,1,1
1,1,1,1,7,7,5,4,4,4,5,1,1,1,1,1,1,1,1,1
1,1,1,1,1,39,39,39,1,1,1,1,1,1,1,1,1,1,1,1
1,1,1,1,1,39,39,39,39,1,1,1,1,1,1,1,1,1,1,1
1,1,1,1,1,39,42,39,39,1,1,1,1,1,1,1,1,1,1,1
1,1,1,1,1,39,39,39,39,1,1,1,1,1,1,1,1,1,1,1
1,1,1,1,1,39,39,39,1,1,1,1,1,1,1,1,1,1,1,1
1,1,1,1,1,1,1,1,1,1,1,1,1,1,1,1,1,1,1,1
endlayer

layer
1,1,1,1,1,1,1,1,1,1,1,1,1,1,1,1,1,1,1,1
1,1,1,1,1,1,1,1,1,1,1,1,1,1,1,1,1,1,1,1
1,1,1,1,1,1,1,1,1,1,1,1,1,1,1,1,1,1,1,1
1,1,1,1,1,1,1,1,1,1,1,1,1,6,6,6,8,1,1,1
1,1,1,1,1,1,1,1,1,1,1,1,3,43,43,43,8,1,1,1
1,1,1,1,1,1,1,1,1,1,1,1,3,43,44,43,8,1,1,1
1,1,1,1,1,1,1,1,1,1,1,1,3,43,43,43,8,1,1,1
1,1,1,1,1,1,1,1,1,1,1,1,1,7,7,7,1,1,1,1
1,1,1,1,1,1,1,1,1,1,1,1,1,1,1,1,1,1,1,1
1,1,1,1,1,1,1,1,1,1,1,1,1,1,1,1,1,1,1,1
1,1,1,1,1,1,1,6,6,6,1,1,1,1,1,1,1,1,1,1
1,1,1,1,1,1,3,34,34,34,8,1,1,1,1,1,1,1,1,1
1,1,1,1,1,1,3,34,44,34,8,1,1,1,1,1,1,1,1,1
1,1,1,1,1,1,3,34,34,34,8,1,1,1,1,1,1,1,1,1
1,1,1,1,1,1,1,7,7,7,1,1,1,1,1,1,1,1,1,1
1,1,1,1,1,1,1,1,1,1,1,1,1,1,1,1,1,1,1,1
1,1,1,1,1,1,1,1,1,1,1,1,1,1,1,1,1,1,1,1
1,1,1,1,1,1,1,1,1,1,1,1,1,1,1,1,1,1,1,1
1,1,1,1,1,1,1,1,1,1,1,1,1,1,1,1,1,1,1,1
1,1,1,1,1,1,1,1,1,1,1,1,1,1,1,1,1,1,1,1
1,1,1,1,1,1,1,1,1,1,1,1,1,1,1,1,1,1,1,1
endlayer

