
# Created by Ruins mod version 16.7 Ingame Parser
# authoring Player: lafuller

weight=1
embed_into_distance=4
acceptable_target_blocks=
unacceptable_target_blocks=flowing_water,water,flowing_lava,lava,ice,bedrock,netherrack,nether_brick,nether_brick_fence,soul_sand,quartz_ore,gravel,end_stone,obsidian,iron_bars,cloud,flesh,ash_block,slime_grass,slime_congealed,slime_dirt
biomesToSpawnIn=plains,mutated_plains,forest,birch forest,taiga,woodland,woodlands,prarie,meadow,badlands,lavender fields,flower field,sunflower plains
dimensions=14,12,9
allowable_overhang=0
max_leveling=4
leveling_buffer=-1
preserve_water=0
preserve_lava=0

rule1=0,100,preserveBlock
rule2=0,100,stonebrick,cobblestone,cobblestone,dirt-1,gravel
rule3=0,100,minecraft:dirt-0
rule4=0,100,minecraft:fence-0
rule5=0,100,minecraft:oak_stairs-4
rule6=0,100,minecraft:oak_stairs-7
rule7=0,100,minecraft:oak_stairs-6
rule8=0,100,minecraft:oak_stairs-3
rule9=1,100,minecraft:hay_block-4,air,air
rule10=1,100,minecraft:hay_block-8,air,air
rule11=0,100,minecraft:planks-0
rule12=0,100,minecraft:oak_stairs-5
rule13=1,100,minecraft:hay_block-0,air,air
rule14=0,100,minecraft:ladder-2
rule15=0,100,minecraft:fence_gate-1
rule16=0,100,minecraft:spruce_fence-0
rule17=0,100,minecraft:oak_stairs-1
rule18=0,100,minecraft:spruce_stairs-4
rule19=0,100,minecraft:oak_stairs-2
rule20=0,100,minecraft:spruce_stairs-7
rule21=0,100,minecraft:dark_oak_stairs-2
rule22=0,100,minecraft:dark_oak_stairs-4
rule23=0,100,minecraft:spruce_stairs-6
rule24=0,100,minecraft:spruce_stairs-0
rule25=0,100,minecraft:dark_oak_stairs-6
rule26=0,100,minecraft:wooden_slab-5
rule27=0,100,minecraft:dark_oak_stairs-7
rule28=0,100,minecraft:planks-5
rule29=0,100,minecraft:spruce_stairs-5
rule30=0,100,minecraft:spruce_stairs-3
rule31=0,100,minecraft:wooden_slab-9
rule32=0,100,minecraft:dark_oak_stairs-5
rule33=0,100,minecraft:dark_oak_stairs-0
rule34=0,100,minecraft:dark_oak_stairs-3
rule35=0,100,minecraft:planks-1
rule36=0,100,minecraft:wooden_slab-1
rule37=0,100,minecraft:spruce_stairs-2
rule38=0,100,minecraft:double_wooden_slab-5
rule39=0,100,minecraft:dark_oak_stairs-1
rule40=0,100,minecraft:wooden_slab-0
rule41=0,100,minecraft:wooden_slab-8
rule42=0,100,minecraft:fence_gate-3

layer
1,1,2,2,2,2,2,1,1
1,2,2,2,2,2,2,2,1
2,2,2,3,3,3,2,2,2
2,2,3,3,3,3,3,2,2
2,2,3,3,3,3,3,2,2
2,2,3,3,3,3,3,2,2
2,2,3,3,3,3,3,2,2
2,2,3,3,3,3,3,2,2
2,2,2,3,3,3,3,2,2
1,2,2,2,2,2,2,2,1
1,1,2,2,2,2,2,2,1
1,1,1,2,2,2,2,1,1
endlayer

layer
1,1,1,2,2,2,1,1,1
1,1,2,2,2,2,2,1,1
1,2,2,3,3,3,2,2,1
2,2,3,3,3,3,3,2,2
2,2,3,3,3,3,3,2,2
2,2,3,3,3,3,3,2,2
2,2,3,3,3,3,3,2,2
2,2,3,3,3,3,3,2,2
1,2,2,3,3,3,3,2,1
1,1,2,2,2,2,2,2,1
1,1,1,2,2,2,2,1,1
1,1,1,1,2,2,1,1,1
endlayer

layer
1,1,1,1,2,2,1,1,1
1,1,1,2,2,2,2,1,1
1,2,2,3,3,3,2,2,1
1,2,3,3,3,3,3,2,1
2,2,3,3,3,3,3,2,1
2,2,3,3,3,3,3,2,2
1,2,3,3,3,3,3,2,2
1,2,3,3,3,3,3,2,1
1,2,2,3,3,3,3,2,1
1,1,1,2,2,2,2,2,1
1,1,1,1,2,2,1,1,1
1,1,1,1,1,1,1,1,1
endlayer

layer
1,1,1,1,1,1,1,1,1
1,1,1,2,2,2,2,1,1
1,1,2,3,3,3,2,1,1
1,2,3,3,3,3,3,2,1
1,2,3,3,3,3,3,2,1
1,2,3,3,3,3,3,2,1
1,2,3,3,3,3,3,2,1
1,2,3,3,3,3,3,2,1
1,1,2,3,3,3,3,2,1
1,1,1,2,3,3,2,1,1
1,1,1,1,1,1,1,1,1
1,1,1,1,1,1,1,1,1
endlayer

layer
1,1,1,1,1,1,1,1,1
1,1,4,7,6,6,5,4,1
1,4,11,9,10,9,8,4,1
1,12,10,13,0,10,10,12,1
1,6,14,0,0,0,9,6,1
0,12,9,0,0,0,13,12,0
0,12,10,0,0,0,9,7,0
1,6,5,9,0,0,10,5,1
1,4,7,10,0,0,9,7,1
1,4,4,12,15,15,11,4,1
1,1,0,4,0,0,4,1,1
1,1,1,1,1,1,1,1,1
endlayer

layer
1,1,16,0,0,0,0,16,1
1,0,11,12,6,6,11,4,1
1,6,12,13,0,13,17,7,1
0,6,13,0,0,0,13,7,0
0,5,14,0,0,0,10,12,0
0,5,0,0,0,0,0,6,0
0,12,13,0,0,0,13,12,0
0,7,12,0,0,0,0,12,0
0,4,7,0,0,0,13,12,0
1,4,12,11,0,0,12,4,1
1,0,0,4,0,0,4,0,1
1,1,1,0,0,0,1,1,1
endlayer

layer
1,0,16,5,0,0,5,16,1
1,16,18,12,19,8,6,18,1
0,20,12,0,0,0,0,12,0
0,20,0,0,0,0,9,11,16
0,11,14,0,0,0,0,6,0
0,7,0,0,0,0,0,5,0
0,12,0,0,0,0,0,7,0
0,7,10,0,0,0,0,7,0
0,6,7,0,0,0,0,11,16
0,4,11,11,0,0,7,12,0
1,0,0,6,0,0,12,0,1
1,1,0,0,0,0,0,1,1
endlayer

layer
1,26,25,24,23,20,22,21,1
0,27,25,17,23,20,5,25,0
16,28,27,19,0,0,17,6,23
0,29,12,0,0,0,0,12,18
16,30,14,0,0,0,0,5,16
20,12,31,31,0,0,0,25,23
16,11,0,0,0,0,0,7,16
0,12,0,0,0,0,0,29,16
0,7,19,0,0,0,0,32,23
0,16,12,7,0,0,11,6,29
0,0,0,16,0,0,4,0,0
1,0,0,0,0,0,0,0,1
endlayer

layer
0,0,16,33,22,22,22,26,0
0,26,28,17,0,13,5,22,0
26,34,13,0,0,0,0,22,21
27,25,9,0,0,0,0,25,25
32,35,14,0,0,0,0,25,21
32,17,0,0,36,36,36,25,16
25,19,36,36,36,36,36,27,37
32,25,31,31,31,31,31,27,25
16,35,7,31,31,31,31,27,21
0,29,17,11,7,6,12,35,25
0,0,12,16,0,0,4,4,0
0,0,0,0,0,0,0,0,0
endlayer

layer
0,0,0,38,33,22,26,0,0
0,0,27,33,0,0,22,26,0
0,39,10,0,0,0,32,38,0
0,22,0,0,0,0,32,25,39
27,28,0,0,0,0,0,32,25
34,39,0,0,0,0,0,32,25
27,27,0,0,0,0,0,27,21
25,27,10,0,0,0,13,27,16
0,27,10,9,0,0,10,32,25
0,32,32,7,40,40,12,39,32
0,32,30,12,41,41,6,29,0
0,0,0,0,0,0,0,0,0
endlayer

layer
0,0,0,0,0,0,0,0,0
0,0,26,38,33,21,0,0,0
0,0,34,27,32,27,26,0,0
0,26,27,0,0,0,22,33,0
0,27,0,0,0,0,32,25,0
0,34,0,0,0,0,32,25,26
26,27,0,0,0,0,27,32,32
0,27,0,0,0,0,0,21,25
0,27,9,0,0,0,9,32,26
0,27,27,0,0,0,27,25,21
0,34,25,8,42,42,19,32,0
0,0,0,0,0,0,0,0,0
endlayer

layer
0,0,0,0,0,0,0,0,0
0,0,0,0,0,0,0,0,0
0,0,0,26,21,26,0,0,0
0,0,26,38,34,33,26,0,0
0,0,33,32,32,25,21,26,0
0,0,33,32,32,32,25,21,0
0,26,33,0,0,0,25,33,0
0,26,27,0,0,0,25,32,0
0,34,27,0,0,0,32,32,0
0,16,28,0,0,0,32,21,0
0,0,39,29,7,6,39,16,0
0,0,34,0,0,0,39,0,0
endlayer

layer
0,0,0,0,0,0,0,0,0
0,0,0,0,0,0,0,0,0
0,0,0,0,0,0,0,0,0
0,0,0,0,26,0,0,0,0
0,0,0,33,33,26,0,0,0
0,0,0,26,21,38,0,0,0
0,0,34,39,32,25,26,0,0
0,0,39,39,0,0,25,26,0
0,0,34,39,0,0,25,21,0
0,0,34,39,22,32,32,26,0
0,0,26,27,22,32,21,0,0
0,0,0,26,39,39,0,0,0
endlayer

layer
0,0,0,0,0,0,0,0,0
0,0,0,0,0,0,0,0,0
0,0,0,0,0,0,0,0,0
0,0,0,0,0,0,0,0,0
0,0,0,0,0,0,0,0,0
0,0,0,26,26,0,0,0,0
0,0,0,34,26,26,0,0,0
0,0,0,26,33,21,0,0,0
0,0,0,34,32,21,26,0,0
0,0,0,34,39,21,0,0,0
0,0,0,0,34,21,0,0,0
0,0,0,0,26,26,0,0,0
endlayer

