
# Created by Ruins mod version 16.7 Ingame Parser
# authoring Player: lafuller

weight=1
embed_into_distance=4
acceptable_target_blocks=
unacceptable_target_blocks=dirt,stone,flowing_water,water,flowing_lava,lava,ice,bedrock,netherrack,nether_brick,nether_brick_fence,soul_sand,quartz_ore,gravel,end_stone,obsidian,iron_bars,cloud,flesh,ash_block,slime_grass,slime_congealed,slime_dirt
biomesToSpawnIn=savanna,mesa,outback,chaparral
dimensions=20,20,18
allowable_overhang=0
max_leveling=4
leveling_buffer=-1
preserve_water=0
preserve_lava=0

rule1=0,100,preserveBlock
rule2=0,100,minecraft:wool-8
rule3=0,100,minecraft:wool-0
rule4=0,100,minecraft:log2-12
rule5=0,100,minecraft:stained_hardened_clay-8
rule6=0,100,minecraft:fence-0
rule7=0,100,minecraft:log2-0

layer
1,1,1,1,1,1,1,1,3,2,3,3,2,1,1,1,1,1
1,1,1,1,3,2,3,2,1,1,1,1,1,3,2,1,1,1
1,1,2,3,1,1,1,1,1,1,1,1,1,1,1,3,1,1
1,3,1,1,1,1,1,1,1,1,1,1,1,1,1,1,3,1
1,4,4,1,1,1,1,1,1,1,1,1,1,1,1,1,1,2
1,3,1,1,1,1,1,1,1,1,1,1,1,1,1,1,1,4
1,3,1,1,1,1,1,1,1,1,1,1,1,1,1,1,1,2
2,1,1,1,1,1,1,1,1,1,1,1,1,1,1,1,1,3
3,1,1,1,1,1,1,1,1,1,1,1,1,1,1,1,1,3
3,1,1,1,1,1,1,1,1,1,1,1,1,1,1,1,1,2
2,1,1,1,1,1,1,1,1,1,1,1,1,1,1,1,1,1
3,1,1,1,1,1,1,1,1,1,1,1,1,1,1,1,1,1
2,1,1,1,1,1,1,1,1,1,1,1,1,1,1,1,1,1
1,3,1,1,1,1,1,1,1,1,1,1,1,1,1,1,1,1
1,2,1,1,1,1,1,1,1,1,1,1,1,1,1,1,1,1
1,1,3,1,1,1,1,1,1,1,1,1,1,1,1,1,1,1
1,1,2,1,1,1,1,1,1,1,1,1,1,1,1,1,1,1
1,1,1,3,1,1,1,1,1,1,1,1,1,1,1,1,1,1
1,1,1,1,2,3,4,1,1,1,3,1,1,1,1,1,1,1
1,1,1,1,1,4,4,2,3,2,1,1,1,1,1,1,1,1
endlayer

layer
1,1,1,1,1,1,1,1,1,1,1,1,1,1,1,1,1,1
1,1,1,1,1,1,1,2,3,2,3,2,3,1,1,1,1,1
1,1,1,1,2,3,3,1,1,1,1,1,1,3,2,1,1,1
1,1,2,3,1,1,1,1,1,1,1,1,1,1,3,3,1,1
1,4,4,1,1,1,1,1,1,1,1,1,1,1,1,1,2,1
1,2,4,1,1,1,1,1,1,1,1,1,1,1,1,1,1,4
1,3,1,1,1,1,1,1,1,1,1,1,1,1,1,1,4,4
1,3,1,1,1,1,1,1,1,1,1,1,1,1,1,1,4,2
2,1,1,1,1,1,1,1,1,1,1,1,1,1,1,1,1,3
3,1,1,1,1,1,1,1,1,1,1,1,1,1,1,1,2,2
2,1,1,1,1,1,1,1,1,1,1,1,1,1,1,1,1,1
1,3,1,1,1,1,1,1,1,1,1,1,1,1,1,1,1,1
1,3,1,1,1,1,1,1,1,1,1,1,1,1,1,1,1,1
1,3,1,1,1,1,1,1,1,1,1,1,1,1,1,1,1,1
1,1,2,1,1,1,1,1,1,1,1,1,1,1,1,1,1,1
1,1,3,1,1,1,1,1,1,1,1,1,1,1,1,1,1,1
1,1,1,2,1,1,1,1,1,1,1,1,1,1,1,1,1,1
1,1,1,1,3,2,4,1,1,1,1,1,1,1,1,1,1,1
1,1,1,1,1,1,4,3,1,3,2,1,1,1,1,1,1,1
1,1,1,1,1,1,4,1,3,1,1,1,1,1,1,1,1,1
endlayer

layer
1,1,1,1,1,1,1,1,1,1,1,1,1,1,1,1,1,1
1,1,1,1,1,1,1,1,1,3,3,2,1,1,1,1,1,1
1,1,1,1,1,1,2,3,2,1,1,1,2,3,1,1,1,1
1,1,1,1,2,3,1,1,1,1,1,1,1,3,3,1,1,1
1,1,1,2,1,1,1,1,1,1,1,1,1,1,1,2,1,1
1,1,4,1,1,1,1,1,1,1,1,1,1,1,1,1,3,1
1,1,2,1,1,1,1,1,1,1,1,1,1,1,1,1,4,1
1,3,1,1,1,1,1,1,1,1,1,1,1,1,1,4,4,1
1,3,1,1,1,1,1,1,1,1,1,1,1,1,1,1,3,1
3,3,1,1,1,1,1,1,1,1,1,1,1,1,1,1,3,1
1,3,1,1,1,1,1,1,1,5,1,1,1,1,1,1,3,1
1,3,1,1,1,1,1,1,1,1,1,1,1,1,1,1,1,1
1,2,1,1,1,1,1,1,1,1,1,1,1,1,1,1,1,1
1,1,3,1,1,1,1,1,1,1,1,1,1,1,1,1,1,1
1,1,1,2,1,1,1,1,1,1,1,1,1,1,1,1,1,1
1,1,1,3,1,1,1,1,1,1,1,1,1,1,1,1,1,1
1,1,1,1,3,1,1,1,1,1,1,1,1,1,1,1,1,1
1,1,1,1,1,3,4,4,1,1,3,1,1,1,1,1,1,1
1,1,1,1,1,1,4,3,2,3,1,1,1,1,1,1,1,1
1,1,1,1,1,1,1,1,1,1,1,1,1,1,1,1,1,1
endlayer

layer
1,1,1,1,1,1,1,1,1,1,1,1,1,1,1,1,1,1
1,1,1,1,1,1,1,1,1,1,1,1,1,1,1,1,1,1
1,1,1,1,1,1,1,1,2,3,2,3,1,1,1,1,1,1
1,1,1,1,1,2,3,3,0,0,0,0,3,2,1,1,1,1
1,1,1,1,3,0,0,0,0,0,0,0,0,0,3,1,1,1
1,1,4,4,0,0,0,0,0,0,0,0,0,0,0,3,1,1
1,1,2,0,0,0,0,0,0,0,0,0,0,0,0,3,4,1
1,1,3,0,0,0,0,0,0,0,0,0,0,0,0,4,1,1
1,1,3,0,0,0,0,0,0,0,0,0,0,0,0,3,1,1
1,2,0,0,0,0,0,0,0,0,0,0,0,0,0,3,2,1
1,3,0,0,0,0,0,0,0,6,0,0,0,0,0,3,1,1
1,2,0,0,0,0,0,0,0,0,0,0,0,0,0,0,1,1
1,1,3,0,0,0,0,0,0,0,0,0,0,0,0,0,1,1
1,1,1,3,0,0,0,0,0,0,0,0,0,0,0,0,1,1
1,1,1,3,1,0,0,0,0,0,0,0,0,0,0,1,1,1
1,1,1,1,3,0,0,0,0,0,0,0,0,0,1,1,1,1
1,1,1,1,2,3,1,4,0,0,0,0,0,1,1,1,1,1
1,1,1,1,1,1,4,4,3,2,3,1,1,1,1,1,1,1
1,1,1,1,1,1,1,1,1,1,1,1,1,1,1,1,1,1
1,1,1,1,1,1,1,1,1,1,1,1,1,1,1,1,1,1
endlayer

layer
1,1,1,1,1,1,1,1,1,1,1,1,1,1,1,1,1,1
1,1,1,1,1,1,1,1,1,1,1,1,1,1,1,1,1,1
1,1,1,1,1,1,0,0,0,3,2,0,1,1,1,1,1,1
1,1,1,1,0,0,3,2,3,0,0,3,0,0,0,1,1,1
1,1,1,0,0,3,0,0,0,0,0,0,3,3,0,0,1,1
1,1,0,4,2,0,0,0,0,0,0,0,0,0,2,0,0,1
1,0,0,4,0,0,0,0,0,0,0,0,0,0,1,4,0,1
1,0,3,0,0,0,0,0,0,0,0,0,0,0,4,4,0,1
1,0,2,0,0,0,0,0,0,0,0,0,0,0,0,3,0,1
1,0,3,0,0,0,0,0,0,0,0,0,0,0,0,3,0,1
1,0,3,0,0,0,0,0,0,6,0,0,0,0,0,2,0,1
1,0,2,0,0,0,0,0,0,0,0,0,0,0,0,0,0,1
1,0,0,3,0,0,0,0,0,0,0,0,0,0,0,0,1,1
1,1,0,2,0,0,0,0,0,0,0,0,0,0,0,0,1,1
1,1,0,0,3,0,0,0,0,0,0,0,0,0,0,1,1,1
1,1,1,0,3,1,0,0,0,0,0,0,0,0,1,1,1,1
1,1,1,1,0,2,3,4,3,0,2,0,0,1,1,1,1,1
1,1,1,1,1,0,0,4,2,3,0,0,1,1,1,1,1,1
1,1,1,1,1,1,0,0,0,0,0,1,1,1,1,1,1,1
1,1,1,1,1,1,1,1,1,1,1,1,1,1,1,1,1,1
endlayer

layer
1,1,1,1,1,1,1,1,1,1,1,1,1,1,1,1,1,1
1,1,1,1,1,1,1,1,1,1,1,1,1,1,1,1,1,1
1,1,1,1,1,1,0,0,0,0,0,0,1,1,1,1,1,1
1,1,1,1,0,0,0,0,0,3,3,0,0,0,0,1,1,1
1,1,1,0,0,0,2,3,3,0,0,2,0,0,0,0,1,1
1,1,0,0,0,3,1,0,0,0,0,0,3,2,0,0,0,1
1,0,0,4,4,0,0,0,0,0,0,0,0,1,2,0,0,1
1,0,0,2,4,0,0,0,0,0,0,0,0,0,4,0,0,1
1,0,0,3,0,0,0,0,0,0,0,0,0,4,2,0,0,1
1,0,0,3,0,0,0,0,0,0,0,0,0,0,0,3,0,1
1,0,3,0,0,0,0,0,0,6,0,0,0,0,0,3,0,1
1,0,0,3,0,0,0,0,0,0,0,0,0,0,2,0,0,1
1,0,0,3,0,0,0,0,0,0,0,0,0,0,0,0,1,1
1,1,0,0,2,0,0,0,0,0,0,0,0,0,0,0,1,1
1,1,0,0,0,3,0,0,0,0,0,0,0,0,0,1,1,1
1,1,1,0,0,2,3,4,4,0,2,0,0,0,1,1,1,1
1,1,1,1,0,0,0,4,2,3,3,0,0,1,1,1,1,1
1,1,1,1,1,0,0,0,0,0,0,0,1,1,1,1,1,1
1,1,1,1,1,1,0,0,0,0,0,1,1,1,1,1,1,1
1,1,1,1,1,1,1,1,1,1,1,1,1,1,1,1,1,1
endlayer

layer
1,1,1,1,1,1,1,1,1,1,1,1,1,1,1,1,1,1
1,1,1,1,1,1,1,1,1,1,1,1,1,1,1,1,1,1
1,1,1,1,1,1,0,0,0,0,0,0,1,1,1,1,1,1
1,1,1,1,0,0,0,0,0,0,0,0,0,0,0,1,1,1
1,1,1,0,0,0,0,0,2,3,3,0,0,0,0,0,1,1
1,1,0,0,0,0,3,3,0,0,0,2,3,0,0,0,0,1
1,0,0,0,4,3,1,0,0,0,0,0,1,3,0,0,0,1
1,0,0,0,4,4,0,0,0,0,0,0,0,1,4,0,0,1
1,0,0,0,3,0,0,0,0,0,0,0,0,4,3,0,0,1
1,0,0,2,0,0,0,0,0,0,0,0,0,0,2,0,0,1
1,0,0,3,0,0,0,0,0,6,0,0,0,0,3,0,0,1
1,0,0,2,0,0,0,0,0,0,0,0,0,0,3,0,0,1
1,0,0,0,3,0,0,0,0,0,0,0,0,0,0,0,1,1
1,1,0,0,0,2,0,0,0,0,0,0,0,0,0,0,1,1
1,1,0,0,0,3,1,0,0,0,0,0,0,0,0,1,1,1
1,1,1,0,0,0,3,4,4,2,3,3,0,0,1,1,1,1
1,1,1,1,0,0,0,0,0,0,0,0,0,1,1,1,1,1
1,1,1,1,1,0,0,0,0,0,0,0,1,1,1,1,1,1
1,1,1,1,1,1,0,0,0,0,0,1,1,1,1,1,1,1
1,1,1,1,1,1,1,1,1,1,1,1,1,1,1,1,1,1
endlayer

layer
1,1,1,1,1,1,1,1,1,1,1,1,1,1,1,1,1,1
1,1,1,1,1,1,1,1,1,1,1,1,1,1,1,1,1,1
1,1,1,1,1,1,0,0,0,0,0,0,1,1,1,1,1,1
1,1,1,1,0,0,0,0,0,0,0,0,0,0,0,1,1,1
1,1,1,0,0,0,0,0,0,3,0,0,0,0,0,0,1,1
1,1,0,0,0,0,0,3,2,0,3,3,0,0,0,0,0,1
1,0,0,0,0,2,2,0,0,0,0,0,2,0,0,0,0,1
1,0,0,0,4,4,0,0,0,0,0,0,1,4,0,0,0,1
1,0,0,0,2,1,0,0,0,0,0,0,4,4,0,0,0,1
1,0,0,0,3,0,0,0,0,0,0,0,0,3,2,0,0,1
1,0,0,0,3,0,0,0,0,6,0,0,0,3,0,0,0,1
1,0,0,0,2,0,0,0,0,0,0,0,0,2,0,0,0,1
1,0,0,0,0,3,0,0,0,0,0,0,0,0,0,0,1,1
1,1,0,0,0,3,0,0,0,0,0,0,0,0,0,0,1,1
1,1,0,0,0,0,2,2,4,3,3,2,0,0,0,1,1,1
1,1,1,0,0,0,0,0,4,3,0,0,0,0,1,1,1,1
1,1,1,1,0,0,0,0,0,0,0,0,0,1,1,1,1,1
1,1,1,1,1,0,0,0,0,0,0,0,1,1,1,1,1,1
1,1,1,1,1,1,1,0,0,0,1,1,1,1,1,1,1,1
1,1,1,1,1,1,1,1,1,1,1,1,1,1,1,1,1,1
endlayer

layer
1,1,1,1,1,1,1,1,1,1,1,1,1,1,1,1,1,1
1,1,1,1,1,1,1,1,1,1,1,1,1,1,1,1,1,1
1,1,1,1,1,1,0,0,0,0,0,0,1,1,1,1,1,1
1,1,1,1,1,0,0,0,0,0,0,0,0,0,1,1,1,1
1,1,1,0,0,0,0,0,0,0,0,0,0,0,0,1,1,1
1,1,0,0,0,0,0,0,3,3,2,0,0,0,0,0,1,1
1,1,0,0,0,0,3,2,0,0,1,3,2,0,0,0,0,1
1,0,0,0,0,4,1,0,0,0,0,0,3,0,0,0,0,1
1,0,0,0,0,4,4,0,0,0,0,0,4,4,0,0,0,1
1,0,0,0,0,3,0,0,0,0,0,0,4,3,0,0,0,1
1,0,0,0,3,1,0,0,0,6,0,0,3,3,0,0,0,1
1,0,0,0,0,3,0,0,0,0,0,0,2,0,0,0,1,1
1,1,0,0,0,3,0,0,0,0,0,0,0,0,0,0,1,1
1,1,0,0,0,0,2,3,4,4,3,0,0,0,0,0,1,1
1,1,1,0,0,0,0,0,4,3,0,2,0,0,0,1,1,1
1,1,1,0,0,0,0,0,0,0,0,0,0,0,1,1,1,1
1,1,1,1,0,0,0,0,0,0,0,0,0,1,1,1,1,1
1,1,1,1,1,0,0,0,0,0,0,1,1,1,1,1,1,1
1,1,1,1,1,1,1,1,1,1,1,1,1,1,1,1,1,1
1,1,1,1,1,1,1,1,1,1,1,1,1,1,1,1,1,1
endlayer

layer
1,1,1,1,1,1,1,1,1,1,1,1,1,1,1,1,1,1
1,1,1,1,1,1,1,1,1,1,1,1,1,1,1,1,1,1
1,1,1,1,1,1,1,1,1,1,1,1,1,1,1,1,1,1
1,1,1,1,1,1,0,0,0,0,0,0,1,1,1,1,1,1
1,1,1,1,0,0,0,0,0,0,0,0,0,0,1,1,1,1
1,1,1,0,0,0,0,0,0,0,0,0,0,0,0,1,1,1
1,1,0,0,0,0,0,2,3,3,2,3,0,0,0,0,1,1
1,1,0,0,0,0,3,0,0,0,0,1,3,0,0,0,1,1
1,1,0,0,0,4,4,0,0,0,0,0,4,0,0,0,1,1
1,1,0,0,0,2,4,0,0,0,0,0,4,2,0,0,1,1
1,1,0,0,0,3,1,0,0,6,0,0,3,0,0,0,1,1
1,1,0,0,0,2,1,0,0,0,0,0,3,0,0,0,1,1
1,1,1,0,0,0,3,3,0,0,0,0,0,0,0,0,1,1
1,1,1,0,0,0,0,0,4,4,2,3,0,0,0,1,1,1
1,1,1,1,0,0,0,0,0,0,0,0,0,0,1,1,1,1
1,1,1,1,1,0,0,0,0,0,0,0,0,1,1,1,1,1
1,1,1,1,1,1,0,0,0,0,0,1,1,1,1,1,1,1
1,1,1,1,1,1,1,0,0,0,1,1,1,1,1,1,1,1
1,1,1,1,1,1,1,1,1,1,1,1,1,1,1,1,1,1
1,1,1,1,1,1,1,1,1,1,1,1,1,1,1,1,1,1
endlayer

layer
1,1,1,1,1,1,1,1,1,1,1,1,1,1,1,1,1,1
1,1,1,1,1,1,1,1,1,1,1,1,1,1,1,1,1,1
1,1,1,1,1,1,1,1,1,1,1,1,1,1,1,1,1,1
1,1,1,1,1,1,1,1,0,0,1,1,1,1,1,1,1,1
1,1,1,1,1,1,1,0,0,0,0,0,1,1,1,1,1,1
1,1,1,1,0,0,0,0,0,0,0,0,0,0,1,1,1,1
1,1,1,0,0,0,0,0,0,3,3,0,0,0,1,1,1,1
1,1,1,0,0,0,0,3,3,0,0,2,0,0,0,1,1,1
1,1,1,0,0,0,4,0,0,0,0,4,4,0,0,1,1,1
1,1,0,0,0,0,4,4,0,0,0,0,4,0,0,1,1,1
1,1,1,0,0,0,2,0,0,6,0,0,2,0,0,1,1,1
1,1,1,0,0,0,3,1,0,0,0,3,0,0,0,1,1,1
1,1,1,1,0,0,0,2,3,4,0,3,0,0,0,1,1,1
1,1,1,1,0,0,0,0,0,4,2,0,0,0,1,1,1,1
1,1,1,1,1,0,0,0,0,0,0,0,0,1,1,1,1,1
1,1,1,1,1,1,0,0,0,0,0,0,1,1,1,1,1,1
1,1,1,1,1,1,1,0,0,1,1,1,1,1,1,1,1,1
1,1,1,1,1,1,1,1,1,1,1,1,1,1,1,1,1,1
1,1,1,1,1,1,1,1,1,1,1,1,1,1,1,1,1,1
1,1,1,1,1,1,1,1,1,1,1,1,1,1,1,1,1,1
endlayer

layer
1,1,1,1,1,1,1,1,1,1,1,1,1,1,1,1,1,1
1,1,1,1,1,1,1,1,1,1,1,1,1,1,1,1,1,1
1,1,1,1,1,1,1,1,1,1,1,1,1,1,1,1,1,1
1,1,1,1,1,1,1,1,1,1,1,1,1,1,1,1,1,1
1,1,1,1,1,1,1,1,0,0,0,1,1,1,1,1,1,1
1,1,1,1,1,0,0,0,0,0,0,0,0,1,1,1,1,1
1,1,1,1,0,0,0,0,0,0,0,0,0,0,1,1,1,1
1,1,1,1,0,0,0,0,0,3,2,0,0,0,1,1,1,1
1,1,1,0,0,0,0,2,3,0,1,4,0,0,1,1,1,1
1,1,1,0,0,0,4,4,0,0,0,4,0,0,0,1,1,1
1,1,1,1,0,0,2,4,0,6,0,3,0,0,1,1,1,1
1,1,1,1,0,0,0,2,0,4,0,3,0,0,1,1,1,1
1,1,1,1,0,0,0,0,2,4,3,0,0,0,1,1,1,1
1,1,1,1,1,0,0,0,0,0,0,0,0,1,1,1,1,1
1,1,1,1,1,1,0,0,0,0,0,0,1,1,1,1,1,1
1,1,1,1,1,1,1,1,0,0,0,1,1,1,1,1,1,1
1,1,1,1,1,1,1,1,1,1,1,1,1,1,1,1,1,1
1,1,1,1,1,1,1,1,1,1,1,1,1,1,1,1,1,1
1,1,1,1,1,1,1,1,1,1,1,1,1,1,1,1,1,1
1,1,1,1,1,1,1,1,1,1,1,1,1,1,1,1,1,1
endlayer

layer
1,1,1,1,1,1,1,1,1,1,1,1,1,1,1,1,1,1
1,1,1,1,1,1,1,1,1,1,1,1,1,1,1,1,1,1
1,1,1,1,1,1,1,1,1,1,1,1,1,1,1,1,1,1
1,1,1,1,1,1,1,1,1,1,1,1,1,1,1,1,1,1
1,1,1,1,1,1,1,1,1,0,1,1,1,1,1,1,1,1
1,1,1,1,1,1,1,0,0,0,0,0,1,1,1,1,1,1
1,1,1,1,1,1,0,0,0,0,0,0,0,1,1,1,1,1
1,1,1,1,1,0,0,0,0,0,0,0,0,1,1,1,1,1
1,1,1,1,0,0,0,0,2,3,4,0,0,0,1,1,1,1
1,1,1,1,0,0,0,4,0,0,4,4,0,0,1,1,1,1
1,1,1,1,0,0,0,4,4,6,0,3,0,0,1,1,1,1
1,1,1,1,1,0,0,2,4,4,0,2,0,1,1,1,1,1
1,1,1,1,1,0,0,0,0,4,0,0,0,1,1,1,1,1
1,1,1,1,1,1,0,0,0,0,0,0,1,1,1,1,1,1
1,1,1,1,1,1,1,0,0,0,0,1,1,1,1,1,1,1
1,1,1,1,1,1,1,1,1,1,1,1,1,1,1,1,1,1
1,1,1,1,1,1,1,1,1,1,1,1,1,1,1,1,1,1
1,1,1,1,1,1,1,1,1,1,1,1,1,1,1,1,1,1
1,1,1,1,1,1,1,1,1,1,1,1,1,1,1,1,1,1
1,1,1,1,1,1,1,1,1,1,1,1,1,1,1,1,1,1
endlayer

layer
1,1,1,1,1,1,1,1,1,1,1,1,1,1,1,1,1,1
1,1,1,1,1,1,1,1,1,1,1,1,1,1,1,1,1,1
1,1,1,1,1,1,1,1,1,1,1,1,1,1,1,1,1,1
1,1,1,1,1,1,1,1,1,1,1,1,1,1,1,1,1,1
1,1,1,1,1,1,1,1,1,1,1,1,1,1,1,1,1,1
1,1,1,1,1,1,1,1,0,0,0,1,1,1,1,1,1,1
1,1,1,1,1,1,1,0,0,0,0,0,1,1,1,1,1,1
1,1,1,1,1,1,0,0,0,0,0,0,0,1,1,1,1,1
1,1,1,1,1,0,0,0,0,0,0,0,0,1,1,1,1,1
1,1,1,1,1,0,0,0,2,4,4,0,0,0,1,1,1,1
1,1,1,1,1,0,0,0,4,6,0,2,0,1,1,1,1,1
1,1,1,1,1,0,0,0,4,4,4,0,0,1,1,1,1,1
1,1,1,1,1,1,0,0,0,0,0,0,0,1,1,1,1,1
1,1,1,1,1,1,0,0,0,0,0,0,1,1,1,1,1,1
1,1,1,1,1,1,1,1,0,0,0,1,1,1,1,1,1,1
1,1,1,1,1,1,1,1,1,1,1,1,1,1,1,1,1,1
1,1,1,1,1,1,1,1,1,1,1,1,1,1,1,1,1,1
1,1,1,1,1,1,1,1,1,1,1,1,1,1,1,1,1,1
1,1,1,1,1,1,1,1,1,1,1,1,1,1,1,1,1,1
1,1,1,1,1,1,1,1,1,1,1,1,1,1,1,1,1,1
endlayer

layer
1,1,1,1,1,1,1,1,1,1,1,1,1,1,1,1,1,1
1,1,1,1,1,1,1,1,1,1,1,1,1,1,1,1,1,1
1,1,1,1,1,1,1,1,1,1,1,1,1,1,1,1,1,1
1,1,1,1,1,1,1,1,1,1,1,1,1,1,1,1,1,1
1,1,1,1,1,1,1,1,1,1,1,1,1,1,1,1,1,1
1,1,1,1,1,1,1,1,1,1,1,1,1,1,1,1,1,1
1,1,1,1,1,1,1,1,0,0,0,0,1,1,1,1,1,1
1,1,1,1,1,1,1,0,0,0,0,0,1,1,1,1,1,1
1,1,1,1,1,1,0,0,0,0,0,0,0,1,1,1,1,1
1,1,1,1,1,1,0,0,0,4,4,0,0,1,1,1,1,1
1,1,1,1,1,1,0,0,0,4,4,0,0,1,1,1,1,1
1,1,1,1,1,1,0,0,4,0,4,0,0,1,1,1,1,1
1,1,1,1,1,1,1,0,0,0,0,0,1,1,1,1,1,1
1,1,1,1,1,1,1,1,0,0,0,0,1,1,1,1,1,1
1,1,1,1,1,1,1,1,1,0,0,1,1,1,1,1,1,1
1,1,1,1,1,1,1,1,1,1,1,1,1,1,1,1,1,1
1,1,1,1,1,1,1,1,1,1,1,1,1,1,1,1,1,1
1,1,1,1,1,1,1,1,1,1,1,1,1,1,1,1,1,1
1,1,1,1,1,1,1,1,1,1,1,1,1,1,1,1,1,1
1,1,1,1,1,1,1,1,1,1,1,1,1,1,1,1,1,1
endlayer

layer
1,1,1,1,1,1,1,1,1,1,1,1,1,1,1,1,1,1
1,1,1,1,1,1,1,1,1,1,1,1,1,1,1,1,1,1
1,1,1,1,1,1,1,1,1,1,1,1,1,1,1,1,1,1
1,1,1,1,1,1,1,1,1,1,1,1,1,1,1,1,1,1
1,1,1,1,1,1,1,1,1,1,1,1,1,1,1,1,1,1
1,1,1,1,1,1,1,1,1,1,1,1,1,1,1,1,1,1
1,1,1,1,1,1,1,1,1,1,0,1,1,1,1,1,1,1
1,1,1,1,1,1,1,1,1,0,0,0,1,1,1,1,1,1
1,1,1,1,1,1,1,0,0,0,0,0,0,1,1,1,1,1
1,1,1,1,1,1,0,0,4,4,0,0,0,1,1,1,1,1
1,1,1,1,1,1,0,0,0,0,4,0,0,1,1,1,1,1
1,1,1,1,1,1,0,0,4,4,0,0,0,1,1,1,1,1
1,1,1,1,1,1,1,0,0,4,0,0,1,1,1,1,1,1
1,1,1,1,1,1,1,1,0,0,0,0,1,1,1,1,1,1
1,1,1,1,1,1,1,1,1,0,0,1,1,1,1,1,1,1
1,1,1,1,1,1,1,1,1,1,1,1,1,1,1,1,1,1
1,1,1,1,1,1,1,1,1,1,1,1,1,1,1,1,1,1
1,1,1,1,1,1,1,1,1,1,1,1,1,1,1,1,1,1
1,1,1,1,1,1,1,1,1,1,1,1,1,1,1,1,1,1
1,1,1,1,1,1,1,1,1,1,1,1,1,1,1,1,1,1
endlayer

layer
1,1,1,1,1,1,1,1,1,1,1,1,1,1,1,1,1,1
1,1,1,1,1,1,1,1,1,1,1,1,1,1,1,1,1,1
1,1,1,1,1,1,1,1,1,1,1,1,1,1,1,1,1,1
1,1,1,1,1,1,1,1,1,1,1,1,1,1,1,1,1,1
1,1,1,1,1,1,1,1,1,1,1,1,1,1,1,1,1,1
1,1,1,1,1,1,1,1,1,1,1,1,1,1,1,1,1,1
1,1,1,1,1,1,1,1,1,1,1,1,1,1,1,1,1,1
1,1,1,1,1,1,1,1,1,0,0,0,1,1,1,1,1,1
1,1,1,1,1,1,1,0,0,0,0,0,0,1,1,1,1,1
1,1,1,1,1,1,0,0,4,0,4,0,0,1,1,1,1,1
1,1,1,1,1,1,0,0,0,0,4,0,0,1,1,1,1,1
1,1,1,1,1,1,0,0,0,0,0,0,0,1,1,1,1,1
1,1,1,1,1,1,1,0,0,4,4,0,1,1,1,1,1,1
1,1,1,1,1,1,1,0,0,0,0,0,1,1,1,1,1,1
1,1,1,1,1,1,1,1,0,0,0,1,1,1,1,1,1,1
1,1,1,1,1,1,1,1,1,1,1,1,1,1,1,1,1,1
1,1,1,1,1,1,1,1,1,1,1,1,1,1,1,1,1,1
1,1,1,1,1,1,1,1,1,1,1,1,1,1,1,1,1,1
1,1,1,1,1,1,1,1,1,1,1,1,1,1,1,1,1,1
1,1,1,1,1,1,1,1,1,1,1,1,1,1,1,1,1,1
endlayer

layer
1,1,1,1,1,1,1,1,1,1,1,1,1,1,1,1,1,1
1,1,1,1,1,1,1,1,1,1,1,1,1,1,1,1,1,1
1,1,1,1,1,1,1,1,1,1,1,1,1,1,1,1,1,1
1,1,1,1,1,1,1,1,1,1,1,1,1,1,1,1,1,1
1,1,1,1,1,1,1,1,1,1,1,1,1,1,1,1,1,1
1,1,1,1,1,1,1,1,1,1,1,1,1,1,1,1,1,1
1,1,1,1,1,1,1,1,1,1,1,1,1,1,1,1,1,1
1,1,1,1,1,1,1,1,1,0,0,0,1,1,1,1,1,1
1,1,1,1,1,1,1,0,0,0,4,0,0,1,1,1,1,1
1,1,1,1,1,1,0,0,4,0,4,0,0,0,1,1,1,1
1,1,1,1,1,1,0,4,4,0,0,0,0,1,1,1,1,1
1,1,1,1,1,1,0,0,0,0,0,0,0,1,1,1,1,1
1,1,1,1,1,1,1,0,0,4,4,0,1,1,1,1,1,1
1,1,1,1,1,1,1,0,0,0,0,0,1,1,1,1,1,1
1,1,1,1,1,1,1,1,0,0,0,0,1,1,1,1,1,1
1,1,1,1,1,1,1,1,1,0,1,1,1,1,1,1,1,1
1,1,1,1,1,1,1,1,1,1,1,1,1,1,1,1,1,1
1,1,1,1,1,1,1,1,1,1,1,1,1,1,1,1,1,1
1,1,1,1,1,1,1,1,1,1,1,1,1,1,1,1,1,1
1,1,1,1,1,1,1,1,1,1,1,1,1,1,1,1,1,1
endlayer

layer
1,1,1,1,1,1,1,1,1,1,1,1,1,1,1,1,1,1
1,1,1,1,1,1,1,1,1,1,1,1,1,1,1,1,1,1
1,1,1,1,1,1,1,1,1,1,1,1,1,1,1,1,1,1
1,1,1,1,1,1,1,1,1,1,1,1,1,1,1,1,1,1
1,1,1,1,1,1,1,1,1,1,1,1,1,1,1,1,1,1
1,1,1,1,1,1,1,1,1,1,1,1,1,1,1,1,1,1
1,1,1,1,1,1,1,1,1,1,0,1,1,1,1,1,1,1
1,1,1,1,1,1,1,1,1,0,0,0,0,1,1,1,1,1
1,1,1,1,1,1,1,0,0,0,4,4,0,1,1,1,1,1
1,1,1,1,1,1,0,0,0,0,0,0,0,0,1,1,1,1
1,1,1,1,1,0,0,4,0,0,0,0,0,0,1,1,1,1
1,1,1,1,1,1,0,0,0,0,0,0,0,1,1,1,1,1
1,1,1,1,1,1,0,0,0,0,4,0,0,1,1,1,1,1
1,1,1,1,1,1,1,0,0,0,4,0,1,1,1,1,1,1
1,1,1,1,1,1,1,1,0,0,0,0,1,1,1,1,1,1
1,1,1,1,1,1,1,1,1,0,0,1,1,1,1,1,1,1
1,1,1,1,1,1,1,1,1,1,1,1,1,1,1,1,1,1
1,1,1,1,1,1,1,1,1,1,1,1,1,1,1,1,1,1
1,1,1,1,1,1,1,1,1,1,1,1,1,1,1,1,1,1
1,1,1,1,1,1,1,1,1,1,1,1,1,1,1,1,1,1
endlayer

layer
1,1,1,1,1,1,1,1,1,1,1,1,1,1,1,1,1,1
1,1,1,1,1,1,1,1,1,1,1,1,1,1,1,1,1,1
1,1,1,1,1,1,1,1,1,1,1,1,1,1,1,1,1,1
1,1,1,1,1,1,1,1,1,1,1,1,1,1,1,1,1,1
1,1,1,1,1,1,1,1,1,1,1,1,1,1,1,1,1,1
1,1,1,1,1,1,1,1,1,1,1,1,1,1,1,1,1,1
1,1,1,1,1,1,1,1,1,0,0,0,1,1,1,1,1,1
1,1,1,1,1,1,1,1,0,0,0,0,0,1,1,1,1,1
1,1,1,1,1,1,0,0,0,0,0,7,0,0,1,1,1,1
1,1,1,1,1,0,0,0,0,0,0,0,0,0,1,1,1,1
1,1,1,1,1,0,0,7,0,0,0,0,0,0,1,1,1,1
1,1,1,1,1,0,0,0,0,0,0,0,0,0,1,1,1,1
1,1,1,1,1,1,0,0,0,0,0,0,0,1,1,1,1,1
1,1,1,1,1,1,0,0,0,0,7,0,0,1,1,1,1,1
1,1,1,1,1,1,1,0,0,0,0,0,1,1,1,1,1,1
1,1,1,1,1,1,1,1,0,0,0,1,1,1,1,1,1,1
1,1,1,1,1,1,1,1,1,1,1,1,1,1,1,1,1,1
1,1,1,1,1,1,1,1,1,1,1,1,1,1,1,1,1,1
1,1,1,1,1,1,1,1,1,1,1,1,1,1,1,1,1,1
1,1,1,1,1,1,1,1,1,1,1,1,1,1,1,1,1,1
endlayer

