# Gilly's Readymade underground survival base access port

# template generated with Ruins mod version 16.5 Ingame Parser
# Structure created and developed by Gilly

weight=1
embed_into_distance=14
acceptable_target_blocks=
unacceptable_target_blocks=flowing_water,water,flowing_lava,lava,ice,bedrock,netherrack,nether_brick,nether_brick_fence,soul_sand,quartz_ore,end_stone,obsidian,iron_bars,cloud,flesh,ash_block,slime_grass,slime_congealed,slime_dirt
dimensions=25,7,9
allowable_overhang=0
max_leveling=3
leveling_buffer=-1
preserve_water=0
preserve_lava=0

rule1=0,100,preserveBlock
rule2=0,100,minecraft:stained_hardened_clay-9
rule3=0,100,minecraft:stonebrick-0
rule4=0,100,minecraft:ladder-3
rule5=0,100,minecraft:ladder-2
rule6=0,100,minecraft:stone_brick_stairs-7
rule7=0,100,minecraft:iron_bars-0
rule8=0,100,minecraft:stone_brick_stairs-6
rule9=0,100,minecraft:stone_brick_stairs-4
rule10=0,100,minecraft:stone_brick_stairs-1
rule11=0,0,minecraft:sea_lantern-0
rule12=0,100,minecraft:cauldron-0
rule13=0,100,minecraft:stone_brick_stairs-3
rule14=0,100,minecraft:stone_brick_stairs-2
rule15=0,100,minecraft:stone_brick_stairs-0
rule16=0,100,minecraft:stone_slab-5
rule17=0,100,minecraft:stone_slab-13

layer
1,1,2,1,1,2,1,1,1
1,1,2,3,3,2,1,1,1
2,3,2,5,4,2,3,2,1
1,8,0,7,7,0,6,1,1
1,8,0,0,0,0,6,1,1
2,8,0,0,0,0,6,2,1
1,3,8,9,9,6,3,1,1
endlayer

layer
1,1,2,1,1,2,1,1,1
1,1,2,3,3,2,1,1,1
2,3,2,5,4,2,3,2,1
1,8,0,7,7,0,6,1,1
1,8,0,0,0,0,6,1,1
2,8,0,0,0,0,6,2,1
1,3,8,9,9,6,3,1,1
endlayer

layer
1,1,2,1,1,2,1,1,1
1,1,2,3,3,2,1,1,1
2,3,2,5,4,2,3,2,1
1,8,0,7,7,0,6,1,1
1,8,0,0,0,0,6,1,1
2,8,0,0,0,0,6,2,1
1,3,8,9,9,6,3,1,1
endlayer

layer
1,1,2,1,1,2,1,1,1
1,1,2,3,3,2,1,1,1
2,3,2,5,4,2,3,2,1
1,8,0,7,7,0,6,1,1
1,8,0,0,0,0,6,1,1
2,8,0,0,0,0,6,2,1
1,3,8,9,9,6,3,1,1
endlayer

layer
1,1,2,1,1,2,1,1,1
1,1,2,3,3,2,1,1,1
2,3,2,5,4,2,3,2,1
1,8,0,7,7,0,6,1,1
1,8,0,0,0,0,6,1,1
2,8,0,0,0,0,6,2,1
1,3,8,9,9,6,3,1,1
endlayer

layer
1,1,2,1,1,2,1,1,1
1,1,2,3,3,2,1,1,1
2,3,2,5,4,2,3,2,1
1,8,0,7,7,0,6,1,1
1,8,0,0,0,0,6,1,1
2,8,0,0,0,0,6,2,1
1,3,8,9,9,6,3,1,1
endlayer

layer
1,1,2,1,1,2,1,1,1
1,1,2,3,3,2,1,1,1
2,3,2,5,4,2,3,2,1
1,8,0,7,7,0,6,1,1
1,8,0,0,0,0,6,1,1
2,8,0,0,0,0,6,2,1
1,3,8,9,9,6,3,1,1
endlayer

layer
1,1,2,1,1,2,1,1,1
1,2,2,3,3,2,2,1,1
2,3,2,5,4,2,3,2,1
1,8,0,7,7,0,6,1,1
1,8,0,0,0,0,6,1,1
2,8,0,0,0,0,6,2,1
1,3,8,9,9,6,3,1,1
endlayer

layer
1,1,2,2,2,2,1,1,1
1,2,2,3,3,2,2,1,1
2,3,2,5,4,2,3,2,1
1,8,0,7,7,0,6,1,1
1,8,0,0,0,0,6,1,1
2,8,0,0,0,0,6,2,1
1,3,8,9,9,6,3,1,1
endlayer

layer
1,2,2,2,2,2,2,1,1
2,3,3,3,3,3,3,2,1
2,3,2,5,4,2,3,2,1
2,8,7,7,7,7,6,2,1
2,8,0,0,0,0,6,2,1
2,8,0,0,0,0,6,2,1
2,2,2,2,2,2,2,2,1
endlayer

layer
2,2,3,2,2,3,2,2,1
2,3,3,3,3,3,3,2,1
3,3,2,5,4,2,3,3,1
2,8,0,7,7,0,6,2,1
2,8,0,0,0,0,6,2,1
10,8,0,0,0,0,6,10,1
1,3,8,9,9,6,3,1,1
endlayer

layer
2,2,3,3,3,3,2,2,1
2,3,11,12,12,11,3,2,1
3,3,2,5,4,2,3,3,1
3,8,0,7,7,0,6,3,1
10,8,0,0,0,0,6,10,1
1,8,0,0,0,0,6,1,1
1,3,8,9,9,6,3,1,1
endlayer

layer
2,3,14,1,1,13,3,2,1
3,3,3,3,3,3,3,3,1
3,3,2,5,4,2,3,3,1
10,8,0,7,7,0,6,10,1
1,8,0,0,0,0,6,1,1
1,8,0,0,0,0,6,1,1
1,3,8,9,9,6,3,1,1
endlayer

layer
3,14,1,1,1,1,13,3,1
3,3,8,9,9,6,3,3,1
10,3,2,5,4,2,3,10,1
1,8,0,7,7,0,6,1,1
1,8,0,0,0,0,6,1,1
1,8,0,0,0,0,6,1,1
1,3,8,9,9,6,3,1,1
endlayer

layer
1,1,1,1,1,1,1,1,1
1,13,3,9,9,3,14,1,1
1,3,2,5,4,2,3,1,1
1,3,0,7,7,0,3,1,1
1,3,0,0,0,0,3,1,1
1,3,0,0,0,0,3,1,1
1,3,3,3,3,3,3,1,1
endlayer

layer
1,1,1,1,1,1,1,1,1
1,1,13,15,15,14,1,1,1
1,0,2,5,4,2,0,1,1
1,0,0,7,7,0,0,1,1
1,0,0,0,0,0,0,1,1
1,2,0,0,0,0,2,1,1
1,1,2,0,0,2,1,1,1
endlayer

layer
1,1,1,0,0,1,1,1,1
1,1,0,0,0,0,0,1,1
1,16,2,5,4,2,16,0,1
0,16,0,7,7,0,16,0,0
1,16,0,0,0,0,16,0,1
1,2,0,0,0,0,2,1,1
1,16,2,16,16,2,16,1,1
endlayer

layer
1,1,0,0,0,0,0,1,1
1,0,0,0,0,0,0,0,1
0,17,2,5,4,2,17,0,0
0,17,0,7,7,0,17,0,0
0,17,0,0,0,0,17,0,0
1,2,0,0,0,0,2,0,1
1,17,2,17,17,2,17,1,1
endlayer

layer
1,0,0,0,0,0,0,0,1
0,0,0,0,0,0,0,0,0
0,0,2,5,4,2,0,0,0
0,0,0,7,7,0,0,0,0
0,0,0,0,0,0,0,0,0
0,2,0,0,0,0,2,0,0
1,0,2,0,0,2,0,0,1
endlayer

layer
0,0,0,0,0,0,0,0,0
0,0,0,0,0,0,0,0,0
0,16,2,5,4,2,16,0,0
0,16,0,7,7,0,16,0,0
0,16,0,0,0,0,16,0,0
0,2,0,0,0,0,2,0,0
0,16,2,16,16,2,16,0,0
endlayer

layer
0,0,0,0,0,0,0,0,0
0,0,0,0,0,0,0,0,0
0,17,2,5,4,2,17,0,0
0,17,0,7,7,0,17,0,0
0,17,0,0,0,0,17,0,0
0,2,0,0,0,0,2,0,0
0,17,2,17,17,2,17,0,0
endlayer

layer
0,0,0,0,0,0,0,0,0
0,0,0,0,0,0,0,0,0
0,0,2,5,4,2,0,0,0
0,0,0,7,7,0,0,0,0
0,0,0,0,0,0,0,0,0
0,2,0,0,0,0,2,0,0
0,0,2,0,0,2,0,0,0
endlayer

layer
0,0,0,0,0,0,0,0,0
0,0,0,0,0,0,0,0,0
0,2,2,5,4,2,2,0,0
0,2,0,7,7,0,2,0,0
0,2,2,2,2,2,2,0,0
0,2,0,0,0,0,2,0,0
0,2,2,2,2,2,2,0,0
endlayer

layer
0,0,0,0,0,0,0,0,0
0,0,0,0,0,0,0,0,0
0,0,2,5,4,2,0,0,0
0,0,7,7,7,7,0,0,0
0,0,0,0,0,0,0,0,0
0,2,2,2,2,2,2,0,0
0,0,0,0,0,0,0,0,0
endlayer

layer
0,0,0,0,0,0,0,0,0
0,0,0,0,0,0,0,0,0
0,2,2,5,4,2,2,0,0
0,2,0,0,0,0,2,0,0
0,2,0,0,0,0,2,0,0
0,2,0,0,0,0,2,0,0
0,0,0,0,0,0,0,0,0
endlayer

