
# Created by Ruins mod version 16.7 Ingame Parser
# authoring Player: lafuller

weight=1
embed_into_distance=13
acceptable_target_blocks=water,waterlily
unacceptable_target_blocks=
biomesToSpawnIn=swampland,jungle,river,marsh,bog,wetland,mini_jungle,lush_swamp,green_swamp,dead_swamp,tropical_island,land_of_lakes
dimensions=20,9,8
allowable_overhang=0
max_leveling=2
leveling_buffer=-1
preserve_water=0
preserve_lava=0

rule1=0,100,preserveBlock
rule2=0,100,minecraft:log2-1
rule3=0,100,minecraft:log2-5
rule4=0,100,minecraft:log2-9
rule5=0,100,minecraft:spruce_fence-0
rule6=0,100,minecraft:ladder-3
rule7=0,100,minecraft:wooden_slab-9
rule8=0,100,minecraft:spruce_stairs-6
rule9=0,100,minecraft:spruce_stairs-7

layer
1,1,1,1,1,1,1,1
1,1,1,1,1,1,1,1
1,1,2,1,1,1,1,1
1,1,1,1,1,2,1,1
1,1,1,1,1,1,1,1
1,1,1,1,1,1,1,1
1,1,2,1,1,2,1,1
1,1,1,1,1,1,1,1
1,1,1,1,1,1,1,1
endlayer

layer
1,1,1,1,1,1,1,1
1,1,1,1,1,1,1,1
1,1,2,1,1,1,1,1
1,1,1,1,1,2,1,1
1,1,1,1,1,1,1,1
1,1,1,1,1,1,1,1
1,1,2,1,1,2,1,1
1,1,1,1,1,1,1,1
1,1,1,1,1,1,1,1
endlayer

layer
1,1,1,1,1,1,1,1
1,1,1,1,1,1,1,1
1,1,2,1,1,1,1,1
1,1,1,1,1,2,1,1
1,1,1,1,1,1,1,1
1,1,1,1,1,1,1,1
1,1,2,1,1,2,1,1
1,1,1,1,1,1,1,1
1,1,1,1,1,1,1,1
endlayer

layer
1,1,1,1,1,1,1,1
1,1,1,1,1,1,1,1
1,1,2,1,1,1,1,1
1,1,1,1,1,2,1,1
1,1,1,1,1,1,1,1
1,1,1,1,1,1,1,1
1,1,2,1,1,2,1,1
1,1,1,1,1,1,1,1
1,1,1,1,1,1,1,1
endlayer

layer
1,1,1,1,1,1,1,1
1,1,1,1,1,1,1,1
1,1,2,1,1,1,1,1
1,1,1,1,1,2,1,1
1,1,1,1,1,1,1,1
1,1,1,1,1,1,1,1
1,1,2,1,1,2,1,1
1,1,1,1,1,1,1,1
1,1,1,1,1,1,1,1
endlayer

layer
1,1,1,1,1,1,1,1
1,1,1,1,1,1,1,1
1,1,2,1,1,1,1,1
1,1,1,1,1,2,1,1
1,1,1,1,1,1,1,1
1,1,1,1,1,1,1,1
1,1,2,1,1,2,1,1
1,1,1,1,1,1,1,1
1,1,1,1,1,1,1,1
endlayer

layer
1,1,1,1,1,1,1,1
1,1,1,1,1,1,1,1
1,1,2,1,1,1,1,1
1,1,1,1,1,2,1,1
1,1,1,1,1,1,1,1
1,1,1,1,1,1,1,1
1,1,2,1,1,2,1,1
1,1,1,1,1,1,1,1
1,1,1,1,1,1,1,1
endlayer

layer
1,1,1,1,1,1,1,1
1,1,1,1,1,1,1,1
1,1,2,1,1,1,1,1
1,1,1,1,1,2,1,1
1,1,1,1,1,1,1,1
1,1,1,1,1,1,1,1
1,1,2,1,1,2,1,1
1,1,1,1,1,1,1,1
1,1,1,1,1,1,1,1
endlayer

layer
1,1,1,1,1,1,1,1
1,1,1,1,1,1,1,1
1,1,2,1,1,1,1,1
1,1,1,1,1,2,1,1
1,1,1,1,1,1,1,1
1,1,1,1,1,1,1,1
1,1,2,1,1,2,1,1
1,1,1,1,1,1,1,1
1,1,1,1,1,1,1,1
endlayer

layer
1,1,1,1,1,1,1,1
1,1,1,1,1,1,1,1
1,1,2,3,1,1,1,1
1,1,1,3,1,2,1,1
1,1,1,3,1,1,1,1
1,1,1,3,1,1,1,1
1,1,2,3,4,4,4,1
1,1,1,3,1,1,1,1
1,1,1,1,1,1,1,1
endlayer

layer
1,1,1,1,1,1,1,1
1,1,1,1,1,1,1,1
1,4,4,4,4,4,4,1
1,1,1,1,1,2,1,1
1,1,1,1,1,1,1,1
1,4,4,4,4,4,4,4
1,1,2,1,1,1,2,1
1,1,1,1,1,1,1,1
1,1,1,1,1,1,1,1
endlayer

layer
1,1,1,1,1,1,1,1
1,1,1,1,1,3,1,1
1,1,1,2,1,3,1,1
1,1,1,1,1,3,1,1
1,1,1,1,1,3,1,1
1,1,1,1,1,3,1,1
1,1,2,1,1,3,2,1
1,1,1,1,1,3,1,1
1,1,1,1,1,1,1,1
endlayer

layer
1,1,1,1,1,1,1,1
1,1,1,1,1,1,1,1
1,1,1,2,1,1,1,1
1,4,4,4,4,4,4,1
1,1,1,1,1,1,1,1
1,1,1,1,1,1,1,1
1,4,4,4,4,4,4,4
1,1,1,1,1,1,1,1
1,1,1,1,1,1,1,1
endlayer

layer
1,1,5,1,1,1,1,1
1,1,3,1,1,1,1,1
1,1,3,2,1,1,1,1
1,1,3,1,1,2,1,1
1,1,3,1,1,1,1,1
1,1,3,1,1,1,1,1
1,1,3,1,1,1,2,1
1,1,3,1,1,1,1,1
1,1,5,1,1,1,1,1
endlayer

layer
1,1,1,1,1,1,1,1
1,1,1,1,1,1,1,1
1,1,6,2,1,1,1,1
1,1,1,1,1,2,1,1
1,1,1,1,1,1,1,1
1,1,2,1,1,1,1,1
1,1,1,1,1,1,2,1
1,1,1,1,1,1,1,1
1,1,1,1,1,1,1,1
endlayer

layer
1,1,1,1,1,1,1,1
1,1,1,1,1,1,1,1
1,1,6,2,1,1,1,1
1,1,1,1,1,2,1,1
1,1,1,1,1,1,1,1
5,4,4,4,4,4,4,5
1,1,1,1,1,1,2,1
1,1,1,1,1,1,1,1
1,1,1,1,1,1,1,1
endlayer

layer
1,1,1,1,5,1,1,1
1,1,1,1,3,1,1,1
1,1,6,2,3,8,7,1
1,1,7,9,3,2,7,1
1,1,7,7,3,7,7,1
1,1,9,7,3,8,8,1
1,1,7,9,3,4,2,1
1,1,1,1,3,1,1,1
1,1,1,1,5,1,1,1
endlayer

layer
1,1,1,1,1,1,1,1
1,1,1,1,1,1,1,1
1,1,1,2,1,1,1,1
1,1,1,1,1,1,1,1
1,1,1,1,1,1,1,1
1,1,1,1,1,1,1,1
1,1,1,1,1,1,2,1
1,1,1,1,1,1,1,1
1,1,1,1,1,1,1,1
endlayer

layer
1,1,1,1,1,1,1,1
1,1,1,1,1,1,1,1
1,1,1,2,1,1,1,1
1,1,1,1,1,1,1,1
1,1,1,1,1,1,1,1
1,1,1,1,1,1,1,1
1,1,1,1,1,1,2,1
1,1,1,1,1,1,1,1
1,1,1,1,1,1,1,1
endlayer

layer
1,1,1,1,1,1,1,1
1,1,1,1,1,1,1,1
1,1,1,2,1,1,1,1
1,1,1,1,1,1,1,1
1,1,1,1,1,1,1,1
1,1,1,1,1,1,1,1
1,1,1,1,1,1,1,1
1,1,1,1,1,1,1,1
1,1,1,1,1,1,1,1
endlayer

