
# file generated with Ruins mod version 16.7 Ingame Parser
# authoring Player: lafuller

weight=1
embed_into_distance=32
random_height_offset=-20,4
acceptable_target_blocks=grass,dirt,stone,sand
unacceptable_target_blocks=flowing_water,water,flowing_lava,lava,ice,bedrock,netherrack,nether_brick,nether_brick_fence,soul_sand,quartz_ore,gravel,end_stone,obsidian,iron_bars,cloud,flesh,ash_block,slime_grass,slime_congealed,slime_dirt
dimensions=16,19,19
allowable_overhang=0
max_leveling=20
leveling_buffer=-1
preserve_water=0
preserve_lava=0
preventRotation=1

rule1=0,100,preserveBlock
rule2=0,100,stonebrick-0,stonebrick-0,stonebrick-1,stonebrick-1,stonebrick-2,stonebrick-2,stonebrick-3,cobblestone,stone-5,stone-6
rule3=0,100,diamond_ore-0,lapis_block-0,gold_block-0,emerald_block-0,iron_block-0,gold_ore-0,lapis_ore-0,emerald_ore-0,lapis_block-0,gold_block-0,gold_ore-0,lapis_ore-0,emerald_ore-0
rule4=0,100,minecraft:cobblestone_wall-0
rule5=0,100,minecraft:water-0
rule6=0,100,minecraft:obsidian-0
rule7=0,100,ChestGenHook:chests/stronghold_corridor:5-5
rule8=0,100,minecraft:water-9
rule9=0,100,minecraft:stone_slab-0
rule10=0,100,minecraft:stone_brick_stairs-0
rule11=0,100,minecraft:iron_bars-0
rule12=0,100,minecraft:stone_brick_stairs-2
rule13=0,100,minecraft:stone_brick_stairs-3
rule14=0,100,minecraft:stone_brick_stairs-1
rule15=0,100,MobSpawner:Creeper
rule16=1,100,minecraft:redstone_torch-5
rule17=0,100,minecraft:water-1
rule18=0,100,air
rule19=0,100,CommandBlock:RUINSTRIGGER /testruin Gilly/GillyRift ~-16 ~2 ~0 1:@
rule20=0,100,CommandBlock:RUINSTRIGGER /testruin Gilly/GillyRift ~0 ~2 ~-16 2:@
rule21=0,100,CommandBlock:RUINSTRIGGER /testruin Gilly/GillyRift ~16 ~2 ~0 3:@
rule22=0,100,CommandBlock:RUINSTRIGGER /testruin Gilly/GillyRift ~0 ~2 ~16 0:@

layer
1,1,1,1,2,2,2,2,2,19,2,2,2,2,2,1,1,1,1
1,1,1,1,2,2,2,2,2,2,2,2,2,2,2,1,1,1,1
1,1,1,2,2,4,4,4,4,4,4,4,4,4,2,2,1,1,1
1,1,2,4,4,4,4,2,4,4,4,2,4,4,4,4,2,1,1
2,2,2,4,4,4,4,2,4,4,4,2,4,4,4,4,2,2,2
2,2,4,4,4,2,4,4,4,2,4,4,4,2,4,4,4,2,2
2,2,4,4,4,4,4,4,4,4,4,4,4,4,4,4,4,2,2
2,2,4,2,2,4,4,4,2,2,2,4,4,4,2,2,4,2,2
2,2,4,4,4,4,4,2,2,2,2,2,4,4,4,4,4,2,2
22,2,4,4,4,2,4,2,2,2,2,2,4,2,4,4,4,2,20
2,2,4,4,4,4,4,2,2,2,2,2,4,4,4,4,4,2,2
2,2,4,2,2,4,4,4,2,2,2,4,4,4,2,2,4,2,2
2,2,4,4,4,4,4,4,4,4,4,4,4,4,4,4,4,2,2
2,2,4,4,4,2,4,4,4,2,4,4,4,2,4,4,4,2,2
2,2,2,4,4,4,4,2,4,4,4,2,4,4,4,4,2,2,2
1,1,2,4,4,4,4,2,4,4,4,2,4,4,4,4,2,1,1
1,1,1,2,2,4,4,4,4,4,4,4,4,4,2,2,1,1,1
1,1,1,1,2,2,2,2,2,2,2,2,2,2,2,1,1,1,1
1,1,1,1,2,2,2,2,2,21,2,2,2,2,2,1,1,1,1
endlayer

layer
1,1,1,2,2,2,2,2,2,2,2,2,2,2,2,2,1,1,1
1,1,1,2,2,2,2,2,2,2,2,2,2,2,2,2,1,1,1
1,1,2,2,2,5,5,5,5,5,5,5,5,5,2,2,2,1,1
2,2,2,5,5,5,5,2,5,5,5,2,5,5,5,5,2,2,2
2,2,2,5,5,5,5,2,5,5,5,2,5,5,5,5,2,2,2
2,2,5,5,5,2,5,5,5,2,5,5,5,2,5,5,5,2,2
2,2,5,5,5,5,5,5,5,5,5,5,5,5,5,5,5,2,2
2,2,5,2,2,5,5,5,2,2,2,5,5,5,2,2,5,2,2
2,2,5,5,5,5,5,2,6,6,6,2,5,5,5,5,5,2,2
2,2,5,5,5,2,5,2,6,7,6,2,5,2,5,5,5,2,2
2,2,5,5,5,5,5,2,6,6,6,2,5,5,5,5,5,2,2
2,2,5,2,2,5,5,5,2,2,2,5,5,5,2,2,5,2,2
2,2,5,5,5,5,5,5,5,5,5,5,5,5,5,5,5,2,2
2,2,5,5,5,2,5,5,5,2,5,5,5,2,5,5,5,2,2
2,2,2,5,5,5,5,2,5,5,5,2,5,5,5,5,2,2,2
2,2,2,5,5,5,5,2,5,5,5,2,5,5,5,5,2,2,2
1,1,2,2,2,5,5,5,5,5,5,5,5,5,2,2,2,1,1
1,1,1,2,2,2,2,2,2,2,2,2,2,2,2,2,1,1,1
1,1,1,2,2,2,2,2,2,2,2,2,2,2,2,2,1,1,1
endlayer

layer
1,1,1,2,2,0,2,2,2,2,2,2,2,0,2,2,1,1,1
1,1,2,2,0,0,2,0,2,0,2,0,2,0,0,2,2,1,1
1,2,2,0,0,0,0,0,0,0,0,0,0,0,0,0,2,2,1
2,2,0,0,8,0,8,9,8,0,8,9,8,0,8,0,0,2,2
2,0,0,0,0,0,0,0,0,0,0,0,0,0,0,0,0,0,2
0,0,0,0,0,0,0,0,0,9,0,0,0,0,0,0,0,0,0
2,2,0,0,0,0,0,0,0,0,0,0,0,0,0,0,0,2,2
2,0,0,9,0,0,0,0,0,2,0,0,0,0,0,9,0,0,2
2,2,0,0,0,0,0,0,4,6,4,0,0,0,0,0,0,2,2
2,0,0,0,0,9,0,2,6,3,6,2,0,9,0,0,0,0,2
2,2,0,0,0,0,0,0,4,6,4,0,0,0,0,0,0,2,2
2,0,0,9,0,0,0,0,0,2,0,0,0,0,0,9,0,0,2
2,2,0,0,0,0,0,0,0,0,0,0,0,0,0,0,0,2,2
0,0,0,0,0,0,0,0,0,9,0,0,0,0,0,0,0,0,0
2,0,0,0,0,0,0,0,0,0,0,0,0,0,0,0,0,0,2
2,2,0,0,0,0,0,9,0,0,0,9,0,0,0,0,0,2,2
1,2,2,0,0,0,0,0,0,0,0,0,0,0,0,0,2,2,1
1,1,2,2,0,0,2,0,2,0,2,0,2,0,0,2,2,1,1
1,1,1,2,2,0,2,2,2,2,2,2,2,0,2,2,1,1,1
endlayer

layer
1,2,2,2,2,0,2,0,2,2,2,0,2,0,2,2,2,2,1
2,2,2,2,0,0,0,0,2,0,2,0,0,0,0,2,2,2,2
2,2,2,0,0,0,0,0,0,0,0,0,0,0,0,0,2,2,2
2,2,0,0,8,0,8,0,8,0,8,0,8,0,8,0,0,2,2
2,0,0,0,0,0,0,0,0,0,0,0,0,0,0,0,0,0,2
0,0,0,0,0,0,0,0,0,0,0,0,0,0,0,0,0,0,0
2,0,0,0,0,0,0,0,0,0,0,0,0,0,0,0,0,0,2
0,0,0,0,0,0,0,0,0,10,0,0,0,0,0,0,0,0,0
2,2,0,0,0,0,0,0,11,11,11,0,0,0,0,0,0,2,2
2,0,0,0,0,0,0,13,11,11,11,12,0,0,0,0,0,0,2
2,2,0,0,0,0,0,0,11,11,11,0,0,0,0,0,0,2,2
0,0,0,0,0,0,0,0,0,14,0,0,0,0,0,0,0,0,0
2,0,0,0,0,0,0,0,0,0,0,0,0,0,0,0,0,0,2
0,0,0,0,0,0,0,0,0,0,0,0,0,0,0,0,0,0,0
2,0,0,0,0,0,0,0,0,0,0,0,0,0,0,0,0,0,2
2,2,0,0,0,0,0,0,0,0,0,0,0,0,0,0,0,2,2
2,2,2,0,0,0,0,0,0,0,0,0,0,0,0,0,2,2,2
2,2,2,2,0,0,0,0,2,0,2,0,0,0,0,2,2,2,2
1,2,2,2,2,0,2,0,2,2,2,0,2,0,2,2,2,2,1
endlayer

layer
1,2,0,2,2,2,2,0,2,0,2,0,2,2,2,2,0,2,1
2,2,0,2,0,2,0,0,0,0,0,0,0,2,0,2,0,2,2
0,0,0,0,0,0,0,0,0,0,0,0,0,0,0,0,0,0,0
2,2,0,0,8,0,8,0,8,0,8,0,8,0,8,0,0,2,2
2,0,0,0,0,0,0,0,0,0,0,0,0,0,0,0,0,0,2
2,2,0,0,0,0,0,0,0,0,0,0,0,0,0,0,0,2,2
2,0,0,0,0,0,0,0,0,0,0,0,0,0,0,0,0,0,2
0,0,0,0,0,0,0,0,0,0,0,0,0,0,0,0,0,0,0
2,0,0,0,0,0,0,0,0,6,0,0,0,0,0,0,0,0,2
0,0,0,0,0,0,0,0,6,6,6,0,0,0,0,0,0,0,0
2,0,0,0,0,0,0,0,0,6,0,0,0,0,0,0,0,0,2
0,0,0,0,0,0,0,0,0,0,0,0,0,0,0,0,0,0,0
2,0,0,0,0,0,0,0,0,0,0,0,0,0,0,0,0,0,2
2,2,0,0,0,0,0,0,0,0,0,0,0,0,0,0,0,2,2
2,0,0,0,0,0,0,0,0,0,0,0,0,0,0,0,0,0,2
2,2,0,0,0,0,0,0,0,0,0,0,0,0,0,0,0,2,2
0,0,0,0,0,0,0,0,0,0,0,0,0,0,0,0,0,0,0
2,2,0,2,0,2,0,0,0,0,0,0,0,2,0,2,0,2,2
1,2,0,2,2,2,2,0,2,0,2,0,2,2,2,2,0,2,1
endlayer

layer
1,2,0,2,0,2,2,2,2,0,2,2,2,2,0,2,0,2,1
2,2,0,2,0,2,0,2,0,0,0,2,0,2,0,2,0,2,2
0,0,0,0,0,0,0,0,0,0,0,0,0,0,0,0,0,0,0
2,2,0,0,8,0,8,0,8,0,8,0,8,0,8,0,0,2,2
0,0,0,0,0,0,0,0,0,0,0,0,0,0,0,0,0,0,0
2,2,0,0,0,0,0,0,0,0,0,0,0,0,0,0,0,2,2
2,0,0,0,0,0,0,0,0,0,0,0,0,0,0,0,0,0,2
2,2,0,0,0,0,0,0,0,0,0,0,0,0,0,0,0,2,2
2,0,0,0,0,0,0,0,0,6,0,0,0,0,0,0,0,0,2
0,0,0,0,0,0,0,0,6,15,6,0,0,0,0,0,0,0,0
2,0,0,0,0,0,0,0,0,6,0,0,0,0,0,0,0,0,2
2,2,0,0,0,0,0,0,0,0,0,0,0,0,0,0,0,2,2
2,0,0,0,0,0,0,0,0,0,0,0,0,0,0,0,0,0,2
2,2,0,0,0,0,0,0,0,0,0,0,0,0,0,0,0,2,2
0,0,0,0,0,0,0,0,0,0,0,0,0,0,0,0,0,0,0
2,2,0,0,0,0,0,0,0,0,0,0,0,0,0,0,0,2,2
0,0,0,0,0,0,0,0,0,0,0,0,0,0,0,0,0,0,0
2,2,0,2,0,2,0,2,0,0,0,2,0,2,0,2,0,2,2
1,2,0,2,0,2,2,2,2,0,2,2,2,2,0,2,0,2,1
endlayer

layer
1,2,2,2,0,2,0,2,2,2,2,2,0,2,0,2,2,2,1
2,2,2,2,0,2,0,2,0,2,0,2,0,2,0,2,2,2,2
2,2,2,0,0,0,0,0,0,0,0,0,0,0,0,0,2,2,2
2,2,0,0,8,0,8,0,8,0,8,0,8,0,8,0,0,2,2
0,0,0,0,0,0,0,0,0,0,0,0,0,0,0,0,0,0,0
2,2,0,0,0,0,0,0,0,0,0,0,0,0,0,0,0,2,2
0,0,0,0,0,0,0,0,0,0,0,0,0,0,0,0,0,0,0
2,2,0,0,0,0,0,0,0,0,0,0,0,0,0,0,0,2,2
2,0,0,0,0,0,0,0,0,0,0,0,0,0,0,0,0,0,2
2,2,0,0,0,0,0,0,0,0,0,0,0,0,0,0,0,2,2
2,0,0,0,0,0,0,0,0,0,0,0,0,0,0,0,0,0,2
2,2,0,0,0,0,0,0,0,0,0,0,0,0,0,0,0,2,2
0,0,0,0,0,0,0,0,0,0,0,0,0,0,0,0,0,0,0
2,2,0,0,0,0,0,0,0,0,0,0,0,0,0,0,0,2,2
0,0,0,0,0,0,0,0,0,0,0,0,0,0,0,0,0,0,0
2,2,0,0,0,0,0,0,0,0,0,0,0,0,0,0,0,2,2
2,2,2,0,0,0,0,0,0,0,0,0,0,0,0,0,2,2,2
2,2,2,2,0,2,0,2,0,2,0,2,0,2,0,2,2,2,2
1,2,2,2,0,2,0,2,2,2,2,2,0,2,0,2,2,2,1
endlayer

layer
1,1,2,2,2,2,0,2,0,2,0,2,0,2,2,2,2,1,1
1,2,2,2,2,2,0,2,0,2,0,2,0,2,2,2,2,2,1
2,2,2,0,2,0,0,0,0,0,0,0,0,0,2,0,2,2,2
2,2,0,0,8,0,8,0,8,0,8,0,8,0,8,0,0,2,2
2,2,2,0,0,0,0,0,0,0,0,0,0,0,0,0,2,2,2
2,2,0,0,0,0,0,0,0,0,0,0,0,0,0,0,0,2,2
0,0,0,0,0,0,0,0,0,0,0,0,0,0,0,0,0,0,0
2,2,0,0,0,0,0,0,0,0,0,0,0,0,0,0,0,2,2
0,0,0,0,0,0,0,0,0,2,0,0,0,0,0,0,0,0,0
2,2,0,0,0,0,0,0,2,2,2,0,0,0,0,0,0,2,2
0,0,0,0,0,0,0,0,0,2,0,0,0,0,0,0,0,0,0
2,2,0,0,0,0,0,0,0,0,0,0,0,0,0,0,0,2,2
0,0,0,0,0,0,0,0,0,0,0,0,0,0,0,0,0,0,0
2,2,0,0,0,0,0,0,0,0,0,0,0,0,0,0,0,2,2
2,2,2,0,0,0,0,0,0,0,0,0,0,0,0,0,2,2,2
2,2,0,0,0,0,0,0,0,0,0,0,0,0,0,0,0,2,2
2,2,2,0,2,0,0,0,0,0,0,0,0,0,2,0,2,2,2
1,2,2,2,2,2,0,2,0,2,0,2,0,2,2,2,2,2,1
1,1,2,2,2,2,0,2,0,2,0,2,0,2,2,2,2,1,1
endlayer

layer
1,1,2,0,2,2,2,2,0,2,0,2,2,2,2,0,2,1,1
1,2,2,0,2,2,2,2,0,2,0,2,2,2,2,0,2,2,1
2,2,2,0,2,0,2,0,0,0,0,0,2,0,2,0,2,2,2
0,0,0,0,8,0,8,0,8,0,8,0,8,0,8,0,0,0,0
2,2,2,0,0,0,0,0,0,0,0,0,0,0,0,0,2,2,2
2,2,0,0,0,0,0,0,0,0,0,0,0,0,0,0,0,2,2
2,2,2,0,0,0,0,0,0,0,0,0,0,0,0,0,2,2,2
2,2,0,0,0,0,0,0,0,0,0,0,0,0,0,0,0,2,2
0,0,0,0,0,0,0,0,0,4,0,0,0,0,0,0,0,0,0
2,2,0,0,0,0,0,0,4,2,4,0,0,0,0,0,0,2,2
0,0,0,0,0,0,0,0,0,4,0,0,0,0,0,0,0,0,0
2,2,0,0,0,0,0,0,0,0,0,0,0,0,0,0,0,2,2
2,2,2,0,0,0,0,0,0,0,0,0,0,0,0,0,2,2,2
2,2,0,0,0,0,0,0,0,0,0,0,0,0,0,0,0,2,2
2,2,2,0,0,0,0,0,0,0,0,0,0,0,0,0,2,2,2
0,0,0,0,0,0,0,0,0,0,0,0,0,0,0,0,0,0,0
2,2,2,0,2,0,2,0,0,0,0,0,2,0,2,0,2,2,2
1,2,2,0,2,2,2,2,0,2,0,2,2,2,2,0,2,2,1
1,1,2,0,2,2,2,2,0,2,0,2,2,2,2,0,2,1,1
endlayer

layer
1,1,2,0,2,0,2,2,2,2,2,2,2,0,2,0,2,1,1
1,2,2,0,2,0,2,2,2,2,2,2,2,0,2,0,2,2,1
2,2,2,0,2,0,2,0,2,0,2,0,2,0,2,0,2,2,2
0,0,0,2,8,0,8,0,8,0,8,0,8,0,8,2,0,0,0
2,2,2,0,0,0,0,0,0,0,0,0,0,0,0,0,2,2,2
0,0,0,0,0,0,0,0,0,0,0,0,0,0,0,0,0,0,0
2,2,2,0,0,0,0,0,0,0,0,0,0,0,0,0,2,2,2
2,2,0,0,0,0,0,0,0,0,0,0,0,0,0,0,0,2,2
2,2,2,0,0,0,0,0,0,2,0,0,0,0,0,0,2,2,2
2,2,0,0,0,0,0,0,2,2,2,0,0,0,0,0,0,2,2
2,2,2,0,0,0,0,0,0,2,0,0,0,0,0,0,2,2,2
2,2,0,0,0,0,0,0,0,0,0,0,0,0,0,0,0,2,2
2,2,2,0,0,0,0,0,0,0,0,0,0,0,0,0,2,2,2
0,0,0,0,0,0,0,0,0,0,0,0,0,0,0,0,0,0,0
2,2,2,0,0,0,0,0,0,0,0,0,0,0,0,0,2,2,2
0,0,0,2,0,0,0,0,0,0,0,0,0,0,0,2,0,0,0
2,2,2,0,2,0,2,0,2,0,2,0,2,0,2,0,2,2,2
1,2,2,0,2,0,2,2,2,2,2,2,2,0,2,0,2,2,1
1,1,2,0,2,0,2,2,2,2,2,2,2,0,2,0,2,1,1
endlayer

layer
1,1,2,2,2,0,2,0,2,2,2,0,2,0,2,2,2,1,1
1,1,2,2,2,0,2,0,2,2,2,0,2,0,2,2,2,1,1
2,2,2,2,2,0,2,0,2,0,2,0,2,0,2,2,2,2,2
2,2,2,2,8,0,8,0,8,0,8,0,8,0,8,2,2,2,2
2,2,2,0,0,0,0,0,0,0,0,0,0,0,0,0,2,2,2
0,0,0,0,0,0,0,0,0,0,0,0,0,0,0,0,0,0,0
2,2,2,0,0,0,0,0,0,0,0,0,0,0,0,0,2,2,2
0,0,0,0,0,0,0,0,0,0,0,0,0,0,0,0,0,0,0
2,2,2,0,0,0,0,0,0,2,0,0,0,0,0,0,2,2,2
2,2,0,0,0,0,0,0,2,16,2,0,0,0,0,0,0,2,2
2,2,2,0,0,0,0,0,0,2,0,0,0,0,0,0,2,2,2
0,0,0,0,0,0,0,0,0,0,0,0,0,0,0,0,0,0,0
2,2,2,0,0,0,0,0,0,0,0,0,0,0,0,0,2,2,2
0,0,0,0,0,0,0,0,0,0,0,0,0,0,0,0,0,0,0
2,2,2,0,0,0,0,0,0,0,0,0,0,0,0,0,2,2,2
2,2,2,2,0,0,0,0,0,0,0,0,0,0,0,2,2,2,2
2,2,2,2,2,0,2,0,2,0,2,0,2,0,2,2,2,2,2
1,1,2,2,2,0,2,0,2,2,2,0,2,0,2,2,2,1,1
1,1,2,2,2,0,2,0,2,2,2,0,2,0,2,2,2,1,1
endlayer

layer
1,1,1,2,2,2,2,0,2,0,2,0,2,2,2,2,1,1,1
1,1,2,2,2,2,2,0,2,0,2,0,2,2,2,2,2,1,1
1,2,2,2,2,2,2,0,2,0,2,0,2,2,2,2,2,2,1
2,2,2,2,8,2,8,0,8,0,8,0,8,2,8,2,2,2,2
2,2,2,0,0,0,0,0,0,0,0,0,0,0,0,0,2,2,2
2,2,2,2,0,0,0,0,0,0,0,0,0,0,0,2,2,2,2
2,2,2,0,0,0,0,0,0,0,0,0,0,0,0,0,2,2,2
0,0,0,0,0,0,0,0,0,0,0,0,0,0,0,0,0,0,0
2,2,2,0,0,0,0,0,0,4,0,0,0,0,0,0,2,2,2
0,0,0,0,0,0,0,0,4,2,4,0,0,0,0,0,0,0,0
2,2,2,0,0,0,0,0,0,4,0,0,0,0,0,0,2,2,2
0,0,0,0,0,0,0,0,0,0,0,0,0,0,0,0,0,0,0
2,2,2,0,0,0,0,0,0,0,0,0,0,0,0,0,2,2,2
2,2,2,2,0,0,0,0,0,0,0,0,0,0,0,2,2,2,2
2,2,2,0,0,0,0,0,0,0,0,0,0,0,0,0,2,2,2
2,2,2,2,0,2,0,0,0,0,0,0,0,2,0,2,2,2,2
1,2,2,2,2,2,2,0,2,0,2,0,2,2,2,2,2,2,1
1,1,2,2,2,2,2,0,2,0,2,0,2,2,2,2,2,1,1
1,1,1,2,2,2,2,0,2,0,2,0,2,2,2,2,1,1,1
endlayer

layer
1,1,1,2,0,2,2,2,2,0,2,2,2,2,0,2,1,1,1
1,1,2,2,0,2,2,2,2,0,2,2,2,2,0,2,2,1,1
1,2,2,2,5,16,2,2,2,0,2,2,2,16,5,2,2,2,1
2,2,2,2,17,2,8,2,8,0,8,2,8,2,17,2,2,2,2
0,0,0,0,0,0,0,0,0,0,0,0,0,0,0,0,0,0,0
2,2,16,2,0,2,0,0,0,0,0,0,0,2,0,2,16,2,2
2,2,2,0,0,0,0,0,0,0,0,0,0,0,0,0,2,2,2
2,2,2,2,0,0,0,0,0,0,0,0,0,0,0,2,2,2,2
2,2,2,0,0,0,0,0,0,2,0,0,0,0,0,0,2,2,2
0,0,0,0,0,0,0,0,2,2,2,0,0,0,0,0,0,0,0
2,2,2,0,0,0,0,0,0,2,0,0,0,0,0,0,2,2,2
2,2,2,2,0,0,0,0,0,0,0,0,0,0,0,2,2,2,2
2,2,2,0,0,0,0,0,0,0,0,0,0,0,0,0,2,2,2
2,2,16,2,0,2,0,0,0,0,0,0,0,2,0,2,16,2,2
0,0,0,0,0,0,0,0,0,0,0,0,0,0,0,0,0,0,0
2,2,2,2,0,2,0,2,0,0,0,2,0,2,0,2,2,2,2
1,2,2,2,0,16,2,2,2,0,2,2,2,16,0,2,2,2,1
1,1,2,2,0,2,2,2,2,0,2,2,2,2,0,2,2,1,1
1,1,1,2,0,2,2,2,2,0,2,2,2,2,0,2,1,1,1
endlayer

layer
1,1,1,2,0,2,0,2,2,2,2,2,0,2,0,2,1,1,1
1,1,2,2,0,0,0,2,2,2,2,2,0,0,0,2,2,1,1
1,2,2,2,0,2,5,2,2,2,2,2,5,2,0,2,2,2,1
2,2,2,2,0,2,17,2,8,2,8,2,17,2,0,2,2,2,2
0,0,0,0,2,0,0,2,0,0,0,2,0,0,2,0,0,0,0
2,0,2,2,0,2,0,0,0,0,0,0,0,2,0,2,2,0,2
0,0,0,0,0,0,0,0,2,0,2,0,0,0,0,0,0,0,0
2,2,2,2,2,0,0,0,0,0,0,0,0,0,2,2,2,2,2
2,2,2,0,0,0,2,0,0,0,0,0,2,0,0,0,2,2,2
2,2,2,2,0,0,0,0,0,16,0,0,0,0,0,2,2,2,2
2,2,2,0,0,0,2,0,0,0,0,0,2,0,0,0,2,2,2
2,2,2,2,2,0,0,0,0,0,0,0,0,0,2,2,2,2,2
0,0,0,0,0,0,0,0,2,0,2,0,0,0,0,0,0,0,0
2,0,2,2,0,2,0,0,0,0,0,0,0,2,0,2,2,0,2
0,0,0,0,2,0,0,2,0,0,0,2,0,0,2,0,0,0,0
2,2,2,2,0,2,0,2,0,2,0,2,0,2,0,2,2,2,2
1,2,2,2,0,2,0,2,2,2,2,2,0,2,0,2,2,2,1
1,1,2,2,0,0,0,2,2,2,2,2,0,0,0,2,2,1,1
1,1,1,2,0,2,0,2,2,2,2,2,0,2,0,2,1,1,1
endlayer

layer
1,1,1,2,2,2,0,2,0,2,0,2,0,2,2,2,1,1,1
1,1,1,2,2,2,0,0,0,16,0,0,0,2,2,2,1,1,1
1,1,1,2,2,2,0,2,5,2,5,2,0,2,2,2,1,1,1
2,2,2,2,2,2,0,2,17,2,17,2,0,2,2,2,2,2,2
2,2,2,2,2,2,0,2,0,2,0,2,0,2,2,2,2,2,2
2,2,2,2,2,2,2,0,2,0,2,0,2,2,2,2,2,2,2
0,0,0,0,0,2,0,0,2,0,2,0,0,2,0,0,0,0,0
2,0,2,2,2,0,0,2,0,0,0,2,0,0,2,2,2,0,2
0,0,0,0,0,2,2,0,2,0,2,0,2,2,0,0,0,0,0
2,16,2,2,2,0,0,0,0,2,0,0,0,0,2,2,2,16,2
0,0,0,0,0,2,2,0,2,0,2,0,2,2,0,0,0,0,0
2,0,2,2,2,0,0,2,0,0,0,2,0,0,2,2,2,0,2
0,0,0,0,0,2,0,0,2,0,2,0,0,2,0,0,0,0,0
2,2,2,2,2,2,2,0,2,0,2,0,2,2,2,2,2,2,2
2,2,2,2,2,2,0,2,0,2,0,2,0,2,2,2,2,2,2
2,2,2,2,2,2,0,2,0,2,0,2,0,2,2,2,2,2,2
1,1,1,2,2,2,0,2,0,2,0,2,0,2,2,2,1,1,1
1,1,1,2,2,2,0,0,0,16,0,0,0,2,2,2,1,1,1
1,1,1,2,2,2,0,2,0,2,0,2,0,2,2,2,1,1,1
endlayer

layer
1,1,1,1,1,2,2,2,0,2,0,2,2,2,1,1,1,1,1
1,1,1,1,1,2,2,2,0,2,0,2,2,2,1,1,1,1,1
1,1,1,1,1,2,2,2,0,2,0,2,2,2,1,1,1,1,1
1,1,1,1,1,2,2,2,0,2,0,2,2,2,1,1,1,1,1
1,1,1,1,2,2,2,2,2,2,2,2,2,2,2,1,1,1,1
2,2,2,2,2,2,2,2,2,2,2,2,2,2,2,2,2,2,2
2,2,2,2,2,2,2,2,2,2,2,2,2,2,2,2,2,2,2
2,2,2,2,2,2,2,2,2,2,2,2,2,2,2,2,2,2,2
0,0,0,0,2,2,2,2,2,2,2,2,2,2,2,0,0,0,0
2,2,2,2,2,2,2,2,2,18,2,2,2,2,2,2,2,2,2
0,0,0,0,2,2,2,2,2,2,2,2,2,2,2,0,0,0,0
2,2,2,2,2,2,2,2,2,2,2,2,2,2,2,2,2,2,2
2,2,2,2,2,2,2,2,2,2,2,2,2,2,2,2,2,2,2
2,2,2,2,2,2,2,2,2,2,2,2,2,2,2,2,2,2,2
1,1,1,1,2,2,2,2,2,2,2,2,2,2,2,1,1,1,1
1,1,1,1,1,2,2,2,0,2,0,2,2,2,1,1,1,1,1
1,1,1,1,1,2,2,2,0,2,0,2,2,2,1,1,1,1,1
1,1,1,1,1,2,2,2,0,2,0,2,2,2,1,1,1,1,1
1,1,1,1,1,2,2,2,0,2,0,2,2,2,1,1,1,1,1
endlayer

