
# Created by Ruins mod version 16.7 Ingame Parser
# authoring Player: lafuller

weight=1
embed_into_distance=5
acceptable_target_blocks=
unacceptable_target_blocks=flowing_water,water,flowing_lava,lava,ice,bedrock,netherrack,nether_brick,nether_brick_fence,soul_sand,quartz_ore,gravel,end_stone,obsidian,iron_bars,cloud,flesh,ash_block,slime_grass,slime_congealed,slime_dirt
dimensions=25,21,21
allowable_overhang=0
max_leveling=5
leveling_buffer=-1
preserve_water=0
preserve_lava=0

rule1=0,100,preserveBlock
rule2=0,100,minecraft:sandstone-2
rule3=0,100,minecraft:sandstone_stairs-1
rule4=0,100,minecraft:sandstone_stairs-3
rule5=0,100,minecraft:sandstone_stairs-2
rule6=0,100,minecraft:sandstone_stairs-0
rule7=0,100,minecraft:stone-6
rule8=0,100,minecraft:stone-5
rule9=0,100,minecraft:double_stone_slab-9
rule10=0,100,minecraft:sandstone_stairs-4
rule11=0,100,minecraft:sandstone_stairs-5
rule12=0,100,minecraft:sandstone_stairs-6
rule13=0,100,minecraft:sandstone_stairs-7
rule14=0,100,minecraft:stone_slab-9
rule15=0,100,minecraft:stained_hardened_clay-3
rule16=0,100,minecraft:sandstone-1
rule17=0,100,minecraft:stone_slab-1
rule18=0,100,minecraft:spruce_fence_gate-1
rule19=0,100,minecraft:spruce_fence_gate-2
rule20=0,100,minecraft:spruce_fence_gate-0
rule21=0,100,minecraft:spruce_fence_gate-3

layer
2,2,2,2,2,2,2,2,2,2,2,2,2,2,2,2,2,2,2,2,2
2,2,2,2,2,2,2,2,2,2,2,2,2,2,2,2,2,2,2,2,2
2,2,2,2,2,2,2,2,2,2,2,2,2,2,2,2,2,2,2,2,2
2,2,2,2,3,3,2,2,2,2,2,2,2,2,2,3,3,2,2,2,2
2,2,2,5,0,0,4,2,2,2,2,2,2,2,5,0,0,4,2,2,2
2,2,2,5,0,0,4,2,2,2,2,2,2,2,5,0,0,4,2,2,2
2,2,2,2,6,6,4,2,2,2,2,2,2,2,6,6,6,2,2,2,2
2,2,2,2,2,2,2,2,2,2,7,2,2,2,2,2,2,2,2,2,2
2,2,2,2,2,2,2,2,2,2,7,2,2,2,2,2,2,2,2,2,2
2,2,2,2,2,2,2,2,2,8,7,8,2,2,2,2,2,2,2,2,2
2,2,2,2,2,2,2,7,7,7,2,7,7,7,2,2,2,2,2,2,2
2,2,2,2,2,2,2,2,2,8,7,8,2,2,2,2,2,2,2,2,2
2,2,2,2,2,2,2,2,2,2,7,2,2,2,2,2,2,2,2,2,2
2,2,2,2,2,2,2,2,2,2,7,2,2,2,2,2,2,2,2,2,2
2,2,2,2,3,3,3,2,2,2,2,2,2,2,5,3,3,2,2,2,2
2,2,2,5,0,0,4,2,2,2,2,2,2,2,5,0,0,4,2,2,2
2,2,2,5,0,0,4,2,2,2,2,2,2,2,5,0,0,4,2,2,2
2,2,2,2,6,6,2,2,2,2,2,2,2,2,2,6,6,2,2,2,2
2,2,2,2,2,2,2,2,2,2,2,2,2,2,2,2,2,2,2,2,2
2,2,2,2,2,2,2,2,2,2,2,2,2,2,2,2,2,2,2,2,2
2,2,2,2,2,2,2,2,2,2,2,2,2,2,2,2,2,2,2,2,2
endlayer

layer
9,9,9,9,9,9,9,2,9,6,6,6,9,2,9,9,9,9,9,9,9
9,8,8,8,8,8,8,2,2,2,2,2,2,2,8,8,8,8,8,8,9
9,8,8,2,2,2,2,2,2,2,2,2,2,2,2,2,2,2,8,8,9
9,8,2,9,0,0,0,10,6,2,2,2,6,10,0,0,0,9,2,8,9
9,8,2,0,0,0,0,3,11,2,2,2,11,3,0,0,0,0,2,8,9
9,8,2,0,0,0,0,0,4,2,2,2,5,0,0,0,0,0,2,8,9
9,8,2,0,0,0,0,0,3,3,3,3,5,0,0,0,0,0,2,8,9
2,2,2,13,5,0,0,0,0,0,0,0,0,0,0,0,4,12,2,2,2
9,2,2,4,12,6,6,0,0,0,0,0,0,0,4,6,13,5,2,2,9
4,2,2,2,2,2,5,0,0,0,0,0,0,0,4,2,2,2,2,2,5
4,2,2,2,2,2,5,0,0,0,0,0,0,0,4,2,2,2,2,2,5
4,2,2,2,2,2,5,0,0,0,0,0,0,0,4,2,2,2,2,2,5
9,2,2,4,12,3,5,0,0,0,0,0,0,0,3,3,13,5,2,2,9
2,2,2,13,5,0,0,0,0,0,0,0,0,0,0,0,4,12,2,2,2
9,8,2,0,0,0,0,0,4,6,6,6,6,0,0,0,0,0,2,8,9
9,8,2,0,0,0,0,0,4,2,2,2,5,0,0,0,0,0,2,8,9
9,8,2,0,0,0,0,6,10,2,2,2,10,6,0,0,0,0,2,8,9
9,8,2,9,0,0,0,11,3,2,2,2,3,11,0,0,0,9,2,8,9
9,8,8,2,2,2,2,2,2,2,2,2,2,2,2,2,2,2,8,8,9
9,8,8,8,8,8,8,2,2,2,2,2,2,2,8,8,8,8,8,8,9
9,9,9,9,9,9,9,2,9,3,3,3,9,2,9,9,9,9,9,9,9
endlayer

layer
9,5,1,1,1,1,1,2,9,1,1,1,9,2,1,1,1,1,1,4,9
3,2,13,4,14,4,13,2,9,6,6,6,9,2,12,5,14,5,12,2,3
1,10,8,8,7,8,15,2,2,2,2,2,2,2,15,8,7,8,8,10,1
1,6,8,9,0,0,0,4,12,2,2,2,13,5,0,0,0,9,8,6,1
1,14,7,0,0,0,0,0,4,2,2,2,5,0,0,0,0,0,7,14,1
1,6,8,0,0,0,0,0,0,4,3,5,0,0,0,0,0,0,8,6,1
1,10,15,0,0,0,0,0,0,0,0,0,0,0,0,0,0,0,15,10,1
2,2,2,6,0,0,0,0,0,0,0,0,0,0,0,0,0,6,2,2,2
9,9,2,11,6,0,0,0,0,0,0,0,0,0,0,0,6,11,2,9,9
1,4,2,2,2,6,0,0,0,0,0,0,0,0,0,6,2,2,2,5,1
1,4,2,2,2,5,0,0,0,0,0,0,0,0,0,4,2,2,2,5,1
1,4,2,2,2,3,0,0,0,0,0,0,0,0,0,3,2,2,2,5,1
9,9,2,10,3,0,0,0,0,0,0,0,0,0,0,0,3,10,2,9,9
2,2,2,3,0,0,0,0,0,0,0,0,0,0,0,0,0,3,2,2,2
1,11,15,0,0,0,0,0,0,0,0,0,0,0,0,0,0,0,15,11,1
1,3,8,0,0,0,0,0,0,4,6,5,0,0,0,0,0,0,8,3,1
1,14,7,0,0,0,0,0,4,2,2,2,5,0,0,0,0,0,7,14,1
1,3,8,9,0,0,0,4,12,2,2,2,13,5,0,0,0,9,8,3,1
1,11,8,8,7,8,15,2,2,2,2,2,2,2,15,8,7,8,8,11,1
6,2,13,4,14,4,13,2,9,3,3,3,9,2,12,5,14,5,12,2,6
9,5,1,1,1,1,1,2,9,1,1,1,9,2,1,1,1,1,1,4,9
endlayer

layer
16,1,1,1,1,1,1,2,9,1,1,1,9,2,1,1,1,1,1,1,16
1,2,14,4,13,17,13,2,9,1,1,1,9,2,12,17,12,5,14,2,1
1,14,8,8,15,8,8,2,2,6,6,6,2,2,8,8,15,8,8,14,1
1,6,8,16,0,0,0,11,16,2,2,2,16,11,0,0,0,16,8,6,1
1,10,15,0,0,0,0,0,11,3,3,3,11,0,0,0,0,0,15,10,1
1,17,8,0,0,0,0,0,0,0,0,0,0,0,0,0,0,0,8,17,1
1,10,8,0,0,0,0,0,0,0,0,0,0,0,0,0,0,0,8,10,1
2,2,2,12,0,0,0,0,0,0,0,0,0,0,0,0,0,13,2,2,2
9,9,2,16,12,0,0,0,0,0,0,0,0,0,0,0,13,16,2,9,9
1,1,4,2,5,0,0,0,0,0,0,0,0,0,0,0,4,2,5,1,1
1,1,4,2,5,0,0,0,0,0,0,0,0,0,0,0,4,2,5,1,1
1,1,4,2,5,0,0,0,0,0,0,0,0,0,0,0,4,2,5,1,1
9,9,2,16,12,0,0,0,0,0,0,0,0,0,0,0,13,16,2,9,9
2,2,2,12,0,0,0,0,0,0,0,0,0,0,0,0,0,13,2,2,2
1,11,8,0,0,0,0,0,0,0,0,0,0,0,0,0,0,0,8,11,1
1,17,8,0,0,0,0,0,0,0,0,0,0,0,0,0,0,0,8,17,1
1,11,15,0,0,0,0,0,10,6,6,6,10,0,0,0,0,0,15,11,1
1,3,8,16,0,0,0,10,16,2,2,2,16,10,0,0,0,16,8,3,1
1,14,8,8,15,8,8,2,2,3,3,3,2,2,8,8,15,8,8,14,1
1,2,14,4,13,17,13,2,9,1,1,1,9,2,12,17,12,5,14,2,1
16,1,1,1,1,1,1,2,9,1,1,1,9,2,1,1,1,1,1,1,16
endlayer

layer
1,1,1,1,1,1,1,16,9,1,1,1,9,16,1,1,1,1,1,1,1
1,9,9,9,9,9,9,2,5,1,1,1,4,2,9,9,9,9,9,9,1
1,9,8,8,8,8,8,2,6,1,1,1,6,2,8,8,8,8,8,9,1
1,9,8,8,12,11,13,4,12,0,0,0,13,5,12,11,13,8,8,9,1
1,9,8,11,11,0,0,13,17,0,0,0,17,12,0,0,13,11,8,9,1
1,9,8,12,0,0,0,0,0,0,0,0,0,0,0,0,0,13,8,9,1
1,9,8,10,0,0,0,0,0,0,0,0,0,0,0,0,0,10,8,9,1
16,2,2,6,10,0,0,0,0,0,0,0,0,0,0,0,10,6,2,2,16
9,3,4,11,17,0,0,0,0,0,0,0,0,0,0,0,17,11,5,3,9
1,1,1,0,0,0,0,0,0,0,0,0,0,0,0,0,0,0,1,1,1
1,1,1,0,0,0,0,0,0,0,0,0,0,0,0,0,0,0,1,1,1
1,1,1,0,0,0,0,0,0,0,0,0,0,0,0,0,0,0,1,1,1
9,6,4,10,17,0,0,0,0,0,0,0,0,0,0,0,17,10,5,6,9
16,2,2,3,11,0,0,0,0,0,0,0,0,0,0,0,11,3,2,2,16
1,9,8,11,0,0,0,0,0,0,0,0,0,0,0,0,0,11,8,9,1
1,9,8,12,0,0,0,0,0,0,0,0,0,0,0,0,0,13,8,9,1
1,9,8,10,12,0,0,13,17,0,0,0,17,12,0,0,10,10,8,9,1
1,9,8,8,12,10,13,4,12,0,0,0,13,5,12,10,13,8,8,9,1
1,9,8,8,8,8,8,2,3,1,1,1,3,2,8,8,8,8,8,9,1
1,9,9,9,9,9,9,2,5,1,1,1,4,2,9,9,9,9,9,9,1
1,1,1,1,1,1,1,16,9,1,1,1,9,16,1,1,1,1,1,1,1
endlayer

layer
1,1,1,1,1,1,1,2,9,1,1,1,9,2,1,1,1,1,1,1,1
1,9,5,1,1,1,1,17,11,1,1,1,11,17,1,1,1,1,4,9,1
1,3,2,13,17,13,4,2,0,0,0,0,0,2,5,12,17,12,2,3,1
1,1,10,8,8,8,15,3,6,0,0,0,6,3,15,8,8,8,10,1,1
1,1,17,8,9,3,17,0,11,0,0,0,11,0,17,3,9,8,17,1,1
1,1,10,8,5,0,0,0,0,0,0,0,0,0,0,0,4,8,10,1,1
1,1,6,15,17,0,0,0,0,0,0,0,0,0,0,0,17,15,6,1,1
2,17,2,5,0,0,0,0,0,0,0,0,0,0,0,0,0,4,2,17,2
9,12,0,4,12,0,0,0,0,0,0,0,0,0,0,0,13,5,0,13,9
1,1,0,0,0,0,0,0,0,0,0,0,0,0,0,0,0,0,0,1,1
1,1,0,0,0,0,0,0,0,0,0,0,0,0,0,0,0,0,0,1,1
1,1,0,0,0,0,0,0,0,0,0,0,0,0,0,0,0,0,0,1,1
9,12,0,4,12,0,0,0,0,0,0,0,0,0,0,0,13,5,0,13,9
2,17,2,5,0,0,0,0,0,0,0,0,0,0,0,0,0,4,2,17,2
1,1,3,15,17,0,0,0,0,0,0,0,0,0,0,0,17,15,3,1,1
1,1,11,8,5,0,0,0,0,0,0,0,0,0,0,0,4,8,11,1,1
1,1,17,8,9,6,17,0,10,0,0,0,10,0,17,6,9,8,17,1,1
1,1,11,8,8,8,15,6,3,0,0,0,3,6,15,8,8,8,11,1,1
1,6,2,13,17,13,4,2,0,0,0,0,0,2,5,12,17,12,2,6,1
1,9,5,1,1,1,1,17,10,1,1,1,10,17,1,1,1,1,4,9,1
1,1,1,1,1,1,1,2,9,1,1,1,9,2,1,1,1,1,1,1,1
endlayer

layer
1,1,1,1,1,1,1,1,9,1,1,1,9,1,1,1,1,1,1,1,1
1,16,1,1,1,1,1,17,5,0,0,0,4,17,1,1,1,1,1,16,1
1,1,2,13,4,14,4,2,0,0,0,0,0,2,5,14,5,12,2,1,1
1,1,10,8,15,7,8,4,12,0,0,0,13,5,8,7,15,8,10,1,1
1,1,6,15,17,0,0,13,5,0,0,0,4,12,0,0,17,15,6,1,1
1,1,14,7,0,0,0,0,0,0,0,0,0,0,0,0,0,7,14,1,1
1,1,6,8,0,0,0,0,0,0,0,0,0,0,0,0,0,8,6,1,1
1,17,2,6,10,0,0,0,0,0,0,0,0,0,0,0,10,6,2,17,1
9,3,0,11,3,0,0,0,0,0,0,0,0,0,0,0,3,11,0,3,9
1,0,0,0,0,0,0,0,0,0,0,0,0,0,0,0,0,0,0,0,1
1,0,0,0,0,0,0,0,0,0,0,0,0,0,0,0,0,0,0,0,1
1,0,0,0,0,0,0,0,0,0,0,0,0,0,0,0,0,0,0,0,1
9,6,0,10,6,0,0,0,0,0,0,0,0,0,0,0,6,10,0,6,9
1,17,2,3,11,0,0,0,0,0,0,0,0,0,0,0,11,3,2,17,1
1,1,3,8,0,0,0,0,0,0,0,0,0,0,0,0,0,8,3,1,1
1,1,14,7,0,0,0,0,0,0,0,0,0,0,0,0,0,7,14,1,1
1,1,3,15,17,0,0,13,5,0,0,0,4,12,0,0,17,15,3,1,1
1,1,11,8,15,7,8,4,12,0,0,0,13,5,8,7,15,8,11,1,1
1,1,2,13,4,14,4,2,0,0,0,0,0,2,5,14,5,12,2,1,1
1,16,1,1,1,1,1,17,5,0,0,0,4,17,1,1,1,1,1,16,1
1,1,1,1,1,1,1,1,9,1,1,1,9,1,1,1,1,1,1,1,1
endlayer

layer
1,1,1,1,1,1,1,1,9,1,1,1,9,1,1,1,1,1,1,1,1
1,1,1,1,1,1,1,17,11,0,0,0,11,17,1,1,1,1,1,1,1
1,1,9,9,9,9,9,2,0,0,0,0,0,2,9,9,9,9,9,1,1
1,1,9,8,8,8,8,10,6,0,0,0,6,10,8,8,8,8,9,1,1
1,1,9,8,8,11,13,3,11,0,0,0,11,3,12,11,8,8,9,1,1
1,1,9,8,12,0,0,0,0,0,0,0,0,0,0,0,13,8,9,1,1
1,1,9,8,10,0,0,0,0,0,0,0,0,0,0,0,10,8,9,1,1
1,17,2,13,5,0,0,0,0,0,0,0,0,0,0,0,4,12,2,17,1
9,12,0,4,12,0,0,0,0,0,0,0,0,0,0,0,13,5,0,13,9
1,0,0,0,0,0,0,0,0,0,0,0,0,0,0,0,0,0,0,0,1
1,0,0,0,0,0,0,0,0,0,0,0,0,0,0,0,0,0,0,0,1
1,0,0,0,0,0,0,0,0,0,0,0,0,0,0,0,0,0,0,0,1
9,12,0,4,12,0,0,0,0,0,0,0,0,0,0,0,13,5,0,13,9
1,17,2,13,5,0,0,0,0,0,0,0,0,0,0,0,4,12,2,17,1
1,1,9,8,11,0,0,0,0,0,0,0,0,0,0,0,11,8,9,1,1
1,1,9,8,12,0,0,0,0,0,0,0,0,0,0,0,13,8,9,1,1
1,1,9,8,8,10,13,6,10,0,0,0,10,6,12,10,8,8,9,1,1
1,1,9,8,8,8,8,11,3,0,0,0,3,11,8,8,8,8,9,1,1
1,1,9,9,9,9,9,2,0,0,0,0,0,2,9,9,9,9,9,1,1
1,1,1,1,1,1,1,17,10,0,0,0,10,17,1,1,1,1,1,1,1
1,1,1,1,1,1,1,1,9,1,1,1,9,1,1,1,1,1,1,1,1
endlayer

layer
1,1,1,1,1,1,1,1,9,1,1,1,9,1,1,1,1,1,1,1,1
1,1,1,1,1,1,1,1,5,0,0,0,4,1,1,1,1,1,1,1,1
1,1,9,5,1,1,1,2,0,0,0,0,0,2,1,1,1,4,9,1,1
1,1,3,2,14,4,13,4,12,0,0,0,13,5,12,5,14,2,3,1,1
1,1,1,14,8,15,8,13,5,0,0,0,4,12,8,15,8,14,1,1,1
1,1,1,6,15,14,0,0,0,0,0,0,0,0,0,14,15,6,1,1,1
1,1,1,10,8,0,0,0,0,0,0,0,0,0,0,0,8,10,1,1,1
1,1,2,6,10,0,0,0,0,0,0,0,0,0,0,0,10,6,2,1,1
9,3,0,11,3,0,0,0,0,0,0,0,0,0,0,0,3,11,0,3,9
1,0,0,0,0,0,0,0,0,0,0,0,0,0,0,0,0,0,0,0,1
1,0,0,0,0,0,0,0,0,0,0,0,0,0,0,0,0,0,0,0,1
1,0,0,0,0,0,0,0,0,0,0,0,0,0,0,0,0,0,0,0,1
9,6,0,10,6,0,0,0,0,0,0,0,0,0,0,0,6,10,0,6,9
1,1,2,3,11,0,0,0,0,0,0,0,0,0,0,0,11,3,2,1,1
1,1,1,11,8,0,0,0,0,0,0,0,0,0,0,0,8,11,1,1,1
1,1,1,3,15,14,0,0,0,0,0,0,0,0,0,14,15,3,1,1,1
1,1,1,14,8,15,8,13,5,0,0,0,4,12,8,15,8,14,1,1,1
1,1,6,2,14,4,13,4,12,0,0,0,13,5,12,5,14,2,6,1,1
1,1,9,5,1,1,1,2,0,0,0,0,0,2,1,1,1,4,9,1,1
1,1,1,1,1,1,1,1,5,0,0,0,4,1,1,1,1,1,1,1,1
1,1,1,1,1,1,1,1,9,1,1,1,9,1,1,1,1,1,1,1,1
endlayer

layer
1,1,1,1,1,1,1,17,2,10,10,10,2,17,1,1,1,1,1,1,1
1,1,1,1,1,1,1,17,11,0,0,0,11,17,1,1,1,1,1,1,1
1,1,16,1,1,1,1,2,0,0,0,0,0,2,1,1,1,1,16,1,1
1,1,1,2,13,17,13,2,6,0,0,0,6,2,12,17,12,2,1,1,1
1,1,1,10,8,8,15,3,11,0,0,0,11,3,8,8,8,10,1,1,1
1,1,1,17,8,9,5,0,0,0,0,0,0,0,4,9,8,17,1,1,1
1,1,1,10,15,3,0,0,0,0,0,0,0,0,0,3,8,10,1,1,1
17,17,2,2,5,0,0,0,0,0,0,0,0,0,0,0,4,2,2,17,17
2,12,0,4,12,0,0,0,0,0,0,0,0,0,0,0,13,5,0,13,2
13,0,0,0,0,0,0,0,0,0,0,0,0,0,0,0,0,0,0,0,12
13,0,0,0,0,0,0,0,0,0,0,0,0,0,0,0,0,0,0,0,12
13,0,0,0,0,0,0,0,0,0,0,0,0,0,0,0,0,0,0,0,12
2,12,0,4,12,0,0,0,0,0,0,0,0,0,0,0,13,5,0,13,2
17,17,2,2,5,0,0,0,0,0,0,0,0,0,0,0,4,2,2,17,17
1,1,1,11,8,6,0,0,0,0,0,0,0,0,0,6,8,11,1,1,1
1,1,1,17,8,9,5,0,0,0,0,0,0,0,4,9,8,17,1,1,1
1,1,1,11,8,8,8,6,10,0,0,0,10,6,8,8,8,11,1,1,1
1,1,1,2,13,17,13,2,3,0,0,0,3,2,12,17,12,2,1,1,1
1,1,16,1,1,1,1,2,0,0,0,0,0,2,1,1,1,1,16,1,1
1,1,1,1,1,1,1,17,10,0,0,0,10,17,1,1,1,1,1,1,1
1,1,1,1,1,1,1,17,2,11,11,11,2,17,1,1,1,1,1,1,1
endlayer

layer
1,1,1,1,1,1,1,17,2,2,16,2,2,17,1,1,1,1,1,1,1
1,1,1,1,1,1,14,14,2,18,18,18,2,14,14,1,1,1,1,1,1
1,1,1,1,1,1,14,2,2,18,18,18,2,2,14,1,1,1,1,1,1
1,1,1,9,9,9,2,2,2,9,16,9,2,2,2,9,9,9,1,1,1
1,1,1,9,8,8,8,13,16,0,0,0,16,12,15,8,8,9,1,1,1
1,1,1,9,8,7,14,0,11,0,0,0,11,0,14,7,8,9,1,1,1
1,14,14,2,8,14,0,0,14,0,0,0,14,0,0,14,15,2,14,14,1
17,14,2,2,10,0,0,0,0,0,0,0,0,0,0,0,10,2,2,14,17
2,2,2,2,16,12,14,0,0,0,0,0,0,0,14,13,16,2,2,2,2
2,20,20,9,0,0,0,0,0,0,0,0,0,0,0,0,0,9,19,19,2
16,20,20,16,0,0,0,0,0,0,0,0,0,0,0,0,0,16,19,19,16
2,20,20,9,0,0,0,0,0,0,0,0,0,0,0,0,0,9,19,19,2
2,2,2,2,16,12,14,0,0,0,0,0,0,0,14,13,16,2,2,2,2
17,14,2,2,11,0,0,0,0,0,0,0,0,0,0,0,11,2,2,14,17
1,14,14,2,15,14,0,0,14,0,0,0,14,0,0,14,15,2,14,14,1
1,1,1,9,8,7,14,0,10,0,0,0,10,0,14,7,8,9,1,1,1
1,1,1,9,8,8,15,13,16,0,0,0,16,12,15,8,8,9,1,1,1
1,1,1,9,9,9,2,2,2,9,16,9,2,2,2,9,9,9,1,1,1
1,1,1,1,1,1,14,2,2,21,21,21,2,2,14,1,1,1,1,1,1
1,1,1,1,1,1,14,14,2,21,21,21,2,14,14,1,1,1,1,1,1
1,1,1,1,1,1,1,17,2,2,16,2,2,17,1,1,1,1,1,1,1
endlayer

layer
1,1,1,1,1,1,1,1,1,1,17,1,1,1,1,1,1,1,1,1,1
1,1,1,1,1,1,1,1,2,1,1,1,2,1,1,1,1,1,1,1,1
1,1,1,1,1,1,17,1,1,1,1,1,1,1,17,1,1,1,1,1,1
1,1,1,9,5,1,1,2,2,9,9,9,2,2,1,1,4,9,1,1,1
1,1,1,3,2,4,17,2,2,18,18,18,2,2,17,5,2,3,1,1,1
1,1,1,1,6,8,8,11,2,18,18,18,2,11,8,8,6,1,1,1,1
1,1,17,1,17,8,0,0,2,9,9,9,2,0,0,8,17,1,17,1,1
1,1,1,2,2,12,0,9,11,0,0,0,11,9,0,13,2,2,1,1,1
1,2,1,2,2,2,2,12,0,0,0,0,0,13,2,2,2,2,1,2,1
1,1,1,9,20,20,9,0,0,0,0,0,0,0,9,19,19,9,1,1,1
17,1,1,9,20,20,9,0,0,0,0,0,0,0,9,19,19,9,1,1,17
1,1,1,9,20,20,9,0,0,0,0,0,0,0,9,19,19,9,1,1,1
1,2,1,2,2,2,2,12,0,0,0,0,0,13,2,2,2,2,1,2,1
1,1,1,2,2,12,0,9,10,0,0,0,10,9,0,13,2,2,1,1,1
1,1,17,1,17,8,0,0,2,9,9,9,2,0,0,8,17,1,17,1,1
1,1,1,1,3,8,8,10,2,21,21,21,2,10,8,8,3,1,1,1,1
1,1,1,6,2,4,17,2,2,21,21,21,2,2,17,5,2,6,1,1,1
1,1,1,9,5,1,1,2,2,9,9,9,2,2,1,1,4,9,1,1,1
1,1,1,1,1,1,17,1,1,1,1,1,1,1,17,1,1,1,1,1,1
1,1,1,1,1,1,1,1,2,1,1,1,2,1,1,1,1,1,1,1,1
1,1,1,1,1,1,1,1,1,1,17,1,1,1,1,1,1,1,1,1,1
endlayer

layer
1,1,1,1,1,1,1,1,1,1,1,1,1,1,1,1,1,1,1,1,1
1,1,1,1,1,1,1,1,3,1,1,1,3,1,1,1,1,1,1,1,1
1,1,1,1,1,1,1,1,1,1,1,1,1,1,1,1,1,1,1,1,1
1,1,1,16,1,1,1,17,1,1,1,1,1,17,1,1,1,16,1,1,1
1,1,1,1,2,17,17,2,12,1,1,1,13,2,17,17,2,1,1,1,1
1,1,1,1,17,8,15,0,0,1,1,1,0,0,15,8,17,1,1,1,1
1,1,1,1,17,15,14,0,0,0,0,0,0,0,14,15,17,1,1,1,1
1,1,1,17,2,0,0,2,0,0,0,0,0,2,0,0,2,17,1,1,1
1,5,1,1,11,0,0,0,0,0,0,0,0,0,0,0,11,1,1,4,1
1,1,1,1,1,1,0,0,0,0,0,0,0,0,0,1,1,1,1,1,1
1,1,1,1,1,1,0,0,0,0,0,0,0,0,0,1,1,1,1,1,1
1,1,1,1,1,1,0,0,0,0,0,0,0,0,0,1,1,1,1,1,1
1,5,1,1,10,0,0,0,0,0,0,0,0,0,0,0,10,1,1,4,1
1,1,1,17,2,0,0,2,0,0,0,0,0,2,0,0,2,17,1,1,1
1,1,1,1,17,15,14,0,0,0,0,0,0,0,14,15,17,1,1,1,1
1,1,1,1,17,8,15,0,0,1,1,1,0,0,15,8,17,1,1,1,1
1,1,1,1,2,17,17,2,12,1,1,1,13,2,17,17,2,1,1,1,1
1,1,1,16,1,1,1,17,1,1,1,1,1,17,1,1,1,16,1,1,1
1,1,1,1,1,1,1,1,1,1,1,1,1,1,1,1,1,1,1,1,1
1,1,1,1,1,1,1,1,6,1,1,1,6,1,1,1,1,1,1,1,1
1,1,1,1,1,1,1,1,1,1,1,1,1,1,1,1,1,1,1,1,1
endlayer

layer
1,1,1,1,1,1,1,1,1,1,1,1,1,1,1,1,1,1,1,1,1
1,1,1,1,1,1,1,1,1,1,1,1,1,1,1,1,1,1,1,1,1
1,1,1,1,1,1,1,1,1,1,1,1,1,1,1,1,1,1,1,1,1
1,1,1,1,1,1,1,1,1,1,1,1,1,1,1,1,1,1,1,1,1
1,1,1,1,9,2,2,12,1,1,1,1,1,13,2,2,9,1,1,1,1
1,1,1,1,2,2,8,2,14,1,1,1,14,2,8,2,2,1,1,1,1
1,1,1,1,2,8,8,12,0,0,0,0,0,13,8,8,2,1,1,1,1
1,1,1,1,11,2,11,9,0,0,0,0,0,9,11,2,11,1,1,1,1
1,1,1,1,1,14,0,0,0,0,0,0,0,0,0,14,1,1,1,1,1
1,1,1,1,1,1,0,0,0,0,0,0,0,0,0,1,1,1,1,1,1
1,1,1,1,1,1,0,0,0,0,0,0,0,0,0,1,1,1,1,1,1
1,1,1,1,1,1,0,0,0,0,0,0,0,0,0,1,1,1,1,1,1
1,1,1,1,1,14,0,0,0,0,0,0,0,0,0,14,1,1,1,1,1
1,1,1,1,10,2,10,9,0,0,0,0,0,9,10,2,10,1,1,1,1
1,1,1,1,2,8,8,12,0,0,0,0,0,13,8,8,2,1,1,1,1
1,1,1,1,2,2,8,2,14,1,1,1,14,2,8,2,2,1,1,1,1
1,1,1,1,9,2,2,12,1,1,1,1,1,13,2,2,9,1,1,1,1
1,1,1,1,1,1,1,1,1,1,1,1,1,1,1,1,1,1,1,1,1
1,1,1,1,1,1,1,1,1,1,1,1,1,1,1,1,1,1,1,1,1
1,1,1,1,1,1,1,1,1,1,1,1,1,1,1,1,1,1,1,1,1
1,1,1,1,1,1,1,1,1,1,1,1,1,1,1,1,1,1,1,1,1
endlayer

layer
1,1,1,1,1,1,1,1,1,1,1,1,1,1,1,1,1,1,1,1,1
1,1,1,1,1,1,1,1,1,1,1,1,1,1,1,1,1,1,1,1,1
1,1,1,1,1,1,1,1,1,1,1,1,1,1,1,1,1,1,1,1,1
1,1,1,1,1,1,1,1,1,1,1,1,1,1,1,1,1,1,1,1,1
1,1,1,1,9,5,1,1,1,1,1,1,1,1,1,4,9,1,1,1,1
1,1,1,1,3,2,1,12,1,1,1,1,1,13,1,2,3,1,1,1,1
1,1,1,1,1,1,8,0,0,0,0,0,0,0,8,1,1,1,1,1,1
1,1,1,1,1,11,0,9,0,0,0,0,0,9,0,11,1,1,1,1,1
1,1,1,1,1,1,0,0,0,0,0,0,0,0,0,1,1,1,1,1,1
1,1,1,1,1,1,0,0,0,0,0,0,0,0,0,1,1,1,1,1,1
1,1,1,1,1,1,0,0,0,0,0,0,0,0,0,1,1,1,1,1,1
1,1,1,1,1,1,0,0,0,0,0,0,0,0,0,1,1,1,1,1,1
1,1,1,1,1,1,0,0,0,0,0,0,0,0,0,1,1,1,1,1,1
1,1,1,1,1,10,0,9,0,0,0,0,0,9,0,10,1,1,1,1,1
1,1,1,1,1,1,8,0,0,0,0,0,0,0,8,1,1,1,1,1,1
1,1,1,1,6,2,1,12,1,1,1,1,1,13,1,2,6,1,1,1,1
1,1,1,1,9,5,1,1,1,1,1,1,1,1,1,4,9,1,1,1,1
1,1,1,1,1,1,1,1,1,1,1,1,1,1,1,1,1,1,1,1,1
1,1,1,1,1,1,1,1,1,1,1,1,1,1,1,1,1,1,1,1,1
1,1,1,1,1,1,1,1,1,1,1,1,1,1,1,1,1,1,1,1,1
1,1,1,1,1,1,1,1,1,1,1,1,1,1,1,1,1,1,1,1,1
endlayer

layer
1,1,1,1,1,1,1,1,1,1,1,1,1,1,1,1,1,1,1,1,1
1,1,1,1,1,1,1,1,1,1,1,1,1,1,1,1,1,1,1,1,1
1,1,1,1,1,1,1,1,1,1,1,1,1,1,1,1,1,1,1,1,1
1,1,1,1,1,1,1,1,1,1,1,1,1,1,1,1,1,1,1,1,1
1,1,1,1,16,1,1,1,1,1,1,1,1,1,1,1,16,1,1,1,1
1,1,1,1,1,2,17,12,14,1,1,1,14,13,17,2,1,1,1,1,1
1,1,1,1,1,17,8,0,0,0,0,0,0,0,8,17,1,1,1,1,1
1,1,1,1,1,11,0,9,0,0,0,0,0,9,0,11,1,1,1,1,1
1,1,1,1,1,14,0,0,0,0,0,0,0,0,0,14,1,1,1,1,1
1,1,1,1,1,1,0,0,0,0,0,0,0,0,0,1,1,1,1,1,1
1,1,1,1,1,1,0,0,0,0,0,0,0,0,0,1,1,1,1,1,1
1,1,1,1,1,1,0,0,0,0,0,0,0,0,0,1,1,1,1,1,1
1,1,1,1,1,14,0,0,0,0,0,0,0,0,0,14,1,1,1,1,1
1,1,1,1,1,10,0,9,0,0,0,0,0,9,0,10,1,1,1,1,1
1,1,1,1,1,17,8,0,0,0,0,0,0,0,8,17,1,1,1,1,1
1,1,1,1,1,2,17,12,14,1,1,1,14,13,17,2,1,1,1,1,1
1,1,1,1,16,1,1,1,1,1,1,1,1,1,1,1,16,1,1,1,1
1,1,1,1,1,1,1,1,1,1,1,1,1,1,1,1,1,1,1,1,1
1,1,1,1,1,1,1,1,1,1,1,1,1,1,1,1,1,1,1,1,1
1,1,1,1,1,1,1,1,1,1,1,1,1,1,1,1,1,1,1,1,1
1,1,1,1,1,1,1,1,1,1,1,1,1,1,1,1,1,1,1,1,1
endlayer

layer
1,1,1,1,1,1,1,1,1,1,1,1,1,1,1,1,1,1,1,1,1
1,1,1,1,1,1,1,1,1,1,1,1,1,1,1,1,1,1,1,1,1
1,1,1,1,1,1,1,1,1,1,1,1,1,1,1,1,1,1,1,1,1
1,1,1,1,1,1,1,1,1,1,1,1,1,1,1,1,1,1,1,1,1
1,1,1,1,1,1,1,1,1,1,1,1,1,1,1,1,1,1,1,1,1
1,1,1,1,1,9,2,17,12,1,1,1,13,17,2,9,1,1,1,1,1
1,1,1,1,1,2,2,2,11,0,0,0,11,2,2,2,1,1,1,1,1
1,1,1,1,1,17,2,2,0,0,0,0,0,2,2,17,1,1,1,1,1
1,1,1,1,1,11,12,0,0,0,0,0,0,0,13,11,1,1,1,1,1
1,1,1,1,1,1,0,0,0,0,0,0,0,0,0,1,1,1,1,1,1
1,1,1,1,1,1,0,0,0,0,0,0,0,0,0,1,1,1,1,1,1
1,1,1,1,1,1,0,0,0,0,0,0,0,0,0,1,1,1,1,1,1
1,1,1,1,1,10,12,0,0,0,0,0,0,0,13,10,1,1,1,1,1
1,1,1,1,1,17,2,2,0,0,0,0,0,2,2,17,1,1,1,1,1
1,1,1,1,1,2,2,2,10,0,0,0,10,2,2,2,1,1,1,1,1
1,1,1,1,1,9,2,17,12,1,1,1,13,17,2,9,1,1,1,1,1
1,1,1,1,1,1,1,1,1,1,1,1,1,1,1,1,1,1,1,1,1
1,1,1,1,1,1,1,1,1,1,1,1,1,1,1,1,1,1,1,1,1
1,1,1,1,1,1,1,1,1,1,1,1,1,1,1,1,1,1,1,1,1
1,1,1,1,1,1,1,1,1,1,1,1,1,1,1,1,1,1,1,1,1
1,1,1,1,1,1,1,1,1,1,1,1,1,1,1,1,1,1,1,1,1
endlayer

layer
1,1,1,1,1,1,1,1,1,1,1,1,1,1,1,1,1,1,1,1,1
1,1,1,1,1,1,1,1,1,1,1,1,1,1,1,1,1,1,1,1,1
1,1,1,1,1,1,1,1,1,1,1,1,1,1,1,1,1,1,1,1,1
1,1,1,1,1,1,1,1,1,1,1,1,1,1,1,1,1,1,1,1,1
1,1,1,1,1,1,1,1,1,1,1,1,1,1,1,1,1,1,1,1,1
1,1,1,1,1,9,5,1,1,1,1,1,1,1,4,9,1,1,1,1,1
1,1,1,1,1,3,2,2,2,2,16,2,2,2,2,3,1,1,1,1,1
1,1,1,1,1,1,2,16,14,11,0,11,14,16,2,1,1,1,1,1,1
1,1,1,1,1,1,2,14,0,0,0,0,0,14,2,1,1,1,1,1,1
1,1,1,1,1,1,2,12,0,0,0,0,0,13,2,1,1,1,1,1,1
1,1,1,1,1,1,16,0,0,0,0,0,0,0,16,1,1,1,1,1,1
1,1,1,1,1,1,2,12,0,0,0,0,0,13,2,1,1,1,1,1,1
1,1,1,1,1,1,2,14,0,0,0,0,0,14,2,1,1,1,1,1,1
1,1,1,1,1,1,2,16,14,10,0,10,14,16,2,1,1,1,1,1,1
1,1,1,1,1,6,2,2,2,2,16,2,2,2,2,6,1,1,1,1,1
1,1,1,1,1,9,5,1,1,1,1,1,1,1,4,9,1,1,1,1,1
1,1,1,1,1,1,1,1,1,1,1,1,1,1,1,1,1,1,1,1,1
1,1,1,1,1,1,1,1,1,1,1,1,1,1,1,1,1,1,1,1,1
1,1,1,1,1,1,1,1,1,1,1,1,1,1,1,1,1,1,1,1,1
1,1,1,1,1,1,1,1,1,1,1,1,1,1,1,1,1,1,1,1,1
1,1,1,1,1,1,1,1,1,1,1,1,1,1,1,1,1,1,1,1,1
endlayer

layer
1,1,1,1,1,1,1,1,1,1,1,1,1,1,1,1,1,1,1,1,1
1,1,1,1,1,1,1,1,1,1,1,1,1,1,1,1,1,1,1,1,1
1,1,1,1,1,1,1,1,1,1,1,1,1,1,1,1,1,1,1,1,1
1,1,1,1,1,1,1,1,1,1,1,1,1,1,1,1,1,1,1,1,1
1,1,1,1,1,1,1,1,1,1,1,1,1,1,1,1,1,1,1,1,1
1,1,1,1,1,16,1,1,1,1,1,1,1,1,1,16,1,1,1,1,1
1,1,1,1,1,1,2,1,1,1,1,1,1,1,2,1,1,1,1,1,1
1,1,1,1,1,1,1,1,1,9,1,9,1,1,1,1,1,1,1,1,1
1,1,1,1,1,1,1,1,0,0,0,0,0,1,1,1,1,1,1,1,1
1,1,1,1,1,1,1,9,0,0,0,0,0,9,1,1,1,1,1,1,1
1,1,1,1,1,1,1,1,0,0,0,0,0,1,1,1,1,1,1,1,1
1,1,1,1,1,1,1,9,0,0,0,0,0,9,1,1,1,1,1,1,1
1,1,1,1,1,1,1,1,0,0,0,0,0,1,1,1,1,1,1,1,1
1,1,1,1,1,1,1,1,1,9,1,9,1,1,1,1,1,1,1,1,1
1,1,1,1,1,1,2,1,1,1,1,1,1,1,2,1,1,1,1,1,1
1,1,1,1,1,16,1,1,1,1,1,1,1,1,1,16,1,1,1,1,1
1,1,1,1,1,1,1,1,1,1,1,1,1,1,1,1,1,1,1,1,1
1,1,1,1,1,1,1,1,1,1,1,1,1,1,1,1,1,1,1,1,1
1,1,1,1,1,1,1,1,1,1,1,1,1,1,1,1,1,1,1,1,1
1,1,1,1,1,1,1,1,1,1,1,1,1,1,1,1,1,1,1,1,1
1,1,1,1,1,1,1,1,1,1,1,1,1,1,1,1,1,1,1,1,1
endlayer

layer
1,1,1,1,1,1,1,1,1,1,1,1,1,1,1,1,1,1,1,1,1
1,1,1,1,1,1,1,1,1,1,1,1,1,1,1,1,1,1,1,1,1
1,1,1,1,1,1,1,1,1,1,1,1,1,1,1,1,1,1,1,1,1
1,1,1,1,1,1,1,1,1,1,1,1,1,1,1,1,1,1,1,1,1
1,1,1,1,1,1,1,1,1,1,1,1,1,1,1,1,1,1,1,1,1
1,1,1,1,1,1,1,1,1,1,1,1,1,1,1,1,1,1,1,1,1
1,1,1,1,1,1,9,17,1,1,1,1,1,17,9,1,1,1,1,1,1
1,1,1,1,1,1,17,2,17,9,17,9,17,2,17,1,1,1,1,1,1
1,1,1,1,1,1,1,17,1,11,17,11,1,17,1,1,1,1,1,1,1
1,1,1,1,1,1,1,9,12,0,0,0,13,9,1,1,1,1,1,1,1
1,1,1,1,1,1,1,17,17,0,0,0,17,17,1,1,1,1,1,1,1
1,1,1,1,1,1,1,9,12,0,0,0,13,9,1,1,1,1,1,1,1
1,1,1,1,1,1,1,17,1,10,17,10,1,17,1,1,1,1,1,1,1
1,1,1,1,1,1,17,2,17,9,17,9,17,2,17,1,1,1,1,1,1
1,1,1,1,1,1,9,17,1,1,1,1,1,17,9,1,1,1,1,1,1
1,1,1,1,1,1,1,1,1,1,1,1,1,1,1,1,1,1,1,1,1
1,1,1,1,1,1,1,1,1,1,1,1,1,1,1,1,1,1,1,1,1
1,1,1,1,1,1,1,1,1,1,1,1,1,1,1,1,1,1,1,1,1
1,1,1,1,1,1,1,1,1,1,1,1,1,1,1,1,1,1,1,1,1
1,1,1,1,1,1,1,1,1,1,1,1,1,1,1,1,1,1,1,1,1
1,1,1,1,1,1,1,1,1,1,1,1,1,1,1,1,1,1,1,1,1
endlayer

layer
1,1,1,1,1,1,1,1,1,1,1,1,1,1,1,1,1,1,1,1,1
1,1,1,1,1,1,1,1,1,1,1,1,1,1,1,1,1,1,1,1,1
1,1,1,1,1,1,1,1,1,1,1,1,1,1,1,1,1,1,1,1,1
1,1,1,1,1,1,1,1,1,1,1,1,1,1,1,1,1,1,1,1,1
1,1,1,1,1,1,1,1,1,1,1,1,1,1,1,1,1,1,1,1,1
1,1,1,1,1,1,1,1,1,1,1,1,1,1,1,1,1,1,1,1,1
1,1,1,1,1,1,9,5,1,1,1,1,1,4,9,1,1,1,1,1,1
1,1,1,1,1,1,3,2,1,16,17,16,1,2,3,1,1,1,1,1,1
1,1,1,1,1,1,1,1,14,2,17,2,14,1,1,1,1,1,1,1,1
1,1,1,1,1,1,1,16,2,1,1,1,2,16,1,1,1,1,1,1,1
1,1,1,1,1,1,1,17,17,1,1,1,17,17,1,1,1,1,1,1,1
1,1,1,1,1,1,1,16,2,1,1,1,2,16,1,1,1,1,1,1,1
1,1,1,1,1,1,1,1,14,2,17,2,14,1,1,1,1,1,1,1,1
1,1,1,1,1,1,6,2,1,16,17,16,1,2,6,1,1,1,1,1,1
1,1,1,1,1,1,9,5,1,1,1,1,1,4,9,1,1,1,1,1,1
1,1,1,1,1,1,1,1,1,1,1,1,1,1,1,1,1,1,1,1,1
1,1,1,1,1,1,1,1,1,1,1,1,1,1,1,1,1,1,1,1,1
1,1,1,1,1,1,1,1,1,1,1,1,1,1,1,1,1,1,1,1,1
1,1,1,1,1,1,1,1,1,1,1,1,1,1,1,1,1,1,1,1,1
1,1,1,1,1,1,1,1,1,1,1,1,1,1,1,1,1,1,1,1,1
1,1,1,1,1,1,1,1,1,1,1,1,1,1,1,1,1,1,1,1,1
endlayer

layer
1,1,1,1,1,1,1,1,1,1,1,1,1,1,1,1,1,1,1,1,1
1,1,1,1,1,1,1,1,1,1,1,1,1,1,1,1,1,1,1,1,1
1,1,1,1,1,1,1,1,1,1,1,1,1,1,1,1,1,1,1,1,1
1,1,1,1,1,1,1,1,1,1,1,1,1,1,1,1,1,1,1,1,1
1,1,1,1,1,1,1,1,1,1,1,1,1,1,1,1,1,1,1,1,1
1,1,1,1,1,1,1,1,1,1,1,1,1,1,1,1,1,1,1,1,1
1,1,1,1,1,1,16,1,1,1,1,1,1,1,16,1,1,1,1,1,1
1,1,1,1,1,1,1,2,14,2,10,2,14,2,1,1,1,1,1,1,1
1,1,1,1,1,1,1,14,1,17,1,17,1,14,1,1,1,1,1,1,1
1,1,1,1,1,1,1,2,17,1,1,1,17,2,1,1,1,1,1,1,1
1,1,1,1,1,1,1,13,1,1,1,1,1,12,1,1,1,1,1,1,1
1,1,1,1,1,1,1,2,17,1,1,1,17,2,1,1,1,1,1,1,1
1,1,1,1,1,1,1,14,1,17,1,17,1,14,1,1,1,1,1,1,1
1,1,1,1,1,1,1,2,14,2,11,2,14,2,1,1,1,1,1,1,1
1,1,1,1,1,1,16,1,1,1,1,1,1,1,16,1,1,1,1,1,1
1,1,1,1,1,1,1,1,1,1,1,1,1,1,1,1,1,1,1,1,1
1,1,1,1,1,1,1,1,1,1,1,1,1,1,1,1,1,1,1,1,1
1,1,1,1,1,1,1,1,1,1,1,1,1,1,1,1,1,1,1,1,1
1,1,1,1,1,1,1,1,1,1,1,1,1,1,1,1,1,1,1,1,1
1,1,1,1,1,1,1,1,1,1,1,1,1,1,1,1,1,1,1,1,1
1,1,1,1,1,1,1,1,1,1,1,1,1,1,1,1,1,1,1,1,1
endlayer

layer
1,1,1,1,1,1,1,1,1,1,1,1,1,1,1,1,1,1,1,1,1
1,1,1,1,1,1,1,1,1,1,1,1,1,1,1,1,1,1,1,1,1
1,1,1,1,1,1,1,1,1,1,1,1,1,1,1,1,1,1,1,1,1
1,1,1,1,1,1,1,1,1,1,1,1,1,1,1,1,1,1,1,1,1
1,1,1,1,1,1,1,1,1,1,1,1,1,1,1,1,1,1,1,1,1
1,1,1,1,1,1,1,1,1,1,1,1,1,1,1,1,1,1,1,1,1
1,1,1,1,1,1,1,1,1,1,1,1,1,1,1,1,1,1,1,1,1
1,1,1,1,1,1,1,9,17,9,14,9,17,9,1,1,1,1,1,1,1
1,1,1,1,1,1,1,17,1,1,1,1,1,17,1,1,1,1,1,1,1
1,1,1,1,1,1,1,9,1,1,1,1,1,9,1,1,1,1,1,1,1
1,1,1,1,1,1,1,14,1,1,1,1,1,14,1,1,1,1,1,1,1
1,1,1,1,1,1,1,9,1,1,1,1,1,9,1,1,1,1,1,1,1
1,1,1,1,1,1,1,17,1,1,1,1,1,17,1,1,1,1,1,1,1
1,1,1,1,1,1,1,9,17,9,14,9,17,9,1,1,1,1,1,1,1
1,1,1,1,1,1,1,1,1,1,1,1,1,1,1,1,1,1,1,1,1
1,1,1,1,1,1,1,1,1,1,1,1,1,1,1,1,1,1,1,1,1
1,1,1,1,1,1,1,1,1,1,1,1,1,1,1,1,1,1,1,1,1
1,1,1,1,1,1,1,1,1,1,1,1,1,1,1,1,1,1,1,1,1
1,1,1,1,1,1,1,1,1,1,1,1,1,1,1,1,1,1,1,1,1
1,1,1,1,1,1,1,1,1,1,1,1,1,1,1,1,1,1,1,1,1
1,1,1,1,1,1,1,1,1,1,1,1,1,1,1,1,1,1,1,1,1
endlayer

layer
1,1,1,1,1,1,1,1,1,1,1,1,1,1,1,1,1,1,1,1,1
1,1,1,1,1,1,1,1,1,1,1,1,1,1,1,1,1,1,1,1,1
1,1,1,1,1,1,1,1,1,1,1,1,1,1,1,1,1,1,1,1,1
1,1,1,1,1,1,1,1,1,1,1,1,1,1,1,1,1,1,1,1,1
1,1,1,1,1,1,1,1,1,1,1,1,1,1,1,1,1,1,1,1,1
1,1,1,1,1,1,1,1,1,1,1,1,1,1,1,1,1,1,1,1,1
1,1,1,1,1,1,1,1,1,1,1,1,1,1,1,1,1,1,1,1,1
1,1,1,1,1,1,1,9,1,16,1,16,1,9,1,1,1,1,1,1,1
1,1,1,1,1,1,1,1,1,1,1,1,1,1,1,1,1,1,1,1,1
1,1,1,1,1,1,1,16,1,1,1,1,1,16,1,1,1,1,1,1,1
1,1,1,1,1,1,1,1,1,1,1,1,1,1,1,1,1,1,1,1,1
1,1,1,1,1,1,1,16,1,1,1,1,1,16,1,1,1,1,1,1,1
1,1,1,1,1,1,1,1,1,1,1,1,1,1,1,1,1,1,1,1,1
1,1,1,1,1,1,1,9,1,16,1,16,1,9,1,1,1,1,1,1,1
1,1,1,1,1,1,1,1,1,1,1,1,1,1,1,1,1,1,1,1,1
1,1,1,1,1,1,1,1,1,1,1,1,1,1,1,1,1,1,1,1,1
1,1,1,1,1,1,1,1,1,1,1,1,1,1,1,1,1,1,1,1,1
1,1,1,1,1,1,1,1,1,1,1,1,1,1,1,1,1,1,1,1,1
1,1,1,1,1,1,1,1,1,1,1,1,1,1,1,1,1,1,1,1,1
1,1,1,1,1,1,1,1,1,1,1,1,1,1,1,1,1,1,1,1,1
1,1,1,1,1,1,1,1,1,1,1,1,1,1,1,1,1,1,1,1,1
endlayer

layer
1,1,1,1,1,1,1,1,1,1,1,1,1,1,1,1,1,1,1,1,1
1,1,1,1,1,1,1,1,1,1,1,1,1,1,1,1,1,1,1,1,1
1,1,1,1,1,1,1,1,1,1,1,1,1,1,1,1,1,1,1,1,1
1,1,1,1,1,1,1,1,1,1,1,1,1,1,1,1,1,1,1,1,1
1,1,1,1,1,1,1,1,1,1,1,1,1,1,1,1,1,1,1,1,1
1,1,1,1,1,1,1,1,1,1,1,1,1,1,1,1,1,1,1,1,1
1,1,1,1,1,1,1,1,1,1,1,1,1,1,1,1,1,1,1,1,1
1,1,1,1,1,1,1,2,1,1,1,1,1,2,1,1,1,1,1,1,1
1,1,1,1,1,1,1,1,1,1,1,1,1,1,1,1,1,1,1,1,1
1,1,1,1,1,1,1,1,1,1,1,1,1,1,1,1,1,1,1,1,1
1,1,1,1,1,1,1,1,1,1,1,1,1,1,1,1,1,1,1,1,1
1,1,1,1,1,1,1,1,1,1,1,1,1,1,1,1,1,1,1,1,1
1,1,1,1,1,1,1,1,1,1,1,1,1,1,1,1,1,1,1,1,1
1,1,1,1,1,1,1,2,1,1,1,1,1,2,1,1,1,1,1,1,1
1,1,1,1,1,1,1,1,1,1,1,1,1,1,1,1,1,1,1,1,1
1,1,1,1,1,1,1,1,1,1,1,1,1,1,1,1,1,1,1,1,1
1,1,1,1,1,1,1,1,1,1,1,1,1,1,1,1,1,1,1,1,1
1,1,1,1,1,1,1,1,1,1,1,1,1,1,1,1,1,1,1,1,1
1,1,1,1,1,1,1,1,1,1,1,1,1,1,1,1,1,1,1,1,1
1,1,1,1,1,1,1,1,1,1,1,1,1,1,1,1,1,1,1,1,1
1,1,1,1,1,1,1,1,1,1,1,1,1,1,1,1,1,1,1,1,1
endlayer

