
# Created by Ruins mod version 17.1 Ingame Parser
# authoring Player: ST753M

weight=3
embed_into_distance=4
acceptable_target_blocks=
unacceptable_target_blocks=bedrock,netherrack,nether_brick,nether_brick_fence,soul_sand,quartz_ore,end_stone,obsidian,iron_bars,Natura:Cloud,slime_grass,slime_congealed,slime_dirt,clouds,natura:clouds,twilightforest:wispy_cloud,twilightforest:fluffy_cloud
dimensions=13,13,13
allowable_overhang=3
max_leveling=0
leveling_buffer=0
preserve_water=0
preserve_lava=0

biomesToSpawnIn=wetland,overgrown_greens

=0,100,preserveBlock
rule1=0,100,biomesoplenty:log_2-5
rule2=0,100,biomesoplenty:willow_stairs-4
rule3=0,100,biomesoplenty:willow_stairs-6
rule4=0,100,biomesoplenty:willow_stairs-7
rule5=0,100,biomesoplenty:wood_slab_1-9
rule6=0,100,biomesoplenty:willow_stairs-5
rule7=0,100,biomesoplenty:wood_slab_1-1
rule8=0,100,biomesoplenty:willow_stairs-2
rule9=0,100,biomesoplenty:planks_0-9
rule10=0,100,biomesoplenty:willow_vine-8
rule11=0,100,biomesoplenty:log_2-9
rule12=0,100,biomesoplenty:log_2-1
rule13=0,100,biomesoplenty:willow_stairs-0
rule14=0,100,biomesoplenty:willow_vine-1
rule15=0,100,biomesoplenty:planks_0-14
rule16=0,100,biomesoplenty:willow_door_block-2
rule17=0,100,biomesoplenty:willow_fence-0
rule18=0,20,ChestGenHook:chests/jungle_temple:2-2
rule19=0,100,teBlock;minecraft:bed;{color:13,x:-3505,y:93,z:-1540,id:"minecraft:bed"}-0
rule20=0,100,teBlock;minecraft:bed;{color:13,x:-3505,y:93,z:-1539,id:"minecraft:bed"}-8
rule21=0,50,ChestGenHook:chests/spawn_bonus_chest:5-4
rule22=0,100,biomesoplenty:willow_vine-4
rule23=0,100,biomesoplenty:willow_vine-2
rule24=0,100,biomesoplenty:willow_door_block-9
rule25=0,100,biomesoplenty:willow_door_block-8
rule26=0,100,minecraft:stained_glass_pane-13,preserveBlock
rule27=0,100,minecraft:carpet-13
rule28=0,100,minecraft:web-0
rule29=0,100,biomesoplenty:willow_stairs-3
rule30=0,100,biomesoplenty:double_wood_slab_1-1
rule31=0,100,biomesoplenty:willow_stairs-1
rule32=0,60,MobSpawner:spider,MobSpawner:witch,MobSpawner:cave_spider,MobSpawner:witch

layer
0,0,0,0,0,0,0,0,0,0,0,0,0
0,1,0,0,0,0,1,0,0,0,0,1,0
0,0,0,0,0,0,0,0,0,0,0,0,0
0,0,0,0,0,0,0,0,0,0,0,0,0
0,0,0,0,0,0,0,0,0,0,0,0,0
0,0,0,0,0,0,0,0,0,0,0,0,0
0,1,0,0,0,0,0,0,0,0,0,1,0
0,0,0,0,0,0,0,0,0,0,0,0,0
0,0,0,0,0,0,0,0,0,0,0,0,0
0,0,0,0,0,0,0,0,0,0,0,0,0
0,0,0,0,0,0,0,0,0,0,0,0,0
0,1,0,0,0,0,1,0,0,0,0,1,0
0,0,0,0,0,0,0,0,0,0,0,0,0
endlayer

layer
0,0,0,0,0,0,0,0,0,0,0,0,0
0,1,0,0,0,0,1,0,0,0,0,1,0
0,0,0,0,0,0,0,0,0,0,0,0,0
0,0,0,0,0,0,0,0,0,0,0,0,0
0,0,0,0,0,0,0,0,0,0,0,0,0
0,0,0,0,0,0,0,0,0,0,0,0,0
0,1,0,0,0,0,0,0,0,0,0,1,0
0,0,0,0,0,0,0,0,0,0,0,0,0
0,0,0,0,0,0,0,0,0,0,0,0,0
0,0,0,0,0,0,0,0,0,0,0,0,0
0,0,0,0,0,0,0,0,0,0,0,0,0
0,1,0,0,0,0,1,0,0,0,0,1,0
0,0,0,0,0,0,0,0,0,0,0,0,0
endlayer

layer
0,0,0,0,0,0,0,0,0,0,0,0,0
0,1,0,0,0,0,1,0,0,0,0,1,0
0,0,0,0,0,0,0,0,0,0,0,0,0
0,0,0,0,0,0,0,0,0,0,0,0,0
0,0,0,0,0,0,0,0,0,0,0,0,0
0,0,0,0,0,0,0,0,0,0,0,0,0
0,1,0,0,0,0,0,0,0,0,0,1,0
0,0,0,0,0,0,0,0,0,0,0,0,0
0,0,0,0,0,0,0,0,0,0,0,0,0
0,0,0,0,0,0,0,0,0,0,0,0,0
0,0,0,0,0,0,0,0,0,0,0,0,0
0,1,0,0,0,0,1,0,0,0,0,1,0
0,0,0,0,0,0,0,0,0,0,0,0,0
endlayer

layer
0,0,0,0,0,0,0,0,0,0,0,0,0
0,1,0,0,0,0,1,0,0,0,0,1,0
0,0,0,0,0,0,0,0,0,0,0,0,0
0,0,0,0,0,0,0,0,0,0,0,0,0
0,0,0,0,0,0,0,0,0,0,0,0,0
0,0,0,0,0,0,0,0,0,0,0,0,0
0,1,0,0,0,0,0,0,0,0,0,1,0
0,0,0,0,0,0,0,0,0,0,0,0,0
0,0,0,0,0,0,0,0,0,0,0,0,0
0,0,0,0,0,0,0,0,0,0,0,0,0
0,0,0,0,0,0,0,0,0,0,0,0,0
0,1,0,0,0,0,1,0,0,0,0,1,0
0,0,0,0,0,0,0,0,0,0,0,0,0
endlayer

layer
0,0,0,0,0,0,2,0,0,0,0,2,0
4,1,0,0,0,0,1,0,0,0,0,1,3
0,0,0,0,0,0,0,0,0,0,0,0,0
0,0,0,0,0,0,0,0,0,0,0,0,0
0,0,0,0,0,0,0,0,0,0,0,0,0
0,0,0,0,0,0,0,0,0,0,0,0,0
4,1,0,0,0,0,0,0,0,0,0,1,3
0,0,0,0,0,0,0,0,0,0,0,0,0
0,0,0,0,0,0,0,0,0,0,0,0,0
0,0,0,0,0,0,0,0,0,0,0,0,0
0,0,0,0,0,0,0,0,0,0,0,0,0
4,1,0,0,0,0,1,0,0,0,0,1,5
0,6,0,0,0,0,6,0,0,0,0,6,0
endlayer

layer
0,10,7,9,2,2,9,2,2,2,2,8,7
7,1,11,11,11,11,1,11,11,11,11,1,9
13,12,9,9,9,9,9,9,9,9,9,12,3
4,12,9,9,9,9,9,9,9,9,9,12,3
4,12,9,9,9,9,9,9,9,9,9,12,3
4,12,9,9,9,9,9,9,9,9,9,12,3
9,1,9,9,9,9,9,9,9,9,9,1,9
4,12,9,9,9,9,9,9,9,9,9,12,3
4,12,9,9,9,9,9,9,9,9,9,12,3
4,12,9,9,9,9,9,9,9,9,9,12,5
4,12,9,9,9,9,9,9,9,9,9,12,3
9,1,11,11,11,11,1,11,11,11,11,1,9
9,9,6,6,6,6,9,6,6,6,6,9,14
endlayer

layer
0,0,0,0,0,0,0,0,0,0,0,10,0
0,1,15,15,15,15,1,15,16,16,15,1,0
0,15,9,7,17,0,0,0,0,0,0,15,0
0,15,17,0,17,7,0,0,0,0,0,15,0
0,15,7,0,0,0,0,0,0,0,0,15,0
0,15,0,0,0,0,17,17,17,0,0,15,0
0,1,18,0,0,0,13,0,13,0,0,1,0
0,15,0,0,0,0,0,0,0,0,0,15,0
0,15,17,0,0,0,0,0,0,0,0,15,0
0,15,20,19,0,0,0,0,0,0,17,15,0
22,15,0,0,0,0,21,7,17,10,17,15,0
0,1,15,15,15,15,1,15,15,15,15,1,14
0,0,0,0,23,0,0,0,0,0,0,23,0
endlayer

layer
0,10,0,0,0,0,0,0,0,0,10,0,0
0,1,15,26,26,15,1,15,25,24,15,1,0
0,15,0,0,0,0,0,0,0,0,0,15,0
0,26,0,0,0,0,0,0,0,0,0,26,0
0,26,0,0,0,0,0,0,0,0,0,26,0
0,15,0,0,0,0,27,27,27,0,0,15,0
0,1,0,0,0,0,0,0,0,0,0,1,0
0,15,0,0,0,0,0,0,0,0,0,15,0
0,26,27,0,0,0,0,0,0,0,0,26,0
0,26,0,0,0,0,0,0,0,0,0,26,0
0,15,0,0,0,0,0,0,0,0,0,15,0
22,1,15,26,26,15,1,15,26,26,15,1,14
0,0,23,0,0,23,23,0,0,0,23,0,0
endlayer

layer
0,0,10,0,0,0,10,0,0,0,10,0,0
0,1,15,26,26,15,1,15,15,15,15,1,14
0,15,0,0,0,0,0,0,0,23,0,15,14
0,26,0,0,0,0,0,0,0,0,0,26,0
0,26,0,0,0,0,0,0,0,0,0,26,0
22,15,0,0,0,0,0,0,0,0,0,15,0
22,1,0,0,0,0,0,0,0,0,0,1,14
0,15,0,0,0,0,0,0,0,0,0,15,0
0,26,0,0,0,0,0,0,0,0,0,26,0
22,26,0,0,0,0,0,0,0,0,0,26,0
22,15,0,0,0,0,0,10,0,0,22,15,0
22,1,15,26,26,15,1,15,26,26,15,1,0
0,0,0,0,0,0,0,0,0,0,0,23,0
endlayer

layer
0,2,10,0,0,0,2,0,0,10,10,2,0
4,1,15,15,15,15,1,15,15,15,15,1,3
0,15,0,0,0,0,0,23,0,23,0,15,0
0,15,0,0,0,0,0,0,0,0,0,15,0
0,15,0,0,0,0,0,0,0,0,0,15,0
22,15,0,0,0,0,0,0,0,0,22,15,0
4,1,0,0,0,0,0,0,0,0,0,1,3
0,15,0,0,0,0,0,0,0,0,22,15,0
0,15,0,0,0,0,0,0,0,0,0,15,0
22,15,0,0,0,0,0,0,0,0,0,15,0
0,15,0,0,10,0,0,10,0,10,0,15,14
4,1,15,15,15,15,1,15,15,15,15,1,3
0,6,0,23,0,23,6,0,0,23,23,6,0
endlayer

layer
9,9,2,2,2,2,9,2,2,2,2,9,9
9,1,11,11,11,11,1,11,11,11,11,1,9
4,12,5,23,0,28,12,5,23,23,23,12,3
4,12,14,0,0,0,12,0,0,0,22,12,3
4,12,0,0,0,0,12,28,0,0,22,12,3
4,12,14,0,0,0,12,0,0,0,0,12,3
9,1,11,11,11,11,11,11,11,11,11,1,9
4,12,28,0,0,0,12,28,0,0,22,12,3
4,12,0,0,0,0,12,0,0,0,22,12,3
4,12,14,0,0,0,12,0,0,0,28,12,3
4,12,0,5,0,0,12,10,10,5,22,12,3
9,1,11,11,11,11,1,11,11,11,11,1,9
9,9,6,6,6,6,9,6,6,6,6,9,9
endlayer

layer
0,0,0,7,0,0,0,0,7,0,0,0,0
0,7,29,7,13,7,7,13,8,7,7,7,0
7,7,9,9,9,9,9,9,9,9,9,8,0
7,7,9,30,5,5,5,5,6,5,9,7,0
0,31,9,5,0,0,28,0,0,5,9,31,0
0,29,9,5,5,28,2,28,0,5,9,7,0
0,7,9,5,0,4,32,3,28,5,3,7,0
0,7,9,30,28,0,6,5,5,5,9,9,7
0,7,9,5,5,28,5,0,6,30,9,7,7
7,7,9,30,30,5,5,30,5,30,9,7,0
7,29,9,9,9,9,9,9,9,9,9,31,0
0,31,7,7,7,7,7,31,7,29,9,8,7
0,0,0,0,0,0,7,0,0,7,23,0,0
endlayer

layer
0,0,0,0,0,0,0,0,0,0,0,0,0
0,0,0,0,0,0,0,0,0,0,0,0,0
0,0,0,0,0,0,0,7,0,0,0,0,0
0,0,0,7,10,0,7,0,0,13,0,0,0
0,0,7,7,30,7,7,7,7,8,0,0,0
0,0,0,7,29,9,9,8,7,7,0,0,0
0,0,0,0,7,7,9,9,31,30,14,0,0
0,0,0,0,7,9,31,9,30,7,7,0,0
0,0,0,0,31,8,7,7,7,7,0,0,0
0,0,0,0,7,0,7,0,0,0,0,0,0
0,0,0,7,0,7,0,0,7,0,0,0,0
0,0,0,0,0,0,0,0,0,0,0,0,0
0,0,0,0,0,0,0,0,0,0,0,0,0
endlayer

