
# Created by Ruins mod version 16.7 Ingame Parser
# authoring Player: ST753M

weight=3
embed_into_distance=4
acceptable_target_blocks=water,grass,dirt,mud,sand,gravel,clay,podzol,biomesoplenty:grass,biomesoplenty:dirt
unacceptable_target_blocks=
dimensions=19,13,13
allowable_overhang=99
max_leveling=0
leveling_buffer=0
preserve_water=0
preserve_lava=0
preventRotation=1

biomesToSpawnIn=wetland,overgrown_greens

rule1=0,100,preserveBlock
rule2=0,100,biomesoplenty:log_2-5
rule3=0,100,minecraft:vine-8
rule4=0,100,minecraft:vine-1
rule5=0,100,minecraft:vine-4
rule6=0,100,biomesoplenty:wood_slab_1-9
rule7=0,100,biomesoplenty:willow_stairs-4
rule8=0,100,biomesoplenty:willow_fence-0
rule9=0,100,biomesoplenty:willow_stairs-6
rule10=0,100,minecraft:vine-12
rule11=0,100,minecraft:vine-9
rule12=0,100,biomesoplenty:willow_stairs-7
rule13=0,100,biomesoplenty:planks_0-9
rule14=0,100,biomesoplenty:willow_door_block-2
rule15=0,100,minecraft:vine-6
rule16=0,100,minecraft:bed-9
rule17=0,100,minecraft:spruce_stairs-1
rule18=0,100,minecraft:bed-1
rule19=0,100,biomesoplenty:willow_door_block-3
rule20=0,100,minecraft:spruce_stairs-0
rule21=0,100,biomesoplenty:willow_door_block-1
rule22=0,100,minecraft:crafting_table-0
rule23=0,100,biomesoplenty:willow_door_block-0
rule24=0,100,biomesoplenty:willow_stairs-5
rule25=0,100,minecraft:vine-3
rule26=0,100,minecraft:stained_glass_pane-13
rule27=0,100,biomesoplenty:willow_door_block-9
rule28=0,100,minecraft:carpet-13
rule29=0,100,minecraft:vine-2
rule30=0,50,ChestGenHook:chests/jungle_temple:2-4,ChestGenHook:chests/spawn_bonus_chest:4-4
rule31=0,50,MobSpawner:Witch,MobSpawner:Slime,MobSpawner:Cave_Spider,MobSpawner:Spider,MobSpawner:Zombie
rule32=0,100,biomesoplenty:double_wood_slab_1-1
rule33=0,100,biomesoplenty:wood_slab_1-1
rule34=0,100,biomesoplenty:willow_stairs-2
rule35=0,100,biomesoplenty:willow_stairs-3
rule36=0,100,biomesoplenty:willow_stairs-0
rule37=0,100,biomesoplenty:willow_stairs-1

layer
1,1,1,1,1,1,1,1,1,1,1,1,1
1,2,1,1,1,1,1,1,1,1,1,2,1
1,1,1,1,1,1,1,1,1,1,1,1,1
1,1,1,1,1,1,1,1,1,1,1,1,1
1,1,1,1,1,1,1,1,1,1,1,1,1
1,1,1,1,1,1,1,1,1,1,1,1,1
1,1,1,1,1,1,1,1,1,1,1,1,1
1,1,1,1,1,1,1,1,1,1,1,1,1
1,1,1,1,1,1,1,1,1,1,1,1,1
1,1,1,1,1,1,1,1,1,1,1,1,1
1,1,1,1,1,1,1,1,1,1,1,1,1
1,2,1,1,1,1,1,1,1,1,1,2,1
1,1,1,1,1,1,1,1,1,1,1,1,1
endlayer

layer
1,1,1,1,1,1,1,1,1,1,1,1,1
1,2,1,1,1,1,1,1,1,1,1,2,1
1,1,1,1,1,1,1,1,1,1,1,1,1
1,1,1,1,1,1,1,1,1,1,1,1,1
1,1,1,1,1,1,1,1,1,1,1,1,1
1,1,1,1,1,1,1,1,1,1,1,1,1
1,1,1,1,1,1,1,1,1,1,1,1,1
1,1,1,1,1,1,1,1,1,1,1,1,1
1,1,1,1,1,1,1,1,1,1,1,1,1
1,1,1,1,1,1,1,1,1,1,1,1,1
1,1,1,1,1,1,1,1,1,1,1,1,1
1,2,1,1,1,1,1,1,1,1,1,2,1
1,1,1,1,1,1,1,1,1,1,1,1,1
endlayer

layer
1,1,1,1,1,1,1,1,1,1,1,1,1
1,2,1,1,1,1,1,1,1,1,1,2,1
1,1,1,1,1,1,1,1,1,1,1,1,1
1,1,1,1,1,1,1,1,1,1,1,1,1
1,1,1,1,1,1,1,1,1,1,1,1,1
1,1,1,1,1,1,1,1,1,1,1,1,1
1,1,1,1,1,1,1,1,1,1,1,1,1
1,1,1,1,1,1,1,1,1,1,1,1,1
1,1,1,1,1,1,1,1,1,1,1,1,1
1,1,1,1,1,1,1,1,1,1,1,1,1
1,1,1,1,1,1,1,1,1,1,1,1,1
1,2,1,1,1,1,1,1,1,1,1,2,1
1,1,1,1,1,1,1,1,1,1,1,1,1
endlayer

layer
1,1,1,1,1,1,1,1,1,1,1,1,1
1,2,1,1,1,1,1,1,1,1,1,2,1
1,1,1,1,1,1,1,1,1,1,1,1,1
1,1,1,1,1,1,1,1,1,1,1,1,1
1,1,1,1,1,1,1,1,1,1,1,1,1
1,1,1,1,1,1,1,1,1,1,1,1,1
1,1,1,1,1,1,1,1,1,1,1,1,1
1,1,1,1,1,1,1,1,1,1,1,1,1
1,1,1,1,1,1,1,1,1,1,1,1,1
1,1,1,1,1,1,1,1,1,1,1,1,1
1,1,1,1,1,1,1,1,1,1,1,1,1
1,2,1,1,1,1,1,1,1,1,1,2,1
1,1,1,1,1,1,1,1,1,1,1,1,1
endlayer

layer
1,1,1,1,1,1,1,1,1,1,1,3,1
1,2,1,1,1,1,1,1,1,1,5,2,4
1,1,1,1,1,1,1,1,1,1,1,1,1
1,1,1,1,1,1,1,1,1,1,1,1,1
1,1,1,1,1,1,1,1,1,1,1,1,1
1,1,1,1,1,1,1,1,1,1,1,1,1
1,1,1,1,1,1,1,1,1,1,1,1,1
1,1,1,1,1,1,1,1,1,1,1,1,1
1,1,1,1,1,1,1,1,1,1,1,1,1
1,1,1,1,1,1,1,1,1,1,1,1,1
1,1,1,1,1,1,1,1,1,1,1,1,1
1,2,1,1,1,1,1,1,1,1,1,2,1
1,1,1,1,1,1,1,1,1,1,1,1,1
endlayer

layer
1,1,1,1,1,1,1,1,1,1,1,0,1
1,2,1,1,1,1,1,1,1,1,5,2,0
1,1,1,1,1,1,1,1,1,1,1,1,1
1,1,1,1,1,1,1,1,1,1,1,1,1
1,1,1,1,1,1,1,1,1,1,1,1,1
1,1,1,1,1,1,1,1,1,1,1,1,1
1,1,1,1,1,1,1,1,1,1,1,1,1
1,1,1,1,1,1,1,1,1,1,1,1,1
1,1,1,1,1,1,1,1,1,1,1,1,1
1,1,1,1,1,1,1,1,1,1,1,1,1
1,1,1,1,1,1,1,1,1,1,1,1,1
1,2,1,1,1,1,1,1,1,1,1,2,1
1,1,1,1,1,1,1,1,1,1,1,1,1
endlayer

layer
6,6,6,6,6,6,6,6,6,6,6,6,6
6,2,0,6,6,6,6,6,6,6,5,2,6
6,0,6,6,6,6,6,6,6,6,6,0,6
6,6,6,6,6,6,6,6,6,6,6,6,6
6,6,6,6,6,6,6,6,6,6,6,6,6
6,6,6,6,6,6,6,6,6,6,6,6,6
6,6,6,6,6,6,6,6,6,6,6,6,6
6,6,6,6,6,6,6,6,6,6,6,6,6
6,6,6,6,6,6,6,6,6,6,6,6,6
6,6,6,6,6,6,6,6,6,6,6,6,6
6,0,6,6,6,6,6,6,6,6,6,0,6
6,2,4,6,6,6,6,6,6,6,0,2,6
6,6,6,6,6,6,6,6,6,6,6,6,6
endlayer

layer
0,7,8,8,8,8,8,8,8,8,8,7,0
12,2,11,3,0,0,0,0,0,0,10,2,9
8,15,13,2,2,2,14,2,2,2,13,4,8
8,0,2,16,0,0,0,0,0,0,2,0,8
8,0,2,18,0,0,17,17,0,0,2,0,8
8,0,2,0,0,0,8,8,0,0,2,0,8
8,0,21,0,0,0,20,20,0,0,19,0,8
8,0,2,0,0,0,0,0,0,0,2,0,8
8,0,2,0,22,0,0,0,0,0,2,0,8
8,0,2,0,0,0,0,0,0,3,2,0,8
8,0,13,2,2,2,23,2,2,2,13,3,8
12,2,4,0,0,0,0,0,0,0,0,2,9
0,24,8,8,8,8,8,8,8,8,8,24,0
endlayer

layer
0,7,0,0,0,0,0,0,0,0,0,7,0
12,2,11,0,0,0,0,0,0,0,0,2,9
0,15,13,2,26,2,27,2,26,2,13,25,0
0,0,2,0,0,0,0,0,0,0,2,0,0
0,0,26,0,0,0,0,0,0,0,26,0,0
0,0,2,0,0,0,28,28,0,0,2,0,0
0,0,27,0,0,0,0,0,0,0,27,0,0
0,0,2,0,0,0,0,0,0,0,2,0,0
0,0,26,0,0,0,0,0,0,0,26,0,0
0,0,2,0,0,0,0,0,0,3,2,0,0
0,10,13,2,26,2,27,2,26,2,13,3,0
12,2,25,29,0,0,0,0,0,0,5,2,9
0,24,0,0,0,0,0,0,0,0,0,24,0
endlayer

layer
0,7,0,0,0,0,0,0,0,0,0,7,0
12,2,0,0,0,0,0,0,0,0,0,2,9
0,0,13,2,26,2,2,2,26,2,13,0,0
0,0,2,0,0,0,0,0,0,0,2,0,0
0,0,26,0,0,0,0,0,0,0,26,0,0
0,0,2,0,0,0,0,0,0,0,2,0,0
0,0,2,0,0,0,0,0,0,0,2,0,0
0,0,2,0,0,0,0,0,0,0,2,0,0
0,0,26,0,0,0,0,0,0,0,26,0,0
0,0,2,0,0,0,0,0,0,3,2,0,0
0,0,13,2,26,2,2,2,26,2,13,0,0
12,2,0,0,0,0,0,0,0,0,5,2,9
0,24,0,0,0,0,0,0,0,0,0,24,0
endlayer

layer
7,7,7,7,7,7,7,7,7,7,7,7,9
12,2,6,6,6,6,6,6,6,6,6,2,9
12,6,13,2,2,2,2,2,2,2,13,6,9
12,6,2,6,6,6,6,6,6,6,2,6,9
12,6,2,6,6,6,6,6,6,6,2,6,9
12,6,2,6,6,6,6,6,6,6,2,6,9
12,6,2,6,6,6,6,6,6,6,2,6,9
12,6,2,6,6,6,6,6,6,6,2,6,9
12,6,2,6,6,6,6,6,6,6,2,6,9
12,6,2,6,6,6,6,6,6,10,2,6,9
12,6,13,2,2,2,2,2,2,2,13,6,9
12,2,6,6,6,6,6,6,6,6,6,2,9
12,24,24,24,24,24,24,24,24,24,24,24,9
endlayer

layer
8,1,1,1,1,1,1,1,1,1,1,1,8
1,2,8,8,8,8,8,8,8,8,8,2,1
1,8,28,28,28,28,28,28,28,28,28,8,1
1,8,28,0,0,0,0,0,0,0,28,8,1
1,8,28,0,0,0,0,0,0,0,28,8,1
1,8,28,0,0,0,30,0,0,0,28,8,1
1,8,28,0,0,0,2,0,0,0,28,8,1
1,8,28,0,0,0,0,0,0,0,28,8,1
1,8,28,0,0,0,0,0,0,0,28,8,1
1,8,28,0,0,0,0,0,0,0,28,8,1
1,8,28,20,20,28,28,28,28,28,28,8,1
1,2,8,8,8,8,8,8,8,8,8,2,1
8,1,1,1,1,1,1,1,1,1,1,1,8
endlayer

layer
8,1,1,1,1,1,1,1,1,1,1,1,8
1,2,1,1,1,1,1,1,1,1,1,2,1
1,1,0,0,0,0,0,0,0,0,0,1,1
1,1,0,0,0,0,0,0,0,0,0,1,1
1,1,0,0,0,0,0,0,0,0,0,1,1
1,1,0,0,0,0,6,0,0,0,0,1,1
1,1,0,0,0,6,2,6,0,0,0,1,1
1,1,0,0,0,0,6,0,0,0,0,1,1
1,1,0,0,0,0,0,0,0,0,0,1,1
1,1,0,0,0,0,0,0,0,0,0,1,1
1,1,0,0,0,0,0,0,0,0,0,1,1
1,2,1,1,1,1,1,1,1,1,1,2,1
8,1,1,1,1,1,1,1,1,1,1,1,8
endlayer

layer
8,1,1,1,1,1,1,1,1,1,1,1,8
1,2,1,1,1,1,1,1,1,1,1,2,1
1,1,0,0,0,0,0,0,0,0,0,1,1
1,1,0,0,0,0,0,0,0,0,0,1,1
1,1,0,0,0,0,0,0,0,0,0,1,1
1,1,0,0,0,0,7,0,0,0,0,1,1
1,1,0,0,0,12,31,9,0,0,0,1,1
1,1,0,0,0,0,24,0,0,0,0,1,1
1,1,0,0,0,0,0,0,0,0,0,1,1
1,1,0,0,0,0,0,0,0,0,0,1,1
1,1,0,0,0,0,0,0,0,0,0,1,1
1,2,1,1,1,1,1,1,1,1,1,2,1
8,1,1,1,1,1,1,1,1,1,1,1,8
endlayer

layer
32,32,6,1,1,1,1,1,1,1,6,32,32
32,2,0,1,1,1,1,1,1,1,0,2,32
6,0,0,0,0,0,0,0,0,0,0,0,6
1,1,0,0,0,0,0,0,0,0,0,1,1
1,1,0,0,0,0,0,0,0,0,0,1,1
1,1,0,0,0,0,7,0,0,0,0,1,1
1,1,0,0,0,12,2,9,0,0,0,1,1
1,1,0,0,0,0,24,0,0,0,0,1,1
1,1,0,0,0,0,0,0,0,0,0,1,1
1,1,0,0,0,0,0,0,0,0,0,1,1
6,0,0,0,0,0,0,0,0,0,0,0,6
13,2,0,1,1,1,1,1,1,1,0,2,32
13,32,6,1,1,1,1,1,1,1,6,32,32
endlayer

layer
1,33,32,32,6,1,1,1,6,32,32,33,1
33,33,9,0,0,1,1,1,0,0,12,33,33
32,24,24,0,0,0,0,0,0,0,12,24,32
32,0,0,0,0,0,0,0,0,0,0,0,32
6,0,0,0,0,0,0,0,0,0,0,0,6
1,1,0,0,0,0,8,0,0,0,0,1,1
1,1,0,0,0,8,2,8,0,0,0,1,1
1,1,0,0,0,0,8,0,0,0,0,1,1
6,0,0,0,0,0,0,0,0,0,0,0,6
32,0,0,0,0,0,0,0,0,0,0,0,32
32,7,9,0,0,0,0,0,0,0,7,7,32
33,33,9,0,0,1,1,1,0,0,12,33,33
1,33,32,32,6,1,1,1,6,32,32,33,1
endlayer

layer
1,1,1,33,32,32,6,32,32,33,1,1,1
1,1,1,33,6,0,0,0,6,33,1,1,1
1,1,1,33,6,0,0,0,6,33,1,1,1
33,33,33,33,6,0,0,0,6,33,33,33,33
32,6,6,6,6,0,0,0,6,6,6,6,32
32,0,0,0,0,0,8,0,0,0,0,0,32
6,0,0,0,0,8,2,8,0,0,0,0,6
32,0,0,0,0,0,8,0,0,0,0,0,32
32,6,6,6,6,0,0,0,6,6,6,6,32
33,33,33,33,6,0,0,0,6,33,33,33,33
1,1,1,33,6,0,0,0,6,33,1,1,1
1,1,1,33,6,0,0,0,6,33,1,1,1
1,1,1,33,32,32,6,32,32,33,1,1,1
endlayer

layer
1,1,1,1,1,35,6,34,1,1,1,1,1
1,1,1,1,1,33,6,33,1,1,1,1,1
1,1,1,1,1,33,6,33,1,1,1,1,1
1,1,1,1,1,33,6,33,1,1,1,1,1
1,1,1,1,1,33,6,33,1,1,1,1,1
36,33,33,33,33,33,32,33,33,33,33,33,36
6,6,6,6,6,32,2,32,6,6,6,6,6
37,33,33,33,33,33,32,33,33,33,33,33,37
1,1,1,1,1,33,6,33,1,1,1,1,1
1,1,1,1,1,33,6,33,1,1,1,1,1
1,1,1,1,1,33,6,33,1,1,1,1,1
1,1,1,1,1,33,6,33,1,1,1,1,1
1,1,1,1,1,35,6,34,1,1,1,1,1
endlayer

layer
1,1,1,1,1,1,37,1,1,1,1,1,1
1,1,1,1,1,1,1,1,1,1,1,1,1
1,1,1,1,1,1,1,1,1,1,1,1,1
1,1,1,1,1,1,1,1,1,1,1,1,1
1,1,1,1,1,1,1,1,1,1,1,1,1
1,1,1,1,1,1,33,1,1,1,1,1,1
34,1,1,1,1,33,13,33,1,1,1,1,35
1,1,1,1,1,1,33,1,1,1,1,1,1
1,1,1,1,1,1,1,1,1,1,1,1,1
1,1,1,1,1,1,1,1,1,1,1,1,1
1,1,1,1,1,1,1,1,1,1,1,1,1
1,1,1,1,1,1,1,1,1,1,1,1,1
1,1,1,1,1,1,36,1,1,1,1,1,1
endlayer

