
# Created by Ruins mod version 16.7 Ingame Parser
# authoring Player: ST753M

weight=1
embed_into_distance=3
acceptable_target_blocks=water,grass,dirt,mud,podzol
unacceptable_target_blocks=
dimensions=12,12,12
allowable_overhang=3
max_leveling=0
leveling_buffer=0
preserve_water=0
preserve_lava=0

biomesToSpawnIn=mangrove

rule1=0,100,preserveBlock
rule2=0,100,biomesoplenty:log_1-6
rule3=0,100,minecraft:ladder-2
rule4=0,100,minecraft:ladder-3
rule5=0,100,biomesoplenty:mangrove_stairs-6
rule6=0,100,biomesoplenty:mangrove_stairs-4
rule7=0,100,biomesoplenty:planks_0-6
rule8=0,100,biomesoplenty:mangrove_stairs-7
rule9=0,100,biomesoplenty:wood_slab_0-6
rule10=0,100,biomesoplenty:mangrove_stairs-5
rule11=0,100,biomesoplenty:fir_fence-0
rule12=0,100,biomesoplenty:mangrove_fence-0
rule13=0,100,minecraft:glowstone-0
rule14=0,100,biomesoplenty:mangrove_stairs-3
rule15=0,100,biomesoplenty:mangrove_stairs-2
rule16=0,100,biomesoplenty:mangrove_stairs-1
rule17=0,100,biomesoplenty:mangrove_stairs-0

layer
1,1,1,1,1,1,1,1,1,1,1,1
1,2,1,1,1,1,1,1,1,1,2,1
1,1,1,1,1,1,1,1,1,1,1,1
1,1,1,1,1,1,1,1,1,1,1,1
1,1,1,1,1,1,1,1,1,1,1,1
1,1,1,1,1,2,2,1,1,1,1,1
1,1,1,1,1,2,2,1,1,1,1,1
1,1,1,1,1,1,1,1,1,1,1,1
1,1,1,1,1,1,1,1,1,1,1,1
1,1,1,1,1,1,1,1,1,1,1,1
1,2,1,1,1,1,1,1,1,1,2,1
1,1,1,1,1,1,1,1,1,1,1,1
endlayer

layer
1,1,1,1,1,1,1,1,1,1,1,1
1,2,1,1,1,1,1,1,1,1,2,1
1,1,1,1,1,1,1,1,1,1,1,1
1,1,1,1,1,1,1,1,1,1,1,1
1,1,1,1,1,1,1,1,1,1,1,1
1,1,1,1,1,2,2,1,1,1,1,1
1,1,1,1,1,2,2,1,1,1,1,1
1,1,1,1,1,1,1,1,1,1,1,1
1,1,1,1,1,1,1,1,1,1,1,1
1,1,1,1,1,1,1,1,1,1,1,1
1,2,1,1,1,1,1,1,1,1,2,1
1,1,1,1,1,1,1,1,1,1,1,1
endlayer

layer
1,1,1,1,1,1,1,1,1,1,1,1
1,2,1,1,1,1,1,1,1,1,2,1
1,1,1,1,1,1,1,1,1,1,1,1
1,1,1,1,1,1,1,1,1,1,1,1
1,1,1,1,1,1,1,1,1,1,1,1
1,1,1,1,1,2,2,1,1,1,1,1
1,1,1,1,1,2,2,1,1,1,1,1
1,1,1,1,1,1,1,1,1,1,1,1
1,1,1,1,1,1,1,1,1,1,1,1
1,1,1,1,1,1,1,1,1,1,1,1
1,2,1,1,1,1,1,1,1,1,2,1
1,1,1,1,1,1,1,1,1,1,1,1
endlayer

layer
1,1,1,1,1,1,1,1,1,1,1,1
1,2,1,1,1,1,1,1,1,1,2,3
1,1,1,1,1,1,1,1,1,1,1,1
1,1,1,1,1,1,1,1,1,1,1,1
1,1,1,1,1,1,1,1,1,1,1,1
1,1,1,1,1,2,2,1,1,1,1,1
1,1,1,1,1,2,2,1,1,1,1,1
1,1,1,1,1,1,1,1,1,1,1,1
1,1,1,1,1,1,1,1,1,1,1,1
1,1,1,1,1,1,1,1,1,1,1,1
4,2,1,1,1,1,1,1,1,1,2,1
1,1,1,1,1,1,1,1,1,1,1,1
endlayer

layer
1,1,1,1,1,1,1,1,1,1,1,1
1,2,1,1,1,1,1,1,1,1,2,3
1,1,1,1,1,1,1,1,1,1,1,1
1,1,1,1,1,1,1,1,1,1,1,1
1,1,1,1,1,1,1,1,1,1,1,1
1,1,1,1,1,2,2,1,1,1,1,1
1,1,1,1,1,2,2,1,1,1,1,1
1,1,1,1,1,1,1,1,1,1,1,1
1,1,1,1,1,1,1,1,1,1,1,1
1,1,1,1,1,1,1,1,1,1,1,1
4,2,1,1,1,1,1,1,1,1,2,1
1,1,1,1,1,1,1,1,1,1,1,1
endlayer

layer
1,1,1,1,1,1,1,1,1,1,1,1
1,2,1,1,1,1,1,1,1,1,2,3
1,1,1,1,1,1,1,1,1,1,1,1
1,1,1,1,1,1,1,1,1,1,1,1
1,1,1,1,1,1,1,1,1,1,1,1
1,1,1,1,1,2,2,1,1,1,1,1
1,1,1,1,1,2,2,1,1,1,1,1
1,1,1,1,1,1,1,1,1,1,1,1
1,1,1,1,1,1,1,1,1,1,1,1
1,1,1,1,1,1,1,1,1,1,1,1
4,2,1,1,1,1,1,1,1,1,2,1
1,1,1,1,1,1,1,1,1,1,1,1
endlayer

layer
6,6,6,6,6,6,6,6,6,6,6,5
8,2,7,7,7,7,7,7,7,7,2,3
8,7,7,7,7,7,7,7,7,7,7,5
8,7,7,7,7,7,7,7,7,7,7,5
8,7,7,7,7,9,9,7,7,7,7,5
8,7,7,7,9,9,9,9,7,7,7,5
8,7,7,7,9,9,9,9,7,7,7,5
8,7,7,7,7,9,9,7,7,7,7,5
8,7,7,7,7,7,7,7,7,7,7,5
8,7,7,7,7,7,7,7,7,7,7,5
4,2,7,7,7,7,7,7,7,7,2,5
8,10,10,10,10,10,10,10,10,10,10,5
endlayer

layer
1,1,1,1,1,1,1,1,1,1,1,1
1,2,11,11,11,11,11,11,11,11,2,3
1,11,0,0,0,0,0,0,0,0,11,1
1,11,0,2,12,0,0,12,2,0,1,1
1,11,0,12,0,0,0,0,12,0,11,1
1,11,0,0,0,0,0,0,0,0,11,1
1,11,0,0,0,0,0,0,0,0,11,1
1,11,0,12,0,0,0,0,12,0,11,1
1,1,0,2,12,0,0,12,2,0,11,1
1,11,0,0,0,0,0,0,0,0,11,1
4,2,11,11,11,11,11,11,11,11,2,1
1,1,1,1,1,1,1,1,1,1,1,1
endlayer

layer
1,1,1,1,1,1,1,1,1,1,1,1
1,12,1,1,1,1,1,1,1,0,12,1
1,1,0,0,0,0,0,0,0,0,1,1
1,1,0,2,12,0,0,12,2,0,1,1
1,1,0,12,0,0,0,0,12,0,1,1
1,1,0,0,0,0,0,0,0,0,1,1
1,1,0,0,0,0,0,0,0,0,1,1
1,1,0,12,0,0,0,0,12,0,1,1
1,1,0,2,12,0,0,12,2,0,1,1
1,1,0,0,0,0,0,0,0,0,1,1
1,12,1,1,1,1,1,1,1,1,12,1
1,1,1,1,1,1,1,1,1,1,1,1
endlayer

layer
1,1,1,1,1,1,1,1,1,1,1,1
1,13,1,1,1,1,1,1,1,1,13,1
1,1,0,0,0,0,0,0,0,0,1,1
1,1,0,2,12,0,0,12,2,0,1,1
1,1,0,12,0,0,0,0,12,0,1,1
1,1,0,0,0,0,0,0,0,0,1,1
1,1,0,0,0,0,0,0,0,0,1,1
1,1,0,12,0,0,0,0,12,0,1,1
1,1,0,2,12,0,0,12,2,0,1,1
1,1,0,0,0,0,0,0,0,0,1,1
1,13,1,1,1,1,1,1,1,1,13,1
1,1,1,1,1,1,1,1,1,1,1,1
endlayer

layer
1,1,1,1,1,1,1,1,1,1,1,1
1,1,1,1,1,1,1,1,1,1,1,1
1,1,0,0,0,0,0,0,0,0,1,1
1,1,0,2,9,15,14,9,2,0,1,1
1,1,0,9,0,0,0,0,9,0,1,1
1,1,0,16,0,0,0,0,16,0,1,1
1,1,0,17,0,0,0,0,17,0,1,1
1,1,0,9,0,0,0,0,9,0,1,1
1,1,0,2,9,15,14,9,2,0,1,1
1,1,0,0,0,0,0,0,0,0,1,1
1,1,1,1,1,1,1,1,1,1,1,1
1,1,1,1,1,1,1,1,1,1,1,1
endlayer

layer
1,1,1,1,1,1,1,1,1,1,1,1
1,1,1,1,1,1,1,1,1,1,1,1
1,1,14,17,17,17,17,17,17,17,1,1
1,1,14,7,9,9,9,9,7,15,1,1
1,1,14,9,9,17,17,9,9,15,1,1
1,1,14,9,14,7,7,15,9,15,1,1
1,1,14,9,14,7,7,15,9,15,1,1
1,1,14,9,9,16,16,9,9,15,1,1
1,1,14,7,9,9,9,9,7,15,1,1
1,1,14,16,16,16,16,16,16,15,1,1
1,1,1,1,1,1,1,1,1,1,1,1
1,1,1,1,1,1,1,1,1,1,1,1
endlayer

