
# Created by Ruins mod version 17.0 Ingame Parser
# authoring Player: ST753M

weight=1
embed_into_distance=4
acceptable_target_blocks=
unacceptable_target_blocks=flowing_water,water,flowing_lava,lava,ice,bedrock,netherrack,nether_brick,nether_brick_fence,soul_sand,quartz_ore,end_stone,obsidian,iron_bars,Natura:Cloud,slime_grass,slime_congealed,slime_dirt,clouds,natura:clouds,twilightforest:wispy_cloud,twilightforest:fluffy_cloud
dimensions=7,9,9
allowable_overhang=10
max_leveling=5
leveling_buffer=0
preserve_water=0
preserve_lava=0

=0,100,preserveBlock
rule1=0,100,minecraft:concrete-9
rule2=0,100,iceandfire:frozen_stone-0
rule3=0,100,minecraft:sea_lantern-0
rule4=0,100,minecraft:packed_ice-0
rule5=0,100,minecraft:farmland-7
rule6=0,100,minecraft:water-0

rule7=0,100,minecraft:wheat-0,minecraft:wheat-1,minecraft:wheat-2,minecraft:wheat-3,minecraft:wheat-4,minecraft:wheat-5,minecraft:wheat-6,minecraft:wheat-7

^0,100,minecraft:potatoes-0,minecraft:potatoes-1,minecraft:potatoes-2,minecraft:potatoes-3,minecraft:potatoes-4,minecraft:potatoes-5,minecraft:potatoes-6,minecraft:potatoes-7

^0,100,minecraft:carrots-0,minecraft:carrots-1,minecraft:carrots-2,minecraft:carrots-3,minecraft:carrots-4,minecraft:carrots-5,minecraft:carrots-6,minecraft:carrots-7

rule8=0,100,minecraft:stone_slab-7

layer
1,2,2,2,1,2,2,2,1
2,2,2,2,2,2,2,2,2
2,2,2,2,2,2,2,2,2
2,2,2,2,2,2,2,2,2
1,2,2,2,2,2,2,2,1
2,2,2,2,2,2,2,2,2
2,2,2,2,2,2,2,2,2
2,2,2,2,2,2,2,2,2
1,2,2,2,1,2,2,2,1
endlayer

layer
1,2,2,2,1,2,2,2,1
2,2,2,2,2,2,2,2,2
2,2,2,2,2,2,2,2,2
2,2,2,2,2,2,2,2,2
1,2,2,2,2,2,2,2,1
2,2,2,2,2,2,2,2,2
2,2,2,2,2,2,2,2,2
2,2,2,2,2,2,2,2,2
1,2,2,2,1,2,2,2,1
endlayer

layer
1,2,2,2,1,2,2,2,1
2,2,2,2,2,2,2,2,2
2,2,2,2,2,2,2,2,2
2,2,2,2,2,2,2,2,2
1,2,2,2,2,2,2,2,1
2,2,2,2,2,2,2,2,2
2,2,2,2,2,2,2,2,2
2,2,2,2,2,2,2,2,2
1,2,2,2,1,2,2,2,1
endlayer

layer
1,2,2,2,1,2,2,2,1
2,2,2,2,2,2,2,2,2
2,2,2,2,2,2,2,2,2
2,2,2,2,2,2,2,2,2
1,2,2,2,3,2,2,2,1
2,2,2,2,2,2,2,2,2
2,2,2,2,2,2,2,2,2
2,2,2,2,2,2,2,2,2
1,2,2,2,1,2,2,2,1
endlayer

layer
1,4,4,4,1,4,4,4,1
4,5,5,5,5,5,5,5,4
4,5,5,5,5,5,5,5,4
4,5,5,5,5,5,5,5,4
1,6,6,6,6,6,6,6,1
4,5,5,5,5,5,5,5,4
4,5,5,5,5,5,5,5,4
4,5,5,5,5,5,5,5,4
1,4,4,4,1,4,4,4,1
endlayer

layer
3,0,0,0,3,0,0,0,3
0,7,7,7,7,7,7,7,0
0,7,7,7,7,7,7,7,0
0,7,7,7,7,7,7,7,0
3,0,0,0,0,0,0,0,3
0,7,7,7,7,7,7,7,0
0,7,7,7,7,7,7,7,0
0,7,7,7,7,7,7,7,0
3,0,0,0,3,0,0,0,3
endlayer

layer
8,0,0,0,8,0,0,0,8
0,0,0,0,0,0,0,0,0
0,0,0,0,0,0,0,0,0
0,0,0,0,0,0,0,0,0
8,0,0,0,0,0,0,0,8
0,0,0,0,0,0,0,0,0
0,0,0,0,0,0,0,0,0
0,0,0,0,0,0,0,0,0
8,0,0,0,8,0,0,0,8
endlayer

