
# Created by Ruins mod version 17.0 Ingame Parser
# authoring Player: ST753M

weight=1
embed_into_distance=6
acceptable_target_blocks=
unacceptable_target_blocks=flowing_water,water,flowing_lava,lava
dimensions=13,11,11
allowable_overhang=6
max_leveling=2
leveling_buffer=0
preserve_water=0
preserve_lava=0

rule1=0,100,preserveBlock
rule2=0,100,minecraft:end_stone-0
rule3=0,100,minecraft:purpur_pillar-4
rule4=0,100,minecraft:purpur_stairs-0
rule5=0,100,minecraft:purpur_pillar-8
rule6=0,100,minecraft:purpur_pillar-0
rule7=0,100,minecraft:purpur_block-0
rule8=0,100,minecraft:purpur_stairs-1
rule9=0,100,minecraft:purpur_slab-0
rule10=0,100,minecraft:purpur_stairs-2
rule11=0,100,minecraft:purpur_stairs-6
rule12=0,100,minecraft:purpur_stairs-3
rule13=0,100,minecraft:end_bricks-0
rule14=0,100,ChestGenHook:chests/end_city_treasure:3-4
rule15=0,100,minecraft:stained_glass_pane-10
rule16=0,100,minecraft:purpur_stairs-4
rule17=0,100,minecraft:purpur_slab-8

layer
1,1,1,1,1,1,1,1,1,1,1
1,1,1,1,1,1,1,1,1,1,1
1,1,1,1,1,1,1,1,1,1,1
1,1,1,1,1,1,1,1,1,1,1
1,1,1,1,2,2,2,1,1,1,1
1,1,1,1,2,2,2,1,1,1,1
1,1,1,1,2,2,2,1,1,1,1
1,1,1,1,1,1,1,1,1,1,1
1,1,1,1,1,1,1,1,1,1,1
1,1,1,1,1,1,1,1,1,1,1
1,1,1,1,1,1,1,1,1,1,1
endlayer

layer
1,1,1,1,1,1,1,1,1,1,1
1,1,1,1,1,1,1,1,1,1,1
1,1,1,1,2,2,2,1,1,1,1
1,1,1,2,2,2,2,2,1,1,1
1,1,2,2,2,2,2,2,2,1,1
1,1,2,2,2,2,2,2,2,1,1
1,1,2,2,2,2,2,2,2,1,1
1,1,1,2,2,2,2,2,1,1,1
1,1,1,1,2,2,2,1,1,1,1
1,1,1,1,1,1,1,1,1,1,1
1,1,1,1,1,1,1,1,1,1,1
endlayer

layer
1,1,1,1,1,1,1,1,1,1,1
1,1,2,2,2,2,2,2,2,1,1
1,2,2,2,2,2,2,2,2,2,1
1,2,2,2,2,2,2,2,2,2,1
1,2,2,2,2,2,2,2,2,2,1
1,2,2,2,2,2,2,2,2,2,1
1,2,2,2,2,2,2,2,2,2,1
1,2,2,2,2,2,2,2,2,2,1
1,2,2,2,2,2,2,2,2,2,1
1,1,2,2,2,2,2,2,2,1,1
1,1,1,1,1,1,1,1,1,1,1
endlayer

layer
1,1,1,2,2,2,2,2,1,1,1
1,1,2,2,2,2,2,2,2,1,1
1,2,2,2,2,2,2,2,2,2,1
2,2,2,2,2,2,2,2,2,2,2
2,2,2,2,2,2,2,2,2,2,2
2,2,2,2,2,2,2,2,2,2,2
2,2,2,2,2,2,2,2,2,2,2
2,2,2,2,2,2,2,2,2,2,2
1,2,2,2,2,2,2,2,2,2,1
1,1,2,2,2,2,2,2,2,1,1
1,1,1,2,2,2,2,2,1,1,1
endlayer

layer
1,1,2,2,2,2,2,2,2,1,1
1,2,2,2,2,2,2,2,2,2,1
2,2,2,2,2,2,2,2,2,2,2
2,2,2,2,2,2,2,2,2,2,2
2,2,2,2,2,2,2,2,2,2,2
2,2,2,2,2,2,2,2,2,2,2
2,2,2,2,2,2,2,2,2,2,2
2,2,2,2,2,2,2,2,2,2,2
2,2,2,2,2,2,2,2,2,2,2
1,2,2,2,2,2,2,2,2,2,1
1,1,2,2,2,2,2,2,2,1,1
endlayer

layer
1,1,1,2,2,2,2,2,1,1,1
1,2,2,2,2,2,2,2,2,2,1
1,2,2,2,2,2,2,2,2,2,1
2,2,2,2,2,2,2,2,2,2,2
2,2,2,2,2,2,2,2,2,2,2
2,2,2,2,2,2,2,2,2,2,2
2,2,2,2,2,2,2,2,2,2,2
2,2,2,2,2,2,2,2,2,2,2
1,2,2,2,2,2,2,2,2,2,1
1,2,2,2,2,2,2,2,2,2,1
1,1,1,2,2,2,2,2,1,1,1
endlayer

layer
1,3,4,4,4,3,0,0,0,3,1
5,6,5,5,5,6,5,5,5,6,5
0,3,7,7,7,7,7,7,7,3,0
0,3,7,9,11,10,9,7,8,3,0
0,3,7,7,4,8,7,12,12,3,0
5,6,7,7,7,7,4,4,7,6,5
0,3,7,7,7,7,7,7,7,3,0
0,3,7,7,7,7,7,4,7,3,0
0,3,7,7,7,7,7,7,7,3,0
5,6,5,5,5,6,5,5,5,6,5
1,3,0,0,0,3,0,0,0,3,1
endlayer

layer
0,0,0,0,0,0,0,0,0,0,0
0,6,13,0,0,6,13,13,13,6,0
0,13,0,9,0,0,0,0,0,13,0
0,13,0,0,0,0,0,0,0,13,0
0,13,10,0,0,0,0,0,0,13,0
0,6,0,4,0,0,0,0,9,6,0
0,13,7,9,0,7,10,0,0,13,0
0,13,0,7,10,7,0,0,9,13,0
0,13,0,14,7,0,4,7,0,13,0
0,6,13,13,13,6,13,13,13,6,0
0,0,0,0,0,0,0,0,0,0,0
endlayer

layer
0,0,0,0,0,0,0,0,0,0,0
0,6,13,0,0,6,13,0,13,6,0
0,0,0,0,0,0,0,0,0,13,0
0,0,0,0,0,0,0,0,0,0,0
0,13,0,0,0,0,0,0,0,13,0
0,6,0,0,0,0,0,0,0,6,0
0,13,0,0,0,0,0,0,0,13,0
0,0,0,9,0,9,0,0,0,0,0
0,13,0,0,0,0,0,0,0,13,0
0,6,13,15,13,6,13,0,13,6,0
0,0,0,0,0,0,0,0,0,0,0
endlayer

layer
0,0,0,0,0,0,0,0,0,0,0
0,6,13,0,0,0,0,0,13,6,0
0,13,0,0,0,0,0,0,0,0,0
0,0,0,0,0,0,0,0,0,0,0
0,13,0,0,0,0,0,0,0,13,0
0,6,0,0,0,0,0,0,0,6,0
0,13,0,0,0,0,0,0,0,0,0
0,0,0,0,0,0,0,0,0,0,0
0,13,0,0,0,0,0,0,0,13,0
0,6,13,15,13,6,13,0,13,6,0
0,0,0,0,0,0,0,0,0,0,0
endlayer

layer
0,0,0,0,0,0,0,0,0,0,0
0,9,0,0,0,0,0,0,0,6,0
0,13,0,0,0,0,0,0,0,0,0
0,13,0,0,0,0,0,0,0,0,0
0,13,0,0,0,0,0,0,0,0,0
0,6,0,0,0,0,0,0,0,9,0
0,13,0,0,0,0,0,0,0,0,0
0,13,0,0,0,0,0,0,0,0,0
0,13,0,0,0,0,0,0,0,13,0
0,6,13,13,13,6,13,13,13,6,0
0,0,0,0,0,0,0,0,0,0,0
endlayer

layer
0,0,0,0,0,0,0,0,0,0,0
0,0,0,0,0,0,0,0,0,0,0
0,0,0,0,0,0,0,0,0,0,0
0,0,0,0,0,0,0,0,0,0,0
0,9,0,0,0,0,0,0,0,0,0
0,6,0,0,0,0,0,0,0,0,0
9,3,0,0,0,0,0,0,0,0,0
0,3,0,0,0,0,0,0,0,0,0
12,3,0,0,0,0,0,0,0,0,0
5,6,5,5,5,6,5,5,5,6,0
0,3,8,8,0,3,0,8,8,3,0
endlayer

layer
0,0,0,0,0,0,0,0,0,0,0
0,0,0,0,0,0,0,0,0,0,0
0,0,0,0,0,0,0,0,0,0,0
0,0,0,0,0,0,0,0,0,0,0
0,0,0,0,0,0,0,0,0,0,0
0,9,0,0,0,0,0,0,0,0,0
0,0,0,0,0,0,0,0,0,0,0
0,9,11,0,0,0,0,0,0,0,0
0,12,16,17,17,16,11,0,0,0,0
0,12,8,9,8,8,8,9,8,10,0
0,0,0,0,0,0,0,0,0,0,0
endlayer

