
# Created by Ruins mod version 17.1 Ingame Parser
# authoring Player: ST753M

weight=1
embed_into_distance=0
acceptable_target_blocks=
unacceptable_target_blocks=flowing_water,water,flowing_lava,lava
dimensions=5,31,31
allowable_overhang=0
max_leveling=0
leveling_buffer=-1
preserve_water=0
preserve_lava=0

rule1=0,100,minecraft:bedrock-0

rule2=0,100,minecraft:stone_slab-9
^0,100,minecraft:stone_slab-9
^0,100,minecraft:stone_slab-9
^0,100,minecraft:stone_slab-9
^0,100,minecraft:stone_slab-9
^0,100,minecraft:stone_slab-9
^0,100,minecraft:stone_slab-11
^0,100,minecraft:stone_slab-11
^0,100,minecraft:stone_slab-13
^0,100,minecraft:stone_slab-13
^0,100,minecraft:stone_slab-13
^0,100,minecraft:stone_slab-13
^0,100,minecraft:stone_slab-13
^0,100,minecraft:stone_slab-14
^0,100,minecraft:stone_slab-14
^0,100,minecraft:stone_slab-14
^0,100,minecraft:stone_slab-14
^0,100,minecraft:stone_slab-14
^0,100,minecraft:stone_slab-14
^0,100,minecraft:stone_slab-15
^0,100,minecraft:stone_slab-15
^0,100,minecraft:stone_slab-15
^0,100,minecraft:stone_slab-15
^0,100,minecraft:stone_slab-15
^0,100,minecraft:stone_slab2-8
^0,100,minecraft:stone_slab2-8
^0,100,minecraft:stone_slab2-8
^0,100,minecraft:stone_slab2-8
rule3^0,100,minecraft:sandstone-1
^0,100,minecraft:concrete-14
^0,100,minecraft:magma-0
^0,100,minecraft:sandstone-2
^0,100,minecraft:stained_hardened_clay-14
^0,100,minecraft:sandstone-0
^0,100,minecraft:cobblestone-0
^0,100,minecraft:stone-0
^0,100,minecraft:stonebrick-0
^0,100,minecraft:stonebrick-2
^0,100,minecraft:stone-3
^0,100,minecraft:stone-0
^0,100,minecraft:cobblestone-0
^0,100,minecraft:concrete-14
^0,100,minecraft:magma-0
^0,100,minecraft:red_nether_brick-0
^0,100,minecraft:nether_brick-0
^0,100,minecraft:nether_brick-0
^0,100,minecraft:nether_brick-0
^0,100,minecraft:magma-0
^0,100,minecraft:red_nether_brick-0
^0,100,minecraft:obsidian-0
^0,100,minecraft:stained_hardened_clay-14
^0,100,minecraft:quartz_block-2
^0,100,minecraft:stained_hardened_clay-1
^0,100,minecraft:magma-0
^0,100,minecraft:red_sandstone-1,minecraft:red_sandstone-2
^0,100,minecraft:red_sandstone-0
rule4^0,100,minecraft:stone_slab-1
^0,100,minecraft:stone_slab-1
^0,100,minecraft:stone_slab-1
^0,100,minecraft:stone_slab-1
^0,100,minecraft:stone_slab-1
^0,100,minecraft:stone_slab-1
^0,100,minecraft:stone_slab-3
^0,100,minecraft:stone_slab-3
^0,100,minecraft:stone_slab-5
^0,100,minecraft:stone_slab-5
^0,100,minecraft:stone_slab-5
^0,100,minecraft:stone_slab-5
^0,100,minecraft:stone_slab-5
^0,100,minecraft:stone_slab-6
^0,100,minecraft:stone_slab-6
^0,100,minecraft:stone_slab-6
^0,100,minecraft:stone_slab-6
^0,100,minecraft:stone_slab-6
^0,100,minecraft:stone_slab-6
^0,100,minecraft:stone_slab-7
^0,100,minecraft:stone_slab-7
^0,100,minecraft:stone_slab-7
^0,100,minecraft:stone_slab-7
^0,100,minecraft:stone_slab-7
^0,100,minecraft:stone_slab2-0
^0,100,minecraft:stone_slab2-0
^0,100,minecraft:stone_slab2-0
^0,100,minecraft:stone_slab2-0

rule5=0,100,minecraft:iron_trapdoor-2
rule6=0,100,MobSpawner:silverfish,MobSpawner:blaze,MobSpawner:silverfish

rule7=0,100,CommandBlock:RUINSTRIGGER /summon blaze ~ ~ ~ {PersistenceRequired:1}:@-1

rule8=0,100,IInventory;minecraft:chest;minecraft:rotten_flesh#12#0#4+minecraft:record_cat#1#0#9+minecraft:iron_horse_armor#1#0#23-2,IInventory;minecraft:chest;minecraft:golden_horse_armor#1#0#13+minecraft:record_ward#1#0#19+minecraft:poisonous_potato#10#0#24-2,IInventory;minecraft:chest;minecraft:record_blocks#1#0#12+minecraft:potion#{Potion:"minecraft:long_fire_resistance"}#0#19+minecraft:blaze_rod#3#0#24-2,IInventory;minecraft:chest;minecraft:record_chirp#1#0#5+minecraft:emerald#3#0#10+minecraft:potion#{Potion:"minecraft:fire_resistance"}#0#12-2,IInventory;minecraft:chest;minecraft:record_strad#1#0#5+minecraft:ender_eye#4#0#11+minecraft:potion#{Potion:"minecraft:fire_resistance"}#0#22-2,IInventory;minecraft:chest;minecraft:blaze_rod#3#0#10+minecraft:iron_horse_armor#1#0#15+minecraft:record_stal#1#0#22-2,IInventory;minecraft:chest;minecraft:potion#{Potion:"minecraft:night_vision"}#0#15+minecraft:record_11#1#0#20+minecraft:golden_horse_armor#1#0#23-2,IInventory;minecraft:chest;minecraft:record_mellohi#1#0#2+minecraft:cake#1#0#13+minecraft:potion#{Potion:"minecraft:long_fire_resistance"}#0#16-2,IInventory;minecraft:chest;minecraft:diamond_horse_armor#1#0#12+minecraft:cake#1#0#23+minecraft:record_wait#1#0#25-2,IInventory;minecraft:chest;minecraft:beetroot_seeds#12#0#2+minecraft:golden_horse_armor#1#0#16+minecraft:record_13#1#0#21-2,IInventory;minecraft:chest;minecraft:ender_pearl#5#0#10+minecraft:record_mall#1#0#14+minecraft:potion#{Potion:"minecraft:long_fire_resistance"}#0#20-2,IInventory;minecraft:chest;minecraft:record_far#1#0#11+minecraft:potion#{Potion:"minecraft:fire_resistance"}#0#14+minecraft:rotten_flesh#13#0#22-2
rule9=0,100,IInventory;minecraft:chest;minecraft:skull#1#1#6+minecraft:ender_pearl#5#0#9+minecraft:rabbit_hide#9#0#12+minecraft:spawn_egg#{EntityTag:{id:"minecraft:spider"}}#0#21-2,IInventory;minecraft:chest;minecraft:rabbit_hide#12#0#12+minecraft:skull#1#0#14+minecraft:spawn_egg#{EntityTag:{id:"minecraft:skeleton"}}#0#19+minecraft:ender_eye#6#0#26-2,IInventory;minecraft:chest;minecraft:nether_wart#7#0#3+minecraft:spawn_egg#{EntityTag:{id:"minecraft:bat"}}#0#6+minecraft:skull#1#4#20+minecraft:experience_bottle#6#0#23-2,IInventory;minecraft:chest;minecraft:ender_pearl#5#0#7+minecraft:skull#1#3#13+minecraft:experience_bottle#6#0#19+minecraft:spawn_egg#{EntityTag:{id:"minecraft:cave_spider"}}#0#24-2,IInventory;minecraft:chest;minecraft:ender_eye#3#0#3+minecraft:skull#1#2#14+minecraft:spawn_egg#{EntityTag:{id:"minecraft:zombie"}}#0#20+minecraft:fish#4#3#26-2,IInventory;minecraft:chest;minecraft:rabbit_hide#11#0#7+minecraft:spawn_egg#{EntityTag:{id:"minecraft:silverfish"}}#0#14+minecraft:skull#1#3#21+minecraft:spider_eye#10#0#24-2
rule10=0,100,IInventory;minecraft:chest;minecraft:emerald#2#0#7+minecraft:golden_leggings#1#0#10+minecraft:golden_sword#{}#0#14+minecraft:golden_apple#1#0#25-2,IInventory;minecraft:chest;minecraft:golden_apple#1#1#5+minecraft:golden_sword#{}#0#12+minecraft:gold_ingot#6#0#16+minecraft:golden_helmet#1#0#23-2,IInventory;minecraft:chest;minecraft:golden_pickaxe#1#0#3+minecraft:golden_apple#1#0#14+minecraft:golden_helmet#1#0#20+minecraft:emerald#2#0#25-2,IInventory;minecraft:chest;minecraft:emerald#3#0#8+minecraft:golden_chestplate#1#0#10+minecraft:golden_apple#1#0#15+minecraft:golden_axe#{}#0#22-2,IInventory;minecraft:chest;minecraft:gold_ingot#5#0#6+minecraft:golden_boots#1#0#11+minecraft:golden_apple#1#1#14+minecraft:golden_shovel#1#0#21-2,IInventory;minecraft:chest;minecraft:golden_sword#{}#0#1+minecraft:golden_apple#1#1#14+minecraft:gold_ingot#5#0#16+minecraft:golden_chestplate#1#0#20-2

layer
1,1,1,1,1,1,1,1,1,1,1,1,1,1,1,1,1,1,1,1,1,1,1,1,1,1,1,1,1,1,1
1,1,1,1,1,1,1,1,1,1,1,1,1,1,1,1,1,1,1,1,1,1,1,1,1,1,1,1,1,1,1
1,1,1,1,1,1,1,1,1,1,1,1,1,1,1,1,1,1,1,1,1,1,1,1,1,1,1,1,1,1,1
1,1,1,1,1,1,1,1,1,1,1,1,1,1,1,1,1,1,1,1,1,1,1,1,1,1,1,1,1,1,1
1,1,1,1,1,1,1,1,1,1,1,1,1,1,1,1,1,1,1,1,1,1,1,1,1,1,1,1,1,1,1
1,1,1,1,1,1,1,1,1,1,1,1,1,1,1,1,1,1,1,1,1,1,1,1,1,1,1,1,1,1,1
1,1,1,1,1,1,1,1,1,1,1,1,1,1,1,1,1,1,1,1,1,1,1,1,1,1,1,1,1,1,1
1,1,1,1,1,1,1,1,1,1,1,1,1,1,1,1,1,1,1,1,1,1,1,1,1,1,1,1,1,1,1
1,1,1,1,1,1,1,1,1,1,1,1,1,1,1,1,1,1,1,1,1,1,1,1,1,1,1,1,1,1,1
1,1,1,1,1,1,1,1,1,1,1,1,1,1,1,1,1,1,1,1,1,1,1,1,1,1,1,1,1,1,1
1,1,1,1,1,1,1,1,1,1,1,1,1,1,1,1,1,1,1,1,1,1,1,1,1,1,1,1,1,1,1
1,1,1,1,1,1,1,1,1,1,1,1,1,1,1,1,1,1,1,1,1,1,1,1,1,1,1,1,1,1,1
1,1,1,1,1,1,1,1,1,1,1,1,4,3,3,3,3,3,2,1,1,1,1,1,1,1,1,1,1,1,1
1,1,1,1,1,1,1,1,1,1,1,1,3,3,3,3,3,3,3,1,1,1,1,1,1,1,1,1,1,1,1
1,1,1,1,1,1,1,1,1,1,1,1,3,3,5,5,5,3,3,1,1,1,1,1,1,1,1,1,1,1,1
1,1,1,1,1,1,1,1,1,1,1,1,3,3,5,5,5,3,3,1,1,1,1,1,1,1,1,1,1,1,1
1,1,1,1,1,1,1,1,1,1,1,1,3,3,5,5,5,3,3,1,1,1,1,1,1,1,1,1,1,1,1
1,1,1,1,1,1,1,1,1,1,1,1,3,3,3,3,3,3,3,1,1,1,1,1,1,1,1,1,1,1,1
1,1,1,1,1,1,1,1,1,1,1,1,2,3,3,3,3,3,4,1,1,1,1,1,1,1,1,1,1,1,1
1,1,1,1,1,1,1,1,1,1,1,1,1,1,1,1,1,1,1,1,1,1,1,1,1,1,1,1,1,1,1
1,1,1,1,1,1,1,1,1,1,1,1,1,1,1,1,1,1,1,1,1,1,1,1,1,1,1,1,1,1,1
1,1,1,1,1,1,1,1,1,1,1,1,1,1,1,1,1,1,1,1,1,1,1,1,1,1,1,1,1,1,1
1,1,1,1,1,1,1,1,1,1,1,1,1,1,1,1,1,1,1,1,1,1,1,1,1,1,1,1,1,1,1
1,1,1,1,1,1,1,1,1,1,1,1,1,1,1,1,1,1,1,1,1,1,1,1,1,1,1,1,1,1,1
1,1,1,1,1,1,1,1,1,1,1,1,1,1,1,1,1,1,1,1,1,1,1,1,1,1,1,1,1,1,1
1,1,1,1,1,1,1,1,1,1,1,1,1,1,1,1,1,1,1,1,1,1,1,1,1,1,1,1,1,1,1
1,1,1,1,1,1,1,1,1,1,1,1,1,1,1,1,1,1,1,1,1,1,1,1,1,1,1,1,1,1,1
1,1,1,1,1,1,1,1,1,1,1,1,1,1,1,1,1,1,1,1,1,1,1,1,1,1,1,1,1,1,1
1,1,1,1,1,1,1,1,1,1,1,1,1,1,1,1,1,1,1,1,1,1,1,1,1,1,1,1,1,1,1
1,1,1,1,1,1,1,1,1,1,1,1,1,1,1,1,1,1,1,1,1,1,1,1,1,1,1,1,1,1,1
1,1,1,1,1,1,1,1,1,1,1,1,1,1,1,1,1,1,1,1,1,1,1,1,1,1,1,1,1,1,1
endlayer

layer
1,1,1,1,1,1,1,1,1,1,1,1,1,1,1,1,1,1,1,1,1,1,1,1,1,1,1,1,1,1,1
1,4,4,4,3,2,1,4,4,4,4,4,1,4,4,4,3,4,1,4,4,3,4,4,1,4,4,3,4,3,1
1,4,3,4,4,4,1,4,3,4,3,4,1,4,3,4,4,4,1,3,4,4,3,4,1,3,4,4,4,3,1
1,1,1,4,3,4,1,4,4,1,1,1,6,1,1,1,4,3,4,1,1,4,4,4,1,4,4,1,1,1,1
1,4,4,1,4,4,4,3,4,3,4,3,1,4,3,4,4,4,4,4,3,1,4,3,3,4,3,4,4,4,1
1,3,4,1,4,3,4,4,4,4,4,4,1,4,4,4,3,4,3,4,4,1,4,4,4,4,4,4,3,4,1
1,4,4,1,4,4,1,1,1,4,3,2,1,3,4,1,1,1,0,0,3,1,4,3,1,1,1,4,3,4,1
1,4,3,4,3,4,4,4,3,1,4,4,4,3,4,4,4,4,1,0,0,0,4,3,4,4,4,1,4,4,1
1,4,4,4,4,4,3,4,4,1,4,3,4,4,4,3,4,3,1,3,0,3,4,4,4,3,4,1,4,3,1
1,4,3,1,1,1,4,4,3,1,4,4,1,1,1,4,4,4,1,0,0,0,1,1,4,3,4,1,4,4,1
1,4,3,4,4,4,1,4,4,1,4,3,4,4,4,1,3,4,1,0,3,1,4,4,1,4,4,1,3,4,1
1,4,4,4,3,4,1,3,4,1,4,4,4,3,4,1,4,4,1,0,0,1,4,3,1,4,3,1,4,4,1
1,1,1,4,3,4,4,1,1,4,1,1,1,1,1,1,1,1,6,1,1,4,4,4,4,1,1,4,1,1,1
1,4,3,1,4,4,1,4,3,4,4,4,1,4,4,4,4,4,1,3,4,1,3,4,3,4,4,4,3,4,1
1,4,4,1,4,3,1,4,4,4,3,4,1,4,0,0,0,0,4,4,4,1,4,4,4,4,3,4,4,4,1
1,3,4,1,4,4,4,1,1,4,3,4,1,4,0,0,0,0,4,4,3,1,4,3,1,1,1,4,3,4,1
1,4,4,4,3,4,3,4,3,1,4,4,1,4,0,0,0,0,4,4,4,4,4,4,4,4,3,1,4,4,1
1,4,3,4,4,4,4,4,4,1,3,3,1,4,4,4,4,4,1,3,4,3,3,4,3,4,4,1,4,3,1
1,4,4,1,1,1,4,3,4,1,4,4,1,1,1,1,1,1,1,4,4,4,1,1,4,4,3,4,1,1,1
1,4,4,4,3,4,1,4,4,4,4,3,4,4,4,1,4,4,4,3,4,1,3,3,1,4,4,4,4,4,1
1,4,3,4,4,4,1,4,3,3,4,4,4,3,4,1,4,3,4,4,4,1,4,4,1,4,3,4,3,4,1
1,1,1,4,1,1,6,1,1,1,1,1,1,4,4,1,4,4,1,1,1,4,4,3,1,4,4,1,4,4,1
1,4,4,1,3,4,1,3,4,4,4,4,4,3,4,1,3,4,4,4,4,1,4,3,4,3,4,1,4,3,1
1,3,4,1,4,4,1,4,4,3,4,3,4,4,4,1,4,4,4,3,4,1,4,4,4,4,4,1,4,4,1
1,4,4,1,4,3,4,1,1,4,4,4,1,4,3,1,4,3,4,1,1,6,1,1,1,1,1,4,3,4,1
1,4,3,4,4,4,4,3,4,1,4,3,1,4,4,4,4,4,1,4,4,1,3,4,4,4,3,4,4,4,1
1,4,4,4,3,3,4,4,4,1,4,3,1,3,4,3,4,3,1,4,3,1,4,4,3,4,4,4,3,4,1
1,1,1,3,1,1,4,3,4,1,4,4,3,1,1,4,4,4,1,4,4,4,1,1,1,3,4,1,4,4,1
1,3,3,4,3,4,1,4,4,4,3,4,4,4,3,1,4,3,4,4,4,3,4,4,4,3,4,1,4,3,1
1,3,4,4,4,4,1,4,3,4,4,4,3,4,4,1,4,4,4,3,4,4,4,3,4,4,4,1,4,4,1
1,1,1,1,1,1,1,1,1,1,1,1,1,1,1,1,1,1,1,1,1,1,1,1,1,1,1,1,1,1,1
endlayer

layer
3,3,3,3,3,3,3,3,3,3,3,3,3,3,3,3,3,3,3,3,3,3,3,3,3,3,3,3,3,3,3
3,0,0,0,3,0,3,0,0,0,0,0,3,0,0,0,3,0,3,0,0,3,0,0,3,0,0,3,7,3,3
3,0,3,0,0,0,3,0,3,0,3,7,3,0,3,0,0,0,3,3,0,0,3,0,3,3,0,0,7,8,3
3,3,3,0,3,0,3,0,0,3,3,3,1,3,3,3,0,3,0,3,3,0,0,0,3,0,0,3,3,3,3
3,0,0,3,0,0,0,3,0,3,0,3,3,0,3,0,0,0,0,0,3,3,0,3,3,0,3,0,0,0,3
3,3,0,3,0,3,0,0,0,0,0,0,3,0,0,0,3,0,3,0,0,3,0,0,0,0,0,0,3,0,3
3,0,0,3,0,0,3,3,3,0,3,0,3,3,0,3,3,3,0,0,3,3,0,3,3,3,3,0,3,0,3
3,0,3,0,3,0,0,0,3,3,0,0,0,3,0,0,0,0,3,0,0,0,0,3,0,0,0,3,0,0,3
3,0,0,0,0,0,3,0,0,3,0,3,0,0,0,3,0,3,3,3,0,3,0,0,0,3,0,3,0,3,3
3,0,3,3,3,3,0,0,3,3,0,0,3,3,3,0,0,0,3,0,0,0,3,3,0,3,0,3,0,0,3
3,0,3,0,0,0,3,0,0,3,0,3,0,0,0,3,3,0,3,0,3,3,0,0,3,0,0,3,3,0,3
3,0,0,0,3,0,3,3,0,3,0,0,0,3,0,3,0,0,3,0,0,3,0,3,3,0,3,3,0,0,3
3,3,3,0,3,0,0,3,3,0,3,3,3,3,3,3,3,3,1,3,3,0,0,0,0,3,3,0,3,3,3
3,0,3,3,0,0,3,7,3,0,0,0,3,0,0,0,0,0,3,3,0,3,3,0,3,0,0,0,3,0,3
3,0,0,3,0,3,3,0,0,0,3,0,3,0,0,0,0,0,0,0,0,3,0,0,0,0,3,0,0,0,3
3,3,7,3,0,0,0,3,3,0,3,0,3,0,0,0,0,0,0,0,3,3,0,3,3,3,3,0,3,0,3
3,0,0,0,3,0,3,0,3,3,0,0,3,0,0,0,0,0,0,0,0,0,0,0,0,0,3,3,0,0,3
3,0,3,0,0,0,0,0,0,3,3,3,3,0,0,0,0,0,3,3,0,3,3,0,3,0,0,3,7,3,3
3,0,0,3,3,3,0,3,0,3,0,0,3,3,3,3,3,3,3,0,0,0,3,3,0,0,3,0,3,3,3
3,0,0,0,3,0,3,0,0,0,0,3,0,0,0,3,0,0,0,3,0,3,9,3,3,0,0,0,0,0,3
3,0,3,0,0,0,3,0,3,3,0,0,0,3,0,3,0,3,0,0,0,3,0,7,3,0,3,0,3,0,3
3,3,3,0,3,3,1,3,3,3,3,3,3,0,0,3,0,0,3,3,3,0,0,3,3,0,0,3,0,0,3
3,7,0,3,3,0,3,3,0,0,0,0,0,3,0,3,3,0,0,0,0,3,0,3,0,3,0,3,0,3,3
3,3,0,3,0,0,3,0,0,3,0,3,0,0,0,3,0,0,0,3,0,3,0,0,0,0,0,3,0,0,3
3,0,0,3,0,3,0,3,3,0,0,0,3,0,3,3,0,3,0,3,3,1,3,3,3,3,3,0,3,0,3
3,0,3,0,0,0,0,3,0,3,0,3,3,0,0,0,0,0,3,0,0,3,3,0,0,0,3,0,0,0,3
3,0,0,0,3,3,0,0,0,3,0,3,3,3,0,3,0,3,3,0,3,3,0,0,3,0,0,0,3,0,3
3,3,3,3,3,3,0,3,0,3,0,0,3,3,3,0,0,0,3,0,0,0,3,3,3,3,0,3,0,0,3
3,3,3,0,3,0,3,0,0,0,3,0,0,0,3,3,0,3,0,0,0,3,0,0,0,3,0,3,0,3,3
3,10,0,0,0,0,3,0,3,0,0,0,3,0,0,3,0,0,0,3,0,0,0,3,0,0,0,3,0,0,3
3,3,3,3,3,3,3,3,3,3,3,3,3,3,3,3,3,3,3,3,3,3,3,3,3,3,3,3,3,3,3
endlayer

layer
1,1,1,1,1,1,1,1,1,1,1,1,1,1,1,1,1,1,1,1,1,1,1,1,1,1,1,1,1,1,1
1,2,2,2,3,2,1,2,2,2,2,2,1,2,2,2,3,2,1,2,2,3,2,2,1,2,2,3,2,3,1
1,2,3,2,2,2,1,2,3,2,3,2,1,2,3,2,2,2,1,3,2,2,3,2,1,3,2,2,2,2,1
1,1,1,2,3,2,1,2,2,1,1,1,1,1,1,1,2,3,2,1,1,2,2,2,1,2,2,1,1,1,1
1,2,2,1,2,2,2,3,2,3,2,3,1,2,3,2,2,2,2,2,3,1,2,3,3,2,3,2,2,2,1
1,3,2,1,2,3,2,2,2,2,2,2,1,2,2,2,3,2,3,2,2,1,2,2,2,2,2,2,3,2,1
1,2,2,1,2,2,1,1,1,2,3,2,1,3,2,1,1,1,2,2,3,1,2,3,1,1,1,2,3,2,1
1,2,3,2,3,2,2,2,3,1,2,2,2,3,2,2,2,2,1,2,2,2,2,3,2,2,2,1,2,2,1
1,2,2,2,2,2,3,2,2,1,2,3,2,2,2,3,2,3,1,3,2,3,2,2,2,3,2,1,2,3,1
1,2,3,1,1,1,2,2,3,1,2,2,1,1,1,2,2,2,1,2,2,2,1,1,2,3,2,1,2,2,1
1,2,3,2,2,2,1,2,2,1,2,3,2,2,2,1,3,2,1,2,3,1,2,2,1,2,2,1,3,2,1
1,2,2,2,3,2,1,3,2,1,2,2,2,3,2,1,2,2,1,2,2,1,2,3,1,2,3,1,2,2,1
1,1,1,2,3,2,2,1,1,2,1,1,1,1,1,1,1,1,1,1,1,2,2,2,2,1,1,2,1,1,1
1,2,3,1,2,2,1,2,3,2,2,2,1,2,2,2,2,2,1,3,2,1,3,2,3,2,2,2,3,2,1
1,2,2,1,2,3,1,2,2,2,3,2,1,2,2,2,2,2,2,2,2,1,2,2,2,2,3,2,2,2,1
1,3,2,1,2,2,2,1,1,2,3,2,1,2,2,2,2,2,2,2,3,1,2,3,1,1,1,2,3,2,1
1,2,2,2,3,2,3,2,3,1,2,2,1,2,2,2,2,2,2,2,2,2,2,2,2,2,3,1,2,2,1
1,2,3,2,2,2,2,2,2,1,3,3,1,2,2,2,2,2,1,3,2,3,3,2,3,2,2,1,2,3,1
1,2,2,1,1,1,2,3,2,1,2,2,1,1,1,1,1,1,1,2,2,2,1,1,2,2,3,2,1,1,1
1,2,2,2,3,2,1,2,2,2,2,3,2,2,2,1,2,2,2,3,2,1,2,3,1,2,2,2,2,2,1
1,2,3,2,2,2,1,2,3,3,2,2,2,3,2,1,2,3,2,2,2,1,2,2,1,2,3,2,3,2,1
1,1,1,2,1,1,1,1,1,1,1,1,1,2,2,1,2,2,1,1,1,2,2,3,1,2,2,1,2,2,1
1,2,2,1,3,2,1,3,2,2,2,2,2,3,2,1,3,2,2,2,2,1,2,3,2,3,2,1,2,3,1
1,3,2,1,2,2,1,2,2,3,2,3,2,2,2,1,2,2,2,3,2,1,2,2,2,2,2,1,2,2,1
1,2,2,1,2,3,2,1,1,2,2,2,1,2,3,1,2,3,2,1,1,1,1,1,1,1,1,2,3,2,1
1,2,3,2,2,2,2,3,2,1,2,3,1,2,2,2,2,2,1,2,2,1,3,2,2,2,3,2,2,2,1
1,2,2,2,3,3,2,2,2,1,2,3,1,3,2,3,2,3,1,2,3,1,2,2,3,2,2,2,3,2,1
1,1,1,3,1,1,2,3,2,1,2,2,3,1,1,2,2,2,1,2,2,2,1,1,1,3,2,1,2,2,1
1,3,3,2,3,2,1,2,2,2,3,2,2,2,3,1,2,3,2,2,2,3,2,2,2,3,2,1,2,3,1
1,2,2,2,2,2,1,2,3,2,2,2,3,2,2,1,2,2,2,3,2,2,2,3,2,2,2,1,2,2,1
1,1,1,1,1,1,1,1,1,1,1,1,1,1,1,1,1,1,1,1,1,1,1,1,1,1,1,1,1,1,1
endlayer

layer
1,1,1,1,1,1,1,1,1,1,1,1,1,1,1,1,1,1,1,1,1,1,1,1,1,1,1,1,1,1,1
1,1,1,1,1,1,1,1,1,1,1,1,1,1,1,1,1,1,1,1,1,1,1,1,1,1,1,1,1,1,1
1,1,1,1,1,1,1,1,1,1,1,1,1,1,1,1,1,1,1,1,1,1,1,1,1,1,1,1,1,1,1
1,1,1,1,1,1,1,1,1,1,1,1,1,1,1,1,1,1,1,1,1,1,1,1,1,1,1,1,1,1,1
1,1,1,1,1,1,1,1,1,1,1,1,1,1,1,1,1,1,1,1,1,1,1,1,1,1,1,1,1,1,1
1,1,1,1,1,1,1,1,1,1,1,1,1,1,1,1,1,1,1,1,1,1,1,1,1,1,1,1,1,1,1
1,1,1,1,1,1,1,1,1,1,1,1,1,1,1,1,1,1,1,1,1,1,1,1,1,1,1,1,1,1,1
1,1,1,1,1,1,1,1,1,1,1,1,1,1,1,1,1,1,1,1,1,1,1,1,1,1,1,1,1,1,1
1,1,1,1,1,1,1,1,1,1,1,1,1,1,1,1,1,1,1,1,1,1,1,1,1,1,1,1,1,1,1
1,1,1,1,1,1,1,1,1,1,1,1,1,1,1,1,1,1,1,1,1,1,1,1,1,1,1,1,1,1,1
1,1,1,1,1,1,1,1,1,1,1,1,1,1,1,1,1,1,1,1,1,1,1,1,1,1,1,1,1,1,1
1,1,1,1,1,1,1,1,1,1,1,1,1,1,1,1,1,1,1,1,1,1,1,1,1,1,1,1,1,1,1
1,1,1,1,1,1,1,1,1,1,1,1,1,1,1,1,1,1,1,1,1,1,1,1,1,1,1,1,1,1,1
1,1,1,1,1,1,1,1,1,1,1,1,1,1,1,1,1,1,1,1,1,1,1,1,1,1,1,1,1,1,1
1,1,1,1,1,1,1,1,1,1,1,1,1,1,1,1,1,1,1,1,1,1,1,1,1,1,1,1,1,1,1
1,1,1,1,1,1,1,1,1,1,1,1,1,1,1,1,1,1,1,1,1,1,1,1,1,1,1,1,1,1,1
1,1,1,1,1,1,1,1,1,1,1,1,1,1,1,1,1,1,1,1,1,1,1,1,1,1,1,1,1,1,1
1,1,1,1,1,1,1,1,1,1,1,1,1,1,1,1,1,1,1,1,1,1,1,1,1,1,1,1,1,1,1
1,1,1,1,1,1,1,1,1,1,1,1,1,1,1,1,1,1,1,1,1,1,1,1,1,1,1,1,1,1,1
1,1,1,1,1,1,1,1,1,1,1,1,1,1,1,1,1,1,1,1,1,1,1,1,1,1,1,1,1,1,1
1,1,1,1,1,1,1,1,1,1,1,1,1,1,1,1,1,1,1,1,1,1,1,1,1,1,1,1,1,1,1
1,1,1,1,1,1,1,1,1,1,1,1,1,1,1,1,1,1,1,1,1,1,1,1,1,1,1,1,1,1,1
1,1,1,1,1,1,1,1,1,1,1,1,1,1,1,1,1,1,1,1,1,1,1,1,1,1,1,1,1,1,1
1,1,1,1,1,1,1,1,1,1,1,1,1,1,1,1,1,1,1,1,1,1,1,1,1,1,1,1,1,1,1
1,1,1,1,1,1,1,1,1,1,1,1,1,1,1,1,1,1,1,1,1,1,1,1,1,1,1,1,1,1,1
1,1,1,1,1,1,1,1,1,1,1,1,1,1,1,1,1,1,1,1,1,1,1,1,1,1,1,1,1,1,1
1,1,1,1,1,1,1,1,1,1,1,1,1,1,1,1,1,1,1,1,1,1,1,1,1,1,1,1,1,1,1
1,1,1,1,1,1,1,1,1,1,1,1,1,1,1,1,1,1,1,1,1,1,1,1,1,1,1,1,1,1,1
1,1,1,1,1,1,1,1,1,1,1,1,1,1,1,1,1,1,1,1,1,1,1,1,1,1,1,1,1,1,1
1,1,1,1,1,1,1,1,1,1,1,1,1,1,1,1,1,1,1,1,1,1,1,1,1,1,1,1,1,1,1
1,1,1,1,1,1,1,1,1,1,1,1,1,1,1,1,1,1,1,1,1,1,1,1,1,1,1,1,1,1,1
endlayer

