
# Created by Ruins mod version 16.7 Ingame Parser
# authoring Player: ST753M

weight=1
embed_into_distance=1
acceptable_target_blocks=
unacceptable_target_blocks=flowing_water,water,flowing_lava,lava
dimensions=11,15,15
allowable_overhang=0
max_leveling=0
leveling_buffer=0
preserve_water=0
preserve_lava=0

rule1=0,100,preserveBlock
rule2=0,100,minecraft:lava-0
rule3=0,100,minecraft:nether_brick-0
rule4=0,100,minecraft:nether_brick_stairs-6
rule5=0,100,minecraft:nether_brick_stairs-4
rule6=0,100,minecraft:nether_brick_stairs-7
rule7=0,100,minecraft:stone_slab-14
rule8=0,100,minecraft:nether_brick_stairs-5
rule9=0,100,minecraft:nether_brick_fence-0
rule10=0,100,minecraft:stained_glass_pane-14

rule11=0,30,CommandBlock:RUINSTRIGGER /summon villager ~ ~1 ~ {Profession:2,Offers:{Recipes:[{rewardExp:0b,maxUses:256,uses:0,buy:{id:"minecraft:emerald",Count:32b},sell:{id:"minecraft:spawn_egg",Damage:56,Count:1b,tag:{EntityTag:{id:"minecraft:ghast"}}}},{rewardExp:0b,maxUses:2147483647,uses:0,buy:{id:"minecraft:emerald",Count:2b},sell:{id:"minecraft:nether_brick",Count:32b}}]}}:@-1,CommandBlock:RUINSTRIGGER /summon villager ~ ~1 ~ {Profession:2,Offers:{Recipes:[{rewardExp:0b,maxUses:256,uses:0,buy:{id:"minecraft:emerald",Count:16b},sell:{id:"minecraft:spawn_egg",Damage:57,Count:1b,tag:{EntityTag:{id:"minecraft:zombie_pigman"}}}},{rewardExp:0b,maxUses:2147483647,uses:0,buy:{id:"minecraft:emerald",Count:1b},sell:{id:"minecraft:quartz",Count:8b}}]}}:@-1,CommandBlock:RUINSTRIGGER /summon villager ~ ~1 ~ {Profession:2,Offers:{Recipes:[{rewardExp:0b,maxUses:256,uses:0,buy:{id:"minecraft:emerald",Count:8b},sell:{id:"minecraft:spawn_egg",Damage:61,Count:1b,tag:{EntityTag:{id:"minecraft:blaze"}}}},{rewardExp:0b,maxUses:2147483647,uses:0,buy:{id:"minecraft:quartz",Count:32b},sell:{id:"minecraft:emerald",Count:1b}}]}}:@-1,CommandBlock:RUINSTRIGGER /summon villager ~ ~1 ~ {Profession:2,Offers:{Recipes:[{rewardExp:0b,maxUses:256,uses:0,buy:{id:"minecraft:emerald",Count:10b},sell:{id:"minecraft:spawn_egg",Damage:62,Count:1b,tag:{EntityTag:{id:"minecraft:magma_cube"}}}},{rewardExp:0b,maxUses:2147483647,uses:0,buy:{id:"minecraft:quartz",Count:38b},sell:{id:"minecraft:emerald",Count:1b}}]}}:@-1,CommandBlock:RUINSTRIGGER /summon villager ~ ~1 ~ {Profession:2,Offers:{Recipes:[{rewardExp:0b,maxUses:256,uses:0,buy:{id:"minecraft:emerald",Count:2b},sell:{id:"minecraft:obsidian",Count:12b}},{rewardExp:0b,maxUses:2147483647,uses:0,buy:{id:"minecraft:quartz",Count:29b},sell:{id:"minecraft:emerald",Count:1b}}]}}:@-1,CommandBlock:RUINSTRIGGER /summon villager ~ ~1 ~ {Profession:2,Offers:{Recipes:[{rewardExp:0b,maxUses:256,uses:0,buy:{id:"minecraft:emerald",Count:1b},sell:{id:"minecraft:glowstone_dust",Count:7b}},{rewardExp:0b,maxUses:2147483647,uses:0,buy:{id:"minecraft:blaze_rod",Count:10b},sell:{id:"minecraft:emerald",Count:1b}}]}}:@-1,CommandBlock:RUINSTRIGGER /summon villager ~ ~1 ~ {Profession:2,Offers:{Recipes:[{rewardExp:0b,maxUses:256,uses:0,buy:{id:"minecraft:emerald",Count:1b},sell:{id:"minecraft:blaze_powder",Count:4b}},{rewardExp:0b,maxUses:2147483647,uses:0,buy:{id:"minecraft:water_bucket",Count:1b},sell:{id:"minecraft:emerald",Count:1b}}]}}:@-1,CommandBlock:RUINSTRIGGER /summon villager ~ ~1 ~ {Profession:2,Offers:{Recipes:[{rewardExp:0b,maxUses:256,uses:0,buy:{id:"minecraft:blaze_powder",Count:2b},sell:{id:"minecraft:blaze_rod",Count:1b}},{rewardExp:0b,maxUses:6,uses:0,buy:{id:"minecraft:emerald",Count:20b},sell:{id:"minecraft:skull",Damage:1,Count:1b}}]}}:@-1,CommandBlock:RUINSTRIGGER /summon villager ~ ~1 ~ {Profession:2,Offers:{Recipes:[{rewardExp:0b,maxUses:256,uses:0,buy:{id:"minecraft:emerald",Count:32b},sell:{id:"minecraft:flint_and_steel",Count:1b,tag:{Unbreakable:1}}},{rewardExp:0b,maxUses:256,uses:0,buy:{id:"minecraft:skull",Damage:1,Count:1b},sell:{id:"minecraft:emerald",Count:8b}}]}}:@-1,CommandBlock:RUINSTRIGGER /summon villager ~ ~1 ~ {Profession:2,Offers:{Recipes:[{rewardExp:0b,maxUses:256,uses:0,buy:{id:"minecraft:emerald",Count:4b},sell:{id:"minecraft:ghast_tear",Count:1b}},{rewardExp:0b,maxUses:256,uses:0,buy:{id:"minecraft:glowstone_dust",Count:23b},sell:{id:"minecraft:emerald",Count:1b}}]}}:@-1,CommandBlock:RUINSTRIGGER /summon villager ~ ~1 ~ {Profession:2,Offers:{Recipes:[{rewardExp:0b,maxUses:256,uses:0,buy:{id:"minecraft:obsidian",Count:12b},sell:{id:"minecraft:emerald",Count:1b}},{rewardExp:0b,maxUses:256,uses:0,buy:{id:"minecraft:glowstone",Count:8b},sell:{id:"minecraft:glowstone_dust",Count:30b}}]}}:@-1

rule12=0,100,minecraft:glowstone-0
rule13=0,100,minecraft:nether_brick_stairs-2
rule14=0,100,minecraft:nether_brick_stairs-0
rule15=0,100,minecraft:nether_brick_stairs-3
rule16=0,100,minecraft:nether_brick_stairs-1
rule17=0,100,minecraft:stone_slab-6

layer
1,1,1,1,1,1,1,1,1,1,1,1,1,1,1
1,1,1,1,1,2,2,2,2,2,1,1,1,1,1
1,1,1,2,2,2,2,2,2,2,2,2,1,1,1
1,1,2,2,2,2,2,2,2,2,2,2,2,1,1
1,1,2,2,2,2,2,2,2,2,2,2,2,1,1
1,2,2,2,2,3,2,2,2,3,2,2,2,2,1
1,2,2,2,2,2,2,2,2,2,2,2,2,2,1
1,2,2,2,2,2,2,2,2,2,2,2,2,2,1
1,2,2,2,2,2,2,2,2,2,2,2,2,2,1
1,2,2,2,2,3,2,2,2,3,2,2,2,2,1
1,1,2,2,2,2,2,2,2,2,2,2,2,1,1
1,1,2,2,2,2,2,2,2,2,2,2,2,1,1
1,1,1,2,2,2,2,2,2,2,2,2,1,1,1
1,1,1,1,1,2,2,2,2,2,1,1,1,1,1
1,1,1,1,1,1,1,1,1,1,1,1,1,1,1
endlayer

layer
1,1,1,1,1,0,0,0,0,0,1,1,1,1,1
1,1,1,0,0,0,0,0,0,0,0,0,1,1,1
1,1,0,0,0,0,0,0,0,0,0,0,0,1,1
1,0,0,0,0,0,0,0,0,0,0,0,0,0,1
1,0,0,0,0,0,0,0,0,0,0,0,0,0,1
0,0,0,0,0,3,0,0,0,3,0,0,0,0,0
0,0,0,0,0,0,0,0,0,0,0,0,0,0,0
0,0,0,0,0,0,0,0,0,0,0,0,0,0,0
0,0,0,0,0,0,0,0,0,0,0,0,0,0,0
0,0,0,0,0,3,0,0,0,3,0,0,0,0,0
1,0,0,0,0,0,0,0,0,0,0,0,0,0,1
1,0,0,0,0,0,0,0,0,0,0,0,0,0,1
1,1,0,0,0,0,0,0,0,0,0,0,0,1,1
1,1,1,0,0,0,0,0,0,0,0,0,1,1,1
1,1,1,1,1,0,0,0,0,0,1,1,1,1,1
endlayer

layer
1,1,1,1,1,0,0,0,0,0,1,1,1,1,1
1,1,1,0,0,0,0,0,0,0,0,0,1,1,1
1,1,0,0,0,0,0,0,0,0,0,0,0,1,1
1,0,0,0,0,0,0,0,0,0,0,0,0,0,1
1,0,0,0,0,0,0,0,0,0,0,0,0,0,1
0,0,0,0,0,3,0,0,0,3,0,0,0,0,0
0,0,0,0,0,0,0,0,0,0,0,0,0,0,0
0,0,0,0,0,0,0,0,0,0,0,0,0,0,0
0,0,0,0,0,0,0,0,0,0,0,0,0,0,0
0,0,0,0,0,3,0,0,0,3,0,0,0,0,0
1,0,0,0,0,0,0,0,0,0,0,0,0,0,1
1,0,0,0,0,0,0,0,0,0,0,0,0,0,1
1,1,0,0,0,0,0,0,0,0,0,0,0,1,1
1,1,1,0,0,0,0,0,0,0,0,0,1,1,1
1,1,1,1,1,0,0,0,0,0,1,1,1,1,1
endlayer

layer
1,1,1,1,1,0,0,0,0,0,1,1,1,1,1
1,1,1,0,0,0,0,0,0,0,0,0,1,1,1
1,1,0,0,0,0,0,0,0,0,0,0,0,1,1
1,0,0,0,0,0,0,0,0,0,0,0,0,0,1
1,0,0,0,6,5,5,5,5,5,4,0,0,0,1
0,0,0,0,6,3,3,3,3,3,4,0,0,0,0
0,0,0,0,6,3,7,7,7,3,4,0,0,0,0
0,0,0,0,6,3,7,7,7,3,4,0,0,0,0
0,0,0,0,6,3,7,7,7,3,4,0,0,0,0
0,0,0,0,6,3,3,3,3,3,4,0,0,0,0
1,0,0,0,6,8,8,8,8,8,8,0,0,0,1
1,0,0,0,0,0,0,0,0,0,0,0,0,0,1
1,1,0,0,0,0,0,0,0,0,0,0,0,1,1
1,1,1,0,0,0,0,0,0,0,0,0,1,1,1
1,1,1,1,1,0,0,0,0,0,1,1,1,1,1
endlayer

layer
1,1,1,1,1,0,0,0,0,0,1,1,1,1,1
1,1,1,0,0,0,0,0,0,0,0,0,1,1,1
1,1,0,0,0,0,0,0,0,0,0,0,0,1,1
1,0,0,0,0,0,0,0,0,0,0,0,0,0,1
1,0,0,0,9,0,0,0,0,0,9,0,0,0,1
0,0,0,0,0,3,10,10,10,3,0,0,0,0,0
0,0,0,0,0,10,11,0,0,10,0,0,0,0,0
0,0,0,0,0,10,0,12,0,10,0,0,0,0,0
0,0,0,0,0,10,0,0,0,10,0,0,0,0,0
0,0,0,0,0,3,10,10,10,3,0,0,0,0,0
1,0,0,0,9,0,0,0,0,0,9,0,0,0,1
1,0,0,0,0,0,0,0,0,0,0,0,0,0,1
1,1,0,0,0,0,0,0,0,0,0,0,0,1,1
1,1,1,0,0,0,0,0,0,0,0,0,1,1,1
1,1,1,1,1,0,0,0,0,0,1,1,1,1,1
endlayer

layer
1,1,1,1,1,1,0,0,0,1,1,1,1,1,1
1,1,1,0,0,0,0,0,0,0,0,0,1,1,1
1,1,0,0,0,0,0,0,0,0,0,0,0,1,1
1,0,0,0,0,0,0,0,0,0,0,0,0,0,1
1,0,0,0,9,0,0,0,0,0,9,0,0,0,1
1,0,0,0,0,3,10,10,10,3,0,0,0,0,1
0,0,0,0,0,10,0,0,0,10,0,0,0,0,0
0,0,0,0,0,10,0,12,0,10,0,0,0,0,0
0,0,0,0,0,10,0,0,0,10,0,0,0,0,0
1,0,0,0,0,3,10,10,10,3,0,0,0,0,1
1,0,0,0,9,0,0,0,0,0,9,0,0,0,1
1,0,0,0,0,0,0,0,0,0,0,0,0,0,1
1,1,0,0,0,0,0,0,0,0,0,0,0,1,1
1,1,1,0,0,0,0,0,0,0,0,0,1,1,1
1,1,1,1,1,1,0,0,0,1,1,1,1,1,1
endlayer

layer
1,1,1,1,1,1,1,1,1,1,1,1,1,1,1
1,1,1,1,0,0,0,0,0,0,0,1,1,1,1
1,1,0,0,0,0,0,0,0,0,0,0,0,1,1
1,1,0,0,0,0,0,0,0,0,0,0,0,1,1
1,0,0,0,9,0,0,0,0,0,9,0,0,0,1
1,0,0,0,0,3,10,10,10,3,0,0,0,0,1
1,0,0,0,0,10,0,0,0,10,0,0,0,0,1
1,0,0,0,0,10,0,12,0,10,0,0,0,0,1
1,0,0,0,0,10,0,0,0,10,0,0,0,0,1
1,0,0,0,0,3,10,10,10,3,0,0,0,0,1
1,0,0,0,9,0,0,0,0,0,9,0,0,0,1
1,1,0,0,0,0,0,0,0,0,0,0,0,1,1
1,1,0,0,0,0,0,0,0,0,0,0,0,1,1
1,1,1,1,0,0,0,0,0,0,0,1,1,1,1
1,1,1,1,1,1,1,1,1,1,1,1,1,1,1
endlayer

layer
1,1,1,1,1,1,1,1,1,1,1,1,1,1,1
1,1,1,1,1,0,0,0,0,0,1,1,1,1,1
1,1,1,0,0,0,0,0,0,0,0,0,1,1,1
1,1,0,0,0,0,0,0,0,0,0,0,0,1,1
1,1,0,0,14,14,14,14,14,14,13,0,0,1,1
1,0,0,0,15,3,3,3,3,3,13,0,0,0,1
1,0,0,0,15,3,4,8,8,3,13,0,0,0,1
1,0,0,0,15,3,4,12,6,3,13,0,0,0,1
1,0,0,0,15,3,5,5,5,3,13,0,0,0,1
1,0,0,0,15,3,3,3,3,3,13,0,0,0,1
1,1,0,0,15,16,16,16,16,16,13,0,0,1,1
1,1,0,0,0,0,0,0,0,0,0,0,0,1,1
1,1,1,0,0,0,0,0,0,0,0,0,1,1,1
1,1,1,1,1,0,0,0,0,0,1,1,1,1,1
1,1,1,1,1,1,1,1,1,1,1,1,1,1,1
endlayer

layer
1,1,1,1,1,1,1,1,1,1,1,1,1,1,1
1,1,1,1,1,1,1,1,1,1,1,1,1,1,1
1,1,1,1,0,0,0,0,0,0,0,1,1,1,1
1,1,1,0,0,0,0,0,0,0,0,0,1,1,1
1,1,0,0,0,0,0,0,0,0,0,0,0,1,1
1,1,0,0,0,14,14,14,14,13,0,0,0,1,1
1,1,0,0,0,15,3,3,3,13,0,0,0,1,1
1,1,0,0,0,15,3,3,3,13,0,0,0,1,1
1,1,0,0,0,15,3,3,3,13,0,0,0,1,1
1,1,0,0,0,16,16,16,16,16,0,0,0,1,1
1,1,0,0,0,0,0,0,0,0,0,0,0,1,1
1,1,1,0,0,0,0,0,0,0,0,0,1,1,1
1,1,1,1,0,0,0,0,0,0,0,1,1,1,1
1,1,1,1,1,1,1,1,1,1,1,1,1,1,1
1,1,1,1,1,1,1,1,1,1,1,1,1,1,1
endlayer

layer
1,1,1,1,1,1,1,1,1,1,1,1,1,1,1
1,1,1,1,1,1,1,1,1,1,1,1,1,1,1
1,1,1,1,1,1,1,1,1,1,1,1,1,1,1
1,1,1,1,1,0,0,0,0,0,1,1,1,1,1
1,1,1,1,0,0,0,0,0,0,0,1,1,1,1
1,1,1,0,0,0,0,0,0,0,0,0,1,1,1
1,1,1,0,0,0,14,14,14,0,0,0,1,1,1
1,1,1,0,0,0,15,3,13,0,0,0,1,1,1
1,1,1,0,0,0,16,16,13,0,0,0,1,1,1
1,1,1,0,0,0,0,0,0,0,0,0,1,1,1
1,1,1,1,0,0,0,0,0,0,0,1,1,1,1
1,1,1,1,1,0,0,0,0,0,1,1,1,1,1
1,1,1,1,1,1,1,1,1,1,1,1,1,1,1
1,1,1,1,1,1,1,1,1,1,1,1,1,1,1
1,1,1,1,1,1,1,1,1,1,1,1,1,1,1
endlayer

layer
1,1,1,1,1,1,1,1,1,1,1,1,1,1,1
1,1,1,1,1,1,1,1,1,1,1,1,1,1,1
1,1,1,1,1,1,1,1,1,1,1,1,1,1,1
1,1,1,1,1,1,1,1,1,1,1,1,1,1,1
1,1,1,1,1,1,1,1,1,1,1,1,1,1,1
1,1,1,1,1,1,0,0,0,1,1,1,1,1,1
1,1,1,1,1,0,0,0,0,0,1,1,1,1,1
1,1,1,1,1,0,0,17,0,0,1,1,1,1,1
1,1,1,1,1,0,0,0,0,0,1,1,1,1,1
1,1,1,1,1,1,0,0,0,1,1,1,1,1,1
1,1,1,1,1,1,1,1,1,1,1,1,1,1,1
1,1,1,1,1,1,1,1,1,1,1,1,1,1,1
1,1,1,1,1,1,1,1,1,1,1,1,1,1,1
1,1,1,1,1,1,1,1,1,1,1,1,1,1,1
1,1,1,1,1,1,1,1,1,1,1,1,1,1,1
endlayer

