
# Created by Ruins mod version 17.0 Ingame Parser
# authoring Player: ST753M

weight=1
embed_into_distance=0
acceptable_target_blocks=
unacceptable_target_blocks=flowing_water,water,flowing_lava,lava
dimensions=18,17,20
allowable_overhang=0
max_leveling=0
leveling_buffer=-1
preserve_water=0
preserve_lava=0

=0,100,air
rule1=0,100,preserveBlock

rule2=0,100,minecraft:stonebrick-0,minecraft:monster_egg-3,minecraft:monster_egg-4,minecraft:stonebrick-1,minecraft:stonebrick-2,minecraft:stone-0,minecraft:monster_egg-2,minecraft:stonebrick-0,minecraft:monster_egg-3,minecraft:monster_egg-4,minecraft:stonebrick-1,minecraft:stonebrick-2,minecraft:stone-0,minecraft:monster_egg-2,minecraft:stonebrick-0,minecraft:monster_egg-3,minecraft:monster_egg-4,minecraft:stonebrick-1,minecraft:stonebrick-2,minecraft:stone-0,minecraft:monster_egg-2,minecraft:stone_brick_stairs-1,minecraft:stone_brick_stairs-3,minecraft:stone_brick_stairs-7,minecraft:stone_brick_stairs-5
rule3=0,100,minecraft:stonebrick-0,minecraft:monster_egg-3,minecraft:monster_egg-4,minecraft:stonebrick-1,minecraft:stonebrick-2,minecraft:stone-0,minecraft:monster_egg-2,minecraft:stonebrick-0,minecraft:monster_egg-3,minecraft:monster_egg-4,minecraft:stonebrick-1,minecraft:stonebrick-2,minecraft:stone-0,minecraft:monster_egg-2,minecraft:stonebrick-0,minecraft:monster_egg-3,minecraft:monster_egg-4,minecraft:stonebrick-1,minecraft:stonebrick-2,minecraft:stone-0,minecraft:monster_egg-2,minecraft:stone_brick_stairs-1,minecraft:stone_brick_stairs-3,minecraft:stone_brick_stairs-7,minecraft:stone_brick_stairs-5

rule4=0,100,minecraft:stonebrick-3
rule5=0,100,minecraft:stone_brick_stairs-2
rule6=0,100,minecraft:stone_brick_stairs-3
rule7=0,100,minecraft:stone_brick_stairs-0
rule8=0,100,minecraft:stone_brick_stairs-5
rule9=0,100,minecraft:stone_brick_stairs-1
rule10=0,100,minecraft:stone_brick_stairs-4
rule11=0,100,minecraft:obsidian-0
rule12=0,100,minecraft:stone_brick_stairs-7
rule13=0,100,minecraft:stone_brick_stairs-6
rule14=0,100,minecraft:portal-1
^0,100,air
^0,100,air
rule15=0,100,minecraft:netherrack-0
rule16=0,100,minecraft:fire-15

layer
1,1,1,1,1,1,2,2,2,2,2,2,2,2,2,1,1,1,1,1
1,1,1,1,1,2,2,2,3,3,3,3,3,2,2,2,1,1,1,1
1,1,1,1,2,2,3,3,3,3,3,3,3,3,3,2,2,1,1,1
1,1,1,2,2,3,3,3,3,3,3,3,3,3,3,3,2,2,1,1
2,2,2,2,3,3,3,3,3,3,3,3,3,3,3,3,3,2,2,1
2,2,2,2,3,3,3,3,3,3,3,3,3,3,3,3,3,2,2,1
2,2,2,3,3,3,3,3,3,3,3,3,3,3,3,3,3,3,2,1
2,2,2,3,3,3,3,3,3,3,3,3,3,3,3,3,3,3,2,1
2,2,2,3,3,3,3,3,3,3,3,3,3,3,3,3,3,3,2,1
2,2,2,3,3,3,3,3,3,3,3,3,3,3,3,3,3,3,2,1
2,2,2,3,3,3,3,3,3,3,3,3,3,3,3,3,3,3,2,1
2,2,2,2,3,3,3,3,3,3,3,3,3,3,3,3,3,2,2,1
2,2,2,2,3,3,3,3,3,3,3,3,3,3,3,3,3,2,2,1
1,1,1,2,2,3,3,3,3,3,3,3,3,3,3,3,2,2,1,1
1,1,1,1,2,2,3,3,3,3,3,3,3,3,3,2,2,1,1,1
1,1,1,1,1,2,2,2,3,3,3,3,3,2,2,2,1,1,1,1
1,1,1,1,1,1,2,2,2,2,2,2,2,2,2,1,1,1,1,1
endlayer

layer
1,1,1,1,1,1,2,2,2,2,2,2,2,2,2,1,1,1,1,1
1,1,1,1,1,2,2,2,3,3,3,3,3,2,2,2,1,1,1,1
1,1,1,1,2,2,3,3,3,3,4,3,3,3,3,2,2,1,1,1
1,1,1,2,2,3,3,3,4,3,3,3,4,3,3,3,2,2,1,1
2,2,2,2,3,3,3,3,3,3,3,3,3,3,3,3,3,2,2,1
2,2,2,2,3,3,3,3,3,3,3,3,3,3,3,3,3,2,2,1
3,3,3,3,3,3,3,3,3,3,3,3,3,3,3,4,3,3,2,1
3,4,3,4,3,4,3,3,3,3,3,3,3,3,3,3,3,3,2,1
4,3,4,3,4,3,4,3,3,3,3,3,3,3,4,3,4,3,2,1
3,4,3,4,3,4,3,3,3,3,3,3,3,3,3,3,3,3,2,1
3,3,3,3,3,3,3,3,3,3,3,3,3,3,3,4,3,3,2,1
2,2,2,2,3,3,3,3,3,3,3,3,3,3,3,3,3,2,2,1
2,2,2,2,3,3,3,3,3,3,3,3,3,3,3,3,3,2,2,1
1,1,1,2,2,3,3,3,4,3,3,3,4,3,3,3,2,2,1,1
1,1,1,1,2,2,3,3,3,3,4,3,3,3,3,2,2,1,1,1
1,1,1,1,1,2,2,2,3,3,3,3,3,2,2,2,1,1,1,1
1,1,1,1,1,1,2,2,2,2,2,2,2,2,2,1,1,1,1,1
endlayer

layer
1,1,1,1,1,1,2,2,3,3,3,3,3,2,2,1,1,1,1,1
1,1,1,1,1,2,3,3,0,0,0,0,0,3,3,2,1,1,1,1
1,1,1,1,2,3,0,0,0,0,0,0,0,0,0,3,2,1,1,1
1,1,1,2,3,0,0,0,0,0,0,0,0,0,0,0,3,2,1,1
2,2,2,3,0,0,0,0,0,0,0,0,0,0,0,0,0,3,2,1
3,9,8,3,0,0,6,3,3,5,7,6,3,3,5,0,0,3,2,1
0,0,0,0,0,0,0,6,3,3,3,3,3,5,0,0,0,0,3,1
0,0,0,0,0,0,0,0,6,3,3,3,5,0,0,0,0,0,3,1
0,0,0,0,0,0,0,0,6,3,3,3,5,0,0,0,0,0,3,1
0,0,0,0,0,0,0,0,6,3,3,3,5,0,0,0,0,0,3,1
0,0,0,0,0,0,0,6,3,3,3,3,3,5,0,0,0,0,3,1
3,7,10,3,0,0,6,3,3,3,9,3,3,3,5,0,0,3,2,1
2,2,2,3,0,0,0,0,0,0,0,0,0,0,0,0,0,3,2,1
1,1,1,2,3,0,0,0,0,0,0,0,0,0,0,0,3,2,1,1
1,1,1,1,2,3,0,0,0,0,0,0,0,0,0,3,2,1,1,1
1,1,1,1,1,2,3,3,0,0,0,0,0,3,3,2,1,1,1,1
1,1,1,1,1,1,2,2,3,3,3,3,3,2,2,1,1,1,1,1
endlayer

layer
1,1,1,1,1,1,2,2,3,9,8,9,3,2,2,1,1,1,1,1
1,1,1,1,1,2,9,3,0,0,0,0,0,3,9,2,1,1,1,1
1,1,1,1,2,3,0,0,0,0,0,0,0,0,0,3,2,1,1,1
1,1,1,2,3,0,0,0,0,0,0,0,0,0,0,0,3,2,1,1
2,2,2,5,0,0,0,0,0,0,0,0,0,0,0,0,0,6,2,1
3,9,8,3,0,0,0,6,3,0,0,0,3,5,0,0,0,3,2,1
0,0,0,0,0,0,0,0,6,3,4,3,5,0,0,0,0,0,3,1
0,0,0,0,0,0,0,0,0,6,11,5,0,0,0,0,0,0,6,1
0,0,0,0,0,0,0,0,0,6,11,5,0,0,0,0,0,0,12,1
0,0,0,0,0,0,0,0,0,6,11,5,0,0,0,0,0,0,6,1
0,0,0,0,0,0,0,0,6,3,4,3,5,0,0,0,0,0,3,1
3,7,10,3,0,0,0,6,3,0,0,0,3,5,0,0,0,3,2,1
2,2,2,5,0,0,0,0,0,0,0,0,0,0,0,0,0,6,2,1
1,1,1,2,3,0,0,0,0,0,0,0,0,0,0,0,3,2,1,1
1,1,1,1,2,3,0,0,0,0,0,0,0,0,0,3,2,1,1,1
1,1,1,1,1,2,7,3,0,0,0,0,0,3,7,2,1,1,1,1
1,1,1,1,1,1,2,2,3,7,10,7,3,2,2,1,1,1,1,1
endlayer

layer
1,1,1,1,1,1,2,2,3,3,3,3,3,2,2,1,1,1,1,1
1,1,1,1,1,2,8,3,0,0,0,0,0,3,8,2,1,1,1,1
1,1,1,1,2,3,0,0,0,0,0,0,0,0,0,3,2,1,1,1
1,1,1,2,3,0,0,0,0,0,0,0,0,0,0,0,3,2,1,1
2,2,2,13,0,0,0,0,0,0,0,0,0,0,0,0,0,12,2,1
3,9,8,3,0,0,0,0,6,13,10,12,5,0,0,0,0,3,2,1
0,0,0,0,0,0,0,0,0,3,11,3,0,0,0,0,0,0,3,1
0,0,0,0,0,0,0,0,0,0,14,0,0,0,0,0,0,0,3,1
0,0,0,0,0,0,0,0,0,0,14,0,0,0,0,0,0,0,3,1
0,0,0,0,0,0,0,0,0,0,14,0,0,0,0,0,0,0,3,1
0,0,0,0,0,0,0,0,0,3,11,3,0,0,0,0,0,0,3,1
3,7,10,3,0,0,0,0,6,3,8,3,5,0,0,0,0,3,2,1
2,2,2,13,0,0,0,0,0,0,0,0,0,0,0,0,0,12,2,1
1,1,1,2,3,0,0,0,0,0,0,0,0,0,0,0,3,2,1,1
1,1,1,1,2,3,0,0,0,0,0,0,0,0,0,3,2,1,1,1
1,1,1,1,1,2,10,3,0,0,0,0,0,3,10,2,1,1,1,1
1,1,1,1,1,1,2,2,3,3,3,3,3,2,2,1,1,1,1,1
endlayer

layer
1,1,1,1,1,1,2,2,3,3,3,3,3,2,2,1,1,1,1,1
1,1,1,1,1,2,3,3,8,8,8,8,8,3,3,2,1,1,1,1
1,1,1,1,2,3,0,0,0,0,0,0,0,0,0,3,2,1,1,1
1,1,1,2,3,0,0,0,0,0,0,0,0,0,0,0,3,2,1,1
2,2,2,3,0,0,0,0,0,0,0,0,0,0,0,0,0,3,2,1
3,9,8,3,0,0,0,0,0,10,4,10,0,0,0,0,0,3,2,1
0,0,0,0,0,0,0,0,0,3,11,3,0,0,0,0,0,12,3,1
0,0,0,0,0,0,0,0,0,0,14,0,0,0,0,0,0,12,3,1
0,0,0,0,0,0,0,0,0,0,14,0,0,0,0,0,0,12,3,1
0,0,0,0,0,0,0,0,0,0,14,0,0,0,0,0,0,12,3,1
0,0,0,0,0,0,0,0,0,3,11,3,0,0,0,0,0,12,3,1
3,7,10,3,0,0,0,0,0,8,4,8,0,0,0,0,0,3,2,1
2,2,2,3,0,0,0,0,0,0,0,0,0,0,0,0,0,3,2,1
1,1,1,2,3,0,0,0,0,0,0,0,0,0,0,0,3,2,1,1
1,1,1,1,2,3,0,0,0,0,0,0,0,0,0,3,2,1,1,1
1,1,1,1,1,2,3,3,10,10,10,10,10,3,3,2,1,1,1,1
1,1,1,1,1,1,2,2,3,3,3,3,3,2,2,1,1,1,1,1
endlayer

layer
1,1,1,1,1,1,2,2,3,3,3,3,3,2,2,1,1,1,1,1
1,1,1,1,1,2,3,3,15,15,15,15,15,3,3,2,1,1,1,1
1,1,1,1,2,3,8,8,8,8,8,8,8,8,8,3,2,1,1,1
1,1,1,2,3,0,0,0,0,0,0,0,0,0,0,0,3,2,1,1
4,2,2,3,0,0,0,0,0,0,0,0,0,0,0,0,12,3,2,1
2,2,2,3,0,0,0,0,0,6,7,5,0,0,0,0,12,3,2,1
8,8,8,0,0,0,0,0,0,6,11,5,0,0,0,0,12,15,3,1
0,0,0,0,0,0,0,0,0,0,14,0,0,0,0,0,12,15,3,1
0,0,0,0,0,0,0,0,0,0,14,0,0,0,0,0,12,15,3,1
0,0,0,0,0,0,0,0,0,0,14,0,0,0,0,0,12,15,3,1
10,10,10,0,0,0,0,0,0,6,11,5,0,0,0,0,12,15,3,1
2,2,2,3,0,0,0,0,0,6,9,5,0,0,0,0,12,3,2,1
4,2,2,3,0,0,0,0,0,0,0,0,0,0,0,0,12,3,2,1
1,1,1,2,3,0,0,0,0,0,0,0,0,0,0,0,3,2,1,1
1,1,1,1,2,3,10,10,10,10,10,10,10,10,10,3,2,1,1,1
1,1,1,1,1,2,3,3,15,15,15,15,15,3,3,2,1,1,1,1
1,1,1,1,1,1,2,2,3,3,3,3,3,2,2,1,1,1,1,1
endlayer

layer
1,1,1,1,1,1,2,2,3,3,3,3,3,2,2,1,1,1,1,1
1,1,1,1,1,2,3,3,16,16,16,16,16,3,3,2,1,1,1,1
1,1,1,1,2,3,9,3,5,0,0,0,6,3,9,3,2,1,1,1
1,1,1,2,3,0,0,0,0,0,0,0,0,0,0,0,3,2,1,1
2,2,2,3,0,0,0,0,0,0,0,0,0,0,0,0,6,3,2,1
2,2,2,3,0,0,0,0,0,0,0,0,0,0,0,0,3,3,2,1
4,2,3,0,0,0,0,0,0,12,11,13,0,0,0,0,9,16,3,1
2,2,3,0,0,0,0,0,0,0,14,0,0,0,0,0,0,16,3,1
2,2,3,0,0,0,0,0,0,0,14,0,0,0,0,0,0,16,3,1
2,2,3,0,0,0,0,0,0,0,14,0,0,0,0,0,0,16,3,1
4,2,3,0,0,0,0,0,0,12,11,13,0,0,0,0,7,16,3,1
2,2,2,3,0,0,0,0,0,0,0,0,0,0,0,0,3,3,2,1
2,2,2,3,0,0,0,0,0,0,0,0,0,0,0,0,6,3,2,1
1,1,1,2,3,0,0,0,0,0,0,0,0,0,0,0,3,2,1,1
1,1,1,1,2,3,7,3,5,0,0,0,6,3,7,3,2,1,1,1
1,1,1,1,1,2,3,3,16,16,16,16,16,3,3,2,1,1,1,1
1,1,1,1,1,1,2,2,3,3,3,3,3,2,2,1,1,1,1,1
endlayer

layer
1,1,1,1,1,1,2,2,3,9,9,9,3,2,2,1,1,1,1,1
1,1,1,1,1,2,3,3,0,0,0,0,0,3,3,2,1,1,1,1
1,1,1,1,2,3,8,5,0,0,0,0,0,6,8,3,2,1,1,1
1,1,1,2,3,0,0,0,0,0,0,0,0,0,0,0,3,2,1,1
2,2,2,3,0,0,0,0,0,0,0,0,0,0,0,0,12,3,2,1
2,2,2,3,0,0,0,0,0,0,10,0,0,0,0,0,9,3,2,1
2,2,3,0,0,0,0,0,0,3,11,3,0,0,0,0,0,0,3,1
2,2,5,0,0,0,0,0,0,6,11,5,0,0,0,0,0,0,6,1
4,2,5,0,0,0,0,0,0,4,11,4,0,0,0,0,0,0,6,1
2,2,5,0,0,0,0,0,0,6,11,5,0,0,0,0,0,0,6,1
2,2,3,0,0,0,0,0,0,3,11,3,0,0,0,0,0,0,3,1
2,2,2,3,0,0,0,0,0,0,8,0,0,0,0,0,7,3,2,1
2,2,2,3,0,0,0,0,0,0,0,0,0,0,0,0,12,3,2,1
1,1,1,2,3,0,0,0,0,0,0,0,0,0,0,0,3,2,1,1
1,1,1,1,2,3,10,5,0,0,0,0,0,6,10,3,2,1,1,1
1,1,1,1,1,2,3,3,0,0,0,0,0,3,3,2,1,1,1,1
1,1,1,1,1,1,2,2,3,7,7,7,3,2,2,1,1,1,1,1
endlayer

layer
1,1,1,1,1,1,1,1,3,3,4,3,3,1,1,1,1,1,1,1
1,1,1,1,1,1,3,3,0,0,0,0,0,3,3,1,1,1,1,1
1,1,1,1,1,3,5,0,0,0,0,0,0,0,6,3,1,1,1,1
1,1,1,1,3,0,0,0,0,0,0,0,0,0,0,0,3,1,1,1
1,1,1,3,0,0,0,0,0,0,0,0,0,0,0,0,9,3,1,1
1,1,1,3,0,0,0,0,0,0,7,0,0,0,0,0,0,3,1,1
2,2,3,0,0,0,0,0,0,6,15,5,0,0,0,0,0,0,3,1
2,2,3,0,0,0,0,0,0,0,9,0,0,0,0,0,0,0,3,1
2,2,4,0,0,0,0,0,0,0,3,0,0,0,0,0,0,0,4,1
2,2,3,0,0,0,0,0,0,0,7,0,0,0,0,0,0,0,3,1
2,2,3,0,0,0,0,0,0,6,15,5,0,0,0,0,0,0,3,1
1,1,1,3,0,0,0,0,0,0,9,0,0,0,0,0,0,3,1,1
1,1,1,3,0,0,0,0,0,0,0,0,0,0,0,0,7,3,1,1
1,1,1,1,3,0,0,0,0,0,0,0,0,0,0,0,3,1,1,1
1,1,1,1,1,3,5,0,0,0,0,0,0,0,6,3,1,1,1,1
1,1,1,1,1,1,3,3,0,0,0,0,0,3,3,1,1,1,1,1
1,1,1,1,1,1,1,1,3,3,4,3,3,1,1,1,1,1,1,1
endlayer

layer
1,1,1,1,1,1,1,1,3,8,8,8,3,1,1,1,1,1,1,1
1,1,1,1,1,1,3,3,0,0,0,0,0,3,3,1,1,1,1,1
1,1,1,1,1,3,0,0,0,0,0,0,0,0,0,3,1,1,1,1
1,1,1,1,3,0,0,0,0,0,0,0,0,0,0,0,3,1,1,1
1,1,1,3,0,0,0,0,0,0,0,0,0,0,0,0,0,3,1,1
1,1,1,3,0,0,0,0,0,0,0,0,0,0,0,0,0,3,1,1
1,1,3,0,0,0,0,0,0,0,16,0,0,0,0,0,0,0,3,1
1,1,13,0,0,0,0,0,0,0,0,0,0,0,0,0,0,0,12,1
1,1,13,0,0,0,0,0,0,0,0,0,0,0,0,0,0,0,12,1
1,1,13,0,0,0,0,0,0,0,0,0,0,0,0,0,0,0,12,1
1,1,3,0,0,0,0,0,0,0,16,0,0,0,0,0,0,0,3,1
1,1,1,3,0,0,0,0,0,0,0,0,0,0,0,0,0,3,1,1
1,1,1,3,0,0,0,0,0,0,0,0,0,0,0,0,0,3,1,1
1,1,1,1,3,0,0,0,0,0,0,0,0,0,0,0,3,1,1,1
1,1,1,1,1,3,0,0,0,0,0,0,0,0,0,3,1,1,1,1
1,1,1,1,1,1,3,3,0,0,0,0,0,3,3,1,1,1,1,1
1,1,1,1,1,1,1,1,3,10,10,10,3,1,1,1,1,1,1,1
endlayer

layer
1,1,1,1,1,1,1,1,1,3,3,3,1,1,1,1,1,1,1,1
1,1,1,1,1,1,3,3,3,0,0,0,3,3,3,1,1,1,1,1
1,1,1,1,1,3,0,0,0,0,0,0,0,0,0,3,1,1,1,1
1,1,1,1,3,0,0,0,0,0,0,0,0,0,0,0,3,1,1,1
1,1,1,3,0,0,0,0,0,0,0,0,0,0,0,0,0,3,1,1
1,1,1,3,0,0,0,0,0,0,0,0,0,0,0,0,0,3,1,1
1,1,1,3,0,0,0,0,0,0,0,0,0,0,0,0,0,3,1,1
1,1,3,0,0,0,0,0,0,0,0,0,0,0,0,0,0,0,3,1
1,1,3,0,0,0,0,0,0,0,0,0,0,0,0,0,0,0,3,1
1,1,3,0,0,0,0,0,0,0,0,0,0,0,0,0,0,0,3,1
1,1,1,3,0,0,0,0,0,0,0,0,0,0,0,0,0,3,1,1
1,1,1,3,0,0,0,0,0,0,0,0,0,0,0,0,0,3,1,1
1,1,1,3,0,0,0,0,0,0,0,0,0,0,0,0,0,3,1,1
1,1,1,1,3,0,0,0,0,0,0,0,0,0,0,0,3,1,1,1
1,1,1,1,1,3,0,0,0,0,0,0,0,0,0,3,1,1,1,1
1,1,1,1,1,1,3,3,3,0,0,0,3,3,3,1,1,1,1,1
1,1,1,1,1,1,1,1,1,3,3,3,1,1,1,1,1,1,1,1
endlayer

layer
1,1,1,1,1,1,1,1,1,1,1,1,1,1,1,1,1,1,1,1
1,1,1,1,1,1,1,3,3,3,3,3,3,3,1,1,1,1,1,1
1,1,1,1,1,3,3,0,0,0,0,0,0,0,3,3,1,1,1,1
1,1,1,1,3,0,0,0,0,0,0,0,0,0,0,0,3,1,1,1
1,1,1,1,3,0,0,0,0,0,0,0,0,0,0,0,3,1,1,1
1,1,1,3,0,0,0,0,0,0,0,0,0,0,0,0,0,3,1,1
1,1,1,3,0,0,0,0,0,0,0,0,0,0,0,0,0,3,1,1
1,1,1,3,0,0,0,0,0,0,0,0,0,0,0,0,0,3,1,1
1,1,1,3,0,0,0,0,0,0,0,0,0,0,0,0,0,3,1,1
1,1,1,3,0,0,0,0,0,0,0,0,0,0,0,0,0,3,1,1
1,1,1,3,0,0,0,0,0,0,0,0,0,0,0,0,0,3,1,1
1,1,1,3,0,0,0,0,0,0,0,0,0,0,0,0,0,3,1,1
1,1,1,1,3,0,0,0,0,0,0,0,0,0,0,0,3,1,1,1
1,1,1,1,3,0,0,0,0,0,0,0,0,0,0,0,3,1,1,1
1,1,1,1,1,3,3,0,0,0,0,0,0,0,3,3,1,1,1,1
1,1,1,1,1,1,1,3,3,3,3,3,3,3,1,1,1,1,1,1
1,1,1,1,1,1,1,1,1,1,1,1,1,1,1,1,1,1,1,1
endlayer

layer
1,1,1,1,1,1,1,1,1,1,1,1,1,1,1,1,1,1,1,1
1,1,1,1,1,1,1,1,3,3,3,3,3,1,1,1,1,1,1,1
1,1,1,1,1,1,3,3,0,8,0,8,0,3,3,1,1,1,1,1
1,1,1,1,1,3,0,0,0,0,0,0,0,0,0,3,1,1,1,1
1,1,1,1,3,0,0,0,0,0,0,0,0,0,0,0,3,1,1,1
1,1,1,1,3,0,0,0,0,0,0,0,0,0,0,0,3,1,1,1
1,1,1,3,0,0,0,0,0,0,0,0,0,0,0,0,0,3,1,1
1,1,1,3,13,0,0,0,0,0,0,0,0,0,0,0,12,3,1,1
1,1,1,3,0,0,0,0,0,0,0,0,0,0,0,0,0,3,1,1
1,1,1,3,13,0,0,0,0,0,0,0,0,0,0,0,12,3,1,1
1,1,1,3,0,0,0,0,0,0,0,0,0,0,0,0,0,3,1,1
1,1,1,1,3,0,0,0,0,0,0,0,0,0,0,0,3,1,1,1
1,1,1,1,3,0,0,0,0,0,0,0,0,0,0,0,3,1,1,1
1,1,1,1,1,3,0,0,0,0,0,0,0,0,0,3,1,1,1,1
1,1,1,1,1,1,3,3,0,10,0,10,0,3,3,1,1,1,1,1
1,1,1,1,1,1,1,1,3,3,3,3,3,1,1,1,1,1,1,1
1,1,1,1,1,1,1,1,1,1,1,1,1,1,1,1,1,1,1,1
endlayer

layer
1,1,1,1,1,1,1,1,1,1,1,1,1,1,1,1,1,1,1,1
1,1,1,1,1,1,1,1,1,1,1,1,1,1,1,1,1,1,1,1
1,1,1,1,1,1,1,3,3,3,3,3,3,3,1,1,1,1,1,1
1,1,1,1,1,1,3,0,0,8,0,8,0,0,3,1,1,1,1,1
1,1,1,1,1,3,0,0,0,0,0,0,0,0,0,3,1,1,1,1
1,1,1,1,3,0,0,0,0,0,0,0,0,0,0,0,3,1,1,1
1,1,1,1,3,0,0,0,0,0,0,0,0,0,0,0,3,1,1,1
1,1,1,1,3,13,0,0,0,0,0,0,0,0,0,12,3,1,1,1
1,1,1,1,3,0,0,0,0,0,0,0,0,0,0,0,3,1,1,1
1,1,1,1,3,13,0,0,0,0,0,0,0,0,0,12,3,1,1,1
1,1,1,1,3,0,0,0,0,0,0,0,0,0,0,0,3,1,1,1
1,1,1,1,3,0,0,0,0,0,0,0,0,0,0,0,3,1,1,1
1,1,1,1,1,3,0,0,0,0,0,0,0,0,0,3,1,1,1,1
1,1,1,1,1,1,3,0,0,10,0,10,0,0,3,1,1,1,1,1
1,1,1,1,1,1,1,3,3,3,3,3,3,3,1,1,1,1,1,1
1,1,1,1,1,1,1,1,1,1,1,1,1,1,1,1,1,1,1,1
1,1,1,1,1,1,1,1,1,1,1,1,1,1,1,1,1,1,1,1
endlayer

layer
1,1,1,1,1,1,1,1,1,1,1,1,1,1,1,1,1,1,1,1
1,1,1,1,1,1,1,1,1,1,1,1,1,1,1,1,1,1,1,1
1,1,1,1,1,1,1,1,1,1,1,1,1,1,1,1,1,1,1,1
1,1,1,1,1,1,1,3,3,3,3,3,3,3,1,1,1,1,1,1
1,1,1,1,1,1,3,3,0,8,0,8,0,3,3,1,1,1,1,1
1,1,1,1,1,3,3,0,0,0,0,0,0,0,3,3,1,1,1,1
1,1,1,1,1,3,0,0,0,0,0,0,0,0,0,3,1,1,1,1
1,1,1,1,1,3,13,0,0,0,0,0,0,0,12,3,1,1,1,1
1,1,1,1,1,3,0,0,0,0,0,0,0,0,0,3,1,1,1,1
1,1,1,1,1,3,13,0,0,0,0,0,0,0,12,3,1,1,1,1
1,1,1,1,1,3,0,0,0,0,0,0,0,0,0,3,1,1,1,1
1,1,1,1,1,3,3,0,0,0,0,0,0,0,3,3,1,1,1,1
1,1,1,1,1,1,3,3,0,10,0,10,0,3,3,1,1,1,1,1
1,1,1,1,1,1,1,3,3,3,3,3,3,3,1,1,1,1,1,1
1,1,1,1,1,1,1,1,1,1,1,1,1,1,1,1,1,1,1,1
1,1,1,1,1,1,1,1,1,1,1,1,1,1,1,1,1,1,1,1
1,1,1,1,1,1,1,1,1,1,1,1,1,1,1,1,1,1,1,1
endlayer

layer
1,1,1,1,1,1,1,1,1,1,1,1,1,1,1,1,1,1,1,1
1,1,1,1,1,1,1,1,1,1,1,1,1,1,1,1,1,1,1,1
1,1,1,1,1,1,1,1,1,1,1,1,1,1,1,1,1,1,1,1
1,1,1,1,1,1,1,1,1,1,1,1,1,1,1,1,1,1,1,1
1,1,1,1,1,1,1,1,3,3,3,3,3,1,1,1,1,1,1,1
1,1,1,1,1,1,1,3,3,3,3,3,3,3,1,1,1,1,1,1
1,1,1,1,1,1,3,3,3,8,0,8,3,3,3,1,1,1,1,1
1,1,1,1,1,1,3,3,13,0,0,0,12,3,3,1,1,1,1,1
1,1,1,1,1,1,3,3,0,0,0,0,0,3,3,1,1,1,1,1
1,1,1,1,1,1,3,3,13,0,0,0,12,3,3,1,1,1,1,1
1,1,1,1,1,1,3,3,3,10,0,10,3,3,3,1,1,1,1,1
1,1,1,1,1,1,1,3,3,3,3,3,3,3,1,1,1,1,1,1
1,1,1,1,1,1,1,1,3,3,3,3,3,1,1,1,1,1,1,1
1,1,1,1,1,1,1,1,1,1,1,1,1,1,1,1,1,1,1,1
1,1,1,1,1,1,1,1,1,1,1,1,1,1,1,1,1,1,1,1
1,1,1,1,1,1,1,1,1,1,1,1,1,1,1,1,1,1,1,1
1,1,1,1,1,1,1,1,1,1,1,1,1,1,1,1,1,1,1,1
endlayer

layer
1,1,1,1,1,1,1,1,1,1,1,1,1,1,1,1,1,1,1,1
1,1,1,1,1,1,1,1,1,1,1,1,1,1,1,1,1,1,1,1
1,1,1,1,1,1,1,1,1,1,1,1,1,1,1,1,1,1,1,1
1,1,1,1,1,1,1,1,1,1,1,1,1,1,1,1,1,1,1,1
1,1,1,1,1,1,1,1,1,1,1,1,1,1,1,1,1,1,1,1
1,1,1,1,1,1,1,1,1,1,1,1,1,1,1,1,1,1,1,1
1,1,1,1,1,1,1,1,1,3,3,3,1,1,1,1,1,1,1,1
1,1,1,1,1,1,1,1,3,8,8,12,3,1,1,1,1,1,1,1
1,1,1,1,1,1,1,1,3,13,4,12,3,1,1,1,1,1,1,1
1,1,1,1,1,1,1,1,3,13,10,10,3,1,1,1,1,1,1,1
1,1,1,1,1,1,1,1,1,3,3,3,1,1,1,1,1,1,1,1
1,1,1,1,1,1,1,1,1,1,1,1,1,1,1,1,1,1,1,1
1,1,1,1,1,1,1,1,1,1,1,1,1,1,1,1,1,1,1,1
1,1,1,1,1,1,1,1,1,1,1,1,1,1,1,1,1,1,1,1
1,1,1,1,1,1,1,1,1,1,1,1,1,1,1,1,1,1,1,1
1,1,1,1,1,1,1,1,1,1,1,1,1,1,1,1,1,1,1,1
1,1,1,1,1,1,1,1,1,1,1,1,1,1,1,1,1,1,1,1
endlayer

