
# Created by Ruins mod version 17.0 Ingame Parser
# authoring Player: ST753M

weight=1
embed_into_distance=4
acceptable_target_blocks=
unacceptable_target_blocks=flowing_water,water,flowing_lava,lava,ice,bedrock,netherrack,nether_brick,nether_brick_fence,soul_sand,quartz_ore,end_stone,obsidian,iron_bars,Natura:Cloud,slime_grass,slime_congealed,slime_dirt,clouds,natura:clouds,twilightforest:wispy_cloud,twilightforest:fluffy_cloud
dimensions=11,9,9
allowable_overhang=10
max_leveling=4
leveling_buffer=0
preserve_water=0
preserve_lava=0

=0,100,preserveBlock
rule1=0,100,iceandfire:frozen_stone-0
rule2=0,100,minecraft:concrete-9
rule3=0,100,minecraft:light_blue_glazed_terracotta-3
rule4=0,100,minecraft:light_blue_glazed_terracotta-2
rule5=0,100,minecraft:light_blue_glazed_terracotta-0
rule6=0,100,minecraft:light_blue_glazed_terracotta-1
rule7=0,100,minecraft:packed_ice-0
rule8=0,100,minecraft:quartz_stairs-1
rule9=0,100,minecraft:spruce_door-1
rule10=0,100,minecraft:iron_trapdoor-9
rule11=0,100,minecraft:quartz_stairs-0
rule12=0,100,minecraft:stained_glass_pane-9
rule13=0,100,minecraft:carpet-0
rule14=0,100,minecraft:carpet-3
rule15=0,100,minecraft:spruce_door-8
rule16=0,100,minecraft:sea_lantern-0

layer
1,1,1,1,1,1,1,1,1
1,1,1,1,1,1,1,1,1
1,1,1,1,1,1,1,1,1
1,1,1,1,1,1,1,1,1
1,1,1,1,1,1,1,1,1
1,1,1,1,1,1,1,1,1
1,1,1,1,1,1,1,1,1
1,1,1,1,1,1,1,1,1
1,1,1,1,1,1,1,1,1
endlayer

layer
1,1,1,1,1,1,1,1,1
1,1,1,1,1,1,1,1,1
1,1,1,1,1,1,1,1,1
1,1,1,1,1,1,1,1,1
1,1,1,1,1,1,1,1,1
1,1,1,1,1,1,1,1,1
1,1,1,1,1,1,1,1,1
1,1,1,1,1,1,1,1,1
1,1,1,1,1,1,1,1,1
endlayer

layer
1,1,0,0,0,0,0,1,1
1,1,2,2,2,2,2,1,1
0,2,1,1,2,1,1,2,0
0,2,1,1,1,1,1,2,0
0,2,1,1,1,1,1,2,0
0,2,1,1,1,1,2,2,0
0,2,1,1,1,1,1,2,0
1,1,2,2,2,2,2,1,1
1,1,0,0,0,0,0,1,1
endlayer

layer
1,1,1,1,1,1,1,1,1
1,1,1,1,1,1,1,1,1
1,1,1,1,1,1,1,1,1
1,1,1,1,1,1,1,1,1
1,1,1,4,3,1,1,1,1
1,1,1,6,5,1,1,1,1
1,1,1,1,1,1,1,1,1
1,1,1,1,1,1,1,1,1
1,1,1,1,1,1,1,1,1
endlayer

layer
7,7,7,0,0,0,7,7,7
7,7,1,1,1,1,1,7,7
7,1,2,2,0,2,2,1,7
0,1,0,0,0,0,0,1,0
0,9,0,0,0,0,8,1,0
0,1,0,0,0,0,10,1,0
7,1,0,0,0,0,11,1,7
7,7,1,1,1,1,1,7,7
7,7,7,0,0,0,7,7,7
endlayer

layer
7,0,7,0,0,0,7,0,7
0,2,1,12,1,12,1,2,0
7,1,13,14,0,14,13,1,7
0,1,0,0,0,0,0,12,0
0,15,0,0,0,0,0,1,0
0,1,0,0,0,0,13,12,0
7,1,0,0,0,0,0,1,7
0,2,1,12,1,12,1,2,0
7,0,7,0,0,0,7,0,7
endlayer

layer
7,0,7,0,0,0,7,0,7
0,2,1,12,1,12,1,2,0
7,1,0,0,0,0,0,1,7
0,1,0,0,0,0,0,12,0
0,1,0,0,0,0,0,1,0
0,1,0,0,0,0,0,12,0
7,1,0,0,0,0,0,1,7
0,2,1,12,1,12,1,2,0
7,0,7,0,0,0,7,0,7
endlayer

layer
7,0,7,0,0,0,7,0,7
0,2,1,12,1,12,1,2,0
7,1,0,0,0,0,0,1,7
0,1,0,0,0,0,0,12,0
0,1,0,0,0,0,0,1,0
0,1,0,0,0,0,0,12,0
7,1,0,0,0,0,0,1,7
0,2,1,12,1,12,1,2,0
7,0,7,0,0,0,7,0,7
endlayer

layer
7,0,7,0,0,0,7,0,7
0,2,1,12,1,12,1,2,0
7,1,0,0,0,0,0,1,7
0,12,0,0,0,0,0,12,0
0,12,0,0,16,0,0,1,0
0,12,0,0,0,0,0,12,0
7,1,0,0,0,0,0,1,7
0,2,1,12,1,12,1,2,0
7,0,7,0,0,0,7,0,7
endlayer

layer
7,0,7,7,7,7,7,0,7
0,2,1,1,1,1,1,2,0
7,1,1,1,1,1,1,1,7
7,1,1,1,1,1,1,1,7
7,1,1,1,1,1,1,1,7
7,1,1,1,1,1,1,1,7
7,1,1,1,1,1,1,1,7
0,2,1,1,1,1,1,2,0
7,0,7,7,7,7,7,0,7
endlayer

layer
7,7,7,0,0,0,7,7,7
7,14,14,14,14,14,14,14,7
7,14,14,13,13,13,14,14,7
0,14,13,13,13,13,13,14,0
0,14,13,13,13,13,13,14,0
0,14,13,13,13,13,13,14,0
7,14,14,13,13,13,14,14,7
7,14,14,14,14,14,14,14,7
7,7,7,0,0,0,7,7,7
endlayer

