
# Created by Ruins mod version 17.0 Ingame Parser
# authoring Player: ST753M

weight=1
embed_into_distance=6
acceptable_target_blocks=
unacceptable_target_blocks=flowing_water,water,flowing_lava,lava
dimensions=14,11,11
allowable_overhang=6
max_leveling=2
leveling_buffer=0
preserve_water=0
preserve_lava=0

rule1=0,100,preserveBlock
rule2=0,100,minecraft:end_stone-0
rule3=0,100,minecraft:purpur_pillar-4
rule4=0,100,minecraft:purpur_pillar-8
rule5=0,100,minecraft:purpur_pillar-0
rule6=0,100,minecraft:purpur_block-0
rule7=0,100,minecraft:wool-10
rule8=0,100,minecraft:purpur_stairs-2
rule9=0,100,minecraft:end_bricks-0
rule10=0,100,minecraft:purpur_stairs-1
rule11=0,100,minecraft:purpur_stairs-3
rule12=0,100,minecraft:nether_brick_fence-0
rule13=0,100,minecraft:purpur_stairs-0
rule14=0,100,minecraft:wooden_door-3
rule15=0,100,minecraft:stained_glass_pane-10
rule16=0,100,minecraft:carpet-10
rule17=0,100,minecraft:wooden_door-8
rule18=0,100,minecraft:end_rod-0
rule19=0,100,minecraft:purpur_stairs-5
rule20=0,100,minecraft:purpur_stairs-7
rule21=0,100,minecraft:purpur_slab-8
rule22=0,100,minecraft:purpur_stairs-6
rule23=0,100,minecraft:purpur_stairs-4
rule24=0,100,minecraft:purpur_slab-0
rule25=0,100,minecraft:purpur_double_slab-0

layer
1,1,1,1,1,1,1,1,1,1,1
1,1,1,1,1,1,1,1,1,1,1
1,1,1,1,1,1,1,1,1,1,1
1,1,1,1,1,1,1,1,1,1,1
1,1,1,1,2,2,2,1,1,1,1
1,1,1,1,2,2,2,1,1,1,1
1,1,1,1,2,2,2,1,1,1,1
1,1,1,1,1,1,1,1,1,1,1
1,1,1,1,1,1,1,1,1,1,1
1,1,1,1,1,1,1,1,1,1,1
1,1,1,1,1,1,1,1,1,1,1
endlayer

layer
1,1,1,1,1,1,1,1,1,1,1
1,1,1,1,1,1,1,1,1,1,1
1,1,1,1,2,2,2,1,1,1,1
1,1,1,2,2,2,2,2,1,1,1
1,1,2,2,2,2,2,2,2,1,1
1,1,2,2,2,2,2,2,2,1,1
1,1,2,2,2,2,2,2,2,1,1
1,1,1,2,2,2,2,2,1,1,1
1,1,1,1,2,2,2,1,1,1,1
1,1,1,1,1,1,1,1,1,1,1
1,1,1,1,1,1,1,1,1,1,1
endlayer

layer
1,1,1,1,1,1,1,1,1,1,1
1,1,2,2,2,2,2,2,2,1,1
1,2,2,2,2,2,2,2,2,2,1
1,2,2,2,2,2,2,2,2,2,1
1,2,2,2,2,2,2,2,2,2,1
1,2,2,2,2,2,2,2,2,2,1
1,2,2,2,2,2,2,2,2,2,1
1,2,2,2,2,2,2,2,2,2,1
1,2,2,2,2,2,2,2,2,2,1
1,1,2,2,2,2,2,2,2,1,1
1,1,1,1,1,1,1,1,1,1,1
endlayer

layer
1,1,1,2,2,2,2,2,1,1,1
1,1,2,2,2,2,2,2,2,1,1
1,2,2,2,2,2,2,2,2,2,1
2,2,2,2,2,2,2,2,2,2,2
2,2,2,2,2,2,2,2,2,2,2
2,2,2,2,2,2,2,2,2,2,2
2,2,2,2,2,2,2,2,2,2,2
2,2,2,2,2,2,2,2,2,2,2
1,2,2,2,2,2,2,2,2,2,1
1,1,2,2,2,2,2,2,2,1,1
1,1,1,2,2,2,2,2,1,1,1
endlayer

layer
1,1,2,2,2,2,2,2,2,1,1
1,2,2,2,2,2,2,2,2,2,1
2,2,2,2,2,2,2,2,2,2,2
2,2,2,2,2,2,2,2,2,2,2
2,2,2,2,2,2,2,2,2,2,2
2,2,2,2,2,2,2,2,2,2,2
2,2,2,2,2,2,2,2,2,2,2
2,2,2,2,2,2,2,2,2,2,2
2,2,2,2,2,2,2,2,2,2,2
1,2,2,2,2,2,2,2,2,2,1
1,1,2,2,2,2,2,2,2,1,1
endlayer

layer
1,1,1,2,2,2,2,2,1,1,1
1,2,2,2,2,2,2,2,2,2,1
1,2,2,2,2,2,2,2,2,2,1
2,2,2,2,2,2,2,2,2,2,2
2,2,2,2,2,2,2,2,2,2,2
2,2,2,2,2,2,2,2,2,2,2
2,2,2,2,2,2,2,2,2,2,2
2,2,2,2,2,2,2,2,2,2,2
1,2,2,2,2,2,2,2,2,2,1
1,2,2,2,2,2,2,2,2,2,1
1,1,1,2,2,2,2,2,1,1,1
endlayer

layer
1,3,1,1,1,3,1,1,1,3,1
4,5,4,4,4,5,4,4,4,5,4
1,3,6,6,6,6,6,6,6,3,1
1,3,6,7,7,7,7,7,6,3,1
1,3,6,7,7,7,7,7,6,3,1
4,5,6,7,7,7,7,7,6,5,4
1,3,6,7,7,7,7,7,6,3,8
1,3,6,7,7,7,7,7,6,3,8
1,3,6,6,6,6,6,6,6,3,8
4,5,4,4,4,5,4,4,4,5,4
1,3,1,1,1,3,1,1,1,3,1
endlayer

layer
1,1,1,1,1,1,1,1,1,1,1
1,5,9,9,9,5,9,9,9,5,1
1,9,0,0,0,0,0,0,0,9,1
1,9,0,0,0,0,0,0,0,9,1
1,9,0,0,0,10,0,0,0,9,1
1,5,0,0,8,12,11,0,0,5,1
1,9,0,0,0,13,0,0,0,9,0
1,9,0,0,0,0,0,0,0,14,0
1,9,0,0,0,0,0,0,0,9,0
1,5,9,9,9,5,9,9,9,5,1
1,1,1,1,1,1,1,1,1,1,1
endlayer

layer
1,1,1,1,1,1,1,1,1,1,1
1,5,9,15,9,5,9,15,9,5,1
1,9,0,0,0,0,0,0,0,9,1
1,15,0,0,0,0,0,0,0,15,1
1,9,0,0,0,0,0,0,0,9,1
1,5,0,0,0,16,0,0,0,5,1
1,9,0,0,0,0,0,0,0,9,0
1,15,0,0,0,0,0,0,0,17,0
1,9,0,0,0,0,0,0,0,9,0
1,5,9,15,9,5,9,15,9,5,1
1,1,1,1,1,1,1,1,1,1,1
endlayer

layer
1,1,1,1,1,1,1,1,1,1,1
1,5,9,15,9,5,9,15,9,5,1
1,9,0,0,0,0,0,0,0,9,1
1,15,0,0,0,0,0,0,0,15,1
1,9,0,0,0,0,0,0,0,9,1
1,5,0,0,0,0,0,0,0,5,1
1,9,0,0,0,0,0,0,0,9,0
1,15,0,0,0,0,0,0,0,0,0
1,9,0,0,0,0,0,0,0,9,0
1,5,9,15,9,5,9,15,9,5,1
1,1,1,1,1,1,1,1,1,1,1
endlayer

layer
1,1,1,1,1,1,1,1,1,1,1
1,5,9,9,9,5,9,9,9,5,1
1,9,0,0,0,0,0,0,0,9,1
1,9,0,0,0,0,0,0,0,9,1
1,9,0,0,0,0,0,0,0,9,1
1,5,0,0,0,0,0,0,0,5,1
1,9,0,0,0,0,0,0,0,9,0
1,9,0,0,0,0,0,0,0,9,0
1,9,0,0,0,0,0,0,0,9,0
1,5,9,9,9,5,9,9,9,5,1
1,1,1,1,1,1,1,1,1,1,1
endlayer

layer
0,3,13,13,13,3,13,13,13,3,0
4,5,4,4,4,5,4,4,4,5,4
11,3,0,0,0,18,0,0,0,3,8
11,3,0,0,0,0,0,0,0,3,8
11,3,0,0,0,0,0,0,0,3,8
4,5,18,0,0,0,0,0,18,5,4
11,3,0,0,0,0,0,0,0,3,8
11,3,0,0,0,0,0,0,0,3,8
11,3,0,0,0,18,0,0,0,3,8
4,5,4,4,4,5,4,4,4,5,4
0,3,10,10,10,3,10,10,10,3,0
endlayer

layer
0,0,0,0,0,0,0,0,0,0,0
0,11,13,13,13,13,13,13,13,13,0
0,11,6,19,19,5,19,19,6,8,0
0,11,22,21,21,21,21,21,20,8,0
0,11,22,21,0,0,0,21,20,8,0
0,11,5,21,0,0,0,21,5,8,0
0,11,22,21,0,0,0,21,20,8,0
0,11,22,21,21,21,21,21,20,8,0
0,11,6,23,23,5,23,23,6,8,0
0,11,10,10,10,10,10,10,10,8,0
0,0,0,0,0,0,0,0,0,0,0
endlayer

layer
0,0,0,0,0,0,0,0,0,0,0
0,0,0,0,0,0,0,0,0,0,0
0,0,0,24,24,24,24,24,0,0,0
0,0,24,24,24,24,24,24,24,0,0
0,0,24,24,25,25,25,24,24,0,0
0,0,24,24,25,25,25,24,24,0,0
0,0,24,24,25,25,25,24,24,0,0
0,0,24,24,24,24,24,24,24,0,0
0,0,0,24,24,24,24,24,0,0,0
0,0,0,0,0,0,0,0,0,0,0
0,0,0,0,0,0,0,0,0,0,0
endlayer

