
# Created by Ruins mod version 17.0 Ingame Parser
# authoring Player: ST753M

# Summoned by other buildings that could use buildings around them to look nicer

weight=1
embed_into_distance=1
acceptable_target_blocks=grass,dirt,podzol
unacceptable_target_blocks=flowing_water,water,flowing_lava,lava
dimensions=10,11,7
allowable_overhang=1
max_leveling=2
leveling_buffer=-1
preserve_water=0
preserve_lava=0

=0,100,air
rule1=0,100,preserveBlock
rule2=0,100,minecraft:log-0
rule3=0,100,minecraft:brick_block-0
rule4=0,100,minecraft:log-8
rule5=0,100,minecraft:log-4
rule6=0,100,minecraft:spruce_stairs-0
rule7=0,100,minecraft:spruce_stairs-3
rule8=0,100,minecraft:spruce_stairs-1
rule9=0,100,minecraft:planks-0
rule10=0,100,minecraft:crafting_table-0,air
rule11=0,100,minecraft:wooden_door-1
rule12=0,100,minecraft:bed-3
rule13=0,100,minecraft:bed-11
rule14=0,100,minecraft:stained_glass_pane-8
rule15=0,100,minecraft:wooden_door-8
rule16=0,100,minecraft:spruce_stairs-2
rule17=0,100,minecraft:spruce_stairs-7
rule18=0,100,minecraft:spruce_stairs-5
rule19=0,100,minecraft:spruce_stairs-6
rule20=0,100,minecraft:spruce_stairs-4
rule21=0,100,minecraft:planks-1
rule22=0,100,minecraft:wooden_slab-1

layer
1,1,1,1,1,1,1
1,2,1,1,1,2,1
3,3,3,3,3,1,1
3,3,3,3,3,1,1
3,3,3,3,3,1,1
1,2,3,3,3,2,1
1,1,3,3,3,1,1
1,1,3,3,3,1,1
1,1,3,3,3,1,1
1,2,1,1,1,2,1
1,1,1,1,1,1,1
endlayer

layer
1,1,1,1,1,1,1
1,2,4,4,4,2,1
6,5,3,3,3,5,1
7,5,3,3,3,5,1
8,5,3,3,3,5,1
1,2,3,3,3,2,1
1,5,3,3,3,5,1
1,5,3,3,3,5,1
1,5,3,3,3,5,1
1,2,4,4,4,2,1
1,1,1,1,1,1,1
endlayer

layer
1,1,1,1,1,1,1
1,2,9,9,9,2,1
1,9,0,0,10,9,1
1,11,0,0,10,9,1
1,9,0,0,10,9,1
1,2,0,0,0,2,1
1,9,0,0,0,9,1
1,9,0,12,0,9,1
1,9,0,13,0,9,1
1,2,9,9,9,2,1
1,1,1,1,1,1,1
endlayer

layer
1,1,1,1,1,1,1
1,2,9,14,9,2,1
1,9,0,0,0,9,1
1,15,0,0,0,14,1
1,9,0,0,0,9,1
1,2,0,0,0,2,1
1,9,0,0,0,9,1
1,14,0,0,0,14,1
1,9,0,0,0,9,1
1,2,9,14,9,2,1
1,1,1,1,1,1,1
endlayer

layer
1,1,1,1,1,1,1
1,2,9,14,9,2,1
1,9,0,0,0,9,1
1,9,0,0,0,14,1
1,9,0,0,0,9,1
1,2,0,0,0,2,1
1,9,0,0,0,9,1
1,14,0,0,0,14,1
1,9,0,0,0,9,1
1,2,9,14,9,2,1
1,1,1,1,1,1,1
endlayer

layer
1,1,1,1,1,1,1
1,2,9,9,9,2,1
1,9,0,0,0,9,1
1,9,0,0,0,9,1
1,9,0,0,0,9,1
1,2,0,0,0,2,1
1,9,0,0,0,9,1
1,9,0,0,0,9,1
1,9,0,0,0,9,1
1,2,9,9,9,2,1
1,1,1,1,1,1,1
endlayer

layer
6,6,6,6,6,6,16
7,2,4,4,4,2,16
7,5,0,0,0,5,16
7,5,0,0,0,5,16
7,5,0,0,0,5,16
7,2,4,4,4,2,16
7,5,0,0,0,5,16
7,5,0,0,0,5,16
7,5,0,0,0,5,16
7,2,4,4,4,2,16
8,8,8,8,8,8,8
endlayer

layer
1,1,1,1,1,1,1
1,7,6,6,6,6,1
1,7,19,18,17,16,1
1,7,19,0,17,16,1
1,7,19,0,17,16,1
1,7,19,0,17,16,1
1,7,19,0,17,16,1
1,7,19,0,17,16,1
1,7,19,20,20,16,1
1,8,8,8,8,8,1
1,1,1,1,1,1,1
endlayer

layer
1,1,1,1,1,1,1
1,1,1,1,1,1,1
1,1,7,6,16,1,1
1,1,7,21,16,1,1
1,1,7,21,16,1,1
1,1,7,21,16,1,1
1,1,7,21,16,1,1
1,1,7,21,16,1,1
1,1,8,8,16,1,1
1,1,1,1,1,1,1
1,1,1,1,1,1,1
endlayer

layer
1,1,1,1,1,1,1
1,1,1,1,1,1,1
1,1,1,1,1,1,1
1,1,1,22,1,1,1
1,1,1,22,1,1,1
1,1,1,22,1,1,1
1,1,1,22,1,1,1
1,1,1,22,1,1,1
1,1,1,1,1,1,1
1,1,1,1,1,1,1
1,1,1,1,1,1,1
endlayer

