
# Created by Ruins mod version 17.0 Ingame Parser
# authoring Player: ST753M

weight=1
embed_into_distance=0
acceptable_target_blocks=
unacceptable_target_blocks=flowing_water,water,flowing_lava,lava
dimensions=18,17,20
allowable_overhang=0
max_leveling=0
leveling_buffer=-1
preserve_water=0
preserve_lava=0

=0,100,air
rule1=0,100,preserveBlock

rule2=0,100,minecraft:stonebrick-0,minecraft:monster_egg-3,minecraft:monster_egg-4,minecraft:stonebrick-1,minecraft:stonebrick-2,minecraft:stone-0,minecraft:monster_egg-2,minecraft:stonebrick-0,minecraft:monster_egg-3,minecraft:monster_egg-4,minecraft:stonebrick-1,minecraft:stonebrick-2,minecraft:stone-0,minecraft:monster_egg-2,minecraft:stonebrick-0,minecraft:monster_egg-3,minecraft:monster_egg-4,minecraft:stonebrick-1,minecraft:stonebrick-2,minecraft:stone-0,minecraft:monster_egg-2,minecraft:stone_brick_stairs-1,minecraft:stone_brick_stairs-3,minecraft:stone_brick_stairs-7,minecraft:stone_brick_stairs-5
rule3=0,100,minecraft:stonebrick-0,minecraft:monster_egg-3,minecraft:monster_egg-4,minecraft:stonebrick-1,minecraft:stonebrick-2,minecraft:stone-0,minecraft:monster_egg-2,minecraft:stonebrick-0,minecraft:monster_egg-3,minecraft:monster_egg-4,minecraft:stonebrick-1,minecraft:stonebrick-2,minecraft:stone-0,minecraft:monster_egg-2,minecraft:stonebrick-0,minecraft:monster_egg-3,minecraft:monster_egg-4,minecraft:stonebrick-1,minecraft:stonebrick-2,minecraft:stone-0,minecraft:monster_egg-2,minecraft:stone_brick_stairs-1,minecraft:stone_brick_stairs-3,minecraft:stone_brick_stairs-7,minecraft:stone_brick_stairs-5

rule4=0,100,minecraft:stone_brick_stairs-3
rule5=0,100,minecraft:stone_brick_stairs-6
rule6=0,100,minecraft:stone_brick_stairs-1
rule7=0,100,minecraft:stone_brick_stairs-2
rule8=0,100,minecraft:stone_brick_stairs-0
rule9=0,100,minecraft:stone_brick_stairs-5
rule10=0,100,minecraft:water-0
rule11=0,100,minecraft:stone_brick_stairs-4
rule12=0,100,minecraft:water-9
rule13=0,100,minecraft:stonebrick-3
rule14=0,100,minecraft:vine-2
rule15=0,100,minecraft:water-1
rule16=0,100,minecraft:vine-4
rule17=0,100,minecraft:stone_brick_stairs-7
rule18=0,100,minecraft:stone_slab-13
rule19=0,100,minecraft:vine-1
rule20=0,100,minecraft:vine-8
rule21=0,100,minecraft:vine-6

layer
1,1,1,1,1,1,2,2,2,2,2,2,2,2,2,1,1,1,1,1
1,1,1,1,1,2,2,2,3,3,3,3,3,2,2,2,1,1,1,1
1,1,1,1,2,2,3,3,3,3,3,3,3,3,3,2,2,1,1,1
1,1,1,2,2,3,3,3,3,3,3,3,3,3,3,3,2,2,1,1
2,2,2,2,3,3,3,3,3,3,3,3,3,3,3,3,3,2,2,1
2,2,2,2,3,3,3,3,3,3,3,3,3,3,3,3,3,2,2,1
2,2,2,3,3,3,3,3,3,3,3,3,3,3,3,3,3,3,2,1
2,2,2,3,3,3,3,3,3,3,3,3,3,3,3,3,3,3,2,1
2,2,2,3,3,3,3,3,3,3,3,3,3,3,3,3,3,3,2,1
2,2,2,3,3,3,3,3,3,3,3,3,3,3,3,3,3,3,2,1
2,2,2,3,3,3,3,3,3,3,3,3,3,3,3,3,3,3,2,1
2,2,2,2,3,3,3,3,3,3,3,3,3,3,3,3,3,2,2,1
2,2,2,2,3,3,3,3,3,3,3,3,3,3,3,3,3,2,2,1
1,1,1,2,2,3,3,3,3,3,3,3,3,3,3,3,2,2,1,1
1,1,1,1,2,2,3,3,3,3,3,3,3,3,3,2,2,1,1,1
1,1,1,1,1,2,2,2,3,3,3,3,3,2,2,2,1,1,1,1
1,1,1,1,1,1,2,2,2,2,2,2,2,2,2,1,1,1,1,1
endlayer

layer
1,1,1,1,1,1,2,2,2,2,2,2,2,2,2,1,1,1,1,1
1,1,1,1,1,2,2,2,3,3,3,3,3,2,2,2,1,1,1,1
1,1,1,1,2,2,3,3,3,3,3,3,3,3,3,2,2,1,1,1
1,1,1,2,2,3,3,3,3,3,3,3,3,3,3,3,2,2,1,1
2,2,2,2,3,3,3,3,3,3,3,3,3,3,3,3,3,2,2,1
2,2,2,2,3,3,3,3,3,3,3,3,3,3,3,3,3,2,2,1
2,2,2,3,3,3,3,3,3,3,3,3,3,3,3,3,3,3,2,1
2,2,2,3,3,3,3,3,3,3,3,3,3,3,3,3,3,3,2,1
2,2,2,3,3,3,3,3,3,3,3,3,3,3,3,3,3,3,2,1
2,2,2,3,3,3,3,3,3,3,3,3,3,3,3,3,3,3,2,1
2,2,2,3,3,3,3,3,3,3,3,3,3,3,3,3,3,3,2,1
2,2,2,2,3,3,3,3,3,3,3,3,3,3,3,3,3,2,2,1
2,2,2,2,3,3,3,3,3,3,3,3,3,3,3,3,3,2,2,1
1,1,1,2,2,3,3,3,3,3,3,3,3,3,3,3,2,2,1,1
1,1,1,1,2,2,3,3,3,3,3,3,3,3,3,2,2,1,1,1
1,1,1,1,1,2,2,2,3,3,3,3,3,2,2,2,1,1,1,1
1,1,1,1,1,1,2,2,2,2,2,2,2,2,2,1,1,1,1,1
endlayer

layer
1,1,1,1,1,1,2,2,3,3,3,3,3,2,2,1,1,1,1,1
1,1,1,1,1,2,3,3,6,5,0,0,4,3,3,2,1,1,1,1
1,1,1,1,2,3,7,0,0,0,0,0,0,0,4,3,2,1,1,1
1,1,1,2,3,0,0,0,0,0,0,0,0,0,0,0,3,2,1,1
2,2,2,3,6,0,0,0,8,8,8,8,7,0,0,0,6,3,2,1
2,6,9,3,0,0,0,8,4,3,3,3,8,7,0,0,0,3,2,1
0,0,0,0,0,0,8,4,3,10,10,10,3,8,7,0,0,6,3,1
0,0,0,0,0,0,4,3,10,10,10,10,10,3,7,0,0,0,3,1
0,0,0,0,0,0,4,3,10,10,3,10,10,3,7,0,0,0,3,1
0,0,0,0,0,0,4,3,10,10,10,10,10,3,7,0,0,0,3,1
0,0,0,0,0,0,6,4,3,10,10,10,3,7,6,0,0,8,3,1
2,8,11,3,0,0,0,6,4,3,3,3,7,6,0,0,0,3,2,1
2,2,2,3,8,0,0,0,6,6,6,6,6,0,0,0,8,3,2,1
1,1,1,2,3,0,0,0,0,0,0,0,0,0,0,0,3,2,1,1
1,1,1,1,2,3,7,0,0,0,0,0,0,0,4,3,2,1,1,1
1,1,1,1,1,2,3,3,8,5,0,0,4,3,3,2,1,1,1,1
1,1,1,1,1,1,2,2,3,3,3,3,3,2,2,1,1,1,1,1
endlayer

layer
1,1,1,1,1,1,2,2,3,3,3,3,3,2,2,1,1,1,1,1
1,1,1,1,1,2,3,3,0,4,5,0,0,3,3,2,1,1,1,1
1,1,1,1,2,3,0,0,0,0,0,0,0,0,0,3,2,1,1,1
1,1,1,2,3,0,0,0,0,0,0,0,0,0,0,0,3,2,1,1
2,2,2,3,0,0,0,0,0,0,0,0,0,0,0,0,0,3,2,1
2,6,9,3,0,0,0,0,0,0,0,0,0,0,0,0,0,3,2,1
0,0,0,0,0,0,0,0,0,0,0,0,0,0,0,0,0,0,3,1
0,0,0,0,0,0,0,0,0,0,12,0,0,0,0,0,0,0,3,1
0,0,0,0,0,0,0,0,0,12,3,12,0,0,0,0,0,0,13,1
0,0,0,0,0,0,0,0,0,0,12,0,0,0,0,0,0,0,3,1
0,0,0,0,0,0,0,0,0,0,0,0,0,0,0,0,0,0,3,1
2,8,11,3,0,0,0,0,0,0,0,0,0,0,0,0,0,3,2,1
2,2,2,3,0,0,0,0,0,0,0,0,0,0,0,0,0,3,2,1
1,1,1,2,3,0,0,0,0,0,0,0,0,0,0,0,3,2,1,1
1,1,1,1,2,3,0,0,0,0,0,0,0,0,0,3,2,1,1,1
1,1,1,1,1,2,3,3,0,4,5,0,0,3,3,2,1,1,1,1
1,1,1,1,1,1,2,2,3,3,3,3,3,2,2,1,1,1,1,1
endlayer

layer
1,1,1,1,1,1,2,2,3,3,3,3,3,2,2,1,1,1,1,1
1,1,1,1,1,2,3,3,0,0,4,5,0,3,3,2,1,1,1,1
1,1,1,1,2,3,0,0,0,0,0,0,0,0,0,3,2,1,1,1
1,1,1,2,3,0,0,0,0,0,0,0,0,0,0,0,3,2,1,1
2,2,2,3,0,0,0,0,0,0,0,0,0,0,0,0,0,3,2,1
2,6,9,3,0,0,0,0,0,0,0,0,0,0,0,0,0,3,2,1
0,0,0,0,0,0,0,0,0,0,0,0,0,0,0,0,0,0,3,1
0,0,0,0,0,0,0,0,0,0,12,0,0,0,0,0,0,0,13,1
0,0,0,0,0,0,0,0,0,12,13,12,0,0,0,0,0,0,3,1
0,0,0,0,0,0,0,0,0,0,12,0,0,0,0,0,0,0,13,1
0,0,0,0,0,0,0,0,0,0,0,0,0,0,0,0,0,0,3,1
2,8,11,3,0,0,0,0,0,0,0,0,0,0,0,0,0,3,2,1
2,2,2,3,0,0,0,0,0,0,0,0,0,0,0,0,0,3,2,1
1,1,1,2,3,0,0,0,0,0,0,0,0,0,0,0,3,2,1,1
1,1,1,1,2,3,0,0,0,0,0,0,0,0,0,3,2,1,1,1
1,1,1,1,1,2,3,3,0,0,4,5,0,3,3,2,1,1,1,1
1,1,1,1,1,1,2,2,3,3,3,3,3,2,2,1,1,1,1,1
endlayer

layer
1,1,1,1,1,1,2,2,3,13,3,3,3,2,2,1,1,1,1,1
1,1,1,1,1,2,3,3,0,0,0,4,5,3,3,2,1,1,1,1
1,1,1,1,2,3,0,0,0,0,0,0,0,0,0,3,2,1,1,1
1,1,1,2,3,0,0,0,0,0,0,0,0,0,0,0,3,2,1,1
2,2,2,3,0,0,0,0,0,0,0,0,0,0,0,0,14,3,2,1
2,6,9,3,0,0,0,0,0,0,0,0,0,0,0,0,0,3,2,1
0,0,0,0,0,0,0,0,0,0,0,0,0,0,0,0,0,0,3,1
0,0,0,0,0,0,0,0,0,0,15,0,0,0,0,0,0,0,3,1
0,0,0,0,0,0,0,0,0,15,10,15,0,0,0,0,0,0,13,1
0,0,0,0,0,0,0,0,0,0,15,0,0,0,0,0,0,0,3,1
0,0,0,0,0,0,0,0,0,0,0,0,0,0,0,0,0,0,3,1
2,8,11,3,0,0,0,0,0,0,0,0,0,0,0,0,16,3,2,1
2,2,2,3,0,0,0,0,0,0,0,0,0,0,0,0,0,3,2,1
1,1,1,2,3,0,0,0,0,0,0,0,0,0,0,0,3,2,1,1
1,1,1,1,2,3,0,0,0,0,0,0,0,0,0,3,2,1,1,1
1,1,1,1,1,2,3,3,0,0,0,4,5,3,3,2,1,1,1,1
1,1,1,1,1,1,2,2,3,13,3,3,3,2,2,1,1,1,1,1
endlayer

layer
1,1,1,1,1,1,2,2,3,3,3,3,3,2,2,1,1,1,1,1
1,1,1,1,1,2,3,3,5,0,0,0,4,3,3,2,1,1,1,1
1,1,1,1,2,3,5,0,0,0,0,0,0,0,17,3,2,1,1,1
1,1,1,2,3,0,0,0,0,0,0,0,0,0,0,14,3,2,1,1
2,2,2,3,9,0,0,0,0,0,0,0,0,0,0,0,9,3,2,1
2,2,2,3,0,0,0,0,0,0,0,0,0,0,0,0,0,3,2,1
9,9,9,9,0,0,0,0,0,0,0,0,0,0,0,0,0,9,3,1
0,0,0,0,0,0,0,0,0,0,0,0,0,0,0,0,0,0,3,1
0,0,0,0,0,0,0,0,0,0,0,0,0,0,0,0,0,16,3,1
0,0,0,0,0,0,0,0,0,0,0,0,0,0,0,0,0,0,3,1
11,11,11,11,0,0,0,0,0,0,0,0,0,0,0,0,0,11,3,1
2,2,2,3,0,0,0,0,0,0,0,0,0,0,0,0,0,3,2,1
2,2,2,3,11,0,0,0,0,0,0,0,0,0,0,0,11,3,2,1
1,1,1,2,3,0,0,0,0,0,0,0,0,0,0,0,3,2,1,1
1,1,1,1,2,3,5,0,0,0,0,0,0,0,17,3,2,1,1,1
1,1,1,1,1,2,3,3,5,0,0,0,4,3,3,2,1,1,1,1
1,1,1,1,1,1,2,2,3,3,3,3,3,2,2,1,1,1,1,1
endlayer

layer
1,1,1,1,1,1,2,2,3,3,3,3,3,2,2,1,1,1,1,1
1,1,1,1,1,2,3,3,3,5,0,0,0,3,3,2,1,1,1,1
1,1,1,1,2,3,3,3,3,3,3,3,3,3,3,3,2,1,1,1
1,1,1,2,3,3,3,3,3,5,9,17,3,3,3,3,3,2,1,1
2,2,2,3,3,3,3,5,9,9,18,9,9,17,3,3,3,3,2,1
2,2,2,3,3,3,5,9,0,0,0,0,0,9,17,3,3,3,2,1
2,2,3,3,3,3,5,0,0,0,0,0,0,0,17,3,3,3,3,1
2,2,3,3,3,5,9,0,0,0,0,0,0,0,9,17,3,3,3,1
2,2,3,3,3,5,18,0,0,0,0,0,0,0,18,17,3,3,3,1
2,2,3,3,3,5,11,0,0,0,0,0,0,0,17,11,3,3,3,1
2,2,3,3,3,3,5,0,0,0,0,0,0,0,17,3,3,3,3,1
2,2,2,3,3,3,5,11,0,0,0,0,0,17,11,3,3,3,2,1
2,2,2,3,3,3,3,5,11,5,18,17,11,11,3,3,3,3,2,1
1,1,1,2,3,3,3,3,3,5,11,11,3,3,3,3,3,2,1,1
1,1,1,1,2,3,3,3,3,3,3,3,3,3,3,3,2,1,1,1
1,1,1,1,1,2,3,3,3,5,0,0,0,3,3,2,1,1,1,1
1,1,1,1,1,1,2,2,3,3,3,3,3,2,2,1,1,1,1,1
endlayer

layer
1,1,1,1,1,1,2,2,3,3,3,3,3,2,2,1,1,1,1,1
1,1,1,1,1,2,3,3,0,0,0,0,0,3,3,2,1,1,1,1
1,1,1,1,2,3,0,0,0,0,0,0,0,0,0,3,2,1,1,1
1,1,1,2,3,0,0,0,0,0,0,0,0,0,0,0,3,2,1,1
2,2,2,3,0,0,0,8,8,8,13,8,8,7,0,0,0,3,2,1
2,2,2,3,0,0,8,4,0,0,0,0,0,8,7,0,0,3,2,1
2,2,3,0,0,0,4,0,0,0,0,0,0,0,7,0,0,0,3,1
2,2,3,0,0,0,4,0,0,0,0,0,0,0,7,0,0,0,3,1
2,2,3,0,0,0,13,0,0,0,0,0,0,0,13,0,0,0,3,1
2,2,3,0,0,0,4,0,0,0,0,0,0,0,7,0,0,0,3,1
2,2,3,19,0,0,4,0,0,0,0,0,0,0,7,0,0,0,3,1
2,2,2,3,0,0,4,6,0,0,0,0,0,7,6,0,0,3,2,1
2,2,2,3,0,0,0,4,6,6,13,6,6,7,0,0,0,3,2,1
1,1,1,2,3,0,0,0,0,0,0,0,0,0,0,0,3,2,1,1
1,1,1,1,2,3,0,0,0,0,0,0,0,0,0,3,2,1,1,1
1,1,1,1,1,2,3,3,0,0,0,0,0,3,3,2,1,1,1,1
1,1,1,1,1,1,2,2,3,3,3,3,3,2,2,1,1,1,1,1
endlayer

layer
1,1,1,1,1,1,1,1,3,6,3,6,3,1,1,1,1,1,1,1
1,1,1,1,1,1,13,3,14,0,0,0,0,3,13,1,1,1,1,1
1,1,1,1,1,3,19,0,0,0,0,0,0,0,0,3,1,1,1,1
1,1,1,1,3,0,0,0,0,0,0,0,0,0,0,0,3,1,1,1
1,1,1,13,0,0,0,0,0,0,0,0,0,0,0,0,0,13,1,1
1,1,1,3,0,0,0,0,0,0,0,0,0,0,0,0,0,3,1,1
2,2,3,0,0,0,0,0,0,0,0,0,0,0,0,0,0,0,3,1
2,2,3,19,0,0,0,0,0,0,0,0,0,0,0,0,0,0,4,1
2,2,3,0,0,0,0,0,0,0,0,0,0,0,0,0,0,0,3,1
2,2,3,0,0,0,0,0,0,0,0,0,0,0,0,0,0,0,4,1
2,2,3,0,0,0,0,0,0,0,0,0,0,0,0,0,0,0,3,1
1,1,1,3,0,0,0,0,0,0,0,0,0,0,0,0,0,3,1,1
1,1,1,13,0,0,0,0,0,0,0,0,0,0,0,0,0,13,1,1
1,1,1,1,3,0,0,0,0,0,0,0,0,0,0,0,3,1,1,1
1,1,1,1,1,3,0,0,0,0,0,0,0,0,0,3,1,1,1,1
1,1,1,1,1,1,13,3,0,0,0,0,0,3,13,1,1,1,1,1
1,1,1,1,1,1,1,1,3,8,3,8,3,1,1,1,1,1,1,1
endlayer

layer
1,1,1,1,1,1,1,1,3,3,13,3,3,1,1,1,1,1,1,1
1,1,1,1,1,1,3,3,14,0,0,0,0,3,3,1,1,1,1,1
1,1,1,1,1,3,0,0,0,0,0,0,0,0,0,3,1,1,1,1
1,1,1,1,3,0,0,0,0,0,0,0,0,0,0,0,3,1,1,1
1,1,1,3,0,0,0,0,0,0,0,0,0,0,0,0,16,3,1,1
1,1,1,3,0,0,0,0,0,0,0,0,0,0,0,0,16,3,1,1
1,1,3,0,0,0,0,0,0,0,0,0,0,0,0,0,0,0,3,1
1,1,3,0,0,0,0,0,0,0,0,0,0,0,0,0,0,0,3,1
1,1,13,0,0,0,0,0,0,0,0,0,0,0,0,0,0,16,13,1
1,1,3,0,0,0,0,0,0,0,0,0,0,0,0,0,0,0,3,1
1,1,3,0,0,0,0,0,0,0,0,0,0,0,0,0,0,0,3,1
1,1,1,3,0,0,0,0,0,0,0,0,0,0,0,0,0,3,1,1
1,1,1,3,0,0,0,0,0,0,0,0,0,0,0,0,20,3,1,1
1,1,1,1,3,0,0,0,0,0,0,0,0,0,0,0,3,1,1,1
1,1,1,1,1,3,0,0,0,0,0,0,0,0,0,3,1,1,1,1
1,1,1,1,1,1,3,3,0,0,0,0,0,3,3,1,1,1,1,1
1,1,1,1,1,1,1,1,3,3,13,3,3,1,1,1,1,1,1,1
endlayer

layer
1,1,1,1,1,1,1,1,1,3,3,3,1,1,1,1,1,1,1,1
1,1,1,1,1,1,3,3,3,18,0,18,3,3,3,1,1,1,1,1
1,1,1,1,1,3,0,0,0,0,0,0,0,0,14,3,1,1,1,1
1,1,1,1,3,14,0,0,0,0,0,0,0,0,0,0,3,1,1,1
1,1,1,3,0,0,0,0,0,0,0,0,0,0,0,0,0,3,1,1
1,1,1,3,0,0,0,0,0,0,0,0,0,0,0,0,0,3,1,1
1,1,1,3,0,0,0,0,0,0,0,0,0,0,0,0,0,3,1,1
1,1,3,18,0,0,0,0,0,0,0,0,0,0,0,0,0,18,3,1
1,1,3,0,0,0,0,0,0,0,0,0,0,0,0,0,0,0,3,1
1,1,3,18,0,0,0,0,0,0,0,0,0,0,0,0,0,18,3,1
1,1,1,3,0,0,0,0,0,0,0,0,0,0,0,0,0,3,1,1
1,1,1,3,0,0,0,0,0,0,0,0,0,0,0,0,0,3,1,1
1,1,1,3,19,0,0,0,0,0,0,0,0,0,0,0,0,3,1,1
1,1,1,1,3,0,0,0,0,0,0,0,0,0,0,0,3,1,1,1
1,1,1,1,1,3,0,0,0,0,0,0,0,0,16,3,1,1,1,1
1,1,1,1,1,1,3,3,3,18,0,18,3,3,3,1,1,1,1,1
1,1,1,1,1,1,1,1,1,3,3,3,1,1,1,1,1,1,1,1
endlayer

layer
1,1,1,1,1,1,1,1,1,1,1,1,1,1,1,1,1,1,1,1
1,1,1,1,1,1,1,3,13,3,3,3,13,3,1,1,1,1,1,1
1,1,1,1,1,3,3,0,0,0,0,0,0,16,3,3,1,1,1,1
1,1,1,1,3,0,0,0,0,0,0,0,0,0,0,0,3,1,1,1
1,1,1,1,3,0,0,0,0,0,0,0,0,0,0,0,3,1,1,1
1,1,1,3,0,0,0,0,0,0,0,0,0,0,0,0,0,3,1,1
1,1,1,13,0,0,0,0,0,0,0,0,0,0,0,0,0,13,1,1
1,1,1,3,19,0,0,0,0,0,0,0,0,0,0,0,0,3,1,1
1,1,1,3,0,0,0,0,0,0,0,0,0,0,0,0,16,3,1,1
1,1,1,3,19,0,0,0,0,0,0,0,0,0,0,0,0,3,1,1
1,1,1,13,0,0,0,0,0,0,0,0,0,0,0,0,16,13,1,1
1,1,1,3,0,0,0,0,0,0,0,0,0,0,0,0,0,3,1,1
1,1,1,1,3,0,0,0,0,0,0,0,0,0,0,0,3,1,1,1
1,1,1,1,3,0,0,0,0,0,0,0,0,0,0,0,3,1,1,1
1,1,1,1,1,3,3,20,0,20,0,0,0,16,3,3,1,1,1,1
1,1,1,1,1,1,1,3,13,3,3,3,13,3,1,1,1,1,1,1
1,1,1,1,1,1,1,1,1,1,1,1,1,1,1,1,1,1,1,1
endlayer

layer
1,1,1,1,1,1,1,1,1,1,1,1,1,1,1,1,1,1,1,1
1,1,1,1,1,1,1,1,3,3,3,3,3,1,1,1,1,1,1,1
1,1,1,1,1,1,3,3,18,0,0,14,18,3,3,1,1,1,1,1
1,1,1,1,1,13,0,0,0,0,14,0,0,0,0,13,1,1,1,1
1,1,1,1,3,0,0,0,0,0,0,0,0,0,0,14,3,1,1,1
1,1,1,1,3,0,0,0,0,0,0,0,0,0,0,0,3,1,1,1
1,1,1,3,18,0,0,0,0,0,0,0,0,0,0,0,18,3,1,1
1,1,1,3,0,0,0,0,0,0,0,0,0,0,0,0,0,3,1,1
1,1,1,3,0,0,0,0,0,0,0,0,0,0,0,0,0,3,1,1
1,1,1,3,0,0,0,0,0,0,0,0,0,0,0,0,0,3,1,1
1,1,1,3,18,0,0,0,0,0,0,0,0,0,0,0,18,3,1,1
1,1,1,1,3,0,0,0,0,0,0,0,0,0,0,0,3,1,1,1
1,1,1,1,3,0,0,0,0,0,0,0,0,0,0,0,3,1,1,1
1,1,1,1,1,13,0,0,0,0,0,0,0,0,0,13,1,1,1,1
1,1,1,1,1,1,3,3,18,0,0,0,18,3,3,1,1,1,1,1
1,1,1,1,1,1,1,1,3,3,3,3,3,1,1,1,1,1,1,1
1,1,1,1,1,1,1,1,1,1,1,1,1,1,1,1,1,1,1,1
endlayer

layer
1,1,1,1,1,1,1,1,1,1,1,1,1,1,1,1,1,1,1,1
1,1,1,1,1,1,1,1,1,1,1,1,1,1,1,1,1,1,1,1
1,1,1,1,1,1,1,3,3,3,3,3,3,3,1,1,1,1,1,1
1,1,1,1,1,1,3,18,0,0,14,0,0,18,3,1,1,1,1,1
1,1,1,1,1,3,0,0,0,0,0,0,0,0,0,3,1,1,1,1
1,1,1,1,3,18,0,0,0,0,0,0,0,0,0,18,3,1,1,1
1,1,1,1,3,0,0,0,0,0,0,0,0,0,0,0,3,1,1,1
1,1,1,1,3,0,0,0,0,0,0,0,0,0,0,0,3,1,1,1
1,1,1,1,3,0,0,0,0,0,0,0,0,0,0,16,3,1,1,1
1,1,1,1,3,0,0,0,0,0,0,0,0,0,0,0,3,1,1,1
1,1,1,1,3,0,0,0,0,0,0,0,0,0,0,0,3,1,1,1
1,1,1,1,3,18,0,0,0,0,0,0,0,0,0,18,3,1,1,1
1,1,1,1,1,3,0,0,0,0,0,0,0,0,0,3,1,1,1,1
1,1,1,1,1,1,3,18,0,0,0,20,0,18,3,1,1,1,1,1
1,1,1,1,1,1,1,3,3,3,3,3,3,3,1,1,1,1,1,1
1,1,1,1,1,1,1,1,1,1,1,1,1,1,1,1,1,1,1,1
1,1,1,1,1,1,1,1,1,1,1,1,1,1,1,1,1,1,1,1
endlayer

layer
1,1,1,1,1,1,1,1,1,1,1,1,1,1,1,1,1,1,1,1
1,1,1,1,1,1,1,1,1,1,1,1,1,1,1,1,1,1,1,1
1,1,1,1,1,1,1,1,1,1,1,1,1,1,1,1,1,1,1,1
1,1,1,1,1,1,1,3,3,3,3,3,3,3,1,1,1,1,1,1
1,1,1,1,1,1,3,3,18,0,0,0,18,3,3,1,1,1,1,1
1,1,1,1,1,3,3,0,0,0,0,0,0,0,3,3,1,1,1,1
1,1,1,1,1,3,18,0,0,0,0,0,0,0,18,3,1,1,1,1
1,1,1,1,1,3,0,0,0,0,0,0,0,0,0,3,1,1,1,1
1,1,1,1,1,3,0,0,0,0,0,0,0,0,0,3,1,1,1,1
1,1,1,1,1,3,0,0,0,0,0,0,0,0,0,3,1,1,1,1
1,1,1,1,1,3,18,0,0,0,0,0,0,0,18,3,1,1,1,1
1,1,1,1,1,3,3,19,0,0,0,0,0,0,3,3,1,1,1,1
1,1,1,1,1,1,3,3,18,0,0,0,18,3,3,1,1,1,1,1
1,1,1,1,1,1,1,3,3,3,3,3,3,3,1,1,1,1,1,1
1,1,1,1,1,1,1,1,1,1,1,1,1,1,1,1,1,1,1,1
1,1,1,1,1,1,1,1,1,1,1,1,1,1,1,1,1,1,1,1
1,1,1,1,1,1,1,1,1,1,1,1,1,1,1,1,1,1,1,1
endlayer

layer
1,1,1,1,1,1,1,1,1,1,1,1,1,1,1,1,1,1,1,1
1,1,1,1,1,1,1,1,1,1,1,1,1,1,1,1,1,1,1,1
1,1,1,1,1,1,1,1,1,1,1,1,1,1,1,1,1,1,1,1
1,1,1,1,1,1,1,1,1,1,1,1,1,1,1,1,1,1,1,1
1,1,1,1,1,1,1,1,3,3,3,3,3,1,1,1,1,1,1,1
1,1,1,1,1,1,1,3,3,3,3,3,3,3,1,1,1,1,1,1
1,1,1,1,1,1,3,3,3,0,0,21,3,3,3,1,1,1,1,1
1,1,1,1,1,1,3,3,19,0,0,0,0,3,3,1,1,1,1,1
1,1,1,1,1,1,3,3,0,0,0,0,16,3,3,1,1,1,1,1
1,1,1,1,1,1,3,3,0,0,0,0,0,3,3,1,1,1,1,1
1,1,1,1,1,1,3,3,3,20,0,0,3,3,3,1,1,1,1,1
1,1,1,1,1,1,1,3,3,3,3,3,3,3,1,1,1,1,1,1
1,1,1,1,1,1,1,1,3,3,3,3,3,1,1,1,1,1,1,1
1,1,1,1,1,1,1,1,1,1,1,1,1,1,1,1,1,1,1,1
1,1,1,1,1,1,1,1,1,1,1,1,1,1,1,1,1,1,1,1
1,1,1,1,1,1,1,1,1,1,1,1,1,1,1,1,1,1,1,1
1,1,1,1,1,1,1,1,1,1,1,1,1,1,1,1,1,1,1,1
endlayer

layer
1,1,1,1,1,1,1,1,1,1,1,1,1,1,1,1,1,1,1,1
1,1,1,1,1,1,1,1,1,1,1,1,1,1,1,1,1,1,1,1
1,1,1,1,1,1,1,1,1,1,1,1,1,1,1,1,1,1,1,1
1,1,1,1,1,1,1,1,1,1,1,1,1,1,1,1,1,1,1,1
1,1,1,1,1,1,1,1,1,1,1,1,1,1,1,1,1,1,1,1
1,1,1,1,1,1,1,1,1,1,1,1,1,1,1,1,1,1,1,1
1,1,1,1,1,1,1,1,1,3,3,3,1,1,1,1,1,1,1,1
1,1,1,1,1,1,1,1,3,3,3,3,3,1,1,1,1,1,1,1
1,1,1,1,1,1,1,1,3,3,13,3,3,1,1,1,1,1,1,1
1,1,1,1,1,1,1,1,3,3,3,3,3,1,1,1,1,1,1,1
1,1,1,1,1,1,1,1,1,3,3,3,1,1,1,1,1,1,1,1
1,1,1,1,1,1,1,1,1,1,1,1,1,1,1,1,1,1,1,1
1,1,1,1,1,1,1,1,1,1,1,1,1,1,1,1,1,1,1,1
1,1,1,1,1,1,1,1,1,1,1,1,1,1,1,1,1,1,1,1
1,1,1,1,1,1,1,1,1,1,1,1,1,1,1,1,1,1,1,1
1,1,1,1,1,1,1,1,1,1,1,1,1,1,1,1,1,1,1,1
1,1,1,1,1,1,1,1,1,1,1,1,1,1,1,1,1,1,1,1
endlayer

