
# Created by Ruins mod version 17.1 Ingame Parser
# authoring Player: ST753M

weight=1
embed_into_distance=122
acceptable_target_blocks=
unacceptable_target_blocks=flowing_water,water,flowing_lava,lava
dimensions=122,5,5
allowable_overhang=0
max_leveling=0
leveling_buffer=-1
preserve_water=0
preserve_lava=0

=0,100,preserveBlock
rule1=0,100,quark:iron_plate_stairs-6
rule2=0,100,quark:iron_plate-0
rule3=0,100,quark:iron_plate_stairs-7
rule4=0,100,quark:iron_plate_stairs-3
rule5=0,100,quark:iron_plate_stairs-2
rule6=0,100,quark:iron_plate_stairs-4
rule7=0,100,quark:iron_plate_stairs-5
rule8=0,100,quark:iron_plate_stairs-1
rule9=0,100,quark:iron_plate_stairs-0

layer
0,0,0,0,0
0,0,0,0,0
0,3,2,1,0
0,0,0,0,0
0,0,0,0,0
endlayer

layer
0,0,0,0,0
0,0,0,0,0
3,5,0,4,1
0,0,0,0,0
0,0,0,0,0
endlayer

layer
0,0,0,0,0
0,0,0,0,0
2,0,0,0,2
0,0,0,0,0
0,0,0,0,0
endlayer

layer
0,0,0,0,0
0,0,0,0,0
2,0,0,0,2
0,0,0,0,0
0,0,0,0,0
endlayer

layer
0,0,0,0,0
0,0,6,0,0
4,1,2,3,5
0,0,7,0,0
0,0,0,0,0
endlayer

layer
0,0,6,0,0
0,0,8,0,0
0,4,2,5,0
0,0,9,0,0
0,0,7,0,0
endlayer

layer
0,0,2,0,0
0,0,0,0,0
0,0,0,0,0
0,0,0,0,0
0,0,2,0,0
endlayer

layer
0,0,2,0,0
0,0,0,0,0
0,0,0,0,0
0,0,0,0,0
0,0,2,0,0
endlayer

layer
0,0,9,0,0
0,0,7,0,0
0,3,2,1,0
0,0,6,0,0
0,0,8,0,0
endlayer

layer
0,0,0,0,0
0,0,9,0,0
3,5,2,4,1
0,0,8,0,0
0,0,0,0,0
endlayer

layer
0,0,0,0,0
0,0,0,0,0
2,0,0,0,2
0,0,0,0,0
0,0,0,0,0
endlayer

layer
0,0,0,0,0
0,0,0,0,0
2,0,0,0,2
0,0,0,0,0
0,0,0,0,0
endlayer

layer
0,0,0,0,0
0,0,6,0,0
4,1,2,3,5
0,0,7,0,0
0,0,0,0,0
endlayer

layer
0,0,6,0,0
0,0,8,0,0
0,4,2,5,0
0,0,9,0,0
0,0,7,0,0
endlayer

layer
0,0,2,0,0
0,0,0,0,0
0,0,0,0,0
0,0,0,0,0
0,0,2,0,0
endlayer

layer
0,0,2,0,0
0,0,0,0,0
0,0,0,0,0
0,0,0,0,0
0,0,2,0,0
endlayer

layer
0,0,9,0,0
0,0,7,0,0
0,3,2,1,0
0,0,6,0,0
0,0,8,0,0
endlayer

layer
0,0,0,0,0
0,0,9,0,0
3,5,2,4,1
0,0,8,0,0
0,0,0,0,0
endlayer

layer
0,0,0,0,0
0,0,0,0,0
2,0,0,0,2
0,0,0,0,0
0,0,0,0,0
endlayer

layer
0,0,0,0,0
0,0,0,0,0
2,0,0,0,2
0,0,0,0,0
0,0,0,0,0
endlayer

layer
0,0,0,0,0
0,0,6,0,0
4,1,2,3,5
0,0,7,0,0
0,0,0,0,0
endlayer

layer
0,0,6,0,0
0,0,8,0,0
0,4,2,5,0
0,0,9,0,0
0,0,7,0,0
endlayer

layer
0,0,2,0,0
0,0,0,0,0
0,0,0,0,0
0,0,0,0,0
0,0,2,0,0
endlayer

layer
0,0,2,0,0
0,0,0,0,0
0,0,0,0,0
0,0,0,0,0
0,0,2,0,0
endlayer

layer
0,0,9,0,0
0,0,7,0,0
0,3,2,1,0
0,0,6,0,0
0,0,8,0,0
endlayer

layer
0,0,0,0,0
0,0,9,0,0
3,5,2,4,1
0,0,8,0,0
0,0,0,0,0
endlayer

layer
0,0,0,0,0
0,0,0,0,0
2,0,0,0,2
0,0,0,0,0
0,0,0,0,0
endlayer

layer
0,0,0,0,0
0,0,0,0,0
2,0,0,0,2
0,0,0,0,0
0,0,0,0,0
endlayer

layer
0,0,0,0,0
0,0,6,0,0
4,1,2,3,5
0,0,7,0,0
0,0,0,0,0
endlayer

layer
0,0,6,0,0
0,0,8,0,0
0,4,2,5,0
0,0,9,0,0
0,0,7,0,0
endlayer

layer
0,0,2,0,0
0,0,0,0,0
0,0,0,0,0
0,0,0,0,0
0,0,2,0,0
endlayer

layer
0,0,2,0,0
0,0,0,0,0
0,0,0,0,0
0,0,0,0,0
0,0,2,0,0
endlayer

layer
0,0,9,0,0
0,0,7,0,0
0,3,2,1,0
0,0,6,0,0
0,0,8,0,0
endlayer

layer
0,0,0,0,0
0,0,9,0,0
3,5,2,4,1
0,0,8,0,0
0,0,0,0,0
endlayer

layer
0,0,0,0,0
0,0,0,0,0
2,0,0,0,2
0,0,0,0,0
0,0,0,0,0
endlayer

layer
0,0,0,0,0
0,0,0,0,0
2,0,0,0,2
0,0,0,0,0
0,0,0,0,0
endlayer

layer
0,0,0,0,0
0,0,6,0,0
4,1,2,3,5
0,0,7,0,0
0,0,0,0,0
endlayer

layer
0,0,6,0,0
0,0,8,0,0
0,4,2,5,0
0,0,9,0,0
0,0,7,0,0
endlayer

layer
0,0,2,0,0
0,0,0,0,0
0,0,0,0,0
0,0,0,0,0
0,0,2,0,0
endlayer

layer
0,0,2,0,0
0,0,0,0,0
0,0,0,0,0
0,0,0,0,0
0,0,2,0,0
endlayer

layer
0,0,9,0,0
0,0,7,0,0
0,3,2,1,0
0,0,6,0,0
0,0,8,0,0
endlayer

layer
0,0,0,0,0
0,0,9,0,0
3,5,2,4,1
0,0,8,0,0
0,0,0,0,0
endlayer

layer
0,0,0,0,0
0,0,0,0,0
2,0,0,0,2
0,0,0,0,0
0,0,0,0,0
endlayer

layer
0,0,0,0,0
0,0,0,0,0
2,0,0,0,2
0,0,0,0,0
0,0,0,0,0
endlayer

layer
0,0,0,0,0
0,0,6,0,0
4,1,2,3,5
0,0,7,0,0
0,0,0,0,0
endlayer

layer
0,0,6,0,0
0,0,8,0,0
0,4,2,5,0
0,0,9,0,0
0,0,7,0,0
endlayer

layer
0,0,2,0,0
0,0,0,0,0
0,0,0,0,0
0,0,0,0,0
0,0,2,0,0
endlayer

layer
0,0,2,0,0
0,0,0,0,0
0,0,0,0,0
0,0,0,0,0
0,0,2,0,0
endlayer

layer
0,0,9,0,0
0,0,7,0,0
0,3,2,1,0
0,0,6,0,0
0,0,8,0,0
endlayer

layer
0,0,0,0,0
0,0,9,0,0
3,5,2,4,1
0,0,8,0,0
0,0,0,0,0
endlayer

layer
0,0,0,0,0
0,0,0,0,0
2,0,0,0,2
0,0,0,0,0
0,0,0,0,0
endlayer

layer
0,0,0,0,0
0,0,0,0,0
2,0,0,0,2
0,0,0,0,0
0,0,0,0,0
endlayer

layer
0,0,0,0,0
0,0,6,0,0
4,1,2,3,5
0,0,7,0,0
0,0,0,0,0
endlayer

layer
0,0,6,0,0
0,0,8,0,0
0,4,2,5,0
0,0,9,0,0
0,0,7,0,0
endlayer

layer
0,0,2,0,0
0,0,0,0,0
0,0,0,0,0
0,0,0,0,0
0,0,2,0,0
endlayer

layer
0,0,2,0,0
0,0,0,0,0
0,0,0,0,0
0,0,0,0,0
0,0,2,0,0
endlayer

layer
0,0,9,0,0
0,0,7,0,0
0,3,2,1,0
0,0,6,0,0
0,0,8,0,0
endlayer

layer
0,0,0,0,0
0,0,9,0,0
3,5,2,4,1
0,0,8,0,0
0,0,0,0,0
endlayer

layer
0,0,0,0,0
0,0,0,0,0
2,0,0,0,2
0,0,0,0,0
0,0,0,0,0
endlayer

layer
0,0,0,0,0
0,0,0,0,0
2,0,0,0,2
0,0,0,0,0
0,0,0,0,0
endlayer

layer
0,0,0,0,0
0,0,6,0,0
4,1,2,3,5
0,0,7,0,0
0,0,0,0,0
endlayer

layer
0,0,6,0,0
0,0,8,0,0
0,4,2,5,0
0,0,9,0,0
0,0,7,0,0
endlayer

layer
0,0,2,0,0
0,0,0,0,0
0,0,0,0,0
0,0,0,0,0
0,0,2,0,0
endlayer

layer
0,0,2,0,0
0,0,0,0,0
0,0,0,0,0
0,0,0,0,0
0,0,2,0,0
endlayer

layer
0,0,9,0,0
0,0,7,0,0
0,3,2,1,0
0,0,6,0,0
0,0,8,0,0
endlayer

layer
0,0,0,0,0
0,0,9,0,0
3,5,2,4,1
0,0,8,0,0
0,0,0,0,0
endlayer

layer
0,0,0,0,0
0,0,0,0,0
2,0,0,0,2
0,0,0,0,0
0,0,0,0,0
endlayer

layer
0,0,0,0,0
0,0,0,0,0
2,0,0,0,2
0,0,0,0,0
0,0,0,0,0
endlayer

layer
0,0,0,0,0
0,0,6,0,0
4,1,2,3,5
0,0,7,0,0
0,0,0,0,0
endlayer

layer
0,0,6,0,0
0,0,8,0,0
0,4,2,5,0
0,0,9,0,0
0,0,7,0,0
endlayer

layer
0,0,2,0,0
0,0,0,0,0
0,0,0,0,0
0,0,0,0,0
0,0,2,0,0
endlayer

layer
0,0,2,0,0
0,0,0,0,0
0,0,0,0,0
0,0,0,0,0
0,0,2,0,0
endlayer

layer
0,0,9,0,0
0,0,7,0,0
0,3,2,1,0
0,0,6,0,0
0,0,8,0,0
endlayer

layer
0,0,0,0,0
0,0,9,0,0
3,5,2,4,1
0,0,8,0,0
0,0,0,0,0
endlayer

layer
0,0,0,0,0
0,0,0,0,0
2,0,0,0,2
0,0,0,0,0
0,0,0,0,0
endlayer

layer
0,0,0,0,0
0,0,0,0,0
2,0,0,0,2
0,0,0,0,0
0,0,0,0,0
endlayer

layer
0,0,0,0,0
0,0,6,0,0
4,1,2,3,5
0,0,7,0,0
0,0,0,0,0
endlayer

layer
0,0,6,0,0
0,0,8,0,0
0,4,2,5,0
0,0,9,0,0
0,0,7,0,0
endlayer

layer
0,0,2,0,0
0,0,0,0,0
0,0,0,0,0
0,0,0,0,0
0,0,2,0,0
endlayer

layer
0,0,2,0,0
0,0,0,0,0
0,0,0,0,0
0,0,0,0,0
0,0,2,0,0
endlayer

layer
0,0,9,0,0
0,0,7,0,0
0,3,2,1,0
0,0,6,0,0
0,0,8,0,0
endlayer

layer
0,0,0,0,0
0,0,9,0,0
3,5,2,4,1
0,0,8,0,0
0,0,0,0,0
endlayer

layer
0,0,0,0,0
0,0,0,0,0
2,0,0,0,2
0,0,0,0,0
0,0,0,0,0
endlayer

layer
0,0,0,0,0
0,0,0,0,0
2,0,0,0,2
0,0,0,0,0
0,0,0,0,0
endlayer

layer
0,0,0,0,0
0,0,6,0,0
4,1,2,3,5
0,0,7,0,0
0,0,0,0,0
endlayer

layer
0,0,6,0,0
0,0,8,0,0
0,4,2,5,0
0,0,9,0,0
0,0,7,0,0
endlayer

layer
0,0,2,0,0
0,0,0,0,0
0,0,0,0,0
0,0,0,0,0
0,0,2,0,0
endlayer

layer
0,0,2,0,0
0,0,0,0,0
0,0,0,0,0
0,0,0,0,0
0,0,2,0,0
endlayer

layer
0,0,9,0,0
0,0,7,0,0
0,3,2,1,0
0,0,6,0,0
0,0,8,0,0
endlayer

layer
0,0,0,0,0
0,0,9,0,0
3,5,2,4,1
0,0,8,0,0
0,0,0,0,0
endlayer

layer
0,0,0,0,0
0,0,0,0,0
2,0,0,0,2
0,0,0,0,0
0,0,0,0,0
endlayer

layer
0,0,0,0,0
0,0,0,0,0
2,0,0,0,2
0,0,0,0,0
0,0,0,0,0
endlayer

layer
0,0,0,0,0
0,0,6,0,0
4,1,2,3,5
0,0,7,0,0
0,0,0,0,0
endlayer

layer
0,0,6,0,0
0,0,8,0,0
0,4,2,5,0
0,0,9,0,0
0,0,7,0,0
endlayer

layer
0,0,2,0,0
0,0,0,0,0
0,0,0,0,0
0,0,0,0,0
0,0,2,0,0
endlayer

layer
0,0,2,0,0
0,0,0,0,0
0,0,0,0,0
0,0,0,0,0
0,0,2,0,0
endlayer

layer
0,0,9,0,0
0,0,7,0,0
0,3,2,1,0
0,0,6,0,0
0,0,8,0,0
endlayer

layer
0,0,0,0,0
0,0,9,0,0
3,5,2,4,1
0,0,8,0,0
0,0,0,0,0
endlayer

layer
0,0,0,0,0
0,0,0,0,0
2,0,0,0,2
0,0,0,0,0
0,0,0,0,0
endlayer

layer
0,0,0,0,0
0,0,0,0,0
2,0,0,0,2
0,0,0,0,0
0,0,0,0,0
endlayer

layer
0,0,0,0,0
0,0,6,0,0
4,1,2,3,5
0,0,7,0,0
0,0,0,0,0
endlayer

layer
0,0,6,0,0
0,0,8,0,0
0,4,2,5,0
0,0,9,0,0
0,0,7,0,0
endlayer

layer
0,0,2,0,0
0,0,0,0,0
0,0,0,0,0
0,0,0,0,0
0,0,2,0,0
endlayer

layer
0,0,2,0,0
0,0,0,0,0
0,0,0,0,0
0,0,0,0,0
0,0,2,0,0
endlayer

layer
0,0,9,0,0
0,0,7,0,0
0,3,2,1,0
0,0,6,0,0
0,0,8,0,0
endlayer

layer
0,0,0,0,0
0,0,9,0,0
3,5,2,4,1
0,0,8,0,0
0,0,0,0,0
endlayer

layer
0,0,0,0,0
0,0,0,0,0
2,0,0,0,2
0,0,0,0,0
0,0,0,0,0
endlayer

layer
0,0,0,0,0
0,0,0,0,0
2,0,0,0,2
0,0,0,0,0
0,0,0,0,0
endlayer

layer
0,0,0,0,0
0,0,6,0,0
4,1,2,3,5
0,0,7,0,0
0,0,0,0,0
endlayer

layer
0,0,6,0,0
0,0,8,0,0
0,4,2,5,0
0,0,9,0,0
0,0,7,0,0
endlayer

layer
0,0,2,0,0
0,0,0,0,0
0,0,0,0,0
0,0,0,0,0
0,0,2,0,0
endlayer

layer
0,0,2,0,0
0,0,0,0,0
0,0,0,0,0
0,0,0,0,0
0,0,2,0,0
endlayer

layer
0,0,9,0,0
0,0,7,0,0
0,3,2,1,0
0,0,6,0,0
0,0,8,0,0
endlayer

layer
0,0,0,0,0
0,0,9,0,0
3,5,2,4,1
0,0,8,0,0
0,0,0,0,0
endlayer

layer
0,0,0,0,0
0,0,0,0,0
2,0,0,0,2
0,0,0,0,0
0,0,0,0,0
endlayer

layer
0,0,0,0,0
0,0,0,0,0
2,0,0,0,2
0,0,0,0,0
0,0,0,0,0
endlayer

layer
0,0,0,0,0
0,0,6,0,0
4,1,2,3,5
0,0,7,0,0
0,0,0,0,0
endlayer

layer
0,0,6,0,0
0,0,8,0,0
0,4,2,5,0
0,0,9,0,0
0,0,7,0,0
endlayer

layer
0,0,2,0,0
0,0,0,0,0
0,0,0,0,0
0,0,0,0,0
0,0,2,0,0
endlayer

layer
0,0,2,0,0
0,0,0,0,0
0,0,0,0,0
0,0,0,0,0
0,0,2,0,0
endlayer

layer
0,0,9,0,0
0,0,7,0,0
0,0,0,0,0
0,0,6,0,0
0,0,8,0,0
endlayer

layer
0,0,0,0,0
0,0,9,0,0
0,0,2,0,0
0,0,8,0,0
0,0,0,0,0
endlayer

