
# Created by Ruins mod version 17.0 Ingame Parser
# authoring Player: ST753M

weight=1
embed_into_distance=6
acceptable_target_blocks=
unacceptable_target_blocks=flowing_water,water,flowing_lava,lava
dimensions=19,11,11
allowable_overhang=6
max_leveling=2
leveling_buffer=0
preserve_water=0
preserve_lava=0

rule1=0,100,preserveBlock
rule2=0,100,minecraft:end_stone-0
rule3=0,100,minecraft:purpur_pillar-4
rule4=0,100,minecraft:purpur_pillar-8
rule5=0,100,minecraft:purpur_pillar-0
rule6=0,100,minecraft:purpur_stairs-2
rule7=0,100,minecraft:purpur_block-0
rule8=0,100,minecraft:wool-10
rule9=0,100,minecraft:end_bricks-0
rule10=0,100,minecraft:wooden_door-3
rule11=0,100,minecraft:purpur_stairs-1
rule12=0,100,minecraft:nether_brick_fence-0
rule13=0,100,minecraft:purpur_stairs-0
rule14=0,100,minecraft:purpur_stairs-4
rule15=0,100,minecraft:stained_glass_pane-10
rule16=0,100,minecraft:wooden_door-8
rule17=0,100,minecraft:carpet-10
rule18=0,100,minecraft:end_rod-0
rule19=0,100,minecraft:purpur_stairs-3
rule20=0,100,minecraft:anvil-11
rule21=0,100,minecraft:purpur_stairs-7
rule22=0,100,minecraft:purpur_stairs-5
rule23=0,100,minecraft:purpur_stairs-6
rule24=0,100,minecraft:purpur_slab-0
rule25=0,100,minecraft:purpur_slab-8

layer
1,1,1,1,1,1,1,1,1,1,1
1,1,1,1,1,1,1,1,1,1,1
1,1,1,1,1,1,1,1,1,1,1
1,1,1,1,1,1,1,1,1,1,1
1,1,1,1,2,2,2,1,1,1,1
1,1,1,1,2,2,2,1,1,1,1
1,1,1,1,2,2,2,1,1,1,1
1,1,1,1,1,1,1,1,1,1,1
1,1,1,1,1,1,1,1,1,1,1
1,1,1,1,1,1,1,1,1,1,1
1,1,1,1,1,1,1,1,1,1,1
endlayer

layer
1,1,1,1,1,1,1,1,1,1,1
1,1,1,1,1,1,1,1,1,1,1
1,1,1,1,2,2,2,1,1,1,1
1,1,1,2,2,2,2,2,1,1,1
1,1,2,2,2,2,2,2,2,1,1
1,1,2,2,2,2,2,2,2,1,1
1,1,2,2,2,2,2,2,2,1,1
1,1,1,2,2,2,2,2,1,1,1
1,1,1,1,2,2,2,1,1,1,1
1,1,1,1,1,1,1,1,1,1,1
1,1,1,1,1,1,1,1,1,1,1
endlayer

layer
1,1,1,1,1,1,1,1,1,1,1
1,1,2,2,2,2,2,2,2,1,1
1,2,2,2,2,2,2,2,2,2,1
1,2,2,2,2,2,2,2,2,2,1
1,2,2,2,2,2,2,2,2,2,1
1,2,2,2,2,2,2,2,2,2,1
1,2,2,2,2,2,2,2,2,2,1
1,2,2,2,2,2,2,2,2,2,1
1,2,2,2,2,2,2,2,2,2,1
1,1,2,2,2,2,2,2,2,1,1
1,1,1,1,1,1,1,1,1,1,1
endlayer

layer
1,1,1,2,2,2,2,2,1,1,1
1,1,2,2,2,2,2,2,2,1,1
1,2,2,2,2,2,2,2,2,2,1
2,2,2,2,2,2,2,2,2,2,2
2,2,2,2,2,2,2,2,2,2,2
2,2,2,2,2,2,2,2,2,2,2
2,2,2,2,2,2,2,2,2,2,2
2,2,2,2,2,2,2,2,2,2,2
1,2,2,2,2,2,2,2,2,2,1
1,1,2,2,2,2,2,2,2,1,1
1,1,1,2,2,2,2,2,1,1,1
endlayer

layer
1,1,2,2,2,2,2,2,2,1,1
1,2,2,2,2,2,2,2,2,2,1
2,2,2,2,2,2,2,2,2,2,2
2,2,2,2,2,2,2,2,2,2,2
2,2,2,2,2,2,2,2,2,2,2
2,2,2,2,2,2,2,2,2,2,2
2,2,2,2,2,2,2,2,2,2,2
2,2,2,2,2,2,2,2,2,2,2
2,2,2,2,2,2,2,2,2,2,2
1,2,2,2,2,2,2,2,2,2,1
1,1,2,2,2,2,2,2,2,1,1
endlayer

layer
1,1,1,2,2,2,2,2,1,1,1
1,2,2,2,2,2,2,2,2,2,1
1,2,2,2,2,2,2,2,2,2,1
2,2,2,2,2,2,2,2,2,2,2
2,2,2,2,2,2,2,2,2,2,2
2,2,2,2,2,2,2,2,2,2,2
2,2,2,2,2,2,2,2,2,2,2
2,2,2,2,2,2,2,2,2,2,2
1,2,2,2,2,2,2,2,2,2,1
1,2,2,2,2,2,2,2,2,2,1
1,1,1,2,2,2,2,2,1,1,1
endlayer

layer
1,3,1,1,1,3,1,1,1,3,1
4,5,4,4,4,5,4,4,4,5,4
1,3,7,7,7,7,7,7,7,3,6
1,3,7,7,8,8,8,7,7,3,6
1,3,7,7,8,8,8,7,7,3,6
4,5,7,7,8,8,8,7,7,5,4
1,3,7,7,8,8,8,7,7,3,1
1,3,7,7,8,8,8,7,7,3,1
1,3,7,7,7,7,7,7,7,3,1
4,5,4,4,4,5,4,4,4,5,4
1,3,1,1,1,3,1,1,1,3,1
endlayer

layer
1,1,1,1,1,1,1,1,1,1,1
1,5,9,9,9,5,9,9,9,5,1
1,9,0,0,0,0,0,0,0,9,0
1,9,0,0,0,0,0,0,0,10,0
1,9,0,0,0,11,0,0,0,9,0
1,5,0,0,0,12,0,0,0,5,1
1,9,14,0,0,13,0,0,0,9,1
1,9,11,0,0,0,0,0,0,9,1
1,9,0,0,0,0,0,0,0,9,1
1,5,9,9,9,5,9,9,9,5,1
1,1,1,1,1,1,1,1,1,1,1
endlayer

layer
1,1,1,1,1,1,1,1,1,1,1
1,5,9,15,9,5,9,15,9,5,1
1,9,0,0,0,0,0,0,0,9,0
1,15,0,0,0,0,0,0,0,16,0
1,9,0,0,0,0,0,0,0,9,0
1,5,14,0,0,17,0,0,0,5,1
1,9,11,0,0,0,0,0,0,9,1
1,15,0,0,0,0,0,0,0,15,1
1,9,0,0,0,0,0,0,0,9,1
1,5,9,15,9,5,9,15,9,5,1
1,1,1,1,1,1,1,1,1,1,1
endlayer

layer
1,1,1,1,1,1,1,1,1,1,1
1,5,9,15,9,5,9,15,9,5,1
1,9,0,0,0,0,0,0,0,9,0
1,15,0,0,0,0,0,0,0,0,0
1,9,14,0,0,0,0,0,0,9,0
1,5,11,0,0,0,0,0,0,5,1
1,9,0,0,0,0,0,0,0,9,1
1,15,0,0,0,0,0,0,0,15,1
1,9,0,0,0,0,0,0,0,9,1
1,5,9,15,9,5,9,15,9,5,1
1,1,1,1,1,1,1,1,1,1,1
endlayer

layer
1,1,1,1,1,1,1,1,1,1,1
1,5,9,9,9,5,9,9,9,5,1
1,9,0,0,0,18,0,0,0,9,0
1,9,14,0,0,0,0,0,0,9,0
1,9,11,0,0,0,0,0,0,9,0
1,5,0,0,0,0,0,0,18,5,1
1,9,0,0,0,0,0,0,0,9,1
1,9,0,0,0,0,0,0,0,9,1
1,9,0,0,0,18,0,0,0,9,1
1,5,9,9,9,5,9,9,9,5,1
1,1,1,1,1,1,1,1,1,1,1
endlayer

layer
1,3,13,13,13,3,13,13,13,3,1
4,5,4,4,4,5,4,4,4,5,4
19,3,7,7,7,7,7,7,7,3,6
19,3,11,7,7,7,7,7,7,3,6
19,3,0,7,7,7,7,7,7,3,6
4,5,0,7,7,7,7,7,7,5,4
19,3,0,7,7,7,7,7,7,3,6
19,3,0,7,7,7,7,7,7,3,6
19,3,0,7,7,7,7,7,7,3,6
4,5,4,4,4,5,4,4,4,5,4
1,3,11,11,11,3,11,11,11,3,1
endlayer

layer
1,1,1,1,1,1,1,1,1,1,1
1,5,9,9,9,5,9,9,9,5,1
1,9,0,0,0,0,0,0,0,9,1
1,9,0,0,0,0,0,0,0,9,1
1,9,0,0,0,0,0,0,0,9,1
1,5,0,0,0,0,0,20,0,5,1
1,9,0,0,0,0,0,20,0,9,1
1,9,0,0,0,0,0,20,0,9,1
1,9,0,0,0,0,0,0,0,9,1
1,5,9,9,9,5,9,9,9,5,1
1,1,1,1,1,1,1,1,1,1,1
endlayer

layer
1,1,1,1,1,1,1,1,1,1,1
1,5,9,15,9,5,9,15,9,5,1
1,9,0,0,0,0,0,0,0,9,1
1,15,0,0,0,0,0,0,0,15,1
1,9,0,0,0,0,0,0,0,9,1
1,5,0,0,0,0,0,17,0,5,1
1,9,0,0,0,0,0,17,0,9,1
1,15,0,0,0,0,0,17,0,15,1
1,9,0,0,0,0,0,0,0,9,1
1,5,9,15,9,5,9,15,9,5,1
1,1,1,1,1,1,1,1,1,1,1
endlayer

layer
1,1,1,1,1,1,1,1,1,1,1
1,5,9,15,9,5,9,15,9,5,1
1,9,0,0,0,0,0,0,0,9,1
1,15,0,0,0,0,0,0,0,15,1
1,9,0,0,0,0,0,0,0,9,1
1,5,0,0,0,0,0,0,0,5,1
1,9,0,0,0,0,0,0,0,9,1
1,15,0,0,0,0,0,0,0,15,1
1,9,0,0,0,0,0,0,0,9,1
1,5,9,15,9,5,9,15,9,5,1
1,1,1,1,1,1,1,1,1,1,1
endlayer

layer
1,1,1,1,1,1,1,1,1,1,1
1,5,9,9,9,5,9,9,9,5,1
1,9,0,0,0,0,0,0,0,9,1
1,9,0,0,0,0,0,0,0,9,1
1,9,0,0,0,0,0,0,0,9,1
1,5,0,0,0,0,0,0,0,5,1
1,9,0,0,0,0,0,0,0,9,1
1,9,0,0,0,0,0,0,0,9,1
1,9,0,0,0,0,0,0,0,9,1
1,5,9,9,9,5,9,9,9,5,1
1,1,1,1,1,1,1,1,1,1,1
endlayer

layer
0,3,13,13,13,3,13,13,13,3,0
4,5,4,4,4,5,4,4,4,5,4
19,3,0,0,0,18,0,0,0,3,6
19,3,0,0,0,0,0,0,0,3,6
19,3,0,0,0,0,0,0,0,3,6
4,5,18,0,0,0,0,0,18,5,4
19,3,0,0,0,0,0,0,0,3,6
19,3,0,0,0,0,0,0,0,3,6
19,3,0,0,0,18,0,0,0,3,6
4,5,4,4,4,5,4,4,4,5,4
0,3,11,11,11,3,11,11,11,3,0
endlayer

layer
0,0,0,0,0,0,0,0,0,0,0
0,19,13,13,13,13,13,13,13,13,0
0,19,23,22,22,5,22,22,21,6,0
0,19,23,0,0,0,0,0,21,6,0
0,19,23,0,0,0,0,0,21,6,0
0,19,5,0,0,0,0,0,5,6,0
0,19,23,0,0,0,0,0,21,6,0
0,19,23,0,0,0,0,0,21,6,0
0,19,23,14,14,5,14,14,21,6,0
0,11,11,11,11,11,11,11,11,11,0
0,0,0,0,0,0,0,0,0,0,0
endlayer

layer
0,0,0,0,0,0,0,0,0,0,0
0,0,0,0,0,0,0,0,0,0,0
0,0,0,24,24,24,24,24,0,0,0
0,0,24,24,24,24,24,24,24,0,0
0,0,24,24,25,25,25,24,24,0,0
0,0,24,24,25,25,25,24,24,0,0
0,0,24,24,25,25,25,24,24,0,0
0,0,24,24,24,24,24,24,24,0,0
0,0,0,24,24,24,24,24,0,0,0
0,0,0,0,0,0,0,0,0,0,0
0,0,0,0,0,0,0,0,0,0,0
endlayer

