
# Created by Ruins mod version 17.0 Ingame Parser
# authoring Player: ST753M

weight=1
uniqueMinDistance=1000
spawnMinDistance=1000
embed_into_distance=4
acceptable_target_blocks=gravel,sand,grass
unacceptable_target_blocks=flowing_water,water,flowing_lava,lava,ice,bedrock,netherrack,nether_brick,nether_brick_fence,soul_sand,quartz_ore,end_stone,obsidian,iron_bars,Natura:Cloud,slime_grass,slime_congealed,slime_dirt,clouds,natura:clouds,twilightforest:wispy_cloud,twilightforest:fluffy_cloud
dimensions=14,3,11
allowable_overhang=4
max_leveling=5
leveling_buffer=-1
preserve_water=1
preserve_lava=1
preventRotation=1

biomesToSpawnIn=deep_ocean

=0,100,preserveBlock
rule1=0,100,minecraft:prismarine-1
rule2=0,100,minecraft:prismarine-2
rule3=0,100,minecraft:stained_glass-9
rule4=0,100,minecraft:sea_lantern-0
rule5=0,50,MobSpawner:guardian

layer
1,1,1,1,1,1,1,1,1,1,1
1,1,1,1,1,1,1,1,1,1,1
1,1,1,1,1,1,1,1,1,1,1
endlayer

layer
2,2,2,2,2,2,2,2,2,2,2
2,2,2,2,2,2,2,2,2,2,2
2,2,2,2,2,2,2,2,2,2,2
endlayer

layer
2,2,2,2,2,2,2,2,2,2,2
2,2,2,2,2,2,2,2,2,2,2
2,2,2,2,2,2,2,2,2,2,2
endlayer

layer
1,1,1,1,1,1,1,1,1,1,1
1,1,1,1,1,1,1,1,1,1,1
1,1,1,1,1,1,1,1,1,1,1
endlayer

layer
2,2,2,2,2,2,2,2,2,2,2
2,2,1,2,1,1,1,2,1,2,2
2,2,2,2,2,2,2,2,2,2,2
endlayer

layer
0,2,0,2,0,0,0,2,0,2,0
1,1,3,1,0,0,0,1,3,1,1
0,2,0,2,0,0,0,2,0,2,0
endlayer

layer
0,2,0,2,0,0,0,2,0,2,0
1,1,3,1,0,0,0,1,3,1,1
0,2,0,2,0,0,0,2,0,2,0
endlayer

layer
0,2,0,2,0,0,0,2,0,2,0
1,1,3,1,0,0,0,1,3,1,1
0,2,0,2,0,0,0,2,0,2,0
endlayer

layer
2,2,2,2,0,0,0,2,2,2,2
2,2,1,1,0,0,0,1,1,2,2
2,2,2,2,0,0,0,2,2,2,2
endlayer

layer
0,0,2,2,0,0,0,2,2,0,0
2,2,2,1,1,1,1,1,2,2,2
0,0,2,2,0,0,0,2,2,0,0
endlayer

layer
0,0,0,2,2,0,2,2,0,0,0
0,0,2,1,1,4,1,1,2,0,0
0,0,0,2,2,0,2,2,0,0,0
endlayer

layer
0,0,0,0,2,2,2,0,0,0,0
0,0,0,2,1,1,1,2,0,0,0
0,0,0,0,2,2,2,0,0,0,0
endlayer

layer
0,0,0,0,0,2,0,0,0,0,0
0,0,0,0,2,5,2,0,0,0,0
0,0,0,0,0,2,0,0,0,0,0
endlayer

layer
0,0,0,0,0,0,0,0,0,0,0
0,0,0,0,0,2,0,0,0,0,0
0,0,0,0,0,0,0,0,0,0,0
endlayer

