
# Created by Ruins mod version 17.0 Ingame Parser
# authoring Player: ST753M

weight=1
embed_into_distance=6
acceptable_target_blocks=
unacceptable_target_blocks=flowing_water,water,flowing_lava,lava
dimensions=19,11,11
allowable_overhang=6
max_leveling=2
leveling_buffer=0
preserve_water=0
preserve_lava=0

rule1=0,100,preserveBlock
rule2=0,100,minecraft:end_stone-0
rule3=0,100,minecraft:purpur_pillar-4
rule4=0,100,minecraft:purpur_pillar-8
rule5=0,100,minecraft:purpur_pillar-0
rule6=0,100,minecraft:purpur_stairs-2
rule7=0,100,minecraft:purpur_block-0
rule8=0,100,minecraft:purple_glazed_terracotta-2
rule9=0,100,minecraft:purple_glazed_terracotta-3
rule10=0,100,minecraft:purple_glazed_terracotta-1
rule11=0,100,minecraft:purple_glazed_terracotta-0
rule12=0,100,minecraft:end_bricks-0
rule13=0,100,minecraft:wooden_door-3
rule14=0,100,minecraft:purpur_stairs-4
rule15=0,100,minecraft:purpur_stairs-1
rule16=0,100,minecraft:stained_glass_pane-10
rule17=0,100,minecraft:wooden_door-8
rule18=0,100,minecraft:end_rod-0
rule19=0,100,minecraft:purpur_stairs-0
rule20=0,100,minecraft:purpur_stairs-3
rule21=0,100,minecraft:stained_hardened_clay-11
rule22=0,100,minecraft:carpet-10
rule23=0,100,CommandBlock:RUINSTRIGGER /summon shulker ~ ~1 ~:@-1
rule24=0,100,minecraft:purpur_stairs-7
rule25=0,100,minecraft:purpur_stairs-5
rule26=0,100,minecraft:purpur_stairs-6
rule27=0,100,minecraft:purpur_slab-0
rule28=0,100,minecraft:purpur_slab-8

layer
1,1,1,1,1,1,1,1,1,1,1
1,1,1,1,1,1,1,1,1,1,1
1,1,1,1,1,1,1,1,1,1,1
1,1,1,1,1,1,1,1,1,1,1
1,1,1,1,2,2,2,1,1,1,1
1,1,1,1,2,2,2,1,1,1,1
1,1,1,1,2,2,2,1,1,1,1
1,1,1,1,1,1,1,1,1,1,1
1,1,1,1,1,1,1,1,1,1,1
1,1,1,1,1,1,1,1,1,1,1
1,1,1,1,1,1,1,1,1,1,1
endlayer

layer
1,1,1,1,1,1,1,1,1,1,1
1,1,1,1,1,1,1,1,1,1,1
1,1,1,1,2,2,2,1,1,1,1
1,1,1,2,2,2,2,2,1,1,1
1,1,2,2,2,2,2,2,2,1,1
1,1,2,2,2,2,2,2,2,1,1
1,1,2,2,2,2,2,2,2,1,1
1,1,1,2,2,2,2,2,1,1,1
1,1,1,1,2,2,2,1,1,1,1
1,1,1,1,1,1,1,1,1,1,1
1,1,1,1,1,1,1,1,1,1,1
endlayer

layer
1,1,1,1,1,1,1,1,1,1,1
1,1,2,2,2,2,2,2,2,1,1
1,2,2,2,2,2,2,2,2,2,1
1,2,2,2,2,2,2,2,2,2,1
1,2,2,2,2,2,2,2,2,2,1
1,2,2,2,2,2,2,2,2,2,1
1,2,2,2,2,2,2,2,2,2,1
1,2,2,2,2,2,2,2,2,2,1
1,2,2,2,2,2,2,2,2,2,1
1,1,2,2,2,2,2,2,2,1,1
1,1,1,1,1,1,1,1,1,1,1
endlayer

layer
1,1,1,2,2,2,2,2,1,1,1
1,1,2,2,2,2,2,2,2,1,1
1,2,2,2,2,2,2,2,2,2,1
2,2,2,2,2,2,2,2,2,2,2
2,2,2,2,2,2,2,2,2,2,2
2,2,2,2,2,2,2,2,2,2,2
2,2,2,2,2,2,2,2,2,2,2
2,2,2,2,2,2,2,2,2,2,2
1,2,2,2,2,2,2,2,2,2,1
1,1,2,2,2,2,2,2,2,1,1
1,1,1,2,2,2,2,2,1,1,1
endlayer

layer
1,1,2,2,2,2,2,2,2,1,1
1,2,2,2,2,2,2,2,2,2,1
2,2,2,2,2,2,2,2,2,2,2
2,2,2,2,2,2,2,2,2,2,2
2,2,2,2,2,2,2,2,2,2,2
2,2,2,2,2,2,2,2,2,2,2
2,2,2,2,2,2,2,2,2,2,2
2,2,2,2,2,2,2,2,2,2,2
2,2,2,2,2,2,2,2,2,2,2
1,2,2,2,2,2,2,2,2,2,1
1,1,2,2,2,2,2,2,2,1,1
endlayer

layer
1,1,1,2,2,2,2,2,1,1,1
1,2,2,2,2,2,2,2,2,2,1
1,2,2,2,2,2,2,2,2,2,1
2,2,2,2,2,2,2,2,2,2,2
2,2,2,2,2,2,2,2,2,2,2
2,2,2,2,2,2,2,2,2,2,2
2,2,2,2,2,2,2,2,2,2,2
2,2,2,2,2,2,2,2,2,2,2
1,2,2,2,2,2,2,2,2,2,1
1,2,2,2,2,2,2,2,2,2,1
1,1,1,2,2,2,2,2,1,1,1
endlayer

layer
1,3,1,1,1,3,1,1,1,3,1
4,5,4,4,4,5,4,4,4,5,4
1,3,7,7,7,7,7,7,7,3,6
1,3,7,7,9,8,9,8,7,3,6
1,3,7,7,11,10,11,10,7,3,6
4,5,7,7,9,8,9,8,7,5,4
1,3,7,7,11,10,11,10,7,3,1
1,3,7,7,9,8,9,8,7,3,1
1,3,7,7,7,7,7,7,7,3,1
4,5,4,4,4,5,4,4,4,5,4
1,3,1,1,1,3,1,1,1,3,1
endlayer

layer
1,1,1,1,1,1,1,1,1,1,1
1,5,12,12,12,5,12,12,12,5,1
1,12,0,0,0,0,0,0,0,12,0
1,12,0,0,0,0,0,0,0,13,0
1,12,0,0,0,0,0,0,0,12,0
1,5,0,0,0,0,0,0,0,5,1
1,12,14,0,0,0,0,0,0,12,1
1,12,15,0,0,0,0,0,0,12,1
1,12,0,0,0,0,0,0,0,12,1
1,5,12,12,12,5,12,12,12,5,1
1,1,1,1,1,1,1,1,1,1,1
endlayer

layer
1,1,1,1,1,1,1,1,1,1,1
1,5,12,16,12,5,12,16,12,5,1
1,12,0,0,0,0,0,0,0,12,0
1,16,0,0,0,0,0,0,0,17,0
1,12,0,0,0,0,0,0,0,12,0
1,5,14,0,0,0,0,0,0,5,1
1,12,15,0,0,0,0,0,0,12,1
1,16,0,0,0,0,0,0,0,16,1
1,12,0,0,0,0,0,0,0,12,1
1,5,12,16,12,5,12,16,12,5,1
1,1,1,1,1,1,1,1,1,1,1
endlayer

layer
1,1,1,1,1,1,1,1,1,1,1
1,5,12,16,12,5,12,16,12,5,1
1,12,0,0,0,0,0,0,0,12,0
1,16,0,0,0,0,0,0,0,0,0
1,12,14,0,0,0,0,0,0,12,0
1,5,15,0,0,0,0,0,0,5,1
1,12,0,0,0,0,0,0,0,12,1
1,16,0,0,0,0,0,0,0,16,1
1,12,0,0,0,0,0,0,0,12,1
1,5,12,16,12,5,12,16,12,5,1
1,1,1,1,1,1,1,1,1,1,1
endlayer

layer
1,1,1,1,1,1,1,1,1,1,1
1,5,12,12,12,5,12,12,12,5,1
1,12,0,0,0,18,0,0,0,12,0
1,12,14,0,0,0,0,0,0,12,0
1,12,15,0,0,0,0,0,0,12,0
1,5,0,0,0,0,0,0,18,5,1
1,12,0,0,0,0,0,0,0,12,1
1,12,0,0,0,0,0,0,0,12,1
1,12,0,0,0,18,0,0,0,12,1
1,5,12,12,12,5,12,12,12,5,1
1,1,1,1,1,1,1,1,1,1,1
endlayer

layer
1,3,19,19,19,3,19,19,19,3,1
4,5,4,4,4,5,4,4,4,5,4
20,3,7,7,7,7,7,7,7,3,6
20,3,15,7,7,7,7,7,7,3,6
20,3,0,7,7,7,7,7,7,3,6
4,5,0,7,7,7,7,7,7,5,4
20,3,0,7,7,7,7,7,7,3,6
20,3,0,7,7,7,7,7,7,3,6
20,3,0,7,7,7,7,7,7,3,6
4,5,4,4,4,5,4,4,4,5,4
1,3,15,15,15,3,15,15,15,3,1
endlayer

layer
1,1,1,1,1,1,1,1,1,1,1
1,5,12,12,12,5,12,12,12,5,1
1,12,0,0,0,0,0,0,0,12,1
1,12,0,0,0,21,21,21,0,12,1
1,12,0,0,0,21,21,21,0,12,1
1,5,0,0,0,21,21,21,0,5,1
1,12,0,0,0,0,0,0,0,12,1
1,12,0,0,0,0,0,0,0,12,1
1,12,0,0,0,0,0,0,0,12,1
1,5,12,12,12,5,12,12,12,5,1
1,1,1,1,1,1,1,1,1,1,1
endlayer

layer
1,1,1,1,1,1,1,1,1,1,1
1,5,12,16,12,5,12,16,12,5,1
1,12,0,0,0,0,0,0,0,12,1
1,16,0,0,0,22,22,22,0,16,1
1,12,0,0,0,22,23,22,0,12,1
1,5,0,0,0,22,22,22,0,5,1
1,12,0,0,0,0,0,0,0,12,1
1,16,0,0,0,0,0,0,0,16,1
1,12,0,0,0,0,0,0,0,12,1
1,5,12,16,12,5,12,16,12,5,1
1,1,1,1,1,1,1,1,1,1,1
endlayer

layer
1,1,1,1,1,1,1,1,1,1,1
1,5,12,16,12,5,12,16,12,5,1
1,12,0,0,0,0,0,0,0,12,1
1,16,0,0,0,0,0,0,0,16,1
1,12,0,0,0,0,0,0,0,12,1
1,5,0,0,0,0,0,0,0,5,1
1,12,0,0,0,0,0,0,0,12,1
1,16,0,0,0,0,0,0,0,16,1
1,12,0,0,0,0,0,0,0,12,1
1,5,12,16,12,5,12,16,12,5,1
1,1,1,1,1,1,1,1,1,1,1
endlayer

layer
1,1,1,1,1,1,1,1,1,1,1
1,5,12,12,12,5,12,12,12,5,1
1,12,0,0,0,0,0,0,0,12,1
1,12,0,0,0,0,0,0,0,12,1
1,12,0,0,0,0,0,0,0,12,1
1,5,0,0,0,0,0,0,0,5,1
1,12,0,0,0,0,0,0,0,12,1
1,12,0,0,0,0,0,0,0,12,1
1,12,0,0,0,0,0,0,0,12,1
1,5,12,12,12,5,12,12,12,5,1
1,1,1,1,1,1,1,1,1,1,1
endlayer

layer
0,3,19,19,19,3,19,19,19,3,0
4,5,4,4,4,5,4,4,4,5,4
20,3,0,0,0,18,0,0,0,3,6
20,3,0,0,0,0,0,0,0,3,6
20,3,0,0,0,0,0,0,0,3,6
4,5,18,0,0,0,0,0,18,5,4
20,3,0,0,0,0,0,0,0,3,6
20,3,0,0,0,0,0,0,0,3,6
20,3,0,0,0,18,0,0,0,3,6
4,5,4,4,4,5,4,4,4,5,4
0,3,15,15,15,3,15,15,15,3,0
endlayer

layer
0,0,0,0,0,0,0,0,0,0,0
0,20,19,19,19,19,19,19,19,19,0
0,20,26,25,25,5,25,25,24,6,0
0,20,26,0,0,0,0,0,24,6,0
0,20,26,0,0,0,0,0,24,6,0
0,20,5,0,0,0,0,0,5,6,0
0,20,26,0,0,0,0,0,24,6,0
0,20,26,0,0,0,0,0,24,6,0
0,20,26,14,14,5,14,14,24,6,0
0,15,15,15,15,15,15,15,15,15,0
0,0,0,0,0,0,0,0,0,0,0
endlayer

layer
0,0,0,0,0,0,0,0,0,0,0
0,0,0,0,0,0,0,0,0,0,0
0,0,0,27,27,27,27,27,0,0,0
0,0,27,27,27,27,27,27,27,0,0
0,0,27,27,28,28,28,27,27,0,0
0,0,27,27,28,28,28,27,27,0,0
0,0,27,27,28,28,28,27,27,0,0
0,0,27,27,27,27,27,27,27,0,0
0,0,0,27,27,27,27,27,0,0,0
0,0,0,0,0,0,0,0,0,0,0
0,0,0,0,0,0,0,0,0,0,0
endlayer

