
# Created by Ruins mod version 17.1 Ingame Parser
# authoring Player: ST753M

weight=1
embed_into_distance=50
acceptable_target_blocks=
unacceptable_target_blocks=flowing_water,water,flowing_lava,lava
dimensions=50,9,9
allowable_overhang=0
max_leveling=0
leveling_buffer=-1
preserve_water=0
preserve_lava=0

rule1=0,100,preserveBlock

rule2=0,100,minecraft:red_nether_brick-0
^0,100,minecraft:red_nether_brick-0
^0,100,minecraft:red_nether_brick-0
^0,100,minecraft:nether_brick-0
^0,100,minecraft:nether_brick-0
^0,100,minecraft:obsidian-0
^0,100,minecraft:obsidian-0
^0,100,minecraft:netherrack-0

rule3=0,100,minecraft:nether_brick_stairs-4
rule4=0,100,minecraft:nether_brick_stairs-1
rule5=0,100,minecraft:nether_brick-0
rule6=0,100,minecraft:nether_brick_stairs-7
rule7=0,100,minecraft:stone_slab-14
rule8=0,100,minecraft:stone_slab-6
rule9=0,100,minecraft:nether_brick_stairs-2
rule10=0,100,minecraft:nether_brick_stairs-5
rule11=0,100,minecraft:nether_brick_stairs-0
rule12=0,100,minecraft:nether_brick_stairs-6
rule13=0,100,minecraft:nether_brick_stairs-3

layer
1,1,1,1,1,1,1,1,1
1,1,1,1,1,1,1,1,1
1,1,2,1,1,1,2,1,1
1,1,1,1,1,1,1,1,1
1,1,1,1,1,1,1,1,1
1,1,1,1,1,1,1,1,1
1,1,2,1,1,1,2,1,1
1,1,1,1,1,1,1,1,1
1,1,1,1,1,1,1,1,1
endlayer

layer
1,1,1,1,1,1,1,1,1
1,1,1,1,1,1,1,1,1
1,1,2,2,1,1,2,1,1
1,1,1,1,1,1,2,1,1
1,1,1,1,1,1,1,1,1
1,1,2,1,1,1,1,1,1
1,1,2,1,1,2,2,1,1
1,1,1,1,1,1,1,1,1
1,1,1,1,1,1,1,1,1
endlayer

layer
1,1,1,1,1,1,1,1,1
1,1,1,1,1,1,1,1,1
1,1,2,2,1,2,2,1,1
1,1,2,1,1,1,2,1,1
1,1,1,1,1,1,1,1,1
1,1,2,1,1,1,2,1,1
1,1,2,2,1,2,2,1,1
1,1,1,1,1,1,1,1,1
1,1,1,1,1,1,1,1,1
endlayer

layer
1,1,1,1,1,1,1,1,1
1,1,1,1,1,1,1,1,1
1,1,2,2,2,2,2,1,1
1,1,2,1,1,1,2,1,1
1,1,2,1,0,1,2,1,1
1,1,2,1,1,1,2,1,1
1,1,2,2,2,2,2,1,1
1,1,1,1,1,1,1,1,1
1,1,1,1,1,1,1,1,1
endlayer

layer
1,1,1,1,1,1,1,1,1
1,1,1,1,1,1,1,1,1
1,1,2,2,2,2,2,1,1
1,1,2,1,0,3,2,1,1
1,1,2,0,0,4,2,1,1
1,1,2,1,0,1,2,1,1
1,1,2,2,2,2,2,1,1
1,1,1,1,1,1,1,1,1
1,1,1,1,1,1,1,1,1
endlayer

layer
1,5,5,5,5,1,1,1,1
5,5,5,5,5,5,1,1,1
5,5,2,2,2,5,2,1,1
5,5,2,0,6,4,2,1,1
7,7,2,0,0,0,2,1,1
1,1,2,0,0,0,2,1,1
1,1,2,2,2,2,2,1,1
1,1,1,1,1,1,1,1,1
1,1,1,1,1,1,1,1,1
endlayer

layer
1,5,5,5,8,1,1,1,1
5,5,5,5,8,0,1,1,1
5,5,2,2,2,0,2,1,1
5,5,2,6,9,0,2,1,1
5,5,2,0,0,0,2,1,1
5,5,2,0,0,0,2,1,1
5,5,2,2,2,2,2,1,1
5,5,5,7,1,1,1,1,1
1,5,5,7,1,1,1,1,1
endlayer

layer
1,8,0,0,0,1,1,1,1
8,8,0,0,0,0,1,1,1
5,5,2,2,2,0,2,1,1
5,5,5,9,0,0,2,1,1
5,5,2,10,0,0,2,1,1
5,5,2,0,0,0,2,1,1
5,5,2,2,2,2,2,1,1
5,5,5,5,5,5,7,1,1
1,5,5,5,5,5,7,1,1
endlayer

layer
1,0,0,0,0,1,1,1,1
0,0,0,0,0,0,1,1,1
0,0,2,2,2,2,2,1,1
0,0,0,0,0,0,2,1,1
8,8,2,11,0,0,2,1,1
5,5,2,10,0,0,2,7,7
5,5,2,2,2,2,2,5,5
5,5,5,5,5,5,5,5,5
1,5,5,5,5,5,5,5,1
endlayer

layer
1,0,0,0,0,1,1,1,1
0,0,0,0,0,0,1,1,1
0,0,2,2,2,2,2,7,7
0,0,0,0,0,0,2,5,5
0,0,2,0,0,0,2,5,5
0,0,2,11,12,0,2,5,5
0,0,2,5,2,2,2,5,5
8,8,5,5,5,5,5,5,5
1,8,5,5,5,5,5,5,1
endlayer

layer
1,0,0,0,0,7,5,5,1
0,0,0,0,0,7,5,5,5
0,0,2,2,2,2,2,5,5
0,0,2,0,0,0,2,5,5
0,0,2,0,0,0,2,5,5
0,0,2,0,13,12,2,5,5
0,0,2,0,2,2,2,5,5
0,0,0,0,8,5,5,5,5
1,0,0,0,8,5,5,5,1
endlayer

layer
1,0,7,5,5,5,5,5,1
0,0,7,5,5,5,5,5,5
0,0,2,2,2,2,2,5,5
0,0,2,0,0,0,2,5,5
0,0,2,0,0,3,2,5,5
0,0,2,0,0,13,5,5,5
0,0,2,0,2,2,2,5,5
0,0,0,0,0,0,0,8,8
1,0,0,0,0,0,0,8,1
endlayer

layer
1,5,5,5,5,5,5,5,1
5,5,5,5,5,5,5,5,5
5,5,2,2,2,2,2,5,5
7,7,2,0,0,3,2,5,5
0,0,2,0,0,4,2,8,8
0,0,2,0,0,0,0,0,0
0,0,2,2,2,2,2,0,0
0,0,0,0,0,0,0,0,0
1,0,0,0,0,0,0,0,1
endlayer

layer
1,5,5,5,5,5,5,8,1
5,5,5,5,5,5,5,8,8
5,5,2,2,2,5,2,0,0
5,5,2,0,6,4,2,0,0
5,5,2,0,0,0,2,0,0
5,5,2,0,0,0,0,0,0
7,7,2,2,2,2,2,0,0
0,0,0,0,0,0,0,0,0
1,0,0,0,0,0,0,0,1
endlayer

layer
1,5,5,5,8,0,0,0,1
5,5,5,5,8,0,0,0,0
5,5,2,2,2,0,2,0,0
5,5,2,6,9,0,2,0,0
5,5,2,0,0,0,2,0,0
5,5,2,0,0,0,2,0,0
5,5,2,2,2,2,2,0,0
5,5,5,7,0,0,0,0,0
1,5,5,7,0,0,0,0,1
endlayer

layer
1,8,0,0,0,0,0,0,1
8,8,0,0,0,0,0,0,0
5,5,2,2,2,0,2,0,0
5,5,5,9,0,0,2,0,0
5,5,2,10,0,0,2,0,0
5,5,2,0,0,0,2,0,0
5,5,2,2,2,2,2,0,0
5,5,5,5,5,5,7,0,0
1,5,5,5,5,5,7,0,1
endlayer

layer
1,0,0,0,0,0,0,0,1
0,0,0,0,0,0,0,0,0
0,0,2,2,2,2,2,0,0
0,0,0,0,0,0,2,0,0
8,8,2,11,0,0,2,0,0
5,5,2,10,0,0,2,7,7
5,5,2,2,2,2,2,5,5
5,5,5,5,5,5,5,5,5
1,5,5,5,5,5,5,5,1
endlayer

layer
1,0,0,0,0,0,0,0,1
0,0,0,0,0,0,0,0,0
0,0,2,2,2,2,2,7,7
0,0,0,0,0,0,2,5,5
0,0,2,0,0,0,2,5,5
0,0,2,11,12,0,2,5,5
0,0,2,5,2,2,2,5,5
8,8,5,5,5,5,5,5,5
1,8,5,5,5,5,5,5,1
endlayer

layer
1,0,0,0,0,7,5,5,1
0,0,0,0,0,7,5,5,5
0,0,2,2,2,2,2,5,5
0,0,2,0,0,0,2,5,5
0,0,2,0,0,0,2,5,5
0,0,2,0,13,12,2,5,5
0,0,2,0,2,2,2,5,5
0,0,0,0,8,5,5,5,5
1,0,0,0,8,5,5,5,1
endlayer

layer
1,0,7,5,5,5,5,5,1
0,0,7,5,5,5,5,5,5
0,0,2,2,2,2,2,5,5
0,0,2,0,0,0,2,5,5
0,0,2,0,0,3,2,5,5
0,0,2,0,0,13,5,5,5
0,0,2,0,2,2,2,5,5
0,0,0,0,0,0,0,8,8
1,0,0,0,0,0,0,8,1
endlayer

layer
1,5,5,5,5,5,5,5,1
5,5,5,5,5,5,5,5,5
5,5,2,2,2,2,2,5,5
7,7,2,0,0,3,2,5,5
0,0,2,0,0,4,2,8,8
0,0,2,0,0,0,0,0,0
0,0,2,2,2,2,2,0,0
0,0,0,0,0,0,0,0,0
1,0,0,0,0,0,0,0,1
endlayer

layer
1,5,5,5,5,5,5,8,1
5,5,5,5,5,5,5,8,8
5,5,2,2,2,5,2,0,0
5,5,2,0,6,4,2,0,0
5,5,2,0,0,0,2,0,0
5,5,2,0,0,0,0,0,0
7,7,2,2,2,2,2,0,0
0,0,0,0,0,0,0,0,0
1,0,0,0,0,0,0,0,1
endlayer

layer
1,5,5,5,8,0,0,0,1
5,5,5,5,8,0,0,0,0
5,5,2,2,2,0,2,0,0
5,5,2,6,9,0,2,0,0
5,5,2,0,0,0,2,0,0
5,5,2,0,0,0,2,0,0
5,5,2,2,2,2,2,0,0
5,5,5,7,0,0,0,0,0
1,5,5,7,0,0,0,0,1
endlayer

layer
1,8,0,0,0,0,0,0,1
8,8,0,0,0,0,0,0,0
5,5,2,2,2,0,2,0,0
5,5,5,9,0,0,2,0,0
5,5,2,10,0,0,2,0,0
5,5,2,0,0,0,2,0,0
5,5,2,2,2,2,2,0,0
5,5,5,5,5,5,7,0,0
1,5,5,5,5,5,7,0,1
endlayer

layer
1,0,0,0,0,0,0,0,1
0,0,0,0,0,0,0,0,0
0,0,2,2,2,2,2,0,0
0,0,0,0,0,0,2,0,0
8,8,2,11,0,0,2,0,0
5,5,2,10,0,0,2,7,7
5,5,2,2,2,2,2,5,5
5,5,5,5,5,5,5,5,5
1,5,5,5,5,5,5,5,1
endlayer

layer
1,0,0,0,0,0,0,0,1
0,0,0,0,0,0,0,0,0
0,0,2,2,2,2,2,7,7
0,0,0,0,0,0,2,5,5
0,0,2,0,0,0,2,5,5
0,0,2,11,12,0,2,5,5
0,0,2,5,2,2,2,5,5
8,8,5,5,5,5,5,5,5
1,8,5,5,5,5,5,5,1
endlayer

layer
1,0,0,0,0,7,5,5,1
0,0,0,0,0,7,5,5,5
0,0,2,2,2,2,2,5,5
0,0,2,0,0,0,2,5,5
0,0,2,0,0,0,2,5,5
0,0,2,0,13,12,2,5,5
0,0,2,0,2,2,2,5,5
0,0,0,0,8,5,5,5,5
1,0,0,0,8,5,5,5,1
endlayer

layer
1,0,7,5,5,5,5,5,1
0,0,7,5,5,5,5,5,5
0,0,2,2,2,2,2,5,5
0,0,2,0,0,0,2,5,5
0,0,2,0,0,3,2,5,5
0,0,2,0,0,13,5,5,5
0,0,2,0,2,2,2,5,5
0,0,0,0,0,0,0,8,8
1,0,0,0,0,0,0,8,1
endlayer

layer
1,5,5,5,5,5,5,5,1
5,5,5,5,5,5,5,5,5
5,5,2,2,2,2,2,5,5
7,7,2,0,0,3,2,5,5
0,0,2,0,0,4,2,8,8
0,0,2,0,0,0,0,0,0
0,0,2,2,2,2,2,0,0
0,0,0,0,0,0,0,0,0
1,0,0,0,0,0,0,0,1
endlayer

layer
1,5,5,5,5,5,5,8,1
5,5,5,5,5,5,5,8,8
5,5,2,2,2,5,2,0,0
5,5,2,0,6,4,2,0,0
5,5,2,0,0,0,2,0,0
5,5,2,0,0,0,0,0,0
7,7,2,2,2,2,2,0,0
0,0,0,0,0,0,0,0,0
1,0,0,0,0,0,0,0,1
endlayer

layer
1,5,5,5,8,0,0,0,1
5,5,5,5,8,0,0,0,0
5,5,2,2,2,0,2,0,0
5,5,2,6,9,0,2,0,0
5,5,2,0,0,0,2,0,0
5,5,2,0,0,0,2,0,0
5,5,2,2,2,2,2,0,0
5,5,5,7,0,0,0,0,0
1,5,5,7,0,0,0,0,1
endlayer

layer
1,8,0,0,0,0,0,0,1
8,8,0,0,0,0,0,0,0
5,5,2,2,2,0,2,0,0
5,5,5,9,0,0,2,0,0
5,5,2,10,0,0,2,0,0
5,5,2,0,0,0,2,0,0
5,5,2,2,2,2,2,0,0
5,5,5,5,5,5,7,0,0
1,5,5,5,5,5,7,0,1
endlayer

layer
1,0,0,0,0,0,0,0,1
0,0,0,0,0,0,0,0,0
0,0,2,2,2,2,2,0,0
0,0,0,0,0,0,2,0,0
8,8,2,11,0,0,2,0,0
5,5,2,10,0,0,2,7,7
5,5,2,2,2,2,2,5,5
5,5,5,5,5,5,5,5,5
1,5,5,5,5,5,5,5,1
endlayer

layer
1,0,0,0,0,0,0,0,1
0,0,0,0,0,0,0,0,0
0,0,2,2,2,2,2,7,7
0,0,0,0,0,0,2,5,5
0,0,2,0,0,0,2,5,5
0,0,2,11,12,0,2,5,5
0,0,2,5,2,2,2,5,5
8,8,5,5,5,5,5,5,5
1,8,5,5,5,5,5,5,1
endlayer

layer
1,0,0,0,0,7,5,5,1
0,0,0,0,0,7,5,5,5
0,0,2,2,2,2,2,5,5
0,0,2,0,0,0,2,5,5
0,0,2,0,0,0,2,5,5
0,0,2,0,13,12,2,5,5
0,0,2,0,2,2,2,5,5
0,0,0,0,8,5,5,5,5
1,0,0,0,8,5,5,5,1
endlayer

layer
1,0,7,5,5,5,5,5,1
0,0,7,5,5,5,5,5,5
0,0,2,2,2,2,2,5,5
0,0,2,0,0,0,2,5,5
0,0,2,0,0,3,2,5,5
0,0,2,0,0,13,5,5,5
0,0,2,0,2,2,2,5,5
0,0,0,0,0,0,0,8,8
1,0,0,0,0,0,0,8,1
endlayer

layer
1,5,5,5,5,5,5,5,1
5,5,5,5,5,5,5,5,5
5,5,2,2,2,2,2,5,5
7,7,2,0,0,3,2,5,5
0,0,2,0,0,4,2,8,8
0,0,2,0,0,0,0,0,0
0,0,2,2,2,2,2,0,0
0,0,0,0,0,0,0,0,0
1,0,0,0,0,0,0,0,1
endlayer

layer
1,5,5,5,5,5,5,8,1
5,5,5,5,5,5,5,8,8
5,5,2,2,2,5,2,0,0
5,5,2,0,6,4,2,0,0
5,5,2,0,0,0,2,0,0
5,5,2,0,0,0,0,0,0
7,7,2,2,2,2,2,0,0
0,0,0,0,0,0,0,0,0
1,0,0,0,0,0,0,0,1
endlayer

layer
1,5,5,5,8,0,0,0,1
5,5,5,5,8,0,0,0,0
5,5,2,2,2,0,2,0,0
5,5,2,6,9,0,2,0,0
5,5,2,0,0,0,2,0,0
5,5,2,0,0,0,2,0,0
5,5,2,2,2,2,2,0,0
5,5,5,7,0,0,0,0,0
1,5,5,7,0,0,0,0,1
endlayer

layer
1,8,0,0,0,0,0,0,1
8,8,0,0,0,0,0,0,0
5,5,2,2,2,0,2,0,0
5,5,5,9,0,0,2,0,0
5,5,2,10,0,0,2,0,0
5,5,2,0,0,0,2,0,0
5,5,2,2,2,2,2,0,0
5,5,5,5,5,5,7,0,0
1,5,5,5,5,5,7,0,1
endlayer

layer
1,0,0,0,0,0,0,0,1
0,0,0,0,0,0,0,0,0
0,0,2,2,2,2,2,0,0
0,0,0,0,0,0,2,0,0
8,8,2,11,0,0,2,0,0
5,5,2,10,0,0,2,7,7
5,5,2,2,2,2,2,5,5
5,5,5,5,5,5,5,5,5
1,5,5,5,5,5,5,5,1
endlayer

layer
1,0,0,0,0,0,0,0,1
0,0,0,0,0,0,0,0,0
0,0,2,2,2,2,2,7,7
0,0,0,0,0,0,2,5,5
0,0,2,0,0,0,2,5,5
0,0,2,11,12,0,2,5,5
0,0,2,5,2,2,2,5,5
8,8,5,5,5,5,5,5,5
1,8,5,5,5,5,5,5,1
endlayer

layer
1,0,0,0,0,7,5,5,1
0,0,0,0,0,7,5,5,5
0,0,2,2,2,2,2,5,5
0,0,2,0,0,0,2,5,5
0,0,2,0,0,0,2,5,5
0,0,2,0,13,12,2,5,5
0,0,2,0,2,2,2,5,5
0,0,0,0,8,5,5,5,5
1,0,0,0,8,5,5,5,1
endlayer

layer
1,0,7,5,5,5,5,5,1
0,0,7,5,5,5,5,5,5
0,0,2,2,2,2,2,5,5
0,0,2,0,0,0,2,5,5
0,0,2,0,0,3,2,5,5
0,0,2,0,0,13,5,5,5
0,0,2,0,2,2,2,5,5
0,0,0,0,0,0,0,8,8
1,0,0,0,0,0,0,8,1
endlayer

layer
1,5,5,5,5,5,5,5,1
5,5,5,5,5,5,5,5,5
5,5,2,2,2,2,2,5,5
7,7,2,0,0,3,2,5,5
0,0,2,0,0,4,2,8,8
0,0,2,0,0,0,0,0,0
0,0,2,2,2,2,2,0,0
0,0,0,0,0,0,0,0,0
1,0,0,0,0,0,0,0,1
endlayer

layer
1,5,5,5,5,5,5,8,1
5,5,5,5,5,5,5,8,8
5,5,2,2,2,5,2,1,1
5,5,2,0,6,4,2,0,0
5,5,2,0,0,0,2,0,0
5,5,2,0,0,0,0,0,0
7,7,2,2,2,2,2,0,0
0,0,0,0,0,0,0,0,0
1,0,0,0,0,0,0,0,1
endlayer

layer
1,5,5,5,8,1,1,1,1
5,5,5,5,8,1,1,1,1
5,5,2,2,2,2,2,0,0
5,5,2,6,9,0,2,0,0
5,5,2,0,0,0,2,0,0
5,5,2,0,0,0,2,0,0
5,5,2,2,2,2,2,0,0
5,5,5,7,0,0,0,0,0
1,5,5,7,0,0,0,0,1
endlayer

layer
1,8,1,1,1,1,1,1,1
8,8,1,1,1,1,1,1,1
5,5,2,2,2,2,2,1,1
5,5,2,9,0,0,2,0,0
5,5,2,10,0,0,2,0,0
5,5,2,0,0,0,2,0,0
5,5,2,2,2,2,2,0,0
5,5,5,5,5,5,7,0,0
1,5,5,5,5,5,7,0,1
endlayer

layer
1,1,1,1,1,1,1,1,1
1,1,1,1,1,1,1,1,1
1,1,2,2,2,2,2,1,1
1,1,2,0,0,0,2,1,1
8,8,2,11,0,0,2,0,0
5,5,2,10,0,0,2,7,7
5,5,2,2,2,2,2,5,5
5,5,5,5,5,5,5,5,5
1,5,5,5,5,5,5,5,1
endlayer

layer
1,1,1,1,1,1,1,1,1
1,1,1,1,1,1,1,1,1
1,1,2,2,2,2,2,1,1
1,1,2,0,0,0,2,1,1
1,1,2,0,0,0,2,5,5
1,1,2,11,12,0,2,5,5
1,1,2,2,2,2,2,5,5
8,8,5,5,5,5,5,5,5
1,8,5,5,5,5,5,5,1
endlayer

