
# Created by Ruins mod version 17.1 Ingame Parser
# authoring Player: ST753M

weight=1
embed_into_distance=33
acceptable_target_blocks=
unacceptable_target_blocks=flowing_water,water,flowing_lava,lava
dimensions=33,17,17
allowable_overhang=0
max_leveling=0
leveling_buffer=-1
preserve_water=0
preserve_lava=0

=0,100,air
rule1=0,100,preserveBlock
rule2=0,100,minecraft:glowstone-0
rule3=0,100,minecraft:nether_brick-0
^0,100,minecraft:red_nether_brick-0
^0,100,minecraft:obsidian-0
rule4=0,100,minecraft:nether_brick-0
^0,100,minecraft:red_nether_brick-0
^0,100,minecraft:obsidian-0
rule5=0,100,minecraft:stone_slab-14
rule6=0,100,minecraft:stained_glass-14

layer
1,1,1,1,1,1,1,1,1,1,1,1,1,1,1,1,1
1,1,1,1,2,1,1,1,1,1,1,1,2,1,1,1,1
1,1,1,1,1,1,1,1,1,1,1,1,1,1,1,1,1
1,1,1,1,1,1,1,1,1,1,1,1,1,1,1,1,1
1,2,1,1,1,1,3,3,4,3,3,1,1,1,1,2,1
1,1,1,1,1,3,3,3,4,3,3,3,1,1,1,1,1
1,1,1,1,3,3,3,3,4,3,3,3,3,1,1,1,1
1,1,1,1,3,3,3,4,4,4,3,3,3,1,1,1,1
1,1,1,1,4,4,4,4,4,4,4,4,4,1,1,1,1
1,1,1,1,3,3,3,4,4,4,3,3,3,1,1,1,1
1,1,1,1,3,3,3,3,4,3,3,3,3,1,1,1,1
1,1,1,1,1,3,3,3,4,3,3,3,1,1,1,1,1
1,2,1,1,1,1,3,3,4,3,3,1,1,1,1,2,1
1,1,1,1,1,1,1,1,1,1,1,1,1,1,1,1,1
1,1,1,1,1,1,1,1,1,1,1,1,1,1,1,1,1
1,1,1,1,2,1,1,1,1,1,1,1,2,1,1,1,1
1,1,1,1,1,1,1,1,1,1,1,1,1,1,1,1,1
endlayer

layer
1,1,1,1,1,1,1,1,1,1,1,1,1,1,1,1,1
1,1,1,1,4,1,1,1,1,1,1,1,4,1,1,1,1
1,1,1,1,1,1,1,1,1,1,1,1,1,1,1,1,1
1,1,1,1,1,3,3,4,4,4,3,3,1,1,1,1,1
1,4,1,1,3,3,0,0,0,0,0,3,3,1,1,4,1
1,1,1,3,3,0,0,0,0,0,0,0,3,3,1,1,1
1,1,1,3,0,0,4,3,3,3,4,0,0,3,1,1,1
1,1,1,4,0,0,3,0,0,5,3,0,0,4,1,1,1
1,1,1,4,0,0,0,0,0,0,0,0,0,4,1,1,1
1,1,1,4,0,0,3,0,0,0,3,0,0,4,1,1,1
1,1,1,3,0,0,4,3,0,3,4,0,0,3,1,1,1
1,1,1,3,3,0,0,0,0,0,0,0,3,3,1,1,1
1,4,1,1,3,3,0,0,0,0,0,3,3,1,1,4,1
1,1,1,1,1,3,3,4,4,4,3,3,1,1,1,1,1
1,1,1,1,1,1,1,1,1,1,1,1,1,1,1,1,1
1,1,1,1,4,1,1,1,1,1,1,1,4,1,1,1,1
1,1,1,1,1,1,1,1,1,1,1,1,1,1,1,1,1
endlayer

layer
1,1,1,1,1,1,1,1,1,1,1,1,1,1,1,1,1
1,1,1,1,3,1,1,1,1,1,1,1,3,1,1,1,1
1,1,1,1,1,4,4,4,4,4,4,4,1,1,1,1,1
1,1,1,1,3,0,0,0,0,0,0,0,3,1,1,1,1
1,3,1,3,0,0,0,0,0,0,0,0,0,3,1,3,1
1,1,4,0,0,0,0,0,0,0,0,0,0,0,4,1,1
1,1,4,0,0,0,4,3,3,3,4,0,0,0,4,1,1
1,1,4,0,0,0,3,0,5,0,3,0,0,0,4,1,1
1,1,4,0,0,0,0,0,0,0,0,0,0,0,4,1,1
1,1,4,0,0,0,3,0,0,0,3,0,0,0,4,1,1
1,1,4,0,0,0,4,3,0,3,4,0,0,0,4,1,1
1,1,4,0,0,0,0,0,0,0,0,0,0,0,4,1,1
1,3,1,3,0,0,0,0,0,0,0,0,0,3,1,3,1
1,1,1,1,3,0,0,0,0,0,0,0,3,1,1,1,1
1,1,1,1,1,4,4,4,4,4,4,4,1,1,1,1,1
1,1,1,1,3,1,1,1,1,1,1,1,3,1,1,1,1
1,1,1,1,1,1,1,1,1,1,1,1,1,1,1,1,1
endlayer

layer
1,1,1,1,1,1,1,1,1,1,1,1,1,1,1,1,1
1,1,1,1,3,4,3,3,3,3,3,4,3,1,1,1,1
1,1,1,1,4,4,0,0,0,0,0,4,4,1,1,1,1
1,1,1,3,0,0,0,0,0,0,0,0,0,3,1,1,1
1,3,4,0,0,0,0,0,0,0,0,0,0,0,4,3,1
1,4,4,0,0,0,0,0,2,0,0,0,0,0,4,4,1
1,3,0,0,0,0,4,3,3,3,4,0,0,0,0,3,1
1,3,0,0,0,0,3,5,0,0,3,0,0,0,0,3,1
1,3,0,0,0,2,3,0,0,0,3,2,0,0,0,3,1
1,3,0,0,0,0,3,0,0,0,3,0,0,0,0,3,1
1,3,0,0,0,0,4,3,3,3,4,0,0,0,0,3,1
1,4,4,0,0,0,0,0,2,0,0,0,0,0,4,4,1
1,3,4,0,0,0,0,0,0,0,0,0,0,0,4,3,1
1,1,1,3,0,0,0,0,0,0,0,0,0,3,1,1,1
1,1,1,1,4,4,0,0,0,0,0,4,4,1,1,1,1
1,1,1,1,3,4,3,3,3,3,3,4,3,1,1,1,1
1,1,1,1,1,1,1,1,1,1,1,1,1,1,1,1,1
endlayer

layer
1,1,1,1,1,1,1,1,1,1,1,1,1,1,1,1,1
1,1,1,1,3,3,6,6,6,6,6,3,3,1,1,1,1
1,1,1,4,4,0,0,0,0,0,0,0,4,4,1,1,1
1,1,4,0,0,0,0,0,0,0,0,0,0,0,4,1,1
1,3,4,0,0,0,0,0,0,0,0,0,0,0,4,3,1
1,3,0,0,0,0,0,2,2,2,0,0,0,0,0,3,1
1,6,0,0,0,0,2,3,3,3,2,0,0,0,0,6,1
1,6,0,0,0,2,3,0,0,0,3,2,0,0,0,6,1
1,6,0,0,0,2,3,5,0,0,3,2,0,0,0,6,1
1,6,0,0,0,2,3,0,0,0,3,2,0,0,0,6,1
1,6,0,0,0,0,2,3,3,3,2,0,0,0,0,6,1
1,3,0,0,0,0,0,2,2,2,0,0,0,0,0,3,1
1,3,4,0,0,0,0,0,0,0,0,0,0,0,4,3,1
1,1,4,0,0,0,0,0,0,0,0,0,0,0,4,1,1
1,1,1,4,4,0,0,0,0,0,0,0,4,4,1,1,1
1,1,1,1,3,3,6,6,6,6,6,3,3,1,1,1,1
1,1,1,1,1,1,1,1,1,1,1,1,1,1,1,1,1
endlayer

layer
1,1,1,1,1,1,1,6,6,6,1,1,1,1,1,1,1
1,1,1,3,3,6,6,0,0,0,6,6,3,3,1,1,1
1,1,3,4,0,0,0,0,0,0,0,0,0,4,3,1,1
1,3,4,0,0,0,0,0,0,0,0,0,0,0,4,3,1
1,3,0,0,0,0,0,0,2,0,0,0,0,0,0,3,1
1,6,0,0,0,0,0,2,2,2,0,0,0,0,0,6,1
1,6,0,0,0,0,2,3,3,3,2,0,0,0,0,6,1
6,0,0,0,0,2,3,0,0,0,3,2,0,0,0,0,6
6,0,0,0,2,2,3,0,0,0,3,2,2,0,0,0,6
6,0,0,0,0,2,3,5,0,0,3,2,0,0,0,0,6
1,6,0,0,0,0,2,3,3,3,2,0,0,0,0,6,1
1,6,0,0,0,0,0,2,2,2,0,0,0,0,0,6,1
1,3,0,0,0,0,0,0,2,0,0,0,0,0,0,3,1
1,3,4,0,0,0,0,0,0,0,0,0,0,0,4,3,1
1,1,3,4,0,0,0,0,0,0,0,0,0,4,3,1,1
1,1,1,3,3,6,6,0,0,0,6,6,3,3,1,1,1
1,1,1,1,1,1,1,6,6,6,1,1,1,1,1,1,1
endlayer

layer
1,1,1,1,1,1,6,6,6,6,6,1,1,1,1,1,1
1,1,1,6,3,6,0,0,0,0,0,6,3,6,1,1,1
1,1,6,0,0,0,0,0,0,0,0,0,0,0,6,1,1
1,6,0,0,0,0,0,0,0,0,0,0,0,0,0,6,1
1,3,0,0,0,0,0,2,2,2,0,0,0,0,0,3,1
1,6,0,0,0,0,2,2,2,2,2,0,0,0,0,6,1
6,0,0,0,0,2,2,3,3,3,2,2,0,0,0,0,6
6,0,0,0,2,2,3,0,0,0,3,2,2,0,0,0,6
6,0,0,0,2,2,3,0,0,0,3,2,2,0,0,0,6
6,0,0,0,2,2,3,0,5,0,3,2,2,0,0,0,6
6,0,0,0,0,2,2,3,3,3,2,2,0,0,0,0,6
1,6,0,0,0,0,2,2,2,2,2,0,0,0,0,6,1
1,3,0,0,0,0,0,2,2,2,0,0,0,0,0,3,1
1,6,0,0,0,0,0,0,0,0,0,0,0,0,0,6,1
1,1,6,0,0,0,0,0,0,0,0,0,0,0,6,1,1
1,1,1,6,3,6,0,0,0,0,0,6,3,6,1,1,1
1,1,1,1,1,1,6,6,6,6,6,1,1,1,1,1,1
endlayer

layer
1,1,1,1,1,1,6,6,6,6,6,1,1,1,1,1,1
1,1,1,6,3,6,0,0,0,0,0,6,3,6,1,1,1
1,1,6,0,0,0,0,0,0,0,0,0,0,0,6,1,1
1,6,0,0,0,0,0,0,0,0,0,0,0,0,0,6,1
1,3,0,0,0,0,0,2,2,2,0,0,0,0,0,3,1
1,6,0,0,0,0,2,2,2,2,2,0,0,0,0,6,1
6,0,0,0,0,2,2,3,3,3,2,2,0,0,0,0,6
6,0,0,0,2,2,3,0,0,0,3,2,2,0,0,0,6
6,0,0,0,2,2,3,0,0,0,3,2,2,0,0,0,6
6,0,0,0,2,2,3,0,0,5,3,2,2,0,0,0,6
6,0,0,0,0,2,2,3,3,3,2,2,0,0,0,0,6
1,6,0,0,0,0,2,2,2,2,2,0,0,0,0,6,1
1,3,0,0,0,0,0,2,2,2,0,0,0,0,0,3,1
1,6,0,0,0,0,0,0,0,0,0,0,0,0,0,6,1
1,1,6,0,0,0,0,0,0,0,0,0,0,0,6,1,1
1,1,1,6,3,6,0,0,0,0,0,6,3,6,1,1,1
1,1,1,1,1,1,6,6,6,6,6,1,1,1,1,1,1
endlayer

layer
1,1,1,1,1,1,6,6,6,6,6,1,1,1,1,1,1
1,1,1,6,3,6,0,0,0,0,0,6,3,6,1,1,1
1,1,6,0,0,0,0,0,0,0,0,0,0,0,6,1,1
1,6,0,0,0,0,0,0,0,0,0,0,0,0,0,6,1
1,3,0,0,0,0,0,2,2,2,0,0,0,0,0,3,1
1,6,0,0,0,0,2,2,2,2,2,0,0,0,0,6,1
6,0,0,0,0,2,2,3,3,3,2,2,0,0,0,0,6
6,0,0,0,2,2,3,0,0,0,3,2,2,0,0,0,6
6,0,0,0,2,2,3,0,0,5,3,2,2,0,0,0,6
6,0,0,0,2,2,3,0,0,0,3,2,2,0,0,0,6
6,0,0,0,0,2,2,3,3,3,2,2,0,0,0,0,6
1,6,0,0,0,0,2,2,2,2,2,0,0,0,0,6,1
1,3,0,0,0,0,0,2,2,2,0,0,0,0,0,3,1
1,6,0,0,0,0,0,0,0,0,0,0,0,0,0,6,1
1,1,6,0,0,0,0,0,0,0,0,0,0,0,6,1,1
1,1,1,6,3,6,0,0,0,0,0,6,3,6,1,1,1
1,1,1,1,1,1,6,6,6,6,6,1,1,1,1,1,1
endlayer

layer
1,1,1,1,1,1,1,6,6,6,1,1,1,1,1,1,1
1,1,1,3,3,6,6,0,0,0,6,6,3,3,1,1,1
1,1,3,4,0,0,0,0,0,0,0,0,0,4,3,1,1
1,3,4,0,0,0,0,0,0,0,0,0,0,0,4,3,1
1,3,0,0,0,0,0,0,2,0,0,0,0,0,0,3,1
1,6,0,0,0,0,0,2,2,2,0,0,0,0,0,6,1
1,6,0,0,0,0,2,3,3,3,2,0,0,0,0,6,1
6,0,0,0,0,2,3,0,0,5,3,2,0,0,0,0,6
6,0,0,0,2,2,3,0,0,0,3,2,2,0,0,0,6
6,0,0,0,0,2,3,0,0,0,3,2,0,0,0,0,6
1,6,0,0,0,0,2,3,3,3,2,0,0,0,0,6,1
1,6,0,0,0,0,0,2,2,2,0,0,0,0,0,6,1
1,3,0,0,0,0,0,0,2,0,0,0,0,0,0,3,1
1,3,4,0,0,0,0,0,0,0,0,0,0,0,4,3,1
1,1,3,4,0,0,0,0,0,0,0,0,0,4,3,1,1
1,1,1,3,3,6,6,0,0,0,6,6,3,3,1,1,1
1,1,1,1,1,1,1,6,6,6,1,1,1,1,1,1,1
endlayer

layer
1,1,1,1,1,1,1,1,1,1,1,1,1,1,1,1,1
1,1,1,1,3,3,6,6,6,6,6,3,3,1,1,1,1
1,1,1,4,4,0,0,0,0,0,0,0,4,4,1,1,1
1,1,4,0,0,0,0,0,0,0,0,0,0,0,4,1,1
1,3,4,0,0,0,0,0,0,0,0,0,0,0,4,3,1
1,3,0,0,0,0,0,2,2,2,0,0,0,0,0,3,1
1,6,0,0,0,0,2,3,3,3,2,0,0,0,0,6,1
1,6,0,0,0,2,3,0,5,0,3,2,0,0,0,6,1
1,6,0,0,0,2,3,0,0,0,3,2,0,0,0,6,1
1,6,0,0,0,2,3,0,0,0,3,2,0,0,0,6,1
1,6,0,0,0,0,2,3,3,3,2,0,0,0,0,6,1
1,3,0,0,0,0,0,2,2,2,0,0,0,0,0,3,1
1,3,4,0,0,0,0,0,0,0,0,0,0,0,4,3,1
1,1,4,0,0,0,0,0,0,0,0,0,0,0,4,1,1
1,1,1,4,4,0,0,0,0,0,0,0,4,4,1,1,1
1,1,1,1,3,3,6,6,6,6,6,3,3,1,1,1,1
1,1,1,1,1,1,1,1,1,1,1,1,1,1,1,1,1
endlayer

layer
1,1,1,1,1,1,1,1,1,1,1,1,1,1,1,1,1
1,1,1,1,3,4,3,3,3,3,3,4,3,1,1,1,1
1,1,1,1,4,4,0,0,0,0,0,4,4,1,1,1,1
1,1,1,4,0,0,0,0,0,0,0,0,0,4,1,1,1
1,3,4,0,0,0,0,0,0,0,0,0,0,0,4,3,1
1,4,4,0,0,0,0,0,2,0,0,0,0,0,4,4,1
1,3,0,0,0,0,0,3,3,3,0,0,0,0,0,3,1
1,3,0,0,0,0,3,5,0,0,3,0,0,0,0,3,1
1,3,0,0,0,2,3,0,0,0,3,2,0,0,0,3,1
1,3,0,0,0,0,3,0,0,0,3,0,0,0,0,3,1
1,3,0,0,0,0,0,3,3,3,0,0,0,0,0,3,1
1,4,4,0,0,0,0,0,2,0,0,0,0,0,4,4,1
1,3,4,0,0,0,0,0,0,0,0,0,0,0,4,3,1
1,1,1,4,0,0,0,0,0,0,0,0,0,4,1,1,1
1,1,1,1,4,4,0,0,0,0,0,4,4,1,1,1,1
1,1,1,1,3,4,3,3,3,3,3,4,3,1,1,1,1
1,1,1,1,1,1,1,1,1,1,1,1,1,1,1,1,1
endlayer

layer
1,1,1,1,1,1,1,1,1,1,1,1,1,1,1,1,1
1,1,1,1,3,1,1,1,1,1,1,1,3,1,1,1,1
1,1,1,1,1,4,4,4,4,4,4,4,1,1,1,1,1
1,1,1,1,4,0,0,0,0,0,0,0,4,1,1,1,1
1,3,1,4,0,0,0,0,0,0,0,0,0,4,1,3,1
1,1,4,0,0,0,0,0,0,0,0,0,0,0,4,1,1
1,1,4,0,0,0,0,3,3,3,0,0,0,0,4,1,1
1,1,4,0,0,0,3,0,0,0,3,0,0,0,4,1,1
1,1,4,0,0,0,3,5,0,0,3,0,0,0,4,1,1
1,1,4,0,0,0,3,0,0,0,3,0,0,0,4,1,1
1,1,4,0,0,0,0,3,3,3,0,0,0,0,4,1,1
1,1,4,0,0,0,0,0,0,0,0,0,0,0,4,1,1
1,3,1,4,0,0,0,0,0,0,0,0,0,4,1,3,1
1,1,1,1,4,0,0,0,0,0,0,0,4,1,1,1,1
1,1,1,1,1,4,4,4,4,4,4,4,1,1,1,1,1
1,1,1,1,3,1,1,1,1,1,1,1,3,1,1,1,1
1,1,1,1,1,1,1,1,1,1,1,1,1,1,1,1,1
endlayer

layer
1,1,1,1,1,1,1,1,1,1,1,1,1,1,1,1,1
1,1,1,1,4,1,1,1,1,1,1,1,4,1,1,1,1
1,1,1,1,1,1,1,1,1,1,1,1,1,1,1,1,1
1,1,1,1,1,3,3,4,4,4,3,3,1,1,1,1,1
1,4,1,1,3,3,0,0,0,0,0,3,3,1,1,4,1
1,1,1,3,3,0,0,0,0,0,0,0,3,3,1,1,1
1,1,1,3,0,0,0,3,3,3,0,0,0,3,1,1,1
1,1,1,4,0,0,3,0,0,0,3,0,0,4,1,1,1
1,1,1,4,0,0,3,0,0,0,3,0,0,4,1,1,1
1,1,1,4,0,0,3,5,0,0,3,0,0,4,1,1,1
1,1,1,3,0,0,0,3,3,3,0,0,0,3,1,1,1
1,1,1,3,3,0,0,0,0,0,0,0,3,3,1,1,1
1,4,1,1,3,3,0,0,0,0,0,3,3,1,1,4,1
1,1,1,1,1,3,3,4,4,4,3,3,1,1,1,1,1
1,1,1,1,1,1,1,1,1,1,1,1,1,1,1,1,1
1,1,1,1,4,1,1,1,1,1,1,1,4,1,1,1,1
1,1,1,1,1,1,1,1,1,1,1,1,1,1,1,1,1
endlayer

layer
1,1,1,1,4,1,1,1,1,1,1,1,4,1,1,1,1
1,1,1,1,4,1,1,1,1,1,1,1,4,1,1,1,1
1,1,1,1,1,1,1,1,1,1,1,1,1,1,1,1,1
1,1,1,1,1,1,1,1,1,1,1,1,1,1,1,1,1
4,4,1,1,1,1,3,3,4,3,3,1,1,1,1,4,4
1,1,1,1,1,3,3,3,3,3,3,3,1,1,1,1,1
1,1,1,1,3,3,3,3,3,3,3,3,3,1,1,1,1
1,1,1,1,3,3,3,0,0,0,3,3,3,1,1,1,1
1,1,1,1,4,3,3,0,0,0,3,3,4,1,1,1,1
1,1,1,1,3,3,3,0,5,0,3,3,3,1,1,1,1
1,1,1,1,3,3,3,3,3,3,3,3,3,1,1,1,1
1,1,1,1,1,3,3,3,3,3,3,3,1,1,1,1,1
4,4,1,1,1,1,3,3,4,3,3,1,1,1,1,4,4
1,1,1,1,1,1,1,1,1,1,1,1,1,1,1,1,1
1,1,1,1,1,1,1,1,1,1,1,1,1,1,1,1,1
1,1,1,1,4,1,1,1,1,1,1,1,4,1,1,1,1
1,1,1,1,4,1,1,1,1,1,1,1,4,1,1,1,1
endlayer

layer
1,1,1,1,4,1,1,1,1,1,1,1,4,1,1,1,1
1,1,1,1,1,1,1,1,1,1,1,1,1,1,1,1,1
1,1,1,1,1,1,1,1,1,1,1,1,1,1,1,1,1
1,1,1,1,1,1,1,1,1,1,1,1,1,1,1,1,1
4,1,1,1,1,1,1,1,1,1,1,1,1,1,1,1,4
1,1,1,1,1,1,1,4,4,3,1,1,1,1,1,1,1
1,1,1,1,1,1,3,3,3,3,3,1,1,1,1,1,1
1,1,1,1,1,3,3,0,0,0,3,4,1,1,1,1,1
1,1,1,1,1,4,3,0,0,0,3,4,1,1,1,1,1
1,1,1,1,1,4,3,0,0,5,3,3,1,1,1,1,1
1,1,1,1,1,1,3,3,3,3,3,1,1,1,1,1,1
1,1,1,1,1,1,1,3,4,4,1,1,1,1,1,1,1
4,1,1,1,1,1,1,1,1,1,1,1,1,1,1,1,4
1,1,1,1,1,1,1,1,1,1,1,1,1,1,1,1,1
1,1,1,1,1,1,1,1,1,1,1,1,1,1,1,1,1
1,1,1,1,1,1,1,1,1,1,1,1,1,1,1,1,1
1,1,1,1,4,1,1,1,1,1,1,1,4,1,1,1,1
endlayer

layer
1,1,1,1,4,1,1,1,1,1,1,1,4,1,1,1,1
1,1,1,1,1,1,1,1,1,1,1,1,1,1,1,1,1
1,1,1,1,1,1,1,1,1,1,1,1,1,1,1,1,1
1,1,1,1,1,1,1,1,1,1,1,1,1,1,1,1,1
4,1,1,1,1,1,1,1,1,1,1,1,1,1,1,1,4
1,1,1,1,1,1,1,4,3,3,1,1,1,1,1,1,1
1,1,1,1,1,1,4,3,3,3,4,1,1,1,1,1,1
1,1,1,1,1,3,3,0,0,0,3,4,1,1,1,1,1
1,1,1,1,1,3,3,0,0,5,3,3,1,1,1,1,1
1,1,1,1,1,4,3,0,0,0,3,3,1,1,1,1,1
1,1,1,1,1,1,4,3,3,3,4,1,1,1,1,1,1
1,1,1,1,1,1,1,3,3,4,1,1,1,1,1,1,1
4,1,1,1,1,1,1,1,1,1,1,1,1,1,1,1,4
1,1,1,1,1,1,1,1,1,1,1,1,1,1,1,1,1
1,1,1,1,1,1,1,1,1,1,1,1,1,1,1,1,1
1,1,1,1,1,1,1,1,1,1,1,1,1,1,1,1,1
1,1,1,1,4,1,1,1,1,1,1,1,4,1,1,1,1
endlayer

layer
1,1,1,1,2,1,1,1,1,1,1,1,2,1,1,1,1
1,1,1,1,1,1,1,1,1,1,1,1,1,1,1,1,1
1,1,1,1,1,1,1,1,1,1,1,1,1,1,1,1,1
1,1,1,1,1,1,1,1,1,1,1,1,1,1,1,1,1
2,1,1,1,1,1,1,1,1,1,1,1,1,1,1,1,2
1,1,1,1,1,1,1,3,3,4,1,1,1,1,1,1,1
1,1,1,1,1,1,4,3,3,3,4,1,1,1,1,1,1
1,1,1,1,1,4,3,0,0,5,3,3,1,1,1,1,1
1,1,1,1,1,3,3,0,0,0,3,3,1,1,1,1,1
1,1,1,1,1,3,3,0,0,0,3,4,1,1,1,1,1
1,1,1,1,1,1,4,3,3,3,4,1,1,1,1,1,1
1,1,1,1,1,1,1,4,3,3,1,1,1,1,1,1,1
2,1,1,1,1,1,1,1,1,1,1,1,1,1,1,1,2
1,1,1,1,1,1,1,1,1,1,1,1,1,1,1,1,1
1,1,1,1,1,1,1,1,1,1,1,1,1,1,1,1,1
1,1,1,1,1,1,1,1,1,1,1,1,1,1,1,1,1
1,1,1,1,2,1,1,1,1,1,1,1,2,1,1,1,1
endlayer

layer
1,1,1,1,1,1,1,1,1,1,1,1,1,1,1,1,1
1,1,1,1,1,1,1,1,1,1,1,1,1,1,1,1,1
1,1,1,1,1,1,1,1,1,1,1,1,1,1,1,1,1
1,1,1,1,1,1,1,1,1,1,1,1,1,1,1,1,1
1,1,1,1,1,1,1,1,1,1,1,1,1,1,1,1,1
1,1,1,1,1,1,1,3,4,4,1,1,1,1,1,1,1
1,1,1,1,1,1,3,3,3,3,3,1,1,1,1,1,1
1,1,1,1,1,4,3,0,5,0,3,3,1,1,1,1,1
1,1,1,1,1,4,3,0,0,0,3,4,1,1,1,1,1
1,1,1,1,1,3,3,0,0,0,3,4,1,1,1,1,1
1,1,1,1,1,1,3,3,3,3,3,1,1,1,1,1,1
1,1,1,1,1,1,1,4,4,3,1,1,1,1,1,1,1
1,1,1,1,1,1,1,1,1,1,1,1,1,1,1,1,1
1,1,1,1,1,1,1,1,1,1,1,1,1,1,1,1,1
1,1,1,1,1,1,1,1,1,1,1,1,1,1,1,1,1
1,1,1,1,1,1,1,1,1,1,1,1,1,1,1,1,1
1,1,1,1,1,1,1,1,1,1,1,1,1,1,1,1,1
endlayer

layer
1,1,1,1,1,1,1,1,1,1,1,1,1,1,1,1,1
1,1,1,1,1,1,1,1,1,1,1,1,1,1,1,1,1
1,1,1,1,1,1,1,1,1,1,1,1,1,1,1,1,1
1,1,1,1,1,1,1,1,1,1,1,1,1,1,1,1,1
1,1,1,1,1,1,1,1,1,1,1,1,1,1,1,1,1
1,1,1,1,1,1,1,4,4,3,1,1,1,1,1,1,1
1,1,1,1,1,1,3,3,3,3,3,1,1,1,1,1,1
1,1,1,1,1,3,3,5,0,0,3,4,1,1,1,1,1
1,1,1,1,1,4,3,0,0,0,3,4,1,1,1,1,1
1,1,1,1,1,4,3,0,0,0,3,3,1,1,1,1,1
1,1,1,1,1,1,3,3,3,3,3,1,1,1,1,1,1
1,1,1,1,1,1,1,3,4,4,1,1,1,1,1,1,1
1,1,1,1,1,1,1,1,1,1,1,1,1,1,1,1,1
1,1,1,1,1,1,1,1,1,1,1,1,1,1,1,1,1
1,1,1,1,1,1,1,1,1,1,1,1,1,1,1,1,1
1,1,1,1,1,1,1,1,1,1,1,1,1,1,1,1,1
1,1,1,1,1,1,1,1,1,1,1,1,1,1,1,1,1
endlayer

layer
1,1,1,1,1,1,1,1,1,1,1,1,1,1,1,1,1
1,1,1,1,1,1,1,1,1,1,1,1,1,1,1,1,1
1,1,1,1,1,1,1,1,1,1,1,1,1,1,1,1,1
1,1,1,1,1,1,1,1,1,1,1,1,1,1,1,1,1
1,1,1,1,1,1,1,1,1,1,1,1,1,1,1,1,1
1,1,1,1,1,1,1,4,3,3,1,1,1,1,1,1,1
1,1,1,1,1,1,4,3,3,3,4,1,1,1,1,1,1
1,1,1,1,1,3,3,0,0,0,3,4,1,1,1,1,1
1,1,1,1,1,3,3,5,0,0,3,3,1,1,1,1,1
1,1,1,1,1,4,3,0,0,0,3,3,1,1,1,1,1
1,1,1,1,1,1,4,3,3,3,4,1,1,1,1,1,1
1,1,1,1,1,1,1,3,3,4,1,1,1,1,1,1,1
1,1,1,1,1,1,1,1,1,1,1,1,1,1,1,1,1
1,1,1,1,1,1,1,1,1,1,1,1,1,1,1,1,1
1,1,1,1,1,1,1,1,1,1,1,1,1,1,1,1,1
1,1,1,1,1,1,1,1,1,1,1,1,1,1,1,1,1
1,1,1,1,1,1,1,1,1,1,1,1,1,1,1,1,1
endlayer

layer
1,1,1,1,1,1,1,1,1,1,1,1,1,1,1,1,1
1,1,1,1,1,1,1,1,1,1,1,1,1,1,1,1,1
1,1,1,1,1,1,1,1,1,1,1,1,1,1,1,1,1
1,1,1,1,1,1,1,1,1,1,1,1,1,1,1,1,1
1,1,1,1,1,1,1,1,1,1,1,1,1,1,1,1,1
1,1,1,1,1,1,1,3,3,4,1,1,1,1,1,1,1
1,1,1,1,1,1,4,3,3,3,4,1,1,1,1,1,1
1,1,1,1,1,4,3,0,0,0,3,3,1,1,1,1,1
1,1,1,1,1,3,3,0,0,0,3,3,1,1,1,1,1
1,1,1,1,1,3,3,5,0,0,3,4,1,1,1,1,1
1,1,1,1,1,1,4,3,3,3,4,1,1,1,1,1,1
1,1,1,1,1,1,1,4,3,3,1,1,1,1,1,1,1
1,1,1,1,1,1,1,1,1,1,1,1,1,1,1,1,1
1,1,1,1,1,1,1,1,1,1,1,1,1,1,1,1,1
1,1,1,1,1,1,1,1,1,1,1,1,1,1,1,1,1
1,1,1,1,1,1,1,1,1,1,1,1,1,1,1,1,1
1,1,1,1,1,1,1,1,1,1,1,1,1,1,1,1,1
endlayer

layer
1,1,1,1,1,1,1,1,1,1,1,1,1,1,1,1,1
1,1,1,1,1,1,1,1,1,1,1,1,1,1,1,1,1
1,1,1,1,1,1,1,1,1,1,1,1,1,1,1,1,1
1,1,1,1,1,1,1,1,1,1,1,1,1,1,1,1,1
1,1,1,1,1,1,1,1,1,1,1,1,1,1,1,1,1
1,1,1,1,1,1,1,3,4,4,1,1,1,1,1,1,1
1,1,1,1,1,1,3,3,3,3,3,1,1,1,1,1,1
1,1,1,1,1,4,3,0,0,0,3,3,1,1,1,1,1
1,1,1,1,1,4,3,0,0,0,3,4,1,1,1,1,1
1,1,1,1,1,3,3,0,5,0,3,4,1,1,1,1,1
1,1,1,1,1,1,3,3,3,3,3,1,1,1,1,1,1
1,1,1,1,1,1,1,4,4,3,1,1,1,1,1,1,1
1,1,1,1,1,1,1,1,1,1,1,1,1,1,1,1,1
1,1,1,1,1,1,1,1,1,1,1,1,1,1,1,1,1
1,1,1,1,1,1,1,1,1,1,1,1,1,1,1,1,1
1,1,1,1,1,1,1,1,1,1,1,1,1,1,1,1,1
1,1,1,1,1,1,1,1,1,1,1,1,1,1,1,1,1
endlayer

layer
1,1,1,1,1,1,1,1,1,1,1,1,1,1,1,1,1
1,1,1,1,1,1,1,1,1,1,1,1,1,1,1,1,1
1,1,1,1,1,1,1,1,1,1,1,1,1,1,1,1,1
1,1,1,1,1,1,1,1,1,1,1,1,1,1,1,1,1
1,1,1,1,1,1,1,1,1,1,1,1,1,1,1,1,1
1,1,1,1,1,1,1,4,4,3,1,1,1,1,1,1,1
1,1,1,1,1,1,3,3,3,3,3,1,1,1,1,1,1
1,1,1,1,1,3,3,0,0,0,3,4,1,1,1,1,1
1,1,1,1,1,4,3,0,0,0,3,4,1,1,1,1,1
1,1,1,1,1,4,3,0,0,5,3,3,1,1,1,1,1
1,1,1,1,1,1,3,3,3,3,3,1,1,1,1,1,1
1,1,1,1,1,1,1,3,4,4,1,1,1,1,1,1,1
1,1,1,1,1,1,1,1,1,1,1,1,1,1,1,1,1
1,1,1,1,1,1,1,1,1,1,1,1,1,1,1,1,1
1,1,1,1,1,1,1,1,1,1,1,1,1,1,1,1,1
1,1,1,1,1,1,1,1,1,1,1,1,1,1,1,1,1
1,1,1,1,1,1,1,1,1,1,1,1,1,1,1,1,1
endlayer

layer
1,1,1,1,1,1,1,1,1,1,1,1,1,1,1,1,1
1,1,1,1,1,1,1,1,1,1,1,1,1,1,1,1,1
1,1,1,1,1,1,1,1,1,1,1,1,1,1,1,1,1
1,1,1,1,1,1,1,1,1,1,1,1,1,1,1,1,1
1,1,1,1,1,1,1,1,1,1,1,1,1,1,1,1,1
1,1,1,1,1,1,1,4,3,3,1,1,1,1,1,1,1
1,1,1,1,1,1,4,3,3,3,4,1,1,1,1,1,1
1,1,1,1,1,3,3,0,0,0,3,4,1,1,1,1,1
1,1,1,1,1,3,3,0,0,5,3,3,1,1,1,1,1
1,1,1,1,1,4,3,0,0,0,3,3,1,1,1,1,1
1,1,1,1,1,1,4,3,3,3,4,1,1,1,1,1,1
1,1,1,1,1,1,1,3,3,4,1,1,1,1,1,1,1
1,1,1,1,1,1,1,1,1,1,1,1,1,1,1,1,1
1,1,1,1,1,1,1,1,1,1,1,1,1,1,1,1,1
1,1,1,1,1,1,1,1,1,1,1,1,1,1,1,1,1
1,1,1,1,1,1,1,1,1,1,1,1,1,1,1,1,1
1,1,1,1,1,1,1,1,1,1,1,1,1,1,1,1,1
endlayer

layer
1,1,1,1,1,1,1,1,1,1,1,1,1,1,1,1,1
1,1,1,1,1,1,1,1,1,1,1,1,1,1,1,1,1
1,1,1,1,1,1,1,1,1,1,1,1,1,1,1,1,1
1,1,1,1,1,1,1,1,1,1,1,1,1,1,1,1,1
1,1,1,1,1,1,1,1,1,1,1,1,1,1,1,1,1
1,1,1,1,1,1,1,3,3,4,1,1,1,1,1,1,1
1,1,1,1,1,1,4,3,3,3,4,1,1,1,1,1,1
1,1,1,1,1,4,3,0,0,5,3,3,1,1,1,1,1
1,1,1,1,1,3,3,0,0,0,3,3,1,1,1,1,1
1,1,1,1,1,3,3,0,0,0,3,4,1,1,1,1,1
1,1,1,1,1,1,4,3,3,3,4,1,1,1,1,1,1
1,1,1,1,1,1,1,4,3,3,1,1,1,1,1,1,1
1,1,1,1,1,1,1,1,1,1,1,1,1,1,1,1,1
1,1,1,1,1,1,1,1,1,1,1,1,1,1,1,1,1
1,1,1,1,1,1,1,1,1,1,1,1,1,1,1,1,1
1,1,1,1,1,1,1,1,1,1,1,1,1,1,1,1,1
1,1,1,1,1,1,1,1,1,1,1,1,1,1,1,1,1
endlayer

layer
1,1,1,1,1,1,1,1,1,1,1,1,1,1,1,1,1
1,1,1,1,1,1,1,1,1,1,1,1,1,1,1,1,1
1,1,1,1,1,1,1,1,1,1,1,1,1,1,1,1,1
1,1,1,1,1,1,1,1,1,1,1,1,1,1,1,1,1
1,1,1,1,1,1,1,1,1,1,1,1,1,1,1,1,1
1,1,1,1,1,1,1,3,4,4,1,1,1,1,1,1,1
1,1,1,1,1,1,3,3,3,3,3,1,1,1,1,1,1
1,1,1,1,1,4,3,0,5,0,3,3,1,1,1,1,1
1,1,1,1,1,4,3,0,0,0,3,4,1,1,1,1,1
1,1,1,1,1,3,3,0,0,0,3,4,1,1,1,1,1
1,1,1,1,1,1,3,3,3,3,3,1,1,1,1,1,1
1,1,1,1,1,1,1,4,4,3,1,1,1,1,1,1,1
1,1,1,1,1,1,1,1,1,1,1,1,1,1,1,1,1
1,1,1,1,1,1,1,1,1,1,1,1,1,1,1,1,1
1,1,1,1,1,1,1,1,1,1,1,1,1,1,1,1,1
1,1,1,1,1,1,1,1,1,1,1,1,1,1,1,1,1
1,1,1,1,1,1,1,1,1,1,1,1,1,1,1,1,1
endlayer

layer
1,1,1,1,1,1,1,1,1,1,1,1,1,1,1,1,1
1,1,1,1,1,1,1,1,1,1,1,1,1,1,1,1,1
1,1,1,1,1,1,1,1,1,1,1,1,1,1,1,1,1
1,1,1,1,1,1,1,1,1,1,1,1,1,1,1,1,1
1,1,1,1,1,1,1,1,1,1,1,1,1,1,1,1,1
1,1,1,1,1,1,1,4,4,3,1,1,1,1,1,1,1
1,1,1,1,1,1,3,3,3,3,3,1,1,1,1,1,1
1,1,1,1,1,3,3,5,0,0,3,4,1,1,1,1,1
1,1,1,1,1,4,3,0,0,0,3,4,1,1,1,1,1
1,1,1,1,1,4,3,0,0,0,3,3,1,1,1,1,1
1,1,1,1,1,1,3,3,3,3,3,1,1,1,1,1,1
1,1,1,1,1,1,1,3,4,4,1,1,1,1,1,1,1
1,1,1,1,1,1,1,1,1,1,1,1,1,1,1,1,1
1,1,1,1,1,1,1,1,1,1,1,1,1,1,1,1,1
1,1,1,1,1,1,1,1,1,1,1,1,1,1,1,1,1
1,1,1,1,1,1,1,1,1,1,1,1,1,1,1,1,1
1,1,1,1,1,1,1,1,1,1,1,1,1,1,1,1,1
endlayer

layer
1,1,1,1,1,1,1,1,1,1,1,1,1,1,1,1,1
1,1,1,1,1,1,1,1,1,1,1,1,1,1,1,1,1
1,1,1,1,1,1,1,1,1,1,1,1,1,1,1,1,1
1,1,1,1,1,1,1,1,1,1,1,1,1,1,1,1,1
1,1,1,1,1,1,1,1,1,1,1,1,1,1,1,1,1
1,1,1,1,1,1,1,4,3,3,1,1,1,1,1,1,1
1,1,1,1,1,1,4,3,3,3,4,1,1,1,1,1,1
1,1,1,1,1,3,3,0,0,0,3,4,1,1,1,1,1
1,1,1,1,1,3,3,5,0,0,3,3,1,1,1,1,1
1,1,1,1,1,4,3,0,0,0,3,3,1,1,1,1,1
1,1,1,1,1,1,4,3,3,3,4,1,1,1,1,1,1
1,1,1,1,1,1,1,3,3,4,1,1,1,1,1,1,1
1,1,1,1,1,1,1,1,1,1,1,1,1,1,1,1,1
1,1,1,1,1,1,1,1,1,1,1,1,1,1,1,1,1
1,1,1,1,1,1,1,1,1,1,1,1,1,1,1,1,1
1,1,1,1,1,1,1,1,1,1,1,1,1,1,1,1,1
1,1,1,1,1,1,1,1,1,1,1,1,1,1,1,1,1
endlayer

layer
1,1,1,1,1,1,1,1,1,1,1,1,1,1,1,1,1
1,1,1,1,1,1,1,1,1,1,1,1,1,1,1,1,1
1,1,1,1,1,1,1,1,1,1,1,1,1,1,1,1,1
1,1,1,1,1,1,1,1,1,1,1,1,1,1,1,1,1
1,1,1,1,1,1,1,1,1,1,1,1,1,1,1,1,1
1,1,1,1,1,1,1,3,3,4,1,1,1,1,1,1,1
1,1,1,1,1,1,4,3,3,3,4,1,1,1,1,1,1
1,1,1,1,1,4,3,0,0,0,3,3,1,1,1,1,1
1,1,1,1,1,3,3,0,0,0,3,3,1,1,1,1,1
1,1,1,1,1,3,3,5,0,0,3,4,1,1,1,1,1
1,1,1,1,1,1,4,3,3,3,4,1,1,1,1,1,1
1,1,1,1,1,1,1,4,3,3,1,1,1,1,1,1,1
1,1,1,1,1,1,1,1,1,1,1,1,1,1,1,1,1
1,1,1,1,1,1,1,1,1,1,1,1,1,1,1,1,1
1,1,1,1,1,1,1,1,1,1,1,1,1,1,1,1,1
1,1,1,1,1,1,1,1,1,1,1,1,1,1,1,1,1
1,1,1,1,1,1,1,1,1,1,1,1,1,1,1,1,1
endlayer

layer
1,1,1,1,1,1,1,1,1,1,1,1,1,1,1,1,1
1,1,1,1,1,1,1,1,1,1,1,1,1,1,1,1,1
1,1,1,1,1,1,1,1,1,1,1,1,1,1,1,1,1
1,1,1,1,1,1,1,1,1,1,1,1,1,1,1,1,1
1,1,1,1,1,1,1,1,1,1,1,1,1,1,1,1,1
1,1,1,1,1,1,1,3,4,4,1,1,1,1,1,1,1
1,1,1,1,1,1,3,3,3,3,3,1,1,1,1,1,1
1,1,1,1,1,4,3,0,0,0,3,3,1,1,1,1,1
1,1,1,1,1,4,3,0,0,0,3,4,1,1,1,1,1
1,1,1,1,1,3,3,0,5,0,3,4,1,1,1,1,1
1,1,1,1,1,1,3,3,3,3,3,1,1,1,1,1,1
1,1,1,1,1,1,1,4,4,3,1,1,1,1,1,1,1
1,1,1,1,1,1,1,1,1,1,1,1,1,1,1,1,1
1,1,1,1,1,1,1,1,1,1,1,1,1,1,1,1,1
1,1,1,1,1,1,1,1,1,1,1,1,1,1,1,1,1
1,1,1,1,1,1,1,1,1,1,1,1,1,1,1,1,1
1,1,1,1,1,1,1,1,1,1,1,1,1,1,1,1,1
endlayer

layer
1,1,1,1,1,1,1,1,1,1,1,1,1,1,1,1,1
1,1,1,1,1,1,1,1,1,1,1,1,1,1,1,1,1
1,1,1,1,1,1,1,1,1,1,1,1,1,1,1,1,1
1,1,1,1,1,1,1,1,1,1,1,1,1,1,1,1,1
1,1,1,1,1,1,1,1,1,1,1,1,1,1,1,1,1
1,1,1,1,1,1,1,4,4,3,1,1,1,1,1,1,1
1,1,1,1,1,1,3,3,3,3,3,1,1,1,1,1,1
1,1,1,1,1,3,3,0,0,0,3,4,1,1,1,1,1
1,1,1,1,1,4,3,0,0,0,3,4,1,1,1,1,1
1,1,1,1,1,4,3,0,0,5,3,3,1,1,1,1,1
1,1,1,1,1,1,3,3,3,3,3,1,1,1,1,1,1
1,1,1,1,1,1,1,3,4,4,1,1,1,1,1,1,1
1,1,1,1,1,1,1,1,1,1,1,1,1,1,1,1,1
1,1,1,1,1,1,1,1,1,1,1,1,1,1,1,1,1
1,1,1,1,1,1,1,1,1,1,1,1,1,1,1,1,1
1,1,1,1,1,1,1,1,1,1,1,1,1,1,1,1,1
1,1,1,1,1,1,1,1,1,1,1,1,1,1,1,1,1
endlayer

layer
1,1,1,1,1,1,1,1,1,1,1,1,1,1,1,1,1
1,1,1,1,1,1,1,1,1,1,1,1,1,1,1,1,1
1,1,1,1,1,1,1,1,1,1,1,1,1,1,1,1,1
1,1,1,1,1,1,1,1,1,1,1,1,1,1,1,1,1
1,1,1,1,1,1,1,1,1,1,1,1,1,1,1,1,1
1,1,1,1,1,1,1,4,3,3,1,1,1,1,1,1,1
1,1,1,1,1,1,4,3,3,3,4,1,1,1,1,1,1
1,1,1,1,1,3,3,0,0,0,3,4,1,1,1,1,1
1,1,1,1,1,3,3,0,0,5,3,3,1,1,1,1,1
1,1,1,1,1,4,3,0,0,0,3,3,1,1,1,1,1
1,1,1,1,1,1,4,3,3,3,4,1,1,1,1,1,1
1,1,1,1,1,1,1,3,3,4,1,1,1,1,1,1,1
1,1,1,1,1,1,1,1,1,1,1,1,1,1,1,1,1
1,1,1,1,1,1,1,1,1,1,1,1,1,1,1,1,1
1,1,1,1,1,1,1,1,1,1,1,1,1,1,1,1,1
1,1,1,1,1,1,1,1,1,1,1,1,1,1,1,1,1
1,1,1,1,1,1,1,1,1,1,1,1,1,1,1,1,1
endlayer

