
# Created by Ruins mod version 17.0 Ingame Parser
# authoring Player: ST753M

weight=1
embed_into_distance=6
acceptable_target_blocks=
unacceptable_target_blocks=flowing_water,water,flowing_lava,lava
dimensions=9,11,11
allowable_overhang=6
max_leveling=2
leveling_buffer=0
preserve_water=0
preserve_lava=0

rule1=0,100,preserveBlock
rule2=0,100,minecraft:end_stone-0
rule3=0,100,minecraft:purpur_stairs-6
rule4=0,100,minecraft:purpur_stairs-4
rule5=0,100,minecraft:purpur_stairs-7
rule6=0,100,minecraft:purpur_pillar-0
rule7=0,100,minecraft:purpur_stairs-5
rule8=0,100,minecraft:purpur_pillar-8
rule9=0,100,minecraft:purpur_pillar-4
rule10=0,100,minecraft:water-0
rule11=0,100,minecraft:farmland-7
rule12=0,100,minecraft:purpur_stairs-0
rule13=0,100,minecraft:purpur_stairs-2
rule14=0,100,minecraft:purpur_stairs-3

rule15=0,100,minecraft:carrots-0,minecraft:carrots-1,minecraft:carrots-2,minecraft:carrots-3,minecraft:carrots-4,minecraft:carrots-5,minecraft:carrots-6,minecraft:carrots-7

^0,100,minecraft:potatoes-0,minecraft:potatoes-1,minecraft:potatoes-2,minecraft:potatoes-3,minecraft:potatoes-4,minecraft:potatoes-5,minecraft:potatoes-6,minecraft:potatoes-7

^0,100,minecraft:wheat-0,minecraft:wheat-1,minecraft:wheat-2,minecraft:wheat-3,minecraft:wheat-4,minecraft:wheat-5,minecraft:wheat-6,minecraft:wheat-7

rule16=0,100,minecraft:purpur_stairs-1
rule17=0,100,minecraft:end_rod-1

layer
1,1,1,1,1,1,1,1,1,1,1
1,1,1,1,1,1,1,1,1,1,1
1,1,1,1,1,1,1,1,1,1,1
1,1,1,1,1,1,1,1,1,1,1
1,1,1,1,2,2,2,1,1,1,1
1,1,1,1,2,2,2,1,1,1,1
1,1,1,1,2,2,2,1,1,1,1
1,1,1,1,1,1,1,1,1,1,1
1,1,1,1,1,1,1,1,1,1,1
1,1,1,1,1,1,1,1,1,1,1
1,1,1,1,1,1,1,1,1,1,1
endlayer

layer
1,1,1,1,1,1,1,1,1,1,1
1,1,1,1,1,1,1,1,1,1,1
1,1,1,1,2,2,2,1,1,1,1
1,1,1,2,2,2,2,2,1,1,1
1,1,2,2,2,2,2,2,2,1,1
1,1,2,2,2,2,2,2,2,1,1
1,1,2,2,2,2,2,2,2,1,1
1,1,1,2,2,2,2,2,1,1,1
1,1,1,1,2,2,2,1,1,1,1
1,1,1,1,1,1,1,1,1,1,1
1,1,1,1,1,1,1,1,1,1,1
endlayer

layer
1,1,1,1,1,1,1,1,1,1,1
1,1,2,2,2,2,2,2,2,1,1
1,2,2,2,2,2,2,2,2,2,1
1,2,2,2,2,2,2,2,2,2,1
1,2,2,2,2,2,2,2,2,2,1
1,2,2,2,2,2,2,2,2,2,1
1,2,2,2,2,2,2,2,2,2,1
1,2,2,2,2,2,2,2,2,2,1
1,2,2,2,2,2,2,2,2,2,1
1,1,2,2,2,2,2,2,2,1,1
1,1,1,1,1,1,1,1,1,1,1
endlayer

layer
1,1,1,2,2,2,2,2,1,1,1
1,1,2,2,2,2,2,2,2,1,1
1,2,2,2,2,2,2,2,2,2,1
2,2,2,2,2,2,2,2,2,2,2
2,2,2,2,2,2,2,2,2,2,2
2,2,2,2,2,2,2,2,2,2,2
2,2,2,2,2,2,2,2,2,2,2
2,2,2,2,2,2,2,2,2,2,2
1,2,2,2,2,2,2,2,2,2,1
1,1,2,2,2,2,2,2,2,1,1
1,1,1,2,2,2,2,2,1,1,1
endlayer

layer
1,1,2,2,2,2,2,2,2,1,1
1,2,2,2,2,2,2,2,2,2,1
2,2,2,2,2,2,2,2,2,2,2
2,2,2,2,2,2,2,2,2,2,2
2,2,2,2,2,2,2,2,2,2,2
2,2,2,2,2,2,2,2,2,2,2
2,2,2,2,2,2,2,2,2,2,2
2,2,2,2,2,2,2,2,2,2,2
2,2,2,2,2,2,2,2,2,2,2
1,2,2,2,2,2,2,2,2,2,1
1,1,2,2,2,2,2,2,2,1,1
endlayer

layer
5,4,2,2,2,2,2,2,2,4,3
5,6,2,2,2,2,2,2,2,6,3
2,2,2,2,2,2,2,2,2,2,2
2,2,2,2,2,2,2,2,2,2,2
2,2,2,2,2,2,2,2,2,2,2
2,2,2,2,2,2,2,2,2,2,2
2,2,2,2,2,2,2,2,2,2,2
2,2,2,2,2,2,2,2,2,2,2
2,2,2,2,2,2,2,2,2,2,2
5,6,2,2,2,2,2,2,2,6,3
5,7,2,2,2,2,2,2,2,7,3
endlayer

layer
6,8,6,1,1,1,1,1,6,8,6
9,10,9,8,8,6,8,8,9,10,9
6,8,6,11,11,11,11,11,6,8,6
1,9,11,11,11,11,11,11,11,9,1
1,9,11,11,11,11,11,11,11,9,1
1,6,11,11,11,11,11,11,11,6,1
1,9,11,11,11,11,11,11,11,9,1
1,9,11,11,11,11,11,11,11,9,1
6,8,6,11,11,11,11,11,6,8,6
9,10,9,8,8,6,8,8,9,10,9
6,8,6,1,1,1,1,1,6,8,6
endlayer

layer
0,12,0,0,0,0,0,0,0,12,0
14,6,0,0,0,0,0,0,0,6,13
0,0,0,15,15,15,15,15,0,0,0
0,0,15,15,15,15,15,15,15,0,0
0,0,15,15,15,15,15,15,15,0,0
0,0,15,15,15,15,15,15,15,0,0
0,0,15,15,15,15,15,15,15,0,0
0,0,15,15,15,15,15,15,15,0,0
0,0,0,15,15,15,15,15,0,0,0
14,6,0,0,0,0,0,0,0,6,13
0,16,0,0,0,0,0,0,0,16,0
endlayer

layer
0,0,0,0,0,0,0,0,0,0,0
0,17,0,0,0,0,0,0,0,17,0
0,0,0,0,0,0,0,0,0,0,0
0,0,0,0,0,0,0,0,0,0,0
0,0,0,0,0,0,0,0,0,0,0
0,0,0,0,0,0,0,0,0,0,0
0,0,0,0,0,0,0,0,0,0,0
0,0,0,0,0,0,0,0,0,0,0
0,0,0,0,0,0,0,0,0,0,0
0,17,0,0,0,0,0,0,0,17,0
0,0,0,0,0,0,0,0,0,0,0
endlayer

