
# Created by Ruins mod version 16.9 Ingame Parser
# authoring Player: ST753M

# Summoned by mystic_grove/MysticCastle_CB

weight=1
embed_into_distance=10
acceptable_target_blocks=
unacceptable_target_blocks=flowing_water,water,flowing_lava,lava
dimensions=38,13,21
allowable_overhang=0
max_leveling=0
leveling_buffer=0
preserve_water=0
preserve_lava=0

rule1=0,100,preserveBlock
rule2=0,100,biomesoplenty:white_sandstone-0
rule3=0,100,biomesoplenty:planks_0-5
rule4=0,100,biomesoplenty:white_sandstone_stairs-0
rule5=0,100,biomesoplenty:white_sandstone_stairs-2
rule6=0,100,biomesoplenty:white_sandstone_stairs-3
rule7=0,100,biomesoplenty:white_sandstone_stairs-1
rule8=0,100,biomesoplenty:white_sandstone_stairs-6
rule9=0,100,biomesoplenty:other_slab-9
rule10=0,100,biomesoplenty:white_sandstone_stairs-7
rule11=0,100,minecraft:sea_lantern-0
rule12=0,100,biomesoplenty:magic_stairs-6
rule13=0,100,biomesoplenty:magic_stairs-1
rule14=0,100,minecraft:bed-10
rule15=0,100,minecraft:bed-2
rule16=0,100,biomesoplenty:other_slab-1
rule17=0,100,biomesoplenty:magic_fence-0
rule18=0,100,CommandBlock:RUINSTRIGGER /summon stray ~ ~1 ~ {ArmorItems:[{id:"minecraft:iron_boots",Count:1b},{id:"minecraft:iron_leggings",Count:1b},{id:"minecraft:iron_chestplate",Count:1b},{id:"minecraft:stained_glass",Damage:11,Count:1b}],HandItems:[{id:"minecraft:bow",Count:1b,tag:{ench:[{id:34,lvl:2},{id:48,lvl:2},{id:50,lvl:1}]}},{}],PersistenceRequired:1,Silent:1}:@-1
rule19=0,100,minecraft:quartz_stairs-3
rule20=0,100,minecraft:quartz_stairs-2
rule21=0,100,minecraft:stained_glass-11
rule22=0,100,biomesoplenty:magic_stairs-3
rule23=0,100,minecraft:carpet-11
rule24=0,100,biomesoplenty:white_sandstone_stairs-4
rule25=0,100,biomesoplenty:white_sandstone_stairs-5
rule26=0,100,minecraft:trapdoor-14
rule27=0,100,minecraft:trapdoor-12
rule28=0,100,minecraft:grass-0
rule29=0,100,minecraft:trapdoor-13
rule30=0,100,minecraft:trapdoor-15
rule31=0,100,biomesoplenty:sapling_0-11
rule32=0,100,biomesoplenty:magic_stairs-7
rule33=0,100,biomesoplenty:magic_stairs-5
rule34=0,100,biomesoplenty:magic_stairs-4
rule35=0,100,biomesoplenty:wood_slab_0-13
rule36=0,100,biomesoplenty:magic_stairs-0
rule37=0,100,biomesoplenty:magic_stairs-2
rule38=0,100,biomesoplenty:wood_slab_0-5

layer
1,1,1,1,1,1,1,1,1,1,1,1,1,1,1,1,1,1,1,1,1
1,1,1,1,1,1,1,1,1,1,1,2,0,2,0,2,1,1,1,1,1
1,1,1,1,1,1,1,1,1,1,1,0,0,0,0,0,1,1,1,1,1
1,1,1,1,1,1,1,1,1,2,0,0,0,0,0,0,0,2,1,1,1
1,1,1,1,1,1,1,1,1,0,0,0,0,0,0,0,0,0,1,1,1
1,1,1,1,1,1,1,1,2,0,0,0,0,0,0,0,0,0,2,1,1
1,1,1,1,1,1,1,1,0,0,0,0,0,0,0,0,0,0,0,1,1
1,1,1,1,1,1,1,1,2,0,0,0,0,0,0,0,0,0,2,1,1
1,1,1,1,1,1,1,1,1,0,0,0,0,0,0,0,0,0,1,1,1
1,1,1,1,1,1,1,1,1,2,0,0,0,0,0,0,0,2,1,1,1
1,1,1,1,1,1,1,1,1,1,1,0,0,0,0,0,1,1,1,1,1
1,1,1,1,1,1,1,1,1,1,1,2,0,2,0,2,1,1,1,1,1
1,1,1,1,1,1,1,1,1,1,1,1,1,1,1,1,1,1,1,1,1
endlayer

layer
1,1,1,1,1,1,1,1,1,1,1,1,1,1,1,1,1,1,1,1,1
1,1,1,1,1,1,1,1,1,1,1,2,2,2,2,2,1,1,1,1,1
1,1,1,1,1,1,1,1,1,1,2,0,0,0,0,0,2,1,1,1,1
1,1,1,1,1,1,1,1,1,2,0,0,0,0,0,0,0,2,1,1,1
1,1,1,1,1,1,1,1,2,0,0,0,0,0,0,0,0,0,2,1,1
1,1,1,1,1,1,1,1,2,0,0,0,0,0,0,0,0,0,2,1,1
1,1,1,1,1,1,1,1,2,0,0,0,0,0,0,0,0,0,2,1,1
1,1,1,1,1,1,1,1,2,0,0,0,0,0,0,0,0,0,2,1,1
1,1,1,1,1,1,1,1,2,0,0,0,0,0,0,0,0,0,2,1,1
1,1,1,1,1,1,1,1,1,2,0,0,0,0,0,0,0,2,1,1,1
1,1,1,1,1,1,1,1,1,1,2,0,0,0,0,0,2,1,1,1,1
1,1,1,1,1,1,1,1,1,1,1,2,2,2,2,2,1,1,1,1,1
1,1,1,1,1,1,1,1,1,1,1,1,1,1,1,1,1,1,1,1,1
endlayer

layer
1,1,1,1,1,1,1,1,1,1,1,1,1,1,1,1,1,1,1,1,1
1,1,1,1,1,1,1,1,1,1,1,0,2,0,2,0,1,1,1,1,1
1,1,1,1,1,1,1,1,1,1,2,3,3,3,3,3,2,1,1,1,1
1,1,1,1,1,1,1,1,1,0,3,0,0,0,0,0,3,0,1,1,1
1,1,1,1,1,1,1,1,2,3,0,0,0,0,0,0,0,3,2,1,1
1,1,1,1,1,1,1,1,0,3,0,0,0,0,0,0,0,3,0,1,1
1,1,1,1,1,1,1,1,2,3,0,0,0,0,0,0,0,3,2,1,1
1,1,1,1,1,1,1,1,0,3,0,0,0,0,0,0,0,3,0,1,1
1,1,1,1,1,1,1,1,2,3,0,0,0,0,0,0,0,3,2,1,1
1,1,1,1,1,1,1,1,1,0,3,0,0,0,0,0,3,0,1,1,1
1,1,1,1,1,1,1,1,1,1,2,3,3,3,3,3,2,1,1,1,1
1,1,1,1,1,1,1,1,1,1,1,0,2,0,2,0,1,1,1,1,1
1,1,1,1,1,1,1,1,1,1,1,1,1,1,1,1,1,1,1,1,1
endlayer

layer
1,1,1,1,1,1,1,1,1,1,1,1,1,1,1,1,1,1,1,1,1
1,1,1,1,1,1,1,1,1,1,1,2,4,2,4,2,1,1,1,1,1
1,1,1,1,1,1,1,1,1,1,2,3,3,3,3,3,2,1,1,1,1
1,1,1,1,1,1,1,1,1,2,3,3,3,3,3,3,3,2,1,1,1
1,1,1,1,1,1,1,1,6,3,3,3,0,0,0,3,3,3,5,1,1
1,1,1,1,1,1,1,1,2,3,3,0,0,0,0,0,3,3,2,1,1
1,1,1,1,1,1,1,1,6,3,3,0,0,0,0,0,3,3,5,1,1
1,1,1,1,1,1,1,1,2,3,3,0,0,0,0,0,3,3,2,1,1
1,1,1,1,1,1,1,1,6,3,3,3,0,0,0,3,3,3,5,1,1
1,1,1,1,1,1,1,1,1,2,3,3,3,3,3,3,3,2,1,1,1
1,1,1,1,1,1,1,1,1,1,2,3,3,3,3,3,2,1,1,1,1
1,1,1,1,1,1,1,1,1,1,1,2,7,2,7,2,1,1,1,1,1
1,1,1,1,1,1,1,1,1,1,1,1,1,1,1,1,1,1,1,1,1
endlayer

layer
1,1,1,1,1,1,1,1,1,1,1,1,1,1,1,1,1,1,1,1,1
1,1,1,1,1,1,1,1,1,1,1,4,0,4,0,4,1,1,1,1,1
1,1,1,1,1,1,1,1,1,1,0,2,2,2,2,2,0,1,1,1,1
1,1,1,1,1,1,1,1,1,6,2,3,3,3,3,3,2,5,1,1,1
1,1,1,1,1,1,1,1,0,2,3,3,3,3,3,3,3,2,0,1,1
1,1,10,9,8,1,1,1,2,2,3,3,3,3,3,3,3,2,5,1,1
1,1,1,1,1,1,1,1,0,2,3,3,3,11,3,3,3,2,0,1,1
1,1,10,9,8,1,1,1,2,2,3,3,3,3,3,3,3,2,5,1,1
1,1,1,1,1,1,1,1,0,2,3,3,3,3,3,3,3,2,0,1,1
1,1,1,1,1,1,1,1,1,6,2,3,3,3,3,3,2,5,1,1,1
1,1,1,1,1,1,1,1,1,1,0,2,2,2,2,2,0,1,1,1,1
1,1,1,1,1,1,1,1,1,1,1,7,0,7,0,7,1,1,1,1,1
1,1,1,1,1,1,1,1,1,1,1,1,1,1,1,1,1,1,1,1,1
endlayer

layer
1,1,1,1,1,1,1,1,1,1,1,1,1,1,1,1,1,1,1,1,1
1,1,1,1,1,1,1,1,1,1,1,0,0,0,0,0,1,1,1,1,1
1,1,1,1,1,1,1,1,1,1,0,2,2,2,2,2,0,1,1,1,1
1,1,1,1,1,1,1,1,1,0,2,13,12,0,0,0,2,0,1,1,1
1,1,1,1,1,1,1,1,0,2,0,0,0,0,0,0,0,2,0,1,1
16,16,16,2,16,16,16,2,5,2,0,0,0,0,0,15,14,2,0,1,1
0,0,0,0,0,0,0,0,0,2,0,0,18,0,0,0,17,2,0,1,1
16,16,16,2,16,16,16,2,5,2,0,0,0,0,0,15,14,2,0,1,1
1,1,1,1,1,1,1,1,0,2,0,0,0,0,0,0,0,2,0,1,1
1,1,1,1,1,1,1,1,1,0,2,0,20,17,19,0,2,0,1,1,1
1,1,1,1,1,1,1,1,1,1,0,2,2,2,2,2,0,1,1,1,1
1,1,1,1,1,1,1,1,1,1,1,0,0,0,0,0,1,1,1,1,1
1,1,1,1,1,1,1,1,1,1,1,1,1,1,1,1,1,1,1,1,1
endlayer

layer
1,1,1,1,1,1,1,1,1,1,1,1,1,1,1,1,1,1,1,1,1
1,1,1,1,1,1,1,1,1,1,1,0,0,0,0,0,1,1,1,1,1
1,1,1,1,1,1,1,1,1,1,0,2,21,2,21,2,0,1,1,1,1
1,1,1,1,1,1,1,1,1,0,21,0,22,12,0,0,21,0,1,1,1
1,1,1,1,1,1,1,1,0,2,0,0,0,0,0,0,0,2,0,1,1
8,0,0,2,0,0,10,5,0,21,0,0,0,0,0,0,0,21,0,1,1
0,0,0,0,0,0,0,0,0,2,0,0,0,0,0,0,23,2,0,1,1
8,0,0,2,0,0,10,5,0,21,0,0,0,0,0,0,0,21,0,1,1
1,1,1,1,1,1,1,1,0,2,0,0,0,0,0,0,0,2,0,1,1
1,1,1,1,1,1,1,1,1,0,21,0,0,23,0,0,21,0,1,1,1
1,1,1,1,1,1,1,1,1,1,0,2,21,2,21,2,0,1,1,1,1
1,1,1,1,1,1,1,1,1,1,1,0,0,0,0,0,1,1,1,1,1
1,1,1,1,1,1,1,1,1,1,1,1,1,1,1,1,1,1,1,1,1
endlayer

layer
1,1,1,1,1,1,1,1,1,1,1,1,1,1,1,1,1,1,1,1,1
1,1,1,1,1,1,1,1,1,1,1,0,0,0,0,0,1,1,1,1,1
1,1,1,1,1,1,1,1,1,1,0,2,21,2,21,2,0,1,1,1,1
1,1,1,1,1,1,1,1,1,0,21,0,0,22,12,0,21,0,1,1,1
1,1,1,1,1,1,1,1,0,2,0,0,0,0,0,0,0,2,0,1,1
6,8,10,2,8,10,5,0,0,21,0,0,0,0,0,0,0,21,0,1,1
0,0,0,0,0,0,0,0,0,2,0,0,0,0,0,0,0,2,0,1,1
6,8,10,2,8,10,5,0,0,21,0,0,0,0,0,0,0,21,0,1,1
1,1,1,1,1,1,1,1,0,2,0,0,0,0,0,0,0,2,0,1,1
1,1,1,1,1,1,1,1,1,0,21,0,0,0,0,0,21,0,1,1,1
1,1,1,1,1,1,1,1,1,1,0,2,21,2,21,2,0,1,1,1,1
1,1,1,1,1,1,1,1,1,1,1,0,0,0,0,0,1,1,1,1,1
1,1,1,1,1,1,1,1,1,1,1,1,1,1,1,1,1,1,1,1,1
endlayer

layer
1,1,1,1,1,1,1,1,1,1,1,1,1,1,1,1,1,1,1,1,1
1,1,1,1,1,1,1,1,1,1,1,0,0,0,0,0,1,1,1,1,1
1,1,1,1,1,1,1,1,1,1,0,2,2,2,2,2,0,1,1,1,1
1,1,1,1,1,1,1,1,1,0,2,0,0,0,22,12,2,0,1,1,1
24,24,24,24,24,24,24,24,24,2,0,0,0,0,0,0,0,2,0,1,1
2,2,2,2,2,2,2,2,2,2,0,0,0,0,0,0,0,2,0,1,1
3,3,3,3,3,3,3,3,3,2,0,0,0,0,0,0,0,2,0,1,1
2,2,2,2,2,2,2,2,2,2,0,0,0,0,0,0,0,2,0,1,1
25,25,25,25,25,25,25,25,25,2,0,0,0,0,0,0,0,2,0,1,1
1,1,1,1,1,1,1,1,1,0,2,0,0,0,0,0,2,0,1,1,1
1,1,1,1,1,1,1,1,1,1,0,2,2,2,2,2,0,1,1,1,1
1,1,1,1,1,1,1,1,1,1,1,0,0,0,0,0,1,1,1,1,1
1,1,1,1,1,1,1,1,1,1,1,1,1,1,1,1,1,1,1,1,1
endlayer

layer
1,1,1,1,1,1,1,1,1,1,1,1,1,1,1,1,1,1,1,1,1
1,1,1,1,1,1,1,1,1,1,1,4,4,4,4,4,1,1,1,1,1
1,1,1,1,1,1,1,1,1,1,4,2,2,2,2,2,4,1,1,1,1
2,2,2,2,2,2,2,2,2,2,2,12,0,0,0,22,2,5,1,1,1
2,2,2,2,2,2,2,2,2,2,3,3,3,3,3,3,3,2,5,1,1
3,3,3,3,3,3,3,3,3,3,3,3,3,3,3,3,3,2,5,1,1
3,3,3,3,3,3,3,3,3,3,3,3,3,11,3,3,3,2,5,1,1
3,3,3,3,3,3,3,3,3,3,3,3,3,3,3,3,3,2,5,1,1
2,2,2,2,2,2,2,2,2,2,3,3,3,3,3,3,3,2,5,1,1
2,2,2,2,2,2,2,2,2,2,2,3,3,3,3,3,2,5,1,1,1
1,1,1,1,1,1,1,1,1,1,7,2,2,2,2,2,7,1,1,1,1
1,1,1,1,1,1,1,1,1,1,1,7,7,7,7,7,1,1,1,1,1
1,1,1,1,1,1,1,1,1,1,1,1,1,1,1,1,1,1,1,1,1
endlayer

layer
1,1,1,1,1,1,1,1,1,1,1,1,1,1,1,1,1,1,1,1,1
1,1,1,1,1,1,1,1,1,1,1,0,0,0,0,0,1,1,1,1,1
1,1,1,1,1,1,1,1,1,1,0,2,2,2,2,2,0,1,1,1,1
4,0,4,0,4,0,4,0,4,0,2,13,12,0,0,0,2,0,1,1,1
2,2,2,2,2,2,2,2,2,2,0,0,0,0,0,0,0,2,0,1,1
0,0,0,0,0,0,0,0,0,0,0,0,0,0,0,0,0,2,0,1,1
0,0,0,0,0,0,0,0,0,0,0,0,0,0,0,0,0,2,0,1,1
0,0,0,0,0,0,0,0,0,0,0,0,0,0,0,0,0,2,0,1,1
2,2,2,2,2,2,2,2,2,2,0,0,0,0,0,0,0,2,0,1,1
7,0,7,0,7,0,7,0,7,0,2,0,0,0,0,0,2,0,1,1,1
1,1,1,1,1,1,1,1,1,1,0,2,2,2,2,2,0,1,1,1,1
1,1,1,1,1,1,1,1,1,1,1,0,0,0,0,0,1,1,1,1,1
1,1,1,1,1,1,1,1,1,1,1,1,1,1,1,1,1,1,1,1,1
endlayer

layer
1,1,1,1,1,1,1,1,1,1,1,1,1,1,1,1,1,1,1,1,1
1,1,1,1,1,1,1,1,1,1,1,0,0,0,0,0,1,1,1,1,1
1,1,1,1,1,1,1,1,1,1,0,2,21,2,21,2,0,1,1,1,1
0,0,0,0,0,0,0,0,0,0,21,0,22,12,0,0,21,0,1,1,1
21,2,21,2,21,2,21,2,21,2,0,0,0,0,0,0,0,2,0,1,1
0,0,0,0,0,0,0,0,0,0,0,0,0,0,0,0,0,21,0,1,1
0,0,0,0,0,0,0,0,0,0,0,0,0,0,0,0,0,2,0,1,1
0,0,0,0,0,0,0,0,0,0,0,0,0,0,0,0,0,21,0,1,1
21,2,21,2,21,2,21,2,21,2,0,0,0,0,0,0,0,2,0,1,1
0,0,0,0,0,0,0,0,0,0,21,0,0,0,0,0,21,0,1,1,1
1,1,1,1,1,1,1,1,1,1,0,2,21,2,21,2,0,1,1,1,1
1,1,1,1,1,1,1,1,1,1,1,0,0,0,0,0,1,1,1,1,1
1,1,1,1,1,1,1,1,1,1,1,1,1,1,1,1,1,1,1,1,1
endlayer

layer
1,1,1,1,1,1,1,1,1,1,1,1,1,1,1,1,1,1,1,1,1
1,1,1,1,1,1,1,1,1,1,1,0,0,0,0,0,1,1,1,1,1
1,1,1,1,1,1,1,1,1,1,0,2,21,2,21,2,0,1,1,1,1
0,0,0,0,0,0,0,0,0,0,21,0,0,22,12,0,21,0,1,1,1
21,2,21,2,21,2,21,2,21,2,0,0,0,0,0,0,0,2,0,1,1
0,0,0,0,0,0,0,0,0,0,0,0,0,0,0,0,0,21,0,1,1
0,0,0,0,0,0,0,0,0,0,0,0,0,0,0,0,0,2,0,1,1
0,0,0,0,0,0,0,0,0,0,0,0,0,0,0,0,0,21,0,1,1
21,2,21,2,21,2,21,2,21,2,0,0,0,0,0,0,0,2,0,1,1
0,0,0,0,0,0,0,0,0,0,21,0,0,0,0,0,21,0,1,1,1
1,1,1,1,1,1,1,1,1,1,0,2,21,2,21,2,0,1,1,1,1
1,1,1,1,1,1,1,1,1,1,1,0,0,0,0,0,1,1,1,1,1
1,1,1,1,1,1,1,1,1,1,1,1,1,1,1,1,1,1,1,1,1
endlayer

layer
1,1,1,1,1,1,1,1,1,1,1,1,1,1,1,1,1,1,1,1,1
1,1,1,1,1,1,1,1,1,1,1,0,0,0,0,0,1,1,1,1,1
1,1,1,1,1,1,1,1,1,1,0,2,2,2,2,2,0,1,1,1,1
24,0,24,0,24,0,24,0,24,0,2,0,0,0,22,12,2,0,1,1,1
2,2,2,2,2,2,2,2,2,2,0,0,0,0,0,0,0,2,0,1,1
25,25,25,25,25,25,25,25,25,25,0,0,0,0,0,0,0,2,0,1,1
0,0,0,0,0,0,0,0,0,0,0,0,0,0,0,0,0,2,0,1,1
24,24,24,24,24,24,24,24,24,24,0,0,0,0,0,0,0,2,0,1,1
2,2,2,2,2,2,2,2,2,2,0,0,0,0,0,0,0,2,0,1,1
25,0,25,0,25,0,25,0,25,0,2,0,0,0,0,0,2,0,1,1,1
1,1,1,1,1,1,1,1,1,1,0,2,2,2,2,2,0,1,1,1,1
1,1,1,1,1,1,1,1,1,1,1,0,0,0,0,0,1,1,1,1,1
1,1,1,1,1,1,1,1,1,1,1,1,1,1,1,1,1,1,1,1,1
endlayer

layer
1,1,1,1,1,1,1,1,1,1,1,1,1,1,1,1,1,1,1,1,1
1,1,1,1,1,1,1,1,1,1,1,4,4,4,4,4,1,1,1,1,1
1,1,1,1,1,1,1,1,1,1,4,2,2,2,2,2,4,1,1,1,1
2,2,2,2,2,2,2,2,2,2,2,0,0,0,18,22,2,5,1,1,1
2,2,2,2,2,2,2,2,2,2,3,3,3,3,3,3,3,2,5,1,1
3,3,3,3,3,3,3,3,3,3,3,3,3,3,3,3,3,2,5,1,1
3,3,3,11,3,3,3,3,3,3,3,3,3,11,3,3,3,2,5,1,1
3,3,3,3,3,3,3,3,3,3,3,3,3,3,3,3,3,2,5,1,1
2,2,2,2,2,2,2,2,2,2,3,3,3,3,3,3,3,2,5,1,1
2,2,2,2,2,2,2,2,2,2,2,3,3,3,3,3,2,5,1,1,1
1,1,1,1,1,1,1,1,1,1,7,2,2,2,2,2,7,1,1,1,1
1,1,1,1,1,1,1,1,1,1,1,7,7,7,7,7,1,1,1,1,1
1,1,1,1,1,1,1,1,1,1,1,1,1,1,1,1,1,1,1,1,1
endlayer

layer
1,1,1,1,1,1,1,1,1,1,1,1,1,1,1,1,1,1,1,1,1
1,1,1,1,1,1,1,1,1,1,1,0,0,0,0,0,1,1,1,1,1
1,1,1,1,1,1,1,1,1,1,0,2,2,2,2,2,0,1,1,1,1
23,23,23,23,23,23,23,23,23,23,2,0,0,0,0,0,2,0,1,1,1
5,5,5,5,5,5,5,5,5,2,0,0,0,0,0,0,0,2,0,1,1
0,0,0,0,0,0,0,0,0,7,0,0,0,26,0,0,0,2,0,1,1
0,0,0,0,0,0,0,0,0,0,0,0,29,28,27,0,0,2,0,1,1
0,0,0,0,0,0,0,0,0,4,0,0,0,30,0,0,0,2,0,1,1
5,5,5,5,5,5,5,5,5,2,0,0,0,0,0,0,0,2,0,1,1
23,23,23,23,23,23,23,23,23,23,2,0,0,0,0,0,2,0,1,1,1
1,1,1,1,1,1,1,1,1,1,0,2,2,2,2,2,0,1,1,1,1
1,1,1,1,1,1,1,1,1,1,1,0,0,0,0,0,1,1,1,1,1
1,1,1,1,1,1,1,1,1,1,1,1,1,1,1,1,1,1,1,1,1
endlayer

layer
1,1,1,1,1,1,1,1,1,1,1,1,1,1,1,1,1,1,1,1,1
1,1,1,1,1,1,1,1,1,1,1,0,0,0,0,0,1,1,1,1,1
1,1,1,1,1,1,1,1,1,1,0,2,21,2,21,2,0,1,1,1,1
1,1,1,1,1,1,1,1,1,1,21,0,0,0,0,0,21,0,1,1,1
1,1,1,1,1,1,1,1,1,2,0,0,0,0,0,0,0,2,0,1,1
1,1,1,1,1,1,1,1,1,0,0,0,0,0,0,0,0,21,0,1,1
1,1,1,1,1,1,1,1,1,0,0,0,0,31,0,0,0,2,0,1,1
1,1,1,1,1,1,1,1,1,0,0,0,0,0,0,0,0,21,0,1,1
1,1,1,1,1,1,1,1,1,2,0,0,0,0,0,0,0,2,0,1,1
1,1,1,1,1,1,1,1,1,1,21,0,0,0,0,0,21,0,1,1,1
1,1,1,1,1,1,1,1,1,1,0,2,21,2,21,2,0,1,1,1,1
1,1,1,1,1,1,1,1,1,1,1,0,0,0,0,0,1,1,1,1,1
1,1,1,1,1,1,1,1,1,1,1,1,1,1,1,1,1,1,1,1,1
endlayer

layer
1,1,1,1,1,1,1,1,1,1,1,1,1,1,1,1,1,1,1,1,1
1,1,1,1,1,1,1,1,1,1,1,0,0,0,0,0,1,1,1,1,1
1,1,1,1,1,1,1,1,1,1,0,2,21,2,21,2,0,1,1,1,1
1,1,1,1,1,1,1,1,1,1,21,0,0,0,0,0,21,0,1,1,1
1,1,1,1,1,1,1,1,1,2,0,0,0,0,0,0,0,2,0,1,1
1,1,1,1,1,1,1,1,1,0,0,0,0,0,0,0,0,21,0,1,1
1,1,1,1,1,1,1,1,1,0,0,0,0,0,0,0,0,2,0,1,1
1,1,1,1,1,1,1,1,1,0,0,0,0,0,0,0,0,21,0,1,1
1,1,1,1,1,1,1,1,1,2,0,0,0,0,0,0,0,2,0,1,1
1,1,1,1,1,1,1,1,1,1,21,0,0,0,0,0,21,0,1,1,1
1,1,1,1,1,1,1,1,1,1,0,2,21,2,21,2,0,1,1,1,1
1,1,1,1,1,1,1,1,1,1,1,0,0,0,0,0,1,1,1,1,1
1,1,1,1,1,1,1,1,1,1,1,1,1,1,1,1,1,1,1,1,1
endlayer

layer
1,1,1,1,1,1,1,1,1,1,1,1,1,1,1,1,1,1,1,1,1
1,1,1,1,1,1,1,1,1,1,1,0,0,0,0,0,1,1,1,1,1
1,1,1,1,1,1,1,1,1,1,0,2,2,2,2,2,0,1,1,1,1
1,1,1,1,1,1,1,1,1,1,2,0,0,0,0,0,2,0,1,1,1
1,1,1,1,1,1,1,1,1,2,0,0,0,0,0,0,0,2,0,1,1
1,1,1,1,1,1,1,1,1,25,0,0,0,0,0,0,0,2,0,1,1
1,1,1,1,1,1,1,1,1,0,0,0,0,0,0,0,0,2,0,1,1
1,1,1,1,1,1,1,1,1,24,0,0,0,0,0,0,0,2,0,1,1
1,1,1,1,1,1,1,1,1,2,0,0,0,0,0,0,0,2,0,1,1
1,1,1,1,1,1,1,1,1,1,2,0,0,0,0,0,2,0,1,1,1
1,1,1,1,1,1,1,1,1,1,0,2,2,2,2,2,0,1,1,1,1
1,1,1,1,1,1,1,1,1,1,1,0,0,0,0,0,1,1,1,1,1
1,1,1,1,1,1,1,1,1,1,1,1,1,1,1,1,1,1,1,1,1
endlayer

layer
1,1,1,1,1,1,1,1,1,1,1,1,1,1,1,1,1,1,1,1,1
1,1,1,1,1,1,1,1,1,1,1,4,4,4,4,4,1,1,1,1,1
1,1,1,1,1,1,1,1,1,1,4,2,2,25,2,2,4,1,1,1,1
1,1,1,1,1,1,1,1,1,6,2,12,0,0,0,32,2,5,1,1,1
1,1,1,1,1,1,1,1,6,2,33,0,0,0,0,0,33,2,5,1,1
1,1,1,1,1,1,1,1,6,2,0,0,0,0,0,0,0,2,5,1,1
1,1,1,1,1,1,1,1,6,2,0,0,0,0,0,0,0,10,5,1,1
1,1,1,1,1,1,1,1,6,2,0,0,0,0,0,0,0,2,5,1,1
1,1,1,1,1,1,1,1,6,2,34,0,0,0,0,0,34,2,5,1,1
1,1,1,1,1,1,1,1,1,6,2,12,0,0,0,32,2,5,1,1,1
1,1,1,1,1,1,1,1,1,1,7,2,2,24,2,2,7,1,1,1,1
1,1,1,1,1,1,1,1,1,1,1,7,7,7,7,7,1,1,1,1,1
1,1,1,1,1,1,1,1,1,1,1,1,1,1,1,1,1,1,1,1,1
endlayer

layer
1,1,1,1,1,1,1,1,1,1,1,1,1,1,1,1,1,1,1,1,1
1,1,1,1,1,1,1,1,1,1,1,0,0,0,0,0,1,1,1,1,1
1,1,1,1,1,1,1,1,1,1,0,2,2,2,2,2,0,1,1,1,1
1,1,1,1,1,1,1,1,1,1,2,3,33,33,33,3,2,0,1,1,1
1,1,1,1,1,1,1,1,1,2,3,35,0,0,0,35,3,2,0,1,1
1,1,1,1,1,1,1,1,1,2,12,0,0,0,0,0,32,2,0,1,1
1,1,1,1,1,1,1,1,1,2,12,0,0,0,0,0,32,2,0,1,1
1,1,1,1,1,1,1,1,1,2,12,0,0,0,0,0,32,2,0,1,1
1,1,1,1,1,1,1,1,1,2,3,35,0,0,0,35,3,2,0,1,1
1,1,1,1,1,1,1,1,1,1,2,3,34,34,34,3,2,0,1,1,1
1,1,1,1,1,1,1,1,1,1,0,2,2,2,2,2,0,1,1,1,1
1,1,1,1,1,1,1,1,1,1,1,0,0,0,0,0,1,1,1,1,1
1,1,1,1,1,1,1,1,1,1,1,1,1,1,1,1,1,1,1,1,1
endlayer

layer
1,1,1,1,1,1,1,1,1,1,1,36,36,36,36,36,1,1,1,1,1
1,1,1,1,1,1,1,1,1,22,36,3,3,3,3,3,36,37,1,1,1
1,1,1,1,1,1,1,1,36,3,3,2,2,2,2,2,3,3,36,1,1
1,1,1,1,1,1,1,1,22,3,2,3,3,3,3,3,2,3,37,1,1
1,1,1,1,1,1,1,22,3,2,3,3,12,33,32,3,3,2,3,37,1
1,1,1,1,1,1,1,22,3,2,3,33,35,0,35,33,3,2,3,37,1
1,1,1,1,1,1,1,22,3,2,3,12,0,0,0,32,3,2,3,37,1
1,1,1,1,1,1,1,22,3,2,3,34,35,0,35,34,3,2,3,37,1
1,1,1,1,1,1,1,22,3,2,3,3,12,34,32,3,3,2,3,37,1
1,1,1,1,1,1,1,1,22,3,2,3,3,3,3,3,2,3,37,1,1
1,1,1,1,1,1,1,1,13,3,3,2,2,2,2,2,3,3,13,1,1
1,1,1,1,1,1,1,1,1,22,13,3,3,3,3,3,13,37,1,1,1
1,1,1,1,1,1,1,1,1,1,1,13,13,13,13,13,1,1,1,1,1
endlayer

layer
1,1,1,1,1,1,1,1,1,1,1,1,1,1,1,1,1,1,1,1,1
1,1,1,1,1,1,1,1,1,1,1,1,36,36,36,1,1,1,1,1,1
1,1,1,1,1,1,1,1,1,1,36,3,3,3,3,3,37,1,1,1,1
1,1,1,1,1,1,1,1,1,22,3,3,3,3,3,3,3,36,1,1,1
1,1,1,1,1,1,1,1,1,3,3,3,3,3,3,3,3,3,1,1,1
1,1,1,1,1,1,1,1,22,3,3,3,3,3,3,3,3,3,37,1,1
1,1,1,1,1,1,1,1,22,3,3,3,3,11,3,3,3,3,37,1,1
1,1,1,1,1,1,1,1,22,3,3,3,3,3,3,3,3,3,37,1,1
1,1,1,1,1,1,1,1,1,3,3,3,3,3,3,3,3,3,1,1,1
1,1,1,1,1,1,1,1,1,13,3,3,3,3,3,3,3,13,1,1,1
1,1,1,1,1,1,1,1,1,1,22,3,3,3,3,3,37,1,1,1,1
1,1,1,1,1,1,1,1,1,1,1,1,13,13,13,1,1,1,1,1,1
1,1,1,1,1,1,1,1,1,1,1,1,1,1,1,1,1,1,1,1,1
endlayer

layer
1,1,1,1,1,1,1,1,1,1,1,1,1,1,1,1,1,1,1,1,1
1,1,1,1,1,1,1,1,1,1,1,1,1,1,1,1,1,1,1,1,1
1,1,1,1,1,1,1,1,1,1,1,1,36,36,36,1,1,1,1,1,1
1,1,1,1,1,1,1,1,1,1,1,36,3,3,3,36,1,1,1,1,1
1,1,1,1,1,1,1,1,1,1,22,3,3,3,3,3,37,1,1,1,1
1,1,1,1,1,1,1,1,1,22,3,3,3,3,3,3,3,37,1,1,1
1,1,1,1,1,1,1,1,1,22,3,3,3,3,3,3,3,37,1,1,1
1,1,1,1,1,1,1,1,1,22,3,3,3,3,3,3,3,37,1,1,1
1,1,1,1,1,1,1,1,1,1,22,3,3,3,3,3,37,1,1,1,1
1,1,1,1,1,1,1,1,1,1,1,13,3,3,3,13,1,1,1,1,1
1,1,1,1,1,1,1,1,1,1,1,1,13,13,13,1,1,1,1,1,1
1,1,1,1,1,1,1,1,1,1,1,1,1,1,1,1,1,1,1,1,1
1,1,1,1,1,1,1,1,1,1,1,1,1,1,1,1,1,1,1,1,1
endlayer

layer
1,1,1,1,1,1,1,1,1,1,1,1,1,1,1,1,1,1,1,1,1
1,1,1,1,1,1,1,1,1,1,1,1,1,1,1,1,1,1,1,1,1
1,1,1,1,1,1,1,1,1,1,1,1,1,1,1,1,1,1,1,1,1
1,1,1,1,1,1,1,1,1,1,1,1,3,3,3,1,1,1,1,1,1
1,1,1,1,1,1,1,1,1,1,1,3,3,3,3,3,1,1,1,1,1
1,1,1,1,1,1,1,1,1,1,3,3,3,3,3,3,3,1,1,1,1
1,1,1,1,1,1,1,1,1,1,3,3,3,3,3,3,3,1,1,1,1
1,1,1,1,1,1,1,1,1,1,3,3,3,3,3,3,3,1,1,1,1
1,1,1,1,1,1,1,1,1,1,1,3,3,3,3,3,1,1,1,1,1
1,1,1,1,1,1,1,1,1,1,1,1,3,3,3,1,1,1,1,1,1
1,1,1,1,1,1,1,1,1,1,1,1,1,1,1,1,1,1,1,1,1
1,1,1,1,1,1,1,1,1,1,1,1,1,1,1,1,1,1,1,1,1
1,1,1,1,1,1,1,1,1,1,1,1,1,1,1,1,1,1,1,1,1
endlayer

layer
1,1,1,1,1,1,1,1,1,1,1,1,1,1,1,1,1,1,1,1,1
1,1,1,1,1,1,1,1,1,1,1,1,1,1,1,1,1,1,1,1,1
1,1,1,1,1,1,1,1,1,1,1,1,1,1,1,1,1,1,1,1,1
1,1,1,1,1,1,1,1,1,1,1,1,1,36,1,1,1,1,1,1,1
1,1,1,1,1,1,1,1,1,1,1,1,3,3,3,1,1,1,1,1,1
1,1,1,1,1,1,1,1,1,1,1,3,3,3,3,3,1,1,1,1,1
1,1,1,1,1,1,1,1,1,1,22,3,3,3,3,3,37,1,1,1,1
1,1,1,1,1,1,1,1,1,1,1,3,3,3,3,3,1,1,1,1,1
1,1,1,1,1,1,1,1,1,1,1,1,3,3,3,1,1,1,1,1,1
1,1,1,1,1,1,1,1,1,1,1,1,1,13,1,1,1,1,1,1,1
1,1,1,1,1,1,1,1,1,1,1,1,1,1,1,1,1,1,1,1,1
1,1,1,1,1,1,1,1,1,1,1,1,1,1,1,1,1,1,1,1,1
1,1,1,1,1,1,1,1,1,1,1,1,1,1,1,1,1,1,1,1,1
endlayer

layer
1,1,1,1,1,1,1,1,1,1,1,1,1,1,1,1,1,1,1,1,1
1,1,1,1,1,1,1,1,1,1,1,1,1,1,1,1,1,1,1,1,1
1,1,1,1,1,1,1,1,1,1,1,1,1,1,1,1,1,1,1,1,1
1,1,1,1,1,1,1,1,1,1,1,1,1,1,1,1,1,1,1,1,1
1,1,1,1,1,1,1,1,1,1,1,1,36,3,36,1,1,1,1,1,1
1,1,1,1,1,1,1,1,1,1,1,22,3,3,3,37,1,1,1,1,1
1,1,1,1,1,1,1,1,1,1,1,3,3,3,3,3,1,1,1,1,1
1,1,1,1,1,1,1,1,1,1,1,22,3,3,3,37,1,1,1,1,1
1,1,1,1,1,1,1,1,1,1,1,1,13,3,13,1,1,1,1,1,1
1,1,1,1,1,1,1,1,1,1,1,1,1,1,1,1,1,1,1,1,1
1,1,1,1,1,1,1,1,1,1,1,1,1,1,1,1,1,1,1,1,1
1,1,1,1,1,1,1,1,1,1,1,1,1,1,1,1,1,1,1,1,1
1,1,1,1,1,1,1,1,1,1,1,1,1,1,1,1,1,1,1,1,1
endlayer

layer
1,1,1,1,1,1,1,1,1,1,1,1,1,1,1,1,1,1,1,1,1
1,1,1,1,1,1,1,1,1,1,1,1,1,1,1,1,1,1,1,1,1
1,1,1,1,1,1,1,1,1,1,1,1,1,1,1,1,1,1,1,1,1
1,1,1,1,1,1,1,1,1,1,1,1,1,1,1,1,1,1,1,1,1
1,1,1,1,1,1,1,1,1,1,1,1,1,36,1,1,1,1,1,1,1
1,1,1,1,1,1,1,1,1,1,1,1,3,3,3,1,1,1,1,1,1
1,1,1,1,1,1,1,1,1,1,1,22,3,3,3,37,1,1,1,1,1
1,1,1,1,1,1,1,1,1,1,1,1,3,3,3,1,1,1,1,1,1
1,1,1,1,1,1,1,1,1,1,1,1,1,13,1,1,1,1,1,1,1
1,1,1,1,1,1,1,1,1,1,1,1,1,1,1,1,1,1,1,1,1
1,1,1,1,1,1,1,1,1,1,1,1,1,1,1,1,1,1,1,1,1
1,1,1,1,1,1,1,1,1,1,1,1,1,1,1,1,1,1,1,1,1
1,1,1,1,1,1,1,1,1,1,1,1,1,1,1,1,1,1,1,1,1
endlayer

layer
1,1,1,1,1,1,1,1,1,1,1,1,1,1,1,1,1,1,1,1,1
1,1,1,1,1,1,1,1,1,1,1,1,1,1,1,1,1,1,1,1,1
1,1,1,1,1,1,1,1,1,1,1,1,1,1,1,1,1,1,1,1,1
1,1,1,1,1,1,1,1,1,1,1,1,1,1,1,1,1,1,1,1,1
1,1,1,1,1,1,1,1,1,1,1,1,1,1,1,1,1,1,1,1,1
1,1,1,1,1,1,1,1,1,1,1,1,38,3,38,1,1,1,1,1,1
1,1,1,1,1,1,1,1,1,1,1,1,3,3,3,1,1,1,1,1,1
1,1,1,1,1,1,1,1,1,1,1,1,38,3,38,1,1,1,1,1,1
1,1,1,1,1,1,1,1,1,1,1,1,1,1,1,1,1,1,1,1,1
1,1,1,1,1,1,1,1,1,1,1,1,1,1,1,1,1,1,1,1,1
1,1,1,1,1,1,1,1,1,1,1,1,1,1,1,1,1,1,1,1,1
1,1,1,1,1,1,1,1,1,1,1,1,1,1,1,1,1,1,1,1,1
1,1,1,1,1,1,1,1,1,1,1,1,1,1,1,1,1,1,1,1,1
endlayer

layer
1,1,1,1,1,1,1,1,1,1,1,1,1,1,1,1,1,1,1,1,1
1,1,1,1,1,1,1,1,1,1,1,1,1,1,1,1,1,1,1,1,1
1,1,1,1,1,1,1,1,1,1,1,1,1,1,1,1,1,1,1,1,1
1,1,1,1,1,1,1,1,1,1,1,1,1,1,1,1,1,1,1,1,1
1,1,1,1,1,1,1,1,1,1,1,1,1,1,1,1,1,1,1,1,1
1,1,1,1,1,1,1,1,1,1,1,1,1,36,1,1,1,1,1,1,1
1,1,1,1,1,1,1,1,1,1,1,1,22,3,37,1,1,1,1,1,1
1,1,1,1,1,1,1,1,1,1,1,1,1,13,1,1,1,1,1,1,1
1,1,1,1,1,1,1,1,1,1,1,1,1,1,1,1,1,1,1,1,1
1,1,1,1,1,1,1,1,1,1,1,1,1,1,1,1,1,1,1,1,1
1,1,1,1,1,1,1,1,1,1,1,1,1,1,1,1,1,1,1,1,1
1,1,1,1,1,1,1,1,1,1,1,1,1,1,1,1,1,1,1,1,1
1,1,1,1,1,1,1,1,1,1,1,1,1,1,1,1,1,1,1,1,1
endlayer

layer
1,1,1,1,1,1,1,1,1,1,1,1,1,1,1,1,1,1,1,1,1
1,1,1,1,1,1,1,1,1,1,1,1,1,1,1,1,1,1,1,1,1
1,1,1,1,1,1,1,1,1,1,1,1,1,1,1,1,1,1,1,1,1
1,1,1,1,1,1,1,1,1,1,1,1,1,1,1,1,1,1,1,1,1
1,1,1,1,1,1,1,1,1,1,1,1,1,1,1,1,1,1,1,1,1
1,1,1,1,1,1,1,1,1,1,1,1,1,1,1,1,1,1,1,1,1
1,1,1,1,1,1,1,1,1,1,1,1,1,3,1,1,1,1,1,1,1
1,1,1,1,1,1,1,1,1,1,1,1,1,1,1,1,1,1,1,1,1
1,1,1,1,1,1,1,1,1,1,1,1,1,1,1,1,1,1,1,1,1
1,1,1,1,1,1,1,1,1,1,1,1,1,1,1,1,1,1,1,1,1
1,1,1,1,1,1,1,1,1,1,1,1,1,1,1,1,1,1,1,1,1
1,1,1,1,1,1,1,1,1,1,1,1,1,1,1,1,1,1,1,1,1
1,1,1,1,1,1,1,1,1,1,1,1,1,1,1,1,1,1,1,1,1
endlayer

layer
1,1,1,1,1,1,1,1,1,1,1,1,1,1,1,1,1,1,1,1,1
1,1,1,1,1,1,1,1,1,1,1,1,1,1,1,1,1,1,1,1,1
1,1,1,1,1,1,1,1,1,1,1,1,1,1,1,1,1,1,1,1,1
1,1,1,1,1,1,1,1,1,1,1,1,1,1,1,1,1,1,1,1,1
1,1,1,1,1,1,1,1,1,1,1,1,1,1,1,1,1,1,1,1,1
1,1,1,1,1,1,1,1,1,1,1,1,1,1,1,1,1,1,1,1,1
1,1,1,1,1,1,1,1,1,1,1,1,1,3,1,1,1,1,1,1,1
1,1,1,1,1,1,1,1,1,1,1,1,1,1,1,1,1,1,1,1,1
1,1,1,1,1,1,1,1,1,1,1,1,1,1,1,1,1,1,1,1,1
1,1,1,1,1,1,1,1,1,1,1,1,1,1,1,1,1,1,1,1,1
1,1,1,1,1,1,1,1,1,1,1,1,1,1,1,1,1,1,1,1,1
1,1,1,1,1,1,1,1,1,1,1,1,1,1,1,1,1,1,1,1,1
1,1,1,1,1,1,1,1,1,1,1,1,1,1,1,1,1,1,1,1,1
endlayer

layer
1,0,0,0,0,0,0,0,0,0,0,0,0,0,0,0,0,0,0,0,0
1,0,0,0,0,0,0,0,0,0,0,0,0,0,0,0,0,0,0,0,0
1,0,0,0,0,0,0,0,0,0,0,0,0,0,0,0,0,0,0,0,0
1,0,0,0,0,0,0,0,0,0,0,0,0,0,0,0,0,0,0,0,0
1,0,0,0,0,0,0,0,0,0,0,0,0,0,0,0,0,0,0,0,0
1,0,0,0,0,0,0,0,0,0,0,0,0,0,0,0,0,0,0,0,0
1,0,0,0,0,0,0,0,0,0,0,0,0,0,0,0,0,0,0,0,0
1,0,0,0,0,0,0,0,0,0,0,0,0,0,0,0,0,0,0,0,0
1,0,0,0,0,0,0,0,0,0,0,0,0,0,0,0,0,0,0,0,0
1,0,0,0,0,0,0,0,0,0,0,0,0,0,0,0,0,0,0,0,0
1,0,0,0,0,0,0,0,0,0,0,0,0,0,0,0,0,0,0,0,0
1,0,0,0,0,0,0,0,0,0,0,0,0,0,0,0,0,0,0,0,0
1,0,0,0,0,0,0,0,0,0,0,0,0,0,0,0,0,0,0,0,0
endlayer

layer
1,0,0,0,0,0,0,0,0,0,0,0,0,0,0,0,0,0,0,0,0
1,0,0,0,0,0,0,0,0,0,0,0,0,0,0,0,0,0,0,0,0
1,0,0,0,0,0,0,0,0,0,0,0,0,0,0,0,0,0,0,0,0
1,0,0,0,0,0,0,0,0,0,0,0,0,0,0,0,0,0,0,0,0
1,0,0,0,0,0,0,0,0,0,0,0,0,0,0,0,0,0,0,0,0
1,0,0,0,0,0,0,0,0,0,0,0,0,0,0,0,0,0,0,0,0
1,0,0,0,0,0,0,0,0,0,0,0,0,0,0,0,0,0,0,0,0
1,0,0,0,0,0,0,0,0,0,0,0,0,0,0,0,0,0,0,0,0
1,0,0,0,0,0,0,0,0,0,0,0,0,0,0,0,0,0,0,0,0
1,0,0,0,0,0,0,0,0,0,0,0,0,0,0,0,0,0,0,0,0
1,0,0,0,0,0,0,0,0,0,0,0,0,0,0,0,0,0,0,0,0
1,0,0,0,0,0,0,0,0,0,0,0,0,0,0,0,0,0,0,0,0
1,0,0,0,0,0,0,0,0,0,0,0,0,0,0,0,0,0,0,0,0
endlayer

layer
1,0,0,0,0,0,0,0,0,0,0,0,0,0,0,0,0,0,0,0,0
1,0,0,0,0,0,0,0,0,0,0,0,0,0,0,0,0,0,0,0,0
1,0,0,0,0,0,0,0,0,0,0,0,0,0,0,0,0,0,0,0,0
1,0,0,0,0,0,0,0,0,0,0,0,0,0,0,0,0,0,0,0,0
1,0,0,0,0,0,0,0,0,0,0,0,0,0,0,0,0,0,0,0,0
1,0,0,0,0,0,0,0,0,0,0,0,0,0,0,0,0,0,0,0,0
1,0,0,0,0,0,0,0,0,0,0,0,0,0,0,0,0,0,0,0,0
1,0,0,0,0,0,0,0,0,0,0,0,0,0,0,0,0,0,0,0,0
1,0,0,0,0,0,0,0,0,0,0,0,0,0,0,0,0,0,0,0,0
1,0,0,0,0,0,0,0,0,0,0,0,0,0,0,0,0,0,0,0,0
1,0,0,0,0,0,0,0,0,0,0,0,0,0,0,0,0,0,0,0,0
1,0,0,0,0,0,0,0,0,0,0,0,0,0,0,0,0,0,0,0,0
1,0,0,0,0,0,0,0,0,0,0,0,0,0,0,0,0,0,0,0,0
endlayer

layer
1,0,0,0,0,0,0,0,0,0,0,0,0,0,0,0,0,0,0,0,0
1,0,0,0,0,0,0,0,0,0,0,0,0,0,0,0,0,0,0,0,0
1,0,0,0,0,0,0,0,0,0,0,0,0,0,0,0,0,0,0,0,0
1,0,0,0,0,0,0,0,0,0,0,0,0,0,0,0,0,0,0,0,0
1,0,0,0,0,0,0,0,0,0,0,0,0,0,0,0,0,0,0,0,0
1,0,0,0,0,0,0,0,0,0,0,0,0,0,0,0,0,0,0,0,0
1,0,0,0,0,0,0,0,0,0,0,0,0,0,0,0,0,0,0,0,0
1,0,0,0,0,0,0,0,0,0,0,0,0,0,0,0,0,0,0,0,0
1,0,0,0,0,0,0,0,0,0,0,0,0,0,0,0,0,0,0,0,0
1,0,0,0,0,0,0,0,0,0,0,0,0,0,0,0,0,0,0,0,0
1,0,0,0,0,0,0,0,0,0,0,0,0,0,0,0,0,0,0,0,0
1,0,0,0,0,0,0,0,0,0,0,0,0,0,0,0,0,0,0,0,0
1,0,0,0,0,0,0,0,0,0,0,0,0,0,0,0,0,0,0,0,0
endlayer

layer
1,0,0,0,0,0,0,0,0,0,0,0,0,0,0,0,0,0,0,0,0
1,0,0,0,0,0,0,0,0,0,0,0,0,0,0,0,0,0,0,0,0
1,0,0,0,0,0,0,0,0,0,0,0,0,0,0,0,0,0,0,0,0
1,0,0,0,0,0,0,0,0,0,0,0,0,0,0,0,0,0,0,0,0
1,0,0,0,0,0,0,0,0,0,0,0,0,0,0,0,0,0,0,0,0
1,0,0,0,0,0,0,0,0,0,0,0,0,0,0,0,0,0,0,0,0
1,0,0,0,0,0,0,0,0,0,0,0,0,0,0,0,0,0,0,0,0
1,0,0,0,0,0,0,0,0,0,0,0,0,0,0,0,0,0,0,0,0
1,0,0,0,0,0,0,0,0,0,0,0,0,0,0,0,0,0,0,0,0
1,0,0,0,0,0,0,0,0,0,0,0,0,0,0,0,0,0,0,0,0
1,0,0,0,0,0,0,0,0,0,0,0,0,0,0,0,0,0,0,0,0
1,0,0,0,0,0,0,0,0,0,0,0,0,0,0,0,0,0,0,0,0
1,0,0,0,0,0,0,0,0,0,0,0,0,0,0,0,0,0,0,0,0
endlayer

layer
1,0,0,0,0,0,0,0,0,0,0,0,0,0,0,0,0,0,0,0,0
1,0,0,0,0,0,0,0,0,0,0,0,0,0,0,0,0,0,0,0,0
1,0,0,0,0,0,0,0,0,0,0,0,0,0,0,0,0,0,0,0,0
1,0,0,0,0,0,0,0,0,0,0,0,0,0,0,0,0,0,0,0,0
1,0,0,0,0,0,0,0,0,0,0,0,0,0,0,0,0,0,0,0,0
1,0,0,0,0,0,0,0,0,0,0,0,0,0,0,0,0,0,0,0,0
1,0,0,0,0,0,0,0,0,0,0,0,0,0,0,0,0,0,0,0,0
1,0,0,0,0,0,0,0,0,0,0,0,0,0,0,0,0,0,0,0,0
1,0,0,0,0,0,0,0,0,0,0,0,0,0,0,0,0,0,0,0,0
1,0,0,0,0,0,0,0,0,0,0,0,0,0,0,0,0,0,0,0,0
1,0,0,0,0,0,0,0,0,0,0,0,0,0,0,0,0,0,0,0,0
1,0,0,0,0,0,0,0,0,0,0,0,0,0,0,0,0,0,0,0,0
1,0,0,0,0,0,0,0,0,0,0,0,0,0,0,0,0,0,0,0,0
endlayer

