
# Created by Ruins mod version 17.0 Ingame Parser
# authoring Player: ST753M

weight=1
uniqueMinDistance=1000
spawnMinDistance=1000
embed_into_distance=5
acceptable_target_blocks=
unacceptable_target_blocks=flowing_water,water,flowing_lava,lava,ice,bedrock,netherrack,nether_brick,nether_brick_fence,soul_sand,quartz_ore,end_stone,obsidian,iron_bars,Natura:Cloud,slime_grass,slime_congealed,slime_dirt,clouds,natura:clouds,twilightforest:wispy_cloud,twilightforest:fluffy_cloud
dimensions=28,11,11
allowable_overhang=5
max_leveling=0
leveling_buffer=-1
preserve_water=0
preserve_lava=0
preventRotation=1

=0,100,air
rule1=0,100,preserveBlock
rule2=0,100,minecraft:stonebrick-0
rule3=0,100,minecraft:concrete-14
rule4=0,100,minecraft:nether_brick-0
rule5=0,100,minecraft:stone_brick_stairs-0
rule6=0,100,minecraft:stone_brick_stairs-2
rule7=0,100,minecraft:stone_brick_stairs-3
rule8=0,100,thaumcraft:loot_urn_common-0
rule9=0,100,thaumcraft:loot_crate_common-0
rule10=0,100,minecraft:bed-10
rule11=0,100,minecraft:bed-2
rule12=0,100,thaumcraft:table_wood-0
rule13=0,100,minecraft:nether_brick_stairs-4
rule14=0,100,minecraft:nether_brick_stairs-2
rule15=0,100,minecraft:stone_brick_stairs-1
rule16=0,100,thaumcraft:candle_red-0,air
rule17=0,100,minecraft:nether_brick_stairs-1
rule18=0,100,minecraft:stone_brick_stairs-4
rule19=0,100,minecraft:stone_brick_stairs-6
rule20=0,100,minecraft:stone_brick_stairs-7
rule21=0,100,minecraft:stone_brick_stairs-5
rule22=0,100,minecraft:nether_brick_stairs-0
rule23=0,100,minecraft:nether_brick_stairs-3
rule24=0,100,minecraft:stained_glass_pane-14
rule25=0,50,thaumcraft:nitor_red-0
rule26=0,100,teBlock;thaumcraft:banner_crimson_cult;{aspect:"",x:17457,y:95,facing:4b,z:19903,id:"thaumcraft:tilebanner",wall:1b}-0
rule27=0,100,teBlock;thaumcraft:banner_crimson_cult;{aspect:"",x:17457,y:95,facing:4b,z:19907,id:"thaumcraft:tilebanner",wall:1b}-0
rule28=0,100,teBlock;thaumcraft:banner_crimson_cult;{aspect:"",x:17460,y:95,facing:8b,z:19900,id:"thaumcraft:tilebanner",wall:1b}-0
rule29=0,100,teBlock;thaumcraft:banner_crimson_cult;{aspect:"",x:17460,y:95,facing:0b,z:19910,id:"thaumcraft:tilebanner",wall:1b}-0
rule30=0,100,teBlock;thaumcraft:banner_crimson_cult;{aspect:"",x:17464,y:95,facing:8b,z:19900,id:"thaumcraft:tilebanner",wall:1b}-0
rule31=0,100,teBlock;thaumcraft:banner_crimson_cult;{aspect:"",x:17464,y:95,facing:0b,z:19910,id:"thaumcraft:tilebanner",wall:1b}-0
rule32=0,100,teBlock;thaumcraft:banner_crimson_cult;{aspect:"",x:17467,y:95,facing:12b,z:19903,id:"thaumcraft:tilebanner",wall:1b}-0
rule33=0,100,teBlock;thaumcraft:banner_crimson_cult;{aspect:"",x:17467,y:95,facing:12b,z:19907,id:"thaumcraft:tilebanner",wall:1b}-0
rule34=0,100,minecraft:nether_brick_stairs-7
rule35=0,100,minecraft:nether_brick_stairs-5
rule36=0,100,minecraft:nether_brick_stairs-6
rule37=0,100,minecraft:stone_slab-6

layer
1,1,1,1,2,2,2,1,1,1,1
1,2,2,2,2,2,2,2,2,2,1
1,2,2,2,2,2,2,2,2,2,1
1,2,2,2,2,2,2,2,2,2,1
2,2,2,2,2,2,2,2,2,2,2
2,2,2,2,2,2,2,2,2,2,2
2,2,2,2,2,2,2,2,2,2,2
1,2,2,2,2,2,2,2,2,2,1
1,2,2,2,2,2,2,2,2,2,1
1,2,2,2,2,2,2,2,2,2,1
1,1,1,1,2,2,2,1,1,1,1
endlayer

layer
1,1,1,1,3,4,3,1,1,1,1
1,4,3,4,2,2,2,4,3,4,1
1,3,2,2,2,2,2,2,2,3,1
1,4,2,2,2,2,2,2,2,4,1
3,2,2,2,2,2,2,2,2,2,3
4,2,2,2,2,2,2,2,2,2,4
3,2,2,2,2,2,2,2,2,2,3
1,4,2,2,2,2,2,2,2,4,1
1,3,2,2,2,2,2,2,2,3,1
1,4,3,4,2,2,2,4,3,4,1
1,1,1,1,3,4,3,1,1,1,1
endlayer

layer
1,1,1,1,4,3,4,1,1,1,1
1,3,4,3,2,2,2,3,4,3,1
1,4,2,2,2,2,2,2,2,4,1
1,3,2,2,2,2,2,2,2,3,1
4,2,2,2,2,2,2,2,2,2,4
3,2,2,2,2,2,2,2,2,2,3
4,2,2,2,2,2,2,2,2,2,4
1,3,2,2,2,2,2,2,2,3,1
1,4,2,2,2,2,2,2,2,4,1
1,3,4,3,2,2,2,3,4,3,1
1,1,1,1,4,3,4,1,1,1,1
endlayer

layer
2,2,2,2,2,2,2,2,2,2,2
2,2,2,2,2,2,2,2,2,2,2
2,2,2,2,2,2,2,2,2,2,2
2,2,2,2,2,2,2,2,2,2,2
2,2,2,2,2,2,2,2,2,2,2
2,2,2,2,2,2,2,2,2,2,2
2,2,2,2,2,2,2,2,2,2,2
2,2,2,2,2,2,2,2,2,2,2
2,2,2,2,2,2,2,2,2,2,2
2,2,2,2,2,2,2,2,2,2,2
2,2,2,2,2,2,2,2,2,2,2
endlayer

layer
4,4,4,4,4,4,4,4,4,4,4
4,4,4,4,2,2,2,4,4,4,4
4,4,2,2,2,2,2,2,2,4,4
4,4,2,2,2,2,2,2,2,4,4
4,2,2,2,2,2,2,2,2,2,4
4,2,2,2,2,2,2,2,2,2,4
4,2,2,2,2,2,2,2,2,2,4
4,4,2,2,2,2,2,2,2,4,4
4,4,2,2,2,2,2,2,2,4,4
4,4,4,4,2,2,2,4,4,4,4
4,4,4,4,4,4,4,4,4,4,4
endlayer

layer
2,2,2,2,4,4,4,2,2,2,2
2,2,2,2,2,2,2,2,2,2,2
2,2,2,2,4,4,4,2,2,2,2
2,2,2,4,4,4,4,4,2,2,2
4,2,2,4,4,4,4,4,4,2,4
4,2,2,4,4,4,4,4,4,2,4
4,2,2,4,4,4,4,4,4,2,4
2,2,2,4,4,4,4,4,2,2,2
2,2,2,2,4,4,4,2,2,2,2
2,2,2,2,2,2,2,2,2,2,2
2,2,2,2,4,4,4,2,2,2,2
endlayer

layer
1,5,1,1,4,5,4,1,1,5,1
7,2,1,5,4,2,4,5,1,2,6
1,1,3,2,0,0,8,2,3,1,1
1,7,2,0,0,9,0,0,2,6,1
4,4,4,8,0,0,0,11,10,4,4
7,2,2,0,0,0,0,0,0,2,6
4,4,4,13,0,0,0,0,12,4,4
1,7,2,14,0,0,0,0,2,6,1
1,1,3,2,0,0,9,2,3,1,1
7,2,1,15,4,2,4,15,1,2,6
1,15,1,1,4,15,4,1,1,15,1
endlayer

layer
1,1,1,1,4,1,4,1,1,1,1
1,2,1,1,4,2,4,1,1,2,1
1,1,3,2,0,0,0,2,3,1,1
1,1,2,0,0,0,0,0,2,1,1
4,4,4,0,0,0,0,0,0,4,4
0,2,2,13,0,0,0,0,0,2,1
4,4,4,17,0,0,0,0,16,4,4
1,1,2,0,0,0,0,0,2,1,1
1,1,3,2,0,0,0,2,3,1,1
1,2,1,1,4,2,4,1,1,2,1
1,1,1,1,4,1,4,1,1,1,1
endlayer

layer
1,1,1,1,4,1,4,1,1,1,1
1,2,1,1,4,2,4,1,1,2,0
1,1,3,2,0,0,0,2,3,0,0
1,1,2,0,0,0,0,0,2,1,1
4,4,4,13,0,0,0,0,0,4,4
0,2,2,17,0,0,0,0,0,2,1
4,4,4,0,0,0,0,0,0,4,4
1,1,2,0,0,0,0,0,2,1,1
1,1,3,2,0,0,0,2,3,1,1
1,2,1,1,4,2,4,1,1,2,1
1,1,1,1,4,1,4,1,1,1,1
endlayer

layer
1,18,1,1,4,18,4,1,1,18,1
20,2,1,18,4,2,4,18,1,2,19
1,1,3,2,0,0,0,2,3,1,1
1,20,2,13,0,0,0,0,2,19,1
4,4,4,17,0,0,0,0,0,4,4
20,2,2,0,0,0,0,0,0,2,19
4,4,4,0,0,0,0,0,0,4,4
1,20,2,0,0,0,0,0,2,19,1
1,1,3,2,0,0,0,2,3,1,1
20,2,1,21,4,2,4,21,1,2,19
1,21,1,1,4,21,4,1,1,21,1
endlayer

layer
22,22,22,4,4,4,4,4,22,22,14
23,4,4,4,2,2,2,4,4,4,14
23,4,4,4,4,4,4,4,4,4,14
4,4,4,17,4,4,4,4,4,4,4
4,2,4,0,4,4,4,4,4,2,4
4,2,4,0,4,4,4,4,4,2,4
4,2,4,0,4,4,4,4,4,2,4
4,4,4,13,4,4,4,4,4,4,4
23,4,4,4,4,4,4,4,4,4,14
23,4,4,4,2,2,2,4,4,4,14
23,17,17,4,4,4,4,4,17,17,17
endlayer

layer
0,0,0,5,0,0,0,5,0,0,0
0,0,0,2,6,0,7,2,6,0,0
0,0,3,2,4,4,4,2,3,5,0
7,2,2,0,0,0,0,0,2,2,6
0,15,4,0,0,0,12,0,4,15,0
0,0,4,0,0,0,0,0,4,0,0
0,5,4,0,0,0,0,0,4,5,0
7,2,2,9,0,0,0,0,2,2,6
0,15,3,2,4,4,4,2,3,15,0
0,0,7,2,6,0,7,2,6,0,0
0,0,0,15,0,0,0,15,0,0,0
endlayer

layer
0,0,0,0,0,0,0,0,0,0,0
0,0,0,2,0,0,0,2,0,0,0
0,0,3,2,4,24,4,2,3,0,0
0,2,2,0,0,0,0,0,2,2,0
0,0,4,0,0,0,0,0,4,0,0
0,0,24,0,0,0,0,0,24,0,0
0,0,4,0,0,0,0,0,4,0,0
0,2,2,0,0,0,0,0,2,2,0
0,0,3,2,4,24,4,2,3,0,0
0,0,0,2,0,0,0,2,0,0,0
0,0,0,0,0,0,0,0,0,0,0
endlayer

layer
0,0,0,0,0,0,0,0,0,0,0
0,0,0,2,0,0,0,2,0,0,0
0,0,3,2,24,24,24,2,3,0,0
0,2,2,0,0,0,0,0,2,2,0
0,0,24,0,0,0,0,0,24,0,0
0,0,24,0,0,0,0,0,24,0,0
0,0,24,0,0,0,0,0,24,0,0
0,2,2,0,0,0,0,0,2,2,0
0,0,3,2,24,24,24,2,3,0,0
0,0,0,2,0,0,0,2,0,0,0
0,0,0,0,0,0,0,0,0,0,0
endlayer

layer
0,0,0,0,0,0,0,0,0,0,0
0,0,0,2,0,0,0,2,0,0,0
0,0,3,2,24,24,24,2,3,0,0
0,2,2,0,0,0,0,0,2,2,0
0,0,24,0,0,0,0,0,24,0,0
0,0,24,0,0,25,0,0,24,0,0
0,0,24,0,0,0,0,0,24,0,0
0,2,2,0,0,0,0,0,2,2,0
0,0,3,2,24,24,24,2,3,0,0
0,0,0,2,0,0,0,2,0,0,0
0,0,0,0,0,0,0,0,0,0,0
endlayer

layer
0,0,0,27,0,0,0,26,0,0,0
0,0,0,2,0,0,0,2,0,0,0
0,0,3,2,4,24,4,2,3,0,0
29,2,2,0,0,0,0,0,2,2,28
0,0,4,0,0,0,0,0,4,0,0
0,0,24,0,0,0,0,0,24,0,0
0,0,4,0,0,0,0,0,4,0,0
31,2,2,0,0,0,0,0,2,2,30
0,0,3,2,4,24,4,2,3,0,0
0,0,0,2,0,0,0,2,0,0,0
0,0,0,33,0,0,0,32,0,0,0
endlayer

layer
0,0,0,18,0,0,0,18,0,0,0
0,0,0,2,19,0,20,2,19,0,0
0,0,3,2,4,4,4,2,3,18,0
20,2,2,0,0,0,0,0,2,2,19
0,21,4,0,0,0,0,0,4,21,0
0,0,4,0,0,0,0,0,4,0,0
0,18,4,0,0,0,0,0,4,18,0
20,2,2,0,0,0,0,0,2,2,19
0,21,3,2,4,4,4,2,3,21,0
0,0,20,2,19,0,20,2,19,0,0
0,0,0,21,0,0,0,21,0,0,0
endlayer

layer
0,18,0,2,0,18,0,2,0,18,0
20,2,2,2,2,2,2,2,2,2,19
0,2,2,2,2,2,2,2,2,2,0
2,2,2,0,0,0,0,0,2,2,2
0,2,2,0,0,0,0,0,2,2,0
20,2,2,0,0,0,0,0,2,2,19
0,2,2,0,0,0,0,0,2,2,0
2,2,2,0,0,0,0,0,2,2,2
0,2,2,2,2,2,2,2,2,2,0
20,2,2,2,2,2,2,2,2,2,19
0,21,0,2,0,21,0,2,0,21,0
endlayer

layer
0,15,0,15,0,15,0,15,0,15,0
6,4,4,4,4,4,4,4,4,4,7
0,4,4,4,4,4,4,4,4,4,0
6,4,4,35,35,35,35,34,4,4,7
0,4,4,36,0,0,0,34,4,4,0
6,4,4,36,0,0,0,34,4,4,7
0,4,4,36,0,0,0,34,4,4,0
6,4,4,13,13,13,13,34,4,4,7
0,4,4,4,4,4,4,4,4,4,0
6,4,4,4,4,4,4,4,4,4,7
0,5,0,5,0,5,0,5,0,5,0
endlayer

layer
0,0,0,0,0,0,0,0,0,0,0
0,0,4,4,4,4,4,4,4,0,0
0,4,4,4,4,4,4,4,4,4,0
0,4,4,4,4,4,4,4,4,4,0
0,4,4,4,35,35,34,4,4,4,0
0,4,4,4,36,0,34,4,4,4,0
0,4,4,4,13,13,13,4,4,4,0
0,4,4,4,4,4,4,4,4,4,0
0,4,4,4,4,4,4,4,4,4,0
0,0,4,4,4,4,4,4,4,0,0
0,0,0,0,0,0,0,0,0,0,0
endlayer

layer
0,0,0,0,0,0,0,0,0,0,0
0,0,0,37,4,4,4,37,0,0,0
0,0,4,4,4,4,4,4,4,0,0
0,37,4,4,4,4,4,4,4,37,0
0,4,4,4,4,4,4,4,4,4,0
0,4,4,4,4,4,4,4,4,4,0
0,4,4,4,4,4,4,4,4,4,0
0,37,4,4,4,4,4,4,4,37,0
0,0,4,4,4,4,4,4,4,0,0
0,0,0,37,4,4,4,37,0,0,0
0,0,0,0,0,0,0,0,0,0,0
endlayer

layer
0,0,0,0,0,0,0,0,0,0,0
0,0,0,0,0,37,0,0,0,0,0
0,0,0,4,4,4,4,4,0,0,0
0,0,4,4,4,4,4,4,4,0,0
0,0,4,4,4,4,4,4,4,0,0
0,37,4,4,4,4,4,4,4,37,0
0,0,4,4,4,4,4,4,4,0,0
0,0,4,4,4,4,4,4,4,0,0
0,0,0,4,4,4,4,4,0,0,0
0,0,0,0,0,37,0,0,0,0,0
0,0,0,0,0,0,0,0,0,0,0
endlayer

layer
0,0,0,0,0,0,0,0,0,0,0
0,0,0,0,0,0,0,0,0,0,0
0,0,0,0,37,22,37,0,0,0,0
0,0,0,4,4,4,4,4,0,0,0
0,0,37,4,4,4,4,4,37,0,0
0,0,23,4,4,4,4,4,14,0,0
0,0,37,4,4,4,4,4,37,0,0
0,0,0,4,4,4,4,4,0,0,0
0,0,0,0,37,17,37,0,0,0,0
0,0,0,0,0,0,0,0,0,0,0
0,0,0,0,0,0,0,0,0,0,0
endlayer

layer
0,0,0,0,0,0,0,0,0,0,0
0,0,0,0,0,0,0,0,0,0,0
0,0,0,0,0,0,0,0,0,0,0
0,0,0,0,4,4,4,0,0,0,0
0,0,0,4,4,4,4,4,0,0,0
0,0,0,4,4,4,4,4,0,0,0
0,0,0,4,4,4,4,4,0,0,0
0,0,0,0,4,4,4,0,0,0,0
0,0,0,0,0,0,0,0,0,0,0
0,0,0,0,0,0,0,0,0,0,0
0,0,0,0,0,0,0,0,0,0,0
endlayer

layer
0,0,0,0,0,0,0,0,0,0,0
0,0,0,0,0,0,0,0,0,0,0
0,0,0,0,0,0,0,0,0,0,0
0,0,0,0,0,22,0,0,0,0,0
0,0,0,0,4,4,4,0,0,0,0
0,0,0,23,4,4,4,14,0,0,0
0,0,0,0,4,4,4,0,0,0,0
0,0,0,0,0,17,0,0,0,0,0
0,0,0,0,0,0,0,0,0,0,0
0,0,0,0,0,0,0,0,0,0,0
0,0,0,0,0,0,0,0,0,0,0
endlayer

layer
0,0,0,0,0,0,0,0,0,0,0
0,0,0,0,0,0,0,0,0,0,0
0,0,0,0,0,0,0,0,0,0,0
0,0,0,0,0,0,0,0,0,0,0
0,0,0,0,37,4,37,0,0,0,0
0,0,0,0,4,4,4,0,0,0,0
0,0,0,0,37,4,37,0,0,0,0
0,0,0,0,0,0,0,0,0,0,0
0,0,0,0,0,0,0,0,0,0,0
0,0,0,0,0,0,0,0,0,0,0
0,0,0,0,0,0,0,0,0,0,0
endlayer

layer
0,0,0,0,0,0,0,0,0,0,0
0,0,0,0,0,0,0,0,0,0,0
0,0,0,0,0,0,0,0,0,0,0
0,0,0,0,0,0,0,0,0,0,0
0,0,0,0,0,22,0,0,0,0,0
0,0,0,0,23,4,14,0,0,0,0
0,0,0,0,0,17,0,0,0,0,0
0,0,0,0,0,0,0,0,0,0,0
0,0,0,0,0,0,0,0,0,0,0
0,0,0,0,0,0,0,0,0,0,0
0,0,0,0,0,0,0,0,0,0,0
endlayer

layer
0,0,0,0,0,0,0,0,0,0,0
0,0,0,0,0,0,0,0,0,0,0
0,0,0,0,0,0,0,0,0,0,0
0,0,0,0,0,0,0,0,0,0,0
0,0,0,0,0,0,0,0,0,0,0
0,0,0,0,0,4,0,0,0,0,0
0,0,0,0,0,0,0,0,0,0,0
0,0,0,0,0,0,0,0,0,0,0
0,0,0,0,0,0,0,0,0,0,0
0,0,0,0,0,0,0,0,0,0,0
0,0,0,0,0,0,0,0,0,0,0
endlayer

