
# Created by Ruins mod version 17.0 Ingame Parser
# authoring Player: ST753M

weight=1
embed_into_distance=13
acceptable_target_blocks=
unacceptable_target_blocks=flowing_water,water,flowing_lava,lava,ice,bedrock,netherrack,nether_brick,nether_brick_fence,soul_sand,quartz_ore,end_stone,obsidian,iron_bars,Natura:Cloud,slime_grass,slime_congealed,slime_dirt,clouds,natura:clouds
dimensions=13,11,16
allowable_overhang=8
max_leveling=0
leveling_buffer=0
preserve_water=0
preserve_lava=0
preventRotation=1

biomesToSpawnIn=dead_swamp,coralium_infested_swamp,forest,maple_woods,boreal_forest,forest_hills,woodland,seasonal_forest,temperate_rainforest,fen,grove,sacred_springs,land_of_lakes,forested_hills,lush_hills,thicket,birch_forest,birch_forest_hills,mutated_birch_forest,mutated_birch_forest_hills,birch_forested_hills,taiga,taiga_hills,mutated_redwood_taiga,mutated_redwood_taiga_hills,redwood_taiga,mutated_taiga,redwood_taiga_hills,redwood_forest,coniferous_forest,shield,dead_forest,autumnal_wooded_hills,autumnal_woods,extreme_hills,smaller_extreme_hills,mutated_extreme_hills,mutated_extreme_hills_with_trees,extreme_hills_with_trees,highland,alps,alps_foothills,mountain,mountain_foothills,crag,cliffs,savanna,savanna_rock,mutated_savanna,mutated_savanna_rock,brushland,steppe,wasteland,tundra,outback,badlands,desert_shrubland,arid_highland,mesa,mesa_clear_rock,mesa_rock,mutated_mesa,mutated_mesa_clear_rock,mutated_mesa_rock,lush_desert,darklands,darklands_forest,darklands_hills,darklands_mountains,darklands_plains,ominous_woods,eerie

rule1=0,100,minecraft:concrete-7
rule2=0,100,minecraft:stonebrick-0
rule3=0,100,minecraft:stone_brick_stairs-2
rule4=0,100,minecraft:bed-9
rule5=0,100,rustic:table_spruce-0
rule6=0,100,minecraft:bed-1
rule7=0,100,rustic:iron_lattice-0
rule8=0,100,rustic:barrel-0
rule9=0,100,rustic:chair_spruce-2
rule10=0,100,minecraft:wooden_slab-8
rule11=0,100,rustic:iron_lantern-1
rule12=0,100,IInventory;minecraft:chest;minecraft:air#0#0#4+minecraft:air#0#0#9+minecraft:air#0#0#12+minecraft:bone#2#0#14+minecraft:air#0#0#18+minecraft:air#0#0#19+rustic:elixir#{ElixirEffects:[{Effect:"rustic:ironskin",Duration:9600,Amplifier:0}]}#0#20+minecraft:air#0#0#25-5
rule13=0,100,IInventory;minecraft:trapped_chest;rustic:rope#3#0#3+rustic:fluid_bottle#{Fluid:{FluidName:"honey",Amount:1000}}#0#11+rustic:rope#4#0#15+rustic:rope#4#0#18+rustic:rope#4#0#23+rustic:rope#2#0#25-5
rule14=0,100,IInventory;minecraft:chest;minecraft:air#0#0#0+minecraft:log#2#0#1+minecraft:air#0#0#3+rustic:chain#4#0#5+minecraft:air#0#0#6+rustic:chain#3#0#7+minecraft:log#1#0#9+minecraft:log#3#0#10+minecraft:air#0#0#11+rustic:fluid_bottle#{Fluid:{FluidName:"honey",Amount:1000}}#0#12+rustic:chain#2#0#15+minecraft:air#0#0#17+minecraft:log#3#0#18+minecraft:log#2#0#20+rustic:fluid_bottle#{Fluid:{FluidName:"honey",Amount:1000}}#0#22+minecraft:air#0#0#25+minecraft:air#0#0#26-5
rule15=0,100,minecraft:stone_brick_stairs-1
rule16=0,100,minecraft:stone_brick_stairs-0
rule17=0,100,minecraft:quartz_stairs-6
rule18=0,100,minecraft:quartz_block-2
rule19=0,100,minecraft:quartz_stairs-7


rule20=0,100,rustic:brewing_barrel-2


rule21=0,100,rustic:vase-0


rule22=0,100,rustic:brewing_barrel-1


rule23=0,100,IInventory;minecraft:trapped_chest;rustic:elixir#{ElixirEffects:[{Effect:"rustic:blazing_trail",Duration:3600,Amplifier:0}]}#0#10+rustic:book#1#0#13-5
rule24=0,100,IInventory;minecraft:chest;minecraft:air#0#0#1+minecraft:air#0#0#2+minecraft:rabbit_hide#3#0#6+minecraft:air#0#0#7+minecraft:air#0#0#10+rustic:fluid_bottle#{Fluid:{FluidName:"wine",Amount:1000,Tag:{Quality:0.55f}}}#0#13+rustic:chili_pepper_seeds#1#0#16+minecraft:rabbit_hide#5#0#19+minecraft:air#0#0#22+rustic:fluid_bottle#{Fluid:{FluidName:"wine",Amount:1000,Tag:{Quality:0.43f}}}#0#23+minecraft:air#0#0#24+minecraft:air#0#0#26-5
rule25=0,100,IInventory;minecraft:trapped_chest;rustic:fluid_bottle#{Fluid:{FluidName:"honey",Amount:1000}}#0#5+minecraft:pumpkin_seeds#2#0#11+minecraft:rabbit_hide#8#0#13+rustic:fluid_bottle#{Fluid:{FluidName:"honey",Amount:1000}}#0#24-5
rule26=0,100,minecraft:lever-10
rule27=0,100,minecraft:quartz_block-4
rule28=0,100,minecraft:quartz_block-3
rule29=0,100,minecraft:lever-9
rule30=0,100,minecraft:bookshelf-0
rule31=0,100,minecraft:stone_brick_stairs-5
rule32=0,100,minecraft:stone_brick_stairs-4
rule33=0,100,minecraft:quartz_stairs-2
rule34=0,100,minecraft:quartz_stairs-3
rule35=0,100,preserveBlock
rule36=0,100,minecraft:stone_brick_stairs-3
rule37=0,100,MobSpawner:zombie,MobSpawner:skeleton,air,air

layer
1,1,1,1,1,1,1,1,1,1,1,1,1,1,1,1
1,2,2,2,2,2,1,2,2,2,2,2,2,2,2,1
1,2,2,2,2,2,1,2,2,2,2,2,2,2,2,1
1,2,2,2,2,2,1,1,1,1,1,2,2,2,2,1
1,2,2,2,2,2,2,2,2,2,1,2,2,2,2,1
1,2,2,2,2,2,2,2,2,2,1,2,2,2,2,1
1,2,2,2,2,2,2,2,2,2,1,2,2,2,2,1
1,2,2,2,2,2,2,2,2,2,1,2,2,2,2,1
1,2,2,2,2,2,2,2,2,2,1,2,2,2,2,1
1,2,2,2,2,2,2,2,2,1,1,2,2,2,2,1
1,1,1,1,1,1,1,1,1,1,1,1,1,1,1,1
endlayer

layer
1,2,2,2,2,2,2,2,2,2,1,2,2,2,2,1
2,4,5,5,4,2,2,2,2,2,3,0,0,0,0,2
2,6,0,0,6,2,2,2,2,2,3,0,0,0,0,2
1,7,0,0,7,1,2,2,2,2,1,7,7,0,7,2
2,8,0,0,0,0,5,5,5,0,2,0,0,0,0,2
2,1,9,0,0,0,0,0,0,7,2,0,0,0,0,2
2,10,0,0,0,0,0,0,0,0,2,0,0,0,0,2
2,10,0,0,0,0,0,0,0,7,2,0,0,0,0,2
2,10,8,0,0,0,0,0,0,0,2,0,0,0,0,2
2,1,10,10,10,1,10,10,10,1,2,0,0,0,0,2
1,2,2,2,2,2,2,2,2,2,1,2,2,2,2,1
endlayer

layer
1,2,2,2,2,2,2,2,2,2,1,2,2,2,2,1
2,0,11,0,0,2,2,2,2,3,0,0,0,0,0,2
2,0,0,0,0,2,2,2,2,3,0,0,0,0,0,2
1,7,0,0,7,1,2,2,2,2,1,7,7,0,7,2
2,0,0,0,0,0,14,13,12,7,2,0,0,0,0,2
2,1,0,0,0,0,0,0,0,0,15,0,0,0,0,2
2,10,0,0,0,0,0,0,0,0,0,0,0,0,0,2
2,10,0,0,0,0,0,0,0,0,16,0,0,0,0,2
2,10,0,0,0,0,0,0,0,7,2,19,18,17,0,2
2,1,22,22,21,1,20,20,10,1,2,0,0,0,0,2
1,2,2,2,2,2,2,2,2,2,1,2,2,2,2,1
endlayer

layer
1,2,2,2,2,2,2,2,2,2,1,2,2,2,2,1
2,0,0,0,0,2,2,2,3,0,0,0,0,0,0,2
2,0,0,0,0,2,2,2,3,0,0,0,0,0,0,2
1,7,0,0,7,1,2,2,2,2,1,7,7,7,7,2
2,0,0,0,0,0,25,24,23,0,2,0,0,0,0,2
2,1,0,0,0,0,0,0,0,0,0,0,0,0,0,2
2,10,0,0,0,0,0,0,0,0,0,0,0,0,0,2
2,10,0,0,0,0,0,0,0,0,0,0,0,26,0,2
2,10,0,0,0,0,0,0,0,0,2,27,28,27,0,2
2,1,22,0,0,1,10,10,10,1,2,0,37,29,0,2
1,2,2,2,2,2,2,2,2,2,1,2,2,2,2,1
endlayer

layer
1,2,2,2,2,2,2,2,2,2,1,2,2,2,2,1
2,30,30,30,30,2,2,3,0,0,0,0,0,0,0,2
2,0,0,0,0,2,2,3,0,0,0,0,0,0,0,2
1,7,0,0,7,1,2,2,2,2,1,7,7,7,7,2
2,0,0,0,0,0,0,0,0,7,2,0,0,0,0,2
2,1,0,0,0,0,0,0,0,0,31,0,0,0,0,2
2,10,0,0,0,0,0,0,0,0,0,0,0,0,0,2
2,10,0,0,0,0,0,0,0,0,32,0,0,0,0,2
2,10,0,0,0,0,0,0,0,7,2,34,18,33,0,2
2,1,10,10,10,1,10,10,10,1,2,0,0,0,0,2
1,2,2,2,2,2,2,2,2,2,1,2,2,2,2,1
endlayer

layer
1,2,2,2,2,2,2,2,2,2,1,2,2,2,2,1
2,2,2,2,2,2,3,0,0,0,7,0,0,0,0,2
2,2,2,2,2,2,3,0,0,0,7,0,0,0,0,2
1,1,1,1,1,1,2,2,2,2,1,7,7,7,7,2
2,0,0,0,0,0,0,0,0,0,2,0,0,0,0,2
2,1,0,0,0,0,0,0,0,7,2,0,0,0,0,2
2,0,0,0,0,0,0,0,0,0,2,0,0,0,0,2
2,20,0,0,0,0,0,0,0,7,2,0,0,0,0,2
2,0,0,0,0,0,0,0,0,0,2,0,0,0,0,2
2,1,21,0,0,1,0,22,22,1,2,0,0,0,0,2
1,2,2,2,2,2,2,2,2,2,1,2,2,2,2,1
endlayer

layer
1,1,1,1,1,1,1,1,1,1,1,1,1,1,1,1
1,2,2,2,2,3,0,0,0,0,2,2,2,2,2,1
1,2,2,2,2,3,0,0,0,0,2,2,2,2,2,1
1,2,2,2,2,1,1,1,1,1,1,1,1,1,1,1
1,2,2,2,2,2,2,2,2,2,1,2,2,2,2,1
1,2,2,2,2,2,2,2,2,2,1,2,2,2,2,1
1,2,2,2,2,2,2,2,2,2,1,2,2,2,2,1
1,2,2,2,2,2,2,2,2,2,1,2,2,2,2,1
1,2,2,2,2,2,2,2,2,2,1,2,2,2,2,1
1,2,2,2,2,2,2,2,2,2,1,2,2,2,2,1
1,1,1,1,1,1,1,1,1,1,1,1,1,1,1,1
endlayer

layer
35,35,35,35,35,35,35,35,35,35,35,35,35,35,35,35
35,35,35,0,0,0,0,0,35,35,35,35,35,35,35,35
35,35,35,0,0,0,0,0,35,35,35,35,35,35,35,35
35,35,35,0,0,35,35,35,35,35,35,35,35,35,35,35
35,35,35,0,0,36,2,2,35,35,35,35,35,35,35,35
35,35,35,0,0,36,2,2,35,35,35,35,35,35,35,35
35,35,35,35,35,35,35,35,35,35,35,35,35,35,35,35
35,35,35,35,35,35,35,35,35,35,35,35,35,35,35,35
35,35,35,35,35,35,35,35,35,35,35,35,35,35,35,35
35,35,35,35,35,35,35,35,35,35,35,35,35,35,35,35
35,35,35,35,35,35,35,35,35,35,35,35,35,35,35,35
endlayer

layer
35,35,35,35,35,35,35,35,35,35,35,35,35,35,35,35
35,35,35,0,0,0,0,35,35,35,35,35,35,35,35,35
35,35,35,0,0,0,0,35,35,35,35,35,35,35,35,35
35,35,35,0,0,35,35,35,35,35,35,35,35,35,35,35
35,35,35,0,0,0,36,2,2,35,35,35,35,35,35,35
35,35,35,0,0,0,36,2,2,35,35,35,35,35,35,35
35,35,35,35,35,35,35,35,35,35,35,35,35,35,35,35
35,35,35,35,35,35,35,35,35,35,35,35,35,35,35,35
35,35,35,35,35,35,35,35,35,35,35,35,35,35,35,35
35,35,35,35,35,35,35,35,35,35,35,35,35,35,35,35
35,35,35,35,35,35,35,35,35,35,35,35,35,35,35,35
endlayer

layer
35,35,35,35,35,35,35,35,35,35,35,35,35,35,35,35
35,35,35,35,35,35,35,35,35,35,35,35,35,35,35,35
35,35,35,35,35,35,35,35,35,35,35,35,35,35,35,35
35,35,35,35,35,35,35,35,35,35,35,35,35,35,35,35
35,35,35,35,0,0,0,36,2,2,35,35,35,35,35,35
35,35,35,35,0,0,0,36,2,2,35,35,35,35,35,35
35,35,35,35,35,35,35,35,35,35,35,35,35,35,35,35
35,35,35,35,35,35,35,35,35,35,35,35,35,35,35,35
35,35,35,35,35,35,35,35,35,35,35,35,35,35,35,35
35,35,35,35,35,35,35,35,35,35,35,35,35,35,35,35
35,35,35,35,35,35,35,35,35,35,35,35,35,35,35,35
endlayer

layer
35,35,35,35,35,35,35,35,35,35,35,35,35,35,35,35
35,35,35,35,35,35,35,35,35,35,35,35,35,35,35,35
35,35,35,35,35,35,35,35,35,35,35,35,35,35,35,35
35,35,35,35,35,35,35,35,35,35,35,35,35,35,35,35
35,35,35,35,35,0,0,0,36,2,2,35,35,35,35,35
35,35,35,35,35,0,0,0,36,2,2,35,35,35,35,35
35,35,35,35,35,35,35,35,35,35,35,35,35,35,35,35
35,35,35,35,35,35,35,35,35,35,35,35,35,35,35,35
35,35,35,35,35,35,35,35,35,35,35,35,35,35,35,35
35,35,35,35,35,35,35,35,35,35,35,35,35,35,35,35
35,35,35,35,35,35,35,35,35,35,35,35,35,35,35,35
endlayer

layer
35,35,35,35,35,35,35,35,35,35,35,35,35,35,35,35
35,35,35,35,35,35,35,35,35,35,35,35,35,35,35,35
35,35,35,35,35,35,35,35,35,35,35,35,35,35,35,35
35,35,35,35,35,35,35,35,35,35,35,35,35,35,35,35
35,35,35,35,35,35,0,0,0,36,2,35,35,35,35,35
35,35,35,35,35,35,0,0,0,36,2,35,35,35,35,35
35,35,35,35,35,35,35,35,35,35,35,35,35,35,35,35
35,35,35,35,35,35,35,35,35,35,35,35,35,35,35,35
35,35,35,35,35,35,35,35,35,35,35,35,35,35,35,35
35,35,35,35,35,35,35,35,35,35,35,35,35,35,35,35
35,35,35,35,35,35,35,35,35,35,35,35,35,35,35,35
endlayer

layer
35,35,35,35,35,35,35,35,35,35,35,35,35,35,35,35
35,35,35,35,35,35,35,35,35,35,35,35,35,35,35,35
35,35,35,35,35,35,35,35,35,35,35,35,35,35,35,35
35,35,35,35,35,35,35,35,35,35,35,35,35,35,35,35
35,35,35,35,35,35,35,0,0,0,36,35,35,35,35,35
35,35,35,35,35,35,35,0,0,0,36,35,35,35,35,35
35,35,35,35,35,35,35,35,35,35,35,35,35,35,35,35
35,35,35,35,35,35,35,35,35,35,35,35,35,35,35,35
35,35,35,35,35,35,35,35,35,35,35,35,35,35,35,35
35,35,35,35,35,35,35,35,35,35,35,35,35,35,35,35
35,35,35,35,35,35,35,35,35,35,35,35,35,35,35,35
endlayer

