
# Created by Ruins mod version 17.0 Ingame Parser
# authoring Player: ST753M

weight=1
embed_into_distance=5
acceptable_target_blocks=
unacceptable_target_blocks=flowing_water,water,flowing_lava,lava,ice,bedrock,netherrack,nether_brick,nether_brick_fence,soul_sand,quartz_ore,end_stone,obsidian,iron_bars,Natura:Cloud,slime_grass,slime_congealed,slime_dirt,clouds,natura:clouds,twilightforest:wispy_cloud,twilightforest:fluffy_cloud
dimensions=20,11,11
allowable_overhang=5
max_leveling=2
leveling_buffer=0
preserve_water=0
preserve_lava=0
uniqueMinDistance=1000
spawnMinDistance=1000

biomesToSpawnIn=prairie,rocky_plains,rocky_plateau,savanna,savanna_rock,steppe,wasteland,tundra,badlands,outback,red_desert,black_desert

=0,100,air
rule1=0,100,minecraft:stonebrick-0
rule2=0,100,minecraft:nether_brick-0
rule3=0,100,preserveBlock
rule4=0,100,minecraft:stone_brick_stairs-0
rule5=0,100,minecraft:stone_brick_stairs-2
rule6=0,100,minecraft:stone_brick_stairs-3
rule7=0,100,minecraft:concrete-14
rule8=0,100,minecraft:stone_brick_stairs-5
rule9=0,100,thaumcraft:loot_crate_common-0
rule10=0,100,minecraft:stone_brick_stairs-6
rule11=0,100,minecraft:stone_brick_stairs-1
rule12=0,100,thaumcraft:table_wood-0
rule13=0,100,minecraft:stained_glass_pane-14
rule14=0,50,thaumcraft:candle_red-0
rule15=0,100,minecraft:stone_brick_stairs-4
rule16=0,100,minecraft:stone_brick_stairs-7
rule17=0,100,minecraft:nether_brick_fence-0
rule18=0,100,minecraft:bed-0
rule19=0,100,minecraft:bed-8
rule20=0,100,CommandBlock:RUINSTRIGGER /summon thaumcraft:cultistcleric ~ ~1 ~ {PersistenceRequired:1}:@-1,CommandBlock:RUINSTRIGGER /summon thaumcraft:thaumcraft:cultistknight ~ ~1 ~ {PersistenceRequired:1}:@-1,CommandBlock:RUINSTRIGGER /summon thaumcraft:thaumcraft:cultistknight ~ ~1 ~ {PersistenceRequired:1}:@-1

layer
1,1,1,1,1,1,1,1,1,1,1
1,1,1,1,1,1,1,1,1,1,1
1,1,1,1,1,1,1,1,1,1,1
1,1,1,1,1,1,1,1,1,1,1
1,1,1,1,1,1,1,1,1,1,2
1,1,1,1,1,1,1,1,1,1,2
1,1,1,1,1,1,1,1,1,1,2
1,1,1,1,1,1,1,1,1,1,1
1,1,1,1,1,1,1,1,1,1,1
1,1,1,1,1,1,1,1,1,1,1
1,1,1,1,1,1,1,1,1,1,1
endlayer

layer
1,1,1,1,1,1,1,1,1,1,1
1,1,1,1,1,1,1,1,1,1,1
1,1,1,1,1,1,1,1,1,1,1
1,1,1,1,1,1,1,1,1,1,1
1,1,1,1,1,1,1,1,1,1,2
1,1,1,1,1,1,1,1,1,1,2
1,1,1,1,1,1,1,1,1,1,2
1,1,1,1,1,1,1,1,1,1,1
1,1,1,1,1,1,1,1,1,1,1
1,1,1,1,1,1,1,1,1,1,1
1,1,1,1,1,1,1,1,1,1,1
endlayer

layer
2,2,2,2,2,2,2,2,2,2,2
2,1,1,1,1,1,1,1,1,1,2
2,1,1,1,1,1,1,1,1,1,2
2,1,1,1,1,1,1,1,1,1,2
2,1,1,1,1,1,1,1,1,1,2
2,1,1,1,1,1,1,1,1,1,2
2,1,1,1,1,1,1,1,1,1,2
2,1,1,1,1,1,1,1,1,1,2
2,1,1,1,1,1,1,1,1,1,2
2,1,1,1,1,1,1,1,1,1,2
2,2,2,2,2,2,2,2,2,2,2
endlayer

layer
1,1,1,1,1,1,1,1,1,1,1
1,1,1,1,1,1,1,1,1,1,1
1,1,2,2,2,2,2,2,2,1,1
1,1,2,2,2,2,2,2,2,1,1
1,1,2,2,2,2,2,2,2,1,2
1,1,2,2,2,2,2,2,2,1,2
1,1,2,2,2,2,2,2,2,2,2
1,1,2,2,2,2,2,2,2,1,1
1,1,2,2,2,2,2,2,2,1,1
1,1,1,1,1,1,1,1,1,1,1
1,1,1,1,1,1,1,1,1,1,1
endlayer

layer
1,1,1,1,1,1,1,1,1,1,1
1,1,1,1,1,1,1,1,1,1,1
1,1,2,2,2,2,2,2,2,1,1
1,1,2,2,2,2,2,2,2,1,1
1,1,2,2,2,2,2,2,2,2,3
1,1,2,2,2,2,2,2,2,2,3
1,1,2,2,2,2,2,2,2,2,3
1,1,2,2,2,2,2,2,2,1,1
1,1,2,2,2,2,2,2,2,1,1
1,1,1,1,1,1,1,1,1,1,1
1,1,1,1,1,1,1,1,1,1,1
endlayer

layer
3,4,3,4,3,3,3,4,3,4,3
6,1,1,1,5,0,6,1,1,1,5
3,1,7,1,2,2,2,1,7,1,3
6,1,1,0,6,10,9,8,1,1,5
3,11,2,0,0,0,0,0,0,0,0
3,0,2,0,0,0,0,0,0,0,0
3,4,2,0,12,12,0,0,0,0,0
6,1,1,0,0,0,0,0,1,1,5
3,1,7,1,2,2,2,1,7,1,3
6,1,1,1,5,0,6,1,1,1,5
3,11,3,11,3,3,3,11,3,11,3
endlayer

layer
3,3,3,3,3,3,3,3,3,3,3
3,3,6,1,0,0,0,1,5,3,3
3,4,7,1,2,13,2,1,7,4,3
3,1,1,0,0,6,10,9,1,1,3
3,0,2,0,0,0,0,0,0,0,0
3,0,13,0,0,0,0,0,0,0,0
3,0,2,0,14,0,0,0,0,0,0
3,1,1,0,0,0,0,0,1,1,3
3,11,7,1,2,13,2,1,7,11,3
3,0,6,1,0,0,0,1,5,0,3
3,3,3,3,3,3,3,3,3,3,3
endlayer

layer
3,3,3,3,3,3,3,3,3,3,3
3,3,0,1,0,0,0,1,0,3,3
3,0,7,1,13,13,13,1,7,0,3
3,1,1,0,0,0,6,10,1,1,3
3,0,13,0,0,0,0,0,0,0,0
3,0,13,0,0,0,0,0,0,0,0
3,0,13,0,0,0,0,0,0,0,0
3,1,1,0,0,0,0,0,1,1,3
3,0,7,1,13,13,13,1,7,0,3
3,0,0,1,0,0,0,1,0,0,3
3,3,3,3,3,3,3,3,3,3,3
endlayer

layer
3,3,3,3,3,3,3,3,3,3,3
3,3,0,1,0,0,0,1,0,3,3
3,0,7,1,13,13,13,1,7,0,3
3,1,1,0,0,0,0,6,1,1,3
3,0,13,0,0,0,0,8,8,8,0
3,0,13,0,0,0,0,0,0,0,0
3,0,13,0,0,0,0,0,15,15,0
3,1,1,0,0,0,0,0,1,1,3
3,0,7,1,13,13,13,1,7,0,3
3,0,0,1,0,0,0,1,0,0,3
3,3,3,3,3,3,3,3,3,3,3
endlayer

layer
3,3,3,3,3,3,3,3,3,3,3
3,3,16,1,0,0,0,1,10,3,3
3,15,7,1,2,13,2,1,7,15,3
3,1,1,0,0,0,0,0,1,1,3
3,0,2,0,0,0,0,4,1,1,0
3,0,13,0,0,0,0,8,1,1,0
3,0,2,0,0,0,0,0,1,1,0
3,1,1,0,0,0,0,0,1,1,3
3,8,7,1,2,13,2,1,7,8,3
3,0,16,1,0,0,0,1,10,0,3
3,3,3,3,3,3,3,3,3,3,3
endlayer

layer
3,3,3,15,3,3,3,15,3,3,3
3,1,1,1,10,0,16,1,1,1,3
3,1,7,1,2,2,2,1,7,1,3
16,1,1,0,0,0,0,0,1,1,10
3,8,2,0,0,0,0,0,1,7,0
3,0,2,0,0,0,0,4,1,7,0
3,15,2,0,0,0,0,8,1,7,0
16,1,1,0,0,0,0,0,1,1,10
3,1,7,1,2,2,2,1,7,1,3
3,1,1,1,10,0,16,1,1,1,3
3,3,3,8,3,3,3,8,3,3,3
endlayer

layer
3,15,3,1,3,15,3,1,3,15,3
16,1,1,1,1,1,1,1,1,1,10
3,1,1,1,1,1,1,1,1,1,0
1,1,1,2,2,2,2,0,1,1,1
3,1,1,2,2,2,2,0,1,1,0
16,1,1,2,2,2,2,0,1,1,10
3,1,1,2,2,2,2,4,1,1,0
1,1,1,2,2,2,2,2,1,1,1
3,1,1,1,1,1,1,1,1,1,3
16,1,1,1,1,1,1,1,1,1,10
3,8,3,1,3,8,3,1,3,8,3
endlayer

layer
0,11,0,11,0,11,0,11,0,11,0
5,1,1,1,5,0,6,1,1,1,6
0,1,7,1,2,2,2,1,7,1,0
5,1,1,12,0,0,17,0,1,1,6
0,11,2,19,18,0,17,0,2,11,0
5,0,2,0,20,20,17,0,2,0,6
0,4,2,19,18,0,17,0,2,4,0
5,1,1,12,0,0,0,0,1,1,6
0,1,7,1,2,2,2,1,7,1,0
5,1,1,1,5,0,6,1,1,1,6
0,4,0,4,0,4,0,4,0,4,0
endlayer

layer
0,0,0,0,0,0,0,0,0,0,0
0,0,0,1,0,0,0,1,0,0,0
0,0,7,1,2,13,2,1,7,0,0
0,1,1,14,0,0,0,0,1,1,0
0,0,2,0,0,0,0,0,2,0,0
0,0,13,0,0,0,0,0,13,0,0
0,0,2,0,0,0,0,0,2,0,0
0,1,1,14,0,0,0,0,1,1,0
0,0,7,1,2,13,2,1,7,0,0
0,0,0,1,0,0,0,1,0,0,0
0,0,0,0,0,0,0,0,0,0,0
endlayer

layer
0,0,0,0,0,0,0,0,0,0,0
0,0,0,1,0,0,0,1,0,0,0
0,0,7,1,13,13,13,1,7,0,0
0,1,1,0,0,0,0,0,1,1,0
0,0,13,0,0,0,0,0,13,0,0
0,0,13,0,0,0,0,0,13,0,0
0,0,13,0,0,0,0,0,13,0,0
0,1,1,0,0,0,0,0,1,1,0
0,0,7,1,13,13,13,1,7,0,0
0,0,0,1,0,0,0,1,0,0,0
0,0,0,0,0,0,0,0,0,0,0
endlayer

layer
0,0,0,0,0,0,0,0,0,0,0
0,0,0,1,0,0,0,1,0,0,0
0,0,7,1,13,13,13,1,7,0,0
0,1,1,0,0,0,0,0,1,1,0
0,0,13,0,0,0,0,0,13,0,0
0,0,13,0,0,0,0,0,13,0,0
0,0,13,0,0,0,0,0,13,0,0
0,1,1,0,0,0,0,0,1,1,0
0,0,7,1,13,13,13,1,7,0,0
0,0,0,1,0,0,0,1,0,0,0
0,0,0,0,0,0,0,0,0,0,0
endlayer

layer
0,0,0,0,0,0,0,0,0,0,0
0,0,0,1,0,0,0,1,0,0,0
0,0,7,1,2,13,2,1,7,0,0
0,1,1,0,0,0,0,0,1,1,0
0,0,2,0,0,0,0,0,2,0,0
0,0,13,0,0,0,0,0,13,0,0
0,0,2,0,0,0,0,0,2,0,0
0,1,1,0,0,0,0,0,1,1,0
0,0,7,1,2,13,2,1,7,0,0
0,0,0,1,0,0,0,1,0,0,0
0,0,0,0,0,0,0,0,0,0,0
endlayer

layer
0,0,0,15,0,0,0,15,0,0,0
0,1,1,1,10,0,16,1,1,1,0
0,1,7,7,2,2,2,7,7,1,0
16,1,7,0,0,0,0,0,7,1,10
0,8,2,0,0,0,0,0,2,8,0
0,0,2,0,0,0,0,0,2,0,0
0,15,2,0,0,0,0,0,2,15,0
16,1,7,0,0,0,0,0,7,1,10
0,1,7,7,2,2,2,7,7,1,0
0,1,1,1,10,0,16,1,1,1,0
0,0,0,8,0,0,0,8,0,0,0
endlayer

layer
0,15,0,1,0,15,0,1,0,15,0
16,1,1,1,1,1,1,1,1,1,10
0,1,2,2,2,2,2,2,2,1,0
1,1,2,2,2,2,2,2,2,1,1
0,1,2,2,2,2,2,2,2,1,0
16,1,2,2,2,2,2,2,2,1,10
0,1,2,2,2,2,2,2,2,1,0
1,1,2,2,2,2,2,2,2,1,1
0,1,2,2,2,2,2,2,2,1,0
16,1,1,1,1,1,1,1,1,1,10
0,8,0,1,0,8,0,1,0,8,0
endlayer

layer
0,11,0,11,0,11,0,11,0,11,0
5,0,0,0,0,0,0,0,0,0,6
0,0,0,0,0,0,0,0,0,0,0
5,0,0,0,0,0,0,0,0,0,6
0,0,0,0,0,0,0,0,0,0,0
5,0,0,0,0,0,0,0,0,0,6
0,0,0,0,0,0,0,0,0,0,0
5,0,0,0,0,0,0,0,0,0,6
0,0,0,0,0,0,0,0,0,0,0
5,0,0,0,0,0,0,0,0,0,6
0,4,0,4,0,4,0,4,0,4,0
endlayer

