
# Created by Ruins mod version 17.0 Ingame Parser
# authoring Player: ST753M

weight=5
embed_into_distance=4
acceptable_target_blocks=
unacceptable_target_blocks=flowing_water,water,flowing_lava,lava,ice,bedrock,netherrack,nether_brick,nether_brick_fence,soul_sand,quartz_ore,end_stone,obsidian,iron_bars,Natura:Cloud,slime_grass,slime_congealed,slime_dirt,clouds,natura:clouds,twilightforest:wispy_cloud,twilightforest:fluffy_cloud
dimensions=9,17,17
allowable_overhang=4
max_leveling=0
leveling_buffer=0
preserve_water=0
preserve_lava=0
preventRotation=1

biomesToSpawnIn=swampland,mutated_swampland,wetland,quagmire,lush_swamp,mangrove,marsh,bayou,bog,bamboo_forest,dead_swamp,moor,dead_swamp,coralium_infested_swamp,darklands,darklands_forest,darklands_hills,darklands_mountains,darklands_plains,ominous_woods,eerie,swamp_defiled,desert_defiled,plains_defiled,ice_plains_defiled,hills_defiled,forest_tenebra,forest_vilespine,savanna,savanna_rock,mutated_savanna,mutated_savanna_rock,brushland,steppe,wasteland,tundra,outback,badlands

=0,100,preserveBlock
rule1=0,100,minecraft:stone_brick_stairs-4
rule2=0,100,minecraft:stonebrick-0
rule3=0,100,minecraft:stonebrick-3
rule4=0,100,minecraft:stone_brick_stairs-6
rule5=0,100,minecraft:stone_brick_stairs-7
rule6=0,100,minecraft:stone_brick_stairs-5
rule7=0,100,minecraft:stone_brick_stairs-0
rule8=0,100,minecraft:stone_brick_stairs-2
rule9=0,100,minecraft:stone_brick_stairs-1
rule10=0,100,minecraft:concrete-14
rule11=0,100,minecraft:stone_brick_stairs-3
rule12=0,100,CommandBlock:RUINSTRIGGER /summon thaumcraft:cultistportallesser ~ ~2 ~ {PersistenceRequired:1}:@-1
rule13=0,100,minecraft:stone_slab-13
rule14=0,100,thaumcraft:stone_arcane_brick-0
rule15=0,100,minecraft:black_glazed_terracotta-2
rule16=0,100,minecraft:black_glazed_terracotta-1
rule17=0,100,minecraft:black_glazed_terracotta-3
rule18=0,100,minecraft:black_glazed_terracotta-0
rule19=0,100,minecraft:stone_slab-5
rule20=0,100,teBlock;thaumcraft:banner_crimson_cult;{aspect:"",x:1687,y:100,facing:4b,z:9733,id:"thaumcraft:tilebanner",wall:0b}-0
rule21=0,100,thaumcraft:loot_crate_common-0
rule22=0,100,teBlock;thaumcraft:banner_crimson_cult;{aspect:"",x:1689,y:100,facing:6b,z:9729,id:"thaumcraft:tilebanner",wall:0b}-0
rule23=0,100,teBlock;thaumcraft:banner_crimson_cult;{aspect:"",x:1689,y:100,facing:2b,z:9737,id:"thaumcraft:tilebanner",wall:0b}-0
rule24=0,100,teBlock;thaumcraft:banner_crimson_cult;{aspect:"",x:1693,y:100,facing:8b,z:9727,id:"thaumcraft:tilebanner",wall:0b}-0
rule25=0,100,teBlock;thaumcraft:banner_crimson_cult;{aspect:"",x:1693,y:100,facing:0b,z:9739,id:"thaumcraft:tilebanner",wall:0b}-0
rule26=0,100,teBlock;thaumcraft:banner_crimson_cult;{aspect:"",x:1697,y:100,facing:10b,z:9729,id:"thaumcraft:tilebanner",wall:0b}-0
rule27=0,100,teBlock;thaumcraft:banner_crimson_cult;{aspect:"",x:1697,y:100,facing:14b,z:9737,id:"thaumcraft:tilebanner",wall:0b}-0
rule28=0,100,teBlock;thaumcraft:banner_crimson_cult;{aspect:"",x:1699,y:100,facing:12b,z:9733,id:"thaumcraft:tilebanner",wall:0b}-0
rule29=0,100,thaumcraft:nitor_red-0

layer
0,0,0,0,0,0,1,0,1,0,1,0,0,0,0,0,0
0,0,0,0,1,0,2,2,2,2,2,0,1,0,0,0,0
0,0,0,0,2,2,2,2,2,2,2,2,2,0,0,0,0
0,0,0,3,2,2,2,2,2,2,2,2,2,3,0,0,0
0,5,2,2,2,2,2,2,2,2,2,2,2,2,2,4,0
0,0,2,2,2,2,2,2,2,2,2,2,2,2,2,0,0
5,2,2,2,2,2,2,2,2,2,2,2,2,2,2,2,4
0,2,2,2,2,2,2,2,2,2,2,2,2,2,2,2,0
5,2,2,2,2,2,2,2,2,2,2,2,2,2,2,2,4
0,2,2,2,2,2,2,2,2,2,2,2,2,2,2,2,0
5,2,2,2,2,2,2,2,2,2,2,2,2,2,2,2,4
0,0,2,2,2,2,2,2,2,2,2,2,2,2,2,0,0
0,5,2,2,2,2,2,2,2,2,2,2,2,2,2,4,0
0,0,0,3,2,2,2,2,2,2,2,2,2,3,0,0,0
0,0,0,0,2,2,2,2,2,2,2,2,2,0,0,0,0
0,0,0,0,6,0,2,2,2,2,2,0,6,0,0,0,0
0,0,0,0,0,0,6,0,6,0,6,0,0,0,0,0,0
endlayer

layer
0,0,0,0,0,0,2,0,2,0,2,0,0,0,0,0,0
0,0,0,0,2,0,2,7,2,7,2,0,2,0,0,0,0
0,0,0,2,2,7,2,2,2,2,2,7,2,2,0,0,0
0,0,2,2,2,2,2,2,2,2,2,2,2,2,2,0,0
0,2,2,2,2,2,2,2,2,2,2,2,2,2,2,2,0
0,0,2,2,2,2,2,2,2,2,2,2,2,2,8,0,0
2,2,2,2,2,2,2,2,2,2,2,2,2,2,2,2,2
0,2,2,2,2,2,2,2,2,2,2,2,2,2,2,8,0
2,2,2,2,2,2,2,2,2,2,2,2,2,2,2,2,2
0,2,2,2,2,2,2,2,2,2,2,2,2,2,2,8,0
2,2,2,2,2,2,2,2,2,2,2,2,2,2,2,2,2
0,0,2,2,2,2,2,2,2,2,2,2,2,2,8,0,0
0,2,2,2,2,2,2,2,2,2,2,2,2,2,2,2,0
0,0,2,2,2,2,2,2,2,2,2,2,2,2,2,0,0
0,0,0,2,2,9,2,2,2,2,2,9,2,2,0,0,0
0,0,0,0,2,0,2,9,2,9,2,0,2,0,0,0,0
0,0,0,0,0,0,2,0,2,0,2,0,0,0,0,0,0
endlayer

layer
0,0,0,0,0,0,7,0,7,0,7,0,0,0,0,0,0
0,0,0,0,7,0,2,0,2,0,2,0,7,0,0,0,0
0,0,0,7,2,0,2,10,2,10,2,0,2,7,0,0,0
0,0,11,3,2,10,2,2,2,2,2,10,2,3,8,0,0
0,11,2,2,2,2,2,2,2,2,2,2,2,2,2,8,0
0,0,0,10,2,2,2,2,2,2,2,2,2,10,0,0,0
11,2,2,2,2,2,2,2,2,2,2,2,2,2,2,2,8
0,0,10,2,2,2,2,2,2,2,2,2,2,2,10,0,0
11,2,2,2,2,2,2,2,2,2,2,2,2,2,2,2,8
0,0,10,2,2,2,2,2,2,2,2,2,2,2,10,0,0
11,2,2,2,2,2,2,2,2,2,2,2,2,2,2,2,8
0,0,0,10,2,2,2,2,2,2,2,2,2,10,0,0,0
0,11,2,2,2,2,2,2,2,2,2,2,2,2,2,8,0
0,0,11,3,2,10,2,2,2,2,2,10,2,3,8,0,0
0,0,0,9,2,0,2,10,2,10,2,0,2,9,0,0,0
0,0,0,0,9,0,2,0,2,0,2,0,9,0,0,0,0
0,0,0,0,0,0,9,0,9,0,9,0,0,0,0,0,0
endlayer

layer
0,0,0,0,0,0,0,0,0,0,0,0,0,0,0,0,0
0,0,0,0,0,0,2,0,2,0,2,0,0,0,0,0,0
0,0,0,0,2,0,2,10,2,10,2,0,2,0,0,0,0
0,0,0,0,10,10,2,2,2,2,2,10,10,0,0,0,0
0,0,2,10,2,2,2,2,2,2,2,2,2,10,2,0,0
0,0,0,10,2,2,2,2,2,2,2,2,2,10,0,0,0
0,2,2,2,2,2,2,2,2,2,2,2,2,2,2,2,0
0,0,10,2,2,2,2,2,2,2,2,2,2,2,10,0,0
0,2,2,2,2,2,2,2,2,2,2,2,2,2,2,2,0
0,0,10,2,2,2,2,2,2,2,2,2,2,2,10,0,0
0,2,2,2,2,2,2,2,2,2,2,2,2,2,2,2,0
0,0,0,10,2,2,2,2,2,2,2,2,2,10,0,0,0
0,0,2,10,2,2,2,2,2,2,2,2,10,10,2,0,0
0,0,0,0,10,10,2,2,2,2,2,10,10,0,0,0,0
0,0,0,0,2,0,2,10,2,10,2,0,2,0,0,0,0
0,0,0,0,0,0,2,0,2,0,2,0,0,0,0,0,0
0,0,0,0,0,0,0,0,0,0,0,0,0,0,0,0,0
endlayer

layer
0,0,0,0,0,0,1,0,1,0,1,0,0,0,0,0,0
0,0,0,0,1,0,2,0,2,0,2,0,1,0,0,0,0
0,0,0,1,2,0,2,10,2,10,2,0,2,1,0,0,0
0,0,5,3,2,10,2,2,2,2,2,10,2,3,4,0,0
0,5,2,2,2,2,2,2,2,2,2,2,2,2,2,4,0
0,0,0,10,2,2,2,2,2,2,2,2,2,10,0,0,0
5,2,2,2,2,2,2,2,2,2,2,2,2,2,2,2,4
0,0,10,2,2,2,2,2,2,2,2,2,2,2,10,0,0
5,2,2,2,2,2,2,2,12,2,2,2,2,2,2,2,4
0,0,10,2,2,2,2,2,2,2,2,2,2,2,10,0,0
5,2,2,2,2,2,2,2,2,2,2,2,2,2,2,2,4
0,0,0,10,2,2,2,2,2,2,2,2,2,10,0,0,0
0,5,2,2,2,2,2,2,2,2,2,2,2,2,2,4,0
0,0,5,3,2,10,2,2,2,2,2,10,2,3,4,0,0
0,0,0,6,2,0,2,10,2,10,2,0,2,6,0,0,0
0,0,0,0,6,0,2,0,2,0,2,0,6,0,0,0,0
0,0,0,0,0,0,6,0,6,0,6,0,0,0,0,0,0
endlayer

layer
0,0,0,0,0,0,2,0,3,0,2,0,0,0,0,0,0
0,0,0,0,3,0,2,1,2,1,2,0,3,0,0,0,0
0,0,13,2,2,1,14,14,14,14,14,1,2,2,13,0,0
0,0,2,2,14,14,14,14,14,14,14,14,14,2,2,0,0
0,3,2,14,14,14,16,15,14,16,15,14,14,14,2,3,0
0,0,5,14,14,14,18,15,14,16,17,14,14,14,4,0,0
2,2,14,14,16,15,14,18,16,17,14,16,15,14,14,2,2
0,5,14,14,18,18,15,17,17,18,16,17,17,14,14,4,0
3,2,14,14,14,14,18,15,14,18,15,14,14,14,14,2,3
0,5,14,14,16,16,17,15,16,16,18,15,15,14,14,4,0
2,2,14,14,18,17,14,16,17,15,14,18,17,14,14,2,2
0,0,5,14,14,14,16,17,14,18,15,14,14,14,4,0,0
0,3,2,14,14,14,18,17,14,18,17,14,14,14,2,3,0
0,0,2,2,14,14,14,14,14,14,14,14,14,2,2,0,0
0,0,13,2,2,6,14,14,14,14,14,6,2,2,13,0,0
0,0,0,0,3,0,2,6,2,6,2,0,3,0,0,0,0
0,0,0,0,0,0,2,0,3,0,2,0,0,0,0,0,0
endlayer

layer
0,0,0,0,0,0,3,0,2,0,3,0,0,0,0,0,0
0,0,0,0,2,0,19,19,19,19,19,0,2,0,0,0,0
0,0,3,8,19,19,0,0,20,0,0,19,19,11,3,0,0
0,0,9,19,0,0,0,0,0,0,0,0,0,19,9,0,0
0,2,19,0,23,0,0,0,0,0,0,0,22,21,19,2,0
0,0,19,21,0,0,0,0,0,0,0,0,0,0,19,0,0
3,19,0,0,0,0,0,0,0,0,0,0,0,0,0,19,3
0,19,0,0,0,0,0,0,0,0,0,0,0,0,0,19,0
2,19,25,0,0,0,0,0,0,0,0,0,0,0,24,19,2
0,19,0,0,0,0,0,0,0,0,0,0,0,0,0,19,0
3,19,0,0,0,0,0,0,0,0,0,0,0,0,0,19,3
0,0,19,0,0,0,0,0,0,0,0,0,0,0,19,0,0
0,2,19,0,27,0,0,0,0,0,0,0,26,0,19,2,0
0,0,7,19,0,0,0,0,0,0,0,0,0,19,7,0,0
0,0,3,8,19,19,0,0,28,0,21,19,19,11,3,0,0
0,0,0,0,2,0,19,19,19,19,19,0,2,0,0,0,0
0,0,0,0,0,0,3,0,2,0,3,0,0,0,0,0,0
endlayer

layer
0,0,0,0,0,0,9,0,9,0,9,0,0,0,0,0,0
0,0,0,0,9,0,0,0,0,0,0,0,9,0,0,0,0
0,0,2,0,0,0,0,0,0,0,0,0,0,0,2,0,0
0,0,0,0,0,0,0,0,0,0,0,0,0,0,0,0,0
0,8,0,0,0,0,0,0,0,0,0,0,0,0,0,11,0
0,0,0,0,0,0,0,0,0,0,0,0,0,0,0,0,0
8,0,0,0,0,0,0,0,0,0,0,0,0,0,0,0,11
0,0,0,0,0,0,0,0,0,0,0,0,0,0,0,0,0
8,0,0,0,0,0,0,0,0,0,0,0,0,0,0,0,11
0,0,0,0,0,0,0,0,0,0,0,0,0,0,0,0,0
8,0,0,0,0,0,0,0,0,0,0,0,0,0,0,0,11
0,0,0,0,0,0,0,0,0,0,0,0,0,0,0,0,0
0,8,0,0,0,0,0,0,0,0,0,0,0,0,0,11,0
0,0,0,0,0,0,0,0,0,0,0,0,0,0,0,0,0
0,0,2,0,0,0,0,0,0,0,0,0,0,0,2,0,0
0,0,0,0,7,0,0,0,0,0,0,0,7,0,0,0,0
0,0,0,0,0,0,7,0,7,0,7,0,0,0,0,0,0
endlayer

layer
0,0,0,0,0,0,0,0,0,0,0,0,0,0,0,0,0
0,0,0,0,0,0,0,0,0,0,0,0,0,0,0,0,0
0,0,29,0,0,0,0,0,0,0,0,0,0,0,29,0,0
0,0,0,0,0,0,0,0,0,0,0,0,0,0,0,0,0
0,0,0,0,0,0,0,0,0,0,0,0,0,0,0,0,0
0,0,0,0,0,0,0,0,0,0,0,0,0,0,0,0,0
0,0,0,0,0,0,0,0,0,0,0,0,0,0,0,0,0
0,0,0,0,0,0,0,0,0,0,0,0,0,0,0,0,0
0,0,0,0,0,0,0,0,0,0,0,0,0,0,0,0,0
0,0,0,0,0,0,0,0,0,0,0,0,0,0,0,0,0
0,0,0,0,0,0,0,0,0,0,0,0,0,0,0,0,0
0,0,0,0,0,0,0,0,0,0,0,0,0,0,0,0,0
0,0,0,0,0,0,0,0,0,0,0,0,0,0,0,0,0
0,0,0,0,0,0,0,0,0,0,0,0,0,0,0,0,0
0,0,29,0,0,0,0,0,0,0,0,0,0,0,29,0,0
0,0,0,0,0,0,0,0,0,0,0,0,0,0,0,0,0
0,0,0,0,0,0,0,0,0,0,0,0,0,0,0,0,0
endlayer

