
# Created by Ruins mod version 17.0 Ingame Parser
# authoring Player: ST753M

weight=1
embed_into_distance=5
acceptable_target_blocks=
unacceptable_target_blocks=flowing_water,water,flowing_lava,lava,ice,bedrock,netherrack,nether_brick,nether_brick_fence,soul_sand,quartz_ore,end_stone,obsidian,iron_bars,Natura:Cloud,slime_grass,slime_congealed,slime_dirt,clouds,natura:clouds,twilightforest:wispy_cloud,twilightforest:fluffy_cloud
dimensions=13,11,11
allowable_overhang=5
max_leveling=2
leveling_buffer=0
preserve_water=0
preserve_lava=0
uniqueMinDistance=1000
spawnMinDistance=1000

biomesToSpawnIn=prairie,rocky_plains,rocky_plateau,savanna,savanna_rock,steppe,wasteland,tundra,badlands,outback,red_desert,black_desert

=0,100,air
rule1=0,100,minecraft:stonebrick-0
rule2=0,100,minecraft:nether_brick-0
rule3=0,100,preserveBlock
rule4=0,100,minecraft:stone_brick_stairs-0
rule5=0,100,minecraft:stone_brick_stairs-2
rule6=0,100,minecraft:stone_brick_stairs-3
rule7=0,100,minecraft:concrete-14
rule8=0,100,thaumcraft:table_wood-0
rule9=0,100,minecraft:bed-9
rule10=0,100,minecraft:bed-1
rule11=0,100,minecraft:stone_brick_stairs-1
rule12=0,50,teBlock;thaumcraft:banner_crimson_cult;{aspect:"",x:17453,y:95,facing:6b,z:19872,id:"thaumcraft:tilebanner",wall:0b}-0
rule13=0,100,thaumcraft:loot_crate_common-0
rule14=0,100,minecraft:stained_glass_pane-14
rule15=0,50,thaumcraft:candle_red-0
rule16=0,50,CommandBlock:RUINSTRIGGER /summon thaumcraft:cultistcleric ~ ~1 ~ {PersistenceRequired:1}:@-1,CommandBlock:RUINSTRIGGER /summon thaumcraft:thaumcraft:cultistknight ~ ~1 ~ {PersistenceRequired:1}:@-1,CommandBlock:RUINSTRIGGER /summon thaumcraft:thaumcraft:cultistknight ~ ~1 ~ {PersistenceRequired:1}:@-1
rule17=0,100,minecraft:stone_brick_stairs-5
rule18=0,100,minecraft:stone_brick_stairs-4
rule19=0,100,minecraft:stone_brick_stairs-6
rule20=0,100,minecraft:stone_brick_stairs-7

layer
1,1,1,1,1,1,1,1,1,1,1
1,1,1,1,1,1,1,1,1,1,1
1,1,1,1,1,1,1,1,1,1,1
1,1,1,1,1,1,1,1,1,1,1
1,1,1,1,1,1,1,1,1,1,1
1,1,1,1,1,1,1,1,1,1,1
1,1,1,1,1,1,1,1,1,1,1
1,1,1,1,1,1,1,1,1,1,1
1,1,1,1,1,1,1,1,1,1,1
1,1,1,1,1,1,1,1,1,1,1
1,1,1,1,1,1,1,1,1,1,1
endlayer

layer
2,1,2,1,2,1,2,1,2,1,2
1,1,1,1,1,1,1,1,1,1,1
2,1,1,1,1,1,1,1,1,1,2
1,1,1,1,1,1,1,1,1,1,1
2,1,1,1,1,1,1,1,1,1,2
1,1,1,1,1,1,1,1,1,1,1
2,1,1,1,1,1,1,1,1,1,2
1,1,1,1,1,1,1,1,1,1,1
2,1,1,1,1,1,1,1,1,1,2
1,1,1,1,1,1,1,1,1,1,1
2,1,2,1,2,1,2,1,2,1,2
endlayer

layer
1,2,1,2,1,2,1,2,1,2,1
2,1,1,1,1,1,1,1,1,1,2
1,1,1,1,1,1,1,1,1,1,1
2,1,1,1,1,1,1,1,1,1,2
1,1,1,1,1,1,1,1,1,1,1
2,1,1,1,1,1,1,1,1,1,2
1,1,1,1,1,1,1,1,1,1,1
2,1,1,1,1,1,1,1,1,1,2
1,1,1,1,1,1,1,1,1,1,1
2,1,1,1,1,1,1,1,1,1,2
1,2,1,2,1,2,1,2,1,2,1
endlayer

layer
1,1,1,1,1,1,1,1,1,1,1
1,1,1,1,1,1,1,1,1,1,1
1,1,2,2,2,2,2,2,2,1,1
1,1,2,2,2,2,2,2,2,1,1
1,1,2,2,2,2,2,2,2,1,1
1,1,2,2,2,2,2,2,2,1,1
1,1,2,2,2,2,2,2,2,2,1
1,1,2,2,2,2,2,2,2,1,1
1,1,2,2,2,2,2,2,2,1,1
1,1,1,1,1,1,1,1,1,1,1
1,1,1,1,1,1,1,1,1,1,1
endlayer

layer
1,1,1,1,1,1,1,1,1,1,1
1,1,1,1,1,1,1,1,1,1,1
1,1,2,2,2,2,2,2,2,1,1
1,1,2,2,2,2,2,2,2,1,1
1,1,2,2,2,2,2,2,2,2,3
1,1,2,2,2,2,2,2,2,2,3
1,1,2,2,2,2,2,2,2,2,3
1,1,2,2,2,2,2,2,2,1,1
1,1,2,2,2,2,2,2,2,1,1
1,1,1,1,1,1,1,1,1,1,1
1,1,1,1,1,1,1,1,1,1,1
endlayer

layer
3,4,3,4,3,3,3,4,3,4,3
6,1,1,1,5,0,6,1,1,1,5
3,1,7,1,2,2,2,1,7,1,3
6,1,1,9,8,0,0,0,1,1,5
3,11,2,10,0,0,0,0,0,0,0
3,0,2,0,0,0,0,0,0,0,0
3,4,2,0,0,12,0,0,0,0,0
6,1,1,0,0,0,13,13,1,1,5
3,1,7,1,2,2,2,1,7,1,3
6,1,1,1,5,0,6,1,1,1,5
3,11,3,11,3,3,3,11,3,11,3
endlayer

layer
3,3,3,3,3,3,3,3,3,3,3
3,0,6,1,0,0,0,1,5,3,3
3,4,7,1,2,14,2,1,7,4,3
3,1,1,0,15,0,0,0,1,1,3
3,0,2,0,0,0,0,0,0,0,0
3,0,14,0,0,0,0,0,0,0,0
3,0,2,0,0,0,0,0,0,0,0
3,1,1,0,0,0,0,13,1,1,3
3,11,7,1,2,14,2,1,7,11,3
3,0,6,1,0,0,0,1,5,3,3
3,3,3,3,3,3,3,3,3,3,3
endlayer

layer
3,3,3,3,3,3,3,3,3,3,3
3,0,0,1,0,0,0,1,3,3,3
3,0,7,1,14,14,14,1,7,0,3
3,1,1,0,0,0,0,0,1,1,3
3,0,14,16,0,0,0,0,0,0,0
3,0,14,16,0,0,0,0,0,0,0
3,0,14,0,0,0,0,0,0,0,0
3,1,1,0,0,0,0,0,1,1,3
3,0,7,1,14,14,14,1,7,0,3
3,0,0,1,0,0,0,1,3,3,3
3,3,3,3,3,3,3,3,3,3,3
endlayer

layer
3,3,3,3,3,3,3,3,3,3,3
3,0,0,1,0,0,0,1,3,3,3
3,0,7,1,14,14,14,1,7,0,3
3,1,1,0,0,0,0,0,1,1,3
3,0,14,0,0,0,0,0,17,17,0
3,0,14,0,0,0,0,0,0,0,0
3,0,14,0,0,0,0,0,18,18,0
3,1,1,0,0,0,0,0,1,1,3
3,0,7,1,14,14,14,1,7,0,3
3,0,0,1,0,0,0,1,3,3,3
3,3,3,3,3,3,3,3,3,3,3
endlayer

layer
3,3,3,3,3,3,3,3,3,3,3
3,0,20,1,0,0,0,1,19,3,3
3,18,7,1,2,14,2,1,7,18,3
3,1,1,0,0,0,0,0,1,1,3
3,0,2,0,0,0,0,0,1,1,3
3,0,14,0,0,0,0,0,1,1,0
3,0,2,0,0,0,0,0,1,1,3
3,1,1,0,0,0,0,0,1,1,3
3,17,7,1,2,14,2,1,7,17,3
3,0,20,1,0,0,0,1,19,3,3
3,3,3,3,3,3,3,3,3,3,3
endlayer

layer
3,3,3,18,3,3,3,18,3,3,3
3,1,1,1,19,0,20,1,1,1,3
3,1,7,7,2,2,2,7,7,1,3
20,1,7,0,0,0,0,0,7,1,19
3,17,2,0,0,0,0,0,2,14,3
3,0,2,0,0,0,0,0,2,14,3
3,18,2,0,0,0,0,0,2,14,3
20,1,7,0,0,0,0,0,7,1,19
3,1,7,7,2,2,2,7,7,1,3
3,1,1,1,19,0,20,1,1,1,3
3,3,3,17,3,3,3,17,3,3,3
endlayer

layer
3,18,3,1,3,18,3,1,3,18,3
20,1,1,1,1,1,1,1,1,1,19
3,1,1,1,2,2,2,1,1,1,3
1,1,1,2,2,2,2,2,1,1,1
3,1,2,2,2,2,2,2,2,1,3
20,1,2,2,2,2,2,2,2,1,19
3,1,2,2,2,2,2,2,2,1,3
1,1,1,2,2,2,2,2,1,1,1
3,1,1,1,2,2,2,1,1,1,3
20,1,1,1,1,1,1,1,1,1,19
3,17,3,1,3,17,3,1,3,17,3
endlayer

layer
3,11,3,11,3,11,3,11,3,11,3
5,0,0,0,0,0,0,0,0,0,6
3,0,0,0,0,0,0,0,0,0,3
5,0,0,0,0,0,0,0,0,0,6
3,0,0,0,0,0,0,0,0,0,3
5,0,0,0,0,0,0,0,0,0,6
3,0,0,0,0,0,0,0,0,0,3
5,0,0,0,0,0,0,0,0,0,6
3,0,0,0,0,0,0,0,0,0,3
5,0,0,0,0,0,0,0,0,0,6
3,4,3,4,3,4,3,4,3,4,3
endlayer

