
# Created by Ruins mod version 17.0 Ingame Parser
# authoring Player: ST753M

# Summons a bunch of stuff around itself (total footprint is about 60x60)

weight=2
uniqueMinDistance=2000
spawnMinDistance=1000
embed_into_distance=4
acceptable_target_blocks=
unacceptable_target_blocks=flowing_water,water,flowing_lava,lava,ice,bedrock,netherrack,nether_brick,nether_brick_fence,soul_sand,quartz_ore,end_stone,obsidian,iron_bars,Natura:Cloud,slime_grass,slime_congealed,slime_dirt,clouds,natura:clouds,twilightforest:wispy_cloud,twilightforest:fluffy_cloud
dimensions=32,19,19
allowable_overhang=4
max_leveling=2
leveling_buffer=0
preserve_water=0
preserve_lava=0
preventRotation=1

biomesToSpawnIn=prairie,rocky_plains,rocky_plateau,savanna,steppe,wasteland,tundra,badlands,outback,red_desert,black_desert,desert


adjoining_template=ST753M/753_Crimson_Gate_EW;0;99;25;100
adjoining_template=ST753M/753_Crimson_Gate_EW;0;99;-25;100
adjoining_template=ST753M/753_Crimson_Gate_NS;25;99;0;100
adjoining_template=ST753M/753_Crimson_Gate_NS;-25;99;0;100

adjoining_template=ST753M/753_Crimson_Wall_EW;9;99;25;100
adjoining_template=ST753M/753_Crimson_Wall_EW;16;99;25;100
adjoining_template=ST753M/753_Crimson_Wall_EW;-9;99;25;100
adjoining_template=ST753M/753_Crimson_Wall_EW;-16;99;25;100
adjoining_template=ST753M/753_Crimson_Wall_EW;9;99;-25;100
adjoining_template=ST753M/753_Crimson_Wall_EW;16;99;-25;100
adjoining_template=ST753M/753_Crimson_Wall_EW;-9;99;-25;100
adjoining_template=ST753M/753_Crimson_Wall_EW;-16;99;-25;100

adjoining_template=ST753M/753_Crimson_Wall_NS;25;99;9;100
adjoining_template=ST753M/753_Crimson_Wall_NS;25;99;16;100
adjoining_template=ST753M/753_Crimson_Wall_NS;25;99;-9;100
adjoining_template=ST753M/753_Crimson_Wall_NS;25;99;-16;100
adjoining_template=ST753M/753_Crimson_Wall_NS;-25;99;9;100
adjoining_template=ST753M/753_Crimson_Wall_NS;-25;99;16;100
adjoining_template=ST753M/753_Crimson_Wall_NS;-25;99;-9;100
adjoining_template=ST753M/753_Crimson_Wall_NS;-25;99;-16;100

adjoining_template=savanna/753_Crimson_House1_CB;-17;99;7;100
adjoining_template=savanna/753_Crimson_House2_CB;-17;99;-7;100
adjoining_template=savanna/753_Crimson_House2_CB;17;99;7;100
adjoining_template=savanna/753_Crimson_House1_CB;17;99;-7;100
adjoining_template=savanna/753_Crimson_House2_CB;-7;99;17;100
adjoining_template=savanna/753_Crimson_House3_CB;-7;99;-17;100
adjoining_template=savanna/753_Crimson_House3_CB;7;99;17;100
adjoining_template=savanna/753_Crimson_House1_CB;7;99;-17;100

adjoining_template=savanna/753_Crimson_GuardTower;25;99;25;100
adjoining_template=savanna/753_Crimson_GuardTower;25;99;-25;100
adjoining_template=savanna/753_Crimson_GuardTower;-25;99;25;100
adjoining_template=savanna/753_Crimson_GuardTower;-25;99;-25;100

=0,100,air
rule1=0,100,minecraft:concrete-14
rule2=0,100,preserveBlock
rule3=0,100,minecraft:stonebrick-0
rule4=0,100,minecraft:nether_brick-0
rule5=0,100,thaumcraft:stone_arcane_brick-0
rule6=0,100,minecraft:black_glazed_terracotta-2
rule7=0,100,minecraft:black_glazed_terracotta-1
rule8=0,100,minecraft:black_glazed_terracotta-3
rule9=0,100,minecraft:black_glazed_terracotta-0
rule10=0,100,thaumcraft:stone_arcane-0
rule11=0,100,minecraft:stone_brick_stairs-0
rule12=0,100,minecraft:stone_brick_stairs-2
rule13=0,100,minecraft:stone_brick_stairs-3
rule14=0,100,minecraft:stone_brick_stairs-1
	# Creates a crimson portal
rule15=0,100,CommandBlock:RUINSTRIGGER /summon thaumcraft:cultistportallesser ~ ~0 ~ {PersistenceRequired:1}:@-1

rule16=0,100,thaumcraft:nitor_red-0
rule17=0,100,minecraft:stained_glass_pane-14
rule18=0,100,CommandBlock:RUINSTRIGGER /fill ~-1 ~-15 ~-35 ~1 ~15 ~35 grass_path 0 replace grass 0:@-1
rule19=0,100,CommandBlock:RUINSTRIGGER /fill ~-35 ~-15 ~1 ~35 ~15 ~-1 grass_path 0 replace grass 0:@-1
rule20=0,100,minecraft:stone_brick_stairs-7
rule21=0,100,minecraft:stone_brick_stairs-6
rule22=0,100,minecraft:stone_brick_stairs-5

rule23=0,100,air

rule24=0,100,minecraft:stone_brick_stairs-4
rule25=0,100,teBlock;thaumcraft:banner_crimson_cult;{aspect:"",x:17555,y:114,facing:4b,z:19827,id:"thaumcraft:tilebanner",wall:1b}-0
rule26=0,100,teBlock;thaumcraft:banner_crimson_cult;{aspect:"",x:17555,y:114,facing:4b,z:19831,id:"thaumcraft:tilebanner",wall:1b}-0
rule27=0,100,teBlock;thaumcraft:banner_crimson_cult;{aspect:"",x:17555,y:114,facing:4b,z:19835,id:"thaumcraft:tilebanner",wall:1b}-0
rule28=0,100,teBlock;thaumcraft:banner_crimson_cult;{aspect:"",x:17555,y:114,facing:4b,z:19839,id:"thaumcraft:tilebanner",wall:1b}-0
rule29=0,100,teBlock;thaumcraft:banner_crimson_cult;{aspect:"",x:17558,y:114,facing:8b,z:19824,id:"thaumcraft:tilebanner",wall:1b}-0
rule30=0,100,teBlock;thaumcraft:banner_crimson_cult;{aspect:"",x:17558,y:114,facing:0b,z:19842,id:"thaumcraft:tilebanner",wall:1b}-0
rule31=0,100,teBlock;thaumcraft:banner_crimson_cult;{aspect:"",x:17562,y:114,facing:8b,z:19824,id:"thaumcraft:tilebanner",wall:1b}-0
rule32=0,100,teBlock;thaumcraft:banner_crimson_cult;{aspect:"",x:17562,y:114,facing:0b,z:19842,id:"thaumcraft:tilebanner",wall:1b}-0

rule33=0,100,air

rule34=0,100,teBlock;thaumcraft:banner_crimson_cult;{aspect:"",x:17566,y:114,facing:8b,z:19824,id:"thaumcraft:tilebanner",wall:1b}-0
rule35=0,100,teBlock;thaumcraft:banner_crimson_cult;{aspect:"",x:17566,y:114,facing:0b,z:19842,id:"thaumcraft:tilebanner",wall:1b}-0
rule36=0,100,teBlock;thaumcraft:banner_crimson_cult;{aspect:"",x:17570,y:114,facing:8b,z:19824,id:"thaumcraft:tilebanner",wall:1b}-0
rule37=0,100,teBlock;thaumcraft:banner_crimson_cult;{aspect:"",x:17570,y:114,facing:0b,z:19842,id:"thaumcraft:tilebanner",wall:1b}-0
rule38=0,100,teBlock;thaumcraft:banner_crimson_cult;{aspect:"",x:17573,y:114,facing:12b,z:19827,id:"thaumcraft:tilebanner",wall:1b}-0
rule39=0,100,teBlock;thaumcraft:banner_crimson_cult;{aspect:"",x:17573,y:114,facing:12b,z:19831,id:"thaumcraft:tilebanner",wall:1b}-0
rule40=0,100,teBlock;thaumcraft:banner_crimson_cult;{aspect:"",x:17573,y:114,facing:12b,z:19835,id:"thaumcraft:tilebanner",wall:1b}-0
rule41=0,100,teBlock;thaumcraft:banner_crimson_cult;{aspect:"",x:17573,y:114,facing:12b,z:19839,id:"thaumcraft:tilebanner",wall:1b}-0

rule42=0,100,air
rule43=0,100,air

rule44=0,100,minecraft:stonebrick-3
rule45=0,100,minecraft:nether_brick_stairs-7
rule46=0,100,minecraft:nether_brick_stairs-5
rule47=0,100,minecraft:nether_brick_stairs-6

rule48=0,100,air

rule49=0,100,minecraft:nether_brick_stairs-4
rule50=0,60,MobSpawner:thaumcraft:cultistcleric

rule51=0,100,air

rule52=0,60,MobSpawner:thaumcraft:cultistknight

rule53=0,100,air
rule54=0,100,air
rule55=0,100,air

rule56=0,100,teBlock;thaumcraft:banner_crimson_cult;{aspect:"",x:17557,y:122,facing:4b,z:19829,id:"thaumcraft:tilebanner",wall:1b}-0
rule57=0,100,teBlock;thaumcraft:banner_crimson_cult;{aspect:"",x:17557,y:122,facing:4b,z:19833,id:"thaumcraft:tilebanner",wall:1b}-0
rule58=0,100,teBlock;thaumcraft:banner_crimson_cult;{aspect:"",x:17557,y:122,facing:4b,z:19837,id:"thaumcraft:tilebanner",wall:1b}-0
rule59=0,100,teBlock;thaumcraft:banner_crimson_cult;{aspect:"",x:17560,y:122,facing:8b,z:19826,id:"thaumcraft:tilebanner",wall:1b}-0
rule60=0,100,teBlock;thaumcraft:banner_crimson_cult;{aspect:"",x:17560,y:122,facing:0b,z:19840,id:"thaumcraft:tilebanner",wall:1b}-0
rule61=0,100,teBlock;thaumcraft:banner_crimson_cult;{aspect:"",x:17564,y:122,facing:8b,z:19826,id:"thaumcraft:tilebanner",wall:1b}-0

rule62=0,100,air

rule63=0,100,teBlock;thaumcraft:banner_crimson_cult;{aspect:"",x:17564,y:122,facing:0b,z:19840,id:"thaumcraft:tilebanner",wall:1b}-0
rule64=0,100,teBlock;thaumcraft:banner_crimson_cult;{aspect:"",x:17568,y:122,facing:8b,z:19826,id:"thaumcraft:tilebanner",wall:1b}-0
rule65=0,100,teBlock;thaumcraft:banner_crimson_cult;{aspect:"",x:17568,y:122,facing:0b,z:19840,id:"thaumcraft:tilebanner",wall:1b}-0
rule66=0,100,teBlock;thaumcraft:banner_crimson_cult;{aspect:"",x:17571,y:122,facing:12b,z:19829,id:"thaumcraft:tilebanner",wall:1b}-0
rule67=0,100,teBlock;thaumcraft:banner_crimson_cult;{aspect:"",x:17571,y:122,facing:12b,z:19833,id:"thaumcraft:tilebanner",wall:1b}-0
rule68=0,100,teBlock;thaumcraft:banner_crimson_cult;{aspect:"",x:17571,y:122,facing:12b,z:19837,id:"thaumcraft:tilebanner",wall:1b}-0

rule69=0,100,air
rule70=0,100,air
rule71=0,100,minecraft:stone_slab-6
rule72=0,100,air
rule73=0,100,air

layer
1,2,2,3,2,2,2,3,2,2,2,3,2,2,2,3,2,2,1
2,3,3,3,3,3,3,3,4,4,4,3,3,3,3,3,3,3,2
2,3,3,3,3,3,3,3,3,3,3,3,3,3,3,3,3,3,2
3,3,3,3,3,3,3,3,3,3,3,3,3,3,3,3,3,3,3
2,3,3,3,3,3,3,3,3,3,3,3,3,3,3,3,3,3,2
2,3,3,3,3,3,3,3,3,3,3,3,3,3,3,3,3,3,2
2,3,3,3,3,3,3,3,3,3,3,3,3,3,3,3,3,3,2
3,3,3,3,3,3,3,3,3,3,3,3,3,3,3,3,3,3,3
2,4,3,3,3,3,3,3,3,3,3,3,3,3,3,3,3,4,2
2,4,3,3,3,3,3,3,3,3,3,3,3,3,3,3,3,4,2
2,4,3,3,3,3,3,3,3,3,3,3,3,3,3,3,3,4,2
3,3,3,3,3,3,3,3,3,3,3,3,3,3,3,3,3,3,3
2,3,3,3,3,3,3,3,3,3,3,3,3,3,3,3,3,3,2
2,3,3,3,3,3,3,3,3,3,3,3,3,3,3,3,3,3,2
2,3,3,3,3,3,3,3,3,3,3,3,3,3,3,3,3,3,2
3,3,3,3,3,3,3,3,3,3,3,3,3,3,3,3,3,3,3
2,3,3,3,3,3,3,3,3,3,3,3,3,3,3,3,3,3,2
2,3,3,3,3,3,3,3,4,4,4,3,3,3,3,3,3,3,2
1,2,2,3,2,2,2,3,2,2,2,3,2,2,2,3,2,2,1
endlayer

layer
1,2,2,3,2,2,2,3,2,2,2,3,2,2,2,3,2,2,1
2,4,3,4,3,4,3,4,1,1,1,4,3,4,3,4,3,4,2
2,3,4,4,4,4,4,4,4,4,4,4,4,4,4,4,4,3,2
3,4,4,4,4,4,4,4,4,4,4,4,4,4,4,4,4,4,3
2,3,4,4,4,4,4,4,4,4,4,4,4,4,4,4,4,3,2
2,4,4,4,4,4,4,4,4,4,4,4,4,4,4,4,4,4,2
2,3,4,4,4,4,4,4,4,4,4,4,4,4,4,4,4,3,2
3,4,4,4,4,4,4,4,4,4,4,4,4,4,4,4,4,4,3
2,1,4,4,4,4,4,4,4,4,4,4,4,4,4,4,4,1,2
2,1,4,4,4,4,4,4,4,4,4,4,4,4,4,4,4,1,2
2,1,4,4,4,4,4,4,4,4,4,4,4,4,4,4,4,1,2
3,4,4,4,4,4,4,4,4,4,4,4,4,4,4,4,4,4,3
2,3,4,4,4,4,4,4,4,4,4,4,4,4,4,4,4,3,2
2,4,4,4,4,4,4,4,4,4,4,4,4,4,4,4,4,4,2
2,3,4,4,4,4,4,4,4,4,4,4,4,4,4,4,4,3,2
3,4,4,4,4,4,4,4,4,4,4,4,4,4,4,4,4,4,3
2,3,4,4,4,4,4,4,1,4,4,4,4,4,4,4,4,3,2
2,4,3,4,3,4,3,4,1,1,1,4,3,4,3,4,3,4,2
1,2,2,3,2,2,2,3,2,2,2,3,2,2,2,3,2,2,1
endlayer

layer
1,2,2,3,2,2,2,3,2,2,2,3,2,2,2,3,2,2,1
2,4,4,4,4,4,4,4,1,1,1,4,4,4,4,4,4,4,2
2,4,4,4,4,4,4,4,4,4,4,4,4,4,4,4,4,4,2
3,4,4,4,4,4,4,4,4,4,4,4,4,4,4,4,4,4,3
2,4,4,4,4,4,4,4,4,4,4,4,4,4,4,4,4,4,2
2,4,4,4,4,4,4,4,4,4,4,4,4,4,4,4,4,4,2
2,4,4,4,4,4,4,4,4,4,4,4,4,4,4,4,4,4,2
3,4,4,4,4,4,4,4,4,4,4,4,4,4,4,4,4,4,3
2,1,4,4,4,4,4,4,4,4,4,4,4,4,4,4,4,1,2
2,1,4,4,4,4,4,4,4,4,4,4,4,4,4,4,4,1,2
2,1,4,4,4,4,4,4,4,4,4,4,4,4,4,4,4,1,2
3,4,4,4,4,4,4,4,4,4,4,4,4,4,4,4,4,4,3
2,4,4,4,4,4,4,4,4,4,4,4,4,4,4,4,4,4,2
2,4,4,4,4,4,4,4,4,4,4,4,4,4,4,4,4,4,2
2,4,4,4,4,4,4,4,4,4,4,4,4,4,4,4,4,4,2
3,4,4,4,4,4,4,4,4,4,4,4,4,4,4,4,4,4,3
2,4,4,4,4,4,4,4,4,4,4,4,4,4,4,4,4,4,2
2,4,4,4,4,4,4,4,1,1,1,4,4,4,4,4,4,4,2
1,2,2,3,2,2,2,3,2,2,2,3,2,2,2,3,2,2,1
endlayer

layer
1,2,2,3,2,2,2,3,2,2,2,3,2,2,2,3,2,2,1
2,4,4,4,3,4,3,4,4,4,4,4,3,4,3,4,4,4,2
2,4,4,4,4,4,4,4,4,4,4,4,4,4,4,4,4,4,2
3,4,4,4,4,4,4,4,4,4,4,4,4,4,4,4,4,4,3
2,3,4,4,4,4,4,4,4,4,4,4,4,4,4,4,4,3,2
2,4,4,4,4,4,4,4,4,4,4,4,4,4,4,4,4,4,2
2,3,4,4,4,4,4,4,4,4,4,4,4,4,4,4,4,3,2
3,4,4,4,4,4,4,4,4,4,4,4,4,4,4,4,4,4,3
2,4,4,4,4,4,4,4,4,4,4,4,4,4,4,4,4,4,2
2,4,4,4,4,4,4,4,4,4,4,4,4,4,4,4,4,4,2
2,4,4,4,4,4,4,4,4,4,4,4,4,4,4,4,4,4,2
3,4,4,4,4,4,4,4,4,4,4,4,4,4,4,4,4,4,3
2,3,4,4,4,4,4,4,4,4,4,4,4,4,4,4,4,3,2
2,4,4,4,4,4,4,4,4,4,4,4,4,4,4,4,4,4,2
2,3,4,4,4,4,4,4,4,4,4,4,4,4,4,4,4,3,2
3,4,4,4,4,4,4,4,4,4,4,4,4,4,4,4,4,4,3
2,4,4,4,4,4,4,4,4,4,4,4,4,4,4,4,4,4,2
2,4,4,4,3,4,3,4,4,4,4,4,3,4,3,4,4,4,2
1,2,2,3,2,2,2,3,2,2,2,3,2,2,2,3,2,2,1
endlayer

layer
1,2,2,3,2,2,2,3,2,2,2,3,2,2,2,3,2,2,1
2,4,3,3,3,3,3,3,2,2,2,3,3,3,3,3,3,4,2
2,3,5,5,5,5,5,5,4,4,4,5,5,5,5,5,5,3,2
3,3,5,5,5,5,5,5,4,4,4,5,5,5,5,5,5,3,3
2,3,5,5,7,6,5,5,5,5,5,5,5,7,6,5,5,3,2
2,3,5,5,9,8,5,7,6,5,7,6,5,9,8,5,5,3,2
2,3,5,5,5,5,5,9,6,10,7,8,5,5,5,5,5,3,2
3,3,5,5,5,7,6,10,9,7,8,10,7,6,5,5,5,3,3
2,2,4,4,5,9,9,6,8,8,9,7,8,8,5,4,4,2,2
2,2,4,4,5,5,10,9,6,10,9,6,10,5,5,4,4,2,2
2,2,4,4,5,7,7,8,6,7,7,9,6,6,5,4,4,2,2
3,3,5,5,5,9,8,10,7,8,6,10,9,8,5,5,5,3,3
2,3,5,5,5,5,5,7,8,10,9,6,5,5,5,5,5,3,2
2,3,5,5,7,6,5,9,8,5,9,8,5,7,6,5,5,3,2
2,3,5,5,9,8,5,5,5,5,5,5,5,9,8,5,5,3,2
3,3,5,5,5,5,5,5,4,4,4,5,5,5,5,5,5,3,3
2,3,5,5,5,5,5,5,4,4,4,5,5,5,5,5,5,3,2
2,4,3,3,3,3,3,3,2,2,2,3,3,3,3,3,3,4,2
1,2,2,3,2,2,2,3,2,2,2,3,2,2,2,3,2,2,1
endlayer

layer
1,2,2,11,2,2,2,11,0,0,0,11,2,2,2,11,2,2,1
2,2,13,3,12,2,13,3,0,0,0,3,12,2,13,3,12,2,2
2,11,1,3,4,4,4,3,0,0,0,3,4,4,4,3,1,11,2
13,3,3,1,0,0,0,3,0,0,0,3,0,0,0,1,3,3,12
2,14,4,0,0,0,0,0,0,0,0,0,0,0,0,0,4,14,2
2,2,4,0,0,0,0,0,0,0,0,0,0,0,0,0,4,2,2
2,11,4,0,0,0,0,0,0,0,0,0,0,0,0,0,4,11,2
13,3,3,3,0,0,0,0,0,0,0,0,0,0,0,3,3,3,12
0,0,0,0,0,0,0,0,0,0,0,0,0,0,0,0,0,0,0
0,0,0,0,0,0,0,0,0,15,0,0,0,0,0,0,0,0,0
0,0,0,0,0,0,0,0,0,0,0,0,0,0,0,0,0,0,0
13,3,3,3,0,0,0,0,0,0,0,0,0,0,0,3,3,3,12
2,14,4,0,0,0,0,0,0,0,0,0,0,0,0,0,4,14,2
2,2,4,0,0,0,0,0,0,0,0,0,0,0,0,0,4,2,2
2,11,4,0,0,0,0,0,0,0,0,0,0,0,0,0,4,11,2
13,3,3,1,0,0,0,3,0,0,0,3,0,0,0,1,3,3,12
2,14,1,3,4,4,4,3,0,0,0,3,4,4,4,3,1,14,2
2,2,13,3,12,2,13,3,0,0,0,3,12,2,13,3,12,2,2
1,2,2,14,2,2,2,14,0,0,0,14,2,2,2,14,2,2,1
endlayer

layer
16,2,2,2,2,2,2,2,0,0,0,2,2,2,2,2,2,2,16
2,2,2,3,2,2,2,3,0,0,0,3,2,2,2,3,2,2,2
2,2,1,3,4,17,4,3,0,0,0,3,4,17,4,3,1,2,2
2,3,3,1,0,0,0,3,0,0,0,3,0,0,0,1,3,3,2
2,2,4,0,0,0,0,0,0,0,0,0,0,0,0,0,4,2,2
2,2,17,0,0,0,0,0,0,0,0,0,0,0,0,0,17,2,2
2,2,4,0,0,0,0,0,0,0,0,0,0,0,0,0,4,2,2
2,3,3,3,0,0,0,0,0,0,0,0,0,0,0,3,3,3,2
0,0,0,0,0,0,0,0,0,0,0,0,0,0,0,0,0,0,0
0,0,0,0,0,0,0,0,0,18,0,0,0,0,0,0,0,0,0
0,0,0,0,0,0,0,0,0,0,0,0,0,0,0,0,0,0,0
2,3,3,3,0,0,0,0,0,0,0,0,0,0,0,3,3,3,2
2,2,4,0,0,0,0,0,0,0,0,0,0,0,0,0,4,2,2
2,2,17,0,0,0,0,0,0,0,0,0,0,0,0,0,17,2,2
2,2,4,0,0,0,0,0,0,0,0,0,0,0,0,0,4,2,2
2,3,3,1,0,0,0,3,0,0,0,3,0,0,0,1,3,3,0
2,2,1,3,4,17,4,3,0,0,0,3,4,17,4,3,1,2,2
2,2,2,3,2,2,2,3,0,0,0,3,2,2,2,3,2,2,2
16,2,2,2,2,2,2,2,0,0,0,2,2,2,2,2,2,2,16
endlayer

layer
2,2,2,2,2,2,2,2,0,0,0,2,2,2,2,2,2,2,2
2,2,2,3,2,2,2,3,0,0,0,3,2,2,2,3,2,2,2
2,2,1,3,17,17,17,3,0,0,0,3,17,17,17,3,1,2,2
2,3,3,1,0,0,0,3,0,0,0,3,0,0,0,1,3,3,2
2,2,17,0,0,0,0,0,0,0,0,0,0,0,0,0,17,2,2
2,2,17,0,0,0,0,0,0,0,0,0,0,0,0,0,17,2,2
2,2,17,0,0,0,0,0,0,0,0,0,0,0,0,0,17,2,2
2,3,3,3,0,0,0,0,0,0,0,0,0,0,0,3,3,3,2
0,0,0,0,0,0,0,0,0,0,0,0,0,0,0,0,0,0,0
0,0,0,0,0,0,0,0,0,19,0,0,0,0,0,0,0,0,0
0,0,0,0,0,0,0,0,0,0,0,0,0,0,0,0,0,0,0
2,3,3,3,0,0,0,0,0,0,0,0,0,0,0,3,3,3,2
2,2,17,0,0,0,0,0,0,0,0,0,0,0,0,0,17,2,2
2,2,17,0,0,0,0,0,0,0,0,0,0,0,0,0,17,2,2
2,2,17,0,0,0,0,0,0,0,0,0,0,0,0,0,17,2,2
2,3,3,1,0,0,0,3,0,0,0,3,0,0,0,1,3,3,0
2,2,1,3,17,17,17,3,0,0,0,3,17,17,17,3,1,2,2
2,2,2,3,2,2,2,3,0,0,0,3,2,2,2,3,2,2,2
2,2,2,2,2,2,2,2,0,0,0,2,2,2,2,2,2,2,2
endlayer

layer
2,2,2,0,2,2,2,0,0,0,0,0,2,2,2,0,2,2,2
2,2,2,3,2,2,2,3,21,0,20,3,2,2,2,3,2,2,2
2,2,1,3,17,17,17,3,21,0,20,3,17,17,17,3,1,2,2
0,3,3,1,0,0,0,3,21,0,20,3,0,0,0,1,3,3,0
2,2,17,0,0,0,0,0,0,0,0,0,0,0,0,0,17,2,2
2,2,17,0,0,0,0,0,0,0,0,0,0,0,0,0,17,2,2
2,2,17,0,0,0,0,0,0,0,0,0,0,0,0,0,17,2,2
0,3,3,3,0,0,0,0,0,0,0,0,0,0,0,3,3,3,0
0,22,22,22,0,0,0,0,0,0,0,0,0,0,0,22,22,22,0
0,0,0,0,0,0,0,0,0,23,0,0,0,0,0,0,0,0,0
0,24,24,24,0,0,0,0,0,0,0,0,0,0,0,24,24,24,0
0,3,3,3,0,0,0,0,0,0,0,0,0,0,0,3,3,3,0
2,2,17,0,0,0,0,0,0,0,0,0,0,0,0,0,17,2,2
2,2,17,0,0,0,0,0,0,0,0,0,0,0,0,0,17,2,2
2,2,17,0,0,0,0,0,0,0,0,0,0,0,0,0,17,2,2
0,3,3,1,0,0,0,3,21,0,20,3,0,0,0,1,3,3,0
2,2,1,3,17,17,17,3,21,0,20,3,17,17,17,3,1,2,2
2,2,2,3,2,2,2,3,21,0,20,3,2,2,2,3,2,2,2
2,2,2,0,2,2,2,0,0,0,0,0,2,2,2,0,2,2,2
endlayer

layer
2,2,2,28,2,2,2,27,0,0,0,26,2,2,2,25,2,2,2
2,2,2,3,2,2,2,3,3,3,3,3,2,2,2,3,2,2,2
2,2,1,3,4,17,4,3,1,3,1,3,4,17,4,3,1,2,2
30,3,3,1,0,0,0,3,3,3,3,3,0,0,0,1,3,3,29
2,2,4,0,0,0,0,0,0,0,0,0,0,0,0,0,4,2,2
2,2,17,0,0,0,0,0,0,0,0,0,0,0,0,0,17,2,2
2,2,4,0,0,0,0,0,0,0,0,0,0,0,0,0,4,2,2
32,3,3,3,0,0,0,0,0,0,0,0,0,0,0,3,3,3,31
0,3,1,3,0,0,0,0,0,0,0,0,0,0,0,3,1,3,0
0,3,3,3,0,0,0,0,0,33,0,0,0,0,0,3,3,3,0
0,3,1,3,0,0,0,0,0,0,0,0,0,0,0,3,1,3,0
35,3,3,3,0,0,0,0,0,0,0,0,0,0,0,3,3,3,34
2,2,4,0,0,0,0,0,0,0,0,0,0,0,0,0,4,2,2
2,2,17,0,0,0,0,0,0,0,0,0,0,0,0,0,17,2,2
2,2,4,0,0,0,0,0,0,0,0,0,0,0,0,0,4,2,2
37,3,3,1,0,0,0,3,3,3,3,3,0,0,0,1,3,3,36
2,2,1,3,4,17,4,3,1,3,1,3,4,17,4,3,1,2,2
2,2,2,3,2,2,2,3,3,3,3,3,2,2,2,3,2,2,2
2,2,2,41,2,2,2,40,0,0,0,39,2,2,2,38,2,2,2
endlayer

layer
2,2,2,24,2,2,2,24,2,2,2,24,2,2,2,24,2,2,2
2,2,20,3,21,2,20,3,0,0,0,3,21,2,20,3,21,2,2
2,24,1,3,4,4,4,3,1,1,1,3,4,4,4,3,1,24,2
20,3,3,1,0,0,0,3,0,0,0,3,0,0,0,1,3,3,21
2,22,4,0,0,0,0,22,0,0,0,22,0,0,0,0,4,22,2
2,2,4,0,0,0,0,0,0,0,0,0,0,0,0,0,4,2,2
2,24,4,0,0,0,0,0,0,0,0,0,0,0,0,0,4,24,2
20,3,3,3,21,0,0,0,0,0,0,0,0,0,20,3,3,3,21
2,0,1,0,0,0,0,0,0,0,0,0,0,0,0,0,1,0,2
2,0,1,0,0,0,0,0,0,42,0,0,0,0,0,0,1,0,2
2,0,1,0,0,0,0,0,0,0,0,0,0,0,0,0,1,0,2
20,3,3,3,21,0,0,0,0,0,0,0,0,0,20,3,3,3,21
2,22,4,0,0,0,0,0,0,0,0,0,0,0,0,0,4,22,2
2,2,4,0,0,0,0,0,0,0,0,0,0,0,0,0,4,2,2
2,24,4,0,0,0,0,24,0,0,0,24,0,0,0,0,4,24,2
20,3,3,1,0,0,0,3,0,0,0,3,0,0,0,1,3,3,21
2,22,1,3,4,4,4,3,1,1,1,3,4,4,4,3,1,22,2
2,2,20,3,21,2,20,3,0,0,0,3,21,2,20,3,21,2,2
2,2,2,22,2,2,2,22,2,2,2,22,2,2,2,22,2,2,2
endlayer

layer
2,24,2,3,2,24,2,3,2,24,2,3,2,24,2,3,2,24,2
20,3,3,3,3,3,3,3,3,3,3,3,3,3,3,3,3,3,21
2,3,3,3,3,3,3,3,3,3,3,3,3,3,3,3,3,3,2
3,3,3,3,3,3,3,3,3,3,3,3,3,3,3,3,3,3,3
2,3,3,3,21,22,22,3,3,3,3,3,22,22,22,3,3,3,2
20,3,3,3,21,0,0,22,0,22,0,22,0,0,20,3,3,3,21
2,3,3,3,21,0,0,0,0,0,0,0,0,0,20,3,3,3,2
3,3,3,3,3,21,0,0,0,0,0,0,0,20,3,3,3,3,3
2,3,3,3,3,0,0,0,0,0,0,0,0,0,3,3,3,3,2
20,3,3,3,3,21,0,0,0,43,0,0,0,20,3,3,3,3,21
2,3,3,3,3,0,0,0,0,0,0,0,0,0,3,3,3,3,2
3,3,3,3,3,21,0,0,0,0,0,0,0,20,3,3,3,3,3
2,3,3,3,21,0,0,0,0,0,0,0,0,0,20,3,3,3,2
20,3,3,3,21,0,0,24,0,24,0,24,0,0,20,3,3,3,21
2,3,3,3,24,24,24,3,3,3,3,3,24,24,20,3,3,3,2
3,3,3,3,3,3,3,3,3,3,3,3,3,3,3,3,3,3,3
2,3,3,3,3,3,3,3,3,3,3,3,3,3,3,3,3,3,2
20,3,3,3,3,3,3,3,3,3,3,3,3,3,3,3,3,3,21
2,22,2,3,2,22,2,3,2,22,2,3,2,22,2,3,2,22,2
endlayer

layer
2,14,2,14,2,14,2,14,2,14,2,14,2,14,2,14,2,14,2
12,4,2,0,2,0,2,0,2,0,2,0,2,0,2,0,2,4,13
2,2,2,0,13,44,12,0,13,44,12,0,13,44,12,0,2,2,2
12,0,0,3,3,3,3,3,3,3,3,3,3,3,3,3,0,0,13
2,2,11,3,3,3,3,3,3,3,3,3,3,3,3,3,11,2,2
12,0,44,3,3,4,4,4,4,4,4,4,4,4,3,3,44,0,13
2,2,14,3,3,4,47,46,46,46,46,46,45,4,3,3,14,2,2
12,0,0,3,3,4,47,0,0,0,0,0,45,4,3,3,0,0,13
2,2,11,3,3,4,47,0,0,0,0,0,45,4,3,3,11,2,2
12,0,44,3,3,4,47,0,0,48,0,0,45,4,3,3,44,0,13
2,2,14,3,3,4,47,0,0,0,0,0,45,4,3,3,14,2,2
12,0,0,3,3,4,47,0,0,0,0,0,45,4,3,3,0,0,13
2,2,11,3,3,4,47,49,49,49,49,49,45,4,3,3,11,2,2
12,0,44,3,3,4,4,4,4,4,4,4,4,4,3,3,44,0,13
2,2,14,3,3,3,3,3,3,3,3,3,3,3,3,3,14,2,2
12,0,0,3,3,3,3,3,3,3,3,3,3,3,3,3,0,0,13
2,2,2,0,13,44,12,0,13,44,12,0,13,44,12,0,2,2,2
12,4,2,0,2,0,2,0,2,0,2,0,2,0,2,0,2,4,13
2,11,2,11,2,11,2,11,2,11,2,11,2,11,2,11,2,11,2
endlayer

layer
2,2,2,2,2,2,2,2,2,2,2,2,2,2,2,2,2,2,2
2,4,2,2,2,2,2,2,2,2,2,2,2,2,2,2,2,4,2
2,2,2,2,2,11,2,2,2,11,2,2,2,11,2,2,2,2,2
2,2,2,0,13,3,12,0,13,3,12,0,13,3,12,0,2,2,2
2,2,2,11,1,50,4,4,4,3,4,4,4,3,1,11,2,2,2
2,2,13,3,3,1,0,0,0,1,0,0,0,1,3,3,12,2,2
2,2,2,14,4,0,0,0,0,0,0,0,0,0,4,14,2,2,2
2,2,2,0,4,0,0,0,0,0,0,0,0,0,4,0,2,2,2
2,2,2,11,4,0,0,0,0,0,0,0,0,0,4,11,2,2,2
2,2,13,3,3,1,0,0,0,51,0,0,0,1,3,3,12,2,2
2,2,2,14,4,0,0,0,0,0,0,0,0,0,4,14,2,2,2
2,2,2,0,4,0,0,0,0,0,0,0,0,0,4,0,2,2,2
2,2,2,11,4,0,0,0,0,0,0,0,0,0,4,11,2,2,2
2,2,13,3,3,1,0,0,0,1,0,0,0,1,3,3,12,2,2
2,2,2,14,1,3,4,4,4,3,4,4,4,52,1,14,2,2,2
2,2,2,0,13,3,12,0,13,3,12,0,13,3,12,0,2,2,2
2,2,2,2,2,14,2,2,2,14,2,2,2,14,2,2,2,2,2
2,4,2,2,2,2,2,2,2,2,2,2,2,2,2,2,2,4,2
2,2,2,2,2,2,2,2,2,2,2,2,2,2,2,2,2,2,2
endlayer

layer
2,2,2,2,2,2,2,2,2,2,2,2,2,2,2,2,2,2,2
2,16,2,2,2,2,2,2,2,2,2,2,2,2,2,2,2,16,2
2,2,2,2,2,2,2,2,2,2,2,2,2,2,2,2,2,2,2
2,2,2,0,0,3,0,0,0,3,0,0,0,3,0,0,2,2,2
2,2,2,0,1,3,4,17,4,3,4,17,4,3,1,0,2,2,2
2,2,2,3,3,1,0,0,0,1,0,0,0,1,3,3,2,2,2
2,2,2,0,4,0,0,0,0,0,0,0,0,0,4,0,2,2,2
2,2,2,0,17,0,0,0,0,0,0,0,0,0,17,0,2,2,2
2,2,2,0,4,0,0,0,0,0,0,0,0,0,4,0,2,2,2
2,2,2,3,3,1,0,0,0,53,0,0,0,1,3,3,2,2,2
2,2,2,0,4,0,0,0,0,0,0,0,0,0,4,0,2,2,2
2,2,2,0,17,0,0,0,0,0,0,0,0,0,17,0,2,2,2
2,2,2,0,4,0,0,0,0,0,0,0,0,0,4,0,2,2,2
2,2,2,3,3,1,0,0,0,1,0,0,0,1,3,3,2,2,2
2,2,2,0,1,3,4,17,4,3,4,17,4,3,1,0,2,2,2
2,2,2,0,0,3,0,0,0,3,0,0,0,3,0,0,2,2,2
2,2,2,2,2,2,2,2,2,2,2,2,2,2,2,2,2,2,2
2,16,2,2,2,2,2,2,2,2,2,2,2,2,2,2,2,16,2
2,2,2,2,2,2,2,2,2,2,2,2,2,2,2,2,2,2,2
endlayer

layer
2,2,2,2,2,2,2,2,2,2,2,2,2,2,2,2,2,2,2
2,2,2,2,2,2,2,2,2,2,2,2,2,2,2,2,2,2,2
2,2,2,2,2,2,2,2,2,2,2,2,2,2,2,2,2,2,2
2,2,2,0,0,3,0,0,0,3,0,0,0,3,0,0,2,2,2
2,2,2,0,1,3,17,17,17,3,17,17,17,3,1,0,2,2,2
2,2,2,3,3,1,0,0,0,1,0,0,0,1,3,3,2,2,2
2,2,2,0,17,0,0,0,0,0,0,0,0,0,17,0,2,2,2
2,2,2,0,17,0,0,0,0,0,0,0,0,0,17,0,2,2,2
2,2,2,0,17,0,0,0,0,0,0,0,0,0,17,0,2,2,2
2,2,2,3,3,1,0,0,0,54,0,0,0,1,3,3,2,2,2
2,2,2,0,17,0,0,0,0,0,0,0,0,0,17,0,2,2,2
2,2,2,0,17,0,0,0,0,0,0,0,0,0,17,0,2,2,2
2,2,2,0,17,0,0,0,0,0,0,0,0,0,17,0,2,2,2
2,2,2,3,3,1,0,0,0,1,0,0,0,1,3,3,2,2,2
2,2,2,0,1,3,17,17,17,3,17,17,17,3,1,0,2,2,2
2,2,2,0,0,3,0,0,0,3,0,0,0,3,0,0,2,2,2
2,2,2,2,2,2,2,2,2,2,2,2,2,2,2,2,2,2,2
2,2,2,2,2,2,2,2,2,2,2,2,2,2,2,2,2,2,2
2,2,2,2,2,2,2,2,2,2,2,2,2,2,2,2,2,2,2
endlayer

layer
2,2,2,2,2,2,2,2,2,2,2,2,2,2,2,2,2,2,2
2,2,2,2,2,2,2,2,2,2,2,2,2,2,2,2,2,2,2
2,2,2,2,2,2,2,2,2,2,2,2,2,2,2,2,2,2,2
2,2,2,0,0,3,0,0,0,3,0,0,0,3,0,0,2,2,2
2,2,2,0,1,3,17,17,17,3,17,17,17,3,1,0,2,2,2
2,2,2,3,3,1,0,0,0,1,0,0,0,1,3,3,2,2,2
2,2,2,0,17,0,0,0,0,0,0,0,0,0,17,0,2,2,2
2,2,2,0,17,0,0,0,0,0,0,0,0,0,17,0,2,2,2
2,2,2,0,17,0,0,0,0,0,0,0,0,0,17,0,2,2,2
2,2,2,3,3,1,0,0,0,55,0,0,0,1,3,3,2,2,2
2,2,2,0,17,0,0,0,0,0,0,0,0,0,17,0,2,2,2
2,2,2,0,17,0,0,0,0,0,0,0,0,0,17,0,2,2,2
2,2,2,0,17,0,0,0,0,0,0,0,0,0,17,0,2,2,2
2,2,2,3,3,1,0,0,0,1,0,0,0,1,3,3,2,2,2
2,2,2,0,1,3,17,17,17,3,17,17,17,3,1,0,2,2,2
2,2,2,0,0,3,0,0,0,3,0,0,0,3,0,0,2,2,2
2,2,2,2,2,0,2,2,2,2,2,2,2,2,2,2,2,2,2
2,2,2,2,2,2,2,2,2,2,2,2,2,2,2,2,2,2,2
2,2,2,2,2,2,2,2,2,2,2,2,2,2,2,2,2,2,2
endlayer

layer
2,2,2,2,2,0,2,2,2,0,2,2,2,0,2,2,2,2,2
2,2,2,2,2,0,2,2,2,0,2,2,2,0,2,2,2,2,2
2,2,2,2,2,58,2,2,2,57,2,2,2,56,2,2,2,2,2
2,2,2,0,0,3,0,0,0,3,0,0,0,3,0,0,2,2,2
2,2,2,0,1,3,4,17,4,3,4,17,4,3,1,0,2,2,2
0,0,60,3,3,1,0,0,0,1,0,0,0,1,3,3,59,0,0
2,2,2,0,4,0,0,0,0,0,0,0,0,0,4,0,2,2,2
2,2,2,0,17,0,0,0,0,0,0,0,0,0,17,0,2,2,2
2,2,2,0,4,0,0,0,0,0,0,0,0,0,4,0,2,2,2
0,0,63,3,3,1,0,0,0,62,0,0,0,1,3,3,61,0,0
2,2,2,0,4,0,0,0,0,0,0,0,0,0,4,0,2,2,2
2,2,2,0,17,0,0,0,0,0,0,0,0,0,17,0,2,2,2
2,2,2,0,4,0,0,0,0,0,0,0,0,0,4,0,2,2,2
0,0,65,3,3,1,0,0,0,1,0,0,0,1,3,3,64,0,0
2,2,2,0,1,3,4,17,4,3,4,17,4,3,1,0,2,2,2
2,2,2,0,0,3,0,0,0,3,0,0,0,3,0,0,2,2,2
2,2,2,2,2,68,2,2,2,67,2,2,2,66,2,2,2,2,2
2,2,2,2,2,0,2,2,2,0,2,2,2,0,2,2,2,2,2
2,2,2,2,2,0,2,2,2,0,2,2,2,0,2,2,2,2,2
endlayer

layer
2,2,2,2,2,2,2,2,2,2,2,2,2,2,2,2,2,2,2
2,2,2,2,2,2,2,2,2,2,2,2,2,2,2,2,2,2,2
2,2,2,2,2,24,2,2,2,24,2,2,2,24,2,2,2,2,2
2,2,2,0,20,3,21,0,20,3,21,0,20,3,21,0,2,2,2
2,2,2,24,1,3,4,4,4,3,4,4,4,3,1,24,2,2,2
2,2,20,3,3,1,0,0,0,1,0,0,0,1,3,3,21,2,2
2,2,2,22,4,0,0,0,0,0,0,0,0,0,4,22,2,2,2
2,2,2,0,4,0,0,0,0,0,0,0,0,0,4,0,2,2,2
2,2,2,24,4,0,0,0,0,0,0,0,0,0,4,24,2,2,2
2,2,20,3,3,1,0,0,0,69,0,0,0,1,3,3,21,2,2
2,2,2,22,4,0,0,0,0,0,0,0,0,0,4,22,2,2,2
2,2,2,0,4,0,0,0,0,0,0,0,0,0,4,0,2,2,2
2,2,2,24,4,0,0,0,0,0,0,0,0,0,4,24,2,2,2
2,2,20,3,3,1,0,0,0,1,0,0,0,1,3,3,21,2,2
2,2,2,22,1,3,4,4,4,3,4,4,4,3,1,22,2,2,2
2,2,2,0,20,3,21,0,20,3,21,0,20,3,21,0,2,2,2
2,2,2,2,2,22,2,2,2,22,2,2,2,22,2,2,2,2,2
2,2,2,2,2,2,2,2,2,2,2,2,2,2,2,2,2,2,2
2,2,2,2,2,2,2,2,2,2,2,2,2,2,2,2,2,2,2
endlayer

layer
2,2,2,2,2,2,2,2,2,2,2,2,2,2,2,2,2,2,2
2,2,2,2,2,2,2,2,2,2,2,2,2,2,2,2,2,2,2
2,2,2,24,2,3,2,24,2,3,2,24,2,3,2,24,2,2,2
2,2,20,3,3,3,3,3,3,3,3,3,3,3,3,3,21,2,2
2,2,2,3,4,4,4,4,4,4,4,4,4,4,4,3,2,2,2
2,2,3,3,4,4,4,4,4,4,4,4,4,4,4,3,3,2,2
2,2,2,3,4,4,46,46,46,46,46,46,45,4,4,3,2,2,2
2,2,20,3,4,4,47,0,0,0,0,0,45,4,4,3,21,2,2
2,2,2,3,4,4,47,0,0,0,0,0,45,4,4,3,2,2,2
2,2,3,3,4,4,47,0,0,70,0,0,45,4,4,3,3,2,2
2,2,2,3,4,4,47,0,0,0,0,0,45,4,4,3,2,2,2
2,2,20,3,4,4,47,0,0,0,0,0,45,4,4,3,21,2,2
2,2,2,3,4,4,47,49,49,49,49,49,45,4,4,3,2,2,2
2,2,3,3,4,4,4,4,4,4,4,4,4,4,4,3,3,2,2
2,2,2,3,4,4,4,4,4,4,4,4,4,4,4,3,2,2,2
2,2,20,3,3,3,3,3,3,3,3,3,3,3,3,3,21,2,2
2,2,2,22,2,3,2,22,2,3,2,22,2,3,2,22,2,2,2
2,2,2,2,2,2,2,2,2,2,2,2,2,2,2,2,2,2,2
2,2,2,2,2,2,2,2,2,2,2,2,2,2,2,2,2,2,2
endlayer

layer
2,2,2,2,2,2,2,2,2,2,2,2,2,2,2,2,2,2,2
2,2,2,2,2,2,2,2,2,2,2,2,2,2,2,2,2,2,2
2,2,2,14,2,14,2,14,2,14,2,14,2,14,2,14,2,2,2
2,2,12,0,71,4,4,4,4,4,4,4,4,4,71,0,13,2,2
2,2,2,71,4,4,4,4,4,4,4,4,4,4,4,71,2,2,2
2,2,12,4,4,4,4,4,4,4,4,4,4,4,4,4,13,2,2
2,2,2,4,4,4,4,4,4,4,4,4,4,4,4,4,2,2,2
2,2,12,4,4,4,4,46,46,46,46,45,4,4,4,4,13,2,2
2,2,2,4,4,4,4,47,0,0,0,45,4,4,4,4,2,2,2
2,2,12,4,4,4,4,47,0,72,0,45,4,4,4,4,13,2,2
2,2,2,4,4,4,4,47,0,0,0,45,4,4,4,4,2,2,2
2,2,12,4,4,4,4,49,49,49,49,49,4,4,4,4,13,2,2
2,2,2,4,4,4,4,4,4,4,4,4,4,4,4,4,2,2,2
2,2,12,4,4,4,4,4,4,4,4,4,4,4,4,4,13,2,2
2,2,2,71,4,4,4,4,4,4,4,4,4,4,4,71,2,2,2
2,2,12,0,71,4,4,4,4,4,4,4,4,4,71,0,13,2,2
2,2,2,11,2,11,2,11,2,11,2,11,2,11,2,11,2,2,2
2,2,2,2,2,2,2,2,2,2,2,2,2,2,2,2,2,2,2
2,2,2,2,2,2,2,2,2,2,2,2,2,2,2,2,2,2,2
endlayer

layer
2,2,2,2,2,2,2,2,2,2,2,2,2,2,2,2,2,2,2
2,2,2,2,2,2,2,2,2,2,2,2,2,2,2,2,2,2,2
2,2,2,2,2,2,2,2,2,2,2,2,2,2,2,2,2,2,2
2,2,2,2,2,2,2,71,4,4,4,71,2,2,2,2,2,2,2
2,2,2,2,71,4,4,4,4,4,4,4,4,4,71,2,2,2,2
2,2,2,2,4,4,4,4,4,4,4,4,4,4,4,2,2,2,2
2,2,2,2,4,4,4,4,4,4,4,4,4,4,4,2,2,2,2
2,2,2,71,4,4,4,4,4,4,4,4,4,4,4,71,2,2,2
2,2,2,4,4,4,4,4,47,46,45,4,4,4,4,4,2,2,2
2,2,2,4,4,4,4,4,47,73,45,4,4,4,4,4,2,2,2
2,2,2,4,4,4,4,4,47,49,45,4,4,4,4,4,2,2,2
2,2,2,71,4,4,4,4,4,4,4,4,4,4,4,71,2,2,2
2,2,2,2,4,4,4,4,4,4,4,4,4,4,4,2,2,2,2
2,2,2,2,4,4,4,4,4,4,4,4,4,4,4,2,2,2,2
2,2,2,2,71,4,4,4,4,4,4,4,4,4,71,2,2,2,2
2,2,2,2,2,2,2,71,4,4,4,71,2,2,2,2,2,2,2
2,2,2,2,2,2,2,2,2,2,2,2,2,2,2,2,2,2,2
2,2,2,2,2,2,2,2,2,2,2,2,2,2,2,2,2,2,2
2,2,2,2,2,2,2,2,2,2,2,2,2,2,2,2,2,2,2
endlayer

layer
2,2,2,2,2,2,2,2,2,2,2,2,2,2,2,2,2,2,2
2,2,2,2,2,2,2,2,2,2,2,2,2,2,2,2,2,2,2
2,2,2,2,2,2,2,2,2,2,2,2,2,2,2,2,2,2,2
2,2,2,2,2,2,2,2,2,71,2,2,2,2,2,2,2,2,2
2,2,2,2,2,71,4,4,4,4,4,4,4,71,2,2,2,2,2
2,2,2,2,71,4,4,4,4,4,4,4,4,4,71,2,2,2,2
2,2,2,2,4,4,4,4,4,4,4,4,4,4,4,2,2,2,2
2,2,2,2,4,4,4,4,4,4,4,4,4,4,4,2,2,2,2
2,2,2,2,4,4,4,4,4,4,4,4,4,4,4,2,2,2,2
2,2,2,71,4,4,4,4,4,4,4,4,4,4,4,71,2,2,2
2,2,2,2,4,4,4,4,4,4,4,4,4,4,4,2,2,2,2
2,2,2,2,4,4,4,4,4,4,4,4,4,4,4,2,2,2,2
2,2,2,2,4,4,4,4,4,4,4,4,4,4,4,2,2,2,2
2,2,2,2,71,4,4,4,4,4,4,4,4,4,71,2,2,2,2
2,2,2,2,2,71,4,4,4,4,4,4,4,71,2,2,2,2,2
2,2,2,2,2,2,2,2,2,71,2,2,2,2,2,2,2,2,2
2,2,2,2,2,2,2,2,2,2,2,2,2,2,2,2,2,2,2
2,2,2,2,2,2,2,2,2,2,2,2,2,2,2,2,2,2,2
2,2,2,2,2,2,2,2,2,2,2,2,2,2,2,2,2,2,2
endlayer

layer
2,2,2,2,2,2,2,2,2,2,2,2,2,2,2,2,2,2,2
2,2,2,2,2,2,2,2,2,2,2,2,2,2,2,2,2,2,2
2,2,2,2,2,2,2,2,2,2,2,2,2,2,2,2,2,2,2
2,2,2,2,2,2,2,2,2,2,2,2,2,2,2,2,2,2,2
2,2,2,2,2,2,2,2,71,4,71,2,2,2,2,2,2,2,2
2,2,2,2,2,71,4,4,4,4,4,4,4,71,2,2,2,2,2
2,2,2,2,2,4,4,4,4,4,4,4,4,4,2,2,2,2,2
2,2,2,2,2,4,4,4,4,4,4,4,4,4,2,2,2,2,2
2,2,2,2,71,4,4,4,4,4,4,4,4,4,71,2,2,2,2
2,2,2,2,4,4,4,4,4,4,4,4,4,4,4,2,2,2,2
2,2,2,2,71,4,4,4,4,4,4,4,4,4,71,2,2,2,2
2,2,2,2,2,4,4,4,4,4,4,4,4,4,2,2,2,2,2
2,2,2,2,2,4,4,4,4,4,4,4,4,4,2,2,2,2,2
2,2,2,2,2,71,4,4,4,4,4,4,4,71,2,2,2,2,2
2,2,2,2,2,2,2,2,71,4,71,2,2,2,2,2,2,2,2
2,2,2,2,2,2,2,2,2,2,2,2,2,2,2,2,2,2,2
2,2,2,2,2,2,2,2,2,2,2,2,2,2,2,2,2,2,2
2,2,2,2,2,2,2,2,2,2,2,2,2,2,2,2,2,2,2
2,2,2,2,2,2,2,2,2,2,2,2,2,2,2,2,2,2,2
endlayer

layer
2,2,2,2,2,2,2,2,2,2,2,2,2,2,2,2,2,2,2
2,2,2,2,2,2,2,2,2,2,2,2,2,2,2,2,2,2,2
2,2,2,2,2,2,2,2,2,2,2,2,2,2,2,2,2,2,2
2,2,2,2,2,2,2,2,2,2,2,2,2,2,2,2,2,2,2
2,2,2,2,2,2,2,2,2,2,2,2,2,2,2,2,2,2,2
2,2,2,2,2,2,71,4,4,4,4,4,71,2,2,2,2,2,2
2,2,2,2,2,71,4,4,4,4,4,4,4,71,2,2,2,2,2
2,2,2,2,2,4,4,4,4,4,4,4,4,4,2,2,2,2,2
2,2,2,2,2,4,4,4,4,4,4,4,4,4,2,2,2,2,2
2,2,2,2,2,4,4,4,4,4,4,4,4,4,2,2,2,2,2
2,2,2,2,2,4,4,4,4,4,4,4,4,4,2,2,2,2,2
2,2,2,2,2,4,4,4,4,4,4,4,4,4,2,2,2,2,2
2,2,2,2,2,71,4,4,4,4,4,4,4,71,2,2,2,2,2
2,2,2,2,2,2,71,4,4,4,4,4,71,2,2,2,2,2,2
2,2,2,2,2,2,2,2,2,2,2,2,2,2,2,2,2,2,2
2,2,2,2,2,2,2,2,2,2,2,2,2,2,2,2,2,2,2
2,2,2,2,2,2,2,2,2,2,2,2,2,2,2,2,2,2,2
2,2,2,2,2,2,2,2,2,2,2,2,2,2,2,2,2,2,2
2,2,2,2,2,2,2,2,2,2,2,2,2,2,2,2,2,2,2
endlayer

layer
2,2,2,2,2,2,2,2,2,2,2,2,2,2,2,2,2,2,2
2,2,2,2,2,2,2,2,2,2,2,2,2,2,2,2,2,2,2
2,2,2,2,2,2,2,2,2,2,2,2,2,2,2,2,2,2,2
2,2,2,2,2,2,2,2,2,2,2,2,2,2,2,2,2,2,2
2,2,2,2,2,2,2,2,2,2,2,2,2,2,2,2,2,2,2
2,2,2,2,2,2,2,2,2,71,2,2,2,2,2,2,2,2,2
2,2,2,2,2,2,71,4,4,4,4,4,71,2,2,2,2,2,2
2,2,2,2,2,2,4,4,4,4,4,4,4,2,2,2,2,2,2
2,2,2,2,2,2,4,4,4,4,4,4,4,2,2,2,2,2,2
2,2,2,2,2,71,4,4,4,4,4,4,4,71,2,2,2,2,2
2,2,2,2,2,2,4,4,4,4,4,4,4,2,2,2,2,2,2
2,2,2,2,2,2,4,4,4,4,4,4,4,2,2,2,2,2,2
2,2,2,2,2,2,71,4,4,4,4,4,71,2,2,2,2,2,2
2,2,2,2,2,2,2,2,2,71,2,2,2,2,2,2,2,2,2
2,2,2,2,2,2,2,2,2,2,2,2,2,2,2,2,2,2,2
2,2,2,2,2,2,2,2,2,2,2,2,2,2,2,2,2,2,2
2,2,2,2,2,2,2,2,2,2,2,2,2,2,2,2,2,2,2
2,2,2,2,2,2,2,2,2,2,2,2,2,2,2,2,2,2,2
2,2,2,2,2,2,2,2,2,2,2,2,2,2,2,2,2,2,2
endlayer

layer
2,2,2,2,2,2,2,2,2,2,2,2,2,2,2,2,2,2,2
2,2,2,2,2,2,2,2,2,2,2,2,2,2,2,2,2,2,2
2,2,2,2,2,2,2,2,2,2,2,2,2,2,2,2,2,2,2
2,2,2,2,2,2,2,2,2,2,2,2,2,2,2,2,2,2,2
2,2,2,2,2,2,2,2,2,2,2,2,2,2,2,2,2,2,2
2,2,2,2,2,2,2,2,2,2,2,2,2,2,2,2,2,2,2
2,2,2,2,2,2,2,71,4,4,4,71,2,2,2,2,2,2,2
2,2,2,2,2,2,71,4,4,4,4,4,71,2,2,2,2,2,2
2,2,2,2,2,2,4,4,4,4,4,4,4,2,2,2,2,2,2
2,2,2,2,2,2,4,4,4,4,4,4,4,2,2,2,2,2,2
2,2,2,2,2,2,4,4,4,4,4,4,4,2,2,2,2,2,2
2,2,2,2,2,2,71,4,4,4,4,4,71,2,2,2,2,2,2
2,2,2,2,2,2,2,71,4,4,4,71,2,2,2,2,2,2,2
2,2,2,2,2,2,2,2,2,2,2,2,2,2,2,2,2,2,2
2,2,2,2,2,2,2,2,2,2,2,2,2,2,2,2,2,2,2
2,2,2,2,2,2,2,2,2,2,2,2,2,2,2,2,2,2,2
2,2,2,2,2,2,2,2,2,2,2,2,2,2,2,2,2,2,2
2,2,2,2,2,2,2,2,2,2,2,2,2,2,2,2,2,2,2
2,2,2,2,2,2,2,2,2,2,2,2,2,2,2,2,2,2,2
endlayer

layer
2,2,2,2,2,2,2,2,2,2,2,2,2,2,2,2,2,2,2
2,2,2,2,2,2,2,2,2,2,2,2,2,2,2,2,2,2,2
2,2,2,2,2,2,2,2,2,2,2,2,2,2,2,2,2,2,2
2,2,2,2,2,2,2,2,2,2,2,2,2,2,2,2,2,2,2
2,2,2,2,2,2,2,2,2,2,2,2,2,2,2,2,2,2,2
2,2,2,2,2,2,2,2,2,2,2,2,2,2,2,2,2,2,2
2,2,2,2,2,2,2,2,2,2,2,2,2,2,2,2,2,2,2
2,2,2,2,2,2,2,71,4,4,4,71,2,2,2,2,2,2,2
2,2,2,2,2,2,2,4,4,4,4,4,2,2,2,2,2,2,2
2,2,2,2,2,2,2,4,4,4,4,4,2,2,2,2,2,2,2
2,2,2,2,2,2,2,4,4,4,4,4,2,2,2,2,2,2,2
2,2,2,2,2,2,2,71,4,4,4,71,2,2,2,2,2,2,2
2,2,2,2,2,2,2,2,2,2,2,2,2,2,2,2,2,2,2
2,2,2,2,2,2,2,2,2,2,2,2,2,2,2,2,2,2,2
2,2,2,2,2,2,2,2,2,2,2,2,2,2,2,2,2,2,2
2,2,2,2,2,2,2,2,2,2,2,2,2,2,2,2,2,2,2
2,2,2,2,2,2,2,2,2,2,2,2,2,2,2,2,2,2,2
2,2,2,2,2,2,2,2,2,2,2,2,2,2,2,2,2,2,2
2,2,2,2,2,2,2,2,2,2,2,2,2,2,2,2,2,2,2
endlayer

layer
2,2,2,2,2,2,2,2,2,2,2,2,2,2,2,2,2,2,2
2,2,2,2,2,2,2,2,2,2,2,2,2,2,2,2,2,2,2
2,2,2,2,2,2,2,2,2,2,2,2,2,2,2,2,2,2,2
2,2,2,2,2,2,2,2,2,2,2,2,2,2,2,2,2,2,2
2,2,2,2,2,2,2,2,2,2,2,2,2,2,2,2,2,2,2
2,2,2,2,2,2,2,2,2,2,2,2,2,2,2,2,2,2,2
2,2,2,2,2,2,2,2,2,2,2,2,2,2,2,2,2,2,2
2,2,2,2,2,2,2,2,71,4,71,2,2,2,2,2,2,2,2
2,2,2,2,2,2,2,71,4,4,4,71,2,2,2,2,2,2,2
2,2,2,2,2,2,2,4,4,4,4,4,2,2,2,2,2,2,2
2,2,2,2,2,2,2,71,4,4,4,71,2,2,2,2,2,2,2
2,2,2,2,2,2,2,2,71,4,71,2,2,2,2,2,2,2,2
2,2,2,2,2,2,2,2,2,2,2,2,2,2,2,2,2,2,2
2,2,2,2,2,2,2,2,2,2,2,2,2,2,2,2,2,2,2
2,2,2,2,2,2,2,2,2,2,2,2,2,2,2,2,2,2,2
2,2,2,2,2,2,2,2,2,2,2,2,2,2,2,2,2,2,2
2,2,2,2,2,2,2,2,2,2,2,2,2,2,2,2,2,2,2
2,2,2,2,2,2,2,2,2,2,2,2,2,2,2,2,2,2,2
2,2,2,2,2,2,2,2,2,2,2,2,2,2,2,2,2,2,2
endlayer

layer
2,2,2,2,2,2,2,2,2,2,2,2,2,2,2,2,2,2,2
2,2,2,2,2,2,2,2,2,2,2,2,2,2,2,2,2,2,2
2,2,2,2,2,2,2,2,2,2,2,2,2,2,2,2,2,2,2
2,2,2,2,2,2,2,2,2,2,2,2,2,2,2,2,2,2,2
2,2,2,2,2,2,2,2,2,2,2,2,2,2,2,2,2,2,2
2,2,2,2,2,2,2,2,2,2,2,2,2,2,2,2,2,2,2
2,2,2,2,2,2,2,2,2,2,2,2,2,2,2,2,2,2,2
2,2,2,2,2,2,2,2,2,2,2,2,2,2,2,2,2,2,2
2,2,2,2,2,2,2,2,71,4,71,2,2,2,2,2,2,2,2
2,2,2,2,2,2,2,2,4,4,4,2,2,2,2,2,2,2,2
2,2,2,2,2,2,2,2,71,4,71,2,2,2,2,2,2,2,2
2,2,2,2,2,2,2,2,2,2,2,2,2,2,2,2,2,2,2
2,2,2,2,2,2,2,2,2,2,2,2,2,2,2,2,2,2,2
2,2,2,2,2,2,2,2,2,2,2,2,2,2,2,2,2,2,2
2,2,2,2,2,2,2,2,2,2,2,2,2,2,2,2,2,2,2
2,2,2,2,2,2,2,2,2,2,2,2,2,2,2,2,2,2,2
2,2,2,2,2,2,2,2,2,2,2,2,2,2,2,2,2,2,2
2,2,2,2,2,2,2,2,2,2,2,2,2,2,2,2,2,2,2
2,2,2,2,2,2,2,2,2,2,2,2,2,2,2,2,2,2,2
endlayer

layer
2,2,2,2,2,2,2,2,2,2,2,2,2,2,2,2,2,2,2
2,2,2,2,2,2,2,2,2,2,2,2,2,2,2,2,2,2,2
2,2,2,2,2,2,2,2,2,2,2,2,2,2,2,2,2,2,2
2,2,2,2,2,2,2,2,2,2,2,2,2,2,2,2,2,2,2
2,2,2,2,2,2,2,2,2,2,2,2,2,2,2,2,2,2,2
2,2,2,2,2,2,2,2,2,2,2,2,2,2,2,2,2,2,2
2,2,2,2,2,2,2,2,2,2,2,2,2,2,2,2,2,2,2
2,2,2,2,2,2,2,2,2,2,2,2,2,2,2,2,2,2,2
2,2,2,2,2,2,2,2,2,71,2,2,2,2,2,2,2,2,2
2,2,2,2,2,2,2,2,71,4,71,2,2,2,2,2,2,2,2
2,2,2,2,2,2,2,2,2,71,2,2,2,2,2,2,2,2,2
2,2,2,2,2,2,2,2,2,2,2,2,2,2,2,2,2,2,2
2,2,2,2,2,2,2,2,2,2,2,2,2,2,2,2,2,2,2
2,2,2,2,2,2,2,2,2,2,2,2,2,2,2,2,2,2,2
2,2,2,2,2,2,2,2,2,2,2,2,2,2,2,2,2,2,2
2,2,2,2,2,2,2,2,2,2,2,2,2,2,2,2,2,2,2
2,2,2,2,2,2,2,2,2,2,2,2,2,2,2,2,2,2,2
2,2,2,2,2,2,2,2,2,2,2,2,2,2,2,2,2,2,2
2,2,2,2,2,2,2,2,2,2,2,2,2,2,2,2,2,2,2
endlayer

layer
2,2,2,2,2,2,2,2,2,2,2,2,2,2,2,2,2,2,2
2,2,2,2,2,2,2,2,2,2,2,2,2,2,2,2,2,2,2
2,2,2,2,2,2,2,2,2,2,2,2,2,2,2,2,2,2,2
2,2,2,2,2,2,2,2,2,2,2,2,2,2,2,2,2,2,2
2,2,2,2,2,2,2,2,2,2,2,2,2,2,2,2,2,2,2
2,2,2,2,2,2,2,2,2,2,2,2,2,2,2,2,2,2,2
2,2,2,2,2,2,2,2,2,2,2,2,2,2,2,2,2,2,2
2,2,2,2,2,2,2,2,2,2,2,2,2,2,2,2,2,2,2
2,2,2,2,2,2,2,2,2,2,2,2,2,2,2,2,2,2,2
2,2,2,2,2,2,2,2,2,4,2,2,2,2,2,2,2,2,2
2,2,2,2,2,2,2,2,2,2,2,2,2,2,2,2,2,2,2
2,2,2,2,2,2,2,2,2,2,2,2,2,2,2,2,2,2,2
2,2,2,2,2,2,2,2,2,2,2,2,2,2,2,2,2,2,2
2,2,2,2,2,2,2,2,2,2,2,2,2,2,2,2,2,2,2
2,2,2,2,2,2,2,2,2,2,2,2,2,2,2,2,2,2,2
2,2,2,2,2,2,2,2,2,2,2,2,2,2,2,2,2,2,2
2,2,2,2,2,2,2,2,2,2,2,2,2,2,2,2,2,2,2
2,2,2,2,2,2,2,2,2,2,2,2,2,2,2,2,2,2,2
2,2,2,2,2,2,2,2,2,2,2,2,2,2,2,2,2,2,2
endlayer

