
# Created by Ruins mod version 16.9 Ingame Parser
# authoring Player: ST753M

weight=1
uniqueMinDistance=1000
embed_into_distance=13
acceptable_target_blocks=
unacceptable_target_blocks=flowing_water,water,flowing_lava,lava,ice,quartz_ore,Natura:Cloud,slime_grass,slime_congealed,slime_dirt,clouds,natura:clouds
dimensions=16,33,17
allowable_overhang=99
max_leveling=2
leveling_buffer=0
preserve_water=0
preserve_lava=0

biomesToSpawnIn=plains,prairie,shrubland,chaparral,rocky_plains,rocky_plateau,orchard,savanna,savanna_rock

=0,100,air
rule1=0,100,minecraft:stone-0
rule2=0,100,minecraft:stonebrick-0,minecraft:stonebrick-1,minecraft:stonebrick-2
^0,100,minecraft:stonebrick-0
rule3=0,100,minecraft:water-0
rule4=0,100,minecraft:wooden_door-2
rule5=0,100,minecraft:fence_gate-3
rule6=0,100,CommandBlock:RUINSTRIGGER /summon villager ~ ~1 ~:@-1
rule7=0,100,minecraft:wooden_door-3
rule8=0,100,minecraft:oak_stairs-7
rule9=0,100,minecraft:oak_stairs-6
rule10=0,60,minecraft:cauldron-0
rule11=0,100,minecraft:wooden_door-1
rule12=0,100,ChestGenHook:chests/village_blacksmith:2-5,ChestGenHook:chests/abandoned_mineshaft:2-5
rule13=0,100,minecraft:wooden_door-0
rule14=0,100,minecraft:oak_stairs-5
rule15=0,100,CommandBlock:RUINSTRIGGER /summon villager ~ ~1 ~:@-3
rule16=0,100,minecraft:stone_brick_stairs-6
rule17=0,100,CommandBlock:RUINSTRIGGER /summon villager_golem ~ ~1 ~ {PlayerCreated:0}:@-1
rule18=0,100,minecraft:water-9
rule19=0,100,CommandBlock:RUINSTRIGGER /summon villager ~ ~1 ~ {CustomName:"Izchak",CustomNameVisible:1,Profession:1,Offers:{Recipes:[{rewardExp:0b,maxUses:2147483647,uses:0,buy:{id:"minecraft:emerald",Count:1b},sell:{id:"minecraft:torch",Count:24b}},{rewardExp:0b,maxUses:2147483647,uses:0,buy:{id:"minecraft:redstone_torch",Count:32b},sell:{id:"minecraft:emerald",Count:1b}},{rewardExp:0b,maxUses:2147483647,uses:0,buy:{id:"minecraft:glowstone",Count:12b},sell:{id:"minecraft:emerald",Count:1b}},{rewardExp:0b,maxUses:2147483647,uses:0,buy:{id:"minecraft:emerald",Count:1b},sell:{id:"minecraft:redstone_lamp",Count:2b}}]}}:@-1
rule20=0,100,minecraft:stone_brick_stairs-4
rule21=0,100,minecraft:quartz_stairs-4
rule22=0,100,minecraft:fence_gate-0
rule23=0,100,CommandBlock:RUINSTRIGGER /summon villager ~ ~1 ~ {Profession:2,Offers:{Recipes:[{rewardExp:0b,maxUses:2147483647,uses:0,buy:{id:"minecraft:emerald",Count:11b},sell:{id:"minecraft:chainmail_helmet",Count:1b,tag:{ench:[{id:0,lvl:4}]}}},{rewardExp:0b,maxUses:2147483647,uses:0,buy:{id:"minecraft:emerald",Count:21b},sell:{id:"minecraft:chainmail_chestplate",Count:1b,tag:{ench:[{id:0,lvl:4}]}}},{rewardExp:0b,maxUses:2147483647,uses:0,buy:{id:"minecraft:emerald",Count:15b},sell:{id:"minecraft:chainmail_leggings",Count:1b,tag:{ench:[{id:0,lvl:4}]}}},{rewardExp:0b,maxUses:2147483647,uses:0,buy:{id:"minecraft:emerald",Count:12b},sell:{id:"minecraft:chainmail_boots",Count:1b,tag:{ench:[{id:0,lvl:4}]}}}]}}:@-1
rule24=0,100,minecraft:quartz_stairs-5
rule25=0,100,minecraft:trapped_chest-2
rule26=0,100,CommandBlock:RUINSTRIGGER /summon villager ~ ~1 ~ {Profession:0,Offers:{Recipes:[{rewardExp:0b,maxUses:256,uses:0,buy:{id:"minecraft:apple",Count:15b},sell:{id:"minecraft:emerald",Count:1b}},{rewardExp:0b,maxUses:2147483647,uses:0,buy:{id:"minecraft:emerald",Count:1b},sell:{id:"minecraft:carrot",Count:7b}},{rewardExp:0b,maxUses:32,uses:0,buy:{id:"minecraft:cake",Count:1b},sell:{id:"minecraft:emerald",Count:1b}},{rewardExp:0b,maxUses:2147483647,uses:0,buy:{id:"minecraft:emerald",Count:2b},sell:{id:"minecraft:milk_bucket",Count:1b}}]}}:@-1
rule27=0,100,CommandBlock:RUINSTRIGGER /summon villager ~ ~1 ~ {Profession:3,Offers:{Recipes:[{rewardExp:0b,maxUses:2147483647,uses:0,buy:{id:"minecraft:emerald",Count:6b},sell:{id:"minecraft:iron_pickaxe",Count:1b,tag:{ench:[{id:34,lvl:3}]}}},{rewardExp:0b,maxUses:8,uses:0,buy:{id:"minecraft:shears",Count:1b},sell:{id:"minecraft:emerald",Count:1b}},{rewardExp:0b,maxUses:2147483647,uses:0,buy:{id:"minecraft:emerald",Count:2b},buyB:{id:"minecraft:bucket",Count:1b},sell:{id:"minecraft:lava_bucket",Count:1b}},{rewardExp:0b,maxUses:2147483647,uses:0,buy:{id:"minecraft:emerald",Count:2b},sell:{id:"minecraft:flint_and_steel",Count:1b}}]}}:@-1
rule28=0,100,minecraft:stone_brick_stairs-2
rule29=0,100,minecraft:stone_brick_stairs-7
rule30=0,100,minecraft:wooden_door-9
rule31=0,100,minecraft:wooden_door-8
rule32=1,100,minecraft:torch-5
rule33=0,100,minecraft:fence-0
rule34=0,100,minecraft:water-1
rule35=0,100,minecraft:carpet-14
^0,100,minecraft:carpet-4
^0,100,minecraft:carpet-13
^0,100,minecraft:carpet-3
^0,100,minecraft:carpet-11
^0,100,minecraft:carpet-10
^0,100,minecraft:carpet-0
^0,100,minecraft:carpet-15
rule36=2,100,minecraft:torch-2
rule37=2,100,minecraft:torch-1
rule38=2,100,minecraft:torch-4
rule39=2,100,minecraft:torch-3
rule40=2,100,WallSign:null:Welcome to:Minetown:null-5
rule41=0,100,minecraft:stone_brick_stairs-5
rule42=0,100,preserveBlock
rule43=0,100,minecraft:stone_brick_stairs-3
rule44=0,100,minecraft:fence_gate-1
rule45=0,100,minecraft:stone_brick_stairs-0

layer
1,1,1,1,1,1,1,1,1,1,1,1,1,1,1,1,1
1,1,1,1,1,1,1,1,1,1,1,1,1,1,1,1,1
1,1,1,1,1,1,1,1,1,1,1,1,1,1,1,1,1
1,1,1,1,1,1,1,1,1,1,1,1,1,1,1,1,1
1,1,1,1,1,1,1,1,1,1,1,1,1,1,1,1,1
1,1,1,1,1,1,1,1,1,1,1,1,1,1,1,1,1
1,1,1,1,1,1,1,1,1,1,1,1,1,1,1,1,1
1,1,1,1,1,1,1,1,1,1,1,1,1,1,1,1,1
1,1,1,1,1,1,1,1,1,1,1,1,1,1,1,1,1
1,1,1,1,1,1,1,1,1,1,1,1,1,1,1,1,1
1,1,1,1,1,1,1,1,1,1,1,1,1,1,1,1,1
1,1,1,1,1,1,1,1,1,1,1,1,1,1,1,1,1
1,1,1,1,1,1,1,1,1,1,1,1,1,1,1,1,1
1,1,1,1,1,1,1,2,2,1,1,1,1,1,1,1,1
1,1,1,1,1,1,1,2,3,1,1,1,1,1,1,1,1
1,1,1,1,1,1,1,2,2,1,1,1,1,1,1,1,1
1,1,1,1,1,1,1,1,1,1,1,1,1,1,1,1,1
1,1,1,1,1,1,1,1,1,2,3,2,1,1,1,1,1
1,1,1,1,1,1,1,1,1,2,2,2,1,1,1,1,1
1,1,1,1,1,1,1,1,1,1,1,1,1,1,1,1,1
1,1,1,1,1,1,1,1,1,1,1,1,1,1,1,1,1
1,1,1,1,1,1,1,1,1,1,1,1,1,1,1,1,1
1,1,1,1,1,1,1,1,1,1,1,1,1,1,1,1,1
1,1,1,1,1,1,1,1,1,1,1,1,1,1,1,1,1
1,1,1,1,1,1,1,1,1,1,1,1,1,1,1,1,1
1,1,1,1,1,1,1,1,1,1,1,1,1,1,1,1,1
1,1,1,1,1,1,1,1,1,1,1,1,1,1,1,1,1
1,1,1,1,1,1,1,1,1,1,1,1,1,1,1,1,1
1,1,1,1,1,1,1,1,1,1,1,1,1,1,1,1,1
1,1,1,1,1,1,1,1,1,1,1,1,1,1,1,1,1
1,1,1,1,1,1,1,1,1,1,1,1,1,1,1,1,1
1,1,1,1,1,1,1,1,1,1,1,1,1,1,1,1,1
1,1,1,1,1,1,1,1,1,1,1,1,1,1,1,1,1
endlayer

layer
2,2,2,2,2,2,2,2,2,2,2,2,2,2,2,2,2
2,0,0,0,0,0,0,0,0,0,0,0,0,0,0,0,2
2,0,2,2,5,2,2,0,2,2,2,2,0,2,2,4,2
2,0,2,0,6,0,2,0,2,0,0,2,0,2,0,0,2
2,0,2,0,0,0,2,0,2,0,0,7,0,2,0,0,2
2,0,2,9,0,8,2,0,2,2,2,2,0,2,2,2,2
2,0,2,9,0,10,2,0,2,0,0,2,0,2,0,0,2
2,0,2,2,2,2,2,0,11,0,0,2,0,11,0,0,2
2,0,2,0,0,0,2,0,2,2,2,2,0,2,2,2,2
2,0,2,0,12,0,7,0,2,12,0,2,0,2,0,0,2
2,0,2,0,0,0,2,0,2,0,0,7,0,2,0,0,2
2,0,2,2,2,2,2,0,2,2,2,2,0,2,13,2,2
2,0,2,0,14,14,2,0,0,0,0,0,0,0,0,0,2
2,0,2,0,0,0,2,16,0,0,0,0,0,0,0,15,2
2,0,2,0,14,14,2,16,18,0,17,17,0,0,0,15,2
2,0,2,0,19,0,2,16,0,0,0,0,0,0,0,0,2
2,0,2,2,5,2,2,0,0,0,0,0,0,2,4,2,2
2,0,0,0,0,0,0,0,0,0,18,0,0,2,0,0,2
2,0,2,4,2,2,2,0,0,20,20,20,0,2,0,0,2
2,0,2,0,0,0,2,2,2,2,2,2,0,2,2,2,2
2,0,2,0,0,0,2,0,0,0,0,2,0,2,0,0,2
2,0,2,0,0,0,2,0,21,0,0,2,0,11,0,0,2
2,0,2,0,0,0,2,0,24,0,23,22,0,2,2,2,2
2,0,2,2,2,2,2,0,0,0,0,2,0,2,0,0,2
2,0,2,25,0,0,2,2,2,2,2,2,0,11,0,0,2
2,0,2,9,0,0,2,0,0,0,0,2,0,2,2,2,2
2,0,2,9,0,0,2,0,0,0,26,22,0,2,0,12,2
2,0,2,0,0,27,2,0,0,0,0,2,0,2,0,0,2
2,0,2,2,2,5,2,2,2,2,2,2,0,2,13,2,2
2,0,0,0,0,0,0,0,0,0,0,0,0,0,0,0,2
2,0,0,0,0,0,0,0,0,0,0,0,0,0,0,0,2
2,0,0,0,0,0,0,0,29,28,0,0,0,0,0,0,2
2,2,2,2,2,2,2,2,2,2,2,2,2,2,2,2,2
endlayer

layer
2,2,2,2,2,2,2,2,2,2,2,2,2,2,2,2,2
2,0,0,0,0,0,0,0,0,0,0,0,0,0,0,0,2
2,0,2,2,0,2,2,0,2,2,2,2,0,2,2,30,2
2,0,2,0,0,0,2,0,2,0,0,2,0,2,0,0,2
2,0,2,0,0,0,2,0,2,0,0,31,0,2,0,0,2
2,0,2,0,0,0,2,0,2,2,2,2,0,2,2,2,2
2,0,2,0,0,0,2,0,2,0,0,2,0,2,0,0,2
2,0,2,2,2,2,2,0,30,0,0,2,0,30,0,0,2
2,0,2,0,0,0,2,0,2,2,2,2,0,2,2,2,2
2,0,2,0,0,0,30,0,2,0,0,2,0,2,0,0,2
2,0,2,0,0,0,2,0,2,0,0,30,0,2,0,0,2
2,0,2,2,2,2,2,0,2,2,2,2,0,2,30,2,2
2,0,2,0,32,32,2,0,0,0,0,0,0,0,0,0,2
2,0,2,0,0,0,2,33,0,0,0,0,0,0,0,0,2
2,0,2,0,32,32,2,3,34,0,0,0,0,0,0,0,2
2,0,2,0,0,0,2,33,0,0,0,0,0,0,0,0,2
2,0,2,2,0,2,2,0,0,0,0,0,0,2,30,2,2
2,0,0,0,0,0,0,0,0,0,34,0,0,2,0,0,2
2,0,2,30,2,2,2,0,0,33,3,33,0,2,0,0,2
2,0,2,0,0,0,2,2,2,2,2,2,0,2,2,2,2
2,0,2,0,0,0,2,0,0,0,0,2,0,2,0,0,2
2,0,2,0,0,0,2,0,35,0,0,2,0,30,0,0,2
2,0,2,0,0,0,2,0,35,0,0,0,0,2,2,2,2
2,0,2,2,2,2,2,0,0,0,0,2,0,2,0,0,2
2,0,2,0,0,0,2,2,2,2,2,2,0,31,0,0,2
2,0,2,0,0,0,2,0,0,0,0,2,0,2,2,2,2
2,0,2,0,0,0,2,0,0,0,0,0,0,2,0,0,2
2,0,2,0,36,0,2,0,0,0,0,2,0,2,0,0,2
2,0,2,2,2,0,2,2,2,2,2,2,0,2,31,2,2
2,0,0,0,0,0,0,0,0,0,0,0,0,0,0,0,2
2,0,0,0,0,0,0,0,0,0,0,0,0,0,0,0,2
2,0,0,0,0,0,0,29,28,0,0,0,0,0,0,0,2
2,2,2,2,2,2,2,2,2,2,2,2,2,2,2,2,2
endlayer

layer
2,2,2,2,2,2,2,2,2,2,2,2,2,2,2,2,2
2,0,0,0,0,0,0,0,0,0,0,0,37,0,0,0,2
2,0,2,2,2,2,2,0,2,2,2,2,0,2,2,2,2
2,0,2,0,37,0,2,0,2,0,0,2,0,2,0,0,2
2,0,2,0,0,0,2,0,2,0,0,2,0,2,0,0,2
2,38,2,0,0,0,2,0,2,2,2,2,0,2,2,2,2
2,0,2,0,0,0,2,0,2,0,0,2,0,2,0,0,2
2,0,2,2,2,2,2,0,2,0,0,2,0,2,0,0,2
2,0,2,0,0,0,2,0,2,2,2,2,0,2,2,2,2
2,0,2,0,0,0,2,0,2,0,0,2,0,2,0,0,2
2,0,2,0,0,0,2,0,2,0,0,2,0,2,36,0,2
2,0,2,2,2,2,2,0,2,2,2,2,0,2,2,2,2
2,0,2,0,0,0,2,0,0,0,0,0,0,0,0,0,2
2,0,2,0,0,0,2,32,0,0,0,0,0,0,0,0,2
2,0,2,0,0,0,2,0,0,0,0,0,0,0,0,0,2
2,0,2,0,36,0,2,32,0,0,0,0,0,0,0,0,2
2,0,2,2,2,2,2,0,0,0,0,0,0,2,2,2,2
2,0,0,0,37,0,0,0,0,0,0,0,0,2,0,0,2
2,0,2,2,2,2,2,0,0,32,0,32,0,2,0,0,2
2,0,2,0,0,0,2,2,2,2,2,2,0,2,2,2,2
2,0,2,0,0,0,2,0,0,0,0,2,0,2,0,0,2
2,0,2,0,0,0,2,0,0,0,39,2,0,2,0,0,2
2,0,2,0,0,0,2,0,0,0,0,2,0,2,2,2,2
2,0,2,2,2,2,2,0,0,0,0,2,0,2,0,0,2
2,0,2,0,0,0,2,2,2,2,2,2,0,2,0,0,2
2,38,2,0,0,0,2,0,0,0,0,2,0,2,2,2,2
2,0,2,0,0,0,2,0,0,0,39,2,0,2,0,0,2
2,0,2,0,0,0,2,0,0,0,0,2,20,2,0,0,2
2,0,2,2,2,2,2,2,2,2,2,2,2,2,2,2,2
2,0,0,0,0,0,0,0,0,0,0,37,40,37,0,0,2
2,0,0,0,0,0,0,0,0,0,0,0,0,0,0,0,2
2,0,0,0,0,0,29,28,0,0,0,0,0,0,0,0,2
2,2,2,2,2,2,2,2,2,2,2,2,2,2,2,2,2
endlayer

layer
2,2,2,2,2,2,2,2,2,2,2,2,2,2,2,2,2
2,2,2,2,2,2,2,2,2,2,2,2,2,2,2,2,2
2,2,2,2,2,2,2,2,2,2,2,2,2,2,2,2,2
2,2,2,16,0,29,2,2,2,0,0,2,2,2,0,0,2
2,2,2,16,0,29,2,2,2,0,0,2,2,2,0,0,2
2,2,2,16,0,29,2,2,2,2,2,2,2,2,2,2,2
2,2,2,16,0,29,2,2,2,0,0,2,2,2,0,0,2
2,2,2,2,2,2,2,2,2,0,0,2,2,2,0,0,2
2,2,2,0,0,0,2,2,2,2,2,2,2,2,2,2,2
2,2,2,0,0,0,2,2,2,0,0,2,2,2,0,0,2
2,2,2,0,0,0,2,2,2,0,0,2,2,2,0,0,2
2,2,2,2,2,2,2,2,2,2,2,2,2,2,2,2,2
2,2,2,16,0,29,2,16,41,41,41,41,41,41,41,29,2
2,2,2,16,0,29,2,16,0,0,0,0,0,0,0,29,2
2,2,2,16,0,29,2,16,0,0,0,0,0,0,0,29,2
2,2,2,16,0,29,2,16,0,0,0,0,0,0,0,29,2
2,2,2,2,2,2,2,16,0,0,0,0,0,2,2,2,2
2,2,2,2,2,2,2,16,0,0,0,0,0,2,0,0,2
2,2,2,2,2,2,2,20,20,20,20,20,20,2,0,0,2
2,2,2,16,0,29,2,2,2,2,2,2,2,2,2,2,2
2,2,2,16,0,29,2,41,41,41,41,2,2,2,0,0,2
2,2,2,16,0,29,2,0,0,0,0,2,2,2,0,0,2
2,2,2,16,0,29,2,0,0,0,0,2,2,2,2,2,2
2,2,2,2,2,2,2,20,20,20,20,2,2,2,0,0,2
2,2,2,0,0,0,2,2,2,2,2,2,2,2,0,0,2
2,2,2,0,0,0,2,41,41,41,41,2,2,2,2,2,2
2,2,2,0,0,0,2,0,0,0,0,2,2,2,0,0,2
2,2,2,0,0,0,2,20,20,20,20,2,2,2,0,0,2
2,2,2,2,2,2,2,2,2,2,2,2,33,2,2,2,2
2,41,41,41,41,41,41,41,41,41,41,41,41,41,41,41,2
2,0,0,0,0,0,0,0,0,0,0,0,0,0,0,0,2
2,20,20,20,20,29,28,0,0,0,0,29,20,20,20,20,2
2,2,2,2,2,2,2,2,2,2,2,2,2,2,2,2,2
endlayer

layer
1,1,1,1,1,1,1,1,1,1,1,1,1,1,1,1,1
1,1,1,1,1,1,1,1,1,1,1,1,1,1,1,1,1
1,1,1,1,1,1,1,1,1,1,1,1,1,1,1,1,1
1,1,1,1,1,1,1,1,1,1,1,1,1,1,1,1,1
1,1,1,1,1,1,1,1,1,1,1,1,1,1,1,1,1
1,1,1,1,1,1,1,1,1,1,1,1,1,1,1,1,1
1,1,1,1,1,1,1,1,1,1,1,1,1,1,1,1,1
1,1,1,1,1,1,1,1,1,1,1,1,1,1,1,1,1
1,1,1,1,1,1,1,1,1,1,1,1,1,1,1,1,1
1,1,1,1,1,1,1,1,1,1,1,1,1,1,1,1,1
1,1,1,1,1,1,1,1,1,1,1,1,1,1,1,1,1
1,1,1,1,1,1,1,1,1,1,1,1,1,1,1,1,1
1,1,1,1,1,1,1,1,1,1,1,1,1,1,1,1,1
1,1,1,1,1,1,1,1,1,1,1,1,1,1,1,1,1
1,1,1,1,1,1,1,1,1,1,1,1,1,1,1,1,1
1,1,1,1,1,1,1,1,1,1,1,1,1,1,1,1,1
1,1,1,1,1,1,1,1,1,1,1,1,1,1,1,1,1
1,1,1,1,1,1,1,1,1,1,1,1,1,1,1,1,1
1,1,1,1,1,1,1,1,1,1,1,1,1,1,1,1,1
1,1,1,1,1,1,1,1,1,1,1,1,1,1,1,1,1
1,1,1,1,1,1,1,1,1,1,1,1,1,1,1,1,1
1,1,1,1,1,1,1,1,1,1,1,1,1,1,1,1,1
1,1,1,1,1,1,1,1,1,1,1,1,1,1,1,1,1
1,1,1,1,1,1,1,1,1,1,1,1,1,1,1,1,1
1,1,1,1,1,1,1,1,1,1,1,1,1,1,1,1,1
1,1,1,1,1,1,1,1,1,1,1,1,1,1,1,1,1
1,1,1,1,1,1,1,1,1,1,1,1,1,1,1,1,1
1,1,1,1,1,1,1,1,1,1,1,1,1,1,1,1,1
1,1,1,1,1,1,1,1,1,1,1,1,1,1,1,1,1
1,1,1,1,1,1,1,1,1,1,1,1,1,1,1,1,1
1,1,1,1,1,1,1,1,1,1,1,1,1,1,1,1,1
1,1,1,2,2,28,0,0,0,0,29,1,1,1,1,1,1
1,1,1,1,1,2,2,2,2,2,2,1,1,1,1,1,1
endlayer

layer
42,42,42,42,42,42,42,42,42,42,42,42,42,42,42,42,42
42,42,42,42,42,42,42,42,42,42,42,42,42,42,42,42,42
42,42,42,42,42,42,42,42,42,42,42,42,42,42,42,42,42
42,42,42,42,42,42,42,42,42,42,42,42,42,42,42,42,42
42,42,42,42,42,42,0,42,42,42,42,42,42,42,42,42,42
42,42,42,42,0,0,0,0,0,42,42,42,42,42,42,42,42
42,42,42,42,0,0,0,0,0,42,42,42,42,42,42,42,42
42,42,42,0,0,0,0,0,0,0,42,42,42,42,42,42,42
42,42,42,42,0,0,0,0,0,42,42,42,42,42,42,42,42
42,42,42,42,0,0,0,0,0,0,0,42,42,42,42,42,42
42,42,42,42,42,42,0,0,0,0,0,42,42,42,42,42,42
42,42,42,42,42,0,0,0,0,0,0,0,42,42,42,42,42
42,42,42,0,0,0,0,0,0,0,0,42,42,42,42,42,42
42,42,42,0,0,0,0,0,0,0,0,42,42,42,42,42,42
42,42,0,0,0,0,0,0,0,0,0,42,42,42,42,42,42
42,42,0,0,0,0,0,0,0,0,0,42,42,42,42,42,42
42,42,0,0,0,0,0,0,0,0,0,0,42,42,42,42,42
42,42,42,0,0,0,0,0,0,0,0,0,42,42,42,42,42
42,42,42,0,0,0,0,0,0,0,0,0,0,42,42,42,42
42,42,42,42,0,0,0,0,0,0,0,0,0,42,42,42,42
42,42,42,0,0,0,0,0,0,0,0,0,0,42,42,42,42
42,42,42,0,0,0,0,0,0,0,0,0,42,42,42,42,42
42,42,0,0,0,0,0,0,0,0,0,0,42,42,42,42,42
42,42,0,0,0,0,0,0,0,0,0,42,42,42,42,42,42
42,42,0,0,0,0,0,0,0,0,0,42,42,42,42,42,42
42,42,42,0,0,0,0,0,0,0,42,42,42,42,42,42,42
42,42,42,0,0,0,0,0,0,0,42,42,42,42,42,42,42
42,42,42,42,0,0,0,0,0,0,0,42,42,42,42,42,42
42,42,42,42,42,0,0,0,0,0,42,42,42,42,42,42,42
42,42,42,0,0,0,0,0,0,0,42,42,42,42,42,42,42
42,42,42,33,0,33,2,2,2,2,42,42,42,42,42,42,42
42,42,42,2,0,0,0,0,0,29,42,42,42,42,42,42,42
42,42,42,2,2,2,2,2,2,2,42,42,42,42,42,42,42
endlayer

layer
42,42,42,42,42,42,42,42,42,42,42,42,42,42,42,42,42
42,42,42,42,42,42,42,42,42,42,42,42,42,42,42,42,42
42,42,42,42,42,42,42,42,42,42,42,42,42,42,42,42,42
42,42,42,42,42,0,0,0,42,42,42,42,42,42,42,42,42
42,42,42,0,0,0,0,0,0,0,42,42,42,42,42,42,42
42,42,42,0,0,0,0,0,0,0,42,42,42,42,42,42,42
42,42,0,0,0,0,0,0,0,0,0,42,42,42,42,42,42
42,42,0,0,0,0,0,0,0,0,0,42,42,42,42,42,42
42,42,0,0,0,0,0,0,0,0,0,0,42,42,42,42,42
42,42,42,0,0,0,0,0,0,0,0,0,42,42,42,42,42
42,42,42,0,0,0,0,0,0,0,0,0,0,42,42,42,42
42,42,42,0,0,0,0,0,0,0,0,0,0,42,42,42,42
42,42,0,0,0,0,0,0,0,0,0,0,0,42,42,42,42
42,42,0,0,0,0,0,0,0,0,0,0,42,42,42,42,42
42,42,0,0,0,0,0,0,0,0,0,0,42,42,42,42,42
42,0,0,0,0,0,0,0,0,0,0,0,42,42,42,42,42
42,42,0,0,0,0,0,0,0,0,0,0,0,42,42,42,42
42,42,0,0,0,0,0,0,0,0,0,0,0,42,42,42,42
42,42,0,0,0,0,0,0,0,0,0,0,0,42,42,42,42
42,42,42,0,0,0,0,0,0,0,0,0,0,0,42,42,42
42,42,0,0,0,0,0,0,0,0,0,0,0,42,42,42,42
42,42,0,0,0,0,0,0,0,0,0,0,0,42,42,42,42
42,42,0,0,0,0,0,0,0,0,0,0,0,42,42,42,42
42,0,0,0,0,0,0,0,0,0,0,0,42,42,42,42,42
42,42,0,0,0,0,0,0,0,0,0,42,42,42,42,42,42
42,42,0,0,0,0,0,0,0,0,0,42,42,42,42,42,42
42,42,0,0,0,0,0,0,0,0,0,0,42,42,42,42,42
42,42,42,0,0,0,0,0,0,0,0,0,42,42,42,42,42
42,42,42,0,0,0,0,0,0,0,0,0,42,42,42,42,42
42,42,42,0,0,0,0,0,0,0,0,42,42,42,42,42,42
42,42,42,33,44,33,43,2,2,2,0,42,42,42,42,42,42
42,42,42,45,0,0,0,0,29,2,42,42,42,42,42,42,42
42,42,42,2,2,2,2,2,2,2,42,42,42,42,42,42,42
endlayer

layer
42,42,42,42,42,42,42,42,42,42,42,42,42,42,42,42,42
42,42,42,42,42,42,42,42,42,42,42,42,42,42,42,42,42
42,42,42,42,42,42,0,42,42,42,42,42,42,42,42,42,42
42,42,42,0,0,0,0,0,0,0,42,42,42,42,42,42,42
42,42,0,0,0,0,0,0,0,0,0,42,42,42,42,42,42
42,42,0,0,0,0,0,0,0,0,0,42,42,42,42,42,42
42,42,0,0,0,0,0,0,0,0,0,42,42,42,42,42,42
42,0,0,0,0,0,0,0,0,0,0,0,42,42,42,42,42
42,42,0,0,0,0,0,0,0,0,0,0,0,42,42,42,42
42,42,0,0,0,0,0,0,0,0,0,0,0,42,42,42,42
42,42,0,0,0,0,0,0,0,0,0,0,0,42,42,42,42
42,42,42,0,0,0,0,0,0,0,0,0,0,0,42,42,42
42,42,0,0,0,0,0,0,0,0,0,0,0,42,42,42,42
42,0,0,0,0,0,0,0,0,0,0,0,0,42,42,42,42
42,0,0,0,0,0,0,0,0,0,0,0,0,42,42,42,42
42,0,0,0,0,0,0,0,0,0,0,0,42,42,42,42,42
42,0,0,0,0,0,0,0,0,0,0,0,0,42,42,42,42
42,0,0,0,0,0,0,0,0,0,0,0,0,0,42,42,42
42,42,0,0,0,0,0,0,0,0,0,0,0,0,42,42,42
42,42,42,0,0,0,0,0,0,0,0,0,0,0,42,42,42
42,42,0,0,0,0,0,0,0,0,0,0,0,0,42,42,42
42,0,0,0,0,0,0,0,0,0,0,0,0,0,42,42,42
42,0,0,0,0,0,0,0,0,0,0,0,0,42,42,42,42
42,0,0,0,0,0,0,0,0,0,0,0,42,42,42,42,42
42,0,0,0,0,0,0,0,0,0,0,0,42,42,42,42,42
42,0,0,0,0,0,0,0,0,0,0,0,42,42,42,42,42
42,42,0,0,0,0,0,0,0,0,0,0,42,42,42,42,42
42,42,0,0,0,0,0,0,0,0,0,0,0,42,42,42,42
42,42,42,0,0,0,0,0,0,0,0,0,42,42,42,42,42
42,42,42,0,0,0,0,0,0,0,0,0,42,42,42,42,42
42,42,42,32,0,32,0,43,2,28,0,0,42,42,42,42,42
42,42,42,0,0,0,0,43,2,28,0,42,42,42,42,42,42
42,42,42,42,2,2,2,2,2,28,42,42,42,42,42,42,42
endlayer

layer
42,42,42,42,42,42,42,42,42,42,42,42,42,42,42,42,42
42,42,42,42,42,42,42,42,42,42,42,42,42,42,42,42,42
42,42,42,42,0,0,0,0,0,42,42,42,42,42,42,42,42
42,42,42,0,0,0,0,0,0,0,42,42,42,42,42,42,42
42,42,0,0,0,0,0,0,0,0,0,42,42,42,42,42,42
42,0,0,0,0,0,0,0,0,0,0,0,42,42,42,42,42
42,0,0,0,0,0,0,0,0,0,0,0,42,42,42,42,42
42,0,0,0,0,0,0,0,0,0,0,0,42,42,42,42,42
42,0,0,0,0,0,0,0,0,0,0,0,0,42,42,42,42
42,0,0,0,0,0,0,0,0,0,0,0,0,0,42,42,42
42,42,0,0,0,0,0,0,0,0,0,0,0,0,42,42,42
42,42,0,0,0,0,0,0,0,0,0,0,0,0,42,42,42
42,42,0,0,0,0,0,0,0,0,0,0,0,0,42,42,42
42,0,0,0,0,0,0,0,0,0,0,0,0,0,42,42,42
42,0,0,0,0,0,0,0,0,0,0,0,0,42,42,42,42
42,0,0,0,0,0,0,0,0,0,0,0,0,42,42,42,42
42,0,0,0,0,0,0,0,0,0,0,0,0,42,42,42,42
42,0,0,0,0,0,0,0,0,0,0,0,0,0,42,42,42
42,42,0,0,0,0,0,0,0,0,0,0,0,0,42,42,42
42,42,0,0,0,0,0,0,0,0,0,0,0,0,42,42,42
42,42,0,0,0,0,0,0,0,0,0,0,0,0,42,42,42
42,0,0,0,0,0,0,0,0,0,0,0,0,0,42,42,42
42,0,0,0,0,0,0,0,0,0,0,0,0,42,42,42,42
42,0,0,0,0,0,0,0,0,0,0,0,0,42,42,42,42
42,0,0,0,0,0,0,0,0,0,0,0,42,42,42,42,42
42,0,0,0,0,0,0,0,0,0,0,0,0,42,42,42,42
42,42,0,0,0,0,0,0,0,0,0,0,0,42,42,42,42
42,42,0,0,0,0,0,0,0,0,0,0,0,42,42,42,42
42,42,0,0,0,0,0,0,0,0,0,0,0,42,42,42,42
42,42,0,0,0,0,0,0,0,0,0,0,0,42,42,42,42
42,42,42,0,0,0,0,0,0,0,0,0,42,42,42,42,42
42,42,42,0,0,0,0,0,0,0,0,42,42,42,42,42,42
42,42,42,42,42,42,42,42,0,0,42,42,42,42,42,42,42
endlayer

layer
42,42,42,42,42,42,42,42,42,42,42,42,42,42,42,42,42
42,42,42,42,42,42,42,42,42,42,42,42,42,42,42,42,42
42,42,42,42,0,0,0,0,0,42,42,42,42,42,42,42,42
42,42,0,0,0,0,0,0,0,0,0,42,42,42,42,42,42
42,42,0,0,0,0,0,0,0,0,0,42,42,42,42,42,42
42,0,0,0,0,0,0,0,0,0,0,0,42,42,42,42,42
42,0,0,0,0,0,0,0,0,0,0,0,42,42,42,42,42
42,0,0,0,0,0,0,0,0,0,0,0,0,42,42,42,42
42,0,0,0,0,0,0,0,0,0,0,0,0,42,42,42,42
42,0,0,0,0,0,0,0,0,0,0,0,0,0,42,42,42
42,42,0,0,0,0,0,0,0,0,0,0,0,0,42,42,42
42,42,0,0,0,0,0,0,0,0,0,0,0,0,42,42,42
42,0,0,0,0,0,0,0,0,0,0,0,0,0,42,42,42
42,0,0,0,0,0,0,0,0,0,0,0,0,0,42,42,42
42,0,0,0,0,0,0,0,0,0,0,0,0,42,42,42,42
42,0,0,0,0,0,0,0,0,0,0,0,0,42,42,42,42
42,0,0,0,0,0,0,0,0,0,0,0,0,0,42,42,42
42,0,0,0,0,0,0,0,0,0,0,0,0,0,42,42,42
42,0,0,0,0,0,0,0,0,0,0,0,0,0,42,42,42
42,42,0,0,0,0,0,0,0,0,0,0,0,0,42,42,42
42,0,0,0,0,0,0,0,0,0,0,0,0,0,42,42,42
42,0,0,0,0,0,0,0,0,0,0,0,0,0,42,42,42
42,0,0,0,0,0,0,0,0,0,0,0,0,0,42,42,42
42,0,0,0,0,0,0,0,0,0,0,0,0,42,42,42,42
42,0,0,0,0,0,0,0,0,0,0,0,42,42,42,42,42
42,0,0,0,0,0,0,0,0,0,0,0,0,42,42,42,42
42,0,0,0,0,0,0,0,0,0,0,0,0,42,42,42,42
42,42,0,0,0,0,0,0,0,0,0,0,0,42,42,42,42
42,42,0,0,0,0,0,0,0,0,0,0,0,42,42,42,42
42,42,0,0,0,0,0,0,0,0,0,0,0,42,42,42,42
42,42,42,0,0,0,0,0,0,0,0,0,42,42,42,42,42
42,42,42,0,0,0,0,0,0,0,0,0,42,42,42,42,42
42,42,42,42,42,42,42,0,0,0,42,42,42,42,42,42,42
endlayer

layer
42,42,42,42,42,42,42,42,42,42,42,42,42,42,42,42,42
42,42,42,42,42,42,42,42,42,42,42,42,42,42,42,42,42
42,42,42,0,0,0,0,0,0,0,42,42,42,42,42,42,42
42,42,0,0,0,0,0,0,0,0,0,42,42,42,42,42,42
42,0,0,0,0,0,0,0,0,0,0,0,42,42,42,42,42
42,0,0,0,0,0,0,0,0,0,0,0,42,42,42,42,42
42,0,0,0,0,0,0,0,0,0,0,0,42,42,42,42,42
42,0,0,0,0,0,0,0,0,0,0,0,0,42,42,42,42
42,0,0,0,0,0,0,0,0,0,0,0,0,0,42,42,42
42,0,0,0,0,0,0,0,0,0,0,0,0,0,42,42,42
42,0,0,0,0,0,0,0,0,0,0,0,0,0,42,42,42
42,42,0,0,0,0,0,0,0,0,0,0,0,0,42,42,42
42,42,0,0,0,0,0,0,0,0,0,0,0,0,42,42,42
42,0,0,0,0,0,0,0,0,0,0,0,0,0,42,42,42
42,0,0,0,0,0,0,0,0,0,0,0,0,0,42,42,42
42,0,0,0,0,0,0,0,0,0,0,0,0,42,42,42,42
42,0,0,0,0,0,0,0,0,0,0,0,0,42,42,42,42
42,0,0,0,0,0,0,0,0,0,0,0,0,0,42,42,42
42,42,0,0,0,0,0,0,0,0,0,0,0,0,42,42,42
42,42,0,0,0,0,0,0,0,0,0,0,0,0,42,42,42
42,42,0,0,0,0,0,0,0,0,0,0,0,0,42,42,42
42,0,0,0,0,0,0,0,0,0,0,0,0,0,42,42,42
42,0,0,0,0,0,0,0,0,0,0,0,0,42,42,42,42
42,0,0,0,0,0,0,0,0,0,0,0,0,42,42,42,42
42,0,0,0,0,0,0,0,0,0,0,0,0,42,42,42,42
42,0,0,0,0,0,0,0,0,0,0,0,0,42,42,42,42
42,42,0,0,0,0,0,0,0,0,0,0,0,42,42,42,42
42,42,0,0,0,0,0,0,0,0,0,0,0,42,42,42,42
42,42,0,0,0,0,0,0,0,0,0,0,0,42,42,42,42
42,42,0,0,0,0,0,0,0,0,0,0,0,42,42,42,42
42,42,0,0,0,0,0,0,0,0,0,0,0,42,42,42,42
42,42,42,0,0,0,0,0,0,0,0,0,42,42,42,42,42
42,42,42,42,42,42,0,0,0,0,0,42,42,42,42,42,42
endlayer

layer
42,42,42,42,42,42,42,42,42,42,42,42,42,42,42,42,42
42,42,42,42,42,42,42,42,42,42,42,42,42,42,42,42,42
42,42,42,42,0,0,0,0,0,42,42,42,42,42,42,42,42
42,42,0,0,0,0,0,0,0,0,0,42,42,42,42,42,42
42,42,0,0,0,0,0,0,0,0,0,42,42,42,42,42,42
42,0,0,0,0,0,0,0,0,0,0,0,42,42,42,42,42
42,0,0,0,0,0,0,0,0,0,0,0,42,42,42,42,42
42,0,0,0,0,0,0,0,0,0,0,0,0,42,42,42,42
42,0,0,0,0,0,0,0,0,0,0,0,0,42,42,42,42
42,0,0,0,0,0,0,0,0,0,0,0,0,0,42,42,42
42,42,0,0,0,0,0,0,0,0,0,0,0,0,42,42,42
42,42,0,0,0,0,0,0,0,0,0,0,0,0,42,42,42
42,42,0,0,0,0,0,0,0,0,0,0,0,0,42,42,42
42,0,0,0,0,0,0,0,0,0,0,0,0,0,42,42,42
42,0,0,0,0,0,0,0,0,0,0,0,0,42,42,42,42
42,0,0,0,0,0,0,0,0,0,0,0,0,42,42,42,42
42,0,0,0,0,0,0,0,0,0,0,0,0,42,42,42,42
42,0,0,0,0,0,0,0,0,0,0,0,0,0,42,42,42
42,42,0,0,0,0,0,0,0,0,0,0,0,0,42,42,42
42,42,42,0,0,0,0,0,0,0,0,0,0,0,42,42,42
42,42,0,0,0,0,0,0,0,0,0,0,0,0,42,42,42
42,0,0,0,0,0,0,0,0,0,0,0,0,0,42,42,42
42,0,0,0,0,0,0,0,0,0,0,0,0,42,42,42,42
42,0,0,0,0,0,0,0,0,0,0,0,42,42,42,42,42
42,0,0,0,0,0,0,0,0,0,0,0,42,42,42,42,42
42,0,0,0,0,0,0,0,0,0,0,0,0,42,42,42,42
42,42,0,0,0,0,0,0,0,0,0,0,0,42,42,42,42
42,42,0,0,0,0,0,0,0,0,0,0,0,42,42,42,42
42,42,0,0,0,0,0,0,0,0,0,0,0,42,42,42,42
42,42,0,0,0,0,0,0,0,0,0,0,0,42,42,42,42
42,42,42,0,0,0,0,0,0,0,0,0,42,42,42,42,42
42,42,42,0,0,0,0,0,0,0,0,0,42,42,42,42,42
42,42,42,42,42,0,0,0,0,0,0,42,42,42,42,42,42
endlayer

layer
42,42,42,42,42,42,42,42,42,42,42,42,42,42,42,42,42
42,42,42,42,42,42,42,42,42,42,42,42,42,42,42,42,42
42,42,42,42,0,0,0,0,0,42,42,42,42,42,42,42,42
42,42,42,0,0,0,0,0,0,0,42,42,42,42,42,42,42
42,42,0,0,0,0,0,0,0,0,0,42,42,42,42,42,42
42,0,0,0,0,0,0,0,0,0,0,0,42,42,42,42,42
42,0,0,0,0,0,0,0,0,0,0,0,42,42,42,42,42
42,0,0,0,0,0,0,0,0,0,0,0,42,42,42,42,42
42,0,0,0,0,0,0,0,0,0,0,0,0,42,42,42,42
42,0,0,0,0,0,0,0,0,0,0,0,0,0,42,42,42
42,42,0,0,0,0,0,0,0,0,0,0,0,0,42,42,42
42,42,42,0,0,0,0,0,0,0,0,0,0,0,42,42,42
42,42,0,0,0,0,0,0,0,0,0,0,0,0,42,42,42
42,42,0,0,0,0,0,0,0,0,0,0,0,0,42,42,42
42,42,0,0,0,0,0,0,0,0,0,0,0,42,42,42,42
42,0,0,0,0,0,0,0,0,0,0,0,42,42,42,42,42
42,42,0,0,0,0,0,0,0,0,0,0,0,42,42,42,42
42,42,0,0,0,0,0,0,0,0,0,0,0,42,42,42,42
42,42,0,0,0,0,0,0,0,0,0,0,0,42,42,42,42
42,42,42,0,0,0,0,0,0,0,0,0,0,0,42,42,42
42,42,0,0,0,0,0,0,0,0,0,0,0,42,42,42,42
42,42,0,0,0,0,0,0,0,0,0,0,0,42,42,42,42
42,42,0,0,0,0,0,0,0,0,0,0,0,42,42,42,42
42,0,0,0,0,0,0,0,0,0,0,0,42,42,42,42,42
42,42,0,0,0,0,0,0,0,0,0,0,0,42,42,42,42
42,42,0,0,0,0,0,0,0,0,0,0,0,42,42,42,42
42,42,0,0,0,0,0,0,0,0,0,0,0,42,42,42,42
42,42,0,0,0,0,0,0,0,0,0,0,0,42,42,42,42
42,42,0,0,0,0,0,0,0,0,0,0,0,42,42,42,42
42,42,0,0,0,0,0,0,0,0,0,0,0,42,42,42,42
42,42,42,0,0,0,0,0,0,0,0,0,0,42,42,42,42
42,42,42,42,0,0,0,0,0,0,0,0,42,42,42,42,42
42,42,42,42,42,0,0,0,0,0,42,42,42,42,42,42,42
endlayer

layer
42,42,42,42,42,42,42,42,42,42,42,42,42,42,42,42,42
42,42,42,42,42,42,42,42,42,42,42,42,42,42,42,42,42
42,42,42,42,42,42,0,42,42,42,42,42,42,42,42,42,42
42,42,42,0,0,0,0,0,0,0,42,42,42,42,42,42,42
42,42,0,0,0,0,0,0,0,0,0,42,42,42,42,42,42
42,42,0,0,0,0,0,0,0,0,0,42,42,42,42,42,42
42,42,0,0,0,0,0,0,0,0,0,42,42,42,42,42,42
42,0,0,0,0,0,0,0,0,0,0,0,42,42,42,42,42
42,42,0,0,0,0,0,0,0,0,0,0,0,42,42,42,42
42,42,0,0,0,0,0,0,0,0,0,0,0,42,42,42,42
42,42,0,0,0,0,0,0,0,0,0,0,0,42,42,42,42
42,42,42,0,0,0,0,0,0,0,0,0,0,0,42,42,42
42,42,42,0,0,0,0,0,0,0,0,0,0,42,42,42,42
42,42,42,0,0,0,0,0,0,0,0,0,0,42,42,42,42
42,42,0,0,0,0,0,0,0,0,0,0,0,42,42,42,42
42,42,0,0,0,0,0,0,0,0,0,0,42,42,42,42,42
42,42,0,0,0,0,0,0,0,0,0,0,42,42,42,42,42
42,42,42,0,0,0,0,0,0,0,0,0,42,42,42,42,42
42,42,42,0,0,0,0,0,0,0,0,0,0,42,42,42,42
42,42,42,42,0,0,0,0,0,0,0,0,0,42,42,42,42
42,42,42,0,0,0,0,0,0,0,0,0,0,42,42,42,42
42,42,42,0,0,0,0,0,0,0,0,0,42,42,42,42,42
42,42,0,0,0,0,0,0,0,0,0,0,42,42,42,42,42
42,42,0,0,0,0,0,0,0,0,0,0,42,42,42,42,42
42,42,0,0,0,0,0,0,0,0,0,0,0,42,42,42,42
42,42,42,0,0,0,0,0,0,0,0,0,0,42,42,42,42
42,42,42,0,0,0,0,0,0,0,0,0,0,42,42,42,42
42,42,0,0,0,0,0,0,0,0,0,0,0,42,42,42,42
42,42,42,0,0,0,0,0,0,0,0,0,0,42,42,42,42
42,42,42,0,0,0,0,0,0,0,0,0,0,42,42,42,42
42,42,42,0,0,0,0,0,0,0,0,0,0,42,42,42,42
42,42,42,42,0,0,0,0,0,0,0,42,42,42,42,42,42
42,42,42,42,42,42,0,0,0,42,42,42,42,42,42,42,42
endlayer

layer
42,42,42,42,42,42,42,42,42,42,42,42,42,42,42,42,42
42,42,42,42,42,42,42,42,42,42,42,42,42,42,42,42,42
42,42,42,42,42,42,42,42,42,42,42,42,42,42,42,42,42
42,42,42,42,42,0,0,0,42,42,42,42,42,42,42,42,42
42,42,42,0,0,0,0,0,0,0,42,42,42,42,42,42,42
42,42,42,0,0,0,0,0,0,0,42,42,42,42,42,42,42
42,42,0,0,0,0,0,0,0,0,0,42,42,42,42,42,42
42,42,0,0,0,0,0,0,0,0,0,42,42,42,42,42,42
42,42,0,0,0,0,0,0,0,0,0,0,42,42,42,42,42
42,42,42,0,0,0,0,0,0,0,0,0,42,42,42,42,42
42,42,42,0,0,0,0,0,0,0,0,0,0,42,42,42,42
42,42,42,42,0,0,0,0,0,0,0,0,0,42,42,42,42
42,42,42,42,0,0,0,0,0,0,0,0,0,42,42,42,42
42,42,42,42,0,0,0,0,0,0,0,0,42,42,42,42,42
42,42,42,42,0,0,0,0,0,0,0,0,42,42,42,42,42
42,42,42,0,0,0,0,0,0,0,42,42,42,42,42,42,42
42,42,42,42,0,0,0,0,0,42,42,42,42,42,42,42,42
42,42,42,42,0,0,0,0,0,0,0,42,42,42,42,42,42
42,42,42,42,42,42,0,0,0,0,0,42,42,42,42,42,42
42,42,42,42,42,0,0,0,0,0,0,0,42,42,42,42,42
42,42,42,42,42,42,0,0,0,0,0,42,42,42,42,42,42
42,42,42,42,0,0,0,0,0,0,0,42,42,42,42,42,42
42,42,42,42,0,0,0,0,0,0,42,42,42,42,42,42,42
42,42,42,0,0,0,0,0,0,0,0,42,42,42,42,42,42
42,42,42,42,0,0,0,0,0,0,0,42,42,42,42,42,42
42,42,42,0,0,0,0,0,0,0,0,0,42,42,42,42,42
42,42,42,0,0,0,0,0,0,0,0,0,0,42,42,42,42
42,42,42,0,0,0,0,0,0,0,0,0,42,42,42,42,42
42,42,42,42,0,0,0,0,0,0,0,0,42,42,42,42,42
42,42,42,42,42,0,0,0,0,0,0,0,42,42,42,42,42
42,42,42,42,42,0,0,0,0,0,0,42,42,42,42,42,42
42,42,42,42,42,42,0,0,0,0,42,42,42,42,42,42,42
42,42,42,42,42,42,42,42,42,42,42,42,42,42,42,42,42
endlayer

