
# Created by Ruins mod version 17.0 Ingame Parser
# authoring Player: ST753M

weight=1
embed_into_distance=5
acceptable_target_blocks=
unacceptable_target_blocks=flowing_water,water,flowing_lava,lava,ice,bedrock,netherrack,nether_brick,nether_brick_fence,soul_sand,quartz_ore,end_stone,obsidian,iron_bars,Natura:Cloud,slime_grass,slime_congealed,slime_dirt,clouds,natura:clouds,twilightforest:wispy_cloud,twilightforest:fluffy_cloud
dimensions=22,11,11
allowable_overhang=5
max_leveling=2
leveling_buffer=0
preserve_water=0
preserve_lava=0
uniqueMinDistance=1000
spawnMinDistance=1000

biomesToSpawnIn=prairie,rocky_plains,rocky_plateau,savanna,savanna_rock,steppe,wasteland,tundra,badlands,outback,red_desert,black_desert

=0,100,air
rule1=0,100,minecraft:stonebrick-0
rule2=0,100,minecraft:nether_brick-0
rule3=0,100,minecraft:concrete-14
rule4=0,100,minecraft:stone_brick_stairs-0
rule5=0,100,minecraft:stone_brick_stairs-2
rule6=0,100,minecraft:stone_brick_stairs-3
rule7=0,100,thaumcraft:loot_urn_common-0
rule8=0,100,thaumcraft:table_wood-0
rule9=0,100,minecraft:stone_brick_stairs-1
rule10=0,100,CommandBlock:RUINSTRIGGER /summon thaumcraft:cultistcleric ~ ~1 ~ {PersistenceRequired:1}:@-1,CommandBlock:RUINSTRIGGER /summon thaumcraft:thaumcraft:cultistknight ~ ~1 ~ {PersistenceRequired:1}:@-1,CommandBlock:RUINSTRIGGER /summon thaumcraft:thaumcraft:cultistknight ~ ~1 ~ {PersistenceRequired:1}:@-1
rule11=0,100,minecraft:bed-0
rule12=0,100,minecraft:bed-8
rule13=0,100,minecraft:stained_glass_pane-14
rule14=0,50,thaumcraft:candle_red-0
rule15=0,100,minecraft:stone_brick_stairs-5
rule16=0,100,minecraft:stone_brick_stairs-4
rule17=0,100,minecraft:stone_brick_stairs-6
rule18=0,100,minecraft:stone_brick_stairs-7
rule19=0,100,minecraft:nether_brick_stairs-7
rule20=0,100,minecraft:nether_brick_stairs-5
rule21=0,100,minecraft:nether_brick_stairs-6
rule22=0,100,minecraft:nether_brick_stairs-4
rule23=0,100,minecraft:stone_slab-6
rule24=0,100,minecraft:nether_brick_stairs-0
rule25=0,100,minecraft:nether_brick_stairs-2
rule26=0,100,minecraft:nether_brick_stairs-3
rule27=0,100,minecraft:nether_brick_stairs-1

layer
1,1,1,1,2,2,2,1,1,1,1
1,1,1,1,1,1,1,1,1,1,1
1,1,1,1,1,1,1,1,1,1,1
1,1,1,1,1,1,1,1,1,1,1
2,1,1,1,1,1,1,1,1,1,2
2,1,1,1,1,1,1,1,1,1,2
2,1,1,1,1,1,1,1,1,1,2
1,1,1,1,1,1,1,1,1,1,1
1,1,1,1,1,1,1,1,1,1,1
1,1,1,1,1,1,1,1,1,1,1
1,1,1,1,2,2,2,1,1,1,1
endlayer

layer
2,1,1,1,2,2,2,1,1,1,2
1,1,1,1,1,1,1,1,1,1,1
1,1,1,1,1,1,1,1,1,1,1
1,1,1,1,1,1,1,1,1,1,1
2,1,1,1,1,1,1,1,1,1,2
2,1,1,1,1,1,1,1,1,1,2
2,1,1,1,1,1,1,1,1,1,2
1,1,1,1,1,1,1,1,1,1,1
1,1,1,1,1,1,1,1,1,1,1
1,1,1,1,1,1,1,1,1,1,1
2,1,1,1,2,2,2,1,1,1,2
endlayer

layer
2,2,2,1,2,2,2,1,2,2,2
2,1,1,1,1,1,1,1,1,1,2
2,1,1,1,1,1,1,1,1,1,2
1,1,1,1,1,1,1,1,1,1,1
2,1,1,1,1,1,1,1,1,1,2
2,1,1,1,1,1,1,1,1,1,2
2,1,1,1,1,1,1,1,1,1,2
1,1,1,1,1,1,1,1,1,1,1
2,1,1,1,1,1,1,1,1,1,2
2,1,1,1,1,1,1,1,1,1,2
2,2,2,1,2,2,2,1,2,2,2
endlayer

layer
2,1,1,1,2,2,2,1,1,1,2
1,1,1,1,1,1,1,1,1,1,1
1,1,2,2,2,2,2,2,2,1,1
1,1,2,2,2,2,2,2,2,1,1
2,1,2,2,3,2,2,2,2,1,2
2,1,2,2,2,2,2,2,2,1,2
2,1,2,2,2,2,2,2,2,2,2
1,1,2,2,2,2,2,2,2,1,1
1,1,2,2,2,2,2,2,2,1,1
1,1,1,1,1,1,1,1,1,1,1
2,1,1,1,2,2,2,1,1,1,2
endlayer

layer
1,1,1,1,2,2,2,1,1,1,1
1,1,1,1,2,2,2,1,1,1,1
1,1,2,2,2,2,2,2,2,1,1
1,1,2,2,2,2,2,2,2,1,1
2,2,2,2,2,2,2,2,2,2,2
2,2,2,2,2,2,2,2,2,2,2
2,2,2,2,2,2,2,2,2,2,2
1,1,2,2,2,2,2,2,2,1,1
1,1,2,2,2,2,2,2,2,1,1
1,1,1,1,2,2,2,1,1,1,1
1,1,1,1,2,2,2,1,1,1,1
endlayer

layer
0,4,0,4,0,0,0,4,0,4,0
6,1,1,1,5,0,6,1,1,1,5
0,1,3,1,2,2,2,1,3,1,0
6,1,1,0,0,0,0,7,1,1,5
0,9,2,0,8,0,0,0,0,0,0
0,0,2,0,8,10,0,0,0,0,0
0,4,2,0,0,0,0,0,0,0,0
6,1,1,12,11,0,0,0,1,1,5
0,1,3,1,2,2,2,1,3,1,0
6,1,1,1,5,0,6,1,1,1,5
0,9,0,9,0,0,0,9,0,9,0
endlayer

layer
0,0,0,0,0,0,0,0,0,0,0
0,0,6,1,0,0,0,1,5,0,0
0,4,3,1,2,13,2,1,3,4,0
0,1,1,0,0,0,0,0,1,1,0
0,0,2,0,14,0,0,0,0,0,0
0,0,13,0,0,0,0,0,0,0,0
0,0,2,0,0,0,0,0,0,0,0
0,1,1,0,0,0,0,0,1,1,0
0,9,3,1,2,13,2,1,3,9,0
0,0,6,1,0,0,0,1,5,0,0
0,0,0,0,0,0,0,0,0,0,0
endlayer

layer
0,0,0,0,0,0,0,0,0,0,0
0,0,0,1,0,0,0,1,0,0,0
0,0,3,1,13,13,13,1,3,0,0
0,1,1,0,0,0,0,0,1,1,0
0,0,13,0,0,0,0,0,0,0,0
0,0,13,0,0,0,0,0,0,0,0
0,0,13,0,0,0,0,0,0,0,0
0,1,1,0,0,0,0,0,1,1,0
0,0,3,1,13,13,13,1,3,0,0
0,0,0,1,0,0,0,1,0,0,0
0,0,0,0,0,0,0,0,0,0,0
endlayer

layer
0,0,0,0,0,0,0,0,0,0,0
0,0,0,1,0,0,0,1,0,0,0
0,0,3,1,13,13,13,1,3,0,0
0,1,1,0,0,0,0,0,1,1,0
0,0,13,0,0,0,0,0,15,15,0
0,0,13,0,0,0,0,0,0,0,0
0,0,13,0,0,0,0,0,16,16,0
0,1,1,0,0,0,0,0,1,1,0
0,0,3,1,13,13,13,1,3,0,0
0,0,0,1,0,0,0,1,0,0,0
0,0,0,0,0,0,0,0,0,0,0
endlayer

layer
0,0,0,0,0,0,0,0,0,0,0
0,0,18,1,0,0,0,1,17,0,0
0,16,3,1,2,13,2,1,3,16,0
0,1,1,0,0,0,0,0,1,1,0
0,0,2,0,0,0,0,0,1,1,0
0,0,13,0,0,0,0,0,1,1,0
0,0,2,0,0,0,0,0,1,1,0
0,1,1,0,0,0,0,0,1,1,0
0,15,3,1,2,13,2,1,3,15,0
0,0,18,1,0,0,0,1,17,0,0
0,0,0,0,0,0,0,0,0,0,0
endlayer

layer
0,0,0,16,0,0,0,16,0,0,0
0,1,1,1,17,0,18,1,1,1,0
0,1,3,1,2,2,2,1,3,1,0
18,1,1,0,0,0,0,0,1,1,17
0,15,2,0,0,0,0,0,13,0,0
0,0,2,0,0,0,0,0,13,0,0
0,16,2,0,0,0,0,0,13,0,0
18,1,1,0,0,0,0,0,1,1,17
0,1,3,1,2,2,2,1,3,1,0
0,1,1,1,17,0,18,1,1,1,0
0,0,0,15,0,0,0,15,0,0,0
endlayer

layer
0,16,0,1,0,16,0,1,0,16,0
18,1,1,1,1,1,1,1,1,1,17
0,1,1,1,1,1,1,1,1,1,0
1,1,1,0,0,0,0,0,1,1,1
0,1,1,0,0,0,0,0,1,1,0
18,1,1,0,0,0,0,0,1,1,17
0,1,1,0,0,0,0,0,1,1,0
1,1,1,0,0,0,0,0,1,1,1
0,1,1,1,1,1,1,1,1,1,0
18,1,1,1,1,1,1,1,1,1,17
0,15,0,1,0,15,0,1,0,15,0
endlayer

layer
0,9,0,9,0,9,0,9,0,9,0
5,2,2,2,2,2,2,2,2,2,6
0,2,2,2,2,2,2,2,2,2,0
5,2,2,21,20,20,20,19,2,2,6
0,2,2,21,0,0,0,19,2,2,0
5,2,2,21,0,0,0,19,2,2,6
0,2,2,21,0,0,0,19,2,2,0
5,2,2,21,22,22,22,22,2,2,6
0,2,2,2,2,2,2,2,2,2,0
5,2,2,2,2,2,2,2,2,2,6
0,4,0,4,0,4,0,4,0,4,0
endlayer

layer
0,0,0,0,0,0,0,0,0,0,0
0,23,2,2,2,2,2,2,2,23,0
0,2,2,2,2,2,2,2,2,2,0
0,2,2,2,2,2,2,2,2,2,0
0,2,2,2,21,20,19,2,2,2,0
0,2,2,2,21,0,19,2,2,2,0
0,2,2,2,21,22,22,2,2,2,0
0,2,2,2,2,2,2,2,2,2,0
0,2,2,2,2,2,2,2,2,2,0
0,23,2,2,2,2,2,2,2,23,0
0,0,0,0,0,0,0,0,0,0,0
endlayer

layer
0,0,0,0,0,0,0,0,0,0,0
0,0,0,23,2,2,2,23,0,0,0
0,0,2,2,2,2,2,2,2,0,0
0,23,2,2,2,2,2,2,2,23,0
0,2,2,2,2,2,2,2,2,2,0
0,2,2,2,2,2,2,2,2,2,0
0,2,2,2,2,2,2,2,2,2,0
0,23,2,2,2,2,2,2,2,23,0
0,0,2,2,2,2,2,2,2,0,0
0,0,0,23,2,2,2,23,0,0,0
0,0,0,0,0,0,0,0,0,0,0
endlayer

layer
0,0,0,0,0,0,0,0,0,0,0
0,0,0,0,0,23,0,0,0,0,0
0,0,23,2,2,2,2,2,23,0,0
0,0,2,2,2,2,2,2,2,0,0
0,0,2,2,2,2,2,2,2,0,0
0,23,2,2,2,2,2,2,2,23,0
0,0,2,2,2,2,2,2,2,0,0
0,0,2,2,2,2,2,2,2,0,0
0,0,23,2,2,2,2,2,23,0,0
0,0,0,0,0,23,0,0,0,0,0
0,0,0,0,0,0,0,0,0,0,0
endlayer

layer
0,0,0,0,0,0,0,0,0,0,0
0,0,0,0,0,0,0,0,0,0,0
0,0,0,0,23,2,23,0,0,0,0
0,0,0,2,2,2,2,2,0,0,0
0,0,23,2,2,2,2,2,23,0,0
0,0,2,2,2,2,2,2,2,0,0
0,0,23,2,2,2,2,2,23,0,0
0,0,0,2,2,2,2,2,0,0,0
0,0,0,0,23,2,23,0,0,0,0
0,0,0,0,0,0,0,0,0,0,0
0,0,0,0,0,0,0,0,0,0,0
endlayer

layer
0,0,0,0,0,0,0,0,0,0,0
0,0,0,0,0,0,0,0,0,0,0
0,0,0,0,0,0,0,0,0,0,0
0,0,0,23,2,2,2,23,0,0,0
0,0,0,2,2,2,2,2,0,0,0
0,0,0,2,2,2,2,2,0,0,0
0,0,0,2,2,2,2,2,0,0,0
0,0,0,23,2,2,2,23,0,0,0
0,0,0,0,0,0,0,0,0,0,0
0,0,0,0,0,0,0,0,0,0,0
0,0,0,0,0,0,0,0,0,0,0
endlayer

layer
0,0,0,0,0,0,0,0,0,0,0
0,0,0,0,0,0,0,0,0,0,0
0,0,0,0,0,0,0,0,0,0,0
0,0,0,0,0,23,0,0,0,0,0
0,0,0,0,2,2,2,0,0,0,0
0,0,0,23,2,2,2,23,0,0,0
0,0,0,0,2,2,2,0,0,0,0
0,0,0,0,0,23,0,0,0,0,0
0,0,0,0,0,0,0,0,0,0,0
0,0,0,0,0,0,0,0,0,0,0
0,0,0,0,0,0,0,0,0,0,0
endlayer

layer
0,0,0,0,0,0,0,0,0,0,0
0,0,0,0,0,0,0,0,0,0,0
0,0,0,0,0,0,0,0,0,0,0
0,0,0,0,0,0,0,0,0,0,0
0,0,0,0,23,2,23,0,0,0,0
0,0,0,0,2,2,2,0,0,0,0
0,0,0,0,23,2,23,0,0,0,0
0,0,0,0,0,0,0,0,0,0,0
0,0,0,0,0,0,0,0,0,0,0
0,0,0,0,0,0,0,0,0,0,0
0,0,0,0,0,0,0,0,0,0,0
endlayer

layer
0,0,0,0,0,0,0,0,0,0,0
0,0,0,0,0,0,0,0,0,0,0
0,0,0,0,0,0,0,0,0,0,0
0,0,0,0,0,0,0,0,0,0,0
0,0,0,0,0,24,0,0,0,0,0
0,0,0,0,26,2,25,0,0,0,0
0,0,0,0,0,27,0,0,0,0,0
0,0,0,0,0,0,0,0,0,0,0
0,0,0,0,0,0,0,0,0,0,0
0,0,0,0,0,0,0,0,0,0,0
0,0,0,0,0,0,0,0,0,0,0
endlayer

layer
0,0,0,0,0,0,0,0,0,0,0
0,0,0,0,0,0,0,0,0,0,0
0,0,0,0,0,0,0,0,0,0,0
0,0,0,0,0,0,0,0,0,0,0
0,0,0,0,0,0,0,0,0,0,0
0,0,0,0,0,2,0,0,0,0,0
0,0,0,0,0,0,0,0,0,0,0
0,0,0,0,0,0,0,0,0,0,0
0,0,0,0,0,0,0,0,0,0,0
0,0,0,0,0,0,0,0,0,0,0
0,0,0,0,0,0,0,0,0,0,0
endlayer

