
# Created by Ruins mod version 17.0 Ingame Parser
# authoring Player: ST753M

weight=1
embed_into_distance=21
acceptable_target_blocks=
unacceptable_target_blocks=flowing_water,water,flowing_lava,lava,ice,bedrock,netherrack,nether_brick,nether_brick_fence,soul_sand,quartz_ore,end_stone,obsidian,iron_bars,Natura:Cloud,slime_grass,slime_congealed,slime_dirt,clouds,natura:clouds
dimensions=27,17,17
allowable_overhang=999
max_leveling=2
leveling_buffer=0
preserve_water=0
preserve_lava=0

biomesToSpawnIn=bamboo_forest,overgrown_cliffs,eucalyptus_forest,forest,maple_woods,boreal_forest,forest_hills,woodland,seasonal_forest,lush_hills,mountain,mountain_foothills,extreme_hills,smaller_extreme_hills,mutated_extreme_hills,mutated_extreme_hills_with_trees,extreme_hills_with_trees,highland,rocky_plains,rocky_plateau,savanna,savanna_rock,mutated_savanna,mutated_savanna_rock,brushland,steppe,wasteland,tundra,outback,badlands,desert_shrubland,arid_highland,darklands,darklands_forest,darklands_hills,darklands_mountains,darklands_plains,ominous_woods,eerie

rule1=0,100,preserveBlock

#	Main walls
rule2=0,100,minecraft:stone_brick_stairs-3,minecraft:stone_brick_stairs-6,minecraft:stone_brick_stairs-0,minecraft:stonebrick-2,minecraft:stonebrick-0,minecraft:stonebrick-1,minecraft:monster_egg-3,minecraft:monster_egg-2,minecraft:stonebrick-2,minecraft:stonebrick-0,minecraft:stonebrick-1,minecraft:monster_egg-3,minecraft:monster_egg-2,minecraft:stone_brick_stairs-1,minecraft:stone_brick_stairs-5
^0,100,minecraft:monster_egg-1,minecraft:stone_stairs-6,minecraft:stone_stairs-7,minecraft:stone_stairs-2,minecraft:stone_stairs-0,minecraft:cobblestone-0,minecraft:mossy_cobblestone-0,minecraft:cobblestone-0,minecraft:mossy_cobblestone-0,minecraft:cobblestone-0,minecraft:mossy_cobblestone-0,minecraft:monster_egg-1,minecraft:monster_egg-1,minecraft:mossy_cobblestone-0,minecraft:stone_stairs-1,minecraft:stone_stairs-5
^0,100,minecraft:brick_block-0

#	Floor.  Should be crumbly.
rule3^2,65,minecraft:stone_brick_stairs-3,minecraft:stone_brick_stairs-6,minecraft:stone_brick_stairs-0,minecraft:stonebrick-2,minecraft:stonebrick-0,minecraft:stonebrick-1,minecraft:monster_egg-3,minecraft:monster_egg-2,minecraft:stonebrick-2,minecraft:stonebrick-0,minecraft:stonebrick-1,minecraft:monster_egg-3,minecraft:monster_egg-2,minecraft:stone_slab-5
^2,65,minecraft:monster_egg-1,minecraft:stone_stairs-6,minecraft:stone_stairs-7,minecraft:stone_stairs-2,minecraft:stone_stairs-0,minecraft:cobblestone-0,minecraft:mossy_cobblestone-0,minecraft:cobblestone-0,minecraft:mossy_cobblestone-0,minecraft:cobblestone-0,minecraft:mossy_cobblestone-0,minecraft:monster_egg-1,minecraft:monster_egg-1,minecraft:mossy_cobblestone-0,minecraft:stone_slab-3,minecraft:stone_slab-3
^2,65,minecraft:brick_block-0,minecraft:stone_slab-4

rule4^0,100,minecraft:stone_brick_stairs-3
^0,100,minecraft:stone_stairs-3
^0,100,minecraft:brick_stairs-3

rule5^0,100,minecraft:stone_brick_stairs-5
^0,100,minecraft:stone_stairs-5
^0,100,minecraft:brick_stairs-5

rule6^0,100,minecraft:stone_brick_stairs-1
^0,100,minecraft:stone_stairs-1
^0,100,minecraft:brick_stairs-1

rule7^0,100,ChestGenHook:chests/simple_dungeon:5-2
^0,100,ChestGenHook:chests/simple_dungeon:5-2
^0,100,ChestGenHook:chests/simple_dungeon:5-2

rule8^0,100,minecraft:stone_brick_stairs-0
^0,100,minecraft:stone_stairs-0
^0,100,minecraft:brick_stairs-0

rule9^0,100,minecraft:stone_brick_stairs-2
^0,100,minecraft:stone_stairs-2
^0,100,minecraft:brick_stairs-2

rule10^0,80,MobSpawner:skeleton,MobSpawner:skeleton,MobSpawner:zombie,MobSpawner:zombie,MobSpawner:creeper,MobSpawner:witch
^0,80,MobSpawner:skeleton,MobSpawner:zombie,MobSpawner:silverfish
^0,80,MobSpawner:spider,MobSpawner:cave_spider,MobSpawner:zombie

rule11^0,100,minecraft:stone_brick_stairs-4
^0,100,minecraft:stone_stairs-4
^0,100,minecraft:brick_stairs-4

rule12^0,100,minecraft:stone_brick_stairs-7
^0,100,minecraft:stone_stairs-7
^0,100,minecraft:brick_stairs-7

rule13^0,100,minecraft:stone_brick_stairs-6
^0,100,minecraft:stone_stairs-6
^0,100,minecraft:brick_stairs-6

rule14^0,100,minecraft:water-0
^0,100,minecraft:water-0
^0,100,minecraft:water-0

rule15^0,100,minecraft:stone_slab-5
^0,100,minecraft:stone_slab-3
^0,100,minecraft:stone_slab-4

rule16=0,100,minecraft:water-9

rule17=0,100,minecraft:water-1

layer
1,1,1,1,1,1,2,1,1,1,2,1,1,1,1,1,1
1,1,1,1,1,1,2,2,2,2,2,1,1,1,1,1,1
1,1,1,1,2,2,2,2,2,2,2,2,2,1,1,1,1
1,1,1,2,2,2,3,3,3,3,3,2,2,2,1,1,1
1,1,2,2,2,3,3,3,3,3,3,3,2,2,2,1,1
1,1,2,2,3,3,3,3,2,3,3,3,3,2,2,1,1
2,2,2,2,3,3,3,2,2,2,3,3,3,2,2,2,2
1,2,2,2,3,3,2,2,2,2,2,3,3,2,2,2,1
1,2,2,2,3,2,2,2,2,2,2,2,3,3,2,2,1
1,2,2,2,3,2,2,2,2,2,2,2,3,3,2,2,1
2,2,2,2,3,3,2,2,2,2,2,3,3,3,2,2,2
1,1,2,2,3,3,3,2,2,2,3,3,3,2,2,1,1
1,1,2,2,2,3,3,3,3,3,3,3,2,2,2,1,1
1,1,1,2,2,2,3,3,3,3,3,2,2,2,1,1,1
1,1,1,1,2,2,2,2,2,2,2,2,2,1,1,1,1
1,1,1,1,1,1,2,2,2,2,2,1,1,1,1,1,1
1,1,1,1,1,1,2,1,1,1,2,1,1,1,1,1,1
endlayer

layer
1,1,1,1,1,1,2,1,1,1,2,1,1,1,1,1,1
1,1,1,1,1,1,2,2,2,2,2,1,1,1,1,1,1
1,1,1,1,2,2,0,0,0,0,0,2,2,1,1,1,1
1,1,1,2,0,0,0,0,0,0,0,0,0,2,1,1,1
1,1,2,0,0,0,0,0,0,0,0,0,0,0,2,1,1
1,1,2,0,0,0,0,0,0,0,0,0,0,0,2,1,1
2,2,2,0,0,0,0,2,2,2,0,0,0,0,4,2,2
1,2,2,0,0,0,2,2,2,2,2,0,0,0,5,2,1
1,2,2,0,0,0,2,2,2,2,2,0,0,0,0,2,1
1,2,2,0,0,0,2,2,2,2,2,0,0,0,0,2,1
2,2,2,0,0,0,0,2,2,2,0,0,0,0,0,2,2
1,1,2,0,0,0,0,0,0,0,0,0,0,0,2,1,1
1,1,2,0,0,0,0,0,0,0,0,0,0,0,2,1,1
1,1,1,2,0,0,0,0,0,0,0,0,0,2,1,1,1
1,1,1,1,2,2,0,0,0,0,0,2,2,1,1,1,1
1,1,1,1,1,1,2,2,2,2,2,1,1,1,1,1,1
1,1,1,1,1,1,2,1,1,1,2,1,1,1,1,1,1
endlayer

layer
1,1,1,1,1,1,2,1,1,1,2,1,1,1,1,1,1
1,1,1,1,1,1,2,6,6,6,2,1,1,1,1,1,1
1,1,1,1,2,2,0,0,0,0,0,2,2,1,1,1,1
1,1,1,2,0,0,0,0,0,0,0,0,0,2,1,1,1
1,1,2,0,0,0,0,0,0,0,0,0,0,0,2,1,1
1,1,2,0,0,0,0,0,0,0,0,0,0,0,2,1,1
2,2,7,0,0,0,0,3,2,3,0,0,0,0,0,2,2
1,2,7,0,0,0,3,2,2,2,3,0,0,0,8,2,1
1,2,9,0,0,0,2,2,2,2,2,0,0,0,5,2,1
1,2,7,0,0,0,3,2,2,2,3,0,0,0,0,2,1
2,2,7,0,0,0,0,3,2,3,0,0,0,0,0,2,2
1,1,2,0,0,0,0,0,0,0,0,0,0,0,2,1,1
1,1,2,0,0,0,0,0,0,0,0,0,0,0,2,1,1
1,1,1,2,0,0,0,0,0,0,0,0,0,2,1,1,1
1,1,1,1,2,2,0,0,0,0,0,2,2,1,1,1,1
1,1,1,1,1,1,2,8,8,8,2,1,1,1,1,1,1
1,1,1,1,1,1,2,1,1,1,2,1,1,1,1,1,1
endlayer

layer
1,1,1,1,1,1,2,1,1,1,2,1,1,1,1,1,1
1,1,1,1,1,1,2,5,5,5,2,1,1,1,1,1,1
1,1,1,1,2,2,0,0,0,0,0,2,2,1,1,1,1
1,1,1,2,0,0,0,0,0,0,0,0,0,2,1,1,1
1,1,2,0,0,0,0,0,0,0,0,0,0,0,2,1,1
1,1,2,0,0,0,0,0,0,0,0,0,0,0,2,1,1
2,2,0,0,0,0,0,3,2,3,0,0,0,0,0,2,2
1,2,0,0,0,0,3,2,2,2,3,0,0,0,0,2,1
1,2,0,0,0,0,2,2,10,2,2,0,0,0,8,2,1
1,2,0,0,0,0,3,2,2,2,3,0,0,0,5,2,1
2,2,0,0,0,0,0,3,2,3,0,0,0,0,0,2,2
1,1,2,0,0,0,0,0,0,0,0,0,0,0,2,1,1
1,1,2,0,0,0,0,0,0,0,0,0,0,0,2,1,1
1,1,1,2,0,0,0,0,0,0,0,0,0,2,1,1,1
1,1,1,1,2,2,0,0,0,0,0,2,2,1,1,1,1
1,1,1,1,1,1,2,11,11,11,2,1,1,1,1,1,1
1,1,1,1,1,1,2,1,1,1,2,1,1,1,1,1,1
endlayer

layer
1,1,1,1,1,1,2,1,1,1,2,1,1,1,1,1,1
1,1,1,1,1,1,2,2,2,2,2,1,1,1,1,1,1
1,1,1,1,2,2,13,0,0,0,12,2,2,1,1,1,1
1,1,1,2,0,0,0,0,0,0,0,0,0,2,1,1,1
1,1,2,0,0,0,0,0,0,0,0,0,0,0,2,1,1
1,1,2,0,0,0,0,11,0,11,0,0,0,0,2,1,1
2,2,5,0,0,0,0,2,2,2,0,0,0,0,0,2,2
1,2,0,0,0,12,2,2,2,2,2,13,0,0,0,2,1
1,2,0,0,0,0,2,2,2,2,2,0,0,0,0,2,1
1,2,0,0,0,12,2,2,2,2,2,13,0,0,8,2,1
2,2,11,0,0,0,0,2,2,2,0,0,0,0,5,2,2
1,1,2,0,0,0,0,5,0,5,0,0,0,0,2,1,1
1,1,2,0,0,0,0,0,0,0,0,0,0,0,2,1,1
1,1,1,2,0,0,0,0,0,0,0,0,0,2,1,1,1
1,1,1,1,2,2,13,0,0,0,12,2,2,1,1,1,1
1,1,1,1,1,1,2,2,2,2,2,1,1,1,1,1,1
1,1,1,1,1,1,2,1,1,1,2,1,1,1,1,1,1
endlayer

layer
1,1,1,1,1,1,2,1,1,1,2,1,1,1,1,1,1
1,1,1,1,1,1,2,2,2,2,2,1,1,1,1,1,1
1,1,1,1,2,2,2,3,3,3,2,2,2,1,1,1,1
1,1,1,2,2,3,3,3,3,3,3,3,2,2,1,1,1
1,1,2,2,3,3,3,3,3,3,3,3,3,2,2,1,1
1,1,2,3,3,3,3,2,3,2,3,3,3,3,2,1,1
2,2,2,3,3,3,3,2,2,2,3,3,3,3,0,2,2
1,2,3,3,3,2,2,2,2,2,2,2,3,3,0,2,1
1,2,3,3,3,3,2,2,2,2,2,3,3,3,0,2,1
1,2,3,3,3,2,2,2,2,2,2,2,3,3,0,2,1
2,2,2,2,3,3,3,2,2,2,3,3,3,3,8,2,2
1,1,2,3,3,3,3,2,3,2,3,3,3,3,2,1,1
1,1,2,2,3,3,3,3,3,3,3,3,3,2,2,1,1
1,1,1,2,2,3,3,3,3,3,3,3,2,2,1,1,1
1,1,1,1,2,2,2,3,3,3,2,2,2,1,1,1,1
1,1,1,1,1,1,2,2,2,2,2,1,1,1,1,1,1
1,1,1,1,1,1,2,1,1,1,2,1,1,1,1,1,1
endlayer

layer
1,1,1,1,1,1,2,1,1,1,2,1,1,1,1,1,1
1,1,1,1,1,1,2,2,2,2,2,1,1,1,1,1,1
1,1,1,1,2,2,0,0,0,0,0,2,2,1,1,1,1
1,1,1,2,0,0,0,0,0,0,0,0,0,2,1,1,1
1,1,2,0,0,0,0,0,0,0,0,0,0,0,2,1,1
1,1,2,0,0,0,0,0,0,0,0,0,0,0,2,1,1
2,2,0,0,0,0,0,2,2,2,0,0,0,0,0,2,2
1,2,0,0,0,0,2,2,2,2,2,0,0,0,0,2,1
1,2,0,0,0,0,2,2,2,2,2,0,0,0,0,2,1
1,2,11,0,0,0,2,2,2,2,2,0,0,0,0,2,1
2,2,9,0,0,0,0,2,2,2,0,0,0,0,0,2,2
1,1,2,0,0,0,0,0,0,0,0,0,0,0,2,1,1
1,1,2,0,0,0,0,0,0,0,0,0,0,0,2,1,1
1,1,1,2,0,0,0,0,0,0,0,0,0,2,1,1,1
1,1,1,1,2,2,0,0,0,0,0,2,2,1,1,1,1
1,1,1,1,1,1,2,2,2,2,2,1,1,1,1,1,1
1,1,1,1,1,1,2,1,1,1,2,1,1,1,1,1,1
endlayer

layer
1,1,1,1,1,1,2,1,1,1,2,1,1,1,1,1,1
1,1,1,1,1,1,2,6,6,6,2,1,1,1,1,1,1
1,1,1,1,2,2,0,0,0,0,0,2,2,1,1,1,1
1,1,1,2,0,0,0,0,0,0,0,0,0,2,1,1,1
1,1,2,0,0,0,0,0,0,0,0,0,0,0,2,1,1
1,1,2,0,0,0,0,0,0,0,0,0,0,0,2,1,1
2,2,0,0,0,0,0,3,2,3,0,0,0,0,0,2,2
1,2,0,0,0,0,3,2,2,2,3,0,0,0,0,4,1
1,2,11,0,0,0,2,2,2,2,2,0,0,0,0,4,1
1,2,6,0,0,0,3,2,2,2,3,0,0,0,0,4,1
2,2,0,0,0,0,0,3,2,3,0,0,0,0,0,2,2
1,1,2,0,0,0,0,0,0,0,0,0,0,0,2,1,1
1,1,2,0,0,0,0,0,0,0,0,0,0,0,2,1,1
1,1,1,2,0,0,0,0,0,0,0,0,0,2,1,1,1
1,1,1,1,2,2,0,0,0,0,0,2,2,1,1,1,1
1,1,1,1,1,1,2,8,8,8,2,1,1,1,1,1,1
1,1,1,1,1,1,2,1,1,1,2,1,1,1,1,1,1
endlayer

layer
1,1,1,1,1,1,2,1,1,1,2,1,1,1,1,1,1
1,1,1,1,1,1,2,5,5,5,2,1,1,1,1,1,1
1,1,1,1,2,2,0,0,0,0,0,2,2,1,1,1,1
1,1,1,2,0,0,0,0,0,0,0,0,0,2,1,1,1
1,1,2,0,0,0,0,0,0,0,0,0,0,0,2,1,1
1,1,2,0,0,0,0,0,0,0,0,0,0,0,2,1,1
2,2,0,0,0,0,0,3,2,3,0,0,0,0,0,2,2
1,2,11,0,0,0,3,2,2,2,3,0,0,0,0,12,1
1,2,6,0,0,0,2,2,10,2,2,0,0,0,0,12,1
1,2,0,0,0,0,3,2,2,2,3,0,0,0,0,12,1
2,2,0,0,0,0,0,3,2,3,0,0,0,0,0,2,2
1,1,2,0,0,0,0,0,0,0,0,0,0,0,2,1,1
1,1,2,0,0,0,0,0,0,0,0,0,0,0,2,1,1
1,1,1,2,0,0,0,0,0,0,0,0,0,2,1,1,1
1,1,1,1,2,2,0,0,0,0,0,2,2,1,1,1,1
1,1,1,1,1,1,2,11,11,11,2,1,1,1,1,1,1
1,1,1,1,1,1,2,1,1,1,2,1,1,1,1,1,1
endlayer

layer
1,1,1,1,1,1,2,1,1,1,2,1,1,1,1,1,1
1,1,1,1,1,1,2,2,2,2,2,1,1,1,1,1,1
1,1,1,1,2,2,13,0,0,0,12,2,2,1,1,1,1
1,1,1,2,0,0,0,0,0,0,0,0,0,2,1,1,1
1,1,2,0,0,0,0,0,0,0,0,0,0,0,2,1,1
1,1,2,0,0,0,0,11,0,11,0,0,0,0,2,1,1
2,2,11,0,0,0,0,2,2,2,0,0,0,0,5,2,2
1,2,6,0,0,12,2,2,2,2,2,13,0,0,0,2,1
1,2,0,0,0,0,2,2,2,2,2,0,0,0,0,2,1
1,2,0,0,0,12,2,2,2,2,2,13,0,0,0,2,1
2,2,0,0,0,0,0,2,2,2,0,0,0,0,11,2,2
1,1,2,0,0,0,0,5,0,5,0,0,0,0,2,1,1
1,1,2,0,0,0,0,0,0,0,0,0,0,0,2,1,1
1,1,1,2,0,0,0,0,0,0,0,0,0,2,1,1,1
1,1,1,1,2,2,13,0,0,0,12,2,2,1,1,1,1
1,1,1,1,1,1,2,2,2,2,2,1,1,1,1,1,1
1,1,1,1,1,1,2,1,1,1,2,1,1,1,1,1,1
endlayer

layer
1,1,1,1,1,1,2,1,1,1,2,1,1,1,1,1,1
1,1,1,1,1,1,2,2,2,2,2,1,1,1,1,1,1
1,1,1,1,2,2,2,3,3,3,2,2,2,1,1,1,1
1,1,1,2,2,3,3,3,3,3,3,3,2,2,1,1,1
1,1,2,2,3,3,3,3,3,3,3,3,3,2,2,1,1
1,1,2,3,3,3,3,2,3,2,3,3,3,3,2,1,1
2,2,6,3,3,3,3,2,2,2,3,3,3,2,2,2,2
1,2,0,3,3,2,2,2,2,2,2,2,3,3,3,2,1
1,2,0,3,3,3,2,2,2,2,2,3,3,3,3,2,1
1,2,0,3,3,2,2,2,2,2,2,2,3,3,3,2,1
2,2,0,3,3,3,3,2,2,2,3,3,3,3,2,2,2
1,1,2,3,3,3,3,2,3,2,3,3,3,3,2,1,1
1,1,2,2,3,3,3,3,3,3,3,3,3,2,2,1,1
1,1,1,2,2,2,3,3,3,3,3,3,2,2,1,1,1
1,1,1,1,2,2,2,3,3,3,2,2,2,1,1,1,1
1,1,1,1,1,1,2,2,2,2,2,1,1,1,1,1,1
1,1,1,1,1,1,2,1,1,1,2,1,1,1,1,1,1
endlayer

layer
1,1,1,1,1,1,2,1,1,1,2,1,1,1,1,1,1
1,1,1,1,1,1,2,2,2,2,2,1,1,1,1,1,1
1,1,1,1,2,2,0,0,0,0,0,2,2,1,1,1,1
1,1,1,2,0,0,0,0,0,0,0,0,0,2,1,1,1
1,1,2,0,0,0,0,0,0,0,0,0,0,0,2,1,1
1,1,2,0,0,0,0,0,0,0,0,0,0,0,2,1,1
2,2,0,0,0,0,0,2,2,2,0,0,0,0,4,2,2
1,2,0,0,0,0,2,2,2,2,2,0,0,0,5,2,1
1,2,0,0,0,0,2,2,2,2,2,0,0,0,0,2,1
1,2,0,0,0,0,2,2,2,2,2,0,0,0,0,2,1
2,2,0,0,0,0,0,2,2,2,0,0,0,0,0,2,2
1,1,2,0,0,0,0,0,0,0,0,0,0,0,2,1,1
1,1,2,0,0,0,0,0,0,0,0,0,0,0,2,1,1
1,1,1,2,0,0,0,0,0,0,0,0,0,2,1,1,1
1,1,1,1,2,2,0,0,0,0,0,2,2,1,1,1,1
1,1,1,1,1,1,2,2,2,2,2,1,1,1,1,1,1
1,1,1,1,1,1,2,1,1,1,2,1,1,1,1,1,1
endlayer

layer
1,1,1,1,1,1,2,1,1,1,2,1,1,1,1,1,1
1,1,1,1,1,1,2,6,6,6,2,1,1,1,1,1,1
1,1,1,1,2,2,0,0,0,0,0,2,2,1,1,1,1
1,1,1,2,0,0,0,0,0,0,0,0,0,2,1,1,1
1,1,2,0,0,0,0,0,0,0,0,0,0,0,2,1,1
1,1,2,0,0,0,0,0,0,0,0,0,0,0,2,1,1
2,2,0,0,0,0,0,3,2,3,0,0,0,0,0,2,2
1,9,0,0,0,0,3,2,2,2,3,0,0,0,8,2,1
1,9,0,0,0,0,2,2,2,2,2,0,0,0,5,2,1
1,9,0,0,0,0,3,2,2,2,3,0,0,0,0,2,1
2,2,0,0,0,0,0,3,2,3,0,0,0,0,0,2,2
1,1,2,0,0,0,0,0,0,0,0,0,0,0,2,1,1
1,1,2,0,0,0,0,0,0,0,0,0,0,0,2,1,1
1,1,1,2,0,0,0,0,0,0,0,0,0,2,1,1,1
1,1,1,1,2,2,0,0,0,0,0,2,2,1,1,1,1
1,1,1,1,1,1,2,8,8,8,2,1,1,1,1,1,1
1,1,1,1,1,1,2,1,1,1,2,1,1,1,1,1,1
endlayer

layer
1,1,1,1,1,1,2,1,1,1,2,1,1,1,1,1,1
1,1,1,1,1,1,2,5,5,5,2,1,1,1,1,1,1
1,1,1,1,2,2,0,0,0,0,0,2,2,1,1,1,1
1,1,1,2,0,0,0,0,0,0,0,0,0,2,1,1,1
1,1,2,0,0,0,0,0,0,0,0,0,0,0,2,1,1
1,1,2,0,0,0,0,0,0,0,0,0,0,0,2,1,1
2,2,0,0,0,0,0,3,2,3,0,0,0,0,0,2,2
1,13,0,0,0,0,3,2,2,2,3,0,0,0,0,2,1
1,13,0,0,0,0,2,2,10,2,2,0,0,0,8,2,1
1,13,0,0,0,0,3,2,2,2,3,0,0,0,5,2,1
2,2,0,0,0,0,0,3,2,3,0,0,0,0,0,2,2
1,1,2,0,0,0,0,0,0,0,0,0,0,0,2,1,1
1,1,2,0,0,0,0,0,0,0,0,0,0,0,2,1,1
1,1,1,2,0,0,0,0,0,0,0,0,0,2,1,1,1
1,1,1,1,2,2,0,0,0,0,0,2,2,1,1,1,1
1,1,1,1,1,1,2,11,11,11,2,1,1,1,1,1,1
1,1,1,1,1,1,2,1,1,1,2,1,1,1,1,1,1
endlayer

layer
1,1,1,1,1,1,2,1,1,1,2,1,1,1,1,1,1
1,1,1,1,1,1,2,2,2,2,2,1,1,1,1,1,1
1,1,1,1,2,2,13,0,0,0,12,2,2,1,1,1,1
1,1,1,2,0,0,0,0,0,0,0,0,0,2,1,1,1
1,1,2,0,0,0,0,0,0,0,0,0,0,0,2,1,1
1,1,2,0,0,0,0,11,0,11,0,0,0,0,2,1,1
2,2,5,0,0,0,0,2,2,2,0,0,0,0,0,2,2
1,2,0,0,0,12,2,2,2,2,2,13,0,0,0,2,1
1,2,0,0,0,0,2,2,2,2,2,0,0,0,0,2,1
1,2,0,0,0,12,2,2,2,2,2,13,0,0,8,2,1
2,2,11,0,0,0,0,2,2,2,0,0,0,0,5,2,2
1,1,2,0,0,0,0,5,0,5,0,0,0,0,2,1,1
1,1,2,0,0,0,0,0,0,0,0,0,0,0,2,1,1
1,1,1,2,0,0,0,0,0,0,0,0,0,2,1,1,1
1,1,1,1,2,2,13,0,0,0,12,2,2,1,1,1,1
1,1,1,1,1,1,2,2,2,2,2,1,1,1,1,1,1
1,1,1,1,1,1,2,1,1,1,2,1,1,1,1,1,1
endlayer

layer
1,1,1,1,1,1,2,1,1,1,2,1,1,1,1,1,1
1,1,1,1,1,1,2,2,2,2,2,1,1,1,1,1,1
1,1,1,1,2,2,2,3,3,3,2,2,2,1,1,1,1
1,1,1,2,2,3,3,3,3,3,3,3,2,2,1,1,1
1,1,2,2,3,3,3,3,3,3,3,3,3,2,2,1,1
1,1,2,3,3,3,3,2,3,2,3,3,3,3,2,1,1
2,2,2,3,3,3,3,2,2,2,3,3,3,3,0,2,2
1,2,3,3,3,2,2,2,2,2,2,2,3,3,0,2,1
1,2,3,3,3,3,2,2,2,2,2,3,3,3,0,2,1
1,2,3,3,3,2,2,2,2,2,2,2,3,3,0,2,1
2,2,2,2,3,3,3,2,2,2,3,3,3,3,8,2,2
1,1,2,3,3,3,3,2,3,2,2,3,3,3,2,1,1
1,1,2,2,3,3,3,3,3,3,3,3,3,2,2,1,1
1,1,1,2,2,3,3,3,3,3,3,3,2,2,1,1,1
1,1,1,1,2,2,2,3,3,3,2,2,2,1,1,1,1
1,1,1,1,1,1,2,2,2,2,2,1,1,1,1,1,1
1,1,1,1,1,1,2,1,1,1,2,1,1,1,1,1,1
endlayer

layer
1,1,1,1,1,1,2,1,1,1,2,1,1,1,1,1,1
1,1,1,1,1,1,2,2,2,2,2,1,1,1,1,1,1
1,1,1,1,2,2,0,0,0,0,0,2,2,1,1,1,1
1,1,1,2,0,0,0,0,0,0,0,0,0,2,1,1,1
1,1,2,0,0,0,0,0,0,0,0,0,0,0,2,1,1
1,1,2,0,0,0,0,0,0,0,0,0,0,0,2,1,1
2,2,0,0,0,0,0,2,2,2,0,0,0,0,0,2,2
1,2,0,0,0,0,2,2,2,2,2,0,0,0,0,2,1
1,2,0,0,0,0,2,2,2,2,2,0,0,0,0,2,1
1,2,11,0,0,0,2,2,2,2,2,0,0,0,0,2,1
2,2,9,0,0,0,0,2,2,2,0,0,0,0,0,2,2
1,1,2,0,0,0,0,0,0,0,0,0,0,0,2,1,1
1,1,2,0,0,0,0,0,0,0,0,0,0,0,2,1,1
1,1,1,2,0,0,0,0,0,0,0,0,0,2,1,1,1
1,1,1,1,2,2,0,0,0,0,0,2,2,1,1,1,1
1,1,1,1,1,1,2,2,2,2,2,1,1,1,1,1,1
1,1,1,1,1,1,2,1,1,1,2,1,1,1,1,1,1
endlayer

layer
1,1,1,1,1,1,2,1,1,1,2,1,1,1,1,1,1
1,1,1,1,1,1,2,6,6,6,2,1,1,1,1,1,1
1,1,1,1,2,2,0,0,0,0,0,2,2,1,1,1,1
1,1,1,2,0,0,0,0,0,0,0,0,0,2,1,1,1
1,1,2,0,0,0,0,0,0,0,0,0,0,0,2,1,1
1,1,2,0,0,0,0,0,0,0,0,0,0,0,2,1,1
2,2,0,0,0,0,0,3,2,3,0,0,0,0,0,2,2
1,2,0,0,0,0,3,2,2,2,3,0,0,0,0,4,1
1,2,11,0,0,0,2,2,2,2,2,0,0,0,0,4,1
1,2,6,0,0,0,3,2,2,2,3,0,0,0,0,4,1
2,2,0,0,0,0,0,3,2,3,0,0,0,0,0,2,2
1,1,2,0,0,0,0,0,0,0,0,0,0,0,2,1,1
1,1,2,0,0,0,0,0,0,0,0,0,0,0,2,1,1
1,1,1,2,0,0,0,0,0,0,0,0,0,2,1,1,1
1,1,1,1,2,2,0,0,0,0,0,2,2,1,1,1,1
1,1,1,1,1,1,2,8,8,8,2,1,1,1,1,1,1
1,1,1,1,1,1,2,1,1,1,2,1,1,1,1,1,1
endlayer

layer
1,1,1,1,1,1,2,1,1,1,2,1,1,1,1,1,1
1,1,1,1,1,1,2,5,5,5,2,1,1,1,1,1,1
1,1,1,1,2,2,0,0,0,0,0,2,2,1,1,1,1
1,1,1,2,0,0,0,0,0,0,0,0,0,2,1,1,1
1,1,2,0,0,0,0,0,0,0,0,0,0,0,2,1,1
1,1,2,0,0,0,0,0,0,0,0,0,0,0,2,1,1
2,2,0,0,0,0,0,3,2,3,0,0,0,0,0,2,2
1,2,11,0,0,0,3,2,2,2,3,0,0,0,0,12,1
1,2,6,0,0,0,2,2,10,2,2,0,0,0,0,12,1
1,2,0,0,0,0,3,2,2,2,3,0,0,0,0,12,1
2,2,0,0,0,0,0,3,2,3,0,0,0,0,0,2,2
1,1,2,0,0,0,0,0,0,0,0,0,0,0,2,1,1
1,1,2,0,0,0,0,0,0,0,0,0,0,0,2,1,1
1,1,1,2,0,0,0,0,0,0,0,0,0,2,1,1,1
1,1,1,1,2,2,0,0,0,0,0,2,2,1,1,1,1
1,1,1,1,1,1,2,11,11,11,2,1,1,1,1,1,1
1,1,1,1,1,1,2,1,1,1,2,1,1,1,1,1,1
endlayer

layer
1,1,1,1,1,1,8,1,1,1,8,1,1,1,1,1,1
1,1,1,1,1,1,2,2,2,2,2,1,1,1,1,1,1
1,1,1,1,2,2,13,0,0,0,12,2,2,1,1,1,1
1,1,1,2,0,0,0,0,0,0,0,0,0,2,1,1,1
1,1,2,0,0,0,0,0,0,0,0,0,0,0,2,1,1
1,1,2,0,0,0,0,11,0,11,0,0,0,0,2,1,1
4,2,11,0,0,0,0,2,2,2,0,0,0,0,5,2,9
1,2,6,0,0,12,2,2,2,2,2,13,0,0,0,2,1
1,2,0,0,0,0,2,2,2,2,2,0,0,0,0,2,1
1,2,0,0,0,12,2,2,2,2,2,13,0,0,0,2,1
4,2,0,0,0,0,0,2,2,2,0,0,0,0,11,2,9
1,1,2,0,0,0,0,5,0,5,0,0,0,0,2,1,1
1,1,2,0,0,0,0,0,0,0,0,0,0,0,2,1,1
1,1,1,2,0,0,0,0,0,0,0,0,0,2,1,1,1
1,1,1,1,2,2,13,0,0,0,12,2,2,1,1,1,1
1,1,1,1,1,1,2,2,2,2,2,1,1,1,1,1,1
1,1,1,1,1,1,6,1,1,1,6,1,1,1,1,1,1
endlayer

layer
1,1,1,1,1,1,1,1,1,1,1,1,1,1,1,1,1
1,1,1,1,1,1,2,2,2,2,2,1,1,1,1,1,1
1,1,1,1,2,2,2,2,2,2,2,2,2,1,1,1,1
1,1,1,2,2,2,2,2,2,2,2,2,2,2,1,1,1
1,1,2,2,2,2,2,2,2,2,2,2,2,2,2,1,1
1,1,2,2,2,2,2,2,2,2,2,2,2,2,2,1,1
1,2,6,2,2,2,2,14,14,14,2,2,2,2,2,2,1
1,2,0,2,2,2,14,14,14,14,14,2,2,2,2,2,1
1,2,0,2,2,2,14,14,2,14,14,2,2,2,2,2,1
1,2,0,2,2,2,14,14,14,14,14,2,2,2,2,2,1
1,2,11,2,2,2,2,14,14,14,2,2,2,2,2,2,1
1,1,2,2,2,2,2,2,2,2,2,2,2,2,2,1,1
1,1,2,2,2,2,2,2,2,2,2,2,2,2,2,1,1
1,1,1,2,2,2,2,2,2,2,2,2,2,2,1,1,1
1,1,1,1,2,2,2,2,2,2,2,2,2,1,1,1,1
1,1,1,1,1,1,2,2,2,2,2,1,1,1,1,1,1
1,1,1,1,1,1,1,1,1,1,1,1,1,1,1,1,1
endlayer

layer
1,1,1,1,1,1,1,1,1,1,1,1,1,1,1,1,1
1,1,1,1,1,1,2,15,15,15,2,1,1,1,1,1,1
1,1,1,1,15,15,15,0,0,0,15,15,15,1,1,1,1
1,1,1,2,15,0,0,0,0,0,0,0,15,2,1,1,1
1,1,15,15,0,0,0,0,0,0,0,0,0,15,15,1,1
1,1,15,0,0,0,0,15,15,15,0,0,0,0,15,1,1
1,2,0,0,0,0,15,0,0,0,15,0,0,0,15,2,1
1,15,0,0,0,15,0,0,16,0,0,15,0,0,0,15,1
1,15,0,0,0,15,0,16,2,16,0,15,0,0,0,15,1
1,15,0,0,0,15,0,0,16,0,0,15,0,0,0,15,1
1,2,15,0,0,0,15,0,0,0,15,0,0,0,15,2,1
1,1,15,0,0,0,0,15,15,15,0,0,0,0,15,1,1
1,1,15,15,0,0,0,0,0,0,0,0,0,15,15,1,1
1,1,1,2,15,0,0,0,0,0,0,0,15,2,1,1,1
1,1,1,1,15,15,15,0,0,0,15,15,15,1,1,1,1
1,1,1,1,1,1,2,15,15,15,2,1,1,1,1,1,1
1,1,1,1,1,1,1,1,1,1,1,1,1,1,1,1,1
endlayer

layer
1,1,1,1,1,1,1,1,1,1,1,1,1,1,1,1,1
1,1,1,1,1,1,2,0,0,0,2,1,1,1,1,1,1
1,1,1,1,0,0,0,0,0,0,0,0,0,1,1,1,1
1,1,1,2,0,0,0,0,0,0,0,0,0,2,1,1,1
1,1,0,0,0,0,0,0,0,0,0,0,0,0,0,1,1
1,1,0,0,0,0,0,0,0,0,0,0,0,0,0,1,1
1,2,0,0,0,0,0,0,0,0,0,0,0,0,0,2,1
1,0,0,0,0,0,0,0,16,0,0,0,0,0,0,0,1
1,0,0,0,0,0,0,16,2,16,0,0,0,0,0,0,1
1,0,0,0,0,0,0,0,16,0,0,0,0,0,0,0,1
1,2,0,0,0,0,0,0,0,0,0,0,0,0,0,2,1
1,1,0,0,0,0,0,0,0,0,0,0,0,0,0,1,1
1,1,0,0,0,0,0,0,0,0,0,0,0,0,0,1,1
1,1,1,2,0,0,0,0,0,0,0,0,0,2,1,1,1
1,1,1,1,0,0,0,0,0,0,0,0,0,1,1,1,1
1,1,1,1,1,1,2,0,0,0,2,1,1,1,1,1,1
1,1,1,1,1,1,1,1,1,1,1,1,1,1,1,1,1
endlayer

layer
1,1,1,1,1,1,1,1,1,1,1,1,1,1,1,1,1
1,1,1,1,1,1,2,0,0,0,2,1,1,1,1,1,1
1,1,1,1,0,0,0,0,0,0,0,0,0,1,1,1,1
1,1,1,2,0,0,0,0,0,0,0,0,0,2,1,1,1
1,1,0,0,0,0,0,0,0,0,0,0,0,0,0,1,1
1,1,0,0,0,0,0,0,0,0,0,0,0,0,0,1,1
1,2,0,0,0,0,0,0,0,0,0,0,0,0,0,2,1
1,0,0,0,0,0,0,0,17,0,0,0,0,0,0,0,1
1,0,0,0,0,0,0,17,14,17,0,0,0,0,0,0,1
1,0,0,0,0,0,0,0,17,0,0,0,0,0,0,0,1
1,2,0,0,0,0,0,0,0,0,0,0,0,0,0,2,1
1,1,0,0,0,0,0,0,0,0,0,0,0,0,0,1,1
1,1,0,0,0,0,0,0,0,0,0,0,0,0,0,1,1
1,1,1,2,0,0,0,0,0,0,0,0,0,2,1,1,1
1,1,1,1,0,0,0,0,0,0,0,0,0,1,1,1,1
1,1,1,1,1,1,2,0,0,0,2,1,1,1,1,1,1
1,1,1,1,1,1,1,1,1,1,1,1,1,1,1,1,1
endlayer

layer
1,1,1,1,1,1,1,1,1,1,1,1,1,1,1,1,1
1,1,1,1,1,1,2,0,0,0,2,1,1,1,1,1,1
1,1,1,1,0,0,0,0,0,0,0,0,0,1,1,1,1
1,1,1,2,0,0,0,0,0,0,0,0,0,2,1,1,1
1,1,0,0,0,0,0,0,0,0,0,0,0,0,0,1,1
1,1,0,0,0,0,0,0,0,0,0,0,0,0,0,1,1
1,2,0,0,0,0,0,0,0,0,0,0,0,0,0,2,1
1,0,0,0,0,0,0,0,0,0,0,0,0,0,0,0,1
1,0,0,0,0,0,0,0,0,0,0,0,0,0,0,0,1
1,0,0,0,0,0,0,0,0,0,0,0,0,0,0,0,1
1,2,0,0,0,0,0,0,0,0,0,0,0,0,0,2,1
1,1,0,0,0,0,0,0,0,0,0,0,0,0,0,1,1
1,1,0,0,0,0,0,0,0,0,0,0,0,0,0,1,1
1,1,1,2,0,0,0,0,0,0,0,0,0,2,1,1,1
1,1,1,1,0,0,0,0,0,0,0,0,0,1,1,1,1
1,1,1,1,1,1,2,0,0,0,2,1,1,1,1,1,1
1,1,1,1,1,1,1,1,1,1,1,1,1,1,1,1,1
endlayer

layer
1,1,1,1,1,1,3,3,3,3,3,1,1,1,1,1,1
1,1,1,1,3,3,2,3,3,3,2,3,3,1,1,1,1
1,1,1,3,3,3,3,3,3,3,3,3,3,3,1,1,1
1,1,3,2,3,3,3,0,0,0,3,3,3,2,3,1,1
1,3,3,3,3,0,0,0,0,0,0,0,3,3,3,3,1
1,3,3,3,0,0,0,0,0,0,0,0,0,3,3,3,1
3,2,3,3,0,0,0,0,0,0,0,0,0,3,3,2,3
3,3,3,0,0,0,0,0,0,0,0,0,0,0,3,3,3
3,3,3,0,0,0,0,0,0,0,0,0,0,0,3,3,3
3,3,3,0,0,0,0,0,0,0,0,0,0,0,3,3,3
3,2,3,3,0,0,0,0,0,0,0,0,0,3,3,2,3
1,3,3,3,0,0,0,0,0,0,0,0,0,3,3,3,1
1,3,3,3,3,0,0,0,0,0,0,0,3,3,3,3,1
1,1,3,2,3,3,3,0,0,0,3,3,3,2,3,1,1
1,1,1,3,3,3,3,3,3,3,3,3,3,3,1,1,1
1,1,1,1,3,3,2,3,3,3,2,3,3,1,1,1,1
1,1,1,1,1,1,3,3,3,3,3,1,1,1,1,1,1
endlayer

layer
1,1,1,1,1,1,1,1,1,1,1,1,1,1,1,1,1
1,1,1,1,1,1,2,3,3,3,2,1,1,1,1,1,1
1,1,1,1,3,3,3,0,0,0,3,3,3,1,1,1,1
1,1,1,2,3,0,0,0,0,0,0,0,3,2,1,1,1
1,1,3,3,0,0,0,0,0,0,0,0,0,3,3,1,1
1,1,3,0,0,0,0,0,0,0,0,0,0,0,3,1,1
1,2,3,0,0,0,0,0,0,0,0,0,0,0,3,2,1
1,3,0,0,0,0,0,0,0,0,0,0,0,0,0,3,1
1,3,0,0,0,0,0,0,0,0,0,0,0,0,0,3,1
1,3,0,0,0,0,0,0,0,0,0,0,0,0,0,3,1
1,2,3,0,0,0,0,0,0,0,0,0,0,0,3,2,1
1,1,3,0,0,0,0,0,0,0,0,0,0,0,3,1,1
1,1,3,3,0,0,0,0,0,0,0,0,0,3,3,1,1
1,1,1,2,3,0,0,0,0,0,0,0,3,2,1,1,1
1,1,1,1,3,3,3,0,0,0,3,3,3,1,1,1,1
1,1,1,1,1,1,2,3,3,3,2,1,1,1,1,1,1
1,1,1,1,1,1,1,1,1,1,1,1,1,1,1,1,1
endlayer

