
# Created by Ruins mod version 16.7 Ingame Parser
# authoring Player: lafuller

weight=1
embed_into_distance=4
acceptable_target_blocks=
unacceptable_target_blocks=flowing_water,water,flowing_lava,lava,ice,bedrock,netherrack,nether_brick,nether_brick_fence,soul_sand,quartz_ore,gravel,end_stone,obsidian,iron_bars,cloud,flesh,ash_block,slime_grass,slime_congealed,slime_dirt
dimensions=16,11,11
allowable_overhang=0
max_leveling=4
leveling_buffer=-1
preserve_water=0
preserve_lava=0

rule1=0,100,preserveBlock
rule2=0,100,minecraft:dirt-1
rule3=0,100,minecraft:dirt-0
rule4=0,100,minecraft:dirt-2
rule5=0,100,minecraft:spruce_fence-0
rule6=0,100,minecraft:spruce_stairs-0
rule7=0,100,minecraft:log2-1
rule8=0,100,minecraft:spruce_stairs-2
rule9=0,100,minecraft:spruce_stairs-3
rule10=0,100,minecraft:spruce_fence_gate-5
rule11=0,100,minecraft:ladder-5
rule12=0,100,minecraft:spruce_stairs-6
rule13=0,100,minecraft:spruce_stairs-4
rule14=0,100,minecraft:spruce_stairs-7
rule15=0,100,minecraft:spruce_stairs-5
rule16=0,100,minecraft:spruce_fence_gate-1
rule17=0,100,minecraft:planks-1
rule18=0,100,minecraft:trapdoor-9
rule19=0,100,minecraft:trapdoor-11
rule20=0,100,minecraft:wooden_slab-1
rule21=0,100,minecraft:wooden_slab-9
rule22=0,100,minecraft:log2-5
rule23=0,100,minecraft:log2-9
rule24=0,100,minecraft:double_wooden_slab-1
rule25=0,100,minecraft:spruce_stairs-1

layer
1,1,1,1,1,1,1,1,1,1,1
1,1,1,1,2,2,2,1,1,1,1
1,1,1,2,3,3,3,2,2,1,1
1,1,2,2,3,3,3,3,2,1,1
1,2,2,3,3,3,3,3,3,2,1
1,2,3,3,3,3,3,3,3,2,1
1,2,3,3,3,3,3,3,3,2,1
1,2,3,3,3,3,3,3,3,2,1
1,1,2,3,3,3,3,3,2,1,1
1,1,2,3,3,3,3,2,2,1,1
1,1,1,1,2,2,2,1,1,1,1
endlayer

layer
1,1,1,1,1,1,1,1,1,1,1
1,1,1,1,1,2,2,1,1,1,1
1,1,1,1,3,3,3,2,1,1,1
1,1,1,3,3,3,3,3,2,1,1
1,1,3,3,3,3,3,3,3,1,1
1,2,3,3,3,3,3,3,3,2,1
1,2,3,3,3,3,3,3,3,2,1
1,1,2,3,3,3,3,3,2,1,1
1,1,2,2,3,3,3,3,1,1,1
1,1,1,2,3,3,3,2,1,1,1
1,1,1,1,1,2,1,1,1,1,1
endlayer

layer
1,1,1,1,1,1,1,1,1,1,1
1,1,1,1,1,2,1,1,1,1,1
1,1,1,1,3,3,3,1,1,1,1
1,1,1,2,3,3,3,2,1,1,1
1,1,2,3,3,3,3,3,2,1,1
1,1,3,3,3,3,3,3,3,1,1
1,1,3,3,3,3,3,3,2,1,1
1,1,1,2,3,3,3,2,1,1,1
1,1,1,2,3,3,3,2,1,1,1
1,1,1,1,2,3,2,1,1,1,1
1,1,1,1,1,1,1,1,1,1,1
endlayer

layer
1,1,1,1,1,1,1,1,1,1,1
1,1,1,1,1,1,1,1,1,1,1
1,1,1,1,3,3,2,1,1,1,1
1,1,1,2,3,3,3,2,1,1,1
1,1,1,3,3,3,3,3,1,1,1
1,1,2,3,3,3,3,3,3,1,1
1,1,1,3,3,3,3,3,1,1,1
1,1,1,2,3,3,3,2,1,1,1
1,1,1,1,2,2,2,1,1,1,1
1,1,1,1,1,2,1,1,1,1,1
1,1,1,1,1,1,1,1,1,1,1
endlayer

layer
1,1,1,1,1,1,1,1,1,1,1
1,1,1,1,1,1,1,1,1,1,1
1,1,1,1,2,3,2,1,1,1,1
1,1,1,1,2,4,2,1,1,1,1
1,1,1,3,4,2,2,3,1,1,1
1,1,1,2,2,2,4,2,1,1,1
1,1,1,3,4,2,4,3,1,1,1
1,1,1,1,3,2,3,1,1,1,1
1,1,1,1,2,2,1,1,1,1,1
1,1,1,1,1,1,1,1,1,1,1
1,1,1,1,1,1,1,1,1,1,1
endlayer

layer
1,1,1,1,1,1,1,1,1,1,1
1,1,1,1,1,1,1,1,1,1,1
1,1,1,1,5,6,5,1,1,1,1
1,1,1,0,7,0,7,0,1,1,1
1,1,1,9,0,0,0,8,1,1,1
1,1,1,7,0,0,0,7,1,1,1
1,1,1,9,0,0,0,8,1,1,1
1,1,1,0,7,10,7,0,1,1,1
1,1,1,1,1,1,1,1,1,1,1
1,1,1,1,1,1,1,1,1,1,1
1,1,1,1,1,1,1,1,1,1,1
endlayer

layer
1,1,1,1,1,1,1,1,1,1,1
1,1,1,1,1,1,1,1,1,1,1
1,1,1,1,5,5,5,1,1,1,1
1,1,1,0,7,0,7,0,1,1,1
1,1,1,5,11,0,0,5,1,1,1
1,1,1,7,0,0,0,7,1,1,1
1,1,1,5,0,0,0,5,1,1,1
1,1,1,0,7,0,7,0,1,1,1
1,1,1,1,1,1,1,1,1,1,1
1,1,1,1,1,1,1,1,1,1,1
1,1,1,1,1,1,1,1,1,1,1
endlayer

layer
1,1,1,1,1,1,1,1,1,1,1
1,1,1,1,1,1,1,1,1,1,1
1,1,1,1,14,13,12,1,1,1,1
1,1,1,5,7,0,7,5,1,1,1
1,1,1,15,11,0,0,15,1,1,1
1,1,5,7,0,0,0,7,5,1,1
1,1,1,13,0,0,0,13,1,1,1
1,1,1,5,7,16,7,5,1,1,1
1,1,1,1,5,1,5,1,1,1,1
1,1,1,1,1,1,1,1,1,1,1
1,1,1,1,1,1,1,1,1,1,1
endlayer

layer
1,1,1,1,1,1,1,1,1,1,1
1,1,1,1,14,13,12,1,1,1,1
1,1,1,1,17,17,17,1,1,1,1
1,1,5,14,7,15,7,12,5,1,1
1,1,14,7,11,19,18,7,12,1,1
1,1,7,12,0,0,18,17,7,1,1
1,1,14,17,0,0,18,7,12,1,1
1,1,5,14,7,20,7,12,5,1,1
1,1,1,1,15,21,15,1,1,1,1
1,1,1,1,1,1,1,1,1,1,1
1,1,1,1,1,1,1,1,1,1,1
endlayer

layer
1,1,1,1,1,1,1,1,1,1,1
1,1,1,20,1,6,1,20,1,1,1
1,1,21,14,8,22,9,12,21,1,1
1,1,21,17,17,17,17,17,5,1,1
1,14,7,17,0,0,0,17,7,12,1
1,9,17,8,0,0,0,9,17,8,1
1,14,7,17,0,0,0,17,7,12,1
1,1,5,23,12,0,14,23,5,1,1
1,1,1,21,7,21,7,21,1,1,1
1,1,1,1,5,1,5,1,1,1,1
1,1,1,1,1,1,1,1,1,1,1
endlayer

layer
1,1,1,1,1,1,1,1,1,1,1
1,1,1,1,1,1,1,1,1,1,1
1,1,1,7,6,7,6,7,1,1,1
1,1,20,23,23,17,23,23,20,1,1
1,1,7,17,0,0,0,24,7,1,1
1,1,21,0,0,0,0,0,21,1,1
1,23,7,17,0,0,0,24,7,23,1
1,1,20,7,8,16,9,7,20,1,1
1,1,1,21,7,1,7,21,1,1,1
1,1,1,1,22,5,22,1,1,1,1
1,1,1,1,5,1,5,1,1,1,1
endlayer

layer
1,1,1,1,1,1,1,1,1,1,1
1,1,1,1,1,22,5,1,1,1,1
1,1,1,7,5,7,1,7,1,1,1
1,1,5,5,22,5,22,5,5,1,1
1,23,7,9,15,0,15,8,7,23,1
1,1,5,20,0,0,0,20,1,1,1
1,5,7,9,20,0,20,25,7,1,1
1,5,23,7,0,20,0,7,23,5,1
1,1,1,21,7,23,7,21,1,1,1
1,1,1,5,5,1,5,5,1,1,1
1,1,1,1,1,1,1,1,1,1,1
endlayer

layer
1,1,1,1,1,5,1,1,1,1,1
1,1,1,1,1,7,5,1,1,1,1
1,1,1,5,5,1,1,5,1,1,1
1,1,22,5,7,5,7,5,22,1,1
1,1,7,5,5,15,5,5,7,5,1
1,1,22,5,12,1,14,5,1,1,1
1,23,7,5,5,13,5,5,7,23,1
1,5,1,7,5,5,5,7,1,5,1
1,1,1,5,7,1,7,1,1,1,1
1,1,1,1,5,1,5,1,1,1,1
1,1,1,1,1,1,1,1,1,1,1
endlayer

layer
1,1,1,1,1,5,1,1,1,1,1
1,1,1,1,5,7,5,1,1,1,1
1,1,1,1,1,1,1,1,1,1,1
1,1,5,1,7,1,7,1,5,1,1
1,5,7,5,5,5,5,5,7,1,1
1,1,1,1,5,5,5,1,1,1,1
5,7,1,1,5,7,5,5,1,7,5
1,5,1,1,1,5,1,1,1,5,1
1,1,1,5,7,20,7,5,1,1,1
1,1,1,1,1,1,1,1,1,1,1
1,1,1,1,1,1,1,1,1,1,1
endlayer

layer
1,1,1,1,1,5,1,1,1,1,1
1,1,1,1,1,7,1,1,1,1,1
1,1,1,1,1,5,1,1,1,1,1
1,1,1,1,7,1,7,1,5,1,1
1,5,7,5,1,1,5,1,7,5,1
1,1,1,1,1,5,1,1,1,1,1
5,7,1,1,1,7,1,1,1,7,5
1,5,1,1,1,1,1,1,1,1,1
1,1,1,1,7,1,7,5,1,1,1
1,1,1,1,1,1,5,1,1,1,1
1,1,1,1,1,1,1,1,1,1,1
endlayer

layer
1,1,1,1,1,5,1,1,1,1,1
1,1,1,1,1,1,1,1,1,1,1
1,1,1,1,1,1,1,1,1,1,1
1,1,1,1,1,1,7,1,1,1,1
1,1,7,1,1,1,1,1,7,5,1
1,1,1,1,1,1,1,1,1,1,1
5,1,1,1,1,1,1,1,1,1,1
1,1,1,1,1,1,1,1,1,1,1
1,1,1,1,1,1,7,1,1,1,1
1,1,1,1,1,1,5,1,1,1,1
1,1,1,1,1,1,1,1,1,1,1
endlayer

