
# Created by Ruins mod version 16.7 Ingame Parser
# authoring Player: lafuller

weight=1
embed_into_distance=5
acceptable_target_blocks=
unacceptable_target_blocks=flowing_water,water,flowing_lava,lava
dimensions=40,9,7
allowable_overhang=0
max_leveling=5
leveling_buffer=-1
preserve_water=0
preserve_lava=0

rule1=0,100,preserveBlock
rule2=0,100,minecraft:planks-1
rule3=0,100,minecraft:log-1
rule4=0,100,minecraft:spruce_stairs-6
rule5=0,100,minecraft:wooden_slab-13
rule6=0,100,minecraft:spruce_stairs-4
rule7=0,100,minecraft:spruce_stairs-5
rule8=0,100,minecraft:spruce_stairs-7
rule9=0,100,minecraft:spruce_stairs-0
rule10=0,100,minecraft:spruce_stairs-3
rule11=0,100,minecraft:spruce_stairs-2
rule12=0,100,minecraft:spruce_stairs-1
rule13=0,100,minecraft:wooden_slab-5
rule14=0,100,minecraft:dark_oak_stairs-2
rule15=0,100,minecraft:dark_oak_stairs-3
rule16=0,100,minecraft:dark_oak_stairs-4
rule17=0,100,minecraft:dark_oak_stairs-5
rule18=0,100,minecraft:spruce_fence-0
rule19=0,100,minecraft:log2-1
rule20=0,100,minecraft:log2-9
rule21=0,100,minecraft:log2-5

layer
1,1,1,1,1,1,1
1,1,1,1,1,1,1
1,1,1,1,1,1,1
1,1,2,2,2,1,1
1,1,2,3,2,1,1
1,1,2,2,2,1,1
1,1,1,1,1,1,1
1,1,1,1,1,1,1
1,1,1,1,1,1,1
endlayer

layer
1,1,1,1,1,1,1
1,1,1,1,1,1,1
1,1,1,1,1,1,1
1,1,2,2,2,1,1
1,1,2,3,2,1,1
1,1,2,2,2,1,1
1,1,1,1,1,1,1
1,1,1,1,1,1,1
1,1,1,1,1,1,1
endlayer

layer
1,1,1,1,1,1,1
1,1,1,1,1,1,1
1,1,1,1,1,1,1
1,1,2,2,2,1,1
1,1,2,3,2,1,1
1,1,2,2,2,1,1
1,1,1,1,1,1,1
1,1,1,1,1,1,1
1,1,1,1,1,1,1
endlayer

layer
1,1,1,1,1,1,1
1,1,1,1,1,1,1
1,1,1,1,1,1,1
1,1,2,2,2,1,1
1,1,2,3,2,1,1
1,1,2,2,2,1,1
1,1,1,1,1,1,1
1,1,1,1,1,1,1
1,1,1,1,1,1,1
endlayer

layer
1,1,1,1,1,1,1
1,1,1,1,1,1,1
1,1,1,1,1,1,1
1,1,2,2,2,1,1
1,1,2,3,2,1,1
1,1,2,2,2,1,1
1,1,1,1,1,1,1
1,1,1,1,1,1,1
1,1,1,1,1,1,1
endlayer

layer
1,1,1,1,1,1,1
1,1,1,1,1,1,1
1,1,1,1,1,1,1
1,1,6,5,4,1,1
1,1,5,3,5,1,1
1,1,8,5,7,1,1
1,1,1,1,1,1,1
1,1,1,1,1,1,1
1,1,1,1,1,1,1
endlayer

layer
1,1,1,1,1,1,1
1,1,1,1,1,1,1
1,1,1,1,1,1,1
1,1,10,6,9,1,1
1,1,8,3,4,1,1
1,1,12,7,11,1,1
1,1,1,1,1,1,1
1,1,1,1,1,1,1
1,1,1,1,1,1,1
endlayer

layer
1,1,1,1,1,1,1
1,1,1,1,1,1,1
1,1,1,1,1,1,1
1,1,6,13,4,1,1
1,1,13,3,13,1,1
1,1,8,13,7,1,1
1,1,1,1,1,1,1
1,1,1,1,1,1,1
1,1,1,1,1,1,1
endlayer

layer
1,1,1,1,1,1,1
1,1,1,1,1,1,1
1,1,1,1,1,1,1
1,1,13,6,13,1,1
1,1,8,3,4,1,1
1,1,13,7,13,1,1
1,1,1,1,1,1,1
1,1,1,1,1,1,1
1,1,1,1,1,1,1
endlayer

layer
1,1,1,1,1,1,1
1,1,1,1,1,1,1
1,1,1,1,1,1,1
1,1,10,9,11,1,1
1,1,13,3,13,1,1
1,1,10,12,11,1,1
1,1,1,1,1,1,1
1,1,1,1,1,1,1
1,1,1,1,1,1,1
endlayer

layer
1,1,1,1,1,1,1
1,1,1,1,1,1,1
1,1,1,1,1,1,1
1,1,10,5,9,1,1
1,1,8,3,4,1,1
1,1,12,5,13,1,1
1,1,1,1,1,1,1
1,1,1,1,1,1,1
1,1,1,1,1,1,1
endlayer

layer
1,1,1,1,1,1,1
1,1,1,1,1,1,1
1,1,1,1,1,1,1
1,1,9,9,9,1,1
1,1,10,3,11,1,1
1,1,10,12,12,1,1
1,1,1,1,1,1,1
1,1,1,1,1,1,1
1,1,1,1,1,1,1
endlayer

layer
1,1,1,1,1,1,1
1,1,1,1,1,1,1
1,1,1,1,1,1,1
1,1,8,13,13,1,1
1,1,5,3,5,1,1
1,1,13,13,4,1,1
1,1,1,1,1,1,1
1,1,1,1,1,1,1
1,1,1,1,1,1,1
endlayer

layer
1,1,1,1,1,1,1
1,1,1,1,1,1,1
1,1,1,1,1,1,1
1,1,5,6,11,1,1
1,1,13,3,13,1,1
1,1,10,7,5,1,1
1,1,1,1,1,1,1
1,1,1,1,1,1,1
1,1,1,1,1,1,1
endlayer

layer
1,1,1,1,1,1,1
1,1,1,1,1,1,1
1,1,1,1,1,1,1
1,1,13,5,6,1,1
1,1,13,3,13,1,1
1,1,7,5,13,1,1
1,1,1,1,1,1,1
1,1,1,1,1,1,1
1,1,1,1,1,1,1
endlayer

layer
1,1,1,1,1,1,1
1,1,1,1,1,1,1
1,1,1,1,1,1,1
1,1,9,13,5,1,1
1,1,8,3,4,1,1
1,1,5,13,13,1,1
1,1,1,1,1,1,1
1,1,1,1,1,1,1
1,1,1,1,1,1,1
endlayer

layer
1,1,1,1,1,1,1
1,1,1,1,1,1,1
1,1,1,1,1,1,1
1,1,8,13,13,1,1
1,1,5,3,5,1,1
1,1,13,13,4,1,1
1,1,1,1,1,1,1
1,1,1,1,1,1,1
1,1,1,1,1,1,1
endlayer

layer
1,1,1,1,1,1,1
1,1,1,1,1,1,1
1,1,1,1,1,1,1
1,1,5,6,11,1,1
1,1,13,3,13,1,1
1,1,10,7,5,1,1
1,1,1,1,1,1,1
1,1,1,1,1,1,1
1,1,1,1,1,1,1
endlayer

layer
1,1,1,1,1,1,1
1,1,1,1,1,1,1
1,1,1,1,1,1,1
1,1,13,5,6,1,1
1,1,13,3,13,1,1
1,1,7,5,13,1,1
1,1,1,1,1,1,1
1,1,1,1,1,1,1
1,1,1,1,1,1,1
endlayer

layer
1,1,1,1,1,1,1
1,1,1,1,1,1,1
1,1,1,1,1,1,1
1,1,9,13,5,1,1
1,1,8,3,4,1,1
1,1,5,13,12,1,1
1,1,1,1,1,1,1
1,1,1,1,1,1,1
1,1,1,1,1,1,1
endlayer

layer
1,1,1,1,1,1,1
1,1,1,1,1,1,1
1,1,1,1,1,1,1
1,1,8,13,13,1,1
1,1,5,3,5,1,1
1,1,13,13,4,1,1
1,1,1,1,1,1,1
1,1,1,1,1,1,1
1,1,1,1,1,1,1
endlayer

layer
1,1,1,1,1,1,1
1,1,1,1,1,1,1
1,1,1,1,1,1,1
1,1,5,6,11,1,1
1,1,13,3,13,1,1
1,1,10,7,5,1,1
1,1,1,1,1,1,1
1,1,1,1,1,1,1
1,1,1,1,1,1,1
endlayer

layer
1,1,1,1,1,1,1
1,1,1,1,1,1,1
1,1,1,1,1,1,1
1,1,14,5,6,1,1
1,1,13,3,13,1,1
1,1,7,5,15,1,1
1,1,1,1,1,1,1
1,1,1,1,1,1,1
1,1,1,1,1,1,1
endlayer

layer
1,1,1,1,1,1,1
1,1,1,1,1,1,1
1,1,1,1,1,1,1
1,1,16,13,16,1,1
1,1,8,3,4,1,1
1,1,17,13,17,1,1
1,1,1,1,1,1,1
1,1,1,1,1,1,1
1,1,1,1,1,1,1
endlayer

layer
1,1,1,1,1,1,1
1,1,1,1,1,1,1
1,1,1,1,18,1,1
1,18,19,13,19,1,1
1,1,5,3,5,1,1
1,1,19,13,19,18,1
1,1,18,1,1,1,1
1,1,1,1,1,1,1
1,1,1,1,1,1,1
endlayer

layer
1,1,1,1,1,1,1
1,1,1,1,1,1,1
1,18,18,1,18,18,1
1,18,19,6,19,18,1
18,20,13,3,13,20,18
1,18,19,7,19,18,1
1,18,18,1,18,18,1
1,1,1,1,1,1,1
1,1,1,1,1,1,1
endlayer

layer
1,1,1,1,1,1,1
1,1,1,18,1,1,1
1,1,18,21,1,1,1
1,1,19,13,19,18,1
1,1,13,3,13,1,1
1,18,19,13,19,1,1
1,1,1,21,18,1,1
1,1,1,18,1,1,1
1,1,1,1,1,1,1
endlayer

layer
1,1,1,1,1,1,1
1,1,1,1,1,1,1
1,1,18,1,1,1,1
1,20,20,9,20,20,1
1,1,10,3,11,1,1
1,20,20,12,20,20,1
1,1,1,1,18,1,1
1,1,1,1,1,1,1
1,1,1,1,1,1,1
endlayer

layer
1,1,1,1,1,1,1
1,1,1,1,1,1,1
1,1,21,1,21,1,1
1,1,21,9,21,1,1
1,1,10,3,11,1,1
1,1,21,12,21,1,1
1,1,21,1,21,1,1
1,1,1,1,1,1,1
1,1,1,1,1,1,1
endlayer

layer
1,1,1,1,1,1,1
1,1,1,1,1,1,1
1,1,1,1,1,1,1
1,1,5,13,5,1,1
20,20,20,3,20,20,20
1,1,5,13,5,1,1
1,1,1,1,1,1,1
1,1,1,1,1,1,1
1,1,1,1,1,1,1
endlayer

layer
1,1,1,1,1,1,1
1,1,1,21,1,1,1
1,1,1,21,1,1,1
1,1,13,21,13,1,1
1,1,8,3,4,1,1
1,1,13,21,13,1,1
1,1,1,21,1,1,1
1,1,1,21,1,1,1
1,1,1,1,1,1,1
endlayer

layer
1,1,1,1,1,1,1
1,1,1,1,1,1,1
1,18,21,21,21,1,1
20,20,20,9,20,20,20
1,1,13,3,13,1,1
20,20,20,12,20,20,20
1,1,21,21,21,1,1
1,1,1,1,1,1,1
1,1,1,1,1,1,1
endlayer

layer
1,1,1,1,1,1,1
1,1,1,21,1,1,1
1,1,1,21,1,1,1
18,19,10,13,21,1,1
1,20,10,3,11,20,1
1,1,21,13,12,19,1
1,1,1,21,1,18,1
1,1,1,21,1,1,1
1,1,1,1,1,1,1
endlayer

layer
1,1,1,1,1,1,1
1,1,18,19,1,1,1
1,21,1,1,1,21,1
18,19,5,6,19,21,1
20,20,13,3,13,20,20
1,21,19,7,5,19,1
1,21,1,1,1,21,1
1,1,1,19,1,1,1
1,1,1,1,1,1,1
endlayer

layer
1,1,1,18,1,1,1
1,1,18,21,1,1,1
1,18,1,21,18,1,1
1,20,13,5,19,18,1
1,1,13,3,11,1,1
1,18,19,5,13,20,18
1,1,1,21,1,1,1
1,1,18,21,1,1,1
1,1,1,1,1,1,1
endlayer

layer
1,1,1,18,1,1,1
1,1,18,19,18,1,1
1,18,1,1,1,1,1
1,19,1,13,19,18,1
1,1,8,3,4,1,1
1,18,19,13,12,19,18
1,1,1,1,1,1,1
1,1,18,19,18,1,1
1,1,1,18,1,1,1
endlayer

layer
1,1,1,18,1,1,1
1,1,18,19,18,1,1
1,18,1,1,1,1,1
18,19,1,1,19,18,1
1,1,1,1,1,1,1
1,18,19,1,1,19,1
1,1,1,1,1,18,1
1,1,18,19,18,1,1
1,1,1,18,1,1,1
endlayer

layer
1,1,1,1,1,1,1
1,1,1,19,18,1,1
1,1,1,1,1,1,1
18,19,1,1,19,1,1
1,1,1,1,1,18,1
1,1,19,1,1,19,1
1,1,1,1,1,18,1
1,1,18,19,18,1,1
1,1,1,18,1,1,1
endlayer

layer
1,1,1,1,1,1,1
1,1,1,19,1,1,1
1,1,1,18,1,1,1
18,19,1,1,18,1,1
1,1,1,1,1,18,1
1,1,18,1,1,19,1
1,1,1,18,1,1,1
1,1,1,19,18,1,1
1,1,1,1,1,1,1
endlayer

layer
1,1,1,1,1,1,1
1,1,1,1,1,1,1
1,1,1,18,1,1,1
1,19,18,1,18,1,1
1,1,1,1,1,1,1
1,1,1,1,18,19,1
1,1,1,18,1,1,1
1,1,1,1,1,1,1
1,1,1,1,1,1,1
endlayer

