# Gilly's Kimberlite Pipe

# template generated by Ruins mod version 14.6 Ingame Parser
# Structure created by Gilly

weight=1
embed_into_distance=60
acceptable_target_blocks=
unacceptable_target_blocks=flowing_water,water,flowing_lava,lava
dimensions=62,7,7
allowable_overhang=0
max_leveling=3
leveling_buffer=-1
preserve_water=0
preserve_lava=0

rule1=0,100,preserveBlock
rule2=0,100,obsidian-0,coal_ore-0,stained_hardened_clay-7
rule3=0,100,obsidian-0
rule4=0,100,diamond_ore-0,obsidian-0,coal_ore-0,stained_hardened_clay-7
rule5=0,100,obsidian-0
rule6=0,100,stained_hardened_clay-7
rule7=0,100,stained_glass-12
rule8=0,100,sandstone-2
rule9=0,100,sand
rule10=0,100,clay-0
rule11=0,100,gravel

layer
1,1,1,1,1,1,1
1,1,1,1,2,1,1
1,1,1,1,3,1,1
1,1,1,1,1,1,1
1,1,1,1,1,1,1
1,1,1,1,1,1,1
1,1,1,1,1,1,1
endlayer

layer
1,1,1,1,1,1,1
1,1,1,1,1,1,1
1,1,1,4,3,3,2
1,1,1,1,4,1,1
1,1,1,1,1,1,1
1,1,1,1,1,1,1
1,1,1,1,1,1,1
endlayer

layer
1,1,1,1,1,1,1
1,1,1,1,4,1,1
1,1,2,3,3,4,1
1,1,1,4,3,1,1
1,1,1,1,2,1,1
1,1,1,1,1,1,1
1,1,1,1,1,1,1
endlayer

layer
1,1,1,1,1,1,1
1,1,1,1,2,1,1
1,1,1,4,3,2,1
1,1,1,1,4,1,1
1,1,1,1,1,1,1
1,1,1,1,1,1,1
1,1,1,1,1,1,1
endlayer

layer
1,1,1,1,1,1,1
1,1,1,1,4,1,1
1,1,2,3,3,4,1
1,1,1,4,3,1,1
1,1,1,1,2,1,1
1,1,1,1,1,1,1
1,1,1,1,1,1,1
endlayer

layer
1,1,1,1,1,1,1
1,1,1,1,4,1,1
1,1,1,4,3,3,2
1,1,1,4,4,1,1
1,1,1,1,1,1,1
1,1,1,1,1,1,1
1,1,1,1,1,1,1
endlayer

layer
1,1,1,1,2,1,1
1,1,1,1,3,1,1
1,1,1,4,3,4,1
1,1,2,3,3,2,1
1,1,1,2,1,1,1
1,1,1,1,1,1,1
1,1,1,1,1,1,1
endlayer

layer
1,1,1,1,1,1,1
1,1,1,1,4,1,1
1,1,1,4,3,1,1
1,1,4,3,3,4,1
1,1,1,2,3,1,1
1,1,1,1,2,1,1
1,1,1,1,1,1,1
endlayer

layer
1,1,1,1,2,1,1
1,1,1,1,3,1,1
1,1,2,4,3,1,1
1,1,3,3,3,2,1
1,1,1,4,4,1,1
1,1,1,1,1,1,1
1,1,1,1,1,1,1
endlayer

layer
1,1,1,1,1,1,1
1,1,1,1,1,1,1
1,1,1,3,4,1,1
1,2,3,3,3,1,1
1,1,1,3,1,1,1
1,1,1,2,1,1,1
1,1,1,1,1,1,1
endlayer

layer
1,1,1,1,1,1,1
1,1,1,1,1,1,1
1,1,1,4,4,1,1
1,1,4,3,4,1,1
1,1,1,4,1,1,1
1,1,1,1,1,1,1
1,1,1,1,1,1,1
endlayer

layer
1,1,1,1,1,1,1
1,1,1,1,2,1,1
1,1,1,4,3,1,1
1,1,3,3,3,2,1
1,1,1,3,1,1,1
1,1,1,2,1,1,1
1,1,1,1,1,1,1
endlayer

layer
1,1,1,1,1,1,1
1,1,1,2,1,1,1
1,1,1,3,4,1,1
1,2,3,3,4,1,1
1,1,1,1,1,1,1
1,1,1,1,1,1,1
1,1,1,1,1,1,1
endlayer

layer
1,1,1,1,1,1,1
1,1,1,4,4,1,1
1,1,3,3,4,1,1
1,1,1,4,4,1,1
1,1,1,1,1,1,1
1,1,1,1,1,1,1
1,1,1,1,1,1,1
endlayer

layer
1,1,1,1,2,1,1
1,1,1,4,3,1,1
1,1,4,3,3,2,1
1,1,1,4,4,1,1
1,1,1,1,1,1,1
1,1,1,1,1,1,1
1,1,1,1,1,1,1
endlayer

layer
1,1,1,1,1,1,1
1,1,1,4,2,1,1
1,2,3,3,3,4,1
1,1,1,1,3,1,1
1,1,1,1,1,1,1
1,1,1,1,1,1,1
1,1,1,1,1,1,1
endlayer

layer
1,1,1,1,1,1,1
1,1,1,2,4,1,1
1,1,1,3,3,3,2
1,1,1,1,4,1,1
1,1,1,1,1,1,1
1,1,1,1,1,1,1
1,1,1,1,1,1,1
endlayer

layer
1,1,1,1,1,1,1
1,1,1,1,4,1,1
1,1,1,3,3,4,1
1,1,1,1,4,1,1
1,1,1,1,2,1,1
1,1,1,1,1,1,1
1,1,1,1,1,1,1
endlayer

layer
1,1,1,1,2,1,1
1,1,1,1,3,1,1
1,1,1,4,3,4,1
1,1,1,4,3,3,2
1,1,1,1,1,1,1
1,1,1,1,1,1,1
1,1,1,1,1,1,1
endlayer

layer
1,1,1,1,1,1,1
1,1,1,1,2,1,1
1,1,1,4,4,1,1
1,1,1,4,3,1,1
1,1,1,1,4,1,1
1,1,1,1,1,1,1
1,1,1,1,1,1,1
endlayer

layer
1,1,1,1,1,1,1
1,1,1,1,1,1,1
1,1,2,3,3,1,1
1,1,1,4,3,4,1
1,1,1,1,3,1,1
1,1,1,1,2,1,1
1,1,1,1,1,1,1
endlayer

layer
1,1,1,1,1,1,1
1,1,1,1,1,1,1
1,1,1,4,4,1,1
1,1,1,4,3,3,2
1,1,1,1,4,1,1
1,1,1,1,1,1,1
1,1,1,1,1,1,1
endlayer

layer
1,1,1,1,1,1,1
1,1,1,1,2,1,1
1,1,1,4,3,1,1
1,2,3,3,3,4,1
1,1,1,4,4,1,1
1,1,1,1,1,1,1
1,1,1,1,1,1,1
endlayer

layer
1,1,1,1,1,1,1
1,1,1,1,1,1,1
1,1,2,3,4,1,1
1,1,4,3,3,2,1
1,1,1,3,1,1,1
1,1,1,2,1,1,1
1,1,1,1,1,1,1
endlayer

layer
1,1,1,1,1,1,1
1,1,1,1,2,1,1
1,1,3,4,3,1,1
1,1,4,3,3,1,1
1,1,1,4,1,1,1
1,1,1,1,1,1,1
1,1,1,1,1,1,1
endlayer

layer
1,1,1,1,1,1,1
1,1,1,2,1,1,1
1,1,4,3,4,1,1
1,1,3,3,4,1,1
1,1,1,2,1,1,1
1,1,1,1,1,1,1
1,1,1,1,1,1,1
endlayer

layer
1,1,1,1,1,1,1
1,1,1,4,1,1,1
1,2,3,3,3,2,1
1,1,4,3,1,1,1
1,1,1,1,1,1,1
1,1,1,1,1,1,1
1,1,1,1,1,1,1
endlayer

layer
1,1,1,1,1,1,1
1,1,1,2,1,1,1
1,1,1,3,4,1,1
1,1,1,4,1,1,1
1,1,1,1,1,1,1
1,1,1,1,1,1,1
1,1,1,1,1,1,1
endlayer

layer
1,1,1,1,1,1,1
1,1,1,4,1,1,1
1,1,2,3,4,1,1
1,1,1,3,2,1,1
1,1,1,2,1,1,1
1,1,1,1,1,1,1
1,1,1,1,1,1,1
endlayer

layer
1,1,1,2,1,1,1
1,1,1,3,1,1,1
1,2,2,3,4,1,1
1,1,1,4,1,1,1
1,1,1,1,1,1,1
1,1,1,1,1,1,1
1,1,1,1,1,1,1
endlayer

layer
1,1,1,1,1,1,1
1,1,1,4,1,1,1
1,1,4,3,3,1,1
1,1,1,5,1,1,1
1,1,1,1,1,1,1
1,1,1,1,1,1,1
1,1,1,1,1,1,1
endlayer

layer
1,1,1,1,1,1,1
1,1,1,3,1,1,1
1,1,2,3,4,1,1
1,1,1,5,1,1,1
1,1,1,1,1,1,1
1,1,1,1,1,1,1
1,1,1,1,1,1,1
endlayer

layer
1,1,1,1,1,1,1
1,1,1,6,1,1,1
1,1,1,3,5,1,1
1,1,6,4,1,1,1
1,1,1,1,1,1,1
1,1,1,1,1,1,1
1,1,1,1,1,1,1
endlayer

layer
1,1,1,1,1,1,1
1,1,1,5,1,1,1
1,1,1,3,6,1,1
1,1,5,3,5,1,1
1,1,1,6,1,1,1
1,1,1,1,1,1,1
1,1,1,1,1,1,1
endlayer

layer
1,1,1,1,1,1,1
1,1,1,6,1,1,1
1,1,6,3,1,1,1
1,1,7,5,7,1,1
1,1,1,1,1,1,1
1,1,1,1,1,1,1
1,1,1,1,1,1,1
endlayer

layer
1,1,1,1,1,1,1
1,1,1,1,1,1,1
1,1,5,6,1,1,1
1,1,5,5,6,1,1
1,1,6,5,1,1,1
1,1,1,1,1,1,1
1,1,1,1,1,1,1
endlayer

layer
1,1,1,1,1,1,1
1,1,6,1,1,1,1
1,1,7,6,1,1,1
1,5,5,7,1,1,1
1,1,6,1,1,1,1
1,1,1,1,1,1,1
1,1,1,1,1,1,1
endlayer

layer
1,1,1,1,1,1,1
1,1,1,1,1,1,1
1,1,5,7,1,1,1
1,6,5,5,6,1,1
1,1,5,1,1,1,1
1,1,1,1,1,1,1
1,1,1,1,1,1,1
endlayer

layer
1,1,1,1,1,1,1
1,1,6,1,1,1,1
1,7,5,5,1,1,1
1,1,5,7,1,1,1
1,1,7,1,1,1,1
1,1,1,1,1,1,1
1,1,1,1,1,1,1
endlayer

layer
1,1,1,1,1,1,1
1,1,5,6,1,1,1
1,5,5,7,6,1,1
1,1,7,6,1,1,1
1,1,1,1,1,1,1
1,1,1,1,1,1,1
1,1,1,1,1,1,1
endlayer

layer
1,1,1,1,1,1,1
1,1,7,6,1,1,1
1,7,5,5,6,1,1
1,1,5,7,1,1,1
1,1,1,1,1,1,1
1,1,1,1,1,1,1
1,1,1,1,1,1,1
endlayer

layer
1,1,1,6,1,1,1
1,1,7,5,1,1,1
1,1,5,5,6,6,1
1,1,7,7,6,1,1
1,1,1,1,1,1,1
1,1,1,1,1,1,1
1,1,1,1,1,1,1
endlayer

layer
1,1,1,1,1,1,1
1,1,6,7,6,1,1
1,1,7,5,7,1,1
1,1,6,5,6,1,1
1,1,1,1,1,1,1
1,1,1,1,1,1,1
1,1,1,1,1,1,1
endlayer

layer
1,1,1,6,1,1,1
1,1,8,7,6,1,1
1,1,5,5,5,6,1
1,1,7,7,6,1,1
1,1,1,8,1,1,1
1,1,1,1,1,1,1
1,1,1,1,1,1,1
endlayer

layer
1,1,1,1,1,1,1
1,1,1,8,1,1,1
1,1,7,5,7,1,1
1,1,5,5,7,6,1
1,1,8,7,6,1,1
1,1,1,1,1,1,1
1,1,1,1,1,1,1
endlayer

layer
1,1,1,1,1,1,1
1,1,1,8,1,1,1
1,1,8,7,8,1,1
1,8,7,5,5,8,1
1,1,6,5,6,1,1
1,1,1,1,1,1,1
1,1,1,1,1,1,1
endlayer

layer
1,1,1,1,1,1,1
1,1,8,9,8,1,1
1,6,5,9,8,1,1
1,7,5,5,7,6,1
1,1,6,8,8,8,1
1,1,8,1,1,1,1
1,1,1,1,1,1,1
endlayer

layer
1,1,1,8,1,1,1
1,1,8,9,1,1,1
1,8,7,9,9,1,1
1,5,5,7,9,8,1
1,1,8,8,6,1,1
1,1,1,1,8,1,1
1,1,1,1,1,1,1
endlayer

layer
1,1,1,1,1,1,1
1,8,8,9,8,1,1
1,6,7,7,9,8,1
1,8,5,9,9,8,1
1,8,6,9,8,1,1
1,1,1,1,1,1,1
1,1,1,1,1,1,1
endlayer

layer
1,1,1,8,1,1,1
1,1,9,9,8,1,1
1,8,7,7,9,1,1
8,8,7,9,9,8,1
1,1,9,9,8,8,1
1,1,1,8,1,1,1
1,1,1,1,1,1,1
endlayer

layer
1,1,1,1,1,1,1
1,8,9,9,9,1,1
1,8,7,7,9,8,1
1,9,9,9,9,8,8
1,8,9,9,9,1,1
1,1,8,8,1,1,1
1,1,1,1,1,1,1
endlayer

layer
1,1,1,8,1,1,1
1,1,9,9,9,8,1
1,9,9,10,9,9,1
8,9,9,10,9,9,1
1,8,9,9,9,1,1
1,1,1,9,8,1,1
1,1,1,1,1,1,1
endlayer

layer
1,1,1,8,8,1,1
1,1,9,10,9,8,1
1,9,10,10,10,9,8
8,9,9,10,9,9,1
1,9,9,9,9,8,1
1,1,8,9,8,1,1
1,1,1,1,1,1,1
endlayer

layer
1,1,1,9,8,1,1
1,8,9,10,9,9,1
1,9,10,10,10,9,8
9,9,10,10,10,9,8
1,9,9,10,9,8,1
1,1,8,9,9,1,1
1,1,1,8,1,1,1
endlayer

layer
1,1,8,9,8,1,1
1,9,10,10,10,9,8
8,10,10,10,10,10,9
9,9,10,10,10,9,8
8,9,9,10,10,9,1
1,1,9,9,9,8,1
1,1,1,8,8,1,1
endlayer

layer
1,1,8,10,9,8,1
1,9,10,10,10,9,9
9,10,10,10,10,10,9
9,10,10,11,10,10,9
1,9,10,10,10,9,8
1,8,9,10,9,8,1
1,1,8,9,8,1,1
endlayer

layer
1,1,9,10,10,8,1
8,10,10,10,10,10,9
10,10,10,11,10,10,10
10,10,11,11,11,10,10
8,10,10,11,10,10,10
1,10,10,10,10,10,8
1,1,9,10,10,8,1
endlayer

layer
1,10,10,11,11,10,1
10,11,11,11,11,11,10
11,11,11,11,11,11,11
11,11,11,0,11,11,11
10,11,11,11,11,11,11
10,11,11,11,11,11,10
1,10,10,11,11,10,1
endlayer

layer
1,11,11,11,11,11,1
11,11,11,1,11,11,11
11,1,0,0,0,1,11
11,11,0,0,0,11,11
11,11,0,0,0,11,11
11,11,1,11,11,11,11
1,11,11,11,11,11,1
endlayer

layer
1,1,11,1,1,11,1
11,1,0,0,0,1,11
1,0,0,0,0,0,1
1,0,0,0,0,0,1
11,0,0,0,0,0,11
1,1,0,0,0,1,1
1,11,1,1,11,1,1
endlayer

layer
1,1,0,0,0,1,1
1,0,0,0,0,0,1
0,0,0,0,0,0,0
0,0,0,0,0,0,0
0,0,0,0,0,0,0
1,0,0,0,0,0,1
1,1,0,0,0,1,1
endlayer

layer
1,0,0,0,0,0,1
0,0,0,0,0,0,0
0,0,0,0,0,0,0
0,0,0,0,0,0,0
0,0,0,0,0,0,0
0,0,0,0,0,0,0
1,0,0,0,0,0,1
endlayer

