
# Created by Ruins mod version 16.7 Ingame Parser
# authoring Player: lafuller

weight=1
embed_into_distance=5
acceptable_target_blocks=
unacceptable_target_blocks=flowing_water,water,flowing_lava,lava
dimensions=40,9,7
allowable_overhang=0
max_leveling=5
leveling_buffer=-1
preserve_water=0
preserve_lava=0

rule1=0,100,preserveBlock
rule2=0,100,minecraft:log2-1
rule3=0,100,minecraft:planks-1
rule4=0,100,minecraft:log-1
rule5=0,100,minecraft:wooden_slab-13
rule6=0,100,minecraft:spruce_stairs-4
rule7=0,100,minecraft:spruce_stairs-6
rule8=0,100,minecraft:spruce_stairs-7
rule9=0,100,minecraft:spruce_stairs-2
rule10=0,100,minecraft:spruce_stairs-1
rule11=0,100,minecraft:wooden_slab-5
rule12=0,100,minecraft:spruce_stairs-3
rule13=0,100,minecraft:spruce_stairs-0
rule14=0,100,minecraft:spruce_stairs-5
rule15=0,100,minecraft:dark_oak_stairs-2
rule16=0,100,minecraft:dark_oak_stairs-4
rule17=0,100,minecraft:dark_oak_stairs-5
rule18=0,100,minecraft:spruce_fence-0
rule19=0,100,minecraft:log2-9
rule20=0,100,minecraft:log2-5
rule21=0,100,minecraft:dark_oak_stairs-6
rule22=0,100,minecraft:dark_oak_stairs-7
rule23=0,100,minecraft:dark_oak_stairs-0
rule24=0,100,minecraft:dark_oak_stairs-1

layer
1,1,1,1,1,1,1
1,1,1,1,1,1,1
1,1,1,1,1,1,1
1,1,2,3,2,1,1
1,1,3,4,3,1,1
1,1,2,3,2,1,1
1,1,1,1,1,1,1
1,1,1,1,1,1,1
1,1,1,1,1,1,1
endlayer

layer
1,1,1,1,1,1,1
1,1,1,1,1,1,1
1,1,1,1,1,1,1
1,1,2,3,2,1,1
1,1,3,4,3,1,1
1,1,2,3,2,1,1
1,1,1,1,1,1,1
1,1,1,1,1,1,1
1,1,1,1,1,1,1
endlayer

layer
1,1,1,1,1,1,1
1,1,1,1,1,1,1
1,1,1,1,1,1,1
1,1,2,3,2,1,1
1,1,3,4,3,1,1
1,1,2,3,2,1,1
1,1,1,1,1,1,1
1,1,1,1,1,1,1
1,1,1,1,1,1,1
endlayer

layer
1,1,1,1,1,1,1
1,1,1,1,1,1,1
1,1,1,1,1,1,1
1,1,2,3,2,1,1
1,1,3,4,3,1,1
1,1,2,3,2,1,1
1,1,1,1,1,1,1
1,1,1,1,1,1,1
1,1,1,1,1,1,1
endlayer

layer
1,1,1,1,1,1,1
1,1,1,1,1,1,1
1,1,1,1,1,1,1
1,1,2,3,2,1,1
1,1,3,4,3,1,1
1,1,2,3,2,1,1
1,1,1,1,1,1,1
1,1,1,1,1,1,1
1,1,1,1,1,1,1
endlayer

layer
1,1,1,1,1,1,1
1,1,1,1,1,1,1
1,1,1,1,1,1,1
1,1,2,5,2,1,1
1,1,5,4,5,1,1
1,1,2,5,2,1,1
1,1,1,1,1,1,1
1,1,1,1,1,1,1
1,1,1,1,1,1,1
endlayer

layer
1,1,1,1,1,1,1
1,1,1,1,1,1,1
1,1,1,1,1,1,1
1,1,2,6,2,1,1
1,1,8,4,7,1,1
1,1,10,1,9,1,1
1,1,1,1,1,1,1
1,1,1,1,1,1,1
1,1,1,1,1,1,1
endlayer

layer
1,1,1,1,1,1,1
1,1,1,1,1,1,1
1,1,1,1,1,1,1
1,1,2,11,7,1,1
1,1,11,4,11,1,1
1,1,8,1,1,1,1
1,1,1,1,1,1,1
1,1,1,1,1,1,1
1,1,1,1,1,1,1
endlayer

layer
1,1,1,1,1,1,1
1,1,1,1,1,1,1
1,1,1,1,1,1,1
1,1,11,6,1,1,1
1,1,8,4,1,1,1
1,1,11,1,1,1,1
1,1,1,1,1,1,1
1,1,1,1,1,1,1
1,1,1,1,1,1,1
endlayer

layer
1,1,1,1,1,1,1
1,1,1,1,1,1,1
1,1,1,1,1,1,1
1,1,12,1,1,1,1
1,1,11,4,1,1,1
1,1,12,10,1,1,1
1,1,1,1,1,1,1
1,1,1,1,1,1,1
1,1,1,1,1,1,1
endlayer

layer
1,1,1,1,1,1,1
1,1,1,1,1,1,1
1,1,1,1,1,1,1
1,1,1,1,1,1,1
1,1,8,4,7,1,1
1,1,10,5,11,1,1
1,1,1,1,1,1,1
1,1,1,1,1,1,1
1,1,1,1,1,1,1
endlayer

layer
1,1,1,1,1,1,1
1,1,1,1,1,1,1
1,1,1,1,1,1,1
1,1,1,1,13,1,1
1,1,1,4,9,1,1
1,1,12,10,10,1,1
1,1,1,1,1,1,1
1,1,1,1,1,1,1
1,1,1,1,1,1,1
endlayer

layer
1,1,1,1,1,1,1
1,1,1,1,1,1,1
1,1,1,1,1,1,1
1,1,1,11,11,1,1
1,1,1,4,5,1,1
1,1,1,11,7,1,1
1,1,1,1,1,1,1
1,1,1,1,1,1,1
1,1,1,1,1,1,1
endlayer

layer
1,1,1,1,1,1,1
1,1,1,1,1,1,1
1,1,1,1,1,1,1
1,1,5,6,9,1,1
1,1,1,4,11,1,1
1,1,1,1,1,1,1
1,1,1,1,1,1,1
1,1,1,1,1,1,1
1,1,1,1,1,1,1
endlayer

layer
1,1,1,1,1,1,1
1,1,1,1,1,1,1
1,1,1,1,1,1,1
1,1,11,5,1,1,1
1,1,11,4,1,1,1
1,1,1,1,1,1,1
1,1,1,1,1,1,1
1,1,1,1,1,1,1
1,1,1,1,1,1,1
endlayer

layer
1,1,1,1,1,1,1
1,1,1,1,1,1,1
1,1,1,1,1,1,1
1,1,13,1,1,1,1
1,1,8,4,1,1,1
1,1,5,11,1,1,1
1,1,1,1,1,1,1
1,1,1,1,1,1,1
1,1,1,1,1,1,1
endlayer

layer
1,1,1,1,1,1,1
1,1,1,1,1,1,1
1,1,1,1,1,1,1
1,1,1,1,1,1,1
1,1,5,4,5,1,1
1,1,11,11,7,1,1
1,1,1,1,1,1,1
1,1,1,1,1,1,1
1,1,1,1,1,1,1
endlayer

layer
1,1,1,1,1,1,1
1,1,1,1,1,1,1
1,1,1,1,1,1,1
1,1,1,1,9,1,1
1,1,1,4,11,1,1
1,1,12,14,5,1,1
1,1,1,1,1,1,1
1,1,1,1,1,1,1
1,1,1,1,1,1,1
endlayer

layer
1,1,1,1,1,1,1
1,1,1,1,1,1,1
1,1,1,1,1,1,1
1,1,1,5,6,1,1
1,1,1,4,11,1,1
1,1,1,5,11,1,1
1,1,1,1,1,1,1
1,1,1,1,1,1,1
1,1,1,1,1,1,1
endlayer

layer
1,1,1,1,1,1,1
1,1,1,1,1,1,1
1,1,1,1,1,1,1
1,1,13,11,5,1,1
1,1,1,4,7,1,1
1,1,1,1,10,1,1
1,1,1,1,1,1,1
1,1,1,1,1,1,1
1,1,1,1,1,1,1
endlayer

layer
1,1,1,1,1,1,1
1,1,1,1,1,1,1
1,1,1,1,1,1,1
1,1,8,11,11,1,1
1,1,5,4,5,1,1
1,1,1,1,1,1,1
1,1,1,1,1,1,1
1,1,1,1,1,1,1
1,1,1,1,1,1,1
endlayer

layer
1,1,1,1,1,1,1
1,1,1,1,1,1,1
1,1,1,1,1,1,1
1,1,5,6,9,1,1
1,1,11,4,1,1,1
1,1,12,1,1,1,1
1,1,1,1,1,1,1
1,1,1,1,1,1,1
1,1,1,1,1,1,1
endlayer

layer
1,1,1,1,1,1,1
1,1,1,1,1,1,1
1,1,1,1,1,1,1
1,1,15,5,1,1,1
1,1,11,4,1,1,1
1,1,14,5,1,1,1
1,1,1,1,1,1,1
1,1,1,1,1,1,1
1,1,1,1,1,1,1
endlayer

layer
1,1,1,1,1,1,1
1,1,1,1,1,1,1
1,1,1,1,1,1,1
1,1,16,1,1,1,1
1,1,8,4,1,1,1
1,1,17,11,17,1,1
1,1,1,1,1,1,1
1,1,1,1,1,1,1
1,1,1,1,1,1,1
endlayer

layer
1,1,1,1,1,1,1
1,1,1,1,1,1,1
1,1,1,1,18,1,1
1,18,1,1,1,1,1
1,1,5,4,5,1,1
1,1,2,11,2,18,1
1,1,18,1,1,1,1
1,1,1,1,1,1,1
1,1,1,1,1,1,1
endlayer

layer
1,1,1,1,1,1,1
1,1,1,1,1,1,1
1,18,18,1,18,18,1
1,18,1,1,2,18,1
18,19,1,4,11,19,18
1,18,2,14,2,18,1
1,18,18,1,18,18,1
1,1,1,1,1,1,1
1,1,1,1,1,1,1
endlayer

layer
1,1,1,1,1,1,1
1,1,1,18,1,1,1
1,1,18,20,1,1,1
1,1,1,11,2,18,1
1,1,1,4,11,1,1
1,18,1,11,2,1,1
1,1,1,20,18,1,1
1,1,1,18,1,1,1
1,1,1,1,1,1,1
endlayer

layer
1,1,1,1,1,1,1
1,1,1,1,1,1,1
1,1,18,1,1,1,1
1,19,19,13,19,1,1
1,1,1,4,9,19,1
1,19,1,1,1,19,1
1,1,1,1,2,1,1
1,1,1,1,1,1,1
1,1,1,1,1,1,1
endlayer

layer
1,1,1,1,1,1,1
1,1,1,1,1,1,1
1,1,20,1,20,1,1
1,1,20,13,20,19,1
1,1,12,4,1,2,1
1,1,1,1,1,1,1
1,1,20,1,20,1,1
1,1,1,1,1,1,1
1,1,1,1,1,1,1
endlayer

layer
1,1,1,1,1,1,1
1,1,1,1,1,1,1
1,1,1,1,1,1,1
1,1,5,11,1,1,1
22,19,19,4,1,2,21
1,1,5,1,1,1,1
1,1,2,1,1,1,1
1,1,1,1,1,1,1
1,1,1,1,1,1,1
endlayer

layer
1,1,1,1,1,1,1
1,1,1,16,1,1,1
1,1,1,20,1,1,1
1,1,11,1,1,1,1
1,1,8,4,1,1,1
1,1,11,20,11,1,1
1,1,1,20,1,1,1
1,1,1,17,1,1,1
1,1,1,1,1,1,1
endlayer

layer
1,1,1,1,1,1,1
1,1,1,1,1,1,1
1,18,23,20,23,1,1
19,19,1,1,1,19,19
1,1,11,4,11,1,1
19,19,19,20,19,19,19
1,1,24,20,24,1,1
1,1,1,1,1,1,1
1,1,1,1,1,1,1
endlayer

layer
1,1,1,1,1,1,1
1,1,1,20,1,1,1
1,1,1,20,1,1,1
18,2,1,1,20,1,1
1,19,1,4,9,19,1
1,1,1,11,10,2,1
1,1,1,20,1,18,1
1,1,1,20,1,1,1
1,1,1,1,1,1,1
endlayer

layer
1,1,1,1,1,1,1
1,1,18,2,1,1,1
1,20,1,1,1,20,1
18,2,5,6,2,20,1
19,19,1,4,11,19,19
1,20,1,1,1,2,1
1,20,1,1,1,20,1
1,1,1,2,1,1,1
1,1,1,1,1,1,1
endlayer

layer
1,1,1,18,1,1,1
1,1,18,20,1,1,1
1,18,1,24,18,1,1
1,19,11,1,2,18,1
1,1,24,1,1,1,1
1,2,1,1,1,19,18
1,1,1,23,1,1,1
1,1,18,20,1,1,1
1,1,1,1,1,1,1
endlayer

layer
1,1,1,18,1,1,1
1,1,18,2,18,1,1
1,18,1,1,1,1,1
1,2,1,1,2,18,1
1,1,1,1,1,1,1
1,2,2,1,1,2,18
1,1,1,1,1,1,1
1,1,18,2,18,1,1
1,1,1,18,1,1,1
endlayer

layer
1,1,1,18,1,1,1
1,1,18,2,18,1,1
1,18,1,1,1,1,1
18,2,1,1,2,18,1
1,1,1,1,1,1,1
1,18,2,1,1,2,1
1,1,1,1,1,18,1
1,1,18,2,18,1,1
1,1,1,18,1,1,1
endlayer

layer
1,1,1,1,1,1,1
1,1,1,2,18,1,1
1,1,1,18,1,1,1
18,2,1,1,2,1,1
1,1,18,18,1,18,1
1,1,2,1,1,2,1
1,1,1,18,1,18,1
1,1,18,2,18,1,1
1,1,1,18,1,1,1
endlayer

layer
1,1,1,1,1,1,1
1,1,1,2,1,1,1
1,1,1,18,1,1,1
18,2,1,1,18,1,1
1,1,1,18,1,18,1
1,1,18,1,1,2,1
1,1,1,18,1,1,1
1,1,1,2,18,1,1
1,1,1,1,1,1,1
endlayer

layer
1,1,1,1,1,1,1
1,1,1,1,1,1,1
1,1,1,1,1,1,1
1,2,18,1,18,1,1
1,1,1,18,1,1,1
1,1,1,1,18,2,1
1,1,1,1,1,1,1
1,1,1,1,1,1,1
1,1,1,1,1,1,1
endlayer

