
# Created by Ruins mod version 17.1 Ingame Parser
# authoring Player: ST753M

weight=1
embed_into_distance=200
acceptable_target_blocks=
unacceptable_target_blocks=flowing_water,water,flowing_lava,lava
dimensions=14,21,21
allowable_overhang=999
max_leveling=0
leveling_buffer=-1
preserve_water=1
preserve_lava=1

biomesToSpawnIn=darklands,darklands_forest,darklands_hills,darklands_mountains,darklands_plains,abyssal_wastelands,dreadlands,dreadlands_forest,dreadlands_mountains,purged_dreadlands,dark_realm,coralium_infested_swamp

=0,100,air
rule1=0,100,quark:iron_plate-0,quark:iron_plate-1
rule2=0,100,preserveBlock
rule3=0,100,quark:smoker-0
rule4=0,100,abyssalcraft:antiwater-0
rule5=0,100,abyssalcraft:antiwater-0
rule6=0,100,quark:iron_rod-4
rule7=0,100,quark:iron_plate_stairs-3
rule8=0,100,quark:iron_plate_stairs-1
rule9=0,100,quark:iron_plate_stairs-2
rule10=0,100,quark:iron_plate_stairs-0
rule11=0,100,minecraft:concrete-7
rule12=0,100,minecraft:rail-6
rule13=0,100,minecraft:rail-0
rule14=0,100,minecraft:rail-9
rule15=0,100,minecraft:rail-1
rule16=0,100,quark:iron_ladder-3
rule17=0,100,quark:iron_plate_stairs-4
rule18=0,100,quark:iron_plate_stairs-6
rule19=0,100,quark:iron_plate_stairs-5
rule20=0,100,quark:iron_ladder-2
rule21=0,100,minecraft:rail-7
rule22=0,100,minecraft:rail-8
rule23=0,100,minecraft:iron_bars-0
rule24=0,100,abyssalcraft:dsbutton-4
rule25=0,100,minecraft:concrete-15
rule26=0,100,quark:iron_plate_stairs-7
rule27=0,100,MobSpawner:abyssalcraft:antibat,MobSpawner:abyssalcraft:antiplayer,MobSpawner:abyssalcraft:antizombie,MobSpawner:abyssalcraft:anticreeper,MobSpawner:abyssalcraft:antispider,MobSpawner:abyssalcraft:antiskeleton,MobSpawner:abyssalcraft:antiabyssalzombie
rule28=0,100,abyssalcraft:coraliumstone-0
rule29=0,100,minecraft:iron_block-0
rule30=0,100,IInventory;abyssalcraft:crate;abyssalcraft:cloth#1#0#15+abyssalcraft:antibeef#2#0#20-0
rule31=0,100,IInventory;abyssalcraft:crate;abyssalcraft:antiflesh#2#0#5+abyssalcraft:antiflesh#5#0#20+abyssalcraft:antiflesh#1#0#25+abyssalcraft:antiflesh#2#0#33-0
rule32=0,100,IInventory;abyssalcraft:crate;abyssalcraft:antispidereye#2#0#23-0
rule33=0,100,abyssalcraft:statue-0,abyssalcraft:statue-1,abyssalcraft:statue-2,abyssalcraft:statue-3,abyssalcraft:statue-4,abyssalcraft:statue-5,abyssalcraft:statue-6
rule34=0,100,abyssalcraft:dsbutton-1
rule35=0,100,IInventory;abyssalcraft:crate;abyssalcraft:abyingot#1#0#14+abyssalcraft:abyingot#2#0#29-0
rule36=0,100,minecraft:pumpkin-0
rule37=0,100,minecraft:iron_trapdoor-9
rule38=0,100,minecraft:iron_trapdoor-10

layer
1,2,2,2,2,2,2,2,2,2,2,2,2,2,2,2,2,2,2,2,1
2,2,2,2,2,2,2,2,2,2,2,2,2,2,2,2,2,2,2,2,2
2,2,2,2,2,2,2,2,2,2,2,2,2,2,2,2,2,2,2,2,2
2,2,2,2,2,2,2,2,2,2,2,2,2,2,2,2,2,2,2,2,2
2,2,2,2,1,1,1,1,1,1,1,1,1,1,1,1,1,2,2,2,2
2,2,2,2,1,1,1,1,1,1,3,1,1,1,1,1,1,2,2,2,2
2,2,2,2,1,1,1,1,1,1,1,1,1,1,1,1,1,2,2,2,2
2,2,2,2,1,1,1,1,1,1,1,1,1,1,1,1,1,2,2,2,2
2,2,2,2,1,3,1,1,1,1,1,1,1,1,1,3,1,2,2,2,2
2,2,2,2,1,1,1,1,1,1,1,1,1,1,1,1,1,2,2,2,2
2,2,2,2,1,1,1,1,1,1,1,1,1,1,1,1,1,2,2,2,2
2,2,2,2,1,1,1,1,1,1,1,1,1,1,1,1,1,2,2,2,2
2,2,2,2,1,1,1,1,1,1,1,1,1,1,1,1,1,2,2,2,2
2,2,2,2,1,1,1,1,1,1,1,1,3,1,1,1,1,2,2,2,2
2,2,2,2,1,1,1,1,1,1,1,1,1,1,1,1,1,2,2,2,2
2,2,2,2,1,1,1,1,1,1,1,1,1,1,1,1,1,2,2,2,2
2,2,2,2,1,1,1,1,1,1,1,1,1,1,1,1,1,2,2,2,2
2,2,2,2,2,2,2,2,2,2,2,2,2,2,2,2,2,2,2,2,2
2,2,2,2,2,2,2,2,2,2,2,2,2,2,2,2,2,2,2,2,2
2,2,2,2,2,2,2,2,2,2,2,2,2,2,2,2,2,2,2,2,2
1,2,2,2,2,2,2,2,2,2,2,2,2,2,2,2,2,2,2,2,1
endlayer

layer
1,2,2,2,2,2,2,2,2,2,2,2,2,2,2,2,2,2,2,2,1
2,2,2,2,2,2,2,2,2,2,2,2,2,2,2,2,2,2,2,2,2
2,2,2,2,2,2,2,2,2,2,2,2,2,2,2,2,2,2,2,2,2
2,2,2,2,2,2,2,2,2,2,2,2,2,2,2,2,2,2,2,2,2
2,2,2,2,1,1,1,1,1,1,1,1,1,1,1,1,1,2,2,2,2
2,2,2,2,1,4,4,4,4,4,4,4,4,4,4,4,1,2,2,2,2
2,2,2,2,1,4,4,4,4,4,4,4,4,4,4,4,1,2,2,2,2
2,2,2,2,1,4,4,4,4,4,4,4,4,4,4,4,1,2,2,2,2
2,2,2,2,1,4,4,4,4,4,4,4,4,4,4,4,1,2,2,2,2
2,2,2,2,1,4,4,4,4,4,4,4,4,4,4,4,1,2,2,2,2
2,2,2,2,1,4,4,4,4,4,4,4,4,4,4,4,1,2,2,2,2
2,2,2,2,1,4,4,4,4,4,4,4,4,4,4,4,1,2,2,2,2
2,2,2,2,1,4,4,4,4,4,4,4,4,4,4,4,1,2,2,2,2
2,2,2,2,1,4,4,4,4,4,4,4,4,4,4,4,1,2,2,2,2
2,2,2,2,1,4,4,4,4,4,4,4,4,4,4,4,1,2,2,2,2
2,2,2,2,1,4,4,4,4,4,4,4,4,4,4,4,1,2,2,2,2
2,2,2,2,1,1,1,1,1,1,1,1,1,1,1,1,1,2,2,2,2
2,2,2,2,2,2,2,2,2,2,2,2,2,2,2,2,2,2,2,2,2
2,2,2,2,2,2,2,2,2,2,2,2,2,2,2,2,2,2,2,2,2
2,2,2,2,2,2,2,2,2,2,2,2,2,2,2,2,2,2,2,2,2
1,2,2,2,2,2,2,2,2,2,2,2,2,2,2,2,2,2,2,2,1
endlayer

layer
1,2,2,2,2,2,2,2,2,2,2,2,2,2,2,2,2,2,2,2,1
2,2,2,2,2,2,2,2,2,2,2,2,2,2,2,2,2,2,2,2,2
2,2,2,2,2,2,2,2,2,2,2,2,2,2,2,2,2,2,2,2,2
2,2,2,2,2,2,2,2,2,2,2,2,2,2,2,2,2,2,2,2,2
2,2,2,2,1,1,1,1,1,1,1,1,1,1,1,1,1,2,2,2,2
2,2,2,2,1,5,5,5,5,5,5,5,5,5,5,5,1,2,2,2,2
2,2,2,2,1,5,5,5,5,5,5,5,5,5,5,5,1,2,2,2,2
2,2,2,2,1,5,5,5,5,5,5,5,5,5,5,5,1,2,2,2,2
2,2,2,2,1,5,5,5,5,5,5,5,5,5,5,5,1,2,2,2,2
2,2,2,2,1,5,5,5,5,5,5,5,5,5,5,5,1,2,2,2,2
2,2,2,2,1,5,5,5,5,5,5,5,5,5,5,5,1,2,2,2,2
2,2,2,2,1,5,5,5,5,5,5,5,5,5,5,5,1,2,2,2,2
2,2,2,2,1,5,5,5,5,5,5,5,5,5,5,5,1,2,2,2,2
2,2,2,2,1,5,5,5,5,5,5,5,5,5,5,5,1,2,2,2,2
2,2,2,2,1,5,5,5,5,5,5,5,5,5,5,5,1,2,2,2,2
2,2,2,2,1,5,5,5,5,5,5,5,5,5,5,5,1,2,2,2,2
2,2,2,2,1,1,1,1,1,1,1,1,1,1,1,1,1,2,2,2,2
2,2,2,2,2,2,2,2,2,2,2,2,2,2,2,2,2,2,2,2,2
2,2,2,2,2,2,2,2,2,2,2,2,2,2,2,2,2,2,2,2,2
2,2,2,2,2,2,2,2,2,2,2,2,2,2,2,2,2,2,2,2,2
1,2,2,2,2,2,2,2,2,2,2,2,2,2,2,2,2,2,2,2,1
endlayer

layer
1,1,1,1,1,1,1,1,1,1,1,1,1,1,1,1,1,1,1,1,1
1,1,1,1,1,1,1,1,1,1,1,1,1,1,1,1,1,1,1,1,1
1,1,1,1,1,1,1,1,1,1,1,1,1,1,1,1,1,1,1,1,1
1,1,1,1,1,1,1,1,1,1,1,1,1,1,1,1,1,1,1,1,1
1,1,1,1,1,1,1,1,1,1,1,1,1,1,1,1,1,1,1,1,1
1,1,1,1,1,0,6,6,6,6,6,6,6,6,6,0,1,1,1,1,1
1,1,1,1,1,0,6,6,6,6,6,6,6,6,6,0,1,1,1,1,1
1,1,1,1,1,0,6,6,6,6,6,6,6,6,6,0,1,1,1,1,1
1,1,1,9,8,0,6,6,6,6,6,6,6,6,6,0,8,7,1,1,1
1,1,1,9,0,0,6,6,6,6,6,6,6,6,6,0,0,7,1,1,1
1,1,1,9,0,0,6,6,6,6,6,6,6,6,6,0,0,7,1,1,1
1,1,1,9,0,0,6,6,6,6,6,6,6,6,6,0,0,7,1,1,1
1,1,1,9,10,0,6,6,6,6,6,6,6,6,6,0,10,7,1,1,1
1,1,1,1,1,0,6,6,6,6,6,6,6,6,6,0,1,1,1,1,1
1,1,1,1,1,0,6,6,6,6,6,6,6,6,6,0,1,1,1,1,1
1,1,1,1,1,0,6,6,6,6,6,6,6,6,6,0,1,1,1,1,1
1,1,1,1,1,1,1,1,1,1,1,1,1,1,1,1,1,1,1,1,1
1,1,1,1,1,1,1,1,1,1,1,1,1,1,1,1,1,1,1,1,1
1,1,1,1,1,1,1,1,1,1,1,1,1,1,1,1,1,1,1,1,1
1,1,1,1,1,1,1,1,1,1,1,1,1,1,1,1,1,1,1,1,1
1,1,1,1,1,1,1,1,1,1,1,1,1,1,1,1,1,1,1,1,1
endlayer

layer
1,1,1,1,1,1,1,1,1,1,1,1,1,1,1,1,1,1,1,1,1
1,11,0,0,0,0,0,0,0,0,0,0,0,0,0,0,0,0,0,11,1
1,0,14,13,13,13,13,13,13,13,13,13,13,13,13,13,13,13,12,0,1
1,0,15,0,0,0,0,0,0,0,0,0,0,0,0,0,0,0,15,0,1
1,0,15,16,1,9,0,0,0,0,0,0,0,0,0,7,1,0,15,0,1
1,0,15,0,8,0,0,0,0,0,0,0,0,0,0,0,8,0,15,0,1
1,0,15,0,0,0,0,0,0,0,0,0,0,0,0,0,0,0,15,0,1
1,0,15,0,0,0,0,0,0,0,0,0,0,0,0,0,0,0,15,0,1
1,0,15,0,0,0,0,0,0,0,0,0,0,0,0,0,0,0,15,0,1
1,0,15,0,0,0,0,0,0,0,0,0,0,0,0,0,0,0,15,0,1
1,0,15,0,0,0,0,0,0,0,0,0,0,0,0,0,0,0,15,0,1
1,17,15,0,0,0,0,0,0,0,0,0,0,0,0,0,0,0,15,0,1
1,18,15,0,0,0,0,0,0,0,0,0,0,0,0,0,0,0,15,0,1
1,19,15,0,0,0,0,0,0,0,0,0,0,0,0,0,0,0,15,0,1
1,0,15,0,0,0,0,0,0,0,0,0,0,0,0,0,0,0,15,0,1
1,0,15,0,10,0,0,0,0,0,0,0,0,0,0,0,10,0,15,0,1
1,0,15,0,1,9,0,0,0,0,0,0,0,0,0,7,1,20,15,0,1
1,0,15,0,0,0,0,0,0,0,0,0,0,0,0,0,0,0,15,0,1
1,0,22,13,13,13,13,13,13,13,13,13,13,13,13,13,13,13,21,0,1
1,11,0,0,0,0,0,0,0,0,0,0,0,0,0,0,0,0,0,11,1
1,1,1,1,1,1,1,1,1,1,1,1,1,1,1,1,1,1,1,1,1
endlayer

layer
1,1,1,1,1,1,1,1,1,1,1,1,1,1,1,1,1,1,1,1,1
1,11,0,0,0,0,0,0,0,0,0,0,0,0,0,0,0,0,0,11,1
1,0,0,0,0,0,0,0,0,0,0,0,0,0,0,0,0,0,0,0,1
1,0,0,0,0,0,0,0,0,0,0,0,0,0,0,0,0,0,0,0,1
1,0,0,16,1,0,0,0,0,0,0,0,0,0,0,0,1,0,0,0,1
1,0,0,0,0,0,0,0,0,0,0,0,0,0,0,0,0,0,0,0,1
1,0,0,0,0,0,0,0,0,0,0,0,0,0,0,0,0,0,0,0,1
1,0,0,0,0,0,0,0,0,0,0,0,0,0,0,0,0,0,0,0,1
1,0,0,0,0,0,0,0,0,0,0,0,0,0,0,0,0,0,0,0,1
1,0,0,0,0,0,0,0,0,0,0,0,0,0,0,0,0,0,0,0,1
1,23,0,0,0,0,0,0,0,0,0,0,0,0,0,0,0,0,0,0,1
1,25,24,0,0,0,0,0,0,0,0,0,0,0,0,0,0,0,0,0,1
1,25,24,0,0,0,0,0,0,0,0,0,0,0,0,0,0,0,0,0,1
1,25,24,0,0,0,0,0,0,0,0,0,0,0,0,0,0,0,0,0,1
1,23,0,0,0,0,0,0,0,0,0,0,0,0,0,0,0,0,0,0,1
1,0,0,0,0,0,0,0,0,0,0,0,0,0,0,0,0,0,0,0,1
1,0,0,0,1,0,0,0,0,0,0,0,0,0,0,0,1,20,0,0,1
1,0,0,0,0,0,0,0,0,0,0,0,0,0,0,0,0,0,0,0,1
1,0,0,0,0,0,0,0,0,0,0,0,0,0,0,0,0,0,0,0,1
1,11,0,0,0,0,0,0,0,0,0,0,0,0,0,0,0,0,0,11,1
1,1,1,1,1,1,1,1,1,1,1,1,1,1,1,1,1,1,1,1,1
endlayer

layer
1,1,1,1,1,1,1,1,1,1,1,1,1,1,1,1,1,1,1,1,1
1,11,0,0,0,0,0,0,0,0,0,0,0,0,0,0,0,0,0,11,1
1,0,0,0,0,0,0,0,0,0,0,0,0,0,0,0,0,0,0,0,1
1,0,0,0,0,0,0,0,0,0,0,0,0,0,0,0,0,0,0,0,1
1,0,0,16,1,0,0,0,0,0,0,0,0,0,0,0,1,0,0,0,1
1,0,0,0,0,0,0,0,0,0,0,0,0,0,0,0,0,0,0,0,1
1,0,0,0,0,0,0,0,0,0,0,0,0,0,0,0,0,0,0,0,1
1,0,0,0,0,0,0,0,0,0,0,0,0,0,0,0,0,0,0,0,1
1,0,0,0,0,0,0,0,0,0,0,0,0,0,0,0,0,0,0,0,1
1,0,0,0,0,0,0,0,0,0,0,0,0,0,0,0,0,0,0,0,1
1,23,0,0,0,0,0,0,0,0,0,0,0,0,0,0,0,0,0,0,1
1,25,24,0,0,0,0,0,0,0,0,0,0,0,0,0,0,0,0,0,1
1,25,24,0,0,0,0,0,0,0,0,0,0,0,0,0,0,0,0,0,1
1,25,24,0,0,0,0,0,0,0,0,0,0,0,0,0,0,0,0,0,1
1,23,0,0,0,0,0,0,0,0,0,0,0,0,0,0,0,0,0,0,1
1,0,0,0,0,0,0,0,0,0,0,0,0,0,0,0,0,0,0,0,1
1,0,0,0,1,0,0,0,0,0,0,0,0,0,0,0,1,20,0,0,1
1,0,0,0,0,0,0,0,0,0,0,0,0,0,0,0,0,0,0,0,1
1,0,0,0,0,0,0,0,0,0,0,0,0,0,0,0,0,0,0,0,1
1,11,0,0,0,0,0,0,0,0,0,0,0,0,0,0,0,0,0,11,1
1,1,1,1,1,1,1,1,1,1,1,1,1,1,1,1,1,1,1,1,1
endlayer

layer
1,1,1,1,1,1,1,1,1,1,1,1,1,1,1,1,1,1,1,1,1
1,11,0,0,0,0,0,0,0,0,0,0,0,0,0,0,0,0,0,11,1
1,0,0,0,0,0,0,0,0,0,0,0,0,0,0,0,0,0,0,0,1
1,0,0,0,0,0,0,0,0,0,0,0,0,0,0,0,0,0,0,0,1
1,0,0,16,1,18,0,0,0,0,0,0,0,0,0,26,1,0,0,0,1
1,0,0,0,19,0,0,0,0,0,0,0,0,0,0,0,19,0,0,0,1
1,0,0,0,0,0,0,0,0,0,0,0,0,0,0,0,0,0,0,0,1
1,0,0,0,0,0,0,0,0,0,0,0,0,0,0,0,0,0,0,0,1
1,0,0,0,0,0,0,0,0,0,0,0,0,0,0,0,0,0,0,0,1
1,0,0,0,0,0,0,0,0,0,0,0,0,0,0,0,0,0,0,0,1
1,0,0,0,0,0,0,0,0,0,0,0,0,0,0,0,0,0,0,0,1
1,10,0,0,0,0,0,0,0,0,0,0,0,0,0,0,0,0,0,0,1
1,9,0,0,0,0,0,0,0,0,0,0,0,0,0,0,0,0,0,0,1
1,8,0,0,0,0,0,0,0,0,0,0,0,0,0,0,0,0,0,0,1
1,0,0,0,0,0,0,0,0,0,0,0,0,0,0,0,0,0,0,0,1
1,0,0,0,17,0,0,0,0,0,0,0,0,0,0,0,17,0,0,0,1
1,0,0,0,1,18,0,0,0,0,0,0,0,0,0,26,1,20,0,0,1
1,0,0,0,0,0,0,0,0,0,0,0,0,0,0,0,0,0,0,0,1
1,0,0,0,0,0,0,0,0,0,0,0,0,0,0,0,0,0,0,0,1
1,11,0,0,0,0,0,0,0,0,0,0,0,0,0,0,0,0,0,11,1
1,1,1,1,1,1,1,1,1,1,1,1,1,1,1,1,1,1,1,1,1
endlayer

layer
1,1,1,1,1,1,1,1,1,1,1,1,1,1,1,1,1,1,1,1,1
1,1,1,1,1,1,1,1,1,1,1,1,1,1,1,1,1,1,1,1,1
1,1,1,1,1,1,1,1,1,1,1,1,1,1,1,1,1,1,1,1,1
1,1,1,1,1,1,1,1,1,1,1,1,1,1,1,1,1,1,1,1,1
1,1,1,16,1,1,1,1,1,1,1,1,1,1,1,1,27,1,1,1,1
1,1,1,1,1,18,19,19,19,19,19,19,19,19,19,26,1,1,1,1,1
1,1,1,1,1,18,0,0,0,0,0,0,0,0,0,26,1,1,1,1,1
1,1,1,1,1,18,0,0,0,0,0,0,0,0,0,26,1,1,1,1,1
1,1,1,1,1,18,0,0,0,0,0,0,0,0,0,26,1,1,1,1,1
1,1,1,1,1,18,0,0,0,0,0,0,0,0,0,26,1,1,1,1,1
1,1,1,1,1,18,0,0,0,0,0,0,0,0,0,26,1,1,1,1,1
1,1,1,1,1,18,0,0,0,0,0,0,0,0,0,26,1,1,1,1,1
1,1,1,1,1,18,0,0,0,0,0,0,0,0,0,26,1,1,1,1,1
1,1,1,1,1,18,0,0,0,0,0,0,0,0,0,26,1,1,1,1,1
1,1,1,1,1,18,0,0,0,0,0,0,0,0,0,26,1,1,1,1,1
1,1,1,1,1,17,17,17,17,17,17,17,17,17,17,17,1,1,1,1,1
1,1,1,1,27,1,1,1,1,1,1,1,1,1,1,1,1,20,1,1,1
1,1,1,1,1,1,1,1,1,1,1,1,1,1,1,1,1,1,1,1,1
1,1,1,1,1,1,1,1,1,1,1,1,1,1,1,1,1,1,1,1,1
1,1,1,1,1,1,1,1,1,1,1,1,1,1,1,1,1,1,1,1,1
1,1,1,1,1,1,1,1,1,1,1,1,1,1,1,1,1,1,1,1,1
endlayer

layer
1,1,1,1,1,1,1,1,1,1,1,1,1,1,1,1,1,1,1,1,1
1,11,0,0,0,0,0,0,0,26,19,18,0,0,0,0,0,0,0,11,1
1,0,0,0,0,0,0,0,0,0,0,0,0,0,0,0,0,0,0,28,1
1,0,0,0,0,0,0,0,0,0,0,0,0,0,0,0,0,0,0,0,1
1,0,0,16,1,1,0,0,0,0,0,0,0,0,0,1,1,0,0,0,1
1,0,0,0,1,1,23,23,23,23,23,23,23,23,23,1,1,0,0,0,1
1,0,0,0,0,23,0,0,0,0,0,0,0,0,0,23,0,0,0,0,1
1,0,0,0,0,23,0,0,0,0,0,0,0,0,0,23,0,0,0,0,1
1,0,0,0,0,23,0,0,0,0,0,0,0,0,0,23,0,0,0,0,1
1,0,0,0,0,23,0,0,0,0,0,0,0,0,0,23,0,0,0,0,1
1,0,0,0,0,23,0,0,0,0,0,0,0,0,0,23,0,0,0,0,1
1,0,0,0,0,23,0,0,0,0,0,0,0,0,0,23,0,0,0,0,1
1,0,0,0,0,23,0,0,0,0,0,0,0,0,0,23,0,0,0,0,1
1,0,0,0,0,23,0,0,0,0,0,0,0,0,0,23,0,0,0,0,1
1,0,0,29,0,23,0,0,0,0,0,0,0,0,0,23,0,0,0,0,1
1,0,0,0,1,1,23,23,23,23,23,23,23,23,23,1,1,0,0,0,1
1,0,0,0,1,1,0,0,0,0,0,0,0,0,0,1,1,20,0,0,1
1,0,0,0,0,0,0,0,0,0,0,0,0,0,0,0,0,0,0,0,1
1,0,0,0,0,0,0,0,0,30,0,0,0,0,0,0,0,0,0,0,1
1,11,0,0,0,0,0,32,31,0,0,0,0,0,0,0,0,0,0,11,1
1,1,1,1,1,1,1,1,1,1,1,1,1,1,1,1,1,1,1,1,1
endlayer

layer
1,1,1,1,1,1,1,1,1,1,1,1,1,1,1,1,1,1,1,1,1
1,11,0,0,0,0,0,0,23,25,25,25,23,0,0,0,0,0,0,11,1
1,0,0,0,0,0,0,0,0,34,34,34,0,0,0,0,0,0,0,33,1
1,0,0,0,0,0,0,0,0,0,0,0,0,0,0,0,0,0,0,0,1
1,0,0,16,1,1,0,0,0,0,0,0,0,0,0,1,1,0,0,0,1
1,0,0,0,1,1,23,23,23,23,23,23,23,23,23,1,1,0,0,0,1
1,0,0,0,0,23,0,0,0,0,0,0,0,0,0,23,0,0,0,0,1
1,0,0,0,0,23,0,0,0,0,0,0,0,0,0,23,0,0,0,0,1
1,0,0,0,0,23,0,0,0,0,0,0,0,0,0,23,0,0,0,0,1
1,0,0,0,0,23,0,0,0,0,0,0,0,0,0,23,0,0,0,0,1
1,0,0,0,0,23,0,0,0,0,0,0,0,0,0,23,0,0,0,0,1
1,0,0,0,0,23,0,0,0,0,0,0,0,0,0,23,0,0,0,0,1
1,0,0,0,0,23,0,0,0,0,0,0,0,0,0,23,0,0,0,0,1
1,0,0,29,0,23,0,0,0,0,0,0,0,0,0,23,0,0,0,0,1
1,0,0,29,0,23,0,0,0,0,0,0,0,0,0,23,0,0,0,0,1
1,0,0,29,1,1,23,23,23,23,23,23,23,23,23,1,1,0,0,0,1
1,0,0,0,1,1,0,0,0,0,0,0,0,0,0,1,1,20,0,0,1
1,0,0,0,0,0,0,0,0,0,0,0,0,0,0,0,0,0,0,0,1
1,0,0,0,0,0,0,0,0,0,0,0,0,0,0,0,0,0,0,0,1
1,11,0,0,0,0,0,0,35,0,0,0,0,0,0,0,0,0,0,11,1
1,1,1,1,1,1,1,1,1,1,1,1,1,1,1,1,1,1,1,1,1
endlayer

layer
1,1,1,1,1,1,1,1,1,1,1,1,1,1,1,1,1,1,1,1,1
1,11,0,0,0,0,0,0,23,25,25,25,23,0,0,0,0,0,0,11,1
1,0,0,0,0,0,0,0,0,34,34,34,0,0,0,0,0,0,0,0,1
1,0,0,0,0,0,0,0,0,0,0,0,0,0,0,0,0,0,0,0,1
1,0,0,16,1,1,0,0,0,0,0,0,0,0,0,1,1,0,0,0,1
1,0,0,0,1,1,23,23,23,23,23,23,23,23,23,1,1,0,0,0,1
1,0,0,0,0,23,0,0,0,0,0,0,0,0,0,23,0,0,0,0,1
1,0,0,0,0,23,0,0,0,0,0,0,0,0,0,23,0,0,0,0,1
1,0,0,0,0,23,0,0,0,0,0,0,0,0,0,23,0,0,0,0,1
1,0,0,0,0,23,0,0,0,0,0,0,0,0,0,23,0,0,0,0,1
1,0,0,0,0,23,0,0,0,0,0,0,0,0,0,23,0,0,0,0,1
1,0,0,0,0,23,0,0,0,0,0,0,0,0,0,23,0,0,0,0,1
1,0,0,0,0,23,0,0,0,0,0,0,0,0,0,23,0,0,0,0,1
1,0,0,0,0,23,0,0,0,0,0,0,0,0,0,23,0,0,0,0,1
1,0,0,36,0,23,0,0,0,0,0,0,0,0,0,23,0,0,0,0,1
1,0,0,0,1,1,23,23,23,23,23,23,23,23,23,1,1,0,0,0,1
1,0,0,0,1,1,0,0,0,0,0,0,0,0,0,1,1,20,0,0,1
1,0,0,0,0,0,0,0,0,0,0,0,0,0,0,0,0,0,0,0,1
1,0,0,0,0,0,0,0,0,0,0,0,0,0,0,0,0,0,0,0,1
1,11,0,0,0,0,0,0,0,0,0,0,0,0,0,0,0,0,0,11,1
1,1,1,1,1,1,1,1,1,1,1,1,1,1,1,1,1,1,1,1,1
endlayer

layer
1,1,1,1,1,1,1,1,1,1,1,1,1,1,1,1,1,1,1,1,1
1,11,0,0,0,0,0,0,0,7,8,9,0,0,0,0,0,0,0,11,1
1,0,0,0,0,0,0,0,0,0,0,0,0,0,0,0,0,0,0,0,1
1,0,0,0,0,0,0,0,0,0,0,0,0,0,0,0,0,0,0,0,1
1,0,0,16,1,1,0,0,0,0,0,0,0,0,0,1,1,0,0,0,1
1,0,0,0,1,1,23,23,23,23,23,23,23,23,23,1,1,0,0,0,1
1,0,0,0,0,23,0,0,0,0,0,0,0,0,0,23,0,0,0,0,1
1,0,0,0,0,23,0,0,0,0,0,0,0,0,0,23,0,0,0,0,1
1,0,0,0,0,23,0,0,0,0,0,0,0,0,0,23,0,0,0,0,1
1,0,0,0,0,23,0,0,0,0,0,0,0,0,0,23,0,0,0,0,1
1,0,0,0,0,23,0,0,0,0,0,0,0,0,0,23,0,0,0,0,1
1,0,0,0,0,23,0,0,0,0,0,0,0,0,0,23,0,0,0,0,1
1,0,0,0,0,23,0,0,0,0,0,0,0,0,0,23,0,0,0,0,1
1,0,0,0,0,23,0,0,0,0,0,0,0,0,0,23,0,0,0,0,1
1,0,0,0,0,23,0,0,0,0,0,0,0,0,0,23,0,0,0,0,1
1,0,0,0,1,1,23,23,23,23,23,23,23,23,23,1,1,0,0,0,1
1,0,0,0,1,1,0,0,0,0,0,0,0,0,0,1,1,20,0,0,1
1,0,0,0,0,0,0,0,0,0,0,0,0,0,0,0,0,0,0,0,1
1,0,0,0,0,0,0,0,0,0,0,0,0,0,0,0,0,0,0,0,1
1,11,0,0,0,0,0,0,0,0,0,0,0,0,0,0,0,0,0,11,1
1,1,1,1,1,1,1,1,1,1,1,1,1,1,1,1,1,1,1,1,1
endlayer

layer
1,1,1,1,1,1,1,1,1,1,1,1,1,1,1,1,1,1,1,1,1
1,1,1,1,1,1,1,1,1,1,1,1,1,1,1,1,1,1,1,1,1
1,1,1,1,1,1,1,1,1,1,1,1,1,1,1,1,1,1,1,1,1
1,1,1,1,1,1,1,1,1,1,1,1,1,1,1,1,1,1,1,1,1
1,1,1,1,1,1,1,1,1,1,1,1,1,1,1,1,1,1,1,1,1
1,1,1,1,1,1,1,1,1,1,1,1,1,1,1,1,1,1,1,1,1
1,1,1,1,1,1,1,1,1,1,1,1,1,1,1,1,1,1,1,1,1
1,1,1,1,1,1,1,18,19,19,19,19,19,26,1,1,1,1,1,1,1
1,1,1,1,1,1,1,18,37,37,37,37,37,26,1,1,1,1,1,1,1
1,1,1,1,1,1,1,18,37,37,37,37,37,26,1,1,1,1,1,1,1
1,1,1,1,1,1,1,18,37,38,38,38,37,26,1,1,1,1,1,1,1
1,1,1,1,1,1,1,18,37,37,37,37,37,26,1,1,1,1,1,1,1
1,1,1,1,1,1,1,18,37,37,37,37,37,26,1,1,1,1,1,1,1
1,1,1,1,1,1,1,17,17,17,17,17,17,17,1,1,1,1,1,1,1
1,1,1,1,1,1,1,1,1,1,1,1,1,1,1,1,1,1,1,1,1
1,1,1,1,1,1,1,1,1,1,1,1,1,1,1,1,1,1,1,1,1
1,1,1,1,1,1,1,1,1,1,1,1,1,1,1,1,1,1,1,1,1
1,1,1,1,1,1,1,1,1,1,1,1,1,1,1,1,1,1,1,1,1
1,1,1,1,1,1,1,1,1,1,1,1,1,1,1,1,1,1,1,1,1
1,1,1,1,1,1,1,1,1,1,1,1,1,1,1,1,1,1,1,1,1
1,1,1,1,1,1,1,1,1,1,1,1,1,1,1,1,1,1,1,1,1
endlayer

