# Gilly's Vertical Nether Access Port
# template generated with Ruins mod version 16.5 Ingame Parser
# Structure created and developed by Gilly

weight=1
embed_into_distance=0
uniqueMinDistance=250
acceptable_target_blocks=
unacceptable_target_blocks=flowing_water,water,flowing_lava,lava
biomesToSpawnIn=hell
dimensions=119,5,4
allowable_overhang=0
max_leveling=4
leveling_buffer=-1
preserve_water=0
preserve_lava=0

rule1=0,100,minecraft:stained_hardened_clay-4
rule2=0,100,minecraft:hay_block-0
rule3=0,100,preserveBlock
rule4=0,100,minecraft:ladder-5
rule5=0,100,minecraft:vine-4
rule6=0,100,minecraft:vine-1
rule7=0,100,minecraft:stained_glass-0
rule8=0,100,minecraft:glowstone-0
rule9=7,100,wooden_button-3
rule10=7,100,wooden_button-4
rule11=0,100,minecraft:stained_hardened_clay-15

layer
1,1,1,1
1,2,2,1
1,2,2,1
1,2,2,1
1,1,1,1
endlayer

layer
3,1,1,3
0,4,4,0
1,6,5,1
1,6,5,1
3,7,7,3
endlayer

layer
3,1,1,3
0,4,4,0
1,6,5,1
1,6,5,1
3,7,7,3
endlayer

layer
3,1,1,3
0,4,4,0
1,6,5,1
1,6,5,1
3,7,7,3
endlayer

layer
3,1,1,3
7,4,4,7
8,6,5,8
1,6,5,1
3,7,7,3
endlayer

layer
3,1,1,3
7,4,4,7
1,0,0,1
1,0,0,1
3,7,7,3
endlayer

layer
3,1,1,3
7,4,4,7
1,10,9,1
1,10,9,1
3,7,7,3
endlayer

layer
3,1,1,3
7,4,4,7
1,0,0,1
1,0,0,1
3,7,7,3
endlayer

layer
3,11,11,3
7,4,4,7
11,0,0,11
11,0,0,11
3,7,7,3
endlayer

layer
3,11,11,3
7,4,4,7
11,0,0,11
11,0,0,11
3,7,7,3
endlayer

layer
3,11,11,3
7,4,4,7
11,0,0,11
11,0,0,11
3,7,7,3
endlayer

layer
3,11,11,3
7,4,4,7
11,0,0,11
11,0,0,11
3,7,7,3
endlayer

layer
3,11,11,3
7,4,4,7
11,0,0,11
11,0,0,11
3,7,7,3
endlayer

layer
3,11,11,3
7,4,4,7
11,0,0,11
11,0,0,11
3,7,7,3
endlayer

layer
3,11,11,3
7,4,4,7
11,0,0,11
11,0,0,11
3,7,7,3
endlayer

layer
3,1,1,3
7,4,4,7
1,0,0,1
1,0,0,1
3,7,7,3
endlayer

layer
3,1,1,3
7,4,4,7
1,0,0,1
1,0,0,1
3,7,7,3
endlayer

layer
3,1,1,3
7,4,4,7
1,0,0,1
1,0,0,1
3,7,7,3
endlayer

layer
3,1,1,3
7,4,4,7
8,0,0,8
1,0,0,1
3,7,7,3
endlayer

layer
3,1,1,3
7,4,4,7
1,0,0,1
1,0,0,1
3,7,7,3
endlayer

layer
3,1,1,3
7,4,4,7
1,0,0,1
1,0,0,1
3,7,7,3
endlayer

layer
3,1,1,3
7,4,4,7
1,0,0,1
1,0,0,1
3,7,7,3
endlayer

layer
3,11,11,3
7,4,4,7
11,0,0,11
11,0,0,11
3,7,7,3
endlayer

layer
3,11,11,3
7,4,4,7
11,0,0,11
11,0,0,11
3,7,7,3
endlayer

layer
3,11,11,3
7,4,4,7
11,0,0,11
11,0,0,11
3,7,7,3
endlayer

layer
3,11,11,3
7,4,4,7
11,0,0,11
11,0,0,11
3,7,7,3
endlayer

layer
3,11,11,3
7,4,4,7
11,0,0,11
11,0,0,11
3,7,7,3
endlayer

layer
3,11,11,3
7,4,4,7
11,0,0,11
11,0,0,11
3,7,7,3
endlayer

layer
3,11,11,3
7,4,4,7
11,0,0,11
11,0,0,11
3,7,7,3
endlayer

layer
3,1,1,3
7,4,4,7
1,0,0,1
1,0,0,1
3,7,7,3
endlayer

layer
3,1,1,3
7,4,4,7
1,0,0,1
1,0,0,1
3,7,7,3
endlayer

layer
3,1,1,3
7,4,4,7
1,0,0,1
1,0,0,1
3,7,7,3
endlayer

layer
3,1,1,3
7,4,4,7
8,0,0,8
1,0,0,1
3,7,7,3
endlayer

layer
3,1,1,3
7,4,4,7
1,0,0,1
1,0,0,1
3,7,7,3
endlayer

layer
3,1,1,3
7,4,4,7
1,0,0,1
1,0,0,1
3,7,7,3
endlayer

layer
3,1,1,3
7,4,4,7
1,0,0,1
1,0,0,1
3,7,7,3
endlayer

layer
3,11,11,3
7,4,4,7
11,0,0,11
11,0,0,11
3,7,7,3
endlayer

layer
3,11,11,3
7,4,4,7
11,0,0,11
11,0,0,11
3,7,7,3
endlayer

layer
3,11,11,3
7,4,4,7
11,0,0,11
11,0,0,11
3,7,7,3
endlayer

layer
3,11,11,3
7,4,4,7
11,0,0,11
11,0,0,11
3,7,7,3
endlayer

layer
3,11,11,3
7,4,4,7
11,0,0,11
11,0,0,11
3,7,7,3
endlayer

layer
3,11,11,3
7,4,4,7
11,0,0,11
11,0,0,11
3,7,7,3
endlayer

layer
3,11,11,3
7,4,4,7
11,0,0,11
11,0,0,11
3,7,7,3
endlayer

layer
3,1,1,3
7,4,4,7
1,0,0,1
1,0,0,1
3,7,7,3
endlayer

layer
3,1,1,3
7,4,4,7
1,0,0,1
1,0,0,1
3,7,7,3
endlayer

layer
3,1,1,3
7,4,4,7
1,0,0,1
1,0,0,1
3,7,7,3
endlayer

layer
3,1,1,3
7,4,4,7
8,0,0,8
1,0,0,1
3,7,7,3
endlayer

layer
3,1,1,3
7,4,4,7
1,0,0,1
1,0,0,1
3,7,7,3
endlayer

layer
3,1,1,3
7,4,4,7
1,0,0,1
1,0,0,1
3,7,7,3
endlayer

layer
3,1,1,3
7,4,4,7
1,0,0,1
1,0,0,1
3,7,7,3
endlayer

layer
3,11,11,3
7,4,4,7
11,0,0,11
11,0,0,11
3,7,7,3
endlayer

layer
3,11,11,3
7,4,4,7
11,0,0,11
11,0,0,11
3,7,7,3
endlayer

layer
3,11,11,3
7,4,4,7
11,0,0,11
11,0,0,11
3,7,7,3
endlayer

layer
3,11,11,3
7,4,4,7
11,0,0,11
11,0,0,11
3,7,7,3
endlayer

layer
3,11,11,3
7,4,4,7
11,0,0,11
11,0,0,11
3,7,7,3
endlayer

layer
3,11,11,3
7,4,4,7
11,0,0,11
11,0,0,11
3,7,7,3
endlayer

layer
3,11,11,3
7,4,4,7
11,0,0,11
11,0,0,11
3,7,7,3
endlayer

layer
3,1,1,3
7,4,4,7
1,0,0,1
1,0,0,1
3,7,7,3
endlayer

layer
3,1,1,3
7,4,4,7
1,0,0,1
1,0,0,1
3,7,7,3
endlayer

layer
3,1,1,3
7,4,4,7
1,0,0,1
1,0,0,1
3,7,7,3
endlayer

layer
3,1,1,3
7,4,4,7
8,0,0,8
1,0,0,1
3,7,7,3
endlayer

layer
3,1,1,3
7,4,4,7
1,0,0,1
1,0,0,1
3,7,7,3
endlayer

layer
3,1,1,3
7,4,4,7
1,0,0,1
1,0,0,1
3,7,7,3
endlayer

layer
3,1,1,3
7,4,4,7
1,0,0,1
1,0,0,1
3,7,7,3
endlayer

layer
3,11,11,3
7,4,4,7
11,0,0,11
11,0,0,11
3,7,7,3
endlayer

layer
3,11,11,3
7,4,4,7
11,0,0,11
11,0,0,11
3,7,7,3
endlayer

layer
3,11,11,3
7,4,4,7
11,0,0,11
11,0,0,11
3,7,7,3
endlayer

layer
3,11,11,3
7,4,4,7
11,0,0,11
11,0,0,11
3,7,7,3
endlayer

layer
3,11,11,3
7,4,4,7
11,0,0,11
11,0,0,11
3,7,7,3
endlayer

layer
3,11,11,3
7,4,4,7
11,0,0,11
11,0,0,11
3,7,7,3
endlayer

layer
3,11,11,3
7,4,4,7
11,0,0,11
11,0,0,11
3,7,7,3
endlayer

layer
3,1,1,3
7,4,4,7
1,0,0,1
1,0,0,1
3,7,7,3
endlayer

layer
3,1,1,3
7,4,4,7
1,0,0,1
1,0,0,1
3,7,7,3
endlayer

layer
3,1,1,3
7,4,4,7
1,0,0,1
1,0,0,1
3,7,7,3
endlayer

layer
3,1,1,3
7,4,4,7
8,0,0,8
1,0,0,1
3,7,7,3
endlayer

layer
3,1,1,3
7,4,4,7
1,0,0,1
1,0,0,1
3,7,7,3
endlayer

layer
3,1,1,3
7,4,4,7
1,0,0,1
1,0,0,1
3,7,7,3
endlayer

layer
3,1,1,3
7,4,4,7
1,0,0,1
1,0,0,1
3,7,7,3
endlayer

layer
3,11,11,3
7,4,4,7
11,0,0,11
11,0,0,11
3,7,7,3
endlayer

layer
3,11,11,3
7,4,4,7
11,0,0,11
11,0,0,11
3,7,7,3
endlayer

layer
3,11,11,3
7,4,4,7
11,0,0,11
11,0,0,11
3,7,7,3
endlayer

layer
3,11,11,3
7,4,4,7
11,0,0,11
11,0,0,11
3,7,7,3
endlayer

layer
3,11,11,3
7,4,4,7
11,0,0,11
11,0,0,11
3,7,7,3
endlayer

layer
3,11,11,3
7,4,4,7
11,0,0,11
11,0,0,11
3,7,7,3
endlayer

layer
3,11,11,3
7,4,4,7
11,0,0,11
11,0,0,11
3,7,7,3
endlayer

layer
3,1,1,3
7,4,4,7
1,0,0,1
1,0,0,1
3,7,7,3
endlayer

layer
3,1,1,3
7,4,4,7
1,0,0,1
1,0,0,1
3,7,7,3
endlayer

layer
3,1,1,3
7,4,4,7
1,0,0,1
1,0,0,1
3,7,7,3
endlayer

layer
3,1,1,3
7,4,4,7
8,0,0,8
1,0,0,1
3,7,7,3
endlayer

layer
3,1,1,3
7,4,4,7
1,0,0,1
1,0,0,1
3,7,7,3
endlayer

layer
3,1,1,3
7,4,4,7
1,0,0,1
1,0,0,1
3,7,7,3
endlayer

layer
3,1,1,3
7,4,4,7
1,0,0,1
1,0,0,1
3,7,7,3
endlayer

layer
3,11,11,3
7,4,4,7
11,0,0,11
11,0,0,11
3,7,7,3
endlayer

layer
3,11,11,3
7,4,4,7
11,0,0,11
11,0,0,11
3,7,7,3
endlayer

layer
3,11,11,3
7,4,4,7
11,0,0,11
11,0,0,11
3,7,7,3
endlayer

layer
3,11,11,3
7,4,4,7
11,0,0,11
11,0,0,11
3,7,7,3
endlayer

layer
3,11,11,3
7,4,4,7
11,0,0,11
11,0,0,11
3,7,7,3
endlayer

layer
3,11,11,3
7,4,4,7
11,0,0,11
11,0,0,11
3,7,7,3
endlayer

layer
3,11,11,3
7,4,4,7
11,0,0,11
11,0,0,11
3,7,7,3
endlayer

layer
3,1,1,3
7,4,4,7
1,0,0,1
1,0,0,1
3,7,7,3
endlayer

layer
3,1,1,3
7,4,4,7
1,0,0,1
1,0,0,1
3,7,7,3
endlayer

layer
3,1,1,3
7,4,4,7
1,0,0,1
1,0,0,1
3,7,7,3
endlayer

layer
3,1,1,3
7,4,4,7
8,0,0,8
1,0,0,1
3,7,7,3
endlayer

layer
3,1,1,3
7,4,4,7
1,0,0,1
1,0,0,1
3,7,7,3
endlayer

layer
3,1,1,3
7,4,4,7
1,0,0,1
1,0,0,1
3,7,7,3
endlayer

layer
3,1,1,3
7,4,4,7
1,0,0,1
1,0,0,1
3,7,7,3
endlayer

layer
3,11,11,3
7,4,4,7
11,0,0,11
11,0,0,11
3,7,7,3
endlayer

layer
3,11,11,3
7,4,4,7
11,0,0,11
11,0,0,11
3,7,7,3
endlayer

layer
3,11,11,3
7,4,4,7
11,0,0,11
11,0,0,11
3,7,7,3
endlayer

layer
3,11,11,3
7,4,4,7
11,0,0,11
11,0,0,11
3,7,7,3
endlayer

layer
3,11,11,3
7,4,4,7
11,0,0,11
11,0,0,11
3,7,7,3
endlayer

layer
3,11,11,3
7,4,4,7
11,0,0,11
11,0,0,11
3,7,7,3
endlayer

layer
3,11,11,3
7,4,4,7
11,0,0,11
11,0,0,11
3,7,7,3
endlayer

layer
3,1,1,3
7,4,4,7
1,0,0,1
1,0,0,1
3,7,7,3
endlayer

layer
3,1,1,3
7,4,4,7
1,0,0,1
1,0,0,1
3,7,7,3
endlayer

layer
3,1,1,3
7,4,4,7
1,0,0,1
1,0,0,1
3,7,7,3
endlayer

layer
3,1,1,3
7,4,4,7
8,0,0,8
1,0,0,1
3,7,7,3
endlayer

layer
3,1,1,3
7,4,4,7
1,0,0,1
1,0,0,1
3,7,7,3
endlayer

layer
3,1,1,3
7,4,4,7
1,0,0,1
1,0,0,1
3,7,7,3
endlayer
