
# Created by Ruins mod version 16.7 Ingame Parser
# authoring Player: lafuller

weight=1
embed_into_distance=0
acceptable_target_blocks=
unacceptable_target_blocks=flowing_water,water,flowing_lava,lava
dimensions=98,8,8
allowable_overhang=0
max_leveling=98
leveling_buffer=-1
preserve_water=0
preserve_lava=0

rule1=0,100,preserveBlock
rule2=0,100,minecraft:nether_brick-0
rule3=0,100,minecraft:nether_brick_stairs-6
rule4=0,100,minecraft:vine-4
rule5=0,100,minecraft:ladder-2
rule6=0,100,minecraft:nether_brick_stairs-0
rule7=0,100,minecraft:stone_slab-6
rule8=0,100,minecraft:nether_brick_stairs-7
rule9=0,100,minecraft:nether_brick_stairs-4
rule10=0,100,minecraft:nether_brick_stairs-3
rule11=0,100,minecraft:stone_slab-14
rule12=0,100,minecraft:nether_brick_stairs-1
rule13=0,100,minecraft:trapdoor-7
rule14=0,100,minecraft:nether_brick_stairs-2
rule15=0,100,minecraft:nether_brick_stairs-5
rule16=0,100,minecraft:nether_brick_fence-0
rule17=0,100,minecraft:trapdoor-6

layer
2,2,2,2,2,2,2,1
2,2,2,2,2,2,2,1
2,2,2,2,2,2,2,1
2,2,2,2,2,2,2,1
2,2,2,2,2,2,2,1
2,2,2,2,2,2,2,1
1,1,1,1,1,1,1,1
1,1,1,1,1,1,1,1
endlayer

layer
1,0,0,0,0,0,0,1
0,0,0,0,0,0,0,1
0,0,0,0,0,0,0,1
7,7,6,2,5,4,3,1
6,2,2,8,5,4,2,1
2,2,2,2,9,9,2,1
1,1,1,1,1,1,1,1
1,1,1,1,1,1,1,1
endlayer

layer
1,0,0,0,0,0,0,1
0,0,0,0,0,0,0,1
0,0,0,0,0,0,0,1
0,0,0,8,5,4,3,1
0,0,6,8,5,4,2,1
0,7,10,2,9,9,2,1
7,7,11,1,1,1,1,1
1,11,1,1,1,1,1,1
endlayer

layer
1,0,0,0,0,0,0,1
0,0,0,0,0,0,0,1
0,0,0,0,0,0,0,1
0,0,0,2,5,4,3,1
0,0,0,8,5,4,2,1
0,0,0,10,9,9,2,1
0,0,0,10,11,1,1,1
1,0,7,11,1,1,1,1
endlayer

layer
1,0,0,0,0,0,0,1
0,0,0,0,0,0,0,1
0,0,0,0,0,0,0,1
0,0,0,2,5,4,3,1
0,0,0,2,5,4,2,1
0,0,0,0,10,9,2,1
0,0,0,0,7,2,11,1
1,0,0,0,7,10,11,1
endlayer

layer
1,0,0,0,0,0,0,1
0,0,0,0,0,0,0,1
0,0,0,0,9,9,9,1
0,0,0,2,5,4,2,1
0,0,0,2,5,4,2,11
0,0,0,0,13,10,12,2
0,0,0,0,0,0,7,7
1,0,0,0,0,0,0,1
endlayer

layer
1,0,0,0,0,0,1,1
0,0,0,0,0,0,1,1
0,0,0,0,2,2,2,1
0,0,0,8,5,0,2,11
0,0,0,2,5,0,12,7
0,0,0,0,13,0,0,0
0,0,0,0,0,0,0,0
1,0,0,0,0,0,0,1
endlayer

layer
1,0,0,0,0,1,1,1
0,0,0,0,1,1,2,12
0,0,0,0,2,15,14,7
0,0,0,2,5,16,12,0
0,0,0,8,5,16,0,0
0,0,0,0,13,0,0,0
0,0,0,0,0,0,0,0
1,0,0,0,0,0,0,1
endlayer

layer
1,0,1,1,1,11,7,1
0,0,0,1,11,14,0,0
0,0,0,1,2,14,0,0
0,0,0,2,5,16,0,0
0,0,0,2,5,16,0,0
0,0,0,0,13,0,0,0
0,0,0,0,0,0,0,0
1,0,0,0,0,0,0,1
endlayer

layer
1,1,11,14,7,0,0,1
1,1,1,8,7,0,0,0
1,1,1,8,14,0,0,0
0,1,1,2,5,16,0,0
0,0,0,8,5,16,0,0
0,0,0,0,13,0,0,0
0,0,0,0,0,0,0,0
1,0,0,0,0,0,0,1
endlayer

layer
1,7,0,0,0,0,0,1
7,7,7,0,0,0,0,0
11,2,6,14,17,0,0,0
1,11,11,2,5,16,0,0
1,1,1,8,5,16,0,0
1,1,1,0,13,0,0,0
0,0,0,0,0,0,0,0
1,0,0,0,0,0,0,1
endlayer

layer
1,0,0,0,0,0,0,1
0,0,0,0,0,0,0,0
0,0,0,0,17,0,0,0
7,7,6,2,5,16,0,0
6,2,2,8,5,16,0,0
11,11,11,1,13,0,0,0
1,1,1,0,0,0,0,0
1,1,0,0,0,0,0,1
endlayer

layer
1,0,0,0,0,0,0,1
0,0,0,0,0,0,0,0
0,0,0,0,17,0,0,0
0,0,0,2,5,16,0,0
0,0,6,2,5,16,0,0
0,7,10,3,13,0,0,0
7,7,11,1,1,0,0,0
1,11,1,1,0,0,0,1
endlayer

layer
1,0,0,0,0,0,0,1
0,0,0,0,0,0,0,0
0,0,0,0,17,0,0,0
0,0,0,2,5,16,0,0
0,0,0,8,5,16,0,0
0,0,0,10,3,1,1,0
0,0,0,10,11,1,1,1
1,0,7,11,1,1,1,1
endlayer

layer
1,0,0,0,0,0,0,1
0,0,0,0,0,0,0,0
0,0,0,0,17,0,0,0
0,0,0,2,5,16,0,0
0,0,0,8,5,16,1,1
0,0,0,0,10,3,11,1
0,0,0,0,7,2,11,1
1,0,0,0,7,10,11,1
endlayer

layer
1,0,0,0,0,0,0,1
0,0,0,0,0,0,0,0
0,0,0,0,17,0,0,0
0,0,0,2,5,16,1,1
0,0,0,8,5,16,9,11
0,0,0,0,13,10,12,2
0,0,0,0,0,0,7,7
1,0,0,0,0,0,0,1
endlayer

layer
1,0,0,0,0,0,0,1
0,0,0,0,0,0,1,1
0,0,0,0,17,1,1,1
0,0,0,2,5,16,9,11
0,0,0,2,5,16,12,7
0,0,0,0,13,0,0,0
0,0,0,0,0,0,0,0
1,0,0,0,0,0,0,1
endlayer

layer
1,0,0,0,0,1,1,1
0,0,0,0,1,1,2,12
0,0,0,0,17,8,14,7
0,0,0,8,5,16,12,0
0,0,0,8,5,16,0,0
0,0,0,0,13,0,0,0
0,0,0,0,0,0,0,0
1,0,0,0,0,0,0,1
endlayer

layer
1,0,1,1,1,11,7,1
0,0,0,1,11,14,0,0
0,0,0,1,8,14,0,0
0,0,0,2,5,16,0,0
0,0,0,2,5,16,0,0
0,0,0,0,13,0,0,0
0,0,0,0,0,0,0,0
1,0,0,0,0,0,0,1
endlayer

layer
1,1,11,14,7,0,0,1
1,1,1,8,7,0,0,0
1,1,1,8,14,0,0,0
0,1,1,2,5,16,0,0
0,0,0,8,5,16,0,0
0,0,0,0,13,0,0,0
0,0,0,0,0,0,0,0
1,0,0,0,0,0,0,1
endlayer

layer
1,7,0,0,0,0,0,1
7,7,7,0,0,0,0,0
11,2,6,14,17,0,0,0
1,11,11,2,5,16,0,0
1,1,1,2,5,16,0,0
1,1,1,0,13,0,0,0
0,0,0,0,0,0,0,0
1,0,0,0,0,0,0,1
endlayer

layer
1,0,0,0,0,0,0,1
0,0,0,0,0,0,0,0
0,0,0,0,17,0,0,0
7,7,6,2,5,16,0,0
6,2,2,2,5,16,0,0
11,11,11,1,13,0,0,0
1,1,1,0,0,0,0,0
1,1,0,0,0,0,0,1
endlayer

layer
1,0,0,0,0,0,0,1
0,0,0,0,0,0,0,0
0,0,0,0,17,0,0,0
0,0,0,2,5,16,0,0
0,0,6,8,5,16,0,0
0,7,10,3,13,0,0,0
7,7,11,1,1,0,0,0
1,11,1,1,0,0,0,1
endlayer

layer
1,0,0,0,0,0,0,1
0,0,0,0,0,0,0,0
0,0,0,0,17,0,0,0
0,0,0,8,5,16,0,0
0,0,0,8,5,16,0,0
0,0,0,10,3,1,1,0
0,0,0,10,11,1,1,1
1,0,7,11,1,1,1,1
endlayer

layer
1,0,0,0,0,0,0,1
0,0,0,0,0,0,0,0
0,0,0,0,17,0,0,0
0,0,0,2,5,16,0,0
0,0,0,2,5,16,1,1
0,0,0,0,10,3,11,1
0,0,0,0,7,2,11,1
1,0,0,0,7,10,11,1
endlayer

layer
1,0,0,0,0,0,0,1
0,0,0,0,0,0,0,0
0,0,0,0,17,0,0,0
0,0,0,2,5,16,1,1
0,0,0,2,5,16,9,11
0,0,0,0,13,10,12,2
0,0,0,0,0,0,7,7
1,0,0,0,0,0,0,1
endlayer

layer
1,0,0,0,0,0,0,1
0,0,0,0,0,0,1,1
0,0,0,0,17,1,1,1
0,0,0,2,5,16,9,11
0,0,0,2,5,16,12,7
0,0,0,0,13,0,0,0
0,0,0,0,0,0,0,0
1,0,0,0,0,0,0,1
endlayer

layer
1,0,0,0,0,1,1,1
0,0,0,0,1,1,2,12
0,0,0,0,17,8,14,7
0,0,0,2,5,16,12,0
0,0,0,8,5,16,0,0
0,0,0,0,13,0,0,0
0,0,0,0,0,0,0,0
1,0,0,0,0,0,0,1
endlayer

layer
1,0,1,1,1,11,7,1
0,0,0,1,11,14,0,0
0,0,0,1,8,14,0,0
0,0,0,2,5,16,0,0
0,0,0,2,5,16,0,0
0,0,0,0,13,0,0,0
0,0,0,0,0,0,0,0
1,0,0,0,0,0,0,1
endlayer

layer
1,1,11,14,7,0,0,1
1,1,1,8,7,0,0,0
1,1,1,8,14,0,0,0
0,1,1,2,5,16,0,0
0,0,0,8,5,16,0,0
0,0,0,0,13,0,0,0
0,0,0,0,0,0,0,0
1,0,0,0,0,0,0,1
endlayer

layer
1,7,0,0,0,0,0,1
7,7,7,0,0,0,0,0
11,2,6,14,17,0,0,0
1,11,11,2,5,16,0,0
1,1,1,8,5,16,0,0
1,1,1,0,13,0,0,0
0,0,0,0,0,0,0,0
1,0,0,0,0,0,0,1
endlayer

layer
1,0,0,0,0,0,0,1
0,0,0,0,0,0,0,0
0,0,0,0,17,0,0,0
7,7,6,2,5,16,0,0
6,2,2,8,5,16,0,0
11,11,11,1,13,0,0,0
1,1,1,0,0,0,0,0
1,1,0,0,0,0,0,1
endlayer

layer
1,0,0,0,0,0,0,1
0,0,0,0,0,0,0,0
0,0,0,0,17,0,0,0
0,0,0,2,5,16,0,0
0,0,6,2,5,16,0,0
0,7,10,3,13,0,0,0
7,7,11,1,1,0,0,0
1,11,1,1,0,0,0,1
endlayer

layer
1,0,0,0,0,0,0,1
0,0,0,0,0,0,0,0
0,0,0,0,17,0,0,0
0,0,0,2,5,16,0,0
0,0,0,8,5,16,0,0
0,0,0,10,3,1,1,0
0,0,0,10,11,1,1,1
1,0,7,11,1,1,1,1
endlayer

layer
1,0,0,0,0,0,0,1
0,0,0,0,0,0,0,0
0,0,0,0,17,0,0,0
0,0,0,2,5,16,0,0
0,0,0,8,5,16,1,1
0,0,0,0,10,3,11,1
0,0,0,0,7,2,11,1
1,0,0,0,7,10,11,1
endlayer

layer
1,0,0,0,0,0,0,1
0,0,0,0,0,0,0,0
0,0,0,0,17,0,0,0
0,0,0,2,5,16,1,1
0,0,0,8,5,16,9,11
0,0,0,0,13,10,12,2
0,0,0,0,0,0,7,7
1,0,0,0,0,0,0,1
endlayer

layer
1,0,0,0,0,0,0,1
0,0,0,0,0,0,1,1
0,0,0,0,17,1,1,1
0,0,0,2,5,16,9,11
0,0,0,2,5,16,12,7
0,0,0,0,13,0,0,0
0,0,0,0,0,0,0,0
1,0,0,0,0,0,0,1
endlayer

layer
1,0,0,0,0,1,1,1
0,0,0,0,1,1,2,12
0,0,0,0,17,8,14,7
0,0,0,8,5,16,12,0
0,0,0,8,5,16,0,0
0,0,0,0,13,0,0,0
0,0,0,0,0,0,0,0
1,0,0,0,0,0,0,1
endlayer

layer
1,0,1,1,1,11,7,1
0,0,0,1,11,14,0,0
0,0,0,1,8,14,0,0
0,0,0,2,5,16,0,0
0,0,0,2,5,16,0,0
0,0,0,0,13,0,0,0
0,0,0,0,0,0,0,0
1,0,0,0,0,0,0,1
endlayer

layer
1,1,11,14,7,0,0,1
1,1,1,8,7,0,0,0
1,1,1,8,14,0,0,0
0,1,1,2,5,16,0,0
0,0,0,8,5,16,0,0
0,0,0,0,13,0,0,0
0,0,0,0,0,0,0,0
1,0,0,0,0,0,0,1
endlayer

layer
1,7,0,0,0,0,0,1
7,7,7,0,0,0,0,0
11,2,6,14,17,0,0,0
1,11,11,2,5,16,0,0
1,1,1,2,5,16,0,0
1,1,1,0,13,0,0,0
0,0,0,0,0,0,0,0
1,0,0,0,0,0,0,1
endlayer

layer
1,0,0,0,0,0,0,1
0,0,0,0,0,0,0,0
0,0,0,0,17,0,0,0
7,7,6,2,5,16,0,0
6,2,2,2,5,16,0,0
11,11,11,1,13,0,0,0
1,1,1,0,0,0,0,0
1,1,0,0,0,0,0,1
endlayer

layer
1,0,0,0,0,0,0,1
0,0,0,0,0,0,0,0
0,0,0,0,17,0,0,0
0,0,0,2,5,16,0,0
0,0,6,8,5,16,0,0
0,7,10,3,13,0,0,0
7,7,11,1,1,0,0,0
1,11,1,1,0,0,0,1
endlayer

layer
1,0,0,0,0,0,0,1
0,0,0,0,0,0,0,0
0,0,0,0,17,0,0,0
0,0,0,8,5,16,0,0
0,0,0,8,5,16,0,0
0,0,0,10,3,1,1,0
0,0,0,10,11,1,1,1
1,0,7,11,1,1,1,1
endlayer

layer
1,0,0,0,0,0,0,1
0,0,0,0,0,0,0,0
0,0,0,0,17,0,0,0
0,0,0,2,5,16,0,0
0,0,0,2,5,16,1,1
0,0,0,0,10,3,11,1
0,0,0,0,7,2,11,1
1,0,0,0,7,10,11,1
endlayer

layer
1,0,0,0,0,0,0,1
0,0,0,0,0,0,0,0
0,0,0,0,17,0,0,0
0,0,0,2,5,16,1,1
0,0,0,2,5,16,9,11
0,0,0,0,13,10,12,2
0,0,0,0,0,0,7,7
1,0,0,0,0,0,0,1
endlayer

layer
1,0,0,0,0,0,0,1
0,0,0,0,0,0,1,1
0,0,0,0,17,1,1,1
0,0,0,2,5,16,9,11
0,0,0,8,5,16,12,7
0,0,0,0,13,0,0,0
0,0,0,0,0,0,0,0
1,0,0,0,0,0,0,1
endlayer

layer
1,0,0,0,0,1,1,1
0,0,0,0,1,1,2,12
0,0,0,0,17,8,14,7
0,0,0,8,5,16,12,0
0,0,0,2,5,16,0,0
0,0,0,0,13,0,0,0
0,0,0,0,0,0,0,0
1,0,0,0,0,0,0,1
endlayer

layer
1,0,1,1,1,11,7,1
0,0,0,1,11,14,0,0
0,0,0,1,8,14,0,0
0,0,0,2,5,16,0,0
0,0,0,2,5,16,0,0
0,0,0,0,13,0,0,0
0,0,0,0,0,0,0,0
1,0,0,0,0,0,0,1
endlayer

layer
1,1,11,14,7,0,0,1
1,1,1,8,7,0,0,0
1,1,1,8,14,0,0,0
0,1,1,2,5,16,0,0
0,0,0,8,5,16,0,0
0,0,0,0,13,0,0,0
0,0,0,0,0,0,0,0
1,0,0,0,0,0,0,1
endlayer

layer
1,7,0,0,0,0,0,1
7,7,7,0,0,0,0,0
11,2,6,14,17,0,0,0
1,11,11,8,5,16,0,0
1,1,1,8,5,16,0,0
1,1,1,0,13,0,0,0
0,0,0,0,0,0,0,0
1,0,0,0,0,0,0,1
endlayer

layer
1,0,0,0,0,0,0,1
0,0,0,0,0,0,0,0
0,0,0,0,17,0,0,0
7,7,6,2,5,16,0,0
6,2,2,8,5,16,0,0
11,11,11,1,13,0,0,0
1,1,1,0,0,0,0,0
1,1,0,0,0,0,0,1
endlayer

layer
1,0,0,0,0,0,0,1
0,0,0,0,0,0,0,0
0,0,0,0,17,0,0,0
0,0,0,2,5,16,0,0
0,0,6,2,5,16,0,0
0,7,10,3,13,0,0,0
7,7,11,1,1,0,0,0
1,11,1,1,0,0,0,1
endlayer

layer
1,0,0,0,0,0,0,1
0,0,0,0,0,0,0,0
0,0,0,0,17,0,0,0
0,0,0,2,5,16,0,0
0,0,0,8,5,16,0,0
0,0,0,10,3,1,1,0
0,0,0,10,11,1,1,1
1,0,7,11,1,1,1,1
endlayer

layer
1,0,0,0,0,0,0,1
0,0,0,0,0,0,0,0
0,0,0,0,17,0,0,0
0,0,0,8,5,16,0,0
0,0,0,2,5,16,1,1
0,0,0,0,10,3,11,1
0,0,0,0,7,2,11,1
1,0,0,0,7,10,11,1
endlayer

layer
1,0,0,0,0,0,0,1
0,0,0,0,0,0,0,0
0,0,0,0,17,0,0,0
0,0,0,2,5,16,1,1
0,0,0,8,5,16,9,11
0,0,0,0,13,10,12,2
0,0,0,0,0,0,7,7
1,0,0,0,0,0,0,1
endlayer

layer
1,0,0,0,0,0,0,1
0,0,0,0,0,0,1,1
0,0,0,0,17,1,1,1
0,0,0,2,5,16,9,11
0,0,0,2,5,16,12,7
0,0,0,0,13,0,0,0
0,0,0,0,0,0,0,0
1,0,0,0,0,0,0,1
endlayer

layer
1,0,0,0,0,1,1,1
0,0,0,0,1,1,2,12
0,0,0,0,17,8,14,7
0,0,0,2,5,16,12,0
0,0,0,8,5,16,0,0
0,0,0,0,13,0,0,0
0,0,0,0,0,0,0,0
1,0,0,0,0,0,0,1
endlayer

layer
1,0,1,1,1,11,7,1
0,0,0,1,11,14,0,0
0,0,0,1,8,14,0,0
0,0,0,2,5,16,0,0
0,0,0,8,5,16,0,0
0,0,0,0,13,0,0,0
0,0,0,0,0,0,0,0
1,0,0,0,0,0,0,1
endlayer

layer
1,1,11,14,7,0,0,1
1,1,1,8,7,0,0,0
1,1,1,8,14,0,0,0
0,1,1,2,5,16,0,0
0,0,0,8,5,16,0,0
0,0,0,0,13,0,0,0
0,0,0,0,0,0,0,0
1,0,0,0,0,0,0,1
endlayer

layer
1,7,0,0,0,0,0,1
7,7,7,0,0,0,0,0
11,2,6,14,17,0,0,0
1,11,11,2,5,16,0,0
1,1,1,2,5,16,0,0
1,1,1,0,13,0,0,0
0,0,0,0,0,0,0,0
1,0,0,0,0,0,0,1
endlayer

layer
1,0,0,0,0,0,0,1
0,0,0,0,0,0,0,0
0,0,0,0,17,0,0,0
7,7,6,2,5,16,0,0
6,2,2,2,5,16,0,0
11,11,11,1,13,0,0,0
1,1,1,0,0,0,0,0
1,1,0,0,0,0,0,1
endlayer

layer
1,0,0,0,0,0,0,1
0,0,0,0,0,0,0,0
0,0,0,0,17,0,0,0
0,0,0,8,5,16,0,0
0,0,6,8,5,16,0,0
0,7,10,3,13,0,0,0
7,7,11,1,1,0,0,0
1,11,1,1,0,0,0,1
endlayer

layer
1,0,0,0,0,0,0,1
0,0,0,0,0,0,0,0
0,0,0,0,17,0,0,0
0,0,0,2,5,16,0,0
0,0,0,8,5,16,0,0
0,0,0,10,3,1,1,0
0,0,0,10,11,1,1,1
1,0,7,11,1,1,1,1
endlayer

layer
1,0,0,0,0,0,0,1
0,0,0,0,0,0,0,0
0,0,0,0,17,0,0,0
0,0,0,2,5,16,0,0
0,0,0,2,5,16,1,1
0,0,0,0,10,3,11,1
0,0,0,0,7,2,11,1
1,0,0,0,7,10,11,1
endlayer

layer
1,0,0,0,0,0,0,1
0,0,0,0,0,0,0,0
0,0,0,0,17,0,0,0
0,0,0,2,5,16,1,1
0,0,0,8,5,16,9,11
0,0,0,0,13,10,12,2
0,0,0,0,0,0,7,7
1,0,0,0,0,0,0,1
endlayer

layer
1,0,0,0,0,0,0,1
0,0,0,0,0,0,1,1
0,0,0,0,17,1,1,1
0,0,0,8,5,16,9,11
0,0,0,8,5,16,12,7
0,0,0,0,13,0,0,0
0,0,0,0,0,0,0,0
1,0,0,0,0,0,0,1
endlayer

layer
1,0,0,0,0,1,1,1
0,0,0,0,1,1,2,12
0,0,0,0,17,8,14,7
0,0,0,8,5,16,12,0
0,0,0,2,5,16,0,0
0,0,0,0,13,0,0,0
0,0,0,0,0,0,0,0
1,0,0,0,0,0,0,1
endlayer

layer
1,0,1,1,1,11,7,1
0,0,0,1,11,14,0,0
0,0,0,1,8,14,0,0
0,0,0,2,5,16,0,0
0,0,0,2,5,16,0,0
0,0,0,0,13,0,0,0
0,0,0,0,0,0,0,0
1,0,0,0,0,0,0,1
endlayer

layer
1,1,11,14,7,0,0,1
1,1,1,8,7,0,0,0
1,1,1,8,14,0,0,0
0,1,1,2,5,16,0,0
0,0,0,8,5,16,0,0
0,0,0,0,13,0,0,0
0,0,0,0,0,0,0,0
1,0,0,0,0,0,0,1
endlayer

layer
1,7,0,0,0,0,0,1
7,7,7,0,0,0,0,0
11,2,6,14,17,0,0,0
1,11,11,8,5,16,0,0
1,1,1,2,5,16,0,0
1,1,1,0,13,0,0,0
0,0,0,0,0,0,0,0
1,0,0,0,0,0,0,1
endlayer

layer
1,0,0,0,0,0,0,1
0,0,0,0,0,0,0,0
0,0,0,0,17,0,0,0
7,7,6,2,5,16,0,0
6,2,2,8,5,16,0,0
11,11,11,1,13,0,0,0
1,1,1,0,0,0,0,0
1,1,0,0,0,0,0,1
endlayer

layer
1,0,0,0,0,0,0,1
0,0,0,0,0,0,0,0
0,0,0,0,17,0,0,0
0,0,0,2,5,16,0,0
0,0,6,2,5,16,0,0
0,7,10,3,13,0,0,0
7,7,11,1,1,0,0,0
1,11,1,1,0,0,0,1
endlayer

layer
1,0,0,0,0,0,0,1
0,0,0,0,0,0,0,0
0,0,0,0,17,0,0,0
0,0,0,2,5,16,0,0
0,0,0,8,5,16,0,0
0,0,0,10,3,1,1,0
0,0,0,10,11,1,1,1
1,0,7,11,1,1,1,1
endlayer

layer
1,0,0,0,0,0,0,1
0,0,0,0,0,0,0,0
0,0,0,0,17,0,0,0
0,0,0,2,5,16,0,0
0,0,0,2,5,16,1,1
0,0,0,0,10,3,11,1
0,0,0,0,7,2,11,1
1,0,0,0,7,10,11,1
endlayer

layer
1,0,0,0,0,0,0,1
0,0,0,0,0,0,0,0
0,0,0,0,17,0,0,0
0,0,0,8,5,16,1,1
0,0,0,8,5,16,9,11
0,0,0,0,13,10,12,2
0,0,0,0,0,0,7,7
1,0,0,0,0,0,0,1
endlayer

layer
1,0,0,0,0,0,0,1
0,0,0,0,0,0,1,1
0,0,0,0,17,1,1,1
0,0,0,2,5,16,9,11
0,0,0,2,5,16,12,7
0,0,0,0,13,0,0,0
0,0,0,0,0,0,0,0
1,0,0,0,0,0,0,1
endlayer

layer
1,0,0,0,0,1,1,1
0,0,0,0,1,1,2,12
0,0,0,0,17,8,14,7
0,0,0,8,5,16,12,0
0,0,0,8,5,16,0,0
0,0,0,0,13,0,0,0
0,0,0,0,0,0,0,0
1,0,0,0,0,0,0,1
endlayer

layer
1,0,1,1,1,11,7,1
0,0,0,1,11,14,0,0
0,0,0,1,8,14,0,0
0,0,0,8,5,16,0,0
0,0,0,2,5,16,0,0
0,0,0,0,13,0,0,0
0,0,0,0,0,0,0,0
1,0,0,0,0,0,0,1
endlayer

layer
1,1,11,14,7,0,0,1
1,1,1,8,7,0,0,0
1,1,1,8,14,0,0,0
0,1,1,8,5,16,0,0
0,0,0,8,5,16,0,0
0,0,0,0,13,0,0,0
0,0,0,0,0,0,0,0
1,0,0,0,0,0,0,1
endlayer

layer
1,7,0,0,0,0,0,1
7,7,7,0,0,0,0,0
11,2,6,14,17,0,0,0
1,11,11,2,5,16,0,0
1,1,1,2,5,16,0,0
1,1,1,0,13,0,0,0
0,0,0,0,0,0,0,0
1,0,0,0,0,0,0,1
endlayer

layer
1,0,0,0,0,0,0,1
0,0,0,0,0,0,0,0
0,0,0,0,17,0,0,0
7,7,6,2,5,16,0,0
6,2,2,8,5,16,0,0
11,11,11,1,13,0,0,0
1,1,1,0,0,0,0,0
1,1,0,0,0,0,0,1
endlayer

layer
1,0,0,0,0,0,0,1
0,0,0,0,0,0,0,0
0,0,0,0,17,0,0,0
0,0,0,2,5,16,0,0
0,0,6,8,5,16,0,0
0,7,10,3,13,0,0,0
7,7,11,1,1,0,0,0
1,11,1,1,0,0,0,1
endlayer

layer
1,0,0,0,0,0,0,1
0,0,0,0,0,0,0,0
0,0,0,0,17,0,0,0
0,0,0,2,5,16,0,0
0,0,0,8,5,16,0,0
0,0,0,10,3,1,1,0
0,0,0,10,11,1,1,1
1,0,7,11,1,1,1,1
endlayer

layer
1,0,0,0,0,0,0,1
0,0,0,0,0,0,0,0
0,0,0,0,17,0,0,0
0,0,0,2,5,16,0,0
0,0,0,2,5,16,1,1
0,0,0,0,10,3,11,1
0,0,0,0,7,2,11,1
1,0,0,0,7,10,11,2
endlayer

layer
1,0,0,0,0,0,0,1
0,0,0,0,0,0,0,0
0,0,0,0,17,0,0,0
0,0,0,2,5,16,1,1
0,0,0,8,5,16,9,11
0,0,0,0,13,10,12,2
0,0,0,0,0,0,7,7
1,0,0,0,0,0,0,2
endlayer

layer
1,0,0,0,0,0,0,1
0,0,0,0,0,0,1,1
0,0,0,0,17,1,1,1
0,0,0,2,5,16,9,11
0,0,0,8,5,16,12,7
0,0,0,0,13,0,0,0
0,0,0,0,0,0,0,0
1,0,0,0,0,0,0,2
endlayer

layer
1,0,0,0,0,1,1,2
0,0,0,0,1,1,2,12
0,0,0,0,17,8,14,7
0,0,0,2,5,16,12,0
0,0,0,8,5,16,0,0
0,0,0,0,13,0,0,0
0,0,0,0,0,0,0,0
1,0,0,0,0,0,0,2
endlayer

layer
1,0,1,1,1,11,7,2
0,0,0,1,11,14,0,0
0,0,0,0,8,14,0,0
0,0,0,2,5,16,0,0
0,0,0,2,5,16,0,0
0,0,0,0,13,0,0,0
0,0,0,0,0,0,0,0
1,0,0,0,0,0,0,2
endlayer

layer
1,1,11,14,7,0,0,2
1,1,1,8,7,0,0,0
1,1,1,8,14,0,0,0
1,1,1,2,5,16,0,0
0,1,1,2,5,16,0,0
0,0,0,0,13,0,0,0
0,0,0,0,0,0,0,0
1,0,0,0,0,0,0,2
endlayer

layer
2,7,0,0,0,0,0,2
7,7,7,0,0,0,0,0
11,2,6,14,17,0,0,0
1,11,11,2,5,16,0,0
1,1,1,8,5,16,0,0
1,1,1,0,13,0,0,0
1,1,1,0,0,0,0,0
1,1,0,0,0,0,0,2
endlayer

layer
2,0,0,0,0,0,0,2
0,0,0,0,0,0,0,0
0,0,0,0,17,0,0,0
7,7,6,8,5,16,0,0
6,2,2,2,5,16,0,0
2,2,2,1,13,0,0,0
1,1,1,1,0,0,0,0
1,1,1,1,1,0,0,2
endlayer

layer
2,0,0,0,0,0,0,2
0,0,0,0,0,0,0,0
0,0,0,0,17,0,0,0
0,0,0,2,5,16,0,0
0,0,6,2,5,16,0,0
0,7,10,3,13,0,0,0
7,7,2,2,2,11,11,0
2,2,2,2,2,2,2,2
endlayer

layer
2,0,0,0,0,0,0,2
0,0,0,0,0,0,0,0
0,0,0,0,17,0,0,0
0,0,0,2,5,16,0,0
0,0,0,2,5,16,0,0
0,0,0,10,2,11,11,11
0,0,0,10,2,2,2,2
2,0,7,2,2,2,2,2
endlayer

layer
2,0,0,0,0,11,2,2
0,0,0,0,0,11,2,2
0,0,0,0,17,11,2,2
0,0,0,8,5,16,8,2
0,0,0,8,5,16,8,2
0,0,0,0,10,9,2,2
0,0,0,0,7,2,2,2
2,0,0,0,7,10,2,2
endlayer

layer
2,11,11,2,2,2,2,2
0,0,11,11,2,2,2,2
0,0,0,11,17,15,2,2
0,0,0,8,5,16,8,2
0,0,0,8,5,16,8,2
0,0,0,0,13,10,12,2
0,0,0,0,0,0,7,7
2,0,0,0,0,0,0,2
endlayer

layer
2,2,2,2,2,2,2,2
2,2,2,2,2,2,2,2
2,2,2,2,2,15,2,2
11,11,11,2,5,16,2,2
11,11,11,2,5,16,7,7
0,0,0,0,13,0,0,0
0,0,0,0,0,0,0,0
2,0,0,0,0,0,0,2
endlayer

layer
0,0,0,0,0,0,0,0
0,0,0,0,0,0,0,0
0,0,0,0,0,0,0,0
0,0,0,0,0,16,0,0
0,0,0,0,0,16,0,0
0,0,0,0,0,0,0,0
0,0,0,0,0,0,0,0
0,0,0,0,0,0,0,0
endlayer

