
# Created by Ruins mod version 17.1 Ingame Parser
# authoring Player: ST753M

weight=1
embed_into_distance=7
acceptable_target_blocks=
unacceptable_target_blocks=flowing_water,water,flowing_lava,lava,ice,bedrock,netherrack,nether_brick,nether_brick_fence,soul_sand,quartz_ore,end_stone,obsidian,iron_bars,Natura:Cloud,slime_grass,slime_congealed,slime_dirt,clouds,natura:clouds,twilightforest:wispy_cloud,twilightforest:fluffy_cloud,abyssalcraft:cwater,cwater
dimensions=14,16,16
allowable_overhang=7
max_leveling=0
leveling_buffer=0
preserve_water=0
preserve_lava=0

biomesToSpawnIn=tropical_rainforest

=0,100,air
rule1=0,100,preserveBlock
rule2=0,100,biomesoplenty:log_3-5
rule3=0,100,minecraft:sandstone-0
rule4=0,100,biomesoplenty:log_3-9
rule5=0,100,biomesoplenty:log_3-1
rule6=0,100,biomesoplenty:planks_0-13
rule7=0,100,biomesoplenty:mahogany_stairs-1
rule8=0,100,biomesoplenty:mahogany_fence-0
rule9=0,100,biomesoplenty:mahogany_stairs-0
rule10=0,100,teBlock;minecraft:bed;{color:6,x:-1097,y:94,z:804,id:"minecraft:bed"}-10
rule11=0,100,teBlock;minecraft:bed;{color:6,x:-1097,y:94,z:805,id:"minecraft:bed"}-2
rule12=0,100,biomesoplenty:mahogany_stairs-2
rule13=0,100,minecraft:pink_glazed_terracotta-3
rule14=0,100,minecraft:pink_glazed_terracotta-2
rule15=0,100,biomesoplenty:mahogany_stairs-3
rule16=0,100,teBlock;minecraft:bed;{color:6,x:-1096,y:94,z:804,id:"minecraft:bed"}-10
rule17=0,100,teBlock;minecraft:bed;{color:6,x:-1096,y:94,z:805,id:"minecraft:bed"}-2
rule18=0,100,minecraft:pink_glazed_terracotta-0
rule19=0,100,minecraft:pink_glazed_terracotta-1

rule20=0,100,ChestGenHook:chests/jungle_temple:1-4,ChestGenHook:chests/jungle_temple:2-4,ChestGenHook:chests/jungle_temple:3-4,ChestGenHook:chests/jungle_temple:4-4,ChestGenHook:chests/spawn_bonus_chest:5-4,ChestGenHook:chests/spawn_bonus_chest:5-4,air,air,air

rule21=0,100,minecraft:anvil-8,minecraft:ender_chest-4,minecraft:jukebox-0,minecraft:lit_pumpkin-1,minecraft:pumpkin-1,minecraft:bookshelf-0,minecraft:trapped_chest-4,minecraft:crafting_table-0,biomesoplenty:mahogany_stairs-4,biomesoplenty:log_3-5,biomesoplenty:wood_slab_1-13,biomesoplenty:planks_0-13,minecraft:cauldron-0,minecraft:brewing_stand-0,minecraft:iron_trapdoor-8,minecraft:trapdoor-8,air,air,air,air,air,air,air,air,air,air,air,air
rule22=0,100,biomesoplenty:mahogany_stairs-6
rule23=0,100,minecraft:carpet-6
rule24=0,100,biomesoplenty:mahogany_stairs-5
rule25=0,100,minecraft:furnace-2
rule26=0,100,biomesoplenty:wood_slab_1-5
rule27=0,100,biomesoplenty:wood_slab_1-13
rule28=0,100,biomesoplenty:mahogany_stairs-7
rule29=0,100,biomesoplenty:mahogany_stairs-4
rule30=0,100,minecraft:stained_glass-6

layer
1,1,1,1,1,1,1,1,1,1,1,1,1,1,1,1
1,1,1,1,1,1,2,2,2,2,1,1,1,1,1,1
1,1,1,1,2,2,3,3,3,3,2,2,1,1,1,1
1,1,1,2,3,3,3,3,3,3,3,3,2,1,1,1
1,1,2,3,3,3,5,4,5,4,3,3,3,2,1,1
1,1,2,3,3,5,4,5,4,5,4,3,3,2,1,1
1,2,3,3,5,4,5,4,5,4,5,4,3,3,2,1
1,2,3,3,4,5,4,5,4,5,4,5,3,3,2,1
1,2,3,3,5,4,5,4,5,4,5,4,3,3,2,1
1,2,3,3,4,5,4,5,4,5,4,5,3,3,2,1
1,1,2,3,3,4,5,4,5,4,5,3,3,2,1,1
1,1,2,3,3,3,4,5,4,5,3,3,3,2,1,1
1,1,1,2,3,3,3,3,3,3,3,3,2,1,1,1
1,1,1,1,2,2,3,3,3,3,2,2,1,1,1,1
1,1,1,1,1,1,2,2,2,2,1,1,1,1,1,1
1,1,1,1,1,1,1,1,1,1,1,1,1,1,1,1
endlayer

layer
1,1,1,1,1,1,1,1,1,1,1,1,1,1,1,1
1,1,1,1,1,1,2,2,2,2,1,1,1,1,1,1
1,1,1,1,2,2,6,0,0,0,2,2,1,1,1,1
1,1,1,2,0,0,7,0,0,0,0,0,2,1,1,1
1,1,2,0,0,0,0,0,0,0,0,0,0,2,1,1
1,1,2,0,0,0,0,0,0,0,0,0,0,2,1,1
1,2,8,0,0,0,9,9,9,9,0,0,0,8,2,1
1,2,8,0,0,0,15,14,13,12,0,0,11,10,2,1
1,2,8,0,0,0,15,19,18,12,0,0,17,16,2,1
1,2,8,0,0,0,7,7,7,12,0,0,0,8,2,1
1,1,2,0,0,0,0,0,0,0,0,0,0,2,1,1
1,1,2,0,0,0,0,0,0,0,0,0,0,2,1,1
1,1,1,2,20,0,0,0,0,0,0,20,2,1,1,1
1,1,1,1,2,2,21,21,21,21,2,2,1,1,1,1
1,1,1,1,1,1,2,2,2,2,1,1,1,1,1,1
1,1,1,1,1,1,1,1,1,1,1,1,1,1,1,1
endlayer

layer
1,1,1,1,1,1,1,1,1,1,1,1,1,1,1,1
1,1,1,1,1,1,2,2,2,2,1,1,1,1,1,1
1,1,1,1,6,2,7,22,0,0,2,6,1,1,1,1
1,1,1,2,0,0,0,0,0,0,0,0,2,1,1,1
1,1,6,0,0,0,0,0,0,0,0,0,0,6,1,1
1,1,6,0,0,0,0,0,0,0,0,0,0,6,1,1
1,2,23,0,0,0,0,0,0,0,0,0,0,23,2,1
1,6,23,0,0,0,0,0,0,0,0,0,0,0,6,1
1,6,23,0,0,0,0,0,0,0,0,0,0,0,6,1
1,2,23,0,0,0,0,0,0,0,0,0,0,23,2,1
1,1,6,0,0,0,0,0,0,0,0,0,0,6,1,1
1,1,6,0,0,0,0,0,0,0,0,0,0,6,1,1
1,1,1,2,0,0,0,0,0,0,0,0,2,1,1,1
1,1,1,1,6,6,0,0,0,0,6,6,1,1,1,1
1,1,1,1,1,1,2,6,6,2,1,1,1,1,1,1
1,1,1,1,1,1,1,1,1,1,1,1,1,1,1,1
endlayer

layer
1,1,1,1,1,1,1,1,1,1,1,1,1,1,1,1
1,1,1,1,1,1,2,2,2,2,1,1,1,1,1,1
1,1,1,1,6,2,0,15,22,0,2,6,1,1,1,1
1,1,1,2,0,0,0,0,0,0,0,0,2,1,1,1
1,1,6,0,0,0,0,0,0,0,0,0,0,6,1,1
1,1,6,0,0,0,0,0,0,0,0,0,0,6,1,1
1,2,0,0,0,0,0,0,0,0,0,0,0,0,2,1
1,6,0,0,0,0,0,0,0,0,0,0,0,0,6,1
1,6,0,0,0,0,0,0,0,0,0,0,0,0,6,1
1,2,0,0,0,0,0,0,0,0,0,0,0,0,2,1
1,1,6,0,0,0,0,0,0,0,0,0,0,6,1,1
1,1,6,0,0,0,0,0,0,0,0,0,0,6,1,1
1,1,1,2,0,0,0,0,0,0,0,0,2,1,1,1
1,1,1,1,6,6,0,0,0,0,6,6,1,1,1,1
1,1,1,1,1,1,2,6,6,2,1,1,1,1,1,1
1,1,1,1,1,1,1,1,1,1,1,1,1,1,1,1
endlayer

layer
1,1,1,1,1,1,1,1,1,1,1,1,1,1,1,1
1,1,1,1,1,1,2,2,2,2,1,1,1,1,1,1
1,1,1,1,6,2,0,0,15,22,2,6,1,1,1,1
1,1,1,2,0,0,0,0,0,0,0,0,2,1,1,1
1,1,6,0,0,0,0,0,0,0,0,0,0,6,1,1
1,1,6,0,0,0,0,0,0,0,0,0,0,6,1,1
1,2,0,0,0,0,0,0,0,0,0,0,0,0,2,1
1,6,0,0,0,0,0,0,0,0,0,0,0,0,6,1
1,6,0,0,0,0,0,0,0,0,0,0,0,0,6,1
1,2,0,0,0,0,0,0,0,0,0,0,0,0,2,1
1,1,6,0,0,0,0,0,0,0,0,0,0,6,1,1
1,1,6,0,0,0,0,0,0,0,0,0,0,6,1,1
1,1,1,2,0,0,0,0,0,0,0,0,2,1,1,1
1,1,1,1,6,6,0,0,0,0,6,6,1,1,1,1
1,1,1,1,1,1,2,6,6,2,1,1,1,1,1,1
1,1,1,1,1,1,1,1,1,1,1,1,1,1,1,1
endlayer

layer
1,1,1,1,1,1,1,1,1,1,1,1,1,1,1,1
1,1,1,1,1,1,2,2,2,2,1,1,1,1,1,1
1,1,1,1,2,2,0,0,0,15,2,2,1,1,1,1
1,1,1,2,0,0,0,0,0,24,0,0,2,1,1,1
1,1,2,0,0,0,0,0,0,0,0,0,0,2,1,1
1,1,2,0,0,0,0,0,0,0,0,0,0,2,1,1
1,2,0,0,0,0,0,0,0,0,0,0,0,0,2,1
1,2,0,0,0,0,0,0,0,0,0,0,0,0,2,1
1,2,0,0,0,0,0,0,0,0,0,0,0,0,2,1
1,2,0,0,0,0,0,0,0,0,0,0,0,0,2,1
1,1,2,0,0,0,0,0,0,0,0,0,0,2,1,1
1,1,2,0,0,0,0,0,0,0,0,0,0,2,1,1
1,1,1,2,0,0,0,0,0,0,0,0,2,1,1,1
1,1,1,1,2,2,0,0,0,0,2,2,1,1,1,1
1,1,1,1,1,1,2,2,2,2,1,1,1,1,1,1
1,1,1,1,1,1,1,1,1,1,1,1,1,1,1,1
endlayer

layer
1,1,1,1,1,1,1,1,1,1,1,1,1,1,1,1
1,1,1,1,1,1,2,2,2,2,1,1,1,1,1,1
1,1,1,1,2,2,0,0,0,0,2,2,1,1,1,1
1,1,1,2,3,3,3,3,3,9,3,3,2,1,1,1
1,1,2,3,3,3,3,3,3,3,3,3,3,2,1,1
1,1,2,3,3,3,3,3,3,3,3,3,3,2,1,1
1,2,3,3,3,3,3,3,3,3,3,3,3,3,2,1
1,4,3,3,3,3,3,3,3,3,3,3,3,3,4,1
1,4,3,3,3,3,3,3,3,3,3,3,3,3,4,1
1,2,3,3,3,3,3,3,3,3,3,3,3,3,2,1
1,1,2,3,3,3,3,3,3,3,3,3,3,2,1,1
1,1,2,3,3,3,3,3,3,3,3,3,3,2,1,1
1,1,1,2,3,3,3,3,3,3,3,3,2,1,1,1
1,1,1,1,2,2,3,3,3,3,2,2,1,1,1,1
1,1,1,1,1,1,2,5,5,2,1,1,1,1,1,1
1,1,1,1,1,1,1,1,1,1,1,1,1,1,1,1
endlayer

layer
1,1,1,1,1,1,1,1,1,1,1,1,1,1,1,1
1,1,1,1,1,1,2,2,2,2,1,1,1,1,1,1
1,1,1,1,2,2,0,0,0,0,2,2,1,1,1,1
1,1,1,2,0,8,8,8,8,0,8,0,2,1,1,1
1,1,2,0,0,0,0,0,0,0,0,0,0,2,1,1
1,1,2,0,0,0,0,0,0,0,0,0,0,2,1,1
1,2,8,0,0,0,7,0,7,0,7,0,0,0,2,1
1,2,25,0,0,0,8,8,8,8,8,0,0,0,0,1
1,2,25,0,0,0,8,8,8,8,8,0,0,0,0,1
1,2,8,0,0,0,9,0,9,0,9,0,0,0,2,1
1,1,2,0,0,0,0,0,0,0,0,0,0,2,1,1
1,1,2,0,0,0,0,0,0,0,0,0,0,2,1,1
1,1,1,2,0,0,0,0,0,0,0,0,2,1,1,1
1,1,1,1,2,2,21,21,21,21,2,2,1,1,1,1
1,1,1,1,1,1,2,2,2,2,1,1,1,1,1,1
1,1,1,1,1,1,1,1,1,1,1,1,1,1,1,1
endlayer

layer
1,1,1,1,1,1,1,1,1,1,1,1,1,1,1,1
1,1,1,1,1,1,2,26,26,2,1,1,1,1,1,1
1,1,1,1,26,26,0,0,0,0,26,26,1,1,1,1
1,1,1,2,0,0,0,0,0,0,0,0,2,1,1,1
1,1,26,0,0,0,0,0,0,0,0,0,0,26,1,1
1,1,26,0,0,0,0,0,0,0,0,0,0,26,1,1
1,2,23,0,0,0,0,0,0,0,0,0,0,0,2,1
1,26,0,0,0,0,23,23,23,23,23,0,0,0,0,1
1,26,0,0,0,0,23,23,23,23,23,0,0,0,0,1
1,2,23,0,0,0,0,0,0,0,0,0,0,0,2,1
1,1,26,0,0,0,0,0,0,0,0,0,0,26,1,1
1,1,26,0,0,0,0,0,0,0,0,0,0,26,1,1
1,1,1,2,0,0,0,0,0,0,0,0,2,1,1,1
1,1,1,1,26,26,0,0,0,0,26,26,1,1,1,1
1,1,1,1,1,1,2,26,26,2,1,1,1,1,1,1
1,1,1,1,1,1,1,1,1,1,1,1,1,1,1,1
endlayer

layer
1,1,1,1,1,1,1,1,1,1,1,1,1,1,1,1
1,1,1,1,1,1,2,0,0,2,1,1,1,1,1,1
1,1,1,1,0,0,0,0,0,0,0,0,1,1,1,1
1,1,1,2,0,0,0,0,0,0,0,0,2,1,1,1
1,1,0,0,0,0,0,0,0,0,0,0,0,0,1,1
1,1,0,0,0,0,0,0,0,0,0,0,0,0,1,1
1,2,0,0,0,0,0,0,0,0,0,0,0,0,2,1
1,0,0,0,0,0,0,0,0,0,0,0,0,0,26,1
1,0,0,0,0,0,0,0,0,0,0,0,0,0,26,1
1,2,0,0,0,0,0,0,0,0,0,0,0,0,2,1
1,1,0,0,0,0,0,0,0,0,0,0,0,0,1,1
1,1,0,0,0,0,0,0,0,0,0,0,0,0,1,1
1,1,1,2,0,0,0,0,0,0,0,0,2,1,1,1
1,1,1,1,0,0,0,0,0,0,0,0,1,1,1,1
1,1,1,1,1,1,2,0,0,2,1,1,1,1,1,1
1,1,1,1,1,1,1,1,1,1,1,1,1,1,1,1
endlayer

layer
1,1,1,1,1,1,1,1,1,1,1,1,1,1,1,1
1,1,1,1,1,1,2,27,27,2,1,1,1,1,1,1
1,1,1,1,27,27,0,0,0,0,27,27,1,1,1,1
1,1,1,2,0,0,0,0,0,0,0,0,2,1,1,1
1,1,27,0,0,0,0,0,0,0,0,0,0,27,1,1
1,1,27,0,0,0,0,0,0,0,0,0,0,27,1,1
1,2,0,0,0,0,0,0,0,0,0,0,0,0,2,1
1,27,0,0,0,0,0,0,0,0,0,0,0,0,27,1
1,27,0,0,0,0,0,0,0,0,0,0,0,0,27,1
1,2,0,0,0,0,0,0,0,0,0,0,0,0,2,1
1,1,27,0,0,0,0,0,0,0,0,0,0,27,1,1
1,1,27,0,0,0,0,0,0,0,0,0,0,27,1,1
1,1,1,2,0,0,0,0,0,0,0,0,2,1,1,1
1,1,1,1,27,27,0,0,0,0,27,27,1,1,1,1
1,1,1,1,1,1,2,27,27,2,1,1,1,1,1,1
1,1,1,1,1,1,1,1,1,1,1,1,1,1,1,1
endlayer

layer
1,1,1,1,1,1,1,1,1,1,1,1,1,1,1,1
1,1,1,1,1,1,2,2,2,2,1,1,1,1,1,1
1,1,1,1,2,2,0,0,0,0,2,2,1,1,1,1
1,1,1,2,0,0,0,0,0,0,0,0,2,1,1,1
1,1,2,0,0,0,0,0,0,0,0,0,0,2,1,1
1,1,2,0,0,0,0,0,0,0,0,0,0,2,1,1
1,2,0,0,0,0,0,0,0,0,0,0,0,0,2,1
1,2,0,0,0,0,0,0,0,0,0,0,0,0,2,1
1,2,0,0,0,0,0,0,0,0,0,0,0,0,2,1
1,2,0,0,0,0,0,0,0,0,0,0,0,0,2,1
1,1,2,0,0,0,0,0,0,0,0,0,0,2,1,1
1,1,2,0,0,0,0,0,0,0,0,0,0,2,1,1
1,1,1,2,0,0,0,0,0,0,0,0,2,1,1,1
1,1,1,1,2,2,0,0,0,0,2,2,1,1,1,1
1,1,1,1,1,1,2,2,2,2,1,1,1,1,1,1
1,1,1,1,1,1,1,1,1,1,1,1,1,1,1,1
endlayer

layer
1,1,1,1,1,9,9,9,9,9,9,1,1,1,1,1
1,1,1,9,9,15,2,2,2,2,12,9,9,1,1,1
1,1,9,15,2,2,3,3,3,3,2,2,12,9,1,1
1,9,15,2,3,3,3,6,6,3,3,3,2,12,9,1
1,15,2,3,24,24,24,28,22,24,24,28,3,2,12,1
9,15,2,3,22,0,0,24,24,0,0,28,3,2,12,9
15,2,3,3,22,0,0,0,0,0,0,28,3,3,2,12
15,2,3,6,29,22,0,0,0,0,28,29,6,3,2,12
15,2,3,6,24,22,0,0,0,0,28,24,6,3,2,12
15,2,3,3,22,0,0,0,0,0,0,28,3,3,2,12
15,7,2,3,22,0,0,29,29,0,0,28,3,2,12,7
1,15,2,3,22,29,29,28,22,29,29,29,3,2,12,1
1,15,7,2,3,3,3,6,6,3,3,3,2,12,7,1
1,1,15,7,2,2,3,3,3,3,2,2,12,7,1,1
1,1,1,15,7,7,2,2,2,2,12,7,7,1,1,1
1,1,1,1,1,15,7,7,7,7,7,1,1,1,1,1
endlayer

layer
1,1,1,1,1,1,1,1,1,1,1,1,1,1,1,1
1,1,1,1,1,1,9,9,9,12,1,1,1,1,1,1
1,1,1,1,9,9,15,6,6,9,9,12,1,1,1,1
1,1,1,9,15,6,26,7,15,26,6,9,12,1,1,1
1,1,9,15,26,6,6,12,9,6,6,26,9,12,1,1
1,1,15,6,6,30,30,6,6,30,30,6,6,12,1,1
1,9,15,26,6,30,30,30,30,30,30,6,26,9,12,1
1,15,6,7,15,6,30,30,30,30,6,7,15,6,12,1
1,15,6,12,9,6,30,30,30,30,6,12,9,6,12,1
1,7,15,26,6,30,30,30,30,30,30,6,26,12,7,1
1,1,15,6,6,30,30,6,6,30,30,6,6,12,1,1
1,1,7,15,26,6,6,7,15,6,6,26,12,7,1,1
1,1,1,7,15,6,26,12,9,26,6,12,7,1,1,1
1,1,1,1,7,7,15,6,6,12,7,7,1,1,1,1
1,1,1,1,1,1,7,7,7,7,1,1,1,1,1,1
1,1,1,1,1,1,1,1,1,1,1,1,1,1,1,1
endlayer

