# Ancient Warfare Structure Template File
# Auto-generated structure template file. created on: 6/10/2024 at: 21:12:20
# Lines beginning with # denote comments

header:
version=2.11
name=DemonOutpostWIP1
mods=
size=25,18,24
offset=11,1,17
:endheader

#### VALIDATION ####
validation:
type=lava
structureAuthor=lumberjacksparrow
survival=false
worldGenEnabled=true
unique=false
preserveBlocks=false
preventNaturalHostileSpawns=true
selectionWeight=100
clusterValue=1
minDuplicateDistance=1000
dimensionWhiteList=true
dimensionList=-1
biomeGroupList=
biomeWhiteList=false
biomeList=
leveling=0
fill=0
border=0
blockSwap=false
territoryName=
biomeReplacement=minecraft:
:endvalidation

#### LAYERS ####
layer: 0
1,1,1,1,1,1,1,1,1,1,1,1,1,1,1,1,1,1,1,1,1,1,1,1,1
1,1,1,1,1,1,1,1,1,1,1,1,1,1,1,1,1,1,1,1,1,1,1,1,1
1,1,1,1,1,1,1,1,1,1,1,1,1,1,1,1,1,1,1,1,1,1,1,1,1
1,1,1,1,1,1,1,1,1,1,1,1,1,1,1,1,1,1,1,1,1,1,1,1,1
1,1,1,1,1,1,1,1,1,1,1,1,1,1,1,1,1,1,1,1,1,1,1,1,1
1,1,1,1,1,2,2,2,1,1,1,1,1,1,1,2,2,2,1,1,1,1,1,1,1
1,1,1,1,1,2,2,2,1,2,2,2,2,2,1,2,2,2,1,1,1,1,1,1,1
1,1,1,1,1,2,2,2,1,2,2,2,2,2,1,2,2,2,1,1,1,1,1,1,1
1,1,1,1,1,1,1,1,2,2,2,2,2,2,2,1,1,1,1,1,1,1,1,1,1
1,1,1,1,1,1,2,2,2,2,2,2,2,2,2,2,2,1,1,1,1,1,1,1,1
1,1,1,1,1,1,2,2,2,2,2,2,2,2,2,2,2,1,1,1,1,1,1,1,1
1,1,1,1,1,1,2,2,2,2,2,2,2,2,2,2,2,1,1,1,1,1,1,1,1
1,1,1,1,1,1,2,2,2,2,2,2,2,2,2,2,2,1,1,1,1,1,1,1,1
1,1,1,1,1,1,2,2,2,2,2,2,2,2,2,2,2,1,1,1,1,1,1,1,1
1,1,1,1,1,1,1,1,2,2,2,2,2,2,2,1,1,1,1,1,1,1,1,1,1
1,1,1,1,1,2,2,2,1,2,2,2,2,2,1,2,2,2,1,1,1,1,1,1,1
1,1,1,1,1,2,2,2,1,2,2,2,2,2,1,2,2,2,1,1,1,1,1,1,1
1,1,1,1,1,2,2,2,1,1,1,3,1,1,1,2,2,2,1,1,1,1,1,1,1
1,1,1,1,1,1,1,1,1,1,1,1,1,1,1,1,1,1,1,1,1,1,1,1,1
1,1,1,1,1,1,1,1,1,1,1,1,1,1,1,1,1,1,1,1,1,1,1,1,1
1,1,1,1,1,1,1,1,1,1,1,1,1,1,1,1,1,1,1,1,1,1,1,1,1
1,1,1,1,1,1,1,1,1,1,1,1,1,1,1,1,1,1,1,1,1,1,1,1,1
1,1,1,1,1,1,1,1,1,1,1,1,1,1,1,1,1,1,1,1,1,1,1,1,1
1,1,1,1,1,1,1,1,1,1,1,1,1,1,1,1,1,1,1,1,1,1,1,1,1
:endlayer
layer: 1
0,0,0,0,0,0,0,0,0,0,0,0,0,0,0,0,0,0,0,0,0,0,0,0,0
0,0,0,0,0,0,0,0,0,0,0,0,0,0,0,0,0,0,0,0,0,0,0,0,0
0,0,0,0,0,0,0,0,0,0,0,0,0,0,0,0,0,0,0,0,0,0,0,0,0
0,0,0,0,0,0,0,0,0,0,0,0,0,0,0,0,0,0,0,0,0,0,0,0,0
0,0,0,0,0,0,0,0,0,0,0,0,0,0,0,0,0,0,0,0,0,0,0,0,0
0,0,0,0,0,5,6,6,0,0,0,0,0,0,0,5,6,6,0,0,0,0,0,0,0
0,0,0,0,0,5,2,7,0,0,0,0,0,0,0,5,2,7,0,0,0,0,0,0,0
0,0,0,0,0,4,4,7,0,0,0,0,0,0,0,4,4,4,0,0,0,0,0,0,0
0,0,0,0,0,0,0,0,0,0,0,0,0,0,0,0,0,0,0,0,0,0,0,0,0
0,0,0,0,0,0,0,0,0,0,0,0,0,0,0,0,0,0,0,0,0,0,0,0,0
0,0,0,0,0,0,0,0,0,0,2,2,2,0,0,0,0,0,0,0,0,0,0,0,0
0,0,0,0,0,0,0,0,0,0,2,10,2,0,0,0,0,0,0,0,0,0,0,0,0
0,0,0,0,0,0,0,0,0,0,8,0,8,0,0,0,0,0,0,0,0,0,0,0,0
0,0,0,0,0,0,0,0,0,0,0,0,0,0,0,0,0,0,0,0,0,0,0,0,0
0,0,0,0,0,0,0,0,0,0,0,0,0,0,0,0,0,0,0,0,0,0,0,0,0
0,0,0,0,0,5,6,6,0,0,0,0,0,0,0,6,6,6,0,0,0,0,0,0,0
0,0,0,0,0,5,2,7,0,0,0,0,0,0,0,5,2,7,0,0,0,0,0,0,0
0,0,0,0,0,4,4,7,0,0,0,9,0,0,0,4,4,7,0,0,0,0,0,0,0
0,0,0,0,0,0,0,0,0,0,0,0,0,0,0,0,0,0,0,0,0,0,0,0,0
0,0,0,0,0,0,0,0,0,0,0,0,0,0,0,0,0,0,0,0,0,0,0,0,0
0,0,0,0,0,0,0,0,0,0,0,0,0,0,0,0,0,0,0,0,0,0,0,0,0
0,0,0,0,0,0,0,0,0,0,0,0,0,0,0,0,0,0,0,0,0,0,0,0,0
0,0,0,0,0,0,0,0,0,0,0,0,0,0,0,0,0,0,0,0,0,0,0,0,0
0,0,0,0,0,0,0,0,0,0,0,0,0,0,0,0,0,0,0,0,0,0,0,0,0
:endlayer
layer: 2
0,0,0,0,0,0,0,0,0,0,0,0,0,0,0,0,0,0,0,0,0,0,0,0,0
0,0,0,0,0,0,0,0,0,0,0,0,0,0,0,0,0,0,0,0,0,0,0,0,0
0,0,0,0,0,0,0,0,0,0,0,0,0,0,0,0,0,0,0,0,0,0,0,0,0
0,0,0,0,0,0,0,0,0,0,0,0,0,0,0,0,0,0,0,0,0,0,0,0,0
0,0,0,0,0,0,0,0,0,0,0,0,0,0,0,0,0,0,0,0,0,0,0,0,0
0,0,0,0,0,0,0,0,0,0,0,0,0,0,0,0,0,0,0,0,0,0,0,0,0
0,0,0,0,0,0,2,0,0,0,0,0,0,0,0,0,2,0,0,0,0,0,0,0,0
0,0,0,0,0,0,0,0,0,0,0,0,0,0,0,0,0,0,0,0,0,0,0,0,0
0,0,0,0,0,0,0,0,0,0,0,0,0,0,0,0,0,0,0,0,0,0,0,0,0
0,0,0,0,0,0,0,0,0,0,0,0,0,0,0,0,0,0,0,0,0,0,0,0,0
0,0,0,0,0,0,0,0,0,0,2,2,2,0,0,0,0,0,0,0,0,0,0,0,0
0,0,0,0,0,0,0,0,0,0,2,10,2,0,0,0,0,0,0,0,0,0,0,0,0
0,0,0,0,0,0,0,0,0,0,11,0,12,0,0,0,0,0,0,0,0,0,0,0,0
0,0,0,0,0,0,0,0,0,0,0,0,0,0,0,0,0,0,0,0,0,0,0,0,0
0,0,0,0,0,0,0,0,0,0,0,0,0,0,0,0,0,0,0,0,0,0,0,0,0
0,0,0,0,0,0,0,0,0,0,0,0,0,0,0,0,0,0,0,0,0,0,0,0,0
0,0,0,0,0,0,2,0,0,0,0,0,0,0,0,0,2,0,0,0,0,0,0,0,0
0,0,0,0,0,0,0,0,0,0,0,0,0,0,0,0,0,0,0,0,0,0,0,0,0
0,0,0,0,0,0,0,0,0,0,0,0,0,0,0,0,0,0,0,0,0,0,0,0,0
0,0,0,0,0,0,0,0,0,0,0,0,0,0,0,0,0,0,0,0,0,0,0,0,0
0,0,0,0,0,0,0,0,0,0,0,0,0,0,0,0,0,0,0,0,0,0,0,0,0
0,0,0,0,0,0,0,0,0,0,0,0,0,0,0,0,0,0,0,0,0,0,0,0,0
0,0,0,0,0,0,0,0,0,0,0,0,0,0,0,0,0,0,0,0,0,0,0,0,0
0,0,0,0,0,0,0,0,0,0,0,0,0,0,0,0,0,0,0,0,0,0,0,0,0
:endlayer
layer: 3
0,0,0,0,0,0,0,0,0,0,0,0,0,0,0,0,0,0,0,0,0,0,0,0,0
0,0,0,0,0,0,0,0,0,0,0,0,0,0,0,0,0,0,0,0,0,0,0,0,0
0,0,0,0,0,0,0,0,0,0,0,0,0,0,0,0,0,0,0,0,0,0,0,0,0
0,0,0,0,0,0,0,0,0,0,0,0,0,0,0,0,0,0,0,0,0,0,0,0,0
0,0,0,0,0,0,0,0,0,0,0,0,0,0,0,0,0,0,0,0,0,0,0,0,0
0,0,0,0,0,0,14,15,0,0,0,0,0,0,0,13,14,0,0,0,0,0,0,0,0
0,0,0,0,0,13,2,15,0,0,0,0,0,0,0,13,2,15,0,0,0,0,0,0,0
0,0,0,0,0,8,8,8,0,0,0,0,0,0,0,8,8,15,0,0,0,0,0,0,0
0,0,0,0,0,0,0,0,0,0,0,0,0,0,0,0,0,0,0,0,0,0,0,0,0
0,0,0,0,0,0,0,0,0,0,0,0,0,0,0,0,0,0,0,0,0,0,0,0,0
0,0,0,0,0,0,0,0,0,0,16,16,16,0,0,0,0,0,0,0,0,0,0,0,0
0,0,0,0,0,0,0,0,0,0,16,10,16,0,0,0,0,0,0,0,0,0,0,0,0
0,0,0,0,0,0,0,0,0,0,0,0,0,0,0,0,0,0,0,0,0,0,0,0,0
0,0,0,0,0,0,0,0,0,0,0,0,0,0,0,0,0,0,0,0,0,0,0,0,0
0,0,0,0,0,0,0,0,0,0,0,0,0,0,0,0,0,0,0,0,0,0,0,0,0
0,0,0,0,0,13,14,14,0,0,0,0,0,0,0,13,14,14,0,0,0,0,0,0,0
0,0,0,0,0,13,2,15,0,0,0,0,0,0,0,13,2,15,0,0,0,0,0,0,0
0,0,0,0,0,0,8,8,0,0,0,0,0,0,0,13,8,0,0,0,0,0,0,0,0
0,0,0,0,0,0,0,0,0,0,0,0,0,0,0,0,0,0,0,0,0,0,0,0,0
0,0,0,0,0,0,0,0,0,0,0,0,0,0,0,0,0,0,0,0,0,0,0,0,0
0,0,0,0,0,0,0,0,0,0,0,0,0,0,0,0,0,0,0,0,0,0,0,0,0
0,0,0,0,0,0,0,0,0,0,0,0,0,0,0,0,0,0,0,0,0,0,0,0,0
0,0,0,0,0,0,0,0,0,0,0,0,0,0,0,0,0,0,0,0,0,0,0,0,0
0,0,0,0,0,0,0,0,0,0,0,0,0,0,0,0,0,0,0,0,0,0,0,0,0
:endlayer
layer: 4
0,0,0,0,0,0,0,0,0,0,0,0,0,0,0,0,0,0,0,0,0,0,0,0,0
0,0,0,0,0,0,0,0,0,0,0,0,0,0,0,0,0,0,0,0,0,0,0,0,0
0,0,0,0,0,0,0,0,0,0,0,0,0,0,0,0,0,0,0,0,0,0,0,0,0
0,0,0,0,0,0,0,0,0,0,0,0,0,0,0,0,0,0,0,0,0,0,0,0,0
0,0,0,0,0,0,0,0,16,16,16,16,16,16,16,0,0,0,0,0,0,0,0,0,0
0,0,0,0,0,0,16,16,2,2,2,2,2,2,2,16,16,0,0,0,0,0,0,0,0
0,0,0,0,0,16,16,16,2,2,2,2,2,2,2,16,16,16,0,0,0,0,0,0,0
0,0,0,0,0,16,16,16,2,2,2,2,2,2,2,16,16,16,0,0,0,0,0,0,0
0,0,0,0,16,2,2,2,2,2,2,2,2,2,2,2,2,2,16,0,0,0,0,0,0
0,0,0,0,16,2,2,2,2,2,2,2,2,2,2,2,2,2,16,0,0,0,0,0,0
0,0,0,0,16,2,2,2,2,2,2,2,2,2,2,2,2,2,16,0,0,0,0,0,0
0,0,0,0,16,2,2,2,2,2,2,10,2,2,2,2,2,2,16,0,0,0,0,0,0
0,0,0,0,16,2,2,2,2,2,2,2,2,2,2,2,2,2,16,0,0,0,0,0,0
0,0,0,0,16,2,2,2,2,2,2,2,2,2,2,2,2,2,16,0,0,0,0,0,0
0,0,0,0,16,2,2,2,2,2,2,2,2,2,2,2,2,2,16,0,0,0,0,0,0
0,0,0,0,0,16,16,16,2,2,2,2,2,2,2,16,16,16,0,0,0,0,0,0,0
0,0,0,0,0,16,16,16,2,2,2,2,2,2,2,16,16,16,0,0,0,0,0,0,0
0,0,0,0,0,0,16,16,2,2,2,2,2,2,2,16,16,0,0,0,0,0,0,0,0
0,0,0,0,0,0,0,0,16,16,16,16,16,16,16,0,0,0,0,0,0,0,0,0,0
0,0,0,0,0,0,0,0,0,0,0,0,0,0,0,0,0,0,0,0,0,0,0,0,0
0,0,0,0,0,0,0,0,0,0,0,0,0,0,0,0,0,0,0,0,0,0,0,0,0
0,0,0,0,0,0,0,0,0,0,0,0,0,0,0,0,0,0,0,0,0,0,0,0,0
0,0,0,0,0,0,0,0,0,0,0,0,0,0,0,0,0,0,0,0,0,0,0,0,0
0,0,0,0,0,0,0,0,0,0,0,0,0,0,0,0,0,0,0,0,0,0,0,0,0
:endlayer
layer: 5
0,0,0,0,0,0,0,0,0,0,0,0,0,0,0,0,0,0,0,0,0,0,0,0,0
0,0,0,0,0,0,0,0,0,0,0,0,0,0,0,0,0,0,0,0,0,0,0,0,0
0,0,0,0,0,0,0,0,0,0,0,0,0,0,0,0,0,0,0,0,0,0,0,0,0
0,0,0,0,0,0,0,0,0,0,0,0,0,0,0,0,0,0,0,0,0,0,0,0,0
0,0,0,0,0,0,0,0,2,2,2,2,2,2,2,0,0,0,0,0,0,0,0,0,0
0,0,0,0,0,0,2,2,0,0,2,0,0,0,29,2,2,0,0,0,0,0,0,0,0
0,0,0,0,0,2,0,0,0,0,2,0,0,0,0,0,35,2,0,0,0,0,0,0,0
0,0,0,0,0,2,20,24,0,25,2,0,0,0,0,32,34,2,0,0,0,0,0,0,0
0,0,0,0,2,0,19,23,0,0,2,0,0,0,0,14,14,0,2,0,0,0,0,0,0
0,0,0,0,2,0,0,0,0,0,2,0,2,0,0,0,0,0,2,0,0,0,0,0,0
0,0,0,0,2,0,0,0,0,2,26,0,26,2,0,0,0,0,2,0,0,0,0,0,0
0,0,0,0,2,0,0,0,0,7,0,0,0,5,0,0,0,0,2,0,0,0,0,0,0
0,0,0,0,2,0,0,0,0,2,26,0,26,2,0,0,0,36,2,0,0,0,0,0,0
0,0,0,0,2,0,0,0,0,0,2,6,2,0,0,0,0,0,2,0,0,0,0,0,0
0,0,0,0,2,0,18,0,0,0,0,0,0,0,0,0,0,27,2,0,0,0,0,0,0
0,0,0,0,0,2,17,22,0,0,0,0,0,0,0,31,33,2,0,0,0,0,0,0,0
0,0,0,0,0,2,2,21,0,0,0,0,0,0,28,30,27,2,0,0,0,0,0,0,0
0,0,0,0,0,0,2,2,0,0,0,0,0,0,27,2,2,0,0,0,0,0,0,0,0
0,0,0,0,0,0,0,0,2,2,2,2,2,2,2,0,0,0,0,0,0,0,0,0,0
0,0,0,0,0,0,0,0,0,0,0,0,0,0,0,0,0,0,0,0,0,0,0,0,0
0,0,0,0,0,0,0,0,0,0,0,0,0,0,0,0,0,0,0,0,0,0,0,0,0
0,0,0,0,0,0,0,0,0,0,0,0,0,0,0,0,0,0,0,0,0,0,0,0,0
0,0,0,0,0,0,0,0,0,0,0,0,0,0,0,0,0,0,0,0,0,0,0,0,0
0,0,0,0,0,0,0,0,0,0,0,0,0,0,0,0,0,0,0,0,0,0,0,0,0
:endlayer
layer: 6
0,0,0,0,0,0,0,0,0,0,0,0,0,0,0,0,0,0,0,0,0,0,0,0,0
0,0,0,0,0,0,0,0,0,0,0,0,0,0,0,0,0,0,0,0,0,0,0,0,0
0,0,0,0,0,0,0,0,0,14,0,0,0,14,0,0,0,0,0,0,0,0,0,0,0
0,0,0,0,0,0,0,0,0,2,0,0,0,2,0,0,0,0,0,0,0,0,0,0,0
0,0,0,0,0,0,0,0,2,2,2,2,2,2,2,0,0,0,0,0,0,0,0,0,0
0,0,0,0,0,0,2,2,0,26,2,0,0,26,0,2,2,0,0,0,0,0,0,0,0
0,0,0,0,0,2,0,0,0,0,2,0,0,0,0,0,0,2,0,0,0,0,0,0,0
0,0,0,0,0,2,0,0,0,25,2,0,0,0,0,0,0,2,0,0,0,0,0,0,0
0,0,0,0,2,0,0,0,0,0,2,0,0,0,0,0,0,0,2,0,0,0,0,0,0
0,0,13,2,2,26,0,0,0,0,2,0,2,0,0,0,0,26,2,2,15,0,0,0,0
0,0,0,0,2,0,0,0,0,2,39,0,41,2,0,0,0,0,2,0,0,0,0,0,0
0,0,0,0,2,0,0,0,13,26,0,0,0,26,15,0,0,0,2,0,0,0,0,0,0
0,0,0,0,2,0,0,0,0,2,38,0,40,2,0,0,0,0,2,0,0,0,0,0,0
0,0,13,2,2,26,0,0,0,0,2,26,2,0,0,0,0,26,2,2,15,0,0,0,0
0,0,0,0,2,0,0,0,0,0,0,8,0,0,0,0,0,0,2,0,0,0,0,0,0
0,0,0,0,0,2,0,0,0,0,0,0,0,0,0,0,43,2,0,0,0,0,0,0,0
0,0,0,0,0,2,37,0,0,0,0,0,0,0,0,42,27,2,0,0,0,0,0,0,0
0,0,0,0,0,0,2,2,0,26,0,0,0,26,0,2,2,0,0,0,0,0,0,0,0
0,0,0,0,0,0,0,0,2,2,2,2,2,2,2,0,0,0,0,0,0,0,0,0,0
0,0,0,0,0,0,0,0,0,2,0,0,0,2,0,0,0,0,0,0,0,0,0,0,0
0,0,0,0,0,0,0,0,0,8,0,0,0,8,0,0,0,0,0,0,0,0,0,0,0
0,0,0,0,0,0,0,0,0,0,0,0,0,0,0,0,0,0,0,0,0,0,0,0,0
0,0,0,0,0,0,0,0,0,0,0,0,0,0,0,0,0,0,0,0,0,0,0,0,0
0,0,0,0,0,0,0,0,0,0,0,0,0,0,0,0,0,0,0,0,0,0,0,0,0
:endlayer
layer: 7
0,0,0,0,0,0,0,0,0,0,0,0,0,0,0,0,0,0,0,0,0,0,0,0,0
0,0,0,0,0,0,0,0,0,26,0,0,0,26,0,0,0,0,0,0,0,0,0,0,0
0,0,0,0,0,0,0,0,0,2,0,0,0,2,0,0,0,0,0,0,0,0,0,0,0
0,0,0,0,0,0,0,0,0,26,0,0,0,26,0,0,0,0,0,0,0,0,0,0,0
0,0,0,0,0,0,0,0,2,2,2,2,2,2,2,0,0,0,0,0,0,0,0,0,0
0,0,0,0,0,0,2,2,0,47,2,8,0,49,0,2,2,0,0,0,0,0,0,0,0
0,0,0,0,0,2,0,0,0,0,2,0,0,0,0,0,0,2,0,0,0,0,0,0,0
0,0,0,0,0,2,0,0,0,25,2,0,0,0,0,0,0,2,0,0,0,0,0,0,0
0,0,0,0,2,0,0,0,0,0,2,0,0,0,0,0,0,0,2,0,0,0,0,0,0
0,26,2,26,2,45,0,0,0,0,2,0,2,0,0,0,0,51,2,26,2,26,0,0,0
0,0,0,0,2,0,0,0,0,2,0,0,0,2,0,0,0,0,2,0,0,0,0,0,0
0,0,0,0,2,15,0,0,2,0,0,0,0,0,2,0,0,13,2,0,0,0,0,0,0
0,0,0,0,2,0,0,0,0,2,0,0,0,2,0,0,0,0,2,0,0,0,0,0,0
0,26,2,26,2,44,0,0,0,0,2,0,2,0,0,0,0,50,2,26,2,26,0,0,0
0,0,0,0,2,0,0,0,0,0,0,2,0,0,0,0,0,0,2,0,0,0,0,0,0
0,0,0,0,0,2,0,0,0,0,0,0,0,0,0,0,0,2,0,0,0,0,0,0,0
0,0,0,0,0,2,0,0,0,0,0,0,0,0,0,0,27,2,0,0,0,0,0,0,0
0,0,0,0,0,0,2,2,0,46,0,14,0,48,0,2,2,0,0,0,0,0,0,0,0
0,0,0,0,0,0,0,0,2,2,2,2,2,2,2,0,0,0,0,0,0,0,0,0,0
0,0,0,0,0,0,0,0,0,26,0,0,0,26,0,0,0,0,0,0,0,0,0,0,0
0,0,0,0,0,0,0,0,0,2,0,0,0,2,0,0,0,0,0,0,0,0,0,0,0
0,0,0,0,0,0,0,0,0,26,0,0,0,26,0,0,0,0,0,0,0,0,0,0,0
0,0,0,0,0,0,0,0,0,0,0,0,0,0,0,0,0,0,0,0,0,0,0,0,0
0,0,0,0,0,0,0,0,0,0,0,0,0,0,0,0,0,0,0,0,0,0,0,0,0
:endlayer
layer: 8
0,0,0,0,0,0,0,0,0,0,0,0,0,0,0,0,0,0,0,0,0,0,0,0,0
0,0,0,0,0,0,0,0,0,0,0,0,0,0,0,0,0,0,0,0,0,0,0,0,0
0,0,0,0,0,0,0,0,0,26,0,0,0,26,0,0,0,0,0,0,0,0,0,0,0
0,0,0,0,0,0,0,0,0,0,0,0,0,0,0,0,0,0,0,0,0,0,0,0,0
0,0,0,0,0,0,0,0,2,2,2,2,2,2,2,0,0,0,0,0,0,0,0,0,0
0,0,0,0,0,0,2,2,0,0,2,2,0,0,0,2,2,0,0,0,0,0,0,0,0
0,0,0,0,0,2,26,0,0,0,2,8,0,0,0,0,26,2,0,0,0,0,0,0,0
0,0,0,0,0,2,0,0,0,25,2,0,0,0,0,0,0,2,0,0,0,0,0,0,0
0,0,0,0,2,0,0,0,0,0,2,14,0,0,0,0,0,0,2,0,0,0,0,0,0
0,0,26,0,2,0,0,0,0,0,2,2,2,0,0,0,0,0,2,0,26,0,0,0,0
0,0,0,0,2,0,0,0,0,2,0,0,0,2,0,0,0,0,2,0,0,0,0,0,0
0,0,0,0,2,2,15,13,2,0,0,0,0,0,2,15,13,2,2,0,0,0,0,0,0
0,0,0,0,2,0,0,0,0,2,0,0,0,2,0,0,0,0,2,0,0,0,0,0,0
0,0,26,0,2,0,0,0,0,0,2,0,2,0,0,0,0,0,2,0,26,0,0,0,0
0,0,0,0,2,0,0,0,0,0,0,2,0,0,0,0,0,0,2,0,0,0,0,0,0
0,0,0,0,0,2,0,0,0,0,0,8,0,0,0,0,0,2,0,0,0,0,0,0,0
0,0,0,0,0,2,0,0,0,0,0,14,0,0,0,0,0,2,0,0,0,0,0,0,0
0,0,0,0,0,0,2,2,0,0,0,2,0,0,0,2,2,0,0,0,0,0,0,0,0
0,0,0,0,0,0,0,0,2,2,2,2,2,2,2,0,0,0,0,0,0,0,0,0,0
0,0,0,0,0,0,0,0,0,0,0,0,0,0,0,0,0,0,0,0,0,0,0,0,0
0,0,0,0,0,0,0,0,0,26,0,0,0,26,0,0,0,0,0,0,0,0,0,0,0
0,0,0,0,0,0,0,0,0,0,0,0,0,0,0,0,0,0,0,0,0,0,0,0,0
0,0,0,0,0,0,0,0,0,0,0,0,0,0,0,0,0,0,0,0,0,0,0,0,0
0,0,0,0,0,0,0,0,0,0,0,0,0,0,0,0,0,0,0,0,0,0,0,0,0
:endlayer
layer: 9
0,0,0,0,0,0,0,0,0,0,0,0,0,0,0,0,0,0,0,0,0,0,0,0,0
0,0,0,0,0,0,0,0,0,0,0,0,0,0,0,0,0,0,0,0,0,0,0,0,0
0,0,0,0,0,0,0,0,0,0,0,0,0,0,0,0,0,0,0,0,0,0,0,0,0
0,0,0,0,0,0,0,0,0,0,0,0,0,0,0,0,0,0,0,0,0,0,0,0,0
0,0,0,0,0,0,0,0,16,16,16,16,16,16,16,0,0,0,0,0,0,0,0,0,0
0,0,0,0,0,0,16,16,15,52,53,2,52,52,13,16,16,0,0,0,0,0,0,0,0
0,0,0,0,0,16,16,15,52,52,53,2,52,52,52,13,16,16,0,0,0,0,0,0,0
0,0,0,0,0,16,8,52,52,25,53,2,52,52,52,52,8,16,0,0,0,0,0,0,0
0,0,0,0,16,8,52,52,52,52,53,2,52,52,52,52,52,8,16,0,0,0,0,0,0
0,0,0,0,16,52,52,52,52,52,2,2,2,52,52,52,52,52,16,0,0,0,0,0,0
0,0,0,0,16,52,52,52,52,2,53,52,53,2,52,52,52,52,16,0,0,0,0,0,0
0,0,0,0,16,2,2,2,2,2,52,52,52,2,2,2,2,2,16,0,0,0,0,0,0
0,0,0,0,16,52,52,52,52,2,53,52,53,2,52,52,52,52,16,0,0,0,0,0,0
0,0,0,0,16,52,52,52,52,52,2,2,2,52,52,52,52,52,16,0,0,0,0,0,0
0,0,0,0,16,52,52,52,52,52,52,2,52,52,52,52,52,52,16,0,0,0,0,0,0
0,0,0,0,0,16,52,52,52,52,52,2,52,52,52,52,52,16,0,0,0,0,0,0,0
0,0,0,0,0,16,52,52,52,52,52,2,52,52,52,52,52,16,0,0,0,0,0,0,0
0,0,0,0,0,0,16,16,52,52,52,2,52,52,52,16,16,0,0,0,0,0,0,0,0
0,0,0,0,0,0,0,0,16,16,16,16,16,16,16,0,0,0,0,0,0,0,0,0,0
0,0,0,0,0,0,0,0,0,0,0,0,0,0,0,0,0,0,0,0,0,0,0,0,0
0,0,0,0,0,0,0,0,0,0,0,0,0,0,0,0,0,0,0,0,0,0,0,0,0
0,0,0,0,0,0,0,0,0,0,0,0,0,0,0,0,0,0,0,0,0,0,0,0,0
0,0,0,0,0,0,0,0,0,0,0,0,0,0,0,0,0,0,0,0,0,0,0,0,0
0,0,0,0,0,0,0,0,0,0,0,0,0,0,0,0,0,0,0,0,0,0,0,0,0
:endlayer
layer: 10
0,0,0,0,0,0,0,0,0,0,0,0,0,0,0,0,0,0,0,0,0,0,0,0,0
0,0,0,0,0,0,0,0,0,0,0,0,0,0,0,0,0,0,0,0,0,0,0,0,0
0,0,0,0,0,0,0,0,0,0,0,0,0,0,0,0,0,0,0,0,0,0,0,0,0
0,0,0,0,0,0,0,0,0,0,0,0,0,0,0,0,0,0,0,0,0,0,0,0,0
0,0,0,0,0,0,0,0,60,0,5,2,7,0,62,0,0,0,0,0,0,0,0,0,0
0,0,0,0,0,0,0,0,2,2,2,2,2,2,2,0,0,0,0,0,0,0,0,0,0
0,0,0,0,0,0,2,2,0,0,0,0,0,0,0,2,2,0,0,0,0,0,0,0,0
0,0,0,0,0,0,2,58,0,0,0,0,0,0,0,64,2,0,0,0,0,0,0,0,0
0,0,0,0,55,2,0,6,0,6,0,6,0,6,0,6,0,2,66,0,0,0,0,0,0
0,0,0,0,0,2,0,57,0,57,0,57,0,57,0,57,0,2,0,0,0,0,0,0,0
0,0,0,0,6,2,0,57,0,57,0,57,0,57,0,57,0,2,6,0,0,0,0,0,0
0,0,0,0,2,2,0,57,0,57,0,57,0,57,0,57,0,2,2,0,0,0,0,0,0
0,0,0,0,4,2,0,57,0,57,0,57,0,57,0,57,0,2,4,0,0,0,0,0,0
0,0,0,0,0,2,0,57,0,57,0,57,0,57,0,57,0,2,0,0,0,0,0,0,0
0,0,0,0,54,2,0,4,0,4,0,4,0,4,0,4,0,2,65,0,0,0,0,0,0
0,0,0,0,0,0,2,56,0,0,0,0,0,0,0,63,2,0,0,0,0,0,0,0,0
0,0,0,0,0,0,2,2,0,0,0,0,0,0,0,2,2,0,0,0,0,0,0,0,0
0,0,0,0,0,0,0,0,2,2,2,2,2,2,2,0,0,0,0,0,0,0,0,0,0
0,0,0,0,0,0,0,0,59,0,5,2,7,0,61,0,0,0,0,0,0,0,0,0,0
0,0,0,0,0,0,0,0,0,0,0,0,0,0,0,0,0,0,0,0,0,0,0,0,0
0,0,0,0,0,0,0,0,0,0,0,0,0,0,0,0,0,0,0,0,0,0,0,0,0
0,0,0,0,0,0,0,0,0,0,0,0,0,0,0,0,0,0,0,0,0,0,0,0,0
0,0,0,0,0,0,0,0,0,0,0,0,0,0,0,0,0,0,0,0,0,0,0,0,0
0,0,0,0,0,0,0,0,0,0,0,0,0,0,0,0,0,0,0,0,0,0,0,0,0
:endlayer
layer: 11
0,0,0,0,0,0,0,0,0,0,0,0,0,0,0,0,0,0,0,0,0,0,0,0,0
0,0,0,0,0,0,0,0,0,0,0,0,0,0,0,0,0,0,0,0,0,0,0,0,0
0,0,0,0,0,0,0,0,0,0,0,0,0,0,0,0,0,0,0,0,0,0,0,0,0
0,0,0,0,0,0,0,0,0,0,0,14,0,0,0,0,0,0,0,0,0,0,0,0,0
0,0,0,0,0,0,0,0,0,0,0,2,0,0,0,0,0,0,0,0,0,0,0,0,0
0,0,0,0,0,0,0,0,2,2,2,2,2,2,2,0,0,0,0,0,0,0,0,0,0
0,0,0,0,0,0,2,2,15,0,0,0,0,0,13,2,2,0,0,0,0,0,0,0,0
0,0,0,0,0,0,2,0,0,0,0,0,0,0,0,0,2,0,0,0,0,0,0,0,0
0,0,0,0,0,2,8,0,0,0,0,0,0,0,0,0,8,2,0,0,0,0,0,0,0
0,0,0,0,0,2,0,68,0,69,0,68,0,68,0,67,0,2,0,0,0,0,0,0,0
0,0,0,0,0,2,0,67,0,69,0,70,0,69,0,69,0,2,0,0,0,0,0,0,0
0,0,0,13,2,2,0,67,0,69,0,70,0,67,0,68,0,2,2,15,0,0,0,0,0
0,0,0,0,0,2,0,68,0,67,0,70,0,68,0,68,0,2,0,0,0,0,0,0,0
0,0,0,0,0,2,0,67,0,68,0,69,0,69,0,69,0,2,0,0,0,0,0,0,0
0,0,0,0,0,2,0,0,0,0,0,0,0,0,0,0,0,2,0,0,0,0,0,0,0
0,0,0,0,0,0,2,0,0,0,0,0,0,0,0,0,2,0,0,0,0,0,0,0,0
0,0,0,0,0,0,2,2,0,0,0,0,0,0,0,2,2,0,0,0,0,0,0,0,0
0,0,0,0,0,0,0,0,2,2,2,2,2,2,2,0,0,0,0,0,0,0,0,0,0
0,0,0,0,0,0,0,0,0,0,0,2,0,0,0,0,0,0,0,0,0,0,0,0,0
0,0,0,0,0,0,0,0,0,0,0,8,0,0,0,0,0,0,0,0,0,0,0,0,0
0,0,0,0,0,0,0,0,0,0,0,0,0,0,0,0,0,0,0,0,0,0,0,0,0
0,0,0,0,0,0,0,0,0,0,0,0,0,0,0,0,0,0,0,0,0,0,0,0,0
0,0,0,0,0,0,0,0,0,0,0,0,0,0,0,0,0,0,0,0,0,0,0,0,0
0,0,0,0,0,0,0,0,0,0,0,0,0,0,0,0,0,0,0,0,0,0,0,0,0
:endlayer
layer: 12
0,0,0,0,0,0,0,0,0,0,0,0,0,0,0,0,0,0,0,0,0,0,0,0,0
0,0,0,0,0,0,0,0,0,0,0,0,0,0,0,0,0,0,0,0,0,0,0,0,0
0,0,0,0,0,0,0,0,0,0,0,0,0,0,0,0,0,0,0,0,0,0,0,0,0
0,0,0,0,0,0,0,0,0,0,26,2,26,0,0,0,0,0,0,0,0,0,0,0,0
0,0,0,0,0,0,0,0,0,0,0,26,0,0,0,0,0,0,0,0,0,0,0,0,0
0,0,0,0,0,0,0,0,75,72,72,72,72,72,77,0,0,0,0,0,0,0,0,0,0
0,0,0,0,0,0,0,72,16,16,16,16,16,16,16,72,0,0,0,0,0,0,0,0,0
0,0,0,0,0,0,72,16,2,2,2,2,2,2,2,16,72,0,0,0,0,0,0,0,0
0,0,0,0,0,73,16,2,2,2,2,2,2,2,2,2,16,79,0,0,0,0,0,0,0
0,0,0,0,0,72,16,2,2,2,2,2,2,2,2,2,16,72,0,0,0,0,0,0,0
0,0,0,26,0,72,16,2,2,2,2,2,2,2,2,2,16,72,0,26,0,0,0,0,0
0,0,0,2,26,72,16,2,2,2,2,2,2,2,2,2,16,72,26,2,0,0,0,0,0
0,0,0,26,0,72,16,2,2,2,2,2,2,2,2,2,16,72,0,26,0,0,0,0,0
0,0,0,0,0,72,16,2,2,2,2,2,2,2,2,2,16,72,0,0,0,0,0,0,0
0,0,0,0,0,71,16,2,2,2,2,2,2,2,2,2,16,78,0,0,0,0,0,0,0
0,0,0,0,0,0,72,16,2,2,2,2,2,2,2,16,72,0,0,0,0,0,0,0,0
0,0,0,0,0,0,0,72,16,16,16,16,16,16,16,72,0,0,0,0,0,0,0,0,0
0,0,0,0,0,0,0,0,74,72,72,72,72,72,76,0,0,0,0,0,0,0,0,0,0
0,0,0,0,0,0,0,0,0,0,0,26,0,0,0,0,0,0,0,0,0,0,0,0,0
0,0,0,0,0,0,0,0,0,0,26,2,26,0,0,0,0,0,0,0,0,0,0,0,0
0,0,0,0,0,0,0,0,0,0,0,0,0,0,0,0,0,0,0,0,0,0,0,0,0
0,0,0,0,0,0,0,0,0,0,0,0,0,0,0,0,0,0,0,0,0,0,0,0,0
0,0,0,0,0,0,0,0,0,0,0,0,0,0,0,0,0,0,0,0,0,0,0,0,0
0,0,0,0,0,0,0,0,0,0,0,0,0,0,0,0,0,0,0,0,0,0,0,0,0
:endlayer
layer: 13
0,0,0,0,0,0,0,0,0,0,0,0,0,0,0,0,0,0,0,0,0,0,0,0,0
0,0,0,0,0,0,0,0,0,0,0,0,0,0,0,0,0,0,0,0,0,0,0,0,0
0,0,0,0,0,0,0,0,0,0,0,0,0,0,0,0,0,0,0,0,0,0,0,0,0
0,0,0,0,0,0,0,0,0,0,0,26,0,0,0,0,0,0,0,0,0,0,0,0,0
0,0,0,0,0,0,0,0,0,0,0,0,0,0,0,0,0,0,0,0,0,0,0,0,0
0,0,0,0,0,0,0,0,0,0,0,0,0,0,0,0,0,0,0,0,0,0,0,0,0
0,0,0,0,0,0,0,0,0,0,0,0,0,0,0,0,0,0,0,0,0,0,0,0,0
0,0,0,0,0,0,0,0,0,0,0,0,0,0,0,0,0,0,0,0,0,0,0,0,0
0,0,0,0,0,0,0,0,0,0,0,0,0,0,0,0,0,0,0,0,0,0,0,0,0
0,0,0,0,0,0,0,0,0,0,72,72,72,0,0,0,0,0,0,0,0,0,0,0,0
0,0,0,0,0,0,0,0,0,72,72,2,72,72,0,0,0,0,0,0,0,0,0,0,0
0,0,0,26,0,0,0,0,0,72,2,16,2,72,0,0,0,0,0,26,0,0,0,0,0
0,0,0,0,0,0,0,0,0,72,72,2,72,72,0,0,0,0,0,0,0,0,0,0,0
0,0,0,0,0,0,0,0,0,0,72,72,72,0,0,0,0,0,0,0,0,0,0,0,0
0,0,0,0,0,0,0,0,0,0,0,0,0,0,0,0,0,0,0,0,0,0,0,0,0
0,0,0,0,0,0,0,0,0,0,0,0,0,0,0,0,0,0,0,0,0,0,0,0,0
0,0,0,0,0,0,0,0,0,0,0,0,0,0,0,0,0,0,0,0,0,0,0,0,0
0,0,0,0,0,0,0,0,0,0,0,0,0,0,0,0,0,0,0,0,0,0,0,0,0
0,0,0,0,0,0,0,0,0,0,0,0,0,0,0,0,0,0,0,0,0,0,0,0,0
0,0,0,0,0,0,0,0,0,0,0,26,0,0,0,0,0,0,0,0,0,0,0,0,0
0,0,0,0,0,0,0,0,0,0,0,0,0,0,0,0,0,0,0,0,0,0,0,0,0
0,0,0,0,0,0,0,0,0,0,0,0,0,0,0,0,0,0,0,0,0,0,0,0,0
0,0,0,0,0,0,0,0,0,0,0,0,0,0,0,0,0,0,0,0,0,0,0,0,0
0,0,0,0,0,0,0,0,0,0,0,0,0,0,0,0,0,0,0,0,0,0,0,0,0
:endlayer
layer: 14
0,0,0,0,0,0,0,0,0,0,0,0,0,0,0,0,0,0,0,0,0,0,0,0,0
0,0,0,0,0,0,0,0,0,0,0,0,0,0,0,0,0,0,0,0,0,0,0,0,0
0,0,0,0,0,0,0,0,0,0,0,0,0,0,0,0,0,0,0,0,0,0,0,0,0
0,0,0,0,0,0,0,0,0,0,0,0,0,0,0,0,0,0,0,0,0,0,0,0,0
0,0,0,0,0,0,0,0,0,0,0,0,0,0,0,0,0,0,0,0,0,0,0,0,0
0,0,0,0,0,0,0,0,0,0,0,0,0,0,0,0,0,0,0,0,0,0,0,0,0
0,0,0,0,0,0,0,0,0,0,0,0,0,0,0,0,0,0,0,0,0,0,0,0,0
0,0,0,0,0,0,0,0,0,0,0,82,0,0,0,0,0,0,0,0,0,0,0,0,0
0,0,0,0,0,0,0,0,0,0,0,0,0,0,0,0,0,0,0,0,0,0,0,0,0
0,0,0,0,0,0,0,0,0,0,0,0,0,0,0,0,0,0,0,0,0,0,0,0,0
0,0,0,0,0,0,0,0,0,0,0,2,0,0,0,0,0,0,0,0,0,0,0,0,0
0,0,0,0,0,0,0,80,0,0,2,16,2,0,0,83,0,0,0,0,0,0,0,0,0
0,0,0,0,0,0,0,0,0,0,0,2,0,0,0,0,0,0,0,0,0,0,0,0,0
0,0,0,0,0,0,0,0,0,0,0,0,0,0,0,0,0,0,0,0,0,0,0,0,0
0,0,0,0,0,0,0,0,0,0,0,0,0,0,0,0,0,0,0,0,0,0,0,0,0
0,0,0,0,0,0,0,0,0,0,0,81,0,0,0,0,0,0,0,0,0,0,0,0,0
0,0,0,0,0,0,0,0,0,0,0,0,0,0,0,0,0,0,0,0,0,0,0,0,0
0,0,0,0,0,0,0,0,0,0,0,0,0,0,0,0,0,0,0,0,0,0,0,0,0
0,0,0,0,0,0,0,0,0,0,0,0,0,0,0,0,0,0,0,0,0,0,0,0,0
0,0,0,0,0,0,0,0,0,0,0,0,0,0,0,0,0,0,0,0,0,0,0,0,0
0,0,0,0,0,0,0,0,0,0,0,0,0,0,0,0,0,0,0,0,0,0,0,0,0
0,0,0,0,0,0,0,0,0,0,0,0,0,0,0,0,0,0,0,0,0,0,0,0,0
0,0,0,0,0,0,0,0,0,0,0,0,0,0,0,0,0,0,0,0,0,0,0,0,0
0,0,0,0,0,0,0,0,0,0,0,0,0,0,0,0,0,0,0,0,0,0,0,0,0
:endlayer
layer: 15
0,0,0,0,0,0,0,0,0,0,0,0,0,0,0,0,0,0,0,0,0,0,0,0,0
0,0,0,0,0,0,0,0,0,0,0,0,0,0,0,0,0,0,0,0,0,0,0,0,0
0,0,0,0,0,0,0,0,0,0,0,0,0,0,0,0,0,0,0,0,0,0,0,0,0
0,0,0,0,0,0,0,0,0,0,0,0,0,0,0,0,0,0,0,0,0,0,0,0,0
0,0,0,0,0,0,0,0,0,0,0,0,0,0,0,0,0,0,0,0,0,0,0,0,0
0,0,0,0,0,0,0,0,0,0,0,0,0,0,0,0,0,0,0,0,0,0,0,0,0
0,0,0,0,0,0,0,0,0,0,0,0,0,0,0,0,0,0,0,0,0,0,0,0,0
0,0,0,0,0,0,0,0,0,0,26,86,26,0,0,0,0,0,0,0,0,0,0,0,0
0,0,0,0,0,0,0,0,0,0,0,0,0,0,0,0,0,0,0,0,0,0,0,0,0
0,0,0,0,0,0,0,0,0,0,0,0,0,0,0,0,0,0,0,0,0,0,0,0,0
0,0,0,0,0,0,0,26,0,0,0,2,0,0,0,26,0,0,0,0,0,0,0,0,0
0,0,0,0,0,0,0,84,0,0,2,16,2,0,0,87,0,0,0,0,0,0,0,0,0
0,0,0,0,0,0,0,26,0,0,0,2,0,0,0,26,0,0,0,0,0,0,0,0,0
0,0,0,0,0,0,0,0,0,0,0,0,0,0,0,0,0,0,0,0,0,0,0,0,0
0,0,0,0,0,0,0,0,0,0,0,0,0,0,0,0,0,0,0,0,0,0,0,0,0
0,0,0,0,0,0,0,0,0,0,26,85,26,0,0,0,0,0,0,0,0,0,0,0,0
0,0,0,0,0,0,0,0,0,0,0,0,0,0,0,0,0,0,0,0,0,0,0,0,0
0,0,0,0,0,0,0,0,0,0,0,0,0,0,0,0,0,0,0,0,0,0,0,0,0
0,0,0,0,0,0,0,0,0,0,0,0,0,0,0,0,0,0,0,0,0,0,0,0,0
0,0,0,0,0,0,0,0,0,0,0,0,0,0,0,0,0,0,0,0,0,0,0,0,0
0,0,0,0,0,0,0,0,0,0,0,0,0,0,0,0,0,0,0,0,0,0,0,0,0
0,0,0,0,0,0,0,0,0,0,0,0,0,0,0,0,0,0,0,0,0,0,0,0,0
0,0,0,0,0,0,0,0,0,0,0,0,0,0,0,0,0,0,0,0,0,0,0,0,0
0,0,0,0,0,0,0,0,0,0,0,0,0,0,0,0,0,0,0,0,0,0,0,0,0
:endlayer
layer: 16
0,0,0,0,0,0,0,0,0,0,0,0,0,0,0,0,0,0,0,0,0,0,0,0,0
0,0,0,0,0,0,0,0,0,0,0,0,0,0,0,0,0,0,0,0,0,0,0,0,0
0,0,0,0,0,0,0,0,0,0,0,0,0,0,0,0,0,0,0,0,0,0,0,0,0
0,0,0,0,0,0,0,0,0,0,0,0,0,0,0,0,0,0,0,0,0,0,0,0,0
0,0,0,0,0,0,0,0,0,0,0,0,0,0,0,0,0,0,0,0,0,0,0,0,0
0,0,0,0,0,0,0,0,0,0,0,0,0,0,0,0,0,0,0,0,0,0,0,0,0
0,0,0,0,0,0,0,0,0,0,0,0,0,0,0,0,0,0,0,0,0,0,0,0,0
0,0,0,0,0,0,0,0,0,0,26,91,26,0,0,0,0,0,0,0,0,0,0,0,0
0,0,0,0,0,0,0,0,0,0,0,14,0,0,0,0,0,0,0,0,0,0,0,0,0
0,0,0,0,0,0,0,0,0,0,0,2,0,0,0,0,0,0,0,0,0,0,0,0,0
0,0,0,0,0,0,0,26,0,0,0,4,0,0,0,26,0,0,0,0,0,0,0,0,0
0,0,0,0,0,0,0,88,13,2,7,90,5,2,15,92,0,0,0,0,0,0,0,0,0
0,0,0,0,0,0,0,26,0,0,0,6,0,0,0,26,0,0,0,0,0,0,0,0,0
0,0,0,0,0,0,0,0,0,0,0,2,0,0,0,0,0,0,0,0,0,0,0,0,0
0,0,0,0,0,0,0,0,0,0,0,8,0,0,0,0,0,0,0,0,0,0,0,0,0
0,0,0,0,0,0,0,0,0,0,26,89,26,0,0,0,0,0,0,0,0,0,0,0,0
0,0,0,0,0,0,0,0,0,0,0,0,0,0,0,0,0,0,0,0,0,0,0,0,0
0,0,0,0,0,0,0,0,0,0,0,0,0,0,0,0,0,0,0,0,0,0,0,0,0
0,0,0,0,0,0,0,0,0,0,0,0,0,0,0,0,0,0,0,0,0,0,0,0,0
0,0,0,0,0,0,0,0,0,0,0,0,0,0,0,0,0,0,0,0,0,0,0,0,0
0,0,0,0,0,0,0,0,0,0,0,0,0,0,0,0,0,0,0,0,0,0,0,0,0
0,0,0,0,0,0,0,0,0,0,0,0,0,0,0,0,0,0,0,0,0,0,0,0,0
0,0,0,0,0,0,0,0,0,0,0,0,0,0,0,0,0,0,0,0,0,0,0,0,0
0,0,0,0,0,0,0,0,0,0,0,0,0,0,0,0,0,0,0,0,0,0,0,0,0
:endlayer
layer: 17
0,0,0,0,0,0,0,0,0,0,0,0,0,0,0,0,0,0,0,0,0,0,0,0,0
0,0,0,0,0,0,0,0,0,0,0,0,0,0,0,0,0,0,0,0,0,0,0,0,0
0,0,0,0,0,0,0,0,0,0,0,0,0,0,0,0,0,0,0,0,0,0,0,0,0
0,0,0,0,0,0,0,0,0,0,0,0,0,0,0,0,0,0,0,0,0,0,0,0,0
0,0,0,0,0,0,0,0,0,0,0,0,0,0,0,0,0,0,0,0,0,0,0,0,0
0,0,0,0,0,0,0,0,0,0,0,0,0,0,0,0,0,0,0,0,0,0,0,0,0
0,0,0,0,0,0,0,0,0,0,0,0,0,0,0,0,0,0,0,0,0,0,0,0,0
0,0,0,0,0,0,0,0,0,0,26,0,26,0,0,0,0,0,0,0,0,0,0,0,0
0,0,0,0,0,0,0,0,0,0,26,2,26,0,0,0,0,0,0,0,0,0,0,0,0
0,0,0,0,0,0,0,0,0,0,0,26,0,0,0,0,0,0,0,0,0,0,0,0,0
0,0,0,0,0,0,0,26,26,0,0,0,0,0,26,26,0,0,0,0,0,0,0,0,0
0,0,0,0,0,0,0,0,2,0,0,0,0,0,2,0,0,0,0,0,0,0,0,0,0
0,0,0,0,0,0,0,26,26,0,0,0,0,0,26,26,0,0,0,0,0,0,0,0,0
0,0,0,0,0,0,0,0,0,0,0,0,0,0,0,0,0,0,0,0,0,0,0,0,0
0,0,0,0,0,0,0,0,0,0,26,2,26,0,0,0,0,0,0,0,0,0,0,0,0
0,0,0,0,0,0,0,0,0,0,26,0,26,0,0,0,0,0,0,0,0,0,0,0,0
0,0,0,0,0,0,0,0,0,0,0,0,0,0,0,0,0,0,0,0,0,0,0,0,0
0,0,0,0,0,0,0,0,0,0,0,0,0,0,0,0,0,0,0,0,0,0,0,0,0
0,0,0,0,0,0,0,0,0,0,0,0,0,0,0,0,0,0,0,0,0,0,0,0,0
0,0,0,0,0,0,0,0,0,0,0,0,0,0,0,0,0,0,0,0,0,0,0,0,0
0,0,0,0,0,0,0,0,0,0,0,0,0,0,0,0,0,0,0,0,0,0,0,0,0
0,0,0,0,0,0,0,0,0,0,0,0,0,0,0,0,0,0,0,0,0,0,0,0,0
0,0,0,0,0,0,0,0,0,0,0,0,0,0,0,0,0,0,0,0,0,0,0,0,0
0,0,0,0,0,0,0,0,0,0,0,0,0,0,0,0,0,0,0,0,0,0,0,0,0
:endlayer

#### RULES ####
rule:
plugin=fluid
number=1
data:
JSON:{blockState:{blockName:"minecraft:lava",properties:{level:"0"}}}
:enddata
:endrule

rule:
plugin=vanillaBlocks
number=2
data:
JSON:{blockState:{blockName:"minecraft:nether_brick"}}
:enddata
:endrule

rule:
plugin=blockTile
number=3
data:
JSON:{blockState:{blockName:"ancientwarfarestructure:structure_scanner_block",properties:{facing:"down"}},teData:{id:"ancientwarfarestructure:structure_scanner_block_tile",scannerInventory:{Items:[{Slot:0,id:"ancientwarfarestructure:structure_scanner",Count:1b,Damage:0s,tag:{structData:{pos1:-68991401853605L,pos2:-75315137217165L,buildKey:{face:5b,key:-73665869775514L}},structureName:"DemonOutpostWIP1",validator:{validationType:"lava",structureAuthor:"lumberjacksparrow",survival:0b,worldGenEnabled:1b,unique:0b,preserveBlocks:0b,preventNaturalHostileSpawns:1b,selectionWeight:100,clusterValue:1,minDuplicateDistance:100,dimensionWhiteList:1b,dimensionList:[I;],biomeGroupList:[],biomeWhiteList:0b,biomeList:[],leveling:0,fill:0,border:0,blockSwap:0b,territoryName:"",biomeReplacement:"minecraft:"}}}],Size:1},boundsActive:1b,facing:4b}}
:enddata
:endrule

rule:
plugin=vanillaBlocks
number=4
data:
JSON:{blockState:{blockName:"minecraft:nether_brick_stairs",properties:{facing:"north",half:"bottom",shape:"straight"}}}
:enddata
:endrule

rule:
plugin=vanillaBlocks
number=5
data:
JSON:{blockState:{blockName:"minecraft:nether_brick_stairs",properties:{facing:"east",half:"bottom",shape:"straight"}}}
:enddata
:endrule

rule:
plugin=vanillaBlocks
number=6
data:
JSON:{blockState:{blockName:"minecraft:nether_brick_stairs",properties:{facing:"south",half:"bottom",shape:"straight"}}}
:enddata
:endrule

rule:
plugin=vanillaBlocks
number=7
data:
JSON:{blockState:{blockName:"minecraft:nether_brick_stairs",properties:{facing:"west",half:"bottom",shape:"straight"}}}
:enddata
:endrule

rule:
plugin=vanillaBlocks
number=8
data:
JSON:{blockState:{blockName:"minecraft:nether_brick_stairs",properties:{facing:"north",half:"top",shape:"straight"}}}
:enddata
:endrule

rule:
plugin=vanillaBlocks
number=9
data:
JSON:{blockState:{blockName:"minecraft:fire",properties:{age:"3",east:"false",north:"false",south:"false",up:"false",west:"false"}}}
:enddata
:endrule

rule:
plugin=vanillaBlocks
number=10
data:
JSON:{blockState:{blockName:"minecraft:ladder",properties:{facing:"south"}}}
:enddata
:endrule

rule:
plugin=blockTile
number=11
data:
JSON:{blockState:{blockName:"ancientwarfarestructure:altar_candle"},teData:{customColor:1b,color:16711680,customData:"demon",unlocalizedNamePart:"faction",flameColor:16711680,id:"ancientwarfarestructure:altar_candle_tile"}}
:enddata
:endrule

rule:
plugin=blockTile
number=12
data:
JSON:{blockState:{blockName:"ancientwarfarestructure:altar_candle"},teData:{customColor:1b,color:16711680,customData:"demon",unlocalizedNamePart:"faction",flameColor:16711680,id:"ancientwarfarestructure:altar_candle_tile"}}
:enddata
:endrule

rule:
plugin=vanillaBlocks
number=13
data:
JSON:{blockState:{blockName:"minecraft:nether_brick_stairs",properties:{facing:"east",half:"top",shape:"straight"}}}
:enddata
:endrule

rule:
plugin=vanillaBlocks
number=14
data:
JSON:{blockState:{blockName:"minecraft:nether_brick_stairs",properties:{facing:"south",half:"top",shape:"straight"}}}
:enddata
:endrule

rule:
plugin=vanillaBlocks
number=15
data:
JSON:{blockState:{blockName:"minecraft:nether_brick_stairs",properties:{facing:"west",half:"top",shape:"straight"}}}
:enddata
:endrule

rule:
plugin=vanillaBlocks
number=16
data:
JSON:{blockState:{blockName:"minecraft:red_nether_brick"}}
:enddata
:endrule

rule:
plugin=vanillaBlocks
number=17
data:
JSON:{blockState:{blockName:"minecraft:cauldron",properties:{level:"0"}}}
:enddata
:endrule

rule:
plugin=blockTile
number=18
data:
JSON:{blockState:{blockName:"ancientwarfarestructure:advanced_spawner",properties:{transparent:"true"}},teData:{id:"ancientwarfarestructure:advanced_spawner_tile",spawnerSettings:{respondToRedstone:0b,minDelay:10,maxDelay:10,spawnDelay:8,playerRange:4,mobRange:0,spawnRange:0,maxNearbyMonsters:0,xpToDrop:0,lightSensitive:0b,transparent:1b,debugMode:0b,spawnGroups:[{groupWeight:1,settingsList:[{hostile:1b,entityId:"ancientwarfarenpc:faction.trader",customTag:{npcSubtype:"",HandDropChances:[0.085f,0.085f],factionName:"demon",npcType:"faction.archer.elite",HandItems:[{id:"minecraft:bow",Count:1b,Damage:0s},{}]},minToSpawn:1,maxToSpawn:1,remainingSpawnCount:1}]}],inventory:{Items:[],Size:9},spawnYOffset:0}}}
:enddata
:endrule

rule:
plugin=blockTile
number=19
data:
JSON:{blockState:{blockName:"ancientwarfarestructure:advanced_spawner",properties:{transparent:"true"}},teData:{id:"ancientwarfarestructure:advanced_spawner_tile",spawnerSettings:{respondToRedstone:0b,minDelay:10,maxDelay:10,spawnDelay:6,playerRange:4,mobRange:0,spawnRange:0,maxNearbyMonsters:0,xpToDrop:0,lightSensitive:0b,transparent:1b,debugMode:0b,spawnGroups:[{groupWeight:1,settingsList:[{hostile:1b,entityId:"ancientwarfarenpc:faction.archer.elite",customTag:{npcSubtype:"",HandDropChances:[0.085f,0.085f],factionName:"demon",npcType:"faction.archer.elite",HandItems:[{id:"minecraft:bow",Count:1b,Damage:0s},{}]},minToSpawn:1,maxToSpawn:1,remainingSpawnCount:1}]}],inventory:{Items:[],Size:9},spawnYOffset:0}}}
:enddata
:endrule

rule:
plugin=blockTile
number=20
data:
JSON:{blockState:{blockName:"ancientwarfarestructure:advanced_loot_chest",properties:{facing:"south"}},teData:{id:"ancientwarfarestructure:advanced_loot_chest_tile",Lock:"",Items:[],lootSettings:{hasLoot:1b,lootTableName:"ancientwarfare:chests/castle_armoury_gold",lootRolls:1,splashPotion:0b,spawnEntity:0b,hasMessage:0b}}}
:enddata
:endrule

rule:
plugin=vanillaBlocks
number=21
data:
JSON:{blockState:{blockName:"minecraft:anvil",properties:{damage:"2",facing:"east"}}}
:enddata
:endrule

rule:
plugin=blockTile
number=22
data:
JSON:{blockState:{blockName:"ancientwarfarestructure:advanced_loot_chest",properties:{facing:"east"}},teData:{id:"ancientwarfarestructure:advanced_loot_chest_tile",ForgeData:{},Lock:"",Items:[],lootSettings:{hasLoot:1b,lootTableName:"minecraft:chests/village_blacksmith",lootRolls:1,splashPotion:0b,spawnEntity:0b,entity:"minecraft:",hasMessage:0b}}}
:enddata
:endrule

rule:
plugin=blockTile
number=23
data:
JSON:{blockState:{blockName:"ancientwarfarestructure:advanced_spawner",properties:{transparent:"true"}},teData:{id:"ancientwarfarestructure:advanced_spawner_tile",spawnerSettings:{respondToRedstone:0b,minDelay:10,maxDelay:10,spawnDelay:8,playerRange:4,mobRange:0,spawnRange:0,maxNearbyMonsters:0,xpToDrop:0,lightSensitive:0b,transparent:1b,debugMode:0b,spawnGroups:[{groupWeight:1,settingsList:[{hostile:1b,entityId:"ancientwarfarenpc:faction.archer.elite",customTag:{npcSubtype:"",HandDropChances:[0.085f,0.085f],factionName:"demon",npcType:"faction.archer.elite",HandItems:[{id:"minecraft:bow",Count:1b,Damage:0s},{}]},minToSpawn:1,maxToSpawn:1,remainingSpawnCount:1}]}],inventory:{Items:[],Size:9},spawnYOffset:0}}}
:enddata
:endrule

rule:
plugin=blockTile
number=24
data:
JSON:{blockState:{blockName:"ancientwarfarestructure:advanced_loot_chest",properties:{facing:"south"}},teData:{id:"ancientwarfarestructure:advanced_loot_chest_tile",Lock:"",Items:[],lootSettings:{hasLoot:1b,lootTableName:"ancientwarfare:chests/castle_armoury_chainmail",lootRolls:1,splashPotion:0b,spawnEntity:0b,hasMessage:0b}}}
:enddata
:endrule

rule:
plugin=vanillaBlocks
number=25
data:
JSON:{blockState:{blockName:"minecraft:ladder",properties:{facing:"west"}}}
:enddata
:endrule

rule:
plugin=vanillaBlocks
number=26
data:
JSON:{blockState:{blockName:"minecraft:nether_brick_fence",properties:{east:"false",north:"false",south:"false",west:"false"}}}
:enddata
:endrule

rule:
plugin=vanillaBlocks
number=27
data:
JSON:{blockState:{blockName:"minecraft:crafting_table"}}
:enddata
:endrule

rule:
plugin=blockTile
number=28
data:
JSON:{blockState:{blockName:"ancientwarfarestructure:advanced_spawner",properties:{transparent:"true"}},teData:{id:"ancientwarfarestructure:advanced_spawner_tile",spawnerSettings:{respondToRedstone:0b,minDelay:10,maxDelay:10,spawnDelay:4,playerRange:4,mobRange:0,spawnRange:0,maxNearbyMonsters:0,xpToDrop:0,lightSensitive:0b,transparent:1b,debugMode:0b,spawnGroups:[{groupWeight:1,settingsList:[{hostile:1b,entityId:"ancientwarfarenpc:faction.civilian.female",customTag:{npcSubtype:"",HandDropChances:[0.085f,0.085f],factionName:"demon",npcType:"faction.archer.elite",HandItems:[{id:"minecraft:bow",Count:1b,Damage:0s},{}]},minToSpawn:1,maxToSpawn:1,remainingSpawnCount:1}]}],inventory:{Items:[],Size:9},spawnYOffset:0}}}
:enddata
:endrule

rule:
plugin=blockTile
number=29
data:
JSON:{blockState:{blockName:"ancientwarfarestructure:advanced_loot_chest",properties:{facing:"south"}},teData:{id:"ancientwarfarestructure:advanced_loot_chest_tile",Lock:"",Items:[],lootSettings:{hasLoot:1b,lootTableName:"ancientwarfare:chests/castle_pantry_meat_raw",lootRolls:1,splashPotion:0b,spawnEntity:0b,hasMessage:0b}}}
:enddata
:endrule

rule:
plugin=inventory
number=30
data:
JSON:{blockState:{blockName:"minecraft:furnace",properties:{facing:"north"}},teData:{id:"minecraft:furnace",ForgeCaps:{"levelup:cooking":{}},Lock:"",BurnTime:0,CookTime:0,CookTimeTotal:200,Items:[]},lootLevel:0,legacyFeatures:0b,inventoryData:{length:0,inventoryContents:[]}}
:enddata
:endrule

rule:
plugin=blockTile
number=31
data:
JSON:{blockState:{blockName:"ancientwarfarestructure:advanced_spawner",properties:{transparent:"true"}},teData:{id:"ancientwarfarestructure:advanced_spawner_tile",spawnerSettings:{respondToRedstone:0b,minDelay:10,maxDelay:10,spawnDelay:7,playerRange:4,mobRange:0,spawnRange:0,maxNearbyMonsters:0,xpToDrop:0,lightSensitive:0b,transparent:1b,debugMode:0b,spawnGroups:[{groupWeight:1,settingsList:[{hostile:1b,entityId:"ancientwarfarenpc:faction.civilian.female",customTag:{npcSubtype:"",HandDropChances:[0.085f,0.085f],factionName:"demon",npcType:"faction.archer.elite",HandItems:[{id:"minecraft:bow",Count:1b,Damage:0s},{}]},minToSpawn:1,maxToSpawn:1,remainingSpawnCount:1}]}],inventory:{Items:[],Size:9},spawnYOffset:0}}}
:enddata
:endrule

rule:
plugin=blockTile
number=32
data:
JSON:{blockState:{blockName:"ancientwarfarestructure:advanced_spawner",properties:{transparent:"true"}},teData:{id:"ancientwarfarestructure:advanced_spawner_tile",spawnerSettings:{respondToRedstone:0b,minDelay:10,maxDelay:10,spawnDelay:5,playerRange:4,mobRange:0,spawnRange:0,maxNearbyMonsters:0,xpToDrop:0,lightSensitive:0b,transparent:1b,debugMode:0b,spawnGroups:[{groupWeight:1,settingsList:[{hostile:1b,entityId:"ancientwarfarenpc:faction.soldier",customTag:{npcSubtype:"",HandDropChances:[0.085f,0.085f],factionName:"demon",npcType:"faction.archer.elite",HandItems:[{id:"minecraft:bow",Count:1b,Damage:0s},{}]},minToSpawn:1,maxToSpawn:1,remainingSpawnCount:1}]}],inventory:{Items:[],Size:9},spawnYOffset:0}}}
:enddata
:endrule

rule:
plugin=inventory
number=33
data:
JSON:{blockState:{blockName:"minecraft:furnace",properties:{facing:"west"}},teData:{id:"minecraft:furnace",ForgeCaps:{"levelup:cooking":{}},Lock:"",BurnTime:0,CookTime:0,CookTimeTotal:200,Items:[]},lootLevel:0,legacyFeatures:0b,inventoryData:{length:0,inventoryContents:[]}}
:enddata
:endrule

rule:
plugin=blockTile
number=34
data:
JSON:{blockState:{blockName:"ancientwarfarestructure:advanced_spawner",properties:{transparent:"true"}},teData:{id:"ancientwarfarestructure:advanced_spawner_tile",spawnerSettings:{respondToRedstone:0b,minDelay:10,maxDelay:10,spawnDelay:7,playerRange:4,mobRange:0,spawnRange:0,maxNearbyMonsters:0,xpToDrop:0,lightSensitive:0b,transparent:1b,debugMode:0b,spawnGroups:[{groupWeight:1,settingsList:[{hostile:1b,entityId:"ancientwarfarenpc:faction.soldier",customTag:{npcSubtype:"",HandDropChances:[0.085f,0.085f],factionName:"demon",npcType:"faction.archer.elite",HandItems:[{id:"minecraft:bow",Count:1b,Damage:0s},{}]},minToSpawn:1,maxToSpawn:1,remainingSpawnCount:1}]}],inventory:{Items:[],Size:9},spawnYOffset:0}}}
:enddata
:endrule

rule:
plugin=vanillaBlocks
number=35
data:
JSON:{blockState:{blockName:"ancientwarfarestructure:fire_pit",properties:{lit:"true",variant:"default"}}}
:enddata
:endrule

rule:
plugin=blockTile
number=36
data:
JSON:{blockState:{blockName:"ancientwarfarestructure:advanced_spawner",properties:{transparent:"true"}},teData:{id:"ancientwarfarestructure:advanced_spawner_tile",spawnerSettings:{respondToRedstone:0b,minDelay:10,maxDelay:10,spawnDelay:4,playerRange:4,mobRange:0,spawnRange:0,maxNearbyMonsters:0,xpToDrop:0,lightSensitive:0b,transparent:1b,debugMode:0b,spawnGroups:[{groupWeight:1,settingsList:[{hostile:1b,entityId:"ancientwarfarenpc:faction.civilian.female",customTag:{npcSubtype:"",HandDropChances:[0.085f,0.085f],factionName:"demon",npcType:"faction.archer.elite",HandItems:[{id:"minecraft:bow",Count:1b,Damage:0s},{}]},minToSpawn:1,maxToSpawn:1,remainingSpawnCount:1}]}],inventory:{Items:[],Size:9},spawnYOffset:0}}}
:enddata
:endrule

rule:
plugin=vanillaBlocks
number=37
data:
JSON:{blockState:{blockName:"futuremc:grindstone",properties:{face:"floor",facing:"west"}}}
:enddata
:endrule

rule:
plugin=blockTile
number=38
data:
JSON:{blockState:{blockName:"ancientwarfarestructure:altar_candle"},teData:{customColor:1b,color:16711680,customData:"demon",unlocalizedNamePart:"faction",flameColor:16711680,id:"ancientwarfarestructure:altar_candle_tile"}}
:enddata
:endrule

rule:
plugin=blockTile
number=39
data:
JSON:{blockState:{blockName:"ancientwarfarestructure:altar_candle"},teData:{customColor:1b,color:16711680,customData:"demon",unlocalizedNamePart:"faction",flameColor:16711680,id:"ancientwarfarestructure:altar_candle_tile"}}
:enddata
:endrule

rule:
plugin=blockTile
number=40
data:
JSON:{blockState:{blockName:"ancientwarfarestructure:altar_candle"},teData:{customColor:1b,color:16711680,customData:"demon",unlocalizedNamePart:"faction",flameColor:16711680,id:"ancientwarfarestructure:altar_candle_tile"}}
:enddata
:endrule

rule:
plugin=blockTile
number=41
data:
JSON:{blockState:{blockName:"ancientwarfarestructure:altar_candle"},teData:{customColor:1b,color:16711680,customData:"demon",unlocalizedNamePart:"faction",flameColor:16711680,id:"ancientwarfarestructure:altar_candle_tile"}}
:enddata
:endrule

rule:
plugin=inventory
number=42
data:
JSON:{blockState:{blockName:"minecraft:furnace",properties:{facing:"north"}},teData:{id:"minecraft:furnace",ForgeCaps:{"levelup:cooking":{}},Lock:"",BurnTime:0,CookTime:0,CookTimeTotal:200,Items:[]},lootLevel:0,legacyFeatures:0b,inventoryData:{length:0,inventoryContents:[]}}
:enddata
:endrule

rule:
plugin=inventory
number=43
data:
JSON:{blockState:{blockName:"minecraft:furnace",properties:{facing:"west"}},teData:{id:"minecraft:furnace",ForgeCaps:{"levelup:cooking":{}},Lock:"",BurnTime:0,CookTime:0,CookTimeTotal:200,Items:[]},lootLevel:0,legacyFeatures:0b,inventoryData:{length:0,inventoryContents:[]}}
:enddata
:endrule

rule:
plugin=blockTile
number=44
data:
JSON:{blockState:{blockName:"ancientwarfarestructure:altar_candle"},teData:{customColor:1b,color:16711680,customData:"demon",unlocalizedNamePart:"faction",flameColor:16711680,id:"ancientwarfarestructure:altar_candle_tile"}}
:enddata
:endrule

rule:
plugin=blockTile
number=45
data:
JSON:{blockState:{blockName:"ancientwarfarestructure:altar_candle"},teData:{customColor:1b,color:16711680,customData:"demon",unlocalizedNamePart:"faction",flameColor:16711680,id:"ancientwarfarestructure:altar_candle_tile"}}
:enddata
:endrule

rule:
plugin=blockTile
number=46
data:
JSON:{blockState:{blockName:"ancientwarfarestructure:altar_candle"},teData:{customColor:1b,color:16711680,customData:"demon",unlocalizedNamePart:"faction",flameColor:16711680,id:"ancientwarfarestructure:altar_candle_tile"}}
:enddata
:endrule

rule:
plugin=blockTile
number=47
data:
JSON:{blockState:{blockName:"ancientwarfarestructure:altar_candle"},teData:{customColor:1b,color:16711680,customData:"demon",unlocalizedNamePart:"faction",flameColor:16711680,id:"ancientwarfarestructure:altar_candle_tile"}}
:enddata
:endrule

rule:
plugin=blockTile
number=48
data:
JSON:{blockState:{blockName:"ancientwarfarestructure:altar_candle"},teData:{customColor:1b,color:16711680,customData:"demon",unlocalizedNamePart:"faction",flameColor:16711680,id:"ancientwarfarestructure:altar_candle_tile"}}
:enddata
:endrule

rule:
plugin=blockTile
number=49
data:
JSON:{blockState:{blockName:"ancientwarfarestructure:altar_candle"},teData:{customColor:1b,color:16711680,customData:"demon",unlocalizedNamePart:"faction",flameColor:16711680,id:"ancientwarfarestructure:altar_candle_tile"}}
:enddata
:endrule

rule:
plugin=blockTile
number=50
data:
JSON:{blockState:{blockName:"ancientwarfarestructure:altar_candle"},teData:{customColor:1b,color:16711680,customData:"demon",unlocalizedNamePart:"faction",flameColor:16711680,id:"ancientwarfarestructure:altar_candle_tile"}}
:enddata
:endrule

rule:
plugin=blockTile
number=51
data:
JSON:{blockState:{blockName:"ancientwarfarestructure:altar_candle"},teData:{customColor:1b,color:16711680,customData:"demon",unlocalizedNamePart:"faction",flameColor:16711680,id:"ancientwarfarestructure:altar_candle_tile"}}
:enddata
:endrule

rule:
plugin=vanillaBlocks
number=52
data:
JSON:{blockState:{blockName:"minecraft:stone_slab",properties:{half:"top",variant:"nether_brick"}}}
:enddata
:endrule

rule:
plugin=vanillaBlocks
number=53
data:
JSON:{blockState:{blockName:"minecraft:double_stone_slab",properties:{seamless:"false",variant:"nether_brick"}}}
:enddata
:endrule

rule:
plugin=blockTile
number=54
data:
JSON:{blockState:{blockName:"ancientwarfarestructure:altar_candle"},teData:{customColor:1b,color:16711680,customData:"demon",unlocalizedNamePart:"faction",flameColor:16711680,id:"ancientwarfarestructure:altar_candle_tile"}}
:enddata
:endrule

rule:
plugin=blockTile
number=55
data:
JSON:{blockState:{blockName:"ancientwarfarestructure:altar_candle"},teData:{customColor:1b,color:16711680,customData:"demon",unlocalizedNamePart:"faction",flameColor:16711680,id:"ancientwarfarestructure:altar_candle_tile"}}
:enddata
:endrule

rule:
plugin=blockTile
number=56
data:
JSON:{blockState:{blockName:"ancientwarfarestructure:altar_candle"},teData:{customColor:1b,color:16711680,customData:"demon",unlocalizedNamePart:"faction",flameColor:16711680,id:"ancientwarfarestructure:altar_candle_tile"}}
:enddata
:endrule

rule:
plugin=vanillaBlocks
number=57
data:
JSON:{blockState:{blockName:"minecraft:soul_sand"}}
:enddata
:endrule

rule:
plugin=blockTile
number=58
data:
JSON:{blockState:{blockName:"ancientwarfarestructure:altar_candle"},teData:{customColor:1b,color:16711680,customData:"demon",unlocalizedNamePart:"faction",flameColor:16711680,id:"ancientwarfarestructure:altar_candle_tile"}}
:enddata
:endrule

rule:
plugin=blockTile
number=59
data:
JSON:{blockState:{blockName:"ancientwarfarestructure:altar_candle"},teData:{customColor:1b,color:16711680,customData:"demon",unlocalizedNamePart:"faction",flameColor:16711680,id:"ancientwarfarestructure:altar_candle_tile"}}
:enddata
:endrule

rule:
plugin=blockTile
number=60
data:
JSON:{blockState:{blockName:"ancientwarfarestructure:altar_candle"},teData:{customColor:1b,color:16711680,customData:"demon",unlocalizedNamePart:"faction",flameColor:16711680,id:"ancientwarfarestructure:altar_candle_tile"}}
:enddata
:endrule

rule:
plugin=blockTile
number=61
data:
JSON:{blockState:{blockName:"ancientwarfarestructure:altar_candle"},teData:{customColor:1b,color:16711680,customData:"demon",unlocalizedNamePart:"faction",flameColor:16711680,id:"ancientwarfarestructure:altar_candle_tile"}}
:enddata
:endrule

rule:
plugin=blockTile
number=62
data:
JSON:{blockState:{blockName:"ancientwarfarestructure:altar_candle"},teData:{customColor:1b,color:16711680,customData:"demon",unlocalizedNamePart:"faction",flameColor:16711680,id:"ancientwarfarestructure:altar_candle_tile"}}
:enddata
:endrule

rule:
plugin=blockTile
number=63
data:
JSON:{blockState:{blockName:"ancientwarfarestructure:altar_candle"},teData:{customColor:1b,color:16711680,customData:"demon",unlocalizedNamePart:"faction",flameColor:16711680,id:"ancientwarfarestructure:altar_candle_tile"}}
:enddata
:endrule

rule:
plugin=blockTile
number=64
data:
JSON:{blockState:{blockName:"ancientwarfarestructure:altar_candle"},teData:{customColor:1b,color:16711680,customData:"demon",unlocalizedNamePart:"faction",flameColor:16711680,id:"ancientwarfarestructure:altar_candle_tile"}}
:enddata
:endrule

rule:
plugin=blockTile
number=65
data:
JSON:{blockState:{blockName:"ancientwarfarestructure:altar_candle"},teData:{customColor:1b,color:16711680,customData:"demon",unlocalizedNamePart:"faction",flameColor:16711680,id:"ancientwarfarestructure:altar_candle_tile"}}
:enddata
:endrule

rule:
plugin=blockTile
number=66
data:
JSON:{blockState:{blockName:"ancientwarfarestructure:altar_candle"},teData:{customColor:1b,color:16711680,customData:"demon",unlocalizedNamePart:"faction",flameColor:16711680,id:"ancientwarfarestructure:altar_candle_tile"}}
:enddata
:endrule

rule:
plugin=vanillaBlocks
number=67
data:
JSON:{blockState:{blockName:"minecraft:nether_wart",properties:{age:"2"}}}
:enddata
:endrule

rule:
plugin=vanillaBlocks
number=68
data:
JSON:{blockState:{blockName:"minecraft:nether_wart",properties:{age:"1"}}}
:enddata
:endrule

rule:
plugin=vanillaBlocks
number=69
data:
JSON:{blockState:{blockName:"minecraft:nether_wart",properties:{age:"0"}}}
:enddata
:endrule

rule:
plugin=vanillaBlocks
number=70
data:
JSON:{blockState:{blockName:"minecraft:nether_wart",properties:{age:"3"}}}
:enddata
:endrule

rule:
plugin=blockTile
number=71
data:
JSON:{blockState:{blockName:"ancientwarfarestructure:altar_candle"},teData:{customColor:1b,color:16711680,customData:"demon",unlocalizedNamePart:"faction",flameColor:16711680,id:"ancientwarfarestructure:altar_candle_tile"}}
:enddata
:endrule

rule:
plugin=vanillaBlocks
number=72
data:
JSON:{blockState:{blockName:"minecraft:stone_slab",properties:{half:"bottom",variant:"nether_brick"}}}
:enddata
:endrule

rule:
plugin=blockTile
number=73
data:
JSON:{blockState:{blockName:"ancientwarfarestructure:altar_candle"},teData:{customColor:1b,color:16711680,customData:"demon",unlocalizedNamePart:"faction",flameColor:16711680,id:"ancientwarfarestructure:altar_candle_tile"}}
:enddata
:endrule

rule:
plugin=blockTile
number=74
data:
JSON:{blockState:{blockName:"ancientwarfarestructure:altar_candle"},teData:{customColor:1b,color:16711680,customData:"demon",unlocalizedNamePart:"faction",flameColor:16711680,id:"ancientwarfarestructure:altar_candle_tile"}}
:enddata
:endrule

rule:
plugin=blockTile
number=75
data:
JSON:{blockState:{blockName:"ancientwarfarestructure:altar_candle"},teData:{customColor:1b,color:16711680,customData:"demon",unlocalizedNamePart:"faction",flameColor:16711680,id:"ancientwarfarestructure:altar_candle_tile"}}
:enddata
:endrule

rule:
plugin=blockTile
number=76
data:
JSON:{blockState:{blockName:"ancientwarfarestructure:altar_candle"},teData:{customColor:1b,color:16711680,customData:"demon",unlocalizedNamePart:"faction",flameColor:16711680,id:"ancientwarfarestructure:altar_candle_tile"}}
:enddata
:endrule

rule:
plugin=blockTile
number=77
data:
JSON:{blockState:{blockName:"ancientwarfarestructure:altar_candle"},teData:{customColor:1b,color:16711680,customData:"demon",unlocalizedNamePart:"faction",flameColor:16711680,id:"ancientwarfarestructure:altar_candle_tile"}}
:enddata
:endrule

rule:
plugin=blockTile
number=78
data:
JSON:{blockState:{blockName:"ancientwarfarestructure:altar_candle"},teData:{customColor:1b,color:16711680,customData:"demon",unlocalizedNamePart:"faction",flameColor:16711680,id:"ancientwarfarestructure:altar_candle_tile"}}
:enddata
:endrule

rule:
plugin=blockTile
number=79
data:
JSON:{blockState:{blockName:"ancientwarfarestructure:altar_candle"},teData:{customColor:1b,color:16711680,customData:"demon",unlocalizedNamePart:"faction",flameColor:16711680,id:"ancientwarfarestructure:altar_candle_tile"}}
:enddata
:endrule

rule:
plugin=flag
number=80
data:
JSON:{blockState:{blockName:"ancientwarfarestructure:decorative_flag",properties:{rotation:"4"}},teData:{id:"ancientwarfarestructure:decorative_flag_tile",name:"demon"}}
:enddata
:endrule

rule:
plugin=flag
number=81
data:
JSON:{blockState:{blockName:"ancientwarfarestructure:decorative_flag",properties:{rotation:"0"}},teData:{id:"ancientwarfarestructure:decorative_flag_tile",name:"demon"}}
:enddata
:endrule

rule:
plugin=flag
number=82
data:
JSON:{blockState:{blockName:"ancientwarfarestructure:decorative_flag",properties:{rotation:"8"}},teData:{id:"ancientwarfarestructure:decorative_flag_tile",name:"demon"}}
:enddata
:endrule

rule:
plugin=flag
number=83
data:
JSON:{blockState:{blockName:"ancientwarfarestructure:decorative_flag",properties:{rotation:"12"}},teData:{id:"ancientwarfarestructure:decorative_flag_tile",name:"demon"}}
:enddata
:endrule

rule:
plugin=flag
number=84
data:
JSON:{blockState:{blockName:"ancientwarfarestructure:decorative_flag",properties:{rotation:"4"}},teData:{id:"ancientwarfarestructure:decorative_flag_tile",name:"demon"}}
:enddata
:endrule

rule:
plugin=flag
number=85
data:
JSON:{blockState:{blockName:"ancientwarfarestructure:decorative_flag",properties:{rotation:"0"}},teData:{id:"ancientwarfarestructure:decorative_flag_tile",name:"demon"}}
:enddata
:endrule

rule:
plugin=flag
number=86
data:
JSON:{blockState:{blockName:"ancientwarfarestructure:decorative_flag",properties:{rotation:"8"}},teData:{id:"ancientwarfarestructure:decorative_flag_tile",name:"demon"}}
:enddata
:endrule

rule:
plugin=flag
number=87
data:
JSON:{blockState:{blockName:"ancientwarfarestructure:decorative_flag",properties:{rotation:"12"}},teData:{id:"ancientwarfarestructure:decorative_flag_tile",name:"demon"}}
:enddata
:endrule

rule:
plugin=flag
number=88
data:
JSON:{blockState:{blockName:"ancientwarfarestructure:decorative_flag",properties:{rotation:"4"}},teData:{id:"ancientwarfarestructure:decorative_flag_tile",name:"demon"}}
:enddata
:endrule

rule:
plugin=flag
number=89
data:
JSON:{blockState:{blockName:"ancientwarfarestructure:decorative_flag",properties:{rotation:"0"}},teData:{id:"ancientwarfarestructure:decorative_flag_tile",name:"demon"}}
:enddata
:endrule

rule:
plugin=blockTile
number=90
data:
JSON:{blockState:{blockName:"ancientwarfarestructure:altar_candle"},teData:{customColor:1b,color:16711680,customData:"demon",unlocalizedNamePart:"faction",flameColor:16711680,id:"ancientwarfarestructure:altar_candle_tile"}}
:enddata
:endrule

rule:
plugin=flag
number=91
data:
JSON:{blockState:{blockName:"ancientwarfarestructure:decorative_flag",properties:{rotation:"8"}},teData:{id:"ancientwarfarestructure:decorative_flag_tile",name:"demon"}}
:enddata
:endrule

rule:
plugin=flag
number=92
data:
JSON:{blockState:{blockName:"ancientwarfarestructure:decorative_flag",properties:{rotation:"12"}},teData:{id:"ancientwarfarestructure:decorative_flag_tile",name:"demon"}}
:enddata
:endrule

#### ENTITIES ####
entity:
plugin=entity
number=0
data:
JSON:{position:1649602985990L,mobID:"minecraft:armor_stand",xOffset:0.5f,yOffset:0.0f,zOffset:0.5f,rotation:0.0f,entityData:{Pos:[-256.5d,25.0d,-670.5d],Motion:[0.0d,-0.0784000015258789d,0.0d],Rotation:[90.0f,0.0f],FallDistance:0.0f,Fire:-1s,Air:300s,OnGround:1b,Dimension:0,Invulnerable:0b,PortalCooldown:0,AABB:[-256.75d,25.0d,-670.75d,-256.25d,26.975000023841858d,-670.25d],UpdateBlocked:0b,ForgeData:{"Potion Core - Health Fix":20.0f,"Potion Core - Jump Boost Updated":1b,srpcothimmunity:0},ForgeCaps:{"llibrary:extendedentitydatacapability":{"Ice and Fire - Player Property Tracker":{DismountedDragon:0b,GauntletDamage:0,DreadPortalX:0,DreadPortalY:0,DreadPortalZ:0},"Ice And Fire - Frozen Property Tracker":{IsFrozen:0b,TicksUntilUnfrozen:0},"Ice And Fire - Siren Property Tracker":{CharmedBySiren:0b,SirenID:0},"Ice And Fire - Chain Property Tracker":{ConnectedEntities:[]},"mm:living":{freezeProgress:0.0f,frozenYaw:0.0f,frozenPitch:0.0f,frozenYawHead:0.0f,frozenRenderYawOffset:0.0f,frozenSwingProgress:0.0f,frozenLimbSwingAmount:0.0f,prevHasAI:0b,freezeDecayDelay:0}},"ancientwarfarestructure:respawn_data":{},"twilightforest:cap_shield":{tempshields:0,permshields:0},"liketechnikstinkertweaks:entityxp":[],"somanyenchantments:player_capabilities":{isResurrecting:0b,moralitasDamage:0.0d}},Health:20.0f,HurtTime:0s,HurtByTimestamp:0,DeathTime:0s,AbsorptionAmount:0.0f,Attributes:[{Name:"potioncore.projectileDamage",Base:1.0d},{Name:"potioncore.magicDamage",Base:1.0d},{Name:"potioncore.jumpHeight",Base:1.0d},{Name:"potioncore.damageResistance",Base:1.0d},{Name:"potioncore.magicShielding",Base:0.0d},{Name:"generic.maxHealth",Base:20.0d},{Name:"generic.knockbackResistance",Base:0.0d},{Name:"generic.movementSpeed",Base:0.699999988079071d},{Name:"generic.armor",Base:0.0d},{Name:"generic.armorToughness",Base:0.0d},{Name:"forge.swimSpeed",Base:1.0d}],FallFlying:0b,ArmorItems:[{id:"minecraft:golden_boots",Count:1b,Damage:0s},{id:"minecraft:golden_leggings",Count:1b,Damage:0s},{id:"minecraft:golden_chestplate",Count:1b,Damage:0s},{id:"minecraft:golden_helmet",Count:1b,Damage:0s}],HandItems:[{},{}],Invisible:0b,Small:0b,ShowArms:1b,DisabledSlots:0,NoBasePlate:0b,Pose:{Head:[4.2350106f,5.742339f,0.0f],Body:[0.0f,4.0998335f,0.0f]}}}
:enddata
:endentity

entity:
plugin=entity
number=1
data:
JSON:{position:1924480892934L,mobID:"minecraft:armor_stand",xOffset:0.5f,yOffset:0.0f,zOffset:0.5f,rotation:0.0f,entityData:{Pos:[-256.5d,25.0d,-669.5d],Motion:[0.0d,-0.0784000015258789d,0.0d],Rotation:[90.0f,0.0f],FallDistance:0.0f,Fire:-1s,Air:300s,OnGround:1b,Dimension:0,Invulnerable:0b,PortalCooldown:0,AABB:[-256.75d,25.0d,-669.75d,-256.25d,26.975000023841858d,-669.25d],UpdateBlocked:0b,ForgeData:{"Potion Core - Health Fix":20.0f,"Potion Core - Jump Boost Updated":1b,srpcothimmunity:0},ForgeCaps:{"llibrary:extendedentitydatacapability":{"Ice and Fire - Player Property Tracker":{DismountedDragon:0b,GauntletDamage:0,DreadPortalX:0,DreadPortalY:0,DreadPortalZ:0},"Ice And Fire - Frozen Property Tracker":{IsFrozen:0b,TicksUntilUnfrozen:0},"Ice And Fire - Siren Property Tracker":{CharmedBySiren:0b,SirenID:0},"Ice And Fire - Chain Property Tracker":{ConnectedEntities:[]},"mm:living":{freezeProgress:0.0f,frozenYaw:0.0f,frozenPitch:0.0f,frozenYawHead:0.0f,frozenRenderYawOffset:0.0f,frozenSwingProgress:0.0f,frozenLimbSwingAmount:0.0f,prevHasAI:0b,freezeDecayDelay:0}},"ancientwarfarestructure:respawn_data":{},"twilightforest:cap_shield":{tempshields:0,permshields:0},"liketechnikstinkertweaks:entityxp":[],"somanyenchantments:player_capabilities":{isResurrecting:0b,moralitasDamage:0.0d}},Health:20.0f,HurtTime:0s,HurtByTimestamp:0,DeathTime:0s,AbsorptionAmount:0.0f,Attributes:[{Name:"potioncore.projectileDamage",Base:1.0d},{Name:"potioncore.magicDamage",Base:1.0d},{Name:"potioncore.jumpHeight",Base:1.0d},{Name:"potioncore.damageResistance",Base:1.0d},{Name:"potioncore.magicShielding",Base:0.0d},{Name:"generic.maxHealth",Base:20.0d},{Name:"generic.knockbackResistance",Base:0.0d},{Name:"generic.movementSpeed",Base:0.699999988079071d},{Name:"generic.armor",Base:0.0d},{Name:"generic.armorToughness",Base:0.0d},{Name:"forge.swimSpeed",Base:1.0d}],FallFlying:0b,ArmorItems:[{id:"minecraft:chainmail_boots",Count:1b,Damage:0s},{id:"minecraft:chainmail_leggings",Count:1b,Damage:0s},{id:"minecraft:chainmail_chestplate",Count:1b,Damage:0s},{id:"minecraft:chainmail_helmet",Count:1b,Damage:0s}],HandItems:[{},{}],Invisible:0b,Small:0b,ShowArms:1b,DisabledSlots:0,NoBasePlate:0b,Pose:{Head:[4.1115217f,6.7061577f,0.0f],Body:[0.0f,-2.8083336f,0.0f]}}}
:enddata
:endentity

