
# Created by Ruins mod version 16.7 Ingame Parser
# authoring Player: lafuller

weight=1
embed_into_distance=13
acceptable_target_blocks=water,waterlily
unacceptable_target_blocks=
biomesToSpawnIn=swampland,jungle,marsh,bog,wetland,mini_jungle,lush_swamp,green_swamp,dead_swamp,tropical_island,land_of_lakes
dimensions=31,10,12
allowable_overhang=0
max_leveling=20
leveling_buffer=-1
preserve_water=0
preserve_lava=0

rule1=0,100,preserveBlock
rule2=0,100,minecraft:log2-1
rule3=0,100,minecraft:log2-5
rule4=0,100,minecraft:log2-9
rule5=0,100,minecraft:spruce_fence-0
rule6=0,100,minecraft:ladder-5
rule7=0,100,minecraft:log-3
rule8=0,100,minecraft:log-7
rule9=0,100,minecraft:log-11
rule10=0,100,minecraft:wooden_slab-9
rule11=0,100,minecraft:wooden_slab-8
rule12=0,100,minecraft:spruce_stairs-0
rule13=0,100,minecraft:spruce_stairs-3
rule14=0,100,minecraft:spruce_stairs-2
rule15=0,100,minecraft:trapdoor-7
rule16=0,100,minecraft:ladder-2
rule17=0,100,minecraft:spruce_stairs-1
rule18=0,100,minecraft:spruce_fence_gate-2
rule19=0,100,minecraft:spruce_fence_gate-0
rule20=0,100,minecraft:spruce_fence_gate-3
rule21=0,100,minecraft:spruce_fence_gate-1
rule22=0,100,minecraft:spruce_stairs-4
rule23=0,100,minecraft:spruce_stairs-7
rule24=0,100,minecraft:spruce_stairs-6
rule25=0,100,minecraft:spruce_stairs-5
rule26=0,100,minecraft:wooden_slab-1
rule27=0,100,minecraft:dark_oak_stairs-4
rule28=0,100,minecraft:dark_oak_stairs-6
rule29=0,100,minecraft:wooden_slab-13
rule30=0,100,minecraft:wooden_slab-5
rule31=0,100,minecraft:double_wooden_slab-5
rule32=0,100,minecraft:planks-1
rule33=0,100,minecraft:dark_oak_stairs-7
rule34=0,100,minecraft:dark_oak_stairs-1
rule35=0,100,minecraft:trapdoor-4

layer
1,1,1,1,1,1,1,1,1,1,1,1
1,1,1,1,1,1,1,1,1,1,1,1
1,1,1,2,1,1,1,1,1,1,1,1
1,1,1,1,1,1,2,1,1,1,1,1
1,1,1,2,1,1,1,1,1,2,1,1
1,1,1,1,1,1,1,1,1,1,1,1
1,1,1,1,1,1,1,1,1,1,1,1
1,1,2,1,1,1,1,2,1,1,1,1
1,1,1,1,1,1,1,1,1,1,1,1
1,1,1,1,1,1,1,1,1,1,1,1
endlayer

layer
1,1,1,1,1,1,1,1,1,1,1,1
1,1,1,1,1,1,1,1,1,1,1,1
1,1,1,2,1,1,1,1,1,1,1,1
1,1,1,1,1,1,2,1,1,1,1,1
1,1,1,2,1,1,1,1,1,2,1,1
1,1,1,1,1,1,1,1,1,1,1,1
1,1,1,1,1,1,1,1,1,1,1,1
1,1,2,1,1,1,1,2,1,1,1,1
1,1,1,1,1,1,1,1,1,1,1,1
1,1,1,1,1,1,1,1,1,1,1,1
endlayer

layer
1,1,1,1,1,1,1,1,1,1,1,1
1,1,1,1,1,1,1,1,1,1,1,1
1,1,1,2,1,1,1,1,1,1,1,1
1,1,1,1,1,1,2,1,1,1,1,1
1,1,1,2,1,1,1,1,1,2,1,1
1,1,1,1,1,1,1,1,1,1,1,1
1,1,1,1,1,1,1,1,1,1,1,1
1,1,2,1,1,1,1,2,1,1,1,1
1,1,1,1,1,1,1,1,1,1,1,1
1,1,1,1,1,1,1,1,1,1,1,1
endlayer

layer
1,1,1,1,1,1,1,1,1,1,1,1
1,1,1,1,1,1,1,1,1,1,1,1
1,1,1,2,1,1,1,1,1,1,1,1
1,1,1,1,1,1,2,1,1,1,1,1
1,1,1,2,1,1,1,1,1,2,1,1
1,1,1,1,1,1,1,1,1,1,1,1
1,1,1,1,1,1,1,1,1,1,1,1
1,1,2,1,1,1,1,2,1,1,1,1
1,1,1,1,1,1,1,1,1,1,1,1
1,1,1,1,1,1,1,1,1,1,1,1
endlayer

layer
1,1,1,1,1,1,1,1,1,1,1,1
1,1,1,1,1,1,1,1,1,1,1,1
1,1,1,2,1,1,1,1,1,1,1,1
1,1,1,1,1,1,2,1,1,1,1,1
1,1,1,2,1,1,1,1,1,2,1,1
1,1,1,1,1,1,1,1,1,1,1,1
1,1,1,1,1,1,1,1,1,1,1,1
1,1,2,1,1,1,1,2,1,1,1,1
1,1,1,1,1,1,1,1,1,1,1,1
1,1,1,1,1,1,1,1,1,1,1,1
endlayer

layer
1,1,1,1,1,1,1,1,1,1,1,1
1,1,1,1,1,1,1,1,1,1,1,1
1,1,1,2,1,1,1,1,1,1,1,1
1,1,1,1,1,1,2,1,1,1,1,1
1,1,1,2,1,1,1,1,1,2,1,1
1,1,1,1,1,1,1,1,1,1,1,1
1,1,1,1,1,1,1,1,1,1,1,1
1,1,2,1,1,1,1,2,1,1,1,1
1,1,1,1,1,1,1,1,1,1,1,1
1,1,1,1,1,1,1,1,1,1,1,1
endlayer

layer
1,1,1,1,1,1,1,1,1,1,1,1
1,1,1,1,1,1,1,1,1,1,1,1
1,1,1,2,1,1,1,1,1,1,1,1
1,1,1,1,1,1,2,1,1,1,1,1
1,1,1,2,1,1,1,1,1,2,1,1
1,1,1,1,1,1,1,1,1,1,1,1
1,1,1,1,1,1,1,1,1,1,1,1
1,1,2,1,1,1,1,2,1,1,1,1
1,1,1,1,1,1,1,1,1,1,1,1
1,1,1,1,1,1,1,1,1,1,1,1
endlayer

layer
1,1,1,1,1,1,1,1,1,1,1,1
1,1,1,1,1,1,1,1,1,1,1,1
1,1,1,2,1,1,1,1,1,1,1,1
1,1,1,1,1,1,2,1,1,1,1,1
1,1,1,2,1,1,1,1,1,2,1,1
1,1,1,1,1,1,1,1,1,1,1,1
1,1,1,1,1,1,1,1,1,1,1,1
1,1,2,1,1,1,1,2,1,1,1,1
1,1,1,1,1,1,1,1,1,1,1,1
1,1,1,1,1,1,1,1,1,1,1,1
endlayer

layer
1,1,1,1,1,1,1,1,1,1,1,1
1,1,1,1,1,1,1,1,1,1,1,1
1,1,1,2,1,1,1,1,1,1,1,1
1,1,1,1,1,1,2,1,1,1,1,1
1,1,1,2,1,1,1,1,1,2,1,1
1,1,1,1,1,1,1,1,1,1,1,1
1,1,1,1,1,1,1,1,1,1,1,1
1,1,2,1,1,1,1,2,1,1,1,1
1,1,1,1,1,1,1,1,1,1,1,1
1,1,1,1,1,1,1,1,1,1,1,1
endlayer

layer
1,1,1,1,1,1,1,1,1,1,1,1
1,1,1,1,1,1,1,1,1,1,1,1
1,1,1,2,1,1,1,1,1,1,1,1
1,1,1,1,1,1,2,1,1,1,1,1
1,1,1,2,1,1,1,1,1,2,1,1
1,1,1,1,1,1,1,1,1,1,1,1
1,1,1,1,1,1,1,1,1,1,1,1
1,1,2,1,1,1,1,2,1,1,1,1
1,1,1,1,1,1,1,1,1,1,1,1
1,1,1,1,1,1,1,1,1,1,1,1
endlayer

layer
1,1,1,1,1,1,1,1,1,1,1,1
1,1,1,1,1,1,1,1,1,1,1,1
1,1,1,2,1,1,1,1,1,1,1,1
1,1,1,1,1,1,2,1,1,1,1,1
1,1,1,2,1,1,1,1,1,2,1,1
1,1,1,1,1,1,1,1,1,1,1,1
1,1,1,1,1,1,1,1,1,1,1,1
1,1,2,1,1,1,1,2,1,1,1,1
1,1,1,1,1,1,1,1,1,1,1,1
1,1,1,1,1,1,1,1,1,1,1,1
endlayer

layer
1,1,1,1,1,1,1,1,1,1,1,1
1,1,1,1,1,1,1,1,1,1,1,1
1,4,4,4,4,4,4,4,4,3,1,1
1,1,1,1,1,1,2,1,1,3,1,1
1,1,1,2,1,1,1,1,1,3,1,1
1,1,1,1,1,1,1,1,1,3,1,1
1,4,4,4,4,4,4,4,4,3,1,1
1,1,2,1,1,1,1,2,1,1,1,1
1,1,1,1,1,1,1,1,1,1,1,1
1,1,1,1,1,1,1,1,1,1,1,1
endlayer

layer
1,1,1,1,1,1,1,1,1,1,1,1
1,1,3,1,1,1,1,3,1,1,1,1
1,1,3,2,1,1,1,3,1,1,1,1
1,1,3,1,1,1,2,3,1,1,1,1
1,1,3,2,1,1,1,1,1,2,1,1
1,1,3,1,1,1,1,1,1,1,1,1
1,1,3,1,1,1,1,1,1,1,1,1
1,1,3,1,1,1,1,3,1,1,1,1
1,1,3,1,1,1,1,3,1,1,1,1
1,1,1,1,1,1,1,1,1,1,1,1
endlayer

layer
1,1,1,1,1,1,1,1,1,1,1,1
1,1,1,1,1,1,1,1,1,1,1,1
1,1,1,2,1,1,1,1,1,1,1,1
5,4,4,4,4,4,4,4,4,4,4,5
1,1,1,2,1,1,1,1,1,2,1,1
1,1,1,1,1,1,1,1,1,6,1,1
1,1,1,1,1,1,1,1,1,1,1,1
1,1,2,1,1,1,1,2,1,1,1,1
1,1,1,1,1,1,1,1,1,1,1,1
1,1,1,1,1,1,1,1,1,1,1,1
endlayer

layer
1,1,1,1,1,1,5,1,1,1,1,1
1,1,1,1,1,1,3,1,1,1,1,1
1,1,1,7,1,1,3,1,1,1,1,1
1,1,1,1,1,1,3,1,1,1,1,1
1,1,1,2,1,1,3,1,1,7,1,1
1,1,1,1,1,1,3,1,1,6,1,1
1,1,1,1,1,1,3,1,1,1,1,1
1,1,7,1,1,1,3,7,1,1,1,1
1,1,1,1,1,1,3,1,1,1,1,1
1,1,1,1,1,1,5,1,1,1,1,1
endlayer

layer
1,1,1,5,1,1,1,1,1,1,1,1
1,1,1,8,1,1,1,1,1,1,1,1
5,9,9,8,9,9,9,9,5,1,1,1
1,1,10,8,11,11,7,10,10,1,1,1
5,9,9,8,9,9,9,9,9,7,10,1
1,1,10,8,11,11,11,11,8,6,10,1
1,1,10,8,9,9,9,9,8,10,10,1
5,9,9,8,11,10,10,7,8,10,1,1
1,1,1,8,1,1,1,1,8,1,1,1
1,1,1,5,1,1,1,1,5,1,1,1
endlayer

layer
1,1,1,1,1,1,1,1,1,1,1,1
1,1,1,1,1,1,1,1,1,1,1,1
1,1,12,7,12,12,1,1,1,1,1,1
1,1,13,0,0,0,7,12,12,1,1,1
1,1,13,0,0,0,0,0,0,7,12,1
1,1,13,0,0,0,0,0,0,15,14,1
1,1,13,0,0,7,16,0,0,0,14,1
1,1,7,0,0,14,17,17,7,17,1,1
1,1,1,17,17,14,1,1,1,1,1,1
1,1,1,1,1,1,1,1,1,1,1,1
endlayer

layer
1,1,1,1,1,1,1,1,1,1,1,1
1,1,1,1,1,1,1,1,1,1,1,1
1,1,5,7,5,5,1,1,1,1,1,1
1,1,5,0,0,0,7,5,5,1,1,1
1,1,18,0,0,0,0,0,0,7,5,1
1,1,18,0,0,0,0,0,0,0,19,1
1,1,5,0,0,7,16,0,0,0,5,1
1,1,7,0,0,5,20,5,7,5,1,1
1,1,1,5,21,5,1,1,1,1,1,1
1,1,1,1,1,1,1,1,1,1,1,1
endlayer

layer
1,1,1,1,1,1,1,1,1,1,1,1
1,1,1,1,1,1,1,1,1,1,1,1
1,1,22,7,22,22,1,1,1,1,1,1
1,1,23,0,0,0,7,22,22,1,1,1
1,1,23,0,0,0,0,0,0,7,22,1
1,1,23,0,0,0,0,0,0,0,24,1
1,1,23,0,0,7,16,0,0,0,24,1
1,1,7,0,0,25,25,25,7,25,1,1
1,1,13,25,25,24,1,1,1,1,1,1
1,1,1,1,1,1,1,1,1,1,1,1
endlayer

layer
1,1,1,1,1,1,1,1,1,1,1,1
1,1,1,1,1,8,1,1,1,1,1,1
1,1,13,7,12,8,5,1,1,1,1,1
1,1,13,26,26,8,7,12,12,14,1,1
1,1,13,26,26,8,26,0,0,7,14,1
1,1,13,26,26,8,26,0,0,0,14,1
1,1,13,26,26,8,16,0,0,0,14,1
1,1,7,26,26,8,17,17,7,17,1,1
1,1,1,17,17,8,1,1,1,1,1,1
1,1,1,1,1,1,1,1,1,1,1,1
endlayer

layer
1,1,1,1,1,1,1,1,1,1,1,1
1,1,1,1,1,1,1,1,1,1,1,1
1,1,5,7,5,5,5,1,1,1,1,1
1,1,18,0,0,0,7,5,5,1,1,1
1,1,18,0,0,0,0,0,0,7,5,1
1,1,5,0,0,0,0,0,0,0,5,1
1,1,18,0,0,7,16,0,0,0,5,1
1,1,7,21,21,5,5,5,7,5,1,1
1,1,1,1,1,1,1,1,1,1,1,1
1,1,1,1,1,1,1,1,1,1,1,1
endlayer

layer
1,1,1,1,1,1,1,1,1,1,1,1
1,1,1,1,1,1,1,1,1,1,1,1
1,1,27,7,22,22,5,1,1,1,1,1
1,29,28,0,0,0,7,22,22,22,1,1
1,29,28,0,0,0,0,0,0,7,24,1
1,29,28,0,0,0,0,0,0,0,24,1
1,29,28,0,0,7,16,0,0,0,24,1
1,29,7,25,25,25,25,25,7,25,24,1
1,1,29,29,29,1,1,1,1,1,1,1
1,1,1,1,1,1,1,1,1,1,1,1
endlayer

layer
1,1,1,1,1,1,1,1,1,1,1,1
1,1,1,1,1,1,1,1,1,1,1,1
1,1,1,30,30,30,30,30,1,1,1,1
1,1,1,30,29,29,7,31,31,30,1,1
1,1,30,30,29,10,0,0,0,7,30,1
1,1,30,30,29,10,0,0,0,31,30,1
1,1,30,30,29,7,16,0,0,31,30,1
1,1,30,30,31,31,31,31,7,31,30,1
1,1,1,30,30,30,30,30,30,30,1,1
1,1,1,1,1,1,1,1,1,1,1,1
endlayer

layer
1,1,1,1,1,1,1,1,1,1,1,1
1,1,1,1,1,1,1,1,1,1,1,1
1,1,1,1,1,1,1,1,1,1,1,1
1,1,1,1,1,1,7,12,12,1,1,1
1,1,1,1,1,13,0,0,0,7,1,1
1,1,1,1,1,13,0,0,0,14,1,1
1,1,1,1,1,7,16,0,0,14,1,1
1,1,1,1,1,5,21,5,7,5,1,1
1,1,1,1,1,1,1,1,1,1,1,1
1,1,1,1,1,1,1,1,1,1,1,1
endlayer

layer
1,1,1,1,1,1,1,1,1,1,1,1
1,1,1,1,1,1,1,1,1,1,1,1
1,1,1,1,1,1,1,1,1,1,1,1
1,1,1,1,1,1,7,5,5,1,1,1
1,1,1,1,1,5,0,0,0,7,1,1
1,1,1,1,1,5,0,0,0,5,1,1
1,1,1,1,1,7,16,0,0,5,1,1
1,1,1,1,1,5,21,5,7,5,1,1
1,1,1,1,1,1,1,1,1,1,1,1
1,1,1,1,1,1,1,1,1,1,1,1
endlayer

layer
1,1,1,1,1,1,1,1,1,1,1,1
1,1,1,1,1,1,1,1,1,1,1,1
1,1,1,1,1,1,1,1,1,1,1,1
1,1,1,1,1,5,7,22,8,5,1,1
1,1,1,1,1,23,8,0,8,7,1,1
1,1,1,1,1,23,8,0,8,24,1,1
1,1,1,1,1,7,16,0,8,24,1,1
1,1,1,1,1,5,21,5,7,25,1,1
1,1,1,1,1,1,1,1,1,1,1,1
1,1,1,1,1,1,1,1,1,1,1,1
endlayer

layer
1,1,1,1,1,1,1,1,1,1,1,1
1,1,1,1,1,1,1,1,1,1,1,1
1,1,1,1,1,1,29,27,29,1,1,1
1,1,1,1,1,33,7,32,24,28,1,1
1,1,1,1,29,9,9,9,9,7,29,1
1,1,1,1,33,32,10,10,10,32,28,1
1,1,1,1,29,7,16,9,9,9,29,1
1,1,1,1,29,34,25,24,7,34,1,1
1,1,1,1,1,1,29,29,29,1,1,1
1,1,1,1,1,1,1,1,1,1,1,1
endlayer

layer
1,1,1,1,1,1,1,1,1,1,1,1
1,1,1,1,1,1,1,1,1,1,1,1
1,1,1,1,1,1,1,1,1,1,1,1
1,1,1,1,1,5,5,5,5,5,1,1
1,1,1,1,1,5,1,1,1,7,1,1
1,1,1,1,1,5,1,1,1,5,1,1
1,1,1,1,1,7,35,1,1,5,1,1
1,1,1,1,1,5,5,5,5,5,1,1
1,1,1,1,1,1,1,1,1,1,1,1
1,1,1,1,1,1,1,1,1,1,1,1
endlayer

layer
1,1,1,1,1,1,1,1,1,1,1,1
1,1,1,1,1,1,1,1,1,1,1,1
1,1,1,1,1,1,1,1,1,1,1,1
1,1,1,1,1,1,1,1,1,1,1,1
1,1,1,1,1,5,1,1,1,5,1,1
1,1,1,1,1,1,1,1,1,1,1,1
1,1,1,1,1,5,1,1,1,5,1,1
1,1,1,1,1,1,1,1,1,1,1,1
1,1,1,1,1,1,1,1,1,1,1,1
1,1,1,1,1,1,1,1,1,1,1,1
endlayer

layer
1,1,1,1,1,1,1,1,1,1,1,1
1,1,1,1,1,1,1,1,1,1,1,1
1,1,1,1,1,1,1,1,1,1,1,1
1,1,1,1,1,1,1,1,1,1,1,1
1,1,1,1,1,5,1,1,1,5,1,1
1,1,1,1,1,1,1,1,1,1,1,1
1,1,1,1,1,5,1,1,1,5,1,1
1,1,1,1,1,1,1,1,1,1,1,1
1,1,1,1,1,1,1,1,1,1,1,1
1,1,1,1,1,1,1,1,1,1,1,1
endlayer

layer
1,1,1,1,1,1,1,1,1,1,1,1
1,1,1,1,1,1,1,1,1,1,1,1
1,1,1,1,1,1,1,1,1,1,1,1
1,1,1,1,1,18,18,18,18,18,1,1
1,1,1,1,21,5,5,5,5,5,21,1
1,1,1,1,1,18,18,18,18,18,1,1
1,1,1,1,21,5,5,5,5,5,21,1
1,1,1,1,1,18,18,18,18,18,1,1
1,1,1,1,1,1,1,1,1,1,1,1
1,1,1,1,1,1,1,1,1,1,1,1
endlayer

