
# Created by Ruins mod version 16.7 Ingame Parser
# authoring Player: lafuller

weight=1
embed_into_distance=13
acceptable_target_blocks=water,waterlily
unacceptable_target_blocks=
biomesToSpawnIn=swampland,jungle,marsh,bog,wetland,mini_jungle,lush_swamp,green_swamp,dead_swamp,tropical_island,land_of_lakes
dimensions=23,10,12
allowable_overhang=0
max_leveling=2
leveling_buffer=-1
preserve_water=0
preserve_lava=0

rule1=0,100,preserveBlock
rule2=0,100,minecraft:log2-1
rule3=0,100,minecraft:log2-5
rule4=0,100,minecraft:log2-9
rule5=0,100,minecraft:spruce_fence-0
rule6=0,100,minecraft:ladder-3
rule7=0,100,minecraft:log-3
rule8=0,100,minecraft:spruce_stairs-6
rule9=0,100,minecraft:spruce_stairs-7
rule10=0,100,minecraft:spruce_stairs-4
rule11=0,100,minecraft:log-7
rule12=0,100,minecraft:wooden_slab-9
rule13=0,100,minecraft:log-11
rule14=0,100,minecraft:spruce_stairs-5
rule15=0,100,minecraft:spruce_stairs-2
rule16=0,100,minecraft:spruce_stairs-0
rule17=0,100,minecraft:spruce_stairs-3
rule18=0,100,minecraft:trapdoor-5
rule19=0,100,minecraft:trapdoor-4
rule20=0,100,minecraft:spruce_fence_gate-0
rule21=0,100,minecraft:wooden_slab-1
rule22=0,100,minecraft:ladder-2
rule23=0,100,minecraft:spruce_stairs-1
rule24=0,100,minecraft:spruce_fence_gate-3
rule25=0,100,minecraft:spruce_fence_gate-2
rule26=0,100,minecraft:spruce_fence_gate-1
rule27=0,100,minecraft:dark_oak_fence-0
rule28=0,100,minecraft:carpet-8
rule29=0,100,minecraft:carpet-7
rule30=0,100,minecraft:wooden_slab-13
rule31=0,100,minecraft:dark_oak_stairs-6
rule32=0,100,minecraft:planks-5
rule33=0,100,minecraft:dark_oak_stairs-5
rule34=0,100,minecraft:wooden_slab-5
rule35=0,100,minecraft:dark_oak_stairs-4
rule36=0,100,minecraft:dark_oak_stairs-2
rule37=0,100,minecraft:planks-1
rule38=0,100,minecraft:dark_oak_stairs-1
rule39=0,100,minecraft:dark_oak_stairs-7
rule40=0,100,minecraft:dark_oak_stairs-0
rule41=0,100,minecraft:dark_oak_stairs-3
rule42=0,100,minecraft:trapdoor-0

layer
1,1,1,1,1,1,1,1,1,1,1,1
1,1,1,1,1,1,1,1,1,1,1,1
1,1,1,1,2,1,1,1,1,1,1,1
1,1,2,1,1,1,1,1,2,1,1,1
1,1,1,1,1,1,1,1,1,1,1,1
1,1,1,1,1,1,1,1,1,2,1,1
1,1,1,2,1,1,1,1,1,1,1,1
1,1,1,1,1,2,1,2,1,1,1,1
1,1,1,1,1,1,1,1,1,1,1,1
1,1,1,1,1,1,1,1,1,1,1,1
endlayer

layer
1,1,1,1,1,1,1,1,1,1,1,1
1,1,1,1,1,1,1,1,1,1,1,1
1,1,1,1,2,1,1,1,1,1,1,1
1,1,2,1,1,1,1,1,2,1,1,1
1,1,1,1,1,1,1,1,1,1,1,1
1,1,1,1,1,1,1,1,1,2,1,1
1,1,1,2,1,1,1,1,1,1,1,1
1,1,1,1,1,2,1,2,1,1,1,1
1,1,1,1,1,1,1,1,1,1,1,1
1,1,1,1,1,1,1,1,1,1,1,1
endlayer

layer
1,1,1,1,1,1,1,1,1,1,1,1
1,1,1,1,1,1,1,1,1,1,1,1
1,1,1,1,2,1,1,1,1,1,1,1
1,1,2,1,1,1,1,1,2,1,1,1
1,1,1,1,1,1,1,1,1,1,1,1
1,1,1,1,1,1,1,1,1,2,1,1
1,1,1,2,1,1,1,1,1,1,1,1
1,1,1,1,1,2,1,2,1,1,1,1
1,1,1,1,1,1,1,1,1,1,1,1
1,1,1,1,1,1,1,1,1,1,1,1
endlayer

layer
1,1,1,1,1,1,1,1,1,1,1,1
1,1,1,1,1,1,1,1,1,1,1,1
1,1,1,1,2,1,1,1,1,1,1,1
1,1,2,1,1,1,1,1,2,1,1,1
1,1,1,1,1,1,1,1,1,1,1,1
1,1,1,1,1,1,1,1,1,2,1,1
1,1,1,2,1,1,1,1,1,1,1,1
1,1,1,1,1,2,1,2,1,1,1,1
1,1,1,1,1,1,1,1,1,1,1,1
1,1,1,1,1,1,1,1,1,1,1,1
endlayer

layer
1,1,1,1,1,1,1,1,1,1,1,1
1,1,1,1,1,1,1,1,1,1,1,1
1,1,1,1,2,1,1,1,1,1,1,1
1,1,2,1,1,1,1,1,2,1,1,1
1,1,1,1,1,1,1,1,1,1,1,1
1,1,1,1,1,1,1,1,1,2,1,1
1,1,1,2,1,1,1,1,1,1,1,1
1,1,1,1,1,2,1,2,1,1,1,1
1,1,1,1,1,1,1,1,1,1,1,1
1,1,1,1,1,1,1,1,1,1,1,1
endlayer

layer
1,1,1,1,1,1,1,1,1,1,1,1
1,1,1,1,1,1,1,1,1,1,1,1
1,1,1,1,2,1,1,1,1,1,1,1
1,1,2,1,1,1,1,1,2,1,1,1
1,1,1,1,1,1,1,1,1,1,1,1
1,1,1,1,1,1,1,1,1,2,1,1
1,1,1,2,1,1,1,1,1,1,1,1
1,1,1,1,1,2,1,2,1,1,1,1
1,1,1,1,1,1,1,1,1,1,1,1
1,1,1,1,1,1,1,1,1,1,1,1
endlayer

layer
1,1,1,1,1,1,1,1,1,1,1,1
1,1,1,1,1,1,1,1,1,1,1,1
1,1,1,1,2,1,1,1,1,1,1,1
1,1,2,1,1,1,1,1,2,1,1,1
1,1,1,1,1,1,1,1,1,1,1,1
1,1,1,1,1,1,1,1,1,2,1,1
1,1,1,2,1,1,1,1,1,1,1,1
1,1,1,1,1,2,1,2,1,1,1,1
1,1,1,1,1,1,1,1,1,1,1,1
1,1,1,1,1,1,1,1,1,1,1,1
endlayer

layer
1,1,1,1,1,1,1,1,1,1,1,1
1,1,1,1,1,1,1,1,1,1,1,1
1,1,1,1,2,1,1,1,1,1,1,1
1,1,2,1,1,1,1,1,2,1,1,1
1,1,1,1,1,1,1,1,1,1,1,1
1,1,1,1,1,1,1,1,1,2,1,1
1,1,1,2,1,1,1,1,1,1,1,1
1,1,1,1,1,2,1,2,1,1,1,1
1,1,1,1,1,1,1,1,1,1,1,1
1,1,1,1,1,1,1,1,1,1,1,1
endlayer

layer
1,1,1,1,1,1,1,1,1,1,1,1
1,1,1,1,1,1,1,1,1,1,1,1
1,1,1,1,2,1,1,1,1,1,1,1
1,1,2,1,1,1,1,1,2,1,1,1
1,1,1,1,1,1,1,1,1,1,1,1
1,1,1,1,1,1,1,1,1,2,1,1
1,1,1,2,1,1,1,1,1,1,1,1
1,1,1,1,1,2,1,2,1,1,1,1
1,1,1,1,1,1,1,1,1,1,1,1
1,1,1,1,1,1,1,1,1,1,1,1
endlayer

layer
1,1,1,1,1,1,1,1,1,1,1,1
1,1,1,1,1,1,1,1,1,1,1,1
1,1,1,1,2,1,1,1,1,1,1,1
1,1,2,1,1,1,1,1,2,1,1,1
1,1,1,1,1,1,1,1,1,1,1,1
1,1,1,1,1,1,1,1,1,2,1,1
1,1,1,2,1,1,1,1,1,1,1,1
1,1,1,1,1,2,1,2,1,1,1,1
1,1,1,1,1,1,1,1,1,1,1,1
1,1,1,1,1,1,1,1,1,1,1,1
endlayer

layer
1,1,1,1,1,1,1,1,1,1,1,1
1,1,1,3,1,1,1,1,1,1,1,1
1,1,1,3,2,1,1,1,1,1,1,1
1,1,2,3,1,1,1,1,2,1,1,1
1,1,1,3,1,1,1,1,1,1,1,1
1,1,1,3,1,1,1,1,1,2,1,1
1,1,1,3,1,1,1,1,1,1,1,1
1,1,1,3,1,2,1,2,1,1,1,1
1,1,1,1,1,1,1,1,1,1,1,1
1,1,1,1,1,1,1,1,1,1,1,1
endlayer

layer
1,1,1,1,1,1,1,1,1,1,1,1
1,1,1,1,1,1,1,1,1,1,1,1
1,4,4,4,4,4,4,4,4,4,1,1
1,1,2,1,1,1,3,1,2,1,1,1
1,1,1,1,1,1,3,1,1,1,1,1
1,1,4,4,4,4,4,4,4,4,4,1
1,1,1,2,1,1,3,1,1,1,1,1
1,1,1,1,1,2,3,2,1,1,1,1
1,1,1,1,1,1,3,1,1,1,1,1
1,1,1,1,1,1,1,1,1,1,1,1
endlayer

layer
1,1,1,1,1,1,1,1,1,1,1,1
1,1,1,1,1,1,1,1,3,1,1,1
1,1,1,2,2,1,1,2,3,1,1,1
1,1,2,1,1,1,1,1,3,1,1,1
1,1,1,1,1,1,1,1,3,1,1,1
1,1,1,1,1,1,1,1,3,2,1,1
1,1,1,2,4,4,4,4,3,1,1,1
1,1,1,1,3,2,1,2,3,1,1,1
1,1,1,1,3,1,1,1,3,1,1,1
1,1,1,1,1,1,1,1,1,1,1,1
endlayer

layer
1,1,1,5,1,1,1,1,1,1,1,1
1,1,1,3,1,1,1,1,1,1,1,1
1,1,1,3,7,1,6,2,1,1,1,1
1,1,7,3,1,1,1,1,1,1,1,1
1,1,1,3,1,1,1,1,7,1,1,1
1,1,1,3,1,1,1,1,1,7,1,1
1,5,4,4,4,4,4,4,4,4,4,5
1,1,1,1,1,7,1,2,1,1,1,1
1,1,1,1,1,1,1,1,1,1,1,1
1,1,1,1,1,1,1,1,1,1,1,1
endlayer

layer
1,1,1,1,1,1,1,5,1,1,1,1
1,1,1,1,1,1,1,3,1,1,1,1
1,1,1,1,7,1,6,3,1,1,1,1
1,1,7,1,1,1,1,3,1,1,1,1
1,1,1,1,1,1,1,3,7,1,1,1
1,1,1,1,1,1,1,3,1,7,1,1
1,1,1,7,1,1,1,3,1,1,1,1
1,1,1,3,1,7,1,3,1,1,1,1
1,1,1,3,1,1,1,3,1,1,1,1
1,1,1,5,1,1,1,5,1,1,1,1
endlayer

layer
1,1,1,1,5,1,1,1,1,1,1,1
1,1,1,1,11,10,9,8,1,1,1,1
1,1,12,10,11,1,6,7,8,12,1,1
5,13,13,13,11,13,13,13,13,13,12,1
1,1,12,12,11,12,12,12,7,10,12,1
5,13,13,13,13,13,13,13,13,13,13,5
1,1,14,7,12,11,12,12,14,12,12,1
1,5,13,13,13,11,13,13,13,13,5,1
1,1,1,14,8,11,14,1,1,1,1,1
1,1,1,1,1,5,1,1,1,1,1,1
endlayer

layer
1,1,1,1,1,1,1,1,1,1,1,1
1,1,1,1,17,16,16,15,1,1,1,1
1,1,1,16,7,19,18,7,16,1,1,1
1,1,17,0,0,0,0,0,20,1,1,1
1,1,21,0,0,0,0,0,7,16,1,1
1,1,17,0,0,0,0,0,0,15,1,1
1,1,23,7,22,0,0,0,0,15,1,1
1,1,1,17,0,0,7,23,23,1,1,1
1,1,1,5,21,23,15,21,1,1,1,1
1,1,1,1,1,1,1,1,1,1,1,1
endlayer

layer
1,1,1,1,1,1,1,1,1,1,1,1
1,1,1,1,5,24,24,5,1,1,1,1
1,1,1,5,7,0,0,7,5,1,1,1
1,1,5,0,0,0,0,0,0,1,1,1
1,1,25,0,0,0,0,0,7,5,1,1
1,1,5,0,0,0,0,0,0,20,1,1
1,1,5,7,22,0,0,0,0,5,1,1
1,1,1,5,0,0,7,5,5,1,1,1
1,1,1,5,24,26,5,1,1,1,1,1
1,1,1,1,1,1,1,1,1,1,1,1
endlayer

layer
1,1,1,1,1,1,1,1,1,1,1,1
1,1,1,1,9,10,10,12,10,1,1,1
1,1,1,10,7,0,0,7,8,1,1,1
1,1,9,12,12,0,0,0,8,1,1,1
1,1,9,12,12,0,0,0,7,5,1,1
1,1,9,12,12,0,0,0,0,8,1,1
1,1,5,7,22,0,0,0,0,8,1,1
1,1,1,9,0,0,7,14,14,23,1,1
1,1,1,9,14,14,5,12,1,1,1,1
1,1,1,1,1,1,1,1,1,1,1,1
endlayer

layer
1,1,1,1,1,1,1,1,1,1,1,1
1,1,1,1,5,16,17,5,5,1,1,1
1,1,1,16,7,0,0,7,15,1,1,1
1,1,17,28,0,0,0,27,15,1,1,1
1,1,17,29,0,0,0,27,7,21,1,1
1,1,17,29,0,0,0,0,27,15,1,1
1,1,21,7,0,0,0,0,27,15,1,1
1,1,21,17,0,0,7,23,23,21,1,1
1,1,1,5,23,23,21,5,1,1,1,1
1,1,1,1,1,1,1,1,1,1,1,1
endlayer

layer
1,1,1,1,5,1,1,5,1,1,1,1
1,1,1,5,11,24,24,11,5,1,1,1
1,1,1,5,7,0,0,11,31,30,1,1
1,1,5,0,0,0,0,11,32,27,1,1
1,1,25,0,0,0,0,11,7,13,5,1
1,1,5,0,0,0,0,11,30,32,30,1
1,5,13,7,0,0,0,11,30,32,31,1
1,1,5,5,0,0,7,11,32,33,1,1
1,1,1,5,26,5,5,11,30,1,1,1
1,1,1,1,1,1,1,5,1,1,1,1
endlayer

layer
1,1,1,30,30,32,34,34,34,1,1,1
1,1,30,35,32,32,32,32,34,34,1,1
1,5,13,13,7,13,13,32,32,34,34,1
1,5,37,0,0,0,30,32,32,36,34,1
1,1,9,0,0,0,30,32,32,36,34,1
1,1,9,0,0,0,30,32,32,34,1,1
1,30,37,7,13,13,13,32,36,34,1,1
1,33,32,32,30,30,32,36,34,1,1,1
1,1,39,38,38,38,38,34,1,1,1,1
1,1,1,34,34,34,34,1,1,1,1,1
endlayer

layer
1,1,1,1,1,1,1,1,1,1,1,1
1,1,1,34,34,34,1,1,1,1,1,1
1,34,34,40,40,34,34,1,1,1,1,1
1,34,41,32,36,34,34,34,1,1,1,1
1,34,41,32,36,42,34,34,1,1,1,1
1,34,41,38,38,34,34,1,1,1,1,1
1,34,34,34,34,34,34,1,1,1,1,1
1,1,1,1,1,1,1,1,1,1,1,1
1,1,1,1,1,1,1,1,1,1,1,1
1,1,1,1,1,1,1,1,1,1,1,1
endlayer

