
# Created by Ruins mod version 16.7 Ingame Parser
# authoring Player: lafuller

weight=1
embed_into_distance=13
acceptable_target_blocks=flowing_water,water
unacceptable_target_blocks=
biomesToSpawnIn=river,swampland,lush swamp,marsh
dimensions=25,15,11
allowable_overhang=0
max_leveling=5
leveling_buffer=-1
preserve_water=0
preserve_lava=0

rule1=0,100,preserveBlock
rule2=0,100,minecraft:log2-1
rule3=0,100,minecraft:log2-5
rule4=0,100,minecraft:fence-0
rule5=0,100,minecraft:spruce_fence-0
rule6=0,100,minecraft:log-8
rule7=0,100,minecraft:spruce_stairs-0
rule8=0,100,minecraft:log-4
rule9=0,100,minecraft:spruce_stairs-6
rule10=0,100,minecraft:log-0
rule11=0,100,minecraft:wooden_slab-9
rule12=0,100,minecraft:spruce_stairs-7
rule13=0,100,minecraft:trapdoor-9
rule14=0,100,minecraft:trapdoor-8
rule15=0,100,minecraft:trapdoor-13
rule16=0,100,minecraft:trapdoor-12
rule17=0,100,minecraft:oak_stairs-5
rule18=0,100,minecraft:oak_stairs-6
rule19=0,100,minecraft:planks-0
rule20=0,100,minecraft:oak_stairs-7
rule21=0,100,minecraft:oak_stairs-2
rule22=0,100,minecraft:carpet-8
rule23=0,100,minecraft:carpet-7
rule24=0,100,minecraft:bookshelf-0
rule25=0,100,minecraft:oak_stairs-3
rule26=0,100,minecraft:cauldron-0
rule27=0,100,minecraft:stone-4
rule28=0,100,minecraft:crafting_table-0

rule29=0,100,IInventory;hopper;book#3#0#0+fish#1#3#1-3,IInventory;hopper;rabbit_stew#1#0#0-3,IInventory;hopper;apple#3#0#0-3,IInventory;hopper;coal#5#0#0+fish#2#1#1-3,IInventory;hopper;cooked_rabbit#2#0#0-3,IInventory;hopper;baked_potato#4#0#0-3

rule30=0,100,IInventory;dropper;clay_ball#5#0#0-1,IInventory;dropper;coal#3#0#3-1,IInventory;dropper;cooked_fish#4#1#2+fishing_rod#1#0#7-1,IInventory;dropper;flint#4#0#2-1,IInventory;dropper;glass_bottle#5#0#5-1,IInventory;dropper;dark_oak_boat#1#0#4-1

rule31=0,100,minecraft:oak_stairs-0
rule32=0,100,minecraft:oak_stairs-1
rule33=0,100,minecraft:fence_gate-0
rule34=0,100,minecraft:fence_gate-2
rule35=0,100,IInventory;furnace;coal#2#0#1-2
rule36=0,100,minecraft:fence_gate-3
rule37=0,100,minecraft:cobblestone_wall-0
rule38=0,100,minecraft:spruce_stairs-4
rule39=0,100,minecraft:spruce_stairs-5
rule40=0,100,minecraft:double_wooden_slab-1
rule41=0,100,minecraft:spruce_stairs-3
rule42=0,100,minecraft:spruce_stairs-1
rule43=0,100,minecraft:spruce_stairs-2
rule44=0,100,minecraft:planks-1
rule45=0,100,minecraft:wooden_slab-13
rule46=0,100,minecraft:dark_oak_stairs-0
rule47=0,100,minecraft:dark_oak_stairs-7
rule48=0,100,minecraft:dark_oak_stairs-5
rule49=0,100,minecraft:dark_oak_stairs-3
rule50=0,100,minecraft:wooden_slab-5
rule51=0,100,minecraft:dark_oak_stairs-6
rule52=0,100,minecraft:planks-5
rule53=0,100,minecraft:dark_oak_stairs-4
rule54=0,100,minecraft:dark_oak_stairs-2
rule55=0,100,minecraft:double_wooden_slab-5
rule56=0,100,minecraft:dark_oak_stairs-1
rule57=0,100,minecraft:wooden_slab-1
rule58=0,100,minecraft:trapdoor-11
rule59=0,100,minecraft:trapdoor-10

layer
1,1,1,1,1,1,1,1,1,1,1
1,1,1,1,1,1,1,1,1,1,1
1,1,1,1,1,1,1,1,1,1,1
1,1,2,1,2,1,1,2,1,1,1
1,1,1,1,1,1,1,1,1,1,1
1,1,1,1,1,1,1,1,1,1,1
1,1,1,1,1,1,1,1,1,1,1
1,1,1,1,1,1,1,1,1,1,1
1,1,1,1,1,1,1,2,1,1,1
1,1,1,1,1,1,1,1,1,1,1
1,1,2,1,2,1,1,1,1,1,1
1,1,1,1,1,1,1,1,1,1,1
1,1,1,1,2,1,1,2,1,1,1
1,1,1,1,1,1,1,1,1,1,1
1,1,1,1,1,1,1,1,1,1,1
endlayer

layer
1,1,1,1,1,1,1,1,1,1,1
1,1,1,1,1,1,1,1,1,1,1
1,1,1,1,1,1,1,1,1,1,1
1,1,2,1,2,1,1,2,1,1,1
1,1,1,1,1,1,1,1,1,1,1
1,1,1,1,1,1,1,1,1,1,1
1,1,1,1,1,1,1,1,1,1,1
1,1,1,1,1,1,1,1,1,1,1
1,1,1,1,1,1,1,2,1,1,1
1,1,1,1,1,1,1,1,1,1,1
1,1,2,1,2,1,1,1,1,1,1
1,1,1,1,1,1,1,1,1,1,1
1,1,1,1,2,1,1,2,1,1,1
1,1,1,1,1,1,1,1,1,1,1
1,1,1,1,1,1,1,1,1,1,1
endlayer

layer
1,1,1,1,1,1,1,1,1,1,1
1,1,1,1,1,1,1,1,1,1,1
1,1,1,1,1,1,1,1,1,1,1
1,1,2,1,2,1,1,2,1,1,1
1,1,1,1,1,1,1,1,1,1,1
1,1,1,1,1,1,1,1,1,1,1
1,1,1,1,1,1,1,1,1,1,1
1,1,1,1,1,1,1,1,1,1,1
1,1,1,1,1,1,1,2,1,1,1
1,1,1,1,1,1,1,1,1,1,1
1,1,2,1,2,1,1,1,1,1,1
1,1,1,1,1,1,1,1,1,1,1
1,1,1,1,2,1,1,2,1,1,1
1,1,1,1,1,1,1,1,1,1,1
1,1,1,1,1,1,1,1,1,1,1
endlayer

layer
1,1,1,1,1,1,1,1,1,1,1
1,1,1,1,1,1,1,1,1,1,1
1,1,1,1,1,1,1,1,1,1,1
1,1,2,1,2,1,1,2,1,1,1
1,1,1,1,1,1,1,1,1,1,1
1,1,1,1,1,1,1,1,1,1,1
1,1,1,1,1,1,1,1,1,1,1
1,1,1,1,1,1,1,1,1,1,1
1,1,1,1,1,1,1,2,1,1,1
1,1,1,1,1,1,1,1,1,1,1
1,1,2,1,2,1,1,1,1,1,1
1,1,1,1,1,1,1,1,1,1,1
1,1,1,1,2,1,1,2,1,1,1
1,1,1,1,1,1,1,1,1,1,1
1,1,1,1,1,1,1,1,1,1,1
endlayer

layer
1,1,1,1,1,1,1,1,1,1,1
1,1,1,1,1,1,1,1,1,1,1
1,1,1,1,1,1,1,1,1,1,1
1,1,2,1,2,1,1,2,1,1,1
1,1,1,1,1,1,1,1,1,1,1
1,1,1,1,1,1,1,1,1,1,1
1,1,1,1,1,1,1,1,1,1,1
1,1,1,1,1,1,1,1,1,1,1
1,1,1,1,1,1,1,2,1,1,1
1,1,1,1,1,1,1,1,1,1,1
1,1,2,1,2,1,1,1,1,1,1
1,1,1,1,1,1,1,1,1,1,1
1,1,1,1,2,1,1,2,1,1,1
1,1,1,1,1,1,1,1,1,1,1
1,1,1,1,1,1,1,1,1,1,1
endlayer

layer
1,1,1,1,1,1,1,1,1,1,1
1,1,1,1,1,1,1,1,1,1,1
1,1,1,1,1,1,1,1,1,1,1
1,1,2,1,2,1,1,2,1,1,1
1,1,1,1,1,1,1,1,1,1,1
1,1,1,1,1,1,1,1,1,1,1
1,1,1,1,1,1,1,1,1,1,1
1,1,1,1,1,1,1,1,1,1,1
1,1,1,1,1,1,1,2,1,1,1
1,1,1,1,1,1,1,1,1,1,1
1,1,2,1,2,1,1,1,1,1,1
1,1,1,1,1,1,1,1,1,1,1
1,1,1,1,2,1,1,2,1,1,1
1,1,1,1,1,1,1,1,1,1,1
1,1,1,1,1,1,1,1,1,1,1
endlayer

layer
1,1,1,1,1,1,1,1,1,1,1
1,1,1,1,1,1,1,1,1,1,1
1,1,1,1,1,1,1,1,1,1,1
1,1,2,1,2,1,1,2,1,1,1
1,1,1,1,1,1,1,1,1,1,1
1,1,1,1,1,1,1,1,1,1,1
1,1,1,1,1,1,1,1,1,1,1
1,1,1,1,1,1,1,1,1,1,1
1,1,1,1,1,1,1,2,1,1,1
1,1,1,1,1,1,1,1,1,1,1
1,1,2,1,2,1,1,1,1,1,1
1,1,1,1,1,1,1,1,1,1,1
1,1,1,1,2,1,1,2,1,1,1
1,1,1,1,1,1,1,1,1,1,1
1,1,1,1,1,1,1,1,1,1,1
endlayer

layer
1,1,1,1,1,1,1,1,1,1,1
1,1,1,1,1,1,1,1,1,1,1
1,1,1,1,1,1,1,1,1,1,1
1,1,2,1,2,1,1,2,1,1,1
1,1,1,1,1,1,1,1,1,1,1
1,1,1,1,1,1,1,1,1,1,1
1,1,1,1,1,1,1,1,1,1,1
1,1,1,1,1,1,1,1,1,1,1
1,1,1,1,1,1,1,2,1,1,1
1,1,1,1,1,1,1,1,1,1,1
1,1,2,1,2,1,1,1,1,1,1
1,1,1,1,1,1,1,1,1,1,1
1,1,1,1,2,1,1,2,1,1,1
1,1,1,1,1,1,1,1,1,1,1
1,1,1,1,1,1,1,1,1,1,1
endlayer

layer
1,1,1,1,1,1,1,1,1,1,1
1,1,1,1,1,1,1,1,1,1,1
1,1,1,1,1,1,1,1,1,1,1
1,1,2,1,2,1,1,2,1,1,1
1,1,1,1,1,1,1,1,1,1,1
1,1,1,1,1,1,1,1,1,1,1
1,1,1,1,1,1,1,1,1,1,1
1,1,1,1,1,1,1,1,1,1,1
1,1,1,1,1,1,1,2,1,1,1
1,1,1,1,1,1,1,1,1,1,1
1,1,2,1,2,1,1,1,1,1,1
1,1,1,1,1,1,1,1,1,1,1
1,1,1,1,2,1,1,2,1,1,1
1,1,1,1,1,1,1,1,1,1,1
1,1,1,1,1,1,1,1,1,1,1
endlayer

layer
1,1,1,1,1,1,1,1,1,1,1
1,1,1,1,1,1,1,1,1,1,1
1,1,1,1,1,1,1,1,1,1,1
1,1,2,1,2,1,1,2,1,1,1
1,1,1,1,1,1,1,1,1,1,1
1,1,1,1,1,1,1,1,1,1,1
1,1,1,1,1,1,1,1,1,1,1
1,1,1,1,1,1,1,1,1,1,1
1,1,1,1,1,1,1,2,1,1,1
1,1,1,1,1,1,1,1,1,1,1
1,1,2,1,2,1,1,1,1,1,1
1,1,1,1,1,1,1,1,1,1,1
1,1,1,1,2,1,1,2,1,1,1
1,1,1,1,1,1,1,1,1,1,1
1,1,1,1,1,1,1,1,1,1,1
endlayer

layer
1,1,1,1,1,1,1,1,1,1,1
1,1,1,1,1,1,1,1,1,1,1
1,1,1,1,1,1,1,1,1,1,1
1,1,2,1,2,1,1,2,1,1,1
1,1,1,1,1,1,1,1,1,1,1
1,1,1,1,1,1,1,1,1,1,1
1,1,1,1,1,1,1,1,1,1,1
1,1,1,1,1,1,1,1,1,1,1
1,1,1,1,1,1,1,2,1,1,1
1,1,1,1,1,1,1,1,1,1,1
1,1,2,1,2,1,1,1,1,1,1
1,1,1,1,1,1,1,1,1,1,1
1,1,1,1,2,1,1,2,1,1,1
1,1,1,1,1,1,1,1,1,1,1
1,1,1,1,1,1,1,1,1,1,1
endlayer

layer
1,1,1,1,1,1,1,1,1,1,1
1,1,1,1,1,1,1,1,1,1,1
1,1,1,1,1,1,1,1,1,1,1
1,1,2,1,2,1,1,2,1,1,1
1,1,1,1,1,1,1,1,1,1,1
1,1,1,1,1,1,1,1,1,1,1
1,1,1,1,1,1,1,1,1,1,1
1,1,1,1,1,1,1,1,1,1,1
1,1,1,1,1,1,1,2,1,1,1
1,1,1,1,1,1,1,1,1,1,1
1,1,2,1,2,1,1,1,1,1,1
1,1,1,1,1,1,1,1,1,1,1
1,1,1,1,2,1,1,2,1,1,1
1,1,1,1,1,1,1,1,1,1,1
1,1,1,1,1,1,1,1,1,1,1
endlayer

layer
1,1,1,1,1,1,1,1,1,1,1
1,1,1,1,1,1,1,1,1,1,1
1,1,1,3,1,3,3,1,1,1,1
1,1,2,3,2,3,3,2,1,1,1
1,1,1,3,1,3,3,1,1,1,1
1,1,1,1,1,3,3,1,1,1,1
1,1,1,1,1,3,3,1,1,1,1
1,1,1,1,1,3,3,1,1,1,1
1,1,1,1,1,3,3,2,3,1,1
1,1,1,3,1,3,3,1,3,1,1
1,1,2,3,2,3,3,1,3,1,1
1,1,1,3,1,3,3,1,3,1,1
1,1,1,3,2,3,3,2,3,1,1
1,1,1,1,1,1,1,1,1,1,1
1,1,1,1,1,1,1,1,1,1,1
endlayer

layer
1,1,1,1,1,1,1,1,1,1,1
1,1,1,4,1,4,1,4,1,1,1
1,5,6,6,6,6,6,6,6,5,1
1,1,2,1,2,1,1,2,1,1,1
1,5,6,6,6,6,6,6,6,5,1
1,1,1,1,1,1,1,1,1,1,1
1,1,1,1,1,1,1,1,1,1,1
1,1,1,1,1,1,1,1,1,1,1
1,1,1,1,1,7,7,2,1,1,1
1,5,6,6,6,6,6,6,6,5,1
1,1,2,1,2,1,1,1,1,1,1
1,5,6,6,6,6,6,6,6,5,1
1,1,1,1,2,1,1,2,1,1,1
1,1,1,1,4,1,1,4,1,1,1
1,1,1,1,1,1,1,1,1,1,1
endlayer

layer
1,1,5,1,5,1,1,1,5,1,1
1,1,8,1,8,1,1,1,8,1,1
1,4,8,1,8,1,1,1,8,4,1
1,1,8,1,8,1,1,2,8,1,1
1,4,8,1,8,1,1,1,8,4,1
1,1,8,1,1,1,1,1,8,1,1
1,1,8,1,1,1,1,1,8,1,1
1,1,8,1,1,1,1,1,8,1,1
1,1,8,1,8,1,1,2,8,1,1
1,4,8,1,8,7,7,1,8,4,1
1,1,8,1,8,1,8,1,8,1,1
1,4,8,1,8,1,8,1,8,4,1
1,1,8,1,8,1,8,2,8,1,1
1,1,8,1,8,1,8,1,8,1,1
1,1,5,1,5,1,5,1,5,1,1
endlayer

layer
1,1,4,1,4,1,1,1,4,1,1
1,4,6,6,6,6,6,6,6,6,5
1,12,10,11,11,11,11,11,10,9,1
5,6,6,6,6,6,6,6,6,6,5
1,11,11,11,11,11,11,11,11,11,1
5,6,6,6,6,6,6,6,6,6,5
1,11,11,11,11,14,13,11,11,11,1
1,11,11,11,11,16,15,11,11,11,1
5,6,6,6,6,16,15,6,6,6,5
1,11,11,11,11,16,15,11,11,11,1
5,6,6,6,6,7,7,6,6,6,5
1,11,11,11,11,11,11,11,11,11,1
5,6,6,6,6,6,6,6,6,6,5
1,1,10,17,10,17,10,17,10,4,1
1,1,4,1,4,1,4,1,4,1,1
endlayer

layer
1,1,0,0,0,0,0,0,0,1,1
1,4,20,19,19,19,19,19,18,4,0
0,20,10,24,24,23,23,22,10,21,0
0,19,0,0,0,23,23,22,24,19,0
0,21,0,0,0,0,0,0,0,19,0
0,19,0,0,0,0,0,0,0,19,0
0,19,0,0,0,0,0,0,0,19,0
0,19,0,0,0,0,0,0,0,19,0
0,19,0,0,0,0,0,0,0,19,0
0,21,0,0,0,0,0,0,0,19,0
0,21,0,0,0,0,0,0,0,25,0
0,19,26,0,0,0,0,0,0,19,0
0,20,10,30,29,28,27,27,10,17,0
1,4,32,19,31,19,19,19,18,4,1
1,1,0,0,0,0,0,0,0,1,1
endlayer

layer
1,0,0,0,0,0,0,0,0,0,1
0,4,31,19,19,19,19,31,19,5,0
0,19,10,0,0,0,0,0,10,19,0
0,19,0,0,0,0,0,0,24,19,0
0,33,0,0,0,0,0,0,0,19,0
0,19,0,0,0,0,0,0,0,19,0
0,19,0,0,0,0,0,0,0,19,0
0,19,0,0,0,0,0,0,0,19,0
0,19,0,0,0,0,0,0,0,19,0
0,33,0,0,0,0,0,0,0,19,0
0,33,0,0,0,0,0,0,0,34,0
0,19,35,0,0,0,0,0,0,19,0
0,19,10,0,0,0,0,0,10,19,0
0,4,19,19,36,19,19,19,19,4,0
1,0,0,0,0,0,0,0,0,0,1
endlayer

layer
0,0,0,0,0,0,0,0,0,0,0
0,5,25,19,19,19,19,19,31,5,0
0,25,10,0,0,0,0,0,10,7,0
0,19,0,0,0,0,0,0,0,18,0
0,18,0,0,0,0,0,0,0,19,0
0,19,0,0,0,0,0,0,0,19,0
0,19,0,0,0,0,0,0,0,5,0
0,19,0,0,0,0,0,0,0,5,0
0,19,0,0,0,0,0,0,0,19,0
0,18,0,0,0,0,0,0,0,19,0
0,18,0,0,0,0,0,0,0,20,0
0,19,37,0,0,0,0,0,0,19,0
0,25,10,0,0,0,0,0,10,19,0
0,5,25,39,38,32,19,19,17,5,0
0,0,0,0,0,0,0,0,0,0,0
endlayer

layer
0,0,11,11,9,38,12,38,0,0,0
0,12,7,43,7,42,42,41,40,5,0
0,41,10,0,0,0,0,0,10,9,0
12,41,0,0,0,0,0,0,0,44,38
12,41,0,0,0,0,0,0,0,41,9
11,42,0,0,0,0,0,0,0,41,11
0,43,0,0,0,0,0,0,0,9,0
0,43,0,0,0,0,0,0,0,9,0
0,43,0,0,0,0,0,0,0,42,38
5,43,0,0,0,0,0,0,0,43,9
5,43,0,0,0,0,0,0,0,43,0
0,41,37,0,0,0,0,0,0,40,0
5,12,10,38,0,0,0,0,10,41,0
0,39,41,42,42,42,38,38,39,5,0
0,0,0,5,5,11,5,39,0,0,0
endlayer

layer
0,0,46,45,41,5,5,43,7,0,0
0,41,44,42,9,0,0,12,40,11,0
41,40,10,0,0,0,0,0,10,44,5
42,44,43,0,0,0,0,0,39,44,44
47,43,44,0,0,0,0,0,0,41,41
45,43,9,0,0,0,0,0,0,41,43
5,44,0,0,0,0,0,0,0,43,43
0,5,0,0,0,0,0,0,0,43,43
0,5,0,0,0,0,0,0,0,41,40
12,44,0,0,0,0,0,0,0,12,40
12,7,0,0,0,0,0,0,0,40,40
12,40,37,0,0,0,0,0,12,44,5
41,11,10,44,0,0,0,38,10,9,0
48,40,40,44,42,7,38,38,7,42,0
0,0,11,39,42,42,42,7,42,0,0
endlayer

layer
0,0,0,0,50,49,46,46,46,0,0
0,0,50,46,46,53,39,12,52,51,0
0,50,53,53,39,39,39,39,44,52,54
50,47,43,0,0,0,0,0,44,51,54
49,47,44,0,0,0,0,0,12,44,45
49,47,43,0,0,0,0,0,12,44,51
47,44,9,0,0,0,0,0,12,44,45
0,47,9,0,0,0,0,0,12,44,45
0,47,9,0,0,0,0,0,12,52,0
47,44,9,0,0,0,0,0,12,12,51
49,9,9,0,0,0,0,0,12,44,48
55,48,44,9,0,0,0,12,44,44,51
55,9,44,44,38,0,38,44,44,48,0
50,49,56,44,44,5,44,48,48,50,0
0,0,0,57,57,42,42,0,0,0,0
endlayer

layer
0,0,0,0,0,0,0,0,0,0,0
0,0,0,0,0,50,50,50,0,0,0
0,0,0,46,46,46,53,53,46,50,0
0,0,46,49,39,39,39,12,52,51,0
0,46,45,9,0,0,0,39,44,54,0
0,47,47,9,0,0,0,12,12,51,50
50,47,49,9,0,0,0,12,12,51,54
50,47,47,9,0,0,0,12,51,51,50
50,47,45,9,0,0,0,12,53,51,50
50,47,45,9,0,0,0,12,12,51,50
50,47,47,9,0,0,0,12,55,50,0
0,50,47,44,38,38,38,52,55,50,0
0,50,50,48,48,48,48,50,50,0,0
0,0,0,50,50,0,50,50,0,0,0
0,0,0,0,0,0,0,0,0,0,0
endlayer

layer
0,0,0,0,0,0,0,0,0,0,0
0,0,0,0,0,0,0,0,0,0,0
0,0,0,0,0,0,0,0,0,0,0
0,0,0,0,50,46,46,50,0,0,0
0,0,0,50,48,48,48,50,50,0,0
0,0,50,50,51,58,47,51,50,0,0
0,0,50,49,53,53,53,46,50,0,0
0,0,50,55,45,45,45,51,50,0,0
0,0,50,50,48,48,48,54,50,0,0
0,0,50,55,51,59,47,51,50,0,0
0,0,0,50,53,53,53,50,50,0,0
0,0,37,50,50,50,50,50,0,0,0
0,0,0,0,0,0,0,0,0,0,0
0,0,0,0,0,0,0,0,0,0,0
0,0,0,0,0,0,0,0,0,0,0
endlayer

layer
0,0,0,0,0,0,0,0,0,0,0
0,0,0,0,0,0,0,0,0,0,0
0,0,0,0,0,0,0,0,0,0,0
0,0,0,0,0,0,0,0,0,0,0
0,0,0,0,0,0,0,0,0,0,0
0,0,0,0,0,0,0,0,0,0,0
0,0,0,0,0,0,0,0,0,0,0
0,0,0,0,0,0,0,0,0,0,0
0,0,0,0,0,0,0,0,0,0,0
0,0,0,0,0,0,0,0,0,0,0
0,0,0,0,0,0,0,0,0,0,0
0,0,37,0,0,0,0,0,0,0,0
0,0,0,0,0,0,0,0,0,0,0
0,0,0,0,0,0,0,0,0,0,0
0,0,0,0,0,0,0,0,0,0,0
endlayer

