
# Created by Ruins mod version 16.7 Ingame Parser
# authoring Player: lafuller

weight=1
embed_into_distance=13
acceptable_target_blocks=water,waterlily
unacceptable_target_blocks=
biomesToSpawnIn=swampland,jungle,marsh,bog,wetland,mini_jungle,lush_swamp,green_swamp,dead_swamp,tropical_island,land_of_lakes
dimensions=23,11,11
allowable_overhang=0
max_leveling=2
leveling_buffer=-1
preserve_water=0
preserve_lava=0

rule1=0,100,preserveBlock
rule2=0,100,minecraft:log2-1
rule3=0,100,minecraft:log2-9
rule4=0,100,minecraft:log2-5
rule5=0,100,minecraft:spruce_fence-0
rule6=0,100,minecraft:log-3
rule7=0,100,minecraft:ladder-2
rule8=0,100,minecraft:log-11
rule9=0,100,minecraft:wooden_slab-9
rule10=0,100,minecraft:spruce_stairs-5
rule11=0,100,minecraft:spruce_stairs-7
rule12=0,100,minecraft:spruce_stairs-2
rule13=0,100,minecraft:spruce_stairs-0
rule14=0,100,minecraft:wooden_slab-1
rule15=0,100,minecraft:planks-1
rule16=0,100,minecraft:spruce_stairs-3
rule17=0,100,minecraft:spruce_fence_gate-2
rule18=0,100,minecraft:trapdoor-4
rule19=0,100,minecraft:spruce_stairs-1
rule20=0,100,minecraft:spruce_fence_gate-3
rule21=0,100,minecraft:spruce_fence_gate-0
rule22=0,100,minecraft:spruce_fence_gate-1
rule23=0,100,minecraft:spruce_stairs-6
rule24=0,100,minecraft:spruce_stairs-4
rule25=0,100,minecraft:carpet-8
rule26=0,100,minecraft:carpet-7
rule27=0,100,minecraft:log-7
rule28=0,100,minecraft:dark_oak_stairs-4
rule29=0,100,minecraft:wooden_slab-13
rule30=0,100,minecraft:wooden_slab-5
rule31=0,100,minecraft:planks-5
rule32=0,100,minecraft:dark_oak_stairs-1
rule33=0,100,minecraft:dark_oak_stairs-5
rule34=0,100,minecraft:dark_oak_stairs-6
rule35=0,100,minecraft:dark_oak_stairs-7
rule36=0,100,minecraft:dark_oak_stairs-2
rule37=0,100,minecraft:dark_oak_stairs-3
rule38=0,100,minecraft:dark_oak_stairs-0
rule39=0,100,minecraft:trapdoor-0

layer
1,1,1,1,1,1,1,1,1,1,1
1,1,1,1,1,1,1,1,1,1,1
1,1,1,1,1,2,1,1,1,1,1
1,1,2,1,1,1,1,1,1,1,1
1,1,1,1,1,1,1,1,2,1,1
1,1,1,1,1,1,2,1,1,1,1
1,1,1,1,1,1,1,1,1,1,1
1,1,1,1,1,1,1,1,1,1,1
1,1,1,2,1,1,1,2,1,1,1
1,1,1,1,1,1,1,1,1,1,1
1,1,1,1,1,1,1,1,1,1,1
endlayer

layer
1,1,1,1,1,1,1,1,1,1,1
1,1,1,1,1,1,1,1,1,1,1
1,1,1,1,1,2,1,1,1,1,1
1,1,2,1,1,1,1,1,1,1,1
1,1,1,1,1,1,1,1,2,1,1
1,1,1,1,1,1,2,1,1,1,1
1,1,1,1,1,1,1,1,1,1,1
1,1,1,1,1,1,1,1,1,1,1
1,1,1,2,1,1,1,2,1,1,1
1,1,1,1,1,1,1,1,1,1,1
1,1,1,1,1,1,1,1,1,1,1
endlayer

layer
1,1,1,1,1,1,1,1,1,1,1
1,1,1,1,1,1,1,1,1,1,1
1,1,1,1,1,2,1,1,1,1,1
1,1,2,1,1,1,1,1,1,1,1
1,1,1,1,1,1,1,1,2,1,1
1,1,1,1,1,1,2,1,1,1,1
1,1,1,1,1,1,1,1,1,1,1
1,1,1,1,1,1,1,1,1,1,1
1,1,1,2,1,1,1,2,1,1,1
1,1,1,1,1,1,1,1,1,1,1
1,1,1,1,1,1,1,1,1,1,1
endlayer

layer
1,1,1,1,1,1,1,1,1,1,1
1,1,1,1,1,1,1,1,1,1,1
1,1,1,1,1,2,1,1,1,1,1
1,1,2,1,1,1,1,1,1,1,1
1,1,1,1,1,1,1,1,2,1,1
1,1,1,1,1,1,2,1,1,1,1
1,1,1,1,1,1,1,1,1,1,1
1,1,1,1,1,1,1,1,1,1,1
1,1,1,2,1,1,1,2,1,1,1
1,1,1,1,1,1,1,1,1,1,1
1,1,1,1,1,1,1,1,1,1,1
endlayer

layer
1,1,1,1,1,1,1,1,1,1,1
1,1,1,1,1,1,1,1,1,1,1
1,1,1,1,1,2,1,1,1,1,1
1,1,2,1,1,1,1,1,1,1,1
1,1,1,1,1,1,1,1,2,1,1
1,1,1,1,1,1,2,1,1,1,1
1,1,1,1,1,1,1,1,1,1,1
1,1,1,1,1,1,1,1,1,1,1
1,1,1,2,1,1,1,2,1,1,1
1,1,1,1,1,1,1,1,1,1,1
1,1,1,1,1,1,1,1,1,1,1
endlayer

layer
1,1,1,1,1,1,1,1,1,1,1
1,1,1,1,1,1,1,1,1,1,1
1,1,1,1,1,2,1,1,1,1,1
1,1,2,1,1,1,1,1,1,1,1
1,1,1,1,1,1,1,1,2,1,1
1,1,1,1,1,1,2,1,1,1,1
1,1,1,1,1,1,1,1,1,1,1
1,1,1,1,1,1,1,1,1,1,1
1,1,1,2,1,1,1,2,1,1,1
1,1,1,1,1,1,1,1,1,1,1
1,1,1,1,1,1,1,1,1,1,1
endlayer

layer
1,1,1,1,1,1,1,1,1,1,1
1,1,1,1,1,1,1,1,1,1,1
1,1,1,1,1,2,1,1,1,1,1
1,1,2,1,1,1,1,1,1,1,1
1,1,1,1,1,1,1,1,2,1,1
1,1,1,1,1,1,2,1,1,1,1
1,1,1,1,1,1,1,1,1,1,1
1,1,1,1,1,1,1,1,1,1,1
1,1,1,2,1,1,1,2,1,1,1
1,1,1,1,1,1,1,1,1,1,1
1,1,1,1,1,1,1,1,1,1,1
endlayer

layer
1,1,1,1,1,1,1,1,1,1,1
1,1,1,1,1,1,1,1,1,1,1
1,1,1,1,1,2,1,1,1,1,1
1,1,2,1,1,1,1,1,1,1,1
1,1,1,1,1,1,1,1,2,1,1
1,1,1,1,1,1,2,1,1,1,1
1,1,1,1,1,1,1,1,1,1,1
1,1,1,1,1,1,1,1,1,1,1
1,1,1,2,1,1,1,2,1,1,1
1,1,1,1,1,1,1,1,1,1,1
1,1,1,1,1,1,1,1,1,1,1
endlayer

layer
1,1,1,1,1,1,1,1,1,1,1
1,1,1,1,1,1,1,1,1,1,1
1,1,1,1,1,2,1,1,1,1,1
1,1,2,1,1,1,1,1,1,1,1
1,1,1,1,1,1,1,1,2,1,1
1,1,1,1,1,1,2,1,1,1,1
1,1,1,1,1,1,1,1,1,1,1
1,1,1,1,1,1,1,1,1,1,1
1,1,1,2,1,1,1,2,1,1,1
1,1,1,1,1,1,1,1,1,1,1
1,1,1,1,1,1,1,1,1,1,1
endlayer

layer
1,1,1,1,1,1,1,1,1,1,1
1,1,1,1,1,1,1,1,1,1,1
1,1,1,1,1,2,1,1,1,1,1
1,1,2,1,1,1,1,1,1,1,1
1,1,1,1,1,1,1,1,2,1,1
1,1,1,1,1,1,2,1,1,1,1
1,1,1,1,1,1,1,1,1,1,1
1,1,1,1,1,1,1,1,1,1,1
1,1,1,2,1,1,1,2,1,1,1
1,1,1,1,1,1,1,1,1,1,1
1,1,1,1,1,1,1,1,1,1,1
endlayer

layer
1,1,1,1,1,1,1,1,1,1,1
1,1,1,1,1,1,1,1,1,1,1
1,1,1,1,1,2,1,1,1,1,1
1,1,2,1,1,1,1,1,1,1,1
1,1,1,1,1,1,1,1,2,1,1
1,1,1,1,1,1,2,1,1,1,1
1,1,1,1,1,1,1,1,1,1,1
1,1,1,1,1,1,1,1,1,1,1
1,1,1,2,1,1,1,2,1,1,1
1,1,1,1,1,1,1,1,1,1,1
1,1,1,1,1,1,1,1,1,1,1
endlayer

layer
1,1,1,1,1,1,1,1,1,1,1
1,1,1,1,1,1,1,1,1,1,1
1,1,1,1,1,2,1,1,1,1,1
1,1,2,1,1,1,1,1,1,1,1
1,1,1,1,1,1,1,1,2,1,1
1,1,1,1,1,1,2,1,1,1,1
1,1,1,1,1,1,1,1,1,1,1
1,3,3,3,3,3,3,3,3,1,1
1,1,1,2,1,1,1,2,1,1,1
1,1,1,1,1,1,1,1,1,1,1
1,1,1,1,1,1,1,1,1,1,1
endlayer

layer
1,1,1,1,1,1,1,1,1,1,1
1,1,1,1,1,1,1,1,1,1,1
1,1,4,1,1,2,1,4,1,1,1
1,1,4,1,1,1,1,4,1,1,1
1,1,4,1,1,1,1,4,2,1,1
1,1,4,1,1,1,2,4,1,1,1
1,1,4,1,1,1,1,4,1,1,1
1,1,4,2,1,1,1,4,1,1,1
1,1,4,2,1,1,1,4,1,1,1
1,1,1,1,1,1,1,4,1,1,1
1,1,1,1,1,1,1,1,1,1,1
endlayer

layer
1,1,1,1,1,1,1,1,1,1,1
1,1,1,1,1,1,1,1,1,1,1
1,1,1,1,1,2,1,1,1,1,1
5,3,3,3,3,3,3,3,3,3,5
1,1,6,1,1,1,1,1,2,1,1
5,3,3,3,3,3,3,3,3,3,5
1,1,1,1,1,1,1,1,1,1,1
1,1,1,2,7,1,1,1,1,1,1
1,1,1,2,1,1,1,2,1,1,1
1,1,1,1,1,1,1,1,1,1,1
1,1,1,1,1,1,1,1,1,1,1
endlayer

layer
1,1,1,5,1,1,5,1,1,1,1
1,1,1,4,1,1,4,1,5,1,1
1,1,1,4,1,6,4,1,4,1,1
1,1,1,4,1,1,4,1,4,1,1
1,1,6,4,1,1,4,1,4,1,1
1,1,1,4,1,1,4,1,4,1,1
1,1,1,4,1,1,4,1,4,1,1
1,1,1,4,7,1,4,1,4,1,1
1,1,1,4,1,1,4,6,4,1,1
1,1,1,4,1,1,4,1,4,1,1
1,1,1,5,1,1,5,1,5,1,1
endlayer

layer
1,1,1,1,1,1,1,1,1,1,1
1,1,1,1,1,1,1,1,1,1,1
5,8,8,8,8,8,8,8,8,5,1
1,1,9,9,9,9,9,9,1,1,1
5,8,8,8,8,8,8,8,8,8,5
1,11,10,9,9,9,9,9,6,1,1
1,9,9,9,9,9,9,9,9,1,1
1,9,11,6,7,9,9,9,9,1,1
1,5,8,8,8,8,8,8,8,8,5
1,1,1,1,1,1,1,1,1,1,1
1,1,1,1,1,1,1,1,1,1,1
endlayer

layer
1,1,1,1,1,1,1,1,1,1,1
1,1,1,1,1,1,1,1,1,1,1
1,5,5,15,14,13,6,12,1,1,1
1,5,16,0,0,0,0,13,1,1,1
1,1,6,7,0,0,0,0,12,1,1
1,1,16,0,0,0,0,0,6,1,1
1,1,17,0,0,0,0,0,14,1,1
1,1,16,6,18,0,0,0,12,1,1
1,1,1,19,19,14,19,6,10,1,1
1,1,1,1,1,1,1,1,1,1,1
1,1,1,1,1,1,1,1,1,1,1
endlayer

layer
1,1,1,1,1,1,1,1,1,1,1
1,1,1,1,1,1,1,1,1,1,1
1,1,5,5,20,5,6,5,1,1,1
1,5,5,0,0,0,0,5,1,1,1
1,1,6,7,0,0,0,0,5,1,1
1,1,5,0,0,0,0,0,6,1,1
1,1,0,0,0,0,0,0,21,1,1
1,1,5,6,0,0,0,0,5,1,1
1,1,5,5,5,22,5,6,5,1,1
1,1,1,1,1,1,1,5,1,1,1
1,1,1,1,1,1,1,1,1,1,1
endlayer

layer
1,1,1,1,1,1,1,1,1,1,1
1,1,1,1,1,1,1,1,1,1,1
1,1,11,24,24,24,6,23,1,1,1
1,1,15,9,9,9,9,24,1,1,1
1,1,6,7,0,0,0,0,23,1,1
1,1,11,0,0,0,0,0,6,5,1
1,1,11,0,0,0,0,0,23,1,1
1,1,24,6,0,0,0,0,23,1,1
1,1,16,10,10,10,10,6,10,1,1
1,1,1,1,1,1,1,5,1,1,1
1,1,1,1,1,1,1,1,1,1,1
endlayer

layer
1,1,1,1,1,1,1,1,1,1,1
1,1,1,1,1,1,5,1,1,1,1
1,1,1,13,14,13,6,13,1,1,1
1,1,13,0,26,26,25,12,1,1,1
1,5,6,0,0,0,0,11,5,5,1
1,1,16,0,0,0,0,0,6,5,1
1,1,16,0,0,0,0,0,14,1,1
1,1,16,6,0,0,0,5,12,1,1
1,1,10,19,9,9,19,6,5,1,1
1,1,1,1,1,1,1,27,1,1,1
1,1,1,1,1,1,1,5,1,1,1
endlayer

layer
1,1,1,1,1,1,1,1,1,1,1
1,1,1,1,1,1,5,1,1,1,1
1,1,1,5,20,5,6,5,1,1,1
1,5,5,0,0,0,0,21,1,1,1
1,5,6,0,0,0,0,5,28,5,1
1,1,5,0,0,0,0,5,6,8,5
1,1,0,0,0,0,5,5,15,29,1
1,5,8,8,8,8,8,8,31,30,1
1,29,31,31,31,31,31,31,30,1,1
1,1,29,31,30,32,32,30,30,1,1
1,1,1,1,1,1,1,1,1,1,1
endlayer

layer
1,1,1,1,1,1,5,1,1,1,1
1,1,1,1,5,5,27,5,1,1,1
1,1,11,24,24,11,6,33,28,1,1
1,5,11,0,0,0,0,35,34,1,1
5,8,6,0,0,0,0,35,31,36,1
1,29,31,29,29,29,29,31,36,30,1
1,29,31,31,31,31,32,30,30,1,1
1,37,32,32,32,30,30,30,1,1,1
1,1,30,30,30,30,1,1,1,1,1
1,1,1,1,1,1,1,1,1,1,1
1,1,1,1,1,1,1,1,1,1,1
endlayer

layer
1,1,1,1,1,30,30,1,1,1,1
1,1,30,28,28,38,30,30,1,1,1
1,30,31,31,31,31,36,30,1,1,1
1,30,37,31,32,32,30,30,1,1,1
1,30,32,32,39,30,30,1,1,1,1
1,1,30,30,30,1,1,1,1,1,1
1,1,1,1,1,1,1,1,1,1,1
1,1,1,1,1,1,1,1,1,1,1
1,1,1,1,1,1,1,1,1,1,1
1,1,1,1,1,1,1,1,1,1,1
1,1,1,1,1,1,1,1,1,1,1
endlayer

