
# Created by Ruins mod version 16.7 Ingame Parser
# authoring Player: lafuller

weight=1
embed_into_distance=13
acceptable_target_blocks=water
unacceptable_target_blocks=
dimensions=25,9,8
allowable_overhang=0
max_leveling=20
leveling_buffer=-1
preserve_water=0
preserve_lava=0

rule1=0,100,preserveBlock
rule2=0,100,minecraft:log2-1
rule3=0,100,minecraft:log2-5
rule4=0,100,minecraft:log2-9
rule5=0,100,minecraft:spruce_fence-0
rule6=0,100,minecraft:ladder-5
rule7=0,100,minecraft:wooden_slab-9
rule8=0,100,minecraft:spruce_stairs-5
rule9=0,100,minecraft:spruce_stairs-6
rule10=0,100,minecraft:spruce_stairs-7
rule11=0,100,minecraft:spruce_stairs-4
rule12=0,100,minecraft:spruce_stairs-0
rule13=0,100,minecraft:trapdoor-4
rule14=0,100,minecraft:trapdoor-7

layer
1,1,1,1,1,1,1,1
1,1,1,1,1,1,1,1
1,1,1,1,1,1,2,1
1,1,1,1,2,1,1,1
1,1,1,1,1,1,1,1
1,1,2,1,1,1,1,1
1,1,1,1,1,1,1,1
1,1,1,1,1,2,1,1
1,1,1,1,1,1,1,1
endlayer

layer
1,1,1,1,1,1,1,1
1,1,1,1,1,1,1,1
1,1,1,1,1,1,2,1
1,1,1,1,2,1,1,1
1,1,1,1,1,1,1,1
1,1,2,1,1,1,1,1
1,1,1,1,1,1,1,1
1,1,1,1,1,2,1,1
1,1,1,1,1,1,1,1
endlayer

layer
1,1,1,1,1,1,1,1
1,1,1,1,1,1,1,1
1,1,1,1,1,1,2,1
1,1,1,1,2,1,1,1
1,1,1,1,1,1,1,1
1,1,2,1,1,1,1,1
1,1,1,1,1,1,1,1
1,1,1,1,1,2,1,1
1,1,1,1,1,1,1,1
endlayer

layer
1,1,1,1,1,1,1,1
1,1,1,1,1,1,1,1
1,1,1,1,1,1,2,1
1,1,1,1,2,1,1,1
1,1,1,1,1,1,1,1
1,1,2,1,1,1,1,1
1,1,1,1,1,1,1,1
1,1,1,1,1,2,1,1
1,1,1,1,1,1,1,1
endlayer

layer
1,1,1,1,1,1,1,1
1,1,1,1,1,1,1,1
1,1,1,1,1,1,2,1
1,1,1,1,2,1,1,1
1,1,1,1,1,1,1,1
1,1,2,1,1,1,1,1
1,1,1,1,1,1,1,1
1,1,1,1,1,2,1,1
1,1,1,1,1,1,1,1
endlayer

layer
1,1,1,1,1,1,1,1
1,1,1,1,1,1,1,1
1,1,1,1,1,1,2,1
1,1,1,1,2,1,1,1
1,1,1,1,1,1,1,1
1,1,2,1,1,1,1,1
1,1,1,1,1,1,1,1
1,1,1,1,1,2,1,1
1,1,1,1,1,1,1,1
endlayer

layer
1,1,1,1,1,1,1,1
1,1,1,1,1,1,1,1
1,1,1,1,1,1,2,1
1,1,1,1,2,1,1,1
1,1,1,1,1,1,1,1
1,1,2,1,1,1,1,1
1,1,1,1,1,1,1,1
1,1,1,1,1,2,1,1
1,1,1,1,1,1,1,1
endlayer

layer
1,1,1,1,1,1,1,1
1,1,1,1,1,1,1,1
1,1,1,1,1,1,2,1
1,1,1,1,2,1,1,1
1,1,1,1,1,1,1,1
1,1,2,1,1,1,1,1
1,1,1,1,1,1,1,1
1,1,1,1,1,2,1,1
1,1,1,1,1,1,1,1
endlayer

layer
1,1,1,1,1,1,1,1
1,1,1,1,1,1,1,1
1,1,1,1,1,1,2,1
1,1,1,1,2,1,1,1
1,1,1,1,1,1,1,1
1,1,2,1,1,1,1,1
1,1,1,1,1,1,1,1
1,1,1,1,1,2,1,1
1,1,1,1,1,1,1,1
endlayer

layer
1,1,1,1,1,1,1,1
1,1,1,1,1,1,1,1
1,1,1,1,1,1,2,1
1,1,1,1,2,1,1,1
1,1,1,1,3,1,1,1
1,1,2,1,3,1,1,1
1,1,1,1,3,1,1,1
1,1,1,1,3,2,1,1
1,1,1,1,1,1,1,1
endlayer

layer
1,1,1,1,1,1,1,1
1,1,1,1,1,1,1,1
1,1,1,1,1,1,2,1
1,1,1,1,2,1,1,1
1,1,1,1,1,1,1,1
1,4,4,4,4,4,4,4
1,1,1,1,1,1,1,1
1,1,1,1,1,2,1,1
1,1,1,1,1,1,1,1
endlayer

layer
1,1,1,1,1,1,1,1
1,1,1,1,1,1,3,1
1,1,1,1,1,1,3,1
1,1,1,1,2,1,3,1
1,1,1,1,1,1,3,1
1,1,2,1,1,1,3,1
1,1,1,1,1,1,3,1
1,1,1,1,1,2,3,1
1,1,1,1,1,1,3,1
endlayer

layer
1,1,1,1,1,1,1,1
1,1,1,1,1,1,1,1
1,1,1,1,1,1,2,1
1,1,1,1,2,4,4,4
1,1,1,1,1,1,1,1
1,1,2,1,1,1,1,1
1,1,1,1,1,1,1,1
1,1,1,1,1,2,1,1
1,1,1,1,1,1,1,1
endlayer

layer
1,1,1,1,1,5,1,1
1,1,1,1,1,3,1,1
1,1,1,1,1,3,2,1
1,1,1,1,2,3,1,1
1,1,1,1,6,3,1,1
1,1,2,1,1,3,1,1
1,1,1,1,1,3,1,1
1,1,1,1,1,2,1,1
1,1,1,1,1,1,1,1
endlayer

layer
1,1,1,1,1,1,1,1
1,1,1,1,1,1,1,1
1,5,4,4,4,4,4,4
1,1,1,1,2,1,1,1
1,1,1,1,6,1,1,1
1,1,2,1,1,1,1,1
5,4,4,4,4,4,4,5
1,1,1,1,1,2,1,1
1,1,1,1,1,1,1,1
endlayer

layer
1,1,1,5,1,1,1,1
1,1,1,3,1,1,1,1
1,1,1,3,1,1,1,1
1,1,1,3,2,1,1,1
1,1,5,3,6,1,1,1
1,1,2,3,1,1,1,1
1,1,5,3,5,5,1,1
1,1,1,3,1,2,1,1
1,1,1,5,1,1,1,1
endlayer

layer
1,1,1,1,1,1,1,1
1,1,1,1,1,1,1,1
1,1,7,8,7,7,1,1
1,1,7,10,2,9,1,1
1,1,11,10,6,7,1,1
1,1,2,9,7,7,1,1
1,1,8,8,7,11,1,1
1,1,1,1,1,2,1,1
1,1,1,1,1,1,1,1
endlayer

layer
1,1,1,1,1,1,1,1
1,1,1,1,1,1,1,1
1,1,1,1,1,1,1,1
1,1,1,1,2,1,1,1
1,1,1,1,6,1,1,1
1,1,2,1,1,1,1,1
1,1,1,1,1,1,1,1
1,1,1,1,1,2,1,1
1,1,1,1,1,1,1,1
endlayer

layer
1,1,1,1,1,1,1,1
1,1,1,1,1,1,1,1
1,1,1,1,1,1,1,1
1,1,1,1,2,1,1,1
1,1,1,1,6,1,1,1
1,1,2,1,1,1,1,1
1,1,1,1,1,1,1,1
1,1,1,1,1,2,1,1
1,1,1,1,1,1,1,1
endlayer

layer
1,1,1,1,1,1,1,1
1,1,1,1,1,1,1,1
1,1,1,1,1,1,1,1
1,1,1,1,2,1,1,1
1,1,1,1,6,1,1,1
1,1,2,1,1,1,1,1
1,1,1,1,1,1,1,1
1,1,1,1,1,2,1,1
1,1,1,1,1,1,1,1
endlayer

layer
1,1,1,1,1,1,1,1
1,1,1,1,1,1,1,1
1,1,1,1,1,1,1,1
1,1,1,1,2,1,1,1
1,1,1,1,6,1,1,1
1,1,2,1,1,1,1,1
1,1,1,1,1,1,1,1
1,1,1,1,1,2,1,1
1,1,1,1,1,1,1,1
endlayer

layer
1,1,1,1,1,1,1,1
1,1,1,1,1,1,1,1
1,1,1,3,1,1,1,1
1,1,1,3,2,1,1,1
1,1,5,3,6,1,1,1
1,1,2,3,1,1,1,1
1,1,5,3,1,1,1,1
1,1,1,3,1,2,1,1
1,1,1,1,1,1,1,1
endlayer

layer
1,1,1,1,1,1,1,1
1,1,1,1,1,1,1,1
1,1,1,1,1,1,1,1
1,1,1,5,2,1,1,1
1,1,5,1,6,1,1,1
1,1,2,1,1,1,1,1
1,4,4,4,4,4,4,1
1,1,1,1,5,2,5,1
1,1,1,1,1,1,1,1
endlayer

layer
1,1,1,1,1,1,1,1
1,1,1,1,1,1,1,1
1,1,1,1,1,1,1,1
1,1,1,10,2,9,1,1
1,1,11,7,6,7,7,1
1,1,2,9,7,7,7,1
1,1,8,7,7,11,7,1
1,1,1,7,10,2,5,1
1,1,1,1,1,1,1,1
endlayer

layer
1,1,1,1,1,1,1,1
1,1,1,1,1,1,1,1
1,1,1,1,1,1,1,1
1,1,5,5,2,12,9,1
1,1,5,1,14,1,1,13
1,1,2,1,1,1,1,13
1,1,5,1,1,1,1,13
1,1,5,5,5,2,9,1
1,1,1,1,1,1,1,1
endlayer

