
# Created by Ruins mod version 16.7 Ingame Parser
# authoring Player: lafuller

weight=1
embed_into_distance=13
acceptable_target_blocks=water,waterlily
unacceptable_target_blocks=
biomesToSpawnIn=swampland,jungle,marsh,bog,wetland,mini_jungle,lush_swamp,green_swamp,dead_swamp,tropical_island,land_of_lakes
dimensions=27,9,10
allowable_overhang=0
max_leveling=13
leveling_buffer=-1
preserve_water=0
preserve_lava=0

rule1=0,100,preserveBlock
rule2=0,100,minecraft:log2-1
rule3=0,100,minecraft:log2-9
rule4=0,100,minecraft:log2-5
rule5=0,100,minecraft:spruce_fence-0
rule6=0,100,minecraft:log-3
rule7=0,100,minecraft:wooden_slab-1
rule8=0,100,minecraft:ladder-2
rule9=0,100,minecraft:log-7
rule10=0,100,minecraft:log-11
rule11=0,100,minecraft:trapdoor-15
rule12=0,100,minecraft:spruce_stairs-4
rule13=0,100,minecraft:wooden_slab-9
rule14=0,100,minecraft:spruce_stairs-7
rule15=0,100,minecraft:spruce_stairs-6
rule16=0,100,minecraft:spruce_stairs-5
rule17=0,100,minecraft:spruce_stairs-2
rule18=0,100,minecraft:spruce_stairs-0
rule19=0,100,minecraft:ladder-3
rule20=0,100,minecraft:spruce_stairs-3
rule21=0,100,minecraft:trapdoor-0
rule22=0,100,minecraft:spruce_fence_gate-3
rule23=0,100,minecraft:spruce_stairs-1
rule24=0,100,minecraft:carpet-7
rule25=0,100,minecraft:wooden_slab-13
rule26=0,100,minecraft:planks-1
rule27=0,100,minecraft:dark_oak_stairs-6
rule28=0,100,minecraft:planks-5
rule29=0,100,minecraft:dark_oak_stairs-4
rule30=0,100,minecraft:wooden_slab-5
rule31=0,100,minecraft:dark_oak_stairs-2
rule32=0,100,minecraft:dark_oak_stairs-5
rule33=0,100,minecraft:dark_oak_stairs-0
rule34=0,100,minecraft:dark_oak_stairs-3
rule35=0,100,minecraft:dark_oak_stairs-1
rule36=0,100,minecraft:double_wooden_slab-5
rule37=0,100,minecraft:trapdoor-4

layer
1,1,1,1,1,1,1,1,1,1
1,1,1,1,1,1,1,1,1,1
1,1,1,1,2,1,1,1,1,1
1,1,2,1,1,1,1,1,1,1
1,1,1,1,1,1,1,2,1,1
1,1,1,1,1,1,1,1,1,1
1,1,1,2,1,1,1,1,1,1
1,1,1,1,1,1,2,1,1,1
1,1,1,1,1,1,1,1,1,1
endlayer

layer
1,1,1,1,1,1,1,1,1,1
1,1,1,1,1,1,1,1,1,1
1,1,1,1,2,1,1,1,1,1
1,1,2,1,1,1,1,1,1,1
1,1,1,1,1,1,1,2,1,1
1,1,1,1,1,1,1,1,1,1
1,1,1,2,1,1,1,1,1,1
1,1,1,1,1,1,2,1,1,1
1,1,1,1,1,1,1,1,1,1
endlayer

layer
1,1,1,1,1,1,1,1,1,1
1,1,1,1,1,1,1,1,1,1
1,1,1,1,2,1,1,1,1,1
1,1,2,1,1,1,1,1,1,1
1,1,1,1,1,1,1,2,1,1
1,1,1,1,1,1,1,1,1,1
1,1,1,2,1,1,1,1,1,1
1,1,1,1,1,1,2,1,1,1
1,1,1,1,1,1,1,1,1,1
endlayer

layer
1,1,1,1,1,1,1,1,1,1
1,1,1,1,1,1,1,1,1,1
1,1,1,1,2,1,1,1,1,1
1,1,2,1,1,1,1,1,1,1
1,1,1,1,1,1,1,2,1,1
1,1,1,1,1,1,1,1,1,1
1,1,1,2,1,1,1,1,1,1
1,1,1,1,1,1,2,1,1,1
1,1,1,1,1,1,1,1,1,1
endlayer

layer
1,1,1,1,1,1,1,1,1,1
1,1,1,1,1,1,1,1,1,1
1,1,1,1,2,1,1,1,1,1
1,1,2,1,1,1,1,1,1,1
1,1,1,1,1,1,1,2,1,1
1,1,1,1,1,1,1,1,1,1
1,1,1,2,1,1,1,1,1,1
1,1,1,1,1,1,2,1,1,1
1,1,1,1,1,1,1,1,1,1
endlayer

layer
1,1,1,1,1,1,1,1,1,1
1,1,1,1,1,1,1,1,1,1
1,1,1,1,2,1,1,1,1,1
1,1,2,1,1,1,1,1,1,1
1,1,1,1,1,1,1,2,1,1
1,1,1,1,1,1,1,1,1,1
1,1,1,2,1,1,1,1,1,1
1,1,1,1,1,1,2,1,1,1
1,1,1,1,1,1,1,1,1,1
endlayer

layer
1,1,1,1,1,1,1,1,1,1
1,1,1,1,1,1,1,1,1,1
1,1,1,1,2,1,1,1,1,1
1,1,2,1,1,1,1,1,1,1
1,1,1,1,1,1,1,2,1,1
1,1,1,1,1,1,1,1,1,1
1,1,1,2,1,1,1,1,1,1
1,1,1,1,1,1,2,1,1,1
1,1,1,1,1,1,1,1,1,1
endlayer

layer
1,1,1,1,1,1,1,1,1,1
1,1,1,1,1,1,1,1,1,1
1,1,1,1,2,1,1,1,1,1
1,1,2,1,1,1,1,1,1,1
1,1,1,1,1,1,1,2,1,1
1,1,1,1,1,1,1,1,1,1
1,1,1,2,1,1,1,1,1,1
1,1,1,1,1,1,2,1,1,1
1,1,1,1,1,1,1,1,1,1
endlayer

layer
1,1,1,1,1,1,1,1,1,1
1,1,1,1,1,1,1,1,1,1
1,1,1,1,2,1,1,1,1,1
1,1,2,1,1,1,1,1,1,1
1,1,1,1,1,1,1,2,1,1
1,1,1,1,1,1,1,1,1,1
1,1,1,2,1,1,1,1,1,1
1,1,1,1,1,1,2,1,1,1
1,1,1,1,1,1,1,1,1,1
endlayer

layer
1,1,1,1,1,1,1,1,1,1
1,1,1,1,1,1,1,1,1,1
1,1,1,1,2,1,1,1,1,1
1,1,2,1,1,1,1,1,1,1
1,3,3,3,3,3,3,3,3,1
1,1,1,1,1,1,1,1,1,1
1,1,1,2,1,1,1,1,1,1
1,1,1,3,3,3,3,3,1,1
1,1,1,1,1,1,1,1,1,1
endlayer

layer
1,1,1,1,1,1,1,1,1,1
1,1,1,1,4,1,1,4,1,1
1,1,1,1,4,1,1,4,1,1
1,1,2,1,4,1,1,4,1,1
1,1,1,1,4,1,1,4,1,1
1,1,1,1,4,1,1,4,1,1
1,1,1,2,4,1,1,4,1,1
1,1,1,1,4,1,1,4,1,1
1,1,1,1,1,1,1,4,1,1
endlayer

layer
1,1,1,1,1,1,1,1,1,1
1,1,1,1,2,1,1,1,1,1
1,3,3,3,3,3,3,3,1,1
1,1,2,1,1,1,1,1,1,1
1,1,1,1,1,1,1,2,1,1
1,1,3,3,3,3,3,3,3,1
1,1,1,2,1,1,1,1,1,1
1,1,1,1,1,1,1,2,1,1
1,1,1,1,1,1,1,1,1,1
endlayer

layer
1,1,1,1,1,1,1,1,1,1
1,1,1,4,2,1,4,1,1,1
1,1,1,4,1,1,4,1,1,1
1,1,2,4,1,1,4,1,1,1
1,1,1,4,1,1,4,2,1,1
1,1,1,4,1,1,4,1,1,1
1,1,1,4,1,1,4,1,1,1
1,1,1,4,1,1,4,2,1,1
1,1,1,4,1,1,4,1,1,1
endlayer

layer
1,1,1,1,5,1,1,1,1,1
1,1,1,1,6,1,5,1,1,1
1,1,5,1,1,1,6,5,1,1
1,1,6,1,1,1,1,1,1,1
5,3,3,3,3,3,3,3,3,5
1,1,7,6,7,7,7,7,1,1
1,1,7,7,7,7,7,7,1,1
1,1,1,7,7,7,7,6,5,1
1,1,1,1,1,1,1,5,1,1
endlayer

layer
1,1,1,1,5,1,1,1,1,1
1,1,1,1,6,1,1,1,1,1
1,1,1,7,7,7,6,1,1,1
1,1,6,7,7,7,7,7,1,1
1,1,1,7,7,1,1,6,5,1
1,1,1,6,8,1,1,1,1,1
1,1,1,1,1,1,1,1,1,1
1,1,1,1,1,1,1,6,1,1
1,1,1,1,1,1,1,5,1,1
endlayer

layer
1,1,1,1,1,1,1,1,1,1
1,1,1,1,6,1,1,1,1,1
1,1,1,1,1,1,6,1,1,1
1,1,6,1,1,1,1,1,1,1
1,1,1,1,1,1,1,6,5,1
1,1,1,6,8,1,1,1,1,1
1,1,1,1,1,1,1,1,1,1
1,1,1,1,1,1,1,6,1,1
1,1,1,1,1,1,1,1,1,1
endlayer

layer
1,1,1,1,1,1,1,1,1,1
1,1,1,1,6,1,1,1,1,1
1,1,1,1,1,1,6,1,1,1
1,1,6,1,1,1,1,1,1,1
1,1,1,1,1,1,1,6,5,1
1,1,1,6,8,1,1,5,1,1
1,1,1,1,1,1,1,1,1,1
1,1,1,1,1,1,1,6,1,1
1,1,1,1,1,1,1,1,1,1
endlayer

layer
1,1,1,5,1,1,1,1,1,1
1,1,1,9,6,1,1,1,1,1
1,1,1,9,1,1,6,5,5,1
5,10,10,10,10,10,10,10,10,5
1,1,5,9,1,1,1,6,5,1
1,1,5,9,8,1,1,5,5,1
1,1,1,9,1,1,1,1,1,1
1,1,1,9,1,1,1,6,1,1
1,1,1,11,1,1,1,1,1,1
endlayer

layer
1,1,1,1,1,1,1,5,1,1
1,1,1,13,6,13,12,9,1,1
1,1,1,14,13,14,6,9,5,1
1,1,14,13,13,13,13,9,15,1
1,1,13,12,13,13,16,9,13,1
1,1,14,6,8,13,12,9,15,1
1,5,10,10,10,10,10,9,10,5
1,1,1,16,13,13,16,9,1,1
1,1,1,1,1,1,1,11,1,1
endlayer

layer
1,1,1,1,1,1,1,1,1,1
1,1,1,18,6,18,17,1,1,1
1,1,20,0,0,19,6,18,5,1
1,1,20,0,0,0,0,0,17,1
1,1,20,0,0,0,0,0,17,1
1,1,5,6,21,0,0,0,17,1
1,1,5,5,23,20,22,6,5,1
1,1,1,1,1,1,1,5,1,1
1,1,1,1,1,1,1,1,1,1
endlayer

layer
1,1,1,1,5,1,1,1,1,1
1,1,1,5,6,5,1,1,1,1
1,1,5,0,0,19,6,5,5,1
1,1,5,0,0,0,0,0,5,1
1,1,0,0,0,0,0,0,0,1
1,1,5,6,0,0,0,0,5,1
1,1,1,5,0,5,0,6,5,1
1,1,1,1,1,1,1,1,1,1
1,1,1,1,1,1,1,1,1,1
endlayer

layer
1,1,1,1,5,5,1,1,1,1
1,1,1,12,6,12,12,1,1,1
1,1,14,13,13,19,6,12,1,1
1,1,14,13,13,0,0,0,15,1
1,1,14,13,13,0,0,0,15,1
1,1,14,6,13,0,0,0,15,1
1,1,1,16,16,16,16,6,16,1
1,1,1,13,1,1,1,13,1,1
1,1,1,1,1,1,1,1,1,1
endlayer

layer
1,1,1,1,1,1,1,1,1,1
1,1,1,18,6,18,18,1,1,1
1,1,20,24,24,19,6,18,1,1
1,1,20,24,24,0,0,0,17,1
1,1,20,24,24,0,0,0,17,1
1,1,20,6,0,0,0,0,17,1
1,1,20,0,0,0,0,6,23,1
1,1,1,23,23,23,23,5,1,1
1,1,1,1,1,1,1,1,1,1
endlayer

layer
1,1,1,1,1,1,1,1,1,1
1,1,1,5,6,0,5,1,1,1
1,1,5,0,0,0,6,12,12,1
1,1,5,0,0,0,0,0,26,25
1,1,0,0,0,0,0,0,26,27
1,1,5,6,0,0,0,0,28,25
1,1,5,0,0,0,0,6,27,25
1,1,1,5,5,0,5,5,1,1
1,1,1,1,1,1,1,1,1,1
endlayer

layer
1,1,1,25,29,25,25,1,1,1
1,1,12,12,6,12,29,27,25,1
1,25,14,0,0,0,6,28,28,30
1,1,14,0,0,0,0,14,28,31
1,1,14,0,0,0,0,14,28,31
1,1,14,6,0,0,0,14,28,30
1,25,14,0,0,0,0,6,31,1
1,1,25,16,16,16,16,32,30,1
1,1,1,25,25,25,25,1,1,1
endlayer

layer
1,1,1,1,1,1,5,1,1,1
1,1,34,33,33,33,9,33,1,1
1,1,34,15,16,16,9,31,30,1
1,30,28,15,13,13,9,28,30,1
1,30,28,15,13,0,9,28,30,1
1,30,35,6,12,12,9,28,30,1
1,1,34,28,28,28,9,28,1,1
1,1,1,34,35,35,9,35,1,1
1,1,1,1,1,1,5,1,1,1
endlayer

layer
1,1,1,1,1,1,1,1,1,1
1,1,1,1,1,1,1,1,1,1
1,1,1,30,33,33,30,1,1,1
1,1,1,34,36,36,31,1,1,1
1,1,1,34,36,37,36,31,1,1
1,1,1,30,28,36,36,30,1,1
1,1,1,1,30,35,30,1,1,1
1,1,1,1,1,1,1,1,1,1
1,1,1,1,1,1,1,1,1,1
endlayer

