
# Created by Ruins mod version 16.7 Ingame Parser
# authoring Player: lafuller

weight=1
embed_into_distance=13
acceptable_target_blocks=flowing_water,water
unacceptable_target_blocks=
biomesToSpawnIn=river,swampland,lush swamp,marsh
dimensions=24,14,14
allowable_overhang=0
max_leveling=3
leveling_buffer=-1
preserve_water=0
preserve_lava=0

rule1=0,100,preserveBlock
rule2=0,100,minecraft:log2-1
rule3=0,100,minecraft:log2-9
rule4=0,100,minecraft:planks-1
rule5=0,100,minecraft:spruce_fence-0
rule6=0,100,minecraft:log-4
rule7=0,100,minecraft:ladder-4
rule8=0,100,minecraft:fence-0
rule9=0,100,minecraft:log-8
rule10=0,100,minecraft:wooden_slab-9
rule11=0,100,minecraft:log-0
rule12=0,100,minecraft:oak_stairs-7
rule13=0,100,minecraft:spruce_stairs-0
rule14=0,100,minecraft:oak_stairs-5
rule15=0,100,minecraft:oak_stairs-4
rule16=0,100,minecraft:oak_stairs-6
rule17=0,100,minecraft:planks-0
rule18=0,100,minecraft:oak_stairs-1
rule19=0,100,minecraft:oak_stairs-0
rule20=0,100,minecraft:bookshelf-0
rule21=0,100,minecraft:crafting_table-0
rule22=0,100,minecraft:oak_stairs-2
rule23=0,100,minecraft:spruce_stairs-5
rule24=0,100,minecraft:oak_stairs-3
rule25=0,100,minecraft:spruce_fence_gate-3
rule26=0,100,minecraft:spruce_stairs-4
rule27=0,100,minecraft:spruce_door-0
rule28=0,100,minecraft:trapdoor-9
rule29=0,100,minecraft:cauldron-0

rule30=0,100,IInventory;hopper;gold_ingot#2#0#0-3,IInventory;hopper;redstone#3#0#0+paper#4#0#1-3,IInventory;hopper;cooked_porkchop#4#0#0-3,IInventory;hopper;iron_ingot#1#0#0-3,IInventory;hopper;glass_bottle#6#0#0+cooked_beef#3#0#1-3,IInventory;hopper;double_plant#2#0#0+cooked_mutton#2#0#1-3

rule31=0,100,IInventory;dropper;iron_ingot#2#0#6-1,IInventory;dropper;gold_ingot#1#0#8-1,IInventory;dropper;spruce_boat#1#0#3-1,IInventory;dropper;milk_bucket#1#0#4-1,IInventory;dropper;gunpowder#4#0#5-1,IInventory;dropper;coal#3#0#2-1

rule32=0,100,minecraft:stone-4
rule33=0,100,minecraft:spruce_fence_gate-1
rule34=0,100,minecraft:carpet-8
rule35=0,100,minecraft:spruce_fence_gate-2
rule36=0,100,minecraft:carpet-7
rule37=0,100,minecraft:carpet-12
rule38=0,100,minecraft:spruce_door-8
rule39=0,100,minecraft:spruce_door-9
rule40=0,100,minecraft:spruce_fence_gate-0
rule41=0,100,IInventory;furnace;coal#3#0#1-4
rule42=0,100,minecraft:trapdoor-11
rule43=0,100,minecraft:cobblestone_wall-0
rule44=0,100,minecraft:spruce_stairs-6
rule45=0,100,minecraft:spruce_stairs-7
rule46=0,100,minecraft:spruce_stairs-3
rule47=0,100,minecraft:spruce_stairs-1
rule48=0,100,minecraft:wooden_slab-13
rule49=0,100,minecraft:dark_oak_stairs-5
rule50=0,100,minecraft:dark_oak_stairs-7
rule51=0,100,minecraft:dark_oak_stairs-4
rule52=0,100,minecraft:dark_oak_stairs-0
rule53=0,100,minecraft:wooden_slab-1
rule54=0,100,minecraft:dark_oak_stairs-1
rule55=0,100,minecraft:spruce_stairs-2
rule56=0,100,minecraft:dark_oak_stairs-6
rule57=0,100,minecraft:dark_oak_stairs-2
rule58=0,100,minecraft:dark_oak_stairs-3
rule59=0,100,minecraft:wooden_slab-5
rule60=0,100,minecraft:double_wooden_slab-5
rule61=0,100,minecraft:planks-5

layer
1,1,1,1,1,1,1,1,1,1,1,1,1,1
1,1,1,1,1,1,1,1,1,1,1,1,1,1
1,1,1,1,1,1,1,1,1,1,1,1,1,1
1,1,1,1,1,1,1,1,1,1,1,1,1,1
1,1,1,1,2,1,2,1,1,1,1,1,1,1
1,1,1,1,1,1,1,1,1,1,1,1,1,1
1,1,1,1,1,1,1,1,1,1,1,1,1,1
1,1,1,1,1,1,1,1,1,1,1,1,1,1
1,1,1,1,2,1,1,1,1,1,2,1,1,1
1,1,1,1,1,1,1,1,1,1,1,1,1,1
1,1,1,1,2,1,1,1,1,1,2,1,1,1
1,1,1,1,1,1,1,1,1,1,1,1,1,1
1,1,1,1,1,1,1,1,1,1,1,1,1,1
1,1,1,1,1,1,1,1,1,1,1,1,1,1
endlayer

layer
1,1,1,1,1,1,1,1,1,1,1,1,1,1
1,1,1,1,1,1,1,1,1,1,1,1,1,1
1,1,1,1,1,1,1,1,1,1,1,1,1,1
1,1,1,1,1,1,1,1,1,1,1,1,1,1
1,1,1,1,2,1,2,1,1,1,1,1,1,1
1,1,1,1,1,1,1,1,1,1,1,1,1,1
1,1,1,1,1,1,1,1,1,1,1,1,1,1
1,1,1,1,1,1,1,1,1,1,1,1,1,1
1,1,1,1,2,1,1,1,1,1,2,1,1,1
1,1,1,1,1,1,1,1,1,1,1,1,1,1
1,1,1,1,2,1,1,1,1,1,2,1,1,1
1,1,1,1,1,1,1,1,1,1,1,1,1,1
1,1,1,1,1,1,1,1,1,1,1,1,1,1
1,1,1,1,1,1,1,1,1,1,1,1,1,1
endlayer

layer
1,1,1,1,1,1,1,1,1,1,1,1,1,1
1,1,1,1,1,1,1,1,1,1,1,1,1,1
1,1,1,1,1,1,1,1,1,1,1,1,1,1
1,1,1,1,1,1,1,1,1,1,1,1,1,1
1,1,1,1,2,1,2,1,1,1,1,1,1,1
1,1,1,1,1,1,1,1,1,1,1,1,1,1
1,1,1,1,1,1,1,1,1,1,1,1,1,1
1,1,1,1,1,1,1,1,1,1,1,1,1,1
1,1,1,1,2,1,1,1,1,1,2,1,1,1
1,1,1,1,1,1,1,1,1,1,1,1,1,1
1,1,1,1,2,1,1,1,1,1,2,1,1,1
1,1,1,1,1,1,1,1,1,1,1,1,1,1
1,1,1,1,1,1,1,1,1,1,1,1,1,1
1,1,1,1,1,1,1,1,1,1,1,1,1,1
endlayer

layer
1,1,1,1,1,1,1,1,1,1,1,1,1,1
1,1,1,1,1,1,1,1,1,1,1,1,1,1
1,1,1,1,1,1,1,1,1,1,1,1,1,1
1,1,1,1,1,1,1,1,1,1,1,1,1,1
1,1,1,1,2,1,2,1,1,1,1,1,1,1
1,1,1,1,1,1,1,1,1,1,1,1,1,1
1,1,1,1,1,1,1,1,1,1,1,1,1,1
1,1,1,1,1,1,1,1,1,1,1,1,1,1
1,1,1,1,2,1,1,1,1,1,2,1,1,1
1,1,1,1,1,1,1,1,1,1,1,1,1,1
1,1,1,1,2,1,1,1,1,1,2,1,1,1
1,1,1,1,1,1,1,1,1,1,1,1,1,1
1,1,1,1,1,1,1,1,1,1,1,1,1,1
1,1,1,1,1,1,1,1,1,1,1,1,1,1
endlayer

layer
1,1,1,1,1,1,1,1,1,1,1,1,1,1
1,1,1,1,1,1,1,1,1,1,1,1,1,1
1,1,1,1,1,1,1,1,1,1,1,1,1,1
1,1,1,1,1,1,1,1,1,1,1,1,1,1
1,1,1,1,2,1,2,1,1,1,1,1,1,1
1,1,1,1,1,1,1,1,1,1,1,1,1,1
1,1,1,1,1,1,1,1,1,1,1,1,1,1
1,1,1,1,1,1,1,1,1,1,1,1,1,1
1,1,1,1,2,1,1,1,1,1,2,1,1,1
1,1,1,1,1,1,1,1,1,1,1,1,1,1
1,1,1,1,2,1,1,1,1,1,2,1,1,1
1,1,1,1,1,1,1,1,1,1,1,1,1,1
1,1,1,1,1,1,1,1,1,1,1,1,1,1
1,1,1,1,1,1,1,1,1,1,1,1,1,1
endlayer

layer
1,1,1,1,1,1,1,1,1,1,1,1,1,1
1,1,1,1,1,1,1,1,1,1,1,1,1,1
1,1,1,1,1,1,1,1,1,1,1,1,1,1
1,1,1,1,1,1,1,1,1,1,1,1,1,1
1,1,1,1,2,1,2,1,1,1,1,1,1,1
1,1,1,1,1,1,1,1,1,1,1,1,1,1
1,1,1,1,1,1,1,1,1,1,1,1,1,1
1,1,1,1,1,1,1,1,1,1,1,1,1,1
1,1,1,1,2,1,1,1,1,1,2,1,1,1
1,1,1,1,1,1,1,1,1,1,1,1,1,1
1,1,1,1,2,1,1,1,1,1,2,1,1,1
1,1,1,1,1,1,1,1,1,1,1,1,1,1
1,1,1,1,1,1,1,1,1,1,1,1,1,1
1,1,1,1,1,1,1,1,1,1,1,1,1,1
endlayer

layer
1,1,1,1,1,1,1,1,1,1,1,1,1,1
1,1,1,1,1,1,1,1,1,1,1,1,1,1
1,1,1,1,1,1,1,1,1,1,1,1,1,1
1,1,1,1,1,1,1,1,1,1,1,1,1,1
1,1,1,1,2,1,2,1,1,1,1,1,1,1
1,1,1,1,1,1,1,1,1,1,1,1,1,1
1,1,1,1,1,1,1,1,1,1,1,1,1,1
1,1,1,1,1,1,1,1,1,1,1,1,1,1
1,1,1,1,2,1,1,1,1,1,2,1,1,1
1,1,1,1,1,1,1,1,1,1,1,1,1,1
1,1,1,1,2,1,1,1,1,1,2,1,1,1
1,1,1,1,1,1,1,1,1,1,1,1,1,1
1,1,1,1,1,1,1,1,1,1,1,1,1,1
1,1,1,1,1,1,1,1,1,1,1,1,1,1
endlayer

layer
1,1,1,1,1,1,1,1,1,1,1,1,1,1
1,1,1,1,1,1,1,1,1,1,1,1,1,1
1,1,1,1,1,1,1,1,1,1,1,1,1,1
1,1,1,1,1,1,1,1,1,1,1,1,1,1
1,1,1,1,2,1,2,1,1,1,1,1,1,1
1,1,1,1,1,1,1,1,1,1,1,1,1,1
1,1,1,1,1,1,1,1,1,1,1,1,1,1
1,1,1,1,1,1,1,1,1,1,1,1,1,1
1,1,1,1,2,1,1,1,1,1,2,1,1,1
1,1,1,1,1,1,1,1,1,1,1,1,1,1
1,1,1,1,2,1,1,1,1,1,2,1,1,1
1,1,1,1,1,1,1,1,1,1,1,1,1,1
1,1,1,1,1,1,1,1,1,1,1,1,1,1
1,1,1,1,1,1,1,1,1,1,1,1,1,1
endlayer

layer
1,1,1,1,1,1,1,1,1,1,1,1,1,1
1,1,1,1,1,1,1,1,1,1,1,1,1,1
1,1,1,1,1,1,1,1,1,1,1,1,1,1
1,1,1,1,1,1,1,1,1,1,1,1,1,1
1,1,1,1,2,1,2,1,1,1,1,1,1,1
1,1,1,1,1,1,1,1,1,1,1,1,1,1
1,1,1,1,1,1,1,1,1,1,1,1,1,1
1,1,1,1,1,1,1,1,1,1,1,1,1,1
1,1,1,1,2,1,1,1,1,1,2,1,1,1
1,1,1,1,1,1,1,1,1,1,1,1,1,1
1,1,1,1,2,1,1,1,1,1,2,1,1,1
1,1,1,1,1,1,1,1,1,1,1,1,1,1
1,1,1,1,1,1,1,1,1,1,1,1,1,1
1,1,1,1,1,1,1,1,1,1,1,1,1,1
endlayer

layer
1,1,1,1,1,1,1,1,1,1,1,1,1,1
1,1,1,1,1,1,1,1,1,1,1,1,1,1
1,1,1,1,1,1,1,1,1,1,1,1,1,1
1,1,1,1,1,1,1,1,1,1,1,1,1,1
1,1,1,1,2,1,2,1,1,1,1,1,1,1
1,1,1,1,1,1,1,1,1,1,1,1,1,1
1,1,1,1,1,1,1,1,1,1,1,1,1,1
1,1,1,1,1,1,1,1,1,1,1,1,1,1
1,1,1,1,2,1,1,1,1,1,2,1,1,1
1,1,1,1,1,1,1,1,1,1,1,1,1,1
1,1,1,1,2,1,1,1,1,1,2,1,1,1
1,1,1,1,1,1,1,1,1,1,1,1,1,1
1,1,1,1,1,1,1,1,1,1,1,1,1,1
1,1,1,1,1,1,1,1,1,1,1,1,1,1
endlayer

layer
1,1,1,1,1,1,1,1,1,1,1,1,1,1
1,1,1,1,1,1,1,1,1,1,1,1,1,1
1,1,1,1,1,1,1,1,1,1,1,1,1,1
1,1,1,1,1,1,1,1,1,1,1,1,1,1
1,1,1,1,2,1,2,1,1,1,1,1,1,1
1,1,1,1,1,1,1,1,1,1,1,1,1,1
1,1,1,1,1,1,1,1,1,1,1,1,1,1
1,1,1,1,1,1,1,1,1,1,1,1,1,1
1,1,1,1,2,1,1,1,1,1,2,1,1,1
1,1,1,1,1,1,1,1,1,1,1,1,1,1
1,1,1,1,2,1,1,1,1,1,2,1,1,1
1,1,1,1,1,1,1,1,1,1,1,1,1,1
1,1,1,1,1,1,1,1,1,1,1,1,1,1
1,1,1,1,1,1,1,1,1,1,1,1,1,1
endlayer

layer
1,1,1,1,1,1,1,1,1,1,1,1,1,1
1,1,1,1,1,1,1,1,1,1,1,1,1,1
1,1,1,1,1,1,1,1,1,1,1,1,1,1
1,1,1,1,1,1,1,1,1,1,1,1,1,1
1,1,1,1,2,1,2,1,1,1,1,1,1,1
1,1,1,1,1,1,1,1,1,1,1,1,1,1
1,1,1,1,1,1,1,1,1,1,1,1,1,1
1,1,1,1,1,1,1,1,1,1,1,1,1,1
1,1,1,1,2,1,1,1,1,1,2,1,1,1
1,1,1,1,1,1,1,1,1,1,1,1,1,1
1,1,1,1,2,1,1,1,1,1,2,1,1,1
1,1,1,1,1,1,1,1,1,1,1,1,1,1
1,1,1,1,1,1,1,1,1,1,1,1,1,1
1,1,1,1,1,1,1,1,1,1,1,1,1,1
endlayer

layer
1,1,1,1,1,1,1,1,1,1,1,1,1,1
1,1,1,1,1,1,1,1,1,1,1,1,1,1
1,1,1,1,1,1,1,1,1,1,1,1,1,1
1,1,3,3,3,3,3,3,3,3,3,3,1,1
1,1,1,1,2,1,2,1,1,4,4,4,1,1
1,1,3,3,3,3,3,3,3,3,3,3,3,1
1,1,1,1,1,1,1,1,1,1,1,1,1,1
1,1,3,3,3,3,3,3,3,3,3,3,3,1
1,1,1,1,2,1,1,1,1,1,2,1,1,1
1,1,3,3,3,3,3,3,3,3,3,3,3,1
1,1,1,1,2,1,1,1,1,1,2,1,1,1
1,1,3,3,3,3,3,3,3,3,3,3,3,1
1,1,1,1,1,1,1,1,1,1,1,1,1,1
1,1,1,1,1,1,1,1,1,1,1,1,1,1
endlayer

layer
1,1,1,1,1,1,1,1,1,1,1,1,1,1
1,1,1,5,1,5,1,5,1,1,1,1,1,1
1,1,1,6,1,6,1,6,1,1,1,1,1,1
1,1,1,6,1,6,1,6,1,1,1,1,1,1
1,1,1,6,2,6,2,6,1,7,7,1,1,1
1,1,1,6,1,6,1,6,1,6,4,6,1,1
1,1,1,6,1,6,1,6,1,6,1,6,1,1
1,1,1,6,1,6,1,6,1,6,1,6,1,1
1,1,1,6,2,6,1,6,1,6,2,6,1,1
1,1,1,6,1,6,1,6,1,6,1,6,1,1
1,1,1,6,2,6,1,6,1,6,2,6,1,1
1,1,1,6,1,6,1,6,1,6,1,6,1,1
1,1,1,5,1,5,1,5,1,5,1,5,1,1
1,1,1,1,1,1,1,1,1,1,1,1,1,1
endlayer

layer
1,1,1,1,1,1,1,1,1,1,1,1,1,1
1,5,1,8,1,8,1,8,1,1,1,1,1,1
5,9,9,9,9,9,9,9,9,1,1,1,1,1
1,1,1,1,1,1,1,1,1,1,1,1,1,1
1,1,1,1,2,1,2,1,1,7,7,1,1,1
5,9,9,9,9,9,9,9,9,9,9,9,9,8
1,1,1,1,1,1,1,1,1,1,1,1,1,1
1,1,1,1,1,1,1,1,1,1,1,1,1,1
5,9,9,9,9,9,9,9,9,9,9,9,9,5
1,1,1,1,1,1,1,1,1,1,1,1,1,1
1,1,1,1,2,1,1,1,1,1,2,1,1,1
5,9,9,9,9,9,9,9,9,9,9,9,9,5
1,1,1,8,1,8,1,8,1,8,1,8,1,1
1,1,1,1,1,1,1,1,1,1,1,1,1,1
endlayer

layer
1,1,5,0,5,0,5,0,5,1,1,1,1,1
1,8,6,10,6,10,6,10,6,0,1,1,1,1
8,11,6,10,6,10,6,10,6,0,0,1,1,1
0,8,6,10,6,10,6,10,6,0,0,0,1,1
0,12,6,10,6,10,6,10,6,0,0,0,0,1
8,11,6,10,6,10,6,10,6,13,13,13,6,8
0,14,6,10,6,10,6,0,6,10,6,10,6,0
0,12,6,10,6,10,6,10,6,10,6,10,6,0
8,11,6,10,6,10,6,10,6,10,6,10,6,5
0,14,6,10,6,10,6,10,6,10,6,10,6,0
0,15,6,10,6,10,6,10,6,10,6,10,6,0
8,11,6,10,6,10,6,10,6,10,6,10,6,5
1,0,6,14,6,16,6,8,6,12,6,8,6,1
1,1,5,0,5,0,5,0,5,0,5,0,5,1
endlayer

layer
1,0,0,0,0,0,0,0,0,0,1,1,1,1
0,8,15,19,18,18,17,15,8,0,0,1,1,1
0,12,11,21,0,0,20,11,17,0,0,0,1,1
0,17,23,23,0,0,0,0,22,0,0,0,0,1
0,17,10,10,0,0,0,0,24,0,0,0,0,0
0,17,26,26,0,0,5,25,17,0,0,0,5,0
0,17,20,0,0,0,5,25,11,27,27,17,11,0
0,12,0,0,0,0,0,0,0,0,0,28,16,0
0,22,0,0,0,0,0,0,0,0,0,0,24,0
0,22,0,0,0,0,0,0,0,0,0,0,24,0
0,17,21,0,0,0,0,0,0,0,0,28,22,0
0,12,11,32,31,30,29,0,0,0,0,11,17,8
0,0,17,18,19,19,17,17,19,19,17,17,8,0
1,0,8,0,8,0,8,0,8,0,8,0,0,1
endlayer

layer
0,0,0,0,0,0,0,0,0,0,0,1,1,1
0,8,17,17,33,33,17,17,8,0,0,0,1,1
0,12,11,20,0,0,20,11,16,0,0,0,0,1
0,17,34,34,0,0,0,0,17,0,0,0,0,0
0,17,36,36,0,0,0,0,35,0,0,0,0,0
0,17,36,36,0,0,37,37,17,0,0,0,8,0
0,17,20,0,0,0,37,37,11,39,38,17,11,0
0,17,0,0,0,0,0,0,0,0,0,0,17,0
0,40,0,0,0,0,0,0,0,0,0,0,35,0
0,40,0,0,0,0,0,0,0,0,0,0,35,0
0,17,0,0,0,0,0,0,0,0,0,0,17,0
0,17,11,0,0,0,41,0,0,0,0,11,14,0
0,8,17,17,25,25,17,17,25,25,17,18,8,0
0,0,0,0,0,0,0,0,0,0,0,0,0,0
endlayer

layer
0,0,0,0,0,0,0,0,0,0,0,0,1,1
0,8,15,17,14,14,17,22,8,0,0,0,0,1
0,17,11,20,0,0,42,11,22,0,0,0,0,0
0,17,0,0,0,0,0,0,17,0,0,0,0,0
0,17,0,0,0,0,0,0,12,0,0,0,0,0
0,17,0,0,0,0,0,0,17,0,0,0,8,0
0,17,0,0,0,0,0,0,11,25,25,17,11,8
0,17,0,0,0,0,0,0,0,0,0,28,17,0
0,16,0,0,0,0,0,0,0,0,0,28,12,0
0,16,0,0,0,0,0,0,0,0,0,28,12,0
0,17,0,0,0,0,0,0,0,0,0,28,22,0
0,17,11,0,0,0,43,0,0,0,0,11,17,0
0,8,17,17,15,15,17,14,15,15,17,17,8,0
0,0,0,0,0,0,0,0,0,0,0,0,0,0
endlayer

layer
0,0,0,8,8,0,0,0,0,0,0,0,0,1
0,45,26,17,17,17,19,44,26,0,0,0,0,0
0,46,11,0,0,0,0,11,17,0,0,0,0,0
0,45,0,0,0,0,0,0,17,0,0,0,0,0
0,45,0,0,0,0,0,0,17,10,0,0,0,0
0,17,0,0,0,0,0,0,17,44,26,10,0,0
0,24,0,0,0,0,0,0,11,17,17,17,11,8
0,17,0,0,0,0,0,0,0,0,0,0,17,44
0,24,0,0,0,0,0,0,0,0,0,0,17,23
0,46,0,0,0,0,0,0,0,0,0,0,17,0
0,45,0,0,0,0,0,0,0,0,0,0,17,0
0,45,11,0,0,0,43,0,0,0,0,11,22,0
0,8,47,17,17,17,17,17,17,17,14,17,44,0
0,0,0,0,0,8,50,49,48,8,0,0,0,0
endlayer

layer
0,0,51,51,50,50,51,48,0,0,0,0,0,0
0,50,51,50,51,0,0,51,51,52,0,0,0,0
0,50,11,5,5,5,5,11,5,49,0,0,0,0
51,50,5,0,0,0,0,0,5,49,0,0,0,0
50,51,5,0,0,0,0,0,5,54,53,0,0,0
10,46,5,0,0,0,0,0,5,56,51,55,53,0
0,45,5,0,0,0,0,0,11,5,5,5,56,56
0,45,5,0,0,0,0,0,0,0,0,5,56,56
10,46,5,0,0,0,0,0,0,0,0,5,56,56
10,4,5,0,0,0,0,0,0,0,0,5,57,48
49,50,5,0,0,0,0,0,0,0,0,5,56,56
0,58,11,5,5,5,43,5,5,5,5,11,49,57
0,47,46,49,49,49,49,0,56,49,0,49,49,59
0,0,0,0,49,0,54,49,54,59,49,59,54,0
endlayer

layer
0,0,0,59,52,52,52,52,0,0,0,0,0,0
0,0,52,51,51,51,49,56,52,0,0,0,0,0
0,0,58,23,23,23,23,4,60,0,0,0,0,0
0,58,48,10,0,0,0,10,56,57,0,0,0,0
0,58,44,10,0,0,0,10,56,57,0,0,0,0
58,50,44,10,10,10,10,10,56,56,57,51,57,0
0,50,4,4,4,4,4,4,4,58,51,56,51,0
0,50,44,10,10,10,10,10,10,10,10,45,57,59
0,50,44,0,0,0,0,0,0,0,0,50,54,0
58,54,44,0,0,0,0,0,0,0,0,50,0,0
0,58,44,10,10,10,10,10,10,10,10,50,52,0
0,59,58,26,26,26,51,26,26,26,26,60,57,0
0,0,58,49,49,49,49,54,54,54,54,57,57,0
0,0,0,0,0,0,54,59,0,0,0,0,0,0
endlayer

layer
0,0,0,0,0,0,0,0,0,0,0,0,0,0
0,0,0,0,0,59,59,0,0,0,0,0,0,0
0,0,0,59,58,57,59,59,0,0,0,0,0,0
0,0,0,58,58,61,56,59,0,0,0,0,0,0
0,0,59,58,58,61,56,57,59,0,0,0,0,0
0,0,59,58,52,61,56,57,57,0,0,0,0,0
0,0,59,58,51,61,56,51,52,52,52,57,0,0
0,0,59,59,58,61,56,51,51,51,51,59,0,0
0,0,58,50,50,61,57,57,51,51,57,57,0,0
0,0,58,61,61,61,61,61,61,61,61,52,0,0
0,0,59,54,50,61,59,49,54,54,54,57,0,0
0,0,0,59,59,54,43,59,59,59,54,0,0,0
0,0,0,0,0,0,0,0,0,0,0,0,0,0
0,0,0,0,0,0,0,0,0,0,0,0,0,0
endlayer

layer
0,0,0,0,0,0,0,0,0,0,0,0,0,0
0,0,0,0,0,0,0,0,0,0,0,0,0,0
0,0,0,0,0,0,0,0,0,0,0,0,0,0
0,0,0,0,0,0,0,0,0,0,0,0,0,0
0,0,0,0,0,0,0,0,0,0,0,0,0,0
0,0,0,0,0,0,0,0,0,0,0,0,0,0
0,0,0,0,0,0,0,0,0,0,0,0,0,0
0,0,0,0,0,0,0,0,0,0,0,0,0,0
0,0,0,0,0,0,0,0,0,0,0,0,0,0
0,0,0,0,0,0,0,0,0,0,0,0,0,0
0,0,0,0,0,0,0,0,0,0,0,0,0,0
0,0,0,0,0,0,43,0,0,0,0,0,0,0
0,0,0,0,0,0,0,0,0,0,0,0,0,0
0,0,0,0,0,0,0,0,0,0,0,0,0,0
endlayer

