
# Created by Ruins mod version 17.0 Ingame Parser
# authoring Player: ST753M

weight=1
embed_into_distance=7
acceptable_target_blocks=
unacceptable_target_blocks=flowing_water,water,flowing_lava,lava,ice,bedrock,netherrack,nether_brick,nether_brick_fence,soul_sand,quartz_ore,end_stone,obsidian,iron_bars,Natura:Cloud,slime_grass,slime_congealed,slime_dirt,clouds,natura:clouds
dimensions=14,15,15
allowable_overhang=2
max_leveling=2
leveling_buffer=0
preserve_water=0
preserve_lava=0

biomesToSpawnIn=roofed_forest,mutated_roofed_forest

rule1=0,100,minecraft:cobblestone-0
rule2=0,100,minecraft:log-1
rule3=0,100,minecraft:log-5
rule4=0,100,minecraft:log-9
rule5=0,100,minecraft:cobblestone_wall-0
rule6=0,100,minecraft:stone_stairs-2
rule7=0,100,minecraft:stone_stairs-0
rule8=0,100,minecraft:stone_stairs-3
rule9=0,100,minecraft:stone_stairs-1
rule10=0,100,ChestGenHook:chests/woodland_mansion:4-3
rule11=0,100,minecraft:stone_slab-3
rule12=0,100,MobSpawner:silverfish,MobSpawner:skeleton,MobSpawner:skeleton,MobSpawner:zombie,MobSpawner:zombie,MobSpawner:zombie_villager,MobSpawner:witch,minecraft:log-1
rule13=0,100,minecraft:ladder-4
rule14=0,100,minecraft:stone_slab-11
rule15=0,100,minecraft:stone_stairs-4
rule16=0,100,minecraft:stone_stairs-6
rule17=0,100,minecraft:stone_stairs-7
rule18=0,100,minecraft:stone_stairs-5
rule19=0,100,minecraft:planks-5
rule20=0,100,minecraft:dark_oak_stairs-2
rule21=0,100,minecraft:dark_oak_stairs-3
rule22=0,100,minecraft:dark_oak_stairs-0
rule23=0,100,minecraft:wooden_slab-5
rule24=0,100,minecraft:dark_oak_stairs-1
rule25=0,100,minecraft:wooden_slab-13

layer
1,1,1,1,1,1,1,1,1,1,1,1,1,1,1
1,1,1,1,1,1,1,1,1,1,1,1,1,1,1
1,1,1,1,1,1,1,1,1,1,1,1,1,1,1
1,1,1,1,1,1,1,1,1,1,1,1,1,1,1
1,1,1,1,1,1,1,1,1,1,1,1,1,1,1
1,1,1,1,1,1,1,1,1,1,1,1,1,1,1
1,1,1,1,1,1,1,1,1,1,1,1,1,1,1
1,1,1,1,1,1,1,1,1,1,1,1,1,1,1
1,1,1,1,1,1,1,1,1,1,1,1,1,1,1
1,1,1,1,1,1,1,1,1,1,1,1,1,1,1
1,1,1,1,1,1,1,1,1,1,1,1,1,1,1
1,1,1,1,1,1,1,1,1,1,1,1,1,1,1
1,1,1,1,1,1,1,1,1,1,1,1,1,1,1
1,1,1,1,1,1,1,1,1,1,1,1,1,1,1
1,1,1,1,1,1,1,1,1,1,1,1,1,1,1
endlayer

layer
1,1,1,1,1,1,1,1,1,1,1,1,1,1,1
1,1,1,1,1,1,1,1,1,1,1,1,1,1,1
1,1,1,1,1,2,1,1,1,2,1,1,1,1,1
1,1,1,1,3,0,0,0,0,0,3,1,1,1,1
1,1,1,4,2,0,0,5,0,0,2,4,1,1,1
1,1,2,0,0,5,0,0,0,5,0,0,2,1,1
1,1,1,0,0,0,8,7,6,0,0,0,1,1,1
1,1,1,0,5,0,8,2,6,0,5,0,1,1,1
1,1,1,0,0,0,8,9,9,0,0,0,1,1,1
1,1,2,0,0,5,0,0,0,5,0,0,2,1,1
1,1,1,4,2,0,0,5,0,0,2,4,1,1,1
1,1,1,1,3,0,0,0,0,0,3,1,1,1,1
1,1,1,1,1,2,1,1,1,2,1,1,1,1,1
1,1,1,1,1,1,1,1,1,1,1,1,1,1,1
1,1,1,1,1,1,1,1,1,1,1,1,1,1,1
endlayer

layer
1,1,1,1,1,1,1,1,1,1,1,1,1,1,1
1,1,1,1,1,1,1,1,1,1,1,1,1,1,1
1,1,1,1,1,2,1,1,1,2,1,1,1,1,1
1,1,1,0,0,0,0,0,0,0,0,10,1,1,1
1,1,1,0,2,0,0,0,0,0,2,0,1,1,1
1,1,2,0,0,0,0,0,0,0,0,0,2,1,1
1,1,1,0,0,0,11,7,11,0,0,0,1,1,1
1,1,1,0,0,0,8,12,6,0,0,0,1,1,1
1,1,1,0,0,0,11,9,11,0,0,0,1,1,1
1,1,2,0,0,0,0,0,0,0,0,0,2,1,1
1,1,1,0,2,0,0,0,0,0,2,0,1,1,1
1,1,1,13,0,0,0,0,0,0,0,0,1,1,1
1,1,1,1,1,2,1,1,1,2,1,1,1,1,1
1,1,1,1,1,1,1,1,1,1,1,1,1,1,1
1,1,1,1,1,1,1,1,1,1,1,1,1,1,1
endlayer

layer
1,1,1,1,1,1,1,1,1,1,1,1,1,1,1
1,1,1,1,1,1,1,1,1,1,1,1,1,1,1
1,1,1,1,1,2,1,1,1,2,1,1,1,1,1
1,1,1,0,0,0,0,0,0,0,0,0,1,1,1
1,1,1,0,2,0,0,0,0,0,2,0,1,1,1
1,1,2,0,0,0,0,0,0,0,0,0,2,1,1
1,1,1,0,0,0,0,0,0,0,0,0,1,1,1
1,1,1,0,0,0,0,1,0,0,0,0,1,1,1
1,1,1,0,0,0,0,0,0,0,0,0,1,1,1
1,1,2,0,0,0,0,0,0,0,0,0,2,1,1
1,1,1,0,2,0,0,0,0,0,2,0,1,1,1
1,1,1,13,0,0,0,0,0,0,0,0,1,1,1
1,1,1,1,1,2,1,1,1,2,1,1,1,1,1
1,1,1,1,1,1,1,1,1,1,1,1,1,1,1
1,1,1,1,1,1,1,1,1,1,1,1,1,1,1
endlayer

layer
1,1,1,1,1,1,1,1,1,1,1,1,1,1,1
1,1,1,1,1,1,1,1,1,1,1,1,1,1,1
1,1,1,1,1,2,1,1,1,2,1,1,1,1,1
1,1,1,0,0,0,0,0,0,0,0,0,1,1,1
1,1,1,0,2,0,0,0,0,0,2,0,1,1,1
1,1,2,0,0,0,0,0,0,0,0,0,2,1,1
1,1,1,0,0,0,14,15,14,0,0,0,1,1,1
1,1,1,0,0,0,17,2,16,0,0,0,1,1,1
1,1,1,0,0,0,14,18,14,0,0,0,1,1,1
1,1,2,0,0,0,0,0,0,0,0,0,2,1,1
1,1,1,0,2,0,0,0,0,0,2,0,1,1,1
1,1,1,13,0,0,0,0,0,0,0,0,1,1,1
1,1,1,1,1,2,1,1,1,2,1,1,1,1,1
1,1,1,1,1,1,1,1,1,1,1,1,1,1,1
1,1,1,1,1,1,1,1,1,1,1,1,1,1,1
endlayer

layer
1,1,1,1,1,1,1,1,1,1,1,1,1,1,1
1,1,1,1,1,1,1,1,1,1,1,1,1,1,1
1,1,1,1,1,2,1,1,1,2,1,1,1,1,1
1,1,1,0,3,0,14,18,14,0,3,0,1,1,1
1,1,1,4,2,0,0,14,0,0,2,4,1,1,1
1,1,2,0,0,0,0,14,0,0,0,0,2,1,1
1,1,1,14,0,0,15,15,16,0,0,14,1,1,1
1,1,1,16,14,14,17,2,16,14,14,17,1,1,1
1,1,1,14,0,0,17,18,16,0,0,14,1,1,1
1,1,2,0,0,0,0,14,0,0,0,0,2,1,1
1,1,1,4,2,0,0,14,0,0,2,4,1,1,1
1,1,1,13,3,0,14,15,14,0,3,0,1,1,1
1,1,1,1,1,2,1,1,1,2,1,1,1,1,1
1,1,1,1,1,1,1,1,1,1,1,1,1,1,1
1,1,1,1,1,1,1,1,1,1,1,1,1,1,1
endlayer

layer
1,1,1,1,1,1,1,1,1,1,1,1,1,1,1
1,1,1,1,1,1,1,1,1,1,1,1,1,1,1
1,1,1,1,1,1,1,1,1,1,1,1,1,1,1
1,1,1,19,19,19,19,19,19,19,19,19,1,1,1
1,1,1,19,3,4,3,4,3,4,3,19,1,1,1
1,1,1,19,4,3,4,3,4,3,4,19,1,1,1
1,1,1,19,3,4,3,4,3,4,3,19,1,1,1
1,1,1,19,4,3,4,3,4,3,4,19,1,1,1
1,1,1,19,3,4,3,4,3,4,3,19,1,1,1
1,1,1,19,4,3,4,3,4,3,4,19,1,1,1
1,1,1,19,3,4,3,4,3,4,3,19,1,1,1
1,1,1,13,19,19,19,19,19,19,19,19,1,1,1
1,1,1,1,1,1,1,1,1,1,1,1,1,1,1
1,1,1,1,1,1,1,1,1,1,1,1,1,1,1
1,1,1,1,1,1,9,9,9,1,1,1,1,1,1
endlayer

layer
5,1,7,1,0,7,0,7,0,7,0,1,7,1,5
1,1,1,1,1,1,1,1,1,1,1,1,1,1,1
8,1,1,1,1,1,1,1,1,1,1,1,1,1,6
1,1,1,0,0,0,0,0,0,0,0,0,1,1,1
0,1,1,0,0,0,0,0,0,0,0,0,1,1,0
8,1,1,11,0,0,0,0,0,0,0,0,1,1,6
0,1,1,7,0,0,7,6,0,2,0,0,1,1,0
8,1,1,1,0,11,1,0,0,0,0,0,1,1,6
0,1,1,1,6,0,0,0,0,0,0,0,1,1,0
8,1,1,1,6,7,1,6,0,0,0,0,1,1,6
0,1,1,1,8,7,1,1,6,0,0,0,1,1,0
1,1,1,13,1,9,1,1,0,0,0,0,1,1,1
8,1,1,1,1,3,20,0,0,3,1,1,1,1,6
1,1,1,1,1,0,0,0,0,0,1,1,1,1,1
5,1,9,1,0,0,0,0,0,0,0,1,9,1,5
endlayer

layer
0,0,0,0,0,0,0,0,0,0,0,0,0,0,0
0,1,1,1,0,0,0,0,0,0,0,7,1,1,0
0,1,2,1,19,19,22,21,19,19,19,1,2,1,0
0,1,1,0,0,0,0,0,0,0,0,0,1,1,0
0,0,19,0,0,0,0,0,0,0,0,0,19,0,0
0,0,20,0,0,0,0,0,23,23,23,0,19,0,0
0,0,24,0,0,0,0,0,23,2,23,0,20,0,0
0,0,23,0,0,0,0,0,23,23,23,0,21,0,0
0,0,19,7,0,0,0,0,0,0,0,0,22,0,0
0,0,19,11,0,0,0,0,0,0,0,0,19,0,0
0,0,19,0,0,0,1,11,0,0,0,0,19,0,0
0,1,1,13,1,0,0,0,0,0,0,0,1,1,0
0,1,2,1,19,19,0,0,0,3,19,1,2,1,0
0,1,1,1,0,0,0,0,0,0,0,1,1,1,0
0,0,0,0,0,0,0,0,0,0,0,0,0,0,0
endlayer

layer
0,0,0,0,0,0,0,0,0,0,0,0,0,0,0
0,0,5,0,0,0,0,0,0,0,0,0,5,0,0
0,5,2,1,19,3,0,0,0,3,19,1,2,5,0
0,0,1,0,0,0,0,0,0,0,0,0,1,0,0
0,0,19,0,0,0,0,0,0,0,0,0,19,0,0
0,0,23,0,0,0,0,0,0,0,0,0,4,0,0
0,0,0,0,0,0,0,0,0,0,0,0,0,0,0
0,0,0,0,0,0,0,0,0,0,0,0,0,0,0
0,0,0,0,0,0,0,0,0,0,0,0,0,0,0
0,0,0,0,0,0,0,0,0,0,0,0,4,0,0
0,0,22,0,0,0,0,0,0,0,0,0,19,0,0
0,0,1,13,0,0,0,0,0,0,0,0,1,0,0
0,5,2,1,19,3,0,0,0,3,19,1,2,5,0
0,0,5,0,0,0,0,0,0,0,0,0,5,0,0
0,0,0,0,0,0,0,0,0,0,0,0,0,0,0
endlayer

layer
0,0,0,0,0,0,0,0,0,0,0,0,0,0,0
0,0,5,0,0,0,0,0,0,0,0,0,5,0,0
0,5,2,1,19,3,0,0,0,0,19,1,2,5,0
0,0,1,0,0,0,0,0,0,0,0,0,1,0,0
0,0,23,0,0,0,0,0,0,0,0,0,19,0,0
0,0,0,0,0,0,0,0,0,0,0,0,4,0,0
0,0,0,0,0,0,0,0,0,0,0,0,0,0,0
0,0,0,0,0,0,0,0,0,0,0,0,0,0,0
0,0,0,0,0,0,0,0,0,0,0,0,0,0,0
0,0,0,0,0,0,0,0,0,0,0,0,4,0,0
0,0,21,25,0,0,0,0,0,0,0,0,19,0,0
0,0,1,25,25,0,0,0,0,0,0,0,1,0,0
0,5,2,1,19,3,0,0,0,23,19,1,2,5,0
0,0,5,0,0,0,0,0,0,0,0,0,5,0,0
0,0,0,0,0,0,0,0,0,0,0,0,0,0,0
endlayer

layer
0,0,0,0,0,0,0,0,0,0,0,0,0,0,0
0,0,5,0,0,0,0,0,0,0,0,0,0,0,0
0,5,0,1,0,0,0,0,0,0,22,1,2,5,0
0,0,6,0,0,0,0,0,0,0,0,0,1,0,0
0,0,0,0,0,0,0,0,0,0,0,0,21,0,0
0,0,0,0,0,0,0,0,0,0,0,0,4,0,0
0,0,0,0,0,0,0,0,0,0,0,0,0,0,0
0,0,0,0,0,0,0,0,0,0,0,0,0,0,0
0,0,0,0,0,0,0,0,0,0,0,0,0,0,0
0,0,0,0,0,0,0,0,0,0,0,0,0,0,0
0,0,0,0,0,0,0,0,0,0,0,0,19,0,0
0,0,1,22,0,0,0,0,0,0,0,0,1,0,0
0,5,2,1,23,0,0,0,0,0,21,1,2,5,0
0,0,0,0,0,0,0,0,0,0,0,0,5,0,0
0,0,0,0,0,0,0,0,0,0,0,0,0,0,0
endlayer

layer
0,0,0,0,0,0,0,0,0,0,0,0,0,0,0
0,0,5,0,0,0,0,0,0,0,0,0,0,0,0
0,5,0,1,0,0,0,0,0,0,0,1,2,5,0
0,0,0,0,0,0,0,0,0,0,0,0,1,0,0
0,0,0,0,0,0,0,0,0,0,0,0,0,0,0
0,0,0,0,0,0,0,0,0,0,0,0,0,0,0
0,0,0,0,0,0,0,0,0,0,0,0,0,0,0
0,0,0,0,0,0,0,0,0,0,0,0,0,0,0
0,0,0,0,0,0,0,0,0,0,0,0,0,0,0
0,0,0,0,0,0,0,0,0,0,0,0,0,0,0
0,0,0,0,0,0,0,0,0,0,0,0,21,0,0
0,0,1,0,0,0,0,0,0,0,0,0,1,0,0
0,0,2,1,0,0,0,0,0,0,0,1,0,5,0
0,0,0,0,0,0,0,0,0,0,0,0,5,0,0
0,0,0,0,0,0,0,0,0,0,0,0,0,0,0
endlayer

layer
0,0,0,0,0,0,0,0,0,0,0,0,0,0,0
0,0,5,0,0,0,0,0,0,0,0,0,0,0,0
0,0,0,0,0,0,0,0,0,0,0,7,0,5,0
0,0,0,0,0,0,0,0,0,0,0,0,0,0,0
0,0,0,0,0,0,0,0,0,0,0,0,0,0,0
0,0,0,0,0,0,0,0,0,0,0,0,0,0,0
0,0,0,0,0,0,0,0,0,0,0,0,0,0,0
0,0,0,0,0,0,0,0,0,0,0,0,0,0,0
0,0,0,0,0,0,0,0,0,0,0,0,0,0,0
0,0,0,0,0,0,0,0,0,0,0,0,0,0,0
0,0,0,0,0,0,0,0,0,0,0,0,0,0,0
0,0,11,0,0,0,0,0,0,0,0,0,1,0,0
0,0,0,1,0,0,0,0,0,0,0,7,0,5,0
0,0,0,0,0,0,0,0,0,0,0,0,0,0,0
0,0,0,0,0,0,0,0,0,0,0,0,0,0,0
endlayer

