
# Created by Ruins mod version 17.0 Ingame Parser
# authoring Player: ST753M

weight=1
embed_into_distance=10
uniqueMinDistance=1000
spawnMinDistance=1000
acceptable_target_blocks=
unacceptable_target_blocks=flowing_water,water,flowing_lava,lava,ice,bedrock,netherrack,nether_brick,nether_brick_fence,soul_sand,quartz_ore,end_stone,obsidian,iron_bars,Natura:Cloud,slime_grass,slime_congealed,slime_dirt,clouds,natura:clouds
dimensions=32,25,25
allowable_overhang=10
max_leveling=7
leveling_buffer=0
preserve_water=0
preserve_lava=0

biomesToSpawnIn=roofed_forest,mutated_roofed_forest,ominous_woods,darklands_forest

=0,100,air
rule1=0,100,minecraft:cobblestone-0
rule2=0,100,minecraft:water-0
rule3=0,100,minecraft:carpet-7
rule4=0,100,minecraft:cobblestone_wall-0
rule5=0,100,minecraft:stone_stairs-0
rule6=0,100,ChestGenHook:chests/woodland_mansion:5-4
rule7=0,100,Skull:0:10-1
rule8=0,100,Skull:0:0-1
rule9=0,100,MobSpawner:vex,MobSpawner:witch,MobSpawner:cave_spider,MobSpawner:silverfish,MobSpawner:silverfish,MobSpawner:skeleton,MobSpawner:zombie,MobSpawner:zombie,MobSpawner:zombie_villager,MobSpawner:spider
rule10=0,100,Skull:1:7-1
rule11=0,100,Skull:0:11-1
rule12=0,100,minecraft:stone_stairs-5
rule13=0,100,minecraft:stone_slab-11
rule14=0,100,minecraft:stone_stairs-4
rule15=0,100,minecraft:stone_stairs-7
rule16=0,100,minecraft:stone_stairs-6
rule17=0,100,preserveBlock
rule18=0,100,minecraft:stone_stairs-2
rule19=0,100,minecraft:stone_stairs-3
rule20=0,100,minecraft:stone_stairs-1
rule21=1,100,minecraft:redstone_torch-5
rule22=0,100,minecraft:log-1
rule23=0,100,minecraft:planks-5
rule24=0,100,minecraft:log-5
rule25=0,100,minecraft:spruce_stairs-1
rule26=0,100,minecraft:spruce_fence-0
rule27=0,100,minecraft:spruce_stairs-0
rule28=0,100,minecraft:carpet-0
rule29=0,100,minecraft:carpet-14
rule30=0,100,minecraft:dark_oak_stairs-0
rule31=0,100,minecraft:dark_oak_stairs-5
rule32=0,100,minecraft:spruce_stairs-3
rule33=0,100,minecraft:spruce_stairs-2
rule34=0,100,minecraft:dark_oak_door-3
rule35=0,100,minecraft:anvil-8
rule36=0,100,minecraft:cauldron-0
rule37=0,100,minecraft:lit_redstone_lamp-0
rule38=0,100,minecraft:glass_pane-0
rule39=0,100,minecraft:carpet-12
rule40=0,100,minecraft:log-9
rule41=0,100,minecraft:water-9
rule42=0,100,minecraft:furnace-2
rule43=0,100,minecraft:dark_oak_door-8
rule44=0,100,minecraft:dark_oak_door-9
rule45=0,100,minecraft:water-1
rule46=0,100,minecraft:dark_oak_fence-0
rule47=0,100,minecraft:dark_oak_stairs-4
rule48=0,100,minecraft:dark_oak_stairs-7
rule49=0,100,minecraft:dark_oak_stairs-6
rule50=2,100,minecraft:redstone_torch-2
rule51=0,100,minecraft:dark_oak_stairs-2
rule52=2,100,minecraft:redstone_torch-1
rule53=0,100,minecraft:spruce_stairs-6
rule54=0,100,minecraft:spruce_stairs-5
rule55=0,100,minecraft:spruce_stairs-7
rule56=2,100,WallSign:null:null:null:null-4
rule57=0,100,minecraft:bed-9
rule58=0,100,minecraft:bookshelf-0
rule59=0,100,minecraft:bed-1
rule60=0,100,minecraft:bed-0
rule61=0,100,minecraft:bed-8
rule62=2,100,WallSign:null:null:null:null-5
rule63=0,100,minecraft:dark_oak_door-2
rule64=0,100,minecraft:spruce_stairs-4
rule65=0,100,minecraft:dark_oak_stairs-3

rule66=0,80,CommandBlock:RUINSTRIGGER /summon illusion_illager ~ ~1 ~ {PersistenceRequired:1}:@-1,CommandBlock:RUINSTRIGGER /summon illusion_illager ~ ~1 ~ {PersistenceRequired:1}:@-1,CommandBlock:RUINSTRIGGER /summon evocation ~ ~1 ~ {PersistenceRequired:1}:@-1,CommandBlock:RUINSTRIGGER /summon vindication_illager ~ ~1 ~ {PersistenceRequired:1}:@-1,CommandBlock:RUINSTRIGGER /summon vindication_illager ~ ~1 ~ {PersistenceRequired:1}:@-1,CommandBlock:RUINSTRIGGER /summon vindication_illager ~ ~1 ~ {PersistenceRequired:1}:@-1,CommandBlock:RUINSTRIGGER /summon vindication_illager ~ ~1 ~ {PersistenceRequired:1}:@-1,CommandBlock:RUINSTRIGGER /summon vindication_illager ~ ~1 ~ {PersistenceRequired:1}:@-1

rule67=0,100,minecraft:dark_oak_door-1
rule68=2,100,WallSign:null:null:null:null-2
rule69=2,100,WallSign:null:null:null:null-3
rule70=0,100,minecraft:dark_oak_door-0
rule71=0,100,minecraft:wooden_slab-5
rule72=0,100,minecraft:wooden_slab-13
rule73=2,100,minecraft:redstone_torch-4
rule74=0,100,minecraft:web-0
rule75=0,100,cobblestone
rule76=0,100,minecraft:dark_oak_stairs-1

layer
1,1,1,1,1,1,1,1,1,1,1,1,1,1,1,1,1,1,1,1,1,1,1,1,1
1,1,1,1,1,1,1,1,1,1,1,1,1,1,1,1,1,1,1,1,1,1,1,1,1
1,1,1,1,1,1,1,1,1,1,1,1,1,1,1,1,1,1,1,1,1,1,1,1,1
1,1,1,1,1,1,1,1,1,1,1,1,1,1,1,1,1,1,1,1,1,1,1,1,1
1,1,1,1,1,1,1,1,1,1,1,1,1,1,1,1,1,1,1,1,1,1,1,1,1
1,1,1,1,1,1,1,1,1,1,1,1,1,1,1,1,1,1,1,1,1,1,1,1,1
1,1,1,1,1,1,1,1,1,1,1,1,1,1,1,1,1,1,1,1,1,1,1,1,1
1,1,1,1,1,1,1,1,1,1,1,1,1,1,1,1,1,1,1,1,1,1,1,1,1
1,1,1,1,1,1,1,1,1,1,1,1,1,1,1,1,1,1,1,1,1,1,1,1,1
1,1,1,1,1,1,1,1,1,1,1,1,1,1,1,1,1,1,1,1,1,1,1,1,1
1,1,1,1,1,1,1,1,1,1,1,1,1,1,1,1,1,1,1,1,1,1,1,1,1
1,1,1,1,1,1,1,1,1,1,1,1,1,1,1,1,1,1,1,1,1,1,1,1,1
1,1,1,1,1,1,1,1,1,1,1,1,1,1,1,1,1,1,1,1,1,1,1,1,1
1,1,1,1,1,1,1,1,1,1,1,1,1,1,1,1,1,1,1,1,1,1,1,1,1
1,1,1,1,1,1,1,1,1,1,1,1,1,1,1,1,1,1,1,1,1,1,1,1,1
1,1,1,1,1,1,1,1,1,1,1,1,1,1,1,1,1,1,1,1,1,1,1,1,1
1,1,1,1,1,1,1,1,1,1,1,1,1,1,1,1,1,1,1,1,1,1,1,1,1
1,1,1,1,1,1,1,1,1,1,1,1,1,1,1,1,1,1,1,1,1,1,1,1,1
1,1,1,1,1,1,1,1,1,1,1,1,1,1,1,1,1,1,1,1,1,1,1,1,1
1,1,1,1,1,1,1,1,1,1,1,1,1,1,1,1,1,1,1,1,1,1,1,1,1
1,1,1,1,1,1,1,1,1,1,1,1,1,1,1,1,1,1,1,1,1,1,1,1,1
1,1,1,1,1,1,1,1,1,1,1,1,1,1,1,1,1,1,1,1,1,1,1,1,1
1,1,1,1,1,1,1,1,1,1,1,1,1,1,1,1,1,1,1,1,1,1,1,1,1
1,1,1,1,1,1,1,1,1,1,1,1,1,1,1,1,1,1,1,1,1,1,1,1,1
1,1,1,1,1,1,1,1,1,1,1,1,1,1,1,1,1,1,1,1,1,1,1,1,1
endlayer

layer
1,1,1,1,1,1,1,1,1,1,1,1,1,1,1,1,1,1,1,1,1,1,1,1,1
1,1,1,1,1,1,1,1,1,1,1,1,1,1,1,1,1,1,1,1,1,1,1,1,1
1,1,1,1,1,1,1,1,1,1,1,1,1,1,1,1,1,1,1,1,1,1,1,1,1
1,1,1,1,1,1,1,2,2,2,1,1,1,1,1,1,1,1,2,2,2,1,1,1,1
1,1,1,1,1,1,1,2,2,2,1,1,1,1,1,1,1,1,2,2,2,1,1,1,1
1,1,1,1,1,1,1,2,2,2,1,1,1,1,1,1,1,1,2,2,2,1,1,1,1
1,1,1,1,1,1,1,2,2,2,1,1,1,1,1,1,1,1,2,2,2,1,1,1,1
1,1,1,1,1,1,1,2,2,2,1,1,1,1,1,1,1,1,2,2,2,1,1,1,1
1,1,1,1,1,1,1,2,2,2,1,1,1,1,1,1,1,1,2,2,2,1,1,1,1
1,1,1,1,1,1,1,2,2,2,1,1,1,1,1,1,1,1,2,2,2,1,1,1,1
1,1,1,1,1,1,1,2,2,2,1,1,1,1,1,1,1,1,2,2,2,1,1,1,1
1,1,1,1,1,1,1,2,2,2,1,1,1,1,1,1,1,1,2,2,2,1,1,1,1
1,1,1,1,1,1,1,2,2,2,1,1,1,1,1,1,1,1,2,2,2,1,1,1,1
1,1,1,1,1,1,1,2,2,2,1,1,1,1,1,1,1,1,2,2,2,1,1,1,1
1,1,1,1,1,1,1,2,2,2,1,1,1,1,1,1,1,1,2,2,2,1,1,1,1
1,1,1,1,1,1,1,2,2,2,1,1,1,1,1,1,1,1,2,2,2,1,1,1,1
1,1,1,1,1,1,1,2,2,2,1,1,1,1,1,1,1,1,2,2,2,1,1,1,1
1,1,1,1,1,1,1,2,2,2,1,1,1,1,1,1,1,1,2,2,2,1,1,1,1
1,1,1,1,1,1,1,2,2,2,1,1,1,1,1,1,1,1,2,2,2,1,1,1,1
1,1,1,1,1,1,1,2,2,2,1,1,1,1,1,1,1,1,2,2,2,1,1,1,1
1,1,1,1,1,1,1,2,2,2,1,1,1,1,1,1,1,1,2,2,2,1,1,1,1
1,1,1,1,1,1,1,2,2,2,1,1,1,1,1,1,1,1,2,2,2,1,1,1,1
1,1,1,1,1,1,1,1,1,1,1,1,1,1,1,1,1,1,1,1,1,1,1,1,1
1,1,1,1,1,1,1,1,1,1,1,1,1,1,1,1,1,1,1,1,1,1,1,1,1
1,1,1,1,1,1,1,1,1,1,1,1,1,1,1,1,1,1,1,1,1,1,1,1,1
endlayer

layer
1,1,1,1,1,1,1,1,1,1,1,1,1,1,1,1,1,1,1,1,1,1,1,1,1
1,1,1,1,1,1,1,1,1,1,1,1,1,1,1,1,1,1,1,1,1,1,1,1,1
1,1,1,1,1,1,3,3,3,3,3,4,1,1,1,1,4,3,3,3,3,3,1,1,1
1,1,1,1,1,1,3,0,0,0,3,0,0,0,0,0,0,3,0,0,0,3,1,1,1
1,1,1,1,1,1,3,0,0,0,3,0,0,0,0,0,0,3,0,0,0,3,1,1,1
1,1,1,1,1,1,3,0,0,0,3,4,1,5,5,1,4,3,0,0,0,3,1,1,1
1,1,1,1,1,1,3,0,0,0,3,1,1,1,1,1,1,3,0,0,0,3,1,1,1
1,1,1,1,1,1,3,0,0,0,3,1,1,1,1,1,1,3,0,0,0,3,1,1,1
1,1,1,1,1,1,3,0,0,0,3,1,1,1,1,1,1,3,0,0,0,3,1,1,1
1,1,1,1,1,1,3,0,0,0,3,1,1,1,1,1,1,3,0,0,0,3,1,1,1
1,1,1,1,1,1,3,0,0,0,3,1,1,1,1,1,1,3,0,0,0,3,1,1,1
1,1,1,1,1,1,3,0,0,0,3,1,1,1,1,1,1,3,0,0,0,3,1,1,1
1,1,1,1,1,1,3,0,0,0,3,1,1,1,1,1,1,3,0,0,0,3,1,1,1
1,1,1,1,1,1,3,0,0,0,3,1,1,1,1,1,1,3,0,0,0,3,1,1,1
1,1,1,1,1,1,3,0,0,0,3,1,1,1,1,1,1,3,0,0,0,3,1,1,1
1,1,1,1,1,1,3,0,0,0,3,1,1,1,1,1,1,3,0,0,0,3,1,1,1
1,1,1,1,1,1,3,0,0,0,3,1,1,1,1,1,1,3,0,0,0,3,1,1,1
1,1,1,1,1,1,3,0,0,0,3,1,1,1,1,1,1,3,0,0,0,3,1,1,1
1,1,1,1,1,1,3,0,0,0,3,1,1,1,1,1,1,3,0,0,0,3,1,1,1
1,1,1,1,1,1,3,0,0,0,3,1,1,1,1,1,1,3,0,0,0,3,1,1,1
1,1,1,1,1,1,3,0,0,0,3,1,1,1,1,1,1,3,0,0,0,3,1,1,1
1,1,1,1,1,1,3,0,0,0,3,1,1,1,1,1,1,3,0,0,0,3,1,1,1
1,1,1,1,1,1,3,3,6,3,3,1,1,1,1,1,1,3,3,6,3,3,1,1,1
1,1,1,1,1,1,1,1,1,1,1,1,1,1,1,1,1,1,1,1,1,1,1,1,1
1,1,1,1,1,1,1,1,1,1,1,1,1,1,1,1,1,1,1,1,1,1,1,1,1
endlayer

layer
1,1,1,1,1,1,1,1,1,1,1,1,1,1,1,1,1,1,1,1,1,1,1,1,1
1,1,1,1,1,1,1,1,1,1,1,1,1,1,1,1,1,1,1,1,1,1,1,1,1
1,1,1,1,1,1,0,0,0,0,0,4,1,1,1,1,4,0,0,0,0,0,1,1,1
1,1,1,1,1,0,0,0,0,0,0,0,0,0,0,0,0,0,0,0,0,0,0,1,1
1,1,1,1,1,0,0,0,0,0,0,0,0,0,0,0,0,0,0,0,0,0,0,1,1
1,1,1,1,1,0,0,0,0,0,0,4,1,0,0,1,4,0,0,0,0,0,7,1,1
1,1,1,1,1,1,0,0,0,0,0,1,1,5,5,1,1,0,0,0,0,0,1,1,1
1,1,1,1,1,0,0,0,0,0,0,0,1,1,1,1,8,0,0,0,0,0,0,1,1
1,1,1,1,1,0,0,0,0,0,0,0,9,1,1,1,0,0,0,0,0,0,0,1,1
1,1,1,1,1,0,0,0,0,0,0,0,1,1,1,1,0,0,0,0,0,0,0,1,1
1,1,1,1,1,1,0,0,0,0,0,1,1,1,1,1,1,0,0,0,0,0,1,1,1
1,1,1,1,1,0,0,0,0,0,0,0,1,1,1,1,0,0,0,0,0,0,0,1,1
1,1,1,1,1,0,0,0,0,0,0,0,1,1,1,1,0,0,0,0,0,0,0,1,1
1,1,1,1,1,8,0,0,0,0,0,0,1,1,1,1,0,0,0,0,0,0,0,1,1
1,1,1,1,1,1,0,0,0,0,0,1,1,1,1,1,1,0,0,0,0,0,1,1,1
1,1,1,1,1,0,0,0,0,0,0,0,1,1,1,1,0,0,0,0,0,0,10,1,1
1,1,1,1,1,0,0,0,0,0,0,0,1,1,1,9,0,0,0,0,0,0,0,1,1
1,1,1,1,1,0,0,0,0,0,0,0,1,1,1,1,0,0,0,0,0,0,0,1,1
1,1,1,1,1,1,0,0,0,0,0,1,1,1,1,1,1,0,0,0,0,0,1,1,1
1,1,1,1,1,0,0,0,0,0,0,0,1,1,1,1,0,0,0,0,0,0,0,1,1
1,1,1,1,9,0,0,0,0,0,0,11,1,1,1,1,8,0,0,0,0,0,0,1,1
1,1,1,1,1,0,0,0,0,0,0,0,1,1,1,1,0,0,0,0,0,0,0,1,1
1,1,1,1,1,1,0,0,0,0,0,1,1,1,1,1,1,0,0,0,0,0,1,1,1
1,1,1,1,1,1,1,1,5,1,1,1,1,1,1,1,1,1,1,5,1,1,1,1,1
1,1,1,1,1,1,1,1,1,1,1,1,1,1,1,1,1,1,1,1,1,1,1,1,1
endlayer

layer
1,1,1,1,1,1,1,1,1,1,1,1,1,1,1,1,1,1,1,1,1,1,1,1,1
1,1,1,1,1,1,1,1,1,1,1,1,1,1,1,1,1,1,1,1,1,1,1,1,1
1,1,1,1,1,1,0,0,0,0,0,4,1,1,1,1,4,0,0,0,0,0,1,1,1
1,1,1,1,1,12,0,0,0,0,0,0,0,0,0,0,0,0,0,0,0,0,12,1,1
1,1,1,1,1,13,0,0,0,0,0,0,0,0,0,0,0,0,0,0,0,0,13,1,1
1,1,1,1,1,14,0,0,0,0,0,4,1,0,0,1,4,0,0,0,0,0,14,1,1
1,1,1,1,1,1,0,0,0,0,0,1,1,0,0,1,1,0,0,0,0,0,1,1,1
1,1,1,1,1,12,0,0,0,0,0,12,1,5,5,1,12,0,0,0,0,0,12,1,1
1,1,1,1,1,13,0,0,0,0,0,13,1,1,1,1,13,0,0,0,0,0,13,1,1
1,1,1,1,1,14,0,0,0,0,0,14,1,1,1,1,14,0,0,0,0,0,14,1,1
1,1,1,1,1,1,0,0,0,0,0,1,1,1,1,1,1,0,0,0,0,0,1,1,1
1,1,1,1,1,12,0,0,0,0,0,12,1,1,1,1,12,0,0,0,0,0,12,1,1
1,1,1,1,1,13,0,0,0,0,0,13,1,1,1,1,13,0,0,0,0,0,13,1,1
1,1,1,1,1,14,0,0,0,0,0,14,1,1,1,1,14,0,0,0,0,0,14,1,1
1,1,1,1,1,1,0,0,0,0,0,1,1,1,1,1,1,0,0,0,0,0,1,1,1
1,1,1,1,1,12,0,0,0,0,0,12,1,1,1,1,12,0,0,0,0,0,12,1,1
1,1,1,1,1,13,0,0,0,0,0,13,1,1,1,1,13,0,0,0,0,0,13,1,1
1,1,1,1,1,14,0,0,0,0,0,14,1,1,1,1,14,0,0,0,0,0,14,1,1
1,1,1,1,1,1,0,0,0,0,0,1,1,1,1,1,1,0,0,0,0,0,1,1,1
1,1,1,1,1,12,0,0,0,0,0,12,1,1,1,1,12,0,0,0,0,0,12,1,1
1,1,1,1,1,13,0,0,0,0,0,13,1,1,1,1,13,0,0,0,0,0,13,1,1
1,1,1,1,1,14,0,0,0,0,0,14,1,1,1,1,14,0,0,0,0,0,14,1,1
1,1,1,1,1,1,0,0,0,0,0,1,1,1,1,1,1,0,0,0,0,0,1,1,1
1,1,1,1,1,1,1,5,1,5,1,1,1,1,1,1,1,1,5,1,5,1,1,1,1
1,1,1,1,1,1,1,1,1,1,1,1,1,1,1,1,1,1,1,1,1,1,1,1,1
endlayer

layer
1,1,1,1,1,1,1,1,1,1,1,1,1,1,1,1,1,1,1,1,1,1,1,1,1
1,1,1,1,1,1,1,1,1,1,1,1,1,1,1,1,1,1,1,1,1,1,1,1,1
1,1,1,1,1,1,0,0,0,0,0,1,1,1,1,1,1,0,0,0,0,0,1,1,1
1,1,1,1,1,1,0,0,0,0,0,1,0,0,0,0,1,0,0,0,0,0,1,1,1
1,1,1,1,1,1,0,0,0,0,0,1,0,0,0,0,1,0,0,0,0,0,1,1,1
1,1,1,1,1,1,0,0,0,0,0,1,1,0,0,1,1,0,0,0,0,0,1,1,1
1,1,1,1,1,1,0,0,0,0,0,1,1,0,0,1,1,0,0,0,0,0,1,1,1
1,1,1,1,1,1,0,0,0,0,0,1,1,0,0,1,1,0,0,0,0,0,1,1,1
1,1,1,1,1,1,0,0,0,0,0,1,1,5,5,1,1,0,0,0,0,0,1,1,1
1,1,1,1,1,1,0,0,0,0,0,1,1,1,1,1,1,0,0,0,0,0,1,1,1
1,1,1,1,1,1,0,0,0,0,0,1,1,1,1,1,1,0,0,0,0,0,1,1,1
1,1,1,1,1,1,0,0,0,0,0,1,1,1,1,1,1,0,0,0,0,0,1,1,1
1,1,1,1,1,1,0,0,0,0,0,1,1,1,1,1,1,0,0,0,0,0,1,1,1
1,1,1,1,1,1,0,0,0,0,0,1,1,1,1,1,1,0,0,0,0,0,1,1,1
1,1,1,1,1,1,0,0,0,0,0,1,1,1,1,1,1,0,0,0,0,0,1,1,1
1,1,1,1,1,1,0,0,0,0,0,1,1,1,1,1,1,0,0,0,0,0,1,1,1
1,1,1,1,1,1,0,0,0,0,0,1,1,1,1,1,1,0,0,0,0,0,1,1,1
1,1,1,1,1,1,0,0,0,0,0,1,1,1,1,1,1,0,0,0,0,0,1,1,1
1,1,1,1,1,1,0,0,0,0,0,1,1,1,1,1,1,0,0,0,0,0,1,1,1
1,1,1,1,1,1,0,0,0,0,0,1,1,1,1,1,1,0,0,0,0,0,1,1,1
1,1,1,1,1,1,0,0,0,0,0,1,1,1,1,1,1,0,0,0,0,0,1,1,1
1,1,1,1,1,1,0,0,0,0,0,1,1,1,1,1,1,0,0,0,0,0,1,1,1
1,1,1,1,1,1,0,0,0,0,0,1,1,1,1,1,1,0,0,0,0,0,1,1,1
1,1,1,1,1,1,1,1,5,1,1,1,1,1,1,1,1,1,1,5,1,1,1,1,1
1,1,1,1,1,1,1,1,1,1,1,1,1,1,1,1,1,1,1,1,1,1,1,1,1
endlayer

layer
1,1,1,1,1,1,1,1,1,1,1,1,1,1,1,1,1,1,1,1,1,1,1,1,1
1,1,1,1,1,1,1,1,1,1,1,1,1,1,1,1,1,1,1,1,1,1,1,1,1
1,1,1,1,1,1,16,0,0,0,15,1,1,1,1,1,1,16,0,0,0,15,1,1,1
1,1,1,1,1,1,16,0,0,0,15,1,1,1,1,1,1,16,0,0,0,15,1,1,1
1,1,1,1,1,1,16,0,0,0,15,1,1,1,1,1,1,16,0,0,0,15,1,1,1
1,1,1,1,1,1,16,0,0,0,15,1,1,12,12,1,1,16,0,0,0,15,1,1,1
1,1,1,1,1,1,16,0,0,0,15,1,1,0,0,1,1,16,0,0,0,15,1,1,1
1,1,1,1,1,1,16,0,0,0,15,1,1,0,0,1,1,16,0,0,0,15,1,1,1
1,1,1,1,1,1,16,0,0,0,15,1,1,0,0,1,1,16,0,0,0,15,1,1,1
1,1,1,1,1,1,16,0,0,0,15,1,1,5,5,1,1,16,0,0,0,15,1,1,1
1,1,1,1,1,1,16,0,0,0,15,1,1,1,1,1,1,16,0,0,0,15,1,1,1
1,1,1,1,1,1,16,0,0,0,15,1,1,1,1,1,1,16,0,0,0,15,1,1,1
1,1,1,1,1,1,16,0,0,0,15,1,1,1,1,1,1,16,0,0,0,15,1,1,1
1,1,1,1,1,1,16,0,0,0,15,1,1,1,1,1,1,16,0,0,0,15,1,1,1
1,1,1,1,1,1,16,0,0,0,15,1,1,1,1,1,1,16,0,0,0,15,1,1,1
1,1,1,1,1,1,16,0,0,0,15,1,1,1,1,1,1,16,0,0,0,15,1,1,1
1,1,1,1,1,1,16,0,0,0,15,1,1,1,1,1,1,16,0,0,0,15,1,1,1
1,1,1,1,1,1,16,0,0,0,15,1,1,1,1,1,1,16,0,0,0,15,1,1,1
1,1,1,1,1,1,16,0,0,0,15,1,1,1,1,1,1,16,0,0,0,15,1,1,1
1,1,1,1,1,1,16,0,0,0,15,1,1,1,1,1,1,16,0,0,0,15,1,1,1
1,1,1,1,1,1,16,0,0,0,15,1,1,1,1,1,1,16,0,0,0,15,1,1,1
1,1,1,1,1,1,16,0,0,0,15,1,1,1,1,1,1,16,0,0,0,15,1,1,1
1,1,1,1,1,1,16,0,0,0,15,1,1,1,1,1,1,16,0,0,0,15,1,1,1
1,1,1,1,1,1,1,1,1,1,1,1,1,1,1,1,1,1,1,1,1,1,1,1,1
1,1,1,1,1,1,1,1,1,1,1,1,1,1,1,1,1,1,1,1,1,1,1,1,1
endlayer

layer
1,1,1,1,1,1,1,1,1,1,1,1,1,1,1,1,1,1,1,1,1,1,1,1,1
1,1,1,1,1,1,1,1,1,1,1,1,1,1,1,1,1,1,1,1,1,1,1,1,1
1,1,1,1,1,1,1,16,13,15,1,1,1,1,1,1,1,1,16,13,15,1,1,1,1
1,1,1,1,1,1,1,16,13,15,1,1,1,1,1,1,1,1,16,13,15,1,1,1,1
1,1,1,1,1,1,1,16,13,15,1,1,1,1,1,1,1,1,16,13,15,1,1,1,1
1,1,1,1,1,1,1,16,13,15,1,1,1,1,1,1,1,1,16,13,15,1,1,1,1
1,1,1,1,1,1,1,16,13,15,1,1,1,12,12,1,1,1,16,13,15,1,1,1,1
1,1,1,1,1,1,1,16,13,15,1,1,1,0,0,1,1,1,16,13,15,1,1,1,1
1,1,1,1,1,1,1,16,13,15,1,1,1,0,0,1,1,1,16,13,15,1,1,1,1
1,1,1,1,1,1,1,16,13,15,1,1,1,0,0,1,1,1,16,13,15,1,1,1,1
1,1,1,1,1,1,1,16,13,15,1,1,1,5,5,1,1,1,16,13,15,1,1,1,1
1,1,1,1,1,1,1,16,13,15,1,1,1,1,1,1,1,1,16,13,15,1,1,1,1
1,1,1,1,1,1,1,16,13,15,1,1,1,1,1,1,1,1,16,13,15,1,1,1,1
1,1,1,1,1,1,1,16,13,15,1,1,1,1,1,1,1,1,16,13,15,1,1,1,1
1,1,1,1,1,1,1,16,13,15,1,1,1,1,1,1,1,1,16,13,15,1,1,1,1
1,1,1,1,1,1,1,16,13,15,1,1,1,1,1,1,1,1,16,13,15,1,1,1,1
1,1,1,1,1,1,1,16,13,15,1,1,1,1,1,1,1,1,16,13,15,1,1,1,1
1,1,1,1,1,1,1,16,13,15,1,1,1,1,1,1,1,1,16,13,15,1,1,1,1
1,1,1,1,1,1,1,16,13,15,1,1,1,1,1,1,1,1,16,13,15,1,1,1,1
1,1,1,1,1,1,1,16,13,15,1,1,1,1,1,1,1,1,16,13,15,1,1,1,1
1,1,1,1,1,1,1,16,13,15,1,1,1,1,1,1,1,1,16,13,15,1,1,1,1
1,1,1,1,1,1,1,16,13,15,1,1,1,1,1,1,1,1,16,13,15,1,1,1,1
1,1,1,1,1,1,1,16,13,15,1,1,1,1,1,1,1,1,16,13,15,1,1,1,1
1,1,1,1,1,1,1,1,1,1,1,1,1,1,1,1,1,1,1,1,1,1,1,1,1
1,1,1,1,1,1,1,1,1,1,1,1,1,1,1,1,1,1,1,1,1,1,1,1,1
endlayer

layer
1,1,1,1,1,1,1,1,1,1,1,1,1,1,1,1,1,1,1,1,1,1,1,1,1
1,1,1,1,1,1,1,1,1,1,1,1,1,1,1,1,1,1,1,1,1,1,1,1,1
1,1,1,1,1,1,1,1,1,1,1,1,1,1,1,1,1,1,1,1,1,1,1,1,1
1,1,1,1,1,1,1,1,1,1,1,1,1,1,1,1,1,1,1,1,1,1,1,1,1
1,1,1,1,1,1,1,1,1,1,1,1,1,1,1,1,1,1,1,1,1,1,1,1,1
1,1,1,1,1,1,1,1,1,1,1,1,1,1,1,1,1,1,1,1,1,1,1,1,1
1,1,1,1,1,1,1,1,1,1,1,1,1,1,1,1,1,1,1,1,1,1,1,1,1
1,1,1,1,1,1,1,1,1,1,1,1,1,12,12,1,1,1,1,1,1,1,1,1,1
1,1,1,1,1,1,1,1,1,1,1,1,1,0,0,1,1,1,1,1,1,1,1,1,1
1,1,1,1,1,1,1,1,1,1,1,1,1,0,0,1,1,1,1,1,1,1,1,1,1
1,1,1,1,1,1,1,1,1,1,1,1,1,0,0,1,1,1,1,1,1,1,1,1,1
1,1,1,1,1,1,1,1,1,1,1,1,1,5,5,1,1,1,1,1,1,1,1,1,1
1,1,1,1,1,1,1,1,1,1,1,1,1,1,1,1,1,1,1,1,1,1,1,1,1
1,1,1,1,1,1,1,1,1,1,1,1,1,1,1,1,1,1,1,1,1,1,1,1,1
1,1,1,1,1,1,1,1,1,1,1,1,1,1,1,1,1,1,1,1,1,1,1,1,1
1,1,1,1,1,1,1,1,1,1,1,1,1,1,1,1,1,1,1,1,1,1,1,1,1
1,1,1,1,1,1,1,1,1,1,1,1,1,1,1,1,1,1,1,1,1,1,1,1,1
1,1,1,1,1,1,1,1,1,1,1,1,1,1,1,1,1,1,1,1,1,1,1,1,1
1,1,1,1,1,1,1,1,1,1,1,1,1,1,1,1,1,1,1,1,1,1,1,1,1
1,1,1,1,1,1,1,1,1,1,1,1,1,1,1,1,1,1,1,1,1,1,1,1,1
1,1,1,1,1,1,1,1,1,1,1,1,1,1,1,1,1,1,1,1,1,1,1,1,1
1,1,1,1,1,1,1,1,1,1,1,1,1,1,1,1,1,1,1,1,1,1,1,1,1
1,1,1,1,1,1,1,1,1,1,1,1,1,1,1,1,1,1,1,1,1,1,1,1,1
1,1,1,1,1,1,1,1,1,1,1,1,1,1,1,1,1,1,1,1,1,1,1,1,1
1,1,1,1,1,1,1,1,1,1,1,1,1,1,1,1,1,1,1,1,1,1,1,1,1
endlayer

layer
1,1,1,1,1,1,1,1,1,1,1,1,1,1,1,1,1,1,1,1,1,1,1,1,1
1,1,1,1,1,1,1,1,1,1,1,1,1,1,1,1,1,1,1,1,1,1,1,1,1
1,1,1,1,1,1,1,1,1,1,1,1,1,1,1,1,1,1,1,1,1,1,1,1,1
1,1,1,1,1,1,1,1,1,1,1,1,1,1,1,1,1,1,1,1,1,1,1,1,1
1,1,1,1,1,1,1,1,1,1,1,1,1,1,1,1,1,1,1,1,1,1,1,1,1
1,1,1,1,1,1,1,1,1,1,1,1,1,1,1,1,1,1,1,1,1,1,1,1,1
1,1,1,1,1,1,1,1,1,1,1,1,1,1,1,1,1,1,1,1,1,1,1,1,1
1,1,1,1,1,1,1,1,1,1,1,1,1,1,1,1,1,1,1,1,1,1,1,1,1
1,1,1,1,1,1,1,1,1,1,1,1,1,12,12,1,1,1,1,1,1,1,1,1,1
1,1,1,1,1,1,1,1,1,1,1,1,1,0,0,1,1,1,1,1,1,1,1,1,1
1,1,1,1,1,1,1,1,1,1,1,1,1,0,0,1,1,1,1,1,1,1,1,1,1
1,1,1,1,1,1,1,1,1,1,1,1,1,0,0,1,1,1,1,1,1,1,1,1,1
1,1,1,1,1,1,1,1,1,1,1,1,1,5,5,1,1,1,1,1,1,1,1,1,1
1,1,1,1,1,1,1,1,1,1,1,1,1,1,1,1,1,1,1,1,1,1,1,1,1
1,1,1,1,1,1,1,1,1,1,1,1,1,1,1,1,1,1,1,1,1,1,1,1,1
1,1,1,1,1,1,1,1,1,1,1,1,1,1,1,1,1,1,1,1,1,1,1,1,1
1,1,1,1,1,1,1,1,1,1,1,1,1,1,1,1,1,1,1,1,1,1,1,1,1
1,1,1,1,1,1,1,1,1,1,1,1,1,1,1,1,1,1,1,1,1,1,1,1,1
1,1,1,1,1,1,1,1,1,1,1,1,1,1,1,1,1,1,1,1,1,1,1,1,1
1,1,1,1,1,1,1,1,1,1,1,1,1,1,1,1,1,1,1,1,1,1,1,1,1
1,1,1,1,1,1,1,1,1,1,1,1,1,1,1,1,1,1,1,1,1,1,1,1,1
1,1,1,1,1,1,1,1,1,1,1,1,1,1,1,1,1,1,1,1,1,1,1,1,1
1,1,1,1,1,1,1,1,1,1,1,1,1,1,1,1,1,1,1,1,1,1,1,1,1
1,1,1,1,1,1,1,1,1,1,1,1,1,1,1,1,1,1,1,1,1,1,1,1,1
1,1,1,1,1,1,1,1,1,1,1,1,1,1,1,1,1,1,1,1,1,1,1,1,1
endlayer

layer
1,5,5,5,5,17,1,5,5,5,1,17,5,17,5,17,5,17,5,17,5,5,5,5,1
19,1,1,1,1,1,1,1,1,1,1,1,1,1,1,1,1,1,1,1,1,1,1,1,18
19,1,1,1,1,1,1,1,1,1,1,1,1,1,1,1,1,1,1,1,1,1,1,1,18
19,1,1,1,1,1,1,1,1,1,1,1,1,1,1,1,1,1,1,1,1,1,1,1,18
19,1,1,1,1,1,1,1,1,1,1,1,1,1,1,1,1,1,1,1,1,1,1,1,18
17,1,1,1,1,1,1,1,1,1,1,1,1,1,1,1,1,1,1,1,1,1,1,1,17
19,1,1,1,1,1,1,1,1,1,1,1,1,1,1,1,1,1,1,1,1,1,1,1,18
17,1,1,1,1,1,1,1,1,1,1,1,1,1,1,1,1,1,1,1,1,1,1,1,17
19,1,1,1,1,1,1,1,1,1,1,1,1,1,1,1,1,1,1,1,1,1,1,1,18
17,1,1,1,1,1,1,1,1,1,1,1,1,12,12,1,1,1,1,1,1,1,1,1,17
19,1,1,1,1,1,1,1,1,1,1,1,1,0,0,1,1,1,1,1,1,1,1,1,18
17,1,1,1,1,1,1,1,1,1,1,1,1,0,0,1,1,1,1,1,1,1,1,1,17
19,1,1,1,1,1,1,1,1,1,1,1,1,0,0,1,1,1,1,1,1,1,1,1,18
17,1,1,1,1,1,1,1,1,1,1,1,1,5,5,1,1,1,1,1,1,1,1,1,17
19,1,1,1,1,1,1,1,1,1,1,1,1,1,1,1,1,1,1,1,1,1,1,1,18
17,1,1,1,1,1,1,1,1,1,1,1,1,1,1,1,1,1,1,1,1,1,1,1,17
19,1,1,1,1,1,1,1,1,1,1,1,1,1,1,1,1,1,1,1,1,1,1,1,18
17,1,1,1,1,1,1,1,1,1,1,1,1,1,1,1,1,1,1,1,1,1,1,1,17
19,1,1,1,1,1,1,1,1,1,1,1,1,1,1,1,1,1,1,1,1,1,1,1,18
17,1,1,1,1,1,1,1,1,1,1,1,1,1,1,1,1,1,1,1,1,1,1,1,17
19,1,1,1,1,1,1,1,1,1,1,1,1,1,1,1,1,1,1,1,1,1,1,1,18
19,1,1,1,1,1,1,1,1,1,1,1,1,1,1,1,1,1,1,1,1,1,1,1,18
19,1,1,1,1,1,1,1,1,1,1,1,1,1,1,1,1,1,1,1,1,1,1,1,18
19,1,1,1,1,1,1,1,1,1,1,1,1,1,1,1,1,1,1,1,1,1,1,1,18
1,20,20,20,20,17,20,17,20,17,20,17,20,17,20,17,20,17,20,17,20,20,20,20,1
endlayer

layer
1,17,17,17,17,17,5,0,0,0,5,17,17,17,17,17,17,17,17,17,17,17,17,17,1
17,17,1,1,0,0,1,0,0,0,1,0,0,0,0,0,0,0,0,0,0,1,1,17,17
17,1,21,1,22,23,24,0,0,0,24,23,22,23,23,23,23,23,23,23,22,1,21,1,17
17,1,1,0,0,0,0,0,0,0,0,0,1,0,0,0,0,0,0,0,4,1,1,1,17
17,0,22,0,0,0,0,0,0,0,0,0,22,0,25,0,25,0,25,0,22,4,22,0,17
17,0,23,0,0,0,5,1,5,0,0,0,23,0,26,26,26,26,26,0,0,0,23,0,17
17,0,23,0,0,19,2,2,2,18,0,0,0,0,27,0,27,0,27,0,0,0,23,0,17
17,0,23,0,0,1,2,1,2,1,0,0,0,0,0,0,0,0,0,0,0,0,23,0,17
17,0,23,0,0,19,2,2,2,18,0,0,0,0,0,28,28,28,28,28,0,0,23,0,17
17,0,23,0,0,0,20,1,20,0,0,0,23,30,30,28,29,29,29,28,0,0,23,0,17
17,0,23,0,0,0,0,0,0,0,0,0,22,31,31,28,29,29,29,28,0,0,23,0,17
17,0,23,0,0,0,0,0,0,0,0,0,1,0,0,28,29,29,29,28,0,0,23,0,17
17,0,22,1,22,23,0,0,0,23,22,1,22,0,0,28,29,29,29,28,0,0,22,0,17
17,0,23,0,0,0,0,0,0,0,0,0,1,0,0,28,29,29,29,28,0,0,23,0,17
17,0,23,0,0,0,0,0,0,0,0,0,22,4,0,28,29,29,29,28,0,0,23,0,17
17,0,23,0,0,0,25,0,25,0,0,0,1,1,0,28,29,29,29,28,0,0,23,0,17
17,0,23,0,0,33,26,26,26,32,0,0,1,1,0,28,29,29,29,28,0,0,23,0,17
17,0,23,0,0,0,26,22,26,0,0,0,22,4,26,28,29,29,29,28,0,0,23,0,17
17,0,23,0,0,33,26,26,26,32,0,0,34,0,0,28,28,28,28,28,0,0,23,0,17
17,0,23,0,0,0,27,0,27,0,0,0,34,0,0,0,0,0,0,0,0,0,23,0,17
17,0,22,0,0,0,0,0,0,0,0,0,22,0,35,35,36,35,35,0,22,4,22,0,17
17,1,1,0,0,0,0,0,0,0,0,0,1,0,0,0,0,0,0,0,4,1,1,1,17
17,1,21,1,22,23,23,23,23,23,23,23,22,23,23,23,23,23,23,23,22,1,21,1,17
17,17,1,1,0,0,0,0,0,0,0,0,0,0,0,0,0,0,0,0,0,1,1,17,17
1,17,17,17,17,17,17,17,17,17,17,17,17,17,17,17,17,17,17,17,17,17,17,17,1
endlayer

layer
4,17,17,17,17,17,17,0,0,0,0,17,17,17,17,17,17,17,17,17,17,17,17,17,4
17,17,1,0,0,0,0,0,0,0,0,0,0,0,0,0,0,0,0,0,0,0,1,17,17
17,1,37,1,22,23,24,0,0,0,24,23,22,23,24,38,38,38,24,23,22,1,37,1,17
17,0,1,0,0,0,0,0,0,0,0,0,1,0,0,0,0,0,0,0,4,1,1,0,17
17,0,22,0,0,0,0,0,0,0,0,0,22,0,0,0,0,0,0,0,22,4,22,0,17
17,0,23,0,0,0,0,0,0,0,0,0,23,0,39,39,39,39,39,0,0,0,23,0,17
17,0,40,0,0,0,0,41,0,0,0,0,0,0,0,0,0,0,0,0,0,0,40,0,17
17,0,38,0,0,0,41,4,41,0,0,0,0,0,0,0,0,0,0,0,0,0,38,0,17
17,0,38,0,0,0,0,41,0,0,0,0,0,0,0,0,0,0,0,0,0,0,38,0,17
17,0,38,0,0,0,0,0,0,0,0,0,23,0,0,0,0,0,0,0,0,0,38,0,17
17,0,40,0,0,0,0,0,0,0,0,0,22,30,30,0,0,0,0,0,0,0,40,0,17
17,0,23,0,0,0,0,0,0,0,0,0,1,31,31,0,0,0,0,0,0,0,23,0,17
17,0,22,1,22,23,0,0,0,23,22,1,22,0,0,0,0,0,0,0,0,0,22,0,17
17,0,23,0,0,0,0,0,0,0,0,0,1,0,0,0,0,0,0,0,0,0,23,0,17
17,0,40,0,0,0,0,0,0,0,0,0,22,4,0,0,0,0,0,0,0,0,40,0,17
17,0,38,0,0,0,0,0,0,0,0,0,1,42,0,0,0,0,0,0,0,0,38,0,17
17,0,38,0,0,0,39,39,39,0,0,0,1,42,0,0,0,0,0,0,0,0,38,0,17
17,0,38,0,0,0,39,39,39,0,0,0,22,4,39,0,0,0,0,0,0,0,38,0,17
17,0,40,0,0,0,39,39,39,0,0,0,43,0,0,0,0,0,0,0,0,0,40,0,17
17,0,23,0,0,0,0,0,0,0,0,0,44,0,0,0,0,0,0,0,0,0,23,0,17
17,0,22,0,0,0,0,0,0,0,0,0,22,0,3,3,0,3,3,0,22,4,22,0,17
17,0,1,0,0,0,0,0,0,0,0,0,1,0,0,0,0,0,0,0,4,1,1,0,17
17,1,37,1,22,23,24,38,38,38,24,23,22,23,24,38,38,38,24,23,22,1,37,1,17
17,17,1,0,0,0,0,0,0,0,0,0,0,0,0,0,0,0,0,0,0,0,1,17,17
4,17,17,17,17,17,17,17,17,17,17,17,17,17,17,17,17,17,17,17,17,17,17,17,4
endlayer

layer
21,17,17,17,17,17,17,0,0,0,0,17,17,17,17,17,17,17,17,17,17,17,17,17,21
17,17,4,0,0,0,0,0,0,0,0,0,0,0,0,0,0,0,0,0,0,0,4,17,17
17,4,0,1,22,23,24,0,0,0,24,23,22,23,24,38,38,38,24,23,22,1,0,4,17
17,0,1,0,0,0,0,0,0,0,0,0,1,0,0,0,0,0,0,0,4,1,1,0,17
17,0,22,0,0,0,0,0,0,0,0,0,22,0,0,0,0,0,0,0,22,4,22,0,17
17,0,23,0,0,0,0,0,0,0,0,0,23,0,0,0,0,0,0,0,0,0,23,0,17
17,0,40,0,0,0,0,45,0,0,0,0,0,0,0,0,0,0,0,0,0,0,40,0,17
17,0,38,0,0,0,45,2,45,0,0,0,0,0,0,0,0,0,0,0,0,0,38,0,17
17,0,38,0,0,0,0,45,0,0,0,0,0,0,0,0,0,0,0,0,0,0,38,0,17
17,0,38,0,0,0,0,0,0,0,0,0,23,0,0,0,0,0,0,0,0,0,38,0,17
17,0,40,0,0,0,0,0,0,0,0,0,22,0,0,0,0,0,0,0,0,0,40,0,17
17,0,23,0,0,0,0,0,0,0,0,0,1,30,30,0,0,0,0,0,0,0,23,0,17
17,0,22,1,22,23,0,0,0,23,22,1,22,31,31,0,0,0,0,0,0,0,22,0,17
17,0,23,0,0,0,0,0,0,0,0,0,1,0,0,0,0,0,0,0,0,0,23,0,17
17,0,40,0,0,0,0,0,0,0,0,0,22,21,0,0,0,0,0,0,0,0,40,0,17
17,0,38,0,0,0,0,0,0,0,0,0,1,18,0,0,0,0,0,0,0,0,38,0,17
17,0,38,0,0,0,0,0,0,0,0,0,1,18,0,0,0,0,0,0,0,0,38,0,17
17,0,38,0,0,0,0,0,0,0,0,0,22,21,0,0,0,0,0,0,0,0,38,0,17
17,0,40,0,0,0,0,0,0,0,0,0,24,0,0,0,0,0,0,0,0,0,40,0,17
17,0,23,0,0,0,0,0,0,0,0,0,24,0,0,0,0,0,0,0,0,0,23,0,17
17,0,22,0,0,0,0,0,0,0,0,0,22,0,0,0,0,0,0,0,22,4,22,0,17
17,0,1,0,0,0,0,0,0,0,0,0,1,0,0,0,0,0,0,0,4,1,1,0,17
17,4,0,1,22,23,24,38,38,38,24,23,22,23,24,38,38,38,24,23,22,1,0,4,17
17,17,4,0,0,0,0,0,0,0,0,0,0,0,0,0,0,0,0,0,0,0,4,17,17
21,17,17,17,17,17,17,17,17,17,17,17,17,17,17,17,17,17,17,17,17,17,17,17,21
endlayer

layer
0,17,17,17,17,17,0,0,0,0,0,0,17,17,17,17,17,17,17,17,17,17,17,17,0
17,17,4,0,0,0,46,0,0,0,46,0,0,0,46,0,0,0,46,0,0,0,4,17,17
17,4,0,1,22,23,24,0,0,0,24,23,22,23,24,38,38,38,24,23,22,1,0,4,17
17,0,1,0,0,0,0,0,0,0,0,0,1,0,0,0,0,0,0,0,4,1,1,0,17
17,0,22,0,0,0,0,0,0,0,0,0,22,0,0,0,0,0,0,0,22,4,22,0,17
17,0,23,0,0,0,0,0,0,0,0,0,23,0,0,0,0,0,0,0,0,0,23,0,17
17,46,40,0,0,0,0,0,0,0,0,0,0,0,0,0,0,0,0,0,0,0,40,46,17
17,0,38,0,0,0,0,0,0,0,0,0,0,0,0,0,0,0,0,0,0,0,38,0,17
17,0,38,0,0,0,0,0,0,0,0,0,0,0,0,0,0,0,0,0,0,0,38,0,17
17,0,38,0,0,0,0,0,0,0,0,0,23,0,0,0,0,0,0,0,0,0,38,0,17
17,46,40,0,0,0,0,0,0,0,0,0,22,0,0,0,0,0,0,0,0,0,40,46,17
17,0,23,0,0,0,0,0,0,0,0,0,1,0,0,0,0,0,0,0,0,0,23,0,17
17,0,22,1,22,23,0,0,0,23,22,1,22,30,30,0,0,0,0,0,0,0,22,0,17
17,0,23,0,0,0,0,0,0,0,0,0,1,31,31,0,0,0,0,0,0,0,23,0,17
17,46,40,0,0,0,0,0,0,0,0,0,22,0,0,0,0,0,0,0,0,0,40,46,17
17,0,38,0,0,0,0,26,0,0,0,0,1,0,0,0,0,0,0,0,0,0,38,0,17
17,0,38,0,0,0,26,26,26,0,0,0,1,0,0,0,0,0,0,0,0,0,38,0,17
17,0,38,0,0,26,26,26,26,26,0,0,22,0,0,0,0,0,0,0,0,0,38,0,17
17,46,40,0,0,0,26,26,26,0,0,0,1,0,0,0,0,0,0,0,0,0,40,46,17
17,0,23,0,0,0,0,26,0,0,0,0,1,0,0,0,0,0,0,0,0,0,23,0,17
17,0,22,0,0,0,0,0,0,0,0,0,22,0,0,0,0,0,0,0,22,4,22,0,17
17,0,1,0,0,0,0,0,0,0,0,0,1,0,0,0,0,0,0,0,4,1,1,0,17
17,4,0,1,22,23,24,38,38,38,24,23,22,23,24,38,38,38,24,23,22,1,0,4,17
17,17,4,0,0,0,46,0,0,0,46,0,0,0,46,0,0,0,46,0,0,0,4,17,17
0,17,17,17,17,17,17,17,17,17,17,17,17,17,17,17,17,17,17,17,17,17,17,17,0
endlayer

layer
0,17,17,17,17,17,0,0,0,0,0,0,17,17,17,17,17,17,17,17,17,17,17,17,0
17,17,4,0,0,0,46,0,0,0,46,0,0,0,46,0,0,0,46,0,0,0,4,17,17
17,4,0,1,22,23,24,46,46,46,24,23,22,23,24,38,38,38,24,23,22,1,0,4,17
17,0,1,0,0,0,0,0,0,0,0,0,1,0,0,0,0,0,0,0,4,1,1,0,17
17,0,22,0,0,0,0,0,0,0,0,0,22,0,0,0,0,0,0,0,22,4,22,0,17
17,0,23,0,0,0,0,0,0,0,0,0,23,0,0,0,0,0,0,0,0,0,23,0,17
17,46,40,0,0,0,0,0,0,0,0,0,31,0,0,0,0,0,0,0,0,0,40,46,17
17,0,38,0,0,0,0,0,0,0,0,0,0,0,0,0,0,0,0,0,0,0,38,0,17
17,0,38,0,0,0,0,0,0,0,0,0,47,0,0,0,0,0,0,0,0,0,38,0,17
17,0,38,0,0,0,0,0,0,0,0,0,23,0,0,0,0,0,0,0,0,0,38,0,17
17,46,40,0,0,0,0,0,0,0,0,0,22,0,0,0,0,0,0,0,0,0,40,46,17
17,0,23,0,0,0,0,0,0,0,0,0,1,0,0,0,0,0,0,0,0,0,23,0,17
17,0,22,1,22,23,49,0,48,23,22,1,22,0,0,0,0,0,0,0,0,0,22,0,17
17,0,23,0,0,0,0,0,0,0,0,0,1,30,30,0,0,0,0,0,0,0,23,0,17
17,46,40,0,0,0,0,0,0,0,0,0,22,31,31,0,0,0,0,0,0,0,40,46,17
17,0,38,0,0,0,0,21,0,0,0,0,1,0,0,0,0,0,0,0,0,0,38,0,17
17,0,38,0,0,0,26,0,26,0,0,0,1,0,0,0,0,0,0,0,0,0,38,0,17
17,0,38,0,0,21,0,26,0,21,0,0,22,0,0,0,0,0,0,0,0,0,38,0,17
17,46,40,0,0,0,26,0,26,0,0,0,1,0,0,0,0,0,0,0,0,0,40,46,17
17,0,23,0,0,0,0,21,0,0,0,0,1,0,0,0,0,0,0,0,0,0,23,0,17
17,0,22,0,0,0,0,0,0,0,0,0,22,0,0,0,0,0,0,0,22,4,22,0,17
17,0,1,0,0,0,0,0,0,0,0,0,1,0,0,0,0,0,0,0,4,0,1,0,17
17,4,0,1,22,23,24,38,38,38,24,23,22,23,24,38,38,38,24,23,22,1,0,4,17
17,17,4,0,0,0,46,0,0,0,46,0,0,0,46,0,0,0,46,0,0,0,4,17,17
0,17,17,17,17,17,17,17,17,17,17,17,17,17,17,17,17,17,17,17,17,17,17,17,0
endlayer

layer
0,17,17,17,17,17,0,0,0,0,0,0,17,17,17,17,17,17,17,17,17,17,17,17,0
17,17,1,0,0,0,40,40,40,40,40,0,0,0,40,40,40,40,40,0,0,0,1,17,17
17,1,37,1,22,23,24,24,24,24,24,23,22,23,24,24,24,24,24,23,22,1,37,1,17
17,0,1,0,0,0,0,0,0,0,0,0,1,0,0,0,0,0,0,0,4,0,1,0,17
17,0,22,0,0,0,0,0,0,0,0,0,22,0,0,0,0,0,0,0,22,4,22,0,17
17,0,23,0,0,0,0,0,0,0,0,0,23,0,0,0,0,0,0,0,0,0,23,0,17
17,24,40,0,0,0,0,0,0,0,0,0,23,0,0,0,0,0,0,0,0,0,40,24,17
17,24,40,0,0,0,0,0,0,0,0,0,23,0,0,0,0,0,0,0,0,0,40,24,17
17,24,40,0,0,0,0,0,0,0,0,0,23,0,0,0,0,0,0,0,0,0,40,24,17
17,24,40,0,0,0,0,0,0,0,0,0,23,0,0,0,0,0,0,0,0,0,40,24,17
17,24,40,0,0,0,0,0,0,0,0,0,22,0,0,0,0,0,0,0,0,0,40,24,17
17,0,23,0,0,0,0,0,0,0,0,0,1,0,0,0,0,0,0,0,0,0,23,0,17
17,0,22,1,22,23,23,23,23,23,22,1,22,0,0,0,0,0,0,0,0,0,22,0,17
17,0,23,0,0,0,0,0,0,0,0,0,1,0,0,0,0,0,0,0,0,0,23,0,17
17,24,40,0,0,0,0,0,0,0,0,0,22,30,30,0,0,0,0,0,0,0,40,24,17
17,24,40,0,0,0,0,0,0,0,0,0,24,23,23,0,0,0,0,0,0,0,40,24,17
17,24,40,0,0,0,21,0,21,0,0,0,24,23,23,0,0,0,0,0,0,0,40,24,17
17,24,40,0,0,0,0,26,0,0,0,0,22,0,0,0,0,0,0,0,0,0,40,24,17
17,24,40,0,0,0,21,0,21,0,0,0,1,0,0,0,0,0,0,0,0,0,40,24,17
17,0,23,0,0,0,0,0,0,0,0,0,1,0,0,0,0,0,0,0,0,0,23,0,17
17,0,22,0,0,0,0,0,0,0,0,0,22,0,0,0,0,0,0,0,22,4,22,0,17
17,0,1,0,0,0,0,0,0,0,0,0,1,0,0,0,0,0,0,0,4,1,1,0,17
17,1,37,1,22,23,24,24,24,24,24,23,22,23,24,24,24,24,24,23,22,1,37,1,17
17,17,1,0,0,0,40,40,40,40,40,0,0,0,40,40,40,40,40,0,0,0,1,17,17
0,17,17,17,17,17,17,17,17,17,17,17,17,17,17,17,17,17,17,17,17,17,17,17,0
endlayer

layer
0,17,17,17,17,17,0,0,0,0,0,0,17,17,17,17,17,17,17,17,17,17,17,17,0
17,17,1,1,0,0,0,0,0,0,0,0,0,0,0,0,0,0,0,0,0,1,1,17,17
17,1,50,1,22,23,23,23,23,23,23,23,22,23,23,23,23,23,23,23,22,1,50,1,17
17,1,1,0,0,0,0,0,0,0,0,0,1,0,0,0,0,0,0,0,4,1,1,1,17
17,0,22,0,0,0,0,0,0,0,0,0,22,0,0,0,0,0,0,0,22,4,22,0,17
17,0,23,0,0,0,0,0,0,0,0,0,24,0,0,0,0,0,0,0,0,0,23,0,17
17,0,23,0,0,0,0,0,0,0,0,0,24,0,0,0,0,0,0,0,0,0,23,0,17
17,0,23,0,0,0,0,0,0,0,0,0,24,0,0,0,0,0,0,0,0,0,23,0,17
17,0,23,0,0,0,0,0,0,0,0,0,24,0,0,0,0,0,0,0,0,0,23,0,17
17,0,23,0,0,0,0,0,0,0,0,0,24,0,0,0,0,0,0,0,0,0,23,0,17
17,0,23,0,0,0,0,0,0,0,0,0,22,0,0,0,0,0,0,0,0,0,23,0,17
17,0,23,0,0,0,0,0,0,0,0,0,1,0,0,0,0,0,0,0,0,0,23,0,17
17,0,22,1,22,40,40,40,40,40,22,1,22,0,0,0,0,0,0,0,0,0,22,0,17
17,0,23,0,0,0,0,0,0,0,0,0,1,0,0,0,0,0,0,0,0,0,23,0,17
17,0,23,0,0,0,0,0,0,0,0,0,22,0,0,0,0,0,0,0,0,0,23,0,17
17,0,23,0,0,0,0,0,0,0,0,48,51,0,0,0,0,0,0,0,0,0,23,0,17
17,0,23,0,0,0,0,0,0,0,0,48,51,0,0,0,0,0,0,0,0,0,23,0,17
17,0,23,0,0,0,0,26,0,0,0,0,22,0,0,0,0,0,0,0,0,0,23,0,17
17,0,23,0,0,0,0,0,0,0,0,0,1,0,0,0,0,0,0,0,0,0,23,0,17
17,0,23,0,0,0,0,0,0,0,0,0,1,0,0,0,0,0,0,0,0,0,23,0,17
17,0,22,0,0,0,0,0,0,0,0,0,22,0,0,0,0,0,0,0,22,4,22,0,17
17,1,1,0,0,0,0,0,0,0,0,0,1,0,0,0,0,0,0,0,4,1,1,1,17
17,1,52,1,22,23,23,23,23,23,23,23,22,23,23,23,23,23,23,23,22,1,52,1,17
17,17,1,1,0,0,0,0,0,0,0,0,0,0,0,0,0,0,0,0,0,1,1,17,17
0,17,17,17,17,17,17,17,17,17,17,17,17,17,17,17,17,17,17,17,17,17,17,17,0
endlayer

layer
0,14,17,14,17,17,17,0,0,0,0,17,17,17,17,17,17,17,17,17,17,14,0,14,0
15,1,1,1,0,14,0,14,0,14,0,14,0,14,0,14,0,14,0,14,0,1,1,1,16
0,1,1,1,1,1,1,1,1,1,1,1,1,1,1,1,1,1,1,1,1,1,1,1,0
15,1,1,0,0,0,0,0,0,0,0,0,1,0,0,0,0,0,0,0,4,1,1,1,16
17,0,1,0,0,0,0,0,0,0,0,0,22,0,0,0,0,0,0,0,22,4,1,0,17
17,15,1,0,0,0,0,0,0,0,0,0,0,0,0,0,0,0,0,0,0,0,1,16,17
17,0,1,0,0,0,0,0,0,0,0,0,0,0,0,0,0,0,0,0,0,0,1,0,17
17,15,1,0,0,0,0,0,0,0,0,0,0,0,0,0,0,0,0,0,0,0,1,16,17
17,0,1,0,0,0,0,0,0,0,0,0,0,0,0,0,0,0,0,0,0,0,1,0,17
17,15,1,0,0,0,0,0,0,0,0,0,0,0,0,0,0,0,0,0,0,0,1,16,17
17,0,1,0,0,0,0,0,0,0,0,0,22,0,0,0,0,0,0,0,0,0,1,0,17
17,15,1,0,0,0,0,0,0,0,0,0,1,0,0,0,0,0,0,0,0,0,1,16,17
17,0,1,1,22,0,0,0,0,0,22,1,22,0,0,0,0,0,0,0,0,0,1,0,17
17,15,1,0,0,0,0,0,0,0,0,0,1,0,0,0,0,0,0,0,0,0,1,16,17
17,0,1,0,0,0,0,0,0,0,0,0,22,0,0,0,0,0,0,0,0,0,1,0,17
17,15,1,0,0,0,0,0,0,0,48,51,0,0,0,0,0,0,0,0,0,0,1,16,17
17,0,1,0,0,0,0,0,0,0,48,51,0,0,0,0,0,0,0,0,0,0,1,0,17
17,15,1,0,0,0,0,26,0,0,0,0,22,0,0,0,0,0,0,0,0,0,1,16,17
17,0,1,0,0,0,0,0,0,0,0,0,1,0,0,0,0,0,0,0,0,0,1,0,17
17,15,1,0,0,0,0,0,0,0,0,0,1,0,0,0,0,0,0,0,0,0,1,16,17
17,0,1,0,0,0,0,0,0,0,0,0,22,0,0,0,0,0,0,0,22,4,1,0,17
15,1,1,0,0,0,0,0,0,0,0,0,1,0,0,0,0,0,0,0,4,1,1,1,16
0,1,1,1,1,1,1,1,1,1,1,1,1,1,1,1,1,1,1,1,1,1,1,1,0
15,1,1,1,0,12,0,12,0,12,0,12,0,12,0,12,0,12,0,12,0,1,1,1,16
0,12,0,12,17,17,17,17,17,17,17,17,17,17,17,17,17,17,17,17,17,12,0,12,0
endlayer

layer
0,4,1,1,4,17,17,0,0,0,0,17,17,17,17,17,17,17,17,17,4,1,1,4,0
4,1,1,1,1,1,14,1,14,1,14,1,14,1,14,1,14,1,14,1,1,1,1,1,4
1,1,1,1,1,1,1,1,1,1,1,1,1,1,1,1,1,1,1,1,1,1,1,1,1
1,1,1,23,23,23,23,23,23,23,23,23,24,23,23,23,23,23,23,23,23,23,1,1,1
4,1,1,23,23,23,23,23,23,23,23,23,24,23,23,23,23,23,23,23,23,23,1,1,4
17,1,1,23,23,23,23,23,23,23,23,23,24,23,23,23,23,23,23,23,23,23,1,1,17
17,15,1,23,23,23,23,23,23,23,23,23,24,23,23,23,23,23,23,23,23,23,1,16,17
17,1,1,23,23,23,23,23,23,23,23,23,24,23,23,23,23,23,23,23,23,23,1,1,17
17,15,1,23,23,23,23,23,23,23,23,23,24,23,23,23,23,23,23,23,23,23,1,16,17
17,1,1,23,23,23,23,23,23,23,23,23,24,23,23,23,23,23,23,23,23,23,1,1,17
17,15,1,23,23,23,23,23,23,23,23,23,24,23,23,23,23,23,23,23,23,23,1,16,17
17,1,1,23,23,23,23,23,23,23,23,23,24,23,23,23,23,23,23,23,23,23,1,1,17
17,15,1,40,40,40,40,40,40,40,40,40,22,40,40,40,40,40,40,40,40,40,1,16,17
17,1,1,23,23,23,23,23,23,23,23,23,24,23,23,23,23,23,23,23,23,23,1,1,17
17,15,1,23,23,23,23,23,23,23,23,23,24,23,23,23,23,23,23,23,23,23,1,16,17
17,1,1,23,23,23,23,23,23,23,51,0,0,0,48,23,23,23,23,23,23,23,1,1,17
17,15,1,23,23,23,23,23,23,23,51,0,0,0,48,23,23,23,23,23,23,23,1,16,17
17,1,1,23,23,23,23,22,23,23,23,23,22,23,23,23,23,23,23,23,23,23,1,1,17
17,15,1,23,23,23,23,23,23,23,23,23,24,23,23,23,23,23,23,23,23,23,1,16,17
17,1,1,23,23,23,23,23,23,23,23,23,24,23,23,23,23,23,23,23,23,23,1,1,17
4,1,1,23,23,23,23,23,23,23,23,23,24,23,23,23,23,23,23,23,23,23,1,1,4
1,1,1,23,23,23,23,23,23,23,23,23,24,23,23,23,23,23,23,23,23,23,1,1,1
1,1,1,1,1,1,1,1,1,1,1,1,1,1,1,1,1,1,1,1,1,1,1,1,1
4,1,1,1,1,1,12,1,12,1,12,1,12,1,12,1,12,1,12,1,1,1,1,1,4
0,4,1,1,4,17,17,17,17,17,17,17,17,17,17,17,17,17,17,17,4,1,1,4,0
endlayer

layer
0,0,0,0,0,0,0,0,0,0,0,0,0,0,0,0,0,0,0,0,0,0,0,0,0
0,0,1,1,0,0,0,0,0,0,0,0,0,0,0,0,0,0,0,0,0,1,1,0,0
0,1,21,1,22,23,23,23,23,23,23,23,22,23,23,23,23,23,23,23,22,1,21,1,0
0,1,1,23,23,39,0,0,57,57,0,22,23,56,0,55,54,53,0,0,23,23,1,1,0
0,0,22,23,23,39,0,0,59,59,0,58,23,33,0,0,0,0,0,6,23,23,22,0,0
0,0,23,61,60,23,0,0,0,0,0,58,23,33,0,39,39,0,0,23,26,57,23,0,0
0,0,23,26,0,0,23,0,0,0,0,22,23,62,0,0,0,0,23,0,0,59,23,0,0
0,0,23,0,0,0,0,22,23,63,63,23,22,23,63,63,23,22,0,0,0,0,23,0,0
0,0,23,0,0,0,0,23,0,0,0,65,49,0,0,0,0,23,0,0,0,64,23,0,0
0,0,23,0,64,53,0,67,0,0,0,0,0,0,0,0,0,34,0,0,66,55,23,0,0
0,0,23,0,55,54,0,67,0,0,0,0,0,0,0,0,0,34,0,0,0,54,23,0,0
0,0,23,0,0,0,0,23,0,0,0,0,0,0,0,0,0,23,69,27,68,0,23,0,0
0,0,22,23,23,23,23,22,0,0,0,0,22,0,0,0,0,22,23,23,23,23,22,0,0
0,0,23,0,0,0,0,23,0,0,0,0,0,0,0,0,0,23,0,0,25,25,23,0,0
0,0,23,26,66,0,0,67,0,0,46,46,46,46,0,0,0,34,0,0,26,26,23,0,0
0,0,23,61,60,0,0,67,0,0,0,0,0,46,0,0,0,34,0,0,27,27,23,0,0
0,0,23,26,0,0,0,23,0,0,0,0,0,46,0,0,0,23,0,66,0,0,23,0,0
0,0,23,61,60,0,0,22,23,70,70,23,22,23,70,70,23,22,0,0,25,25,23,0,0
0,0,23,26,0,0,23,0,0,0,0,22,23,26,0,0,0,0,23,0,26,26,23,0,0
0,0,23,0,0,23,0,0,25,66,0,58,23,61,60,0,69,25,68,23,27,27,23,0,0
0,0,22,23,23,58,0,33,26,32,0,58,23,61,60,66,0,0,0,58,23,23,22,0,0
0,1,1,23,23,58,0,0,27,0,0,22,23,26,0,0,0,0,0,58,23,23,1,1,0
0,1,21,1,22,23,23,23,23,23,23,23,22,23,23,23,23,23,23,23,22,1,21,1,0
0,0,1,1,0,0,0,0,0,0,0,0,0,0,0,0,0,0,0,0,0,1,1,0,0
0,0,0,0,0,0,0,0,0,0,0,0,0,0,0,0,0,0,0,0,0,0,0,0,0
endlayer

layer
0,0,0,0,0,0,0,0,0,0,0,0,0,0,0,0,0,0,0,0,0,0,0,0,0
0,0,1,0,0,0,0,0,0,0,0,0,0,0,0,0,0,0,0,0,0,0,1,0,0
0,1,37,1,22,23,24,38,38,38,24,23,22,23,24,38,38,38,24,23,22,1,37,1,0
0,0,1,23,23,39,0,0,0,0,0,22,23,0,0,0,0,0,0,0,23,23,1,0,0
0,0,22,23,23,39,0,0,0,66,0,58,23,0,0,0,0,0,0,0,23,23,22,0,0
0,0,23,0,0,23,0,0,0,0,0,58,23,0,0,66,0,0,0,23,39,0,23,0,0
0,0,40,39,0,0,23,0,0,0,0,22,23,0,0,0,0,0,23,0,0,0,40,0,0
0,0,38,0,0,0,0,22,23,43,44,23,22,23,43,44,23,22,0,0,0,0,38,0,0
0,0,38,0,0,0,0,23,0,0,0,0,65,49,0,0,0,23,0,0,0,0,38,0,0
0,0,38,0,0,0,0,44,0,0,0,0,0,0,0,0,0,43,0,0,0,0,38,0,0
0,0,40,0,66,0,0,43,0,0,0,0,0,0,0,0,0,44,0,0,0,0,40,0,0
0,0,23,0,0,0,0,23,0,0,0,0,0,0,0,0,0,23,0,0,0,0,23,0,0
0,0,22,23,23,23,23,22,0,0,0,0,22,0,0,0,0,22,23,23,23,23,22,0,0
0,0,23,0,0,0,0,23,0,0,0,0,0,0,0,0,0,23,0,0,0,0,23,0,0
0,0,40,39,0,0,0,44,0,0,0,0,0,0,0,0,0,43,0,0,39,39,40,0,0
0,0,38,0,0,0,0,43,0,0,0,0,0,0,0,0,0,44,0,0,0,0,38,0,0
0,0,38,39,0,0,0,23,0,0,0,0,0,0,0,0,0,23,0,0,0,0,38,0,0
0,0,38,0,0,0,0,22,23,44,43,23,22,23,44,43,23,22,0,0,0,0,38,0,0
0,0,40,39,0,0,23,0,0,0,0,22,23,39,0,0,0,0,23,0,39,39,40,0,0
0,0,23,0,0,23,0,0,0,0,0,58,23,0,0,0,0,0,0,23,0,0,23,0,0
0,0,22,23,23,58,0,0,39,0,0,58,23,0,0,0,0,0,0,58,23,23,22,0,0
0,0,1,23,23,58,0,0,0,0,0,22,23,39,0,0,0,0,0,58,23,23,1,0,0
0,1,37,1,22,23,24,38,38,38,24,23,22,23,24,38,38,38,24,23,22,1,37,1,0
0,0,1,0,0,0,0,0,0,0,0,0,0,0,0,0,0,0,0,0,0,0,1,0,0
0,0,0,0,0,0,0,0,0,0,0,0,0,0,0,0,0,0,0,0,0,0,0,0,0
endlayer

layer
0,0,0,0,0,0,0,0,0,0,0,0,0,0,0,0,0,0,0,0,0,0,0,0,0
0,0,4,0,0,0,0,0,0,0,0,0,0,0,0,0,0,0,0,0,0,0,4,0,0
0,4,0,1,22,23,24,38,38,38,24,23,22,23,24,38,38,38,24,23,22,1,0,4,0
0,0,1,23,23,39,0,0,0,0,0,22,23,0,0,0,0,0,0,0,23,23,1,0,0
0,0,22,23,23,39,0,0,0,0,0,71,23,0,0,0,0,0,0,0,23,23,22,0,0
0,0,23,0,0,23,0,0,0,0,0,71,23,0,0,0,0,0,0,23,0,0,23,0,0
0,0,40,0,0,0,23,0,0,0,0,22,23,0,0,0,0,0,23,0,0,0,40,0,0
0,0,38,0,0,0,0,22,23,23,23,23,22,23,23,23,23,22,0,0,0,0,38,0,0
0,0,38,0,0,0,0,23,0,0,0,0,0,65,49,0,0,23,0,0,0,0,38,0,0
0,0,38,0,0,0,0,23,0,0,0,0,0,0,0,0,0,23,0,0,0,0,38,0,0
0,0,40,0,0,0,0,23,0,0,0,0,0,0,0,0,0,23,0,0,0,0,40,0,0
0,0,23,0,0,0,0,23,0,0,0,0,46,0,0,0,0,23,0,0,0,0,23,0,0
0,0,22,23,23,23,23,22,0,0,0,46,22,46,0,0,0,22,23,23,23,23,22,0,0
0,0,23,0,0,0,0,23,0,0,0,0,46,0,0,0,0,23,0,0,0,0,23,0,0
0,0,40,0,0,0,0,23,0,0,0,0,0,0,0,0,0,23,0,0,0,0,40,0,0
0,0,38,0,0,0,0,23,0,0,0,0,0,0,0,0,0,23,0,0,0,0,38,0,0
0,0,38,0,0,0,0,23,0,0,0,0,0,0,0,0,0,23,0,0,0,0,38,0,0
0,0,38,0,0,0,0,22,23,23,23,23,22,23,23,23,23,22,0,0,0,0,38,0,0
0,0,40,0,0,0,23,0,0,0,0,22,23,0,0,0,0,0,23,0,0,0,40,0,0
0,0,23,0,0,23,0,0,0,0,0,71,23,0,0,0,0,0,0,23,0,0,23,0,0
0,0,22,23,23,58,0,0,0,0,0,71,23,0,0,0,0,0,0,58,23,23,22,0,0
0,0,1,23,23,58,0,0,0,0,0,22,23,0,0,0,0,0,0,58,23,23,1,0,0
0,4,0,1,22,23,24,38,38,38,24,23,22,23,24,38,38,38,24,23,22,1,0,4,0
0,0,4,0,0,0,0,0,0,0,0,0,0,0,0,0,0,0,0,0,0,0,4,0,0
0,0,0,0,0,0,0,0,0,0,0,0,0,0,0,0,0,0,0,0,0,0,0,0,0
endlayer

layer
0,0,0,0,0,0,0,0,0,0,0,0,0,0,0,0,0,0,0,0,0,0,0,0,0
0,0,4,0,0,0,46,0,0,0,46,0,0,0,46,0,0,0,46,0,0,0,4,0,0
0,4,0,1,22,23,24,38,38,38,24,23,22,23,24,38,38,38,24,23,22,1,0,4,0
0,0,1,23,23,39,0,0,0,0,0,0,23,0,0,0,0,0,0,0,23,23,1,0,0
0,0,22,23,23,39,0,0,0,0,0,0,23,0,0,0,0,0,0,0,23,23,22,0,0
0,0,23,0,0,23,0,0,0,0,0,0,23,0,0,0,0,0,0,23,0,0,23,0,0
0,46,40,0,0,0,23,0,0,0,0,0,23,0,0,0,0,0,23,0,0,0,40,46,0
0,0,38,0,0,0,0,22,23,23,23,23,22,23,23,23,23,22,0,0,0,0,38,0,0
0,0,38,0,0,0,0,23,0,0,0,0,0,0,65,49,0,23,0,0,0,0,38,0,0
0,0,38,0,0,0,0,23,0,0,0,0,0,0,0,0,0,23,0,0,0,0,38,0,0
0,46,40,0,0,0,0,23,0,0,0,0,0,0,0,0,0,23,0,0,0,0,40,46,0
0,0,23,0,0,0,0,23,0,0,0,0,21,0,0,0,0,23,0,0,0,0,23,0,0
0,0,22,23,23,23,23,22,0,0,0,21,22,21,0,0,0,22,23,23,23,23,22,0,0
0,0,23,0,0,0,0,23,0,0,0,0,21,0,0,0,0,23,0,0,0,0,23,0,0
0,46,40,0,0,0,0,23,0,0,0,0,0,0,0,0,0,23,0,0,0,0,40,46,0
0,0,38,0,0,0,0,23,0,0,0,0,0,0,0,0,0,23,0,0,0,0,38,0,0
0,0,38,0,0,0,0,23,0,0,0,0,0,0,0,0,0,23,0,0,0,0,38,0,0
0,0,38,0,0,0,0,22,23,23,23,23,22,23,23,23,23,22,0,0,0,0,38,0,0
0,46,40,0,0,0,23,0,0,0,0,0,23,0,0,0,0,0,23,0,0,0,40,46,0
0,0,23,0,0,23,0,0,0,0,0,0,23,0,0,0,0,0,0,23,0,0,23,0,0
0,0,22,23,23,71,0,0,0,0,0,0,23,0,0,0,0,0,0,71,23,23,22,0,0
0,0,1,23,23,71,0,0,0,0,0,0,23,0,0,0,0,0,0,71,23,23,1,0,0
0,4,0,1,22,23,24,38,38,38,24,23,22,23,24,38,38,38,24,23,22,1,0,4,0
0,0,4,0,0,0,46,0,0,0,46,0,0,0,46,0,0,0,46,0,0,0,4,0,0
0,0,0,0,0,0,0,0,0,0,0,0,0,0,0,0,0,0,0,0,0,0,0,0,0
endlayer

layer
0,0,0,0,0,0,0,0,0,0,0,0,0,0,0,0,0,0,0,0,0,0,0,0,0
0,0,4,0,0,0,46,0,0,0,46,0,0,0,46,0,0,0,46,0,0,0,4,0,0
0,4,0,1,22,23,24,38,38,38,24,23,22,23,24,38,38,38,24,23,22,1,0,4,0
0,0,1,22,22,39,0,0,0,0,0,0,24,0,0,0,0,0,0,0,22,22,1,0,0
0,0,22,22,22,39,0,0,0,0,0,0,24,0,0,0,0,0,0,0,22,22,22,0,0
0,0,23,0,0,22,0,0,0,0,0,0,24,0,0,0,0,0,0,22,0,0,23,0,0
0,46,40,0,0,0,22,0,0,0,0,0,24,0,0,0,0,0,22,0,0,0,40,46,0
0,0,38,0,0,0,0,22,40,40,40,40,22,40,40,40,40,22,0,0,0,0,38,0,0
0,0,38,0,0,0,0,24,72,72,72,72,0,0,0,65,49,24,0,0,0,0,38,0,0
0,0,38,0,0,0,0,24,72,72,72,72,72,72,72,72,72,24,0,0,0,0,38,0,0
0,46,40,0,0,0,0,24,72,72,0,0,0,0,0,72,72,24,0,0,0,0,40,46,0
0,0,23,0,0,0,0,24,72,72,0,0,0,0,0,72,72,24,0,0,0,0,23,0,0
0,0,22,40,40,40,40,22,72,72,0,0,22,0,0,72,72,22,40,40,40,40,22,0,0
0,0,23,0,0,0,0,24,72,72,0,0,0,0,0,72,72,24,0,0,0,0,23,0,0
0,46,40,0,0,0,0,24,72,72,0,0,0,0,0,72,72,24,0,0,0,0,40,46,0
0,0,38,0,0,0,0,24,72,72,72,72,72,72,72,72,72,24,0,0,0,0,38,0,0
0,0,38,0,0,0,0,24,72,72,72,72,72,72,72,72,72,24,0,0,0,0,38,0,0
0,0,38,0,0,0,0,22,40,40,40,40,22,40,40,40,40,22,0,0,0,0,38,0,0
0,46,40,0,0,0,22,0,0,0,0,0,24,0,0,0,0,0,22,0,0,0,40,46,0
0,0,23,0,0,22,0,0,0,0,0,0,24,0,0,0,0,0,0,22,0,0,23,0,0
0,0,22,22,22,0,0,0,0,0,0,0,24,0,0,0,0,0,0,0,22,22,22,0,0
0,0,1,22,22,0,0,0,0,0,0,0,24,0,0,0,0,0,0,0,22,22,1,0,0
0,4,0,1,22,23,24,38,38,38,24,23,22,23,24,38,38,38,24,23,22,1,0,4,0
0,0,4,0,0,0,46,0,0,0,46,0,0,0,46,0,0,0,46,0,0,0,4,0,0
0,0,0,0,0,0,0,0,0,0,0,0,0,0,0,0,0,0,0,0,0,0,0,0,0
endlayer

layer
0,0,0,0,0,0,0,0,0,0,0,0,0,0,0,0,0,0,0,0,0,0,0,0,0
0,0,1,0,0,0,40,40,40,40,40,0,0,0,40,40,40,40,40,0,0,0,1,0,0
0,1,37,1,22,23,24,24,24,24,24,23,22,23,24,24,24,24,24,23,22,1,37,1,0
0,0,1,23,23,0,0,0,0,0,0,0,23,0,0,0,0,0,0,0,23,23,1,0,0
0,0,22,23,23,0,0,0,0,0,0,0,23,0,0,0,0,0,0,0,23,23,22,0,0
0,0,23,0,0,23,0,0,0,0,0,0,23,0,0,0,0,0,0,23,0,0,23,0,0
0,24,40,0,0,0,23,0,0,0,0,0,23,0,0,0,0,0,23,0,0,0,40,24,0
0,24,40,0,0,0,0,22,23,23,23,23,22,23,23,23,23,22,0,0,0,0,40,24,0
0,24,40,0,0,0,0,23,0,0,0,0,0,0,0,0,0,23,0,0,0,0,40,24,0
0,24,40,0,0,0,0,23,0,46,46,46,46,46,46,46,0,23,0,0,0,0,40,24,0
0,24,40,0,0,0,0,23,0,46,0,0,0,0,0,46,0,23,0,0,0,0,40,24,0
0,0,23,0,0,0,0,23,0,46,0,0,0,0,0,46,0,23,0,0,0,0,23,0,0
0,0,22,23,23,23,23,22,0,46,0,0,22,0,0,46,0,22,23,23,23,23,22,0,0
0,0,23,0,0,0,0,23,0,46,0,0,0,0,0,46,0,23,0,0,0,0,23,0,0
0,24,40,0,0,0,0,23,0,46,0,0,0,0,0,46,0,23,0,0,0,0,40,24,0
0,24,40,0,0,0,0,23,0,46,46,46,46,46,46,46,0,23,0,0,0,0,40,24,0
0,24,40,0,0,0,0,23,0,0,0,0,0,0,0,0,0,23,0,0,0,0,40,24,0
0,24,40,0,0,0,0,22,23,23,23,23,22,23,23,23,23,22,0,0,0,0,40,24,0
0,24,40,0,0,0,23,0,0,0,0,0,23,0,0,0,0,0,23,0,0,0,40,24,0
0,0,23,0,0,23,0,0,0,0,0,0,23,0,0,0,0,0,0,23,0,0,23,0,0
0,0,22,23,23,0,0,0,0,0,0,0,23,0,0,0,0,0,0,0,23,23,22,0,0
0,0,1,23,23,0,0,0,0,0,0,0,23,0,0,0,0,0,0,0,23,23,1,0,0
0,1,37,1,22,23,24,24,24,24,24,23,22,23,24,24,24,24,24,23,22,1,37,1,0
0,0,1,0,0,0,40,40,40,40,40,0,0,0,40,40,40,40,40,0,0,0,1,0,0
0,0,0,0,0,0,0,0,0,0,0,0,0,0,0,0,0,0,0,0,0,0,0,0,0
endlayer

layer
0,0,0,0,0,0,0,0,0,0,0,0,0,0,0,0,0,0,0,0,0,0,0,0,0
0,0,1,1,0,0,0,0,0,0,0,0,0,0,0,0,0,0,0,0,0,1,1,0,0
0,1,50,1,22,23,23,23,23,23,23,23,22,23,23,23,23,23,23,23,22,1,73,1,0
0,1,1,23,23,0,0,0,0,0,0,0,23,0,0,0,0,0,0,0,23,23,1,1,0
0,0,22,23,23,0,0,0,0,0,0,0,23,0,0,0,0,0,0,0,23,23,22,0,0
0,0,23,0,0,23,0,0,0,0,0,0,23,0,0,0,0,0,0,23,0,0,23,0,0
0,0,23,0,0,0,23,0,0,0,0,0,23,0,0,0,0,0,23,0,0,0,23,0,0
0,0,23,0,0,0,0,22,23,23,23,23,22,23,23,23,23,22,0,0,0,0,23,0,0
0,0,23,0,0,0,0,23,0,0,0,0,0,0,0,0,0,23,0,0,0,0,23,0,0
0,0,23,0,0,0,0,23,0,0,0,0,0,0,0,0,0,23,0,0,0,0,23,0,0
0,0,23,0,0,0,0,23,0,0,0,0,0,0,0,0,0,23,0,0,0,0,23,0,0
0,0,23,0,0,0,0,23,0,0,0,0,0,0,0,0,0,23,0,0,0,0,23,0,0
0,0,22,23,23,23,23,22,0,0,0,0,22,0,0,0,0,22,23,23,23,23,22,0,0
0,0,23,0,0,0,0,23,0,0,0,0,0,0,0,0,0,23,0,0,0,0,23,0,0
0,0,23,0,0,0,0,23,0,0,0,0,0,0,0,0,0,23,0,0,0,0,23,0,0
0,0,23,0,0,0,0,23,0,0,0,0,0,0,0,0,0,23,0,0,0,0,23,0,0
0,0,23,0,0,0,0,23,0,0,0,0,0,0,0,0,0,23,0,0,0,0,23,0,0
0,0,23,0,0,0,0,22,23,23,23,23,22,23,23,23,23,22,0,0,0,0,23,0,0
0,0,23,0,0,0,23,0,0,0,0,0,23,0,0,0,0,0,23,0,0,0,23,0,0
0,0,23,0,0,23,0,0,0,0,0,0,23,0,0,0,0,0,0,23,0,0,23,0,0
0,0,22,23,23,0,0,0,0,0,0,0,23,0,0,0,0,0,0,0,23,23,22,0,0
0,1,1,23,23,0,0,0,0,0,0,0,23,0,0,0,0,0,0,0,23,23,1,1,0
0,1,52,1,22,23,23,23,23,23,23,23,22,23,23,23,23,23,23,23,22,1,52,1,0
0,0,1,1,0,0,0,0,0,0,0,0,0,0,0,0,0,0,0,0,0,1,1,0,0
0,0,0,0,0,0,0,0,0,0,0,0,0,0,0,0,0,0,0,0,0,0,0,0,0
endlayer

layer
0,14,0,14,0,0,0,0,0,0,0,0,0,0,0,0,0,0,0,0,0,14,0,14,0
15,1,1,1,0,14,0,14,0,14,0,14,0,14,0,14,0,14,0,14,0,1,1,1,16
0,1,1,1,1,1,1,1,1,1,1,1,1,1,1,1,1,1,1,1,1,1,1,1,0
15,1,1,23,23,0,0,0,0,0,0,0,23,0,0,0,0,0,0,0,23,23,1,1,16
0,0,1,23,23,0,0,0,0,0,0,0,23,0,0,0,0,0,0,0,23,23,1,0,0
0,15,1,0,0,23,0,0,0,0,0,0,23,0,0,0,0,0,0,23,0,0,1,16,0
0,0,1,0,0,0,23,0,0,0,0,0,23,0,0,0,0,0,23,0,0,0,1,0,0
0,15,1,0,0,0,0,22,23,23,23,23,22,23,23,23,23,22,0,0,0,0,1,16,0
0,0,1,0,0,0,0,23,0,0,0,0,0,0,0,0,0,23,0,0,0,0,1,0,0
0,15,1,0,0,0,0,23,0,0,0,0,0,0,0,0,0,23,0,0,0,0,1,16,0
0,0,1,0,0,0,0,23,0,0,0,0,0,0,0,0,0,23,0,0,0,0,1,0,0
0,15,1,0,0,0,0,23,0,0,0,0,0,0,0,0,0,23,0,0,0,0,1,16,0
0,0,1,23,23,23,23,22,0,0,0,0,22,0,0,0,0,22,23,23,23,23,1,0,0
0,15,1,0,0,0,0,23,0,0,0,0,0,0,0,0,0,23,0,0,0,0,1,16,0
0,0,1,0,0,0,0,23,0,0,0,0,0,0,0,0,0,23,0,0,0,0,1,0,0
0,15,1,0,0,0,0,23,0,0,0,0,0,0,0,0,0,23,0,0,0,0,1,16,0
0,0,1,0,0,0,0,23,0,0,0,0,0,0,0,0,0,23,0,0,0,0,1,0,0
0,15,1,0,0,0,0,22,23,23,23,23,22,23,23,23,23,22,0,0,0,0,1,16,0
0,0,1,0,0,0,23,0,0,0,0,0,23,0,0,0,0,0,23,0,0,0,1,0,0
0,15,1,0,0,23,0,0,0,0,0,0,23,0,0,0,0,0,0,23,0,0,1,16,0
0,0,1,23,23,0,0,0,0,0,0,0,23,0,0,0,0,0,0,0,23,23,1,0,0
15,1,1,23,23,0,0,0,0,0,0,0,23,0,0,0,0,0,0,0,23,23,1,1,16
0,1,1,1,1,1,1,1,1,1,1,1,22,1,1,1,1,1,1,1,1,1,1,1,0
15,1,1,1,0,12,0,12,0,12,0,12,0,12,0,12,0,12,0,12,0,1,1,1,16
0,12,0,12,0,0,0,0,0,0,0,0,0,0,0,0,0,0,0,0,0,12,0,12,0
endlayer

layer
0,4,1,1,4,0,0,0,0,0,0,0,0,0,0,0,0,0,0,0,4,1,1,4,0
4,1,1,1,14,1,14,1,14,1,14,1,14,1,14,1,14,1,14,1,14,1,1,1,4
1,1,40,40,40,40,40,40,40,40,40,40,40,40,40,40,40,40,40,40,40,40,24,1,1
1,1,24,23,23,72,72,24,0,0,0,0,24,0,0,0,0,24,72,72,23,23,24,1,1
4,15,24,23,23,72,72,24,0,0,0,0,24,0,0,0,0,24,72,72,23,23,24,16,4
0,1,24,72,72,23,72,24,0,0,0,0,24,0,0,0,0,24,72,23,72,72,24,1,0
0,15,24,72,72,72,23,24,0,0,0,0,24,0,0,0,0,24,23,72,72,72,24,16,0
0,1,24,40,40,40,40,24,40,40,40,40,24,40,40,40,40,40,40,40,40,40,24,1,0
0,15,24,0,0,0,0,24,72,72,72,72,24,72,72,72,72,24,0,0,0,0,24,16,0
0,1,24,0,0,0,0,24,72,72,72,72,24,72,72,72,72,24,0,0,0,0,24,1,0
0,15,24,0,0,0,0,24,72,72,72,72,24,72,72,72,72,24,0,0,0,0,24,16,0
0,1,24,0,0,0,0,24,72,72,72,72,24,72,72,72,72,24,0,0,0,0,24,1,0
0,15,24,40,40,40,40,40,40,40,40,40,22,40,40,40,40,40,40,40,40,40,24,16,0
0,1,24,0,0,0,0,24,72,72,72,72,24,72,72,72,72,24,0,0,0,0,24,1,0
0,15,24,0,0,0,0,24,72,72,72,72,24,72,72,72,72,24,0,0,0,0,24,16,0
0,1,24,0,0,0,0,24,72,72,72,72,24,72,72,72,72,24,0,0,0,0,24,1,0
0,15,24,0,0,0,0,24,72,72,72,72,24,72,72,72,72,24,0,0,0,0,24,16,0
0,1,24,40,40,40,40,40,40,40,40,40,24,40,40,40,40,24,40,40,40,40,24,1,0
0,15,24,72,72,72,23,24,0,0,0,0,24,0,0,0,0,24,23,72,72,72,24,16,0
0,1,24,72,72,23,72,24,0,0,0,0,24,0,0,0,0,24,72,23,72,72,24,1,0
4,15,24,23,23,72,72,24,0,0,0,0,24,0,0,0,0,24,72,72,23,23,24,16,4
1,1,24,23,23,72,72,24,0,0,0,0,24,0,0,0,0,24,72,72,23,23,24,1,1
1,1,40,40,40,40,40,40,40,40,40,40,40,40,40,40,40,40,40,40,40,40,40,1,1
4,1,1,1,12,1,12,1,12,1,12,1,12,1,12,1,12,1,12,1,12,1,1,1,4
0,4,1,1,4,0,0,0,0,0,0,0,0,0,0,0,0,0,0,0,4,1,1,4,0
endlayer

layer
30,30,30,30,30,30,30,30,30,30,30,30,30,30,30,30,30,30,30,30,30,30,30,30,51
65,0,23,23,23,23,23,23,23,23,23,23,23,23,23,23,23,23,23,23,23,23,23,1,51
65,23,0,0,0,0,0,0,0,0,0,0,74,0,0,0,0,0,0,0,74,0,0,23,51
65,23,0,0,0,0,0,0,0,0,0,0,0,0,0,0,0,0,0,0,0,0,0,23,51
65,23,74,0,0,0,0,0,0,0,0,0,0,0,0,0,0,0,0,0,0,74,0,23,51
65,23,0,0,0,0,0,0,0,0,0,0,0,0,0,0,0,0,0,0,0,0,0,23,51
65,23,0,0,0,0,0,0,0,0,0,0,0,0,0,0,0,0,0,0,0,0,0,23,51
65,23,0,0,0,0,0,0,0,0,0,0,0,0,0,0,0,0,0,0,0,0,0,23,51
65,23,0,0,0,0,0,0,23,23,23,23,23,23,23,23,23,0,0,0,0,0,0,23,51
65,23,0,0,0,0,0,0,23,23,23,23,23,23,23,23,23,0,0,0,0,0,0,23,51
65,23,0,0,0,0,0,0,23,23,23,23,23,23,23,23,23,0,0,0,0,0,0,23,51
65,23,0,0,0,0,0,0,23,23,23,23,23,23,23,23,23,0,0,0,0,0,0,23,51
65,23,0,0,0,0,0,0,23,23,23,23,22,23,23,23,23,0,0,0,0,0,0,23,51
65,23,0,0,0,0,0,0,23,23,23,23,23,23,23,23,23,0,0,0,0,0,0,23,51
65,23,0,0,0,0,0,0,23,23,23,23,23,23,23,23,23,74,0,0,0,0,0,23,51
65,23,0,0,0,0,0,0,23,23,23,23,23,23,23,23,23,0,0,0,0,0,0,23,51
65,23,0,0,0,0,0,0,23,23,23,23,23,23,23,23,23,0,0,0,0,0,0,23,51
65,23,0,0,0,0,0,0,0,0,0,0,0,74,0,0,0,0,0,0,0,0,0,23,51
65,23,0,0,0,0,0,0,0,0,0,0,0,0,0,0,0,0,0,0,0,0,74,23,51
65,23,0,0,0,0,0,0,0,0,0,0,0,0,0,0,0,0,0,0,0,0,0,23,51
65,23,74,0,0,0,0,0,0,0,0,0,0,0,0,0,0,0,0,0,0,0,0,23,51
65,23,0,0,0,0,0,0,0,0,0,0,0,0,0,0,0,0,0,0,0,0,0,23,51
65,23,0,0,74,0,74,0,0,0,0,0,0,0,0,0,0,0,0,74,0,74,0,23,51
65,1,23,23,23,23,23,23,23,23,23,23,23,23,23,23,23,23,23,23,23,23,23,75,51
65,76,76,76,76,76,76,76,76,76,76,76,76,76,76,76,76,76,76,76,76,76,76,76,76
endlayer

layer
0,0,0,0,0,0,0,0,0,0,0,0,0,0,0,0,0,0,0,0,0,0,0,0,0
0,65,30,30,30,30,30,30,30,30,30,30,30,30,30,30,30,30,30,30,30,30,30,30,0
0,65,74,0,0,74,0,0,0,0,0,0,0,0,0,0,0,0,0,0,0,0,74,51,0
0,65,74,0,0,0,0,0,0,0,0,0,0,0,0,0,0,0,0,0,0,0,0,51,0
0,65,0,0,0,0,0,0,0,0,0,0,0,0,0,0,0,0,0,0,0,0,0,51,0
0,65,0,0,0,0,0,0,0,0,0,0,0,0,0,0,0,0,0,0,0,0,74,51,0
0,65,0,0,0,0,0,0,0,0,0,0,0,0,0,0,0,0,0,0,0,0,0,51,0
0,65,74,0,0,0,0,0,0,0,0,0,0,0,0,0,0,0,0,0,0,0,0,51,0
0,65,0,0,0,0,0,0,23,23,23,23,23,23,23,23,23,0,0,0,0,0,0,51,0
0,65,0,0,0,0,0,0,23,23,23,23,23,23,23,9,23,0,0,0,0,0,0,51,0
0,65,0,0,0,0,0,0,23,23,23,23,23,23,23,23,23,0,0,0,0,0,0,51,0
0,65,0,0,0,0,0,0,23,23,23,23,23,23,23,23,23,74,0,0,0,0,0,51,0
0,65,0,0,0,0,0,0,23,23,23,23,22,23,23,23,23,0,0,0,0,0,0,51,0
0,65,0,0,0,0,0,74,23,23,23,23,23,23,23,23,23,74,0,0,0,0,0,51,0
0,65,0,0,0,0,0,0,23,23,23,23,23,23,23,23,23,0,0,0,0,0,0,51,0
0,65,0,0,0,0,0,74,23,9,23,23,23,23,23,23,23,0,0,0,0,0,0,51,0
0,65,0,0,0,0,0,0,23,23,23,23,23,23,23,23,23,0,0,0,0,0,0,51,0
0,65,0,0,0,0,0,0,0,0,0,74,0,0,0,0,0,0,0,0,0,0,0,51,0
0,65,0,0,0,0,0,0,0,0,0,0,0,0,0,0,0,0,0,0,0,0,0,51,0
0,65,0,0,0,0,0,0,0,0,0,0,0,0,0,0,0,0,0,0,0,0,0,51,0
0,65,74,0,0,0,0,0,0,0,0,0,0,0,0,0,0,0,0,0,0,0,0,51,0
0,65,0,0,0,0,0,0,0,0,0,0,0,0,0,0,0,0,0,0,74,74,74,51,0
0,65,0,0,0,0,0,0,0,0,0,0,0,0,0,0,0,0,0,0,0,0,0,51,0
0,76,76,76,76,76,76,76,76,76,76,76,76,76,76,76,76,76,76,76,76,76,76,76,0
0,0,0,0,0,0,0,0,0,0,0,0,0,0,0,0,0,0,0,0,0,0,0,0,0
endlayer

layer
0,0,0,0,0,0,0,0,0,0,0,0,0,0,0,0,0,0,0,0,0,0,0,0,0
0,0,0,0,0,0,0,0,0,0,0,0,0,0,0,0,0,0,0,0,0,0,0,0,0
0,0,65,30,30,30,30,30,30,30,30,30,30,30,30,30,30,30,30,30,30,30,30,0,0
0,0,65,23,23,23,23,23,23,23,23,23,23,23,23,23,23,23,23,23,23,23,51,0,0
0,0,65,23,23,23,23,23,23,23,23,23,23,23,23,23,23,23,23,23,23,23,51,0,0
0,0,65,23,23,23,23,23,23,23,23,23,23,23,23,23,23,23,23,23,23,23,51,0,0
0,0,65,23,23,23,23,23,23,23,23,23,23,23,23,23,23,23,23,23,23,23,51,0,0
0,0,65,23,23,23,23,23,23,23,23,23,23,23,23,23,23,23,23,23,23,23,51,0,0
0,0,65,23,23,23,23,23,23,23,23,23,23,23,23,23,23,23,23,23,23,23,51,0,0
0,0,65,23,23,23,23,23,23,23,23,23,23,23,23,23,23,23,23,23,23,23,51,0,0
0,0,65,23,23,23,23,23,23,23,23,23,23,23,23,23,23,23,23,23,23,23,51,0,0
0,0,65,23,23,23,23,23,23,23,23,23,23,23,23,23,23,23,23,23,23,23,51,0,0
0,0,65,23,23,23,23,23,23,23,23,23,23,23,23,23,23,23,23,23,23,23,51,0,0
0,0,65,23,23,23,23,23,23,23,23,23,23,23,23,23,23,23,23,23,23,23,51,0,0
0,0,65,23,23,23,23,23,23,23,23,23,23,23,23,23,23,23,23,23,23,23,51,0,0
0,0,65,23,23,23,23,23,23,23,23,23,23,23,23,23,23,23,23,23,23,23,51,0,0
0,0,65,23,23,23,23,23,23,23,23,23,23,23,23,23,23,23,23,23,23,23,51,0,0
0,0,65,23,23,23,23,23,23,23,23,23,23,23,23,23,23,23,23,23,23,23,51,0,0
0,0,65,23,23,23,23,23,23,23,23,23,23,23,23,23,23,23,23,23,23,23,51,0,0
0,0,65,23,23,23,23,23,23,23,23,23,23,23,23,23,23,23,23,23,23,23,51,0,0
0,0,65,23,23,23,23,23,23,23,23,23,23,23,23,23,23,23,23,23,23,23,51,0,0
0,0,65,23,23,23,23,23,23,23,23,23,23,23,23,23,23,23,23,23,23,23,51,0,0
0,0,76,76,76,76,76,76,76,76,76,76,76,76,76,76,76,76,76,76,76,76,76,0,0
0,0,0,0,0,0,0,0,0,0,0,0,0,0,0,0,0,0,0,0,0,0,0,0,0
0,0,0,0,0,0,0,0,0,0,0,0,0,0,0,0,0,0,0,0,0,0,0,0,0
endlayer

