
# Created by Ruins mod version 16.5 Ingame Parser
# authoring Player: ST753M

weight=2
embed_into_distance=0
acceptable_target_blocks=
unacceptable_target_blocks=flowing_water,water,flowing_lava,lava,ice,bedrock,netherrack,nether_brick,nether_brick_fence,soul_sand,quartz_ore,end_stone,obsidian,iron_bars,Natura:Cloud,slime_grass,slime_congealed,slime_dirt,clouds,natura:clouds
dimensions=54,15,15
allowable_overhang=0
max_leveling=2
leveling_buffer=0
preserve_water=0
preserve_lava=0
preserve_plants=1

biomesToSpawnIn=Roofed Forest,Roofed Forest M,Omininous Woods

=0,100,air
rule1=0,100,minecraft:cobblestone-0
rule2=0,100,minecraft:stone_stairs-0
rule3=0,100,minecraft:stone_stairs-2
rule4=0,100,minecraft:stone_stairs-3
rule5=0,100,minecraft:stone_stairs-1
rule6=0,100,minecraft:dark_oak_fence-0
rule7=0,100,minecraft:cobblestone_wall-0
rule8=0,100,minecraft:planks-5
rule9=0,100,minecraft:log-1
rule10=0,100,minecraft:planks-1
rule11=0,100,minecraft:wool-14
rule12=0,100,minecraft:log-9
rule13=0,100,minecraft:spruce_stairs-2
rule14=0,100,minecraft:spruce_stairs-7
rule15=1,100,minecraft:redstone_torch-5
rule16=0,100,minecraft:log-5
rule17=0,100,minecraft:glass_pane-0
rule18=0,100,minecraft:spruce_stairs-5
rule19=0,100,minecraft:glass_pane-0
rule20=0,100,minecraft:spruce_stairs-0
rule21=0,100,minecraft:spruce_stairs-6
rule22=0,100,minecraft:spruce_stairs-3
rule23=0,100,minecraft:spruce_stairs-4
rule24=0,100,minecraft:spruce_stairs-1
rule25=0,100,minecraft:oak_stairs-1
rule26=0,100,minecraft:fence-0
rule27=0,100,minecraft:bookshelf-0
rule28=0,100,CommandBlock:RUINSTRIGGER /summon Vindication_Illager ~0 ~0 ~0 {PersistenceRequired:1}:@
rule29=0,100,minecraft:oak_stairs-0
rule30=2,100,WallSign:null:null:null:null-4
rule31=0,100,minecraft:oak_stairs-2
rule32=2,100,WallSign:null:null:null:null-5
rule33=0,100,minecraft:carpet-14
rule34=0,100,minecraft:bed-9
rule35=0,100,minecraft:bed-1
rule36=0,100,minecraft:oak_stairs-3
rule37=0,50,ChestGenHook:chests/woodland_mansion:5-4
rule38=0,100,minecraft:stone_slab-3
rule39=0,100,minecraft:flower_pot-0
rule40=0,100,ChestGenHook:chests/woodland_mansion:5-5
rule41=0,50,minecraft:enchanting_table-0
rule42=0,100,CommandBlock:RUINSTRIGGER /summon Evocation_Illager ~0 ~0 ~0 {PersistenceRequired:1}:@
rule43=0,100,minecraft:bed-3
rule44=0,100,minecraft:bed-11
rule45=0,100,minecraft:dark_oak_stairs-4
rule46=0,100,minecraft:dark_oak_stairs-7
rule47=0,100,minecraft:dark_oak_stairs-6
rule48=0,100,minecraft:dark_oak_stairs-5

layer
1,1,2,1,2,1,2,1,2,1,2,1,2,1,1
1,1,1,1,1,1,1,1,1,1,1,1,1,1,1
4,1,1,1,1,1,1,1,1,1,1,1,1,1,3
1,1,1,1,1,1,1,1,1,1,1,1,1,1,1
4,1,1,1,1,1,1,1,1,1,1,1,1,1,3
1,1,1,1,1,1,1,1,1,1,1,1,1,1,1
4,1,1,1,1,1,1,1,1,1,1,1,1,1,3
1,1,1,1,1,1,1,1,1,1,1,1,1,1,3
4,1,1,1,1,1,1,1,1,1,1,1,1,1,3
1,1,1,1,1,1,1,1,1,1,1,1,1,1,1
4,1,1,1,1,1,1,1,1,1,1,1,1,1,3
1,1,1,1,1,1,1,1,1,1,1,1,1,1,1
4,1,1,1,1,1,1,1,1,1,1,1,1,1,3
1,1,1,1,1,1,1,1,1,1,1,1,1,1,1
1,1,5,1,5,1,5,1,5,1,5,1,5,1,1
endlayer

layer
6,7,0,0,0,0,0,0,0,0,0,0,0,7,6
7,1,8,1,7,1,7,1,7,1,7,1,8,1,7
0,8,9,1,1,1,1,1,1,1,1,1,9,8,0
0,1,1,1,1,1,1,1,1,1,1,1,1,1,0
0,7,1,1,10,10,10,10,10,10,10,1,1,7,0
0,1,1,1,10,11,11,11,11,11,10,1,1,1,7
0,7,1,1,10,11,11,11,11,11,10,1,1,3,0
0,1,1,1,10,11,11,9,11,11,10,1,1,3,0
0,7,1,1,10,11,11,11,11,11,10,1,1,3,0
0,1,1,1,10,11,11,11,11,11,10,1,1,1,7
0,7,1,1,10,10,10,10,10,10,10,1,1,7,0
0,1,1,1,1,1,1,1,1,1,1,1,1,1,0
0,8,9,1,1,1,1,1,1,1,1,1,9,8,0
7,1,8,1,7,1,7,1,7,1,7,1,8,1,7
6,7,0,0,0,0,0,0,0,0,0,0,0,7,6
endlayer

layer
6,0,0,0,0,0,0,0,0,0,0,0,0,0,6
0,1,1,1,7,7,0,0,0,7,7,1,1,1,0
0,1,9,1,8,8,8,8,8,8,8,1,9,1,0
0,1,1,0,0,0,0,0,0,0,0,0,1,1,0
0,7,8,0,0,0,0,0,0,0,0,0,8,7,0
0,7,8,0,0,0,0,0,0,0,0,0,12,7,0
0,0,8,0,0,0,14,13,0,0,0,0,0,0,0
0,0,8,0,0,0,0,9,0,0,0,0,0,0,0
0,0,8,0,0,0,0,0,0,0,0,0,0,0,0
0,7,8,0,0,0,0,0,0,0,0,0,12,7,0
0,7,8,0,0,0,0,0,0,0,0,0,8,7,0
0,1,1,0,0,0,0,0,0,0,0,0,1,1,0
0,1,9,1,8,8,8,8,8,8,8,1,9,1,0
0,1,1,1,7,7,0,0,0,7,7,1,1,1,0
6,0,0,0,0,0,0,0,0,0,0,0,0,0,6
endlayer

layer
15,0,0,0,0,0,0,0,0,0,0,0,0,0,15
0,6,1,6,0,0,0,0,0,0,0,6,1,6,0
0,1,9,1,8,16,17,17,17,16,8,1,9,1,0
0,6,1,0,0,0,0,0,0,0,0,0,1,6,0
0,0,8,0,0,0,0,0,0,0,0,0,8,0,0
0,0,12,0,0,0,0,0,0,0,0,0,12,0,0
0,0,17,0,0,0,13,0,0,0,0,0,0,0,0
0,0,17,0,0,0,18,9,0,0,0,0,0,0,0
0,0,17,0,0,0,0,0,0,0,0,0,0,0,0
0,0,12,0,0,0,0,0,0,0,0,0,12,0,0
0,0,8,0,0,0,0,0,0,0,0,0,8,0,0
0,6,1,0,0,0,0,0,0,0,0,0,1,6,0
0,1,9,1,8,16,19,19,19,16,8,1,9,1,0
0,6,1,6,0,0,0,0,0,0,0,6,1,6,0
15,0,0,0,0,0,0,0,0,0,0,0,0,0,15
endlayer

layer
0,0,0,0,0,0,0,0,0,0,0,0,0,0,0
0,6,1,6,0,0,0,0,0,0,0,6,1,6,0
0,1,9,1,8,16,17,17,17,16,8,1,9,1,0
0,6,1,0,0,0,0,0,0,0,0,0,1,6,0
0,0,8,0,0,0,0,0,0,0,0,0,8,0,0
0,0,12,0,0,0,0,0,0,0,0,0,12,0,0
0,0,17,0,0,0,0,0,0,0,0,0,0,0,0
0,0,17,0,0,0,20,9,0,0,0,0,0,0,0
0,0,17,0,0,0,18,0,0,0,0,0,0,0,0
0,0,12,0,0,0,0,0,0,0,0,0,12,0,0
0,0,8,0,0,0,0,0,0,0,0,0,8,0,0
0,6,1,0,0,0,0,0,0,0,0,0,1,6,0
0,1,9,1,8,16,19,19,19,16,8,1,9,1,0
0,6,1,6,0,0,0,0,0,0,0,6,1,6,0
0,0,0,0,0,0,0,0,0,0,0,0,0,0,0
endlayer

layer
0,0,0,0,0,0,0,0,0,0,0,0,0,0,0
0,6,1,6,0,6,0,0,0,6,0,6,1,6,0
0,1,9,1,8,16,17,17,17,16,8,1,9,1,0
0,6,1,6,0,0,0,0,0,0,0,6,1,6,0
0,0,8,0,0,0,0,0,0,0,0,0,8,0,0
0,6,12,0,0,0,0,0,0,0,0,0,12,6,0
0,0,17,0,0,0,0,0,0,0,0,0,0,0,0
0,0,17,0,0,0,0,9,0,0,0,0,0,0,0
0,0,17,0,0,0,20,21,0,0,0,0,0,0,0
0,6,12,0,0,0,0,0,0,0,0,0,12,6,0
0,0,8,0,0,0,0,0,0,0,0,0,8,0,0
0,6,1,6,0,0,0,0,0,0,0,6,1,6,0
0,1,9,1,8,16,19,19,19,16,8,1,9,1,0
0,6,1,6,0,6,0,0,0,6,0,6,1,6,0
0,0,0,0,0,0,0,0,0,0,0,0,0,0,0
endlayer

layer
0,0,0,0,0,0,0,0,0,0,0,0,0,0,0
0,6,1,6,0,6,0,0,0,6,0,6,1,6,0
0,1,9,1,8,16,17,17,17,16,8,1,9,1,0
0,6,1,15,0,0,0,0,0,0,0,15,1,6,0
0,0,8,0,0,0,0,0,0,0,0,0,8,0,0
0,6,12,0,0,0,0,0,0,0,0,0,12,6,0
0,0,17,0,0,0,0,0,0,0,0,0,0,0,0
0,0,17,0,0,0,0,9,0,0,0,0,0,0,0
0,0,17,0,0,0,0,22,21,0,0,0,0,0,0
0,6,12,0,0,0,0,0,0,0,0,0,12,6,0
0,0,8,0,0,0,0,0,0,0,0,0,8,0,0
0,6,1,15,0,0,0,0,0,0,0,15,1,6,0
0,1,9,1,8,16,19,19,19,16,8,1,9,1,0
0,6,1,6,0,6,0,0,0,6,0,6,1,6,0
0,0,0,0,0,0,0,0,0,0,0,0,0,0,0
endlayer

layer
0,0,0,0,0,0,0,0,0,0,0,0,0,0,0
0,6,1,6,0,12,12,12,12,12,0,6,1,6,0
0,1,9,1,8,16,16,16,16,16,8,1,9,1,0
0,6,1,0,0,0,0,0,0,0,0,0,1,6,0
0,0,8,0,0,0,0,0,0,0,0,0,8,0,0
0,16,12,0,0,0,0,0,0,0,0,0,12,16,0
0,16,12,0,0,0,0,0,0,0,0,0,12,16,0
0,16,12,0,0,0,0,9,23,0,0,0,12,16,0
0,16,12,0,0,0,0,0,22,0,0,0,12,16,0
0,16,12,0,0,0,0,0,0,0,0,0,12,16,0
0,0,8,0,0,0,0,0,0,0,0,0,8,0,0
0,6,1,0,0,0,0,0,0,0,0,0,1,6,0
0,1,9,1,8,16,16,16,16,16,8,1,9,1,0
0,6,1,6,6,12,12,12,12,12,0,6,1,6,0
0,0,0,0,0,0,0,0,0,0,0,0,0,0,0
endlayer

layer
0,0,0,0,0,0,0,0,0,0,0,0,0,0,0
0,6,1,6,0,0,0,0,0,0,0,6,1,6,0
0,1,9,1,8,8,8,8,8,8,8,1,9,1,0
0,6,1,0,0,0,0,0,0,0,0,0,1,6,0
0,0,8,0,0,0,0,0,0,0,0,0,8,0,0
0,0,8,0,0,0,0,0,0,0,0,0,8,0,0
0,0,8,0,0,0,0,0,23,0,0,0,8,0,0
0,0,8,0,0,0,0,9,24,0,0,0,8,0,0
0,0,8,0,0,0,0,0,0,0,0,0,8,0,0
0,0,8,0,0,0,0,0,0,0,0,0,8,0,0
0,0,8,0,0,0,0,0,0,0,0,0,8,0,0
0,6,1,0,0,0,0,0,0,0,0,0,1,6,0
0,1,9,1,8,8,8,8,8,8,8,1,9,1,0
0,6,1,6,0,0,0,0,0,0,0,6,1,6,0
0,0,0,0,0,0,0,0,0,0,0,0,0,0,0
endlayer

layer
0,0,0,0,0,0,0,0,0,0,0,0,0,0,0
0,1,1,1,7,7,7,7,7,7,7,1,1,1,0
0,1,1,1,1,1,1,1,1,1,1,1,1,1,0
0,1,1,0,0,0,0,0,0,0,0,0,1,1,0
0,7,1,0,0,0,0,0,0,0,0,0,1,7,0
0,7,1,0,0,0,0,0,0,0,0,0,1,7,0
0,7,1,0,0,0,0,14,24,0,0,0,1,7,0
0,7,1,0,0,0,0,9,0,0,0,0,1,7,0
0,7,1,0,0,0,0,0,0,0,0,0,1,7,0
0,7,1,0,0,0,0,0,0,0,0,0,1,7,0
0,7,1,0,0,0,0,0,0,0,0,0,1,7,0
0,1,1,0,0,0,0,0,0,0,0,0,1,1,0
0,1,1,1,1,1,1,1,1,1,1,1,1,1,0
0,1,1,1,7,7,7,7,7,7,7,1,1,1,0
0,0,0,0,0,0,0,0,0,0,0,0,0,0,0
endlayer

layer
0,0,0,0,0,0,0,0,0,0,0,0,0,0,0
0,1,8,1,1,1,1,1,1,1,1,1,8,1,0
0,8,1,1,1,1,1,1,1,1,1,1,1,8,0
0,1,1,1,1,1,1,1,1,1,1,1,1,1,0
0,1,1,1,1,1,1,1,1,1,1,1,1,1,0
0,1,1,1,1,1,1,1,1,1,1,1,1,1,0
0,1,1,1,1,1,14,13,0,1,1,1,1,1,0
0,1,1,1,1,1,0,9,0,1,1,1,1,1,0
0,1,1,1,1,1,0,0,0,1,1,1,1,1,0
0,1,1,1,1,1,1,1,1,1,1,1,1,1,0
0,1,1,1,1,1,1,1,1,1,1,1,1,1,0
0,1,1,1,1,1,1,1,1,1,1,1,1,1,0
0,8,1,1,1,1,1,1,1,1,1,1,1,8,0
0,1,8,1,1,1,1,1,1,1,1,1,8,1,0
0,0,0,0,0,0,0,0,0,0,0,0,0,0,0
endlayer

layer
0,0,0,0,0,0,0,0,0,0,0,0,0,0,0
0,1,8,1,7,1,7,1,7,1,7,1,8,1,0
0,8,9,1,1,1,1,1,1,1,1,1,9,8,0
0,1,1,1,1,1,1,1,1,1,1,1,1,1,0
0,7,1,1,1,1,1,1,1,1,1,1,1,7,0
0,1,1,1,1,1,1,1,1,1,1,1,1,1,0
0,7,1,1,1,1,13,0,0,1,1,1,1,7,0
0,1,1,1,1,1,18,9,0,1,1,1,1,1,0
0,7,1,1,1,1,0,0,0,1,1,1,1,7,0
0,1,1,1,1,1,1,1,1,1,1,1,1,1,0
0,7,1,1,1,1,1,1,1,1,1,1,1,7,0
0,1,1,1,1,1,1,1,1,1,1,1,1,1,0
0,8,9,1,1,1,1,1,1,1,1,1,9,8,0
0,1,8,1,7,1,7,1,7,1,7,1,8,1,0
0,0,0,0,0,0,0,0,0,0,0,0,0,0,0
endlayer

layer
0,0,0,0,0,0,0,0,0,0,0,0,0,0,0
0,1,1,1,7,7,0,0,0,7,7,1,1,1,0
0,1,9,1,8,8,8,8,8,8,8,1,9,1,0
0,1,1,27,27,26,0,0,0,0,25,25,1,1,0
0,7,8,0,0,0,28,0,28,0,26,26,8,7,0
0,7,8,30,0,0,0,0,0,0,29,29,8,7,0
0,0,8,31,0,0,0,0,0,0,25,25,8,0,0
0,0,8,31,0,0,20,9,0,0,26,26,8,0,0
0,0,8,31,0,0,18,0,0,0,29,29,8,0,0
0,7,8,32,0,0,0,0,0,0,25,25,8,7,0
0,7,8,0,0,0,28,0,28,0,26,26,8,7,0
0,1,1,27,27,26,0,0,0,0,29,29,1,1,0
0,1,9,1,8,8,8,8,8,8,8,1,9,1,0
0,1,1,1,7,7,0,0,0,7,7,1,1,1,0
0,0,0,0,0,0,0,0,0,0,0,0,0,0,0
endlayer

layer
0,0,0,0,0,0,0,0,0,0,0,0,0,0,0
0,6,1,6,0,0,0,0,0,0,0,6,1,6,0
0,1,9,1,8,16,17,17,17,16,8,1,9,1,0
0,6,1,27,27,33,0,0,0,0,0,0,1,6,0
0,0,8,0,0,0,0,0,0,0,33,33,8,0,0
0,0,12,0,0,0,0,0,0,0,0,0,12,0,0
0,0,17,0,0,0,0,0,0,0,0,0,17,0,0
0,0,17,0,0,0,0,9,0,0,33,33,17,0,0
0,0,17,0,0,0,20,21,0,0,0,0,17,0,0
0,0,12,0,0,0,0,0,0,0,0,0,12,0,0
0,0,8,0,0,0,0,0,0,0,33,33,8,0,0
0,6,1,27,27,33,0,0,0,0,0,0,1,6,0
0,1,9,1,8,16,17,17,17,16,8,1,9,1,0
0,6,1,6,0,0,0,0,0,0,0,6,1,6,0
0,0,0,0,0,0,0,0,0,0,0,0,0,0,0
endlayer

layer
0,0,0,0,0,0,0,0,0,0,0,0,0,0,0
0,6,1,6,0,0,0,0,0,0,0,6,1,6,0
0,1,9,1,8,16,17,17,17,16,8,1,9,1,0
0,6,1,27,27,0,0,0,0,0,0,0,1,6,0
0,0,8,0,0,0,0,0,0,0,0,0,8,0,0
0,0,12,0,0,0,0,0,0,0,0,0,12,0,0
0,0,17,0,0,0,0,0,0,0,0,0,17,0,0
0,0,17,0,0,0,0,9,0,0,0,0,17,0,0
0,0,17,0,0,0,0,22,21,0,0,0,17,0,0
0,0,12,0,0,0,0,0,0,0,0,0,12,0,0
0,0,8,0,0,0,0,0,0,0,0,0,8,0,0
0,6,1,27,27,0,0,0,0,0,0,0,1,6,0
0,1,9,1,8,16,17,17,17,16,8,1,9,1,0
0,6,1,6,0,0,0,0,0,0,0,6,1,6,0
0,0,0,0,0,0,0,0,0,0,0,0,0,0,0
endlayer

layer
0,0,0,0,0,0,0,0,0,0,0,0,0,0,0
0,6,1,6,0,6,0,0,0,6,0,6,1,6,0
0,1,9,1,8,16,17,17,17,16,8,1,9,1,0
0,6,1,6,0,0,0,0,0,0,0,6,1,6,0
0,0,8,0,0,0,0,0,0,0,0,0,8,0,0
0,6,12,0,0,0,0,0,0,0,0,0,12,6,0
0,0,17,0,0,0,0,0,0,0,0,0,17,0,0
0,0,17,0,0,0,0,9,23,0,0,0,17,0,0
0,0,17,0,0,0,0,0,22,0,0,0,17,0,0
0,6,12,0,0,0,0,0,0,0,0,0,12,6,0
0,0,8,0,0,0,0,0,0,0,0,0,8,0,0
0,6,1,6,0,0,0,0,0,0,0,6,1,6,0
0,1,9,1,8,16,17,17,17,16,8,1,9,1,0
0,6,1,6,0,6,0,0,0,6,0,6,1,6,0
0,0,0,0,0,0,0,0,0,0,0,0,0,0,0
endlayer

layer
0,0,0,0,0,0,0,0,0,0,0,0,0,0,0
0,6,1,6,0,6,0,0,0,6,0,6,1,6,0
0,1,9,1,8,16,17,17,17,16,8,1,9,1,0
0,6,1,15,0,0,0,0,0,0,0,15,1,6,0
0,0,8,0,0,0,0,0,0,0,0,0,8,0,0
0,6,12,0,0,0,0,0,0,0,0,0,12,6,0
0,0,17,0,0,0,0,0,23,0,0,0,17,0,0
0,0,17,0,0,0,0,9,24,0,0,0,17,0,0
0,0,17,0,0,0,0,0,0,0,0,0,17,0,0
0,6,12,0,0,0,0,0,0,0,0,0,12,6,0
0,0,8,0,0,0,0,0,0,0,0,0,8,0,0
0,6,1,15,0,0,0,0,0,0,0,15,1,6,0
0,1,9,1,8,16,17,17,17,16,8,1,9,1,0
0,6,1,6,0,6,0,0,0,6,0,6,1,6,0
0,0,0,0,0,0,0,0,0,0,0,0,0,0,0
endlayer

layer
0,0,0,0,0,0,0,0,0,0,0,0,0,0,0
0,6,1,6,0,12,12,12,12,12,0,6,1,6,0
0,1,9,1,8,16,16,16,16,16,8,1,9,1,0
0,6,1,0,0,0,0,0,0,0,0,0,1,6,0
0,0,8,0,0,0,0,0,0,0,0,0,8,0,0
0,16,12,0,0,0,0,0,0,0,0,0,12,16,0
0,16,12,0,0,0,0,14,24,0,0,0,12,16,0
0,16,12,0,0,0,0,9,0,0,0,0,12,16,0
0,16,12,0,0,0,0,0,0,0,0,0,12,16,0
0,16,12,0,0,0,0,0,0,0,0,0,12,16,0
0,0,8,0,0,0,0,0,0,0,0,0,8,0,0
0,6,1,0,0,0,0,0,0,0,0,0,1,6,0
0,1,9,1,8,16,16,16,16,16,8,1,9,1,0
0,6,1,6,6,12,12,12,12,12,0,6,1,6,0
0,0,0,0,0,0,0,0,0,0,0,0,0,0,0
endlayer

layer
0,0,0,0,0,0,0,0,0,0,0,0,0,0,0
0,6,1,6,0,0,0,0,0,0,0,6,1,6,0
0,1,9,1,8,8,8,8,8,8,8,1,9,1,0
0,6,1,0,0,0,0,0,0,0,0,0,1,6,0
0,0,8,0,0,0,0,0,0,0,0,0,8,0,0
0,0,8,0,0,0,0,0,0,0,0,0,8,0,0
0,0,8,0,0,0,14,13,0,0,0,0,8,0,0
0,0,8,0,0,0,0,9,0,0,0,0,8,0,0
0,0,8,0,0,0,0,0,0,0,0,0,8,0,0
0,0,8,0,0,0,0,0,0,0,0,0,8,0,0
0,0,8,0,0,0,0,0,0,0,0,0,8,0,0
0,6,1,0,0,0,0,0,0,0,0,0,1,6,0
0,1,9,1,8,8,8,8,8,8,8,1,9,1,0
0,6,1,6,0,0,0,0,0,0,0,6,1,6,0
0,0,0,0,0,0,0,0,0,0,0,0,0,0,0
endlayer

layer
0,0,0,0,0,0,0,0,0,0,0,0,0,0,0
0,1,1,1,7,7,7,7,7,7,7,1,1,1,0
0,1,1,1,1,1,1,1,1,1,1,1,1,1,0
0,1,1,0,0,0,0,0,0,0,0,0,1,1,0
0,7,1,0,0,0,0,0,0,0,0,0,1,7,0
0,7,1,0,0,0,0,0,0,0,0,0,1,7,0
0,7,1,0,0,0,13,0,0,0,0,0,1,7,0
0,7,1,0,0,0,18,9,0,0,0,0,1,7,0
0,7,1,0,0,0,0,0,0,0,0,0,1,7,0
0,7,1,0,0,0,0,0,0,0,0,0,1,7,0
0,7,1,0,0,0,0,0,0,0,0,0,1,7,0
0,1,1,0,0,0,0,0,0,0,0,0,1,1,0
0,1,1,1,1,1,1,1,1,1,1,1,1,1,0
0,1,1,1,7,7,7,7,7,7,7,1,1,1,0
0,0,0,0,0,0,0,0,0,0,0,0,0,0,0
endlayer

layer
0,0,0,0,0,0,0,0,0,0,0,0,0,0,0
0,1,8,1,1,1,1,1,1,1,1,1,8,1,0
0,8,1,1,1,1,1,1,1,1,1,1,1,8,0
0,1,1,1,1,1,1,1,1,1,1,1,1,1,0
0,1,1,1,1,1,1,1,1,1,1,1,1,1,0
0,1,1,1,1,1,1,1,1,1,1,1,1,1,0
0,1,1,1,1,1,0,0,0,1,1,1,1,1,0
0,1,1,1,1,1,20,9,0,1,1,1,1,1,0
0,1,1,1,1,1,18,0,0,1,1,1,1,1,0
0,1,1,1,1,1,1,1,1,1,1,1,1,1,0
0,1,1,1,1,1,1,1,1,1,1,1,1,1,0
0,1,1,1,1,1,1,1,1,1,1,1,1,1,0
0,8,1,1,1,1,1,1,1,1,1,1,1,8,0
0,1,8,1,1,1,1,1,1,1,1,1,8,1,0
0,0,0,0,0,0,0,0,0,0,0,0,0,0,0
endlayer

layer
0,0,0,0,0,0,0,0,0,0,0,0,0,0,0
0,1,8,1,7,1,7,1,7,1,7,1,8,1,0
0,8,9,1,1,1,1,1,1,1,1,1,9,8,0
0,1,1,1,1,1,1,1,1,1,1,1,1,1,0
0,7,1,1,1,1,1,1,1,1,1,1,1,7,0
0,1,1,1,1,1,1,1,1,1,1,1,1,1,0
0,7,1,1,1,1,0,0,0,1,1,1,1,7,0
0,1,1,1,1,1,0,9,0,1,1,1,1,1,0
0,7,1,1,1,1,20,21,0,1,1,1,1,7,0
0,1,1,1,1,1,1,1,1,1,1,1,1,1,0
0,7,1,1,1,1,1,1,1,1,1,1,1,7,0
0,1,1,1,1,1,1,1,1,1,1,1,1,1,0
0,8,9,1,1,1,1,1,1,1,1,1,9,8,0
0,1,8,1,7,1,7,1,7,1,7,1,8,1,0
0,0,0,0,0,0,0,0,0,0,0,0,0,0,0
endlayer

layer
0,0,0,0,0,0,0,0,0,0,0,0,0,0,0
0,1,1,1,7,7,0,0,0,7,7,1,1,1,0
0,1,9,1,8,8,8,8,8,8,8,1,9,1,0
0,1,1,26,34,34,26,9,26,34,34,26,1,1,0
0,7,8,0,35,35,0,9,0,35,35,0,8,7,0
0,7,8,0,0,0,42,9,28,0,0,0,8,7,0
0,0,8,21,0,0,0,0,0,0,0,14,8,0,0
0,0,8,21,0,0,0,9,0,0,0,14,8,0,0
0,0,8,0,0,0,0,22,21,0,0,0,8,0,0
0,7,8,0,0,0,0,0,0,0,0,0,8,7,0
0,7,8,31,26,0,0,0,0,0,26,36,8,7,0
0,1,1,27,29,0,0,37,0,0,29,27,1,1,0
0,1,9,1,8,8,8,8,8,8,8,1,9,1,0
0,1,1,1,7,7,0,0,0,7,7,1,1,1,0
0,0,0,0,0,0,0,0,0,0,0,0,0,0,0
endlayer

layer
0,0,0,0,0,0,0,0,0,0,0,0,0,0,0
0,6,1,6,0,0,0,0,0,0,0,6,1,6,0
0,1,9,1,8,16,17,17,17,16,8,1,9,1,0
0,6,1,33,0,0,33,38,33,0,0,33,1,6,0
0,0,8,0,0,0,0,38,0,0,0,0,8,0,0
0,0,12,0,0,0,0,38,0,0,0,0,12,0,0
0,0,17,0,0,0,0,0,0,0,0,39,17,0,0
0,0,17,39,0,0,0,9,23,0,0,39,17,0,0
0,0,17,0,0,0,0,0,22,0,0,0,17,0,0
0,0,12,0,0,0,0,0,0,0,0,0,12,0,0
0,0,8,0,33,0,0,0,0,0,33,0,8,0,0
0,6,1,39,0,0,0,0,0,0,0,39,1,6,0
0,1,9,1,8,16,17,17,17,16,8,1,9,1,0
0,6,1,6,0,0,0,0,0,0,0,6,1,6,0
0,0,0,0,0,0,0,0,0,0,0,0,0,0,0
endlayer

layer
0,0,0,0,0,0,0,0,0,0,0,0,0,0,0
0,6,1,6,0,0,0,0,0,0,0,6,1,6,0
0,1,9,1,8,16,17,17,17,16,8,1,9,1,0
0,6,1,0,0,0,0,0,0,0,0,0,1,6,0
0,0,8,0,0,0,0,0,0,0,0,0,8,0,0
0,0,12,0,0,0,0,0,0,0,0,0,12,0,0
0,0,17,0,0,0,0,0,23,0,0,0,17,0,0
0,0,17,0,0,0,0,9,24,0,0,0,17,0,0
0,0,17,0,0,0,0,0,0,0,0,0,17,0,0
0,0,12,0,0,0,0,0,0,0,0,0,12,0,0
0,0,8,0,0,0,0,0,0,0,0,0,8,0,0
0,6,1,0,0,0,0,0,0,0,0,0,1,6,0
0,1,9,1,8,16,17,17,17,16,8,1,9,1,0
0,6,1,6,0,0,0,0,0,0,0,6,1,6,0
0,0,0,0,0,0,0,0,0,0,0,0,0,0,0
endlayer

layer
0,0,0,0,0,0,0,0,0,0,0,0,0,0,0
0,6,1,6,0,6,0,0,0,6,0,6,1,6,0
0,1,9,1,8,16,17,17,17,16,8,1,9,1,0
0,6,1,6,0,0,0,0,0,0,0,6,1,6,0
0,0,8,0,0,0,0,0,0,0,0,0,8,0,0
0,6,12,0,0,0,0,0,0,0,0,0,12,6,0
0,0,17,0,0,0,0,14,24,0,0,0,17,0,0
0,0,17,0,0,0,0,9,0,0,0,0,17,0,0
0,0,17,0,0,0,0,0,0,0,0,0,17,0,0
0,6,12,0,0,0,0,0,0,0,0,0,12,6,0
0,0,8,0,0,0,0,0,0,0,0,0,8,0,0
0,6,1,6,0,0,0,0,0,0,0,6,1,6,0
0,1,9,1,8,16,17,17,17,16,8,1,9,1,0
0,6,1,6,0,6,0,0,0,6,0,6,1,6,0
0,0,0,0,0,0,0,0,0,0,0,0,0,0,0
endlayer

layer
0,0,0,0,0,0,0,0,0,0,0,0,0,0,0
0,6,1,6,0,6,0,0,0,6,0,6,1,6,0
0,1,9,1,8,16,17,17,17,16,8,1,9,1,0
0,6,1,15,0,0,0,0,0,0,0,15,1,6,0
0,0,8,0,0,0,0,0,0,0,0,0,8,0,0
0,6,12,0,0,0,0,0,0,0,0,0,12,6,0
0,0,17,0,0,0,14,13,0,0,0,0,17,0,0
0,0,17,0,0,0,0,9,0,0,0,0,17,0,0
0,0,17,0,0,0,0,0,0,0,0,0,17,0,0
0,6,12,0,0,0,0,0,0,0,0,0,12,6,0
0,0,8,0,0,0,0,0,0,0,0,0,8,0,0
0,6,1,15,0,0,0,0,0,0,0,15,1,6,0
0,1,9,1,8,16,17,17,17,16,8,1,9,1,0
0,6,1,6,0,6,0,0,0,6,0,6,1,6,0
0,0,0,0,0,0,0,0,0,0,0,0,0,0,0
endlayer

layer
0,0,0,0,0,0,0,0,0,0,0,0,0,0,0
0,6,1,6,0,12,12,12,12,12,0,6,1,6,0
0,1,9,1,8,16,16,16,16,16,8,1,9,1,0
0,6,1,0,0,0,0,0,0,0,0,0,1,6,0
0,0,8,0,0,0,0,0,0,0,0,0,8,0,0
0,16,12,0,0,0,0,0,0,0,0,0,12,16,0
0,16,12,0,0,0,13,0,0,0,0,0,12,16,0
0,16,12,0,0,0,18,9,0,0,0,0,12,16,0
0,16,12,0,0,0,0,0,0,0,0,0,12,16,0
0,16,12,0,0,0,0,0,0,0,0,0,12,16,0
0,0,8,0,0,0,0,0,0,0,0,0,8,0,0
0,6,1,0,0,0,0,0,0,0,0,0,1,6,0
0,1,9,1,8,16,16,16,16,16,8,1,9,1,0
0,6,1,6,6,12,12,12,12,12,0,6,1,6,0
0,0,0,0,0,0,0,0,0,0,0,0,0,0,0
endlayer

layer
0,0,0,0,0,0,0,0,0,0,0,0,0,0,0
0,6,1,6,0,0,0,0,0,0,0,6,1,6,0
0,1,9,1,8,8,8,8,8,8,8,1,9,1,0
0,6,1,0,0,0,0,0,0,0,0,0,1,6,0
0,0,8,0,0,0,0,0,0,0,0,0,8,0,0
0,0,8,0,0,0,0,0,0,0,0,0,8,0,0
0,0,8,0,0,0,0,0,0,0,0,0,8,0,0
0,0,8,0,0,0,20,9,0,0,0,0,8,0,0
0,0,8,0,0,0,18,0,0,0,0,0,8,0,0
0,0,8,0,0,0,0,0,0,0,0,0,8,0,0
0,0,8,0,0,0,0,0,0,0,0,0,8,0,0
0,6,1,0,0,0,0,0,0,0,0,0,1,6,0
0,1,9,1,8,8,8,8,8,8,8,1,9,1,0
0,6,1,6,0,0,0,0,0,0,0,6,1,6,0
0,0,0,0,0,0,0,0,0,0,0,0,0,0,0
endlayer

layer
0,0,0,0,0,0,0,0,0,0,0,0,0,0,0
0,1,1,1,7,7,7,7,7,7,7,1,1,1,0
0,1,1,1,1,1,1,1,1,1,1,1,1,1,0
0,1,1,0,0,0,0,0,0,0,0,0,1,1,0
0,7,1,0,0,0,0,0,0,0,0,0,1,7,0
0,7,1,0,0,0,0,0,0,0,0,0,1,7,0
0,7,1,0,0,0,0,0,0,0,0,0,1,7,0
0,7,1,0,0,0,0,9,0,0,0,0,1,7,0
0,7,1,0,0,0,20,21,0,0,0,0,1,7,0
0,7,1,0,0,0,0,0,0,0,0,0,1,7,0
0,7,1,0,0,0,0,0,0,0,0,0,1,7,0
0,1,1,0,0,0,0,0,0,0,0,0,1,1,0
0,1,1,1,1,1,1,1,1,1,1,1,1,1,0
0,1,1,1,7,7,7,7,7,7,7,1,1,1,0
0,0,0,0,0,0,0,0,0,0,0,0,0,0,0
endlayer

layer
0,0,0,0,0,0,0,0,0,0,0,0,0,0,0
0,1,8,1,1,1,1,1,1,1,1,1,8,1,0
0,8,1,1,1,1,1,1,1,1,1,1,1,8,0
0,1,1,1,1,1,1,1,1,1,1,1,1,1,0
0,1,1,1,1,1,1,1,1,1,1,1,1,1,0
0,1,1,1,1,1,1,1,1,1,1,1,1,1,0
0,1,1,1,1,1,0,0,0,1,1,1,1,1,0
0,1,1,1,1,1,0,9,0,1,1,1,1,1,0
0,1,1,1,1,1,0,22,21,1,1,1,1,1,0
0,1,1,1,1,1,1,1,1,1,1,1,1,1,0
0,1,1,1,1,1,1,1,1,1,1,1,1,1,0
0,1,1,1,1,1,1,1,1,1,1,1,1,1,0
0,8,1,1,1,1,1,1,1,1,1,1,1,8,0
0,1,8,1,1,1,1,1,1,1,1,1,8,1,0
0,0,0,0,0,0,0,0,0,0,0,0,0,0,0
endlayer

layer
0,0,0,0,0,0,0,0,0,0,0,0,0,0,0
0,1,8,1,7,1,7,1,7,1,7,1,8,1,0
0,8,9,1,1,1,1,1,1,1,1,1,9,8,0
0,1,1,1,1,1,1,1,1,1,1,1,1,1,0
0,7,1,1,1,1,1,1,1,1,1,1,1,7,0
0,1,1,1,1,1,1,1,1,1,1,1,1,1,0
0,7,1,1,1,1,0,0,0,1,1,1,1,7,0
0,1,1,1,1,1,0,9,23,1,1,1,1,1,0
0,7,1,1,1,1,0,0,22,1,1,1,1,7,0
0,1,1,1,1,1,1,1,1,1,1,1,1,1,0
0,7,1,1,1,1,1,1,1,1,1,1,1,7,0
0,1,1,1,1,1,1,1,1,1,1,1,1,1,0
0,8,9,1,1,1,1,1,1,1,1,1,9,8,0
0,1,8,1,7,1,7,1,7,1,7,1,8,1,0
0,0,0,0,0,0,0,0,0,0,0,0,0,0,0
endlayer

layer
0,0,0,0,0,0,0,0,0,0,0,0,0,0,0
0,1,1,1,7,7,0,0,0,7,7,1,1,1,0
0,1,9,1,8,8,8,8,8,8,8,1,9,1,0
0,1,1,27,31,26,36,7,31,26,36,27,1,1,0
0,7,8,25,0,0,0,0,0,0,0,25,8,7,0
0,7,8,26,0,28,0,0,0,28,0,26,8,7,0
0,0,8,29,0,0,0,0,23,0,0,29,8,0,0
0,0,8,7,0,0,0,9,24,0,0,7,8,0,0
0,0,8,25,0,0,0,0,0,0,0,25,8,0,0
0,7,8,26,0,28,0,0,0,28,0,26,8,7,0
0,7,8,29,0,0,0,0,0,0,0,29,8,7,0
0,1,1,27,31,26,36,7,31,26,36,27,1,1,0
0,1,9,1,8,8,8,8,8,8,8,1,9,1,0
0,1,1,1,7,7,0,0,0,7,7,1,1,1,0
0,0,0,0,0,0,0,0,0,0,0,0,0,0,0
endlayer

layer
0,0,0,0,0,0,0,0,0,0,0,0,0,0,0
0,6,1,6,0,0,0,0,0,0,0,6,1,6,0
0,1,9,1,8,16,17,17,17,16,8,1,9,1,0
0,6,1,38,0,33,0,0,0,33,0,38,1,6,0
0,0,8,0,0,0,0,0,0,0,0,0,8,0,0
0,0,12,33,0,0,0,0,0,0,0,33,12,0,0
0,0,17,0,0,0,0,14,24,0,0,0,17,0,0
0,0,17,0,0,0,0,9,0,0,0,0,17,0,0
0,0,17,0,0,0,0,0,0,0,0,0,17,0,0
0,0,12,33,0,0,0,0,0,0,0,33,12,0,0
0,0,8,0,0,0,0,0,0,0,0,0,8,0,0
0,6,1,38,0,33,0,0,0,33,0,38,1,6,0
0,1,9,1,8,16,17,17,17,16,8,1,9,1,0
0,6,1,6,0,0,0,0,0,0,0,6,1,6,0
0,0,0,0,0,0,0,0,0,0,0,0,0,0,0
endlayer

layer
0,0,0,0,0,0,0,0,0,0,0,0,0,0,0
0,6,1,6,0,0,0,0,0,0,0,6,1,6,0
0,1,9,1,8,16,17,17,17,16,8,1,9,1,0
0,6,1,0,0,0,0,0,0,0,0,0,1,6,0
0,0,8,0,0,0,0,0,0,0,0,0,8,0,0
0,0,12,0,0,0,0,0,0,0,0,0,12,0,0
0,0,17,0,0,0,14,13,0,0,0,0,17,0,0
0,0,17,0,0,0,0,9,0,0,0,0,17,0,0
0,0,17,0,0,0,0,0,0,0,0,0,17,0,0
0,0,12,0,0,0,0,0,0,0,0,0,12,0,0
0,0,8,0,0,0,0,0,0,0,0,0,8,0,0
0,6,1,0,0,0,0,0,0,0,0,0,1,6,0
0,1,9,1,8,16,17,17,17,16,8,1,9,1,0
0,6,1,6,0,0,0,0,0,0,0,6,1,6,0
0,0,0,0,0,0,0,0,0,0,0,0,0,0,0
endlayer

layer
0,0,0,0,0,0,0,0,0,0,0,0,0,0,0
0,6,1,6,0,6,0,0,0,6,0,6,1,6,0
0,1,9,1,8,16,17,17,17,16,8,1,9,1,0
0,6,1,6,0,0,0,0,0,0,0,6,1,6,0
0,0,8,0,0,0,0,0,0,0,0,0,8,0,0
0,6,12,0,0,0,0,0,0,0,0,0,12,6,0
0,0,17,0,0,0,13,0,0,0,0,0,17,0,0
0,0,17,0,0,0,18,9,0,0,0,0,17,0,0
0,0,17,0,0,0,0,0,0,0,0,0,17,0,0
0,6,12,0,0,0,0,0,0,0,0,0,12,6,0
0,0,8,0,0,0,0,0,0,0,0,0,8,0,0
0,6,1,6,0,0,0,0,0,0,0,6,1,6,0
0,1,9,1,8,16,17,17,17,16,8,1,9,1,0
0,6,1,6,0,6,0,0,0,6,0,6,1,6,0
0,0,0,0,0,0,0,0,0,0,0,0,0,0,0
endlayer

layer
0,0,0,0,0,0,0,0,0,0,0,0,0,0,0
0,6,1,6,0,6,0,0,0,6,0,6,1,6,0
0,1,9,1,8,16,17,17,17,16,8,1,9,1,0
0,6,1,15,0,0,0,0,0,0,0,15,1,6,0
0,0,8,0,0,0,0,0,0,0,0,0,8,0,0
0,6,12,0,0,0,0,0,0,0,0,0,12,6,0
0,0,17,0,0,0,0,0,0,0,0,0,17,0,0
0,0,17,0,0,0,20,9,0,0,0,0,17,0,0
0,0,17,0,0,0,18,0,0,0,0,0,17,0,0
0,6,12,0,0,0,0,0,0,0,0,0,12,6,0
0,0,8,0,0,0,0,0,0,0,0,0,8,0,0
0,6,1,15,0,0,0,0,0,0,0,15,1,6,0
0,1,9,1,8,16,17,17,17,16,8,1,9,1,0
0,6,1,6,0,6,0,0,0,6,0,6,1,6,0
0,0,0,0,0,0,0,0,0,0,0,0,0,0,0
endlayer

layer
0,0,0,0,0,0,0,0,0,0,0,0,0,0,0
0,6,1,6,0,12,12,12,12,12,0,6,1,6,0
0,1,9,1,8,16,16,16,16,16,8,1,9,1,0
0,6,1,0,0,0,0,0,0,0,0,0,1,6,0
0,0,8,0,0,0,0,0,0,0,0,0,8,0,0
0,16,12,0,0,0,0,0,0,0,0,0,12,16,0
0,16,12,0,0,0,0,0,0,0,0,0,12,16,0
0,16,12,0,0,0,0,9,0,0,0,0,12,16,0
0,16,12,0,0,0,20,21,0,0,0,0,12,16,0
0,16,12,0,0,0,0,0,0,0,0,0,12,16,0
0,0,8,0,0,0,0,0,0,0,0,0,8,0,0
0,6,1,0,0,0,0,0,0,0,0,0,1,6,0
0,1,9,1,8,16,16,16,16,16,8,1,9,1,0
0,6,1,6,6,12,12,12,12,12,0,6,1,6,0
0,0,0,0,0,0,0,0,0,0,0,0,0,0,0
endlayer

layer
0,0,0,0,0,0,0,0,0,0,0,0,0,0,0
0,6,1,6,0,0,0,0,0,0,0,6,1,6,0
0,1,9,1,8,8,8,8,8,8,8,1,9,1,0
0,6,1,0,0,0,0,0,0,0,0,0,1,6,0
0,0,8,0,0,0,0,0,0,0,0,0,8,0,0
0,0,8,0,0,0,0,0,0,0,0,0,8,0,0
0,0,8,0,0,0,0,0,0,0,0,0,8,0,0
0,0,8,0,0,0,0,9,0,0,0,0,8,0,0
0,0,8,0,0,0,0,22,21,0,0,0,8,0,0
0,0,8,0,0,0,0,0,0,0,0,0,8,0,0
0,0,8,0,0,0,0,0,0,0,0,0,8,0,0
0,6,1,0,0,0,0,0,0,0,0,0,1,6,0
0,1,9,1,8,8,8,8,8,8,8,1,9,1,0
0,6,1,6,0,0,0,0,0,0,0,6,1,6,0
0,0,0,0,0,0,0,0,0,0,0,0,0,0,0
endlayer

layer
0,0,0,0,0,0,0,0,0,0,0,0,0,0,0
0,1,1,1,7,7,7,7,7,7,7,1,1,1,0
0,1,1,1,1,1,1,1,1,1,1,1,1,1,0
0,1,1,0,0,0,0,0,0,0,0,0,1,1,0
0,7,1,0,0,0,0,0,0,0,0,0,1,7,0
0,7,1,0,0,0,0,0,0,0,0,0,1,7,0
0,7,1,0,0,0,0,0,0,0,0,0,1,7,0
0,7,1,0,0,0,0,9,23,0,0,0,1,7,0
0,7,1,0,0,0,0,0,22,0,0,0,1,7,0
0,7,1,0,0,0,0,0,0,0,0,0,1,7,0
0,7,1,0,0,0,0,0,0,0,0,0,1,7,0
0,1,1,0,0,0,0,0,0,0,0,0,1,1,0
0,1,1,1,1,1,1,1,1,1,1,1,1,1,0
0,1,1,1,7,7,7,7,7,7,7,1,1,1,0
0,0,0,0,0,0,0,0,0,0,0,0,0,0,0
endlayer

layer
0,0,0,0,0,0,0,0,0,0,0,0,0,0,0
0,1,8,1,1,1,1,1,1,1,1,1,8,1,0
0,8,1,1,1,1,1,1,1,1,1,1,1,8,0
0,1,1,1,1,1,1,1,1,1,1,1,1,1,0
0,1,1,1,1,1,1,1,1,1,1,1,1,1,0
0,1,1,1,1,1,1,1,1,1,1,1,1,1,0
0,1,1,1,1,1,0,0,23,1,1,1,1,1,0
0,1,1,1,1,1,0,9,24,1,1,1,1,1,0
0,1,1,1,1,1,0,0,0,1,1,1,1,1,0
0,1,1,1,1,1,1,1,1,1,1,1,1,1,0
0,1,1,1,1,1,1,1,1,1,1,1,1,1,0
0,1,1,1,1,1,1,1,1,1,1,1,1,1,0
0,8,1,1,1,1,1,1,1,1,1,1,1,8,0
0,1,8,1,1,1,1,1,1,1,1,1,8,1,0
0,0,0,0,0,0,0,0,0,0,0,0,0,0,0
endlayer

layer
0,0,0,0,0,0,0,0,0,0,0,0,0,0,0
0,1,8,1,7,1,7,1,7,1,7,1,8,1,0
0,8,9,1,1,1,1,1,1,1,1,1,9,8,0
0,1,1,1,1,1,1,1,1,1,1,1,1,1,0
0,7,1,1,1,1,1,1,1,1,1,1,1,7,0
0,1,1,1,1,1,1,1,1,1,1,1,1,1,0
0,7,1,1,1,1,0,14,24,1,1,1,1,7,0
0,1,1,1,1,1,0,9,0,1,1,1,1,1,0
0,7,1,1,1,1,0,0,0,1,1,1,1,7,0
0,1,1,1,1,1,1,1,1,1,1,1,1,1,0
0,7,1,1,1,1,1,1,1,1,1,1,1,7,0
0,1,1,1,1,1,1,1,1,1,1,1,1,1,0
0,8,9,1,1,1,1,1,1,1,1,1,9,8,0
0,1,8,1,7,1,7,1,7,1,7,1,8,1,0
0,0,0,0,0,0,0,0,0,0,0,0,0,0,0
endlayer

layer
0,0,0,0,0,0,0,0,0,0,0,0,0,0,0
0,1,1,1,7,7,0,0,0,7,7,1,1,1,0
0,1,9,1,8,8,8,8,8,8,8,1,9,1,0
0,1,1,31,25,36,0,18,40,0,25,25,1,1,0
0,7,8,0,0,0,0,0,0,0,26,26,8,7,0
0,7,8,26,0,0,0,0,0,0,29,29,8,7,0
0,0,8,9,0,9,9,9,0,0,0,30,8,0,0
0,0,8,30,0,0,0,9,0,0,0,36,8,0,0
0,0,8,31,0,0,0,0,0,0,0,32,8,0,0
0,7,8,32,28,0,28,27,0,41,0,27,8,7,0
0,7,8,0,43,43,28,27,42,0,0,27,8,7,0
0,1,1,26,44,44,26,27,27,27,27,27,1,1,0
0,1,9,1,8,8,8,8,8,8,8,1,9,1,0
0,1,1,1,7,7,0,0,0,7,7,1,1,1,0
0,0,0,0,0,0,0,0,0,0,0,0,0,0,0
endlayer

layer
0,0,0,0,0,0,0,0,0,0,0,0,0,0,0
0,6,1,6,0,0,0,0,0,0,0,6,1,6,0
0,1,9,1,8,16,17,17,17,16,8,1,9,1,0
0,6,1,31,25,36,0,39,0,0,0,0,1,6,0
0,0,8,0,0,0,0,0,0,0,33,33,8,0,0
0,0,12,33,0,0,0,0,0,0,0,0,12,0,0
0,0,17,38,0,38,9,9,0,0,0,0,17,0,0
0,0,17,0,0,0,0,9,0,0,0,0,17,0,0
0,0,17,0,0,0,0,0,0,0,0,0,17,0,0
0,0,12,0,0,0,0,27,0,0,0,27,12,0,0
0,0,8,0,0,0,0,27,0,0,0,27,8,0,0
0,6,1,33,0,0,33,27,27,27,27,27,1,6,0
0,1,9,1,8,16,17,17,17,16,8,1,9,1,0
0,6,1,6,0,0,0,0,0,0,0,6,1,6,0
0,0,0,0,0,0,0,0,0,0,0,0,0,0,0
endlayer

layer
0,0,0,0,0,0,0,0,0,0,0,0,0,0,0
0,6,1,6,0,0,0,0,0,0,0,6,1,6,0
0,1,9,1,8,16,17,17,17,16,8,1,9,1,0
0,6,1,31,25,36,0,0,0,0,0,0,1,6,0
0,0,8,0,0,0,0,0,0,0,0,0,8,0,0
0,0,12,0,0,0,0,0,0,0,0,0,12,0,0
0,0,17,0,0,0,38,9,0,0,0,0,17,0,0
0,0,17,0,0,0,0,9,0,0,0,0,17,0,0
0,0,17,0,0,0,0,0,0,0,0,0,17,0,0
0,0,12,0,0,0,0,33,0,0,0,33,12,0,0
0,0,8,0,0,0,0,33,0,0,0,33,8,0,0
0,6,1,0,0,0,0,33,33,33,33,33,1,6,0
0,1,9,1,8,16,17,17,17,16,8,1,9,1,0
0,6,1,6,0,0,0,0,0,0,0,6,1,6,0
0,0,0,0,0,0,0,0,0,0,0,0,0,0,0
endlayer

layer
0,0,0,0,0,0,0,0,0,0,0,0,0,0,0
0,6,1,6,0,6,0,0,0,6,0,6,1,6,0
0,1,9,1,8,16,17,17,17,16,8,1,9,1,0
0,6,1,6,0,0,0,0,0,0,0,6,1,6,0
0,0,8,0,0,0,0,0,0,0,0,0,8,0,0
0,6,12,0,0,0,0,0,0,0,0,0,12,6,0
0,0,17,0,0,0,0,38,0,0,0,0,17,0,0
0,0,17,0,0,0,0,9,0,0,0,0,17,0,0
0,0,17,0,0,0,0,0,0,0,0,0,17,0,0
0,6,12,0,0,0,0,0,0,0,0,0,12,6,0
0,0,8,0,0,0,0,0,0,0,0,0,8,0,0
0,6,1,6,0,0,0,0,0,0,0,6,1,6,0
0,1,9,1,8,16,17,17,17,16,8,1,9,1,0
0,6,1,6,0,6,0,0,0,6,0,6,1,6,0
0,0,0,0,0,0,0,0,0,0,0,0,0,0,0
endlayer

layer
0,0,0,0,0,0,0,0,0,0,0,0,0,0,0
0,6,1,6,0,6,0,0,0,6,0,6,1,6,0
0,1,9,1,8,16,17,17,17,16,8,1,9,1,0
0,6,1,15,0,0,0,0,0,0,0,15,1,6,0
0,0,8,0,0,0,0,0,0,0,0,0,8,0,0
0,6,12,0,0,0,0,0,0,0,0,0,12,6,0
0,0,17,0,0,0,0,0,0,0,0,0,17,0,0
0,0,17,0,0,0,0,9,0,0,0,0,17,0,0
0,0,17,0,0,0,0,0,0,0,0,0,17,0,0
0,6,12,0,0,0,0,0,0,0,0,0,12,6,0
0,0,8,0,0,0,0,0,0,0,0,0,8,0,0
0,6,1,15,0,0,0,0,0,0,0,15,1,6,0
0,1,9,1,8,16,17,17,17,16,8,1,9,1,0
0,6,1,6,0,6,0,0,0,6,0,6,1,6,0
0,0,0,0,0,0,0,0,0,0,0,0,0,0,0
endlayer

layer
0,0,0,0,0,0,0,0,0,0,0,0,0,0,0
0,6,1,6,0,12,12,12,12,12,0,6,1,6,0
0,1,9,1,8,16,16,16,16,16,8,1,9,1,0
0,6,1,0,0,0,0,0,0,0,0,0,1,6,0
0,0,8,0,0,0,0,0,0,0,0,0,8,0,0
0,16,12,0,0,0,0,0,0,0,0,0,12,16,0
0,16,12,0,0,0,0,0,0,0,0,0,12,16,0
0,16,12,0,0,0,0,9,0,0,0,0,12,16,0
0,16,12,0,0,0,0,0,0,0,0,0,12,16,0
0,16,12,0,0,0,0,0,0,0,0,0,12,16,0
0,0,8,0,0,0,0,0,0,0,0,0,8,0,0
0,6,1,0,0,0,0,0,0,0,0,0,1,6,0
0,1,9,1,8,16,16,16,16,16,8,1,9,1,0
0,6,1,6,6,12,12,12,12,12,0,6,1,6,0
0,0,0,0,0,0,0,0,0,0,0,0,0,0,0
endlayer

layer
0,0,0,0,0,0,0,0,0,0,0,0,0,0,0
0,6,1,6,0,0,0,0,0,0,0,6,1,6,0
0,1,9,1,8,8,8,8,8,8,8,1,9,1,0
0,6,1,0,0,0,0,0,0,0,0,0,1,6,0
0,0,8,0,0,0,0,0,0,0,0,0,8,0,0
0,0,8,0,0,0,0,0,0,0,0,0,8,0,0
0,0,8,0,0,0,0,0,0,0,0,0,8,0,0
0,0,8,0,0,0,0,9,0,0,0,0,8,0,0
0,0,8,0,0,0,0,0,0,0,0,0,8,0,0
0,0,8,0,0,0,0,0,0,0,0,0,8,0,0
0,0,8,0,0,0,0,0,0,0,0,0,8,0,0
0,6,1,0,0,0,0,0,0,0,0,0,1,6,0
0,1,9,1,8,8,8,8,8,8,8,1,9,1,0
0,6,1,6,0,0,0,0,0,0,0,6,1,6,0
0,0,0,0,0,0,0,0,0,0,0,0,0,0,0
endlayer

layer
0,0,0,0,0,0,0,0,0,0,0,0,0,0,0
0,1,1,1,7,7,7,7,7,7,7,1,1,1,0
0,1,1,1,1,1,1,1,1,1,1,1,1,1,0
0,1,1,0,0,0,0,0,0,0,0,0,1,1,0
0,7,1,0,0,0,0,0,0,0,0,0,1,7,0
0,7,1,0,0,0,0,0,0,0,0,0,1,7,0
0,7,1,0,0,0,46,45,45,0,0,0,1,7,0
0,7,1,0,0,0,46,9,47,0,0,0,1,7,0
0,7,1,0,0,0,46,48,48,0,0,0,1,7,0
0,7,1,0,0,0,0,0,0,0,0,0,1,7,0
0,7,1,0,0,0,0,0,0,0,0,0,1,7,0
0,1,1,0,0,0,0,0,0,0,0,0,1,1,0
0,1,1,1,1,1,1,1,1,1,1,1,1,1,0
0,1,1,1,7,7,7,7,7,7,7,1,1,1,0
0,0,0,0,0,0,0,0,0,0,0,0,0,0,0
endlayer

layer
0,0,0,0,0,0,0,0,0,0,0,0,0,0,0
0,1,8,1,1,1,1,1,1,1,1,1,8,1,0
0,8,1,1,1,1,1,1,1,1,1,1,1,8,0
0,1,1,1,1,1,1,1,1,1,1,1,1,1,0
0,1,1,1,1,1,1,1,1,1,1,1,1,1,0
0,1,1,1,1,1,1,1,1,1,1,1,1,1,0
0,1,1,1,1,1,1,1,1,1,1,1,1,1,0
0,1,1,1,1,1,1,1,1,1,1,1,1,1,0
0,1,1,1,1,1,1,1,1,1,1,1,1,1,0
0,1,1,1,1,1,1,1,1,1,1,1,1,1,0
0,1,1,1,1,1,1,1,1,1,1,1,1,1,0
0,1,1,1,1,1,1,1,1,1,1,1,1,1,0
0,8,1,1,1,1,1,1,1,1,1,1,1,8,0
0,1,8,1,1,1,1,1,1,1,1,1,8,1,0
0,0,0,0,0,0,0,0,0,0,0,0,0,0,0
endlayer

layer
20,20,20,20,20,20,20,20,20,20,20,20,20,20,13
22,1,1,1,1,1,1,1,1,1,1,1,1,1,13
22,1,1,1,1,1,1,1,1,1,1,1,1,1,13
22,1,1,1,1,1,1,1,1,1,1,1,1,1,13
22,1,1,1,1,1,1,1,1,1,1,1,1,1,13
22,1,1,1,1,1,1,1,1,1,1,1,1,1,13
22,1,1,1,1,1,1,1,1,1,1,1,1,1,13
22,1,1,1,1,1,1,1,1,1,1,1,1,1,13
22,1,1,1,1,1,1,1,1,1,1,1,1,1,13
22,1,1,1,1,1,1,1,1,1,1,1,1,1,13
22,1,1,1,1,1,1,1,1,1,1,1,1,1,13
22,1,1,1,1,1,1,1,1,1,1,1,1,1,13
22,1,1,1,1,1,1,1,1,1,1,1,1,1,13
22,1,1,1,1,1,1,1,1,1,1,1,1,1,13
24,24,24,24,24,24,24,24,24,24,24,24,24,24,24
endlayer

layer
0,0,0,0,0,0,0,0,0,0,0,0,0,0,0
0,22,20,20,20,20,20,20,20,20,20,20,20,20,0
0,22,1,1,1,1,1,1,1,1,1,1,1,13,0
0,22,1,1,1,1,1,1,1,1,1,1,1,13,0
0,22,1,1,1,1,1,1,1,1,1,1,1,13,0
0,22,1,1,1,1,1,1,1,1,1,1,1,13,0
0,22,1,1,1,1,1,1,1,1,1,1,1,13,0
0,22,1,1,1,1,1,1,1,1,1,1,1,13,0
0,22,1,1,1,1,1,1,1,1,1,1,1,13,0
0,22,1,1,1,1,1,1,1,1,1,1,1,13,0
0,22,1,1,1,1,1,1,1,1,1,1,1,13,0
0,22,1,1,1,1,1,1,1,1,1,1,1,13,0
0,22,1,1,1,1,1,1,1,1,1,1,1,13,0
0,22,24,24,24,24,24,24,24,24,24,24,24,13,0
0,0,0,0,0,0,0,0,0,0,0,0,0,0,0
endlayer

layer
0,0,0,0,0,0,0,0,0,0,0,0,0,0,0
0,0,0,0,0,0,0,0,0,0,0,0,0,0,0
0,0,22,20,20,20,20,20,20,20,20,20,20,0,0
0,0,22,10,10,10,10,10,10,10,10,10,13,0,0
0,0,22,10,10,10,10,10,10,10,10,10,13,0,0
0,0,22,10,10,10,10,10,10,10,10,10,13,0,0
0,0,22,10,10,10,10,10,10,10,10,10,13,0,0
0,0,22,10,10,10,10,10,10,10,10,10,13,0,0
0,0,22,10,10,10,10,10,10,10,10,10,13,0,0
0,0,22,10,10,10,10,10,10,10,10,10,13,0,0
0,0,22,10,10,10,10,10,10,10,10,10,13,0,0
0,0,22,10,10,10,10,10,10,10,10,10,13,0,0
0,0,22,24,24,24,24,24,24,24,24,24,13,0,0
0,0,0,0,0,0,0,0,0,0,0,0,0,0,0
0,0,0,0,0,0,0,0,0,0,0,0,0,0,0
endlayer

