
# Created by Ruins mod version 16.5 Ingame Parser
# authoring Player: ST753M

weight=1
embed_into_distance=1
acceptable_target_blocks=
unacceptable_target_blocks=flowing_water,water,flowing_lava,lava,ice,bedrock,netherrack,nether_brick,nether_brick_fence,soul_sand,quartz_ore,end_stone,obsidian,iron_bars,Natura:Cloud,slime_grass,slime_congealed,slime_dirt,clouds,natura:clouds
dimensions=24,15,15
allowable_overhang=1
max_leveling=2
leveling_buffer=0
preserve_water=0
preserve_lava=0

biomesToSpawnIn=Roofed Forest,Roofed Forest M,Ominous Woods

=0,100,air
rule1=0,100,minecraft:cobblestone-0
rule2=0,100,minecraft:stone_stairs-1
rule3=0,100,minecraft:cobblestone_wall-0
rule4=0,100,minecraft:log-1
rule5=0,100,minecraft:planks-1
rule6=0,100,minecraft:planks-5
rule7=0,100,minecraft:stone_stairs-3
rule8=0,100,minecraft:furnace-3
rule9=0,100,minecraft:oak_stairs-3
rule10=0,100,minecraft:fence-0
rule11=0,100,minecraft:oak_stairs-2
rule12=0,100,minecraft:spruce_stairs-1
rule13=0,100,minecraft:oak_stairs-6
rule14=0,100,minecraft:oak_stairs-4
rule15=0,100,minecraft:oak_stairs-5
rule16=0,100,minecraft:oak_stairs-7
rule17=0,100,minecraft:crafting_table-0
rule18=0,100,minecraft:log-5
rule19=0,100,minecraft:dark_oak_fence-0
rule20=0,100,minecraft:glass_pane-0
rule21=0,100,minecraft:carpet-14
rule22=0,100,minecraft:log-9
rule23=0,100,minecraft:flower_pot-0
rule24=0,100,minecraft:stone_stairs-7
rule25=0,100,minecraft:stone_slab-11
rule26=0,100,minecraft:stone_slab-3
rule27=0,100,minecraft:spruce_stairs-2
rule28=0,100,minecraft:spruce_stairs-7
rule29=1,100,minecraft:redstone_torch-5
rule30=0,100,minecraft:dark_oak_stairs-4
rule31=0,100,minecraft:dark_oak_stairs-6
rule32=0,100,minecraft:dark_oak_stairs-7
rule33=0,100,minecraft:dark_oak_stairs-5
rule34=0,100,minecraft:oak_stairs-1
rule35=0,100,minecraft:oak_stairs-0
rule36=0,100,minecraft:bookshelf-0
rule37=0,100,minecraft:spruce_fence_gate-5
rule38=0,100,minecraft:bed-3
rule39=0,100,minecraft:bed-11
rule40=0,100,CommandBlock:RUINSTRIGGER /summon Vindication_Illager ~0 ~0 ~0 {PersistenceRequired:1}:@
rule41=0,100,CommandBlock:RUINSTRIGGER /summon Evocation_Illager ~0 ~0 ~0 {PersistenceRequired:1}:@
rule42=0,100,minecraft:spruce_fence-0
rule43=0,100,minecraft:spruce_stairs-0
rule44=0,100,minecraft:spruce_stairs-3
rule45=0,100,minecraft:stained_glass-14




layer
1,1,1,1,1,1,1,1,1,1,1,1,1,1,1
1,1,1,1,1,1,1,1,1,1,1,1,1,1,1
1,1,1,1,1,1,1,1,1,1,1,1,1,1,1
1,1,1,1,1,1,1,1,1,1,1,1,1,1,1
1,1,1,1,1,1,1,1,1,1,1,1,1,1,1
1,1,1,1,1,1,1,1,1,1,1,1,1,1,1
1,1,1,1,1,1,1,1,1,1,1,1,1,1,1
1,1,1,1,1,1,1,1,1,1,1,1,1,1,1
1,1,1,1,1,1,1,1,1,1,1,1,1,1,1
1,1,1,1,1,1,1,1,1,1,1,1,1,1,1
1,1,1,1,1,1,1,1,1,1,1,1,1,1,1
1,1,1,1,1,1,1,1,1,1,1,1,1,1,1
1,1,1,1,1,1,1,1,1,1,1,1,1,1,1
1,1,1,1,1,1,1,1,1,1,1,1,1,1,1
1,1,1,1,1,1,2,2,2,1,1,1,1,1,1
endlayer

layer
1,3,0,0,0,0,0,0,0,0,0,0,0,3,1
3,1,0,1,3,1,3,1,3,1,3,1,0,1,3
0,0,4,1,1,1,1,1,1,1,1,1,4,0,0
0,1,1,5,5,5,5,5,5,1,1,5,1,1,0
0,3,1,5,5,5,5,5,5,1,1,5,1,3,0
0,1,1,5,5,5,5,5,5,1,1,5,1,1,0
0,3,1,5,5,5,5,5,5,1,1,5,1,3,0
0,1,1,5,5,5,5,5,5,5,5,5,1,1,0
0,3,1,5,5,5,5,5,5,5,5,5,1,3,0
0,1,1,5,5,5,5,5,5,5,5,5,1,1,0
0,3,1,5,5,5,5,5,5,5,5,5,1,3,0
0,1,1,5,5,5,5,5,5,5,5,5,1,1,0
0,0,4,1,1,1,1,1,1,1,1,1,4,0,0
3,1,0,1,3,1,2,2,2,1,3,1,0,1,3
1,3,0,0,0,3,0,0,0,3,0,0,0,3,1
endlayer

layer
0,0,0,0,0,0,0,0,0,0,0,0,0,0,0
0,1,1,1,3,3,0,0,0,3,3,1,1,1,0
0,1,4,1,6,6,6,6,6,6,6,1,4,1,0
0,1,1,0,0,0,0,0,0,7,1,1,1,1,0
0,3,6,0,11,10,9,0,0,0,8,1,6,3,0
0,3,6,0,0,10,0,0,0,7,1,1,6,3,0
0,0,6,0,11,10,9,0,0,0,3,12,6,0,0
0,0,6,0,0,10,0,0,0,0,0,0,6,0,0
0,0,6,0,11,10,9,0,0,0,0,0,6,0,0
0,3,6,0,0,0,0,0,0,14,13,0,6,3,0
0,3,6,0,0,0,0,0,0,16,15,0,6,3,0
0,1,1,17,17,17,0,0,0,0,0,0,1,1,0
0,1,4,1,6,18,0,0,0,18,6,1,4,1,0
0,1,1,1,3,3,0,0,0,3,3,1,1,1,0
0,0,0,0,0,0,0,0,0,0,0,0,0,0,0
endlayer

layer
0,0,0,0,0,0,0,0,0,0,0,0,0,0,0
0,19,1,19,0,0,0,0,0,0,0,19,1,19,0
0,1,4,1,6,18,20,20,20,18,6,1,4,1,0
0,19,1,0,0,0,0,0,0,0,1,1,1,19,0
0,0,6,0,0,21,0,0,0,0,0,1,6,0,0
0,0,22,0,0,21,0,0,0,0,1,12,22,0,0
0,0,20,0,0,21,0,0,0,0,3,0,20,0,0
0,0,20,0,0,21,0,0,0,0,0,0,20,0,0
0,0,20,0,0,21,0,0,0,0,0,0,20,0,0
0,0,22,0,0,0,0,0,0,0,23,0,22,0,0
0,0,6,0,0,0,0,0,0,0,0,0,6,0,0
0,19,1,0,0,0,0,0,0,0,0,0,1,19,0
0,1,4,1,6,18,0,0,0,18,6,1,4,1,0
0,19,1,19,0,0,0,0,0,0,0,19,1,19,0
0,0,0,0,0,0,0,0,0,0,0,0,0,0,0
endlayer

layer
0,0,0,0,0,0,0,0,0,0,0,0,0,0,0
0,19,1,19,0,0,0,0,0,0,0,19,1,19,0
0,1,4,1,6,18,20,20,20,18,6,1,4,1,0
0,19,1,0,0,0,0,0,0,24,1,1,1,19,0
0,0,6,0,0,0,0,0,0,25,1,12,6,0,0
0,0,22,0,0,0,0,0,0,24,1,0,22,0,0
0,0,20,0,0,0,0,0,0,0,3,0,20,0,0
0,0,20,0,0,0,0,0,0,0,0,0,20,0,0
0,0,20,0,0,0,0,0,0,0,0,0,20,0,0
0,0,22,0,0,0,0,0,0,0,0,0,22,0,0
0,0,6,0,0,0,0,0,0,0,0,0,6,0,0
0,19,1,0,0,0,0,0,0,0,0,0,1,19,0
0,1,4,1,6,18,0,0,0,18,6,1,4,1,0
0,19,1,19,0,0,0,0,0,0,0,19,1,19,0
0,0,0,0,0,0,0,0,0,0,0,0,0,0,0
endlayer

layer
0,0,0,0,0,0,0,0,0,0,0,0,0,0,0
0,19,1,19,0,19,0,0,0,19,0,19,1,19,0
0,1,4,1,6,18,20,20,20,18,6,1,4,1,0
0,19,1,0,0,0,0,0,0,0,5,12,1,19,0
0,0,6,0,0,0,0,0,0,0,1,0,6,0,0
0,19,22,0,0,0,0,0,0,0,26,0,22,19,0
0,0,20,0,0,0,0,0,0,0,26,0,20,0,0
0,0,20,0,0,0,0,0,0,0,0,0,20,0,0
0,0,20,0,0,0,0,0,0,0,0,0,20,0,0
0,19,22,0,0,0,0,0,0,0,0,0,22,19,0
0,0,6,0,0,0,0,0,0,0,0,0,6,0,0
0,19,1,0,0,0,0,0,0,0,0,0,1,19,0
0,1,4,1,6,18,19,19,19,18,6,1,4,1,0
0,19,1,19,0,19,0,0,0,19,0,19,1,19,0
0,0,0,0,0,0,0,0,0,0,0,0,0,0,0
endlayer

layer
0,0,0,0,0,0,0,0,0,0,0,0,0,0,0
0,19,1,19,0,19,0,0,0,19,0,19,1,19,0
0,1,4,1,6,18,20,20,20,18,6,1,4,1,0
0,19,1,0,0,0,0,0,0,28,27,0,1,19,0
0,0,6,0,0,0,0,0,0,0,3,0,6,0,0
0,19,22,0,0,0,0,0,0,0,0,0,22,19,0
0,0,20,0,0,0,0,19,0,0,0,0,20,0,0
0,0,20,0,0,0,19,19,19,0,0,0,20,0,0
0,0,20,0,0,0,0,19,0,0,0,0,20,0,0
0,19,22,0,0,0,0,0,0,0,0,0,22,19,0
0,0,6,0,0,0,0,0,0,0,0,0,6,0,0
0,19,1,0,0,0,0,0,0,0,0,0,1,19,0
0,1,4,1,6,18,19,19,19,18,6,1,4,1,0
0,19,1,19,0,19,0,0,0,19,0,19,1,19,0
0,0,0,0,0,0,0,0,0,0,0,0,0,0,0
endlayer

layer
0,0,0,0,0,0,0,0,0,0,0,0,0,0,0
0,19,1,19,0,22,22,22,22,22,0,19,1,19,0
0,1,4,1,6,18,18,18,18,18,6,1,4,1,0
0,19,1,0,0,0,0,0,28,27,0,0,1,19,0
0,0,6,0,0,0,0,0,0,0,3,0,6,0,0
0,18,22,0,0,0,0,0,0,0,0,0,22,18,0
0,18,22,0,0,0,0,29,0,0,0,0,22,18,0
0,18,22,0,0,0,29,19,29,0,0,0,22,18,0
0,18,22,0,0,0,0,29,0,0,0,0,22,18,0
0,18,22,0,0,0,0,0,0,0,0,0,22,18,0
0,0,6,0,0,0,0,0,0,0,0,0,6,0,0
0,19,1,0,0,0,0,0,0,0,0,0,1,19,0
0,1,4,1,6,18,18,18,18,18,6,1,4,1,0
0,19,1,19,19,22,22,22,22,22,0,19,1,19,0
0,0,0,0,0,0,0,0,0,0,0,0,0,0,0
endlayer

layer
0,0,0,0,0,0,0,0,0,0,0,0,0,0,0
0,19,1,19,0,0,0,0,0,0,0,19,1,19,0
0,1,4,1,6,6,6,6,6,6,6,1,4,1,0
0,19,1,0,0,0,0,28,27,0,0,0,1,19,0
0,0,6,0,0,0,0,0,0,0,3,0,6,0,0
0,0,6,0,0,0,0,0,0,0,0,0,6,0,0
0,0,6,0,0,0,0,0,0,0,0,0,6,0,0
0,0,6,0,0,0,0,19,0,0,0,0,6,0,0
0,0,6,0,0,0,0,0,0,0,0,0,6,0,0
0,0,6,0,0,0,0,0,0,0,0,0,6,0,0
0,0,6,0,0,0,0,0,0,0,0,0,6,0,0
0,19,1,0,0,0,0,0,0,0,0,0,1,19,0
0,1,4,1,6,6,6,6,6,6,6,1,4,1,0
0,19,1,19,0,0,0,0,0,0,0,19,1,19,0
0,0,0,0,0,0,0,0,0,0,0,0,0,0,0
endlayer

layer
0,0,0,0,0,0,0,0,0,0,0,0,0,0,0
0,1,1,1,0,0,0,0,0,0,0,1,1,1,0
0,1,1,1,1,1,1,1,1,1,1,1,1,1,0
0,1,1,0,0,0,28,27,0,0,0,0,1,1,0
0,0,1,0,0,0,0,0,0,0,3,0,1,0,0
0,0,1,0,0,0,0,0,0,0,0,0,1,0,0
0,0,1,0,0,0,0,30,0,0,0,0,1,0,0
0,0,1,0,0,0,32,6,31,0,0,0,1,0,0
0,0,1,0,0,0,0,33,0,0,0,0,1,0,0
0,0,1,0,0,0,0,0,0,0,0,0,1,0,0
0,0,1,0,0,0,0,0,0,0,0,0,1,0,0
0,1,1,0,0,0,0,0,0,0,0,0,1,1,0
0,1,1,1,1,1,1,1,1,1,1,1,1,1,0
0,1,1,1,0,0,0,0,0,0,0,1,1,1,0
0,0,0,0,0,0,0,0,0,0,0,0,0,0,0
endlayer

layer
0,0,0,0,0,0,0,0,0,0,0,0,0,0,0
0,1,0,1,1,1,1,1,1,1,1,1,0,1,0
0,0,4,1,1,22,22,22,22,22,22,22,4,0,0
0,1,1,1,1,1,27,0,0,0,0,0,18,1,0
0,1,1,1,1,1,1,1,1,1,1,1,1,1,0
0,1,1,1,1,1,1,1,1,1,1,1,1,1,0
0,1,1,1,1,1,1,1,1,1,1,1,1,1,0
0,1,1,1,1,1,1,1,1,1,1,1,1,1,0
0,1,1,1,1,1,1,1,1,1,1,1,1,1,0
0,1,1,1,1,1,1,1,1,1,1,1,1,1,0
0,1,1,1,1,1,1,1,1,1,1,1,1,1,0
0,1,1,1,1,1,1,1,1,1,1,1,1,1,0
0,0,4,1,1,1,1,1,1,1,1,1,4,0,0
0,1,0,1,1,1,1,1,1,1,1,1,0,1,0
0,0,0,0,0,0,0,0,0,0,0,0,0,0,0
endlayer

layer
0,0,0,0,0,0,0,0,0,0,0,0,0,0,0
0,1,0,1,3,1,3,1,3,1,3,1,0,1,0
0,0,4,1,1,1,1,1,1,1,1,1,4,0,0
0,1,1,5,5,27,0,0,0,0,0,0,1,1,0
0,3,1,5,5,5,5,5,5,5,5,5,1,3,0
0,1,1,5,5,5,5,5,5,5,5,5,1,1,0
0,3,1,5,5,5,5,5,5,5,5,5,1,3,0
0,1,1,5,5,5,5,5,5,5,5,5,1,1,0
0,3,1,5,5,5,5,5,5,5,5,5,1,3,0
0,1,1,5,5,5,5,5,5,5,5,5,1,1,0
0,3,1,5,5,5,5,5,5,5,5,5,1,3,0
0,1,1,5,5,5,5,5,5,5,5,5,1,1,0
0,0,4,1,1,1,1,1,1,1,1,1,4,0,0
0,1,0,1,3,1,3,1,3,1,3,1,0,1,0
0,0,0,0,0,0,0,0,0,0,0,0,0,0,0
endlayer

layer
0,0,0,0,0,0,0,0,0,0,0,0,0,0,0
0,1,1,1,3,3,0,0,0,3,3,1,1,1,0
0,1,4,1,6,6,6,6,6,6,6,1,4,1,0
0,1,1,17,0,0,0,0,0,0,0,0,1,1,0
0,3,6,17,0,19,19,19,19,19,19,19,6,3,0
0,3,6,34,0,21,21,21,21,21,0,34,6,3,0
0,0,6,10,0,0,0,0,0,0,0,10,6,0,0
0,0,6,35,0,3,36,36,36,3,0,35,6,0,0
0,0,6,4,37,4,4,4,4,4,37,4,6,0,0
0,3,6,0,0,0,0,4,0,0,0,0,6,3,0
0,3,6,0,38,38,0,4,0,38,38,0,6,3,0
0,1,1,10,39,39,10,4,10,39,39,10,1,1,0
0,1,4,1,6,6,6,6,6,6,6,1,4,1,0
0,1,1,1,3,3,0,0,0,3,3,1,1,1,0
0,0,0,0,0,0,0,0,0,0,0,0,0,0,0
endlayer

layer
0,0,0,0,0,0,0,0,0,0,0,0,0,0,0
0,19,1,19,0,0,0,0,0,0,0,19,1,19,0
0,1,4,1,6,18,20,20,20,18,6,1,4,1,0
0,19,1,0,0,0,0,0,0,0,0,0,1,19,0
0,0,6,0,0,0,0,0,0,0,0,0,6,0,0
0,0,22,0,0,0,0,0,0,0,0,0,22,0,0
0,0,20,21,0,0,0,0,0,0,0,21,20,0,0
0,0,20,0,0,3,36,36,36,3,0,0,20,0,0
0,0,20,26,0,26,26,26,26,26,0,26,20,0,0
0,0,22,0,0,0,0,26,0,0,0,0,22,0,0
0,0,6,0,0,0,0,26,0,0,0,0,6,0,0
0,19,1,21,0,0,21,26,21,0,0,21,1,19,0
0,1,4,1,6,18,20,20,20,18,6,1,4,1,0
0,19,1,19,0,0,0,0,0,0,0,19,1,19,0
0,0,0,0,0,0,0,0,0,0,0,0,0,0,0
endlayer

layer
0,0,0,0,0,0,0,0,0,0,0,0,0,0,0
0,19,1,19,0,0,0,0,0,0,0,19,1,19,0
0,1,4,1,6,18,20,20,20,18,6,1,4,1,0
0,19,1,0,0,0,0,0,0,0,0,0,1,19,0
0,0,6,0,0,0,0,0,0,0,0,0,6,0,0
0,0,22,0,0,0,0,0,0,0,0,0,22,0,0
0,0,20,0,0,0,0,0,0,0,0,0,20,0,0
0,0,20,0,0,3,36,36,36,3,0,0,20,0,0
0,0,20,0,0,0,40,41,40,0,0,0,20,0,0
0,0,22,0,0,0,0,0,0,0,0,0,22,0,0
0,0,6,0,0,0,0,0,0,0,0,0,6,0,0
0,19,1,0,0,0,0,0,0,0,0,0,1,19,0
0,1,4,1,6,18,20,20,20,18,6,1,4,1,0
0,19,1,19,0,0,0,0,0,0,0,19,1,19,0
0,0,0,0,0,0,0,0,0,0,0,0,0,0,0
endlayer

layer
0,0,0,0,0,0,0,0,0,0,0,0,0,0,0
0,19,1,19,0,19,0,0,0,19,0,19,1,19,0
0,1,4,1,6,18,20,20,20,18,6,1,4,1,0
0,19,1,0,0,0,0,0,0,0,0,0,1,19,0
0,0,6,0,0,0,0,0,0,0,0,0,6,0,0
0,19,22,0,0,0,0,0,0,0,0,0,22,19,0
0,0,20,0,0,0,0,0,0,0,0,0,20,0,0
0,0,20,0,0,26,26,26,26,26,0,0,20,0,0
0,0,20,0,0,0,0,0,0,0,0,0,20,0,0
0,19,22,0,0,0,0,0,0,0,0,0,22,19,0
0,0,6,0,0,0,0,0,0,0,0,0,6,0,0
0,19,1,0,0,0,0,0,0,0,0,0,1,19,0
0,1,4,1,6,18,20,20,20,18,6,1,4,1,0
0,19,1,19,0,19,0,0,0,19,0,19,1,19,0
0,0,0,0,0,0,0,0,0,0,0,0,0,0,0
endlayer

layer
0,0,0,0,0,0,0,0,0,0,0,0,0,0,0
0,19,1,19,0,19,0,0,0,19,0,19,1,19,0
0,1,4,1,6,18,20,20,20,18,6,1,4,1,0
0,19,1,0,0,0,0,0,0,0,0,0,1,19,0
0,0,6,0,0,0,0,0,0,0,0,0,6,0,0
0,19,22,0,0,0,0,0,0,0,0,0,22,19,0
0,0,20,0,0,0,0,0,0,0,0,0,20,0,0
0,0,20,0,0,0,0,0,0,0,0,0,20,0,0
0,0,20,0,0,0,0,0,0,0,0,0,20,0,0
0,19,22,0,0,0,0,0,0,0,0,0,22,19,0
0,0,6,0,0,0,0,0,0,0,0,0,6,0,0
0,19,1,0,0,0,0,0,0,0,0,0,1,19,0
0,1,4,1,6,18,20,20,20,18,6,1,4,1,0
0,19,1,19,0,19,0,0,0,19,0,19,1,19,0
0,0,0,0,0,0,0,0,0,0,0,0,0,0,0
endlayer

layer
0,0,0,0,0,0,0,0,0,0,0,0,0,0,0
0,19,1,19,0,22,22,22,22,22,0,19,1,19,0
0,1,4,1,6,18,18,18,18,18,6,1,4,1,0
0,19,1,0,0,0,0,0,0,0,0,0,1,19,0
0,0,6,0,0,0,0,0,0,0,0,0,6,0,0
0,18,22,0,0,0,0,0,0,0,0,0,22,18,0
0,18,22,0,0,0,0,0,0,0,0,0,22,18,0
0,18,22,0,0,0,0,0,0,0,0,0,22,18,0
0,18,22,0,0,0,0,0,0,0,0,0,22,18,0
0,18,22,0,0,0,0,0,0,0,0,0,22,18,0
0,0,6,0,0,0,0,0,0,0,0,0,6,0,0
0,19,1,0,0,0,0,0,0,0,0,0,1,19,0
0,1,4,1,6,18,18,18,18,18,6,1,4,1,0
0,19,1,19,19,22,22,22,22,22,0,19,1,19,0
0,0,0,0,0,0,0,0,0,0,0,0,0,0,0
endlayer

layer
0,0,0,0,0,0,0,0,0,0,0,0,0,0,0
0,19,1,19,0,0,0,0,0,0,0,19,1,19,0
0,1,4,1,6,6,6,6,6,6,6,1,4,1,0
0,19,1,0,0,0,0,0,0,0,0,0,1,19,0
0,0,6,0,0,0,0,0,0,0,0,0,6,0,0
0,0,6,0,0,0,0,0,0,0,0,0,6,0,0
0,0,6,0,0,0,0,42,0,0,0,0,6,0,0
0,0,6,0,0,0,42,42,42,0,0,0,6,0,0
0,0,6,0,0,0,0,42,0,0,0,0,6,0,0
0,0,6,0,0,0,0,0,0,0,0,0,6,0,0
0,0,6,0,0,0,0,0,0,0,0,0,6,0,0
0,19,1,0,0,0,0,0,0,0,0,0,1,19,0
0,1,4,1,6,6,6,6,6,6,6,1,4,1,0
0,19,1,19,0,0,0,0,0,0,0,19,1,19,0
0,0,0,0,0,0,0,0,0,0,0,0,0,0,0
endlayer

layer
0,0,0,0,0,0,0,0,0,0,0,0,0,0,0
0,1,1,1,3,1,3,1,3,1,3,1,1,1,0
0,1,1,1,1,1,1,1,1,1,1,1,1,1,0
0,1,1,0,0,0,0,0,0,0,0,0,1,1,0
0,3,1,0,0,0,0,0,0,0,0,0,1,3,0
0,1,1,0,0,0,0,0,0,0,0,0,1,1,0
0,3,1,0,0,0,0,29,0,0,0,0,1,3,0
0,1,1,0,0,0,29,42,29,0,0,0,1,1,0
0,3,1,0,0,0,0,29,0,0,0,0,1,3,0
0,1,1,0,0,0,0,0,0,0,0,0,1,1,0
0,3,1,0,0,0,0,0,0,0,0,0,1,3,0
0,1,1,0,0,0,0,0,0,0,0,0,1,1,0
0,1,1,1,1,1,1,1,1,1,1,1,1,1,0
0,1,1,1,3,1,3,1,3,1,3,1,1,1,0
0,0,0,0,0,0,0,0,0,0,0,0,0,0,0
endlayer

layer
0,0,0,0,0,0,0,0,0,0,0,0,0,0,0
0,1,0,1,1,1,1,1,1,1,1,1,0,1,0
0,0,4,22,22,22,22,22,22,22,22,22,4,0,0
0,1,18,0,0,0,0,0,0,0,0,0,18,1,0
0,1,18,0,0,0,0,0,0,0,0,0,18,1,0
0,1,18,0,0,0,0,0,0,0,0,0,18,1,0
0,1,18,0,0,0,0,0,0,0,0,0,18,1,0
0,1,18,0,0,0,0,42,0,0,0,0,18,1,0
0,1,18,0,0,0,0,0,0,0,0,0,18,1,0
0,1,18,0,0,0,0,0,0,0,0,0,18,1,0
0,1,18,0,0,0,0,0,0,0,0,0,18,1,0
0,1,18,0,0,0,0,0,0,0,0,0,18,1,0
0,0,4,22,22,22,22,22,22,22,22,22,4,0,0
0,1,0,1,1,1,1,1,1,1,1,1,0,1,0
0,0,0,0,0,0,0,0,0,0,0,0,0,0,0
endlayer

layer
43,43,43,43,43,43,43,43,43,43,43,43,43,43,27
44,1,1,1,1,1,1,1,1,1,1,1,1,1,27
44,1,1,1,1,1,1,1,1,1,1,1,1,1,27
44,1,1,5,5,5,5,18,5,5,5,5,1,1,27
44,1,1,5,5,5,5,18,5,5,5,5,1,1,27
44,1,1,5,5,45,45,18,45,45,5,5,1,1,27
44,1,1,5,5,45,45,18,45,45,5,5,1,1,27
44,1,1,22,22,22,22,18,22,22,22,22,1,1,27
44,1,1,5,5,45,45,18,45,45,5,5,1,1,27
44,1,1,5,5,45,45,18,45,45,5,5,1,1,27
44,1,1,5,5,5,5,18,5,5,5,5,1,1,27
44,1,1,5,5,5,5,18,5,5,5,5,1,1,27
44,1,1,1,1,1,1,1,1,1,1,1,1,1,27
44,1,1,1,1,1,1,1,1,1,1,1,1,1,27
44,12,12,12,12,12,12,12,12,12,12,12,12,12,27
endlayer

layer
0,0,0,0,0,0,0,0,0,0,0,0,0,0,0
0,43,43,43,43,43,43,43,43,43,43,43,43,43,0
0,44,5,5,5,5,5,5,5,5,5,5,5,27,0
0,44,5,5,5,5,5,5,5,5,5,5,5,27,0
0,44,5,5,27,12,12,12,12,12,12,5,5,27,0
0,44,5,5,27,0,0,0,0,0,44,5,5,27,0
0,44,5,5,27,0,0,0,0,0,44,5,5,27,0
0,44,5,5,27,0,0,0,0,0,44,5,5,27,0
0,44,5,5,27,0,0,0,0,0,44,5,5,27,0
0,44,5,5,27,0,0,0,0,0,44,5,5,27,0
0,44,5,5,27,43,43,43,43,43,43,5,5,27,0
0,44,5,5,5,5,5,5,5,5,5,5,5,27,0
0,44,5,5,5,5,5,5,5,5,5,5,5,27,0
0,44,12,12,12,12,12,12,12,12,12,12,12,12,0
0,0,0,0,0,0,0,0,0,0,0,0,0,0,0
endlayer

layer
0,0,0,0,0,0,0,0,0,0,0,0,0,0,0
0,0,0,0,0,0,0,0,0,0,0,0,0,0,0
0,0,43,43,43,43,43,43,43,43,43,43,27,0,0
0,0,44,12,12,12,12,12,12,12,12,44,27,0,0
0,0,44,27,0,0,0,0,0,0,0,44,27,0,0
0,0,44,27,0,0,0,0,0,0,0,44,27,0,0
0,0,44,27,0,0,0,0,0,0,0,44,27,0,0
0,0,44,27,0,0,0,0,0,0,0,44,27,0,0
0,0,44,27,0,0,0,0,0,0,0,44,27,0,0
0,0,44,27,0,0,0,0,0,0,0,44,27,0,0
0,0,44,27,0,0,0,0,0,0,0,44,27,0,0
0,0,44,27,43,43,43,43,43,43,43,44,27,0,0
0,0,44,12,12,12,12,12,12,12,12,12,27,0,0
0,0,0,0,0,0,0,0,0,0,0,0,0,0,0
0,0,0,0,0,0,0,0,0,0,0,0,0,0,0
endlayer

