
# Created by Ruins mod version 16.5 Ingame Parser
# authoring Player: ST753M

weight=1
embed_into_distance=0
acceptable_target_blocks=grass,dirt,podzol
unacceptable_target_blocks=flowing_water,water,flowing_lava,lava,ice,bedrock,netherrack,nether_brick,nether_brick_fence,soul_sand,quartz_ore,end_stone,obsidian,iron_bars,Natura:Cloud,slime_grass,slime_congealed,slime_dirt,clouds,natura:clouds
dimensions=15,15,15
allowable_overhang=0
max_leveling=2
leveling_buffer=0
preserve_water=0
preserve_lava=0


biomesToSpawnIn=roofed_forest,mutated_roofed_forest,roofed forest,roofed forest m,ominous woods

=0,100,air
rule1=0,100,minecraft:cobblestone-0
rule2=0,100,minecraft:planks-5
rule3=0,100,minecraft:log-5
rule4=0,100,minecraft:log-9
rule5=0,100,minecraft:log-1
rule6=0,100,minecraft:stone_stairs-1
rule7=0,100,minecraft:cobblestone_wall-0
rule8=0,100,minecraft:stone_stairs-0
rule9=0,100,minecraft:stone_stairs-2
rule10=0,100,minecraft:stone_stairs-3
rule11=0,100,minecraft:bookshelf-0
rule12=0,100,minecraft:spruce_stairs-1
rule13=0,100,minecraft:spruce_stairs-3
rule14=0,100,minecraft:spruce_fence-0
rule15=0,100,minecraft:spruce_stairs-2
rule16=0,100,minecraft:spruce_stairs-0
rule17=0,100,minecraft:carpet-12
rule18=0,100,minecraft:glass_pane-0
rule19=0,100,minecraft:dark_oak_fence-0
rule20=1,100,minecraft:redstone_torch-5
rule21=0,100,minecraft:stone_stairs-4
rule22=0,100,minecraft:stone_stairs-6
rule23=0,100,minecraft:stone_stairs-7
rule24=0,100,minecraft:dark_oak_stairs-4
rule25=0,100,minecraft:dark_oak_stairs-6
rule26=0,100,minecraft:dark_oak_fence-0
rule27=0,100,minecraft:dark_oak_stairs-7
rule28=0,100,minecraft:dark_oak_stairs-5
rule29=0,100,minecraft:stone_stairs-5
rule30=0,100,minecraft:wooden_slab-13
rule31=0,100,minecraft:dark_oak_stairs-2
rule32=0,100,minecraft:dark_oak_stairs-0
rule33=0,100,minecraft:dark_oak_stairs-3
rule34=0,60,ChestGenHook:chests/woodland_mansion:3-5
rule35=0,50,ChestGenHook:chests/woodland_mansion:3-3
rule36=0,30,ChestGenHook:chests/woodland_mansion:3-2
rule37=0,10,ChestGenHook:chests/woodland_mansion:3-4
rule38=0,100,minecraft:dark_oak_stairs-1

layer
1,1,1,1,1,1,1,1,1,1,1,1,1,1,1
1,1,1,1,1,1,1,1,1,1,1,1,1,1,1
1,1,1,1,1,1,1,1,1,1,1,1,1,1,1
1,1,1,2,2,2,2,2,2,2,2,2,1,1,1
1,1,1,2,3,4,3,4,3,4,3,2,1,1,1
1,1,1,2,4,3,4,3,4,3,4,2,1,1,1
1,1,1,2,3,4,3,4,3,4,3,2,1,1,1
1,1,1,2,4,3,4,5,4,3,4,2,1,1,1
1,1,1,2,3,4,3,4,3,4,3,2,1,1,1
1,1,1,2,4,3,4,3,4,3,4,2,1,1,1
1,1,1,2,3,4,3,4,3,4,3,2,1,1,1
1,1,1,2,2,2,2,2,2,2,2,2,1,1,1
1,1,1,1,1,1,4,4,4,1,1,1,1,1,1
1,1,1,1,1,1,1,1,1,1,1,1,1,1,1
1,1,1,1,1,1,6,6,6,1,1,1,1,1,1
endlayer

layer
7,1,8,1,0,8,0,8,0,8,0,1,8,1,7
1,1,1,1,1,1,1,1,1,1,1,1,1,1,1
10,1,1,1,1,1,1,1,1,1,1,1,1,1,9
1,1,1,11,0,0,0,0,0,0,0,11,1,1,1
0,1,1,0,0,12,0,0,0,12,0,0,1,1,0
10,1,1,0,15,14,13,0,15,14,13,0,1,1,9
0,1,1,0,0,16,0,0,0,16,0,0,1,1,0
10,1,1,0,0,0,0,5,0,0,0,0,1,1,9
0,1,1,0,0,12,0,0,0,12,0,0,1,1,0
10,1,1,0,15,14,13,0,15,14,13,0,1,1,9
0,1,1,0,0,16,0,0,0,16,0,0,1,1,0
1,1,1,11,0,0,0,0,0,0,0,11,1,1,1
10,1,1,1,1,3,0,0,0,3,1,1,1,1,9
1,1,1,1,1,0,0,0,0,0,1,1,1,1,1
7,1,6,1,0,0,0,0,0,0,0,1,6,1,7
endlayer

layer
7,0,0,0,0,0,0,0,0,0,0,0,0,0,7
0,1,1,1,0,0,0,0,0,0,0,1,1,1,0
0,1,5,1,2,2,2,2,2,2,2,1,5,1,0
0,1,1,11,0,0,0,0,0,0,0,11,1,1,0
0,0,2,0,0,0,0,0,0,0,0,0,2,0,0
0,0,2,0,0,17,0,0,0,17,0,0,2,0,0
0,0,2,0,0,0,0,0,0,0,0,0,2,0,0
0,0,2,0,0,0,0,5,0,0,0,0,2,0,0
0,0,2,0,0,0,0,0,0,0,0,0,2,0,0
0,0,2,0,0,17,0,0,0,17,0,0,2,0,0
0,0,2,0,0,0,0,0,0,0,0,0,2,0,0
0,1,1,11,0,0,0,0,0,0,0,11,1,1,0
0,1,5,1,2,3,0,0,0,3,2,1,5,1,0
0,1,1,1,0,0,0,0,0,0,0,1,1,1,0
7,0,0,0,0,0,0,0,0,0,0,0,0,0,7
endlayer

layer
7,0,0,0,0,0,0,0,0,0,0,0,0,0,7
0,0,7,0,0,0,0,0,0,0,0,0,7,0,0
0,7,5,1,2,3,18,18,18,3,2,1,5,7,0
0,0,1,11,0,0,0,0,0,0,0,11,1,0,0
0,0,2,0,0,0,0,0,0,0,0,0,2,0,0
0,0,4,0,0,0,0,0,0,0,0,0,4,0,0
0,0,18,0,0,0,0,0,0,0,0,0,18,0,0
0,0,18,0,0,0,0,5,0,0,0,0,18,0,0
0,0,18,0,0,0,0,0,0,0,0,0,18,0,0
0,0,4,0,0,0,0,0,0,0,0,0,4,0,0
0,0,2,0,0,0,0,0,0,0,0,0,2,0,0
0,0,1,11,0,0,0,0,0,0,0,11,1,0,0
0,7,5,1,2,3,19,19,19,3,2,1,5,7,0
0,0,7,0,0,0,0,0,0,0,0,0,7,0,0
7,0,0,0,0,0,0,0,0,0,0,0,0,0,7
endlayer

layer
20,0,0,0,0,0,0,0,0,0,0,0,0,0,20
0,0,7,0,0,0,0,0,0,0,0,0,7,0,0
0,7,5,1,2,3,18,18,18,3,2,1,5,7,0
0,0,1,19,0,0,0,0,0,0,0,19,1,0,0
0,0,2,0,0,0,0,0,0,0,0,0,2,0,0
0,0,4,0,0,0,0,0,0,0,0,0,4,0,0
0,0,18,0,0,0,0,0,0,0,0,0,18,0,0
0,0,18,0,0,0,0,5,0,0,0,0,18,0,0
0,0,18,0,0,0,0,0,0,0,0,0,18,0,0
0,0,4,0,0,0,0,0,0,0,0,0,4,0,0
0,0,2,0,0,0,0,0,0,0,0,0,2,0,0
0,0,1,19,0,0,0,0,0,0,0,19,1,0,0
0,7,5,1,2,3,4,4,4,3,2,1,5,7,0
0,0,7,0,0,0,0,0,0,0,0,0,7,0,0
20,0,0,0,0,0,0,0,0,0,0,0,0,0,20
endlayer

layer
0,0,0,0,0,0,0,0,0,0,0,0,0,0,0
0,0,7,0,0,19,0,0,0,19,0,0,7,0,0
0,7,5,1,2,3,18,18,18,3,2,1,5,7,0
0,0,1,19,0,0,0,0,0,0,0,19,1,0,0
0,0,2,0,0,0,0,0,0,0,0,0,2,0,0
0,19,4,0,0,0,0,0,0,0,0,0,4,19,0
0,0,18,0,0,0,0,0,0,0,0,0,18,0,0
0,0,18,0,0,0,0,5,0,0,0,0,18,0,0
0,0,18,0,0,0,0,0,0,0,0,0,18,0,0
0,19,4,0,0,0,0,0,0,0,0,0,4,19,0
0,0,2,0,0,0,0,0,0,0,0,0,2,0,0
0,0,1,19,0,0,0,0,0,0,0,19,1,0,0
0,7,5,1,2,3,18,18,18,3,2,1,5,7,0
0,0,7,0,0,19,0,0,0,19,0,0,7,0,0
0,0,0,0,0,0,0,0,0,0,0,0,0,0,0
endlayer

layer
0,0,0,0,0,0,0,0,0,0,0,0,0,0,0
0,0,7,0,0,19,0,0,0,19,0,0,7,0,0
0,7,5,1,2,3,18,18,18,3,2,1,5,7,0
0,0,1,19,0,0,0,0,0,0,0,19,1,0,0
0,0,2,0,0,0,0,0,0,0,0,0,2,0,0
0,19,4,0,0,0,0,0,0,0,0,0,4,19,0
0,0,18,0,0,0,0,19,0,0,0,0,18,0,0
0,0,18,0,0,0,19,5,19,0,0,0,18,0,0
0,0,18,0,0,0,0,19,0,0,0,0,18,0,0
0,19,4,0,0,0,0,0,0,0,0,0,4,19,0
0,0,2,0,0,0,0,0,0,0,0,0,2,0,0
0,0,1,19,0,0,0,0,0,0,0,19,1,0,0
0,7,5,1,2,3,18,18,18,3,2,1,5,7,0
0,0,7,0,0,19,0,0,0,19,0,0,7,0,0
0,0,0,0,0,0,0,0,0,0,0,0,0,0,0
endlayer

layer
0,0,0,0,0,0,0,0,0,0,0,0,0,0,0
0,0,7,0,0,4,4,4,4,4,0,0,7,0,0
0,7,5,1,2,3,3,3,3,3,2,1,5,7,0
0,0,1,19,0,0,0,0,0,0,0,19,1,0,0
0,0,2,0,0,0,0,0,0,0,0,0,2,0,0
0,3,4,0,0,0,0,0,0,0,0,0,4,3,0
0,3,4,0,0,0,0,20,0,0,0,0,4,3,0
0,3,4,0,0,0,20,5,20,0,0,0,4,3,0
0,3,4,0,0,0,0,20,0,0,0,0,4,3,0
0,3,4,0,0,0,0,0,0,0,0,0,4,3,0
0,0,2,0,0,0,0,0,0,0,0,0,2,0,0
0,0,1,19,0,0,0,0,0,0,0,19,1,0,0
0,7,5,1,2,3,3,3,3,3,2,1,5,7,0
0,0,7,0,0,4,4,4,4,4,0,0,7,0,0
0,0,0,0,0,0,0,0,0,0,0,0,0,0,0
endlayer

layer
0,0,0,0,0,0,0,0,0,0,0,0,0,0,0
0,1,1,1,0,0,0,0,0,0,0,1,1,1,0
0,1,5,1,2,2,2,2,2,2,2,1,5,1,0
0,1,1,19,0,0,0,0,0,0,0,19,1,1,0
0,0,2,0,0,0,0,0,0,0,0,0,2,0,0
0,0,2,0,0,0,0,0,0,0,0,0,2,0,0
0,0,2,0,0,0,0,0,0,0,0,0,2,0,0
0,0,2,0,0,0,0,5,0,0,0,0,2,0,0
0,0,2,0,0,0,0,0,0,0,0,0,2,0,0
0,0,2,0,0,0,0,0,0,0,0,0,2,0,0
0,0,2,0,0,0,0,0,0,0,0,0,2,0,0
0,1,1,19,0,0,0,0,0,0,0,19,1,1,0
0,1,5,1,2,2,2,2,2,2,2,1,5,1,0
0,1,1,1,0,0,0,0,0,0,0,1,1,1,0
0,0,0,0,0,0,0,0,0,0,0,0,0,0,0
endlayer

layer
0,0,0,0,0,0,0,0,0,0,0,0,0,0,0
0,1,19,1,0,21,0,21,0,21,0,1,19,1,0
0,19,5,1,1,1,1,1,1,1,1,1,5,19,0
0,1,1,19,0,0,0,0,0,0,0,19,1,1,0
0,0,1,0,0,0,0,0,0,0,0,0,1,0,0
0,23,1,0,0,0,0,0,0,0,0,0,1,22,0
0,0,1,0,0,0,0,24,0,0,0,0,1,0,0
0,23,1,0,0,0,27,26,25,0,0,0,1,22,0
0,0,1,0,0,0,0,28,0,0,0,0,1,0,0
0,23,1,0,0,0,0,0,0,0,0,0,1,22,0
0,0,1,0,0,0,0,0,0,0,0,0,1,0,0
0,1,1,19,0,0,0,0,0,0,0,19,1,1,0
0,19,5,1,1,1,1,1,1,1,1,1,5,19,0
0,1,19,1,0,29,0,29,0,29,0,1,19,1,0
0,0,0,0,0,0,0,0,0,0,0,0,0,0,0
endlayer

layer
0,0,0,0,0,0,0,0,0,0,0,0,0,0,0
0,1,1,1,21,1,21,1,21,1,21,1,1,1,0
0,1,5,4,4,4,4,4,4,4,4,4,5,1,0
0,1,3,19,0,0,3,30,3,0,0,19,3,1,0
0,23,3,0,0,0,3,30,3,0,0,0,3,22,0
0,1,3,0,0,0,3,30,3,0,0,0,3,1,0
0,23,3,4,4,4,4,4,3,4,4,4,3,22,0
0,1,3,30,30,30,3,5,3,30,30,30,3,1,0
0,23,3,4,4,4,3,4,4,4,4,4,3,22,0
0,1,3,0,0,0,3,30,3,0,0,0,3,1,0
0,23,3,0,0,0,3,30,3,0,0,0,3,22,0
0,1,3,19,0,0,3,30,3,0,0,19,3,1,0
0,1,5,4,4,4,4,4,4,4,4,4,5,1,0
0,1,1,1,29,1,29,1,29,1,29,1,1,1,0
0,0,0,0,0,0,0,0,0,0,0,0,0,0,0
endlayer

layer
32,32,32,32,32,32,32,32,32,32,32,32,32,32,31
33,1,1,1,1,1,1,1,1,1,1,1,1,1,31
33,1,2,2,2,2,2,2,2,2,2,2,2,1,31
33,1,2,19,0,0,19,34,19,0,0,19,2,1,31
33,1,2,0,0,0,0,0,0,0,0,0,2,1,31
33,1,2,0,0,0,0,0,0,0,0,0,2,1,31
33,1,2,19,0,0,0,0,0,0,0,19,2,1,31
33,1,2,36,0,0,0,5,0,0,0,35,2,1,31
33,1,2,19,0,0,0,0,0,0,0,19,2,1,31
33,1,2,0,0,0,0,0,0,0,0,0,2,1,31
33,1,2,0,0,0,0,0,0,0,0,0,2,1,31
33,1,2,19,0,0,19,37,19,0,0,19,2,1,31
33,1,2,2,2,2,2,2,2,2,2,2,2,1,31
33,1,1,1,1,1,1,1,1,1,1,1,1,1,31
33,38,38,38,38,38,38,38,38,38,38,38,38,38,31
endlayer

layer
0,0,0,0,0,0,0,0,0,0,0,0,0,0,0
0,33,32,32,32,32,32,32,32,32,32,32,32,32,0
0,33,2,2,2,2,2,2,2,2,2,2,2,31,0
0,33,2,2,0,0,19,0,19,0,0,2,2,31,0
0,33,2,0,0,0,0,0,0,0,0,0,2,31,0
0,33,2,0,0,0,0,0,0,0,0,0,2,31,0
0,33,2,19,0,0,0,0,0,0,0,19,2,31,0
0,33,2,0,0,0,0,5,0,0,0,0,2,31,0
0,33,2,19,0,0,0,0,0,0,0,19,2,31,0
0,33,2,0,0,0,0,0,0,0,0,0,2,31,0
0,33,2,0,0,0,0,0,0,0,0,0,2,31,0
0,33,2,2,0,0,19,0,19,0,0,2,2,31,0
0,33,2,2,2,2,2,2,2,2,2,2,2,31,0
0,38,38,38,38,38,38,38,38,38,38,38,38,38,0
0,0,0,0,0,0,0,0,0,0,0,0,0,0,0
endlayer

layer
0,0,0,0,0,0,0,0,0,0,0,0,0,0,0
0,0,0,0,0,0,0,0,0,0,0,0,0,0,0
0,0,32,32,32,32,32,32,32,32,32,32,32,0,0
0,0,33,2,2,25,28,28,28,27,2,2,31,0,0
0,0,33,2,30,0,0,0,0,0,30,2,31,0,0
0,0,33,28,0,0,0,0,0,0,0,28,31,0,0
0,0,33,25,0,0,0,24,0,0,0,27,31,0,0
0,0,33,25,0,0,27,5,25,0,0,27,31,0,0
0,0,33,25,0,0,0,28,0,0,0,27,31,0,0
0,0,33,24,0,0,0,0,0,0,0,24,31,0,0
0,0,33,2,30,0,0,0,0,0,30,2,31,0,0
0,0,33,2,2,25,24,24,24,27,2,2,31,0,0
0,0,38,38,38,38,38,38,38,38,38,38,31,0,0
0,0,0,0,0,0,0,0,0,0,0,0,0,0,0
0,0,0,0,0,0,0,0,0,0,0,0,0,0,0
endlayer

layer
0,0,0,0,0,0,0,0,0,0,0,0,0,0,0
0,0,0,0,0,0,0,0,0,0,0,0,0,0,0
0,0,0,0,0,0,0,0,0,0,0,0,0,0,0
0,0,0,33,32,32,32,32,32,32,32,31,0,0,0
0,0,0,33,2,2,2,2,2,2,2,31,0,0,0
0,0,0,33,2,2,2,2,2,2,2,31,0,0,0
0,0,0,33,2,2,2,2,2,2,2,31,0,0,0
0,0,0,33,2,2,2,2,2,2,2,31,0,0,0
0,0,0,33,2,2,2,2,2,2,2,31,0,0,0
0,0,0,33,2,2,2,2,2,2,2,31,0,0,0
0,0,0,33,2,2,2,2,2,2,2,31,0,0,0
0,0,0,38,38,38,38,38,38,38,38,38,0,0,0
0,0,0,0,0,0,0,0,0,0,0,0,0,0,0
0,0,0,0,0,0,0,0,0,0,0,0,0,0,0
0,0,0,0,0,0,0,0,0,0,0,0,0,0,0
endlayer

