
# Created by Ruins mod version 16.5 Ingame Parser
# authoring Player: ST753M

weight=1
embed_into_distance=0
acceptable_target_blocks=grass,dirt,podzol
unacceptable_target_blocks=flowing_water,water,flowing_lava,lava,ice,bedrock,netherrack,nether_brick,nether_brick_fence,soul_sand,quartz_ore,end_stone,obsidian,iron_bars,Natura:Cloud,slime_grass,slime_congealed,slime_dirt,clouds,natura:clouds
dimensions=18,15,15
allowable_overhang=0
max_leveling=2
leveling_buffer=0
preserve_water=0
preserve_lava=0
preventRotation=1


biomesToSpawnIn=roofed_forest,mutated_roofed_forest,roofed forest,roofed forest m,ominous woods

=0,100,air
rule1=0,100,minecraft:cobblestone-0
rule2=0,100,minecraft:stone_stairs-3
rule3=0,100,minecraft:stone_stairs-0
rule4=0,100,minecraft:stone_stairs-2
rule5=0,100,minecraft:planks-5
rule6=0,100,minecraft:stone_stairs-1
rule7=0,100,minecraft:cobblestone_wall-0
rule8=0,100,minecraft:dark_oak_fence-0
rule9=0,100,minecraft:dark_oak_door-0
rule10=0,100,minecraft:ladder-5
rule11=0,100,minecraft:bookshelf-0
rule12=0,100,minecraft:ladder-3
rule13=0,100,minecraft:ladder-2
rule14=0,100,minecraft:dark_oak_door-1
rule15=0,100,minecraft:enchanting_table-0
rule16=0,100,minecraft:dark_oak_door-3
rule17=0,100,minecraft:ladder-4
rule18=0,100,minecraft:dark_oak_door-2
rule19=0,100,minecraft:log-1
rule20=0,100,minecraft:dark_oak_door-9
rule21=0,100,minecraft:wooden_slab-5
rule22=0,100,minecraft:dark_oak_door-8
rule23=0,100,minecraft:wooden_slab-13
rule24=0,100,minecraft:log-9
rule25=0,100,minecraft:log-5
rule26=1,100,minecraft:redstone_torch-5
rule27=0,100,minecraft:redstone_lamp-0
rule28=0,100,minecraft:stone_stairs-4
rule29=0,100,minecraft:stone_stairs-6
rule30=0,100,minecraft:stone_stairs-7
rule31=0,100,minecraft:web-0
rule32=0,100,minecraft:stone_stairs-5
rule33=0,100,minecraft:dark_oak_stairs-2
rule34=0,100,minecraft:dark_oak_stairs-0
rule35=0,100,minecraft:dark_oak_stairs-3
rule36=0,100,minecraft:dark_oak_stairs-1
rule37=0,100,minecraft:dark_oak_stairs-7
rule38=0,100,minecraft:dark_oak_stairs-5
rule39=0,100,minecraft:dark_oak_stairs-6
rule40=0,100,minecraft:dark_oak_stairs-4
rule41=0,50,MobSpawner:Spider,MobSpawner:Bat

layer
1,1,1,1,1,1,4,3,2,1,1,1,1,1,1
1,1,1,1,1,1,1,1,1,1,1,1,1,1,1
1,1,1,1,1,1,1,1,1,1,1,1,1,1,1
1,1,1,5,5,1,1,1,1,1,5,5,1,1,1
1,1,1,5,5,1,1,1,1,1,5,5,1,1,1
1,1,1,1,1,5,5,5,5,5,1,1,1,1,1
6,1,1,1,1,5,5,5,5,5,1,1,1,1,6
2,1,1,1,1,5,5,5,5,5,1,1,1,1,4
3,1,1,1,1,5,5,5,5,5,1,1,1,1,3
1,1,1,1,1,5,5,5,5,5,1,1,1,1,1
1,1,1,5,5,1,1,1,1,1,5,5,1,1,1
1,1,1,5,5,1,1,1,1,1,5,5,1,1,1
1,1,1,1,1,1,1,1,1,1,1,1,1,1,1
1,1,1,1,1,1,1,1,1,1,1,1,1,1,1
1,1,1,1,1,1,4,6,2,1,1,1,1,1,1
endlayer

layer
7,1,3,1,0,0,0,0,0,0,0,1,3,1,7
1,1,1,1,3,1,8,0,8,1,3,1,1,1,1
2,1,1,1,1,1,1,9,1,1,1,1,1,1,4
1,1,1,1,1,4,10,0,10,2,1,1,1,1,1
0,2,1,1,1,4,0,0,0,2,1,1,1,4,0
0,1,1,6,6,11,11,11,11,11,6,6,1,1,0
0,8,1,13,0,11,0,0,0,11,0,12,1,8,0
0,0,16,0,0,11,0,15,0,11,0,0,14,0,0
0,8,1,13,0,11,0,0,0,11,0,12,1,8,0
0,1,1,3,3,11,11,11,11,11,3,3,1,1,0
0,2,1,1,1,4,0,0,0,2,1,1,1,4,0
1,1,1,1,1,4,17,0,17,2,1,1,1,1,1
2,1,1,1,1,1,1,18,1,1,1,1,1,1,4
1,1,1,1,6,1,8,0,8,1,6,1,1,1,1
7,1,6,1,0,0,0,0,0,0,0,1,6,1,7
endlayer

layer
7,0,0,0,0,0,0,0,0,0,0,0,0,0,7
0,1,1,1,0,0,8,0,8,0,0,1,1,1,0
0,1,19,1,5,5,5,20,5,5,5,1,19,1,0
0,1,1,11,0,0,10,0,10,0,0,11,1,1,0
0,0,5,0,0,0,0,0,0,0,0,0,5,0,0
0,0,5,0,0,21,21,21,21,21,0,0,5,0,0
0,8,5,13,0,21,0,0,0,21,0,12,5,8,0
0,0,22,0,0,21,0,0,0,21,0,0,22,0,0
0,8,5,13,0,21,0,0,0,21,0,12,5,8,0
0,0,5,0,0,21,21,21,21,21,0,0,5,0,0
0,0,5,0,0,0,0,0,0,0,0,0,5,0,0
0,1,1,11,0,0,17,0,17,0,0,11,1,1,0
0,1,19,1,5,5,5,20,5,5,5,1,19,1,0
0,1,1,1,0,0,8,0,8,0,0,1,1,1,0
7,0,0,0,0,0,0,0,0,0,0,0,0,0,7
endlayer

layer
7,0,0,0,0,23,23,23,23,23,0,0,0,0,7
0,0,7,0,0,24,24,24,24,24,0,0,7,0,0
0,7,19,1,5,25,24,24,24,25,5,1,19,7,0
0,0,1,11,0,0,10,0,10,0,0,11,1,0,0
0,0,5,0,0,0,0,0,0,0,0,0,5,0,0
23,25,24,0,0,0,0,0,0,0,0,0,24,25,23
23,25,25,13,0,0,0,0,0,0,0,12,25,25,23
23,25,25,0,0,0,0,0,0,0,0,0,25,25,23
23,25,25,13,0,0,0,0,0,0,0,12,25,25,23
23,25,24,0,0,0,0,0,0,0,0,0,24,25,23
0,0,5,0,0,0,0,0,0,0,0,0,5,0,0
0,0,1,11,0,0,17,0,17,0,0,11,1,0,0
0,7,19,1,5,25,24,24,24,25,5,1,19,7,0
0,0,7,0,0,24,24,24,24,24,0,0,7,0,0
7,0,0,0,0,23,23,23,23,23,0,0,0,0,7
endlayer

layer
26,0,0,0,0,8,8,8,8,8,0,0,0,0,26
0,0,7,0,0,8,0,0,0,8,0,0,7,0,0
0,7,19,1,5,19,0,0,0,19,5,1,19,7,0
0,0,1,11,0,0,0,0,0,0,0,11,1,0,0
0,0,5,0,0,0,0,0,0,0,0,0,5,0,0
8,8,19,0,0,0,0,0,0,0,0,0,19,8,8
8,0,0,0,0,0,0,0,0,0,0,0,0,0,8
8,0,0,0,0,0,0,0,0,0,0,0,0,0,8
8,0,0,0,0,0,0,0,0,0,0,0,0,0,8
8,8,19,0,0,0,0,0,0,0,0,0,19,8,8
0,0,5,0,0,0,0,0,0,0,0,0,5,0,0
0,0,1,11,0,0,0,0,0,0,0,11,1,0,0
0,7,19,1,5,19,0,0,0,19,5,1,19,7,0
0,0,7,0,0,8,0,0,0,8,0,0,7,0,0
26,0,0,0,0,8,8,8,8,8,0,0,0,0,26
endlayer

layer
0,0,0,0,0,0,0,0,0,0,0,0,0,0,0
0,0,7,0,0,8,0,0,0,8,0,0,7,0,0
0,7,19,1,5,19,0,0,0,19,5,1,19,7,0
0,0,1,11,0,0,0,0,0,0,0,11,1,0,0
0,0,5,0,0,0,0,0,0,0,0,0,5,0,0
0,8,19,0,0,0,0,0,0,0,0,0,19,8,0
0,0,0,0,0,0,0,0,0,0,0,0,0,0,0
0,0,0,0,0,0,0,8,0,0,0,0,0,0,0
0,0,0,0,0,0,0,0,0,0,0,0,0,0,0
0,8,19,0,0,0,0,0,0,0,0,0,19,8,0
0,0,5,0,0,0,0,0,0,0,0,0,5,0,0
0,0,1,11,0,0,0,0,0,0,0,11,1,0,0
0,7,19,1,5,19,0,0,0,19,5,1,19,7,0
0,0,7,0,0,8,0,0,0,8,0,0,7,0,0
0,0,0,0,0,0,0,0,0,0,0,0,0,0,0
endlayer

layer
0,0,0,0,0,0,0,0,0,0,0,0,0,0,0
0,0,7,0,0,8,0,0,0,8,0,0,7,0,0
0,7,19,1,5,19,8,8,8,19,5,1,19,7,0
0,0,1,11,0,0,0,0,0,0,0,11,1,0,0
0,0,5,0,0,0,0,0,0,0,0,0,5,0,0
0,8,19,0,0,0,0,8,0,0,0,0,19,8,0
0,0,8,0,0,0,8,8,8,0,0,0,8,0,0
0,0,8,0,0,8,8,27,8,8,0,0,8,0,0
0,0,8,0,0,0,8,8,8,0,0,0,8,0,0
0,8,19,0,0,0,0,8,0,0,0,0,19,8,0
0,0,5,0,0,0,0,0,0,0,0,0,5,0,0
0,0,1,11,0,0,0,0,0,0,0,11,1,0,0
0,7,19,1,5,19,8,8,8,19,5,1,19,7,0
0,0,7,0,0,8,0,0,0,8,0,0,7,0,0
0,0,0,0,0,0,0,0,0,0,0,0,0,0,0
endlayer

layer
0,0,0,0,0,0,0,0,0,0,0,0,0,0,0
0,0,7,0,0,24,24,24,24,24,0,0,7,0,0
0,7,19,1,5,25,24,24,24,25,5,1,19,7,0
0,0,1,11,0,0,0,0,0,0,0,11,1,0,0
0,0,5,0,0,0,0,0,0,0,0,0,5,0,0
0,25,24,0,0,0,0,26,0,0,0,0,24,25,0
0,25,25,0,0,0,8,0,8,0,0,0,25,25,0
0,25,25,0,0,26,0,8,0,26,0,0,25,25,0
0,25,25,0,0,0,8,0,8,0,0,0,25,25,0
0,25,24,0,0,0,0,26,0,0,0,0,24,25,0
0,0,5,0,0,0,0,0,0,0,0,0,5,0,0
0,0,1,11,0,0,0,0,0,0,0,11,1,0,0
0,7,19,1,5,25,24,24,24,25,5,1,19,7,0
0,0,7,0,0,24,24,24,24,24,0,0,7,0,0
0,0,0,0,0,0,0,0,0,0,0,0,0,0,0
endlayer

layer
0,0,0,0,0,0,0,0,0,0,0,0,0,0,0
0,1,3,1,0,0,0,0,0,0,0,1,3,1,0
0,2,19,1,5,5,5,5,5,5,5,1,19,4,0
0,1,1,11,0,0,0,0,0,0,0,11,1,1,0
0,0,5,0,0,0,0,0,0,0,0,0,5,0,0
0,0,5,0,0,0,0,0,0,0,0,0,5,0,0
0,0,5,0,0,0,26,0,26,0,0,0,5,0,0
0,0,5,0,0,0,0,8,0,0,0,0,5,0,0
0,0,5,0,0,0,26,0,26,0,0,0,5,0,0
0,0,5,0,0,0,0,0,0,0,0,0,5,0,0
0,0,5,0,0,0,0,0,0,0,0,0,5,0,0
0,1,1,11,0,0,0,0,0,0,0,11,1,1,0
0,2,19,1,5,5,5,5,5,5,5,1,19,4,0
0,1,6,1,0,0,0,0,0,0,0,1,6,1,0
0,0,0,0,0,0,0,0,0,0,0,0,0,0,0
endlayer

layer
0,0,0,0,0,0,0,0,0,0,0,0,0,0,0
0,7,0,7,0,0,0,0,0,0,0,7,0,7,0
0,0,19,1,1,1,1,1,1,1,1,1,19,0,0
0,7,1,0,0,0,0,0,0,0,0,0,1,7,0
0,0,1,0,0,0,0,0,0,0,0,0,1,0,0
0,0,1,0,0,0,0,0,0,0,0,0,1,0,0
0,0,1,0,0,0,0,0,0,0,0,0,1,0,0
0,0,1,0,0,0,0,8,0,0,0,0,1,0,0
0,0,1,0,0,0,0,0,0,0,0,0,1,0,0
0,0,1,0,0,0,0,0,0,0,0,0,1,0,0
0,0,1,0,0,0,0,0,0,0,0,0,1,0,0
0,7,1,0,0,0,0,0,0,0,0,0,1,7,0
0,0,19,1,1,1,1,1,1,1,1,1,19,0,0
0,7,0,7,0,0,0,0,0,0,0,7,0,7,0
0,0,0,0,0,0,0,0,0,0,0,0,0,0,0
endlayer

layer
0,0,0,0,0,0,0,0,0,0,0,0,0,0,0
0,1,28,1,7,1,7,1,7,1,7,1,28,1,0
0,30,19,24,24,24,24,24,24,24,24,24,19,29,0
0,1,25,0,0,25,0,0,0,25,0,0,25,1,0
0,7,25,0,0,25,0,0,0,25,0,0,25,7,0
0,1,25,24,24,24,24,24,24,25,24,24,25,1,0
0,7,25,0,0,25,0,0,0,25,0,0,25,7,0
0,1,25,0,0,25,0,8,0,25,0,0,25,1,0
0,7,25,0,31,25,0,0,0,25,0,0,25,7,0
0,1,25,24,24,25,24,24,24,24,24,24,25,1,0
0,7,25,31,0,25,0,0,0,25,0,0,25,7,0
0,1,25,0,31,25,0,0,0,25,0,0,25,1,0
0,30,19,24,24,24,24,24,24,24,24,24,19,29,0
0,1,32,1,7,1,7,1,7,1,7,1,32,1,0
0,0,0,0,0,0,0,0,0,0,0,0,0,0,0
endlayer

layer
34,34,34,34,34,34,34,34,34,34,34,34,34,34,33
35,1,1,1,1,1,1,1,1,1,1,1,1,1,33
35,1,5,5,5,5,5,5,5,5,5,5,5,1,33
35,1,5,0,0,0,0,0,0,0,0,0,5,1,33
35,1,5,0,0,0,0,0,0,0,0,0,5,1,33
35,1,5,0,0,0,0,0,0,0,0,0,5,1,33
35,1,5,0,0,0,0,0,0,0,0,0,5,1,33
35,1,5,0,0,0,0,19,0,0,0,0,5,1,33
35,1,5,0,0,0,0,0,0,0,0,0,5,1,33
35,1,5,0,0,0,0,0,0,0,0,0,5,1,33
35,1,5,0,0,0,0,0,0,0,0,0,5,1,33
35,1,5,31,0,0,0,0,0,0,0,0,5,1,33
35,1,5,5,5,5,5,5,5,5,5,5,5,1,33
35,1,1,1,1,1,1,1,1,1,1,1,1,1,33
35,36,36,36,36,36,36,36,36,36,36,36,36,36,33
endlayer

layer
0,0,0,0,0,0,0,0,0,0,0,0,0,0,0
0,35,34,34,34,34,34,34,34,34,34,34,34,34,0
0,35,5,5,5,5,5,5,5,5,5,5,5,33,0
0,35,5,0,0,0,0,0,0,0,0,0,5,33,0
0,35,5,0,0,0,0,0,0,0,0,0,5,33,0
0,35,5,0,0,0,0,0,0,0,0,0,5,33,0
0,35,5,0,0,0,0,0,0,0,0,0,5,33,0
0,35,5,0,0,0,0,19,0,0,0,0,5,33,0
0,35,5,0,0,0,0,0,0,0,0,0,5,33,0
0,35,5,0,0,0,0,0,0,0,0,0,5,33,0
0,35,5,0,0,0,0,0,0,0,0,0,5,33,0
0,35,5,0,0,0,0,0,0,31,0,31,5,33,0
0,35,5,5,5,5,5,5,5,5,5,5,5,33,0
0,36,36,36,36,36,36,36,36,36,36,36,36,36,0
0,0,0,0,0,0,0,0,0,0,0,0,0,0,0
endlayer

layer
0,0,0,0,0,0,0,0,0,0,0,0,0,0,0
0,0,0,0,0,0,0,0,0,0,0,0,0,0,0
0,0,34,34,34,34,34,34,34,34,34,34,34,0,0
0,0,35,38,38,38,38,38,38,38,38,37,33,0,0
0,0,35,39,0,0,0,0,0,0,0,37,33,0,0
0,0,35,39,0,0,0,0,0,0,0,37,33,0,0
0,0,35,39,0,0,0,0,0,0,0,37,33,0,0
0,0,35,39,0,0,0,19,0,0,0,37,33,0,0
0,0,35,39,0,0,0,0,0,0,0,37,33,0,0
0,0,35,39,0,0,0,0,0,0,0,37,33,0,0
0,0,35,39,0,0,0,0,0,0,31,37,33,0,0
0,0,35,40,40,40,40,40,40,40,40,40,33,0,0
0,0,36,36,36,36,36,36,36,36,36,36,33,0,0
0,0,0,0,0,0,0,0,0,0,0,0,0,0,0
0,0,0,0,0,0,0,0,0,0,0,0,0,0,0
endlayer

layer
0,0,0,0,0,0,0,0,0,0,0,0,0,0,0
0,0,0,0,0,0,0,0,0,0,0,0,0,0,0
0,0,0,0,0,0,0,0,0,0,0,0,0,0,0
0,0,0,35,34,34,34,34,34,34,34,33,0,0,0
0,0,0,35,38,38,38,38,38,38,38,33,0,0,0
0,0,0,35,39,0,31,0,0,0,37,33,0,0,0
0,0,0,35,39,0,0,0,0,0,37,33,0,0,0
0,0,0,35,39,0,0,19,0,0,37,33,0,0,0
0,0,0,35,39,0,0,0,0,0,37,33,0,0,0
0,0,0,35,39,0,0,0,0,0,37,33,0,0,0
0,0,0,35,39,40,40,40,40,40,40,33,0,0,0
0,0,0,35,36,36,36,36,36,36,36,33,0,0,0
0,0,0,0,0,0,0,0,0,0,0,0,0,0,0
0,0,0,0,0,0,0,0,0,0,0,0,0,0,0
0,0,0,0,0,0,0,0,0,0,0,0,0,0,0
endlayer

layer
0,0,0,0,0,0,0,0,0,0,0,0,0,0,0
0,0,0,0,0,0,0,0,0,0,0,0,0,0,0
0,0,0,0,0,0,0,0,0,0,0,0,0,0,0
0,0,0,0,0,0,0,0,0,0,0,0,0,0,0
0,0,0,0,35,34,34,34,34,34,33,0,0,0,0
0,0,0,0,35,38,38,38,38,37,33,0,0,0,0
0,0,0,0,35,39,0,31,0,37,33,0,0,0,0
0,0,0,0,35,39,31,19,0,37,33,0,0,0,0
0,0,0,0,35,39,0,0,0,37,33,0,0,0,0
0,0,0,0,35,40,40,40,40,40,33,0,0,0,0
0,0,0,0,36,36,36,36,36,36,33,0,0,0,0
0,0,0,0,0,0,0,0,0,0,0,0,0,0,0
0,0,0,0,0,0,0,0,0,0,0,0,0,0,0
0,0,0,0,0,0,0,0,0,0,0,0,0,0,0
0,0,0,0,0,0,0,0,0,0,0,0,0,0,0
endlayer

layer
0,0,0,0,0,0,0,0,0,0,0,0,0,0,0
0,0,0,0,0,0,0,0,0,0,0,0,0,0,0
0,0,0,0,0,0,0,0,0,0,0,0,0,0,0
0,0,0,0,0,0,0,0,0,0,0,0,0,0,0
0,0,0,0,0,0,0,0,0,0,0,0,0,0,0
0,0,0,0,0,35,34,34,34,34,0,0,0,0,0
0,0,0,0,0,35,5,5,5,33,0,0,0,0,0
0,0,0,0,0,35,5,41,5,33,0,0,0,0,0
0,0,0,0,0,35,5,5,5,33,0,0,0,0,0
0,0,0,0,0,36,36,36,36,36,0,0,0,0,0
0,0,0,0,0,0,0,0,0,0,0,0,0,0,0
0,0,0,0,0,0,0,0,0,0,0,0,0,0,0
0,0,0,0,0,0,0,0,0,0,0,0,0,0,0
0,0,0,0,0,0,0,0,0,0,0,0,0,0,0
0,0,0,0,0,0,0,0,0,0,0,0,0,0,0
endlayer

layer
0,0,0,0,0,0,0,0,0,0,0,0,0,0,0
0,0,0,0,0,0,0,0,0,0,0,0,0,0,0
0,0,0,0,0,0,0,0,0,0,0,0,0,0,0
0,0,0,0,0,0,0,0,0,0,0,0,0,0,0
0,0,0,0,0,0,0,0,0,0,0,0,0,0,0
0,0,0,0,0,0,0,0,0,0,0,0,0,0,0
0,0,0,0,0,0,34,34,33,0,0,0,0,0,0
0,0,0,0,0,0,35,5,33,0,0,0,0,0,0
0,0,0,0,0,0,36,36,36,0,0,0,0,0,0
0,0,0,0,0,0,0,0,0,0,0,0,0,0,0
0,0,0,0,0,0,0,0,0,0,0,0,0,0,0
0,0,0,0,0,0,0,0,0,0,0,0,0,0,0
0,0,0,0,0,0,0,0,0,0,0,0,0,0,0
0,0,0,0,0,0,0,0,0,0,0,0,0,0,0
0,0,0,0,0,0,0,0,0,0,0,0,0,0,0
endlayer

