
# Created by Ruins mod version 16.9 Ingame Parser
# authoring Player: ST753M

weight=1
embed_into_distance=2
acceptable_target_blocks=
unacceptable_target_blocks=flowing_water,water,flowing_lava,lava,ice,bedrock,netherrack,nether_brick,nether_brick_fence,soul_sand,quartz_ore,end_stone,obsidian,iron_bars,Natura:Cloud,slime_grass,slime_congealed,slime_dirt,clouds,natura:clouds
dimensions=30,15,15
allowable_overhang=29
max_leveling=0
leveling_buffer=0
preserve_water=1
preserve_lava=0

biomesToSpawnIn=dead_swamp,quagmire,snowy_dead_forest,snowy_forest,extreme_hills,mutated_extreme_hills_with_trees,extreme_hills_with_trees,mountain,mountain_foothills,crag,shrubland,brushland,steppe,wasteland,tundra,outback,mesa,mesa_clear_rock,mesa_rock,volcanic_island,darklands,darklands_forest,darklands_hills,darklands_mountains,darklands_plains,ominous_woods,eerie,swamp_defiled,desert_defiled,plains_defiled,ice_plains_defiled,hills_defiled,forest_tenebra,forest_vilespine,dreadlands,dreadlands_forest,dreadlands_mountains,purged_dreadlands

rule1=0,100,preserveBlock
rule2=0,100,biomesoplenty:log_4-1
rule3=0,100,biomesoplenty:log_4-9
rule4=0,100,biomesoplenty:log_4-5
rule5=0,100,biomesoplenty:leaves_1-5
rule6=0,100,biomesoplenty:leaves_1-13

layer
1,1,1,1,1,1,1,1,1,1,1,1,1,1,1
1,1,1,1,1,1,1,1,2,1,1,1,1,1,1
1,1,1,1,1,1,1,1,3,2,1,1,1,1,1
1,1,1,1,1,1,1,1,1,2,1,1,1,1,1
1,1,1,1,1,1,1,1,1,3,4,1,4,3,1
1,1,1,1,4,1,1,1,1,1,1,1,1,1,1
1,1,1,1,1,1,1,1,1,1,1,1,1,1,1
1,1,1,1,1,1,1,1,1,1,1,1,1,1,1
1,1,1,1,1,1,1,1,1,1,1,1,1,1,4
1,1,1,1,1,1,1,1,1,1,1,4,4,1,1
1,1,1,1,4,1,1,1,1,1,1,1,1,1,1
1,1,1,1,1,1,1,3,4,1,1,1,1,1,1
1,1,1,1,1,1,1,1,1,1,4,1,1,1,1
1,1,1,1,1,1,1,1,1,1,1,1,1,1,1
1,1,1,1,1,1,1,1,1,1,1,1,1,1,1
endlayer

layer
1,1,1,1,1,1,1,1,1,1,1,1,1,1,1
1,1,1,1,1,1,1,1,1,1,1,1,1,1,1
1,1,1,1,1,1,1,1,1,1,1,1,1,1,1
1,1,1,1,1,1,1,1,1,1,1,1,1,1,1
1,1,1,1,1,1,1,1,1,1,3,4,3,1,1
1,1,1,1,3,4,1,1,1,1,1,1,1,1,1
1,1,1,1,1,1,1,1,1,1,1,1,1,1,1
1,1,1,1,1,1,1,1,1,1,1,1,1,1,1
1,1,1,1,1,1,1,1,1,1,1,4,1,1,4
1,1,1,1,1,1,1,1,1,1,1,4,4,1,1
1,1,1,1,3,4,1,1,1,1,1,1,1,1,1
1,1,1,1,1,1,1,1,4,1,4,1,1,1,1
1,1,1,1,1,1,1,1,1,1,2,1,1,1,1
1,1,1,1,1,1,1,1,1,1,1,1,1,1,1
1,1,1,1,1,1,1,1,1,1,1,1,1,1,1
endlayer

layer
1,1,1,1,1,1,1,1,1,1,1,1,1,1,1
1,1,1,1,1,1,1,1,1,1,1,1,1,1,1
1,1,1,1,1,1,1,1,1,1,1,1,1,1,1
1,1,1,1,1,1,1,1,1,1,1,1,1,1,1
1,1,1,1,1,1,1,1,1,1,1,2,1,1,1
1,1,1,1,1,2,1,1,1,1,1,4,1,1,1
1,1,1,1,1,3,4,1,1,1,1,1,1,1,1
1,1,1,1,1,1,1,1,1,1,1,1,1,4,4
1,1,1,1,1,1,1,1,1,1,4,4,1,1,2
1,1,1,1,1,2,4,1,1,1,4,4,1,1,1
1,1,1,1,1,4,1,1,1,1,1,1,1,1,1
1,1,1,1,1,1,1,1,3,4,4,1,1,1,1
1,1,1,1,1,1,1,1,1,1,1,1,1,1,1
1,1,1,1,1,1,1,1,1,1,1,1,1,1,1
1,1,1,1,1,1,1,1,1,1,1,1,1,1,1
endlayer

layer
1,1,1,1,1,1,1,1,1,1,1,1,1,1,1
1,1,1,1,1,1,1,1,1,1,1,1,1,1,1
1,1,1,1,1,1,1,1,1,1,1,1,1,1,1
1,1,1,1,1,1,1,1,1,1,1,1,1,1,1
1,1,1,1,1,1,1,1,1,1,1,1,1,1,1
1,1,1,1,1,1,1,1,1,1,1,2,1,1,1
1,1,1,1,1,1,2,1,1,1,1,4,1,1,1
1,1,1,1,1,1,3,4,1,1,1,1,1,4,1
1,1,1,1,1,1,1,1,1,1,4,1,1,1,1
1,1,1,1,1,1,4,1,1,1,4,4,1,1,1
1,1,1,1,1,4,1,1,1,4,4,1,1,1,1
1,1,1,1,1,1,1,1,1,4,4,1,1,1,1
1,1,1,1,1,1,1,1,1,1,1,1,1,1,1
1,1,1,1,1,1,1,1,1,1,1,1,1,1,1
1,1,1,1,1,1,1,1,1,1,1,1,1,1,1
endlayer

layer
1,1,1,1,1,1,1,1,1,1,1,1,1,1,1
1,1,1,1,1,1,1,1,1,1,1,1,1,1,1
1,1,1,1,1,1,1,1,1,1,1,1,1,1,1
1,1,1,1,1,1,1,1,1,1,1,1,1,1,1
1,1,1,1,1,1,1,1,1,1,1,1,1,1,1
1,1,1,1,1,1,1,1,1,1,1,1,1,1,1
1,1,1,1,1,1,1,1,1,1,1,2,1,1,1
1,1,1,1,1,1,1,2,1,1,1,2,3,3,1
1,1,1,1,1,1,1,3,1,1,4,4,1,1,1
1,1,1,1,1,1,4,3,1,4,4,4,1,1,1
1,1,1,1,1,1,1,1,1,4,4,1,1,1,1
1,1,1,1,1,1,1,1,1,4,4,1,1,1,1
1,1,1,1,1,1,1,1,1,1,1,1,1,1,1
1,1,1,1,1,1,1,1,1,1,1,1,1,1,1
1,1,1,1,1,1,1,1,1,1,1,1,1,1,1
endlayer

layer
1,1,1,1,1,1,1,1,1,1,1,1,1,1,1
1,1,1,1,1,1,1,1,1,1,1,1,1,1,1
1,1,1,1,1,1,1,1,1,1,1,1,1,1,1
1,1,1,1,1,1,1,1,1,1,1,1,1,1,1
1,1,1,1,1,1,1,1,1,1,1,1,1,1,1
1,1,1,1,1,1,1,1,1,1,1,1,1,1,1
1,1,1,1,1,1,1,1,1,1,1,1,1,1,1
1,1,1,1,1,1,1,1,1,4,4,2,1,1,1
1,1,1,1,1,1,1,1,4,4,4,2,1,1,1
1,1,1,1,1,1,1,1,4,4,4,4,1,1,1
1,1,1,1,1,1,1,1,1,4,4,4,1,1,1
1,1,1,1,1,1,1,1,1,4,4,1,1,1,1
1,1,1,1,1,1,1,1,1,1,1,1,1,1,1
1,1,1,1,1,1,1,1,1,1,1,1,1,1,1
1,1,1,1,1,1,1,1,1,1,1,1,1,1,1
endlayer

layer
1,1,1,1,1,1,1,1,1,1,1,1,1,1,1
1,1,1,1,1,1,1,1,1,1,1,1,1,1,1
1,1,1,1,1,1,1,1,1,1,1,1,1,1,1
1,1,1,1,1,1,1,1,1,1,1,1,1,1,1
1,1,1,1,1,1,1,1,1,1,1,1,1,1,1
1,1,1,1,1,1,1,1,1,1,1,1,1,1,1
1,1,1,1,1,1,1,1,1,1,1,1,1,1,1
1,1,1,1,1,1,1,1,1,4,4,0,1,1,1
1,1,1,1,1,1,1,1,0,4,4,0,1,1,1
1,1,1,1,1,1,1,1,4,4,4,4,1,1,1
1,1,1,1,1,1,1,1,1,4,4,4,1,1,1
1,1,1,1,1,1,1,1,1,1,4,1,1,1,1
1,1,1,1,1,1,1,1,1,1,1,1,1,1,1
1,1,1,1,1,1,1,1,1,1,1,1,1,1,1
1,1,1,1,1,1,1,1,1,1,1,1,1,1,1
endlayer

layer
1,1,1,1,1,1,1,1,1,1,1,1,1,1,1
1,1,1,1,1,1,1,1,1,1,1,1,1,1,1
1,1,1,1,1,1,1,1,1,1,1,1,1,1,1
1,1,1,1,1,1,1,1,1,1,1,1,1,1,1
1,1,1,1,1,1,1,1,1,1,1,1,1,1,1
1,1,1,1,1,1,1,1,1,1,1,1,1,1,1
1,1,1,1,1,1,1,1,1,1,1,1,1,1,1
1,1,1,1,1,1,1,1,1,0,0,0,1,1,1
1,1,1,1,1,1,1,1,0,4,4,0,1,1,1
1,1,1,1,1,1,1,1,3,4,4,3,1,1,1
1,1,1,1,1,1,1,1,1,4,4,1,1,1,1
1,1,1,1,1,1,1,1,1,1,1,1,1,1,1
1,1,1,1,1,1,1,1,1,1,1,1,1,1,1
1,1,1,1,1,1,1,1,1,1,1,1,1,1,1
1,1,1,1,1,1,1,1,1,1,1,1,1,1,1
endlayer

layer
1,1,1,1,1,1,1,1,1,1,1,1,1,1,1
1,1,1,1,1,1,1,1,1,1,1,1,1,1,1
1,1,1,1,1,1,1,1,1,1,1,1,1,1,1
1,1,1,1,1,1,1,1,1,1,1,1,1,1,1
1,1,1,1,1,1,1,1,1,1,1,1,1,1,1
1,1,1,1,1,1,1,1,1,1,1,1,1,1,1
1,1,1,1,1,1,1,1,1,1,1,1,1,1,1
1,1,1,1,1,1,1,1,1,0,0,0,1,1,1
1,1,1,1,1,1,1,1,0,4,2,0,1,1,1
1,1,1,1,1,1,1,1,4,4,4,4,1,1,1
1,1,1,1,1,1,1,1,1,2,4,1,1,1,1
1,1,1,1,1,1,1,1,1,1,1,1,1,1,1
1,1,1,1,1,1,1,1,1,1,1,1,1,1,1
1,1,1,1,1,1,1,1,1,1,1,1,1,1,1
1,1,1,1,1,1,1,1,1,1,1,1,1,1,1
endlayer

layer
1,1,1,1,1,1,1,1,1,1,1,1,1,1,1
1,1,1,1,1,1,1,1,1,1,1,1,1,1,1
1,1,1,1,1,1,1,1,1,1,1,1,1,1,1
1,1,1,1,1,1,1,1,1,1,1,1,1,1,1
1,1,1,1,1,1,1,1,1,1,1,1,1,1,1
1,1,1,1,1,1,1,1,1,1,1,1,1,1,1
1,1,1,1,1,1,1,1,1,1,1,1,1,1,1
1,1,1,1,1,1,1,1,1,0,0,0,1,1,1
1,1,1,1,1,1,1,1,0,4,4,0,1,1,1
1,1,1,1,1,1,1,1,4,4,4,4,1,1,1
1,1,1,1,1,1,1,1,1,4,4,1,1,1,1
1,1,1,1,1,1,1,1,1,1,1,1,1,1,1
1,1,1,1,1,1,1,1,1,1,1,1,1,1,1
1,1,1,1,1,1,1,1,1,1,1,1,1,1,1
1,1,1,1,1,1,1,1,1,1,1,1,1,1,1
endlayer

layer
1,1,1,1,1,1,1,1,1,1,1,1,1,1,1
1,1,1,1,1,1,1,1,1,1,1,1,1,1,1
1,1,1,1,1,1,1,1,1,1,1,1,1,1,1
1,1,1,1,1,1,1,1,1,1,1,1,1,1,1
1,1,1,1,1,1,1,1,1,1,1,1,1,1,1
1,1,1,1,1,1,1,1,1,1,1,1,1,1,1
1,1,1,1,1,1,1,1,1,1,1,1,1,1,1
1,1,1,1,1,1,1,1,1,2,0,0,1,1,1
1,1,1,1,1,1,1,1,4,4,4,0,1,1,1
1,1,1,1,1,1,1,1,4,4,4,0,1,1,1
1,1,1,1,1,1,1,1,4,4,0,1,1,1,1
1,1,1,1,1,1,1,1,1,1,1,1,1,1,1
1,1,1,1,1,1,1,1,1,1,1,1,1,1,1
1,1,1,1,1,1,1,1,1,1,1,1,1,1,1
1,1,1,1,1,1,1,1,1,1,1,1,1,1,1
endlayer

layer
1,1,1,1,1,1,1,1,1,1,1,1,1,1,1
1,1,1,1,1,1,1,1,1,1,1,1,1,1,1
1,1,1,1,1,1,1,1,1,1,1,1,1,1,1
1,1,1,1,1,1,1,1,1,1,1,1,1,1,1
1,1,1,1,1,1,1,1,1,1,1,1,1,1,1
1,1,1,1,1,1,1,1,1,1,1,1,1,1,1
1,1,1,1,1,1,1,1,2,1,1,1,1,1,1
1,1,1,1,1,1,1,1,2,0,0,0,1,1,1
1,1,1,1,1,1,1,1,4,4,4,0,1,1,1
1,1,1,1,1,1,1,1,4,4,3,0,1,1,1
1,1,1,1,1,1,1,1,0,4,0,1,1,1,1
1,1,1,1,1,1,1,1,1,1,1,1,1,1,1
1,1,1,1,1,1,1,1,1,1,1,1,1,1,1
1,1,1,1,1,1,1,1,1,1,1,1,1,1,1
1,1,1,1,1,1,1,1,1,1,1,1,1,1,1
endlayer

layer
1,1,1,1,1,1,1,1,1,1,1,1,1,1,1
1,1,1,1,1,1,1,1,1,1,1,1,1,1,1
1,1,1,1,1,1,1,1,1,1,1,1,1,1,1
1,1,1,1,1,1,1,1,1,1,1,1,1,1,1
1,1,1,1,1,1,1,1,1,1,1,1,1,1,1
1,1,1,1,1,1,1,1,2,1,1,1,1,1,1
1,1,1,1,1,1,1,1,2,1,1,1,1,1,1
1,1,1,1,1,1,1,1,0,0,0,0,1,1,1
1,1,1,1,1,1,1,1,4,4,0,0,1,1,1
1,1,1,1,1,1,1,4,4,4,4,0,1,1,1
1,1,1,1,1,1,1,1,0,0,0,1,1,1,1
1,1,1,1,1,1,1,1,1,1,1,1,1,1,1
1,1,1,1,1,1,1,1,1,1,1,1,1,1,1
1,1,1,1,1,1,1,1,1,1,1,1,1,1,1
1,1,1,1,1,1,1,1,1,1,1,1,1,1,1
endlayer

layer
1,1,1,1,1,1,1,1,1,1,1,1,1,1,1
1,1,1,1,1,1,1,1,1,1,1,1,1,1,1
1,1,1,1,1,1,1,1,1,1,1,1,1,1,1
1,1,1,1,1,1,1,1,1,1,1,1,1,1,1
1,1,1,1,1,1,1,1,1,1,1,1,1,1,1
1,1,1,1,1,1,1,1,0,1,1,1,1,1,1
1,1,1,1,1,1,1,1,0,1,1,1,1,1,1
1,1,1,1,1,1,1,1,0,0,0,0,1,1,1
1,1,1,1,1,1,1,4,4,4,0,0,1,1,1
1,1,1,1,1,1,1,4,4,4,0,0,1,1,1
1,1,1,1,1,1,1,1,0,0,0,1,1,1,1
1,1,1,1,1,1,1,1,1,1,1,1,1,1,1
1,1,1,1,1,1,1,1,1,1,1,1,1,1,1
1,1,1,1,1,1,1,1,1,1,1,1,1,1,1
1,1,1,1,1,1,1,1,1,1,1,1,1,1,1
endlayer

layer
1,1,1,1,1,1,1,1,1,1,1,1,1,1,1
1,1,1,1,1,1,1,1,1,1,1,1,1,1,1
1,1,1,1,1,1,1,1,1,1,1,1,1,1,1
1,1,1,1,1,1,1,1,1,1,1,1,1,1,1
1,1,1,1,1,1,1,1,1,1,1,1,1,1,1
1,1,1,1,1,1,1,1,0,1,1,1,1,1,1
1,1,1,1,1,1,1,1,0,1,1,1,1,1,1
1,1,1,1,1,1,1,1,0,0,0,0,1,1,1
1,1,1,1,1,1,1,4,4,0,0,0,1,1,1
1,1,1,1,1,1,1,4,4,3,0,0,1,1,1
1,1,1,1,1,1,1,4,0,0,0,1,1,1,1
1,1,1,1,1,1,1,1,1,1,1,1,1,1,1
1,1,1,1,1,1,1,1,1,1,1,1,1,1,1
1,1,1,1,1,1,1,1,1,1,1,1,1,1,1
1,1,1,1,1,1,1,1,1,1,1,1,1,1,1
endlayer

layer
1,1,1,1,1,1,1,1,1,1,1,1,1,1,1
1,1,1,1,1,1,1,1,1,1,1,1,1,1,1
1,1,1,1,1,1,1,1,1,1,1,1,1,1,1
1,1,1,1,1,1,1,1,1,1,1,1,1,1,1
1,1,1,1,1,1,1,1,1,1,1,1,1,1,1
1,1,1,1,1,1,1,1,0,1,1,1,1,1,1
1,1,1,1,1,1,2,2,0,1,1,1,1,1,1
1,1,1,1,1,1,1,2,0,0,0,0,1,1,1
1,1,1,1,1,1,1,2,4,0,0,0,1,1,1
1,1,1,1,1,1,4,4,4,0,0,0,1,1,1
1,1,1,1,1,1,1,4,0,0,0,1,1,1,1
1,1,1,1,1,1,1,1,1,1,1,1,1,1,1
1,1,1,1,1,1,1,1,1,1,1,1,1,1,1
1,1,1,1,1,1,1,1,1,1,1,1,1,1,1
1,1,1,1,1,1,1,1,1,1,1,1,1,1,1
endlayer

layer
1,1,1,1,1,1,1,1,1,1,1,1,1,1,1
1,1,1,1,1,1,1,1,1,1,1,1,1,1,1
1,1,1,1,1,1,1,1,1,1,1,1,1,1,1
1,1,1,1,1,1,1,1,1,1,1,1,1,1,1
1,1,1,1,1,2,1,1,1,1,1,1,1,1,1
1,1,1,1,1,2,2,1,0,1,1,1,1,1,1
1,1,1,1,1,1,2,0,0,1,1,1,1,1,1
1,1,1,1,1,1,1,0,0,0,0,0,1,1,1
1,1,1,1,1,1,1,0,0,0,0,0,1,1,1
1,1,1,5,2,3,3,4,4,0,0,0,1,1,1
1,1,1,1,2,2,1,4,4,0,0,1,1,1,1
1,1,1,1,2,1,1,1,1,1,4,2,1,1,1
1,1,1,1,1,1,1,1,1,1,1,2,1,1,1
1,1,6,1,1,1,1,1,1,1,1,2,3,1,1
1,6,6,1,1,1,1,1,1,1,1,5,1,1,1
endlayer

layer
1,1,1,1,1,1,1,1,1,1,1,1,1,1,1
1,1,1,1,1,1,1,1,1,1,1,1,1,1,1
1,1,1,1,1,1,1,1,1,1,1,1,1,1,1
1,1,1,1,1,1,1,1,1,1,1,1,1,1,1
1,1,1,1,3,3,1,1,1,1,1,1,1,1,1
1,1,1,1,1,0,0,1,0,1,1,1,1,1,1
1,1,1,1,1,1,0,0,0,1,1,1,1,1,1
1,1,1,1,1,1,1,0,0,0,0,0,1,1,1
1,1,5,1,1,1,1,0,0,0,0,0,1,1,1
1,1,5,4,3,0,0,4,4,0,0,0,1,1,1
1,1,1,1,5,0,1,2,4,2,1,3,3,3,1
1,1,1,2,3,1,1,1,1,2,4,0,1,1,1
1,1,1,2,1,1,1,1,1,5,5,0,1,1,1
1,6,3,2,1,1,1,1,1,1,1,0,4,1,1
1,4,2,1,1,1,1,1,1,1,1,0,2,1,1
endlayer

layer
1,1,1,1,1,1,1,1,1,1,1,1,1,1,1
1,1,1,1,1,1,1,1,1,1,1,1,1,1,1
1,1,1,1,1,1,1,1,1,1,1,1,1,1,1
1,1,1,1,1,1,1,1,1,1,1,1,1,1,1
1,1,1,1,4,0,1,1,1,1,1,1,1,1,1
1,1,1,1,1,0,0,1,0,1,1,1,1,1,1
1,1,5,1,1,1,0,0,0,1,1,1,1,1,1
6,3,2,6,1,1,1,0,0,0,0,0,1,1,1
1,1,4,1,1,1,1,0,4,0,0,0,1,1,1
1,1,4,3,6,0,0,4,4,0,0,0,1,1,1
1,1,1,1,0,0,1,0,4,0,0,0,1,3,3
1,1,1,0,0,1,1,1,1,5,5,0,1,5,1
1,1,1,4,1,1,1,1,1,0,0,0,1,1,1
1,0,0,0,1,1,1,1,1,1,1,0,0,1,1
1,4,0,1,1,1,1,1,1,1,1,0,4,1,1
endlayer

layer
1,1,1,1,1,1,1,1,1,1,1,1,1,1,1
1,1,1,1,1,1,1,1,1,1,1,1,1,1,1
1,1,1,1,1,1,1,1,1,1,1,1,1,1,1
1,1,1,4,3,1,1,1,1,1,1,1,1,1,1
1,1,1,1,4,0,1,1,1,1,1,1,1,1,1
1,1,1,1,1,0,0,1,0,1,1,1,1,1,1
3,2,0,1,1,1,0,0,0,1,1,1,1,1,1
0,4,6,0,1,1,1,0,4,0,0,0,1,1,1
1,1,6,1,1,1,1,0,4,0,0,0,1,1,1
3,3,3,6,0,0,0,0,4,3,3,0,1,1,1
1,1,1,1,0,0,1,0,4,0,0,0,1,0,4
1,1,1,0,0,1,1,1,1,0,0,0,1,0,1
1,1,1,4,1,1,1,1,1,0,0,0,1,1,1
1,0,0,0,1,1,1,1,1,1,1,0,0,1,1
1,0,0,1,1,1,1,1,1,1,1,0,4,1,1
endlayer

layer
1,1,1,1,1,1,1,1,1,1,1,1,1,1,1
1,1,1,1,1,1,1,1,5,1,1,1,1,1,1
1,1,1,1,1,1,1,1,5,1,6,1,1,1,1
1,1,1,4,0,1,1,1,5,1,1,1,1,1,1
1,1,1,1,5,0,1,1,2,1,1,1,1,1,1
1,1,1,1,1,0,4,1,2,1,1,1,1,1,1
0,0,0,1,1,1,3,3,2,1,1,1,1,1,1
0,6,0,0,1,1,1,0,2,0,0,0,1,1,1
1,1,0,1,1,1,1,0,4,4,0,0,1,1,1
4,0,0,0,0,0,0,0,4,4,0,0,1,1,1
1,1,1,1,0,0,1,0,0,0,0,0,1,0,0
1,1,1,0,0,1,1,1,1,0,0,0,1,0,1
1,1,1,0,1,1,1,1,1,0,0,0,1,1,1
1,0,0,0,1,1,1,1,1,1,1,0,0,1,1
1,0,0,1,1,1,1,1,1,1,1,0,0,1,1
endlayer

layer
1,1,1,1,1,1,1,1,5,1,1,1,1,1,1
1,1,1,1,1,1,1,5,2,5,1,1,1,1,1
1,1,1,1,1,1,1,3,2,5,4,6,1,1,1
1,1,1,5,0,1,1,1,2,3,3,3,5,1,1
1,1,1,1,0,0,1,1,4,1,5,5,1,1,1
1,1,1,1,1,3,3,1,1,1,1,1,1,1,1
0,0,0,1,1,1,0,0,0,1,1,1,1,1,1
0,0,0,0,1,1,1,0,0,0,0,0,1,1,1
1,1,0,1,1,1,1,0,4,4,0,0,1,1,1
0,0,0,0,0,0,0,0,4,4,0,0,1,1,1
1,1,1,1,0,0,1,3,3,1,0,0,1,0,0
1,1,1,0,0,1,1,1,1,0,0,0,1,0,1
1,1,1,0,1,1,1,1,1,0,0,0,1,1,1
1,0,0,0,1,1,1,1,1,1,1,0,0,1,1
1,0,0,1,1,1,1,1,1,1,1,0,0,1,1
endlayer

layer
1,1,1,1,1,1,1,1,2,1,1,1,1,1,1
1,1,1,1,1,1,1,0,2,0,1,1,1,1,1
1,1,1,1,1,1,1,0,1,0,4,0,1,1,1
1,1,1,0,0,1,1,1,0,0,5,5,0,1,1
1,1,1,1,0,0,1,1,0,1,0,5,1,1,1
1,1,1,1,1,4,0,1,1,1,1,1,1,1,1
0,0,0,1,1,1,0,0,0,1,1,1,1,1,1
0,0,0,0,1,1,1,0,0,0,0,0,1,1,1
1,1,0,1,1,1,1,0,4,4,4,0,1,1,1
0,0,0,0,0,0,0,1,4,4,0,0,1,1,1
1,1,1,1,0,0,1,2,0,5,0,0,1,0,0
1,1,1,0,0,5,2,2,5,0,0,0,1,0,1
1,1,1,0,1,5,2,5,1,0,0,0,1,1,1
1,0,0,0,1,1,5,1,1,1,1,0,0,1,1
1,0,0,1,1,1,1,1,1,1,1,0,0,1,1
endlayer

layer
1,1,1,1,1,1,1,1,4,1,1,1,1,1,1
1,1,1,1,1,1,1,0,5,0,1,1,1,1,1
1,1,1,1,1,1,1,0,1,0,5,0,1,1,1
1,1,1,0,0,1,1,1,0,0,0,0,0,1,1
1,1,1,1,0,0,1,1,0,1,0,0,1,1,1
1,1,1,1,1,0,0,1,1,1,1,1,1,1,1
0,0,0,1,1,1,0,0,0,1,1,1,1,1,1
0,0,0,0,1,1,1,0,0,0,2,3,1,1,1
1,1,0,1,1,1,1,0,4,4,4,0,1,1,1
0,0,0,0,0,0,0,1,0,4,5,0,1,1,1
1,1,1,1,0,0,1,0,0,5,0,0,1,0,0
1,1,1,0,0,5,1,0,0,0,0,0,1,0,1
1,1,1,0,1,5,2,0,1,0,0,0,1,1,1
1,0,0,0,1,5,2,5,1,1,1,0,0,1,1
1,0,0,1,1,1,5,1,1,1,1,0,0,1,1
endlayer

layer
1,1,1,1,1,1,1,1,5,1,1,1,1,1,1
1,1,1,1,1,1,1,0,0,0,1,1,1,1,1
1,1,1,1,1,1,1,0,1,0,0,0,1,1,1
1,1,1,0,0,1,1,1,0,0,0,0,0,1,1
1,1,1,1,0,0,1,1,0,1,0,0,1,1,1
1,1,1,1,1,0,0,1,1,1,1,1,5,5,1
0,0,0,1,1,1,0,0,0,1,1,2,3,5,1
0,0,0,0,1,1,1,0,0,0,0,4,1,1,1
1,1,0,1,1,1,1,0,0,4,0,0,1,1,1
0,0,0,0,0,0,0,1,0,4,4,0,1,1,1
1,1,1,1,0,0,1,0,0,5,0,0,1,0,0
1,1,1,0,0,0,1,0,0,0,0,0,1,0,1
1,1,1,0,1,5,5,0,1,0,0,0,1,1,1
1,0,0,0,1,0,4,5,1,1,1,0,0,1,1
1,0,0,1,1,1,5,5,1,1,1,0,0,1,1
endlayer

layer
1,1,1,1,1,1,1,1,0,1,1,1,1,1,1
1,1,1,1,1,1,1,0,0,0,1,1,1,1,1
1,1,1,1,1,1,1,0,1,0,0,0,1,1,1
1,1,1,0,0,1,1,1,0,0,0,0,0,1,1
1,1,1,1,0,0,1,1,0,1,0,0,5,2,1
1,1,1,1,1,0,0,1,1,1,1,1,5,2,5
0,0,0,1,1,1,0,0,0,1,4,0,4,3,5
0,0,0,0,1,1,1,0,0,0,0,0,0,2,3
1,1,0,1,1,1,1,0,0,0,0,0,0,0,2
0,0,0,0,0,0,0,1,4,0,4,0,0,0,0
1,1,1,1,0,0,1,0,0,0,2,3,3,0,0
1,1,1,0,0,0,1,0,0,0,0,0,1,0,1
1,1,1,0,1,0,5,0,1,0,0,0,1,1,1
1,0,0,0,1,5,4,5,1,1,1,0,0,1,1
1,0,0,1,1,1,0,0,1,1,1,0,0,1,1
endlayer

layer
1,1,1,1,1,1,1,1,0,1,1,1,1,1,1
1,1,1,1,1,1,1,0,0,0,1,1,1,1,1
1,1,1,1,1,1,1,0,1,0,0,0,1,1,1
1,1,1,0,0,1,1,1,0,5,0,0,0,1,1
1,1,1,1,0,0,1,1,5,2,5,0,0,5,5
1,1,1,1,1,0,0,1,1,2,2,0,5,4,4
0,0,0,1,1,1,0,0,0,1,4,0,5,5,0
0,0,0,0,1,1,1,0,0,0,0,0,0,0,0
1,1,0,1,1,1,1,0,0,0,0,0,0,0,4
0,0,0,0,0,0,0,5,4,0,0,0,0,0,0
1,1,1,1,0,0,0,0,5,0,0,4,0,0,0
1,1,1,0,0,0,0,0,0,0,0,5,5,5,1
1,1,1,0,1,0,0,0,1,0,0,5,1,1,1
1,0,0,0,1,0,0,0,1,1,1,0,0,1,1
1,0,0,1,1,1,0,0,1,1,1,0,0,1,1
endlayer

layer
1,1,1,1,1,1,1,1,0,1,1,1,1,1,1
1,1,1,1,1,1,1,0,0,0,1,1,1,1,1
1,1,1,1,1,1,1,0,1,0,0,0,1,1,1
1,1,1,0,0,1,1,1,0,5,0,0,0,1,1
1,1,1,1,0,0,1,1,0,5,5,0,0,0,0
1,1,1,1,1,0,0,1,5,4,0,0,0,0,4
0,0,0,1,1,1,0,0,0,0,0,0,0,0,0
0,0,0,0,1,1,1,0,0,0,0,0,0,0,0
1,1,0,1,1,1,1,0,0,0,0,0,0,0,0
0,0,0,0,0,0,0,5,4,0,0,0,0,0,0
1,1,1,1,0,0,0,0,5,0,5,4,0,0,0
1,1,1,0,0,0,0,0,0,0,5,2,3,3,5
1,1,1,0,1,0,0,0,1,0,5,2,5,1,1
1,0,0,0,1,0,0,0,1,1,1,5,0,1,1
1,0,0,1,1,1,0,0,1,1,1,0,0,1,1
endlayer

layer
1,1,1,1,1,1,1,1,0,1,1,1,1,1,1
1,1,1,1,1,1,1,0,0,0,1,1,1,1,1
1,1,1,1,1,1,1,0,1,0,0,0,1,1,1
1,1,1,0,0,1,1,1,0,0,0,0,0,1,1
1,1,1,1,0,0,1,1,0,0,0,0,0,0,0
1,1,1,1,1,0,0,1,0,0,0,0,0,0,0
0,0,0,1,1,1,0,0,0,0,0,0,0,0,0
0,0,0,0,1,1,1,0,0,0,0,0,0,0,0
1,1,0,1,1,1,1,0,0,0,0,0,0,0,0
0,0,0,0,0,0,0,0,0,0,0,0,0,0,0
1,1,1,1,0,0,0,0,0,0,0,0,6,0,0
1,1,1,0,0,0,0,0,0,0,0,0,4,6,0
1,1,1,0,1,0,0,0,1,0,0,5,6,1,1
1,0,0,0,1,0,0,0,1,1,1,0,0,1,1
1,0,0,1,1,1,0,0,1,1,1,0,0,1,1
endlayer

layer
1,1,1,1,1,1,1,1,0,1,1,1,1,1,1
1,1,1,1,1,1,1,0,0,0,1,1,1,1,1
1,1,1,1,1,1,1,0,1,0,0,0,1,1,1
1,1,1,0,0,1,1,1,0,0,0,0,0,1,1
1,1,1,1,0,0,1,1,0,0,0,0,0,0,0
1,1,1,1,1,0,0,1,0,0,0,0,0,0,0
0,0,0,1,1,1,0,0,0,0,0,0,0,0,0
0,0,0,0,1,1,1,0,0,0,0,0,0,0,0
1,1,0,1,1,1,1,0,0,0,0,0,0,0,0
0,0,0,0,0,0,0,0,0,0,0,0,0,0,0
1,1,1,1,0,0,0,0,0,0,0,0,0,0,0
1,1,1,0,0,0,0,0,0,0,0,0,4,0,0
1,1,1,0,1,0,0,0,1,0,0,0,0,1,1
1,0,0,0,1,0,0,0,1,1,1,0,0,1,1
1,0,0,1,1,1,0,0,1,1,1,0,0,1,1
endlayer

