
# Created by Ruins mod version 17.1 Ingame Parser
# authoring Player: ST753M

weight=1
embed_into_distance=35
random_height_offset=-15,15
acceptable_target_blocks=
unacceptable_target_blocks=flowing_water,water,flowing_lava,lava,ice,cloud,natura_cloud,slime_grass,slime_congealed,slime_dirt,twilightforest:wispy_cloud,twilightforest:fluffy_cloud
dimensions=75,6,7
allowable_overhang=999
max_leveling=0
leveling_buffer=0
preserve_water=1
preserve_lava=1

biomesToSpawnIn=darklands,darklands_forest,darklands_hills,darklands_mountains,darklands_plains,ominous_woods,eerie,swamp_defiled,desert_defiled,plains_defiled,ice_plains_defiled,hills_defiled,forest_tenebra,forest_vilespine,abyssal_wastelands,dreadlands,dreadlands_forest,dreadlands_mountains,dark_realm,undergarden,visceral_heap,corrupted_sands,fungi_forest,ruthless_sands,torrid_wasteland,a

=0,100,preserveBlock
rule1=0,100,!biomesoplenty:flesh-0
^0,100,biomesoplenty:flesh-0
^0,100,biomesoplenty:dirt-8
^0,100,biomesoplenty:ash_block-0
^0,100,minecraft:obsidian-0
^0,100,minecraft:obsidian-0

layer
0,0,0,0,0,0,0
0,0,0,0,0,0,0
0,0,0,0,0,0,0
0,0,1,0,0,0,0
0,0,0,0,0,0,0
0,0,0,0,0,0,0
endlayer

layer
0,0,0,0,0,0,0
0,0,0,0,0,0,0
0,0,0,0,0,0,0
0,0,1,0,0,0,0
0,0,0,0,0,0,0
0,0,0,0,0,0,0
endlayer

layer
0,0,0,0,0,0,0
0,0,0,0,0,0,0
0,0,0,0,0,0,0
0,0,1,0,0,0,0
0,0,0,0,0,0,0
0,0,0,0,0,0,0
endlayer

layer
0,0,0,0,0,0,0
0,0,0,0,0,0,0
0,0,1,0,0,0,0
0,0,1,0,0,0,0
0,0,0,0,0,0,0
0,0,0,0,0,0,0
endlayer

layer
0,0,0,0,0,0,0
0,0,0,0,0,0,0
0,0,1,0,0,0,0
0,0,1,0,0,0,0
0,0,0,0,0,0,0
0,0,0,0,0,0,0
endlayer

layer
0,0,0,0,0,0,0
0,0,0,0,0,0,0
0,0,1,0,0,0,0
0,0,1,0,0,0,0
0,0,1,0,0,0,0
0,0,0,0,0,0,0
endlayer

layer
0,0,0,0,0,0,0
0,0,0,0,0,0,0
0,0,1,0,0,0,0
0,1,1,0,0,0,0
0,0,1,0,0,0,0
0,0,0,0,0,0,0
endlayer

layer
0,0,0,0,0,0,0
0,0,1,0,0,0,0
0,0,1,0,0,0,0
0,1,1,1,0,0,0
0,0,1,0,0,0,0
0,0,0,0,0,0,0
endlayer

layer
0,0,0,0,0,0,0
0,0,1,0,0,0,0
0,0,1,0,0,0,0
0,1,1,1,0,0,0
0,0,1,1,0,0,0
0,0,0,0,0,0,0
endlayer

layer
0,0,0,0,0,0,0
0,0,1,0,0,0,0
0,1,1,0,0,0,0
0,1,1,1,0,0,0
0,0,1,1,0,0,0
0,0,0,0,0,0,0
endlayer

layer
0,0,0,0,0,0,0
0,0,1,0,0,0,0
0,1,1,1,0,0,0
0,1,1,1,0,0,0
0,1,1,1,0,0,0
0,0,0,0,0,0,0
endlayer

layer
0,0,0,0,0,0,0
0,0,1,0,0,0,0
0,1,1,1,0,0,0
1,1,1,1,0,0,0
0,1,1,1,0,0,0
0,0,1,0,0,0,0
endlayer

layer
0,0,0,0,0,0,0
0,0,1,0,0,0,0
0,1,1,1,0,0,0
1,1,1,1,0,0,0
0,1,1,1,0,0,0
0,0,1,0,0,0,0
endlayer

layer
0,0,0,0,0,0,0
0,0,0,0,0,0,0
0,1,1,1,0,0,0
1,1,1,1,0,0,0
1,1,1,1,0,0,0
0,0,1,0,0,0,0
endlayer

layer
0,0,0,0,0,0,0
0,0,0,0,0,0,0
0,1,1,0,0,0,0
1,1,1,1,1,0,0
1,1,1,1,0,0,0
0,1,1,0,0,0,0
endlayer

layer
0,0,0,0,0,0,0
0,0,0,0,0,0,0
0,1,1,0,0,0,0
1,1,1,1,1,0,0
1,1,1,1,0,0,0
0,1,1,0,0,0,0
endlayer

layer
0,0,0,0,0,0,0
0,0,0,0,0,0,0
0,1,1,0,0,0,0
1,1,1,1,1,0,0
1,1,1,1,0,0,0
0,1,1,0,0,0,0
endlayer

layer
0,0,0,0,0,0,0
0,0,0,0,0,0,0
0,1,1,1,0,0,0
1,1,1,1,1,0,0
0,1,1,1,1,0,0
0,1,1,0,0,0,0
endlayer

layer
0,0,0,0,0,0,0
0,0,0,0,0,0,0
0,1,1,1,0,0,0
0,1,1,1,1,0,0
0,1,1,1,1,0,0
0,1,1,1,0,0,0
endlayer

layer
0,0,0,0,0,0,0
0,0,1,0,0,0,0
0,0,1,1,1,0,0
0,1,1,1,1,0,0
0,1,1,1,1,0,0
0,0,1,1,0,0,0
endlayer

layer
0,0,0,0,0,0,0
0,0,1,0,0,0,0
0,0,1,1,1,0,0
0,1,1,1,1,0,0
0,1,1,1,1,0,0
0,0,1,1,0,0,0
endlayer

layer
0,0,0,0,0,0,0
0,0,1,1,0,0,0
0,1,1,1,1,0,0
0,1,1,1,1,0,0
0,0,1,1,0,0,0
0,0,0,0,0,0,0
endlayer

layer
0,0,0,0,0,0,0
0,0,1,1,1,0,0
0,1,1,1,1,0,0
0,1,1,1,1,0,0
0,0,1,1,0,0,0
0,0,0,0,0,0,0
endlayer

layer
0,0,0,0,0,0,0
0,0,1,1,1,0,0
0,1,1,1,1,0,0
0,1,1,1,1,1,0
0,0,1,1,0,0,0
0,0,0,0,0,0,0
endlayer

layer
0,0,0,0,0,0,0
0,0,0,1,1,0,0
0,0,1,1,1,1,0
0,0,1,1,1,1,0
0,0,1,1,1,0,0
0,0,0,0,0,0,0
endlayer

layer
0,0,0,0,0,0,0
0,0,0,1,1,0,0
0,0,1,1,1,1,0
0,0,1,1,1,1,0
0,0,0,1,1,0,0
0,0,0,0,0,0,0
endlayer

layer
0,0,0,0,0,0,0
0,0,0,1,1,0,0
0,0,1,1,1,1,0
0,0,1,1,1,1,0
0,0,0,1,1,0,0
0,0,0,0,1,0,0
endlayer

layer
0,0,0,0,0,0,0
0,0,0,1,0,0,0
0,1,1,1,1,1,0
0,0,1,1,1,1,0
0,0,0,1,1,1,0
0,0,0,1,1,0,0
endlayer

layer
0,0,0,0,0,0,0
0,0,0,1,0,0,0
0,1,1,1,1,0,0
0,0,1,1,1,1,0
0,0,1,1,1,1,0
0,0,0,1,1,0,0
endlayer

layer
0,0,0,0,0,0,0
0,0,1,1,0,0,0
0,1,1,1,1,0,0
0,1,1,1,1,1,0
0,0,1,1,1,1,0
0,0,0,1,1,0,0
endlayer

layer
0,0,0,0,0,0,0
0,0,1,1,0,0,0
0,1,1,1,1,1,0
0,1,1,1,1,1,0
0,1,1,1,1,1,1
0,0,1,1,1,0,0
endlayer

layer
0,0,0,0,0,0,0
0,0,1,1,1,0,0
0,1,1,1,1,1,0
0,1,1,1,1,1,0
0,1,1,1,1,1,1
0,0,1,1,1,0,0
endlayer

layer
0,0,0,0,0,0,0
0,0,1,1,1,0,0
0,1,1,1,1,1,0
0,1,1,1,1,1,1
0,1,1,1,1,1,1
0,0,1,1,1,1,0
endlayer

layer
0,0,0,0,0,0,0
0,0,0,1,1,1,0
0,1,1,1,1,1,1
0,1,1,1,1,1,1
0,1,1,1,1,1,1
0,0,0,1,1,1,0
endlayer

layer
0,0,0,0,0,0,0
0,0,0,1,1,1,0
0,0,1,1,1,1,1
0,1,1,1,1,1,1
0,0,1,1,1,1,1
0,0,0,1,1,1,0
endlayer

layer
0,0,0,0,0,0,0
0,0,0,1,1,1,0
0,0,1,1,1,1,1
0,0,1,1,1,1,1
0,0,1,1,1,1,0
0,0,0,0,1,1,0
endlayer

layer
0,0,0,1,1,1,0
0,0,1,1,1,1,1
0,0,1,1,1,1,1
0,0,1,1,1,1,1
0,0,1,1,1,1,0
0,0,0,0,1,0,0
endlayer

layer
0,0,0,1,1,1,0
0,0,1,1,1,1,1
0,0,1,1,1,1,1
0,1,1,1,1,1,1
0,0,0,1,1,1,0
0,0,0,0,1,0,0
endlayer

layer
0,0,0,1,1,1,0
0,0,1,1,1,1,1
0,1,1,1,1,1,1
0,1,1,1,1,1,0
0,0,0,1,1,1,0
0,0,0,0,0,0,0
endlayer

layer
0,0,1,1,1,1,0
0,1,1,1,1,1,0
0,1,1,1,1,1,0
0,1,1,1,1,1,0
0,0,1,1,1,0,0
0,0,0,0,0,0,0
endlayer

layer
0,0,1,1,1,0,0
0,1,1,1,1,1,0
1,1,1,1,1,1,0
0,1,1,1,1,1,0
0,0,1,1,1,0,0
0,0,0,0,0,0,0
endlayer

layer
0,1,1,1,1,0,0
0,1,1,1,1,1,0
1,1,1,1,1,1,0
1,1,1,1,1,0,0
0,0,1,1,1,0,0
0,0,0,0,0,0,0
endlayer

layer
0,1,1,1,1,0,0
1,1,1,1,1,0,0
1,1,1,1,1,0,0
1,1,1,1,1,0,0
0,1,1,1,1,0,0
0,0,0,1,0,0,0
endlayer

layer
0,1,1,1,0,0,0
1,1,1,1,1,0,0
1,1,1,1,1,0,0
1,1,1,1,1,0,0
0,1,1,1,0,0,0
0,0,0,1,0,0,0
endlayer

layer
0,1,1,0,0,0,0
0,1,1,1,1,0,0
1,1,1,1,1,0,0
1,1,1,1,1,0,0
0,1,1,1,0,0,0
0,0,1,1,0,0,0
endlayer

layer
0,0,1,0,0,0,0
0,1,1,1,0,0,0
1,1,1,1,1,0,0
1,1,1,1,1,0,0
1,1,1,1,1,0,0
0,1,1,1,0,0,0
endlayer

layer
0,0,1,0,0,0,0
0,1,1,1,0,0,0
1,1,1,1,1,0,0
1,1,1,1,1,0,0
1,1,1,1,1,0,0
0,1,1,1,0,0,0
endlayer

layer
0,0,0,0,0,0,0
0,1,1,1,0,0,0
1,1,1,1,1,0,0
1,1,1,1,1,0,0
1,1,1,1,1,0,0
0,1,1,1,0,0,0
endlayer

layer
0,0,0,0,0,0,0
0,0,1,1,1,0,0
0,1,1,1,1,0,0
1,1,1,1,1,1,0
1,1,1,1,1,0,0
0,0,1,1,1,0,0
endlayer

layer
0,0,0,0,0,0,0
0,0,1,1,1,0,0
0,1,1,1,1,0,0
1,1,1,1,1,1,0
0,1,1,1,1,1,0
0,0,1,1,1,0,0
endlayer

layer
0,0,0,0,0,0,0
0,0,1,1,1,0,0
0,1,1,1,1,0,0
0,1,1,1,1,1,0
0,1,1,1,1,1,0
0,0,1,1,1,0,0
endlayer

layer
0,0,0,0,0,0,0
0,0,0,1,1,0,0
0,1,1,1,1,1,0
0,1,1,1,1,1,0
0,0,1,1,1,1,0
0,0,1,1,1,0,0
endlayer

layer
0,0,0,0,0,0,0
0,0,0,1,1,0,0
0,1,1,1,1,1,0
0,1,1,1,1,1,0
0,0,1,1,1,1,0
0,0,0,1,1,0,0
endlayer

layer
0,0,0,0,1,0,0
0,0,0,1,1,0,0
0,1,1,1,1,1,0
0,0,1,1,1,1,0
0,0,0,1,1,0,0
0,0,0,1,1,0,0
endlayer

layer
0,0,0,0,1,0,0
0,0,0,1,1,0,0
0,0,1,1,1,1,0
0,0,1,1,1,1,0
0,0,0,1,1,0,0
0,0,0,1,0,0,0
endlayer

layer
0,0,0,0,1,0,0
0,0,1,1,1,0,0
0,0,1,1,1,1,0
0,0,1,1,1,1,0
0,0,0,1,1,0,0
0,0,0,0,0,0,0
endlayer

layer
0,0,0,1,1,0,0
0,0,1,1,1,1,0
0,0,1,1,1,1,0
0,0,1,1,1,0,0
0,0,0,0,1,0,0
0,0,0,0,0,0,0
endlayer

layer
0,0,0,1,1,0,0
0,0,1,1,1,1,0
0,0,1,1,1,1,0
0,0,0,1,1,0,0
0,0,0,0,1,0,0
0,0,0,0,0,0,0
endlayer

layer
0,0,0,1,1,0,0
0,0,1,1,1,1,0
0,0,1,1,1,1,0
0,0,0,1,1,0,0
0,0,0,0,0,0,0
0,0,0,0,0,0,0
endlayer

layer
0,0,0,0,1,1,0
0,0,1,1,1,1,1
0,0,1,1,1,1,1
0,0,0,1,1,1,0
0,0,0,0,0,0,0
0,0,0,0,0,0,0
endlayer

layer
0,0,0,0,1,1,0
0,0,1,1,1,1,1
0,0,0,1,1,1,1
0,0,0,1,1,1,0
0,0,0,0,0,0,0
0,0,0,0,0,0,0
endlayer

layer
0,0,0,0,0,1,0
0,0,0,1,1,1,1
0,0,0,1,1,1,1
0,0,0,0,1,1,0
0,0,0,0,0,0,0
0,0,0,0,0,0,0
endlayer

layer
0,0,0,0,0,1,0
0,0,0,1,1,1,1
0,0,0,1,1,1,1
0,0,0,0,1,1,1
0,0,0,0,0,0,0
0,0,0,0,0,0,0
endlayer

layer
0,0,0,0,0,1,0
0,0,0,0,1,1,1
0,0,0,1,1,1,1
0,0,0,0,1,1,1
0,0,0,0,0,0,0
0,0,0,0,0,0,0
endlayer

layer
0,0,0,0,0,1,0
0,0,0,0,1,1,0
0,0,0,0,1,1,1
0,0,0,0,1,1,1
0,0,0,0,0,0,0
0,0,0,0,0,0,0
endlayer

layer
0,0,0,0,0,1,0
0,0,0,0,0,1,0
0,0,0,0,1,1,1
0,0,0,0,1,1,0
0,0,0,0,0,0,0
0,0,0,0,0,0,0
endlayer

layer
0,0,0,0,0,0,0
0,0,0,0,0,1,0
0,0,0,0,1,1,1
0,0,0,0,1,1,0
0,0,0,0,0,0,0
0,0,0,0,0,0,0
endlayer

layer
0,0,0,0,0,0,0
0,0,0,0,0,1,0
0,0,0,0,1,1,1
0,0,0,0,0,1,0
0,0,0,0,0,0,0
0,0,0,0,0,0,0
endlayer

layer
0,0,0,0,0,0,0
0,0,0,0,0,1,0
0,0,0,0,1,1,1
0,0,0,0,0,1,0
0,0,0,0,0,0,0
0,0,0,0,0,0,0
endlayer

layer
0,0,0,0,0,0,0
0,0,0,0,0,1,0
0,0,0,0,0,1,1
0,0,0,0,0,1,0
0,0,0,0,0,0,0
0,0,0,0,0,0,0
endlayer

layer
0,0,0,0,0,0,0
0,0,0,0,0,1,0
0,0,0,0,0,1,0
0,0,0,0,0,1,0
0,0,0,0,0,0,0
0,0,0,0,0,0,0
endlayer

layer
0,0,0,0,0,0,0
0,0,0,0,0,0,0
0,0,0,0,0,1,0
0,0,0,0,0,1,0
0,0,0,0,0,0,0
0,0,0,0,0,0,0
endlayer

layer
0,0,0,0,0,0,0
0,0,0,0,0,0,0
0,0,0,0,0,1,0
0,0,0,0,0,0,0
0,0,0,0,0,0,0
0,0,0,0,0,0,0
endlayer

layer
0,0,0,0,0,0,0
0,0,0,0,0,0,0
0,0,0,0,0,1,0
0,0,0,0,0,0,0
0,0,0,0,0,0,0
0,0,0,0,0,0,0
endlayer

layer
0,0,0,0,0,0,0
0,0,0,0,0,0,0
0,0,0,0,0,1,0
0,0,0,0,0,0,0
0,0,0,0,0,0,0
0,0,0,0,0,0,0
endlayer

