
# Created by Ruins mod version 16.7 Ingame Parser
# authoring Player: ST753M

weight=1
embed_into_distance=5
acceptable_target_blocks=
unacceptable_target_blocks=flowing_water,water,flowing_lava,lava,ice,bedrock,netherrack,nether_brick,nether_brick_fence,soul_sand,quartz_ore,end_stone,obsidian,iron_bars,Natura:Cloud,slime_grass,slime_congealed,slime_dirt
dimensions=14,16,16
allowable_overhang=5
max_leveling=0
leveling_buffer=0
preserve_water=0
preserve_lava=0
preventRotation=1

biomesToSpawnIn=wasteland,bog,brushland,cold_desert,dead_forest,fen,quagmire,snowy_forest,steppe,tundra,cold desert,dead forest,snowy forest

rule1=0,100,preserveBlock
rule2=0,100,biomesoplenty:log_4-5
rule3=0,100,biomesoplenty:log_4-9
rule4=0,100,biomesoplenty:log_4-1
rule5=0,100,biomesoplenty:fir_fence-0
rule6=0,100,biomesoplenty:wood_slab_0-3
rule7=0,100,biomesoplenty:wood_slab_0-11
rule8=0,100,biomesoplenty:fir_stairs-0
rule9=0,100,biomesoplenty:fir_stairs-2
rule10=0,100,biomesoplenty:fir_stairs-3
rule11=0,100,biomesoplenty:fir_stairs-1
rule12=0,100,biomesoplenty:planks_0-3
rule13=0,100,biomesoplenty:fir_stairs-5
rule14=0,100,biomesoplenty:fir_stairs-7
rule15=0,100,biomesoplenty:fir_stairs-6
rule16=0,100,biomesoplenty:fir_stairs-4

layer
1,1,1,1,1,1,1,1,1,1,1,1,1,1,1,1
1,1,1,1,1,1,2,2,2,2,1,1,1,1,1,1
1,1,1,1,2,2,2,2,2,2,2,2,1,1,1,1
1,1,1,2,2,2,2,2,2,2,2,2,2,1,1,1
1,1,2,2,2,2,2,2,2,2,2,2,2,2,1,1
1,1,2,2,2,2,2,2,2,2,2,2,2,2,1,1
1,2,2,2,2,2,2,2,2,2,2,2,2,2,2,1
1,2,2,2,2,2,2,2,2,2,2,2,2,2,2,1
1,2,2,2,2,2,2,2,2,2,2,2,2,2,2,1
1,2,2,2,2,2,2,2,2,2,2,2,2,2,2,1
1,1,2,2,2,2,2,2,2,2,2,2,2,2,1,1
1,1,2,2,2,2,2,2,2,2,2,2,2,2,1,1
1,1,1,2,2,2,2,2,2,2,2,2,2,1,1,1
1,1,1,1,2,2,2,2,2,2,2,2,1,1,1,1
1,1,1,1,1,1,2,2,2,2,1,1,1,1,1,1
1,1,1,1,1,1,1,1,1,1,1,1,1,1,1,1
endlayer

layer
1,1,1,1,1,1,1,1,1,1,1,1,1,1,1,1
1,1,1,1,1,1,2,2,2,2,1,1,1,1,1,1
1,1,1,1,2,2,2,2,2,2,2,2,1,1,1,1
1,1,1,2,2,2,2,2,2,2,2,2,2,1,1,1
1,1,2,2,2,2,2,2,2,2,2,2,2,2,1,1
1,1,2,2,2,2,2,2,2,2,2,2,2,2,1,1
1,2,2,2,2,2,2,2,2,2,2,2,2,2,2,1
1,2,2,2,2,2,2,2,2,2,2,2,2,2,2,1
1,2,2,2,2,2,2,2,2,2,2,2,2,2,2,1
1,2,2,2,2,2,2,2,2,2,2,2,2,2,2,1
1,1,2,2,2,2,2,2,2,2,2,2,2,2,1,1
1,1,2,2,2,2,2,2,2,2,2,2,2,2,1,1
1,1,1,2,2,2,2,2,2,2,2,2,2,1,1,1
1,1,1,1,2,2,2,2,2,2,2,2,1,1,1,1
1,1,1,1,1,1,2,2,2,2,1,1,1,1,1,1
1,1,1,1,1,1,1,1,1,1,1,1,1,1,1,1
endlayer

layer
1,1,1,1,1,1,1,1,1,1,1,1,1,1,1,1
1,1,1,1,1,1,2,2,2,2,1,1,1,1,1,1
1,1,1,1,2,2,2,2,2,2,2,2,1,1,1,1
1,1,1,2,2,2,2,2,2,2,2,2,2,1,1,1
1,1,2,2,2,2,2,2,2,2,2,2,2,2,1,1
1,1,2,2,2,2,2,2,2,2,2,2,2,2,1,1
1,2,2,2,2,2,2,4,3,2,2,2,2,2,2,1
1,2,2,2,2,2,4,3,4,3,2,2,2,2,2,1
1,2,2,2,2,2,3,4,3,4,2,2,2,2,2,1
1,2,2,2,2,2,2,3,4,2,2,2,2,2,2,1
1,1,2,2,2,2,2,2,2,2,2,2,2,2,1,1
1,1,2,2,2,2,2,2,2,2,2,2,2,2,1,1
1,1,1,2,2,2,2,2,2,2,2,2,2,1,1,1
1,1,1,1,2,2,2,2,2,2,2,2,1,1,1,1
1,1,1,1,1,1,2,2,2,2,1,1,1,1,1,1
1,1,1,1,1,1,1,1,1,1,1,1,1,1,1,1
endlayer

layer
1,1,1,1,1,1,1,1,1,1,1,1,1,1,1,1
1,1,1,1,1,1,2,2,2,2,1,1,1,1,1,1
1,1,1,1,2,2,2,2,2,2,2,2,1,1,1,1
1,1,1,2,2,2,2,2,2,2,2,2,2,1,1,1
1,1,2,2,2,2,2,2,2,2,2,2,2,2,1,1
1,1,2,2,2,2,2,2,2,2,2,2,2,2,1,1
1,2,2,2,2,2,2,2,2,2,2,2,2,2,2,1
1,2,2,2,2,2,2,2,2,2,2,2,2,2,2,1
1,2,2,2,2,2,2,2,2,2,2,2,2,2,2,1
1,2,2,2,2,2,2,2,2,2,2,2,2,2,2,1
1,1,2,2,2,2,2,2,2,2,2,2,2,2,1,1
1,1,2,2,2,2,2,2,2,2,2,2,2,2,1,1
1,1,1,2,2,2,2,2,2,2,2,2,2,1,1,1
1,1,1,1,2,2,2,2,2,2,2,2,1,1,1,1
1,1,1,1,1,1,2,2,2,2,1,1,1,1,1,1
1,1,1,1,1,1,1,1,1,1,1,1,1,1,1,1
endlayer

layer
1,1,1,1,1,1,1,1,1,1,1,1,1,1,1,1
1,1,1,1,1,1,2,2,2,2,1,1,1,1,1,1
1,1,1,1,2,2,3,4,3,4,2,2,1,1,1,1
1,1,1,2,4,3,4,3,4,3,4,3,2,1,1,1
1,1,2,4,3,4,3,4,3,4,3,4,3,2,1,1
1,1,2,3,4,3,4,3,4,3,4,3,4,2,1,1
1,2,3,4,3,4,3,4,3,4,3,4,3,4,2,1
1,2,4,3,4,3,4,3,4,3,4,3,4,3,2,1
1,2,3,4,3,4,3,4,3,4,3,4,3,4,2,1
1,2,4,3,4,3,4,3,4,3,4,3,4,3,2,1
1,1,2,4,3,4,3,4,3,4,3,4,3,2,1,1
1,1,2,3,4,3,4,3,4,3,4,3,4,2,1,1
1,1,1,2,3,4,3,4,3,4,3,4,2,1,1,1
1,1,1,1,2,2,4,3,4,3,2,2,1,1,1,1
1,1,1,1,1,1,2,2,2,2,1,1,1,1,1,1
1,1,1,1,1,1,1,1,1,1,1,1,1,1,1,1
endlayer

layer
1,1,1,1,1,1,5,0,0,5,1,1,1,1,1,1
1,1,1,1,1,1,2,6,6,2,1,1,1,1,1,1
1,1,1,1,2,2,0,0,0,0,2,2,1,1,1,1
1,1,1,2,0,0,0,0,0,0,0,0,2,1,1,1
1,1,2,0,0,0,0,0,0,0,0,0,0,2,1,1
1,1,2,0,0,0,0,0,0,0,0,0,0,2,1,1
5,2,0,0,0,0,0,0,0,0,0,0,0,0,2,5
0,2,0,0,0,0,0,0,0,0,0,0,0,0,2,0
0,2,0,0,0,0,0,0,0,0,0,0,0,0,2,0
5,2,0,0,0,0,0,0,0,0,0,0,0,0,2,5
1,1,2,0,0,0,0,0,0,0,0,0,0,2,1,1
1,1,2,0,0,0,0,0,0,0,0,0,0,2,1,1
1,1,1,2,0,0,0,0,0,0,0,0,2,1,1,1
1,1,1,1,2,2,0,0,0,0,2,2,1,1,1,1
1,1,1,1,1,1,2,6,6,2,1,1,1,1,1,1
1,1,1,1,1,1,5,0,0,5,1,1,1,1,1,1
endlayer

layer
1,1,1,1,1,1,6,0,0,6,1,1,1,1,1,1
1,1,1,1,6,6,2,0,0,2,6,6,1,1,1,1
1,1,1,6,6,6,0,0,0,0,6,6,6,1,1,1
1,1,6,2,0,0,0,0,0,0,0,0,2,6,1,1
1,6,6,0,0,0,0,0,0,0,0,0,0,6,6,1
1,6,6,0,0,0,0,0,0,0,0,0,0,6,6,1
6,2,0,0,0,0,0,0,0,0,0,0,0,0,2,6
6,6,0,0,0,0,0,0,0,0,0,0,0,0,6,6
6,6,0,0,0,0,0,0,0,0,0,0,0,0,6,6
6,2,0,0,0,0,0,0,0,0,0,0,0,0,2,6
1,6,6,0,0,0,0,0,0,0,0,0,0,6,6,1
1,6,6,0,0,0,0,0,0,0,0,0,0,6,6,1
1,1,6,2,0,0,0,0,0,0,0,0,2,6,1,1
1,1,1,6,6,6,0,0,0,0,6,6,6,1,1,1
1,1,1,1,6,6,2,0,0,2,6,6,1,1,1,1
1,1,1,1,1,1,6,0,0,6,1,1,1,1,1,1
endlayer

layer
1,1,1,1,1,1,0,0,0,0,1,1,1,1,1,1
1,1,1,1,0,0,2,0,0,2,0,0,1,1,1,1
1,1,1,0,0,0,0,0,0,0,0,0,0,1,1,1
1,1,0,2,0,0,0,0,0,0,0,0,2,0,1,1
1,0,0,0,0,0,0,0,0,0,0,0,0,0,0,1
1,0,0,0,0,0,0,0,0,0,0,0,0,0,0,1
0,2,0,0,0,0,0,0,0,0,0,0,0,0,2,0
0,0,0,0,0,0,0,0,0,0,0,0,0,0,0,0
0,0,0,0,0,0,0,0,0,0,0,0,0,0,0,0
0,2,0,0,0,0,0,0,0,0,0,0,0,0,2,0
1,0,0,0,0,0,0,0,0,0,0,0,0,0,0,1
1,0,0,0,0,0,0,0,0,0,0,0,0,0,0,1
1,1,0,2,0,0,0,0,0,0,0,0,2,0,1,1
1,1,1,0,0,0,0,0,0,0,0,0,0,1,1,1
1,1,1,1,0,0,2,0,0,2,0,0,1,1,1,1
1,1,1,1,1,1,0,0,0,0,1,1,1,1,1,1
endlayer

layer
1,1,1,1,1,1,7,7,7,7,1,1,1,1,1,1
1,1,1,1,7,7,2,7,7,2,7,7,1,1,1,1
1,1,1,7,7,7,0,0,0,0,7,7,7,1,1,1
1,1,7,2,0,0,0,0,0,0,0,0,2,7,1,1
1,7,7,0,0,0,0,0,0,0,0,0,0,7,7,1
1,7,7,0,0,0,0,0,0,0,0,0,0,7,7,1
7,2,0,0,0,0,0,0,0,0,0,0,0,0,2,7
7,7,0,0,0,0,0,0,0,0,0,0,0,0,7,7
7,7,0,0,0,0,0,0,0,0,0,0,0,0,7,7
7,2,0,0,0,0,0,0,0,0,0,0,0,0,2,7
1,7,7,0,0,0,0,0,0,0,0,0,0,7,7,1
1,7,7,0,0,0,0,0,0,0,0,0,0,7,7,1
1,1,7,2,0,0,0,0,0,0,0,0,2,7,1,1
1,1,1,7,7,7,0,0,0,0,7,7,7,1,1,1
1,1,1,1,7,7,2,7,7,2,7,7,1,1,1,1
1,1,1,1,1,1,7,7,7,7,1,1,1,1,1,1
endlayer

layer
1,1,1,1,1,1,5,0,0,5,1,1,1,1,1,1
1,1,1,1,5,0,2,2,2,2,0,5,1,1,1,1
1,1,1,0,2,2,0,0,0,0,2,2,0,1,1,1
1,1,0,2,0,0,0,0,0,0,0,0,2,0,1,1
1,5,2,0,0,0,0,0,0,0,0,0,0,2,5,1
1,0,2,0,0,0,0,0,0,0,0,0,0,2,0,1
5,2,0,0,0,0,0,0,0,0,0,0,0,0,2,5
0,2,0,0,0,0,0,0,0,0,0,0,0,0,2,0
0,2,0,0,0,0,0,0,0,0,0,0,0,0,2,0
5,2,0,0,0,0,0,0,0,0,0,0,0,0,2,5
1,0,2,0,0,0,0,0,0,0,0,0,0,2,0,1
1,5,2,0,0,0,0,0,0,0,0,0,0,2,5,1
1,1,0,2,0,0,0,0,0,0,0,0,2,0,1,1
1,1,1,0,2,2,0,0,0,0,2,2,0,1,1,1
1,1,1,1,5,0,2,2,2,2,0,5,1,1,1,1
1,1,1,1,1,1,5,0,0,5,1,1,1,1,1,1
endlayer

layer
1,1,1,1,1,1,8,8,8,8,1,1,1,1,1,1
1,1,1,10,8,10,2,2,2,2,9,8,9,1,1,1
1,1,6,8,2,2,0,0,0,0,2,2,8,6,1,1
1,8,10,2,0,0,0,0,0,0,0,0,2,9,8,1
1,10,2,0,0,0,0,0,0,0,0,0,0,2,9,1
1,8,2,0,0,0,0,0,0,0,0,0,0,2,8,1
10,2,0,0,0,0,0,0,0,0,0,0,0,0,2,9
10,2,0,0,0,0,0,0,0,0,0,0,0,0,2,9
10,2,0,0,0,0,0,0,0,0,0,0,0,0,2,9
10,2,0,0,0,0,0,0,0,0,0,0,0,0,2,9
1,11,2,0,0,0,0,0,0,0,0,0,0,2,11,1
1,10,2,0,0,0,0,0,0,0,0,0,0,2,9,1
1,11,10,2,0,0,0,0,0,0,0,0,2,9,11,1
1,1,6,11,2,2,0,0,0,0,2,2,11,6,1,1
1,1,1,10,11,10,2,2,2,2,9,11,9,1,1,1
1,1,1,1,1,1,11,11,11,11,1,1,1,1,1,1
endlayer

layer
1,1,1,1,1,1,1,1,1,1,1,1,1,1,1,1
1,1,1,1,1,1,8,8,8,8,1,1,1,1,1,1
1,1,1,1,8,12,12,12,12,12,12,8,1,1,1,1
1,1,1,12,12,12,7,7,7,7,12,12,12,1,1,1
1,1,10,12,7,7,0,0,0,0,7,7,12,9,1,1
1,1,12,12,7,0,0,0,0,0,0,7,12,12,1,1
1,10,12,7,0,0,0,0,0,0,0,0,7,12,9,1
1,10,12,7,0,0,0,0,0,0,0,0,7,12,9,1
1,10,12,7,0,0,0,0,0,0,0,0,7,12,9,1
1,10,12,7,0,0,0,0,0,0,0,0,7,12,9,1
1,1,12,12,7,0,0,0,0,0,0,7,12,12,1,1
1,1,10,12,7,7,0,0,0,0,7,7,12,9,1,1
1,1,1,12,12,12,7,7,7,7,12,12,12,1,1,1
1,1,1,1,11,12,12,12,12,12,12,11,1,1,1,1
1,1,1,1,1,1,11,11,11,11,1,1,1,1,1,1
1,1,1,1,1,1,1,1,1,1,1,1,1,1,1,1
endlayer

layer
1,1,1,1,1,1,1,1,1,1,1,1,1,1,1,1
1,1,1,1,1,1,1,1,1,1,1,1,1,1,1,1
1,1,1,1,1,1,6,6,6,6,1,1,1,1,1,1
1,1,1,1,6,6,12,12,12,12,6,6,1,1,1,1
1,1,1,6,12,12,12,13,13,12,12,12,6,1,1,1
1,1,1,6,12,12,7,7,7,7,12,12,6,1,1,1
1,1,6,12,12,7,7,0,0,7,7,12,12,6,1,1
1,1,6,12,15,7,0,0,0,0,7,14,12,6,1,1
1,1,6,12,15,7,0,0,0,0,7,14,12,6,1,1
1,1,6,12,12,7,7,0,0,7,7,12,12,6,1,1
1,1,1,6,12,12,7,7,7,7,12,12,6,1,1,1
1,1,1,6,12,12,12,16,16,12,12,12,6,1,1,1
1,1,1,1,6,6,12,12,12,12,6,6,1,1,1,1
1,1,1,1,1,1,6,6,6,6,1,1,1,1,1,1
1,1,1,1,1,1,1,1,1,1,1,1,1,1,1,1
1,1,1,1,1,1,1,1,1,1,1,1,1,1,1,1
endlayer

layer
1,1,1,1,1,1,1,1,1,1,1,1,1,1,1,1
1,1,1,1,1,1,1,1,1,1,1,1,1,1,1,1
1,1,1,1,1,1,1,1,1,1,1,1,1,1,1,1
1,1,1,1,1,1,1,1,1,1,1,1,1,1,1,1
1,1,1,1,1,1,1,6,6,1,1,1,1,1,1,1
1,1,1,1,1,6,6,12,12,6,6,1,1,1,1,1
1,1,1,1,1,6,12,12,12,12,6,1,1,1,1,1
1,1,1,1,6,12,12,12,12,12,12,6,1,1,1,1
1,1,1,1,6,12,12,12,12,12,12,6,1,1,1,1
1,1,1,1,1,6,12,12,12,12,6,1,1,1,1,1
1,1,1,1,1,6,6,12,12,6,6,1,1,1,1,1
1,1,1,1,1,1,1,6,6,1,1,1,1,1,1,1
1,1,1,1,1,1,1,1,1,1,1,1,1,1,1,1
1,1,1,1,1,1,1,1,1,1,1,1,1,1,1,1
1,1,1,1,1,1,1,1,1,1,1,1,1,1,1,1
1,1,1,1,1,1,1,1,1,1,1,1,1,1,1,1
endlayer

