
# Created by Ruins mod version 17.0 Ingame Parser
# authoring Player: ST753M

weight=1
embed_into_distance=5
acceptable_target_blocks=
unacceptable_target_blocks=flowing_water,water,flowing_lava,lava
dimensions=13,15,15
allowable_overhang=5
max_leveling=2
leveling_buffer=0
preserve_water=0
preserve_lava=0
uniqueMinDistance=1000

biomesToSpawnIn=jungle,jungle_edge,jungle_hills,tropical_island,tropical_rainforest,rainforest,mutated_jungle,mutated_jungle_edge,bamboo_forest,overgrown_cliffs,eucalyptus_forest,mini_jungle,birch_forest,birch_forest_hills,mutated_birch_forest,mutated_birch_forest_hills,birch_forested_hills,cherry_blossom_grove,mutated_forest,mutated_plains,flower_field,lavender_fields,flower_island

=0,100,preserveBlock
rule1=0,100,minecraft:stonebrick-0
rule2=0,100,minecraft:stone-0

rule3=0,100,minecraft:gray_glazed_terracotta-0
^0,100,minecraft:white_glazed_terracotta-0
^0,100,minecraft:orange_glazed_terracotta-0
^0,100,minecraft:light_blue_glazed_terracotta-0
^0,100,minecraft:yellow_glazed_terracotta-0
^0,100,minecraft:lime_glazed_terracotta-0
^0,100,minecraft:pink_glazed_terracotta-0
^0,100,minecraft:gray_glazed_terracotta-0
^0,100,minecraft:silver_glazed_terracotta-0
^0,100,minecraft:cyan_glazed_terracotta-0
^0,100,minecraft:purple_glazed_terracotta-0
^0,100,minecraft:blue_glazed_terracotta-0
^0,100,minecraft:brown_glazed_terracotta-0
^0,100,minecraft:green_glazed_terracotta-0
^0,100,minecraft:red_glazed_terracotta-0
^0,100,minecraft:black_glazed_terracotta-0

rule4^0,100,minecraft:gray_glazed_terracotta-3
^0,100,minecraft:white_glazed_terracotta-3
^0,100,minecraft:orange_glazed_terracotta-3
^0,100,minecraft:light_blue_glazed_terracotta-3
^0,100,minecraft:yellow_glazed_terracotta-3
^0,100,minecraft:lime_glazed_terracotta-3
^0,100,minecraft:pink_glazed_terracotta-3
^0,100,minecraft:gray_glazed_terracotta-3
^0,100,minecraft:silver_glazed_terracotta-3
^0,100,minecraft:cyan_glazed_terracotta-3
^0,100,minecraft:purple_glazed_terracotta-3
^0,100,minecraft:blue_glazed_terracotta-3
^0,100,minecraft:brown_glazed_terracotta-3
^0,100,minecraft:green_glazed_terracotta-3
^0,100,minecraft:red_glazed_terracotta-3
^0,100,minecraft:black_glazed_terracotta-3

rule5^0,100,minecraft:gray_glazed_terracotta-1
^0,100,minecraft:white_glazed_terracotta-1
^0,100,minecraft:orange_glazed_terracotta-1
^0,100,minecraft:light_blue_glazed_terracotta-1
^0,100,minecraft:yellow_glazed_terracotta-1
^0,100,minecraft:lime_glazed_terracotta-1
^0,100,minecraft:pink_glazed_terracotta-1
^0,100,minecraft:gray_glazed_terracotta-1
^0,100,minecraft:silver_glazed_terracotta-1
^0,100,minecraft:cyan_glazed_terracotta-1
^0,100,minecraft:purple_glazed_terracotta-1
^0,100,minecraft:blue_glazed_terracotta-1
^0,100,minecraft:brown_glazed_terracotta-1
^0,100,minecraft:green_glazed_terracotta-1
^0,100,minecraft:red_glazed_terracotta-1
^0,100,minecraft:black_glazed_terracotta-1

rule6^0,100,minecraft:gray_glazed_terracotta-2
^0,100,minecraft:white_glazed_terracotta-2
^0,100,minecraft:orange_glazed_terracotta-2
^0,100,minecraft:light_blue_glazed_terracotta-2
^0,100,minecraft:yellow_glazed_terracotta-2
^0,100,minecraft:lime_glazed_terracotta-2
^0,100,minecraft:pink_glazed_terracotta-2
^0,100,minecraft:gray_glazed_terracotta-2
^0,100,minecraft:silver_glazed_terracotta-2
^0,100,minecraft:cyan_glazed_terracotta-2
^0,100,minecraft:purple_glazed_terracotta-2
^0,100,minecraft:blue_glazed_terracotta-2
^0,100,minecraft:brown_glazed_terracotta-2
^0,100,minecraft:green_glazed_terracotta-2
^0,100,minecraft:red_glazed_terracotta-2
^0,100,minecraft:black_glazed_terracotta-2

rule7=0,100,minecraft:stone_brick_stairs-0
rule8=0,100,minecraft:stone_brick_stairs-3
rule9=0,100,minecraft:stone_brick_stairs-2
rule10=0,100,minecraft:stone_brick_stairs-1
rule11=0,100,minecraft:stone_brick_stairs-6
rule12=0,100,minecraft:stone_brick_stairs-4
rule13=0,100,minecraft:stone_brick_stairs-7
rule14=0,100,minecraft:stone_brick_stairs-5
rule15=0,100,minecraft:double_stone_slab-5
rule16=0,100,minecraft:stone_slab-13
rule17=0,100,minecraft:stone_slab-5

layer
1,1,1,1,1,1,1,1,1,1,1,1,1,1,1
1,2,2,2,2,2,2,2,2,2,2,2,2,2,1
1,2,2,2,2,2,2,2,2,2,2,2,2,2,1
1,2,2,2,2,2,2,2,2,2,2,2,2,2,1
1,2,2,2,2,2,2,2,2,2,2,2,2,2,1
1,2,2,2,2,2,2,2,2,2,2,2,2,2,1
1,2,2,2,2,2,2,2,2,2,2,2,2,2,1
1,2,2,2,2,2,2,2,2,2,2,2,2,2,1
1,2,2,2,2,2,2,2,2,2,2,2,2,2,1
1,2,2,2,2,2,2,2,2,2,2,2,2,2,1
1,2,2,2,2,2,2,2,2,2,2,2,2,2,1
1,2,2,2,2,2,2,2,2,2,2,2,2,2,1
1,2,2,2,2,2,2,2,2,2,2,2,2,2,1
1,2,2,2,2,2,2,2,2,2,2,2,2,2,1
1,1,1,1,1,1,1,1,1,1,1,1,1,1,1
endlayer

layer
1,1,1,1,1,1,1,1,1,1,1,1,1,1,1
1,2,2,2,2,2,2,2,2,2,2,2,2,2,1
1,2,2,2,2,2,2,2,2,2,2,2,2,2,1
1,2,2,2,2,2,2,2,2,2,2,2,2,2,1
1,2,2,2,2,2,2,2,2,2,2,2,2,2,1
1,2,2,2,2,2,2,2,2,2,2,2,2,2,1
1,2,2,2,2,2,2,2,2,2,2,2,2,2,1
1,2,2,2,2,2,2,2,2,2,2,2,2,2,1
1,2,2,2,2,2,2,2,2,2,2,2,2,2,1
1,2,2,2,2,2,2,2,2,2,2,2,2,2,1
1,2,2,2,2,2,2,2,2,2,2,2,2,2,1
1,2,2,2,2,2,2,2,2,2,2,2,2,2,1
1,2,2,2,2,2,2,2,2,2,2,2,2,2,1
1,2,2,2,2,2,2,2,2,2,2,2,2,2,1
1,1,1,1,1,1,1,1,1,1,1,1,1,1,1
endlayer

layer
1,1,1,1,1,1,1,1,1,1,1,1,1,1,1
1,2,2,2,2,2,2,2,2,2,2,2,2,2,1
1,2,2,2,2,2,2,2,2,2,2,2,2,2,1
1,2,2,2,2,2,2,2,2,2,2,2,2,2,1
1,2,2,2,2,2,2,2,2,2,2,2,2,2,1
1,2,2,2,2,2,2,2,2,2,2,2,2,2,1
1,2,2,2,2,2,2,2,2,2,2,2,2,2,1
1,2,2,2,2,2,2,2,2,2,2,2,2,2,1
1,2,2,2,2,2,2,2,2,2,2,2,2,2,1
1,2,2,2,2,2,2,2,2,2,2,2,2,2,1
1,2,2,2,2,2,2,2,2,2,2,2,2,2,1
1,2,2,2,2,2,2,2,2,2,2,2,2,2,1
1,2,2,2,2,2,2,2,2,2,2,2,2,2,1
1,2,2,2,2,2,2,2,2,2,2,2,2,2,1
1,1,1,1,1,1,1,1,1,1,1,1,1,1,1
endlayer

layer
1,1,1,1,1,1,1,1,1,1,1,1,1,1,1
1,2,2,2,2,2,2,2,2,2,2,2,2,2,1
1,2,2,2,2,2,2,2,2,2,2,2,2,2,1
1,2,2,2,2,2,2,2,2,2,2,2,2,2,1
1,2,2,2,2,2,2,2,2,2,2,2,2,2,1
1,2,2,2,2,2,2,2,2,2,2,2,2,2,1
1,2,2,2,2,2,2,2,2,2,2,2,2,2,1
1,2,2,2,2,2,2,2,2,2,2,2,2,2,1
1,2,2,2,2,2,2,2,2,2,2,2,2,2,1
1,2,2,2,2,2,2,2,2,2,2,2,2,2,1
1,2,2,2,2,2,2,2,2,2,2,2,2,2,1
1,2,2,2,2,2,2,2,2,2,2,2,2,2,1
1,2,2,2,2,2,2,2,2,2,2,2,2,2,1
1,2,2,2,2,2,2,2,2,2,2,2,2,2,1
1,1,1,1,1,1,1,1,1,1,1,1,1,1,1
endlayer

layer
1,1,1,1,1,1,1,1,1,1,1,1,1,1,1
1,2,2,2,2,2,2,2,2,2,2,2,2,2,1
1,2,2,2,2,2,2,2,2,2,2,2,2,2,1
1,2,2,3,4,3,4,3,4,3,4,3,2,2,1
1,2,2,5,6,5,6,5,6,5,6,5,2,2,1
1,2,2,3,4,3,4,3,4,3,4,3,2,2,1
1,2,2,5,6,5,6,5,6,5,6,5,2,2,1
1,2,2,3,4,3,4,3,4,3,4,3,2,2,1
1,2,2,5,6,5,6,5,6,5,6,5,2,2,1
1,2,2,3,4,3,4,3,4,3,4,3,2,2,1
1,2,2,5,6,5,6,5,6,5,6,5,2,2,1
1,2,2,3,4,3,4,3,4,3,4,3,2,2,1
1,2,2,2,2,2,2,2,2,2,2,2,2,2,1
1,2,2,2,2,2,2,2,2,2,2,2,2,2,1
1,1,1,1,1,1,1,1,1,1,1,1,1,1,1
endlayer

layer
8,7,9,8,7,9,8,7,9,8,7,9,8,7,7
8,1,9,8,1,9,8,1,9,8,1,9,8,1,9
10,10,9,8,10,9,8,10,9,8,10,9,8,10,10
7,7,7,0,0,0,0,0,0,0,0,0,7,7,7
8,1,9,0,0,0,0,0,0,0,0,0,8,1,9
10,10,10,0,0,0,0,0,0,0,0,0,10,10,10
7,7,7,0,0,0,0,0,0,0,0,0,7,7,7
8,1,9,0,0,0,0,0,0,0,0,0,8,1,9
10,10,10,0,0,0,0,0,0,0,0,0,10,10,10
7,7,7,0,0,0,0,0,0,0,0,0,7,7,7
8,1,9,0,0,0,0,0,0,0,0,0,8,1,9
10,10,10,0,0,0,0,0,0,0,0,0,10,10,10
7,7,9,7,7,7,8,7,9,7,7,9,8,7,9
8,1,9,8,1,9,8,1,9,8,1,9,8,1,9
10,10,9,10,10,9,8,10,9,8,10,9,8,10,9
endlayer

layer
0,0,0,0,0,0,0,0,0,0,0,0,0,0,0
0,1,0,0,1,0,0,1,0,0,1,0,0,1,0
0,0,0,0,0,0,0,0,0,0,0,0,0,0,0
0,0,0,0,0,0,0,0,0,0,0,0,0,0,0
0,1,0,0,0,0,0,0,0,0,0,0,0,1,0
0,0,0,0,0,0,0,0,0,0,0,0,0,0,0
0,0,0,0,0,0,0,0,0,0,0,0,0,0,0
0,1,0,0,0,0,0,0,0,0,0,0,0,1,0
0,0,0,0,0,0,0,0,0,0,0,0,0,0,0
0,0,0,0,0,0,0,0,0,0,0,0,0,0,0
0,1,0,0,0,0,0,0,0,0,0,0,0,1,0
0,0,0,0,0,0,0,0,0,0,0,0,0,0,0
0,0,0,0,0,0,0,0,0,0,0,0,0,0,0
0,1,0,0,1,0,0,1,0,0,1,0,0,1,0
0,0,0,0,0,0,0,0,0,0,0,0,0,0,0
endlayer

layer
0,0,0,0,0,0,0,0,0,0,0,0,0,0,0
0,1,0,0,1,0,0,1,0,0,1,0,0,1,0
0,0,0,0,0,0,0,0,0,0,0,0,0,0,0
0,0,0,0,0,0,0,0,0,0,0,0,0,0,0
0,1,0,0,0,0,0,0,0,0,0,0,0,1,0
0,0,0,0,0,0,0,0,0,0,0,0,0,0,0
0,0,0,0,0,0,0,0,0,0,0,0,0,0,0
0,1,0,0,0,0,0,0,0,0,0,0,0,1,0
0,0,0,0,0,0,0,0,0,0,0,0,0,0,0
0,0,0,0,0,0,0,0,0,0,0,0,0,0,0
0,1,0,0,0,0,0,0,0,0,0,0,0,1,0
0,0,0,0,0,0,0,0,0,0,0,0,0,0,0
0,0,0,0,0,0,0,0,0,0,0,0,0,0,0
0,1,0,0,1,0,0,1,0,0,1,0,0,1,0
0,0,0,0,0,0,0,0,0,0,0,0,0,0,0
endlayer

layer
0,0,0,0,0,0,0,0,0,0,0,0,0,0,0
0,1,0,0,1,0,0,1,0,0,1,0,0,1,0
0,0,0,0,0,0,0,0,0,0,0,0,0,0,0
0,0,0,0,0,0,0,0,0,0,0,0,0,0,0
0,1,0,0,0,0,0,0,0,0,0,0,0,1,0
0,0,0,0,0,0,0,0,0,0,0,0,0,0,0
0,0,0,0,0,0,0,0,0,0,0,0,0,0,0
0,1,0,0,0,0,0,0,0,0,0,0,0,1,0
0,0,0,0,0,0,0,0,0,0,0,0,0,0,0
0,0,0,0,0,0,0,0,0,0,0,0,0,0,0
0,1,0,0,0,0,0,0,0,0,0,0,0,1,0
0,0,0,0,0,0,0,0,0,0,0,0,0,0,0
0,0,0,0,0,0,0,0,0,0,0,0,0,0,0
0,1,0,0,1,0,0,1,0,0,1,0,0,1,0
0,0,0,0,0,0,0,0,0,0,0,0,0,0,0
endlayer

layer
13,12,11,13,12,11,13,12,11,13,12,11,12,12,11
13,1,11,13,1,11,13,1,11,13,1,11,13,1,11
14,14,14,13,14,11,13,14,11,13,14,11,14,14,14
12,12,12,0,0,0,0,0,0,0,0,0,12,12,12
13,1,11,0,0,0,0,0,0,0,0,0,13,1,11
14,14,14,0,0,0,0,0,0,0,0,0,14,14,14
12,12,12,0,0,0,0,0,0,0,0,0,12,12,12
13,1,11,0,0,0,0,0,0,0,0,0,13,1,11
14,14,14,0,0,0,0,0,0,0,0,0,14,14,14
12,12,12,0,0,0,0,0,0,0,0,0,12,12,12
13,1,11,0,0,0,0,0,0,0,0,0,13,1,11
14,14,14,0,0,0,0,0,0,0,0,0,14,14,14
12,12,11,13,12,11,13,12,11,13,12,11,12,12,12
13,1,11,13,1,11,13,1,11,13,1,11,13,1,11
13,14,11,13,14,11,13,14,11,13,14,11,13,14,11
endlayer

layer
15,15,15,16,16,0,0,0,0,0,16,16,15,15,15
15,1,1,6,4,6,6,3,4,5,3,4,1,1,15
15,1,15,16,16,0,0,0,0,0,16,16,15,1,15
16,3,16,0,0,0,0,0,0,0,0,0,16,6,16
16,3,16,0,0,0,0,0,0,0,0,0,16,3,16
0,3,0,0,0,0,0,0,0,0,0,0,0,4,0
0,6,0,0,0,0,0,0,0,0,0,0,0,6,0
0,3,0,0,0,0,0,0,0,0,0,0,0,3,0
0,5,0,0,0,0,0,0,0,0,0,0,0,3,0
0,5,0,0,0,0,0,0,0,0,0,0,0,5,0
16,5,16,0,0,0,0,0,0,0,0,0,16,5,16
16,4,16,0,0,0,0,0,0,0,0,0,16,6,16
15,1,15,16,16,0,0,0,0,0,16,16,15,1,15
15,1,1,6,6,6,5,6,5,6,5,6,1,1,15
15,15,15,16,16,0,0,0,0,0,16,16,15,15,15
endlayer

layer
0,0,0,17,17,15,11,16,13,15,17,17,0,0,0
0,0,17,17,15,1,6,6,4,1,15,17,17,0,0
0,17,17,17,17,15,11,16,13,15,17,17,17,17,0
17,17,17,0,0,0,0,0,0,0,0,0,17,17,17
17,15,17,0,0,0,0,0,0,0,0,0,17,15,17
15,1,15,0,0,0,0,0,0,0,0,0,15,1,15
14,6,14,0,0,0,0,0,0,0,0,0,14,6,14
16,4,16,0,0,0,0,0,0,0,0,0,16,4,16
12,5,12,0,0,0,0,0,0,0,0,0,12,3,12
15,1,15,0,0,0,0,0,0,0,0,0,15,1,15
17,15,17,0,0,0,0,0,0,0,0,0,17,15,17
17,17,17,0,0,0,0,0,0,0,0,0,17,17,17
0,17,17,17,17,15,11,16,13,15,17,17,17,17,0
0,0,17,17,15,1,3,4,4,1,15,17,17,0,0
0,0,0,17,17,15,11,16,13,15,17,17,0,0,0
endlayer

layer
0,0,0,0,0,0,0,17,0,0,0,0,0,0,0
0,0,0,0,0,0,17,17,17,0,0,0,0,0,0
0,0,0,0,0,0,0,17,0,0,0,0,0,0,0
0,0,0,0,0,0,0,0,0,0,0,0,0,0,0
0,0,0,0,0,0,0,0,0,0,0,0,0,0,0
0,0,0,0,0,0,0,0,0,0,0,0,0,0,0
0,17,0,0,0,0,0,0,0,0,0,0,0,17,0
17,17,17,0,0,0,0,0,0,0,0,0,17,17,17
0,17,0,0,0,0,0,0,0,0,0,0,0,17,0
0,0,0,0,0,0,0,0,0,0,0,0,0,0,0
0,0,0,0,0,0,0,0,0,0,0,0,0,0,0
0,0,0,0,0,0,0,0,0,0,0,0,0,0,0
0,0,0,0,0,0,0,17,0,0,0,0,0,0,0
0,0,0,0,0,0,17,17,17,0,0,0,0,0,0
0,0,0,0,0,0,0,17,0,0,0,0,0,0,0
endlayer

