
# Created by Ruins mod version 16.9 Ingame Parser
# authoring Player: ST753M

# House shaped like a boot

weight=1
uniqueMinDistance=1000
embed_into_distance=1
acceptable_target_blocks=grass,dirt,podzol
unacceptable_target_blocks=flowing_water,water,flowing_lava,lava,ice,bedrock,netherrack,nether_brick,nether_brick_fence,soul_sand,quartz_ore,end_stone,obsidian,iron_bars,Natura:Cloud,slime_grass,slime_congealed,slime_dirt,clouds,natura:clouds
dimensions=13,20,20
allowable_overhang=2
max_leveling=0
leveling_buffer=0
preserve_water=0
preserve_lava=0

biomesToSpawnIn=mutated_forest,flower_forest,sacred_springs,mutated_birch_forest,flower_field,lavender_fields,flower_island,origin_island,mystic_grove

rule1=0,100,preserveBlock
rule2=0,100,minecraft:dirt-0
rule3=0,100,minecraft:planks-1
rule4=0,100,minecraft:log-1
rule5=0,100,minecraft:grass-0
rule6=0,100,minecraft:spruce_stairs-4
rule7=0,100,minecraft:dark_oak_door-2
rule8=0,100,minecraft:dark_oak_door-3
rule9=0,100,minecraft:dark_oak_stairs-3
rule10=0,100,minecraft:dark_oak_fence-0
rule11=0,100,minecraft:dark_oak_stairs-2
rule12=0,100,minecraft:furnace-2
rule13=0,100,minecraft:spruce_stairs-7
rule14=0,100,minecraft:crafting_table-0
rule15=0,100,minecraft:spruce_stairs-6
rule16=0,100,minecraft:double_plant-4
rule17=0,100,minecraft:trapdoor-5
rule18=0,100,minecraft:bookshelf-0
rule19=0,100,minecraft:dark_oak_door-1
rule20=0,100,minecraft:trapdoor-6
rule21=0,100,minecraft:spruce_stairs-5
rule22=0,100,minecraft:carpet-0
^0,100,minecraft:carpet-1
^0,100,minecraft:carpet-2
^0,100,minecraft:carpet-3
^0,100,minecraft:carpet-4
^0,100,minecraft:carpet-5
^0,100,minecraft:carpet-6
^0,100,minecraft:carpet-7
^0,100,minecraft:carpet-8
^0,100,minecraft:carpet-9
^0,100,minecraft:carpet-10
^0,100,minecraft:carpet-11
^0,100,minecraft:carpet-12
^0,100,minecraft:carpet-13
^0,100,minecraft:carpet-14
^0,100,minecraft:carpet-15
rule23=0,100,minecraft:bed-10
rule24=0,100,minecraft:bed-2
rule25=0,100,minecraft:dark_oak_stairs-6
rule26=0,100,minecraft:dark_oak_stairs-0
rule27=0,100,minecraft:flower_pot-1
rule28=0,100,minecraft:stained_glass-12
rule29=0,100,minecraft:dark_oak_door-8
rule30=0,100,minecraft:dark_oak_door-9
rule31=0,100,minecraft:trapdoor-0
rule32=0,100,minecraft:double_plant-10
rule33=0,100,ChestGenHook:chests/stronghold_library:5-5,IInventory;minecraft:chest;minecraft:written_book#{title:"Old Book",author:"Unknown",pages:["'Humpty Dumpty sat on a wall, Humpty Dumpty had a big fall.  All the kings horses and all the kings men, Couldnt put Humpty together again.'","'Humpty Dumpty sat on a wall, Humpty Dumpty had a great fall.  Four-score men and four-score more, Could not make Humpty himself once more.'"]}#0#4-3,IInventory;minecraft:chest;minecraft:written_book#{title:"Little Book",author:"Unknown",pages:["'Jack and Jill went up the hill to fetch a pail of water.  Jack fell down and broke his crown, and Jill came tumbling after.'","'Up Jack got, and home did trot as fast as he could caper, and went to bed and bound his head with vinegar and brown paper.'","'Then Jill came in, and she did grin, to see Jacks paper plaster; Her mother whipped her across the knee, for causing Jacks disaster.'"]}#0#4-3,IInventory;minecraft:chest;minecraft:written_book#{title:"Worn-Out Book",author:"Unknown",pages:["'Little boy Blue come blow your horn, the sheeps in the meadow, the cows in the corn.  But where is the boy who looks after the sheep?'","'Hes under a haystack.  Hes fast asleep.  Will you wake him?  No, not I, for if I do hes sure to cry.'"]}#0#4-3
rule34=0,100,minecraft:wooden_slab-13
rule35=0,50,minecraft:web-0
rule36=0,100,minecraft:dark_oak_stairs-5
rule37=0,100,minecraft:dark_oak_stairs-7
rule38=0,100,minecraft:planks-5
rule39=0,100,minecraft:dark_oak_stairs-4
rule40=0,100,minecraft:dark_oak_stairs-1
rule41=0,100,minecraft:wooden_slab-5
rule42=0,100,minecraft:double_wooden_slab-5
rule43=0,100,minecraft:bed-0
rule44=0,100,minecraft:bed-8
rule45=0,100,minecraft:trapdoor-8
rule46=0,100,minecraft:spruce_stairs-0
rule47=0,100,minecraft:spruce_stairs-2
rule48=0,100,minecraft:spruce_stairs-3
rule49=0,100,minecraft:spruce_stairs-1

layer
1,1,1,1,1,1,1,1,1,1,1,1,1,1,1,1,1,1,1,1
1,1,1,1,1,3,3,1,1,1,2,2,2,1,1,1,1,1,1,1
1,1,1,3,3,3,3,3,3,2,2,2,2,2,1,1,1,1,1,1
1,1,3,3,3,3,3,3,3,3,2,2,2,2,1,1,1,1,1,1
1,3,3,3,3,3,3,3,3,3,3,2,2,2,1,1,1,1,1,1
1,3,3,3,3,3,3,3,3,3,3,3,2,1,1,1,1,1,1,1
1,3,3,3,3,3,3,3,3,3,3,3,3,1,1,1,1,1,1,1
1,1,3,3,3,3,3,3,3,3,3,3,3,1,1,1,1,1,1,1
1,1,3,3,3,3,3,3,3,3,3,3,1,1,1,1,1,1,1,1
1,1,1,3,3,3,3,3,3,3,3,1,1,1,1,1,1,1,1,1
1,1,1,1,3,3,3,3,3,3,1,1,1,3,3,3,1,1,1,1
1,1,1,1,1,3,3,3,3,1,1,1,3,3,3,3,3,1,1,1
1,1,1,1,1,1,3,3,1,1,1,3,3,3,3,3,3,3,1,1
1,1,1,1,1,1,1,1,1,1,3,3,3,3,3,3,3,3,3,1
1,1,1,1,1,1,1,1,1,1,3,3,3,3,3,3,3,3,3,1
1,1,1,1,1,1,1,1,1,1,3,3,3,3,3,3,3,3,3,1
1,1,1,1,1,1,1,1,1,1,1,3,3,3,3,3,3,3,3,1
1,1,1,1,1,1,1,1,1,1,1,1,3,3,3,3,3,3,1,1
1,1,1,1,1,1,1,1,1,1,1,1,1,3,3,3,3,1,1,1
1,1,1,1,1,1,1,1,1,1,1,1,1,1,1,1,1,1,1,1
endlayer

layer
1,1,1,1,1,1,1,1,1,1,1,1,1,1,1,1,1,1,1,1
1,1,1,1,1,3,3,1,1,1,1,1,1,1,1,1,1,1,1,1
1,1,1,3,3,3,3,3,3,1,2,2,1,1,1,1,1,1,1,1
1,1,3,3,3,3,3,3,3,3,2,2,2,1,1,1,1,1,1,1
1,3,3,3,3,3,3,3,3,3,3,2,2,1,1,1,1,1,1,1
1,3,3,3,3,3,3,3,3,3,3,3,1,1,1,1,1,1,1,1
1,3,3,3,3,3,3,3,3,3,3,3,3,1,1,1,1,1,1,1
1,1,3,3,3,3,3,3,3,3,3,3,3,1,1,1,1,1,1,1
1,1,3,3,3,3,3,3,3,3,3,3,5,4,1,1,1,1,1,1
1,1,1,3,3,3,3,3,3,3,3,3,5,3,4,1,1,1,1,1
1,1,1,1,3,3,3,3,3,3,3,3,3,3,3,3,1,1,1,1
1,1,1,1,1,3,3,3,3,3,3,3,3,3,3,3,3,1,1,1
1,1,1,1,1,1,3,3,5,5,3,3,3,3,3,3,3,3,1,1
1,1,1,1,1,1,1,1,4,3,3,3,3,3,3,3,3,3,3,1
1,1,1,1,1,1,1,1,1,4,3,3,3,3,3,3,3,3,3,1
1,1,1,1,1,1,1,1,1,1,3,3,3,3,3,3,3,3,3,1
1,1,1,1,1,1,1,1,1,1,1,3,3,3,3,3,3,3,3,1
1,1,1,1,1,1,1,1,1,1,1,1,3,3,3,3,3,3,1,1
1,1,1,1,1,1,1,1,1,1,1,1,1,3,3,3,3,1,1,1
1,1,1,1,1,1,1,1,1,1,1,1,1,1,1,1,1,1,1,1
endlayer

layer
1,1,1,1,1,1,1,1,1,1,1,1,1,1,1,1,1,1,1,1
1,1,1,1,6,4,4,6,1,1,1,1,1,1,1,1,1,1,1,1
1,1,1,4,4,0,0,4,4,1,1,1,1,1,1,1,1,1,1,1
1,1,4,0,0,0,0,0,0,4,7,1,1,1,1,1,1,1,1,1
1,4,12,0,11,10,10,9,0,0,0,8,1,1,1,1,1,1,1,1
13,4,12,0,0,10,10,0,0,0,0,4,1,1,1,1,1,1,1,1
1,4,14,0,11,10,10,9,0,0,0,0,4,1,1,1,1,1,1,1
1,1,4,0,0,10,10,0,0,0,0,0,4,15,1,1,1,1,1,1
1,1,4,0,11,10,10,9,0,0,0,17,16,4,1,1,1,1,1,1
1,1,1,4,0,0,0,0,0,0,0,17,16,4,4,1,1,1,1,1
1,1,1,13,4,0,0,0,0,0,0,7,4,18,18,4,6,6,1,1
1,1,1,21,21,4,0,0,20,20,19,0,0,0,0,0,4,15,1,1
1,1,1,1,1,1,4,4,16,16,4,0,0,22,22,0,0,4,1,1
1,1,1,1,1,1,1,1,4,4,18,0,22,22,22,22,0,0,4,1
1,1,1,1,1,1,1,1,1,4,18,0,22,22,22,22,24,23,4,15
1,1,1,1,1,1,1,1,1,1,4,0,0,22,22,0,24,23,4,15
1,1,1,1,1,1,1,1,1,1,13,4,0,0,0,0,0,0,4,1
1,1,1,1,1,1,1,1,1,1,21,21,4,26,25,0,0,4,1,1
1,1,1,1,1,1,1,1,1,1,1,1,1,4,4,4,4,1,1,1
1,1,1,1,1,1,1,1,1,1,1,1,1,1,1,1,1,1,1,1
endlayer

layer
1,1,1,1,1,1,1,1,1,1,1,1,1,1,1,1,1,1,1,1
1,1,1,1,27,4,4,27,1,1,1,1,1,1,1,1,1,1,1,1
1,1,1,4,28,0,0,28,4,1,1,1,1,1,1,1,1,1,1,1
1,1,4,0,0,0,0,0,0,4,29,1,1,1,1,1,1,1,1,1
1,4,0,0,0,31,31,0,0,0,0,30,1,1,1,1,1,1,1,1
27,28,0,0,0,31,31,0,0,0,0,4,1,1,1,1,1,1,1,1
1,4,0,0,0,31,31,0,0,0,0,0,4,1,1,1,1,1,1,1
1,1,4,0,0,31,31,0,0,0,0,0,28,27,1,1,1,1,1,1
1,1,4,0,0,31,31,0,0,0,0,0,32,4,1,1,1,1,1,1
1,1,1,4,0,0,0,0,0,0,0,0,32,4,4,1,1,1,1,1
1,1,1,1,28,0,0,0,0,0,0,30,4,18,18,4,27,0,1,1
1,1,1,27,27,4,6,6,0,0,29,0,0,0,0,0,28,27,1,1
1,1,1,1,1,1,4,4,32,32,4,0,0,0,0,0,0,4,1,1
1,1,1,1,1,1,1,1,4,4,18,0,0,0,0,0,0,0,4,1
1,1,1,1,1,1,1,1,1,4,18,0,0,0,0,0,0,0,28,0
1,1,1,1,1,1,1,1,1,1,4,0,0,0,0,0,0,0,28,27
1,1,1,1,1,1,1,1,1,1,27,28,0,0,0,0,0,0,4,1
1,1,1,1,1,1,1,1,1,1,0,27,4,0,9,25,0,4,1,1
1,1,1,1,1,1,1,1,1,1,1,1,1,4,4,4,4,1,1,1
1,1,1,1,1,1,1,1,1,1,1,1,1,1,1,1,1,1,1,1
endlayer

layer
1,1,1,1,1,1,1,1,1,1,1,1,1,1,1,1,1,1,1,1
1,1,1,1,0,4,4,0,1,1,1,1,1,1,1,1,1,1,1,1
1,1,1,4,28,0,0,28,4,1,1,1,1,1,1,1,1,1,1,1
1,1,4,0,0,0,0,0,0,4,1,1,1,1,1,1,1,1,1,1
1,4,0,0,0,0,0,0,0,0,4,1,1,1,1,1,1,1,1,1
0,28,0,0,0,0,0,0,0,0,0,4,1,1,1,1,1,1,1,1
1,4,0,0,0,0,0,0,0,0,0,0,4,1,1,1,1,1,1,1
1,1,4,0,0,0,0,0,0,0,0,0,28,0,1,1,1,1,1,1
1,1,4,0,0,0,0,0,0,0,0,0,0,4,1,1,1,1,1,1
1,1,1,4,0,0,0,0,0,0,0,0,0,4,4,1,1,1,1,1
1,1,1,1,28,0,0,0,0,0,0,0,4,33,0,4,0,0,1,1
1,1,1,1,0,4,0,27,0,0,0,4,0,0,0,0,28,0,1,1
1,1,1,1,1,1,4,4,0,0,4,0,0,0,0,0,0,4,1,1
1,1,1,1,1,1,1,1,4,4,0,0,0,0,0,0,0,0,4,1
1,1,1,1,1,1,1,1,1,4,0,0,0,0,0,0,0,0,28,0
1,1,1,1,1,1,1,1,1,1,4,0,0,0,0,0,0,0,28,0
1,1,1,1,1,1,1,1,1,1,0,28,0,0,0,0,0,0,4,1
1,1,1,1,1,1,1,1,1,1,0,0,4,0,0,9,25,4,1,1
1,1,1,1,1,1,1,1,1,1,1,1,1,4,4,4,4,1,1,1
1,1,1,1,1,1,1,1,1,1,1,1,1,1,1,1,1,1,1,1
endlayer

layer
1,1,1,1,1,34,34,1,1,1,1,1,1,1,1,1,1,1,1,1
1,1,1,34,34,4,4,34,34,1,1,1,1,1,1,1,1,1,1,1
1,1,34,4,4,0,0,4,4,34,1,1,1,1,1,1,1,1,1,1
1,34,4,0,0,0,0,0,0,4,34,1,1,1,1,1,1,1,1,1
34,4,0,0,0,0,0,0,0,0,4,34,1,1,1,1,1,1,1,1
34,4,0,0,0,0,0,0,0,0,0,4,34,1,1,1,1,1,1,1
34,4,0,0,0,0,0,0,0,0,0,0,4,34,1,1,1,1,1,1
1,34,4,0,0,0,0,0,0,0,0,0,4,34,1,1,1,1,1,1
1,34,4,0,0,0,0,0,0,0,0,0,0,4,1,1,1,1,1,1
1,1,34,4,0,0,0,0,0,0,0,0,0,4,4,1,1,1,1,1
1,1,1,34,4,0,0,0,0,0,0,0,4,0,0,4,0,0,1,1
1,1,1,1,34,4,0,0,0,0,0,4,0,0,0,0,4,0,1,1
1,1,1,1,1,34,4,4,0,35,4,0,0,0,0,0,0,4,1,1
1,1,1,1,1,1,34,34,4,4,0,0,0,0,0,0,0,0,4,1
1,1,1,1,1,1,1,1,1,4,0,0,0,0,0,0,0,0,4,0
1,1,1,1,1,1,1,1,1,1,4,0,0,0,0,0,0,0,4,0
1,1,1,1,1,1,1,1,1,1,0,4,0,0,0,0,0,0,4,1
1,1,1,1,1,1,1,1,1,1,0,0,4,0,0,0,9,4,1,1
1,1,1,1,1,1,1,1,1,1,1,1,1,4,4,4,4,1,1,1
1,1,1,1,1,1,1,1,1,1,1,1,1,1,1,1,1,1,1,1
endlayer

layer
1,1,1,1,1,1,1,1,1,1,1,1,1,1,1,1,1,1,1,1
1,1,1,1,1,26,26,1,1,1,1,1,1,1,1,1,1,1,1,1
1,1,1,26,26,36,36,26,26,1,1,1,1,1,1,1,1,1,1,1
1,1,26,36,36,0,0,36,36,26,1,1,1,1,1,1,1,1,1,1
1,9,25,0,0,0,0,0,0,36,26,1,1,1,1,1,1,1,1,1
1,9,25,0,0,0,0,0,0,0,36,26,1,1,1,1,1,1,1,1
1,9,25,0,0,0,0,0,0,0,0,37,26,1,1,1,1,1,1,1
1,1,9,25,0,0,0,0,0,0,0,37,11,1,1,1,1,1,1,1
1,1,9,25,0,0,0,0,0,0,0,0,37,11,1,1,1,1,1,1
1,1,1,9,25,0,0,0,0,0,0,0,37,4,4,1,1,1,1,1
1,1,1,1,9,39,0,0,0,0,0,0,4,38,38,4,0,0,1,1
1,1,1,1,1,9,39,39,0,0,35,4,38,38,38,38,4,0,1,1
1,1,1,1,1,1,9,40,39,39,4,38,38,38,38,38,38,4,1,1
1,1,1,1,1,1,1,1,9,4,38,38,38,38,38,38,38,38,4,1
1,1,1,1,1,1,1,1,1,4,38,38,38,38,38,38,38,38,4,0
1,1,1,1,1,1,1,1,1,1,4,38,38,38,38,38,38,38,4,0
1,1,1,1,1,1,1,1,1,1,0,4,38,38,38,38,40,38,4,1
1,1,1,1,1,1,1,1,1,1,0,0,4,0,0,0,0,4,1,1
1,1,1,1,1,1,1,1,1,1,1,1,1,4,4,4,4,1,1,1
1,1,1,1,1,1,1,1,1,1,1,1,1,1,1,1,1,1,1,1
endlayer

layer
1,1,1,1,1,1,1,1,1,1,1,1,1,1,1,1,1,1,1,1
1,1,1,1,1,1,1,1,1,1,1,1,1,1,1,1,1,1,1,1
1,1,1,1,1,1,1,1,1,1,1,1,1,1,1,1,1,1,1,1
1,1,1,1,1,41,41,1,1,1,1,1,1,1,1,1,1,1,1,1
1,1,1,41,41,41,41,41,41,1,1,1,1,1,1,1,1,1,1,1
1,1,1,41,42,42,42,41,41,41,1,1,1,1,1,1,1,1,1,1
1,1,1,41,41,42,42,42,41,41,41,1,1,1,1,1,1,1,1,1
1,1,1,1,41,41,42,42,42,41,41,1,1,1,1,1,1,1,1,1
1,1,1,1,41,41,41,42,42,42,41,41,1,1,1,1,1,1,1,1
1,1,1,1,0,41,41,41,42,42,42,41,1,4,4,1,1,1,1,1
1,1,1,1,1,1,41,41,41,42,42,38,4,24,23,4,6,6,1,1
1,1,1,1,1,1,1,1,41,41,38,38,41,0,0,0,4,15,1,1
1,1,1,1,1,1,1,1,1,41,4,41,41,0,0,0,0,4,1,1
1,1,1,1,1,1,1,1,1,4,44,43,0,0,0,0,24,23,4,1
1,1,1,1,1,1,1,1,13,4,0,0,0,0,0,0,0,0,4,15
1,1,1,1,1,1,1,1,21,21,4,44,43,0,0,0,0,0,4,15
1,1,1,1,1,1,1,1,1,1,0,4,0,0,0,0,0,0,4,1
1,1,1,1,1,1,1,1,1,1,0,0,4,0,0,0,0,4,1,1
1,1,1,1,1,1,1,1,1,1,1,1,1,4,4,4,4,1,1,1
1,1,1,1,1,1,1,1,1,1,1,1,1,1,21,21,1,1,1,1
endlayer

layer
1,1,1,1,1,1,1,1,1,1,1,1,1,1,1,1,1,1,1,1
1,1,1,1,1,1,1,1,1,1,1,1,1,1,1,1,1,1,1,1
1,1,1,1,1,1,1,1,1,1,1,1,1,1,1,1,1,1,1,1
1,1,1,1,1,1,1,1,1,1,1,1,1,1,1,1,1,1,1,1
1,1,1,1,1,1,1,1,1,1,1,1,1,1,1,1,1,1,1,1
1,1,1,1,1,1,1,1,1,1,1,1,1,1,1,1,1,1,1,1
1,1,1,1,1,1,1,1,1,1,1,1,1,1,1,1,1,1,1,1
1,1,1,1,1,1,1,1,1,1,1,1,1,1,1,1,1,1,1,1
1,1,1,1,1,1,1,1,1,1,1,1,1,1,1,1,1,1,1,1
1,1,1,1,1,1,1,1,1,1,1,1,1,4,4,1,1,1,1,1
1,1,1,1,1,1,1,1,1,1,0,7,4,24,23,4,0,27,1,1
1,1,1,1,1,1,1,1,1,1,19,0,0,0,0,0,28,0,1,1
1,1,1,1,1,1,1,1,1,1,4,0,0,0,0,0,0,4,1,1
1,1,1,1,1,1,1,1,1,4,44,43,0,0,0,0,24,23,4,1
1,1,1,1,1,1,1,1,27,28,0,0,0,0,0,0,0,0,28,27
1,1,1,1,1,1,1,1,1,27,4,44,43,0,0,0,0,0,28,27
1,1,1,1,1,1,1,1,1,1,0,4,0,0,0,0,0,0,4,1
1,1,1,1,1,1,1,1,1,1,0,0,4,0,0,0,0,4,1,1
1,1,1,1,1,1,1,1,1,1,1,1,1,4,28,28,4,1,1,1
1,1,1,1,1,1,1,1,1,1,1,1,1,1,27,27,1,1,1,1
endlayer

layer
1,1,1,1,1,1,1,1,1,1,1,1,1,1,1,1,1,1,1,1
1,1,1,1,1,1,1,1,1,1,1,1,1,1,1,1,1,1,1,1
1,1,1,1,1,1,1,1,1,1,1,1,1,1,1,1,1,1,1,1
1,1,1,1,1,1,1,1,1,1,1,1,1,1,1,1,1,1,1,1
1,1,1,1,1,1,1,1,1,1,1,1,1,1,1,1,1,1,1,1
1,1,1,1,1,1,1,1,1,1,1,1,1,1,1,1,1,1,1,1
1,1,1,1,1,1,1,1,1,1,1,1,1,1,1,1,1,1,1,1
1,1,1,1,1,1,1,1,1,1,1,1,1,1,1,1,1,1,1,1
1,1,1,1,1,1,1,1,1,1,1,1,1,1,1,1,1,1,1,1
1,1,1,1,1,1,1,1,1,1,1,1,1,4,4,1,1,1,1,1
1,1,1,1,1,1,1,1,1,1,0,30,4,0,0,4,0,0,1,1
1,1,1,1,1,1,1,1,1,1,29,0,0,0,0,0,28,0,1,1
1,1,1,1,1,1,1,1,1,1,4,0,0,0,0,0,0,4,1,1
1,1,1,1,1,1,1,1,1,4,0,0,0,0,0,0,0,0,4,1
1,1,1,1,1,1,1,1,1,28,0,0,0,0,0,0,0,0,28,0
1,1,1,1,1,1,1,1,1,0,4,0,0,0,0,0,0,0,28,0
1,1,1,1,1,1,1,1,1,1,0,4,0,0,0,0,0,0,4,1
1,1,1,1,1,1,1,1,1,1,0,0,4,0,0,0,0,4,1,1
1,1,1,1,1,1,1,1,1,1,1,1,1,4,28,28,4,1,1,1
1,1,1,1,1,1,1,1,1,1,1,1,1,1,0,0,1,1,1,1
endlayer

layer
1,1,1,1,1,1,1,1,1,1,1,1,1,1,1,1,1,1,1,1
1,1,1,1,1,1,1,1,1,1,1,1,1,1,1,1,1,1,1,1
1,1,1,1,1,1,1,1,1,1,1,1,1,1,1,1,1,1,1,1
1,1,1,1,1,1,1,1,1,1,1,1,1,1,1,1,1,1,1,1
1,1,1,1,1,1,1,1,1,1,1,1,1,1,1,1,1,1,1,1
1,1,1,1,1,1,1,1,1,1,1,1,1,1,1,1,1,1,1,1
1,1,1,1,1,1,1,1,1,1,1,1,1,1,1,1,1,1,1,1
1,1,1,1,1,1,1,1,1,1,1,1,1,1,1,1,1,1,1,1
1,1,1,1,1,1,1,1,1,1,1,1,1,1,1,1,1,1,1,1
1,1,1,1,1,1,1,1,1,1,1,1,1,4,4,1,1,1,1,1
1,1,1,1,1,1,1,1,1,1,0,4,4,0,0,4,0,0,1,1
1,1,1,1,1,1,1,1,1,1,4,0,0,0,0,0,4,0,1,1
1,1,1,1,1,1,1,1,1,1,4,0,0,0,0,0,0,4,1,1
1,1,1,1,1,1,1,1,1,4,0,0,0,0,0,0,0,0,4,1
1,1,1,1,1,1,1,1,1,4,0,0,0,0,0,0,0,0,4,0
1,1,1,1,1,1,1,1,1,0,4,0,0,0,0,0,0,0,4,0
1,1,1,1,1,1,1,1,1,1,0,4,0,0,0,0,0,0,4,1
1,1,1,1,1,1,1,1,1,1,0,0,4,0,0,0,0,4,1,1
1,1,1,1,1,1,1,1,1,1,1,1,1,4,4,4,4,1,1,1
1,1,1,1,1,1,1,1,1,1,1,1,1,1,0,0,1,1,1,1
endlayer

layer
1,1,1,1,1,1,1,1,1,1,1,1,1,1,1,1,1,1,1,1
1,1,1,1,1,1,1,1,1,1,1,1,1,1,1,1,1,1,1,1
1,1,1,1,1,1,1,1,1,1,1,1,1,1,1,1,1,1,1,1
1,1,1,1,1,1,1,1,1,1,1,1,1,1,1,1,1,1,1,1
1,1,1,1,1,1,1,1,1,1,1,1,1,1,1,1,1,1,1,1
1,1,1,1,1,1,1,1,1,1,1,1,1,1,1,1,1,1,1,1
1,1,1,1,1,1,1,1,1,1,1,1,1,1,1,1,1,1,1,1
1,1,1,1,1,1,1,1,1,1,1,1,1,1,1,1,1,1,1,1
1,1,1,1,1,1,1,1,1,1,1,1,1,3,3,1,1,1,1,1
1,1,1,1,1,1,1,1,1,1,1,3,3,4,4,3,1,1,1,1
1,1,1,1,1,1,1,1,1,1,3,4,4,25,36,4,3,0,1,1
1,1,1,1,1,1,1,1,1,3,4,25,36,25,34,37,4,3,1,1
1,1,1,1,1,1,1,1,1,3,4,25,34,45,45,36,37,4,3,1
1,1,1,1,1,1,1,1,3,4,25,34,45,45,45,45,36,37,4,3
1,1,1,1,1,1,1,1,3,4,39,25,45,45,45,45,34,37,4,3
1,1,1,1,1,1,1,1,1,3,4,39,25,45,45,45,34,37,4,3
1,1,1,1,1,1,1,1,1,1,3,4,39,25,34,34,39,37,4,3
1,1,1,1,1,1,1,1,1,1,0,3,4,39,39,39,37,4,3,1
1,1,1,1,1,1,1,1,1,1,1,1,3,4,4,4,4,3,1,1
1,1,1,1,1,1,1,1,1,1,1,1,1,3,3,3,3,1,1,1
endlayer

layer
1,1,1,1,1,1,1,1,1,1,1,1,1,1,1,1,1,1,1,1
1,1,1,1,1,1,1,1,1,1,1,1,1,1,1,1,1,1,1,1
1,1,1,1,1,1,1,1,1,1,1,1,1,1,1,1,1,1,1,1
1,1,1,1,1,1,1,1,1,1,1,1,1,1,1,1,1,1,1,1
1,1,1,1,1,1,1,1,1,1,1,1,1,1,1,1,1,1,1,1
1,1,1,1,1,1,1,1,1,1,1,1,1,1,1,1,1,1,1,1
1,1,1,1,1,1,1,1,1,1,1,1,1,1,1,1,1,1,1,1
1,1,1,1,1,1,1,1,1,1,1,1,1,1,1,1,1,1,1,1
1,1,1,1,1,1,1,1,1,1,1,1,1,46,46,1,1,1,1,1
1,1,1,1,1,1,1,1,1,1,1,46,46,3,3,47,1,1,1,1
1,1,1,1,1,1,1,1,1,1,48,3,3,0,0,3,46,0,1,1
1,1,1,1,1,1,1,1,1,48,3,0,0,0,0,0,3,46,1,1
1,1,1,1,1,1,1,1,1,48,3,0,0,0,0,0,0,3,47,1
1,1,1,1,1,1,1,1,48,3,0,0,0,0,0,0,0,0,3,47
1,1,1,1,1,1,1,1,48,3,0,0,0,0,0,0,0,0,3,47
1,1,1,1,1,1,1,1,1,48,3,0,0,0,0,0,0,0,3,47
1,1,1,1,1,1,1,1,1,1,49,3,0,0,0,0,0,0,3,47
1,1,1,1,1,1,1,1,1,1,0,48,3,0,0,0,0,3,47,1
1,1,1,1,1,1,1,1,1,1,1,1,49,3,3,3,3,47,1,1
1,1,1,1,1,1,1,1,1,1,1,1,1,49,49,49,49,1,1,1
endlayer

