
# Created by Ruins mod version 17.1 Ingame Parser
# authoring Player: ST753M

weight=1
spawnMinDistance=600
uniqueMinDistance=1500
embed_into_distance=3
acceptable_target_blocks=grass,dirt,mycelium,podzol,stone,gravel,clay,sand
unacceptable_target_blocks=flowing_water,water,flowing_lava,lava
dimensions=14,16,11
allowable_overhang=3
max_leveling=0
leveling_buffer=0
preserve_water=0
preserve_lava=0

biomesToSpawnIn=mutated_roofed_forest,mushroom_island,mushroom_island_shore,mushroomisland,mushroomislandshore,mushroom_forest,mutated_swampland

=0,100,air
rule1=0,100,preserveBlock
rule2=0,100,minecraft:log-0
rule3=0,100,minecraft:dirt-0
rule4=0,100,minecraft:mycelium-0
rule5=0,100,minecraft:log-8
rule6=0,100,minecraft:log-4
rule7=0,100,red_mushroom_block-0
rule8=0,100,minecraft:spruce_fence-0
rule9=0,100,minecraft:spruce_fence_gate-3
rule10=0,100,minecraft:spruce_stairs-0
rule11=0,100,minecraft:planks-1

rule12=0,100,CommandBlock:RUINSTRIGGER /summon mooshroom ~ ~1 ~:@-1

rule13=0,100,minecraft:spruce_stairs-6
rule14=0,100,minecraft:red_mushroom_block-14
rule15=0,100,minecraft:spruce_stairs-3
rule16=0,100,minecraft:hay_block-0

rule17=0,100,CommandBlock:RUINSTRIGGER /summon villager ~ ~1 ~ {Profession:0,Offers:{Recipes:[{rewardExp:0b,maxUses:2147483647,uses:0,buy:{id:"minecraft:brown_mushroom",Count:16b},sell:{id:"minecraft:brown_mushroom_block",Count:4b}},{rewardExp:0b,maxUses:2147483647,uses:0,buy:{id:"minecraft:red_mushroom",Count:16b},sell:{id:"minecraft:red_mushroom_block",Count:4b}},{rewardExp:0b,maxUses:2147483647,uses:0,buy:{id:"minecraft:emerald",Count:1b},sell:{id:"minecraft:mushroom_stew",Count:1b}},{rewardExp:0b,maxUses:2147483647,uses:0,buy:{id:"minecraft:dirt",Count:4b},buyB:{id:"minecraft:emerald",Count:1b},sell:{id:"minecraft:mycelium",Count:4b}}]}}:@-1

rule18=1,100,minecraft:torch-5

layer
1,1,1,1,1,1,1,1,1,1,1
1,2,1,1,1,2,1,1,1,2,1
1,1,3,3,3,3,3,3,3,1,1
1,1,3,3,3,3,3,3,3,1,1
1,1,3,3,3,3,3,3,3,1,1
1,2,3,3,3,2,3,3,3,2,1
1,1,3,3,3,3,3,3,3,1,1
1,1,3,3,3,3,3,3,3,1,1
1,1,3,3,3,3,3,3,3,1,1
1,1,3,3,3,3,3,3,3,1,1
1,2,3,3,3,2,3,3,3,2,1
1,1,3,3,3,3,3,3,3,1,1
1,1,3,3,3,3,3,3,3,1,1
1,1,3,3,3,3,3,3,3,1,1
1,2,1,1,1,2,1,1,1,2,1
1,1,1,1,1,1,1,1,1,1,1
endlayer

layer
1,1,1,1,1,1,1,1,1,1,1
1,2,1,1,1,2,1,1,1,2,1
1,1,3,3,3,4,3,3,3,1,1
1,1,3,3,3,3,3,3,3,1,1
1,1,3,3,3,3,3,3,3,1,1
1,2,3,3,3,2,3,3,3,2,1
1,1,3,3,3,3,3,3,3,1,1
1,1,3,3,3,3,3,3,3,1,1
1,1,3,3,3,3,3,3,4,1,1
1,1,3,3,3,3,3,3,3,1,1
1,2,3,3,3,2,3,3,3,2,1
1,1,3,3,3,3,3,3,3,1,1
1,1,3,3,3,3,3,3,3,1,1
1,1,3,3,3,3,3,3,3,1,1
1,2,1,1,1,2,1,1,1,2,1
1,1,1,1,1,1,1,1,1,1,1
endlayer

layer
1,1,1,1,1,1,1,1,1,1,1
1,2,5,5,5,2,5,5,5,2,1
1,6,4,4,4,6,4,4,4,6,1
1,6,4,4,4,6,4,4,4,6,1
1,6,4,4,4,6,4,4,4,6,1
1,2,4,4,4,2,4,4,4,2,1
1,6,4,4,4,4,4,4,4,6,1
1,6,4,4,4,4,4,4,4,6,1
1,6,4,4,4,4,4,4,4,6,1
1,6,4,4,4,4,4,4,4,6,1
1,2,4,4,4,2,4,4,4,2,1
1,6,4,4,4,6,4,4,4,6,1
1,6,3,4,4,6,4,4,4,6,1
1,6,3,4,4,6,4,4,4,6,1
1,2,5,5,5,2,5,5,5,2,1
1,1,1,1,1,1,1,1,1,1,1
endlayer

layer
1,1,1,1,1,1,1,1,1,1,1
1,2,7,7,7,2,7,7,7,2,1
1,7,0,0,0,7,0,0,0,7,1
1,7,0,0,0,7,0,0,0,7,1
1,7,0,0,0,7,0,0,0,7,1
1,2,8,9,8,2,8,9,8,2,1
1,8,0,0,0,0,0,0,0,8,1
0,0,0,0,0,0,0,0,0,0,0
0,0,0,0,0,0,0,0,0,0,0
1,8,0,0,0,0,0,0,0,8,1
1,2,0,0,0,2,8,9,8,2,1
1,7,10,0,0,7,0,0,0,7,1
1,7,11,0,0,7,0,0,0,7,1
1,7,11,0,0,7,0,0,0,7,1
1,2,7,7,7,2,7,7,7,2,1
1,1,1,1,1,1,1,1,1,1,1
endlayer

layer
1,1,1,1,1,1,1,1,1,1,1
1,2,7,8,7,2,7,8,7,2,1
1,7,0,0,0,7,0,0,0,7,1
1,8,0,12,0,7,0,12,0,8,1
1,7,0,0,0,7,0,0,0,7,1
1,2,0,0,0,2,0,0,0,2,1
1,8,0,0,0,0,0,0,0,8,1
0,0,0,0,0,0,0,0,0,0,0
0,0,0,0,0,0,0,0,0,0,0
1,8,0,0,0,0,0,0,0,8,1
1,2,0,0,0,2,0,0,0,2,1
1,7,0,0,0,7,0,0,0,7,1
1,8,10,0,0,7,0,12,0,8,1
1,7,11,0,0,7,0,0,0,7,1
1,2,7,8,7,2,7,8,7,2,1
1,1,1,1,1,1,1,1,1,1,1
endlayer

layer
1,1,1,1,1,1,1,1,1,1,1
1,2,7,0,7,2,7,0,7,2,1
1,7,0,0,0,8,0,0,0,7,1
1,0,0,0,0,8,0,0,0,0,1
1,7,0,0,0,8,0,0,0,7,1
1,2,0,0,0,2,0,0,0,2,1
1,8,0,0,0,0,0,0,0,8,1
0,0,0,0,0,0,0,0,0,0,0
0,0,0,0,0,0,0,0,0,0,0
1,8,0,0,0,0,0,0,0,8,1
1,2,0,0,0,2,0,0,0,2,1
1,7,0,0,0,8,0,0,0,7,1
1,0,0,0,0,8,0,0,0,0,1
1,7,10,13,0,8,0,0,0,7,1
1,2,7,0,7,2,7,0,7,2,1
1,1,1,1,1,1,1,1,1,1,1
endlayer

layer
14,14,14,14,14,14,14,14,14,14,14
1,2,7,7,7,2,7,7,7,2,1
1,7,0,0,0,0,0,0,0,7,1
1,7,0,0,0,0,0,0,0,7,1
1,7,0,0,0,0,0,0,0,7,1
1,2,0,0,0,2,0,0,0,2,1
14,14,0,0,0,0,0,0,0,14,14
14,14,0,0,0,0,0,0,0,14,14
14,14,0,0,0,0,0,0,0,14,14
14,14,0,0,0,0,0,0,0,14,14
1,2,0,0,0,2,0,0,0,2,1
1,7,0,0,0,0,0,0,0,7,1
1,7,0,0,0,0,0,0,0,7,1
1,7,0,15,13,0,0,0,0,7,1
1,2,7,7,7,2,7,7,7,2,1
14,14,14,14,14,14,14,14,14,14,14
endlayer

layer
14,14,14,14,14,14,14,14,14,14,14
14,2,5,5,5,2,5,5,5,2,14
1,6,7,7,7,6,7,7,7,6,1
1,6,7,7,7,6,7,7,7,6,1
1,6,7,7,7,6,7,7,7,6,1
1,2,5,5,5,5,5,5,5,2,1
1,6,7,14,0,0,0,14,7,6,1
14,6,7,14,0,0,0,14,7,6,14
14,6,7,14,0,0,0,14,7,6,14
1,6,7,14,0,0,0,14,7,6,1
1,2,5,5,5,5,5,5,5,2,1
1,6,7,7,7,6,7,7,7,6,1
1,6,0,7,7,6,7,7,7,6,1
1,6,0,0,15,6,7,7,7,6,1
14,2,5,5,5,2,5,5,5,5,14
14,14,14,14,14,14,14,14,14,14,14
endlayer

layer
1,1,1,1,1,1,1,1,1,1,1
14,14,14,14,14,14,14,14,14,14,14
1,7,0,0,0,0,0,16,0,7,1
1,7,16,0,0,0,0,0,16,7,1
1,7,0,0,16,0,0,17,0,7,1
1,2,0,8,8,8,8,8,0,2,1
1,7,0,8,0,0,0,8,0,7,1
1,7,0,8,0,0,0,8,0,7,1
1,7,0,8,0,0,0,8,0,7,1
1,7,0,8,0,0,0,8,0,7,1
1,2,0,8,8,8,8,8,0,2,1
1,7,0,0,16,0,0,0,0,7,1
1,7,0,0,0,0,0,0,16,7,1
1,7,0,0,0,0,0,0,0,7,1
14,14,14,14,14,14,14,14,14,14,14
1,1,1,1,1,1,1,1,1,1,1
endlayer

layer
1,1,1,1,1,1,1,1,1,1,1
14,14,14,14,14,14,14,14,14,14,14
14,7,0,0,0,0,0,0,0,7,14
1,7,0,0,0,0,0,0,16,7,1
1,7,0,0,16,0,0,0,0,7,1
1,2,0,18,0,0,0,18,0,2,1
1,7,0,0,0,0,0,0,0,7,1
1,8,0,0,0,0,0,0,0,8,1
1,8,0,0,0,0,0,0,0,8,1
1,7,0,0,0,0,0,0,0,7,1
1,2,0,18,0,0,0,18,0,2,1
1,7,0,0,0,0,0,0,0,7,1
1,7,0,0,0,0,0,0,0,7,1
14,7,0,0,0,0,0,0,0,7,14
14,14,14,14,14,14,14,14,14,14,14
1,1,1,1,1,1,1,1,1,1,1
endlayer

layer
1,1,1,1,1,1,1,1,1,1,1
1,1,1,1,1,1,1,1,1,1,1
14,14,14,14,14,14,14,14,14,14,14
14,7,0,0,0,0,0,0,0,7,14
1,7,0,0,0,0,0,0,0,7,1
1,2,0,0,0,0,0,0,0,2,1
1,7,0,0,0,0,0,0,0,7,1
1,0,0,0,0,0,0,0,0,0,1
1,0,0,0,0,0,0,0,0,0,1
1,7,0,0,0,0,0,0,0,7,1
1,2,0,0,0,0,0,0,0,2,1
1,7,0,0,0,0,0,0,0,7,1
14,7,0,0,0,0,0,0,0,7,14
14,14,14,14,14,14,14,14,14,14,14
1,1,1,1,1,1,1,1,1,1,1
1,1,1,1,1,1,1,1,1,1,1
endlayer

layer
1,1,1,1,1,1,1,1,1,1,1
1,1,1,1,1,1,1,1,1,1,1
1,1,1,1,1,1,1,1,1,1,1
14,14,14,14,14,14,14,14,14,14,14
14,14,14,14,14,14,14,14,14,14,14
14,2,0,0,0,0,0,0,0,2,14
1,7,0,0,0,0,0,0,0,7,1
1,7,0,0,0,0,0,0,0,7,1
1,7,0,0,0,0,0,0,0,7,1
1,7,0,0,0,0,0,0,0,7,1
14,2,0,0,0,0,0,0,0,2,14
14,14,14,14,14,14,14,14,14,14,14
14,14,14,14,14,14,14,14,14,14,14
1,1,1,1,1,1,1,1,1,1,1
1,1,1,1,1,1,1,1,1,1,1
1,1,1,1,1,1,1,1,1,1,1
endlayer

layer
1,1,1,1,1,1,1,1,1,1,1
1,1,1,1,1,1,1,1,1,1,1
1,1,1,1,1,1,1,1,1,1,1
1,1,1,1,1,1,1,1,1,1,1
1,1,1,1,1,1,1,1,1,1,1
14,14,14,14,14,14,14,14,14,14,14
14,14,14,14,14,14,14,14,14,14,14
14,14,14,0,0,0,0,0,14,14,14
14,14,14,0,0,0,0,0,14,14,14
14,14,14,14,14,14,14,14,14,14,14
14,14,14,14,14,14,14,14,14,14,14
1,1,1,1,1,1,1,1,1,1,1
1,1,1,1,1,1,1,1,1,1,1
1,1,1,1,1,1,1,1,1,1,1
1,1,1,1,1,1,1,1,1,1,1
1,1,1,1,1,1,1,1,1,1,1
endlayer

layer
1,1,1,1,1,1,1,1,1,1,1
1,1,1,1,1,1,1,1,1,1,1
1,1,1,1,1,1,1,1,1,1,1
1,1,1,1,1,1,1,1,1,1,1
1,1,1,1,1,1,1,1,1,1,1
1,1,1,1,1,1,1,1,1,1,1
1,1,1,1,1,1,1,1,1,1,1
14,14,14,14,14,14,14,14,14,14,14
14,14,14,14,14,14,14,14,14,14,14
1,1,1,1,1,1,1,1,1,1,1
1,1,1,1,1,1,1,1,1,1,1
1,1,1,1,1,1,1,1,1,1,1
1,1,1,1,1,1,1,1,1,1,1
1,1,1,1,1,1,1,1,1,1,1
1,1,1,1,1,1,1,1,1,1,1
1,1,1,1,1,1,1,1,1,1,1
endlayer

