
# Created by Ruins mod version 16.7 Ingame Parser
# authoring Player: lafuller

weight=1
embed_into_distance=5
acceptable_target_blocks=mycelium,grass
unacceptable_target_blocks=
biomesToSpawnIn=mushroom_island,fungi_forest,roofed_forest,swampland
dimensions=27,20,19
allowable_overhang=0
max_leveling=5
leveling_buffer=-1
preserve_water=0
preserve_lava=0

rule1=0,100,preserveBlock
rule2=0,100,minecraft:red_mushroom_block-10
rule3=0,100,minecraft:red_mushroom_block-15
rule4=0,100,minecraft:red_mushroom_block-14
rule5=0,100,minecraft:red_mushroom_block-0

layer
1,1,1,1,1,1,1,1,1,1,1,1,1,1,1,1,1,1,1
1,1,1,1,1,1,1,1,1,1,1,1,1,1,1,1,1,1,1
1,1,1,1,1,1,1,1,1,1,1,1,1,1,1,1,1,1,1
1,1,1,1,1,1,1,1,1,1,1,1,1,1,1,1,1,1,1
1,1,1,1,1,1,1,1,1,1,1,1,1,1,1,1,1,1,1
1,1,1,1,1,1,1,1,1,1,1,1,1,1,1,1,1,1,1
1,1,1,1,1,1,1,1,2,2,2,1,1,1,1,1,1,1,1
1,1,1,1,1,1,1,2,2,2,2,2,1,1,1,1,1,1,1
1,1,1,1,1,1,2,2,2,2,2,2,3,1,1,1,1,1,1
1,1,1,1,1,1,2,2,2,2,2,2,2,1,1,1,1,1,1
1,1,1,1,1,1,2,2,2,2,2,2,2,1,1,1,1,1,1
1,1,1,1,1,1,2,2,2,2,2,2,2,1,1,1,1,1,1
1,1,1,1,1,1,1,2,2,2,2,2,1,1,1,1,1,1,1
1,1,1,1,1,1,1,1,2,2,3,1,1,1,1,1,1,1,1
1,1,1,1,1,1,1,1,1,1,1,1,1,1,1,1,1,1,1
1,1,1,1,1,1,1,1,1,1,1,1,1,1,1,1,1,1,1
1,1,1,1,1,1,1,1,1,1,1,1,1,1,1,1,1,1,1
1,1,1,1,1,1,1,1,1,1,1,1,1,1,1,1,1,1,1
1,1,1,1,1,1,1,1,1,1,1,1,1,1,1,1,1,1,1
1,1,1,1,1,1,1,1,1,1,1,1,1,1,1,1,1,1,1
endlayer

layer
1,1,1,1,1,1,1,1,1,1,1,1,1,1,1,1,1,1,1
1,1,1,1,1,1,1,1,1,1,1,1,1,1,1,1,1,1,1
1,1,1,1,1,1,1,1,1,1,1,1,1,1,1,1,1,1,1
1,1,1,1,1,1,1,1,1,1,1,1,1,1,1,1,1,1,1
1,1,1,1,1,1,1,1,1,1,1,1,1,1,1,1,1,1,1
1,1,1,1,1,1,1,1,1,1,1,1,1,1,1,1,1,1,1
1,1,1,1,1,1,1,1,2,2,3,1,1,1,1,1,1,1,1
1,1,1,1,1,1,1,2,2,2,2,2,1,1,1,1,1,1,1
1,1,1,1,1,1,2,2,2,2,2,2,1,1,1,1,1,1,1
1,1,1,1,1,1,2,2,2,2,2,2,2,1,1,1,1,1,1
1,1,1,1,1,1,2,2,2,2,2,2,2,1,1,1,1,1,1
1,1,1,1,1,1,2,2,2,2,2,2,3,1,1,1,1,1,1
1,1,1,1,1,1,1,2,2,2,2,2,1,1,1,1,1,1,1
1,1,1,1,1,1,1,1,3,2,1,1,1,1,1,1,1,1,1
1,1,1,1,1,1,1,1,1,1,1,1,1,1,1,1,1,1,1
1,1,1,1,1,1,1,1,1,1,1,1,1,1,1,1,1,1,1
1,1,1,1,1,1,1,1,1,1,1,1,1,1,1,1,1,1,1
1,1,1,1,1,1,1,1,1,1,1,1,1,1,1,1,1,1,1
1,1,1,1,1,1,1,1,1,1,1,1,1,1,1,1,1,1,1
1,1,1,1,1,1,1,1,1,1,1,1,1,1,1,1,1,1,1
endlayer

layer
1,1,1,1,1,1,1,1,1,1,1,1,1,1,1,1,1,1,1
1,1,1,1,1,1,1,1,1,1,1,1,1,1,1,1,1,1,1
1,1,1,1,1,1,1,1,1,1,1,1,1,1,1,1,1,1,1
1,1,1,1,1,1,1,1,1,1,1,1,1,1,1,1,1,1,1
1,1,1,1,1,1,1,1,1,1,1,1,1,1,1,1,1,1,1
1,1,1,1,1,1,1,1,1,1,1,1,1,1,1,1,1,1,1
1,1,1,1,1,1,1,1,3,2,1,1,1,1,1,1,1,1,1
1,1,1,1,1,1,1,2,2,2,2,2,1,1,1,1,1,1,1
1,1,1,1,1,1,3,2,2,2,2,2,1,1,1,1,1,1,1
1,1,1,1,1,1,2,2,2,2,2,2,2,1,1,1,1,1,1
1,1,1,1,1,1,2,2,2,2,2,2,2,1,1,1,1,1,1
1,1,1,1,1,1,2,2,2,2,2,2,1,1,1,1,1,1,1
1,1,1,1,1,1,1,3,2,2,2,3,1,1,1,1,1,1,1
1,1,1,1,1,1,1,1,1,2,1,1,1,1,1,1,1,1,1
1,1,1,1,1,1,1,1,1,1,1,1,1,1,1,1,1,1,1
1,1,1,1,1,1,1,1,1,1,1,1,1,1,1,1,1,1,1
1,1,1,1,1,1,1,1,1,1,1,1,1,1,1,1,1,1,1
1,1,1,1,1,1,1,1,1,1,1,1,1,1,1,1,1,1,1
1,1,1,1,1,1,1,1,1,1,1,1,1,1,1,1,1,1,1
1,1,1,1,1,1,1,1,1,1,1,1,1,1,1,1,1,1,1
endlayer

layer
1,1,1,1,1,1,1,1,1,1,1,1,1,1,1,1,1,1,1
1,1,1,1,1,1,1,1,1,1,1,1,1,1,1,1,1,1,1
1,1,1,1,1,1,1,1,1,1,1,1,1,1,1,1,1,1,1
1,1,1,1,1,1,1,1,1,1,1,1,1,1,1,1,1,1,1
1,1,1,1,1,1,1,1,1,1,1,1,1,1,1,1,1,1,1
1,1,1,1,1,1,1,1,1,1,1,1,1,1,1,1,1,1,1
1,1,1,1,1,1,1,1,1,2,1,1,1,1,1,1,1,1,1
1,1,1,1,1,1,1,3,2,2,2,3,1,1,1,1,1,1,1
1,1,1,1,1,1,1,2,2,2,2,2,1,1,1,1,1,1,1
1,1,1,1,1,1,2,2,2,2,2,2,2,1,1,1,1,1,1
1,1,1,1,1,1,2,2,2,2,2,2,2,1,1,1,1,1,1
1,1,1,1,1,1,3,2,2,2,2,2,1,1,1,1,1,1,1
1,1,1,1,1,1,1,1,2,2,2,1,1,1,1,1,1,1,1
1,1,1,1,1,1,1,1,1,3,1,1,1,1,1,1,1,1,1
1,1,1,1,1,1,1,1,1,1,1,1,1,1,1,1,1,1,1
1,1,1,1,1,1,1,1,1,1,1,1,1,1,1,1,1,1,1
1,1,1,1,1,1,1,1,1,1,1,1,1,1,1,1,1,1,1
1,1,1,1,1,1,1,1,1,1,1,1,1,1,1,1,1,1,1
1,1,1,1,1,1,1,1,1,1,1,1,1,1,1,1,1,1,1
1,1,1,1,1,1,1,1,1,1,1,1,1,1,1,1,1,1,1
endlayer

layer
1,1,1,1,1,1,1,1,1,1,1,1,1,1,1,1,1,1,1
1,1,1,1,1,1,1,1,1,1,1,1,1,1,1,1,1,1,1
1,1,1,1,1,1,1,1,1,1,1,1,1,1,1,1,1,1,1
1,1,1,1,1,1,1,1,1,1,1,1,1,1,1,1,1,1,1
1,1,1,1,1,1,1,1,1,1,1,1,1,1,1,1,1,1,1
1,1,1,1,1,1,1,1,1,1,1,1,1,1,1,1,1,1,1
1,1,1,1,1,1,1,1,1,3,1,1,1,1,1,1,1,1,1
1,1,1,1,1,1,1,1,2,2,2,1,1,1,1,1,1,1,1
1,1,1,1,1,1,1,2,2,2,2,2,1,1,1,1,1,1,1
1,1,1,1,1,1,3,2,2,2,2,2,3,1,1,1,1,1,1
1,1,1,1,1,1,2,2,2,2,2,2,2,1,1,1,1,1,1
1,1,1,1,1,1,1,2,2,2,2,2,1,1,1,1,1,1,1
1,1,1,1,1,1,1,1,3,2,2,1,1,1,1,1,1,1,1
1,1,1,1,1,1,1,1,1,1,1,1,1,1,1,1,1,1,1
1,1,1,1,1,1,1,1,1,1,1,1,1,1,1,1,1,1,1
1,1,1,1,1,1,1,1,1,1,1,1,1,1,1,1,1,1,1
1,1,1,1,1,1,1,1,1,1,1,1,1,1,1,1,1,1,1
1,1,1,1,1,1,1,1,1,1,1,1,1,1,1,1,1,1,1
1,1,1,1,1,1,1,1,1,1,1,1,1,1,1,1,1,1,1
1,1,1,1,1,1,1,1,1,1,1,1,1,1,1,1,1,1,1
endlayer

layer
1,1,1,1,1,1,1,1,1,1,1,1,1,1,1,1,1,1,1
1,1,1,1,1,1,1,1,1,1,1,1,1,1,1,1,1,1,1
1,1,1,1,1,1,1,1,1,1,1,1,1,1,1,1,1,1,1
1,1,1,1,1,1,1,1,1,1,1,1,1,1,1,1,1,1,1
1,1,1,1,1,1,1,1,1,1,1,1,1,1,1,1,1,1,1
1,1,1,1,1,1,1,1,1,1,1,1,1,1,1,1,1,1,1
1,1,1,1,1,1,1,1,1,1,1,1,1,1,1,1,1,1,1
1,1,1,1,1,1,1,1,2,2,2,1,1,1,1,1,1,1,1
1,1,1,1,1,1,1,2,2,2,2,2,1,1,1,1,1,1,1
1,1,1,1,1,1,1,2,2,2,2,2,1,1,1,1,1,1,1
1,1,1,1,1,1,3,2,2,2,2,2,3,1,1,1,1,1,1
1,1,1,1,1,1,1,2,2,2,2,2,1,1,1,1,1,1,1
1,1,1,1,1,1,1,1,1,2,3,1,1,1,1,1,1,1,1
1,1,1,1,1,1,1,1,1,1,1,1,1,1,1,1,1,1,1
1,1,1,1,1,1,1,1,1,1,1,1,1,1,1,1,1,1,1
1,1,1,1,1,1,1,1,1,1,1,1,1,1,1,1,1,1,1
1,1,1,1,1,1,1,1,1,1,1,1,1,1,1,1,1,1,1
1,1,1,1,1,1,1,1,1,1,1,1,1,1,1,1,1,1,1
1,1,1,1,1,1,1,1,1,1,1,1,1,1,1,1,1,1,1
1,1,1,1,1,1,1,1,1,1,1,1,1,1,1,1,1,1,1
endlayer

layer
1,1,1,1,1,1,1,1,1,1,1,1,1,1,1,1,1,1,1
1,1,1,1,1,1,1,1,1,1,1,1,1,1,1,1,1,1,1
1,1,1,1,1,1,1,1,1,1,1,1,1,1,1,1,1,1,1
1,1,1,1,1,1,1,1,1,1,1,1,1,1,1,1,1,1,1
1,1,1,1,1,1,1,1,1,1,1,1,1,1,1,1,1,1,1
1,1,1,1,1,1,1,1,1,1,1,1,1,1,1,1,1,1,1
1,1,1,1,1,1,1,1,1,1,1,1,1,1,1,1,1,1,1
1,1,1,1,1,1,1,1,3,2,3,1,1,1,1,1,1,1,1
1,1,1,1,1,1,1,2,2,2,2,2,1,1,1,1,1,1,1
1,1,1,1,1,1,1,2,2,2,2,2,1,1,1,1,1,1,1
1,1,1,1,1,1,1,2,2,2,2,2,1,1,1,1,1,1,1
1,1,1,1,1,1,1,2,2,2,2,3,1,1,1,1,1,1,1
1,1,1,1,1,1,1,1,1,3,1,1,1,1,1,1,1,1,1
1,1,1,1,1,1,1,1,1,1,1,1,1,1,1,1,1,1,1
1,1,1,1,1,1,1,1,1,1,1,1,1,1,1,1,1,1,1
1,1,1,1,1,1,1,1,1,1,1,1,1,1,1,1,1,1,1
1,1,1,1,1,1,1,1,1,1,1,1,1,1,1,1,1,1,1
1,1,1,1,1,1,1,1,1,1,1,1,1,1,1,1,1,1,1
1,1,1,1,1,1,1,1,1,1,1,1,1,1,1,1,1,1,1
1,1,1,1,1,1,1,1,1,1,1,1,1,1,1,1,1,1,1
endlayer

layer
1,1,1,1,1,1,1,1,1,1,1,1,1,1,1,1,1,1,1
1,1,1,1,1,1,1,1,1,1,1,1,1,1,1,1,1,1,1
1,1,1,1,1,1,1,1,1,1,1,1,1,1,1,1,1,1,1
1,1,1,1,1,1,1,1,1,1,1,1,1,1,1,1,1,1,1
1,1,1,1,1,1,1,1,1,1,1,1,1,1,1,1,1,1,1
1,1,1,1,1,1,1,1,1,1,1,1,1,1,1,1,1,1,1
1,1,1,1,1,1,1,1,1,1,1,1,1,1,1,1,1,1,1
1,1,1,1,1,1,1,1,1,2,1,1,1,1,1,1,1,1,1
1,1,1,1,1,1,1,3,2,2,2,3,1,1,1,1,1,1,1
1,1,1,1,1,1,1,2,2,2,2,2,1,1,1,1,1,1,1
1,1,1,1,1,1,1,2,2,2,2,2,1,1,1,1,1,1,1
1,1,1,1,1,1,1,3,2,2,2,1,1,1,1,1,1,1,1
1,1,1,1,1,1,1,1,1,1,1,1,1,1,1,1,1,1,1
1,1,1,1,1,1,1,1,1,1,1,1,1,1,1,1,1,1,1
1,1,1,1,1,1,1,1,1,1,1,1,1,1,1,1,1,1,1
1,1,1,1,1,1,1,1,1,1,1,1,1,1,1,1,1,1,1
1,1,1,1,1,1,1,1,1,1,1,1,1,1,1,1,1,1,1
1,1,1,1,1,1,1,1,1,1,1,1,1,1,1,1,1,1,1
1,1,1,1,1,1,1,1,1,1,1,1,1,1,1,1,1,1,1
1,1,1,1,1,1,1,1,1,1,1,1,1,1,1,1,1,1,1
endlayer

layer
1,1,1,1,1,1,1,1,1,1,1,1,1,1,1,1,1,1,1
1,1,1,1,1,1,1,1,1,1,1,1,1,1,1,1,1,1,1
1,1,1,1,1,1,1,1,1,1,1,1,1,1,1,1,1,1,1
1,1,1,1,1,1,1,1,1,1,1,1,1,1,1,1,1,1,1
1,1,1,1,1,1,1,1,1,1,1,1,1,1,1,1,1,1,1
1,1,1,1,1,1,1,1,1,1,1,1,1,1,1,1,1,1,1
1,1,1,1,1,1,1,1,1,1,1,1,1,1,1,1,1,1,1
1,1,1,1,1,1,1,1,1,3,1,1,1,1,1,1,1,1,1
1,1,1,1,1,1,1,1,2,2,2,1,1,1,1,1,1,1,1
1,1,1,1,1,1,1,2,2,2,2,2,1,1,1,1,1,1,1
1,1,1,1,1,1,1,2,2,2,2,3,1,1,1,1,1,1,1
1,1,1,1,1,1,1,1,2,2,3,1,1,1,1,1,1,1,1
1,1,1,1,1,1,1,1,1,1,1,1,1,1,1,1,1,1,1
1,1,1,1,1,1,1,1,1,1,1,1,1,1,1,1,1,1,1
1,1,1,1,1,1,1,1,1,1,1,1,1,1,1,1,1,1,1
1,1,1,1,1,1,1,1,1,1,1,1,1,1,1,1,1,1,1
1,1,1,1,1,1,1,1,1,1,1,1,1,1,1,1,1,1,1
1,1,1,1,1,1,1,1,1,1,1,1,1,1,1,1,1,1,1
1,1,1,1,1,1,1,1,1,1,1,1,1,1,1,1,1,1,1
1,1,1,1,1,1,1,1,1,1,1,1,1,1,1,1,1,1,1
endlayer

layer
1,1,1,1,1,1,1,1,1,1,1,1,1,1,1,1,1,1,1
1,1,1,1,1,1,1,1,1,1,1,1,1,1,1,1,1,1,1
1,1,1,1,1,1,1,1,1,1,1,1,1,1,1,1,1,1,1
1,1,1,1,1,1,1,1,1,1,1,1,1,1,1,1,1,1,1
1,1,1,1,1,1,1,1,1,1,1,1,1,1,1,1,1,1,1
1,1,1,1,1,1,1,1,1,1,1,1,1,1,1,1,1,1,1
1,1,1,1,1,1,1,1,1,1,1,1,1,1,1,1,1,1,1
1,1,1,1,1,1,1,1,1,1,1,1,1,1,1,1,1,1,1
1,1,1,1,1,1,1,1,2,2,2,1,1,1,1,1,1,1,1
1,1,1,1,1,1,1,3,2,2,2,2,1,1,1,1,1,1,1
1,1,1,1,1,1,1,2,2,2,2,1,1,1,1,1,1,1,1
1,1,1,1,1,1,1,1,3,2,1,1,1,1,1,1,1,1,1
1,1,1,1,1,1,1,1,1,1,1,1,1,1,1,1,1,1,1
1,1,1,1,1,1,1,1,1,1,1,1,1,1,1,1,1,1,1
1,1,1,1,1,1,1,1,1,1,1,1,1,1,1,1,1,1,1
1,1,1,1,1,1,1,1,1,1,1,1,1,1,1,1,1,1,1
1,1,1,1,1,1,1,1,1,1,1,1,1,1,1,1,1,1,1
1,1,1,1,1,1,1,1,1,1,1,1,1,1,1,1,1,1,1
1,1,1,1,1,1,1,1,1,1,1,1,1,1,1,1,1,1,1
1,1,1,1,1,1,1,1,1,1,1,1,1,1,1,1,1,1,1
endlayer

layer
1,1,1,1,1,1,1,1,1,1,1,1,1,1,1,1,1,1,1
1,1,1,1,1,1,1,1,1,1,1,1,1,1,1,1,1,1,1
1,1,1,1,1,1,1,1,1,1,1,1,1,1,1,1,1,1,1
1,1,1,1,1,1,1,1,1,1,1,1,1,1,1,1,1,1,1
1,1,1,1,1,1,1,1,1,1,1,1,1,1,1,1,1,1,1
1,1,1,1,1,1,1,1,1,1,1,1,1,1,1,1,1,1,1
1,1,1,1,1,1,1,1,1,1,1,1,1,1,1,1,1,1,1
1,1,1,1,1,1,1,1,1,1,1,1,1,1,1,1,1,1,1
1,1,1,1,1,1,1,1,2,2,3,1,1,1,1,1,1,1,1
1,1,1,1,1,1,1,1,2,2,2,2,1,1,1,1,1,1,1
1,1,1,1,1,1,1,3,2,2,2,1,1,1,1,1,1,1,1
1,1,1,1,1,1,1,1,1,2,1,1,1,1,1,1,1,1,1
1,1,1,1,1,1,1,1,1,1,1,1,1,1,1,1,1,1,1
1,1,1,1,1,1,1,1,1,1,1,1,1,1,1,1,1,1,1
1,1,1,1,1,1,1,1,1,1,1,1,1,1,1,1,1,1,1
1,1,1,1,1,1,1,1,1,1,1,1,1,1,1,1,1,1,1
1,1,1,1,1,1,1,1,1,1,1,1,1,1,1,1,1,1,1
1,1,1,1,1,1,1,1,1,1,1,1,1,1,1,1,1,1,1
1,1,1,1,1,1,1,1,1,1,1,1,1,1,1,1,1,1,1
1,1,1,1,1,1,1,1,1,1,1,1,1,1,1,1,1,1,1
endlayer

layer
1,1,1,1,1,1,1,1,1,1,1,1,1,1,1,1,1,1,1
1,1,1,1,1,1,1,1,1,1,1,1,1,1,1,1,1,1,1
1,1,1,1,1,1,1,1,1,1,1,1,1,1,1,1,1,1,1
1,1,1,1,1,1,1,1,1,1,1,1,1,1,1,1,1,1,1
1,1,1,1,1,1,1,1,1,1,1,1,1,1,1,1,1,1,1
1,1,1,1,1,1,1,1,1,1,1,1,1,1,1,1,1,1,1
1,1,1,1,1,1,1,1,1,1,1,1,1,1,1,1,1,1,1
1,1,1,1,1,1,1,1,1,1,1,1,1,1,1,1,1,1,1
1,1,1,1,1,1,1,1,2,2,1,1,1,1,1,1,1,1,1
1,1,1,1,1,1,1,1,2,2,2,3,1,1,1,1,1,1,1
1,1,1,1,1,1,1,1,2,2,2,1,1,1,1,1,1,1,1
1,1,1,1,1,1,1,1,1,2,1,1,1,1,1,1,1,1,1
1,1,1,1,1,1,1,1,1,1,1,1,1,1,1,1,1,1,1
1,1,1,1,1,1,1,1,1,1,1,1,1,1,1,1,1,1,1
1,1,1,1,1,1,1,1,1,1,1,1,1,1,1,1,1,1,1
1,1,1,1,1,1,1,1,1,1,1,1,1,1,1,1,1,1,1
1,1,1,1,1,1,1,1,1,1,1,1,1,1,1,1,1,1,1
1,1,1,1,1,1,1,1,1,1,1,1,1,1,1,1,1,1,1
1,1,1,1,1,1,1,1,1,1,1,1,1,1,1,1,1,1,1
1,1,1,1,1,1,1,1,1,1,1,1,1,1,1,1,1,1,1
endlayer

layer
1,1,1,1,1,1,1,1,1,1,1,1,1,1,1,1,1,1,1
1,1,1,1,1,1,1,1,1,1,1,1,1,1,1,1,1,1,1
1,1,1,1,1,1,1,1,1,1,1,1,1,1,1,1,1,1,1
1,1,1,1,1,1,1,1,1,1,1,1,1,1,1,1,1,1,1
1,1,1,1,1,1,1,1,1,1,1,1,1,1,1,1,1,1,1
1,1,1,1,1,1,1,1,1,1,1,1,1,1,1,1,1,1,1
1,1,1,1,1,1,1,1,1,1,1,1,1,1,1,1,1,1,1
1,1,1,1,1,1,1,1,1,1,1,1,1,1,1,1,1,1,1
1,1,1,1,1,1,1,1,2,2,1,1,1,1,1,1,1,1,1
1,1,1,1,1,1,1,1,2,2,2,1,1,1,1,1,1,1,1
1,1,1,1,1,1,1,1,2,2,2,1,1,1,1,1,1,1,1
1,1,1,1,1,1,1,1,1,2,1,1,1,1,1,1,1,1,1
1,1,1,1,1,1,1,1,1,1,1,1,1,1,1,1,1,1,1
1,1,1,1,1,1,1,1,1,1,1,1,1,1,1,1,1,1,1
1,1,1,1,1,1,1,1,1,1,1,1,1,1,1,1,1,1,1
1,1,1,1,1,1,1,1,1,1,1,1,1,1,1,1,1,1,1
1,1,1,1,1,1,1,1,1,1,1,1,1,1,1,1,1,1,1
1,1,1,1,1,1,1,1,1,1,1,1,1,1,1,1,1,1,1
1,1,1,1,1,1,1,1,1,1,1,1,1,1,1,1,1,1,1
1,1,1,1,1,1,1,1,1,1,1,1,1,1,1,1,1,1,1
endlayer

layer
1,1,1,1,1,1,1,1,1,1,1,1,1,1,1,1,1,1,1
1,1,1,1,1,1,1,1,1,1,1,1,1,1,1,1,1,1,1
1,1,1,1,1,1,1,1,1,1,1,1,1,1,1,1,1,1,1
1,1,1,1,1,1,1,1,1,1,1,1,1,1,1,1,1,1,1
1,1,1,1,1,1,1,1,1,1,1,1,1,1,1,1,1,1,1
1,1,1,1,1,1,1,1,1,1,1,1,1,1,1,1,1,1,1
1,1,1,1,1,1,1,1,1,1,1,1,1,1,1,1,1,1,1
1,1,1,1,1,1,1,1,1,1,1,1,1,1,1,1,1,1,1
1,1,1,1,1,1,1,1,2,2,1,1,1,1,1,1,1,1,1
1,1,1,1,1,1,1,1,2,2,2,1,1,1,1,1,1,1,1
1,1,1,1,1,1,1,1,2,2,2,1,1,1,1,1,1,1,1
1,1,1,1,1,1,1,1,1,2,1,1,1,1,1,1,1,1,1
1,1,1,1,1,1,1,1,1,1,1,1,1,1,1,1,1,1,1
1,1,1,1,1,1,1,1,1,1,1,1,1,1,1,1,1,1,1
1,1,1,1,1,1,1,1,1,1,1,1,1,1,1,1,1,1,1
1,1,1,1,1,1,1,1,1,1,1,1,1,1,1,1,1,1,1
1,1,1,1,1,1,1,1,1,1,1,1,1,1,1,1,1,1,1
1,1,1,1,1,1,1,1,1,1,1,1,1,1,1,1,1,1,1
1,1,1,1,1,1,1,1,1,1,1,1,1,1,1,1,1,1,1
1,1,1,1,1,1,1,1,1,1,1,1,1,1,1,1,1,1,1
endlayer

layer
1,1,1,1,1,1,1,1,1,1,1,1,1,1,1,1,1,1,1
1,1,1,1,1,1,1,1,1,1,1,1,1,1,1,1,1,1,1
1,1,1,1,1,1,1,1,1,1,1,1,1,1,1,1,1,1,1
1,1,1,1,1,1,1,1,1,1,1,1,1,1,1,1,1,1,1
1,1,1,1,1,1,1,1,1,1,1,1,1,1,1,1,1,1,1
1,1,1,1,1,1,1,1,1,1,1,1,1,1,1,1,1,1,1
1,1,1,1,1,1,1,1,1,1,1,1,1,1,1,1,1,1,1
1,1,1,1,1,1,1,1,1,1,1,1,1,1,1,1,1,1,1
1,1,1,1,1,1,1,1,2,2,1,1,1,1,1,1,1,1,1
1,1,1,1,1,1,1,1,2,2,2,1,1,1,1,1,1,1,1
1,1,1,1,1,1,1,1,2,2,2,1,1,1,1,1,1,1,1
1,1,1,1,1,1,1,1,1,2,1,1,1,1,1,1,1,1,1
1,1,1,1,1,1,1,1,1,1,1,1,1,1,1,1,1,1,1
1,1,1,1,1,1,1,1,1,1,1,1,1,1,1,1,1,1,1
1,1,1,1,1,1,1,1,1,1,1,1,1,1,1,1,1,1,1
1,1,1,1,1,1,1,1,1,1,1,1,1,1,1,1,1,1,1
1,1,1,1,1,1,1,1,1,1,1,1,1,1,1,1,1,1,1
1,1,1,1,1,1,1,1,1,1,1,1,1,1,1,1,1,1,1
1,1,1,1,1,1,1,1,1,1,1,1,1,1,1,1,1,1,1
1,1,1,1,1,1,1,1,1,1,1,1,1,1,1,1,1,1,1
endlayer

layer
1,1,1,1,1,1,1,1,1,1,1,1,1,1,1,1,1,1,1
1,1,1,1,1,1,1,1,1,1,1,1,1,1,1,1,1,1,1
1,1,1,1,1,1,1,1,1,1,1,1,1,1,1,1,1,1,1
1,1,1,1,1,1,1,1,1,1,1,1,1,1,1,1,1,1,1
1,1,1,1,1,1,1,1,1,1,1,1,1,1,1,1,1,1,1
1,1,1,1,1,1,1,1,1,1,1,1,1,1,1,1,1,1,1
1,1,1,1,1,1,1,1,1,1,1,1,1,1,1,1,1,1,1
1,1,1,1,1,1,1,1,1,1,1,1,1,1,1,1,1,1,1
1,1,1,1,1,1,1,1,2,2,1,1,1,1,1,1,1,1,1
1,1,1,1,1,1,1,3,2,2,2,1,1,1,1,1,1,1,1
1,1,1,1,1,1,1,1,2,2,2,1,1,1,1,1,1,1,1
1,1,1,1,1,1,1,1,1,2,1,1,1,1,1,1,1,1,1
1,1,1,1,1,1,1,1,1,1,1,1,1,1,1,1,1,1,1
1,1,1,1,1,1,1,1,1,1,1,1,1,1,1,1,1,1,1
1,1,1,1,1,1,1,1,1,1,1,1,1,1,1,1,1,1,1
1,1,1,1,1,1,1,1,1,1,1,1,1,1,1,1,1,1,1
1,1,1,1,1,1,1,1,1,1,1,1,1,1,1,1,1,1,1
1,1,1,1,1,1,1,1,1,1,1,1,1,1,1,1,1,1,1
1,1,1,1,1,1,1,1,1,1,1,1,1,1,1,1,1,1,1
1,1,1,1,1,1,1,1,1,1,1,1,1,1,1,1,1,1,1
endlayer

layer
1,1,1,1,1,1,1,1,1,1,1,1,1,1,1,1,1,1,1
1,1,1,1,1,1,1,1,1,1,1,1,1,1,1,1,1,1,1
1,1,1,1,1,1,1,1,1,1,1,1,1,1,1,1,1,1,1
1,1,1,1,1,1,1,1,1,1,1,1,1,1,1,1,1,1,1
1,1,1,1,1,1,1,1,1,1,1,1,1,1,1,1,1,1,1
1,1,1,1,1,1,1,1,1,1,1,1,1,1,1,1,1,1,1
1,1,1,1,1,1,1,1,1,1,1,1,1,1,1,1,1,1,1
1,1,1,1,1,1,1,1,1,1,1,1,1,1,1,1,1,1,1
1,1,1,1,1,1,1,1,2,2,1,1,1,1,1,1,1,1,1
1,1,1,1,1,1,1,2,2,2,2,1,1,1,1,1,1,1,1
1,1,1,1,1,1,1,3,2,2,2,3,1,1,1,1,1,1,1
1,1,1,1,1,1,1,1,1,2,3,1,1,1,1,1,1,1,1
1,1,1,1,1,1,1,1,1,1,1,1,1,1,1,1,1,1,1
1,1,1,1,1,1,1,1,1,1,1,1,1,1,1,1,1,1,1
1,1,1,1,1,1,1,1,1,1,1,1,1,1,1,1,1,1,1
1,1,1,1,1,1,1,1,1,1,1,1,1,1,1,1,1,1,1
1,1,1,1,1,1,1,1,1,1,1,1,1,1,1,1,1,1,1
1,1,1,1,1,1,1,1,1,1,1,1,1,1,1,1,1,1,1
1,1,1,1,1,1,1,1,1,1,1,1,1,1,1,1,1,1,1
1,1,1,1,1,1,1,1,1,1,1,1,1,1,1,1,1,1,1
endlayer

layer
1,1,1,1,1,1,1,4,4,4,4,1,1,1,1,1,1,1,1
1,1,1,1,1,4,4,4,1,1,4,4,4,1,1,1,1,1,1
1,1,1,1,4,4,1,1,1,1,1,1,4,4,3,1,1,1,1
1,1,1,2,4,1,1,1,1,1,1,1,1,1,4,3,1,1,1
1,1,2,4,1,1,1,1,1,1,1,1,1,1,1,4,4,1,1
1,1,4,1,1,1,1,1,1,1,1,1,1,1,1,1,4,1,1
1,4,4,1,1,1,1,1,1,1,1,1,1,1,1,1,4,4,1
1,4,1,1,1,1,1,1,1,1,1,1,1,1,1,1,1,3,1
4,4,1,1,1,1,1,1,2,2,1,1,1,1,1,1,1,4,3
4,1,1,1,1,1,1,2,2,2,2,3,1,1,1,1,1,1,4
4,1,1,1,1,1,1,2,2,2,2,2,1,1,1,1,1,1,4
3,4,1,1,1,1,1,1,3,2,2,1,1,1,1,1,1,1,4
1,3,1,1,1,1,1,1,1,3,1,1,1,1,1,1,1,4,4
1,4,4,1,1,1,1,1,1,1,1,1,1,1,1,1,1,4,1
1,1,4,1,1,1,1,1,1,1,1,1,1,1,1,1,4,4,1
1,1,4,4,1,1,1,1,1,1,1,1,1,1,1,4,3,1,1
1,1,1,4,4,1,1,1,1,1,1,1,1,1,4,3,1,1,1
1,1,1,1,4,4,1,1,1,1,1,1,4,4,4,1,1,1,1
1,1,1,1,1,4,4,4,1,1,4,4,4,1,1,1,1,1,1
1,1,1,1,1,1,1,4,4,4,4,1,1,1,1,1,1,1,1
endlayer

layer
1,1,1,1,1,1,4,4,4,4,4,4,1,1,1,1,1,1,1
1,1,1,1,4,4,5,1,1,1,1,5,4,4,1,1,1,1,1
1,1,1,4,5,1,1,1,1,1,1,1,1,5,3,3,1,1,1
1,1,2,4,1,1,1,1,1,1,1,1,1,1,1,5,4,1,1
1,1,2,1,1,1,1,1,1,1,1,1,1,1,1,1,4,1,1
1,4,1,1,1,1,1,1,1,1,1,1,1,1,1,1,5,4,1
1,4,1,1,1,1,1,1,1,1,1,1,1,1,1,1,1,4,1
4,5,1,1,1,1,1,1,1,3,1,1,1,1,1,1,1,5,4
4,1,1,1,1,1,1,3,2,2,3,1,1,1,1,1,1,1,4
4,1,1,1,1,1,3,2,2,2,2,2,1,1,1,1,1,1,4
4,1,1,1,1,1,1,2,2,2,2,2,1,1,1,1,1,1,4
3,1,1,1,1,1,1,3,2,2,2,3,1,1,1,1,1,5,4
3,5,1,1,1,1,1,1,3,3,1,1,1,1,1,1,1,1,4
1,4,1,1,1,1,1,1,1,1,1,1,1,1,1,1,1,5,4
1,4,5,1,1,1,1,1,1,1,1,1,1,1,1,1,1,4,1
1,4,5,1,1,1,1,1,1,1,1,1,1,1,1,1,5,4,1
1,1,4,4,1,1,1,1,1,1,1,1,1,1,1,3,3,1,1
1,1,1,4,5,1,1,1,1,1,1,1,1,5,4,1,1,1,1
1,1,1,1,3,3,5,1,1,1,1,5,4,4,4,1,1,1,1
1,1,1,1,1,1,4,4,4,4,4,4,1,1,1,1,1,1,1
endlayer

layer
1,1,1,1,1,4,4,4,4,4,3,3,4,1,1,1,1,1,1
1,1,1,1,4,4,5,5,1,5,1,5,4,4,4,1,1,1,1
1,1,1,4,5,1,1,1,1,1,1,1,1,5,4,4,1,1,1
1,1,4,4,1,1,1,1,1,1,1,1,1,1,1,5,4,1,1
1,4,5,1,1,1,1,1,1,1,1,1,1,1,1,1,4,1,1
1,4,1,1,1,1,1,1,1,1,1,1,1,1,1,1,5,4,1
4,5,1,1,1,1,1,1,1,3,1,1,1,1,1,1,1,4,1
4,5,1,1,1,1,1,3,3,2,3,1,1,1,1,1,1,5,4
4,5,1,1,1,1,1,2,2,2,2,3,1,1,1,1,1,1,4
4,1,1,1,1,1,2,2,2,2,2,2,1,1,1,1,1,5,4
4,5,1,1,1,1,3,2,2,2,2,2,3,1,1,1,1,1,4
4,1,1,1,1,1,1,2,2,2,2,2,1,1,1,1,1,5,4
4,5,1,1,1,1,1,3,3,2,3,3,1,1,1,1,1,1,4
1,4,1,1,1,1,1,1,3,3,1,1,1,1,1,1,1,5,4
1,4,5,1,1,1,1,1,1,1,1,1,1,1,1,1,1,5,4
1,4,5,1,1,1,1,1,1,1,1,1,1,1,1,1,5,4,1
1,1,4,4,1,1,1,1,1,1,1,1,1,1,1,5,4,1,1
1,1,1,4,5,1,1,1,1,1,1,1,1,5,5,4,1,1,1
1,1,1,1,3,4,5,5,1,5,1,5,5,4,4,1,1,1,1
1,1,1,1,1,3,4,4,4,4,3,3,4,1,1,1,1,1,1
endlayer

layer
1,1,1,1,1,1,4,4,4,4,3,3,1,1,1,1,1,1,1
1,1,1,1,4,4,5,5,5,5,5,5,4,4,1,1,1,1,1
1,1,1,4,5,5,5,1,5,1,5,1,5,5,4,4,1,1,1
1,1,4,5,5,1,5,1,1,1,1,1,5,1,5,5,4,1,1
1,1,4,5,1,1,1,1,1,1,1,1,1,1,1,5,4,1,1
1,4,5,5,5,1,1,1,2,1,2,1,1,1,1,1,5,4,1
1,4,1,1,1,1,2,1,3,2,3,2,1,1,1,5,5,4,1
4,5,5,5,1,2,3,2,2,2,2,3,2,1,1,1,1,4,1
4,5,1,1,1,1,3,2,2,2,2,2,1,1,1,1,5,5,4
4,5,5,1,1,2,2,2,2,2,2,2,2,1,1,1,1,5,4
4,5,1,1,2,3,2,2,2,2,2,2,2,2,1,1,5,5,4
4,5,5,1,1,1,3,2,2,2,2,2,1,1,1,1,1,5,3
1,4,1,1,1,2,3,2,2,2,2,2,2,1,1,5,5,5,3
1,4,5,5,1,1,2,2,3,2,1,2,1,1,1,1,1,5,4
1,4,5,1,1,1,1,1,2,1,1,1,1,1,5,1,5,4,1
1,1,4,5,1,1,1,1,1,1,1,1,1,1,5,5,5,4,1
1,1,4,5,5,1,5,1,1,1,1,1,5,1,5,5,4,1,1
1,1,1,4,5,5,5,1,5,1,5,1,5,5,4,4,1,1,1
1,1,1,1,4,4,5,5,5,5,5,5,4,4,1,1,1,1,1
1,1,1,1,1,1,4,4,4,4,3,3,1,1,1,1,1,1,1
endlayer

layer
1,1,1,1,1,1,1,1,4,4,1,1,1,1,1,1,1,1,1
1,1,1,1,1,3,3,4,5,5,4,4,4,1,1,1,1,1,1
1,1,1,1,4,5,5,5,5,5,5,5,5,4,1,1,1,1,1
1,1,1,4,5,5,5,5,5,5,5,5,5,5,4,4,1,1,1
1,1,4,5,5,5,5,5,5,5,5,5,5,5,5,5,4,1,1
1,1,4,5,5,5,5,5,5,5,5,5,5,5,5,5,3,1,1
1,3,5,5,5,5,5,5,5,5,5,5,5,5,5,5,5,3,1
1,3,5,5,5,5,5,5,5,5,5,5,5,5,5,5,5,4,1
4,5,5,5,5,5,5,5,5,5,5,5,5,5,5,5,5,4,1
4,5,5,5,5,5,5,5,5,5,5,5,5,5,5,5,5,5,4
4,5,5,5,5,5,5,5,5,5,5,5,5,5,5,5,5,5,4
1,4,5,5,5,5,5,5,5,5,5,5,5,5,5,5,5,5,3
1,4,5,5,5,5,5,5,5,5,5,5,5,5,5,5,5,3,1
1,4,5,5,5,5,5,5,5,5,5,5,5,5,5,5,5,4,1
1,1,4,5,5,5,5,5,5,5,5,5,5,5,5,5,4,1,1
1,1,4,5,5,5,5,5,5,5,5,5,5,5,5,5,4,1,1
1,1,1,4,5,5,5,5,5,5,5,5,5,5,5,4,1,1,1
1,1,1,1,4,5,5,5,5,5,5,5,5,4,4,1,1,1,1
1,1,1,1,1,4,4,5,5,5,5,4,4,1,1,1,1,1,1
1,1,1,1,1,1,1,4,4,4,4,1,1,1,1,1,1,1,1
endlayer

layer
1,1,1,1,1,1,1,1,1,1,1,1,1,1,1,1,1,1,1
1,1,1,1,1,1,1,4,4,4,1,1,1,1,1,1,1,1,1
1,1,1,1,1,3,3,5,5,5,4,4,4,1,1,1,1,1,1
1,1,1,1,4,5,5,5,5,5,5,5,5,4,4,1,1,1,1
1,1,1,4,5,5,5,5,5,5,5,5,5,5,5,4,1,1,1
1,1,4,5,5,5,5,5,5,5,5,5,5,5,5,3,1,1,1
1,1,3,5,5,5,5,5,5,5,5,5,5,5,5,5,3,1,1
1,3,5,5,5,5,5,5,5,5,5,5,5,5,5,5,4,1,1
1,4,5,5,5,5,5,5,5,5,5,5,5,5,5,5,5,4,1
1,4,5,5,5,5,5,5,5,5,5,5,5,5,5,5,5,4,1
1,4,5,5,5,5,5,5,5,5,5,5,5,5,5,5,5,4,1
1,4,4,5,5,5,5,5,5,5,5,5,5,5,5,5,5,4,1
1,1,4,5,5,5,5,5,5,5,5,5,5,5,5,5,5,4,1
1,1,3,5,5,5,5,5,5,5,5,5,5,5,5,5,4,1,1
1,1,1,4,5,5,5,5,5,5,5,5,5,5,5,5,4,1,1
1,1,1,4,5,5,5,5,5,5,5,5,5,5,5,4,1,1,1
1,1,1,1,4,5,5,5,5,5,5,5,5,4,3,1,1,1,1
1,1,1,1,1,4,4,5,5,5,5,4,4,1,1,1,1,1,1
1,1,1,1,1,1,1,4,4,4,4,1,1,1,1,1,1,1,1
1,1,1,1,1,1,1,1,1,1,1,1,1,1,1,1,1,1,1
endlayer

layer
1,1,1,1,1,1,1,1,1,1,1,1,1,1,1,1,1,1,1
1,1,1,1,1,1,1,1,1,1,1,1,1,1,1,1,1,1,1
1,1,1,1,1,1,4,4,4,4,4,1,1,1,1,1,1,1,1
1,1,1,1,1,4,4,4,5,5,5,3,3,1,1,1,1,1,1
1,1,1,1,4,4,5,5,5,5,5,5,5,4,4,1,1,1,1
1,1,1,4,4,5,5,5,5,5,5,5,5,5,4,4,1,1,1
1,1,1,4,5,5,5,5,5,5,5,5,5,5,5,4,1,1,1
1,1,4,4,5,5,5,5,5,5,5,5,5,5,5,4,1,1,1
1,1,4,5,5,5,5,5,5,5,5,5,5,5,5,4,4,1,1
1,1,4,5,5,5,5,5,5,5,5,5,5,5,5,5,4,1,1
1,1,4,5,5,5,5,5,5,5,5,5,5,5,5,5,4,1,1
1,1,4,5,5,5,5,5,5,5,5,5,5,5,5,5,4,1,1
1,1,3,3,5,5,5,5,5,5,5,5,5,5,5,4,4,1,1
1,1,1,3,5,5,5,5,5,5,5,5,5,5,5,4,1,1,1
1,1,1,1,4,5,5,5,5,5,5,5,5,5,4,4,1,1,1
1,1,1,1,4,4,5,5,5,5,5,5,5,3,3,1,1,1,1
1,1,1,1,1,4,4,5,5,5,5,4,4,3,1,1,1,1,1
1,1,1,1,1,1,1,4,4,4,4,4,1,1,1,1,1,1,1
1,1,1,1,1,1,1,1,1,1,1,1,1,1,1,1,1,1,1
1,1,1,1,1,1,1,1,1,1,1,1,1,1,1,1,1,1,1
endlayer

layer
1,1,1,1,1,1,1,1,1,1,1,1,1,1,1,1,1,1,1
1,1,1,1,1,1,1,1,1,1,1,1,1,1,1,1,1,1,1
1,1,1,1,1,1,1,1,1,1,1,1,1,1,1,1,1,1,1
1,1,1,1,1,1,1,1,4,4,4,1,1,1,1,1,1,1,1
1,1,1,1,1,1,4,4,4,4,4,3,3,1,1,1,1,1,1
1,1,1,1,1,4,4,4,5,5,5,5,4,4,1,1,1,1,1
1,1,1,1,4,4,5,5,5,5,5,5,5,4,4,1,1,1,1
1,1,1,1,4,5,5,5,5,5,5,5,5,5,4,1,1,1,1
1,1,1,4,4,5,5,5,5,5,5,5,5,5,4,1,1,1,1
1,1,1,4,5,5,5,5,5,5,5,5,5,5,5,4,1,1,1
1,1,1,4,5,5,5,5,5,5,5,5,5,5,5,4,1,1,1
1,1,1,4,5,5,5,5,5,5,5,5,5,5,4,4,1,1,1
1,1,1,1,4,5,5,5,5,5,5,5,5,5,4,1,1,1,1
1,1,1,1,4,4,5,5,5,5,5,5,5,4,4,1,1,1,1
1,1,1,1,4,4,4,5,5,5,5,5,4,4,1,1,1,1,1
1,1,1,1,1,4,4,3,5,5,5,4,4,1,1,1,1,1,1
1,1,1,1,1,1,1,3,3,4,4,1,1,1,1,1,1,1,1
1,1,1,1,1,1,1,1,1,1,1,1,1,1,1,1,1,1,1
1,1,1,1,1,1,1,1,1,1,1,1,1,1,1,1,1,1,1
1,1,1,1,1,1,1,1,1,1,1,1,1,1,1,1,1,1,1
endlayer

layer
1,1,1,1,1,1,1,1,1,1,1,1,1,1,1,1,1,1,1
1,1,1,1,1,1,1,1,1,1,1,1,1,1,1,1,1,1,1
1,1,1,1,1,1,1,1,1,1,1,1,1,1,1,1,1,1,1
1,1,1,1,1,1,1,1,1,1,1,1,1,1,1,1,1,1,1
1,1,1,1,1,1,1,1,1,1,1,1,1,1,1,1,1,1,1
1,1,1,1,1,1,1,1,4,4,4,4,1,1,1,1,1,1,1
1,1,1,1,1,1,4,4,4,4,4,4,4,1,1,1,1,1,1
1,1,1,1,1,4,4,3,5,5,5,4,4,4,1,1,1,1,1
1,1,1,1,1,4,4,5,5,5,5,5,4,4,1,1,1,1,1
1,1,1,1,4,4,5,5,5,5,5,5,5,3,3,1,1,1,1
1,1,1,1,4,4,5,5,5,5,5,5,5,3,3,1,1,1,1
1,1,1,1,4,4,5,5,5,5,5,5,5,4,1,1,1,1,1
1,1,1,1,1,4,4,5,5,5,5,5,4,4,1,1,1,1,1
1,1,1,1,1,4,4,4,5,5,5,4,4,1,1,1,1,1,1
1,1,1,1,1,1,4,4,4,4,4,4,1,1,1,1,1,1,1
1,1,1,1,1,1,1,1,3,4,4,1,1,1,1,1,1,1,1
1,1,1,1,1,1,1,1,1,1,1,1,1,1,1,1,1,1,1
1,1,1,1,1,1,1,1,1,1,1,1,1,1,1,1,1,1,1
1,1,1,1,1,1,1,1,1,1,1,1,1,1,1,1,1,1,1
1,1,1,1,1,1,1,1,1,1,1,1,1,1,1,1,1,1,1
endlayer

layer
1,1,1,1,1,1,1,1,1,1,1,1,1,1,1,1,1,1,1
1,1,1,1,1,1,1,1,1,1,1,1,1,1,1,1,1,1,1
1,1,1,1,1,1,1,1,1,1,1,1,1,1,1,1,1,1,1
1,1,1,1,1,1,1,1,1,1,1,1,1,1,1,1,1,1,1
1,1,1,1,1,1,1,1,1,1,1,1,1,1,1,1,1,1,1
1,1,1,1,1,1,1,1,1,1,1,1,1,1,1,1,1,1,1
1,1,1,1,1,1,1,1,1,1,1,1,1,1,1,1,1,1,1
1,1,1,1,1,1,1,1,3,4,4,1,1,1,1,1,1,1,1
1,1,1,1,1,1,1,3,3,4,4,4,1,1,1,1,1,1,1
1,1,1,1,1,1,4,4,4,4,4,4,4,1,1,1,1,1,1
1,1,1,1,1,1,4,4,4,4,4,4,4,1,1,1,1,1,1
1,1,1,1,1,1,4,4,4,4,4,4,4,1,1,1,1,1,1
1,1,1,1,1,1,1,4,4,4,4,4,1,1,1,1,1,1,1
1,1,1,1,1,1,1,1,4,4,4,1,1,1,1,1,1,1,1
1,1,1,1,1,1,1,1,1,1,1,1,1,1,1,1,1,1,1
1,1,1,1,1,1,1,1,1,1,1,1,1,1,1,1,1,1,1
1,1,1,1,1,1,1,1,1,1,1,1,1,1,1,1,1,1,1
1,1,1,1,1,1,1,1,1,1,1,1,1,1,1,1,1,1,1
1,1,1,1,1,1,1,1,1,1,1,1,1,1,1,1,1,1,1
1,1,1,1,1,1,1,1,1,1,1,1,1,1,1,1,1,1,1
endlayer

