
# Created by Ruins mod version 16.8 Ingame Parser
# authoring Player: ST753M

weight=1
uniqueMinDistance=3000
spawnMinDistance=2000
embed_into_distance=10
acceptable_target_blocks=water,sand
unacceptable_target_blocks=
dimensions=23,31,31
allowable_overhang=0
max_leveling=0
leveling_buffer=0
preserve_water=0
preserve_lava=0
preventRotation=1

biomesToSpawnIn=beach,ocean,kelp_forest,coral_reef

rule1=0,100,preserveBlock
rule2=0,100,minecraft:sandstone-0
rule3=0,100,minecraft:birch_stairs-3
rule4=0,100,minecraft:carpet-14
rule5=0,100,minecraft:birch_stairs-4
rule6=0,100,minecraft:sandstone-1
rule7=0,100,ChestGenHook:chests/simple_dungeon:5-4
rule8=0,100,minecraft:sand-0
rule9=0,100,minecraft:sandstone_stairs-7
rule10=0,100,minecraft:sandstone_stairs-6
rule11=0,100,minecraft:log-0
rule12=0,100,minecraft:birch_stairs-6
rule13=0,100,minecraft:grass-0
rule14=0,100,minecraft:birch_stairs-7
rule15=0,100,minecraft:redstone_wire-15
rule16=1,100,minecraft:redstone_torch-5
rule17=0,100,minecraft:redstone_wire-14
rule18=0,100,air
rule19=0,100,minecraft:unlit_redstone_torch-4
rule20=0,100,minecraft:redstone_wire-0
rule21=0,100,minecraft:unlit_redstone_torch-1
rule22=0,100,IInventory;minecraft:dispenser;minecraft:spawn_egg#{EntityTag:{id:"minecraft:villager"}}#0#4-1
rule23=0,100,minecraft:dirt-0
rule24=0,100,ChestGenHook:chests/simple_dungeon:2-3,air
rule25=1,100,minecraft:torch-5
rule26=0,100,minecraft:water-0
rule27=0,100,minecraft:sandstone_stairs-3
rule28=0,100,minecraft:sandstone_stairs-5
rule29=0,100,minecraft:sandstone_stairs-1
rule30=0,100,minecraft:sandstone_stairs-4
rule31=0,100,minecraft:sandstone_stairs-0
rule32=0,100,minecraft:tallgrass-1
rule33=0,100,minecraft:red_flower-0
rule34=0,100,minecraft:yellow_flower-0
rule35=0,100,minecraft:planks-2
rule36=0,100,minecraft:wooden_slab-10
rule37=0,100,minecraft:birch_stairs-1
rule38=0,100,minecraft:leaves-4
rule39=0,100,minecraft:stone_slab-1
rule40=0,100,minecraft:ladder-5
rule41=0,100,minecraft:wooden_door-3
rule42=0,100,minecraft:wooden_door-1
rule43=0,100,minecraft:oak_stairs-1
rule44=0,100,minecraft:bookshelf-0
rule45=0,100,minecraft:oak_stairs-2
rule46=0,100,minecraft:wooden_door-7
rule47=0,100,minecraft:birch_stairs-2
rule48=0,100,minecraft:bed-0
rule49=0,100,minecraft:bed-8
rule50=0,100,minecraft:wooden_door-2
rule51=0,100,minecraft:ladder-3
rule52=0,100,minecraft:oak_stairs-3
rule53=0,100,minecraft:fence-0
rule54=0,100,minecraft:birch_stairs-0
rule55=0,100,minecraft:oak_stairs-0
rule56=0,100,minecraft:wooden_door-0
rule57=0,100,minecraft:double_stone_slab-1
rule58=0,100,minecraft:glass_pane-0
rule59=0,100,minecraft:wooden_door-8
rule60=0,100,minecraft:wooden_door-9
rule61=2,100,minecraft:torch-4
rule62=0,100,minecraft:wooden_pressure_plate-0
rule63=0,100,minecraft:wooden_slab-2
rule64=0,100,minecraft:double_wooden_slab-2
rule65=0,100,minecraft:bed-3
rule66=0,100,minecraft:bed-11
rule67=0,100,minecraft:bed-10
rule68=0,100,minecraft:bed-2
rule69=0,100,minecraft:bed-9
rule70=0,100,minecraft:bed-1

layer
1,1,1,1,1,1,1,1,1,1,1,1,2,2,2,2,2,2,2,1,1,1,1,1,1,1,1,1,1,1,1
1,1,1,1,1,1,1,1,1,2,2,2,2,2,2,2,2,2,2,2,2,2,1,1,1,1,1,1,1,1,1
1,1,1,1,1,1,1,2,2,2,2,2,2,2,2,2,2,2,2,2,2,2,2,2,1,1,1,1,1,1,1
1,1,1,1,1,1,2,2,2,2,2,2,2,2,2,2,2,2,2,2,2,2,2,2,2,1,1,1,1,1,1
1,1,1,1,1,2,2,2,2,2,2,2,2,2,2,2,2,2,2,2,2,2,2,2,2,2,1,1,1,1,1
1,1,1,1,2,2,2,2,2,2,2,2,2,2,2,2,2,2,2,2,2,2,2,2,2,2,2,1,1,1,1
1,1,1,2,2,2,2,2,2,2,2,2,2,2,2,2,2,2,2,2,2,2,2,2,2,2,2,2,1,1,1
1,1,2,2,2,2,2,2,2,2,2,2,2,2,2,2,2,2,2,2,2,2,2,2,2,2,2,2,2,1,1
1,1,2,2,2,2,2,2,2,2,2,2,2,2,2,2,2,2,2,2,2,2,2,2,2,2,2,2,2,1,1
1,2,2,2,2,2,2,2,2,2,2,2,2,2,2,2,2,2,2,2,2,2,2,2,2,2,2,2,2,2,1
1,2,2,2,2,2,2,2,2,2,2,2,2,2,2,2,2,2,2,2,2,2,2,2,2,2,2,2,2,2,1
1,2,2,2,2,2,2,2,2,2,2,2,2,2,2,2,2,2,2,2,2,2,2,2,2,2,2,2,2,2,1
2,2,2,2,2,2,2,2,2,2,2,2,2,2,2,2,2,2,2,2,2,2,2,2,2,2,2,2,2,2,2
2,2,2,2,2,2,2,2,2,2,2,2,2,2,2,2,2,2,2,2,2,2,2,2,2,2,2,2,2,2,2
2,2,2,2,2,2,2,2,2,2,2,2,2,2,2,2,2,2,2,2,2,2,2,2,2,2,2,2,2,2,2
2,2,2,2,2,2,2,2,2,2,2,2,2,2,2,2,2,2,2,2,2,2,2,2,2,2,2,2,2,2,2
2,2,2,2,2,2,2,2,2,2,2,2,2,2,2,2,2,2,2,2,2,2,2,2,2,2,2,2,2,2,2
2,2,2,2,2,2,2,2,2,2,2,2,2,2,2,2,2,2,2,2,2,2,2,2,2,2,2,2,2,2,2
2,2,2,2,2,2,2,2,2,2,2,2,2,2,2,2,2,2,2,2,2,2,2,2,2,2,2,2,2,2,2
1,2,2,2,2,2,2,2,2,2,2,2,2,2,2,2,2,2,2,2,2,2,2,2,2,2,2,2,2,2,1
1,2,2,2,2,2,2,2,2,2,2,2,2,2,2,2,2,2,2,2,2,2,2,2,2,2,2,2,2,2,1
1,2,2,2,2,2,2,2,2,2,2,2,2,2,2,2,2,2,2,2,2,2,2,2,2,2,2,2,2,2,1
1,1,2,2,2,2,2,2,2,2,2,2,2,2,2,2,2,2,2,2,2,2,2,2,2,2,2,2,2,1,1
1,1,2,2,2,2,2,2,2,2,2,2,2,2,2,2,2,2,2,2,2,2,2,2,2,2,2,2,2,1,1
1,1,1,2,2,2,2,2,2,2,2,2,2,2,2,2,2,2,2,2,2,2,2,2,2,2,2,2,1,1,1
1,1,1,1,2,2,2,2,2,2,2,2,2,2,2,2,2,2,2,2,2,2,2,2,2,2,2,1,1,1,1
1,1,1,1,1,2,2,2,2,2,2,2,2,2,2,2,2,2,2,2,2,2,2,2,2,2,1,1,1,1,1
1,1,1,1,1,1,2,2,2,2,2,2,2,2,2,2,2,2,2,2,2,2,2,2,2,1,1,1,1,1,1
1,1,1,1,1,1,1,2,2,2,2,2,2,2,2,2,2,2,2,2,2,2,2,2,1,1,1,1,1,1,1
1,1,1,1,1,1,1,1,1,2,2,2,2,2,2,2,2,2,2,2,2,2,1,1,1,1,1,1,1,1,1
1,1,1,1,1,1,1,1,1,1,1,1,2,2,2,2,2,2,2,1,1,1,1,1,1,1,1,1,1,1,1
endlayer

layer
1,1,1,1,1,1,1,1,1,1,1,1,2,2,2,2,2,2,2,1,1,1,1,1,1,1,1,1,1,1,1
1,1,1,1,1,1,1,1,1,2,2,2,2,2,2,2,2,2,2,2,2,2,1,1,1,1,1,1,1,1,1
1,1,1,1,1,1,1,2,2,2,2,2,2,2,2,2,2,2,2,2,2,2,2,2,1,1,1,1,1,1,1
1,1,1,1,1,1,2,2,2,2,2,2,2,2,2,2,2,2,2,2,2,2,2,2,2,1,1,1,1,1,1
1,1,1,1,1,2,2,2,2,2,2,2,2,2,2,2,2,2,2,2,2,2,2,2,2,2,1,1,1,1,1
1,1,1,1,2,2,2,2,2,2,2,2,2,2,2,2,2,2,2,2,2,2,2,2,2,2,2,1,1,1,1
1,1,1,2,2,2,2,2,2,2,2,2,2,2,2,2,2,2,2,2,2,2,2,2,2,2,2,2,1,1,1
1,1,2,2,2,2,2,2,2,2,2,2,2,2,2,2,2,2,2,2,2,2,2,2,2,2,2,2,2,1,1
1,1,2,2,2,2,2,2,2,2,2,2,2,2,2,2,2,2,2,2,2,2,2,2,2,2,2,2,2,1,1
1,2,2,2,2,2,2,2,2,2,2,2,2,2,2,2,2,2,2,2,2,2,2,2,2,2,2,2,2,2,1
1,2,2,2,2,2,2,2,0,0,0,0,0,0,3,2,2,2,2,2,2,2,2,2,2,2,2,2,2,2,1
1,2,2,2,2,2,2,2,0,2,0,4,4,0,2,2,2,2,2,2,2,2,2,2,2,2,2,2,2,2,1
2,2,2,2,2,2,2,2,0,0,0,4,4,0,0,0,2,2,2,2,2,2,2,2,2,2,2,2,2,2,2
2,2,2,2,2,2,2,2,0,2,0,4,4,0,2,0,2,2,2,2,2,2,2,2,2,2,2,2,2,2,2
2,2,2,2,2,2,2,2,0,0,0,4,4,0,0,0,2,2,2,2,2,2,2,2,2,2,2,2,2,2,2
2,2,2,2,2,2,2,2,0,2,0,4,4,0,2,0,2,2,2,2,2,2,2,2,2,2,2,2,2,2,2
2,2,2,2,2,2,2,2,0,0,0,4,4,0,0,0,2,2,2,2,2,2,2,2,2,2,2,2,2,2,2
2,2,2,2,2,2,2,2,0,2,0,4,4,0,2,0,2,2,2,2,2,2,2,2,2,2,2,2,2,2,2
2,2,2,2,2,2,2,2,0,0,0,4,4,0,0,0,2,2,2,2,2,2,2,2,2,2,2,2,2,2,2
1,2,2,2,2,2,2,2,0,2,0,4,4,0,2,0,2,2,2,2,2,2,2,2,2,2,2,2,2,2,1
1,2,2,2,2,2,2,2,0,0,0,4,4,0,0,0,2,2,2,2,2,2,2,2,2,2,2,2,2,2,1
1,2,2,2,2,2,2,2,0,2,0,4,4,0,2,0,2,2,2,2,2,2,2,2,2,2,2,2,2,2,1
1,1,2,2,2,2,2,2,0,0,0,4,4,0,0,0,2,2,2,2,2,2,2,2,2,2,2,2,2,1,1
1,1,2,2,2,2,2,2,0,2,0,4,4,0,2,0,2,2,2,2,2,2,2,2,2,2,2,2,2,1,1
1,1,1,2,2,2,2,2,0,0,0,4,4,0,0,0,2,2,2,2,2,2,2,2,2,2,2,2,1,1,1
1,1,1,1,2,2,2,2,0,2,0,4,4,0,2,0,2,2,2,2,2,2,2,2,2,2,2,1,1,1,1
1,1,1,1,1,2,2,2,0,0,0,0,0,0,0,0,2,2,2,2,2,2,2,2,2,2,1,1,1,1,1
1,1,1,1,1,1,2,2,2,2,0,5,5,0,2,2,2,2,2,2,2,2,2,2,2,1,1,1,1,1,1
1,1,1,1,1,1,1,2,2,2,2,2,2,2,2,2,2,2,2,2,2,2,2,2,1,1,1,1,1,1,1
1,1,1,1,1,1,1,1,1,2,2,2,2,2,2,2,2,2,2,2,2,2,1,1,1,1,1,1,1,1,1
1,1,1,1,1,1,1,1,1,1,1,1,2,2,2,2,2,2,2,1,1,1,1,1,1,1,1,1,1,1,1
endlayer

layer
1,1,1,1,1,1,1,1,1,1,1,1,2,2,2,2,2,2,2,1,1,1,1,1,1,1,1,1,1,1,1
1,1,1,1,1,1,1,1,1,2,2,2,2,2,2,2,2,2,2,2,2,2,1,1,1,1,1,1,1,1,1
1,1,1,1,1,1,1,2,2,2,2,2,2,2,2,2,2,2,2,2,2,2,2,2,1,1,1,1,1,1,1
1,1,1,1,1,1,2,2,2,2,2,2,2,2,2,2,2,2,2,2,2,2,2,2,2,1,1,1,1,1,1
1,1,1,1,1,2,2,2,2,2,2,2,2,2,2,2,2,2,2,2,2,2,2,2,2,2,1,1,1,1,1
1,1,1,1,2,2,2,2,2,2,2,2,2,2,2,2,2,2,2,2,2,2,2,2,2,2,2,1,1,1,1
1,1,1,2,2,2,2,2,2,2,2,2,2,2,2,2,2,2,2,2,2,2,2,2,2,2,2,2,1,1,1
1,1,2,2,2,2,2,2,2,2,2,2,2,2,2,2,2,2,2,2,2,2,2,2,2,2,2,2,2,1,1
1,1,2,2,2,2,2,2,2,2,2,2,2,2,2,2,2,2,2,2,2,2,2,2,2,2,2,2,2,1,1
1,2,2,2,2,2,2,2,2,2,2,2,2,2,2,2,2,2,2,2,2,2,2,2,2,2,2,2,2,2,1
1,2,2,2,2,2,2,2,0,0,0,0,0,0,0,3,2,2,2,2,2,2,2,2,2,2,2,2,2,2,1
1,2,2,2,2,2,2,2,0,6,0,0,0,0,6,2,2,2,2,2,2,2,2,2,2,2,2,2,2,2,1
2,2,2,2,2,2,2,2,0,0,0,0,0,0,0,0,2,2,2,2,2,2,2,2,2,2,2,2,2,2,2
2,2,2,2,2,2,2,2,0,6,0,0,0,0,6,0,2,2,2,2,2,2,2,2,2,2,2,2,2,2,2
2,2,2,2,2,2,2,2,0,0,0,0,0,0,0,0,2,2,2,2,2,2,2,2,2,2,2,2,2,2,2
2,2,2,2,2,2,2,2,0,6,0,0,0,0,6,0,2,2,2,2,2,2,2,2,2,2,2,2,2,2,2
2,2,2,2,2,2,2,2,0,0,0,0,0,0,0,0,2,2,2,2,2,2,2,2,2,2,2,2,2,2,2
2,2,2,2,2,2,2,2,0,6,0,0,0,0,6,0,2,2,2,2,2,2,2,2,2,2,2,2,2,2,2
2,2,2,2,2,2,2,2,0,0,0,0,0,0,0,0,2,2,2,2,2,2,2,2,2,2,2,2,2,2,2
1,2,2,2,2,2,2,2,0,6,0,0,0,0,6,0,2,2,2,2,2,2,2,2,2,2,2,2,2,2,1
1,2,2,2,2,2,2,2,0,0,0,0,0,0,0,0,2,2,2,2,2,2,2,2,2,2,2,2,2,2,1
1,2,2,2,2,2,2,2,0,6,0,0,0,0,6,0,2,2,2,2,2,2,2,2,2,2,2,2,2,2,1
1,1,2,2,2,2,2,2,0,0,0,0,0,0,0,0,2,2,2,2,2,2,2,2,2,2,2,2,2,1,1
1,1,2,2,2,2,2,2,0,6,0,0,0,0,6,0,2,2,2,2,2,2,2,2,2,2,2,2,2,1,1
1,1,1,2,2,2,2,2,0,0,0,0,0,0,0,0,2,2,2,2,2,2,2,2,2,2,2,2,1,1,1
1,1,1,1,2,2,2,2,0,6,0,0,0,0,6,0,2,2,2,2,2,2,2,2,2,2,2,1,1,1,1
1,1,1,1,1,2,2,2,0,0,0,0,0,0,0,0,2,2,2,2,2,2,2,2,2,2,1,1,1,1,1
1,1,1,1,1,1,2,2,2,6,0,7,7,0,6,2,2,2,2,2,2,2,2,2,2,1,1,1,1,1,1
1,1,1,1,1,1,1,2,2,2,2,2,2,2,2,2,2,2,2,2,2,2,2,2,1,1,1,1,1,1,1
1,1,1,1,1,1,1,1,1,2,2,2,2,2,2,2,2,2,2,2,2,2,1,1,1,1,1,1,1,1,1
1,1,1,1,1,1,1,1,1,1,1,1,2,2,2,2,2,2,2,1,1,1,1,1,1,1,1,1,1,1,1
endlayer

layer
1,1,1,1,1,1,1,1,1,1,1,1,8,2,2,2,2,2,8,1,1,1,1,1,1,1,1,1,1,1,1
1,1,1,1,1,1,1,1,1,8,2,2,2,2,2,2,2,2,2,2,2,8,1,1,1,1,1,1,1,1,1
1,1,1,1,1,1,1,8,2,2,2,2,2,2,2,2,2,2,2,2,2,2,2,8,1,1,1,1,1,1,1
1,1,1,1,1,1,2,2,2,2,2,2,2,2,2,2,2,2,2,2,2,2,2,2,2,1,1,1,1,1,1
1,1,1,1,1,2,2,2,2,2,2,2,2,2,2,2,2,2,2,2,2,2,2,2,2,2,1,1,1,1,1
1,1,1,1,2,2,2,2,2,2,2,2,2,2,2,2,2,2,2,2,2,2,2,2,2,2,2,1,1,1,1
1,1,1,2,2,2,2,2,2,2,2,2,2,2,2,2,2,2,2,2,2,2,2,2,2,2,2,2,1,1,1
1,1,8,2,2,2,2,2,2,2,2,2,2,2,2,2,2,2,2,2,2,2,2,2,2,2,2,2,8,1,1
1,1,2,2,2,2,2,2,2,2,2,2,2,2,2,2,2,2,2,2,2,2,2,2,2,2,2,2,2,1,1
1,8,2,2,2,2,2,2,2,2,2,2,2,2,2,2,2,2,2,2,2,2,2,2,2,2,2,2,2,8,1
1,2,2,2,2,2,2,2,0,0,0,0,0,0,0,0,3,2,2,2,2,2,2,2,2,2,2,2,2,2,1
1,2,2,2,2,2,2,2,0,2,0,0,0,0,2,2,2,2,2,2,2,2,2,2,2,2,2,2,2,2,1
8,2,2,2,2,2,2,2,0,0,0,0,0,0,0,0,2,2,2,2,2,2,2,2,2,2,2,2,2,2,8
2,2,2,2,2,2,2,2,0,2,0,0,0,0,2,0,2,2,2,2,2,2,2,2,2,2,2,2,2,2,2
2,2,2,2,2,2,2,2,0,0,0,0,0,0,0,0,2,2,2,2,2,2,2,2,2,2,2,2,2,2,2
2,2,2,2,2,2,2,2,0,2,0,0,0,0,2,0,2,2,2,2,2,2,2,2,2,2,2,2,2,2,2
2,2,2,2,2,2,2,2,0,0,0,0,0,0,0,0,2,2,2,2,2,2,2,2,2,2,2,2,2,2,2
2,2,2,2,2,2,2,2,0,2,0,0,0,0,2,0,2,2,2,2,2,2,2,2,2,2,2,2,2,2,2
8,2,2,2,2,2,2,2,0,0,0,0,0,0,0,0,2,2,2,2,2,2,2,2,2,2,2,2,2,2,8
1,2,2,2,2,2,2,2,0,2,0,0,0,0,2,0,2,2,2,2,2,2,2,2,2,2,2,2,2,2,1
1,2,2,2,2,2,2,2,0,0,0,0,0,0,0,0,2,2,2,2,2,2,2,2,2,2,2,2,2,2,1
1,8,2,2,2,2,2,2,0,2,0,0,0,0,2,0,2,2,2,2,2,2,2,2,2,2,2,2,2,8,1
1,1,2,2,2,2,2,2,0,0,0,0,0,0,0,0,2,2,2,2,2,2,2,2,2,2,2,2,2,1,1
1,1,8,2,2,2,2,2,0,2,0,0,0,0,2,0,2,2,2,2,2,2,2,2,2,2,2,2,8,1,1
1,1,1,2,2,2,2,2,0,0,0,0,0,0,0,0,2,2,2,2,2,2,2,2,2,2,2,2,1,1,1
1,1,1,1,2,2,2,2,0,2,0,0,0,0,2,0,2,2,2,2,2,2,2,2,2,2,2,1,1,1,1
1,1,1,1,1,2,2,2,0,0,0,0,0,0,0,0,2,2,2,2,2,2,2,2,2,2,1,1,1,1,1
1,1,1,1,1,1,2,2,2,2,0,0,0,0,2,2,2,2,2,2,2,2,2,2,2,1,1,1,1,1,1
1,1,1,1,1,1,1,8,2,2,2,2,2,2,2,2,2,2,2,2,2,2,2,8,1,1,1,1,1,1,1
1,1,1,1,1,1,1,1,1,1,2,2,2,2,2,2,2,2,2,2,2,8,1,1,1,1,1,1,1,1,1
1,1,1,1,1,1,1,1,1,1,1,1,8,2,2,2,2,2,8,1,1,1,1,1,1,1,1,1,1,1,1
endlayer

layer
1,1,1,1,1,1,1,1,1,1,1,1,1,8,8,8,8,8,1,1,1,1,1,1,1,1,1,1,1,1,1
1,1,1,1,1,1,1,1,1,1,2,2,2,2,2,2,2,2,2,2,2,1,1,1,1,1,1,1,1,1,1
1,1,1,1,1,1,1,1,2,2,2,2,2,2,2,2,2,2,2,2,2,2,2,1,1,1,1,1,1,1,1
1,1,1,1,1,1,8,2,2,2,2,2,2,2,2,2,2,2,2,2,2,2,2,2,8,1,1,1,1,1,1
1,1,1,1,1,2,2,2,2,2,2,2,2,2,2,2,2,2,2,2,2,2,2,2,2,2,1,1,1,1,1
1,1,1,1,2,2,2,2,2,2,2,2,2,2,2,2,2,2,2,2,2,2,2,2,2,2,2,1,1,1,1
1,1,1,8,2,2,2,2,2,2,2,2,2,2,2,2,2,2,2,2,2,2,2,2,2,2,2,8,1,1,1
1,1,1,2,2,2,2,2,2,2,2,2,2,2,2,2,2,2,2,2,2,2,2,2,2,2,2,2,1,1,1
1,1,2,2,2,2,2,2,2,2,2,2,2,2,2,2,2,2,2,2,2,2,2,2,2,2,2,2,2,1,1
1,1,2,2,2,2,2,2,2,2,2,2,2,2,2,2,2,2,2,2,2,2,2,2,2,2,2,2,2,1,1
1,2,2,2,2,2,2,2,0,0,0,0,0,0,0,0,0,3,2,2,2,2,2,2,2,2,2,2,2,2,1
1,2,2,2,2,2,2,2,0,2,10,0,0,9,2,2,2,2,2,2,2,2,2,2,2,2,2,2,2,2,1
8,2,2,2,2,2,2,2,0,0,0,0,0,0,0,0,2,2,2,2,2,2,2,2,2,2,2,2,2,2,1
8,2,2,2,2,2,2,2,0,2,10,0,0,9,2,0,2,2,2,2,2,2,2,2,2,2,2,2,2,2,8
8,2,2,2,2,2,2,2,0,0,0,0,0,0,0,0,2,2,2,2,2,2,2,2,2,2,2,2,2,2,8
8,2,2,2,2,2,2,2,0,2,10,0,0,9,2,0,2,2,2,2,2,2,2,2,2,2,2,2,2,2,8
8,2,2,2,2,2,2,2,0,0,0,0,0,0,0,0,2,2,2,2,2,2,2,2,2,2,2,2,2,2,8
8,2,2,2,2,2,2,2,0,2,10,0,0,9,2,0,2,2,2,2,2,2,2,2,2,2,2,2,2,2,8
1,2,2,2,2,2,2,2,0,0,0,0,0,0,0,0,2,2,2,2,2,2,2,2,2,2,2,2,2,2,1
1,2,2,2,2,2,2,2,0,2,10,0,0,9,2,0,2,2,2,2,2,2,2,2,2,2,2,2,2,2,1
1,2,2,2,2,2,2,2,0,0,0,0,0,0,0,0,2,2,2,2,2,2,2,2,2,2,2,2,2,11,1
1,8,2,2,2,2,2,2,0,2,10,0,0,9,2,0,2,2,2,2,2,2,2,2,2,2,2,2,2,1,1
1,1,2,2,2,2,2,2,0,0,0,0,0,0,0,0,2,2,2,2,2,2,2,2,2,2,2,2,2,1,1
1,1,8,2,2,2,2,2,0,2,10,0,0,9,2,0,2,2,2,2,2,2,2,2,2,2,2,2,8,1,1
1,1,1,8,2,2,2,2,0,0,0,0,0,0,0,0,2,2,2,2,2,2,2,2,2,2,2,8,1,1,1
1,1,1,1,2,2,2,2,0,2,10,0,0,9,2,0,2,2,2,2,2,2,2,2,2,2,2,1,1,1,1
1,1,1,1,1,2,2,2,0,0,0,0,0,0,0,0,2,2,2,2,2,2,2,2,2,2,1,1,1,1,1
1,1,1,1,1,1,8,2,2,2,10,0,0,9,2,2,2,2,2,2,2,2,2,2,8,1,1,1,1,1,1
1,1,1,1,1,1,1,1,2,2,2,2,2,2,2,2,2,2,2,2,2,2,2,1,1,1,1,1,1,1,1
1,1,1,1,1,1,1,1,1,1,2,2,2,2,2,2,2,2,2,2,2,1,1,1,1,1,1,1,1,1,1
1,1,1,1,1,1,1,1,1,1,1,1,1,8,8,8,8,8,1,1,1,1,1,1,1,1,1,1,1,1,1
endlayer

layer
1,1,1,1,1,1,1,1,1,1,1,1,1,1,8,8,8,1,1,1,1,1,1,1,1,1,1,1,1,1,1
1,1,1,1,1,1,1,1,1,1,8,2,2,2,2,2,2,2,2,2,8,1,1,1,1,1,1,1,1,1,1
1,1,1,1,1,1,1,1,8,2,2,2,2,2,2,2,2,2,2,2,2,2,8,1,1,1,1,1,1,1,1
1,1,1,1,1,1,1,2,2,2,2,2,2,2,2,2,2,2,2,2,2,2,2,2,1,1,1,1,1,1,1
1,1,1,1,1,8,2,2,2,2,2,2,2,2,2,2,2,2,2,2,2,2,2,2,2,8,1,1,1,1,1
1,1,1,1,8,2,2,2,2,2,2,2,2,2,2,2,2,2,2,2,2,2,2,2,2,2,8,1,1,1,1
1,1,1,1,2,2,2,2,2,2,2,2,2,2,2,2,2,2,2,2,2,2,2,2,2,2,2,8,1,1,1
1,1,1,2,2,2,2,2,2,2,2,2,2,2,2,2,2,2,2,2,2,2,2,2,2,2,2,2,1,1,1
1,1,8,2,2,2,2,2,2,2,2,2,2,2,2,2,2,2,2,2,2,2,2,2,2,2,2,2,8,1,1
1,1,2,2,2,2,2,2,2,2,2,2,2,2,2,2,2,2,2,2,2,2,2,2,2,2,2,2,2,1,1
1,8,2,2,2,2,2,2,2,2,2,2,2,12,0,0,0,0,3,2,2,2,2,2,2,2,2,2,2,8,1
1,2,2,2,2,2,2,2,2,2,2,2,2,2,2,2,2,2,2,2,2,2,2,2,2,2,2,2,2,2,1
1,2,2,2,2,2,2,2,2,2,2,2,2,2,2,2,2,2,2,2,2,2,2,2,2,2,2,2,2,2,1
8,2,2,2,2,2,2,2,2,2,2,2,2,2,2,2,2,2,2,2,2,2,2,2,2,2,2,2,2,2,1
8,2,2,2,2,2,2,2,2,2,2,2,2,2,2,2,2,2,2,2,2,2,2,2,2,2,2,2,2,2,8
8,2,2,2,2,2,2,2,2,2,2,2,2,2,2,0,2,2,2,2,2,2,2,2,2,2,2,2,2,2,8
8,2,2,2,2,2,2,2,2,2,2,2,2,2,2,2,2,2,2,2,2,2,2,2,2,2,2,2,2,2,8
1,2,2,2,2,2,2,2,2,2,2,2,2,2,2,2,2,2,2,2,2,2,2,2,2,2,2,2,2,2,1
1,2,2,2,2,2,2,2,2,2,2,2,2,2,2,2,2,2,2,2,2,2,2,2,2,2,2,2,2,2,1
1,2,2,2,2,2,2,2,2,2,2,2,2,2,2,2,2,2,2,2,2,2,2,2,2,2,2,2,2,2,1
1,8,2,2,2,2,2,2,2,2,2,2,2,2,2,2,2,2,2,2,2,2,2,2,2,2,2,2,2,11,1
1,8,2,2,2,2,2,2,2,2,2,2,2,2,2,2,2,2,2,2,2,2,2,2,2,2,2,2,2,1,1
1,1,8,2,2,2,2,2,2,2,2,2,2,2,2,2,2,2,2,2,2,2,2,2,2,2,2,2,8,1,1
1,1,8,2,2,2,2,2,2,2,2,2,2,2,2,2,2,2,2,2,2,2,2,2,2,2,2,2,8,1,1
1,1,1,8,2,2,2,2,2,2,2,2,2,2,2,2,2,2,2,2,2,2,2,2,2,2,2,1,1,1,1
1,1,1,1,8,2,2,2,2,2,2,2,2,2,2,2,2,2,2,2,2,2,2,2,2,2,8,1,1,1,1
1,1,1,1,1,1,2,2,2,2,2,2,2,2,2,2,2,2,2,2,2,2,2,2,2,13,1,1,1,1,1
1,1,1,1,1,1,1,2,2,2,2,2,2,2,2,2,2,2,2,2,2,2,2,2,1,1,1,1,1,1,1
1,1,1,1,1,1,1,1,8,2,2,2,2,2,2,2,2,2,2,2,2,2,8,1,1,1,1,1,1,1,1
1,1,1,1,1,1,1,1,1,1,8,2,2,2,2,2,2,2,2,2,8,1,1,1,1,1,1,1,1,1,1
1,1,1,1,1,1,1,1,1,1,1,1,1,1,8,8,8,1,1,1,1,1,1,1,1,1,1,1,1,1,1
endlayer

layer
1,1,1,1,1,1,1,1,1,1,1,1,1,1,1,1,1,1,1,1,1,1,1,1,1,1,1,1,1,1,1
1,1,1,1,1,1,1,1,1,1,1,8,8,2,2,2,2,2,8,8,1,1,1,1,1,1,1,1,1,1,1
1,1,1,1,1,1,1,1,1,8,2,2,2,2,2,2,2,2,2,2,2,8,1,1,1,1,1,1,1,1,1
1,1,1,1,1,1,1,1,2,2,2,2,2,2,2,2,2,2,2,2,2,2,2,8,1,1,1,1,1,1,1
1,1,1,1,1,1,2,2,2,2,2,2,2,2,2,2,2,2,2,2,2,2,2,2,2,1,1,1,1,1,1
1,1,1,1,1,2,2,2,0,0,2,2,0,0,0,2,0,0,0,2,2,2,2,2,2,2,1,1,1,1,1
1,1,1,1,2,2,2,2,0,0,0,0,0,0,14,2,0,0,0,0,0,0,0,2,2,2,2,1,1,1,1
1,1,1,8,2,2,2,0,0,0,0,0,0,0,14,2,0,0,0,0,0,0,0,2,2,2,2,8,1,1,1
1,1,1,2,2,2,0,0,0,0,2,2,0,0,0,2,0,0,0,2,0,0,0,2,2,2,2,2,1,1,1
1,1,8,2,2,0,0,0,0,2,16,15,2,2,2,2,2,2,2,11,0,0,0,0,0,2,2,2,8,1,1
1,1,2,2,2,0,0,0,2,18,0,17,2,2,12,0,0,0,0,0,0,0,0,2,0,2,2,2,2,1,1
1,8,2,2,2,0,0,0,2,2,18,2,19,2,2,2,2,2,2,11,0,0,0,0,0,2,2,2,2,8,1
1,8,2,2,2,0,0,0,2,2,2,21,20,20,20,20,20,20,20,2,0,0,0,2,0,2,2,2,2,8,1
1,2,2,2,2,0,0,2,0,0,0,2,20,2,20,2,20,2,20,2,0,0,0,0,0,2,2,2,2,2,1
1,2,2,2,2,0,0,0,0,0,0,2,20,2,22,2,22,2,20,2,0,0,0,2,0,2,2,2,2,2,1
1,2,2,2,2,0,0,0,0,0,0,2,20,20,22,2,22,20,20,2,0,0,0,0,0,2,2,2,2,2,1
1,8,2,2,2,0,0,2,0,0,0,2,20,2,22,2,22,2,20,2,0,0,0,2,0,2,2,2,2,2,1
1,2,2,2,2,0,0,0,2,2,2,2,20,2,20,2,20,2,20,2,0,0,0,0,0,2,2,2,2,2,1
1,8,2,2,2,0,0,0,0,0,0,2,20,20,20,20,20,20,20,2,0,0,0,2,0,2,2,2,2,8,1
1,8,2,2,2,0,0,0,0,0,0,0,2,2,2,2,2,2,2,0,0,0,0,0,0,2,2,2,2,8,1
1,8,2,2,2,2,0,0,0,0,0,0,0,0,0,0,0,0,0,0,0,0,0,2,0,2,2,2,2,11,1
1,1,8,2,2,2,0,0,0,0,0,0,0,0,0,0,0,0,0,0,0,0,0,0,0,2,2,2,8,1,1
1,1,8,2,2,2,2,0,0,2,2,2,2,2,0,0,0,0,0,0,0,0,0,2,2,2,2,2,8,1,1
1,1,1,8,2,2,2,0,0,3,2,2,2,2,0,2,0,2,0,2,0,2,0,2,2,2,2,23,1,1,1
1,1,1,8,2,2,2,2,2,2,2,2,2,2,0,0,0,0,0,0,0,0,0,2,2,2,2,1,1,1,1
1,1,1,1,8,2,2,2,2,2,2,2,2,2,2,2,2,2,2,2,2,2,2,2,2,2,1,1,1,1,1
1,1,1,1,1,1,2,2,2,2,2,2,2,2,2,2,2,2,2,2,2,2,2,2,2,1,1,1,1,1,1
1,1,1,1,1,1,1,8,2,2,2,2,2,2,2,2,2,2,2,2,2,2,2,23,1,1,1,1,1,1,1
1,1,1,1,1,1,1,1,8,11,2,2,2,2,2,2,2,2,2,2,2,8,1,1,1,1,1,1,1,1,1
1,1,1,1,1,1,1,1,1,1,1,8,8,2,8,2,2,2,8,8,1,1,1,1,1,1,1,1,1,1,1
1,1,1,1,1,1,1,1,1,1,1,1,1,1,1,1,1,1,1,1,1,1,1,1,1,1,1,1,1,1,1
endlayer

layer
1,1,1,1,1,1,1,1,1,1,1,1,1,1,1,1,1,1,1,1,1,1,1,1,1,1,1,1,1,1,1
1,1,1,1,1,1,1,1,1,1,1,1,1,8,8,8,8,8,1,1,1,1,1,1,1,1,1,1,1,1,1
1,1,1,1,1,1,1,1,1,1,8,2,2,2,2,2,2,2,2,2,8,23,1,1,1,1,1,1,1,1,1
1,1,1,1,1,1,1,1,8,2,2,2,2,2,2,2,2,2,2,2,2,2,23,1,1,1,1,1,1,1,1
1,1,1,1,1,1,8,2,2,2,2,2,2,6,2,2,2,2,2,2,2,2,2,2,8,1,1,1,1,1,1
1,1,1,1,1,8,2,2,0,0,2,2,0,0,0,2,0,0,0,2,2,6,2,2,2,11,1,1,1,1,1
1,1,1,1,8,2,2,2,0,0,0,0,0,0,0,2,0,0,0,0,0,0,0,2,2,2,8,1,1,1,1
1,1,1,1,2,2,2,0,0,0,0,0,0,0,24,2,0,0,0,0,0,0,0,6,2,2,2,1,1,1,1
1,1,1,8,2,2,0,0,0,0,2,2,0,0,0,2,0,0,0,2,0,0,0,2,2,2,2,8,1,1,1
1,1,1,2,2,0,0,0,0,2,0,0,2,6,2,2,2,2,2,11,0,0,0,0,0,2,2,2,1,1,1
1,1,8,2,2,0,0,0,2,8,0,0,2,2,2,12,0,0,0,0,0,0,0,2,0,2,2,2,8,1,1
1,1,2,2,2,0,0,0,2,26,2,25,0,2,2,2,2,2,2,11,0,0,0,0,0,2,2,2,2,1,1
1,1,2,2,2,0,0,0,2,2,2,2,0,2,2,2,2,2,2,2,0,0,0,2,0,2,2,2,2,1,1
1,8,2,2,2,0,0,2,0,0,0,2,0,2,2,2,2,2,2,2,0,0,0,0,0,2,2,2,2,11,1
1,8,2,2,2,0,0,0,0,0,0,2,0,2,26,26,26,2,2,2,0,0,0,2,0,2,2,2,2,1,1
1,8,2,2,2,0,0,0,0,0,0,2,0,2,26,26,26,2,2,2,0,0,0,0,0,2,2,2,2,1,1
1,8,2,2,2,0,0,2,0,0,0,2,2,2,26,26,26,2,2,2,0,0,0,2,0,2,2,2,2,1,1
1,8,2,2,2,0,0,0,2,2,2,2,2,2,2,2,2,2,2,2,0,0,0,0,0,2,2,2,2,11,1
1,8,2,2,2,0,0,0,0,0,0,2,2,2,2,2,2,2,2,2,0,0,0,2,0,2,2,2,2,1,1
1,8,2,2,2,0,0,0,0,0,0,0,2,2,2,2,2,2,2,0,0,0,0,0,0,2,2,2,2,0,1
1,1,8,2,2,2,0,0,0,0,0,0,0,0,0,0,0,0,0,0,0,0,0,2,0,2,2,2,8,11,1
1,1,8,2,2,2,0,0,0,0,0,0,0,0,0,0,0,0,0,0,0,0,0,0,0,2,2,2,8,1,1
1,1,1,8,2,2,2,0,0,27,2,2,2,2,0,0,0,0,0,0,0,0,0,2,2,2,2,13,1,1,1
1,1,1,8,2,2,2,0,0,0,3,2,2,2,0,2,0,2,0,2,0,2,0,2,2,2,2,13,1,1,1
1,1,1,1,8,2,2,2,2,2,2,2,2,2,0,0,0,0,0,0,0,0,0,2,2,2,13,1,1,1,1
1,1,1,1,1,8,2,2,2,2,2,2,2,2,2,2,2,2,2,2,2,2,2,2,2,13,1,1,1,1,1
1,1,1,1,1,1,8,2,2,2,2,2,2,2,2,2,2,2,2,2,2,2,2,2,13,1,1,1,1,1,1
1,1,1,1,1,1,1,1,8,2,2,2,2,2,2,2,2,2,2,2,2,2,23,13,1,1,1,1,1,1,1
1,1,1,1,1,1,1,1,1,11,8,2,2,2,2,2,2,2,2,2,8,1,1,1,1,1,1,1,1,1,1
1,1,1,1,1,1,1,1,1,1,1,8,8,8,8,8,8,8,8,8,1,1,1,1,1,1,1,1,1,1,1
1,1,1,1,1,1,1,1,1,1,1,1,1,1,1,1,1,1,1,1,1,1,1,1,1,1,1,1,1,1,1
endlayer

layer
1,1,1,1,1,1,1,1,1,1,1,1,1,1,1,1,1,1,1,1,1,1,1,1,1,1,1,1,1,1,1
1,1,1,1,1,1,1,1,1,1,1,1,1,1,1,1,1,1,1,1,1,1,1,1,1,1,1,1,1,1,1
1,1,1,1,1,1,1,1,1,1,1,8,8,2,2,2,2,2,8,8,23,13,1,1,1,1,1,1,1,1,1
1,1,1,1,1,1,1,1,1,8,2,2,2,2,2,2,2,2,2,2,2,8,13,1,1,1,1,1,1,1,1
1,1,1,1,1,1,1,8,2,2,2,2,2,2,2,2,2,2,2,2,2,2,2,23,1,1,1,1,1,1,1
1,1,1,1,1,1,8,2,0,0,2,2,0,0,0,2,0,0,0,2,2,2,2,2,8,11,1,1,1,1,1
1,1,1,1,1,8,2,2,0,0,28,0,0,0,0,29,0,0,0,28,0,0,0,2,2,8,1,1,1,1,1
1,1,1,1,8,2,2,0,0,0,30,0,0,0,0,31,0,0,0,30,0,0,0,2,2,2,8,1,1,1,1
1,1,1,1,2,2,0,0,0,0,2,2,0,0,0,2,0,0,0,2,0,0,0,2,2,2,2,1,1,1,1
1,1,1,8,2,0,0,0,0,2,2,2,2,2,2,2,2,2,2,11,0,0,0,0,0,2,2,8,1,1,1
1,1,1,2,2,0,0,0,2,2,2,2,2,2,2,2,12,0,0,0,0,0,0,2,0,2,2,2,1,1,1
1,1,8,2,2,0,0,0,2,2,2,2,0,2,2,2,2,2,2,11,0,0,0,0,0,2,2,2,8,1,1
1,1,11,2,2,0,0,0,2,2,2,2,0,2,2,2,2,2,2,2,0,0,0,2,0,2,2,2,8,1,1
1,1,2,2,2,0,0,2,0,0,0,2,0,2,2,2,2,2,2,2,0,0,0,0,0,2,2,2,2,11,1
1,1,2,2,2,0,0,28,0,0,0,2,0,2,26,26,26,2,2,2,0,0,0,2,0,2,2,2,2,1,1
1,1,2,2,2,0,0,30,0,0,0,2,0,2,26,26,26,2,2,2,0,0,0,0,0,2,2,2,2,1,1
1,1,2,2,2,0,0,2,0,0,0,2,2,2,26,26,26,2,2,2,0,0,0,2,0,2,2,2,2,1,1
1,1,2,2,2,0,0,0,2,2,2,2,2,2,2,2,2,2,2,2,0,0,0,0,0,2,2,2,2,11,1
1,1,8,2,2,0,0,0,0,0,0,2,2,2,2,2,2,2,2,2,0,0,0,2,0,2,2,2,8,1,1
1,1,8,2,2,0,0,0,0,0,0,0,2,2,2,2,2,2,2,0,0,0,0,0,0,2,2,2,8,0,1
1,1,8,2,2,2,0,0,0,0,0,0,0,0,0,0,0,0,0,0,0,0,0,2,0,2,2,2,13,11,1
1,1,1,8,2,2,0,0,0,0,0,0,0,0,0,0,0,0,0,0,0,0,0,0,0,2,2,23,1,1,1
1,1,1,8,2,2,2,0,0,0,2,2,2,2,0,0,0,0,0,0,0,0,0,2,2,2,2,32,1,1,1
1,1,1,1,8,2,2,0,0,0,0,3,2,2,0,2,0,2,0,2,0,2,0,2,2,2,11,32,1,1,1
1,1,1,1,8,8,2,2,2,2,2,2,2,2,0,0,0,0,0,0,0,0,0,2,2,13,32,1,1,1,1
1,1,1,1,1,1,11,2,2,2,2,2,2,2,2,2,2,2,2,2,2,2,2,2,13,32,1,1,1,1,1
1,1,1,1,1,1,1,13,2,2,2,2,2,2,2,2,2,2,2,2,2,2,2,11,1,1,1,1,1,1,1
1,1,1,1,1,1,1,1,1,23,2,2,2,2,2,2,2,2,2,2,2,23,13,1,1,1,1,1,1,1,1
1,1,1,1,1,1,1,1,1,11,8,11,8,2,2,2,2,2,8,8,1,1,1,1,1,1,1,1,1,1,1
1,1,1,1,1,1,1,1,1,1,1,1,1,8,8,8,8,8,1,1,1,1,1,1,1,1,1,1,1,1,1
1,1,1,1,1,1,1,1,1,1,1,1,1,1,1,1,1,1,1,1,1,1,1,1,1,1,1,1,1,1,1
endlayer

layer
1,1,1,1,1,1,1,1,1,1,1,1,1,1,1,1,1,1,1,1,1,1,1,1,1,1,1,1,1,1,1
1,1,1,1,1,1,1,1,1,1,1,1,1,1,1,1,1,1,1,1,1,1,1,1,1,1,1,1,1,1,1
1,1,1,1,1,1,1,1,1,1,1,1,8,8,8,8,8,8,23,13,13,32,1,1,1,1,1,1,1,1,1
1,1,1,1,1,1,1,1,1,8,8,8,2,2,2,2,2,2,2,8,8,13,32,1,1,1,1,1,1,1,1
1,1,1,1,1,1,1,1,8,2,2,2,2,2,2,2,2,2,2,2,2,2,23,13,1,1,1,1,1,1,1
1,1,1,1,1,1,1,8,0,0,2,2,28,28,28,2,0,0,0,2,2,2,2,8,13,11,1,1,1,1,1
1,1,1,1,1,1,8,2,0,0,2,10,0,0,0,28,0,0,0,2,0,0,0,2,8,13,1,1,1,1,1
1,1,1,1,1,8,2,0,0,0,2,10,0,0,0,30,0,0,0,2,0,0,0,2,2,8,1,1,1,1,1
1,1,1,1,8,2,0,0,0,0,2,2,30,30,30,2,0,0,0,2,0,0,0,2,2,2,2,1,1,1,1
1,1,1,1,2,0,0,0,0,2,2,2,2,2,2,2,2,2,2,11,0,0,0,0,0,2,2,1,1,1,1
1,1,1,8,2,0,0,0,2,2,2,2,2,2,2,2,2,12,0,0,0,0,0,2,0,2,2,8,1,1,1
1,1,1,8,2,0,0,0,2,2,2,2,2,2,2,2,2,2,2,11,0,0,0,0,0,2,2,8,1,1,1
1,1,11,2,2,0,0,0,2,2,2,2,2,2,2,2,2,2,2,2,0,0,0,2,0,2,2,2,1,1,1
1,1,8,2,2,0,0,2,0,0,0,2,2,2,2,2,2,2,2,2,0,0,0,0,0,2,2,2,8,11,1
1,1,11,2,2,0,0,2,0,0,0,2,2,2,26,26,26,2,2,2,0,0,0,2,0,2,2,2,8,1,1
1,1,13,2,2,0,0,2,0,0,0,2,2,2,26,26,26,2,2,2,0,0,0,0,0,2,2,2,8,1,1
1,1,13,2,2,0,0,2,0,0,0,2,2,2,26,26,26,2,2,2,0,0,0,2,0,2,2,2,8,1,1
1,1,13,2,2,0,0,0,2,2,2,2,2,2,2,2,2,2,2,2,0,0,0,0,0,2,2,2,8,11,1
1,1,23,2,2,0,0,0,0,0,0,2,2,2,2,2,2,2,2,2,0,0,0,2,0,2,2,2,13,1,1
1,1,1,8,2,0,0,0,0,0,0,0,2,2,2,2,2,2,2,0,0,0,0,0,0,2,2,23,13,0,1
1,1,1,8,2,2,0,0,0,0,0,0,0,0,0,0,0,0,0,0,0,0,0,2,0,2,2,13,33,11,1
1,1,1,8,2,2,0,0,0,0,0,0,0,0,0,0,0,0,0,0,0,0,0,0,0,2,2,13,1,1,1
1,1,1,1,8,2,2,10,0,9,2,2,2,2,0,0,0,0,0,0,0,0,0,2,2,2,2,1,1,1,1
1,1,1,1,8,8,2,12,0,0,0,0,3,2,0,2,0,2,0,2,0,2,0,2,2,2,11,1,1,1,1
1,1,1,1,1,1,13,2,2,2,2,2,2,2,0,0,0,0,0,0,0,0,0,2,13,32,1,1,1,1,1
1,1,1,1,1,1,11,13,2,2,2,2,2,2,2,2,2,2,2,2,2,2,2,13,32,1,1,1,1,1,1
1,1,1,1,1,1,1,32,2,2,2,2,2,2,2,2,2,2,2,2,2,2,13,11,1,1,1,1,1,1,1
1,1,1,1,1,1,1,1,1,13,13,23,2,2,2,2,2,2,2,23,13,13,32,1,1,1,1,1,1,1,1
1,1,1,1,1,1,1,1,1,11,0,11,0,8,8,8,8,8,0,1,1,1,1,1,1,1,1,1,1,1,1
1,1,1,1,1,1,1,1,1,1,1,1,1,1,1,1,1,1,1,1,1,1,1,1,1,1,1,1,1,1,1
1,1,1,1,1,1,1,1,1,1,1,1,1,1,1,1,1,1,1,1,1,1,1,1,1,1,1,1,1,1,1
endlayer

layer
1,1,1,1,1,1,1,1,1,1,1,1,1,1,1,1,1,1,1,1,1,1,1,1,1,1,1,1,1,1,1
1,1,1,1,1,1,1,1,1,1,1,1,1,1,1,1,1,1,1,1,1,1,1,1,1,1,1,1,1,1,1
1,1,1,1,1,1,1,1,1,1,1,1,1,1,1,1,1,0,11,32,32,1,1,1,1,1,1,1,1,1,1
1,1,1,1,1,1,1,1,1,1,1,8,8,8,8,8,13,13,13,13,13,32,0,1,1,1,1,1,1,1,1
1,1,1,1,1,1,1,1,1,8,8,2,2,2,2,2,2,2,2,2,23,2,13,34,1,1,1,1,1,1,1
1,1,1,1,1,1,1,1,2,2,2,2,2,2,2,2,2,2,2,2,2,2,8,13,32,11,1,1,1,1,1
1,1,1,1,1,1,1,11,2,2,2,35,35,35,35,2,2,2,2,2,2,2,2,8,13,34,1,1,1,1,1
1,1,1,1,1,1,8,2,2,2,2,35,35,35,35,2,2,2,2,2,2,2,2,2,13,13,1,1,1,1,1
1,1,1,1,1,8,2,2,2,2,2,2,2,2,2,2,2,2,2,2,2,2,2,2,2,2,2,1,1,1,1
1,1,1,1,8,2,2,2,2,2,2,2,2,2,2,2,2,2,2,11,2,2,2,2,2,2,2,1,1,1,1
1,1,1,0,8,2,2,2,2,2,2,2,2,2,2,2,2,2,2,2,2,2,2,2,2,2,2,1,1,1,1
1,1,1,0,2,2,2,2,2,2,2,2,2,2,2,2,2,2,2,11,2,2,2,2,2,2,2,1,1,1,1
1,1,11,0,2,2,2,2,2,2,2,2,2,2,2,2,2,2,2,2,2,2,2,2,2,2,2,8,1,1,1
1,1,0,13,2,2,2,2,2,2,2,2,2,2,2,2,2,2,2,2,2,2,2,2,2,2,2,8,1,11,1
1,1,11,13,2,2,2,2,2,2,2,2,2,2,26,26,26,2,2,2,2,2,2,2,2,2,2,8,1,1,1
1,1,1,13,2,2,2,2,2,2,2,2,2,2,26,26,26,2,2,2,2,2,2,2,2,2,2,8,1,1,1
1,1,34,13,2,2,2,2,2,2,2,2,2,2,26,26,26,2,2,2,2,2,2,2,2,2,2,8,1,1,1
1,1,32,13,2,2,2,2,2,2,2,2,2,2,2,2,2,2,2,2,2,2,2,2,2,2,2,13,1,11,1
1,1,11,13,2,2,2,2,2,2,2,2,2,2,2,2,2,2,2,2,2,2,2,2,2,2,2,13,32,1,1
1,1,1,13,2,2,2,2,2,2,2,2,2,2,2,2,2,2,2,2,2,2,2,2,2,2,2,13,32,0,1
36,36,36,36,36,2,2,2,2,2,2,2,2,2,2,2,2,2,2,2,2,2,2,2,2,2,2,32,0,11,1
36,36,36,36,36,2,2,2,2,2,2,2,2,2,2,2,2,2,2,2,2,2,2,2,2,2,2,32,1,1,1
1,1,1,1,8,8,2,2,2,2,2,2,2,2,2,2,2,2,2,2,2,2,2,2,2,23,2,1,1,1,1
1,1,1,1,1,8,13,2,12,0,0,0,0,3,2,2,2,2,2,2,2,2,2,2,2,2,11,1,1,1,1
1,1,1,1,1,1,32,13,2,2,2,2,2,2,2,2,2,2,2,2,2,2,2,13,32,1,1,1,1,1,1
1,1,1,1,1,1,11,34,2,2,2,2,2,2,2,2,2,2,2,2,2,2,13,32,1,1,1,1,1,1,1
1,1,1,1,1,1,1,1,2,2,2,2,2,2,2,2,2,2,2,2,13,13,32,11,1,1,1,1,1,1,1
1,1,1,1,1,1,1,1,1,32,34,13,13,13,13,13,13,23,13,13,32,32,1,1,1,1,1,1,1,1,1
1,1,1,1,1,1,1,1,1,11,0,11,0,1,1,1,0,0,0,1,1,1,1,1,1,1,1,1,1,1,1
1,1,1,1,1,1,1,1,1,1,1,1,1,1,1,1,1,1,1,1,1,1,1,1,1,1,1,1,1,1,1
1,1,1,1,1,1,1,1,1,1,1,1,1,1,1,1,1,1,1,1,1,1,1,1,1,1,1,1,1,1,1
endlayer

layer
1,1,1,1,1,1,1,1,1,1,1,1,1,1,1,1,1,1,1,1,1,1,1,1,1,1,1,1,1,1,1
1,1,1,1,1,1,1,1,1,1,1,1,1,1,1,1,1,1,1,1,1,1,1,1,1,1,1,1,1,1,1
1,1,1,1,1,1,1,1,1,1,1,1,1,1,1,1,1,0,11,1,1,1,1,1,1,1,1,1,1,1,1
1,1,1,1,1,1,1,1,1,1,1,1,1,1,1,1,32,32,32,32,0,0,0,1,1,1,1,1,1,1,1
1,1,1,1,1,1,1,1,1,1,1,13,13,13,13,13,13,11,11,11,11,11,0,1,1,1,1,1,1,1,1
1,1,1,1,1,1,1,1,1,13,13,2,2,2,2,2,2,2,2,2,23,2,13,32,0,11,1,1,1,1,1
1,1,1,1,1,1,1,11,13,2,2,2,2,2,2,2,2,2,2,2,2,2,13,13,32,0,1,1,1,1,1
1,1,1,1,1,1,1,13,2,2,2,2,2,2,2,2,2,2,2,2,2,2,2,13,32,32,1,1,1,1,1
1,1,1,1,1,1,2,2,2,2,2,2,2,2,2,2,2,2,2,2,2,2,2,2,11,11,11,1,1,1,1
1,1,1,1,1,13,2,2,2,2,2,2,2,2,2,2,2,2,2,2,2,2,2,2,2,23,11,1,1,1,1
1,1,1,0,0,13,2,2,2,2,2,2,2,2,2,2,2,2,2,2,2,2,2,2,2,23,11,1,1,1,1
1,1,1,0,2,2,2,2,2,2,2,2,2,2,2,2,2,2,2,2,2,2,2,2,2,2,11,1,1,1,1
1,1,11,0,2,2,2,2,2,2,2,2,2,2,2,2,2,2,2,2,2,2,2,2,2,2,11,1,1,1,1
1,1,0,0,2,2,2,2,2,2,2,2,2,2,2,2,2,2,2,2,2,2,2,2,2,2,8,1,1,11,1
1,1,11,32,2,2,2,2,2,2,2,2,2,2,26,26,26,2,2,2,2,2,2,2,2,2,8,36,36,36,36
1,1,1,32,2,2,2,2,2,2,2,2,2,2,26,26,26,2,2,2,2,2,2,2,2,2,8,36,36,36,36
1,1,1,32,13,2,2,2,2,2,2,2,2,2,26,26,26,2,2,2,2,2,2,2,2,2,8,36,36,36,36
1,1,0,32,13,2,2,2,2,2,2,2,2,2,2,2,2,2,2,2,2,2,2,2,2,2,13,32,1,11,1
1,1,11,32,13,2,2,2,2,2,2,2,2,2,2,2,2,2,2,2,2,2,2,2,2,2,13,32,1,1,1
1,1,0,0,13,2,2,2,2,2,2,2,2,2,2,2,2,2,2,2,2,2,2,2,2,2,2,32,0,0,1
1,1,1,1,1,27,2,2,2,2,2,2,2,2,2,2,2,2,2,2,2,2,2,2,2,23,2,0,0,11,1
1,1,1,1,1,27,2,2,2,2,2,2,2,2,2,2,2,2,2,2,2,2,2,2,2,23,2,1,1,1,1
1,1,1,1,1,13,23,2,2,2,2,2,2,37,35,2,2,2,2,2,2,2,2,2,23,2,2,1,1,1,1
1,1,1,1,1,1,33,13,2,2,12,0,0,0,35,2,2,2,2,2,2,2,2,2,2,2,11,1,1,1,1
1,1,1,1,1,1,1,32,2,2,2,2,2,2,2,2,2,2,2,2,2,2,23,0,1,1,1,1,1,1,1
1,1,1,1,1,1,11,1,2,23,23,2,2,2,2,2,2,2,2,2,13,13,32,0,1,1,1,1,1,1,1
1,1,1,1,1,1,1,1,2,2,2,2,2,13,13,13,13,13,13,13,32,32,0,11,1,1,1,1,1,1,1
1,1,1,1,1,1,1,1,1,1,1,32,32,32,33,32,32,11,32,1,1,1,1,1,1,1,1,1,1,1,1
1,1,1,1,1,1,1,1,1,11,1,11,0,1,1,1,0,0,0,1,1,1,1,1,1,1,1,1,1,1,1
1,1,1,1,1,1,1,1,1,1,1,1,1,1,1,1,1,1,1,1,1,1,1,1,1,1,1,1,1,1,1
1,1,1,1,1,1,1,1,1,1,1,1,1,1,1,1,1,1,1,1,1,1,1,1,1,1,1,1,1,1,1
endlayer

layer
1,1,1,1,1,1,1,1,1,1,1,1,1,1,1,1,1,1,1,1,1,1,1,1,1,1,1,1,1,1,1
1,1,1,1,1,1,1,1,1,1,1,1,1,1,1,1,1,38,38,38,1,1,1,1,1,1,1,1,1,1,1
1,1,1,1,1,1,1,1,1,1,1,1,1,1,1,1,1,38,11,38,1,1,1,1,1,1,1,1,1,1,1
1,1,1,1,1,1,1,1,1,1,1,1,1,1,1,1,0,38,38,38,0,0,0,1,1,1,1,1,1,1,1
1,1,1,1,1,1,1,1,1,1,1,32,32,1,1,32,34,2,2,2,2,2,30,30,30,30,10,1,1,1,1
1,1,1,1,1,1,1,1,1,32,1,2,2,2,2,13,13,2,35,35,35,2,36,36,36,35,10,1,1,1,1
1,1,1,1,1,1,1,11,32,13,13,2,35,35,2,13,8,2,35,35,35,2,36,36,36,36,10,1,1,1,1
1,1,1,1,1,1,1,32,13,13,13,2,35,35,2,13,8,2,2,2,2,2,35,36,36,36,10,1,1,1,1
1,1,1,1,1,1,2,2,2,2,13,2,2,2,2,13,8,2,35,35,35,2,2,2,2,2,2,1,1,1,1
1,1,1,1,1,32,2,35,35,2,13,13,8,13,13,13,8,2,35,35,35,2,35,35,35,35,2,1,1,1,1
1,1,1,0,0,32,2,35,35,2,8,8,8,8,13,13,8,2,2,2,2,2,35,35,35,35,2,1,1,1,1
1,9,30,30,2,2,2,2,2,2,13,13,13,8,13,13,8,13,8,8,8,2,35,35,35,35,2,1,1,1,1
1,9,35,36,2,35,35,35,35,2,13,13,8,8,8,8,8,8,8,13,13,2,2,2,2,2,2,1,1,1,1
1,9,36,36,2,35,35,35,35,2,8,8,8,2,2,2,2,2,8,13,13,13,13,13,13,13,1,1,1,11,1
1,9,35,36,2,35,35,35,35,2,13,13,8,2,26,26,26,2,8,8,8,8,8,8,8,39,1,1,1,1,1
1,28,28,28,2,2,2,2,2,2,13,13,8,2,26,26,26,2,8,8,8,8,8,8,8,39,1,1,1,1,1
1,1,1,0,0,11,35,35,2,13,13,13,8,2,26,26,26,2,8,8,8,8,8,8,8,39,1,1,1,1,1
1,1,0,0,32,11,35,35,2,8,8,13,8,2,2,2,2,2,8,13,13,23,13,13,8,13,32,1,1,11,1
1,1,11,0,32,11,35,35,2,13,8,8,8,8,8,8,8,8,8,13,13,13,13,13,8,13,32,1,1,1,1
1,1,0,0,32,11,11,2,2,13,8,13,2,2,2,2,2,13,13,13,13,13,2,2,2,2,2,30,30,30,30
1,1,1,1,1,1,27,13,13,13,8,13,2,35,35,35,2,2,2,2,13,13,2,35,35,35,2,36,36,35,10
1,1,1,1,1,1,27,8,8,8,8,13,2,37,35,35,35,35,35,2,13,13,2,35,35,35,2,36,36,36,10
1,1,1,1,1,32,13,13,2,2,2,2,2,0,35,35,35,35,35,2,13,13,2,35,35,35,2,36,36,36,10
1,1,1,1,1,1,1,32,2,35,35,12,0,0,35,35,35,35,35,2,13,13,2,2,2,2,11,36,36,36,10
1,1,1,1,1,1,1,1,2,35,35,35,2,2,2,2,2,2,2,11,13,13,9,36,36,36,36,36,36,36,10
1,1,1,1,1,1,11,1,2,35,35,35,2,13,13,13,13,13,13,13,32,1,9,36,36,36,36,36,36,36,10
1,1,1,1,1,1,1,1,2,2,2,2,2,32,32,32,34,32,32,32,1,1,9,35,36,36,36,36,36,36,10
1,1,1,1,1,1,1,1,9,36,36,36,10,1,1,1,0,11,0,1,1,1,28,28,28,28,28,28,28,28,10
1,1,1,1,1,1,1,1,9,35,36,35,10,1,1,1,0,0,0,1,1,1,1,1,1,1,1,1,1,1,1
1,1,1,1,1,1,1,1,9,28,28,28,28,1,1,1,1,1,1,1,1,1,1,1,1,1,1,1,1,1,1
1,1,1,1,1,1,1,1,1,1,1,1,1,1,1,1,1,1,1,1,1,1,1,1,1,1,1,1,1,1,1
endlayer

layer
1,1,1,1,1,1,1,1,1,1,1,1,1,1,1,1,1,1,1,1,1,1,1,1,1,1,1,1,1,1,1
1,1,1,1,1,1,1,1,1,1,1,1,1,1,1,1,1,38,38,38,1,1,1,1,1,1,1,1,1,1,1
1,1,1,1,1,1,1,1,1,1,1,1,1,1,1,1,1,38,38,38,1,1,1,1,1,1,1,1,1,1,1
1,1,1,1,1,1,1,1,1,1,1,1,1,1,1,1,0,38,38,38,0,0,0,1,1,1,1,1,1,1,1
1,1,1,1,1,1,1,1,1,1,1,1,1,1,1,1,0,2,2,2,2,2,39,39,39,39,39,1,1,1,1
1,1,1,1,1,1,1,1,1,1,1,2,2,2,2,32,32,2,40,0,0,2,0,0,0,0,39,1,1,1,1
1,1,1,1,1,1,1,11,0,32,32,2,0,0,2,34,0,42,0,0,0,41,0,0,0,0,39,1,1,1,1
1,1,1,1,1,1,1,0,32,32,32,2,0,0,2,0,0,2,2,2,2,2,0,0,0,0,39,1,1,1,1
1,1,1,1,1,1,2,2,2,2,32,2,0,2,2,32,0,2,0,0,0,2,2,2,2,2,2,1,1,1,1
1,1,1,1,1,1,2,0,0,2,33,1,1,32,32,34,0,0,0,0,0,2,0,43,43,0,2,1,1,1,1
1,1,1,0,0,0,2,0,0,0,0,1,1,1,32,32,0,11,2,2,2,11,0,0,0,0,2,1,1,1,1
1,39,39,39,2,2,2,2,2,2,32,32,32,1,32,32,1,3,12,0,0,41,0,44,44,0,2,1,1,1,1
1,39,0,0,2,45,0,0,0,2,34,32,0,0,0,0,0,0,0,0,32,2,2,2,2,2,2,1,1,1,1
1,39,0,0,42,0,0,0,0,46,0,0,0,2,2,2,2,2,0,32,0,32,32,34,32,34,1,1,1,25,1
1,39,0,0,2,0,14,47,0,2,0,0,1,2,26,26,26,2,0,1,1,0,1,1,1,1,1,1,1,1,1
1,39,39,39,2,2,2,2,2,2,32,32,1,2,26,26,26,2,0,1,1,0,1,1,1,1,1,1,1,1,1
1,1,1,0,0,2,49,48,2,32,32,32,1,2,26,26,26,2,1,1,0,0,0,1,1,1,1,1,1,1,1
1,38,38,38,1,2,0,0,41,0,0,32,1,2,2,2,2,2,1,32,32,11,32,32,1,32,1,1,1,1,1
1,38,11,38,1,2,49,48,2,0,0,0,1,0,0,0,0,0,1,32,32,32,32,32,1,32,1,1,1,1,1
1,38,38,38,1,2,2,2,2,32,0,32,2,2,50,2,2,34,32,32,32,32,2,2,50,2,2,39,39,39,39
1,1,1,1,0,0,0,32,32,32,0,32,2,0,0,0,2,2,2,11,32,32,2,0,0,51,2,0,0,0,39
1,1,1,1,1,1,1,1,0,0,0,32,2,0,0,0,0,43,43,2,32,32,2,0,0,0,41,0,0,0,39
1,1,1,1,1,1,32,32,2,2,50,2,2,0,0,54,0,53,53,2,32,32,2,53,52,0,2,0,0,0,39
1,1,1,1,1,1,1,1,2,0,0,51,2,0,44,44,0,55,55,2,32,32,2,2,2,2,2,0,0,0,39
1,1,1,1,1,1,1,1,2,0,0,44,2,2,2,2,2,2,2,11,32,32,39,0,0,0,0,0,43,0,39
1,1,1,1,1,1,11,1,2,0,0,44,2,32,32,34,32,0,32,32,0,1,39,0,0,0,0,45,53,52,39
1,1,1,1,1,1,1,1,2,2,56,2,2,0,1,1,0,0,0,1,1,1,39,0,0,0,0,0,55,0,39
1,1,1,1,1,1,1,1,39,0,0,0,39,1,1,1,0,11,0,1,1,1,39,39,39,39,39,39,39,39,57
1,1,1,1,1,1,1,1,39,0,0,0,39,1,1,1,0,0,0,1,1,1,1,1,1,1,1,1,1,1,1
1,1,1,1,1,1,1,1,39,39,39,39,39,1,1,1,1,1,1,1,1,1,1,1,1,1,1,1,1,1,1
1,1,1,1,1,1,1,1,1,1,1,1,1,1,1,1,1,1,1,1,1,1,1,1,1,1,1,1,1,1,1
endlayer

layer
1,1,1,1,1,1,1,1,1,1,1,1,1,1,1,1,1,1,1,1,1,1,1,1,1,1,1,1,1,1,1
1,1,1,1,1,1,1,1,1,1,1,1,1,1,1,1,1,1,38,1,1,1,1,1,1,1,1,1,1,1,1
1,1,1,1,1,1,1,1,1,1,1,1,1,1,1,1,1,38,38,38,1,1,1,1,1,1,1,1,1,1,1
1,1,1,1,1,1,1,1,1,1,1,1,1,1,1,1,0,0,38,0,0,0,0,1,1,1,1,1,1,1,1
1,1,1,1,1,1,1,1,1,1,1,1,1,1,1,1,0,2,2,58,2,2,0,1,1,1,1,1,1,1,1
1,1,1,1,1,1,1,1,1,1,1,2,2,58,2,0,0,2,40,0,0,2,0,1,1,1,1,1,1,1,1
1,1,1,1,1,1,1,11,0,0,0,58,0,0,2,0,0,60,0,0,0,59,0,1,1,1,1,1,1,1,1
1,1,1,1,1,1,1,0,0,0,0,2,0,0,0,0,0,2,2,2,2,2,0,1,1,1,1,1,1,1,1
1,1,1,1,1,1,2,2,58,2,0,2,0,2,2,0,0,2,0,0,0,2,2,58,58,2,2,1,1,1,1
1,1,1,1,1,1,58,0,0,2,1,1,1,1,0,0,0,0,0,0,0,2,0,0,0,0,2,1,1,1,1
1,1,1,0,0,0,2,0,0,0,0,1,1,1,0,0,0,11,2,2,2,11,61,0,0,0,58,1,1,1,1
1,1,1,0,2,2,2,2,2,2,0,1,1,1,1,1,1,1,3,12,0,59,0,0,0,0,2,1,1,1,1
1,1,1,0,2,0,0,0,0,2,0,1,0,0,0,0,0,0,0,1,1,2,2,58,58,2,2,1,1,1,1
1,1,1,0,59,0,0,0,0,59,0,0,0,1,1,1,1,0,0,0,1,1,1,1,1,1,1,1,1,1,1
1,1,1,0,2,14,47,0,0,2,0,0,0,1,0,0,0,1,1,1,1,1,1,1,1,1,1,1,1,1,1
1,1,1,0,2,2,2,2,2,2,0,0,0,1,0,0,0,1,1,1,1,1,1,1,1,1,1,1,1,1,1
1,1,1,0,0,2,0,0,2,0,0,0,0,1,0,0,0,1,1,1,0,0,0,1,1,1,1,1,1,1,1
1,38,38,38,1,58,0,0,59,1,0,0,0,1,1,1,1,1,1,1,0,11,0,1,1,1,1,1,1,1,1
1,38,38,38,1,2,0,0,2,1,0,0,0,1,1,1,1,1,1,1,0,0,0,1,1,1,1,1,1,1,1
1,38,38,38,1,2,58,58,2,0,0,0,2,2,60,2,2,0,0,0,0,1,2,2,60,2,2,1,1,1,1
1,1,1,1,1,0,0,0,0,0,1,1,2,0,0,0,2,58,2,11,0,1,2,0,0,51,2,1,1,1,1
1,1,1,1,1,1,1,1,0,0,0,0,58,0,0,0,0,0,0,2,0,1,58,0,0,0,60,1,1,1,1
1,1,1,1,1,1,1,1,2,2,60,2,6,0,0,0,0,62,62,58,0,1,2,62,0,0,2,1,1,1,1
1,1,1,1,1,1,1,1,2,0,0,51,2,0,25,54,0,0,0,2,0,1,2,2,58,2,2,1,1,1,1
1,1,1,1,1,1,1,1,58,0,0,25,2,2,58,2,2,58,2,11,0,1,1,1,1,1,1,1,1,1,1
1,1,1,1,1,1,11,1,2,0,0,0,2,0,0,0,0,0,0,0,0,1,1,1,1,1,1,1,62,1,1
1,1,1,1,1,1,1,1,2,2,60,2,2,0,1,1,38,38,38,1,1,1,1,1,1,1,1,1,1,1,1
1,1,1,1,1,1,1,1,1,1,1,1,1,1,1,1,38,11,38,1,1,1,1,1,1,1,1,1,1,1,25
1,1,1,1,1,1,1,1,1,1,1,1,1,1,1,1,38,38,38,1,1,1,1,1,1,1,1,1,1,1,1
1,1,1,1,1,1,1,1,1,1,1,1,1,1,1,1,1,1,1,1,1,1,1,1,1,1,1,1,1,1,1
1,1,1,1,1,1,1,1,1,1,1,1,1,1,1,1,1,1,1,1,1,1,1,1,1,1,1,1,1,1,1
endlayer

layer
1,1,1,1,1,1,1,1,1,1,1,1,1,1,1,1,1,1,1,1,1,1,1,1,1,1,1,1,1,1,1
1,1,1,1,1,1,1,1,1,1,1,1,1,1,1,1,1,1,1,1,1,1,1,1,1,1,1,1,1,1,1
1,1,1,1,1,1,1,1,1,1,1,1,1,1,1,1,1,1,1,1,1,1,1,1,1,1,1,1,1,1,1
1,1,1,1,1,1,1,1,1,1,1,1,1,1,1,1,0,0,0,0,0,0,0,1,1,1,1,1,1,1,1
1,1,1,1,1,1,1,1,1,1,1,1,1,1,1,1,0,2,2,2,2,2,0,1,1,1,1,1,1,1,1
1,1,1,1,1,1,30,30,30,30,30,2,2,2,2,30,30,2,40,36,36,2,0,1,1,1,1,1,1,1,1
1,1,1,1,1,1,9,35,36,36,36,35,36,36,35,36,36,2,36,36,36,2,0,1,1,1,1,1,1,1,1
1,1,1,1,1,1,9,36,36,36,36,35,36,36,35,36,36,2,2,2,2,2,0,1,1,1,1,1,1,1,1
1,1,1,1,1,1,2,35,35,2,28,2,2,2,2,36,36,35,36,36,36,2,2,2,2,2,2,1,1,1,1
1,1,1,1,1,1,2,36,36,2,1,1,1,1,9,36,36,35,36,36,36,2,36,36,36,36,2,1,1,1,1
1,1,1,0,0,0,2,36,36,2,0,1,1,1,28,28,28,11,2,2,2,11,36,36,36,36,2,1,1,1,1
1,1,1,0,2,2,2,2,2,2,0,1,1,1,1,1,1,1,1,3,35,2,36,36,36,36,2,1,1,1,1
1,1,1,0,2,36,36,36,36,2,0,1,1,1,1,1,1,1,1,1,1,2,2,2,2,2,2,1,1,1,1
1,1,1,0,2,36,36,36,36,2,0,1,1,1,1,1,1,1,1,1,1,1,1,1,1,1,1,1,1,1,1
1,1,1,0,2,47,0,0,0,2,0,1,1,1,1,1,1,1,1,1,1,1,1,1,1,1,1,1,1,1,1
1,1,1,0,2,2,2,2,2,2,0,1,1,1,1,0,1,1,1,1,1,1,1,1,1,1,1,1,1,1,1
1,1,1,0,0,2,36,36,2,0,0,1,1,1,1,1,1,1,1,1,38,38,38,1,1,1,1,1,1,1,1
1,1,38,1,1,2,36,36,2,1,1,1,1,1,1,1,1,1,1,1,38,11,38,1,1,1,1,1,1,1,1
1,38,38,38,1,2,36,36,2,1,1,1,1,1,1,1,1,1,1,1,38,38,38,1,1,1,1,1,1,1,1
1,1,38,1,1,2,35,35,2,1,1,0,2,2,2,2,2,63,63,63,63,1,2,2,2,2,2,1,1,1,1
1,1,1,1,1,9,36,36,0,1,1,1,2,36,36,0,2,2,2,11,63,1,2,36,36,51,2,1,1,1,1
1,1,1,1,1,9,36,36,0,0,0,0,2,36,36,0,36,36,36,2,63,1,2,36,36,36,2,1,1,1,1
1,1,1,1,1,9,36,36,2,2,2,2,2,36,36,0,36,36,36,2,63,1,2,36,36,36,2,1,1,1,1
1,1,1,1,1,9,36,36,2,36,36,51,2,64,47,0,3,36,36,2,63,1,2,2,2,2,2,1,1,1,1
1,1,1,1,1,9,36,36,2,36,36,36,2,2,2,2,2,2,2,11,63,1,1,1,1,1,1,1,1,1,1
1,1,1,1,1,9,35,36,2,36,36,36,2,63,63,63,63,63,63,63,63,1,1,1,1,1,1,1,1,1,1
1,1,1,1,1,9,28,28,2,2,2,2,2,0,1,1,38,38,38,1,1,1,1,1,1,1,1,1,1,1,1
1,1,1,1,1,1,1,1,1,1,1,1,1,1,1,1,38,38,38,1,1,1,1,1,1,1,1,1,1,1,1
1,1,1,1,1,1,1,1,1,1,1,1,1,1,1,1,38,38,38,1,1,1,1,1,1,1,1,1,1,1,1
1,1,1,1,1,1,1,1,1,1,1,1,1,1,1,1,1,1,1,1,1,1,1,1,1,1,1,1,1,1,1
1,1,1,1,1,1,1,1,1,1,1,1,1,1,1,1,1,1,1,1,1,1,1,1,1,1,1,1,1,1,1
endlayer

layer
1,1,1,1,1,1,1,1,1,1,1,1,1,1,1,1,1,1,1,1,1,1,1,1,1,1,1,1,1,1,1
1,1,1,1,1,1,1,1,1,1,1,1,1,1,1,1,1,1,1,1,1,1,1,1,1,1,1,1,1,1,1
1,1,1,1,1,1,1,1,1,1,1,1,1,1,1,1,1,1,1,1,1,1,1,1,1,1,1,1,1,1,1
1,1,1,1,1,1,1,1,1,1,1,1,1,1,1,1,0,0,0,0,0,0,0,1,1,1,1,1,1,1,1
1,1,1,1,1,1,1,1,1,1,1,1,1,1,1,1,0,2,2,2,2,2,0,1,1,1,1,1,1,1,1
1,1,1,1,1,1,57,39,39,39,39,39,39,39,39,39,39,2,40,0,65,2,0,1,1,1,1,1,1,1,1
1,1,1,1,1,1,39,0,0,0,0,0,0,0,0,0,0,42,0,0,66,2,0,1,1,1,1,1,1,1,1
1,1,1,1,1,1,39,0,0,0,0,0,0,0,0,0,0,2,2,2,2,2,0,1,1,1,1,1,1,1,1
1,1,1,1,1,1,39,0,0,39,39,39,39,39,39,0,0,0,0,0,0,2,2,2,2,2,2,1,1,1,1
1,1,1,1,1,1,39,0,0,39,1,1,1,1,39,0,0,0,0,0,0,42,0,0,0,43,2,1,1,1,1
1,1,1,0,0,0,39,0,0,39,0,1,1,1,39,39,39,11,39,39,0,2,44,0,0,53,2,1,1,1,1
1,1,1,0,2,2,2,2,2,2,0,1,1,1,1,1,1,1,1,1,1,2,44,0,0,55,2,1,1,1,1
1,1,1,0,2,44,44,68,67,2,0,1,1,1,1,1,1,1,1,1,1,2,2,2,2,2,2,1,1,1,1
1,1,1,0,2,0,0,0,53,2,0,1,1,1,1,1,1,1,1,1,1,1,1,1,1,1,1,1,1,1,1
1,1,1,0,2,0,0,0,0,2,0,1,1,1,1,1,1,1,1,1,1,1,1,1,1,1,1,1,1,1,1
1,1,1,0,2,2,2,2,2,2,0,1,1,1,1,0,1,1,1,1,1,1,1,1,1,1,1,1,1,1,1
1,1,1,0,0,39,0,0,39,0,0,1,1,1,1,1,1,1,1,1,38,38,38,1,1,1,1,1,1,1,1
1,1,1,1,1,39,0,0,39,1,1,1,1,1,1,1,1,1,1,1,38,38,38,1,1,1,1,1,1,1,1
1,1,1,1,1,39,0,0,39,1,1,1,1,1,1,1,1,1,1,1,38,38,38,1,1,1,1,1,1,1,1
1,1,1,1,1,39,0,0,39,1,1,0,2,2,2,2,2,0,0,0,0,1,2,2,2,2,2,1,1,1,1
1,1,1,1,1,39,0,0,39,1,1,1,2,69,53,0,2,2,2,11,0,1,2,0,0,51,2,1,1,1,1
1,1,1,1,1,39,0,0,39,0,0,0,2,70,0,0,0,53,69,2,0,1,2,0,0,0,2,1,1,1,1
1,1,1,1,1,39,0,0,2,2,2,2,2,0,0,0,0,0,70,2,0,1,2,49,48,0,2,1,1,1,1
1,1,1,1,1,39,0,0,2,0,0,51,2,0,0,0,0,0,0,2,0,1,2,2,2,2,2,1,1,1,1
1,1,1,1,1,39,0,0,42,0,0,0,2,2,2,2,2,2,2,11,0,1,1,1,1,1,1,1,1,1,1
1,1,1,1,1,39,0,0,2,45,53,52,2,0,0,0,0,0,0,0,0,1,1,1,1,1,1,1,1,1,1
1,1,1,1,1,57,39,39,2,2,2,2,2,0,1,1,1,38,1,1,1,1,1,1,1,1,1,1,1,1,1
1,1,1,1,1,1,1,1,1,1,1,1,1,1,1,1,38,38,38,1,1,1,1,1,1,1,1,1,1,1,1
1,1,1,1,1,1,1,1,1,1,1,1,1,1,1,1,1,38,1,1,1,1,1,1,1,1,1,1,1,1,1
1,1,1,1,1,1,1,1,1,1,1,1,1,1,1,1,1,1,1,1,1,1,1,1,1,1,1,1,1,1,1
1,1,1,1,1,1,1,1,1,1,1,1,1,1,1,1,1,1,1,1,1,1,1,1,1,1,1,1,1,1,1
endlayer

layer
1,1,1,1,1,1,1,1,1,1,1,1,1,1,1,1,1,1,1,1,1,1,1,1,1,1,1,1,1,1,1
1,1,1,1,1,1,1,1,1,1,1,1,1,1,1,1,1,1,1,1,1,1,1,1,1,1,1,1,1,1,1
1,1,1,1,1,1,1,1,1,1,1,1,1,1,1,1,1,1,1,1,1,1,1,1,1,1,1,1,1,1,1
1,1,1,1,1,1,1,1,1,1,1,1,1,1,1,1,0,0,0,0,0,0,0,1,1,1,1,1,1,1,1
1,1,1,1,1,1,1,1,1,1,1,1,1,1,1,1,0,2,2,58,2,2,0,1,1,1,1,1,1,1,1
1,1,1,1,1,1,25,1,1,1,1,1,1,1,1,1,0,2,40,0,0,58,0,1,1,1,1,1,1,1,1
1,1,1,1,1,1,1,1,1,1,1,1,1,1,1,1,0,59,0,0,0,58,0,1,1,1,1,1,1,1,1
1,1,1,1,1,1,1,1,1,1,1,1,1,1,1,1,0,2,2,58,2,2,0,1,1,1,1,1,1,1,1
1,1,1,1,1,1,1,1,1,1,1,1,1,1,1,1,0,0,0,0,0,2,2,58,58,2,2,1,1,1,1
1,1,1,1,1,1,1,1,1,1,1,1,1,1,1,1,1,0,0,0,0,60,0,0,0,0,2,1,1,1,1
1,1,1,0,0,0,0,0,0,0,0,1,1,1,1,1,1,11,0,0,0,2,0,0,0,62,58,1,1,1,1
1,1,1,0,2,2,58,58,2,2,0,1,1,1,1,1,1,1,1,1,1,58,0,0,0,0,2,1,1,1,1
1,1,1,0,2,0,0,0,0,2,0,1,1,1,1,1,1,1,1,1,1,2,2,58,58,2,2,1,1,1,1
1,1,1,0,58,0,0,0,62,58,0,1,1,1,1,1,1,1,1,1,1,1,1,1,1,1,1,1,1,1,1
1,1,1,0,2,0,0,0,0,2,0,1,1,1,1,1,1,1,1,1,1,1,1,1,1,1,1,1,1,1,1
1,1,1,0,2,2,58,58,2,2,0,1,1,1,1,0,1,1,1,1,1,1,1,1,1,1,1,1,1,1,1
1,1,1,0,0,0,0,0,0,0,0,1,1,1,1,1,1,1,1,1,1,38,1,1,1,1,1,1,1,1,1
1,1,1,1,1,1,1,1,1,1,1,1,1,1,1,1,1,1,1,1,38,38,38,1,1,1,1,1,1,1,1
1,1,1,1,1,1,1,1,1,1,1,1,1,1,1,1,1,1,1,1,1,38,1,1,1,1,1,1,1,1,1
1,1,1,1,1,1,1,1,1,1,1,0,2,2,58,2,2,0,0,0,0,1,2,2,58,2,2,1,1,1,1
1,1,1,1,1,1,1,1,1,1,1,1,2,0,62,0,2,58,2,11,0,1,2,0,0,51,2,1,1,1,1
1,1,1,1,1,1,1,0,0,0,0,0,58,0,0,0,0,62,0,2,0,1,58,0,0,0,58,1,1,1,1
1,1,1,1,1,1,1,0,2,2,58,2,2,0,0,0,0,0,0,58,0,1,2,0,0,0,2,1,1,1,1
1,1,1,1,1,1,1,0,2,0,0,51,2,0,0,0,0,0,0,2,0,1,2,2,58,2,2,1,1,1,1
1,1,1,1,1,1,1,0,59,0,0,0,2,2,58,2,2,58,2,11,0,1,1,1,1,1,1,1,1,1,1
1,1,1,1,1,1,1,0,2,0,62,0,2,0,0,0,0,0,0,0,0,1,1,1,1,1,1,1,1,1,1
1,1,1,1,1,25,1,0,2,2,58,2,2,0,1,1,1,1,1,1,1,1,1,1,1,1,1,1,1,1,1
1,1,1,1,1,1,1,1,1,1,1,1,1,1,1,1,1,1,1,1,1,1,1,1,1,1,1,1,1,1,1
1,1,1,1,1,1,1,1,1,1,1,1,1,1,1,1,1,1,1,1,1,1,1,1,1,1,1,1,1,1,1
1,1,1,1,1,1,1,1,1,1,1,1,1,1,1,1,1,1,1,1,1,1,1,1,1,1,1,1,1,1,1
1,1,1,1,1,1,1,1,1,1,1,1,1,1,1,1,1,1,1,1,1,1,1,1,1,1,1,1,1,1,1
endlayer

layer
1,1,1,1,1,1,1,1,1,1,1,1,1,1,1,1,1,1,1,1,1,1,1,1,1,1,1,1,1,1,1
1,1,1,1,1,1,1,1,1,1,1,1,1,1,1,1,1,30,30,30,30,10,1,1,1,1,1,1,1,1,1
1,1,1,1,1,1,1,1,1,1,1,1,1,1,1,1,1,9,36,36,36,10,1,1,1,1,1,1,1,1,1
1,1,1,1,1,1,1,1,1,1,1,1,1,1,1,1,0,9,36,36,36,10,0,1,1,1,1,1,1,1,1
1,1,1,1,1,1,1,1,1,1,1,1,1,1,1,1,0,2,2,2,2,2,0,1,1,1,1,1,1,1,1
1,1,1,1,1,1,1,1,1,1,1,1,1,1,1,1,0,2,40,36,36,2,0,1,1,1,1,1,1,1,1
1,1,1,1,1,1,1,1,1,1,1,1,1,1,1,1,0,2,36,36,36,2,0,1,1,1,1,1,1,1,1
1,1,1,1,1,1,1,1,1,1,1,1,1,1,1,1,0,2,2,2,2,2,0,1,1,1,1,1,1,1,1
1,1,1,1,1,1,1,1,1,1,1,1,1,1,1,1,0,9,36,36,36,2,2,2,2,2,2,1,1,1,1
1,1,1,1,1,1,1,1,1,1,1,1,1,1,1,1,1,9,36,36,36,64,36,36,36,36,2,1,1,1,1
1,1,1,54,54,54,54,54,54,54,47,1,1,1,1,1,1,11,28,28,28,2,36,36,36,36,2,1,1,1,1
1,1,1,3,2,2,2,2,2,2,47,1,1,1,1,1,1,1,1,1,1,2,36,36,36,36,2,1,1,1,1
1,1,1,3,2,36,36,36,36,2,47,1,1,1,1,1,1,1,1,1,1,2,2,2,2,2,2,1,1,1,1
1,1,1,3,2,36,36,36,36,2,47,1,1,1,1,1,1,1,1,1,1,1,1,1,1,1,1,1,1,1,1
1,1,1,3,2,36,36,36,36,2,47,1,1,1,1,1,1,1,1,1,1,1,1,1,1,1,1,1,1,1,1
1,1,1,3,2,2,2,2,2,2,47,1,1,1,1,0,1,1,1,1,1,1,1,1,1,1,1,1,1,1,1
1,1,1,37,37,37,37,37,37,37,37,1,1,1,1,1,1,1,1,1,1,1,1,1,1,1,1,1,1,1,1
1,1,1,1,1,1,1,1,1,1,1,1,1,1,1,1,1,1,1,1,1,1,1,1,1,1,1,1,1,1,1
1,1,1,1,1,1,1,1,1,1,1,3,12,1,1,1,14,47,1,1,1,1,1,1,1,1,1,1,1,1,1
1,1,1,1,1,1,1,1,1,1,1,3,2,2,2,2,2,47,63,63,63,1,2,2,2,2,2,1,1,1,1
1,1,1,1,1,1,1,1,1,1,1,1,2,36,36,36,2,2,2,11,63,1,2,36,36,51,2,1,1,1,1
1,1,1,1,1,1,1,0,0,0,0,0,2,36,36,36,36,36,36,2,63,1,2,36,36,36,2,1,1,1,1
1,1,1,1,1,1,1,0,2,2,2,2,2,36,36,36,36,36,36,2,63,1,2,36,36,36,2,1,1,1,1
1,1,1,1,1,1,1,0,2,36,36,51,2,36,36,36,36,36,36,2,63,1,2,2,2,2,2,1,1,1,1
1,1,1,1,1,1,1,0,2,36,36,36,2,2,2,2,2,2,2,11,63,1,1,1,1,1,1,1,1,1,1
1,1,1,1,1,1,1,0,2,36,36,36,2,63,63,63,63,63,63,63,63,1,1,1,1,1,1,1,1,1,1
1,1,1,1,1,1,1,0,2,2,2,2,2,0,1,1,1,1,1,1,1,1,1,1,1,1,1,1,1,1,1
1,1,1,1,1,1,1,1,1,1,1,1,1,1,1,1,1,1,1,1,1,1,1,1,1,1,1,1,1,1,1
1,1,1,1,1,1,1,1,1,1,1,1,1,1,1,1,1,1,1,1,1,1,1,1,1,1,1,1,1,1,1
1,1,1,1,1,1,1,1,1,1,1,1,1,1,1,1,1,1,1,1,1,1,1,1,1,1,1,1,1,1,1
1,1,1,1,1,1,1,1,1,1,1,1,1,1,1,1,1,1,1,1,1,1,1,1,1,1,1,1,1,1,1
endlayer

layer
1,1,1,1,1,1,1,1,1,1,1,1,1,1,1,1,1,1,1,1,1,1,1,1,1,1,1,1,1,1,1
1,1,1,1,1,1,1,1,1,1,1,1,1,1,1,1,1,39,39,39,39,39,1,1,1,1,1,1,1,1,1
1,1,1,1,1,1,1,1,1,1,1,1,1,1,1,1,1,39,45,0,0,39,1,1,1,1,1,1,1,1,1
1,1,1,1,1,1,1,1,1,1,1,1,1,1,1,1,0,39,0,0,0,39,0,1,1,1,1,1,1,1,1
1,1,1,1,1,1,1,1,1,1,1,1,1,1,1,1,0,2,2,50,2,2,0,1,1,1,1,1,1,1,1
1,1,1,1,1,1,1,1,1,1,1,1,1,1,1,1,0,2,40,0,0,2,0,1,1,1,1,1,1,1,1
1,1,1,1,1,1,1,1,1,1,1,1,1,1,1,1,0,2,0,0,0,2,0,1,1,1,1,1,1,1,1
1,1,1,1,1,1,1,1,1,1,1,1,1,1,1,1,0,2,2,56,2,2,0,1,1,1,1,1,1,1,1
1,1,1,1,1,1,1,1,1,1,1,1,1,1,1,1,0,39,0,0,0,39,39,39,39,39,39,1,1,1,1
1,1,1,1,1,1,1,1,1,1,1,1,1,1,1,1,1,39,0,0,0,0,0,43,43,0,39,1,1,1,1
1,1,1,1,1,1,1,1,1,1,1,1,1,1,1,1,1,11,39,39,39,39,0,0,0,53,39,1,1,1,1
1,1,1,1,3,54,54,54,54,54,1,1,1,1,1,1,1,1,1,1,1,39,0,0,0,0,39,1,1,1,1
1,1,1,1,3,35,35,35,35,47,1,1,1,1,1,1,1,1,1,1,1,39,39,39,39,39,39,1,1,1,1
1,1,1,1,3,35,35,35,35,47,1,1,1,1,1,1,1,1,1,1,1,1,1,1,1,1,1,1,1,1,1
1,1,1,1,3,35,35,35,35,47,1,1,1,1,1,1,1,1,1,1,1,1,1,1,1,1,1,1,1,1,1
1,1,1,1,3,37,37,37,37,37,1,1,1,1,1,0,1,1,1,1,1,1,1,1,1,1,1,1,1,1,1
1,1,1,1,1,1,1,1,1,1,1,1,1,1,1,1,1,1,1,1,1,1,1,1,1,1,1,1,1,1,1
1,1,1,1,1,1,1,1,1,1,1,1,1,1,1,1,1,1,1,1,1,1,1,1,1,1,1,1,1,1,1
1,1,1,1,1,1,1,1,1,1,1,1,3,12,1,14,47,1,1,1,1,1,1,1,1,1,1,1,1,1,1
1,1,1,1,1,1,1,1,1,1,1,1,3,35,63,35,47,1,1,1,1,1,2,2,2,2,2,1,1,1,1
1,1,1,1,1,1,1,1,1,1,1,1,39,0,0,0,39,39,39,11,1,1,2,0,0,51,2,1,1,1,1
1,1,1,1,1,1,1,0,0,0,0,0,39,0,0,0,0,0,0,39,1,1,2,65,0,0,2,1,1,1,1
1,1,1,1,1,1,1,0,2,2,2,2,2,0,0,0,0,0,0,39,1,1,2,66,0,0,2,1,1,1,1
1,1,1,1,1,1,1,0,2,0,0,0,2,0,0,0,0,0,0,39,1,1,2,2,2,2,2,1,1,1,1
1,1,1,1,1,1,1,0,2,53,0,0,2,39,39,39,39,39,39,11,1,1,1,1,1,1,1,1,1,1,1
1,1,1,1,1,1,1,0,2,49,48,0,2,0,1,1,1,1,1,1,1,1,1,1,1,1,1,1,1,1,1
1,1,1,1,1,1,1,0,2,2,2,2,2,0,1,1,1,1,1,1,1,1,1,1,1,1,1,1,1,1,1
1,1,1,1,1,1,1,1,1,1,1,1,1,1,1,1,1,1,1,1,1,1,1,1,1,1,1,1,1,1,1
1,1,1,1,1,1,1,1,1,1,1,1,1,1,1,1,1,1,1,1,1,1,1,1,1,1,1,1,1,1,1
1,1,1,1,1,1,1,1,1,1,1,1,1,1,1,1,1,1,1,1,1,1,1,1,1,1,1,1,1,1,1
1,1,1,1,1,1,1,1,1,1,1,1,1,1,1,1,1,1,1,1,1,1,1,1,1,1,1,1,1,1,1
endlayer

layer
1,1,1,1,1,1,1,1,1,1,1,1,1,1,1,1,1,1,1,1,1,1,1,1,1,1,1,1,1,1,1
1,1,1,1,1,1,1,1,1,1,1,1,1,1,1,1,1,1,1,1,1,1,1,1,1,1,1,1,1,1,1
1,1,1,1,1,1,1,1,1,1,1,1,1,1,1,1,1,1,1,1,1,1,1,1,1,1,1,1,1,1,1
1,1,1,1,1,1,1,1,1,1,1,1,1,1,1,1,0,0,0,0,0,0,0,1,1,1,1,1,1,1,1
1,1,1,1,1,1,1,1,1,1,1,1,1,1,1,1,0,2,2,59,2,2,0,1,1,1,1,1,1,1,1
1,1,1,1,1,1,1,1,1,1,1,1,1,1,1,1,0,58,0,0,0,0,0,1,1,1,1,1,1,1,1
1,1,1,1,1,1,1,1,1,1,1,1,1,1,1,1,0,58,0,0,0,0,0,1,1,1,1,1,1,1,1
1,1,1,1,1,1,1,1,1,1,1,1,1,1,1,1,0,2,2,60,2,2,0,1,1,1,1,1,1,1,1
1,1,1,1,1,1,1,1,1,1,1,1,1,1,1,1,0,0,0,0,0,0,0,1,1,1,1,1,1,1,1
1,1,1,1,1,1,1,1,1,1,1,1,1,1,1,1,1,1,1,1,1,1,1,1,1,1,1,1,1,1,1
1,1,1,1,1,1,1,1,1,1,1,1,1,1,1,1,1,1,1,1,1,1,1,1,1,62,1,1,1,1,1
1,1,1,1,1,1,1,1,1,1,1,1,1,1,1,1,1,1,1,1,1,1,1,1,1,1,1,1,1,1,1
1,1,1,1,1,1,1,1,1,1,1,1,1,1,1,1,1,1,1,1,1,1,1,1,1,1,1,1,1,1,1
1,1,1,1,1,1,1,1,1,1,1,1,1,1,1,1,1,1,1,1,1,1,1,1,1,1,1,1,1,1,1
1,1,1,1,1,1,1,1,1,1,1,1,1,1,1,1,1,1,1,1,1,1,1,1,1,1,1,1,1,1,1
1,1,1,1,1,1,1,1,1,1,1,1,1,1,1,0,1,1,1,1,1,1,1,1,1,1,1,1,1,1,1
1,1,1,1,1,1,1,1,1,1,1,1,1,1,1,1,1,1,1,1,1,1,1,1,1,1,1,1,1,1,1
1,1,1,1,1,1,1,1,1,1,1,1,1,1,1,1,1,1,1,1,1,1,1,1,1,1,1,1,1,1,1
1,1,1,1,1,1,1,1,1,1,1,1,1,3,35,47,1,1,1,1,1,1,1,1,1,1,1,1,1,1,1
1,1,1,1,1,1,1,1,1,1,1,1,1,3,35,47,1,1,1,1,1,1,2,2,58,2,2,1,1,1,1
1,1,1,1,1,1,1,1,1,1,1,1,1,1,1,1,1,1,1,1,1,1,2,0,0,51,2,1,1,1,1
1,1,1,1,1,1,1,0,0,0,0,0,0,0,1,1,1,1,1,1,1,1,58,0,0,0,58,1,1,1,1
1,1,1,1,1,1,1,0,2,2,58,2,2,0,1,1,1,1,1,1,1,1,2,0,0,0,2,1,1,1,1
1,1,1,1,1,1,1,0,2,0,0,0,2,0,1,1,1,1,1,1,1,1,2,2,58,2,2,1,1,1,1
1,1,1,1,1,1,1,0,58,62,0,0,58,0,1,1,1,1,1,1,1,1,1,1,1,1,1,1,1,1,1
1,1,1,1,1,1,1,0,2,0,0,0,2,0,1,1,1,1,1,1,1,1,1,1,1,1,1,1,1,1,1
1,1,1,1,1,1,1,0,2,2,58,2,2,0,1,1,1,1,1,1,1,1,1,1,1,1,1,1,1,1,1
1,1,1,1,1,1,1,1,1,1,1,1,1,1,1,1,1,1,1,1,1,1,1,1,1,1,1,1,1,1,1
1,1,1,1,1,1,1,1,1,1,1,1,1,1,1,1,1,1,1,1,1,1,1,1,1,1,1,1,1,1,1
1,1,1,1,1,1,1,1,1,1,1,1,1,1,1,1,1,1,1,1,1,1,1,1,1,1,1,1,1,1,1
1,1,1,1,1,1,1,1,1,1,1,1,1,1,1,1,1,1,1,1,1,1,1,1,1,1,1,1,1,1,1
endlayer

layer
1,1,1,1,1,1,1,1,1,1,1,1,1,1,1,1,1,1,1,1,1,1,1,1,1,1,1,1,1,1,1
1,1,1,1,1,1,1,1,1,1,1,1,1,1,1,1,1,1,1,1,1,1,1,1,1,1,1,1,1,1,1
1,1,1,1,1,1,1,1,1,1,1,1,1,1,1,1,1,1,1,1,1,1,1,1,1,1,1,1,1,1,1
1,1,1,1,1,1,1,1,1,1,1,1,1,1,1,1,54,54,54,54,54,54,47,1,1,1,1,1,1,1,1
1,1,1,1,1,1,1,1,1,1,1,1,1,1,1,1,3,2,2,2,2,2,47,1,1,1,1,1,1,1,1
1,1,1,1,1,1,1,1,1,1,1,1,1,1,1,1,3,2,36,36,36,2,47,1,1,1,1,1,1,1,1
1,1,1,1,1,1,1,1,1,1,1,1,1,1,1,1,3,2,36,36,36,2,47,1,1,1,1,1,1,1,1
1,1,1,1,1,1,1,1,1,1,1,1,1,1,1,1,3,2,2,2,2,2,47,1,1,1,1,1,1,1,1
1,1,1,1,1,1,1,1,1,1,1,1,1,1,1,1,3,37,37,37,37,37,47,1,1,1,1,1,1,1,1
1,1,1,1,1,1,1,1,1,1,1,1,1,1,1,1,1,1,1,1,1,1,1,1,1,1,1,1,1,1,1
1,1,1,1,1,1,1,1,1,1,1,1,1,1,1,1,1,1,1,1,1,1,1,1,1,1,1,1,1,1,1
1,1,1,1,1,1,1,1,1,1,1,1,1,1,1,1,1,1,1,1,1,1,1,1,1,1,1,1,1,1,1
1,1,1,1,1,1,1,1,1,1,1,1,1,1,1,1,1,1,1,1,1,1,1,1,1,1,1,1,1,1,1
1,1,1,1,1,1,1,1,1,1,1,1,1,1,1,1,1,1,1,1,1,1,1,1,1,1,1,1,1,1,1
1,1,1,1,1,1,1,1,1,1,1,1,1,1,1,1,1,1,1,1,1,1,1,1,1,1,1,1,1,1,1
1,1,1,1,1,1,1,1,1,1,1,1,1,1,1,0,1,1,1,1,1,1,1,1,1,1,1,1,1,1,1
1,1,1,1,1,1,1,1,1,1,1,1,1,1,1,1,1,1,1,1,1,1,1,1,1,1,1,1,1,1,1
1,1,1,1,1,1,1,1,1,1,1,1,1,1,1,1,1,1,1,1,1,1,1,1,1,1,1,1,1,1,1
1,1,1,1,1,1,1,1,1,1,1,1,1,1,63,1,1,1,1,1,1,1,1,1,1,1,1,1,1,1,1
1,1,1,1,1,1,1,1,1,1,1,1,1,1,63,1,1,1,1,1,1,1,2,2,2,2,2,1,1,1,1
1,1,1,1,1,1,1,1,1,1,1,1,1,1,1,1,1,1,1,1,1,1,2,36,36,51,2,1,1,1,1
1,1,1,1,1,1,1,54,54,54,54,54,54,47,1,1,1,1,1,1,1,1,2,36,36,36,2,1,1,1,1
1,1,1,1,1,1,1,3,2,2,2,2,2,47,1,1,1,1,1,1,1,1,2,36,36,36,2,1,1,1,1
1,1,1,1,1,1,1,3,2,36,36,36,2,47,1,1,1,1,1,1,1,1,2,2,2,2,2,1,1,1,1
1,1,1,1,1,1,1,3,2,36,36,36,2,47,1,1,1,1,1,1,1,1,1,1,1,1,1,1,1,1,1
1,1,1,1,1,1,1,3,2,36,36,36,2,47,1,1,1,1,1,1,1,1,1,1,1,1,1,1,1,1,1
1,1,1,1,1,1,1,3,2,2,2,2,2,47,1,1,1,1,1,1,1,1,1,1,1,1,1,1,1,1,1
1,1,1,1,1,1,1,37,37,37,37,37,37,37,1,1,1,1,1,1,1,1,1,1,1,1,1,1,1,1,1
1,1,1,1,1,1,1,1,1,1,1,1,1,1,1,1,1,1,1,1,1,1,1,1,1,1,1,1,1,1,1
1,1,1,1,1,1,1,1,1,1,1,1,1,1,1,1,1,1,1,1,1,1,1,1,1,1,1,1,1,1,1
1,1,1,1,1,1,1,1,1,1,1,1,1,1,1,1,1,1,1,1,1,1,1,1,1,1,1,1,1,1,1
endlayer

layer
1,1,1,1,1,1,1,1,1,1,1,1,1,1,1,1,1,1,1,1,1,1,1,1,1,1,1,1,1,1,1
1,1,1,1,1,1,1,1,1,1,1,1,1,1,1,1,1,1,1,1,1,1,1,1,1,1,1,1,1,1,1
1,1,1,1,1,1,1,1,1,1,1,1,1,1,1,1,1,1,1,1,1,1,1,1,1,1,1,1,1,1,1
1,1,1,1,1,1,1,1,1,1,1,1,1,1,1,1,1,1,1,1,1,1,1,1,1,1,1,1,1,1,1
1,1,1,1,1,1,1,1,1,1,1,1,1,1,1,1,1,54,54,54,54,47,1,1,1,1,1,1,1,1,1
1,1,1,1,1,1,1,1,1,1,1,1,1,1,1,1,1,3,35,35,35,47,1,1,1,1,1,1,1,1,1
1,1,1,1,1,1,1,1,1,1,1,1,1,1,1,1,1,3,35,35,35,47,1,1,1,1,1,1,1,1,1
1,1,1,1,1,1,1,1,1,1,1,1,1,1,1,1,1,37,37,37,37,37,1,1,1,1,1,1,1,1,1
1,1,1,1,1,1,1,1,1,1,1,1,1,1,1,1,1,1,1,1,1,1,1,1,1,1,1,1,1,1,1
1,1,1,1,1,1,1,1,1,1,1,1,1,1,1,1,1,1,1,1,1,1,1,1,1,1,1,1,1,1,1
1,1,1,1,1,1,1,1,1,1,1,1,1,1,1,1,1,1,1,1,1,1,1,1,1,1,1,1,1,1,1
1,1,1,1,1,1,1,1,1,1,1,1,1,1,1,1,1,1,1,1,1,1,1,1,1,1,1,1,1,1,1
1,1,1,1,1,1,1,1,1,1,1,1,1,1,1,1,1,1,1,1,1,1,1,1,1,1,1,1,1,1,1
1,1,1,1,1,1,1,1,1,1,1,1,1,1,1,1,1,1,1,1,1,1,1,1,1,1,1,1,1,1,1
1,1,1,1,1,1,1,1,1,1,1,1,1,1,1,1,1,1,1,1,1,1,1,1,1,1,1,1,1,1,1
1,1,1,1,1,1,1,1,1,1,1,1,1,1,1,0,1,1,1,1,1,1,1,1,1,1,1,1,1,1,1
1,1,1,1,1,1,1,1,1,1,1,1,1,1,1,1,1,1,1,1,1,1,1,1,1,1,1,1,1,1,1
1,1,1,1,1,1,1,1,1,1,1,1,1,1,1,1,1,1,1,1,1,1,1,1,1,1,1,1,1,1,1
1,1,1,1,1,1,1,1,1,1,1,1,1,1,1,1,1,1,1,1,1,1,1,1,1,1,1,1,1,1,1
1,1,1,1,1,1,1,1,1,1,1,1,1,1,1,1,1,1,1,1,1,1,39,39,39,39,39,1,1,1,1
1,1,1,1,1,1,1,1,1,1,1,1,1,1,1,1,1,1,1,1,1,1,39,0,0,0,39,1,1,1,1
1,1,1,1,1,1,1,1,1,1,1,1,1,1,1,1,1,1,1,1,1,1,39,0,0,0,39,1,1,1,1
1,1,1,1,1,1,1,1,3,54,54,54,54,1,1,1,1,1,1,1,1,1,39,0,0,0,39,1,1,1,1
1,1,1,1,1,1,1,1,3,35,35,35,47,1,1,1,1,1,1,1,1,1,39,39,39,39,39,1,1,1,1
1,1,1,1,1,1,1,1,3,35,35,35,47,1,1,1,1,1,1,1,1,1,1,1,1,1,1,1,1,1,1
1,1,1,1,1,1,1,1,3,35,35,35,47,1,1,1,1,1,1,1,1,1,1,1,1,1,1,1,1,1,1
1,1,1,1,1,1,1,1,3,37,37,37,47,1,1,1,1,1,1,1,1,1,1,1,1,1,1,1,1,1,1
1,1,1,1,1,1,1,1,1,1,1,1,1,1,1,1,1,1,1,1,1,1,1,1,1,1,1,1,1,1,1
1,1,1,1,1,1,1,1,1,1,1,1,1,1,1,1,1,1,1,1,1,1,1,1,1,1,1,1,1,1,1
1,1,1,1,1,1,1,1,1,1,1,1,1,1,1,1,1,1,1,1,1,1,1,1,1,1,1,1,1,1,1
1,1,1,1,1,1,1,1,1,1,1,1,1,1,1,1,1,1,1,1,1,1,1,1,1,1,1,1,1,1,1
endlayer

