
# Created by Ruins mod version 16.7 Ingame Parser
# authoring Player: ST753M

# A "swimming" concrete fish

weight=1
embed_into_distance=12
acceptable_target_blocks=water
unacceptable_target_blocks=
dimensions=10,13,11
allowable_overhang=0
max_leveling=0
leveling_buffer=0
preserve_water=0
preserve_lava=1
preserve_plants=1

biomesToSpawnIn=ocean,kelp_forest,coral_reef,kelp forest,coral reef,deep_ocean,deep ocean,coralium_infested_ocean

rule1=0,100,preserveBlock
rule2=0,100,minecraft:concrete-1
rule3=0,100,minecraft:stained_hardened_clay-0
rule4=0,100,IInventory;minecraft:chest;minecraft:fish#3#2#1+minecraft:fish#6#2#3+minecraft:fish#6#2#5+minecraft:fish#2#2#7+minecraft:fish#2#2#10+minecraft:fish#3#2#13+minecraft:fishing_rod#{ench:[{lvl:3s,id:62s},{lvl:3s,id:34s}],RepairCost:3}#0#15+minecraft:fish#4#2#17+minecraft:air#0#2#18+minecraft:fish#1#2#20+minecraft:fish#4#2#22+minecraft:air#0#2#23+minecraft:fish#5#2#25-4
rule5=0,100,minecraft:stained_hardened_clay-15
rule6=0,30,minecraft:glowstone-0
rule7=0,100,air

layer
1,1,1,1,1,1,1,1,1,1,1
1,1,1,1,1,1,1,1,1,1,1
1,1,1,1,1,1,1,1,1,1,1
1,1,1,1,2,2,2,1,1,1,1
1,1,1,1,2,2,2,1,1,1,1
1,1,1,1,1,1,1,1,1,1,1
1,1,1,1,1,2,1,1,1,1,1
1,1,1,1,1,1,1,1,1,1,1
1,1,1,1,1,1,1,1,1,1,1
1,1,1,1,1,1,1,1,1,1,1
1,1,1,1,1,1,1,1,1,1,1
1,1,1,1,1,1,1,1,1,1,1
1,1,1,1,1,1,1,1,1,1,1
endlayer

layer
1,1,1,1,1,1,1,1,1,1,1
1,1,1,1,1,1,1,1,1,1,1
1,1,1,1,2,2,2,1,1,1,1
1,1,1,1,1,3,1,1,1,1,1
1,1,1,1,1,3,1,1,1,1,1
1,1,1,1,1,3,1,1,1,1,1
1,1,1,1,1,2,1,1,1,1,1
1,1,1,1,1,2,1,1,1,1,1
1,1,1,1,1,1,1,1,1,1,1
1,1,1,1,1,1,1,1,1,1,1
1,1,1,1,1,1,1,1,1,1,1
1,1,1,1,1,2,1,1,1,1,1
1,1,1,1,1,2,1,1,1,1,1
endlayer

layer
1,1,1,1,1,2,1,1,1,1,1
1,1,1,1,3,2,3,1,1,1,1
1,1,1,3,2,3,2,3,1,1,1
1,1,1,3,3,3,3,3,1,1,1
1,1,1,3,2,2,2,3,1,1,1
1,1,1,2,3,3,3,2,1,1,1
1,1,1,3,3,3,3,3,1,1,1
1,1,1,1,3,3,3,1,1,1,1
1,1,1,1,1,1,1,1,1,1,1
1,1,1,1,1,1,1,1,1,1,1
1,1,1,1,1,2,1,1,1,1,1
1,1,1,1,2,2,2,1,1,1,1
1,1,1,1,1,3,1,1,1,1,1
endlayer

layer
1,1,1,1,2,1,2,1,1,1,1
1,1,1,2,1,1,1,2,1,1,1
1,1,1,3,1,1,1,3,1,1,1
1,1,1,2,1,1,1,2,1,1,1
1,1,1,3,1,1,1,3,1,1,1
1,1,1,2,1,4,1,2,1,1,1
1,1,1,3,1,1,1,3,1,1,1
1,1,1,1,2,2,2,1,1,1,1
1,1,1,1,1,3,1,1,1,1,1
1,1,1,1,1,2,1,1,1,1,1
1,1,1,1,2,2,2,1,1,1,1
1,1,1,1,1,3,1,1,1,1,1
1,1,1,1,1,1,1,1,1,1,1
endlayer

layer
1,1,1,1,2,1,2,1,1,1,1
1,1,1,5,1,1,1,5,1,1,1
1,1,1,3,1,1,1,3,1,1,1
1,2,2,2,1,1,1,2,2,2,1
2,2,3,3,1,1,1,3,3,2,2
2,3,1,2,1,1,1,2,1,3,2
1,3,1,3,1,1,1,3,1,3,1
1,1,1,2,2,6,2,2,1,1,1
1,1,1,1,1,3,1,1,1,1,1
1,1,1,1,2,2,2,1,1,1,1
1,1,1,1,3,3,3,1,1,1,1
1,1,1,1,1,1,1,1,1,1,1
1,1,1,1,1,1,1,1,1,1,1
endlayer

layer
1,1,1,1,2,2,2,1,1,1,1
1,1,1,3,1,1,1,3,1,1,1
1,1,1,3,1,1,1,3,1,1,1
1,1,1,2,1,1,1,2,1,1,1
1,1,1,3,1,1,1,3,1,1,1
1,1,1,2,1,1,1,2,1,1,1
1,1,1,2,1,1,1,2,1,1,1
1,1,1,3,2,2,2,3,1,1,1
1,1,1,1,1,3,1,1,1,1,1
1,1,1,1,1,2,1,1,1,1,1
1,1,1,1,2,2,2,1,1,1,1
1,1,1,1,1,3,1,1,1,1,1
1,1,1,1,1,1,1,1,1,1,1
endlayer

layer
1,1,1,1,1,1,1,1,1,1,1
1,1,1,1,2,2,2,1,1,1,1
1,1,1,2,2,7,2,2,1,1,1
1,1,1,2,2,7,2,2,1,1,1
1,1,1,3,3,7,3,3,1,1,1
1,1,1,2,3,7,3,2,1,1,1
1,1,1,2,2,2,2,2,1,1,1
1,1,1,1,2,3,2,1,1,1,1
1,1,1,1,1,1,1,1,1,1,1
1,1,1,1,1,1,1,1,1,1,1
1,1,1,1,1,2,1,1,1,1,1
1,1,1,1,2,2,2,1,1,1,1
1,1,1,1,1,3,1,1,1,1,1
endlayer

layer
1,1,1,1,1,1,1,1,1,1,1
1,1,1,1,1,1,1,1,1,1,1
1,1,1,1,2,2,2,1,1,1,1
1,1,1,1,1,3,1,1,1,1,1
1,1,1,1,1,3,1,1,1,1,1
1,1,1,1,1,2,1,1,1,1,1
1,1,1,1,1,1,1,1,1,1,1
1,1,1,1,1,1,1,1,1,1,1
1,1,1,1,1,1,1,1,1,1,1
1,1,1,1,1,1,1,1,1,1,1
1,1,1,1,1,1,1,1,1,1,1
1,1,1,1,1,2,1,1,1,1,1
1,1,1,1,1,2,1,1,1,1,1
endlayer

layer
1,1,1,1,1,1,1,1,1,1,1
1,1,1,1,1,1,1,1,1,1,1
1,1,1,1,1,1,1,1,1,1,1
1,1,1,1,2,3,2,1,1,1,1
1,1,1,1,1,3,1,1,1,1,1
1,1,1,1,1,3,1,1,1,1,1
1,1,1,1,1,2,1,1,1,1,1
1,1,1,1,1,1,1,1,1,1,1
1,1,1,1,1,1,1,1,1,1,1
1,1,1,1,1,1,1,1,1,1,1
1,1,1,1,1,1,1,1,1,1,1
1,1,1,1,1,1,1,1,1,1,1
1,1,1,1,1,1,1,1,1,1,1
endlayer

layer
1,1,1,1,1,1,1,1,1,1,1
1,1,1,1,1,1,1,1,1,1,1
1,1,1,1,1,1,1,1,1,1,1
1,1,1,1,1,1,1,1,1,1,1
1,1,1,1,3,3,3,1,1,1,1
1,1,1,1,2,2,2,1,1,1,1
1,1,1,1,1,3,1,1,1,1,1
1,1,1,1,1,3,1,1,1,1,1
1,1,1,1,1,1,1,1,1,1,1
1,1,1,1,1,1,1,1,1,1,1
1,1,1,1,1,1,1,1,1,1,1
1,1,1,1,1,1,1,1,1,1,1
1,1,1,1,1,1,1,1,1,1,1
endlayer

