
# Created by Ruins mod version 16.5 Ingame Parser
# authoring Player: ST753M

weight=1
uniqueMinDistance=1000
embed_into_distance=2
acceptable_target_blocks=water
unacceptable_target_blocks=
dimensions=17,5,13
allowable_overhang=0
max_leveling=0
leveling_buffer=0
preserve_water=0
preserve_lava=0

biomesToSpawnIn=ocean,coral_reef,kelp_forest,river,coralium_infested_ocean

rule1=0,100,preserveBlock
rule2=0,100,minecraft:planks-1
rule3=0,100,minecraft:log-0
^0,100,minecraft:log-1
^0,100,minecraft:log2-1
rule4=0,100,minecraft:wooden_slab-1
rule5=0,100,minecraft:ladder-3
rule6=0,50,IInventory;minecraft:chest;minecraft:fish#6#1#3+minecraft:dark_oak_boat#1#0#6+minecraft:fish#2#2#21+minecraft:clock#1#0#23+minecraft:fishing_rod#1#0#26-2,IInventory;minecraft:chest;minecraft:fishing_rod#1#0#4+minecraft:fish#4#2#11+minecraft:cooked_fish#2#1#15+minecraft:compass#1#0#20+minecraft:birch_boat#1#0#22-2,IInventory;minecraft:chest;minecraft:acacia_boat#1#0#3+minecraft:fish#4#1#10+minecraft:fish#2#2#20+minecraft:fishing_rod#{ench:[{lvl:3s,id:61s}],RepairCost:1}#0#23-2,IInventory;minecraft:chest;minecraft:fishing_rod#1#0#6+minecraft:fish#3#1#11+minecraft:fish#4#0#12+minecraft:spruce_boat#1#0#22-2,IInventory;minecraft:chest;minecraft:jungle_boat#1#0#12+minecraft:fishing_rod#{ench:[{lvl:1s,id:70s}],RepairCost:1}#0#14+minecraft:fish#4#0#24+minecraft:cooked_fish#3#1#25-2,IInventory;minecraft:chest;minecraft:fishing_rod#1#0#5+minecraft:fish#3#1#7+minecraft:boat#1#0#12+minecraft:cooked_fish#4#0#13+minecraft:fish#2#3#19+minecraft:bucket#2#0#24-2,IInventory;minecraft:chest;minecraft:fishing_rod#{ench:[{lvl:3s,id:62s}],RepairCost:1}#0#4+minecraft:birch_boat#1#0#10+minecraft:fish#3#0#14+minecraft:cooked_fish#4#1#16-2,IInventory;minecraft:chest;minecraft:boat#1#0#3+minecraft:fishing_rod#1#0#9+minecraft:fish#3#0#11+minecraft:fish#4#3#15+minecraft:water_bucket#1#0#22-2
rule7=0,100,minecraft:spruce_stairs-6
rule8=0,100,minecraft:spruce_stairs-2
rule9=0,100,minecraft:spruce_stairs-3
rule10=0,100,minecraft:fence-0
rule11=0,100,minecraft:wool-0
^0,100,minecraft:wool-0
^0,100,minecraft:wool-1
^0,100,minecraft:wool-2
^0,100,minecraft:wool-3
^0,100,minecraft:wool-4
^0,100,minecraft:wool-5
^0,100,minecraft:wool-6
^0,100,minecraft:wool-7
^0,100,minecraft:wool-8
^0,100,minecraft:wool-9
^0,100,minecraft:wool-10
^0,100,minecraft:wool-11
^0,100,minecraft:wool-12
^0,100,minecraft:wool-13
^0,100,minecraft:wool-14
^0,100,minecraft:wool-15
rule12=0,100,CommandBlock:RUINSTRIGGER /summon skeleton ~ ~2 ~ {ArmorItems:[{id:"minecraft:leather_boot",Count:1b,tag:{display:{color:10896452}}},{id:"minecraft:leather_leggings",Count:1b,tag:{display:{color:10896452}}},{id:"minecraft:leather_chestplate",Count:1b,tag:{display:{color:10896452}}},{id:"minecraft:leather_helmet",Count:1b,tag:{display:{color:10896452}}}],HandItems:[{id:"minecraft:bow",Count:1b,tag:{ench:[{id:49,lvl:2}]}},{}],PersistenceRequired:1}:@-1

layer
1,1,1,1,1,1,1,1,1,1,1,1,1
1,1,1,1,1,1,1,1,1,1,1,1,1
1,1,2,2,12,2,2,2,2,1,1,1,1
1,1,1,1,1,1,1,1,1,1,1,1,1
1,1,1,1,1,1,1,1,1,1,1,1,1
endlayer

layer
1,1,1,1,1,1,1,1,1,1,1,1,1
1,2,2,2,2,2,2,2,2,1,1,1,1
2,2,2,2,2,2,3,2,2,2,1,1,1
1,2,2,2,2,2,2,2,2,1,1,1,1
1,1,1,1,1,1,1,1,1,1,1,1,1
endlayer

layer
5,2,2,4,4,4,4,2,2,0,0,0,0
2,6,0,0,0,0,0,0,0,2,2,0,0
2,8,0,0,0,0,3,0,0,0,2,7,0
2,6,0,0,0,0,0,0,0,2,2,0,0
5,2,2,4,4,4,4,2,2,0,0,0,0
endlayer

layer
0,0,0,0,0,0,0,0,0,0,0,0,0
0,0,0,0,0,0,0,0,0,0,0,0,0
10,0,0,0,0,0,3,0,0,0,9,2,2
0,0,0,0,0,0,0,0,0,0,0,0,0
0,0,0,0,0,0,0,0,0,0,0,0,0
endlayer

layer
0,0,0,0,0,0,0,0,0,0,0,0,0
0,0,0,0,0,0,0,0,0,0,0,0,0
10,0,0,0,0,0,3,0,0,0,0,10,0
0,0,0,0,0,0,0,0,0,0,0,0,0
0,0,0,0,0,0,0,0,0,0,0,0,0
endlayer

layer
0,0,0,0,0,0,0,0,0,0,0,0,0
0,0,0,0,0,0,0,0,0,0,0,0,0
11,11,11,0,0,11,3,11,11,11,11,11,0
0,0,0,11,11,0,0,0,0,0,0,0,0
0,0,0,0,0,0,0,0,0,0,0,0,0
endlayer

layer
0,0,0,0,0,0,0,0,0,0,0,0,0
0,0,0,0,0,0,0,0,0,0,0,0,0
11,0,0,0,0,0,3,0,0,0,11,11,0
0,11,11,0,0,11,0,11,11,11,0,0,0
0,0,0,11,11,0,0,0,0,0,0,0,0
endlayer

layer
0,0,0,0,0,0,0,0,0,0,0,0,0
0,0,0,0,0,0,0,0,0,0,0,0,0
0,0,0,0,0,0,3,0,0,0,0,0,0
0,11,0,0,0,0,0,11,0,11,11,0,0
0,0,11,11,11,11,0,0,11,0,0,0,0
endlayer

layer
0,0,0,0,0,0,0,0,0,0,0,0,0
0,0,0,0,0,0,0,0,0,0,0,0,0
0,0,0,0,0,0,3,0,0,0,0,0,0
0,11,0,0,0,0,0,0,0,0,11,0,0
0,0,11,11,11,11,0,11,11,11,0,0,0
endlayer

layer
0,0,0,0,0,0,0,0,0,0,0,0,0
0,0,0,0,0,0,0,0,0,0,0,0,0
0,0,0,0,0,0,3,0,0,0,0,0,0
0,0,11,0,0,0,0,0,0,11,0,0,0
0,0,0,11,11,11,0,11,11,0,0,0,0
endlayer

layer
0,0,0,0,0,0,0,0,0,0,0,0,0
0,0,0,0,0,0,0,0,0,0,0,0,0
0,0,0,0,0,0,3,0,0,0,0,0,0
0,0,11,11,0,0,0,11,11,11,0,0,0
0,0,0,0,11,11,0,0,0,0,0,0,0
endlayer

layer
0,0,0,0,0,0,0,0,0,0,0,0,0
0,0,0,0,0,0,0,0,0,0,0,0,0
0,0,0,0,0,0,3,0,11,0,0,0,0
0,0,0,11,11,11,0,11,0,0,0,0,0
0,0,0,0,0,0,0,0,0,0,0,0,0
endlayer

layer
0,0,0,0,0,0,0,0,0,0,0,0,0
0,0,0,0,0,0,0,0,0,0,0,0,0
0,0,0,11,0,0,3,11,11,0,0,0,0
0,0,0,0,11,11,0,0,0,0,0,0,0
0,0,0,0,0,0,0,0,0,0,0,0,0
endlayer

layer
0,0,0,0,0,0,0,0,0,0,0,0,0
0,0,0,0,0,0,0,0,0,0,0,0,0
0,0,0,0,11,0,3,11,0,0,0,0,0
0,0,0,0,0,11,0,0,0,0,0,0,0
0,0,0,0,0,0,0,0,0,0,0,0,0
endlayer

layer
0,0,0,0,0,0,0,0,0,0,0,0,0
0,0,0,0,0,0,0,0,0,0,0,0,0
0,0,0,0,11,11,3,11,0,0,0,0,0
0,0,0,0,0,0,0,0,0,0,0,0,0
0,0,0,0,0,0,0,0,0,0,0,0,0
endlayer

layer
0,0,0,0,0,0,0,0,0,0,0,0,0
0,0,0,0,0,0,0,0,0,0,0,0,0
0,0,0,0,0,11,3,0,0,0,0,0,0
0,0,0,0,0,0,0,0,0,0,0,0,0
0,0,0,0,0,0,0,0,0,0,0,0,0
endlayer

layer
0,0,0,0,0,0,0,0,0,0,0,0,0
0,0,0,0,0,0,0,0,0,0,0,0,0
0,0,0,0,0,11,3,0,0,0,0,0,0
0,0,0,0,0,0,0,0,0,0,0,0,0
0,0,0,0,0,0,0,0,0,0,0,0,0
endlayer

