
# Created by Ruins mod version 17.0 Ingame Parser
# authoring Player: ST753M

weight=1
embed_into_distance=2
acceptable_target_blocks=
unacceptable_target_blocks=flowing_water,water,flowing_lava,lava,ice,bedrock,netherrack,nether_brick,nether_brick_fence,soul_sand,quartz_ore,end_stone,obsidian,iron_bars,Natura:Cloud,slime_grass,slime_congealed,slime_dirt,clouds,natura:clouds,twilightforest:wispy_cloud,twilightforest:fluffy_cloud
dimensions=18,7,7
allowable_overhang=4
max_leveling=2
leveling_buffer=0
preserve_water=1
preserve_lava=1

biomesToSpawnIn=ocean,kelp_forest,coral_reef,deep_ocean,coralium_infested_ocean,jungle,jungle_edge,jungle_hills,tropical_island,tropical_rainforest,rainforest,mutated_jungle,mutated_jungle_edge,bamboo_forest,overgrown_cliffs,eucalyptus_forest,mini_jungle,dark_forest,dark_forest_center,deep_mushroom_forest,dense_twilight_forest,enchanted_forest,fire_swamp,firefly_forest,highlands_center,mushroom_forest,oak_savannah,thornlands,twilight_clearing,twilight_forest,twilight_glacier,twilight_highlands,twilight_lake,twilight_stream,twilight_swamp

=0,100,preserveBlock

rule1=0,100,minecraft:cobblestone-0,minecraft:monster_egg-1,minecraft:mossy_cobblestone-0

rule2=0,100,minecraft:cobblestone-0,minecraft:monster_egg-1,minecraft:mossy_cobblestone-0
^0,100,minecraft:cobblestone-0,minecraft:monster_egg-1,minecraft:mossy_cobblestone-0
^0,100,preserveBlock

rule3^0,100,minecraft:cobblestone-0,minecraft:monster_egg-1,minecraft:mossy_cobblestone-0
^0,100,preserveBlock
^0,100,preserveBlock

layer
0,0,1,1,1,0,0
0,1,1,1,1,1,0
1,1,1,1,1,1,1
1,1,1,1,1,1,1
1,1,1,1,1,1,1
0,1,1,1,1,1,0
0,0,1,1,1,0,0
endlayer

layer
0,0,1,1,1,0,0
0,1,1,1,1,1,0
1,1,1,1,1,1,1
1,1,1,1,1,1,1
1,1,1,1,1,1,1
0,1,1,1,1,1,0
0,0,1,1,1,0,0
endlayer

layer
0,0,1,1,1,0,0
0,1,1,1,1,1,0
1,1,1,1,1,1,1
1,1,1,1,1,1,1
1,1,1,1,1,1,1
0,1,1,1,1,1,0
0,0,1,1,1,0,0
endlayer

layer
0,0,0,0,0,0,0
0,0,1,1,1,0,0
0,1,1,1,1,1,0
0,1,1,1,1,1,0
0,1,1,1,1,1,0
0,0,1,1,1,0,0
0,0,0,0,0,0,0
endlayer

layer
0,0,0,0,0,0,0
0,0,0,0,0,0,0
0,0,1,1,1,0,0
0,0,1,1,1,0,0
0,0,1,1,1,0,0
0,0,0,0,0,0,0
0,0,0,0,0,0,0
endlayer

layer
0,0,0,0,0,0,0
0,0,0,0,0,0,0
0,0,1,1,1,0,0
0,0,1,1,1,0,0
0,0,1,1,1,0,0
0,0,0,0,0,0,0
0,0,0,0,0,0,0
endlayer

layer
0,0,0,0,0,0,0
0,0,0,0,0,0,0
0,0,2,1,1,0,0
0,0,1,1,1,0,0
0,0,1,2,1,0,0
0,0,0,0,0,0,0
0,0,0,0,0,0,0
endlayer

layer
0,0,0,0,0,0,0
0,0,0,0,0,0,0
0,0,2,1,1,0,0
0,0,1,1,1,0,0
0,0,2,2,2,0,0
0,0,0,0,0,0,0
0,0,0,0,0,0,0
endlayer

layer
0,0,0,0,0,0,0
0,0,0,0,0,0,0
0,0,2,1,2,0,0
0,0,2,1,1,0,0
0,0,2,2,2,0,0
0,0,0,0,0,0,0
0,0,0,0,0,0,0
endlayer

layer
0,0,0,0,0,0,0
0,0,0,0,0,0,0
0,0,2,2,2,0,0
0,0,2,1,1,0,0
0,0,2,2,2,0,0
0,0,0,0,0,0,0
0,0,0,0,0,0,0
endlayer

layer
0,0,0,0,0,0,0
0,0,0,0,0,0,0
0,0,2,2,2,0,0
0,0,2,1,2,0,0
0,0,2,2,2,0,0
0,0,0,0,0,0,0
0,0,0,0,0,0,0
endlayer

layer
0,0,0,0,0,0,0
0,0,0,0,0,0,0
0,0,2,2,3,0,0
0,0,2,2,2,0,0
0,0,3,2,2,0,0
0,0,0,0,0,0,0
0,0,0,0,0,0,0
endlayer

layer
0,0,0,0,0,0,0
0,0,0,0,0,0,0
0,0,3,3,3,0,0
0,0,2,2,2,0,0
0,0,3,3,2,0,0
0,0,0,0,0,0,0
0,0,0,0,0,0,0
endlayer

layer
0,0,0,0,0,0,0
0,0,0,0,0,0,0
0,0,3,3,3,0,0
0,0,3,2,2,0,0
0,0,3,3,3,0,0
0,0,0,0,0,0,0
0,0,0,0,0,0,0
endlayer

layer
0,0,0,0,0,0,0
0,0,0,0,0,0,0
0,0,3,3,3,0,0
0,0,3,2,3,0,0
0,0,3,3,3,0,0
0,0,0,0,0,0,0
0,0,0,0,0,0,0
endlayer

layer
0,0,0,0,0,0,0
0,0,0,0,0,0,0
0,0,3,3,3,0,0
0,0,3,3,3,0,0
0,0,3,3,3,0,0
0,0,0,0,0,0,0
0,0,0,0,0,0,0
endlayer

layer
0,0,0,0,0,0,0
0,0,0,0,0,0,0
0,0,0,3,0,0,0
0,0,3,3,3,0,0
0,0,0,3,0,0,0
0,0,0,0,0,0,0
0,0,0,0,0,0,0
endlayer

layer
0,0,0,0,0,0,0
0,0,0,0,0,0,0
0,0,0,0,0,0,0
0,0,0,3,0,0,0
0,0,0,0,0,0,0
0,0,0,0,0,0,0
0,0,0,0,0,0,0
endlayer

