
# Created by Ruins mod version 16.7 Ingame Parser
# authoring Player: ST753M

# A ship manned by illagers

weight=1
spawnMinDistance=500
embed_into_distance=4
acceptable_target_blocks=water
unacceptable_target_blocks=
dimensions=24,15,28
allowable_overhang=0
max_leveling=0
leveling_buffer=0
preserve_water=0
preserve_lava=0

biomesToSpawnIn=ocean,kelp_forest,coral_reef,deep_ocean,coralium_infested_ocean

rule1=0,100,preserveBlock
rule2=0,100,minecraft:cobblestone-0
rule3=0,100,minecraft:log-5
rule4=0,100,minecraft:planks-5
rule5=0,100,minecraft:log-9
rule6=0,100,minecraft:log-1
rule7=0,100,minecraft:bed-10
rule8=0,100,minecraft:bed-2
rule9=0,100,minecraft:dark_oak_stairs-2
rule10=0,100,minecraft:dark_oak_stairs-1
rule11=0,100,minecraft:dark_oak_stairs-4

rule12=0,100,CommandBlock:RUINSTRIGGER /summon vindication_illager ~ ~1 ~ {PersistenceRequired:1}:@-1

rule13=0,100,CommandBlock:RUINSTRIGGER /summon illusion_illager ~ ~1 ~ {PersistenceRequired:1}:@-1,CommandBlock:RUINSTRIGGER /summon vindication_illager ~ ~1 ~ {PersistenceRequired:1}:@-1,CommandBlock:RUINSTRIGGER /summon vindication_illager ~ ~1 ~ {PersistenceRequired:1}:@-1,CommandBlock:RUINSTRIGGER /summon vindication_illager ~ ~1 ~ {PersistenceRequired:1}:@-1,CommandBlock:RUINSTRIGGER /summon vindication_illager ~ ~1 ~ {PersistenceRequired:1}:@-1,CommandBlock:RUINSTRIGGER /summon vindication_illager ~ ~1 ~ {PersistenceRequired:1}:@-1,CommandBlock:RUINSTRIGGER /summon vindication_illager ~ ~1 ~ {PersistenceRequired:1}:@-1,CommandBlock:RUINSTRIGGER /summon vindication_illager ~ ~1 ~ {PersistenceRequired:1}:@-1,CommandBlock:RUINSTRIGGER /summon vindication_illager ~ ~1 ~ {PersistenceRequired:1}:@-1,CommandBlock:RUINSTRIGGER /summon vindication_illager ~ ~1 ~ {PersistenceRequired:1}:@-1,CommandBlock:RUINSTRIGGER /summon vindication_illager ~ ~1 ~ {PersistenceRequired:1}:@-1


rule14=0,100,minecraft:dark_oak_fence-0
rule15=0,100,minecraft:dark_oak_stairs-0
rule16=0,100,minecraft:crafting_table-0
rule17=0,100,minecraft:furnace-4
rule18=0,100,minecraft:iron_door-1
rule19=0,100,minecraft:wooden_slab-5
rule20=0,100,minecraft:carpet-14
rule21=0,100,CommandBlock:RUINSTRIGGER /summon villager ~ ~1 ~:@-1
rule22=0,100,minecraft:iron_bars-0
rule23=0,100,minecraft:bed-3
rule24=0,100,minecraft:bed-11
rule25=0,100,minecraft:stained_glass-14
rule26=0,100,minecraft:lever-4
rule27=0,100,minecraft:flower_pot-0
rule28=0,100,minecraft:iron_door-8
rule29=0,100,minecraft:ladder-4
rule30=0,100,minecraft:wooden_slab-13
rule31=0,100,minecraft:trapdoor-9
rule32=0,100,minecraft:trapdoor-13
rule33=0,100,minecraft:glowstone-0
rule34=0,100,minecraft:ladder-5
rule35=0,100,minecraft:stone_stairs-4
rule36=0,100,minecraft:stone_stairs-6
rule37=0,100,minecraft:ladder-2
rule38=0,100,minecraft:stone_stairs-5
rule39=0,100,minecraft:stone_stairs-3
rule40=0,100,minecraft:stone_slab-3
rule41=0,100,minecraft:stone_stairs-2
rule42=0,100,minecraft:stone_stairs-1
rule43=0,100,minecraft:stone_slab-11
rule44=0,100,minecraft:cobblestone_wall-0
rule45=0,100,minecraft:stone_stairs-0
rule46=0,100,minecraft:glass_pane-0
rule47=1,100,minecraft:redstone_torch-5
rule48=0,100,minecraft:dark_oak_stairs-7
rule49=0,100,minecraft:wool-8
rule50=0,100,minecraft:stone_stairs-7
rule51=0,100,minecraft:spruce_stairs-2
rule52=0,100,minecraft:spruce_stairs-0
rule53=0,100,minecraft:spruce_stairs-3
rule54=0,10,MobSpawner:Spider
rule55=0,100,minecraft:spruce_stairs-1
rule56=0,100,minecraft:planks-1
rule57=0,100,minecraft:wool-14

layer
1,1,1,1,1,1,1,1,1,1,1,1,1,1,1,1,1,1,1,1,1,1,1,1,1,1,1,1
1,1,1,1,1,1,1,1,1,1,1,1,1,1,1,1,1,1,1,1,1,1,1,1,1,1,1,1
1,1,1,1,1,1,1,1,1,1,1,1,1,1,1,1,1,1,1,1,1,1,1,1,1,1,1,1
1,1,1,1,1,1,1,1,1,1,1,1,1,1,1,1,1,1,1,1,1,1,1,1,1,1,1,1
1,1,1,1,1,1,1,1,1,1,1,1,1,1,1,1,1,1,1,1,1,1,1,1,1,1,1,1
1,1,1,1,1,1,1,1,1,1,4,2,2,2,2,2,2,2,3,2,2,2,2,2,2,2,1,1
1,1,1,1,1,1,1,1,1,1,4,2,2,2,2,2,2,2,3,2,2,2,2,2,2,2,1,1
1,1,1,1,1,1,1,1,1,1,4,2,2,2,2,2,2,2,3,2,2,2,2,2,2,2,1,1
1,1,1,1,1,1,1,1,1,1,4,2,2,2,2,2,2,2,3,2,2,2,2,2,2,2,1,1
1,1,1,1,1,1,1,1,1,1,4,2,2,2,2,2,2,2,3,2,2,2,2,2,2,2,1,1
1,1,1,1,1,1,1,1,1,1,1,1,1,1,1,1,1,1,1,1,1,1,1,1,1,1,1,1
1,1,1,1,1,1,1,1,1,1,1,1,1,1,1,1,1,1,1,1,1,1,1,1,1,1,1,1
1,1,1,1,1,1,1,1,1,1,1,1,1,1,1,1,1,1,1,1,1,1,1,1,1,1,1,1
1,1,1,1,1,1,1,1,1,1,1,1,1,1,1,1,1,1,1,1,1,1,1,1,1,1,1,1
1,1,1,1,1,1,1,1,1,1,1,1,1,1,1,1,1,1,1,1,1,1,1,1,1,1,1,1
endlayer

layer
1,1,1,1,1,1,1,1,1,1,1,1,1,1,1,1,1,1,1,1,1,1,1,1,1,1,1,1
1,1,1,1,1,1,1,1,1,1,1,1,1,1,1,1,1,1,1,1,1,1,1,1,1,1,1,1
1,1,1,1,1,1,1,1,1,1,1,1,1,1,1,1,1,1,1,1,1,1,1,1,1,1,1,1
1,1,1,1,1,1,1,1,1,1,1,1,1,1,1,1,1,1,1,1,1,1,1,1,1,1,1,1
1,1,1,1,1,1,1,1,1,1,4,5,5,5,5,5,5,5,5,5,5,5,5,5,5,5,1,1
1,1,1,1,1,1,1,4,4,4,9,0,0,0,0,0,0,0,0,6,8,7,6,8,7,6,4,1
1,1,1,1,1,1,1,4,4,4,9,0,10,0,10,0,10,0,0,0,0,0,0,0,0,0,4,1
1,1,1,1,1,1,4,4,4,5,6,0,14,14,14,14,14,0,13,0,12,12,0,0,0,11,4,1
1,1,1,1,1,1,1,4,4,4,9,0,15,0,15,0,15,0,0,0,0,0,0,0,0,10,4,1
1,1,1,1,1,1,1,4,4,4,9,0,0,0,0,0,0,0,0,0,17,17,16,0,0,0,4,1
1,1,1,1,1,1,1,1,1,1,4,5,5,5,5,5,5,5,5,5,5,5,5,5,5,5,1,1
1,1,1,1,1,1,1,1,1,1,1,1,1,1,1,1,1,1,1,1,1,1,1,1,1,1,1,1
1,1,1,1,1,1,1,1,1,1,1,1,1,1,1,1,1,1,1,1,1,1,1,1,1,1,1,1
1,1,1,1,1,1,1,1,1,1,1,1,1,1,1,1,1,1,1,1,1,1,1,1,1,1,1,1
1,1,1,1,1,1,1,1,1,1,1,1,1,1,1,1,1,1,1,1,1,1,1,1,1,1,1,1
endlayer

layer
1,1,1,1,1,1,1,1,1,1,1,1,1,1,1,1,1,1,1,1,1,1,1,1,1,1,1,1
1,1,1,1,1,1,1,1,1,1,1,1,1,1,1,1,1,1,1,1,1,1,1,1,1,1,1,1
1,1,1,1,1,1,1,1,1,1,1,1,1,1,1,1,1,1,1,1,1,1,1,1,1,1,1,1
1,1,1,1,1,1,1,1,1,1,1,4,4,4,4,4,4,4,4,4,4,4,4,4,4,4,1,1
1,1,1,1,1,1,1,4,4,4,4,14,0,0,0,0,0,0,14,0,0,0,0,0,0,6,4,1
1,1,1,1,1,1,4,0,0,4,0,0,0,0,0,0,0,0,0,6,8,7,6,8,7,6,4,1
1,1,1,1,1,4,19,0,0,18,0,0,0,0,0,0,0,0,0,0,0,0,0,0,0,11,4,1
1,1,1,1,1,4,0,21,0,4,6,0,20,20,20,20,20,0,0,0,0,0,0,0,0,10,4,1
1,1,1,1,1,4,19,23,0,22,0,0,0,0,0,0,0,0,0,0,0,0,0,0,0,0,4,1
1,1,1,1,1,1,4,24,0,22,0,0,0,0,0,0,0,0,0,0,0,0,0,0,0,0,4,1
1,1,1,1,1,1,1,4,4,4,4,14,0,0,0,0,0,0,14,0,0,0,0,0,0,6,4,1
1,1,1,1,1,1,1,1,1,1,1,4,4,4,4,4,4,4,4,4,4,4,4,4,4,4,1,1
1,1,1,1,1,1,1,1,1,1,1,1,1,1,1,1,1,1,1,1,1,1,1,1,1,1,1,1
1,1,1,1,1,1,1,1,1,1,1,1,1,1,1,1,1,1,1,1,1,1,1,1,1,1,1,1
1,1,1,1,1,1,1,1,1,1,1,1,1,1,1,1,1,1,1,1,1,1,1,1,1,1,1,1
endlayer

layer
1,1,1,1,1,1,1,1,1,1,1,1,1,1,1,1,1,1,1,1,1,1,1,1,1,1,1,1
1,1,1,1,1,1,1,1,1,1,1,1,1,1,1,1,1,1,1,1,1,1,1,1,1,1,1,1
1,1,1,1,1,1,1,1,1,1,1,1,1,1,1,1,1,1,1,1,1,1,1,1,1,1,1,1
1,1,1,1,1,1,1,1,1,1,1,4,4,25,4,4,25,4,4,25,4,4,25,4,4,4,2,1
1,1,1,1,1,1,4,4,4,4,4,14,0,0,0,0,0,0,14,0,0,0,0,0,0,6,4,1
1,1,1,1,1,4,27,0,0,4,26,0,0,0,0,0,0,0,0,14,0,0,14,0,0,14,4,1
1,1,1,1,4,4,0,0,0,28,0,0,0,0,0,0,0,0,0,0,0,0,0,0,0,10,4,1
1,1,1,1,4,4,0,0,0,4,6,0,0,0,0,0,0,0,0,0,0,0,0,0,0,0,4,1
1,1,1,1,4,4,0,0,0,22,0,0,0,0,0,0,0,0,0,0,0,0,0,0,0,0,4,1
1,1,1,1,1,4,0,0,0,22,0,0,0,0,0,0,0,0,0,0,0,0,0,0,0,0,4,1
1,1,1,1,1,1,4,4,4,4,4,14,0,0,0,0,0,0,14,0,0,0,0,0,0,6,4,1
1,1,1,1,1,1,1,1,1,1,1,4,4,25,4,4,25,4,4,25,4,4,25,4,4,4,2,1
1,1,1,1,1,1,1,1,1,1,1,1,1,1,1,1,1,1,1,1,1,1,1,1,1,1,1,1
1,1,1,1,1,1,1,1,1,1,1,1,1,1,1,1,1,1,1,1,1,1,1,1,1,1,1,1
1,1,1,1,1,1,1,1,1,1,1,1,1,1,1,1,1,1,1,1,1,1,1,1,1,1,1,1
endlayer

layer
1,1,1,1,1,1,1,1,1,1,1,1,1,1,1,1,1,1,1,1,1,1,1,1,1,1,1,1
1,1,1,1,1,1,1,1,1,1,1,1,1,1,1,1,1,1,1,1,1,1,1,1,1,1,1,1
1,1,1,1,1,1,1,1,1,1,1,1,1,1,1,1,1,29,1,1,1,1,1,1,1,1,1,1
1,1,1,1,1,1,1,1,1,1,1,4,4,4,4,4,4,4,4,4,4,4,4,4,4,4,2,1
1,1,1,1,1,1,4,4,4,4,4,5,5,5,5,5,5,5,5,5,5,5,5,5,5,5,4,1
1,1,1,1,1,4,0,0,0,4,0,30,30,30,30,30,30,30,3,30,30,30,30,30,30,10,4,1
1,1,1,1,4,4,0,0,0,4,0,30,31,31,31,31,31,30,3,30,30,30,30,30,30,0,4,1
1,30,5,5,33,32,0,0,0,4,6,30,31,31,31,31,31,30,3,30,30,30,30,30,30,0,4,1
1,1,1,1,4,4,0,0,0,4,0,30,31,31,31,31,31,30,3,30,30,30,30,30,30,0,4,1
1,1,1,1,1,4,0,0,0,4,0,30,30,30,30,30,30,30,3,30,30,30,30,30,30,0,4,1
1,1,1,1,1,1,4,4,4,4,4,5,5,5,5,5,5,5,5,5,5,5,5,5,5,5,4,1
1,1,1,1,1,1,1,1,1,1,1,4,4,4,4,4,4,4,4,4,4,4,4,4,4,4,2,1
1,1,1,1,1,1,1,1,1,1,1,1,1,1,1,1,1,34,1,1,1,1,1,1,1,1,1,1
1,1,1,1,1,1,1,1,1,1,1,1,1,1,1,1,1,1,1,1,1,1,1,1,1,1,1,1
1,1,1,1,1,1,1,1,1,1,1,1,1,1,1,1,1,1,1,1,1,1,1,1,1,1,1,1
endlayer

layer
1,1,1,1,1,1,1,1,1,1,1,1,1,1,1,1,1,1,1,1,1,1,1,1,1,1,1,1
1,1,1,1,1,1,1,1,1,1,1,1,1,1,1,1,1,1,1,1,1,1,1,1,1,1,1,1
1,1,1,1,1,1,1,1,1,1,1,1,35,1,35,1,35,29,35,1,35,1,35,1,35,1,35,1
1,1,1,1,1,1,1,1,1,1,1,19,4,19,4,19,4,4,2,4,4,4,4,4,4,4,2,36
1,1,1,1,1,1,4,4,4,4,4,0,0,0,0,0,0,19,4,0,0,0,0,0,0,0,4,0
1,1,1,1,1,4,30,30,30,4,19,0,0,0,0,0,0,14,5,0,0,0,0,0,0,0,4,36
1,1,1,1,4,4,30,30,30,4,19,0,0,0,0,0,0,0,0,0,20,20,20,20,0,0,4,0
5,5,5,19,4,4,30,30,30,4,6,37,0,0,0,0,0,0,0,0,20,20,20,20,0,0,4,36
1,1,1,1,4,4,30,30,30,4,19,0,0,0,0,0,0,0,0,0,20,20,20,20,0,0,4,0
1,1,1,1,1,4,30,30,30,4,19,0,0,0,0,0,0,14,5,0,0,0,0,0,0,0,4,36
1,1,1,1,1,1,4,4,4,4,4,0,0,0,0,0,0,19,4,0,0,0,0,0,0,0,4,0
1,1,1,1,1,1,1,1,1,1,1,19,4,19,4,19,4,4,2,4,4,4,4,4,4,4,2,36
1,1,1,1,1,1,1,1,1,1,1,1,38,1,38,1,38,34,38,1,38,1,38,1,38,1,38,1
1,1,1,1,1,1,1,1,1,1,1,1,1,1,1,1,1,1,1,1,1,1,1,1,1,1,1,1
1,1,1,1,1,1,1,1,1,1,1,1,1,1,1,1,1,1,1,1,1,1,1,1,1,1,1,1
endlayer

layer
1,1,1,1,1,1,1,1,1,1,1,1,1,1,1,1,1,1,1,1,1,1,1,1,1,1,1,1
1,1,1,1,1,1,1,1,1,1,1,1,1,1,1,1,1,1,1,1,1,1,1,1,1,1,1,1
1,1,1,1,1,1,1,1,1,1,1,2,2,41,40,40,40,1,40,40,40,40,40,40,40,39,2,2
1,1,1,1,1,1,35,1,35,1,35,4,4,4,4,4,9,1,2,4,3,3,3,3,3,4,2,2
1,1,1,1,1,35,4,19,4,19,4,0,0,0,0,0,0,1,4,0,0,0,0,0,0,0,4,42
1,1,1,1,35,4,0,0,0,0,0,0,0,0,0,0,0,14,5,0,0,0,0,0,0,0,5,40
1,1,1,1,4,0,0,12,0,0,0,0,0,0,0,0,0,0,0,0,0,0,0,0,0,0,5,40
44,0,14,43,4,5,9,0,0,0,6,37,0,0,0,0,0,0,0,0,0,0,0,0,0,0,5,40
1,1,1,1,4,0,0,12,0,0,0,0,0,0,0,0,0,0,0,0,0,0,0,0,0,0,5,40
1,1,1,1,38,4,0,0,0,0,0,0,0,0,0,0,0,14,5,0,0,0,0,0,0,0,5,40
1,1,1,1,1,38,4,19,4,19,4,0,0,0,0,0,0,1,4,0,0,0,0,0,0,0,4,45
1,1,1,1,1,1,38,1,38,1,38,4,4,4,4,4,9,1,2,4,3,3,3,3,3,4,2,2
1,1,1,1,1,1,1,1,1,1,1,2,2,41,40,40,40,1,40,40,40,40,40,40,40,39,2,2
1,1,1,1,1,1,1,1,1,1,1,1,1,1,1,1,1,1,1,1,1,1,1,1,1,1,1,1
1,1,1,1,1,1,1,1,1,1,1,1,1,1,1,1,1,1,1,1,1,1,1,1,1,1,1,1
endlayer

layer
1,1,1,1,1,1,1,1,1,1,1,1,1,1,1,1,1,1,1,1,1,1,1,1,1,1,1,1
1,1,1,1,1,1,1,1,1,1,1,1,1,1,1,1,1,1,1,1,1,1,1,1,1,1,1,1
1,1,1,1,1,1,1,1,1,1,1,40,1,1,1,1,1,1,1,1,1,1,1,1,1,1,1,44
1,1,1,1,1,1,40,40,40,40,40,4,19,19,1,1,1,1,2,4,3,46,46,46,3,4,2,0
1,1,1,1,1,40,4,4,4,4,4,0,0,0,1,1,1,1,4,0,0,0,0,0,0,0,4,0
1,1,1,1,40,4,0,0,0,0,0,0,0,0,1,1,1,14,5,0,0,0,0,0,0,0,5,0
1,1,1,40,40,0,0,0,0,0,0,0,0,0,1,1,1,0,0,0,0,0,0,0,0,0,46,0
14,0,14,2,5,9,0,0,0,0,6,37,0,0,1,1,1,0,0,0,0,0,0,0,0,0,46,0
1,1,1,40,40,0,0,0,0,0,0,0,0,0,1,1,1,0,0,0,0,0,0,0,0,0,46,0
1,1,1,1,40,4,0,0,0,0,0,0,0,0,1,1,1,14,5,0,0,0,0,0,0,0,5,0
1,1,1,1,1,40,4,4,4,4,4,0,0,0,1,1,1,1,4,0,0,0,0,0,0,0,4,0
1,1,1,1,1,1,40,40,40,40,40,4,19,19,1,1,1,1,2,4,3,46,46,46,3,4,2,0
1,1,1,1,1,1,1,1,1,1,1,40,1,1,1,1,1,1,1,1,1,1,1,1,1,1,1,44
1,1,1,1,1,1,1,1,1,1,1,1,1,1,1,1,1,1,1,1,1,1,1,1,1,1,1,1
1,1,1,1,1,1,1,1,1,1,1,1,1,1,1,1,1,1,1,1,1,1,1,1,1,1,1,1
endlayer

layer
1,1,1,1,1,1,1,1,1,1,1,1,1,1,1,1,1,1,1,1,1,1,1,1,1,1,1,1
1,1,1,1,1,1,1,1,1,1,1,1,1,1,1,1,1,1,1,1,1,1,1,1,1,1,1,1
1,1,1,1,1,1,1,1,1,1,1,1,1,1,1,1,1,1,1,1,14,1,1,1,14,1,1,47
1,1,1,1,1,1,1,1,1,1,1,1,1,1,1,1,1,1,2,4,3,46,46,46,3,4,2,0
1,1,1,1,1,1,1,1,1,1,1,1,1,1,1,1,1,1,4,0,0,0,0,0,0,0,4,0
1,1,1,1,1,1,1,1,1,1,1,1,1,1,1,1,1,14,5,0,0,0,0,0,0,0,5,14
1,1,1,1,1,1,1,1,1,1,1,1,1,1,1,1,1,0,0,0,0,0,14,0,0,0,46,0
14,0,48,5,9,0,0,0,0,0,6,37,1,1,1,1,1,0,0,0,0,14,14,14,0,0,46,0
1,1,1,1,1,1,1,1,1,1,1,1,1,1,1,1,1,0,0,0,0,0,14,0,0,0,46,0
1,1,1,1,1,1,1,1,1,1,1,1,1,1,1,1,1,14,5,0,0,0,0,0,0,0,5,14
1,1,1,1,1,1,1,1,1,1,1,1,1,1,1,1,1,1,4,0,0,0,0,0,0,0,4,0
1,1,1,1,1,1,1,1,1,1,1,1,1,1,1,1,1,1,2,4,3,46,46,46,3,4,2,0
1,1,1,1,1,1,1,1,1,1,1,1,1,1,1,1,1,1,1,1,14,1,1,1,14,1,1,47
1,1,1,1,1,1,1,1,1,1,1,1,1,1,1,1,1,1,1,1,1,1,1,1,1,1,1,1
1,1,1,1,1,1,1,1,1,1,1,1,1,1,1,1,1,1,1,1,1,1,1,1,1,1,1,1
endlayer

layer
1,1,1,1,1,1,1,1,1,49,3,1,1,1,1,1,1,1,1,1,1,1,1,1,1,1,1,1
1,1,1,1,1,1,1,1,1,49,3,1,1,1,1,1,1,1,1,1,1,1,1,1,1,1,1,1
1,1,1,1,1,1,1,1,1,49,3,1,1,1,1,1,1,1,1,1,14,1,1,1,14,1,1,1
1,1,1,1,1,1,1,1,1,49,3,1,1,1,1,1,1,1,2,4,3,46,46,46,3,4,2,0
1,1,1,1,1,1,1,1,1,49,3,1,1,1,1,1,1,1,4,0,0,0,0,0,0,0,4,0
1,1,1,1,1,1,1,1,1,49,3,1,1,1,1,1,1,14,5,0,0,0,0,0,0,0,5,14
1,1,1,1,1,1,1,1,1,49,3,1,1,1,1,1,1,0,14,0,0,0,47,0,0,0,46,0
14,48,5,9,0,0,0,0,0,0,6,37,1,1,1,1,1,0,14,0,0,47,14,47,0,0,46,0
1,1,1,1,1,1,1,1,1,49,3,1,1,1,1,1,1,0,14,0,0,0,47,0,0,0,46,0
1,1,1,1,1,1,1,1,1,49,3,1,1,1,1,1,1,14,5,0,0,0,0,0,0,0,5,14
1,1,1,1,1,1,1,1,1,49,3,1,1,1,1,1,1,1,4,0,0,0,0,0,0,0,4,0
1,1,1,1,1,1,1,1,1,49,3,1,1,1,1,1,1,1,2,4,3,46,46,46,3,4,2,0
1,1,1,1,1,1,1,1,1,49,3,1,1,1,1,1,1,1,1,1,14,1,1,1,14,1,1,1
1,1,1,1,1,1,1,1,1,49,3,1,1,1,1,1,1,1,1,1,1,1,1,1,1,1,1,1
1,1,1,1,1,1,1,1,1,49,3,1,1,1,1,1,1,1,1,1,1,1,1,1,1,1,1,1
endlayer

layer
1,1,1,1,1,1,1,1,1,49,1,1,1,1,1,1,1,1,1,1,1,1,1,1,1,1,1,1
1,1,1,1,1,1,1,1,49,0,0,1,1,1,1,1,1,1,1,1,1,1,1,1,1,1,1,1
1,1,1,1,1,1,1,1,49,0,0,1,1,1,1,1,1,1,1,1,5,5,5,5,5,1,1,1
1,1,1,1,1,1,1,1,49,0,0,1,1,1,1,1,1,1,2,4,3,3,3,3,3,4,2,0
1,1,1,1,1,1,1,1,49,0,0,1,1,1,1,1,1,1,4,0,0,0,0,0,0,0,4,0
1,1,1,1,1,1,1,1,49,0,0,1,1,1,1,1,1,3,5,0,0,0,0,0,0,0,5,3
1,1,1,1,1,1,1,1,1,49,0,1,1,1,1,1,1,3,5,0,0,0,0,0,0,0,5,3
5,5,9,1,1,1,1,1,1,0,6,37,1,1,1,1,1,3,5,0,0,0,14,0,0,0,5,3
1,1,1,1,1,1,1,1,1,49,1,1,1,1,1,1,1,3,5,0,0,0,0,0,0,0,5,3
1,1,1,1,1,1,1,1,49,0,1,1,1,1,1,1,1,3,5,0,0,0,0,0,0,0,5,3
1,1,1,1,1,1,1,1,49,0,1,1,1,1,1,1,1,3,4,0,0,0,0,0,0,0,4,0
1,1,1,1,1,1,1,1,49,0,1,1,1,1,1,1,1,1,2,4,3,3,3,3,3,4,2,0
1,1,1,1,1,1,1,1,49,0,1,1,1,1,1,1,1,1,1,1,5,5,5,5,5,1,1,1
1,1,1,1,1,1,1,1,49,0,1,1,1,1,1,1,1,1,1,1,1,1,1,1,1,1,1,1
1,1,1,1,1,1,1,1,1,49,1,1,1,1,1,1,1,1,1,1,1,1,1,1,1,1,1,1
endlayer

layer
1,1,1,1,1,1,1,1,1,1,1,1,1,1,1,1,1,1,1,1,1,1,1,1,1,1,1,1
1,1,1,1,1,1,1,1,49,0,0,1,1,1,1,1,1,1,1,1,1,1,1,1,1,1,1,1
1,1,1,1,1,1,1,49,0,0,0,1,1,1,1,1,1,1,1,1,1,1,1,1,1,1,1,1
1,1,1,1,1,1,1,49,0,0,0,1,1,1,1,1,1,1,2,4,4,4,4,4,4,4,2,0
1,1,1,1,1,1,1,49,0,0,0,1,1,1,1,1,1,1,4,0,0,0,0,0,0,0,4,0
1,1,1,1,1,1,1,1,49,0,0,1,1,1,1,1,1,1,4,0,0,0,0,0,0,0,4,0
1,1,1,1,1,1,1,1,1,0,0,1,1,1,1,1,1,1,4,0,0,0,0,0,0,0,4,0
9,44,1,1,1,1,1,1,1,0,6,37,1,1,1,1,1,1,4,0,0,0,6,0,0,0,4,0
1,1,1,1,1,1,1,1,1,0,1,1,1,1,1,1,1,1,4,0,0,0,0,0,0,0,4,0
1,1,1,1,1,1,1,1,49,0,1,1,1,1,1,1,1,1,4,0,0,0,0,0,0,0,4,0
1,1,1,1,1,1,1,49,0,0,1,1,1,1,1,1,1,1,4,0,0,0,0,0,0,0,4,0
1,1,1,1,1,1,1,49,0,0,1,1,1,1,1,1,1,1,2,4,4,4,4,4,4,4,2,0
1,1,1,1,1,1,1,49,0,0,1,1,1,1,1,1,1,1,1,1,1,1,1,1,1,1,1,1
1,1,1,1,1,1,1,1,49,0,1,1,1,1,1,1,1,1,1,1,1,1,1,1,1,1,1,1
1,1,1,1,1,1,1,1,1,1,1,1,1,1,1,1,1,1,1,1,1,1,1,1,1,1,1,1
endlayer

layer
1,1,1,1,1,1,1,1,1,1,1,1,1,1,1,1,1,1,1,1,1,1,1,1,1,1,1,1
1,1,1,1,1,1,1,49,0,0,0,1,1,1,1,1,1,1,1,1,1,1,1,1,1,1,1,1
1,1,1,1,1,1,1,49,0,0,0,1,1,1,1,1,1,1,35,1,35,1,35,1,35,1,35,1
1,1,1,1,1,1,1,49,0,0,0,1,1,1,1,1,1,50,2,2,2,2,2,2,2,2,2,36
1,1,1,1,1,1,1,49,0,0,0,1,1,1,1,1,1,0,2,0,0,0,3,0,0,0,2,0
1,1,1,1,1,1,1,49,0,0,0,1,1,1,1,1,1,50,2,0,0,0,3,0,0,0,2,36
1,1,1,1,1,1,1,1,1,0,0,1,1,1,1,1,1,0,2,0,0,0,3,0,0,0,2,0
0,14,1,1,1,1,1,1,1,0,6,37,1,1,1,1,1,50,2,5,5,5,6,5,5,5,2,36
1,1,1,1,1,1,1,1,1,0,1,1,1,1,1,1,1,0,2,0,0,0,3,0,0,0,2,0
1,1,1,1,1,1,1,49,0,0,1,1,1,1,1,1,1,50,2,0,0,0,3,0,0,0,2,36
1,1,1,1,1,1,1,49,0,0,1,1,1,1,1,1,1,0,2,0,0,0,3,0,0,0,2,0
1,1,1,1,1,1,1,49,0,0,1,1,1,1,1,1,1,50,2,2,2,2,2,2,2,2,2,36
1,1,1,1,1,1,1,49,0,0,1,1,1,1,1,1,1,1,38,1,38,1,38,1,38,1,38,1
1,1,1,1,1,1,1,49,0,0,1,1,1,1,1,1,1,1,1,1,1,1,1,1,1,1,1,1
1,1,1,1,1,1,1,1,1,1,1,1,1,1,1,1,1,1,1,1,1,1,1,1,1,1,1,1
endlayer

layer
1,1,1,1,1,1,1,1,1,1,1,1,1,1,1,1,1,1,1,1,1,1,1,1,1,1,1,1
1,1,1,1,1,1,1,49,0,0,0,1,1,1,1,1,1,1,1,1,1,1,1,1,1,1,1,1
1,1,1,1,1,1,1,49,0,0,0,1,1,1,1,1,1,52,52,52,52,52,52,52,52,52,52,51
1,1,1,1,1,1,1,49,0,0,0,1,1,1,1,1,1,53,5,5,5,5,5,5,5,5,5,51
1,1,1,1,1,1,1,49,0,0,0,1,1,1,1,1,1,53,3,0,0,0,0,0,0,0,3,51
1,1,1,1,1,1,1,49,0,0,0,1,1,1,1,1,1,53,3,0,0,0,0,0,0,0,3,51
1,1,1,1,1,1,1,1,1,0,0,1,1,1,1,1,1,53,3,0,0,0,0,0,0,0,3,51
0,33,1,1,1,1,1,1,1,0,6,37,1,1,1,1,1,53,3,0,0,0,54,0,0,0,3,51
1,1,1,1,1,1,1,1,1,0,1,1,1,1,1,1,1,53,3,0,0,0,0,0,0,0,3,51
1,1,1,1,1,1,1,49,0,0,1,1,1,1,1,1,1,53,3,0,0,0,0,0,0,0,3,51
1,1,1,1,1,1,1,49,0,0,1,1,1,1,1,1,1,53,3,0,0,0,0,0,0,0,3,51
1,1,1,1,1,1,1,49,0,0,1,1,1,1,1,1,1,53,5,5,5,5,5,5,5,5,3,51
1,1,1,1,1,1,1,49,0,0,1,1,1,1,1,1,1,55,55,55,55,55,55,55,55,55,55,55
1,1,1,1,1,1,1,49,0,0,1,1,1,1,1,1,1,1,1,1,1,1,1,1,1,1,1,1
1,1,1,1,1,1,1,1,1,1,1,1,1,1,1,1,1,1,1,1,1,1,1,1,1,1,1,1
endlayer

layer
1,1,1,1,1,1,1,1,1,1,1,1,1,1,1,1,1,1,1,1,1,1,1,1,1,1,1,1
1,1,1,1,1,1,1,1,49,0,0,1,1,1,1,1,1,1,1,1,1,1,1,1,1,1,1,1
1,1,1,1,1,1,1,49,0,0,0,1,1,1,1,1,1,1,1,1,1,1,1,1,1,1,1,1
1,1,1,1,1,1,1,49,0,0,0,1,1,1,1,1,1,1,53,52,52,52,52,52,52,52,52,1
1,1,1,1,1,1,1,49,0,0,0,1,1,1,1,1,1,1,53,56,56,56,56,56,56,56,51,1
1,1,1,1,1,1,1,1,49,0,0,1,1,1,1,1,1,1,53,56,56,56,56,56,56,56,51,1
53,52,51,1,1,1,1,1,1,0,0,1,1,1,1,1,1,1,53,56,56,56,56,56,56,56,51,1
53,56,51,1,1,1,1,1,1,0,6,37,1,1,1,1,1,1,53,56,56,56,56,56,56,56,51,1
53,55,51,1,1,1,1,1,1,0,1,1,1,1,1,1,1,1,53,56,56,56,56,56,56,56,51,1
1,1,1,1,1,1,1,1,49,0,1,1,1,1,1,1,1,1,53,56,56,56,56,56,56,56,51,1
1,1,1,1,1,1,1,49,0,0,1,1,1,1,1,1,1,1,53,56,56,56,56,56,56,56,51,1
1,1,1,1,1,1,1,49,0,0,1,1,1,1,1,1,1,1,53,55,55,55,55,55,55,55,51,1
1,1,1,1,1,1,1,49,0,0,1,1,1,1,1,1,1,1,1,1,1,1,1,1,1,1,1,1
1,1,1,1,1,1,1,1,49,0,1,1,1,1,1,1,1,1,1,1,1,1,1,1,1,1,1,1
1,1,1,1,1,1,1,1,1,1,1,1,1,1,1,1,1,1,1,1,1,1,1,1,1,1,1,1
endlayer

layer
1,1,1,1,1,1,1,1,1,49,1,1,1,1,1,1,1,1,1,1,1,1,1,1,1,1,1,1
1,1,1,1,1,1,1,1,49,0,0,1,1,1,1,1,1,1,1,1,1,1,1,1,1,1,1,1
1,1,1,1,1,1,1,49,0,0,0,1,1,1,1,1,1,1,1,1,1,1,1,1,1,1,1,1
1,1,1,1,1,1,1,49,0,0,0,1,1,1,1,1,1,1,1,1,1,1,1,1,1,1,1,1
1,1,1,1,1,1,1,49,0,0,0,1,1,1,1,1,1,1,1,1,1,1,1,1,1,1,1,1
1,1,1,1,1,1,1,1,49,0,0,1,1,1,1,1,1,1,1,1,1,1,1,1,1,1,1,1
1,1,1,1,1,1,1,1,1,49,0,1,1,1,1,1,1,1,1,1,1,1,1,1,1,1,1,1
1,1,1,1,1,1,1,1,1,0,6,37,1,1,1,1,1,1,1,1,1,1,1,1,1,1,1,1
1,1,1,1,1,1,1,1,1,49,1,1,1,1,1,1,1,1,1,1,1,1,1,1,1,1,1,1
1,1,1,1,1,1,1,1,49,0,1,1,1,1,1,1,1,1,1,1,1,1,1,1,1,1,1,1
1,1,1,1,1,1,1,49,0,0,1,1,1,1,1,1,1,1,1,1,1,1,1,1,1,1,1,1
1,1,1,1,1,1,1,49,0,0,1,1,1,1,1,1,1,1,1,1,1,1,1,1,1,1,1,1
1,1,1,1,1,1,1,49,0,0,1,1,1,1,1,1,1,1,1,1,1,1,1,1,1,1,1,1
1,1,1,1,1,1,1,1,49,0,1,1,1,1,1,1,1,1,1,1,1,1,1,1,1,1,1,1
1,1,1,1,1,1,1,1,1,49,1,1,1,1,1,1,1,1,1,1,1,1,1,1,1,1,1,1
endlayer

layer
1,1,1,1,1,1,1,1,1,49,1,1,1,1,1,1,1,1,1,1,1,1,1,1,1,1,1,1
1,1,1,1,1,1,1,1,49,0,0,1,1,1,1,1,1,1,1,1,1,1,1,1,1,1,1,1
1,1,1,1,1,1,1,1,49,0,0,1,1,1,1,1,1,1,1,1,1,1,1,1,1,1,1,1
1,1,1,1,1,1,1,1,49,0,0,1,1,1,1,1,1,1,1,1,1,1,1,1,1,1,1,1
1,1,1,1,1,1,1,1,49,0,0,1,1,1,1,1,1,1,1,1,1,1,1,1,1,1,1,1
1,1,1,1,1,1,1,1,49,0,0,1,1,1,1,1,1,1,1,1,1,1,1,1,1,1,1,1
1,1,1,1,1,1,1,1,1,49,0,1,1,1,1,1,1,1,1,1,1,1,1,1,1,1,1,1
1,1,1,1,1,1,1,1,1,0,6,37,1,1,1,1,1,1,1,1,1,1,1,1,1,1,1,1
1,1,1,1,1,1,1,1,1,49,1,1,1,1,1,1,1,1,1,1,1,1,1,1,1,1,1,1
1,1,1,1,1,1,1,1,49,0,1,1,1,1,1,1,1,1,1,1,1,1,1,1,1,1,1,1
1,1,1,1,1,1,1,1,49,0,1,1,1,1,1,1,1,1,1,1,1,1,1,1,1,1,1,1
1,1,1,1,1,1,1,1,49,0,1,1,1,1,1,1,1,1,1,1,1,1,1,1,1,1,1,1
1,1,1,1,1,1,1,1,49,0,1,1,1,1,1,1,1,1,1,1,1,1,1,1,1,1,1,1
1,1,1,1,1,1,1,1,49,0,1,1,1,1,1,1,1,1,1,1,1,1,1,1,1,1,1,1
1,1,1,1,1,1,1,1,1,49,1,1,1,1,1,1,1,1,1,1,1,1,1,1,1,1,1,1
endlayer

layer
1,1,1,1,1,1,1,1,1,49,3,1,1,1,1,1,1,1,1,1,1,1,1,1,1,1,1,1
1,1,1,1,1,1,1,1,1,49,3,1,1,1,1,1,1,1,1,1,1,1,1,1,1,1,1,1
1,1,1,1,1,1,1,1,1,1,3,1,1,1,1,1,1,1,1,1,1,1,1,1,1,1,1,1
1,1,1,1,1,1,1,1,1,1,3,1,1,1,1,1,1,1,1,1,1,1,1,1,1,1,1,1
1,1,1,1,1,1,1,1,1,1,3,1,1,1,1,1,1,1,1,1,1,1,1,1,1,1,1,1
1,1,1,1,1,1,1,1,1,49,3,1,1,1,1,1,1,1,1,1,1,1,1,1,1,1,1,1
1,1,1,1,1,1,1,1,1,49,3,1,1,1,1,1,1,1,1,1,1,1,1,1,1,1,1,1
1,1,1,1,1,1,1,1,1,0,6,37,1,1,1,1,1,1,1,1,1,1,1,1,1,1,1,1
1,1,1,1,1,1,1,1,1,49,3,1,1,1,1,1,1,1,1,1,1,1,1,1,1,1,1,1
1,1,1,1,1,1,1,1,1,49,3,1,1,1,1,1,1,1,1,1,1,1,1,1,1,1,1,1
1,1,1,1,1,1,1,1,1,1,3,1,1,1,1,1,1,1,1,1,1,1,1,1,1,1,1,1
1,1,1,1,1,1,1,1,1,1,3,1,1,1,1,1,1,1,1,1,1,1,1,1,1,1,1,1
1,1,1,1,1,1,1,1,1,1,3,1,1,1,1,1,1,1,1,1,1,1,1,1,1,1,1,1
1,1,1,1,1,1,1,1,1,49,3,1,1,1,1,1,1,1,1,1,1,1,1,1,1,1,1,1
1,1,1,1,1,1,1,1,1,49,3,1,1,1,1,1,1,1,1,1,1,1,1,1,1,1,1,1
endlayer

layer
1,1,1,1,1,1,1,1,1,1,1,1,1,1,1,1,1,1,1,1,1,1,1,1,1,1,1,1
1,1,1,1,1,1,1,1,1,1,1,1,1,1,1,1,1,1,1,1,1,1,1,1,1,1,1,1
1,1,1,1,1,1,1,1,1,1,1,1,1,1,1,1,1,1,1,1,1,1,1,1,1,1,1,1
1,1,1,1,1,1,1,1,1,1,1,1,1,1,1,1,1,1,1,1,1,1,1,1,1,1,1,1
1,1,1,1,1,1,1,1,1,1,1,1,1,1,1,1,1,1,1,1,1,1,1,1,1,1,1,1
1,1,1,1,1,1,1,1,1,30,30,30,1,1,1,1,1,1,1,1,1,1,1,1,1,1,1,1
1,1,1,1,1,1,1,1,30,30,30,30,30,1,1,1,1,1,1,1,1,1,1,1,1,1,1,1
1,1,1,1,1,1,1,1,30,30,6,31,30,1,1,1,1,1,1,1,1,1,1,1,1,1,1,1
1,1,1,1,1,1,1,1,30,30,30,30,30,1,1,1,1,1,1,1,1,1,1,1,1,1,1,1
1,1,1,1,1,1,1,1,1,30,30,30,1,1,1,1,1,1,1,1,1,1,1,1,1,1,1,1
1,1,1,1,1,1,1,1,1,1,1,1,1,1,1,1,1,1,1,1,1,1,1,1,1,1,1,1
1,1,1,1,1,1,1,1,1,1,1,1,1,1,1,1,1,1,1,1,1,1,1,1,1,1,1,1
1,1,1,1,1,1,1,1,1,1,1,1,1,1,1,1,1,1,1,1,1,1,1,1,1,1,1,1
1,1,1,1,1,1,1,1,1,1,1,1,1,1,1,1,1,1,1,1,1,1,1,1,1,1,1,1
1,1,1,1,1,1,1,1,1,1,1,1,1,1,1,1,1,1,1,1,1,1,1,1,1,1,1,1
endlayer

layer
1,1,1,1,1,1,1,1,1,1,1,1,1,1,1,1,1,1,1,1,1,1,1,1,1,1,1,1
1,1,1,1,1,1,1,1,1,1,1,1,1,1,1,1,1,1,1,1,1,1,1,1,1,1,1,1
1,1,1,1,1,1,1,1,1,1,1,1,1,1,1,1,1,1,1,1,1,1,1,1,1,1,1,1
1,1,1,1,1,1,1,1,1,1,1,1,1,1,1,1,1,1,1,1,1,1,1,1,1,1,1,1
1,1,1,1,1,1,1,1,1,1,1,1,1,1,1,1,1,1,1,1,1,1,1,1,1,1,1,1
1,1,1,1,1,1,1,1,14,14,14,14,14,1,1,1,1,1,1,1,1,1,1,1,1,1,1,1
1,1,1,1,1,1,1,1,14,12,0,0,14,1,1,1,1,1,1,1,1,1,1,1,1,1,1,1
1,1,1,1,1,1,1,1,14,0,6,0,14,1,1,1,1,1,1,1,1,1,1,1,1,1,1,1
1,1,1,1,1,1,1,1,14,0,0,0,14,1,1,1,1,1,1,1,1,1,1,1,1,1,1,1
1,1,1,1,1,1,1,1,14,14,14,14,14,1,1,1,1,1,1,1,1,1,1,1,1,1,1,1
1,1,1,1,1,1,1,1,1,1,1,1,1,1,1,1,1,1,1,1,1,1,1,1,1,1,1,1
1,1,1,1,1,1,1,1,1,1,1,1,1,1,1,1,1,1,1,1,1,1,1,1,1,1,1,1
1,1,1,1,1,1,1,1,1,1,1,1,1,1,1,1,1,1,1,1,1,1,1,1,1,1,1,1
1,1,1,1,1,1,1,1,1,1,1,1,1,1,1,1,1,1,1,1,1,1,1,1,1,1,1,1
1,1,1,1,1,1,1,1,1,1,1,1,1,1,1,1,1,1,1,1,1,1,1,1,1,1,1,1
endlayer

layer
1,1,1,1,1,1,1,1,1,1,1,1,1,1,1,1,1,1,1,1,1,1,1,1,1,1,1,1
1,1,1,1,1,1,1,1,1,1,1,1,1,1,1,1,1,1,1,1,1,1,1,1,1,1,1,1
1,1,1,1,1,1,1,1,1,1,1,1,1,1,1,1,1,1,1,1,1,1,1,1,1,1,1,1
1,1,1,1,1,1,1,1,1,1,1,1,1,1,1,1,1,1,1,1,1,1,1,1,1,1,1,1
1,1,1,1,1,1,1,1,1,1,1,1,1,1,1,1,1,1,1,1,1,1,1,1,1,1,1,1
1,1,1,1,1,1,1,1,1,1,1,1,1,1,1,1,1,1,1,1,1,1,1,1,1,1,1,1
1,1,1,1,1,1,1,1,1,1,1,1,1,1,1,1,1,1,1,1,1,1,1,1,1,1,1,1
1,1,1,1,1,1,1,1,1,1,6,1,1,1,1,1,1,1,1,1,1,1,1,1,1,1,1,1
1,1,1,1,1,1,1,1,1,1,1,1,1,1,1,1,1,1,1,1,1,1,1,1,1,1,1,1
1,1,1,1,1,1,1,1,1,1,1,1,1,1,1,1,1,1,1,1,1,1,1,1,1,1,1,1
1,1,1,1,1,1,1,1,1,1,1,1,1,1,1,1,1,1,1,1,1,1,1,1,1,1,1,1
1,1,1,1,1,1,1,1,1,1,1,1,1,1,1,1,1,1,1,1,1,1,1,1,1,1,1,1
1,1,1,1,1,1,1,1,1,1,1,1,1,1,1,1,1,1,1,1,1,1,1,1,1,1,1,1
1,1,1,1,1,1,1,1,1,1,1,1,1,1,1,1,1,1,1,1,1,1,1,1,1,1,1,1
1,1,1,1,1,1,1,1,1,1,1,1,1,1,1,1,1,1,1,1,1,1,1,1,1,1,1,1
endlayer

layer
1,1,1,1,1,1,1,1,1,1,1,1,1,1,1,1,1,1,1,1,1,1,1,1,1,1,1,1
1,1,1,1,1,1,1,1,1,1,1,1,1,1,1,1,1,1,1,1,1,1,1,1,1,1,1,1
1,1,1,1,1,1,1,1,1,1,1,1,1,1,1,1,1,1,1,1,1,1,1,1,1,1,1,1
1,1,1,1,1,1,1,1,1,1,1,1,1,1,1,1,1,1,1,1,1,1,1,1,1,1,1,1
1,1,1,1,1,1,1,1,1,1,1,1,1,1,1,1,1,1,1,1,1,1,1,1,1,1,1,1
1,1,1,1,1,1,1,1,1,1,1,1,1,1,1,1,1,1,1,1,1,1,1,1,1,1,1,1
1,1,1,1,1,1,1,1,1,1,1,1,1,1,1,1,1,1,1,1,1,1,1,1,1,1,1,1
1,1,1,1,1,1,1,1,1,1,14,1,1,1,1,1,1,1,1,1,1,1,1,1,1,1,1,1
1,1,1,1,1,1,1,1,1,1,1,1,1,1,1,1,1,1,1,1,1,1,1,1,1,1,1,1
1,1,1,1,1,1,1,1,1,1,1,1,1,1,1,1,1,1,1,1,1,1,1,1,1,1,1,1
1,1,1,1,1,1,1,1,1,1,1,1,1,1,1,1,1,1,1,1,1,1,1,1,1,1,1,1
1,1,1,1,1,1,1,1,1,1,1,1,1,1,1,1,1,1,1,1,1,1,1,1,1,1,1,1
1,1,1,1,1,1,1,1,1,1,1,1,1,1,1,1,1,1,1,1,1,1,1,1,1,1,1,1
1,1,1,1,1,1,1,1,1,1,1,1,1,1,1,1,1,1,1,1,1,1,1,1,1,1,1,1
1,1,1,1,1,1,1,1,1,1,1,1,1,1,1,1,1,1,1,1,1,1,1,1,1,1,1,1
endlayer

layer
1,1,1,1,1,1,1,1,1,1,1,1,1,1,1,1,1,1,1,1,1,1,1,1,1,1,1,1
1,1,1,1,1,1,1,1,1,1,1,1,1,1,1,1,1,1,1,1,1,1,1,1,1,1,1,1
1,1,1,1,1,1,1,1,1,1,1,1,1,1,1,1,1,1,1,1,1,1,1,1,1,1,1,1
1,1,1,1,1,1,1,1,1,1,1,1,1,1,1,1,1,1,1,1,1,1,1,1,1,1,1,1
1,1,1,1,1,1,1,1,1,1,1,1,1,1,1,1,1,1,1,1,1,1,1,1,1,1,1,1
1,1,1,1,1,1,1,1,1,1,1,1,1,1,1,1,1,1,1,1,1,1,1,1,1,1,1,1
1,1,1,1,1,1,57,57,57,1,1,1,1,1,1,1,1,1,1,1,1,1,1,1,1,1,1,1
1,1,1,1,1,1,1,1,57,0,14,1,1,1,1,1,1,1,1,1,1,1,1,1,1,1,1,1
1,1,1,1,1,1,1,1,1,1,1,1,1,1,1,1,1,1,1,1,1,1,1,1,1,1,1,1
1,1,1,1,1,1,1,1,1,1,1,1,1,1,1,1,1,1,1,1,1,1,1,1,1,1,1,1
1,1,1,1,1,1,1,1,1,1,1,1,1,1,1,1,1,1,1,1,1,1,1,1,1,1,1,1
1,1,1,1,1,1,1,1,1,1,1,1,1,1,1,1,1,1,1,1,1,1,1,1,1,1,1,1
1,1,1,1,1,1,1,1,1,1,1,1,1,1,1,1,1,1,1,1,1,1,1,1,1,1,1,1
1,1,1,1,1,1,1,1,1,1,1,1,1,1,1,1,1,1,1,1,1,1,1,1,1,1,1,1
1,1,1,1,1,1,1,1,1,1,1,1,1,1,1,1,1,1,1,1,1,1,1,1,1,1,1,1
endlayer

layer
1,1,1,1,1,1,1,1,1,1,1,1,1,1,1,1,1,1,1,1,1,1,1,1,1,1,1,1
1,1,1,1,1,1,1,1,1,1,1,1,1,1,1,1,1,1,1,1,1,1,1,1,1,1,1,1
1,1,1,1,1,1,1,1,1,1,1,1,1,1,1,1,1,1,1,1,1,1,1,1,1,1,1,1
1,1,1,1,1,1,1,1,1,1,1,1,1,1,1,1,1,1,1,1,1,1,1,1,1,1,1,1
1,1,1,1,1,1,1,1,1,1,1,1,1,1,1,1,1,1,1,1,1,1,1,1,1,1,1,1
1,1,1,1,1,1,1,1,1,1,1,1,1,1,1,1,1,1,1,1,1,1,1,1,1,1,1,1
1,1,1,1,1,1,1,1,1,1,1,1,1,1,1,1,1,1,1,1,1,1,1,1,1,1,1,1
1,1,1,1,1,1,1,1,57,57,57,1,1,1,1,1,1,1,1,1,1,1,1,1,1,1,1,1
1,1,1,1,1,1,1,1,1,1,1,1,1,1,1,1,1,1,1,1,1,1,1,1,1,1,1,1
1,1,1,1,1,1,1,1,1,1,1,1,1,1,1,1,1,1,1,1,1,1,1,1,1,1,1,1
1,1,1,1,1,1,1,1,1,1,1,1,1,1,1,1,1,1,1,1,1,1,1,1,1,1,1,1
1,1,1,1,1,1,1,1,1,1,1,1,1,1,1,1,1,1,1,1,1,1,1,1,1,1,1,1
1,1,1,1,1,1,1,1,1,1,1,1,1,1,1,1,1,1,1,1,1,1,1,1,1,1,1,1
1,1,1,1,1,1,1,1,1,1,1,1,1,1,1,1,1,1,1,1,1,1,1,1,1,1,1,1
1,1,1,1,1,1,1,1,1,1,1,1,1,1,1,1,1,1,1,1,1,1,1,1,1,1,1,1
endlayer

