
# Created by Ruins mod version 16.2 Ingame Parser
# authoring Player: ST753M

weight=1
uniqueMinDistance=2000
embed_into_distance=12
acceptable_target_blocks=water,sand
unacceptable_target_blocks=
dimensions=31,21,21
allowable_overhang=0
max_leveling=0
leveling_buffer=0
preserve_water=0
preserve_lava=0

biomesToSpawnIn=ocean,coral_reef,kelp_forest,beach

rule1=0,100,preserveBlock
rule2=0,100,minecraft:stone-0
rule3=0,100,minecraft:planks-0
rule4=0,100,minecraft:stonebrick-0
rule5=0,100,minecraft:oak_stairs-1
rule6=0,100,minecraft:carpet-8
rule7=0,100,minecraft:oak_stairs-0
rule8=0,100,minecraft:oak_stairs-5
rule9=0,100,minecraft:ladder-2
rule10=0,100,minecraft:oak_stairs-2
rule11=0,100,minecraft:oak_stairs-6
rule12=0,100,MobSpawner:Skeleton
rule13=0,80,ChestGenHook:chests/simple_dungeon:5-3
rule14=0,80,ChestGenHook:chests/simple_dungeon:5-2
rule15=0,100,minecraft:oak_stairs-7
rule16=0,100,minecraft:sand-0
rule17=0,100,minecraft:oak_stairs-4
rule18=0,100,minecraft:dirt-0
rule19=0,100,IInventory;minecraft:chest;minecraft:gold_ingot#4#0#1+minecraft:emerald#1#0#2+minecraft:gold_nugget#2#0#5+minecraft:gold_nugget#2#0#7+minecraft:diamond#1#0#10+minecraft:potion#{Potion:"minecraft:long_poison"}#0#15+minecraft:gold_nugget#2#0#18+minecraft:gold_nugget#2#0#20+minecraft:golden_sword#1#0#22+minecraft:gold_ingot#2#0#25+minecraft:potion#{Potion:"minecraft:long_poison"}#0#26-3
rule20=0,100,minecraft:grass-0
rule21=0,100,minecraft:sandstone_stairs-7
rule22=0,100,minecraft:leaves-7
rule23=0,100,minecraft:leaves-15
rule24=0,100,minecraft:log-3
rule25=0,100,minecraft:trapdoor-8
rule26=0,100,minecraft:stained_hardened_clay-14
rule27=0,100,minecraft:oak_stairs-3
rule28=0,100,minecraft:cobblestone_wall-0
rule29=0,100,minecraft:wooden_door-1
rule30=0,100,minecraft:iron_bars-0
rule31=0,100,minecraft:wooden_door-8
rule32=0,100,minecraft:stained_hardened_clay-0
rule33=0,100,IInventory;minecraft:chest;minecraft:flint_and_steel#1#0#0+minecraft:book#2#0#2+minecraft:glowstone#4#0#6+minecraft:compass#1#0#10+minecraft:flint_and_steel#1#0#13+minecraft:cooked_fish#6#0#20+minecraft:boat#1#0#25+minecraft:bucket#1#0#26-3
rule34=0,100,minecraft:glowstone-0

layer
1,1,1,1,1,1,1,1,1,1,1,1,1,1,1,1,1,1,1,1,1
1,1,1,1,1,1,1,1,1,1,1,1,1,1,1,1,1,1,1,1,1
1,1,1,1,1,1,1,1,1,1,1,1,1,1,1,1,1,1,1,1,1
1,1,1,1,1,1,1,1,1,1,1,1,1,1,1,1,1,1,1,1,1
1,1,1,1,1,1,1,1,1,1,1,1,1,1,1,1,1,1,1,1,1
1,1,1,1,1,1,1,1,1,1,1,1,1,1,1,1,1,1,1,1,1
1,1,1,1,1,1,1,1,1,1,1,1,1,1,1,1,1,1,1,1,1
1,1,1,1,1,1,1,1,1,2,2,2,1,1,1,1,1,1,1,1,1
1,1,1,1,1,1,1,1,2,2,2,2,2,1,1,1,1,1,1,1,1
1,1,1,1,1,1,1,2,2,2,2,2,2,2,1,1,1,1,1,1,1
1,1,1,1,1,1,1,2,2,2,2,2,2,2,1,1,1,1,1,1,1
1,1,1,1,1,1,1,2,2,2,2,2,2,2,1,1,1,1,1,1,1
1,1,1,1,1,1,1,1,2,2,2,2,2,1,1,1,1,1,1,1,1
1,1,1,1,1,1,1,1,1,2,2,2,1,1,1,1,1,1,1,1,1
1,1,1,1,1,1,1,1,1,1,1,1,1,1,1,1,1,1,1,1,1
1,1,1,1,1,1,1,1,1,1,1,1,1,1,1,1,1,1,1,1,1
1,1,1,1,1,1,1,1,1,1,1,1,1,1,1,1,1,1,1,1,1
1,1,1,1,1,1,1,1,1,1,1,1,1,1,1,1,1,1,1,1,1
1,1,1,1,1,1,1,1,1,1,1,1,1,1,1,1,1,1,1,1,1
1,1,1,1,1,1,1,1,1,1,1,1,1,1,1,1,1,1,1,1,1
1,1,1,1,1,1,1,1,1,1,1,1,1,1,1,1,1,1,1,1,1
endlayer

layer
1,1,1,1,1,1,1,1,1,1,1,1,1,1,1,1,1,1,1,1,1
1,1,1,1,1,1,1,1,1,1,1,1,1,1,1,1,1,1,1,1,1
1,1,1,1,1,1,1,1,1,1,1,1,1,1,1,1,1,1,1,1,1
1,1,1,1,1,1,1,1,1,1,1,1,1,1,1,1,1,1,1,1,1
1,1,1,1,1,1,1,1,1,1,1,1,1,1,1,1,1,1,1,1,1
1,1,1,1,1,1,1,1,2,2,2,2,2,1,1,1,1,1,1,1,1
1,1,1,1,1,1,1,2,2,2,2,2,2,2,1,1,1,1,1,1,1
1,1,1,1,1,1,2,2,2,2,2,2,2,2,2,1,1,1,1,1,1
1,1,1,1,1,2,2,2,2,2,2,2,2,2,2,2,1,1,1,1,1
1,1,1,1,1,2,2,2,2,2,2,2,2,2,2,2,1,1,1,1,1
1,1,1,1,1,2,2,2,2,2,2,2,2,2,2,2,1,1,1,1,1
1,1,1,1,1,2,2,2,2,2,2,2,2,2,2,2,1,1,1,1,1
1,1,1,1,1,2,2,2,2,2,2,2,2,2,2,2,1,1,1,1,1
1,1,1,1,1,1,2,2,2,2,2,2,2,2,2,1,1,1,1,1,1
1,1,1,1,1,1,1,2,2,2,2,2,2,2,1,1,1,1,1,1,1
1,1,1,1,1,1,1,1,2,2,2,2,2,1,1,1,1,1,1,1,1
1,1,1,1,1,1,1,1,1,1,1,1,1,1,1,1,1,1,1,1,1
1,1,1,1,1,1,1,1,1,1,1,1,1,1,1,1,1,1,1,1,1
1,1,1,1,1,1,1,1,1,1,1,1,1,1,1,1,1,1,1,1,1
1,1,1,1,1,1,1,1,1,1,1,1,1,1,1,1,1,1,1,1,1
1,1,1,1,1,1,1,1,1,1,1,1,1,1,1,1,1,1,1,1,1
endlayer

layer
1,1,1,1,1,1,1,1,1,1,1,1,1,1,1,1,1,1,1,1,1
1,1,1,1,1,1,1,1,1,1,1,1,1,1,1,1,1,1,1,1,1
1,1,1,1,1,1,1,1,1,1,1,1,1,1,1,1,1,1,1,1,1
1,1,1,1,1,1,1,1,1,1,1,1,1,1,1,1,1,1,1,1,1
1,1,1,1,1,1,1,2,2,2,2,2,2,2,1,1,1,1,1,1,1
1,1,1,1,1,1,2,2,2,2,2,2,2,2,2,1,1,1,1,1,1
1,1,1,1,1,2,2,2,2,2,2,2,2,2,2,2,1,1,1,1,1
1,1,1,1,2,2,2,3,3,3,3,3,3,2,3,3,2,1,1,1,1
1,1,1,1,2,2,2,3,3,3,3,3,3,2,3,3,2,1,1,1,1
1,1,1,1,2,2,2,3,3,3,3,3,3,2,3,3,2,1,1,1,1
1,1,1,1,2,2,2,3,3,3,3,3,3,2,3,3,2,1,1,1,1
1,1,1,1,2,2,2,3,3,3,3,3,3,2,3,3,2,1,1,1,1
1,1,1,1,2,2,2,2,2,2,3,2,2,2,3,3,2,1,1,1,1
1,1,1,1,2,2,2,2,3,3,3,3,3,2,2,2,2,1,1,1,1
1,1,1,1,1,2,2,2,3,3,3,3,3,2,2,2,1,1,1,1,1
1,1,1,1,1,1,2,2,3,3,3,3,3,2,2,1,1,1,1,1,1
1,1,1,1,1,1,1,2,2,2,2,2,2,2,1,1,1,1,1,1,1
1,1,1,1,1,1,1,1,1,1,1,1,1,1,1,1,1,1,1,1,1
1,1,1,1,1,1,1,1,1,1,1,1,1,1,1,1,1,1,1,1,1
1,1,1,1,1,1,1,1,1,1,1,1,1,1,1,1,1,1,1,1,1
1,1,1,1,1,1,1,1,1,1,1,1,1,1,1,1,1,1,1,1,1
endlayer

layer
1,1,1,1,1,1,1,1,1,1,1,1,1,1,1,1,1,1,1,1,1
1,1,1,1,1,1,1,1,1,1,1,1,1,1,1,1,1,1,1,1,1
1,1,1,1,1,1,1,1,1,1,1,1,1,1,1,1,1,1,1,1,1
1,1,1,1,1,1,1,2,2,2,2,2,2,2,1,1,1,1,1,1,1
1,1,1,1,1,2,2,2,2,2,2,2,2,2,2,2,1,1,1,1,1
1,1,1,1,2,2,2,2,2,2,2,2,2,2,2,2,2,1,1,1,1
1,1,1,1,2,2,4,4,4,4,4,4,4,4,5,4,2,1,1,1,1
1,1,1,2,2,2,4,0,0,0,0,0,0,4,0,0,4,2,1,1,1
1,1,1,2,2,2,4,7,0,6,6,6,0,4,0,0,4,2,1,1,1
1,1,1,2,2,2,4,8,0,6,6,6,0,4,0,0,4,2,1,1,1
1,1,1,2,2,2,4,0,0,6,6,6,0,4,0,0,4,2,1,1,1
1,1,1,2,2,2,4,0,0,0,0,0,0,4,0,0,4,2,1,1,1
1,1,1,2,2,2,4,4,4,4,0,4,4,4,0,0,4,2,1,1,1
1,1,1,2,2,2,2,4,9,0,0,0,0,4,4,4,4,2,1,1,1
1,1,1,1,2,2,2,4,0,0,0,0,0,4,2,2,2,1,1,1,1
1,1,1,1,2,2,2,4,0,0,0,0,0,4,2,2,2,1,1,1,1
1,1,1,1,1,2,2,4,4,4,4,4,4,4,2,2,1,1,1,1,1
1,1,1,1,1,1,1,2,2,2,2,2,2,2,1,1,1,1,1,1,1
1,1,1,1,1,1,1,1,1,1,1,1,1,1,1,1,1,1,1,1,1
1,1,1,1,1,1,1,1,1,1,1,1,1,1,1,1,1,1,1,1,1
1,1,1,1,1,1,1,1,1,1,1,1,1,1,1,1,1,1,1,1,1
endlayer

layer
1,1,1,1,1,1,1,1,1,1,1,1,1,1,1,1,1,1,1,1,1
1,1,1,1,1,1,1,1,1,1,1,1,1,1,1,1,1,1,1,1,1
1,1,1,1,1,1,1,2,2,2,2,2,2,2,1,1,1,1,1,1,1
1,1,1,1,1,2,2,2,2,2,2,2,2,2,2,2,1,1,1,1,1
1,1,1,1,2,2,2,2,2,2,2,2,2,2,2,2,2,1,1,1,1
1,1,1,2,2,2,2,2,2,2,2,2,2,3,5,4,2,2,1,1,1
1,1,1,2,2,2,4,4,4,4,4,4,4,4,0,4,2,2,1,1,1
1,1,2,2,2,2,4,0,0,0,0,0,0,4,0,0,4,2,2,1,1
1,1,2,2,2,2,4,0,0,0,0,0,0,0,0,0,4,2,2,1,1
1,1,2,2,2,2,4,7,0,0,0,0,0,0,0,0,4,2,2,1,1
1,1,2,2,2,2,4,8,0,0,0,0,0,0,0,0,4,2,2,1,1
1,1,2,2,2,2,4,0,0,0,0,0,0,4,0,0,4,2,2,1,1
1,1,2,2,2,2,4,4,4,4,0,4,4,4,0,0,4,2,2,1,1
1,1,2,2,2,2,2,4,9,0,0,0,0,4,4,4,4,2,2,1,1
1,1,1,2,2,2,2,4,0,0,0,0,0,4,2,2,2,2,1,1,1
1,1,1,2,2,2,2,4,0,0,0,0,0,4,2,2,2,2,1,1,1
1,1,1,1,2,2,2,4,4,4,4,4,4,4,2,2,2,1,1,1,1
1,1,1,1,1,2,2,2,2,2,2,2,2,2,2,2,1,1,1,1,1
1,1,1,1,1,1,1,2,2,2,2,2,2,2,1,1,1,1,1,1,1
1,1,1,1,1,1,1,1,1,1,1,1,1,1,1,1,1,1,1,1,1
1,1,1,1,1,1,1,1,1,1,1,1,1,1,1,1,1,1,1,1,1
endlayer

layer
1,1,1,1,1,1,1,1,1,1,1,1,1,1,1,1,1,1,1,1,1
1,1,1,1,1,1,1,1,2,2,2,2,2,1,1,1,1,1,1,1,1
1,1,1,1,1,1,2,2,2,2,2,2,2,2,2,1,1,1,1,1,1
1,1,1,1,2,2,2,2,2,2,2,2,2,2,2,2,2,1,1,1,1
1,1,1,2,2,2,2,2,2,2,2,2,2,4,4,2,2,2,1,1,1
1,1,1,2,2,2,2,2,2,2,2,2,2,10,0,4,2,2,1,1,1
1,1,2,2,2,2,4,4,4,4,4,4,4,4,0,4,2,2,2,1,1
1,1,2,2,2,2,4,0,0,0,0,0,0,4,0,0,4,2,2,1,1
1,2,2,2,2,2,4,0,0,0,0,0,0,4,0,0,4,2,2,2,1
1,2,2,2,2,2,4,0,0,0,0,0,0,4,0,0,4,2,2,2,1
1,2,2,2,2,2,4,7,0,0,0,0,0,4,0,0,4,2,2,2,1
1,2,2,2,2,2,4,8,0,0,0,0,0,4,0,0,4,2,2,2,1
1,2,2,2,2,2,4,4,4,4,4,4,4,4,0,0,4,2,2,2,1
1,1,2,2,2,2,2,4,9,0,0,0,0,4,4,4,4,2,2,1,1
1,1,2,2,2,2,2,4,0,0,0,0,0,4,2,2,2,2,2,1,1
1,1,1,2,2,2,2,4,0,0,0,0,0,4,2,2,2,2,1,1,1
1,1,1,2,2,2,2,4,4,4,4,4,4,4,2,2,2,2,1,1,1
1,1,1,1,2,2,2,2,2,2,2,2,2,2,2,2,2,1,1,1,1
1,1,1,1,1,1,2,2,2,2,2,2,2,2,2,1,1,1,1,1,1
1,1,1,1,1,1,1,1,2,2,2,2,2,1,1,1,1,1,1,1,1
1,1,1,1,1,1,1,1,1,1,1,1,1,1,1,1,1,1,1,1,1
endlayer

layer
1,1,1,1,1,1,1,1,1,1,1,1,1,1,1,1,1,1,1,1,1
1,1,1,1,1,1,1,2,2,2,2,2,2,2,1,1,1,1,1,1,1
1,1,1,1,1,2,2,2,2,2,2,2,4,2,2,2,1,1,1,1,1
1,1,1,1,2,2,2,4,3,3,3,3,4,2,2,2,2,1,1,1,1
1,1,1,2,2,2,2,4,3,3,3,3,4,4,4,2,2,2,1,1,1
1,1,2,2,2,2,2,4,3,3,3,3,10,0,0,4,2,2,2,1,1
1,1,2,2,2,2,4,4,4,4,4,4,4,4,0,4,2,2,2,1,1
1,2,2,2,2,2,3,8,3,3,3,3,3,4,0,0,4,2,2,2,1
1,2,2,4,4,4,3,0,3,0,0,0,3,4,0,0,4,2,2,2,1
1,2,2,3,3,3,3,0,3,0,0,0,3,4,0,0,4,2,2,2,1
1,2,2,3,3,3,3,0,3,0,0,0,3,4,0,0,4,2,2,2,1
1,2,2,3,3,3,3,7,3,3,3,3,3,4,0,0,4,2,2,2,1
1,2,2,3,3,3,3,3,3,3,3,3,3,4,0,0,4,2,2,2,1
1,2,2,4,4,4,4,3,9,3,3,3,3,4,4,4,4,2,2,2,1
1,1,2,2,2,2,2,3,3,3,3,3,3,4,2,2,2,2,2,1,1
1,1,2,2,2,2,2,3,3,3,3,3,3,4,2,2,2,2,2,1,1
1,1,1,2,2,2,2,2,3,3,3,3,3,4,2,2,2,2,1,1,1
1,1,1,1,2,2,2,2,2,2,2,2,2,2,2,2,2,1,1,1,1
1,1,1,1,1,2,2,2,2,2,2,2,2,2,2,2,1,1,1,1,1
1,1,1,1,1,1,1,2,2,2,2,2,2,2,1,1,1,1,1,1,1
1,1,1,1,1,1,1,1,1,1,1,1,1,1,1,1,1,1,1,1,1
endlayer

layer
1,1,1,1,1,1,1,1,1,2,2,2,1,1,1,1,1,1,1,1,1
1,1,1,1,1,1,2,2,2,2,2,2,2,2,2,1,1,1,1,1,1
1,1,1,1,2,2,2,2,4,4,4,4,4,2,2,2,2,1,1,1,1
1,1,1,2,2,2,2,4,0,0,0,0,4,2,2,2,2,2,1,1,1
1,1,2,2,2,2,2,4,11,0,0,0,4,4,4,2,2,2,2,1,1
1,1,2,2,2,2,2,4,0,0,0,0,0,0,0,4,2,2,2,1,1
1,2,2,2,2,2,4,4,4,4,4,4,4,4,0,4,2,2,2,2,1
1,2,2,2,2,2,4,4,4,4,4,4,4,4,0,0,4,2,2,2,1
1,2,4,4,4,4,4,4,4,0,0,0,4,4,0,0,4,2,2,2,1
2,2,4,5,0,0,0,0,4,0,0,0,4,4,0,0,4,2,2,2,2
2,2,4,0,0,0,0,0,4,0,0,0,4,4,0,0,4,2,2,2,2
2,2,4,0,0,0,0,0,4,4,4,4,12,4,0,0,4,2,2,2,2
1,2,4,0,0,0,0,0,4,4,4,4,4,4,0,0,4,2,2,2,1
1,2,2,4,4,4,4,4,9,0,0,0,4,4,4,4,4,2,2,2,1
1,2,2,2,2,2,2,4,0,0,0,13,4,4,2,2,2,2,2,2,1
1,1,2,2,2,2,2,4,0,0,0,0,4,4,2,2,2,2,2,1,1
1,1,2,2,2,2,2,2,4,4,4,4,4,4,2,2,2,2,2,1,1
1,1,1,2,2,2,2,2,2,2,2,2,2,2,2,2,2,2,1,1,1
1,1,1,1,2,2,2,2,2,2,2,2,2,2,2,2,2,1,1,1,1
1,1,1,1,1,1,2,2,2,2,2,2,2,2,2,1,1,1,1,1,1
1,1,1,1,1,1,1,1,1,2,2,2,1,1,1,1,1,1,1,1,1
endlayer

layer
1,1,1,1,1,1,1,1,2,2,2,2,2,1,1,1,1,1,1,1,1
1,1,1,1,1,2,2,2,2,2,2,2,2,2,2,2,1,1,1,1,1
1,1,1,1,2,2,2,2,4,4,4,4,4,2,2,2,2,1,1,1,1
1,1,1,2,2,2,2,4,0,0,0,0,4,2,2,2,2,2,1,1,1
1,1,2,2,2,2,2,4,14,0,0,0,4,4,4,2,2,2,2,1,1
1,2,2,2,2,2,2,4,0,0,0,0,0,0,15,4,2,2,2,2,1
1,2,2,2,2,2,4,4,4,4,4,4,4,4,4,4,2,2,2,2,1
1,2,2,2,2,2,4,4,4,4,4,4,4,4,0,0,4,2,2,2,1
2,2,4,5,4,4,4,4,4,0,0,0,4,4,0,0,4,2,2,2,2
2,2,4,0,0,0,0,0,4,0,0,0,4,4,0,0,4,2,2,2,2
2,2,4,0,0,0,0,0,4,0,0,0,4,4,0,0,4,2,2,2,2
2,2,4,0,0,0,0,0,4,4,4,4,4,4,0,0,4,2,2,2,2
2,2,4,0,0,0,0,0,4,4,4,4,4,4,0,0,4,2,2,2,2
1,2,2,4,4,4,4,4,9,0,0,0,4,4,4,4,4,2,2,2,1
1,2,2,2,2,2,2,4,0,0,0,0,4,4,2,2,2,2,2,2,1
1,2,2,2,2,2,2,4,0,0,0,0,4,4,2,2,2,2,2,2,1
1,1,2,2,2,2,2,2,4,4,4,4,4,4,2,2,2,2,2,1,1
1,1,1,2,2,2,2,2,2,2,2,2,2,2,2,2,2,2,1,1,1
1,1,1,1,2,2,2,2,2,2,2,2,2,2,2,2,2,1,1,1,1
1,1,1,1,1,2,2,2,2,2,2,2,2,2,2,2,1,1,1,1,1
1,1,1,1,1,1,1,1,2,2,2,2,2,1,1,1,1,1,1,1,1
endlayer

layer
1,1,1,1,1,1,1,2,2,2,2,2,2,2,1,1,1,1,1,1,1
1,1,1,1,1,2,2,2,2,2,2,2,2,2,2,2,1,1,1,1,1
1,1,1,1,2,2,2,2,4,4,4,4,4,2,2,2,2,1,1,1,1
1,1,1,2,2,2,2,4,0,0,0,0,4,2,2,2,2,2,1,1,1
1,1,2,2,2,2,2,4,0,0,0,0,4,4,4,2,2,2,2,1,1
1,2,2,2,2,2,2,4,0,0,0,0,0,15,4,4,2,2,2,2,1
1,2,2,2,2,2,4,4,4,4,4,4,4,4,4,4,2,2,2,2,1
2,2,2,5,2,2,4,4,4,4,4,4,4,4,0,0,4,2,2,2,2
2,2,4,0,4,4,4,4,4,0,0,0,4,4,0,0,4,2,2,2,2
2,2,4,0,0,0,0,0,4,0,0,0,4,4,0,0,4,2,2,2,2
2,2,4,0,0,0,0,0,4,0,0,0,4,4,0,0,4,2,2,2,2
2,2,4,0,0,0,0,0,4,4,4,4,4,4,0,0,4,2,2,2,2
2,2,4,0,0,0,0,0,4,4,4,4,4,4,0,0,4,2,2,2,2
2,2,2,4,4,4,4,4,9,0,0,0,4,4,4,4,4,2,2,2,2
1,2,2,2,2,2,2,4,0,0,0,0,4,4,2,2,2,2,2,2,1
1,2,2,2,2,2,2,4,0,0,0,0,4,4,2,2,2,2,2,2,1
1,1,2,2,2,2,2,2,4,4,4,4,4,4,2,2,2,2,2,1,1
1,1,1,2,2,2,2,2,2,2,2,2,2,2,2,2,2,2,1,1,1
1,1,1,1,2,2,2,2,2,2,2,2,2,2,2,2,2,1,1,1,1
1,1,1,1,1,2,2,2,2,2,2,2,2,2,2,2,1,1,1,1,1
1,1,1,1,1,1,1,2,2,2,2,2,2,2,1,1,1,1,1,1,1
endlayer

layer
1,1,1,1,1,1,1,2,16,16,16,16,16,16,1,1,1,1,1,1,1
1,1,1,1,1,2,2,2,2,2,2,2,2,2,16,16,1,1,1,1,1
1,1,1,1,2,2,2,2,3,3,3,3,2,2,2,2,16,1,1,1,1
1,1,1,2,2,2,2,2,3,3,3,3,2,2,2,2,2,16,1,1,1
1,1,2,2,2,2,2,2,3,3,3,3,2,2,2,2,2,2,16,1,1
1,2,2,2,2,2,2,2,3,3,3,3,3,2,2,2,2,2,2,16,1
2,2,3,5,3,2,2,2,2,2,2,2,2,2,2,2,2,2,2,16,1
2,2,3,0,3,2,2,2,2,2,2,2,2,2,2,2,2,2,2,2,16
2,2,3,0,3,3,3,2,2,3,3,3,2,2,2,2,2,2,2,2,16
2,2,3,0,3,3,3,3,2,3,3,3,2,2,2,2,2,2,2,2,16
2,2,3,17,3,3,3,3,2,3,3,3,2,2,2,2,2,2,2,2,16
2,2,2,3,3,3,3,3,2,2,2,2,2,2,2,2,2,2,2,2,16
2,2,2,3,3,3,3,3,2,2,2,2,2,2,2,2,2,2,2,2,16
16,2,2,2,2,2,2,2,2,2,2,2,2,2,2,2,2,2,2,2,16
1,16,2,2,2,2,2,2,2,2,2,2,2,2,2,2,2,2,2,16,1
1,16,2,2,2,2,2,2,2,2,2,2,2,2,2,2,2,2,2,16,1
1,1,16,2,2,2,2,2,2,2,2,2,2,2,2,2,2,2,16,1,1
1,1,1,16,2,2,2,2,2,2,2,2,2,2,2,2,2,16,1,1,1
1,1,1,1,16,2,2,2,2,2,2,2,2,2,2,2,16,1,1,1,1
1,1,1,1,1,16,16,2,2,2,2,2,2,2,16,16,1,1,1,1,1
1,1,1,1,1,1,1,16,16,16,16,16,16,16,1,1,1,1,1,1,1
endlayer

layer
1,1,1,1,1,1,1,16,16,16,16,16,16,16,1,1,1,1,1,1,1
1,1,1,1,1,2,16,16,16,16,16,16,16,16,16,16,1,1,1,1,1
1,1,1,1,2,2,16,16,0,18,18,18,16,16,16,16,16,1,1,1,1
1,1,1,2,2,2,16,18,18,18,18,18,18,18,16,16,16,16,1,1,1
1,1,2,2,2,2,18,18,18,18,18,18,18,18,16,16,16,16,16,1,1
1,2,2,2,2,2,18,18,18,18,18,18,18,18,18,18,18,16,16,16,1
2,2,10,0,2,2,2,18,18,18,18,18,18,18,18,18,18,16,16,16,1
2,2,2,0,2,2,18,18,18,18,18,18,18,18,18,18,18,18,16,16,16
2,2,2,0,2,18,18,18,18,18,18,18,18,18,18,18,18,18,16,16,16
2,2,2,2,2,18,18,18,18,18,18,18,18,18,16,16,16,18,16,16,16
2,2,18,2,2,18,18,18,18,18,18,18,18,18,16,19,16,18,16,16,16
2,2,18,18,18,18,18,18,18,18,18,18,18,18,16,16,16,18,16,16,16
16,16,16,18,18,18,18,18,18,18,18,18,18,18,18,18,18,18,16,16,16
16,16,16,18,18,18,18,18,18,18,18,18,18,18,18,18,18,18,16,16,16
1,16,16,16,18,18,18,18,18,18,18,18,18,18,18,18,18,18,16,16,1
1,16,16,16,16,18,18,18,18,18,18,18,18,18,18,18,18,16,16,16,1
1,1,16,16,16,16,18,18,18,18,18,18,18,18,18,18,16,16,16,1,1
1,1,1,16,16,16,16,18,18,18,18,18,18,18,16,16,16,16,1,1,1
1,1,1,1,16,16,16,16,16,18,18,16,16,16,16,16,16,1,1,1,1
1,1,1,1,1,16,16,16,16,16,16,16,16,16,16,16,1,1,1,1,1
1,1,1,1,1,1,1,16,16,16,16,16,16,16,1,1,1,1,1,1,1
endlayer

layer
0,0,0,0,0,0,0,0,0,0,0,0,0,0,0,0,0,0,0,0,0
0,0,0,0,0,0,0,16,16,16,16,16,0,0,0,0,0,0,0,0,0
0,0,0,0,2,2,16,16,0,18,18,18,16,16,16,0,0,0,0,0,0
0,0,2,2,2,2,16,18,18,18,18,18,18,18,16,16,0,0,0,0,0
0,2,2,2,2,2,18,18,18,18,18,18,18,18,16,16,16,16,0,0,0
0,2,2,2,2,18,18,18,18,18,18,18,18,18,18,18,16,16,16,0,0
2,10,0,0,2,2,18,18,18,18,18,18,18,18,18,18,18,16,16,0,0
2,3,2,0,2,18,18,18,18,18,18,18,18,18,18,18,18,18,16,16,0
2,2,2,2,18,18,18,18,18,18,18,18,18,20,18,18,18,18,16,16,16
2,2,2,2,2,18,18,18,18,18,18,18,18,18,16,16,16,18,16,16,16
2,2,18,2,18,18,18,18,18,18,18,18,18,18,16,16,16,18,16,16,16
2,20,18,18,18,18,18,18,18,18,18,18,18,18,16,16,16,18,16,16,0
0,16,20,18,18,18,18,18,18,18,18,18,18,18,18,18,18,18,16,16,0
0,0,20,18,18,18,18,18,18,18,18,18,18,18,18,18,18,18,16,16,0
0,0,16,20,18,18,18,18,18,18,18,18,18,18,18,18,18,18,16,0,0
0,0,0,16,16,18,18,18,18,18,18,18,18,18,18,18,18,16,16,0,0
0,0,0,0,16,16,18,18,18,18,18,18,18,18,18,18,16,16,0,0,0
0,0,0,0,16,16,16,18,18,18,18,18,18,18,16,16,16,0,0,0,0
0,0,0,0,0,16,16,16,16,18,18,16,16,16,16,0,0,0,0,0,0
0,0,0,0,0,0,0,16,16,16,16,16,16,0,0,0,0,0,0,0,0
0,0,0,0,0,0,0,0,0,16,16,0,0,0,0,0,0,0,0,0,0
endlayer

layer
0,0,0,0,0,0,0,0,0,0,0,0,0,0,0,0,0,0,0,0,0
0,0,0,0,0,0,0,0,0,0,0,0,0,0,0,0,0,0,0,0,0
0,0,0,2,2,2,0,0,0,20,16,16,0,0,0,0,0,0,0,0,0
0,2,2,2,2,2,0,20,20,20,20,16,16,16,0,0,0,0,0,0,0
2,2,2,2,2,2,2,20,18,18,20,18,16,16,0,0,0,0,0,0,0
2,2,2,2,2,2,2,18,18,18,18,20,16,16,16,16,16,0,0,0,0
2,0,0,0,2,2,2,18,18,18,18,18,20,16,16,16,16,0,0,0,0
2,7,2,2,2,18,18,18,18,18,18,18,20,16,16,16,16,16,0,0,0
2,2,2,2,18,18,18,18,18,18,18,18,18,21,16,16,16,21,0,0,0
2,2,2,2,18,18,18,18,18,18,18,18,18,20,21,16,21,16,16,0,0
2,2,2,18,18,18,18,18,18,18,18,18,20,20,16,21,16,16,16,16,0
0,0,20,18,18,18,18,18,18,18,18,18,20,20,21,16,21,16,16,16,0
0,0,0,20,18,18,18,18,18,18,18,20,20,21,16,16,16,21,16,16,0
0,0,0,20,18,18,18,18,18,18,20,20,20,16,16,16,16,16,16,0,0
0,0,0,0,20,18,18,18,20,20,20,20,16,16,16,16,16,16,0,0,0
0,0,0,0,0,20,20,20,20,20,20,20,16,16,16,16,16,0,0,0,0
0,0,0,0,0,0,20,20,20,20,20,16,16,16,16,16,0,0,0,0,0
0,0,0,0,0,0,0,20,20,20,16,16,16,16,0,0,0,0,0,0,0
0,0,0,0,0,0,0,0,0,16,16,0,0,0,0,0,0,0,0,0,0
0,0,0,0,0,0,0,0,0,0,0,0,0,0,0,0,0,0,0,0,0
0,0,0,0,0,0,0,0,0,0,0,0,0,0,0,0,0,0,0,0,0
endlayer

layer
0,0,0,0,0,0,0,0,0,0,0,0,0,0,0,0,0,0,0,0,0
0,0,0,0,0,0,0,0,0,0,0,0,0,0,0,0,0,0,0,0,0
0,0,2,2,2,0,0,0,0,0,22,22,22,0,0,0,0,0,0,0,0
0,2,2,2,2,2,0,0,0,23,23,22,22,22,0,0,0,0,0,0,0
2,2,2,2,2,2,2,0,20,20,22,24,22,22,0,0,0,0,0,0,0
2,2,2,2,2,2,2,2,20,20,20,22,22,22,0,0,0,0,0,0,0
2,0,0,2,2,2,2,18,18,20,20,20,22,0,0,0,0,0,0,0,0
2,0,2,2,2,2,18,18,18,20,20,20,0,0,0,0,0,0,0,0,0
2,7,2,2,2,2,18,18,20,20,20,20,20,0,0,0,0,0,0,0,0
2,2,2,2,2,18,20,20,20,20,20,20,20,0,0,0,0,0,0,0,0
0,2,2,18,18,20,20,20,20,20,20,20,0,0,0,0,0,0,0,0,0
0,0,0,20,20,20,20,20,20,20,20,20,0,0,0,0,0,0,0,0,0
0,0,0,0,20,20,20,20,20,20,20,0,0,0,0,0,0,0,0,0,0
0,0,0,0,20,20,20,18,20,20,0,0,0,0,0,0,0,0,0,0,0
0,0,0,0,0,20,20,20,0,0,0,0,0,0,0,0,0,0,0,0,0
0,0,0,0,0,0,0,0,0,0,0,0,0,0,0,0,0,0,0,0,0
0,0,0,0,0,0,0,0,0,0,0,0,0,24,0,0,0,0,0,0,0
0,0,0,0,0,0,0,0,0,0,0,0,0,0,0,0,0,0,0,0,0
0,0,0,0,0,0,0,0,0,0,0,0,0,0,0,0,0,0,0,0,0
0,0,0,0,0,0,0,0,0,0,0,0,0,0,0,0,0,0,0,0,0
0,0,0,0,0,0,0,0,0,0,0,0,0,0,0,0,0,0,0,0,0
endlayer

layer
0,0,0,0,0,0,0,0,0,0,0,0,0,0,0,0,0,0,0,0,0
0,0,0,0,0,0,0,0,0,0,0,0,0,0,0,0,0,0,0,0,0
0,0,0,0,0,0,0,0,0,0,0,0,0,0,0,0,0,0,0,0,0
0,0,2,2,2,0,0,0,0,0,0,22,0,0,0,0,0,0,0,0,0
0,2,2,2,2,2,0,0,0,0,22,22,22,0,0,0,0,0,0,0,0
2,2,3,3,3,2,2,0,0,0,0,22,0,0,0,0,0,0,0,0,0
2,0,3,3,3,3,2,2,2,0,0,0,0,0,0,0,0,0,0,0,0
2,25,3,3,3,3,3,2,2,0,0,0,0,0,0,0,0,0,0,0,0
2,25,3,3,3,3,2,2,0,0,0,0,0,0,0,0,0,0,0,0,0
0,2,3,3,3,2,0,0,0,0,0,0,0,0,0,0,0,0,0,0,0
0,0,2,2,2,0,0,0,0,0,0,0,0,0,0,0,0,0,0,0,0
0,0,0,0,0,0,22,23,23,0,0,0,0,0,0,0,0,0,0,0,0
0,0,0,0,0,23,23,23,23,23,0,0,0,0,0,0,0,0,0,0,0
0,0,0,0,0,23,23,24,23,23,0,0,0,0,0,0,0,0,0,0,0
0,0,0,0,0,23,23,23,23,23,0,0,0,0,0,0,0,0,0,0,0
0,0,0,0,0,0,23,23,23,0,0,0,0,0,0,0,0,0,0,0,0
0,0,0,0,0,0,0,0,0,0,0,0,0,24,0,0,0,0,0,0,0
0,0,0,0,0,0,0,0,0,0,0,0,0,0,0,0,0,0,0,0,0
0,0,0,0,0,0,0,0,0,0,0,0,0,0,0,0,0,0,0,0,0
0,0,0,0,0,0,0,0,0,0,0,0,0,0,0,0,0,0,0,0,0
0,0,0,0,0,0,0,0,0,0,0,0,0,0,0,0,0,0,0,0,0
endlayer

layer
0,0,0,0,0,0,0,0,0,0,0,0,0,0,0,0,0,0,0,0,0
0,0,0,0,0,0,0,0,0,0,0,0,0,0,0,0,0,0,0,0,0
0,0,0,0,0,0,0,0,0,0,0,0,0,0,0,0,0,0,0,0,0
0,0,0,0,0,0,0,0,0,0,0,0,0,0,0,0,0,0,0,0,0
0,0,26,26,26,0,0,0,0,0,0,0,0,0,0,0,0,0,0,0,0
0,26,10,28,27,26,0,0,0,0,0,0,0,0,0,0,0,0,0,0,0
26,3,9,0,0,0,26,0,0,0,0,0,0,0,0,0,0,0,0,0,0
26,6,0,28,0,0,29,0,0,0,0,0,0,0,0,0,0,0,0,0,0
26,6,0,0,0,0,26,0,0,0,0,0,0,0,0,0,0,0,0,0,0
0,26,10,28,27,26,0,0,0,0,0,0,0,0,0,0,0,0,0,0,0
0,0,26,26,26,0,0,0,0,0,0,0,0,0,0,0,0,0,0,0,0
0,0,0,0,0,0,0,0,0,0,0,0,0,0,0,0,0,0,0,0,0
0,0,0,0,0,0,0,23,0,0,0,0,0,0,0,0,0,0,0,0,0
0,0,0,0,0,0,23,23,23,0,0,0,0,0,0,0,0,0,0,0,0
0,0,0,0,0,0,0,23,0,0,0,0,0,0,0,0,0,0,0,0,0
0,0,0,0,0,0,0,0,0,0,0,0,0,0,0,0,0,0,0,0,0
0,0,0,0,0,0,0,0,0,0,0,0,0,24,0,0,0,0,0,0,0
0,0,0,0,0,0,0,0,0,0,0,0,0,0,0,0,0,0,0,0,0
0,0,0,0,0,0,0,0,0,0,0,0,0,0,0,0,0,0,0,0,0
0,0,0,0,0,0,0,0,0,0,0,0,0,0,0,0,0,0,0,0,0
0,0,0,0,0,0,0,0,0,0,0,0,0,0,0,0,0,0,0,0,0
endlayer

layer
0,0,0,0,0,0,0,0,0,0,0,0,0,0,0,0,0,0,0,0,0
0,0,0,0,0,0,0,0,0,0,0,0,0,0,0,0,0,0,0,0,0
0,0,0,0,0,0,0,0,0,0,0,0,0,0,0,0,0,0,0,0,0
0,0,0,0,0,0,0,0,0,0,0,0,0,0,0,0,0,0,0,0,0
0,0,26,30,26,0,0,0,0,0,0,0,0,0,0,0,0,0,0,0,0
0,26,0,6,0,26,0,0,0,0,0,0,0,0,0,0,0,0,0,0,0
26,3,9,0,0,0,26,0,0,0,0,0,0,0,0,0,0,0,0,0,0
30,0,0,28,0,0,31,0,0,0,0,0,0,0,0,0,0,0,0,0,0
26,0,0,0,0,0,26,0,0,0,0,0,0,0,0,0,0,0,0,0,0
0,26,0,6,0,26,0,0,0,0,0,0,0,0,0,0,0,0,0,0,0
0,0,26,30,26,0,0,0,0,0,0,0,0,0,0,0,0,0,0,0,0
0,0,0,0,0,0,0,0,0,0,0,0,0,0,0,0,0,0,0,0,0
0,0,0,0,0,0,0,0,0,0,0,0,0,0,0,0,0,0,0,0,0
0,0,0,0,0,0,0,0,0,0,0,0,0,0,0,0,0,0,0,0,0
0,0,0,0,0,0,0,0,0,0,0,0,0,0,0,0,0,0,0,0,0
0,0,0,0,0,0,0,0,0,0,0,0,0,0,0,0,0,0,0,0,0
0,0,0,0,0,0,0,0,0,0,0,0,0,24,0,0,0,0,0,0,0
0,0,0,0,0,0,0,0,0,0,0,0,0,0,0,0,0,0,0,0,0
0,0,0,0,0,0,0,0,0,0,0,0,0,0,0,0,0,0,0,0,0
0,0,0,0,0,0,0,0,0,0,0,0,0,0,0,0,0,0,0,0,0
0,0,0,0,0,0,0,0,0,0,0,0,0,0,0,0,0,0,0,0,0
endlayer

layer
0,0,0,0,0,0,0,0,0,0,0,0,0,0,0,0,0,0,0,0,0
0,0,0,0,0,0,0,0,0,0,0,0,0,0,0,0,0,0,0,0,0
0,0,0,0,0,0,0,0,0,0,0,0,0,0,0,0,0,0,0,0,0
0,0,0,0,0,0,0,0,0,0,0,0,0,0,0,0,0,0,0,0,0
0,0,26,26,26,0,0,0,0,0,0,0,0,0,0,0,0,0,0,0,0
0,32,0,0,0,32,0,0,0,0,0,0,0,0,0,0,0,0,0,0,0
26,3,9,0,0,0,26,0,0,0,0,0,0,0,0,0,0,0,0,0,0
26,0,0,28,0,0,26,0,0,0,0,0,0,0,0,0,0,0,0,0,0
26,0,0,0,0,0,26,0,0,0,0,0,0,0,0,0,0,0,0,0,0
0,32,0,0,0,32,0,0,0,0,0,0,0,0,0,0,0,0,0,0,0
0,0,26,26,26,0,0,0,0,0,0,0,0,0,0,0,0,0,0,0,0
0,0,0,0,0,0,0,0,0,0,0,0,0,0,0,0,0,0,0,0,0
0,0,0,0,0,0,0,0,0,0,0,0,0,0,0,0,0,0,0,0,0
0,0,0,0,0,0,0,0,0,0,0,0,0,0,0,0,0,0,0,0,0
0,0,0,0,0,0,0,0,0,0,0,0,0,0,0,0,0,0,0,0,0
0,0,0,0,0,0,0,0,0,0,0,0,0,0,0,0,0,0,0,0,0
0,0,0,0,0,0,0,0,0,0,0,0,0,0,0,0,0,0,0,0,0
0,0,0,0,0,0,0,0,0,0,0,0,0,24,0,0,0,0,0,0,0
0,0,0,0,0,0,0,0,0,0,0,0,0,0,0,0,0,0,0,0,0
0,0,0,0,0,0,0,0,0,0,0,0,0,0,0,0,0,0,0,0,0
0,0,0,0,0,0,0,0,0,0,0,0,0,0,0,0,0,0,0,0,0
endlayer

layer
0,0,0,0,0,0,0,0,0,0,0,0,0,0,0,0,0,0,0,0,0
0,0,0,0,0,0,0,0,0,0,0,0,0,0,0,0,0,0,0,0,0
0,0,0,0,0,0,0,0,0,0,0,0,0,0,0,0,0,0,0,0,0
0,0,0,0,0,0,0,0,0,0,0,0,0,0,0,0,0,0,0,0,0
0,0,32,32,32,0,0,0,0,0,0,0,0,0,0,0,0,0,0,0,0
0,32,0,0,0,32,0,0,0,0,0,0,0,0,0,0,0,0,0,0,0
32,3,9,0,0,0,32,0,0,0,0,0,0,0,0,0,0,0,0,0,0
32,0,0,28,0,0,32,0,0,0,0,0,0,0,0,0,0,0,0,0,0
32,0,0,0,0,0,32,0,0,0,0,0,0,0,0,0,0,0,0,0,0
0,32,0,0,0,32,0,0,0,0,0,0,0,0,0,0,0,0,0,0,0
0,0,32,32,32,0,0,0,0,0,0,0,0,0,0,0,0,0,0,0,0
0,0,0,0,0,0,0,0,0,0,0,0,0,0,0,0,0,0,0,0,0
0,0,0,0,0,0,0,0,0,0,0,0,0,0,0,0,0,0,0,0,0
0,0,0,0,0,0,0,0,0,0,0,0,0,0,0,0,0,0,0,0,0
0,0,0,0,0,0,0,0,0,0,0,0,0,22,0,0,0,0,0,0,0
0,0,0,0,0,0,0,0,0,0,0,0,0,0,0,0,0,0,0,0,0
0,0,0,0,0,0,0,0,0,0,0,0,0,0,0,0,0,0,0,0,0
0,0,0,0,0,0,0,0,0,0,22,0,0,24,0,0,22,0,0,0,0
0,0,0,0,0,0,0,0,0,0,0,0,0,0,0,0,0,0,0,0,0
0,0,0,0,0,0,0,0,0,0,0,0,0,0,0,0,0,0,0,0,0
0,0,0,0,0,0,0,0,0,0,0,0,0,22,0,0,0,0,0,0,0
endlayer

layer
0,0,0,0,0,0,0,0,0,0,0,0,0,0,0,0,0,0,0,0,0
0,0,0,0,0,0,0,0,0,0,0,0,0,0,0,0,0,0,0,0,0
0,0,0,0,0,0,0,0,0,0,0,0,0,0,0,0,0,0,0,0,0
0,0,0,0,0,0,0,0,0,0,0,0,0,0,0,0,0,0,0,0,0
0,0,32,32,32,0,0,0,0,0,0,0,0,0,0,0,0,0,0,0,0
0,32,3,3,3,32,0,0,0,0,0,0,0,0,0,0,0,0,0,0,0
32,3,9,3,3,3,32,0,0,0,0,0,0,0,0,0,0,0,0,0,0
32,3,3,28,3,3,32,0,0,0,0,0,0,0,0,0,0,0,0,0,0
32,3,3,3,3,3,32,0,0,0,0,0,0,0,0,0,0,0,0,0,0
0,32,3,3,3,32,0,0,0,0,0,0,0,0,0,0,0,0,0,0,0
0,0,32,32,32,0,0,0,0,0,0,0,0,0,0,0,0,0,0,0,0
0,0,0,0,0,0,0,0,0,0,0,0,0,0,0,0,0,0,0,0,0
0,0,0,0,0,0,0,0,0,0,0,0,0,0,0,0,0,0,0,0,0
0,0,0,0,0,0,0,0,0,0,0,0,0,0,0,0,0,0,0,0,0
0,0,0,0,0,0,0,0,0,0,22,0,0,22,0,23,22,0,0,0,0
0,0,0,0,0,0,0,0,0,0,22,0,0,22,0,0,0,0,0,0,0
0,0,0,0,0,0,0,0,0,0,0,0,0,0,0,0,0,0,0,0,0
0,0,0,0,0,0,0,0,0,0,22,22,0,24,0,23,23,0,0,0,0
0,0,0,0,0,0,0,0,0,0,0,0,0,0,0,0,0,0,0,0,0
0,0,0,0,0,0,0,0,0,0,0,0,0,23,0,0,22,0,0,0,0
0,0,0,0,0,0,0,0,0,0,22,22,0,23,0,0,22,0,0,0,0
endlayer

layer
0,0,0,0,0,0,0,0,0,0,0,0,0,0,0,0,0,0,0,0,0
0,0,0,0,0,0,0,0,0,0,0,0,0,0,0,0,0,0,0,0,0
0,0,0,0,0,0,0,0,0,0,0,0,0,0,0,0,0,0,0,0,0
0,0,0,0,0,0,0,0,0,0,0,0,0,0,0,0,0,0,0,0,0
0,0,0,0,0,0,0,0,0,0,0,0,0,0,0,0,0,0,0,0,0
0,0,26,26,26,0,0,0,0,0,0,0,0,0,0,0,0,0,0,0,0
0,26,9,0,0,26,0,0,0,0,0,0,0,0,0,0,0,0,0,0,0
0,26,0,28,0,26,0,0,0,0,0,0,0,0,0,0,0,0,0,0,0
0,26,0,0,0,26,0,0,0,0,0,0,0,0,0,0,0,0,0,0,0
0,0,26,26,26,0,0,0,0,0,0,0,0,0,0,0,0,0,0,0,0
0,0,0,0,0,0,0,0,0,0,0,0,0,0,0,0,0,0,0,0,0
0,0,0,0,0,0,0,0,0,0,0,0,0,0,0,0,0,0,0,0,0
0,0,0,0,0,0,0,0,0,0,0,0,0,0,0,0,0,0,0,0,0
0,0,0,0,0,0,0,0,0,0,0,0,0,0,0,0,0,0,0,0,0
0,0,0,0,0,0,0,0,0,0,0,0,0,0,0,23,0,0,0,0,0
0,0,0,0,0,0,0,0,0,0,22,22,0,22,23,23,0,0,0,0,0
0,0,0,0,0,0,0,0,0,0,0,22,23,23,23,0,0,0,0,0,0
0,0,0,0,0,0,0,0,0,0,0,22,23,23,23,23,0,0,0,0,0
0,0,0,0,0,0,0,0,0,0,0,0,23,23,23,22,0,0,0,0,0
0,0,0,0,0,0,0,0,0,0,0,22,23,23,0,22,22,0,0,0,0
0,0,0,0,0,0,0,0,0,0,0,22,0,0,0,0,0,0,0,0,0
endlayer

layer
0,0,0,0,0,0,0,0,0,0,0,0,0,0,0,0,0,0,0,0,0
0,0,0,0,0,0,0,0,0,0,0,0,0,0,0,0,0,0,0,0,0
0,0,0,0,0,0,0,0,0,0,0,0,0,0,0,0,0,0,0,0,0
0,0,0,0,0,0,0,0,0,0,0,0,0,0,0,0,0,0,0,0,0
0,0,0,0,0,0,0,0,0,0,0,0,0,0,0,0,0,0,0,0,0
0,0,32,32,32,0,0,0,0,0,0,0,0,0,0,0,0,0,0,0,0
0,32,9,0,0,32,0,0,0,0,0,0,0,0,0,0,0,0,0,0,0
0,32,0,28,0,32,0,0,0,0,0,0,0,0,0,0,0,0,0,0,0
0,32,0,0,0,32,0,0,0,0,0,0,0,0,0,0,0,0,0,0,0
0,0,32,32,32,0,0,0,0,0,0,0,0,0,0,0,0,0,0,0,0
0,0,0,0,0,0,0,0,0,0,0,0,0,0,0,0,0,0,0,0,0
0,0,0,0,0,0,0,0,0,0,0,0,0,0,0,0,0,0,0,0,0
0,0,0,0,0,0,0,0,0,0,0,0,0,0,0,0,0,0,0,0,0
0,0,0,0,0,0,0,0,0,0,0,0,0,0,0,0,0,0,0,0,0
0,0,0,0,0,0,0,0,0,0,0,0,0,0,0,0,0,0,0,0,0
0,0,0,0,0,0,0,0,0,0,0,0,22,0,0,0,0,0,0,0,0
0,0,0,0,0,0,0,0,0,0,0,0,22,0,22,22,0,0,0,0,0
0,0,0,0,0,0,0,0,0,0,0,0,0,22,0,0,0,0,0,0,0
0,0,0,0,0,0,0,0,0,0,0,22,22,0,22,0,0,0,0,0,0
0,0,0,0,0,0,0,0,0,0,0,0,0,0,22,0,0,0,0,0,0
0,0,0,0,0,0,0,0,0,0,0,0,0,0,0,0,0,0,0,0,0
endlayer

layer
0,0,0,0,0,0,0,0,0,0,0,0,0,0,0,0,0,0,0,0,0
0,0,0,0,0,0,0,0,0,0,0,0,0,0,0,0,0,0,0,0,0
0,0,0,0,0,0,0,0,0,0,0,0,0,0,0,0,0,0,0,0,0
0,0,0,0,0,0,0,0,0,0,0,0,0,0,0,0,0,0,0,0,0
0,0,0,0,0,0,0,0,0,0,0,0,0,0,0,0,0,0,0,0,0
0,0,32,30,32,0,0,0,0,0,0,0,0,0,0,0,0,0,0,0,0
0,32,9,0,0,32,0,0,0,0,0,0,0,0,0,0,0,0,0,0,0
0,30,0,28,0,30,0,0,0,0,0,0,0,0,0,0,0,0,0,0,0
0,32,0,0,0,32,0,0,0,0,0,0,0,0,0,0,0,0,0,0,0
0,0,32,30,32,0,0,0,0,0,0,0,0,0,0,0,0,0,0,0,0
0,0,0,0,0,0,0,0,0,0,0,0,0,0,0,0,0,0,0,0,0
0,0,0,0,0,0,0,0,0,0,0,0,0,0,0,0,0,0,0,0,0
0,0,0,0,0,0,0,0,0,0,0,0,0,0,0,0,0,0,0,0,0
0,0,0,0,0,0,0,0,0,0,0,0,0,0,0,0,0,0,0,0,0
0,0,0,0,0,0,0,0,0,0,0,0,22,0,0,0,0,0,0,0,0
0,0,0,0,0,0,0,0,0,0,0,0,22,0,0,0,0,0,0,0,0
0,0,0,0,0,0,0,0,0,0,0,0,0,0,0,22,22,0,0,0,0
0,0,0,0,0,0,0,0,0,0,0,0,0,22,0,0,0,0,0,0,0
0,0,0,0,0,0,0,0,0,0,22,22,0,0,0,0,0,0,0,0,0
0,0,0,0,0,0,0,0,0,0,0,0,0,0,22,0,0,0,0,0,0
0,0,0,0,0,0,0,0,0,0,0,0,0,0,22,0,0,0,0,0,0
endlayer

layer
0,0,0,0,0,0,0,0,0,0,0,0,0,0,0,0,0,0,0,0,0
0,0,0,0,0,0,0,0,0,0,0,0,0,0,0,0,0,0,0,0,0
0,0,0,0,0,0,0,0,0,0,0,0,0,0,0,0,0,0,0,0,0
0,0,0,0,0,0,0,0,0,0,0,0,0,0,0,0,0,0,0,0,0
0,0,0,0,0,0,0,0,0,0,0,0,0,0,0,0,0,0,0,0,0
0,0,32,32,32,0,0,0,0,0,0,0,0,0,0,0,0,0,0,0,0
0,32,9,0,0,32,0,0,0,0,0,0,0,0,0,0,0,0,0,0,0
0,32,0,28,0,32,0,0,0,0,0,0,0,0,0,0,0,0,0,0,0
0,32,0,0,0,32,0,0,0,0,0,0,0,0,0,0,0,0,0,0,0
0,0,32,32,32,0,0,0,0,0,0,0,0,0,0,0,0,0,0,0,0
0,0,0,0,0,0,0,0,0,0,0,0,0,0,0,0,0,0,0,0,0
0,0,0,0,0,0,0,0,0,0,0,0,0,0,0,0,0,0,0,0,0
0,0,0,0,0,0,0,0,0,0,0,0,0,0,0,0,0,0,0,0,0
0,0,0,0,0,0,0,0,0,0,0,0,0,0,0,0,0,0,0,0,0
0,0,0,0,0,0,0,0,0,0,0,0,0,0,0,0,0,0,0,0,0
0,0,0,0,0,0,0,0,0,0,0,0,0,0,0,0,0,0,0,0,0
0,0,0,0,0,0,0,0,0,0,0,0,0,0,0,0,0,0,0,0,0
0,0,0,0,0,0,0,0,0,0,0,0,0,22,0,0,0,0,0,0,0
0,0,0,0,0,0,0,0,0,0,0,0,0,0,0,0,0,0,0,0,0
0,0,0,0,0,0,0,0,0,0,0,0,0,0,0,0,0,0,0,0,0
0,0,0,0,0,0,0,0,0,0,0,0,0,0,0,0,0,0,0,0,0
endlayer

layer
0,0,0,0,0,0,0,0,0,0,0,0,0,0,0,0,0,0,0,0,0
0,0,0,0,0,0,0,0,0,0,0,0,0,0,0,0,0,0,0,0,0
0,0,0,0,0,0,0,0,0,0,0,0,0,0,0,0,0,0,0,0,0
0,0,0,0,0,0,0,0,0,0,0,0,0,0,0,0,0,0,0,0,0
0,0,26,26,26,0,0,0,0,0,0,0,0,0,0,0,0,0,0,0,0
0,26,3,3,3,26,0,0,0,0,0,0,0,0,0,0,0,0,0,0,0
26,3,9,3,3,3,26,0,0,0,0,0,0,0,0,0,0,0,0,0,0
26,3,3,28,3,3,26,0,0,0,0,0,0,0,0,0,0,0,0,0,0
26,3,3,3,3,3,26,0,0,0,0,0,0,0,0,0,0,0,0,0,0
0,26,3,3,3,26,0,0,0,0,0,0,0,0,0,0,0,0,0,0,0
0,0,26,26,26,0,0,0,0,0,0,0,0,0,0,0,0,0,0,0,0
0,0,0,0,0,0,0,0,0,0,0,0,0,0,0,0,0,0,0,0,0
0,0,0,0,0,0,0,0,0,0,0,0,0,0,0,0,0,0,0,0,0
0,0,0,0,0,0,0,0,0,0,0,0,0,0,0,0,0,0,0,0,0
0,0,0,0,0,0,0,0,0,0,0,0,0,0,0,0,0,0,0,0,0
0,0,0,0,0,0,0,0,0,0,0,0,0,0,0,0,0,0,0,0,0
0,0,0,0,0,0,0,0,0,0,0,0,0,0,0,0,0,0,0,0,0
0,0,0,0,0,0,0,0,0,0,0,0,0,0,0,0,0,0,0,0,0
0,0,0,0,0,0,0,0,0,0,0,0,0,0,0,0,0,0,0,0,0
0,0,0,0,0,0,0,0,0,0,0,0,0,0,0,0,0,0,0,0,0
0,0,0,0,0,0,0,0,0,0,0,0,0,0,0,0,0,0,0,0,0
endlayer

layer
0,0,0,0,0,0,0,0,0,0,0,0,0,0,0,0,0,0,0,0,0
0,0,0,0,0,0,0,0,0,0,0,0,0,0,0,0,0,0,0,0,0
0,0,0,0,0,0,0,0,0,0,0,0,0,0,0,0,0,0,0,0,0
0,0,0,0,0,0,0,0,0,0,0,0,0,0,0,0,0,0,0,0,0
0,0,26,26,26,0,0,0,0,0,0,0,0,0,0,0,0,0,0,0,0
0,26,0,0,0,26,0,0,0,0,0,0,0,0,0,0,0,0,0,0,0
26,0,0,0,0,0,26,0,0,0,0,0,0,0,0,0,0,0,0,0,0
26,0,0,28,0,0,26,0,0,0,0,0,0,0,0,0,0,0,0,0,0
26,0,0,0,0,33,26,0,0,0,0,0,0,0,0,0,0,0,0,0,0
0,26,0,0,0,26,0,0,0,0,0,0,0,0,0,0,0,0,0,0,0
0,0,26,26,26,0,0,0,0,0,0,0,0,0,0,0,0,0,0,0,0
0,0,0,0,0,0,0,0,0,0,0,0,0,0,0,0,0,0,0,0,0
0,0,0,0,0,0,0,0,0,0,0,0,0,0,0,0,0,0,0,0,0
0,0,0,0,0,0,0,0,0,0,0,0,0,0,0,0,0,0,0,0,0
0,0,0,0,0,0,0,0,0,0,0,0,0,0,0,0,0,0,0,0,0
0,0,0,0,0,0,0,0,0,0,0,0,0,0,0,0,0,0,0,0,0
0,0,0,0,0,0,0,0,0,0,0,0,0,0,0,0,0,0,0,0,0
0,0,0,0,0,0,0,0,0,0,0,0,0,0,0,0,0,0,0,0,0
0,0,0,0,0,0,0,0,0,0,0,0,0,0,0,0,0,0,0,0,0
0,0,0,0,0,0,0,0,0,0,0,0,0,0,0,0,0,0,0,0,0
0,0,0,0,0,0,0,0,0,0,0,0,0,0,0,0,0,0,0,0,0
endlayer

layer
0,0,0,0,0,0,0,0,0,0,0,0,0,0,0,0,0,0,0,0,0
0,0,0,0,0,0,0,0,0,0,0,0,0,0,0,0,0,0,0,0,0
0,0,0,0,0,0,0,0,0,0,0,0,0,0,0,0,0,0,0,0,0
0,0,0,0,0,0,0,0,0,0,0,0,0,0,0,0,0,0,0,0,0
0,0,28,0,28,0,0,0,0,0,0,0,0,0,0,0,0,0,0,0,0
0,0,0,0,0,0,0,0,0,0,0,0,0,0,0,0,0,0,0,0,0
28,0,0,0,0,0,28,0,0,0,0,0,0,0,0,0,0,0,0,0,0
0,0,0,34,0,0,0,0,0,0,0,0,0,0,0,0,0,0,0,0,0
28,0,0,0,0,0,28,0,0,0,0,0,0,0,0,0,0,0,0,0,0
0,0,0,0,0,0,0,0,0,0,0,0,0,0,0,0,0,0,0,0,0
0,0,28,0,28,0,0,0,0,0,0,0,0,0,0,0,0,0,0,0,0
0,0,0,0,0,0,0,0,0,0,0,0,0,0,0,0,0,0,0,0,0
0,0,0,0,0,0,0,0,0,0,0,0,0,0,0,0,0,0,0,0,0
0,0,0,0,0,0,0,0,0,0,0,0,0,0,0,0,0,0,0,0,0
0,0,0,0,0,0,0,0,0,0,0,0,0,0,0,0,0,0,0,0,0
0,0,0,0,0,0,0,0,0,0,0,0,0,0,0,0,0,0,0,0,0
0,0,0,0,0,0,0,0,0,0,0,0,0,0,0,0,0,0,0,0,0
0,0,0,0,0,0,0,0,0,0,0,0,0,0,0,0,0,0,0,0,0
0,0,0,0,0,0,0,0,0,0,0,0,0,0,0,0,0,0,0,0,0
0,0,0,0,0,0,0,0,0,0,0,0,0,0,0,0,0,0,0,0,0
0,0,0,0,0,0,0,0,0,0,0,0,0,0,0,0,0,0,0,0,0
endlayer

layer
0,0,0,0,0,0,0,0,0,0,0,0,0,0,0,0,0,0,0,0,0
0,0,0,0,0,0,0,0,0,0,0,0,0,0,0,0,0,0,0,0,0
0,0,0,0,0,0,0,0,0,0,0,0,0,0,0,0,0,0,0,0,0
0,0,0,0,0,0,0,0,0,0,0,0,0,0,0,0,0,0,0,0,0
0,0,28,0,28,0,0,0,0,0,0,0,0,0,0,0,0,0,0,0,0
0,0,0,0,0,0,0,0,0,0,0,0,0,0,0,0,0,0,0,0,0
28,0,0,34,0,0,28,0,0,0,0,0,0,0,0,0,0,0,0,0,0
0,0,34,12,34,0,0,0,0,0,0,0,0,0,0,0,0,0,0,0,0
28,0,0,34,0,0,28,0,0,0,0,0,0,0,0,0,0,0,0,0,0
0,0,0,0,0,0,0,0,0,0,0,0,0,0,0,0,0,0,0,0,0
0,0,28,0,28,0,0,0,0,0,0,0,0,0,0,0,0,0,0,0,0
0,0,0,0,0,0,0,0,0,0,0,0,0,0,0,0,0,0,0,0,0
0,0,0,0,0,0,0,0,0,0,0,0,0,0,0,0,0,0,0,0,0
0,0,0,0,0,0,0,0,0,0,0,0,0,0,0,0,0,0,0,0,0
0,0,0,0,0,0,0,0,0,0,0,0,0,0,0,0,0,0,0,0,0
0,0,0,0,0,0,0,0,0,0,0,0,0,0,0,0,0,0,0,0,0
0,0,0,0,0,0,0,0,0,0,0,0,0,0,0,0,0,0,0,0,0
0,0,0,0,0,0,0,0,0,0,0,0,0,0,0,0,0,0,0,0,0
0,0,0,0,0,0,0,0,0,0,0,0,0,0,0,0,0,0,0,0,0
0,0,0,0,0,0,0,0,0,0,0,0,0,0,0,0,0,0,0,0,0
0,0,0,0,0,0,0,0,0,0,0,0,0,0,0,0,0,0,0,0,0
endlayer

layer
0,0,0,0,0,0,0,0,0,0,0,0,0,0,0,0,0,0,0,0,0
0,0,0,0,0,0,0,0,0,0,0,0,0,0,0,0,0,0,0,0,0
0,0,0,0,0,0,0,0,0,0,0,0,0,0,0,0,0,0,0,0,0
0,0,0,0,0,0,0,0,0,0,0,0,0,0,0,0,0,0,0,0,0
0,0,26,26,26,0,0,0,0,0,0,0,0,0,0,0,0,0,0,0,0
0,26,0,0,0,26,0,0,0,0,0,0,0,0,0,0,0,0,0,0,0
26,0,0,0,0,0,26,0,0,0,0,0,0,0,0,0,0,0,0,0,0
26,0,0,34,0,0,26,0,0,0,0,0,0,0,0,0,0,0,0,0,0
26,0,0,0,0,0,26,0,0,0,0,0,0,0,0,0,0,0,0,0,0
0,26,0,0,0,26,0,0,0,0,0,0,0,0,0,0,0,0,0,0,0
0,0,26,26,26,0,0,0,0,0,0,0,0,0,0,0,0,0,0,0,0
0,0,0,0,0,0,0,0,0,0,0,0,0,0,0,0,0,0,0,0,0
0,0,0,0,0,0,0,0,0,0,0,0,0,0,0,0,0,0,0,0,0
0,0,0,0,0,0,0,0,0,0,0,0,0,0,0,0,0,0,0,0,0
0,0,0,0,0,0,0,0,0,0,0,0,0,0,0,0,0,0,0,0,0
0,0,0,0,0,0,0,0,0,0,0,0,0,0,0,0,0,0,0,0,0
0,0,0,0,0,0,0,0,0,0,0,0,0,0,0,0,0,0,0,0,0
0,0,0,0,0,0,0,0,0,0,0,0,0,0,0,0,0,0,0,0,0
0,0,0,0,0,0,0,0,0,0,0,0,0,0,0,0,0,0,0,0,0
0,0,0,0,0,0,0,0,0,0,0,0,0,0,0,0,0,0,0,0,0
0,0,0,0,0,0,0,0,0,0,0,0,0,0,0,0,0,0,0,0,0
endlayer

layer
0,0,0,0,0,0,0,0,0,0,0,0,0,0,0,0,0,0,0,0,0
0,0,0,0,0,0,0,0,0,0,0,0,0,0,0,0,0,0,0,0,0
0,0,0,0,0,0,0,0,0,0,0,0,0,0,0,0,0,0,0,0,0
0,0,0,0,0,0,0,0,0,0,0,0,0,0,0,0,0,0,0,0,0
0,0,0,0,0,0,0,0,0,0,0,0,0,0,0,0,0,0,0,0,0
0,0,26,26,26,0,0,0,0,0,0,0,0,0,0,0,0,0,0,0,0
0,26,26,26,26,26,0,0,0,0,0,0,0,0,0,0,0,0,0,0,0
0,26,26,26,26,26,0,0,0,0,0,0,0,0,0,0,0,0,0,0,0
0,26,26,26,26,26,0,0,0,0,0,0,0,0,0,0,0,0,0,0,0
0,0,26,26,26,0,0,0,0,0,0,0,0,0,0,0,0,0,0,0,0
0,0,0,0,0,0,0,0,0,0,0,0,0,0,0,0,0,0,0,0,0
0,0,0,0,0,0,0,0,0,0,0,0,0,0,0,0,0,0,0,0,0
0,0,0,0,0,0,0,0,0,0,0,0,0,0,0,0,0,0,0,0,0
0,0,0,0,0,0,0,0,0,0,0,0,0,0,0,0,0,0,0,0,0
0,0,0,0,0,0,0,0,0,0,0,0,0,0,0,0,0,0,0,0,0
0,0,0,0,0,0,0,0,0,0,0,0,0,0,0,0,0,0,0,0,0
0,0,0,0,0,0,0,0,0,0,0,0,0,0,0,0,0,0,0,0,0
0,0,0,0,0,0,0,0,0,0,0,0,0,0,0,0,0,0,0,0,0
0,0,0,0,0,0,0,0,0,0,0,0,0,0,0,0,0,0,0,0,0
0,0,0,0,0,0,0,0,0,0,0,0,0,0,0,0,0,0,0,0,0
0,0,0,0,0,0,0,0,0,0,0,0,0,0,0,0,0,0,0,0,0
endlayer

