
# Created by Ruins mod version 16.2 Ingame Parser
# authoring Player: ST753M

# A boat inhabited by a villager with custom trades

weight=1
embed_into_distance=3
acceptable_target_blocks=water
unacceptable_target_blocks=
dimensions=9,9,17
allowable_overhang=0
max_leveling=0
leveling_buffer=0
preserve_water=0
preserve_lava=0
uniqueMinDistance=2000
spawnMinDistance=1000

biomesToSpawnIn=ocean,coral_reef,kelp_forest

rule1=0,100,minecraft:water-0
rule2=0,100,minecraft:planks-2
rule3=0,100,CommandBlock:RUINSTRIGGER /summon Villager ~0 ~5 ~0 {Profession:0,Offers:{Recipes:[{rewardExp:0b,maxUses:2147483647,uses:0,buy:{id:"minecraft:emerald",Count:1b},sell:{id:"minecraft:cooked_fish",Count:3b}},{rewardExp:0b,maxUses:3,uses:0,buy:{id:"minecraft:fishing_rod",Count:1b},sell:{id:"minecraft:emerald",Count:1b}},{rewardExp:0b,maxUses:2147483647,uses:0,buy:{id:"minecraft:fish",Damage:3,Count:8b},sell:{id:"minecraft:emerald",Count:1b}}]}}:@-0,CommandBlock:RUINSTRIGGER /summon Villager ~0 ~5 ~0 {Profession:0,Offers:{Recipes:[{rewardExp:0b,maxUses:2147483647,uses:0,buy:{id:"minecraft:emerald",Count:1b},sell:{id:"minecraft:sponge",Count:4b}},{rewardExp:0b,maxUses:34,uses:0,buy:{id:"minecraft:dye",Count:32b},sell:{id:"minecraft:emerald",Count:1b}},{rewardExp:0b,maxUses:2147483647,uses:0,buy:{id:"minecraft:boat",Count:1b},sell:{id:"minecraft:emerald",Count:1b}}]}}:@-0,CommandBlock:RUINSTRIGGER /summon Villager ~0 ~5 ~0 {Profession:0,Offers:{Recipes:[{rewardExp:0b,maxUses:2147483647,uses:0,buy:{id:"minecraft:emerald",Count:1b},sell:{id:"minecraft:fish",Damage:3,Count:2b}},{rewardExp:0b,maxUses:3,uses:0,buy:{id:"minecraft:emerald",Count:10b},sell:{id:"minecraft:leather_helmet",Count:1b,tag:{display:{Name:"Diving Helmet"},ench:[{id:5,lvl:3},{id:6,lvl:1}]}}},{rewardExp:0b,maxUses:2147483647,uses:0,buy:{id:"minecraft:emerald",Count:29b},sell:{id:"minecraft:spawn_egg",Damage:94,Count:1b,tag:{EntityTag:{id:"minecraft:squid"}}}}]}}:@-0
rule4=0,100,minecraft:planks-0
rule5=0,100,minecraft:glowstone-0
rule6=0,100,IInventory;minecraft:chest;minecraft:cooked_beef#4#0#5+minecraft:bucket#1#0#11+minecraft:potion#{Potion:"minecraft:water_breathing"}#0#17+minecraft:birch_boat#1#0#24-5,IInventory;minecraft:chest;minecraft:birch_boat#1#0#5+minecraft:prismarine_shard#8#0#9+minecraft:bucket#1#0#16+minecraft:pumpkin_pie#4#0#21-5,air,air,air
rule7=0,100,IInventory;minecraft:chest;minecraft:cooked_beef#4#0#5+minecraft:bucket#1#0#11+minecraft:potion#{Potion:"minecraft:water_breathing"}#0#17+minecraft:birch_boat#1#0#24-5,IInventory;minecraft:chest;minecraft:birch_boat#1#0#5+minecraft:prismarine_shard#8#0#9+minecraft:bucket#1#0#16+minecraft:pumpkin_pie#4#0#21-5,air,air,air
rule8=0,100,minecraft:spruce_stairs-3
rule9=0,100,minecraft:fence-0
rule10=0,100,minecraft:spruce_stairs-2
rule11=0,100,minecraft:bed-10
rule12=0,100,minecraft:bed-2
rule13=0,100,minecraft:carpet-14
rule14=0,100,minecraft:spruce_stairs-0
rule15=0,100,minecraft:birch_stairs-3
rule16=0,100,minecraft:ladder-4
rule17=0,100,minecraft:birch_stairs-6
rule18=0,100,minecraft:glass_pane-0
rule19=0,100,minecraft:flower_pot-0
rule20=0,100,minecraft:wooden_pressure_plate-0
rule21=0,100,minecraft:ladder-5
rule22=0,100,minecraft:fence_gate-1
rule23=0,100,minecraft:spruce_stairs-1
rule24=0,100,minecraft:wooden_door-5
rule25=0,100,minecraft:wooden_door-1
rule26=0,100,minecraft:fence_gate-3
rule27=0,100,minecraft:wooden_door-8
rule28=0,100,minecraft:oak_stairs-2
rule29=0,100,minecraft:oak_stairs-0
rule30=0,100,minecraft:wooden_slab-0
rule31=2,100,minecraft:torch-3
rule32=2,100,minecraft:torch-4
rule33=0,100,minecraft:oak_stairs-1
rule34=0,100,minecraft:oak_stairs-3

layer
1,1,1,1,1,1,1,1,1,1,1,1,1,1,1,1,1
1,1,1,1,1,1,1,1,1,1,1,1,1,1,1,1,1
1,1,1,1,1,1,1,1,1,1,1,1,1,1,1,1,1
1,1,2,2,2,2,2,2,2,2,2,2,1,1,1,1,1
1,1,2,2,2,2,3,2,2,2,2,2,1,1,1,1,1
1,1,2,2,2,2,2,2,2,2,2,2,1,1,1,1,1
1,1,1,1,1,1,1,1,1,1,1,1,1,1,1,1,1
1,1,1,1,1,1,1,1,1,1,1,1,1,1,1,1,1
1,1,1,1,1,1,1,1,1,1,1,1,1,1,1,1,1
endlayer

layer
1,1,1,1,1,1,1,1,1,1,1,1,1,1,1,1,1
1,1,1,1,1,1,1,1,1,1,1,1,1,1,1,1,1
1,2,2,2,2,2,2,2,2,2,2,2,2,1,1,1,1
1,2,4,4,4,4,4,4,4,4,4,4,4,1,1,1,1
1,2,4,4,5,5,5,5,5,5,4,4,4,1,1,1,1
1,2,2,4,4,4,4,4,4,4,4,4,4,1,1,1,1
1,2,2,2,2,2,2,2,2,2,2,2,2,1,1,1,1
1,1,1,1,1,1,1,1,1,1,1,1,1,1,1,1,1
1,1,1,1,1,1,1,1,1,1,1,1,1,1,1,1,1
endlayer

layer
1,1,1,1,1,1,1,1,1,1,1,1,1,1,1,1,1
2,2,2,2,2,2,2,2,2,2,2,2,2,1,1,1,1
2,2,2,10,9,8,2,2,7,6,2,2,2,2,1,1,1
2,2,2,0,0,0,0,0,0,0,0,12,11,2,2,1,1
2,2,2,0,13,13,13,13,13,13,0,0,9,2,2,1,1
2,2,2,0,0,0,0,0,0,0,0,12,11,2,2,1,1
2,4,2,0,15,2,2,2,14,14,2,2,2,2,1,1,1
2,2,2,2,2,2,2,2,2,2,2,2,2,1,1,1,1
1,1,1,1,1,1,1,1,1,1,1,1,1,1,1,1,1
endlayer

layer
0,0,16,0,0,0,0,0,0,0,0,0,0,0,0,0,0
2,2,2,2,18,2,2,18,2,2,18,2,2,17,0,0,0
2,2,2,0,20,0,2,19,0,0,19,2,2,2,17,0,0
2,2,2,0,0,0,0,0,0,0,0,0,0,2,2,17,0
2,2,2,0,0,0,0,0,0,0,0,0,20,2,4,2,0
2,2,2,0,0,0,0,0,0,0,0,0,0,2,2,17,0
2,4,2,0,0,15,2,19,0,0,19,2,2,2,17,0,0
2,2,2,2,18,2,2,18,2,2,18,2,2,17,0,0,0
0,0,21,0,0,0,0,0,0,0,0,0,0,0,0,0,0
endlayer

layer
0,0,16,0,0,0,0,0,0,0,0,0,0,0,0,0,0
2,2,2,2,2,2,2,2,2,2,2,2,2,2,0,0,0
2,4,4,4,4,4,4,4,4,4,4,4,4,4,2,0,0
2,4,4,4,4,4,4,4,4,4,4,4,4,4,4,2,0
2,4,4,4,4,4,4,4,4,4,4,4,4,4,4,2,17
2,4,4,4,4,4,4,4,4,4,4,4,4,4,4,2,0
2,4,4,0,0,0,15,4,4,4,4,4,4,4,2,0,0
2,2,2,2,2,2,2,2,2,2,2,2,2,2,0,0,0
0,0,21,0,0,0,0,0,0,0,0,0,0,0,0,0,0
endlayer

layer
0,0,0,0,0,0,0,0,0,0,0,0,0,0,0,0,0
9,9,22,2,2,2,2,2,2,2,2,2,2,2,0,0,0
9,0,0,2,0,0,0,0,2,0,23,23,0,2,2,0,0
9,0,0,25,0,13,13,0,24,0,0,0,0,23,2,2,0
9,0,0,2,0,13,13,0,2,0,0,0,0,0,2,2,2
9,0,0,2,0,0,0,0,2,0,0,0,0,14,2,2,0
9,0,0,17,0,0,0,0,2,0,14,14,0,2,2,0,0
9,9,26,2,2,2,2,2,2,2,2,2,2,2,0,0,0
0,0,0,0,0,0,0,0,0,0,0,0,0,0,0,0,0
endlayer

layer
0,0,0,0,0,0,0,0,0,0,0,0,0,0,0,0,0
9,0,0,2,2,18,18,2,2,9,9,9,9,9,0,0,0
0,0,0,2,0,0,0,0,2,0,0,0,0,9,9,0,0
0,0,0,27,0,0,0,0,27,0,0,0,0,0,9,9,0
9,0,0,2,0,0,0,0,2,0,0,0,0,0,0,9,15
0,0,0,18,0,0,0,0,18,0,0,0,0,0,9,9,0
0,0,0,2,0,0,0,0,2,0,0,0,0,9,9,0,0
9,0,0,2,2,18,18,2,2,9,9,9,9,9,0,0,0
0,0,0,0,0,0,0,0,0,0,0,0,0,0,0,0,0
endlayer

layer
0,29,29,29,29,29,29,29,29,28,0,0,0,0,0,0,0
30,4,4,2,2,2,2,2,2,28,0,0,0,0,0,0,0
30,4,4,2,0,0,0,0,2,28,0,0,0,0,0,0,0
30,4,4,2,0,0,0,0,2,28,0,0,0,0,0,0,0
30,4,4,2,32,0,0,31,2,28,0,0,0,0,0,0,0
30,4,4,2,0,0,0,0,2,28,0,0,0,0,0,0,0
30,4,4,2,0,0,0,0,2,28,0,0,0,0,0,0,0
30,4,4,2,2,2,2,2,2,28,0,0,0,0,0,0,0
0,34,33,33,33,33,33,33,33,33,0,0,0,0,0,0,0
endlayer

layer
0,0,0,0,0,0,0,0,0,0,0,0,0,0,0,0,0
0,0,30,29,29,29,29,29,28,0,0,0,0,0,0,0,0
0,0,30,4,4,4,4,4,28,0,0,0,0,0,0,0,0
0,0,30,4,4,4,4,4,28,0,0,0,0,0,0,0,0
0,0,30,4,4,4,4,4,28,0,0,0,0,0,0,0,0
0,0,30,4,4,4,4,4,28,0,0,0,0,0,0,0,0
0,0,30,4,4,4,4,4,28,0,0,0,0,0,0,0,0
0,0,30,33,33,33,33,33,33,0,0,0,0,0,0,0,0
0,0,0,0,0,0,0,0,0,0,0,0,0,0,0,0,0
endlayer

