
# Created by Ruins mod version 16.7 Ingame Parser
# authoring Player: lafuller

weight=1
embed_into_distance=2
uniqueMinDistance=600
acceptable_target_blocks=water
unacceptable_target_blocks=
biomesToSpawnIn=ocean,deep ocean,ocean oil field,kelp forest,deep_ocean,ocean_oil_field,kelp_forest
dimensions=16,14,14
allowable_overhang=0
max_leveling=2
leveling_buffer=0
preserve_water=0
preserve_lava=0

rule1=0,100,preserveBlock
rule2=0,100,minecraft:planks-5
rule3=0,100,minecraft:wooden_slab-9
rule4=0,100,minecraft:spruce_stairs-4
rule5=0,100,minecraft:spruce_stairs-6
rule6=0,100,minecraft:planks-1
rule7=0,100,minecraft:spruce_stairs-7
rule8=0,100,minecraft:spruce_stairs-5
rule9=0,100,minecraft:trapdoor-6
rule10=0,100,minecraft:wooden_slab-1
rule11=0,100,minecraft:trapdoor-4
rule12=0,100,minecraft:spruce_fence-0
rule13=0,100,minecraft:trapdoor-5
rule14=0,100,minecraft:trapdoor-7
rule15=0,100,minecraft:wool-0
rule16=0,100,bookshelf,ChestGenHook:chests/spawn_bonus_chest:5-4,ChestGenHook:chests/village_blacksmith:5-4,ChestGenHook:chests/simple_dungeon:5-4,ChestGenHook:chests/abandoned_mineshaft:5-4,ChestGenHook:chests/stronghold_library:5-4,ChestGenHook:chests/stronghold_corridor:5-4,ChestGenHook:chests/stronghold_crossing:5-3,ChestGenHook:chests/igloo_chest:5-4


layer
1,1,1,1,1,1,1,1,1,1,1,1,1,1
1,1,1,1,1,1,1,1,1,1,1,1,1,1
1,1,1,1,1,1,1,1,1,1,1,1,1,1
1,1,1,1,1,1,1,1,1,1,1,1,1,1
1,1,1,1,1,1,1,1,2,2,1,1,1,1
1,1,1,1,1,1,1,2,2,2,1,1,1,1
1,1,1,1,1,1,2,2,2,1,1,1,1,1
1,1,1,1,1,2,2,2,1,1,1,1,1,1
1,1,1,1,2,2,2,1,1,1,1,1,1,1
1,1,1,2,2,2,1,1,1,1,1,1,1,1
1,1,1,2,2,1,1,1,1,1,1,1,1,1
1,1,1,1,1,1,1,1,1,1,1,1,1,1
1,1,1,1,1,1,1,1,1,1,1,1,1,1
1,1,1,1,1,1,1,1,1,1,1,1,1,1
endlayer

layer
1,1,1,1,1,1,1,1,1,1,1,1,1,1
1,1,1,1,1,1,1,1,1,1,1,1,1,1
1,1,1,1,1,1,1,1,1,1,1,1,1,1
1,1,1,1,1,1,1,1,1,2,2,1,1,1
1,1,1,1,1,1,1,1,2,2,2,1,1,1
1,1,1,1,1,1,1,2,2,2,1,1,1,1
1,1,1,1,1,2,2,2,2,1,1,1,1,1
1,1,1,1,2,2,2,2,1,1,1,1,1,1
1,1,1,2,2,2,2,2,1,1,1,1,1,1
1,1,1,2,2,2,2,1,1,1,1,1,1,1
1,1,2,2,2,2,1,1,1,1,1,1,1,1
1,1,2,2,1,1,1,1,1,1,1,1,1,1
1,1,1,1,1,1,1,1,1,1,1,1,1,1
1,1,1,1,1,1,1,1,1,1,1,1,1,1
endlayer

layer
1,1,1,1,1,1,1,1,1,1,1,1,1,1
1,1,1,1,1,1,1,1,1,1,1,1,1,1
1,1,1,1,1,1,1,1,1,1,4,3,1,1
1,1,1,1,1,1,1,1,1,6,6,5,1,1
1,1,1,1,1,1,1,4,6,6,6,1,1,1
1,1,1,1,1,4,6,6,6,6,1,1,1,1
1,1,1,1,4,6,6,6,6,5,1,1,1,1
1,1,1,7,6,6,6,6,6,1,1,1,1,1
1,1,7,6,6,6,6,6,5,1,1,1,1,1
1,1,6,6,6,6,6,5,1,1,1,1,1,1
1,7,6,6,6,6,8,1,1,1,1,1,1,1
1,6,6,6,6,8,1,1,1,1,1,1,1,1
1,1,6,8,1,1,1,1,1,1,1,1,1,1
1,1,1,1,1,1,1,1,1,1,1,1,1,1
endlayer

layer
1,1,1,1,1,1,1,1,1,1,1,1,1,1
1,1,1,1,1,1,1,1,1,1,1,4,3,1
1,1,1,1,1,1,1,1,1,1,6,6,5,1
1,1,1,1,1,1,1,9,4,6,6,6,1,1
1,1,1,1,1,9,4,6,6,6,6,1,1,1
1,1,1,1,4,6,10,10,10,6,5,1,1,1
1,1,1,7,10,1,1,1,10,6,11,1,1,1
1,1,13,6,1,1,12,1,10,5,1,1,1,1
1,1,6,10,1,1,1,1,6,11,1,1,1,1
1,7,6,10,1,1,1,10,5,1,1,1,1,1
1,6,6,16,10,10,6,8,1,1,1,1,1,1
1,6,6,6,6,6,14,1,1,1,1,1,1,1
1,6,6,6,8,1,1,1,1,1,1,1,1,1
1,1,1,1,1,1,1,1,1,1,1,1,1,1
endlayer

layer
1,1,1,1,1,1,1,1,1,1,1,1,4,5
1,1,1,1,1,1,1,1,1,1,1,6,6,5
1,1,1,1,1,1,1,1,1,1,10,6,6,1
1,1,1,1,1,1,1,1,10,10,6,10,1,1
1,1,1,1,1,1,1,1,1,1,10,1,1,1
1,1,1,1,1,1,1,1,1,1,10,1,1,1
1,1,1,1,1,1,1,1,1,1,1,1,1,1
1,1,1,1,1,1,12,1,1,1,1,1,1,1
1,1,1,1,1,1,1,1,1,1,1,1,1,1
1,10,1,1,1,1,1,1,1,1,1,1,1,1
7,10,1,1,1,1,1,1,1,1,1,1,1,1
6,10,1,1,1,1,1,1,1,1,1,1,1,1
1,6,10,10,10,1,1,1,1,1,1,1,1,1
1,1,6,8,1,1,1,1,1,1,1,1,1,1
endlayer

layer
1,1,1,1,1,1,1,1,1,1,1,1,1,15
1,1,1,1,1,1,1,1,1,1,1,1,15,15
1,1,1,1,1,1,1,1,1,1,1,15,15,1
1,1,1,1,1,1,1,1,1,1,15,15,1,1
1,1,1,1,1,1,1,1,1,1,1,1,1,1
1,1,1,1,1,1,1,1,1,1,1,1,1,1
1,1,1,1,1,1,12,12,1,1,1,1,1,1
1,1,1,1,1,1,12,1,1,1,1,1,1,1
1,1,1,1,1,1,1,1,1,1,1,1,1,1
1,1,1,1,1,1,1,1,1,1,1,1,1,1
1,1,1,1,1,1,1,1,1,1,1,1,1,1
1,1,1,1,1,1,1,1,1,1,1,1,1,1
1,1,1,1,1,1,1,1,1,1,1,1,1,1
1,1,1,1,1,1,1,1,1,1,1,1,1,1
endlayer

layer
1,1,1,1,1,1,1,1,1,1,1,1,1,1
1,1,1,1,1,1,1,1,1,1,1,1,15,1
1,1,1,1,1,1,1,1,1,1,1,15,15,1
1,1,1,1,1,1,1,1,1,1,1,15,1,1
1,1,1,1,1,1,1,1,1,15,15,1,1,1
1,1,1,1,1,1,1,1,15,15,1,1,1,1
1,1,1,1,1,1,12,15,15,15,1,1,1,1
1,1,1,1,1,1,12,12,15,1,1,1,1,1
1,1,1,1,1,1,12,12,1,1,1,1,1,1
1,1,1,1,1,1,12,1,1,1,1,1,1,1
1,1,1,1,1,1,12,1,1,1,1,1,1,1
1,1,1,1,1,12,12,1,1,1,1,1,1,1
1,1,1,1,12,12,1,1,1,1,1,1,1,1
1,1,1,1,12,1,1,1,1,1,1,1,1,1
endlayer

layer
1,1,1,1,1,1,1,1,1,1,1,1,1,1
1,1,1,1,1,1,1,1,1,1,1,1,1,1
1,1,1,1,1,1,1,1,1,1,1,1,15,1
1,1,1,1,1,1,1,1,1,1,1,15,15,1
1,1,1,1,1,1,1,1,1,1,15,15,1,1
1,1,1,1,1,1,1,1,15,15,15,1,1,1
1,1,1,1,1,1,1,15,15,1,1,1,1,1
1,1,1,1,1,1,12,1,1,1,1,1,1,1
1,1,1,1,1,1,1,15,1,1,1,1,1,1
1,1,1,1,1,1,15,15,1,1,1,1,1,1
1,1,1,1,1,15,15,1,1,1,1,1,1,1
1,1,1,1,1,15,15,1,1,1,1,1,1,1
1,1,1,1,15,15,1,1,1,1,1,1,1,1
1,1,1,15,15,1,1,1,1,1,1,1,1,1
endlayer

layer
1,1,1,1,1,1,1,1,1,1,1,1,1,1
1,1,1,1,1,1,1,1,1,1,1,1,1,1
1,1,1,1,1,1,1,1,1,1,1,15,1,1
1,1,1,1,1,1,1,1,1,1,15,15,1,1
1,1,1,1,1,1,1,1,1,1,15,15,1,1
1,1,1,1,1,1,1,1,1,15,15,15,1,1
1,1,1,1,1,1,1,1,15,15,1,1,1,1
1,1,1,1,1,1,12,1,15,1,1,1,1,1
1,1,1,1,1,1,15,15,1,1,1,1,1,1
1,1,1,1,1,1,15,15,1,1,1,1,1,1
1,1,1,1,1,1,15,1,1,1,1,1,1,1
1,1,1,1,1,15,1,1,1,1,1,1,1,1
1,1,1,1,1,15,1,1,1,1,1,1,1,1
1,1,1,1,15,1,1,1,1,1,1,1,1,1
endlayer

layer
1,1,1,1,1,1,1,1,1,1,1,1,1,1
1,1,1,1,1,1,1,1,1,1,1,1,1,1
1,1,1,1,1,1,1,1,1,1,1,1,1,1
1,1,1,1,1,1,1,1,1,1,15,15,1,1
1,1,1,1,1,1,1,1,1,15,15,1,1,1
1,1,1,1,1,1,1,1,15,15,15,1,1,1
1,1,1,1,1,1,1,1,15,1,1,1,1,1
1,1,1,1,1,1,12,1,1,1,1,1,1,1
1,1,1,1,1,1,1,15,1,1,1,1,1,1
1,1,1,1,1,15,15,1,1,1,1,1,1,1
1,1,1,1,1,15,15,1,1,1,1,1,1,1
1,1,1,1,1,15,1,1,1,1,1,1,1,1
1,1,1,1,15,1,1,1,1,1,1,1,1,1
1,1,1,1,1,1,1,1,1,1,1,1,1,1
endlayer

layer
1,1,1,1,1,1,1,1,1,1,1,1,1,1
1,1,1,1,1,1,1,1,1,1,1,1,1,1
1,1,1,1,1,1,1,1,1,1,1,1,1,1
1,1,1,1,1,1,1,1,1,1,1,1,1,1
1,1,1,1,1,1,1,1,1,1,15,1,1,1
1,1,1,1,1,1,1,1,15,15,15,1,1,1
1,1,1,1,1,1,1,1,15,15,1,1,1,1
1,1,1,1,1,1,12,1,15,1,1,1,1,1
1,1,1,1,1,1,15,1,1,1,1,1,1,1
1,1,1,1,1,1,15,1,1,1,1,1,1,1
1,1,1,1,1,15,15,1,1,1,1,1,1,1
1,1,1,1,15,1,1,1,1,1,1,1,1,1
1,1,1,1,1,1,1,1,1,1,1,1,1,1
1,1,1,1,1,1,1,1,1,1,1,1,1,1
endlayer

layer
1,1,1,1,1,1,1,1,1,1,1,1,1,1
1,1,1,1,1,1,1,1,1,1,1,1,1,1
1,1,1,1,1,1,1,1,1,1,1,1,1,1
1,1,1,1,1,1,1,1,1,1,1,1,1,1
1,1,1,1,1,1,1,1,1,15,1,1,1,1
1,1,1,1,1,1,1,1,1,15,1,1,1,1
1,1,1,1,1,1,1,1,15,15,1,1,1,1
1,1,1,1,1,1,12,1,15,1,1,1,1,1
1,1,1,1,1,1,15,1,1,1,1,1,1,1
1,1,1,1,1,15,15,1,1,1,1,1,1,1
1,1,1,1,1,15,1,1,1,1,1,1,1,1
1,1,1,1,1,1,1,1,1,1,1,1,1,1
1,1,1,1,1,1,1,1,1,1,1,1,1,1
1,1,1,1,1,1,1,1,1,1,1,1,1,1
endlayer

layer
1,1,1,1,1,1,1,1,1,1,1,1,1,1
1,1,1,1,1,1,1,1,1,1,1,1,1,1
1,1,1,1,1,1,1,1,1,1,1,1,1,1
1,1,1,1,1,1,1,1,1,1,1,1,1,1
1,1,1,1,1,1,1,1,1,1,1,1,1,1
1,1,1,1,1,1,1,1,15,1,1,1,1,1
1,1,1,1,1,1,1,1,15,15,1,1,1,1
1,1,1,1,1,1,12,15,15,1,1,1,1,1
1,1,1,1,1,15,15,1,1,1,1,1,1,1
1,1,1,1,1,15,1,1,1,1,1,1,1,1
1,1,1,1,1,1,1,1,1,1,1,1,1,1
1,1,1,1,1,1,1,1,1,1,1,1,1,1
1,1,1,1,1,1,1,1,1,1,1,1,1,1
1,1,1,1,1,1,1,1,1,1,1,1,1,1
endlayer

layer
1,1,1,1,1,1,1,1,1,1,1,1,1,1
1,1,1,1,1,1,1,1,1,1,1,1,1,1
1,1,1,1,1,1,1,1,1,1,1,1,1,1
1,1,1,1,1,1,1,1,1,1,1,1,1,1
1,1,1,1,1,1,1,1,1,1,1,1,1,1
1,1,1,1,1,1,1,1,1,1,1,1,1,1
1,1,1,1,1,1,1,15,1,1,1,1,1,1
1,1,1,1,1,1,12,15,15,1,1,1,1,1
1,1,1,1,1,1,15,1,1,1,1,1,1,1
1,1,1,1,1,1,1,1,1,1,1,1,1,1
1,1,1,1,1,1,1,1,1,1,1,1,1,1
1,1,1,1,1,1,1,1,1,1,1,1,1,1
1,1,1,1,1,1,1,1,1,1,1,1,1,1
1,1,1,1,1,1,1,1,1,1,1,1,1,1
endlayer

layer
1,1,1,1,1,1,1,1,1,1,1,1,1,1
1,1,1,1,1,1,1,1,1,1,1,1,1,1
1,1,1,1,1,1,1,1,1,1,1,1,1,1
1,1,1,1,1,1,1,1,1,1,1,1,1,1
1,1,1,1,1,1,1,1,1,1,1,1,1,1
1,1,1,1,1,1,1,1,1,1,1,1,1,1
1,1,1,1,1,1,15,15,1,1,1,1,1,1
1,1,1,1,1,1,12,1,1,1,1,1,1,1
1,1,1,1,1,1,1,1,1,1,1,1,1,1
1,1,1,1,1,1,1,1,1,1,1,1,1,1
1,1,1,1,1,1,1,1,1,1,1,1,1,1
1,1,1,1,1,1,1,1,1,1,1,1,1,1
1,1,1,1,1,1,1,1,1,1,1,1,1,1
1,1,1,1,1,1,1,1,1,1,1,1,1,1
endlayer

layer
1,1,1,1,1,1,1,1,1,1,1,1,1,1
1,1,1,1,1,1,1,1,1,1,1,1,1,1
1,1,1,1,1,1,1,1,1,1,1,1,1,1
1,1,1,1,1,1,1,1,1,1,1,1,1,1
1,1,1,1,1,1,1,1,1,1,1,1,1,1
1,1,1,1,1,1,1,1,1,1,1,1,1,1
1,1,1,1,1,1,15,1,1,1,1,1,1,1
1,1,1,1,1,1,12,1,1,1,1,1,1,1
1,1,1,1,1,1,1,1,1,1,1,1,1,1
1,1,1,1,1,1,1,1,1,1,1,1,1,1
1,1,1,1,1,1,1,1,1,1,1,1,1,1
1,1,1,1,1,1,1,1,1,1,1,1,1,1
1,1,1,1,1,1,1,1,1,1,1,1,1,1
1,1,1,1,1,1,1,1,1,1,1,1,1,1
endlayer

