
# Created by Ruins mod version 16.7 Ingame Parser
# authoring Player: ST753M

# a super rare, powerful, and dangerous structure

weight=1
uniqueMinDistance=9999
embed_into_distance=2
acceptable_target_blocks=grass,dirt
unacceptable_target_blocks=
dimensions=9,15,15
allowable_overhang=32
max_leveling=0
leveling_buffer=0
preserve_water=0
preserve_lava=0
preserve_plants=1

biomesToSpawnIn=mutated_roofed_forest

rule1=0,100,preserveBlock
rule2=0,100,minecraft:obsidian-0
rule3=0,100,minecraft:bedrock-0
rule4=0,100,minecraft:cobblestone-0
rule5=0,100,minecraft:glass-0
rule6=0,100,minecraft:cobblestone_wall-0
rule7=0,100,minecraft:stone_stairs-0
rule8=0,100,minecraft:stone_stairs-2
rule9=0,100,minecraft:stone_stairs-3
rule10=0,100,CommandBlock:/testruin ST753M/AltarActions_CB ~ ~ ~:@-1
rule11=0,100,minecraft:stone_stairs-1
rule12=0,100,minecraft:wooden_pressure_plate-0
rule13=0,100,IInventory;minecraft:dropper;minecraft:stone#64#0#0+minecraft:stone#64#0#1+minecraft:stone#64#0#2-0
rule14=1,100,minecraft:redstone_torch-5
rule15=0,100,minecraft:lever-5
rule16=0,100,minecraft:stone_stairs-7
rule17=0,100,minecraft:stone_stairs-6
rule18=0,100,minecraft:stone_stairs-5
rule19=0,100,minecraft:stone_stairs-4
rule20=0,100,CommandBlock:RUINSTRIGGER /summon ender_crystal:@-1
rule21=0,100,minecraft:stone_slab-3
rule22=0,100,CommandBlock:RUINSTRIGGER /summon evocation_illager ~ ~1 ~ {CustomName:"High Priest",CustomNameVisible:1,ArmorItems:[{id:"minecraft:diamond_boots",Count:1b,tag:{ench:[{id:0,lvl:4},{id:2,lvl:3},{id:7,lvl:1},{id:9,lvl:1}]}},{id:"minecraft:diamond_leggings",Count:1b,tag:{ench:[{id:4,lvl:4}]}},{id:"minecraft:diamond_chestplate",Count:1b,tag:{ench:[{id:1,lvl:4},{id:7,lvl:1}]}},{id:"minecraft:diamond_helmet",Count:1b,tag:{ench:[{id:0,lvl:4},{id:5,lvl:1},{id:7,lvl:1}]}}],ArmorDropChances:[0.0F,0.0F,0.0F,0.0F],Attributes:[{Name:generic.maxHealth,Base:50},{Name:generic.attackDamage,Base:8},{Name:generic.knockbackResistance,Base:50}],Health:50.0f,PersistenceRequired:1,ActiveEffects:[{Id:1,Amplifier:0,Duration:199980,ShowParticles:0},{Id:12,Amplifier:0,Duration:1999980,ShowParticles:0}]}:@-1

layer
1,1,2,2,2,2,2,2,2,2,2,2,2,1,1
1,2,2,2,2,2,2,2,2,2,2,2,2,2,1
2,2,2,2,2,2,2,2,2,2,2,2,2,2,2
2,2,2,2,2,2,2,2,2,2,2,2,2,2,2
2,2,2,2,2,2,2,2,2,2,2,2,2,2,2
2,2,2,2,2,2,2,2,2,2,2,2,2,2,2
2,2,2,2,2,2,3,3,3,2,2,2,2,2,2
2,2,2,2,2,2,3,3,3,2,2,2,2,2,2
2,2,2,2,2,2,3,3,3,2,2,2,2,2,2
2,2,2,2,2,2,2,2,2,2,2,2,2,2,2
2,2,2,2,2,2,2,2,2,2,2,2,2,2,2
2,2,2,2,2,2,2,2,2,2,2,2,2,2,2
2,2,2,2,2,2,2,2,2,2,2,2,2,2,2
1,2,2,2,2,2,2,2,2,2,2,2,2,2,1
1,1,2,2,2,2,2,2,2,2,2,2,2,1,1
endlayer

layer
1,1,2,2,2,2,4,4,4,2,2,2,2,1,1
1,2,2,2,2,2,2,2,2,2,2,2,2,2,1
2,2,2,2,2,2,2,2,2,2,2,2,2,2,2
2,2,2,2,2,2,2,2,2,2,2,2,2,2,2
2,2,2,2,2,2,2,2,2,2,2,2,2,2,2
2,2,2,2,2,2,3,3,3,2,2,2,2,2,2
4,2,2,2,2,3,5,5,5,3,2,2,2,2,4
4,2,2,2,2,3,5,5,5,3,2,2,2,2,4
4,2,2,2,2,3,5,5,5,3,2,2,2,2,4
2,2,2,2,2,2,3,3,3,2,2,2,2,2,2
2,2,2,2,2,2,2,2,2,2,2,2,2,2,2
2,2,2,2,2,2,2,2,2,2,2,2,2,2,2
2,2,2,2,2,2,2,2,2,2,2,2,2,2,2
1,2,2,2,2,2,2,2,2,2,2,2,2,2,1
1,1,2,2,2,2,4,4,4,2,2,2,2,1,1
endlayer

layer
1,1,1,1,2,1,1,1,1,1,2,1,1,1,1
1,6,1,2,2,2,7,7,7,2,2,2,1,6,1
1,1,2,2,2,2,4,4,4,2,2,2,2,1,1
1,2,2,2,2,2,2,2,2,2,2,2,2,2,1
2,2,2,2,2,2,2,2,2,2,2,2,2,2,2
1,2,2,2,2,2,3,3,3,2,2,2,2,2,1
1,9,4,2,2,3,5,5,5,3,2,2,4,8,1
1,9,4,2,2,3,5,10,5,3,2,2,4,8,1
1,9,4,2,2,3,5,5,5,3,2,2,4,8,1
1,2,2,2,2,2,3,3,3,2,2,2,2,2,1
2,2,2,2,2,2,2,2,2,2,2,2,2,2,2
1,2,2,2,2,2,2,2,2,2,2,2,2,2,1
1,1,2,2,2,2,4,4,4,2,2,2,2,1,1
1,6,1,2,2,2,11,11,11,2,2,2,1,6,1
1,1,1,1,2,1,1,1,1,1,2,1,1,1,1
endlayer

layer
1,1,1,1,2,1,1,1,1,1,2,1,1,1,1
1,6,1,1,1,1,1,1,1,1,1,1,1,6,1
1,1,1,1,1,1,1,1,1,1,1,1,1,1,1
1,1,1,1,2,2,7,7,7,2,2,1,1,1,1
2,1,1,2,2,2,4,4,4,2,2,2,1,1,2
1,1,1,2,2,2,3,3,3,2,2,2,1,1,1
1,1,1,9,4,3,5,5,5,3,4,8,1,1,1
1,1,1,9,4,3,5,12,5,3,4,8,1,1,1
1,1,1,9,4,3,5,5,5,3,4,8,1,1,1
1,1,1,2,2,2,3,3,3,2,2,2,1,1,1
2,1,1,2,2,2,4,4,4,2,2,2,1,1,2
1,1,1,1,2,2,11,11,11,2,2,1,1,1,1
1,1,1,1,1,1,1,1,1,1,1,1,1,1,1
1,6,1,1,1,1,1,1,1,1,1,1,1,6,1
1,1,1,1,2,1,1,1,1,1,2,1,1,1,1
endlayer

layer
1,1,1,1,2,1,1,1,1,1,2,1,1,1,1
1,6,1,1,1,1,1,1,1,1,1,1,1,6,1
1,1,1,1,1,1,1,1,1,1,1,1,1,1,1
1,1,1,1,1,1,1,1,1,1,1,1,1,1,1
2,1,1,1,1,1,1,1,1,1,1,1,1,1,2
1,1,1,1,1,2,7,7,7,2,1,1,1,1,1
1,1,1,1,1,9,3,3,3,8,1,1,1,1,1
1,1,1,1,1,9,3,13,3,8,1,1,1,1,1
1,1,1,1,1,9,3,3,3,8,1,1,1,1,1
1,1,1,1,1,2,11,11,11,2,1,1,1,1,1
2,1,1,1,1,1,1,1,1,1,1,1,1,1,2
1,1,1,1,1,1,1,1,1,1,1,1,1,1,1
1,1,1,1,1,1,1,1,1,1,1,1,1,1,1
1,6,1,1,1,1,1,1,1,1,1,1,1,6,1
1,1,1,1,2,1,1,1,1,1,2,1,1,1,1
endlayer

layer
1,1,1,1,2,1,1,1,1,1,2,1,1,1,1
1,14,1,1,1,1,1,1,1,1,1,1,1,14,1
1,1,1,1,1,1,1,1,1,1,1,1,1,1,1
1,1,1,1,1,1,1,1,1,1,1,1,1,1,1
2,1,1,1,1,1,1,1,1,1,1,1,1,1,2
1,1,1,1,1,2,1,1,1,2,1,1,1,1,1
1,1,1,1,1,1,7,7,8,1,1,1,1,1,1
1,1,1,1,1,1,9,3,8,1,1,1,1,1,1
1,1,1,1,1,1,9,11,11,1,1,1,1,1,1
1,1,1,1,1,2,1,1,1,2,1,1,1,1,1
2,1,1,1,1,1,1,1,1,1,1,1,1,1,2
1,1,1,1,1,1,1,1,1,1,1,1,1,1,1
1,1,1,1,1,1,1,1,1,1,1,1,1,1,1
1,14,1,1,1,1,1,1,1,1,1,1,1,14,1
1,1,1,1,2,1,1,1,1,1,2,1,1,1,1
endlayer

layer
1,1,1,1,2,1,1,1,1,1,2,1,1,1,1
1,1,1,1,1,1,1,1,1,1,1,1,1,1,1
1,1,1,1,1,1,1,1,1,1,1,1,1,1,1
1,1,1,1,1,1,1,1,1,1,1,1,1,1,1
2,1,1,1,1,1,1,1,1,1,1,1,1,1,2
1,1,1,1,1,2,1,1,1,2,1,1,1,1,1
1,1,1,1,1,1,0,0,0,1,1,1,1,1,1
1,1,1,1,1,1,0,15,0,1,1,1,1,1,1
1,1,1,1,1,1,0,0,0,1,1,1,1,1,1
1,1,1,1,1,2,1,1,1,2,1,1,1,1,1
2,1,1,1,1,1,1,1,1,1,1,1,1,1,2
1,1,1,1,1,1,1,1,1,1,1,1,1,1,1
1,1,1,1,1,1,1,1,1,1,1,1,1,1,1
1,1,1,1,1,1,1,1,1,1,1,1,1,1,1
1,1,1,1,2,1,1,1,1,1,2,1,1,1,1
endlayer

layer
1,1,1,1,6,1,1,1,1,1,6,1,1,1,1
1,1,1,1,1,1,1,1,1,1,1,1,1,1,1
1,1,1,1,1,1,1,1,1,1,1,1,1,1,1
1,1,1,1,1,1,1,1,1,1,1,1,1,1,1
6,1,1,1,1,1,1,1,1,1,1,1,1,1,6
1,1,1,1,1,6,17,1,16,6,1,1,1,1,1
1,1,1,1,1,18,0,0,0,18,1,1,1,1,1
1,1,1,1,1,1,0,0,0,1,1,1,1,1,1
1,1,1,1,1,19,0,0,0,19,1,1,1,1,1
1,1,1,1,1,6,17,1,16,6,1,1,1,1,1
6,1,1,1,1,1,1,1,1,1,1,1,1,1,6
1,1,1,1,1,1,1,1,1,1,1,1,1,1,1
1,1,1,1,1,1,1,1,1,1,1,1,1,1,1
1,1,1,1,1,1,1,1,1,1,1,1,1,1,1
1,1,1,1,6,1,1,1,1,1,6,1,1,1,1
endlayer

layer
1,1,1,1,20,1,1,1,1,1,20,1,1,1,1
1,1,1,1,1,1,1,1,1,1,1,1,1,1,1
1,1,1,1,1,1,1,1,1,1,1,1,1,1,1
1,1,1,1,1,1,1,1,1,1,1,1,1,1,1
20,1,1,1,1,1,1,1,1,1,1,1,1,1,20
1,1,1,1,1,14,9,21,8,14,1,1,1,1,1
1,1,1,1,1,7,1,1,1,7,1,1,1,1,1
1,1,1,1,1,21,1,22,1,21,1,1,1,1,1
1,1,1,1,1,11,1,1,1,11,1,1,1,1,1
1,1,1,1,1,14,9,21,8,14,1,1,1,1,1
20,1,1,1,1,1,1,1,1,1,1,1,1,1,20
1,1,1,1,1,1,1,1,1,1,1,1,1,1,1
1,1,1,1,1,1,1,1,1,1,1,1,1,1,1
1,1,1,1,1,1,1,1,1,1,1,1,1,1,1
1,1,1,1,20,1,1,1,1,1,20,1,1,1,1
endlayer

