
# Created by Ruins mod version 17.1 Ingame Parser
# authoring Player: ST753M

weight=3
uniqueMinDistance=1000
embed_into_distance=5
acceptable_target_blocks=grass,dirt,sand,sandstone
unacceptable_target_blocks=flowing_water,water,flowing_lava,lava
dimensions=13,13,13
allowable_overhang=5
max_leveling=0
leveling_buffer=0
preserve_water=0
preserve_lava=0

biomesToSpawnIn=oasis

=0,100,air
rule1=0,100,preserveBlock
rule2=0,100,biomesoplenty:log_1-7
rule3=0,100,biomesoplenty:log_1-11
rule4=0,100,biomesoplenty:log_1-3
rule5=0,100,biomesoplenty:planks_0-8
rule6=0,100,biomesoplenty:planks_0-7
rule7=0,100,biomesoplenty:palm_door_block-1
rule8=0,100,biomesoplenty:palm_fence-0
rule9=0,100,teBlock;minecraft:bed;{color:13,x:-803497,y:107,z:-200727,id:"minecraft:bed"}-0
rule10=0,100,teBlock;minecraft:bed;{color:13,x:-803497,y:107,z:-200726,id:"minecraft:bed"}-8
rule11=0,100,teBlock;minecraft:bed;{color:13,x:-803496,y:107,z:-200727,id:"minecraft:bed"}-0
rule12=0,100,teBlock;minecraft:bed;{color:13,x:-803496,y:107,z:-200726,id:"minecraft:bed"}-8
rule13=0,100,teBlock;minecraft:flower_pot;{Item:"minecraft:red_flower",x:-803503,y:108,z:-200733,Data:0,id:"minecraft:flower_pot"}-0
rule14=1,100,minecraft:torch-5
rule15=0,100,biomesoplenty:palm_door_block-9
rule16=0,100,biomesoplenty:palm_door_block-8
rule17=0,100,minecraft:carpet-5,air,air
rule18=0,100,teBlock;minecraft:flower_pot;{Item:"minecraft:red_flower",x:-803497,y:108,z:-200725,Data:8,id:"minecraft:flower_pot"}-0
rule19=0,100,teBlock;minecraft:flower_pot;{Item:"minecraft:yellow_flower",x:-803494,y:108,z:-200732,Data:0,id:"minecraft:flower_pot"}-0
rule20=0,100,biomesoplenty:redwood_stairs-1
rule21=0,100,biomesoplenty:redwood_stairs-0
rule22=0,100,biomesoplenty:wood_slab_1-8
rule23=0,100,biomesoplenty:redwood_stairs-5
rule24=0,100,biomesoplenty:redwood_stairs-4
rule25=0,100,biomesoplenty:redwood_stairs-2
rule26=0,100,biomesoplenty:redwood_stairs-3
rule27=0,100,biomesoplenty:wood_slab_1-0

layer
1,1,1,1,1,1,1,1,1,1,1,1,1
1,1,1,1,1,1,2,1,1,1,1,2,1
1,1,1,1,1,1,1,1,1,1,1,1,1
1,1,1,1,1,1,1,1,1,1,1,1,1
1,1,1,1,1,1,1,1,1,1,1,1,1
1,1,1,1,1,1,1,1,1,1,1,1,1
1,2,1,1,1,1,2,1,1,1,1,2,1
1,1,1,1,1,1,1,1,1,1,1,1,1
1,1,1,1,1,1,1,1,1,1,1,1,1
1,1,1,1,1,1,1,1,1,1,1,1,1
1,1,1,1,1,1,1,1,1,1,1,1,1
1,2,1,1,1,1,2,1,1,1,1,2,1
1,1,1,1,1,1,1,1,1,1,1,1,1
endlayer

layer
1,1,1,1,1,1,1,1,1,1,1,1,1
1,1,1,1,1,1,2,1,1,1,1,2,1
1,1,1,1,1,1,1,1,1,1,1,1,1
1,1,1,1,1,1,1,1,1,1,1,1,1
1,1,1,1,1,1,1,1,1,1,1,1,1
1,1,1,1,1,1,1,1,1,1,1,1,1
1,2,1,1,1,1,2,1,1,1,1,2,1
1,1,1,1,1,1,1,1,1,1,1,1,1
1,1,1,1,1,1,1,1,1,1,1,1,1
1,1,1,1,1,1,1,1,1,1,1,1,1
1,1,1,1,1,1,1,1,1,1,1,1,1
1,2,1,1,1,1,2,1,1,1,1,2,1
1,1,1,1,1,1,1,1,1,1,1,1,1
endlayer

layer
1,1,1,1,1,1,1,1,1,1,1,1,1
1,1,1,1,1,1,2,1,1,1,1,2,1
1,1,1,1,1,1,1,1,1,1,1,1,1
1,1,1,1,1,1,1,1,1,1,1,1,1
1,1,1,1,1,1,1,1,1,1,1,1,1
1,1,1,1,1,1,1,1,1,1,1,1,1
1,2,1,1,1,1,2,1,1,1,1,2,1
1,1,1,1,1,1,1,1,1,1,1,1,1
1,1,1,1,1,1,1,1,1,1,1,1,1
1,1,1,1,1,1,1,1,1,1,1,1,1
1,1,1,1,1,1,1,1,1,1,1,1,1
1,2,1,1,1,1,2,1,1,1,1,2,1
1,1,1,1,1,1,1,1,1,1,1,1,1
endlayer

layer
1,1,1,1,1,1,1,1,1,1,1,1,1
1,1,1,1,1,1,2,1,1,1,1,2,1
1,1,1,1,1,1,1,1,1,1,1,1,1
1,1,1,1,1,1,1,1,1,1,1,1,1
1,1,1,1,1,1,1,1,1,1,1,1,1
1,1,1,1,1,1,1,1,1,1,1,1,1
1,2,1,1,1,1,2,1,1,1,1,2,1
1,1,1,1,1,1,1,1,1,1,1,1,1
1,1,1,1,1,1,1,1,1,1,1,1,1
1,1,1,1,1,1,1,1,1,1,1,1,1
1,1,1,1,1,1,1,1,1,1,1,1,1
1,2,1,1,1,1,2,1,1,1,1,2,1
1,1,1,1,1,1,1,1,1,1,1,1,1
endlayer

layer
1,1,1,1,1,1,1,1,1,1,1,1,1
1,1,1,1,1,1,2,3,3,3,3,2,1
1,1,1,1,1,1,4,5,5,5,5,4,1
1,1,1,1,1,1,4,5,5,5,5,4,1
1,1,1,1,1,1,4,5,5,5,5,4,1
1,1,1,1,1,1,4,5,5,5,5,4,1
1,2,3,3,3,3,2,5,5,5,5,2,1
1,4,5,5,5,5,5,5,5,5,5,4,1
1,4,5,5,5,5,5,5,5,5,5,4,1
1,4,5,5,5,5,5,5,5,5,5,4,1
1,4,5,5,5,5,5,5,5,5,5,4,1
1,2,3,3,3,3,2,3,3,3,3,2,1
1,1,1,1,1,1,1,1,1,1,1,1,1
endlayer

layer
1,1,1,1,1,1,1,1,1,1,1,1,1
1,1,1,1,1,1,2,6,6,6,6,2,1
1,1,1,1,1,1,6,3,3,3,3,6,1
1,1,1,1,1,1,7,0,0,0,0,6,1
1,1,1,1,1,1,7,0,0,0,0,6,1
1,1,1,1,1,1,6,0,0,0,0,6,1
1,2,6,6,6,6,2,0,0,0,0,2,1
1,6,8,0,0,0,6,0,0,0,0,6,1
1,6,10,9,0,0,7,0,0,0,0,6,1
1,6,12,11,0,0,7,0,0,0,0,6,1
1,6,8,0,0,0,6,3,3,3,3,6,1
1,2,6,6,6,6,2,6,6,6,6,2,1
1,1,1,1,1,1,1,1,1,1,1,1,1
endlayer

layer
1,1,1,1,1,1,1,1,1,1,1,1,1
1,1,1,1,1,1,2,6,0,0,6,2,1
1,1,1,1,1,1,6,0,0,13,0,6,1
1,1,1,1,1,1,15,0,0,0,0,14,1
1,1,1,1,1,1,16,0,0,0,0,0,1
1,1,1,1,1,1,6,0,0,0,0,6,1
1,2,6,0,14,6,2,0,0,0,0,2,1
1,6,17,0,0,0,6,0,0,0,0,6,1
1,18,0,0,0,0,15,0,0,0,0,0,1
1,0,0,0,0,0,16,0,0,0,0,0,1
1,6,17,0,0,0,6,0,0,0,0,6,1
1,2,6,0,0,6,2,6,19,0,6,2,1
1,1,1,1,1,1,1,1,1,1,1,1,1
endlayer

layer
1,1,1,1,1,1,1,1,1,1,1,1,1
1,1,1,1,1,1,2,6,0,0,6,2,1
1,1,1,1,1,1,6,0,0,0,0,6,1
1,1,1,1,1,1,20,0,0,0,0,0,1
1,1,1,1,1,1,21,0,0,0,0,0,1
1,1,1,1,1,1,6,0,0,0,0,6,1
1,2,6,0,0,6,2,0,0,0,0,2,1
1,6,0,0,0,0,6,0,0,0,0,6,1
1,0,0,0,0,0,20,0,0,0,0,0,1
1,0,0,0,0,0,21,0,0,0,0,0,1
1,6,0,0,0,0,6,0,0,0,0,6,1
1,2,6,0,0,6,2,6,0,0,6,2,1
1,1,1,1,1,1,1,1,1,1,1,1,1
endlayer

layer
1,1,1,1,1,1,1,1,22,22,1,1,1
1,1,1,1,1,1,2,6,22,22,6,2,1
1,1,1,1,1,1,6,0,0,0,0,6,1
1,1,1,1,1,22,23,0,0,0,0,22,22
1,1,1,1,1,22,24,0,0,0,0,22,22
1,1,1,22,22,1,6,0,0,0,0,6,1
1,2,6,22,22,6,2,8,8,8,8,2,1
1,6,0,0,0,0,6,0,0,0,0,6,1
22,22,0,0,0,0,23,0,0,0,0,22,22
22,22,0,0,0,0,24,0,0,0,0,22,22
1,6,0,0,0,0,6,0,0,0,0,6,1
1,2,6,22,22,6,2,6,22,22,6,2,1
1,1,1,22,22,1,1,1,22,22,1,1,1
endlayer

layer
1,1,1,1,1,1,1,1,1,1,1,1,1
1,1,1,1,1,1,2,6,6,6,6,2,1
1,1,1,1,1,1,6,22,22,22,22,6,1
1,1,1,1,1,1,6,22,0,0,22,6,1
1,1,1,1,1,1,6,22,0,0,22,6,1
1,1,1,1,1,1,6,22,22,22,22,6,1
1,2,6,6,6,6,2,3,3,3,3,2,1
1,6,22,22,22,22,6,22,22,22,22,6,1
1,6,22,0,0,22,6,22,0,0,22,6,1
1,6,22,0,0,22,6,22,0,0,22,6,1
1,6,22,22,22,22,6,22,22,22,22,6,1
1,2,6,6,6,6,2,6,6,6,6,2,1
1,1,1,1,1,1,1,1,1,1,1,1,1
endlayer

layer
1,1,1,1,1,26,21,21,21,21,21,21,25
1,1,1,1,1,26,2,3,3,3,3,2,25
1,1,1,1,1,26,4,8,8,8,8,4,25
1,1,1,1,1,26,4,8,0,0,8,4,25
1,1,1,1,1,26,4,8,0,0,8,4,25
21,21,21,21,21,21,4,8,8,8,8,4,25
26,2,3,3,3,3,2,3,3,3,3,2,25
26,4,8,8,8,8,4,8,8,8,8,4,25
26,4,8,0,0,8,4,8,0,0,8,4,25
26,4,8,0,0,8,4,8,0,0,8,4,25
26,4,8,8,8,8,4,8,8,8,8,4,25
26,2,3,3,3,3,2,3,3,3,3,2,25
26,20,20,20,20,20,20,20,20,20,20,20,20
endlayer

layer
1,1,1,1,1,1,1,1,1,1,1,1,1
1,1,1,1,1,1,2,21,21,21,21,2,1
1,1,1,1,1,1,26,8,8,8,8,25,1
1,1,1,1,1,1,26,8,0,0,8,25,1
1,1,1,1,1,1,26,8,0,0,8,25,1
1,1,1,1,1,1,26,8,8,8,8,25,1
1,2,21,21,21,21,2,5,5,5,5,2,1
1,26,8,8,8,8,5,8,8,8,8,25,1
1,26,8,0,0,8,5,8,0,0,8,25,1
1,26,8,0,0,8,5,8,0,0,8,25,1
1,26,8,8,8,8,5,8,8,8,8,25,1
1,2,20,20,20,20,2,20,20,20,20,2,1
1,1,1,1,1,1,1,1,1,1,1,1,1
endlayer

layer
1,1,1,1,1,1,1,1,1,1,1,1,1
1,1,1,1,1,1,2,1,1,1,1,2,1
1,1,1,1,1,1,1,27,27,27,27,1,1
1,1,1,1,1,1,1,27,0,0,27,1,1
1,1,1,1,1,1,1,27,0,0,27,1,1
1,1,1,1,1,1,1,27,27,27,27,1,1
1,2,1,1,1,1,2,27,27,27,27,2,1
1,1,27,27,27,27,27,27,27,27,27,1,1
1,1,27,0,0,27,27,27,0,0,27,1,1
1,1,27,0,0,27,27,27,0,0,27,1,1
1,1,27,27,27,27,27,27,27,27,27,1,1
1,2,1,1,1,1,2,1,1,1,1,2,1
1,1,1,1,1,1,1,1,1,1,1,1,1
endlayer

