
# Created by Ruins mod version 17.1 Ingame Parser
# authoring Player: ST753M

weight=7
embed_into_distance=2
acceptable_target_blocks=grass,dirt,sand,sandstone
unacceptable_target_blocks=flowing_water,water,flowing_lava,lava
dimensions=6,11,11
allowable_overhang=2
max_leveling=2
leveling_buffer=0
preserve_water=0
preserve_lava=0

biomesToSpawnIn=overgrown_beach,oasis

=0,100,preserveBlock
rule1=0,100,biomesoplenty:log_1-7

rule2=0,100,biomesoplenty:planks_0-8
^0,100,biomesoplenty:planks_0-10
^0,100,biomesoplenty:planks_0-0
^0,100,biomesoplenty:planks_0-6

rule3^0,100,biomesoplenty:wood_slab_1-0,biomesoplenty:redwood_stairs-1,biomesoplenty:redwood_stairs-2,biomesoplenty:redwood_stairs-3,biomesoplenty:redwood_stairs-0
^0,100,biomesoplenty:pine_stairs-1,biomesoplenty:pine_stairs-3,biomesoplenty:pine_stairs-0,biomesoplenty:pine_stairs-2,biomesoplenty:wood_slab_1-2
^0,100,biomesoplenty:sacred_oak_stairs-2,biomesoplenty:sacred_oak_stairs-1,biomesoplenty:sacred_oak_stairs-3,biomesoplenty:sacred_oak_stairs-0,biomesoplenty:wood_slab_0-0
^0,100,biomesoplenty:mangrove_stairs-1,biomesoplenty:mangrove_stairs-3,biomesoplenty:mangrove_stairs-0,biomesoplenty:mangrove_stairs-2,biomesoplenty:wood_slab_0-6

rule4=0,100,biomesoplenty:planks_0-7
rule5=0,80,ChestGenHook:chests/spawn_bonus_chest:2-2
rule6=0,30,ChestGenHook:chests/jungle_temple:1-3
rule7=0,10,ChestGenHook:chests/desert_pyramid:4-4
rule8=0,50,biomesoplenty:terrarium-7

layer
1,0,0,0,0,0,0,1,0,0,0
0,2,2,2,2,2,2,0,0,0,0
0,2,2,2,2,2,2,0,0,0,0
0,2,2,2,2,2,2,0,0,0,0
0,2,2,2,2,2,2,1,0,0,1
0,2,2,2,2,2,2,2,2,2,0
1,0,1,2,2,2,2,2,2,2,0
0,0,0,2,2,2,2,2,2,2,0
0,0,0,2,2,2,2,2,2,2,0
0,0,0,2,2,2,2,2,2,2,0
0,0,1,0,0,0,0,0,0,0,1
endlayer

layer
1,1,1,1,1,1,1,1,0,0,0
1,2,2,3,3,3,3,1,0,0,0
1,2,2,3,3,3,3,1,0,0,0
1,2,3,3,3,3,3,1,0,0,0
1,3,2,3,3,3,2,1,1,1,1
1,3,2,3,3,2,2,2,2,2,1
1,1,1,2,3,2,3,3,3,2,1
0,0,1,3,3,3,2,3,3,3,1
0,0,1,3,3,3,3,3,3,3,1
0,0,1,2,2,3,3,3,3,3,1
0,0,1,1,1,1,1,1,1,1,1
endlayer

layer
1,4,4,4,4,4,4,1,0,0,0
4,5,0,0,0,0,0,4,0,0,0
4,0,0,0,0,0,0,4,0,0,0
4,0,0,0,0,0,0,4,0,0,0
4,0,0,0,0,0,0,1,4,4,1
4,0,4,0,0,0,4,4,0,6,4
1,4,1,0,0,4,0,0,0,4,4
0,0,4,0,0,0,0,0,0,0,4
0,0,4,0,0,0,0,0,0,0,4
0,0,4,7,0,0,0,0,0,0,4
0,0,1,4,4,4,4,4,4,4,1
endlayer

layer
1,4,4,4,0,4,4,1,0,0,0
0,0,0,0,0,0,0,4,0,0,0
4,0,0,0,0,0,0,0,0,0,0
4,0,0,0,0,0,0,4,0,0,0
4,0,0,0,0,0,0,1,4,4,0
4,0,0,0,0,0,4,0,0,0,4
1,0,1,0,0,8,0,0,0,0,4
0,0,4,0,0,0,0,0,0,0,0
0,0,4,0,0,0,0,0,0,0,4
0,0,4,0,0,0,0,0,0,0,0
0,0,1,4,0,4,4,4,4,0,1
endlayer

layer
1,4,0,4,0,0,0,1,0,0,0
0,0,0,0,0,0,0,4,0,0,0
0,0,0,0,0,0,0,0,0,0,0
4,0,0,0,0,0,0,0,0,0,0
4,0,0,0,0,0,0,1,4,4,0
0,0,0,0,0,0,4,0,0,0,0
0,0,1,0,0,0,0,0,0,0,4
0,0,0,0,0,0,0,0,0,0,4
0,0,0,0,0,0,0,0,0,0,4
0,0,4,0,0,0,0,0,0,0,0
0,0,1,0,0,4,0,4,4,0,0
endlayer

layer
0,0,0,0,0,0,0,0,0,0,0
0,0,0,0,0,0,0,4,0,0,0
0,0,0,0,0,0,0,4,0,0,0
0,0,0,0,0,0,0,4,0,0,0
0,0,0,0,0,0,0,1,0,4,0
0,0,0,0,0,0,0,0,0,0,0
0,0,0,0,0,0,0,0,0,0,0
0,0,0,0,0,0,0,0,0,0,0
0,0,0,0,0,0,0,0,0,0,4
0,0,4,0,0,0,0,0,0,0,0
0,0,0,0,0,0,0,4,0,0,0
endlayer

