
# Created by Ruins mod version 17.1 Ingame Parser
# authoring Player: ST753M

weight=2
embed_into_distance=3
acceptable_target_blocks=
unacceptable_target_blocks=flowing_water,water,flowing_lava,lava,ice,bedrock,netherrack,nether_brick,nether_brick_fence,soul_sand,quartz_ore,end_stone,obsidian,iron_bars,Natura:Cloud,slime_grass,slime_congealed,slime_dirt,clouds,natura:clouds,twilightforest:wispy_cloud,twilightforest:fluffy_cloud
dimensions=6,17,9
allowable_overhang=4
max_leveling=0
leveling_buffer=0
preserve_water=0
preserve_lava=0

biomesToSpawnIn=brushland

=0,100,preserveBlock
rule1=0,100,minecraft:stone-5
rule2=0,100,minecraft:stone-6
rule3=0,100,biomesoplenty:log_3-2
rule4=0,100,biomesoplenty:log_3-10
rule5=0,100,biomesoplenty:planks_0-14
rule6=0,100,biomesoplenty:wood_slab_1-6
rule7=0,100,biomesoplenty:ebony_stairs-4
rule8=0,100,biomesoplenty:ebony_stairs-3

rule9=0,30,minecraft:crafting_table-0,minecraft:furnace-2,minecraft:redstone_lamp-0,minecraft:trapped_chest-2,minecraft:anvil-0,minecraft:lit_pumpkin-2,minecraft:anvil-5,minecraft:jukebox-0,minecraft:anvil-9,minecraft:enchanting_table-0,minecraft:ender_chest-2,minecraft:bookshelf-0,minecraft:noteblock-0,minecraft:piston-1,minecraft:cobblestone_wall-0,minecraft:furnace-1,minecraft:furnace-0,minecraft:trapped_chest-2,minecraft:bookshelf-0,minecraft:bookshelf-0,minecraft:bookshelf-0,minecraft:noteblock-0,minecraft:cobblestone_wall-0,minecraft:cobblestone_wall-0,minecraft:piston-1,minecraft:noteblock-0

rule10=0,100,biomesoplenty:ebony_stairs-6
rule11=0,100,biomesoplenty:ebony_stairs-2
rule12=0,100,biomesoplenty:ebony_stairs-1
rule13=0,100,biomesoplenty:ebony_stairs-0
rule14=0,100,biomesoplenty:ebony_stairs-5
rule15=0,100,biomesoplenty:wood_slab_1-14

layer
0,0,1,1,1,1,1,0,0
0,1,1,1,1,1,1,1,0
1,1,1,1,1,1,1,1,1
1,1,1,1,1,1,1,1,1
1,1,1,1,1,1,1,1,1
1,1,1,1,1,1,1,1,1
1,1,1,1,1,1,1,1,1
1,1,1,1,1,1,1,1,1
1,1,1,1,1,1,1,1,1
0,1,1,1,1,1,1,1,1
0,0,1,1,1,1,1,1,1
0,0,1,1,1,1,1,1,1
0,0,1,1,1,1,1,1,1
0,0,1,1,1,1,1,1,1
0,0,1,1,1,1,1,1,1
0,0,0,1,1,1,1,1,0
0,0,0,0,1,1,1,0,0
endlayer

layer
0,1,1,1,1,1,1,1,0
1,1,1,1,1,1,1,1,1
1,1,1,1,1,1,1,1,1
1,1,1,1,1,1,1,1,1
1,1,1,1,1,1,1,1,1
1,1,1,1,1,1,1,1,1
1,1,1,1,1,1,1,1,1
1,1,1,1,1,1,1,1,1
1,1,1,1,1,1,1,1,1
1,1,1,1,1,1,1,1,1
0,1,1,1,1,1,1,1,1
0,0,1,1,1,1,1,1,1
0,0,1,1,1,1,1,1,1
0,0,1,1,1,1,1,1,1
0,0,1,1,1,1,1,1,1
0,0,1,1,1,1,1,1,1
0,0,0,1,1,1,1,1,0
endlayer

layer
2,2,2,2,2,2,2,2,2
2,3,4,3,4,3,4,3,2
2,4,0,4,3,4,3,4,2
2,3,4,3,0,3,4,3,2
2,4,3,0,0,0,3,4,2
2,3,4,3,0,0,4,3,2
2,4,3,4,0,0,0,4,2
2,3,4,3,4,0,0,3,2
2,4,3,4,3,0,0,4,2
2,3,4,3,4,0,0,0,2
2,2,2,4,3,4,0,0,2
0,0,2,3,4,3,4,0,2
0,0,2,4,3,4,3,4,2
0,0,2,3,4,3,4,3,2
0,0,2,4,3,4,3,4,2
0,0,2,3,4,3,4,3,2
0,0,2,2,2,2,2,2,2
endlayer

layer
2,5,7,5,2,5,6,5,2
5,9,9,9,9,0,0,0,8
6,0,0,0,0,0,0,0,5
0,0,0,0,0,0,0,0,10
0,0,0,0,0,0,0,0,2
2,0,0,0,0,0,0,0,5
12,0,0,0,0,0,0,0,11
0,0,0,0,0,0,0,0,6
0,0,0,0,0,0,0,0,2
6,0,0,0,0,0,0,0,0
2,5,2,0,0,0,0,0,0
0,0,11,0,0,0,0,0,0
0,0,5,0,0,0,0,0,2
0,0,0,0,0,0,0,0,0
0,0,0,0,0,0,0,0,0
0,0,6,0,0,0,0,0,8
0,0,2,11,6,0,0,0,2
endlayer

layer
2,12,0,0,2,0,0,13,2
5,0,0,0,0,0,0,0,14
0,0,0,0,0,0,0,0,0
0,0,0,0,0,0,0,0,5
0,0,0,0,0,0,0,0,2
2,0,0,0,0,0,0,0,12
0,0,0,0,0,0,0,0,0
0,0,0,0,0,0,0,0,0
0,0,0,0,0,0,0,0,2
0,0,0,0,0,0,0,0,0
0,5,2,0,0,0,0,0,0
0,0,15,0,0,0,0,0,0
0,0,12,0,0,0,0,0,2
0,0,0,0,0,0,0,0,0
0,0,0,0,0,0,0,0,0
0,0,0,0,0,0,0,0,0
0,0,2,13,0,0,0,0,0
endlayer

layer
2,0,0,0,0,0,0,0,2
6,0,0,0,0,0,0,0,0
0,0,0,0,0,0,0,0,0
0,0,0,0,0,0,0,0,0
0,0,0,0,0,0,0,0,2
0,0,0,0,0,0,0,0,6
0,0,0,0,0,0,0,0,0
0,0,0,0,0,0,0,0,0
0,0,0,0,0,0,0,0,2
0,0,0,0,0,0,0,0,0
0,0,0,0,0,0,0,0,0
0,0,5,0,0,0,0,0,0
0,0,0,0,0,0,0,0,0
0,0,0,0,0,0,0,0,0
0,0,0,0,0,0,0,0,0
0,0,0,0,0,0,0,0,0
0,0,2,0,0,0,0,0,0
endlayer

