
# Created by Ruins mod version 17.0 Ingame Parser
# authoring Player: ST753M

weight=1
embed_into_distance=2
acceptable_target_blocks=
unacceptable_target_blocks=flowing_water,water,flowing_lava,lava,ice,bedrock,netherrack,nether_brick,nether_brick_fence,soul_sand,quartz_ore,end_stone,obsidian,iron_bars,Natura:Cloud,slime_grass,slime_congealed,slime_dirt,clouds,natura:clouds
dimensions=12,23,23
allowable_overhang=2
max_leveling=2
leveling_buffer=0
preserve_water=1
preserve_lava=1

biomesToSpawnIn=deep_ocean

=0,100,preserveBlock
rule1=0,100,minecraft:prismarine-0
^0,100,minecraft:prismarine-1
^0,100,minecraft:prismarine-2
rule2=0,100,minecraft:prismarine-0
^0,100,minecraft:prismarine-1
^0,100,minecraft:prismarine-0
rule3=0,100,minecraft:water-0
rule4=0,100,minecraft:prismarine-0
^0,100,minecraft:prismarine-1
^0,100,minecraft:prismarine-2

rule5=0,30,IInventory;minecraft:chest;minecraft:slime_ball#3#0#2+minecraft:gold_nugget#5#0#3+minecraft:record_blocks#1#0#5+minecraft:gold_nugget#2#0#9+minecraft:slime_ball#1#0#12+minecraft:gold_nugget#1#0#14+minecraft:gold_nugget#3#0#15+minecraft:gold_nugget#3#0#17+minecraft:jungle_boat#1#0#20+minecraft:fish#10#0#23+minecraft:slime_ball#4#0#25-2,IInventory;minecraft:chest;minecraft:coal#3#0#1+minecraft:record_mellohi#1#0#2+minecraft:dye#7#4#4+minecraft:skull#1#0#7+minecraft:dye#4#4#9+minecraft:coal#7#0#14+minecraft:dye#3#4#20+minecraft:fish#11#0#21+minecraft:boat#1#0#24+minecraft:coal#4#0#25-2,IInventory;minecraft:chest;minecraft:dye#4#4#0+minecraft:dye#3#4#4+minecraft:fish#11#0#6+minecraft:ender_pearl#1#0#10+minecraft:spruce_boat#1#0#12+minecraft:dye#7#4#14+minecraft:skull#1#0#15+minecraft:record_11#1#0#23+minecraft:ender_pearl#3#0#26-2,IInventory;minecraft:chest;minecraft:experience_bottle#4#0#1+minecraft:diamond#2#0#3+minecraft:skull#1#1#8+minecraft:record_far#1#0#11+minecraft:birch_boat#1#0#15+minecraft:slime_ball#1#0#17+minecraft:slime_ball#2#0#18+minecraft:slime_ball#1#0#19+minecraft:fish#11#1#22-2,IInventory;minecraft:chest;minecraft:rotten_flesh#5#0#1+minecraft:gold_nugget#3#0#3+minecraft:jungle_boat#1#0#5+minecraft:gold_nugget#7#0#13+minecraft:emerald#3#0#16+minecraft:gold_nugget#4#0#18+minecraft:fish#10#3#20+minecraft:rotten_flesh#3#0#23+minecraft:rotten_flesh#3#0#25-2,IInventory;minecraft:chest;minecraft:fish#10#0#1+minecraft:skull#1#2#6+minecraft:bone#5#0#13+minecraft:record_13#1#0#15+minecraft:bone#4#0#17+minecraft:diamond#3#0#18+minecraft:dark_oak_boat#1#0#20+minecraft:bone#1#0#25-2,IInventory;minecraft:chest;minecraft:rotten_flesh#4#0#2+minecraft:gold_nugget#3#0#4+minecraft:rotten_flesh#1#0#9+minecraft:fish#11#0#10+minecraft:record_cat#1#0#12+minecraft:dark_oak_boat#1#0#16+minecraft:rotten_flesh#4#0#18+minecraft:gold_nugget#2#0#19+minecraft:skull#1#3#22+minecraft:rotten_flesh#9#0#23+minecraft:gold_nugget#1#0#26-2,IInventory;minecraft:chest;minecraft:fish#11#1#4+minecraft:pumpkin_seeds#2#0#9+minecraft:acacia_boat#1#0#11+minecraft:diamond_horse_armor#1#0#14+minecraft:golden_apple#1#1#17+minecraft:pumpkin_seeds#4#0#21+minecraft:record_strad#1#0#24-2,IInventory;minecraft:chest;minecraft:boat#1#0#2+minecraft:fish#12#2#14+minecraft:record_chirp#1#0#25-2,IInventory;minecraft:chest;minecraft:diamond#2#0#0+minecraft:rotten_flesh#5#0#3+minecraft:coal#4#0#5+minecraft:rotten_flesh#5#0#9+minecraft:fish#12#3#11+minecraft:bucket#1#0#13+minecraft:rotten_flesh#3#0#15+minecraft:coal#4#0#17+minecraft:coal#5#0#21+minecraft:birch_boat#1#0#24+minecraft:rotten_flesh#2#0#25-2,IInventory;minecraft:chest;minecraft:gold_nugget#2#0#1+minecraft:skull#1#0#4+minecraft:gold_nugget#2#0#7+minecraft:gold_nugget#2#0#12+minecraft:record_wait#1#0#15+minecraft:jungle_boat#1#0#20+minecraft:fish#10#1#22+minecraft:bucket#2#0#25-2,IInventory;minecraft:chest;minecraft:ender_pearl#2#0#2+minecraft:fish#11#0#5+minecraft:gold_nugget#4#0#7+minecraft:skull#1#2#9+minecraft:gold_nugget#4#0#13+minecraft:boat#1#0#16+minecraft:record_mall#1#0#19+minecraft:gold_nugget#4#0#20+minecraft:ender_pearl#2#0#23-2,IInventory;minecraft:chest;minecraft:melon_seeds#2#0#4+minecraft:golden_apple#1#1#8+minecraft:record_ward#1#0#10+minecraft:bucket#2#0#11+minecraft:boat#1#0#15+minecraft:melon_seeds#3#0#18+minecraft:fish#10#2#21+minecraft:bucket#1#0#26-2,IInventory;minecraft:chest;minecraft:record_stal#1#0#5+minecraft:spruce_boat#1#0#11+minecraft:fish#10#3#15-2,IInventory;minecraft:chest;minecraft:slime_ball#2#0#0+minecraft:ender_pearl#2#0#4+minecraft:slime_ball#1#0#7+minecraft:spruce_boat#1#0#12+minecraft:fish#10#2#15+minecraft:ender_pearl#1#0#19+minecraft:bucket#1#0#22+minecraft:emerald#2#0#25-2

rule6=0,100,air
rule7=0,100,minecraft:stained_glass-9
^0,100,preserveBlock

layer
1,1,1,1,1,1,1,1,1,1,1,1,1,1,1,1,1,1,1,1,1,1,1
1,1,1,1,1,1,1,1,1,1,1,1,1,1,1,1,1,1,1,1,1,1,1
1,1,1,1,1,1,1,1,1,1,1,1,1,1,1,1,1,1,1,1,1,1,1
1,1,1,1,1,1,1,1,1,1,1,1,1,1,1,1,1,1,1,1,1,1,1
1,1,1,1,1,1,1,1,1,1,1,1,1,1,1,1,1,1,1,1,1,1,1
1,1,1,1,1,1,1,1,1,1,1,1,1,1,1,1,1,1,1,1,1,1,1
1,1,1,1,1,1,1,1,1,1,1,1,1,1,1,1,1,1,1,1,1,1,1
1,1,1,1,1,1,1,1,1,1,1,1,1,1,1,1,1,1,1,1,1,1,1
1,1,1,1,1,1,1,1,1,1,1,1,1,1,1,1,1,1,1,1,1,1,1
1,1,1,1,1,1,1,1,1,1,1,1,1,1,1,1,1,1,1,1,1,1,1
1,1,1,1,1,1,1,1,1,1,1,1,1,1,1,1,1,1,1,1,1,1,1
1,1,1,1,1,1,1,1,1,1,1,1,1,1,1,1,1,1,1,1,1,1,1
1,1,1,1,1,1,1,1,1,1,1,1,1,1,1,1,1,1,1,1,1,1,1
1,1,1,1,1,1,1,1,1,1,1,1,1,1,1,1,1,1,1,1,1,1,1
1,1,1,1,1,1,1,1,1,1,1,1,1,1,1,1,1,1,1,1,1,1,1
1,1,1,1,1,1,1,1,1,1,1,1,1,1,1,1,1,1,1,1,1,1,1
1,1,1,1,1,1,1,1,1,1,1,1,1,1,1,1,1,1,1,1,1,1,1
1,1,1,1,1,1,1,1,1,1,1,1,1,1,1,1,1,1,1,1,1,1,1
1,1,1,1,1,1,1,1,1,1,1,1,1,1,1,1,1,1,1,1,1,1,1
1,1,1,1,1,1,1,1,1,1,1,1,1,1,1,1,1,1,1,1,1,1,1
1,1,1,1,1,1,1,1,1,1,1,1,1,1,1,1,1,1,1,1,1,1,1
1,1,1,1,1,1,1,1,1,1,1,1,1,1,1,1,1,1,1,1,1,1,1
1,1,1,1,1,1,1,1,1,1,1,1,1,1,1,1,1,1,1,1,1,1,1
endlayer

layer
1,1,1,1,1,1,1,1,1,1,1,1,1,1,1,1,1,1,1,1,1,1,1
1,1,1,1,1,1,1,1,1,1,1,1,1,1,1,1,1,1,1,1,1,1,1
1,1,1,1,1,1,1,1,1,1,1,1,1,1,1,1,1,1,1,1,1,1,1
1,1,1,1,1,1,1,1,1,1,1,1,1,1,1,1,1,1,1,1,1,1,1
1,1,1,1,1,1,1,1,1,1,1,1,1,1,1,1,1,1,1,1,1,1,1
1,1,1,1,1,1,1,1,1,1,1,1,1,1,1,1,1,1,1,1,1,1,1
1,1,1,1,1,1,1,1,1,1,1,2,1,1,1,1,1,1,1,1,1,1,1
1,1,1,1,1,1,1,1,1,1,1,2,1,1,1,1,1,1,1,1,1,1,1
1,1,1,1,1,1,1,1,1,2,2,1,2,2,1,1,1,1,1,1,1,1,1
1,1,1,1,1,1,1,1,2,1,1,2,1,1,2,1,1,1,1,1,1,1,1
1,1,1,1,1,1,1,1,2,1,2,2,2,1,2,1,1,1,1,1,1,1,1
1,1,1,1,1,1,2,2,1,2,2,1,2,2,1,2,2,1,1,1,1,1,1
1,1,1,1,1,1,1,1,2,1,2,2,2,1,2,1,1,1,1,1,1,1,1
1,1,1,1,1,1,1,1,2,1,1,2,1,1,2,1,1,1,1,1,1,1,1
1,1,1,1,1,1,1,1,1,2,2,1,2,2,1,1,1,1,1,1,1,1,1
1,1,1,1,1,1,1,1,1,1,1,2,1,1,1,1,1,1,1,1,1,1,1
1,1,1,1,1,1,1,1,1,1,1,2,1,1,1,1,1,1,1,1,1,1,1
1,1,1,1,1,1,1,1,1,1,1,1,1,1,1,1,1,1,1,1,1,1,1
1,1,1,1,1,1,1,1,1,1,1,1,1,1,1,1,1,1,1,1,1,1,1
1,1,1,1,1,1,1,1,1,1,1,1,1,1,1,1,1,1,1,1,1,1,1
1,1,1,1,1,1,1,1,1,1,1,1,1,1,1,1,1,1,1,1,1,1,1
1,1,1,1,1,1,1,1,1,1,1,1,1,1,1,1,1,1,1,1,1,1,1
1,1,1,1,1,1,1,1,1,1,1,1,1,1,1,1,1,1,1,1,1,1,1
endlayer

layer
0,0,0,0,0,0,0,0,0,0,0,0,0,0,0,0,0,0,0,0,0,0,0
0,1,1,1,1,1,1,1,1,1,1,1,1,1,1,1,1,1,1,1,1,1,0
0,1,1,1,1,1,1,1,1,1,1,1,1,1,1,1,1,1,1,1,1,1,0
0,1,1,1,1,1,1,1,1,1,1,1,1,1,1,1,1,1,1,1,1,1,0
0,1,1,1,3,3,3,3,3,3,3,3,3,3,3,3,3,3,3,1,1,1,0
0,1,1,1,3,3,3,3,3,3,3,3,3,3,3,3,3,3,3,1,1,1,0
0,1,1,1,3,3,4,3,3,4,3,3,3,4,3,3,4,3,3,1,1,1,0
0,1,1,1,3,3,3,3,3,3,3,3,3,3,3,3,3,3,3,1,1,1,0
0,1,1,1,3,3,3,3,3,3,3,3,3,3,3,3,3,3,3,1,1,1,0
0,1,1,1,3,3,4,3,3,3,3,3,3,3,3,3,4,3,3,1,1,1,0
0,1,1,1,3,3,3,3,3,3,3,3,3,3,3,3,3,3,3,1,1,1,0
0,1,1,1,3,3,3,3,3,3,3,5,3,3,3,3,3,3,3,1,1,1,0
0,1,1,1,3,3,3,3,3,3,3,3,3,3,3,3,3,3,3,1,1,1,0
0,1,1,1,3,3,4,3,3,3,3,3,3,3,3,3,4,3,3,1,1,1,0
0,1,1,1,3,3,3,3,3,3,3,3,3,3,3,3,3,3,3,1,1,1,0
0,1,1,1,3,3,3,3,3,3,3,3,3,3,3,3,3,3,3,1,1,1,0
0,1,1,1,3,3,4,3,3,4,3,3,3,4,3,3,4,3,3,1,1,1,0
0,1,1,1,3,3,3,3,3,3,3,3,3,3,3,3,3,3,3,1,1,1,0
0,1,1,1,3,3,3,3,3,3,3,3,3,3,3,3,3,3,3,1,1,1,0
0,1,1,1,1,1,1,1,1,1,1,1,1,1,1,1,1,1,1,1,1,1,0
0,1,1,1,1,1,1,1,1,1,1,1,1,1,1,1,1,1,1,1,1,1,0
0,1,1,1,1,1,1,1,1,1,1,1,1,1,1,1,1,1,1,1,1,1,0
0,0,0,0,0,0,0,0,0,0,0,0,0,0,0,0,0,0,0,0,0,0,0
endlayer

layer
0,0,0,0,0,0,0,0,0,0,0,0,0,0,0,0,0,0,0,0,0,0,0
0,0,0,0,0,0,0,0,0,0,0,0,0,0,0,0,0,0,0,0,0,0,0
0,0,4,0,0,4,0,0,4,0,0,4,0,0,4,0,0,4,0,0,4,0,0
0,0,0,0,0,0,0,0,0,0,0,0,0,0,0,0,0,0,0,0,0,0,0
0,0,0,0,0,0,0,0,0,0,0,0,0,0,0,0,0,0,0,0,0,0,0
0,0,4,0,0,0,0,0,0,0,0,0,0,0,0,0,0,0,0,0,4,0,0
0,0,0,0,0,0,4,0,0,4,0,0,0,4,0,0,4,0,0,0,0,0,0
0,0,0,0,0,0,0,0,0,0,0,0,0,0,0,0,0,0,0,0,0,0,0
0,0,4,0,0,0,0,0,0,0,0,0,0,0,0,0,0,0,0,0,4,0,0
0,0,0,0,0,0,4,0,0,0,0,0,0,0,0,0,4,0,0,0,0,0,0
0,0,0,0,0,0,0,0,0,0,0,0,0,0,0,0,0,0,0,0,0,0,0
0,0,4,0,0,0,0,0,0,0,0,0,0,0,0,0,0,0,0,0,4,0,0
0,0,0,0,0,0,0,0,0,0,0,0,0,0,0,0,0,0,0,0,0,0,0
0,0,0,0,0,0,4,0,0,0,0,0,0,0,0,0,4,0,0,0,0,0,0
0,0,4,0,0,0,0,0,0,0,0,0,0,0,0,0,0,0,0,0,4,0,0
0,0,0,0,0,0,0,0,0,0,0,0,0,0,0,0,0,0,0,0,0,0,0
0,0,0,0,0,0,4,0,0,4,0,0,0,4,0,0,4,0,0,0,0,0,0
0,0,4,0,0,0,0,0,0,0,0,0,0,0,0,0,0,0,0,0,4,0,0
0,0,0,0,0,0,0,0,0,0,0,0,0,0,0,0,0,0,0,0,0,0,0
0,0,0,0,0,0,0,0,0,0,0,0,0,0,0,0,0,0,0,0,0,0,0
0,0,4,0,0,4,0,0,4,0,0,4,0,0,4,0,0,4,0,0,4,0,0
0,0,0,0,0,0,0,0,0,0,0,0,0,0,0,0,0,0,0,0,0,0,0
0,0,0,0,0,0,0,0,0,0,0,0,0,0,0,0,0,0,0,0,0,0,0
endlayer

layer
0,0,0,0,0,0,0,0,0,0,0,0,0,0,0,0,0,0,0,0,0,0,0
0,0,0,0,0,0,0,0,0,0,0,0,0,0,0,0,0,0,0,0,0,0,0
0,0,4,0,0,4,0,0,4,0,0,4,0,0,4,0,0,4,0,0,4,0,0
0,0,0,0,0,0,0,0,0,0,0,0,0,0,0,0,0,0,0,0,0,0,0
0,0,0,0,0,0,0,0,0,0,0,0,0,0,0,0,0,0,0,0,0,0,0
0,0,4,0,0,0,0,0,0,0,0,0,0,0,0,0,0,0,0,0,4,0,0
0,0,0,0,0,0,4,0,0,4,0,0,0,4,0,0,4,0,0,0,0,0,0
0,0,0,0,0,0,0,0,0,0,0,0,0,0,0,0,0,0,0,0,0,0,0
0,0,4,0,0,0,0,0,0,0,0,0,0,0,0,0,0,0,0,0,4,0,0
0,0,0,0,0,0,4,0,0,0,0,0,0,0,0,0,4,0,0,0,0,0,0
0,0,0,0,0,0,0,0,0,0,0,0,0,0,0,0,0,0,0,0,0,0,0
0,0,4,0,0,0,0,0,0,0,0,0,0,0,0,0,0,0,0,0,4,0,0
0,0,0,0,0,0,0,0,0,0,0,0,0,0,0,0,0,0,0,0,0,0,0
0,0,0,0,0,0,4,0,0,0,0,0,0,0,0,0,4,0,0,0,0,0,0
0,0,4,0,0,0,0,0,0,0,0,0,0,0,0,0,0,0,0,0,4,0,0
0,0,0,0,0,0,0,0,0,0,0,0,0,0,0,0,0,0,0,0,0,0,0
0,0,0,0,0,0,4,0,0,4,0,0,0,4,0,0,4,0,0,0,0,0,0
0,0,4,0,0,0,0,0,0,0,0,0,0,0,0,0,0,0,0,0,4,0,0
0,0,0,0,0,0,0,0,0,0,0,0,0,0,0,0,0,0,0,0,0,0,0
0,0,0,0,0,0,0,0,0,0,0,0,0,0,0,0,0,0,0,0,0,0,0
0,0,4,0,0,4,0,0,4,0,0,4,0,0,4,0,0,4,0,0,4,0,0
0,0,0,0,0,0,0,0,0,0,0,0,0,0,0,0,0,0,0,0,0,0,0
0,0,0,0,0,0,0,0,0,0,0,0,0,0,0,0,0,0,0,0,0,0,0
endlayer

layer
0,0,0,0,0,0,0,0,0,0,0,0,0,0,0,0,0,0,0,0,0,0,0
0,0,0,0,0,0,0,0,0,0,0,0,0,0,0,0,0,0,0,0,0,0,0
0,0,4,0,0,4,0,0,4,0,0,4,0,0,4,0,0,4,0,0,4,0,0
0,0,0,0,0,0,0,0,0,0,0,0,0,0,0,0,0,0,0,0,0,0,0
0,0,0,0,0,0,0,0,0,0,0,0,0,0,0,0,0,0,0,0,0,0,0
0,0,4,0,0,0,0,0,0,0,0,0,0,0,0,0,0,0,0,0,4,0,0
0,0,0,0,0,0,4,0,0,4,0,0,0,4,0,0,4,0,0,0,0,0,0
0,0,0,0,0,0,0,0,0,0,0,0,0,0,0,0,0,0,0,0,0,0,0
0,0,4,0,0,0,0,0,0,0,0,0,0,0,0,0,0,0,0,0,4,0,0
0,0,0,0,0,0,4,0,0,0,0,0,0,0,0,0,4,0,0,0,0,0,0
0,0,0,0,0,0,0,0,0,0,0,0,0,0,0,0,0,0,0,0,0,0,0
0,0,4,0,0,0,0,0,0,0,0,0,0,0,0,0,0,0,0,0,4,0,0
0,0,0,0,0,0,0,0,0,0,0,0,0,0,0,0,0,0,0,0,0,0,0
0,0,0,0,0,0,4,0,0,0,0,0,0,0,0,0,4,0,0,0,0,0,0
0,0,4,0,0,0,0,0,0,0,0,0,0,0,0,0,0,0,0,0,4,0,0
0,0,0,0,0,0,0,0,0,0,0,0,0,0,0,0,0,0,0,0,0,0,0
0,0,0,0,0,0,4,0,0,4,0,0,0,4,0,0,4,0,0,0,0,0,0
0,0,4,0,0,0,0,0,0,0,0,0,0,0,0,0,0,0,0,0,4,0,0
0,0,0,0,0,0,0,0,0,0,0,0,0,0,0,0,0,0,0,0,0,0,0
0,0,0,0,0,0,0,0,0,0,0,0,0,0,0,0,0,0,0,0,0,0,0
0,0,4,0,0,4,0,0,4,0,0,4,0,0,4,0,0,4,0,0,4,0,0
0,0,0,0,0,0,0,0,0,0,0,0,0,0,0,0,0,0,0,0,0,0,0
0,0,0,0,0,0,0,0,0,0,0,0,0,0,0,0,0,0,0,0,0,0,0
endlayer

layer
0,0,0,0,0,0,0,0,0,0,0,0,0,0,0,0,0,0,0,0,0,0,0
0,0,0,0,0,0,0,0,0,0,0,0,0,0,0,0,0,0,0,0,0,0,0
0,0,4,0,0,4,0,0,4,0,0,4,0,0,4,0,0,4,0,0,4,0,0
0,0,0,0,0,0,0,0,0,0,0,0,0,0,0,0,0,0,0,0,0,0,0
0,0,0,0,0,0,0,0,0,0,0,0,0,0,0,0,0,0,0,0,0,0,0
0,0,4,0,0,1,1,1,1,1,1,1,1,1,1,1,1,1,0,0,4,0,0
0,0,0,0,0,1,4,2,2,4,2,2,2,4,2,2,4,1,0,0,0,0,0
0,0,0,0,0,1,2,0,0,0,0,0,0,0,0,0,2,1,0,0,0,0,0
0,0,4,0,0,1,2,0,0,0,0,0,0,0,0,0,2,1,0,0,4,0,0
0,0,0,0,0,1,4,0,0,0,0,0,0,0,0,0,4,1,0,0,0,0,0
0,0,0,0,0,1,2,0,0,0,0,0,0,0,0,0,2,1,0,0,0,0,0
0,0,4,0,0,1,2,0,0,0,0,0,0,0,0,0,2,1,0,0,4,0,0
0,0,0,0,0,1,2,0,0,0,0,0,0,0,0,0,2,1,0,0,0,0,0
0,0,0,0,0,1,4,0,0,0,0,0,0,0,0,0,4,1,0,0,0,0,0
0,0,4,0,0,1,2,0,0,0,0,0,0,0,0,0,2,1,0,0,4,0,0
0,0,0,0,0,1,2,0,0,0,0,0,0,0,0,0,2,1,0,0,0,0,0
0,0,0,0,0,1,4,2,2,4,2,2,2,4,2,2,4,1,0,0,0,0,0
0,0,4,0,0,1,1,1,1,1,1,1,1,1,1,1,1,1,0,0,4,0,0
0,0,0,0,0,0,0,0,0,0,0,0,0,0,0,0,0,0,0,0,0,0,0
0,0,0,0,0,0,0,0,0,0,0,0,0,0,0,0,0,0,0,0,0,0,0
0,0,4,0,0,4,0,0,4,0,0,4,0,0,4,0,0,4,0,0,4,0,0
0,0,0,0,0,0,0,0,0,0,0,0,0,0,0,0,0,0,0,0,0,0,0
0,0,0,0,0,0,0,0,0,0,0,0,0,0,0,0,0,0,0,0,0,0,0
endlayer

layer
0,0,0,0,0,0,0,0,0,0,0,0,0,0,0,0,0,0,0,0,0,0,0
0,0,0,0,0,0,0,0,0,0,0,0,0,0,0,0,0,0,0,0,0,0,0
0,0,4,2,2,4,2,2,4,2,2,4,2,2,4,2,2,4,2,2,4,0,0
0,0,2,0,0,0,0,0,0,0,0,0,0,0,0,0,0,0,0,0,2,0,0
0,0,2,0,0,0,0,0,0,0,0,0,0,0,0,0,0,0,0,0,2,0,0
0,0,4,0,0,0,0,0,0,0,0,0,0,0,0,0,0,0,0,0,4,0,0
0,0,2,0,0,0,1,1,1,1,1,1,1,1,1,1,1,0,0,0,2,0,0
0,0,2,0,0,0,1,1,1,1,1,1,1,1,1,1,1,0,0,0,2,0,0
0,0,4,0,0,0,1,1,6,6,6,6,6,6,6,1,1,0,0,0,4,0,0
0,0,2,0,0,0,1,1,6,6,6,6,6,6,6,1,1,0,0,0,2,0,0
0,0,2,0,0,0,1,1,6,6,6,6,6,6,6,1,1,0,0,0,2,0,0
0,0,4,0,0,0,1,1,6,6,6,6,6,6,6,1,1,0,0,0,4,0,0
0,0,2,0,0,0,1,1,6,6,6,6,6,6,6,1,1,0,0,0,2,0,0
0,0,2,0,0,0,1,1,6,6,6,6,6,6,6,1,1,0,0,0,2,0,0
0,0,4,0,0,0,1,1,6,6,6,6,6,6,6,1,1,0,0,0,4,0,0
0,0,2,0,0,0,1,1,1,1,1,1,1,1,1,1,1,0,0,0,2,0,0
0,0,2,0,0,0,1,1,1,1,1,1,1,1,1,1,1,0,0,0,2,0,0
0,0,4,0,0,0,0,0,0,0,0,0,0,0,0,0,0,0,0,0,4,0,0
0,0,2,0,0,0,0,0,0,0,0,0,0,0,0,0,0,0,0,0,2,0,0
0,0,2,0,0,0,0,0,0,0,0,0,0,0,0,0,0,0,0,0,2,0,0
0,0,4,2,2,4,2,2,4,2,2,4,2,2,4,2,2,4,2,2,4,0,0
0,0,0,0,0,0,0,0,0,0,0,0,0,0,0,0,0,0,0,0,0,0,0
0,0,0,0,0,0,0,0,0,0,0,0,0,0,0,0,0,0,0,0,0,0,0
endlayer

layer
0,0,0,0,0,0,0,0,0,0,0,0,0,0,0,0,0,0,0,0,0,0,0
0,0,0,0,0,0,0,0,0,0,0,0,0,0,0,0,0,0,0,0,0,0,0
0,0,4,0,0,4,0,0,4,0,0,4,0,0,4,0,0,4,0,0,4,0,0
0,0,0,0,0,0,0,0,0,0,0,0,0,0,0,0,0,0,0,0,0,0,0
0,0,0,0,0,0,0,0,0,0,0,0,0,0,0,0,0,0,0,0,0,0,0
0,0,4,0,0,0,0,0,0,0,0,0,0,0,0,0,0,0,0,0,4,0,0
0,0,0,0,0,0,0,0,0,0,0,0,0,0,0,0,0,0,0,0,0,0,0
0,0,0,0,0,0,0,1,1,1,1,1,1,1,1,1,0,0,0,0,0,0,0
0,0,4,0,0,0,0,1,6,6,6,6,6,6,6,1,0,0,0,0,4,0,0
0,0,0,0,0,0,0,1,6,6,6,6,6,6,6,1,0,0,0,0,0,0,0
0,0,0,0,0,0,0,1,6,6,6,6,6,6,6,1,0,0,0,0,0,0,0
0,0,4,0,0,0,0,1,6,6,6,6,6,6,6,1,0,0,0,0,4,0,0
0,0,0,0,0,0,0,1,6,6,6,6,6,6,6,1,0,0,0,0,0,0,0
0,0,0,0,0,0,0,1,6,6,6,6,6,6,6,1,0,0,0,0,0,0,0
0,0,4,0,0,0,0,1,6,6,6,6,6,6,6,1,0,0,0,0,4,0,0
0,0,0,0,0,0,0,1,1,1,1,1,1,1,1,1,0,0,0,0,0,0,0
0,0,0,0,0,0,0,0,0,0,0,0,0,0,0,0,0,0,0,0,0,0,0
0,0,4,0,0,0,0,0,0,0,0,0,0,0,0,0,0,0,0,0,4,0,0
0,0,0,0,0,0,0,0,0,0,0,0,0,0,0,0,0,0,0,0,0,0,0
0,0,0,0,0,0,0,0,0,0,0,0,0,0,0,0,0,0,0,0,0,0,0
0,0,4,0,0,4,0,0,4,0,0,4,0,0,4,0,0,4,0,0,4,0,0
0,0,0,0,0,0,0,0,0,0,0,0,0,0,0,0,0,0,0,0,0,0,0
0,0,0,0,0,0,0,0,0,0,0,0,0,0,0,0,0,0,0,0,0,0,0
endlayer

layer
1,1,1,1,1,1,1,1,1,1,1,1,1,1,1,1,1,1,1,1,1,1,1
1,1,1,1,1,1,1,1,1,1,1,1,1,1,1,1,1,1,1,1,1,1,1
1,1,1,1,1,1,1,1,1,1,1,1,1,1,1,1,1,1,1,1,1,1,1
1,1,1,1,1,1,1,1,1,1,1,1,1,1,1,1,1,1,1,1,1,1,1
1,1,1,1,1,1,1,1,1,1,1,1,1,1,1,1,1,1,1,1,1,1,1
1,1,1,1,1,0,0,0,0,0,0,0,0,0,0,0,0,0,1,1,1,1,1
1,1,1,1,1,0,0,0,0,0,0,0,0,0,0,0,0,0,1,1,1,1,1
1,1,1,1,1,0,0,0,0,0,0,0,0,0,0,0,0,0,1,1,1,1,1
1,1,1,1,1,0,0,0,1,1,1,1,1,1,1,0,0,0,1,1,1,1,1
1,1,1,1,1,0,0,0,1,7,7,7,7,7,1,0,0,0,1,1,1,1,1
1,1,1,1,1,0,0,0,1,7,7,7,7,7,1,0,0,0,1,1,1,1,1
1,1,1,1,1,0,0,0,1,7,7,7,7,7,1,0,0,0,1,1,1,1,1
1,1,1,1,1,0,0,0,1,7,7,7,7,7,1,0,0,0,1,1,1,1,1
1,1,1,1,1,0,0,0,1,7,7,7,7,7,1,0,0,0,1,1,1,1,1
1,1,1,1,1,0,0,0,1,1,1,1,1,1,1,0,0,0,1,1,1,1,1
1,1,1,1,1,0,0,0,0,0,0,0,0,0,0,0,0,0,1,1,1,1,1
1,1,1,1,1,0,0,0,0,0,0,0,0,0,0,0,0,0,1,1,1,1,1
1,1,1,1,1,0,0,0,0,0,0,0,0,0,0,0,0,0,1,1,1,1,1
1,1,1,1,1,1,1,1,1,1,1,1,1,1,1,1,1,1,1,1,1,1,1
1,1,1,1,1,1,1,1,1,1,1,1,1,1,1,1,1,1,1,1,1,1,1
1,1,1,1,1,1,1,1,1,1,1,1,1,1,1,1,1,1,1,1,1,1,1
1,1,1,1,1,1,1,1,1,1,1,1,1,1,1,1,1,1,1,1,1,1,1
1,1,1,1,1,1,1,1,1,1,1,1,1,1,1,1,1,1,1,1,1,1,1
endlayer

layer
0,0,0,0,0,0,0,0,0,0,0,0,0,0,0,0,0,0,0,0,0,0,0
0,1,1,1,1,1,1,1,1,1,1,1,1,1,1,1,1,1,1,1,1,1,0
0,1,1,1,1,1,1,1,1,1,1,1,1,1,1,1,1,1,1,1,1,1,0
0,1,1,1,1,1,1,1,1,1,1,1,1,1,1,1,1,1,1,1,1,1,0
0,1,1,1,0,0,0,0,0,0,0,0,0,0,0,0,0,0,0,1,1,1,0
0,1,1,1,0,0,0,0,0,0,0,0,0,0,0,0,0,0,0,1,1,1,0
0,1,1,1,0,0,0,0,0,0,0,0,0,0,0,0,0,0,0,1,1,1,0
0,1,1,1,0,0,0,0,0,0,0,0,0,0,0,0,0,0,0,1,1,1,0
0,1,1,1,0,0,0,0,0,0,0,0,0,0,0,0,0,0,0,1,1,1,0
0,1,1,1,0,0,0,0,0,0,0,0,0,0,0,0,0,0,0,1,1,1,0
0,1,1,1,0,0,0,0,0,0,0,0,0,0,0,0,0,0,0,1,1,1,0
0,1,1,1,0,0,0,0,0,0,0,0,0,0,0,0,0,0,0,1,1,1,0
0,1,1,1,0,0,0,0,0,0,0,0,0,0,0,0,0,0,0,1,1,1,0
0,1,1,1,0,0,0,0,0,0,0,0,0,0,0,0,0,0,0,1,1,1,0
0,1,1,1,0,0,0,0,0,0,0,0,0,0,0,0,0,0,0,1,1,1,0
0,1,1,1,0,0,0,0,0,0,0,0,0,0,0,0,0,0,0,1,1,1,0
0,1,1,1,0,0,0,0,0,0,0,0,0,0,0,0,0,0,0,1,1,1,0
0,1,1,1,0,0,0,0,0,0,0,0,0,0,0,0,0,0,0,1,1,1,0
0,1,1,1,0,0,0,0,0,0,0,0,0,0,0,0,0,0,0,1,1,1,0
0,1,1,1,1,1,1,1,1,1,1,1,1,1,1,1,1,1,1,1,1,1,0
0,1,1,1,1,1,1,1,1,1,1,1,1,1,1,1,1,1,1,1,1,1,0
0,1,1,1,1,1,1,1,1,1,1,1,1,1,1,1,1,1,1,1,1,1,0
0,0,0,0,0,0,0,0,0,0,0,0,0,0,0,0,0,0,0,0,0,0,0
endlayer

layer
0,0,0,0,0,0,0,0,0,0,0,0,0,0,0,0,0,0,0,0,0,0,0
0,0,0,0,0,0,0,0,0,0,0,0,0,0,0,0,0,0,0,0,0,0,0
0,0,1,1,1,1,1,1,1,1,1,1,1,1,1,1,1,1,1,1,1,0,0
0,0,1,0,0,0,0,0,0,0,0,0,0,0,0,0,0,0,0,0,1,0,0
0,0,1,0,0,0,0,0,0,0,0,0,0,0,0,0,0,0,0,0,1,0,0
0,0,1,0,0,0,0,0,0,0,0,0,0,0,0,0,0,0,0,0,1,0,0
0,0,1,0,0,0,0,0,0,0,0,0,0,0,0,0,0,0,0,0,1,0,0
0,0,1,0,0,0,0,0,0,0,0,0,0,0,0,0,0,0,0,0,1,0,0
0,0,1,0,0,0,0,0,0,0,0,0,0,0,0,0,0,0,0,0,1,0,0
0,0,1,0,0,0,0,0,0,0,0,0,0,0,0,0,0,0,0,0,1,0,0
0,0,1,0,0,0,0,0,0,0,0,0,0,0,0,0,0,0,0,0,1,0,0
0,0,1,0,0,0,0,0,0,0,0,0,0,0,0,0,0,0,0,0,1,0,0
0,0,1,0,0,0,0,0,0,0,0,0,0,0,0,0,0,0,0,0,1,0,0
0,0,1,0,0,0,0,0,0,0,0,0,0,0,0,0,0,0,0,0,1,0,0
0,0,1,0,0,0,0,0,0,0,0,0,0,0,0,0,0,0,0,0,1,0,0
0,0,1,0,0,0,0,0,0,0,0,0,0,0,0,0,0,0,0,0,1,0,0
0,0,1,0,0,0,0,0,0,0,0,0,0,0,0,0,0,0,0,0,1,0,0
0,0,1,0,0,0,0,0,0,0,0,0,0,0,0,0,0,0,0,0,1,0,0
0,0,1,0,0,0,0,0,0,0,0,0,0,0,0,0,0,0,0,0,1,0,0
0,0,1,0,0,0,0,0,0,0,0,0,0,0,0,0,0,0,0,0,1,0,0
0,0,1,1,1,1,1,1,1,1,1,1,1,1,1,1,1,1,1,1,1,0,0
0,0,0,0,0,0,0,0,0,0,0,0,0,0,0,0,0,0,0,0,0,0,0
0,0,0,0,0,0,0,0,0,0,0,0,0,0,0,0,0,0,0,0,0,0,0
endlayer

