
# Created by Ruins mod version 16.7 Ingame Parser
# authoring Player: ST753M

weight=1
embed_into_distance=6
acceptable_target_blocks=gravel,sand
unacceptable_target_blocks=flowing_water,water,flowing_lava,lava
dimensions=16,17,17
allowable_overhang=6
max_leveling=0
leveling_buffer=0
preserve_water=1
preserve_lava=0

biomesToSpawnIn=deep_ocean,coral_reef,kelp_forest

=0,100,air
rule1=0,100,preserveBlock
rule2=0,100,minecraft:stone-0
rule3=0,100,biomesoplenty:log_1-8
rule4=0,100,biomesoplenty:log_1-0
rule5=0,100,biomesoplenty:log_1-4
rule6=0,100,biomesoplenty:planks_0-4
rule7=0,100,biomesoplenty:ethereal_stairs-7
rule8=0,100,biomesoplenty:ethereal_stairs-3
rule9=0,100,biomesoplenty:ethereal_fence-0
rule10=0,100,biomesoplenty:ethereal_stairs-2
rule11=0,100,biomesoplenty:ethereal_stairs-6
rule12=0,100,biomesoplenty:ethereal_stairs-1
rule13=0,100,biomesoplenty:ethereal_door_block-0
rule14=0,100,biomesoplenty:ethereal_stairs-0
rule15=0,100,minecraft:carpet-9
rule16=0,100,minecraft:bed-0
rule17=0,100,minecraft:bed-8
rule18=0,100,biomesoplenty:ethereal_stairs-5
rule19=0,100,biomesoplenty:ethereal_door_block-1
rule20=0,100,biomesoplenty:ethereal_door_block-3
rule21=0,100,biomesoplenty:ethereal_door_block-2
rule22=0,100,biomesoplenty:wood_slab_0-4
rule23=0,100,IInventory;minecraft:chest;biomesoplenty:log_1#64#4#0+biomesoplenty:log_1#32#4#1+biomesoplenty:log_1#16#4#3+biomesoplenty:planks_0#16#4#5+biomesoplenty:planks_0#32#4#6+biomesoplenty:log_1#64#4#7+biomesoplenty:planks_0#48#4#10+biomesoplenty:log_1#48#4#12+biomesoplenty:log_1#32#4#14+biomesoplenty:log_1#16#4#15+biomesoplenty:log_1#32#4#17+biomesoplenty:planks_0#16#4#18+biomesoplenty:log_1#32#4#19+biomesoplenty:log_1#48#4#20+biomesoplenty:planks_0#16#4#21+biomesoplenty:log_1#48#4#22+biomesoplenty:log_1#64#4#24+biomesoplenty:log_1#16#4#25-2
rule24=0,100,biomesoplenty:ethereal_door_block-8
rule25=0,100,biomesoplenty:ethereal_door_block-9
rule26=0,100,IInventory;minecraft:chest;biomesoplenty:log_1#64#4#0+biomesoplenty:log_1#32#4#1+biomesoplenty:log_1#16#4#3+biomesoplenty:planks_0#16#4#5+biomesoplenty:planks_0#32#4#6+biomesoplenty:log_1#64#4#7+biomesoplenty:planks_0#48#4#10+biomesoplenty:log_1#48#4#12+biomesoplenty:log_1#32#4#14+biomesoplenty:log_1#16#4#15+biomesoplenty:log_1#32#4#17+biomesoplenty:planks_0#16#4#18+biomesoplenty:log_1#32#4#19+biomesoplenty:log_1#48#4#20+biomesoplenty:planks_0#16#4#21+biomesoplenty:log_1#48#4#22+biomesoplenty:log_1#64#4#24+biomesoplenty:log_1#16#4#25-2
rule27=0,100,biomesoplenty:ethereal_stairs-4
rule28=0,100,minecraft:sea_lantern-0
rule29=0,100,biomesoplenty:grass-7
rule30=0,100,minecraft:dirt-0
rule31=0,100,air
rule32=0,100,water
rule33=0,100,minecraft:double_plant-4
rule34=0,100,biomesoplenty:flower_1-5
rule35=0,100,minecraft:yellow_flower-0
rule36=0,100,biomesoplenty:flower_0-3
rule37=0,100,biomesoplenty:plant_1-10
rule38=0,100,minecraft:red_flower-3
rule39=0,100,biomesoplenty:log_4-4
rule40=0,100,air
rule41=0,100,air
rule42=0,100,air
rule43=0,100,minecraft:stained_glass-4
^0,100,minecraft:stained_glass-0
^0,100,minecraft:stained_glass-9
^0,100,minecraft:stained_glass-3
^0,100,minecraft:stained_glass-11
^0,100,minecraft:stained_glass-8
^0,100,minecraft:stained_glass-7
rule44=0,100,minecraft:double_plant-10
rule45=0,100,biomesoplenty:waterlily-3
rule46=0,100,biomesoplenty:leaves_6-12
rule47=0,100,CommandBlock:RUINSTRIGGER /summon Rabbit ~ ~ ~:@-4
rule48=0,100,CommandBlock:RUINSTRIGGER /summon Chicken ~ ~ ~:@-2
rule49=0,100,CommandBlock:RUINSTRIGGER /summon Rabbit ~ ~ ~:@-1
rule50=0,100,CommandBlock:RUINSTRIGGER /summon Sheep ~ ~ ~:@-3
rule51=0,100,biomesoplenty:leaves_6-13

layer
1,1,1,1,1,1,2,2,2,2,2,1,1,1,1,1,1
1,1,1,1,2,2,2,2,2,2,2,2,2,1,1,1,1
1,1,1,2,2,2,3,4,3,4,3,2,2,2,1,1,1
1,1,2,2,4,3,4,3,4,3,4,3,4,2,2,1,1
1,2,2,4,3,4,3,4,3,4,3,4,3,4,2,2,1
1,2,2,3,4,3,4,3,4,3,4,3,4,3,2,2,1
2,2,3,4,3,4,3,4,3,4,3,4,3,4,3,2,2
2,2,4,3,4,3,4,3,4,3,4,3,4,3,4,2,2
2,2,3,4,3,4,3,4,5,4,3,4,3,4,3,2,2
2,2,4,3,4,3,4,3,4,3,4,3,4,3,4,2,2
2,2,3,4,3,4,3,4,3,4,3,4,3,4,3,2,2
1,2,2,3,4,3,4,3,4,3,4,3,4,3,2,2,1
1,2,2,4,3,4,3,4,3,4,3,4,3,4,2,2,1
1,1,2,2,4,3,4,3,4,3,4,3,3,2,2,1,1
1,1,1,2,2,2,3,4,3,4,3,2,2,2,1,1,1
1,1,1,1,2,2,2,2,2,2,2,2,2,1,1,1,1
1,1,1,1,1,1,2,2,2,2,2,1,1,1,1,1,1
endlayer

layer
1,1,1,1,1,1,2,2,2,2,2,1,1,1,1,1,1
1,1,1,1,2,2,6,6,6,6,6,2,2,1,1,1,1
1,1,1,2,6,5,0,0,0,0,0,5,6,2,1,1,1
1,1,2,6,6,11,0,10,9,8,0,7,6,6,2,1,1
1,2,6,6,6,11,0,10,9,8,0,7,6,6,6,2,1
1,2,5,12,12,5,0,0,0,0,0,5,12,12,5,2,1
2,6,0,0,0,0,6,6,13,6,6,0,0,0,0,6,2
2,6,17,16,0,0,6,0,0,0,6,0,15,0,14,6,2
2,6,9,0,0,0,20,0,0,0,19,0,15,0,18,6,2
2,6,17,16,0,0,6,0,0,0,6,0,15,0,0,6,2
2,6,0,0,0,0,6,6,21,6,6,0,0,0,0,6,2
1,2,5,14,14,5,0,0,0,0,0,5,14,14,5,2,1
1,2,6,6,6,11,0,10,9,8,0,7,6,6,6,2,1
1,1,2,6,6,11,0,10,9,8,0,7,6,6,2,1,1
1,1,1,2,6,5,0,0,0,0,0,5,6,2,1,1,1
1,1,1,1,2,2,6,6,6,6,6,2,2,1,1,1,1
1,1,1,1,1,1,2,2,2,2,2,1,1,1,1,1,1
endlayer

layer
1,1,1,1,1,1,2,2,2,2,2,1,1,1,1,1,1
1,1,1,1,2,2,6,6,6,6,6,2,2,1,1,1,1
1,1,1,2,6,5,0,0,0,0,0,5,6,2,1,1,1
1,1,2,6,6,23,0,0,22,0,0,0,6,6,2,1,1
1,2,6,6,6,0,0,0,22,0,0,0,6,6,6,2,1
1,2,5,0,0,5,0,0,0,0,0,5,0,0,5,2,1
2,6,0,0,0,0,6,6,24,6,6,0,0,0,0,6,2
2,6,0,0,0,0,6,0,0,0,6,0,0,0,0,6,2
2,6,22,0,0,0,24,0,0,0,25,0,0,0,14,6,2
2,6,0,0,0,0,6,0,0,0,6,0,0,0,18,6,2
2,6,0,0,0,0,6,6,25,6,6,0,0,0,0,6,2
1,2,5,0,0,5,0,0,0,0,0,5,0,0,5,2,1
1,2,6,6,6,26,0,0,22,0,0,0,6,6,6,2,1
1,1,2,6,6,0,0,0,22,0,0,0,6,6,2,1,1
1,1,1,2,6,5,0,0,0,0,0,5,6,2,1,1,1
1,1,1,1,2,2,6,6,6,6,6,2,2,1,1,1,1
1,1,1,1,1,1,2,2,2,2,2,1,1,1,1,1,1
endlayer

layer
1,1,1,1,1,1,2,2,2,2,2,1,1,1,1,1,1
1,1,1,1,2,2,6,6,6,6,6,2,2,1,1,1,1
1,1,1,2,6,5,0,0,0,0,0,5,6,2,1,1,1
1,1,2,6,6,11,0,0,0,0,0,7,6,6,2,1,1
1,2,6,6,6,11,0,0,0,0,0,7,6,6,6,2,1
1,2,5,18,18,5,0,0,0,0,0,5,18,18,5,2,1
2,6,0,0,0,0,6,6,6,6,6,0,0,0,0,6,2
2,6,0,0,0,0,6,0,0,0,6,0,0,0,0,6,2
2,6,0,0,0,0,6,0,0,0,6,0,0,0,0,6,2
2,6,0,0,0,0,6,0,0,0,6,0,0,0,14,6,2
2,6,0,0,0,0,6,6,6,6,6,0,0,0,18,6,2
1,2,5,27,27,5,0,0,0,0,0,5,27,27,5,2,1
1,2,6,6,6,11,0,0,0,0,0,7,6,6,6,2,1
1,1,2,6,6,11,0,0,0,0,0,7,6,6,2,1,1
1,1,1,2,6,5,0,0,0,0,0,5,6,2,1,1,1
1,1,1,1,2,2,6,6,6,6,6,2,2,1,1,1,1
1,1,1,1,1,1,2,2,2,2,2,1,1,1,1,1,1
endlayer

layer
1,1,1,1,1,1,2,2,2,2,2,1,1,1,1,1,1
1,1,1,1,2,2,2,2,2,2,2,2,2,1,1,1,1
1,1,1,2,2,2,4,3,3,3,4,2,2,2,1,1,1
1,1,2,2,3,4,3,4,3,4,3,4,3,2,2,1,1
1,2,2,3,4,3,4,3,4,3,4,3,4,3,2,2,1
1,2,2,4,3,4,3,4,3,4,3,4,3,4,5,2,1
2,2,4,3,4,3,4,3,4,3,4,3,4,3,4,4,2
2,2,3,4,3,4,3,4,3,4,3,4,3,4,0,4,2
2,2,4,3,4,3,4,3,28,3,4,3,4,3,0,3,2
2,2,3,4,3,4,3,4,3,4,3,4,3,4,0,4,2
2,2,4,3,4,3,4,3,4,3,4,3,4,3,14,3,2
1,2,2,30,29,29,3,4,3,4,3,4,3,4,2,2,1
1,2,2,30,29,29,4,3,4,3,4,3,4,3,2,2,1
1,1,2,30,30,30,3,4,3,4,3,4,3,2,2,1,1
1,1,1,2,30,30,4,3,4,3,4,2,2,2,1,1,1
1,1,1,1,2,2,2,2,2,2,2,2,2,1,1,1,1
1,1,1,1,1,1,2,2,2,2,2,1,1,1,1,1,1
endlayer

layer
1,1,1,1,1,1,2,2,2,2,2,1,1,1,1,1,1
1,1,1,1,2,2,29,29,29,29,29,2,2,1,1,1,1
1,1,1,2,29,29,29,29,29,29,29,29,30,2,1,1,1
1,1,2,29,29,29,29,29,29,29,29,29,30,30,2,1,1
1,2,30,29,29,29,29,29,29,29,29,29,29,30,30,2,1
1,2,30,29,29,30,29,29,29,29,29,29,29,30,30,2,1
2,30,30,29,29,29,29,29,29,29,29,29,29,29,30,30,2
2,30,30,30,29,29,29,29,30,30,29,29,29,29,30,30,2
2,30,30,30,30,30,30,30,30,30,30,29,29,29,31,30,2
2,30,30,30,30,30,30,30,30,30,30,29,29,29,0,30,2
2,30,30,29,29,29,30,30,30,30,30,29,29,29,0,30,2
1,2,30,29,32,32,30,30,30,30,29,29,29,29,14,2,1
1,2,30,30,32,32,29,30,30,30,29,29,29,29,29,2,1
1,1,2,30,29,29,29,30,30,30,30,29,29,29,2,1,1
1,1,1,2,30,30,30,30,30,30,30,30,30,2,1,1,1
1,1,1,1,2,2,30,30,30,30,30,2,2,1,1,1,1
1,1,1,1,1,1,2,2,2,2,2,1,1,1,1,1,1
endlayer

layer
1,1,1,1,1,1,2,2,2,2,2,1,1,1,1,1,1
1,1,1,1,2,2,33,0,0,33,0,2,2,1,1,1,1
1,1,1,2,34,0,36,33,34,35,0,34,29,2,1,1,1
1,1,2,0,0,34,0,37,0,0,34,33,29,29,2,1,1
1,2,29,0,0,0,34,0,0,35,0,0,0,29,29,2,1
1,2,29,0,0,39,0,38,0,0,0,34,0,29,29,2,1
2,29,29,0,0,0,0,0,0,0,0,35,0,0,29,29,2
2,29,29,29,0,0,34,0,29,29,0,0,0,34,29,29,2
2,29,29,29,29,29,29,29,29,29,29,0,37,0,29,29,2
2,29,29,29,29,29,29,29,29,29,29,0,0,33,40,29,2
2,29,29,32,32,32,29,29,29,30,29,38,0,35,0,33,2
1,2,29,32,32,32,29,29,29,29,0,34,0,36,41,2,1
1,2,29,29,32,32,32,29,29,29,0,34,0,33,42,2,1
1,1,2,29,32,32,32,29,29,29,29,0,0,34,2,1,1
1,1,1,2,29,29,29,29,29,29,29,29,29,2,1,1,1
1,1,1,1,2,2,29,29,29,29,29,2,2,1,1,1,1
1,1,1,1,1,1,2,2,2,2,2,1,1,1,1,1,1
endlayer

layer
1,1,1,1,1,1,43,43,43,43,43,1,1,1,1,1,1
1,1,1,1,43,43,44,0,0,44,0,43,43,1,1,1,1
1,1,1,43,0,0,0,44,0,0,0,0,0,43,1,1,1
1,1,43,0,0,0,0,0,0,0,0,44,38,0,43,1,1
1,43,0,0,0,0,0,0,0,0,0,0,0,34,33,43,1
1,43,0,0,0,39,0,0,0,0,0,0,0,0,0,43,1
43,0,38,0,0,0,0,0,0,0,0,0,0,0,0,33,43
43,0,0,0,0,0,0,0,34,0,0,0,0,0,0,38,43
43,0,35,0,0,0,0,0,34,35,0,0,0,0,33,0,43
43,36,33,0,0,35,0,0,36,0,0,0,0,44,0,0,43
43,33,0,0,0,0,0,34,0,39,0,0,0,0,0,44,43
1,43,0,0,45,0,35,0,0,0,0,0,0,0,0,43,1
1,43,34,0,0,45,0,0,37,0,0,0,0,44,0,43,1
1,1,43,0,0,0,0,36,0,0,35,0,0,0,43,1,1
1,1,1,43,0,34,33,0,0,0,0,34,0,43,1,1,1
1,1,1,1,43,43,0,35,0,33,38,43,43,1,1,1,1
1,1,1,1,1,1,43,43,43,43,43,1,1,1,1,1,1
endlayer

layer
1,1,1,1,1,1,43,43,43,43,43,1,1,1,1,1,1
1,1,1,1,43,43,0,0,0,0,0,43,43,1,1,1,1
1,1,1,43,0,0,0,0,0,0,0,0,0,43,1,1,1
1,1,43,0,0,0,0,0,0,0,0,0,0,0,43,1,1
1,43,0,0,46,0,46,0,0,0,0,0,0,0,44,43,1
1,43,0,0,0,39,0,0,47,47,0,0,0,0,0,43,1
43,0,0,0,46,0,46,50,49,48,0,0,0,0,0,44,43
43,0,0,0,0,0,0,50,49,48,0,0,0,0,0,0,43
43,0,0,0,0,0,0,0,0,0,0,0,0,0,44,0,43
43,0,44,0,0,0,0,0,0,0,0,0,0,0,0,0,43
43,44,0,0,0,0,0,0,0,39,0,0,0,0,0,0,43
1,43,0,0,0,0,0,0,0,0,0,0,0,0,0,43,1
1,43,0,0,0,0,0,0,0,0,0,0,0,0,0,43,1
1,1,43,0,0,0,0,0,0,0,0,0,0,0,43,1,1
1,1,1,43,0,0,44,0,0,0,0,0,0,43,1,1,1
1,1,1,1,43,43,0,0,0,44,0,43,43,1,1,1,1
1,1,1,1,1,1,43,43,43,43,43,1,1,1,1,1,1
endlayer

layer
1,1,1,1,1,1,1,43,43,43,1,1,1,1,1,1,1
1,1,1,1,43,43,43,0,0,0,43,43,43,1,1,1,1
1,1,1,43,0,0,0,0,0,0,0,0,0,43,1,1,1
1,1,43,0,0,46,0,0,0,0,0,0,0,0,43,1,1
1,43,0,0,0,46,0,0,0,0,0,0,0,0,0,43,1
1,43,0,46,46,51,46,46,0,0,0,0,0,0,0,43,1
1,43,0,0,0,46,0,0,0,0,0,0,0,0,0,43,1
43,0,0,0,0,46,0,0,0,0,0,0,0,0,0,0,43
43,0,0,0,0,0,0,0,0,0,0,0,0,0,0,0,43
43,0,0,0,0,0,0,0,0,0,0,0,0,0,0,0,43
1,43,0,0,0,0,0,0,0,39,0,0,0,0,0,43,1
1,43,0,0,0,0,0,0,0,0,0,0,0,0,0,43,1
1,43,0,0,0,0,0,0,0,0,0,0,0,0,0,43,1
1,1,43,0,0,0,0,0,0,0,0,0,0,0,43,1,1
1,1,1,43,0,0,0,0,0,0,0,0,0,43,1,1,1
1,1,1,1,43,43,43,0,0,0,43,43,43,1,1,1,1
1,1,1,1,1,1,1,43,43,43,1,1,1,1,1,1,1
endlayer

layer
1,1,1,1,1,1,1,1,1,1,1,1,1,1,1,1,1
1,1,1,1,1,43,43,43,43,43,43,43,1,1,1,1,1
1,1,1,43,43,0,0,0,0,0,0,0,43,43,1,1,1
1,1,43,0,0,0,0,0,0,0,0,0,0,0,43,1,1
1,1,43,0,46,0,46,0,0,0,0,0,0,0,43,1,1
1,43,0,0,0,0,0,0,0,0,0,0,0,0,0,43,1
1,43,0,0,46,0,46,0,0,0,0,0,0,0,0,43,1
1,43,0,0,0,0,0,0,0,0,0,0,0,0,0,43,1
1,43,0,0,0,0,0,0,0,0,0,0,0,0,0,43,1
1,43,0,0,0,0,0,0,51,0,51,0,0,0,0,43,1
1,43,0,0,0,0,0,0,0,39,0,0,0,0,0,43,1
1,43,0,0,0,0,0,0,51,0,51,0,0,0,0,43,1
1,1,43,0,0,0,0,0,0,0,0,0,0,0,43,1,1
1,1,43,0,0,0,0,0,0,0,0,0,0,0,43,1,1
1,1,1,43,43,0,0,0,0,0,0,0,43,43,1,1,1
1,1,1,1,1,43,43,43,43,43,43,43,1,1,1,1,1
1,1,1,1,1,1,1,1,1,1,1,1,1,1,1,1,1
endlayer

layer
1,1,1,1,1,1,1,1,1,1,1,1,1,1,1,1,1
1,1,1,1,1,1,43,43,43,43,43,1,1,1,1,1,1
1,1,1,1,43,43,0,0,0,0,0,43,43,1,1,1,1
1,1,1,43,0,0,0,0,0,0,0,0,0,43,1,1,1
1,1,43,0,0,0,0,0,0,0,0,0,0,0,43,1,1
1,1,43,0,0,0,0,0,0,0,0,0,0,0,43,1,1
1,43,0,0,0,0,0,0,0,0,0,0,0,0,0,43,1
1,43,0,0,0,0,0,0,0,0,0,0,0,0,0,43,1
1,43,0,0,0,0,0,0,0,51,0,0,0,0,0,43,1
1,43,0,0,0,0,0,0,0,51,0,0,0,0,0,43,1
1,43,0,0,0,0,0,51,51,46,51,51,0,0,0,43,1
1,1,43,0,0,0,0,0,0,51,0,0,0,0,43,1,1
1,1,43,0,0,0,0,0,0,51,0,0,0,0,43,1,1
1,1,1,43,0,0,0,0,0,0,0,0,0,43,1,1,1
1,1,1,1,43,43,0,0,0,0,0,43,43,1,1,1,1
1,1,1,1,1,1,43,43,43,43,43,1,1,1,1,1,1
1,1,1,1,1,1,1,1,1,1,1,1,1,1,1,1,1
endlayer

layer
1,1,1,1,1,1,1,1,1,1,1,1,1,1,1,1,1
1,1,1,1,1,1,1,1,1,1,1,1,1,1,1,1,1
1,1,1,1,1,43,43,43,43,43,43,43,1,1,1,1,1
1,1,1,1,43,0,0,0,0,0,0,0,43,1,1,1,1
1,1,1,43,0,0,0,0,0,0,0,0,0,43,1,1,1
1,1,43,0,0,0,0,0,0,0,0,0,0,0,43,1,1
1,1,43,0,0,0,0,0,0,0,0,0,0,0,43,1,1
1,1,43,0,0,0,0,0,0,0,0,0,0,0,43,1,1
1,1,43,0,0,0,0,0,0,0,0,0,0,0,43,1,1
1,1,43,0,0,0,0,0,51,0,51,0,0,0,43,1,1
1,1,43,0,0,0,0,0,0,0,0,0,0,0,43,1,1
1,1,43,0,0,0,0,0,51,0,51,0,0,0,43,1,1
1,1,1,43,0,0,0,0,0,0,0,0,0,43,1,1,1
1,1,1,1,43,0,0,0,0,0,0,0,43,1,1,1,1
1,1,1,1,1,43,43,43,43,43,43,43,1,1,1,1,1
1,1,1,1,1,1,1,1,1,1,1,1,1,1,1,1,1
1,1,1,1,1,1,1,1,1,1,1,1,1,1,1,1,1
endlayer

layer
1,1,1,1,1,1,1,1,1,1,1,1,1,1,1,1,1
1,1,1,1,1,1,1,1,1,1,1,1,1,1,1,1,1
1,1,1,1,1,1,1,1,1,1,1,1,1,1,1,1,1
1,1,1,1,1,43,43,43,43,43,43,43,1,1,1,1,1
1,1,1,1,43,43,0,0,0,0,0,43,43,1,1,1,1
1,1,1,43,43,0,0,0,0,0,0,0,43,43,1,1,1
1,1,1,43,0,0,0,0,0,0,0,0,0,43,1,1,1
1,1,1,43,0,0,0,0,0,0,0,0,0,43,1,1,1
1,1,1,43,0,0,0,0,0,0,0,0,0,43,1,1,1
1,1,1,43,0,0,0,0,0,0,0,0,0,43,1,1,1
1,1,1,43,0,0,0,0,0,0,0,0,0,43,1,1,1
1,1,1,43,43,0,0,0,0,0,0,0,43,43,1,1,1
1,1,1,1,43,43,0,0,0,0,0,43,43,1,1,1,1
1,1,1,1,1,43,43,43,43,43,43,43,1,1,1,1,1
1,1,1,1,1,1,1,1,1,1,1,1,1,1,1,1,1
1,1,1,1,1,1,1,1,1,1,1,1,1,1,1,1,1
1,1,1,1,1,1,1,1,1,1,1,1,1,1,1,1,1
endlayer

layer
1,1,1,1,1,1,1,1,1,1,1,1,1,1,1,1,1
1,1,1,1,1,1,1,1,1,1,1,1,1,1,1,1,1
1,1,1,1,1,1,1,1,1,1,1,1,1,1,1,1,1
1,1,1,1,1,1,1,1,1,1,1,1,1,1,1,1,1
1,1,1,1,1,1,43,43,43,43,43,1,1,1,1,1,1
1,1,1,1,1,43,43,43,43,43,43,43,1,1,1,1,1
1,1,1,1,43,43,43,0,0,0,43,43,43,1,1,1,1
1,1,1,1,43,43,0,0,0,0,0,43,43,1,1,1,1
1,1,1,1,43,43,0,0,0,0,0,43,43,1,1,1,1
1,1,1,1,43,43,0,0,0,0,0,43,43,1,1,1,1
1,1,1,1,43,43,43,0,0,0,43,43,43,1,1,1,1
1,1,1,1,1,43,43,43,43,43,43,43,1,1,1,1,1
1,1,1,1,1,1,43,43,43,43,43,1,1,1,1,1,1
1,1,1,1,1,1,1,1,1,1,1,1,1,1,1,1,1
1,1,1,1,1,1,1,1,1,1,1,1,1,1,1,1,1
1,1,1,1,1,1,1,1,1,1,1,1,1,1,1,1,1
1,1,1,1,1,1,1,1,1,1,1,1,1,1,1,1,1
endlayer

layer
1,1,1,1,1,1,1,1,1,1,1,1,1,1,1,1,1
1,1,1,1,1,1,1,1,1,1,1,1,1,1,1,1,1
1,1,1,1,1,1,1,1,1,1,1,1,1,1,1,1,1
1,1,1,1,1,1,1,1,1,1,1,1,1,1,1,1,1
1,1,1,1,1,1,1,1,1,1,1,1,1,1,1,1,1
1,1,1,1,1,1,1,1,1,1,1,1,1,1,1,1,1
1,1,1,1,1,1,1,43,43,43,1,1,1,1,1,1,1
1,1,1,1,1,1,43,43,43,43,43,1,1,1,1,1,1
1,1,1,1,1,1,43,43,43,43,43,1,1,1,1,1,1
1,1,1,1,1,1,43,43,43,43,43,1,1,1,1,1,1
1,1,1,1,1,1,1,43,43,43,1,1,1,1,1,1,1
1,1,1,1,1,1,1,1,1,1,1,1,1,1,1,1,1
1,1,1,1,1,1,1,1,1,1,1,1,1,1,1,1,1
1,1,1,1,1,1,1,1,1,1,1,1,1,1,1,1,1
1,1,1,1,1,1,1,1,1,1,1,1,1,1,1,1,1
1,1,1,1,1,1,1,1,1,1,1,1,1,1,1,1,1
1,1,1,1,1,1,1,1,1,1,1,1,1,1,1,1,1
endlayer

