
# Created by Ruins mod version 16.7 Ingame Parser
# authoring Player: ST753M

weight=1
embed_into_distance=6
acceptable_target_blocks=
unacceptable_target_blocks=flowing_water,water,flowing_lava,lava,ice,bedrock,netherrack,nether_brick,nether_brick_fence,soul_sand,quartz_ore,end_stone,obsidian,iron_bars,Natura:Cloud,slime_grass,slime_congealed,slime_dirt,clouds,natura:clouds
dimensions=16,17,17

allowable_overhang=6
max_leveling=0
leveling_buffer=0
preserve_water=1
preserve_lava=1
uniqueMinDistance=1500

biomesToSpawnIn=deep_ocean
=0,100,air


rule1=0,100,preserveBlock
rule2=0,100,minecraft:stone-0
rule3=0,100,minecraft:mossy_cobblestone-0
rule4=0,100,minecraft:water-0
rule5=0,100,minecraft:emerald_ore-0
rule6=0,100,minecraft:tripwire_hook-7
rule7=0,100,minecraft:water-9
rule8=0,100,minecraft:tripwire-4
rule9=0,100,minecraft:tripwire_hook-5
rule10=0,100,minecraft:vine-4
rule11=0,100,minecraft:vine-1
rule12=0,100,minecraft:cobblestone_wall-1
rule13=0,100,CommandBlock:RUINSTRIGGER /summon cave_spider ~ ~1 ~ {HandItems:[{id:"minecraft:wooden_sword",Count:1b,tag:{display:{Name:"Jungle Blade"},ench:[{id:18,lvl:4},{id:22,lvl:1},{id:34,lvl:2}]}},{}],PersistenceRequired:1}:@-1
rule14=0,100,ChestGenHook:chests/jungle_temple:5-3
rule15=0,100,ChestGenHook:chests/jungle_temple:5-2,air
rule16=0,100,IInventory;minecraft:dispenser;minecraft:splash_potion#{Potion:"minecraft:weakness"}#0#0+minecraft:splash_potion#{Potion:"minecraft:weakness"}#0#1+minecraft:splash_potion#{Potion:"minecraft:weakness"}#0#2+minecraft:splash_potion#{Potion:"minecraft:weakness"}#0#3-5
rule17=0,100,minecraft:water-1
rule18=0,100,minecraft:vine-2
rule19=0,100,minecraft:vine-8
rule20=1,100,minecraft:redstone_torch-5
rule21=0,100,IInventory;minecraft:dispenser;minecraft:splash_potion#{Potion:"minecraft:weakness"}#0#0+minecraft:splash_potion#{Potion:"minecraft:weakness"}#0#1+minecraft:splash_potion#{Potion:"minecraft:weakness"}#0#2+minecraft:splash_potion#{Potion:"minecraft:weakness"}#0#3-4
rule22=0,100,minecraft:vine-6
rule23=0,100,minecraft:stone_stairs-3
rule24=0,100,minecraft:stone_stairs-2
rule25=0,100,minecraft:vine-9
rule26=0,100,minecraft:stone_stairs-5
rule27=0,100,minecraft:stone_stairs-4
rule28=0,100,minecraft:grass-0
rule29=0,100,minecraft:tallgrass-2
rule30=0,100,minecraft:stone_stairs-0
rule31=0,100,minecraft:stone_stairs-7
rule32=0,100,minecraft:stone_stairs-6
rule33=0,100,minecraft:stone_stairs-1
rule34=0,100,minecraft:stained_glass-13
^0,100,minecraft:stained_glass-0
^0,100,minecraft:stained_glass-9
^0,100,minecraft:stained_glass-3
^0,100,minecraft:stained_glass-11
^0,100,minecraft:stained_glass-8
^0,100,minecraft:stained_glass-7
^0,100,minecraft:glass-0

layer
1,1,1,1,1,1,2,2,2,2,2,1,1,1,1,1,1
1,1,1,1,2,2,2,3,3,3,2,2,2,1,1,1,1
1,1,1,2,2,2,3,4,4,4,3,3,2,2,1,1,1
1,1,2,2,3,3,3,3,3,3,3,3,3,2,2,1,1
1,5,2,3,3,3,3,3,3,3,3,3,3,3,2,2,1
1,2,2,3,3,3,3,3,3,3,3,3,3,3,2,2,1
2,2,3,3,3,3,3,3,3,3,3,3,3,3,3,2,2
2,3,4,3,3,3,3,4,4,4,3,3,3,3,4,3,2
2,3,4,3,3,3,3,4,4,4,3,3,3,3,4,3,2
2,3,4,3,3,3,3,4,4,4,3,3,3,3,4,3,2
2,2,3,3,3,3,3,3,3,3,3,3,3,3,3,2,2
1,2,2,3,3,3,3,3,3,3,3,3,3,3,2,2,1
1,2,2,3,3,3,3,3,3,3,3,3,3,3,2,2,1
1,1,2,2,3,3,3,3,3,3,3,3,3,2,2,1,1
1,1,1,2,2,3,3,4,4,4,3,2,2,2,1,1,1
1,1,1,1,2,2,2,3,3,3,2,2,5,1,1,1,1
1,1,1,1,1,1,2,2,2,2,2,1,1,1,1,1,1
endlayer

layer
1,1,1,1,1,1,2,2,2,2,2,1,1,1,1,1,1
1,1,1,1,2,2,3,3,3,3,3,3,2,1,1,1,1
1,1,1,2,3,3,3,0,7,0,3,6,3,2,1,1,1
1,1,2,3,0,0,3,0,0,0,3,8,0,3,2,1,1
1,2,3,0,3,0,0,0,0,0,0,8,3,0,3,2,1
1,2,3,0,0,0,3,11,0,10,3,9,0,0,3,2,1
2,3,3,3,0,3,12,0,13,0,12,3,3,3,3,3,2
2,3,0,0,0,0,3,0,0,0,3,0,0,0,0,3,2
2,15,7,0,0,0,3,0,0,0,3,0,0,0,7,14,3
2,3,0,0,0,0,3,0,0,0,3,0,0,0,0,3,2
2,3,3,3,3,3,12,0,13,0,12,3,0,3,3,3,2
1,2,3,0,0,6,3,11,0,0,3,0,0,0,3,2,1
1,2,3,0,3,8,0,0,0,0,0,0,3,0,3,2,1
1,1,2,3,0,8,3,11,0,0,3,0,0,3,2,1,1
1,1,1,2,3,9,3,0,7,0,3,3,3,2,1,1,1
1,1,1,1,2,3,3,3,3,3,3,2,2,1,1,1,1
1,1,1,1,1,1,2,2,2,2,2,1,1,1,1,1,1
endlayer

layer
1,1,1,1,1,1,2,2,3,2,2,1,1,1,1,1,1
1,1,1,1,2,2,3,3,4,3,3,16,2,1,1,1,1
1,1,1,2,3,3,3,18,17,10,3,0,3,2,1,1,1
1,1,2,3,11,0,3,0,0,10,3,18,0,3,2,1,1
1,2,3,0,3,11,0,0,0,0,19,11,3,0,3,2,1
1,2,3,0,0,0,3,0,0,10,3,0,0,0,3,2,1
2,3,3,3,0,3,20,0,0,0,20,3,3,3,3,3,2
2,3,0,0,0,0,3,0,0,10,3,0,0,0,0,3,2
3,4,17,0,0,0,3,0,0,0,3,0,0,0,17,4,3
2,3,19,0,0,10,3,11,0,10,3,0,0,0,0,3,2
2,3,3,3,3,3,20,0,0,10,20,3,0,3,3,3,2
1,2,3,0,0,0,3,0,0,0,3,0,0,0,3,2,1
1,2,3,0,3,0,0,0,0,0,0,11,3,0,3,2,1
1,1,2,3,0,0,3,0,0,0,3,0,0,3,2,1,1
1,1,1,2,3,0,3,19,17,0,3,3,3,2,1,1,1
1,1,1,1,2,21,3,3,4,3,3,2,2,1,1,1,1
1,1,1,1,1,1,2,2,3,2,2,1,1,1,1,1,1
endlayer

layer
1,1,1,1,1,1,2,2,2,2,2,1,1,1,1,1,1
1,1,1,1,2,2,3,3,3,3,3,2,2,1,1,1,1
1,1,1,2,3,3,3,18,0,18,3,3,3,2,1,1,1
1,1,2,3,11,18,3,0,0,0,3,18,0,3,2,1,1
1,2,3,18,3,22,3,11,0,10,3,11,3,0,3,2,1
1,2,3,0,0,0,3,11,0,10,3,0,0,0,3,2,1
2,3,3,3,3,3,3,11,0,10,3,3,3,3,3,3,2
2,3,11,0,22,10,24,0,0,0,23,0,0,0,0,3,2
2,3,11,0,0,10,3,0,0,0,3,0,0,0,0,3,2
2,3,25,0,19,10,24,0,0,0,23,0,0,0,0,3,2
2,3,3,3,3,3,3,0,0,10,3,3,3,3,3,3,2
1,2,3,11,19,10,3,11,0,0,3,0,0,0,3,2,1
1,2,3,0,3,10,3,11,0,10,3,11,3,0,3,2,1
1,1,2,3,0,19,3,11,0,10,3,0,19,3,2,1,1
1,1,1,2,3,3,3,11,19,19,3,3,3,2,1,1,1
1,1,1,1,2,2,3,3,3,3,3,2,2,1,1,1,1
1,1,1,1,1,1,2,2,2,2,2,1,1,1,1,1,1
endlayer

layer
1,1,1,1,1,1,2,2,2,2,2,1,1,1,1,1,1
1,1,1,1,2,2,2,2,2,2,2,2,2,1,1,1,1
1,1,1,2,2,2,3,3,3,3,3,2,2,2,1,1,1
1,1,2,2,3,3,3,3,18,3,3,3,3,2,2,1,1
1,2,2,3,3,18,3,26,26,26,3,18,3,3,2,2,1
1,2,2,3,11,0,3,0,0,10,3,19,10,3,2,2,1
2,2,3,3,3,3,12,0,0,0,12,3,3,3,3,2,2
2,2,3,3,10,3,0,0,0,0,0,3,0,3,3,2,2
2,2,3,3,11,3,12,0,0,0,12,3,0,3,3,2,2
2,2,3,3,19,3,0,0,0,0,0,3,0,3,3,2,2
2,2,3,3,3,3,12,0,0,0,12,3,3,3,3,2,2
1,2,2,3,11,0,3,0,0,0,3,0,18,3,2,2,1
1,2,2,3,3,19,3,27,27,27,3,19,3,3,2,2,1
1,1,2,2,3,3,3,3,19,3,3,3,3,2,2,1,1
1,1,1,2,2,2,3,3,3,3,3,2,2,2,1,1,1
1,1,1,1,2,2,2,2,2,2,2,2,2,1,1,1,1
1,1,1,1,1,1,2,2,2,2,2,1,1,1,1,1,1
endlayer

layer
1,1,1,1,1,1,2,2,2,2,2,1,1,1,1,1,1
1,1,1,1,2,2,28,28,28,28,28,2,2,1,1,1,1
1,1,1,2,28,28,4,4,4,4,4,28,28,2,1,1,1
1,1,2,28,4,4,28,28,28,28,28,4,4,28,2,1,1
1,2,28,4,3,3,3,3,3,3,3,3,3,4,28,2,1
1,2,28,4,3,18,3,26,26,26,3,10,3,4,28,2,1
2,28,4,28,3,3,12,0,0,0,12,3,3,28,4,28,2
2,28,4,28,3,3,0,0,0,0,0,3,3,28,4,28,2
2,28,4,28,3,3,12,0,0,0,12,3,3,28,4,28,2
2,28,4,28,3,3,0,0,0,0,0,3,3,28,4,28,2
2,28,4,28,3,3,12,0,0,0,12,3,3,28,4,28,2
1,2,28,4,3,11,3,27,27,27,3,10,3,4,28,2,1
1,2,28,4,3,3,3,3,3,3,3,3,3,4,28,2,1
1,1,2,28,4,4,28,28,28,28,28,4,4,28,2,1,1
1,1,1,2,28,28,4,4,4,4,4,28,28,2,1,1,1
1,1,1,1,2,2,28,28,28,28,28,2,2,1,1,1,1
1,1,1,1,1,1,2,2,2,2,2,1,1,1,1,1,1
endlayer

layer
1,1,1,1,1,1,2,2,2,2,2,1,1,1,1,1,1
1,1,1,1,2,2,29,29,29,29,29,2,2,1,1,1,1
1,1,1,2,29,29,0,0,0,0,0,29,29,2,1,1,1
1,1,2,29,0,0,29,29,29,29,29,0,0,29,2,1,1
1,2,29,0,3,19,30,3,0,3,30,0,3,0,29,2,1
1,2,29,0,0,3,3,3,30,3,3,3,0,0,29,2,1
2,29,0,29,23,3,3,26,26,26,3,3,24,29,0,29,2
2,29,0,29,3,3,32,0,0,0,31,3,3,29,0,29,2
2,29,0,29,0,23,3,0,0,0,3,24,0,29,0,29,2
2,29,0,29,3,3,32,0,0,0,31,3,3,29,0,29,2
2,29,0,29,23,3,3,27,27,27,3,3,24,29,0,29,2
1,2,29,0,0,3,3,3,33,3,3,3,0,0,29,2,1
1,2,29,0,3,0,33,3,0,3,33,0,3,0,29,2,1
1,1,2,29,0,0,29,29,29,29,29,0,0,29,2,1,1
1,1,1,2,29,29,0,0,0,0,0,29,29,2,1,1,1
1,1,1,1,2,2,29,29,29,29,29,2,2,1,1,1,1
1,1,1,1,1,1,2,2,2,2,2,1,1,1,1,1,1
endlayer

layer
1,1,1,1,1,1,34,34,34,34,34,1,1,1,1,1,1
1,1,1,1,34,34,0,0,0,0,0,34,34,1,1,1,1
1,1,1,34,0,0,0,0,0,0,0,0,0,34,1,1,1
1,1,34,0,0,0,0,0,0,0,0,0,0,0,34,1,1
1,34,0,0,12,0,0,3,0,3,0,0,12,0,0,34,1
1,34,0,0,0,0,30,0,0,0,30,0,0,0,0,34,1
34,0,0,0,0,23,3,3,30,3,3,24,0,0,0,0,34
34,0,0,0,3,10,3,26,26,26,3,0,3,0,0,0,34
34,0,0,0,19,0,23,0,0,0,24,0,0,0,0,0,34
34,0,0,0,3,0,3,27,27,27,3,0,3,0,0,0,34
34,0,0,0,0,23,3,3,33,3,3,24,0,0,0,0,34
1,34,0,0,0,0,33,0,0,18,33,0,0,0,0,34,1
1,34,0,0,12,0,0,3,0,3,0,0,12,0,0,34,1
1,1,34,0,0,0,0,0,0,0,0,0,0,0,34,1,1
1,1,1,34,0,0,0,0,0,0,0,0,0,34,1,1,1
1,1,1,1,34,34,0,0,0,0,0,34,34,1,1,1,1
1,1,1,1,1,1,34,34,34,34,34,1,1,1,1,1,1
endlayer

layer
1,1,1,1,1,1,34,34,34,34,34,1,1,1,1,1,1
1,1,1,1,34,34,0,0,0,0,0,34,34,1,1,1,1
1,1,1,34,0,0,0,0,0,0,0,0,0,34,1,1,1
1,1,34,0,0,0,0,19,0,19,0,0,0,0,34,1,1
1,34,0,0,12,0,0,3,0,3,11,0,12,0,0,34,1
1,34,0,0,0,0,0,0,0,0,0,0,0,0,0,34,1
34,0,0,0,19,0,0,0,0,19,0,0,0,0,0,0,34
34,0,0,0,3,0,0,3,30,3,11,0,3,0,0,0,34
34,0,0,0,0,0,0,23,10,24,0,0,0,0,0,0,34
34,0,0,0,3,11,10,3,33,3,0,10,3,11,0,0,34
34,0,0,0,0,0,0,18,0,18,0,0,0,0,0,0,34
1,34,0,0,0,0,0,19,0,19,0,0,0,0,0,34,1
1,34,0,0,12,0,0,3,0,3,0,0,12,0,0,34,1
1,1,34,0,0,0,0,0,0,0,0,0,0,0,34,1,1
1,1,1,34,0,0,0,0,0,0,0,0,0,34,1,1,1
1,1,1,1,34,34,0,0,0,0,0,34,34,1,1,1,1
1,1,1,1,1,1,34,34,34,34,34,1,1,1,1,1,1
endlayer

layer
1,1,1,1,1,1,1,34,34,34,1,1,1,1,1,1,1
1,1,1,1,34,34,34,0,0,0,34,34,34,1,1,1,1
1,1,1,34,0,0,0,0,0,0,0,0,0,34,1,1,1
1,1,34,0,19,0,0,0,0,0,0,0,0,0,34,1,1
1,34,0,0,3,11,0,23,12,24,0,0,3,11,0,34,1
1,34,0,0,0,0,0,0,0,0,0,0,18,0,0,34,1
1,34,0,0,0,0,0,0,0,0,0,0,0,0,0,34,1
34,0,0,0,30,0,0,12,0,12,0,0,30,0,0,0,34
34,0,0,0,12,0,0,0,0,0,0,0,12,0,0,0,34
34,0,0,0,33,0,0,12,0,12,0,0,33,0,0,0,34
1,34,0,0,0,0,0,0,0,0,0,0,0,0,0,34,1
1,34,0,0,19,0,0,0,0,0,0,0,19,0,0,34,1
1,34,0,0,3,0,0,23,12,24,0,10,3,0,0,34,1
1,1,34,0,0,0,0,0,0,0,0,0,0,0,34,1,1
1,1,1,34,0,0,0,0,0,0,0,0,0,34,1,1,1
1,1,1,1,34,34,34,0,0,0,34,34,34,1,1,1,1
1,1,1,1,1,1,1,34,34,34,1,1,1,1,1,1,1
endlayer

layer
1,1,1,1,1,1,1,1,1,1,1,1,1,1,1,1,1
1,1,1,1,1,34,34,34,34,34,34,34,1,1,1,1,1
1,1,1,34,34,0,0,0,0,0,0,0,34,34,1,1,1
1,1,34,0,0,0,0,0,0,0,0,0,0,0,34,1,1
1,1,34,0,12,0,0,0,0,0,0,0,12,0,34,1,1
1,34,0,0,0,0,0,0,0,0,0,0,0,0,0,34,1
1,34,0,0,0,0,0,0,0,0,0,0,0,0,0,34,1
1,34,0,0,0,0,0,12,0,12,0,0,0,0,0,34,1
1,34,0,0,0,0,0,0,0,0,0,0,0,0,0,34,1
1,34,0,0,0,0,0,12,0,12,0,0,0,0,0,34,1
1,34,0,0,0,0,0,0,0,0,0,0,0,0,0,34,1
1,34,0,0,0,0,0,0,0,0,0,0,0,0,0,34,1
1,1,34,0,12,0,0,0,0,0,0,0,12,0,34,1,1
1,1,34,0,0,0,0,0,0,0,0,0,0,0,34,1,1
1,1,1,34,34,0,0,0,0,0,0,0,34,34,1,1,1
1,1,1,1,1,34,34,34,34,34,34,34,1,1,1,1,1
1,1,1,1,1,1,1,1,1,1,1,1,1,1,1,1,1
endlayer

layer
1,1,1,1,1,1,1,1,1,1,1,1,1,1,1,1,1
1,1,1,1,1,1,34,34,34,34,34,1,1,1,1,1,1
1,1,1,1,34,34,0,0,0,0,0,34,34,1,1,1,1
1,1,1,34,0,0,0,0,0,0,0,0,0,34,1,1,1
1,1,34,0,0,0,0,0,0,0,0,0,0,0,34,1,1
1,1,34,0,0,0,0,0,0,0,0,0,0,0,34,1,1
1,34,0,0,0,0,0,0,0,0,0,0,0,0,0,34,1
1,34,0,0,0,0,0,23,30,24,0,0,0,0,0,34,1
1,34,0,0,0,0,0,23,3,24,0,0,0,0,0,34,1
1,34,0,0,0,0,0,23,33,33,0,0,0,0,0,34,1
1,34,0,0,0,0,0,0,0,0,0,0,0,0,0,34,1
1,1,34,0,0,0,0,0,0,0,0,0,0,0,34,1,1
1,1,34,0,0,0,0,0,0,0,0,0,0,0,34,1,1
1,1,1,34,0,0,0,0,0,0,0,0,0,34,1,1,1
1,1,1,1,34,34,0,0,0,0,0,34,34,1,1,1,1
1,1,1,1,1,1,34,34,34,34,34,1,1,1,1,1,1
1,1,1,1,1,1,1,1,1,1,1,1,1,1,1,1,1
endlayer

layer
1,1,1,1,1,1,1,1,1,1,1,1,1,1,1,1,1
1,1,1,1,1,1,1,1,1,1,1,1,1,1,1,1,1
1,1,1,1,1,34,34,34,34,34,34,34,1,1,1,1,1
1,1,1,1,34,0,0,0,0,0,0,0,34,1,1,1,1
1,1,1,34,0,0,0,0,0,0,0,0,0,34,1,1,1
1,1,34,0,0,0,0,0,0,0,0,0,0,0,34,1,1
1,1,34,0,0,0,0,0,0,0,0,0,0,0,34,1,1
1,1,34,0,0,0,0,0,0,0,0,0,0,0,34,1,1
1,1,34,0,0,0,0,0,0,0,0,0,0,0,34,1,1
1,1,34,0,0,0,0,0,0,0,0,0,0,0,34,1,1
1,1,34,0,0,0,0,0,0,0,0,0,0,0,34,1,1
1,1,34,0,0,0,0,0,0,0,0,0,0,0,34,1,1
1,1,1,34,0,0,0,0,0,0,0,0,0,34,1,1,1
1,1,1,1,34,0,0,0,0,0,0,0,34,1,1,1,1
1,1,1,1,1,34,34,34,34,34,34,34,1,1,1,1,1
1,1,1,1,1,1,1,1,1,1,1,1,1,1,1,1,1
1,1,1,1,1,1,1,1,1,1,1,1,1,1,1,1,1
endlayer

layer
1,1,1,1,1,1,1,1,1,1,1,1,1,1,1,1,1
1,1,1,1,1,1,1,1,1,1,1,1,1,1,1,1,1
1,1,1,1,1,1,1,1,1,1,1,1,1,1,1,1,1
1,1,1,1,1,34,34,34,34,34,34,34,1,1,1,1,1
1,1,1,1,34,34,0,0,0,0,0,34,34,1,1,1,1
1,1,1,34,34,0,0,0,0,0,0,0,34,34,1,1,1
1,1,1,34,0,0,0,0,0,0,0,0,0,34,1,1,1
1,1,1,34,0,0,0,0,0,0,0,0,0,34,1,1,1
1,1,1,34,0,0,0,0,0,0,0,0,0,34,1,1,1
1,1,1,34,0,0,0,0,0,0,0,0,0,34,1,1,1
1,1,1,34,0,0,0,0,0,0,0,0,0,34,1,1,1
1,1,1,34,34,0,0,0,0,0,0,0,34,34,1,1,1
1,1,1,1,34,34,0,0,0,0,0,34,34,1,1,1,1
1,1,1,1,1,34,34,34,34,34,34,34,1,1,1,1,1
1,1,1,1,1,1,1,1,1,1,1,1,1,1,1,1,1
1,1,1,1,1,1,1,1,1,1,1,1,1,1,1,1,1
1,1,1,1,1,1,1,1,1,1,1,1,1,1,1,1,1
endlayer

layer
1,1,1,1,1,1,1,1,1,1,1,1,1,1,1,1,1
1,1,1,1,1,1,1,1,1,1,1,1,1,1,1,1,1
1,1,1,1,1,1,1,1,1,1,1,1,1,1,1,1,1
1,1,1,1,1,1,1,1,1,1,1,1,1,1,1,1,1
1,1,1,1,1,1,34,34,34,34,34,1,1,1,1,1,1
1,1,1,1,1,34,34,34,34,34,34,34,1,1,1,1,1
1,1,1,1,34,34,34,0,0,0,34,34,34,1,1,1,1
1,1,1,1,34,34,0,0,0,0,0,34,34,1,1,1,1
1,1,1,1,34,34,0,0,0,0,0,34,34,1,1,1,1
1,1,1,1,34,34,0,0,0,0,0,34,34,1,1,1,1
1,1,1,1,34,34,34,0,0,0,34,34,34,1,1,1,1
1,1,1,1,1,34,34,34,34,34,34,34,1,1,1,1,1
1,1,1,1,1,1,34,34,34,34,34,1,1,1,1,1,1
1,1,1,1,1,1,1,1,1,1,1,1,1,1,1,1,1
1,1,1,1,1,1,1,1,1,1,1,1,1,1,1,1,1
1,1,1,1,1,1,1,1,1,1,1,1,1,1,1,1,1
1,1,1,1,1,1,1,1,1,1,1,1,1,1,1,1,1
endlayer

layer
1,1,1,1,1,1,1,1,1,1,1,1,1,1,1,1,1
1,1,1,1,1,1,1,1,1,1,1,1,1,1,1,1,1
1,1,1,1,1,1,1,1,1,1,1,1,1,1,1,1,1
1,1,1,1,1,1,1,1,1,1,1,1,1,1,1,1,1
1,1,1,1,1,1,1,1,1,1,1,1,1,1,1,1,1
1,1,1,1,1,1,1,1,1,1,1,1,1,1,1,1,1
1,1,1,1,1,1,1,34,34,34,1,1,1,1,1,1,1
1,1,1,1,1,1,34,34,34,34,34,1,1,1,1,1,1
1,1,1,1,1,1,34,34,34,34,34,1,1,1,1,1,1
1,1,1,1,1,1,34,34,34,34,34,1,1,1,1,1,1
1,1,1,1,1,1,1,34,34,34,1,1,1,1,1,1,1
1,1,1,1,1,1,1,1,1,1,1,1,1,1,1,1,1
1,1,1,1,1,1,1,1,1,1,1,1,1,1,1,1,1
1,1,1,1,1,1,1,1,1,1,1,1,1,1,1,1,1
1,1,1,1,1,1,1,1,1,1,1,1,1,1,1,1,1
1,1,1,1,1,1,1,1,1,1,1,1,1,1,1,1,1
1,1,1,1,1,1,1,1,1,1,1,1,1,1,1,1,1
endlayer

