
# Created by Ruins mod version 16.5 Ingame Parser
# authoring Player: ST753M

weight=2
embed_into_distance=0
acceptable_target_blocks=gravel,dirt,clay,stone
unacceptable_target_blocks=lava
dimensions=13,20,6
allowable_overhang=1
max_leveling=2
leveling_buffer=0
preserve_water=1
preserve_lava=1
preserve_plants=1

biomesToSpawnIn=deep_ocean

rule1=0,100,preserveBlock
rule2=0,100,minecraft:prismarine-0
^0,100,minecraft:prismarine-1
^0,100,minecraft:prismarine-2
rule3=0,20,IInventory;minecraft:chest;minecraft:prismarine_shard#4#0#2+minecraft:ender_pearl#2#0#5+minecraft:ghast_tear#2#0#10+minecraft:chainmail_helmet#1#0#16+minecraft:potion#{Potion:"minecraft:swiftness"}#0#22+minecraft:prismarine_crystals#5#0#24-3,IInventory;minecraft:chest;minecraft:prismarine_crystals#6#0#4+minecraft:prismarine_shard#7#0#11+minecraft:potion#{Potion:"minecraft:water_breathing"}#0#14+minecraft:water_bucket#1#0#19+minecraft:diamond_chestplate#1#0#21+minecraft:diamond#1#0#25-3,IInventory;minecraft:chest;minecraft:emerald#3#0#3+minecraft:potion#{Potion:"minecraft:night_vision"}#0#5+minecraft:chainmail_boots#1#0#10+minecraft:diamond_horse_armor#1#0#16+minecraft:prismarine_shard#6#0#21+minecraft:dye#5#4#25-3,IInventory;minecraft:chest;minecraft:diamond#3#0#1+minecraft:diamond_horse_armor#1#0#6+minecraft:potion#{Potion:"minecraft:strength"}#0#11+minecraft:prismarine_shard#8#0#13+minecraft:diamond_helmet#1#0#17+minecraft:bucket#1#0#22-3,IInventory;minecraft:chest;minecraft:bucket#2#0#4+minecraft:potion#{Potion:"minecraft:long_water_breathing"}#0#8+minecraft:skull#1#0#11+minecraft:water_bucket#1#0#18+minecraft:chainmail_leggings#1#0#22+minecraft:prismarine_shard#10#0#25-3,IInventory;minecraft:chest;minecraft:ender_pearl#2#0#1+minecraft:diamond_horse_armor#1#0#5+minecraft:diamond_boots#1#0#12+minecraft:prismarine_shard#12#0#15+minecraft:potion#{Potion:"minecraft:regeneration"}#0#19+minecraft:bucket#1#0#23-3,IInventory;minecraft:chest;minecraft:water_bucket#1#0#3+minecraft:prismarine_crystals#5#0#7+minecraft:ender_eye#2#0#9+minecraft:chainmail_chestplate#1#0#14+minecraft:potion#{Potion:"minecraft:invisibility"}#0#20+minecraft:prismarine_shard#7#0#25-3,IInventory;minecraft:chest;minecraft:emerald#5#0#2+minecraft:water_bucket#1#0#9+minecraft:diamond_leggings#1#0#12+minecraft:potion#{Potion:"minecraft:long_leaping"}#0#14+minecraft:prismarine_shard#10#0#16+minecraft:prismarine_crystals#9#0#24-3
rule4=0,100,minecraft:prismarine-0
^0,100,minecraft:prismarine-1
^0,100,minecraft:prismarine-2
rule5=0,100,minecraft:prismarine-0
^0,100,minecraft:prismarine-1
^0,100,minecraft:prismarine-2
rule6=0,100,minecraft:tripwire-0

layer
1,1,1,1,1,1
1,1,2,2,1,1
1,2,2,2,2,1
1,2,2,2,2,1
1,1,2,2,1,1
1,1,1,1,1,1
1,1,1,3,1,1
1,1,1,1,1,1
1,1,2,2,1,1
1,2,2,2,2,1
1,2,2,2,2,1
1,1,2,2,1,1
1,1,1,1,1,1
1,1,3,1,1,1
1,1,1,1,1,1
1,1,2,2,1,1
1,2,2,2,2,1
1,2,2,2,2,1
1,1,2,2,1,1
1,1,1,1,1,1
endlayer

layer
1,1,1,1,1,1
1,1,1,1,1,1
1,1,4,4,1,1
1,1,4,4,1,1
1,1,1,1,1,1
1,1,1,1,1,1
1,1,1,1,1,1
1,1,1,1,1,1
1,1,1,1,1,1
1,1,4,4,1,1
1,1,4,4,1,1
1,1,1,1,1,1
1,1,1,1,1,1
1,1,1,1,1,1
1,1,1,1,1,1
1,1,1,1,1,1
1,1,4,4,1,1
1,1,4,4,1,1
1,1,1,1,1,1
1,1,1,1,1,1
endlayer

layer
1,1,1,1,1,1
1,1,1,1,1,1
1,1,5,5,1,1
1,1,5,5,1,1
1,1,1,1,1,1
1,1,1,1,1,1
1,1,1,1,1,1
1,1,1,1,1,1
1,1,1,1,1,1
1,1,5,5,1,1
1,1,5,5,1,1
1,1,1,1,1,1
1,1,1,1,1,1
1,1,1,1,1,1
1,1,1,1,1,1
1,1,1,1,1,1
1,1,5,5,1,1
1,1,5,5,1,1
1,1,1,1,1,1
1,1,1,1,1,1
endlayer

layer
1,1,1,1,1,1
1,1,1,1,1,1
1,1,4,4,1,1
1,1,4,4,1,1
1,1,1,1,1,1
1,1,1,1,1,1
1,1,1,1,1,1
1,1,1,1,1,1
1,1,1,1,1,1
1,1,4,4,1,1
1,1,4,4,1,1
1,1,1,1,1,1
1,1,1,1,1,1
1,1,1,1,1,1
1,1,1,1,1,1
1,1,1,1,1,1
1,1,4,4,1,1
1,1,4,4,1,1
1,1,1,1,1,1
1,1,1,1,1,1
endlayer

layer
1,1,1,1,1,1
1,1,1,1,1,1
1,1,4,4,1,1
1,1,4,4,1,1
1,1,1,1,1,1
1,1,1,1,1,1
1,1,1,1,1,1
1,1,1,1,1,1
1,1,1,1,1,1
1,1,4,4,1,1
1,1,4,4,1,1
1,1,1,1,1,1
1,1,1,1,1,1
1,1,1,1,1,1
1,1,1,1,1,1
1,1,1,1,1,1
1,1,4,4,1,1
1,1,4,4,1,1
1,1,1,1,1,1
1,1,1,1,1,1
endlayer

layer
1,1,1,1,1,1
1,1,1,1,1,1
1,1,4,4,1,1
1,1,4,4,1,1
1,1,1,1,1,1
1,1,1,1,1,1
1,1,1,1,1,1
1,1,1,1,1,1
1,1,1,1,1,1
1,1,4,4,1,1
1,1,4,4,1,1
1,1,1,1,1,1
1,1,1,1,1,1
1,1,1,1,1,1
1,1,1,1,1,1
1,1,1,1,1,1
1,1,4,4,1,1
1,1,4,4,1,1
1,1,1,1,1,1
1,1,1,1,1,1
endlayer

layer
1,1,1,1,1,1
1,1,1,1,1,1
1,1,4,4,1,1
1,1,4,4,1,1
1,1,1,1,1,1
1,1,1,1,1,1
1,1,1,1,1,1
1,1,1,1,1,1
1,1,1,1,1,1
1,1,4,4,1,1
1,1,4,4,1,1
1,1,1,1,1,1
1,1,1,1,1,1
1,1,1,1,1,1
1,1,1,1,1,1
1,1,1,1,1,1
1,1,4,4,1,1
1,1,4,4,1,1
1,1,1,1,1,1
1,1,1,1,1,1
endlayer

layer
1,1,1,1,1,1
1,1,1,1,1,1
1,1,4,4,1,1
1,1,4,4,1,1
1,1,1,1,1,1
1,1,1,1,1,1
1,1,1,1,1,1
1,1,1,1,1,1
1,1,1,1,1,1
1,1,4,4,1,1
1,1,4,4,1,1
1,1,1,1,1,1
1,1,1,1,1,1
1,1,1,1,1,1
1,1,1,1,1,1
1,1,1,1,1,1
1,1,4,4,1,1
1,1,4,4,1,1
1,1,1,1,1,1
1,1,1,1,1,1
endlayer

layer
1,1,1,1,1,1
1,1,1,1,1,1
1,1,5,5,1,1
1,1,5,5,1,1
1,1,1,1,1,1
1,1,1,1,1,1
1,1,1,1,1,1
1,1,1,1,1,1
1,1,1,1,1,1
1,1,5,5,1,1
1,1,5,5,1,1
1,1,1,1,1,1
1,1,1,1,1,1
1,1,1,1,1,1
1,1,1,1,1,1
1,1,1,1,1,1
1,1,5,5,1,1
1,1,5,5,1,1
1,1,1,1,1,1
1,1,1,1,1,1
endlayer

layer
1,1,1,1,1,1
1,1,1,1,1,1
1,1,4,4,1,1
1,1,4,4,1,1
1,1,1,1,1,1
1,1,1,1,1,1
1,1,1,1,1,1
1,1,1,1,1,1
1,1,1,1,1,1
1,1,4,4,1,1
1,1,4,4,1,1
1,1,1,1,1,1
1,1,1,1,1,1
1,1,1,1,1,1
1,1,1,1,1,1
1,1,1,1,1,1
1,1,4,4,1,1
1,1,4,4,1,1
1,1,1,1,1,1
1,1,1,1,1,1
endlayer

layer
1,1,1,1,1,1
1,1,2,2,1,1
1,2,2,2,2,1
1,2,2,2,2,1
1,1,2,2,1,1
1,1,1,1,1,1
1,1,1,1,1,1
1,1,1,1,1,1
1,1,2,2,1,1
1,2,2,2,2,1
1,2,2,2,2,1
1,1,2,2,1,1
1,1,1,1,1,1
1,1,1,1,1,1
1,1,1,1,1,1
1,1,2,2,1,1
1,2,2,2,2,1
1,2,2,2,2,1
1,1,2,2,1,1
1,1,1,1,1,1
endlayer

layer
0,4,4,4,4,0
4,4,4,4,4,4
4,4,4,4,4,4
4,4,4,4,4,4
4,4,4,4,4,4
4,4,6,6,4,4
4,4,6,6,4,4
4,4,6,6,4,4
4,4,4,4,4,4
4,4,4,4,4,4
4,4,4,4,4,4
4,4,4,4,4,4
4,4,6,6,4,4
4,4,6,6,4,4
4,4,6,6,4,4
4,4,4,4,4,4
4,4,4,4,4,4
4,4,4,4,4,4
4,4,4,4,4,4
0,4,4,4,4,0
endlayer

layer
0,0,0,0,0,0
0,4,4,4,4,0
0,4,4,4,4,0
0,4,4,4,4,0
0,4,4,4,4,0
0,4,4,4,4,0
0,4,4,4,4,0
0,4,4,4,4,0
0,4,4,4,4,0
0,4,4,4,4,0
0,4,4,4,4,0
0,4,4,4,4,0
0,4,4,4,4,0
0,4,4,4,4,0
0,4,4,4,4,0
0,4,4,4,4,0
0,4,4,4,4,0
0,4,4,4,4,0
0,4,4,4,4,0
0,0,0,0,0,0
endlayer

