
# Created by Ruins mod version 16.7 Ingame Parser
# authoring Player: ST753M

weight=1
embed_into_distance=6
acceptable_target_blocks=gravel
unacceptable_target_blocks=flowing_water,water,flowing_lava,lava
dimensions=16,17,17
allowable_overhang=0
max_leveling=0
leveling_buffer=0
preserve_water=1
preserve_lava=0

biomesToSpawnIn=deep_ocean,kelp_forest

=0,100,air
rule1=0,100,preserveBlock
rule2=0,100,minecraft:stone-0
rule3=0,100,quark:midori_pillar-4
rule4=0,100,quark:midori_pillar-8
rule5=0,100,quark:midori_pillar-0
rule6=0,100,minecraft:water-0
rule7=0,100,quark:midori_block-0
rule8=0,100,minecraft:grass-0
rule9=0,100,minecraft:trapdoor-15
rule10=0,100,quark:crystal-4
rule11=0,100,minecraft:trapdoor-13
rule12=0,100,minecraft:trapdoor-12
rule13=0,100,minecraft:water-8
rule14=0,100,minecraft:trapdoor-14
rule15=0,100,minecraft:double_plant-3
rule16=0,100,minecraft:tallgrass-2
rule17=0,100,minecraft:double_plant-10
rule18=0,100,minecraft:double_plant-0
rule19=0,100,minecraft:yellow_flower-0
rule20=0,100,quark:midori_block_slab-0
rule21=0,100,minecraft:stained_glass-13
rule22=0,100,quark:stained_clay_tiles_green_slab-0
rule23=0,100,quark:stained_clay_tiles-13
rule24=0,100,quark:stained_clay_tiles_green_slab-8

layer
1,1,1,1,1,1,2,2,2,2,2,1,1,1,1,1,1
1,1,1,1,2,2,2,2,2,2,2,2,2,1,1,1,1
1,1,1,2,2,2,3,4,3,4,3,2,2,2,1,1,1
1,1,2,2,4,3,4,3,4,3,4,3,4,2,2,1,1
1,2,2,4,3,4,3,4,3,4,3,4,3,4,2,2,1
1,2,2,3,4,3,4,3,4,3,4,3,4,3,2,2,1
2,2,3,4,3,4,3,5,5,5,3,4,3,4,3,2,2
2,2,4,3,4,3,5,6,6,6,5,3,4,3,4,2,2
2,2,3,4,3,4,5,6,6,6,5,4,3,4,3,2,2
2,2,4,3,4,3,5,6,6,6,5,3,4,3,4,2,2
2,2,3,4,3,4,3,5,5,5,3,4,3,4,3,2,2
1,2,2,3,4,3,4,3,4,3,4,3,4,3,2,2,1
1,2,2,4,3,4,3,4,3,4,3,4,3,4,2,2,1
1,1,2,2,4,3,4,3,4,3,4,3,4,2,2,1,1
1,1,1,2,2,2,3,4,3,4,3,2,2,2,1,1,1
1,1,1,1,2,2,2,2,2,2,2,2,2,1,1,1,1
1,1,1,1,1,1,2,2,2,2,2,1,1,1,1,1,1
endlayer

layer
1,1,1,1,1,1,2,2,2,2,2,1,1,1,1,1,1
1,1,1,1,2,2,4,4,4,4,4,2,2,1,1,1,1
1,1,1,2,7,5,8,8,8,8,8,5,7,2,1,1,1
1,1,2,5,0,0,9,9,9,9,9,0,0,5,2,1,1
1,2,7,0,0,0,0,0,0,0,0,0,0,0,7,2,1
1,2,5,0,0,10,0,0,0,0,0,10,0,0,5,2,1
2,3,8,12,0,0,0,0,0,0,0,0,0,11,8,3,2
2,3,8,12,0,0,0,13,13,13,0,0,0,11,8,3,2
2,3,8,12,0,0,0,13,13,13,0,0,0,11,8,3,2
2,3,8,12,0,0,0,13,13,13,0,0,0,11,8,3,2
2,3,8,12,0,0,0,0,0,0,0,0,0,11,8,3,2
1,2,5,0,0,10,0,0,0,0,0,10,0,0,5,2,1
1,2,7,0,0,0,0,0,0,0,0,0,0,0,7,2,1
1,1,2,5,0,0,14,14,14,14,14,0,0,5,2,1,1
1,1,1,2,7,5,8,8,8,8,8,5,7,2,1,1,1
1,1,1,1,2,2,4,4,4,4,4,2,2,1,1,1,1
1,1,1,1,1,1,2,2,2,2,2,1,1,1,1,1,1
endlayer

layer
1,1,1,1,1,1,2,2,2,2,2,1,1,1,1,1,1
1,1,1,1,2,2,7,7,7,7,7,2,2,1,1,1,1
1,1,1,2,7,5,16,15,15,16,15,5,7,2,1,1,1
1,1,2,5,0,0,0,0,0,0,0,0,0,5,2,1,1
1,2,7,0,0,0,0,0,0,0,0,0,0,0,7,2,1
1,2,5,0,0,10,0,0,0,0,0,10,0,0,5,2,1
2,7,16,0,0,0,0,0,0,0,0,0,0,0,16,7,2
2,7,16,0,0,0,0,13,13,13,0,0,0,0,15,7,2
2,7,15,0,0,0,0,13,13,13,0,0,0,0,16,7,2
2,7,15,0,0,0,0,13,13,13,0,0,0,0,15,7,2
2,7,16,0,0,0,0,0,0,0,0,0,0,0,16,7,2
1,2,5,0,0,10,0,0,0,0,0,10,0,0,5,2,1
1,2,7,0,0,0,0,0,0,0,0,0,0,0,7,2,1
1,1,2,5,0,0,0,0,0,0,0,0,0,5,2,1,1
1,1,1,2,7,5,15,16,15,16,16,5,7,2,1,1,1
1,1,1,1,2,2,7,7,7,7,7,2,2,1,1,1,1
1,1,1,1,1,1,2,2,2,2,2,1,1,1,1,1,1
endlayer

layer
1,1,1,1,1,1,2,2,2,2,2,1,1,1,1,1,1
1,1,1,1,2,2,4,4,4,4,4,2,2,1,1,1,1
1,1,1,2,4,5,0,17,17,0,17,5,4,2,1,1,1
1,1,2,5,0,0,0,0,0,0,0,0,0,5,2,1,1
1,2,3,0,0,0,0,0,0,0,0,0,0,0,3,2,1
1,2,5,0,0,10,0,0,0,0,0,10,0,0,5,2,1
2,3,0,0,0,0,0,0,0,0,0,0,0,0,0,3,2
2,3,0,0,0,0,0,13,13,13,0,0,0,0,17,3,2
2,3,17,0,0,0,0,13,13,13,0,0,0,0,0,3,2
2,3,17,0,0,0,0,13,13,13,0,0,0,0,17,3,2
2,3,0,0,0,0,0,0,0,0,0,0,0,0,0,3,2
1,2,5,0,0,10,0,0,0,0,0,10,0,0,5,2,1
1,2,3,0,0,0,0,0,0,0,0,0,0,0,3,2,1
1,1,2,5,0,0,0,0,0,0,0,0,0,5,2,1,1
1,1,1,2,4,5,17,0,17,0,0,5,4,2,1,1,1
1,1,1,1,2,2,4,4,4,4,4,2,2,1,1,1,1
1,1,1,1,1,1,2,2,2,2,2,1,1,1,1,1,1
endlayer

layer
1,1,1,1,1,1,2,2,2,2,2,1,1,1,1,1,1
1,1,1,1,2,2,2,2,2,2,2,2,2,1,1,1,1
1,1,1,2,2,2,7,7,7,7,7,2,2,2,1,1,1
1,1,2,2,7,7,7,7,7,7,7,7,7,2,2,1,1
1,2,2,7,7,7,7,7,7,7,7,7,7,7,2,2,1
1,2,2,7,7,7,7,7,7,7,7,7,7,7,2,2,1
2,2,7,7,7,7,7,7,7,7,7,7,7,7,7,2,2
2,2,7,7,7,7,7,13,13,13,7,7,7,7,7,2,2
2,2,7,7,7,7,7,13,6,13,7,7,7,7,7,2,2
2,2,7,7,7,7,7,13,13,13,7,7,7,7,7,2,2
2,2,7,7,7,7,7,7,7,7,7,7,7,7,7,2,2
1,2,2,7,7,7,7,7,7,7,7,7,7,7,2,2,1
1,2,2,7,7,7,7,7,7,7,7,7,7,7,2,2,1
1,1,2,2,7,7,7,7,7,7,7,7,7,2,2,1,1
1,1,1,2,2,2,7,7,7,7,7,2,2,2,1,1,1
1,1,1,1,2,2,2,2,2,2,2,2,2,1,1,1,1
1,1,1,1,1,1,2,2,2,2,2,1,1,1,1,1,1
endlayer

layer
1,1,1,1,1,1,2,2,2,2,2,1,1,1,1,1,1
1,1,1,1,2,2,8,8,8,8,8,2,2,1,1,1,1
1,1,1,2,8,8,8,8,8,8,8,8,8,2,1,1,1
1,1,2,8,8,8,8,8,8,8,8,8,8,8,2,1,1
1,2,8,8,8,8,8,8,8,8,8,8,8,8,8,2,1
1,2,8,8,8,8,8,8,8,8,8,8,8,8,8,2,1
2,8,8,8,8,8,5,5,5,5,5,8,8,8,8,8,2
2,8,8,8,8,8,5,6,6,6,5,8,8,8,8,8,2
2,8,8,8,8,8,5,6,6,6,5,8,8,8,8,8,2
2,8,8,8,8,8,5,6,6,6,5,8,8,8,8,8,2
2,8,8,8,8,8,5,5,5,5,5,8,8,8,8,8,2
1,2,8,8,8,8,8,8,8,8,8,8,8,8,8,2,1
1,2,8,8,8,8,8,8,8,8,8,8,8,8,8,2,1
1,1,2,8,8,8,8,8,8,8,8,8,8,8,2,1,1
1,1,1,2,8,8,8,8,8,8,8,8,8,2,1,1,1
1,1,1,1,2,2,8,8,8,8,8,2,2,1,1,1,1
1,1,1,1,1,1,2,2,2,2,2,1,1,1,1,1,1
endlayer

layer
1,1,1,1,1,1,2,2,2,2,2,1,1,1,1,1,1
1,1,1,1,2,2,15,15,18,15,15,2,2,1,1,1,1
1,1,1,2,15,18,19,0,15,0,0,16,15,2,1,1,1
1,1,2,15,16,0,16,18,19,16,19,18,0,15,2,1,1
1,2,16,18,19,16,0,16,0,0,0,19,16,19,0,2,1
1,2,0,16,0,18,15,15,15,18,15,16,16,18,15,2,1
2,16,19,19,16,19,5,20,20,20,5,0,19,16,0,15,2
2,18,19,16,16,19,20,0,0,0,20,16,0,19,19,18,2
2,15,16,0,16,15,20,0,0,0,20,15,16,19,16,19,2
2,15,15,19,16,0,20,0,0,0,20,18,0,19,19,16,2
2,16,16,0,18,15,5,20,20,20,5,0,15,16,0,15,2
1,2,15,15,16,16,19,0,15,15,15,15,0,18,15,2,1
1,2,15,0,0,15,0,16,16,0,18,15,19,0,0,2,1
1,1,2,15,19,0,15,19,16,19,0,15,16,16,2,1,1
1,1,1,2,0,15,19,16,18,16,0,15,15,2,1,1,1
1,1,1,1,2,2,15,0,16,0,15,2,2,1,1,1,1
1,1,1,1,1,1,2,2,2,2,2,1,1,1,1,1,1
endlayer

layer
1,1,1,1,1,1,21,21,21,21,21,1,1,1,1,1,1
1,1,1,1,21,21,17,17,17,17,17,21,21,1,1,1,1
1,1,1,21,17,17,0,0,17,0,0,0,17,21,1,1,1
1,1,21,17,0,0,0,17,0,0,0,17,0,17,21,1,1
1,21,0,17,0,0,0,0,0,0,0,0,0,0,0,21,1
1,21,0,0,0,17,17,17,17,17,17,0,0,17,17,21,1
21,0,0,0,0,0,5,0,0,0,5,0,0,0,0,17,21
21,17,0,0,0,0,0,0,0,0,0,0,0,0,0,17,21
21,17,0,0,0,17,0,0,0,0,0,17,0,0,0,0,21
21,17,17,0,0,0,0,0,0,0,0,17,0,0,0,0,21
21,0,0,0,17,17,5,0,0,0,5,0,17,0,0,17,21
1,21,17,17,0,0,0,0,17,17,17,17,0,17,17,21,1
1,21,17,0,0,17,0,0,0,0,17,17,0,0,0,21,1
1,1,21,17,0,0,17,0,0,0,0,17,0,0,21,1,1
1,1,1,21,0,17,0,0,17,0,0,17,17,21,1,1,1
1,1,1,1,21,21,17,0,0,0,17,21,21,1,1,1,1
1,1,1,1,1,1,21,21,21,21,21,1,1,1,1,1,1
endlayer

layer
1,1,1,1,1,1,21,21,21,21,21,1,1,1,1,1,1
1,1,1,1,21,21,0,0,0,0,0,21,21,1,1,1,1
1,1,1,21,0,0,0,0,0,0,0,0,0,21,1,1,1
1,1,21,0,0,0,0,0,0,0,0,0,0,0,21,1,1
1,21,0,0,0,0,0,0,0,0,0,0,0,0,0,21,1
1,21,0,0,0,0,0,0,0,0,0,0,0,0,0,21,1
21,0,0,0,0,0,5,0,0,0,5,0,0,0,0,0,21
21,0,0,0,0,0,0,0,0,0,0,0,0,0,0,0,21
21,0,0,0,0,0,0,0,0,0,0,0,0,0,0,0,21
21,0,0,0,0,0,0,0,0,0,0,0,0,0,0,0,21
21,0,0,0,0,0,5,0,0,0,5,0,0,0,0,0,21
1,21,0,0,0,0,0,0,0,0,0,0,0,0,0,21,1
1,21,0,0,0,0,0,0,0,0,0,0,0,0,0,21,1
1,1,21,0,0,0,0,0,0,0,0,0,0,0,21,1,1
1,1,1,21,0,0,0,0,0,0,0,0,0,21,1,1,1
1,1,1,1,21,21,0,0,0,0,0,21,21,1,1,1,1
1,1,1,1,1,1,21,21,21,21,21,1,1,1,1,1,1
endlayer

layer
1,1,1,1,1,1,1,21,21,21,1,1,1,1,1,1,1
1,1,1,1,21,21,21,0,0,0,21,21,21,1,1,1,1
1,1,1,21,0,0,0,0,0,0,0,0,0,21,1,1,1
1,1,21,0,0,0,0,0,0,0,0,0,0,0,21,1,1
1,21,0,0,0,0,0,0,0,0,0,0,0,0,0,21,1
1,21,0,0,0,22,22,22,22,22,22,22,0,0,0,21,1
1,21,0,0,0,22,23,23,23,23,23,22,0,0,0,21,1
21,0,0,0,0,22,23,24,24,24,23,22,0,0,0,0,21
21,0,0,0,0,22,23,24,0,24,23,22,0,0,0,0,21
21,0,0,0,0,22,23,24,24,24,23,22,0,0,0,0,21
1,21,0,0,0,22,23,23,23,23,23,22,0,0,0,21,1
1,21,0,0,0,22,22,22,22,22,22,22,0,0,0,21,1
1,21,0,0,0,0,0,0,0,0,0,0,0,0,0,21,1
1,1,21,0,0,0,0,0,0,0,0,0,0,0,21,1,1
1,1,1,21,0,0,0,0,0,0,0,0,0,21,1,1,1
1,1,1,1,21,21,21,0,0,0,21,21,21,1,1,1,1
1,1,1,1,1,1,1,21,21,21,1,1,1,1,1,1,1
endlayer

layer
1,1,1,1,1,1,1,1,1,1,1,1,1,1,1,1,1
1,1,1,1,1,21,21,21,21,21,21,21,1,1,1,1,1
1,1,1,21,21,0,0,0,0,0,0,0,21,21,1,1,1
1,1,21,0,0,0,0,0,0,0,0,0,0,0,21,1,1
1,1,21,0,0,0,0,0,0,0,0,0,0,0,21,1,1
1,21,0,0,0,0,0,0,0,0,0,0,0,0,0,21,1
1,21,0,0,0,0,0,0,0,0,0,0,0,0,0,21,1
1,21,0,0,0,0,0,22,22,22,0,0,0,0,0,21,1
1,21,0,0,0,0,0,22,23,22,0,0,0,0,0,21,1
1,21,0,0,0,0,0,22,22,22,0,0,0,0,0,21,1
1,21,0,0,0,0,0,0,0,0,0,0,0,0,0,21,1
1,21,0,0,0,0,0,0,0,0,0,0,0,0,0,21,1
1,1,21,0,0,0,0,0,0,0,0,0,0,0,21,1,1
1,1,21,0,0,0,0,0,0,0,0,0,0,0,21,1,1
1,1,1,21,21,0,0,0,0,0,0,0,21,21,1,1,1
1,1,1,1,1,21,21,21,21,21,21,21,1,1,1,1,1
1,1,1,1,1,1,1,1,1,1,1,1,1,1,1,1,1
endlayer

layer
1,1,1,1,1,1,1,1,1,1,1,1,1,1,1,1,1
1,1,1,1,1,1,21,21,21,21,21,1,1,1,1,1,1
1,1,1,1,21,21,0,0,0,0,0,21,21,1,1,1,1
1,1,1,21,0,0,0,0,0,0,0,0,0,21,1,1,1
1,1,21,0,0,0,0,0,0,0,0,0,0,0,21,1,1
1,1,21,0,0,0,0,0,0,0,0,0,0,0,21,1,1
1,21,0,0,0,0,0,0,0,0,0,0,0,0,0,21,1
1,21,0,0,0,0,0,0,0,0,0,0,0,0,0,21,1
1,21,0,0,0,0,0,0,0,0,0,0,0,0,0,21,1
1,21,0,0,0,0,0,0,0,0,0,0,0,0,0,21,1
1,21,0,0,0,0,0,0,0,0,0,0,0,0,0,21,1
1,1,21,0,0,0,0,0,0,0,0,0,0,0,21,1,1
1,1,21,0,0,0,0,0,0,0,0,0,0,0,21,1,1
1,1,1,21,0,0,0,0,0,0,0,0,0,21,1,1,1
1,1,1,1,21,21,0,0,0,0,0,21,21,1,1,1,1
1,1,1,1,1,1,21,21,21,21,21,1,1,1,1,1,1
1,1,1,1,1,1,1,1,1,1,1,1,1,1,1,1,1
endlayer

layer
1,1,1,1,1,1,1,1,1,1,1,1,1,1,1,1,1
1,1,1,1,1,1,1,1,1,1,1,1,1,1,1,1,1
1,1,1,1,1,21,21,21,21,21,21,21,1,1,1,1,1
1,1,1,1,21,0,0,0,0,0,0,0,21,1,1,1,1
1,1,1,21,0,0,0,0,0,0,0,0,0,21,1,1,1
1,1,21,0,0,0,0,0,0,0,0,0,0,0,21,1,1
1,1,21,0,0,0,0,0,0,0,0,0,0,0,21,1,1
1,1,21,0,0,0,0,0,0,0,0,0,0,0,21,1,1
1,1,21,0,0,0,0,0,0,0,0,0,0,0,21,1,1
1,1,21,0,0,0,0,0,0,0,0,0,0,0,21,1,1
1,1,21,0,0,0,0,0,0,0,0,0,0,0,21,1,1
1,1,21,0,0,0,0,0,0,0,0,0,0,0,21,1,1
1,1,1,21,0,0,0,0,0,0,0,0,0,21,1,1,1
1,1,1,1,21,0,0,0,0,0,0,0,21,1,1,1,1
1,1,1,1,1,21,21,21,21,21,21,21,1,1,1,1,1
1,1,1,1,1,1,1,1,1,1,1,1,1,1,1,1,1
1,1,1,1,1,1,1,1,1,1,1,1,1,1,1,1,1
endlayer

layer
1,1,1,1,1,1,1,1,1,1,1,1,1,1,1,1,1
1,1,1,1,1,1,1,1,1,1,1,1,1,1,1,1,1
1,1,1,1,1,1,1,1,1,1,1,1,1,1,1,1,1
1,1,1,1,1,21,21,21,21,21,21,21,1,1,1,1,1
1,1,1,1,21,21,0,0,0,0,0,21,21,1,1,1,1
1,1,1,21,21,0,0,0,0,0,0,0,21,21,1,1,1
1,1,1,21,0,0,0,0,0,0,0,0,0,21,1,1,1
1,1,1,21,0,0,0,0,0,0,0,0,0,21,1,1,1
1,1,1,21,0,0,0,0,0,0,0,0,0,21,1,1,1
1,1,1,21,0,0,0,0,0,0,0,0,0,21,1,1,1
1,1,1,21,0,0,0,0,0,0,0,0,0,21,1,1,1
1,1,1,21,21,0,0,0,0,0,0,0,21,21,1,1,1
1,1,1,1,21,21,0,0,0,0,0,21,21,1,1,1,1
1,1,1,1,1,21,21,21,21,21,21,21,1,1,1,1,1
1,1,1,1,1,1,1,1,1,1,1,1,1,1,1,1,1
1,1,1,1,1,1,1,1,1,1,1,1,1,1,1,1,1
1,1,1,1,1,1,1,1,1,1,1,1,1,1,1,1,1
endlayer

layer
1,1,1,1,1,1,1,1,1,1,1,1,1,1,1,1,1
1,1,1,1,1,1,1,1,1,1,1,1,1,1,1,1,1
1,1,1,1,1,1,1,1,1,1,1,1,1,1,1,1,1
1,1,1,1,1,1,1,1,1,1,1,1,1,1,1,1,1
1,1,1,1,1,1,21,21,21,21,21,1,1,1,1,1,1
1,1,1,1,1,21,21,21,21,21,21,21,1,1,1,1,1
1,1,1,1,21,21,21,0,0,0,21,21,21,1,1,1,1
1,1,1,1,21,21,0,0,0,0,0,21,21,1,1,1,1
1,1,1,1,21,21,0,0,0,0,0,21,21,1,1,1,1
1,1,1,1,21,21,0,0,0,0,0,21,21,1,1,1,1
1,1,1,1,21,21,21,0,0,0,21,21,21,1,1,1,1
1,1,1,1,1,21,21,21,21,21,21,21,1,1,1,1,1
1,1,1,1,1,1,21,21,21,21,21,1,1,1,1,1,1
1,1,1,1,1,1,1,1,1,1,1,1,1,1,1,1,1
1,1,1,1,1,1,1,1,1,1,1,1,1,1,1,1,1
1,1,1,1,1,1,1,1,1,1,1,1,1,1,1,1,1
1,1,1,1,1,1,1,1,1,1,1,1,1,1,1,1,1
endlayer

layer
1,1,1,1,1,1,1,1,1,1,1,1,1,1,1,1,1
1,1,1,1,1,1,1,1,1,1,1,1,1,1,1,1,1
1,1,1,1,1,1,1,1,1,1,1,1,1,1,1,1,1
1,1,1,1,1,1,1,1,1,1,1,1,1,1,1,1,1
1,1,1,1,1,1,1,1,1,1,1,1,1,1,1,1,1
1,1,1,1,1,1,1,1,1,1,1,1,1,1,1,1,1
1,1,1,1,1,1,1,21,21,21,1,1,1,1,1,1,1
1,1,1,1,1,1,21,21,21,21,21,1,1,1,1,1,1
1,1,1,1,1,1,21,21,21,21,21,1,1,1,1,1,1
1,1,1,1,1,1,21,21,21,21,21,1,1,1,1,1,1
1,1,1,1,1,1,1,21,21,21,1,1,1,1,1,1,1
1,1,1,1,1,1,1,1,1,1,1,1,1,1,1,1,1
1,1,1,1,1,1,1,1,1,1,1,1,1,1,1,1,1
1,1,1,1,1,1,1,1,1,1,1,1,1,1,1,1,1
1,1,1,1,1,1,1,1,1,1,1,1,1,1,1,1,1
1,1,1,1,1,1,1,1,1,1,1,1,1,1,1,1,1
1,1,1,1,1,1,1,1,1,1,1,1,1,1,1,1,1
endlayer

