
# Created by Ruins mod version 16.7 Ingame Parser
# authoring Player: ST753M

weight=2
uniqueMinDistance=2000
embed_into_distance=6
acceptable_target_blocks=gravel,sand
unacceptable_target_blocks=flowing_water,water,flowing_lava,lava
dimensions=16,17,17
allowable_overhang=6
max_leveling=0
leveling_buffer=0
preserve_water=1
preserve_lava=0

biomesToSpawnIn=deep_ocean

=0,100,air
rule1=0,100,preserveBlock
rule2=0,100,minecraft:stone-0
rule3=0,100,minecraft:end_stone-0
rule4=0,100,biomesoplenty:grass-0
rule5=0,100,biomesoplenty:plant_1-1
rule6=0,100,biomesoplenty:biome_block-0
rule7=0,100,biomesoplenty:flower_0-10
rule8=0,100,IInventory;minecraft:chest;biomesoplenty:terrarium#1#15#4+minecraft:experience_bottle#4#0#8+minecraft:golden_apple#1#1#11+minecraft:chorus_fruit_popped#3#0#15+minecraft:experience_bottle#3#0#18+minecraft:clock#1#0#25-3
rule9=0,100,biomesoplenty:gem_ore-0
rule10=0,100,biomesoplenty:leaves_2-7
rule11=0,100,biomesoplenty:log_3-7
rule12=0,100,biomesoplenty:leaves_2-15
rule13=0,100,minecraft:stained_glass-14
^0,100,minecraft:stained_glass-0
^0,100,minecraft:stained_glass-9
^0,100,minecraft:stained_glass-3
^0,100,minecraft:stained_glass-11
^0,100,minecraft:stained_glass-8
^0,100,minecraft:stained_glass-7

layer
1,1,1,1,1,1,2,2,2,2,2,1,1,1,1,1,1
1,1,1,1,2,2,2,2,2,2,2,2,2,1,1,1,1
1,1,1,2,2,2,3,4,3,3,3,2,2,2,1,1,1
1,1,2,2,3,3,4,4,3,3,3,3,3,2,2,1,1
1,2,2,3,3,3,4,4,4,3,3,3,3,3,2,2,1
1,2,2,3,3,4,4,4,4,3,3,3,3,3,2,2,1
2,2,3,3,3,4,4,4,4,3,3,3,3,3,3,2,2
2,2,3,3,3,4,4,4,4,4,3,3,3,3,3,2,2
2,2,3,3,4,4,4,4,4,4,4,4,3,3,3,2,2
2,2,3,3,4,4,3,4,4,4,4,4,4,3,3,2,2
2,2,3,3,4,4,3,3,3,4,4,4,4,3,3,2,2
1,2,2,3,4,3,3,3,4,4,4,3,3,3,2,2,1
1,2,2,3,4,4,4,4,4,4,3,3,3,3,2,2,1
1,1,2,2,3,3,4,4,4,4,3,3,3,2,2,1,1
1,1,1,2,2,2,3,3,4,4,4,2,2,2,1,1,1
1,1,1,1,2,2,2,2,2,2,2,2,2,1,1,1,1
1,1,1,1,1,1,2,2,2,2,2,1,1,1,1,1,1
endlayer

layer
1,1,1,1,1,1,2,2,2,2,2,1,1,1,1,1,1
1,1,1,1,2,2,3,3,3,3,3,2,2,1,1,1,1
1,1,1,2,3,3,4,5,4,4,3,3,3,2,1,1,1
1,1,2,3,4,4,5,5,4,6,3,3,3,3,2,1,1
1,2,3,4,4,4,5,5,5,4,3,4,3,3,3,2,1
1,2,3,4,4,5,5,0,5,4,4,4,4,3,3,2,1
2,3,3,4,4,5,0,5,5,4,4,4,4,4,4,3,2
2,3,4,4,4,5,5,5,5,0,4,4,4,4,4,3,2
2,3,4,4,7,5,5,5,5,7,0,7,4,4,4,3,2
2,3,4,4,5,5,4,0,5,0,5,5,7,4,3,3,2
2,3,4,4,5,5,3,4,4,5,0,0,5,4,3,3,2
1,2,3,4,5,4,3,4,0,5,5,4,4,4,3,2,1
1,2,3,3,5,0,0,0,5,0,4,4,4,4,3,2,1
1,1,2,3,4,4,5,5,5,0,4,4,3,3,2,1,1
1,1,1,2,3,3,4,4,5,5,5,3,3,2,1,1,1
1,1,1,1,2,2,3,3,3,3,3,2,2,1,1,1,1
1,1,1,1,1,1,2,2,2,2,2,1,1,1,1,1,1
endlayer

layer
1,1,1,1,1,1,2,2,2,2,2,1,1,1,1,1,1
1,1,1,1,2,2,3,3,3,3,3,2,2,1,1,1,1
1,1,1,2,3,3,5,0,5,8,3,3,3,2,1,1,1
1,1,2,3,7,0,0,0,5,3,3,4,3,3,2,1,1
1,2,3,5,5,5,0,0,0,5,3,0,3,3,3,2,1
1,2,3,7,5,0,0,0,0,5,5,5,5,4,3,2,1
2,3,4,5,5,0,0,0,0,5,5,0,0,5,5,3,2
2,3,5,5,5,0,0,0,0,0,5,5,5,5,5,3,2
2,3,5,7,0,0,0,0,0,0,0,0,5,5,0,3,2
2,3,5,5,0,0,5,0,0,0,0,0,0,5,4,3,2
2,3,5,5,0,0,4,5,5,0,0,0,0,5,4,3,2
1,2,3,5,0,5,3,5,0,0,0,5,0,5,3,2,1
1,2,3,3,0,0,0,0,0,0,5,0,5,7,3,2,1
1,1,2,3,5,5,0,0,0,0,5,5,4,3,2,1,1
1,1,1,2,3,3,7,5,0,0,0,3,3,2,1,1,1
1,1,1,1,2,2,3,9,3,3,3,2,2,1,1,1,1
1,1,1,1,1,1,2,2,2,2,2,1,1,1,1,1,1
endlayer

layer
1,1,1,1,1,1,2,2,2,2,2,1,1,1,1,1,1
1,1,1,1,2,2,3,3,3,3,3,2,2,1,1,1,1
1,1,1,2,3,3,0,3,0,0,3,3,3,2,1,1,1
1,1,2,3,0,0,0,0,0,3,4,5,3,3,2,1,1
1,2,6,0,0,0,0,0,0,0,3,0,3,3,3,2,1
1,2,4,0,0,0,0,0,0,0,0,0,0,5,3,2,1
2,3,5,0,0,0,0,0,0,0,0,0,0,0,3,3,2
2,3,0,0,0,0,0,0,0,0,0,0,0,0,3,3,2
2,3,0,0,0,0,0,0,0,0,0,0,0,0,0,6,2
2,3,0,0,0,0,0,0,0,0,0,0,0,0,5,3,2
2,3,3,0,0,0,5,0,0,0,0,0,0,0,5,3,2
1,2,3,0,0,0,3,0,0,0,0,0,0,0,3,2,1
1,2,3,3,0,0,0,0,0,0,0,0,0,0,3,2,1
1,1,2,3,3,0,0,0,0,0,0,0,5,3,2,1,1
1,1,1,2,3,3,3,0,0,3,3,6,3,2,1,1,1
1,1,1,1,2,2,3,3,3,3,3,2,2,1,1,1,1
1,1,1,1,1,1,2,2,2,2,2,1,1,1,1,1,1
endlayer

layer
1,1,1,1,1,1,2,2,2,2,2,1,1,1,1,1,1
1,1,1,1,2,2,2,2,2,2,2,2,2,1,1,1,1
1,1,1,2,2,2,3,3,3,3,3,3,2,2,1,1,1
1,1,2,2,3,3,3,3,3,4,5,0,3,2,2,1,1
1,2,3,3,3,3,0,0,3,3,3,0,3,3,2,2,1
1,2,0,0,3,3,0,0,0,3,3,0,0,3,2,2,1
2,2,3,3,0,0,0,0,0,0,0,0,0,3,3,2,2
2,2,9,3,0,0,0,0,0,0,0,0,0,0,3,2,2
2,2,3,3,3,0,0,0,0,0,0,0,0,0,3,2,2
2,2,3,0,0,0,0,0,0,0,0,0,0,3,3,2,2
2,2,3,3,0,0,0,0,0,0,0,0,0,3,3,2,2
1,2,2,3,3,3,6,0,0,0,0,3,3,3,2,2,1
1,2,2,3,3,3,3,3,0,0,0,3,3,3,2,2,1
1,1,2,2,3,3,3,3,3,3,3,3,3,2,2,1,1
1,1,1,2,2,2,3,3,3,3,3,2,2,2,1,1,1
1,1,1,1,2,2,2,2,2,2,2,2,2,1,1,1,1
1,1,1,1,1,1,2,2,2,2,2,1,1,1,1,1,1
endlayer

layer
1,1,1,1,1,1,2,2,2,2,2,1,1,1,1,1,1
1,1,1,1,2,2,4,4,4,3,4,2,2,1,1,1,1
1,1,1,2,4,4,4,4,4,4,4,4,4,2,1,1,1
1,1,2,4,4,4,4,4,4,5,0,0,4,4,2,1,1
1,2,4,4,4,4,4,4,4,4,4,0,4,4,4,2,1
1,2,4,3,4,4,4,4,4,4,4,3,4,4,4,2,1
2,4,4,4,4,4,4,4,4,4,4,4,4,4,4,4,2
2,4,4,4,4,4,4,4,4,4,4,4,4,4,4,4,2
2,4,4,4,4,4,4,4,6,4,4,4,4,4,4,4,2
2,4,4,4,4,4,4,4,4,4,4,4,4,4,4,4,2
2,4,4,4,4,4,4,4,4,4,4,4,4,4,4,4,2
1,2,4,4,4,4,4,4,4,4,4,4,4,4,3,2,1
1,2,4,4,4,3,4,4,4,4,4,4,4,4,4,2,1
1,1,2,4,4,4,4,4,4,4,4,4,4,4,2,1,1
1,1,1,2,4,4,4,4,4,4,4,4,4,2,1,1,1
1,1,1,1,2,2,4,4,4,4,4,2,2,1,1,1,1
1,1,1,1,1,1,2,2,2,2,2,1,1,1,1,1,1
endlayer

layer
1,1,1,1,1,1,2,2,2,2,2,1,1,1,1,1,1
1,1,1,1,2,2,5,0,10,11,10,2,2,1,1,1,1
1,1,1,2,7,5,0,5,10,10,10,0,5,2,1,1,1
1,1,2,5,5,5,5,0,5,0,0,0,5,0,2,1,1
1,2,10,10,10,0,7,0,5,0,10,10,10,5,0,2,1
1,2,10,11,10,5,5,0,5,0,12,11,12,0,7,2,1
2,0,10,10,10,0,7,5,7,0,12,12,12,5,0,5,2
2,5,0,5,0,7,0,0,0,5,5,5,0,0,7,0,2
2,5,0,0,5,0,0,5,11,5,5,0,7,0,5,5,2
2,0,5,0,0,5,5,5,0,5,5,5,0,5,5,5,2
2,5,0,5,0,5,0,7,5,0,0,7,5,10,10,10,2
1,2,5,0,10,10,10,0,0,5,5,5,5,10,11,2,1
1,2,0,0,10,11,10,0,7,5,5,5,5,10,10,2,1
1,1,2,0,10,10,10,7,5,0,5,5,0,5,2,1,1
1,1,1,2,5,5,0,5,5,5,7,0,5,2,1,1,1
1,1,1,1,2,2,5,5,5,7,5,2,2,1,1,1,1
1,1,1,1,1,1,2,2,2,2,2,1,1,1,1,1,1
endlayer

layer
1,1,1,1,1,1,13,13,13,13,13,1,1,1,1,1,1
1,1,1,1,13,13,0,0,10,10,10,13,13,1,1,1,1
1,1,1,13,0,0,0,0,0,10,0,0,0,13,1,1,1
1,1,13,0,0,0,0,0,0,0,0,0,0,0,13,1,1
1,13,0,10,0,0,0,0,0,0,0,10,0,0,0,13,1
1,13,10,10,10,0,0,0,0,0,12,12,12,0,0,13,1
13,0,0,10,0,0,0,0,0,0,0,10,0,0,0,0,13
13,0,0,0,0,0,0,0,0,0,0,0,0,0,0,0,13
13,0,0,0,0,0,0,0,11,0,0,0,0,0,0,0,13
13,0,0,0,0,0,0,0,0,0,0,0,0,0,0,0,13
13,0,0,0,0,0,0,0,0,0,0,0,0,0,10,0,13
1,13,0,0,0,10,0,0,0,0,0,0,0,10,10,13,1
1,13,0,0,10,10,10,0,0,0,0,0,0,0,10,13,1
1,1,13,0,0,10,0,0,0,0,0,0,0,0,13,1,1
1,1,1,13,0,0,0,0,0,0,0,0,0,13,1,1,1
1,1,1,1,13,13,0,0,0,0,0,13,13,1,1,1,1
1,1,1,1,1,1,13,13,13,13,13,1,1,1,1,1,1
endlayer

layer
1,1,1,1,1,1,13,13,13,13,13,1,1,1,1,1,1
1,1,1,1,13,13,0,0,0,0,0,13,13,1,1,1,1
1,1,1,13,0,0,0,0,0,0,0,0,0,13,1,1,1
1,1,13,0,0,0,0,0,0,0,0,0,0,0,13,1,1
1,13,0,0,0,0,0,0,0,0,0,0,0,0,0,13,1
1,13,0,0,0,0,0,0,0,0,0,0,0,0,0,13,1
13,0,0,0,0,0,0,0,0,0,0,0,0,0,0,0,13
13,0,0,0,0,0,0,0,0,0,0,0,0,0,0,0,13
13,0,0,0,0,0,0,0,11,0,0,0,0,0,0,0,13
13,0,0,0,0,0,0,0,0,0,0,0,0,0,0,0,13
13,0,0,0,0,0,0,0,0,0,0,0,0,0,0,0,13
1,13,0,0,0,0,0,0,0,0,0,0,0,0,0,13,1
1,13,0,0,0,0,0,0,0,0,0,0,0,0,0,13,1
1,1,13,0,0,0,0,0,0,0,0,0,0,0,13,1,1
1,1,1,13,0,0,0,0,0,0,0,0,0,13,1,1,1
1,1,1,1,13,13,0,0,0,0,0,13,13,1,1,1,1
1,1,1,1,1,1,13,13,13,13,13,1,1,1,1,1,1
endlayer

layer
1,1,1,1,1,1,1,13,13,13,1,1,1,1,1,1,1
1,1,1,1,13,13,13,0,0,0,13,13,13,1,1,1,1
1,1,1,13,0,0,0,0,0,0,0,0,0,13,1,1,1
1,1,13,0,0,0,0,0,0,0,0,0,0,0,13,1,1
1,13,0,0,0,0,0,0,0,0,0,0,0,0,0,13,1
1,13,0,0,0,0,0,0,0,0,0,0,0,0,0,13,1
1,13,0,0,0,0,0,0,0,0,0,0,0,0,0,13,1
13,0,0,0,0,0,0,0,10,0,0,0,0,0,0,0,13
13,0,0,0,0,0,0,12,11,10,0,0,0,0,0,0,13
13,0,0,0,0,0,0,0,12,0,0,0,0,0,0,0,13
1,13,0,0,0,0,0,0,0,0,0,0,0,0,0,13,1
1,13,0,0,0,0,0,0,0,0,0,0,0,0,0,13,1
1,13,0,0,0,0,0,0,0,0,0,0,0,0,0,13,1
1,1,13,0,0,0,0,0,0,0,0,0,0,0,13,1,1
1,1,1,13,0,0,0,0,0,0,0,0,0,13,1,1,1
1,1,1,1,13,13,13,0,0,0,13,13,13,1,1,1,1
1,1,1,1,1,1,1,13,13,13,1,1,1,1,1,1,1
endlayer

layer
1,1,1,1,1,1,1,1,1,1,1,1,1,1,1,1,1
1,1,1,1,1,13,13,13,13,13,13,13,1,1,1,1,1
1,1,1,13,13,0,0,0,0,0,0,0,13,13,1,1,1
1,1,13,0,0,0,0,0,0,0,0,0,0,0,13,1,1
1,1,13,0,0,0,0,0,0,0,0,0,0,0,13,1,1
1,13,0,0,0,0,0,0,0,0,0,0,0,0,0,13,1
1,13,0,0,0,0,0,0,10,0,0,0,0,0,0,13,1
1,13,0,0,0,0,0,10,10,10,0,0,0,0,0,13,1
1,13,0,0,0,0,12,12,11,10,10,0,0,0,0,13,1
1,13,0,0,0,0,0,12,12,12,0,0,0,0,0,13,1
1,13,0,0,0,0,0,0,12,0,0,0,0,0,0,13,1
1,13,0,0,0,0,0,0,0,0,0,0,0,0,0,13,1
1,1,13,0,0,0,0,0,0,0,0,0,0,0,13,1,1
1,1,13,0,0,0,0,0,0,0,0,0,0,0,13,1,1
1,1,1,13,13,0,0,0,0,0,0,0,13,13,1,1,1
1,1,1,1,1,13,13,13,13,13,13,13,1,1,1,1,1
1,1,1,1,1,1,1,1,1,1,1,1,1,1,1,1,1
endlayer

layer
1,1,1,1,1,1,1,1,1,1,1,1,1,1,1,1,1
1,1,1,1,1,1,13,13,13,13,13,1,1,1,1,1,1
1,1,1,1,13,13,0,0,0,0,0,13,13,1,1,1,1
1,1,1,13,0,0,0,0,0,0,0,0,0,13,1,1,1
1,1,13,0,0,0,0,0,0,0,0,0,0,0,13,1,1
1,1,13,0,0,0,0,0,0,0,0,0,0,0,13,1,1
1,13,0,0,0,0,0,10,10,10,0,0,0,0,0,13,1
1,13,0,0,0,0,10,10,10,10,10,0,0,0,0,13,1
1,13,0,0,0,0,12,12,11,10,10,0,0,0,0,13,1
1,13,0,0,0,0,12,12,12,12,10,0,0,0,0,13,1
1,13,0,0,0,0,0,12,12,10,0,0,0,0,0,13,1
1,1,13,0,0,0,0,0,0,0,0,0,0,0,13,1,1
1,1,13,0,0,0,0,0,0,0,0,0,0,0,13,1,1
1,1,1,13,0,0,0,0,0,0,0,0,0,13,1,1,1
1,1,1,1,13,13,0,0,0,0,0,13,13,1,1,1,1
1,1,1,1,1,1,13,13,13,13,13,1,1,1,1,1,1
1,1,1,1,1,1,1,1,1,1,1,1,1,1,1,1,1
endlayer

layer
1,1,1,1,1,1,1,1,1,1,1,1,1,1,1,1,1
1,1,1,1,1,1,1,1,1,1,1,1,1,1,1,1,1
1,1,1,1,1,13,13,13,13,13,13,13,1,1,1,1,1
1,1,1,1,13,0,0,0,0,0,0,0,13,1,1,1,1
1,1,1,13,0,0,0,0,0,0,0,0,0,13,1,1,1
1,1,13,0,0,0,0,0,0,0,0,0,0,0,13,1,1
1,1,13,0,0,0,0,0,10,0,0,0,0,0,13,1,1
1,1,13,0,0,0,0,10,12,12,0,0,0,0,13,1,1
1,1,13,0,0,0,10,10,11,12,10,0,0,0,13,1,1
1,1,13,0,0,0,0,10,12,12,0,0,0,0,13,1,1
1,1,13,0,0,0,0,0,10,0,0,0,0,0,13,1,1
1,1,13,0,0,0,0,0,0,0,0,0,0,0,13,1,1
1,1,1,13,0,0,0,0,0,0,0,0,0,13,1,1,1
1,1,1,1,13,0,0,0,0,0,0,0,13,1,1,1,1
1,1,1,1,1,13,13,13,13,13,13,13,1,1,1,1,1
1,1,1,1,1,1,1,1,1,1,1,1,1,1,1,1,1
1,1,1,1,1,1,1,1,1,1,1,1,1,1,1,1,1
endlayer

layer
1,1,1,1,1,1,1,1,1,1,1,1,1,1,1,1,1
1,1,1,1,1,1,1,1,1,1,1,1,1,1,1,1,1
1,1,1,1,1,1,1,1,1,1,1,1,1,1,1,1,1
1,1,1,1,1,13,13,13,13,13,13,13,1,1,1,1,1
1,1,1,1,13,13,0,0,0,0,0,13,13,1,1,1,1
1,1,1,13,13,0,0,0,0,0,0,0,13,13,1,1,1
1,1,1,13,0,0,0,0,0,0,0,0,0,13,1,1,1
1,1,1,13,0,0,0,0,12,0,0,0,0,13,1,1,1
1,1,1,13,0,0,0,12,12,12,0,0,0,13,1,1,1
1,1,1,13,0,0,0,0,12,0,0,0,0,13,1,1,1
1,1,1,13,0,0,0,0,0,0,0,0,0,13,1,1,1
1,1,1,13,13,0,0,0,0,0,0,0,13,13,1,1,1
1,1,1,1,13,13,0,0,0,0,0,13,13,1,1,1,1
1,1,1,1,1,13,13,13,13,13,13,13,1,1,1,1,1
1,1,1,1,1,1,1,1,1,1,1,1,1,1,1,1,1
1,1,1,1,1,1,1,1,1,1,1,1,1,1,1,1,1
1,1,1,1,1,1,1,1,1,1,1,1,1,1,1,1,1
endlayer

layer
1,1,1,1,1,1,1,1,1,1,1,1,1,1,1,1,1
1,1,1,1,1,1,1,1,1,1,1,1,1,1,1,1,1
1,1,1,1,1,1,1,1,1,1,1,1,1,1,1,1,1
1,1,1,1,1,1,1,1,1,1,1,1,1,1,1,1,1
1,1,1,1,1,1,13,13,13,13,13,1,1,1,1,1,1
1,1,1,1,1,13,13,13,13,13,13,13,1,1,1,1,1
1,1,1,1,13,13,13,0,0,0,13,13,13,1,1,1,1
1,1,1,1,13,13,0,0,0,0,0,13,13,1,1,1,1
1,1,1,1,13,13,0,0,10,0,0,13,13,1,1,1,1
1,1,1,1,13,13,0,0,0,0,0,13,13,1,1,1,1
1,1,1,1,13,13,13,0,0,0,13,13,13,1,1,1,1
1,1,1,1,1,13,13,13,13,13,13,13,1,1,1,1,1
1,1,1,1,1,1,13,13,13,13,13,1,1,1,1,1,1
1,1,1,1,1,1,1,1,1,1,1,1,1,1,1,1,1
1,1,1,1,1,1,1,1,1,1,1,1,1,1,1,1,1
1,1,1,1,1,1,1,1,1,1,1,1,1,1,1,1,1
1,1,1,1,1,1,1,1,1,1,1,1,1,1,1,1,1
endlayer

layer
1,1,1,1,1,1,1,1,1,1,1,1,1,1,1,1,1
1,1,1,1,1,1,1,1,1,1,1,1,1,1,1,1,1
1,1,1,1,1,1,1,1,1,1,1,1,1,1,1,1,1
1,1,1,1,1,1,1,1,1,1,1,1,1,1,1,1,1
1,1,1,1,1,1,1,1,1,1,1,1,1,1,1,1,1
1,1,1,1,1,1,1,1,1,1,1,1,1,1,1,1,1
1,1,1,1,1,1,1,13,13,13,1,1,1,1,1,1,1
1,1,1,1,1,1,13,13,13,13,13,1,1,1,1,1,1
1,1,1,1,1,1,13,13,13,13,13,1,1,1,1,1,1
1,1,1,1,1,1,13,13,13,13,13,1,1,1,1,1,1
1,1,1,1,1,1,1,13,13,13,1,1,1,1,1,1,1
1,1,1,1,1,1,1,1,1,1,1,1,1,1,1,1,1
1,1,1,1,1,1,1,1,1,1,1,1,1,1,1,1,1
1,1,1,1,1,1,1,1,1,1,1,1,1,1,1,1,1
1,1,1,1,1,1,1,1,1,1,1,1,1,1,1,1,1
1,1,1,1,1,1,1,1,1,1,1,1,1,1,1,1,1
1,1,1,1,1,1,1,1,1,1,1,1,1,1,1,1,1
endlayer

