
# Created by Ruins mod version 17.0 Ingame Parser
# authoring Player: ST753M

weight=1
embed_into_distance=7
acceptable_target_blocks=
unacceptable_target_blocks=flowing_water,water,flowing_lava,lava,ice,bedrock,netherrack,nether_brick,nether_brick_fence,soul_sand,quartz_ore,end_stone,obsidian,iron_bars,Natura:Cloud,slime_grass,slime_congealed,slime_dirt,clouds,natura:clouds
dimensions=22,21,21
allowable_overhang=7
max_leveling=0
leveling_buffer=0
preserve_water=1
preserve_lava=1

biomesToSpawnIn=deep_ocean

=0,100,air
rule1=0,100,preserveBlock
rule2=0,100,minecraft:sandstone-0
rule3=0,100,minecraft:wooden_slab-8
rule4=0,100,minecraft:crafting_table-0
rule5=0,100,minecraft:bed-0
rule6=0,100,minecraft:bed-8
rule7=0,100,minecraft:wooden_door-2
rule8=0,100,minecraft:ladder-5
rule9=0,100,minecraft:wooden_door-3
rule10=0,100,minecraft:wooden_door-1
rule11=0,100,minecraft:wooden_door-4
rule12=0,100,minecraft:wooden_door-8
rule13=0,100,minecraft:glowstone-0
rule14=0,100,minecraft:grass-0
rule15=0,100,minecraft:sand-0
rule16=0,100,minecraft:water-0
rule17=0,100,minecraft:dirt-0
rule18=2,100,minecraft:piston_head-10
rule19=0,100,minecraft:sticky_piston-10
rule20=0,100,minecraft:stained_glass-13
^0,100,minecraft:stained_glass-0
^0,100,minecraft:stained_glass-9
^0,100,minecraft:stained_glass-3
^0,100,minecraft:stained_glass-11
^0,100,minecraft:stained_glass-8
^0,100,minecraft:stained_glass-7
^0,100,minecraft:glass-0
rule21=0,100,minecraft:double_plant-4
rule22=0,100,minecraft:red_flower-0
rule23=0,100,minecraft:lever-10
rule24=0,100,minecraft:double_plant-10
rule25=0,100,minecraft:sandstone_stairs-0
rule26=0,100,minecraft:sandstone-1
rule27=0,100,minecraft:sandstone_stairs-2
rule28=0,100,minecraft:sandstone_stairs-3
rule29=0,100,minecraft:sandstone_stairs-1

layer
1,1,1,1,1,1,1,1,1,1,1,1,1,1,1,1,1,1,1,1,1
1,1,1,1,1,1,1,1,2,2,2,2,2,2,1,1,1,1,1,1,1
1,1,1,1,1,1,2,2,2,2,2,2,2,2,2,2,1,1,1,1,1
1,1,1,1,2,2,2,2,2,2,2,2,2,2,2,2,2,1,1,1,1
1,1,1,2,2,2,2,2,2,2,2,2,2,2,2,2,2,2,1,1,1
1,1,2,2,2,2,2,2,2,2,2,2,2,2,2,2,2,2,1,1,1
1,2,2,2,2,2,2,2,2,2,2,2,2,2,2,2,2,2,2,1,1
1,2,2,2,2,2,2,2,2,2,2,2,2,2,2,2,2,2,2,1,1
1,2,2,2,2,2,2,2,2,2,2,2,2,2,2,2,2,2,2,1,1
1,2,2,2,2,2,2,2,2,2,2,2,2,2,2,2,2,2,2,2,1
2,2,2,2,2,2,2,2,2,2,2,2,2,2,2,2,2,2,2,2,2
1,2,2,2,2,2,2,2,2,2,2,2,2,2,2,2,2,2,2,2,1
1,2,2,2,2,2,2,2,2,2,2,2,2,2,2,2,2,2,2,2,1
1,2,2,2,2,2,2,2,2,2,2,2,2,2,2,2,2,2,2,2,1
1,1,2,2,2,2,2,2,2,2,2,2,2,2,2,2,2,2,2,1,1
1,1,2,2,2,2,2,2,2,2,2,2,2,2,2,2,2,2,1,1,1
1,1,1,1,2,2,2,2,2,2,2,2,2,2,2,2,2,1,1,1,1
1,1,1,1,1,2,2,2,2,2,2,2,2,2,2,2,1,1,1,1,1
1,1,1,1,1,2,2,2,2,2,2,2,2,2,2,2,1,1,1,1,1
1,1,1,1,1,1,1,2,2,2,2,2,2,1,1,1,1,1,1,1,1
1,1,1,1,1,1,1,1,1,1,1,1,1,1,1,1,1,1,1,1,1
endlayer

layer
1,1,1,1,1,1,1,1,1,2,1,1,1,1,1,1,1,1,1,1,1
1,1,1,1,1,1,1,1,2,2,2,2,2,2,2,1,1,1,1,1,1
1,1,1,1,1,2,2,2,2,2,2,2,2,2,2,2,1,1,1,1,1
1,1,1,1,2,2,2,2,0,0,0,0,0,2,2,2,2,1,1,1,1
1,1,2,2,2,2,2,6,5,0,0,4,0,3,2,2,2,2,1,1,1
1,1,2,2,2,2,2,0,0,0,0,0,0,3,2,2,2,2,2,1,1
1,2,2,2,2,2,2,6,5,0,0,0,0,3,2,2,2,2,2,1,1
1,2,2,2,3,3,3,2,0,0,0,0,0,2,3,3,3,2,2,1,1
1,2,2,0,0,0,0,0,2,2,7,2,2,0,0,0,0,0,2,2,1
2,2,2,0,0,0,0,0,2,8,0,0,2,4,0,0,0,0,2,2,2
2,2,2,0,0,0,0,0,10,0,0,0,9,0,0,0,0,0,2,0,2
2,2,2,0,0,0,0,0,2,0,0,0,2,0,0,0,4,0,2,2,2
1,2,2,0,0,0,0,0,2,2,11,2,2,0,0,0,0,4,2,2,1
1,2,2,2,3,3,3,2,0,0,0,0,4,2,3,3,3,2,2,2,1
1,2,2,2,2,2,2,0,0,0,0,0,0,4,2,2,2,2,2,1,1
1,1,2,2,2,2,2,4,0,0,0,0,4,0,2,2,2,2,2,1,1
1,1,1,2,2,2,2,4,4,0,0,0,0,0,2,2,2,2,1,1,1
1,1,1,1,2,2,2,2,0,0,0,4,0,2,2,2,2,1,1,1,1
1,1,1,1,1,2,2,2,2,2,2,2,2,2,2,2,2,1,1,1,1
1,1,1,1,1,1,2,2,2,2,2,2,2,2,1,1,1,1,1,1,1
1,1,1,1,1,1,1,1,1,2,2,2,1,1,1,1,1,1,1,1,1
endlayer

layer
1,1,1,1,1,1,1,1,2,2,2,2,1,1,1,1,1,1,1,1,1
1,1,1,1,1,1,1,1,2,2,2,2,2,2,2,2,1,1,1,1,1
1,1,1,1,1,2,2,2,2,2,2,2,2,2,2,2,1,1,1,1,1
1,1,1,2,2,2,2,2,0,0,0,0,0,2,2,2,2,2,1,1,1
1,1,2,2,2,2,2,0,0,0,0,0,0,3,2,2,2,2,1,1,1
1,1,2,2,2,2,2,0,0,0,0,0,0,3,2,2,2,2,2,1,1
1,2,2,2,2,2,2,0,0,0,0,0,0,3,2,2,2,2,2,2,1
1,2,2,2,3,3,3,2,0,0,0,0,0,2,3,3,3,2,2,2,1
2,2,2,0,0,0,0,0,2,2,12,2,2,0,0,0,0,0,2,2,1
2,2,2,0,0,0,0,0,2,8,0,0,2,0,0,0,0,0,2,2,2
2,2,2,0,0,0,0,0,12,0,0,0,12,0,0,0,0,0,2,2,2
2,2,2,0,0,0,0,0,2,0,0,0,2,0,0,0,4,0,2,2,2
2,2,2,0,0,0,0,0,2,2,12,2,2,0,0,0,0,0,2,2,2
1,2,2,2,3,3,3,2,0,0,0,0,0,2,3,3,3,2,2,2,1
1,2,2,2,2,2,2,0,0,0,0,0,0,4,2,2,2,2,2,2,1
1,1,2,2,2,2,2,0,0,0,0,0,0,0,2,2,2,2,2,1,1
1,1,1,2,2,2,2,4,0,0,0,0,0,0,2,2,2,2,1,1,1
1,1,1,1,2,2,2,2,0,0,0,0,0,2,2,2,2,1,1,1,1
1,1,1,1,1,2,2,2,2,2,2,2,2,2,2,2,2,1,1,1,1
1,1,1,1,1,1,2,2,2,2,2,2,2,2,1,1,1,1,1,1,1
1,1,1,1,1,1,1,1,1,2,2,2,2,1,1,1,1,1,1,1,1
endlayer

layer
1,1,1,1,1,1,1,2,2,2,2,2,2,1,1,1,1,1,1,1,1
1,1,1,1,1,1,2,2,2,2,2,2,2,2,2,2,1,1,1,1,1
1,1,1,1,2,2,2,2,2,2,2,2,2,2,2,2,2,1,1,1,1
1,1,1,2,2,2,2,2,0,0,0,0,0,2,2,2,2,2,1,1,1
1,1,2,2,2,2,2,0,0,0,0,0,0,3,2,2,2,2,2,1,1
1,1,2,2,2,2,2,0,0,0,0,0,0,3,2,2,2,2,2,2,1
1,2,2,2,2,2,2,0,0,0,0,0,0,3,2,2,2,2,2,2,1
2,2,2,2,3,3,3,2,0,0,0,0,0,2,3,3,3,2,2,2,2
2,2,2,0,0,0,0,0,2,2,2,2,2,0,0,0,0,0,2,2,2
2,2,2,0,0,0,0,0,2,8,0,0,2,0,0,0,0,0,2,2,2
2,2,2,0,0,0,0,0,2,0,0,0,2,0,0,0,0,0,2,2,2
2,2,2,0,0,0,0,0,2,0,0,0,2,0,0,0,0,0,2,2,2
2,2,2,0,0,0,0,0,2,2,2,2,2,0,0,0,0,0,2,2,2
2,2,2,2,3,3,3,2,0,0,0,0,0,2,3,3,3,2,2,2,2
1,2,2,2,2,2,2,0,0,0,0,0,0,0,2,2,2,2,2,2,1
1,2,2,2,2,2,2,0,0,0,0,0,0,0,2,2,2,2,2,2,1
1,1,1,2,2,2,2,0,0,0,0,0,0,0,2,2,2,2,2,1,1
1,1,1,2,2,2,2,2,0,0,0,0,0,2,2,2,2,1,1,1,1
1,1,1,1,2,2,2,2,2,2,2,2,2,2,2,2,2,1,1,1,1
1,1,1,1,1,2,2,2,2,2,2,2,2,2,2,1,1,1,1,1,1
1,1,1,1,1,1,1,1,2,2,2,2,2,1,1,1,1,1,1,1,1
endlayer

layer
1,1,1,1,1,1,1,2,2,2,2,2,2,2,1,1,1,1,1,1,1
1,1,1,1,1,2,2,2,2,2,2,2,2,2,2,2,1,1,1,1,1
1,1,1,1,2,2,2,2,2,2,2,2,2,2,2,2,2,1,1,1,1
1,1,1,2,2,2,2,2,0,0,0,0,0,2,2,2,2,2,1,1,1
1,1,2,2,2,2,2,0,0,0,0,0,0,0,2,2,2,2,2,1,1
1,2,2,2,2,2,2,0,0,0,0,0,0,0,2,2,2,2,2,2,1
1,2,2,2,2,2,2,0,0,0,0,0,0,0,2,2,2,2,2,2,1
2,2,2,2,0,0,0,2,0,0,0,0,0,2,0,0,0,2,2,2,2
2,2,2,0,0,0,0,0,2,2,2,2,2,0,0,0,0,0,2,2,2
2,2,2,0,0,0,0,0,2,8,0,0,2,0,0,0,0,0,2,2,2
2,2,2,0,0,0,0,0,2,0,0,0,2,0,0,0,0,0,2,2,2
2,2,2,0,0,0,0,0,2,0,0,0,2,0,0,0,0,0,2,2,2
2,2,2,0,0,0,0,0,2,2,2,2,2,0,0,0,0,0,2,2,2
2,2,2,2,0,0,0,2,0,0,0,0,0,2,0,0,0,2,2,2,2
1,2,2,2,2,2,2,0,0,0,0,0,0,0,2,2,2,2,2,2,1
1,2,2,2,2,2,2,0,0,0,0,0,0,0,2,2,2,2,2,2,1
1,1,2,2,2,2,2,0,0,0,0,0,0,0,2,2,2,2,2,1,1
1,1,1,2,2,2,2,2,0,0,0,0,0,2,2,2,2,2,1,1,1
1,1,1,1,2,2,2,2,2,2,2,2,2,2,2,2,2,1,1,1,1
1,1,1,1,1,2,2,2,2,2,2,2,2,2,2,2,1,1,1,1,1
1,1,1,1,1,1,1,2,2,2,2,2,2,2,1,1,1,1,1,1,1
endlayer

layer
1,1,1,1,1,1,1,2,2,2,2,2,2,2,1,1,1,1,1,1,1
1,1,1,1,1,2,2,2,2,2,2,2,2,2,2,2,1,1,1,1,1
1,1,1,1,2,2,2,2,2,2,2,2,2,2,2,2,2,1,1,1,1
1,1,1,2,2,2,2,2,2,2,2,2,2,2,2,2,2,2,1,1,1
1,1,2,2,2,2,2,2,2,2,2,2,2,2,2,2,2,2,2,1,1
1,2,2,2,2,2,2,2,2,2,2,2,2,2,2,2,2,2,2,2,1
1,2,2,2,2,2,2,2,2,2,2,2,2,2,2,2,2,2,2,2,1
2,2,2,2,2,2,2,2,2,2,2,2,2,2,2,2,2,2,2,2,2
2,2,2,2,2,2,2,2,2,2,2,2,2,2,2,2,2,2,2,2,2
2,2,2,2,2,2,2,2,2,8,0,0,2,2,2,2,2,2,2,2,2
2,2,2,2,2,2,2,2,2,0,0,0,2,2,2,2,2,2,2,2,2
2,2,2,2,2,2,2,2,2,0,0,0,2,2,2,2,2,2,2,2,2
2,2,2,2,2,2,2,2,2,2,2,2,2,2,2,2,2,2,2,2,2
2,2,2,2,2,2,2,2,2,2,2,2,2,2,2,2,2,2,2,2,2
1,2,2,2,2,2,2,2,2,2,2,2,2,2,2,2,2,2,2,2,1
1,2,2,2,2,2,2,2,2,2,2,2,2,2,2,2,2,2,2,2,1
1,1,2,2,2,2,2,2,2,2,2,2,2,2,2,2,2,2,2,1,1
1,1,1,2,2,2,2,2,2,2,2,2,2,2,2,2,2,2,1,1,1
1,1,1,1,2,2,2,2,2,2,2,2,2,2,2,2,2,1,1,1,1
1,1,1,1,1,2,2,2,2,2,2,2,2,2,2,2,1,1,1,1,1
1,1,1,1,1,1,1,2,2,2,2,2,2,2,1,1,1,1,1,1,1
endlayer

layer
1,1,1,1,1,1,1,2,2,2,2,2,2,2,1,1,1,1,1,1,1
1,1,1,1,1,2,2,2,2,2,2,2,2,2,2,2,1,1,1,1,1
1,1,1,1,2,2,2,2,2,2,2,2,2,2,2,2,2,1,1,1,1
1,1,1,2,2,2,2,2,2,13,13,13,2,2,2,2,2,2,1,1,1
1,1,2,2,2,2,2,2,2,13,13,13,2,2,2,2,2,2,2,1,1
1,2,2,2,2,2,2,2,2,2,2,2,2,2,2,2,2,2,2,2,1
1,2,2,2,2,2,2,2,2,2,2,2,2,2,2,2,2,2,2,2,1
2,2,2,2,2,2,2,2,2,2,2,2,2,2,2,2,2,2,2,2,2
2,2,2,2,2,2,2,2,2,2,2,2,2,2,2,2,2,2,2,2,2
2,2,2,13,13,2,2,2,2,8,2,2,2,2,2,2,13,13,2,2,2
2,2,2,13,13,2,2,2,2,2,13,2,2,2,2,2,13,13,2,2,2
2,2,2,13,13,2,2,2,2,2,2,2,2,2,2,2,13,13,2,2,2
2,2,2,2,2,2,2,2,2,2,2,2,2,2,2,2,2,2,2,2,2
2,2,2,2,2,2,2,2,2,2,2,2,2,2,2,2,2,2,2,2,2
1,2,2,2,2,2,2,2,2,2,2,2,2,2,2,2,2,2,2,2,1
1,2,2,2,2,2,2,2,2,2,2,2,2,2,2,2,2,2,2,2,1
1,1,2,2,2,2,2,2,2,13,13,13,2,2,2,2,2,2,2,1,1
1,1,1,2,2,2,2,2,2,13,13,13,2,2,2,2,2,2,1,1,1
1,1,1,1,2,2,2,2,2,2,2,2,2,2,2,2,2,1,1,1,1
1,1,1,1,1,2,2,2,2,2,2,2,2,2,2,2,1,1,1,1,1
1,1,1,1,1,1,1,2,2,2,2,2,2,2,1,1,1,1,1,1,1
endlayer

layer
1,1,1,1,1,1,1,2,2,2,2,2,2,2,1,1,1,1,1,1,1
1,1,1,1,1,2,2,14,14,14,14,14,14,14,2,2,1,1,1,1,1
1,1,1,1,2,14,14,14,15,15,15,15,15,14,14,14,2,1,1,1,1
1,1,1,2,14,14,15,15,15,16,16,16,15,15,15,14,14,2,1,1,1
1,1,2,14,14,15,15,14,15,16,16,16,15,14,15,15,14,14,2,1,1
1,2,14,14,15,15,14,14,15,15,15,15,15,14,14,15,15,14,14,2,1
1,2,14,15,15,14,14,15,15,14,15,14,15,15,14,14,15,15,14,2,1
2,14,14,15,14,14,15,15,14,17,15,17,14,15,15,14,14,15,14,14,2
2,14,15,15,15,15,15,14,17,2,2,2,17,14,15,15,15,15,15,14,2
2,14,15,16,16,15,14,19,18,2,2,2,2,17,14,15,16,16,15,14,2
2,14,15,16,16,15,15,15,2,2,2,2,2,15,15,15,16,16,15,14,2
2,14,15,16,16,15,14,17,2,2,2,2,2,17,14,15,16,16,15,14,2
2,14,15,15,15,15,15,14,17,2,2,2,17,14,15,15,15,15,15,14,2
2,14,14,15,14,14,15,15,14,17,15,17,14,15,15,14,14,15,14,14,2
1,2,14,15,15,14,14,15,15,14,15,14,15,15,14,14,15,15,14,2,1
1,2,14,14,15,15,14,14,15,15,15,15,15,14,14,15,15,14,14,2,1
1,1,2,14,14,15,15,14,15,16,16,16,15,14,15,15,14,14,2,1,1
1,1,1,2,14,14,15,15,15,16,16,16,15,15,15,14,14,2,1,1,1
1,1,1,1,2,14,14,14,15,15,15,15,15,14,14,14,2,1,1,1,1
1,1,1,1,1,2,2,14,14,14,14,14,14,14,2,2,1,1,1,1,1
1,1,1,1,1,1,1,2,2,2,2,2,2,2,1,1,1,1,1,1,1
endlayer

layer
1,1,1,1,1,1,1,20,20,20,20,20,20,20,1,1,1,1,1,1,1
1,1,1,1,1,20,20,21,22,22,22,22,22,21,20,20,1,1,1,1,1
1,1,1,1,20,22,22,22,0,0,0,0,0,22,22,22,20,1,1,1,1
1,1,1,20,22,22,0,0,0,0,0,0,0,0,0,22,22,20,1,1,1
1,1,20,22,22,0,0,22,0,0,0,0,0,22,0,0,22,22,20,1,1
1,20,22,22,0,0,22,22,0,0,0,0,0,22,22,0,0,22,22,20,1
1,20,22,0,0,22,21,0,0,22,0,22,0,0,21,22,0,0,22,20,1
20,21,22,0,22,22,0,0,22,14,0,14,22,0,0,22,22,0,22,21,20
20,22,0,0,0,0,0,23,14,2,0,2,14,22,0,0,0,0,0,22,20
20,22,0,0,0,0,22,14,2,0,0,0,2,14,22,0,0,0,0,22,20
20,22,0,0,0,0,0,0,0,0,0,0,0,0,0,0,0,0,0,22,20
20,22,0,0,0,0,22,14,2,0,0,0,2,14,22,0,0,0,0,22,20
20,22,0,0,0,0,0,22,14,2,0,2,14,22,0,0,0,0,0,22,20
20,21,22,0,22,22,0,0,22,14,0,14,22,0,0,22,22,0,22,21,20
1,20,22,0,0,22,21,0,0,22,0,22,0,0,21,22,0,0,22,20,1
1,20,22,22,0,0,22,22,0,0,0,0,0,22,22,0,0,22,22,20,1
1,1,20,22,22,0,0,22,0,0,0,0,0,22,0,0,22,22,20,1,1
1,1,1,20,22,22,0,0,0,0,0,0,0,0,0,22,22,20,1,1,1
1,1,1,1,20,22,22,22,0,0,0,0,0,22,22,22,20,1,1,1,1
1,1,1,1,1,20,20,21,22,22,22,22,22,21,20,20,1,1,1,1,1
1,1,1,1,1,1,1,20,20,20,20,20,20,20,1,1,1,1,1,1,1
endlayer

layer
1,1,1,1,1,1,1,20,20,20,20,20,20,20,1,1,1,1,1,1,1
1,1,1,1,1,20,20,24,0,0,0,0,0,24,20,20,1,1,1,1,1
1,1,1,1,20,0,0,0,0,0,0,0,0,0,0,0,20,1,1,1,1
1,1,1,20,0,0,0,0,0,0,0,0,0,0,0,0,0,20,1,1,1
1,1,20,0,0,0,0,0,0,0,0,0,0,0,0,0,0,0,20,1,1
1,20,0,0,0,0,0,0,0,0,0,0,0,0,0,0,0,0,0,20,1
1,20,0,0,0,0,24,0,0,0,0,0,0,0,24,0,0,0,0,20,1
20,24,0,0,0,0,0,0,0,21,0,21,0,0,0,0,0,0,0,24,20
20,0,0,0,0,0,0,0,22,2,0,2,22,0,0,0,0,0,0,0,20
20,0,0,0,0,0,0,21,2,0,0,0,2,21,0,0,0,0,0,0,20
20,0,0,0,0,0,0,0,0,0,0,0,0,0,0,0,0,0,0,0,20
20,0,0,0,0,0,0,21,2,0,0,0,2,21,0,0,0,0,0,0,20
20,0,0,0,0,0,0,0,22,2,0,2,22,0,0,0,0,0,0,0,20
20,24,0,0,0,0,0,0,0,21,0,21,0,0,0,0,0,0,0,24,20
1,20,0,0,0,0,24,0,0,0,0,0,0,0,24,0,0,0,0,20,1
1,20,0,0,0,0,0,0,0,0,0,0,0,0,0,0,0,0,0,20,1
1,1,20,0,0,0,0,0,0,0,0,0,0,0,0,0,0,0,20,1,1
1,1,1,20,0,0,0,0,0,0,0,0,0,0,0,0,0,20,1,1,1
1,1,1,1,20,0,0,0,0,0,0,0,0,0,0,0,20,1,1,1,1
1,1,1,1,1,20,20,24,0,0,0,0,0,24,20,20,1,1,1,1,1
1,1,1,1,1,1,1,20,20,20,20,20,20,20,1,1,1,1,1,1,1
endlayer

layer
1,1,1,1,1,1,1,1,20,20,20,20,20,1,1,1,1,1,1,1,1
1,1,1,1,1,1,20,20,0,0,0,0,0,20,20,1,1,1,1,1,1
1,1,1,1,20,20,0,0,0,0,0,0,0,0,0,20,20,1,1,1,1
1,1,1,20,0,0,0,0,0,0,0,0,0,0,0,0,0,20,1,1,1
1,1,20,0,0,0,0,0,0,0,0,0,0,0,0,0,0,0,20,1,1
1,1,20,0,0,0,0,0,0,0,0,0,0,0,0,0,0,0,20,1,1
1,20,0,0,0,0,0,0,0,0,0,0,0,0,0,0,0,0,0,20,1
1,20,0,0,0,0,0,0,0,24,0,24,0,0,0,0,0,0,0,20,1
20,0,0,0,0,0,0,0,0,25,26,25,0,0,0,0,0,0,0,0,20
20,0,0,0,0,0,0,24,28,2,2,2,27,24,0,0,0,0,0,0,20
20,0,0,0,0,0,0,0,26,2,26,2,26,0,0,0,0,0,0,0,20
20,0,0,0,0,0,0,24,28,2,2,2,27,24,0,0,0,0,0,0,20
20,0,0,0,0,0,0,0,0,29,26,29,0,0,0,0,0,0,0,0,20
1,20,0,0,0,0,0,0,0,24,0,24,0,0,0,0,0,0,0,20,1
1,20,0,0,0,0,0,0,0,0,0,0,0,0,0,0,0,0,0,20,1
1,1,20,0,0,0,0,0,0,0,0,0,0,0,0,0,0,0,20,1,1
1,1,20,0,0,0,0,0,0,0,0,0,0,0,0,0,0,0,20,1,1
1,1,1,20,0,0,0,0,0,0,0,0,0,0,0,0,0,20,1,1,1
1,1,1,1,20,20,0,0,0,0,0,0,0,0,0,20,20,1,1,1,1
1,1,1,1,1,1,20,20,0,0,0,0,0,20,20,1,1,1,1,1,1
1,1,1,1,1,1,1,1,20,20,20,20,20,1,1,1,1,1,1,1,1
endlayer

layer
1,1,1,1,1,1,1,1,1,1,1,1,1,1,1,1,1,1,1,1,1
1,1,1,1,1,1,20,20,20,20,20,20,20,20,20,1,1,1,1,1,1
1,1,1,1,1,20,0,0,0,0,0,0,0,0,0,20,1,1,1,1,1
1,1,1,20,20,0,0,0,0,0,0,0,0,0,0,0,20,20,1,1,1
1,1,1,20,0,0,0,0,0,0,0,0,0,0,0,0,0,20,1,1,1
1,1,20,0,0,0,0,0,0,0,0,0,0,0,0,0,0,0,20,1,1
1,20,0,0,0,0,0,0,0,0,0,0,0,0,0,0,0,0,0,20,1
1,20,0,0,0,0,0,0,0,0,0,0,0,0,0,0,0,0,0,20,1
1,20,0,0,0,0,0,0,0,0,0,0,0,0,0,0,0,0,0,20,1
1,20,0,0,0,0,0,0,0,28,25,25,0,0,0,0,0,0,0,20,1
1,20,0,0,0,0,0,0,0,28,26,27,0,0,0,0,0,0,0,20,1
1,20,0,0,0,0,0,0,0,29,29,27,0,0,0,0,0,0,0,20,1
1,20,0,0,0,0,0,0,0,0,0,0,0,0,0,0,0,0,0,20,1
1,20,0,0,0,0,0,0,0,0,0,0,0,0,0,0,0,0,0,20,1
1,20,0,0,0,0,0,0,0,0,0,0,0,0,0,0,0,0,0,20,1
1,1,20,0,0,0,0,0,0,0,0,0,0,0,0,0,0,0,20,1,1
1,1,1,20,0,0,0,0,0,0,0,0,0,0,0,0,0,20,1,1,1
1,1,1,20,20,0,0,0,0,0,0,0,0,0,0,0,20,20,1,1,1
1,1,1,1,1,20,0,0,0,0,0,0,0,0,0,20,1,1,1,1,1
1,1,1,1,1,1,20,20,20,20,20,20,20,20,20,1,1,1,1,1,1
1,1,1,1,1,1,1,1,1,1,1,1,1,1,1,1,1,1,1,1,1
endlayer

layer
1,1,1,1,1,1,1,1,1,1,1,1,1,1,1,1,1,1,1,1,1
1,1,1,1,1,1,1,20,20,20,20,20,20,20,1,1,1,1,1,1,1
1,1,1,1,1,20,20,0,0,0,0,0,0,0,20,20,1,1,1,1,1
1,1,1,1,20,0,0,0,0,0,0,0,0,0,0,0,20,1,1,1,1
1,1,1,20,0,0,0,0,0,0,0,0,0,0,0,0,0,20,1,1,1
1,1,20,0,0,0,0,0,0,0,0,0,0,0,0,0,0,0,20,1,1
1,1,20,0,0,0,0,0,0,0,0,0,0,0,0,0,0,0,20,1,1
1,20,0,0,0,0,0,0,0,0,0,0,0,0,0,0,0,0,0,20,1
1,20,0,0,0,0,0,0,0,0,0,0,0,0,0,0,0,0,0,20,1
1,20,0,0,0,0,0,0,0,0,0,0,0,0,0,0,0,0,0,20,1
1,20,0,0,0,0,0,0,0,0,0,0,0,0,0,0,0,0,0,20,1
1,20,0,0,0,0,0,0,0,0,0,0,0,0,0,0,0,0,0,20,1
1,20,0,0,0,0,0,0,0,0,0,0,0,0,0,0,0,0,0,20,1
1,20,0,0,0,0,0,0,0,0,0,0,0,0,0,0,0,0,0,20,1
1,1,20,0,0,0,0,0,0,0,0,0,0,0,0,0,0,0,20,1,1
1,1,20,0,0,0,0,0,0,0,0,0,0,0,0,0,0,0,20,1,1
1,1,1,20,0,0,0,0,0,0,0,0,0,0,0,0,0,20,1,1,1
1,1,1,1,20,0,0,0,0,0,0,0,0,0,0,0,20,1,1,1,1
1,1,1,1,1,20,20,0,0,0,0,0,0,0,20,20,1,1,1,1,1
1,1,1,1,1,1,1,20,20,20,20,20,20,20,1,1,1,1,1,1,1
1,1,1,1,1,1,1,1,1,1,1,1,1,1,1,1,1,1,1,1,1
endlayer

layer
1,1,1,1,1,1,1,1,1,1,1,1,1,1,1,1,1,1,1,1,1
1,1,1,1,1,1,1,1,1,1,1,1,1,1,1,1,1,1,1,1,1
1,1,1,1,1,1,1,20,20,20,20,20,20,20,1,1,1,1,1,1,1
1,1,1,1,1,20,20,0,0,0,0,0,0,0,20,20,1,1,1,1,1
1,1,1,1,20,0,0,0,0,0,0,0,0,0,0,0,20,1,1,1,1
1,1,1,20,0,0,0,0,0,0,0,0,0,0,0,0,0,20,1,1,1
1,1,1,20,0,0,0,0,0,0,0,0,0,0,0,0,0,20,1,1,1
1,1,20,0,0,0,0,0,0,0,0,0,0,0,0,0,0,0,20,1,1
1,1,20,0,0,0,0,0,0,0,0,0,0,0,0,0,0,0,20,1,1
1,1,20,0,0,0,0,0,0,0,0,0,0,0,0,0,0,0,20,1,1
1,1,20,0,0,0,0,0,0,0,0,0,0,0,0,0,0,0,20,1,1
1,1,20,0,0,0,0,0,0,0,0,0,0,0,0,0,0,0,20,1,1
1,1,20,0,0,0,0,0,0,0,0,0,0,0,0,0,0,0,20,1,1
1,1,20,0,0,0,0,0,0,0,0,0,0,0,0,0,0,0,20,1,1
1,1,1,20,0,0,0,0,0,0,0,0,0,0,0,0,0,20,1,1,1
1,1,1,20,0,0,0,0,0,0,0,0,0,0,0,0,0,20,1,1,1
1,1,1,1,20,0,0,0,0,0,0,0,0,0,0,0,20,1,1,1,1
1,1,1,1,1,20,20,0,0,0,0,0,0,0,20,20,1,1,1,1,1
1,1,1,1,1,1,1,20,20,20,20,20,20,20,1,1,1,1,1,1,1
1,1,1,1,1,1,1,1,1,1,1,1,1,1,1,1,1,1,1,1,1
1,1,1,1,1,1,1,1,1,1,1,1,1,1,1,1,1,1,1,1,1
endlayer

layer
1,1,1,1,1,1,1,1,1,1,1,1,1,1,1,1,1,1,1,1,1
1,1,1,1,1,1,1,1,1,1,1,1,1,1,1,1,1,1,1,1,1
1,1,1,1,1,1,1,1,1,20,20,20,1,1,1,1,1,1,1,1,1
1,1,1,1,1,1,20,20,20,0,0,0,20,20,20,1,1,1,1,1,1
1,1,1,1,1,20,20,0,0,0,0,0,0,0,20,20,1,1,1,1,1
1,1,1,1,20,0,0,0,0,0,0,0,0,0,0,0,20,1,1,1,1
1,1,1,20,20,0,0,0,0,0,0,0,0,0,0,0,20,20,1,1,1
1,1,1,20,0,0,0,0,0,0,0,0,0,0,0,0,0,20,1,1,1
1,1,1,20,0,0,0,0,0,0,0,0,0,0,0,0,0,20,1,1,1
1,1,20,0,0,0,0,0,0,0,0,0,0,0,0,0,0,0,20,1,1
1,1,20,0,0,0,0,0,0,0,0,0,0,0,0,0,0,0,20,1,1
1,1,20,0,0,0,0,0,0,0,0,0,0,0,0,0,0,0,20,1,1
1,1,1,20,0,0,0,0,0,0,0,0,0,0,0,0,0,20,1,1,1
1,1,1,20,0,0,0,0,0,0,0,0,0,0,0,0,0,20,1,1,1
1,1,1,20,20,0,0,0,0,0,0,0,0,0,0,0,20,20,1,1,1
1,1,1,1,20,0,0,0,0,0,0,0,0,0,0,0,20,1,1,1,1
1,1,1,1,1,20,20,0,0,0,0,0,0,0,20,20,1,1,1,1,1
1,1,1,1,1,1,20,20,20,0,0,0,20,20,20,1,1,1,1,1,1
1,1,1,1,1,1,1,1,1,20,20,20,1,1,1,1,1,1,1,1,1
1,1,1,1,1,1,1,1,1,1,1,1,1,1,1,1,1,1,1,1,1
1,1,1,1,1,1,1,1,1,1,1,1,1,1,1,1,1,1,1,1,1
endlayer

layer
1,1,1,1,1,1,1,1,1,1,1,1,1,1,1,1,1,1,1,1,1
1,1,1,1,1,1,1,1,1,1,1,1,1,1,1,1,1,1,1,1,1
1,1,1,1,1,1,1,1,1,1,1,1,1,1,1,1,1,1,1,1,1
1,1,1,1,1,1,1,1,1,20,20,20,1,1,1,1,1,1,1,1,1
1,1,1,1,1,1,1,20,20,20,20,20,20,20,1,1,1,1,1,1,1
1,1,1,1,1,20,20,20,0,0,0,0,0,20,20,20,1,1,1,1,1
1,1,1,1,1,20,0,0,0,0,0,0,0,0,0,20,1,1,1,1,1
1,1,1,1,20,20,0,0,0,0,0,0,0,0,0,20,20,1,1,1,1
1,1,1,1,20,0,0,0,0,0,0,0,0,0,0,0,20,1,1,1,1
1,1,1,20,20,0,0,0,0,0,0,0,0,0,0,0,20,20,1,1,1
1,1,1,20,20,0,0,0,0,0,0,0,0,0,0,0,20,20,1,1,1
1,1,1,20,20,0,0,0,0,0,0,0,0,0,0,0,20,20,1,1,1
1,1,1,1,20,0,0,0,0,0,0,0,0,0,0,0,20,1,1,1,1
1,1,1,1,20,20,0,0,0,0,0,0,0,0,0,20,20,1,1,1,1
1,1,1,1,1,20,0,0,0,0,0,0,0,0,0,20,1,1,1,1,1
1,1,1,1,1,20,20,20,0,0,0,0,0,20,20,20,1,1,1,1,1
1,1,1,1,1,1,1,20,20,20,20,20,20,20,1,1,1,1,1,1,1
1,1,1,1,1,1,1,1,1,20,20,20,1,1,1,1,1,1,1,1,1
1,1,1,1,1,1,1,1,1,1,1,1,1,1,1,1,1,1,1,1,1
1,1,1,1,1,1,1,1,1,1,1,1,1,1,1,1,1,1,1,1,1
1,1,1,1,1,1,1,1,1,1,1,1,1,1,1,1,1,1,1,1,1
endlayer

layer
1,1,1,1,1,1,1,1,1,1,1,1,1,1,1,1,1,1,1,1,1
1,1,1,1,1,1,1,1,1,1,1,1,1,1,1,1,1,1,1,1,1
1,1,1,1,1,1,1,1,1,1,1,1,1,1,1,1,1,1,1,1,1
1,1,1,1,1,1,1,1,1,1,1,1,1,1,1,1,1,1,1,1,1
1,1,1,1,1,1,1,1,1,1,1,1,1,1,1,1,1,1,1,1,1
1,1,1,1,1,1,1,1,20,20,20,20,20,1,1,1,1,1,1,1,1
1,1,1,1,1,1,20,20,20,20,20,20,20,20,20,1,1,1,1,1,1
1,1,1,1,1,1,20,20,20,0,0,0,20,20,20,1,1,1,1,1,1
1,1,1,1,1,20,20,20,0,0,0,0,0,20,20,20,1,1,1,1,1
1,1,1,1,1,20,20,0,0,0,0,0,0,0,20,20,1,1,1,1,1
1,1,1,1,1,20,20,0,0,0,0,0,0,0,20,20,1,1,1,1,1
1,1,1,1,1,20,20,0,0,0,0,0,0,0,20,20,1,1,1,1,1
1,1,1,1,1,20,20,20,0,0,0,0,0,20,20,20,1,1,1,1,1
1,1,1,1,1,1,20,20,20,0,0,0,20,20,20,1,1,1,1,1,1
1,1,1,1,1,1,20,20,20,20,20,20,20,20,20,1,1,1,1,1,1
1,1,1,1,1,1,1,1,20,20,20,20,20,1,1,1,1,1,1,1,1
1,1,1,1,1,1,1,1,1,1,1,1,1,1,1,1,1,1,1,1,1
1,1,1,1,1,1,1,1,1,1,1,1,1,1,1,1,1,1,1,1,1
1,1,1,1,1,1,1,1,1,1,1,1,1,1,1,1,1,1,1,1,1
1,1,1,1,1,1,1,1,1,1,1,1,1,1,1,1,1,1,1,1,1
1,1,1,1,1,1,1,1,1,1,1,1,1,1,1,1,1,1,1,1,1
endlayer

layer
1,1,1,1,1,1,1,1,1,1,1,1,1,1,1,1,1,1,1,1,1
1,1,1,1,1,1,1,1,1,1,1,1,1,1,1,1,1,1,1,1,1
1,1,1,1,1,1,1,1,1,1,1,1,1,1,1,1,1,1,1,1,1
1,1,1,1,1,1,1,1,1,1,1,1,1,1,1,1,1,1,1,1,1
1,1,1,1,1,1,1,1,1,1,1,1,1,1,1,1,1,1,1,1,1
1,1,1,1,1,1,1,1,1,1,1,1,1,1,1,1,1,1,1,1,1
1,1,1,1,1,1,1,1,1,1,1,1,1,1,1,1,1,1,1,1,1
1,1,1,1,1,1,1,1,1,20,20,20,1,1,1,1,1,1,1,1,1
1,1,1,1,1,1,1,1,20,20,20,20,20,1,1,1,1,1,1,1,1
1,1,1,1,1,1,1,20,20,20,20,20,20,20,1,1,1,1,1,1,1
1,1,1,1,1,1,1,20,20,20,20,20,20,20,1,1,1,1,1,1,1
1,1,1,1,1,1,1,20,20,20,20,20,20,20,1,1,1,1,1,1,1
1,1,1,1,1,1,1,1,20,20,20,20,20,1,1,1,1,1,1,1,1
1,1,1,1,1,1,1,1,1,20,20,20,1,1,1,1,1,1,1,1,1
1,1,1,1,1,1,1,1,1,1,1,1,1,1,1,1,1,1,1,1,1
1,1,1,1,1,1,1,1,1,1,1,1,1,1,1,1,1,1,1,1,1
1,1,1,1,1,1,1,1,1,1,1,1,1,1,1,1,1,1,1,1,1
1,1,1,1,1,1,1,1,1,1,1,1,1,1,1,1,1,1,1,1,1
1,1,1,1,1,1,1,1,1,1,1,1,1,1,1,1,1,1,1,1,1
1,1,1,1,1,1,1,1,1,1,1,1,1,1,1,1,1,1,1,1,1
1,1,1,1,1,1,1,1,1,1,1,1,1,1,1,1,1,1,1,1,1
endlayer

layer
1,1,1,1,1,1,1,1,1,1,1,1,1,1,1,1,1,1,1,1,1
1,1,1,1,1,1,1,1,1,1,1,1,1,1,1,1,1,1,1,1,1
1,1,1,1,1,1,1,1,1,1,1,1,1,1,1,1,1,1,1,1,1
1,1,1,1,1,1,1,1,1,1,1,1,1,1,1,1,1,1,1,1,1
1,1,1,1,1,1,1,1,1,1,1,1,1,1,1,1,1,1,1,1,1
1,1,1,1,1,1,1,1,1,1,1,1,1,1,1,1,1,1,1,1,1
1,1,1,1,1,1,1,1,1,1,1,1,1,1,1,1,1,1,1,1,1
1,1,1,1,1,1,1,1,1,1,1,1,1,1,1,1,1,1,1,1,1
1,1,1,1,1,1,1,1,1,1,1,1,1,1,1,1,1,1,1,1,1
1,1,1,1,1,1,1,1,1,1,1,1,1,1,1,1,1,1,1,1,1
1,1,1,1,1,1,1,1,1,1,1,1,1,1,1,1,1,1,1,1,1
1,1,1,1,1,1,1,1,1,1,1,1,1,1,1,1,1,1,1,1,1
1,1,1,1,1,1,1,1,1,1,1,1,1,1,1,1,1,1,1,1,1
1,1,1,1,1,1,1,1,1,1,1,1,1,1,1,1,1,1,1,1,1
1,1,1,1,1,1,1,1,1,1,1,1,1,1,1,1,1,1,1,1,1
1,1,1,1,1,1,1,1,1,1,1,1,1,1,1,1,1,1,1,1,1
1,1,1,1,1,1,1,1,1,1,1,1,1,1,1,1,1,1,1,1,1
1,1,1,1,1,1,1,1,1,1,1,1,1,1,1,1,1,1,1,1,1
1,1,1,1,1,1,1,1,1,1,1,1,1,1,1,1,1,1,1,1,1
1,1,1,1,1,1,1,1,1,1,1,1,1,1,1,1,1,1,1,1,1
1,1,1,1,1,1,1,1,1,1,1,1,1,1,1,1,1,1,1,1,1
endlayer

layer
1,1,1,1,1,1,1,1,1,1,1,1,1,1,1,1,1,1,1,1,1
1,1,1,1,1,1,1,1,1,1,1,1,1,1,1,1,1,1,1,1,1
1,1,1,1,1,1,1,1,1,1,1,1,1,1,1,1,1,1,1,1,1
1,1,1,1,1,1,1,1,1,1,1,1,1,1,1,1,1,1,1,1,1
1,1,1,1,1,1,1,1,1,1,1,1,1,1,1,1,1,1,1,1,1
1,1,1,1,1,1,1,1,1,1,1,1,1,1,1,1,1,1,1,1,1
1,1,1,1,1,1,1,1,1,1,1,1,1,1,1,1,1,1,1,1,1
1,1,1,1,1,1,1,1,1,1,1,1,1,1,1,1,1,1,1,1,1
1,1,1,1,1,1,1,1,1,1,1,1,1,1,1,1,1,1,1,1,1
1,1,1,1,1,1,1,1,1,1,1,1,1,1,1,1,1,1,1,1,1
1,1,1,1,1,1,1,1,1,1,1,1,1,1,1,1,1,1,1,1,1
1,1,1,1,1,1,1,1,1,1,1,1,1,1,1,1,1,1,1,1,1
1,1,1,1,1,1,1,1,1,1,1,1,1,1,1,1,1,1,1,1,1
1,1,1,1,1,1,1,1,1,1,1,1,1,1,1,1,1,1,1,1,1
1,1,1,1,1,1,1,1,1,1,1,1,1,1,1,1,1,1,1,1,1
1,1,1,1,1,1,1,1,1,1,1,1,1,1,1,1,1,1,1,1,1
1,1,1,1,1,1,1,1,1,1,1,1,1,1,1,1,1,1,1,1,1
1,1,1,1,1,1,1,1,1,1,1,1,1,1,1,1,1,1,1,1,1
1,1,1,1,1,1,1,1,1,1,1,1,1,1,1,1,1,1,1,1,1
1,1,1,1,1,1,1,1,1,1,1,1,1,1,1,1,1,1,1,1,1
1,1,1,1,1,1,1,1,1,1,1,1,1,1,1,1,1,1,1,1,1
endlayer

layer
1,1,1,1,1,1,1,1,1,1,1,1,1,1,1,1,1,1,1,1,1
1,1,1,1,1,1,1,1,1,1,1,1,1,1,1,1,1,1,1,1,1
1,1,1,1,1,1,1,1,1,1,1,1,1,1,1,1,1,1,1,1,1
1,1,1,1,1,1,1,1,1,1,1,1,1,1,1,1,1,1,1,1,1
1,1,1,1,1,1,1,1,1,1,1,1,1,1,1,1,1,1,1,1,1
1,1,1,1,1,1,1,1,1,1,1,1,1,1,1,1,1,1,1,1,1
1,1,1,1,1,1,1,1,1,1,1,1,1,1,1,1,1,1,1,1,1
1,1,1,1,1,1,1,1,1,1,1,1,1,1,1,1,1,1,1,1,1
1,1,1,1,1,1,1,1,1,1,1,1,1,1,1,1,1,1,1,1,1
1,1,1,1,1,1,1,1,1,1,1,1,1,1,1,1,1,1,1,1,1
1,1,1,1,1,1,1,1,1,1,1,1,1,1,1,1,1,1,1,1,1
1,1,1,1,1,1,1,1,1,1,1,1,1,1,1,1,1,1,1,1,1
1,1,1,1,1,1,1,1,1,1,1,1,1,1,1,1,1,1,1,1,1
1,1,1,1,1,1,1,1,1,1,1,1,1,1,1,1,1,1,1,1,1
1,1,1,1,1,1,1,1,1,1,1,1,1,1,1,1,1,1,1,1,1
1,1,1,1,1,1,1,1,1,1,1,1,1,1,1,1,1,1,1,1,1
1,1,1,1,1,1,1,1,1,1,1,1,1,1,1,1,1,1,1,1,1
1,1,1,1,1,1,1,1,1,1,1,1,1,1,1,1,1,1,1,1,1
1,1,1,1,1,1,1,1,1,1,1,1,1,1,1,1,1,1,1,1,1
1,1,1,1,1,1,1,1,1,1,1,1,1,1,1,1,1,1,1,1,1
1,1,1,1,1,1,1,1,1,1,1,1,1,1,1,1,1,1,1,1,1
endlayer

layer
1,1,1,1,1,1,1,1,1,1,1,1,1,1,1,1,1,1,1,1,1
1,1,1,1,1,1,1,1,1,1,1,1,1,1,1,1,1,1,1,1,1
1,1,1,1,1,1,1,1,1,1,1,1,1,1,1,1,1,1,1,1,1
1,1,1,1,1,1,1,1,1,1,1,1,1,1,1,1,1,1,1,1,1
1,1,1,1,1,1,1,1,1,1,1,1,1,1,1,1,1,1,1,1,1
1,1,1,1,1,1,1,1,1,1,1,1,1,1,1,1,1,1,1,1,1
1,1,1,1,1,1,1,1,1,1,1,1,1,1,1,1,1,1,1,1,1
1,1,1,1,1,1,1,1,1,1,1,1,1,1,1,1,1,1,1,1,1
1,1,1,1,1,1,1,1,1,1,1,1,1,1,1,1,1,1,1,1,1
1,1,1,1,1,1,1,1,1,1,1,1,1,1,1,1,1,1,1,1,1
1,1,1,1,1,1,1,1,1,1,1,1,1,1,1,1,1,1,1,1,1
1,1,1,1,1,1,1,1,1,1,1,1,1,1,1,1,1,1,1,1,1
1,1,1,1,1,1,1,1,1,1,1,1,1,1,1,1,1,1,1,1,1
1,1,1,1,1,1,1,1,1,1,1,1,1,1,1,1,1,1,1,1,1
1,1,1,1,1,1,1,1,1,1,1,1,1,1,1,1,1,1,1,1,1
1,1,1,1,1,1,1,1,1,1,1,1,1,1,1,1,1,1,1,1,1
1,1,1,1,1,1,1,1,1,1,1,1,1,1,1,1,1,1,1,1,1
1,1,1,1,1,1,1,1,1,1,1,1,1,1,1,1,1,1,1,1,1
1,1,1,1,1,1,1,1,1,1,1,1,1,1,1,1,1,1,1,1,1
1,1,1,1,1,1,1,1,1,1,1,1,1,1,1,1,1,1,1,1,1
1,1,1,1,1,1,1,1,1,1,1,1,1,1,1,1,1,1,1,1,1
endlayer

