
# Created by Ruins mod version 16.7 Ingame Parser
# authoring Player: ST753M

weight=1
embed_into_distance=6
acceptable_target_blocks=gravel,sand
unacceptable_target_blocks=flowing_water,water,flowing_lava,lava
dimensions=16,17,17
allowable_overhang=6
max_leveling=0
leveling_buffer=0
preserve_water=1
preserve_lava=0

biomesToSpawnIn=deep_ocean

=0,100,air
rule1=0,100,preserveBlock
rule2=0,100,minecraft:stone-0
rule3=0,100,biomesoplenty:log_0-6
rule4=0,100,biomesoplenty:dirt-0
rule5=0,100,biomesoplenty:poison-0
rule6=0,100,biomesoplenty:log_0-10
rule7=0,100,biomesoplenty:log_0-2
rule8=0,100,IInventory;minecraft:chest;biomesoplenty:terrarium#1#11#0+minecraft:web#1#0#2+biomesoplenty:ash#3#0#4+biomesoplenty:mushroom#4#5#6+minecraft:web#2#0#8+biomesoplenty:ash#7#0#10+biomesoplenty:mushroom#3#5#11+biomesoplenty:terrarium#1#11#14+biomesoplenty:ash#3#0#16+minecraft:web#3#0#18+biomesoplenty:mushroom#2#5#21+minecraft:web#5#0#23+biomesoplenty:ash#7#0#25-5
rule9=0,100,biomesoplenty:leaves_1-4
rule10=0,100,air
rule11=0,100,biomesoplenty:flower_0-2
rule12=0,100,air
rule13=0,100,biomesoplenty:sapling_0-4
rule14=0,100,Skull:1:7-1
rule15=0,100,biomesoplenty:leaves_1-12
rule16=0,100,biomesoplenty:sapling_0-12
rule17=0,100,air
rule18=0,100,MobSpawner:Witch,MobSpawner:Spider,MobSpawner:Cave_Spider
rule19=0,100,Skull:0:14-1
rule20=0,100,Skull:0:10-1
rule21=0,100,air
rule22=0,100,air
rule23=0,100,minecraft:stained_glass-15
^0,100,minecraft:stained_glass-0
^0,100,minecraft:stained_glass-9
^0,100,minecraft:stained_glass-3
^0,100,minecraft:stained_glass-11
^0,100,minecraft:stained_glass-8
^0,100,minecraft:stained_glass-7
rule24=0,100,minecraft:web-0

layer
1,1,1,1,1,1,2,2,2,2,2,1,1,1,1,1,1
1,1,1,1,2,2,2,2,2,2,2,2,2,1,1,1,1
1,1,1,2,2,2,2,2,2,2,2,2,2,2,1,1,1
1,1,2,2,2,2,2,2,2,2,2,2,2,2,2,1,1
1,2,2,2,2,2,2,2,2,2,2,2,2,2,2,2,1
1,2,2,2,2,2,2,2,2,2,2,2,2,2,2,2,1
2,2,2,2,2,2,2,2,2,2,2,2,2,2,2,2,2
2,2,2,2,2,2,2,2,2,2,2,2,2,2,2,2,2
2,2,2,2,2,2,2,2,2,2,2,2,2,2,2,2,2
2,2,2,2,2,2,2,2,2,2,2,2,2,2,2,2,2
2,2,2,2,2,2,2,2,2,2,2,2,2,2,2,2,2
1,2,2,2,2,2,2,2,2,2,2,2,2,2,2,2,1
1,2,2,2,2,2,2,2,2,2,2,2,2,2,2,2,1
1,1,2,2,2,2,2,2,2,2,2,2,2,2,2,1,1
1,1,1,2,2,2,2,2,2,2,2,2,2,2,1,1,1
1,1,1,1,2,2,2,2,2,2,2,2,2,1,1,1,1
1,1,1,1,1,1,2,2,2,2,2,1,1,1,1,1,1
endlayer

layer
1,1,1,1,1,1,2,2,2,2,2,1,1,1,1,1,1
1,1,1,1,2,2,2,2,2,2,2,2,2,1,1,1,1
1,1,1,2,2,2,2,2,2,2,2,2,2,2,1,1,1
1,1,2,2,2,2,2,2,2,2,2,2,2,2,2,1,1
1,2,2,2,2,2,2,2,2,2,2,2,2,2,2,2,1
1,2,2,2,2,2,2,2,2,2,2,2,2,2,2,2,1
2,2,2,2,2,2,2,2,2,2,2,2,2,2,2,2,2
2,2,2,2,2,2,2,2,2,2,2,2,2,2,2,2,2
2,2,2,2,2,2,2,2,2,2,2,2,2,2,2,2,2
2,2,2,2,2,2,2,2,2,2,2,2,2,2,2,2,2
2,2,2,2,2,2,2,2,2,2,2,2,2,2,2,2,2
1,2,2,2,2,2,2,2,2,2,2,2,2,2,2,2,1
1,2,2,2,2,2,2,2,2,2,2,2,2,2,2,2,1
1,1,2,2,2,2,2,2,2,2,2,2,2,2,2,1,1
1,1,1,2,2,2,2,2,2,2,2,2,2,2,1,1,1
1,1,1,1,2,2,2,2,2,2,2,2,2,1,1,1,1
1,1,1,1,1,1,2,2,2,2,2,1,1,1,1,1,1
endlayer

layer
1,1,1,1,1,1,2,2,2,2,2,1,1,1,1,1,1
1,1,1,1,2,2,2,2,2,2,2,2,2,1,1,1,1
1,1,1,2,2,2,2,2,2,2,2,2,2,2,1,1,1
1,1,2,2,2,2,2,2,2,2,2,2,2,2,2,1,1
1,2,2,2,2,2,2,2,2,2,2,2,2,2,2,2,1
1,2,2,2,2,2,2,2,2,2,2,2,2,2,2,2,1
2,2,2,2,2,2,2,2,2,2,2,2,2,2,2,2,2
2,2,2,2,2,2,2,2,2,2,2,2,2,2,2,2,2
2,2,2,2,2,2,2,2,2,2,2,2,2,2,2,2,2
2,2,2,2,2,2,2,2,2,2,2,2,2,2,2,2,2
2,2,2,2,2,2,2,2,2,2,2,2,2,2,2,2,2
1,2,2,2,2,2,2,2,2,2,2,2,2,2,2,2,1
1,2,2,2,2,2,2,2,2,2,2,2,2,2,2,2,1
1,1,2,2,2,2,2,2,2,2,2,2,2,2,2,1,1
1,1,1,2,2,2,2,2,2,2,2,2,2,2,1,1,1
1,1,1,1,2,2,2,2,2,2,2,2,2,1,1,1,1
1,1,1,1,1,1,2,2,2,2,2,1,1,1,1,1,1
endlayer

layer
1,1,1,1,1,1,2,2,2,2,2,1,1,1,1,1,1
1,1,1,1,2,2,2,2,2,2,2,2,2,1,1,1,1
1,1,1,2,2,2,2,2,2,2,2,2,2,2,1,1,1
1,1,2,2,2,2,2,2,2,2,2,2,2,2,2,1,1
1,2,2,2,2,2,2,2,2,2,2,2,2,2,2,2,1
1,2,2,2,2,2,2,2,2,2,2,2,2,2,2,2,1
2,2,2,2,2,2,2,2,2,2,2,2,2,2,2,2,2
2,2,2,2,2,2,2,2,2,2,2,2,2,2,2,2,2
2,2,2,2,2,2,2,2,3,2,2,2,2,2,2,2,2
2,2,2,2,2,2,2,2,2,2,2,2,2,2,2,2,2
2,2,2,2,2,2,2,2,2,2,2,2,2,2,2,2,2
1,2,2,2,2,2,2,2,2,2,2,2,2,2,2,2,1
1,2,2,2,2,2,2,2,2,2,2,2,2,2,2,2,1
1,1,2,2,2,2,2,2,2,2,2,2,2,2,2,1,1
1,1,1,2,2,2,2,2,2,2,2,2,2,2,1,1,1
1,1,1,1,2,2,2,2,2,2,2,2,2,1,1,1,1
1,1,1,1,1,1,2,2,2,2,2,1,1,1,1,1,1
endlayer

layer
1,1,1,1,1,1,2,2,2,2,2,1,1,1,1,1,1
1,1,1,1,2,2,2,2,2,2,2,2,2,1,1,1,1
1,1,1,2,2,2,2,2,2,2,2,2,2,2,1,1,1
1,1,2,2,2,2,2,2,2,2,2,2,2,2,2,1,1
1,2,2,2,2,2,2,2,2,2,2,2,2,2,2,2,1
1,2,2,2,4,4,2,2,2,2,2,2,2,2,2,2,1
2,2,2,2,4,4,4,2,2,2,2,2,2,2,2,2,2
2,2,2,2,2,4,4,2,2,2,2,2,2,2,2,2,2
2,2,2,2,2,2,2,2,3,2,2,2,2,2,2,2,2
2,2,2,2,2,2,2,2,2,2,2,2,2,2,2,2,2
2,2,2,2,2,2,2,2,2,2,2,2,2,2,2,2,2
1,2,2,2,2,2,2,2,2,2,4,4,2,2,2,2,1
1,2,2,2,2,2,2,2,2,2,4,4,2,2,2,2,1
1,1,2,2,2,2,2,2,2,2,2,2,2,2,2,1,1
1,1,1,2,2,2,2,2,2,2,2,2,2,2,1,1,1
1,1,1,1,2,2,2,2,2,2,2,2,2,1,1,1,1
1,1,1,1,1,1,2,2,2,2,2,1,1,1,1,1,1
endlayer

layer
1,1,1,1,1,1,2,2,2,2,2,1,1,1,1,1,1
1,1,1,1,2,2,4,4,4,4,4,2,2,1,1,1,1
1,1,1,2,4,4,4,4,4,4,4,4,4,2,1,1,1
1,1,2,4,4,4,4,4,4,4,4,4,4,4,2,1,1
1,2,4,4,4,4,4,4,4,4,4,4,4,4,4,2,1
1,2,4,4,5,5,4,4,4,4,4,4,4,4,4,2,1
2,4,4,4,5,5,5,4,4,4,4,4,4,4,4,4,2
2,4,4,4,4,5,5,4,6,4,4,4,4,4,4,4,2
2,4,4,4,4,4,4,7,8,7,4,4,4,4,4,4,2
2,4,4,4,4,4,4,4,6,4,4,4,4,4,4,4,2
2,4,4,4,4,4,4,4,4,4,4,4,4,4,4,4,2
1,2,4,4,4,4,4,4,4,4,5,5,4,4,4,2,1
1,2,4,4,4,4,4,4,4,4,5,5,4,4,4,2,1
1,1,2,4,4,4,4,4,4,4,4,4,4,4,2,1,1
1,1,1,2,4,4,4,4,4,4,4,4,4,2,1,1,1
1,1,1,1,2,2,4,4,4,4,4,2,2,1,1,1,1
1,1,1,1,1,1,2,2,2,2,2,1,1,1,1,1,1
endlayer

layer
1,1,1,1,1,1,2,2,2,2,2,1,1,1,1,1,1
1,1,1,1,2,2,12,11,0,10,9,2,2,1,1,1,1
1,1,1,2,12,9,0,0,13,9,3,9,10,2,1,1,1
1,1,2,11,9,3,9,11,0,0,15,0,14,12,2,1,1
1,2,17,0,0,15,16,0,11,0,0,0,0,11,0,2,1
1,2,0,13,0,0,0,0,0,0,0,11,0,0,0,2,1
2,17,9,0,0,0,0,0,0,11,11,0,0,0,9,10,2
2,9,3,9,0,0,0,0,9,11,0,0,0,9,3,9,2
2,0,9,0,11,0,0,9,18,9,0,13,11,0,9,15,2
2,0,0,11,0,0,0,16,9,0,0,0,17,0,15,3,2
2,17,13,9,16,11,0,0,0,0,0,11,13,11,0,15,2
1,2,9,3,15,0,0,13,0,13,0,0,0,19,0,2,1
1,2,0,15,0,0,20,0,0,0,0,0,0,9,10,2,1
1,1,2,0,16,0,0,9,0,11,0,16,9,3,2,1,1
1,1,1,2,0,21,9,3,9,0,11,0,21,2,1,1,1
1,1,1,1,2,2,22,9,0,16,21,2,2,1,1,1,1
1,1,1,1,1,1,2,2,2,2,2,1,1,1,1,1,1
endlayer

layer
1,1,1,1,1,1,23,23,23,23,23,1,1,1,1,1,1
1,1,1,1,23,23,0,0,0,0,0,23,23,1,1,1,1
1,1,1,23,0,0,0,0,0,10,9,0,0,23,1,1,1
1,1,23,0,0,9,0,0,0,0,0,0,0,0,23,1,1
1,23,0,0,0,12,0,0,0,0,0,0,0,0,0,23,1
1,23,0,0,0,0,0,0,0,0,0,0,0,0,0,23,1
23,0,0,0,0,0,0,0,0,0,0,21,0,0,0,0,23
23,0,9,0,0,0,0,0,0,0,0,0,0,0,9,0,23
23,0,0,0,0,0,0,0,3,0,0,0,0,0,0,0,23
23,0,0,0,0,0,0,0,0,0,0,0,17,0,0,15,23
23,0,0,0,0,0,0,0,0,0,0,0,0,0,0,0,23
1,23,0,9,0,0,0,0,0,0,12,0,0,0,0,23,1
1,23,0,0,0,0,0,0,0,0,0,0,0,0,0,23,1
1,1,23,0,0,0,0,21,0,0,0,0,10,9,23,1,1
1,1,1,23,0,0,0,9,0,0,0,0,0,23,1,1,1
1,1,1,1,23,23,0,0,0,0,0,23,23,1,1,1,1
1,1,1,1,1,1,23,23,23,23,23,1,1,1,1,1,1
endlayer

layer
1,1,1,1,1,1,23,23,23,23,23,1,1,1,1,1,1
1,1,1,1,23,23,0,0,0,0,24,23,23,1,1,1,1
1,1,1,23,0,0,0,0,0,0,0,0,0,23,1,1,1
1,1,23,0,0,0,0,0,0,0,0,0,0,0,23,1,1
1,23,0,0,0,0,0,21,0,21,0,0,0,0,0,23,1
1,23,0,0,0,0,10,15,15,15,21,0,0,0,0,23,1
23,24,0,0,0,21,15,15,15,15,15,21,0,0,0,0,23
23,0,0,0,10,15,15,15,15,15,15,15,17,0,0,0,23
23,0,0,0,10,15,15,15,3,15,15,15,0,0,0,0,23
23,0,0,0,0,15,15,15,15,15,15,15,17,0,0,0,23
23,0,0,0,0,0,15,15,15,15,15,12,0,0,0,0,23
1,23,0,0,0,0,10,15,15,15,12,0,0,0,0,23,1
1,23,24,0,0,0,0,12,0,12,0,0,0,0,0,23,1
1,1,23,0,0,0,0,0,0,0,0,0,0,0,23,1,1
1,1,1,23,0,0,0,0,0,0,0,0,0,23,1,1,1
1,1,1,1,23,23,0,0,0,0,0,23,23,1,1,1,1
1,1,1,1,1,1,23,23,23,23,23,1,1,1,1,1,1
endlayer

layer
1,1,1,1,1,1,1,23,23,23,1,1,1,1,1,1,1
1,1,1,1,23,23,23,0,0,0,23,23,23,1,1,1,1
1,1,1,23,0,0,0,0,0,0,0,0,0,23,1,1,1
1,1,23,0,0,0,0,0,0,0,0,0,0,0,23,1,1
1,23,0,0,0,0,0,0,0,0,0,0,0,0,0,23,1
1,23,0,0,0,0,0,0,0,0,0,0,0,0,0,23,1
1,23,0,0,0,0,10,0,15,0,0,0,0,0,0,23,1
23,0,0,0,0,0,0,15,15,15,0,17,0,0,0,0,23
23,0,0,0,0,0,15,15,3,15,15,0,0,0,0,0,23
23,0,0,0,0,0,0,15,15,15,0,0,0,0,0,0,23
1,23,0,0,0,0,0,0,15,0,0,0,0,0,0,23,1
1,23,0,0,0,0,0,0,0,0,0,0,0,0,0,23,1
1,23,0,0,0,0,0,0,0,0,0,0,0,0,0,23,1
1,1,23,0,0,0,0,0,0,0,0,0,0,0,23,1,1
1,1,1,23,0,0,0,0,0,0,0,0,0,23,1,1,1
1,1,1,1,23,23,23,0,0,0,23,23,23,1,1,1,1
1,1,1,1,1,1,1,23,23,23,1,1,1,1,1,1,1
endlayer

layer
1,1,1,1,1,1,1,1,1,1,1,1,1,1,1,1,1
1,1,1,1,1,23,23,23,23,23,23,23,1,1,1,1,1
1,1,1,23,23,0,0,0,0,0,0,0,23,23,1,1,1
1,1,23,0,0,0,0,0,0,0,0,0,0,0,23,1,1
1,1,23,0,0,0,0,0,21,0,0,0,0,0,23,1,1
1,23,24,0,0,0,0,21,15,21,0,0,0,0,24,23,1
1,23,0,0,0,0,10,15,15,15,0,0,0,0,0,23,1
1,23,0,0,0,10,15,15,15,15,15,17,0,0,0,23,1
1,23,0,0,10,15,15,15,3,15,15,15,17,0,0,23,1
1,23,0,0,0,10,15,15,15,15,15,17,0,0,0,23,1
1,23,0,0,0,0,10,15,15,15,12,0,0,0,24,23,1
1,23,24,0,0,0,0,12,15,12,0,0,0,0,0,23,1
1,1,23,0,0,0,0,0,12,0,0,0,0,0,23,1,1
1,1,23,0,0,0,0,0,0,0,0,0,0,0,23,1,1
1,1,1,23,23,0,0,0,0,0,0,0,23,23,1,1,1
1,1,1,1,1,23,23,23,23,23,23,23,1,1,1,1,1
1,1,1,1,1,1,1,1,1,1,1,1,1,1,1,1,1
endlayer

layer
1,1,1,1,1,1,1,1,1,1,1,1,1,1,1,1,1
1,1,1,1,1,1,23,23,23,23,23,1,1,1,1,1,1
1,1,1,1,23,23,0,0,0,0,0,23,23,1,1,1,1
1,1,1,23,0,0,0,0,0,0,0,0,0,23,1,1,1
1,1,23,0,0,0,0,0,0,0,0,0,0,0,23,1,1
1,1,23,0,0,0,0,0,0,0,0,0,0,0,23,1,1
1,23,0,0,0,0,0,0,0,0,0,0,0,0,24,23,1
1,23,0,0,0,0,10,0,15,0,0,0,0,0,0,23,1
1,23,0,0,0,0,0,15,3,15,0,17,0,0,0,23,1
1,23,0,0,0,0,10,0,15,0,0,0,0,0,0,23,1
1,23,0,0,0,0,0,10,0,0,0,0,0,0,0,23,1
1,1,23,0,0,0,0,0,0,0,0,0,0,0,23,1,1
1,1,23,24,0,0,0,0,0,0,0,0,0,0,23,1,1
1,1,1,23,0,0,0,0,0,0,0,0,0,23,1,1,1
1,1,1,1,23,23,0,0,0,0,0,23,23,1,1,1,1
1,1,1,1,1,1,23,23,23,23,23,1,1,1,1,1,1
1,1,1,1,1,1,1,1,1,1,1,1,1,1,1,1,1
endlayer

layer
1,1,1,1,1,1,1,1,1,1,1,1,1,1,1,1,1
1,1,1,1,1,1,1,1,1,1,1,1,1,1,1,1,1
1,1,1,1,1,23,23,23,23,23,23,23,1,1,1,1,1
1,1,1,1,23,0,24,0,0,0,0,0,23,1,1,1,1
1,1,1,23,0,0,0,0,0,0,0,0,24,23,1,1,1
1,1,23,0,0,0,0,0,0,0,0,0,0,0,23,1,1
1,1,23,0,0,0,0,10,15,21,0,0,0,0,23,1,1
1,1,23,0,0,0,10,15,15,15,21,0,0,0,23,1,1
1,1,23,0,0,0,15,15,3,15,15,17,0,0,23,1,1
1,1,23,24,0,0,10,15,15,15,0,0,0,0,23,1,1
1,1,23,0,0,0,0,10,15,12,0,0,0,0,23,1,1
1,1,23,0,0,0,0,0,12,0,0,0,0,0,23,1,1
1,1,1,23,0,0,0,0,0,0,0,0,0,23,1,1,1
1,1,1,1,23,0,0,0,0,24,0,0,23,1,1,1,1
1,1,1,1,1,23,23,23,23,23,23,23,1,1,1,1,1
1,1,1,1,1,1,1,1,1,1,1,1,1,1,1,1,1
1,1,1,1,1,1,1,1,1,1,1,1,1,1,1,1,1
endlayer

layer
1,1,1,1,1,1,1,1,1,1,1,1,1,1,1,1,1
1,1,1,1,1,1,1,1,1,1,1,1,1,1,1,1,1
1,1,1,1,1,1,1,1,1,1,1,1,1,1,1,1,1
1,1,1,1,1,23,23,23,23,23,23,23,1,1,1,1,1
1,1,1,1,23,23,0,0,0,0,0,23,23,1,1,1,1
1,1,1,23,23,0,0,0,0,0,0,0,23,23,1,1,1
1,1,1,23,0,0,0,0,0,0,0,0,0,23,1,1,1
1,1,1,23,0,0,0,0,15,0,0,0,0,23,1,1,1
1,1,1,23,0,0,0,15,15,15,0,0,0,23,1,1,1
1,1,1,23,0,0,0,0,15,0,0,0,0,23,1,1,1
1,1,1,23,0,0,0,0,0,0,0,0,0,23,1,1,1
1,1,1,23,23,0,0,0,0,0,0,0,23,23,1,1,1
1,1,1,1,23,23,0,0,0,0,0,23,23,1,1,1,1
1,1,1,1,1,23,23,23,23,23,23,23,1,1,1,1,1
1,1,1,1,1,1,1,1,1,1,1,1,1,1,1,1,1
1,1,1,1,1,1,1,1,1,1,1,1,1,1,1,1,1
1,1,1,1,1,1,1,1,1,1,1,1,1,1,1,1,1
endlayer

layer
1,1,1,1,1,1,1,1,1,1,1,1,1,1,1,1,1
1,1,1,1,1,1,1,1,1,1,1,1,1,1,1,1,1
1,1,1,1,1,1,1,1,1,1,1,1,1,1,1,1,1
1,1,1,1,1,1,1,1,1,1,1,1,1,1,1,1,1
1,1,1,1,1,1,23,23,23,23,23,1,1,1,1,1,1
1,1,1,1,1,23,23,23,23,23,23,23,1,1,1,1,1
1,1,1,1,23,23,23,0,0,0,23,23,23,1,1,1,1
1,1,1,1,23,23,0,0,0,0,0,23,23,1,1,1,1
1,1,1,1,23,23,0,0,15,0,0,23,23,1,1,1,1
1,1,1,1,23,23,0,0,0,0,0,23,23,1,1,1,1
1,1,1,1,23,23,23,0,0,0,23,23,23,1,1,1,1
1,1,1,1,1,23,23,23,23,23,23,23,1,1,1,1,1
1,1,1,1,1,1,23,23,23,23,23,1,1,1,1,1,1
1,1,1,1,1,1,1,1,1,1,1,1,1,1,1,1,1
1,1,1,1,1,1,1,1,1,1,1,1,1,1,1,1,1
1,1,1,1,1,1,1,1,1,1,1,1,1,1,1,1,1
1,1,1,1,1,1,1,1,1,1,1,1,1,1,1,1,1
endlayer

layer
1,1,1,1,1,1,1,1,1,1,1,1,1,1,1,1,1
1,1,1,1,1,1,1,1,1,1,1,1,1,1,1,1,1
1,1,1,1,1,1,1,1,1,1,1,1,1,1,1,1,1
1,1,1,1,1,1,1,1,1,1,1,1,1,1,1,1,1
1,1,1,1,1,1,1,1,1,1,1,1,1,1,1,1,1
1,1,1,1,1,1,1,1,1,1,1,1,1,1,1,1,1
1,1,1,1,1,1,1,23,23,23,1,1,1,1,1,1,1
1,1,1,1,1,1,23,23,23,23,23,1,1,1,1,1,1
1,1,1,1,1,1,23,23,23,23,23,1,1,1,1,1,1
1,1,1,1,1,1,23,23,23,23,23,1,1,1,1,1,1
1,1,1,1,1,1,1,23,23,23,1,1,1,1,1,1,1
1,1,1,1,1,1,1,1,1,1,1,1,1,1,1,1,1
1,1,1,1,1,1,1,1,1,1,1,1,1,1,1,1,1
1,1,1,1,1,1,1,1,1,1,1,1,1,1,1,1,1
1,1,1,1,1,1,1,1,1,1,1,1,1,1,1,1,1
1,1,1,1,1,1,1,1,1,1,1,1,1,1,1,1,1
1,1,1,1,1,1,1,1,1,1,1,1,1,1,1,1,1
endlayer

