
# Created by Ruins mod version 17.0 Ingame Parser
# authoring Player: ST753M

weight=1
uniqueMinDistance=1000
spawnMinDistance=1000
embed_into_distance=4
acceptable_target_blocks=gravel,sand,stone,clay
unacceptable_target_blocks=
dimensions=23,19,19
allowable_overhang=4
max_leveling=5
leveling_buffer=0
preserve_water=1
preserve_lava=1

adjoining_template=ST753M/753_Prism_Gate_EW;0;99;25;100
adjoining_template=ST753M/753_Prism_Gate_EW;0;99;-25;100
adjoining_template=ST753M/753_Prism_Gate_NS;25;99;0;100
adjoining_template=ST753M/753_Prism_Gate_NS;-25;99;0;100

adjoining_template=ST753M/753_Prism_Wall_EW;9;99;25;100
adjoining_template=ST753M/753_Prism_Wall_EW;16;99;25;100
adjoining_template=ST753M/753_Prism_Wall_EW;-9;99;25;100
adjoining_template=ST753M/753_Prism_Wall_EW;-16;99;25;100
adjoining_template=ST753M/753_Prism_Wall_EW;9;99;-25;100
adjoining_template=ST753M/753_Prism_Wall_EW;16;99;-25;100
adjoining_template=ST753M/753_Prism_Wall_EW;-9;99;-25;100
adjoining_template=ST753M/753_Prism_Wall_EW;-16;99;-25;100

adjoining_template=ST753M/753_Prism_Wall_NS;25;99;9;100
adjoining_template=ST753M/753_Prism_Wall_NS;25;99;16;100
adjoining_template=ST753M/753_Prism_Wall_NS;25;99;-9;100
adjoining_template=ST753M/753_Prism_Wall_NS;25;99;-16;100
adjoining_template=ST753M/753_Prism_Wall_NS;-25;99;9;100
adjoining_template=ST753M/753_Prism_Wall_NS;-25;99;16;100
adjoining_template=ST753M/753_Prism_Wall_NS;-25;99;-9;100
adjoining_template=ST753M/753_Prism_Wall_NS;-25;99;-16;100

adjoining_template=deep_ocean/753_Prism_House1;17;99;7;100
adjoining_template=deep_ocean/753_Prism_House2;17;99;-7;100
adjoining_template=deep_ocean/753_Prism_House3;-17;99;7;100
adjoining_template=deep_ocean/753_Prism_House1;-17;99;-7;100
adjoining_template=deep_ocean/753_Prism_House2;7;99;17;100
adjoining_template=deep_ocean/753_Prism_House3;7;99;-17;100
adjoining_template=deep_ocean/753_Prism_House1;-7;99;17;100
adjoining_template=deep_ocean/753_Prism_House2;-7;99;-17;100

adjoining_template=deep_ocean/753_Prism_GuardTower;25;99;25;100
adjoining_template=deep_ocean/753_Prism_GuardTower;25;99;-25;100
adjoining_template=deep_ocean/753_Prism_GuardTower;-25;99;25;100
adjoining_template=deep_ocean/753_Prism_GuardTower;-25;99;-25;100

biomesToSpawnIn=deep_ocean

=0,100,preserveBlock
rule1=0,100,minecraft:prismarine-1
rule2=0,100,minecraft:prismarine-2
rule3=0,100,minecraft:sea_lantern-0
rule4=0,100,minecraft:prismarine-0
rule5=0,100,minecraft:water-0
rule6=0,100,minecraft:stained_glass-9
rule7=0,100,minecraft:water-0
rule8=0,100,minecraft:water-0
rule9=0,100,minecraft:water-0
rule10=0,30,ChestGenHook:chests/stronghold_corridor:5-4
rule11=0,100,air
rule12=0,50,MobSpawner:guardian

layer
1,1,1,1,1,1,1,1,1,1,1,1,1,1,1,1,1,1,1
1,1,1,1,1,1,1,1,1,1,1,1,1,1,1,1,1,1,1
1,1,1,1,1,1,1,1,1,1,1,1,1,1,1,1,1,1,1
1,1,1,1,1,1,1,1,1,1,1,1,1,1,1,1,1,1,1
1,1,1,1,1,1,1,1,1,1,1,1,1,1,1,1,1,1,1
1,1,1,1,1,1,1,1,1,1,1,1,1,1,1,1,1,1,1
1,1,1,1,1,1,1,1,1,1,1,1,1,1,1,1,1,1,1
1,1,1,1,1,1,1,1,1,1,1,1,1,1,1,1,1,1,1
1,1,1,1,1,1,1,1,1,1,1,1,1,1,1,1,1,1,1
1,1,1,1,1,1,1,1,1,1,1,1,1,1,1,1,1,1,1
1,1,1,1,1,1,1,1,1,1,1,1,1,1,1,1,1,1,1
1,1,1,1,1,1,1,1,1,1,1,1,1,1,1,1,1,1,1
1,1,1,1,1,1,1,1,1,1,1,1,1,1,1,1,1,1,1
1,1,1,1,1,1,1,1,1,1,1,1,1,1,1,1,1,1,1
1,1,1,1,1,1,1,1,1,1,1,1,1,1,1,1,1,1,1
1,1,1,1,1,1,1,1,1,1,1,1,1,1,1,1,1,1,1
1,1,1,1,1,1,1,1,1,1,1,1,1,1,1,1,1,1,1
1,1,1,1,1,1,1,1,1,1,1,1,1,1,1,1,1,1,1
1,1,1,1,1,1,1,1,1,1,1,1,1,1,1,1,1,1,1
endlayer

layer
2,2,2,2,2,2,2,2,2,2,2,2,2,2,2,2,2,2,2
2,2,2,2,2,2,2,2,2,2,2,2,2,2,2,2,2,2,2
2,2,2,2,2,2,2,2,2,2,2,2,2,2,2,2,2,2,2
2,2,2,2,2,2,2,2,2,2,2,2,2,2,2,2,2,2,2
2,2,2,2,2,2,2,2,2,2,2,2,2,2,2,2,2,2,2
2,2,2,2,2,2,2,2,2,2,2,2,2,2,2,2,2,2,2
2,2,2,2,2,2,2,2,2,2,2,2,2,2,2,2,2,2,2
2,2,2,2,2,2,2,2,2,2,2,2,2,2,2,2,2,2,2
2,2,2,2,2,2,2,2,2,2,2,2,2,2,2,2,2,2,2
2,2,2,2,2,2,2,2,2,2,2,2,2,2,2,2,2,2,2
2,2,2,2,2,2,2,2,2,2,2,2,2,2,2,2,2,2,2
2,2,2,2,2,2,2,2,2,2,2,2,2,2,2,2,2,2,2
2,2,2,2,2,2,2,2,2,2,2,2,2,2,2,2,2,2,2
2,2,2,2,2,2,2,2,2,2,2,2,2,2,2,2,2,2,2
2,2,2,2,2,2,2,2,2,2,2,2,2,2,2,2,2,2,2
2,2,2,2,2,2,2,2,2,2,2,2,2,2,2,2,2,2,2
2,2,2,2,2,2,2,2,2,2,2,2,2,2,2,2,2,2,2
2,2,2,2,2,2,2,2,2,2,2,2,2,2,2,2,2,2,2
2,2,2,2,2,2,2,2,2,2,2,2,2,2,2,2,2,2,2
endlayer

layer
2,2,2,2,2,2,2,2,2,2,2,2,2,2,2,2,2,2,2
2,2,2,2,2,2,2,2,2,2,2,2,2,2,2,2,2,2,2
2,2,2,2,2,2,2,2,2,2,2,2,2,2,2,2,2,2,2
2,2,2,2,2,2,2,2,2,2,2,2,2,2,2,2,2,2,2
2,2,2,2,2,2,2,2,2,2,2,2,2,2,2,2,2,2,2
2,2,2,2,2,2,2,2,2,2,2,2,2,2,2,2,2,2,2
2,2,2,2,2,2,2,2,2,2,2,2,2,2,2,2,2,2,2
2,2,2,2,2,2,2,2,2,2,2,2,2,2,2,2,2,2,2
2,2,2,2,2,2,2,2,2,2,2,2,2,2,2,2,2,2,2
2,2,2,2,2,2,2,2,2,2,2,2,2,2,2,2,2,2,2
2,2,2,2,2,2,2,2,2,2,2,2,2,2,2,2,2,2,2
2,2,2,2,2,2,2,2,2,2,2,2,2,2,2,2,2,2,2
2,2,2,2,2,2,2,2,2,2,2,2,2,2,2,2,2,2,2
2,2,2,2,2,2,2,2,2,2,2,2,2,2,2,2,2,2,2
2,2,2,2,2,2,2,2,2,2,2,2,2,2,2,2,2,2,2
2,2,2,2,2,2,2,2,2,2,2,2,2,2,2,2,2,2,2
2,2,2,2,2,2,2,2,2,2,2,2,2,2,2,2,2,2,2
2,2,2,2,2,2,2,2,2,2,2,2,2,2,2,2,2,2,2
2,2,2,2,2,2,2,2,2,2,2,2,2,2,2,2,2,2,2
endlayer

layer
1,1,1,1,1,2,1,1,1,1,1,1,1,2,1,1,1,1,1
1,1,1,1,1,1,1,1,1,1,1,1,1,1,1,1,1,1,1
1,1,1,1,1,1,1,1,1,1,1,1,1,1,1,1,1,1,1
1,1,1,1,1,1,1,1,1,1,1,1,1,1,1,1,1,1,1
1,1,1,1,1,1,1,1,1,1,1,1,1,1,1,1,1,1,1
2,1,1,1,1,1,1,1,1,1,1,1,1,1,1,1,1,1,2
1,1,1,1,1,1,1,1,1,1,1,1,1,1,1,1,1,1,1
1,1,1,1,1,1,1,1,1,1,1,1,1,1,1,1,1,1,1
1,1,1,1,1,1,1,1,1,1,1,1,1,1,1,1,1,1,1
1,1,1,1,1,1,1,1,1,3,1,1,1,1,1,1,1,1,1
1,1,1,1,1,1,1,1,1,1,1,1,1,1,1,1,1,1,1
1,1,1,1,1,1,1,1,1,1,1,1,1,1,1,1,1,1,1
1,1,1,1,1,1,1,1,1,1,1,1,1,1,1,1,1,1,1
2,1,1,1,1,1,1,1,1,1,1,1,1,1,1,1,1,1,2
1,1,1,1,1,1,1,1,1,1,1,1,1,1,1,1,1,1,1
1,1,1,1,1,1,1,1,1,1,1,1,1,1,1,1,1,1,1
1,1,1,1,1,1,1,1,1,1,1,1,1,1,1,1,1,1,1
1,1,1,1,1,1,1,1,1,1,1,1,1,1,1,1,1,1,1
1,1,1,1,1,2,1,1,1,1,1,1,1,2,1,1,1,1,1
endlayer

layer
2,2,2,2,2,2,0,4,0,0,0,4,0,2,2,2,2,2,2
2,1,1,1,1,1,0,4,1,1,1,4,0,1,1,1,1,1,2
2,1,2,2,2,1,1,1,2,2,2,1,1,1,2,2,2,1,2
2,1,2,2,2,1,5,4,1,1,1,4,5,1,2,2,2,1,2
2,1,2,2,2,1,5,4,5,5,5,4,5,1,2,2,2,1,2
2,1,1,1,1,1,5,5,5,5,5,5,5,1,1,1,1,1,2
0,0,1,5,5,5,5,5,5,5,5,5,5,5,5,5,1,0,0
4,4,1,4,4,5,5,5,5,5,5,5,5,5,4,4,1,4,4
0,1,2,1,5,5,5,5,5,5,5,5,5,5,5,1,2,1,0
0,1,2,1,5,5,5,5,5,5,5,5,5,5,5,1,2,1,0
0,1,2,1,5,5,5,5,5,5,5,5,5,5,5,1,2,1,0
4,4,1,4,4,5,5,5,5,5,5,5,5,5,4,4,1,4,4
0,0,1,5,5,5,5,5,5,5,5,5,5,5,5,5,1,0,0
2,1,1,1,1,1,5,5,5,5,5,5,5,1,1,1,1,1,2
2,1,2,2,2,1,5,4,5,5,5,4,5,1,2,2,2,1,2
2,1,2,2,2,1,5,4,1,1,1,4,5,1,2,2,2,1,2
2,1,2,2,2,1,1,1,2,2,2,1,1,1,2,2,2,1,2
2,1,1,1,1,1,0,4,1,1,1,4,0,1,1,1,1,1,2
2,2,2,2,2,2,0,4,0,0,0,4,0,2,2,2,2,2,2
endlayer

layer
0,2,0,0,0,2,0,4,0,0,0,4,0,2,0,0,0,2,0
2,1,1,6,1,1,0,4,0,0,0,4,0,1,1,6,1,1,2
0,1,5,5,5,1,1,2,6,6,6,2,1,1,5,5,5,1,0
0,6,5,5,5,1,5,4,5,5,5,4,5,1,5,5,5,6,0
0,1,5,5,5,1,5,4,5,5,5,4,5,1,5,5,5,1,0
2,1,1,1,1,5,5,5,5,5,5,5,5,5,1,1,1,1,2
0,0,1,5,5,5,5,5,5,5,5,5,5,5,5,5,1,0,0
4,4,2,4,4,5,5,5,5,5,5,5,5,5,4,4,2,4,4
0,0,6,5,5,5,5,5,5,5,5,5,5,5,5,5,6,0,0
0,0,6,5,5,5,5,5,5,5,5,5,5,5,5,5,6,0,0
0,0,6,5,5,5,5,5,5,5,5,5,5,5,5,5,6,0,0
4,4,2,4,4,5,5,5,5,5,5,5,5,5,4,4,2,4,4
0,0,1,5,5,5,5,5,5,5,5,5,5,5,5,5,1,0,0
2,1,1,1,1,5,5,5,5,5,5,5,5,5,1,1,1,1,2
0,1,5,5,5,1,5,4,5,5,5,4,5,1,5,5,5,1,0
0,6,5,5,5,1,5,4,5,5,5,4,5,1,5,5,5,6,0
0,1,5,5,5,1,1,2,6,6,6,2,1,1,5,5,5,1,0
2,1,1,6,1,1,0,4,0,0,0,4,0,1,1,6,1,1,2
0,2,0,0,0,2,0,4,0,0,0,4,0,2,0,0,0,2,0
endlayer

layer
0,2,0,0,0,2,0,0,0,0,0,0,0,2,0,0,0,2,0
2,1,1,6,1,1,0,4,0,0,0,4,0,1,1,6,1,1,2
0,1,7,7,7,1,1,2,6,6,6,2,1,1,7,7,7,1,0
0,6,7,7,7,1,5,4,5,5,5,4,5,1,8,8,7,6,0
0,1,7,7,5,5,5,5,5,5,5,5,5,5,5,7,7,1,0
2,1,1,1,5,5,5,5,5,5,5,5,5,5,5,1,1,1,2
0,0,1,5,5,5,5,5,5,5,5,5,5,5,5,7,1,0,0
0,4,2,4,5,5,5,5,5,5,5,5,5,5,5,4,2,4,0
0,0,6,5,5,5,5,5,5,5,5,5,5,5,5,5,6,0,0
0,0,6,5,5,5,5,5,5,5,5,5,5,5,5,5,6,0,0
0,0,6,5,5,5,5,5,5,5,5,5,5,5,5,5,6,0,0
0,4,2,4,5,5,5,5,5,5,5,5,5,5,5,4,2,4,0
0,0,1,5,5,5,5,5,5,5,5,5,5,5,5,5,1,0,0
2,1,1,1,5,5,5,5,5,5,5,5,5,5,5,1,1,1,2
0,1,7,7,5,5,5,5,5,5,5,5,5,5,5,7,7,1,0
0,6,7,7,7,1,5,4,5,5,5,4,5,1,7,8,7,6,0
0,1,7,7,7,1,1,2,6,6,6,2,1,1,7,7,7,1,0
2,1,1,6,1,1,0,4,0,0,0,4,0,1,1,6,1,1,2
0,2,0,0,0,2,0,0,0,0,0,0,0,2,0,0,0,2,0
endlayer

layer
0,2,0,0,0,2,0,0,0,0,0,0,0,2,0,0,0,2,0
2,1,1,6,1,1,0,4,0,0,0,4,0,1,1,6,1,1,2
0,1,5,7,7,1,1,2,6,6,6,2,1,1,7,7,7,1,0
0,6,7,7,7,1,7,4,5,5,5,4,7,1,8,8,7,6,0
0,1,7,7,5,5,5,5,5,5,5,5,5,5,5,7,7,1,0
2,1,1,1,5,5,5,5,5,5,5,5,5,5,5,1,1,1,2
0,0,1,5,5,5,5,5,5,5,5,5,5,5,5,5,1,0,0
0,4,2,4,5,5,5,5,5,5,5,5,5,5,5,4,2,4,0
0,0,6,5,5,5,5,5,5,5,5,5,5,5,5,5,6,0,0
0,0,6,5,5,5,5,5,5,5,5,5,5,5,5,5,6,0,0
0,0,6,5,5,5,5,5,5,5,5,5,5,5,5,5,6,0,0
0,4,2,4,5,5,5,5,5,5,5,5,5,5,5,4,2,4,0
0,0,1,5,5,5,5,5,5,5,5,5,5,5,5,5,1,0,0
2,1,1,1,5,5,5,5,5,5,5,5,5,5,5,1,1,1,2
0,1,7,7,5,5,5,5,5,5,5,5,5,5,5,7,7,1,0
0,6,7,7,7,1,5,4,5,5,5,4,5,1,7,8,7,6,0
0,1,5,7,7,1,1,2,6,6,6,2,1,1,7,7,5,1,0
2,1,1,6,1,1,0,4,0,0,0,4,0,1,1,6,1,1,2
0,2,0,0,0,2,0,0,0,0,0,0,0,2,0,0,0,2,0
endlayer

layer
0,2,2,2,2,2,0,0,0,0,0,0,0,2,2,2,2,2,0
2,1,1,1,1,1,0,4,0,0,0,4,0,1,1,1,1,1,2
2,1,7,7,7,1,1,2,6,6,6,2,1,1,7,7,7,1,2
2,1,7,7,7,1,5,4,5,5,5,4,5,1,8,8,7,1,2
2,1,7,7,7,1,5,5,5,5,5,5,5,1,7,7,7,1,2
2,1,1,1,1,5,5,5,5,5,5,5,5,5,1,1,1,1,2
0,0,1,5,5,5,5,5,5,5,5,5,5,5,5,5,1,0,0
0,4,2,4,5,5,5,5,5,5,5,5,5,5,5,4,2,4,0
0,0,6,5,5,5,5,5,5,5,5,5,5,5,5,5,6,0,0
0,0,6,5,5,5,5,5,5,5,5,5,5,5,5,5,6,0,0
0,0,6,5,5,5,5,5,5,5,5,5,5,5,5,5,6,0,0
0,4,2,4,5,5,5,5,5,5,5,5,5,5,5,4,2,4,0
0,0,1,5,5,5,5,5,5,5,5,5,5,5,5,5,1,0,0
2,1,1,1,1,5,5,5,5,5,5,5,5,5,1,1,1,1,2
2,1,7,7,7,1,5,5,5,5,5,5,5,1,7,7,7,1,2
2,1,7,7,7,1,5,4,5,5,5,4,5,1,7,8,7,1,2
2,1,7,7,7,1,1,2,6,6,6,2,1,1,7,7,7,1,2
2,1,1,1,1,1,0,4,0,0,0,4,0,1,1,1,1,1,2
0,2,2,2,2,2,0,0,0,0,0,0,0,2,2,2,2,2,0
endlayer

layer
0,2,0,0,0,2,0,0,0,0,0,0,0,2,0,0,0,2,0
2,1,1,1,1,1,2,4,2,2,2,4,2,1,1,1,1,1,2
0,1,5,5,5,1,1,1,1,1,1,1,1,1,5,5,5,1,0
0,1,5,7,5,1,0,4,0,0,0,4,0,1,9,8,5,1,0
0,1,5,5,5,1,0,0,0,0,0,0,0,1,5,5,5,1,0
2,1,1,1,1,1,0,0,0,0,0,0,0,1,1,1,1,1,2
0,2,1,0,0,0,0,0,0,0,0,0,0,0,0,0,1,2,0
0,4,1,4,0,0,0,0,0,0,0,0,0,0,0,4,1,4,0
0,2,1,0,0,0,0,0,0,0,0,0,0,0,0,0,1,2,0
0,2,1,0,0,0,0,0,0,0,0,0,0,0,0,0,1,2,0
0,2,1,0,0,0,0,0,0,0,0,0,0,0,0,0,1,2,0
0,4,1,4,0,0,0,0,0,0,0,0,0,0,0,4,1,4,0
0,2,1,0,0,0,0,0,0,0,0,0,0,0,0,0,1,2,0
2,1,1,1,1,1,0,0,0,0,0,0,0,1,1,1,1,1,2
0,1,5,5,5,1,0,0,0,0,0,0,0,1,5,5,5,1,0
0,1,5,7,5,1,0,4,0,0,0,4,0,1,5,8,5,1,0
0,1,5,5,5,1,1,1,1,1,1,1,1,1,5,5,5,1,0
2,1,1,1,1,1,2,4,2,2,2,4,2,1,1,1,1,1,2
0,2,0,0,0,2,0,0,0,0,0,0,0,2,0,0,0,2,0
endlayer

layer
0,0,0,0,0,0,0,0,0,0,0,0,0,0,0,0,0,0,0
0,2,0,0,0,2,0,0,0,0,0,0,0,2,0,0,0,2,0
0,0,4,4,4,2,2,4,2,2,2,4,2,2,4,4,4,0,0
0,0,4,5,4,0,0,4,0,0,0,4,0,0,4,8,4,0,0
0,0,4,4,4,0,0,4,0,0,0,4,0,0,4,4,4,0,0
0,2,2,0,0,4,0,0,0,0,0,0,0,4,0,0,2,2,0
0,0,2,0,0,0,0,0,0,0,0,0,0,0,0,0,2,0,0
0,0,4,4,4,0,0,0,0,0,0,0,0,0,4,4,4,0,0
0,0,2,0,0,0,0,0,0,0,0,0,0,0,0,0,2,0,0
0,0,2,0,0,0,0,0,0,0,0,0,0,0,0,0,2,0,0
0,0,2,0,0,0,0,0,0,0,0,0,0,0,0,0,2,0,0
0,0,4,4,4,0,0,0,0,0,0,0,0,0,4,4,4,0,0
0,0,2,0,0,0,0,0,0,0,0,0,0,0,0,0,2,0,0
0,2,2,0,0,4,0,0,0,0,0,0,0,4,0,0,2,2,0
0,0,4,4,4,0,0,4,0,0,0,4,0,0,4,4,4,0,0
0,0,4,7,4,0,0,4,0,0,0,4,0,0,4,8,4,0,0
0,0,4,4,4,2,2,4,2,2,2,4,2,2,4,4,4,0,0
0,2,0,0,0,2,0,0,0,0,0,0,0,2,0,0,0,2,0
0,0,0,0,0,0,0,0,0,0,0,0,0,0,0,0,0,0,0
endlayer

layer
0,0,0,0,0,0,0,0,0,0,0,0,0,0,0,0,0,0,0
0,2,0,0,0,2,0,0,0,0,0,0,0,2,0,0,0,2,0
0,0,1,6,1,0,0,0,0,0,0,0,0,0,1,6,1,0,0
0,0,6,5,1,2,2,4,2,2,2,4,2,2,1,8,6,0,0
0,0,1,1,1,0,0,4,0,0,0,4,0,0,1,1,1,0,0
0,2,0,2,0,4,0,0,0,0,0,0,0,4,0,2,0,2,0
0,0,0,2,0,0,0,0,0,0,0,0,0,0,0,2,0,0,0
0,0,0,4,4,0,0,0,0,0,0,0,0,0,4,4,0,0,0
0,0,0,2,0,0,0,0,0,0,0,0,0,0,0,2,0,0,0
0,0,0,2,0,0,0,0,0,0,0,0,0,0,0,2,0,0,0
0,0,0,2,0,0,0,0,0,0,0,0,0,0,0,2,0,0,0
0,0,0,4,4,0,0,0,0,0,0,0,0,0,4,4,0,0,0
0,0,0,2,0,0,0,0,0,0,0,0,0,0,0,2,0,0,0
0,2,0,2,0,4,0,0,0,0,0,0,0,4,0,2,0,2,0
0,0,1,1,1,0,0,4,0,0,0,4,0,0,1,1,1,0,0
0,0,6,7,1,2,2,4,2,2,2,4,2,2,1,8,6,0,0
0,0,1,6,1,0,0,0,0,0,0,0,0,0,1,6,1,0,0
0,2,0,0,0,2,0,0,0,0,0,0,0,2,0,0,0,2,0
0,0,0,0,0,0,0,0,0,0,0,0,0,0,0,0,0,0,0
endlayer

layer
0,0,0,0,0,0,0,0,0,0,0,0,0,0,0,0,0,0,0
0,2,0,0,0,2,0,0,0,0,0,0,0,2,0,0,0,2,0
0,0,1,6,1,0,0,0,0,0,0,0,0,0,1,6,1,0,0
0,0,6,5,1,0,0,0,0,0,0,0,0,0,1,8,6,0,0
0,0,1,1,1,2,2,4,2,2,2,4,2,2,1,1,1,0,0
0,2,0,0,2,2,4,4,4,4,4,4,4,2,2,0,0,2,0
0,0,0,0,2,4,4,4,4,4,4,4,4,4,2,0,0,0,0
0,0,0,0,4,4,4,4,4,4,4,4,4,4,4,0,0,0,0
0,0,0,0,2,4,4,4,0,0,0,4,4,4,2,0,0,0,0
0,0,0,0,2,4,4,4,0,0,0,4,4,4,2,0,0,0,0
0,0,0,0,2,4,4,4,0,0,0,4,4,4,2,0,0,0,0
0,0,0,0,4,4,4,4,4,4,4,4,4,4,4,0,0,0,0
0,0,0,0,2,4,4,4,4,4,4,4,4,4,2,0,0,0,0
0,2,0,0,2,2,4,4,4,4,4,4,4,2,2,0,0,2,0
0,0,1,1,1,2,2,4,2,2,2,4,2,2,1,1,1,0,0
0,0,6,7,1,0,0,0,0,0,0,0,0,0,1,8,6,0,0
0,0,1,6,1,0,0,0,0,0,0,0,0,0,1,6,1,0,0
0,2,0,0,0,2,0,0,0,0,0,0,0,2,0,0,0,2,0
0,0,0,0,0,0,0,0,0,0,0,0,0,0,0,0,0,0,0
endlayer

layer
0,0,0,0,0,0,0,0,0,0,0,0,0,0,0,0,0,0,0
0,2,0,0,0,2,0,0,0,0,0,0,0,2,0,0,0,2,0
0,0,1,6,1,0,0,0,0,0,0,0,0,0,1,6,1,0,0
0,0,6,5,1,0,0,0,0,0,0,0,0,0,1,8,6,0,0
0,0,1,1,1,0,0,0,0,0,0,0,0,0,1,1,1,0,0
0,2,0,0,0,2,0,0,0,0,0,0,0,2,0,0,0,2,0
0,0,0,0,0,0,1,1,1,1,1,1,1,0,0,0,0,0,0
0,0,0,0,0,0,1,0,0,0,0,0,1,0,0,0,0,0,0
0,0,0,0,0,0,1,0,0,0,0,0,1,0,0,0,0,0,0
0,0,0,0,0,0,1,0,0,0,0,0,1,0,0,0,0,0,0
0,0,0,0,0,0,1,0,0,0,0,0,1,0,0,0,0,0,0
0,0,0,0,0,0,1,0,0,0,0,0,1,0,0,0,0,0,0
0,0,0,0,0,0,1,1,1,1,1,1,1,0,0,0,0,0,0
0,2,0,0,0,2,0,0,0,0,0,0,0,2,0,0,0,2,0
0,0,1,1,1,0,0,0,0,0,0,0,0,0,1,1,1,0,0
0,0,6,7,1,0,0,0,0,0,0,0,0,0,1,8,6,0,0
0,0,1,6,1,0,0,0,0,0,0,0,0,0,1,6,1,0,0
0,2,0,0,0,2,0,0,0,0,0,0,0,2,0,0,0,2,0
0,0,0,0,0,0,0,0,0,0,0,0,0,0,0,0,0,0,0
endlayer

layer
0,0,0,0,0,0,0,0,0,0,0,0,0,0,0,0,0,0,0
0,2,0,0,0,2,0,0,0,0,0,0,0,2,0,0,0,2,0
0,0,1,1,1,0,0,0,0,0,0,0,0,0,1,1,1,0,0
0,0,1,7,1,0,0,0,0,0,0,0,0,0,1,8,1,0,0
0,0,1,1,1,0,0,0,0,0,0,0,0,0,1,1,1,0,0
0,2,0,0,0,2,0,0,0,0,0,0,0,2,0,0,0,2,0
0,0,0,0,0,0,1,0,0,1,0,0,1,0,0,0,0,0,0
0,0,0,0,0,0,0,0,0,0,0,0,0,0,0,0,0,0,0
0,0,0,0,0,0,0,0,0,0,0,0,0,0,0,0,0,0,0
0,0,0,0,0,0,1,0,0,0,0,0,1,0,0,0,0,0,0
0,0,0,0,0,0,0,0,0,0,0,0,0,0,0,0,0,0,0
0,0,0,0,0,0,0,0,0,0,0,0,0,0,0,0,0,0,0
0,0,0,0,0,0,1,0,0,1,0,0,1,0,0,0,0,0,0
0,2,0,0,0,2,0,0,0,0,0,0,0,2,0,0,0,2,0
0,0,1,1,1,0,0,0,0,0,0,0,0,0,1,1,1,0,0
0,0,1,7,1,0,0,0,0,0,0,0,0,0,1,8,1,0,0
0,0,1,1,1,0,0,0,0,0,0,0,0,0,1,1,1,0,0
0,2,0,0,0,2,0,0,0,0,0,0,0,2,0,0,0,2,0
0,0,0,0,0,0,0,0,0,0,0,0,0,0,0,0,0,0,0
endlayer

layer
0,0,0,0,0,0,0,0,0,0,0,0,0,0,0,0,0,0,0
0,2,0,0,0,2,0,0,0,0,0,0,0,2,0,0,0,2,0
0,0,1,6,1,0,0,0,0,0,0,0,0,0,1,6,1,0,0
0,0,6,5,6,0,0,0,0,0,0,0,0,0,6,8,6,0,0
0,0,1,6,1,0,0,0,0,0,0,0,0,0,1,6,1,0,0
0,2,0,0,0,2,0,0,0,0,0,0,0,2,0,0,0,2,0
0,0,0,0,0,0,1,0,0,1,0,0,1,0,0,0,0,0,0
0,0,0,0,0,0,0,0,0,0,0,0,0,0,0,0,0,0,0
0,0,0,0,0,0,0,0,0,0,0,0,0,0,0,0,0,0,0
0,0,0,0,0,0,1,0,0,0,0,0,1,0,0,0,0,0,0
0,0,0,0,0,0,0,0,0,0,0,0,0,0,0,0,0,0,0
0,0,0,0,0,0,0,0,0,0,0,0,0,0,0,0,0,0,0
0,0,0,0,0,0,1,0,0,1,0,0,1,0,0,0,0,0,0
0,2,0,0,0,2,0,0,0,0,0,0,0,2,0,0,0,2,0
0,0,1,6,1,0,0,0,0,0,0,0,0,0,1,6,1,0,0
0,0,6,7,6,0,0,0,0,0,0,0,0,0,6,8,6,0,0
0,0,1,6,1,0,0,0,0,0,0,0,0,0,1,6,1,0,0
0,2,0,0,0,2,0,0,0,0,0,0,0,2,0,0,0,2,0
0,0,0,0,0,0,0,0,0,0,0,0,0,0,0,0,0,0,0
endlayer

layer
0,0,0,0,0,0,0,0,0,0,0,0,0,0,0,0,0,0,0
0,2,0,0,0,2,0,0,0,0,0,0,0,2,0,0,0,2,0
0,0,1,6,1,0,0,0,0,0,0,0,0,0,1,6,1,0,0
0,0,6,5,6,0,0,0,0,0,0,0,0,0,6,8,6,0,0
0,0,1,6,1,0,0,0,0,0,0,0,0,0,1,6,1,0,0
0,2,0,0,0,2,0,0,0,0,0,0,0,2,0,0,0,2,0
0,0,0,0,0,0,1,0,0,1,0,0,1,0,0,0,0,0,0
0,0,0,0,0,0,0,0,0,0,0,0,0,0,0,0,0,0,0
0,0,0,0,0,0,0,0,0,0,0,0,0,0,0,0,0,0,0
0,0,0,0,0,0,1,0,0,0,0,0,1,0,0,0,0,0,0
0,0,0,0,0,0,0,0,0,0,0,0,0,0,0,0,0,0,0
0,0,0,0,0,0,0,0,0,0,0,0,0,0,0,0,0,0,0
0,0,0,0,0,0,1,0,0,1,0,0,1,0,0,0,0,0,0
0,2,0,0,0,2,0,0,0,0,0,0,0,2,0,0,0,2,0
0,0,1,6,1,0,0,0,0,0,0,0,0,0,1,6,1,0,0
0,0,6,7,6,0,0,0,0,0,0,0,0,0,6,8,6,0,0
0,0,1,6,1,0,0,0,0,0,0,0,0,0,1,6,1,0,0
0,2,0,0,0,2,0,0,0,0,0,0,0,2,0,0,0,2,0
0,0,0,0,0,0,0,0,0,0,0,0,0,0,0,0,0,0,0
endlayer

layer
0,0,0,0,0,0,0,0,0,0,0,0,0,0,0,0,0,0,0
0,2,0,0,0,2,0,0,0,0,0,0,0,2,0,0,0,2,0
0,0,1,6,1,0,0,0,0,0,0,0,0,0,1,6,1,0,0
0,0,6,5,6,0,0,0,0,0,0,0,0,0,6,8,6,0,0
0,0,1,6,1,2,2,2,2,2,2,2,2,2,1,6,1,0,0
0,2,0,0,2,2,0,0,0,0,0,0,0,2,2,0,0,2,0
0,0,0,0,2,0,1,1,1,1,1,1,1,0,2,0,0,0,0
0,0,0,0,2,0,1,0,0,0,0,0,1,0,2,0,0,0,0
0,0,0,0,2,0,1,0,0,0,0,0,1,0,2,0,0,0,0
0,0,0,0,2,0,1,0,0,0,0,0,1,0,2,0,0,0,0
0,0,0,0,2,0,1,0,0,0,0,0,1,0,2,0,0,0,0
0,0,0,0,2,0,1,0,0,0,0,0,1,0,2,0,0,0,0
0,0,0,0,2,0,1,1,1,1,1,1,1,0,2,0,0,0,0
0,2,0,0,2,2,0,0,0,0,0,0,0,2,2,0,0,2,0
0,0,1,6,1,2,2,2,2,2,2,2,2,2,1,6,1,0,0
0,0,6,7,6,0,0,0,0,0,0,0,0,0,6,8,6,0,0
0,0,1,6,1,0,0,0,0,0,0,0,0,0,1,6,1,0,0
0,2,0,0,0,2,0,0,0,0,0,0,0,2,0,0,0,2,0
0,0,0,0,0,0,0,0,0,0,0,0,0,0,0,0,0,0,0
endlayer

layer
0,0,0,0,0,0,0,0,0,0,0,0,0,0,0,0,0,0,0
0,2,0,0,0,2,0,0,0,0,0,0,0,2,0,0,0,2,0
0,0,4,4,4,0,0,0,0,0,0,0,0,0,4,4,4,0,0
0,0,4,5,4,0,0,0,0,0,0,0,0,0,4,8,4,0,0
0,0,4,4,4,0,0,0,0,0,0,0,0,0,4,4,4,0,0
0,2,0,0,0,2,2,2,2,2,2,2,2,2,0,0,0,2,0
0,0,0,0,0,2,1,1,1,1,1,1,1,2,0,0,0,0,0
0,0,0,0,0,2,1,0,0,0,0,0,1,2,0,0,0,0,0
0,0,0,0,0,2,1,0,0,0,0,0,1,2,0,0,0,0,0
0,0,0,0,0,2,1,0,0,0,0,0,1,2,0,0,0,0,0
0,0,0,0,0,2,1,0,0,0,0,0,1,2,0,0,0,0,0
0,0,0,0,0,2,1,0,0,0,0,0,1,2,0,0,0,0,0
0,0,0,0,0,2,1,1,1,1,1,1,1,2,0,0,0,0,0
0,2,0,0,0,2,2,2,2,2,2,2,2,2,0,0,0,2,0
0,0,4,4,4,0,0,0,0,0,0,0,0,0,4,4,4,0,0
0,0,4,7,4,0,0,0,0,0,0,0,0,0,4,8,4,0,0
0,0,4,4,4,0,0,0,0,0,0,0,0,0,4,4,4,0,0
0,2,0,0,0,2,0,0,0,0,0,0,0,2,0,0,0,2,0
0,0,0,0,0,0,0,0,0,0,0,0,0,0,0,0,0,0,0
endlayer

layer
2,2,2,2,2,2,2,0,0,0,0,0,2,2,2,2,2,2,2
2,2,2,2,2,2,2,0,0,0,0,0,2,2,2,2,2,2,2
2,2,5,5,5,2,2,0,0,0,0,0,2,2,5,5,5,2,2
2,2,5,5,10,2,2,0,0,0,0,0,2,2,5,9,10,2,2
2,2,5,5,5,2,2,0,0,0,0,0,2,2,5,5,5,2,2
2,2,2,2,2,2,2,0,0,0,0,0,2,2,2,2,2,2,2
2,2,2,2,2,2,2,2,2,2,2,2,2,2,2,2,2,2,2
0,0,0,0,0,0,2,2,2,2,2,2,2,0,0,0,0,0,0
0,0,0,0,0,0,2,2,11,11,11,2,2,0,0,0,0,0,0
0,0,0,0,0,0,2,2,11,11,11,2,2,0,0,0,0,0,0
0,0,0,0,0,0,2,2,11,11,11,2,2,0,0,0,0,0,0
0,0,0,0,0,0,2,2,2,2,2,2,2,0,0,0,0,0,0
2,2,2,2,2,2,2,2,2,2,2,2,2,2,2,2,2,2,2
2,2,2,2,2,2,2,0,0,0,0,0,2,2,2,2,2,2,2
2,2,5,5,5,2,2,0,0,0,0,0,2,2,5,5,5,2,2
2,2,5,5,10,2,2,0,0,0,0,0,2,2,5,9,10,2,2
2,2,5,5,5,2,2,0,0,0,0,0,2,2,5,5,5,2,2
2,2,2,2,2,2,2,0,0,0,0,0,2,2,2,2,2,2,2
2,2,2,2,2,2,2,0,0,0,0,0,2,2,2,2,2,2,2
endlayer

layer
0,0,0,0,0,0,0,0,0,0,0,0,0,0,0,0,0,0,0
0,2,2,2,2,2,0,0,0,0,0,0,0,2,2,2,2,2,0
0,2,11,11,11,2,0,0,0,0,0,0,0,2,11,11,11,2,0
0,2,11,11,11,2,0,0,0,0,0,0,0,2,11,11,11,2,0
0,2,11,11,11,2,0,0,0,0,0,0,0,2,11,11,11,2,0
0,2,2,2,2,2,0,0,0,0,0,0,0,2,2,2,2,2,0
0,0,0,0,0,0,0,0,0,0,0,0,0,0,0,0,0,0,0
0,0,0,0,0,0,0,2,2,2,2,2,0,0,0,0,0,0,0
0,0,0,0,0,0,0,2,2,2,2,2,0,0,0,0,0,0,0
0,0,0,0,0,0,0,2,2,3,2,2,0,0,0,0,0,0,0
0,0,0,0,0,0,0,2,2,2,2,2,0,0,0,0,0,0,0
0,0,0,0,0,0,0,2,2,2,2,2,0,0,0,0,0,0,0
0,0,0,0,0,0,0,0,0,0,0,0,0,0,0,0,0,0,0
0,2,2,2,2,2,0,0,0,0,0,0,0,2,2,2,2,2,0
0,2,11,11,11,2,0,0,0,0,0,0,0,2,11,11,11,2,0
0,2,11,11,11,2,0,0,0,0,0,0,0,2,11,11,11,2,0
0,2,11,11,11,2,0,0,0,0,0,0,0,2,11,11,11,2,0
0,2,2,2,2,2,0,0,0,0,0,0,0,2,2,2,2,2,0
0,0,0,0,0,0,0,0,0,0,0,0,0,0,0,0,0,0,0
endlayer

layer
0,0,0,0,0,0,0,0,0,0,0,0,0,0,0,0,0,0,0
0,0,0,0,0,0,0,0,0,0,0,0,0,0,0,0,0,0,0
0,0,2,2,2,0,0,0,0,0,0,0,0,0,2,2,2,0,0
0,0,2,3,2,0,0,0,0,0,0,0,0,0,2,3,2,0,0
0,0,2,2,2,0,0,0,0,0,0,0,0,0,2,2,2,0,0
0,0,0,0,0,0,0,0,0,0,0,0,0,0,0,0,0,0,0
0,0,0,0,0,0,0,0,0,0,0,0,0,0,0,0,0,0,0
0,0,0,0,0,0,0,0,0,0,0,0,0,0,0,0,0,0,0
0,0,0,0,0,0,0,0,2,2,2,0,0,0,0,0,0,0,0
0,0,0,0,0,0,0,0,2,12,2,0,0,0,0,0,0,0,0
0,0,0,0,0,0,0,0,2,2,2,0,0,0,0,0,0,0,0
0,0,0,0,0,0,0,0,0,0,0,0,0,0,0,0,0,0,0
0,0,0,0,0,0,0,0,0,0,0,0,0,0,0,0,0,0,0
0,0,0,0,0,0,0,0,0,0,0,0,0,0,0,0,0,0,0
0,0,2,2,2,0,0,0,0,0,0,0,0,0,2,2,2,0,0
0,0,2,3,2,0,0,0,0,0,0,0,0,0,2,3,2,0,0
0,0,2,2,2,0,0,0,0,0,0,0,0,0,2,2,2,0,0
0,0,0,0,0,0,0,0,0,0,0,0,0,0,0,0,0,0,0
0,0,0,0,0,0,0,0,0,0,0,0,0,0,0,0,0,0,0
endlayer

layer
0,0,0,0,0,0,0,0,0,0,0,0,0,0,0,0,0,0,0
0,0,0,0,0,0,0,0,0,0,0,0,0,0,0,0,0,0,0
0,0,0,0,0,0,0,0,0,0,0,0,0,0,0,0,0,0,0
0,0,0,2,0,0,0,0,0,0,0,0,0,0,0,2,0,0,0
0,0,0,0,0,0,0,0,0,0,0,0,0,0,0,0,0,0,0
0,0,0,0,0,0,0,0,0,0,0,0,0,0,0,0,0,0,0
0,0,0,0,0,0,0,0,0,0,0,0,0,0,0,0,0,0,0
0,0,0,0,0,0,0,0,0,0,0,0,0,0,0,0,0,0,0
0,0,0,0,0,0,0,0,0,0,0,0,0,0,0,0,0,0,0
0,0,0,0,0,0,0,0,0,2,0,0,0,0,0,0,0,0,0
0,0,0,0,0,0,0,0,0,0,0,0,0,0,0,0,0,0,0
0,0,0,0,0,0,0,0,0,0,0,0,0,0,0,0,0,0,0
0,0,0,0,0,0,0,0,0,0,0,0,0,0,0,0,0,0,0
0,0,0,0,0,0,0,0,0,0,0,0,0,0,0,0,0,0,0
0,0,0,0,0,0,0,0,0,0,0,0,0,0,0,0,0,0,0
0,0,0,2,0,0,0,0,0,0,0,0,0,0,0,2,0,0,0
0,0,0,0,0,0,0,0,0,0,0,0,0,0,0,0,0,0,0
0,0,0,0,0,0,0,0,0,0,0,0,0,0,0,0,0,0,0
0,0,0,0,0,0,0,0,0,0,0,0,0,0,0,0,0,0,0
endlayer

