
# Created by Ruins mod version 16.7 Ingame Parser
# authoring Player: ST753M

weight=1
embed_into_distance=6
acceptable_target_blocks=gravel,sand
unacceptable_target_blocks=flowing_water,water,flowing_lava,lava
dimensions=16,17,17
allowable_overhang=6
max_leveling=0
leveling_buffer=0
preserve_water=1
preserve_lava=0

biomesToSpawnIn=deep_ocean,coral_reef

=0,100,air
rule1=0,100,preserveBlock
rule2=0,100,minecraft:stone-0
rule3=0,100,biomesoplenty:grass-7
rule4=0,100,minecraft:dirt-0
rule5=0,100,biomesoplenty:flower_0-3
rule6=0,100,air
rule7=0,100,IInventory;minecraft:chest;biomesoplenty:flower_0#1#3#1+biomesoplenty:terrarium#1#10#2+biomesoplenty:sapling_0#3#3#5+biomesoplenty:jar_filled#1#1#10+biomesoplenty:flower_0#2#3#15+biomesoplenty:ambrosia#1#0#16+biomesoplenty:flower_0#1#3#18+biomesoplenty:sapling_0#4#3#21+biomesoplenty:terrarium#1#10#23-2,air
rule8=0,100,air
rule9=0,100,air
rule10=0,100,air
rule11=0,100,air
rule12=0,100,biomesoplenty:log_1-5
rule13=0,100,biomesoplenty:leaves_3-6
rule14=0,100,biomesoplenty:double_plant-0
rule15=0,100,minecraft:red_flower-2
rule16=0,100,biomesoplenty:flower_0-6
rule17=0,100,biomesoplenty:leaves_3-14
rule18=0,100,MobSpawner:biomesoplenty:biomesoplenty.pixie,air
rule19=0,100,minecraft:stained_glass-3
^0,100,minecraft:stained_glass-0
^0,100,minecraft:stained_glass-9
^0,100,minecraft:stained_glass-3
^0,100,minecraft:stained_glass-11
^0,100,minecraft:stained_glass-8
^0,100,minecraft:stained_glass-7
rule20=0,100,biomesoplenty:double_plant-8
rule21=0,100,biomesoplenty:leaves_0-15
rule22=0,100,biomesoplenty:leaves_0-7

layer
1,1,1,1,1,1,2,2,2,2,2,1,1,1,1,1,1
1,1,1,1,2,2,2,2,2,2,2,2,2,1,1,1,1
1,1,1,2,2,4,3,3,3,3,2,3,2,2,1,1,1
1,1,2,2,3,3,3,3,3,3,3,3,2,2,2,1,1
1,2,2,2,2,3,3,3,3,3,2,2,2,2,2,2,1
1,2,2,2,2,2,3,3,2,2,2,2,2,2,2,2,1
2,2,2,2,2,2,2,3,2,2,2,2,2,2,2,2,2
2,2,2,2,2,3,3,3,3,2,2,2,2,2,2,2,2
2,2,2,2,2,3,3,3,4,2,2,2,2,2,2,2,2
2,2,2,2,2,2,2,2,2,2,2,2,2,2,2,2,2
2,2,2,2,2,2,2,2,2,2,2,2,2,2,2,2,2
1,2,2,2,2,2,2,2,2,2,2,2,2,2,2,2,1
1,2,2,2,2,2,2,2,2,2,2,2,2,2,2,2,1
1,1,2,2,2,2,2,2,2,2,2,2,2,2,2,1,1
1,1,1,2,2,2,2,2,2,2,2,2,2,2,1,1,1
1,1,1,1,2,2,2,2,2,2,2,2,2,1,1,1,1
1,1,1,1,1,1,2,2,2,2,2,1,1,1,1,1,1
endlayer

layer
1,1,1,1,1,1,2,2,2,2,2,1,1,1,1,1,1
1,1,1,1,2,2,4,3,3,4,2,2,2,1,1,1,1
1,1,1,2,4,3,0,0,0,0,3,0,2,2,1,1,1
1,1,2,0,0,0,0,0,5,0,0,0,2,2,2,1,1
1,2,3,0,0,0,0,0,0,0,2,3,2,2,2,2,1
1,2,2,0,0,0,0,0,4,3,2,2,2,2,2,2,1
2,2,2,2,0,0,0,0,4,2,4,2,2,2,2,2,2
2,2,2,2,4,0,5,0,0,4,2,2,2,2,2,2,2
2,2,2,2,4,0,0,0,3,2,2,2,2,2,2,2,2
2,2,2,2,2,4,4,3,3,3,2,2,2,2,2,2,2
2,2,2,2,2,2,2,2,3,2,2,2,2,2,2,2,2
1,2,2,2,2,2,2,2,2,2,2,2,2,2,2,2,1
1,2,2,2,2,2,2,2,2,2,2,2,2,2,2,2,1
1,1,2,2,2,2,2,2,2,2,2,2,2,2,2,1,1
1,1,1,2,2,2,2,2,2,2,2,2,2,2,1,1,1
1,1,1,1,2,2,2,2,2,2,2,2,2,1,1,1,1
1,1,1,1,1,1,2,2,2,2,2,1,1,1,1,1,1
endlayer

layer
1,1,1,1,1,1,2,2,4,2,2,1,1,1,1,1,1
1,1,1,1,2,4,3,0,6,3,3,4,2,1,1,1,1
1,1,1,4,3,0,6,0,0,0,0,0,2,2,1,1,1
1,1,4,0,0,0,0,0,0,0,0,0,2,2,2,1,1
1,2,7,0,0,0,0,0,0,0,2,0,2,2,2,2,1
1,2,2,0,0,0,0,0,4,0,2,2,2,2,2,2,1
2,2,2,2,0,0,0,0,4,3,4,2,2,2,2,2,2
2,2,2,4,4,0,0,0,0,4,2,2,2,2,2,2,2
2,2,2,2,4,9,8,0,0,4,2,2,2,2,2,2,2
2,2,2,2,2,4,4,8,0,0,3,2,2,2,2,2,2
2,2,2,2,2,2,2,2,0,4,2,2,2,2,2,2,2
1,2,2,2,2,2,2,2,2,2,2,2,2,2,2,2,1
1,2,2,2,2,2,2,2,2,2,2,2,2,2,2,2,1
1,1,2,2,2,2,2,2,2,2,2,2,2,2,2,1,1
1,1,1,2,2,2,2,2,2,2,2,2,2,2,1,1,1
1,1,1,1,2,2,2,2,2,2,2,2,2,1,1,1,1
1,1,1,1,1,1,2,2,2,2,2,1,1,1,1,1,1
endlayer

layer
1,1,1,1,1,1,2,2,4,4,4,1,1,1,1,1,1
1,1,1,1,4,4,0,0,0,0,0,4,2,1,1,1,1
1,1,1,4,6,6,0,0,0,0,0,6,2,2,1,1,1
1,1,4,0,0,0,0,0,0,0,0,8,3,2,2,1,1
1,2,9,0,0,0,0,0,0,0,2,4,2,2,2,2,1
1,2,2,9,0,0,0,0,4,0,4,2,2,2,2,2,1
2,2,2,4,8,0,0,10,3,0,4,2,2,2,2,2,2
2,2,2,2,4,0,8,0,0,4,2,2,2,2,2,2,2
2,2,2,2,2,2,4,0,10,4,2,2,2,2,2,2,2
2,2,2,2,2,2,2,2,10,2,0,2,2,2,2,2,2
2,2,2,2,2,2,2,2,2,2,2,2,2,2,2,2,2
1,2,2,2,2,2,2,2,2,2,2,2,2,2,2,2,1
1,2,2,2,2,2,2,2,2,2,2,2,2,2,2,2,1
1,1,2,2,2,2,2,2,2,2,2,2,2,2,2,1,1
1,1,1,2,2,2,2,2,2,2,2,2,2,2,1,1,1
1,1,1,1,2,2,2,2,2,2,2,2,2,1,1,1,1
1,1,1,1,1,1,2,2,2,2,2,1,1,1,1,1,1
endlayer

layer
1,1,1,1,1,1,2,2,2,4,2,1,1,1,1,1,1
1,1,1,1,4,2,9,4,4,10,2,4,2,1,1,1,1
1,1,1,4,0,0,0,6,0,0,6,4,2,2,1,1,1
1,1,4,11,4,0,0,0,0,0,4,4,0,2,2,1,1
1,4,4,9,8,0,0,0,8,10,4,4,2,2,2,2,1
1,2,2,2,4,9,0,0,3,0,4,2,2,2,2,2,1
2,2,2,2,4,4,9,4,0,0,4,2,2,2,2,2,2
2,2,2,2,4,2,2,2,4,4,2,2,2,2,2,2,2
2,2,2,2,2,2,2,2,2,2,2,2,2,2,2,2,2
2,2,2,2,2,2,2,2,2,2,2,2,2,2,2,2,2
2,2,2,2,2,2,2,2,2,2,2,2,2,2,2,2,2
1,2,2,2,2,2,2,2,2,2,2,2,2,2,2,2,1
1,2,2,2,2,2,2,2,2,2,2,2,2,2,2,2,1
1,1,2,2,2,2,2,2,2,2,2,2,2,2,2,1,1
1,1,1,2,2,2,2,2,2,2,2,2,2,2,1,1,1
1,1,1,1,2,2,2,2,2,2,2,2,2,1,1,1,1
1,1,1,1,1,1,2,2,2,2,2,1,1,1,1,1,1
endlayer

layer
1,1,1,1,1,1,2,2,2,2,2,1,1,1,1,1,1
1,1,1,1,2,2,3,3,3,4,3,2,2,1,1,1,1
1,1,1,2,3,3,3,3,3,3,3,3,3,2,1,1,1
1,1,2,3,3,3,3,3,3,3,3,3,4,3,2,1,1
1,2,3,3,3,3,4,3,3,3,3,3,3,3,3,2,1
1,2,3,3,3,3,3,3,0,3,3,3,3,3,3,2,1
2,3,3,3,3,3,3,3,0,6,3,3,3,3,3,3,2
2,3,3,4,3,3,3,3,12,4,3,3,3,4,3,3,2
2,3,3,3,3,3,3,3,3,3,3,3,3,3,3,3,2
2,3,3,3,3,3,3,3,3,3,3,3,3,3,3,3,2
2,3,3,3,3,4,3,3,3,3,3,3,3,3,3,4,2
1,2,3,3,3,3,3,3,3,3,3,3,3,3,3,2,1
1,2,3,4,3,3,3,3,3,3,4,3,3,3,3,2,1
1,1,2,3,3,3,3,3,4,3,3,3,3,3,2,1,1
1,1,1,2,3,3,3,3,3,3,3,3,3,2,1,1,1
1,1,1,1,2,2,3,3,3,3,3,2,2,1,1,1,1
1,1,1,1,1,1,2,2,2,2,2,1,1,1,1,1,1
endlayer

layer
1,1,1,1,1,1,2,2,2,2,2,1,1,1,1,1,1
1,1,1,1,2,2,0,14,13,12,13,2,2,1,1,1,1
1,1,1,2,0,0,0,0,13,13,13,13,13,2,1,1,1
1,1,2,0,0,16,0,0,15,0,0,13,12,13,2,1,1
1,2,15,0,0,15,12,0,0,16,0,13,13,13,14,2,1
1,2,14,0,5,0,0,0,13,0,5,0,16,0,15,2,1
2,14,13,13,13,0,0,17,13,12,13,0,0,0,0,0,2
2,0,13,12,13,16,0,17,12,18,13,0,0,12,0,16,2
2,0,13,13,13,0,0,13,13,13,13,0,0,0,15,0,2
2,0,16,0,0,0,0,15,0,0,16,0,0,0,17,17,2
2,14,0,0,0,12,0,0,0,0,0,15,0,5,17,12,2
1,2,13,13,13,0,5,0,0,0,0,0,0,0,17,2,1
1,2,13,12,13,0,0,13,13,13,12,0,0,0,0,2,1
1,1,2,13,13,16,0,13,12,13,0,0,0,16,2,1,1
1,1,1,2,15,0,0,13,13,13,5,15,0,2,1,1,1
1,1,1,1,2,2,15,0,16,14,0,2,2,1,1,1,1
1,1,1,1,1,1,2,2,2,2,2,1,1,1,1,1,1
endlayer

layer
1,1,1,1,1,1,19,19,19,19,19,1,1,1,1,1,1
1,1,1,1,19,19,0,20,13,13,13,19,19,1,1,1,1
1,1,1,19,0,0,0,0,0,13,0,0,13,19,1,1,1
1,1,19,0,0,0,0,0,0,0,0,13,13,13,19,1,1
1,19,0,0,0,0,12,0,0,0,0,0,13,0,20,19,1
1,19,20,0,0,0,0,0,0,0,0,0,0,0,0,19,1
19,20,0,13,0,0,0,0,17,12,0,0,0,0,0,0,19
19,0,13,13,13,0,0,17,17,17,13,0,0,12,0,0,19
19,0,0,13,0,0,0,0,13,13,0,0,0,0,0,0,19
19,0,0,0,0,0,0,0,0,0,0,0,0,0,0,13,19
19,20,0,0,0,12,0,0,0,0,0,0,0,0,13,13,19
1,19,0,13,0,0,0,0,0,0,0,0,0,0,0,19,1
1,19,13,13,13,0,0,0,13,0,12,0,0,0,0,19,1
1,1,19,13,0,0,0,13,13,13,0,0,0,0,19,1,1
1,1,1,19,0,0,0,0,13,0,0,0,0,19,1,1,1
1,1,1,1,19,19,0,0,0,20,0,19,19,1,1,1,1
1,1,1,1,1,1,19,19,19,19,19,1,1,1,1,1,1
endlayer

layer
1,1,1,1,1,1,19,19,19,19,19,1,1,1,1,1,1
1,1,1,1,19,19,0,0,0,0,0,19,19,1,1,1,1
1,1,1,19,0,21,21,21,0,0,0,0,0,19,1,1,1
1,1,19,0,22,21,21,21,21,0,0,0,0,0,19,1,1
1,19,0,0,22,21,12,21,21,0,0,0,0,0,0,19,1
1,19,0,0,22,21,21,21,21,0,0,0,21,21,21,19,1
19,0,0,0,0,21,21,21,0,12,0,21,21,21,21,21,19
19,0,0,0,0,0,0,0,0,0,0,21,21,12,21,21,19
19,0,0,0,0,0,0,0,0,0,0,21,21,21,21,21,19
19,0,0,0,0,0,0,0,0,0,0,0,21,21,21,0,19
19,0,0,0,0,12,0,0,0,22,22,21,0,0,0,0,19
1,19,0,0,0,0,0,0,22,22,22,21,21,0,0,19,1
1,19,0,0,0,0,0,0,22,22,12,21,21,0,0,19,1
1,1,19,0,0,0,0,0,22,22,22,21,21,0,19,1,1
1,1,1,19,0,0,0,0,0,22,22,22,0,19,1,1,1
1,1,1,1,19,19,0,0,0,0,0,19,19,1,1,1,1
1,1,1,1,1,1,19,19,19,19,19,1,1,1,1,1,1
endlayer

layer
1,1,1,1,1,1,1,19,19,19,1,1,1,1,1,1,1
1,1,1,1,19,19,19,0,0,0,19,19,19,1,1,1,1
1,1,1,19,0,21,21,21,0,0,0,0,0,19,1,1,1
1,1,19,0,22,21,21,21,21,0,0,0,0,0,19,1,1
1,19,0,0,22,21,12,21,21,0,0,0,0,0,0,19,1
1,19,0,0,22,21,21,21,21,0,0,0,21,21,21,19,1
1,19,0,0,0,21,21,21,0,12,0,21,21,21,21,19,1
19,0,0,0,0,0,0,0,0,0,0,21,21,12,21,21,19
19,0,0,0,22,22,22,0,0,0,0,21,21,21,21,21,19
19,0,0,21,21,21,21,21,0,0,0,0,21,21,21,0,19
1,19,0,21,21,12,21,21,0,22,22,21,0,0,0,19,1
1,19,0,21,21,21,21,21,22,22,22,21,21,0,0,19,1
1,19,0,0,21,21,21,0,22,22,12,21,21,0,0,19,1
1,1,19,0,0,0,0,0,22,22,22,21,21,0,19,1,1
1,1,1,19,0,0,0,0,0,22,22,22,0,19,1,1,1
1,1,1,1,19,19,19,0,0,0,19,19,19,1,1,1,1
1,1,1,1,1,1,1,19,19,19,1,1,1,1,1,1,1
endlayer

layer
1,1,1,1,1,1,1,1,1,1,1,1,1,1,1,1,1
1,1,1,1,1,19,19,19,19,19,19,19,1,1,1,1,1
1,1,1,19,19,0,0,0,0,0,0,0,19,19,1,1,1
1,1,19,0,0,21,21,21,0,0,0,0,0,0,19,1,1
1,1,19,0,0,21,21,21,22,22,22,0,0,0,19,1,1
1,19,0,0,0,21,21,21,22,22,22,21,0,0,0,19,1
1,19,0,0,0,0,0,22,22,12,22,21,21,21,21,19,1
1,19,0,0,0,0,0,22,22,22,22,21,21,21,21,19,1
1,19,0,0,22,22,22,0,22,22,22,0,21,21,21,19,1
1,19,0,21,21,21,21,21,0,0,0,0,0,0,0,19,1
1,19,0,21,21,12,21,21,0,0,0,0,0,0,0,19,1
1,19,0,21,21,21,21,21,0,22,22,21,0,0,0,19,1
1,1,19,0,21,21,21,0,0,22,22,21,0,0,19,1,1
1,1,19,0,0,0,0,0,0,22,22,21,0,0,19,1,1
1,1,1,19,19,0,0,0,0,0,0,0,19,19,1,1,1
1,1,1,1,1,19,19,19,19,19,19,19,1,1,1,1,1
1,1,1,1,1,1,1,1,1,1,1,1,1,1,1,1,1
endlayer

layer
1,1,1,1,1,1,1,1,1,1,1,1,1,1,1,1,1
1,1,1,1,1,1,19,19,19,19,19,1,1,1,1,1,1
1,1,1,1,19,19,0,0,0,0,0,19,19,1,1,1,1
1,1,1,19,0,0,21,0,0,0,0,0,0,19,1,1,1
1,1,19,0,0,21,21,21,22,22,22,0,0,0,19,1,1
1,1,19,0,0,0,21,22,22,22,22,22,0,0,19,1,1
1,19,0,0,0,0,0,22,22,12,22,22,0,22,0,19,1
1,19,0,0,0,0,0,22,22,22,22,22,22,22,22,19,1
1,19,0,0,0,0,0,0,22,22,22,0,0,22,0,19,1
1,19,0,0,22,22,22,0,0,0,0,0,0,0,0,19,1
1,19,0,0,22,22,22,0,0,0,0,0,0,0,0,19,1
1,1,19,0,22,22,22,0,0,0,22,0,0,0,19,1,1
1,1,19,0,0,0,0,0,0,22,22,22,0,0,19,1,1
1,1,1,19,0,0,0,0,0,0,22,0,0,19,1,1,1
1,1,1,1,19,19,0,0,0,0,0,19,19,1,1,1,1
1,1,1,1,1,1,19,19,19,19,19,1,1,1,1,1,1
1,1,1,1,1,1,1,1,1,1,1,1,1,1,1,1,1
endlayer

layer
1,1,1,1,1,1,1,1,1,1,1,1,1,1,1,1,1
1,1,1,1,1,1,1,1,1,1,1,1,1,1,1,1,1
1,1,1,1,1,19,19,19,19,19,19,19,1,1,1,1,1
1,1,1,1,19,0,0,0,0,0,0,0,19,1,1,1,1
1,1,1,19,0,0,0,0,0,0,0,0,0,19,1,1,1
1,1,19,0,0,0,0,0,22,22,22,0,0,0,19,1,1
1,1,19,0,0,0,0,0,22,22,22,0,0,0,19,1,1
1,1,19,0,0,0,0,0,22,22,22,0,0,0,19,1,1
1,1,19,0,0,0,0,0,0,0,0,0,0,0,19,1,1
1,1,19,0,0,22,0,0,0,0,0,0,0,0,19,1,1
1,1,19,0,22,22,22,0,0,0,0,0,0,0,19,1,1
1,1,19,0,0,22,0,0,0,0,0,0,0,0,19,1,1
1,1,1,19,0,0,0,0,0,0,0,0,0,19,1,1,1
1,1,1,1,19,0,0,0,0,0,0,0,19,1,1,1,1
1,1,1,1,1,19,19,19,19,19,19,19,1,1,1,1,1
1,1,1,1,1,1,1,1,1,1,1,1,1,1,1,1,1
1,1,1,1,1,1,1,1,1,1,1,1,1,1,1,1,1
endlayer

layer
1,1,1,1,1,1,1,1,1,1,1,1,1,1,1,1,1
1,1,1,1,1,1,1,1,1,1,1,1,1,1,1,1,1
1,1,1,1,1,1,1,1,1,1,1,1,1,1,1,1,1
1,1,1,1,1,19,19,19,19,19,19,19,1,1,1,1,1
1,1,1,1,19,19,0,0,0,0,0,19,19,1,1,1,1
1,1,1,19,19,0,0,0,0,22,0,0,19,19,1,1,1
1,1,1,19,0,0,0,0,22,22,22,0,0,19,1,1,1
1,1,1,19,0,0,0,0,0,22,0,0,0,19,1,1,1
1,1,1,19,0,0,0,0,0,0,0,0,0,19,1,1,1
1,1,1,19,0,0,0,0,0,0,0,0,0,19,1,1,1
1,1,1,19,0,0,0,0,0,0,0,0,0,19,1,1,1
1,1,1,19,19,0,0,0,0,0,0,0,19,19,1,1,1
1,1,1,1,19,19,0,0,0,0,0,19,19,1,1,1,1
1,1,1,1,1,19,19,19,19,19,19,19,1,1,1,1,1
1,1,1,1,1,1,1,1,1,1,1,1,1,1,1,1,1
1,1,1,1,1,1,1,1,1,1,1,1,1,1,1,1,1
1,1,1,1,1,1,1,1,1,1,1,1,1,1,1,1,1
endlayer

layer
1,1,1,1,1,1,1,1,1,1,1,1,1,1,1,1,1
1,1,1,1,1,1,1,1,1,1,1,1,1,1,1,1,1
1,1,1,1,1,1,1,1,1,1,1,1,1,1,1,1,1
1,1,1,1,1,1,1,1,1,1,1,1,1,1,1,1,1
1,1,1,1,1,1,19,19,19,19,19,1,1,1,1,1,1
1,1,1,1,1,19,19,19,19,19,19,19,1,1,1,1,1
1,1,1,1,19,19,19,0,0,0,19,19,19,1,1,1,1
1,1,1,1,19,19,0,0,0,0,0,19,19,1,1,1,1
1,1,1,1,19,19,0,0,0,0,0,19,19,1,1,1,1
1,1,1,1,19,19,0,0,0,0,0,19,19,1,1,1,1
1,1,1,1,19,19,19,0,0,0,19,19,19,1,1,1,1
1,1,1,1,1,19,19,19,19,19,19,19,1,1,1,1,1
1,1,1,1,1,1,19,19,19,19,19,1,1,1,1,1,1
1,1,1,1,1,1,1,1,1,1,1,1,1,1,1,1,1
1,1,1,1,1,1,1,1,1,1,1,1,1,1,1,1,1
1,1,1,1,1,1,1,1,1,1,1,1,1,1,1,1,1
1,1,1,1,1,1,1,1,1,1,1,1,1,1,1,1,1
endlayer

layer
1,1,1,1,1,1,1,1,1,1,1,1,1,1,1,1,1
1,1,1,1,1,1,1,1,1,1,1,1,1,1,1,1,1
1,1,1,1,1,1,1,1,1,1,1,1,1,1,1,1,1
1,1,1,1,1,1,1,1,1,1,1,1,1,1,1,1,1
1,1,1,1,1,1,1,1,1,1,1,1,1,1,1,1,1
1,1,1,1,1,1,1,1,1,1,1,1,1,1,1,1,1
1,1,1,1,1,1,1,19,19,19,1,1,1,1,1,1,1
1,1,1,1,1,1,19,19,19,19,19,1,1,1,1,1,1
1,1,1,1,1,1,19,19,19,19,19,1,1,1,1,1,1
1,1,1,1,1,1,19,19,19,19,19,1,1,1,1,1,1
1,1,1,1,1,1,1,19,19,19,1,1,1,1,1,1,1
1,1,1,1,1,1,1,1,1,1,1,1,1,1,1,1,1
1,1,1,1,1,1,1,1,1,1,1,1,1,1,1,1,1
1,1,1,1,1,1,1,1,1,1,1,1,1,1,1,1,1
1,1,1,1,1,1,1,1,1,1,1,1,1,1,1,1,1
1,1,1,1,1,1,1,1,1,1,1,1,1,1,1,1,1
1,1,1,1,1,1,1,1,1,1,1,1,1,1,1,1,1
endlayer

