
# Created by Ruins mod version 17.0 Ingame Parser
# authoring Player: ST753M

weight=1
embed_into_distance=7
acceptable_target_blocks=gravel,clay
unacceptable_target_blocks=flowing_water,water,flowing_lava,lava
dimensions=24,31,31
allowable_overhang=15
max_leveling=0
leveling_buffer=0
preserve_water=1
preserve_lava=0
uniqueMinDistance=1000
spawnMinDistance=1000

biomesToSpawnIn=deep_ocean

=0,100,air
rule1=0,100,preserveBlock
rule2=0,100,minecraft:prismarine-1
rule3=0,100,minecraft:prismarine-0
rule4=0,100,iceandfire:silverpile-2
rule5=0,100,iceandfire:silverpile-0
rule6=0,100,iceandfire:silverpile-1
rule7=0,100,iceandfire:silverpile-3
rule8=0,100,minecraft:quartz_stairs-0
rule9=0,100,minecraft:quartz_stairs-3
rule10=0,100,minecraft:quartz_stairs-2
rule11=0,100,minecraft:quartz_block-2
rule12=0,100,minecraft:water-0
rule13=0,100,minecraft:quartz_stairs-1
rule14=0,100,iceandfire:silverpile-4
rule15=0,100,minecraft:stone_slab-7
rule16=0,100,minecraft:water-8
rule17=0,100,MobSpawner:creeper,MobSpawner:spider,MobSpawner:skeleton
rule18=0,100,minecraft:grass-0
rule19=0,100,minecraft:dirt-0
rule20=2,100,WallSign:null:null:null:null-5
rule21=2,100,WallSign:null:null:null:null-3
rule22=2,100,WallSign:null:null:null:null-2
rule23=2,100,WallSign:null:null:null:null-4
rule24=0,100,minecraft:stained_glass-9
rule25=0,100,minecraft:water-9

rule26=0,100,air

rule27=0,100,minecraft:stone_slab-15

rule28=0,100,CommandBlock:RUINSTRIGGER /summon villager ~ ~1 ~:@-1,CommandBlock:RUINSTRIGGER /summon llama ~ ~1 ~:@-1,CommandBlock:RUINSTRIGGER /summon villager ~ ~1 ~:@-1,CommandBlock:RUINSTRIGGER /summon villager ~ ~1 ~:@-1,CommandBlock:RUINSTRIGGER /summon rabbit ~ ~1 ~:@-1,CommandBlock:RUINSTRIGGER /summon ocelot ~ ~1 ~:@-1,CommandBlock:RUINSTRIGGER /summon chicken ~ ~1 ~:@-1,CommandBlock:RUINSTRIGGER /summon cow ~ ~1 ~:@-1,CommandBlock:RUINSTRIGGER /summon llama ~ ~1 ~:@-1,CommandBlock:RUINSTRIGGER /summon pig ~ ~1 ~:@-1

rule29=0,100,minecraft:sea_lantern-0
rule30=0,100,CommandBlock:RUINSTRIGGER /summon iceandfire:gorgon ~ ~1 ~ {PersistenceRequired:1}:@-1
rule31=0,100,minecraft:double_stone_slab-7
rule32=0,100,minecraft:quartz_stairs-7
rule33=0,100,minecraft:quartz_stairs-6
rule34=0,100,minecraft:quartz_stairs-5
rule35=0,100,minecraft:water-1
rule36=0,100,minecraft:quartz_stairs-4

layer
1,1,1,1,1,1,1,1,1,1,1,1,2,2,2,2,2,2,2,1,1,1,1,1,1,1,1,1,1,1,1
1,1,1,1,1,1,1,1,1,2,2,2,2,2,2,2,2,2,2,2,2,2,1,1,1,1,1,1,1,1,1
1,1,1,1,1,1,1,2,2,2,2,2,2,2,2,3,2,2,2,2,2,2,2,2,1,1,1,1,1,1,1
1,1,1,1,1,1,2,2,2,2,2,2,2,2,2,2,2,2,2,2,2,2,2,2,2,1,1,1,1,1,1
1,1,1,1,1,2,2,2,2,2,2,2,2,2,2,2,2,2,2,2,2,2,2,2,2,2,1,1,1,1,1
1,1,1,1,2,2,2,2,2,2,3,2,2,3,2,2,2,3,2,2,3,2,2,2,2,2,2,1,1,1,1
1,1,1,2,2,2,2,2,2,2,2,2,3,3,2,2,2,3,3,2,2,2,2,2,2,2,2,2,1,1,1
1,1,2,2,2,2,2,2,2,2,2,3,2,2,3,2,3,2,2,3,2,2,2,2,2,2,2,2,2,1,1
1,1,2,2,2,2,2,2,2,2,2,2,2,2,2,3,2,2,2,2,2,2,2,2,2,2,2,2,2,1,1
1,2,2,2,2,2,2,2,2,2,2,2,2,2,2,3,2,2,2,2,2,2,2,2,2,2,2,2,2,2,1
1,2,2,2,2,3,2,2,2,2,2,2,2,2,2,3,2,2,2,2,2,2,2,2,2,3,2,2,2,2,1
1,2,2,2,2,2,2,3,2,2,2,2,2,2,2,2,2,2,2,2,2,2,2,3,2,2,2,2,2,2,1
2,2,2,2,2,2,3,2,2,2,2,2,2,2,2,2,2,2,2,2,2,2,2,2,3,2,2,2,2,2,2
2,2,2,2,2,3,3,2,2,2,2,2,2,2,3,3,3,2,2,2,2,2,2,2,3,3,2,2,2,2,2
2,2,2,2,2,2,2,3,2,2,2,2,2,3,3,3,3,3,2,2,2,2,2,3,2,2,2,2,2,2,2
2,2,3,2,2,2,2,2,3,3,3,2,2,3,3,2,3,3,2,2,3,3,3,2,2,2,2,2,3,2,2
2,2,2,2,2,2,2,3,2,2,2,2,2,3,3,3,3,3,2,2,2,2,2,3,2,2,2,2,2,2,2
2,2,2,2,2,3,3,2,2,2,2,2,2,2,3,3,3,2,2,2,2,2,2,2,3,3,2,2,2,2,2
2,2,2,2,2,2,3,2,2,2,2,2,2,2,2,2,2,2,2,2,2,2,2,2,3,2,2,2,2,2,2
1,2,2,2,2,2,2,3,2,2,2,2,2,2,2,2,2,2,2,2,2,2,2,3,2,2,2,2,2,2,1
1,2,2,2,2,3,2,2,2,2,2,2,2,2,2,3,2,2,2,2,2,2,2,2,2,3,2,2,2,2,1
1,2,2,2,2,2,2,2,2,2,2,2,2,2,2,3,2,2,2,2,2,2,2,2,2,2,2,2,2,2,1
1,1,2,2,2,2,2,2,2,2,2,2,2,2,2,3,2,2,2,2,2,2,2,2,2,2,2,2,2,1,1
1,1,2,2,2,2,2,2,2,2,2,3,2,2,3,2,3,2,2,3,2,2,2,2,2,2,2,2,2,1,1
1,1,1,2,2,2,2,2,2,2,2,2,3,3,2,2,2,3,3,2,2,2,2,2,2,2,2,2,1,1,1
1,1,1,1,2,2,2,2,2,2,3,2,2,3,2,2,2,3,2,2,3,2,2,2,2,2,2,1,1,1,1
1,1,1,1,1,2,2,2,2,2,2,2,2,2,2,2,2,2,2,2,2,2,2,2,2,2,1,1,1,1,1
1,1,1,1,1,1,2,2,2,2,2,2,2,2,2,2,2,2,2,2,2,2,2,2,2,1,1,1,1,1,1
1,1,1,1,1,1,1,2,2,2,2,2,2,2,2,2,2,2,2,2,2,2,2,2,1,1,1,1,1,1,1
1,1,1,1,1,1,1,1,1,2,2,2,2,2,2,2,2,2,2,2,2,2,1,1,1,1,1,1,1,1,1
1,1,1,1,1,1,1,1,1,1,1,1,2,2,2,2,2,2,2,1,1,1,1,1,1,1,1,1,1,1,1
endlayer

layer
1,1,1,1,1,1,1,1,1,1,1,1,2,2,2,2,2,2,2,1,1,1,1,1,1,1,1,1,1,1,1
1,1,1,1,1,1,1,1,1,2,2,2,0,6,5,6,5,0,4,2,2,2,1,1,1,1,1,1,1,1,1
1,1,1,1,1,1,1,2,2,0,0,6,5,2,6,5,0,2,5,5,0,5,2,2,1,1,1,1,1,1,1
1,1,1,1,1,1,2,4,5,0,2,5,5,6,5,0,0,0,5,5,2,6,6,4,2,1,1,1,1,1,1
1,1,1,1,1,2,6,5,6,4,6,5,5,5,5,0,0,0,5,6,5,6,5,0,0,2,1,1,1,1,1
1,1,1,1,2,0,0,0,0,5,5,5,7,5,0,2,0,0,6,5,6,4,6,0,0,0,2,1,1,1,1
1,1,1,2,6,0,2,2,2,5,7,6,4,0,0,0,0,0,0,5,6,5,2,2,2,0,0,2,1,1,1
1,1,2,6,5,6,2,2,2,5,5,6,5,5,5,0,0,0,0,0,0,0,2,2,2,5,7,4,2,1,1
1,1,2,6,4,5,2,2,2,5,6,5,5,5,0,0,0,0,0,0,0,0,2,2,2,5,6,5,2,1,1
1,2,0,6,5,5,6,0,5,2,0,5,5,2,0,0,0,2,0,0,0,2,6,4,6,7,5,0,0,2,1
1,2,0,2,5,6,6,5,0,0,2,5,0,0,0,0,0,0,0,0,2,0,6,6,5,5,0,2,5,2,1
1,2,4,5,6,6,5,0,0,0,0,0,0,9,8,8,8,8,0,0,5,6,5,6,4,5,5,5,0,2,1
2,0,0,4,6,5,0,0,0,0,0,0,9,8,11,11,11,10,8,0,0,0,0,5,6,5,5,6,4,0,2
2,0,2,5,6,6,0,0,0,2,0,9,8,11,12,12,12,11,10,8,0,2,0,5,5,7,5,4,2,0,2
2,5,0,5,0,0,0,0,0,0,0,9,11,12,12,12,12,12,11,10,0,0,0,0,4,4,5,5,4,6,2
2,0,0,0,0,2,0,0,0,0,0,9,11,12,12,11,12,12,11,10,0,0,0,0,6,2,0,6,5,5,2
2,7,0,0,0,0,0,0,0,0,0,9,11,12,12,12,12,12,11,10,0,0,0,0,0,0,0,0,5,0,2
2,5,2,0,0,5,0,0,0,2,0,9,13,11,12,12,12,11,13,10,0,2,0,0,0,0,0,0,2,0,2
2,0,0,5,5,5,5,0,0,0,0,0,9,13,11,11,11,13,10,0,0,0,0,0,0,0,0,0,4,0,2
1,2,6,0,5,6,5,6,0,0,0,0,0,9,13,13,13,10,0,0,0,0,0,0,6,5,0,5,6,2,1
1,2,5,2,5,4,5,6,5,6,2,0,0,0,0,0,0,0,0,0,2,0,0,0,5,4,6,2,0,2,1
1,2,0,0,6,5,7,5,4,2,0,0,0,2,0,0,0,2,0,0,5,2,0,0,5,6,6,5,0,2,1
1,1,2,6,5,6,2,2,2,0,0,0,0,0,0,0,0,0,0,0,5,5,2,2,2,4,6,5,2,1,1
1,1,2,6,5,5,2,2,2,5,0,5,0,0,0,0,0,0,0,0,6,6,2,2,2,5,6,4,2,1,1
1,1,1,2,5,6,2,2,2,6,6,6,0,0,0,0,0,0,0,0,5,4,2,2,2,0,4,2,1,1,1
1,1,1,1,2,0,0,5,4,7,4,5,6,0,0,2,0,0,0,6,6,6,6,0,0,0,2,1,1,1,1
1,1,1,1,1,2,6,4,6,5,0,5,0,0,0,0,0,0,6,5,6,6,6,14,0,2,1,1,1,1,1
1,1,1,1,1,1,2,14,5,0,2,0,0,0,0,0,5,5,5,4,2,0,6,7,2,1,1,1,1,1,1
1,1,1,1,1,1,1,2,2,0,0,0,0,2,0,5,5,2,6,4,0,0,2,2,1,1,1,1,1,1,1
1,1,1,1,1,1,1,1,1,2,2,2,0,0,6,6,6,0,6,2,2,2,1,1,1,1,1,1,1,1,1
1,1,1,1,1,1,1,1,1,1,1,1,2,2,2,2,2,2,2,1,1,1,1,1,1,1,1,1,1,1,1
endlayer

layer
1,1,1,1,1,1,1,1,1,1,1,1,2,2,2,2,2,2,2,1,1,1,1,1,1,1,1,1,1,1,1
1,1,1,1,1,1,1,1,1,2,2,2,0,0,0,0,0,0,0,2,2,2,1,1,1,1,1,1,1,1,1
1,1,1,1,1,1,1,2,2,0,0,0,0,2,0,0,0,2,0,0,0,0,2,2,1,1,1,1,1,1,1
1,1,1,1,1,1,2,0,0,0,2,0,0,0,0,0,0,0,0,0,2,0,0,0,2,1,1,1,1,1,1
1,1,1,1,1,2,0,0,0,0,0,0,0,0,0,0,0,0,0,0,0,0,0,0,0,2,1,1,1,1,1
1,1,1,1,2,0,0,0,0,0,0,0,0,0,0,2,0,0,0,0,0,0,0,0,0,0,2,1,1,1,1
1,1,1,2,0,0,2,2,2,0,0,0,0,0,0,0,0,0,0,0,0,0,2,2,2,0,0,2,1,1,1
1,1,2,0,0,0,2,2,2,0,0,0,0,0,0,0,0,0,0,0,0,0,2,2,2,0,0,0,2,1,1
1,1,2,0,0,0,2,2,2,0,0,0,0,0,0,0,0,0,0,0,0,0,2,2,2,0,0,0,2,1,1
1,2,0,0,0,0,0,0,0,2,0,0,0,2,0,0,0,2,0,0,0,2,0,0,0,0,0,0,0,2,1
1,2,0,2,0,0,0,0,0,0,2,0,0,0,0,0,0,0,0,0,2,0,0,0,0,0,0,2,0,2,1
1,2,0,0,0,0,0,0,0,0,0,0,0,0,0,0,0,0,0,0,0,0,0,0,0,0,0,0,0,2,1
2,0,0,0,0,0,0,0,0,0,0,0,0,0,15,15,15,0,0,0,0,0,0,0,0,0,0,0,0,0,2
2,0,2,0,0,0,0,0,0,2,0,0,0,15,0,0,0,15,0,0,0,2,0,0,0,0,0,0,2,0,2
2,0,0,0,0,0,0,0,0,0,0,0,15,0,16,16,16,0,15,0,0,0,0,0,0,0,0,0,0,0,2
2,0,0,0,0,2,0,0,0,0,0,0,15,0,16,11,16,0,15,0,0,0,0,0,0,2,0,0,0,0,2
2,0,0,0,0,0,0,0,0,0,0,0,15,0,16,16,16,0,15,0,0,0,0,0,0,0,0,0,0,0,2
2,0,2,0,0,0,0,0,0,2,0,0,0,15,0,0,0,15,0,0,0,2,0,0,0,0,0,0,2,0,2
2,0,0,0,0,0,0,0,0,0,0,0,0,0,15,15,15,0,0,0,0,0,0,0,0,0,0,0,0,0,2
1,2,0,0,0,0,0,0,0,0,0,0,0,0,0,0,0,0,0,0,0,0,0,0,0,0,0,0,0,2,1
1,2,0,2,0,0,0,0,0,0,2,0,0,0,0,0,0,0,0,0,2,0,0,0,0,0,0,2,0,2,1
1,2,0,0,0,0,0,0,0,2,0,0,0,2,0,0,0,2,0,0,0,2,0,0,0,0,0,0,0,2,1
1,1,2,0,0,0,2,2,2,0,0,0,0,0,0,0,0,0,0,0,0,0,2,2,2,0,0,0,2,1,1
1,1,2,0,0,0,2,2,2,0,0,0,0,0,0,0,0,0,0,0,0,0,2,2,2,0,0,0,2,1,1
1,1,1,2,0,0,2,2,2,0,0,0,0,0,0,0,0,0,0,0,0,0,2,2,2,0,0,2,1,1,1
1,1,1,1,2,0,0,0,0,0,0,0,0,0,0,2,0,0,0,0,0,0,0,0,0,0,2,1,1,1,1
1,1,1,1,1,2,0,0,0,0,0,0,0,0,0,0,0,0,0,0,0,0,0,0,0,2,1,1,1,1,1
1,1,1,1,1,1,2,0,0,0,2,0,0,0,0,0,0,0,0,0,2,0,0,0,2,1,1,1,1,1,1
1,1,1,1,1,1,1,2,2,0,0,0,0,2,0,0,0,2,0,0,0,0,2,2,1,1,1,1,1,1,1
1,1,1,1,1,1,1,1,1,2,2,2,0,0,0,0,0,0,0,2,2,2,1,1,1,1,1,1,1,1,1
1,1,1,1,1,1,1,1,1,1,1,1,2,2,2,2,2,2,2,1,1,1,1,1,1,1,1,1,1,1,1
endlayer

layer
1,1,1,1,1,1,1,1,1,1,1,1,3,3,3,3,3,3,3,1,1,1,1,1,1,1,1,1,1,1,1
1,1,1,1,1,1,1,1,1,3,3,3,0,0,0,0,0,0,0,3,3,3,1,1,1,1,1,1,1,1,1
1,1,1,1,1,1,1,3,3,0,0,0,0,3,0,0,0,3,0,0,0,0,3,3,1,1,1,1,1,1,1
1,1,1,1,1,1,3,0,0,0,3,0,0,0,0,0,0,0,0,0,3,0,0,0,3,1,1,1,1,1,1
1,1,1,1,1,3,0,0,0,0,0,0,0,0,0,0,0,0,0,0,0,0,0,0,0,3,1,1,1,1,1
1,1,1,1,3,0,0,0,0,0,0,0,0,0,0,3,0,0,0,0,0,0,0,0,0,0,3,1,1,1,1
1,1,1,3,0,0,3,3,3,0,0,0,0,0,0,0,0,0,0,0,0,0,3,3,3,0,0,3,1,1,1
1,1,3,0,0,0,3,17,3,0,0,0,0,0,0,0,0,0,0,0,0,0,3,3,3,0,0,0,3,1,1
1,1,3,0,0,0,3,3,3,0,0,0,0,0,0,0,0,0,0,0,0,0,3,3,3,0,0,0,3,1,1
1,3,0,0,0,0,0,0,0,3,0,0,0,3,0,0,0,3,0,0,0,3,0,0,0,0,0,0,0,3,1
1,3,0,3,0,0,0,0,0,0,3,0,0,0,0,0,0,0,0,0,3,0,0,0,0,0,0,3,0,3,1
1,3,0,0,0,0,0,0,0,0,0,0,0,0,0,0,0,0,0,0,0,0,0,0,0,0,0,0,0,3,1
3,0,0,0,0,0,0,0,0,0,0,0,0,0,0,0,0,0,0,0,0,0,0,0,0,0,0,0,0,0,3
3,0,3,0,0,0,0,0,0,3,0,0,0,0,0,0,0,0,0,0,0,3,0,0,0,0,0,0,3,0,3
3,0,0,0,0,0,0,0,0,0,0,0,0,0,16,16,16,0,0,0,0,0,0,0,0,0,0,0,0,0,3
3,0,0,0,0,3,0,0,0,0,0,0,0,0,16,11,16,0,0,0,0,0,0,0,0,2,0,0,0,0,3
3,0,0,0,0,0,0,0,0,0,0,0,0,0,16,16,16,0,0,0,0,0,0,0,0,0,0,0,0,0,3
3,0,3,0,0,0,0,0,0,3,0,0,0,0,0,0,0,0,0,0,0,3,0,0,0,0,0,0,3,0,3
3,0,0,0,0,0,0,0,0,0,0,0,0,0,0,0,0,0,0,0,0,0,0,0,0,0,0,0,0,0,3
1,3,0,0,0,0,0,0,0,0,0,0,0,0,0,0,0,0,0,0,0,0,0,0,0,0,0,0,0,3,1
1,3,0,3,0,0,0,0,0,0,3,0,0,0,0,0,0,0,0,0,3,0,0,0,0,0,0,3,0,3,1
1,3,0,0,0,0,0,0,0,3,0,0,0,3,0,0,0,3,0,0,0,3,0,0,0,0,0,0,0,3,1
1,1,3,0,0,0,3,3,3,0,0,0,0,0,0,0,0,0,0,0,0,0,3,3,3,0,0,0,3,1,1
1,1,3,0,0,0,3,3,3,0,0,0,0,0,0,0,0,0,0,0,0,0,3,17,3,0,0,0,3,1,1
1,1,1,3,0,0,3,3,3,0,0,0,0,0,0,0,0,0,0,0,0,0,3,3,3,0,0,3,1,1,1
1,1,1,1,3,0,0,0,0,0,0,0,0,0,0,3,0,0,0,0,0,0,0,0,0,0,3,1,1,1,1
1,1,1,1,1,3,0,0,0,0,0,0,0,0,0,0,0,0,0,0,0,0,0,0,0,3,1,1,1,1,1
1,1,1,1,1,1,3,0,0,0,3,0,0,0,0,0,0,0,0,0,3,0,0,0,3,1,1,1,1,1,1
1,1,1,1,1,1,1,3,3,0,0,0,0,3,0,0,0,3,0,0,0,0,3,3,1,1,1,1,1,1,1
1,1,1,1,1,1,1,1,1,3,3,3,0,0,0,0,0,0,0,3,3,3,1,1,1,1,1,1,1,1,1
1,1,1,1,1,1,1,1,1,1,1,1,3,3,3,3,3,3,3,1,1,1,1,1,1,1,1,1,1,1,1
endlayer

layer
1,1,1,1,1,1,1,1,1,1,1,1,2,2,2,2,2,2,2,1,1,1,1,1,1,1,1,1,1,1,1
1,1,1,1,1,1,1,1,1,2,2,2,0,0,0,0,0,0,0,2,2,2,1,1,1,1,1,1,1,1,1
1,1,1,1,1,1,1,2,2,0,0,0,0,2,0,0,0,2,0,0,0,0,2,2,1,1,1,1,1,1,1
1,1,1,1,1,1,2,0,0,0,2,0,0,0,0,0,0,0,0,0,2,0,0,0,2,1,1,1,1,1,1
1,1,1,1,1,2,0,0,0,0,0,0,0,0,0,0,0,0,0,0,0,0,0,0,0,2,1,1,1,1,1
1,1,1,1,2,0,0,0,0,0,0,0,0,0,0,2,0,0,0,0,0,0,0,0,0,0,2,1,1,1,1
1,1,1,2,0,0,2,2,2,0,0,0,0,0,0,0,0,0,0,0,0,0,2,2,2,0,0,2,1,1,1
1,1,2,0,0,0,2,2,2,0,0,0,0,0,0,0,0,0,0,0,0,0,2,2,2,0,0,0,2,1,1
1,1,2,0,0,0,2,2,2,0,0,0,0,0,0,0,0,0,0,0,0,0,2,2,2,0,0,0,2,1,1
1,2,0,0,0,0,0,0,0,2,0,0,0,2,0,0,0,2,0,0,0,2,0,0,0,0,0,0,0,2,1
1,2,0,2,0,0,0,0,0,0,2,0,0,0,0,0,0,0,0,0,2,0,0,0,0,0,0,2,0,2,1
1,2,0,0,0,0,0,0,0,0,0,0,0,0,0,0,0,0,0,0,0,0,0,0,0,0,0,0,0,2,1
2,0,0,0,0,0,0,0,0,0,0,0,0,0,0,0,0,0,0,0,0,0,0,0,0,0,0,0,0,0,2
2,0,2,0,0,0,0,0,0,2,0,0,0,0,0,0,0,0,0,0,0,2,0,0,0,0,0,0,2,0,2
2,0,0,0,0,0,0,0,0,0,0,0,0,0,16,16,16,0,0,0,0,0,0,0,0,0,0,0,0,0,2
2,0,0,0,0,2,0,0,0,0,0,0,0,0,16,11,16,0,0,0,0,0,0,0,0,2,0,0,0,0,2
2,0,0,0,0,0,0,0,0,0,0,0,0,0,16,16,16,0,0,0,0,0,0,0,0,0,0,0,0,0,2
2,0,2,0,0,0,0,0,0,2,0,0,0,0,0,0,0,0,0,0,0,2,0,0,0,0,0,0,2,0,2
2,0,0,0,0,0,0,0,0,0,0,0,0,0,0,0,0,0,0,0,0,0,0,0,0,0,0,0,0,0,2
1,2,0,0,0,0,0,0,0,0,0,0,0,0,0,0,0,0,0,0,0,0,0,0,0,0,0,0,0,2,1
1,2,0,2,0,0,0,0,0,0,2,0,0,0,0,0,0,0,0,0,2,0,0,0,0,0,0,2,0,2,1
1,2,0,0,0,0,0,0,0,2,0,0,0,2,0,0,0,2,0,0,0,2,0,0,0,0,0,0,0,2,1
1,1,2,0,0,0,2,2,2,0,0,0,0,0,0,0,0,0,0,0,0,0,2,2,2,0,0,0,2,1,1
1,1,2,0,0,0,2,2,2,0,0,0,0,0,0,0,0,0,0,0,0,0,2,2,2,0,0,0,2,1,1
1,1,1,2,0,0,2,2,2,0,0,0,0,0,0,0,0,0,0,0,0,0,2,2,2,0,0,2,1,1,1
1,1,1,1,2,0,0,0,0,0,0,0,0,0,0,2,0,0,0,0,0,0,0,0,0,0,2,1,1,1,1
1,1,1,1,1,2,0,0,0,0,0,0,0,0,0,0,0,0,0,0,0,0,0,0,0,2,1,1,1,1,1
1,1,1,1,1,1,2,0,0,0,2,0,0,0,0,0,0,0,0,0,2,0,0,0,2,1,1,1,1,1,1
1,1,1,1,1,1,1,2,2,0,0,0,0,2,0,0,0,2,0,0,0,0,2,2,1,1,1,1,1,1,1
1,1,1,1,1,1,1,1,1,2,2,2,0,0,0,0,0,0,0,2,2,2,1,1,1,1,1,1,1,1,1
1,1,1,1,1,1,1,1,1,1,1,1,2,2,2,2,2,2,2,1,1,1,1,1,1,1,1,1,1,1,1
endlayer

layer
1,1,1,1,1,1,1,1,1,1,1,1,2,2,2,2,2,2,2,1,1,1,1,1,1,1,1,1,1,1,1
1,1,1,1,1,1,1,1,1,2,2,2,2,2,2,2,2,2,2,2,2,2,1,1,1,1,1,1,1,1,1
1,1,1,1,1,1,1,2,2,2,2,2,2,2,2,2,2,2,2,2,2,2,2,2,1,1,1,1,1,1,1
1,1,1,1,1,1,2,2,2,2,2,2,2,2,2,2,2,2,2,2,2,2,2,2,2,1,1,1,1,1,1
1,1,1,1,1,2,2,2,2,2,2,2,2,2,2,2,2,2,2,2,2,2,2,2,2,2,1,1,1,1,1
1,1,1,1,2,2,2,2,2,2,2,2,2,2,2,2,2,2,2,2,2,2,2,2,2,2,2,1,1,1,1
1,1,1,2,2,2,2,2,2,2,2,2,2,2,2,2,2,2,2,2,2,2,2,2,2,2,2,2,1,1,1
1,1,2,2,2,2,2,2,2,2,2,2,2,2,2,2,2,2,2,2,2,2,2,2,2,2,2,2,2,1,1
1,1,2,2,2,2,2,2,2,2,2,2,2,2,2,2,2,2,2,2,2,2,2,2,2,2,2,2,2,1,1
1,2,2,2,2,2,2,2,2,2,2,2,2,2,2,2,2,2,2,2,2,2,2,2,2,2,2,2,2,2,1
1,2,2,2,2,2,2,2,2,2,2,2,2,2,2,2,2,2,2,2,2,2,2,2,2,2,2,2,2,2,1
1,2,2,2,2,2,2,2,2,2,2,2,2,2,2,2,2,2,2,2,2,2,2,2,2,2,2,2,2,2,1
2,2,2,2,2,2,2,2,2,2,2,2,2,2,2,2,2,2,2,2,2,2,2,2,2,2,2,2,2,2,2
2,2,2,2,2,2,2,2,2,2,2,2,2,2,0,0,0,2,2,2,2,2,2,2,2,2,2,2,2,2,2
2,2,2,2,2,2,2,2,2,2,2,2,2,0,16,16,16,0,2,2,2,2,2,2,2,2,2,2,2,2,2
2,2,2,2,2,2,2,2,2,2,2,2,2,0,16,11,16,0,2,2,2,2,2,2,2,2,2,2,2,2,2
2,2,2,2,2,2,2,2,2,2,2,2,2,0,16,16,16,0,2,2,2,2,2,2,2,2,2,2,2,2,2
2,2,2,2,2,2,2,2,2,2,2,2,2,2,0,0,0,2,2,2,2,2,2,2,2,2,2,2,2,2,2
2,2,2,2,2,2,2,2,2,2,2,2,2,2,2,2,2,2,2,2,2,2,2,2,2,2,2,2,2,2,2
1,2,2,2,2,2,2,2,2,2,2,2,2,2,2,2,2,2,2,2,2,2,2,2,2,2,2,2,2,2,1
1,2,2,2,2,2,2,2,2,2,2,2,2,2,2,2,2,2,2,2,2,2,2,2,2,2,2,2,2,2,1
1,2,2,2,2,2,2,2,2,2,2,2,2,2,2,2,2,2,2,2,2,2,2,2,2,2,2,2,2,2,1
1,1,2,2,2,2,2,2,2,2,2,2,2,2,2,2,2,2,2,2,2,2,2,2,2,2,2,2,2,1,1
1,1,2,2,2,2,2,2,2,2,2,2,2,2,2,2,2,2,2,2,2,2,2,2,2,2,2,2,2,1,1
1,1,1,2,2,2,2,2,2,2,2,2,2,2,2,2,2,2,2,2,2,2,2,2,2,2,2,2,1,1,1
1,1,1,1,2,2,2,2,2,2,2,2,2,2,2,2,2,2,2,2,2,2,2,2,2,2,2,1,1,1,1
1,1,1,1,1,2,2,2,2,2,2,2,2,2,2,2,2,2,2,2,2,2,2,2,2,2,1,1,1,1,1
1,1,1,1,1,1,2,2,2,2,2,2,2,2,2,2,2,2,2,2,2,2,2,2,2,1,1,1,1,1,1
1,1,1,1,1,1,1,2,2,2,2,2,2,2,2,2,2,2,2,2,2,2,2,2,1,1,1,1,1,1,1
1,1,1,1,1,1,1,1,1,2,2,2,2,2,2,2,2,2,2,2,2,2,1,1,1,1,1,1,1,1,1
1,1,1,1,1,1,1,1,1,1,1,1,2,2,2,2,2,2,2,1,1,1,1,1,1,1,1,1,1,1,1
endlayer

layer
1,1,1,1,1,1,1,1,1,1,1,1,2,2,2,2,2,2,2,1,1,1,1,1,1,1,1,1,1,1,1
1,1,1,1,1,1,1,1,1,2,2,2,18,18,18,18,18,18,18,2,2,2,1,1,1,1,1,1,1,1,1
1,1,1,1,1,1,1,2,2,18,18,18,18,18,18,18,18,18,18,18,18,18,2,2,1,1,1,1,1,1,1
1,1,1,1,1,1,2,18,18,18,18,18,18,19,18,18,18,19,18,18,18,18,18,18,2,1,1,1,1,1,1
1,1,1,1,1,2,18,18,18,18,19,18,18,18,18,18,18,18,18,18,19,18,18,18,18,2,1,1,1,1,1
1,1,1,1,2,18,18,18,18,18,18,18,18,18,18,18,18,18,18,18,18,18,18,18,18,18,2,1,1,1,1
1,1,1,2,18,18,18,18,18,18,18,18,19,18,18,18,18,18,19,18,18,18,18,18,18,18,18,2,1,1,1
1,1,2,18,18,18,18,19,19,19,19,19,19,18,18,18,18,18,19,19,19,19,19,19,18,18,18,18,2,1,1
1,1,2,18,18,18,18,19,19,19,19,19,19,19,19,19,19,19,19,19,19,19,19,19,18,18,18,18,2,1,1
1,2,18,18,18,18,18,19,19,2,2,2,2,2,2,2,2,2,2,2,2,2,19,19,18,18,18,18,18,2,1
1,2,18,18,19,18,18,19,19,2,2,2,2,2,2,2,2,2,2,2,2,2,19,19,18,18,19,18,18,2,1
1,2,18,18,18,18,18,19,19,2,2,2,2,2,2,2,2,2,2,2,2,2,19,19,18,18,18,18,18,2,1
2,18,18,18,18,18,19,19,19,2,2,2,2,2,2,2,2,2,2,2,2,2,19,19,19,18,18,18,18,18,2
2,18,18,19,18,18,18,18,19,2,2,2,2,2,20,20,20,2,2,2,2,2,19,18,18,18,18,19,18,18,2
2,18,18,18,18,18,18,18,19,2,2,2,2,22,16,16,16,21,2,2,2,2,19,18,18,18,18,18,18,18,2
2,18,18,18,18,18,18,18,19,2,2,2,2,22,16,11,16,21,2,2,2,2,19,18,18,18,18,18,18,18,2
2,18,18,18,18,18,18,18,19,2,2,2,2,22,16,16,16,21,2,2,2,2,19,18,18,18,18,18,18,18,2
2,18,18,19,18,18,18,18,19,2,2,2,2,2,23,23,23,2,2,2,2,2,19,18,18,18,18,19,18,18,2
2,18,18,18,18,18,19,19,19,2,2,2,2,2,2,2,2,2,2,2,2,2,19,19,19,18,18,18,18,18,2
1,2,18,18,18,18,18,19,19,2,2,2,2,2,2,2,2,2,2,2,2,2,19,19,18,18,18,18,18,2,1
1,2,18,18,19,18,18,19,19,2,2,2,2,2,2,2,2,2,2,2,2,2,19,19,18,18,19,18,18,2,1
1,2,18,18,18,18,18,19,19,2,2,2,2,2,2,2,2,2,2,2,2,2,19,19,18,18,18,18,18,2,1
1,1,2,18,18,18,18,19,19,19,19,19,19,19,19,19,19,19,19,19,19,19,19,19,18,18,18,18,2,1,1
1,1,2,18,18,18,18,19,19,19,19,19,19,18,18,18,18,18,19,19,19,19,19,19,18,18,18,18,2,1,1
1,1,1,2,18,18,18,18,18,18,18,18,19,18,18,18,18,18,19,18,18,18,18,18,18,18,18,2,1,1,1
1,1,1,1,2,18,18,18,18,18,18,18,18,18,18,18,18,18,18,18,18,18,18,18,18,18,2,1,1,1,1
1,1,1,1,1,2,18,18,18,18,19,18,18,18,18,18,18,18,18,18,19,18,18,18,18,2,1,1,1,1,1
1,1,1,1,1,1,2,18,18,18,18,18,18,19,18,18,18,19,18,18,18,18,18,18,2,1,1,1,1,1,1
1,1,1,1,1,1,1,2,2,18,18,18,18,18,18,18,18,18,18,18,18,18,2,2,1,1,1,1,1,1,1
1,1,1,1,1,1,1,1,1,2,2,2,18,18,18,18,18,18,18,2,2,2,1,1,1,1,1,1,1,1,1
1,1,1,1,1,1,1,1,1,1,1,1,2,2,2,2,2,2,2,1,1,1,1,1,1,1,1,1,1,1,1
endlayer

layer
1,1,1,1,1,1,1,1,1,1,1,1,2,2,2,2,2,2,2,1,1,1,1,1,1,1,1,1,1,1,1
1,1,1,1,1,1,1,1,1,2,2,2,0,0,0,0,0,0,0,2,2,2,1,1,1,1,1,1,1,1,1
1,1,1,1,1,1,1,2,2,0,0,0,0,0,0,0,0,0,0,0,0,0,2,2,1,1,1,1,1,1,1
1,1,1,1,1,1,2,0,0,0,0,0,0,11,0,0,0,11,0,0,0,0,0,0,2,1,1,1,1,1,1
1,1,1,1,1,2,0,0,0,0,11,0,0,0,0,0,0,0,0,0,11,0,0,0,0,2,1,1,1,1,1
1,1,1,1,2,0,0,0,0,0,0,0,0,0,0,0,0,0,0,0,0,0,0,0,0,0,2,1,1,1,1
1,1,1,2,0,0,0,0,0,0,0,0,2,0,0,0,0,0,2,0,0,0,0,0,0,0,0,2,1,1,1
1,1,2,0,0,0,0,11,2,2,2,2,2,0,0,0,0,0,2,2,2,2,2,11,0,0,0,0,2,1,1
1,1,2,0,0,0,0,2,2,2,2,2,2,2,2,2,2,2,2,2,2,2,2,2,0,0,0,0,2,1,1
1,2,0,0,0,0,0,2,2,11,11,2,11,2,11,2,11,2,11,2,11,11,2,2,0,0,0,0,0,2,1
1,2,0,0,11,0,0,2,2,11,11,2,2,2,2,2,2,2,2,2,11,11,2,2,0,0,11,0,0,2,1
1,2,0,0,0,0,0,2,2,2,2,2,3,3,2,2,2,3,3,2,2,2,2,2,0,0,0,0,0,2,1
2,0,0,0,0,0,2,2,2,11,2,3,2,2,2,2,2,2,2,3,2,11,2,2,2,0,0,0,0,0,2
2,0,0,11,0,0,0,0,2,2,2,3,2,2,12,12,12,2,2,3,2,2,2,0,0,0,0,11,0,0,2
2,0,0,0,0,0,0,0,2,11,2,2,2,12,12,12,12,12,2,2,2,11,2,0,0,0,0,0,0,0,2
2,0,0,0,0,0,0,0,2,2,2,2,2,12,12,11,12,12,2,2,2,2,2,0,0,0,0,0,0,0,2
2,0,0,0,0,0,0,0,2,11,2,2,2,12,12,12,12,12,2,2,2,11,2,0,0,0,0,0,0,0,2
2,0,0,11,0,0,0,0,2,2,2,3,2,2,12,12,12,2,2,3,2,2,2,0,0,0,0,11,0,0,2
2,0,0,0,0,0,2,2,2,11,2,3,2,2,2,2,2,2,2,3,2,11,2,2,2,0,0,0,0,0,2
1,2,0,0,0,0,0,2,2,2,2,2,3,3,2,2,2,3,3,2,2,2,2,2,0,0,0,0,0,2,1
1,2,0,0,11,0,0,2,2,11,11,2,2,2,2,2,2,2,2,2,11,11,2,2,0,0,11,0,0,2,1
1,2,0,0,0,0,0,2,2,11,11,2,11,2,11,2,11,2,11,2,11,11,2,2,0,0,0,0,0,2,1
1,1,2,0,0,0,0,2,2,2,2,2,2,2,2,2,2,2,2,2,2,2,2,2,0,0,0,0,2,1,1
1,1,2,0,0,0,0,11,2,2,2,2,2,0,0,0,0,0,2,2,2,2,2,11,0,0,0,0,2,1,1
1,1,1,2,0,0,0,0,0,0,0,0,2,0,0,0,0,0,2,0,0,0,0,0,0,0,0,2,1,1,1
1,1,1,1,2,0,0,0,0,0,0,0,0,0,0,0,0,0,0,0,0,0,0,0,0,0,2,1,1,1,1
1,1,1,1,1,2,0,0,0,0,11,0,0,0,0,0,0,0,0,0,11,0,0,0,0,2,1,1,1,1,1
1,1,1,1,1,1,2,0,0,0,0,0,0,11,0,0,0,11,0,0,0,0,0,0,2,1,1,1,1,1,1
1,1,1,1,1,1,1,2,2,0,0,0,0,0,0,0,0,0,0,0,0,0,2,2,1,1,1,1,1,1,1
1,1,1,1,1,1,1,1,1,2,2,2,0,0,0,0,0,0,0,2,2,2,1,1,1,1,1,1,1,1,1
1,1,1,1,1,1,1,1,1,1,1,1,2,2,2,2,2,2,2,1,1,1,1,1,1,1,1,1,1,1,1
endlayer

layer
1,1,1,1,1,1,1,1,1,1,1,1,24,24,24,24,24,24,24,1,1,1,1,1,1,1,1,1,1,1,1
1,1,1,1,1,1,1,1,1,24,24,24,0,0,0,0,0,0,0,24,24,24,1,1,1,1,1,1,1,1,1
1,1,1,1,1,1,1,24,24,0,0,0,0,0,0,0,0,0,0,0,0,0,24,24,1,1,1,1,1,1,1
1,1,1,1,1,1,24,0,0,0,0,0,0,11,0,0,0,11,0,0,0,0,0,0,24,1,1,1,1,1,1
1,1,1,1,1,24,0,0,0,0,11,0,0,0,0,0,0,0,0,0,11,0,0,0,0,24,1,1,1,1,1
1,1,1,1,24,0,0,0,0,0,0,0,0,0,0,0,0,0,0,0,0,0,0,0,0,0,24,1,1,1,1
1,1,1,24,0,0,0,0,0,0,0,0,0,0,0,0,0,0,0,0,0,0,0,0,0,0,0,24,1,1,1
1,1,24,0,0,0,0,11,2,2,0,0,0,0,0,0,0,0,0,0,0,2,2,11,0,0,0,0,24,1,1
1,1,24,0,0,0,0,2,0,0,0,0,0,0,0,0,0,0,0,0,0,0,0,2,0,0,0,0,24,1,1
1,24,0,0,0,0,0,2,0,11,11,0,11,0,11,0,11,0,11,0,11,11,0,2,0,0,0,0,0,24,1
1,24,0,0,11,0,0,0,0,11,11,0,0,0,0,0,0,0,0,0,11,11,0,0,0,0,11,0,0,24,1
1,24,0,0,0,0,0,0,0,0,0,0,0,0,0,0,0,0,0,0,0,0,0,0,0,0,0,0,0,24,1
24,0,0,0,0,0,0,0,0,11,0,0,0,0,0,11,0,0,0,0,0,11,0,0,0,0,0,0,0,0,24
24,0,0,11,0,0,0,0,0,0,0,0,0,11,0,0,0,11,0,0,0,0,0,0,0,0,0,11,0,0,24
24,0,0,0,0,0,0,0,0,11,0,0,0,0,0,25,0,0,0,0,0,11,0,0,0,0,0,0,0,0,24
24,0,0,0,0,0,0,0,0,0,0,0,11,0,25,11,25,0,11,0,0,0,0,0,0,0,0,0,0,0,24
24,0,0,0,0,0,0,0,0,11,0,0,0,0,0,25,0,0,0,0,0,11,0,0,0,0,0,0,0,0,24
24,0,0,11,0,0,0,0,0,0,0,0,0,11,0,0,0,11,0,0,0,0,0,0,0,0,0,11,0,0,24
24,0,0,0,0,0,0,0,0,11,0,0,0,0,0,11,0,0,0,0,0,11,0,0,0,0,0,0,0,0,24
1,24,0,0,0,0,0,0,0,0,0,0,0,0,0,0,0,0,0,0,0,0,0,0,0,0,0,0,0,24,1
1,24,0,0,11,0,0,0,0,11,11,0,0,0,0,0,0,0,0,0,11,11,0,0,0,0,11,0,0,24,1
1,24,0,0,0,0,0,2,0,11,11,0,11,0,11,0,11,0,11,0,11,11,0,2,0,0,0,0,0,24,1
1,1,24,0,0,0,0,2,0,0,0,0,0,0,0,0,0,0,0,0,0,0,0,2,0,0,0,0,24,1,1
1,1,24,0,0,0,0,11,2,2,0,0,0,0,0,0,0,0,0,0,0,2,2,11,0,0,0,0,24,1,1
1,1,1,24,0,0,0,0,0,0,0,0,26,0,0,0,0,0,26,0,0,0,0,0,0,0,0,24,1,1,1
1,1,1,1,24,0,0,0,0,0,0,0,0,0,0,0,0,0,0,0,0,0,0,0,0,0,24,1,1,1,1
1,1,1,1,1,24,0,0,0,0,11,0,0,0,0,0,0,0,0,0,11,0,0,0,0,24,1,1,1,1,1
1,1,1,1,1,1,24,0,0,0,0,0,0,11,0,0,0,11,0,0,0,0,0,0,24,1,1,1,1,1,1
1,1,1,1,1,1,1,24,24,0,0,0,0,0,0,0,0,0,0,0,0,0,24,24,1,1,1,1,1,1,1
1,1,1,1,1,1,1,1,1,24,24,24,0,0,0,0,0,0,0,24,24,24,1,1,1,1,1,1,1,1,1
1,1,1,1,1,1,1,1,1,1,1,1,24,24,24,24,24,24,24,1,1,1,1,1,1,1,1,1,1,1,1
endlayer

layer
1,1,1,1,1,1,1,1,1,1,1,1,24,24,24,24,24,24,24,1,1,1,1,1,1,1,1,1,1,1,1
1,1,1,1,1,1,1,1,1,24,24,24,0,0,0,0,0,0,0,24,24,24,1,1,1,1,1,1,1,1,1
1,1,1,1,1,1,1,24,24,0,0,0,0,0,0,0,0,0,0,0,0,0,24,24,1,1,1,1,1,1,1
1,1,1,1,1,1,24,0,0,0,0,0,0,15,0,0,0,15,0,0,0,0,0,0,24,1,1,1,1,1,1
1,1,1,1,1,24,0,0,0,0,15,0,0,0,0,0,0,0,0,0,15,0,0,0,0,24,1,1,1,1,1
1,1,1,1,24,0,0,0,0,0,0,0,0,0,0,0,0,0,0,0,0,0,0,0,0,0,24,1,1,1,1
1,1,1,24,0,0,0,0,0,0,0,0,0,0,0,0,0,0,0,0,0,0,0,0,0,0,0,24,1,1,1
1,1,24,0,0,0,0,15,0,0,0,0,0,0,0,0,0,0,0,0,0,0,0,15,0,0,0,0,24,1,1
1,1,24,0,0,0,0,0,0,0,0,0,0,0,0,0,0,0,0,0,0,0,0,0,0,0,0,0,24,1,1
1,24,0,0,0,0,0,0,0,11,11,0,11,0,11,0,11,0,11,0,11,11,0,0,0,0,0,0,0,24,1
1,24,0,0,15,0,0,0,0,11,11,0,0,0,0,0,0,0,0,0,11,11,0,0,0,0,15,0,0,24,1
1,24,0,0,0,0,0,0,0,0,0,0,0,0,0,0,0,0,0,0,0,0,0,0,0,0,0,0,0,24,1
24,0,0,0,0,0,0,0,0,11,0,0,0,0,0,11,0,0,0,0,0,11,0,0,0,0,0,0,0,0,24
24,0,0,15,0,0,0,0,0,0,0,0,0,11,0,0,0,11,0,0,0,0,0,0,0,0,0,15,0,0,24
24,0,0,0,0,0,0,0,0,11,0,0,0,0,0,25,0,0,0,0,0,11,0,0,0,0,0,0,0,0,24
24,0,0,0,0,0,0,0,0,0,0,0,11,0,25,11,25,0,11,0,0,0,0,0,0,0,0,0,0,0,24
24,0,0,0,0,0,0,0,0,11,0,0,0,0,0,25,0,0,0,0,0,11,0,0,0,0,0,0,0,0,24
24,0,0,15,0,0,0,0,0,0,0,0,0,11,0,0,0,11,0,0,0,0,0,0,0,0,0,15,0,0,24
24,0,0,0,0,0,0,0,0,11,0,0,0,0,0,11,0,0,0,0,0,11,0,0,0,0,0,0,0,0,24
1,24,0,0,0,0,0,0,0,0,0,0,0,0,0,0,0,0,0,0,0,0,0,0,0,0,0,0,0,24,1
1,24,0,0,15,0,0,0,0,11,11,0,0,0,0,0,0,0,0,0,11,11,0,0,0,0,15,0,0,24,1
1,24,0,0,0,0,0,0,0,11,11,0,11,0,11,0,11,0,11,0,11,11,0,0,0,0,0,0,0,24,1
1,1,24,0,0,0,0,0,0,0,0,0,0,0,0,0,0,0,0,0,0,0,0,0,0,0,0,0,24,1,1
1,1,24,0,0,0,0,15,0,0,0,0,0,0,0,0,0,0,0,0,0,0,0,15,0,0,0,0,24,1,1
1,1,1,24,0,0,0,0,0,0,0,0,0,0,0,0,0,0,0,0,0,0,0,0,0,0,0,24,1,1,1
1,1,1,1,24,0,0,0,0,0,0,0,0,0,0,0,0,0,0,0,0,0,0,0,0,0,24,1,1,1,1
1,1,1,1,1,24,0,0,0,0,15,0,0,0,0,0,0,0,0,0,15,0,0,0,0,24,1,1,1,1,1
1,1,1,1,1,1,24,0,0,0,0,0,0,15,0,0,0,15,0,0,0,0,0,0,24,1,1,1,1,1,1
1,1,1,1,1,1,1,24,24,0,0,0,0,0,0,0,0,0,0,0,0,0,24,24,1,1,1,1,1,1,1
1,1,1,1,1,1,1,1,1,24,24,24,0,0,0,0,0,0,0,24,24,24,1,1,1,1,1,1,1,1,1
1,1,1,1,1,1,1,1,1,1,1,1,24,24,24,24,24,24,24,1,1,1,1,1,1,1,1,1,1,1,1
endlayer

layer
1,1,1,1,1,1,1,1,1,1,1,1,24,24,24,24,24,24,24,1,1,1,1,1,1,1,1,1,1,1,1
1,1,1,1,1,1,1,1,1,24,24,24,0,0,0,0,0,0,0,24,24,24,1,1,1,1,1,1,1,1,1
1,1,1,1,1,1,1,24,24,0,0,0,0,0,0,0,0,0,0,0,0,0,24,24,1,1,1,1,1,1,1
1,1,1,1,1,1,24,0,0,0,0,0,0,0,0,0,0,0,0,0,0,0,0,0,24,1,1,1,1,1,1
1,1,1,1,1,24,0,0,0,0,0,0,0,0,0,0,0,0,0,0,0,0,0,0,0,24,1,1,1,1,1
1,1,1,1,24,0,0,0,0,0,0,0,0,0,0,0,0,0,0,0,0,0,0,0,0,0,24,1,1,1,1
1,1,1,24,0,0,0,0,0,0,0,0,0,0,0,0,0,0,0,0,0,0,0,0,0,0,0,24,1,1,1
1,1,24,0,0,0,0,0,0,0,0,0,0,0,0,0,0,0,0,0,0,0,0,0,0,0,0,0,24,1,1
1,1,24,0,0,0,0,0,0,0,0,0,0,0,0,0,0,0,0,0,0,0,0,0,0,0,0,0,24,1,1
1,24,0,0,0,0,0,0,0,11,11,0,11,0,11,0,11,0,11,0,11,11,0,0,0,0,0,0,0,24,1
1,24,0,0,0,0,0,0,0,11,11,0,0,0,0,0,0,0,0,0,11,11,0,0,0,0,0,0,0,24,1
1,24,0,0,0,0,0,0,0,0,0,0,0,0,0,0,0,0,0,0,0,0,0,0,0,0,0,0,0,24,1
24,0,0,0,0,0,0,0,0,11,0,0,0,0,0,15,0,0,0,0,0,11,0,0,0,0,0,0,0,0,24
24,0,0,0,0,0,0,0,0,0,0,0,0,15,0,0,0,15,0,0,0,0,0,0,0,0,0,0,0,0,24
24,0,0,0,0,0,0,0,0,11,0,0,0,0,0,25,0,0,0,0,0,11,0,0,0,0,0,0,0,0,24
24,0,0,0,0,0,0,0,0,0,0,0,15,0,25,11,25,0,15,0,0,0,0,0,0,0,0,0,0,0,24
24,0,0,0,0,0,0,0,0,11,0,0,0,0,0,25,0,0,0,0,0,11,0,0,0,0,0,0,0,0,24
24,0,0,0,0,0,0,0,0,0,0,0,0,15,0,0,0,15,0,0,0,0,0,0,0,0,0,0,0,0,24
24,0,0,0,0,0,0,0,0,11,0,0,0,0,0,15,0,0,0,0,0,11,0,0,0,0,0,0,0,0,24
1,24,0,0,0,0,0,0,0,0,0,0,0,0,0,0,0,0,0,0,0,0,0,0,0,0,0,0,0,24,1
1,24,0,0,0,0,0,0,0,11,11,0,0,0,0,0,0,0,0,0,11,11,0,0,0,0,0,0,0,24,1
1,24,0,0,0,0,0,0,0,11,11,0,11,0,11,0,11,0,11,0,11,11,0,0,0,0,0,0,0,24,1
1,1,24,0,0,0,0,0,0,0,0,0,0,0,0,0,0,0,0,0,0,0,0,0,0,0,0,0,24,1,1
1,1,24,0,0,0,0,0,0,0,0,0,0,0,0,0,0,0,0,0,0,0,0,0,0,0,0,0,24,1,1
1,1,1,24,0,0,0,0,0,0,0,0,0,0,0,0,0,0,0,0,0,0,0,0,0,0,0,24,1,1,1
1,1,1,1,24,0,0,0,0,0,0,0,0,0,0,0,0,0,0,0,0,0,0,0,0,0,24,1,1,1,1
1,1,1,1,1,24,0,0,0,0,0,0,0,0,0,0,0,0,0,0,0,0,0,0,0,24,1,1,1,1,1
1,1,1,1,1,1,24,0,0,0,0,0,0,0,0,0,0,0,0,0,0,0,0,0,24,1,1,1,1,1,1
1,1,1,1,1,1,1,24,24,0,0,0,0,0,0,0,0,0,0,0,0,0,24,24,1,1,1,1,1,1,1
1,1,1,1,1,1,1,1,1,24,24,24,0,0,0,0,0,0,0,24,24,24,1,1,1,1,1,1,1,1,1
1,1,1,1,1,1,1,1,1,1,1,1,24,24,24,24,24,24,24,1,1,1,1,1,1,1,1,1,1,1,1
endlayer

layer
1,1,1,1,1,1,1,1,1,1,1,1,1,24,24,24,24,24,1,1,1,1,1,1,1,1,1,1,1,1,1
1,1,1,1,1,1,1,1,1,1,24,24,24,0,0,0,0,0,24,24,24,1,1,1,1,1,1,1,1,1,1
1,1,1,1,1,1,1,1,24,24,0,0,0,0,0,0,0,0,0,0,0,24,24,1,1,1,1,1,1,1,1
1,1,1,1,1,1,24,24,0,0,0,0,0,0,0,0,0,0,0,0,0,0,0,24,24,1,1,1,1,1,1
1,1,1,1,1,24,0,0,0,0,0,0,0,0,0,0,0,0,0,0,0,0,0,0,0,24,1,1,1,1,1
1,1,1,1,24,0,0,0,0,0,0,0,0,0,0,0,0,0,0,0,0,0,0,0,0,0,24,1,1,1,1
1,1,1,24,0,0,0,0,0,0,0,0,0,0,0,0,0,0,0,0,0,0,0,0,0,0,0,24,1,1,1
1,1,1,24,0,0,0,0,0,0,0,0,0,0,0,0,0,0,0,0,0,0,0,0,0,0,0,24,1,1,1
1,1,24,0,0,0,0,0,27,27,27,27,27,27,27,27,27,27,27,27,27,27,27,0,0,0,0,0,24,1,1
1,1,24,0,0,0,0,0,27,11,11,27,11,27,11,27,11,27,11,27,11,11,27,0,0,0,0,0,24,1,1
1,24,0,0,0,0,0,0,27,11,11,27,27,27,27,27,27,27,27,27,11,11,27,0,0,0,0,0,0,24,1
1,24,0,0,0,0,0,0,27,27,27,0,0,0,0,0,0,0,0,0,27,27,27,0,0,0,0,0,0,24,1
1,24,0,0,0,0,0,0,27,11,27,0,0,0,0,28,0,0,0,0,27,11,27,0,0,0,0,0,0,24,1
24,0,0,0,0,0,0,0,27,27,27,0,0,28,0,0,0,28,0,0,27,27,27,0,0,0,0,0,0,0,24
24,0,0,0,0,0,0,0,27,11,27,0,0,0,0,25,0,0,0,0,27,11,27,0,0,0,0,0,0,0,24
24,0,0,0,0,0,0,0,27,27,27,0,28,0,25,29,25,0,28,0,27,27,27,0,0,0,0,0,0,0,24
24,0,0,0,0,0,0,0,27,11,27,0,0,0,0,25,0,0,0,0,27,11,27,0,0,0,0,0,0,0,24
24,0,0,0,0,0,0,0,27,27,27,0,0,28,0,0,0,30,0,0,27,27,27,0,0,0,0,0,0,0,24
1,24,0,0,0,0,0,0,27,11,27,0,0,0,0,28,0,0,0,0,27,11,27,0,0,0,0,0,0,24,1
1,24,0,0,0,0,0,0,27,27,27,0,0,0,0,0,0,0,0,0,27,27,27,0,0,0,0,0,0,24,1
1,24,0,0,0,0,0,0,27,11,11,27,27,27,27,27,27,27,27,27,11,11,27,0,0,0,0,0,0,24,1
1,1,24,0,0,0,0,0,27,11,11,27,11,27,11,27,11,27,11,27,11,11,27,0,0,0,0,0,24,1,1
1,1,24,0,0,0,0,0,27,27,27,27,27,27,27,27,27,27,27,27,27,27,27,0,0,0,0,0,24,1,1
1,1,1,24,0,0,0,0,0,0,0,0,0,0,0,0,0,0,0,0,0,0,0,0,0,0,0,24,1,1,1
1,1,1,24,0,0,0,0,0,0,0,0,0,0,0,0,0,0,0,0,0,0,0,0,0,0,0,24,1,1,1
1,1,1,1,24,0,0,0,0,0,0,0,0,0,0,0,0,0,0,0,0,0,0,0,0,0,24,1,1,1,1
1,1,1,1,1,24,0,0,0,0,0,0,0,0,0,0,0,0,0,0,0,0,0,0,0,24,1,1,1,1,1
1,1,1,1,1,1,24,24,0,0,0,0,0,0,0,0,0,0,0,0,0,0,0,24,24,1,1,1,1,1,1
1,1,1,1,1,1,1,1,24,24,0,0,0,0,0,0,0,0,0,0,0,24,24,1,1,1,1,1,1,1,1
1,1,1,1,1,1,1,1,1,1,24,24,24,0,0,0,0,0,24,24,24,1,1,1,1,1,1,1,1,1,1
1,1,1,1,1,1,1,1,1,1,1,1,1,24,24,24,24,24,1,1,1,1,1,1,1,1,1,1,1,1,1
endlayer

layer
1,1,1,1,1,1,1,1,1,1,1,1,1,1,1,1,1,1,1,1,1,1,1,1,1,1,1,1,1,1,1
1,1,1,1,1,1,1,1,1,1,24,24,24,24,24,24,24,24,24,24,24,1,1,1,1,1,1,1,1,1,1
1,1,1,1,1,1,1,1,24,24,0,0,0,0,0,0,0,0,0,0,0,24,24,1,1,1,1,1,1,1,1
1,1,1,1,1,1,1,24,0,0,0,0,0,0,0,0,0,0,0,0,0,0,0,24,1,1,1,1,1,1,1
1,1,1,1,1,24,24,0,0,0,0,0,0,0,0,0,0,0,0,0,0,0,0,0,24,24,1,1,1,1,1
1,1,1,1,24,0,0,0,0,0,0,0,0,0,0,0,0,0,0,0,0,0,0,0,0,0,24,1,1,1,1
1,1,1,1,24,0,0,0,0,0,0,0,0,0,0,0,0,0,0,0,0,0,0,0,0,0,24,1,1,1,1
1,1,1,24,0,0,0,0,0,0,0,0,0,0,0,0,0,0,0,0,0,0,0,0,0,0,0,24,1,1,1
1,1,24,0,0,0,0,0,15,31,31,27,27,0,0,0,0,0,27,27,31,31,15,0,0,0,0,0,24,1,1
1,1,24,0,0,0,0,0,31,27,27,3,3,3,3,3,3,3,3,3,27,27,31,0,0,0,0,0,24,1,1
1,24,0,0,0,0,0,0,31,27,11,33,27,0,0,0,0,0,27,32,11,27,31,0,0,0,0,0,0,24,1
1,24,0,0,0,0,0,0,27,3,34,0,0,0,0,0,0,0,0,0,34,3,27,0,0,0,0,0,0,24,1
1,24,0,0,0,0,0,0,27,3,27,0,0,0,0,0,0,0,0,0,27,3,27,0,0,0,0,0,0,24,1
1,24,0,0,0,0,0,0,0,3,0,0,0,0,0,0,0,0,0,0,0,3,0,0,0,0,0,0,0,24,1
1,24,0,0,0,0,0,0,0,3,0,0,0,0,0,35,0,0,0,0,0,3,0,0,0,0,0,0,0,24,1
1,24,0,0,0,0,0,0,0,3,0,0,0,0,35,12,35,0,0,0,0,3,0,0,0,0,0,0,0,24,1
1,24,0,0,0,0,0,0,0,3,0,0,0,0,0,35,0,0,0,0,0,3,0,0,0,0,0,0,0,24,1
1,24,0,0,0,0,0,0,0,3,0,0,0,0,0,0,0,0,0,0,0,3,0,0,0,0,0,0,0,24,1
1,24,0,0,0,0,0,0,27,3,27,0,0,0,0,0,0,0,0,0,27,3,27,0,0,0,0,0,0,24,1
1,24,0,0,0,0,0,0,27,3,36,0,0,0,0,0,0,0,0,0,36,3,27,0,0,0,0,0,0,24,1
1,24,0,0,0,0,0,0,31,27,11,33,27,0,0,0,0,0,27,32,11,27,31,0,0,0,0,0,0,24,1
1,1,24,0,0,0,0,0,31,27,27,3,3,3,3,3,3,3,3,3,27,27,31,0,0,0,0,0,24,1,1
1,1,24,0,0,0,0,0,15,31,31,27,27,0,0,0,0,0,27,27,31,31,15,0,0,0,0,0,24,1,1
1,1,1,24,0,0,0,0,0,0,0,0,0,0,0,0,0,0,0,0,0,0,0,0,0,0,0,24,1,1,1
1,1,1,1,24,0,0,0,0,0,0,0,0,0,0,0,0,0,0,0,0,0,0,0,0,0,24,1,1,1,1
1,1,1,1,24,0,0,0,0,0,0,0,0,0,0,0,0,0,0,0,0,0,0,0,0,0,24,1,1,1,1
1,1,1,1,1,24,24,0,0,0,0,0,0,0,0,0,0,0,0,0,0,0,0,0,24,24,1,1,1,1,1
1,1,1,1,1,1,1,24,0,0,0,0,0,0,0,0,0,0,0,0,0,0,0,24,1,1,1,1,1,1,1
1,1,1,1,1,1,1,1,24,24,0,0,0,0,0,0,0,0,0,0,0,24,24,1,1,1,1,1,1,1,1
1,1,1,1,1,1,1,1,1,1,24,24,24,24,24,24,24,24,24,24,24,1,1,1,1,1,1,1,1,1,1
1,1,1,1,1,1,1,1,1,1,1,1,1,1,1,1,1,1,1,1,1,1,1,1,1,1,1,1,1,1,1
endlayer

layer
1,1,1,1,1,1,1,1,1,1,1,1,1,1,1,1,1,1,1,1,1,1,1,1,1,1,1,1,1,1,1
1,1,1,1,1,1,1,1,1,1,1,24,24,24,24,24,24,24,24,24,1,1,1,1,1,1,1,1,1,1,1
1,1,1,1,1,1,1,1,1,24,24,0,0,0,0,0,0,0,0,0,24,24,1,1,1,1,1,1,1,1,1
1,1,1,1,1,1,1,24,24,0,0,0,0,0,0,0,0,0,0,0,0,0,24,24,1,1,1,1,1,1,1
1,1,1,1,1,1,24,0,0,0,0,0,0,0,0,0,0,0,0,0,0,0,0,0,24,1,1,1,1,1,1
1,1,1,1,1,24,0,0,0,0,0,0,0,0,0,0,0,0,0,0,0,0,0,0,0,24,1,1,1,1,1
1,1,1,1,24,0,0,0,0,0,0,0,0,0,0,0,0,0,0,0,0,0,0,0,0,0,24,1,1,1,1
1,1,1,24,0,0,0,0,0,0,0,0,0,0,0,0,0,0,0,0,0,0,0,0,0,0,0,24,1,1,1
1,1,1,24,0,0,0,0,0,0,0,15,15,31,33,27,32,31,15,15,0,0,0,0,0,0,0,24,1,1,1
1,1,24,0,0,0,0,0,0,0,0,15,15,27,3,3,3,27,15,15,0,0,0,0,0,0,0,0,24,1,1
1,1,24,0,0,0,0,0,0,0,0,15,15,31,33,27,32,31,15,15,0,0,0,0,0,0,0,0,24,1,1
1,24,0,0,0,0,0,0,15,15,15,0,0,0,0,0,0,0,0,0,15,15,15,0,0,0,0,0,0,24,1
1,24,0,0,0,0,0,0,15,15,15,0,0,0,0,0,0,0,0,0,15,15,15,0,0,0,0,0,0,24,1
1,24,0,0,0,0,0,0,31,27,31,0,0,0,0,0,0,0,0,0,31,27,31,0,0,0,0,0,0,24,1
1,24,0,0,0,0,0,0,34,3,34,0,0,0,0,0,0,0,0,0,34,3,34,0,0,0,0,0,0,24,1
1,24,0,0,0,0,0,0,27,3,27,0,0,0,0,0,0,0,0,0,27,3,27,0,0,0,0,0,0,24,1
1,24,0,0,0,0,0,0,36,3,36,0,0,0,0,0,0,0,0,0,36,3,36,0,0,0,0,0,0,24,1
1,24,0,0,0,0,0,0,31,27,31,0,0,0,0,0,0,0,0,0,31,27,31,0,0,0,0,0,0,24,1
1,24,0,0,0,0,0,0,15,15,15,0,0,0,0,0,0,0,0,0,15,15,15,0,0,0,0,0,0,24,1
1,24,0,0,0,0,0,0,15,15,15,0,0,0,0,0,0,0,0,0,15,15,15,0,0,0,0,0,0,24,1
1,1,24,0,0,0,0,0,0,0,0,15,15,31,33,27,32,31,15,15,0,0,0,0,0,0,0,0,24,1,1
1,1,24,0,0,0,0,0,0,0,0,15,15,27,3,3,3,27,15,15,0,0,0,0,0,0,0,0,24,1,1
1,1,1,24,0,0,0,0,0,0,0,15,15,31,33,27,32,31,15,15,0,0,0,0,0,0,0,24,1,1,1
1,1,1,24,0,0,0,0,0,0,0,0,0,0,0,0,0,0,0,0,0,0,0,0,0,0,0,24,1,1,1
1,1,1,1,24,0,0,0,0,0,0,0,0,0,0,0,0,0,0,0,0,0,0,0,0,0,24,1,1,1,1
1,1,1,1,1,24,0,0,0,0,0,0,0,0,0,0,0,0,0,0,0,0,0,0,0,24,1,1,1,1,1
1,1,1,1,1,1,24,0,0,0,0,0,0,0,0,0,0,0,0,0,0,0,0,0,24,1,1,1,1,1,1
1,1,1,1,1,1,1,24,24,0,0,0,0,0,0,0,0,0,0,0,0,0,24,24,1,1,1,1,1,1,1
1,1,1,1,1,1,1,1,1,24,24,0,0,0,0,0,0,0,0,0,24,24,1,1,1,1,1,1,1,1,1
1,1,1,1,1,1,1,1,1,1,1,24,24,24,24,24,24,24,24,24,1,1,1,1,1,1,1,1,1,1,1
1,1,1,1,1,1,1,1,1,1,1,1,1,1,1,1,1,1,1,1,1,1,1,1,1,1,1,1,1,1,1
endlayer

layer
1,1,1,1,1,1,1,1,1,1,1,1,1,1,1,1,1,1,1,1,1,1,1,1,1,1,1,1,1,1,1
1,1,1,1,1,1,1,1,1,1,1,1,1,24,24,24,24,24,1,1,1,1,1,1,1,1,1,1,1,1,1
1,1,1,1,1,1,1,1,1,1,24,24,24,0,0,0,0,0,24,24,24,1,1,1,1,1,1,1,1,1,1
1,1,1,1,1,1,1,1,24,24,0,0,0,0,0,0,0,0,0,0,0,24,24,1,1,1,1,1,1,1,1
1,1,1,1,1,1,24,24,0,0,0,0,0,0,0,0,0,0,0,0,0,0,0,24,24,1,1,1,1,1,1
1,1,1,1,1,24,0,0,0,0,0,0,0,0,0,0,0,0,0,0,0,0,0,0,0,24,1,1,1,1,1
1,1,1,1,24,0,0,0,0,0,0,0,0,0,0,0,0,0,0,0,0,0,0,0,0,0,24,1,1,1,1
1,1,1,1,24,0,0,0,0,0,0,0,0,0,0,0,0,0,0,0,0,0,0,0,0,0,24,1,1,1,1
1,1,1,24,0,0,0,0,0,0,0,0,0,0,15,31,15,0,0,0,0,0,0,0,0,0,0,24,1,1,1
1,1,1,24,0,0,0,0,0,0,0,0,0,0,15,27,15,0,0,0,0,0,0,0,0,0,0,24,1,1,1
1,1,24,0,0,0,0,0,0,0,0,0,0,0,15,31,15,0,0,0,0,0,0,0,0,0,0,0,24,1,1
1,1,24,0,0,0,0,0,0,0,0,0,0,0,0,0,0,0,0,0,0,0,0,0,0,0,0,0,24,1,1
1,1,24,0,0,0,0,0,0,0,0,0,0,0,0,0,0,0,0,0,0,0,0,0,0,0,0,0,24,1,1
1,24,0,0,0,0,0,0,0,0,0,0,0,0,0,0,0,0,0,0,0,0,0,0,0,0,0,0,0,24,1
1,24,0,0,0,0,0,0,15,15,15,0,0,0,0,0,0,0,0,0,15,15,15,0,0,0,0,0,0,24,1
1,24,0,0,0,0,0,0,31,27,31,0,0,0,0,0,0,0,0,0,31,27,31,0,0,0,0,0,0,24,1
1,24,0,0,0,0,0,0,15,15,15,0,0,0,0,0,0,0,0,0,15,15,15,0,0,0,0,0,0,24,1
1,24,0,0,0,0,0,0,0,0,0,0,0,0,0,0,0,0,0,0,0,0,0,0,0,0,0,0,0,24,1
1,0,24,0,0,0,0,0,0,0,0,0,0,0,0,0,0,0,0,0,0,0,0,0,0,0,0,0,24,1,1
1,1,24,0,0,0,0,0,0,0,0,0,0,0,0,0,0,0,0,0,0,0,0,0,0,0,0,0,24,1,1
1,1,24,0,0,0,0,0,0,0,0,0,0,0,15,31,15,0,0,0,0,0,0,0,0,0,0,0,24,1,1
1,1,1,24,0,0,0,0,0,0,0,0,0,0,15,31,15,0,0,0,0,0,0,0,0,0,0,24,1,1,1
1,1,1,24,0,0,0,0,0,0,0,0,0,0,15,31,15,0,0,0,0,0,0,0,0,0,0,24,1,1,1
1,1,1,1,24,0,0,0,0,0,0,0,0,0,0,0,0,0,0,0,0,0,0,0,0,0,24,1,1,1,1
1,1,1,1,24,0,0,0,0,0,0,0,0,0,0,0,0,0,0,0,0,0,0,0,0,0,24,1,1,1,1
1,1,1,1,1,24,0,0,0,0,0,0,0,0,0,0,0,0,0,0,0,0,0,0,0,24,1,1,1,1,1
1,1,1,1,1,1,24,24,0,0,0,0,0,0,0,0,0,0,0,0,0,0,0,24,24,1,1,1,1,1,1
1,1,1,1,1,1,1,1,24,24,0,0,0,0,0,0,0,0,0,0,0,24,24,1,1,1,1,1,1,1,1
1,1,1,1,1,1,1,1,1,1,24,24,24,0,0,0,0,0,24,24,24,1,1,1,1,1,1,1,1,1,1
1,1,1,1,1,1,1,1,1,1,1,1,1,24,24,24,24,24,1,1,1,1,1,1,1,1,1,1,1,1,1
1,1,1,1,1,1,1,1,1,1,1,1,1,1,1,1,1,1,1,1,1,1,1,1,1,1,1,1,1,1,1
endlayer

layer
1,1,1,1,1,1,1,1,1,1,1,1,1,1,1,1,1,1,1,1,1,1,1,1,1,1,1,1,1,1,1
1,1,1,1,1,1,1,1,1,1,1,1,1,1,1,1,1,1,1,1,1,1,1,1,1,1,1,1,1,1,1
1,1,1,1,1,1,1,1,1,1,1,24,24,24,24,24,24,24,24,24,1,1,1,1,1,1,1,1,1,1,1
1,1,1,1,1,1,1,1,1,24,24,0,0,0,0,0,0,0,0,0,24,24,1,1,1,1,1,1,1,1,1
1,1,1,1,1,1,1,24,24,0,0,0,0,0,0,0,0,0,0,0,0,0,24,24,1,1,1,1,1,1,1
1,1,1,1,1,1,24,0,0,0,0,0,0,0,0,0,0,0,0,0,0,0,0,0,24,1,1,1,1,1,1
1,1,1,1,1,24,0,0,0,0,0,0,0,0,0,0,0,0,0,0,0,0,0,0,0,24,1,1,1,1,1
1,1,1,1,24,0,0,0,0,0,0,0,0,0,0,0,0,0,0,0,0,0,0,0,0,0,24,1,1,1,1
1,1,1,1,24,0,0,0,0,0,0,0,0,0,0,0,0,0,0,0,0,0,0,0,0,0,24,1,1,1,1
1,1,1,24,0,0,0,0,0,0,0,0,0,0,0,0,0,0,0,0,0,0,0,0,0,0,0,24,1,1,1
1,1,1,24,0,0,0,0,0,0,0,0,0,0,0,0,0,0,0,0,0,0,0,0,0,0,0,24,1,1,1
1,1,24,0,0,0,0,0,0,0,0,0,0,0,0,0,0,0,0,0,0,0,0,0,0,0,0,0,24,1,1
1,1,24,0,0,0,0,0,0,0,0,0,0,0,0,0,0,0,0,0,0,0,0,0,0,0,0,0,24,1,1
1,1,24,0,0,0,0,0,0,0,0,0,0,0,0,0,0,0,0,0,0,0,0,0,0,0,0,0,24,1,1
1,1,24,0,0,0,0,0,0,0,0,0,0,0,0,0,0,0,0,0,0,0,0,0,0,0,0,0,24,1,1
1,1,24,0,0,0,0,0,0,0,0,0,0,0,0,0,0,0,0,0,0,0,0,0,0,0,0,0,24,1,1
1,1,24,0,0,0,0,0,0,0,0,0,0,0,0,0,0,0,0,0,0,0,0,0,0,0,0,0,24,1,1
1,1,24,0,0,0,0,0,0,0,0,0,0,0,0,0,0,0,0,0,0,0,0,0,0,0,0,0,24,1,1
1,1,24,0,0,0,0,0,0,0,0,0,0,0,0,0,0,0,0,0,0,0,0,0,0,0,0,0,24,1,1
1,1,24,0,0,0,0,0,0,0,0,0,0,0,0,0,0,0,0,0,0,0,0,0,0,0,0,0,24,1,1
1,1,1,24,0,0,0,0,0,0,0,0,0,0,0,0,0,0,0,0,0,0,0,0,0,0,0,24,1,1,1
1,1,1,24,0,0,0,0,0,0,0,0,0,0,0,0,0,0,0,0,0,0,0,0,0,0,0,24,1,1,1
1,1,1,1,24,0,0,0,0,0,0,0,0,0,0,0,0,0,0,0,0,0,0,0,0,0,24,1,1,1,1
1,1,1,1,24,0,0,0,0,0,0,0,0,0,0,0,0,0,0,0,0,0,0,0,0,0,24,1,1,1,1
1,1,1,1,1,24,0,0,0,0,0,0,0,0,0,0,0,0,0,0,0,0,0,0,0,24,1,1,1,1,1
1,1,1,1,1,1,24,0,0,0,0,0,0,0,0,0,0,0,0,0,0,0,0,0,24,1,1,1,1,1,1
1,1,1,1,1,1,1,24,24,0,0,0,0,0,0,0,0,0,0,0,0,0,24,24,1,1,1,1,1,1,1
1,1,1,1,1,1,1,1,1,24,24,0,0,0,0,0,0,0,0,0,24,24,1,1,1,1,1,1,1,1,1
1,1,1,1,1,1,1,1,1,1,1,24,24,24,24,24,24,24,24,24,1,1,1,1,1,1,1,1,1,1,1
1,1,1,1,1,1,1,1,1,1,1,1,1,1,1,1,1,1,1,1,1,1,1,1,1,1,1,1,1,1,1
1,1,1,1,1,1,1,1,1,1,1,1,1,1,1,1,1,1,1,1,1,1,1,1,1,1,1,1,1,1,1
endlayer

layer
1,1,1,1,1,1,1,1,1,1,1,1,1,1,1,1,1,1,1,1,1,1,1,1,1,1,1,1,1,1,1
1,1,1,1,1,1,1,1,1,1,1,1,1,1,1,1,1,1,1,1,1,1,1,1,1,1,1,1,1,1,1
1,1,1,1,1,1,1,1,1,1,1,1,1,24,24,24,24,24,1,1,1,1,1,1,1,1,1,1,1,1,1
1,1,1,1,1,1,1,1,1,1,24,24,24,0,0,0,0,0,24,24,24,1,1,1,1,1,1,1,1,1,1
1,1,1,1,1,1,1,1,24,24,0,0,0,0,0,0,0,0,0,0,0,24,24,1,1,1,1,1,1,1,1
1,1,1,1,1,1,1,24,0,0,0,0,0,0,0,0,0,0,0,0,0,0,0,24,1,1,1,1,1,1,1
1,1,1,1,1,1,24,0,0,0,0,0,0,0,0,0,0,0,0,0,0,0,0,0,24,1,1,1,1,1,1
1,1,1,1,1,24,0,0,0,0,0,0,0,0,0,0,0,0,0,0,0,0,0,0,0,24,1,1,1,1,1
1,1,1,1,24,0,0,0,0,0,0,0,0,0,0,0,0,0,0,0,0,0,0,0,0,0,24,1,1,1,1
1,1,1,1,24,0,0,0,0,0,0,0,0,0,0,0,0,0,0,0,0,0,0,0,0,0,24,1,1,1,1
1,1,1,24,0,0,0,0,0,0,0,0,0,0,0,0,0,0,0,0,0,0,0,0,0,0,0,24,1,1,1
1,1,1,24,0,0,0,0,0,0,0,0,0,0,0,0,0,0,0,0,0,0,0,0,0,0,0,24,1,1,1
1,1,1,24,0,0,0,0,0,0,0,0,0,0,0,0,0,0,0,0,0,0,0,0,0,0,0,24,1,1,1
1,1,24,0,0,0,0,0,0,0,0,0,0,0,0,0,0,0,0,0,0,0,0,0,0,0,0,0,24,1,1
1,1,24,0,0,0,0,0,0,0,0,0,0,0,0,0,0,0,0,0,0,0,0,0,0,0,0,0,24,1,1
1,1,24,0,0,0,0,0,0,0,0,0,0,0,0,0,0,0,0,0,0,0,0,0,0,0,0,0,24,1,1
1,1,24,0,0,0,0,0,0,0,0,0,0,0,0,0,0,0,0,0,0,0,0,0,0,0,0,0,24,1,1
1,1,24,0,0,0,0,0,0,0,0,0,0,0,0,0,0,0,0,0,0,0,0,0,0,0,0,0,24,1,1
1,1,1,24,0,0,0,0,0,0,0,0,0,0,0,0,0,0,0,0,0,0,0,0,0,0,0,24,1,1,1
1,1,1,24,0,0,0,0,0,0,0,0,0,0,0,0,0,0,0,0,0,0,0,0,0,0,0,24,1,1,1
1,1,1,24,0,0,0,0,0,0,0,0,0,0,0,0,0,0,0,0,0,0,0,0,0,0,0,24,1,1,1
1,1,1,1,24,0,0,0,0,0,0,0,0,0,0,0,0,0,0,0,0,0,0,0,0,0,24,1,1,1,1
1,1,1,1,24,0,0,0,0,0,0,0,0,0,0,0,0,0,0,0,0,0,0,0,0,0,24,1,1,1,1
1,1,1,1,1,24,0,0,0,0,0,0,0,0,0,0,0,0,0,0,0,0,0,0,0,24,1,1,1,1,1
1,1,1,1,1,1,24,0,0,0,0,0,0,0,0,0,0,0,0,0,0,0,0,0,24,1,1,1,1,1,1
1,1,1,1,1,1,1,24,0,0,0,0,0,0,0,0,0,0,0,0,0,0,0,24,1,1,1,1,1,1,1
1,1,1,1,1,1,1,1,24,24,0,0,0,0,0,0,0,0,0,0,0,24,24,1,1,1,1,1,1,1,1
1,1,1,1,1,1,1,1,1,1,24,24,24,0,0,0,0,0,24,24,24,1,1,1,1,1,1,1,1,1,1
1,1,1,1,1,1,1,1,1,1,1,1,1,24,24,24,24,24,1,1,1,1,1,1,1,1,1,1,1,1,1
1,1,1,1,1,1,1,1,1,1,1,1,1,1,1,1,1,1,1,1,1,1,1,1,1,1,1,1,1,1,1
1,1,1,1,1,1,1,1,1,1,1,1,1,1,1,1,1,1,1,1,1,1,1,1,1,1,1,1,1,1,1
endlayer

layer
1,1,1,1,1,1,1,1,1,1,1,1,1,1,1,1,1,1,1,1,1,1,1,1,1,1,1,1,1,1,1
1,1,1,1,1,1,1,1,1,1,1,1,1,1,1,1,1,1,1,1,1,1,1,1,1,1,1,1,1,1,1
1,1,1,1,1,1,1,1,1,1,1,1,1,1,1,1,1,1,1,1,1,1,1,1,1,1,1,1,1,1,1
1,1,1,1,1,1,1,1,1,1,1,1,24,24,24,24,24,24,24,1,1,1,1,1,1,1,1,1,1,1,1
1,1,1,1,1,1,1,1,1,24,24,24,0,0,0,0,0,0,0,24,24,24,1,1,1,1,1,1,1,1,1
1,1,1,1,1,1,1,1,24,0,0,0,0,0,0,0,0,0,0,0,0,0,24,1,1,1,1,1,1,1,1
1,1,1,1,1,1,1,24,0,0,0,0,0,0,0,0,0,0,0,0,0,0,0,24,1,1,1,1,1,1,1
1,1,1,1,1,1,24,0,0,0,0,0,0,0,0,0,0,0,0,0,0,0,0,0,24,1,1,1,1,1,1
1,1,1,1,1,24,0,0,0,0,0,0,0,0,0,0,0,0,0,0,0,0,0,0,0,24,1,1,1,1,1
1,1,1,1,24,0,0,0,0,0,0,0,0,0,0,0,0,0,0,0,0,0,0,0,0,0,24,1,1,1,1
1,1,1,1,24,0,0,0,0,0,0,0,0,0,0,0,0,0,0,0,0,0,0,0,0,0,24,1,1,1,1
1,1,1,1,24,0,0,0,0,0,0,0,0,0,0,0,0,0,0,0,0,0,0,0,0,0,24,1,1,1,1
1,1,1,24,0,0,0,0,0,0,0,0,0,0,0,0,0,0,0,0,0,0,0,0,0,0,0,24,1,1,1
1,1,1,24,0,0,0,0,0,0,0,0,0,0,0,0,0,0,0,0,0,0,0,0,0,0,0,24,1,1,1
1,1,1,24,0,0,0,0,0,0,0,0,0,0,0,0,0,0,0,0,0,0,0,0,0,0,0,24,1,1,1
1,1,1,24,0,0,0,0,0,0,0,0,0,0,0,0,0,0,0,0,0,0,0,0,0,0,0,24,1,1,1
1,1,1,24,0,0,0,0,0,0,0,0,0,0,0,0,0,0,0,0,0,0,0,0,0,0,0,24,1,1,1
1,1,1,24,0,0,0,0,0,0,0,0,0,0,0,0,0,0,0,0,0,0,0,0,0,0,0,24,1,1,1
1,1,1,24,0,0,0,0,0,0,0,0,0,0,0,0,0,0,0,0,0,0,0,0,0,0,0,24,1,1,1
1,1,1,1,24,0,0,0,0,0,0,0,0,0,0,0,0,0,0,0,0,0,0,0,0,0,24,1,1,1,1
1,1,1,1,24,0,0,0,0,0,0,0,0,0,0,0,0,0,0,0,0,0,0,0,0,0,24,1,1,1,1
1,1,1,1,24,0,0,0,0,0,0,0,0,0,0,0,0,0,0,0,0,0,0,0,0,0,24,1,1,1,1
1,1,1,1,1,24,0,0,0,0,0,0,0,0,0,0,0,0,0,0,0,0,0,0,0,24,1,1,1,1,1
1,1,1,1,1,1,24,0,0,0,0,0,0,0,0,0,0,0,0,0,0,0,0,0,24,1,1,1,1,1,1
1,1,1,1,1,1,1,24,0,0,0,0,0,0,0,0,0,0,0,0,0,0,0,24,1,1,1,1,1,1,1
1,1,1,1,1,1,1,1,24,0,0,0,0,0,0,0,0,0,0,0,0,0,24,1,1,1,1,1,1,1,1
1,1,1,1,1,1,1,1,1,24,24,24,0,0,0,0,0,0,0,24,24,24,1,1,1,1,1,1,1,1,1
1,1,1,1,1,1,1,1,1,1,1,1,24,24,24,24,24,24,24,1,1,1,1,1,1,1,1,1,1,1,1
1,1,1,1,1,1,1,1,1,1,1,1,1,1,1,1,1,1,1,1,1,1,1,1,1,1,1,1,1,1,1
1,1,1,1,1,1,1,1,1,1,1,1,1,1,1,1,1,1,1,1,1,1,1,1,1,1,1,1,1,1,1
1,1,1,1,1,1,1,1,1,1,1,1,1,1,1,1,1,1,1,1,1,1,1,1,1,1,1,1,1,1,1
endlayer

layer
1,1,1,1,1,1,1,1,1,1,1,1,1,1,1,1,1,1,1,1,1,1,1,1,1,1,1,1,1,1,1
1,1,1,1,1,1,1,1,1,1,1,1,1,1,1,1,1,1,1,1,1,1,1,1,1,1,1,1,1,1,1
1,1,1,1,1,1,1,1,1,1,1,1,1,1,1,1,1,1,1,1,1,1,1,1,1,1,1,1,1,1,1
1,1,1,1,1,1,1,1,1,1,1,1,1,1,1,1,1,1,1,1,1,1,1,1,1,1,1,1,1,1,1
1,1,1,1,1,1,1,1,1,1,1,24,24,24,24,24,24,24,24,24,1,1,1,1,1,1,1,1,1,1,1
1,1,1,1,1,1,1,1,1,24,24,0,0,0,0,0,0,0,0,0,24,24,1,1,1,1,1,1,1,1,1
1,1,1,1,1,1,1,1,24,0,0,0,0,0,0,0,0,0,0,0,0,0,24,1,1,1,1,1,1,1,1
1,1,1,1,1,1,1,24,0,0,0,0,0,0,0,0,0,0,0,0,0,0,0,24,1,1,1,1,1,1,1
1,1,1,1,1,1,24,0,0,0,0,0,0,0,0,0,0,0,0,0,0,0,0,0,24,1,1,1,1,1,1
1,1,1,1,1,24,0,0,0,0,0,0,0,0,0,0,0,0,0,0,0,0,0,0,0,24,1,1,1,1,1
1,1,1,1,1,24,0,0,0,0,0,0,0,0,0,0,0,0,0,0,0,0,0,0,0,24,1,1,1,1,1
1,1,1,1,24,0,0,0,0,0,0,0,0,0,0,0,0,0,0,0,0,0,0,0,0,0,24,1,1,1,1
1,1,1,1,24,0,0,0,0,0,0,0,0,0,0,0,0,0,0,0,0,0,0,0,0,0,24,1,1,1,1
1,1,1,1,24,0,0,0,0,0,0,0,0,0,0,0,0,0,0,0,0,0,0,0,0,0,24,1,1,1,1
1,1,1,1,24,0,0,0,0,0,0,0,0,0,0,0,0,0,0,0,0,0,0,0,0,0,24,1,1,1,1
1,1,1,1,24,0,0,0,0,0,0,0,0,0,0,0,0,0,0,0,0,0,0,0,0,0,24,1,1,1,1
1,1,1,1,24,0,0,0,0,0,0,0,0,0,0,0,0,0,0,0,0,0,0,0,0,0,24,1,1,1,1
1,1,1,1,24,0,0,0,0,0,0,0,0,0,0,0,0,0,0,0,0,0,0,0,0,0,24,1,1,1,1
1,1,1,1,24,0,0,0,0,0,0,0,0,0,0,0,0,0,0,0,0,0,0,0,0,0,24,1,1,1,1
1,1,1,1,24,0,0,0,0,0,0,0,0,0,0,0,0,0,0,0,0,0,0,0,0,0,24,1,1,1,1
1,1,1,1,1,24,0,0,0,0,0,0,0,0,0,0,0,0,0,0,0,0,0,0,0,24,1,1,1,1,1
1,1,1,1,1,24,0,0,0,0,0,0,0,0,0,0,0,0,0,0,0,0,0,0,0,24,1,1,1,1,1
1,1,1,1,1,1,24,0,0,0,0,0,0,0,0,0,0,0,0,0,0,0,0,0,24,1,1,1,1,1,1
1,1,1,1,1,1,1,24,0,0,0,0,0,0,0,0,0,0,0,0,0,0,0,24,1,1,1,1,1,1,1
1,1,1,1,1,1,1,1,24,0,0,0,0,0,0,0,0,0,0,0,0,0,24,1,1,1,1,1,1,1,1
1,1,1,1,1,1,1,1,1,24,24,0,0,0,0,0,0,0,0,0,24,24,1,1,1,1,1,1,1,1,1
1,1,1,1,1,1,1,1,1,1,1,24,24,24,24,24,24,24,24,24,1,1,1,1,1,1,1,1,1,1,1
1,1,1,1,1,1,1,1,1,1,1,1,1,1,1,1,1,1,1,1,1,1,1,1,1,1,1,1,1,1,1
1,1,1,1,1,1,1,1,1,1,1,1,1,1,1,1,1,1,1,1,1,1,1,1,1,1,1,1,1,1,1
1,1,1,1,1,1,1,1,1,1,1,1,1,1,1,1,1,1,1,1,1,1,1,1,1,1,1,1,1,1,1
1,1,1,1,1,1,1,1,1,1,1,1,1,1,1,1,1,1,1,1,1,1,1,1,1,1,1,1,1,1,1
endlayer

layer
1,1,1,1,1,1,1,1,1,1,1,1,1,1,1,1,1,1,1,1,1,1,1,1,1,1,1,1,1,1,1
1,1,1,1,1,1,1,1,1,1,1,1,1,1,1,1,1,1,1,1,1,1,1,1,1,1,1,1,1,1,1
1,1,1,1,1,1,1,1,1,1,1,1,1,1,1,1,1,1,1,1,1,1,1,1,1,1,1,1,1,1,1
1,1,1,1,1,1,1,1,1,1,1,1,1,1,1,1,1,1,1,1,1,1,1,1,1,1,1,1,1,1,1
1,1,1,1,1,1,1,1,1,1,1,1,1,1,1,1,1,1,1,1,1,1,1,1,1,1,1,1,1,1,1
1,1,1,1,1,1,1,1,1,1,1,24,24,24,24,24,24,24,24,24,1,1,1,1,1,1,1,1,1,1,1
1,1,1,1,1,1,1,1,1,24,24,24,0,0,0,0,0,0,0,24,24,24,1,1,1,1,1,1,1,1,1
1,1,1,1,1,1,1,1,24,24,0,0,0,0,0,0,0,0,0,0,0,24,24,1,1,1,1,1,1,1,1
1,1,1,1,1,1,1,24,24,0,0,0,0,0,0,0,0,0,0,0,0,0,24,24,1,1,1,1,1,1,1
1,1,1,1,1,1,24,24,0,0,0,0,0,0,0,0,0,0,0,0,0,0,0,24,24,1,1,1,1,1,1
1,1,1,1,1,1,24,0,0,0,0,0,0,0,0,0,0,0,0,0,0,0,0,0,24,1,1,1,1,1,1
1,1,1,1,1,24,24,0,0,0,0,0,0,0,0,0,0,0,0,0,0,0,0,0,24,24,1,1,1,1,1
1,1,1,1,1,24,0,0,0,0,0,0,0,0,0,0,0,0,0,0,0,0,0,0,0,24,1,1,1,1,1
1,1,1,1,1,24,0,0,0,0,0,0,0,0,0,0,0,0,0,0,0,0,0,0,0,24,1,1,1,1,1
1,1,1,1,1,24,0,0,0,0,0,0,0,0,0,0,0,0,0,0,0,0,0,0,0,24,1,1,1,1,1
1,1,1,1,1,24,0,0,0,0,0,0,0,0,0,0,0,0,0,0,0,0,0,0,0,24,1,1,1,1,1
1,1,1,1,1,24,0,0,0,0,0,0,0,0,0,0,0,0,0,0,0,0,0,0,0,24,1,1,1,1,1
1,1,1,1,1,24,0,0,0,0,0,0,0,0,0,0,0,0,0,0,0,0,0,0,0,24,1,1,1,1,1
1,1,1,1,1,24,0,0,0,0,0,0,0,0,0,0,0,0,0,0,0,0,0,0,0,24,1,1,1,1,1
1,1,1,1,1,24,24,0,0,0,0,0,0,0,0,0,0,0,0,0,0,0,0,0,24,24,1,1,1,1,1
1,1,1,1,1,1,24,0,0,0,0,0,0,0,0,0,0,0,0,0,0,0,0,0,24,1,1,1,1,1,1
1,1,1,1,1,1,24,24,0,0,0,0,0,0,0,0,0,0,0,0,0,0,0,24,24,1,1,1,1,1,1
1,1,1,1,1,1,1,24,24,0,0,0,0,0,0,0,0,0,0,0,0,0,24,24,1,1,1,1,1,1,1
1,1,1,1,1,1,1,1,24,24,0,0,0,0,0,0,0,0,0,0,0,24,24,1,1,1,1,1,1,1,1
1,1,1,1,1,1,1,1,1,24,24,24,0,0,0,0,0,0,0,24,24,24,1,1,1,1,1,1,1,1,1
1,1,1,1,1,1,1,1,1,1,1,24,24,24,24,24,24,24,24,24,1,1,1,1,1,1,1,1,1,1,1
1,1,1,1,1,1,1,1,1,1,1,1,1,1,1,1,1,1,1,1,1,1,1,1,1,1,1,1,1,1,1
1,1,1,1,1,1,1,1,1,1,1,1,1,1,1,1,1,1,1,1,1,1,1,1,1,1,1,1,1,1,1
1,1,1,1,1,1,1,1,1,1,1,1,1,1,1,1,1,1,1,1,1,1,1,1,1,1,1,1,1,1,1
1,1,1,1,1,1,1,1,1,1,1,1,1,1,1,1,1,1,1,1,1,1,1,1,1,1,1,1,1,1,1
1,1,1,1,1,1,1,1,1,1,1,1,1,1,1,1,1,1,1,1,1,1,1,1,1,1,1,1,1,1,1
endlayer

layer
1,1,1,1,1,1,1,1,1,1,1,1,1,1,1,1,1,1,1,1,1,1,1,1,1,1,1,1,1,1,1
1,1,1,1,1,1,1,1,1,1,1,1,1,1,1,1,1,1,1,1,1,1,1,1,1,1,1,1,1,1,1
1,1,1,1,1,1,1,1,1,1,1,1,1,1,1,1,1,1,1,1,1,1,1,1,1,1,1,1,1,1,1
1,1,1,1,1,1,1,1,1,1,1,1,1,1,1,1,1,1,1,1,1,1,1,1,1,1,1,1,1,1,1
1,1,1,1,1,1,1,1,1,1,1,1,1,1,1,1,1,1,1,1,1,1,1,1,1,1,1,1,1,1,1
1,1,1,1,1,1,1,1,1,1,1,1,1,1,1,1,1,1,1,1,1,1,1,1,1,1,1,1,1,1,1
1,1,1,1,1,1,1,1,1,1,1,1,24,24,24,24,24,24,24,1,1,1,1,1,1,1,1,1,1,1,1
1,1,1,1,1,1,1,1,1,1,24,24,24,0,0,0,0,0,24,24,24,1,1,1,1,1,1,1,1,1,1
1,1,1,1,1,1,1,1,1,24,24,0,0,0,0,0,0,0,0,0,24,24,1,1,1,1,1,1,1,1,1
1,1,1,1,1,1,1,1,24,24,0,0,0,0,0,0,0,0,0,0,0,24,24,1,1,1,1,1,1,1,1
1,1,1,1,1,1,1,24,24,0,0,0,0,0,0,0,0,0,0,0,0,0,24,24,1,1,1,1,1,1,1
1,1,1,1,1,1,1,24,0,0,0,0,0,0,0,0,0,0,0,0,0,0,0,24,1,1,1,1,1,1,1
1,1,1,1,1,1,24,24,0,0,0,0,0,0,0,0,0,0,0,0,0,0,0,24,24,1,1,1,1,1,1
1,1,1,1,1,1,24,0,0,0,0,0,0,0,0,0,0,0,0,0,0,0,0,0,24,1,1,1,1,1,1
1,1,1,1,1,1,24,0,0,0,0,0,0,0,0,0,0,0,0,0,0,0,0,0,24,1,1,1,1,1,1
1,1,1,1,1,1,24,0,0,0,0,0,0,0,0,0,0,0,0,0,0,0,0,0,24,1,1,1,1,1,1
1,1,1,1,1,1,24,0,0,0,0,0,0,0,0,0,0,0,0,0,0,0,0,0,24,1,1,1,1,1,1
1,1,1,1,1,1,24,0,0,0,0,0,0,0,0,0,0,0,0,0,0,0,0,0,24,1,1,1,1,1,1
1,1,1,1,1,1,24,24,0,0,0,0,0,0,0,0,0,0,0,0,0,0,0,24,24,1,1,1,1,1,1
1,1,1,1,1,1,1,24,0,0,0,0,0,0,0,0,0,0,0,0,0,0,0,24,1,1,1,1,1,1,1
1,1,1,1,1,1,1,24,24,0,0,0,0,0,0,0,0,0,0,0,0,0,24,24,1,1,1,1,1,1,1
1,1,1,1,1,1,1,1,24,24,0,0,0,0,0,0,0,0,0,0,0,24,24,1,1,1,1,1,1,1,1
1,1,1,1,1,1,1,1,1,24,24,0,0,0,0,0,0,0,0,0,24,24,1,1,1,1,1,1,1,1,1
1,1,1,1,1,1,1,1,1,1,24,24,24,0,0,0,0,0,24,24,24,1,1,1,1,1,1,1,1,1,1
1,1,1,1,1,1,1,1,1,1,1,1,24,24,24,24,24,24,24,1,1,1,1,1,1,1,1,1,1,1,1
1,1,1,1,1,1,1,1,1,1,1,1,1,1,1,1,1,1,1,1,1,1,1,1,1,1,1,1,1,1,1
1,1,1,1,1,1,1,1,1,1,1,1,1,1,1,1,1,1,1,1,1,1,1,1,1,1,1,1,1,1,1
1,1,1,1,1,1,1,1,1,1,1,1,1,1,1,1,1,1,1,1,1,1,1,1,1,1,1,1,1,1,1
1,1,1,1,1,1,1,1,1,1,1,1,1,1,1,1,1,1,1,1,1,1,1,1,1,1,1,1,1,1,1
1,1,1,1,1,1,1,1,1,1,1,1,1,1,1,1,1,1,1,1,1,1,1,1,1,1,1,1,1,1,1
1,1,1,1,1,1,1,1,1,1,1,1,1,1,1,1,1,1,1,1,1,1,1,1,1,1,1,1,1,1,1
endlayer

layer
1,1,1,1,1,1,1,1,1,1,1,1,1,1,1,1,1,1,1,1,1,1,1,1,1,1,1,1,1,1,1
1,1,1,1,1,1,1,1,1,1,1,1,1,1,1,1,1,1,1,1,1,1,1,1,1,1,1,1,1,1,1
1,1,1,1,1,1,1,1,1,1,1,1,1,1,1,1,1,1,1,1,1,1,1,1,1,1,1,1,1,1,1
1,1,1,1,1,1,1,1,1,1,1,1,1,1,1,1,1,1,1,1,1,1,1,1,1,1,1,1,1,1,1
1,1,1,1,1,1,1,1,1,1,1,1,1,1,1,1,1,1,1,1,1,1,1,1,1,1,1,1,1,1,1
1,1,1,1,1,1,1,1,1,1,1,1,1,1,1,1,1,1,1,1,1,1,1,1,1,1,1,1,1,1,1
1,1,1,1,1,1,1,1,1,1,1,1,1,1,1,1,1,1,1,1,1,1,1,1,1,1,1,1,1,1,1
1,1,1,1,1,1,1,1,1,1,1,1,1,24,24,24,24,24,1,1,1,1,1,1,1,1,1,1,1,1,1
1,1,1,1,1,1,1,1,1,1,1,24,24,24,24,24,24,24,24,24,1,1,1,1,1,1,1,1,1,1,1
1,1,1,1,1,1,1,1,1,1,24,24,24,0,0,0,0,0,24,24,24,1,1,1,1,1,1,1,1,1,1
1,1,1,1,1,1,1,1,1,24,24,0,0,0,0,0,0,0,0,0,24,24,1,1,1,1,1,1,1,1,1
1,1,1,1,1,1,1,1,24,24,0,0,0,0,0,0,0,0,0,0,0,24,24,1,1,1,1,1,1,1,1
1,1,1,1,1,1,1,1,24,24,0,0,0,0,0,0,0,0,0,0,0,24,24,1,1,1,1,1,1,1,1
1,1,1,1,1,1,1,24,24,0,0,0,0,0,0,0,0,0,0,0,0,0,24,24,1,1,1,1,1,1,1
1,1,1,1,1,1,1,24,24,0,0,0,0,0,0,0,0,0,0,0,0,0,24,24,1,1,1,1,1,1,1
1,1,1,1,1,1,1,24,24,0,0,0,0,0,0,0,0,0,0,0,0,0,24,24,1,1,1,1,1,1,1
1,1,1,1,1,1,1,24,24,0,0,0,0,0,0,0,0,0,0,0,0,0,24,24,1,1,1,1,1,1,1
1,1,1,1,1,1,1,24,24,0,0,0,0,0,0,0,0,0,0,0,0,0,24,24,1,1,1,1,1,1,1
1,1,1,1,1,1,1,1,24,24,0,0,0,0,0,0,0,0,0,0,0,24,24,1,1,1,1,1,1,1,1
1,1,1,1,1,1,1,1,24,24,0,0,0,0,0,0,0,0,0,0,0,24,24,1,1,1,1,1,1,1,1
1,1,1,1,1,1,1,1,1,24,24,0,0,0,0,0,0,0,0,0,24,24,1,1,1,1,1,1,1,1,1
1,1,1,1,1,1,1,1,1,1,24,24,24,0,0,0,0,0,24,24,24,1,1,1,1,1,1,1,1,1,1
1,1,1,1,1,1,1,1,1,1,1,24,24,24,24,24,24,24,24,24,1,1,1,1,1,1,1,1,1,1,1
1,1,1,1,1,1,1,1,1,1,1,1,1,24,24,24,24,24,1,1,1,1,1,1,1,1,1,1,1,1,1
1,1,1,1,1,1,1,1,1,1,1,1,1,1,1,1,1,1,1,1,1,1,1,1,1,1,1,1,1,1,1
1,1,1,1,1,1,1,1,1,1,1,1,1,1,1,1,1,1,1,1,1,1,1,1,1,1,1,1,1,1,1
1,1,1,1,1,1,1,1,1,1,1,1,1,1,1,1,1,1,1,1,1,1,1,1,1,1,1,1,1,1,1
1,1,1,1,1,1,1,1,1,1,1,1,1,1,1,1,1,1,1,1,1,1,1,1,1,1,1,1,1,1,1
1,1,1,1,1,1,1,1,1,1,1,1,1,1,1,1,1,1,1,1,1,1,1,1,1,1,1,1,1,1,1
1,1,1,1,1,1,1,1,1,1,1,1,1,1,1,1,1,1,1,1,1,1,1,1,1,1,1,1,1,1,1
1,1,1,1,1,1,1,1,1,1,1,1,1,1,1,1,1,1,1,1,1,1,1,1,1,1,1,1,1,1,1
endlayer

layer
1,1,1,1,1,1,1,1,1,1,1,1,1,1,1,1,1,1,1,1,1,1,1,1,1,1,1,1,1,1,1
1,1,1,1,1,1,1,1,1,1,1,1,1,1,1,1,1,1,1,1,1,1,1,1,1,1,1,1,1,1,1
1,1,1,1,1,1,1,1,1,1,1,1,1,1,1,1,1,1,1,1,1,1,1,1,1,1,1,1,1,1,1
1,1,1,1,1,1,1,1,1,1,1,1,1,1,1,1,1,1,1,1,1,1,1,1,1,1,1,1,1,1,1
1,1,1,1,1,1,1,1,1,1,1,1,1,1,1,1,1,1,1,1,1,1,1,1,1,1,1,1,1,1,1
1,1,1,1,1,1,1,1,1,1,1,1,1,1,1,1,1,1,1,1,1,1,1,1,1,1,1,1,1,1,1
1,1,1,1,1,1,1,1,1,1,1,1,1,1,1,1,1,1,1,1,1,1,1,1,1,1,1,1,1,1,1
1,1,1,1,1,1,1,1,1,1,1,1,1,1,1,1,1,1,1,1,1,1,1,1,1,1,1,1,1,1,1
1,1,1,1,1,1,1,1,1,1,1,1,1,1,1,1,1,1,1,1,1,1,1,1,1,1,1,1,1,1,1
1,1,1,1,1,1,1,1,1,1,1,1,1,24,24,24,24,24,1,1,1,1,1,1,1,1,1,1,1,1,1
1,1,1,1,1,1,1,1,1,1,1,24,24,24,24,24,24,24,24,24,1,1,1,1,1,1,1,1,1,1,1
1,1,1,1,1,1,1,1,1,1,24,24,24,24,24,24,24,24,24,24,24,1,1,1,1,1,1,1,1,1,1
1,1,1,1,1,1,1,1,1,1,24,24,24,0,0,0,0,0,24,24,24,1,1,1,1,1,1,1,1,1,1
1,1,1,1,1,1,1,1,1,24,24,24,0,0,0,0,0,0,0,24,24,24,1,1,1,1,1,1,1,1,1
1,1,1,1,1,1,1,1,1,24,24,24,0,0,0,0,0,0,0,24,24,24,1,1,1,1,1,1,1,1,1
1,1,1,1,1,1,1,1,1,24,24,24,0,0,0,0,0,0,0,24,24,24,1,1,1,1,1,1,1,1,1
1,1,1,1,1,1,1,1,1,24,24,24,0,0,0,0,0,0,0,24,24,24,1,1,1,1,1,1,1,1,1
1,1,1,1,1,1,1,1,1,24,24,24,0,0,0,0,0,0,0,24,24,24,1,1,1,1,1,1,1,1,1
1,1,1,1,1,1,1,1,1,1,24,24,24,0,0,0,0,0,24,24,24,1,1,1,1,1,1,1,1,1,1
1,1,1,1,1,1,1,1,1,1,24,24,24,24,24,24,24,24,24,24,24,1,1,1,1,1,1,1,1,1,1
1,1,1,1,1,1,1,1,1,1,1,24,24,24,24,24,24,24,24,24,1,1,1,1,1,1,1,1,1,1,1
1,1,1,1,1,1,1,1,1,1,1,1,1,24,24,24,24,24,1,1,1,1,1,1,1,1,1,1,1,1,1
1,1,1,1,1,1,1,1,1,1,1,1,1,1,1,1,1,1,1,1,1,1,1,1,1,1,1,1,1,1,1
1,1,1,1,1,1,1,1,1,1,1,1,1,1,1,1,1,1,1,1,1,1,1,1,1,1,1,1,1,1,1
1,1,1,1,1,1,1,1,1,1,1,1,1,1,1,1,1,1,1,1,1,1,1,1,1,1,1,1,1,1,1
1,1,1,1,1,1,1,1,1,1,1,1,1,1,1,1,1,1,1,1,1,1,1,1,1,1,1,1,1,1,1
1,1,1,1,1,1,1,1,1,1,1,1,1,1,1,1,1,1,1,1,1,1,1,1,1,1,1,1,1,1,1
1,1,1,1,1,1,1,1,1,1,1,1,1,1,1,1,1,1,1,1,1,1,1,1,1,1,1,1,1,1,1
1,1,1,1,1,1,1,1,1,1,1,1,1,1,1,1,1,1,1,1,1,1,1,1,1,1,1,1,1,1,1
1,1,1,1,1,1,1,1,1,1,1,1,1,1,1,1,1,1,1,1,1,1,1,1,1,1,1,1,1,1,1
1,1,1,1,1,1,1,1,1,1,1,1,1,1,1,1,1,1,1,1,1,1,1,1,1,1,1,1,1,1,1
endlayer

layer
1,1,1,1,1,1,1,1,1,1,1,1,1,1,1,1,1,1,1,1,1,1,1,1,1,1,1,1,1,1,1
1,1,1,1,1,1,1,1,1,1,1,1,1,1,1,1,1,1,1,1,1,1,1,1,1,1,1,1,1,1,1
1,1,1,1,1,1,1,1,1,1,1,1,1,1,1,1,1,1,1,1,1,1,1,1,1,1,1,1,1,1,1
1,1,1,1,1,1,1,1,1,1,1,1,1,1,1,1,1,1,1,1,1,1,1,1,1,1,1,1,1,1,1
1,1,1,1,1,1,1,1,1,1,1,1,1,1,1,1,1,1,1,1,1,1,1,1,1,1,1,1,1,1,1
1,1,1,1,1,1,1,1,1,1,1,1,1,1,1,1,1,1,1,1,1,1,1,1,1,1,1,1,1,1,1
1,1,1,1,1,1,1,1,1,1,1,1,1,1,1,1,1,1,1,1,1,1,1,1,1,1,1,1,1,1,1
1,1,1,1,1,1,1,1,1,1,1,1,1,1,1,1,1,1,1,1,1,1,1,1,1,1,1,1,1,1,1
1,1,1,1,1,1,1,1,1,1,1,1,1,1,1,1,1,1,1,1,1,1,1,1,1,1,1,1,1,1,1
1,1,1,1,1,1,1,1,1,1,1,1,1,1,1,1,1,1,1,1,1,1,1,1,1,1,1,1,1,1,1
1,1,1,1,1,1,1,1,1,1,1,1,1,1,1,1,1,1,1,1,1,1,1,1,1,1,1,1,1,1,1
1,1,1,1,1,1,1,1,1,1,1,1,1,1,1,1,1,1,1,1,1,1,1,1,1,1,1,1,1,1,1
1,1,1,1,1,1,1,1,1,1,1,1,1,24,24,24,24,24,1,1,1,1,1,1,1,1,1,1,1,1,1
1,1,1,1,1,1,1,1,1,1,1,1,24,24,24,24,24,24,24,1,1,1,1,1,1,1,1,1,1,1,1
1,1,1,1,1,1,1,1,1,1,1,1,24,24,24,24,24,24,24,1,1,1,1,1,1,1,1,1,1,1,1
1,1,1,1,1,1,1,1,1,1,1,1,24,24,24,24,24,24,24,1,1,1,1,1,1,1,1,1,1,1,1
1,1,1,1,1,1,1,1,1,1,1,1,24,24,24,24,24,24,24,1,1,1,1,1,1,1,1,1,1,1,1
1,1,1,1,1,1,1,1,1,1,1,1,24,24,24,24,24,24,24,1,1,1,1,1,1,1,1,1,1,1,1
1,1,1,1,1,1,1,1,1,1,1,1,1,24,24,24,24,24,1,1,1,1,1,1,1,1,1,1,1,1,1
1,1,1,1,1,1,1,1,1,1,1,1,1,1,1,1,1,1,1,1,1,1,1,1,1,1,1,1,1,1,1
1,1,1,1,1,1,1,1,1,1,1,1,1,1,1,1,1,1,1,1,1,1,1,1,1,1,1,1,1,1,1
1,1,1,1,1,1,1,1,1,1,1,1,1,1,1,1,1,1,1,1,1,1,1,1,1,1,1,1,1,1,1
1,1,1,1,1,1,1,1,1,1,1,1,1,1,1,1,1,1,1,1,1,1,1,1,1,1,1,1,1,1,1
1,1,1,1,1,1,1,1,1,1,1,1,1,1,1,1,1,1,1,1,1,1,1,1,1,1,1,1,1,1,1
1,1,1,1,1,1,1,1,1,1,1,1,1,1,1,1,1,1,1,1,1,1,1,1,1,1,1,1,1,1,1
1,1,1,1,1,1,1,1,1,1,1,1,1,1,1,1,1,1,1,1,1,1,1,1,1,1,1,1,1,1,1
1,1,1,1,1,1,1,1,1,1,1,1,1,1,1,1,1,1,1,1,1,1,1,1,1,1,1,1,1,1,1
1,1,1,1,1,1,1,1,1,1,1,1,1,1,1,1,1,1,1,1,1,1,1,1,1,1,1,1,1,1,1
1,1,1,1,1,1,1,1,1,1,1,1,1,1,1,1,1,1,1,1,1,1,1,1,1,1,1,1,1,1,1
1,1,1,1,1,1,1,1,1,1,1,1,1,1,1,1,1,1,1,1,1,1,1,1,1,1,1,1,1,1,1
1,1,1,1,1,1,1,1,1,1,1,1,1,1,1,1,1,1,1,1,1,1,1,1,1,1,1,1,1,1,1
endlayer

