
# Created by Ruins mod version 16.7 Ingame Parser
# authoring Player: ST753M

# A "swimming" concrete shark

weight=1
embed_into_distance=13
acceptable_target_blocks=water
unacceptable_target_blocks=
dimensions=10,23,9
allowable_overhang=0
max_leveling=0
leveling_buffer=0
preserve_water=0
preserve_lava=0

biomesToSpawnIn=deep_ocean

rule1=0,100,preserveBlock
rule2=0,100,minecraft:concrete-8
rule3=0,30,IInventory;minecraft:chest;minecraft:rotten_flesh#1#0#1+minecraft:fish#2#0#2+minecraft:rotten_flesh#4#0#5+minecraft:air#0#0#6+minecraft:rotten_flesh#1#0#7+minecraft:leather_leggings#{ench:[{lvl:3s,id:7s}],RepairCost:1,display:{color:7567221,Name:"Sharkskin Pants"}}#0#8+minecraft:rotten_flesh#3#0#9+minecraft:leather_helmet#{ench:[{lvl:3s,id:7s},{lvl:3s,id:5s},{lvl:1s,id:6s}],RepairCost:7,display:{color:7567221,Name:"Sharkskin Cap"}}#0#11+minecraft:rotten_flesh#1#0#13+minecraft:fish#1#0#16+minecraft:rotten_flesh#1#0#18+minecraft:fish#1#0#19+minecraft:leather_chestplate#{ench:[{lvl:3s,id:7s}],RepairCost:1,display:{color:7567221,Name:"Sharkskin Tunic"}}#0#21+minecraft:leather_boots#{ench:[{lvl:3s,id:7s},{lvl:3s,id:8s}],RepairCost:3,display:{color:7567221,Name:"Sharkskin Boots"}}#0#23+minecraft:rotten_flesh#2#0#26-5
rule4=0,100,minecraft:concrete-7

layer
1,1,1,1,1,1,1,1,1
1,1,1,1,1,1,1,1,1
1,1,1,1,1,1,1,1,1
1,1,1,1,1,1,1,1,1
1,1,1,1,1,1,1,1,1
1,1,1,1,1,1,1,1,1
1,1,1,1,1,1,1,1,1
1,1,1,1,1,1,1,1,1
1,1,1,1,1,1,1,1,1
1,1,1,1,1,1,1,1,1
1,1,1,1,1,1,1,1,1
1,1,1,1,2,1,1,1,1
1,1,1,1,2,1,1,1,1
1,1,1,1,1,1,1,1,1
1,1,1,1,1,1,1,1,1
1,1,1,1,1,1,1,1,1
1,1,1,1,2,1,1,1,1
1,1,1,1,2,1,1,1,1
1,1,1,1,1,1,1,1,1
1,1,1,1,1,1,1,1,1
1,1,1,1,1,1,1,1,1
1,1,1,1,1,1,1,1,1
1,1,1,1,1,1,1,1,1
endlayer

layer
1,1,1,1,1,1,1,1,1
1,1,1,1,1,1,1,1,1
1,1,1,1,2,1,1,1,1
1,1,1,1,2,1,1,1,1
1,1,1,1,1,1,1,1,1
1,1,1,1,1,1,1,1,1
1,1,1,1,1,1,1,1,1
1,1,1,1,1,1,1,1,1
1,1,1,1,1,1,1,1,1
1,1,1,1,1,1,1,1,1
1,1,1,1,1,1,1,1,1
1,1,1,1,1,1,1,1,1
1,1,1,1,2,1,1,1,1
1,1,1,2,2,2,1,1,1
1,1,1,1,1,1,1,1,1
1,1,1,1,1,1,1,1,1
1,1,1,1,1,1,1,1,1
1,1,1,1,2,1,1,1,1
1,1,1,1,2,1,1,1,1
1,1,1,1,1,1,1,1,1
1,1,1,1,1,1,1,1,1
1,1,1,1,1,1,1,1,1
1,1,1,1,1,1,1,1,1
endlayer

layer
1,1,1,1,1,1,1,1,1
1,1,1,1,1,1,1,1,1
1,1,1,1,1,1,1,1,1
1,1,1,1,2,1,1,1,1
1,1,1,1,2,1,1,1,1
1,1,1,1,1,1,1,1,1
1,1,1,1,1,1,1,1,1
1,1,1,1,2,1,1,1,1
1,1,1,1,2,1,1,1,1
1,1,1,1,2,1,1,1,1
1,1,1,2,2,2,1,1,1
1,1,1,2,2,2,1,1,1
1,1,1,2,2,2,1,1,1
2,1,1,2,2,2,1,1,2
2,2,1,2,2,2,1,2,2
2,2,1,2,2,2,1,2,2
1,1,1,2,2,2,1,1,1
1,1,1,2,2,2,1,1,1
1,1,1,1,2,1,1,1,1
1,1,1,1,2,1,1,1,1
1,1,1,1,2,1,1,1,1
1,1,1,1,1,1,1,1,1
1,1,1,1,1,1,1,1,1
endlayer

layer
1,1,1,1,1,1,1,1,1
1,1,1,1,1,1,1,1,1
1,1,1,1,1,1,1,1,1
1,1,1,1,1,1,1,1,1
1,1,1,1,2,1,1,1,1
1,1,1,1,2,1,1,1,1
1,1,1,1,2,1,1,1,1
1,1,1,1,2,1,1,1,1
1,1,1,2,2,2,1,1,1
1,1,1,2,2,2,1,1,1
1,1,1,2,2,2,1,1,1
1,1,1,2,2,2,1,1,1
1,1,1,2,3,2,1,1,1
1,1,1,2,1,2,1,1,1
1,2,1,2,1,2,1,2,1
1,2,2,2,1,2,2,2,1
1,2,2,2,1,2,2,2,1
1,1,2,2,1,2,2,1,1
1,1,1,2,1,2,1,1,1
1,1,1,2,1,2,1,1,1
2,1,1,2,1,2,1,1,2
2,2,2,2,1,2,2,2,2
2,2,2,1,1,1,2,2,2
endlayer

layer
1,1,1,1,1,1,1,1,1
1,1,1,1,1,1,1,1,1
1,1,1,1,1,1,1,1,1
1,1,1,1,1,1,1,1,1
1,1,1,1,2,1,1,1,1
1,1,1,1,2,1,1,1,1
1,1,1,2,2,2,1,1,1
1,1,1,2,2,2,1,1,1
1,1,1,2,2,2,1,1,1
1,1,1,2,2,2,1,1,1
1,1,1,2,2,2,1,1,1
1,1,1,2,2,2,1,1,1
1,1,1,2,1,2,1,1,1
1,1,1,2,1,2,1,1,1
1,1,1,2,1,2,1,1,1
1,1,1,2,1,2,1,1,1
1,1,1,2,1,2,1,1,1
1,1,1,2,1,2,1,1,1
1,1,1,2,1,2,1,1,1
1,1,1,2,1,2,1,1,1
2,1,1,2,1,2,1,1,2
4,2,2,2,1,2,2,2,4
2,2,2,2,2,2,2,2,2
endlayer

layer
1,1,1,1,1,1,1,1,1
1,1,1,1,1,1,1,1,1
1,1,1,1,1,1,1,1,1
1,1,1,1,2,1,1,1,1
1,1,1,1,2,1,1,1,1
1,1,1,2,2,2,1,1,1
1,1,1,2,2,2,1,1,1
1,1,1,1,2,1,1,1,1
1,1,1,1,1,1,1,1,1
1,1,1,1,2,1,1,1,1
1,1,1,1,2,1,1,1,1
1,1,1,2,2,2,1,1,1
1,1,1,2,2,2,1,1,1
1,1,1,2,2,2,1,1,1
1,1,1,2,1,2,1,1,1
1,1,1,2,1,2,1,1,1
1,1,1,2,1,2,1,1,1
1,1,1,2,1,2,1,1,1
1,1,1,2,2,2,1,1,1
1,1,1,1,2,1,1,1,1
1,1,1,2,2,2,1,1,1
1,1,1,2,2,2,1,1,1
1,1,1,1,1,1,1,1,1
endlayer

layer
1,1,1,1,1,1,1,1,1
1,1,1,1,1,1,1,1,1
1,1,1,1,1,1,1,1,1
1,1,1,1,2,1,1,1,1
1,1,1,2,2,2,1,1,1
1,1,1,1,2,1,1,1,1
1,1,1,1,1,1,1,1,1
1,1,1,1,1,1,1,1,1
1,1,1,1,1,1,1,1,1
1,1,1,1,1,1,1,1,1
1,1,1,1,1,1,1,1,1
1,1,1,1,1,1,1,1,1
1,1,1,1,1,1,1,1,1
1,1,1,1,1,1,1,1,1
1,1,1,1,2,1,1,1,1
1,1,1,2,2,2,1,1,1
1,1,1,2,2,2,1,1,1
1,1,1,1,2,1,1,1,1
1,1,1,1,1,1,1,1,1
1,1,1,1,1,1,1,1,1
1,1,1,1,1,1,1,1,1
1,1,1,1,1,1,1,1,1
1,1,1,1,1,1,1,1,1
endlayer

layer
1,1,1,1,1,1,1,1,1
1,1,1,1,1,1,1,1,1
1,1,1,1,2,1,1,1,1
1,1,1,1,2,1,1,1,1
1,1,1,1,2,1,1,1,1
1,1,1,1,1,1,1,1,1
1,1,1,1,1,1,1,1,1
1,1,1,1,1,1,1,1,1
1,1,1,1,1,1,1,1,1
1,1,1,1,1,1,1,1,1
1,1,1,1,1,1,1,1,1
1,1,1,1,1,1,1,1,1
1,1,1,1,1,1,1,1,1
1,1,1,1,1,1,1,1,1
1,1,1,1,2,1,1,1,1
1,1,1,2,2,2,1,1,1
1,1,1,1,2,1,1,1,1
1,1,1,1,1,1,1,1,1
1,1,1,1,1,1,1,1,1
1,1,1,1,1,1,1,1,1
1,1,1,1,1,1,1,1,1
1,1,1,1,1,1,1,1,1
1,1,1,1,1,1,1,1,1
endlayer

layer
1,1,1,1,2,1,1,1,1
1,1,1,1,2,1,1,1,1
1,1,1,1,2,1,1,1,1
1,1,1,1,2,1,1,1,1
1,1,1,1,1,1,1,1,1
1,1,1,1,1,1,1,1,1
1,1,1,1,1,1,1,1,1
1,1,1,1,1,1,1,1,1
1,1,1,1,1,1,1,1,1
1,1,1,1,1,1,1,1,1
1,1,1,1,1,1,1,1,1
1,1,1,1,1,1,1,1,1
1,1,1,1,1,1,1,1,1
1,1,1,1,1,1,1,1,1
1,1,1,1,2,1,1,1,1
1,1,1,1,2,1,1,1,1
1,1,1,1,1,1,1,1,1
1,1,1,1,1,1,1,1,1
1,1,1,1,1,1,1,1,1
1,1,1,1,1,1,1,1,1
1,1,1,1,1,1,1,1,1
1,1,1,1,1,1,1,1,1
1,1,1,1,1,1,1,1,1
endlayer

layer
1,1,1,1,1,1,1,1,1
1,1,1,1,1,1,1,1,1
1,1,1,1,1,1,1,1,1
1,1,1,1,1,1,1,1,1
1,1,1,1,1,1,1,1,1
1,1,1,1,1,1,1,1,1
1,1,1,1,1,1,1,1,1
1,1,1,1,1,1,1,1,1
1,1,1,1,1,1,1,1,1
1,1,1,1,1,1,1,1,1
1,1,1,1,1,1,1,1,1
1,1,1,1,1,1,1,1,1
1,1,1,1,1,1,1,1,1
1,1,1,1,2,1,1,1,1
1,1,1,1,2,1,1,1,1
1,1,1,1,1,1,1,1,1
1,1,1,1,1,1,1,1,1
1,1,1,1,1,1,1,1,1
1,1,1,1,1,1,1,1,1
1,1,1,1,1,1,1,1,1
1,1,1,1,1,1,1,1,1
1,1,1,1,1,1,1,1,1
1,1,1,1,1,1,1,1,1
endlayer

