
# Created by Ruins mod version 16.7 Ingame Parser
# authoring Player: ST753M

weight=1
embed_into_distance=6
acceptable_target_blocks=
unacceptable_target_blocks=flowing_water,water,flowing_lava,lava,ice,bedrock,netherrack,nether_brick,nether_brick_fence,soul_sand,quartz_ore,end_stone,obsidian,iron_bars,Natura:Cloud,slime_grass,slime_congealed,slime_dirt,clouds,natura:clouds
dimensions=16,17,17

allowable_overhang=6
max_leveling=0
leveling_buffer=0
preserve_water=1
preserve_lava=1
uniqueMinDistance=1500

biomesToSpawnIn=deep_ocean
=0,100,air


rule1=0,100,preserveBlock
rule2=0,100,minecraft:stone-0
rule3=0,100,minecraft:cobblestone-0
rule4=0,100,minecraft:water-0
rule5=0,100,ChestGenHook:chests/simple_dungeon:2-5,air,ChestGenHook:chests/village_blacksmith:2-5,air,air,air,air
rule6=0,100,ChestGenHook:chests/simple_dungeon:2-3,air,ChestGenHook:chests/village_blacksmith:2-3,air,air,air,air
rule7=0,100,ChestGenHook:chests/simple_dungeon:2-2,air,ChestGenHook:chests/village_blacksmith:2-2,air,air,air,air
rule8=0,100,minecraft:ladder-4
rule9=0,100,MobSpawner:Skeleton,MobSpawner:Zombie,air,air
rule10=0,100,minecraft:grass-0
rule11=0,100,minecraft:dirt-0
rule12=0,100,minecraft:log-4
rule13=0,100,minecraft:trapdoor-9
rule14=0,100,minecraft:log-8
rule15=0,100,minecraft:farmland-7
rule16=0,100,minecraft:farmland-0
rule17=0,100,minecraft:tallgrass-1
rule18=0,100,minecraft:red_flower-0
rule19=0,100,minecraft:log-0
rule20=0,100,minecraft:planks-0
rule21=0,100,CommandBlock:RUINSTRIGGER /summon Villager ~ ~ ~:@-1
rule22=0,100,minecraft:spruce_stairs-3
rule23=0,100,minecraft:spruce_fence-0
rule24=0,100,minecraft:spruce_stairs-2
rule25=0,100,minecraft:bed-9
rule26=0,100,minecraft:yellow_flower-0
rule27=0,100,minecraft:wooden_door-3
rule28=0,100,minecraft:bed-1
rule29=0,100,minecraft:bookshelf-0
rule30=2,100,WallSign:null:null:null:null-4
rule31=0,100,minecraft:fence-0
rule32=0,100,minecraft:crafting_table-0
rule33=2,100,WallSign:null:null:null:null-5
rule34=0,100,minecraft:anvil-9
rule35=0,100,minecraft:wooden_door-0
rule36=0,100,CommandBlock:RUINSTRIGGER /summon Sheep ~ ~ ~:@-1,CommandBlock:RUINSTRIGGER /summon Cow ~ ~ ~:@-1,CommandBlock:RUINSTRIGGER /summon  ~ ~ ~:@-1,CommandBlock:RUINSTRIGGER /summon Chicken ~ ~ ~:@-1,CommandBlock:RUINSTRIGGER /summon Llama ~ ~ ~:@-1,CommandBlock:RUINSTRIGGER /summon Pig ~ ~ ~:@-1
rule37=0,100,minecraft:fence_gate-2
rule38=0,100,minecraft:potatoes-1
rule39=0,100,minecraft:potatoes-2
rule40=0,100,minecraft:potatoes-0
rule41=0,100,minecraft:potatoes-3
rule42=0,100,minecraft:wheat-0
rule43=0,100,minecraft:wheat-1
rule44=0,100,minecraft:wheat-3
rule45=0,100,minecraft:wheat-2
rule46=0,100,minecraft:wheat-4
rule47=0,100,minecraft:stained_glass-13
^0,100,minecraft:stained_glass-0
^0,100,minecraft:stained_glass-9
^0,100,minecraft:stained_glass-3
^0,100,minecraft:stained_glass-11
^0,100,minecraft:stained_glass-8
^0,100,minecraft:stained_glass-7
^0,100,minecraft:glass-0
rule48=0,100,minecraft:glass_pane-0
rule49=0,100,minecraft:carpet-12
rule50=0,100,minecraft:wooden_door-9
rule51=0,100,minecraft:wooden_door-8
rule52=1,100,minecraft:torch-5
rule53=2,100,minecraft:torch-2
rule54=2,100,minecraft:torch-3
rule55=0,100,minecraft:spruce_stairs-0
rule56=0,100,minecraft:wooden_slab-9
rule57=0,100,minecraft:spruce_stairs-1
rule58=0,100,minecraft:planks-1

layer
1,1,1,1,1,1,2,2,2,2,2,1,1,1,1,1,1
1,1,1,1,2,2,2,2,2,2,2,2,2,1,1,1,1
1,1,1,2,2,2,2,2,2,2,2,2,2,2,1,1,1
1,1,2,2,2,2,2,2,2,2,2,2,2,2,2,1,1
1,2,2,2,2,2,2,2,2,2,2,2,2,2,2,2,1
1,2,2,2,2,2,2,2,2,2,2,2,2,2,2,2,1
2,2,2,2,2,2,2,2,2,2,2,2,2,2,2,2,2
2,2,2,2,2,2,2,2,2,2,2,2,2,2,2,2,2
2,2,2,2,2,2,2,2,2,2,2,2,2,2,2,2,2
2,2,2,2,2,2,2,2,2,2,2,2,2,2,2,2,2
2,2,2,2,2,2,2,2,2,2,2,2,2,2,2,2,2
1,2,2,2,2,2,2,2,2,2,2,2,2,2,2,2,1
1,2,2,2,2,2,2,2,2,2,2,2,2,2,2,2,1
1,1,2,2,2,2,2,2,2,2,2,2,2,2,2,1,1
1,1,1,2,2,2,2,2,2,2,2,2,2,2,1,1,1
1,1,1,1,2,2,2,2,2,2,2,2,2,1,1,1,1
1,1,1,1,1,1,2,2,2,2,2,1,1,1,1,1,1
endlayer

layer
1,1,1,1,1,1,2,2,2,2,2,1,1,1,1,1,1
1,1,1,1,2,2,3,3,3,3,3,3,2,1,1,1,1
1,1,1,2,2,3,3,3,3,3,3,3,3,2,1,1,1
1,1,2,2,2,3,3,3,4,4,3,3,3,2,2,1,1
1,2,2,2,2,3,3,4,4,4,4,3,3,2,2,2,1
1,2,2,2,2,3,3,4,4,4,4,3,3,2,2,2,1
2,2,2,2,2,3,3,3,4,4,3,3,3,2,2,2,2
2,2,2,2,2,3,3,3,3,3,3,3,3,2,2,2,2
2,2,2,2,2,2,3,3,3,3,3,3,2,2,2,2,2
2,2,2,2,2,2,2,2,2,2,2,2,2,2,2,2,2
2,2,2,2,2,2,2,2,2,2,2,2,2,2,2,2,2
1,2,2,2,2,2,2,2,2,2,2,2,2,2,2,2,1
1,2,2,2,2,2,2,2,2,2,2,2,2,2,2,2,1
1,1,2,2,2,2,2,2,2,2,2,2,2,2,2,1,1
1,1,1,2,2,2,2,2,2,2,2,2,2,2,1,1,1
1,1,1,1,2,2,2,2,2,2,2,2,2,1,1,1,1
1,1,1,1,1,1,2,2,2,2,2,1,1,1,1,1,1
endlayer

layer
1,1,1,1,1,1,2,2,2,2,2,1,1,1,1,1,1
1,1,1,1,2,2,3,0,5,5,0,3,2,1,1,1,1
1,1,1,2,2,3,0,0,0,0,0,0,3,2,1,1,1
1,1,2,2,2,0,0,0,0,0,0,0,0,2,2,1,1
1,2,2,2,2,7,0,0,0,0,0,0,6,2,2,2,1
1,2,2,2,2,7,0,0,0,0,0,0,6,2,2,2,1
2,2,2,2,2,0,0,0,0,0,0,0,0,2,2,2,2
2,2,2,2,2,3,0,0,0,0,0,0,3,2,2,2,2
2,2,2,2,2,2,3,3,8,3,3,3,2,2,2,2,2
2,2,2,2,2,2,2,2,2,2,2,2,2,2,2,2,2
2,2,2,2,2,2,2,2,2,2,2,2,2,2,2,2,2
1,2,2,2,2,2,2,2,2,2,2,2,2,2,2,2,1
1,2,2,2,2,2,2,2,2,2,2,2,2,2,2,2,1
1,1,2,2,2,2,2,2,2,2,2,2,2,2,2,1,1
1,1,1,2,2,2,2,2,2,2,2,2,2,2,1,1,1
1,1,1,1,2,2,2,2,2,2,2,2,2,1,1,1,1
1,1,1,1,1,1,2,2,2,2,2,1,1,1,1,1,1
endlayer

layer
1,1,1,1,1,1,2,2,2,2,2,1,1,1,1,1,1
1,1,1,1,2,2,3,3,0,0,3,3,2,1,1,1,1
1,1,1,2,2,3,0,0,0,0,0,0,3,2,1,1,1
1,1,2,2,2,3,0,0,0,0,0,0,3,2,2,1,1
1,2,2,2,2,0,0,0,0,0,0,0,0,2,2,2,1
1,2,2,2,2,0,0,0,0,0,0,0,0,2,2,2,1
2,2,2,2,2,3,0,0,0,0,0,0,3,2,2,2,2
2,2,2,2,2,3,0,0,0,0,0,0,3,2,2,2,2
2,2,2,2,2,2,3,3,8,3,9,3,2,2,2,2,2
2,2,2,2,2,2,2,2,2,2,2,2,2,2,2,2,2
2,2,2,2,2,2,2,2,2,2,2,2,2,2,2,2,2
1,2,2,2,2,2,2,2,2,2,2,2,2,2,2,2,1
1,2,2,2,2,2,2,2,2,2,2,2,2,2,2,2,1
1,1,2,2,2,2,2,2,2,2,2,2,2,2,2,1,1
1,1,1,2,2,2,2,2,2,2,2,2,2,2,1,1,1
1,1,1,1,2,2,2,2,2,2,2,2,2,1,1,1,1
1,1,1,1,1,1,2,2,2,2,2,1,1,1,1,1,1
endlayer

layer
1,1,1,1,1,1,2,2,2,2,2,1,1,1,1,1,1
1,1,1,1,2,2,2,2,3,3,2,2,2,1,1,1,1
1,1,1,2,2,2,3,3,3,3,3,3,2,2,1,1,1
1,1,2,2,2,2,3,0,0,0,0,3,2,2,2,1,1
1,2,2,2,2,3,3,0,0,0,0,3,3,2,2,2,1
1,2,2,2,2,3,3,0,0,0,0,3,3,2,2,2,1
2,2,2,2,2,2,3,0,0,0,0,3,2,2,2,2,2
2,2,2,2,2,2,3,3,3,3,3,3,2,2,2,2,2
2,2,2,2,2,2,2,3,8,3,2,2,2,2,2,2,2
2,2,2,2,2,2,2,2,2,2,2,2,2,2,2,2,2
2,2,2,2,2,2,2,2,2,2,2,2,2,2,2,2,2
1,2,2,2,2,2,2,2,2,2,2,2,2,2,2,2,1
1,2,2,2,2,2,2,2,2,2,2,2,2,2,2,2,1
1,1,2,2,2,2,2,2,2,2,2,2,2,2,2,1,1
1,1,1,2,2,2,2,2,2,2,2,2,2,2,1,1,1
1,1,1,1,2,2,2,2,2,2,2,2,2,1,1,1,1
1,1,1,1,1,1,2,2,2,2,2,1,1,1,1,1,1
endlayer

layer
1,1,1,1,1,1,2,2,2,2,2,1,1,1,1,1,1
1,1,1,1,2,2,10,10,10,10,10,2,2,1,1,1,1
1,1,1,2,10,10,10,10,10,10,10,10,10,2,1,1,1
1,1,2,10,10,11,11,3,3,3,3,11,10,10,2,1,1
1,2,10,10,10,11,3,3,3,3,3,11,11,10,10,2,1
1,2,10,10,10,11,3,3,3,3,3,10,10,10,10,2,1
2,10,10,10,10,11,3,3,3,3,3,11,11,10,10,10,2
2,10,10,10,10,11,3,3,3,11,11,11,10,10,10,10,2
2,10,10,10,10,11,3,3,13,12,10,10,10,10,10,10,2
2,10,10,10,10,11,11,10,14,11,10,10,10,10,10,10,2
2,10,10,10,10,10,10,10,10,10,10,11,10,10,10,10,2
1,2,15,15,15,10,10,10,10,10,10,10,10,10,10,2,1
1,2,15,15,15,10,10,10,10,10,10,10,10,10,10,2,1
1,1,2,15,15,10,10,10,10,10,10,10,10,10,2,1,1
1,1,1,2,10,10,15,15,15,15,16,10,10,2,1,1,1
1,1,1,1,2,4,15,15,15,15,16,2,2,1,1,1,1
1,1,1,1,1,1,2,2,2,2,2,1,1,1,1,1,1
endlayer

layer
1,1,1,1,1,1,2,2,2,2,2,1,1,1,1,1,1
1,1,1,1,2,2,0,17,17,18,17,2,2,1,1,1,1
1,1,1,2,17,0,17,17,17,17,0,18,17,2,1,1,1
1,1,2,17,17,19,20,20,20,20,20,19,17,17,2,1,1
1,2,26,17,17,20,25,0,24,23,22,20,21,0,0,2,1
1,2,17,0,17,20,28,0,0,0,0,27,17,0,17,2,1
2,0,0,0,0,20,0,0,30,29,29,20,21,17,17,17,2
2,17,17,18,17,20,32,0,22,19,20,19,31,26,17,17,2
2,17,17,17,17,20,34,0,33,20,0,17,31,17,17,17,2
2,26,17,17,17,19,20,35,20,19,0,17,31,17,17,0,2
2,17,0,0,0,17,0,0,0,31,17,36,31,17,17,0,2
1,2,40,39,38,17,0,0,0,37,0,0,31,17,17,2,1
1,2,38,38,38,17,0,0,0,31,31,31,31,17,17,2,1
1,1,2,41,40,31,0,0,17,26,0,17,17,17,2,1,1
1,1,1,2,0,17,44,44,43,43,42,17,17,2,1,1,1
1,1,1,1,2,2,45,46,45,42,45,2,2,1,1,1,1
1,1,1,1,1,1,2,2,2,2,2,1,1,1,1,1,1
endlayer

layer
1,1,1,1,1,1,47,47,47,47,47,1,1,1,1,1,1
1,1,1,1,47,47,0,0,0,0,0,47,47,1,1,1,1
1,1,1,47,0,0,0,0,0,0,0,0,0,47,1,1,1
1,1,47,0,0,19,20,48,20,48,20,19,0,0,47,1,1
1,47,0,0,0,20,0,0,0,49,0,20,0,0,0,47,1
1,47,0,0,0,48,0,0,0,0,0,50,0,0,0,47,1
47,0,0,0,0,20,0,0,0,0,0,20,0,0,0,0,47
47,0,0,0,0,48,0,0,0,19,48,19,0,0,0,0,47
47,0,0,0,0,20,0,0,0,48,0,0,0,0,0,0,47
47,0,0,0,0,19,20,51,20,19,0,0,0,0,0,0,47
47,0,0,0,0,0,0,0,0,0,0,0,0,0,0,0,47
1,47,0,0,0,0,0,0,0,0,0,0,0,0,0,47,1
1,47,0,0,0,0,0,0,0,0,0,0,0,0,0,47,1
1,1,47,0,0,52,0,0,0,0,0,0,0,0,47,1,1
1,1,1,47,0,0,0,0,0,0,0,0,0,47,1,1,1
1,1,1,1,47,47,0,0,0,0,0,47,47,1,1,1,1
1,1,1,1,1,1,47,47,47,47,47,1,1,1,1,1,1
endlayer

layer
1,1,1,1,1,1,47,47,47,47,47,1,1,1,1,1,1
1,1,1,1,47,47,0,0,0,0,0,47,47,1,1,1,1
1,1,1,47,0,0,0,0,0,0,0,0,0,47,1,1,1
1,1,47,0,0,19,20,20,20,20,20,19,0,0,47,1,1
1,47,0,0,0,20,0,0,0,0,0,20,0,0,0,47,1
1,47,0,0,0,20,0,0,0,0,0,20,0,0,0,47,1
47,0,0,0,0,20,0,0,0,53,0,20,0,0,0,0,47
47,0,0,0,0,20,0,0,54,19,20,19,0,0,0,0,47
47,0,0,0,0,20,0,0,0,20,0,0,0,0,0,0,47
47,0,0,0,0,19,20,20,20,19,0,0,0,0,0,0,47
47,0,0,0,0,0,0,0,0,0,0,0,0,0,0,0,47
1,47,0,0,0,0,0,0,0,0,0,0,0,0,0,47,1
1,47,0,0,0,0,0,0,0,0,0,0,0,0,0,47,1
1,1,47,0,0,0,0,0,0,0,0,0,0,0,47,1,1
1,1,1,47,0,0,0,0,0,0,0,0,0,47,1,1,1
1,1,1,1,47,47,0,0,0,0,0,47,47,1,1,1,1
1,1,1,1,1,1,47,47,47,47,47,1,1,1,1,1,1
endlayer

layer
1,1,1,1,1,1,1,47,47,47,1,1,1,1,1,1,1
1,1,1,1,47,47,47,0,0,0,47,47,47,1,1,1,1
1,1,1,47,55,55,55,55,55,55,55,55,55,47,1,1,1
1,1,47,0,22,19,14,14,14,14,14,19,24,0,47,1,1
1,47,0,0,22,12,56,56,56,56,56,12,24,0,0,47,1
1,47,0,0,22,12,56,56,56,56,56,12,24,0,0,47,1
1,47,0,0,22,12,56,56,56,56,56,12,24,0,0,47,1
47,0,0,0,22,12,56,56,56,19,14,19,24,0,0,0,47
47,0,0,0,22,12,56,56,56,12,24,57,57,0,0,0,47
47,0,0,0,22,19,14,14,14,19,24,0,0,0,0,0,47
1,47,0,0,22,57,57,57,57,57,24,0,0,0,0,47,1
1,47,0,0,0,0,0,0,0,0,0,0,0,0,0,47,1
1,47,0,0,0,0,0,0,0,0,0,0,0,0,0,47,1
1,1,47,0,0,0,0,0,0,0,0,0,0,0,47,1,1
1,1,1,47,0,0,0,0,0,0,0,0,0,47,1,1,1
1,1,1,1,47,47,47,0,0,0,47,47,47,1,1,1,1
1,1,1,1,1,1,1,47,47,47,1,1,1,1,1,1,1
endlayer

layer
1,1,1,1,1,1,1,1,1,1,1,1,1,1,1,1,1
1,1,1,1,1,47,47,47,47,47,47,47,1,1,1,1,1
1,1,1,47,47,0,0,0,0,0,0,0,47,47,1,1,1
1,1,47,0,0,22,55,55,55,55,55,55,0,0,47,1,1
1,1,47,0,0,22,58,58,58,58,58,24,0,0,47,1,1
1,47,0,0,0,22,58,58,58,58,58,24,0,0,0,47,1
1,47,0,0,0,22,58,58,58,58,58,24,0,0,0,47,1
1,47,0,0,0,22,58,58,58,24,57,24,0,0,0,47,1
1,47,0,0,0,22,58,58,58,24,0,0,0,0,0,47,1
1,47,0,0,0,57,57,57,57,24,0,0,0,0,0,47,1
1,47,0,0,0,0,0,0,0,0,0,0,0,0,0,47,1
1,47,0,0,0,0,0,0,0,0,0,0,0,0,0,47,1
1,1,47,0,0,0,0,0,0,0,0,0,0,0,47,1,1
1,1,47,0,0,0,0,0,0,0,0,0,0,0,47,1,1
1,1,1,47,47,0,0,0,0,0,0,0,47,47,1,1,1
1,1,1,1,1,47,47,47,47,47,47,47,1,1,1,1,1
1,1,1,1,1,1,1,1,1,1,1,1,1,1,1,1,1
endlayer

layer
1,1,1,1,1,1,1,1,1,1,1,1,1,1,1,1,1
1,1,1,1,1,1,47,47,47,47,47,1,1,1,1,1,1
1,1,1,1,47,47,0,0,0,0,0,47,47,1,1,1,1
1,1,1,47,0,0,0,0,0,0,0,0,0,47,1,1,1
1,1,47,0,0,0,22,55,55,55,55,0,0,0,47,1,1
1,1,47,0,0,0,22,58,58,58,24,0,0,0,47,1,1
1,47,0,0,0,0,22,58,57,57,57,0,0,0,0,47,1
1,47,0,0,0,0,22,58,24,0,0,0,0,0,0,47,1
1,47,0,0,0,0,57,57,57,0,0,0,0,0,0,47,1
1,47,0,0,0,0,0,0,0,0,0,0,0,0,0,47,1
1,47,0,0,0,0,0,0,0,0,0,0,0,0,0,47,1
1,1,47,0,0,0,0,0,0,0,0,0,0,0,47,1,1
1,1,47,0,0,0,0,0,0,0,0,0,0,0,47,1,1
1,1,1,47,0,0,0,0,0,0,0,0,0,47,1,1,1
1,1,1,1,47,47,0,0,0,0,0,47,47,1,1,1,1
1,1,1,1,1,1,47,47,47,47,47,1,1,1,1,1,1
1,1,1,1,1,1,1,1,1,1,1,1,1,1,1,1,1
endlayer

layer
1,1,1,1,1,1,1,1,1,1,1,1,1,1,1,1,1
1,1,1,1,1,1,1,1,1,1,1,1,1,1,1,1,1
1,1,1,1,1,47,47,47,47,47,47,47,1,1,1,1,1
1,1,1,1,47,0,0,0,0,0,0,0,47,1,1,1,1
1,1,1,47,0,0,0,0,0,0,0,0,0,47,1,1,1
1,1,47,0,0,0,0,0,0,0,0,0,0,0,47,1,1
1,1,47,0,0,0,0,0,0,0,0,0,0,0,47,1,1
1,1,47,0,0,0,0,0,0,0,0,0,0,0,47,1,1
1,1,47,0,0,0,0,0,0,0,0,0,0,0,47,1,1
1,1,47,0,0,0,0,0,0,0,0,0,0,0,47,1,1
1,1,47,0,0,0,0,0,0,0,0,0,0,0,47,1,1
1,1,47,0,0,0,0,0,0,0,0,0,0,0,47,1,1
1,1,1,47,0,0,0,0,0,0,0,0,0,47,1,1,1
1,1,1,1,47,0,0,0,0,0,0,0,47,1,1,1,1
1,1,1,1,1,47,47,47,47,47,47,47,1,1,1,1,1
1,1,1,1,1,1,1,1,1,1,1,1,1,1,1,1,1
1,1,1,1,1,1,1,1,1,1,1,1,1,1,1,1,1
endlayer

layer
1,1,1,1,1,1,1,1,1,1,1,1,1,1,1,1,1
1,1,1,1,1,1,1,1,1,1,1,1,1,1,1,1,1
1,1,1,1,1,1,1,1,1,1,1,1,1,1,1,1,1
1,1,1,1,1,47,47,47,47,47,47,47,1,1,1,1,1
1,1,1,1,47,47,0,0,0,0,0,47,47,1,1,1,1
1,1,1,47,47,0,0,0,0,0,0,0,47,47,1,1,1
1,1,1,47,0,0,0,0,0,0,0,0,0,47,1,1,1
1,1,1,47,0,0,0,0,0,0,0,0,0,47,1,1,1
1,1,1,47,0,0,0,0,0,0,0,0,0,47,1,1,1
1,1,1,47,0,0,0,0,0,0,0,0,0,47,1,1,1
1,1,1,47,0,0,0,0,0,0,0,0,0,47,1,1,1
1,1,1,47,47,0,0,0,0,0,0,0,47,47,1,1,1
1,1,1,1,47,47,0,0,0,0,0,47,47,1,1,1,1
1,1,1,1,1,47,47,47,47,47,47,47,1,1,1,1,1
1,1,1,1,1,1,1,1,1,1,1,1,1,1,1,1,1
1,1,1,1,1,1,1,1,1,1,1,1,1,1,1,1,1
1,1,1,1,1,1,1,1,1,1,1,1,1,1,1,1,1
endlayer

layer
1,1,1,1,1,1,1,1,1,1,1,1,1,1,1,1,1
1,1,1,1,1,1,1,1,1,1,1,1,1,1,1,1,1
1,1,1,1,1,1,1,1,1,1,1,1,1,1,1,1,1
1,1,1,1,1,1,1,1,1,1,1,1,1,1,1,1,1
1,1,1,1,1,1,47,47,47,47,47,1,1,1,1,1,1
1,1,1,1,1,47,47,47,47,47,47,47,1,1,1,1,1
1,1,1,1,47,47,47,0,0,0,47,47,47,1,1,1,1
1,1,1,1,47,47,0,0,0,0,0,47,47,1,1,1,1
1,1,1,1,47,47,0,0,0,0,0,47,47,1,1,1,1
1,1,1,1,47,47,0,0,0,0,0,47,47,1,1,1,1
1,1,1,1,47,47,47,0,0,0,47,47,47,1,1,1,1
1,1,1,1,1,47,47,47,47,47,47,47,1,1,1,1,1
1,1,1,1,1,1,47,47,47,47,47,1,1,1,1,1,1
1,1,1,1,1,1,1,1,1,1,1,1,1,1,1,1,1
1,1,1,1,1,1,1,1,1,1,1,1,1,1,1,1,1
1,1,1,1,1,1,1,1,1,1,1,1,1,1,1,1,1
1,1,1,1,1,1,1,1,1,1,1,1,1,1,1,1,1
endlayer

layer
1,1,1,1,1,1,1,1,1,1,1,1,1,1,1,1,1
1,1,1,1,1,1,1,1,1,1,1,1,1,1,1,1,1
1,1,1,1,1,1,1,1,1,1,1,1,1,1,1,1,1
1,1,1,1,1,1,1,1,1,1,1,1,1,1,1,1,1
1,1,1,1,1,1,1,1,1,1,1,1,1,1,1,1,1
1,1,1,1,1,1,1,1,1,1,1,1,1,1,1,1,1
1,1,1,1,1,1,1,47,47,47,1,1,1,1,1,1,1
1,1,1,1,1,1,47,47,47,47,47,1,1,1,1,1,1
1,1,1,1,1,1,47,47,47,47,47,1,1,1,1,1,1
1,1,1,1,1,1,47,47,47,47,47,1,1,1,1,1,1
1,1,1,1,1,1,1,47,47,47,1,1,1,1,1,1,1
1,1,1,1,1,1,1,1,1,1,1,1,1,1,1,1,1
1,1,1,1,1,1,1,1,1,1,1,1,1,1,1,1,1
1,1,1,1,1,1,1,1,1,1,1,1,1,1,1,1,1
1,1,1,1,1,1,1,1,1,1,1,1,1,1,1,1,1
1,1,1,1,1,1,1,1,1,1,1,1,1,1,1,1,1
1,1,1,1,1,1,1,1,1,1,1,1,1,1,1,1,1
endlayer

