
# Created by Ruins mod version 17.1 Ingame Parser
# authoring Player: ST753M

weight=3
uniqueMinDistance=1000
embed_into_distance=3
acceptable_target_blocks=dirt,gravel,clay,sand,stone
unacceptable_target_blocks=flowing_water,water,flowing_lava,lava
dimensions=14,19,15
allowable_overhang=4
max_leveling=0
leveling_buffer=0
preserve_water=1
preserve_lava=0

biomesToSpawnIn=deep_ocean,twilight_lake

rule1=0,100,preserveBlock
rule2=0,100,minecraft:prismarine-1
rule3=0,100,minecraft:prismarine-2
rule4=0,100,minecraft:prismarine-2
rule5=0,100,minecraft:water-0
rule6=0,100,minecraft:prismarine-0
rule7=0,100,CommandBlock:RUINSTRIGGER /summon iceandfire:hippocampus ~ ~1 ~:@-1
rule8=0,100,minecraft:stained_glass-9
rule9=0,100,minecraft:prismarine-1
rule10=0,100,minecraft:prismarine-1
rule11=0,100,minecraft:sea_lantern-0
rule12=0,100,minecraft:prismarine-0
rule13=0,100,air
rule14=0,100,minecraft:prismarine-0

layer
1,1,1,1,1,1,1,1,1,1,1,1,1,1,1
1,2,3,3,3,2,3,3,3,2,3,3,3,2,1
1,3,3,3,3,3,3,3,3,3,3,3,3,3,1
1,3,3,3,3,3,3,3,3,3,3,3,3,3,1
1,3,3,3,3,3,3,3,3,3,3,3,3,3,1
1,2,3,3,3,3,3,3,3,3,3,3,3,2,1
1,3,3,3,3,3,3,3,3,3,3,3,3,3,1
1,2,3,3,3,3,3,3,3,3,3,3,3,2,1
1,3,3,3,3,3,3,3,3,3,3,3,3,3,1
1,3,3,3,3,3,3,3,3,3,3,3,3,3,1
1,3,3,3,3,3,3,3,3,3,3,3,3,3,1
1,2,3,3,3,3,3,3,3,3,3,3,3,2,1
1,3,3,3,3,3,3,3,3,3,3,3,3,3,1
1,2,3,3,3,3,3,3,3,3,3,3,3,2,1
1,3,3,3,3,3,3,3,3,3,3,3,3,3,1
1,3,3,3,3,3,3,3,3,3,3,3,3,3,1
1,3,3,3,3,3,3,3,3,3,3,3,3,3,1
1,2,3,3,3,2,3,3,3,2,3,3,3,2,1
1,1,1,1,1,1,1,1,1,1,1,1,1,1,1
endlayer

layer
1,1,1,1,1,1,1,1,1,1,1,1,1,1,1
1,2,3,3,3,2,3,3,3,2,3,3,3,2,1
1,3,4,4,4,4,4,4,4,4,4,4,4,3,1
1,3,4,4,4,4,4,4,4,4,4,4,4,3,1
1,3,4,4,4,4,4,4,4,4,4,4,4,3,1
1,2,4,4,4,4,4,4,4,4,4,4,4,2,1
1,3,4,4,4,4,4,4,4,4,4,4,4,3,1
1,2,4,4,4,4,4,4,4,4,4,4,4,2,1
1,3,4,4,3,3,3,3,3,3,3,4,4,3,1
1,3,4,4,3,3,3,3,3,3,3,4,3,3,1
1,3,4,4,3,3,3,3,3,3,3,4,4,3,1
1,2,4,4,4,4,4,4,4,4,4,4,4,2,1
1,3,4,4,4,4,4,4,4,4,4,4,4,3,1
1,2,4,4,4,4,4,4,4,4,4,4,4,2,1
1,3,4,4,4,4,4,4,4,4,4,4,4,3,1
1,3,4,4,4,4,4,4,4,4,4,4,4,3,1
1,3,4,4,4,4,4,4,4,4,4,4,4,3,1
1,2,3,3,3,2,3,3,3,2,3,3,3,2,1
1,1,1,1,1,1,1,1,1,1,1,1,1,1,1
endlayer

layer
1,1,1,1,1,1,1,1,1,1,1,1,1,1,1
1,2,3,3,3,2,3,3,3,2,3,3,3,2,1
1,3,3,3,3,4,3,3,3,4,3,3,3,3,1
1,3,3,3,3,4,3,3,3,4,3,3,3,3,1
1,3,3,3,3,4,3,3,3,4,3,3,3,3,1
1,2,3,3,3,4,3,3,3,4,3,3,3,2,1
1,3,3,3,3,3,3,3,3,3,3,3,3,3,1
1,2,3,3,3,3,3,3,3,3,3,3,3,2,1
1,3,3,3,5,5,5,5,5,5,5,3,3,3,1
1,3,3,3,5,5,5,5,5,5,5,3,3,3,1
1,3,3,3,5,5,5,5,5,5,5,3,3,3,1
1,2,3,3,3,3,3,3,3,3,3,3,3,2,1
1,3,3,3,3,3,3,3,3,3,3,3,3,3,1
1,2,3,3,3,4,3,3,3,4,3,3,3,2,1
1,3,3,3,3,4,3,3,3,4,3,3,3,3,1
1,3,3,3,3,4,3,3,3,4,3,3,3,3,1
1,3,3,3,3,4,3,3,3,4,3,3,3,3,1
1,2,3,3,3,2,3,3,3,2,3,3,3,2,1
1,1,1,1,1,1,1,1,1,1,1,1,1,1,1
endlayer

layer
1,1,1,1,1,1,1,1,1,1,1,1,1,1,1
1,2,6,6,6,2,6,6,6,2,6,6,6,2,1
1,6,5,5,5,6,5,5,5,6,5,5,5,6,1
1,6,5,7,5,6,5,7,5,6,5,7,5,6,1
1,6,5,5,5,6,5,5,5,6,5,5,5,6,1
1,2,8,8,8,2,8,8,8,2,8,8,8,2,1
1,6,0,0,0,0,0,0,0,0,0,0,0,6,1
1,2,0,0,0,0,0,0,0,0,0,0,0,2,1
1,0,0,0,0,0,0,0,0,0,0,0,0,0,1
1,0,0,0,0,0,0,0,0,0,0,0,0,0,1
1,0,0,0,0,0,0,0,0,0,0,0,0,0,1
1,2,0,0,0,0,0,0,0,0,0,0,0,2,1
1,6,0,0,0,0,0,0,0,0,0,0,0,6,1
1,2,8,8,8,2,8,8,8,2,8,8,8,2,1
1,6,5,5,5,6,5,5,5,6,5,5,5,6,1
1,6,5,7,5,6,5,7,5,6,5,7,5,6,1
1,6,5,5,5,6,5,5,5,6,5,5,5,6,1
1,2,6,6,6,2,6,6,6,2,6,6,6,2,1
1,1,1,1,1,1,1,1,1,1,1,1,1,1,1
endlayer

layer
1,1,1,1,1,1,1,1,1,1,1,1,1,1,1
1,2,6,8,6,2,6,8,6,2,6,8,6,2,1
1,6,5,5,5,6,5,5,5,6,5,5,5,6,1
1,8,5,5,5,6,5,5,5,6,5,5,5,8,1
1,6,5,5,5,6,5,5,5,6,5,5,5,6,1
1,2,8,8,8,2,8,8,8,2,8,8,8,2,1
1,6,0,0,0,0,0,0,0,0,0,0,0,6,1
1,2,0,0,0,0,0,0,0,0,0,0,0,2,1
1,0,0,0,0,0,0,0,0,0,0,0,0,0,1
1,0,0,0,0,0,0,0,0,0,0,0,0,0,1
1,0,0,0,0,0,0,0,0,0,0,0,0,0,1
1,2,0,0,0,0,0,0,0,0,0,0,0,2,1
1,6,0,0,0,0,0,0,0,0,0,0,0,6,1
1,2,8,8,8,2,8,8,8,2,8,8,8,2,1
1,6,5,5,5,6,5,5,5,6,5,5,5,6,1
1,8,5,5,5,6,5,5,5,6,5,5,5,8,1
1,6,5,5,5,6,5,5,5,6,5,5,5,6,1
1,2,6,8,6,2,6,8,6,2,6,8,6,2,1
1,1,1,1,1,1,1,1,1,1,1,1,1,1,1
endlayer

layer
1,1,1,1,1,1,1,1,1,1,1,1,1,1,1
1,2,6,8,6,2,6,8,6,2,6,8,6,2,1
1,6,5,5,5,8,5,5,5,8,5,5,5,6,1
1,8,5,5,5,8,5,5,5,8,5,5,5,8,1
1,6,5,5,5,8,5,5,5,8,5,5,5,6,1
1,2,8,8,8,2,8,8,8,2,8,8,8,2,1
1,6,0,0,0,0,0,0,0,0,0,0,0,6,1
1,2,0,0,0,0,0,0,0,0,0,0,0,2,1
1,0,0,0,0,0,0,0,0,0,0,0,0,0,1
1,0,0,0,0,0,0,0,0,0,0,0,0,0,1
1,0,0,0,0,0,0,0,0,0,0,0,0,0,1
1,2,0,0,0,0,0,0,0,0,0,0,0,2,1
1,6,0,0,0,0,0,0,0,0,0,0,0,6,1
1,2,8,8,8,2,8,8,8,2,8,8,8,2,1
1,6,5,5,5,8,5,5,5,8,5,5,5,6,1
1,8,5,5,5,8,5,5,5,8,5,5,5,8,1
1,6,5,5,5,8,5,5,5,8,5,5,5,6,1
1,2,6,8,6,2,6,8,6,2,6,8,6,2,1
1,1,1,1,1,1,1,1,1,1,1,1,1,1,1
endlayer

layer
3,3,3,3,3,3,3,3,3,3,3,3,3,3,3
3,9,10,2,10,9,10,2,10,9,10,2,10,9,3
1,2,6,6,6,2,6,6,6,2,6,6,6,2,1
1,2,6,11,6,2,6,11,6,2,6,11,6,2,1
1,2,6,6,6,2,6,6,6,2,6,6,6,2,1
1,2,2,2,2,9,2,2,2,9,2,2,2,2,1
1,2,6,6,6,2,0,0,0,2,6,6,6,2,1
1,2,6,6,6,2,0,0,0,2,6,6,6,2,1
1,2,6,6,6,2,0,0,0,2,6,6,6,2,1
1,2,6,6,6,2,0,0,0,2,6,6,6,2,1
1,2,6,6,6,2,0,0,0,2,6,6,6,2,1
1,2,6,6,6,2,0,0,0,2,6,6,6,2,1
1,2,6,6,6,2,0,0,0,2,6,6,6,2,1
1,2,2,2,2,9,2,2,2,9,2,2,2,2,1
1,2,6,6,6,2,6,6,6,2,6,6,6,2,1
1,2,6,11,6,2,6,11,6,2,6,11,6,2,1
1,2,6,6,6,2,6,6,6,2,6,6,6,2,1
3,9,10,2,10,2,10,2,10,9,10,2,10,9,3
3,3,3,3,3,3,3,3,3,3,3,3,3,3,3
endlayer

layer
0,0,0,0,0,0,0,0,0,0,0,0,0,0,0
3,3,3,3,3,3,3,3,3,3,3,3,3,3,3
3,12,3,3,3,3,3,3,3,3,3,3,3,12,3
1,6,0,0,0,0,0,0,0,0,0,0,0,6,1
1,6,0,0,0,0,0,0,0,0,0,0,0,6,1
1,2,0,0,0,2,0,0,0,2,0,0,0,2,1
1,6,0,0,0,0,0,0,0,0,0,0,0,6,1
1,6,0,0,0,0,0,0,0,0,0,0,0,6,1
1,6,0,0,0,0,0,0,0,0,0,0,0,6,1
1,2,0,0,0,2,0,0,0,2,0,0,0,2,1
1,6,0,0,0,0,0,0,0,0,0,0,0,6,1
1,6,0,0,0,0,0,0,0,0,0,0,0,6,1
1,6,0,0,0,0,0,0,0,0,0,0,0,6,1
1,2,0,0,0,2,0,0,0,2,0,0,0,2,1
1,6,0,0,0,0,0,0,0,0,0,0,0,6,1
1,6,0,0,0,0,0,0,0,0,0,0,0,6,1
3,12,3,3,3,3,3,3,3,3,3,3,3,12,3
3,3,3,3,3,3,3,3,3,3,3,3,3,3,3
0,0,0,0,0,0,0,0,0,0,0,0,0,0,0
endlayer

layer
0,0,0,0,0,0,0,0,0,0,0,0,0,0,0
0,0,0,0,0,0,0,0,0,0,0,0,0,0,0
3,3,3,3,3,3,3,3,3,3,3,3,3,3,3
3,6,0,0,0,0,0,0,0,0,0,0,0,6,3
1,6,0,0,0,0,0,0,0,0,0,0,0,6,1
1,2,0,0,0,2,0,0,0,2,0,0,0,2,1
1,6,0,0,0,0,0,0,0,0,0,0,0,6,1
1,8,0,0,0,0,0,0,0,0,0,0,0,8,1
1,6,0,0,0,0,0,0,0,0,0,0,0,6,1
1,2,0,0,0,2,0,0,0,2,0,0,0,2,1
1,6,0,0,0,0,0,0,0,0,0,0,0,6,1
1,8,0,0,0,0,0,0,0,0,0,0,0,8,1
1,6,0,0,0,0,0,0,0,0,0,0,0,6,1
1,2,0,0,0,2,0,0,0,2,0,0,0,2,1
1,6,0,0,0,0,0,0,0,0,0,0,0,6,1
3,6,0,0,0,0,0,0,0,0,0,0,0,6,3
3,3,3,3,3,3,3,3,3,3,3,3,3,3,3
0,0,0,0,0,0,0,0,0,0,0,0,0,0,0
0,0,0,0,0,0,0,0,0,0,0,0,0,0,0
endlayer

layer
0,0,0,0,0,0,0,0,0,0,0,0,0,0,0
0,0,0,0,0,0,0,0,0,0,0,0,0,0,0
0,0,0,0,0,0,0,0,0,0,0,0,0,0,0
3,3,3,3,3,3,3,3,3,3,3,3,3,3,3
3,6,0,0,0,0,0,0,0,0,0,0,0,6,3
1,2,0,0,0,2,0,0,0,2,0,0,0,2,1
1,6,0,0,0,0,0,0,0,0,0,0,0,6,1
1,8,0,0,0,0,0,0,0,0,0,0,0,8,1
1,6,0,0,0,0,0,0,0,0,0,0,0,6,1
1,2,0,0,0,2,0,0,0,2,0,0,0,2,1
1,6,0,0,0,0,0,0,0,0,0,0,0,6,1
1,8,0,0,0,0,0,0,0,0,0,0,0,8,1
1,6,0,0,0,0,0,0,0,0,0,0,0,6,1
1,2,0,0,0,2,0,0,0,2,0,0,0,2,1
3,6,0,0,0,0,0,0,0,0,0,0,0,6,3
3,3,3,3,3,3,3,3,3,3,3,3,3,3,3
0,0,0,0,0,0,0,0,0,0,0,0,0,0,0
0,0,0,0,0,0,0,0,0,0,0,0,0,0,0
0,0,0,0,0,0,0,0,0,0,0,0,0,0,0
endlayer

layer
0,0,0,0,0,0,0,0,0,0,0,0,0,0,0
0,0,0,0,0,0,0,0,0,0,0,0,0,0,0
0,0,0,0,0,0,0,0,0,0,0,0,0,0,0
0,0,0,0,0,0,0,0,0,0,0,0,0,0,0
3,3,3,3,3,3,3,3,3,3,3,3,3,3,3
3,2,13,13,13,2,13,13,13,2,13,13,13,2,3
1,2,13,13,13,13,13,13,13,13,13,13,13,2,1
1,2,13,13,13,13,13,13,13,13,13,13,13,2,1
1,2,13,13,13,13,13,13,13,13,13,13,13,2,1
1,2,2,2,2,2,2,2,2,2,2,2,2,2,1
1,2,13,13,13,13,13,13,13,13,13,13,13,2,1
1,2,13,13,13,13,13,13,13,13,13,13,13,2,1
1,2,13,13,13,13,13,13,13,13,13,13,13,2,1
3,2,13,13,13,2,13,13,13,2,13,13,13,2,3
3,3,3,3,3,3,3,3,3,3,3,3,3,3,3
0,0,0,0,0,0,0,0,0,0,0,0,0,0,0
0,0,0,0,0,0,0,0,0,0,0,0,0,0,0
0,0,0,0,0,0,0,0,0,0,0,0,0,0,0
0,0,0,0,0,0,0,0,0,0,0,0,0,0,0
endlayer

layer
0,0,0,0,0,0,0,0,0,0,0,0,0,0,0
0,0,0,0,0,0,0,0,0,0,0,0,0,0,0
0,0,0,0,0,0,0,0,0,0,0,0,0,0,0
0,0,0,0,0,0,0,0,0,0,0,0,0,0,0
0,0,0,0,0,0,0,0,0,0,0,0,0,0,0
3,3,3,3,3,3,3,3,3,3,3,3,3,3,3
3,3,3,3,3,3,3,3,3,3,3,3,3,3,3
3,12,3,3,3,3,3,3,3,3,3,3,3,12,3
1,6,13,13,13,13,13,13,13,13,13,13,13,6,1
1,6,13,13,13,2,13,13,13,2,13,13,13,6,1
1,6,13,13,13,13,13,13,13,13,13,13,13,6,1
3,12,3,3,3,3,3,3,3,3,3,3,3,12,3
3,3,3,3,3,3,3,3,3,3,3,3,3,3,3
3,3,3,3,3,3,3,3,3,3,3,3,3,3,3
0,0,0,0,0,0,0,0,0,0,0,0,0,0,0
0,0,0,0,0,0,0,0,0,0,0,0,0,0,0
0,0,0,0,0,0,0,0,0,0,0,0,0,0,0
0,0,0,0,0,0,0,0,0,0,0,0,0,0,0
0,0,0,0,0,0,0,0,0,0,0,0,0,0,0
endlayer

layer
0,0,0,0,0,0,0,0,0,0,0,0,0,0,0
0,0,0,0,0,0,0,0,0,0,0,0,0,0,0
0,0,0,0,0,0,0,0,0,0,0,0,0,0,0
0,0,0,0,0,0,0,0,0,0,0,0,0,0,0
0,0,0,0,0,0,0,0,0,0,0,0,0,0,0
0,0,0,0,0,0,0,0,0,0,0,0,0,0,0
0,0,0,0,0,0,0,0,0,0,0,0,0,0,0
3,3,3,3,3,3,3,3,3,3,3,3,3,3,3
3,3,3,3,3,3,3,3,3,3,3,3,3,3,3
3,14,3,3,3,14,3,3,3,14,3,3,3,14,3
3,3,3,3,3,3,3,3,3,3,3,3,3,3,3
3,3,3,3,3,3,3,3,3,3,3,3,3,3,3
0,0,0,0,0,0,0,0,0,0,0,0,0,0,0
0,0,0,0,0,0,0,0,0,0,0,0,0,0,0
0,0,0,0,0,0,0,0,0,0,0,0,0,0,0
0,0,0,0,0,0,0,0,0,0,0,0,0,0,0
0,0,0,0,0,0,0,0,0,0,0,0,0,0,0
0,0,0,0,0,0,0,0,0,0,0,0,0,0,0
0,0,0,0,0,0,0,0,0,0,0,0,0,0,0
endlayer

layer
0,0,0,0,0,0,0,0,0,0,0,0,0,0,0
0,0,0,0,0,0,0,0,0,0,0,0,0,0,0
0,0,0,0,0,0,0,0,0,0,0,0,0,0,0
0,0,0,0,0,0,0,0,0,0,0,0,0,0,0
0,0,0,0,0,0,0,0,0,0,0,0,0,0,0
0,0,0,0,0,0,0,0,0,0,0,0,0,0,0
0,0,0,0,0,0,0,0,0,0,0,0,0,0,0
0,0,0,0,0,0,0,0,0,0,0,0,0,0,0
0,0,0,0,0,0,0,0,0,0,0,0,0,0,0
3,3,3,3,3,3,3,3,3,3,3,3,3,3,3
0,0,0,0,0,0,0,0,0,0,0,0,0,0,0
0,0,0,0,0,0,0,0,0,0,0,0,0,0,0
0,0,0,0,0,0,0,0,0,0,0,0,0,0,0
0,0,0,0,0,0,0,0,0,0,0,0,0,0,0
0,0,0,0,0,0,0,0,0,0,0,0,0,0,0
0,0,0,0,0,0,0,0,0,0,0,0,0,0,0
0,0,0,0,0,0,0,0,0,0,0,0,0,0,0
0,0,0,0,0,0,0,0,0,0,0,0,0,0,0
0,0,0,0,0,0,0,0,0,0,0,0,0,0,0
endlayer

