
# Created by Ruins mod version 16.7 Ingame Parser
# authoring Player: ST753M

weight=1
embed_into_distance=6
acceptable_target_blocks=gravel,sand
unacceptable_target_blocks=flowing_water,water,flowing_lava,lava
dimensions=16,17,17
allowable_overhang=6
max_leveling=0
leveling_buffer=0
preserve_water=1
preserve_lava=0

biomesToSpawnIn=deep_ocean,kelp_forest

=0,100,air
rule1=0,100,preserveBlock
rule2=0,100,minecraft:stone-0
rule3=0,100,biomesoplenty:grass-5
rule4=0,100,minecraft:dirt-0
rule5=0,100,minecraft:water-0
rule6=0,100,minecraft:double_plant-4
rule7=0,100,biomesoplenty:flower_1-5
rule8=0,100,biomesoplenty:sapling_1-8
rule9=0,100,minecraft:yellow_flower-0
rule10=0,100,biomesoplenty:sapling_1-0
rule11=0,100,minecraft:log-0
rule12=0,100,minecraft:stained_glass-5
^0,100,minecraft:stained_glass-0
^0,100,minecraft:stained_glass-9
^0,100,minecraft:stained_glass-3
^0,100,minecraft:stained_glass-11
^0,100,minecraft:stained_glass-8
^0,100,minecraft:stained_glass-7
rule13=0,100,minecraft:double_plant-10
rule14=0,100,biomesoplenty:leaves_2-4
rule15=0,100,CommandBlock:RUINSTRIGGER /summon Sheep ~ ~ ~:@-1,CommandBlock:RUINSTRIGGER /summon Sheep ~ ~ ~:@-1,CommandBlock:RUINSTRIGGER /summon Sheep ~ ~ ~:@-1,CommandBlock:RUINSTRIGGER /summon Parrot ~ ~ ~:@-1,CommandBlock:RUINSTRIGGER /summon Sheep ~ ~ ~:@-1,CommandBlock:RUINSTRIGGER /summon Sheep ~ ~ ~:@-1
rule16=0,100,biomesoplenty:leaves_2-12

layer
1,1,1,1,1,1,2,2,2,2,2,1,1,1,1,1,1
1,1,1,1,2,2,2,2,2,2,2,2,2,1,1,1,1
1,1,1,2,2,2,2,2,2,2,2,2,2,2,1,1,1
1,1,2,2,2,2,2,2,2,2,2,2,2,2,2,1,1
1,2,2,2,2,2,2,2,2,2,2,2,2,2,2,2,1
1,2,2,2,2,2,2,2,2,2,2,2,2,2,2,2,1
2,2,2,2,2,2,2,2,2,2,2,2,2,2,2,2,2
2,2,2,2,2,2,2,2,2,2,2,2,2,2,2,2,2
2,2,2,2,2,2,2,2,2,2,2,2,2,2,2,2,2
2,2,2,2,2,2,2,2,2,2,2,2,2,2,2,2,2
2,2,2,2,2,2,2,2,2,2,2,2,2,2,2,2,2
1,2,2,2,2,2,2,2,2,2,2,2,2,2,2,2,1
1,2,2,2,2,2,2,2,2,2,2,2,2,2,2,2,1
1,1,2,2,2,2,2,2,2,2,2,2,2,2,2,1,1
1,1,1,2,2,2,2,2,2,2,2,2,2,2,1,1,1
1,1,1,1,2,2,2,2,2,2,2,2,2,1,1,1,1
1,1,1,1,1,1,2,2,2,2,2,1,1,1,1,1,1
endlayer

layer
1,1,1,1,1,1,2,2,2,2,2,1,1,1,1,1,1
1,1,1,1,2,2,2,2,2,2,2,2,2,1,1,1,1
1,1,1,2,2,2,2,2,2,2,2,2,2,2,1,1,1
1,1,2,2,2,2,2,2,2,2,2,2,2,2,2,1,1
1,2,2,2,2,2,2,2,2,2,2,2,2,2,2,2,1
1,2,2,2,2,2,2,2,2,2,2,2,2,2,2,2,1
2,2,2,2,2,2,2,2,2,2,2,2,2,2,2,2,2
2,2,2,2,2,2,2,2,2,2,2,2,2,2,2,2,2
2,2,2,2,2,2,2,2,2,2,2,2,2,2,2,2,2
2,2,2,2,2,2,2,2,2,2,2,2,2,2,2,2,2
2,2,2,2,2,2,2,2,2,2,2,2,2,2,2,2,2
1,2,2,2,2,2,2,2,2,2,2,2,2,2,2,2,1
1,2,2,2,2,2,2,2,2,2,2,2,2,2,2,2,1
1,1,2,2,2,2,2,2,2,2,2,2,2,2,2,1,1
1,1,1,2,2,2,2,2,2,2,2,2,2,2,1,1,1
1,1,1,1,2,2,2,2,2,2,2,2,2,1,1,1,1
1,1,1,1,1,1,2,2,2,2,2,1,1,1,1,1,1
endlayer

layer
1,1,1,1,1,1,2,2,2,2,2,1,1,1,1,1,1
1,1,1,1,2,2,2,2,2,2,2,2,2,1,1,1,1
1,1,1,2,2,2,2,2,2,2,2,2,2,2,1,1,1
1,1,2,2,2,2,2,2,2,2,2,2,2,2,2,1,1
1,2,2,2,2,2,2,2,2,2,2,2,2,2,2,2,1
1,2,2,2,2,2,2,2,2,2,2,2,2,2,2,2,1
2,2,2,2,2,2,2,2,2,2,2,2,2,2,2,2,2
2,2,2,2,2,2,2,2,2,2,2,2,2,2,2,2,2
2,2,2,2,2,2,2,2,2,2,2,2,2,2,2,2,2
2,2,2,2,2,2,2,2,2,2,2,2,2,2,2,2,2
2,2,2,2,2,2,2,2,2,2,2,2,2,2,2,2,2
1,2,2,2,2,2,2,2,2,2,2,2,2,2,2,2,1
1,2,2,2,2,2,2,2,2,2,2,2,2,2,2,2,1
1,1,2,2,2,2,2,2,2,2,2,2,2,2,2,1,1
1,1,1,2,2,2,2,2,2,2,2,2,2,2,1,1,1
1,1,1,1,2,2,2,2,2,2,2,2,2,1,1,1,1
1,1,1,1,1,1,2,2,2,2,2,1,1,1,1,1,1
endlayer

layer
1,1,1,1,1,1,2,2,2,2,2,1,1,1,1,1,1
1,1,1,1,2,2,2,2,2,2,2,2,2,1,1,1,1
1,1,1,2,2,2,2,2,2,2,2,2,2,2,1,1,1
1,1,2,2,2,2,2,2,2,2,2,2,2,2,2,1,1
1,2,2,2,2,2,2,2,2,2,2,2,2,2,2,2,1
1,2,2,2,2,2,2,2,2,2,2,2,2,2,2,2,1
2,2,2,2,2,2,2,2,2,2,2,2,2,2,2,2,2
2,2,2,2,2,2,2,2,2,2,2,2,2,2,2,2,2
2,2,2,2,2,2,2,2,2,2,2,2,2,2,2,2,2
2,2,2,2,2,2,2,2,2,2,2,2,2,2,2,2,2
2,2,2,2,2,2,2,2,2,2,2,2,2,2,2,2,2
1,2,2,2,2,2,2,2,2,2,2,2,2,2,2,2,1
1,2,2,2,2,2,2,2,2,2,2,2,2,2,2,2,1
1,1,2,2,2,2,2,2,2,2,2,2,2,2,2,1,1
1,1,1,2,2,2,2,2,2,2,2,2,2,2,1,1,1
1,1,1,1,2,2,2,2,2,2,2,2,2,1,1,1,1
1,1,1,1,1,1,2,2,2,2,2,1,1,1,1,1,1
endlayer

layer
1,1,1,1,1,1,2,2,2,2,2,1,1,1,1,1,1
1,1,1,1,2,2,2,2,2,2,2,2,2,1,1,1,1
1,1,1,2,2,2,2,2,2,2,2,2,2,2,1,1,1
1,1,2,2,2,2,2,2,2,2,2,2,2,2,2,1,1
1,2,2,2,2,2,2,2,2,2,2,2,2,2,2,2,1
1,2,2,2,2,2,2,2,2,2,2,2,2,2,2,2,1
2,2,2,2,2,2,2,2,2,2,2,2,2,2,2,2,2
2,2,2,2,2,2,2,2,2,2,2,2,2,2,2,2,2
2,2,2,2,2,2,2,2,2,2,2,2,2,2,2,2,2
2,2,2,2,2,2,2,2,2,2,2,2,2,2,2,2,2
2,2,2,2,2,2,2,2,2,2,2,2,2,2,2,2,2
1,2,2,2,2,2,2,2,2,2,2,2,2,2,2,2,1
1,2,2,2,2,2,2,2,2,2,2,2,2,2,2,2,1
1,1,2,2,2,2,2,2,2,2,2,2,2,2,2,1,1
1,1,1,2,2,2,2,2,2,2,2,2,2,2,1,1,1
1,1,1,1,2,2,2,2,2,2,2,2,2,1,1,1,1
1,1,1,1,1,1,2,2,2,2,2,1,1,1,1,1,1
endlayer

layer
1,1,1,1,1,1,2,2,2,2,2,1,1,1,1,1,1
1,1,1,1,2,2,3,3,3,3,3,2,2,1,1,1,1
1,1,1,2,3,3,3,3,3,3,3,3,3,2,1,1,1
1,1,2,3,3,3,3,3,3,3,3,3,3,3,2,1,1
1,2,3,3,3,3,3,3,3,3,3,3,3,3,3,2,1
1,2,3,3,3,4,3,3,3,3,3,3,3,3,3,2,1
2,3,3,3,3,3,3,5,5,3,3,3,3,3,3,3,2
2,3,3,3,3,3,5,5,5,5,3,3,3,3,3,3,2
2,3,3,3,5,5,5,5,5,5,3,3,3,3,3,3,2
2,3,3,3,5,5,5,5,5,5,3,3,3,3,3,3,2
2,3,3,3,5,5,5,5,5,3,4,3,3,3,3,3,2
1,2,3,3,3,5,5,3,3,3,3,3,3,3,3,2,1
1,2,3,3,3,3,3,3,3,3,3,3,3,3,3,2,1
1,1,2,3,3,3,3,3,3,3,3,3,3,3,2,1,1
1,1,1,2,3,3,3,3,3,3,3,3,3,2,1,1,1
1,1,1,1,2,2,3,3,3,3,3,2,2,1,1,1,1
1,1,1,1,1,1,2,2,2,2,2,1,1,1,1,1,1
endlayer

layer
1,1,1,1,1,1,2,2,2,2,2,1,1,1,1,1,1
1,1,1,1,2,2,0,0,7,7,6,2,2,1,1,1,1
1,1,1,2,0,0,8,0,0,0,7,7,0,2,1,1,1
1,1,2,0,9,0,0,0,0,7,0,0,6,7,2,1,1
1,2,0,0,0,9,0,0,0,0,0,7,7,10,0,2,1
1,2,0,0,0,11,9,0,0,7,0,0,7,0,7,2,1
2,7,0,7,0,0,0,0,0,7,0,0,7,0,0,6,2
2,0,10,7,0,0,0,0,0,0,0,0,0,7,6,10,2
2,6,0,7,0,0,0,0,0,0,7,0,0,7,0,7,2
2,0,6,7,0,0,0,0,0,0,0,0,0,0,7,7,2
2,7,0,7,0,0,0,0,0,0,11,9,0,0,0,6,2
1,2,7,7,0,0,0,0,0,7,0,0,0,9,0,2,1
1,2,0,6,7,0,0,0,9,0,0,0,0,0,0,2,1
1,1,2,7,10,0,7,0,0,9,9,0,8,9,2,1,1
1,1,1,2,6,7,7,0,0,0,9,9,0,2,1,1,1
1,1,1,1,2,2,7,0,10,0,9,2,2,1,1,1,1
1,1,1,1,1,1,2,2,2,2,2,1,1,1,1,1,1
endlayer

layer
1,1,1,1,1,1,12,12,12,12,12,1,1,1,1,1,1
1,1,1,1,12,12,0,0,0,0,13,12,12,1,1,1,1
1,1,1,12,0,0,0,0,0,0,0,0,0,12,1,1,1
1,1,12,0,0,0,0,0,0,0,0,0,13,0,12,1,1
1,12,0,0,0,0,0,0,0,0,0,0,0,0,0,12,1
1,12,0,0,0,11,0,0,0,0,0,0,0,0,0,12,1
12,0,0,0,0,0,0,0,0,0,0,0,0,0,0,13,12
12,0,0,0,0,0,0,0,0,0,0,0,0,0,13,0,12
12,13,0,0,0,0,0,0,0,0,0,0,0,0,0,0,12
12,0,13,0,0,0,0,0,0,0,0,0,0,0,0,0,12
12,0,0,0,0,0,0,0,0,0,11,0,0,0,0,13,12
1,12,0,0,0,0,0,0,0,0,0,0,0,0,0,12,1
1,12,0,13,0,0,0,0,0,0,0,0,0,0,0,12,1
1,1,12,0,0,0,0,0,0,0,0,0,0,0,12,1,1
1,1,1,12,13,0,0,0,0,0,0,0,0,12,1,1,1
1,1,1,1,12,12,0,0,0,0,0,12,12,1,1,1,1
1,1,1,1,1,1,12,12,12,12,12,1,1,1,1,1,1
endlayer

layer
1,1,1,1,1,1,12,12,12,12,12,1,1,1,1,1,1
1,1,1,1,12,12,0,0,0,0,0,12,12,1,1,1,1
1,1,1,12,0,0,0,0,0,0,0,0,0,12,1,1,1
1,1,12,0,14,14,14,0,0,0,0,0,0,0,12,1,1
1,12,0,14,14,14,14,14,0,0,0,0,0,0,0,12,1
1,12,0,14,14,11,14,14,0,0,0,0,0,0,0,12,1
12,0,0,14,14,14,14,14,0,0,0,0,0,0,0,0,12
12,0,0,0,14,14,14,0,0,0,0,0,0,0,0,0,12
12,0,0,0,0,0,0,0,0,0,0,0,0,0,0,0,12
12,0,0,0,0,0,15,0,0,0,0,0,0,0,0,0,12
12,0,0,0,0,0,0,0,0,0,11,0,0,0,0,0,12
1,12,0,0,0,0,0,0,0,0,0,0,0,0,0,12,1
1,12,0,0,0,0,0,0,0,0,0,0,0,0,0,12,1
1,1,12,0,0,0,0,0,0,0,0,0,0,0,12,1,1
1,1,1,12,0,0,0,0,0,0,0,0,0,12,1,1,1
1,1,1,1,12,12,0,0,0,0,0,12,12,1,1,1,1
1,1,1,1,1,1,12,12,12,12,12,1,1,1,1,1,1
endlayer

layer
1,1,1,1,1,1,1,12,12,12,1,1,1,1,1,1,1
1,1,1,1,12,12,12,0,0,0,12,12,12,1,1,1,1
1,1,1,12,0,0,0,0,0,0,0,0,0,12,1,1,1
1,1,12,0,14,14,14,0,0,0,0,0,0,0,12,1,1
1,12,0,14,14,14,14,14,0,0,0,0,0,0,0,12,1
1,12,0,14,14,11,14,14,0,0,0,0,0,0,0,12,1
1,12,0,14,14,14,14,14,0,0,0,0,0,0,0,12,1
12,0,0,0,14,14,14,0,0,0,0,0,0,0,0,0,12
12,0,0,0,0,0,0,0,0,14,14,14,0,0,0,0,12
12,0,0,0,0,0,15,0,16,14,14,14,14,0,0,0,12
1,12,0,0,0,0,0,0,16,14,11,14,14,0,0,12,1
1,12,0,0,0,0,0,0,16,14,14,14,14,0,0,12,1
1,12,0,0,0,0,0,0,0,14,14,14,0,0,0,12,1
1,1,12,0,0,0,0,0,0,0,0,0,0,0,12,1,1
1,1,1,12,0,0,0,0,0,0,0,0,0,12,1,1,1
1,1,1,1,12,12,12,0,0,0,12,12,12,1,1,1,1
1,1,1,1,1,1,1,12,12,12,1,1,1,1,1,1,1
endlayer

layer
1,1,1,1,1,1,1,1,1,1,1,1,1,1,1,1,1
1,1,1,1,1,12,12,12,12,12,12,12,1,1,1,1,1
1,1,1,12,12,0,0,0,0,0,0,0,12,12,1,1,1
1,1,12,0,0,0,0,0,0,0,0,0,0,0,12,1,1
1,1,12,0,14,14,14,0,0,0,0,0,0,0,12,1,1
1,12,0,0,14,14,14,0,0,0,0,0,0,0,0,12,1
1,12,0,0,14,14,14,0,0,0,0,0,0,0,0,12,1
1,12,0,0,0,0,0,0,0,0,0,0,0,0,0,12,1
1,12,0,0,0,0,0,0,0,14,14,14,0,0,0,12,1
1,12,0,0,0,0,15,0,16,14,14,14,14,0,0,12,1
1,12,0,0,0,0,0,0,16,14,11,14,14,0,0,12,1
1,12,0,0,0,0,0,0,16,14,14,14,14,0,0,12,1
1,1,12,0,0,0,0,0,0,14,14,14,0,0,12,1,1
1,1,12,0,0,0,0,0,0,0,0,0,0,0,12,1,1
1,1,1,12,12,0,0,0,0,0,0,0,12,12,1,1,1
1,1,1,1,1,12,12,12,12,12,12,12,1,1,1,1,1
1,1,1,1,1,1,1,1,1,1,1,1,1,1,1,1,1
endlayer

layer
1,1,1,1,1,1,1,1,1,1,1,1,1,1,1,1,1
1,1,1,1,1,1,12,12,12,12,12,1,1,1,1,1,1
1,1,1,1,12,12,0,0,0,0,0,12,12,1,1,1,1
1,1,1,12,0,0,0,0,0,0,0,0,0,12,1,1,1
1,1,12,0,0,14,0,0,0,0,0,0,0,0,12,1,1
1,1,12,0,14,14,14,0,0,0,0,0,0,0,12,1,1
1,12,0,0,0,14,0,0,0,0,0,0,0,0,0,12,1
1,12,0,0,0,0,0,0,0,0,0,0,0,0,0,12,1
1,12,0,0,0,0,0,0,0,0,0,0,0,0,0,12,1
1,12,0,0,0,0,15,0,0,14,14,14,0,0,0,12,1
1,12,0,0,0,0,0,0,0,14,14,14,0,0,0,12,1
1,1,12,0,0,0,0,0,0,14,14,14,0,0,12,1,1
1,1,12,0,0,0,0,0,0,0,0,0,0,0,12,1,1
1,1,1,12,0,0,0,0,0,0,0,0,0,12,1,1,1
1,1,1,1,12,12,0,0,0,0,0,12,12,1,1,1,1
1,1,1,1,1,1,12,12,12,12,12,1,1,1,1,1,1
1,1,1,1,1,1,1,1,1,1,1,1,1,1,1,1,1
endlayer

layer
1,1,1,1,1,1,1,1,1,1,1,1,1,1,1,1,1
1,1,1,1,1,1,1,1,1,1,1,1,1,1,1,1,1
1,1,1,1,1,12,12,12,12,12,12,12,1,1,1,1,1
1,1,1,1,12,0,0,0,0,0,0,0,12,1,1,1,1
1,1,1,12,0,0,0,0,0,0,0,0,0,12,1,1,1
1,1,12,0,0,0,0,0,0,0,0,0,0,0,12,1,1
1,1,12,0,0,0,0,0,0,0,0,0,0,0,12,1,1
1,1,12,0,0,0,0,0,0,0,0,0,0,0,12,1,1
1,1,12,0,0,0,0,0,0,0,0,0,0,0,12,1,1
1,1,12,0,0,0,0,0,0,0,14,0,0,0,12,1,1
1,1,12,0,0,0,0,0,0,14,14,14,0,0,12,1,1
1,1,12,0,0,0,0,0,0,0,14,0,0,0,12,1,1
1,1,1,12,0,0,0,0,0,0,0,0,0,12,1,1,1
1,1,1,1,12,0,0,0,0,0,0,0,12,1,1,1,1
1,1,1,1,1,12,12,12,12,12,12,12,1,1,1,1,1
1,1,1,1,1,1,1,1,1,1,1,1,1,1,1,1,1
1,1,1,1,1,1,1,1,1,1,1,1,1,1,1,1,1
endlayer

layer
1,1,1,1,1,1,1,1,1,1,1,1,1,1,1,1,1
1,1,1,1,1,1,1,1,1,1,1,1,1,1,1,1,1
1,1,1,1,1,1,1,1,1,1,1,1,1,1,1,1,1
1,1,1,1,1,12,12,12,12,12,12,12,1,1,1,1,1
1,1,1,1,12,12,0,0,0,0,0,12,12,1,1,1,1
1,1,1,12,12,0,0,0,0,0,0,0,12,12,1,1,1
1,1,1,12,0,0,0,0,0,0,0,0,0,12,1,1,1
1,1,1,12,0,0,0,0,0,0,0,0,0,12,1,1,1
1,1,1,12,0,0,0,0,0,0,0,0,0,12,1,1,1
1,1,1,12,0,0,0,0,0,0,0,0,0,12,1,1,1
1,1,1,12,0,0,0,0,0,0,0,0,0,12,1,1,1
1,1,1,12,12,0,0,0,0,0,0,0,12,12,1,1,1
1,1,1,1,12,12,0,0,0,0,0,12,12,1,1,1,1
1,1,1,1,1,12,12,12,12,12,12,12,1,1,1,1,1
1,1,1,1,1,1,1,1,1,1,1,1,1,1,1,1,1
1,1,1,1,1,1,1,1,1,1,1,1,1,1,1,1,1
1,1,1,1,1,1,1,1,1,1,1,1,1,1,1,1,1
endlayer

layer
1,1,1,1,1,1,1,1,1,1,1,1,1,1,1,1,1
1,1,1,1,1,1,1,1,1,1,1,1,1,1,1,1,1
1,1,1,1,1,1,1,1,1,1,1,1,1,1,1,1,1
1,1,1,1,1,1,1,1,1,1,1,1,1,1,1,1,1
1,1,1,1,1,1,12,12,12,12,12,1,1,1,1,1,1
1,1,1,1,1,12,12,12,12,12,12,12,1,1,1,1,1
1,1,1,1,12,12,12,0,0,0,12,12,12,1,1,1,1
1,1,1,1,12,12,0,0,0,0,0,12,12,1,1,1,1
1,1,1,1,12,12,0,0,0,0,0,12,12,1,1,1,1
1,1,1,1,12,12,0,0,0,0,0,12,12,1,1,1,1
1,1,1,1,12,12,12,0,0,0,12,12,12,1,1,1,1
1,1,1,1,1,12,12,12,12,12,12,12,1,1,1,1,1
1,1,1,1,1,1,12,12,12,12,12,1,1,1,1,1,1
1,1,1,1,1,1,1,1,1,1,1,1,1,1,1,1,1
1,1,1,1,1,1,1,1,1,1,1,1,1,1,1,1,1
1,1,1,1,1,1,1,1,1,1,1,1,1,1,1,1,1
1,1,1,1,1,1,1,1,1,1,1,1,1,1,1,1,1
endlayer

layer
1,1,1,1,1,1,1,1,1,1,1,1,1,1,1,1,1
1,1,1,1,1,1,1,1,1,1,1,1,1,1,1,1,1
1,1,1,1,1,1,1,1,1,1,1,1,1,1,1,1,1
1,1,1,1,1,1,1,1,1,1,1,1,1,1,1,1,1
1,1,1,1,1,1,1,1,1,1,1,1,1,1,1,1,1
1,1,1,1,1,1,1,1,1,1,1,1,1,1,1,1,1
1,1,1,1,1,1,1,12,12,12,1,1,1,1,1,1,1
1,1,1,1,1,1,12,12,12,12,12,1,1,1,1,1,1
1,1,1,1,1,1,12,12,12,12,12,1,1,1,1,1,1
1,1,1,1,1,1,12,12,12,12,12,1,1,1,1,1,1
1,1,1,1,1,1,1,12,12,12,1,1,1,1,1,1,1
1,1,1,1,1,1,1,1,1,1,1,1,1,1,1,1,1
1,1,1,1,1,1,1,1,1,1,1,1,1,1,1,1,1
1,1,1,1,1,1,1,1,1,1,1,1,1,1,1,1,1
1,1,1,1,1,1,1,1,1,1,1,1,1,1,1,1,1
1,1,1,1,1,1,1,1,1,1,1,1,1,1,1,1,1
1,1,1,1,1,1,1,1,1,1,1,1,1,1,1,1,1
endlayer

