
# Created by Ruins mod version 17.0 Ingame Parser
# authoring Player: ST753M

weight=2
embed_into_distance=2
acceptable_target_blocks=water
unacceptable_target_blocks=
dimensions=26,32,15
allowable_overhang=0
uniqueMinDistance=1000
max_leveling=0
leveling_buffer=0
preserve_water=0
preserve_lava=0

biomesToSpawnIn=deep_ocean,ocean,coral_reef,kelp_forest,coralium_infested_ocean

rule1=0,100,preserveBlock
rule2=0,100,minecraft:log-4
rule3=0,100,minecraft:planks-1
rule4=0,100,minecraft:planks-0
rule5=0,100,minecraft:spruce_stairs-1
rule6=0,100,minecraft:spruce_stairs-3
rule7=0,100,minecraft:spruce_stairs-2
rule8=0,100,minecraft:log-0
rule9=0,100,minecraft:bed-10
rule10=0,100,minecraft:bed-2
rule11=0,100,minecraft:spruce_door-0
rule12=0,100,iceandfire:goldpile-2
rule13=0,100,iceandfire:goldpile-0
rule14=0,100,iceandfire:goldpile-3
rule15=0,100,iceandfire:goldpile-1
rule16=0,100,iceandfire:goldpile-4
rule17=0,100,iceandfire:goldpile-7
rule18=0,100,iceandfire:goldpile-5
rule19=0,100,IInventory;minecraft:chest;minecraft:potion#{Potion:"minecraft:long_poison"}#0#1+minecraft:gold_nugget#1#0#4+iceandfire:sapphire_gem#1#0#5+minecraft:potion#{Potion:"minecraft:strong_poison"}#0#7+minecraft:gold_nugget#1#0#10+minecraft:potion#{Potion:"minecraft:poison"}#0#11+iceandfire:sapphire_gem#2#0#13+minecraft:gold_nugget#2#0#17+minecraft:gold_nugget#2#0#20+minecraft:potion#{Potion:"minecraft:long_poison"}#0#24+iceandfire:sapphire_gem#1#0#25-3,air
rule20=0,100,minecraft:ladder-4
rule21=0,100,minecraft:spruce_stairs-4
rule22=0,100,minecraft:spruce_stairs-6
rule23=0,100,minecraft:spruce_stairs-7
rule24=0,100,minecraft:ladder-2
rule25=0,100,minecraft:ladder-3
rule26=0,100,minecraft:spruce_door-8
rule27=0,100,minecraft:spruce_stairs-5
rule28=0,100,minecraft:wooden_slab-8
rule29=0,100,minecraft:oak_stairs-4
rule30=0,100,minecraft:oak_stairs-6
rule31=0,100,minecraft:double_wooden_slab-0
rule32=0,100,minecraft:oak_stairs-7
rule33=0,100,minecraft:trapdoor-10
rule34=0,100,minecraft:wooden_slab-9
rule35=0,100,MobSpawner:skeleton,MobSpawner:zombie
rule36=0,100,Skull:0:0-5
rule37=0,100,minecraft:spruce_fence-0
rule38=0,100,minecraft:oak_stairs-1
rule39=0,100,minecraft:oak_stairs-0
rule40=0,100,minecraft:ladder-5
rule41=0,100,minecraft:wooden_slab-1
rule42=0,100,minecraft:spruce_stairs-0
rule43=0,100,minecraft:stained_glass_pane-7
rule44=0,100,minecraft:carpet-12
rule45=0,100,minecraft:wooden_slab-0
rule46=0,100,minecraft:oak_stairs-5
rule47=0,100,minecraft:trapdoor-9
rule48=0,100,minecraft:trapdoor-8
rule49=0,100,minecraft:log-8
# Sail
rule50=0,100,minecraft:wool-15
^0,100,minecraft:wool-0
^0,100,minecraft:wool-8
^0,100,minecraft:wool-7
# Flag
rule51=0,100,minecraft:wool-0
^0,100,minecraft:wool-1
^0,100,minecraft:wool-2
^0,100,minecraft:wool-3
^0,100,minecraft:wool-4
^0,100,minecraft:wool-5
^0,100,minecraft:wool-6
^0,100,minecraft:wool-7
^0,100,minecraft:wool-8
^0,100,minecraft:wool-9
^0,100,minecraft:wool-10
^0,100,minecraft:wool-11
^0,100,minecraft:wool-12
^0,100,minecraft:wool-13
^0,100,minecraft:wool-14
^0,100,minecraft:wool-15

layer
1,1,1,1,1,1,1,2,1,1,1,1,1,1,1
1,1,1,1,1,1,1,2,1,1,1,1,1,1,1
1,1,1,1,1,1,1,2,1,1,1,1,1,1,1
1,1,1,1,1,1,3,2,3,1,1,1,1,1,1
1,1,1,1,1,3,3,2,3,3,1,1,1,1,1
1,1,1,1,1,3,3,2,3,3,1,1,1,1,1
1,1,1,1,1,3,3,2,3,3,1,1,1,1,1
1,1,1,1,1,3,3,2,3,3,1,1,1,1,1
1,1,1,1,1,3,3,2,3,3,1,1,1,1,1
1,1,1,1,1,3,3,2,3,3,1,1,1,1,1
1,1,1,1,1,3,3,2,3,3,1,1,1,1,1
1,1,1,1,1,3,3,2,3,3,1,1,1,1,1
1,1,1,1,1,3,3,2,3,3,1,1,1,1,1
1,1,1,1,1,3,3,2,3,3,1,1,1,1,1
1,1,1,1,1,3,3,2,3,3,1,1,1,1,1
1,1,1,1,1,3,3,2,3,3,1,1,1,1,1
1,1,1,1,1,3,3,2,3,3,1,1,1,1,1
1,1,1,1,1,3,3,2,3,3,1,1,1,1,1
1,1,1,1,1,3,3,2,3,3,1,1,1,1,1
1,1,1,1,1,3,3,2,3,3,1,1,1,1,1
1,1,1,1,1,3,3,2,3,3,1,1,1,1,1
1,1,1,1,1,3,3,2,3,3,1,1,1,1,1
1,1,1,1,1,1,3,2,3,1,1,1,1,1,1
1,1,1,1,1,1,1,2,1,1,1,1,1,1,1
1,1,1,1,1,1,1,2,1,1,1,1,1,1,1
1,1,1,1,1,1,1,2,1,1,1,1,1,1,1
1,1,1,1,1,1,1,1,1,1,1,1,1,1,1
1,1,1,1,1,1,1,1,1,1,1,1,1,1,1
1,1,1,1,1,1,1,1,1,1,1,1,1,1,1
1,1,1,1,1,1,1,1,1,1,1,1,1,1,1
1,1,1,1,1,1,1,1,1,1,1,1,1,1,1
1,1,1,1,1,1,1,1,1,1,1,1,1,1,1
endlayer

layer
1,1,1,1,1,1,1,1,1,1,1,1,1,1,1
1,1,1,1,4,1,1,1,1,1,4,1,1,1,1
1,1,1,1,1,3,3,5,3,3,1,1,1,1,1
1,1,1,1,3,7,0,0,0,6,3,1,1,1,1
1,1,1,1,3,0,0,0,0,0,3,1,1,1,1
1,1,1,1,3,0,0,0,0,0,3,1,1,1,1
1,1,1,1,3,0,0,0,0,0,3,1,1,1,1
1,1,1,1,3,0,0,0,0,0,3,1,1,1,1
1,1,1,1,3,0,0,8,3,3,3,1,1,1,1
1,1,4,1,3,0,0,0,10,9,3,1,4,1,1
1,1,1,1,3,0,0,0,0,0,3,1,1,1,1
1,1,1,1,3,0,0,0,10,9,3,1,1,1,1
1,1,1,1,3,0,0,0,0,0,3,1,1,1,1
1,1,1,1,3,0,0,0,0,0,3,1,1,1,1
1,1,1,1,3,0,0,0,10,9,3,1,1,1,1
1,1,1,1,3,0,0,0,0,0,3,1,1,1,1
1,1,1,1,3,0,0,0,10,9,3,1,1,1,1
1,1,1,1,3,11,3,8,3,3,3,1,1,1,1
1,1,1,1,3,0,0,0,13,12,3,1,1,1,1
1,1,1,1,3,0,0,13,14,13,3,1,1,1,1
1,1,1,1,3,13,0,12,15,14,3,1,1,1,1
1,1,1,1,3,16,15,18,17,16,3,1,1,1,1
1,1,1,1,1,3,12,14,19,3,1,1,1,1,1
1,1,1,1,1,1,3,3,3,1,1,1,1,1,1
1,1,1,1,1,1,1,1,1,1,1,1,1,1,1
1,1,1,1,1,1,1,1,1,1,1,1,1,1,1
1,1,1,1,1,1,1,1,1,1,1,1,1,1,1
1,1,1,1,1,1,1,1,1,1,1,1,1,1,1
1,1,1,1,1,1,1,1,1,1,1,1,1,1,1
1,1,1,1,1,1,1,1,1,1,1,1,1,1,1
1,1,1,1,1,1,1,1,1,1,1,1,1,1,1
1,1,1,1,1,1,1,1,1,1,1,1,1,1,1
endlayer

layer
1,1,1,1,20,0,0,0,0,0,20,1,1,1,1
1,1,1,1,4,3,3,3,3,3,4,1,1,1,1
1,1,1,21,3,3,7,0,6,3,3,21,1,1,1
1,1,1,23,0,0,0,0,0,0,0,22,1,1,1
1,1,1,23,0,0,0,0,0,0,0,22,1,1,1
1,1,1,23,0,0,0,0,0,0,0,22,1,1,1
1,1,1,23,0,0,0,0,0,0,0,22,1,1,1
1,1,1,23,0,0,0,0,0,0,0,22,1,1,1
1,1,1,23,0,0,0,8,22,23,3,22,1,1,1
1,25,4,23,0,0,0,0,0,0,0,22,4,24,1
1,1,1,23,0,0,0,0,0,0,0,22,1,1,1
1,1,1,23,0,0,0,0,0,0,0,22,1,1,1
1,1,1,23,0,0,0,0,0,0,0,22,1,1,1
1,1,1,23,0,0,0,0,0,0,0,22,1,1,1
1,1,1,23,0,0,0,0,0,0,0,22,1,1,1
1,1,1,23,0,0,0,0,0,0,0,22,1,1,1
1,1,1,23,0,0,0,0,0,0,0,22,1,1,1
1,1,1,23,3,26,3,8,3,3,3,22,1,1,1
1,1,1,23,15,0,0,0,0,0,13,22,1,1,1
1,1,1,23,0,0,0,0,0,0,0,22,1,1,1
1,1,1,23,12,0,0,0,0,0,15,22,1,1,1
1,1,1,23,13,0,0,0,0,0,13,22,1,1,1
1,1,1,1,3,14,0,0,0,12,3,1,1,1,1
1,1,1,1,1,3,15,13,13,3,1,1,1,1,1
1,1,1,1,1,1,27,3,27,1,1,1,1,1,1
1,1,1,1,1,1,1,27,1,1,1,1,1,1,1
1,1,1,1,1,1,1,1,1,1,1,1,1,1,1
1,1,1,1,1,1,1,1,1,1,1,1,1,1,1
1,1,1,1,1,1,1,1,1,1,1,1,1,1,1
1,1,1,1,1,1,1,1,1,1,1,1,1,1,1
1,1,1,1,1,1,1,1,1,1,1,1,1,1,1
1,1,1,1,1,1,1,1,1,1,1,1,1,1,1
endlayer

layer
1,28,29,28,20,29,28,29,28,29,20,28,29,28,1
1,32,31,31,31,3,3,3,3,3,31,31,31,30,1
1,28,31,31,3,7,0,0,0,6,3,31,31,28,1
1,28,32,3,27,27,33,33,33,27,27,3,30,28,1
1,28,28,3,34,34,34,34,34,34,34,3,28,28,1
1,28,32,3,34,34,34,34,34,34,34,3,30,28,1
1,28,28,3,34,34,34,34,34,34,34,3,28,28,1
1,28,32,3,34,34,21,21,22,34,34,3,30,28,1
1,28,28,3,34,34,23,35,3,3,3,3,28,28,1
1,25,4,3,34,34,27,27,22,34,34,3,4,24,1
1,1,28,3,34,34,34,34,34,34,34,3,28,1,1
1,1,32,3,34,34,34,34,34,34,34,3,30,1,1
1,1,28,3,34,34,34,34,34,34,34,3,28,1,1
1,1,32,3,34,34,34,34,34,34,34,3,30,1,1
1,1,28,3,34,34,34,34,34,34,34,3,28,1,1
1,1,32,3,34,34,34,34,34,34,34,3,30,1,1
1,1,28,3,34,34,23,21,22,34,34,3,28,1,1
1,1,32,3,3,3,3,35,3,3,3,3,30,1,1
1,1,28,3,34,34,23,27,22,34,34,3,28,1,1
1,1,32,3,34,34,34,34,34,34,34,3,30,1,1
1,1,28,3,34,34,34,34,34,34,34,3,28,1,1
1,1,32,3,34,34,34,34,34,34,34,3,30,1,1
1,1,1,32,3,34,34,34,34,34,3,30,1,1,1
1,1,1,1,32,3,34,34,34,3,30,1,1,1,1
1,1,1,1,1,32,3,3,3,30,1,1,1,1,1
1,1,1,1,1,1,32,2,30,1,1,1,1,1,1
1,1,1,1,1,1,1,2,1,1,1,1,1,1,1
1,1,1,1,1,1,1,2,1,1,1,1,1,1,1
1,1,1,1,1,1,1,2,1,1,1,1,1,1,1
1,1,1,1,1,1,1,2,1,1,1,1,1,1,1
1,1,1,1,1,1,1,2,1,1,1,1,1,1,1
1,1,1,1,1,1,1,36,1,1,1,1,1,1,1
endlayer

layer
1,37,37,37,0,0,0,0,0,0,0,37,37,37,1
1,37,0,0,0,3,3,3,3,3,0,0,0,37,1
1,37,0,0,3,0,0,0,0,0,3,0,0,37,1
1,37,0,3,0,0,0,0,0,0,0,3,0,37,1
1,37,0,3,38,0,0,0,0,0,38,3,0,37,1
1,37,0,3,37,0,0,0,0,0,37,3,0,37,1
1,37,0,3,39,0,0,0,0,0,39,3,0,37,1
1,37,0,3,0,0,0,0,0,0,0,3,0,37,1
1,37,0,0,3,11,3,8,3,3,3,0,0,37,1
1,0,0,0,0,0,0,40,0,0,0,0,0,0,1
1,1,5,0,0,0,0,0,0,0,0,0,5,1,1
1,1,5,0,0,0,0,0,0,0,0,0,5,1,1
1,1,5,0,0,0,0,0,0,0,0,0,5,1,1
1,1,5,0,0,0,0,0,0,0,0,0,5,1,1
1,1,5,0,0,0,0,0,0,0,0,0,5,1,1
1,1,5,0,0,0,0,0,0,0,0,0,5,1,1
1,1,5,0,0,0,0,20,0,0,0,0,5,1,1
1,1,5,0,0,0,0,8,0,0,0,0,5,1,1
1,1,5,0,0,0,0,0,0,0,0,0,5,1,1
1,1,5,0,41,0,0,0,0,0,41,0,5,1,1
1,1,5,0,3,0,0,0,0,0,3,0,5,1,1
1,1,5,6,3,0,0,0,0,0,3,7,5,1,1
1,1,27,1,27,39,0,0,0,39,27,1,27,1,1
1,1,1,1,1,27,42,0,42,27,1,1,1,1,1
1,1,1,1,1,0,3,42,3,0,1,1,1,1,1
1,1,1,1,1,1,27,3,27,1,1,1,1,1,1
1,1,1,1,1,1,1,27,1,1,1,1,1,1,1
1,1,1,1,1,1,1,0,1,1,1,1,1,1,1
1,1,1,1,1,1,1,37,1,1,1,1,1,1,1
1,1,1,1,1,1,1,0,1,1,1,1,1,1,1
1,1,1,1,1,1,1,37,1,1,1,1,1,1,1
1,1,1,1,1,1,1,1,1,1,1,1,1,1,1
endlayer

layer
1,0,0,0,0,0,0,0,0,0,0,0,0,0,1
1,0,0,0,0,3,43,3,43,3,0,0,0,0,1
1,0,0,0,3,0,0,0,0,0,3,0,0,0,1
1,0,0,3,0,0,0,0,0,0,0,3,0,0,1
1,0,0,43,0,0,0,0,0,0,0,43,0,0,1
1,0,0,3,44,0,0,0,0,0,44,3,0,0,1
1,0,0,43,0,0,0,0,0,0,0,43,0,0,1
1,0,0,3,0,0,0,0,0,0,0,3,0,0,1
1,0,0,0,3,26,3,8,3,43,3,0,0,0,1
1,0,0,0,0,0,0,40,0,0,0,0,0,0,1
1,1,45,0,0,0,0,0,0,0,0,0,45,1,1
1,1,45,0,0,0,0,0,0,0,0,0,45,1,1
1,1,45,0,0,0,0,0,0,0,0,0,45,1,1
1,1,45,0,0,0,0,0,0,0,0,0,45,1,1
1,1,45,0,0,0,0,0,0,0,0,0,45,1,1
1,1,45,0,0,0,0,0,0,0,0,0,45,1,1
1,1,45,0,0,0,0,20,0,0,0,0,45,1,1
1,1,45,0,0,0,0,8,0,0,0,0,45,1,1
1,1,45,0,0,0,0,0,0,0,0,0,45,1,1
1,1,45,0,0,0,0,0,0,0,0,0,45,1,1
1,1,45,0,0,0,0,0,0,0,0,0,45,1,1
1,1,45,45,41,0,0,0,0,0,41,45,45,1,1
1,1,45,1,3,0,0,0,0,0,3,1,45,1,1
1,1,45,1,1,4,0,0,0,4,1,1,45,1,1
1,1,1,1,1,32,42,0,42,30,1,1,1,1,1
1,1,1,1,1,1,4,42,4,1,1,1,1,1,1
1,1,1,1,1,1,46,3,46,1,1,1,1,1,1
1,1,1,1,1,1,1,3,1,1,1,1,1,1,1
1,1,1,1,1,1,1,3,1,1,1,1,1,1,1
1,1,1,1,1,1,1,34,1,1,1,1,1,1,1
1,1,1,1,1,1,1,37,1,1,1,1,1,1,1
1,1,1,1,1,1,1,1,1,1,1,1,1,1,1
endlayer

layer
1,0,0,0,0,29,28,29,28,29,0,0,0,0,1
1,0,0,0,29,3,3,3,3,3,29,0,0,0,1
1,0,0,32,3,34,34,34,34,34,3,30,0,0,1
1,0,32,3,34,34,34,34,34,34,34,3,30,0,1
1,0,28,3,34,48,34,34,34,47,34,3,28,0,1
1,0,32,3,34,48,34,34,34,47,34,3,30,0,1
1,0,28,3,34,48,34,34,34,47,34,3,28,0,1
1,0,32,3,34,34,34,34,34,34,34,3,30,0,1
1,0,0,32,3,3,3,8,3,3,3,30,0,0,1
1,0,0,0,46,28,46,40,46,28,46,0,0,0,1
1,1,0,0,0,0,28,28,28,0,0,0,0,1,1
1,1,0,0,0,0,0,0,0,0,0,0,0,1,1
1,1,0,0,0,0,0,0,0,0,0,0,0,1,1
1,1,0,0,0,0,0,0,0,0,0,0,0,1,1
1,1,0,0,0,0,0,0,0,0,0,0,0,1,1
1,1,0,0,0,0,0,0,0,0,0,0,0,1,1
1,1,0,0,0,0,0,20,0,0,0,0,0,1,1
1,1,0,0,0,0,0,8,0,0,0,0,0,1,1
1,1,0,0,0,0,0,0,0,0,0,0,0,1,1
1,1,1,1,0,0,0,0,0,0,0,0,0,1,1
1,1,1,1,0,0,0,0,0,0,0,1,1,1,1
1,1,1,1,0,0,0,0,0,0,0,1,1,1,1
1,1,1,1,37,0,0,0,0,0,37,1,1,1,1
1,1,1,1,1,41,0,0,0,41,1,1,1,1,1
1,1,1,1,1,3,0,0,0,3,1,1,1,1,1
1,1,1,1,1,27,42,0,42,27,1,1,1,1,1
1,1,1,1,1,1,3,42,3,1,1,1,1,1,1
1,1,1,1,1,1,27,2,27,1,1,1,1,1,1
1,1,1,1,1,1,1,2,1,1,1,1,1,1,1
1,1,1,1,1,1,1,2,1,1,1,1,1,1,1
1,1,1,1,1,1,1,2,1,1,1,1,1,1,1
1,1,1,1,1,1,1,2,1,1,1,1,1,1,1
endlayer

layer
1,0,0,0,0,7,7,3,6,6,0,0,0,0,1
1,0,0,0,3,0,0,0,0,0,3,0,0,0,1
1,0,0,3,0,0,0,8,0,0,0,3,0,0,1
1,0,5,0,0,0,0,0,0,0,0,0,5,0,1
1,0,5,0,0,0,0,0,0,0,0,0,5,0,1
1,0,3,0,0,0,0,0,0,0,0,0,3,0,1
1,0,42,0,0,0,0,0,0,0,0,0,42,0,1
1,0,42,0,0,0,0,20,0,0,0,0,42,0,1
1,0,0,3,0,0,0,8,0,0,0,3,0,0,1
1,0,0,0,7,6,0,40,0,7,6,0,0,0,1
1,1,0,0,0,0,7,3,6,0,0,0,0,1,1
1,1,0,0,0,0,0,0,0,0,0,0,0,1,1
1,1,0,0,0,0,0,0,0,0,0,0,0,1,1
1,1,0,0,0,0,0,0,0,0,0,0,0,1,1
1,1,0,0,0,0,0,0,0,0,0,0,0,1,1
1,1,0,0,0,0,0,0,0,0,0,0,0,1,1
1,1,0,0,0,0,0,20,0,0,0,0,0,1,1
1,1,0,0,0,0,0,8,0,0,0,0,0,1,1
1,1,0,0,0,0,0,0,0,0,0,0,0,1,1
1,1,1,1,1,1,1,1,1,0,0,0,0,1,1
1,1,1,1,1,1,1,1,1,1,1,1,1,1,1
1,1,1,1,1,1,1,1,1,1,1,1,1,1,1
1,1,1,1,1,1,1,1,1,1,1,1,1,1,1
1,1,1,1,1,1,1,1,1,1,1,1,1,1,1
1,1,1,1,1,1,1,1,1,1,1,1,1,1,1
1,1,1,1,1,37,0,0,0,37,1,1,1,1,1
1,1,1,1,1,1,1,1,1,1,1,1,1,1,1
1,1,1,1,1,1,1,42,0,1,1,1,1,1,1
1,1,1,1,1,1,1,27,1,1,1,1,1,1,1
1,1,1,1,1,1,1,0,1,1,1,1,1,1,1
1,1,1,1,1,1,1,0,1,1,1,1,1,1,1
1,1,1,1,1,1,1,37,1,1,1,1,1,1,1
endlayer

layer
0,0,0,0,0,45,45,45,45,45,0,0,0,0,0
0,0,0,0,45,0,0,0,0,0,45,0,0,0,0
0,0,0,45,0,0,0,8,0,0,0,45,0,0,0
0,0,45,0,0,0,0,0,0,0,0,0,45,0,0
0,0,45,0,0,0,0,0,0,0,0,0,45,0,0
0,0,45,0,0,0,0,0,0,0,0,0,45,0,0
0,0,45,0,0,0,0,0,0,0,0,0,45,0,0
0,0,45,0,0,0,0,20,0,0,0,0,45,0,0
0,0,0,45,0,0,0,8,0,0,0,45,0,0,0
0,0,0,0,45,45,0,0,0,45,45,0,0,0,0
0,0,0,0,0,0,45,45,45,0,0,0,0,0,0
0,0,0,0,0,0,0,0,0,0,0,0,0,0,0
0,0,0,0,0,0,0,0,0,0,0,0,0,0,0
0,0,0,0,0,0,0,0,0,0,0,0,0,0,0
0,0,0,0,0,0,0,0,0,0,0,0,0,0,0
0,0,0,0,0,0,0,0,0,0,0,0,0,0,0
0,0,0,0,0,0,0,20,0,0,0,0,0,0,0
23,49,49,49,49,49,49,8,49,49,49,49,49,49,22
50,50,0,0,0,50,50,0,50,50,0,0,0,50,50
1,1,1,1,1,1,1,1,1,0,0,0,0,1,1
1,1,1,1,1,1,1,1,1,1,1,1,1,1,1
1,1,1,1,1,1,1,1,1,1,1,1,1,1,1
1,1,1,1,1,1,1,1,1,1,1,1,1,1,1
1,1,1,1,1,1,1,1,1,1,1,1,1,1,1
1,1,1,1,1,1,1,1,1,1,1,1,1,1,1
1,1,1,1,1,1,1,1,1,1,1,1,1,1,1
1,1,1,1,1,1,1,1,1,1,1,1,1,1,1
1,1,1,1,1,1,1,1,1,1,1,1,1,1,1
1,1,1,1,1,1,1,42,1,1,1,1,1,1,1
1,1,1,1,1,1,1,27,1,1,1,1,1,1,1
1,1,1,1,1,1,1,34,1,1,1,1,1,1,1
1,1,1,1,1,1,1,37,1,1,1,1,1,1,1
endlayer

layer
0,0,0,0,0,0,0,0,0,0,0,0,0,0,0
0,0,0,0,0,0,0,0,0,0,0,0,0,0,0
0,0,0,0,0,0,0,41,0,0,0,0,0,0,0
0,0,0,0,0,0,0,0,0,0,0,0,0,0,0
0,0,0,0,0,0,0,0,0,0,0,0,0,0,0
0,0,0,0,0,0,0,0,0,0,0,0,0,0,0
0,0,0,0,0,0,0,0,0,0,0,0,0,0,0
0,0,0,0,0,0,0,20,0,0,0,0,0,0,0
0,0,0,0,0,0,0,8,0,0,0,0,0,0,0
0,0,0,0,0,0,0,0,0,0,0,0,0,0,0
0,0,0,0,0,0,0,0,0,0,0,0,0,0,0
0,0,0,0,0,0,0,0,0,0,0,0,0,0,0
0,0,0,0,0,0,0,0,0,0,0,0,0,0,0
0,0,0,0,0,0,0,0,0,0,0,0,0,0,0
0,0,0,0,0,0,0,0,0,0,0,0,0,0,0
0,0,0,0,0,0,0,0,0,0,0,0,0,0,0
0,0,0,0,0,0,0,20,0,0,0,0,0,0,0
37,0,0,0,0,0,0,8,0,0,0,0,0,0,37
0,0,0,0,0,0,0,0,0,0,0,0,0,0,0
50,50,0,0,0,50,1,1,1,50,0,0,0,50,50
1,1,50,50,50,1,1,1,1,1,50,50,50,1,1
1,1,1,1,1,1,1,1,1,1,1,1,1,1,1
1,1,1,1,1,1,1,1,1,1,1,1,1,1,1
1,1,1,1,1,1,1,1,1,1,1,1,1,1,1
1,1,1,1,1,1,1,1,1,1,1,1,1,1,1
1,1,1,1,1,1,1,1,1,1,1,1,1,1,1
1,1,1,1,1,1,1,1,1,1,1,1,1,1,1
1,1,1,1,1,1,1,1,1,1,1,1,1,1,1
1,1,1,1,1,1,1,1,1,1,1,1,1,1,1
1,1,1,1,1,1,1,37,1,1,1,1,1,1,1
1,1,1,1,1,1,1,1,1,1,1,1,1,1,1
1,1,1,1,1,1,1,50,1,1,1,1,1,1,1
endlayer

layer
0,0,0,0,0,0,0,0,0,0,0,0,0,0,0
0,0,0,0,0,0,0,0,0,0,0,0,0,0,0
0,0,0,0,0,0,0,0,0,0,0,0,0,0,0
0,0,0,0,0,0,0,0,0,0,0,0,0,0,0
0,0,0,0,0,0,0,0,0,0,0,0,0,0,0
0,0,0,0,0,0,0,0,0,0,0,0,0,0,0
0,0,0,0,0,0,0,0,0,0,0,0,0,0,0
0,0,0,0,0,0,0,20,0,0,0,0,0,0,0
23,49,49,49,49,49,49,8,49,49,49,49,49,49,22
50,50,0,0,0,50,50,0,50,50,0,0,0,50,50
0,0,0,0,0,0,0,0,0,0,0,0,0,0,0
0,0,0,0,0,0,0,0,0,0,0,0,0,0,0
0,0,0,0,0,0,0,0,0,0,0,0,0,0,0
0,0,0,0,0,0,0,0,0,0,0,0,0,0,0
0,0,0,0,0,0,0,0,0,0,0,0,0,0,0
0,0,0,0,0,0,0,0,0,0,0,0,0,0,0
0,0,0,0,0,0,0,20,0,0,0,0,0,0,0
0,0,0,0,0,0,0,8,0,0,0,0,0,0,0
0,0,0,0,0,0,0,0,0,0,0,0,0,0,0
50,0,0,0,0,0,1,1,1,0,0,0,0,0,50
1,50,50,50,50,50,1,1,1,50,50,50,50,50,1
1,1,1,1,1,1,1,1,1,1,1,1,1,1,1
1,1,1,1,1,1,1,1,1,1,1,1,1,1,1
1,1,1,1,1,1,1,1,1,1,1,1,1,1,1
1,1,1,1,1,1,1,1,1,1,1,1,1,1,1
1,1,1,1,1,1,1,1,1,1,1,1,1,1,1
1,1,1,1,1,1,1,1,1,1,1,1,1,1,1
1,1,1,1,1,1,1,1,1,1,1,1,1,1,1
1,1,1,1,1,1,1,1,1,1,1,1,1,1,1
1,1,1,1,1,1,1,1,50,1,1,1,1,1,1
1,1,1,1,1,1,1,50,1,1,1,1,1,1,1
1,1,1,1,1,1,1,50,1,1,1,1,1,1,1
endlayer

layer
0,0,0,0,0,0,0,0,0,0,0,0,0,0,0
0,0,0,0,0,0,0,0,0,0,0,0,0,0,0
0,0,0,0,0,0,0,0,0,0,0,0,0,0,0
0,0,0,0,0,0,0,0,0,0,0,0,0,0,0
0,0,0,0,0,0,0,0,0,0,0,0,0,0,0
0,0,0,0,0,0,0,0,0,0,0,0,0,0,0
0,0,0,0,0,0,0,0,0,0,0,0,0,0,0
0,0,0,0,0,0,0,20,0,0,0,0,0,0,0
37,0,0,0,0,0,0,8,0,0,0,0,0,0,37
0,0,0,0,0,0,0,0,0,0,0,0,0,0,0
50,50,0,0,0,50,0,0,0,50,0,0,0,50,50
0,0,50,50,50,0,0,0,0,0,50,50,50,0,0
0,0,0,0,0,0,0,0,0,0,0,0,0,0,0
0,0,0,0,0,0,0,0,0,0,0,0,0,0,0
0,0,0,0,0,0,0,0,0,0,0,0,0,0,0
0,0,0,0,0,0,0,0,0,0,0,0,0,0,0
0,0,0,0,0,0,0,20,0,0,0,0,0,0,0
0,0,0,0,0,0,0,8,0,0,0,0,0,0,0
0,0,0,0,0,0,0,0,0,0,0,0,0,0,0
50,0,0,0,0,0,1,1,1,0,0,0,0,0,50
1,50,50,50,50,50,1,1,1,50,50,50,50,50,1
1,1,1,1,1,1,1,1,1,1,1,1,1,1,1
1,1,1,1,1,1,1,1,1,1,1,1,1,1,1
1,1,1,1,1,1,1,1,1,1,1,1,1,1,1
1,1,1,1,1,1,1,1,1,1,1,1,1,1,1
1,1,1,1,1,1,1,1,1,1,1,1,1,1,1
1,1,1,1,1,1,1,1,1,1,1,1,1,1,1
1,1,1,1,1,1,1,1,1,50,1,1,1,1,1
1,1,1,1,1,1,1,1,50,1,1,1,1,1,1
1,1,1,1,1,1,1,0,50,1,1,1,1,1,1
1,1,1,1,1,1,1,50,1,1,1,1,1,1,1
1,1,1,1,1,1,1,1,1,1,1,1,1,1,1
endlayer

layer
0,0,0,0,0,0,0,0,0,0,0,0,0,0,0
0,0,0,0,0,0,0,0,0,0,0,0,0,0,0
0,0,0,0,0,0,0,0,0,0,0,0,0,0,0
0,0,0,0,0,0,0,0,0,0,0,0,0,0,0
0,0,0,0,0,0,0,0,0,0,0,0,0,0,0
0,0,0,0,0,0,0,0,0,0,0,0,0,0,0
0,0,0,0,0,0,0,0,0,0,0,0,0,0,0
0,0,0,0,0,0,0,20,0,0,0,0,0,0,0
0,0,0,0,0,0,0,8,0,0,0,0,0,0,0
0,0,0,0,0,0,0,0,0,0,0,0,0,0,0
50,0,0,0,0,0,0,0,0,0,0,0,0,0,50
0,50,50,50,50,50,0,0,0,50,50,50,50,50,0
0,0,0,0,0,0,0,0,0,0,0,0,0,0,0
0,0,0,0,0,0,0,0,0,0,0,0,0,0,0
0,0,0,0,0,0,0,0,0,0,0,0,0,0,0
0,0,0,0,0,0,0,0,0,0,0,0,0,0,0
0,0,0,0,0,0,0,20,0,0,0,0,0,0,0
0,0,0,0,0,0,0,8,0,0,0,0,0,0,0
0,0,0,0,0,0,0,0,0,0,0,0,0,0,0
50,0,0,0,0,0,1,1,1,0,0,0,0,0,50
1,50,50,50,50,50,1,1,1,50,50,50,50,50,1
1,1,1,1,1,1,1,1,1,1,1,1,1,1,1
1,1,1,1,1,1,1,1,1,1,1,1,1,1,1
1,1,1,1,1,1,1,1,1,1,1,1,1,1,1
1,1,1,1,1,1,1,1,1,1,1,1,1,1,1
1,1,1,1,1,1,1,1,1,1,1,1,1,1,1
1,1,1,1,1,1,1,1,1,1,1,1,1,1,1
1,1,1,1,1,1,1,1,1,50,1,1,1,1,1
1,1,1,1,1,1,1,1,50,1,1,1,1,1,1
1,1,1,1,1,1,1,0,50,1,1,1,1,1,1
1,1,1,1,1,1,1,50,1,1,1,1,1,1,1
1,1,1,1,1,1,1,1,1,1,1,1,1,1,1
endlayer

layer
0,0,0,0,0,0,0,0,0,0,0,0,0,0,0
0,0,0,0,0,0,0,0,0,0,0,0,0,0,0
0,0,0,0,0,0,0,0,0,0,0,0,0,0,0
0,0,0,0,0,0,0,0,0,0,0,0,0,0,0
0,0,0,0,0,0,0,0,0,0,0,0,0,0,0
0,0,0,0,0,0,0,0,0,0,0,0,0,0,0
0,0,0,0,0,0,0,0,0,0,0,0,0,0,0
0,0,0,0,0,0,0,20,0,0,0,0,0,0,0
0,0,0,0,0,0,0,8,0,0,0,0,0,0,0
0,0,0,0,0,0,0,0,0,0,0,0,0,0,0
50,0,0,0,0,0,0,0,0,0,0,0,0,0,50
0,50,50,50,50,50,0,0,0,50,50,50,50,50,0
0,0,0,0,0,0,0,0,0,0,0,0,0,0,0
0,0,0,0,0,0,0,0,0,0,0,0,0,0,0
0,0,0,0,0,0,0,0,0,0,0,0,0,0,0
0,0,0,0,0,0,0,0,0,0,0,0,0,0,0
0,0,0,0,0,0,0,20,0,0,0,0,0,0,0
0,0,0,0,0,0,0,8,0,0,0,0,0,0,0
50,0,0,0,0,0,0,0,0,0,0,0,0,0,50
0,50,50,0,50,50,1,1,1,50,50,0,50,50,0
1,0,0,50,1,1,1,1,1,0,0,50,0,0,1
1,1,1,1,1,1,1,1,1,1,1,1,1,1,1
1,1,1,1,1,1,1,1,1,1,1,1,1,1,1
1,1,1,1,1,1,1,1,1,1,1,1,1,1,1
1,1,1,1,1,1,1,1,1,1,1,1,1,1,1
1,1,1,1,1,1,1,1,1,1,1,1,1,1,1
1,1,1,1,1,1,1,1,1,50,1,1,1,1,1
1,1,1,1,1,1,1,1,1,50,1,1,1,1,1
1,1,1,1,1,1,1,0,1,50,1,1,1,1,1
1,1,1,1,1,1,1,0,50,1,1,1,1,1,1
1,1,1,1,1,1,1,1,50,1,1,1,1,1,1
1,1,1,1,1,1,1,1,1,1,1,1,1,1,1
endlayer

layer
0,0,0,0,0,0,0,0,0,0,0,0,0,0,0
0,0,0,0,0,0,0,0,0,0,0,0,0,0,0
0,0,0,0,0,0,0,0,0,0,0,0,0,0,0
0,0,0,0,0,0,0,0,0,0,0,0,0,0,0
0,0,0,0,0,0,0,0,0,0,0,0,0,0,0
0,0,0,0,0,0,0,0,0,0,0,0,0,0,0
0,0,0,0,0,0,0,0,0,0,0,0,0,0,0
0,0,0,0,0,0,0,20,0,0,0,0,0,0,0
0,0,0,0,0,0,0,8,0,0,0,0,0,0,0
0,0,0,0,0,0,0,0,0,0,0,0,0,0,0
50,0,0,0,0,0,0,0,0,0,0,0,0,0,50
0,50,50,50,50,50,0,0,0,50,50,50,50,50,0
0,0,0,0,0,0,0,0,0,0,0,0,0,0,0
0,0,0,0,0,0,0,0,0,0,0,0,0,0,0
0,0,0,0,0,0,0,0,0,0,0,0,0,0,0
0,0,0,0,0,0,0,0,0,0,0,0,0,0,0
0,0,0,0,0,0,0,20,0,0,0,0,0,0,0
23,49,49,49,49,49,49,8,49,49,49,49,49,49,22
50,50,0,0,0,50,50,0,50,50,0,0,0,50,50
0,0,1,1,1,1,1,1,1,0,0,0,0,0,0
1,0,1,1,1,1,1,1,1,0,0,0,0,0,1
1,1,1,1,1,1,1,1,1,1,1,1,1,1,1
1,1,1,1,1,1,1,1,1,1,1,1,1,1,1
1,1,1,1,1,1,1,1,1,1,1,1,1,1,1
1,1,1,1,1,1,1,1,1,1,1,1,1,1,1
1,1,1,1,1,1,1,1,1,1,1,1,1,1,1
1,1,1,1,1,1,1,0,0,50,1,1,1,1,1
1,1,1,1,1,1,0,0,1,50,1,1,1,1,1
1,1,1,1,1,1,1,0,0,50,1,1,1,1,1
1,1,1,1,1,1,1,1,50,1,1,1,1,1,1
1,1,1,1,1,1,1,1,1,1,1,1,1,1,1
1,1,1,1,1,1,1,1,1,1,1,1,1,1,1
endlayer

layer
0,0,0,0,0,0,0,0,0,0,0,0,0,0,0
0,0,0,0,0,0,0,0,0,0,0,0,0,0,0
0,0,0,0,0,0,0,0,0,0,0,0,0,0,0
0,0,0,0,0,0,0,0,0,0,0,0,0,0,0
0,0,0,0,0,0,0,0,0,0,0,0,0,0,0
0,0,0,0,0,0,0,0,0,0,0,0,0,0,0
0,0,0,0,0,0,0,0,0,0,0,0,0,0,0
0,0,0,0,0,0,0,20,0,0,0,0,0,0,0
0,0,0,0,0,0,0,8,0,0,0,0,0,0,0
50,0,0,0,0,0,0,0,0,0,0,0,0,0,50
0,50,50,0,50,50,0,0,0,50,50,0,50,50,0
0,0,0,50,0,0,0,0,0,0,0,50,0,0,0
0,0,0,0,0,0,0,0,0,0,0,0,0,0,0
0,0,0,0,0,0,0,0,0,0,0,0,0,0,0
0,0,0,0,0,0,0,0,0,0,0,0,0,0,0
0,0,0,0,0,0,0,0,0,0,0,0,0,0,0
0,0,0,0,0,0,0,20,0,0,0,0,0,0,0
37,0,0,0,0,0,0,8,0,0,0,0,0,0,37
0,0,0,0,0,0,0,0,0,0,0,0,0,0,0
50,50,0,0,0,50,1,1,1,50,0,0,0,50,50
1,0,50,50,50,1,1,1,1,0,50,50,50,0,1
1,1,1,1,1,1,1,1,1,1,1,1,1,1,1
1,1,1,1,1,1,1,1,1,1,1,1,1,1,1
1,1,1,1,1,1,1,1,1,1,1,1,1,1,1
1,1,1,1,1,1,1,1,1,1,1,1,1,1,1
1,1,1,1,1,1,1,1,1,50,1,1,1,1,1
1,1,1,1,1,1,0,0,1,50,1,1,1,1,1
1,1,1,1,1,1,0,0,1,50,1,1,1,1,1
1,1,1,1,1,1,0,0,50,1,1,1,1,1,1
1,1,1,1,1,1,1,1,50,1,1,1,1,1,1
1,1,1,1,1,1,1,1,1,1,1,1,1,1,1
1,1,1,1,1,1,1,1,1,1,1,1,1,1,1
endlayer

layer
0,0,0,0,0,0,0,0,0,0,0,0,0,0,0
0,0,0,0,0,0,0,0,0,0,0,0,0,0,0
0,0,0,0,0,0,0,0,0,0,0,0,0,0,0
0,0,0,0,0,0,0,0,0,0,0,0,0,0,0
0,0,0,0,0,0,0,0,0,0,0,0,0,0,0
0,0,0,0,0,0,0,0,0,0,0,0,0,0,0
0,0,0,0,0,0,0,0,0,0,0,0,0,0,0
0,0,0,0,0,0,0,20,0,0,0,0,0,0,0
23,49,49,49,49,49,49,8,49,49,49,49,49,49,22
50,50,0,0,0,50,50,0,50,50,0,0,0,50,50
0,0,0,0,0,0,0,0,0,0,0,0,0,0,0
0,0,0,0,0,0,0,0,0,0,0,0,0,0,0
0,0,0,0,0,0,0,0,0,0,0,0,0,0,0
0,0,0,0,0,0,0,0,0,0,0,0,0,0,0
0,0,0,0,0,0,0,0,0,0,0,0,0,0,0
0,0,0,0,0,0,0,0,0,0,0,0,0,0,0
0,0,0,0,0,0,0,20,0,0,0,0,0,0,0
0,0,0,0,0,0,0,8,0,0,0,0,0,0,0
0,0,0,0,0,0,0,0,0,0,0,0,0,0,0
50,0,0,0,0,0,1,1,1,0,0,0,0,0,50
1,50,50,50,50,50,1,1,1,50,50,50,50,50,1
1,1,1,1,1,1,1,1,1,1,1,1,1,1,1
1,1,1,1,1,1,1,1,1,1,1,1,1,1,1
1,1,1,1,1,1,1,1,1,1,1,1,1,1,1
1,1,1,1,1,1,1,1,50,1,1,1,1,1,1
1,1,1,1,1,1,0,0,1,50,1,1,1,1,1
1,1,1,1,1,1,0,0,1,50,1,1,1,1,1
1,1,1,1,1,1,0,0,1,50,1,1,1,1,1
1,1,1,1,1,1,1,1,50,1,1,1,1,1,1
1,1,1,1,1,1,1,1,1,1,1,1,1,1,1
1,1,1,1,1,1,1,1,1,1,1,1,1,1,1
1,1,1,1,1,1,1,1,1,1,1,1,1,1,1
endlayer

layer
0,0,0,0,0,0,0,0,0,0,0,0,0,0,0
0,0,0,0,0,0,0,0,0,0,0,0,0,0,0
0,0,0,0,0,0,0,0,0,0,0,0,0,0,0
0,0,0,0,0,0,0,0,0,0,0,0,0,0,0
0,0,0,0,0,0,0,0,0,0,0,0,0,0,0
0,0,0,0,0,0,0,0,0,0,0,0,0,0,0
0,0,0,0,0,0,0,0,0,0,0,0,0,0,0
0,0,0,0,0,0,34,20,34,0,0,0,0,0,0
37,0,0,0,0,0,34,8,34,0,0,0,0,0,37
0,0,0,0,0,0,34,34,34,0,0,0,0,0,0
0,0,0,0,0,0,0,0,0,0,0,0,0,0,0
0,0,0,0,0,0,0,0,0,0,0,0,0,0,0
0,0,0,0,0,0,0,0,0,0,0,0,0,0,0
0,0,0,0,0,0,0,0,0,0,0,0,0,0,0
0,0,0,0,0,0,0,0,0,0,0,0,0,0,0
0,0,0,0,0,0,0,0,0,0,0,0,0,0,0
0,0,0,0,0,0,0,20,0,0,0,0,0,0,0
0,0,0,0,0,0,0,8,0,0,0,0,0,0,0
0,0,0,0,0,0,0,0,0,0,0,0,0,0,0
50,0,0,0,0,0,1,1,1,0,0,0,0,0,50
1,50,50,50,50,50,1,1,1,50,50,50,50,50,1
1,1,1,1,1,1,1,1,1,1,1,1,1,1,1
1,1,1,1,1,1,1,1,1,1,1,1,1,1,1
1,1,1,1,1,1,1,1,1,1,1,1,1,1,1
1,1,1,1,1,1,0,1,50,1,1,1,1,1,1
1,1,1,1,1,1,0,0,50,1,1,1,1,1,1
1,1,1,1,1,1,0,0,1,50,1,1,1,1,1
1,1,1,1,1,1,1,1,50,1,1,1,1,1,1
1,1,1,1,1,1,1,1,50,1,1,1,1,1,1
1,1,1,1,1,1,1,1,1,1,1,1,1,1,1
1,1,1,1,1,1,1,1,1,1,1,1,1,1,1
1,1,1,1,1,1,1,1,1,1,1,1,1,1,1
endlayer

layer
0,0,0,0,0,0,0,0,0,0,0,0,0,0,0
0,0,0,0,0,0,0,0,0,0,0,0,0,0,0
0,0,0,0,0,0,0,0,0,0,0,0,0,0,0
0,0,0,0,0,0,0,0,0,0,0,0,0,0,0
0,0,0,0,0,0,0,0,0,0,0,0,0,0,0
0,0,0,0,0,0,0,0,0,0,0,0,0,0,0
0,0,0,0,0,32,29,29,29,30,0,0,0,0,0
0,0,0,0,0,32,0,20,0,30,0,0,0,0,0
0,0,0,0,0,32,0,8,0,30,0,0,0,0,0
0,0,0,0,0,32,0,0,0,30,0,0,0,0,0
0,0,0,0,0,46,46,46,46,30,0,0,0,0,0
0,0,0,0,0,0,0,0,0,0,0,0,0,0,0
0,0,0,0,0,0,0,0,0,0,0,0,0,0,0
0,0,0,0,0,0,0,0,0,0,0,0,0,0,0
0,0,0,0,0,0,0,0,0,0,0,0,0,0,0
0,0,0,0,0,0,0,0,0,0,0,0,0,0,0
0,0,0,0,0,0,0,20,0,0,0,0,0,0,0
0,0,0,0,0,0,0,8,0,0,0,0,0,0,0
0,0,0,0,0,0,0,0,0,0,0,0,0,0,0
50,0,0,0,0,0,1,0,1,0,0,0,0,0,50
1,50,50,50,50,50,1,0,1,50,50,50,50,50,1
1,1,1,1,1,1,1,0,1,1,1,1,1,1,1
1,1,1,1,1,1,1,0,1,1,1,1,1,1,1
1,1,1,1,1,1,1,50,1,1,1,1,1,1,1
1,1,1,1,1,1,0,50,0,1,1,1,1,1,1
1,1,1,1,1,1,0,0,50,1,1,1,1,1,1
1,1,1,1,1,1,0,1,50,1,1,1,1,1,1
1,1,1,1,1,1,1,1,50,1,1,1,1,1,1
1,1,1,1,1,1,1,1,1,1,1,1,1,1,1
1,1,1,1,1,1,1,1,1,1,1,1,1,1,1
1,1,1,1,1,1,1,1,1,1,1,1,1,1,1
1,1,1,1,1,1,1,1,1,1,1,1,1,1,1
endlayer

layer
0,0,0,0,0,0,0,0,0,0,0,0,0,0,0
0,0,0,0,0,0,0,0,0,0,0,0,0,0,0
0,0,0,0,0,0,0,0,0,0,0,0,0,0,0
0,0,0,0,0,0,0,0,0,0,0,0,0,0,0
0,0,0,0,0,0,0,0,0,0,0,0,0,0,0
0,0,0,0,0,0,0,0,0,0,0,0,0,0,0
0,0,0,0,0,37,37,37,37,37,0,0,0,0,0
0,0,0,0,0,37,0,20,0,37,0,0,0,0,0
0,0,0,0,0,37,0,8,0,37,0,0,0,0,0
0,0,0,0,0,37,0,0,0,37,0,0,0,0,0
0,0,0,0,0,37,37,37,37,37,0,0,0,0,0
0,0,0,0,0,0,0,0,0,0,0,0,0,0,0
0,0,0,0,0,0,0,0,0,0,0,0,0,0,0
0,0,0,0,0,0,0,0,0,0,0,0,0,0,0
0,0,0,0,0,0,0,0,0,0,0,0,0,0,0
0,0,0,0,0,0,0,0,0,0,0,0,0,0,0
0,0,0,0,0,0,0,20,0,0,0,0,0,0,0
0,0,0,0,0,0,0,8,0,0,0,0,0,0,0
50,0,0,0,0,0,0,0,0,0,0,0,0,0,50
0,50,50,0,50,50,1,0,1,50,50,0,50,50,0
1,0,0,50,1,1,1,0,1,1,1,50,0,0,1
1,1,1,1,1,1,1,0,1,1,1,1,1,1,1
1,1,1,1,1,1,1,50,1,1,1,1,1,1,1
1,1,1,1,1,1,1,50,1,1,1,1,1,1,1
1,1,1,1,1,1,0,50,0,1,1,1,1,1,1
1,1,1,1,1,1,1,50,1,1,1,1,1,1,1
1,1,1,1,1,1,1,1,50,1,1,1,1,1,1
1,1,1,1,1,1,1,1,1,1,1,1,1,1,1
1,1,1,1,1,1,1,1,1,1,1,1,1,1,1
1,1,1,1,1,1,1,1,1,1,1,1,1,1,1
1,1,1,1,1,1,1,1,1,1,1,1,1,1,1
1,1,1,1,1,1,1,1,1,1,1,1,1,1,1
endlayer

layer
0,0,0,0,0,0,0,0,0,0,0,0,0,0,0
0,0,0,0,0,0,0,0,0,0,0,0,0,0,0
0,0,0,0,0,0,0,0,0,0,0,0,0,0,0
0,0,0,0,0,0,0,0,0,0,0,0,0,0,0
0,0,0,0,0,0,0,0,0,0,0,0,0,0,0
0,0,0,0,0,0,0,0,0,0,0,0,0,0,0
0,0,0,0,0,0,0,0,0,0,0,0,0,0,0
0,0,0,0,0,0,0,0,0,0,0,0,0,0,0
0,0,0,0,0,0,0,37,0,0,0,0,0,0,0
0,0,0,0,0,0,0,0,0,0,0,0,0,0,0
0,0,0,0,0,0,0,0,0,0,0,0,0,0,0
0,0,0,0,0,0,0,0,0,0,0,0,0,0,0
0,0,0,0,0,0,0,0,0,0,0,0,0,0,0
0,0,0,0,0,0,0,0,0,0,0,0,0,0,0
0,0,0,0,0,0,0,0,0,0,0,0,0,0,0
0,0,0,0,0,0,0,0,0,0,0,0,0,0,0
0,0,0,0,0,0,0,20,0,0,0,0,0,0,0
23,49,49,49,49,49,49,8,49,49,49,49,49,49,22
50,50,1,1,1,50,50,2,50,50,1,1,1,50,50
1,1,1,1,1,1,1,2,1,1,1,1,1,1,1
1,1,1,1,1,1,1,2,1,1,1,1,1,1,1
1,1,1,1,1,1,1,2,1,1,1,1,1,1,1
1,1,1,1,1,1,1,50,1,1,1,1,1,1,1
1,1,1,1,1,1,1,50,1,1,1,1,1,1,1
1,1,1,1,1,1,0,0,0,1,1,1,1,1,1
1,1,1,1,1,1,1,1,1,1,1,1,1,1,1
1,1,1,1,1,1,1,1,1,1,1,1,1,1,1
1,1,1,1,1,1,1,1,1,1,1,1,1,1,1
1,1,1,1,1,1,1,1,1,1,1,1,1,1,1
1,1,1,1,1,1,1,1,1,1,1,1,1,1,1
1,1,1,1,1,1,1,1,1,1,1,1,1,1,1
1,1,1,1,1,1,1,1,1,1,1,1,1,1,1
endlayer

layer
0,0,0,0,0,0,0,0,0,0,0,0,0,0,0
0,0,0,0,0,0,0,0,0,0,0,0,0,0,0
0,0,0,0,0,0,0,0,0,0,0,0,0,0,0
0,0,0,0,0,0,0,0,0,0,0,0,0,0,0
0,0,0,0,0,0,0,0,0,0,0,0,0,0,0
0,0,0,0,0,0,0,0,0,0,0,0,0,0,0
0,0,0,0,0,0,0,0,0,0,0,0,0,0,0
0,0,0,0,0,0,0,0,0,0,0,0,0,0,0
0,0,0,0,0,0,0,51,0,0,0,0,0,0,0
0,0,0,0,0,0,0,0,51,0,0,0,0,0,0
0,0,0,0,0,0,0,0,51,0,0,0,0,0,0
0,0,0,0,0,0,0,0,0,51,0,0,0,0,0
0,0,0,0,0,0,0,0,0,0,0,0,0,0,0
0,0,0,0,0,0,0,0,0,0,0,0,0,0,0
0,0,0,0,0,0,0,0,0,0,0,0,0,0,0
0,0,0,0,0,0,0,0,0,1,1,1,1,1,0
1,1,1,1,1,1,34,20,34,1,1,1,1,1,0
37,1,1,1,1,1,34,8,34,1,1,1,1,1,37
1,1,1,1,1,1,34,34,34,1,1,1,1,1,1
1,1,1,1,1,1,1,1,1,1,1,1,1,1,1
1,1,1,1,1,1,1,1,1,1,1,1,1,1,1
1,1,1,1,1,1,1,1,1,1,1,1,1,1,1
1,1,1,1,1,1,1,1,1,1,1,1,1,1,1
1,1,1,1,1,1,1,1,1,1,1,1,1,1,1
1,1,1,1,1,1,0,0,0,1,1,1,1,1,1
1,1,1,1,1,1,1,1,1,1,1,1,1,1,1
1,1,1,1,1,1,1,1,1,1,1,1,1,1,1
1,1,1,1,1,1,1,1,1,1,1,1,1,1,1
1,1,1,1,1,1,1,1,1,1,1,1,1,1,1
1,1,1,1,1,1,1,1,1,1,1,1,1,1,1
1,1,1,1,1,1,1,1,1,1,1,1,1,1,1
1,1,1,1,1,1,1,1,1,1,1,1,1,1,1
endlayer

layer
0,0,0,0,0,0,0,0,0,0,0,0,0,0,0
0,0,0,0,0,0,0,0,0,0,0,0,0,0,0
0,0,0,0,0,0,0,0,0,0,0,0,0,0,0
0,0,0,0,0,0,0,0,0,0,0,0,0,0,0
0,0,0,0,0,0,0,0,0,0,0,0,0,0,0
0,0,0,0,0,0,0,0,0,0,0,0,0,0,0
0,0,0,0,0,0,0,0,0,0,0,0,0,0,0
0,0,0,0,0,0,0,0,0,0,0,0,0,0,0
0,0,0,0,0,0,0,0,0,0,0,0,0,0,0
0,0,0,0,0,0,0,0,0,0,0,0,0,0,0
0,0,0,0,0,0,0,0,0,0,0,0,0,0,0
0,0,0,0,0,0,0,0,0,0,0,0,0,0,0
0,0,0,0,0,0,0,0,0,0,0,0,0,0,0
0,0,0,0,0,0,0,0,0,0,0,0,0,0,0
0,0,0,0,0,0,0,0,0,0,0,0,0,0,0
0,0,0,0,0,29,29,29,29,29,1,1,1,1,1
1,1,1,1,1,32,0,20,0,30,1,1,1,1,1
1,1,1,1,1,32,0,8,0,30,1,1,1,1,1
1,1,1,1,1,32,0,0,0,30,1,1,1,1,1
1,1,1,1,1,46,46,46,46,46,1,1,1,1,1
1,1,1,1,1,1,1,1,1,1,1,1,1,1,1
1,1,1,1,1,1,1,1,1,1,1,1,1,1,1
1,1,1,1,1,1,1,1,1,1,1,1,1,1,1
1,1,1,1,1,1,1,1,1,1,1,1,1,1,1
1,1,1,1,1,1,0,0,0,1,1,1,1,1,1
1,1,1,1,1,1,1,1,1,1,1,1,1,1,1
1,1,1,1,1,1,1,1,1,1,1,1,1,1,1
1,1,1,1,1,1,1,1,1,1,1,1,1,1,1
1,1,1,1,1,1,1,1,1,1,1,1,1,1,1
1,1,1,1,1,1,1,1,1,1,1,1,1,1,1
1,1,1,1,1,1,1,1,1,1,1,1,1,1,1
1,1,1,1,1,1,1,1,1,1,1,1,1,1,1
endlayer

layer
0,0,0,0,0,0,0,0,0,0,0,0,0,0,0
0,0,0,0,0,0,0,0,0,0,0,0,0,0,0
0,0,0,0,0,0,0,0,0,0,0,0,0,0,0
0,0,0,0,0,0,0,0,0,0,0,0,0,0,0
0,0,0,0,0,0,0,0,0,0,0,0,0,0,0
0,0,0,0,0,0,0,0,0,0,0,0,0,0,0
0,0,0,0,0,0,0,0,0,0,0,0,0,0,0
0,0,0,0,0,0,0,0,0,0,0,0,0,0,0
0,0,0,0,0,0,0,0,0,0,0,0,0,0,0
0,0,0,0,0,0,0,0,0,0,0,0,0,0,0
0,0,0,0,0,0,0,0,0,0,0,0,0,0,0
0,0,0,0,0,0,0,0,0,0,0,0,0,0,0
0,0,0,0,0,0,0,0,0,0,0,0,0,0,0
0,0,0,0,0,0,0,0,0,0,0,0,0,0,0
0,0,0,0,0,0,0,0,0,0,0,0,0,0,0
0,0,0,0,0,37,37,37,37,37,1,1,1,1,1
1,1,1,1,1,37,0,0,0,37,1,1,1,1,1
1,1,1,1,1,37,0,8,0,37,1,1,1,1,1
1,1,1,1,1,37,0,0,0,37,1,1,1,1,1
1,1,1,1,1,37,37,37,37,37,1,1,1,1,1
1,1,1,1,1,1,1,1,1,1,1,1,1,1,1
1,1,1,1,1,1,1,1,1,1,1,1,1,1,1
1,1,1,1,1,1,1,1,1,1,1,1,1,1,1
1,1,1,1,1,1,1,1,1,1,1,1,1,1,1
1,1,1,1,1,1,0,1,0,1,1,1,1,1,1
1,1,1,1,1,1,1,1,1,1,1,1,1,1,1
1,1,1,1,1,1,1,1,1,1,1,1,1,1,1
1,1,1,1,1,1,1,1,1,1,1,1,1,1,1
1,1,1,1,1,1,1,1,1,1,1,1,1,1,1
1,1,1,1,1,1,1,1,1,1,1,1,1,1,1
1,1,1,1,1,1,1,1,1,1,1,1,1,1,1
1,1,1,1,1,1,1,1,1,1,1,1,1,1,1
endlayer

layer
0,0,0,0,0,0,0,0,0,0,0,0,0,0,0
0,0,0,0,0,0,0,0,0,0,0,0,0,0,0
0,0,0,0,0,0,0,0,0,0,0,0,0,0,0
0,0,0,0,0,0,0,0,0,0,0,0,0,0,0
0,0,0,0,0,0,0,0,0,0,0,0,0,0,0
0,0,0,0,0,0,0,0,0,0,0,0,0,0,0
0,0,0,0,0,0,0,0,0,0,0,0,0,0,0
0,0,0,0,0,0,0,0,0,0,0,0,0,0,0
0,0,0,0,0,0,0,0,0,0,0,0,0,0,0
0,0,0,0,0,0,0,0,0,0,0,0,0,0,0
0,0,0,0,0,0,0,0,0,0,0,0,0,0,0
0,0,0,0,0,0,0,0,0,0,0,0,0,0,0
0,0,0,0,0,0,0,0,0,0,0,0,0,0,0
0,0,0,0,0,0,0,0,0,0,0,0,0,0,0
0,0,0,0,0,0,0,0,0,0,0,0,0,0,0
0,0,0,0,0,0,0,0,1,1,1,1,1,1,1
1,1,1,1,1,1,1,0,1,1,1,1,1,1,1
1,1,1,1,1,1,1,37,1,1,1,1,1,1,1
1,1,1,1,1,1,1,1,1,1,1,1,1,1,1
1,1,1,1,1,1,1,1,1,1,1,1,1,1,1
1,1,1,1,1,1,1,1,1,1,1,1,1,1,1
1,1,1,1,1,1,1,1,1,1,1,1,1,1,1
1,1,1,1,1,1,1,1,1,1,1,1,1,1,1
1,1,1,1,1,1,1,1,1,1,1,1,1,1,1
1,1,1,1,1,1,0,1,0,1,1,1,1,1,1
1,1,1,1,1,1,1,1,1,1,1,1,1,1,1
1,1,1,1,1,1,1,1,1,1,1,1,1,1,1
1,1,1,1,1,1,1,1,1,1,1,1,1,1,1
1,1,1,1,1,1,1,1,1,1,1,1,1,1,1
1,1,1,1,1,1,1,1,1,1,1,1,1,1,1
1,1,1,1,1,1,1,1,1,1,1,1,1,1,1
1,1,1,1,1,1,1,1,1,1,1,1,1,1,1
endlayer

layer
0,0,0,0,0,0,0,0,0,0,0,0,0,0,0
0,0,0,0,0,0,0,0,0,0,0,0,0,0,0
0,0,0,0,0,0,0,0,0,0,0,0,0,0,0
0,0,0,0,0,0,0,0,0,0,0,0,0,0,0
0,0,0,0,0,0,0,0,0,0,0,0,0,0,0
0,0,0,0,0,0,0,0,0,0,0,0,0,0,0
0,0,0,0,0,0,0,0,0,0,0,0,0,0,0
0,0,0,0,0,0,0,0,0,0,0,0,0,0,0
0,0,0,0,0,0,0,0,0,0,0,0,0,0,0
0,0,0,0,0,0,0,0,0,0,0,0,0,0,0
0,0,0,0,0,0,0,0,0,0,0,0,0,0,0
0,0,0,0,0,0,0,0,0,0,0,0,0,0,0
0,0,0,0,0,0,0,0,0,0,0,0,0,0,0
0,0,0,0,0,0,0,0,0,0,0,0,0,0,0
0,0,0,0,0,0,0,0,0,0,0,0,0,0,0
0,0,0,0,0,0,0,0,0,0,1,1,1,1,1
1,1,1,1,1,1,1,0,0,0,1,1,1,1,1
1,1,1,1,1,1,1,51,0,0,1,1,1,1,1
1,1,1,1,1,1,1,1,51,0,1,1,1,1,1
1,1,1,1,1,1,1,1,51,0,1,1,1,1,1
1,1,1,1,1,1,1,1,1,51,1,1,1,1,1
1,1,1,1,1,1,1,1,1,1,1,1,1,1,1
1,1,1,1,1,1,1,1,1,1,1,1,1,1,1
1,1,1,1,1,1,1,1,1,1,1,1,1,1,1
1,1,1,1,1,1,0,1,0,1,1,1,1,1,1
1,1,1,1,1,1,1,1,1,1,1,1,1,1,1
1,1,1,1,1,1,1,1,1,1,1,1,1,1,1
1,1,1,1,1,1,1,1,1,1,1,1,1,1,1
1,1,1,1,1,1,1,1,1,1,1,1,1,1,1
1,1,1,1,1,1,1,1,1,1,1,1,1,1,1
1,1,1,1,1,1,1,1,1,1,1,1,1,1,1
1,1,1,1,1,1,1,1,1,1,1,1,1,1,1
endlayer

