
# Created by Ruins mod version 16.5 Ingame Parser
# authoring Player: ST753M

weight=1
uniqueMinDistance=1500
spawnMinDistance=1000
embed_into_distance=0
acceptable_target_blocks=
unacceptable_target_blocks=flowing_water,water,flowing_lava,lava,ice,bedrock,netherrack,nether_brick,nether_brick_fence,soul_sand,quartz_ore,end_stone,obsidian,iron_bars,Natura:Cloud,slime_grass,slime_congealed,slime_dirt,clouds,natura:clouds
dimensions=8,8,8
allowable_overhang=5
max_leveling=2
leveling_buffer=-1
preserve_water=1
preserve_lava=1

biomesToSpawnIn=jungle,jungle_hills,tropical_rainforest,rainforest,mutated_jungle,mini_jungle,thicket,lush_hills

=0,100,air

rule1=0,100,minecraft:wool-13,minecraft:stained_hardened_clay-13,minecraft:concrete-13,minecraft:wool-5,minecraft:concrete-5,minecraft:stained_hardened_clay-5
rule2=0,100,minecraft:concrete-15
rule3=0,50,ChestGenHook:chests/simple_dungeon:5-2
rule4=0,40,IInventory;minecraft:chest;minecraft:gunpowder#3#0#1+minecraft:tnt#4#0#3+minecraft:spawn_egg#{EntityTag:{id:"minecraft:creeper"}}#0#8+minecraft:tnt#3#0#9+minecraft:gunpowder#2#0#13+minecraft:gunpowder#6#0#20+minecraft:tnt#2#0#23+minecraft:gunpowder#4#0#25-2
rule5=0,100,MobSpawner:Creeper
rule6=0,100,air

layer
1,1,1,1,1,1,1,1
1,2,2,2,2,2,2,1
2,2,2,2,2,2,2,1
1,2,2,1,1,2,2,1
1,2,2,1,1,2,2,1
2,2,2,2,2,2,2,1
1,2,2,2,2,2,2,1
1,1,1,1,1,1,1,1
endlayer

layer
1,1,1,1,1,1,1,1
1,0,0,0,0,0,0,1
0,0,0,0,0,0,0,1
0,0,0,2,2,0,0,1
0,0,0,2,2,0,0,1
0,0,0,0,0,0,0,1
1,0,0,0,0,0,0,1
1,1,1,1,1,1,1,1
endlayer

layer
1,1,1,1,1,1,1,1
1,0,0,0,0,0,0,1
2,0,0,0,0,0,0,1
0,0,0,2,2,0,0,1
0,0,0,2,2,0,0,1
2,0,0,0,0,0,0,1
1,0,0,0,0,0,0,1
1,1,1,1,1,1,1,1
endlayer

layer
1,1,1,1,1,1,1,1
1,0,0,0,0,0,0,1
1,0,0,0,0,0,0,1
2,0,0,2,3,0,0,1
2,0,0,2,4,0,0,1
1,0,0,0,0,0,0,1
1,0,0,0,0,0,0,1
1,1,1,1,1,1,1,1
endlayer

layer
1,1,1,1,1,1,1,1
2,0,0,0,0,0,0,1
0,0,0,0,0,0,0,1
1,0,0,2,5,0,0,1
1,0,0,2,5,0,0,1
0,0,0,0,0,0,0,1
2,0,0,0,0,0,0,1
1,1,1,1,1,1,1,1
endlayer

layer
1,1,1,1,1,1,1,1
2,0,6,6,6,6,6,1
2,0,0,0,0,0,6,1
1,0,0,2,2,0,6,1
1,0,0,2,2,0,6,1
2,6,0,0,0,0,6,1
2,6,6,6,6,6,6,1
1,1,1,1,1,1,1,1
endlayer

layer
1,1,1,1,1,1,1,1
1,6,6,6,6,6,6,1
1,6,6,6,6,6,6,1
1,6,6,2,2,6,6,1
1,6,6,2,2,6,6,1
1,6,6,6,6,6,6,1
1,6,6,6,6,6,6,1
1,1,1,1,1,1,1,1
endlayer

layer
1,1,1,1,1,1,1,1
1,1,1,1,1,1,1,1
1,1,1,1,1,1,1,1
1,1,1,1,1,1,1,1
1,1,1,1,1,1,1,1
1,1,1,1,1,1,1,1
1,1,1,1,1,1,1,1
1,1,1,1,1,1,1,1
endlayer

