
# Created by Ruins mod version 17.1 Ingame Parser
# authoring Player: ST753M

weight=3
uniqueMinDistance=1000
spawnMinDistance=500
embed_into_distance=6
acceptable_target_blocks=grass,dirt,mycelium,podzol,stone
unacceptable_target_blocks=flowing_water,water,flowing_lava,lava
dimensions=16,24,24
allowable_overhang=19
max_leveling=0
leveling_buffer=0
preserve_water=0
preserve_lava=0

biomesToSpawnIn=jungle,jungle_edge,tropical_island,tropical_rainforest,rainforest,mutated_jungle_edge,mini_jungle

=0,100,air
rule1=0,100,preserveBlock
rule2=0,100,minecraft:log-15
rule3=0,100,minecraft:grass-0
rule4=0,100,minecraft:mycelium-0
rule5=0,100,teBlock;iceandfire:pixie_house;{HouseType:5,HasPixie:1b,TamedPixie:0b,x:-8178,y:135,z:-11552,Items:[],id:"minecraft:pixie_house",PixieType:0}-3
rule6=0,100,teBlock;iceandfire:pixie_house;{HouseType:3,HasPixie:1b,TamedPixie:0b,x:-8176,y:135,z:-11550,Items:[],id:"minecraft:pixie_house",PixieType:1}-2
rule7=0,100,minecraft:water-0
rule8=0,100,minecraft:waterlily-0
rule9=0,100,teBlock;iceandfire:pixie_house;{HouseType:1,HasPixie:1b,TamedPixie:0b,x:-8173,y:136,z:-11552,Items:[],id:"minecraft:pixie_house",PixieType:2}-1
rule10=0,100,minecraft:vine-4
rule11=0,100,minecraft:vine-2
rule12=0,100,teBlock;iceandfire:pixie_house;{HouseType:0,HasPixie:1b,TamedPixie:0b,x:-8172,y:137,z:-11550,Items:[],id:"minecraft:pixie_house",PixieType:3}-0
rule13=0,100,minecraft:leaves-7
rule14=0,100,teBlock;iceandfire:pixie_house;{HouseType:1,HasPixie:1b,TamedPixie:0b,x:-8171,y:137,z:-11544,Items:[],id:"minecraft:pixie_house",PixieType:4}-1
rule15=0,100,minecraft:leaves-15
rule16=0,100,teBlock;iceandfire:pixie_house;{HouseType:3,HasPixie:1b,TamedPixie:0b,x:-8187,y:138,z:-11543,Items:[],id:"minecraft:pixie_house",PixieType:0}-2
rule17=0,100,teBlock;iceandfire:pixie_house;{HouseType:0,HasPixie:1b,TamedPixie:0b,x:-8180,y:138,z:-11541,Items:[],id:"minecraft:pixie_house",PixieType:1}-3
rule18=0,100,teBlock;iceandfire:pixie_house;{HouseType:1,HasPixie:1b,TamedPixie:0b,x:-8178,y:138,z:-11540,Items:[],id:"minecraft:pixie_house",PixieType:2}-2
rule19=0,100,teBlock;iceandfire:pixie_house;{HouseType:1,HasPixie:1b,TamedPixie:0b,x:-8173,y:138,z:-11540,Items:[],id:"minecraft:pixie_house",PixieType:3}-2
rule20=0,100,teBlock;iceandfire:pixie_house;{HouseType:0,HasPixie:1b,TamedPixie:0b,x:-8171,y:138,z:-11542,Items:[],id:"minecraft:pixie_house",PixieType:4}-1
rule21=0,100,minecraft:vine-8
rule22=0,100,teBlock;iceandfire:pixie_house;{HouseType:1,HasPixie:1b,TamedPixie:0b,x:-8181,y:139,z:-11550,Items:[],id:"minecraft:pixie_house",PixieType:0}-3

rule23=0,100,air

rule24=0,100,teBlock;iceandfire:pixie_house;{HouseType:1,HasPixie:1b,TamedPixie:0b,x:-8178,y:139,z:-11552,Items:[],id:"minecraft:pixie_house",PixieType:0}-0
rule25=0,100,minecraft:vine-9
rule26=0,100,teBlock;iceandfire:pixie_house;{HouseType:0,HasPixie:1b,TamedPixie:0b,x:-8180,y:140,z:-11551,Items:[],id:"minecraft:pixie_house",PixieType:0}-0
rule27=0,100,minecraft:vine-1
rule28=0,100,teBlock;iceandfire:pixie_house;{HouseType:4,HasPixie:1b,TamedPixie:0b,x:-8174,y:140,z:-11552,Items:[],id:"minecraft:pixie_house",PixieType:1}-1
rule29=0,100,teBlock;iceandfire:pixie_house;{HouseType:0,HasPixie:1b,TamedPixie:0b,x:-8172,y:141,z:-11551,Items:[],id:"minecraft:pixie_house",PixieType:2}-0
rule30=0,100,teBlock;iceandfire:pixie_house;{HouseType:3,HasPixie:1b,TamedPixie:0b,x:-8171,y:141,z:-11550,Items:[],id:"minecraft:pixie_house",PixieType:3}-1
rule31=0,100,teBlock;iceandfire:pixie_house;{HouseType:4,HasPixie:1b,TamedPixie:0b,x:-8170,y:142,z:-11545,Items:[],id:"minecraft:pixie_house",PixieType:4}-1
rule32=0,100,teBlock;iceandfire:pixie_house;{HouseType:5,HasPixie:0b,TamedPixie:0b,x:-8171,y:144,z:-11542,Items:[],id:"minecraft:pixie_house",PixieType:0}-1
rule33=0,100,teBlock;iceandfire:pixie_house;{HouseType:3,HasPixie:0b,TamedPixie:0b,x:-8177,y:145,z:-11540,Items:[],id:"minecraft:pixie_house",PixieType:0}-2
rule34=0,100,teBlock;iceandfire:pixie_house;{HouseType:4,HasPixie:0b,TamedPixie:0b,x:-8183,y:146,z:-11554,Items:[],id:"minecraft:pixie_house",PixieType:1}-0
rule35=0,100,teBlock;iceandfire:pixie_house;{HouseType:3,HasPixie:0b,TamedPixie:0b,x:-8182,y:146,z:-11551,Items:[],id:"minecraft:pixie_house",PixieType:2}-3
rule36=0,100,teBlock;iceandfire:pixie_house;{HouseType:5,HasPixie:0b,TamedPixie:0b,x:-8182,y:146,z:-11544,Items:[],id:"minecraft:pixie_house",PixieType:3}-3
rule37=0,100,minecraft:vine-12
rule38=0,100,teBlock;iceandfire:pixie_house;{HouseType:3,HasPixie:0b,TamedPixie:0b,x:-8177,y:146,z:-11547,Items:[],id:"minecraft:pixie_house",PixieType:4}-2
rule39=0,100,teBlock;iceandfire:pixie_house;{HouseType:5,HasPixie:0b,TamedPixie:0b,x:-8176,y:146,z:-11549,Items:[],id:"minecraft:pixie_house",PixieType:0}-1
rule40=0,100,teBlock;iceandfire:pixie_house;{HouseType:3,HasPixie:0b,TamedPixie:0b,x:-8185,y:147,z:-11556,Items:[],id:"minecraft:pixie_house",PixieType:1}-0
rule41=0,100,minecraft:vine-6
rule42=0,100,minecraft:sapling-3

layer
1,1,1,2,1,1,1,1,2,1,1,1,1,1,1,2,1,1,1,1,1,1,1,1
1,1,1,2,1,1,1,1,2,1,1,1,1,1,2,1,1,1,1,1,1,1,1,1
1,1,1,1,1,1,1,1,2,2,1,1,1,1,1,1,1,1,1,1,1,1,1,1
1,1,1,1,1,1,1,1,1,2,2,1,1,1,1,1,1,1,1,1,1,1,1,1
1,1,1,1,1,1,1,1,1,1,1,1,1,1,1,1,1,1,1,1,1,2,1,1
1,1,1,1,1,1,1,1,1,1,1,1,1,1,1,1,1,1,1,1,1,2,1,1
1,1,1,1,1,1,1,1,1,1,1,1,2,1,1,1,1,1,1,1,1,1,1,1
1,1,1,1,1,1,1,1,1,1,1,1,1,1,1,2,1,1,1,1,1,1,1,1
1,1,1,1,1,1,1,1,1,1,1,1,1,1,1,1,1,1,1,1,1,1,1,1
1,1,1,1,1,1,1,1,2,1,1,1,1,1,1,1,1,1,1,1,1,1,1,1
1,1,1,1,1,1,1,1,1,1,1,1,1,1,1,1,1,1,1,1,1,1,1,1
1,1,1,1,2,2,2,1,1,1,1,1,1,1,1,1,2,2,1,1,1,1,1,1
1,1,1,1,1,1,1,1,1,1,1,1,1,1,1,1,1,2,1,1,1,2,2,2
1,1,1,1,1,1,1,1,2,1,1,1,1,1,1,1,1,1,1,1,1,1,1,1
1,1,1,1,1,1,1,1,1,1,1,1,1,1,1,1,1,1,1,1,1,1,1,1
1,1,1,1,1,1,1,1,1,1,1,1,1,1,1,1,1,1,1,1,1,1,1,1
1,1,1,1,1,1,1,1,1,1,1,1,1,1,1,1,1,1,1,1,1,1,1,1
1,1,1,1,1,1,1,1,1,2,1,1,1,1,1,1,1,1,1,1,1,1,1,1
1,1,1,1,1,1,1,1,1,1,1,1,1,1,1,1,1,1,1,1,1,1,1,1
1,1,1,1,1,1,1,1,1,1,1,1,1,1,1,1,1,1,1,1,1,1,1,1
1,1,1,1,1,1,1,1,1,1,1,1,1,1,1,1,1,1,1,1,1,1,1,1
1,1,1,1,1,1,1,1,1,1,1,1,1,1,1,1,1,1,1,1,1,2,2,1
2,1,1,1,1,1,1,1,1,1,1,1,1,1,1,1,1,1,1,1,1,1,1,1
2,1,1,1,1,1,1,1,1,1,1,1,1,1,1,1,1,1,1,1,1,1,1,1
endlayer

layer
1,1,1,1,1,1,1,1,1,1,1,1,1,1,2,2,1,1,1,1,1,1,1,1
1,1,2,2,2,2,1,1,1,1,1,1,1,2,2,2,1,1,1,1,1,1,1,1
1,1,1,1,1,2,1,1,1,1,1,1,1,1,2,1,1,1,1,1,1,1,1,1
1,1,1,1,1,1,1,1,1,1,2,1,1,1,1,1,1,1,1,1,1,1,1,1
1,1,1,1,1,1,1,1,1,1,1,1,1,1,1,1,1,1,1,1,1,1,1,1
1,1,1,1,1,1,1,1,1,1,1,1,1,1,1,1,1,1,1,1,1,2,1,1
1,1,1,1,1,1,1,1,1,1,1,2,2,2,1,1,1,1,1,1,1,2,1,1
1,1,1,1,1,1,1,1,1,2,2,3,3,3,2,2,1,1,1,1,1,1,2,2
1,1,1,1,1,1,1,1,1,3,3,3,3,3,3,3,2,1,1,1,1,1,1,1
2,1,1,1,1,1,1,1,2,3,3,3,3,3,3,3,2,1,1,1,1,1,1,1
1,1,1,1,1,1,1,1,3,3,3,3,3,3,3,2,2,2,1,1,1,1,1,1
1,1,1,1,1,2,2,2,3,3,3,3,3,3,3,3,2,2,1,1,1,2,1,1
1,1,1,1,1,1,1,2,3,3,3,3,3,3,3,3,2,2,1,1,1,2,2,1
2,2,1,1,1,1,1,1,2,3,3,3,3,3,3,1,2,2,1,1,1,1,1,1
1,1,1,1,1,1,1,1,1,2,1,3,3,3,3,1,1,1,1,1,1,1,1,1
1,1,1,1,1,1,1,1,1,1,1,1,3,3,2,1,1,1,1,1,1,1,1,1
1,1,1,1,1,1,1,1,1,2,1,1,2,2,1,1,1,1,1,1,1,1,1,1
1,1,1,1,1,1,1,1,1,2,1,1,1,1,1,1,1,1,1,1,1,1,1,1
1,1,1,1,1,1,1,1,1,1,1,1,1,1,1,1,1,1,1,1,1,1,1,1
1,1,1,1,1,1,1,1,1,1,1,1,1,1,1,1,1,1,1,1,1,1,1,1
1,1,1,1,1,1,1,1,1,1,1,1,1,1,1,1,1,1,1,1,1,2,1,1
2,1,1,1,1,1,1,1,1,1,1,1,1,1,1,1,1,1,1,1,1,2,1,1
2,1,1,1,1,1,1,1,1,1,1,1,1,1,1,1,1,1,1,1,1,1,1,1
1,1,1,1,1,1,1,1,1,1,1,1,1,1,1,1,1,1,1,1,1,1,1,1
endlayer

layer
1,1,1,1,1,1,1,1,1,1,1,1,1,2,2,4,1,1,1,1,1,1,1,1
1,1,1,1,2,2,1,1,1,1,1,1,2,2,2,2,1,1,1,1,1,1,1,1
1,1,1,1,1,2,2,1,1,1,1,1,1,2,2,2,1,1,1,1,1,1,1,1
1,1,1,1,1,1,2,2,1,1,2,2,1,1,2,2,1,1,1,1,1,1,1,1
1,1,1,1,1,1,1,1,1,1,1,1,1,1,1,2,1,1,1,1,1,1,1,1
1,1,1,1,1,1,1,1,1,1,1,1,1,2,1,1,1,1,1,1,1,1,1,1
1,1,1,1,1,1,1,1,1,1,2,2,2,2,2,1,1,1,1,1,1,2,1,1
1,1,2,1,1,1,1,1,1,2,2,3,3,3,2,2,1,1,1,1,1,2,2,1
1,2,2,2,1,1,1,1,2,3,3,3,3,3,3,3,2,1,1,1,1,1,1,1
2,2,1,1,1,1,1,1,2,3,3,3,3,3,3,3,2,2,2,2,1,1,1,1
1,1,1,1,1,1,1,2,3,3,3,3,3,3,3,2,2,2,2,2,1,1,1,1
1,1,1,1,1,0,2,2,3,3,3,3,3,3,3,3,2,2,2,1,1,2,1,1
1,1,1,1,1,1,1,2,3,3,4,4,3,3,3,3,2,2,2,1,2,2,1,1
1,2,1,1,1,1,1,2,2,3,4,4,4,3,3,3,2,2,1,1,1,1,1,1
1,2,1,1,1,1,1,1,2,3,3,4,4,3,3,3,2,1,1,1,1,1,1,1
1,1,1,1,1,1,1,1,1,2,1,3,3,3,2,2,1,1,1,1,1,1,1,1
1,1,1,1,1,1,1,1,1,2,1,2,2,2,1,1,1,1,1,1,1,1,1,1
1,1,1,1,1,1,1,1,1,1,1,1,2,1,1,1,1,1,1,1,1,1,1,1
1,1,1,1,1,1,1,1,1,1,1,1,1,1,1,1,1,1,1,2,1,1,2,1
1,2,2,1,1,1,1,1,1,1,1,1,1,1,1,1,1,1,1,2,2,1,1,1
2,2,1,1,1,1,1,2,1,1,1,1,1,1,1,1,1,1,1,1,2,2,1,1
2,1,1,1,1,1,1,1,1,1,1,1,1,1,1,1,2,1,1,1,1,1,1,1
1,1,1,1,1,1,1,1,1,1,1,1,1,1,1,1,2,2,1,1,1,1,1,1
1,1,1,1,1,1,1,1,1,1,1,1,1,1,1,1,1,2,1,1,1,1,1,1
endlayer

layer
1,1,1,1,1,1,1,1,1,1,1,1,1,2,4,1,1,1,1,1,1,1,1,1
1,1,1,1,1,1,1,1,1,1,1,1,2,2,2,4,1,1,1,1,1,1,1,1
1,1,1,1,1,2,2,1,1,1,1,1,2,2,2,2,2,1,1,1,1,1,1,1
1,1,1,1,1,1,2,2,2,1,0,2,2,2,2,2,2,1,1,1,1,1,1,1
1,1,1,1,1,1,1,1,2,1,1,2,2,2,2,2,1,1,1,1,1,1,1,1
1,1,1,1,1,1,1,1,1,1,1,1,2,2,2,2,1,1,1,1,1,1,1,1
1,1,1,1,1,1,1,1,1,2,2,2,2,2,2,1,1,1,1,1,2,2,1,1
1,1,1,2,1,1,1,1,2,2,2,3,3,3,2,2,2,1,1,2,2,2,2,1
1,1,2,2,2,1,1,1,2,3,3,3,3,3,3,3,2,2,2,2,2,2,1,1
2,2,2,1,1,1,1,2,2,3,3,3,3,3,3,3,2,0,5,2,1,1,1,1
1,2,2,1,2,1,1,2,3,3,3,4,4,3,3,3,2,0,0,2,1,1,1,1
1,1,1,1,1,0,2,2,3,4,4,4,4,3,3,2,6,0,0,2,2,2,1,1
1,1,1,1,1,1,2,2,3,4,7,7,4,4,3,3,0,0,0,2,2,1,1,1
1,1,1,1,1,1,1,2,2,4,7,7,7,4,3,3,2,2,2,2,1,1,1,1
1,1,2,1,1,1,1,2,2,4,4,7,7,4,3,3,2,2,2,1,1,1,1,1
1,1,2,2,2,1,1,1,2,2,2,4,4,4,2,2,2,1,1,1,1,1,1,1
1,1,1,2,2,2,1,1,1,1,2,2,2,2,2,1,1,1,1,1,1,1,1,1
1,1,1,2,2,1,1,1,1,1,1,2,2,1,1,1,1,1,2,2,1,1,1,1
1,1,2,2,2,1,1,1,1,1,1,1,2,2,1,1,1,1,2,2,2,2,2,1
1,2,2,2,1,1,1,2,1,1,1,2,2,2,1,1,1,1,1,2,2,1,1,1
1,1,1,1,1,1,1,2,1,1,2,2,1,1,1,1,2,1,1,1,1,1,1,1
1,1,1,1,1,1,1,1,1,1,2,1,1,1,1,1,2,1,1,1,1,1,1,1
1,1,1,1,1,1,1,1,1,1,1,1,1,1,1,1,1,1,1,1,1,1,1,1
1,1,1,1,1,1,1,1,1,1,1,2,1,1,1,1,1,1,1,1,1,1,1,1
endlayer

layer
1,1,1,1,1,1,1,1,1,1,1,1,1,1,1,1,1,1,1,1,1,1,1,1
1,1,1,1,1,1,1,1,1,1,1,1,2,4,4,1,1,1,1,1,1,1,1,1
1,1,1,1,1,1,1,1,1,1,1,2,2,2,2,2,1,1,1,1,1,1,1,1
1,1,1,1,1,1,1,2,1,1,0,2,2,2,2,2,2,1,1,1,1,1,1,1
1,1,1,1,1,1,1,2,2,1,2,2,2,2,2,2,2,2,1,1,1,1,1,1
1,1,1,1,1,1,1,1,2,1,2,2,2,2,2,2,2,2,1,1,1,1,1,1
1,1,1,1,1,1,1,1,2,2,3,3,3,3,3,2,2,1,1,2,2,1,1,1
1,1,1,1,2,2,1,2,3,3,3,3,3,3,3,3,3,2,1,2,2,2,1,1
1,1,1,2,2,2,2,2,3,3,3,3,3,3,3,3,3,2,2,2,2,1,1,1
1,2,2,2,2,2,2,3,3,3,4,4,4,4,3,3,2,0,0,2,1,1,1,1
1,1,2,2,2,2,2,3,4,4,4,0,0,4,4,2,2,0,0,2,1,1,1,1
1,1,1,1,2,2,2,3,4,0,0,0,0,2,2,2,0,0,0,2,2,1,1,1
1,1,1,1,1,2,2,3,4,0,0,8,0,0,4,4,0,0,0,2,2,1,1,1
1,1,1,1,1,1,2,3,4,0,8,8,0,0,4,4,4,0,0,2,1,1,1,1
1,1,1,1,1,1,1,2,4,0,0,0,8,0,4,4,4,4,9,2,1,1,1,1
1,1,1,2,2,2,2,2,4,4,4,0,0,0,4,4,4,2,2,1,1,1,1,1
1,1,1,2,2,2,2,1,2,2,4,4,4,4,4,2,2,2,2,2,1,1,1,1
1,1,1,2,2,2,1,1,1,1,2,2,2,2,2,2,2,2,2,2,1,1,1,1
1,1,1,2,2,1,1,1,2,1,1,2,2,2,1,2,1,1,2,2,1,1,1,1
1,1,2,1,1,1,1,2,2,1,2,2,2,2,1,2,2,1,1,1,1,1,1,1
1,1,1,1,1,1,1,1,1,1,2,2,2,2,1,1,2,1,1,1,1,1,1,1
1,1,1,1,1,1,1,1,1,1,2,2,2,1,1,1,1,1,1,1,1,1,1,1
1,1,1,1,1,1,1,1,1,1,2,1,1,1,1,1,1,1,1,1,1,1,1,1
1,1,1,1,1,1,1,1,1,1,2,2,1,1,1,1,1,1,1,1,1,1,1,1
endlayer

layer
1,1,1,1,1,1,1,1,1,2,2,1,1,1,1,1,1,1,1,1,1,1,1,1
1,1,1,1,1,1,1,1,1,1,2,2,1,1,1,1,1,1,1,1,1,1,1,1
1,1,1,1,1,1,1,1,1,1,1,2,4,4,4,1,1,1,1,1,1,1,1,1
1,1,1,1,1,1,1,1,1,1,2,2,4,4,2,2,1,1,1,1,1,1,1,1
1,1,1,1,1,1,1,1,2,2,2,2,4,4,2,2,2,1,1,1,1,1,1,1
1,1,1,1,1,1,1,1,2,2,4,4,4,4,4,2,2,2,1,1,1,1,1,1
1,1,1,1,1,1,2,2,4,4,4,4,4,4,4,3,3,2,2,2,1,1,1,1
1,1,1,1,1,2,2,4,4,4,4,4,4,4,4,4,3,3,2,2,2,1,1,1
1,1,1,1,2,2,2,4,4,4,4,4,4,4,4,4,3,2,2,2,2,1,1,1
1,1,1,2,2,2,4,4,4,4,0,0,0,0,4,3,2,2,2,2,1,1,1,1
1,1,1,1,2,2,4,4,0,0,0,0,0,0,0,2,2,2,2,2,1,1,1,1
1,1,1,1,2,2,4,4,0,0,0,0,0,2,2,2,0,0,10,2,2,1,1,1
1,1,1,1,2,2,4,4,0,0,0,0,0,0,0,11,0,0,0,2,2,1,1,1
1,1,1,1,1,2,4,4,0,0,0,0,0,0,0,0,0,0,0,2,1,1,1,1
1,1,1,1,1,2,4,4,0,0,0,0,0,0,0,0,0,0,0,2,1,1,1,1
1,1,1,1,2,2,2,4,0,0,0,0,0,0,0,0,12,4,2,1,1,1,1,1
1,1,1,1,2,2,2,2,4,4,14,0,0,0,0,4,4,2,2,13,13,1,1,1
1,1,1,1,2,2,2,1,2,2,4,4,4,4,4,2,2,2,2,13,1,1,1,1
1,1,1,2,1,1,1,1,2,1,2,2,2,2,2,2,1,15,15,15,1,1,1,1
1,1,1,1,1,1,1,1,1,1,2,2,2,1,1,2,1,1,1,1,1,1,1,1
1,1,1,1,1,1,1,1,1,1,2,2,2,1,1,1,1,1,1,1,1,1,1,1
1,1,1,1,1,1,1,1,1,1,15,2,2,1,1,1,1,1,1,1,1,1,1,1
1,1,1,1,1,1,1,1,1,1,1,1,1,1,1,1,1,1,1,1,1,1,1,1
1,1,1,1,1,1,1,1,1,1,1,1,1,1,1,1,1,1,1,1,1,1,1,1
endlayer

layer
1,1,1,1,1,1,1,1,1,16,0,0,0,0,0,0,1,1,1,1,1,1,1,1
1,1,1,1,1,1,1,1,1,1,0,0,0,0,0,0,1,1,1,1,1,1,1,1
1,1,1,1,1,1,1,1,1,1,1,0,0,0,13,13,13,1,1,1,1,1,1,1
1,1,1,1,1,1,1,1,1,1,15,2,0,0,2,2,13,1,1,1,1,1,1,1
1,1,1,1,1,1,1,1,1,2,2,2,0,0,2,2,13,1,1,1,1,1,1,1
1,1,1,1,1,1,1,13,2,2,0,0,0,0,0,2,2,1,1,1,1,1,1,1
1,1,1,1,1,1,2,2,0,0,0,0,0,0,0,4,4,2,2,1,1,1,1,1
1,1,1,1,1,1,2,17,0,0,0,0,0,0,0,0,4,3,2,2,1,1,1,1
1,1,1,1,1,2,2,0,0,0,0,0,0,0,0,0,4,3,2,2,1,1,1,1
1,1,1,1,2,2,18,0,0,0,0,0,0,0,0,4,4,4,4,2,1,1,1,1
1,1,1,1,2,2,0,0,0,0,0,0,0,0,0,4,2,2,4,2,1,1,1,1
1,1,1,1,2,2,15,15,15,0,0,0,0,0,2,2,0,0,2,2,2,1,1,1
1,1,1,1,1,2,15,15,15,0,0,0,0,0,11,11,0,0,10,2,1,1,1,1
1,1,1,1,1,2,15,15,13,0,0,0,0,0,0,0,0,0,0,2,1,1,1,1
1,1,1,1,1,2,19,0,0,0,0,0,0,0,0,0,0,0,2,0,1,1,1,1
1,1,1,1,2,2,2,0,0,0,0,0,0,0,0,0,0,0,2,13,13,1,1,1
1,1,1,1,1,2,2,2,20,0,0,0,0,0,0,0,0,2,2,13,13,1,1,1
1,1,1,1,2,1,2,1,2,2,0,0,0,0,21,2,2,2,15,13,1,1,1,1
1,1,1,1,1,1,1,1,1,1,2,2,2,2,2,2,1,1,15,1,1,1,1,1
1,1,1,1,1,1,1,1,1,1,2,2,2,1,1,1,1,1,1,1,1,1,1,1
1,1,1,1,1,1,1,1,1,1,13,2,2,1,1,1,1,1,1,1,1,1,1,1
1,1,1,1,1,1,1,1,1,1,15,15,1,1,1,1,1,1,1,1,1,1,1,1
1,1,1,1,1,1,1,1,1,1,1,1,1,1,1,1,1,1,1,1,1,1,1,1
1,1,1,1,1,1,1,1,1,1,1,1,1,1,1,1,1,1,1,1,1,1,1,1
endlayer

layer
1,1,1,1,1,1,1,1,1,0,0,0,0,0,0,0,1,1,1,1,1,1,1,1
1,1,1,1,1,1,1,1,1,1,0,0,0,0,0,21,1,1,1,1,1,1,1,1
1,1,1,1,1,1,1,1,1,1,15,15,0,0,15,13,1,1,1,1,1,1,1,1
1,1,1,1,1,1,1,1,15,15,15,2,0,0,2,13,13,1,1,1,1,1,1,1
1,1,1,1,1,1,1,1,15,15,2,2,0,0,2,2,1,1,1,1,1,1,1,1
1,1,1,1,1,1,1,1,2,2,0,0,0,0,0,2,2,1,1,1,1,1,1,1
1,1,1,1,1,1,13,2,0,23,23,23,0,0,0,0,22,2,2,1,1,1,1,1
1,1,1,1,1,1,2,0,0,23,23,23,0,0,0,0,0,4,2,1,1,1,1,1
1,1,1,1,1,2,2,0,0,23,23,23,0,0,0,0,0,4,2,2,1,1,1,1
1,1,1,1,2,2,0,0,0,23,23,23,0,0,0,0,0,0,24,2,2,1,1,1
1,1,1,1,2,2,0,0,0,0,0,0,0,0,0,0,0,0,0,2,1,1,1,1
1,1,1,1,1,2,0,13,0,0,0,0,0,0,0,4,2,2,4,2,1,1,1,1
1,1,1,1,1,2,13,13,13,0,0,0,0,0,0,2,2,2,2,2,1,1,1,1
1,1,1,1,1,2,0,13,0,0,0,0,0,0,2,2,2,2,2,2,1,1,1,1
1,1,1,1,1,2,0,0,0,0,0,0,0,0,0,2,2,2,2,0,1,1,1,1
1,1,1,1,2,2,2,0,0,0,0,0,0,0,0,0,0,0,2,13,13,1,1,1
1,1,1,1,1,2,2,2,0,0,0,0,0,0,0,0,21,2,2,13,1,1,1,1
1,1,1,1,1,1,2,2,2,2,2,25,21,21,2,2,2,1,13,1,1,1,1,1
1,1,1,1,1,1,1,1,1,13,2,2,2,2,2,2,1,1,1,1,1,1,1,1
1,1,1,1,1,1,1,1,1,1,13,2,2,1,1,1,1,1,1,1,1,1,1,1
1,1,1,1,1,1,1,1,1,1,13,1,2,1,1,1,1,1,1,1,1,1,1,1
1,1,1,1,1,1,1,1,1,1,1,1,1,1,1,1,1,1,1,1,1,1,1,1
1,1,1,1,1,1,1,1,1,1,1,1,1,1,1,1,1,1,1,1,1,1,1,1
1,1,1,1,1,1,1,1,1,1,1,1,1,1,1,1,1,1,1,1,1,1,1,1
endlayer

layer
1,1,1,1,1,1,1,1,1,0,0,0,0,0,0,0,1,1,1,1,1,1,1,1
1,1,1,1,1,1,1,1,1,1,21,0,0,0,21,0,1,1,1,1,1,1,1,1
1,1,1,1,1,1,1,1,1,13,15,15,0,0,15,1,1,1,1,1,1,1,1,1
1,1,1,1,1,1,1,1,15,15,15,2,0,0,2,1,1,1,1,1,1,1,1,1
1,1,1,1,1,1,1,1,1,13,2,2,0,0,2,2,1,1,1,1,1,1,1,1
1,1,1,1,1,1,1,1,2,2,0,0,0,0,0,2,2,2,1,1,1,1,1,1
1,1,1,1,1,1,1,2,0,0,0,0,0,0,0,0,0,2,2,1,1,1,1,1
1,1,1,1,1,13,2,0,0,0,0,0,0,0,0,0,0,26,2,2,1,1,1,1
1,1,1,1,1,1,2,0,0,0,0,0,0,0,0,0,0,0,2,2,2,1,1,1
1,1,1,1,1,2,0,0,0,0,0,0,0,0,0,0,0,0,0,2,2,1,1,1
1,1,1,1,2,2,27,0,0,0,0,0,0,0,0,0,0,0,0,2,1,1,1,1
1,1,1,1,1,2,0,0,0,0,0,0,0,0,0,0,0,0,0,2,1,1,1,1
1,1,1,1,1,2,27,0,0,0,0,0,0,0,0,0,0,0,0,2,1,1,1,1
1,1,1,1,1,2,27,0,0,0,0,0,0,2,2,0,0,0,28,2,1,1,1,1
1,1,1,1,1,2,2,0,0,0,0,0,0,2,2,2,2,2,2,0,1,1,1,1
1,1,1,1,1,2,2,2,0,0,0,0,0,0,2,2,2,2,2,13,1,1,1,1
1,1,1,1,1,2,1,2,2,0,0,0,2,2,2,2,2,2,2,1,1,1,1,1
1,1,1,1,1,1,1,2,2,2,2,2,2,2,2,2,2,15,1,1,1,1,1,1
1,1,1,1,1,1,1,1,1,13,2,2,2,2,2,1,1,1,1,1,1,1,1,1
1,1,1,1,1,1,1,1,1,13,13,2,2,1,1,1,1,1,1,1,1,1,1,1
1,1,1,1,1,1,1,1,1,1,1,13,1,1,1,1,1,1,1,1,1,1,1,1
1,1,1,1,1,1,1,1,1,1,1,1,1,1,1,1,1,1,1,1,1,1,1,1
1,1,1,1,1,1,1,1,1,1,1,1,1,1,1,1,1,1,1,1,1,1,1,1
1,1,1,1,1,1,1,1,1,1,1,1,1,1,1,1,1,1,1,1,1,1,1,1
endlayer

layer
1,1,1,1,1,1,1,1,1,1,0,0,0,0,0,1,1,1,1,1,1,1,1,1
1,1,1,1,1,1,1,1,1,1,0,0,21,0,0,1,1,1,1,1,1,1,1,1
1,1,1,1,1,1,1,1,1,1,15,15,15,15,15,1,1,1,1,1,1,1,1,1
1,1,1,1,1,1,1,1,1,15,15,2,15,15,2,1,1,1,1,1,1,1,1,1
1,1,1,1,1,1,1,1,1,1,2,2,2,2,2,1,1,1,1,1,1,1,1,1
1,1,1,1,1,1,1,1,2,2,2,0,0,0,0,2,2,2,1,1,1,1,1,1
1,1,1,1,1,1,1,2,27,0,0,0,0,0,0,0,0,2,2,2,1,1,1,1
1,1,1,1,1,13,2,2,0,0,0,0,0,0,0,0,0,0,2,2,2,1,1,1
1,1,1,1,1,1,2,0,0,0,0,0,0,0,0,0,0,0,2,2,2,1,1,1
1,1,1,1,1,2,2,0,0,0,0,0,0,0,0,0,0,0,0,2,1,1,1,1
1,1,1,1,2,2,27,0,0,0,0,0,0,0,0,0,0,0,0,2,1,1,1,1
1,1,1,1,1,2,0,0,0,0,0,0,0,0,0,0,0,0,0,2,1,1,1,1
1,1,1,1,1,1,2,0,0,0,0,0,0,0,0,0,0,0,0,2,1,1,1,1
1,1,1,1,1,2,2,0,0,0,0,0,2,0,0,0,0,0,0,2,1,1,1,1
1,1,1,1,1,1,2,2,27,0,0,2,2,0,0,0,0,0,2,13,13,1,1,1
1,1,1,1,1,2,2,2,2,27,0,2,2,2,0,0,0,29,2,13,13,1,1,1
1,1,1,1,1,1,1,2,2,2,2,2,2,2,0,0,30,2,2,1,1,1,1,1
1,1,1,1,1,1,1,2,2,2,2,2,2,2,2,2,2,13,1,1,1,1,1,1
1,1,1,1,1,1,1,1,13,13,2,2,2,2,2,1,1,1,1,1,1,1,1,1
1,1,1,1,1,1,1,1,1,13,1,13,2,1,1,1,1,1,1,1,1,1,1,1
1,1,1,1,1,1,1,1,1,1,1,1,1,1,1,1,1,1,1,1,1,1,1,1
1,1,1,1,1,1,1,1,1,1,1,1,1,1,1,1,1,1,1,1,1,1,1,1
1,1,1,1,1,1,1,1,1,1,1,1,1,1,1,1,1,1,1,1,1,1,1,1
1,1,1,1,1,1,1,1,1,1,1,1,1,1,1,1,1,1,1,1,1,1,1,1
endlayer

layer
1,1,1,1,1,1,1,1,1,1,1,1,0,0,1,1,1,1,1,1,1,1,1,1
1,1,1,1,1,1,1,1,1,1,1,1,21,0,1,1,1,1,1,1,1,1,1,1
1,1,1,1,1,1,1,1,1,1,1,1,13,15,1,1,1,1,1,1,1,1,1,1
1,1,1,1,1,1,1,1,1,1,1,2,13,15,2,1,1,1,1,1,1,1,1,1
1,1,1,1,1,1,1,1,1,1,2,2,2,2,2,1,1,1,1,1,1,1,1,1
1,1,1,1,1,1,1,1,2,2,2,2,0,0,0,2,2,2,2,2,1,1,1,1
1,1,1,1,1,1,1,2,2,2,0,0,0,0,0,0,0,2,2,2,2,1,1,1
1,1,1,1,1,1,2,2,27,0,11,0,0,0,0,0,0,0,2,2,2,1,1,1
1,1,1,1,1,13,2,2,0,0,0,0,0,0,0,0,0,0,2,2,2,1,1,1
1,1,1,1,1,2,2,0,0,0,0,0,0,0,0,0,0,0,0,2,1,1,1,1
1,1,1,1,1,2,2,0,0,0,0,0,0,0,0,0,0,0,0,2,1,1,1,1
1,1,1,1,1,2,2,2,0,0,0,0,0,0,0,0,0,0,0,2,1,1,1,1
1,1,1,1,1,1,2,27,0,0,2,2,0,0,0,0,0,0,0,2,1,1,1,1
1,1,1,1,1,2,2,2,0,2,2,2,0,0,0,0,0,0,0,2,13,1,1,1
1,1,1,1,1,1,2,2,2,2,2,0,0,0,0,0,0,0,2,13,1,1,1,1
1,1,1,1,1,2,2,2,2,2,2,0,0,0,0,0,0,0,2,1,1,1,1,1
1,1,1,1,1,1,1,2,2,2,2,0,0,0,0,0,0,2,1,1,1,1,1,1
1,1,1,1,1,1,1,2,2,2,2,31,0,0,0,2,2,1,1,1,1,1,1,1
1,1,1,1,1,1,1,13,13,1,2,2,2,2,2,1,1,1,1,1,1,1,1,1
1,1,1,1,1,1,1,1,13,1,1,1,2,1,1,1,1,1,1,1,1,1,1,1
1,1,1,1,1,1,1,1,1,1,1,1,15,1,1,1,1,1,1,1,1,1,1,1
1,1,1,1,1,1,1,1,1,1,1,1,1,1,1,1,1,1,1,1,1,1,1,1
1,1,1,1,1,1,1,1,1,1,1,1,1,1,1,1,1,1,1,1,1,1,1,1
1,1,1,1,1,1,1,1,1,1,1,1,1,1,1,1,1,1,1,1,1,1,1,1
endlayer

layer
1,1,1,1,1,1,1,1,1,1,1,1,1,1,1,1,1,1,1,1,1,1,1,1
1,1,1,1,1,1,1,1,1,1,1,1,0,1,1,1,1,1,1,1,1,1,1,1
1,1,1,1,1,1,1,1,1,1,1,13,13,1,1,1,1,1,13,13,13,1,1,1
1,1,1,1,1,1,1,1,1,1,13,2,13,15,1,1,1,13,13,13,1,1,1,1
1,1,1,1,1,1,1,1,1,1,2,2,2,2,2,1,1,13,13,2,2,1,1,1
1,1,1,1,1,1,1,1,2,2,2,2,2,2,11,2,2,2,2,2,2,1,1,1
1,1,1,1,1,1,1,2,2,2,2,2,0,0,0,11,0,2,2,2,2,1,1,1
1,1,1,1,1,1,2,2,2,2,11,0,0,0,0,0,0,2,2,2,2,1,1,1
1,1,1,1,1,13,2,2,2,0,0,0,0,0,0,0,0,0,2,2,1,1,1,1
1,1,1,1,1,2,2,2,2,0,0,0,0,0,0,0,0,0,0,2,1,1,1,1
1,1,1,1,1,2,2,2,2,2,0,0,0,0,0,0,0,0,0,2,1,1,1,1
1,1,1,1,1,1,2,2,2,2,2,0,0,0,0,0,0,0,0,2,1,1,1,1
1,1,1,1,1,1,2,2,2,2,0,0,0,0,0,0,0,0,0,0,1,1,1,1
1,1,1,1,1,2,2,2,2,2,0,0,0,0,0,0,0,0,0,2,13,1,1,1
1,1,1,1,1,1,2,2,2,2,0,0,0,0,0,0,0,0,2,13,13,1,1,1
1,1,1,1,1,1,2,2,2,0,0,0,0,0,0,0,0,0,2,1,1,1,1,1
1,1,1,1,1,1,1,2,2,0,0,0,0,0,0,0,0,2,1,1,1,1,1,1
1,1,1,1,1,1,15,2,2,2,0,0,0,0,0,2,2,1,1,1,1,1,1,1
1,1,1,1,1,1,1,13,13,1,2,2,2,2,2,1,1,1,1,1,1,1,1,1
1,1,1,1,1,1,1,1,1,1,1,1,1,15,1,1,1,1,1,1,1,1,1,1
1,1,1,1,1,1,1,1,1,1,1,1,1,1,1,1,1,1,1,1,1,1,1,1
1,1,1,1,1,1,1,1,1,1,1,1,1,1,1,1,1,1,1,1,1,1,1,1
1,1,1,1,1,1,1,1,1,1,1,1,1,1,1,1,1,1,1,1,1,1,1,1
1,1,1,1,1,1,1,1,1,1,1,1,1,1,1,1,1,1,1,1,1,1,1,1
endlayer

layer
1,1,1,1,1,1,1,1,1,1,1,1,1,1,1,1,1,1,1,1,1,1,1,1
1,1,1,1,1,1,1,1,1,1,1,1,1,1,1,1,1,1,13,1,1,1,1,1
1,1,1,1,1,1,1,1,1,1,1,13,1,1,1,1,13,13,13,13,13,13,1,1
1,1,1,1,1,1,1,1,1,1,13,2,13,1,1,1,13,13,13,2,2,1,1,1
1,1,1,1,1,1,1,1,1,13,2,2,2,2,2,1,13,13,2,2,2,2,1,1
1,1,1,1,1,1,1,1,2,2,2,2,2,2,11,2,2,2,2,2,2,1,1,1
1,1,1,1,1,1,1,2,2,2,2,2,2,2,0,11,2,2,2,2,1,1,1,1
1,1,1,1,1,1,2,2,2,2,2,2,11,0,0,0,10,2,2,2,1,1,1,1
1,1,1,1,1,1,2,2,2,2,2,0,0,0,0,0,0,2,2,2,1,1,1,1
1,1,1,1,15,2,2,2,2,2,0,0,0,0,0,0,0,0,0,2,1,1,1,1
1,1,1,1,1,2,2,2,2,2,2,0,0,0,0,0,0,0,0,0,1,1,1,1
1,1,1,1,1,1,2,2,0,0,0,0,0,0,0,0,0,0,0,2,1,1,1,1
1,1,1,1,1,2,2,0,0,0,0,0,0,0,0,0,0,0,0,0,1,1,1,1
1,1,1,1,1,2,0,0,0,0,0,0,0,0,0,0,0,0,0,2,13,1,1,1
1,1,1,1,1,1,2,0,0,0,0,0,0,0,0,0,0,0,2,1,1,1,1,1
1,1,1,1,1,15,2,0,0,0,0,0,0,0,0,0,0,0,2,1,1,1,1,1
1,1,1,1,1,1,15,2,32,0,0,0,0,0,0,0,0,2,1,1,1,1,1,1
1,1,1,1,1,15,15,15,2,2,0,0,0,0,0,2,2,1,1,1,1,1,1,1
1,1,1,1,1,1,13,13,1,1,2,2,2,2,2,1,1,1,1,1,1,1,1,1
1,1,1,1,1,1,1,1,1,1,1,1,1,1,15,1,1,1,1,1,1,1,1,1
1,1,1,1,1,1,1,1,1,1,1,1,1,1,1,1,1,1,1,1,1,1,1,1
1,1,1,1,1,1,1,1,1,1,1,1,1,1,1,1,1,1,1,1,1,1,1,1
1,1,1,1,1,1,1,1,1,1,1,1,1,1,1,1,1,1,1,1,1,1,1,1
1,1,1,1,1,1,1,1,1,1,1,1,1,1,1,1,1,1,1,1,1,1,1,1
endlayer

layer
1,1,1,1,1,1,1,1,1,1,1,1,1,1,1,1,1,1,1,1,1,1,1,1
1,1,1,1,1,1,1,1,1,1,1,1,1,1,1,1,1,13,13,1,13,13,13,1
1,1,1,1,1,1,1,1,1,1,1,1,1,1,1,1,13,13,13,13,13,13,13,13
1,1,1,1,1,1,1,1,1,1,13,2,1,1,13,13,13,13,13,2,2,2,13,13
1,1,1,1,1,1,1,1,13,13,2,2,2,2,2,13,13,13,13,2,2,13,13,1
1,1,1,1,1,1,1,1,2,2,2,2,2,2,2,2,2,2,2,2,1,1,1,1
1,1,1,1,1,1,1,2,0,2,2,2,2,2,2,2,2,2,2,2,1,1,1,1
1,1,1,1,1,1,2,0,0,0,2,2,2,2,2,0,2,2,2,0,1,1,1,1
1,1,1,1,1,1,2,27,0,0,0,2,0,2,2,0,0,2,2,0,1,1,1,1
1,1,1,1,1,2,0,0,0,0,0,0,0,0,2,0,0,0,0,0,1,1,1,1
1,1,1,1,10,2,33,0,0,0,0,0,0,2,2,2,0,0,0,0,1,1,1,1
1,1,1,1,1,2,0,0,0,0,0,0,0,0,0,2,0,0,0,0,1,1,1,1
1,1,1,1,1,2,0,0,0,0,0,0,0,0,0,0,0,0,0,15,15,1,1,1
1,1,1,1,15,2,0,0,0,0,0,0,0,0,0,0,0,0,0,2,13,1,1,1
1,1,1,15,15,15,2,0,0,0,0,0,0,0,0,0,0,0,2,1,1,1,1,1
1,1,1,1,15,15,2,0,0,0,0,0,0,0,0,0,0,21,2,1,1,1,1,1
1,1,1,1,1,15,15,2,0,0,0,0,0,0,0,0,10,2,1,1,1,1,1,1
1,1,1,1,1,1,15,15,2,2,0,0,0,0,0,2,2,1,1,1,1,1,1,1
1,1,1,1,1,1,1,1,1,1,2,2,2,1,2,13,1,1,1,1,1,1,1,1
1,1,1,1,1,1,1,1,1,1,1,1,1,1,1,1,1,1,1,1,1,1,1,1
1,1,1,1,1,1,1,1,1,1,1,1,1,1,1,1,1,1,1,1,1,1,1,1
1,1,1,1,1,1,1,1,1,1,1,1,1,1,1,1,1,1,1,1,1,1,1,1
1,1,1,1,1,1,1,1,1,1,1,1,1,1,1,1,1,1,1,1,1,1,1,1
1,1,1,1,1,1,1,1,1,1,1,1,1,1,1,1,1,1,1,1,1,1,1,1
endlayer

layer
1,1,1,1,1,1,1,1,1,1,1,1,1,1,1,1,1,1,1,1,1,1,1,1
1,1,1,1,1,1,1,1,1,1,1,1,1,1,1,1,15,15,1,1,15,15,15,15
1,1,1,1,1,1,1,1,1,1,1,1,1,1,1,15,15,15,13,0,13,2,2,15
1,1,1,1,1,1,1,1,1,1,1,2,1,1,13,13,13,13,0,0,2,2,13,13
1,1,1,1,1,1,1,1,15,15,2,0,2,2,2,13,13,0,0,0,34,13,13,1
1,1,1,1,1,1,1,1,15,2,36,0,0,11,0,0,0,35,0,0,1,1,1,1
1,1,1,1,1,1,37,2,27,0,0,0,0,0,0,0,0,0,0,0,1,1,1,1
1,1,1,1,1,1,2,0,0,0,0,0,0,0,0,0,0,0,0,0,1,1,1,1
1,1,1,1,1,1,2,27,0,0,0,0,0,0,0,0,0,0,0,0,1,1,1,1
1,1,1,1,1,2,0,0,0,0,0,0,0,0,0,0,0,0,0,0,1,1,1,1
1,1,1,1,0,2,0,0,0,0,0,0,0,38,0,0,0,0,15,15,1,1,1,1
1,1,1,1,15,2,0,0,0,0,0,0,0,0,0,39,0,15,15,15,15,13,1,1
1,1,1,15,15,2,15,0,0,0,0,0,0,0,0,0,0,15,15,15,15,13,1,1
1,1,10,15,15,3,15,15,0,0,0,0,0,0,0,0,0,15,15,3,15,13,1,1
1,1,1,15,15,15,2,15,0,0,0,0,0,0,0,0,10,13,15,15,15,13,1,1
1,1,1,15,15,15,15,15,0,0,0,0,0,0,0,0,0,10,2,27,1,1,1,1
1,1,1,1,15,15,15,2,0,21,0,0,0,0,0,0,0,1,1,1,1,1,1,1
1,1,1,1,1,1,1,1,1,2,0,0,21,0,21,2,2,1,1,1,1,1,1,1
1,1,1,1,1,1,1,1,1,1,2,1,2,1,2,15,1,1,1,1,1,1,1,1
1,1,1,1,1,1,1,1,1,1,1,1,11,1,1,1,1,1,1,1,1,1,1,1
1,1,1,1,1,1,1,1,1,1,1,1,1,1,1,1,1,1,1,1,1,1,1,1
1,1,1,1,1,1,1,1,1,1,1,1,1,1,1,1,1,1,1,1,1,1,1,1
1,1,1,1,1,1,1,1,1,1,1,1,1,1,1,1,1,1,1,1,1,1,1,1
1,1,1,1,1,1,1,1,1,1,1,1,1,1,1,1,1,1,1,1,1,1,1,1
endlayer

layer
1,1,1,1,1,1,1,1,1,1,1,1,1,1,1,1,1,1,1,1,1,1,1,21
1,1,1,1,1,1,1,1,1,1,1,1,1,1,1,1,1,1,1,1,0,0,13,13
1,1,1,1,1,1,1,1,1,1,1,1,1,1,1,1,15,13,0,0,0,0,40,13
1,1,1,1,1,1,1,21,13,1,41,2,1,37,1,13,13,0,0,0,0,0,0,13
1,1,1,1,1,1,1,13,15,15,1,0,1,2,1,0,0,0,0,0,0,0,0,1
1,1,1,1,1,1,1,1,15,15,0,0,0,11,0,0,0,0,0,0,1,1,1,1
1,1,1,1,1,1,0,1,0,0,0,0,0,0,0,0,0,0,0,0,1,1,1,1
1,1,1,1,1,1,1,0,0,0,0,0,0,0,0,0,0,0,0,0,1,1,1,1
1,1,1,1,1,10,2,27,0,0,0,0,0,0,0,0,0,0,0,0,1,1,1,1
1,1,1,1,1,1,11,0,0,0,0,0,0,0,0,0,0,0,0,0,1,1,1,1
1,1,1,1,1,1,0,0,0,0,0,0,0,0,0,0,0,0,0,0,1,1,1,1
1,1,1,1,10,2,27,0,0,0,0,0,0,0,0,0,0,0,0,13,1,1,1,1
1,1,1,1,15,15,15,0,0,0,0,0,0,0,0,0,0,0,13,13,13,27,1,1
1,1,0,10,15,42,15,1,0,0,0,0,0,0,0,0,0,0,0,42,13,1,1,1
1,1,1,1,15,15,15,1,0,0,0,0,0,0,0,0,0,0,0,0,1,1,1,1
1,1,1,1,1,15,1,1,0,0,0,0,0,0,0,0,0,0,1,0,1,1,1,1
1,1,1,1,1,1,1,1,0,21,0,0,0,0,0,0,21,1,1,1,1,1,1,1
1,1,1,1,1,1,1,1,10,2,27,0,0,0,0,1,2,27,1,1,1,1,1,1
1,1,1,1,1,1,1,1,1,11,1,1,1,1,1,15,1,1,1,1,1,1,1,1
1,1,1,1,1,1,1,1,1,1,1,1,0,1,1,1,1,1,1,1,1,1,1,1
1,1,1,1,1,1,1,1,1,1,1,1,1,1,1,1,1,1,1,1,1,1,1,1
1,1,1,1,1,1,1,1,1,1,1,1,1,1,1,1,1,1,1,1,1,1,1,1
1,1,1,1,1,1,1,1,1,1,1,1,1,1,1,1,1,1,1,1,1,1,1,1
1,1,1,1,1,1,1,1,1,1,1,1,1,1,1,1,1,1,1,1,1,1,1,1
endlayer

