
# Created by Ruins mod version 17.0 Ingame Parser
# authoring Player: ST753M

weight=1
embed_into_distance=3
acceptable_target_blocks=grass,dirt,podzol,mycelium
unacceptable_target_blocks=flowing_water,water,flowing_lava,lava
dimensions=6,13,13
allowable_overhang=8
max_leveling=2
leveling_buffer=0
preserve_water=0
preserve_lava=0

biomesToSpawnIn=jungle,jungle_edge,jungle_hills,tropical_island,tropical_rainforest,rainforest,mutated_jungle,mutated_jungle_edge,mini_jungle,

rule1=0,100,preserveBlock
rule2=0,100,minecraft:log-3
rule3=0,100,minecraft:mossy_cobblestone-0
rule4=0,100,minecraft:grass-0
rule5=0,100,minecraft:leaves-15
rule6=0,100,minecraft:leaves-7
rule7=0,100,minecraft:sapling-3

layer
1,1,1,1,1,2,2,2,1,1,1,1,1
1,1,1,2,2,3,3,3,2,2,1,1,1
1,1,2,3,3,3,3,3,3,3,2,1,1
1,2,3,3,3,3,3,3,3,3,3,2,1
1,2,3,3,3,3,3,3,3,3,3,2,1
2,3,3,3,3,3,3,3,3,3,3,3,2
2,3,3,3,3,3,3,3,3,3,3,3,2
2,3,3,3,3,3,3,3,3,3,3,3,2
1,2,3,3,3,3,3,3,3,3,3,2,1
1,2,3,3,3,3,3,3,3,3,3,2,1
1,1,2,3,3,3,3,3,3,3,2,1,1
1,1,1,2,2,3,3,3,2,2,1,1,1
1,1,1,1,1,2,2,2,1,1,1,1,1
endlayer

layer
1,1,1,1,1,2,2,2,1,1,1,1,1
1,1,1,2,2,3,3,3,2,2,1,1,1
1,1,2,3,3,3,3,3,3,3,2,1,1
1,2,3,3,3,3,3,3,3,3,3,2,1
1,2,3,3,3,3,3,3,3,3,3,2,1
2,3,3,3,3,3,3,3,3,3,3,3,2
2,3,3,3,3,3,3,3,3,3,3,3,2
2,3,3,3,3,3,3,3,3,3,3,3,2
1,2,3,3,3,3,3,3,3,3,3,2,1
1,2,3,3,3,3,3,3,3,3,3,2,1
1,1,2,3,3,3,3,3,3,3,2,1,1
1,1,1,2,2,3,3,3,2,2,1,1,1
1,1,1,1,1,2,2,2,1,1,1,1,1
endlayer

layer
1,1,1,1,1,2,2,2,1,1,1,1,1
1,1,1,2,2,4,3,4,2,2,1,1,1
1,1,2,3,3,3,4,4,4,3,2,1,1
1,2,3,3,3,3,3,4,4,3,3,2,1
1,2,3,4,4,3,4,4,3,3,3,2,1
2,3,4,3,4,4,4,4,4,3,3,3,2
2,3,3,3,3,4,4,3,4,4,3,3,2
2,3,3,3,4,4,4,3,3,4,4,3,2
1,2,3,4,4,4,4,3,4,3,3,2,1
1,2,3,3,3,3,4,3,3,3,3,2,1
1,1,2,3,3,3,4,4,3,3,2,1,1
1,1,1,2,2,3,3,4,2,2,1,1,1
1,1,1,1,1,2,2,2,1,1,1,1,1
endlayer

layer
1,1,1,1,1,2,2,2,1,1,1,1,1
1,1,1,2,2,6,5,5,2,2,1,1,1
1,1,2,6,0,5,5,0,5,6,2,1,1
1,2,6,6,0,6,0,0,0,0,6,2,1
1,2,6,0,0,0,0,0,6,6,6,2,1
2,6,6,5,0,7,7,0,0,6,6,6,2
2,5,5,5,0,7,7,0,0,0,0,0,2
2,0,0,0,0,0,0,0,0,0,0,0,2
1,2,0,0,0,6,6,0,0,0,0,2,1
1,2,6,0,0,6,0,0,0,6,6,2,1
1,1,2,0,5,6,0,0,0,6,2,1,1
1,1,1,2,2,6,6,0,2,2,1,1,1
1,1,1,1,1,2,2,2,1,1,1,1,1
endlayer

layer
1,1,1,1,1,2,1,2,1,1,1,1,1
1,1,1,2,6,6,0,0,5,2,1,1,1
1,1,2,6,0,0,5,0,6,6,2,1,1
1,1,0,0,0,0,0,0,0,6,6,2,1
1,2,6,0,0,0,0,0,0,0,6,2,1
2,0,0,5,0,0,0,0,0,0,0,6,2
1,0,0,0,0,0,0,0,0,0,0,0,2
2,0,0,0,0,0,0,0,0,0,0,0,1
1,2,5,0,0,0,0,0,0,0,6,2,1
1,1,5,0,0,6,0,0,0,0,6,2,1
1,1,2,5,5,0,0,0,0,6,6,1,1
1,1,1,2,2,0,0,6,1,2,1,1,1
1,1,1,1,1,2,2,2,1,1,1,1,1
endlayer

layer
1,1,1,1,1,2,1,1,1,1,1,1,1
1,1,1,1,1,6,0,0,1,2,1,1,1
1,1,2,0,0,0,0,0,0,6,2,1,1
1,1,0,0,0,0,0,0,0,0,0,1,1
1,2,5,0,0,0,0,0,0,0,0,2,1
1,0,0,0,0,0,0,0,0,0,0,6,6
6,6,0,0,0,0,0,0,0,0,0,0,6
2,6,0,0,0,0,0,0,0,0,0,0,1
1,2,6,0,0,0,0,0,0,0,0,1,1
1,1,5,0,0,0,0,0,0,0,6,2,1
1,1,2,0,6,0,0,0,0,0,1,1,1
1,1,1,1,6,0,0,6,1,2,1,1,1
1,1,1,1,1,2,1,2,1,1,1,1,1
endlayer

