
# Created by Ruins mod version 17.0 Ingame Parser
# authoring Player: ST753M

weight=1
uniqueMinDistance=800
embed_into_distance=9
acceptable_target_blocks=grass
unacceptable_target_blocks=flowing_water,flowing_lava,lava
dimensions=15,25,25
allowable_overhang=12
max_leveling=2
leveling_buffer=0
preserve_water=0
preserve_lava=0

biomesToSpawnIn=jungle,jungle_edge,jungle_hills,tropical_island,tropical_rainforest,rainforest,mutated_jungle,mutated_jungle_edge,bamboo_forest,mini_jungle,temperate_rainforest

=0,100,air
rule1=0,100,preserveBlock
rule2=0,100,minecraft:grass-0
rule3=0,100,minecraft:dirt-0

rule4=0,100,minecraft:stone-0,minecraft:monster_egg-2,minecraft:stonebrick-2,minecraft:monster_egg-3,minecraft:stonebrick-1,minecraft:stone-6,minecraft:monster_egg-4,minecraft:stonebrick-0

rule5=0,100,minecraft:stone_brick_stairs-0
rule6=0,100,minecraft:stone_brick_stairs-3
rule7=0,100,minecraft:stone_brick_stairs-2
rule8=0,100,minecraft:tripwire_hook-4
rule9=0,100,minecraft:tripwire-4
rule10=0,100,minecraft:tripwire_hook-6

rule11=0,100,ChestGenHook:chests/jungle_temple:4-5,air,air

rule12=0,100,minecraft:water-0
rule13=0,100,minecraft:stone_brick_stairs-1
rule14=0,100,minecraft:stone_brick_stairs-5
rule15=0,100,minecraft:vine-8
rule16=0,100,minecraft:stonebrick-3

rule17=0,100,IInventory;minecraft:dispenser;ChestGenHook:chests/jungle_temple_dispenser:5-2

rule18=0,100,minecraft:vine-2
rule19=0,100,minecraft:water-1
rule20=0,100,minecraft:water-8
rule21=0,100,minecraft:stone_brick_stairs-7
rule22=0,100,minecraft:stone_brick_stairs-6
rule23=0,100,minecraft:vine-1
rule24=0,100,minecraft:vine-4,air
rule25=0,100,minecraft:stone_brick_stairs-4
rule26=0,100,minecraft:vine-9
rule27=0,100,minecraft:vine-3

rule28=0,80,MobSpawner:spider,MobSpawner:cave_spider,MobSpawner:witch,MobSpawner:skeleton,MobSpawner:skeleton,MobSpawner:cave_spider

rule29=0,100,minecraft:water-9

layer
1,1,1,2,2,2,2,2,2,2,2,2,2,2,2,2,2,2,2,2,2,2,1,1,1
1,1,2,4,4,4,4,4,4,4,4,4,4,4,4,4,4,4,4,4,4,3,2,1,1
1,2,4,4,4,4,4,4,4,4,4,4,4,4,4,4,4,4,4,4,4,4,3,2,1
2,4,4,4,4,4,4,4,4,4,4,4,4,4,4,4,4,4,4,4,4,4,4,3,2
2,4,4,4,4,4,4,4,4,4,4,4,4,4,4,4,4,4,4,4,4,4,4,4,2
2,4,4,4,4,4,4,4,4,4,4,4,4,4,4,4,4,4,4,4,4,4,4,4,2
2,4,4,4,4,4,4,4,4,4,4,4,4,4,4,4,4,4,4,4,4,4,4,4,2
2,4,4,4,4,4,4,4,4,4,4,4,4,4,4,4,4,4,4,4,4,4,4,4,2
2,4,4,4,4,4,4,4,4,4,4,4,4,4,4,4,4,4,4,4,4,4,4,4,2
2,4,4,4,4,4,4,4,4,4,4,4,4,4,4,4,4,4,4,4,4,4,4,4,2
2,4,4,4,4,4,4,4,4,4,4,4,4,4,4,4,4,4,4,4,4,4,4,4,2
2,4,4,4,4,4,4,4,4,4,4,4,4,4,4,4,4,4,4,4,4,4,4,4,2
2,4,4,4,4,4,4,4,4,4,4,4,4,4,4,4,4,4,4,4,4,4,4,4,2
2,4,4,4,4,4,4,4,4,4,4,4,4,4,4,4,4,4,4,4,4,4,4,4,2
2,4,4,4,4,4,4,4,4,4,4,4,4,4,4,4,4,4,4,4,4,4,4,4,2
2,4,4,4,4,4,4,4,4,4,4,4,4,4,4,4,4,4,4,4,4,4,4,4,2
2,4,4,4,4,4,4,4,4,4,4,4,4,4,4,4,4,4,4,4,4,4,4,4,2
2,4,4,4,4,4,4,4,4,4,4,4,4,4,4,4,4,4,4,4,4,4,4,4,2
2,4,4,4,4,4,4,4,4,4,4,4,4,4,4,4,4,4,4,4,4,4,4,4,2
2,4,4,4,4,4,4,4,4,4,4,4,4,4,4,4,4,4,4,4,4,4,4,4,2
2,4,4,4,4,4,4,4,4,4,4,4,4,4,4,4,4,4,4,4,4,4,4,4,2
2,4,4,4,4,4,4,4,4,4,4,4,4,4,4,4,4,4,4,4,4,4,4,4,2
1,2,4,4,4,4,4,4,4,4,4,4,4,4,4,4,4,4,4,4,4,4,4,2,1
1,1,2,4,4,4,4,4,4,4,4,4,4,4,4,4,4,4,4,4,4,4,2,1,1
1,1,1,2,2,2,2,2,2,2,2,2,2,2,2,2,2,2,2,2,2,2,1,1,1
endlayer

layer
1,1,1,2,2,2,2,2,2,2,2,2,2,2,2,2,2,2,2,2,2,2,1,1,1
1,1,2,3,4,4,4,4,4,4,4,4,4,4,4,4,4,4,4,4,4,3,2,1,1
1,2,4,4,0,0,0,0,0,0,0,0,0,0,0,0,0,0,0,0,0,4,4,2,1
2,3,4,0,0,0,0,0,0,0,0,0,0,0,0,0,0,0,0,0,0,0,4,3,2
2,4,4,0,0,0,0,0,0,0,0,0,0,0,0,0,0,0,0,0,0,0,4,4,2
2,4,0,0,0,0,4,4,4,4,4,5,5,5,4,4,4,4,4,0,0,0,0,4,2
2,4,0,0,0,0,4,0,0,0,4,4,4,4,4,0,0,0,4,0,0,0,0,4,2
2,4,4,7,6,4,4,0,0,0,4,4,4,4,4,0,0,0,4,4,7,6,4,4,2
2,10,9,9,9,9,8,4,0,4,4,4,4,4,4,4,4,4,10,9,9,9,9,8,2
2,4,4,7,6,4,4,0,0,0,4,4,4,4,4,0,0,0,4,4,7,6,4,4,2
2,4,0,0,0,0,4,0,0,0,4,0,0,0,4,0,0,0,4,0,0,0,0,4,2
2,4,0,0,0,0,4,0,0,0,4,0,0,0,4,0,0,0,4,0,0,0,0,4,2
2,4,0,0,0,0,4,0,0,0,4,0,0,0,4,0,0,0,4,0,0,0,0,4,2
2,4,0,0,0,0,4,4,4,4,4,5,5,5,4,4,4,4,4,0,0,0,0,4,2
2,4,0,0,0,0,4,4,11,4,4,4,4,4,4,4,11,4,4,0,0,0,0,4,2
2,4,0,0,0,0,4,12,12,12,4,4,12,4,4,12,12,12,4,0,0,0,0,4,2
2,4,4,0,0,4,4,4,4,4,4,4,4,4,4,4,4,4,4,4,0,0,4,4,2
2,4,0,0,0,0,0,0,0,0,0,0,4,0,0,0,0,0,0,0,0,0,0,4,2
2,4,0,0,0,0,0,0,0,0,0,0,4,0,0,0,0,0,0,0,0,0,0,4,2
2,4,0,0,0,0,0,0,0,0,0,0,13,0,0,0,0,0,0,0,0,0,0,4,2
2,4,0,0,0,0,0,0,0,0,0,0,5,0,0,0,0,0,0,0,0,0,0,4,2
2,2,4,0,0,0,0,0,0,0,0,0,4,0,0,0,0,0,0,0,0,0,4,2,2
1,2,4,4,5,0,5,0,5,0,5,0,4,0,5,0,5,0,5,0,5,4,4,2,1
1,1,2,2,4,4,4,4,4,4,4,4,4,4,4,4,4,4,4,4,4,2,2,1,1
1,1,1,2,2,2,2,2,2,2,2,2,2,2,2,2,2,2,2,2,2,2,1,1,1
endlayer

layer
1,1,1,2,2,2,2,2,2,2,2,2,2,2,2,2,2,2,2,2,2,2,1,1,1
1,1,2,4,13,14,13,14,13,14,13,14,13,14,13,14,13,14,13,14,13,4,2,1,1
1,2,4,4,0,0,0,0,0,0,0,0,0,0,0,0,0,0,0,0,0,4,4,2,1
2,3,4,0,0,0,0,0,0,0,0,0,0,0,0,0,0,0,0,0,0,0,4,3,2
2,4,0,0,0,0,0,0,0,15,0,0,0,0,0,0,0,0,0,0,0,0,0,4,2
2,4,0,0,0,0,4,4,16,4,4,0,0,0,4,4,16,4,4,0,0,0,0,4,2
2,4,0,0,0,0,4,0,0,0,4,5,5,5,4,0,0,0,4,0,0,0,0,4,2
2,4,4,0,0,4,4,0,0,0,4,4,4,4,4,0,0,0,4,4,0,0,4,4,2
2,17,0,0,0,0,0,4,0,4,4,4,4,4,4,4,4,4,17,0,0,0,0,0,2
2,4,4,0,0,4,4,0,0,0,4,4,11,4,4,0,0,0,4,4,0,0,4,4,2
2,4,0,0,0,0,4,0,0,0,4,0,0,0,4,0,0,0,4,0,18,0,0,4,2
2,4,0,0,0,0,4,0,0,0,4,0,0,0,4,0,0,0,4,0,0,0,0,4,2
2,4,0,0,0,0,4,0,0,0,4,0,0,0,4,0,0,0,4,0,0,0,0,4,2
2,4,0,0,0,0,4,4,4,4,4,0,0,0,4,4,4,4,4,0,0,0,0,4,2
2,4,0,0,0,0,4,4,12,4,4,0,0,0,4,4,12,4,4,0,0,0,0,4,2
2,4,0,0,0,0,7,0,19,0,6,0,20,0,7,0,19,0,6,0,0,0,0,4,2
2,4,4,0,0,4,4,0,0,0,4,4,4,4,4,0,0,0,4,4,0,0,4,4,2
2,4,0,0,0,0,0,0,0,0,0,18,4,0,0,0,0,0,0,0,0,0,0,4,2
4,13,0,0,0,0,0,0,0,0,0,0,4,0,0,0,0,0,0,0,0,0,0,13,4
4,5,0,0,0,0,0,0,0,0,0,0,0,0,0,0,0,0,0,0,0,0,0,5,4
2,4,0,0,0,0,0,0,0,0,0,0,0,0,0,0,0,0,0,0,0,0,0,4,2
2,2,4,0,0,0,0,0,0,0,0,0,4,0,0,0,0,0,0,0,0,0,4,2,2
1,2,4,4,0,0,0,0,0,0,0,0,4,0,0,0,0,0,0,0,0,4,4,2,1
1,1,2,2,16,4,16,4,16,4,16,4,4,4,16,4,16,4,16,4,16,2,2,1,1
1,1,1,2,2,2,2,2,2,2,2,2,2,2,2,2,2,2,2,2,2,2,1,1,1
endlayer

layer
1,1,1,1,2,2,2,2,2,2,2,2,2,2,2,2,2,2,2,2,2,1,1,1,1
1,1,2,2,4,4,4,4,4,4,4,4,4,4,4,4,4,4,4,4,4,2,2,1,1
1,2,4,4,0,0,0,0,0,0,18,18,0,0,18,18,0,18,18,0,0,4,4,2,1
1,2,4,0,0,0,0,0,0,0,0,0,0,0,0,0,0,0,0,0,0,0,4,2,1
2,4,0,0,0,0,0,15,15,15,0,0,0,0,15,0,0,15,0,0,0,0,0,4,2
2,4,0,0,0,0,4,4,4,4,4,0,0,0,4,4,4,4,4,0,0,0,0,4,2
2,4,0,0,0,0,4,0,0,0,4,0,0,0,4,0,0,0,4,0,15,0,0,4,2
2,4,16,22,21,16,4,23,0,0,4,5,5,5,4,0,0,0,4,16,22,21,16,4,2
2,4,22,0,0,21,4,4,4,4,4,4,4,4,4,4,4,4,4,22,0,0,21,4,2
2,4,4,22,21,4,4,0,0,0,4,4,0,4,4,0,0,0,4,16,22,21,16,4,2
2,4,0,0,0,0,4,0,0,0,4,0,0,0,4,0,0,0,4,0,18,0,0,4,2
2,4,0,0,0,0,4,0,0,0,4,0,0,0,4,0,0,0,4,0,0,0,0,4,2
2,4,0,0,0,0,4,0,0,0,4,0,0,0,4,0,0,0,4,23,0,0,24,4,2
2,4,0,0,0,24,4,4,4,4,4,0,0,0,4,4,4,4,4,0,0,0,0,4,2
2,4,0,0,0,0,4,16,4,16,4,0,0,0,4,16,4,16,4,0,0,0,0,4,2
2,4,0,0,0,0,22,0,0,0,21,0,20,0,22,0,0,0,21,0,0,0,0,4,2
2,4,4,22,21,4,4,0,0,0,4,4,4,4,4,0,0,0,4,4,22,21,4,4,2
2,4,0,0,0,0,0,0,0,0,0,18,4,0,0,0,0,0,0,0,0,0,0,4,2
4,14,0,0,0,0,0,0,0,0,0,0,16,0,0,0,0,0,0,0,0,0,0,14,4
4,25,0,0,0,0,0,0,0,0,0,0,14,0,0,0,0,0,0,0,0,0,0,25,4
2,4,0,0,0,0,0,0,0,0,0,0,25,23,0,0,0,0,0,0,0,0,0,4,2
1,2,4,0,0,0,0,0,0,0,0,0,16,0,0,0,0,0,0,0,0,0,4,2,1
1,2,4,4,0,0,0,0,0,0,0,0,4,0,0,0,0,0,0,0,0,4,4,2,1
1,1,2,2,4,16,4,16,4,16,4,16,4,16,4,16,4,16,4,16,4,2,2,1,1
1,1,1,1,2,2,2,2,2,2,2,2,2,2,2,2,2,2,2,2,2,1,1,1,1
endlayer

layer
1,1,1,1,2,2,2,2,2,2,2,2,2,2,2,2,2,2,2,2,2,1,1,1,1
1,1,2,2,4,4,4,4,4,4,4,4,4,4,4,4,4,4,4,4,4,2,2,1,1
1,2,4,4,14,14,14,14,14,14,14,14,14,14,14,14,14,14,14,14,14,4,4,2,1
1,2,4,23,0,0,0,0,0,0,0,0,0,0,0,0,0,0,0,0,0,24,4,2,1
2,4,4,23,0,0,25,25,25,25,25,0,0,0,25,25,25,25,25,0,0,24,4,4,2
2,4,0,0,0,0,4,4,4,4,4,0,0,0,4,4,4,4,4,0,0,0,0,4,2
2,4,23,0,15,0,4,23,0,0,4,0,0,0,4,0,0,0,4,0,15,0,0,4,2
2,4,4,4,4,4,4,26,0,0,4,0,0,0,4,0,0,0,4,4,4,4,4,4,2
2,4,4,4,4,4,4,4,4,4,4,5,5,5,4,4,4,4,4,4,4,4,4,4,2
2,4,4,4,4,4,4,0,0,0,4,4,4,4,4,0,0,0,4,4,4,4,4,4,2
2,4,18,0,0,18,4,0,0,0,4,0,0,0,4,0,0,0,4,23,18,0,0,4,2
2,4,22,0,0,21,4,0,0,0,4,22,0,21,4,0,0,0,4,22,0,0,21,4,2
2,4,23,0,0,24,4,0,0,0,4,0,0,0,4,0,0,0,4,23,0,0,24,4,2
2,4,0,0,0,0,4,4,4,4,4,22,0,21,4,4,4,4,4,23,0,0,24,4,2
2,4,22,0,0,21,4,4,4,4,4,0,0,0,4,4,4,4,4,22,0,0,21,4,2
2,4,0,15,0,15,4,4,4,4,4,22,20,21,4,4,4,4,4,15,15,15,24,4,2
2,4,4,4,4,4,4,0,18,24,4,4,4,4,4,0,18,0,4,4,4,4,4,4,2
2,4,23,0,0,18,18,0,0,0,0,0,4,27,0,0,0,0,0,18,0,0,18,4,2
2,4,0,0,0,0,0,0,0,0,0,24,4,0,0,0,0,0,0,0,0,0,0,4,2
2,4,23,0,0,0,0,0,0,0,0,0,4,0,0,0,0,0,0,0,0,0,24,4,2
2,4,0,0,0,0,0,0,0,0,0,24,4,23,0,0,0,0,0,0,0,0,0,4,2
1,2,4,23,0,0,0,0,0,0,0,0,4,23,0,0,0,0,0,0,0,0,4,2,1
1,2,4,4,0,25,15,25,0,25,0,25,4,25,0,25,0,25,15,25,24,4,4,2,1
1,1,2,2,4,4,4,4,4,4,4,4,4,4,4,4,4,4,4,4,4,2,2,1,1
1,1,1,1,2,2,2,2,2,2,2,2,2,2,2,2,2,2,2,2,2,1,1,1,1
endlayer

layer
1,1,1,1,1,2,2,2,2,2,2,2,2,2,2,2,2,2,2,2,1,1,1,1,1
1,1,1,2,2,4,4,4,4,4,4,4,4,4,4,4,4,4,4,4,2,2,1,1,1
1,1,2,4,4,4,4,4,4,4,4,4,4,4,4,4,4,4,4,4,4,4,2,1,1
1,2,4,4,4,4,4,4,4,4,4,14,14,14,4,4,4,4,4,4,4,4,4,2,1
1,2,4,4,4,4,4,4,4,4,4,0,0,0,4,4,4,4,4,4,4,4,4,2,1
2,4,4,4,4,4,4,4,4,4,4,23,0,24,4,4,4,4,4,4,4,4,4,4,2
2,4,4,4,4,4,4,0,0,0,4,0,0,0,4,0,0,0,4,4,4,4,4,4,2
2,4,4,4,4,4,4,15,15,15,4,0,0,0,4,15,15,15,4,4,4,4,4,4,2
2,4,4,4,4,4,4,4,4,4,4,0,0,0,4,4,4,4,4,4,4,4,4,4,2
2,4,4,4,4,4,4,4,4,4,4,5,5,5,4,4,4,4,4,4,4,4,4,4,2
2,4,4,4,4,4,4,4,4,4,4,4,4,4,4,4,4,4,4,4,4,4,4,4,2
2,4,4,4,4,4,4,4,4,4,4,4,4,4,4,4,4,4,4,4,4,4,4,4,2
2,4,4,4,4,4,4,4,4,4,4,4,4,4,4,4,4,4,4,4,4,4,4,4,2
2,4,4,4,4,4,4,4,4,4,4,4,4,4,4,4,4,4,4,4,4,4,4,4,2
2,4,4,4,4,4,4,4,4,4,4,4,4,4,4,4,4,4,4,4,4,4,4,4,2
2,4,4,4,4,4,4,4,4,4,4,4,20,4,4,4,4,4,4,4,4,4,4,4,2
2,4,4,4,4,4,4,4,4,4,4,4,4,4,4,4,4,4,4,4,4,4,4,4,2
2,4,4,4,4,4,4,4,4,4,4,4,4,4,4,4,4,4,4,4,4,4,4,4,2
2,4,4,4,4,4,4,4,4,4,4,4,4,4,4,4,4,4,4,4,4,4,4,4,2
2,4,4,4,4,4,4,4,4,4,4,4,4,4,4,4,4,4,4,4,4,4,4,4,2
1,2,4,4,4,4,4,4,4,4,4,4,4,4,4,4,4,4,4,4,4,4,4,2,1
1,2,4,4,4,4,4,4,4,4,4,4,4,4,4,4,4,4,4,4,4,4,4,2,1
1,1,2,4,4,4,4,4,4,4,4,4,4,4,4,4,4,4,4,4,4,4,2,1,1
1,1,1,2,2,4,4,4,4,4,4,4,4,4,4,4,4,4,4,4,2,2,1,1,1
1,1,1,1,1,2,2,2,2,2,2,2,2,2,2,2,2,2,2,2,1,1,1,1,1
endlayer

layer
1,1,1,1,1,1,2,2,2,2,2,2,2,2,2,2,2,2,2,1,1,1,1,1,1
1,1,1,1,2,2,3,3,3,3,3,3,3,3,3,3,3,3,3,2,2,1,1,1,1
1,1,1,2,3,3,3,4,4,4,4,4,4,4,4,4,4,3,3,3,3,2,1,1,1
1,1,2,3,3,3,4,4,4,4,4,4,4,4,4,4,4,4,4,3,3,3,2,1,1
1,2,3,3,3,4,4,0,0,0,4,14,14,14,4,0,0,0,4,4,3,3,3,2,1
1,2,3,3,4,4,4,0,0,0,4,0,0,0,4,0,0,0,4,4,4,3,3,2,1
2,3,3,4,4,4,4,0,0,0,4,23,0,24,4,0,0,0,4,4,4,4,3,3,2
2,3,3,4,4,4,4,0,0,0,4,0,0,0,4,0,0,24,4,4,4,4,3,3,2
2,3,4,0,0,4,0,0,0,0,4,0,0,0,4,0,0,0,0,4,0,0,4,3,2
2,3,4,0,0,4,7,0,0,0,4,0,0,0,4,0,0,0,6,4,0,0,4,3,2
2,3,4,0,0,4,0,0,0,0,0,0,0,0,4,0,0,0,0,4,0,0,4,3,2
2,3,4,0,0,4,7,0,0,0,0,0,0,0,4,0,0,0,6,4,0,0,4,3,2
2,3,4,0,0,4,0,0,0,0,0,0,0,0,4,0,0,0,0,4,0,0,4,3,2
2,3,4,0,0,4,7,0,0,0,4,4,4,4,4,0,0,0,6,4,0,0,4,3,2
2,3,4,0,0,4,0,0,0,0,4,4,4,4,4,0,0,0,0,4,0,0,4,3,2
2,3,4,4,4,4,4,0,0,4,4,12,12,12,4,4,0,0,4,4,4,4,4,3,2
2,3,4,4,4,4,0,0,0,0,4,4,4,4,4,0,0,0,0,4,4,4,4,3,2
2,3,3,4,12,4,0,0,0,0,0,0,0,0,0,0,0,0,0,4,12,4,3,3,2
2,3,3,4,12,4,0,0,0,0,0,0,0,0,0,0,0,0,0,4,12,4,3,3,2
1,2,3,4,12,4,0,0,0,0,0,0,0,0,0,0,0,0,0,4,12,4,3,2,1
1,2,3,3,4,4,0,0,0,0,4,5,5,5,4,0,0,0,0,4,4,3,3,2,1
1,1,2,3,3,3,4,5,5,4,4,4,4,4,4,4,5,5,4,3,3,3,2,1,1
1,1,1,2,3,3,3,3,3,4,4,4,4,4,4,4,3,3,3,3,3,2,1,1,1
1,1,1,1,2,2,3,3,3,3,4,4,4,4,4,3,3,3,3,2,2,1,1,1,1
1,1,1,1,1,1,2,2,2,2,2,2,2,2,2,2,2,2,2,1,1,1,1,1,1
endlayer

layer
1,1,1,1,1,1,1,2,2,2,2,2,2,2,2,2,2,2,1,1,1,1,1,1,1
1,1,1,1,1,2,2,3,3,3,3,3,3,3,3,3,3,3,2,2,1,1,1,1,1
1,1,1,1,2,3,3,4,4,4,4,4,4,4,4,4,4,4,3,3,2,1,1,1,1
1,1,1,2,3,3,4,7,11,6,4,4,4,4,4,7,11,6,4,3,3,2,1,1,1
1,1,2,3,3,4,4,0,0,0,4,4,28,4,4,0,0,0,4,4,3,3,2,1,1
1,2,3,3,4,4,7,0,0,0,6,14,14,14,7,0,0,0,6,4,4,3,3,2,1
1,2,3,4,4,4,4,0,0,0,4,0,0,24,16,0,15,0,4,4,4,4,3,2,1
2,3,3,4,4,4,4,0,0,0,4,23,0,0,4,0,0,0,4,4,4,4,3,3,2
2,3,4,0,0,0,0,0,0,0,4,0,0,24,16,0,0,0,0,0,0,0,4,3,2
2,3,4,0,0,4,0,0,0,0,4,0,0,0,4,0,0,0,0,4,0,0,4,3,2
2,3,4,0,0,0,0,0,0,0,0,0,0,0,16,0,0,0,0,0,0,0,4,3,2
2,28,4,0,0,4,0,0,0,0,0,0,0,0,4,0,0,0,0,4,0,0,4,3,2
2,3,4,0,0,0,0,0,0,0,0,0,0,0,16,0,0,0,0,0,0,0,4,3,2
2,3,4,0,0,4,0,0,0,0,4,4,4,4,4,0,0,0,0,4,0,0,4,3,2
2,3,4,0,0,0,0,0,0,0,4,4,11,4,16,0,0,0,0,0,0,0,4,3,2
2,3,4,4,4,4,4,0,0,4,4,0,29,0,4,4,0,0,4,4,4,4,4,3,2
2,3,4,4,4,13,0,0,0,0,4,0,0,0,4,0,0,0,0,13,4,4,4,3,2
2,3,3,4,0,0,0,0,0,0,0,0,0,0,0,0,0,0,0,0,0,4,3,3,2
1,2,4,12,19,0,0,0,0,0,0,0,0,0,0,0,0,0,0,0,19,12,4,2,1
1,2,3,4,0,0,0,0,0,0,0,0,0,0,0,0,0,0,0,0,0,4,3,2,1
1,1,2,3,4,5,0,0,0,0,4,0,0,0,4,0,0,0,0,5,4,3,2,1,1
1,1,1,2,3,3,4,7,6,4,4,5,5,5,4,4,7,6,4,3,3,2,1,1,1
1,1,1,1,2,3,3,4,4,3,4,4,4,4,4,3,4,4,3,3,2,1,1,1,1
1,1,1,1,1,2,2,3,3,3,4,4,4,4,4,3,3,3,2,2,1,1,1,1,1
1,1,1,1,1,1,1,2,2,2,2,2,2,2,2,2,2,2,1,1,1,1,1,1,1
endlayer

layer
1,1,1,1,1,1,1,1,1,2,2,2,2,2,2,2,1,1,1,1,1,1,1,1,1
1,1,1,1,1,1,2,2,2,3,3,3,3,3,3,3,2,2,2,1,1,1,1,1,1
1,1,1,1,1,2,3,4,4,4,4,4,4,4,4,4,4,4,3,2,1,1,1,1,1
1,1,1,1,2,3,4,22,0,21,4,4,4,4,4,22,0,21,4,3,2,1,1,1,1
1,1,1,2,3,4,4,0,0,24,4,4,4,4,4,0,0,0,4,4,3,2,1,1,1
1,1,2,3,4,4,22,0,0,0,21,4,4,4,22,0,0,0,21,4,4,3,2,1,1
1,2,3,4,4,4,4,15,0,0,4,14,14,14,4,23,15,0,4,4,4,4,3,2,1
1,2,3,4,4,4,4,22,0,21,4,0,0,0,16,22,0,21,4,4,4,4,3,2,1
1,2,4,0,0,22,0,0,0,0,4,0,0,0,4,0,0,0,0,21,0,0,4,2,1
2,3,4,0,0,4,0,0,0,0,4,0,0,0,16,0,0,0,0,4,0,0,4,3,2
2,3,4,0,0,22,0,0,0,0,14,0,0,0,4,0,0,0,0,21,0,0,4,3,2
2,3,4,0,0,4,0,0,0,0,0,0,0,0,16,0,0,0,0,4,0,0,4,28,2
2,3,4,0,0,22,0,0,0,0,25,0,0,24,4,0,0,0,0,21,0,0,4,3,2
2,3,4,0,0,4,0,0,0,24,4,4,4,4,16,0,0,0,0,4,0,0,4,3,2
2,3,4,0,0,22,0,0,0,0,4,4,12,4,4,0,0,0,0,21,0,0,4,3,2
2,3,4,4,4,4,4,22,21,4,7,0,19,0,6,4,22,21,4,4,4,4,4,3,2
1,2,4,4,4,14,0,0,0,0,4,0,0,0,4,0,0,0,0,14,4,4,4,2,1
1,2,3,16,0,0,0,0,0,0,14,0,0,0,14,0,0,0,0,0,0,16,3,2,1
1,2,3,4,0,0,0,0,0,0,0,0,0,0,0,0,0,0,0,0,0,4,3,2,1
1,1,2,16,0,0,0,0,0,0,25,0,0,0,25,0,0,0,0,0,0,16,2,1,1
1,1,1,2,4,25,0,0,0,0,4,0,0,0,4,15,0,0,0,25,4,2,1,1,1
1,1,1,1,2,3,4,22,21,4,4,0,0,0,4,4,22,21,4,3,2,1,1,1,1
1,1,1,1,1,2,3,4,4,3,4,5,5,5,4,3,4,4,3,2,1,1,1,1,1
1,1,1,1,1,1,2,2,2,3,4,4,4,4,4,3,2,2,2,1,1,1,1,1,1
1,1,1,1,1,1,1,1,1,2,4,4,4,4,4,2,1,1,1,1,1,1,1,1,1
endlayer

layer
1,1,1,1,1,1,1,1,1,1,1,1,1,1,1,1,1,1,1,1,1,1,1,1,1
1,1,1,1,1,1,1,1,2,2,2,2,2,2,2,2,2,1,1,1,1,1,1,1,1
1,1,1,1,1,1,2,2,4,4,4,4,4,4,4,4,4,2,2,1,1,1,1,1,1
1,1,1,1,1,2,4,4,14,4,4,4,4,4,4,4,14,4,4,2,1,1,1,1,1
1,1,1,1,2,4,4,23,0,18,4,4,4,4,4,23,0,24,4,4,2,1,1,1,1
1,1,1,2,4,4,4,0,0,24,4,4,4,4,4,0,0,0,4,4,4,2,1,1,1
1,1,2,4,4,4,4,15,0,0,4,4,4,4,4,0,15,15,4,4,4,4,2,1,1
1,1,2,4,4,4,4,4,4,4,4,14,14,14,4,4,4,4,4,4,4,4,2,1,1
1,2,4,0,0,4,18,0,0,0,4,0,0,0,4,0,0,0,0,4,0,0,4,2,1
1,2,4,0,0,4,22,0,0,0,4,0,0,0,4,23,0,0,21,4,0,0,4,2,1
1,2,4,0,0,4,0,0,0,0,4,0,0,0,4,0,0,0,24,4,0,0,4,2,1
1,2,4,0,0,4,22,0,0,0,4,0,0,0,4,0,0,0,21,4,0,0,4,2,1
1,2,4,0,0,4,0,0,0,0,4,0,0,24,4,0,0,0,0,4,0,0,4,2,1
1,2,4,0,0,4,22,0,0,0,4,4,4,4,4,23,0,0,21,4,0,0,4,2,1
1,2,4,0,0,4,0,15,0,0,4,16,4,16,4,23,0,0,15,4,0,0,4,2,1
1,2,4,4,4,4,4,4,4,4,22,0,0,0,21,4,4,4,4,4,4,4,4,2,1
1,2,4,4,4,4,18,0,0,18,4,0,0,0,4,0,0,0,24,4,4,4,4,2,1
1,1,2,4,4,0,0,0,0,0,4,0,0,24,4,0,0,0,0,24,4,4,2,1,1
1,1,2,4,4,23,0,0,0,0,4,0,0,0,4,23,0,0,0,0,4,4,2,1,1
1,1,1,2,4,0,0,0,0,0,4,23,0,0,4,0,0,0,0,0,4,2,1,1,1
1,1,1,1,2,4,0,0,0,0,4,23,0,0,4,15,0,0,15,4,2,1,1,1,1
1,1,1,1,1,2,4,25,25,4,4,0,0,0,4,4,25,25,4,2,1,1,1,1,1
1,1,1,1,1,1,2,2,3,3,4,0,0,0,4,3,3,2,2,1,1,1,1,1,1
1,1,1,1,1,1,1,1,2,2,4,0,0,0,4,2,2,1,1,1,1,1,1,1,1
1,1,1,1,1,1,1,1,1,1,13,0,0,0,13,1,1,1,1,1,1,1,1,1,1
endlayer

layer
1,1,1,1,1,1,1,1,1,1,1,1,1,1,1,1,1,1,1,1,1,1,1,1,1
1,1,1,1,1,1,1,1,1,1,1,1,1,1,1,1,1,1,1,1,1,1,1,1,1
1,1,1,1,1,1,1,1,2,2,2,2,2,2,2,2,2,1,1,1,1,1,1,1,1
1,1,1,1,1,1,2,2,2,4,4,4,4,4,4,4,2,2,2,1,1,1,1,1,1
1,1,1,1,1,2,2,4,4,4,4,4,4,4,4,4,4,4,2,2,1,1,1,1,1
1,1,1,1,2,2,4,4,4,4,4,4,4,4,4,4,4,4,4,2,2,1,1,1,1
1,1,1,2,2,4,4,4,4,4,4,4,4,4,4,4,4,4,4,4,2,2,1,1,1
1,1,1,2,4,4,4,4,4,4,4,4,4,4,4,4,4,4,4,4,4,2,1,1,1
1,1,2,2,4,4,4,4,4,4,4,4,4,4,4,4,4,4,4,4,4,2,2,1,1
1,1,2,4,4,4,4,4,4,4,4,4,4,4,4,4,4,4,4,4,4,4,2,1,1
1,1,2,4,4,4,4,4,4,4,4,4,4,4,4,4,4,4,4,4,4,4,2,1,1
1,1,2,4,4,4,4,4,4,4,4,4,4,4,4,4,4,4,4,4,4,4,2,1,1
1,1,2,4,4,4,4,4,4,4,4,4,4,4,4,4,4,4,4,4,4,4,2,1,1
1,1,2,4,4,4,4,4,4,4,4,4,4,4,4,4,4,4,4,4,4,4,2,1,1
1,1,2,4,4,4,4,4,4,4,4,4,4,4,4,4,4,4,4,4,4,4,2,1,1
1,1,2,4,4,4,4,4,4,4,4,4,4,4,4,4,4,4,4,4,4,4,2,1,1
1,1,2,2,4,4,4,4,4,4,4,23,0,24,4,4,4,4,4,4,4,2,2,1,1
1,1,1,2,4,4,4,4,4,4,4,25,25,25,4,4,4,4,4,4,4,2,1,1,1
1,1,1,2,2,4,4,4,4,4,4,4,4,4,4,4,4,4,4,4,2,2,1,1,1
1,1,1,1,2,2,4,4,4,4,4,14,14,14,4,4,4,4,4,2,2,1,1,1,1
1,1,1,1,1,2,2,4,4,4,4,0,0,24,4,4,4,4,2,2,1,1,1,1,1
1,1,1,1,1,1,2,2,2,4,4,0,0,0,4,4,2,2,2,1,1,1,1,1,1
1,1,1,1,1,1,1,1,2,2,4,0,0,0,4,2,2,1,1,1,1,1,1,1,1
1,1,1,1,1,1,1,1,1,1,4,0,0,0,4,1,1,1,1,1,1,1,1,1,1
1,1,1,1,1,1,1,1,1,1,0,0,0,0,0,1,1,1,1,1,1,1,1,1,1
endlayer

layer
1,1,1,1,1,1,1,1,1,1,1,1,1,1,1,1,1,1,1,1,1,1,1,1,1
1,1,1,1,1,1,1,1,1,1,1,1,1,1,1,1,1,1,1,1,1,1,1,1,1
1,1,1,1,1,1,1,1,1,1,1,1,1,1,1,1,1,1,1,1,1,1,1,1,1
1,1,1,1,1,1,1,1,1,2,2,2,2,2,2,2,1,1,1,1,1,1,1,1,1
1,1,1,1,1,1,1,2,2,2,3,3,3,3,3,2,2,2,1,1,1,1,1,1,1
1,1,1,1,1,1,2,2,3,3,3,3,3,3,3,3,3,2,2,1,1,1,1,1,1
1,1,1,1,1,2,2,3,3,3,3,3,3,3,3,3,3,3,2,2,1,1,1,1,1
1,1,1,1,2,2,3,3,3,3,3,3,3,3,3,3,3,3,3,2,2,1,1,1,1
1,1,1,1,2,3,3,3,3,3,3,3,3,3,3,3,3,3,3,3,2,1,1,1,1
1,1,1,2,2,3,3,3,3,3,3,3,3,3,3,3,3,3,3,3,2,2,1,1,1
1,1,1,2,3,3,3,3,3,3,3,3,3,3,3,3,3,3,3,3,3,2,1,1,1
1,1,1,2,3,3,3,3,3,3,3,3,3,3,3,3,3,3,3,3,3,2,1,1,1
1,1,1,2,3,3,3,3,3,3,3,3,3,3,3,3,3,3,3,3,3,2,1,1,1
1,1,1,2,3,3,3,3,3,3,3,3,3,3,3,3,3,3,3,3,3,2,1,1,1
1,1,1,2,3,3,3,3,3,3,3,3,3,3,3,3,3,3,3,3,3,2,1,1,1
1,1,1,2,2,3,3,3,3,3,3,3,3,3,3,3,3,3,3,3,2,2,1,1,1
1,1,1,1,2,3,3,3,3,3,3,4,4,4,3,3,3,3,3,3,2,1,1,1,1
1,1,1,1,2,2,3,3,3,3,3,3,3,3,3,3,3,3,3,2,2,1,1,1,1
1,1,1,1,1,2,2,3,3,3,4,4,4,4,4,3,3,3,2,2,1,1,1,1,1
1,1,1,1,1,1,2,2,3,3,4,4,4,4,4,3,3,2,2,1,1,1,1,1,1
1,1,1,1,1,1,1,2,2,2,4,14,14,14,4,2,2,2,1,1,1,1,1,1,1
1,1,1,1,1,1,1,1,1,2,4,22,0,21,4,2,1,1,1,1,1,1,1,1,1
1,1,1,1,1,1,1,1,1,1,4,22,0,21,4,1,1,1,1,1,1,1,1,1,1
1,1,1,1,1,1,1,1,1,1,4,22,0,21,4,1,1,1,1,1,1,1,1,1,1
1,1,1,1,1,1,1,1,1,1,0,0,0,0,0,1,1,1,1,1,1,1,1,1,1
endlayer

layer
1,1,1,1,1,1,1,1,1,1,1,1,1,1,1,1,1,1,1,1,1,1,1,1,1
1,1,1,1,1,1,1,1,1,1,1,1,1,1,1,1,1,1,1,1,1,1,1,1,1
1,1,1,1,1,1,1,1,1,1,1,1,1,1,1,1,1,1,1,1,1,1,1,1,1
1,1,1,1,1,1,1,1,1,1,1,1,1,1,1,1,1,1,1,1,1,1,1,1,1
1,1,1,1,1,1,1,1,1,1,2,2,2,2,2,1,1,1,1,1,1,1,1,1,1
1,1,1,1,1,1,1,1,2,2,2,2,2,2,2,2,2,1,1,1,1,1,1,1,1
1,1,1,1,1,1,1,2,2,2,3,3,3,3,3,2,2,2,1,1,1,1,1,1,1
1,1,1,1,1,1,2,2,3,3,3,3,3,3,3,3,3,2,2,1,1,1,1,1,1
1,1,1,1,1,2,2,3,3,3,3,3,3,3,3,3,3,3,2,2,1,1,1,1,1
1,1,1,1,1,2,2,3,3,3,3,3,3,3,3,3,3,3,2,2,1,1,1,1,1
1,1,1,1,2,2,3,3,3,3,3,3,3,3,3,3,3,3,3,2,2,1,1,1,1
1,1,1,1,2,2,3,3,3,3,3,3,3,3,3,3,3,3,3,2,2,1,1,1,1
1,1,1,1,2,2,3,3,3,3,3,3,3,3,3,3,3,3,3,2,2,1,1,1,1
1,1,1,1,2,2,3,3,3,3,3,3,3,3,3,3,3,3,3,2,2,1,1,1,1
1,1,1,1,2,2,3,3,3,3,3,3,3,3,3,3,3,3,3,2,2,1,1,1,1
1,1,1,1,1,2,2,3,3,3,3,3,3,3,3,3,3,3,2,2,1,1,1,1,1
1,1,1,1,1,2,2,3,3,3,3,3,3,3,3,3,3,3,2,2,1,1,1,1,1
1,1,1,1,1,1,2,2,3,3,3,3,3,3,3,3,3,2,2,1,1,1,1,1,1
1,1,1,1,1,1,1,2,2,2,3,3,3,3,3,2,2,2,1,1,1,1,1,1,1
1,1,1,1,1,1,1,1,2,2,2,4,2,2,2,2,2,1,1,1,1,1,1,1,1
1,1,1,1,1,1,1,1,1,1,2,4,4,4,2,1,1,1,1,1,1,1,1,1,1
1,1,1,1,1,1,1,1,1,1,6,4,4,4,7,1,1,1,1,1,1,1,1,1,1
1,1,1,1,1,1,1,1,1,1,6,4,4,4,7,1,1,1,1,1,1,1,1,1,1
1,1,1,1,1,1,1,1,1,1,6,4,16,4,7,1,1,1,1,1,1,1,1,1,1
1,1,1,1,1,1,1,1,1,1,1,0,0,0,1,1,1,1,1,1,1,1,1,1,1
endlayer

layer
1,1,1,1,1,1,1,1,1,1,1,1,1,1,1,1,1,1,1,1,1,1,1,1,1
1,1,1,1,1,1,1,1,1,1,1,1,1,1,1,1,1,1,1,1,1,1,1,1,1
1,1,1,1,1,1,1,1,1,1,1,1,1,1,1,1,1,1,1,1,1,1,1,1,1
1,1,1,1,1,1,1,1,1,1,1,1,1,1,1,1,1,1,1,1,1,1,1,1,1
1,1,1,1,1,1,1,1,1,1,1,1,1,1,1,1,1,1,1,1,1,1,1,1,1
1,1,1,1,1,1,1,1,1,1,1,1,1,1,1,1,1,1,1,1,1,1,1,1,1
1,1,1,1,1,1,1,1,1,1,2,2,2,2,2,1,1,1,1,1,1,1,1,1,1
1,1,1,1,1,1,1,1,2,2,2,2,2,2,2,2,2,1,1,1,1,1,1,1,1
1,1,1,1,1,1,1,2,2,2,2,2,2,2,2,2,2,2,1,1,1,1,1,1,1
1,1,1,1,1,1,1,2,2,2,3,3,3,3,3,2,2,2,1,1,1,1,1,1,1
1,1,1,1,1,1,2,2,2,3,3,3,3,3,3,3,2,2,2,1,1,1,1,1,1
1,1,1,1,1,1,2,2,2,3,3,3,3,3,3,3,2,2,2,1,1,1,1,1,1
1,1,1,1,1,1,2,2,2,3,3,3,3,3,3,3,2,2,2,1,1,1,1,1,1
1,1,1,1,1,1,2,2,2,3,3,3,3,3,3,3,2,2,2,1,1,1,1,1,1
1,1,1,1,1,1,2,2,2,3,3,3,3,3,3,3,2,2,2,1,1,1,1,1,1
1,1,1,1,1,1,1,2,2,2,3,3,3,3,3,2,2,2,1,1,1,1,1,1,1
1,1,1,1,1,1,1,2,2,2,2,2,2,2,2,2,2,2,1,1,1,1,1,1,1
1,1,1,1,1,1,1,1,2,2,2,2,2,2,2,2,2,1,1,1,1,1,1,1,1
1,1,1,1,1,1,1,1,1,1,2,2,2,2,2,1,1,1,1,1,1,1,1,1,1
1,1,1,1,1,1,1,1,1,1,1,6,4,7,1,1,1,1,1,1,1,1,1,1,1
1,1,1,1,1,1,1,1,1,1,1,6,4,7,1,1,1,1,1,1,1,1,1,1,1
1,1,1,1,1,1,1,1,1,1,1,6,4,7,1,1,1,1,1,1,1,1,1,1,1
1,1,1,1,1,1,1,1,1,1,1,6,4,7,1,1,1,1,1,1,1,1,1,1,1
1,1,1,1,1,1,1,1,1,1,1,6,4,7,1,1,1,1,1,1,1,1,1,1,1
1,1,1,1,1,1,1,1,1,1,1,1,0,1,1,1,1,1,1,1,1,1,1,1,1
endlayer

layer
1,1,1,1,1,1,1,1,1,1,1,1,1,1,1,1,1,1,1,1,1,1,1,1,1
1,1,1,1,1,1,1,1,1,1,1,1,1,1,1,1,1,1,1,1,1,1,1,1,1
1,1,1,1,1,1,1,1,1,1,1,1,1,1,1,1,1,1,1,1,1,1,1,1,1
1,1,1,1,1,1,1,1,1,1,1,1,1,1,1,1,1,1,1,1,1,1,1,1,1
1,1,1,1,1,1,1,1,1,1,1,1,1,1,1,1,1,1,1,1,1,1,1,1,1
1,1,1,1,1,1,1,1,1,1,1,1,1,1,1,1,1,1,1,1,1,1,1,1,1
1,1,1,1,1,1,1,1,1,1,1,1,1,1,1,1,1,1,1,1,1,1,1,1,1
1,1,1,1,1,1,1,1,1,1,1,1,1,1,1,1,1,1,1,1,1,1,1,1,1
1,1,1,1,1,1,1,1,1,1,1,1,1,1,1,1,1,1,1,1,1,1,1,1,1
1,1,1,1,1,1,1,1,1,1,2,2,2,2,2,1,1,1,1,1,1,1,1,1,1
1,1,1,1,1,1,1,1,1,2,2,2,2,2,2,2,1,1,1,1,1,1,1,1,1
1,1,1,1,1,1,1,1,1,2,2,2,2,2,2,2,1,1,1,1,1,1,1,1,1
1,1,1,1,1,1,1,1,1,2,2,2,2,2,2,2,1,1,1,1,1,1,1,1,1
1,1,1,1,1,1,1,1,1,2,2,2,2,2,2,2,1,1,1,1,1,1,1,1,1
1,1,1,1,1,1,1,1,1,2,2,2,2,2,2,2,1,1,1,1,1,1,1,1,1
1,1,1,1,1,1,1,1,1,1,2,2,2,2,2,1,1,1,1,1,1,1,1,1,1
1,1,1,1,1,1,1,1,1,1,1,1,1,1,1,1,1,1,1,1,1,1,1,1,1
1,1,1,1,1,1,1,1,1,1,1,1,1,1,1,1,1,1,1,1,1,1,1,1,1
1,1,1,1,1,1,1,1,1,1,1,1,1,1,1,1,1,1,1,1,1,1,1,1,1
1,1,1,1,1,1,1,1,1,1,1,1,1,1,1,1,1,1,1,1,1,1,1,1,1
1,1,1,1,1,1,1,1,1,1,1,1,1,1,1,1,1,1,1,1,1,1,1,1,1
1,1,1,1,1,1,1,1,1,1,1,1,1,1,1,1,1,1,1,1,1,1,1,1,1
1,1,1,1,1,1,1,1,1,1,1,1,1,1,1,1,1,1,1,1,1,1,1,1,1
1,1,1,1,1,1,1,1,1,1,1,1,1,1,1,1,1,1,1,1,1,1,1,1,1
1,1,1,1,1,1,1,1,1,1,1,1,1,1,1,1,1,1,1,1,1,1,1,1,1
endlayer

