# Gilly's Tower

# template generated with Ruins mod version 16.5 Ingame Parser
# Structure created and developed by Gilly

weight=1
embed_into_distance=5
uniqueMinDistance=500
acceptable_target_blocks=
unacceptable_target_blocks=flowing_water,water,flowing_lava,lava,ice,bedrock,netherrack,nether_brick,nether_brick_fence,soul_sand,quartz_ore,gravel,end_stone,obsidian,iron_bars,cloud,flesh,ash_block,slime_grass,slime_congealed,slime_dirt
biomesToSpawnIn=meadow,forest,taiga,woodland,woodlands,fen,brushland,shrubland,chaparral,badlands,birch forest,jungle,mini jungle,autumnal forest,rocky plateau,roofed forest
dimensions=27,9,9
allowable_overhang=0
max_leveling=5
leveling_buffer=-1
preserve_water=0
preserve_lava=0

rule1=0,100,stonebrick,stonebrick,stonebrick,stonebrick,stonebrick,stonebrick-2,stonebrick-2,stonebrick-1
rule2=0,100,minecraft:stone_brick_stairs-0
rule3=0,100,minecraft:stone_brick_stairs-4
rule4=0,100,minecraft:stone_brick_stairs-2
rule5=0,100,minecraft:stone_brick_stairs-3
rule6=0,100,minecraft:stone_brick_stairs-6
rule7=0,100,minecraft:stone_brick_stairs-7
rule8=0,100,minecraft:stone_brick_stairs-1
rule9=0,100,minecraft:stone_brick_stairs-5
rule10=0,100,preserveBlock
rule11=0,100,minecraft:sea_lantern-0
rule12=0,100,minecraft:stone_slab-5
rule13=0,100,minecraft:stone_slab-13
rule14=0,100,minecraft:stained_glass_pane-3
rule15=1,100,minecraft:torch-5
rule16=0,100,minecraft:fence-0

layer
1,1,1,1,1,1,1,1,1
1,1,1,1,1,1,1,1,1
1,1,1,1,1,1,1,1,1
1,1,1,1,1,1,1,1,1
1,1,1,1,1,1,1,1,1
1,1,1,1,1,1,1,1,1
1,1,1,1,1,1,1,1,1
1,1,1,1,1,1,1,1,1
1,1,1,1,1,1,1,1,1
endlayer

layer
1,1,1,1,1,1,1,1,1
1,1,1,1,1,1,1,1,1
1,1,1,1,1,1,1,1,1
1,1,1,1,1,1,1,1,1
1,1,1,1,1,1,1,1,1
1,1,1,1,1,1,1,1,1
1,1,1,1,1,1,1,1,1
1,1,1,1,1,1,1,1,1
1,1,1,1,1,1,1,1,1
endlayer

layer
1,1,1,2,3,2,1,1,1
1,1,1,0,0,0,1,1,1
1,1,1,1,1,1,1,1,1
5,0,1,1,1,1,1,0,4
7,0,1,1,1,1,1,0,6
5,0,1,1,1,1,1,0,4
1,1,1,1,1,1,1,1,1
1,1,1,0,0,0,1,1,1
1,1,1,8,9,8,1,1,1
endlayer

layer
10,5,6,3,2,3,7,4,10
2,1,1,0,11,0,1,1,2
9,1,1,1,1,1,1,1,9
7,0,1,1,1,1,1,0,6
5,11,1,1,1,1,1,11,4
7,0,1,1,1,1,1,0,6
3,1,1,1,1,1,1,1,3
8,1,1,0,11,0,1,1,8
10,5,6,9,8,9,7,4,10
endlayer

layer
10,10,5,1,1,1,4,10,10
10,1,1,1,1,1,1,1,10
2,1,1,12,12,12,1,1,2
1,1,13,14,14,14,13,1,1
1,1,13,0,15,14,13,1,1
1,1,13,14,14,14,13,1,1
8,1,1,12,12,12,1,1,8
10,1,1,1,1,1,1,1,10
10,10,5,1,1,1,4,10,10
endlayer

layer
10,10,10,5,2,4,10,10,10
10,15,2,1,1,1,2,15,10
10,5,1,12,12,12,1,4,10
2,1,13,14,14,14,13,1,2
5,1,13,14,16,14,13,1,4
8,1,13,14,14,14,13,1,8
10,5,1,12,12,12,1,4,10
10,15,8,1,1,1,8,15,10
10,10,10,5,8,4,10,10,10
endlayer

layer
10,10,0,0,0,0,0,10,10
10,0,0,0,0,0,0,0,10
0,0,7,12,12,12,2,0,0
0,0,13,14,14,14,13,0,0
0,0,13,14,15,14,13,0,0
0,0,13,14,14,14,13,0,0
0,0,8,12,12,12,6,0,0
10,0,0,0,0,0,0,0,10
10,10,0,0,0,0,0,10,10
endlayer

layer
10,0,0,0,0,0,0,0,10
0,0,0,0,0,0,0,0,0
0,0,7,12,12,12,2,0,0
0,0,13,14,14,14,13,0,0
0,0,13,14,16,14,13,0,0
0,0,13,14,14,14,13,0,0
0,0,8,12,12,12,6,0,0
0,0,0,0,0,0,0,0,0
10,0,0,0,0,0,0,0,10
endlayer

layer
0,0,0,0,0,0,0,0,0
0,0,0,0,0,0,0,0,0
0,0,7,12,12,12,2,0,0
0,0,13,14,14,14,13,0,0
0,0,13,14,15,14,13,0,0
0,0,13,14,14,14,13,0,0
0,0,8,12,12,12,6,0,0
0,0,0,0,0,0,0,0,0
0,0,0,0,0,0,0,0,0
endlayer

layer
0,0,0,0,0,0,0,0,0
0,0,0,0,0,0,0,0,0
0,0,7,12,12,12,2,0,0
0,0,13,14,14,14,13,0,0
0,0,13,14,16,14,13,0,0
0,0,13,14,14,14,13,0,0
0,0,8,12,12,12,6,0,0
0,0,0,0,0,0,0,0,0
0,0,0,0,0,0,0,0,0
endlayer

layer
0,0,0,0,0,0,0,0,0
0,0,0,0,0,0,0,0,0
0,0,7,12,12,12,2,0,0
0,0,13,14,14,14,13,0,0
0,0,13,14,15,14,13,0,0
0,0,13,14,14,14,13,0,0
0,0,8,12,12,12,6,0,0
0,0,0,0,0,0,0,0,0
0,0,0,0,0,0,0,0,0
endlayer

layer
0,0,0,0,0,0,0,0,0
0,0,0,0,0,0,0,0,0
0,0,7,12,12,12,2,0,0
0,0,13,14,14,14,13,0,0
0,0,13,14,16,14,13,0,0
0,0,13,14,14,14,13,0,0
0,0,8,12,12,12,6,0,0
0,0,0,0,0,0,0,0,0
0,0,0,0,0,0,0,0,0
endlayer

layer
0,0,0,0,0,0,0,0,0
0,0,0,0,0,0,0,0,0
0,0,7,12,12,12,2,0,0
0,0,13,14,14,14,13,0,0
0,0,13,14,15,14,13,0,0
0,0,13,14,14,14,13,0,0
0,0,8,12,12,12,6,0,0
0,0,0,0,0,0,0,0,0
0,0,0,0,0,0,0,0,0
endlayer

layer
0,0,0,0,0,0,0,0,0
0,0,0,0,0,0,0,0,0
0,0,7,12,12,12,2,0,0
0,0,13,14,14,14,13,0,0
0,0,13,14,16,14,13,0,0
0,0,13,14,14,14,13,0,0
0,0,8,12,12,12,6,0,0
0,0,0,0,0,0,0,0,0
0,0,0,0,0,0,0,0,0
endlayer

layer
0,0,0,0,0,0,0,0,0
0,0,0,0,0,0,0,0,0
0,0,7,12,12,12,2,0,0
0,0,13,14,14,14,13,0,0
0,0,13,14,15,14,13,0,0
0,0,13,14,14,14,13,0,0
0,0,8,12,12,12,6,0,0
0,0,0,0,0,0,0,0,0
0,0,0,0,0,0,0,0,0
endlayer

layer
0,0,0,0,0,0,0,0,0
0,0,0,0,0,0,0,0,0
0,0,7,12,12,12,2,0,0
0,0,13,14,14,14,13,0,0
0,0,13,14,16,14,13,0,0
0,0,13,14,14,14,13,0,0
0,0,8,12,12,12,6,0,0
0,0,0,0,0,0,0,0,0
0,0,0,0,0,0,0,0,0
endlayer

layer
0,0,0,0,0,0,0,0,0
0,0,0,0,0,0,0,0,0
0,0,7,12,12,12,2,0,0
0,0,13,14,14,14,13,0,0
0,0,13,14,15,14,13,0,0
0,0,13,14,14,14,13,0,0
0,0,8,12,12,12,6,0,0
0,0,0,0,0,0,0,0,0
0,0,0,0,0,0,0,0,0
endlayer

layer
0,0,0,0,0,0,0,0,0
0,0,0,0,0,0,0,0,0
0,0,7,12,12,12,2,0,0
0,0,13,14,14,14,13,0,0
0,0,13,14,16,14,13,0,0
0,0,13,14,14,14,13,0,0
0,0,8,12,12,12,6,0,0
0,0,0,0,0,0,0,0,0
0,0,0,0,0,0,0,0,0
endlayer

layer
0,0,0,0,0,0,0,0,0
0,0,0,0,0,0,0,0,0
0,0,7,12,12,12,2,0,0
0,0,13,14,14,14,13,0,0
0,0,13,14,15,14,13,0,0
0,0,13,14,14,14,13,0,0
0,0,8,12,12,12,6,0,0
0,0,0,0,0,0,0,0,0
0,0,0,0,0,0,0,0,0
endlayer

layer
0,0,0,0,0,0,0,0,0
0,0,0,0,0,0,0,0,0
0,0,7,12,12,12,2,0,0
0,0,13,14,14,14,13,0,0
0,0,13,14,16,14,13,0,0
0,0,13,14,14,14,13,0,0
0,0,8,12,12,12,6,0,0
0,0,0,0,0,0,0,0,0
0,0,0,0,0,0,0,0,0
endlayer

layer
0,0,0,0,0,0,0,0,0
0,0,0,0,0,0,0,0,0
0,0,7,12,12,12,2,0,0
0,0,13,14,14,14,13,0,0
0,0,13,14,15,14,13,0,0
0,0,13,14,14,14,13,0,0
0,0,8,12,12,12,6,0,0
0,0,0,0,0,0,0,0,0
0,0,0,0,0,0,0,0,0
endlayer

layer
0,0,0,0,0,0,0,0,0
0,0,0,0,0,0,0,0,0
0,0,7,12,12,12,2,0,0
0,0,13,14,14,14,13,0,0
0,0,13,14,16,14,13,0,0
0,0,13,14,14,14,13,0,0
0,0,8,12,12,12,6,0,0
0,0,0,0,0,0,0,0,0
0,0,0,0,0,0,0,0,0
endlayer

layer
0,0,0,0,0,0,0,0,0
0,0,0,0,0,0,0,0,0
0,0,7,12,12,12,2,0,0
0,0,13,14,14,14,13,0,0
0,0,13,14,15,14,13,0,0
0,0,13,14,14,14,13,0,0
0,0,8,12,12,12,6,0,0
0,0,0,0,0,0,0,0,0
0,0,0,0,0,0,0,0,0
endlayer

layer
0,0,0,0,0,0,0,0,0
0,0,0,0,0,0,0,0,0
0,0,7,12,12,12,2,0,0
0,0,13,14,14,14,13,0,0
0,0,13,14,16,14,13,0,0
0,0,13,14,14,14,13,0,0
0,0,8,12,12,12,6,0,0
0,0,0,0,0,0,0,0,0
0,0,0,0,0,0,0,0,0
endlayer

layer
0,0,0,0,0,0,0,0,0
0,0,0,0,0,0,0,0,0
0,0,7,12,12,12,2,0,0
0,0,13,14,14,14,13,0,0
0,0,13,14,15,14,13,0,0
0,0,13,14,14,14,13,0,0
0,0,8,12,12,12,6,0,0
0,0,0,0,0,0,0,0,0
0,0,0,0,0,0,0,0,0
endlayer

layer
0,0,0,0,0,0,0,0,0
0,0,0,0,0,0,0,0,0
0,0,7,1,1,1,2,0,0
0,0,13,14,14,14,13,0,0
0,0,13,14,0,14,13,0,0
0,0,13,14,14,14,13,0,0
0,0,8,1,1,1,6,0,0
0,0,0,0,0,0,0,0,0
0,0,0,0,0,0,0,0,0
endlayer

layer
0,0,0,0,0,0,0,0,0
0,0,0,0,0,0,0,0,0
0,0,0,0,0,0,0,0,0
0,0,0,12,12,12,0,0,0
0,0,0,12,0,12,0,0,0
0,0,0,12,12,12,0,0,0
0,0,0,0,0,0,0,0,0
0,0,0,0,0,0,0,0,0
0,0,0,0,0,0,0,0,0
endlayer

