
# Created by Ruins mod version 16.7 Ingame Parser
# authoring Player: lafuller

weight=1
embed_into_distance=5
acceptable_target_blocks=
unacceptable_target_blocks=flowing_lava,lava,ice,bedrock,netherrack,nether_brick,nether_brick_fence,soul_sand,quartz_ore,end_stone,obsidian,iron_bars,cloud,flesh,ash_block,slime_grass,slime_congealed,slime_dirt
dimensions=30,19,19
allowable_overhang=0
max_leveling=5
leveling_buffer=-1
preserve_water=0
preserve_lava=0
preventRotation=1

rule1=0,100,preserveBlock
rule2=0,100,stonebrick-0,stonebrick-1,stonebrick-1,stonebrick-1,stonebrick-2,stonebrick-2,stone-5,stone-5,stone-6,cobblestone,cobblestone
rule3=0,100,minecraft:stone_slab-13
rule4=0,100,minecraft:stone_brick_stairs-1
rule5=0,100,minecraft:stone_slab-5
rule6=0,100,minecraft:cobblestone_wall-0
rule7=0,100,minecraft:stone_brick_stairs-0
rule8=0,100,minecraft:stone_brick_stairs-2
rule9=0,100,minecraft:stone_brick_stairs-3
rule10=0,100,minecraft:iron_bars-0
rule11=0,100,minecraft:stone_brick_stairs-4
rule12=0,100,minecraft:stone_brick_stairs-5
rule13=0,100,minecraft:stone_brick_stairs-6
rule14=0,100,minecraft:stone_brick_stairs-7
rule15=0,100,CommandBlock:RUINSTRIGGER /testruin Gilly/GillyAztecCatacombCenter ~0 ~0 ~0 0:@

layer
1,2,2,2,2,2,2,2,2,2,2,2,2,2,2,2,2,2,1
2,2,2,2,2,2,2,2,2,2,2,2,2,2,2,2,2,2,2
2,2,2,2,2,2,2,2,2,2,2,2,2,2,2,2,2,2,2
2,2,2,2,2,2,2,2,2,2,2,2,2,2,2,2,2,2,2
2,2,2,2,2,2,2,2,2,2,2,2,2,2,2,2,2,2,2
2,2,2,2,2,2,2,2,2,2,2,2,2,2,2,2,2,2,2
2,2,2,2,2,2,2,2,2,2,2,2,2,2,2,2,2,2,2
2,2,2,2,2,2,2,2,2,2,2,2,2,2,2,2,2,2,2
2,2,2,2,2,2,2,2,2,3,3,3,3,3,2,2,2,2,2
2,2,2,2,2,2,2,2,2,15,0,0,0,0,0,2,2,2,2
2,2,2,2,2,2,2,4,4,0,0,0,0,0,2,2,2,2,2
2,2,2,2,2,5,5,0,0,0,0,0,0,0,0,2,2,2,2
2,2,2,2,2,5,0,0,0,0,0,0,0,0,2,2,2,2,2
2,2,2,2,2,2,0,0,0,0,0,0,0,0,0,2,2,2,2
2,2,2,2,2,2,2,0,6,0,6,0,2,0,2,2,2,2,2
2,2,2,2,2,2,2,2,2,2,2,2,2,2,2,2,2,2,2
2,2,2,2,2,2,2,2,2,2,2,2,2,2,2,2,2,2,2
2,2,2,2,2,2,2,2,2,2,2,2,2,2,2,2,2,2,2
1,2,2,2,2,2,2,2,2,2,2,2,2,2,2,2,2,2,1
endlayer

layer
1,2,2,2,2,2,2,2,7,7,7,2,2,2,2,2,2,2,1
2,2,2,2,2,2,2,2,2,2,2,2,2,2,2,2,2,2,2
2,2,2,2,2,2,2,2,2,2,2,2,2,2,2,2,2,2,2
2,2,2,2,2,2,2,2,2,2,2,2,2,2,2,2,2,2,2
2,2,2,2,2,2,2,2,2,2,2,2,2,2,2,2,2,2,2
2,2,2,2,2,2,2,2,2,2,2,2,2,2,2,2,2,2,2
2,2,2,2,2,2,2,2,2,2,2,2,2,2,2,2,2,2,2
2,2,2,2,2,2,2,2,2,2,2,2,2,2,2,2,2,2,2
9,2,2,2,2,2,2,2,2,2,2,2,2,2,2,2,2,2,8
9,2,2,2,2,5,5,5,4,10,2,2,2,2,2,2,2,2,8
9,2,2,2,2,0,0,0,0,2,2,2,2,2,2,2,2,2,8
2,2,2,2,0,0,0,0,0,0,0,0,0,0,0,2,2,2,2
2,2,2,2,2,0,0,0,0,0,0,0,0,0,2,2,2,2,2
2,2,2,2,2,2,0,0,0,0,0,0,0,6,2,2,2,2,2
2,2,2,2,2,2,2,0,2,0,2,0,2,2,2,2,2,2,2
2,2,2,2,2,2,2,2,2,2,2,2,2,2,2,2,2,2,2
2,2,2,2,2,2,2,2,2,2,2,2,2,2,2,2,2,2,2
2,2,2,2,2,2,2,2,2,2,2,2,2,2,2,2,2,2,2
1,2,2,2,2,2,2,2,4,4,4,2,2,2,2,2,2,2,1
endlayer

layer
1,2,2,2,2,2,2,2,1,1,1,2,2,2,2,2,2,2,1
2,2,2,2,2,2,2,2,7,7,7,2,2,2,2,2,2,2,2
2,2,2,2,2,2,2,2,2,2,2,2,2,2,2,2,2,2,2
2,2,2,2,2,2,2,2,2,1,2,2,2,2,2,2,2,2,2
2,2,2,2,2,2,2,2,2,2,2,2,2,2,2,2,2,2,2
2,2,2,2,2,2,2,2,2,2,2,2,2,2,2,2,2,2,2
2,2,2,2,2,2,2,2,2,2,2,2,2,2,2,2,2,2,2
2,2,2,2,2,2,2,4,4,4,4,4,2,2,2,2,2,2,2
1,9,2,2,2,2,0,0,0,0,0,0,0,2,2,2,2,8,1
1,9,2,2,0,0,0,0,0,0,0,0,0,0,0,2,2,8,1
1,9,2,2,2,0,0,0,0,0,0,0,0,0,2,2,2,8,1
2,2,2,2,0,0,0,0,0,0,0,0,0,0,0,2,2,2,2
2,2,2,2,2,0,0,0,0,0,0,0,0,2,2,2,2,2,2
2,2,2,2,2,2,6,0,0,0,0,0,2,2,2,2,2,2,2
2,2,2,2,2,2,2,0,2,0,2,0,2,2,2,2,2,2,2
2,2,2,2,2,2,2,2,2,0,2,2,2,2,2,2,2,2,2
2,2,2,2,2,2,2,2,2,2,2,2,2,2,2,2,2,2,2
2,2,2,2,2,2,2,2,4,4,4,2,2,2,2,2,2,2,2
1,2,2,2,2,2,2,2,1,1,1,2,2,2,2,2,2,2,1
endlayer

layer
1,2,2,2,2,1,2,2,1,1,1,2,2,1,2,2,2,2,1
2,2,2,2,2,2,2,2,1,1,1,2,2,2,2,2,2,2,2
2,2,2,2,2,2,2,2,7,7,7,2,2,2,2,2,2,2,2
2,2,2,2,2,2,2,2,2,1,2,2,2,2,2,2,2,2,2
2,2,2,2,2,2,2,2,2,2,2,2,2,2,2,2,2,2,2
1,2,2,2,2,2,2,2,2,2,2,2,2,2,2,2,2,2,1
2,2,2,2,2,2,2,4,4,4,4,4,2,2,2,2,2,2,2
2,2,2,2,2,2,2,0,0,0,0,0,2,2,2,2,2,2,2
1,1,9,2,2,2,0,0,0,0,0,0,0,2,2,2,8,1,1
1,1,9,2,0,0,0,0,0,0,0,0,0,0,0,2,8,1,1
1,1,9,2,2,0,0,0,0,0,0,0,0,0,2,2,8,1,1
2,2,2,2,2,0,0,0,0,0,0,0,0,0,2,2,2,2,2
2,2,2,2,2,2,0,0,0,0,0,0,0,2,2,2,2,2,2
1,2,2,2,2,2,2,0,0,0,0,0,2,2,2,2,2,2,1
2,2,2,2,2,2,2,0,2,3,2,2,2,2,2,2,2,2,2
2,2,2,2,2,2,2,2,2,3,2,2,2,2,2,2,2,2,2
2,2,2,2,2,2,2,2,4,4,4,2,2,2,2,2,2,2,2
2,2,2,2,2,2,2,2,1,1,1,2,2,2,2,2,2,2,2
1,2,2,2,2,1,2,2,1,1,1,2,2,1,2,2,2,2,1
endlayer

layer
1,2,2,2,2,1,2,2,1,1,1,2,2,1,2,2,2,2,1
2,2,2,2,2,2,2,2,1,1,1,2,2,2,2,2,2,2,2
2,2,2,2,2,2,2,2,1,1,1,2,2,2,2,2,2,2,2
2,2,2,2,2,2,2,2,7,7,7,2,2,2,2,2,2,2,2
2,2,2,2,2,2,2,2,2,2,2,2,2,2,2,2,2,2,2
1,2,2,2,2,2,8,4,4,4,4,4,9,2,2,2,2,2,1
2,2,2,2,2,2,8,0,0,0,0,0,9,2,2,2,2,2,2
2,2,2,2,2,2,7,0,0,0,0,0,7,2,2,2,2,2,2
1,1,1,9,2,2,3,0,0,0,0,0,3,2,2,8,1,1,1
1,1,1,9,2,3,3,0,0,0,0,0,3,3,2,8,1,1,1
1,1,1,9,2,3,3,0,0,0,0,0,3,3,2,8,1,1,1
2,2,2,2,2,3,3,3,0,0,0,3,3,3,2,2,2,2,2
2,2,2,2,2,2,3,3,3,3,3,3,3,2,2,2,2,2,2
1,2,2,2,2,2,2,3,3,3,3,3,2,2,2,2,2,2,1
2,2,2,2,2,2,2,2,2,2,2,2,2,2,2,2,2,2,2
2,2,2,2,2,2,2,2,4,4,4,2,2,2,2,2,2,2,2
2,2,2,2,2,2,2,2,1,1,1,2,2,2,2,2,2,2,2
2,2,2,2,2,2,2,2,1,1,1,2,2,2,2,2,2,2,2
1,2,2,2,2,1,2,2,1,1,1,2,2,1,2,2,2,2,1
endlayer

layer
1,6,1,2,7,8,9,6,1,1,1,6,8,9,7,2,1,6,1
6,1,1,1,7,2,2,7,1,1,1,7,2,2,7,1,1,1,6
1,1,1,1,1,6,2,6,1,1,1,6,2,6,1,1,1,1,1
2,1,1,0,0,0,6,6,0,0,0,6,6,0,0,0,1,1,2
9,9,1,0,0,0,0,0,0,0,0,0,0,0,0,0,1,8,8
4,2,6,0,0,0,0,0,0,0,0,0,0,0,0,0,6,2,4
7,2,2,6,0,0,0,0,0,0,0,0,0,0,0,6,2,2,7
6,9,6,6,0,0,0,0,0,0,0,0,0,0,0,6,6,8,6
1,1,1,0,0,0,6,0,0,0,0,0,6,0,0,0,1,1,1
1,1,1,0,0,0,6,0,0,0,0,0,6,0,0,0,1,1,1
1,1,1,0,0,0,0,0,0,0,0,0,0,0,0,0,1,1,1
6,9,6,6,0,0,0,6,0,0,0,6,0,0,0,6,6,8,6
4,2,2,6,0,0,0,0,6,0,6,0,0,0,0,6,2,2,4
7,2,1,0,0,0,0,0,0,0,0,0,0,0,0,0,6,2,7
9,9,1,0,0,0,0,0,0,0,0,0,0,0,0,0,1,8,8
2,1,1,0,0,0,6,6,0,0,0,6,6,0,0,0,1,1,2
1,1,1,1,1,6,2,6,1,1,1,6,2,6,1,1,1,1,1
6,1,1,1,4,2,2,4,1,1,1,4,2,2,4,1,1,1,6
1,6,1,2,4,8,9,6,1,1,1,6,8,9,4,2,1,6,1
endlayer

layer
1,6,1,2,6,5,8,1,1,1,1,1,9,5,6,2,1,6,1
6,1,1,1,1,6,2,8,1,1,1,9,2,6,1,1,1,1,6
1,1,1,1,1,6,2,6,0,0,0,6,2,6,1,1,1,1,1
2,1,1,0,0,0,6,0,0,0,0,0,6,0,0,0,1,1,2
6,1,1,0,0,0,0,0,0,0,0,0,0,0,0,0,1,1,6
5,6,6,0,0,0,0,0,0,0,0,0,0,0,0,0,6,6,5
4,2,2,6,0,0,0,0,0,0,0,0,0,0,0,6,2,2,4
1,4,6,0,0,0,0,0,0,0,0,0,0,0,0,0,6,4,1
1,1,0,0,0,0,0,0,0,0,0,0,0,0,0,0,0,1,1
1,1,0,0,0,0,0,0,0,0,0,0,0,0,0,0,0,1,1
1,1,0,0,0,0,0,0,0,0,0,0,0,0,0,0,0,1,1
1,7,6,0,0,0,0,0,0,0,0,0,0,0,0,0,6,7,1
7,2,2,6,0,0,0,0,0,0,0,0,0,0,0,6,2,2,7
5,6,1,0,0,0,0,0,0,0,0,0,0,0,0,0,6,6,5
6,1,1,0,0,0,0,0,0,0,0,0,0,0,0,0,1,1,6
2,1,1,0,0,0,6,0,0,0,0,0,6,0,0,0,1,1,2
1,1,1,1,1,6,2,6,0,0,0,6,2,6,1,1,1,1,1
6,1,1,1,1,6,2,8,1,1,1,9,2,6,1,1,1,1,6
1,6,1,2,6,5,8,1,1,1,1,1,9,5,6,2,1,6,1
endlayer

layer
1,5,11,2,6,1,6,1,1,1,1,1,6,1,6,2,11,5,1
5,2,12,12,11,7,2,1,0,0,0,1,2,7,11,12,12,2,5
14,13,3,1,1,6,2,6,0,0,0,6,2,6,1,1,3,14,13
2,13,1,0,0,0,6,0,0,0,0,0,6,0,0,0,1,14,2
6,14,1,0,0,0,0,0,0,0,0,0,0,0,0,0,1,13,6
1,9,6,0,0,0,0,0,0,0,0,0,0,0,0,0,6,8,1
6,2,2,6,0,0,0,0,0,0,0,0,0,0,0,6,2,2,6
1,0,6,0,0,0,0,0,0,0,0,0,0,0,0,0,6,0,1
1,0,0,0,0,0,0,0,0,0,0,0,0,0,0,0,0,0,1
1,0,0,0,0,0,0,0,0,0,0,0,0,0,0,0,0,0,1
1,0,0,0,0,0,0,0,0,0,0,0,0,0,0,0,0,0,1
1,0,6,0,0,0,0,0,0,0,0,0,0,0,0,0,6,0,1
6,2,2,6,0,0,0,0,0,0,0,0,0,0,0,6,2,2,6
1,9,1,0,0,0,0,0,0,0,0,0,0,0,0,0,6,8,1
6,14,1,0,0,0,0,0,0,0,0,0,0,0,0,0,1,13,6
2,13,1,0,0,0,6,0,0,0,0,0,6,0,0,0,1,14,2
14,13,3,1,1,6,2,6,0,0,0,6,2,6,1,1,3,14,13
5,2,3,11,12,4,2,0,0,0,0,0,2,4,12,11,11,2,5
1,5,12,2,6,1,6,1,1,1,1,1,6,1,6,2,12,5,1
endlayer

layer
1,1,14,2,13,1,6,0,0,0,0,0,6,1,14,2,13,1,1
1,11,2,4,2,3,2,13,0,0,0,14,2,3,2,4,2,11,1
11,2,8,2,2,2,2,6,0,0,0,6,2,2,2,2,9,2,11
2,2,2,0,0,0,6,0,0,0,0,0,6,0,0,0,2,2,2
12,2,2,0,0,0,0,0,0,0,0,0,0,0,0,0,2,2,12
1,3,2,0,0,0,0,0,0,0,0,0,0,0,0,0,2,3,1
6,2,2,6,0,0,0,0,0,0,0,0,0,0,0,6,2,2,6
0,12,6,0,0,0,0,0,0,0,0,0,0,0,0,0,6,12,0
0,0,0,0,0,0,0,0,0,0,0,0,0,0,0,0,0,0,0
0,0,0,0,0,0,0,0,0,0,0,0,0,0,0,0,0,0,0
0,0,0,0,0,0,0,0,0,0,0,0,0,0,0,0,0,0,0
0,11,6,0,0,0,0,0,0,0,0,0,0,0,0,0,6,11,0
6,2,2,6,0,0,0,0,0,0,0,0,0,0,0,6,2,2,6
1,3,2,0,0,0,0,0,0,0,0,0,0,0,0,0,2,3,1
11,2,13,0,0,0,0,0,0,0,0,0,0,0,0,0,2,2,11
2,2,2,0,0,0,6,0,0,0,0,0,6,0,0,0,2,2,2
12,2,8,2,11,2,2,6,0,0,0,6,2,2,2,2,9,2,12
1,12,2,7,2,3,2,13,0,0,0,14,2,3,2,7,2,12,1
1,1,14,2,13,1,6,0,0,0,0,0,6,1,14,2,13,1,1
endlayer

layer
1,1,6,1,9,7,9,3,0,0,0,3,8,7,8,1,6,1,1
1,6,1,1,2,4,2,11,0,0,0,11,2,4,2,1,1,6,1
6,1,1,1,6,1,2,6,0,0,0,6,2,1,6,1,1,1,6
1,6,1,0,0,0,0,0,0,0,0,0,0,0,0,0,1,6,1
7,2,6,0,0,0,0,0,0,0,0,0,0,0,0,0,6,2,7
9,8,1,0,0,0,0,0,0,0,0,0,0,0,0,0,1,9,8
7,2,2,0,0,0,0,0,0,0,0,0,0,0,0,0,2,2,7
3,14,6,0,0,0,0,0,0,0,0,0,0,0,0,0,6,13,3
0,0,0,0,0,0,0,0,0,0,0,0,0,0,0,0,0,0,0
0,0,0,0,0,0,0,0,0,0,0,0,0,0,0,0,0,0,0
0,0,0,0,0,0,0,0,0,0,0,0,0,0,0,0,0,0,0
3,14,6,0,0,0,0,0,0,0,0,0,0,0,0,0,6,13,3
4,2,2,0,0,0,0,0,0,0,0,0,0,0,0,0,2,2,4
9,8,1,0,0,0,0,0,0,0,0,0,0,0,0,0,1,9,8
4,2,6,0,0,0,0,0,0,0,0,0,0,0,0,0,6,2,4
1,6,1,0,0,0,0,0,0,0,0,0,0,0,0,0,1,6,1
6,1,1,1,6,1,2,6,0,0,0,6,2,1,6,1,1,1,6
1,6,1,1,2,7,2,12,0,0,0,12,2,7,2,1,1,6,1
1,1,6,1,9,4,9,3,0,0,0,3,8,4,8,1,6,1,1
endlayer

layer
1,1,6,1,6,5,11,5,13,0,11,5,11,5,6,1,6,1,1
1,6,1,1,2,1,6,2,13,3,14,2,6,1,2,1,1,6,1
6,1,1,1,6,1,2,5,3,3,3,5,2,1,6,1,1,1,6
1,6,1,0,0,0,0,0,0,0,0,0,0,0,0,0,1,6,1
6,2,6,0,0,0,0,0,0,0,0,0,0,0,0,0,6,2,6
5,1,1,0,0,0,0,0,0,0,0,0,0,0,0,0,1,1,5
14,6,2,0,0,0,0,0,0,0,0,0,0,0,0,0,2,6,13
5,2,5,0,0,0,0,0,0,0,0,0,0,0,0,0,5,2,5
14,12,3,0,0,0,0,0,0,0,0,0,0,0,0,0,3,12,12
0,3,3,0,0,0,0,0,0,0,0,0,0,0,0,0,3,3,0
11,11,3,0,0,0,0,0,0,0,0,0,0,0,0,0,3,11,13
5,2,5,0,0,0,0,0,0,0,0,0,0,0,0,0,5,2,5
14,6,2,0,0,0,0,0,0,0,0,0,0,0,0,0,2,6,13
5,1,1,0,0,0,0,0,0,0,0,0,0,0,0,0,1,1,5
6,2,6,0,0,0,0,0,0,0,0,0,0,0,0,0,6,2,6
1,6,1,0,0,0,0,0,0,0,0,0,0,0,0,0,1,6,1
6,1,1,1,6,1,2,5,3,3,3,5,2,1,6,1,1,1,6
1,6,1,1,2,1,6,2,13,3,14,2,6,1,2,1,1,6,1
1,1,6,1,6,5,12,5,12,0,14,5,12,5,6,1,6,1,1
endlayer

layer
1,1,7,11,6,1,1,5,7,2,7,5,1,1,6,11,7,1,1
1,9,2,2,2,1,6,1,2,4,2,1,6,1,2,2,2,8,1
9,14,2,2,2,1,2,1,6,1,6,1,2,1,2,2,2,13,8
14,9,2,2,0,0,0,0,0,0,0,0,0,0,0,2,2,8,13
6,2,2,0,0,0,0,0,0,0,0,0,0,0,0,0,2,2,6
1,1,1,0,0,0,0,0,0,0,0,0,0,0,0,0,1,1,1
1,6,2,0,0,0,0,0,0,0,0,0,0,0,0,0,2,6,1
5,1,1,0,0,0,0,0,0,0,0,0,0,0,0,0,1,1,5
9,2,6,0,0,0,0,0,0,0,0,0,0,0,0,0,6,2,8
2,8,1,0,0,0,0,0,0,0,0,0,0,0,0,0,1,9,2
9,2,6,0,0,0,0,0,0,0,0,0,0,0,0,0,6,2,8
5,1,1,0,0,0,0,0,0,0,0,0,0,0,0,0,1,1,5
1,6,2,0,0,0,0,0,0,0,0,0,0,0,0,0,2,6,1
1,1,1,0,0,0,0,0,0,0,0,0,0,0,0,0,1,1,1
6,2,2,0,0,0,0,0,0,0,0,0,0,0,0,0,2,2,6
14,9,2,2,0,0,0,0,0,0,0,0,0,0,0,2,2,8,13
9,14,2,2,2,1,2,1,6,1,6,1,2,1,2,2,2,13,8
1,9,2,2,2,1,6,1,2,7,2,1,6,1,2,2,2,8,1
1,1,4,12,6,1,1,5,4,2,4,5,1,1,6,12,4,1,1
endlayer

layer
1,1,1,1,7,1,1,1,6,1,6,1,1,1,7,1,1,1,1
1,1,1,5,9,11,6,1,2,1,2,1,6,11,8,5,1,1,1
1,1,5,2,4,2,2,1,6,1,6,1,2,2,4,2,5,1,1
1,1,9,8,0,6,0,0,0,0,0,0,0,6,0,9,8,1,1
9,7,8,0,0,0,0,0,0,0,0,0,0,0,0,0,9,7,8
1,14,2,6,0,0,0,0,0,0,0,0,0,0,0,6,2,13,1
1,6,2,0,0,0,0,0,0,0,0,0,0,0,0,0,2,6,1
1,1,1,0,0,0,0,0,0,0,0,0,0,0,0,0,1,1,1
6,2,6,0,0,0,0,0,0,0,0,0,0,0,0,0,6,2,6
1,1,1,0,0,0,0,0,0,0,0,0,0,0,0,0,1,1,1
6,2,6,0,0,0,0,0,0,0,0,0,0,0,0,0,6,2,6
1,1,1,0,0,0,0,0,0,0,0,0,0,0,0,0,1,1,1
1,6,2,0,0,0,0,0,0,0,0,0,0,0,0,0,2,6,1
1,14,2,6,0,0,0,0,0,0,0,0,0,0,0,6,2,13,1
9,4,8,0,0,0,0,0,0,0,0,0,0,0,0,0,9,4,8
1,1,9,8,0,6,0,0,0,0,0,0,0,6,0,9,8,1,1
1,1,5,2,7,2,2,1,6,1,6,1,2,2,7,2,5,1,1
1,1,1,5,9,12,6,1,2,1,2,1,6,12,8,5,1,1,1
1,1,1,1,4,1,1,1,6,1,6,1,1,1,4,1,1,1,1
endlayer

layer
1,1,1,1,1,1,1,1,6,1,6,1,1,1,1,1,1,1,1
1,1,1,1,1,7,11,11,2,1,2,11,11,7,1,1,1,1,1
1,1,1,6,1,2,2,2,6,1,6,2,2,2,1,6,1,1,1
1,1,6,0,0,6,0,6,0,0,0,6,0,6,0,0,6,1,1
1,1,1,0,0,0,0,0,0,0,0,0,0,0,0,0,1,1,1
1,9,2,6,0,0,0,0,0,0,0,0,0,0,0,6,2,8,1
1,14,2,0,0,0,0,0,0,0,0,0,0,0,0,0,2,13,1
1,14,2,6,0,0,0,0,0,0,0,0,0,0,0,6,2,13,1
6,2,6,0,0,0,0,0,0,0,0,0,0,0,0,0,6,2,6
1,1,1,0,0,0,0,0,0,0,0,0,0,0,0,0,1,1,1
6,2,6,0,0,0,0,0,0,0,0,0,0,0,0,0,6,2,6
1,14,2,6,0,0,0,0,0,0,0,0,0,0,0,6,2,13,1
1,14,2,0,0,0,0,0,0,0,0,0,0,0,0,0,2,13,1
1,9,2,6,0,0,0,0,0,0,0,0,0,0,0,6,2,8,1
1,1,1,0,0,0,0,0,0,0,0,0,0,0,0,0,1,1,1
1,1,6,0,0,6,0,6,0,0,0,6,0,6,0,0,6,1,1
1,1,1,6,1,2,2,2,6,1,6,2,2,2,1,6,1,1,1
1,1,1,1,1,4,12,12,2,1,2,12,12,4,1,1,1,1,1
1,1,1,1,1,1,1,1,6,1,6,1,1,1,1,1,1,1,1
endlayer

layer
1,1,1,1,1,1,1,1,7,11,7,1,1,1,1,1,1,1,1
1,1,1,1,1,6,1,9,2,2,2,8,1,6,1,1,1,1,1
1,1,1,6,1,2,1,2,4,5,4,2,1,2,1,6,1,1,1
1,1,6,0,0,6,0,6,0,0,0,6,0,6,0,0,6,1,1
1,1,1,0,0,6,0,0,0,0,0,0,0,6,0,0,1,1,1
1,6,2,6,6,0,0,0,0,0,0,0,0,0,6,6,2,6,1
1,1,1,0,0,0,0,0,0,0,0,0,0,0,0,0,1,1,1
1,7,2,6,0,0,0,0,0,0,0,0,0,0,0,6,2,7,1
9,2,8,0,0,0,0,0,0,0,0,0,0,0,0,0,9,2,8
14,2,5,0,0,0,0,0,0,0,0,0,0,0,0,0,5,2,13
9,2,8,0,0,0,0,0,0,0,0,0,0,0,0,0,9,2,8
1,4,2,6,0,0,0,0,0,0,0,0,0,0,0,6,2,4,1
1,1,1,0,0,0,0,0,0,0,0,0,0,0,0,0,1,1,1
1,6,2,6,6,0,0,0,0,0,0,0,0,0,6,6,2,6,1
1,1,1,0,0,6,0,0,0,0,0,0,0,6,0,0,1,1,1
1,1,6,0,0,6,0,6,0,0,0,6,0,6,0,0,6,1,1
1,1,1,6,1,2,1,2,7,5,7,2,1,2,1,6,1,1,1
1,1,1,1,1,6,1,9,2,2,2,8,1,6,1,1,1,1,1
1,1,1,1,1,1,1,1,4,12,4,1,1,1,1,1,1,1,1
endlayer

layer
1,1,1,1,1,1,1,1,1,5,1,1,1,1,1,1,1,1,1
1,1,1,1,1,6,1,6,1,5,1,6,1,6,1,1,1,1,1
1,1,1,11,11,2,1,2,1,1,1,2,1,2,11,11,1,1,1
1,1,11,14,2,2,0,6,0,0,0,6,0,2,2,13,11,1,1
1,1,14,2,2,2,0,6,0,0,0,6,0,2,2,2,13,1,1
1,6,2,2,2,0,0,0,0,0,0,0,0,0,2,2,2,6,1
1,1,1,0,0,0,0,0,0,0,0,0,0,0,0,0,1,1,1
1,6,2,6,6,0,0,0,0,0,0,0,0,0,6,6,2,6,1
1,1,1,0,0,0,0,0,0,0,0,0,0,0,0,0,1,1,1
5,5,1,0,0,0,0,0,0,0,0,0,0,0,0,0,1,5,5
1,1,1,0,0,0,0,0,0,0,0,0,0,0,0,0,1,1,1
1,6,2,6,6,0,0,0,0,0,0,0,0,0,6,6,2,6,1
1,1,1,0,0,0,0,0,0,0,0,0,0,0,0,0,1,1,1
1,6,2,2,2,0,0,0,0,0,0,0,0,0,2,2,2,6,1
1,1,14,2,2,2,0,6,0,0,0,6,0,2,2,2,13,1,1
1,1,12,14,2,2,0,6,0,0,0,6,0,2,2,13,12,1,1
1,1,1,12,12,2,1,2,1,1,1,2,1,2,12,12,1,1,1
1,1,1,1,1,6,1,6,1,5,1,6,1,6,1,1,1,1,1
1,1,1,1,1,1,1,1,1,5,1,1,1,1,1,1,1,1,1
endlayer

layer
1,1,1,1,1,1,1,1,1,1,1,1,1,1,1,1,1,1,1
1,1,1,1,1,7,11,6,1,1,1,6,11,7,1,1,1,1,1
1,1,1,1,1,9,2,2,1,1,1,2,2,8,1,1,1,1,1
1,1,1,1,5,2,2,2,3,0,3,2,2,2,5,1,1,1,1
1,1,1,5,5,2,2,2,3,0,3,2,2,2,5,5,1,1,1
1,9,7,2,2,0,6,0,0,0,0,0,6,0,2,2,7,8,1
1,14,2,2,2,6,0,0,0,0,0,0,0,6,2,2,2,13,1
1,6,2,2,2,0,0,0,0,0,0,0,0,0,2,2,2,6,1
1,1,1,3,3,0,0,0,0,0,0,0,0,0,3,3,1,1,1
1,1,1,0,0,0,0,0,0,0,0,0,0,0,0,0,1,1,1
1,1,1,3,3,0,0,0,0,0,0,0,0,0,3,3,1,1,1
1,6,2,2,2,0,0,0,0,0,0,0,0,0,2,2,2,6,1
1,14,2,2,2,6,0,0,0,0,0,0,0,6,2,2,2,13,1
1,9,4,2,2,0,6,0,0,0,0,0,6,0,2,2,4,8,1
1,1,1,5,5,2,2,2,3,0,3,2,2,2,5,5,1,1,1
1,1,1,1,5,2,2,2,3,0,3,2,2,2,5,1,1,1,1
1,1,1,1,1,9,2,2,1,1,1,2,2,8,1,1,1,1,1
1,1,1,1,1,4,12,6,1,1,1,6,12,4,1,1,1,1,1
1,1,1,1,1,1,1,1,1,1,1,1,1,1,1,1,1,1,1
endlayer

layer
1,1,1,1,1,1,1,1,1,1,1,1,1,1,1,1,1,1,1
1,1,1,1,1,1,1,7,3,1,3,7,1,1,1,1,1,1,1
1,1,1,1,1,1,1,7,11,11,11,7,1,1,1,1,1,1,1
1,1,1,1,1,1,6,4,2,4,2,4,6,1,1,1,1,1,1
1,1,1,1,1,1,2,4,2,4,2,4,2,1,1,1,1,1,1
1,1,1,1,1,0,6,0,6,0,6,0,6,0,1,1,1,1,1
1,1,1,6,2,6,0,0,0,0,0,0,0,6,2,6,1,1,1
1,9,9,8,8,0,0,0,0,0,0,0,0,0,9,9,8,8,1
1,3,14,2,2,6,0,0,0,0,0,0,0,6,2,2,13,3,1
1,1,14,8,8,0,0,0,0,0,0,0,0,0,9,9,13,1,1
1,3,14,2,2,6,0,0,0,0,0,0,0,6,2,2,13,3,1
1,9,9,8,8,0,0,0,0,0,0,0,0,0,9,9,8,8,1
1,1,1,6,2,6,0,0,0,0,0,0,0,6,2,6,1,1,1
1,1,1,1,1,0,6,0,6,0,6,0,6,0,1,1,1,1,1
1,1,1,1,1,1,2,7,2,7,2,7,2,1,1,1,1,1,1
1,1,1,1,1,1,6,7,2,7,2,7,6,1,1,1,1,1,1
1,1,1,1,1,1,1,4,12,12,12,4,1,1,1,1,1,1,1
1,1,1,1,1,1,1,4,3,1,3,4,1,1,1,1,1,1,1
1,1,1,1,1,1,1,1,1,1,1,1,1,1,1,1,1,1,1
endlayer

layer
1,1,1,1,1,1,1,1,1,1,1,1,1,1,1,1,1,1,1
1,1,1,1,1,1,1,1,1,5,1,1,1,1,1,1,1,1,1
1,1,1,1,1,1,1,1,1,5,1,1,1,1,1,1,1,1,1
1,1,1,1,1,1,6,1,6,1,6,1,6,1,1,1,1,1,1
1,1,1,1,1,1,2,1,2,1,2,1,2,1,1,1,1,1,1
1,1,1,1,1,0,6,0,6,0,6,0,6,0,1,1,1,1,1
1,1,1,6,2,6,0,0,0,0,0,0,0,6,2,6,1,1,1
1,1,1,1,1,0,0,0,0,0,0,0,0,0,1,1,1,1,1
1,1,1,6,2,6,0,0,0,0,0,0,0,6,2,6,1,1,1
1,5,5,1,1,0,0,0,0,0,0,0,0,0,1,1,5,5,1
1,1,1,6,2,6,0,0,0,0,0,0,0,6,2,6,1,1,1
1,1,1,1,1,0,0,0,0,0,0,0,0,0,1,1,1,1,1
1,1,1,6,2,6,0,0,0,0,0,0,0,6,2,6,1,1,1
1,1,1,1,1,0,6,0,6,0,6,0,6,0,1,1,1,1,1
1,1,1,1,1,1,2,1,2,1,2,1,2,1,1,1,1,1,1
1,1,1,1,1,1,6,1,6,1,6,1,6,1,1,1,1,1,1
1,1,1,1,1,1,1,1,1,5,1,1,1,1,1,1,1,1,1
1,1,1,1,1,1,1,1,1,5,1,1,1,1,1,1,1,1,1
1,1,1,1,1,1,1,1,1,1,1,1,1,1,1,1,1,1,1
endlayer

layer
1,1,1,1,1,1,1,1,1,1,1,1,1,1,1,1,1,1,1
1,1,1,1,1,1,1,1,1,1,1,1,1,1,1,1,1,1,1
1,1,1,1,1,1,1,1,1,1,1,1,1,1,1,1,1,1,1
1,1,1,1,1,1,6,1,6,1,6,1,6,1,1,1,1,1,1
1,1,1,1,1,1,2,1,2,1,2,1,2,1,1,1,1,1,1
1,1,1,1,1,3,2,0,6,0,6,0,2,3,1,1,1,1,1
1,1,1,6,2,2,0,0,0,0,0,0,0,2,2,6,1,1,1
1,1,1,1,1,0,0,0,0,0,0,0,0,0,1,1,1,1,1
1,1,1,6,2,6,0,0,0,0,0,0,0,6,2,6,1,1,1
1,1,1,1,1,0,0,0,0,0,0,0,0,0,1,1,1,1,1
1,1,1,6,2,6,0,0,0,0,0,0,0,6,2,6,1,1,1
1,1,1,1,1,0,0,0,0,0,0,0,0,0,1,1,1,1,1
1,1,1,6,2,2,0,0,0,0,0,0,0,2,2,6,1,1,1
1,1,1,1,1,3,2,0,6,0,6,0,2,3,1,1,1,1,1
1,1,1,1,1,1,2,1,2,1,2,1,2,1,1,1,1,1,1
1,1,1,1,1,1,6,1,6,1,6,1,6,1,1,1,1,1,1
1,1,1,1,1,1,1,1,1,1,1,1,1,1,1,1,1,1,1
1,1,1,1,1,1,1,1,1,1,1,1,1,1,1,1,1,1,1
1,1,1,1,1,1,1,1,1,1,1,1,1,1,1,1,1,1,1
endlayer

layer
1,1,1,1,1,1,1,1,1,1,1,1,1,1,1,1,1,1,1
1,1,1,1,1,1,1,1,1,1,1,1,1,1,1,1,1,1,1
1,1,1,1,1,1,1,1,1,1,1,1,1,1,1,1,1,1,1
1,1,1,1,1,1,7,11,6,1,6,11,7,1,1,1,1,1,1
1,1,1,1,1,1,7,11,2,1,2,11,7,1,1,1,1,1,1
1,1,1,1,1,9,2,2,2,0,2,2,2,7,1,1,1,1,1
1,1,1,9,9,2,0,6,0,0,0,6,0,2,8,8,1,1,1
1,1,1,14,14,2,6,0,0,0,0,0,6,2,13,13,1,1,1
1,1,1,6,2,2,0,0,0,0,0,0,0,2,2,6,1,1,1
1,1,1,1,1,0,0,0,0,0,0,0,0,0,1,1,1,1,1
1,1,1,6,2,2,0,0,0,0,0,0,0,2,2,6,1,1,1
1,1,1,14,14,2,6,0,0,0,0,0,6,2,13,13,1,1,1
1,1,1,9,9,2,0,6,0,0,0,6,0,2,8,8,1,1,1
1,1,1,1,1,4,2,2,2,0,2,2,2,8,1,1,1,1,1
1,1,1,1,1,1,4,12,2,1,2,12,4,1,1,1,1,1,1
1,1,1,1,1,1,4,12,6,1,6,12,4,1,1,1,1,1,1
1,1,1,1,1,1,1,1,1,1,1,1,1,1,1,1,1,1,1
1,1,1,1,1,1,1,1,1,1,1,1,1,1,1,1,1,1,1
1,1,1,1,1,1,1,1,1,1,1,1,1,1,1,1,1,1,1
endlayer

layer
1,1,1,1,1,1,1,1,1,1,1,1,1,1,1,1,1,1,1
1,1,1,1,1,1,1,1,1,1,1,1,1,1,1,1,1,1,1
1,1,1,1,1,1,1,1,1,1,1,1,1,1,1,1,1,1,1
1,1,1,1,1,1,1,1,7,11,7,1,1,1,1,1,1,1,1
1,1,1,1,1,1,1,1,7,11,7,1,1,1,1,1,1,1,1
1,1,1,1,1,6,5,2,2,4,2,2,5,6,1,1,1,1,1
1,1,1,1,1,5,2,2,0,0,0,2,2,5,1,1,1,1,1
1,1,1,1,1,2,2,0,0,0,0,0,2,2,1,1,1,1,1
1,1,1,9,9,2,0,0,0,0,0,0,0,2,8,8,1,1,1
1,1,1,14,14,8,0,0,0,0,0,0,0,9,13,13,1,1,1
1,1,1,9,9,2,0,0,0,0,0,0,0,2,8,8,1,1,1
1,1,1,1,1,2,2,0,0,0,0,0,2,2,1,1,1,1,1
1,1,1,1,1,5,2,2,0,0,0,2,2,5,1,1,1,1,1
1,1,1,1,1,6,5,2,2,7,2,2,5,6,1,1,1,1,1
1,1,1,1,1,1,1,1,4,12,4,1,1,1,1,1,1,1,1
1,1,1,1,1,1,1,1,4,12,4,1,1,1,1,1,1,1,1
1,1,1,1,1,1,1,1,1,1,1,1,1,1,1,1,1,1,1
1,1,1,1,1,1,1,1,1,1,1,1,1,1,1,1,1,1,1
1,1,1,1,1,1,1,1,1,1,1,1,1,1,1,1,1,1,1
endlayer

layer
1,1,1,1,1,1,1,1,1,1,1,1,1,1,1,1,1,1,1
1,1,1,1,1,1,1,1,1,1,1,1,1,1,1,1,1,1,1
1,1,1,1,1,1,1,1,1,1,1,1,1,1,1,1,1,1,1
1,1,1,1,1,1,1,1,1,5,1,1,1,1,1,1,1,1,1
1,1,1,1,1,1,1,1,1,5,1,1,1,1,1,1,1,1,1
1,1,1,1,1,6,1,6,1,1,1,6,1,6,1,1,1,1,1
1,1,1,1,1,1,0,6,0,0,0,6,0,1,1,1,1,1,1
1,1,1,1,1,6,6,0,0,0,0,0,6,6,1,1,1,1,1
1,1,1,1,1,1,0,0,0,0,0,0,0,1,1,1,1,1,1
1,1,1,5,5,1,0,0,0,0,0,0,0,1,5,5,1,1,1
1,1,1,1,1,1,0,0,0,0,0,0,0,1,1,1,1,1,1
1,1,1,1,1,6,6,0,0,0,0,0,6,6,1,1,1,1,1
1,1,1,1,1,1,0,6,0,0,0,6,0,1,1,1,1,1,1
1,1,1,1,1,6,1,6,1,1,1,6,1,6,1,1,1,1,1
1,1,1,1,1,1,1,1,1,5,1,1,1,1,1,1,1,1,1
1,1,1,1,1,1,1,1,1,5,1,1,1,1,1,1,1,1,1
1,1,1,1,1,1,1,1,1,1,1,1,1,1,1,1,1,1,1
1,1,1,1,1,1,1,1,1,1,1,1,1,1,1,1,1,1,1
1,1,1,1,1,1,1,1,1,1,1,1,1,1,1,1,1,1,1
endlayer

layer
1,1,1,1,1,1,1,1,1,1,1,1,1,1,1,1,1,1,1
1,1,1,1,1,1,1,1,1,1,1,1,1,1,1,1,1,1,1
1,1,1,1,1,1,1,1,1,1,1,1,1,1,1,1,1,1,1
1,1,1,1,1,1,1,1,1,1,1,1,1,1,1,1,1,1,1
1,1,1,1,1,1,1,1,1,1,1,1,1,1,1,1,1,1,1
1,1,1,1,1,5,11,6,1,1,1,6,11,5,1,1,1,1,1
1,1,1,1,1,14,0,6,0,0,0,6,0,13,1,1,1,1,1
1,1,1,1,1,6,6,0,0,0,0,0,6,6,1,1,1,1,1
1,1,1,1,1,1,0,0,0,0,0,0,0,1,1,1,1,1,1
1,1,1,1,1,1,0,0,0,0,0,0,0,1,1,1,1,1,1
1,1,1,1,1,1,0,0,0,0,0,0,0,1,1,1,1,1,1
1,1,1,1,1,6,6,0,0,0,0,0,6,6,1,1,1,1,1
1,1,1,1,1,14,0,6,0,0,0,6,0,13,1,1,1,1,1
1,1,1,1,1,5,12,6,1,1,1,6,12,5,1,1,1,1,1
1,1,1,1,1,1,1,1,1,1,1,1,1,1,1,1,1,1,1
1,1,1,1,1,1,1,1,1,1,1,1,1,1,1,1,1,1,1
1,1,1,1,1,1,1,1,1,1,1,1,1,1,1,1,1,1,1
1,1,1,1,1,1,1,1,1,1,1,1,1,1,1,1,1,1,1
1,1,1,1,1,1,1,1,1,1,1,1,1,1,1,1,1,1,1
endlayer

layer
1,1,1,1,1,1,1,1,1,1,1,1,1,1,1,1,1,1,1
1,1,1,1,1,1,1,1,1,1,1,1,1,1,1,1,1,1,1
1,1,1,1,1,1,1,1,1,1,1,1,1,1,1,1,1,1,1
1,1,1,1,1,1,1,1,1,1,1,1,1,1,1,1,1,1,1
1,1,1,1,1,1,1,1,1,1,1,1,1,1,1,1,1,1,1
1,1,1,1,1,1,1,7,11,11,11,7,1,1,1,1,1,1,1
1,1,1,1,1,1,2,12,6,0,6,12,2,1,1,1,1,1,1
1,1,1,1,1,9,13,0,0,0,0,0,14,8,1,1,1,1,1
1,1,1,1,1,14,6,0,0,0,0,0,6,13,1,1,1,1,1
1,1,1,1,1,14,0,0,0,0,0,0,0,13,1,1,1,1,1
1,1,1,1,1,14,6,0,0,0,0,0,6,13,1,1,1,1,1
1,1,1,1,1,9,13,0,0,0,0,0,14,8,1,1,1,1,1
1,1,1,1,1,1,2,11,6,0,6,11,2,1,1,1,1,1,1
1,1,1,1,1,1,1,4,12,12,12,4,1,1,1,1,1,1,1
1,1,1,1,1,1,1,1,1,1,1,1,1,1,1,1,1,1,1
1,1,1,1,1,1,1,1,1,1,1,1,1,1,1,1,1,1,1
1,1,1,1,1,1,1,1,1,1,1,1,1,1,1,1,1,1,1
1,1,1,1,1,1,1,1,1,1,1,1,1,1,1,1,1,1,1
1,1,1,1,1,1,1,1,1,1,1,1,1,1,1,1,1,1,1
endlayer

layer
1,1,1,1,1,1,1,1,1,1,1,1,1,1,1,1,1,1,1
1,1,1,1,1,1,1,1,1,1,1,1,1,1,1,1,1,1,1
1,1,1,1,1,1,1,1,1,1,1,1,1,1,1,1,1,1,1
1,1,1,1,1,1,1,1,1,1,1,1,1,1,1,1,1,1,1
1,1,1,1,1,1,1,1,1,1,1,1,1,1,1,1,1,1,1
1,1,1,1,1,1,1,1,1,7,1,1,1,1,1,1,1,1,1
1,1,1,1,1,1,1,5,2,5,2,5,1,1,1,1,1,1,1
1,1,1,1,1,1,5,0,0,0,0,0,5,1,1,1,1,1,1
1,1,1,1,1,1,2,0,0,0,0,0,2,1,1,1,1,1,1
1,1,1,1,1,9,5,0,0,0,0,0,5,8,1,1,1,1,1
1,1,1,1,1,1,2,0,0,0,0,0,2,1,1,1,1,1,1
1,1,1,1,1,1,5,0,0,0,0,0,5,1,1,1,1,1,1
1,1,1,1,1,1,1,5,2,5,2,5,1,1,1,1,1,1,1
1,1,1,1,1,1,1,1,1,4,1,1,1,1,1,1,1,1,1
1,1,1,1,1,1,1,1,1,1,1,1,1,1,1,1,1,1,1
1,1,1,1,1,1,1,1,1,1,1,1,1,1,1,1,1,1,1
1,1,1,1,1,1,1,1,1,1,1,1,1,1,1,1,1,1,1
1,1,1,1,1,1,1,1,1,1,1,1,1,1,1,1,1,1,1
1,1,1,1,1,1,1,1,1,1,1,1,1,1,1,1,1,1,1
endlayer

layer
1,1,1,1,1,1,1,1,1,1,1,1,1,1,1,1,1,1,1
1,1,1,1,1,1,1,1,1,1,1,1,1,1,1,1,1,1,1
1,1,1,1,1,1,1,1,1,1,1,1,1,1,1,1,1,1,1
1,1,1,1,1,1,1,1,1,1,1,1,1,1,1,1,1,1,1
1,1,1,1,1,1,1,1,1,1,1,1,1,1,1,1,1,1,1
1,1,1,1,1,1,1,1,1,1,1,1,1,1,1,1,1,1,1
1,1,1,1,1,1,1,1,6,1,6,1,1,1,1,1,1,1,1
1,1,1,1,1,1,1,0,0,0,0,0,1,1,1,1,1,1,1
1,1,1,1,1,1,6,0,0,0,0,0,6,1,1,1,1,1,1
1,1,1,1,1,1,1,0,0,0,0,0,1,1,1,1,1,1,1
1,1,1,1,1,1,6,0,0,0,0,0,6,1,1,1,1,1,1
1,1,1,1,1,1,1,0,0,0,0,0,1,1,1,1,1,1,1
1,1,1,1,1,1,1,1,6,1,6,1,1,1,1,1,1,1,1
1,1,1,1,1,1,1,1,1,1,1,1,1,1,1,1,1,1,1
1,1,1,1,1,1,1,1,1,1,1,1,1,1,1,1,1,1,1
1,1,1,1,1,1,1,1,1,1,1,1,1,1,1,1,1,1,1
1,1,1,1,1,1,1,1,1,1,1,1,1,1,1,1,1,1,1
1,1,1,1,1,1,1,1,1,1,1,1,1,1,1,1,1,1,1
1,1,1,1,1,1,1,1,1,1,1,1,1,1,1,1,1,1,1
endlayer

layer
1,1,1,1,1,1,1,1,1,1,1,1,1,1,1,1,1,1,1
1,1,1,1,1,1,1,1,1,1,1,1,1,1,1,1,1,1,1
1,1,1,1,1,1,1,1,1,1,1,1,1,1,1,1,1,1,1
1,1,1,1,1,1,1,1,1,1,1,1,1,1,1,1,1,1,1
1,1,1,1,1,1,1,1,1,1,1,1,1,1,1,1,1,1,1
1,1,1,1,1,1,1,1,1,1,1,1,1,1,1,1,1,1,1
1,1,1,1,1,1,1,1,6,1,6,1,1,1,1,1,1,1,1
1,1,1,1,1,1,1,0,0,0,0,0,1,1,1,1,1,1,1
1,1,1,1,1,1,6,0,0,0,0,0,6,1,1,1,1,1,1
1,1,1,1,1,1,1,0,0,0,0,0,1,1,1,1,1,1,1
1,1,1,1,1,1,6,0,0,0,0,0,6,1,1,1,1,1,1
1,1,1,1,1,1,1,0,0,0,0,0,1,1,1,1,1,1,1
1,1,1,1,1,1,1,1,6,1,6,1,1,1,1,1,1,1,1
1,1,1,1,1,1,1,1,1,1,1,1,1,1,1,1,1,1,1
1,1,1,1,1,1,1,1,1,1,1,1,1,1,1,1,1,1,1
1,1,1,1,1,1,1,1,1,1,1,1,1,1,1,1,1,1,1
1,1,1,1,1,1,1,1,1,1,1,1,1,1,1,1,1,1,1
1,1,1,1,1,1,1,1,1,1,1,1,1,1,1,1,1,1,1
1,1,1,1,1,1,1,1,1,1,1,1,1,1,1,1,1,1,1
endlayer

layer
1,1,1,1,1,1,1,1,1,1,1,1,1,1,1,1,1,1,1
1,1,1,1,1,1,1,1,1,1,1,1,1,1,1,1,1,1,1
1,1,1,1,1,1,1,1,1,1,1,1,1,1,1,1,1,1,1
1,1,1,1,1,1,1,1,1,1,1,1,1,1,1,1,1,1,1
1,1,1,1,1,1,1,1,1,1,1,1,1,1,1,1,1,1,1
1,1,1,1,1,1,1,1,1,1,1,1,1,1,1,1,1,1,1
1,1,1,1,1,1,1,1,7,11,7,1,1,1,1,1,1,1,1
1,1,1,1,1,1,1,3,12,0,12,3,1,1,1,1,1,1,1
1,1,1,1,1,1,9,13,0,0,0,14,8,1,1,1,1,1,1
1,1,1,1,1,1,14,0,0,0,0,0,13,1,1,1,1,1,1
1,1,1,1,1,1,9,13,0,0,0,14,8,1,1,1,1,1,1
1,1,1,1,1,1,1,3,11,0,11,3,1,1,1,1,1,1,1
1,1,1,1,1,1,1,1,4,12,4,1,1,1,1,1,1,1,1
1,1,1,1,1,1,1,1,1,1,1,1,1,1,1,1,1,1,1
1,1,1,1,1,1,1,1,1,1,1,1,1,1,1,1,1,1,1
1,1,1,1,1,1,1,1,1,1,1,1,1,1,1,1,1,1,1
1,1,1,1,1,1,1,1,1,1,1,1,1,1,1,1,1,1,1
1,1,1,1,1,1,1,1,1,1,1,1,1,1,1,1,1,1,1
1,1,1,1,1,1,1,1,1,1,1,1,1,1,1,1,1,1,1
endlayer

layer
1,1,1,1,1,1,1,1,1,1,1,1,1,1,1,1,1,1,1
1,1,1,1,1,1,1,1,1,1,1,1,1,1,1,1,1,1,1
1,1,1,1,1,1,1,1,1,1,1,1,1,1,1,1,1,1,1
1,1,1,1,1,1,1,1,1,1,1,1,1,1,1,1,1,1,1
1,1,1,1,1,1,1,1,1,1,1,1,1,1,1,1,1,1,1
1,1,1,1,1,1,1,1,1,1,1,1,1,1,1,1,1,1,1
1,1,1,1,1,1,1,1,1,1,1,1,1,1,1,1,1,1,1
1,1,1,1,1,1,1,1,7,4,7,1,1,1,1,1,1,1,1
1,1,1,1,1,1,1,9,0,0,0,8,1,1,1,1,1,1,1
1,1,1,1,1,1,1,8,0,0,0,9,1,1,1,1,1,1,1
1,1,1,1,1,1,1,9,0,0,0,8,1,1,1,1,1,1,1
1,1,1,1,1,1,1,1,4,7,4,1,1,1,1,1,1,1,1
1,1,1,1,1,1,1,1,1,1,1,1,1,1,1,1,1,1,1
1,1,1,1,1,1,1,1,1,1,1,1,1,1,1,1,1,1,1
1,1,1,1,1,1,1,1,1,1,1,1,1,1,1,1,1,1,1
1,1,1,1,1,1,1,1,1,1,1,1,1,1,1,1,1,1,1
1,1,1,1,1,1,1,1,1,1,1,1,1,1,1,1,1,1,1
1,1,1,1,1,1,1,1,1,1,1,1,1,1,1,1,1,1,1
1,1,1,1,1,1,1,1,1,1,1,1,1,1,1,1,1,1,1
endlayer

