
# Created by Ruins mod version 16.7 Ingame Parser
# authoring Player: lafuller

weight=1
embed_into_distance=7
acceptable_target_blocks=
unacceptable_target_blocks=flowing_water,water,flowing_lava,lava,ice,bedrock,netherrack,nether_brick,nether_brick_fence,soul_sand,quartz_ore,end_stone,obsidian,iron_bars,cloud,flesh,ash_block,slime_grass,slime_congealed,slime_dirt
biomesToSpawnIn=jungle,forest,plains,prarie,meadow,brushland,shrubland,woodland,woodlands
dimensions=8,21,29
allowable_overhang=0
max_leveling=7
leveling_buffer=-1
preserve_water=0
preserve_lava=0
preserve_plants=0
preventRotation=1

adjoining_template=Gilly/GillyDCE3;28;15;0;100
adjoining_template=Gilly/GillyDCH4;25;15;12;100
adjoining_template=Gilly/GillyDCH1;-12;15;25;100

adjoining_template=Gilly/GillyDCE1;-28;15;0;100
adjoining_template=Gilly/GillyDCF3;25;15;-12;100
adjoining_template=Gilly/GillyDCF4;12;15;25;100

adjoining_template=Gilly/GillyDCE4;0;15;28;100
adjoining_template=Gilly/GillyDCH3;12;15;-25;100
adjoining_template=Gilly/GillyDCH2;-25;15;-12;100

adjoining_template=Gilly/GillyDCE2;0;15;-28;100
adjoining_template=Gilly/GillyDCF2;-12;15;-25;100
adjoining_template=Gilly/GillyDCF1;-25;15;12;100

adjoining_template=Gilly/GillyDCG1;-20;15;20;100
adjoining_template=Gilly/GillyDCG2;-20;15;-20;100
adjoining_template=Gilly/GillyDCG3;20;15;-20;100
adjoining_template=Gilly/GillyDCG4;20;15;20;100

rule1=0,100,preserveBlock
rule2=0,100,stonebrick-0,stonebrick-0,stonebrick-0,stonebrick-0,stonebrick-1,stonebrick-2,stonebrick-2,stone-5,stone-6,cobblestone
rule3=0,100,minecraft:stone_brick_stairs-3
rule4=0,100,minecraft:stone_brick_stairs-2
rule5=0,100,ChestGenHook:chests/village_blacksmith:5-4
rule6=0,100,minecraft:stone_brick_stairs-5
rule7=0,100,minecraft:stone_slab-13
rule8=0,100,minecraft:stone_brick_stairs-4

layer
1,1,1,1,1,1,1,1,2,1,1,2,1,1,2,1,1,2,1,1,2,1,1,1,1,1,1,1,1
1,1,1,1,1,2,1,1,1,1,1,1,1,1,1,1,1,1,1,1,1,1,1,2,1,1,1,1,1
1,1,1,1,1,1,1,1,1,1,1,1,1,1,1,1,1,1,1,1,1,1,1,1,1,1,1,1,1
1,1,2,1,1,1,1,1,2,1,1,2,1,1,2,1,1,2,1,1,2,1,1,1,1,1,2,1,1
1,1,1,1,1,1,1,1,1,1,1,1,1,1,1,1,1,1,1,1,1,1,1,1,1,1,1,1,1
1,1,1,1,1,2,1,1,1,1,1,1,1,1,1,1,1,1,1,1,1,1,1,2,1,1,1,1,1
1,1,2,1,1,1,1,1,2,1,1,2,1,1,2,1,1,2,1,1,2,1,1,1,1,1,2,1,1
1,1,1,1,1,1,1,1,1,1,1,1,1,1,1,1,1,1,1,1,1,1,1,1,1,1,1,1,1
1,1,1,1,1,1,1,1,1,1,1,1,1,1,1,1,1,1,1,1,1,1,1,1,1,1,1,1,1
1,1,2,1,2,2,2,2,2,1,1,1,1,1,1,1,1,1,1,1,2,2,2,2,2,1,2,1,1
1,1,1,1,2,2,2,2,2,1,1,2,1,1,2,1,1,2,1,1,2,2,2,2,2,1,1,1,1
1,1,2,1,2,2,2,2,2,1,1,1,1,1,1,1,1,1,1,1,2,2,2,2,2,1,2,1,1
1,1,1,1,1,1,1,1,1,1,1,1,1,1,1,1,1,1,1,1,1,1,1,1,1,1,1,1,1
1,1,1,1,1,1,1,1,1,1,1,1,1,1,1,1,1,1,1,1,1,1,1,1,1,1,1,1,1
1,1,2,1,1,1,1,1,2,1,1,2,1,1,2,1,1,2,1,1,2,1,1,1,1,1,2,1,1
1,1,1,1,1,2,1,1,1,1,1,1,1,1,1,1,1,1,1,1,1,1,1,2,1,1,1,1,1
1,1,1,1,1,1,1,1,1,1,1,1,1,1,1,1,1,1,1,1,1,1,1,1,1,1,1,1,1
1,1,2,1,1,1,1,1,2,1,1,2,1,1,2,1,1,2,1,1,2,1,1,1,1,1,2,1,1
1,1,1,1,1,1,1,1,1,1,1,1,1,1,1,1,1,1,1,1,1,1,1,1,1,1,1,1,1
1,1,1,1,1,2,1,1,1,1,1,1,1,1,1,1,1,1,1,1,1,1,1,2,1,1,1,1,1
1,1,1,1,1,1,1,1,2,1,1,2,1,1,2,1,1,2,1,1,2,1,1,1,1,1,1,1,1
endlayer

layer
1,1,1,1,1,1,1,1,2,0,0,2,0,0,2,0,0,2,0,0,2,1,1,1,1,1,1,1,1
1,1,1,1,1,2,1,1,1,0,0,1,0,0,1,0,0,1,0,0,1,1,1,2,1,1,1,1,1
1,1,1,1,1,1,1,1,1,0,0,1,0,0,1,0,0,1,0,0,1,1,1,1,1,1,1,1,1
1,1,2,1,1,1,1,1,2,0,0,2,0,0,2,0,0,2,0,0,2,1,1,1,1,1,2,1,1
1,1,1,1,1,1,1,1,1,1,1,1,1,1,1,1,1,1,1,1,1,1,1,1,1,1,1,1,1
1,1,1,1,1,2,1,1,1,1,1,1,1,1,1,1,1,1,1,1,1,1,1,2,1,1,1,1,1
1,1,2,1,1,1,1,1,2,1,1,2,1,1,2,1,1,2,1,1,2,1,1,1,1,1,2,1,1
1,1,1,1,1,1,1,1,1,1,1,1,1,1,1,1,1,1,1,1,1,1,1,1,1,1,1,1,1
1,1,1,1,1,1,1,1,1,1,1,1,1,1,1,1,1,1,1,1,1,1,1,1,1,1,1,1,1
1,1,2,1,2,2,2,2,2,1,1,1,1,1,1,1,1,1,1,1,2,2,2,2,2,1,2,1,1
1,1,1,1,2,2,2,2,2,1,1,2,1,1,2,1,1,2,1,1,2,2,2,2,2,1,1,1,1
1,1,2,1,2,2,2,2,2,1,1,1,1,1,1,1,1,1,1,1,2,2,2,2,2,1,2,1,1
1,1,1,1,1,1,1,1,1,1,1,1,1,1,1,1,1,1,1,1,1,1,1,1,1,1,1,1,1
1,1,1,1,1,1,1,1,1,1,1,1,1,1,1,1,1,1,1,1,1,1,1,1,1,1,1,1,1
1,1,2,1,1,1,1,1,2,1,1,2,1,1,2,1,1,2,1,1,2,1,1,1,1,1,2,1,1
1,1,1,1,1,2,1,1,1,1,1,1,1,1,1,1,1,1,1,1,1,1,1,2,1,1,1,1,1
1,1,1,1,1,1,1,1,1,1,1,1,1,1,1,1,1,1,1,1,1,1,1,1,1,1,1,1,1
1,1,2,1,1,1,1,1,2,0,0,2,0,0,2,0,0,2,0,0,2,1,1,1,1,1,2,1,1
1,1,1,1,1,1,1,1,1,0,0,1,0,0,1,0,0,1,0,0,1,1,1,1,1,1,1,1,1
1,1,1,1,1,2,1,1,1,0,0,1,0,0,1,0,0,1,0,0,1,1,1,2,1,1,1,1,1
1,1,1,1,1,1,1,1,2,0,0,2,0,0,2,0,0,2,0,0,2,1,1,1,1,1,1,1,1
endlayer

layer
1,1,1,1,1,1,1,1,2,0,0,2,0,0,2,0,0,2,0,0,2,1,1,1,1,1,1,1,1
1,1,1,0,0,2,0,0,1,0,0,1,0,0,1,0,0,1,0,0,1,0,0,2,0,0,1,1,1
0,0,1,0,0,1,0,0,1,0,0,1,0,0,1,0,0,1,0,0,1,0,0,1,0,0,1,0,0
0,0,2,0,0,1,0,0,2,0,0,2,0,0,2,0,0,2,0,0,2,0,0,1,0,0,2,0,0
0,0,1,0,0,1,0,0,1,0,0,1,0,0,1,0,0,1,0,0,1,0,0,1,0,0,1,0,0
0,0,1,1,1,2,1,1,1,0,0,1,0,0,1,0,0,1,0,0,1,1,1,2,1,1,1,0,0
1,1,2,1,1,1,1,1,2,1,1,2,1,1,2,1,1,2,1,1,2,1,1,1,1,1,2,1,1
1,1,1,1,1,1,1,1,1,1,1,1,1,1,1,1,1,1,1,1,1,1,1,1,1,1,1,1,1
1,1,1,1,1,1,1,1,1,1,1,1,1,1,1,1,1,1,1,1,1,1,1,1,1,1,1,1,1
1,1,2,1,2,2,2,2,4,1,1,1,1,1,1,1,1,1,1,1,3,2,2,2,2,1,2,1,1
1,1,1,1,2,2,2,2,4,1,1,2,1,1,2,1,1,2,1,1,3,2,2,2,2,1,1,1,1
1,1,2,1,2,2,2,2,4,1,1,1,1,1,1,1,1,1,1,1,3,2,2,2,2,1,2,1,1
1,1,1,1,1,1,1,1,1,1,1,1,1,1,1,1,1,1,1,1,1,1,1,1,1,1,1,1,1
1,1,1,1,1,1,1,1,1,1,1,1,1,1,1,1,1,1,1,1,1,1,1,1,1,1,1,1,1
1,1,2,1,1,1,1,1,2,1,1,2,1,1,2,1,1,2,1,1,2,1,1,1,1,1,2,1,1
0,0,1,1,1,2,1,1,1,0,0,1,0,0,1,0,0,1,0,0,1,1,1,2,1,1,1,0,0
0,0,1,0,0,1,0,0,1,0,0,1,0,0,1,0,0,1,0,0,1,1,1,1,0,0,1,0,0
0,0,2,0,0,1,0,0,2,0,0,2,0,0,2,0,0,2,0,0,2,1,1,1,0,0,2,0,0
0,0,1,0,0,1,0,0,1,0,0,1,0,0,1,0,0,1,0,0,1,1,1,1,0,0,1,0,0
1,1,1,0,0,2,0,0,1,0,0,1,0,0,1,0,0,1,0,0,1,1,1,2,0,0,1,1,1
1,1,1,1,1,1,1,1,2,0,0,2,0,0,2,0,0,2,0,0,2,1,1,1,1,1,1,1,1
endlayer

layer
1,1,1,1,1,1,1,1,2,0,0,2,0,0,2,0,0,2,0,0,2,1,1,1,1,1,1,1,1
1,1,1,0,0,2,0,0,1,0,0,1,0,0,1,0,0,1,0,0,1,0,0,2,0,0,1,1,1
0,0,1,0,0,1,0,0,1,0,0,1,0,0,1,0,0,1,0,0,1,0,0,1,0,0,1,0,0
0,0,2,0,0,1,0,0,2,0,0,2,0,0,2,0,0,2,0,0,2,0,0,1,0,0,2,0,0
0,0,1,0,0,1,0,0,1,0,0,1,0,0,1,0,0,1,0,0,1,0,0,1,0,0,1,0,0
0,0,1,0,0,2,0,0,1,0,0,1,0,0,1,0,0,1,0,0,1,0,0,2,0,0,1,0,0
0,0,2,0,0,0,0,0,2,0,0,2,0,0,2,0,0,2,0,0,2,0,0,0,0,0,2,0,0
0,0,0,0,0,0,0,0,0,0,0,0,0,0,0,0,0,0,0,0,0,0,0,0,0,0,0,0,0
0,0,0,0,0,0,0,0,0,0,0,0,0,0,0,0,0,0,0,0,0,0,0,0,0,0,0,0,0
1,1,2,5,2,2,2,4,0,0,0,0,0,0,0,0,0,0,0,0,0,3,2,2,2,5,2,1,1
1,1,1,1,2,2,2,4,0,0,0,2,0,0,2,0,0,2,0,0,0,3,2,2,2,1,1,1,1
1,1,2,1,2,2,2,4,0,0,0,0,0,0,0,0,0,0,0,0,0,3,2,2,2,1,2,1,1
0,0,0,0,0,0,0,0,0,0,0,0,0,0,0,0,0,0,0,0,0,0,0,0,0,0,0,0,0
0,0,0,0,0,0,0,0,0,0,0,0,0,0,0,0,0,0,0,0,0,0,0,0,0,0,0,0,0
0,0,2,0,0,0,0,0,2,0,0,2,0,0,2,0,0,2,0,0,2,0,0,0,0,0,2,0,0
0,0,1,0,0,2,0,0,1,0,0,1,0,0,1,0,0,1,0,0,1,0,0,2,0,0,1,0,0
0,0,1,0,0,1,0,0,1,0,0,1,0,0,1,0,0,1,0,0,1,0,0,1,0,0,1,0,0
0,0,2,0,0,1,0,0,2,0,0,2,0,0,2,0,0,2,0,0,2,0,0,1,0,0,2,0,0
0,0,1,0,0,1,0,0,1,0,0,1,0,0,1,0,0,1,0,0,1,0,0,1,0,0,1,0,0
1,1,1,0,0,2,0,0,1,0,0,1,0,0,1,0,0,1,0,0,1,0,0,2,0,0,1,1,1
1,1,1,1,1,1,1,1,2,0,0,2,0,0,2,0,0,2,0,0,2,1,1,1,1,1,1,1,1
endlayer

layer
1,1,1,1,1,1,1,1,2,0,0,2,0,0,2,0,0,2,0,0,2,1,1,1,1,1,1,1,1
1,1,1,0,0,2,0,0,1,0,0,1,0,0,1,0,0,1,0,0,1,0,0,2,0,0,1,1,1
0,0,1,0,0,1,0,0,1,0,0,1,0,0,1,0,0,1,0,0,1,0,0,1,0,0,1,0,0
0,0,2,0,0,1,0,0,2,0,0,2,0,0,2,0,0,2,0,0,2,0,0,1,0,0,2,0,0
0,0,1,0,0,1,0,0,1,0,0,1,0,0,1,0,0,1,0,0,1,0,0,1,0,0,1,0,0
0,0,1,0,0,2,0,0,1,0,0,1,0,0,1,0,0,1,0,0,1,0,0,2,0,0,1,0,0
0,0,2,0,0,0,0,0,2,0,0,2,0,0,2,0,0,2,0,0,2,0,0,0,0,0,2,0,0
0,0,0,0,0,0,0,0,0,0,0,0,0,0,0,0,0,0,0,0,0,0,0,0,0,0,0,0,0
0,0,0,0,0,0,0,0,0,0,0,0,0,0,0,0,0,0,0,0,0,0,0,0,0,0,0,0,0
1,1,2,1,2,2,4,0,0,0,0,0,0,0,0,0,0,0,0,0,0,0,3,2,2,1,2,1,1
1,1,1,1,2,2,4,0,0,0,0,2,0,0,2,0,0,2,0,0,0,0,3,2,2,1,1,1,1
1,1,2,1,2,2,4,0,0,0,0,0,0,0,0,0,0,0,0,0,0,0,3,2,2,1,2,1,1
0,0,0,0,0,0,0,0,0,0,0,0,0,0,0,0,0,0,0,0,0,0,0,0,0,0,0,0,0
0,0,0,0,0,0,0,0,0,0,0,0,0,0,0,0,0,0,0,0,0,0,0,0,0,0,0,0,0
0,0,2,0,0,0,0,0,2,0,0,2,0,0,2,0,0,2,0,0,2,0,0,0,0,0,2,0,0
0,0,1,0,0,2,0,0,1,0,0,1,0,0,1,0,0,1,0,0,1,0,0,2,0,0,1,0,0
0,0,1,0,0,1,0,0,1,0,0,1,0,0,1,0,0,1,0,0,1,0,0,1,0,0,1,0,0
0,0,2,0,0,1,0,0,2,0,0,2,0,0,2,0,0,2,0,0,2,0,0,1,0,0,2,0,0
0,0,1,0,0,1,0,0,1,0,0,1,0,0,1,0,0,1,0,0,1,0,0,1,0,0,1,0,0
1,1,1,0,0,2,0,0,1,0,0,1,0,0,1,0,0,1,0,0,1,0,0,2,0,0,1,1,1
1,1,1,1,1,1,1,1,2,0,0,2,0,0,2,0,0,2,0,0,2,1,1,1,1,1,1,1,1
endlayer

layer
1,1,1,1,1,1,1,1,2,0,0,2,0,0,2,0,0,2,0,0,2,1,1,1,1,1,1,1,1
1,1,1,0,0,2,0,0,1,0,0,1,0,0,1,0,0,1,0,0,1,0,0,2,0,0,1,1,1
0,0,1,0,0,1,0,0,1,0,0,1,0,0,1,0,0,1,0,0,1,0,0,1,0,0,1,0,0
0,0,2,0,0,1,0,0,2,0,0,2,0,0,2,0,0,2,0,0,2,0,0,1,0,0,2,0,0
0,0,1,0,0,1,0,0,1,0,0,1,0,0,1,0,0,1,0,0,1,0,0,1,0,0,1,0,0
0,0,1,0,0,2,0,0,1,0,0,1,0,0,1,0,0,1,0,0,1,0,0,2,0,0,1,0,0
0,0,2,0,0,6,0,0,2,0,0,2,0,0,2,0,0,2,0,0,2,0,0,6,0,0,2,0,0
0,0,7,0,0,7,0,0,0,0,0,0,0,0,0,0,0,0,0,0,0,0,0,7,0,0,7,0,0
0,0,7,0,0,7,0,0,0,0,0,0,0,0,0,0,0,0,0,0,0,0,0,7,0,0,7,0,0
1,1,2,1,2,4,0,0,0,0,0,0,0,0,0,0,0,0,0,0,0,0,0,3,2,1,2,1,1
1,1,1,1,2,4,0,0,0,0,0,2,0,0,2,0,0,2,0,0,0,0,0,3,2,1,1,1,1
1,1,2,1,2,4,0,0,0,0,0,0,0,0,0,0,0,0,0,0,0,0,0,3,2,1,2,1,1
0,0,7,0,0,7,0,0,0,0,0,0,0,0,0,0,0,0,0,0,0,0,0,7,0,0,7,0,0
0,0,7,0,0,7,0,0,0,0,0,0,0,0,0,0,0,0,0,0,0,0,0,7,0,0,7,0,0
0,0,2,0,0,8,0,0,2,0,0,2,0,0,2,0,0,2,0,0,2,0,0,8,0,0,2,0,0
0,0,1,0,0,2,0,0,1,0,0,1,0,0,1,0,0,1,0,0,1,0,0,2,0,0,1,0,0
0,0,1,0,0,1,0,0,1,0,0,1,0,0,1,0,0,1,0,0,1,0,0,1,0,0,1,0,0
0,0,2,0,0,1,0,0,2,0,0,2,0,0,2,0,0,2,0,0,2,0,0,1,0,0,2,0,0
0,0,1,0,0,1,0,0,1,0,0,1,0,0,1,0,0,1,0,0,1,0,0,1,0,0,1,0,0
1,1,1,0,0,2,0,0,1,0,0,1,0,0,1,0,0,1,0,0,1,0,0,2,0,0,1,1,1
1,1,1,1,1,1,1,1,2,0,0,2,0,0,2,0,0,2,0,0,2,1,1,1,1,1,1,1,1
endlayer

layer
1,1,1,1,1,1,1,1,1,1,1,1,1,1,1,1,1,1,1,1,1,1,1,1,1,1,1,1,1
1,1,1,1,1,1,1,1,1,1,1,1,1,1,1,1,1,1,1,1,1,1,1,1,1,1,1,1,1
1,1,1,1,1,1,1,1,1,1,1,1,1,1,1,1,1,1,1,1,1,1,1,1,1,1,1,1,1
1,1,1,1,1,1,1,1,1,1,1,1,1,1,1,1,1,1,1,1,1,1,1,1,1,1,1,1,1
1,1,1,1,1,1,1,1,1,1,1,1,1,1,1,1,0,1,1,1,1,1,1,1,1,1,1,1,1
1,1,1,1,1,1,1,1,1,1,1,1,1,1,1,1,1,1,1,1,1,1,1,1,1,1,1,1,1
1,1,1,1,1,1,1,1,2,1,1,2,1,1,2,1,1,2,1,1,2,1,1,1,1,1,1,1,1
1,1,1,1,1,1,1,1,1,1,1,2,1,1,2,1,1,2,1,1,1,1,1,1,1,1,1,1,1
1,1,1,1,1,1,1,1,1,1,1,2,1,1,2,1,1,2,1,1,1,1,1,1,1,1,1,1,1
1,1,1,1,4,0,0,0,0,0,1,2,1,1,2,1,1,2,1,0,0,0,0,0,3,1,1,1,1
1,1,1,1,4,0,0,0,0,0,1,2,1,1,2,1,1,2,1,0,0,0,0,0,3,1,1,1,1
1,1,1,1,4,0,0,0,0,0,1,2,1,1,2,1,1,2,1,0,0,0,0,0,3,1,1,1,1
1,1,1,1,1,1,1,1,1,1,1,2,1,1,2,1,1,2,1,1,1,1,1,1,1,1,1,1,1
1,1,1,1,1,1,1,1,1,1,1,2,1,1,2,1,1,2,1,1,1,1,1,1,1,1,1,1,1
1,1,1,1,1,1,1,1,2,1,1,2,1,1,2,1,1,2,1,1,2,1,1,1,1,1,1,1,1
1,1,1,1,1,1,1,1,1,1,1,1,1,1,1,1,1,1,1,1,1,1,1,1,1,1,1,1,1
1,1,1,1,1,1,1,1,1,1,1,1,1,1,1,1,1,1,1,1,1,1,1,1,1,1,1,1,1
1,1,1,1,1,1,1,1,1,1,1,1,1,1,1,1,1,1,1,1,1,1,1,1,1,1,1,1,1
1,1,1,1,1,1,1,1,1,1,1,1,1,1,1,1,1,1,1,1,1,1,1,1,1,1,1,1,1
1,1,1,1,1,1,1,1,1,1,1,1,1,1,1,1,1,1,1,1,1,1,1,1,1,1,1,1,1
1,1,1,1,1,1,1,1,1,1,1,1,1,1,1,1,1,1,1,1,1,1,1,1,1,1,1,1,1
endlayer

layer
1,1,1,1,1,1,1,1,1,1,1,1,1,1,1,1,1,1,1,1,1,1,1,1,1,1,1,1,1
1,1,1,1,1,1,1,1,1,1,1,1,1,1,1,1,1,1,1,1,1,1,1,1,1,1,1,1,1
1,1,1,1,1,1,1,1,1,1,1,1,1,1,1,1,1,1,1,1,1,1,1,1,1,1,1,1,1
1,1,1,1,1,1,1,1,1,1,1,1,1,1,1,1,1,1,1,1,1,1,1,1,1,1,1,1,1
1,1,1,1,1,1,1,1,1,1,1,1,1,1,1,1,1,1,1,1,1,1,1,1,1,1,1,1,1
1,1,1,1,1,1,1,1,1,1,1,1,1,1,1,1,1,1,1,1,1,1,1,1,1,1,1,1,1
1,1,1,1,1,1,1,1,1,1,1,1,1,1,1,1,1,1,1,1,1,1,1,1,1,1,1,1,1
1,1,1,1,1,1,1,1,1,1,1,1,1,1,1,1,1,1,1,1,1,1,1,1,1,1,1,1,1
1,1,1,1,1,1,1,1,1,1,1,1,1,1,1,1,1,1,1,1,1,1,1,1,1,1,1,1,1
1,1,1,0,0,0,0,0,0,1,1,1,1,1,1,1,1,1,1,1,0,0,0,0,0,0,1,1,1
1,1,1,0,0,0,0,0,0,1,1,1,1,1,1,1,1,1,1,1,0,0,0,0,0,0,1,1,1
1,1,1,0,0,0,0,0,0,1,1,1,1,1,1,1,1,1,1,1,0,0,0,0,0,0,1,1,1
1,1,1,1,1,1,1,1,1,1,1,1,1,1,1,1,1,1,1,1,1,1,1,1,1,1,1,1,1
1,1,1,1,1,1,1,1,1,1,1,1,1,1,1,1,1,1,1,1,1,1,1,1,1,1,1,1,1
1,1,1,1,1,1,1,1,1,1,1,1,1,1,1,1,1,1,1,1,1,1,1,1,1,1,1,1,1
1,1,1,1,1,1,1,1,1,1,1,1,1,1,1,1,1,1,1,1,1,1,1,1,1,1,1,1,1
1,1,1,1,1,1,1,1,1,1,1,1,1,1,1,1,1,1,1,1,1,1,1,1,1,1,1,1,1
1,1,1,1,1,1,1,1,1,1,1,1,1,1,1,1,1,1,1,1,1,1,1,1,1,1,1,1,1
1,1,1,1,1,1,1,1,1,1,1,1,1,1,1,1,1,1,1,1,1,1,1,1,1,1,1,1,1
1,1,1,1,1,1,1,1,1,1,1,1,1,1,1,1,1,1,1,1,1,1,1,1,1,1,1,1,1
1,1,1,1,1,1,1,1,1,1,1,1,1,1,1,1,1,1,1,1,1,1,1,1,1,1,1,1,1
endlayer

