
# Created by Ruins mod version 16.7 Ingame Parser
# authoring Player: lafuller

weight=1
embed_into_distance=5
acceptable_target_blocks=
unacceptable_target_blocks=flowing_water,water,flowing_lava,lava,ice,bedrock,netherrack,nether_brick,nether_brick_fence,soul_sand,quartz_ore,gravel,end_stone,obsidian,iron_bars,cloud,flesh,ash_block,slime_grass,slime_congealed,slime_dirt
biomesToSpawnIn=jungle
dimensions=15,12,12
allowable_overhang=0
max_leveling=5
leveling_buffer=-1
preserve_water=0
preserve_lava=0

rule1=0,100,preserveBlock
rule2=0,100,minecraft:stonebrick-0
rule3=0,100,minecraft:stone-5
rule4=0,100,minecraft:stone-6
rule5=0,100,minecraft:stone_brick_stairs-2
rule6=0,100,minecraft:stone_brick_stairs-0
rule7=0,100,minecraft:stone-4
rule8=0,100,minecraft:stone_brick_stairs-1
rule9=0,100,minecraft:stone-3
rule10=0,100,minecraft:stone_brick_stairs-3
rule11=0,100,minecraft:stone_slab-5
rule12=0,100,minecraft:stone_brick_stairs-5
rule13=0,100,minecraft:stone_brick_stairs-6
rule14=0,100,minecraft:stone_brick_stairs-7
rule15=0,100,minecraft:stone_brick_stairs-4
rule16=0,100,minecraft:sea_lantern-0
rule17=0,100,minecraft:stone_slab-13
rule18=0,100,minecraft:double_stone_slab-0
rule19=0,100,minecraft:stone_slab-0
rule20=0,100,minecraft:double_stone_slab-5

layer
1,1,1,1,1,1,1,1,1,1,1,1
1,3,2,2,1,1,1,1,1,1,1,1
1,2,2,2,2,1,1,1,1,1,1,1
1,2,2,2,2,1,1,1,1,1,1,1
1,1,2,2,2,1,1,1,1,1,1,1
1,1,1,1,1,1,1,1,1,1,1,1
1,1,1,1,1,1,1,1,1,1,1,1
1,1,1,1,1,1,1,2,2,2,1,1
1,1,1,1,1,1,1,2,2,2,2,1
1,1,1,1,1,1,1,2,2,2,2,1
1,1,1,1,1,1,1,1,2,2,3,1
1,1,1,1,1,1,1,1,1,1,1,1
endlayer

layer
1,1,1,1,1,1,1,1,1,1,1,1
1,3,3,2,1,1,1,1,1,1,1,1
1,3,2,2,2,1,1,1,1,1,1,1
1,2,2,2,2,1,1,1,1,1,1,1
1,1,2,2,2,1,1,1,1,1,1,1
1,1,1,1,1,1,1,1,1,1,1,1
1,1,1,1,1,1,1,1,1,1,1,1
1,1,1,1,1,1,1,2,2,2,1,1
1,1,1,1,1,1,1,2,2,2,2,1
1,1,1,1,1,1,1,2,2,2,3,1
1,1,1,1,1,1,1,1,2,3,3,1
1,1,1,1,1,1,1,1,1,1,1,1
endlayer

layer
1,1,1,1,1,1,1,1,1,1,1,1
1,2,2,2,1,1,1,1,1,1,1,1
1,2,2,2,3,1,1,1,1,1,1,1
1,2,2,2,2,1,1,1,1,1,1,1
1,1,3,2,2,1,1,1,1,1,1,1
1,1,1,1,1,1,1,1,1,1,1,1
1,1,1,1,1,1,1,1,1,1,1,1
1,1,1,1,1,1,1,2,2,3,1,1
1,1,1,1,1,1,1,2,2,2,2,1
1,1,1,1,1,1,1,3,2,2,2,1
1,1,1,1,1,1,1,1,2,2,2,1
1,1,1,1,1,1,1,1,1,0,1,1
endlayer

layer
1,1,1,1,1,1,1,1,1,1,1,1
1,4,4,2,1,1,1,1,1,1,1,1
1,4,4,4,3,1,1,1,1,1,1,1
1,2,4,4,4,1,1,1,1,1,1,1
1,1,3,4,2,1,1,1,1,1,1,1
1,1,1,1,1,1,1,1,1,1,1,1
1,1,1,1,1,1,1,1,1,1,1,1
1,1,1,1,1,1,1,2,4,3,1,1
1,1,1,1,1,1,1,4,4,4,2,1
1,1,1,1,1,1,1,3,4,4,4,1
1,1,1,1,1,1,1,1,2,4,4,1
1,1,1,1,1,1,1,1,1,0,1,1
endlayer

layer
1,1,1,1,1,1,1,1,1,1,1,1
1,1,4,4,1,1,1,1,1,1,1,1
1,4,4,4,4,1,1,1,1,1,1,1
1,4,4,4,4,1,1,1,1,1,1,1
1,1,4,4,0,0,1,1,1,1,1,1
1,1,1,1,0,0,0,1,1,1,1,1
1,1,1,1,1,0,0,0,1,1,1,1
1,1,1,1,1,1,0,0,4,4,1,1
1,1,1,1,1,1,1,4,4,4,4,1
1,1,1,1,1,1,1,4,4,4,4,1
1,1,1,1,1,1,1,1,4,4,0,1
1,1,1,1,1,1,1,1,1,0,1,1
endlayer

layer
1,1,1,1,1,1,1,1,1,1,1,1
1,1,4,5,1,1,1,1,1,1,1,1
1,4,7,4,6,1,1,1,1,1,1,1
1,8,4,9,8,1,1,1,1,1,1,1
1,1,10,5,0,0,0,1,1,1,1,1
1,1,1,1,0,0,0,0,1,1,1,1
1,1,1,1,0,0,0,0,1,1,1,1
1,1,1,1,1,0,0,0,10,5,1,1
1,1,1,1,1,1,1,6,9,4,6,1
1,1,1,1,1,1,1,8,4,7,4,1
1,1,1,1,1,1,1,1,10,4,0,1
1,1,1,1,1,1,1,1,1,0,1,1
endlayer

layer
1,1,1,1,1,1,1,1,1,1,1,1
1,1,11,6,1,1,1,1,1,1,1,1
1,11,7,11,5,1,1,1,1,1,1,1
1,10,11,9,12,0,1,1,1,1,1,1
1,1,8,13,0,0,0,0,1,1,1,1
1,1,1,0,0,0,0,0,1,1,1,1
1,1,1,1,0,0,0,0,0,1,1,1
1,1,1,1,0,0,0,0,14,6,1,1
1,1,1,1,1,1,0,15,9,11,5,1
1,1,1,1,1,1,1,10,11,7,11,1
1,1,1,1,1,1,1,1,8,11,0,1
1,1,1,1,1,1,1,1,1,0,1,1
endlayer

layer
1,1,1,1,1,1,1,1,1,1,1,1
1,1,11,6,1,1,1,1,1,1,1,1
1,6,7,11,5,1,1,1,1,1,1,1
1,10,11,16,0,0,0,1,1,1,1,1
1,1,8,0,0,0,0,0,1,1,1,1
1,1,1,0,0,0,0,0,0,1,1,1
1,1,1,0,0,0,0,0,0,1,1,1
1,1,1,1,0,0,0,0,0,6,1,1
1,1,1,1,1,0,0,0,16,5,5,1
1,1,1,1,1,1,1,10,11,7,11,1
1,1,1,1,1,1,1,1,8,11,0,1
1,1,1,1,1,1,1,1,1,0,1,1
endlayer

layer
1,1,1,1,1,1,1,1,1,1,1,1
1,1,14,6,1,1,1,1,1,1,1,1
1,15,7,11,5,1,1,1,1,1,1,1
1,10,11,9,8,0,0,0,1,1,1,1
1,1,8,5,0,0,0,0,0,1,1,1
1,1,1,0,0,0,0,0,0,1,1,1
1,1,1,0,0,0,0,0,0,1,1,1
1,1,1,0,0,0,0,0,10,6,1,1
1,1,1,1,0,0,0,6,9,2,5,1
1,1,1,1,1,1,1,10,11,7,5,1
1,1,1,1,1,1,1,1,8,8,0,1
1,1,1,1,1,1,1,1,1,0,1,1
endlayer

layer
1,1,1,1,1,1,1,1,1,1,1,1
1,11,15,6,1,1,1,1,1,1,1,1
1,14,7,11,5,1,1,1,1,1,1,1
1,10,11,9,12,0,0,0,1,1,1,1
1,1,8,13,0,0,0,0,0,1,1,1
1,1,1,0,0,0,0,0,0,1,1,1
1,1,1,0,0,0,0,0,0,1,1,1
1,1,1,0,0,0,0,0,14,6,1,1
1,1,1,1,0,0,0,15,9,2,5,1
1,1,1,1,1,1,1,10,11,7,13,1
1,1,1,1,1,1,1,1,8,12,11,1
1,1,1,1,1,1,1,1,1,0,1,1
endlayer

layer
1,1,1,1,1,1,1,1,1,1,1,1
1,2,11,6,1,1,1,1,1,1,1,1
1,11,7,11,5,1,1,0,1,1,1,1
1,10,11,16,11,0,0,0,0,1,1,1
1,1,8,8,17,0,0,0,0,0,1,1
1,1,1,0,0,0,0,0,0,1,1,1
1,1,1,0,0,0,0,0,0,1,1,1
1,1,0,0,0,0,0,17,11,6,1,1
1,1,1,0,0,0,0,10,16,15,13,1
1,1,1,1,0,1,1,14,11,7,11,1
1,1,1,1,1,1,1,1,12,11,2,1
1,1,1,1,1,1,1,1,1,0,1,1
endlayer

layer
1,1,1,1,1,1,1,1,1,1,1,1
1,17,15,5,1,1,1,1,1,1,1,1
1,14,0,11,5,1,0,0,0,1,1,1
1,8,11,7,13,15,0,0,0,0,1,1
1,1,10,11,11,15,13,0,0,0,1,1
1,1,1,12,14,11,0,15,0,0,1,1
1,1,0,0,12,0,11,13,13,1,1,1
1,1,0,0,0,14,12,11,15,5,1,1
1,1,0,0,0,0,14,11,7,15,5,1
1,1,1,0,0,0,1,10,2,7,13,1
1,1,1,1,1,1,1,1,10,12,17,1
1,1,1,1,1,1,1,1,1,0,1,1
endlayer

layer
1,1,15,1,1,1,1,1,1,1,1,1
1,14,15,15,17,1,1,1,1,1,1,1
14,14,7,11,13,1,0,0,0,1,1,1
1,12,2,16,0,15,0,0,0,0,1,1
1,17,8,0,2,6,13,0,0,0,1,1
1,1,1,10,19,18,2,15,0,0,1,1
1,1,0,0,12,2,18,6,13,1,1,1
1,1,0,0,0,14,16,2,0,13,17,1
1,1,0,0,0,0,8,2,16,19,13,1
1,1,1,0,0,0,1,8,14,7,13,13
1,1,1,1,1,1,1,17,12,12,12,1
1,1,1,1,1,1,1,1,1,12,1,1
endlayer

layer
1,1,1,1,1,1,1,1,1,1,1,1
1,0,11,0,0,1,1,0,1,1,1,1
1,11,17,15,5,11,0,0,0,1,1,1
1,0,14,6,5,5,11,0,0,0,1,1
1,0,8,11,16,0,5,11,0,0,0,1
1,1,11,8,19,16,19,6,11,0,1,1
1,1,0,11,8,0,16,6,6,11,1,1
1,0,0,0,11,10,19,16,5,6,0,1
1,1,0,0,0,11,10,11,20,13,0,1
1,1,1,0,0,0,11,10,12,17,11,1
1,1,1,1,0,1,1,0,0,11,0,1
1,1,1,1,1,1,1,1,1,1,1,1
endlayer

layer
1,1,1,1,1,1,1,1,1,1,1,1
1,1,0,0,1,1,0,0,0,1,1,1
1,0,0,0,0,0,0,0,0,0,1,1
1,0,0,11,6,0,0,0,0,0,0,1
1,1,0,10,19,5,0,0,0,0,0,1
1,1,0,0,8,5,2,0,0,0,0,1
1,0,0,0,0,2,10,6,0,0,1,1
1,0,0,0,0,0,10,19,5,0,1,1
1,0,0,0,0,0,0,8,11,0,0,1
1,1,0,0,0,0,0,0,0,0,0,1
1,1,1,0,0,0,1,1,0,0,1,1
1,1,1,1,1,1,1,1,1,1,1,1
endlayer

