
# Created by Ruins mod version 16.7 Ingame Parser
# authoring Player: lafuller

weight=1
embed_into_distance=5
acceptable_target_blocks=
unacceptable_target_blocks=flowing_water,water,flowing_lava,lava,ice,bedrock,netherrack,nether_brick,nether_brick_fence,soul_sand,quartz_ore,gravel,end_stone,obsidian,iron_bars,cloud,flesh,ash_block,slime_grass,slime_congealed,slime_dirt
dimensions=23,17,17
allowable_overhang=0
max_leveling=5
leveling_buffer=-1
preserve_water=0
preserve_lava=0

rule1=0,100,stonebrick-0,stonebrick-1,stonebrick-1,stonebrick-1,stonebrick-2,stonebrick-2,stone-5,stone-5,stone-6,cobblestone,cobblestone
rule2=0,100,minecraft:stone_brick_stairs-0
rule3=0,100,minecraft:stone_brick_stairs-2
rule4=0,100,minecraft:stone_brick_stairs-3
rule5=0,100,minecraft:stone_brick_stairs-1
rule6=0,100,preserveBlock
rule7=0,100,minecraft:stone_brick_stairs-4
rule8=0,100,minecraft:stone_slab-5
rule9=0,100,minecraft:cobblestone_wall-0
rule10=0,100,minecraft:stone_brick_stairs-6
rule11=0,100,minecraft:stone_brick_stairs-7
rule12=0,100,minecraft:stone_brick_stairs-5
rule13=0,100,minecraft:stone_slab-13

layer
1,1,1,1,1,1,1,2,2,2,1,1,1,1,1,1,1
1,1,1,1,1,1,1,1,1,1,1,1,1,1,1,1,1
1,1,1,1,1,1,1,1,1,1,1,1,1,1,1,1,1
1,1,1,1,1,1,1,1,1,1,1,1,1,1,1,1,1
1,1,1,1,1,1,1,1,1,1,1,1,1,1,1,1,1
1,1,1,1,1,1,1,1,1,1,1,1,1,1,1,1,1
1,1,1,1,1,1,1,1,1,1,1,1,1,1,1,1,1
4,1,1,1,1,1,1,1,1,1,1,1,1,1,1,1,3
4,1,1,1,1,1,1,1,1,1,1,1,1,1,1,1,3
4,1,1,1,1,1,1,1,1,1,1,1,1,1,1,1,3
1,1,1,1,1,1,1,1,1,1,1,1,1,1,1,1,1
1,1,1,1,1,1,1,1,1,1,1,1,1,1,1,1,1
1,1,1,1,1,1,1,1,1,1,1,1,1,1,1,1,1
1,1,1,1,1,1,1,1,1,1,1,1,1,1,1,1,1
1,1,1,1,1,1,1,1,1,1,1,1,1,1,1,1,1
1,1,1,1,1,1,1,1,1,1,1,1,1,1,1,1,1
1,1,1,1,1,1,1,5,5,5,1,1,1,1,1,1,1
endlayer

layer
1,1,1,1,1,1,1,6,6,6,1,1,1,1,1,1,1
1,1,1,1,1,1,1,2,2,2,1,1,1,1,1,1,1
1,1,1,1,1,1,1,1,1,1,1,1,1,1,1,1,1
1,1,1,1,1,1,1,1,1,1,1,1,1,1,1,1,1
1,1,1,1,1,1,1,1,1,1,1,1,1,1,1,1,1
1,1,1,1,1,1,1,1,1,1,1,1,1,1,1,1,1
1,1,1,1,1,1,1,1,1,1,1,1,1,1,1,1,1
6,4,1,1,1,1,1,1,1,1,1,1,1,1,1,3,6
6,4,1,1,1,1,1,1,1,1,1,1,1,1,1,3,6
6,4,1,1,1,1,1,1,1,1,1,1,1,1,1,3,6
1,1,1,1,1,1,1,1,1,1,1,1,1,1,1,1,1
1,1,1,1,1,1,1,1,1,1,1,1,1,1,1,1,1
1,1,1,1,1,1,1,1,1,1,1,1,1,1,1,1,1
1,1,1,1,1,1,1,1,1,1,1,1,1,1,1,1,1
1,1,1,1,1,1,1,1,1,1,1,1,1,1,1,1,1
1,1,1,1,1,1,1,5,5,5,1,1,1,1,1,1,1
1,1,1,1,1,1,1,6,6,6,1,1,1,1,1,1,1
endlayer

layer
1,1,6,1,5,1,1,6,6,6,1,1,5,1,6,1,1
1,1,6,1,6,1,1,6,6,6,1,1,6,1,6,1,1
6,6,1,1,1,1,1,2,2,2,1,1,1,1,1,6,6
1,1,1,1,1,1,1,1,1,1,1,1,1,1,1,1,1
3,6,1,1,1,1,1,1,1,1,1,1,1,1,1,6,4
1,1,1,1,1,1,1,1,1,1,1,1,1,1,1,1,1
1,1,1,1,1,1,1,1,1,1,1,1,1,1,1,1,1
6,6,4,1,1,1,1,1,1,1,1,1,1,1,3,6,6
6,6,4,1,1,1,1,1,1,1,1,1,1,1,3,6,6
6,6,4,1,1,1,1,1,1,1,1,1,1,1,3,6,6
1,1,1,1,1,1,1,1,1,1,1,1,1,1,1,1,1
1,1,1,1,1,1,1,1,1,1,1,1,1,1,1,1,1
3,6,1,1,1,1,1,1,1,1,1,1,1,1,1,6,4
1,1,1,1,1,1,1,1,1,1,1,1,1,1,1,1,1
6,6,1,1,1,1,1,5,5,5,1,1,1,1,1,6,6
1,1,6,1,6,1,1,6,6,6,1,1,6,1,6,1,1
1,1,6,1,2,1,1,6,6,6,1,1,2,1,6,1,1
endlayer

layer
1,1,6,1,6,1,1,6,6,6,1,1,6,1,6,1,1
1,1,6,1,6,1,1,6,6,6,1,1,6,1,6,1,1
6,6,1,1,1,1,1,6,6,6,1,1,1,1,1,6,6
1,1,1,1,1,1,1,2,2,2,1,1,1,1,1,1,1
6,6,1,1,1,1,1,1,1,1,1,1,1,1,1,6,6
1,1,1,1,1,1,1,1,1,1,1,1,1,1,1,1,1
1,1,1,1,1,1,1,1,1,1,1,1,1,1,1,1,1
6,6,6,4,1,1,1,1,1,1,1,1,1,3,6,6,6
6,6,6,4,1,1,1,1,1,1,1,1,1,3,6,6,6
6,6,6,4,1,1,1,1,1,1,1,1,1,3,6,6,6
1,1,1,1,1,1,1,1,1,1,1,1,1,1,1,1,1
1,1,1,1,1,1,1,1,1,1,1,1,1,1,1,1,1
6,6,1,1,1,1,1,1,1,1,1,1,1,1,1,6,6
1,1,1,1,1,1,1,5,5,5,1,1,1,1,1,1,1
6,6,1,1,1,1,1,6,6,6,1,1,1,1,1,6,6
1,1,6,1,6,1,1,6,6,6,1,1,6,1,6,1,1
1,1,6,1,6,1,1,6,6,6,1,1,6,1,6,1,1
endlayer

layer
6,2,1,1,6,1,1,6,6,6,1,1,6,1,1,2,6
4,1,1,1,6,1,1,6,6,6,1,1,6,1,1,1,3
1,1,1,1,1,1,1,6,6,6,1,1,1,1,1,1,1
1,1,1,1,1,1,1,6,6,6,1,1,1,1,1,1,1
6,6,1,1,1,1,1,2,2,2,1,1,1,1,1,6,6
1,1,1,1,1,1,5,2,2,2,5,1,1,1,1,1,1
1,1,1,1,1,3,1,1,1,1,1,4,1,1,1,1,1
6,6,6,6,4,4,1,3,5,4,1,3,3,6,6,6,6
6,6,6,6,4,4,1,3,0,4,1,3,3,6,6,6,6
6,6,6,6,4,4,1,3,2,2,1,3,3,6,6,6,6
1,1,1,1,1,3,1,1,1,1,1,4,1,1,1,1,1
1,1,1,1,1,1,2,5,5,5,2,1,1,1,1,1,1
6,6,1,1,1,1,1,5,5,5,1,1,1,1,1,6,6
1,1,1,1,1,1,1,6,6,6,1,1,1,1,1,1,1
1,1,1,1,1,1,1,6,6,6,1,1,1,1,1,1,1
4,1,1,1,6,1,1,6,6,6,1,1,6,1,1,1,3
6,5,1,1,6,1,1,6,6,6,1,1,6,1,1,5,6
endlayer

layer
6,6,6,2,7,2,1,6,6,6,1,2,7,2,6,6,6
6,1,2,5,1,1,1,6,6,6,1,1,1,5,2,1,6
6,4,8,6,9,6,1,6,6,6,1,6,9,6,8,3,6
4,3,6,0,0,0,0,0,0,0,0,0,0,0,6,4,3
11,1,9,0,0,0,0,0,0,0,0,0,0,0,9,1,10
4,1,6,0,0,0,0,0,0,0,0,0,0,0,6,1,3
1,1,1,0,0,0,0,2,5,2,0,0,0,0,1,1,1
6,6,6,0,0,0,4,0,0,0,3,0,0,0,6,6,6
6,6,6,0,0,0,3,0,0,0,4,0,0,0,6,6,6
6,6,6,0,0,0,4,0,0,0,3,0,0,0,6,6,6
1,1,1,0,0,0,0,5,2,5,0,0,0,0,1,1,1
4,1,6,0,0,0,0,0,0,0,0,0,0,0,6,1,3
11,1,9,0,0,0,0,0,0,0,0,0,0,0,9,1,10
4,3,6,0,0,0,0,0,0,0,0,0,0,0,6,4,3
6,4,8,6,9,6,1,6,6,6,1,6,9,6,8,3,6
6,1,5,2,1,1,1,6,6,6,1,1,1,2,5,1,6
6,6,6,5,12,5,1,6,6,6,1,5,12,5,6,6,6
endlayer

layer
6,6,6,6,9,6,9,6,6,6,9,6,9,6,6,6,6
6,9,6,6,1,1,1,6,6,6,1,1,1,6,6,9,6
6,6,6,6,9,6,9,0,0,0,9,6,9,6,6,6,6
6,6,6,0,0,0,0,0,0,0,0,0,0,0,6,6,6
9,1,9,0,0,0,0,0,0,0,0,0,0,0,9,1,9
6,1,6,0,0,0,0,0,0,0,0,0,0,0,6,1,6
9,1,9,0,0,0,0,0,0,0,0,0,0,0,9,1,9
6,6,0,0,0,0,0,0,0,0,0,0,0,0,0,6,6
6,6,0,0,0,0,0,0,0,0,0,0,0,0,0,6,6
6,6,0,0,0,0,0,0,0,0,0,0,0,0,0,6,6
9,1,9,0,0,0,0,0,0,0,0,0,0,0,9,1,9
6,1,6,0,0,0,0,0,0,0,0,0,0,0,6,1,6
9,1,9,0,0,0,0,0,0,0,0,0,0,0,9,1,9
6,6,6,0,0,0,0,0,0,0,0,0,0,0,6,6,6
6,6,6,6,9,6,9,0,0,0,9,6,9,6,6,6,6
6,9,6,6,1,1,1,6,6,6,1,1,1,6,6,9,6
6,6,6,6,9,6,9,6,6,6,9,6,9,6,6,6,6
endlayer

layer
6,6,6,6,9,6,9,6,6,6,9,6,9,6,6,6,6
6,9,6,6,1,6,1,0,0,0,1,6,1,6,6,9,6
6,6,6,6,9,6,9,0,0,0,9,6,9,6,6,6,6
6,6,6,0,0,0,0,0,0,0,0,0,0,0,6,6,6
9,1,9,0,0,0,0,0,0,0,0,0,0,0,9,1,9
6,6,6,0,0,0,0,0,0,0,0,0,0,0,6,6,6
9,1,9,0,0,0,0,0,0,0,0,0,0,0,9,1,9
6,0,0,0,0,0,0,0,0,0,0,0,0,0,0,0,6
6,0,0,0,0,0,0,0,0,0,0,0,0,0,0,0,6
6,0,0,0,0,0,0,0,0,0,0,0,0,0,0,0,6
9,1,9,0,0,0,0,0,0,0,0,0,0,0,9,1,9
6,6,6,0,0,0,0,0,0,0,0,0,0,0,6,6,6
9,1,9,0,0,0,0,0,0,0,0,0,0,0,9,1,9
6,6,6,0,0,0,0,0,0,0,0,0,0,0,6,6,6
6,6,6,6,9,6,9,0,0,0,9,6,9,6,6,6,6
6,9,6,6,1,6,1,0,0,0,1,6,1,6,6,9,6
6,6,6,6,9,6,9,6,6,6,9,6,9,6,6,6,6
endlayer

layer
6,6,6,6,9,6,9,0,0,0,9,6,9,6,6,6,6
6,8,2,7,1,6,1,0,0,0,1,6,1,7,7,8,6
6,4,1,1,1,6,9,0,0,0,9,6,1,1,1,10,6
6,11,1,9,0,0,0,0,0,0,0,0,0,9,1,10,6
9,1,1,0,0,0,0,0,0,0,0,0,0,0,1,1,9
6,6,6,0,0,0,0,0,0,0,0,0,0,0,6,6,6
9,1,9,0,0,0,0,0,0,0,0,0,0,0,9,1,9
0,0,0,0,0,0,0,0,0,0,0,0,0,0,0,0,0
0,0,0,0,0,0,0,0,0,0,0,0,0,0,0,0,0
0,0,0,0,0,0,0,0,0,0,0,0,0,0,0,0,0
9,1,9,0,0,0,0,0,0,0,0,0,0,0,9,1,9
6,6,6,0,0,0,0,0,0,0,0,0,0,0,6,6,6
9,1,1,0,0,0,0,0,0,0,0,0,0,0,1,1,9
6,11,1,9,0,0,0,0,0,0,0,0,0,9,1,10,6
6,11,1,1,1,6,9,0,0,0,9,6,1,1,1,10,6
6,8,12,12,1,6,1,0,0,0,1,6,1,12,12,8,6
6,6,6,6,9,6,9,0,0,0,9,6,9,6,6,6,6
endlayer

layer
6,6,6,6,2,7,2,0,0,0,2,7,2,6,6,6,6
6,6,6,4,1,1,1,0,0,0,1,1,1,3,6,6,6
6,6,8,1,1,1,1,13,0,13,1,1,1,1,8,6,6
6,2,1,1,0,9,0,0,0,0,0,9,0,1,1,2,6
4,1,1,0,0,0,0,0,0,0,0,0,0,0,1,1,3
11,1,1,9,0,0,0,0,0,0,0,0,0,9,1,1,10
4,1,1,0,0,0,0,0,0,0,0,0,0,0,1,1,3
0,0,13,0,0,0,0,0,0,0,0,0,0,0,13,0,0
0,0,0,0,0,0,0,0,0,0,0,0,0,0,0,0,0
0,0,13,0,0,0,0,0,0,0,0,0,0,0,13,0,0
4,1,1,0,0,0,0,0,0,0,0,0,0,0,1,1,3
11,1,1,9,0,0,0,0,0,0,0,0,0,9,1,1,10
4,1,1,0,0,0,0,0,0,0,0,0,0,0,1,1,3
6,5,1,1,0,9,0,0,0,0,0,9,0,1,1,5,6
6,6,8,1,1,1,1,13,0,13,1,1,1,1,8,6,6
6,6,6,4,1,1,1,0,0,0,1,1,1,3,6,6,6
6,6,6,6,5,12,5,0,0,0,5,12,5,6,6,6,6
endlayer

layer
6,6,6,6,6,6,6,0,0,0,6,6,6,6,6,6,6
6,6,6,6,6,6,2,7,7,7,2,6,6,6,6,6,6
6,6,6,6,6,9,5,1,13,1,5,9,6,6,6,6,6
6,6,6,9,0,9,0,9,0,9,0,9,0,9,6,6,6
6,6,6,0,0,0,0,0,0,0,0,0,0,0,6,6,6
6,6,9,9,0,0,0,0,0,0,0,0,0,9,9,6,6
6,4,3,0,0,0,0,0,0,0,0,0,0,0,4,3,6
0,11,1,9,0,0,0,0,0,0,0,0,0,9,1,10,0
0,11,13,0,0,0,0,0,0,0,0,0,0,0,13,10,0
0,11,1,9,0,0,0,0,0,0,0,0,0,9,1,10,0
6,4,3,0,0,0,0,0,0,0,0,0,0,0,4,3,6
6,6,9,9,0,0,0,0,0,0,0,0,0,9,9,6,6
6,6,6,0,0,0,0,0,0,0,0,0,0,0,6,6,6
6,6,6,9,0,9,0,9,0,9,0,9,0,9,6,6,6
6,6,6,6,6,9,2,1,13,1,2,9,6,6,6,6,6
6,6,6,6,6,6,5,12,12,12,5,6,6,6,6,6,6
6,6,6,6,6,6,6,0,0,0,6,6,6,6,6,6,6
endlayer

layer
6,6,6,6,6,6,6,6,6,6,6,6,6,6,6,6,6
6,6,6,6,6,6,6,6,6,6,6,6,6,6,6,6,6
6,6,6,6,6,9,6,9,6,9,6,9,6,6,6,6,6
6,6,6,9,0,9,0,9,0,9,0,9,0,9,6,6,6
6,6,6,0,0,0,0,0,0,0,0,0,0,0,6,6,6
6,6,9,9,0,0,0,0,0,0,0,0,0,9,9,6,6
6,6,6,0,0,0,0,0,0,0,0,0,0,0,6,6,6
6,6,9,9,0,0,0,0,0,0,0,0,0,9,9,6,6
6,6,6,0,0,0,0,0,0,0,0,0,0,0,6,6,6
6,6,9,9,0,0,0,0,0,0,0,0,0,9,9,6,6
6,6,6,0,0,0,0,0,0,0,0,0,0,0,6,6,6
6,6,9,9,0,0,0,0,0,0,0,0,0,9,9,6,6
6,6,6,0,0,0,0,0,0,0,0,0,0,0,6,6,6
6,6,6,9,0,9,0,9,0,9,0,9,0,9,6,6,6
6,6,6,6,6,9,6,9,6,9,6,9,6,6,6,6,6
6,6,6,6,6,6,6,6,6,6,6,6,6,6,6,6,6
6,6,6,6,6,6,6,6,6,6,6,6,6,6,6,6,6
endlayer

layer
6,6,6,6,6,6,6,6,6,6,6,6,6,6,6,6,6
6,6,6,6,6,6,6,6,6,6,6,6,6,6,6,6,6
6,6,6,6,6,9,6,9,6,9,6,9,6,6,6,6,6
6,6,6,8,7,1,0,9,0,9,0,1,7,8,6,6,6
6,6,6,11,9,0,0,0,0,0,0,0,9,10,6,6,6
6,6,9,1,0,0,0,0,0,0,0,0,0,1,9,6,6
6,6,6,0,0,0,0,0,0,0,0,0,0,0,6,6,6
6,6,9,9,0,0,0,0,0,0,0,0,0,9,9,6,6
6,6,6,0,0,0,0,0,0,0,0,0,0,0,6,6,6
6,6,9,9,0,0,0,0,0,0,0,0,0,9,9,6,6
6,6,6,0,0,0,0,0,0,0,0,0,0,0,6,6,6
6,6,9,1,0,0,0,0,0,0,0,0,0,1,9,6,6
6,6,6,11,9,0,0,0,0,0,0,0,9,10,6,6,6
6,6,6,8,12,1,0,9,0,9,0,1,12,8,6,6,6
6,6,6,6,6,9,6,9,6,9,6,9,6,6,6,6,6
6,6,6,6,6,6,6,6,6,6,6,6,6,6,6,6,6
6,6,6,6,6,6,6,6,6,6,6,6,6,6,6,6,6
endlayer

layer
6,6,6,6,6,6,6,6,6,6,6,6,6,6,6,6,6
6,6,6,6,6,6,6,6,6,6,6,6,6,6,6,6,6
6,6,6,6,6,2,7,9,6,9,7,2,6,6,6,6,6
6,6,6,6,6,1,1,1,0,1,1,1,6,6,6,6,6
6,6,6,6,1,0,9,0,0,0,9,0,1,6,6,6,6
6,6,4,1,0,0,0,0,0,0,0,0,0,1,3,6,6
6,6,11,1,9,0,0,0,0,0,0,0,9,1,10,6,6
6,6,9,1,0,0,0,0,0,0,0,0,0,1,9,6,6
6,6,6,0,0,0,0,0,0,0,0,0,0,0,6,6,6
6,6,9,1,0,0,0,0,0,0,0,0,0,1,9,6,6
6,6,11,1,9,0,0,0,0,0,0,0,9,1,10,6,6
6,6,4,1,0,0,0,0,0,0,0,0,0,1,3,6,6
6,6,6,6,1,0,9,0,0,0,9,0,1,6,6,6,6
6,6,6,6,6,1,1,1,0,1,1,1,6,6,6,6,6
6,6,6,6,6,5,12,9,6,9,12,5,6,6,6,6,6
6,6,6,6,6,6,6,6,6,6,6,6,6,6,6,6,6
6,6,6,6,6,6,6,6,6,6,6,6,6,6,6,6,6
endlayer

layer
6,6,6,6,6,6,6,6,6,6,6,6,6,6,6,6,6
6,6,6,6,6,6,6,6,6,6,6,6,6,6,6,6,6
6,6,6,6,6,6,6,2,7,2,6,6,6,6,6,6,6
6,6,6,6,6,6,6,1,8,1,6,6,6,6,6,6,6
6,6,6,6,9,0,1,0,0,0,1,0,9,6,6,6,6
6,6,6,6,0,0,0,0,0,0,0,0,0,6,6,6,6
6,6,6,6,1,0,0,0,0,0,0,0,1,6,6,6,6
6,6,4,1,0,0,0,0,0,0,0,0,0,1,3,6,6
6,6,11,8,0,0,0,0,0,0,0,0,0,8,10,6,6
6,6,4,1,0,0,0,0,0,0,0,0,0,1,3,6,6
6,6,6,6,1,0,0,0,0,0,0,0,1,6,6,6,6
6,6,6,6,0,0,0,0,0,0,0,0,0,6,6,6,6
6,6,6,6,9,0,1,0,0,0,1,0,9,6,6,6,6
6,6,6,6,6,6,6,1,8,1,6,6,6,6,6,6,6
6,6,6,6,6,6,6,5,12,5,6,6,6,6,6,6,6
6,6,6,6,6,6,6,6,6,6,6,6,6,6,6,6,6
6,6,6,6,6,6,6,6,6,6,6,6,6,6,6,6,6
endlayer

layer
6,6,6,6,6,6,6,6,6,6,6,6,6,6,6,6,6
6,6,6,6,6,6,6,6,6,6,6,6,6,6,6,6,6
6,6,6,6,6,6,6,6,6,6,6,6,6,6,6,6,6
6,6,6,6,6,6,6,6,6,6,6,6,6,6,6,6,6
6,6,6,6,9,0,9,0,0,0,9,0,9,6,6,6,6
6,6,6,6,0,0,0,0,0,0,0,0,0,6,6,6,6
6,6,6,6,9,0,0,0,0,0,0,0,9,6,6,6,6
6,6,6,6,0,0,0,0,0,0,0,0,0,6,6,6,6
6,6,6,6,0,0,0,0,0,0,0,0,0,6,6,6,6
6,6,6,6,0,0,0,0,0,0,0,0,0,6,6,6,6
6,6,6,6,9,0,0,0,0,0,0,0,9,6,6,6,6
6,6,6,6,0,0,0,0,0,0,0,0,0,6,6,6,6
6,6,6,6,9,0,9,0,0,0,9,0,9,6,6,6,6
6,6,6,6,6,6,6,6,6,6,6,6,6,6,6,6,6
6,6,6,6,6,6,6,6,6,6,6,6,6,6,6,6,6
6,6,6,6,6,6,6,6,6,6,6,6,6,6,6,6,6
6,6,6,6,6,6,6,6,6,6,6,6,6,6,6,6,6
endlayer

layer
6,6,6,6,6,6,6,6,6,6,6,6,6,6,6,6,6
6,6,6,6,6,6,6,6,6,6,6,6,6,6,6,6,6
6,6,6,6,6,6,6,6,6,6,6,6,6,6,6,6,6
6,6,6,6,6,6,6,6,6,6,6,6,6,6,6,6,6
6,6,6,6,8,7,9,0,0,0,9,7,8,6,6,6,6
6,6,6,6,11,9,0,0,0,0,0,9,10,6,6,6,6
6,6,6,6,9,0,0,0,0,0,0,0,9,6,6,6,6
6,6,6,6,0,0,0,0,0,0,0,0,0,6,6,6,6
6,6,6,6,0,0,0,0,0,0,0,0,0,6,6,6,6
6,6,6,6,0,0,0,0,0,0,0,0,0,6,6,6,6
6,6,6,6,9,0,0,0,0,0,0,0,9,6,6,6,6
6,6,6,6,11,9,0,0,0,0,0,9,10,6,6,6,6
6,6,6,6,8,12,9,0,0,0,9,12,8,6,6,6,6
6,6,6,6,6,6,6,6,6,6,6,6,6,6,6,6,6
6,6,6,6,6,6,6,6,6,6,6,6,6,6,6,6,6
6,6,6,6,6,6,6,6,6,6,6,6,6,6,6,6,6
6,6,6,6,6,6,6,6,6,6,6,6,6,6,6,6,6
endlayer

layer
6,6,6,6,6,6,6,6,6,6,6,6,6,6,6,6,6
6,6,6,6,6,6,6,6,6,6,6,6,6,6,6,6,6
6,6,6,6,6,6,6,6,6,6,6,6,6,6,6,6,6
6,6,6,6,6,6,6,6,6,6,6,6,6,6,6,6,6
6,6,6,6,6,6,2,7,7,7,2,6,6,6,6,6,6
6,6,6,6,6,1,12,9,0,9,12,1,6,6,6,6,6
6,6,6,6,4,10,0,0,0,0,0,11,3,6,6,6,6
6,6,6,6,11,9,0,0,0,0,0,9,10,6,6,6,6
6,6,6,6,11,0,0,0,0,0,0,0,10,6,6,6,6
6,6,6,6,11,9,0,0,0,0,0,9,10,6,6,6,6
6,6,6,6,4,10,0,0,0,0,0,11,3,6,6,6,6
6,6,6,6,6,1,7,9,0,9,7,1,6,6,6,6,6
6,6,6,6,6,6,5,12,12,12,5,6,6,6,6,6,6
6,6,6,6,6,6,6,6,6,6,6,6,6,6,6,6,6
6,6,6,6,6,6,6,6,6,6,6,6,6,6,6,6,6
6,6,6,6,6,6,6,6,6,6,6,6,6,6,6,6,6
6,6,6,6,6,6,6,6,6,6,6,6,6,6,6,6,6
endlayer

layer
6,6,6,6,6,6,6,6,6,6,6,6,6,6,6,6,6
6,6,6,6,6,6,6,6,6,6,6,6,6,6,6,6,6
6,6,6,6,6,6,6,6,6,6,6,6,6,6,6,6,6
6,6,6,6,6,6,6,6,6,6,6,6,6,6,6,6,6
6,6,6,6,6,6,6,6,2,6,6,6,6,6,6,6,6
6,6,6,6,6,6,6,1,8,1,6,6,6,6,6,6,6
6,6,6,6,6,6,0,0,0,0,0,6,6,6,6,6,6
6,6,6,6,6,1,0,0,0,0,0,1,6,6,6,6,6
6,6,6,6,4,8,0,0,0,0,0,8,3,6,6,6,6
6,6,6,6,6,1,0,0,0,0,0,1,6,6,6,6,6
6,6,6,6,6,6,0,0,0,0,0,6,6,6,6,6,6
6,6,6,6,6,6,6,1,8,1,6,6,6,6,6,6,6
6,6,6,6,6,6,6,6,5,6,6,6,6,6,6,6,6
6,6,6,6,6,6,6,6,6,6,6,6,6,6,6,6,6
6,6,6,6,6,6,6,6,6,6,6,6,6,6,6,6,6
6,6,6,6,6,6,6,6,6,6,6,6,6,6,6,6,6
6,6,6,6,6,6,6,6,6,6,6,6,6,6,6,6,6
endlayer

layer
6,6,6,6,6,6,6,6,6,6,6,6,6,6,6,6,6
6,6,6,6,6,6,6,6,6,6,6,6,6,6,6,6,6
6,6,6,6,6,6,6,6,6,6,6,6,6,6,6,6,6
6,6,6,6,6,6,6,6,6,6,6,6,6,6,6,6,6
6,6,6,6,6,6,6,6,6,6,6,6,6,6,6,6,6
6,6,6,6,6,6,6,9,6,9,6,6,6,6,6,6,6
6,6,6,6,6,6,0,0,0,0,0,6,6,6,6,6,6
6,6,6,6,6,9,0,0,0,0,0,9,6,6,6,6,6
6,6,6,6,6,6,0,0,0,0,0,6,6,6,6,6,6
6,6,6,6,6,9,0,0,0,0,0,9,6,6,6,6,6
6,6,6,6,6,6,0,0,0,0,0,6,6,6,6,6,6
6,6,6,6,6,6,6,9,6,9,6,6,6,6,6,6,6
6,6,6,6,6,6,6,6,6,6,6,6,6,6,6,6,6
6,6,6,6,6,6,6,6,6,6,6,6,6,6,6,6,6
6,6,6,6,6,6,6,6,6,6,6,6,6,6,6,6,6
6,6,6,6,6,6,6,6,6,6,6,6,6,6,6,6,6
6,6,6,6,6,6,6,6,6,6,6,6,6,6,6,6,6
endlayer

layer
6,6,6,6,6,6,6,6,6,6,6,6,6,6,6,6,6
6,6,6,6,6,6,6,6,6,6,6,6,6,6,6,6,6
6,6,6,6,6,6,6,6,6,6,6,6,6,6,6,6,6
6,6,6,6,6,6,6,6,6,6,6,6,6,6,6,6,6
6,6,6,6,6,6,6,6,6,6,6,6,6,6,6,6,6
6,6,6,6,6,6,6,9,6,9,6,6,6,6,6,6,6
6,6,6,6,6,6,0,0,0,0,0,6,6,6,6,6,6
6,6,6,6,6,9,0,0,0,0,0,9,6,6,6,6,6
6,6,6,6,6,6,0,0,0,0,0,6,6,6,6,6,6
6,6,6,6,6,9,0,0,0,0,0,9,6,6,6,6,6
6,6,6,6,6,6,0,0,0,0,0,6,6,6,6,6,6
6,6,6,6,6,6,6,9,6,9,6,6,6,6,6,6,6
6,6,6,6,6,6,6,6,6,6,6,6,6,6,6,6,6
6,6,6,6,6,6,6,6,6,6,6,6,6,6,6,6,6
6,6,6,6,6,6,6,6,6,6,6,6,6,6,6,6,6
6,6,6,6,6,6,6,6,6,6,6,6,6,6,6,6,6
6,6,6,6,6,6,6,6,6,6,6,6,6,6,6,6,6
endlayer

layer
6,6,6,6,6,6,6,6,6,6,6,6,6,6,6,6,6
6,6,6,6,6,6,6,6,6,6,6,6,6,6,6,6,6
6,6,6,6,6,6,6,6,6,6,6,6,6,6,6,6,6
6,6,6,6,6,6,6,6,6,6,6,6,6,6,6,6,6
6,6,6,6,6,6,6,6,6,6,6,6,6,6,6,6,6
6,6,6,6,6,6,6,2,7,2,6,6,6,6,6,6,6
6,6,6,6,6,6,13,12,0,12,13,6,6,6,6,6,6
6,6,6,6,6,4,10,0,0,0,11,3,6,6,6,6,6
6,6,6,6,6,11,0,0,0,0,0,10,6,6,6,6,6
6,6,6,6,6,4,10,0,0,0,11,3,6,6,6,6,6
6,6,6,6,6,6,13,7,0,7,13,6,6,6,6,6,6
6,6,6,6,6,6,6,5,12,5,6,6,6,6,6,6,6
6,6,6,6,6,6,6,6,6,6,6,6,6,6,6,6,6
6,6,6,6,6,6,6,6,6,6,6,6,6,6,6,6,6
6,6,6,6,6,6,6,6,6,6,6,6,6,6,6,6,6
6,6,6,6,6,6,6,6,6,6,6,6,6,6,6,6,6
6,6,6,6,6,6,6,6,6,6,6,6,6,6,6,6,6
endlayer

layer
6,6,6,6,6,6,6,6,6,6,6,6,6,6,6,6,6
6,6,6,6,6,6,6,6,6,6,6,6,6,6,6,6,6
6,6,6,6,6,6,6,6,6,6,6,6,6,6,6,6,6
6,6,6,6,6,6,6,6,6,6,6,6,6,6,6,6,6
6,6,6,6,6,6,6,6,6,6,6,6,6,6,6,6,6
6,6,6,6,6,6,6,6,6,6,6,6,6,6,6,6,6
6,6,6,6,6,6,6,2,5,2,6,6,6,6,6,6,6
6,6,6,6,6,6,4,0,0,0,3,6,6,6,6,6,6
6,6,6,6,6,6,3,0,0,0,4,6,6,6,6,6,6
6,6,6,6,6,6,4,0,0,0,3,6,6,6,6,6,6
6,6,6,6,6,6,6,5,2,5,6,6,6,6,6,6,6
6,6,6,6,6,6,6,6,6,6,6,6,6,6,6,6,6
6,6,6,6,6,6,6,6,6,6,6,6,6,6,6,6,6
6,6,6,6,6,6,6,6,6,6,6,6,6,6,6,6,6
6,6,6,6,6,6,6,6,6,6,6,6,6,6,6,6,6
6,6,6,6,6,6,6,6,6,6,6,6,6,6,6,6,6
6,6,6,6,6,6,6,6,6,6,6,6,6,6,6,6,6
endlayer

