
# Created by Ruins mod version 17.0 Ingame Parser
# authoring Player: ST753M

weight=1
embed_into_distance=7
acceptable_target_blocks=
unacceptable_target_blocks=flowing_water,water,flowing_lava,lava
dimensions=8,17,17
allowable_overhang=7
max_leveling=2
leveling_buffer=-1
preserve_water=0
preserve_lava=0
uniqueMinDistance=2000
spawnMinDistance=1000

biomesToSpawnIn=swamp_defiled,desert_defiled,plains_defiled,ice_plains_defiled,hills_defiled,forest_tenebra,forest_vilespine

=0,100,air
rule1=0,100,preserveBlock
rule2=2,100,thaumcraft:taint_soil-0,thaumcraft:taint_crust-0
rule3=1,100,thaumcraft:taint_geyser-0
rule4=1,100,thaumcraft:taint_crust-0,thaumcraft:taint_fibre-0,thaumcraft:taint_soil-0,thaumcraft:taint_feature-1,thaumcraft:taint_feature-1
rule5=1,100,thaumcraft:taint_feature-1,thaumcraft:flux_goo-0,thaumcraft:flux_goo-6,thaumcraft:taint_fibre-0,thaumcraft:taint_log-1

layer
1,1,1,1,1,1,1,1,1,1,1,1,1,1,1,1,1
1,1,1,1,1,1,1,1,1,1,1,1,1,1,1,1,1
1,1,1,1,1,1,1,1,1,1,1,1,1,1,1,1,1
1,1,1,1,1,2,2,2,2,2,2,2,1,1,1,1,1
1,1,1,1,2,2,2,2,2,2,2,2,2,1,1,1,1
1,1,1,2,2,2,2,2,2,2,2,2,2,2,1,1,1
1,1,1,2,2,2,2,2,2,2,2,2,2,2,1,1,1
1,1,1,2,2,2,2,2,2,2,2,2,2,2,1,1,1
1,1,1,2,2,2,2,2,2,2,2,2,2,2,1,1,1
1,1,1,2,2,2,2,2,2,2,2,2,2,2,1,1,1
1,1,1,2,2,2,2,2,2,2,2,2,2,2,1,1,1
1,1,1,2,2,2,2,2,2,2,2,2,2,2,1,1,1
1,1,1,1,2,2,2,2,2,2,2,2,2,1,1,1,1
1,1,1,1,1,2,2,2,2,2,2,2,1,1,1,1,1
1,1,1,1,1,1,1,1,1,1,1,1,1,1,1,1,1
1,1,1,1,1,1,1,1,1,1,1,1,1,1,1,1,1
1,1,1,1,1,1,1,1,1,1,1,1,1,1,1,1,1
endlayer

layer
1,1,1,1,1,1,1,1,1,1,1,1,1,1,1,1,1
1,1,1,1,1,1,1,1,1,1,1,1,1,1,1,1,1
1,1,1,1,1,2,2,2,2,2,2,2,1,1,1,1,1
1,1,1,1,2,2,2,2,2,2,2,2,2,1,1,1,1
1,1,1,2,2,2,2,2,2,2,2,2,2,2,1,1,1
1,1,2,2,2,2,2,2,2,2,2,2,2,2,2,1,1
1,1,2,2,2,2,2,2,2,2,2,2,2,2,2,1,1
1,1,2,2,2,2,2,2,3,2,2,2,2,2,2,1,1
1,1,2,2,2,2,2,2,2,2,2,2,2,2,2,1,1
1,1,2,2,2,2,2,2,2,2,2,2,2,2,2,1,1
1,1,2,2,2,2,2,2,2,2,2,2,2,2,2,1,1
1,1,2,2,2,2,2,2,2,2,2,2,2,2,2,1,1
1,1,1,2,2,2,2,2,2,2,2,2,2,2,1,1,1
1,1,1,1,2,2,2,2,2,2,2,2,2,1,1,1,1
1,1,1,1,1,2,2,2,2,2,2,2,1,1,1,1,1
1,1,1,1,1,1,1,1,1,1,1,1,1,1,1,1,1
1,1,1,1,1,1,1,1,1,1,1,1,1,1,1,1,1
endlayer

layer
1,1,1,1,1,1,1,1,1,1,1,1,1,1,1,1,1
1,1,1,1,1,1,2,2,2,2,2,1,1,1,1,1,1
1,1,1,1,2,2,2,2,2,2,2,2,2,1,1,1,1
1,1,1,2,2,2,2,2,2,2,2,2,2,2,1,1,1
1,1,2,2,2,2,2,2,2,2,2,2,2,2,2,1,1
1,1,2,2,2,2,2,2,2,2,2,2,2,2,2,1,1
1,2,2,2,2,2,2,2,2,4,2,2,2,2,2,2,1
1,2,2,2,2,2,5,5,0,5,2,2,2,2,2,2,1
1,2,2,2,2,4,2,5,3,5,2,0,2,2,2,2,1
1,2,2,2,2,2,2,2,4,5,2,2,2,2,2,2,1
1,2,2,2,2,2,2,0,2,2,2,2,2,2,2,2,1
1,1,2,2,2,2,2,2,2,2,2,2,2,2,2,1,1
1,1,2,2,2,2,2,2,2,2,2,2,2,2,2,1,1
1,1,1,2,2,2,2,2,2,2,2,2,2,2,1,1,1
1,1,1,1,2,2,2,2,2,2,2,2,2,1,1,1,1
1,1,1,1,1,1,2,2,2,2,2,1,1,1,1,1,1
1,1,1,1,1,1,1,1,1,1,1,1,1,1,1,1,1
endlayer

layer
1,1,1,1,1,1,1,1,1,1,1,1,1,1,1,1,1
1,1,1,1,1,2,2,2,2,2,2,2,1,1,1,1,1
1,1,1,2,2,2,2,2,2,2,2,2,2,2,1,1,1
1,1,2,2,2,2,2,2,2,2,2,2,2,2,2,1,1
1,1,2,2,2,2,2,2,2,2,2,2,2,2,2,1,1
1,2,2,2,2,2,2,5,4,2,2,2,2,2,2,2,1
1,2,2,2,2,2,4,5,4,0,5,2,2,2,2,2,1
1,2,2,2,2,5,0,0,0,0,5,2,2,2,2,2,1
1,2,2,2,4,4,4,0,0,0,4,0,2,2,2,2,1
1,2,2,2,2,5,3,5,0,0,5,2,2,2,2,2,1
1,2,2,2,2,2,5,5,5,5,4,2,2,2,2,2,1
1,2,2,2,2,2,2,2,2,5,2,2,2,2,2,2,1
1,1,2,2,2,2,2,2,2,2,2,2,2,2,2,1,1
1,1,2,2,2,2,2,2,2,2,2,2,2,2,2,1,1
1,1,1,2,2,2,2,2,2,2,2,2,2,2,1,1,1
1,1,1,1,1,2,2,2,2,2,2,2,1,1,1,1,1
1,1,1,1,1,1,1,1,1,1,1,1,1,1,1,1,1
endlayer

layer
1,1,1,1,1,1,1,2,2,2,1,1,1,1,1,1,1
1,1,1,1,2,2,2,2,2,2,2,2,2,1,1,1,1
1,1,1,2,2,2,2,2,4,2,2,2,2,2,1,1,1
1,1,2,2,2,5,5,2,5,2,4,2,2,2,2,1,1
1,2,2,2,5,5,5,4,4,4,4,2,5,2,2,2,1
1,2,2,2,2,5,3,0,4,4,4,5,4,4,2,2,1
1,2,0,4,5,5,0,0,0,0,0,5,2,2,2,2,1
2,2,2,2,4,0,0,0,0,0,0,4,4,2,2,2,2
2,2,2,5,4,0,0,0,0,0,0,0,3,5,2,2,2
2,2,2,2,5,0,0,0,0,0,0,5,5,5,5,2,2
1,2,2,5,5,4,0,0,0,0,0,5,2,2,2,2,1
1,2,2,5,2,4,4,2,4,5,5,4,4,2,2,2,1
1,2,2,2,2,4,2,5,5,5,5,4,2,2,2,2,1
1,1,2,2,2,2,2,5,5,2,4,2,2,2,2,1,1
1,1,1,2,2,2,2,5,2,2,2,2,2,2,1,1,1
1,1,1,1,2,2,2,2,2,2,2,2,2,1,1,1,1
1,1,1,1,1,1,1,2,2,2,1,1,1,1,1,1,1
endlayer

layer
1,1,1,1,1,1,2,2,2,2,2,1,1,1,1,1,1
1,1,1,1,1,2,5,2,4,2,4,2,1,1,1,1,1
1,1,1,1,2,3,5,5,0,4,5,5,2,1,1,1,1
1,1,1,2,5,0,0,5,0,5,0,5,4,2,1,1,1
1,1,2,4,0,0,0,0,0,4,0,3,0,5,2,1,1
1,2,4,4,5,0,0,0,0,0,0,0,0,4,0,2,1
2,0,4,0,0,0,0,0,0,0,0,0,5,4,4,0,2
2,2,0,4,4,0,0,0,0,0,0,0,0,5,5,2,2
2,0,5,0,0,0,0,0,0,0,0,0,0,0,4,5,2
2,2,5,5,0,0,0,0,0,0,0,0,0,5,0,2,2
2,0,3,0,0,0,0,0,0,0,0,0,4,5,5,0,2
1,2,0,0,5,4,0,4,0,0,0,0,4,0,5,2,1
1,1,2,5,5,0,4,0,0,0,0,0,4,0,2,1,1
1,1,1,2,5,5,5,0,0,3,0,4,4,2,1,1,1
1,1,1,1,2,5,3,0,4,5,5,5,2,1,1,1,1
1,1,1,1,1,2,2,4,2,5,2,2,1,1,1,1,1
1,1,1,1,1,1,2,2,2,2,2,1,1,1,1,1,1
endlayer

layer
1,1,1,1,1,1,2,2,2,2,2,1,1,1,1,1,1
1,1,1,1,2,2,0,0,0,0,0,2,2,1,1,1,1
1,1,1,2,5,0,0,0,0,0,0,0,5,2,1,1,1
1,1,2,5,0,0,0,0,0,0,0,0,0,5,2,1,1
1,2,4,0,0,0,0,0,0,0,0,0,0,0,5,2,1
1,2,4,0,0,0,0,0,0,0,0,0,0,0,0,2,1
2,0,0,0,0,0,0,0,0,0,0,0,0,0,0,0,2
2,0,0,0,0,0,0,0,0,0,0,0,0,0,0,5,2
2,0,0,0,0,0,0,0,0,0,0,0,0,0,0,0,2
2,0,0,0,0,0,0,0,0,0,0,0,0,0,0,0,2
2,0,0,0,0,0,0,0,0,0,0,0,0,0,0,0,2
1,2,0,0,0,0,0,4,0,0,0,0,4,0,0,2,1
1,2,0,0,0,0,0,0,0,0,0,0,0,0,0,2,1
1,1,2,0,0,0,0,0,0,0,0,0,0,5,2,1,1
1,1,1,2,0,0,0,0,0,0,0,0,0,2,1,1,1
1,1,1,1,2,2,0,0,5,0,0,2,2,1,1,1,1
1,1,1,1,1,1,2,2,2,2,2,1,1,1,1,1,1
endlayer

layer
1,1,1,1,1,1,2,2,5,2,2,1,1,1,1,1,1
1,1,1,1,2,2,0,0,0,0,0,2,2,1,1,1,1
1,1,1,2,0,0,0,0,0,0,0,0,0,2,1,1,1
1,1,2,0,0,0,0,0,0,0,0,0,0,0,2,1,1
1,2,0,0,0,0,0,0,0,0,0,0,0,0,0,2,1
1,2,0,0,0,0,0,0,0,0,0,0,0,0,0,2,1
2,0,0,0,0,0,0,0,0,0,0,0,0,0,0,0,2
2,0,0,0,0,0,0,0,0,0,0,0,0,0,0,0,2
0,0,0,0,0,0,0,0,0,0,0,0,0,0,0,0,0
2,0,0,0,0,0,0,0,0,0,0,0,0,0,0,0,2
2,0,0,0,0,0,0,0,0,0,0,0,0,0,0,0,2
1,2,0,0,0,0,0,0,0,0,0,0,0,0,0,2,1
1,2,0,0,0,0,0,0,0,0,0,0,0,0,0,2,1
1,1,2,0,0,0,0,0,0,0,0,0,0,0,2,1,1
1,1,1,2,0,0,0,0,0,0,0,0,0,2,1,1,1
1,1,1,1,2,2,0,0,0,0,0,2,2,1,1,1,1
1,1,1,1,1,1,2,2,0,2,2,1,1,1,1,1,1
endlayer

