
# Created by Ruins mod version 17.0 Ingame Parser
# authoring Player: ST753M

weight=1
embed_into_distance=5
acceptable_target_blocks=
unacceptable_target_blocks=flowing_water,water,flowing_lava,lava,ice,bedrock,netherrack,nether_brick,nether_brick_fence,soul_sand,quartz_ore,end_stone,obsidian,iron_bars,Natura:Cloud,slime_grass,slime_congealed,slime_dirt,clouds,natura:clouds
dimensions=20,21,21
allowable_overhang=5
max_leveling=0
leveling_buffer=-1
preserve_water=0
preserve_lava=0

biomesToSpawnIn=extreme_hills,smaller_extreme_hills,highland,mountain,mountain_foothills,rocky_plains,rocky_plateau,savanna,savanna_rock,mutated_savanna,mutated_savanna_rock,steppe,wasteland,black_desert,oak_savannah,darklands,darklands_plains,abyssal_wastelands,dreadlands,dreadlands_forest,dreadlands_mountains,omothol,dark_realm

=0,100,air
rule1=0,100,preserveBlock
rule2=0,100,iceandfire:chared_stone-0
rule3=0,100,iceandfire:chared_cobblestone-0
rule4=0,100,iceandfire:goldpile-7,iceandfire:goldpile-6,iceandfire:goldpile-5,iceandfire:goldpile-4,iceandfire:goldpile-3,iceandfire:goldpile-2,iceandfire:goldpile-1,iceandfire:goldpile-0,air,air,air
rule5=0,100,IInventory;minecraft:chest;minecraft:rotten_flesh#2#0#1+minecraft:bone#2#0#6+minecraft:rotten_flesh#1#0#10+minecraft:bone#9#0#12+iceandfire:manuscript#1#0#13+iceandfire:silver_sword#{Quality:{}}#0#14+minecraft:bone#8#0#17+minecraft:rotten_flesh#2#0#20+iceandfire:manuscript#1#0#24+iceandfire:manuscript#2#0#25-5
rule6=0,100,IInventory;minecraft:chest;minecraft:bone#6#0#3+minecraft:rotten_flesh#4#0#6+minecraft:bone#4#0#8+minecraft:skull#1#0#10+minecraft:rotten_flesh#2#0#11+minecraft:iron_ingot#3#0#14+minecraft:bone#3#0#16+minecraft:rotten_flesh#3#0#18+minecraft:iron_ingot#2#0#21+minecraft:iron_ingot#1#0#24-3
rule7=0,100,IInventory;minecraft:chest;iceandfire:manuscript#1#0#1+minecraft:rotten_flesh#3#0#6+minecraft:rotten_flesh#2#0#7+minecraft:skull#1#0#12+iceandfire:manuscript#2#0#17+iceandfire:manuscript#2#0#20+minecraft:rotten_flesh#5#0#23-4
rule8=0,100,CommandBlock:RUINSTRIGGER /summon iceandfire:firedragon ~ ~1 ~:@-1

layer
1,1,1,1,1,1,1,1,2,2,2,2,2,1,1,1,1,1,1,1,1
1,1,1,1,1,1,2,2,2,2,2,2,2,2,2,1,1,1,1,1,1
1,1,1,1,2,2,2,2,2,2,2,2,2,2,2,2,2,1,1,1,1
1,1,1,2,2,2,2,2,2,2,2,2,2,2,2,2,2,2,1,1,1
1,1,2,2,2,2,2,2,2,2,2,2,2,2,2,2,2,2,2,1,1
1,1,2,2,2,2,2,2,2,2,2,2,2,2,2,2,2,2,2,1,1
1,2,2,2,2,2,2,2,2,2,2,2,2,2,2,2,2,2,2,2,1
1,2,2,2,2,2,2,2,2,2,2,2,2,2,2,2,2,2,2,2,1
2,2,2,2,2,2,2,2,2,2,2,2,2,2,2,2,2,2,2,2,2
2,2,2,2,2,2,2,2,2,2,2,2,2,2,2,2,2,2,2,2,2
2,2,2,2,2,2,2,2,2,2,2,2,2,2,2,2,2,2,2,2,2
2,2,2,2,2,2,2,2,2,2,2,2,2,2,2,2,2,2,2,2,2
2,2,2,2,2,2,2,2,2,2,2,2,2,2,2,2,2,2,2,2,2
1,2,2,2,2,2,2,2,2,2,2,2,2,2,2,2,2,2,2,2,1
1,2,2,2,2,2,2,2,2,2,2,2,2,2,2,2,2,2,2,2,1
1,1,2,2,2,2,2,2,2,2,2,2,2,2,2,2,2,2,2,1,1
1,1,2,2,2,2,2,2,2,2,2,2,2,2,2,2,2,2,2,1,1
1,1,1,2,2,2,2,2,2,2,2,2,2,2,2,2,2,2,1,1,1
1,1,1,1,2,2,2,2,2,2,2,2,2,2,2,2,2,1,1,1,1
1,1,1,1,1,1,2,2,2,2,2,2,2,2,2,1,1,1,1,1,1
1,1,1,1,1,1,1,1,2,2,2,2,2,1,1,1,1,1,1,1,1
endlayer

layer
1,1,1,1,1,1,1,1,3,3,3,3,3,1,1,1,1,1,1,1,1
1,1,1,1,1,1,3,3,2,3,3,2,2,3,3,1,1,1,1,1,1
1,1,1,1,3,3,2,2,2,2,2,2,2,2,2,3,3,1,1,1,1
1,1,1,3,2,2,2,2,2,2,2,2,2,2,2,2,2,3,1,1,1
1,1,3,2,2,2,2,2,2,2,2,2,2,2,2,2,2,2,3,1,1
1,1,3,2,2,2,2,2,2,2,2,2,2,2,2,2,2,2,3,1,1
1,3,2,2,2,2,2,2,2,2,2,2,2,2,2,2,2,2,2,3,1
1,3,2,2,2,2,2,2,2,2,2,2,2,2,2,2,2,2,2,3,1
3,2,2,2,2,2,2,2,2,2,2,2,2,2,2,2,2,2,2,2,3
3,2,2,2,2,2,2,2,2,2,2,2,2,2,2,2,2,2,2,2,3
3,2,2,2,2,2,2,2,2,2,2,2,2,2,2,2,2,2,2,2,3
3,2,2,2,2,2,2,2,2,2,2,2,2,2,2,2,2,2,2,2,3
3,2,2,2,2,2,2,2,2,2,2,2,2,2,2,2,2,2,2,2,3
1,3,2,2,2,2,2,2,2,2,2,2,2,2,2,2,2,2,2,3,1
1,3,2,2,2,2,2,2,2,2,2,2,2,2,2,2,2,2,2,3,1
1,1,3,2,2,2,2,2,2,2,2,2,2,2,2,2,2,2,3,1,1
1,1,3,2,2,2,2,2,2,2,2,2,2,2,2,2,2,2,3,1,1
1,1,1,3,2,2,2,2,2,2,2,2,2,2,2,2,2,3,1,1,1
1,1,1,1,3,3,2,2,2,2,2,2,2,2,2,3,3,1,1,1,1
1,1,1,1,1,1,3,3,2,2,2,2,2,3,3,1,1,1,1,1,1
1,1,1,1,1,1,1,1,3,3,3,3,3,1,1,1,1,1,1,1,1
endlayer

layer
1,1,1,1,1,1,1,1,3,3,3,3,3,1,1,1,1,1,1,1,1
1,1,1,1,1,1,3,3,2,2,3,2,2,3,3,1,1,1,1,1,1
1,1,1,1,3,3,2,2,2,2,2,2,2,2,2,3,3,1,1,1,1
1,1,1,3,2,2,2,2,2,2,2,2,2,2,2,2,2,3,1,1,1
1,1,3,2,2,2,2,2,2,2,2,2,2,2,2,2,2,2,3,1,1
1,1,3,2,2,2,2,2,2,2,2,2,2,2,2,2,2,2,3,1,1
1,3,2,2,2,2,2,2,2,2,2,2,2,2,2,2,2,2,2,3,1
1,3,2,2,2,2,2,2,2,2,2,2,2,2,2,2,2,2,2,3,1
3,2,2,2,2,2,2,2,2,2,2,2,2,2,2,2,2,2,2,3,3
3,2,2,2,2,2,2,2,2,2,2,2,2,2,2,2,2,2,2,2,3
3,2,2,2,2,2,2,2,2,2,2,2,2,2,2,2,2,2,2,2,3
3,2,2,2,2,2,2,2,2,2,2,2,2,2,2,2,2,2,2,2,3
3,2,2,2,2,2,2,2,2,2,2,2,2,2,2,2,2,2,2,2,3
1,3,2,2,2,2,2,2,2,2,2,2,2,2,2,2,2,2,2,3,1
1,3,2,2,2,2,2,2,2,2,2,2,2,2,2,2,2,2,2,3,1
1,1,3,2,2,2,2,2,2,2,2,2,2,2,2,2,2,2,3,1,1
1,1,3,2,2,2,2,2,2,2,2,2,2,2,2,2,2,2,3,1,1
1,1,1,3,2,2,2,2,2,2,2,2,2,2,2,2,2,3,1,1,1
1,1,1,1,3,3,2,2,2,2,2,2,2,2,2,3,3,1,1,1,1
1,1,1,1,1,1,3,3,2,2,2,2,2,3,3,1,1,1,1,1,1
1,1,1,1,1,1,1,1,3,3,3,3,3,1,1,1,1,1,1,1,1
endlayer

layer
1,1,1,1,1,1,1,1,3,3,3,3,3,1,1,1,1,1,1,1,1
1,1,1,1,1,1,3,3,2,2,2,2,2,3,3,1,1,1,1,1,1
1,1,1,1,3,3,2,2,2,2,2,2,2,2,2,3,3,1,1,1,1
1,1,1,3,2,2,2,2,2,2,2,2,2,2,2,2,2,3,1,1,1
1,1,3,2,2,2,2,2,2,2,2,2,2,2,2,2,2,2,3,1,1
1,1,3,2,2,2,2,2,2,2,2,2,2,2,2,2,2,2,3,1,1
1,3,2,2,2,2,2,2,2,2,2,2,2,2,2,2,2,2,2,3,1
1,3,2,2,2,2,2,2,3,2,2,2,2,2,2,2,2,2,2,3,1
3,2,2,2,2,2,2,3,3,3,2,2,2,2,2,2,2,2,2,2,3
3,2,2,2,2,2,2,2,2,3,3,2,2,2,2,2,2,2,2,2,3
3,2,2,2,2,2,2,2,2,2,2,2,2,2,2,2,2,2,2,2,3
3,2,2,2,2,2,2,2,2,2,2,2,2,2,2,2,2,2,2,2,3
3,2,2,2,2,2,2,2,2,2,2,2,2,2,2,2,2,2,2,2,3
1,3,2,2,2,2,2,2,2,2,2,2,2,2,2,2,2,2,2,3,1
1,3,2,2,2,2,2,2,2,2,2,2,2,2,2,2,2,2,2,3,1
1,1,3,2,2,2,2,2,2,2,2,2,2,2,2,2,2,2,3,1,1
1,1,3,2,2,2,2,2,2,2,2,2,2,2,2,2,2,2,3,1,1
1,1,1,3,2,2,2,2,2,2,2,2,2,2,2,2,2,3,1,1,1
1,1,1,1,3,3,2,2,2,2,2,2,2,2,2,3,3,1,1,1,1
1,1,1,1,1,1,3,3,2,2,2,2,2,3,3,1,1,1,1,1,1
1,1,1,1,1,1,1,1,3,3,3,3,3,1,1,1,1,1,1,1,1
endlayer

layer
1,1,1,1,1,1,1,1,2,2,2,2,2,1,1,1,1,1,1,1,1
1,1,1,1,1,1,2,2,2,2,2,2,2,2,2,1,1,1,1,1,1
1,1,1,1,3,2,2,2,2,2,2,2,2,2,2,2,2,1,1,1,1
1,1,1,3,2,2,2,2,2,2,2,2,2,2,2,2,2,2,1,1,1
1,1,3,2,2,2,2,2,2,2,2,2,2,2,2,2,2,2,2,1,1
1,1,3,2,2,2,2,2,2,2,2,2,2,2,2,2,2,2,2,1,1
1,3,2,2,2,2,2,3,3,2,2,2,2,2,2,2,2,2,2,2,1
1,2,2,2,2,2,3,3,0,4,4,2,2,2,2,2,2,2,2,2,1
2,2,2,2,2,2,3,3,0,0,4,0,0,2,2,2,2,2,2,2,2
2,2,2,2,2,2,2,0,4,0,0,0,0,4,2,2,2,2,2,2,2
2,2,2,2,2,2,4,4,0,0,0,4,0,0,4,2,2,2,2,2,2
2,2,2,2,2,2,4,4,0,0,0,4,4,4,2,2,2,2,2,2,2
2,2,2,2,2,2,2,4,4,4,4,4,4,3,2,2,2,2,2,2,2
1,2,2,2,2,2,2,2,4,4,2,4,3,3,3,2,2,2,2,2,1
1,2,2,2,2,2,2,2,2,2,2,2,2,3,3,2,2,2,2,2,1
1,1,2,2,2,2,2,2,2,2,2,2,2,2,2,2,2,2,2,1,1
1,1,2,2,2,2,2,2,2,2,2,2,2,2,2,2,2,2,2,1,1
1,1,1,2,2,2,2,2,2,2,2,2,2,2,2,2,2,2,1,1,1
1,1,1,1,2,2,2,2,2,2,2,2,2,2,2,2,2,1,1,1,1
1,1,1,1,1,1,2,2,2,2,2,2,2,2,2,1,1,1,1,1,1
1,1,1,1,1,1,1,1,2,2,2,2,2,1,1,1,1,1,1,1,1
endlayer

layer
1,1,1,1,1,1,1,1,1,1,1,1,1,1,1,1,1,1,1,1,1
1,1,1,1,1,1,1,1,2,2,2,2,2,1,1,1,1,1,1,1,1
1,1,1,1,1,1,2,2,3,2,2,2,3,2,2,1,1,1,1,1,1
1,1,1,1,3,2,2,2,2,2,2,2,2,2,2,2,2,1,1,1,1
1,1,1,3,3,3,2,2,2,2,2,2,2,2,2,2,2,2,1,1,1
1,1,1,3,3,3,3,3,2,4,0,2,2,2,2,2,2,2,1,1,1
1,1,3,3,3,3,3,0,4,4,4,4,4,2,2,2,2,2,2,1,1
1,1,2,2,2,3,3,5,0,0,0,4,0,0,2,2,2,2,2,1,1
1,2,3,2,2,3,4,0,0,0,0,0,0,6,4,2,2,2,3,2,1
1,2,2,2,2,2,0,0,0,0,0,0,0,0,4,2,2,2,2,2,1
1,2,2,2,0,4,0,0,0,0,0,0,0,0,0,4,2,2,2,2,1
1,2,2,2,2,4,0,0,0,0,0,0,0,0,0,2,2,2,2,2,1
1,2,3,2,2,4,4,0,0,0,0,0,0,4,4,2,2,2,3,2,1
1,1,2,2,2,2,4,4,0,0,7,0,4,4,4,0,2,2,2,1,1
1,1,2,2,2,2,2,4,4,4,4,4,4,0,0,2,2,2,2,1,1
1,1,1,2,2,2,2,2,3,4,2,4,2,2,2,2,2,2,1,1,1
1,1,1,2,2,2,2,2,2,2,2,4,2,2,2,2,2,2,1,1,1
1,1,1,1,2,2,2,2,2,2,2,2,2,2,2,2,2,1,1,1,1
1,1,1,1,1,1,2,2,3,2,2,2,3,2,2,1,1,1,1,1,1
1,1,1,1,1,1,1,1,2,2,2,2,2,1,1,1,1,1,1,1,1
1,1,1,1,1,1,1,1,1,1,1,1,1,1,1,1,1,1,1,1,1
endlayer

layer
1,1,1,1,1,1,1,1,1,1,1,1,1,1,1,1,1,1,1,1,1
1,1,1,1,1,1,1,1,1,1,1,1,1,1,1,1,1,1,1,1,1
1,1,1,1,1,1,1,3,3,1,1,1,3,3,1,1,1,1,1,1,1
1,1,1,1,1,1,1,3,3,1,4,1,3,3,1,1,1,1,1,1,1
1,1,1,1,1,1,1,3,3,1,0,4,3,3,1,1,1,1,1,1,1
1,1,1,1,1,1,1,4,4,0,0,4,4,4,1,1,1,1,1,1,1
1,1,1,1,1,1,0,0,0,0,0,0,0,0,0,1,1,1,1,1,1
1,1,3,3,3,4,4,0,0,0,0,0,0,0,4,4,3,3,3,1,1
1,1,3,3,3,0,0,0,0,0,0,0,0,0,0,4,3,3,3,1,1
1,1,1,1,1,4,0,0,0,0,0,0,0,0,0,4,4,1,1,1,1
1,1,1,1,1,0,0,0,0,0,0,0,0,0,0,0,0,4,1,1,1
1,1,1,1,1,0,0,0,0,0,0,0,0,0,0,0,1,1,1,1,1
1,1,3,3,3,0,0,0,0,0,0,0,0,0,0,0,3,3,3,1,1
1,1,3,3,3,4,0,0,0,0,0,0,0,0,0,0,3,3,3,1,1
1,1,1,1,1,4,4,0,0,0,0,0,0,0,0,0,1,1,1,1,1
1,1,1,1,1,0,4,0,0,0,0,0,4,0,0,0,1,1,1,1,1
1,1,1,1,1,4,1,3,3,4,0,1,3,3,1,1,1,1,1,1,1
1,1,1,1,1,1,1,3,3,1,4,1,3,3,1,1,1,1,1,1,1
1,1,1,1,1,1,1,3,3,1,1,1,3,3,1,1,1,1,1,1,1
1,1,1,1,1,1,1,1,1,1,1,1,1,1,1,1,1,1,1,1,1
1,1,1,1,1,1,1,1,1,1,1,1,1,1,1,1,1,1,1,1,1
endlayer

layer
1,1,1,1,1,1,1,1,1,1,1,1,1,1,1,1,1,1,1,1,1
1,1,1,1,1,1,1,1,1,1,1,1,1,1,1,1,1,1,1,1,1
1,1,1,1,1,1,1,3,3,1,1,1,3,3,1,1,1,1,1,1,1
1,1,1,1,1,1,1,3,3,1,1,1,3,3,1,1,1,1,1,1,1
1,1,1,1,1,1,1,3,3,1,1,1,3,3,1,1,1,1,1,1,1
1,1,1,1,1,1,1,0,0,0,0,0,0,0,1,1,1,1,1,1,1
1,1,1,1,1,1,0,0,0,0,0,0,0,0,0,1,1,1,1,1,1
1,1,3,3,3,0,0,0,0,0,0,0,0,0,0,0,3,3,3,1,1
1,1,3,3,3,0,0,0,0,0,0,0,0,0,0,0,3,3,3,1,1
1,1,1,1,1,0,0,0,0,0,0,0,0,0,0,0,1,1,1,1,1
1,1,1,1,1,0,0,0,0,0,0,0,0,0,0,0,1,1,1,1,1
1,1,1,1,1,0,0,0,0,0,0,0,0,0,0,0,1,1,1,1,1
1,1,3,3,3,0,0,0,0,0,0,0,0,0,0,0,3,3,3,1,1
1,1,3,3,3,0,0,0,0,0,0,0,0,0,0,0,3,3,3,1,1
1,1,1,1,1,0,0,0,0,0,0,0,0,0,0,0,1,1,1,1,1
1,1,1,1,1,0,0,0,0,0,0,0,0,0,0,0,1,1,1,1,1
1,1,1,1,1,1,1,3,3,1,1,1,3,3,1,1,1,1,1,1,1
1,1,1,1,1,1,1,3,3,1,1,1,3,3,1,1,1,1,1,1,1
1,1,1,1,1,1,1,3,3,1,1,1,3,3,1,1,1,1,1,1,1
1,1,1,1,1,1,1,1,1,1,1,1,1,1,1,1,1,1,1,1,1
1,1,1,1,1,1,1,1,1,1,1,1,1,1,1,1,1,1,1,1,1
endlayer

layer
1,1,1,1,1,1,1,1,1,1,1,1,1,1,1,1,1,1,1,1,1
1,1,1,1,1,1,1,1,1,1,1,1,1,1,1,1,1,1,1,1,1
1,1,1,1,1,1,1,3,3,1,1,1,3,3,1,1,1,1,1,1,1
1,1,1,1,1,1,1,3,3,1,1,1,3,3,1,1,1,1,1,1,1
1,1,1,1,1,1,1,3,3,1,1,1,3,3,1,1,1,1,1,1,1
1,1,1,1,1,1,1,0,0,0,0,0,0,0,1,1,1,1,1,1,1
1,1,1,1,1,1,0,0,0,0,0,0,0,0,0,1,1,1,1,1,1
1,1,3,3,3,0,0,0,0,0,0,0,0,0,0,0,3,3,3,1,1
1,1,3,3,3,0,0,0,0,0,0,0,0,0,0,0,3,3,3,1,1
1,1,1,1,1,0,0,0,0,0,0,0,0,0,0,0,1,1,1,1,1
1,1,1,1,1,0,0,0,0,0,0,0,0,0,0,0,1,1,1,1,1
1,1,1,1,1,0,0,0,0,0,0,0,0,0,0,0,1,1,1,1,1
1,1,3,3,3,0,0,0,0,0,0,0,0,0,0,0,3,3,3,1,1
1,1,3,3,3,0,0,0,0,0,0,0,0,0,0,0,3,3,3,1,1
1,1,1,1,1,0,0,0,0,0,0,0,0,0,0,0,1,1,1,1,1
1,1,1,1,1,0,0,0,0,0,0,0,0,0,0,0,1,1,1,1,1
1,1,1,1,1,1,1,3,3,1,1,1,3,3,1,1,1,1,1,1,1
1,1,1,1,1,1,1,3,3,1,1,1,3,3,1,1,1,1,1,1,1
1,1,1,1,1,1,1,3,3,1,1,1,3,3,1,1,1,1,1,1,1
1,1,1,1,1,1,1,1,1,1,1,1,1,1,1,1,1,1,1,1,1
1,1,1,1,1,1,1,1,1,1,1,1,1,1,1,1,1,1,1,1,1
endlayer

layer
1,1,1,1,1,1,1,1,1,1,1,1,1,1,1,1,1,1,1,1,1
1,1,1,1,1,1,1,1,1,1,1,1,1,1,1,1,1,1,1,1,1
1,1,1,1,1,1,1,3,3,1,1,1,3,3,1,1,1,1,1,1,1
1,1,1,1,1,1,1,3,3,1,1,1,3,3,1,1,1,1,1,1,1
1,1,1,1,1,1,1,3,3,1,1,1,3,3,1,1,1,1,1,1,1
1,1,1,1,1,1,1,0,0,0,0,0,0,0,1,1,1,1,1,1,1
1,1,1,1,1,1,0,0,0,0,0,0,0,0,0,1,1,1,1,1,1
1,1,3,3,3,0,0,0,0,0,0,0,0,0,0,0,3,3,3,1,1
1,1,3,3,3,0,0,0,0,0,0,0,0,0,0,0,3,3,3,1,1
1,1,1,1,1,0,0,0,0,0,0,0,0,0,0,0,1,1,1,1,1
1,1,1,1,1,0,0,0,0,0,8,0,0,0,0,0,1,1,1,1,1
1,1,1,1,1,0,0,0,0,0,0,0,0,0,0,0,1,1,1,1,1
1,1,3,3,3,0,0,0,0,0,0,0,0,0,0,0,3,3,3,1,1
1,1,3,3,3,0,0,0,0,0,0,0,0,0,0,0,3,3,3,1,1
1,1,1,1,1,0,0,0,0,0,0,0,0,0,0,0,1,1,1,1,1
1,1,1,1,1,0,0,0,0,0,0,0,0,0,0,0,1,1,1,1,1
1,1,1,1,1,1,1,3,3,1,1,1,3,3,1,1,1,1,1,1,1
1,1,1,1,1,1,1,3,3,1,1,1,3,3,1,1,1,1,1,1,1
1,1,1,1,1,1,1,3,3,1,1,1,3,3,1,1,1,1,1,1,1
1,1,1,1,1,1,1,1,1,1,1,1,1,1,1,1,1,1,1,1,1
1,1,1,1,1,1,1,1,1,1,1,1,1,1,1,1,1,1,1,1,1
endlayer

layer
1,1,1,1,1,1,1,1,1,1,1,1,1,1,1,1,1,1,1,1,1
1,1,1,1,1,1,1,1,1,1,1,1,1,1,1,1,1,1,1,1,1
1,1,1,1,1,1,1,3,3,1,1,1,3,3,1,1,1,1,1,1,1
1,1,1,1,1,1,1,3,3,1,1,1,3,3,1,1,1,1,1,1,1
1,1,1,1,1,1,1,3,3,1,1,1,3,3,1,1,1,1,1,1,1
1,1,1,1,1,1,1,0,0,0,0,0,0,0,1,1,1,1,1,1,1
1,1,1,1,1,1,0,0,0,0,0,0,0,0,0,1,1,1,1,1,1
1,1,3,3,3,0,0,0,0,0,0,0,0,0,0,0,3,3,3,1,1
1,1,3,3,3,0,0,0,0,0,0,0,0,0,0,0,3,3,3,1,1
1,1,1,1,1,0,0,0,0,0,0,0,0,0,0,0,1,1,1,1,1
1,1,1,1,1,0,0,0,0,0,0,0,0,0,0,0,1,1,1,1,1
1,1,1,1,1,0,0,0,0,0,0,0,0,0,0,0,1,1,1,1,1
1,1,3,3,3,0,0,0,0,0,0,0,0,0,0,0,3,3,3,1,1
1,1,3,3,3,0,0,0,0,0,0,0,0,0,0,0,3,3,3,1,1
1,1,1,1,1,0,0,0,0,0,0,0,0,0,0,0,1,1,1,1,1
1,1,1,1,1,0,0,0,0,0,0,0,0,0,0,0,1,1,1,1,1
1,1,1,1,1,1,1,3,3,1,1,1,3,3,1,1,1,1,1,1,1
1,1,1,1,1,1,1,3,3,1,1,1,3,3,1,1,1,1,1,1,1
1,1,1,1,1,1,1,3,3,1,1,1,3,3,1,1,1,1,1,1,1
1,1,1,1,1,1,1,1,1,1,1,1,1,1,1,1,1,1,1,1,1
1,1,1,1,1,1,1,1,1,1,1,1,1,1,1,1,1,1,1,1,1
endlayer

layer
1,1,1,1,1,1,1,1,1,1,1,1,1,1,1,1,1,1,1,1,1
1,1,1,1,1,1,1,1,1,1,1,1,1,1,1,1,1,1,1,1,1
1,1,1,1,1,1,3,3,3,3,3,3,3,3,3,1,1,1,1,1,1
1,1,1,1,1,3,3,3,3,3,3,3,3,3,3,3,1,1,1,1,1
1,1,1,1,3,3,3,3,3,3,3,3,3,3,3,3,3,1,1,1,1
1,1,1,3,3,3,3,0,0,0,0,0,0,0,3,3,3,3,1,1,1
1,1,3,3,3,3,0,0,0,0,0,0,0,0,0,3,3,3,3,1,1
1,1,3,3,3,0,0,0,0,0,0,0,0,0,0,0,3,3,3,1,1
1,1,3,3,3,0,0,0,0,0,0,0,0,0,0,0,3,3,3,1,1
1,1,3,3,3,0,0,0,0,0,0,0,0,0,0,0,3,3,3,1,1
1,1,3,3,3,0,0,0,0,0,0,0,0,0,0,0,3,3,3,1,1
1,1,3,3,3,0,0,0,0,0,0,0,0,0,0,0,3,3,3,1,1
1,1,3,3,3,0,0,0,0,0,0,0,0,0,0,0,3,3,3,1,1
1,1,3,3,3,0,0,0,0,0,0,0,0,0,0,0,3,3,3,1,1
1,1,3,3,3,3,0,0,0,0,0,0,0,0,0,3,3,3,3,1,1
1,1,1,3,3,3,3,0,0,0,0,0,0,0,3,3,3,3,1,1,1
1,1,1,1,3,3,3,3,3,3,3,3,3,3,3,3,3,1,1,1,1
1,1,1,1,1,3,3,3,3,3,3,3,3,3,3,3,1,1,1,1,1
1,1,1,1,1,1,3,3,3,3,3,3,3,3,3,1,1,1,1,1,1
1,1,1,1,1,1,1,1,1,1,1,1,1,1,1,1,1,1,1,1,1
1,1,1,1,1,1,1,1,1,1,1,1,1,1,1,1,1,1,1,1,1
endlayer

layer
1,1,1,1,1,1,1,1,1,1,1,1,1,1,1,1,1,1,1,1,1
1,1,1,1,1,1,1,1,1,1,1,1,1,1,1,1,1,1,1,1,1
1,1,1,1,1,1,3,3,3,3,3,3,3,3,3,1,1,1,1,1,1
1,1,1,1,1,3,3,3,3,3,3,3,3,3,3,3,1,1,1,1,1
1,1,1,1,3,3,3,3,3,3,3,3,3,3,3,3,3,1,1,1,1
1,1,1,3,3,3,3,3,3,0,0,0,3,3,3,3,3,3,1,1,1
1,1,3,3,3,3,3,0,0,0,0,0,0,0,3,3,3,3,3,1,1
1,1,3,3,3,3,0,0,0,0,0,0,0,0,0,3,3,3,3,1,1
1,1,3,3,3,3,0,0,0,0,0,0,0,0,0,3,3,3,3,1,1
1,1,3,3,3,0,0,0,0,0,0,0,0,0,0,0,3,3,3,1,1
1,1,3,3,3,0,0,0,0,0,0,0,0,0,0,0,3,3,3,1,1
1,1,3,3,3,0,0,0,0,0,0,0,0,0,0,0,3,3,3,1,1
1,1,3,3,3,3,0,0,0,0,0,0,0,0,0,3,3,3,3,1,1
1,1,3,3,3,3,0,0,0,0,0,0,0,0,0,3,3,3,3,1,1
1,1,3,3,3,3,3,0,0,0,0,0,0,0,3,3,3,3,3,1,1
1,1,1,3,3,3,3,3,3,0,0,0,3,3,3,3,3,3,1,1,1
1,1,1,1,3,3,3,3,3,3,3,3,3,3,3,3,3,1,1,1,1
1,1,1,1,1,3,3,3,3,3,3,3,3,3,3,3,1,1,1,1,1
1,1,1,1,1,1,3,3,3,3,3,3,3,3,3,1,1,1,1,1,1
1,1,1,1,1,1,1,1,1,1,1,1,1,1,1,1,1,1,1,1,1
1,1,1,1,1,1,1,1,1,1,1,1,1,1,1,1,1,1,1,1,1
endlayer

layer
1,1,1,1,1,1,1,1,1,1,1,1,1,1,1,1,1,1,1,1,1
1,1,1,1,1,1,1,1,1,1,1,1,1,1,1,1,1,1,1,1,1
1,1,1,1,1,1,1,1,1,1,1,1,1,1,1,1,1,1,1,1,1
1,1,1,1,1,1,1,1,3,1,1,1,3,1,1,1,1,1,1,1,1
1,1,1,1,1,1,1,1,0,0,0,0,0,1,1,1,1,1,1,1,1
1,1,1,1,1,3,1,1,0,0,0,0,0,1,1,3,1,1,1,1,1
1,1,1,1,1,0,0,0,0,0,0,0,0,0,0,0,1,1,1,1,1
1,1,1,1,1,0,0,0,0,0,0,0,0,0,0,0,1,1,1,1,1
1,1,1,3,0,0,0,0,0,0,0,0,0,0,0,0,0,3,1,1,1
1,1,1,1,0,0,0,0,0,0,0,0,0,0,0,0,0,1,1,1,1
1,1,1,1,0,0,0,0,0,0,0,0,0,0,0,0,0,1,1,1,1
1,1,1,1,0,0,0,0,0,0,0,0,0,0,0,0,0,1,1,1,1
1,1,1,3,0,0,0,0,0,0,0,0,0,0,0,0,0,3,1,1,1
1,1,1,1,1,0,0,0,0,0,0,0,0,0,0,0,1,1,1,1,1
1,1,1,1,1,0,0,0,0,0,0,0,0,0,0,0,1,1,1,1,1
1,1,1,1,1,3,1,1,0,0,0,0,0,1,1,3,1,1,1,1,1
1,1,1,1,1,1,1,1,0,0,0,0,0,1,1,1,1,1,1,1,1
1,1,1,1,1,1,1,1,3,1,1,1,3,1,1,1,1,1,1,1,1
1,1,1,1,1,1,1,1,1,1,1,1,1,1,1,1,1,1,1,1,1
1,1,1,1,1,1,1,1,1,1,1,1,1,1,1,1,1,1,1,1,1
1,1,1,1,1,1,1,1,1,1,1,1,1,1,1,1,1,1,1,1,1
endlayer

layer
1,1,1,1,1,1,1,1,1,1,1,1,1,1,1,1,1,1,1,1,1
1,1,1,1,1,1,1,1,1,1,1,1,1,1,1,1,1,1,1,1,1
1,1,1,1,1,1,1,1,1,1,1,1,1,1,1,1,1,1,1,1,1
1,1,1,1,1,1,1,1,3,1,1,1,3,1,1,1,1,1,1,1,1
1,1,1,1,1,1,1,1,0,0,0,0,0,1,1,1,1,1,1,1,1
1,1,1,1,1,3,1,1,0,0,0,0,0,1,1,3,1,1,1,1,1
1,1,1,1,1,0,0,0,0,0,0,0,0,0,0,0,1,1,1,1,1
1,1,1,1,1,0,0,0,0,0,0,0,0,0,0,0,1,1,1,1,1
1,1,1,3,0,0,0,0,0,0,0,0,0,0,0,0,0,3,1,1,1
1,1,1,1,0,0,0,0,0,0,0,0,0,0,0,0,0,1,1,1,1
1,1,1,1,0,0,0,0,0,0,0,0,0,0,0,0,0,1,1,1,1
1,1,1,1,0,0,0,0,0,0,0,0,0,0,0,0,0,1,1,1,1
1,1,1,3,0,0,0,0,0,0,0,0,0,0,0,0,0,3,1,1,1
1,1,1,1,1,0,0,0,0,0,0,0,0,0,0,0,1,1,1,1,1
1,1,1,1,1,0,0,0,0,0,0,0,0,0,0,0,1,1,1,1,1
1,1,1,1,1,3,1,1,0,0,0,0,0,1,1,3,1,1,1,1,1
1,1,1,1,1,1,1,1,0,0,0,0,0,1,1,1,1,1,1,1,1
1,1,1,1,1,1,1,1,3,1,1,1,3,1,1,1,1,1,1,1,1
1,1,1,1,1,1,1,1,1,1,1,1,1,1,1,1,1,1,1,1,1
1,1,1,1,1,1,1,1,1,1,1,1,1,1,1,1,1,1,1,1,1
1,1,1,1,1,1,1,1,1,1,1,1,1,1,1,1,1,1,1,1,1
endlayer

layer
1,1,1,1,1,1,1,1,1,1,1,1,1,1,1,1,1,1,1,1,1
1,1,1,1,1,1,1,1,1,1,1,1,1,1,1,1,1,1,1,1,1
1,1,1,1,1,1,1,1,1,1,1,1,1,1,1,1,1,1,1,1,1
1,1,1,1,1,1,1,1,3,1,1,1,3,1,1,1,1,1,1,1,1
1,1,1,1,1,1,1,1,0,0,0,0,0,1,1,1,1,1,1,1,1
1,1,1,1,1,3,1,1,0,0,0,0,0,1,1,3,1,1,1,1,1
1,1,1,1,1,0,0,0,0,0,0,0,0,0,0,0,1,1,1,1,1
1,1,1,1,1,0,0,0,0,0,0,0,0,0,0,0,1,1,1,1,1
1,1,1,3,0,0,0,0,0,0,0,0,0,0,0,0,0,3,1,1,1
1,1,1,1,0,0,0,0,0,0,0,0,0,0,0,0,0,1,1,1,1
1,1,1,1,0,0,0,0,0,0,0,0,0,0,0,0,0,1,1,1,1
1,1,1,1,0,0,0,0,0,0,0,0,0,0,0,0,0,1,1,1,1
1,1,1,3,0,0,0,0,0,0,0,0,0,0,0,0,0,3,1,1,1
1,1,1,1,1,0,0,0,0,0,0,0,0,0,0,0,1,1,1,1,1
1,1,1,1,1,0,0,0,0,0,0,0,0,0,0,0,1,1,1,1,1
1,1,1,1,1,3,1,1,0,0,0,0,0,1,1,3,1,1,1,1,1
1,1,1,1,1,1,1,1,0,0,0,0,0,1,1,1,1,1,1,1,1
1,1,1,1,1,1,1,1,3,1,1,1,3,1,1,1,1,1,1,1,1
1,1,1,1,1,1,1,1,1,1,1,1,1,1,1,1,1,1,1,1,1
1,1,1,1,1,1,1,1,1,1,1,1,1,1,1,1,1,1,1,1,1
1,1,1,1,1,1,1,1,1,1,1,1,1,1,1,1,1,1,1,1,1
endlayer

layer
1,1,1,1,1,1,1,1,1,1,1,1,1,1,1,1,1,1,1,1,1
1,1,1,1,1,1,1,1,1,1,1,1,1,1,1,1,1,1,1,1,1
1,1,1,1,1,1,1,1,1,1,1,1,1,1,1,1,1,1,1,1,1
1,1,1,1,1,1,1,1,3,1,1,1,3,1,1,1,1,1,1,1,1
1,1,1,1,1,1,1,1,0,0,0,0,0,1,1,1,1,1,1,1,1
1,1,1,1,1,3,1,1,0,0,0,0,0,1,1,3,1,1,1,1,1
1,1,1,1,1,0,0,0,0,0,0,0,0,0,0,0,1,1,1,1,1
1,1,1,1,1,0,0,0,0,0,0,0,0,0,0,0,1,1,1,1,1
1,1,1,3,0,0,0,0,0,0,0,0,0,0,0,0,0,3,1,1,1
1,1,1,1,0,0,0,0,0,0,0,0,0,0,0,0,0,1,1,1,1
1,1,1,1,0,0,0,0,0,0,0,0,0,0,0,0,0,1,1,1,1
1,1,1,1,0,0,0,0,0,0,0,0,0,0,0,0,0,1,1,1,1
1,1,1,3,0,0,0,0,0,0,0,0,0,0,0,0,0,3,1,1,1
1,1,1,1,1,0,0,0,0,0,0,0,0,0,0,0,1,1,1,1,1
1,1,1,1,1,0,0,0,0,0,0,0,0,0,0,0,1,1,1,1,1
1,1,1,1,1,3,1,1,0,0,0,0,0,1,1,3,1,1,1,1,1
1,1,1,1,1,1,1,1,0,0,0,0,0,1,1,1,1,1,1,1,1
1,1,1,1,1,1,1,1,3,1,1,1,3,1,1,1,1,1,1,1,1
1,1,1,1,1,1,1,1,1,1,1,1,1,1,1,1,1,1,1,1,1
1,1,1,1,1,1,1,1,1,1,1,1,1,1,1,1,1,1,1,1,1
1,1,1,1,1,1,1,1,1,1,1,1,1,1,1,1,1,1,1,1,1
endlayer

layer
1,1,1,1,1,1,1,1,1,1,1,1,1,1,1,1,1,1,1,1,1
1,1,1,1,1,1,1,1,1,1,1,1,1,1,1,1,1,1,1,1,1
1,1,1,1,1,1,1,1,1,1,1,1,1,1,1,1,1,1,1,1,1
1,1,1,1,1,1,1,1,3,1,1,1,3,1,1,1,1,1,1,1,1
1,1,1,1,1,1,1,1,0,0,0,0,0,1,1,1,1,1,1,1,1
1,1,1,1,1,3,1,1,0,0,0,0,0,1,1,3,1,1,1,1,1
1,1,1,1,1,0,0,0,0,0,0,0,0,0,0,0,1,1,1,1,1
1,1,1,1,1,0,0,0,0,0,0,0,0,0,0,0,1,1,1,1,1
1,1,1,3,0,0,0,0,0,0,0,0,0,0,0,0,0,3,1,1,1
1,1,1,1,0,0,0,0,0,0,0,0,0,0,0,0,0,1,1,1,1
1,1,1,1,0,0,0,0,0,0,0,0,0,0,0,0,0,1,1,1,1
1,1,1,1,0,0,0,0,0,0,0,0,0,0,0,0,0,1,1,1,1
1,1,1,3,0,0,0,0,0,0,0,0,0,0,0,0,0,3,1,1,1
1,1,1,1,1,0,0,0,0,0,0,0,0,0,0,0,1,1,1,1,1
1,1,1,1,1,0,0,0,0,0,0,0,0,0,0,0,1,1,1,1,1
1,1,1,1,1,3,1,1,0,0,0,0,0,1,1,3,1,1,1,1,1
1,1,1,1,1,1,1,1,0,0,0,0,0,1,1,1,1,1,1,1,1
1,1,1,1,1,1,1,1,3,1,1,1,3,1,1,1,1,1,1,1,1
1,1,1,1,1,1,1,1,1,1,1,1,1,1,1,1,1,1,1,1,1
1,1,1,1,1,1,1,1,1,1,1,1,1,1,1,1,1,1,1,1,1
1,1,1,1,1,1,1,1,1,1,1,1,1,1,1,1,1,1,1,1,1
endlayer

layer
1,1,1,1,1,1,1,1,1,1,1,1,1,1,1,1,1,1,1,1,1
1,1,1,1,1,1,1,1,1,1,1,1,1,1,1,1,1,1,1,1,1
1,1,1,1,1,1,1,3,3,3,3,3,3,3,1,1,1,1,1,1,1
1,1,1,1,1,1,3,3,3,3,3,3,3,3,3,1,1,1,1,1,1
1,1,1,1,1,3,3,3,0,0,0,0,0,3,3,3,1,1,1,1,1
1,1,1,1,3,3,3,0,0,0,0,0,0,0,3,3,3,1,1,1,1
1,1,1,3,3,3,0,0,0,0,0,0,0,0,0,3,3,3,1,1,1
1,1,3,3,3,0,0,0,0,0,0,0,0,0,0,0,3,3,3,1,1
1,1,3,3,0,0,0,0,0,0,0,0,0,0,0,0,0,3,3,1,1
1,1,3,3,0,0,0,0,0,0,0,0,0,0,0,0,0,3,3,1,1
1,1,3,3,0,0,0,0,0,0,0,0,0,0,0,0,0,3,3,1,1
1,1,3,3,0,0,0,0,0,0,0,0,0,0,0,0,0,3,3,1,1
1,1,3,3,0,0,0,0,0,0,0,0,0,0,0,0,0,3,3,1,1
1,1,3,3,3,0,0,0,0,0,0,0,0,0,0,0,3,3,3,1,1
1,1,1,3,3,3,0,0,0,0,0,0,0,0,0,3,3,3,1,1,1
1,1,1,1,3,3,3,0,0,0,0,0,0,0,3,3,3,1,1,1,1
1,1,1,1,1,3,3,3,0,0,0,0,0,3,3,3,1,1,1,1,1
1,1,1,1,1,1,3,3,3,3,3,3,3,3,3,1,1,1,1,1,1
1,1,1,1,1,1,1,3,3,3,3,3,3,3,1,1,1,1,1,1,1
1,1,1,1,1,1,1,1,1,1,1,1,1,1,1,1,1,1,1,1,1
1,1,1,1,1,1,1,1,1,1,1,1,1,1,1,1,1,1,1,1,1
endlayer

layer
1,1,1,1,1,1,1,1,1,1,1,1,1,1,1,1,1,1,1,1,1
1,1,1,1,1,1,1,1,1,1,1,1,1,1,1,1,1,1,1,1,1
1,1,1,1,1,1,1,3,3,3,3,3,3,3,1,1,1,1,1,1,1
1,1,1,1,1,1,3,3,3,3,3,3,3,3,3,1,1,1,1,1,1
1,1,1,1,1,3,3,3,0,0,0,0,0,3,3,3,1,1,1,1,1
1,1,1,1,3,3,3,0,0,0,0,0,0,0,3,3,3,1,1,1,1
1,1,1,3,3,3,0,0,0,0,0,0,0,0,0,3,3,3,1,1,1
1,1,3,3,3,0,0,0,0,0,0,0,0,0,0,0,3,3,3,1,1
1,1,3,3,0,0,0,0,0,0,0,0,0,0,0,0,0,3,3,1,1
1,1,3,3,0,0,0,0,0,0,0,0,0,0,0,0,0,3,3,1,1
1,1,3,3,0,0,0,0,0,0,0,0,0,0,0,0,0,3,3,1,1
1,1,3,3,0,0,0,0,0,0,0,0,0,0,0,0,0,3,3,1,1
1,1,3,3,0,0,0,0,0,0,0,0,0,0,0,0,0,3,3,1,1
1,1,3,3,3,0,0,0,0,0,0,0,0,0,0,0,3,3,3,1,1
1,1,1,3,3,3,0,0,0,0,0,0,0,0,0,3,3,3,1,1,1
1,1,1,1,3,3,3,0,0,0,0,0,0,0,3,3,3,1,1,1,1
1,1,1,1,1,3,3,3,0,0,0,0,0,3,3,3,1,1,1,1,1
1,1,1,1,1,1,3,3,3,3,3,3,3,3,3,1,1,1,1,1,1
1,1,1,1,1,1,1,3,3,3,3,3,3,3,1,1,1,1,1,1,1
1,1,1,1,1,1,1,1,1,1,1,1,1,1,1,1,1,1,1,1,1
1,1,1,1,1,1,1,1,1,1,1,1,1,1,1,1,1,1,1,1,1
endlayer

