
# Created by Ruins mod version 17.0 Ingame Parser
# authoring Player: ST753M

weight=1
embed_into_distance=2
acceptable_target_blocks=
unacceptable_target_blocks=flowing_water,water,flowing_lava,lava,ice,bedrock,netherrack,nether_brick,nether_brick_fence,soul_sand,quartz_ore,end_stone,obsidian,iron_bars,Natura:Cloud,slime_grass,slime_congealed,slime_dirt,clouds,natura:clouds,twilightforest:wispy_cloud,twilightforest:fluffy_cloud,grass
dimensions=9,9,17
allowable_overhang=10
max_leveling=0
leveling_buffer=-1
preserve_water=1
preserve_lava=0

biomesToSpawnIn=ocean,deep_ocean,kelp_forest,coral_reef,coralium_infested_ocean

=0,100,preserveBlock
rule1=0,100,minecraft:planks-2
rule2=0,100,minecraft:planks-0
rule3=0,100,IInventory;minecraft:chest;minecraft:gold_ingot#8#0#2+minecraft:potion#{Potion:"minecraft:water_breathing"}#0#13-3
rule4=0,100,minecraft:birch_stairs-6

layer
0,0,0,0,0,0,0,0,0,0,0,0,0,0,0,0,0
0,0,0,0,0,0,0,0,0,0,0,0,0,0,0,0,0
0,0,0,0,0,0,0,0,0,0,0,0,0,0,0,0,0
0,0,1,1,1,1,1,1,1,1,1,1,0,0,0,0,0
0,0,1,1,1,1,1,1,1,1,1,1,0,0,0,0,0
0,0,1,1,1,1,1,1,1,1,1,1,0,0,0,0,0
0,0,0,0,0,0,0,0,0,0,0,0,0,0,0,0,0
0,0,0,0,0,0,0,0,0,0,0,0,0,0,0,0,0
0,0,0,0,0,0,0,0,0,0,0,0,0,0,0,0,0
endlayer

layer
0,0,0,0,0,0,0,0,0,0,0,0,0,0,0,0,0
0,0,0,0,0,0,0,0,0,0,0,0,0,0,0,0,0
0,1,1,1,1,1,1,1,1,1,1,1,1,0,0,0,0
0,1,2,2,2,2,2,2,2,2,2,2,2,0,0,0,0
0,1,2,2,2,2,2,2,2,2,2,2,2,0,0,0,0
0,1,1,2,2,2,2,2,2,2,2,2,2,0,0,0,0
0,1,1,1,1,1,1,1,1,1,1,1,1,0,0,0,0
0,0,0,0,0,0,0,0,0,0,0,0,0,0,0,0,0
0,0,0,0,0,0,0,0,0,0,0,0,0,0,0,0,0
endlayer

layer
0,0,0,0,0,0,0,0,0,0,0,0,0,0,0,0,0
0,1,1,1,1,1,1,1,1,1,1,1,1,0,0,0,0
1,1,1,0,0,0,1,1,0,0,1,1,1,1,0,0,0
1,1,1,0,0,0,0,0,0,0,0,0,3,1,1,0,0
1,1,1,0,0,0,0,0,0,0,0,0,0,1,1,0,0
1,1,1,0,0,0,0,0,0,0,0,0,0,1,1,0,0
1,2,1,0,0,1,1,1,0,0,1,1,1,1,0,0,0
0,1,1,1,1,1,1,1,1,1,1,1,0,0,0,0,0
0,0,0,0,0,0,0,0,0,0,0,0,0,0,0,0,0
endlayer

layer
0,0,0,0,0,0,0,0,0,0,0,0,0,0,0,0,0
1,1,1,1,0,1,1,0,1,1,0,1,1,1,0,0,0
1,1,1,0,0,0,1,0,0,0,0,1,1,1,0,0,0
1,1,1,0,0,0,0,0,0,0,0,0,0,1,1,0,0
1,1,1,0,0,0,0,0,0,0,0,0,0,1,2,1,0
1,1,1,0,0,0,0,0,0,0,0,0,0,1,1,0,0
1,2,1,0,0,0,1,0,0,0,0,1,1,1,0,0,0
1,1,1,1,0,1,1,0,1,1,0,1,0,0,0,0,0
0,0,0,0,0,0,0,0,0,0,0,0,0,0,0,0,0
endlayer

layer
0,0,0,0,0,0,0,0,0,0,0,0,0,0,0,0,0
1,1,1,1,1,1,1,1,1,1,1,1,1,1,0,0,0
1,2,2,2,2,2,2,2,2,2,2,2,2,2,1,0,0
1,2,2,2,2,2,2,2,2,2,2,2,2,2,2,1,0
1,2,2,2,2,2,2,2,2,2,2,0,2,2,2,1,0
1,2,2,2,2,2,2,2,2,2,0,0,0,2,2,1,0
1,2,2,0,0,0,0,2,2,2,0,0,0,2,1,0,0
1,1,1,1,1,1,1,1,1,1,1,0,0,0,0,0,0
0,0,0,0,0,0,0,0,0,0,0,0,0,0,0,0,0
endlayer

layer
0,0,0,0,0,0,0,0,0,0,0,0,0,0,0,0,0
0,0,0,1,1,1,1,1,1,1,1,1,1,1,0,0,0
0,0,0,1,0,0,0,0,1,0,0,0,0,1,1,0,0
0,0,0,0,0,0,0,0,0,0,0,0,0,0,1,1,0
1,0,0,1,0,0,0,0,1,0,0,0,0,0,1,1,1
1,0,0,1,0,0,0,0,1,0,0,0,0,0,1,1,0
1,0,0,4,0,0,0,0,1,0,0,0,0,0,1,0,0
1,1,1,1,1,1,1,1,1,1,0,0,0,0,0,0,0
0,0,0,0,0,0,0,0,0,0,0,0,0,0,0,0,0
endlayer

layer
0,0,0,0,0,0,0,0,0,0,0,0,0,0,0,0,0
0,0,0,0,0,0,0,1,1,0,0,0,0,1,0,0,0
0,0,0,1,0,0,0,0,1,0,0,0,0,0,1,0,0
0,0,0,0,0,0,0,0,0,0,0,0,0,0,0,1,0
0,0,0,1,0,0,0,0,1,0,0,0,0,0,0,1,1
0,0,0,0,0,0,0,0,0,0,0,0,0,0,0,0,0
0,0,0,1,0,0,0,0,1,0,0,0,0,0,0,0,0
0,0,0,1,1,0,0,1,1,0,0,0,0,0,0,0,0
0,0,0,0,0,0,0,0,0,0,0,0,0,0,0,0,0
endlayer

layer
0,0,0,0,0,0,0,2,2,0,0,0,0,0,0,0,0
0,0,0,0,0,0,1,1,1,2,0,0,0,0,0,0,0
0,0,0,0,0,0,0,0,1,2,0,0,0,0,0,0,0
0,0,2,0,0,0,0,0,1,2,0,0,0,0,0,1,0
0,0,2,1,0,0,0,0,1,2,0,0,0,0,0,0,1
0,2,2,1,0,0,0,0,1,2,0,0,0,0,0,0,0
0,2,2,1,0,0,0,0,1,2,0,0,0,0,0,0,0
0,2,2,1,1,1,1,1,1,2,0,0,0,0,0,0,0
0,0,2,2,2,2,2,2,2,0,0,0,0,0,0,0,0
endlayer

layer
0,0,0,0,0,0,0,0,0,0,0,0,0,0,0,0,0
0,0,0,0,0,0,0,2,2,0,0,0,0,0,0,0,0
0,0,0,0,0,0,2,2,2,0,0,0,0,0,0,0,0
0,0,0,0,0,0,2,2,2,0,0,0,0,0,0,0,0
0,0,2,2,0,0,0,2,2,0,0,0,0,0,0,0,0
0,0,2,2,2,0,0,0,2,0,0,0,0,0,0,0,0
0,0,0,2,2,2,0,0,0,0,0,0,0,0,0,0,0
0,0,0,2,2,2,2,0,0,0,0,0,0,0,0,0,0
0,0,0,0,0,0,0,0,0,0,0,0,0,0,0,0,0
endlayer

