
# Created by Ruins mod version 16.5 Ingame Parser
# authoring Player: ST753M

weight=1
uniqueMinDistance=1000
embed_into_distance=2
acceptable_target_blocks=grass,biomesoplenty:grass,biomesoplenty:dirt
unacceptable_target_blocks=flowing_water,water,flowing_lava,lava
dimensions=16,27,19
allowable_overhang=3
max_leveling=0
leveling_buffer=-1
preserve_water=0
preserve_lava=0

biomesToSpawnIn=mutated_plains,flower_field,lavender_fields,flower_island,crystal_forest,origin_island,enchanted_forest,mystic_grove,magical_forest

=0,100,air
rule1=0,100,preserveBlock
rule2=0,100,minecraft:quartz_block-2
rule3=0,100,minecraft:glowstone-0
rule4=0,100,minecraft:pink_glazed_terracotta-1
^0,100,minecraft:white_glazed_terracotta-1
^0,100,minecraft:light_blue_glazed_terracotta-1
^0,100,minecraft:yellow_glazed_terracotta-1
^0,100,minecraft:lime_glazed_terracotta-1
^0,100,minecraft:pink_glazed_terracotta-1
^0,100,minecraft:white_glazed_terracotta-1
rule5^0,100,minecraft:pink_glazed_terracotta-2
^0,100,minecraft:white_glazed_terracotta-2
^0,100,minecraft:light_blue_glazed_terracotta-2
^0,100,minecraft:yellow_glazed_terracotta-2
^0,100,minecraft:lime_glazed_terracotta-2
^0,100,minecraft:pink_glazed_terracotta-2
^0,100,minecraft:white_glazed_terracotta-2
rule6^0,100,minecraft:pink_glazed_terracotta-3
^0,100,minecraft:white_glazed_terracotta-3
^0,100,minecraft:light_blue_glazed_terracotta-3
^0,100,minecraft:yellow_glazed_terracotta-3
^0,100,minecraft:lime_glazed_terracotta-3
^0,100,minecraft:pink_glazed_terracotta-3
^0,100,minecraft:white_glazed_terracotta-3
rule7^0,100,minecraft:pink_glazed_terracotta-0
^0,100,minecraft:white_glazed_terracotta-0
^0,100,minecraft:light_blue_glazed_terracotta-0
^0,100,minecraft:yellow_glazed_terracotta-0
^0,100,minecraft:lime_glazed_terracotta-0
^0,100,minecraft:pink_glazed_terracotta-0
^0,100,minecraft:white_glazed_terracotta-0
rule8=0,100,minecraft:water-0
rule9=0,100,minecraft:stone_slab-7
rule10=0,100,minecraft:water-9
rule11=0,100,minecraft:water-1
rule12=0,100,minecraft:stone_slab-15
rule13=0,100,minecraft:quartz_stairs-5
rule14=0,100,minecraft:quartz_stairs-7
rule15=0,100,minecraft:quartz_stairs-6
rule16=0,100,minecraft:quartz_stairs-4
rule17=0,100,minecraft:stained_glass-6
^0,100,minecraft:stained_glass-0
^0,100,minecraft:stained_glass-3
^0,100,minecraft:stained_glass-0
^0,100,minecraft:stained_glass-3
^0,100,minecraft:stained_glass-2
^0,100,minecraft:stained_glass-6
^0,100,minecraft:stained_glass-6

layer
1,1,1,1,1,1,1,2,2,2,2,2,1,1,1,1,1,1,1
1,1,1,1,1,1,2,1,1,1,1,1,2,1,1,1,1,1,1
1,1,1,1,1,2,1,1,1,1,1,1,1,2,1,1,1,1,1
1,1,1,1,2,1,1,1,1,1,1,1,1,1,2,1,1,1,1
1,1,1,2,1,1,1,1,1,1,1,1,1,1,1,2,1,1,1
1,1,2,1,1,1,1,1,3,3,3,1,1,1,1,1,2,1,1
1,1,2,1,1,1,1,3,3,2,3,3,1,1,1,1,2,1,1
1,2,1,1,1,1,1,1,3,3,3,1,1,1,1,1,1,2,1
1,2,1,1,1,1,1,1,1,1,1,1,1,1,1,1,1,2,1
1,2,1,1,1,1,1,1,1,1,1,1,1,1,1,1,1,2,1
2,1,1,1,1,1,1,1,1,1,1,1,1,1,1,1,1,1,2
2,1,1,1,1,1,1,1,1,1,1,1,1,1,1,1,1,1,2
2,1,1,1,1,1,1,1,1,1,1,1,1,1,1,1,1,1,2
2,1,1,1,1,1,1,1,1,1,1,1,1,1,1,1,1,1,2
2,1,1,1,1,1,1,1,1,1,1,1,1,1,1,1,1,1,2
2,1,1,1,1,1,1,1,1,1,1,1,1,1,1,1,1,1,2
2,1,1,1,1,1,1,1,1,1,1,1,1,1,1,1,1,1,2
1,2,1,1,1,1,1,1,1,1,1,1,1,1,1,1,1,2,1
1,2,1,1,1,1,1,1,1,1,1,1,1,1,1,1,1,2,1
1,2,1,1,1,1,1,1,3,3,3,1,1,1,1,1,1,2,1
1,1,2,1,1,1,1,3,3,2,3,3,1,1,1,1,2,1,1
1,1,2,1,1,1,1,1,3,3,3,1,1,1,1,1,2,1,1
1,1,1,2,1,1,1,1,1,1,1,1,1,1,1,2,1,1,1
1,1,1,1,2,1,1,1,1,1,1,1,1,1,2,1,1,1,1
1,1,1,1,1,2,1,1,1,1,1,1,1,2,1,1,1,1,1
1,1,1,1,1,1,2,1,1,1,1,1,2,1,1,1,1,1,1
1,1,1,1,1,1,1,2,2,2,2,2,1,1,1,1,1,1,1
endlayer

layer
1,1,1,1,1,1,1,2,2,2,2,2,1,1,1,1,1,1,1
1,1,1,1,1,1,2,4,5,4,5,4,2,1,1,1,1,1,1
1,1,1,1,1,2,6,7,6,7,6,7,6,2,1,1,1,1,1
1,1,1,1,2,4,5,4,5,4,5,4,5,4,2,1,1,1,1
1,1,1,2,6,7,6,7,2,2,2,7,6,7,6,2,1,1,1
1,1,2,4,5,4,5,2,8,8,8,2,5,4,5,4,2,1,1
1,1,2,7,6,7,2,8,8,2,8,8,2,7,6,7,2,1,1
1,2,5,4,5,4,5,2,8,8,8,2,5,4,5,4,5,2,1
1,2,6,7,6,7,6,7,2,2,2,7,6,7,6,7,6,2,1
1,2,5,4,5,4,5,4,5,4,5,4,5,4,5,4,5,2,1
2,7,6,7,6,7,6,7,6,7,6,7,6,7,6,7,6,7,2
2,4,5,4,5,4,5,4,5,4,5,4,5,4,5,4,5,4,2
6,7,6,7,6,7,6,7,6,7,6,7,6,7,6,7,6,7,6
7,4,5,4,5,4,5,4,5,4,5,4,5,4,5,4,5,4,5
6,7,6,7,6,7,6,7,6,7,6,7,6,7,6,7,6,7,6
2,4,5,4,5,4,5,4,5,4,5,4,5,4,5,4,5,4,2
2,7,6,7,6,7,6,7,6,7,6,7,6,7,6,7,6,7,2
1,2,5,4,5,4,5,4,5,4,5,4,5,4,5,4,5,2,1
1,2,6,7,6,7,6,7,2,2,2,7,6,7,6,7,6,2,1
1,2,5,4,5,4,5,2,8,8,8,2,5,4,5,4,5,2,1
1,1,2,7,6,7,2,8,8,2,8,8,2,7,6,7,2,1,1
1,1,2,4,5,4,5,2,8,8,8,2,5,4,5,4,2,1,1
1,1,1,2,6,7,6,7,2,2,2,7,6,7,6,2,1,1,1
1,1,1,1,2,4,5,4,5,4,5,4,5,4,2,1,1,1,1
1,1,1,1,1,2,6,7,6,7,6,7,6,2,1,1,1,1,1
1,1,1,1,1,1,2,4,5,4,5,4,2,1,1,1,1,1,1
1,1,1,1,1,1,1,2,2,2,2,2,1,1,1,1,1,1,1
endlayer

layer
1,1,1,1,1,1,1,2,2,2,2,2,1,1,1,1,1,1,1
1,1,1,1,1,1,2,2,0,0,0,2,2,1,1,1,1,1,1
1,1,1,1,1,2,0,0,0,0,0,0,0,2,1,1,1,1,1
1,1,1,1,2,0,0,0,0,0,0,0,0,0,2,1,1,1,1
1,1,1,2,0,0,0,0,9,9,9,0,0,0,0,2,1,1,1
1,1,2,2,0,0,0,9,0,10,0,9,0,0,0,2,2,1,1
1,1,2,0,0,0,9,0,10,2,10,0,9,0,0,0,2,1,1
1,2,0,0,0,0,0,9,0,10,0,9,0,0,0,0,0,2,1
1,2,0,0,0,0,0,0,9,9,9,0,0,0,0,0,0,2,1
1,2,0,0,0,0,0,0,0,0,0,0,0,0,0,0,0,2,1
2,2,0,0,0,0,0,0,0,0,0,0,0,0,0,0,0,2,2
2,0,0,0,0,0,0,0,0,0,0,0,0,0,0,0,0,0,2
0,0,0,0,0,0,0,0,0,0,0,0,0,0,0,0,0,0,0
0,0,0,0,0,0,0,0,0,0,0,0,0,0,0,0,0,0,0
0,0,0,0,0,0,0,0,0,0,0,0,0,0,0,0,0,0,0
2,0,0,0,0,0,0,0,0,0,0,0,0,0,0,0,0,0,2
2,2,0,0,0,0,0,0,0,0,0,0,0,0,0,0,0,2,2
1,2,0,0,0,0,0,0,0,0,0,0,0,0,0,0,0,2,1
1,2,0,0,0,0,0,0,9,9,9,0,0,0,0,0,0,2,1
1,2,0,0,0,0,0,9,0,10,0,9,0,0,0,0,0,2,1
1,1,2,0,0,0,9,0,10,2,10,0,9,0,0,0,2,1,1
1,1,2,2,0,0,0,9,0,10,0,9,0,0,0,2,2,1,1
1,1,1,2,0,0,0,0,9,9,9,0,0,0,0,2,1,1,1
1,1,1,1,2,0,0,0,0,0,0,0,0,0,2,1,1,1,1
1,1,1,1,1,2,0,0,0,0,0,0,0,2,1,1,1,1,1
1,1,1,1,1,1,2,2,0,0,0,2,2,1,1,1,1,1,1
1,1,1,1,1,1,1,2,2,2,2,2,1,1,1,1,1,1,1
endlayer

layer
1,1,1,1,1,1,1,9,9,9,9,9,1,1,1,1,1,1,1
1,1,1,1,1,1,9,2,0,0,0,2,9,1,1,1,1,1,1
1,1,1,1,1,9,0,0,0,0,0,0,0,9,1,1,1,1,1
1,1,1,1,9,0,0,0,0,0,0,0,0,0,9,1,1,1,1
1,1,1,9,0,0,0,0,0,0,0,0,0,0,0,9,1,1,1
1,1,9,2,0,0,0,0,0,10,0,0,0,0,0,2,9,1,1
1,1,9,0,0,0,0,0,10,2,10,0,0,0,0,0,9,1,1
1,9,0,0,0,0,0,0,0,10,0,0,0,0,0,0,0,9,1
1,9,0,0,0,0,0,0,0,0,0,0,0,0,0,0,0,9,1
1,9,0,0,0,0,0,0,0,0,0,0,0,0,0,0,0,9,1
9,2,0,0,0,0,0,0,0,0,0,0,0,0,0,0,0,2,9
9,0,0,0,0,0,0,0,0,0,0,0,0,0,0,0,0,0,9
0,0,0,0,0,0,0,0,0,0,0,0,0,0,0,0,0,0,0
0,0,0,0,0,0,0,0,0,0,0,0,0,0,0,0,0,0,0
0,0,0,0,0,0,0,0,0,0,0,0,0,0,0,0,0,0,0
9,0,0,0,0,0,0,0,0,0,0,0,0,0,0,0,0,0,9
9,2,0,0,0,0,0,0,0,0,0,0,0,0,0,0,0,2,9
1,9,0,0,0,0,0,0,0,0,0,0,0,0,0,0,0,9,1
1,9,0,0,0,0,0,0,0,0,0,0,0,0,0,0,0,9,1
1,9,0,0,0,0,0,0,0,10,0,0,0,0,0,0,0,9,1
1,1,9,0,0,0,0,0,10,2,10,0,0,0,0,0,9,1,1
1,1,9,2,0,0,0,0,0,10,0,0,0,0,0,2,9,1,1
1,1,1,9,0,0,0,0,0,0,0,0,0,0,0,9,1,1,1
1,1,1,1,9,0,0,0,0,0,0,0,0,0,9,1,1,1,1
1,1,1,1,1,9,0,0,0,0,0,0,0,9,1,1,1,1,1
1,1,1,1,1,1,9,2,0,0,0,2,9,1,1,1,1,1,1
1,1,1,1,1,1,1,9,9,9,9,9,1,1,1,1,1,1,1
endlayer

layer
1,1,1,1,1,1,1,0,0,0,0,0,1,1,1,1,1,1,1
1,1,1,1,1,1,0,2,0,0,0,2,0,1,1,1,1,1,1
1,1,1,1,1,0,0,0,0,0,0,0,0,0,1,1,1,1,1
1,1,1,1,0,0,0,0,0,0,0,0,0,0,0,1,1,1,1
1,1,1,0,0,0,0,0,0,0,0,0,0,0,0,0,1,1,1
1,1,0,2,0,0,0,0,0,11,0,0,0,0,0,2,0,1,1
1,1,0,0,0,0,0,0,11,8,11,0,0,0,0,0,0,1,1
1,0,0,0,0,0,0,0,0,11,0,0,0,0,0,0,0,0,1
1,0,0,0,0,0,0,0,0,0,0,0,0,0,0,0,0,0,1
1,0,0,0,0,0,0,0,0,0,0,0,0,0,0,0,0,0,1
0,2,0,0,0,0,0,0,0,0,0,0,0,0,0,0,0,2,0
0,0,0,0,0,0,0,0,0,0,0,0,0,0,0,0,0,0,0
0,0,0,0,0,0,0,0,0,0,0,0,0,0,0,0,0,0,0
0,0,0,0,0,0,0,0,0,0,0,0,0,0,0,0,0,0,0
0,0,0,0,0,0,0,0,0,0,0,0,0,0,0,0,0,0,0
0,0,0,0,0,0,0,0,0,0,0,0,0,0,0,0,0,0,0
0,2,0,0,0,0,0,0,0,0,0,0,0,0,0,0,0,2,0
1,0,0,0,0,0,0,0,0,0,0,0,0,0,0,0,0,0,1
1,0,0,0,0,0,0,0,0,0,0,0,0,0,0,0,0,0,1
1,0,0,0,0,0,0,0,0,11,0,0,0,0,0,0,0,0,1
1,1,0,0,0,0,0,0,11,8,11,0,0,0,0,0,0,1,1
1,1,0,2,0,0,0,0,0,11,0,0,0,0,0,2,0,1,1
1,1,1,0,0,0,0,0,0,0,0,0,0,0,0,0,1,1,1
1,1,1,1,0,0,0,0,0,0,0,0,0,0,0,1,1,1,1
1,1,1,1,1,0,0,0,0,0,0,0,0,0,1,1,1,1,1
1,1,1,1,1,1,0,2,0,0,0,2,0,1,1,1,1,1,1
1,1,1,1,1,1,1,0,0,0,0,0,1,1,1,1,1,1,1
endlayer

layer
1,1,1,1,1,1,1,0,0,0,0,0,1,1,1,1,1,1,1
1,1,1,1,1,1,0,2,0,0,0,2,0,1,1,1,1,1,1
1,1,1,1,1,0,0,0,0,0,0,0,0,0,1,1,1,1,1
1,1,1,1,0,0,0,0,0,0,0,0,0,0,0,1,1,1,1
1,1,1,0,0,0,0,0,0,0,0,0,0,0,0,0,1,1,1
1,1,0,2,0,0,0,0,0,0,0,0,0,0,0,2,0,1,1
1,1,0,0,0,0,0,0,0,0,0,0,0,0,0,0,0,1,1
1,0,0,0,0,0,0,0,0,0,0,0,0,0,0,0,0,0,1
1,0,0,0,0,0,0,0,0,0,0,0,0,0,0,0,0,0,1
1,0,0,0,0,0,0,0,0,0,0,0,0,0,0,0,0,0,1
0,2,0,0,0,0,0,0,0,0,0,0,0,0,0,0,0,2,0
0,0,0,0,0,0,0,0,0,0,0,0,0,0,0,0,0,0,0
0,0,0,0,0,0,0,0,0,0,0,0,0,0,0,0,0,0,0
0,0,0,0,0,0,0,0,0,0,0,0,0,0,0,0,0,0,0
0,0,0,0,0,0,0,0,0,0,0,0,0,0,0,0,0,0,0
0,0,0,0,0,0,0,0,0,0,0,0,0,0,0,0,0,0,0
0,2,0,0,0,0,0,0,0,0,0,0,0,0,0,0,0,2,0
1,0,0,0,0,0,0,0,0,0,0,0,0,0,0,0,0,0,1
1,0,0,0,0,0,0,0,0,0,0,0,0,0,0,0,0,0,1
1,0,0,0,0,0,0,0,0,0,0,0,0,0,0,0,0,0,1
1,1,0,0,0,0,0,0,0,0,0,0,0,0,0,0,0,1,1
1,1,0,2,0,0,0,0,0,0,0,0,0,0,0,2,0,1,1
1,1,1,0,0,0,0,0,0,0,0,0,0,0,0,0,1,1,1
1,1,1,1,0,0,0,0,0,0,0,0,0,0,0,1,1,1,1
1,1,1,1,1,0,0,0,0,0,0,0,0,0,1,1,1,1,1
1,1,1,1,1,1,0,2,0,0,0,2,0,1,1,1,1,1,1
1,1,1,1,1,1,1,0,0,0,0,0,1,1,1,1,1,1,1
endlayer

layer
0,0,0,0,0,0,0,0,0,0,0,0,0,0,0,0,0,0,0
0,0,0,0,0,0,0,2,0,0,0,2,0,0,0,0,0,0,0
0,0,0,0,0,0,0,0,0,0,0,0,0,0,0,0,0,0,0
0,0,0,0,0,0,0,0,0,0,0,0,0,0,0,0,0,0,0
0,0,0,0,0,0,0,0,0,0,0,0,0,0,0,0,0,0,0
0,0,0,2,0,0,0,0,0,0,0,0,0,0,0,2,0,0,0
0,0,0,0,0,0,0,0,0,0,0,0,0,0,0,0,0,0,0
0,0,0,0,0,0,0,0,0,0,0,0,0,0,0,0,0,0,0
0,0,0,0,0,0,0,0,0,0,0,0,0,0,0,0,0,0,0
0,0,0,0,0,0,0,0,0,0,0,0,0,0,0,0,0,0,0
0,2,0,0,0,0,0,0,0,0,0,0,0,0,0,0,0,2,0
0,0,0,0,0,0,0,0,0,0,0,0,0,0,0,0,0,0,0
0,0,0,0,0,0,0,0,0,0,0,0,0,0,0,0,0,0,0
0,0,0,0,0,0,0,0,0,0,0,0,0,0,0,0,0,0,0
0,0,0,0,0,0,0,0,0,0,0,0,0,0,0,0,0,0,0
0,0,0,0,0,0,0,0,0,0,0,0,0,0,0,0,0,0,0
0,2,0,0,0,0,0,0,0,0,0,0,0,0,0,0,0,2,0
0,0,0,0,0,0,0,0,0,0,0,0,0,0,0,0,0,0,0
0,0,0,0,0,0,0,0,0,0,0,0,0,0,0,0,0,0,0
0,0,0,0,0,0,0,0,0,0,0,0,0,0,0,0,0,0,0
0,0,0,0,0,0,0,0,0,0,0,0,0,0,0,0,0,0,0
0,0,0,2,0,0,0,0,0,0,0,0,0,0,0,2,0,0,0
0,0,0,0,0,0,0,0,0,0,0,0,0,0,0,0,0,0,0
0,0,0,0,0,0,0,0,0,0,0,0,0,0,0,0,0,0,0
0,0,0,0,0,0,0,0,0,0,0,0,0,0,0,0,0,0,0
0,0,0,0,0,0,0,2,0,0,0,2,0,0,0,0,0,0,0
0,0,0,0,0,0,0,0,0,0,0,0,0,0,0,0,0,0,0
endlayer

layer
0,0,0,0,0,0,0,12,12,12,12,12,0,0,0,0,0,0,0
0,0,0,0,0,0,12,2,0,0,0,2,12,0,0,0,0,0,0
0,0,0,0,0,12,0,0,0,0,0,0,0,12,0,0,0,0,0
0,0,0,0,12,0,0,0,0,0,0,0,0,0,12,0,0,0,0
0,0,0,12,0,0,0,0,0,0,0,0,0,0,0,12,0,0,0
0,0,12,2,0,0,0,0,0,0,0,0,0,0,0,2,12,0,0
0,0,12,0,0,0,0,0,0,0,0,0,0,0,0,0,12,0,0
0,12,0,0,0,0,0,0,0,0,0,0,0,0,0,0,0,12,0
0,12,0,0,0,0,0,0,0,0,0,0,0,0,0,0,0,12,0
0,12,0,0,0,0,0,0,0,0,0,0,0,0,0,0,0,12,0
12,2,0,0,0,0,0,0,0,0,0,0,0,0,0,0,0,2,12
12,0,0,0,0,0,0,0,0,0,0,0,0,0,0,0,0,0,12
12,0,0,0,0,0,0,0,0,0,0,0,0,0,0,0,0,0,12
12,0,0,0,0,0,0,0,0,0,0,0,0,0,0,0,0,0,12
12,0,0,0,0,0,0,0,0,0,0,0,0,0,0,0,0,0,12
12,0,0,0,0,0,0,0,0,0,0,0,0,0,0,0,0,0,12
12,2,0,0,0,0,0,0,0,0,0,0,0,0,0,0,0,2,12
0,12,0,0,0,0,0,0,0,0,0,0,0,0,0,0,0,12,0
0,12,0,0,0,0,0,0,0,0,0,0,0,0,0,0,0,12,0
0,12,0,0,0,0,0,0,0,0,0,0,0,0,0,0,0,12,0
0,0,12,0,0,0,0,0,0,0,0,0,0,0,0,0,12,0,0
0,0,12,2,0,0,0,0,0,0,0,0,0,0,0,2,12,0,0
0,0,0,12,0,0,0,0,0,0,0,0,0,0,0,12,0,0,0
0,0,0,0,12,0,0,0,0,0,0,0,0,0,12,0,0,0,0
0,0,0,0,0,12,0,0,0,0,0,0,0,12,0,0,0,0,0
0,0,0,0,0,0,12,2,0,0,0,2,12,0,0,0,0,0,0
0,0,0,0,0,0,0,12,12,12,12,12,0,0,0,0,0,0,0
endlayer

layer
0,0,0,0,0,0,0,2,2,2,2,2,0,0,0,0,0,0,0
0,0,0,0,0,0,2,2,13,13,13,2,2,0,0,0,0,0,0
0,0,0,0,0,2,13,0,0,0,0,0,13,2,0,0,0,0,0
0,0,0,0,2,13,0,0,0,0,0,0,0,13,2,0,0,0,0
0,0,0,2,15,0,0,0,0,0,0,0,0,0,14,2,0,0,0
0,0,2,2,0,0,0,0,0,0,0,0,0,0,0,2,2,0,0
0,0,2,15,0,0,0,0,0,0,0,0,0,0,0,14,2,0,0
0,2,15,0,0,0,0,0,0,0,0,0,0,0,0,0,14,2,0
0,2,15,0,0,0,0,0,0,0,0,0,0,0,0,0,14,2,0
0,2,13,0,0,0,0,0,0,0,0,0,0,0,0,0,13,2,0
2,2,0,0,0,0,0,0,0,0,0,0,0,0,0,0,0,2,2
2,15,0,0,0,0,0,0,0,0,0,0,0,0,0,0,0,14,2
2,15,0,0,0,0,0,0,0,0,0,0,0,0,0,0,0,14,2
2,15,0,0,0,0,0,0,0,0,0,0,0,0,0,0,0,14,2
2,15,0,0,0,0,0,0,0,0,0,0,0,0,0,0,0,14,2
2,15,0,0,0,0,0,0,0,0,0,0,0,0,0,0,0,14,2
2,2,0,0,0,0,0,0,0,0,0,0,0,0,0,0,0,2,2
0,2,16,0,0,0,0,0,0,0,0,0,0,0,0,0,16,2,0
0,2,15,0,0,0,0,0,0,0,0,0,0,0,0,0,14,2,0
0,2,15,0,0,0,0,0,0,0,0,0,0,0,0,0,14,2,0
0,0,2,15,0,0,0,0,0,0,0,0,0,0,0,14,2,0,0
0,0,2,2,0,0,0,0,0,0,0,0,0,0,0,2,2,0,0
0,0,0,2,15,0,0,0,0,0,0,0,0,0,14,2,0,0,0
0,0,0,0,2,16,0,0,0,0,0,0,0,16,2,0,0,0,0
0,0,0,0,0,2,16,0,0,0,0,0,16,2,0,0,0,0,0
0,0,0,0,0,0,2,2,16,16,16,2,2,0,0,0,0,0,0
0,0,0,0,0,0,0,2,2,2,2,2,0,0,0,0,0,0,0
endlayer

layer
0,0,0,0,0,0,0,9,9,9,9,9,0,0,0,0,0,0,0
0,0,0,0,0,0,9,17,17,17,17,17,9,0,0,0,0,0,0
0,0,0,0,0,9,17,0,0,0,0,0,17,9,0,0,0,0,0
0,0,0,0,9,17,0,0,0,0,0,0,0,17,9,0,0,0,0
0,0,0,9,17,0,0,0,0,0,0,0,0,0,17,9,0,0,0
0,0,9,17,0,0,0,0,0,0,0,0,0,0,0,17,9,0,0
0,0,9,17,0,0,0,0,0,0,0,0,0,0,0,17,9,0,0
0,9,17,0,0,0,0,0,0,0,0,0,0,0,0,0,17,9,0
0,9,17,0,0,0,0,0,0,0,0,0,0,0,0,0,17,9,0
0,9,17,0,0,0,0,0,0,0,0,0,0,0,0,0,17,9,0
9,17,0,0,0,0,0,0,0,0,0,0,0,0,0,0,0,17,9
9,17,0,0,0,0,0,0,0,0,0,0,0,0,0,0,0,17,9
9,17,0,0,0,0,0,0,0,0,0,0,0,0,0,0,0,17,9
9,17,0,0,0,0,0,0,0,0,0,0,0,0,0,0,0,17,9
9,17,0,0,0,0,0,0,0,0,0,0,0,0,0,0,0,17,9
9,17,0,0,0,0,0,0,0,0,0,0,0,0,0,0,0,17,9
9,17,0,0,0,0,0,0,0,0,0,0,0,0,0,0,0,17,9
0,9,17,0,0,0,0,0,0,0,0,0,0,0,0,0,17,9,0
0,9,17,0,0,0,0,0,0,0,0,0,0,0,0,0,17,9,0
0,9,17,0,0,0,0,0,0,0,0,0,0,0,0,0,17,9,0
0,0,9,17,0,0,0,0,0,0,0,0,0,0,0,17,9,0,0
0,0,9,17,0,0,0,0,0,0,0,0,0,0,0,17,9,0,0
0,0,0,9,17,0,0,0,0,0,0,0,0,0,17,9,0,0,0
0,0,0,0,9,17,0,0,0,0,0,0,0,17,9,0,0,0,0
0,0,0,0,0,9,17,0,0,0,0,0,17,9,0,0,0,0,0
0,0,0,0,0,0,9,17,17,17,17,17,9,0,0,0,0,0,0
0,0,0,0,0,0,0,9,9,9,9,9,0,0,0,0,0,0,0
endlayer

layer
0,0,0,0,0,0,0,0,0,0,0,0,0,0,0,0,0,0,0
0,0,0,0,0,0,0,0,0,17,0,0,0,0,0,0,0,0,0
0,0,0,0,0,0,17,17,17,0,17,17,17,0,0,0,0,0,0
0,0,0,0,0,17,0,0,0,0,0,0,0,17,0,0,0,0,0
0,0,0,0,17,0,0,0,0,0,0,0,0,0,17,0,0,0,0
0,0,0,17,0,0,0,0,0,0,0,0,0,0,0,17,0,0,0
0,0,0,17,0,0,0,0,0,0,0,0,0,0,0,17,0,0,0
0,0,17,0,0,0,0,0,0,0,0,0,0,0,0,0,17,0,0
0,0,17,0,0,0,0,0,0,0,0,0,0,0,0,0,17,0,0
0,0,17,0,0,0,0,0,0,0,0,0,0,0,0,0,17,0,0
0,0,17,0,0,0,0,0,0,0,0,0,0,0,0,0,17,0,0
0,17,0,0,0,0,0,0,0,0,0,0,0,0,0,0,0,17,0
0,17,0,0,0,0,0,0,0,0,0,0,0,0,0,0,0,17,0
0,17,0,0,0,0,0,0,0,0,0,0,0,0,0,0,0,17,0
0,17,0,0,0,0,0,0,0,0,0,0,0,0,0,0,0,17,0
0,17,0,0,0,0,0,0,0,0,0,0,0,0,0,0,0,17,0
0,0,17,0,0,0,0,0,0,0,0,0,0,0,0,0,17,0,0
0,0,17,0,0,0,0,0,0,0,0,0,0,0,0,0,17,0,0
0,0,17,0,0,0,0,0,0,0,0,0,0,0,0,0,17,0,0
0,0,17,0,0,0,0,0,0,0,0,0,0,0,0,0,17,0,0
0,0,0,17,0,0,0,0,0,0,0,0,0,0,0,17,0,0,0
0,0,0,17,0,0,0,0,0,0,0,0,0,0,0,17,0,0,0
0,0,0,0,17,0,0,0,0,0,0,0,0,0,17,0,0,0,0
0,0,0,0,0,17,0,0,0,0,0,0,0,17,0,0,0,0,0
0,0,0,0,0,0,17,17,17,0,17,17,17,0,0,0,0,0,0
0,0,0,0,0,0,0,0,0,17,0,0,0,0,0,0,0,0,0
0,0,0,0,0,0,0,0,0,0,0,0,0,0,0,0,0,0,0
endlayer

layer
0,0,0,0,0,0,0,0,0,0,0,0,0,0,0,0,0,0,0
0,0,0,0,0,0,0,0,0,0,0,0,0,0,0,0,0,0,0
0,0,0,0,0,0,0,17,17,17,17,17,0,0,0,0,0,0,0
0,0,0,0,0,0,17,0,0,0,0,0,17,0,0,0,0,0,0
0,0,0,0,0,17,0,0,0,0,0,0,0,17,0,0,0,0,0
0,0,0,0,17,0,0,0,0,0,0,0,0,0,17,0,0,0,0
0,0,0,17,0,0,0,0,0,0,0,0,0,0,0,17,0,0,0
0,0,0,17,0,0,0,0,0,0,0,0,0,0,0,17,0,0,0
0,0,17,0,0,0,0,0,0,0,0,0,0,0,0,0,17,0,0
0,0,17,0,0,0,0,0,0,0,0,0,0,0,0,0,17,0,0
0,0,17,0,0,0,0,0,0,0,0,0,0,0,0,0,17,0,0
0,0,17,0,0,0,0,0,0,0,0,0,0,0,0,0,17,0,0
0,0,17,0,0,0,0,0,0,0,0,0,0,0,0,0,17,0,0
0,0,17,0,0,0,0,0,0,0,0,0,0,0,0,0,17,0,0
0,0,17,0,0,0,0,0,0,0,0,0,0,0,0,0,17,0,0
0,0,17,0,0,0,0,0,0,0,0,0,0,0,0,0,17,0,0
0,0,17,0,0,0,0,0,0,0,0,0,0,0,0,0,17,0,0
0,0,17,0,0,0,0,0,0,0,0,0,0,0,0,0,17,0,0
0,0,17,0,0,0,0,0,0,0,0,0,0,0,0,0,17,0,0
0,0,0,17,0,0,0,0,0,0,0,0,0,0,0,17,0,0,0
0,0,0,17,0,0,0,0,0,0,0,0,0,0,0,17,0,0,0
0,0,0,0,17,0,0,0,0,0,0,0,0,0,17,0,0,0,0
0,0,0,0,0,17,0,0,0,0,0,0,0,17,0,0,0,0,0
0,0,0,0,0,0,17,0,0,0,0,0,17,0,0,0,0,0,0
0,0,0,0,0,0,0,17,17,17,17,17,0,0,0,0,0,0,0
0,0,0,0,0,0,0,0,0,0,0,0,0,0,0,0,0,0,0
0,0,0,0,0,0,0,0,0,0,0,0,0,0,0,0,0,0,0
endlayer

layer
0,0,0,0,0,0,0,0,0,0,0,0,0,0,0,0,0,0,0
0,0,0,0,0,0,0,0,0,0,0,0,0,0,0,0,0,0,0
0,0,0,0,0,0,0,0,0,0,0,0,0,0,0,0,0,0,0
0,0,0,0,0,0,0,17,17,17,17,17,0,0,0,0,0,0,0
0,0,0,0,0,0,17,17,0,0,0,17,17,0,0,0,0,0,0
0,0,0,0,0,17,0,0,0,0,0,0,0,17,0,0,0,0,0
0,0,0,0,17,0,0,0,0,0,0,0,0,0,17,0,0,0,0
0,0,0,0,17,0,0,0,0,0,0,0,0,0,17,0,0,0,0
0,0,0,17,0,0,0,0,0,0,0,0,0,0,0,17,0,0,0
0,0,0,17,0,0,0,0,0,0,0,0,0,0,0,17,0,0,0
0,0,0,17,0,0,0,0,0,0,0,0,0,0,0,17,0,0,0
0,0,17,0,0,0,0,0,0,0,0,0,0,0,0,0,17,0,0
0,0,17,0,0,0,0,0,0,0,0,0,0,0,0,0,17,0,0
0,0,17,0,0,0,0,0,0,0,0,0,0,0,0,0,17,0,0
0,0,17,0,0,0,0,0,0,0,0,0,0,0,0,0,17,0,0
0,0,17,0,0,0,0,0,0,0,0,0,0,0,0,0,17,0,0
0,0,0,17,0,0,0,0,0,0,0,0,0,0,0,17,0,0,0
0,0,0,17,0,0,0,0,0,0,0,0,0,0,0,17,0,0,0
0,0,0,17,0,0,0,0,0,0,0,0,0,0,0,17,0,0,0
0,0,0,0,17,0,0,0,0,0,0,0,0,0,17,0,0,0,0
0,0,0,0,17,0,0,0,0,0,0,0,0,0,17,0,0,0,0
0,0,0,0,0,17,0,0,0,0,0,0,0,17,0,0,0,0,0
0,0,0,0,0,0,17,17,0,0,0,17,17,0,0,0,0,0,0
0,0,0,0,0,0,0,17,17,17,17,17,0,0,0,0,0,0,0
0,0,0,0,0,0,0,0,0,0,0,0,0,0,0,0,0,0,0
0,0,0,0,0,0,0,0,0,0,0,0,0,0,0,0,0,0,0
0,0,0,0,0,0,0,0,0,0,0,0,0,0,0,0,0,0,0
endlayer

layer
0,0,0,0,0,0,0,0,0,0,0,0,0,0,0,0,0,0,0
0,0,0,0,0,0,0,0,0,0,0,0,0,0,0,0,0,0,0
0,0,0,0,0,0,0,0,0,0,0,0,0,0,0,0,0,0,0
0,0,0,0,0,0,0,0,0,0,0,0,0,0,0,0,0,0,0
0,0,0,0,0,0,0,0,17,17,17,0,0,0,0,0,0,0,0
0,0,0,0,0,0,17,17,17,17,17,17,17,0,0,0,0,0,0
0,0,0,0,0,17,17,17,0,0,0,17,17,17,0,0,0,0,0
0,0,0,0,0,17,0,0,0,0,0,0,0,17,0,0,0,0,0
0,0,0,0,17,17,0,0,0,0,0,0,0,17,17,0,0,0,0
0,0,0,0,17,0,0,0,0,0,0,0,0,0,17,0,0,0,0
0,0,0,0,17,0,0,0,0,0,0,0,0,0,17,0,0,0,0
0,0,0,17,17,0,0,0,0,0,0,0,0,0,17,17,0,0,0
0,0,0,17,0,0,0,0,0,0,0,0,0,0,0,17,0,0,0
0,0,0,17,0,0,0,0,0,0,0,0,0,0,0,17,0,0,0
0,0,0,17,0,0,0,0,0,0,0,0,0,0,0,17,0,0,0
0,0,0,17,17,0,0,0,0,0,0,0,0,0,17,17,0,0,0
0,0,0,0,17,0,0,0,0,0,0,0,0,0,17,0,0,0,0
0,0,0,0,17,0,0,0,0,0,0,0,0,0,17,0,0,0,0
0,0,0,0,17,17,0,0,0,0,0,0,0,17,17,0,0,0,0
0,0,0,0,0,17,0,0,0,0,0,0,0,17,0,0,0,0,0
0,0,0,0,0,17,17,17,0,0,0,17,17,17,0,0,0,0,0
0,0,0,0,0,0,17,17,17,17,17,17,17,0,0,0,0,0,0
0,0,0,0,0,0,0,0,17,17,17,0,0,0,0,0,0,0,0
0,0,0,0,0,0,0,0,0,0,0,0,0,0,0,0,0,0,0
0,0,0,0,0,0,0,0,0,0,0,0,0,0,0,0,0,0,0
0,0,0,0,0,0,0,0,0,0,0,0,0,0,0,0,0,0,0
0,0,0,0,0,0,0,0,0,0,0,0,0,0,0,0,0,0,0
endlayer

layer
0,0,0,0,0,0,0,0,0,0,0,0,0,0,0,0,0,0,0
0,0,0,0,0,0,0,0,0,0,0,0,0,0,0,0,0,0,0
0,0,0,0,0,0,0,0,0,0,0,0,0,0,0,0,0,0,0
0,0,0,0,0,0,0,0,0,0,0,0,0,0,0,0,0,0,0
0,0,0,0,0,0,0,0,0,0,0,0,0,0,0,0,0,0,0
0,0,0,0,0,0,0,0,0,0,0,0,0,0,0,0,0,0,0
0,0,0,0,0,0,0,0,17,17,17,0,0,0,0,0,0,0,0
0,0,0,0,0,0,17,17,17,17,17,17,17,0,0,0,0,0,0
0,0,0,0,0,0,17,17,17,17,17,17,17,0,0,0,0,0,0
0,0,0,0,0,17,17,17,0,0,0,17,17,17,0,0,0,0,0
0,0,0,0,0,17,17,0,0,0,0,0,17,17,0,0,0,0,0
0,0,0,0,0,17,17,0,0,0,0,0,17,17,0,0,0,0,0
0,0,0,0,17,17,17,0,0,0,0,0,17,17,17,0,0,0,0
0,0,0,0,17,17,0,0,0,0,0,0,0,17,17,0,0,0,0
0,0,0,0,17,17,17,0,0,0,0,0,17,17,17,0,0,0,0
0,0,0,0,0,17,17,0,0,0,0,0,17,17,0,0,0,0,0
0,0,0,0,0,17,17,0,0,0,0,0,17,17,0,0,0,0,0
0,0,0,0,0,17,17,17,0,0,0,17,17,17,0,0,0,0,0
0,0,0,0,0,0,17,17,17,17,17,17,17,0,0,0,0,0,0
0,0,0,0,0,0,17,17,17,17,17,17,17,0,0,0,0,0,0
0,0,0,0,0,0,0,0,17,17,17,0,0,0,0,0,0,0,0
0,0,0,0,0,0,0,0,0,0,0,0,0,0,0,0,0,0,0
0,0,0,0,0,0,0,0,0,0,0,0,0,0,0,0,0,0,0
0,0,0,0,0,0,0,0,0,0,0,0,0,0,0,0,0,0,0
0,0,0,0,0,0,0,0,0,0,0,0,0,0,0,0,0,0,0
0,0,0,0,0,0,0,0,0,0,0,0,0,0,0,0,0,0,0
0,0,0,0,0,0,0,0,0,0,0,0,0,0,0,0,0,0,0
endlayer

layer
0,0,0,0,0,0,0,0,0,0,0,0,0,0,0,0,0,0,0
0,0,0,0,0,0,0,0,0,0,0,0,0,0,0,0,0,0,0
0,0,0,0,0,0,0,0,0,0,0,0,0,0,0,0,0,0,0
0,0,0,0,0,0,0,0,0,0,0,0,0,0,0,0,0,0,0
0,0,0,0,0,0,0,0,0,0,0,0,0,0,0,0,0,0,0
0,0,0,0,0,0,0,0,0,0,0,0,0,0,0,0,0,0,0
0,0,0,0,0,0,0,0,0,0,0,0,0,0,0,0,0,0,0
0,0,0,0,0,0,0,0,0,0,0,0,0,0,0,0,0,0,0
0,0,0,0,0,0,0,0,0,0,0,0,0,0,0,0,0,0,0
0,0,0,0,0,0,0,0,17,17,17,0,0,0,0,0,0,0,0
0,0,0,0,0,0,0,17,17,17,17,17,0,0,0,0,0,0,0
0,0,0,0,0,0,0,17,17,17,17,17,0,0,0,0,0,0,0
0,0,0,0,0,0,0,17,17,17,17,17,0,0,0,0,0,0,0
0,0,0,0,0,0,17,17,17,17,17,17,17,0,0,0,0,0,0
0,0,0,0,0,0,0,17,17,17,17,17,0,0,0,0,0,0,0
0,0,0,0,0,0,0,17,17,17,17,17,0,0,0,0,0,0,0
0,0,0,0,0,0,0,17,17,17,17,17,0,0,0,0,0,0,0
0,0,0,0,0,0,0,0,17,17,17,0,0,0,0,0,0,0,0
0,0,0,0,0,0,0,0,0,0,0,0,0,0,0,0,0,0,0
0,0,0,0,0,0,0,0,0,0,0,0,0,0,0,0,0,0,0
0,0,0,0,0,0,0,0,0,0,0,0,0,0,0,0,0,0,0
0,0,0,0,0,0,0,0,0,0,0,0,0,0,0,0,0,0,0
0,0,0,0,0,0,0,0,0,0,0,0,0,0,0,0,0,0,0
0,0,0,0,0,0,0,0,0,0,0,0,0,0,0,0,0,0,0
0,0,0,0,0,0,0,0,0,0,0,0,0,0,0,0,0,0,0
0,0,0,0,0,0,0,0,0,0,0,0,0,0,0,0,0,0,0
0,0,0,0,0,0,0,0,0,0,0,0,0,0,0,0,0,0,0
endlayer

