
# Created by Ruins mod version 17.1 Ingame Parser
# authoring Player: ST753M

weight=1
uniqueMinDistance=1000
embed_into_distance=5
acceptable_target_blocks=grass,dirt,stone
unacceptable_target_blocks=flowing_water,water,flowing_lava,lava
dimensions=31,16,16
allowable_overhang=5
max_leveling=0
leveling_buffer=-1
preserve_water=0
preserve_lava=0

biomesToSpawnIn=crystal_forest,mystic_grove

=0,100,air
rule1=0,100,preserveBlock
rule2=0,100,biomesoplenty:white_sandstone_stairs-6
rule3=0,100,biomesoplenty:white_sandstone-0
rule4=0,100,biomesoplenty:white_sandstone_stairs-7
rule5=0,100,biomesoplenty:planks_0-5
rule6=0,100,minecraft:light_blue_glazed_terracotta-0
rule7=0,100,minecraft:light_blue_glazed_terracotta-3
rule8=0,100,biomesoplenty:white_sandstone_stairs-4
rule9=0,100,minecraft:light_blue_glazed_terracotta-1
rule10=0,100,minecraft:light_blue_glazed_terracotta-2
rule11=0,100,biomesoplenty:white_sandstone_stairs-5
rule12=0,100,minecraft:sea_lantern-0
rule13=0,100,biomesoplenty:white_sandstone_stairs-0
rule14=0,100,biomesoplenty:white_sandstone_stairs-2
rule15=0,100,biomesoplenty:white_sandstone_stairs-3
rule16=0,100,biomesoplenty:magic_stairs-6
rule17=0,100,biomesoplenty:magic_stairs-3
rule18=0,100,biomesoplenty:white_sandstone_stairs-1
rule19=0,100,biomesoplenty:magic_fence-0
rule20=0,100,biomesoplenty:other_slab-1
rule21=0,100,biomesoplenty:magic_stairs-4
rule22=0,100,biomesoplenty:magic_stairs-7
rule23=0,100,biomesoplenty:magic_stairs-5
rule24=0,100,IInventory;minecraft:chest;biomesoplenty:gem#3#6#1+minecraft:milk_bucket#1#0#6+biomesoplenty:sapling_1#1#7#13+biomesoplenty:jar_filled#1#1#21+minecraft:diamond#2#0#25-5
rule25=0,100,IInventory;minecraft:chest;biomesoplenty:grass#3#7#0+minecraft:potion#{Potion:"minecraft:invisibility"}#0#11+biomesoplenty:gem#4#6#13+minecraft:potion#{Potion:"minecraft:invisibility"}#0#15+biomesoplenty:peach#5#0#21+biomesoplenty:terrarium#1#10#25-5
rule26=0,100,CommandBlock:RUINSTRIGGER /summon illusion_illager ~ ~1 ~ {PersistenceRequired:1}:@-1
rule27=0,100,biomesoplenty:magic_stairs-2
rule28=0,100,biomesoplenty:magic_stairs-0
rule29=0,100,biomesoplenty:magic_stairs-1

layer
1,1,1,1,1,1,1,1,1,1,1,1,1,1,1,1
1,1,1,1,1,1,1,1,1,1,1,1,1,1,1,1
1,1,1,1,1,1,1,1,1,1,1,1,1,1,1,1
1,1,1,1,1,1,4,3,3,2,1,1,1,1,1,1
1,1,1,1,5,5,5,5,5,5,5,5,1,1,1,1
1,1,1,1,5,7,6,7,6,7,6,5,1,1,1,1
1,1,1,8,5,10,9,10,9,10,9,5,8,1,1,1
1,1,1,3,5,7,6,7,6,7,6,5,3,1,1,1
1,1,1,3,5,10,9,10,9,10,9,5,3,1,1,1
1,1,1,11,5,7,6,7,6,7,6,5,11,1,1,1
1,1,1,1,5,10,9,10,9,10,9,5,1,1,1,1
1,1,1,1,5,5,5,5,5,5,5,5,1,1,1,1
1,1,1,1,1,1,4,3,3,2,1,1,1,1,1,1
1,1,1,1,1,1,1,1,1,1,1,1,1,1,1,1
1,1,1,1,1,1,1,1,1,1,1,1,1,1,1,1
1,1,1,1,1,1,1,1,1,1,1,1,1,1,1,1
endlayer

layer
1,1,1,1,1,1,1,1,1,1,1,1,1,1,1,1
1,1,1,1,1,1,1,1,1,1,1,1,1,1,1,1
1,1,1,1,1,1,1,1,1,1,1,1,1,1,1,1
1,1,1,1,1,4,3,3,3,3,2,1,1,1,1,1
1,1,1,1,5,5,3,3,3,3,5,5,1,1,1,1
1,1,1,8,5,3,3,3,3,3,3,5,8,1,1,1
1,1,1,3,3,3,3,3,3,3,3,3,3,1,1,1
1,1,1,3,3,3,3,3,3,3,3,3,3,1,1,1
1,1,1,3,3,3,3,3,3,3,3,3,3,1,1,1
1,1,1,3,3,3,3,3,3,3,3,3,3,1,1,1
1,1,1,11,5,3,3,3,3,3,3,5,11,1,1,1
1,1,1,1,5,5,3,3,3,3,5,5,1,1,1,1
1,1,1,1,1,4,3,3,3,3,2,1,1,1,1,1
1,1,1,1,1,1,1,1,1,1,1,1,1,1,1,1
1,1,1,1,1,1,1,1,1,1,1,1,1,1,1,1
1,1,1,1,1,1,1,1,1,1,1,1,1,1,1,1
endlayer

layer
1,1,1,1,1,1,1,1,1,1,1,1,1,1,1,1
1,1,1,1,1,1,8,1,1,8,1,1,1,1,1,1
1,1,1,1,1,1,3,1,1,3,1,1,1,1,1,1
1,1,1,1,4,3,3,7,10,3,3,2,1,1,1,1
1,1,1,8,5,3,3,3,3,3,3,5,8,1,1,1
1,1,1,3,3,3,3,3,3,3,3,3,3,1,1,1
1,4,3,3,3,3,3,3,3,3,3,3,3,3,2,1
1,1,1,9,3,3,3,3,3,3,3,3,6,1,1,1
1,1,1,10,3,3,3,3,3,3,3,3,7,1,1,1
1,4,3,3,3,3,3,3,3,3,3,3,3,3,2,1
1,1,1,3,3,3,3,3,3,3,3,3,3,1,1,1
1,1,1,11,5,3,3,3,3,3,3,5,11,1,1,1
1,1,1,1,4,3,3,6,9,3,3,2,1,1,1,1
1,1,1,1,1,1,3,1,1,3,1,1,1,1,1,1
1,1,1,1,1,1,11,1,1,11,1,1,1,1,1,1
1,1,1,1,1,1,1,1,1,1,1,1,1,1,1,1
endlayer

layer
1,1,1,1,1,1,1,1,1,1,1,1,1,1,1,1
1,1,1,1,1,1,3,1,1,3,1,1,1,1,1,1
1,1,4,8,1,8,3,1,1,3,8,1,8,8,1,1
1,1,4,3,3,3,3,6,9,3,3,3,3,2,1,1
1,1,1,3,3,3,3,3,3,3,3,3,3,1,1,1
1,1,4,3,3,3,3,3,3,3,3,3,3,2,1,1
1,3,3,3,3,3,3,3,3,3,3,3,3,3,3,1
1,1,1,6,3,3,3,3,3,3,3,3,9,1,1,1
1,1,1,7,3,3,3,3,3,3,3,3,10,1,1,1
1,3,3,3,3,3,3,3,3,3,3,3,3,3,3,1
1,1,4,3,3,3,3,3,3,3,3,3,3,2,1,1
1,1,1,3,3,3,3,3,3,3,3,3,3,1,1,1
1,1,4,3,3,3,3,7,10,3,3,3,3,2,1,1
1,1,11,11,1,11,3,1,1,3,11,1,11,2,1,1
1,1,1,1,1,1,3,1,1,3,1,1,1,1,1,1
1,1,1,1,1,1,1,1,1,1,1,1,1,1,1,1
endlayer

layer
1,1,1,1,1,1,1,1,1,1,1,1,1,1,1,1
1,1,1,1,1,1,3,8,8,3,1,1,1,1,1,1
1,1,12,3,1,3,3,3,3,3,3,1,3,12,1,1
1,1,3,3,3,3,3,5,5,3,3,3,3,3,1,1
1,1,1,3,7,10,7,10,7,10,7,10,3,1,1,1
1,1,3,3,6,9,6,9,6,9,6,9,3,3,1,1
1,3,3,3,7,10,7,10,7,10,7,10,3,3,3,1
1,4,3,3,6,9,6,9,6,9,6,9,3,3,2,1
1,4,3,3,7,10,7,10,7,10,7,10,3,3,2,1
1,3,3,3,6,9,6,9,6,9,6,9,3,3,3,1
1,1,3,3,7,10,7,10,7,10,7,10,3,3,1,1
1,1,1,3,6,9,6,9,6,9,6,9,3,1,1,1
1,1,3,3,3,3,3,3,3,3,3,3,3,3,1,1
1,1,12,3,1,3,3,3,3,3,3,1,3,12,1,1
1,1,1,1,1,1,3,11,11,3,1,1,1,1,1,1
1,1,1,1,1,1,1,1,1,1,1,1,1,1,1,1
endlayer

layer
1,1,1,1,1,1,1,1,1,1,1,1,1,1,1,1
1,1,1,1,1,1,13,1,1,13,1,1,1,1,1,1
1,1,3,3,1,13,3,1,1,3,13,1,3,3,1,1
1,1,3,3,3,3,3,0,0,3,3,3,3,3,1,1
1,1,1,3,0,0,0,0,0,0,0,0,3,1,1,1
1,1,15,3,0,0,0,0,0,0,0,0,3,14,1,1
1,15,3,3,0,0,0,0,0,0,0,0,3,3,14,1
1,1,1,3,0,0,0,0,0,0,0,0,3,1,1,1
1,1,1,3,0,0,0,0,0,0,0,0,3,1,1,1
1,15,3,3,0,0,0,0,0,0,0,0,3,3,14,1
1,1,15,3,0,0,0,0,0,0,0,0,3,14,1,1
1,1,1,3,0,17,16,0,0,0,0,0,3,1,1,1
1,1,3,3,3,3,3,3,3,3,3,3,3,3,1,1
1,1,3,3,1,18,3,1,1,3,18,1,3,3,1,1
1,1,1,1,1,1,18,1,1,18,1,1,1,1,1,1
1,1,1,1,1,1,1,1,1,1,1,1,1,1,1,1
endlayer

layer
1,1,1,1,1,1,1,1,1,1,1,1,1,1,1,1
1,1,1,1,1,1,1,1,1,1,1,1,1,1,1,1
1,1,1,19,1,1,19,1,1,19,1,1,19,1,1,1
1,1,19,3,0,0,3,0,0,3,0,0,3,19,1,1
1,1,1,0,0,0,0,0,0,0,0,0,0,1,1,1
1,1,1,0,0,0,0,0,0,0,0,0,0,1,1,1
1,1,19,3,0,0,0,0,0,0,0,0,3,19,1,1
1,1,1,0,0,0,0,0,0,0,0,0,0,1,1,1
1,1,1,0,0,0,0,0,0,0,0,0,0,1,1,1
1,1,19,3,0,0,0,0,0,0,0,0,3,19,1,1
1,1,1,0,0,0,0,0,0,0,0,0,0,1,1,1
1,1,1,0,0,0,17,16,0,0,0,0,0,1,1,1
1,1,19,3,0,0,3,0,0,3,0,0,3,19,1,1
1,1,1,19,1,1,19,1,1,19,1,1,19,1,1,1
1,1,1,1,1,1,1,1,1,1,1,1,1,1,1,1
1,1,1,1,1,1,1,1,1,1,1,1,1,1,1,1
endlayer

layer
1,1,1,1,1,1,1,1,1,1,1,1,1,1,1,1
1,1,1,1,1,1,1,1,1,1,1,1,1,1,1,1
1,1,1,19,1,1,0,1,1,0,1,1,19,1,1,1
1,1,19,3,0,0,3,0,0,3,0,0,3,19,1,1
1,1,1,0,0,0,0,0,0,0,0,0,0,1,1,1
1,1,1,0,0,0,0,0,0,0,0,0,0,1,1,1
1,1,0,3,0,0,0,0,0,0,0,0,3,0,1,1
1,1,1,0,0,0,0,0,0,0,0,0,0,1,1,1
1,1,1,0,0,0,0,0,0,0,0,0,0,1,1,1
1,1,0,3,0,0,0,0,0,0,0,0,3,0,1,1
1,1,1,0,0,0,0,0,0,0,0,0,0,1,1,1
1,1,1,0,0,0,0,17,16,0,0,0,0,1,1,1
1,1,19,3,0,0,3,0,0,3,0,0,3,19,1,1
1,1,1,19,1,1,0,1,1,0,1,1,19,1,1,1
1,1,1,1,1,1,1,1,1,1,1,1,1,1,1,1
1,1,1,1,1,1,1,1,1,1,1,1,1,1,1,1
endlayer

layer
1,1,1,1,1,1,1,1,1,1,1,1,1,1,1,1
1,1,1,1,1,1,1,1,1,1,1,1,1,1,1,1
1,1,1,19,1,1,0,1,1,0,1,1,19,1,1,1
1,1,19,3,2,4,20,2,4,20,2,4,3,19,1,1
1,1,1,11,0,0,0,0,0,0,0,0,11,1,1,1
1,1,1,8,0,0,0,0,0,0,0,0,8,1,1,1
1,1,0,20,0,0,0,0,0,0,0,0,20,0,1,1
1,1,1,11,0,0,0,0,0,0,0,0,11,1,1,1
1,1,1,8,0,0,0,0,0,0,0,0,8,1,1,1
1,1,0,20,0,0,0,0,0,0,0,0,20,0,1,1
1,1,1,11,0,0,0,0,0,0,0,0,11,1,1,1
1,1,1,8,0,0,0,0,17,16,0,0,8,1,1,1
1,1,19,3,2,4,20,2,4,20,2,4,3,19,1,1
1,1,1,19,1,1,0,1,1,0,1,1,19,1,1,1
1,1,1,1,1,1,1,1,1,1,1,1,1,1,1,1
1,1,1,1,1,1,1,1,1,1,1,1,1,1,1,1
endlayer

layer
1,1,1,1,1,1,1,1,1,1,1,1,1,1,1,1
1,1,1,1,1,1,1,2,4,1,1,1,1,1,1,1
1,1,3,3,1,1,0,2,4,0,1,1,3,3,1,1
1,1,3,3,3,3,3,3,3,3,3,3,3,3,1,1
1,1,1,3,0,0,0,0,0,0,0,0,3,1,1,1
1,1,1,3,0,0,0,0,0,0,0,0,3,1,1,1
1,1,0,3,0,0,0,0,0,0,0,0,3,0,1,1
1,11,11,3,0,0,0,0,0,0,0,0,3,11,11,1
1,8,8,3,0,0,0,0,0,0,0,0,3,8,8,1
1,1,0,3,0,0,0,0,0,0,0,0,3,0,1,1
1,1,1,3,0,0,0,0,0,0,0,0,3,1,1,1
1,1,1,3,0,0,0,0,0,17,16,0,3,1,1,1
1,1,3,3,3,3,3,3,3,3,3,3,3,3,1,1
1,1,3,3,1,1,0,2,4,0,1,1,3,3,1,1
1,1,1,1,1,1,1,2,4,1,1,1,1,1,1,1
1,1,1,1,1,1,1,1,1,1,1,1,1,1,1,1
endlayer

layer
1,1,1,1,1,1,22,21,21,16,1,1,1,1,1,1
1,1,1,1,1,1,22,5,5,16,1,1,1,1,1,1
1,1,12,3,21,21,22,5,5,16,21,21,3,12,1,1
1,1,3,3,3,3,3,5,5,3,3,3,3,3,1,1
1,1,22,3,7,10,7,10,7,10,7,10,3,16,1,1
1,1,22,3,6,9,6,9,6,9,6,9,3,16,1,1
21,21,21,3,7,10,7,10,7,10,7,10,3,21,21,21
22,5,5,5,6,9,6,9,6,9,6,9,5,5,5,16
22,5,5,5,7,10,7,10,7,10,7,10,5,5,5,16
23,23,23,3,6,9,6,9,6,9,6,9,3,23,23,23
1,1,22,3,7,10,7,10,7,10,7,10,3,16,1,1
1,1,22,3,6,16,0,0,0,0,17,9,3,16,1,1
1,1,3,3,3,5,5,5,5,5,5,3,3,3,1,1
1,1,12,3,23,23,22,5,5,16,23,23,3,12,1,1
1,1,1,1,1,1,22,5,5,16,1,1,1,1,1,1
1,1,1,1,1,1,22,23,23,16,1,1,1,1,1,1
endlayer

layer
1,1,1,1,1,1,19,19,19,19,1,1,1,1,1,1
1,1,1,1,1,1,19,0,0,19,1,1,1,1,1,1
1,1,3,3,0,0,19,0,0,19,0,0,3,3,1,1
1,1,3,3,3,3,3,0,0,3,3,3,3,3,1,1
1,1,0,3,0,0,0,0,0,0,0,0,3,0,1,1
1,1,0,3,0,0,0,0,0,0,0,0,3,0,1,1
19,19,19,3,0,0,0,0,0,0,0,0,3,19,19,19
19,0,0,0,0,0,0,0,0,0,0,0,0,0,0,19
19,0,0,0,0,0,0,0,0,0,0,0,0,0,0,19
19,19,19,3,0,0,0,0,0,0,0,0,3,19,19,19
1,1,0,3,0,0,0,0,0,0,0,0,3,0,1,1
1,1,0,3,0,17,16,0,0,0,0,0,3,0,1,1
1,1,3,3,3,3,3,3,3,3,3,3,3,3,1,1
1,1,3,3,0,0,19,0,0,19,0,0,3,3,1,1
1,1,1,1,1,1,19,0,0,19,1,1,1,1,1,1
1,1,1,1,1,1,19,19,19,19,1,1,1,1,1,1
endlayer

layer
1,1,1,1,1,1,0,0,0,0,1,1,1,1,1,1
1,1,1,1,1,1,0,0,0,0,1,1,1,1,1,1
1,1,0,19,0,0,19,0,0,19,0,0,19,0,1,1
1,1,19,3,0,0,3,0,0,3,0,0,3,19,1,1
1,1,0,0,0,0,0,0,0,0,0,0,0,0,1,1
1,1,0,0,0,0,0,0,0,0,0,0,0,0,1,1
0,0,19,3,0,0,0,0,0,0,0,0,3,19,0,0
0,0,0,0,0,0,0,0,0,0,0,0,0,0,0,0
0,0,0,0,0,0,0,0,0,0,0,0,0,0,0,0
0,0,19,3,0,0,0,0,0,0,0,0,3,19,0,0
1,1,0,0,0,0,0,0,0,0,0,0,0,0,1,1
1,1,0,0,0,0,17,16,0,0,0,0,0,0,1,1
1,1,19,3,0,0,3,0,0,3,0,0,3,19,1,1
1,1,0,19,0,0,19,0,0,19,0,0,19,0,1,1
1,1,1,1,1,1,0,0,0,0,1,1,1,1,1,1
1,1,1,1,1,1,0,0,0,0,1,1,1,1,1,1
endlayer

layer
1,1,1,1,1,1,0,0,0,0,1,1,1,1,1,1
1,1,1,1,1,1,0,0,0,0,1,1,1,1,1,1
1,1,0,19,0,0,0,0,0,0,0,0,19,0,1,1
1,1,19,3,0,0,3,0,0,3,0,0,3,19,1,1
1,1,0,0,0,0,0,0,0,0,0,0,0,0,1,1
1,1,0,0,0,0,0,0,0,0,0,0,0,0,1,1
0,0,0,3,0,0,0,0,0,0,0,0,3,0,0,0
0,0,0,0,0,0,0,0,0,0,0,0,0,0,0,0
0,0,0,0,0,0,0,0,0,0,0,0,0,0,0,0
0,0,0,3,0,0,0,0,0,0,0,0,3,0,0,0
1,1,0,0,0,0,0,0,0,0,0,0,0,0,1,1
1,1,0,0,0,0,0,17,16,0,0,0,0,0,1,1
1,1,19,3,0,0,3,0,0,3,0,0,3,19,1,1
1,1,0,19,0,0,0,0,0,0,0,0,19,0,1,1
1,1,1,1,1,1,0,0,0,0,1,1,1,1,1,1
1,1,1,1,1,1,0,0,0,0,1,1,1,1,1,1
endlayer

layer
1,1,1,1,1,1,0,0,0,0,1,1,1,1,1,1
1,1,1,1,1,1,0,0,0,0,1,1,1,1,1,1
1,1,0,19,0,0,0,0,0,0,0,0,19,0,1,1
1,1,19,3,2,4,20,2,4,20,2,4,3,19,1,1
1,1,0,11,0,0,0,0,0,0,0,0,11,0,1,1
1,1,0,8,0,0,0,0,0,0,0,0,8,0,1,1
0,0,0,20,0,0,0,0,0,0,0,0,20,0,0,0
0,0,0,11,0,0,0,0,0,0,0,0,11,0,0,0
0,0,0,8,0,0,0,0,0,0,0,0,8,0,0,0
0,0,0,20,0,0,0,0,0,0,0,0,20,0,0,0
1,1,0,11,0,0,0,0,0,0,0,0,11,0,1,1
1,1,0,8,0,0,0,0,17,16,0,0,8,0,1,1
1,1,19,3,2,4,20,2,4,20,2,4,3,19,1,1
1,1,0,19,0,0,0,0,0,0,0,0,19,0,1,1
1,1,1,1,1,1,0,0,0,0,1,1,1,1,1,1
1,1,1,1,1,1,0,0,0,0,1,1,1,1,1,1
endlayer

layer
1,1,1,1,1,1,0,0,0,0,1,1,1,1,1,1
1,1,1,1,1,1,0,0,0,0,1,1,1,1,1,1
1,1,3,3,0,0,0,0,0,0,0,0,3,3,1,1
1,1,3,3,3,3,3,3,3,3,3,3,3,3,1,1
1,1,0,3,0,0,0,0,0,0,0,0,3,0,1,1
1,1,0,3,0,0,0,0,0,0,0,0,3,0,1,1
0,0,0,3,0,0,0,0,0,0,0,0,3,0,0,0
0,0,0,3,0,0,0,0,0,0,0,0,3,0,0,0
0,0,0,3,0,0,0,0,0,0,0,0,3,0,0,0
0,0,0,3,0,0,0,0,0,0,0,0,3,0,0,0
1,1,0,3,0,0,0,0,0,0,0,0,3,0,1,1
1,1,0,3,0,0,0,0,0,17,16,0,3,0,1,1
1,1,3,3,3,3,3,3,3,3,3,3,3,3,1,1
1,1,3,3,0,0,0,0,0,0,0,0,3,3,1,1
1,1,1,1,1,1,0,0,0,0,1,1,1,1,1,1
1,1,1,1,1,1,0,0,0,0,1,1,1,1,1,1
endlayer

layer
1,1,1,1,1,1,0,0,0,0,1,1,1,1,1,1
1,1,1,1,1,1,0,0,0,0,1,1,1,1,1,1
1,1,12,3,21,21,21,21,21,21,21,21,3,12,1,1
1,1,3,3,3,3,3,3,3,3,3,3,3,3,1,1
1,1,22,3,23,23,23,23,23,23,23,23,3,16,1,1
1,1,22,3,16,0,0,0,0,0,0,22,3,16,1,1
0,0,22,3,16,0,0,0,0,0,0,22,3,16,0,0
0,0,22,3,16,0,0,0,0,0,0,22,3,16,0,0
0,0,22,3,16,0,0,0,0,0,0,22,3,16,0,0
0,0,22,3,16,0,0,0,0,0,0,22,3,16,0,0
1,1,22,3,16,0,0,0,0,0,0,22,3,16,1,1
1,1,22,3,21,16,0,0,0,0,17,21,3,16,1,1
1,1,3,3,3,3,3,3,3,3,3,3,3,3,1,1
1,1,12,3,23,23,23,23,23,23,23,23,3,12,1,1
1,1,1,1,1,1,0,0,0,0,1,1,1,1,1,1
1,1,1,1,1,1,0,0,0,0,1,1,1,1,1,1
endlayer

layer
1,1,1,1,1,1,0,0,0,0,1,1,1,1,1,1
1,22,21,21,21,21,21,21,21,21,21,21,21,21,16,1
1,22,3,3,3,3,3,3,3,3,3,3,3,3,16,1
1,22,3,10,7,10,7,10,7,10,7,10,7,3,16,1
1,22,3,9,6,9,6,9,6,9,6,9,6,3,16,1
1,22,3,10,7,10,7,10,7,10,7,10,7,3,16,1
0,22,3,9,6,9,6,9,6,9,6,9,6,3,16,0
0,22,3,10,7,10,7,10,7,10,7,10,7,3,16,0
0,22,3,9,6,9,6,9,6,9,6,9,6,3,16,0
0,22,3,10,7,10,7,10,7,10,7,10,7,3,16,0
1,22,3,9,6,9,6,9,6,9,6,9,6,3,16,1
1,22,3,10,7,10,7,0,0,0,0,17,7,3,16,1
1,22,3,9,6,9,6,9,6,9,6,9,6,3,16,1
1,22,3,3,3,3,3,3,3,3,3,3,3,3,16,1
1,22,23,23,23,23,23,23,23,23,23,23,23,23,23,1
1,1,1,1,1,1,0,0,0,0,1,1,1,1,1,1
endlayer

layer
1,1,1,1,1,1,0,0,0,0,1,1,1,1,1,1
1,3,3,0,0,0,0,0,0,0,0,0,0,3,3,1
1,3,3,3,3,3,3,3,3,3,3,3,3,3,3,1
1,0,3,0,0,0,0,0,0,0,0,0,0,3,0,1
1,0,3,0,0,0,0,25,24,0,0,0,0,3,0,1
1,0,3,0,0,0,0,0,0,0,0,0,0,3,0,1
0,0,3,0,0,0,0,0,0,0,0,0,0,3,0,0
0,0,3,0,0,0,0,26,0,0,0,0,0,3,0,0
0,0,3,0,0,0,0,0,0,0,0,0,0,3,0,0
0,0,3,0,0,0,0,0,0,0,0,0,0,3,0,0
1,0,3,0,0,0,0,0,0,0,0,0,0,3,0,1
1,0,3,0,0,0,0,0,0,0,0,0,0,3,0,1
1,0,3,0,0,0,0,0,0,0,0,0,0,3,0,1
1,3,3,3,3,3,3,3,3,3,3,3,3,3,3,1
1,3,3,0,0,0,0,0,0,0,0,0,0,3,3,1
1,1,1,1,1,1,0,0,0,0,1,1,1,1,1,1
endlayer

layer
1,1,1,1,1,1,0,0,0,0,1,1,1,1,1,1
1,0,19,0,0,0,0,0,0,0,0,0,0,19,0,1
1,19,3,19,19,19,19,19,19,19,19,19,19,3,19,1
1,0,19,0,0,0,0,0,0,0,0,0,0,19,0,1
1,0,19,0,0,0,0,0,0,0,0,0,0,19,0,1
1,0,19,0,0,0,0,0,0,0,0,0,0,19,0,1
0,0,19,0,0,0,0,0,0,0,0,0,0,19,0,0
0,0,19,0,0,0,0,0,0,0,0,0,0,19,0,0
0,0,19,0,0,0,0,0,0,0,0,0,0,19,0,0
0,0,19,0,0,0,0,0,0,0,0,0,0,19,0,0
1,0,19,0,0,0,0,0,0,0,0,0,0,19,0,1
1,0,19,0,0,0,0,0,0,0,0,0,0,19,0,1
1,0,19,0,0,0,0,0,0,0,0,0,0,19,0,1
1,19,3,19,19,19,19,19,19,19,19,19,19,3,19,1
1,0,19,0,0,0,0,0,0,0,0,0,0,19,0,1
1,1,1,1,1,1,0,0,0,0,1,1,1,1,1,1
endlayer

layer
1,1,1,1,1,1,0,0,0,0,1,1,1,1,1,1
1,0,19,0,0,0,0,0,0,0,0,0,0,19,0,1
1,19,3,0,0,0,0,0,0,0,0,0,0,3,19,1
1,0,0,0,0,0,0,0,0,0,0,0,0,0,0,1
1,0,0,0,0,0,0,0,0,0,0,0,0,0,0,1
1,0,0,0,0,0,0,0,0,0,0,0,0,0,0,1
0,0,0,0,0,0,0,0,0,0,0,0,0,0,0,0
0,0,0,0,0,0,0,0,0,0,0,0,0,0,0,0
0,0,0,0,0,0,0,0,0,0,0,0,0,0,0,0
0,0,0,0,0,0,0,0,0,0,0,0,0,0,0,0
1,0,0,0,0,0,0,0,0,0,0,0,0,0,0,1
1,0,0,0,0,0,0,0,0,0,0,0,0,0,0,1
1,0,0,0,0,0,0,0,0,0,0,0,0,0,0,1
1,19,3,0,0,0,0,0,0,0,0,0,0,3,19,1
1,0,19,0,0,0,0,0,0,0,0,0,0,19,0,1
1,1,1,1,1,1,0,0,0,0,1,1,1,1,1,1
endlayer

layer
1,1,1,1,1,1,0,0,0,0,1,1,1,1,1,1
1,0,19,0,0,0,0,0,0,0,0,0,0,19,0,1
1,19,3,0,0,0,0,0,0,0,0,0,0,3,19,1
1,0,0,0,0,0,0,0,0,0,0,0,0,0,0,1
1,0,0,0,0,0,0,0,0,0,0,0,0,0,0,1
1,0,0,0,0,0,0,0,0,0,0,0,0,0,0,1
0,0,0,0,0,0,0,0,0,0,0,0,0,0,0,0
0,0,0,0,0,0,0,0,0,0,0,0,0,0,0,0
0,0,0,0,0,0,0,0,0,0,0,0,0,0,0,0
0,0,0,0,0,0,0,0,0,0,0,0,0,0,0,0
1,0,0,0,0,0,0,0,0,0,0,0,0,0,0,1
1,0,0,0,0,0,0,0,0,0,0,0,0,0,0,1
1,0,0,0,0,0,0,0,0,0,0,0,0,0,0,1
1,19,3,0,0,0,0,0,0,0,0,0,0,3,19,1
1,0,19,0,0,0,0,0,0,0,0,0,0,19,0,1
1,1,1,1,1,1,0,0,0,0,1,1,1,1,1,1
endlayer

layer
1,1,8,1,1,1,0,0,0,0,1,1,1,8,1,1
1,0,3,0,0,0,0,0,0,0,0,0,0,3,0,1
4,3,3,0,0,0,0,0,0,0,0,0,0,3,3,2
1,0,0,0,0,0,0,0,0,0,0,0,0,0,0,1
1,0,0,0,0,0,0,0,0,0,0,0,0,0,0,1
1,0,0,0,0,0,0,0,0,0,0,0,0,0,0,1
0,0,0,0,0,0,0,0,0,0,0,0,0,0,0,0
0,0,0,0,0,0,0,0,0,0,0,0,0,0,0,0
0,0,0,0,0,0,0,0,0,0,0,0,0,0,0,0
0,0,0,0,0,0,0,0,0,0,0,0,0,0,0,0
1,0,0,0,0,0,0,0,0,0,0,0,0,0,0,1
1,0,0,0,0,0,0,0,0,0,0,0,0,0,0,1
1,0,0,0,0,0,0,0,0,0,0,0,0,0,0,1
4,3,3,0,0,0,0,0,0,0,0,0,0,3,3,2
1,0,3,0,0,0,0,0,0,0,0,0,0,3,0,1
1,1,11,1,1,1,0,0,0,0,1,1,1,11,1,1
endlayer

layer
1,1,15,3,2,1,0,0,0,0,1,4,3,14,1,1
1,0,17,16,0,0,0,0,0,0,0,0,22,27,0,1
13,28,28,16,0,0,0,0,0,0,0,0,22,27,28,13
3,23,23,23,0,0,0,0,0,0,0,0,22,23,23,3
11,0,0,0,0,0,0,0,0,0,0,0,0,0,0,11
1,0,0,0,0,0,0,0,0,0,0,0,0,0,0,1
0,0,0,0,0,0,0,0,0,0,0,0,0,0,0,0
0,0,0,0,0,0,0,0,0,0,0,0,0,0,0,0
0,0,0,0,0,0,0,0,0,0,0,0,0,0,0,0
0,0,0,0,0,0,0,0,0,0,0,0,0,0,0,0
1,0,0,0,0,0,0,0,0,0,0,0,0,0,0,1
8,0,0,0,0,0,0,0,0,0,0,0,0,0,0,8
3,21,21,21,0,0,0,0,0,0,0,0,22,21,21,3
18,29,17,16,0,0,0,0,0,0,0,0,22,29,29,18
1,0,17,16,0,0,0,0,0,0,0,0,22,27,0,1
1,1,15,3,2,1,0,0,0,0,1,4,3,14,1,1
endlayer

layer
0,0,0,15,3,2,0,0,0,0,4,3,14,0,0,0
0,0,0,17,16,0,0,0,0,0,0,22,27,0,0,0
0,0,0,17,16,0,0,0,0,0,0,22,27,0,0,0
13,28,28,28,16,0,0,0,0,0,0,22,28,28,28,13
3,23,23,23,16,0,0,0,0,0,0,22,23,23,23,3
11,0,0,0,0,0,0,0,0,0,0,0,0,0,0,11
0,0,0,0,0,0,0,0,0,0,0,0,0,0,0,0
0,0,0,0,0,0,0,0,0,0,0,0,0,0,0,0
0,0,0,0,0,0,0,0,0,0,0,0,0,0,0,0
0,0,0,0,0,0,0,0,0,0,0,0,0,0,0,0
8,0,0,0,0,0,0,0,0,0,0,0,0,0,0,8
3,21,21,21,21,0,0,0,0,0,0,22,21,21,21,3
18,29,29,29,16,0,0,0,0,0,0,22,27,29,29,18
0,0,0,17,16,0,0,0,0,0,0,22,27,0,0,0
0,0,0,17,16,0,0,0,0,0,0,22,27,0,0,0
0,0,0,15,3,2,0,0,0,0,4,3,14,0,0,0
endlayer

layer
0,0,0,0,15,3,2,0,0,4,3,14,0,0,0,0
0,0,0,0,17,16,0,0,0,0,22,27,0,0,0,0
0,0,0,0,17,16,0,0,0,0,22,27,0,0,0,0
0,0,0,0,17,16,0,0,0,0,22,27,0,0,0,0
13,28,28,28,17,16,0,0,0,0,22,28,28,28,28,13
3,23,23,23,23,16,0,0,0,0,22,23,23,23,23,3
11,0,0,0,0,0,0,0,0,0,0,0,0,0,0,11
0,0,0,0,0,0,0,0,0,0,0,0,0,0,0,0
0,0,0,0,0,0,0,0,0,0,0,0,0,0,0,0
8,0,0,0,0,0,0,0,0,0,0,0,0,0,0,8
3,21,21,21,21,21,0,0,0,0,22,21,21,21,21,3
18,29,29,29,29,16,0,0,0,0,22,27,29,29,29,18
0,0,0,0,17,16,0,0,0,0,22,27,0,0,0,0
0,0,0,0,17,16,0,0,0,0,22,27,0,0,0,0
0,0,0,0,17,16,0,0,0,0,22,27,0,0,0,0
0,0,0,0,15,3,2,0,0,4,3,14,0,0,0,0
endlayer

layer
0,0,0,0,0,15,3,2,4,3,14,0,0,0,0,0
0,0,0,0,0,17,16,0,0,22,27,0,0,0,0,0
0,0,0,0,0,17,16,0,0,22,27,0,0,0,0,0
0,0,0,0,0,17,16,0,0,22,27,0,0,0,0,0
0,0,0,0,0,17,16,0,0,22,27,0,0,0,0,0
13,28,28,28,28,17,16,0,0,22,28,28,28,28,28,13
3,23,23,23,23,23,16,0,0,22,23,23,23,23,23,3
11,0,0,0,0,0,0,0,0,0,0,0,0,0,0,11
8,0,0,0,0,0,0,0,0,0,0,0,0,0,0,8
3,21,21,21,21,21,21,0,0,22,21,21,21,21,21,3
18,29,29,29,29,29,16,0,0,22,27,29,29,29,29,18
0,0,0,0,0,17,16,0,0,22,27,0,0,0,0,0
0,0,0,0,0,17,16,0,0,22,27,0,0,0,0,0
0,0,0,0,0,17,16,0,0,22,27,0,0,0,0,0
0,0,0,0,0,17,16,0,0,22,27,0,0,0,0,0
0,0,0,0,0,15,3,2,4,3,14,0,0,0,0,0
endlayer

layer
0,0,0,0,0,0,15,14,15,14,0,0,0,0,0,0
0,0,0,0,0,0,17,16,22,27,0,0,0,0,0,0
0,0,0,0,0,0,17,16,22,27,0,0,0,0,0,0
0,0,0,0,0,0,17,16,22,27,0,0,0,0,0,0
0,0,0,0,0,0,17,16,22,27,0,0,0,0,0,0
0,0,0,0,0,0,17,16,22,27,0,0,0,0,0,0
13,28,28,28,28,28,17,16,22,28,28,28,28,28,28,13
18,23,23,23,23,23,23,0,0,23,23,23,23,23,23,18
13,21,21,21,21,21,21,0,0,21,21,21,21,21,21,13
18,29,29,29,29,29,29,16,22,27,29,29,29,29,29,18
0,0,0,0,0,0,17,16,22,27,0,0,0,0,0,0
0,0,0,0,0,0,17,16,22,27,0,0,0,0,0,0
0,0,0,0,0,0,17,16,22,27,0,0,0,0,0,0
0,0,0,0,0,0,17,16,22,27,0,0,0,0,0,0
0,0,0,0,0,0,17,16,22,27,0,0,0,0,0,0
0,0,0,0,0,0,15,14,15,14,0,0,0,0,0,0
endlayer

layer
0,0,0,0,0,0,0,2,4,0,0,0,0,0,0,0
0,0,0,0,0,0,0,17,27,0,0,0,0,0,0,0
0,0,0,0,0,0,0,17,27,0,0,0,0,0,0,0
0,0,0,0,0,0,0,17,27,0,0,0,0,0,0,0
0,0,0,0,0,0,0,17,27,0,0,0,0,0,0,0
0,0,0,0,0,0,0,17,27,0,0,0,0,0,0,0
0,0,0,0,0,0,0,17,27,0,0,0,0,0,0,0
11,28,28,28,28,28,28,17,28,28,28,28,28,28,28,11
8,29,29,29,29,29,29,29,27,29,29,29,29,29,29,8
0,0,0,0,0,0,0,17,27,0,0,0,0,0,0,0
0,0,0,0,0,0,0,17,27,0,0,0,0,0,0,0
0,0,0,0,0,0,0,17,27,0,0,0,0,0,0,0
0,0,0,0,0,0,0,17,27,0,0,0,0,0,0,0
0,0,0,0,0,0,0,17,27,0,0,0,0,0,0,0
0,0,0,0,0,0,0,17,27,0,0,0,0,0,0,0
0,0,0,0,0,0,0,2,4,0,0,0,0,0,0,0
endlayer

layer
0,0,0,0,0,0,0,15,14,0,0,0,0,0,0,0
0,0,0,0,0,0,0,0,0,0,0,0,0,0,0,0
0,0,0,0,0,0,0,0,0,0,0,0,0,0,0,0
0,0,0,0,0,0,0,0,0,0,0,0,0,0,0,0
0,0,0,0,0,0,0,0,0,0,0,0,0,0,0,0
0,0,0,0,0,0,0,0,0,0,0,0,0,0,0,0
0,0,0,0,0,0,0,0,0,0,0,0,0,0,0,0
13,0,0,0,0,0,0,8,2,0,0,0,0,0,0,13
18,0,0,0,0,0,0,4,11,0,0,0,0,0,0,18
0,0,0,0,0,0,0,0,0,0,0,0,0,0,0,0
0,0,0,0,0,0,0,0,0,0,0,0,0,0,0,0
0,0,0,0,0,0,0,0,0,0,0,0,0,0,0,0
0,0,0,0,0,0,0,0,0,0,0,0,0,0,0,0
0,0,0,0,0,0,0,0,0,0,0,0,0,0,0,0
0,0,0,0,0,0,0,0,0,0,0,0,0,0,0,0
0,0,0,0,0,0,0,15,14,0,0,0,0,0,0,0
endlayer

layer
0,0,0,0,0,0,0,0,0,0,0,0,0,0,0,0
0,0,0,0,0,0,0,0,0,0,0,0,0,0,0,0
0,0,0,0,0,0,0,0,0,0,0,0,0,0,0,0
0,0,0,0,0,0,0,0,0,0,0,0,0,0,0,0
0,0,0,0,0,0,0,0,0,0,0,0,0,0,0,0
0,0,0,0,0,0,0,0,0,0,0,0,0,0,0,0
0,0,0,0,0,0,0,0,0,0,0,0,0,0,0,0
0,0,0,0,0,0,0,19,19,0,0,0,0,0,0,0
0,0,0,0,0,0,0,19,19,0,0,0,0,0,0,0
0,0,0,0,0,0,0,0,0,0,0,0,0,0,0,0
0,0,0,0,0,0,0,0,0,0,0,0,0,0,0,0
0,0,0,0,0,0,0,0,0,0,0,0,0,0,0,0
0,0,0,0,0,0,0,0,0,0,0,0,0,0,0,0
0,0,0,0,0,0,0,0,0,0,0,0,0,0,0,0
0,0,0,0,0,0,0,0,0,0,0,0,0,0,0,0
0,0,0,0,0,0,0,0,0,0,0,0,0,0,0,0
endlayer

