
# Created by Ruins mod version 16.8 Ingame Parser
# authoring Player: ST753M

weight=1
uniqueMinDistance=1500
spawnMinDistance=500
embed_into_distance=6
acceptable_target_blocks=
unacceptable_target_blocks=flowing_water,water,flowing_lava,lava,ice,bedrock,netherrack,nether_brick,nether_brick_fence,soul_sand,quartz_ore,end_stone,obsidian,iron_bars,Natura:Cloud,slime_grass,slime_congealed,slime_dirt,clouds,natura:clouds
dimensions=32,17,17
allowable_overhang=9
max_leveling=2
leveling_buffer=-1
preserve_water=0
preserve_lava=0

biomesToSpawnIn=coralium_infested_swamp,overgrown_cliffs,roofed_forest,mutated_roofed_forest,extreme_hills,smaller_extreme_hills,mutated_extreme_hills,mutated_extreme_hills_with_trees,extreme_hills_with_trees,highland,alps,alps_foothills,mountain,mountain_foothills,crag,cliffs,mutated_savanna,mutated_savanna_rock,brushland,steppe,wasteland,tundra,outback,badlands,red_desert,mesa,mesa_clear_rock,mesa_rock,mutated_mesa,mutated_mesa_clear_rock,mutated_mesa_rock,lush_desert,darklands_plains,ominous_woods,eerie,

=0,100,air
rule1=0,100,preserveBlock
# Tower Wall
rule2=0,100,minecraft:stonebrick-1,minecraft:stonebrick-0,minecraft:stonebrick-2
rule3=0,100,minecraft:ladder-4
# Tower Floors
rule4=0,100,minecraft:stonebrick-1,minecraft:stonebrick-0,minecraft:stonebrick-2
^0,100,minecraft:stone-6
^0,100,minecraft:double_stone_slab-0
rule5=0,100,minecraft:ladder-3
rule6=0,100,minecraft:ladder-2
rule7=0,100,minecraft:ladder-5
# Basement Treasure
rule8=0,100,ChestGenHook:chests/simple_dungeon:2-2
rule9=0,100,MobSpawner:Skeleton,MobSpawner:Zombie
# Tower Molding
rule10=0,100,minecraft:stone_brick_stairs-5
rule11=0,100,minecraft:stone_brick_stairs-7
rule12=0,100,minecraft:stone_brick_stairs-6
rule13=0,100,minecraft:stone_brick_stairs-4
# The Wyrm
rule14=0,100,minecraft:stone_slab2-8
^0,100,minecraft:stone_slab-9
^0,100,minecraft:stone_slab2-8
^0,100,minecraft:stone_slab-14
rule15^0,100,minecraft:red_sandstone-0
^0,100,minecraft:sandstone-0
^0,100,minecraft:red_sandstone-0
^0,100,minecraft:nether_brick-0
rule16^0,100,minecraft:red_sandstone_stairs-7
^0,100,minecraft:sandstone_stairs-7
^0,100,minecraft:red_sandstone_stairs-7
^0,100,minecraft:nether_brick_stairs-7
rule17^0,100,minecraft:red_sandstone_stairs-6
^0,100,minecraft:sandstone_stairs-6
^0,100,minecraft:red_sandstone_stairs-6
^0,100,minecraft:nether_brick_stairs-6
rule18^0,100,minecraft:red_sandstone_stairs-5
^0,100,minecraft:sandstone_stairs-5
^0,100,minecraft:red_sandstone_stairs-5
^0,100,minecraft:nether_brick_stairs-5
rule19^0,100,minecraft:red_sandstone_stairs-4
^0,100,minecraft:sandstone_stairs-4
^0,100,minecraft:red_sandstone_stairs-4
^0,100,minecraft:nether_brick_stairs-4
rule20^0,100,minecraft:red_sandstone_stairs-1
^0,100,minecraft:sandstone_stairs-1
^0,100,minecraft:red_sandstone_stairs-1
^0,100,minecraft:nether_brick_stairs-1
rule21^0,100,minecraft:red_sandstone_stairs-3
^0,100,minecraft:sandstone_stairs-3
^0,100,minecraft:red_sandstone_stairs-3
^0,100,minecraft:nether_brick_stairs-3
rule22^0,100,minecraft:red_sandstone_stairs-2
^0,100,minecraft:sandstone_stairs-2
^0,100,minecraft:red_sandstone_stairs-2
^0,100,minecraft:nether_brick_stairs-2
rule23^0,100,minecraft:red_sandstone_stairs-0
^0,100,minecraft:sandstone_stairs-0
^0,100,minecraft:red_sandstone_stairs-0
^0,100,minecraft:nether_brick_stairs-0
rule24^0,100,minecraft:stone_slab2-0
^0,100,minecraft:stone_slab-1
^0,100,minecraft:stone_slab2-0
^0,100,minecraft:stone_slab-6

# Mouth
rule25=0,100,ChestGenHook:chests/simple_dungeon:5-3
# Eyes
rule26=0,100,minecraft:gold_block-0
^0,100,minecraft:emerald_block-0
^0,100,minecraft:gold_block-0

layer
1,1,1,1,1,1,1,1,1,1,1,1,1,1,1,1,1
1,1,1,1,1,1,1,1,1,1,1,1,1,1,1,1,1
1,1,1,1,1,1,1,1,1,1,1,1,1,1,1,1,1
1,1,1,1,1,1,1,2,2,2,1,1,1,1,1,1,1
1,1,1,1,5,2,2,4,4,4,2,2,3,1,1,1,1
1,1,1,1,2,4,4,4,4,4,4,4,2,1,1,1,1
1,1,1,1,2,4,4,4,4,4,4,4,2,1,1,1,1
1,1,1,2,4,4,4,4,4,4,4,4,4,2,1,1,1
1,1,1,2,4,4,4,4,4,4,4,4,4,2,1,1,1
1,1,1,2,4,4,4,4,4,4,4,4,4,2,1,1,1
1,1,1,1,2,4,4,4,4,4,4,4,2,1,1,1,1
1,1,1,1,2,4,4,4,4,4,4,4,2,1,1,1,1
1,1,1,1,7,2,2,4,4,4,2,2,6,1,1,1,1
1,1,1,1,1,1,1,2,2,2,1,1,1,1,1,1,1
1,1,1,1,1,1,1,1,1,1,1,1,1,1,1,1,1
1,1,1,1,1,1,1,1,1,1,1,1,1,1,1,1,1
1,1,1,1,1,1,1,1,1,1,1,1,1,1,1,1,1
endlayer

layer
1,1,1,1,1,1,1,1,1,1,1,1,1,1,1,1,1
1,1,1,1,1,1,1,1,1,1,1,1,1,1,1,1,1
1,1,1,1,1,1,1,1,1,1,1,1,1,1,1,1,1
1,1,1,1,1,1,1,2,2,2,1,1,1,1,1,1,1
1,1,1,1,1,2,2,0,0,0,2,2,1,1,1,1,1
1,1,1,1,2,0,0,0,0,0,0,0,2,1,1,1,1
1,1,1,1,2,0,0,0,0,0,0,0,2,1,1,1,1
1,1,1,2,8,0,0,0,0,0,0,0,0,2,1,1,1
1,1,1,2,0,0,0,0,2,0,0,0,0,2,1,1,1
1,1,1,2,0,0,0,0,0,0,0,0,5,2,1,1,1
1,1,1,1,2,0,0,0,0,0,0,0,2,1,1,1,1
1,1,1,1,2,0,0,0,0,0,0,0,2,1,1,1,1
1,1,1,1,1,2,2,0,0,0,2,2,1,1,1,1,1
1,1,1,1,1,1,1,2,2,2,1,1,1,1,1,1,1
1,1,1,1,1,1,1,1,1,1,1,1,1,1,1,1,1
1,1,1,1,1,1,1,1,1,1,1,1,1,1,1,1,1
1,1,1,1,1,1,1,1,1,1,1,1,1,1,1,1,1
endlayer

layer
1,1,1,1,1,1,1,1,1,1,1,1,1,1,1,1,1
1,1,1,1,1,1,1,1,1,1,1,1,1,1,1,1,1
1,1,1,1,1,1,1,1,1,1,1,1,1,1,1,1,1
1,1,1,1,1,1,1,2,2,2,1,1,1,1,1,1,1
1,1,1,1,1,2,2,0,0,0,2,2,1,1,1,1,1
1,1,1,1,2,0,0,0,0,0,0,0,2,1,1,1,1
1,1,1,1,2,0,0,0,0,0,0,0,2,1,1,1,1
1,1,1,2,0,0,0,0,0,0,0,0,0,2,1,1,1
1,1,1,2,0,0,0,0,9,0,0,0,0,2,1,1,1
1,1,1,2,0,0,0,0,0,0,0,0,5,2,1,1,1
1,1,1,1,2,0,0,0,0,0,0,0,2,1,1,1,1
1,1,1,1,2,0,0,0,0,0,0,0,2,1,1,1,1
1,1,1,1,1,2,2,0,0,0,2,2,1,1,1,1,1
1,1,1,1,1,1,1,2,2,2,1,1,1,1,1,1,1
1,1,1,1,1,1,1,1,1,1,1,1,1,1,1,1,1
1,1,1,1,1,1,1,1,1,1,1,1,1,1,1,1,1
1,1,1,1,1,1,1,1,1,1,1,1,1,1,1,1,1
endlayer

layer
1,1,1,1,1,1,1,1,1,1,1,1,1,1,1,1,1
1,1,1,1,1,1,1,1,1,1,1,1,1,1,1,1,1
1,1,1,1,1,1,1,1,1,1,1,1,1,1,1,1,1
1,1,1,1,1,1,1,2,2,2,1,1,1,1,1,1,1
1,1,1,1,1,2,2,0,0,0,2,2,1,1,1,1,1
1,1,1,1,2,0,0,0,0,0,0,0,2,1,1,1,1
1,1,1,1,2,0,0,0,0,0,0,0,2,1,1,1,1
1,1,1,2,0,0,0,0,0,0,0,0,0,2,1,1,1
1,1,1,2,0,0,0,0,2,0,0,0,0,2,1,1,1
1,1,1,2,0,0,0,0,0,0,0,0,5,2,1,1,1
1,1,1,1,2,0,0,0,0,0,0,0,2,1,1,1,1
1,1,1,1,2,0,0,0,0,0,0,0,2,1,1,1,1
1,1,1,1,1,2,2,0,0,0,2,2,1,1,1,1,1
1,1,1,1,1,1,1,2,2,2,1,1,1,1,1,1,1
1,1,1,1,1,1,1,1,1,1,1,1,1,1,1,1,1
1,1,1,1,1,1,1,1,1,1,1,1,1,1,1,1,1
1,1,1,1,1,1,1,1,1,1,1,1,1,1,1,1,1
endlayer

layer
1,1,1,1,1,1,1,1,1,1,1,1,1,1,1,1,1
1,1,1,1,1,1,1,1,1,1,1,1,1,1,1,1,1
1,1,1,1,1,1,1,1,1,1,1,1,1,1,1,1,1
1,1,1,1,1,1,1,2,2,2,1,1,1,1,1,1,1
1,1,1,1,1,2,2,10,10,10,2,2,1,1,1,1,1
1,1,1,1,2,10,10,0,0,0,10,11,2,1,1,1,1
1,1,1,1,2,12,0,0,0,0,0,11,2,1,1,1,1
1,1,1,2,12,0,0,13,13,13,0,0,11,2,1,1,1
1,1,1,2,12,0,0,11,2,12,0,0,11,2,1,1,1
1,1,1,2,12,0,0,11,10,10,0,0,5,2,1,1,1
1,1,14,1,2,12,0,0,0,0,0,11,2,1,1,1,1
1,1,14,1,2,12,13,0,0,0,13,13,2,1,1,1,1
1,1,1,14,1,2,2,13,13,13,2,2,1,1,1,1,1
1,1,1,1,16,15,15,2,2,2,1,1,1,1,1,1,1
1,1,1,1,16,15,15,15,15,17,1,1,1,1,1,1,1
1,1,1,1,1,18,16,15,15,17,1,1,1,1,1,1,1
1,1,1,1,1,1,1,1,1,1,1,1,1,1,1,1,1
endlayer

layer
1,1,1,1,1,1,1,1,1,1,1,1,1,1,1,1,1
1,1,1,1,1,1,1,1,1,1,1,1,1,1,1,1,1
1,1,1,1,1,1,1,1,1,1,1,1,1,1,1,1,1
1,1,1,1,1,1,2,2,2,2,2,1,1,1,1,1,1
1,1,1,1,1,2,2,4,4,4,2,2,1,1,1,1,1
1,1,1,1,2,4,4,4,4,4,4,4,2,1,1,1,1
1,1,1,1,2,4,4,4,4,4,4,4,2,1,1,1,1
1,1,1,2,4,4,4,4,4,4,4,4,4,2,1,1,1
1,14,1,2,4,4,4,4,4,4,4,4,4,2,1,1,1
1,19,19,2,4,4,4,4,4,4,4,4,5,2,1,1,1
1,16,15,15,2,4,4,4,4,4,4,4,2,1,1,1,1
1,16,15,15,2,4,4,4,4,4,4,4,2,1,1,1,1
1,1,18,15,15,2,2,4,4,4,2,2,1,1,1,1,1
1,1,1,16,15,15,15,2,2,2,1,1,1,1,1,1,1
1,1,1,1,15,15,15,15,15,15,17,1,1,1,1,1,1
1,1,1,1,1,15,15,15,15,15,1,1,1,1,1,1,1
1,1,1,1,1,1,1,18,18,18,1,1,1,1,1,1,1
endlayer

layer
1,1,1,1,1,1,1,1,1,1,1,1,1,1,1,1,1
1,1,1,1,1,1,1,1,1,1,1,1,1,1,1,1,1
1,1,1,1,1,1,1,1,1,1,1,1,1,1,1,1,1
1,1,1,1,1,1,2,0,0,0,2,1,1,1,1,1,1
1,1,1,1,1,2,2,0,0,0,2,2,1,1,1,1,1
1,1,1,1,2,0,0,0,0,0,0,0,2,1,1,1,1
1,1,1,1,2,0,0,0,0,0,0,0,2,1,1,1,1
1,19,19,2,6,0,0,0,0,0,0,0,0,2,1,1,1
1,15,15,2,0,0,0,0,2,0,0,0,0,2,1,1,1
16,15,15,2,0,0,0,0,0,0,0,0,0,2,1,1,1
1,15,15,15,2,0,0,0,0,0,0,0,2,1,1,1,1
1,15,15,15,2,0,0,0,0,0,0,0,2,1,1,1,1
1,1,15,15,15,2,2,0,0,0,2,2,1,1,1,1,1
1,1,1,15,15,15,15,2,2,2,15,15,17,1,1,1,1
1,1,1,1,20,15,15,15,15,15,15,15,1,1,1,1,1
1,1,1,1,1,20,21,15,15,15,18,18,1,1,1,1,1
1,1,1,1,1,1,1,15,15,15,1,1,1,1,1,1,1
endlayer

layer
1,1,1,1,1,1,1,1,1,1,1,1,1,1,1,1,1
1,1,1,1,1,1,1,1,1,1,1,1,1,1,1,1,1
1,1,1,1,1,1,1,1,1,1,1,1,1,1,1,1,1
1,1,1,1,1,1,2,0,0,0,2,1,1,1,1,1,1
1,1,1,1,1,2,2,0,0,0,2,2,1,1,1,1,1
1,1,1,1,2,0,0,0,0,0,0,0,2,1,1,1,1
1,1,19,1,2,0,0,0,0,0,0,0,2,1,1,1,1
16,15,15,2,6,0,0,0,0,0,0,0,0,2,1,1,1
19,15,15,2,0,0,0,0,2,0,0,0,0,2,1,1,1
15,15,15,2,0,0,0,0,0,0,0,0,0,2,1,1,1
1,15,15,15,2,0,0,0,0,0,0,0,2,1,1,1,1
1,20,15,15,2,0,0,0,0,0,0,0,2,1,14,1,1
1,1,21,15,15,2,2,0,0,0,2,2,15,19,1,1,1
1,1,1,21,15,22,0,2,2,2,15,15,15,15,1,1,1
1,1,1,1,0,0,24,23,15,15,15,15,18,18,1,1,1
1,1,1,1,1,0,0,21,15,15,15,15,1,1,1,1,1
1,1,1,1,1,1,1,20,20,20,1,1,1,1,1,1,1
endlayer

layer
1,1,1,1,1,1,1,1,1,1,1,1,1,1,1,1,1
1,1,1,1,1,1,1,1,1,1,1,1,1,1,1,1,1
1,1,1,1,1,1,1,1,1,1,1,1,1,1,1,1,1
1,1,1,1,1,1,2,0,0,0,2,1,1,1,1,1,1
1,1,1,1,1,2,2,0,0,0,2,2,1,1,1,1,1
1,1,1,1,2,0,0,0,0,0,0,0,2,1,1,1,1
1,19,15,15,2,0,0,0,0,0,0,0,2,1,1,1,1
15,15,15,2,6,0,0,0,0,0,0,0,0,2,1,1,1
15,15,15,2,0,0,0,0,2,0,0,0,0,2,1,1,1
21,15,15,2,0,0,0,0,0,0,0,0,0,2,19,17,1
1,20,15,15,2,0,0,0,0,0,0,0,2,15,15,17,1
1,0,20,20,2,0,0,0,0,0,0,0,2,15,15,1,1
1,1,0,24,0,2,2,0,0,0,2,2,15,15,18,1,1
1,1,1,0,0,0,0,2,2,2,15,15,15,15,1,1,1
1,1,1,1,0,0,0,0,0,0,21,15,15,15,1,1,1
1,1,1,1,1,0,0,0,0,24,21,20,1,1,1,1,1
1,1,1,1,1,1,1,0,0,0,1,1,1,1,1,1,1
endlayer

layer
1,1,1,1,1,1,1,1,1,1,1,1,1,1,1,1,1
1,1,1,1,1,1,1,1,1,1,1,1,1,1,1,1,1
1,1,1,1,1,1,1,1,1,1,1,1,1,1,1,1,1
1,1,1,1,1,1,2,2,2,2,2,1,1,1,1,1,1
1,1,1,1,1,2,2,10,10,10,2,2,1,1,1,1,1
1,1,19,1,2,10,10,0,0,0,10,11,2,1,1,1,1
1,15,15,15,2,12,0,0,0,0,0,11,2,1,14,1,1
23,15,15,2,6,0,0,13,13,12,0,0,11,2,19,19,1
21,15,15,2,12,0,0,11,2,12,0,0,11,2,15,15,1
0,20,20,2,12,0,0,10,10,10,0,0,11,2,15,15,1
1,0,24,0,2,12,0,0,0,0,0,11,2,15,15,15,1
1,0,0,0,2,12,13,0,0,0,13,13,2,15,15,1,1
1,1,0,0,0,2,2,13,13,13,2,2,15,15,15,1,1
1,1,1,0,0,0,0,2,2,2,0,21,15,15,1,1,1
1,1,1,1,0,0,0,0,0,0,0,21,20,22,1,1,1
1,1,1,1,1,0,0,0,0,0,0,0,1,1,1,1,1
1,1,1,1,1,1,1,0,0,0,1,1,1,1,1,1,1
endlayer

layer
1,1,1,1,1,1,1,1,1,1,1,1,1,1,1,1,1
1,1,1,1,1,1,1,1,1,1,1,1,1,1,1,1,1
1,1,1,1,1,1,1,1,1,1,1,1,1,1,1,1,1
1,1,1,1,1,1,0,2,2,2,0,1,1,1,1,1,1
1,1,19,1,1,2,2,4,4,4,2,2,15,17,1,1,1
1,1,15,1,2,4,4,4,4,4,4,4,2,15,15,17,1
1,24,15,15,2,4,4,4,4,4,4,4,2,15,15,17,1
0,0,20,2,6,4,4,4,4,4,4,4,4,2,15,15,17
0,0,24,2,4,4,4,4,4,4,4,4,4,2,15,15,18
0,0,0,2,4,4,4,4,4,4,4,4,4,2,15,15,1
1,0,0,0,2,4,4,4,4,4,4,4,2,15,15,22,1
1,0,0,0,2,4,4,4,4,4,4,4,2,15,15,1,1
1,1,0,0,0,2,2,4,4,4,2,2,0,20,20,1,1
1,1,1,0,0,0,0,2,2,2,0,0,24,0,1,1,1
1,1,1,1,0,0,0,0,0,0,0,0,0,0,1,1,1
1,1,1,1,1,0,0,0,0,0,0,0,1,1,1,1,1
1,1,1,1,1,1,1,0,0,0,1,1,1,1,1,1,1
endlayer

layer
1,1,1,1,1,1,1,1,1,1,1,1,1,1,1,1,1
1,1,1,1,1,1,1,1,1,1,1,1,1,1,1,1,1
1,1,1,1,1,1,1,1,1,1,14,1,1,1,1,1,1
1,1,24,1,1,1,0,2,2,2,0,16,15,15,1,1,1
1,1,15,1,1,2,2,0,0,0,2,2,15,15,17,1,1
1,1,20,1,2,0,0,0,0,0,0,0,2,15,15,15,1
1,0,0,0,2,0,0,0,0,0,0,0,2,15,15,15,1
0,0,0,2,0,0,0,0,0,0,0,0,0,2,15,15,15
0,0,0,2,0,0,0,0,2,0,0,0,0,2,15,15,15
0,0,0,2,0,0,0,0,0,0,0,0,0,2,15,15,1
1,0,0,0,2,0,0,0,0,0,0,0,2,0,20,0,1
1,0,0,0,2,0,0,0,0,0,0,0,2,0,0,1,1
1,1,0,0,0,2,2,0,0,3,2,2,0,0,0,1,1
1,1,1,0,0,0,0,2,2,2,0,0,0,0,1,1,1
1,1,1,1,0,0,0,0,0,0,0,0,0,0,1,1,1
1,1,1,1,1,0,0,0,0,0,0,0,1,1,1,1,1
1,1,1,1,1,1,1,0,0,0,1,1,1,1,1,1,1
endlayer

layer
1,1,1,1,1,1,1,1,1,1,1,1,1,1,1,1,1
1,1,1,1,1,1,1,1,14,16,19,1,1,1,1,1,1
1,1,1,1,1,1,1,1,1,16,15,15,17,1,1,1,1
1,1,0,1,1,1,0,2,2,2,15,15,15,15,1,1,1
1,1,0,1,1,2,2,0,0,0,2,2,15,15,15,1,1
1,1,0,1,2,0,0,0,0,0,0,0,2,15,15,23,1
1,0,0,0,2,0,0,0,0,0,0,0,2,15,15,22,1
0,14,0,2,0,0,0,0,0,0,0,0,0,2,15,15,22
0,14,0,2,0,0,0,0,9,0,0,0,0,2,15,15,22
0,14,0,2,0,0,0,0,0,0,0,0,0,2,20,20,1
1,0,14,0,2,0,0,0,0,0,0,0,2,0,0,0,1
1,0,14,0,2,0,0,0,0,0,0,0,2,0,0,1,1
1,1,0,0,0,2,2,0,0,3,2,2,0,0,0,1,1
1,1,1,0,0,0,0,2,2,2,0,0,0,0,1,1,1
1,1,1,1,0,0,0,0,0,0,0,0,0,0,1,1,1
1,1,1,1,1,0,0,0,0,0,0,0,1,1,1,1,1
1,1,1,1,1,1,1,0,0,0,1,1,1,1,1,1,1
endlayer

layer
1,1,1,1,1,1,1,19,19,19,1,1,1,1,1,1,1
1,1,1,1,1,1,1,15,15,15,15,1,1,1,1,1,1
1,1,1,1,1,14,16,15,15,15,15,15,15,1,1,1,1
1,1,0,1,1,1,18,2,2,2,15,15,15,15,1,1,1
1,1,0,1,1,2,2,0,0,0,2,2,15,15,22,1,1
1,1,0,1,2,0,0,0,0,0,0,0,2,20,20,0,1
1,19,19,0,2,0,0,0,0,0,0,0,2,0,24,0,1
16,15,15,2,0,0,0,0,0,0,0,0,0,2,0,24,0
16,15,15,2,0,0,0,0,2,0,0,0,0,2,0,0,0
16,15,15,2,0,0,0,0,0,0,0,0,0,2,0,0,1
1,16,15,15,2,0,0,0,0,0,0,0,2,0,0,0,1
1,16,15,15,2,0,0,0,0,0,0,0,2,0,0,1,1
1,1,16,15,15,2,2,0,0,3,2,2,0,0,0,1,1
1,1,16,15,18,0,0,2,2,2,0,0,0,0,1,1,1
1,1,1,1,0,14,0,0,0,0,0,0,0,0,1,1,1
1,1,1,1,1,0,0,0,0,0,0,0,1,1,1,1,1
1,1,1,1,1,1,1,0,0,0,1,1,1,1,1,1,1
endlayer

layer
1,1,1,1,1,1,1,15,15,15,1,1,1,1,1,1,1
1,1,1,1,1,19,19,15,15,15,15,1,1,1,1,1,1
1,1,1,1,1,15,15,15,15,15,15,15,22,1,1,1,1
1,1,0,1,16,15,15,2,2,2,15,15,22,0,1,1,1
1,1,0,19,1,2,2,10,10,10,2,2,0,24,0,1,1
1,1,15,15,2,10,10,0,0,0,10,11,2,0,0,0,1
1,15,15,15,2,12,0,0,0,0,0,11,2,0,0,0,1
15,15,15,2,12,0,0,11,13,12,0,0,11,2,0,0,0
15,15,15,2,12,0,0,11,2,12,0,0,11,2,0,0,0
15,15,15,2,12,0,0,11,10,10,0,0,11,2,0,0,1
1,15,15,15,2,12,0,0,0,0,0,11,2,0,0,0,1
1,15,15,15,2,12,13,0,0,0,13,13,2,0,0,1,1
1,1,15,15,15,2,2,13,13,3,2,2,0,0,0,1,1
1,1,15,15,15,15,15,2,2,2,0,0,0,0,1,1,1
1,1,1,18,18,15,15,17,0,0,0,0,0,0,1,1,1
1,1,1,1,1,18,18,14,0,0,0,0,1,1,1,1,1
1,1,1,1,1,1,1,0,0,0,1,1,1,1,1,1,1
endlayer

layer
1,1,1,1,1,1,1,21,23,22,1,1,1,1,1,1,1
1,1,1,1,1,15,15,15,15,15,22,1,1,1,1,1,1
1,1,1,19,19,15,15,15,15,15,22,24,0,1,1,1,1
1,1,0,15,15,15,15,2,2,2,0,0,0,0,1,1,1
1,1,19,15,15,2,2,4,4,4,2,2,0,0,0,1,1
1,1,15,15,2,4,4,4,4,4,4,4,2,0,0,0,1
1,15,15,15,2,4,4,4,4,4,4,4,2,0,0,0,1
21,15,15,2,4,4,4,4,4,4,4,4,4,2,0,0,0
21,15,15,2,4,4,4,4,4,4,4,4,4,2,0,0,0
21,15,15,2,4,4,4,4,4,4,4,4,4,2,0,0,1
1,20,15,15,2,4,4,4,4,4,4,4,2,0,0,0,1
1,0,15,15,2,4,4,4,4,4,4,4,2,0,0,1,1
1,1,21,15,15,2,2,4,4,3,2,2,0,0,0,1,1
1,1,21,15,15,15,15,2,2,2,0,0,0,0,1,1,1
1,1,1,15,15,15,15,15,15,17,0,0,0,0,1,1,1
1,1,1,1,1,15,15,15,15,17,0,0,1,1,1,1,1
1,1,1,1,1,1,1,18,18,0,1,1,1,1,1,1,1
endlayer

layer
1,1,1,1,1,1,1,0,0,0,1,1,1,1,1,1,1
1,1,1,1,1,23,23,23,24,0,0,1,1,1,1,1,1
1,1,1,15,15,15,15,22,0,0,0,0,0,1,1,1,1
1,1,0,15,15,15,15,2,2,2,0,0,0,0,1,1,1
1,1,15,15,15,2,2,7,0,0,2,2,0,0,0,1,1
1,1,15,15,2,0,0,0,0,0,0,0,2,0,0,0,1
1,21,15,15,2,0,0,0,0,0,0,0,2,0,0,0,1
0,20,20,2,0,0,0,0,0,0,0,0,0,2,0,0,0
0,24,0,2,0,0,0,0,2,0,0,0,0,2,0,0,0
0,0,0,2,0,0,0,0,0,0,0,0,0,2,0,0,1
1,0,0,0,2,0,0,0,0,0,0,0,2,0,0,0,1
1,0,0,24,2,0,0,0,0,0,0,0,2,0,0,1,1
1,1,0,21,15,2,2,0,0,0,2,2,0,0,0,1,1
1,1,0,21,15,15,15,2,2,2,0,14,0,0,1,1,1
1,1,1,0,21,15,15,15,15,15,17,0,0,0,1,1,1
1,1,1,1,1,20,20,15,15,15,0,0,1,1,1,1,1
1,1,1,1,1,1,1,15,15,18,1,1,1,1,1,1,1
endlayer

layer
1,1,1,1,1,1,1,0,0,0,1,1,1,1,1,1,1
1,1,1,1,1,0,0,0,0,0,0,1,1,1,1,1,1
1,1,1,23,23,22,0,0,0,0,0,0,0,1,1,1,1
1,1,0,15,15,22,0,2,2,2,0,0,0,0,1,1,1
1,1,21,15,15,2,2,7,0,0,2,2,0,0,0,1,1
1,1,20,20,2,0,0,0,0,0,0,0,2,0,0,0,1
1,0,0,0,2,0,0,0,0,0,0,0,2,0,0,0,1
0,0,0,2,0,0,0,0,0,0,0,0,0,2,0,0,0
0,0,0,2,0,0,0,0,9,0,0,0,0,2,0,0,0
0,0,0,2,0,0,0,0,0,0,0,0,0,2,0,0,1
1,0,0,0,2,0,0,0,0,0,0,0,2,0,0,0,1
1,0,0,0,2,0,0,0,0,0,0,0,2,0,0,1,1
1,1,0,0,0,2,2,0,0,0,2,2,0,0,0,1,1
1,1,0,0,0,24,0,2,2,2,15,15,17,0,1,1,1
1,1,1,0,0,0,21,15,15,15,15,15,0,0,1,1,1
1,1,1,1,1,0,0,15,15,15,17,18,1,1,1,1,1
1,1,1,1,1,1,1,20,15,15,1,1,1,1,1,1,1
endlayer

layer
1,1,1,1,1,1,1,0,0,0,1,1,1,1,1,1,1
1,1,1,1,1,0,0,0,0,0,0,1,1,1,1,1,1
1,1,1,0,0,0,0,0,0,0,0,0,0,1,1,1,1
1,1,0,0,24,0,0,2,2,2,0,0,0,0,1,1,1
1,1,0,24,0,2,2,7,0,0,2,2,0,0,0,1,1
1,1,0,0,2,0,0,0,0,0,0,0,2,0,0,0,1
1,0,0,0,2,0,0,0,0,0,0,0,2,0,0,0,1
0,0,0,2,0,0,0,0,0,0,0,0,0,2,0,0,0
0,0,0,2,0,0,0,0,2,0,0,0,0,2,0,0,0
0,0,0,2,0,0,0,0,0,0,0,0,0,2,0,0,1
1,0,0,0,2,0,0,0,0,0,0,0,2,0,0,0,1
1,0,0,0,2,0,0,0,0,0,0,0,2,0,0,1,1
1,1,0,0,0,2,2,0,0,0,2,2,15,17,0,1,1
1,1,0,0,0,0,0,2,2,2,15,15,15,17,1,1,1
1,1,1,0,0,0,0,21,15,15,15,15,17,0,1,1,1
1,1,1,1,1,0,0,21,15,15,15,15,1,1,1,1,1
1,1,1,1,1,1,1,0,20,20,1,1,1,1,1,1,1
endlayer

layer
1,1,1,1,1,1,1,0,0,0,1,1,1,1,1,1,1
1,1,1,1,1,0,0,0,0,0,0,1,1,1,1,1,1
1,1,1,0,0,0,0,0,0,0,0,0,0,1,1,1,1
1,1,0,0,0,0,0,2,2,2,0,0,0,0,1,1,1
1,1,0,0,0,2,2,7,10,10,2,2,0,0,0,1,1
1,1,0,0,2,10,10,0,0,0,10,11,2,0,0,0,1
1,0,0,0,2,12,0,0,0,0,0,11,2,0,0,0,1
0,0,0,2,12,0,0,13,13,12,0,0,11,2,0,0,0
0,0,0,2,12,0,0,11,2,12,0,0,11,2,0,0,0
0,0,0,2,12,0,0,10,10,10,0,0,11,2,0,0,1
1,0,0,0,2,12,0,0,0,0,0,11,2,0,0,0,1
1,0,0,0,2,12,13,0,0,0,13,13,2,19,17,1,1
1,1,0,0,0,2,2,13,13,13,2,2,15,15,0,1,1
1,1,0,0,0,0,0,2,2,2,15,15,15,15,1,1,1
1,1,1,0,0,0,0,0,0,21,15,15,15,0,1,1,1
1,1,1,1,1,0,0,0,24,20,20,20,1,1,1,1,1
1,1,1,1,1,1,1,0,0,0,1,1,1,1,1,1,1
endlayer

layer
1,1,1,1,1,1,1,0,0,0,1,1,1,1,1,1,1
1,1,1,1,1,0,0,0,0,0,0,1,1,1,1,1,1
1,1,1,0,0,0,0,0,0,0,0,0,0,1,1,1,1
1,1,0,0,0,0,0,2,2,2,0,0,0,0,1,1,1
1,1,0,0,0,2,2,7,4,4,2,2,0,0,0,1,1
1,1,0,0,2,4,4,4,4,4,4,4,2,0,0,0,1
1,0,0,0,2,4,4,4,4,4,4,4,2,0,0,0,1
0,0,0,2,4,4,4,4,4,4,4,4,4,2,0,0,0
0,0,0,2,4,4,4,4,4,4,4,4,4,2,0,0,0
0,0,0,2,4,4,4,4,4,4,4,4,4,2,0,0,1
1,0,0,0,2,4,4,4,4,4,4,4,2,0,0,0,1
1,0,0,0,2,4,4,4,4,4,4,4,2,15,15,1,1
1,1,0,0,0,2,2,4,4,4,2,2,15,15,18,1,1
1,1,0,0,0,0,0,2,2,2,21,15,15,15,1,1,1
1,1,1,0,0,0,0,0,0,0,21,20,15,0,1,1,1
1,1,1,1,1,0,0,0,0,0,0,0,1,1,1,1,1
1,1,1,1,1,1,1,0,0,0,1,1,1,1,1,1,1
endlayer

layer
1,1,1,1,1,1,1,0,0,0,1,1,1,1,1,1,1
1,1,1,1,1,0,0,0,0,0,0,1,1,1,1,1,1
1,1,1,0,0,0,0,13,0,13,0,0,0,1,1,1,1
1,1,0,0,0,13,0,2,2,2,0,13,0,0,1,1,1
1,1,0,0,0,2,2,0,0,0,2,2,0,0,0,1,1
1,1,0,11,2,0,0,0,0,0,0,0,2,12,0,0,1
1,0,0,0,2,0,0,0,0,0,0,0,2,0,0,0,1
0,0,11,2,0,0,0,0,0,0,0,0,0,2,12,0,0
0,0,0,2,0,0,0,0,0,0,0,0,0,2,0,0,0
0,0,11,2,0,0,0,0,0,0,0,0,0,2,12,0,1
1,0,0,0,2,0,0,0,0,0,0,0,2,0,0,0,1
1,0,0,11,2,0,0,0,0,0,0,0,2,15,15,1,1
1,1,0,0,0,2,2,0,0,0,2,2,15,15,15,1,1
1,1,0,0,0,10,0,2,2,2,0,10,15,15,1,1,1
1,1,1,0,0,0,0,10,0,10,0,0,20,0,1,1,1
1,1,1,1,1,0,0,0,0,0,0,0,1,1,1,1,1
1,1,1,1,1,1,1,0,0,0,1,1,1,1,1,1,1
endlayer

layer
1,1,1,1,1,1,1,0,0,0,1,1,1,1,1,1,1
1,1,1,1,1,0,0,0,0,0,0,1,1,1,1,1,1
1,1,1,0,0,0,0,2,0,2,0,0,0,1,1,1,1
1,1,0,0,0,2,0,0,0,0,0,2,0,0,1,1,1
1,1,0,0,0,0,0,0,0,0,0,0,0,0,0,1,1
1,1,0,2,0,0,0,0,0,0,0,0,0,2,0,0,1
1,0,0,0,0,0,0,0,0,0,0,0,0,0,0,0,1
0,0,2,0,0,0,0,0,0,0,0,0,0,0,2,0,0
0,0,0,0,0,0,0,0,0,0,0,0,0,0,0,0,0
0,0,2,0,0,0,0,0,0,0,0,0,0,0,2,0,1
1,0,0,0,0,0,0,0,0,0,0,0,0,0,0,0,1
1,0,0,2,0,0,0,0,0,0,0,0,15,15,15,1,1
1,1,0,0,0,0,0,0,0,0,0,0,15,15,15,1,1
1,1,0,0,0,2,0,0,0,0,0,2,15,15,1,1,1
1,1,1,0,0,0,0,2,0,2,0,0,0,0,1,1,1
1,1,1,1,1,0,0,0,0,0,0,0,1,1,1,1,1
1,1,1,1,1,1,1,0,0,0,1,1,1,1,1,1,1
endlayer

layer
1,1,1,1,1,1,1,0,0,0,1,1,1,1,1,1,1
1,1,1,1,1,0,0,0,0,0,0,1,1,1,1,1,1
1,1,1,0,0,0,0,0,0,0,0,0,0,1,1,1,1
1,1,0,0,0,0,0,0,0,0,0,0,0,0,1,1,1
1,1,0,0,0,0,0,0,0,0,0,0,0,0,0,1,1
1,1,0,0,0,0,0,0,0,0,0,0,0,0,0,0,1
1,0,0,0,0,0,0,0,0,19,19,0,0,0,0,0,1
0,0,0,0,0,0,0,0,16,15,15,19,0,0,0,0,0
0,0,0,0,0,0,0,0,16,15,15,15,17,0,0,0,0
0,0,0,0,0,0,0,0,0,18,15,15,0,0,0,0,1
1,0,0,0,0,0,0,0,0,0,18,0,0,15,0,0,1
1,0,0,0,0,0,0,0,0,0,0,0,15,15,15,1,1
1,1,0,0,0,0,0,0,0,0,0,0,15,15,15,1,1
1,1,0,0,0,0,0,0,0,0,0,0,20,15,1,1,1
1,1,1,0,0,0,0,0,0,0,0,0,0,0,1,1,1
1,1,1,1,1,0,0,0,0,0,0,0,1,1,1,1,1
1,1,1,1,1,1,1,0,0,0,1,1,1,1,1,1,1
endlayer

layer
1,1,1,1,1,1,1,0,0,0,1,1,1,1,1,1,1
1,1,1,1,1,0,0,0,0,0,0,1,1,1,1,1,1
1,1,1,0,0,0,0,0,0,0,0,0,0,1,1,1,1
1,1,0,0,0,0,0,0,0,0,0,0,0,0,1,1,1
1,1,0,0,0,0,0,0,0,0,0,0,0,0,0,1,1
1,1,0,0,0,0,0,0,0,0,0,0,0,0,0,0,1
1,0,0,0,0,0,0,0,0,0,21,0,0,0,0,0,1
0,0,0,0,0,0,0,0,0,0,0,0,0,0,0,0,0
0,0,0,0,0,0,0,0,23,0,0,0,15,0,0,0,0
0,0,0,0,0,0,0,0,0,0,0,0,15,17,0,0,1
1,0,0,0,0,0,0,0,0,0,15,15,15,15,0,0,1
1,0,0,0,0,0,0,0,0,0,0,16,15,15,15,1,1
1,1,0,0,0,0,0,0,0,0,0,0,15,15,15,1,1
1,1,0,0,0,0,0,0,0,0,0,0,0,20,1,1,1
1,1,1,0,0,0,0,0,0,0,0,0,0,0,1,1,1
1,1,1,1,1,0,0,0,0,0,0,0,1,1,1,1,1
1,1,1,1,1,1,1,0,0,0,1,1,1,1,1,1,1
endlayer

layer
1,1,1,1,1,1,1,0,0,0,1,1,1,1,1,1,1
1,1,1,1,1,0,0,0,0,0,0,1,1,1,1,1,1
1,1,1,0,0,0,0,0,0,0,0,0,0,1,1,1,1
1,1,0,0,0,0,0,0,0,0,0,0,0,0,1,1,1
1,1,0,0,0,0,0,0,0,0,0,0,0,0,0,1,1
1,1,0,0,0,0,0,0,0,19,0,0,0,0,0,0,1
1,0,0,0,0,0,0,0,0,0,0,0,0,0,0,0,1
0,0,0,0,0,0,0,16,0,0,0,0,0,0,0,0,0
0,0,0,0,0,0,0,0,0,0,0,0,0,19,0,0,0
0,0,0,0,0,0,0,0,0,0,0,0,0,15,0,0,1
1,0,0,0,0,0,0,0,0,0,0,0,25,15,0,0,1
1,0,0,0,0,0,0,0,0,0,16,15,15,15,22,1,1
1,1,0,0,0,0,0,0,0,0,0,0,15,15,15,1,1
1,1,0,0,0,0,0,0,0,0,0,0,0,0,1,1,1
1,1,1,0,0,0,0,0,0,0,0,0,0,0,1,1,1
1,1,1,1,1,0,0,0,0,0,0,0,1,1,1,1,1
1,1,1,1,1,1,1,0,0,0,1,1,1,1,1,1,1
endlayer

layer
1,1,1,1,1,1,1,0,0,0,1,1,1,1,1,1,1
1,1,1,1,1,0,0,0,0,0,0,1,1,1,1,1,1
1,1,1,0,0,0,0,0,0,0,0,0,0,1,1,1,1
1,1,0,0,0,0,0,0,0,0,0,0,0,0,1,1,1
1,1,0,0,0,0,0,0,0,0,0,0,0,0,0,1,1
1,1,0,0,0,0,0,0,17,15,0,0,0,0,0,0,1
1,0,0,0,0,0,0,18,0,0,17,17,0,0,0,0,1
0,0,0,0,0,0,0,15,0,0,0,0,18,0,0,0,0
0,0,0,0,0,0,0,0,18,0,0,0,0,15,0,0,0
0,0,0,0,0,0,0,0,18,0,0,0,0,15,0,0,1
1,0,0,0,0,0,0,0,0,19,0,0,0,15,0,0,1
1,0,0,0,0,0,0,0,0,0,15,15,15,15,0,1,1
1,1,0,0,0,0,0,0,0,0,0,0,20,15,22,1,1
1,1,0,0,0,0,0,0,0,0,0,0,0,0,1,1,1
1,1,1,0,0,0,0,0,0,0,0,0,0,0,1,1,1
1,1,1,1,1,0,0,0,0,0,0,0,1,1,1,1,1
1,1,1,1,1,1,1,0,0,0,1,1,1,1,1,1,1
endlayer

layer
1,1,1,1,1,1,1,0,0,0,1,1,1,1,1,1,1
1,1,1,1,1,0,0,0,0,0,0,1,1,1,1,1,1
1,1,1,0,0,0,0,0,0,0,0,0,0,1,1,1,1
1,1,0,0,0,0,0,0,0,0,0,0,0,0,1,1,1
1,1,0,0,0,0,0,0,0,0,0,0,0,0,0,1,1
1,1,0,0,0,0,0,0,15,15,0,0,0,0,0,0,1
1,0,0,0,0,0,0,15,15,0,15,15,0,0,0,0,1
0,0,0,0,0,0,0,15,0,0,0,0,15,0,0,0,0
0,0,0,0,0,0,0,0,15,0,0,0,16,22,0,0,0
0,0,0,0,0,0,0,0,15,0,0,0,16,15,0,0,1
1,0,0,0,0,0,0,0,0,15,19,19,19,15,0,0,1
1,0,0,0,0,0,0,0,0,0,20,15,15,15,0,1,1
1,1,0,0,0,0,0,0,0,0,0,0,0,20,0,1,1
1,1,0,0,0,0,0,0,0,0,0,0,0,0,1,1,1
1,1,1,0,0,0,0,0,0,0,0,0,0,0,1,1,1
1,1,1,1,1,0,0,0,0,0,0,0,1,1,1,1,1
1,1,1,1,1,1,1,0,0,0,1,1,1,1,1,1,1
endlayer

layer
1,1,1,1,1,1,1,0,0,0,1,1,1,1,1,1,1
1,1,1,1,1,0,0,0,0,0,0,1,1,1,1,1,1
1,1,1,0,0,0,0,0,0,0,0,0,0,1,1,1,1
1,1,0,0,0,0,0,0,0,0,0,0,0,0,1,1,1
1,1,0,0,0,0,0,0,0,0,0,0,0,0,0,1,1
1,1,0,0,0,0,0,0,23,15,0,0,0,0,0,0,1
1,0,0,0,0,0,0,21,15,15,23,0,0,0,0,0,1
0,0,0,0,0,0,0,15,15,15,15,26,22,0,0,0,0
0,0,0,0,0,0,0,0,21,15,15,15,15,0,0,0,0
0,0,0,0,0,0,0,0,0,26,15,15,15,15,0,0,1
1,0,0,0,0,0,0,0,0,20,15,15,15,15,0,0,1
1,0,0,0,0,0,0,0,0,0,0,15,15,24,0,1,1
1,1,0,0,0,0,0,0,0,0,0,0,0,0,0,1,1
1,1,0,0,0,0,0,0,0,0,0,0,0,0,1,1,1
1,1,1,0,0,0,0,0,0,0,0,0,0,0,1,1,1
1,1,1,1,1,0,0,0,0,0,0,0,1,1,1,1,1
1,1,1,1,1,1,1,0,0,0,1,1,1,1,1,1,1
endlayer

layer
1,1,1,1,1,1,1,0,0,0,1,1,1,1,1,1,1
1,1,1,1,1,0,0,0,0,0,0,1,1,1,1,1,1
1,1,1,0,0,0,0,0,0,0,0,0,0,1,1,1,1
1,1,0,0,0,0,0,0,0,0,0,0,0,0,1,1,1
1,1,0,0,0,0,0,0,0,0,0,0,0,0,0,1,1
1,1,0,0,0,0,0,0,0,22,0,0,0,0,0,0,1
1,0,0,0,0,0,0,0,0,0,0,0,0,0,0,0,1
0,0,0,0,0,0,0,20,0,0,23,23,22,0,0,0,0
0,0,0,0,0,0,0,0,0,21,15,15,15,0,0,0,0
0,0,0,0,0,0,0,0,0,21,15,15,15,15,0,0,1
1,0,0,0,0,0,0,0,0,20,15,15,15,15,15,14,1
1,0,0,0,0,0,0,0,0,0,0,15,15,0,0,1,1
1,1,0,0,0,0,0,0,0,0,0,0,15,0,0,1,1
1,1,0,0,0,0,0,0,0,0,0,0,14,0,1,1,1
1,1,1,0,0,0,0,0,0,0,0,0,0,0,1,1,1
1,1,1,1,1,0,0,0,0,0,0,0,1,1,1,1,1
1,1,1,1,1,1,1,0,0,0,1,1,1,1,1,1,1
endlayer

layer
1,1,1,1,1,1,1,0,0,0,1,1,1,1,1,1,1
1,1,1,1,1,0,0,0,0,0,0,1,1,1,1,1,1
1,1,1,0,0,0,0,0,0,0,0,0,0,1,1,1,1
1,1,0,0,0,0,0,0,0,0,0,0,0,0,1,1,1
1,1,0,0,0,0,0,0,0,0,0,0,0,0,0,1,1
1,1,0,0,0,0,0,0,0,0,0,0,0,0,0,0,1
1,0,0,0,0,0,0,0,0,0,0,0,0,0,0,0,1
0,0,0,0,0,0,0,0,0,0,0,24,24,24,0,0,0
0,0,0,0,0,0,0,0,0,0,0,0,0,0,0,0,0
0,0,0,0,0,0,0,0,0,24,0,0,0,0,0,0,1
1,0,0,0,0,0,0,0,0,24,0,0,0,21,15,15,1
1,0,0,0,0,0,0,0,0,24,0,0,23,0,0,15,17
1,1,0,0,0,0,0,0,0,0,0,0,15,0,0,1,1
1,1,0,0,0,0,0,0,0,0,0,0,15,15,1,1,1
1,1,1,0,0,0,0,0,0,0,0,0,0,18,1,1,1
1,1,1,1,1,0,0,0,0,0,0,0,1,1,1,1,1
1,1,1,1,1,1,1,0,0,0,1,1,1,1,1,1,1
endlayer

layer
1,1,1,1,1,1,1,0,0,0,1,1,1,1,1,1,1
1,1,1,1,1,0,0,0,0,0,0,1,1,1,1,1,1
1,1,1,0,0,0,0,0,0,0,0,0,0,1,1,1,1
1,1,0,0,0,0,0,0,0,0,0,0,0,0,1,1,1
1,1,0,0,0,0,0,0,0,0,0,0,0,0,0,1,1
1,1,0,0,0,0,0,0,0,0,0,0,0,0,0,0,1
1,0,0,0,0,0,0,0,0,0,0,0,0,0,0,0,1
0,0,0,0,0,0,0,0,0,0,0,0,0,0,0,0,0
0,0,0,0,0,0,0,0,0,0,0,0,0,0,0,0,0
0,0,0,0,0,0,0,0,0,0,0,0,0,0,0,0,1
1,0,0,0,0,0,0,0,0,0,0,0,0,0,0,0,1
1,0,0,0,0,0,0,0,0,0,0,0,0,0,0,21,23
1,1,0,0,0,0,0,0,0,0,0,0,0,0,0,1,18
1,1,0,0,0,0,0,0,0,0,0,0,0,23,1,1,1
1,1,1,0,0,0,0,0,0,0,0,0,0,21,17,1,1
1,1,1,1,1,0,0,0,0,0,0,0,1,1,1,1,1
1,1,1,1,1,1,1,0,0,0,1,1,1,1,1,1,1
endlayer

