
# Created by Ruins mod version 17.0 Ingame Parser
# authoring Player: ST753M

weight=1
uniqueMinDistance=1000
embed_into_distance=1
acceptable_target_blocks=
unacceptable_target_blocks=flowing_water,water,flowing_lava,lava,ice,bedrock,netherrack,nether_brick,nether_brick_fence,soul_sand,quartz_ore,end_stone,obsidian,iron_bars,Natura:Cloud,slime_grass,slime_congealed,slime_dirt,clouds,natura:clouds
dimensions=16,15,15
allowable_overhang=2
max_leveling=2
leveling_buffer=-1
preserve_water=0
preserve_lava=0

adjoining_template=ST753M/753_SmallVillageHut1;20;20;10;40
adjoining_template=ST753M/753_SmallVillageHut1;20;20;-10;40
adjoining_template=ST753M/753_SmallVillageHut1;-20;20;10;40
adjoining_template=ST753M/753_SmallVillageHut1;-20;20;-10;40
adjoining_template=ST753M/753_SmallVillageHut2;10;20;20;40
adjoining_template=ST753M/753_SmallVillageHut2;10;20;-20;40
adjoining_template=ST753M/753_SmallVillageHut2;-10;20;20;40
adjoining_template=ST753M/753_SmallVillageHut2;-10;20;-20;40

biomesToSpawnIn=forest,maple_woods,boreal_forest,forest_hills,woodland,seasonal_forest,temperate_rainforest,fen,grove,sacred_springs,land_of_lakes,forested_hills,lush_hills,thicket,taiga,taiga_hills,mutated_redwood_taiga,mutated_redwood_taiga_hills,redwood_taiga,mutated_taiga,redwood_taiga_hills,redwood_forest,coniferous_forest,shield,dead_forest,autumnal_wooded_hills,autumnal_woods

=0,100,air
rule1=0,100,preserveBlock
rule2=0,100,minecraft:log-1

rule3=0,100,chisel:cobblestone2-3

rule4=0,100,chisel:wool_blue-0
^0,100,chisel:wool_black-0
^0,100,chisel:wool_blue-0
^0,100,chisel:wool_gray-0
^0,100,chisel:wool_lightblue-0
^0,100,chisel:wool_black-1
^0,100,chisel:wool_blue-1
^0,100,chisel:wool_gray-1
^0,100,chisel:wool_lightblue-1
^0,100,chisel:wool_red-0
^0,100,chisel:wool_purple-0
^0,100,chisel:wool_pink-0
^0,100,chisel:wool_magenta-0
^0,100,chisel:wool_red-1
^0,100,chisel:wool_purple-1
^0,100,chisel:wool_pink-1
^0,100,chisel:wool_magenta-1
^0,100,chisel:wool_green-0
^0,100,chisel:wool_cyan-0
^0,100,chisel:wool_lime-0
^0,100,chisel:wool_orange-0
^0,100,chisel:wool_green-1
^0,100,chisel:wool_cyan-1
^0,100,chisel:wool_lime-1
^0,100,chisel:wool_orange-1
^0,100,chisel:wool_brown-0
^0,100,chisel:wool_lightgray-0
^0,100,chisel:wool_yellow-0
^0,100,chisel:wool_white-0
^0,100,chisel:wool_brown-1
^0,100,chisel:wool_lightgray-1
^0,100,chisel:wool_yellow-1
^0,100,chisel:wool_white-1

rule5^0,100,chisel:carpet_blue-0
^0,100,chisel:carpet_black-0
^0,100,chisel:carpet_blue-0
^0,100,chisel:carpet_gray-0
^0,100,chisel:carpet_lightblue-0
^0,100,chisel:carpet_black-1
^0,100,chisel:carpet_blue-1
^0,100,chisel:carpet_gray-1
^0,100,chisel:carpet_lightblue-1
^0,100,chisel:carpet_red-0
^0,100,chisel:carpet_purple-0
^0,100,chisel:carpet_pink-0
^0,100,chisel:carpet_magenta-0
^0,100,chisel:carpet_red-1
^0,100,chisel:carpet_purple-1
^0,100,chisel:carpet_pink-1
^0,100,chisel:carpet_magenta-1
^0,100,chisel:carpet_green-0
^0,100,chisel:carpet_cyan-0
^0,100,chisel:carpet_lime-0
^0,100,chisel:carpet_orange-0
^0,100,chisel:carpet_green-1
^0,100,chisel:carpet_cyan-1
^0,100,chisel:carpet_lime-1
^0,100,chisel:carpet_orange-1
^0,100,chisel:carpet_brown-0
^0,100,chisel:carpet_lightgray-0
^0,100,chisel:carpet_yellow-0
^0,100,chisel:carpet_white-0
^0,100,chisel:carpet_brown-1
^0,100,chisel:carpet_lightgray-1
^0,100,chisel:carpet_yellow-1
^0,100,chisel:carpet_white-1

rule6=0,100,minecraft:log-9
rule7=0,100,minecraft:log-5
rule8=0,100,chisel:planks-spruce-8
rule9=0,100,chisel:planks-spruce-0
rule10=0,100,minecraft:planks-1
rule11=0,100,minecraft:spruce_stairs-3
rule12=0,100,minecraft:spruce_stairs-1
rule13=0,100,chisel:cobblestone-3
rule14=0,100,minecraft:crafting_table-0
rule15=0,100,minecraft:spruce_door-3
rule16=0,100,minecraft:stone_brick_stairs-0
rule17=0,100,minecraft:stone_brick_stairs-5
rule18=0,100,minecraft:bed-10
rule19=0,100,minecraft:bed-2
rule20=0,100,minecraft:spruce_door-0
rule21=0,100,chisel:glass-4
rule22=0,100,minecraft:spruce_door-8
rule23=0,100,minecraft:spruce_fence-0
rule24=1,100,minecraft:torch-5
rule25=0,100,minecraft:spruce_stairs-2
rule26=0,100,minecraft:spruce_stairs-7
rule27=0,100,minecraft:stone_brick_stairs-2
rule28=0,100,minecraft:spruce_stairs-4
rule29=0,100,minecraft:stone_brick_stairs-1

rule30=0,100,CommandBlock:RUINSTRIGGER /summon villager ~ ~1 ~ {Profession:0,Offers:{Recipes:[{rewardExp:0b,maxUses:2147483647,uses:0,buy:{id:"minecraft:emerald",Count:1b},sell:{id:"chisel:icepillar",Count:32b}},{rewardExp:0b,maxUses:2147483647,uses:0,buy:{id:"minecraft:emerald",Count:2b},sell:{id:"chisel:lavastone",Count:32b}},{rewardExp:0b,maxUses:2147483647,uses:0,buy:{id:"minecraft:emerald",Count:3b},sell:{id:"chisel:futura",Count:32b}}]},PersistenceRequired:1}:@-1,CommandBlock:RUINSTRIGGER /summon villager ~ ~1 ~ {Profession:0,Offers:{Recipes:[{rewardExp:0b,maxUses:2147483647,uses:0,buy:{id:"minecraft:emerald",Count:1b},sell:{id:"chisel:paper",Count:32b}},{rewardExp:0b,maxUses:2147483647,uses:0,buy:{id:"minecraft:emerald",Count:2b},sell:{id:"chisel:templemossy",Count:32b}},{rewardExp:0b,maxUses:2147483647,uses:0,buy:{id:"minecraft:emerald",Count:3b},sell:{id:"chisel:technical",Count:32b}}]},PersistenceRequired:1}:@-1,CommandBlock:RUINSTRIGGER /summon villager ~ ~1 ~ {Profession:0,Offers:{Recipes:[{rewardExp:0b,maxUses:2147483647,uses:0,buy:{id:"minecraft:emerald",Count:1b},sell:{id:"chisel:limestone",Count:32b}},{rewardExp:0b,maxUses:2147483647,uses:0,buy:{id:"minecraft:emerald",Count:2b},sell:{id:"chisel:tyrian",Count:32b}},{rewardExp:0b,maxUses:2147483647,uses:0,buy:{id:"minecraft:emerald",Count:3b},sell:{id:"chisel:factory",Count:32b}}]},PersistenceRequired:1}:@-1,CommandBlock:RUINSTRIGGER /summon villager ~ ~1 ~ {Profession:0,Offers:{Recipes:[{rewardExp:0b,maxUses:2147483647,uses:0,buy:{id:"minecraft:emerald",Count:1b},sell:{id:"chisel:valentines",Count:32b}},{rewardExp:0b,maxUses:2147483647,uses:0,buy:{id:"minecraft:emerald",Count:2b},sell:{id:"chisel:technicalnew",Count:32b}},{rewardExp:0b,maxUses:2147483647,uses:0,buy:{id:"minecraft:emerald",Count:3b},sell:{id:"chisel:voidstone",Count:32b}}]},PersistenceRequired:1}:@-1,CommandBlock:RUINSTRIGGER /summon villager ~ ~1 ~ {Profession:0,Offers:{Recipes:[{rewardExp:0b,maxUses:2147483647,uses:0,buy:{id:"minecraft:emerald",Count:1b},sell:{id:"chisel:laboratory",Count:32b}},{rewardExp:0b,maxUses:2147483647,uses:0,buy:{id:"minecraft:emerald",Count:2b},sell:{id:"chisel:technical1",Count:32b}},{rewardExp:0b,maxUses:2147483647,uses:0,buy:{id:"minecraft:emerald",Count:3b},sell:{id:"chisel:waterstone",Count:32b}}]},PersistenceRequired:1}:@-1,CommandBlock:RUINSTRIGGER /summon villager ~ ~1 ~ {Profession:0,Offers:{Recipes:[{rewardExp:0b,maxUses:2147483647,uses:0,buy:{id:"minecraft:emerald",Count:1b},sell:{id:"chisel:ice",Count:32b}},{rewardExp:0b,maxUses:2147483647,uses:0,buy:{id:"minecraft:emerald",Count:2b},sell:{id:"chisel:temple",Count:32b}},{rewardExp:0b,maxUses:2147483647,uses:0,buy:{id:"minecraft:emerald",Count:3b},sell:{id:"chisel:lavastone1",Count:32b}}]},PersistenceRequired:1}:@-1

rule31=0,100,minecraft:spruce_fence_gate-2
rule32=0,100,minecraft:wooden_slab-9
rule33=0,100,minecraft:trapdoor-3
rule34=0,100,minecraft:spruce_stairs-0
rule35=0,70,minecraft:web-0
rule36=0,100,minecraft:stone_brick_stairs-3
rule37=0,100,minecraft:spruce_stairs-5
rule38=0,100,minecraft:spruce_stairs-6
rule39=0,100,minecraft:log-1,minecraft:log-1,minecraft:log-1,minecraft:log-1,minecraft:log-1,MobSpawner:cave_spider,MobSpawner:spider,minecraft:log-1,minecraft:log-1,minecraft:log-1

layer
1,1,1,1,1,1,1,1,1,1,1,1,1,1,1
1,2,1,1,1,2,1,1,1,2,1,1,1,2,1
1,1,3,3,3,3,3,3,3,3,3,3,3,1,1
1,1,3,3,3,3,3,3,3,3,3,3,3,1,1
1,1,3,3,3,3,3,3,3,3,3,3,3,1,1
1,2,3,3,3,3,3,3,3,2,3,3,3,2,1
1,1,3,3,3,3,3,3,3,3,3,3,3,1,1
1,1,3,3,3,3,3,3,3,3,3,3,3,1,1
1,1,3,3,3,3,3,3,3,3,3,3,3,1,1
1,2,3,3,3,5,4,3,3,2,3,3,3,2,1
1,1,3,3,3,3,3,3,3,3,3,3,3,1,1
1,1,3,3,3,3,3,3,3,3,3,3,3,1,1
1,1,3,3,3,3,3,3,3,3,3,3,3,1,1
1,1,1,1,1,2,1,1,1,2,1,1,1,2,1
1,1,1,1,1,1,1,1,1,1,1,1,1,1,1
endlayer

layer
1,1,1,1,1,1,1,1,1,1,1,1,1,1,1
1,2,6,6,6,2,6,6,6,2,6,6,6,2,1
1,7,8,9,8,9,8,9,8,9,8,9,8,7,1
1,7,9,8,9,8,9,8,9,8,9,8,9,7,1
1,7,8,9,4,4,8,9,8,9,8,9,8,7,1
1,2,9,8,4,4,9,8,9,2,9,8,9,2,1
1,7,8,9,4,4,8,9,8,9,8,9,8,7,1
1,7,9,8,9,8,9,8,9,8,9,8,9,7,1
1,7,8,9,8,9,8,9,8,9,8,9,8,7,1
1,2,6,6,6,2,9,8,9,2,9,8,9,2,1
1,1,11,10,10,7,8,9,8,9,8,9,8,7,1
1,1,11,10,10,7,9,8,9,8,9,8,9,7,1
1,1,11,12,12,7,8,9,8,9,8,9,8,7,1
1,1,1,1,1,2,6,6,6,2,6,6,6,2,1
1,1,1,1,1,1,1,1,1,1,1,1,1,1,1
endlayer

layer
1,1,1,1,1,1,1,1,1,1,1,1,1,1,1
1,2,13,13,13,2,13,13,13,2,13,13,13,2,1
1,13,0,0,0,0,0,0,0,13,14,0,0,13,1
1,13,0,5,5,5,5,0,0,15,0,0,0,13,1
1,13,0,5,0,0,5,0,16,13,0,0,0,13,1
1,2,0,5,0,0,5,0,17,2,0,0,0,2,1
1,13,0,5,0,0,5,0,0,13,0,0,0,13,1
1,13,0,5,5,5,5,0,0,13,0,19,18,13,1
1,13,0,0,0,0,0,0,0,13,0,0,14,13,1
1,2,13,20,13,2,13,20,13,2,13,13,13,2,1
1,0,0,0,0,13,14,0,0,0,0,0,0,13,1
0,0,0,0,0,13,0,0,0,0,0,19,18,13,1
1,0,0,0,0,13,0,0,0,0,0,0,14,13,1
1,1,0,0,0,2,13,13,13,2,13,13,13,2,1
1,1,1,0,1,1,1,1,1,1,1,1,1,1,1
endlayer

layer
1,1,1,1,1,1,1,1,1,1,1,1,1,1,1
1,2,13,21,13,2,13,21,13,2,13,21,13,2,1
1,13,0,0,0,0,0,0,0,13,0,0,0,13,1
1,21,0,0,0,0,0,0,0,22,0,0,0,21,1
1,13,0,0,0,0,0,0,0,13,0,0,0,13,1
1,2,0,0,0,0,0,0,16,2,0,0,0,2,1
1,13,0,0,0,0,0,0,17,13,0,0,0,13,1
1,21,0,0,0,0,0,0,0,3,0,0,0,21,1
1,13,0,0,0,0,0,0,0,13,0,0,0,13,1
1,2,13,22,13,2,13,22,13,2,13,3,13,2,1
1,0,0,0,0,13,0,0,0,0,0,0,0,13,1
0,0,0,0,0,21,0,0,0,0,0,0,0,21,1
1,0,0,0,0,13,0,0,0,0,0,0,0,13,1
1,1,0,0,0,2,13,21,13,2,13,21,13,2,1
1,1,1,0,1,1,1,1,1,1,1,1,1,1,1
endlayer

layer
1,1,1,1,1,1,1,1,1,1,1,1,1,1,1
1,2,13,21,13,2,13,21,13,2,13,21,13,2,1
1,13,0,0,0,0,0,0,0,13,0,0,0,13,1
1,21,0,0,0,0,0,0,0,13,0,0,0,21,1
1,13,0,0,0,23,0,0,0,13,0,0,0,13,1
1,2,0,0,23,23,23,0,0,2,0,0,0,2,1
1,13,0,0,0,23,0,0,16,13,0,0,0,13,1
1,21,0,0,0,0,0,0,17,3,0,0,0,21,1
1,13,0,0,0,0,0,0,0,13,0,0,0,13,1
1,2,13,3,13,2,13,13,13,2,13,3,13,2,1
1,0,0,0,0,13,0,0,0,0,0,0,0,13,1
0,0,0,0,0,21,0,0,0,0,0,0,0,21,1
1,0,0,0,0,13,0,0,0,0,0,0,0,13,1
1,1,0,0,0,2,13,21,13,2,13,21,13,2,1
1,1,1,0,1,1,1,1,1,1,1,1,1,1,1
endlayer

layer
1,1,1,1,1,1,1,1,1,1,1,1,1,1,1
1,2,13,13,13,2,13,13,13,2,13,13,13,2,1
1,13,0,0,0,0,0,0,0,13,0,0,0,13,1
1,13,0,0,0,0,0,0,0,13,0,0,0,13,1
1,13,0,0,0,24,0,0,0,13,0,0,0,13,1
1,2,0,0,24,23,24,0,0,2,0,0,0,2,1
1,13,0,0,0,24,0,0,0,13,0,0,0,13,1
1,13,0,0,0,0,0,0,16,13,0,0,0,13,1
1,13,0,0,0,0,0,0,17,13,0,0,0,13,1
1,2,13,13,13,2,13,13,13,2,13,13,13,2,1
1,1,1,1,1,13,0,0,0,0,0,0,0,13,1
1,1,1,1,1,13,0,0,0,0,0,0,0,13,1
1,1,1,1,1,13,0,0,0,0,0,0,0,13,1
1,1,1,1,1,2,13,13,13,2,13,13,13,2,1
1,1,1,1,1,1,1,1,1,1,1,1,1,1,1
endlayer

layer
1,1,1,1,1,1,1,1,1,1,1,1,1,26,25
1,2,6,6,6,2,6,6,6,2,6,6,6,2,27
1,7,9,8,9,8,9,8,9,7,0,0,0,7,25
1,7,8,9,8,9,8,9,8,7,0,0,0,7,25
1,7,9,8,9,8,9,8,9,7,0,0,0,7,25
1,2,8,9,8,9,8,9,0,2,0,0,0,2,27
1,7,9,8,9,8,9,8,0,7,0,0,0,7,25
1,7,8,9,8,9,8,9,0,7,0,0,0,7,25
1,7,9,8,9,8,9,8,16,7,0,0,0,7,25
1,2,6,6,6,2,6,6,6,2,6,6,6,2,27
1,1,1,1,0,7,0,0,0,0,0,0,0,7,25
1,1,1,1,0,7,0,0,0,0,0,0,0,7,25
1,1,1,1,0,7,0,0,0,0,0,0,0,7,25
1,1,1,1,28,2,6,6,6,2,6,6,6,2,25
1,1,1,1,12,29,12,12,12,29,12,12,12,12,12
endlayer

layer
1,1,1,1,1,1,1,1,1,1,1,1,26,25,1
1,2,13,13,13,2,13,13,13,2,13,13,13,27,1
1,13,0,0,25,23,11,0,0,13,0,0,26,25,1
1,13,0,0,0,0,0,0,0,13,0,0,26,25,1
1,13,0,5,5,5,0,23,23,13,0,0,26,25,1
1,2,0,5,5,5,0,23,0,2,6,6,6,27,1
1,13,0,5,5,5,0,23,0,13,0,0,26,25,1
1,13,0,30,0,0,0,23,0,13,0,0,26,25,1
1,13,0,0,0,0,0,31,0,13,0,0,26,25,1
1,2,13,13,13,2,13,13,13,2,10,10,10,27,1
1,1,1,1,0,13,0,0,0,7,0,0,26,25,1
1,1,1,1,0,13,0,0,0,7,0,0,26,25,1
1,1,1,1,28,13,28,28,28,7,28,28,26,25,1
1,1,1,1,12,29,12,12,12,29,12,12,12,25,1
1,1,1,1,1,1,1,1,1,1,1,1,1,1,1
endlayer

layer
1,1,1,1,1,1,1,1,1,32,32,26,25,1,1
1,2,13,21,13,2,13,21,13,2,13,13,27,1,1
1,13,0,0,0,33,0,0,0,13,32,26,25,1,1
1,21,0,0,0,0,0,0,0,13,32,26,25,1,1
1,13,0,0,0,0,0,0,0,13,32,26,25,1,1
1,2,0,0,0,0,0,0,0,2,13,13,27,1,1
1,13,0,0,0,0,0,0,0,13,32,26,25,1,1
1,21,0,0,0,0,0,0,0,13,32,26,25,1,1
1,13,0,0,0,0,0,0,0,13,32,26,25,1,1
1,2,13,21,13,2,13,13,13,2,13,13,27,1,1
1,1,1,1,32,13,32,32,32,13,32,26,25,1,1
1,1,1,1,28,13,28,28,28,13,28,28,25,1,1
1,1,1,1,12,29,12,12,12,29,12,12,25,1,1
1,1,1,1,1,1,1,1,1,1,1,1,1,1,1
1,1,1,1,1,1,1,1,1,1,1,1,1,1,1
endlayer

layer
1,1,1,1,1,1,1,1,1,1,1,1,1,1,1
1,2,13,21,13,2,13,21,13,2,0,1,1,1,1
1,13,0,0,0,0,0,0,0,13,0,1,1,1,1
1,21,0,0,0,0,0,0,0,21,0,1,1,1,1
1,13,0,0,0,23,0,0,0,13,0,1,1,1,1
1,2,0,0,23,23,23,0,0,2,0,1,1,1,1
1,13,0,0,0,23,0,0,0,13,0,1,1,1,1
1,21,0,0,0,0,0,0,0,21,0,1,1,1,1
1,13,0,0,0,0,0,0,0,13,0,1,1,1,1
1,2,13,21,13,2,13,21,13,2,0,1,1,1,1
1,1,1,1,1,1,1,1,1,1,1,1,1,1,1
1,1,1,1,1,1,1,1,1,1,1,1,1,1,1
1,1,1,1,1,1,1,1,1,1,1,1,1,1,1
1,1,1,1,1,1,1,1,1,1,1,1,1,1,1
1,1,1,1,1,1,1,1,1,1,1,1,1,1,1
endlayer

layer
1,1,1,1,1,1,1,1,1,1,1,1,1,1,1
1,2,13,13,13,2,13,13,13,2,0,1,1,1,1
1,13,0,0,0,0,0,0,0,13,0,1,1,1,1
1,13,0,0,0,0,0,0,0,13,0,1,1,1,1
1,13,0,0,0,24,0,0,0,13,0,1,1,1,1
1,2,0,0,24,23,24,0,0,2,0,1,1,1,1
1,13,0,0,0,24,0,0,0,13,0,1,1,1,1
1,13,0,0,0,0,0,0,0,13,0,1,1,1,1
1,13,0,0,0,0,0,0,0,13,0,1,1,1,1
1,2,13,13,13,2,13,13,13,2,0,1,1,1,1
1,1,1,1,1,1,1,1,1,1,1,1,1,1,1
1,1,1,1,1,1,1,1,1,1,1,1,1,1,1
1,1,1,1,1,1,1,1,1,1,1,1,1,1,1
1,1,1,1,1,1,1,1,1,1,1,1,1,1,1
1,1,1,1,1,1,1,1,1,1,1,1,1,1,1
endlayer

layer
34,34,34,16,34,34,34,16,34,34,25,1,1,1,1
11,2,6,6,6,2,6,6,6,2,25,1,1,1,1
11,7,0,0,0,7,0,0,0,7,25,1,1,1,1
36,7,35,0,0,7,0,0,0,7,27,1,1,1,1
11,7,0,0,0,7,0,0,0,7,25,1,1,1,1
11,2,6,6,6,2,6,6,6,2,25,1,1,1,1
11,7,0,0,0,7,0,0,0,7,25,1,1,1,1
36,7,0,0,0,7,0,0,0,7,27,1,1,1,1
11,7,0,0,0,7,0,0,0,7,25,1,1,1,1
11,2,6,6,6,2,6,6,6,2,25,1,1,1,1
11,12,12,29,12,12,12,29,12,12,25,1,1,1,1
1,1,1,1,1,1,1,1,1,1,1,1,1,1,1
1,1,1,1,1,1,1,1,1,1,1,1,1,1,1
1,1,1,1,1,1,1,1,1,1,1,1,1,1,1
1,1,1,1,1,1,1,1,1,1,1,1,1,1,1
endlayer

layer
1,1,1,1,1,1,1,1,1,1,1,1,1,1,1
1,11,34,16,34,34,34,16,34,34,1,1,1,1,1
1,11,38,37,37,37,37,37,26,25,1,1,1,1,1
1,36,38,0,0,0,0,0,26,27,1,1,1,1,1
1,11,38,35,0,0,35,0,26,25,1,1,1,1,1
1,11,38,0,0,2,0,0,26,25,1,1,1,1,1
1,11,38,0,0,0,0,0,26,25,1,1,1,1,1
1,36,38,0,0,0,0,0,26,27,1,1,1,1,1
1,11,38,28,28,28,28,28,28,25,1,1,1,1,1
1,12,12,29,12,12,12,29,12,12,1,1,1,1,1
1,1,1,1,1,1,1,1,1,1,1,1,1,1,1
1,1,1,1,1,1,1,1,1,1,1,1,1,1,1
1,1,1,1,1,1,1,1,1,1,1,1,1,1,1
1,1,1,1,1,1,1,1,1,1,1,1,1,1,1
1,1,1,1,1,1,1,1,1,1,1,1,1,1,1
endlayer

layer
1,1,1,1,1,1,1,1,1,1,1,1,1,1,1
1,1,1,1,1,1,1,1,1,1,1,1,1,1,1
1,1,34,16,34,34,34,16,34,1,1,1,1,1,1
1,1,36,38,37,37,37,26,27,1,1,1,1,1,1
1,1,11,38,0,0,0,26,25,1,1,1,1,1,1
1,1,11,38,0,39,35,26,25,1,1,1,1,1,1
1,1,11,38,0,0,0,26,25,1,1,1,1,1,1
1,1,36,38,28,28,28,28,27,1,1,1,1,1,1
1,1,12,29,12,12,12,29,12,1,1,1,1,1,1
1,1,1,1,1,1,1,1,1,1,1,1,1,1,1
1,1,1,1,1,1,1,1,1,1,1,1,1,1,1
1,1,1,1,1,1,1,1,1,1,1,1,1,1,1
1,1,1,1,1,1,1,1,1,1,1,1,1,1,1
1,1,1,1,1,1,1,1,1,1,1,1,1,1,1
1,1,1,1,1,1,1,1,1,1,1,1,1,1,1
endlayer

layer
1,1,1,1,1,1,1,1,1,1,1,1,1,1,1
1,1,1,1,1,1,1,1,1,1,1,1,1,1,1
1,1,1,1,1,1,1,1,1,1,1,1,1,1,1
1,1,1,16,34,34,34,16,1,1,1,1,1,1,1
1,1,1,11,38,37,26,25,1,1,1,1,1,1,1
1,1,1,11,38,2,26,25,1,1,1,1,1,1,1
1,1,1,11,38,28,28,25,1,1,1,1,1,1,1
1,1,1,36,12,12,12,29,1,1,1,1,1,1,1
1,1,1,1,1,1,1,1,1,1,1,1,1,1,1
1,1,1,1,1,1,1,1,1,1,1,1,1,1,1
1,1,1,1,1,1,1,1,1,1,1,1,1,1,1
1,1,1,1,1,1,1,1,1,1,1,1,1,1,1
1,1,1,1,1,1,1,1,1,1,1,1,1,1,1
1,1,1,1,1,1,1,1,1,1,1,1,1,1,1
1,1,1,1,1,1,1,1,1,1,1,1,1,1,1
endlayer

layer
1,1,1,1,1,1,1,1,1,1,1,1,1,1,1
1,1,1,1,1,1,1,1,1,1,1,1,1,1,1
1,1,1,1,1,1,1,1,1,1,1,1,1,1,1
1,1,1,1,1,1,1,1,1,1,1,1,1,1,1
1,1,1,1,11,34,25,1,1,1,1,1,1,1,1
1,1,1,1,11,10,25,1,1,1,1,1,1,1,1
1,1,1,1,12,12,12,1,1,1,1,1,1,1,1
1,1,1,1,1,1,1,1,1,1,1,1,1,1,1
1,1,1,1,1,1,1,1,1,1,1,1,1,1,1
1,1,1,1,1,1,1,1,1,1,1,1,1,1,1
1,1,1,1,1,1,1,1,1,1,1,1,1,1,1
1,1,1,1,1,1,1,1,1,1,1,1,1,1,1
1,1,1,1,1,1,1,1,1,1,1,1,1,1,1
1,1,1,1,1,1,1,1,1,1,1,1,1,1,1
1,1,1,1,1,1,1,1,1,1,1,1,1,1,1
endlayer

