
# Created by Ruins mod version 16.5 Ingame Parser
# authoring Player: ST753M

weight=1
uniqueMinDistance=2000
embed_into_distance=-60
random_height_offset=-30,30
acceptable_target_blocks=
unacceptable_target_blocks=Natura:Cloud,slime_grass,slime_congealed,slime_dirt,cloud,cloud_block
dimensions=22,13,13
allowable_overhang=99
max_leveling=0
leveling_buffer=0
preserve_water=0
preserve_lava=0
preserve_plants=1

biomesToSpawnIn=taiga_hills,mutated_redwood_taiga_hills,redwood_taiga_hills,extreme_hills,mutated_extreme_hills,mutated_extreme_hills_with_trees,extreme_hills_with_trees,savanna_rock,mutated_savanna_rock

rule1=0,100,minecraft:stone-0
rule2=0,100,minecraft:dirt-0
rule3=0,100,minecraft:gold_ore-0,minecraft:stone-0
rule4=0,100,minecraft:diamond_ore-0,minecraft:stone-0
rule5=0,100,minecraft:stonebrick-1
rule6=0,100,minecraft:stone_brick_stairs-0
rule7=0,100,minecraft:stone_brick_stairs-2
rule8=0,100,minecraft:stone_brick_stairs-3
rule9=0,100,minecraft:stone_brick_stairs-1

rule10=0,50,IInventory;minecraft:chest;minecraft:feather#1#0#0+minecraft:potion#{Potion:"minecraft:long_leaping"}#0#1+minecraft:feather#4#0#5+minecraft:feather#1#0#11+minecraft:string#1#0#14+minecraft:feather#2#0#15+minecraft:string#1#0#16+minecraft:string#1#0#19+minecraft:diamond_sword#{ench:[{lvl:1s,id:16s},{lvl:2s,id:22s}],RepairCost:3,display:{Name:"Sky Sword"}}#0#21+minecraft:string#1#0#22+minecraft:feather#1#0#23-4

rule11=0,50,IInventory;minecraft:chest;minecraft:feather#1#0#1+minecraft:string#1#0#5+minecraft:gold_nugget#2#0#6+minecraft:gold_nugget#1#0#9+minecraft:feather#2#0#10+minecraft:gold_nugget#2#0#16+minecraft:diamond_boots#{ench:[{lvl:4s,id:2s}],RepairCost:1,display:{Name:"Sky Boots"}}#0#18+minecraft:string#1#0#21+minecraft:feather#2#0#24+minecraft:feather#2#0#25-4

rule12=0,100,minecraft:spruce_stairs-6
rule13=0,100,minecraft:spruce_stairs-3
rule14=0,100,minecraft:grass-0
^0,100,minecraft:dirt-2
rule15=0,100,MobSpawner:Skeleton,MobSpawner:Zombie,MobSpawner:Zombie_Villager
rule16=0,100,minecraft:stone_brick_stairs-4
rule17=0,100,minecraft:stone_brick_stairs-6
rule18=0,100,minecraft:stone_brick_stairs-7
rule19=0,100,minecraft:stone_brick_stairs-5
rule20=0,100,minecraft:planks-1
rule21=0,100,minecraft:piston-9
rule22=1,100,minecraft:redstone_torch-5
rule23=0,100,minecraft:oak_stairs-1
rule24=0,100,minecraft:oak_stairs-3
rule25=2,100,minecraft:piston_head-1
rule26=0,100,minecraft:oak_stairs-2
rule27=0,100,minecraft:oak_stairs-0
rule28=0,100,minecraft:spruce_stairs-0
rule29=0,100,minecraft:iron_bars-0
rule30=0,100,minecraft:fence-0
rule31=0,100,minecraft:stone_slab-5
rule32=0,100,minecraft:wooden_pressure_plate-0
rule33=0,100,minecraft:wool-14
^0,100,minecraft:wool-0
^0,100,minecraft:wool-1
^0,100,minecraft:wool-2
^0,100,minecraft:wool-3
^0,100,minecraft:wool-4
^0,100,minecraft:wool-5
^0,100,minecraft:wool-6
^0,100,minecraft:wool-7
^0,100,minecraft:wool-8
^0,100,minecraft:wool-9
^0,100,minecraft:wool-10
^0,100,minecraft:wool-11
^0,100,minecraft:wool-12
^0,100,minecraft:wool-13
^0,100,minecraft:wool-14
^0,100,minecraft:wool-15

layer
0,0,0,0,0,0,0,0,0,0,0,0,0
0,0,0,0,0,0,0,0,0,0,0,0,0
0,0,0,0,0,0,0,0,0,0,0,0,0
0,0,0,0,0,0,0,0,0,0,0,0,0
0,0,0,0,0,0,0,0,0,0,0,0,0
0,0,0,1,0,0,0,0,0,0,0,0,0
0,0,0,0,0,0,0,0,0,0,0,0,0
0,0,0,0,0,0,0,0,0,0,0,0,0
0,0,0,0,0,0,0,0,0,0,0,0,0
0,0,0,0,0,0,0,0,0,0,0,0,0
0,0,0,0,0,0,1,0,0,0,0,0,0
0,0,0,0,0,0,0,0,0,0,0,0,0
0,0,0,0,0,0,0,0,0,0,0,0,0
endlayer

layer
0,0,0,0,0,0,0,0,0,0,0,0,0
0,0,0,0,0,0,0,0,0,0,0,0,0
0,0,0,0,0,0,0,0,0,0,0,0,0
0,0,0,0,0,0,0,1,0,0,0,0,0
0,0,0,0,0,0,0,0,0,0,0,0,0
0,0,0,1,1,0,0,0,0,0,0,0,0
0,0,0,0,0,0,0,0,0,0,0,0,0
0,0,0,0,0,0,0,0,0,0,0,0,0
0,0,0,0,1,0,0,0,0,0,0,0,0
0,0,0,0,0,0,0,0,0,0,0,0,0
0,0,0,0,0,1,1,0,0,0,0,0,0
0,0,0,0,0,0,0,0,0,0,0,0,0
0,0,0,0,0,0,0,0,0,0,0,0,0
endlayer

layer
0,0,0,0,0,0,0,0,0,0,0,0,0
0,0,0,0,0,0,0,0,0,0,0,0,0
0,0,0,0,1,0,0,0,0,0,0,0,0
0,0,0,0,0,0,1,1,0,0,0,0,0
0,0,0,1,0,0,0,1,0,0,0,0,0
0,0,1,1,1,0,0,0,0,1,0,0,0
0,0,0,0,0,0,0,0,0,0,0,0,0
0,0,0,1,0,0,0,0,0,0,0,0,0
0,0,0,0,1,0,0,0,0,0,0,0,0
0,0,0,0,1,1,0,0,0,0,0,0,0
0,0,0,0,0,1,1,1,0,0,0,0,0
0,0,0,0,0,0,1,0,0,0,0,0,0
0,0,0,0,0,0,0,0,0,0,0,0,0
endlayer

layer
0,0,0,0,0,0,0,0,0,0,0,0,0
0,0,0,0,0,1,0,0,0,0,0,0,0
0,0,0,1,1,1,0,0,0,0,0,0,0
0,0,0,0,1,2,2,1,1,0,0,0,0
0,0,0,1,0,0,1,1,1,0,0,0,0
0,0,1,1,1,0,1,1,1,1,0,0,0
0,0,1,1,3,0,0,0,0,0,0,0,0
0,1,1,1,1,3,0,0,0,0,0,1,0
0,0,0,1,1,3,1,0,1,0,0,0,0
0,0,0,1,1,1,1,0,0,0,0,0,0
0,0,0,1,1,1,1,1,0,0,0,0,0
0,0,0,0,1,1,1,1,0,0,0,0,0
0,0,0,0,0,0,0,0,0,0,0,0,0
endlayer

layer
0,0,0,0,0,0,0,0,0,0,0,0,0
0,0,0,1,0,1,1,0,0,0,0,0,0
0,0,0,1,1,1,0,0,0,1,0,0,0
0,1,0,1,1,1,2,2,1,1,1,0,0
0,0,1,1,1,2,1,1,1,1,1,0,1
0,0,1,1,1,2,1,1,1,1,1,0,0
0,1,1,1,1,2,0,0,0,1,1,0,0
0,1,1,1,1,1,3,0,0,0,1,1,0
0,1,0,1,1,1,1,3,3,0,1,0,0
0,0,0,1,1,1,1,1,1,0,0,0,0
0,0,0,1,1,1,1,1,1,1,0,0,0
0,0,0,0,1,1,1,1,1,0,0,0,0
0,0,0,0,0,0,0,0,0,0,0,0,0
endlayer

layer
0,0,0,0,0,1,0,0,0,0,0,0,0
0,0,0,1,1,1,1,1,0,1,0,0,0
0,0,1,1,1,1,1,0,0,1,1,0,0
0,1,1,1,1,1,1,2,2,1,1,0,0
0,1,1,1,1,1,1,1,1,1,1,0,1
0,1,1,1,1,1,1,1,1,1,1,0,1
0,1,1,1,1,1,0,1,1,1,1,1,0
1,1,1,1,1,1,1,3,1,1,1,1,0
0,1,1,1,1,1,1,1,3,1,1,0,0
0,0,0,1,1,1,1,1,3,3,0,0,0
0,1,0,1,1,1,1,1,1,1,1,0,0
0,0,0,0,1,1,1,1,1,0,0,0,0
0,0,0,0,0,0,0,0,0,1,0,0,0
endlayer

layer
0,0,0,0,1,1,0,0,1,0,0,0,0
0,0,1,1,1,1,4,1,1,1,1,0,0
0,0,1,1,1,1,2,1,1,1,1,0,0
1,1,1,1,1,1,1,2,1,1,1,1,1
0,1,1,1,1,1,1,1,1,1,1,1,1
1,1,1,1,1,1,1,1,1,1,1,1,1
0,1,1,1,1,1,0,1,1,1,1,1,1
1,1,1,1,1,1,1,1,1,1,1,1,0
1,1,1,1,1,1,1,1,1,1,1,1,1
0,0,1,1,1,1,1,1,1,3,3,1,0
0,1,1,1,1,1,1,1,1,1,3,0,0
0,0,0,1,1,1,1,1,1,0,0,0,0
0,0,0,0,0,0,1,0,0,1,0,0,0
endlayer

layer
0,0,0,1,1,1,1,0,1,1,0,0,0
0,0,1,1,1,1,1,1,1,1,1,0,0
0,1,1,1,1,1,1,1,1,1,1,1,0
1,1,1,5,5,5,5,5,5,5,1,1,2
0,1,1,5,5,5,5,5,5,5,1,1,1
1,1,1,5,5,5,5,5,5,5,1,1,1
1,1,1,5,5,5,5,5,5,5,1,1,1
1,1,1,5,5,5,5,5,5,5,1,1,1
1,1,1,5,5,5,5,5,5,5,1,1,1
0,1,1,5,5,5,5,5,5,5,1,1,0
0,1,1,1,1,1,1,1,1,1,3,0,0
0,0,0,1,1,1,1,1,1,1,1,0,0
0,0,0,0,1,1,1,1,0,1,0,0,0
endlayer

layer
0,0,0,1,2,2,1,1,1,1,0,0,0
0,0,2,1,1,1,1,1,1,1,2,0,0
0,1,1,5,5,5,5,5,5,5,1,1,0
1,1,5,0,0,0,0,0,0,0,5,1,2
1,1,5,0,0,0,0,0,0,0,5,1,2
1,1,5,0,0,0,6,0,0,0,5,1,1
2,1,5,0,0,8,5,7,0,0,5,1,2
2,1,5,0,0,0,9,0,0,0,5,1,1
1,1,5,0,0,0,0,0,0,0,5,1,1
1,1,5,0,0,13,12,0,11,10,5,1,1
0,1,1,5,5,5,5,5,5,5,1,1,0
0,0,1,1,1,1,1,1,1,1,1,0,0
0,0,0,0,1,2,2,1,1,1,0,0,0
endlayer

layer
0,0,0,14,2,2,2,1,1,14,0,0,0
0,0,2,1,1,1,1,1,1,1,2,0,0
0,1,1,5,5,5,5,5,5,5,1,2,0
14,1,5,0,0,0,0,0,0,0,5,1,14
2,1,5,0,0,0,0,0,0,0,5,1,2
2,1,5,0,0,0,0,0,0,0,5,1,2
2,1,5,0,0,0,15,0,0,0,5,1,2
2,1,5,0,0,0,0,0,0,0,5,1,1
2,1,5,0,0,0,0,0,0,0,5,1,2
14,1,5,0,0,0,13,12,0,0,5,1,14
0,2,1,5,5,5,5,5,5,5,1,1,0
0,0,1,2,1,1,1,1,1,1,2,0,0
0,0,0,0,14,2,2,2,1,14,0,0,0
endlayer

layer
0,0,0,0,14,14,14,14,14,0,0,0,0
0,0,14,2,1,1,1,1,1,2,14,0,0
0,14,1,5,5,5,5,5,5,5,1,14,0
0,2,5,0,0,0,0,0,0,0,5,2,0
14,1,5,0,0,0,0,0,0,0,5,1,14
14,1,5,0,0,0,16,0,0,0,5,1,14
14,1,5,0,0,18,5,17,0,0,5,1,14
14,1,5,0,0,0,19,0,0,0,5,1,14
14,1,5,0,0,0,0,0,0,0,5,1,14
0,2,5,0,0,0,0,13,12,0,5,2,0
0,14,1,5,5,5,5,5,5,5,1,14,0
0,0,14,2,2,1,1,1,2,2,14,0,0
0,0,0,0,0,14,14,14,14,0,0,0,0
endlayer

layer
0,0,0,0,0,0,0,0,0,0,0,0,0
0,0,0,14,14,14,14,14,14,14,0,0,0
0,0,14,14,2,5,5,5,2,14,14,0,0
0,14,14,20,20,20,20,20,20,20,14,14,0
0,14,2,20,20,20,20,20,20,20,2,14,0
0,14,2,20,20,20,20,20,20,20,2,14,0
0,14,2,20,20,20,21,20,20,20,2,14,0
0,14,2,20,20,20,22,20,20,20,2,14,0
0,14,2,20,20,20,20,20,20,20,2,14,0
0,14,14,20,12,0,0,0,13,20,14,14,0
0,0,14,14,5,5,5,5,5,14,14,0,0
0,0,0,14,14,14,14,14,14,14,0,0,0
0,0,0,0,0,0,0,0,0,0,0,0,0
endlayer

layer
0,0,0,0,0,0,0,0,0,0,0,0,0
0,0,0,0,0,0,0,0,0,0,0,0,0
0,0,0,0,5,0,0,0,5,0,0,0,0
0,0,0,5,0,0,0,0,0,5,0,0,0
0,0,5,0,0,0,0,0,0,0,5,0,0
0,0,5,0,0,0,23,0,0,0,5,0,0
0,0,5,0,0,26,25,24,0,0,5,0,0
0,0,5,0,0,0,27,0,0,0,5,0,0
0,0,5,0,0,0,0,0,0,0,5,0,0
0,0,0,5,28,12,0,0,0,5,0,0,0
0,0,0,0,5,5,5,5,5,0,0,0,0
0,0,0,0,0,0,0,0,0,0,0,0,0
0,0,0,0,0,0,0,0,0,0,0,0,0
endlayer

layer
0,0,0,0,0,0,0,0,0,0,0,0,0
0,0,0,0,0,0,0,0,0,0,0,0,0
0,0,0,0,5,0,0,0,5,0,0,0,0
0,0,0,5,0,0,0,0,0,5,0,0,0
0,0,5,0,0,0,0,0,0,0,5,0,0
0,0,29,0,0,0,0,0,0,0,29,0,0
0,0,5,0,0,0,0,0,0,0,5,0,0
0,0,29,0,0,0,0,0,0,0,29,0,0
0,0,5,0,0,0,0,0,0,0,5,0,0
0,0,0,5,0,13,12,0,0,5,0,0,0
0,0,0,0,5,5,5,5,5,0,0,0,0
0,0,0,0,0,0,0,0,0,0,0,0,0
0,0,0,0,0,0,0,0,0,0,0,0,0
endlayer

layer
0,0,0,0,0,0,0,0,0,0,0,0,0
0,0,0,0,0,0,0,0,0,0,0,0,0
0,0,0,0,5,29,29,29,5,0,0,0,0
0,0,0,5,0,0,0,0,0,5,0,0,0
0,0,5,0,0,0,0,0,0,0,5,0,0
0,0,29,0,0,0,30,0,0,0,29,0,0
0,0,5,0,0,30,30,30,0,0,5,0,0
0,0,29,0,0,0,30,0,0,0,29,0,0
0,0,5,0,0,0,0,0,0,0,5,0,0
0,0,0,5,0,0,13,12,0,5,0,0,0
0,0,0,0,5,5,5,5,5,0,0,0,0
0,0,0,0,0,0,19,0,0,0,0,0,0
0,0,0,0,0,0,0,0,0,0,0,0,0
endlayer

layer
0,0,0,0,0,0,0,0,0,0,0,0,0
0,0,0,0,0,0,0,0,0,0,0,0,0
0,0,0,16,5,5,5,5,5,16,0,0,0
0,0,18,5,0,0,0,0,0,5,17,0,0
0,0,5,0,0,0,0,0,0,0,5,0,0
0,0,5,0,0,0,22,0,0,0,5,0,0
0,0,5,0,0,22,30,22,0,0,5,0,0
0,0,5,0,0,0,22,0,0,0,5,0,0
0,0,5,0,0,0,0,0,0,0,5,0,0
0,0,18,5,0,0,0,13,12,5,17,0,0
0,0,0,19,5,5,5,5,5,19,0,0,0
0,0,0,0,0,19,5,19,0,0,0,0,0
0,0,0,0,0,0,0,0,0,0,0,0,0
endlayer

layer
0,0,0,0,0,0,0,0,0,0,0,0,0
0,0,0,0,16,5,6,5,16,0,0,0,0
0,0,0,5,20,20,20,20,20,5,0,0,0
0,0,5,20,20,20,20,20,20,20,5,0,0
0,18,20,20,20,20,20,20,20,20,20,17,0
0,5,20,20,20,20,20,20,20,20,20,5,0
0,8,20,20,20,20,20,20,20,20,20,7,0
0,5,20,20,20,20,20,20,20,20,20,5,0
0,18,20,20,20,20,20,20,20,20,20,17,0
0,0,5,20,20,0,0,0,13,20,5,0,0
0,0,0,5,20,20,20,20,20,5,0,0,0
0,0,0,0,19,5,9,5,19,0,0,0,0
0,0,0,0,0,0,0,0,0,0,0,0,0
endlayer

layer
0,0,0,0,0,0,0,0,0,0,0,0,0
0,0,0,0,5,16,16,16,5,0,0,0,0
0,0,0,5,0,0,0,0,0,5,0,0,0
0,0,5,0,0,26,30,24,0,0,5,0,0
0,5,0,0,0,0,0,0,0,0,0,5,0
0,18,0,0,0,0,0,0,0,0,0,17,0
0,18,0,0,0,0,5,0,0,0,0,17,0
0,18,0,0,0,0,0,0,0,0,0,17,0
0,5,0,0,0,0,0,0,0,0,0,5,0
0,0,5,0,0,0,0,0,0,0,5,0,0
0,0,0,5,0,0,0,0,0,5,0,0,0
0,0,0,0,5,19,19,19,5,0,0,0,0
0,0,0,0,0,0,0,0,0,0,0,0,0
endlayer

layer
0,0,0,0,0,0,0,0,0,0,0,0,0
0,0,0,0,5,31,5,31,5,0,0,0,0
0,0,0,31,0,0,0,0,0,31,0,0,0
0,0,5,0,0,0,32,0,0,0,5,0,0
0,31,0,0,0,0,0,0,0,0,0,31,0
0,5,0,0,0,0,0,0,0,0,0,5,0
0,31,0,0,0,0,30,0,0,0,0,31,0
0,5,0,0,0,0,0,0,0,0,0,5,0
0,31,0,0,0,0,0,0,0,0,0,31,0
0,0,5,0,0,0,0,0,0,0,5,0,0
0,0,0,31,0,0,0,0,0,31,0,0,0
0,0,0,0,5,31,5,31,5,0,0,0,0
0,0,0,0,0,0,0,0,0,0,0,0,0
endlayer

layer
0,0,0,0,0,0,0,0,0,0,0,0,0
0,0,0,0,0,0,0,0,0,0,0,0,0
0,0,0,0,0,0,0,0,0,0,0,0,0
0,0,0,0,0,0,0,0,0,0,0,0,0
0,0,0,0,0,0,0,0,0,0,0,0,0
0,0,0,0,0,0,0,0,0,0,0,0,0
0,0,0,0,0,0,30,0,0,0,0,0,0
0,0,0,0,0,0,0,0,0,0,0,0,0
0,0,0,0,0,0,0,0,0,0,0,0,0
0,0,0,0,0,0,0,0,0,0,0,0,0
0,0,0,0,0,0,0,0,0,0,0,0,0
0,0,0,0,0,0,0,0,0,0,0,0,0
0,0,0,0,0,0,0,0,0,0,0,0,0
endlayer

layer
0,0,0,0,0,0,0,0,0,0,0,0,0
0,0,0,0,0,0,0,0,0,0,0,0,0
0,0,0,0,0,0,0,0,0,0,0,0,0
0,0,0,0,0,0,0,0,0,0,0,0,0
0,0,0,0,0,0,0,0,0,0,0,0,0
0,0,0,0,0,0,0,0,0,0,0,0,0
0,0,0,0,0,0,33,33,0,0,0,0,0
0,0,0,0,0,0,0,0,33,33,0,0,0
0,0,0,0,0,0,0,0,0,0,0,0,0
0,0,0,0,0,0,0,0,0,0,0,0,0
0,0,0,0,0,0,0,0,0,0,0,0,0
0,0,0,0,0,0,0,0,0,0,0,0,0
0,0,0,0,0,0,0,0,0,0,0,0,0
endlayer

layer
0,0,0,0,0,0,0,0,0,0,0,0,0
0,0,0,0,0,0,0,0,0,0,0,0,0
0,0,0,0,0,0,0,0,0,0,0,0,0
0,0,0,0,0,0,0,0,0,0,0,0,0
0,0,0,0,0,0,0,0,0,0,0,0,0
0,0,0,0,0,0,0,0,0,0,0,0,0
0,0,0,0,0,0,33,33,0,0,0,0,0
0,0,0,0,0,0,0,0,33,0,0,0,0
0,0,0,0,0,0,0,0,0,0,0,0,0
0,0,0,0,0,0,0,0,0,0,0,0,0
0,0,0,0,0,0,0,0,0,0,0,0,0
0,0,0,0,0,0,0,0,0,0,0,0,0
0,0,0,0,0,0,0,0,0,0,0,0,0
endlayer

