
# Created by Ruins mod version 17.1 Ingame Parser
# authoring Player: ST753M

weight=1
uniqueMinDistance=2000
embed_into_distance=5
acceptable_target_blocks=sand,sandstone
unacceptable_target_blocks=flowing_water,water,flowing_lava,lava
dimensions=16,19,19
allowable_overhang=5
max_leveling=0
leveling_buffer=0
preserve_water=0
preserve_lava=0

biomesToSpawnIn=ocean,beaches

=0,100,air
rule1=0,100,preserveBlock
rule2=0,100,minecraft:sandstone-0
rule3=0,100,minecraft:sand-0
rule4=0,100,minecraft:sandstone_stairs-1
rule5=0,100,IInventory;minecraft:trapped_chest;minecraft:gold_nugget#5#0#1+minecraft:gold_nugget#3#0#7+minecraft:gold_nugget#2#0#11+minecraft:gold_nugget#4#0#15+minecraft:gold_nugget#4#0#21-2
rule6=0,100,IInventory;minecraft:trapped_chest;minecraft:gold_nugget#3#0#3+minecraft:golden_sword#1#0#5+minecraft:gold_nugget#4#0#7+minecraft:gold_nugget#4#0#10+minecraft:gold_nugget#5#0#18+minecraft:golden_apple#1#1#21+minecraft:gold_nugget#2#0#26-2
rule7=0,100,CommandBlock:RUINSTRIGGER /summon quark:pirate ~ ~1 ~ {PersistenceRequired:1,ArmorItems:[{},{},{},{id:"quark:pirate_hat",Count:1b}]}:@-1

rule8=0,100,IInventory;minecraft:trapped_chest;minecraft:golden_horse_armor#1#0#6+minecraft:gold_nugget#2#0#8+minecraft:gold_nugget#9#0#10+minecraft:gold_nugget#4#0#13+minecraft:golden_carrot#2#0#20+minecraft:gold_nugget#3#0#25-4
rule9=0,100,minecraft:sandstone_stairs-2
rule10=0,100,minecraft:planks-3
rule11=0,100,minecraft:sandstone_stairs-5
rule12=0,100,minecraft:sandstone_stairs-0
rule13=0,100,minecraft:sandstone_stairs-3
rule14=0,100,minecraft:sandstone_stairs-4
rule15=0,100,minecraft:sandstone_stairs-7
rule16=0,100,teBlock;minecraft:wall_banner;{x:304449,y:80,z:31957,id:"minecraft:banner",Patterns:[{Pattern:"sku",Color:15}],Base:0}-4
rule17=0,100,teBlock;minecraft:wall_banner;{x:304454,y:80,z:31962,id:"minecraft:banner",Patterns:[{Pattern:"sku",Color:15}],Base:0}-3
rule18=0,100,teBlock;minecraft:wall_banner;{x:304459,y:80,z:31957,id:"minecraft:banner",Patterns:[{Pattern:"sku",Color:15}],Base:0}-5
rule19=0,100,minecraft:stone_slab-9
rule20=0,100,minecraft:sandstone_stairs-6
rule21=0,50,Skull:0:15-1
rule22=0,100,IInventory;minecraft:trapped_chest;minecraft:gold_nugget#5#0#2+minecraft:golden_helmet#1#0#4+quark:ancient_tome#{ench:[{lvl:3s,id:61s}]}#0#7+minecraft:gold_nugget#4#0#9+minecraft:gold_nugget#4#0#14+minecraft:gold_nugget#3#0#17+minecraft:golden_carrot#2#0#20+minecraft:gold_nugget#2#0#25-4
rule23=0,100,IInventory;minecraft:trapped_chest;minecraft:gold_nugget#5#0#2+minecraft:golden_apple#1#0#8+minecraft:golden_carrot#1#0#13+minecraft:gold_nugget#4#0#15+minecraft:gold_nugget#4#0#19+minecraft:gold_nugget#5#0#25-3

layer
1,1,1,1,1,1,1,1,1,1,1,1,1,1,1,1,1,1,1
1,1,1,1,1,1,1,1,1,1,1,1,1,1,1,1,1,1,1
1,1,2,2,2,2,2,2,1,1,1,2,2,2,2,2,2,1,1
1,1,2,2,2,2,2,2,2,2,2,2,2,2,2,2,2,1,1
1,1,2,2,2,2,2,2,2,2,2,2,2,2,2,2,2,1,1
1,1,2,2,2,2,2,2,2,2,2,2,2,2,2,2,2,1,1
1,1,2,2,2,2,2,2,2,2,2,2,2,2,2,2,2,1,1
1,1,2,2,2,2,2,2,2,2,2,2,2,2,2,2,2,1,1
1,1,1,2,2,2,2,2,2,2,2,2,2,2,2,2,1,1,1
1,1,1,2,2,2,2,2,2,2,2,2,2,2,2,2,1,1,1
1,1,1,2,2,2,2,2,2,2,2,2,2,2,2,2,1,1,1
1,1,2,2,2,2,2,2,2,2,2,2,2,2,2,2,2,1,1
1,1,2,2,2,2,2,2,2,2,2,2,2,2,2,2,2,1,1
1,1,2,2,2,2,2,2,2,2,2,2,2,2,2,2,2,1,1
1,1,2,2,2,2,2,2,2,2,2,2,2,2,2,2,2,1,1
1,1,2,2,2,2,2,2,2,2,2,2,2,2,2,2,2,1,1
1,1,2,2,2,2,2,2,1,1,1,2,2,2,2,2,2,1,1
1,1,1,1,1,1,1,1,1,1,1,1,1,1,1,1,1,1,1
1,1,1,1,1,1,1,1,1,1,1,1,1,1,1,1,1,1,1
endlayer

layer
1,1,1,1,1,1,1,1,1,1,1,1,1,1,1,1,1,1,1
1,1,2,1,1,1,2,1,1,1,1,1,2,1,1,1,2,1,1
1,2,2,2,2,2,2,2,1,1,1,2,2,3,3,3,2,2,1
1,1,2,2,2,2,2,2,2,2,2,2,3,3,3,4,3,1,1
1,1,2,2,2,2,2,2,2,2,2,2,3,5,0,0,3,1,1
1,1,2,2,2,2,3,3,3,3,3,3,3,0,0,0,3,1,1
1,2,2,2,2,3,3,0,0,0,0,0,3,3,3,2,2,2,1
1,1,2,2,2,3,6,0,0,0,0,0,0,3,2,2,2,1,1
1,1,1,2,2,3,0,0,0,0,0,0,0,3,2,2,1,1,1
1,1,1,2,2,3,0,0,0,7,0,0,0,3,2,2,1,1,1
1,1,1,2,2,3,0,0,7,0,0,0,0,3,2,2,1,1,1
1,1,2,2,2,3,0,0,0,0,0,0,0,3,2,2,2,1,1
1,2,2,2,2,3,3,0,0,8,0,0,3,3,2,2,2,2,1
1,1,2,2,2,2,3,3,3,3,3,3,3,2,2,2,2,1,1
1,1,2,2,2,2,2,2,2,2,2,2,2,2,2,2,2,1,1
1,1,2,2,2,2,2,2,2,2,2,2,2,2,2,2,2,1,1
1,2,2,2,2,2,2,2,1,1,1,2,2,2,2,2,2,2,1
1,1,2,1,1,1,2,1,1,1,1,1,2,1,1,1,2,1,1
1,1,1,1,1,1,1,1,1,1,1,1,1,1,1,1,1,1,1
endlayer

layer
1,1,1,1,1,1,1,1,1,1,1,1,1,1,1,1,1,1,1
1,3,3,1,1,1,3,1,1,1,1,1,3,1,1,1,3,3,1
1,3,2,3,3,3,2,3,1,1,1,3,2,3,3,3,2,3,1
1,3,3,2,2,2,2,10,2,2,2,10,3,3,9,0,3,1,1
1,3,3,2,2,2,2,2,2,2,2,2,3,0,0,0,3,1,1
1,1,3,2,2,2,3,3,3,3,3,3,3,0,0,0,3,1,1
1,3,2,2,2,3,3,0,0,0,0,0,0,3,3,3,2,3,1
1,1,3,10,2,3,0,0,0,0,0,0,0,3,2,10,3,1,1
1,1,1,2,2,3,0,0,0,0,0,0,0,3,2,2,1,1,1
1,1,1,2,2,3,0,0,0,0,0,0,0,3,2,2,1,1,1
1,1,1,2,2,3,0,0,0,0,0,0,0,3,2,2,1,1,1
1,1,3,10,2,3,0,0,0,0,0,0,0,3,2,10,3,1,1
1,3,2,2,2,3,3,0,0,0,0,0,3,3,2,2,2,3,1
1,1,3,2,2,2,3,3,3,3,3,3,3,2,2,2,3,1,1
1,1,3,2,2,2,2,2,2,2,2,2,2,2,2,2,3,1,1
1,1,3,2,2,2,2,10,2,2,2,10,2,2,2,2,3,1,1
1,3,2,3,3,3,2,3,1,1,1,3,2,3,3,3,2,3,1
1,3,3,1,1,1,3,1,1,1,1,1,3,1,1,1,3,3,1
1,1,1,1,1,1,1,1,1,1,1,1,1,1,1,1,1,1,1
endlayer

layer
1,1,3,1,1,1,3,1,1,1,1,1,3,1,1,1,3,1,1
1,3,3,3,3,3,3,1,1,1,1,1,3,3,3,3,3,3,1
3,3,2,3,3,3,2,3,3,3,3,3,2,3,3,3,2,3,3
1,3,3,2,2,2,2,2,3,3,3,2,3,9,0,0,3,3,1
1,3,3,2,2,2,2,2,2,2,2,2,3,11,0,0,3,3,1
1,3,3,2,2,2,3,3,3,3,3,3,3,0,0,0,3,3,1
3,3,2,2,2,3,3,0,0,0,0,0,0,3,3,3,2,3,3
1,1,3,2,2,3,0,0,0,0,0,0,0,3,2,2,3,1,1
1,1,3,3,2,3,0,0,0,0,0,0,0,3,2,3,3,1,1
1,1,3,3,2,3,0,0,0,0,0,0,0,3,2,3,3,1,1
1,1,3,3,2,3,0,0,0,0,0,0,0,3,2,3,3,1,1
1,1,3,2,2,3,0,0,0,0,0,0,0,3,2,2,3,1,1
3,3,2,2,2,3,3,0,0,0,0,0,3,3,2,2,2,3,3
1,3,3,2,2,2,3,3,3,3,3,3,3,2,2,2,3,3,1
1,3,3,2,2,2,2,2,2,2,2,2,2,2,2,2,3,3,1
1,3,3,2,2,2,2,2,3,3,3,2,2,2,2,2,3,3,1
3,3,2,3,3,3,2,3,3,3,3,3,2,3,3,3,2,3,3
1,3,3,3,3,3,3,1,1,1,1,1,3,3,3,3,3,3,1
1,1,3,1,1,1,3,1,1,1,1,1,3,1,1,1,3,1,1
endlayer

layer
1,1,3,1,1,1,3,1,1,1,1,1,3,1,1,1,3,1,1
1,3,3,3,3,3,3,1,1,1,1,1,3,3,3,3,3,3,1
3,3,2,3,3,3,2,3,3,3,3,3,2,3,3,3,2,3,3
1,3,3,2,2,2,2,3,3,3,3,3,3,0,0,0,3,3,1
1,3,3,2,2,2,2,3,3,3,3,3,3,12,2,2,3,3,1
1,3,3,2,2,2,2,2,2,2,2,2,2,2,2,2,3,3,1
3,3,2,2,2,2,2,2,2,2,2,2,2,2,3,3,2,3,3
1,1,3,3,3,2,2,2,2,2,2,2,2,2,3,3,3,1,1
1,1,3,3,3,2,2,2,2,2,2,2,2,2,3,3,3,1,1
1,1,3,3,3,2,2,2,2,2,2,2,2,2,3,3,3,1,1
1,1,3,3,3,2,2,2,2,2,2,2,2,2,3,3,3,1,1
1,1,3,3,3,2,2,2,2,2,2,2,2,2,3,3,3,1,1
3,3,2,2,2,2,2,2,2,2,2,2,2,2,2,2,2,3,3
1,3,3,2,2,2,2,2,2,2,2,2,2,2,2,2,3,3,1
1,3,3,2,2,2,2,3,3,3,3,3,2,2,2,2,3,3,1
1,3,3,2,2,2,2,3,3,3,3,3,2,2,2,2,3,3,1
3,3,2,3,3,3,2,3,3,3,3,3,2,3,3,3,2,3,3
1,3,3,3,3,3,3,1,1,1,1,1,3,3,3,3,3,3,1
1,1,3,1,1,1,3,1,1,1,1,1,3,1,1,1,3,1,1
endlayer

layer
1,1,3,1,1,1,3,1,1,1,1,1,3,1,1,1,3,1,1
1,3,3,1,1,1,3,1,1,1,1,1,3,1,1,1,3,3,1
3,3,2,3,3,3,2,3,1,1,1,3,2,3,3,3,2,3,3
1,1,3,0,0,0,3,1,1,1,1,1,3,0,0,0,3,1,1
1,1,3,0,0,0,3,1,1,1,1,1,3,0,0,0,3,1,1
1,1,3,0,0,0,0,3,3,3,3,3,0,0,13,2,3,1,1
3,3,2,3,3,0,0,0,0,0,0,0,0,0,3,3,2,3,3
1,1,3,1,1,3,0,0,0,0,0,0,0,3,1,1,3,1,1
1,1,1,1,1,3,0,0,0,0,0,0,0,0,0,1,1,1,1
1,1,1,1,1,3,0,0,0,0,0,0,0,0,0,1,1,1,1
1,1,1,1,1,3,0,0,0,0,0,0,0,0,0,1,1,1,1
1,1,3,1,1,3,0,0,0,0,0,0,0,3,1,1,3,1,1
3,3,2,3,3,0,0,0,0,0,0,0,0,0,3,3,2,3,3
1,1,3,0,0,0,0,3,3,3,3,3,0,0,0,0,3,1,1
1,1,3,0,0,0,3,1,1,1,1,1,3,0,0,0,3,1,1
1,1,3,0,0,0,3,1,1,1,1,1,3,0,0,0,3,1,1
3,3,2,3,3,3,2,3,1,1,1,3,2,3,3,3,2,3,3
1,3,3,1,1,1,3,1,1,1,1,1,3,1,1,1,3,3,1
1,1,3,1,1,1,3,1,1,1,1,1,3,1,1,1,3,1,1
endlayer

layer
1,1,3,1,1,1,3,1,1,1,1,1,3,1,1,1,3,1,1
1,3,3,1,1,1,3,1,1,1,1,1,3,1,1,1,3,3,1
3,3,2,3,0,3,2,3,1,1,1,3,2,3,0,3,2,3,3
1,1,3,0,0,0,3,1,1,1,1,1,3,0,0,0,3,1,1
1,1,0,0,0,0,3,1,1,1,1,1,3,0,0,14,0,1,1
1,1,3,0,0,0,0,3,0,3,0,3,0,0,0,13,3,1,1
3,3,2,3,3,0,0,0,0,0,0,0,0,0,3,3,2,3,3
1,1,3,1,1,3,0,0,0,0,0,0,0,3,1,1,3,1,1
1,1,1,1,1,0,0,0,0,0,0,0,0,0,0,1,1,1,1
1,1,1,1,1,3,0,0,0,0,0,0,0,0,0,1,1,1,1
1,1,1,1,1,0,0,0,0,0,0,0,0,0,0,1,1,1,1
1,1,3,1,1,3,0,0,0,0,0,0,0,3,1,1,3,1,1
3,3,2,3,3,0,0,0,0,0,0,0,0,0,3,3,2,3,3
1,1,3,0,0,0,0,3,0,3,0,3,0,0,0,0,3,1,1
1,1,0,0,0,0,3,1,1,1,1,1,3,0,0,0,0,1,1
1,1,3,0,0,0,3,1,1,1,1,1,3,0,0,0,3,1,1
3,3,2,3,0,3,2,3,1,1,1,3,2,3,0,3,2,3,3
1,3,3,1,1,1,3,1,1,1,1,1,3,1,1,1,3,3,1
1,1,3,1,1,1,3,1,1,1,1,1,3,1,1,1,3,1,1
endlayer

layer
1,1,3,1,1,1,3,1,1,1,1,1,3,1,1,1,3,1,1
1,3,3,1,1,1,3,1,1,1,1,1,3,1,1,1,3,3,1
3,3,2,3,0,3,2,3,1,1,1,3,2,3,0,3,2,3,3
1,1,3,0,0,0,3,1,1,1,1,1,3,0,0,15,3,1,1
1,1,0,0,0,0,3,1,1,0,1,1,3,0,0,4,0,1,1
1,1,3,0,0,0,2,3,0,3,0,3,2,0,0,0,3,1,1
3,3,2,3,3,2,0,0,0,0,0,0,0,2,3,3,2,3,3
1,1,3,1,1,3,0,0,0,0,0,0,0,3,1,1,3,1,1
1,1,1,1,1,0,0,0,0,0,0,0,0,11,0,1,1,1,1
1,1,1,1,0,3,0,0,0,0,0,0,0,0,0,1,1,1,1
1,1,1,1,1,0,0,0,0,0,0,0,0,14,0,1,1,1,1
1,1,3,1,1,3,0,0,0,0,0,0,0,3,1,1,3,1,1
3,3,2,3,3,2,0,0,0,0,0,0,0,2,3,3,2,3,3
1,1,3,0,0,0,2,3,0,3,0,3,2,0,0,0,3,1,1
1,1,0,0,0,0,3,1,1,0,1,1,3,0,0,0,0,1,1
1,1,3,0,0,0,3,1,1,1,1,1,3,0,0,0,3,1,1
3,3,2,3,0,3,2,3,1,1,1,3,2,3,0,3,2,3,3
1,3,3,1,1,1,3,1,1,1,1,1,3,1,1,1,3,3,1
1,1,3,1,1,1,3,1,1,1,1,1,3,1,1,1,3,1,1
endlayer

layer
1,1,3,1,1,1,3,1,1,1,1,1,3,1,1,1,3,1,1
1,1,3,1,1,1,3,1,1,1,1,1,3,1,1,1,3,1,1
3,3,2,3,2,3,2,3,1,1,1,3,2,3,2,3,2,3,3
1,1,3,0,0,0,3,1,1,1,1,1,3,0,15,4,3,1,1
1,1,2,0,0,0,3,1,1,16,1,1,3,0,0,0,2,1,1
1,1,3,0,0,0,3,3,2,3,2,3,3,0,0,0,3,1,1
3,3,2,3,3,3,0,0,0,0,0,0,0,3,3,3,2,3,3
1,1,3,1,1,3,0,0,0,0,0,0,0,3,1,1,3,1,1
1,1,1,1,1,2,0,0,0,0,0,0,0,3,0,1,1,1,1
1,1,1,1,17,3,0,0,0,0,0,0,0,2,0,1,1,1,1
1,1,1,1,1,2,0,0,0,0,0,0,0,3,0,1,1,1,1
1,1,3,1,1,3,0,0,0,0,0,0,0,3,1,1,3,1,1
3,3,2,3,3,3,0,0,0,0,0,0,0,3,3,3,2,3,3
1,1,3,0,0,0,3,3,2,3,2,3,3,0,0,0,3,1,1
1,1,2,0,0,0,3,1,1,18,1,1,3,0,0,0,2,1,1
1,1,3,0,0,0,3,1,1,1,1,1,3,0,0,0,3,1,1
3,3,2,3,2,3,2,3,1,1,1,3,2,3,2,3,2,3,3
1,1,3,1,1,1,3,1,1,1,1,1,3,1,1,1,3,1,1
1,1,3,1,1,1,3,1,1,1,1,1,3,1,1,1,3,1,1
endlayer

layer
1,1,3,1,1,1,3,1,1,1,1,1,3,1,1,1,3,1,1
1,1,3,1,1,1,3,1,1,1,1,1,3,1,1,1,3,1,1
3,3,2,3,3,3,2,3,1,1,1,3,2,3,3,3,2,3,3
1,1,3,2,2,2,3,1,1,1,1,1,3,2,9,0,3,1,1
1,1,3,2,2,2,2,2,14,19,14,2,3,2,2,0,3,1,1
1,1,3,2,2,2,2,3,3,3,3,3,10,2,2,0,3,1,1
3,3,2,3,2,10,2,2,2,2,2,2,2,2,3,3,2,3,3
1,1,3,1,2,3,2,2,11,11,11,2,2,3,2,1,3,1,1
1,1,1,1,15,3,2,20,19,19,19,15,2,3,20,1,1,1,1
1,1,1,1,19,3,2,20,19,19,19,15,2,3,19,1,1,1,1
1,1,1,1,15,3,2,20,19,19,19,15,2,3,20,1,1,1,1
1,1,3,1,2,2,2,2,14,14,14,2,2,3,2,1,3,1,1
3,3,2,3,2,2,2,2,2,2,2,2,2,10,2,3,2,3,3
1,1,3,2,2,2,10,3,3,3,3,3,2,2,2,2,3,1,1
1,1,3,2,2,2,2,2,11,19,11,2,2,2,2,2,3,1,1
1,1,3,2,2,2,3,1,1,1,1,1,3,2,2,2,3,1,1
3,3,2,3,3,3,2,3,1,1,1,3,2,3,3,3,2,3,3
1,1,3,1,1,1,3,1,1,1,1,1,3,1,1,1,3,1,1
1,1,3,1,1,1,3,1,1,1,1,1,3,1,1,1,3,1,1
endlayer

layer
1,1,1,1,1,1,1,1,1,1,1,1,1,1,1,1,1,1,1
1,1,3,1,1,1,3,1,1,1,1,1,3,1,1,1,3,1,1
1,3,2,3,3,3,2,3,1,1,1,3,2,3,3,3,2,3,1
1,1,3,0,0,0,3,1,1,1,1,1,3,0,0,0,3,1,1
1,1,3,0,7,0,3,3,3,3,3,3,3,0,0,0,3,1,1
1,1,3,0,0,0,0,0,0,0,0,0,3,0,0,0,3,1,1
1,3,2,3,3,3,3,3,0,0,0,3,3,0,0,3,2,3,1
1,1,3,1,3,0,3,0,0,0,0,0,3,0,3,1,3,1,1
1,1,1,1,3,0,0,0,0,0,0,0,0,0,3,1,1,1,1
1,1,1,1,3,0,0,0,0,0,0,0,0,0,3,1,1,1,1
1,1,1,1,3,0,0,0,0,0,0,0,0,0,3,1,1,1,1
1,1,3,1,3,0,3,21,0,0,0,0,3,0,3,1,3,1,1
1,3,2,3,3,0,3,3,0,0,0,3,3,3,3,3,2,3,1
1,1,3,0,0,0,3,0,0,0,0,0,0,0,0,0,3,1,1
1,1,3,0,7,0,3,3,3,3,3,3,3,0,7,0,3,1,1
1,1,3,22,0,0,3,1,1,1,1,1,3,0,0,0,3,1,1
1,3,2,3,3,3,2,3,1,1,1,3,2,3,3,3,2,3,1
1,1,3,1,1,1,3,1,1,1,1,1,3,1,1,1,3,1,1
1,1,1,1,1,1,1,1,1,1,1,1,1,1,1,1,1,1,1
endlayer

layer
1,1,1,1,1,1,1,1,1,1,1,1,1,1,1,1,1,1,1
1,1,3,1,1,1,3,1,1,1,1,1,3,1,1,1,3,1,1
1,3,2,3,0,3,2,3,1,1,1,3,2,3,0,3,2,3,1
1,1,3,0,0,0,3,1,1,1,1,1,3,0,0,0,3,1,1
1,1,0,0,0,0,0,1,3,1,3,1,0,0,0,0,0,1,1
1,1,3,0,0,0,0,0,0,0,0,0,3,0,0,0,3,1,1
1,3,2,3,0,3,3,3,0,0,0,3,3,0,0,3,2,3,1
1,1,3,1,1,0,3,0,0,0,0,0,3,0,1,1,3,1,1
1,1,1,1,3,0,0,0,0,0,0,0,0,0,3,1,1,1,1
1,1,1,1,1,0,0,0,0,0,0,0,0,0,1,1,1,1,1
1,1,1,1,3,0,0,0,0,0,0,0,0,0,3,1,1,1,1
1,1,3,1,1,0,3,0,0,0,0,0,3,0,1,1,3,1,1
1,3,2,3,0,0,3,3,0,0,0,3,3,3,0,3,2,3,1
1,1,3,0,0,0,3,0,0,0,0,0,0,0,0,0,3,1,1
1,1,0,0,0,0,0,1,3,1,3,1,0,0,0,0,0,1,1
1,1,3,0,0,0,3,1,1,1,1,1,3,0,0,0,3,1,1
1,3,2,3,0,3,2,3,1,1,1,3,2,3,0,3,2,3,1
1,1,3,1,1,1,3,1,1,1,1,1,3,1,1,1,3,1,1
1,1,1,1,1,1,1,1,1,1,1,1,1,1,1,1,1,1,1
endlayer

layer
1,1,1,1,1,1,1,1,1,1,1,1,1,1,1,1,1,1,1
1,1,3,1,1,1,3,1,1,1,1,1,3,1,1,1,3,1,1
1,3,2,3,0,3,2,3,1,1,1,3,2,3,0,3,2,3,1
1,1,3,0,0,0,3,1,1,1,1,1,3,0,0,0,3,1,1
1,1,0,0,0,0,0,1,1,1,1,1,0,0,0,0,0,1,1
1,1,3,0,0,0,2,0,0,0,0,0,3,0,0,0,3,1,1
1,3,2,3,0,3,2,3,0,0,0,3,2,2,0,3,2,3,1
1,1,3,1,1,0,3,0,0,0,0,0,3,0,1,1,3,1,1
1,1,1,1,1,0,0,0,0,0,0,0,0,0,1,1,1,1,1
1,1,1,1,1,0,0,0,0,0,0,0,0,0,1,1,1,1,1
1,1,1,1,1,0,0,0,0,0,0,0,0,0,1,1,1,1,1
1,1,3,1,1,0,3,0,0,0,0,0,3,0,1,1,3,1,1
1,3,2,3,0,2,2,3,0,0,0,3,2,3,0,3,2,3,1
1,1,3,0,0,0,3,0,0,0,0,0,2,0,0,0,3,1,1
1,1,0,0,0,0,0,1,1,1,1,1,0,0,0,0,0,1,1
1,1,3,0,0,0,3,1,1,1,1,1,3,0,0,0,3,1,1
1,3,2,3,0,3,2,3,1,1,1,3,2,3,0,3,2,3,1
1,1,3,1,1,1,3,1,1,1,1,1,3,1,1,1,3,1,1
1,1,1,1,1,1,1,1,1,1,1,1,1,1,1,1,1,1,1
endlayer

layer
1,1,1,1,1,1,1,1,1,1,1,1,1,1,1,1,1,1,1
1,1,3,1,1,1,3,1,1,1,1,1,3,1,1,1,3,1,1
1,3,2,3,2,3,2,3,1,1,1,3,2,3,2,3,2,3,1
1,1,3,0,0,0,3,1,1,1,1,1,3,0,0,0,3,1,1
1,1,2,0,0,0,2,1,1,1,1,1,2,0,0,0,2,1,1
1,1,3,0,0,0,3,0,0,0,0,0,3,0,0,0,3,1,1
1,3,2,3,2,3,2,3,0,0,0,3,2,3,2,3,2,3,1
1,1,3,1,1,0,3,0,0,0,0,0,3,0,1,1,3,1,1
1,1,1,1,1,0,0,0,0,0,0,0,0,0,1,1,1,1,1
1,1,1,1,1,0,0,0,0,0,0,0,0,0,1,1,1,1,1
1,1,1,1,1,0,0,0,0,0,0,0,0,0,1,1,1,1,1
1,1,3,1,1,0,3,0,0,0,0,0,3,0,1,1,3,1,1
1,3,2,3,2,3,2,3,0,0,0,3,2,3,2,3,2,3,1
1,1,3,0,0,0,3,0,0,0,0,0,3,0,0,0,3,1,1
1,1,2,0,0,0,2,1,1,1,1,1,2,0,0,0,2,1,1
1,1,3,0,0,0,3,1,1,1,1,1,3,0,0,0,3,1,1
1,3,2,3,2,3,2,3,1,1,1,3,2,3,2,3,2,3,1
1,1,3,1,1,1,3,1,1,1,1,1,3,1,1,1,3,1,1
1,1,1,1,1,1,1,1,1,1,1,1,1,1,1,1,1,1,1
endlayer

layer
1,1,1,1,1,1,1,1,1,1,1,1,1,1,1,1,1,1,1
1,1,3,1,1,1,3,1,1,1,1,1,3,1,1,1,3,1,1
1,3,2,3,3,3,2,3,1,1,1,3,2,3,3,3,2,3,1
1,1,3,2,2,2,3,1,1,1,1,1,3,2,2,2,3,1,1
1,1,3,2,2,2,3,1,1,1,1,1,3,2,2,2,3,1,1
1,1,3,2,2,2,3,0,0,0,0,0,3,2,2,2,3,1,1
1,3,2,3,3,3,2,3,0,0,0,3,2,3,3,3,2,3,1
1,1,3,1,1,0,3,0,0,0,0,0,3,0,1,1,3,1,1
1,1,1,1,1,0,0,0,0,0,0,0,0,0,1,1,1,1,1
1,1,1,1,1,0,0,0,0,0,0,0,0,0,1,1,1,1,1
1,1,1,1,1,0,0,0,0,0,0,0,0,0,1,1,1,1,1
1,1,3,1,1,0,3,0,0,0,0,0,3,0,1,1,3,1,1
1,3,2,3,3,3,2,3,0,0,0,3,2,3,3,3,2,3,1
1,1,3,2,2,2,3,0,0,0,0,0,3,2,2,2,3,1,1
1,1,3,2,2,2,3,1,1,1,1,1,3,2,2,2,3,1,1
1,1,3,2,2,2,3,1,1,1,1,1,3,2,2,2,3,1,1
1,3,2,3,3,3,2,3,1,1,1,3,2,3,3,3,2,3,1
1,1,3,1,1,1,3,1,1,1,1,1,3,1,1,1,3,1,1
1,1,1,1,1,1,1,1,1,1,1,1,1,1,1,1,1,1,1
endlayer

layer
1,1,1,1,1,1,1,1,1,1,1,1,1,1,1,1,1,1,1
1,1,3,1,1,1,3,1,1,1,1,1,3,1,1,1,3,1,1
1,3,3,0,3,0,3,3,1,1,1,3,3,0,3,0,3,3,1
1,1,0,0,0,0,0,1,1,1,1,1,0,0,0,0,0,1,1
1,1,3,0,7,0,3,1,1,1,1,1,3,0,7,0,3,1,1
1,1,0,0,0,0,0,0,0,0,0,0,0,0,23,0,0,1,1
1,3,3,0,3,0,3,3,0,0,0,3,3,0,3,0,3,3,1
1,1,3,1,1,0,3,0,0,0,0,0,3,0,1,1,3,1,1
1,1,1,1,1,0,0,0,0,0,0,0,0,0,1,1,1,1,1
1,1,1,1,1,0,0,0,0,0,0,0,0,0,1,1,1,1,1
1,1,1,1,1,0,0,0,0,0,0,0,0,0,1,1,1,1,1
1,1,3,1,1,0,3,0,0,0,0,0,3,0,1,1,3,1,1
1,3,3,0,3,0,3,3,0,0,0,3,3,0,3,0,3,3,1
1,1,0,0,0,0,0,0,0,0,0,0,0,0,0,0,0,1,1
1,1,3,0,7,0,3,1,1,1,1,1,3,0,7,0,3,1,1
1,1,0,0,0,0,0,1,1,1,1,1,0,0,0,0,0,1,1
1,3,3,0,3,0,3,3,1,1,1,3,3,0,3,0,3,3,1
1,1,3,1,1,1,3,1,1,1,1,1,3,1,1,1,3,1,1
1,1,1,1,1,1,1,1,1,1,1,1,1,1,1,1,1,1,1
endlayer

