
# Created by Ruins mod version 16.7 Ingame Parser
# authoring Player: ST753M

weight=1
embed_into_distance=0
acceptable_target_blocks=grass,dirt,stone,cobblestone,podzol,gravel,sand
unacceptable_target_blocks=flowing_water,water,flowing_lava,lava
dimensions=14,10,13
allowable_overhang=2
max_leveling=2
leveling_buffer=-1
preserve_water=0
preserve_lava=0
preserve_plants=1

biomesToSpawnIn=jungle,jungle_hills,mutated_jungle,rainforest

rule1=0,100,preserveBlock
rule2=0,100,minecraft:mossy_cobblestone-0,minecraft:cobblestone-0
rule3=0,100,minecraft:stone_stairs-6
rule4=0,100,minecraft:stone_stairs-0
rule5=0,100,minecraft:stone_stairs-3
rule6=0,100,minecraft:stone_stairs-7
rule7=0,100,minecraft:stone_stairs-1
rule8=0,100,minecraft:stone_stairs-2
rule9=0,100,minecraft:stone_stairs-4
rule10=0,100,minecraft:stone_stairs-5
rule11=0,100,minecraft:cobblestone_wall-1
rule12=0,20,ChestGenHook:chests/jungle_temple:5-3,ChestGenHook:chests/jungle_temple:3-3,IInventory;minecraft:chest;minecraft:fish#2#0#0+minecraft:bone#4#0#3+minecraft:tallgrass#2#2#4+minecraft:spawn_egg#{EntityTag:{id:"minecraft:ocelot"}}#0#6+minecraft:emerald#2#0#10+minecraft:tallgrass#2#2#17+minecraft:fish#3#0#21+minecraft:string#4#0#23+minecraft:emerald#1#0#24-3,IInventory;minecraft:chest;minecraft:vine#3#0#2+minecraft:string#1#0#5+minecraft:bone#1#0#7+minecraft:fish#2#0#9+minecraft:record_cat#1#0#10+minecraft:string#2#0#13+minecraft:double_plant#6#3#16+minecraft:vine#2#0#22+minecraft:spawn_egg#{EntityTag:{id:"minecraft:ocelot"}}#0#24+minecraft:fish#1#0#25-3,IInventory;minecraft:chest;minecraft:double_plant#1#3#1+minecraft:string#2#0#3+minecraft:potion#{Potion:"minecraft:leaping"}#0#4+minecraft:bone#3#0#7+minecraft:string#2#0#9+minecraft:enchanted_book#{StoredEnchantments:[{lvl:3s,id:2s}]}#0#11+minecraft:double_plant#3#3#14+minecraft:double_plant#2#3#17+minecraft:fish#3#0#19+minecraft:double_plant#2#3#21+minecraft:string#1#0#24+minecraft:spawn_egg#{EntityTag:{id:"minecraft:ocelot"}}#0#25-3

layer
1,1,1,1,2,2,2,2,1,1,1,1,1
1,1,1,1,1,2,2,2,2,1,1,1,1
1,2,2,2,1,1,2,2,2,2,1,1,1
1,2,2,1,1,1,2,2,2,2,1,1,1
1,1,1,1,1,1,2,2,2,2,2,3,1
1,1,1,1,1,1,2,2,2,2,2,3,1
1,2,2,1,1,1,2,2,2,2,1,1,1
1,2,2,2,1,1,2,2,2,2,1,1,1
1,1,1,1,1,2,2,2,2,1,1,1,1
1,1,1,1,2,2,2,2,1,1,1,1,1
endlayer

layer
1,1,1,1,1,1,2,2,2,1,1,1,1
1,1,1,1,1,1,2,2,2,2,1,1,1
1,1,2,2,1,1,2,2,2,2,1,1,1
1,1,1,1,1,2,2,2,2,2,2,1,1
1,1,1,1,1,2,2,2,2,2,2,2,3
1,1,1,1,1,2,2,2,2,2,2,2,3
1,1,1,1,1,2,2,2,2,2,2,1,1
1,1,2,2,1,1,2,2,2,2,1,1,1
1,1,1,1,1,1,2,2,2,2,1,1,1
1,1,1,1,1,1,2,2,2,1,1,1,1
endlayer

layer
1,1,1,1,1,1,5,2,4,1,1,1,1
1,1,1,1,1,1,2,2,2,2,1,1,1
1,1,2,2,1,1,2,2,2,2,1,1,1
1,1,1,1,1,2,2,2,2,2,4,1,1
1,1,1,1,6,2,2,2,2,2,2,2,2
1,1,1,1,6,2,2,2,2,2,2,2,2
1,1,1,1,1,2,2,2,2,2,7,1,1
1,1,2,2,1,1,2,2,2,2,1,1,1
1,1,1,1,1,1,2,2,2,2,1,1,1
1,1,1,1,1,1,5,2,7,1,1,1,1
endlayer

layer
1,1,1,1,1,1,1,1,1,1,1,1,1
1,1,1,1,1,1,1,2,2,1,1,1,1
1,1,2,2,1,1,5,2,2,1,1,1,1
1,1,2,1,1,2,2,2,2,4,1,1,1
1,1,1,1,2,2,2,2,2,2,1,2,2
1,1,1,1,2,2,2,2,2,2,1,2,2
1,1,2,1,1,2,2,2,2,7,1,1,1
1,1,2,2,1,1,5,2,2,1,1,1,1
1,1,1,1,1,1,1,2,2,1,1,1,1
1,1,1,1,1,1,1,1,1,1,1,1,1
endlayer

layer
1,1,1,1,1,1,1,1,1,1,1,1,1
1,1,1,1,1,1,1,1,1,1,1,1,1
1,1,2,2,2,1,1,4,4,1,1,1,1
1,1,2,2,2,2,2,2,8,1,1,1,1
1,1,1,2,2,2,2,2,2,1,1,2,2
1,1,1,2,2,2,2,2,2,1,1,7,8
1,1,2,2,2,2,2,2,8,1,1,1,1
1,1,2,2,2,1,1,7,7,1,1,1,1
1,1,1,1,1,1,1,1,1,1,1,1,1
1,1,1,1,1,1,1,1,1,1,1,1,1
endlayer

layer
1,1,1,1,1,1,1,1,1,1,1,1,1
1,1,1,1,1,1,1,1,1,1,1,1,1
1,1,2,2,2,1,1,1,1,1,1,1,1
1,1,2,2,2,2,2,8,1,1,2,2,1
1,1,2,2,2,2,2,2,8,1,2,2,8
1,1,2,2,2,2,2,2,8,1,1,1,1
1,1,2,2,2,2,2,8,1,1,1,1,1
1,1,2,2,2,1,1,1,1,1,1,1,1
1,1,1,1,1,1,1,1,1,1,1,1,1
1,1,1,1,1,1,1,1,1,1,1,1,1
endlayer

layer
1,1,1,1,1,1,1,1,1,1,1,1,1
1,1,1,1,1,1,1,1,1,1,1,1,1
1,1,1,4,4,1,1,1,1,1,2,9,1
1,1,2,2,2,2,8,1,1,1,2,2,1
1,1,2,2,2,2,2,8,1,1,7,7,1
1,1,2,2,2,2,2,8,1,1,1,1,1
1,1,2,2,2,2,8,1,1,1,1,1,1
1,1,1,7,7,1,1,1,1,1,1,1,1
1,1,1,1,1,1,1,1,1,1,1,1,1
1,1,1,1,1,1,1,1,1,1,1,1,1
endlayer

layer
1,1,1,1,1,1,1,1,1,1,1,1,1
1,1,1,1,1,1,1,1,1,1,1,1,1
1,1,1,1,1,1,1,1,1,9,2,2,1
1,1,1,1,1,1,1,1,1,2,2,2,1
1,1,2,2,2,2,8,1,1,1,1,1,1
1,1,2,2,2,2,8,1,1,1,1,1,1
1,1,1,1,1,1,1,1,1,1,1,1,1
1,1,1,1,1,1,1,1,1,1,1,1,1
1,1,1,1,1,1,1,1,1,1,1,1,1
1,1,1,1,1,1,1,1,1,1,1,1,1
endlayer

layer
1,1,1,1,1,1,1,1,1,1,1,1,1
1,1,1,1,1,1,1,1,1,1,1,1,1
1,1,1,1,1,1,1,1,1,2,2,8,1
1,9,2,9,1,1,1,1,1,2,2,8,1
2,2,2,2,1,1,1,1,1,1,10,1,1
2,2,2,2,1,1,1,1,1,1,1,1,1
1,10,2,10,1,1,1,1,1,1,1,1,1
1,1,1,1,1,1,1,1,1,1,1,1,1
1,1,1,1,1,1,1,1,1,1,1,1,1
1,1,1,1,1,1,1,1,1,1,1,1,1
endlayer

layer
1,1,1,1,1,1,1,1,1,1,1,1,1
1,1,1,1,1,1,1,1,1,1,1,1,1
1,1,1,1,1,1,1,1,1,4,2,1,1
1,11,2,2,1,1,1,1,1,2,2,1,1
5,0,0,12,3,1,1,1,1,2,2,1,1
5,0,0,12,3,1,1,1,1,10,1,1,1
1,11,2,2,1,1,1,1,1,1,1,1,1
1,1,1,1,1,1,1,1,1,1,1,1,1
1,1,1,1,1,1,1,1,1,1,1,1,1
1,1,1,1,1,1,1,1,1,1,1,1,1
endlayer

layer
1,1,1,1,1,1,1,1,1,1,1,1,1
1,1,1,1,1,1,1,1,1,1,1,1,1
1,1,6,9,1,1,1,1,1,0,4,1,1
1,2,2,2,1,1,1,1,1,2,2,1,1
1,2,0,0,2,1,1,1,9,2,7,1,1
1,2,0,0,2,1,1,1,2,2,1,1,1
1,2,2,2,1,1,1,1,1,1,1,1,1
1,1,6,10,1,1,1,1,9,9,1,1,1
1,1,1,1,1,1,1,1,2,2,1,1,1
1,1,1,1,1,1,1,1,2,2,1,1,1
endlayer

layer
1,1,1,1,1,1,1,1,1,1,1,1,1
1,1,1,1,1,1,1,1,1,1,1,1,1
1,1,4,2,1,1,1,1,1,1,1,1,1
1,1,2,2,1,1,1,1,1,4,1,1,1
1,5,2,2,8,1,1,1,2,2,1,1,1
1,5,2,2,8,1,1,1,2,2,1,1,1
1,1,2,2,1,1,1,1,2,2,1,1,1
1,1,7,2,1,1,1,1,2,2,1,1,1
1,1,1,1,1,1,1,1,2,2,1,1,1
1,1,1,1,1,1,1,1,7,7,1,1,1
endlayer

layer
1,1,1,1,1,1,1,1,1,1,1,1,1
1,1,1,1,1,1,1,1,1,1,1,1,1
1,1,1,2,1,1,1,1,1,1,1,1,1
1,1,5,7,1,1,1,1,1,1,1,1,1
1,1,1,1,1,1,1,1,4,4,1,1,1
1,1,1,1,1,1,1,1,2,2,1,1,1
1,1,5,4,1,1,1,1,2,2,1,1,1
1,1,1,2,1,1,1,1,7,7,1,1,1
1,1,1,1,1,1,1,1,1,1,1,1,1
1,1,1,1,1,1,1,1,1,1,1,1,1
endlayer

layer
1,1,1,1,1,1,1,1,1,1,1,1,1
1,1,1,1,1,1,1,1,1,1,1,1,1
1,1,1,7,1,1,1,1,1,1,1,1,1
1,1,1,1,1,1,1,1,1,1,1,1,1
1,1,1,1,1,1,1,1,1,1,1,1,1
1,1,1,1,1,1,1,1,1,1,1,1,1
1,1,1,1,1,1,1,1,1,1,1,1,1
1,1,1,4,1,1,1,1,1,1,1,1,1
1,1,1,1,1,1,1,1,1,1,1,1,1
1,1,1,1,1,1,1,1,1,1,1,1,1
endlayer

