
# Created by Ruins mod version 17.0 Ingame Parser
# authoring Player: ST753M

# In optional because I think I can do a better job at this later.

weight=1
uniqueMinDistance=1000
spawnMinDistance=500
embed_into_distance=11
acceptable_target_blocks=
unacceptable_target_blocks=flowing_water,water,flowing_lava,lava,ice,bedrock,netherrack,nether_brick,nether_brick_fence,soul_sand,quartz_ore,end_stone,obsidian,iron_bars,Natura:Cloud,slime_grass,slime_congealed,slime_dirt,clouds,natura:clouds
dimensions=17,10,10
allowable_overhang=10
max_leveling=-1
leveling_buffer=0
preserve_water=1
preserve_lava=1

biomesToSpawnIn=jungle_edge,dead_swamp,mutated_swampland,coralium_infested_swamp,boreal_forest,forest_hills,woodland,seasonal_forest,thicket,mutated_roofed_forest,cliffs,ominous_woods

=0,100,air
rule1=0,100,chisel:laboratory-11
rule2=0,100,chisel:laboratory-12
rule3=0,100,minecraft:quartz_stairs-2
rule4=0,100,minecraft:quartz_stairs-7
rule5=0,100,chisel:laboratory-0
rule6=0,100,chisel:iron-2

# Command Block creating a villager which sells some Chisel blocks
rule7=0,100,CommandBlock:RUINSTRIGGER /summon villager ~ ~1 ~ {Profession:1,Offers:{Recipes:[{rewardExp:0b,maxUses:30,uses:0,buy:{id:"minecraft:iron_ingot",Count:14b},sell:{id:"minecraft:emerald",Count:1b}},{rewardExp:0b,maxUses:2147483647,uses:0,buy:{id:"minecraft:emerald",Count:1b},sell:{id:"chisel:factory",Count:32b}},{rewardExp:0b,maxUses:2147483647,uses:0,buy:{id:"minecraft:emerald",Count:1b},sell:{id:"chisel:laboratory",Count:32b}},{rewardExp:0b,maxUses:2147483647,uses:0,buy:{id:"minecraft:emerald",Count:1b},sell:{id:"chisel:chisel_iron",Count:1b}}]},PersistenceRequired:1}:@-1

# Small treasure hopper
rule8=0,100,IInventory;minecraft:hopper;minecraft:potion#{Potion:"minecraft:strong_healing"}#0#0+minecraft:redstone#7#0#2+minecraft:minecart#1#0#4-0,IInventory;minecraft:hopper;minecraft:redstone#7#0#0+minecraft:potion#{Potion:"minecraft:long_poison"}#0#1+minecraft:minecart#1#0#3-0,IInventory;minecraft:hopper;minecraft:potion#{Potion:"minecraft:long_swiftness"}#0#0+minecraft:bucket#1#0#1+minecraft:redstone#7#0#3+minecraft:bucket#1#0#4-0,IInventory;minecraft:hopper;minecraft:redstone#7#0#1+minecraft:potion#{Potion:"minecraft:regeneration"}#0#2+minecraft:enchanted_book#{StoredEnchantments:[{lvl:1s,id:33s}]}#0#3-0,IInventory;minecraft:hopper;minecraft:minecart#1#0#1+minecraft:potion#{Potion:"minecraft:long_water_breathing"}#0#2+minecraft:redstone#7#0#4-0,IInventory;minecraft:hopper;minecraft:redstone#7#0#0+minecraft:potion#{Potion:"minecraft:long_swiftness"}#0#1+minecraft:bucket#2#0#2-0,IInventory;minecraft:hopper;minecraft:iron_ingot#4#0#1+minecraft:redstone#8#0#3+minecraft:potion#{Potion:"minecraft:long_leaping"}#0#4-0,IInventory;minecraft:hopper;minecraft:redstone#7#0#1+minecraft:potion#{Potion:"minecraft:strong_leaping"}#0#2+minecraft:iron_ingot#4#0#3-0,IInventory;minecraft:hopper;minecraft:potion#{Potion:"minecraft:long_strength"}#0#0+minecraft:iron_ingot#4#0#1+minecraft:redstone#7#0#2-0

rule9=0,100,minecraft:furnace-2
rule10=0,100,minecraft:brewing_stand-0
rule11=0,100,chisel:technical-4

# 2 command blocks, to spawn normal iron golems
rule12=0,100,CommandBlock:RUINSTRIGGER /summon villager_golem ~ ~1 ~:@-0

rule13=0,100,minecraft:quartz_stairs-6
rule14=0,100,minecraft:quartz_stairs-3
rule15=0,100,preserveBlock
rule16=0,100,minecraft:iron_door-3
rule17=0,100,minecraft:iron_door-1
rule18=2,100,minecraft:stone_button-3
rule19=2,100,minecraft:stone_button-4
rule20=0,100,minecraft:iron_door-8
rule21=0,100,minecraft:iron_door-9
rule22=0,100,minecraft:stone_slab-0

layer
1,1,1,1,1,1,1,1,1,1
1,1,1,1,1,2,1,1,1,1
1,1,2,1,2,1,2,1,2,1
1,2,1,2,1,2,1,2,1,1
1,1,2,1,2,1,2,1,2,1
1,2,1,2,1,2,1,2,1,1
1,1,2,1,2,1,2,1,2,1
1,2,1,2,1,2,1,2,1,1
1,1,1,1,1,1,1,1,1,1
1,1,1,1,1,1,1,1,1,1
endlayer

layer
2,2,2,2,2,2,2,2,2,2
2,5,5,5,0,0,4,3,0,2
2,0,0,0,0,0,0,0,0,2
2,6,0,0,0,0,0,0,0,2
2,6,0,0,7,0,0,0,0,2
2,0,0,0,0,0,0,0,0,2
2,0,0,0,0,0,0,8,0,2
2,0,0,0,0,0,0,0,0,2
2,5,5,5,5,5,5,5,5,2
2,2,2,2,2,2,2,2,2,2
endlayer

layer
1,1,1,1,1,1,1,1,1,1
1,0,0,0,0,4,3,0,0,1
1,0,0,0,0,0,0,0,0,1
1,9,0,0,0,0,0,0,0,1
1,9,0,0,0,0,0,0,0,1
1,0,0,0,0,0,0,0,0,1
1,0,0,0,0,0,0,0,0,1
1,0,0,0,0,0,0,0,0,1
1,0,0,0,10,0,0,0,0,1
1,1,1,1,1,1,1,1,1,1
endlayer

layer
1,1,1,11,1,1,11,1,1,1
1,0,0,0,4,3,0,0,0,1
1,0,0,0,0,0,0,0,0,1
11,0,0,0,0,0,0,0,0,11
1,0,0,0,0,0,0,0,0,1
1,0,0,0,0,0,0,0,0,1
11,0,0,0,0,0,0,0,0,11
1,0,0,0,0,0,0,0,0,1
1,0,0,0,0,0,0,0,0,1
1,1,1,11,1,1,11,1,1,1
endlayer

layer
2,2,2,2,2,2,2,2,2,2
2,0,0,4,3,0,0,0,0,2
2,0,0,0,0,0,0,0,0,2
2,0,0,0,0,12,12,0,0,2
2,0,0,0,0,0,0,0,0,2
2,0,0,0,0,0,0,0,0,2
2,0,0,0,0,0,0,0,0,2
2,0,0,0,0,0,0,0,0,2
2,0,0,0,0,0,0,0,0,2
2,2,2,2,2,2,2,2,2,2
endlayer

layer
1,1,1,1,1,1,1,1,1,1
1,1,1,3,0,0,0,0,0,1
1,1,1,0,0,0,0,0,0,1
1,1,1,0,0,0,0,0,0,1
1,1,1,0,0,0,0,0,0,1
1,1,1,1,1,1,1,1,1,1
1,1,1,1,1,1,1,1,1,1
1,1,1,1,1,1,1,1,1,1
1,1,1,1,1,1,1,1,1,1
1,1,1,1,1,1,1,1,1,1
endlayer

layer
2,2,2,2,2,2,2,2,2,2
2,0,0,0,0,0,0,0,0,2
2,0,0,0,0,0,0,0,0,2
2,0,0,0,0,0,0,0,0,2
2,0,14,13,0,0,0,0,0,2
2,2,2,2,2,2,2,2,2,2
15,15,15,15,5,5,15,15,15,15
15,15,15,15,5,5,15,15,15,15
15,15,15,15,15,15,15,15,15,15
15,15,15,15,15,15,15,15,15,15
endlayer

layer
1,1,1,1,1,1,1,1,1,1
1,0,0,0,0,0,0,0,0,1
1,0,0,0,0,0,0,0,0,1
1,0,0,0,0,0,0,0,0,1
1,0,0,14,13,0,0,0,0,1
1,1,1,1,1,1,1,1,1,1
15,15,15,15,5,5,15,15,15,15
15,15,15,15,5,5,15,15,15,15
15,15,15,15,15,15,15,15,15,15
15,15,15,15,15,15,15,15,15,15
endlayer

layer
1,1,1,11,1,1,11,1,1,1
1,0,0,0,0,0,0,0,0,1
1,0,0,0,0,0,0,0,0,1
1,0,0,0,0,0,0,0,0,1
1,0,0,0,14,13,0,0,0,1
1,1,1,11,1,1,11,1,1,1
15,15,15,15,5,5,15,15,15,15
15,15,15,15,5,5,15,15,15,15
15,15,15,15,15,15,15,15,15,15
15,15,15,15,15,15,15,15,15,15
endlayer

layer
2,2,2,2,2,2,2,2,2,2
2,0,0,0,0,0,0,0,0,2
2,0,0,0,0,0,0,0,0,2
2,0,0,0,0,0,0,0,0,2
2,0,0,0,0,14,13,0,0,2
2,2,2,2,2,2,2,2,2,2
15,15,15,15,5,5,15,15,15,15
15,15,15,15,5,5,15,15,15,15
15,15,15,15,15,15,15,15,15,15
15,15,15,15,15,15,15,15,15,15
endlayer

layer
1,1,1,1,1,1,1,1,1,1
1,1,1,1,1,1,1,1,1,1
1,1,1,1,1,1,1,1,1,1
1,1,1,1,1,1,1,1,1,1
1,1,1,0,0,0,14,1,1,1
1,1,1,1,1,1,1,1,1,1
15,15,15,15,5,5,15,15,15,15
15,15,15,15,5,5,15,15,15,15
15,15,15,15,15,15,15,15,15,15
15,15,15,15,15,15,15,15,15,15
endlayer

layer
2,2,2,2,2,2,2,2,2,2
2,0,0,0,0,0,0,0,0,2
17,0,0,0,0,0,0,0,0,16
17,0,0,0,0,0,0,0,0,16
2,0,0,0,0,0,0,0,0,2
2,2,2,2,2,2,2,2,2,2
15,15,15,15,5,5,15,15,15,15
15,15,15,15,5,5,15,15,15,15
15,15,15,15,15,15,15,15,15,15
15,15,15,15,15,15,15,15,15,15
endlayer

layer
1,1,1,1,1,1,1,1,1,1
1,19,0,0,0,0,0,0,18,1
21,0,0,0,0,0,0,0,0,20
20,0,0,0,0,0,0,0,0,21
1,19,0,0,0,0,0,0,18,1
1,1,1,1,1,1,1,1,1,1
15,15,15,15,5,5,15,15,15,15
15,15,15,15,5,5,15,15,15,15
15,15,15,15,15,15,15,15,15,15
15,15,15,15,15,15,15,15,15,15
endlayer

layer
1,1,1,11,1,1,11,1,1,1
1,0,0,0,0,0,0,0,0,1
1,0,0,0,0,0,0,0,0,1
1,0,0,0,0,0,0,0,0,1
1,0,0,0,0,0,0,0,0,1
1,1,1,11,1,1,11,1,1,1
15,15,15,15,5,5,15,15,15,15
15,15,15,15,5,5,15,15,15,15
15,15,15,15,15,15,15,15,15,15
15,15,15,15,15,15,15,15,15,15
endlayer

layer
2,2,2,2,2,2,2,2,2,2
2,0,0,0,0,0,0,0,0,2
2,0,0,0,0,0,0,0,0,2
2,0,0,0,0,0,0,0,0,2
2,0,0,0,0,0,0,0,0,2
2,2,2,2,2,2,2,2,2,2
15,15,15,15,5,5,15,15,15,15
15,15,15,15,5,5,15,15,15,15
15,15,15,15,15,15,15,15,15,15
15,15,15,15,15,15,15,15,15,15
endlayer

layer
1,1,1,1,1,1,1,1,1,1
1,1,1,1,1,1,1,1,1,1
1,1,1,1,1,1,1,1,1,1
1,1,1,1,1,1,1,1,1,1
1,1,1,1,1,1,1,1,1,1
1,1,1,1,1,1,1,1,1,1
15,15,15,15,5,5,15,15,15,15
15,15,15,15,5,5,15,15,15,15
15,15,15,15,15,15,15,15,15,15
15,15,15,15,15,15,15,15,15,15
endlayer

layer
22,22,22,22,22,22,22,22,22,22
22,15,15,15,15,15,15,15,15,22
22,15,11,15,15,15,15,11,15,22
22,15,11,15,15,15,15,11,15,22
22,15,15,15,15,15,15,15,15,22
22,22,22,22,22,22,22,22,22,22
15,15,15,15,5,5,15,15,15,15
15,15,15,15,5,5,15,15,15,15
15,15,15,15,15,15,15,15,15,15
15,15,15,15,15,15,15,15,15,15
endlayer

