
# Created by Ruins mod version 17.0 Ingame Parser
# authoring Player: ST753M

weight=1
embed_into_distance=7
acceptable_target_blocks=
unacceptable_target_blocks=flowing_water,water,flowing_lava,lava,ice,bedrock,netherrack,nether_brick,nether_brick_fence,soul_sand,quartz_ore,end_stone,obsidian,iron_bars,Natura:Cloud,slime_grass,slime_congealed,slime_dirt,clouds,natura:clouds
dimensions=24,19,19
allowable_overhang=7
uniqueMinDistance=1000
max_leveling=0
leveling_buffer=-1
preserve_water=0
preserve_lava=0

biomesToSpawnIn=jungle,jungle_hills,tropical_rainforest,mutated_jungle,mutated_jungle_edge,bamboo_forest,boreal_forest,forest_hills,temperate_rainforest,forested_hills,lush_hills,thicket,taiga,taiga_hills,mutated_redwood_taiga,mutated_redwood_taiga_hills,redwood_taiga,mutated_taiga,redwood_taiga_hills,redwood_forest,coniferous_forest,autumnal_wooded_hills

=0,100,air
rule1=0,100,preserveBlock

rule2=0,100,minecraft:stonebrick-0,minecraft:monster_egg-3,minecraft:monster_egg-4,minecraft:stonebrick-1,minecraft:stonebrick-2,minecraft:stone-0,minecraft:monster_egg-2,minecraft:stonebrick-0,minecraft:monster_egg-3,minecraft:monster_egg-4,minecraft:stonebrick-1,minecraft:stonebrick-2,minecraft:stone-0,minecraft:monster_egg-2,minecraft:stonebrick-0,minecraft:monster_egg-3,minecraft:monster_egg-4,minecraft:stonebrick-1,minecraft:stonebrick-2,minecraft:stone-0,minecraft:monster_egg-2,minecraft:stone_brick_stairs-1,minecraft:stone_brick_stairs-3,minecraft:stone_brick_stairs-7,minecraft:stone_brick_stairs-5

rule3=0,100,minecraft:stonebrick-3
rule4=0,100,minecraft:stone_brick_stairs-3
rule5=0,100,minecraft:stone_brick_stairs-2
rule6=0,100,minecraft:stone_brick_stairs-1
rule7=0,100,ChestGenHook:chests/simple_dungeon:2-3,air
rule8=0,100,minecraft:stone_brick_stairs-0
rule9=0,100,ChestGenHook:chests/simple_dungeon:2-5,air
rule10=0,100,ChestGenHook:chests/simple_dungeon:2-4,air
rule11=0,100,minecraft:stone_brick_stairs-5
rule12=0,100,minecraft:stone_brick_stairs-7
rule13=0,100,minecraft:stone_brick_stairs-6
rule14=0,100,minecraft:web-0
^0,100,air
rule15=0,100,minecraft:stone_slab-13
rule16=0,100,minecraft:stone_brick_stairs-4
rule17=0,70,MobSpawner:skeleton,MobSpawner:zombie,MobSpawner:cave_spider
rule18=0,100,minecraft:stone_slab-5
rule19=1,100,minecraft:torch-5

layer
1,1,1,1,1,1,2,2,2,2,2,2,2,1,1,1,1,1,1
1,1,1,1,1,2,2,2,2,2,2,2,2,2,1,1,1,1,1
1,1,1,1,2,2,2,2,2,2,2,2,2,2,2,1,1,1,1
1,1,1,2,2,2,2,2,3,2,3,2,2,2,2,2,1,1,1
1,1,2,2,2,2,2,2,2,2,2,2,2,2,2,2,2,1,1
1,2,2,2,2,2,2,2,3,2,3,2,2,2,2,2,2,2,1
2,2,2,2,2,2,2,2,2,2,2,2,2,2,2,2,2,2,2
2,2,2,2,2,2,2,2,2,2,2,2,2,2,2,2,2,2,2
2,2,2,3,2,3,2,2,2,2,2,2,2,3,2,3,2,2,2
2,2,2,2,2,2,2,2,2,2,2,2,2,2,2,2,2,2,2
2,2,2,3,2,3,2,2,2,2,2,2,2,3,2,3,2,2,2
2,2,2,2,2,2,2,2,2,2,2,2,2,2,2,2,2,2,2
2,2,2,2,2,2,2,2,2,2,2,2,2,2,2,2,2,2,2
1,2,2,2,2,2,2,2,3,2,3,2,2,2,2,2,2,2,1
1,1,2,2,2,2,2,2,2,2,2,2,2,2,2,2,2,1,1
1,1,1,2,2,2,2,2,3,2,3,2,2,2,2,2,1,1,1
1,1,1,1,2,2,2,2,2,2,2,2,2,2,2,1,1,1,1
1,1,1,1,1,2,2,2,2,2,2,2,2,2,1,1,1,1,1
1,1,1,1,1,1,2,2,2,2,2,2,2,1,1,1,1,1,1
endlayer

layer
1,1,1,1,1,1,2,2,2,2,2,2,2,1,1,1,1,1,1
1,1,1,1,1,2,2,2,5,0,4,2,2,2,1,1,1,1,1
1,1,1,1,2,2,2,0,0,0,0,0,2,2,2,1,1,1,1
1,1,1,2,2,2,6,0,0,0,0,0,6,2,2,2,1,1,1
1,1,2,2,2,2,0,0,0,0,0,0,7,2,2,2,2,1,1
1,2,2,2,2,2,8,0,0,0,0,0,8,2,2,2,2,2,1
2,2,2,5,9,4,2,0,0,0,0,0,2,5,0,4,2,2,2
2,2,0,0,0,0,0,2,2,0,2,2,0,0,0,0,0,2,2
2,6,0,0,0,0,0,2,2,0,2,2,0,0,0,0,0,6,2
2,0,0,0,0,0,0,0,0,0,0,0,0,0,0,0,0,0,2
2,8,0,0,0,0,0,2,2,0,2,2,0,0,0,0,0,8,2
2,2,0,0,0,0,0,2,2,0,2,2,0,0,0,0,0,2,2
2,2,2,5,0,4,2,0,0,0,0,0,2,5,10,4,2,2,2
1,2,2,2,2,2,2,0,0,0,0,0,6,2,2,2,2,2,1
1,1,2,2,2,2,2,0,0,0,0,0,0,2,2,2,2,1,1
1,1,1,2,2,2,5,0,0,0,0,0,8,2,2,2,1,1,1
1,1,1,1,2,2,2,0,0,0,0,0,2,2,2,1,1,1,1
1,1,1,1,1,2,2,2,5,0,4,2,2,2,1,1,1,1,1
1,1,1,1,1,1,2,2,2,2,2,2,2,1,1,1,1,1,1
endlayer

layer
1,1,1,1,1,1,2,2,2,2,2,2,2,1,1,1,1,1,1
1,1,1,1,1,2,2,2,0,0,0,2,2,2,1,1,1,1,1
1,1,1,1,2,2,2,0,0,0,0,0,2,2,2,1,1,1,1
1,1,1,2,2,2,0,0,0,0,0,0,0,2,2,2,1,1,1
1,1,2,2,2,2,0,0,0,0,0,0,0,2,2,2,2,1,1
1,2,2,2,2,2,0,0,0,0,0,0,0,2,2,2,2,2,1
2,2,2,0,0,0,2,0,0,0,0,0,2,0,0,0,2,2,2
2,2,0,0,0,0,0,2,2,0,2,2,0,0,0,0,0,2,2
2,0,0,0,0,0,0,2,2,0,2,2,0,0,0,0,0,0,2
2,0,0,0,0,0,0,0,0,0,0,0,0,0,0,0,0,0,2
2,0,0,0,0,0,0,2,2,0,2,2,0,0,0,0,0,0,2
2,2,0,0,0,0,0,2,2,0,2,2,0,0,0,0,0,2,2
2,2,2,0,0,0,2,0,0,0,0,0,2,0,0,0,2,2,2
1,2,2,2,2,2,2,0,0,0,0,0,0,2,2,2,2,2,1
1,1,2,2,2,2,2,0,0,0,0,0,0,2,2,2,2,1,1
1,1,1,2,2,5,0,0,0,0,0,0,0,2,2,2,1,1,1
1,1,1,1,2,2,2,0,0,0,0,0,2,2,2,1,1,1,1
1,1,1,1,1,2,2,2,0,0,0,2,2,2,1,1,1,1,1
1,1,1,1,1,1,2,2,2,2,2,2,2,1,1,1,1,1,1
endlayer

layer
1,1,1,1,1,1,3,2,3,2,3,2,3,1,1,1,1,1,1
1,1,1,1,1,2,2,2,11,3,11,2,2,2,1,1,1,1,1
1,1,1,1,3,2,2,0,0,0,0,0,2,2,3,1,1,1,1
1,1,1,2,2,2,13,0,0,0,0,0,12,2,2,2,1,1,1
1,1,3,2,2,2,3,0,0,0,0,0,3,2,2,2,3,1,1
1,2,2,2,2,2,13,0,0,0,0,0,12,2,2,2,2,2,1
3,2,2,11,3,11,2,0,0,0,0,0,2,11,3,11,2,2,3
2,2,14,0,0,0,0,2,2,3,2,2,0,0,0,0,0,2,2
3,13,0,0,0,0,0,2,2,11,2,2,0,0,0,0,0,12,3
2,3,0,0,0,0,0,3,13,15,12,3,0,0,0,0,0,3,2
3,13,0,0,0,0,0,2,2,16,2,2,0,0,0,0,0,12,3
2,2,0,0,0,0,0,2,2,3,2,2,0,0,0,0,14,2,2
3,2,2,16,3,16,2,0,0,0,0,0,2,16,3,16,2,2,3
1,2,2,2,2,2,3,0,0,0,0,0,12,2,2,2,2,2,1
1,1,3,2,2,6,2,0,0,0,0,0,3,2,2,2,3,1,1
1,1,1,2,2,0,0,0,0,0,0,0,12,2,2,2,1,1,1
1,1,1,1,3,2,2,0,0,0,0,0,2,2,3,1,1,1,1
1,1,1,1,1,2,2,2,16,3,16,2,2,2,1,1,1,1,1
1,1,1,1,1,1,3,2,3,2,3,2,3,1,1,1,1,1,1
endlayer

layer
1,1,1,1,1,1,2,3,2,3,2,3,2,1,1,1,1,1,1
1,1,1,1,1,3,2,2,2,2,2,2,2,3,1,1,1,1,1
1,1,1,1,2,2,2,15,0,0,0,15,2,2,2,1,1,1,1
1,1,1,3,2,2,2,0,0,0,0,0,2,2,2,3,1,1,1
1,1,2,2,2,2,2,0,0,0,0,0,2,2,2,2,2,1,1
1,3,2,2,2,2,2,14,0,0,0,0,2,2,2,2,2,3,1
2,2,2,2,2,2,2,15,14,0,0,15,2,2,2,2,2,2,2
3,2,15,0,0,0,15,2,2,2,2,2,15,0,0,0,15,2,3
2,2,0,14,0,0,0,2,2,2,2,2,0,0,0,0,0,2,2
3,2,0,0,0,0,0,2,2,17,2,2,0,0,0,0,0,2,3
2,2,0,0,0,0,0,2,2,2,2,2,0,0,0,0,0,2,2
3,2,15,0,0,0,15,2,2,2,2,2,15,0,0,14,15,2,3
2,2,2,2,2,2,2,15,0,0,0,15,2,2,2,2,2,2,2
1,3,2,2,2,2,2,0,0,0,0,0,2,2,2,2,2,3,1
1,1,2,2,5,0,2,0,0,0,0,0,2,2,2,2,2,1,1
1,1,1,3,2,0,0,0,0,0,0,0,2,2,2,3,1,1,1
1,1,1,1,2,2,2,15,0,0,0,15,2,2,2,1,1,1,1
1,1,1,1,1,3,2,2,2,2,2,2,2,3,1,1,1,1,1
1,1,1,1,1,1,2,3,2,3,2,3,2,1,1,1,1,1,1
endlayer

layer
1,1,1,1,1,1,2,2,2,2,2,2,2,1,1,1,1,1,1
1,1,1,1,1,2,2,2,2,2,2,2,2,2,1,1,1,1,1
1,1,1,1,2,2,2,2,2,2,2,2,2,2,2,1,1,1,1
1,1,1,2,2,2,2,2,15,0,15,2,2,2,2,2,1,1,1
1,1,2,2,2,2,2,2,0,0,0,2,2,2,2,2,2,1,1
1,2,2,2,2,2,2,2,15,0,15,2,2,2,2,2,2,2,1
2,2,2,2,2,2,2,2,2,2,2,2,2,2,2,2,2,2,2
2,2,2,2,2,2,2,2,2,2,2,2,2,2,2,2,2,2,2
2,2,2,15,0,15,2,2,2,2,2,2,2,15,0,15,2,2,2
2,2,2,0,0,0,2,2,2,2,2,2,2,0,0,0,2,2,2
2,2,2,15,0,15,2,2,2,2,2,2,2,15,0,15,2,2,2
2,2,2,2,2,2,2,2,2,2,2,2,2,2,2,2,2,2,2
2,2,2,2,2,2,2,2,2,2,2,2,2,2,2,2,2,2,2
1,2,2,2,6,2,2,2,15,0,15,2,2,2,2,2,2,2,1
1,1,2,2,0,0,2,2,0,0,0,2,2,2,2,2,2,1,1
1,1,1,2,2,0,12,2,15,0,15,2,2,2,2,2,1,1,1
1,1,1,1,2,2,2,2,2,2,2,2,2,2,2,1,1,1,1
1,1,1,1,1,2,2,2,2,2,2,2,2,2,1,1,1,1,1
1,1,1,1,1,1,2,2,2,2,2,2,2,1,1,1,1,1,1
endlayer

layer
1,1,1,1,1,1,2,2,2,2,2,2,2,1,1,1,1,1,1
1,1,1,1,1,2,2,2,2,2,2,2,2,2,1,1,1,1,1
1,1,1,1,2,2,2,2,2,2,2,2,2,2,2,1,1,1,1
1,1,1,2,2,2,2,2,2,2,2,2,2,2,2,2,1,1,1
1,1,2,2,2,2,2,2,2,3,2,2,2,2,2,2,2,1,1
1,2,2,2,2,3,2,2,2,2,2,2,2,3,2,2,2,2,1
2,2,2,2,2,2,2,2,2,2,2,2,2,2,2,2,2,2,2
2,2,2,2,2,2,2,2,2,2,2,2,2,2,2,2,2,2,2
2,2,2,2,2,2,2,2,2,2,2,2,2,2,2,2,2,2,2
2,2,2,2,3,2,2,2,2,3,2,2,2,2,3,2,2,2,2
2,2,2,2,2,2,2,2,2,2,2,2,2,2,2,2,2,2,2
2,2,2,2,2,2,2,2,2,2,2,2,2,2,2,2,2,2,2
2,2,2,2,2,2,2,2,2,2,2,2,2,2,2,2,2,2,2
1,2,2,5,0,3,2,2,2,2,2,2,2,3,2,2,2,2,1
1,1,2,2,0,0,2,2,2,3,2,2,2,2,2,2,2,1,1
1,1,1,2,2,16,2,2,2,2,2,2,2,2,2,2,1,1,1
1,1,1,1,2,2,2,2,2,2,2,2,2,2,2,1,1,1,1
1,1,1,1,1,2,2,2,2,2,2,2,2,2,1,1,1,1,1
1,1,1,1,1,1,2,2,2,2,2,2,2,1,1,1,1,1,1
endlayer

layer
1,1,1,1,1,1,2,0,0,0,0,0,2,1,1,1,1,1,1
1,1,1,1,1,2,5,0,0,0,0,0,4,2,1,1,1,1,1
1,1,1,1,2,2,2,0,0,0,0,0,2,2,2,1,1,1,1
1,1,1,2,2,0,0,0,0,0,0,0,0,0,2,2,1,1,1
1,1,2,2,0,0,0,0,0,0,0,0,0,0,0,2,2,1,1
1,2,2,0,0,0,0,0,0,0,0,0,0,0,0,0,2,2,1
2,6,2,0,0,0,0,0,18,18,18,0,0,0,0,0,2,6,2
0,0,0,0,0,0,0,18,0,0,0,18,0,0,0,0,0,0,0
0,0,0,0,0,0,18,0,12,16,13,0,18,0,0,0,0,0,0
0,0,0,0,0,0,18,0,12,2,13,0,18,0,0,0,0,0,0
0,0,0,0,0,0,18,0,12,11,11,0,18,0,0,0,0,0,0
0,0,0,0,0,0,0,18,0,0,0,18,0,0,0,0,0,0,0
2,8,2,0,0,0,0,0,18,18,18,0,0,0,0,0,2,8,2
1,2,2,0,0,0,0,0,0,0,0,0,0,0,0,0,2,2,1
1,1,2,2,0,0,0,0,0,0,0,0,0,0,0,2,2,1,1
1,1,1,2,2,0,0,0,0,0,0,0,0,0,2,2,1,1,1
1,1,1,1,2,2,2,0,0,0,0,0,2,2,2,1,1,1,1
1,1,1,1,1,2,5,0,0,0,0,0,4,2,1,1,1,1,1
1,1,1,1,1,1,2,0,0,0,0,0,2,1,1,1,1,1,1
endlayer

layer
1,1,1,1,1,1,2,0,0,0,0,0,2,1,1,1,1,1,1
1,1,1,1,1,2,5,0,0,0,0,0,4,2,1,1,1,1,1
1,1,1,1,2,11,2,0,0,0,0,0,2,11,2,1,1,1,1
1,1,1,2,2,0,0,0,0,0,0,0,0,0,2,2,1,1,1
1,1,2,2,0,0,0,0,0,0,0,0,0,0,0,2,2,1,1
1,2,13,0,0,0,0,0,0,0,0,0,0,0,0,0,12,2,1
2,6,2,0,0,0,0,0,0,0,0,0,0,0,0,0,2,6,2
0,0,0,0,0,0,0,0,0,16,0,0,0,0,0,0,0,0,0
0,0,0,0,0,0,0,0,0,6,0,0,0,0,0,0,0,0,0
0,0,0,0,0,0,0,12,5,2,4,13,0,0,0,0,0,0,0
0,0,0,0,0,0,0,0,0,8,0,0,0,0,0,0,0,0,0
0,0,0,0,0,0,0,0,0,11,0,0,0,0,0,0,0,0,0
2,8,2,0,0,0,0,0,0,0,0,0,0,0,0,0,2,8,2
1,2,13,0,0,0,0,0,0,0,0,0,0,0,0,0,12,2,1
1,1,2,2,0,0,0,0,0,0,0,0,0,0,0,2,2,1,1
1,1,1,2,2,0,0,0,0,0,0,0,0,0,2,2,1,1,1
1,1,1,1,2,16,2,0,0,0,0,0,2,16,2,1,1,1,1
1,1,1,1,1,2,5,0,0,0,0,0,4,2,1,1,1,1,1
1,1,1,1,1,1,2,0,0,0,0,0,2,1,1,1,1,1,1
endlayer

layer
1,1,1,1,1,1,2,0,0,0,0,0,2,1,1,1,1,1,1
1,1,1,1,1,2,5,0,0,0,0,0,4,2,1,1,1,1,1
1,1,1,1,2,19,2,0,0,0,0,0,2,19,2,1,1,1,1
1,1,1,2,2,0,0,0,0,0,0,0,0,0,2,2,1,1,1
1,1,2,2,0,0,0,0,0,0,0,0,0,0,0,2,2,1,1
1,2,19,0,0,0,0,0,0,0,0,0,0,0,0,0,19,2,1
2,6,2,0,0,0,0,0,0,0,0,0,0,0,0,0,2,6,2
0,0,0,0,0,0,0,0,0,6,0,0,0,0,0,0,0,0,0
0,0,0,0,0,0,0,0,0,0,0,0,0,0,0,0,0,0,0
0,0,0,0,0,0,0,5,0,2,0,4,0,0,0,0,0,0,0
0,0,0,0,0,0,0,0,0,0,0,0,0,0,0,0,0,0,0
0,0,0,0,0,0,0,0,0,8,0,0,0,0,0,0,0,0,0
2,8,2,0,0,0,0,0,0,0,0,0,0,0,0,0,2,8,2
1,2,19,0,0,0,0,0,0,0,0,0,0,0,0,0,19,2,1
1,1,2,2,0,0,0,0,0,0,0,0,0,0,0,2,2,1,1
1,1,1,2,2,0,0,0,0,0,0,0,0,0,2,2,1,1,1
1,1,1,1,2,19,2,0,0,0,0,0,2,19,2,1,1,1,1
1,1,1,1,1,2,5,0,0,0,0,0,4,2,1,1,1,1,1
1,1,1,1,1,1,2,0,0,0,0,0,2,1,1,1,1,1,1
endlayer

layer
1,1,1,1,1,1,2,0,0,0,0,0,2,1,1,1,1,1,1
1,1,1,1,1,2,5,0,0,0,0,0,4,2,1,1,1,1,1
1,1,1,1,2,11,2,0,0,0,0,0,2,11,2,1,1,1,1
1,1,1,2,2,0,0,0,0,0,0,0,0,0,2,2,1,1,1
1,1,2,2,0,0,0,0,0,0,0,0,0,0,0,2,2,1,1
1,2,13,0,0,0,0,0,0,0,0,0,0,0,0,0,12,2,1
2,6,2,0,0,0,0,0,0,0,0,0,0,0,0,0,2,6,2
0,0,0,0,0,0,0,0,0,0,0,0,0,0,0,0,0,0,0
0,0,0,0,0,0,0,0,0,16,0,0,0,0,0,0,0,0,0
0,0,0,0,0,0,0,0,12,3,13,0,0,0,0,0,0,0,0
0,0,0,0,0,0,0,0,0,11,0,0,0,0,0,0,0,0,0
0,0,0,0,0,0,0,0,0,0,0,0,0,0,0,0,0,0,0
2,8,2,0,0,0,0,0,0,0,0,0,0,0,0,0,2,8,2
1,2,13,0,0,0,0,0,0,0,0,0,0,0,0,0,12,2,1
1,1,2,2,0,0,0,0,0,0,0,0,0,0,0,2,2,1,1
1,1,1,2,2,0,0,0,0,0,0,0,0,0,2,2,1,1,1
1,1,1,1,2,16,2,0,0,0,0,0,2,16,2,1,1,1,1
1,1,1,1,1,2,5,0,0,0,0,0,4,2,1,1,1,1,1
1,1,1,1,1,1,2,0,0,0,0,0,2,1,1,1,1,1,1
endlayer

layer
1,1,1,1,1,1,2,13,0,0,0,12,2,1,1,1,1,1,1
1,1,1,1,1,2,2,13,0,0,0,12,2,2,1,1,1,1,1
1,1,1,1,2,2,2,0,0,0,0,0,2,2,2,1,1,1,1
1,1,1,2,2,0,0,0,0,0,0,0,0,0,2,2,1,1,1
1,1,2,2,0,0,0,0,0,0,0,0,0,0,0,2,2,1,1
1,2,2,0,0,0,0,0,0,0,0,0,0,0,0,0,2,2,1
2,2,2,0,0,0,0,0,0,0,0,0,0,0,0,0,2,2,2
11,11,0,0,0,0,0,0,0,0,0,0,0,0,0,0,0,11,11
0,0,0,0,0,0,0,0,18,6,18,0,0,0,0,0,0,0,0
0,0,0,0,0,0,0,0,5,0,4,0,0,0,0,0,0,0,0
0,0,0,0,0,0,0,0,18,8,18,0,0,0,0,0,0,0,0
16,16,0,0,0,0,0,0,0,0,0,0,0,0,0,0,0,16,16
2,2,2,0,0,0,0,0,0,0,0,0,0,0,0,0,2,2,2
1,2,2,0,0,0,0,0,0,0,0,0,0,0,0,0,2,2,1
1,1,2,2,0,0,0,0,0,0,0,0,0,0,0,2,2,1,1
1,1,1,2,2,0,0,0,0,0,0,0,0,0,2,2,1,1,1
1,1,1,1,2,2,2,0,0,0,0,0,2,2,2,1,1,1,1
1,1,1,1,1,2,2,13,0,0,0,12,2,2,1,1,1,1,1
1,1,1,1,1,1,2,13,0,0,0,12,2,1,1,1,1,1,1
endlayer

layer
1,1,1,1,1,1,1,2,2,2,2,2,1,1,1,1,1,1,1
1,1,1,1,1,2,2,2,2,2,2,2,2,2,1,1,1,1,1
1,1,1,1,2,2,2,11,0,0,0,11,2,2,2,1,1,1,1
1,1,1,2,2,11,0,0,0,0,0,0,0,11,2,2,1,1,1
1,1,2,2,0,0,0,0,0,0,0,0,0,0,0,2,2,1,1
1,2,2,13,0,0,0,0,0,0,0,0,0,0,0,12,2,2,1
1,2,2,0,0,0,0,0,0,0,0,0,0,0,0,0,2,2,1
2,2,13,0,0,0,0,0,0,0,0,0,0,0,0,0,12,2,2
2,2,0,0,0,0,0,0,0,0,0,0,0,0,0,0,0,2,2
2,2,0,0,0,0,0,0,0,0,0,0,0,0,0,0,0,2,2
2,2,0,0,0,0,0,0,0,0,0,0,0,0,0,0,0,2,2
2,2,13,0,0,0,0,0,0,0,0,0,0,0,0,0,12,2,2
1,2,2,0,0,0,0,0,0,0,0,0,0,0,0,0,2,2,1
1,2,2,13,0,0,0,0,0,0,0,0,0,0,0,12,2,2,1
1,1,2,2,0,0,0,0,0,0,0,0,0,0,0,2,2,1,1
1,1,1,2,2,16,0,0,0,0,0,0,0,16,2,2,1,1,1
1,1,1,1,2,2,2,16,0,0,0,16,2,2,2,1,1,1,1
1,1,1,1,1,2,2,2,2,2,2,2,2,2,1,1,1,1,1
1,1,1,1,1,1,1,2,2,2,2,2,1,1,1,1,1,1,1
endlayer

layer
1,1,1,1,1,1,1,8,1,1,1,8,1,1,1,1,1,1,1
1,1,1,1,1,2,2,2,2,2,2,2,2,2,1,1,1,1,1
1,1,1,1,2,2,2,2,2,2,2,2,2,2,2,1,1,1,1
1,1,1,2,2,2,2,2,2,3,2,2,2,2,2,2,1,1,1
1,1,2,2,2,2,2,2,11,11,11,2,2,2,2,2,2,1,1
1,2,2,2,2,3,11,11,13,0,12,11,11,3,2,2,2,2,1
1,2,2,2,2,11,13,0,0,0,0,0,12,11,2,2,2,2,1
4,2,2,2,2,13,0,0,0,0,0,0,0,12,2,2,2,2,5
1,2,2,2,11,13,0,0,0,0,0,0,0,12,11,2,2,2,1
1,2,2,3,13,0,0,0,0,0,0,0,0,0,12,3,2,2,1
1,2,2,2,13,16,0,0,0,0,0,0,0,12,16,2,2,2,1
4,2,2,2,2,13,0,0,0,0,0,0,0,12,2,2,2,2,5
1,2,2,2,2,13,16,0,0,0,0,0,12,16,2,2,2,2,1
1,2,2,2,2,3,13,16,16,0,12,16,16,3,2,2,2,2,1
1,1,2,2,2,2,2,2,13,16,16,2,2,2,2,2,2,1,1
1,1,1,2,2,2,2,2,2,3,2,2,2,2,2,2,1,1,1
1,1,1,1,2,2,2,2,2,2,2,2,2,2,2,1,1,1,1
1,1,1,1,1,2,2,2,2,2,2,2,2,2,1,1,1,1,1
1,1,1,1,1,1,1,6,1,1,1,6,1,1,1,1,1,1,1
endlayer

layer
1,1,1,1,1,1,1,1,1,1,1,1,1,1,1,1,1,1,1
1,1,1,1,1,1,2,2,5,1,4,2,2,1,1,1,1,1,1
1,1,1,1,2,2,2,0,0,0,0,0,2,2,2,1,1,1,1
1,1,1,1,2,0,0,0,0,0,0,0,0,0,2,1,1,1,1
1,1,2,2,0,0,0,0,0,0,0,0,0,0,0,2,2,1,1
1,1,2,0,0,0,0,0,0,0,0,0,0,0,0,0,2,1,1
1,2,2,0,0,0,0,0,0,0,0,0,0,0,0,0,2,2,1
1,2,0,0,0,0,0,0,0,0,0,0,0,0,0,0,0,2,1
1,6,0,0,0,0,0,0,0,0,0,0,0,0,0,0,0,6,1
1,1,0,0,0,0,0,0,0,0,0,0,0,0,0,0,0,1,1
1,8,0,0,0,0,0,0,0,0,0,0,0,0,0,0,0,8,1
1,2,0,0,0,0,0,0,0,0,0,0,0,0,0,0,0,2,1
1,2,2,0,0,0,0,0,0,0,0,0,0,0,0,0,2,2,1
1,1,2,0,0,0,0,0,0,0,0,0,0,0,0,0,2,1,1
1,1,2,2,0,0,0,0,0,0,0,0,0,0,0,2,2,1,1
1,1,1,1,2,0,0,0,0,0,0,0,0,0,2,1,1,1,1
1,1,1,1,2,2,2,0,0,0,0,0,2,2,2,1,1,1,1
1,1,1,1,1,1,2,2,5,1,4,2,2,1,1,1,1,1,1
1,1,1,1,1,1,1,1,1,1,1,1,1,1,1,1,1,1,1
endlayer

layer
1,1,1,1,1,1,1,1,1,1,1,1,1,1,1,1,1,1,1
1,1,1,1,1,1,4,2,1,1,1,2,5,1,1,1,1,1,1
1,1,1,1,2,2,2,0,0,0,0,0,2,2,2,1,1,1,1
1,1,1,1,4,0,0,0,0,0,0,0,0,0,5,1,1,1,1
1,1,2,8,0,0,0,0,0,0,0,0,0,0,0,8,2,1,1
1,1,2,0,0,0,0,0,0,0,0,0,0,0,0,0,2,1,1
1,8,2,0,0,0,0,0,0,0,0,0,0,0,0,0,2,8,1
1,2,0,0,0,0,0,0,0,0,0,0,0,0,0,0,0,2,1
1,1,0,0,0,0,0,0,0,0,0,0,0,0,0,0,0,1,1
1,1,0,0,0,0,0,0,0,0,0,0,0,0,0,0,0,1,1
1,1,0,0,0,0,0,0,0,0,0,0,0,0,0,0,0,1,1
1,2,0,0,0,0,0,0,0,0,0,0,0,0,0,0,0,2,1
1,6,2,0,0,0,0,0,0,0,0,0,0,0,0,0,2,6,1
1,1,2,0,0,0,0,0,0,0,0,0,0,0,0,0,2,1,1
1,1,2,6,0,0,0,0,0,0,0,0,0,0,0,6,2,1,1
1,1,1,1,4,0,0,0,0,0,0,0,0,0,5,1,1,1,1
1,1,1,1,2,2,2,0,0,0,0,0,2,2,2,1,1,1,1
1,1,1,1,1,1,4,2,1,1,1,2,5,1,1,1,1,1,1
1,1,1,1,1,1,1,1,1,1,1,1,1,1,1,1,1,1,1
endlayer

layer
1,1,1,1,1,1,1,1,1,1,1,1,1,1,1,1,1,1,1
1,1,1,1,1,1,1,2,13,1,12,2,1,1,1,1,1,1,1
1,1,1,1,1,2,2,0,0,0,0,0,2,2,1,1,1,1,1
1,1,1,1,12,0,0,0,0,0,0,0,0,0,13,1,1,1,1
1,1,1,16,0,0,0,0,0,0,0,0,0,0,0,16,1,1,1
1,1,2,0,0,0,0,0,0,0,0,0,0,0,0,0,2,1,1
1,1,2,0,0,0,0,0,0,0,0,0,0,0,0,0,2,1,1
1,2,0,0,0,0,0,0,0,0,0,0,0,0,0,0,0,2,1
1,11,0,0,0,0,0,0,0,0,0,0,0,0,0,0,0,11,1
1,1,0,0,0,0,0,0,0,0,0,0,0,0,0,0,0,1,1
1,16,0,0,0,0,0,0,0,0,0,0,0,0,0,0,0,16,1
1,2,0,0,0,0,0,0,0,0,0,0,0,0,0,0,0,2,1
1,1,2,0,0,0,0,0,0,0,0,0,0,0,0,0,2,1,1
1,1,2,0,0,0,0,0,0,0,0,0,0,0,0,0,2,1,1
1,1,1,11,0,0,0,0,0,0,0,0,0,0,0,11,1,1,1
1,1,1,1,12,0,0,0,0,0,0,0,0,0,13,1,1,1,1
1,1,1,1,1,2,2,0,0,0,0,0,2,2,1,1,1,1,1
1,1,1,1,1,1,1,2,13,1,12,2,1,1,1,1,1,1,1
1,1,1,1,1,1,1,1,1,1,1,1,1,1,1,1,1,1,1
endlayer

layer
1,1,1,1,1,1,1,1,1,1,1,1,1,1,1,1,1,1,1
1,1,1,1,1,1,1,4,2,2,2,5,1,1,1,1,1,1,1
1,1,1,1,1,2,2,2,15,0,15,2,2,2,1,1,1,1,1
1,1,1,1,2,0,0,0,0,0,0,0,0,0,2,1,1,1,1
1,1,1,2,0,0,0,0,0,0,0,0,0,0,0,2,1,1,1
1,1,2,0,0,0,0,0,0,0,0,0,0,0,0,0,2,1,1
1,1,2,0,0,0,0,0,0,0,0,0,0,0,0,0,2,1,1
1,8,2,0,0,0,0,0,0,0,0,0,0,0,0,0,2,8,1
1,2,15,0,0,0,0,0,0,0,0,0,0,0,0,0,15,2,1
1,2,0,0,0,0,0,0,0,0,0,0,0,0,0,0,0,2,1
1,2,15,0,0,0,0,0,0,0,0,0,0,0,0,0,15,2,1
1,6,2,0,0,0,0,0,0,0,0,0,0,0,0,0,2,6,1
1,1,2,0,0,0,0,0,0,0,0,0,0,0,0,0,2,1,1
1,1,2,0,0,0,0,0,0,0,0,0,0,0,0,0,2,1,1
1,1,1,2,0,0,0,0,0,0,0,0,0,0,0,2,1,1,1
1,1,1,1,2,0,0,0,0,0,0,0,0,0,2,1,1,1,1
1,1,1,1,1,2,2,2,15,0,15,2,2,2,1,1,1,1,1
1,1,1,1,1,1,1,4,2,2,2,5,1,1,1,1,1,1,1
1,1,1,1,1,1,1,1,1,1,1,1,1,1,1,1,1,1,1
endlayer

layer
1,1,1,1,1,1,1,1,1,1,1,1,1,1,1,1,1,1,1
1,1,1,1,1,1,1,1,8,1,8,1,1,1,1,1,1,1,1
1,1,1,1,1,1,2,3,2,2,2,3,2,1,1,1,1,1,1
1,1,1,1,2,2,0,0,0,0,0,0,0,2,2,1,1,1,1
1,1,1,2,0,0,0,0,0,0,0,0,0,0,0,2,1,1,1
1,1,1,2,0,0,0,0,0,0,0,0,0,0,0,2,1,1,1
1,1,2,0,0,0,0,0,0,0,0,0,0,0,0,0,2,1,1
1,1,3,0,0,0,0,0,0,0,0,0,0,0,0,0,3,1,1
1,4,2,0,0,0,0,0,0,0,0,0,0,0,0,0,2,5,1
1,1,2,0,0,0,0,0,0,0,0,0,0,0,0,0,2,1,1
1,4,2,0,0,0,0,0,0,0,0,0,0,0,0,0,2,5,1
1,1,3,0,0,0,0,0,0,0,0,0,0,0,0,0,3,1,1
1,1,2,0,0,0,0,0,0,0,0,0,0,0,0,0,2,1,1
1,1,1,2,0,0,0,0,0,0,0,0,0,0,0,2,1,1,1
1,1,1,2,0,0,0,0,0,0,0,0,0,0,0,2,1,1,1
1,1,1,1,2,2,0,0,0,0,0,0,0,2,2,1,1,1,1
1,1,1,1,1,1,2,3,2,2,2,3,2,1,1,1,1,1,1
1,1,1,1,1,1,1,1,6,1,6,1,1,1,1,1,1,1,1
1,1,1,1,1,1,1,1,1,1,1,1,1,1,1,1,1,1,1
endlayer

layer
1,1,1,1,1,1,1,1,1,1,1,1,1,1,1,1,1,1,1
1,1,1,1,1,1,1,1,1,1,1,1,1,1,1,1,1,1,1
1,1,1,1,1,1,1,2,2,3,2,2,1,1,1,1,1,1,1
1,1,1,1,1,2,2,15,0,0,0,15,2,2,1,1,1,1,1
1,1,1,1,3,0,0,0,0,0,0,0,0,0,3,1,1,1,1
1,1,1,2,0,0,0,0,0,0,0,0,0,0,14,2,1,1,1
1,1,1,2,0,0,0,0,0,0,0,0,0,0,0,2,1,1,1
1,1,2,15,0,0,0,0,0,0,0,0,0,0,0,15,2,1,1
1,1,2,0,0,0,0,0,0,0,0,0,0,0,0,0,2,1,1
1,1,3,0,0,0,0,0,0,0,0,0,0,0,0,0,3,1,1
1,1,2,0,0,0,0,0,0,0,0,0,0,0,0,0,2,1,1
1,1,2,15,0,0,0,0,0,0,0,0,0,0,0,15,2,1,1
1,1,1,2,0,0,0,0,0,0,0,0,0,0,0,2,1,1,1
1,1,1,2,0,0,0,0,0,0,0,0,0,0,0,2,1,1,1
1,1,1,1,3,0,0,0,0,0,0,0,0,0,3,1,1,1,1
1,1,1,1,1,2,2,15,0,0,0,15,2,2,1,1,1,1,1
1,1,1,1,1,1,1,2,2,3,2,2,1,1,1,1,1,1,1
1,1,1,1,1,1,1,1,1,1,1,1,1,1,1,1,1,1,1
1,1,1,1,1,1,1,1,1,1,1,1,1,1,1,1,1,1,1
endlayer

layer
1,1,1,1,1,1,1,1,1,1,1,1,1,1,1,1,1,1,1
1,1,1,1,1,1,1,1,1,1,1,1,1,1,1,1,1,1,1
1,1,1,1,1,1,1,1,8,1,8,1,1,1,1,1,1,1,1
1,1,1,1,1,1,2,2,2,2,2,2,2,1,1,1,1,1,1
1,1,1,1,1,2,15,0,0,0,0,14,15,2,1,1,1,1,1
1,1,1,1,2,0,0,0,0,0,0,0,0,0,2,1,1,1,1
1,1,1,2,15,0,0,0,0,0,0,0,0,0,15,2,1,1,1
1,1,1,2,0,0,0,0,0,0,0,0,0,0,0,2,1,1,1
1,1,4,2,0,0,0,0,0,0,0,0,0,0,0,2,5,1,1
1,1,1,2,0,0,0,0,0,0,0,0,0,0,0,2,1,1,1
1,1,4,2,0,0,0,0,0,0,0,0,0,0,0,2,5,1,1
1,1,1,2,0,0,0,0,0,0,0,0,0,0,0,2,1,1,1
1,1,1,2,15,0,0,0,0,0,0,0,0,0,15,2,1,1,1
1,1,1,1,2,0,0,0,0,0,0,0,0,0,2,1,1,1,1
1,1,1,1,1,2,15,0,0,0,0,0,15,2,1,1,1,1,1
1,1,1,1,1,1,2,2,2,2,2,2,2,1,1,1,1,1,1
1,1,1,1,1,1,1,1,6,1,6,1,1,1,1,1,1,1,1
1,1,1,1,1,1,1,1,1,1,1,1,1,1,1,1,1,1,1
1,1,1,1,1,1,1,1,1,1,1,1,1,1,1,1,1,1,1
endlayer

layer
1,1,1,1,1,1,1,1,1,1,1,1,1,1,1,1,1,1,1
1,1,1,1,1,1,1,1,1,1,1,1,1,1,1,1,1,1,1
1,1,1,1,1,1,1,1,1,1,1,1,1,1,1,1,1,1,1
1,1,1,1,1,1,1,1,8,1,8,1,1,1,1,1,1,1,1
1,1,1,1,1,1,2,2,2,2,2,2,2,1,1,1,1,1,1
1,1,1,1,1,2,2,15,0,0,0,15,2,2,1,1,1,1,1
1,1,1,1,2,2,0,0,0,0,0,0,14,2,2,1,1,1,1
1,1,1,1,2,15,0,0,0,0,0,0,0,15,2,1,1,1,1
1,1,1,4,2,0,0,0,0,0,0,0,0,0,2,5,1,1,1
1,1,1,1,2,0,0,0,0,0,0,0,0,0,2,1,1,1,1
1,1,1,4,2,0,0,0,0,0,0,0,0,0,2,5,1,1,1
1,1,1,1,2,15,0,0,0,0,0,0,0,15,2,1,1,1,1
1,1,1,1,2,2,0,0,0,0,0,0,0,2,2,1,1,1,1
1,1,1,1,1,2,2,15,0,0,0,15,2,2,1,1,1,1,1
1,1,1,1,1,1,2,2,2,2,2,2,2,1,1,1,1,1,1
1,1,1,1,1,1,1,1,6,1,6,1,1,1,1,1,1,1,1
1,1,1,1,1,1,1,1,1,1,1,1,1,1,1,1,1,1,1
1,1,1,1,1,1,1,1,1,1,1,1,1,1,1,1,1,1,1
1,1,1,1,1,1,1,1,1,1,1,1,1,1,1,1,1,1,1
endlayer

layer
1,1,1,1,1,1,1,1,1,1,1,1,1,1,1,1,1,1,1
1,1,1,1,1,1,1,1,1,1,1,1,1,1,1,1,1,1,1
1,1,1,1,1,1,1,1,1,1,1,1,1,1,1,1,1,1,1
1,1,1,1,1,1,1,1,1,1,1,1,1,1,1,1,1,1,1
1,1,1,1,1,1,1,1,8,1,8,1,1,1,1,1,1,1,1
1,1,1,1,1,1,1,2,2,2,2,2,1,1,1,1,1,1,1
1,1,1,1,1,1,2,2,2,11,2,2,2,1,1,1,1,1,1
1,1,1,1,1,2,2,2,0,0,0,2,2,2,1,1,1,1,1
1,1,1,1,4,2,2,0,0,0,0,0,2,2,5,1,1,1,1
1,1,1,1,1,2,13,0,0,0,0,0,12,2,1,1,1,1,1
1,1,1,1,4,2,2,0,0,0,0,0,2,2,5,1,1,1,1
1,1,1,1,1,2,2,2,0,0,0,2,2,2,1,1,1,1,1
1,1,1,1,1,1,2,2,2,16,2,2,2,1,1,1,1,1,1
1,1,1,1,1,1,1,2,2,2,2,2,1,1,1,1,1,1,1
1,1,1,1,1,1,1,1,6,1,6,1,1,1,1,1,1,1,1
1,1,1,1,1,1,1,1,1,1,1,1,1,1,1,1,1,1,1
1,1,1,1,1,1,1,1,1,1,1,1,1,1,1,1,1,1,1
1,1,1,1,1,1,1,1,1,1,1,1,1,1,1,1,1,1,1
1,1,1,1,1,1,1,1,1,1,1,1,1,1,1,1,1,1,1
endlayer

layer
1,1,1,1,1,1,1,1,1,1,1,1,1,1,1,1,1,1,1
1,1,1,1,1,1,1,1,1,1,1,1,1,1,1,1,1,1,1
1,1,1,1,1,1,1,1,1,1,1,1,1,1,1,1,1,1,1
1,1,1,1,1,1,1,1,1,1,1,1,1,1,1,1,1,1,1
1,1,1,1,1,1,1,1,1,1,1,1,1,1,1,1,1,1,1
1,1,1,1,1,1,1,1,1,1,1,1,1,1,1,1,1,1,1
1,1,1,1,1,1,1,1,8,1,8,1,1,1,1,1,1,1,1
1,1,1,1,1,1,1,1,2,2,2,1,1,1,1,1,1,1,1
1,1,1,1,1,1,4,2,15,11,15,2,5,1,1,1,1,1,1
1,1,1,1,1,1,1,2,13,3,12,2,1,1,1,1,1,1,1
1,1,1,1,1,1,4,2,15,16,15,2,5,1,1,1,1,1,1
1,1,1,1,1,1,1,1,2,2,2,1,1,1,1,1,1,1,1
1,1,1,1,1,1,1,1,6,1,6,1,1,1,1,1,1,1,1
1,1,1,1,1,1,1,1,1,1,1,1,1,1,1,1,1,1,1
1,1,1,1,1,1,1,1,1,1,1,1,1,1,1,1,1,1,1
1,1,1,1,1,1,1,1,1,1,1,1,1,1,1,1,1,1,1
1,1,1,1,1,1,1,1,1,1,1,1,1,1,1,1,1,1,1
1,1,1,1,1,1,1,1,1,1,1,1,1,1,1,1,1,1,1
1,1,1,1,1,1,1,1,1,1,1,1,1,1,1,1,1,1,1
endlayer

