
# Created by Ruins mod version 17.0 Ingame Parser
# authoring Player: ST753M

# Has multiple blocks of diamond and gold, however also only appears in the 
# far end, where anyone reaching it will have more diamonds than they could ever
# use, so I consider it fair for a rare ruin in that point of the game.

uniqueMinDistance=2000
spawnMinDistance=2000
weight=1
embed_into_distance=1
acceptable_target_blocks=
unacceptable_target_blocks=flowing_water,water,flowing_lava,lava,ice,bedrock,netherrack,nether_brick,nether_brick_fence,soul_sand,quartz_ore,obsidian,iron_bars,Natura:Cloud,slime_grass,slime_congealed,slime_dirt,clouds,natura:clouds
dimensions=19,7,7
allowable_overhang=2
max_leveling=0
leveling_buffer=-1
preserve_water=1
preserve_lava=1

biomesToSpawnIn=sky,void,the_end,omothol,dark_realm

=0,100,preserveBlock
rule1=0,100,minecraft:obsidian-0,minecraft:obsidian-0,minecraft:obsidian-0,minecraft:obsidian-0,minecraft:obsidian-0,minecraft:obsidian-0,minecraft:obsidian-0,minecraft:obsidian-0,minecraft:obsidian-0,minecraft:obsidian-0,minecraft:obsidian-0,minecraft:obsidian-0,minecraft:obsidian-0,minecraft:obsidian-0,minecraft:obsidian-0,minecraft:obsidian-0,minecraft:obsidian-0,minecraft:obsidian-0,minecraft:obsidian-0,minecraft:obsidian-0,minecraft:obsidian-0,minecraft:obsidian-0,minecraft:obsidian-0,minecraft:obsidian-0,minecraft:obsidian-0,minecraft:obsidian-0,minecraft:obsidian-0,minecraft:obsidian-0,minecraft:obsidian-0,minecraft:obsidian-0,minecraft:obsidian-0,minecraft:obsidian-0,minecraft:obsidian-0,minecraft:obsidian-0,chisel:iron-11,chisel:diamond-3,chisel:diamond-3,chisel:gold-11,chisel:gold-11,chisel:gold-11

rule2=0,100,minecraft:lava-0
rule3=0,100,minecraft:obsidian-0
rule4=0,100,minecraft:obsidian-0
rule5=0,100,minecraft:obsidian-0

layer
0,0,1,1,1,0,0
0,1,2,2,2,1,0
1,2,2,2,2,3,1
1,2,2,2,2,4,1
1,2,2,2,2,5,1
0,1,2,2,2,1,0
0,0,1,1,1,0,0
endlayer

layer
0,0,1,1,1,0,0
0,1,2,2,2,1,0
1,2,2,2,2,2,1
1,2,2,2,2,2,1
1,2,2,2,2,2,1
0,1,2,2,2,1,0
0,0,1,1,1,0,0
endlayer

layer
0,0,1,1,1,0,0
0,1,2,2,2,1,0
1,2,2,2,2,2,1
1,2,2,2,2,2,1
1,2,2,2,2,2,1
0,1,2,2,2,1,0
0,0,1,1,1,0,0
endlayer

layer
0,0,1,1,1,0,0
0,1,2,2,2,1,0
1,2,2,2,2,2,1
1,2,2,2,2,2,1
1,2,2,2,2,2,1
0,1,2,2,2,1,0
0,0,1,1,1,0,0
endlayer

layer
0,0,1,1,1,0,0
0,1,2,2,2,1,0
1,2,2,2,2,2,1
1,2,2,2,2,2,1
1,2,2,2,2,2,1
0,1,2,2,2,1,0
0,0,1,1,1,0,0
endlayer

layer
0,0,1,1,1,0,0
0,1,2,2,2,1,0
1,2,2,2,2,2,1
1,2,2,2,2,2,1
1,2,2,2,2,2,1
0,1,2,2,2,1,0
0,0,1,1,1,0,0
endlayer

layer
0,0,1,1,1,0,0
0,1,2,2,2,1,0
1,2,2,2,2,2,1
1,2,2,2,2,2,1
1,2,2,2,2,2,1
0,1,2,2,2,1,0
0,0,1,1,1,0,0
endlayer

layer
0,0,1,1,1,0,0
0,1,2,2,2,1,0
1,2,2,2,2,2,1
1,2,2,2,2,2,1
1,2,2,2,2,2,1
0,1,2,2,2,1,0
0,0,1,1,1,0,0
endlayer

layer
0,0,1,1,1,0,0
0,1,2,2,2,1,0
1,2,2,2,2,2,1
1,2,2,2,2,2,1
1,2,2,2,2,2,1
0,1,2,2,2,1,0
0,0,1,1,1,0,0
endlayer

layer
0,0,1,1,1,0,0
0,1,2,2,2,1,0
1,2,2,2,2,2,1
1,2,2,2,2,2,1
1,2,2,2,2,2,1
0,1,2,2,2,1,0
0,0,1,1,1,0,0
endlayer

layer
0,0,1,1,1,0,0
0,1,2,2,2,1,0
1,2,2,2,2,2,1
1,2,2,2,2,2,1
1,2,2,2,2,2,1
0,1,2,2,2,1,0
0,0,1,1,1,0,0
endlayer

layer
0,0,1,1,1,0,0
0,1,2,2,2,1,0
1,2,2,2,2,2,1
1,2,2,2,2,2,1
1,2,2,2,2,2,1
0,1,2,2,2,1,0
0,0,1,1,1,0,0
endlayer

layer
0,0,1,1,1,0,0
0,1,2,2,2,1,0
1,2,2,2,2,2,1
1,2,2,2,2,2,1
1,2,2,2,2,2,1
0,1,2,2,2,1,0
0,0,1,1,1,0,0
endlayer

layer
0,0,1,1,1,0,0
0,1,2,2,2,1,0
1,2,2,2,2,2,1
1,2,2,2,2,2,1
1,2,2,2,2,2,1
0,1,2,2,2,1,0
0,0,1,1,1,0,0
endlayer

layer
0,0,1,1,1,0,0
0,1,2,2,2,1,0
1,2,2,2,2,2,1
1,2,2,2,2,2,1
1,2,2,2,2,2,1
0,1,2,2,2,1,0
0,0,1,1,1,0,0
endlayer

layer
0,0,1,1,1,0,0
0,1,2,2,2,1,0
1,2,2,2,2,2,1
1,2,2,2,2,2,1
1,2,2,2,2,2,1
0,1,2,2,2,1,0
0,0,1,1,1,0,0
endlayer

layer
0,0,1,1,1,0,0
0,1,2,2,2,1,0
1,2,2,2,2,2,1
1,2,2,2,2,2,1
1,2,2,2,2,2,1
0,1,2,2,2,1,0
0,0,1,1,1,0,0
endlayer

layer
0,0,1,1,1,0,0
0,1,2,2,2,1,0
1,2,2,2,2,2,1
1,2,2,2,2,2,1
1,2,2,2,2,2,1
0,1,2,2,2,1,0
0,0,1,1,1,0,0
endlayer

layer
0,0,0,0,0,0,0
0,0,1,1,1,0,0
0,1,1,1,1,1,0
0,1,1,1,1,1,0
0,1,1,1,1,1,0
0,0,1,1,1,0,0
0,0,0,0,0,0,0
endlayer

