
# Created by Ruins mod version 17.0 Ingame Parser
# authoring Player: ST753M

weight=1
embed_into_distance=5
acceptable_target_blocks=
unacceptable_target_blocks=flowing_water,water,flowing_lava,lava,ice,bedrock,netherrack,nether_brick,nether_brick_fence,soul_sand,quartz_ore,end_stone,obsidian,iron_bars,Natura:Cloud,slime_grass,slime_congealed,slime_dirt,clouds,natura:clouds
dimensions=13,15,15
allowable_overhang=5
max_leveling=2
leveling_buffer=0
preserve_water=0
preserve_lava=0
uniqueMinDistance=1000
spawnMinDistance=1000

biomesToSpawnIn=ocean,stone_beach,gravel_beach,black_beach,smaller_extreme_hills

=0,100,air
rule1=0,100,minecraft:stonebrick-0
rule2=0,100,iceandfire:silverpile-0
rule3=0,100,iceandfire:silverpile-1
rule4=0,100,iceandfire:silverpile-3
rule5=0,100,iceandfire:silverpile-2
rule6=0,100,iceandfire:silverpile-5
rule7=0,100,minecraft:ladder-4
rule8=0,100,CommandBlock:RUINSTRIGGER /summon iceandfire:gorgon ~ ~1 ~ {PersistenceRequired:1}:@-1
rule9=0,100,iceandfire:silverpile-6
rule10=0,100,iceandfire:silverpile-7
rule11=0,100,minecraft:trapdoor-11
rule12=0,100,minecraft:stone_brick_stairs-0
rule13=0,100,minecraft:stone_brick_stairs-3
rule14=0,100,minecraft:stone_brick_stairs-2
rule15=0,100,minecraft:stone_brick_stairs-1
rule16=0,100,minecraft:carpet-8
^0,100,minecraft:carpet-7
^0,100,minecraft:carpet-8
^0,100,minecraft:carpet-7
^0,100,minecraft:carpet-8
^0,100,minecraft:carpet-0
^0,100,minecraft:carpet-1
^0,100,minecraft:carpet-2
^0,100,minecraft:carpet-3
^0,100,minecraft:carpet-4
^0,100,minecraft:carpet-5
^0,100,minecraft:carpet-6
^0,100,minecraft:carpet-7
^0,100,minecraft:carpet-8
^0,100,minecraft:carpet-9
^0,100,minecraft:carpet-10
^0,100,minecraft:carpet-11
^0,100,minecraft:carpet-12
^0,100,minecraft:carpet-13
^0,100,minecraft:carpet-14
^0,100,minecraft:carpet-15
^0,100,minecraft:carpet-9
rule17=0,100,minecraft:stone_brick_stairs-6
rule18=0,100,minecraft:stone_brick_stairs-4
rule19=0,100,minecraft:stone_brick_stairs-7
rule20=0,100,minecraft:stone_brick_stairs-5
rule21=0,100,minecraft:double_stone_slab-5
rule22=0,100,minecraft:stone_slab-13
rule23=0,100,minecraft:cobblestone-0
rule24=0,100,minecraft:stone_slab-5

layer
1,1,1,1,1,1,1,1,1,1,1,1,1,1,1
1,1,1,1,1,1,1,1,1,1,1,1,1,1,1
1,1,1,1,1,1,1,1,1,1,1,1,1,1,1
1,1,1,1,1,1,1,1,1,1,1,1,1,1,1
1,1,1,1,1,1,1,1,1,1,1,1,1,1,1
1,1,1,1,1,1,1,1,1,1,1,1,1,1,1
1,1,1,1,1,1,1,1,1,1,1,1,1,1,1
1,1,1,1,1,1,1,1,1,1,1,1,1,1,1
1,1,1,1,1,1,1,1,1,1,1,1,1,1,1
1,1,1,1,1,1,1,1,1,1,1,1,1,1,1
1,1,1,1,1,1,1,1,1,1,1,1,1,1,1
1,1,1,1,1,1,1,1,1,1,1,1,1,1,1
1,1,1,1,1,1,1,1,1,1,1,1,1,1,1
1,1,1,1,1,1,1,1,1,1,1,1,1,1,1
1,1,1,1,1,1,1,1,1,1,1,1,1,1,1
endlayer

layer
1,1,1,1,1,1,1,1,1,1,1,1,1,1,1
1,1,1,1,1,1,1,1,1,1,1,1,1,1,1
1,1,0,0,1,4,3,2,0,0,2,0,0,1,1
1,1,0,0,1,3,2,0,2,0,0,0,5,1,1
1,1,0,0,1,1,1,1,0,0,1,2,0,1,1
1,1,0,0,0,0,0,0,0,0,1,5,3,1,1
1,1,0,0,0,0,0,7,0,0,1,6,4,1,1
1,1,1,1,1,1,1,1,0,0,1,1,1,1,1
1,1,10,9,1,0,0,0,0,8,0,0,0,1,1
1,1,3,6,1,0,0,0,0,0,0,0,0,1,1
1,1,5,3,1,0,2,1,1,1,1,2,3,1,1
1,1,2,5,3,0,0,1,3,2,2,2,0,1,1
1,1,3,2,0,2,0,1,6,3,2,3,3,1,1
1,1,1,1,1,1,1,1,1,1,1,1,1,1,1
1,1,1,1,1,1,1,1,1,1,1,1,1,1,1
endlayer

layer
1,1,1,1,1,1,1,1,1,1,1,1,1,1,1
1,1,1,1,1,1,1,1,1,1,1,1,1,1,1
1,1,0,0,1,0,0,0,0,0,0,0,0,1,1
1,1,0,0,1,0,0,0,0,0,0,0,0,1,1
1,1,0,0,1,1,1,1,0,0,1,0,0,1,1
1,1,0,0,0,0,0,0,0,0,1,0,0,1,1
1,1,0,0,0,0,0,7,0,0,1,0,0,1,1
1,1,1,1,1,1,1,1,0,0,1,1,1,1,1
1,1,2,0,1,0,0,0,0,0,0,0,0,1,1
1,1,0,0,1,0,0,0,0,0,0,0,0,1,1
1,1,0,0,1,0,0,1,1,1,1,0,0,1,1
1,1,0,0,0,0,0,1,0,0,0,0,0,1,1
1,1,0,0,0,0,0,1,0,0,0,0,0,1,1
1,1,1,1,1,1,1,1,1,1,1,1,1,1,1
1,1,1,1,1,1,1,1,1,1,1,1,1,1,1
endlayer

layer
1,1,1,1,1,1,1,1,1,1,1,1,1,1,1
1,1,1,1,1,1,1,1,1,1,1,1,1,1,1
1,1,0,0,1,0,0,0,0,0,0,0,0,1,1
1,1,0,0,1,0,0,0,0,0,0,0,0,1,1
1,1,0,0,1,1,1,1,0,0,1,0,0,1,1
1,1,0,0,0,0,0,0,0,0,1,0,0,1,1
1,1,0,0,0,0,0,7,0,0,1,0,0,1,1
1,1,1,1,1,1,1,1,0,0,1,1,1,1,1
1,1,0,0,1,0,0,0,0,0,0,0,0,1,1
1,1,0,0,1,0,0,0,0,0,0,0,0,1,1
1,1,0,0,1,0,0,1,1,1,1,0,0,1,1
1,1,0,0,0,0,0,1,0,0,0,0,0,1,1
1,1,0,0,0,0,0,1,0,0,0,0,0,1,1
1,1,1,1,1,1,1,1,1,1,1,1,1,1,1
1,1,1,1,1,1,1,1,1,1,1,1,1,1,1
endlayer

layer
1,1,1,1,1,1,1,1,1,1,1,1,1,1,1
1,1,1,1,1,1,1,1,1,1,1,1,1,1,1
1,1,1,1,1,1,1,1,1,1,1,1,1,1,1
1,1,1,1,1,1,1,1,1,1,1,1,1,1,1
1,1,1,1,1,1,1,1,1,1,1,1,1,1,1
1,1,1,1,1,1,1,1,1,1,1,1,1,1,1
1,1,1,1,1,1,1,11,1,1,1,1,1,1,1
1,1,1,1,1,1,1,1,1,1,1,1,1,1,1
1,1,1,1,1,1,1,1,1,1,1,1,1,1,1
1,1,1,1,1,1,1,1,1,1,1,1,1,1,1
1,1,1,1,1,1,1,1,1,1,1,1,1,1,1
1,1,1,1,1,1,1,1,1,1,1,1,1,1,1
1,1,1,1,1,1,1,1,1,1,1,1,1,1,1
1,1,1,1,1,1,1,1,1,1,1,1,1,1,1
1,1,1,1,1,1,1,1,1,1,1,1,1,1,1
endlayer

layer
13,12,14,13,12,14,13,12,14,13,12,14,13,12,12
13,1,14,13,1,14,13,1,14,13,1,14,13,1,14
15,15,14,13,15,14,13,15,14,13,15,14,13,15,15
12,12,12,16,16,16,16,16,16,16,16,16,12,12,12
13,1,14,16,16,16,16,16,16,16,16,16,13,1,14
15,15,15,16,16,16,16,16,16,16,16,16,15,15,15
12,12,12,16,16,16,16,16,16,16,16,16,12,12,12
13,1,14,16,16,16,16,16,16,16,16,16,13,1,14
15,15,15,16,16,16,16,16,16,16,16,16,15,15,15
12,12,12,16,16,16,16,16,16,16,16,16,12,12,12
13,1,14,16,16,16,16,16,16,16,16,16,13,1,14
15,15,15,16,16,16,16,16,16,16,16,16,15,15,15
12,12,14,12,12,12,13,12,14,12,12,14,13,12,14
13,1,14,13,1,14,13,1,14,13,1,14,13,1,14
15,15,14,15,15,14,13,15,14,13,15,14,13,15,14
endlayer

layer
0,0,0,0,0,0,0,0,0,0,0,0,0,0,0
0,1,0,0,1,0,0,1,0,0,1,0,0,1,0
0,0,0,0,0,0,0,0,0,0,0,0,0,0,0
0,0,0,0,0,0,0,0,0,0,0,0,0,0,0
0,1,0,0,0,0,0,0,0,0,0,0,0,1,0
0,0,0,0,0,0,0,0,0,0,0,0,0,0,0
0,0,0,0,0,0,0,0,0,0,0,0,0,0,0
0,1,0,0,0,0,0,0,0,0,0,0,0,1,0
0,0,0,0,0,0,0,0,0,0,0,0,0,0,0
0,0,0,0,0,0,0,0,0,0,0,0,0,0,0
0,1,0,0,0,0,0,0,0,0,0,0,0,1,0
0,0,0,0,0,0,0,0,0,0,0,0,0,0,0
0,0,0,0,0,0,0,0,0,0,0,0,0,0,0
0,1,0,0,1,0,0,1,0,0,1,0,0,1,0
0,0,0,0,0,0,0,0,0,0,0,0,0,0,0
endlayer

layer
0,0,0,0,0,0,0,0,0,0,0,0,0,0,0
0,1,0,0,1,0,0,1,0,0,1,0,0,1,0
0,0,0,0,0,0,0,0,0,0,0,0,0,0,0
0,0,0,0,0,0,0,0,0,0,0,0,0,0,0
0,1,0,0,0,0,0,0,0,0,0,0,0,1,0
0,0,0,0,0,0,0,0,0,0,0,0,0,0,0
0,0,0,0,0,0,0,0,0,0,0,0,0,0,0
0,1,0,0,0,0,0,0,0,0,0,0,0,1,0
0,0,0,0,0,0,0,0,0,0,0,0,0,0,0
0,0,0,0,0,0,0,0,0,0,0,0,0,0,0
0,1,0,0,0,0,0,0,0,0,0,0,0,1,0
0,0,0,0,0,0,0,0,0,0,0,0,0,0,0
0,0,0,0,0,0,0,0,0,0,0,0,0,0,0
0,1,0,0,1,0,0,1,0,0,1,0,0,1,0
0,0,0,0,0,0,0,0,0,0,0,0,0,0,0
endlayer

layer
0,0,0,0,0,0,0,0,0,0,0,0,0,0,0
0,1,0,0,1,0,0,1,0,0,1,0,0,1,0
0,0,0,0,0,0,0,0,0,0,0,0,0,0,0
0,0,0,0,0,0,0,0,0,0,0,0,0,0,0
0,1,0,0,0,0,0,0,0,0,0,0,0,1,0
0,0,0,0,0,0,0,0,0,0,0,0,0,0,0
0,0,0,0,0,0,0,0,0,0,0,0,0,0,0
0,1,0,0,0,0,0,0,0,0,0,0,0,1,0
0,0,0,0,0,0,0,0,0,0,0,0,0,0,0
0,0,0,0,0,0,0,0,0,0,0,0,0,0,0
0,1,0,0,0,0,0,0,0,0,0,0,0,1,0
0,0,0,0,0,0,0,0,0,0,0,0,0,0,0
0,0,0,0,0,0,0,0,0,0,0,0,0,0,0
0,1,0,0,1,0,0,1,0,0,1,0,0,1,0
0,0,0,0,0,0,0,0,0,0,0,0,0,0,0
endlayer

layer
19,18,17,19,18,17,19,18,17,19,18,17,18,18,17
19,1,17,19,1,17,19,1,17,19,1,17,19,1,17
20,20,20,19,20,17,19,20,17,19,20,17,20,20,20
18,18,18,0,0,0,0,0,0,0,0,0,18,18,18
19,1,17,0,0,0,0,0,0,0,0,0,19,1,17
20,20,20,0,0,0,0,0,0,0,0,0,20,20,20
18,18,18,0,0,0,0,0,0,0,0,0,18,18,18
19,1,17,0,0,0,0,0,0,0,0,0,19,1,17
20,20,20,0,0,0,0,0,0,0,0,0,20,20,20
18,18,18,0,0,0,0,0,0,0,0,0,18,18,18
19,1,17,0,0,0,0,0,0,0,0,0,19,1,17
20,20,20,0,0,0,0,0,0,0,0,0,20,20,20
18,18,17,19,18,17,19,18,17,19,18,17,18,18,18
19,1,17,19,1,17,19,1,17,19,1,17,19,1,17
19,20,17,19,20,17,19,20,17,19,20,17,19,20,17
endlayer

layer
21,21,21,22,22,0,0,0,0,0,22,22,21,21,21
21,1,1,23,23,23,23,23,23,23,23,23,1,1,21
21,1,21,22,22,0,0,0,0,0,22,22,21,1,21
22,23,22,0,0,0,0,0,0,0,0,0,22,23,22
22,23,22,0,0,0,0,0,0,0,0,0,22,23,22
0,23,0,0,0,0,0,0,0,0,0,0,0,23,0
0,23,0,0,0,0,0,0,0,0,0,0,0,23,0
0,23,0,0,0,0,0,0,0,0,0,0,0,23,0
0,23,0,0,0,0,0,0,0,0,0,0,0,23,0
0,23,0,0,0,0,0,0,0,0,0,0,0,23,0
22,23,22,0,0,0,0,0,0,0,0,0,22,23,22
22,23,22,0,0,0,0,0,0,0,0,0,22,23,22
21,1,21,22,22,0,0,0,0,0,22,22,21,1,21
21,1,1,23,23,23,23,23,23,23,23,23,1,1,21
21,21,21,22,22,0,0,0,0,0,22,22,21,21,21
endlayer

layer
0,0,0,24,24,21,17,22,19,21,24,24,0,0,0
0,0,24,24,21,1,23,23,23,1,21,24,24,0,0
0,24,24,24,24,21,17,22,19,21,24,24,24,24,0
24,24,24,0,0,0,0,0,0,0,0,0,24,24,24
24,21,24,0,0,0,0,0,0,0,0,0,24,21,24
21,1,21,0,0,0,0,0,0,0,0,0,21,1,21
20,23,20,0,0,0,0,0,0,0,0,0,20,23,20
22,23,22,0,0,0,0,0,0,0,0,0,22,23,22
18,23,18,0,0,0,0,0,0,0,0,0,18,23,18
21,1,21,0,0,0,0,0,0,0,0,0,21,1,21
24,21,24,0,0,0,0,0,0,0,0,0,24,21,24
24,24,24,0,0,0,0,0,0,0,0,0,24,24,24
0,24,24,24,24,21,17,22,19,21,24,24,24,24,0
0,0,24,24,21,1,23,23,23,1,21,24,24,0,0
0,0,0,24,24,21,17,22,19,21,24,24,0,0,0
endlayer

layer
0,0,0,0,0,0,0,24,0,0,0,0,0,0,0
0,0,0,0,0,0,24,24,24,0,0,0,0,0,0
0,0,0,0,0,0,0,24,0,0,0,0,0,0,0
0,0,0,0,0,0,0,0,0,0,0,0,0,0,0
0,0,0,0,0,0,0,0,0,0,0,0,0,0,0
0,0,0,0,0,0,0,0,0,0,0,0,0,0,0
0,24,0,0,0,0,0,0,0,0,0,0,0,24,0
24,24,24,0,0,0,0,0,0,0,0,0,24,24,24
0,24,0,0,0,0,0,0,0,0,0,0,0,24,0
0,0,0,0,0,0,0,0,0,0,0,0,0,0,0
0,0,0,0,0,0,0,0,0,0,0,0,0,0,0
0,0,0,0,0,0,0,0,0,0,0,0,0,0,0
0,0,0,0,0,0,0,24,0,0,0,0,0,0,0
0,0,0,0,0,0,24,24,24,0,0,0,0,0,0
0,0,0,0,0,0,0,24,0,0,0,0,0,0,0
endlayer

