
# Created by Ruins mod version 17.1 Ingame Parser
# authoring Player: ST753M

weight=1
uniqueMinDistance=1000
embed_into_distance=8
acceptable_target_blocks=
unacceptable_target_blocks=flowing_water,water,flowing_lava,lava,ice,bedrock,netherrack,nether_brick,nether_brick_fence,soul_sand,quartz_ore,end_stone,obsidian,iron_bars,Natura:Cloud,slime_grass,slime_congealed,slime_dirt,clouds,natura:clouds,twilightforest:wispy_cloud,twilightforest:fluffy_cloud
dimensions=16,21,13
allowable_overhang=8
max_leveling=0
leveling_buffer=-1
preserve_water=0
preserve_lava=0

biomesToSpawnIn=jungle,jungle_hills,tropical_island,tropical_rainforest,rainforest,mutated_jungle,mutated_jungle_edge,bamboo_forest,overgrown_cliffs,eucalyptus_forest,mini_jungle

rule1=0,100,minecraft:cobblestone-0,minecraft:cobblestone-0,minecraft:monster_egg-1,minecraft:mossy_cobblestone-0
rule2=0,100,minecraft:stone_slab-3,preserveBlock,minecraft:mossy_cobblestone-0,minecraft:stone_slab-3
rule3=0,90,minecraft:stone_stairs-3,minecraft:stone_slab-3,minecraft:stone_stairs-3
rule4=0,90,minecraft:stone_stairs-0,minecraft:stone_slab-3,minecraft:stone_stairs-0
rule5=0,90,minecraft:stone_stairs-2,minecraft:stone_slab-3,minecraft:stone_stairs-2
rule6=0,90,minecraft:stone_stairs-1,minecraft:stone_slab-3,minecraft:stone_stairs-1
rule7=0,100,minecraft:cobblestone_wall-0
rule8=0,100,minecraft:cobblestone-0,minecraft:monster_egg-1,minecraft:mossy_cobblestone-0,preserveBlock,preserveBlock
rule9=0,100,ChestGenHook:chests/jungle_temple:4-5
rule10=0,100,MobSpawner:skeleton,MobSpawner:zombie,MobSpawner:spider,MobSpawner:silverfish,MobSpawner:cave_spider
rule11=0,100,preserveBlock
rule12=0,90,minecraft:stone_stairs-4,minecraft:stone_slab-3,minecraft:stone_stairs-4

layer
1,1,1,1,1,1,1,1,1,1,1,1,1
1,1,1,1,1,1,1,1,1,1,1,1,1
1,1,1,1,1,1,1,1,1,1,1,1,1
1,1,1,1,1,1,1,1,1,1,1,1,1
1,1,1,1,1,1,1,1,1,1,1,1,1
1,1,1,1,1,1,1,1,1,1,1,1,1
1,1,1,1,1,1,1,1,1,1,1,1,1
1,1,1,1,1,1,1,1,1,1,1,1,1
1,1,1,1,1,1,1,1,1,1,1,1,1
1,1,1,1,1,1,1,1,1,1,1,1,1
1,1,1,1,1,1,1,1,1,1,1,1,1
1,1,1,1,1,1,1,1,1,1,1,1,1
1,1,1,1,1,1,1,1,1,1,1,1,1
1,1,1,1,1,1,1,1,1,1,1,1,1
1,1,1,1,1,1,1,1,1,1,1,1,1
1,1,1,1,1,1,1,1,1,1,1,1,1
1,1,1,1,1,1,1,1,1,1,1,1,1
1,1,1,1,1,1,1,1,1,1,1,1,1
1,1,1,1,1,1,1,1,1,1,1,1,1
1,1,1,1,1,1,1,1,1,1,1,1,1
1,1,1,1,1,1,1,1,1,1,1,1,1
endlayer

layer
1,1,1,1,1,1,1,1,1,1,1,1,1
1,1,1,1,1,1,2,1,1,1,1,1,1
1,1,1,1,1,2,0,2,1,1,1,1,1
1,1,1,1,2,0,0,0,2,1,1,1,1
1,1,1,2,0,0,0,0,0,2,1,1,1
1,1,2,0,0,0,0,0,0,0,2,1,1
1,2,0,0,0,0,0,0,0,0,0,2,1
1,5,0,0,1,4,4,4,1,0,0,3,1
1,6,0,0,4,1,1,1,4,0,0,6,1
1,0,0,0,1,1,1,1,1,0,0,0,1
1,7,0,0,8,8,8,8,8,0,0,7,1
1,0,0,0,0,0,9,0,0,0,0,0,1
1,4,0,0,0,0,0,0,0,0,0,4,1
1,5,0,0,0,7,8,7,0,0,0,3,1
1,2,0,0,0,8,1,8,0,0,0,2,1
1,1,2,0,0,7,8,7,0,0,2,1,1
1,1,1,2,0,0,0,0,0,2,1,1,1
1,1,1,1,2,0,0,0,2,1,1,1,1
1,1,1,1,1,2,0,2,1,1,1,1,1
1,1,1,1,1,1,2,1,1,1,1,1,1
1,1,1,1,1,1,1,1,1,1,1,1,1
endlayer

layer
1,1,1,1,1,1,1,1,1,1,1,1,1
1,1,1,1,2,0,0,0,2,1,1,1,1
1,1,1,2,0,0,0,0,0,2,1,1,1
1,1,2,0,0,0,0,0,0,0,2,1,1
1,2,0,0,0,0,0,0,0,0,0,2,1
1,0,0,0,0,0,0,0,0,0,0,0,1
1,0,0,0,0,0,0,0,0,0,0,0,1
1,5,0,0,4,0,0,0,4,0,0,3,1
1,6,0,0,1,4,4,4,1,0,0,6,1
1,0,0,0,4,1,1,1,4,0,0,0,1
1,7,0,0,1,1,1,1,1,0,0,7,1
1,0,0,0,8,0,0,0,8,0,0,0,1
1,4,0,0,0,0,0,0,0,0,0,4,1
1,5,0,0,0,0,8,0,0,0,0,3,1
1,0,0,0,0,8,1,8,0,0,0,0,1
1,0,0,0,0,0,8,0,0,0,0,0,1
1,2,0,0,0,0,0,0,0,0,0,2,1
1,1,2,0,0,0,0,0,0,0,2,1,1
1,1,1,2,0,0,0,0,0,2,1,1,1
1,1,1,1,2,0,0,0,2,1,1,1,1
1,1,1,1,1,1,1,1,1,1,1,1,1
endlayer

layer
1,1,1,1,1,1,1,1,1,1,1,1,1
1,1,2,0,0,0,0,0,0,0,2,1,1
1,2,0,0,0,0,0,0,0,0,0,2,1
1,0,0,0,0,0,0,0,0,0,0,0,1
1,0,0,0,0,0,0,0,0,0,0,0,1
1,0,0,0,0,0,0,0,0,0,0,0,1
1,0,0,0,0,0,0,0,0,0,0,0,1
1,5,0,0,0,0,0,0,0,0,0,3,1
1,6,0,0,4,0,0,0,4,0,0,6,1
1,0,0,0,1,4,4,4,1,0,0,0,1
1,7,0,0,4,1,1,1,4,0,0,7,1
1,0,0,0,1,1,1,1,1,0,0,0,1
1,4,0,0,8,0,0,0,8,0,0,4,1
1,5,0,0,0,0,8,0,0,0,0,3,1
1,0,0,0,0,8,10,8,0,0,0,0,1
1,0,0,0,0,0,8,0,0,0,0,0,1
1,0,0,0,0,0,0,0,0,0,0,0,1
1,0,0,0,0,0,0,0,0,0,0,0,1
1,2,0,0,0,0,0,0,0,0,0,2,1
1,1,2,0,0,0,0,0,0,0,2,1,1
1,1,1,1,1,1,1,1,1,1,1,1,1
endlayer

layer
1,1,1,1,1,1,1,1,1,1,1,1,1
1,1,0,0,0,0,0,0,0,0,0,1,1
1,0,0,0,0,0,0,0,0,0,0,0,1
1,0,0,0,0,0,0,0,0,0,0,0,1
1,0,0,0,0,0,0,0,0,0,0,0,1
1,0,0,0,0,0,0,0,0,0,0,0,1
1,4,0,0,0,0,0,0,0,0,0,4,1
1,5,0,0,0,0,0,0,0,0,0,3,1
1,6,0,0,0,0,0,0,0,0,0,6,1
1,0,0,0,4,0,0,0,4,0,0,0,1
1,7,0,0,1,4,4,4,1,0,0,7,1
1,0,0,0,4,1,1,1,4,0,0,0,1
1,4,0,0,1,1,1,1,1,0,0,4,1
1,5,0,0,8,0,8,0,8,0,0,3,1
1,6,0,0,0,8,1,8,0,0,0,6,1
1,0,0,0,0,0,8,0,0,0,0,0,1
1,0,0,0,0,0,0,0,0,0,0,0,1
1,0,0,0,0,0,0,0,0,0,0,0,1
1,0,0,0,0,0,0,0,0,0,0,0,1
1,1,0,0,0,0,0,0,0,0,0,1,1
1,1,1,1,1,1,1,1,1,1,1,1,1
endlayer

layer
1,1,1,1,1,1,1,1,1,1,1,1,1
1,1,0,8,8,0,0,0,8,8,0,1,1
1,0,0,0,0,0,0,0,0,0,0,0,1
1,0,0,0,0,0,0,0,0,0,0,0,1
1,0,0,0,0,0,0,0,0,0,0,0,1
1,0,0,0,0,0,0,0,0,0,0,0,1
1,4,0,0,0,0,0,0,0,0,0,4,1
1,5,0,0,0,0,0,0,0,0,0,3,1
1,0,0,0,0,0,0,0,0,0,0,0,1
1,0,0,0,0,0,0,0,0,0,0,0,1
1,7,0,0,4,0,0,0,4,0,0,7,1
1,0,0,0,1,4,4,4,1,0,0,0,1
1,0,0,0,4,1,1,1,4,0,0,0,1
1,5,0,0,1,1,1,1,1,0,0,3,1
1,6,0,0,8,8,1,8,8,0,0,6,1
1,0,0,0,0,0,8,0,0,0,0,0,1
1,0,0,0,0,0,0,0,0,0,0,0,1
1,0,0,0,0,0,0,0,0,0,0,0,1
1,0,0,0,0,0,0,0,0,0,0,0,1
1,1,0,8,8,0,0,0,8,8,0,1,1
1,1,1,1,1,1,1,1,1,1,1,1,1
endlayer

layer
8,4,8,8,11,4,4,4,11,8,8,4,8
1,1,1,1,1,1,1,1,1,1,1,1,1
1,0,0,8,8,0,0,0,8,8,0,0,1
1,0,0,0,0,0,0,0,0,0,0,0,1
1,0,0,0,0,0,0,0,0,0,0,0,1
1,0,0,0,0,0,0,0,0,0,0,0,1
1,4,0,0,0,0,0,0,0,0,0,4,1
1,5,0,0,0,0,0,0,0,0,0,3,1
1,0,0,0,0,0,0,0,0,0,0,0,1
1,7,0,0,0,0,0,0,0,0,0,7,1
1,7,0,0,0,0,0,0,0,0,0,7,1
1,7,0,0,4,0,0,0,4,0,0,7,1
1,0,0,0,1,4,4,4,1,0,0,0,1
1,5,0,0,4,1,1,1,4,0,0,3,1
1,6,0,0,1,1,1,1,1,0,0,6,1
1,0,0,0,8,0,8,0,8,0,0,0,1
1,0,0,0,0,0,0,0,0,0,0,0,1
1,0,0,0,0,0,0,0,0,0,0,0,1
1,0,0,8,8,0,0,0,8,8,0,0,1
1,1,1,1,1,1,1,1,1,1,1,1,1
8,6,8,8,11,6,6,6,11,8,8,6,8
endlayer

layer
11,11,11,4,11,11,11,11,11,4,11,11,11
8,4,8,8,11,4,4,4,11,8,8,4,8
1,1,1,1,1,1,1,1,1,1,1,1,1
1,0,0,8,8,0,0,0,8,8,0,0,1
1,0,0,0,0,0,0,0,0,0,0,0,1
1,0,0,0,0,0,0,0,0,0,0,0,1
1,0,0,0,0,0,0,0,0,0,0,0,1
1,5,0,0,0,0,0,0,0,0,0,3,1
1,0,0,0,0,0,0,0,0,0,0,0,1
1,7,0,0,0,0,0,0,0,0,0,7,1
1,0,0,0,0,0,0,0,0,0,0,0,1
1,7,0,0,0,0,0,0,0,0,0,7,1
1,0,0,0,4,0,0,0,4,0,0,0,1
1,5,0,0,1,4,4,4,1,0,0,3,1
1,0,0,0,4,1,1,1,4,0,0,0,1
1,0,0,0,1,1,1,1,1,0,0,0,1
1,0,0,0,8,0,0,0,8,0,0,0,1
1,0,0,8,8,0,0,0,8,8,0,0,1
1,1,1,1,1,1,1,1,1,1,1,1,1
8,6,8,8,11,6,6,6,11,8,8,6,8
11,11,11,6,11,11,11,11,11,6,11,11,11
endlayer

layer
11,11,11,11,11,11,11,11,11,11,11,11,11
11,11,11,4,11,11,11,11,11,4,11,11,11
8,4,8,8,11,4,4,4,11,8,8,4,8
1,1,1,1,1,1,1,1,1,1,1,1,1
1,0,0,8,8,0,0,0,8,8,0,0,1
1,0,0,0,0,0,0,0,0,0,0,0,1
1,0,0,0,0,0,0,0,0,0,0,0,1
1,5,0,0,0,0,0,0,0,0,0,3,1
2,0,0,0,0,0,0,0,0,0,0,0,2
6,0,0,0,0,0,0,0,0,0,0,0,6
0,0,0,0,0,0,0,0,0,0,0,0,0
4,0,0,0,0,0,0,0,0,0,0,0,4
2,0,0,0,0,0,0,0,0,0,0,0,2
1,5,0,0,4,0,0,0,4,0,0,3,1
1,0,0,0,1,4,4,4,1,0,0,0,1
1,0,0,0,4,1,1,1,4,0,0,0,1
1,0,0,8,1,1,1,1,1,8,0,0,1
1,1,1,1,1,1,1,1,1,1,1,1,1
8,6,8,8,11,6,6,6,11,8,8,6,8
11,11,11,6,11,11,11,11,11,6,11,11,11
11,11,11,11,11,11,11,11,11,11,11,11,11
endlayer

layer
11,11,11,11,11,11,11,11,11,11,11,11,11
11,11,11,11,11,11,11,11,11,11,11,11,11
11,11,11,4,11,11,11,11,11,4,11,11,11
8,4,8,8,11,4,4,4,11,8,8,4,8
1,1,1,1,1,1,1,1,1,1,1,1,1
1,0,0,8,8,0,0,0,8,8,0,0,1
6,0,0,0,0,0,0,0,0,0,0,0,6
4,0,0,0,0,0,0,0,0,0,0,0,4
1,0,0,0,0,0,0,0,0,0,0,0,1
2,0,0,0,0,0,0,0,0,0,0,0,2
0,0,0,0,0,0,0,0,0,0,0,0,0
2,0,0,0,0,0,0,0,0,0,0,0,2
1,0,0,0,0,0,0,0,0,0,0,0,1
6,0,0,0,0,0,0,0,0,0,0,0,6
4,0,0,0,4,0,0,0,4,0,0,0,4
1,0,0,8,1,4,4,4,1,8,0,0,1
1,1,1,1,1,1,1,1,1,1,1,1,1
8,6,8,8,11,6,6,6,11,8,8,6,8
11,11,11,6,11,11,11,11,11,6,11,11,11
11,11,11,11,11,11,11,11,11,11,11,11,11
11,11,11,11,11,11,11,11,11,11,11,11,11
endlayer

layer
11,11,11,11,11,11,11,11,11,11,11,11,11
11,11,11,11,11,11,11,11,11,11,11,11,11
11,11,11,11,11,11,11,11,11,11,11,11,11
11,11,11,4,11,11,11,11,11,4,11,11,11
8,4,8,8,11,4,4,4,11,8,8,4,8
1,1,1,1,1,1,1,1,1,1,1,1,1
1,0,0,8,8,0,0,0,8,8,0,0,1
6,0,0,0,0,0,0,0,0,0,0,0,6
4,0,0,0,0,0,0,0,0,0,0,0,4
1,0,0,0,0,0,0,0,0,0,0,0,1
2,0,0,0,0,0,0,0,0,0,0,0,2
1,0,0,0,0,0,0,0,0,0,0,0,1
6,0,0,0,0,0,0,0,0,0,0,0,6
4,0,0,0,0,0,0,0,0,0,0,0,4
1,0,0,8,1,0,0,0,1,8,0,0,1
1,1,1,1,1,0,0,0,1,1,1,1,1
8,6,8,8,0,0,0,0,0,8,8,6,8
11,11,11,6,11,0,0,0,11,6,11,11,11
11,11,11,11,11,11,11,11,11,11,11,11,11
11,11,11,11,11,11,11,11,11,11,11,11,11
11,11,11,11,11,11,11,11,11,11,11,11,11
endlayer

layer
11,11,11,11,11,11,11,11,11,11,11,11,11
11,11,11,11,11,11,11,11,11,11,11,11,11
11,11,11,11,11,11,11,11,11,11,11,11,11
11,11,11,11,11,11,11,11,11,11,11,11,11
11,11,11,4,11,11,11,11,11,4,11,11,11
8,4,8,8,11,4,4,4,11,8,8,4,8
1,1,1,1,1,1,1,1,1,1,1,1,1
1,0,0,8,8,0,0,0,8,8,0,0,1
6,0,0,0,0,0,0,0,0,0,0,0,6
4,0,0,0,0,0,0,0,0,0,0,0,4
1,0,0,0,0,0,0,0,0,0,0,0,1
6,0,0,0,0,0,0,0,0,0,0,0,6
4,0,0,0,0,0,0,0,0,0,0,0,4
1,0,0,8,1,0,0,0,1,8,0,0,1
1,1,1,1,1,0,0,0,1,1,1,1,1
8,6,8,8,0,0,0,0,0,8,8,6,8
11,11,11,6,0,0,0,0,0,6,11,11,11
11,11,11,11,11,0,0,0,11,11,11,11,11
11,11,11,11,11,11,11,11,11,11,11,11,11
11,11,11,11,11,11,11,11,11,11,11,11,11
11,11,11,11,11,11,11,11,11,11,11,11,11
endlayer

layer
11,11,11,11,11,11,11,11,11,11,11,11,11
11,11,11,11,11,11,11,11,11,11,11,11,11
11,11,11,11,11,11,11,11,11,11,11,11,11
11,11,11,11,11,11,11,11,11,11,11,11,11
11,11,11,11,11,11,11,11,11,11,11,11,11
11,11,11,4,11,11,11,11,11,4,11,11,11
8,4,8,8,11,4,4,4,11,8,8,4,8
1,1,1,1,1,1,1,1,1,1,1,1,1
1,0,0,8,8,0,0,0,8,8,0,0,1
1,0,0,0,0,0,0,0,0,0,0,0,1
2,0,0,0,0,0,0,0,0,0,0,0,2
1,0,0,0,0,0,0,0,0,0,0,0,1
1,0,0,8,1,0,0,0,1,8,0,0,1
1,1,1,1,1,0,0,0,1,1,1,1,1
8,6,8,8,0,0,0,0,0,8,8,6,8
11,11,11,6,0,0,0,0,0,6,11,11,11
11,11,11,11,0,0,0,0,0,11,11,11,11
11,11,11,11,11,0,0,0,11,11,11,11,11
11,11,11,11,11,11,11,11,11,11,11,11,11
11,11,11,11,11,11,11,11,11,11,11,11,11
11,11,11,11,11,11,11,11,11,11,11,11,11
endlayer

layer
11,11,11,11,11,11,11,11,11,11,11,11,11
11,11,11,11,11,11,11,11,11,11,11,11,11
11,11,11,11,11,11,11,11,11,11,11,11,11
11,11,11,11,11,11,11,11,11,11,11,11,11
11,11,11,11,11,11,11,11,11,11,11,11,11
11,11,11,11,11,11,11,11,11,11,11,11,11
11,11,11,4,11,11,11,11,11,4,11,11,11
8,12,8,8,11,4,4,4,11,8,8,4,8
1,1,1,1,1,1,1,1,1,1,1,1,1
1,0,0,8,8,0,0,0,8,8,0,0,1
1,0,0,0,0,0,0,0,0,0,0,0,1
1,0,0,8,1,0,0,0,1,8,0,0,1
1,1,1,1,1,1,1,1,1,1,1,1,1
8,6,8,8,11,11,11,11,11,8,8,6,8
11,11,11,6,11,0,0,0,11,6,11,11,11
11,11,11,11,11,0,0,0,11,11,11,11,11
11,11,11,11,11,0,0,0,11,11,11,11,11
11,11,11,11,11,11,11,11,11,11,11,11,11
11,11,11,11,11,11,11,11,11,11,11,11,11
11,11,11,11,11,11,11,11,11,11,11,11,11
11,11,11,11,11,11,11,11,11,11,11,11,11
endlayer

layer
11,11,11,11,11,11,11,11,11,11,11,11,11
11,11,11,11,11,11,11,11,11,11,11,11,11
11,11,11,11,11,11,11,11,11,11,11,11,11
11,11,11,11,11,11,11,11,11,11,11,11,11
11,11,11,11,11,11,11,11,11,11,11,11,11
11,11,11,11,11,11,11,11,11,11,11,11,11
11,11,11,11,11,11,11,11,11,11,11,11,11
11,11,11,4,11,11,11,11,11,4,11,11,11
8,4,8,8,11,4,4,4,11,8,8,4,8
1,1,1,1,1,1,1,1,1,1,1,1,1
1,0,0,8,1,0,0,0,1,8,0,0,1
1,1,1,1,1,1,1,1,1,1,1,1,1
8,6,8,8,11,6,6,6,11,8,8,6,8
11,11,11,6,11,11,11,11,11,6,11,11,11
11,11,11,11,11,11,11,11,11,11,11,11,11
11,11,11,11,11,11,11,11,11,11,11,11,11
11,11,11,11,11,11,11,11,11,11,11,11,11
11,11,11,11,11,11,11,11,11,11,11,11,11
11,11,11,11,11,11,11,11,11,11,11,11,11
11,11,11,11,11,11,11,11,11,11,11,11,11
11,11,11,11,11,11,11,11,11,11,11,11,11
endlayer

layer
11,11,11,11,11,11,11,11,11,11,11,11,11
11,11,11,11,11,11,11,11,11,11,11,11,11
11,11,11,11,11,11,11,11,11,11,11,11,11
11,11,11,11,11,11,11,11,11,11,11,11,11
11,11,11,11,11,11,11,11,11,11,11,11,11
11,11,11,11,11,11,11,11,11,11,11,11,11
11,11,11,11,11,11,11,11,11,11,11,11,11
11,11,11,11,11,11,11,11,11,11,11,11,11
11,11,11,4,11,11,11,11,11,4,11,11,11
8,4,8,8,11,4,4,4,11,8,8,4,8
1,1,1,1,1,1,1,1,1,1,1,1,1
8,6,8,8,11,6,6,6,11,8,8,6,8
11,11,11,6,11,11,11,11,11,6,11,11,11
11,11,11,11,11,11,11,11,11,11,11,11,11
11,11,11,11,11,11,11,11,11,11,11,11,11
11,11,11,11,11,11,11,11,11,11,11,11,11
11,11,11,11,11,11,11,11,11,11,11,11,11
11,11,11,11,11,11,11,11,11,11,11,11,11
11,11,11,11,11,11,11,11,11,11,11,11,11
11,11,11,11,11,11,11,11,11,11,11,11,11
11,11,11,11,11,11,11,11,11,11,11,11,11
endlayer

