
# Created by Ruins mod version 16.5 Ingame Parser
# authoring Player: ST753M

weight=1
embed_into_distance=10
random_height_offset=-5,5
uniqueMinDistance=2000
spawnMinDistance=1000
acceptable_target_blocks=gravel,dirt,clay,stone,emerald_block
unacceptable_target_blocks=endstone
dimensions=37,37,7
allowable_overhang=9999
max_leveling=-1
leveling_buffer=0
preserve_water=1
preserve_lava=1

biomesToSpawnIn=deep_ocean

=0,100,preserveBlock
rule1=0,100,minecraft:prismarine-0
^0,100,minecraft:prismarine-1
^0,100,minecraft:prismarine-2
rule2=0,100,minecraft:prismarine-0
^0,100,minecraft:prismarine-1
^0,100,minecraft:prismarine-2
rule3=0,100,minecraft:prismarine-0
rule4=0,100,preserveBlock
rule5=0,100,minecraft:prismarine-0
^0,100,minecraft:prismarine-1
^0,100,minecraft:prismarine-2
rule6=0,100,minecraft:prismarine-0
^0,100,minecraft:prismarine-1
^0,100,minecraft:prismarine-2
rule7=0,100,minecraft:prismarine-0
rule8=0,100,minecraft:sea_lantern-0

layer
1,1,1,1,1,1,1
1,2,2,1,1,1,1
1,2,2,1,1,1,1
2,2,2,1,1,1,1
2,2,2,2,1,1,1
2,2,2,2,1,1,1
2,2,2,2,1,1,1
2,2,2,2,2,1,1
2,2,2,2,2,1,1
2,2,2,2,2,1,1
2,2,2,2,2,2,1
2,2,2,2,2,2,1
2,2,2,2,2,2,1
2,2,2,2,2,2,1
2,2,2,2,2,1,1
2,2,2,2,2,1,1
2,2,2,2,2,1,1
2,2,2,2,2,1,1
2,2,2,2,2,1,1
2,2,2,2,2,1,1
2,2,2,2,2,1,1
2,2,2,2,1,1,1
2,2,2,2,1,1,1
1,1,1,1,1,1,1
1,1,1,1,1,1,1
1,1,1,1,1,1,1
1,1,1,1,1,1,1
1,1,1,1,1,1,1
1,1,1,1,1,1,1
1,1,1,1,1,1,1
1,1,1,1,1,1,1
1,1,1,1,1,1,1
1,1,1,1,1,1,1
1,1,1,1,1,1,1
1,1,1,1,1,1,1
1,1,1,1,1,1,1
1,1,1,1,1,1,1
endlayer

layer
1,1,1,1,1,1,1
1,1,1,1,1,1,1
1,1,1,1,1,1,1
1,1,1,1,1,1,1
1,1,1,1,1,1,1
1,1,1,1,1,1,1
1,1,1,1,1,1,1
1,1,1,1,1,1,1
1,1,1,1,1,1,1
1,1,1,1,1,1,1
1,1,1,1,1,1,1
1,1,1,1,1,1,1
1,1,1,1,1,1,1
1,1,1,1,1,1,1
1,1,1,1,1,1,1
2,1,1,1,1,1,1
2,1,1,1,1,1,1
2,2,1,1,1,1,1
2,2,1,1,1,1,1
2,2,1,1,1,1,1
2,2,1,1,1,1,1
2,2,1,1,1,1,1
2,2,1,1,1,1,1
2,2,2,2,2,1,1
2,2,2,2,2,1,1
2,2,2,2,2,1,1
2,2,2,2,2,1,1
2,2,2,2,2,1,1
2,2,2,2,2,1,1
2,2,2,2,2,1,1
2,2,2,2,2,1,1
2,2,2,2,2,1,1
2,2,2,2,2,1,1
2,2,2,2,2,1,1
2,2,2,2,2,1,1
2,2,2,2,2,1,1
2,2,2,2,2,1,1
endlayer

layer
3,3,3,3,3,3,3
3,3,3,3,3,3,3
3,3,3,3,3,3,3
3,3,3,3,3,3,3
3,3,3,3,3,3,3
3,3,3,3,3,3,3
3,3,3,3,3,3,3
3,3,3,3,3,3,3
3,3,3,3,3,3,3
3,3,3,3,3,3,3
3,3,3,3,3,3,3
3,3,3,1,3,3,3
3,3,1,1,1,3,3
3,3,1,1,1,3,3
3,1,1,1,1,1,3
1,1,1,1,1,1,1
1,1,1,1,1,1,1
1,1,1,1,1,1,1
1,1,1,1,1,1,1
1,1,1,1,1,1,1
1,1,1,1,1,1,1
1,1,1,1,1,1,1
1,1,1,1,1,1,1
2,2,1,1,1,1,1
2,2,2,2,1,1,1
2,2,2,2,1,1,1
2,2,2,2,2,1,1
2,2,2,2,2,1,1
2,2,2,2,2,1,1
2,2,2,2,2,1,1
2,2,2,2,2,1,1
2,2,2,2,2,1,1
2,2,2,2,2,1,1
2,2,2,2,2,1,1
2,2,2,2,2,1,1
2,2,2,2,2,1,1
2,2,2,2,2,1,1
endlayer

layer
3,1,1,1,1,1,1
3,1,1,1,1,1,1
3,1,1,1,1,1,1
3,1,1,1,1,1,1
3,1,1,1,1,1,1
3,1,1,1,1,1,1
3,1,1,1,1,1,1
3,1,1,1,1,1,1
3,1,1,1,1,1,1
3,1,1,1,1,1,1
3,1,1,1,1,1,1
3,1,3,1,1,1,1
3,1,1,1,1,1,1
3,3,1,1,1,3,3
3,1,1,1,1,3,3
3,1,1,1,1,1,3
3,1,1,1,1,1,3
3,1,1,1,1,1,3
3,1,1,1,1,1,3
3,1,1,1,1,1,3
3,1,1,1,1,1,3
3,1,1,1,1,1,3
1,1,1,1,1,1,3
1,1,1,1,1,1,1
1,1,1,1,1,1,1
1,1,1,1,1,1,1
1,1,1,1,1,1,1
1,1,1,1,1,1,1
1,1,1,1,1,1,1
1,1,1,1,1,1,1
1,1,1,1,1,1,1
1,1,1,1,1,1,1
1,1,1,1,1,1,1
1,1,1,1,1,1,1
1,1,1,1,1,1,1
1,1,1,1,1,1,1
1,1,1,1,1,1,1
endlayer

layer
1,1,1,1,1,1,1
1,1,1,1,1,1,1
1,1,1,1,1,1,1
1,1,1,1,1,1,1
1,1,1,1,1,1,1
1,1,1,1,1,1,1
1,1,1,1,1,1,1
1,1,1,1,1,1,1
1,1,1,1,1,1,1
1,1,1,1,1,1,1
1,1,1,1,1,1,1
1,1,1,1,1,1,1
1,1,1,1,1,1,1
1,1,1,1,1,1,1
4,1,1,1,1,1,4
4,1,1,1,1,1,4
4,1,1,1,1,1,4
4,1,1,1,1,3,4
4,1,1,1,3,3,4
4,1,1,1,3,3,4
4,3,1,1,1,3,4
4,3,1,1,1,3,4
4,3,1,1,1,3,4
3,1,1,1,1,1,3
3,1,1,1,1,1,3
1,1,1,1,1,1,3
1,1,1,1,1,1,1
1,1,1,1,1,1,1
1,1,1,1,1,1,1
1,1,1,1,1,1,1
1,1,1,1,1,1,1
1,1,1,1,1,1,1
1,1,1,1,1,1,1
1,1,1,1,1,1,1
1,1,1,1,1,1,1
1,1,1,1,1,1,1
1,1,1,1,1,1,1
endlayer

layer
1,5,5,5,5,5,5
1,5,5,5,5,5,5
1,5,5,5,5,5,5
1,5,5,5,5,5,5
1,5,5,5,5,5,5
1,5,5,5,5,5,5
1,5,5,5,5,5,5
1,5,5,5,5,5,5
1,1,1,1,1,5,5
1,1,1,1,1,5,5
1,1,1,1,1,5,5
1,1,1,1,1,1,1
4,1,1,1,1,1,4
4,1,1,1,1,1,4
4,4,5,5,1,4,4
4,4,5,5,1,4,4
4,4,1,1,1,4,4
4,4,1,1,1,4,4
4,4,1,1,1,4,4
4,4,1,1,1,4,4
4,4,1,1,1,4,4
4,4,1,1,3,4,4
4,4,1,1,3,4,4
4,1,1,3,3,3,4
4,3,1,1,1,3,4
3,1,1,1,1,1,3
3,1,1,1,1,1,3
3,1,1,1,1,1,3
3,1,1,1,1,1,3
1,1,1,1,1,1,1
1,1,1,1,1,1,1
1,1,1,1,1,1,1
1,1,1,1,1,1,1
1,1,1,1,1,1,1
1,1,1,1,1,1,1
1,1,1,1,1,1,1
1,1,1,1,1,1,1
endlayer

layer
5,5,5,5,5,5,5
5,5,5,5,5,5,5
5,5,5,5,5,5,5
5,5,5,5,5,5,5
5,5,5,5,5,5,5
5,5,5,5,5,5,5
5,5,1,1,1,5,5
5,1,1,1,1,1,5
5,1,1,1,1,1,5
5,1,1,1,1,1,5
4,5,1,1,1,5,4
4,5,1,1,5,5,4
4,4,5,5,5,4,4
4,4,5,5,1,4,4
4,4,4,4,4,4,4
4,4,4,4,4,4,4
4,4,4,4,4,4,4
4,4,4,4,4,4,4
4,4,4,4,4,4,4
4,4,4,4,4,4,4
4,4,4,4,4,4,4
4,4,4,4,4,4,4
4,4,4,4,4,4,4
4,4,1,1,1,4,4
4,4,1,1,1,4,4
4,3,1,1,1,1,4
4,3,1,1,1,1,4
3,1,1,1,1,1,3
3,1,1,1,1,3,3
3,1,1,1,1,1,3
3,3,1,1,1,3,3
3,3,3,3,3,3,3
3,3,3,3,3,3,3
3,3,3,3,3,3,3
3,3,3,3,3,3,3
3,3,3,3,3,3,3
3,3,3,3,3,3,3
endlayer

layer
4,6,6,6,6,6,4
6,6,6,6,6,6,6
6,6,6,6,6,6,6
5,6,6,6,6,6,6
5,6,6,6,6,6,6
5,6,1,1,6,6,6
5,6,1,1,1,1,6
5,1,1,1,1,1,6
4,5,1,1,1,6,4
4,5,1,1,1,6,4
4,4,5,5,5,4,4
4,4,5,5,5,4,4
4,4,4,4,4,4,4
4,4,4,4,4,4,4
4,4,4,4,4,4,4
4,4,4,4,4,4,4
4,4,4,4,4,4,4
4,4,4,4,4,4,4
4,4,4,4,4,4,4
4,4,4,4,4,4,4
4,4,4,4,4,4,4
4,4,4,4,4,4,4
4,4,4,4,4,4,4
4,4,4,4,4,4,4
4,4,4,4,4,4,4
4,4,1,1,1,4,4
4,4,1,1,1,4,4
4,1,1,1,1,1,4
4,1,1,1,1,1,4
1,1,1,1,1,1,1
1,1,1,1,1,1,1
1,1,1,1,1,1,1
1,1,1,1,1,1,1
1,1,1,1,1,1,1
1,1,1,1,1,1,1
1,1,1,1,1,1,1
1,1,1,1,1,1,1
endlayer

layer
4,6,6,1,1,4,4
6,6,1,1,1,1,1
6,1,1,1,1,1,1
6,1,1,1,1,1,1
6,1,1,1,1,1,1
6,1,1,1,1,1,1
6,6,1,1,1,1,1
4,6,1,1,1,1,4
4,6,1,1,1,1,4
4,4,6,6,6,4,4
4,4,4,4,4,4,4
4,4,4,4,4,4,4
4,4,4,4,4,4,4
4,4,4,4,4,4,4
4,4,4,4,4,4,4
4,4,4,4,4,4,4
4,4,4,4,4,4,4
4,4,4,4,4,4,4
4,4,4,4,4,4,4
4,4,4,4,4,4,4
4,4,4,4,4,4,4
4,4,4,4,4,4,4
4,4,4,4,4,4,4
4,4,4,4,4,4,4
4,4,4,4,4,4,4
4,4,4,4,4,4,4
4,4,4,4,4,4,4
4,4,1,1,1,4,4
4,1,1,1,1,1,4
4,1,1,1,1,1,4
1,1,1,1,1,1,1
1,1,1,1,1,1,1
1,1,1,1,1,1,1
1,1,1,1,1,1,1
1,1,1,1,1,1,1
1,1,1,1,1,1,1
1,1,1,1,1,1,1
endlayer

layer
4,1,1,1,1,4,4
4,1,1,1,1,1,4
1,1,1,1,1,1,1
1,1,1,1,1,1,1
1,1,1,1,1,1,1
1,1,1,1,1,1,1
1,1,1,1,1,1,1
4,1,1,1,1,1,4
4,4,1,1,1,4,4
4,4,4,4,4,4,4
4,4,4,4,4,4,4
4,4,4,4,4,4,4
4,4,4,4,4,4,4
4,4,4,4,4,4,4
4,4,4,4,4,4,4
4,4,4,4,4,4,4
4,4,4,4,4,4,4
4,4,4,4,4,4,4
4,4,4,4,4,4,4
4,4,4,4,4,4,4
4,4,4,4,4,4,4
4,4,4,4,4,4,4
4,4,4,4,4,4,4
4,4,4,4,4,4,4
4,4,4,4,4,4,4
4,4,4,4,4,4,4
4,4,4,4,4,4,4
4,4,4,4,4,4,4
4,4,5,5,5,4,4
4,5,5,5,5,5,4
1,1,1,1,5,5,5
1,1,1,5,5,5,5
1,1,1,5,5,5,5
1,1,5,5,5,5,5
1,1,5,5,5,5,5
1,1,5,5,5,5,5
1,1,5,5,5,5,4
endlayer

layer
4,4,1,1,1,4,4
4,1,1,1,1,4,4
1,1,1,1,1,1,4
1,1,1,1,1,1,1
1,1,1,1,1,1,1
1,1,1,1,1,1,1
4,1,1,1,1,1,4
4,4,1,1,1,4,4
4,4,4,4,4,4,4
4,4,4,4,4,4,4
4,4,4,4,4,4,4
4,4,4,4,4,4,4
4,4,4,4,4,4,4
4,4,4,4,4,4,4
4,4,4,4,4,4,4
4,4,4,4,4,4,4
4,4,4,4,4,4,4
4,4,4,4,4,4,4
4,4,4,4,4,4,4
4,4,4,4,4,4,4
4,4,4,4,4,4,4
4,4,4,4,4,4,4
4,4,4,4,4,4,4
4,4,4,4,4,4,4
4,4,4,4,4,4,4
4,4,4,4,4,4,4
4,4,4,4,4,4,4
4,4,4,4,4,4,4
4,4,4,4,4,4,4
4,4,5,5,5,4,4
4,5,5,1,1,5,4
5,5,1,1,1,5,5
5,5,1,1,1,5,5
5,5,5,5,5,5,5
5,5,5,5,5,5,5
5,5,5,5,5,5,5
4,5,5,5,5,5,4
endlayer

layer
4,4,1,1,1,4,4
4,1,1,1,1,4,4
1,1,1,1,1,1,4
1,1,1,1,1,1,4
1,1,1,1,1,1,3
1,1,1,1,1,3,3
4,3,1,1,1,3,4
4,4,3,3,3,4,4
4,4,4,4,4,4,4
4,4,4,4,4,4,4
4,4,4,4,4,4,4
4,4,4,4,4,4,4
4,4,4,4,4,4,4
4,4,4,4,4,4,4
4,4,4,4,4,4,4
4,4,4,4,4,4,4
4,4,4,4,4,4,4
4,0,4,4,4,4,4
4,4,4,4,4,4,4
4,4,4,4,4,4,4
4,4,4,4,4,4,4
4,4,4,4,4,4,4
4,4,4,4,4,4,4
4,4,4,4,4,4,4
4,4,4,4,4,4,4
4,4,4,4,4,4,4
4,4,4,4,4,4,4
4,4,4,4,4,4,4
4,4,4,4,4,4,4
4,4,5,6,6,4,4
4,5,5,6,6,6,4
5,5,1,6,1,6,6
5,5,1,1,1,6,6
5,5,5,1,6,6,6
5,5,5,5,6,6,6
5,5,5,5,6,6,6
4,4,5,5,6,6,4
endlayer

layer
4,4,3,3,3,4,4
4,3,3,3,3,4,4
3,3,1,1,1,3,4
3,1,1,1,1,3,3
3,3,1,1,1,1,3
4,3,1,1,1,3,4
4,4,3,3,3,4,4
4,4,4,4,4,4,4
4,4,4,4,4,4,4
4,4,4,4,4,4,4
4,4,4,4,4,4,4
4,4,4,4,4,4,4
4,4,4,4,4,4,4
4,4,4,4,4,4,4
4,4,4,4,4,4,4
4,4,4,4,4,4,4
4,4,4,4,4,4,4
4,0,4,4,4,4,4
4,4,4,4,4,4,4
4,4,4,4,4,4,4
4,4,4,4,4,4,4
4,4,4,4,4,4,4
4,4,4,4,4,4,4
4,4,4,4,4,4,4
4,4,4,4,4,4,4
4,4,4,4,4,4,4
4,4,4,4,4,4,4
4,4,4,4,4,4,4
4,4,4,4,4,4,4
4,4,4,4,4,4,4
4,4,6,6,1,4,4
4,6,6,1,1,1,4
6,6,1,1,1,1,1
6,6,1,1,0,6,1
6,6,6,6,6,6,1
6,6,6,6,6,6,1
4,4,6,6,6,4,4
endlayer

layer
4,4,3,3,3,4,4
4,3,3,3,3,4,4
3,3,1,1,1,3,4
3,1,1,1,1,1,3
3,1,1,1,1,1,3
4,3,1,1,1,7,4
4,4,7,7,7,4,4
4,4,4,4,4,4,4
4,4,4,4,4,4,4
4,4,4,4,4,4,4
4,4,4,4,4,4,4
4,4,4,4,4,4,4
4,4,4,4,4,4,4
4,4,4,4,4,4,4
4,4,4,4,4,4,4
4,4,4,4,4,4,4
4,4,4,4,4,4,4
4,0,4,4,4,4,4
4,4,4,4,4,4,4
4,4,4,4,4,4,4
4,4,4,4,4,4,4
4,4,4,4,4,4,4
4,4,4,4,4,4,4
4,4,4,4,4,4,4
4,4,4,4,4,4,4
4,4,4,4,4,4,4
4,4,4,4,4,4,4
4,4,4,4,4,4,4
4,4,4,4,4,4,4
4,4,4,4,4,4,4
4,4,6,6,6,4,4
4,6,1,1,6,6,4
1,1,1,1,1,6,6
1,1,1,1,1,1,1
1,1,1,1,1,1,1
1,1,1,1,1,1,4
4,4,6,6,6,4,4
endlayer

layer
4,4,7,7,7,4,4
4,7,1,1,1,7,4
7,1,1,1,1,1,7
7,1,1,1,1,1,7
4,7,1,1,1,7,4
4,4,7,1,1,4,4
4,4,4,4,4,4,4
4,4,4,4,4,4,4
4,4,4,4,4,4,4
4,4,4,4,4,4,4
4,4,4,4,4,4,4
4,4,4,4,4,4,4
4,4,4,4,4,4,4
4,4,4,4,4,4,4
4,4,4,4,4,4,4
4,4,4,4,4,4,4
4,4,4,4,4,4,4
4,0,4,4,4,4,4
4,4,4,4,4,4,4
4,4,4,4,4,4,4
4,4,4,4,4,4,4
4,4,4,4,4,4,4
4,4,4,4,4,4,4
4,4,4,4,4,4,4
4,4,4,4,4,4,4
4,4,4,4,4,4,4
4,4,4,4,4,4,4
4,4,4,4,4,4,4
4,4,4,4,4,4,4
4,4,4,4,4,4,4
4,4,4,4,4,4,4
4,4,6,1,1,4,4
4,6,6,1,1,1,4
6,6,1,1,1,6,6
6,1,1,1,1,6,6
4,1,1,1,6,6,4
4,4,1,1,6,4,4
endlayer

layer
4,4,1,1,1,4,4
4,1,1,1,1,1,4
1,1,1,1,1,1,1
1,1,1,1,1,1,1
4,1,1,1,1,1,4
4,4,1,1,1,4,4
4,4,4,4,4,4,4
4,4,4,4,4,4,4
4,4,4,4,4,4,4
4,4,4,4,4,4,4
4,4,4,4,4,4,4
4,4,4,4,4,4,4
4,4,4,4,4,4,4
4,4,4,4,4,4,4
4,4,4,4,4,4,4
4,4,4,4,4,4,4
4,4,4,4,4,4,4
4,0,4,4,4,4,4
4,4,4,4,4,4,4
4,4,4,4,4,4,4
4,4,4,4,4,4,4
4,4,4,4,4,4,4
4,4,4,4,4,4,4
4,4,4,4,4,4,4
4,4,4,4,4,4,4
4,4,4,4,4,4,4
4,4,4,4,4,4,4
4,4,4,4,4,4,4
4,4,4,4,4,4,4
4,4,4,4,4,4,4
4,4,4,4,4,4,4
4,4,1,1,1,4,4
4,1,1,1,1,1,4
1,1,1,1,1,1,1
1,1,1,1,1,1,1
4,6,6,6,1,1,4
4,4,6,6,6,4,4
endlayer

layer
4,4,1,1,1,4,4
4,1,1,1,1,1,4
1,1,1,1,1,1,1
1,1,1,1,1,1,1
4,1,1,1,1,1,4
4,4,1,1,1,4,4
4,4,4,4,4,4,4
4,4,4,4,4,4,4
4,4,4,4,4,4,4
4,4,4,4,4,4,4
4,4,4,4,4,4,4
4,4,4,4,4,4,4
4,4,4,4,4,4,4
4,4,4,4,4,4,4
4,4,4,4,4,4,4
4,4,4,4,4,4,4
4,4,4,4,4,4,4
4,0,4,4,4,4,4
4,4,4,4,4,4,4
4,4,4,4,4,4,4
4,4,4,4,4,4,4
4,4,4,4,4,4,4
4,4,4,4,4,4,4
4,4,4,4,4,4,4
4,4,4,4,4,4,4
4,4,4,4,4,4,4
4,4,4,4,4,4,4
4,4,4,4,4,4,4
4,4,4,4,4,4,4
4,4,4,4,4,4,4
4,4,4,4,4,4,4
4,4,3,3,3,4,4
4,1,1,1,1,3,4
1,1,1,1,1,1,1
1,1,1,1,1,1,1
4,1,1,1,1,1,4
4,4,1,1,1,4,4
endlayer

layer
4,4,2,1,1,4,4
4,2,1,1,1,1,4
2,1,1,1,1,1,2
2,1,1,1,1,1,2
4,2,1,1,1,2,4
4,4,2,8,2,4,4
4,4,4,4,4,4,4
4,4,4,4,4,4,4
4,4,4,4,4,4,4
4,4,4,4,4,4,4
4,4,4,4,4,4,4
4,4,4,4,4,4,4
4,4,4,4,4,4,4
4,4,4,4,4,4,4
4,4,4,4,4,4,4
4,4,4,4,4,4,4
4,4,4,4,4,4,4
4,0,4,4,4,4,4
4,4,4,4,4,4,4
4,4,4,4,4,4,4
4,4,4,4,4,4,4
4,4,4,4,4,4,4
4,4,4,4,4,4,4
4,4,4,4,4,4,4
4,4,4,4,4,4,4
4,4,4,4,4,4,4
4,4,4,4,4,4,4
4,4,4,4,4,4,4
4,4,4,4,4,4,4
4,4,4,4,4,4,4
4,4,4,4,4,4,4
4,4,3,8,3,4,4
4,3,1,1,3,3,4
3,1,1,1,1,3,3
3,3,1,1,1,1,3
4,3,3,1,1,3,4
4,4,3,3,3,4,4
endlayer

layer
4,4,2,2,2,4,4
4,2,1,1,1,2,4
2,1,1,1,1,1,2
2,1,1,1,1,1,1
4,2,1,1,1,1,4
4,4,2,1,1,4,4
4,4,4,4,4,4,4
4,4,4,4,4,4,4
4,4,4,4,4,4,4
4,4,4,4,4,4,4
4,4,4,4,4,4,4
4,4,4,4,4,4,4
4,4,4,4,4,4,4
4,4,4,4,4,4,4
4,4,4,4,4,4,4
4,4,4,4,4,4,4
4,4,4,4,4,4,4
4,0,4,4,4,4,4
4,4,4,4,4,4,4
4,4,4,4,4,4,4
4,4,4,4,4,4,4
4,4,4,4,4,4,4
4,4,4,4,4,4,4
4,4,4,4,4,4,4
4,4,4,4,4,4,4
4,4,4,4,4,4,4
4,4,4,4,4,4,4
4,4,4,4,4,4,4
4,4,4,4,4,4,4
4,4,4,4,4,4,4
4,4,4,4,4,4,4
4,4,3,1,1,4,4
4,3,1,1,1,1,4
3,1,1,1,1,3,1
1,1,1,1,1,1,1
4,1,1,1,1,1,4
4,4,1,1,1,4,4
endlayer

layer
4,4,1,1,2,4,4
4,1,1,1,1,2,4
1,1,1,1,1,1,2
2,1,1,1,1,1,2
4,2,1,1,1,2,4
4,4,1,1,1,4,4
4,4,4,4,4,4,4
4,4,4,4,4,4,4
4,4,4,4,4,4,4
4,4,4,4,4,4,4
4,4,4,4,4,4,4
4,4,4,4,4,4,4
4,4,4,4,4,4,4
4,4,4,4,4,4,4
4,4,4,4,4,4,4
4,4,4,4,4,4,4
4,4,4,4,4,4,4
4,0,4,4,4,4,4
4,4,4,4,4,4,4
4,4,4,4,4,4,4
4,4,4,4,4,4,4
4,4,4,4,4,4,4
4,4,4,4,4,4,4
4,4,4,4,4,4,4
4,4,4,4,4,4,4
4,4,4,4,4,4,4
4,4,4,4,4,4,4
4,4,4,4,4,4,4
4,4,4,4,4,4,4
4,4,4,4,4,4,4
4,4,4,4,4,4,4
4,4,3,3,3,4,4
4,3,1,1,3,3,4
1,1,1,1,1,1,1
1,1,1,1,1,1,1
4,1,1,1,1,1,4
4,4,1,1,1,4,4
endlayer

layer
4,4,1,1,1,4,4
4,1,1,1,1,1,4
1,1,1,1,1,1,1
1,1,1,1,1,1,2
4,1,1,1,1,2,4
4,4,2,2,2,4,4
4,4,4,4,4,4,4
4,4,4,4,4,4,4
4,4,4,4,4,4,4
4,4,4,4,4,4,4
4,4,4,4,4,4,4
4,4,4,4,4,4,4
4,4,4,4,4,4,4
4,4,4,4,4,4,4
4,4,4,4,4,4,4
4,4,4,4,4,4,4
4,4,4,4,4,4,4
4,0,4,4,4,4,4
4,4,4,4,4,4,4
4,4,4,4,4,4,4
4,4,4,4,4,4,4
4,4,4,4,4,4,4
4,4,4,4,4,4,4
4,4,4,4,4,4,4
4,4,4,4,4,4,4
4,4,4,4,4,4,4
4,4,4,4,4,4,4
4,4,4,4,4,4,4
4,4,4,4,4,4,4
4,4,4,4,4,4,4
4,4,4,4,4,4,4
4,4,3,3,3,4,4
4,1,1,1,1,1,4
1,1,1,1,1,1,1
1,1,1,1,1,1,1
4,7,1,1,1,1,4
4,4,7,1,1,4,4
endlayer

layer
4,4,3,1,1,4,4
4,3,1,1,1,1,4
1,1,1,1,1,1,1
1,1,1,1,1,1,1
0,2,1,1,1,1,0
0,0,2,2,2,0,0
0,0,0,0,0,0,0
0,0,0,0,0,0,0
0,0,0,0,0,0,0
0,0,0,0,0,0,0
0,0,0,0,0,0,0
0,0,0,0,0,0,0
0,0,0,0,0,0,0
0,0,0,0,0,0,0
0,0,0,0,0,0,0
0,0,0,0,0,0,0
0,0,0,0,0,0,0
0,0,0,0,0,0,0
0,0,0,0,0,0,0
0,0,0,0,0,0,0
0,0,0,0,0,0,0
0,0,0,0,0,0,0
0,0,0,0,0,0,0
0,0,0,0,0,0,0
0,0,0,0,0,0,0
0,0,0,0,0,0,0
0,0,0,0,0,0,0
0,0,0,0,0,0,0
0,0,0,0,0,0,0
0,0,0,0,0,0,0
0,0,0,0,0,0,0
0,0,1,1,1,0,0
0,1,1,1,1,1,0
1,1,1,1,1,1,1
7,1,1,1,1,1,1
4,7,1,1,1,1,4
4,4,7,7,1,4,4
endlayer

layer
0,0,3,3,1,4,4
0,1,3,3,3,1,4
1,1,1,1,1,1,1
2,1,1,1,1,1,1
0,2,1,1,1,1,0
0,0,1,1,1,0,0
0,0,0,0,0,0,0
0,0,0,0,0,0,0
0,0,0,0,0,0,0
0,0,0,0,0,0,0
0,0,0,0,0,0,0
0,0,0,0,0,0,0
0,0,0,0,0,0,0
0,0,0,0,0,0,0
0,0,0,0,0,0,0
0,0,0,0,0,0,0
0,0,0,0,0,0,0
0,0,0,0,0,0,0
0,0,0,0,0,0,0
0,0,0,0,0,0,0
0,0,0,0,0,0,0
0,0,0,0,0,0,0
0,0,0,0,0,0,0
0,0,0,0,0,0,0
0,0,0,0,0,0,0
0,0,0,0,0,0,0
0,0,0,0,0,0,0
0,0,0,0,0,0,0
0,0,0,0,0,0,0
0,0,0,0,0,0,0
0,0,0,0,0,0,0
0,0,7,7,7,0,0
0,7,1,1,1,7,0
7,1,1,1,1,1,7
7,1,1,1,1,1,7
4,7,1,1,1,7,4
4,4,2,7,7,4,4
endlayer

layer
0,0,0,0,0,4,4
0,0,3,3,3,0,4
0,1,1,3,3,3,0
2,1,1,1,1,1,3
1,1,1,1,1,1,1
0,1,1,1,1,1,0
0,0,1,1,1,0,0
0,0,0,0,0,0,0
0,0,0,0,0,0,0
0,0,0,0,0,0,0
0,0,0,0,0,0,0
0,0,0,0,0,0,0
0,0,0,0,0,0,0
0,0,0,0,0,0,0
0,0,0,0,0,0,0
0,0,0,0,0,0,0
0,0,0,0,0,0,0
0,0,0,0,0,0,0
0,0,0,0,0,0,0
0,0,0,0,0,0,0
0,0,0,0,0,0,0
0,0,0,0,0,0,0
0,0,0,0,0,0,0
0,0,0,0,0,0,0
0,0,0,0,0,0,0
0,0,0,0,0,0,0
0,0,0,0,0,0,0
0,0,0,0,0,0,0
0,0,0,0,0,0,0
0,0,0,0,0,0,0
0,0,7,7,7,0,0
0,7,1,1,1,7,0
7,1,1,1,1,1,7
7,1,1,1,1,1,7
0,2,1,1,1,7,0
0,0,2,2,7,0,0
0,0,0,0,0,0,0
endlayer

layer
0,0,0,0,0,4,4
0,0,3,3,3,0,4
0,2,1,3,3,3,0
1,1,1,1,1,1,3
1,1,1,1,1,1,3
0,3,1,1,1,3,0
0,0,3,3,3,0,0
0,0,0,0,0,0,0
0,0,0,0,0,0,0
0,0,0,0,0,0,0
0,0,0,0,0,0,0
0,0,0,0,0,0,0
0,0,0,0,0,0,0
0,0,0,0,0,0,0
0,0,0,0,0,0,0
0,0,0,0,0,0,0
0,0,0,0,0,0,0
0,0,0,0,0,0,0
0,0,0,0,0,0,0
0,0,0,0,0,0,0
0,0,0,0,0,0,0
0,0,0,0,0,0,0
0,0,0,0,0,0,0
0,0,0,0,0,0,0
0,0,0,0,0,0,0
0,0,0,0,0,0,0
0,0,0,0,0,0,0
0,0,0,0,0,0,0
0,0,0,0,0,0,0
0,0,0,0,0,0,0
0,0,2,2,2,0,0
0,2,1,1,1,2,0
2,1,1,1,1,1,2
2,1,1,1,1,1,2
0,2,1,1,1,2,0
0,0,1,2,2,0,0
0,0,0,0,0,0,0
endlayer

layer
0,0,0,0,0,0,0
0,0,0,0,0,0,0
0,0,1,1,1,0,0
0,1,1,1,1,1,0
1,1,1,1,1,1,1
3,1,1,1,1,1,1
0,3,1,1,1,1,0
0,0,3,1,1,0,0
0,0,0,0,0,0,0
0,0,0,0,0,0,0
0,0,0,0,0,0,0
0,0,0,0,0,0,0
0,0,0,0,0,0,0
0,0,0,0,0,0,0
0,0,0,0,0,0,0
0,0,0,0,0,0,0
0,0,0,0,0,0,0
0,0,0,0,0,0,0
0,0,0,0,0,0,0
0,0,0,0,0,0,0
0,0,0,0,0,0,0
0,0,0,0,0,0,0
0,0,0,0,0,0,0
0,0,0,0,0,0,0
0,0,0,0,0,0,0
0,0,0,0,0,0,0
0,0,0,0,0,0,0
0,0,0,0,0,0,0
0,0,0,0,0,0,0
0,0,1,1,1,0,0
0,1,1,1,1,1,0
1,1,1,1,1,1,1
1,1,1,1,1,1,1
0,1,1,1,1,1,0
0,0,1,1,1,0,0
0,0,0,0,0,0,0
0,0,0,0,0,0,0
endlayer

layer
0,0,0,0,0,0,0
0,0,0,0,0,0,0
0,0,1,1,1,0,0
0,3,1,1,1,1,0
3,1,1,1,1,1,1
3,1,1,1,1,1,1
0,3,1,1,1,1,0
0,0,3,3,3,0,0
0,0,0,0,0,0,0
0,0,0,0,0,0,0
0,0,0,0,0,0,0
0,0,0,0,0,0,0
0,0,0,0,0,0,0
0,0,0,0,0,0,0
0,0,0,0,0,0,0
0,0,0,0,0,0,0
0,0,0,0,0,0,0
0,0,0,0,0,0,0
0,0,0,0,0,0,0
0,0,0,0,0,0,0
0,0,0,0,0,0,0
0,0,0,0,0,0,0
0,0,0,0,0,0,0
0,0,0,0,0,0,0
0,0,0,0,0,0,0
0,0,0,0,0,0,0
0,0,0,0,0,0,0
0,0,0,0,0,0,0
0,0,0,0,0,0,0
0,0,1,1,1,0,0
0,1,1,1,1,1,0
1,1,1,1,1,1,1
1,1,1,1,1,1,1
0,1,1,1,1,1,0
0,0,1,1,1,0,0
0,0,0,0,0,0,0
0,0,0,0,0,0,0
endlayer

layer
0,0,0,0,0,0,0
0,0,0,0,0,0,0
0,0,0,0,0,0,0
0,0,3,3,1,0,0
0,3,1,1,1,1,0
3,1,1,1,1,1,1
1,1,1,1,1,1,1
0,1,1,1,1,3,0
0,0,1,8,3,0,0
0,0,0,0,0,0,0
0,0,0,0,0,0,0
0,0,0,0,0,0,0
0,0,0,0,0,0,0
0,0,0,0,0,0,0
0,0,0,0,0,0,0
0,0,0,0,0,0,0
0,0,0,0,0,0,0
0,0,0,0,0,0,0
0,0,0,0,0,0,0
0,0,0,0,0,0,0
0,0,0,0,0,0,0
0,0,0,0,0,0,0
0,0,0,0,0,0,0
0,0,0,0,0,0,0
0,0,0,0,0,0,0
0,0,0,0,0,0,0
0,0,0,0,0,0,0
0,0,0,0,0,0,0
0,0,1,8,1,0,0
0,1,1,1,1,1,0
1,1,1,1,1,1,1
1,1,1,1,1,1,1
0,1,1,1,1,1,0
0,0,1,1,1,0,0
0,0,0,0,0,0,0
0,0,0,0,0,0,0
0,0,0,0,0,0,0
endlayer

layer
0,0,0,0,0,0,0
0,0,0,0,0,0,0
0,0,0,0,0,0,0
0,0,3,3,3,0,0
0,3,1,1,1,3,0
1,1,1,1,1,1,3
1,1,1,1,1,1,3
0,1,1,1,1,3,0
0,1,1,1,1,3,0
0,0,1,1,3,0,0
0,0,0,0,0,0,0
0,0,0,0,0,0,0
0,0,0,0,0,0,0
0,0,0,0,0,0,0
0,0,0,0,0,0,0
0,0,0,0,0,0,0
0,0,0,0,0,0,0
0,0,0,0,0,0,0
0,0,0,0,0,0,0
0,0,0,0,0,0,0
0,0,0,0,0,0,0
0,0,0,0,0,0,0
0,0,0,0,0,0,0
0,0,0,0,0,0,0
0,0,0,0,0,0,0
0,0,0,0,0,0,0
0,0,0,0,0,0,0
0,0,1,1,1,0,0
0,1,1,1,1,1,0
0,1,1,1,1,1,0
1,1,1,1,1,1,1
1,1,1,1,1,1,1
0,1,1,1,1,1,0
0,0,1,1,1,0,0
0,0,0,0,0,0,0
0,0,0,0,0,0,0
0,0,0,0,0,0,0
endlayer

layer
0,0,0,0,0,0,0
0,0,0,0,0,0,0
0,0,0,0,0,0,0
0,0,0,0,0,0,0
0,0,3,3,3,0,0
0,1,1,1,1,3,0
1,1,1,1,1,1,3
1,1,1,1,1,1,3
0,1,1,1,1,1,0
0,1,1,1,1,1,0
0,0,1,1,1,0,0
0,0,1,1,1,0,0
0,0,0,0,0,0,0
0,0,0,0,0,0,0
0,0,0,0,0,0,0
0,0,0,0,0,0,0
0,0,0,0,0,0,0
0,0,0,0,0,0,0
0,0,0,0,0,0,0
0,0,0,0,0,0,0
0,0,0,0,0,0,0
0,0,0,0,0,0,0
0,0,0,0,0,0,0
0,0,0,0,0,0,0
0,0,0,0,0,0,0
0,0,1,1,1,0,0
0,0,1,1,1,0,0
0,1,1,1,1,1,0
0,1,1,1,1,1,0
1,1,1,1,1,1,1
1,1,1,1,1,1,1
0,1,1,1,1,1,0
0,0,1,1,1,0,0
0,0,0,0,0,0,0
0,0,0,0,0,0,0
0,0,0,0,0,0,0
0,0,0,0,0,0,0
endlayer

layer
0,0,0,0,0,0,0
0,0,0,0,0,0,0
0,0,0,0,0,0,0
0,0,0,0,0,0,0
0,0,0,0,0,0,0
0,0,1,1,1,0,0
0,1,1,1,1,1,0
5,1,1,1,1,1,1
5,1,1,1,1,1,1
5,1,1,1,1,1,1
0,5,1,1,1,5,0
0,5,1,1,1,5,0
0,0,5,5,5,0,0
0,0,5,5,5,0,0
0,0,0,0,0,0,0
0,0,0,0,0,0,0
0,0,0,0,0,0,0
0,0,0,0,0,0,0
0,0,0,0,0,0,0
0,0,0,0,0,0,0
0,0,0,0,0,0,0
0,0,0,0,0,0,0
0,0,0,0,0,0,0
0,0,1,1,1,0,0
0,0,1,1,1,0,0
0,1,1,1,1,1,0
0,1,1,1,1,1,0
1,1,1,1,1,1,1
1,1,1,1,1,1,1
1,1,1,1,1,1,1
0,1,1,1,1,1,0
0,0,1,1,1,0,0
0,0,0,0,0,0,0
0,0,0,0,0,0,0
0,0,0,0,0,0,0
0,0,0,0,0,0,0
0,0,0,0,0,0,0
endlayer

layer
0,0,0,0,0,0,0
0,0,0,0,0,0,0
0,0,0,0,0,0,0
0,0,0,0,0,0,0
0,0,0,0,0,0,0
0,0,0,0,0,0,0
0,0,5,5,5,0,0
0,5,1,1,1,5,0
5,5,1,1,1,1,5
5,5,1,1,1,1,5
5,1,1,1,1,1,5
5,1,1,1,1,1,5
0,5,1,1,1,5,0
0,5,1,1,1,5,0
0,0,5,5,5,0,0
0,0,5,5,5,0,0
0,0,1,5,5,0,0
0,0,1,5,5,0,0
0,0,1,8,5,0,0
0,0,1,1,5,0,0
0,0,1,1,1,0,0
0,0,1,1,1,0,0
0,0,1,1,1,0,0
0,1,1,1,1,1,0
0,1,1,1,1,1,0
1,1,1,1,1,1,1
1,1,1,1,1,1,1
1,1,1,1,1,1,1
1,1,1,1,1,1,1
0,1,1,1,1,1,0
0,0,1,1,5,0,0
0,0,0,0,0,0,0
0,0,0,0,0,0,0
0,0,0,0,0,0,0
0,0,0,0,0,0,0
0,0,0,0,0,0,0
0,0,0,0,0,0,0
endlayer

layer
0,0,0,0,0,0,0
0,0,0,0,0,0,0
0,0,0,0,0,0,0
0,0,0,0,0,0,0
0,0,0,0,0,0,0
0,0,0,0,0,0,0
0,0,0,0,0,0,0
0,0,6,6,6,0,0
0,1,1,1,1,6,0
0,1,1,1,1,6,0
1,1,1,1,1,1,1
1,1,1,1,1,1,1
1,1,1,1,1,1,5
1,1,1,1,1,1,5
0,5,1,1,1,5,0
0,5,1,1,1,5,0
0,5,1,1,1,5,0
0,5,5,1,1,5,0
0,5,1,1,1,5,0
0,5,1,1,1,5,0
0,5,1,1,1,5,0
0,5,1,1,1,5,0
0,5,1,1,1,1,0
1,1,1,1,1,1,1
1,1,1,1,1,1,1
1,1,1,1,1,1,1
1,1,1,1,1,1,1
0,1,1,1,1,1,0
0,1,1,1,1,1,0
0,0,1,5,5,0,0
0,0,0,0,0,0,0
0,0,0,0,0,0,0
0,0,0,0,0,0,0
0,0,0,0,0,0,0
0,0,0,0,0,0,0
0,0,0,0,0,0,0
0,0,0,0,0,0,0
endlayer

layer
0,0,0,0,0,0,0
0,0,0,0,0,0,0
0,0,0,0,0,0,0
0,0,0,0,0,0,0
0,0,0,0,0,0,0
0,0,0,0,0,0,0
0,0,0,0,0,0,0
0,0,0,0,0,0,0
0,0,1,6,6,0,0
0,0,1,1,6,0,0
0,1,1,1,1,6,0
0,1,1,1,1,1,0
1,1,1,1,1,1,1
1,1,1,1,1,1,1
1,1,1,1,1,1,5
1,1,1,1,1,1,5
1,1,1,1,1,1,5
1,1,1,1,1,1,5
1,1,1,1,1,1,5
1,1,1,1,1,1,5
1,1,1,1,1,1,5
1,1,1,1,1,1,5
5,1,1,1,1,1,5
5,1,1,1,1,1,5
5,5,1,1,1,1,5
0,5,1,1,1,5,0
0,5,5,1,1,5,0
0,0,5,5,5,0,0
0,0,5,5,5,0,0
0,0,0,0,0,0,0
0,0,0,0,0,0,0
0,0,0,0,0,0,0
0,0,0,0,0,0,0
0,0,0,0,0,0,0
0,0,0,0,0,0,0
0,0,0,0,0,0,0
0,0,0,0,0,0,0
endlayer

layer
0,0,0,0,0,0,0
0,0,0,0,0,0,0
0,0,0,0,0,0,0
0,0,0,0,0,0,0
0,0,0,0,0,0,0
0,0,0,0,0,0,0
0,0,0,0,0,0,0
0,0,0,0,0,0,0
0,0,0,0,0,0,0
0,0,0,0,0,0,0
0,0,1,1,6,0,0
0,0,1,6,6,0,0
0,1,1,1,1,1,0
0,1,1,1,1,1,0
1,1,1,1,1,1,1
1,1,1,1,1,1,1
1,1,1,1,1,1,1
1,1,1,1,1,1,1
1,1,1,1,1,1,1
1,1,1,1,1,1,1
1,1,1,1,1,1,1
1,1,1,1,1,1,1
1,1,1,1,1,1,1
0,1,1,1,1,1,0
0,1,1,1,1,1,0
0,0,1,1,1,0,0
0,0,1,1,1,0,0
0,0,0,0,0,0,0
0,0,0,0,0,0,0
0,0,0,0,0,0,0
0,0,0,0,0,0,0
0,0,0,0,0,0,0
0,0,0,0,0,0,0
0,0,0,0,0,0,0
0,0,0,0,0,0,0
0,0,0,0,0,0,0
0,0,0,0,0,0,0
endlayer

layer
0,0,0,0,0,0,0
0,0,0,0,0,0,0
0,0,0,0,0,0,0
0,0,0,0,0,0,0
0,0,0,0,0,0,0
0,0,0,0,0,0,0
0,0,0,0,0,0,0
0,0,0,0,0,0,0
0,0,0,0,0,0,0
0,0,0,0,0,0,0
0,0,0,0,0,0,0
0,0,0,0,0,0,0
0,0,6,6,6,0,0
0,0,6,6,6,0,0
0,6,1,1,1,6,0
0,6,1,1,1,6,0
0,6,1,1,1,6,0
0,6,1,1,1,6,0
0,1,1,1,1,6,0
0,1,1,1,1,6,0
0,1,1,1,1,6,0
0,1,1,1,1,6,0
0,1,1,1,1,1,0
0,0,1,1,1,0,0
0,0,1,1,1,0,0
0,0,0,0,0,0,0
0,0,0,0,0,0,0
0,0,0,0,0,0,0
0,0,0,0,0,0,0
0,0,0,0,0,0,0
0,0,0,0,0,0,0
0,0,0,0,0,0,0
0,0,0,0,0,0,0
0,0,0,0,0,0,0
0,0,0,0,0,0,0
0,0,0,0,0,0,0
0,0,0,0,0,0,0
endlayer

layer
0,0,0,0,0,0,0
0,0,0,0,0,0,0
0,0,0,0,0,0,0
0,0,0,0,0,0,0
0,0,0,0,0,0,0
0,0,0,0,0,0,0
0,0,0,0,0,0,0
0,0,0,0,0,0,0
0,0,0,0,0,0,0
0,0,0,0,0,0,0
0,0,0,0,0,0,0
0,0,0,0,0,0,0
0,0,0,0,0,0,0
0,0,0,0,0,0,0
0,0,6,6,6,0,0
0,0,6,6,6,0,0
0,0,6,6,6,0,0
0,0,6,6,6,0,0
0,0,6,6,6,0,0
0,0,6,6,6,0,0
0,0,6,6,6,0,0
0,0,6,6,6,0,0
0,0,1,6,6,0,0
0,0,0,0,0,0,0
0,0,0,0,0,0,0
0,0,0,0,0,0,0
0,0,0,0,0,0,0
0,0,0,0,0,0,0
0,0,0,0,0,0,0
0,0,0,0,0,0,0
0,0,0,0,0,0,0
0,0,0,0,0,0,0
0,0,0,0,0,0,0
0,0,0,0,0,0,0
0,0,0,0,0,0,0
0,0,0,0,0,0,0
0,0,0,0,0,0,0
endlayer

