
# Created by Ruins mod version 17.0 Ingame Parser
# authoring Player: ST753M

weight=1
embed_into_distance=6
acceptable_target_blocks=grass,dirt
unacceptable_target_blocks=flowing_water,water,flowing_lava,lava,ice,bedrock,netherrack,nether_brick,nether_brick_fence,soul_sand,quartz_ore,end_stone,obsidian,iron_bars,Natura:Cloud,slime_grass,slime_congealed,slime_dirt,clouds,natura:clouds
dimensions=10,13,13
allowable_overhang=6
max_leveling=2
leveling_buffer=-1
preserve_water=0
preserve_lava=0
preventRotation=1

biomesToSpawnIn=magical_forest,mystic_grove,enchanted_forest,crystal_forest

=0,100,air
rule1=0,100,preserveBlock
rule2=0,100,minecraft:dirt-0
rule3=0,100,thaumcraft:log_greatwood-1
rule4=0,100,thaumcraft:plank_silverwood-0
rule5=0,100,thaumcraft:slab_double_silverwood-0
rule6=0,100,thaumcraft:plank_greatwood-0
rule7=0,100,minecraft:crafting_table-0
rule8=0,100,thaumcraft:table_wood-0

rule9=0,100,thaumcraft:loot_crate_common-0,thaumcraft:loot_crate_common-0,thaumcraft:loot_crate_common-0,thaumcraft:loot_crate_common-0,thaumcraft:loot_crate_uncommon-0,thaumcraft:loot_crate_uncommon-0,thaumcraft:loot_crate_rare-0

rule10=0,100,minecraft:bed-10
rule11=0,100,minecraft:bed-2

rule12=0,100,ChestGenHook:chests/abandoned_mineshaft:3-2,ChestGenHook:chests/simple_dungeon:3-2,ChestGenHook:chests/village_blacksmith:3-2,ChestGenHook:chests/spawn_bonus_chest:6-2

rule13=0,100,thaumcraft:loot_urn_common-0,thaumcraft:loot_urn_common-0,thaumcraft:loot_urn_common-0,thaumcraft:loot_urn_common-0,thaumcraft:loot_urn_uncommon-0,thaumcraft:loot_urn_uncommon-0,thaumcraft:loot_urn_rare-0

rule14=0,100,thaumcraft:stairs_silverwood-3
rule15=0,100,thaumcraft:candle_white-0
rule16=0,100,minecraft:grass-0
rule17=0,100,thaumcraft:stairs_greatwood-3
rule18=0,100,minecraft:dark_oak_door-3
rule19=0,100,thaumcraft:stairs_silverwood-6
rule20=0,100,minecraft:dark_oak_door-8
rule21=0,100,thaumcraft:stairs_greatwood-6
rule22=0,100,minecraft:dark_oak_door-9
rule23=0,100,thaumcraft:stairs_greatwood-0
rule24=0,100,thaumcraft:stairs_greatwood-5
rule25=0,100,thaumcraft:stairs_greatwood-4
rule26=0,100,thaumcraft:stairs_greatwood-1

layer
1,2,2,2,2,2,2,2,2,2,2,2,1
2,3,4,5,5,4,5,4,5,5,4,3,2
2,4,5,5,4,4,4,4,4,5,5,4,2
2,5,5,4,4,5,4,5,4,4,5,5,2
2,5,4,4,5,5,4,5,5,4,4,5,2
2,4,4,5,5,4,4,4,5,5,4,4,2
2,5,4,4,4,4,5,4,4,4,4,5,2
2,4,4,5,5,4,4,4,5,5,4,4,2
2,5,4,4,5,5,4,5,5,4,4,5,2
2,5,5,4,4,5,4,5,4,4,5,5,2
2,4,5,5,4,4,4,4,4,5,5,4,2
2,3,4,5,5,4,5,4,5,5,4,3,2
1,2,2,2,2,2,2,2,2,2,2,2,1
endlayer

layer
1,2,2,2,2,2,2,2,2,2,2,2,1
2,3,6,6,6,6,6,6,6,6,6,3,2
2,6,7,7,7,0,0,0,0,0,0,6,2
2,6,7,7,0,9,0,0,0,0,8,6,2
2,6,12,0,0,0,0,0,0,11,10,6,2
2,6,0,13,0,0,0,0,0,11,10,6,2
2,6,0,0,0,0,0,0,0,0,8,6,2
2,6,0,0,0,0,0,0,0,0,0,6,2
2,6,0,0,0,0,0,0,0,0,0,6,2
2,6,8,0,0,0,0,14,6,6,6,6,2
2,6,8,0,0,0,0,14,6,6,6,6,2
2,3,6,6,6,6,6,6,6,6,6,3,2
1,2,2,2,2,2,2,2,2,2,2,2,1
endlayer

layer
1,2,2,2,2,2,2,2,2,2,2,2,1
2,3,4,5,4,5,4,5,4,5,4,3,2
2,4,7,7,13,0,0,0,0,0,0,4,2
2,5,9,0,0,0,0,0,0,0,15,5,2
2,4,0,0,0,0,0,0,0,0,0,4,2
2,5,0,0,0,0,0,0,0,0,0,5,2
2,4,0,0,0,0,0,0,0,0,0,4,2
2,5,0,0,0,0,0,0,0,0,0,5,2
2,4,0,0,0,0,0,0,0,0,0,4,6
2,5,15,0,0,0,0,0,14,5,4,5,2
2,4,0,0,0,0,0,0,14,5,4,4,2
2,3,4,5,4,5,4,5,4,5,4,3,6
1,2,2,2,2,2,2,2,2,2,2,2,1
endlayer

layer
1,2,2,2,2,2,2,2,2,2,2,2,1
2,3,4,5,4,5,4,5,4,5,4,3,2
2,4,7,0,0,0,0,0,0,0,0,4,2
2,5,0,0,0,0,0,0,0,0,0,5,2
2,4,0,0,0,0,0,0,0,0,0,4,2
2,5,0,0,0,0,0,0,0,0,0,5,2
2,4,0,0,0,0,0,0,0,0,0,4,2
2,5,0,0,0,0,0,0,0,0,0,5,2
2,4,0,0,0,0,0,0,0,0,0,4,6
2,5,0,0,0,0,0,0,0,14,4,5,6
2,4,0,0,0,0,0,0,0,14,4,4,6
2,3,4,5,4,5,4,5,4,5,4,3,6
1,2,2,2,2,2,2,2,2,2,2,2,1
endlayer

layer
1,16,2,2,2,2,2,2,2,2,2,16,1
16,3,4,5,4,5,4,5,4,5,4,3,16
2,4,0,0,0,0,0,0,0,0,0,4,2
2,5,0,0,0,0,0,0,0,0,0,5,2
2,4,0,0,0,0,0,0,0,0,0,4,2
2,5,0,0,0,0,0,0,0,0,0,5,2
2,4,0,0,0,0,0,0,0,0,0,4,2
2,5,0,0,0,0,0,0,0,0,0,5,2
2,4,0,0,0,0,0,0,0,0,0,4,6
2,5,0,0,0,0,0,0,0,0,14,5,2
2,4,0,0,0,0,0,0,0,0,14,4,2
16,3,4,5,4,5,4,5,4,5,4,3,6
1,16,2,2,2,2,2,2,2,2,2,16,1
endlayer

layer
1,1,16,16,2,2,2,2,2,16,16,1,1
1,16,6,6,6,6,6,6,6,6,6,16,1
16,6,0,0,0,0,0,0,0,0,0,6,16
16,6,0,0,0,0,0,0,0,0,0,6,2
2,6,0,0,0,0,0,0,0,0,0,6,2
2,6,0,0,0,0,0,0,0,0,0,6,2
2,6,0,0,0,0,0,0,0,0,0,6,2
2,6,0,0,0,0,0,0,0,0,0,6,2
2,6,0,0,0,0,0,0,0,0,0,6,6
16,6,0,0,0,0,0,0,0,0,0,17,6
16,6,0,0,0,0,0,0,0,0,0,17,6
1,16,6,6,6,6,6,6,6,6,6,6,6
1,1,16,16,2,2,2,2,2,16,16,1,1
endlayer

layer
1,1,1,1,16,16,16,16,16,1,1,1,1
1,1,16,16,2,2,2,2,2,16,16,1,1
1,16,5,5,4,4,4,4,4,5,5,16,1
1,16,5,4,4,5,4,5,4,4,5,16,16
16,2,4,4,5,5,4,5,5,4,4,16,16
16,2,4,5,5,4,4,4,5,5,4,16,16
16,2,4,4,4,4,5,4,4,4,4,2,1
16,2,4,5,5,4,4,4,5,5,4,16,0
16,2,4,4,5,5,4,5,5,4,4,6,0
1,16,5,4,4,5,4,5,19,0,0,0,18
1,16,5,5,4,4,4,4,19,0,0,0,18
1,1,16,16,2,2,2,2,6,6,6,6,0
1,1,1,1,16,16,16,16,16,1,1,1,0
endlayer

layer
1,1,1,1,1,1,1,1,1,1,1,1,1
1,1,1,1,16,16,16,16,16,1,1,1,1
1,1,16,16,16,16,16,16,16,16,16,1,1
1,1,16,16,16,16,16,16,16,16,16,1,1
1,16,16,16,2,2,2,2,16,16,16,1,1
1,16,16,16,2,2,16,2,2,16,16,1,1
1,16,16,2,2,2,2,2,2,16,16,0,0
1,16,16,2,2,2,2,16,2,16,16,0,0
1,16,16,2,2,2,2,2,16,6,6,6,0
1,1,16,16,2,16,2,2,16,21,0,0,20
1,1,16,16,16,16,16,16,16,21,0,0,22
1,1,1,1,16,16,16,16,16,6,6,6,0
1,1,1,1,1,1,1,1,1,1,1,0,0
endlayer

layer
1,1,1,1,1,1,1,1,1,1,1,1,1
1,1,1,1,1,1,1,1,1,1,1,1,1
1,1,1,1,1,1,1,1,1,1,1,1,1
1,1,1,1,1,1,1,1,1,1,1,1,1
1,1,1,1,16,16,16,16,1,1,1,1,1
1,1,1,1,16,16,16,16,16,1,1,0,0
1,1,1,16,16,16,16,16,16,1,1,0,0
1,1,1,16,16,16,16,16,16,1,1,0,0
1,1,1,16,16,16,16,16,1,17,23,23,23
1,1,1,1,16,1,16,16,1,17,6,6,24
1,1,1,1,1,1,1,1,1,17,6,6,25
1,1,1,1,1,1,1,1,1,17,26,26,26
1,1,1,1,1,1,1,1,1,1,1,1,0
endlayer

layer
1,1,1,1,1,1,1,1,1,1,1,1,1
1,1,1,1,1,1,1,1,1,1,1,1,1
1,1,1,1,1,1,1,1,1,1,1,1,1
1,1,1,1,1,1,1,1,1,1,1,1,1
1,1,1,1,1,1,1,1,1,1,1,0,0
1,1,1,1,1,1,1,1,1,1,1,0,0
1,1,1,1,1,1,1,1,1,1,1,0,0
1,1,1,1,1,1,1,1,1,1,1,0,0
1,1,1,1,1,1,1,1,1,1,1,0,0
1,1,1,1,1,1,1,1,1,1,17,23,23
1,1,1,1,1,1,1,1,1,1,17,26,26
1,1,1,1,1,1,1,1,1,1,1,0,0
1,1,1,1,1,1,1,1,1,1,1,1,1
endlayer

