
# Created by Ruins mod version 16.9 Ingame Parser
# authoring Player: ST753M

weight=1
embed_into_distance=-40
random_height_offset=-30,30
acceptable_target_blocks=
unacceptable_target_blocks=flowing_lava,lava
dimensions=25,11,11
allowable_overhang=999
max_leveling=0
leveling_buffer=-1
preserve_water=0
preserve_lava=0

biomesToSpawnIn=sky,end,the_end,void

rule1=0,100,preserveBlock
rule2=0,100,minecraft:end_stone-0,preserveBlock
rule3=0,100,minecraft:end_stone-0
rule4=0,100,minecraft:obsidian-0
rule5=0,100,minecraft:iron_bars-0
rule6=0,100,minecraft:cobblestone_wall-0
rule7=0,100,CommandBlock:RUINSTRIGGER /summon ender_crystal ~ ~0 ~ :@-1

layer
1,1,1,1,1,1,1,1,1,1,1
1,1,1,1,1,1,1,1,1,1,1
1,1,1,1,1,1,1,1,1,1,1
1,1,1,1,1,1,1,1,1,1,1
1,1,1,1,2,2,2,1,1,1,1
1,1,1,1,2,2,2,1,1,1,1
1,1,1,1,2,2,2,1,1,1,1
1,1,1,1,1,1,1,1,1,1,1
1,1,1,1,1,1,1,1,1,1,1
1,1,1,1,1,1,1,1,1,1,1
1,1,1,1,1,1,1,1,1,1,1
endlayer

layer
1,1,1,1,1,1,1,1,1,1,1
1,1,1,1,1,1,1,1,1,1,1
1,1,1,1,1,1,1,1,1,1,1
1,1,1,1,2,2,2,1,1,1,1
1,1,1,2,3,3,3,2,1,1,1
1,1,1,2,3,3,3,2,1,1,1
1,1,1,2,3,3,3,2,1,1,1
1,1,1,1,2,2,2,1,1,1,1
1,1,1,1,1,1,1,1,1,1,1
1,1,1,1,1,1,1,1,1,1,1
1,1,1,1,1,1,1,1,1,1,1
endlayer

layer
1,1,1,1,1,1,1,1,1,1,1
1,1,1,1,1,1,1,1,1,1,1
1,1,1,1,2,2,2,1,1,1,1
1,1,1,2,3,3,3,2,1,1,1
1,1,2,3,3,3,3,3,2,1,1
1,1,2,3,3,3,3,3,2,1,1
1,1,2,3,3,3,3,3,2,1,1
1,1,1,2,3,3,3,2,1,1,1
1,1,1,1,2,2,2,1,1,1,1
1,1,1,1,1,1,1,1,1,1,1
1,1,1,1,1,1,1,1,1,1,1
endlayer

layer
1,1,1,1,1,1,1,1,1,1,1
1,1,1,1,1,1,1,1,1,1,1
1,1,1,1,2,3,2,1,1,1,1
1,1,1,3,3,3,3,3,1,1,1
1,1,2,3,3,3,3,3,2,1,1
1,1,3,3,3,3,3,3,3,1,1
1,1,2,3,3,3,3,3,2,1,1
1,1,1,3,3,3,3,3,1,1,1
1,1,1,1,2,3,2,1,1,1,1
1,1,1,1,1,1,1,1,1,1,1
1,1,1,1,1,1,1,1,1,1,1
endlayer

layer
1,1,1,1,1,1,1,1,1,1,1
1,1,1,1,2,2,2,1,1,1,1
1,1,1,2,3,3,3,2,1,1,1
1,1,2,3,3,3,3,3,2,1,1
1,2,3,3,3,3,3,3,3,2,1
1,2,3,3,3,3,3,3,3,2,1
1,2,3,3,3,3,3,3,3,2,1
1,1,2,3,3,3,3,3,2,1,1
1,1,1,2,3,3,3,2,1,1,1
1,1,1,1,2,2,2,1,1,1,1
1,1,1,1,1,1,1,1,1,1,1
endlayer

layer
1,1,1,1,1,1,1,1,1,1,1
1,1,1,2,3,2,3,2,1,1,1
1,1,1,3,3,3,3,3,1,1,1
1,2,3,3,3,3,3,3,3,2,1
1,3,3,3,3,3,3,3,3,3,1
1,2,3,3,3,3,3,3,3,2,1
1,3,3,3,3,3,3,3,3,3,1
1,2,3,3,3,3,3,3,3,2,1
1,1,1,3,3,3,3,3,1,1,1
1,1,1,2,3,2,3,2,1,1,1
1,1,1,1,1,1,1,1,1,1,1
endlayer

layer
1,1,1,1,2,2,2,1,1,1,1
1,1,1,2,3,3,3,2,1,1,1
1,1,2,3,3,3,3,3,2,1,1
1,2,3,3,3,3,3,3,3,2,1
2,3,3,3,3,3,3,3,3,3,2
2,3,3,3,3,3,3,3,3,3,2
2,3,3,3,3,3,3,3,3,3,2
1,2,3,3,3,3,3,3,3,2,1
1,1,2,3,3,3,3,3,2,1,1
1,1,1,2,3,3,3,2,1,1,1
1,1,1,1,2,2,2,1,1,1,1
endlayer

layer
1,1,1,2,2,2,2,2,1,1,1
1,1,2,3,3,3,3,3,2,1,1
1,2,3,3,3,3,3,3,3,2,1
2,3,3,3,3,3,3,3,3,3,2
2,3,3,3,3,3,3,3,3,3,2
2,3,3,3,3,3,3,3,3,3,2
2,3,3,3,3,3,3,3,3,3,2
2,3,3,3,3,3,3,3,3,3,2
1,2,3,3,3,3,3,3,3,2,1
1,1,2,3,3,3,3,3,2,1,1
1,1,1,2,2,2,2,2,1,1,1
endlayer

layer
1,1,1,2,2,2,2,2,1,1,1
1,1,2,3,3,3,3,3,2,1,1
1,2,3,3,3,3,3,3,3,2,1
2,3,3,3,3,3,3,3,3,3,2
2,3,3,3,3,3,3,3,3,3,2
2,3,3,3,3,3,3,3,3,3,2
2,3,3,3,3,3,3,3,3,3,2
2,3,3,3,3,3,3,3,3,3,2
1,2,3,3,3,3,3,3,3,2,1
1,1,2,3,3,3,3,3,2,1,1
1,1,1,2,2,2,2,2,1,1,1
endlayer

layer
1,1,1,1,1,1,1,1,1,1,1
1,1,1,2,2,3,2,2,1,1,1
1,1,2,3,3,3,3,3,2,1,1
1,2,3,3,3,3,3,3,3,2,1
1,2,3,3,3,3,3,3,3,2,1
1,3,3,3,3,3,3,3,3,3,1
1,2,3,3,3,3,3,3,3,2,1
1,2,3,3,3,3,3,3,3,2,1
1,1,2,3,3,3,3,3,2,1,1
1,1,1,2,2,3,2,2,1,1,1
1,1,1,1,1,1,1,1,1,1,1
endlayer

layer
1,1,1,1,1,1,1,1,1,1,1
1,1,1,1,1,2,1,1,1,1,1
1,1,1,2,2,2,2,2,1,1,1
1,1,2,2,4,4,4,2,2,1,1
1,1,2,4,4,4,4,4,2,1,1
1,2,2,4,4,4,4,4,2,2,1
1,1,2,4,4,4,4,4,2,1,1
1,1,2,2,4,4,4,2,2,1,1
1,1,1,2,2,2,2,2,1,1,1
1,1,1,1,1,2,1,1,1,1,1
1,1,1,1,1,1,1,1,1,1,1
endlayer

layer
1,1,1,1,1,1,1,1,1,1,1
1,1,1,1,1,1,1,1,1,1,1
1,1,1,1,1,1,1,1,1,1,1
1,1,1,1,4,4,4,1,1,1,1
1,1,1,4,4,4,4,4,1,1,1
1,1,1,4,4,4,4,4,1,1,1
1,1,1,4,4,4,4,4,1,1,1
1,1,1,1,4,4,4,1,1,1,1
1,1,1,1,1,1,1,1,1,1,1
1,1,1,1,1,1,1,1,1,1,1
1,1,1,1,1,1,1,1,1,1,1
endlayer

layer
1,1,1,1,1,1,1,1,1,1,1
1,1,1,1,1,1,1,1,1,1,1
1,1,1,1,1,1,1,1,1,1,1
1,1,1,1,4,4,4,1,1,1,1
1,1,1,4,4,4,4,4,1,1,1
1,1,1,4,4,4,4,4,1,1,1
1,1,1,4,4,4,4,4,1,1,1
1,1,1,1,4,4,4,1,1,1,1
1,1,1,1,1,1,1,1,1,1,1
1,1,1,1,1,1,1,1,1,1,1
1,1,1,1,1,1,1,1,1,1,1
endlayer

layer
1,1,1,1,1,1,1,1,1,1,1
1,1,1,1,1,1,1,1,1,1,1
1,1,1,1,1,1,1,1,1,1,1
1,1,1,1,4,4,4,1,1,1,1
1,1,1,4,4,4,4,4,1,1,1
1,1,1,4,4,4,4,4,1,1,1
1,1,1,4,4,4,4,4,1,1,1
1,1,1,1,4,4,4,1,1,1,1
1,1,1,1,1,1,1,1,1,1,1
1,1,1,1,1,1,1,1,1,1,1
1,1,1,1,1,1,1,1,1,1,1
endlayer

layer
1,1,1,1,1,1,1,1,1,1,1
1,1,1,1,1,1,1,1,1,1,1
1,1,1,1,1,1,1,1,1,1,1
1,1,1,1,4,4,4,1,1,1,1
1,1,1,4,4,4,4,4,1,1,1
1,1,1,4,4,4,4,4,1,1,1
1,1,1,4,4,4,4,4,1,1,1
1,1,1,1,4,4,4,1,1,1,1
1,1,1,1,1,1,1,1,1,1,1
1,1,1,1,1,1,1,1,1,1,1
1,1,1,1,1,1,1,1,1,1,1
endlayer

layer
1,1,1,1,1,1,1,1,1,1,1
1,1,1,1,1,1,1,1,1,1,1
1,1,1,1,1,1,1,1,1,1,1
1,1,1,1,4,4,4,1,1,1,1
1,1,1,4,4,4,4,4,1,1,1
1,1,1,4,4,4,4,4,1,1,1
1,1,1,4,4,4,4,4,1,1,1
1,1,1,1,4,4,4,1,1,1,1
1,1,1,1,1,1,1,1,1,1,1
1,1,1,1,1,1,1,1,1,1,1
1,1,1,1,1,1,1,1,1,1,1
endlayer

layer
1,1,1,1,1,1,1,1,1,1,1
1,1,1,1,1,1,1,1,1,1,1
1,1,1,1,1,1,1,1,1,1,1
1,1,1,1,4,4,4,1,1,1,1
1,1,1,4,4,4,4,4,1,1,1
1,1,1,4,4,4,4,4,1,1,1
1,1,1,4,4,4,4,4,1,1,1
1,1,1,1,4,4,4,1,1,1,1
1,1,1,1,1,1,1,1,1,1,1
1,1,1,1,1,1,1,1,1,1,1
1,1,1,1,1,1,1,1,1,1,1
endlayer

layer
1,1,1,1,1,1,1,1,1,1,1
1,1,1,1,1,1,1,1,1,1,1
1,1,1,1,1,1,1,1,1,1,1
1,1,1,1,4,4,4,1,1,1,1
1,1,1,4,4,4,4,4,1,1,1
1,1,1,4,4,4,4,4,1,1,1
1,1,1,4,4,4,4,4,1,1,1
1,1,1,1,4,4,4,1,1,1,1
1,1,1,1,1,1,1,1,1,1,1
1,1,1,1,1,1,1,1,1,1,1
1,1,1,1,1,1,1,1,1,1,1
endlayer

layer
1,1,1,1,1,1,1,1,1,1,1
1,1,1,1,1,1,1,1,1,1,1
1,1,1,1,1,1,1,1,1,1,1
1,1,1,1,4,4,4,1,1,1,1
1,1,1,4,4,4,4,4,1,1,1
1,1,1,4,4,4,4,4,1,1,1
1,1,1,4,4,4,4,4,1,1,1
1,1,1,1,4,4,4,1,1,1,1
1,1,1,1,1,1,1,1,1,1,1
1,1,1,1,1,1,1,1,1,1,1
1,1,1,1,1,1,1,1,1,1,1
endlayer

layer
1,1,1,1,1,1,1,1,1,1,1
1,1,1,1,1,1,1,1,1,1,1
1,1,1,1,1,1,1,1,1,1,1
1,1,1,1,4,4,4,1,1,1,1
1,1,1,4,4,4,4,4,1,1,1
1,1,1,4,4,4,4,4,1,1,1
1,1,1,4,4,4,4,4,1,1,1
1,1,1,1,4,4,4,1,1,1,1
1,1,1,1,1,1,1,1,1,1,1
1,1,1,1,1,1,1,1,1,1,1
1,1,1,1,1,1,1,1,1,1,1
endlayer

layer
1,1,1,1,1,1,1,1,1,1,1
1,1,1,1,1,1,1,1,1,1,1
1,1,1,1,1,1,1,1,1,1,1
1,1,1,1,4,4,4,1,1,1,1
1,1,1,4,4,4,4,4,1,1,1
1,1,1,4,4,4,4,4,1,1,1
1,1,1,4,4,4,4,4,1,1,1
1,1,1,1,4,4,4,1,1,1,1
1,1,1,1,1,1,1,1,1,1,1
1,1,1,1,1,1,1,1,1,1,1
1,1,1,1,1,1,1,1,1,1,1
endlayer

layer
1,1,1,1,1,1,1,1,1,1,1
1,1,1,1,1,1,1,1,1,1,1
1,1,1,1,1,1,1,1,1,1,1
1,1,1,1,4,4,4,1,1,1,1
1,1,1,4,4,4,4,4,1,1,1
1,1,1,4,4,4,4,4,1,1,1
1,1,1,4,4,4,4,4,1,1,1
1,1,1,1,4,4,4,1,1,1,1
1,1,1,1,1,1,1,1,1,1,1
1,1,1,1,1,1,1,1,1,1,1
1,1,1,1,1,1,1,1,1,1,1
endlayer

layer
1,1,1,1,1,1,1,1,1,1,1
1,1,1,1,1,1,1,1,1,1,1
1,1,1,1,1,1,1,1,1,1,1
1,1,1,1,4,4,4,1,1,1,1
1,1,1,4,4,4,4,4,1,1,1
1,1,1,4,4,4,4,4,1,1,1
1,1,1,4,4,4,4,4,1,1,1
1,1,1,1,4,4,4,1,1,1,1
1,1,1,1,1,1,1,1,1,1,1
1,1,1,1,1,1,1,1,1,1,1
1,1,1,1,1,1,1,1,1,1,1
endlayer

layer
1,1,1,1,1,1,1,1,1,1,1
1,1,1,1,1,1,1,1,1,1,1
1,1,1,1,1,1,1,1,1,1,1
1,1,1,1,5,5,5,1,1,1,1
1,1,1,5,5,0,5,5,1,1,1
1,1,1,5,0,6,0,5,1,1,1
1,1,1,5,5,0,5,5,1,1,1
1,1,1,1,5,5,5,1,1,1,1
1,1,1,1,1,1,1,1,1,1,1
1,1,1,1,1,1,1,1,1,1,1
1,1,1,1,1,1,1,1,1,1,1
endlayer

layer
1,1,1,1,1,1,1,1,1,1,1
1,1,1,1,1,1,1,1,1,1,1
1,1,1,1,1,1,1,1,1,1,1
1,1,1,1,1,1,1,1,1,1,1
1,1,1,1,0,0,0,1,1,1,1
1,1,1,1,0,7,0,1,1,1,1
1,1,1,1,0,0,0,1,1,1,1
1,1,1,1,1,1,1,1,1,1,1
1,1,1,1,1,1,1,1,1,1,1
1,1,1,1,1,1,1,1,1,1,1
1,1,1,1,1,1,1,1,1,1,1
endlayer

