
# Created by Ruins mod version 17.0 Ingame Parser
# authoring Player: ST753M

weight=1
embed_into_distance=5
acceptable_target_blocks=
unacceptable_target_blocks=flowing_water,water,flowing_lava,lava,ice,bedrock,netherrack,nether_brick,nether_brick_fence,soul_sand,quartz_ore,end_stone,obsidian,iron_bars,Natura:Cloud,slime_grass,slime_congealed,slime_dirt,clouds,natura:clouds
dimensions=11,10,10
allowable_overhang=5
max_leveling=2
leveling_buffer=0
preserve_water=0
preserve_lava=0

biomesToSpawnIn=swampland,mutated_swampland,wetland,quagmire,lush_swamp,mangrove,marsh,bayou,bog,bamboo_forest,dead_swamp,moor,dead_swamp,coralium_infested_swamp,forest,maple_woods,boreal_forest,forest_hills,woodland,seasonal_forest,temperate_rainforest,fen,grove,sacred_springs,land_of_lakes,forested_hills,lush_hills,thicket,extreme_hills,smaller_extreme_hills,plains,prairie,shrubland,chaparral,grassland,meadow,orchard,rocky_plains,rocky_plateau,brushland,steppe,wasteland,tundra

rule1=0,100,preserveBlock
rule2=0,100,minecraft:log-0
rule3=0,100,minecraft:log-8
rule4=0,100,minecraft:log-4
rule5=0,100,minecraft:planks-1
rule6=0,100,minecraft:planks-0
rule7=0,100,minecraft:oak_stairs-0
rule8=0,100,minecraft:crafting_table-0
rule9=0,100,minecraft:oak_stairs-2
rule10=0,100,minecraft:spruce_stairs-0
rule11=0,40,ChestGenHook:chests/simple_dungeon:3-4
rule12=0,100,minecraft:spruce_stairs-4
rule13=0,100,minecraft:spruce_stairs-2
rule14=0,100,minecraft:oak_stairs-6
rule15=0,100,minecraft:spruce_stairs-1
rule16=0,100,minecraft:oak_stairs-3
rule17=0,100,minecraft:wooden_slab-1
rule18=0,100,minecraft:oak_stairs-1
rule19=0,100,minecraft:oak_stairs-5
rule20=0,100,minecraft:oak_stairs-4
rule21=0,100,minecraft:oak_stairs-7
rule22=0,100,minecraft:spruce_stairs-6
rule23=0,100,MobSpawner:cave_spider,MobSpawner:spider,MobSpawner:silverfish,MobSpawner:skeleton,MobSpawner:zombie,MobSpawner:zombie,minecraft:log-0,minecraft:log-0,minecraft:log-0,minecraft:log-0,minecraft:log-0,minecraft:log-0
rule24=0,100,minecraft:web-0
rule25=0,100,minecraft:wooden_slab-9
rule26=0,100,minecraft:spruce_stairs-7
rule27=0,100,minecraft:spruce_stairs-5
rule28=0,100,minecraft:spruce_stairs-3

layer
1,1,1,1,1,1,1,1,1,1
2,3,3,3,2,3,3,3,2,1
4,5,5,5,5,5,5,5,4,1
4,5,5,5,5,5,5,5,4,1
4,5,5,5,5,5,5,5,4,1
2,5,5,5,5,5,5,5,2,1
4,5,5,5,5,5,5,5,4,1
4,5,5,5,5,5,5,5,4,1
4,5,5,5,5,5,5,5,4,1
2,3,3,3,2,3,3,3,2,1
endlayer

layer
1,1,1,1,1,1,1,1,1,1
2,6,7,6,2,6,7,6,2,1
6,8,0,0,0,0,8,0,6,1
6,0,0,0,0,8,0,0,9,1
6,11,10,0,0,0,0,0,6,1
2,5,13,0,0,0,0,12,2,1
16,5,0,0,0,0,0,15,14,1
6,17,17,0,0,0,0,17,6,1
6,0,0,8,0,0,0,0,6,1
2,19,6,6,2,6,6,18,2,1
endlayer

layer
1,1,1,1,1,1,1,1,1,1
2,20,21,20,2,20,6,6,2,1
6,0,0,0,0,0,0,0,14,1
16,0,0,0,0,0,0,0,6,1
21,0,0,0,0,0,0,12,6,1
23,22,0,0,0,0,0,17,2,1
21,17,0,0,0,0,0,0,6,1
16,0,0,0,0,0,0,0,14,1
6,24,0,0,0,0,0,0,6,1
2,19,18,18,2,6,19,6,2,1
endlayer

layer
1,1,1,1,1,1,1,1,1,1
2,6,6,6,2,6,6,6,2,1
21,0,0,0,0,0,24,0,6,1
21,0,0,0,0,0,0,12,6,1
6,0,0,0,0,0,0,15,14,1
2,0,0,0,0,0,0,0,2,1
6,0,0,0,0,0,0,0,9,1
6,24,0,0,0,0,0,0,6,1
21,0,0,0,0,0,0,0,6,1
2,6,6,19,2,6,19,6,2,1
endlayer

layer
1,1,1,1,1,1,1,1,1,1
2,3,3,3,2,3,3,3,2,1
4,5,15,5,5,5,5,5,4,1
4,5,5,5,10,13,5,15,4,1
4,5,13,5,13,15,17,0,4,1
2,5,10,17,17,17,10,0,2,1
4,5,5,13,17,5,5,0,4,1
4,5,5,5,10,13,5,25,4,1
4,5,5,5,5,5,5,5,4,1
2,3,3,3,2,3,3,3,2,1
endlayer

layer
1,1,1,1,1,1,1,1,1,1
2,6,6,6,2,6,6,6,2,1
18,8,0,0,0,0,0,0,6,1
9,0,0,0,0,0,0,0,6,1
6,0,0,0,0,0,0,0,6,1
2,0,0,0,0,0,0,0,2,1
18,0,0,0,0,0,0,0,6,1
0,0,0,0,0,0,0,0,9,1
0,0,0,0,0,0,0,8,6,1
2,9,6,6,2,20,6,18,2,1
endlayer

layer
1,1,1,1,1,1,1,1,1,1
2,18,0,6,2,6,0,21,2,1
6,0,0,0,0,0,0,0,6,1
0,0,0,0,0,0,0,0,0,1
16,0,0,0,0,0,0,0,9,1
0,0,0,0,0,0,0,0,2,1
0,0,0,0,0,0,0,0,6,1
0,0,0,0,0,0,0,0,0,1
0,0,0,0,0,0,0,0,6,1
0,0,0,16,2,6,0,6,2,1
endlayer

layer
1,1,1,1,1,1,1,1,1,1
2,14,21,6,2,6,6,6,2,1
6,0,0,0,0,0,0,0,6,1
19,0,0,0,0,0,0,0,6,1
0,0,0,0,0,0,0,0,20,1
0,0,0,0,0,0,0,0,2,1
0,0,0,0,0,0,0,0,19,1
0,0,0,0,0,0,0,0,6,1
0,0,0,0,0,0,0,0,6,1
0,0,0,19,2,6,21,6,2,1
endlayer

layer
17,17,10,10,10,10,10,10,10,17
2,3,3,3,2,3,3,3,2,10
0,0,17,17,17,17,17,0,4,13
0,0,0,0,17,17,0,0,4,13
0,0,0,0,0,0,0,17,4,13
0,0,0,0,0,0,0,17,2,13
0,0,0,0,0,0,17,17,4,13
0,0,0,0,0,0,0,17,4,13
0,0,0,0,0,0,0,0,4,13
0,0,0,0,2,3,3,3,2,13
endlayer

layer
0,0,0,0,0,0,0,0,0,0
0,10,10,10,10,10,10,10,10,0
0,0,27,27,27,27,27,26,13,0
0,0,0,0,0,0,0,26,13,0
0,0,0,0,0,0,0,26,13,0
0,0,0,0,0,0,0,26,13,0
0,0,0,0,0,0,0,26,13,0
0,0,0,0,0,0,0,26,13,0
0,0,0,0,0,25,12,26,13,0
0,0,0,0,0,28,15,15,13,0
endlayer

layer
0,0,0,0,0,0,0,0,0,0
0,0,0,0,0,0,0,0,0,0
0,0,0,0,10,13,10,17,0,0
0,0,0,0,0,27,26,13,0,0
0,0,0,0,0,0,0,10,0,0
0,0,0,0,0,0,26,13,0,0
0,0,0,0,0,0,27,13,0,0
0,0,0,0,0,0,0,13,0,0
0,0,0,0,0,0,17,17,0,0
0,0,0,0,0,0,0,0,0,0
endlayer

