
# Created by Ruins mod version 17.0 Ingame Parser
# authoring Player: ST753M

weight=1
embed_into_distance=2
acceptable_target_blocks=
unacceptable_target_blocks=flowing_water,water,flowing_lava,lava,ice,bedrock,netherrack,nether_brick,nether_brick_fence,soul_sand,quartz_ore,end_stone,obsidian,iron_bars,Natura:Cloud,slime_grass,slime_congealed,slime_dirt,clouds,natura:clouds
dimensions=8,10,10
allowable_overhang=2
max_leveling=2
leveling_buffer=0
preserve_water=0
preserve_lava=0

biomesToSpawnIn=swampland,mutated_swampland,wetland,quagmire,lush_swamp,mangrove,marsh,bayou,bog,bamboo_forest,dead_swamp,moor,dead_swamp,coralium_infested_swamp,forest,maple_woods,boreal_forest,forest_hills,woodland,seasonal_forest,temperate_rainforest,fen,grove,sacred_springs,land_of_lakes,forested_hills,lush_hills,thicket,extreme_hills,smaller_extreme_hills,plains,prairie,shrubland,chaparral,grassland,meadow,orchard,rocky_plains,rocky_plateau,brushland,steppe,wasteland,tundra


=0,100,preserveBlock
rule1=0,100,minecraft:log-0
rule2=0,100,minecraft:log-8
rule3=0,100,minecraft:log-4
rule4=0,100,minecraft:planks-1
rule5=0,100,minecraft:spruce_stairs-1
rule6=0,100,minecraft:spruce_stairs-3
rule7=0,100,minecraft:wooden_slab-1
rule8=0,100,minecraft:spruce_stairs-0
rule9=0,100,minecraft:wooden_slab-9
rule10=0,100,minecraft:planks-0
rule11=0,100,minecraft:oak_stairs-0
rule12=0,100,minecraft:oak_stairs-1

rule13=0,100,minecraft:bed-10
^0,100,preserveBlock
rule14^0,100,minecraft:bed-2
^0,100,preserveBlock

rule15=0,20,ChestGenHook:chests/spawn_bonus_chest:3-5
rule16=0,100,minecraft:oak_stairs-2
rule17=0,100,minecraft:spruce_door-0
rule18=0,100,minecraft:wooden_slab-0
rule19=0,100,minecraft:crafting_table-0
rule20=0,100,minecraft:oak_stairs-5
rule21=0,100,minecraft:oak_stairs-6
rule22=0,100,minecraft:oak_stairs-4
rule23=0,100,minecraft:oak_stairs-3
rule24=0,100,minecraft:spruce_door-8
rule25=0,100,minecraft:oak_stairs-7
rule26=0,100,minecraft:wooden_slab-8
rule27=0,100,minecraft:spruce_stairs-2
rule28=0,100,minecraft:spruce_stairs-5
rule29=0,100,minecraft:spruce_stairs-7
rule30=0,100,minecraft:spruce_stairs-4
rule31=0,100,minecraft:double_wooden_slab-1

layer
0,0,0,0,0,0,0,0,0,0
1,0,0,0,1,0,0,0,1,0
0,0,0,0,0,0,0,0,0,0
0,0,0,0,0,0,0,0,0,0
0,0,0,0,0,0,0,0,0,0
1,0,0,0,1,0,0,0,1,0
0,0,0,0,0,0,0,0,0,0
0,0,0,0,0,0,0,0,0,0
0,0,0,0,0,0,0,0,0,0
1,0,0,0,1,0,0,0,0,0
endlayer

layer
0,0,0,0,0,0,0,0,0,0
1,2,2,2,1,2,2,2,1,0
3,4,4,4,4,5,4,4,3,0
3,4,5,4,7,6,4,4,3,0
3,4,4,7,6,8,4,4,3,0
1,4,4,4,1,2,2,2,1,0
3,7,8,4,3,9,9,0,0,0
3,4,6,4,3,9,0,0,0,0
3,4,4,4,3,0,0,0,0,0
1,2,2,2,1,0,0,0,0,0
endlayer

layer
0,0,0,0,0,0,0,0,0,0
1,10,12,10,1,10,11,10,1,0
10,15,0,0,0,0,14,13,10,0
10,0,0,0,0,0,0,0,10,0
10,0,0,0,0,0,0,0,16,0
1,0,0,0,1,10,17,10,1,0
10,0,0,0,10,0,0,0,0,0
18,0,0,0,10,0,0,0,0,0
11,0,0,19,10,0,0,0,0,0
1,18,10,20,1,0,0,0,0,0
endlayer

layer
0,0,0,0,0,0,0,0,0,0
1,16,0,22,1,21,0,10,1,0
10,0,0,0,0,0,0,0,10,0
0,0,0,0,0,0,0,0,0,0
22,0,0,0,0,0,0,0,23,0
1,0,0,0,1,10,24,10,1,0
23,0,0,0,12,0,0,0,0,0
0,0,0,0,0,0,0,0,0,0
0,0,0,0,10,0,0,0,0,0
0,0,0,10,1,0,0,0,0,0
endlayer

layer
0,0,0,0,0,0,0,0,0,0
1,10,10,10,1,10,10,22,1,0
10,0,0,0,0,0,0,0,20,0
25,0,0,0,0,0,0,0,21,0
10,0,0,0,0,0,0,0,10,0
1,0,0,0,1,10,20,10,1,0
10,0,0,0,10,0,0,0,0,0
20,0,0,0,26,0,0,0,0,0
0,0,0,0,22,0,0,0,0,0
0,0,25,10,1,0,0,0,0,0
endlayer

layer
0,7,8,8,6,8,27,8,27,0
1,2,2,2,1,2,2,2,1,8
3,0,0,7,7,7,0,7,3,27
18,0,0,0,0,7,7,7,3,5
0,0,0,0,7,7,7,7,3,0
0,0,0,0,1,2,2,2,1,7
0,0,0,0,3,5,5,5,27,7
0,0,0,0,3,27,0,0,0,0
0,0,0,0,3,5,0,0,0,0
0,0,0,0,1,0,0,0,0,0
endlayer

layer
0,0,0,0,0,0,0,0,0,0
7,7,8,6,8,7,8,8,27,0
0,0,0,0,0,28,28,0,27,0
0,0,0,0,0,0,0,29,8,0
0,0,9,29,30,30,30,29,27,0
0,0,0,29,27,5,5,5,27,0
0,0,0,9,27,0,0,0,0,0
0,0,0,0,5,0,0,0,0,0
0,0,0,0,7,0,0,0,0,0
0,0,0,0,0,0,0,0,0,0
endlayer

layer
0,0,0,0,0,0,0,0,0,0
0,0,0,0,0,0,0,0,0,0
0,0,0,0,0,0,7,0,0,0
0,0,0,0,0,7,31,27,0,0
0,0,0,7,5,5,5,5,0,0
0,0,0,0,0,0,0,0,0,0
0,0,0,0,0,0,0,0,0,0
0,0,0,0,0,0,0,0,0,0
0,0,0,0,0,0,0,0,0,0
0,0,0,0,0,0,0,0,0,0
endlayer

