
# Created by Ruins mod version 17.0 Ingame Parser
# authoring Player: ST753M

weight=1
embed_into_distance=4
acceptable_target_blocks=grass,dirt,podzol,biomesoplenty:grass,biomesoplenty:dirt
unacceptable_target_blocks=flowing_water,water,flowing_lava,lava
dimensions=22,19,12
allowable_overhang=6
max_leveling=2
leveling_buffer=0
preserve_water=0
preserve_lava=0
preventRotation=1

biomesToSpawnIn=swampland,mutated_swampland,lush_swamp,bayou,bog,dead_swamp,coralium_infested_swamp,forest,maple_woods,boreal_forest,forest_hills,woodland,seasonal_forest,temperate_rainforest,fen,grove,sacred_springs,land_of_lakes,forested_hills,lush_hills,thicket,roofed_forest,mutated_roofed_forest,taiga,taiga_hills,mutated_redwood_taiga,mutated_redwood_taiga_hills,redwood_taiga,mutated_taiga,redwood_taiga_hills,redwood_forest,coniferous_forest,shield,dead_forest,autumnal_wooded_hills,autumnal_woods,rocky_plains,rocky_plateau,mountain_foothills,alps_foothills,highland,darklands_forest,darklands_hills

=0,100,air
rule1=0,100,preserveBlock
rule2=0,100,minecraft:log-0
rule3=0,100,rustic:slate-0
rule4=0,100,minecraft:spruce_stairs-7
rule5=0,100,minecraft:log-8
rule6=0,100,minecraft:log-4
rule7=0,100,minecraft:planks-1
rule8=0,100,minecraft:spruce_stairs-3
rule9=0,100,rustic:clay_wall_cross-0
rule10=0,100,rustic:condenser-7
rule11=0,100,rustic:table_oak-0
rule12=0,100,rustic:chair_oak-2
rule13=0,100,rustic:stairs_slate_roof-6
rule14=0,100,minecraft:crafting_table-0
rule15=0,100,rustic:clay_wall_diag-0
rule16=0,100,rustic:clay_wall_diag-2
rule17=0,100,minecraft:spruce_fence-0
rule18=0,100,minecraft:spruce_door-1
rule19=0,100,minecraft:spruce_stairs-4
rule20=0,100,minecraft:spruce_stairs-1
rule21=0,100,rustic:clay_wall_diag-3
rule22=0,100,minecraft:stained_glass_pane-8
rule23=0,100,rustic:condenser-3
rule24=0,100,rustic:iron_lantern-1
rule25=0,100,rustic:evaporating_basin-0
rule26=0,100,minecraft:spruce_stairs-6
rule27=0,100,minecraft:spruce_door-8
rule28=0,100,rustic:clay_wall_diag-1
rule29=0,100,rustic:vase-0

rule30=0,100,rustic:brewing_barrel-0

rule31=0,100,rustic:chair_oak-0
rule32=0,100,minecraft:spruce_door-0

rule33=0,100,minecraft:bed-0
rule34=0,100,minecraft:bed-8

rule35=0,100,minecraft:bookshelf-0
rule36=0,100,minecraft:spruce_stairs-5
rule37=0,100,minecraft:spruce_stairs-0
rule38=0,100,rustic:stairs_slate_roof-2
rule39=0,100,rustic:stairs_slate_roof-3
rule40=0,100,rustic:stairs_slate_roof-0
rule41=0,100,rustic:stairs_slate_roof-1
rule42=0,100,minecraft:spruce_stairs-2
rule43=0,100,rustic:stairs_slate_roof-7
rule44=0,100,rustic:stairs_slate_roof-5
rule45=0,100,rustic:stairs_slate_roof-4
rule46=0,100,rustic:slate_roof-0

layer
1,1,1,1,1,1,1,1,1,1,1,1
1,1,1,1,1,1,1,1,1,1,1,1
1,1,1,2,1,1,1,1,2,1,1,1
1,1,1,1,3,3,3,3,1,1,1,1
1,1,1,1,3,3,3,3,1,1,1,1
1,1,1,1,3,3,3,3,1,1,1,1
1,1,1,1,3,3,3,3,1,1,1,1
1,1,1,2,3,3,3,3,2,1,1,1
1,1,1,1,3,3,3,3,1,1,1,1
1,1,1,1,3,3,3,3,1,1,1,1
1,1,1,1,3,3,3,3,1,1,1,1
1,1,1,2,3,3,3,3,2,1,1,1
1,1,1,1,3,3,3,3,1,1,1,1
1,1,1,1,3,3,3,3,1,1,1,1
1,1,1,1,3,3,3,3,1,1,1,1
1,1,1,1,3,3,3,3,1,1,1,1
1,1,1,2,1,1,1,1,2,1,1,1
1,1,1,1,1,1,1,1,1,1,1,1
1,1,1,1,1,1,1,1,1,1,1,1
endlayer

layer
1,1,1,1,1,1,1,1,1,1,1,1
1,1,1,1,1,1,1,1,1,1,1,1
1,1,1,2,1,1,1,1,2,1,1,1
1,1,1,1,3,3,3,3,1,1,1,1
1,1,1,1,3,3,3,3,1,1,1,1
1,1,1,1,3,3,3,3,1,1,1,1
1,1,1,1,3,3,3,3,1,1,1,1
1,1,1,2,3,3,3,3,2,1,1,1
1,1,1,4,3,3,3,3,1,1,1,1
1,1,1,4,3,3,3,3,1,1,1,1
1,1,1,4,3,3,3,3,1,1,1,1
1,1,1,2,3,3,3,3,2,1,1,1
1,1,1,1,3,3,3,3,1,1,1,1
1,1,1,1,3,3,3,3,1,1,1,1
1,1,1,1,3,3,3,3,1,1,1,1
1,1,1,1,3,3,3,3,1,1,1,1
1,1,1,2,1,1,1,1,2,1,1,1
1,1,1,1,1,1,1,1,1,1,1,1
1,1,1,1,1,1,1,1,1,1,1,1
endlayer

layer
1,1,1,1,1,1,1,1,1,1,1,1
1,1,1,1,1,1,1,1,1,1,1,1
1,1,1,2,1,1,1,1,2,1,1,1
1,1,1,1,3,3,3,3,1,1,1,1
1,1,1,1,3,3,3,3,1,1,1,1
1,1,1,1,3,3,3,3,1,1,1,1
1,1,1,1,3,3,3,3,1,1,1,1
1,4,5,2,3,3,3,3,2,1,1,1
1,0,4,5,3,3,3,3,1,1,1,1
1,0,4,5,3,3,3,3,1,1,1,1
1,0,4,5,3,3,3,3,1,1,1,1
1,4,5,2,3,3,3,3,2,1,1,1
1,1,1,1,3,3,3,3,1,1,1,1
1,1,1,1,3,3,3,3,1,1,1,1
1,1,1,1,3,3,3,3,1,1,1,1
1,1,1,1,3,3,3,3,1,1,1,1
1,1,1,2,1,1,1,1,2,1,1,1
1,1,1,1,1,1,1,1,1,1,1,1
1,1,1,1,1,1,1,1,1,1,1,1
endlayer

layer
1,1,1,1,1,1,1,1,1,1,1,1
1,1,1,1,1,1,1,1,1,1,1,1
1,1,1,2,5,5,5,5,2,1,1,1
1,1,1,6,3,3,3,3,6,1,1,1
1,1,1,6,3,3,3,3,6,1,1,1
1,1,1,6,3,3,3,3,6,1,1,1
1,1,1,6,3,3,3,3,6,1,1,1
1,2,5,2,3,3,3,3,2,1,1,1
1,8,7,6,3,3,3,3,6,1,1,1
1,8,7,6,3,3,3,3,6,1,1,1
1,8,7,6,3,3,3,3,6,1,1,1
1,2,5,2,3,3,3,3,2,1,1,1
1,1,1,6,3,3,3,3,6,1,1,1
1,1,1,6,3,3,3,3,6,1,1,1
1,1,1,6,3,3,3,3,6,1,1,1
1,1,1,6,3,3,3,3,6,1,1,1
1,1,1,2,5,5,5,5,2,1,1,1
1,1,1,1,1,1,1,1,1,1,1,1
1,1,1,1,1,1,1,1,1,1,1,1
endlayer

layer
1,1,1,1,1,1,1,1,1,1,1,1
1,1,1,1,1,1,1,1,1,1,1,1
1,1,1,2,9,9,9,9,2,1,1,1
1,1,1,9,10,0,0,0,9,1,1,1
1,1,1,9,13,0,12,11,9,1,1,1
1,1,1,9,13,0,12,11,9,1,1,1
1,1,1,9,14,0,0,0,9,1,1,1
1,2,17,2,16,0,0,15,2,1,1,1
1,0,0,9,0,0,0,0,9,1,1,1
1,0,0,18,0,0,0,0,9,1,1,1
1,0,0,9,0,0,0,0,9,1,1,1
1,2,17,2,19,0,0,0,2,1,1,1
1,1,1,9,20,0,0,0,9,1,1,1
1,1,1,9,0,0,0,11,9,1,1,1
1,1,1,9,0,0,12,11,9,1,1,1
1,1,1,9,0,0,0,0,9,1,1,1
1,1,1,2,9,9,9,9,2,1,1,1
1,1,1,1,1,1,1,1,1,1,1,1
1,1,1,1,1,1,1,1,1,1,1,1
endlayer

layer
1,1,1,1,1,1,1,1,1,1,1,1
1,1,1,1,1,1,1,1,1,1,1,1
1,1,1,2,21,22,22,21,2,1,1,1
1,1,1,16,23,0,0,0,15,1,1,1
1,1,1,22,24,0,0,0,22,1,1,1
1,1,1,22,0,0,0,0,22,1,1,1
1,1,1,16,25,0,0,0,15,1,1,1
1,8,26,2,16,0,0,15,2,1,1,1
1,0,0,21,0,0,0,0,15,1,1,1
1,0,0,27,0,0,0,0,22,1,1,1
1,0,0,28,19,0,0,0,15,1,1,1
1,8,26,2,20,0,0,0,2,1,1,1
1,1,1,16,0,0,0,0,15,1,1,1
1,1,1,22,0,0,0,24,22,1,1,1
1,1,1,22,0,0,0,0,22,1,1,1
1,1,1,16,0,0,0,0,15,1,1,1
1,1,1,2,28,22,22,28,2,1,1,1
1,1,1,1,1,1,1,1,1,1,1,1
1,1,1,1,1,1,1,1,1,1,1,1
endlayer

layer
1,1,1,1,1,1,1,1,1,1,1,1
1,1,1,1,1,1,1,1,1,1,1,1
1,1,1,2,21,22,22,21,2,1,1,1
1,1,1,16,0,0,0,0,15,1,1,1
1,1,1,22,0,0,0,0,22,1,1,1
1,1,1,22,0,0,0,0,22,1,1,1
1,1,1,16,0,0,0,0,15,1,1,1
1,0,24,2,28,16,15,28,2,1,1,1
1,0,0,28,0,0,0,0,15,1,1,1
1,0,0,9,19,0,0,0,22,1,1,1
1,0,0,21,20,0,0,0,15,1,1,1
1,0,24,2,0,0,0,0,2,1,1,1
1,1,1,16,0,0,0,0,15,1,1,1
1,1,1,22,0,0,0,0,22,1,1,1
1,1,1,22,0,0,0,0,22,1,1,1
1,1,1,16,0,0,0,0,15,1,1,1
1,1,1,2,28,22,22,28,2,1,1,1
1,1,1,1,1,1,1,1,1,1,1,1
1,1,1,1,1,1,1,1,1,1,1,1
endlayer

layer
1,1,1,1,1,1,1,1,1,1,1,1
1,1,1,1,1,1,1,1,1,1,1,1
1,1,4,2,9,9,9,9,2,26,1,1
1,1,1,9,0,0,0,0,9,1,1,1
1,1,1,9,0,0,0,0,9,1,1,1
1,1,1,9,0,0,0,0,9,1,1,1
1,1,1,9,0,0,0,0,9,1,1,1
1,0,4,2,16,21,28,15,2,26,1,1
1,0,0,9,19,0,0,0,9,1,1,1
1,0,0,9,20,0,0,0,9,1,1,1
1,0,0,9,0,0,0,0,9,1,1,1
1,0,4,2,0,0,0,0,2,26,1,1
1,1,1,9,0,0,0,0,9,1,1,1
1,1,1,9,0,0,0,0,9,1,1,1
1,1,1,9,0,0,0,0,9,1,1,1
1,1,1,9,0,0,0,0,9,1,1,1
1,1,4,2,9,9,9,9,2,26,1,1
1,1,1,1,1,1,1,1,1,1,1,1
1,1,1,1,1,1,1,1,1,1,1,1
endlayer

layer
1,1,1,1,1,1,1,1,1,1,1,1
5,5,5,5,5,5,5,5,5,5,5,5
1,6,3,3,3,3,3,3,3,3,6,1
1,6,3,3,3,3,3,3,3,3,6,1
1,6,3,3,3,3,3,3,3,3,6,1
1,6,3,3,3,3,3,3,3,3,6,1
5,5,5,3,3,3,3,3,3,5,5,5
1,1,6,6,7,3,3,3,3,6,1,1
1,1,6,6,20,3,3,3,3,6,1,1
1,1,6,6,0,3,3,3,3,6,1,1
1,1,6,6,0,3,3,3,3,6,1,1
1,1,6,6,0,3,3,3,3,6,1,1
5,5,5,3,3,3,3,3,3,5,5,5
1,6,3,3,3,3,3,3,3,3,6,1
1,6,3,3,3,3,3,3,3,3,6,1
1,6,3,3,3,3,3,3,3,3,6,1
1,6,3,3,3,3,3,3,3,3,6,1
5,5,5,5,5,5,5,5,5,5,5,5
1,1,1,1,1,1,1,1,1,1,1,1
endlayer

layer
1,1,1,1,1,1,1,1,1,1,1,1
1,2,9,9,2,9,9,2,9,9,2,1
1,9,0,29,0,0,0,0,8,7,9,1
1,9,11,0,0,0,0,0,11,0,9,1
1,9,11,31,0,0,0,0,0,30,9,1
1,9,0,0,0,0,0,0,30,30,9,1
1,2,2,0,0,0,0,0,30,2,2,1
1,1,9,0,0,0,0,0,30,9,1,1
1,1,9,0,0,0,0,0,0,9,1,1
1,1,2,0,0,0,0,0,0,2,1,1
1,1,9,0,0,0,0,0,0,9,1,1
1,1,9,0,0,11,0,0,0,9,1,1
1,2,2,16,16,2,9,32,9,2,2,1
1,9,0,0,0,0,0,0,0,0,9,1
1,9,35,34,33,0,0,0,0,11,9,1
1,9,35,34,33,0,0,0,12,11,9,1
1,9,0,0,0,0,0,0,0,0,9,1
1,2,9,9,2,9,9,2,9,9,2,1
1,1,1,1,1,1,1,1,1,1,1,1
endlayer

layer
1,1,1,1,1,1,1,1,1,1,1,1
1,2,22,22,2,22,22,2,22,22,2,1
1,16,0,0,0,0,0,0,0,8,15,1
1,22,24,0,0,0,0,0,24,36,22,1
1,22,0,0,0,0,0,0,0,0,22,1
1,15,0,0,0,0,0,0,0,30,15,1
1,2,2,0,0,0,0,0,30,2,2,1
1,1,22,0,0,0,0,0,0,22,1,1
1,1,22,0,0,0,0,0,0,22,1,1
1,1,2,0,0,0,0,0,0,2,1,1
1,1,22,0,0,0,0,0,0,22,1,1
1,1,22,0,0,24,0,0,0,22,1,1
1,2,2,15,15,2,16,27,15,2,2,1
1,16,0,0,0,0,0,0,0,0,15,1
1,22,0,0,0,0,0,0,0,24,22,1
1,22,24,0,0,0,0,0,0,0,22,1
1,16,0,0,0,0,0,0,0,0,15,1
1,2,22,22,2,22,22,2,22,22,2,1
1,1,1,1,1,1,1,1,1,1,1,1
endlayer

layer
1,1,1,1,1,1,1,1,1,1,1,1
1,2,22,22,2,22,22,2,22,22,2,1
1,16,0,0,0,0,0,0,0,0,15,1
1,22,0,0,0,0,0,0,0,37,22,1
1,22,0,0,0,0,0,0,0,36,22,1
1,16,0,0,0,0,0,0,0,0,15,1
1,2,2,0,0,0,0,0,0,2,2,1
1,1,22,0,0,0,0,0,0,22,1,1
1,1,22,0,0,0,0,0,0,22,1,1
1,1,2,0,0,0,0,0,0,2,1,1
1,1,22,0,0,0,0,0,0,22,1,1
1,1,22,0,0,0,0,0,0,22,1,1
1,2,2,16,16,2,15,9,16,2,2,1
1,16,0,0,0,0,0,0,0,0,15,1
1,22,0,0,0,0,0,0,0,0,22,1
1,22,0,0,0,0,0,0,0,0,22,1
1,16,0,0,0,0,0,0,0,0,15,1
1,2,22,22,2,22,22,2,22,22,2,1
1,1,1,1,1,1,1,1,1,1,1,1
endlayer

layer
1,1,1,1,1,1,1,1,1,1,1,1
1,2,9,9,2,9,9,2,9,9,2,1
1,9,0,0,0,0,0,0,0,0,9,1
1,9,0,0,0,0,0,0,0,0,9,1
1,9,0,0,0,0,0,0,0,37,9,1
1,9,0,0,0,0,0,0,0,36,9,1
1,2,2,0,0,0,0,0,0,2,2,1
1,1,9,0,0,0,0,0,0,9,1,1
1,1,9,0,0,0,0,0,0,9,1,1
1,1,2,0,0,0,0,0,0,2,1,1
1,1,9,0,0,0,0,0,0,9,1,1
1,1,9,0,0,0,0,0,0,9,1,1
1,2,2,15,15,2,9,9,9,2,2,1
1,9,0,0,0,0,0,0,0,0,9,1
1,9,0,0,0,0,0,0,0,0,9,1
1,9,0,0,0,0,0,0,0,0,9,1
1,9,0,0,0,0,0,0,0,0,9,1
1,2,9,9,2,9,9,2,9,9,2,1
1,1,1,1,1,1,1,1,1,1,1,1
endlayer

layer
1,1,1,1,1,1,1,1,1,1,1,1
5,5,5,5,5,5,5,5,5,5,5,5
0,6,3,3,3,3,3,3,3,0,6,1
0,6,3,3,3,3,3,3,3,0,6,1
0,6,3,3,3,3,3,3,3,0,6,1
0,6,3,3,3,3,3,3,3,37,6,1
5,5,5,5,5,5,5,5,5,5,5,5
0,39,6,0,0,0,0,0,0,6,38,1
0,39,6,0,0,0,0,0,0,6,38,1
0,39,6,0,0,0,0,0,0,6,38,1
0,39,6,0,0,0,0,0,0,6,38,1
40,39,6,0,0,0,0,0,0,6,40,40
5,2,5,5,5,5,5,5,5,5,2,5
0,6,0,0,0,0,0,0,0,0,6,0
0,6,0,0,0,0,0,0,0,0,6,0
0,6,0,0,0,0,0,0,0,0,6,0
0,6,0,0,0,0,0,0,0,0,6,0
5,2,5,5,5,5,5,5,5,5,2,5
41,41,41,41,41,41,41,41,41,41,41,41
endlayer

layer
1,1,1,1,1,1,1,1,1,1,1,1
0,2,9,9,2,9,9,2,9,9,2,0
0,9,0,0,0,0,0,0,17,0,9,0
0,9,35,34,33,0,0,0,17,0,9,0
0,9,35,34,33,0,0,0,17,0,9,0
0,9,0,0,0,0,0,0,0,0,9,0
0,2,9,9,2,42,8,2,9,9,2,0
0,0,39,13,0,0,0,0,43,38,0,0
0,0,39,13,0,0,0,0,43,38,0,0
0,0,39,13,0,0,0,0,43,38,0,0
0,0,39,13,0,0,0,0,43,38,0,0
0,0,39,13,0,0,0,0,43,38,0,0
40,40,40,7,7,42,8,7,7,38,40,40
44,7,44,44,44,0,0,44,44,44,7,44
0,7,0,0,0,0,0,0,0,0,7,0
0,7,0,0,0,0,0,0,0,0,7,0
45,7,45,45,19,42,8,19,45,45,7,45
41,41,41,41,0,0,0,0,41,41,41,41
0,0,0,0,0,0,0,0,0,0,0,0
endlayer

layer
1,1,1,1,1,1,1,1,1,1,1,1
0,2,22,22,2,22,22,2,22,22,2,0
0,16,0,0,0,0,0,0,0,0,15,0
0,22,24,0,0,0,0,0,0,0,22,0
0,22,0,0,0,0,0,0,0,0,22,0
0,16,0,0,0,0,0,0,0,0,15,0
0,2,15,16,2,26,4,2,15,16,2,0
0,0,0,39,13,0,0,43,38,0,0,0
0,0,0,39,13,0,0,43,38,0,0,0
0,0,0,39,13,0,0,43,38,0,0,0
0,0,0,39,13,0,0,43,38,0,0,0
0,0,0,39,13,0,0,43,38,0,0,0
0,0,0,39,7,26,4,7,38,0,0,0
40,40,40,39,46,0,0,46,40,40,40,40
44,7,44,44,44,0,0,44,44,44,7,44
45,7,45,45,45,0,0,45,45,45,7,45
41,41,41,41,7,26,4,7,38,41,41,41
0,0,0,39,13,0,0,43,38,0,0,0
0,0,0,0,0,0,0,0,0,0,0,0
endlayer

layer
1,1,1,1,1,1,1,1,1,1,1,1
0,2,22,22,2,22,22,2,22,22,2,0
0,16,0,0,0,0,0,0,0,0,15,0
0,22,0,0,0,0,0,0,0,0,22,0
0,22,0,0,0,0,0,0,0,0,22,0
0,16,0,0,0,0,0,0,0,0,15,0
0,2,16,15,2,16,15,2,16,15,2,0
0,0,0,0,39,13,43,38,0,0,0,0
0,0,0,0,39,13,43,38,0,0,0,0
0,0,0,0,39,13,43,38,0,0,0,0
0,0,0,0,39,13,43,38,0,0,0,0
0,0,0,0,39,13,43,38,0,0,0,0
0,0,0,0,39,7,7,38,0,0,0,0
0,0,0,0,39,13,43,38,0,0,0,0
40,40,40,40,40,13,43,40,40,40,40,40
41,41,41,41,39,13,43,38,41,41,41,41
0,0,0,0,39,7,7,38,0,0,0,0
0,0,0,0,39,13,43,38,0,0,0,0
0,0,0,0,0,0,0,0,0,0,0,0
endlayer

layer
1,1,1,1,1,1,1,1,1,1,1,1
0,2,9,9,2,9,9,2,9,9,2,0
0,9,0,0,0,0,0,0,0,0,9,0
0,9,0,0,0,0,0,0,0,0,9,0
0,9,0,0,0,0,0,0,0,0,9,0
0,9,0,0,0,0,0,0,0,0,9,0
0,2,9,9,2,9,9,2,9,9,2,0
0,0,0,0,0,39,38,0,0,0,0,0
0,0,0,0,0,39,38,0,0,0,0,0
0,0,0,0,0,39,38,0,0,0,0,0
0,0,0,0,0,39,38,0,0,0,0,0
0,0,0,0,0,39,38,0,0,0,0,0
0,0,0,0,0,39,38,0,0,0,0,0
0,0,0,0,0,39,38,0,0,0,0,0
0,0,0,0,0,39,38,0,0,0,0,0
0,0,0,0,0,39,38,0,0,0,0,0
0,0,0,0,0,39,38,0,0,0,0,0
0,0,0,0,0,39,38,0,0,0,0,0
0,0,0,0,0,0,0,0,0,0,0,0
endlayer

layer
40,40,40,40,40,40,40,40,40,40,40,40
5,2,5,5,5,5,5,5,5,5,2,5
0,6,0,0,6,0,0,6,0,0,6,0
0,6,0,0,6,0,0,6,0,0,6,0
0,6,0,0,6,0,0,6,0,0,6,0
0,6,0,0,6,0,0,6,0,0,6,0
5,2,5,5,5,5,5,5,5,5,2,5
41,41,41,41,41,41,41,41,41,41,41,41
0,0,0,0,0,0,0,0,0,0,0,0
0,0,0,0,0,0,0,0,0,0,0,0
0,0,0,0,0,0,0,0,0,0,0,0
0,0,0,0,0,0,0,0,0,0,0,0
0,0,0,0,0,0,0,0,0,0,0,0
0,0,0,0,0,0,0,0,0,0,0,0
0,0,0,0,0,0,0,0,0,0,0,0
0,0,0,0,0,0,0,0,0,0,0,0
0,0,0,0,0,0,0,0,0,0,0,0
0,0,0,0,0,0,0,0,0,0,0,0
0,0,0,0,0,0,0,0,0,0,0,0
endlayer

layer
0,0,0,0,0,0,0,0,0,0,0,0
40,40,40,40,40,40,40,40,40,40,40,40
44,7,44,44,44,44,44,44,44,44,7,44
0,7,0,0,0,0,0,0,0,0,7,0
0,7,0,0,0,0,0,0,0,0,7,0
45,7,45,45,45,45,45,45,45,45,7,45
41,41,41,41,41,41,41,41,41,41,41,41
0,0,0,0,0,0,0,0,0,0,0,0
0,0,0,0,0,0,0,0,0,0,0,0
0,0,0,0,0,0,0,0,0,0,0,0
0,0,0,0,0,0,0,0,0,0,0,0
0,0,0,0,0,0,0,0,0,0,0,0
0,0,0,0,0,0,0,0,0,0,0,0
0,0,0,0,0,0,0,0,0,0,0,0
0,0,0,0,0,0,0,0,0,0,0,0
0,0,0,0,0,0,0,0,0,0,0,0
0,0,0,0,0,0,0,0,0,0,0,0
0,0,0,0,0,0,0,0,0,0,0,0
0,0,0,0,0,0,0,0,0,0,0,0
endlayer

layer
0,0,0,0,0,0,0,0,0,0,0,0
0,0,0,0,0,0,0,0,0,0,0,0
40,40,40,40,40,40,40,40,40,40,40,40
44,7,44,44,44,44,44,44,44,44,7,44
45,7,45,45,45,45,45,45,45,45,7,45
41,41,41,41,41,41,41,41,41,41,41,41
0,0,0,0,0,0,0,0,0,0,0,0
0,0,0,0,0,0,0,0,0,0,0,0
0,0,0,0,0,0,0,0,0,0,0,0
0,0,0,0,0,0,0,0,0,0,0,0
0,0,0,0,0,0,0,0,0,0,0,0
0,0,0,0,0,0,0,0,0,0,0,0
0,0,0,0,0,0,0,0,0,0,0,0
0,0,0,0,0,0,0,0,0,0,0,0
0,0,0,0,0,0,0,0,0,0,0,0
0,0,0,0,0,0,0,0,0,0,0,0
0,0,0,0,0,0,0,0,0,0,0,0
0,0,0,0,0,0,0,0,0,0,0,0
0,0,0,0,0,0,0,0,0,0,0,0
endlayer

layer
0,0,0,0,0,0,0,0,0,0,0,0
0,0,0,0,0,0,0,0,0,0,0,0
0,0,0,0,0,0,0,0,0,0,0,0
40,40,40,40,40,40,40,40,40,40,40,40
41,41,41,41,41,41,41,41,41,41,41,41
0,0,0,0,0,0,0,0,0,0,0,0
0,0,0,0,0,0,0,0,0,0,0,0
0,0,0,0,0,0,0,0,0,0,0,0
0,0,0,0,0,0,0,0,0,0,0,0
0,0,0,0,0,0,0,0,0,0,0,0
0,0,0,0,0,0,0,0,0,0,0,0
0,0,0,0,0,0,0,0,0,0,0,0
0,0,0,0,0,0,0,0,0,0,0,0
0,0,0,0,0,0,0,0,0,0,0,0
0,0,0,0,0,0,0,0,0,0,0,0
0,0,0,0,0,0,0,0,0,0,0,0
0,0,0,0,0,0,0,0,0,0,0,0
0,0,0,0,0,0,0,0,0,0,0,0
0,0,0,0,0,0,0,0,0,0,0,0
endlayer

