
# Created by Ruins mod version 16.9 Ingame Parser
# authoring Player: ST753M

weight=1
uniqueMinDistance=256
embed_into_distance=11
acceptable_target_blocks=grass,dirt,podzol,biomesoplenty:grass,biomesoplenty:dirt
unacceptable_target_blocks=flowing_water,water,flowing_lava,lava
dimensions=12,18,18
allowable_overhang=15
max_leveling=0
leveling_buffer=0
preserve_water=0
preserve_lava=0

biomesToSpawnIn=sacred_springs,birch_forest,mutated_birch_forest,cherry_blossom_grove,mutated_forest,taiga,mutated_redwood_taiga,autumnal_woods,prairie,rocky_plains,rocky_plateau,savanna,savanna_rock,mutated_savanna,steppe,desert_shrubland,arid_highland,lush_desert,twilight_clearing,twilight_forest

rule1=0,100,preserveBlock
rule2=0,100,minecraft:dirt-0
rule3=0,100,minecraft:grass-0
rule4=0,100,minecraft:water-0
rule5=0,100,minecraft:tallgrass-2
rule6=0,100,minecraft:double_plant-3
rule7=0,100,air
rule8=0,100,minecraft:waterlily-0
rule9=0,100,minecraft:double_plant-10
rule10=0,90,MobSpawner:Ocelot,MobSpawner:Cow,MobSpawner:Chicken,MobSpawner:Pig,MobSpawner:Creeper,MobSpawner:Parrot,dirt,dirt,dirt,dirt,dirt
rule11=0,100,minecraft:vine-2
rule12=0,100,minecraft:vine-1
rule13=0,100,minecraft:vine-4
rule14=0,100,minecraft:vine-8

layer
1,1,1,1,1,1,1,1,1,1,1,1,1,1,1,1,1,1
1,1,1,1,1,1,1,1,1,1,1,1,1,1,1,1,1,1
1,1,1,1,1,1,1,1,1,1,1,1,1,1,1,1,1,1
1,1,1,1,1,1,1,1,1,1,1,1,1,1,1,1,1,1
1,1,1,1,1,1,2,2,2,2,2,1,1,1,1,1,1,1
1,1,1,1,1,1,2,2,2,3,3,2,1,1,1,1,1,1
1,1,1,1,1,2,2,2,3,3,3,3,2,1,1,1,1,1
1,1,1,1,1,2,2,3,4,4,4,3,3,1,1,1,1,1
1,1,1,1,2,2,3,4,4,4,4,4,3,1,1,1,1,1
1,1,1,1,2,3,4,4,4,4,4,4,3,1,1,1,1,1
1,1,1,1,2,3,4,4,4,4,4,3,3,1,1,1,1,1
1,1,1,1,2,3,3,4,4,4,3,3,1,1,1,1,1,1
1,1,1,1,1,2,3,3,3,3,3,1,1,1,1,1,1,1
1,1,1,1,1,1,1,1,1,1,1,1,1,1,1,1,1,1
1,1,1,1,1,1,1,1,1,1,1,1,1,1,1,1,1,1
1,1,1,1,1,1,1,1,1,1,1,1,1,1,1,1,1,1
1,1,1,1,1,1,1,1,1,1,1,1,1,1,1,1,1,1
1,1,1,1,1,1,1,1,1,1,1,1,1,1,1,1,1,1
endlayer

layer
1,1,1,1,1,1,1,1,1,1,1,1,1,1,1,1,1,1
1,1,1,1,1,1,1,1,1,1,1,1,1,1,1,1,1,1
1,1,1,1,1,1,1,1,1,1,1,1,1,1,1,1,1,1
1,1,1,1,1,1,3,3,3,3,3,3,3,1,1,1,1,1
1,1,1,1,1,3,3,3,3,3,3,3,3,3,3,1,1,1
1,1,1,1,1,3,3,3,3,4,4,3,3,3,3,2,1,1
1,1,1,1,3,3,3,3,4,4,4,4,3,3,3,3,1,1
1,1,1,1,3,3,3,4,4,4,4,4,4,3,3,3,1,1
1,1,1,3,3,3,4,4,4,4,4,4,4,3,3,3,1,1
1,1,1,3,3,4,4,4,4,4,4,4,4,3,3,3,1,1
1,1,1,1,3,4,4,4,4,4,4,4,4,3,3,3,1,1
1,1,1,1,3,4,4,4,4,4,4,4,3,3,3,1,1,1
1,1,1,1,3,3,4,4,4,4,4,3,3,3,1,1,1,1
1,1,1,1,1,3,3,3,3,3,3,3,3,1,1,1,1,1
1,1,1,1,1,1,1,1,3,3,3,3,1,1,1,1,1,1
1,1,1,1,1,1,1,1,1,1,1,1,1,1,1,1,1,1
1,1,1,1,1,1,1,1,1,1,1,1,1,1,1,1,1,1
1,1,1,1,1,1,1,1,1,1,1,1,1,1,1,1,1,1
endlayer

layer
1,1,1,1,1,1,1,1,1,1,1,1,1,1,1,1,1,1
1,1,1,1,1,1,1,2,3,3,3,2,1,1,1,1,1,1
1,1,1,1,2,2,3,3,3,3,3,3,3,3,1,1,1,1
1,1,1,1,2,3,5,5,5,5,5,5,5,3,3,2,1,1
1,1,1,1,2,5,6,5,5,5,5,5,5,0,5,2,2,1
1,1,1,2,3,6,5,5,5,0,0,5,5,6,5,3,2,2
1,1,1,3,7,6,5,5,8,0,8,0,5,5,6,7,3,2
1,1,3,3,6,5,5,0,0,0,0,8,8,5,5,6,3,2
1,1,3,5,5,5,0,8,0,8,8,0,0,5,5,5,3,2
1,1,3,5,5,0,8,0,0,0,0,8,0,5,5,5,3,2
1,1,2,3,5,0,0,0,0,0,8,0,0,5,5,6,3,1
1,1,1,3,5,8,8,8,8,0,0,0,5,5,5,3,3,1
1,1,1,2,5,5,0,0,0,0,0,5,5,5,3,3,1,1
1,1,1,2,3,6,6,6,5,6,5,5,5,3,3,2,1,1
1,1,1,1,2,3,3,3,6,5,5,6,3,3,2,1,1,1
1,1,1,1,1,1,2,2,2,3,3,3,2,1,1,1,1,1
1,1,1,1,1,1,1,1,1,1,1,1,1,1,1,1,1,1
1,1,1,1,1,1,1,1,1,1,1,1,1,1,1,1,1,1
endlayer

layer
1,1,1,1,1,1,1,1,2,2,2,2,1,1,1,1,1,1
1,1,1,1,1,2,2,3,6,5,6,3,2,2,2,1,1,1
1,1,1,1,2,3,5,5,5,5,5,5,5,6,3,2,1,1
1,1,1,1,2,6,0,0,0,0,0,0,0,5,6,2,1,1
1,1,1,2,3,0,9,0,0,0,0,0,0,0,0,3,2,1
1,1,2,2,6,9,0,0,0,0,0,0,0,9,0,6,3,2
1,1,3,6,0,9,0,0,0,0,0,0,0,0,9,0,5,2
1,2,5,5,9,0,0,0,0,0,0,0,0,0,0,9,5,2
1,3,5,0,0,0,0,0,0,0,0,0,0,0,0,0,6,2
1,3,5,0,0,0,0,0,0,0,0,0,0,0,0,0,6,2
1,2,3,6,0,0,0,0,0,0,0,0,0,0,0,9,5,2
1,1,3,0,0,0,0,0,0,0,0,0,0,0,0,5,6,2
1,1,2,3,0,0,0,0,0,0,0,0,0,0,5,5,3,2
1,1,1,3,6,9,9,9,0,9,0,0,0,5,6,3,2,1
1,1,1,2,3,6,6,7,9,0,0,9,5,6,3,2,1,1
1,1,1,1,2,3,3,3,3,5,6,6,3,3,2,1,1,1
1,1,1,1,1,2,2,2,3,3,3,2,2,2,1,1,1,1
1,1,1,1,1,1,1,1,1,1,1,1,1,1,1,1,1,1
endlayer

layer
1,1,1,1,1,1,1,2,2,2,2,2,1,1,1,1,1,1
1,1,1,1,1,2,2,6,9,0,9,6,2,2,2,1,1,1
1,1,1,1,2,0,0,0,0,0,0,0,0,9,0,2,1,1
1,1,1,1,2,9,0,0,0,0,0,0,0,0,9,2,1,1
1,1,1,2,6,0,0,0,0,0,0,0,0,0,0,6,10,1
1,1,2,3,9,0,0,0,0,0,0,0,0,0,0,9,6,2
1,2,6,9,0,0,0,0,0,0,0,0,0,0,0,0,0,2
1,2,0,0,0,0,0,0,0,0,0,0,0,0,0,0,0,2
2,0,0,0,0,0,0,0,0,0,0,0,0,0,0,0,9,2
2,6,0,0,0,0,0,0,0,0,0,0,0,0,0,0,9,2
1,2,0,9,0,0,0,0,0,0,0,0,0,0,0,0,0,2
1,2,6,0,0,0,0,0,0,0,0,0,0,0,0,0,9,2
1,1,2,6,0,0,0,0,0,0,0,0,0,0,0,0,6,2
1,1,2,0,9,0,0,0,0,0,0,0,0,0,9,5,2,1
1,1,1,2,6,9,9,0,0,0,0,0,0,9,6,2,1,1
1,1,1,1,2,6,6,6,5,0,9,9,5,6,2,1,1,1
1,1,1,1,1,2,2,2,6,5,6,2,2,2,1,1,1,1
1,1,1,1,1,1,1,1,2,2,2,2,1,1,1,1,1,1
endlayer

layer
1,1,1,1,1,1,1,2,2,2,3,3,1,1,1,1,1,1
1,1,1,1,1,2,2,9,11,0,0,9,3,3,3,1,1,1
1,1,1,1,2,12,0,0,0,0,0,0,0,0,2,3,1,1
1,1,1,1,2,12,0,0,0,0,0,0,0,0,11,3,1,1
1,1,1,2,9,0,0,0,0,0,0,0,0,0,0,9,3,1
1,1,2,12,0,0,0,0,0,0,0,0,0,0,0,0,9,3
1,3,9,0,0,0,0,0,0,0,0,0,0,0,0,0,0,3
1,3,0,0,0,0,0,0,0,0,0,0,0,0,0,0,13,2
3,0,0,0,0,0,0,0,0,0,0,0,0,0,0,0,0,2
3,9,0,0,0,0,0,0,0,0,0,0,0,0,0,0,0,2
1,3,0,0,0,0,0,0,0,0,0,0,0,0,0,0,13,2
1,3,9,0,0,0,0,0,0,0,0,0,0,0,0,0,0,2
1,1,3,9,0,0,0,0,0,0,0,0,0,0,0,0,9,2
1,1,3,12,0,0,0,0,0,0,0,0,0,0,0,0,2,1
1,1,1,3,9,0,0,0,0,0,0,0,0,0,9,2,1,1
1,1,1,1,3,9,9,9,0,0,0,0,0,9,2,1,1,1
1,1,1,1,1,3,2,2,9,0,9,2,2,2,1,1,1,1
1,1,1,1,1,1,1,1,2,2,2,2,1,1,1,1,1,1
endlayer

layer
1,1,1,1,1,1,1,3,3,3,1,1,1,1,1,1,1,1
1,1,1,1,1,3,3,0,11,0,3,3,1,1,1,1,1,1
1,1,1,1,3,0,0,0,0,0,11,0,3,3,3,1,1,1
1,1,1,1,2,12,0,0,0,0,0,0,11,13,3,1,1,1
1,1,1,2,12,0,0,0,0,0,0,0,0,0,0,3,1,1
1,1,2,12,0,0,0,0,0,0,0,0,0,0,0,13,3,1
1,1,2,0,0,0,0,0,0,0,0,0,0,0,0,0,3,1
1,1,2,12,0,0,0,0,0,0,0,0,0,0,0,0,0,3
1,2,0,0,0,0,0,0,0,0,0,0,0,0,0,13,0,3
1,3,0,0,0,0,0,0,0,0,0,0,0,0,0,0,13,3
1,1,3,12,0,0,0,0,0,0,0,0,0,0,0,0,0,3
1,1,3,12,0,0,0,0,0,0,0,0,0,0,0,0,13,2
1,1,1,3,12,0,0,0,0,0,0,0,0,0,0,0,0,2
1,1,1,3,14,0,0,0,0,0,0,0,0,0,0,13,2,1
1,1,1,1,3,0,0,0,0,0,0,0,0,14,14,2,1,1
1,1,1,1,1,3,12,14,0,0,0,14,14,0,2,1,1,1
1,1,1,1,1,1,3,3,14,12,14,2,2,2,1,1,1,1
1,1,1,1,1,1,1,1,3,2,2,3,1,1,1,1,1,1
endlayer

layer
1,1,1,1,1,1,1,1,1,1,1,1,1,1,1,1,1,1
1,1,1,1,1,1,1,3,3,3,1,1,1,1,1,1,1,1
1,1,1,1,1,3,3,12,0,13,3,3,1,1,1,1,1,1
1,1,1,1,3,0,11,0,0,13,0,11,3,3,1,1,1,1
1,1,1,3,12,0,0,0,0,0,0,0,11,11,3,1,1,1
1,1,3,2,12,0,0,0,0,0,0,0,0,0,0,3,1,1
1,1,3,11,0,12,0,0,0,0,0,0,0,0,13,3,1,1
1,1,3,12,11,0,0,0,0,0,0,0,0,0,0,11,3,1
1,3,3,12,0,0,0,0,0,0,0,0,0,0,13,13,3,1
1,1,3,12,14,0,0,0,0,0,0,0,0,0,0,0,3,1
1,1,1,3,0,0,0,0,0,0,0,0,0,0,0,13,2,1
1,1,1,3,12,0,0,0,0,0,0,0,0,0,0,0,13,3
1,1,1,1,3,12,0,0,0,0,0,0,0,0,0,0,0,3
1,1,1,1,3,0,0,0,0,0,0,0,0,0,13,2,3,1
1,1,1,1,1,3,12,14,0,0,0,13,0,14,0,3,1,1
1,1,1,1,1,1,3,3,12,0,0,14,13,2,3,1,1,1
1,1,1,1,1,1,1,1,3,12,14,3,3,3,1,1,1,1
1,1,1,1,1,1,1,1,1,3,3,1,1,1,1,1,1,1
endlayer

layer
1,1,1,1,1,1,1,1,1,1,1,1,1,1,1,1,1,1
1,1,1,1,1,1,1,1,1,1,1,1,1,1,1,1,1,1
1,1,1,1,1,1,1,3,3,3,1,1,1,1,1,1,1,1
1,1,1,1,1,3,3,2,12,13,3,3,1,1,1,1,1,1
1,1,1,1,3,11,11,11,0,0,13,2,3,3,1,1,1,1
1,1,1,3,2,0,0,0,0,0,0,0,0,13,3,1,1,1
1,1,1,3,2,12,0,0,0,0,0,0,0,0,3,1,1,1
1,1,1,3,11,0,0,0,0,0,0,0,0,0,2,3,1,1
1,1,1,3,0,0,0,0,0,0,0,0,0,0,13,3,1,1
1,1,1,3,14,0,0,0,0,0,0,0,0,0,0,3,1,1
1,1,1,1,3,0,0,0,0,0,0,0,0,0,0,13,3,1
1,1,1,1,3,0,0,0,0,0,0,0,0,0,0,0,3,1
1,1,1,1,1,3,12,0,0,0,0,0,0,0,0,13,3,1
1,1,1,1,1,3,2,12,14,0,0,0,14,0,13,3,1,1
1,1,1,1,1,1,3,3,2,14,14,13,2,2,3,1,1,1
1,1,1,1,1,1,1,1,3,2,2,3,3,3,1,1,1,1
1,1,1,1,1,1,1,1,1,3,3,1,1,1,1,1,1,1
1,1,1,1,1,1,1,1,1,1,1,1,1,1,1,1,1,1
endlayer

layer
1,1,1,1,1,1,1,1,1,1,1,1,1,1,1,1,1,1
1,1,1,1,1,1,1,1,1,1,1,1,1,1,1,1,1,1
1,1,1,1,1,1,1,1,1,1,1,1,1,1,1,1,1,1
1,1,1,1,1,1,1,3,3,3,1,1,1,1,1,1,1,1
1,1,1,1,1,3,3,3,3,3,3,3,1,1,1,1,1,1
1,1,1,1,3,3,3,3,3,3,3,3,3,3,1,1,1,1
1,1,1,1,3,3,11,11,13,3,3,3,3,3,1,1,1,1
1,1,1,1,3,3,12,0,0,11,3,3,3,3,3,1,1,1
1,1,1,1,3,3,14,0,0,0,13,3,3,3,3,1,1,1
1,1,1,1,3,3,3,0,0,0,0,0,11,3,3,1,1,1
1,1,1,1,1,3,3,0,0,0,0,0,0,11,3,3,1,1
1,1,1,1,1,3,3,3,0,0,0,0,14,13,3,3,1,1
1,1,1,1,1,1,3,3,0,0,14,0,3,3,3,3,1,1
1,1,1,1,1,1,3,3,3,0,3,3,3,3,3,1,1,1
1,1,1,1,1,1,1,1,3,3,3,3,3,3,1,1,1,1
1,1,1,1,1,1,1,1,1,3,3,1,1,1,1,1,1,1
1,1,1,1,1,1,1,1,1,1,1,1,1,1,1,1,1,1
1,1,1,1,1,1,1,1,1,1,1,1,1,1,1,1,1,1
endlayer

layer
1,1,1,1,1,1,1,1,1,1,1,1,1,1,1,1,1,1
1,1,1,1,1,1,1,1,1,1,1,1,1,1,1,1,1,1
1,1,1,1,1,1,1,1,1,1,1,1,1,1,1,1,1,1
1,1,1,1,1,1,1,1,1,1,1,1,1,1,1,1,1,1
1,1,1,1,1,1,1,1,1,1,1,1,1,1,1,1,1,1
1,1,1,1,1,1,1,1,1,1,1,1,1,1,1,1,1,1
1,1,1,1,1,1,0,0,0,1,1,1,1,1,1,1,1,1
1,1,1,1,1,1,0,0,1,0,1,1,1,1,1,1,1,1
1,1,1,1,1,1,0,0,0,0,0,1,1,1,1,1,1,1
1,1,1,1,1,1,1,1,1,0,0,1,0,1,1,1,1,1
1,1,1,1,1,1,1,1,0,0,0,1,0,0,1,1,1,1
1,1,1,1,1,1,1,1,1,0,0,0,0,0,1,1,1,1
1,1,1,1,1,1,1,1,1,0,0,1,1,1,1,1,1,1
1,1,1,1,1,1,1,1,1,1,1,1,1,1,1,1,1,1
1,1,1,1,1,1,1,1,1,1,1,1,1,1,1,1,1,1
1,1,1,1,1,1,1,1,1,1,1,1,1,1,1,1,1,1
1,1,1,1,1,1,1,1,1,1,1,1,1,1,1,1,1,1
1,1,1,1,1,1,1,1,1,1,1,1,1,1,1,1,1,1
endlayer

layer
1,1,1,1,1,1,1,1,1,1,1,1,1,1,1,1,1,1
1,1,1,1,1,1,1,1,1,1,1,1,1,1,1,1,1,1
1,1,1,1,1,1,1,1,1,1,1,1,1,1,1,1,1,1
1,1,1,1,1,1,1,1,1,1,1,1,1,1,1,1,1,1
1,1,1,1,1,1,1,1,1,1,1,1,1,1,1,1,1,1
1,1,1,1,1,1,1,0,1,1,1,1,1,1,1,1,1,1
1,1,1,1,1,1,1,0,1,1,1,1,1,1,1,1,1,1
1,1,1,1,1,1,0,0,1,1,1,1,1,1,1,1,1,1
1,1,1,1,1,1,1,0,0,0,1,1,1,1,1,1,1,1
1,1,1,1,1,1,1,1,1,0,0,1,1,1,1,1,1,1
1,1,1,1,1,1,1,1,0,0,0,1,0,1,1,1,1,1
1,1,1,1,1,1,1,1,1,0,0,0,0,0,1,1,1,1
1,1,1,1,1,1,1,1,0,0,0,1,1,0,0,1,1,1
1,1,1,1,1,1,1,0,0,1,1,1,1,1,1,1,1,1
1,1,1,1,1,1,1,0,1,1,1,1,1,1,1,1,1,1
1,1,1,1,1,1,1,1,1,1,1,1,1,1,1,1,1,1
1,1,1,1,1,1,1,1,1,1,1,1,1,1,1,1,1,1
1,1,1,1,1,1,1,1,1,1,1,1,1,1,1,1,1,1
endlayer

