# Gilly's Aztec Portal Tower

# template generated with Ruins mod version 16.5 Ingame Parser
# Structure created and developed by Gilly

weight=1
embed_into_distance=4
uniqueMinDistance=700
acceptable_target_blocks=
unacceptable_target_blocks=flowing_water,water,flowing_lava,lava,ice,bedrock,netherrack,nether_brick,nether_brick_fence,soul_sand,quartz_ore,end_stone,obsidian,iron_bars,cloud,flesh,ash_block,slime_grass,slime_congealed,slime_dirt
biomesToSpawnIn=plains,mutated_plains,ice_flats,meadow,forest,taiga,woodland,woodlands,fen,brushland,shrubland,outback,chaparral,savanna,badlands,tundra,desert,jungle,mini jungle,birch forest,red desert,autumnal forest,rocky plateau,ice plains,cold taiga,mega taiga
dimensions=27,9,11
allowable_overhang=0
max_leveling=4
leveling_buffer=-1
preserve_water=0
preserve_lava=0

rule1=0,100,minecraft:stone_brick_stairs-2
rule2=0,100,stonebrick,stonebrick,stonebrick,stonebrick,stonebrick,stonebrick,stonebrick-2,stonebrick-1
rule3=0,100,minecraft:stone_brick_stairs-0
rule4=0,100,minecraft:stone_brick_stairs-3
rule5=0,100,minecraft:stone_brick_stairs-1
rule6=0,100,preserveBlock
rule7=0,100,minecraft:stone_brick_stairs-7
rule8=0,100,minecraft:stone_brick_stairs-4
rule9=0,100,minecraft:stone_brick_stairs-6
rule10=0,100,minecraft:sea_lantern-0
rule11=0,100,minecraft:stone_brick_stairs-5
rule12=0,100,minecraft:quartz_block-0
rule13=0,100,minecraft:obsidian-0
rule14=0,100,minecraft:quartz_stairs-4
rule15=0,100,minecraft:stone_slab-15
rule16=0,100,minecraft:double_stone_slab-7
rule17=0,100,minecraft:quartz_stairs-5
rule18=0,100,minecraft:quartz_stairs-6
rule19=0,100,minecraft:quartz_stairs-7
rule20=0,100,minecraft:stone_slab-8
rule21=0,100,minecraft:stained_glass_pane-3
rule22=0,100,minecraft:fence-0
rule23=1,100,minecraft:torch-5
rule24=0,100,minecraft:stone_slab-13
rule25=0,100,minecraft:stone_slab-7

layer
4,2,2,2,3,2,3,2,2,2,1
4,2,2,2,0,2,0,2,2,2,1
5,2,2,2,2,2,2,2,2,2,5
6,2,2,2,2,2,2,2,2,2,6
6,2,2,2,2,2,2,2,2,2,6
6,2,2,2,2,2,2,2,2,2,6
3,2,2,2,2,2,2,2,2,2,3
4,2,2,2,0,2,0,2,2,2,1
4,2,2,2,5,2,5,2,2,2,1
endlayer

layer
6,4,2,9,8,3,8,7,2,1,6
6,4,2,2,0,10,0,2,2,1,6
6,2,2,2,2,2,2,2,2,2,6
6,2,2,2,2,2,2,2,2,2,6
6,4,0,2,2,2,2,2,0,1,6
6,2,2,2,2,2,2,2,2,2,6
6,2,2,2,2,2,2,2,2,2,6
6,4,2,2,0,10,0,2,2,1,6
6,4,2,9,11,5,11,7,2,1,6
endlayer

layer
6,6,4,3,3,3,3,3,1,6,6
6,6,4,2,1,3,4,2,1,6,6
6,2,2,2,2,2,2,2,2,2,6
6,7,0,2,2,2,2,2,0,9,6
6,4,10,2,2,2,2,2,10,1,6
6,7,0,2,2,2,2,2,0,9,6
6,2,2,2,2,2,2,2,2,2,6
6,6,4,2,2,2,2,2,1,6,6
6,6,4,5,5,5,5,5,1,6,6
endlayer

layer
6,6,6,6,6,6,6,6,6,6,6
6,6,6,4,3,3,3,1,6,6,6
6,2,2,2,2,2,2,2,2,2,6
6,2,2,2,2,2,2,2,2,2,6
6,2,0,2,2,2,2,2,0,2,6
6,2,2,2,2,2,2,2,2,2,6
6,2,2,2,2,2,2,2,2,2,6
6,6,6,4,5,5,5,1,6,6,6
6,6,6,6,6,6,6,6,6,6,6
endlayer

layer
6,6,6,6,6,6,6,6,6,6,6
6,6,6,6,6,6,6,6,6,6,6
6,12,12,12,3,3,3,12,12,12,6
6,12,12,12,12,12,12,12,12,12,6
6,12,12,12,13,13,13,12,12,12,6
6,12,12,12,12,12,12,12,12,12,6
6,12,12,12,5,5,5,12,12,12,6
6,6,6,6,6,6,6,6,6,6,6
6,6,6,6,6,6,6,6,6,6,6
endlayer

layer
6,6,6,6,0,0,0,6,6,6,6
6,6,6,0,0,0,0,0,6,6,6
6,14,15,16,0,0,0,16,15,14,6
6,15,0,0,0,0,0,0,0,15,6
6,15,12,13,0,0,0,13,12,15,6
6,15,0,0,0,0,0,0,0,15,6
6,17,15,16,0,0,0,16,15,17,6
6,6,6,0,0,0,0,0,6,6,6
6,6,6,6,0,0,0,6,6,6,6
endlayer

layer
6,6,6,0,0,0,0,0,6,6,6
6,6,0,0,0,0,0,0,0,6,6
6,14,15,12,0,0,0,16,15,14,6
6,15,0,0,0,0,0,0,0,15,6
6,15,12,13,0,0,0,13,12,15,6
6,15,0,0,0,0,0,0,0,15,6
6,17,15,16,0,0,0,16,15,17,6
6,6,0,0,0,0,0,0,0,6,6
6,6,6,0,0,0,0,0,6,6,6
endlayer

layer
6,6,0,0,0,0,0,0,0,6,6
6,0,0,0,0,0,0,0,0,0,6
0,14,15,16,0,0,0,16,15,14,0
0,15,0,0,0,0,0,0,0,15,0
0,15,12,13,0,0,0,13,12,15,0
0,15,0,0,0,0,0,0,0,15,0
0,17,15,16,0,0,0,16,15,17,0
6,0,0,0,0,0,0,0,0,0,6
6,6,0,0,0,0,0,0,0,6,6
endlayer

layer
6,0,0,0,0,0,0,0,0,0,6
0,0,0,0,0,0,0,0,0,0,0
0,14,15,16,0,0,0,16,15,14,0
0,17,15,0,0,0,0,0,15,17,0
0,15,12,13,0,0,0,13,12,15,0
0,14,15,0,0,0,0,0,15,14,0
0,17,15,16,0,0,0,16,15,17,0
0,0,0,0,0,0,0,0,0,0,0
6,0,0,0,0,0,0,0,0,0,6
endlayer

layer
0,0,0,0,0,0,0,0,0,0,0
0,0,0,0,0,0,0,0,0,0,0
0,15,15,19,18,15,19,18,15,15,0
0,17,0,15,0,15,0,15,0,17,0
0,15,15,15,13,13,13,15,15,15,0
0,14,0,15,0,15,0,15,0,14,0
0,15,15,19,18,15,19,18,15,15,0
0,0,0,0,0,0,0,0,0,0,0
0,0,0,0,0,0,0,0,0,0,0
endlayer

layer
0,0,0,0,0,0,0,0,0,0,0
0,0,0,0,0,0,0,0,0,0,0
0,20,20,15,19,15,18,15,20,20,0
0,14,21,21,21,21,21,21,21,14,0
0,15,21,0,22,0,22,0,21,15,0
0,17,21,21,21,21,21,21,21,17,0
0,20,20,15,19,15,18,15,20,20,0
0,0,0,0,0,0,0,0,0,0,0
0,0,0,0,0,0,0,0,0,0,0
endlayer

layer
0,0,0,0,0,0,0,0,0,0,0
0,0,0,0,0,0,0,0,0,0,0
0,20,20,15,19,0,18,15,20,20,0
0,14,21,21,21,21,21,21,21,14,0
0,0,21,0,23,0,23,0,21,0,0
0,17,21,21,21,21,21,21,21,17,0
0,20,20,15,19,0,18,15,20,20,0
0,0,0,0,0,0,0,0,0,0,0
0,0,0,0,0,0,0,0,0,0,0
endlayer

layer
0,0,0,0,0,0,0,0,0,0,0
0,0,0,0,0,0,0,0,0,0,0
0,15,15,15,19,15,18,15,15,15,0
0,14,21,21,21,21,21,21,21,14,0
0,15,21,0,22,0,22,0,21,15,0
0,17,21,21,21,21,21,21,21,17,0
0,15,15,15,19,15,18,15,15,15,0
0,0,0,0,0,0,0,0,0,0,0
0,0,0,0,0,0,0,0,0,0,0
endlayer

layer
0,0,0,0,0,0,0,0,0,0,0
0,0,0,0,0,0,0,0,0,0,0
0,0,24,20,19,0,18,20,24,0,0
0,14,21,21,21,21,21,21,21,14,0
0,15,21,0,23,0,23,0,21,15,0
0,17,21,21,21,21,21,21,21,17,0
0,0,24,20,19,0,18,20,24,0,0
0,0,0,0,0,0,0,0,0,0,0
0,0,0,0,0,0,0,0,0,0,0
endlayer

layer
0,0,0,0,0,0,0,0,0,0,0
0,0,0,0,0,0,0,0,0,0,0
0,0,24,20,19,0,18,20,24,0,0
0,14,21,21,21,21,21,21,21,14,0
0,24,21,0,22,0,22,0,21,24,0
0,17,21,21,21,21,21,21,21,17,0
0,0,24,20,19,0,18,20,24,0,0
0,0,0,0,0,0,0,0,0,0,0
0,0,0,0,0,0,0,0,0,0,0
endlayer

layer
0,0,0,0,0,0,0,0,0,0,0
0,0,0,0,0,0,0,0,0,0,0
0,0,24,20,19,0,18,20,24,0,0
0,14,21,21,21,21,21,21,21,14,0
0,24,21,0,23,0,23,0,21,24,0
0,17,21,21,21,21,21,21,21,17,0
0,0,24,20,19,0,18,20,24,0,0
0,0,0,0,0,0,0,0,0,0,0
0,0,0,0,0,0,0,0,0,0,0
endlayer

layer
0,0,0,0,0,0,0,0,0,0,0
0,0,0,0,0,0,0,0,0,0,0
0,0,24,20,19,0,18,20,24,0,0
0,14,21,21,21,21,21,21,21,14,0
0,24,21,0,22,0,22,0,21,24,0
0,17,21,21,21,21,21,21,21,17,0
0,0,24,20,19,0,18,20,24,0,0
0,0,0,0,0,0,0,0,0,0,0
0,0,0,0,0,0,0,0,0,0,0
endlayer

layer
0,0,0,0,0,0,0,0,0,0,0
0,0,0,0,0,0,0,0,0,0,0
0,0,24,20,19,0,18,20,24,0,0
0,14,21,21,21,21,21,21,21,14,0
0,24,21,0,23,0,23,0,21,24,0
0,17,21,21,21,21,21,21,21,17,0
0,0,24,20,19,0,18,20,24,0,0
0,0,0,0,0,0,0,0,0,0,0
0,0,0,0,0,0,0,0,0,0,0
endlayer

layer
0,0,0,0,0,0,0,0,0,0,0
0,0,0,0,0,0,0,0,0,0,0
0,0,24,20,19,0,18,20,24,0,0
0,14,21,21,21,21,21,21,21,14,0
0,24,21,0,22,0,22,0,21,24,0
0,17,21,21,21,21,21,21,21,17,0
0,0,24,20,19,0,18,20,24,0,0
0,0,0,0,0,0,0,0,0,0,0
0,0,0,0,0,0,0,0,0,0,0
endlayer

layer
0,0,0,0,0,0,0,0,0,0,0
0,0,0,0,0,0,0,0,0,0,0
0,0,24,20,19,0,18,20,24,0,0
0,14,21,21,21,21,21,21,21,14,0
0,24,21,0,23,0,23,0,21,24,0
0,17,21,21,21,21,21,21,21,17,0
0,0,24,20,19,0,18,20,24,0,0
0,0,0,0,0,0,0,0,0,0,0
0,0,0,0,0,0,0,0,0,0,0
endlayer

layer
0,0,0,0,0,0,0,0,0,0,0
0,0,0,0,0,0,0,0,0,0,0
0,0,24,20,19,0,18,20,24,0,0
0,14,21,21,21,21,21,21,21,14,0
0,24,21,0,22,0,22,0,21,24,0
0,17,21,21,21,21,21,21,21,17,0
0,0,24,20,19,0,18,20,24,0,0
0,0,0,0,0,0,0,0,0,0,0
0,0,0,0,0,0,0,0,0,0,0
endlayer

layer
0,0,0,0,0,0,0,0,0,0,0
0,0,0,0,0,0,0,0,0,0,0
0,0,24,20,19,0,18,20,24,0,0
0,14,21,21,21,21,21,21,21,14,0
0,15,21,0,23,0,23,0,21,15,0
0,17,21,21,21,21,21,21,21,17,0
0,0,24,20,19,0,18,20,24,0,0
0,0,0,0,0,0,0,0,0,0,0
0,0,0,0,0,0,0,0,0,0,0
endlayer

layer
0,0,0,0,0,0,0,0,0,0,0
0,0,0,0,0,0,0,0,0,0,0
0,15,15,15,19,15,18,15,15,15,0
0,14,21,21,21,21,21,21,21,14,0
0,15,21,0,22,0,22,0,21,15,0
0,17,21,21,21,21,21,21,21,17,0
0,15,15,15,19,15,18,15,15,15,0
0,0,0,0,0,0,0,0,0,0,0
0,0,0,0,0,0,0,0,0,0,0
endlayer

layer
0,0,0,0,0,0,0,0,0,0,0
0,0,0,0,0,0,0,0,0,0,0
0,20,20,15,19,0,18,15,20,20,0
0,14,21,21,21,21,21,21,21,14,0
0,0,21,0,23,0,23,0,21,0,0
0,17,21,21,21,21,21,21,21,17,0
0,20,20,15,19,0,18,15,20,20,0
0,0,0,0,0,0,0,0,0,0,0
0,0,0,0,0,0,0,0,0,0,0
endlayer

layer
0,0,0,0,0,0,0,0,0,0,0
0,0,0,0,0,0,0,0,0,0,0
0,20,20,15,19,15,18,15,20,20,0
0,14,21,21,21,21,21,21,21,14,0
0,15,21,0,0,0,0,0,21,15,0
0,17,21,21,21,21,21,21,21,17,0
0,20,20,15,19,15,18,15,20,20,0
0,0,0,0,0,0,0,0,0,0,0
0,0,0,0,0,0,0,0,0,0,0
endlayer

layer
0,0,0,0,0,0,0,0,0,0,0
0,0,0,0,0,0,0,0,0,0,0
0,15,15,15,19,15,18,15,15,15,0
0,14,0,15,0,15,0,15,0,14,0
0,15,15,15,15,15,15,15,15,15,0
0,17,0,15,0,15,0,15,0,17,0
0,15,15,15,19,15,18,15,15,15,0
0,0,0,0,0,0,0,0,0,0,0
0,0,0,0,0,0,0,0,0,0,0
endlayer

layer
0,0,0,0,0,0,0,0,0,0,0
0,0,0,0,0,0,0,0,0,0,0
0,0,25,0,16,0,16,0,25,0,0
0,0,0,0,0,0,0,0,0,0,0
0,25,0,25,0,16,0,25,0,25,0
0,0,0,0,0,0,0,0,0,0,0
0,0,25,0,16,0,16,0,25,0,0
0,0,0,0,0,0,0,0,0,0,0
0,0,0,0,0,0,0,0,0,0,0
endlayer

