
# Created by Ruins mod version 16.7 Ingame Parser
# authoring Player: lafuller

weight=1
embed_into_distance=8
uniqueMinDistance=800
acceptable_target_blocks=
unacceptable_target_blocks=flowing_water,water,flowing_lava,lava,ice,bedrock,netherrack,nether_brick,nether_brick_fence,soul_sand,quartz_ore,end_stone,obsidian,iron_bars,cloud,flesh,ash_block,slime_grass,slime_congealed,slime_dirt
biomesToSpawnIn=forest,foresthills,woodlands,woodland,flower forest
dimensions=21,19,20
allowable_overhang=0
max_leveling=8
leveling_buffer=-1
preserve_water=0
preserve_lava=0

rule1=0,100,preserveBlock
rule2=0,100,minecraft:log-12
rule3=0,100,minecraft:log-0
rule4=0,100,minecraft:brown_mushroom_block-0

layer
1,1,1,2,1,1,1,1,1,1,1,1,1,1,1,2,1,1,1,1
1,1,1,1,1,1,1,1,1,1,1,1,1,1,1,1,1,1,1,1
1,1,1,1,1,1,1,1,1,1,1,1,1,1,1,1,1,1,1,1
2,1,1,1,1,1,1,1,1,1,1,1,1,1,1,1,1,1,1,1
1,1,1,1,1,1,1,1,1,1,1,1,1,1,1,2,1,1,1,1
1,1,1,1,1,1,1,1,1,1,1,1,1,1,1,1,1,1,1,1
1,1,1,1,1,1,1,1,1,1,1,1,1,1,1,1,1,1,1,1
1,1,1,1,1,1,1,1,1,1,1,1,1,1,1,1,1,1,1,2
1,1,1,1,1,1,1,1,1,1,1,1,1,1,1,1,1,1,1,1
1,1,1,1,1,1,1,1,1,1,1,1,1,1,1,1,1,1,1,1
1,1,1,1,1,1,1,1,1,1,1,1,1,1,1,1,1,1,1,1
1,1,1,1,2,1,1,1,1,1,1,1,1,1,1,1,1,1,1,1
1,1,1,1,1,1,1,1,1,1,1,1,1,1,1,1,1,1,1,1
1,1,1,1,1,1,1,1,1,1,1,1,1,1,1,1,1,1,1,1
1,1,1,1,1,1,1,1,1,1,1,1,1,1,1,1,1,1,1,1
2,1,1,1,1,1,1,1,1,1,1,1,1,1,1,1,1,1,1,2
1,1,1,1,1,1,1,1,1,1,1,1,1,1,1,1,1,2,1,1
1,1,1,1,1,1,1,1,1,1,1,1,1,1,1,1,1,1,1,1
1,1,1,1,2,1,1,1,1,1,1,1,2,1,1,1,1,1,1,1
endlayer

layer
1,1,1,2,2,1,1,1,1,1,1,1,1,1,2,2,1,1,1,1
1,1,1,2,1,1,1,1,1,1,1,1,1,1,1,1,1,1,1,1
1,1,1,1,1,1,1,1,1,1,1,1,1,1,1,1,1,1,1,1
2,1,1,1,1,1,1,1,1,2,1,1,1,1,1,1,1,1,2,1
1,1,1,1,1,2,1,1,1,1,1,1,1,1,2,2,1,1,1,1
1,1,1,1,1,1,1,1,1,1,1,1,1,1,1,1,1,1,1,1
1,1,1,1,1,1,1,1,1,1,1,1,1,1,1,1,1,1,1,1
1,1,1,1,1,1,1,1,1,1,1,1,1,1,1,1,1,1,1,2
1,1,1,1,1,1,1,1,1,1,1,1,1,1,1,1,1,1,1,1
1,1,1,1,1,1,1,1,1,1,1,1,1,1,1,1,1,1,1,1
1,1,1,1,2,1,1,1,1,1,1,1,1,1,2,1,1,1,1,1
1,1,1,1,2,2,1,1,1,1,1,1,1,1,1,1,1,1,1,1
1,1,1,1,1,1,1,1,1,1,1,1,1,1,1,1,1,1,1,1
1,1,1,1,1,1,1,1,1,1,1,1,1,1,1,1,1,1,1,1
2,1,1,1,1,1,1,1,1,1,1,1,2,1,1,1,1,1,2,2
2,1,1,1,1,1,1,1,1,1,1,1,1,1,1,1,2,1,1,2
1,1,1,1,1,1,1,1,1,1,1,1,1,1,1,1,2,2,1,1
1,1,1,1,1,2,1,1,1,1,1,1,2,1,1,1,1,1,1,1
1,1,1,1,2,2,1,1,1,1,1,2,2,1,1,1,1,1,1,1
endlayer

layer
1,1,1,1,2,1,1,1,1,1,1,1,1,1,2,2,1,1,1,1
1,1,1,2,2,1,1,1,1,1,1,1,1,1,2,1,1,1,1,1
1,1,1,1,1,1,1,1,1,1,1,1,1,1,1,1,1,1,1,1
2,2,1,1,1,1,1,1,1,2,1,1,1,1,1,1,1,2,2,1
2,2,1,1,1,2,1,1,1,2,2,1,1,1,2,1,1,1,1,1
1,1,1,1,1,2,1,1,1,1,1,1,1,2,2,1,1,1,1,1
1,1,1,1,1,1,1,1,1,1,1,1,1,1,1,1,1,1,1,1
1,1,1,1,1,1,1,1,1,1,1,1,1,1,1,1,1,1,2,2
1,1,1,1,1,1,1,1,1,1,1,1,1,1,1,1,1,1,1,2
1,1,1,1,1,1,1,1,1,1,1,1,1,1,1,1,1,1,1,1
1,1,1,1,2,2,2,1,1,1,1,1,1,2,2,1,1,1,1,1
1,1,1,1,1,2,1,1,1,1,1,1,1,1,1,1,1,1,1,1
1,1,1,1,1,1,1,1,1,1,1,1,1,1,1,1,1,1,1,1
1,2,1,1,1,1,1,1,1,1,1,1,1,1,1,1,1,1,2,1
2,1,1,1,1,1,1,1,1,1,1,1,2,1,1,1,1,1,1,2
1,1,1,1,1,1,1,1,1,1,1,1,1,1,1,1,2,1,1,1
1,1,1,1,1,1,1,1,1,1,1,1,1,1,1,1,2,1,1,1
1,1,1,1,2,2,2,1,1,1,1,2,2,1,1,1,1,1,1,1
1,1,1,1,2,2,1,1,1,1,2,2,2,1,1,1,1,1,1,1
endlayer

layer
1,1,1,1,2,2,1,1,1,1,1,1,1,2,2,1,1,1,1,1
1,1,1,2,2,2,1,1,1,1,1,1,1,2,2,1,1,1,1,1
1,1,1,1,1,1,1,1,1,1,1,1,1,1,1,1,1,1,1,1
1,2,1,1,1,1,1,1,1,1,1,1,1,1,1,1,1,2,2,1
2,2,1,1,1,2,1,1,2,2,2,1,1,2,2,1,1,2,2,1
2,2,1,1,1,2,2,1,1,2,1,1,1,2,2,1,1,1,1,1
1,1,1,1,1,1,1,1,1,2,1,1,2,2,1,1,1,1,1,1
1,1,1,1,1,1,1,1,1,1,1,1,1,1,1,1,1,1,2,1
1,1,1,1,1,1,1,1,1,1,1,1,1,1,1,1,1,1,2,2
1,1,1,1,1,1,2,1,1,1,1,1,2,2,1,1,1,1,1,1
1,1,1,1,1,2,2,1,1,1,1,1,2,2,1,1,1,1,1,1
1,1,1,1,1,1,1,1,1,1,1,1,1,1,1,1,1,1,1,1
1,2,1,1,1,1,1,1,1,1,1,1,1,1,1,1,1,2,1,1
2,2,2,1,1,1,1,1,1,1,1,1,2,1,1,1,1,2,2,1
2,2,1,1,1,1,1,1,1,1,1,2,2,1,1,2,2,1,1,1
1,1,1,1,1,1,1,1,1,1,1,1,1,1,1,1,2,1,1,1
1,1,1,1,1,2,2,1,1,1,1,2,2,1,1,1,1,1,1,1
1,1,1,1,2,2,2,1,1,1,2,2,2,1,1,1,1,1,1,1
1,1,1,1,1,2,1,1,1,1,2,2,1,1,1,1,1,1,1,1
endlayer

layer
1,1,1,1,1,2,1,1,1,1,1,1,1,2,1,1,1,1,1,1
1,1,1,1,2,3,2,1,1,1,1,1,2,2,2,1,1,1,1,1
1,1,1,1,1,2,1,1,1,1,1,1,1,2,1,1,1,1,1,1
1,1,1,1,1,1,1,1,1,1,1,1,1,1,1,1,1,2,1,1
1,2,1,1,1,1,1,1,1,2,1,1,1,1,1,1,1,2,2,1
2,2,2,1,1,2,3,1,2,2,2,1,2,2,1,1,1,1,1,1
1,1,1,1,1,2,2,2,2,2,2,3,3,2,1,1,1,1,1,1
1,1,1,1,1,1,1,1,2,3,3,3,3,1,1,1,1,1,2,1
1,1,1,1,1,1,3,1,3,3,3,3,2,1,1,1,1,1,2,1
1,1,1,1,1,2,3,1,1,3,3,2,2,2,1,1,1,2,2,1
1,1,1,1,1,1,2,1,1,2,1,2,2,2,1,1,1,1,1,1
1,1,2,1,1,1,1,1,1,1,1,1,1,1,1,1,1,2,1,1
1,2,2,2,1,1,1,1,1,1,1,1,1,1,1,1,2,3,1,1
2,2,2,1,1,1,1,1,1,1,1,2,2,1,1,2,2,2,1,1
1,2,1,1,1,1,1,1,1,1,1,2,2,1,1,2,2,1,1,1
1,1,1,1,1,1,2,1,1,1,1,1,1,1,1,1,1,1,1,1
1,1,1,1,1,2,2,1,1,2,2,2,1,1,1,1,1,1,1,1
1,1,1,1,1,2,3,1,1,1,3,2,1,1,1,1,1,1,1,1
1,1,1,1,1,1,1,1,1,1,2,1,1,1,1,1,1,1,1,1
endlayer

layer
1,1,1,1,1,1,1,1,1,1,1,1,1,1,1,1,1,1,1,1
1,1,1,1,2,3,2,1,1,1,1,1,3,2,1,1,1,1,1,1
1,1,1,1,2,2,2,2,1,1,1,3,3,2,1,1,1,1,1,1
1,1,1,1,1,1,2,1,1,1,1,2,1,1,1,1,1,1,1,1
1,1,1,1,1,1,1,1,1,1,2,1,1,1,1,1,3,2,1,1
1,2,2,1,1,1,2,2,2,2,3,1,1,1,1,1,2,2,1,1
1,2,3,2,1,2,2,2,3,3,3,3,3,2,1,1,1,1,1,1
1,1,3,3,1,1,2,2,3,3,3,3,3,1,1,1,1,1,1,1
1,1,1,1,1,1,3,3,3,3,3,3,3,1,1,1,1,1,2,1
1,1,1,1,1,1,2,3,3,3,3,3,2,2,1,1,1,2,3,1
1,1,1,1,1,1,1,3,3,3,3,3,3,1,1,1,1,2,1,1
1,2,3,3,1,1,1,1,2,3,1,1,1,1,1,1,2,2,1,1
1,2,2,2,1,1,1,1,1,1,1,3,1,1,1,2,2,2,1,1
1,2,2,1,1,1,1,1,1,1,1,2,2,1,1,2,2,1,1,1
1,1,1,1,1,1,1,2,1,1,1,1,1,1,1,2,1,1,1,1
1,1,1,1,1,1,2,2,1,2,1,1,1,1,1,1,1,1,1,1
1,1,1,1,1,1,2,3,1,3,2,2,1,1,1,1,1,1,1,1
1,1,1,1,1,2,3,2,1,2,2,1,1,1,1,1,1,1,1,1
1,1,1,1,1,1,1,1,1,1,1,1,1,1,1,1,1,1,1,1
endlayer

layer
1,1,1,1,1,1,1,1,1,1,1,1,1,1,1,1,1,1,1,1
1,1,1,1,1,2,2,1,1,1,1,2,2,1,1,1,1,1,1,1
1,1,1,1,2,3,3,2,1,1,2,3,2,2,1,1,1,1,1,1
1,1,1,1,2,2,3,2,2,1,3,3,2,1,1,1,1,1,1,1
1,1,1,1,1,1,1,3,3,3,3,2,2,1,1,1,2,1,1,1
1,1,2,2,1,1,1,3,3,3,3,3,1,1,1,3,3,2,1,1
1,2,2,2,2,1,3,3,3,3,3,3,3,1,1,3,2,1,1,1
1,2,2,2,2,2,3,3,4,4,4,3,3,1,1,1,1,1,1,1
1,1,2,2,2,2,3,3,4,4,4,4,3,2,1,1,1,1,1,1
1,1,1,2,2,3,3,3,4,4,4,3,3,2,1,1,2,2,2,1
1,1,2,3,2,2,3,3,3,4,3,3,3,1,1,1,3,2,1,1
1,1,3,3,3,2,1,2,3,3,3,2,1,1,1,3,2,2,1,1
1,2,2,2,1,1,1,1,1,1,1,3,1,1,2,2,2,1,1,1
1,1,2,1,1,1,1,2,3,1,1,2,1,1,1,2,1,1,1,1
1,1,1,1,1,1,2,3,3,1,1,1,1,1,1,1,1,1,1,1
1,1,1,1,1,1,2,3,3,3,1,1,1,1,1,1,1,1,1,1
1,1,1,1,1,1,2,2,2,2,2,1,1,1,1,1,1,1,1,1
1,1,1,1,1,1,2,2,1,2,1,1,1,1,1,1,1,1,1,1
1,1,1,1,1,1,1,1,1,1,1,1,1,1,1,1,1,1,1,1
endlayer

layer
1,1,1,1,1,1,1,1,1,1,1,1,1,1,1,1,1,1,1,1
1,1,1,1,1,1,1,1,1,1,2,1,1,1,1,1,1,1,1,1
1,1,1,1,1,2,2,2,1,1,3,2,2,1,1,1,1,1,1,1
1,1,1,1,2,2,3,2,2,2,2,2,2,2,1,1,1,1,1,1
1,1,1,1,2,2,2,3,3,3,3,3,2,2,1,2,1,1,1,1
1,1,2,2,2,1,3,3,3,3,3,3,2,1,1,2,2,1,1,1
1,1,2,2,2,2,3,3,3,4,4,3,3,2,2,2,2,1,1,1
1,2,2,2,2,3,3,4,4,4,4,4,3,3,2,1,1,1,1,1
1,2,2,2,2,3,4,4,4,4,4,4,3,2,3,2,1,1,1,1
1,1,2,2,2,3,3,4,4,4,4,4,3,2,2,3,2,1,1,1
1,1,2,2,2,3,3,3,4,4,4,3,3,3,2,3,2,2,1,1
1,1,2,2,2,2,3,3,3,4,3,3,2,2,2,2,2,1,1,1
1,1,2,2,2,2,3,3,3,3,3,2,2,2,2,2,1,1,1,1
1,1,1,1,1,1,2,2,2,2,2,1,1,1,1,1,1,1,1,1
1,1,1,1,1,1,2,2,2,2,1,1,1,1,1,1,1,1,1,1
1,1,1,1,1,1,2,2,3,2,2,1,1,1,1,1,1,1,1,1
1,1,1,1,1,1,2,2,2,2,1,1,1,1,1,1,1,1,1,1
1,1,1,1,1,1,1,1,1,1,1,1,1,1,1,1,1,1,1,1
1,1,1,1,1,1,1,1,1,1,1,1,1,1,1,1,1,1,1,1
endlayer

layer
1,1,1,1,1,1,1,1,1,1,1,1,1,1,1,1,1,1,1,1
1,1,1,1,1,1,1,1,1,1,1,1,1,1,1,1,1,1,1,1
1,1,1,1,1,1,1,2,2,2,2,2,1,1,1,1,1,1,1,1
1,1,1,1,1,1,2,2,2,2,2,2,2,1,1,1,1,1,1,1
1,1,1,1,2,2,3,3,3,3,3,3,2,2,2,1,1,1,1,1
1,1,1,2,2,3,3,3,3,3,3,3,3,2,2,2,1,1,1,1
1,1,2,2,3,3,3,3,4,4,4,4,3,3,2,2,1,1,1,1
1,1,2,2,3,3,4,4,4,4,4,4,3,3,2,2,1,1,1,1
1,1,2,2,3,3,4,4,4,4,4,4,4,3,2,2,1,1,1,1
1,1,2,2,3,3,4,4,4,4,4,4,4,3,2,2,2,1,1,1
1,1,2,2,3,3,3,4,4,4,4,4,3,3,2,2,2,1,1,1
1,1,2,2,3,3,3,3,4,4,4,3,3,2,2,2,1,1,1,1
1,1,1,2,2,3,3,3,3,3,3,3,2,2,2,1,1,1,1,1
1,1,1,1,2,2,3,3,3,3,2,2,2,1,1,1,1,1,1,1
1,1,1,1,1,2,2,2,2,2,2,2,1,1,1,1,1,1,1,1
1,1,1,1,1,1,2,2,2,2,1,1,1,1,1,1,1,1,1,1
1,1,1,1,1,1,1,2,2,1,1,1,1,1,1,1,1,1,1,1
1,1,1,1,1,1,1,1,1,1,1,1,1,1,1,1,1,1,1,1
1,1,1,1,1,1,1,1,1,1,1,1,1,1,1,1,1,1,1,1
endlayer

layer
1,1,1,1,1,1,1,1,1,1,1,1,1,1,1,1,1,1,1,1
1,1,1,1,1,1,1,1,1,1,1,1,1,1,1,1,1,1,1,1
1,1,1,1,1,1,1,1,2,2,2,1,1,1,1,1,1,1,1,1
1,1,1,1,1,1,2,2,2,2,2,2,2,1,1,1,1,1,1,1
1,1,1,1,1,2,2,3,3,3,3,2,2,2,1,1,1,1,1,1
1,1,1,1,2,2,3,3,3,3,3,3,2,2,1,1,1,1,1,1
1,1,1,2,2,3,3,3,4,4,4,4,3,2,2,1,1,1,1,1
1,1,1,2,3,3,3,4,4,4,4,4,3,3,2,2,1,1,1,1
1,1,2,2,3,3,4,4,0,0,0,4,3,3,2,2,1,1,1,1
1,1,2,2,3,3,4,4,0,0,0,4,3,3,2,2,1,1,1,1
1,1,1,2,3,3,3,4,4,0,4,3,3,3,2,2,1,1,1,1
1,1,1,2,3,3,3,3,4,4,3,3,3,3,2,1,1,1,1,1
1,1,1,2,2,3,3,3,3,3,3,3,3,2,1,1,1,1,1,1
1,1,1,1,1,2,2,3,3,3,2,2,2,1,1,1,1,1,1,1
1,1,1,1,1,2,2,2,2,2,2,1,1,1,1,1,1,1,1,1
1,1,1,1,1,1,2,2,2,2,1,1,1,1,1,1,1,1,1,1
1,1,1,1,1,1,1,1,1,1,1,1,1,1,1,1,1,1,1,1
1,1,1,1,1,1,1,1,1,1,1,1,1,1,1,1,1,1,1,1
1,1,1,1,1,1,1,1,1,1,1,1,1,1,1,1,1,1,1,1
endlayer

layer
1,1,1,1,1,1,1,1,1,1,1,1,1,1,1,1,1,1,1,1
1,1,1,1,1,1,1,1,1,1,1,1,1,1,1,1,1,1,1,1
1,1,1,1,1,1,1,1,1,2,1,1,1,1,1,1,1,1,1,1
1,1,1,1,1,1,1,2,2,2,2,2,1,1,1,1,1,1,1,1
1,1,1,1,1,2,2,3,3,3,3,2,2,1,1,1,1,1,1,1
1,1,1,1,1,3,3,3,3,3,3,3,2,2,1,1,1,1,1,1
1,1,1,1,3,3,3,3,4,4,3,3,3,3,1,1,1,1,1,1
1,1,1,2,3,3,3,4,0,0,0,4,3,3,2,1,1,1,1,1
1,1,1,2,3,3,4,0,0,0,0,0,3,3,2,1,1,1,1,1
1,1,1,2,3,3,4,0,0,0,0,0,3,3,2,1,1,1,1,1
1,1,1,2,3,3,3,0,0,0,0,3,3,3,2,1,1,1,1,1
1,1,1,2,2,3,3,3,0,0,3,3,3,3,1,1,1,1,1,1
1,1,1,1,2,2,3,3,3,3,3,3,3,2,1,1,1,1,1,1
1,1,1,1,1,2,2,3,3,3,2,2,1,1,1,1,1,1,1,1
1,1,1,1,1,1,2,2,2,2,1,1,1,1,1,1,1,1,1,1
1,1,1,1,1,1,1,2,2,1,1,1,1,1,1,1,1,1,1,1
1,1,1,1,1,1,1,1,1,1,1,1,1,1,1,1,1,1,1,1
1,1,1,1,1,1,1,1,1,1,1,1,1,1,1,1,1,1,1,1
1,1,1,1,1,1,1,1,1,1,1,1,1,1,1,1,1,1,1,1
endlayer

layer
1,1,1,1,1,1,1,1,1,1,1,1,1,1,1,1,1,1,1,1
1,1,1,1,1,1,1,1,1,1,1,1,1,1,1,1,1,1,1,1
1,1,1,1,1,1,1,1,0,1,1,1,1,1,1,1,1,1,1,1
1,1,1,1,1,1,1,1,2,2,2,2,1,1,1,1,1,1,1,1
1,1,1,1,1,1,2,3,3,3,3,2,1,1,1,1,1,1,1,1
1,1,1,1,1,3,3,3,3,3,3,3,3,1,1,1,1,1,1,1
1,1,1,1,3,3,3,3,0,0,3,3,3,3,1,1,1,1,1,1
1,1,1,1,3,3,3,0,0,0,0,0,3,3,1,1,1,1,1,1
1,1,1,1,3,3,0,0,0,0,0,0,0,3,2,1,1,1,1,1
1,1,1,2,3,3,0,0,0,0,0,0,3,3,2,1,1,1,1,1
1,1,1,2,3,3,0,0,0,0,0,0,3,3,1,1,1,1,1,1
1,1,1,1,3,3,3,3,0,0,0,3,3,2,1,1,1,1,1,1
1,1,1,1,1,3,3,3,3,0,3,3,3,1,1,1,1,1,1,1
1,1,1,1,1,2,3,3,3,3,0,1,1,1,1,1,1,1,1,1
1,1,1,1,1,1,2,2,2,0,1,1,1,1,1,1,1,1,1,1
1,1,1,1,1,1,1,1,1,1,1,1,1,1,1,1,1,1,1,1
1,1,1,1,1,1,1,1,1,1,1,1,1,1,1,1,1,1,1,1
1,1,1,1,1,1,1,1,1,1,1,1,1,1,1,1,1,1,1,1
1,1,1,1,1,1,1,1,1,1,1,1,1,1,1,1,1,1,1,1
endlayer

layer
1,1,1,1,1,1,1,1,1,1,1,1,1,1,1,1,1,1,1,1
1,1,1,1,1,1,1,1,1,1,1,1,1,1,1,1,1,1,1,1
1,1,1,1,1,1,1,1,1,1,1,1,1,1,1,1,1,1,1,1
1,1,1,1,1,1,1,1,0,0,2,1,1,1,1,1,1,1,1,1
1,1,1,1,1,1,0,3,3,3,3,3,1,1,1,1,1,1,1,1
1,1,1,1,1,2,3,3,0,3,3,3,1,1,1,1,1,1,1,1
1,1,1,1,3,3,3,0,0,0,0,3,3,1,1,1,1,1,1,1
1,1,1,1,3,3,3,0,0,0,0,0,0,3,1,1,1,1,1,1
1,1,1,1,3,3,0,0,0,0,0,0,0,3,1,1,1,1,1,1
1,1,1,1,3,3,0,0,0,0,0,0,3,3,1,1,1,1,1,1
1,1,1,1,3,0,0,0,0,0,0,0,3,3,1,1,1,1,1,1
1,1,1,1,3,3,3,0,0,0,0,3,3,1,1,1,1,1,1,1
1,1,1,1,1,3,3,3,0,0,3,3,2,1,1,1,1,1,1,1
1,1,1,1,1,1,3,3,3,0,0,1,1,1,1,1,1,1,1,1
1,1,1,1,1,1,1,2,0,0,1,1,1,1,1,1,1,1,1,1
1,1,1,1,1,1,1,1,1,1,1,1,1,1,1,1,1,1,1,1
1,1,1,1,1,1,1,1,1,1,1,1,1,1,1,1,1,1,1,1
1,1,1,1,1,1,1,1,1,1,1,1,1,1,1,1,1,1,1,1
1,1,1,1,1,1,1,1,1,1,1,1,1,1,1,1,1,1,1,1
endlayer

layer
1,1,1,1,1,1,1,1,1,1,1,1,1,1,1,1,1,1,1,1
1,1,1,1,1,1,1,1,1,1,1,1,1,1,1,1,1,1,1,1
1,1,1,1,1,1,1,1,1,1,1,1,1,1,1,1,1,1,1,1
1,1,1,1,1,1,1,0,0,0,0,0,1,1,1,1,1,1,1,1
1,1,1,1,1,1,0,3,0,3,3,3,1,1,1,1,1,1,1,1
1,1,1,1,1,3,3,3,0,0,3,3,1,1,1,1,1,1,1,1
1,1,1,1,2,3,3,0,0,0,0,0,3,1,1,1,1,1,1,1
1,1,1,1,3,3,0,0,0,0,0,0,0,0,1,1,1,1,1,1
1,1,1,1,3,3,0,0,0,0,0,0,0,3,1,1,1,1,1,1
1,1,1,1,3,0,0,0,0,0,0,0,3,3,1,1,1,1,1,1
1,1,1,1,0,0,0,0,0,0,0,0,3,3,1,1,1,1,1,1
1,1,1,1,3,3,0,0,0,0,0,3,3,1,1,1,1,1,1,1
1,1,1,1,0,3,3,3,0,0,3,3,0,1,1,1,1,1,1,1
1,1,1,1,1,0,3,3,3,0,0,1,1,1,1,1,1,1,1,1
1,1,1,1,1,1,0,0,0,0,1,1,1,1,1,1,1,1,1,1
1,1,1,1,1,1,1,1,1,1,1,1,1,1,1,1,1,1,1,1
1,1,1,1,1,1,1,1,1,1,1,1,1,1,1,1,1,1,1,1
1,1,1,1,1,1,1,1,1,1,1,1,1,1,1,1,1,1,1,1
1,1,1,1,1,1,1,1,1,1,1,1,1,1,1,1,1,1,1,1
endlayer

layer
1,1,1,1,1,1,1,1,1,1,1,1,1,1,1,1,1,1,1,1
1,1,1,1,1,1,1,1,1,1,1,1,1,1,1,1,1,1,1,1
1,1,1,1,1,1,1,1,1,1,1,1,1,1,1,1,1,1,1,1
1,1,1,1,1,1,1,0,0,0,0,0,1,1,1,1,1,1,1,1
1,1,1,1,1,1,0,0,0,0,3,3,1,1,1,1,1,1,1,1
1,1,1,1,1,0,3,3,0,0,3,3,0,1,1,1,1,1,1,1
1,1,1,1,3,3,3,0,0,0,0,0,0,0,1,1,1,1,1,1
1,1,1,1,3,3,0,0,0,0,0,0,0,0,1,1,1,1,1,1
1,1,1,1,3,0,0,0,0,0,0,0,0,0,1,1,1,1,1,1
1,1,1,1,0,0,0,0,0,0,0,0,3,3,0,1,1,1,1,1
1,1,1,0,0,0,0,0,0,0,0,3,3,0,1,1,1,1,1,1
1,1,1,1,0,3,0,0,0,0,0,3,3,1,1,1,1,1,1,1
1,1,1,1,0,3,0,3,0,0,3,3,0,1,1,1,1,1,1,1
1,1,1,1,1,0,3,3,3,0,2,1,1,1,1,1,1,1,1,1
1,1,1,1,1,0,0,0,0,0,1,1,1,1,1,1,1,1,1,1
1,1,1,1,1,1,1,1,1,1,1,1,1,1,1,1,1,1,1,1
1,1,1,1,1,1,1,1,1,1,1,1,1,1,1,1,1,1,1,1
1,1,1,1,1,1,1,1,1,1,1,1,1,1,1,1,1,1,1,1
1,1,1,1,1,1,1,1,1,1,1,1,1,1,1,1,1,1,1,1
endlayer

layer
1,1,1,1,1,1,1,1,1,1,1,1,1,1,1,1,1,1,1,1
1,1,1,1,1,1,1,1,1,1,1,1,1,1,1,1,1,1,1,1
1,1,1,1,1,1,1,1,1,0,1,1,1,1,1,1,1,1,1,1
1,1,1,1,1,1,0,0,0,0,0,0,1,1,1,1,1,1,1,1
1,1,1,1,1,1,0,0,0,0,3,0,0,1,1,1,1,1,1,1
1,1,1,1,1,0,3,0,0,0,0,3,0,1,1,1,1,1,1,1
1,1,1,1,3,3,3,0,0,0,0,0,0,0,1,1,1,1,1,1
1,1,1,1,3,0,0,0,0,0,0,0,0,0,1,1,1,1,1,1
1,1,1,0,3,0,0,0,0,0,0,0,0,0,0,1,1,1,1,1
1,1,1,0,0,0,0,0,0,0,0,0,3,0,0,1,1,1,1,1
1,1,1,0,0,0,0,0,0,0,0,3,3,0,1,1,1,1,1,1
1,1,1,0,0,3,0,0,0,0,0,3,0,0,1,1,1,1,1,1
1,1,1,1,0,0,0,3,0,0,3,3,0,1,1,1,1,1,1,1
1,1,1,1,0,0,3,3,3,3,3,0,1,1,1,1,1,1,1,1
1,1,1,1,1,0,0,0,0,0,1,1,1,1,1,1,1,1,1,1
1,1,1,1,1,1,1,0,1,1,1,1,1,1,1,1,1,1,1,1
1,1,1,1,1,1,1,1,1,1,1,1,1,1,1,1,1,1,1,1
1,1,1,1,1,1,1,1,1,1,1,1,1,1,1,1,1,1,1,1
1,1,1,1,1,1,1,1,1,1,1,1,1,1,1,1,1,1,1,1
endlayer

layer
1,1,1,1,1,1,1,1,1,1,1,1,1,1,1,1,1,1,1,1
1,1,1,1,1,1,1,1,1,1,1,1,1,1,1,1,1,1,1,1
1,1,1,1,1,1,1,1,0,0,1,1,1,1,1,1,1,1,1,1
1,1,1,1,1,1,0,0,0,0,0,0,1,1,1,1,1,1,1,1
1,1,1,1,1,0,0,0,0,0,0,0,0,1,1,1,1,1,1,1
1,1,1,1,1,0,0,0,0,0,0,3,0,1,1,1,1,1,1,1
1,1,1,1,0,3,3,0,0,0,0,0,0,0,1,1,1,1,1,1
1,1,1,0,3,0,0,0,0,0,0,0,0,0,1,1,1,1,1,1
1,1,1,0,0,0,0,0,0,0,0,0,0,0,0,1,1,1,1,1
1,1,0,0,0,0,0,0,0,0,0,0,3,0,0,1,1,1,1,1
1,1,0,0,0,0,0,0,0,0,0,0,0,0,0,1,1,1,1,1
1,1,1,0,0,0,0,0,0,0,3,3,0,0,1,1,1,1,1,1
1,1,1,1,0,0,0,3,3,0,3,0,0,0,1,1,1,1,1,1
1,1,1,1,0,0,3,3,3,3,3,0,1,1,1,1,1,1,1,1
1,1,1,1,1,0,0,0,0,0,0,1,1,1,1,1,1,1,1,1
1,1,1,1,1,1,1,0,0,1,1,1,1,1,1,1,1,1,1,1
1,1,1,1,1,1,1,1,1,1,1,1,1,1,1,1,1,1,1,1
1,1,1,1,1,1,1,1,1,1,1,1,1,1,1,1,1,1,1,1
1,1,1,1,1,1,1,1,1,1,1,1,1,1,1,1,1,1,1,1
endlayer

layer
1,1,1,1,1,1,1,1,1,1,1,1,1,1,1,1,1,1,1,1
1,1,1,1,1,1,1,1,1,1,1,1,1,1,1,1,1,1,1,1
1,1,1,1,1,1,1,0,0,0,0,1,1,1,1,1,1,1,1,1
1,1,1,1,1,1,0,0,0,0,0,0,1,1,1,1,1,1,1,1
1,1,1,1,1,0,0,0,0,0,0,0,0,1,1,1,1,1,1,1
1,1,1,1,0,0,0,0,0,0,0,0,0,0,1,1,1,1,1,1
1,1,1,0,0,3,0,0,0,0,0,0,0,0,1,1,1,1,1,1
1,1,1,0,3,0,0,0,0,0,0,0,0,0,0,1,1,1,1,1
1,1,0,0,0,0,0,0,0,0,0,0,0,0,0,1,1,1,1,1
1,1,0,0,0,0,0,0,0,0,0,0,0,0,0,0,1,1,1,1
1,1,0,0,0,0,0,0,0,0,0,0,0,0,0,1,1,1,1,1
1,1,1,0,0,0,0,0,0,0,0,0,0,0,0,1,1,1,1,1
1,1,1,0,0,0,0,0,3,3,3,0,0,0,1,1,1,1,1,1
1,1,1,1,0,0,0,3,3,3,0,0,0,1,1,1,1,1,1,1
1,1,1,1,0,0,0,0,0,0,0,1,1,1,1,1,1,1,1,1
1,1,1,1,1,1,0,0,0,0,1,1,1,1,1,1,1,1,1,1
1,1,1,1,1,1,1,1,0,1,1,1,1,1,1,1,1,1,1,1
1,1,1,1,1,1,1,1,1,1,1,1,1,1,1,1,1,1,1,1
1,1,1,1,1,1,1,1,1,1,1,1,1,1,1,1,1,1,1,1
endlayer

layer
1,1,1,1,1,1,1,1,1,1,1,1,1,1,1,1,1,1,1,1
1,1,1,1,1,1,1,1,1,0,1,1,1,1,1,1,1,1,1,1
1,1,1,1,1,1,1,0,0,0,0,1,1,1,1,1,1,1,1,1
1,1,1,1,1,0,0,0,0,0,0,0,1,1,1,1,1,1,1,1
1,1,1,1,1,0,0,0,0,0,0,0,0,1,1,1,1,1,1,1
1,1,1,1,0,0,0,0,0,0,0,0,0,0,1,1,1,1,1,1
1,1,1,0,0,0,0,0,0,0,0,0,0,0,1,1,1,1,1,1
1,1,0,0,3,0,0,0,0,0,0,0,0,0,0,1,1,1,1,1
1,1,0,0,0,0,0,0,0,0,0,0,0,0,0,1,1,1,1,1
1,1,0,0,0,0,0,0,0,0,0,0,0,0,0,0,1,1,1,1
1,0,0,0,0,0,0,0,0,0,0,0,0,0,0,0,1,1,1,1
1,1,0,0,0,0,0,0,0,0,0,0,0,0,0,1,1,1,1,1
1,1,1,0,0,0,0,0,0,3,0,0,0,0,1,1,1,1,1,1
1,1,1,0,0,0,0,3,0,0,0,0,0,0,1,1,1,1,1,1
1,1,1,1,0,0,0,0,0,0,0,0,1,1,1,1,1,1,1,1
1,1,1,1,1,1,0,0,0,0,1,1,1,1,1,1,1,1,1,1
1,1,1,1,1,1,1,0,0,1,1,1,1,1,1,1,1,1,1,1
1,1,1,1,1,1,1,1,1,1,1,1,1,1,1,1,1,1,1,1
1,1,1,1,1,1,1,1,1,1,1,1,1,1,1,1,1,1,1,1
endlayer

layer
1,1,1,1,1,1,1,1,1,1,1,1,1,1,1,1,1,1,1,1
1,1,1,1,1,1,1,1,1,0,0,1,1,1,1,1,1,1,1,1
1,1,1,1,1,1,0,0,0,0,0,0,1,1,1,1,1,1,1,1
1,1,1,1,1,0,0,0,0,0,0,0,0,1,1,1,1,1,1,1
1,1,1,1,0,0,0,0,0,0,0,0,0,0,1,1,1,1,1,1
1,1,1,0,0,0,0,0,0,0,0,0,0,0,1,1,1,1,1,1
1,1,0,0,0,0,0,0,0,0,0,0,0,0,0,1,1,1,1,1
1,1,0,0,0,0,0,0,0,0,0,0,0,0,0,1,1,1,1,1
1,1,0,0,0,0,0,0,0,0,0,0,0,0,0,0,1,1,1,1
1,0,0,0,0,0,0,0,0,0,0,0,0,0,0,0,0,1,1,1
1,0,0,0,0,0,0,0,0,0,0,0,0,0,0,0,1,1,1,1
1,0,0,0,0,0,0,0,0,0,0,0,0,0,0,0,1,1,1,1
1,1,0,0,0,0,0,0,0,0,0,0,0,0,0,1,1,1,1,1
1,1,1,0,0,0,0,3,0,0,0,0,0,0,1,1,1,1,1,1
1,1,1,1,0,0,0,0,0,0,0,0,0,1,1,1,1,1,1,1
1,1,1,1,1,0,0,0,0,0,0,1,1,1,1,1,1,1,1,1
1,1,1,1,1,1,1,0,0,0,1,1,1,1,1,1,1,1,1,1
1,1,1,1,1,1,1,1,1,1,1,1,1,1,1,1,1,1,1,1
1,1,1,1,1,1,1,1,1,1,1,1,1,1,1,1,1,1,1,1
endlayer

layer
1,1,1,1,1,1,1,1,1,1,1,1,1,1,1,1,1,1,1,1
1,1,1,1,1,1,1,1,0,0,0,0,1,1,1,1,1,1,1,1
1,1,1,1,1,1,0,0,0,0,0,0,0,1,1,1,1,1,1,1
1,1,1,1,0,0,0,0,0,0,0,0,0,0,1,1,1,1,1,1
1,1,1,0,0,0,0,0,0,0,0,0,0,0,0,1,1,1,1,1
1,1,0,0,0,0,0,0,0,0,0,0,0,0,0,1,1,1,1,1
1,1,0,0,0,0,0,0,0,0,0,0,0,0,0,0,1,1,1,1
1,1,0,0,0,0,0,0,0,0,0,0,0,0,0,0,1,1,1,1
1,0,0,0,0,0,0,0,0,0,0,0,0,0,0,0,0,1,1,1
1,0,0,0,0,0,0,0,0,0,0,0,0,0,0,0,0,1,1,1
1,0,0,0,0,0,0,0,0,0,0,0,0,0,0,0,0,1,1,1
1,0,0,0,0,0,0,0,0,0,0,0,0,0,0,0,1,1,1,1
1,0,0,0,0,0,0,0,0,0,0,0,0,0,0,0,1,1,1,1
1,1,0,0,0,0,0,0,0,0,0,0,0,0,0,1,1,1,1,1
1,1,1,0,0,0,0,0,0,0,0,0,0,0,1,1,1,1,1,1
1,1,1,1,0,0,0,0,0,0,0,0,0,1,1,1,1,1,1,1
1,1,1,1,1,1,0,0,0,0,0,1,1,1,1,1,1,1,1,1
1,1,1,1,1,1,1,1,1,1,1,1,1,1,1,1,1,1,1,1
1,1,1,1,1,1,1,1,1,1,1,1,1,1,1,1,1,1,1,1
endlayer

