
# Created by Ruins mod version 16.7 Ingame Parser
# authoring Player: lafuller

weight=1
embed_into_distance=8
acceptable_target_blocks=
unacceptable_target_blocks=flowing_water,water,flowing_lava,lava,ice,bedrock,netherrack,nether_brick,nether_brick_fence,soul_sand,quartz_ore,gravel,end_stone,obsidian,iron_bars,cloud,flesh,ash_block,slime_grass,slime_congealed,slime_dirt
biomesToSpawnIn=forest,foresthills,woodlands,woodland,flower forest
dimensions=22,23,22
allowable_overhang=0
max_leveling=8
leveling_buffer=-1
preserve_water=0
preserve_lava=0

rule1=0,100,preserveBlock
rule2=0,100,minecraft:log-13
rule3=0,100,minecraft:log-1
rule4=0,100,minecraft:brown_mushroom_block-0
rule5=0,100,ChestGenHook:chests/spawn_bonus_chest:5-5
rule6=0,100,minecraft:log-0
rule7=0,100,minecraft:log2-1
rule8=0,100,minecraft:log2-13

layer
1,1,1,1,1,2,1,1,2,1,1,1,1,1,1,1,2,1,1,2,1,1
1,1,1,1,1,1,1,1,2,1,1,1,2,1,1,2,2,1,1,1,1,1
2,1,1,1,1,1,2,2,2,1,1,1,1,1,1,1,1,1,1,1,1,2
1,1,1,1,1,2,1,1,1,1,1,1,1,1,1,1,1,1,1,1,1,1
1,1,1,1,1,1,1,1,1,1,1,1,1,1,1,1,1,1,1,1,1,1
1,1,1,2,1,1,1,1,1,1,1,1,1,1,1,1,2,1,1,1,1,2
1,1,2,2,1,1,1,1,1,1,1,1,1,1,1,2,2,1,1,1,1,1
1,1,1,1,1,1,1,1,1,1,1,1,1,1,1,2,1,1,1,1,1,1
2,1,1,1,1,2,1,1,1,1,1,1,1,1,1,1,1,1,1,1,1,1
1,1,1,1,1,1,1,1,1,1,1,1,1,1,1,1,1,1,1,1,2,1
1,1,1,1,1,1,1,1,1,1,1,1,1,1,1,1,1,1,1,1,1,1
1,1,1,1,1,1,1,1,1,1,1,1,1,1,1,1,1,1,1,1,1,1
2,1,1,1,1,1,1,1,1,1,1,1,1,1,1,1,1,1,1,1,1,1
1,1,1,1,1,1,1,1,1,1,1,1,1,1,1,1,1,1,1,1,1,1
1,1,1,1,1,1,1,1,1,1,1,1,1,1,1,1,1,1,1,1,1,1
1,1,2,1,1,1,1,1,1,1,1,1,1,1,1,1,1,1,1,1,1,2
1,1,1,1,1,1,1,1,1,1,1,1,1,1,1,1,1,1,1,2,1,1
1,1,1,1,1,1,1,1,1,1,1,1,1,1,1,1,1,1,1,1,1,1
1,1,1,1,1,1,2,1,1,1,1,1,1,1,1,1,1,1,1,1,1,1
1,1,1,1,1,1,1,1,1,1,1,1,1,1,1,1,1,2,1,1,1,2
1,1,1,1,1,1,1,1,1,2,1,1,1,1,1,1,1,1,1,1,1,1
2,1,1,1,1,1,1,1,1,2,1,1,1,1,2,1,1,1,1,2,1,1
1,1,1,1,2,1,1,1,1,1,1,1,1,1,1,1,2,1,1,1,1,1
endlayer

layer
1,1,1,1,1,2,1,1,1,1,1,1,2,1,1,1,1,1,1,2,1,1
1,1,1,1,1,1,1,1,1,1,1,1,2,1,1,2,1,1,1,1,1,1
2,1,1,1,1,1,1,1,2,1,1,1,1,1,1,1,1,1,1,1,1,2
2,1,1,1,1,2,1,1,2,2,1,1,1,1,1,1,1,1,1,1,1,1
1,1,1,1,1,2,1,1,1,2,1,1,1,1,1,1,1,1,1,1,1,1
1,1,1,2,2,1,1,1,1,1,1,1,1,1,1,1,1,1,1,1,1,2
1,1,1,1,1,1,1,1,1,1,1,1,1,1,1,1,1,1,1,2,2,2
1,1,1,1,1,1,1,1,1,1,1,1,1,1,2,2,1,1,1,1,1,1
2,2,1,1,2,2,1,1,1,1,1,1,1,1,2,1,1,1,1,1,1,1
1,1,1,1,1,1,1,1,1,1,1,1,1,1,1,1,1,1,1,1,2,1
1,1,1,1,1,1,1,1,1,1,1,1,1,1,1,1,1,1,1,1,1,1
2,1,1,1,1,1,1,1,1,1,1,1,1,1,1,1,1,1,1,1,1,1
2,1,1,1,1,1,1,1,1,1,1,1,1,1,1,1,1,1,1,1,1,1
1,1,1,1,1,1,1,1,1,1,1,1,1,1,1,1,1,1,1,1,1,1
1,1,2,2,1,1,1,1,1,1,1,1,1,1,1,1,1,1,1,1,1,1
1,1,2,1,1,1,1,1,1,1,1,1,1,1,1,1,1,1,1,1,1,2
1,1,1,1,1,1,1,1,1,1,1,1,1,1,1,1,1,1,2,2,1,1
1,1,1,1,1,1,2,1,1,1,1,1,1,1,1,1,1,1,1,1,1,1
1,1,1,1,1,1,2,1,1,1,1,1,1,1,1,1,1,1,1,1,1,1
1,1,1,1,1,1,1,1,1,1,2,1,1,1,1,1,1,2,1,1,1,2
2,1,1,1,1,1,1,1,1,2,2,1,1,1,2,1,1,1,1,1,1,2
2,1,1,1,1,1,1,1,1,1,1,1,1,2,1,1,1,1,1,2,1,1
1,1,1,1,2,1,1,1,1,1,1,1,1,1,1,1,2,1,1,1,1,1
endlayer

layer
1,1,1,1,1,2,2,1,1,1,1,2,2,1,1,1,1,1,1,1,1,1
1,1,1,1,1,1,1,1,1,1,1,1,1,1,1,1,1,1,2,2,1,1
1,1,1,1,1,1,1,1,1,1,1,1,1,1,2,2,1,1,1,1,1,2
2,1,1,1,1,1,1,1,1,2,1,1,1,1,1,1,1,1,1,1,1,2
2,2,1,1,2,2,1,1,1,2,2,1,1,1,1,1,1,1,1,1,1,1
1,1,1,1,2,2,1,1,1,2,2,2,1,1,1,1,1,1,1,1,1,1
1,1,1,1,1,1,2,1,1,1,2,1,1,1,1,1,1,1,1,2,1,1
1,1,1,1,1,1,1,1,1,1,1,1,1,2,1,1,1,1,2,2,1,1
1,2,1,1,2,1,1,1,1,1,1,1,2,2,2,1,1,1,1,1,1,2
1,1,1,1,2,1,1,1,1,1,1,1,2,1,1,1,1,1,1,1,2,2
1,1,1,1,1,1,1,1,1,1,1,1,1,1,1,1,1,1,1,1,1,1
2,1,1,1,1,1,1,1,1,1,1,1,1,1,1,1,1,1,1,1,1,1
1,1,1,1,1,1,1,1,1,1,1,1,1,1,1,1,1,1,1,1,1,1
1,1,1,1,1,1,1,1,1,1,1,1,1,1,1,1,1,1,1,1,1,1
1,1,1,2,2,1,1,1,1,1,1,1,1,1,1,1,1,1,1,1,1,1
1,1,1,1,1,1,1,1,1,1,1,1,1,1,1,1,1,1,2,1,1,2
1,1,1,1,1,1,1,2,1,1,1,1,1,1,1,1,1,1,2,1,1,2
1,1,1,1,1,1,2,2,1,1,1,2,1,1,1,1,1,1,1,1,1,1
1,1,1,1,1,1,1,1,1,1,2,2,2,1,1,2,2,1,1,1,1,1
1,1,1,1,1,1,1,1,1,1,2,1,1,2,1,1,2,1,1,1,1,1
2,1,1,1,1,1,1,1,1,1,1,1,1,2,1,1,1,1,1,1,1,2
1,1,1,1,1,1,1,1,1,1,1,1,1,1,1,1,1,1,2,1,1,1
1,1,1,1,2,2,1,1,1,1,1,1,1,1,1,2,2,1,1,1,1,1
endlayer

layer
1,1,1,1,1,1,2,1,1,1,1,2,1,1,1,1,1,1,1,1,1,1
1,1,1,1,1,1,2,1,1,1,1,1,1,1,1,1,1,1,2,1,1,1
1,1,1,1,1,1,1,1,1,1,1,1,1,1,2,1,1,1,2,1,1,1
1,1,1,1,1,1,1,1,1,1,1,1,1,1,2,1,1,1,1,1,1,2
2,2,1,1,1,1,1,1,1,2,1,1,1,1,1,1,1,1,1,1,1,1
1,2,1,1,1,2,1,1,1,2,2,1,1,1,1,1,1,1,1,1,1,1
1,1,1,1,1,2,2,1,1,1,2,2,1,1,1,1,1,1,1,1,1,1
1,2,1,1,1,1,2,1,1,1,2,2,1,1,1,1,1,2,2,1,1,1
1,1,1,1,1,1,1,1,1,1,2,2,2,2,1,1,1,2,1,1,1,2
1,1,1,1,2,1,1,1,2,2,2,2,2,2,1,1,1,1,1,1,1,1
1,1,1,1,1,1,1,2,2,2,2,2,2,1,1,1,1,1,1,1,1,1
2,2,1,1,1,1,1,2,2,2,2,2,2,2,1,1,1,1,1,1,1,1
1,2,1,1,1,1,2,2,2,2,2,2,2,2,1,1,1,1,1,1,1,1
1,1,1,1,2,2,2,1,2,2,2,2,2,2,1,1,1,1,1,1,1,1
1,1,1,1,2,2,1,1,2,2,2,2,2,1,1,1,2,1,1,1,1,1
1,1,1,1,1,1,1,2,2,2,2,2,1,1,1,1,1,2,2,1,1,1
1,1,1,1,1,1,1,2,2,1,2,2,1,1,1,1,1,2,1,1,1,2
1,1,1,1,1,1,1,2,1,1,1,2,2,1,1,2,1,1,1,1,1,1
1,1,1,1,1,1,1,1,1,1,1,2,2,1,1,2,2,1,1,1,1,1
2,2,1,1,1,1,1,1,1,1,1,2,2,1,1,1,1,1,1,1,2,1
2,1,1,1,1,1,1,1,1,1,1,1,1,1,1,1,1,1,1,1,2,2
1,1,1,1,2,2,1,1,1,1,1,1,1,1,1,1,1,1,2,1,1,1
1,1,1,1,1,2,1,1,1,1,1,1,1,1,1,2,1,1,2,1,1,1
endlayer

layer
1,1,1,1,1,1,1,1,1,1,2,1,1,1,1,1,1,1,1,1,1,1
1,1,1,1,1,1,2,2,1,1,2,1,1,1,1,1,1,1,1,1,1,1
1,1,1,1,1,1,1,1,1,1,1,1,1,1,1,1,1,2,2,1,1,1
1,1,1,1,1,1,1,1,1,1,1,1,1,2,2,1,1,1,1,1,1,2
1,1,1,1,1,1,1,1,1,1,1,1,1,2,2,1,1,1,1,1,1,2
1,2,2,1,1,1,1,1,1,1,2,1,1,1,1,1,1,1,1,1,1,1
1,1,2,2,1,1,2,1,1,1,2,2,1,1,1,1,1,1,1,1,1,1
1,2,2,1,1,1,2,1,1,1,2,2,1,1,1,1,1,2,1,1,1,1
1,1,1,1,1,1,1,1,1,2,2,2,2,1,1,1,2,2,1,1,1,2
1,1,1,1,2,2,1,2,3,4,4,4,3,2,1,1,1,1,1,1,1,2
1,1,1,1,1,1,2,3,4,4,4,4,4,2,1,1,1,1,1,1,1,1
1,1,1,1,1,1,2,4,4,4,4,4,4,4,2,1,1,1,1,1,1,1
1,2,1,1,1,2,2,4,4,4,4,4,4,4,2,2,1,1,1,1,1,1
1,1,1,1,2,2,2,2,4,4,4,4,4,4,2,2,1,1,1,1,1,1
1,1,1,1,2,2,2,2,4,4,4,4,4,2,2,1,3,2,1,1,1,1
1,1,1,1,1,1,1,2,2,3,4,4,2,2,1,1,2,1,1,1,1,1
1,1,1,1,1,1,1,2,2,2,2,3,2,2,2,1,1,1,1,1,2,2
1,1,1,1,1,1,1,1,1,1,2,2,2,1,2,2,1,1,1,1,1,1
1,1,1,1,1,1,1,1,1,1,2,2,2,1,1,1,1,1,1,1,1,1
1,2,2,1,1,1,1,1,1,1,1,2,1,1,1,1,1,1,1,1,2,1
1,1,1,1,1,1,1,1,1,1,1,1,1,1,1,1,1,1,1,1,2,1
1,1,1,1,1,2,1,1,1,1,1,1,1,1,1,1,1,1,1,1,1,1
1,1,1,1,1,2,1,1,1,1,1,1,1,1,1,2,1,1,2,1,1,1
endlayer

layer
1,1,1,1,1,1,1,1,1,1,1,1,1,1,1,1,1,1,1,1,1,1
1,1,1,1,1,1,1,2,1,1,2,2,1,1,1,1,1,1,1,1,1,1
1,1,1,1,1,1,2,2,1,1,1,1,1,1,1,1,1,2,1,1,1,1
1,1,1,1,1,1,1,1,1,1,1,1,1,2,1,1,1,1,1,1,1,1
1,1,1,1,1,1,1,1,1,1,1,1,1,3,1,1,1,1,1,1,2,1
1,1,2,1,1,1,1,1,1,1,1,1,2,2,1,1,1,1,1,1,2,1
1,2,2,2,2,1,1,2,1,1,2,3,2,1,1,1,1,1,1,1,1,1
1,1,2,1,2,1,3,2,2,2,3,3,2,1,1,2,2,1,1,1,1,1
1,1,1,1,1,2,2,2,2,4,4,4,4,2,1,2,2,1,1,1,1,1
1,1,1,1,1,2,2,4,4,4,4,4,4,4,2,1,1,1,1,1,2,2
1,1,1,1,1,2,3,4,4,4,4,4,4,4,2,2,1,1,1,1,2,1
1,2,1,1,1,2,4,4,4,4,4,4,4,4,4,2,2,1,1,1,1,1
1,2,1,1,2,3,4,4,4,4,4,4,4,4,4,3,2,1,1,1,1,1
1,1,1,1,2,2,3,4,4,4,4,4,4,4,4,3,2,1,1,1,1,1
1,1,1,1,1,2,2,4,4,4,4,4,4,4,4,2,2,1,1,1,1,1
1,1,1,1,1,1,2,3,4,4,4,4,4,4,2,2,1,1,1,1,2,2
1,1,1,1,1,1,1,2,3,4,4,4,3,3,2,2,1,1,1,1,2,2
1,1,1,1,1,1,1,1,1,2,3,3,2,2,2,1,1,1,1,1,1,1
1,2,2,1,1,1,1,1,1,1,2,2,2,1,1,1,1,1,1,1,1,1
1,2,1,1,1,1,1,1,1,1,1,1,1,1,1,1,1,1,1,2,2,1
1,1,1,1,1,1,1,1,1,1,1,1,1,1,1,1,1,1,1,1,1,1
1,1,1,1,1,3,2,1,1,1,1,1,1,1,1,1,1,1,2,1,1,1
1,1,1,1,1,1,1,1,1,1,1,1,1,1,2,2,1,1,2,1,1,1
endlayer

layer
1,1,1,1,1,1,1,1,1,1,1,1,1,1,1,1,1,1,1,1,1,1
1,1,1,1,1,1,1,1,1,1,1,2,1,1,1,1,1,1,1,1,1,1
1,1,1,1,1,1,1,2,2,1,1,1,1,1,1,1,2,1,1,1,1,1
1,1,1,1,1,1,1,2,1,1,1,1,1,1,1,1,2,2,1,1,1,1
1,1,1,1,1,1,1,1,1,1,1,1,2,2,1,1,1,1,1,1,1,1
1,1,1,1,1,1,1,1,1,1,1,1,3,2,1,1,1,1,1,2,2,1
1,1,1,2,2,1,1,2,1,2,3,3,3,2,1,1,1,1,1,1,1,1
1,1,2,2,2,2,3,3,3,4,4,4,4,2,1,3,1,1,1,1,1,1
1,1,2,1,2,2,3,4,4,4,4,4,4,4,2,3,3,1,1,1,1,1
1,1,1,1,1,3,4,4,4,4,4,4,4,4,4,2,1,1,1,1,2,1
1,1,1,1,1,3,4,4,4,4,4,4,4,4,4,4,2,1,1,2,2,1
1,2,2,2,2,4,4,4,4,4,0,0,4,4,4,4,3,2,1,1,1,1
1,1,2,1,3,4,4,4,4,4,0,0,4,4,4,4,3,1,1,1,1,1
1,1,1,1,1,3,4,4,4,4,4,0,4,4,4,4,3,1,1,1,1,1
1,1,1,1,1,2,4,4,4,4,4,4,4,4,4,4,2,1,1,1,2,1
1,1,1,1,1,2,2,4,4,4,4,4,4,4,4,3,1,1,1,1,2,2
1,1,1,1,1,1,2,3,4,4,4,4,4,4,3,1,1,1,1,1,2,1
1,1,2,2,1,1,1,1,2,4,4,3,3,3,1,1,1,1,1,1,1,1
1,2,2,1,1,1,1,1,1,2,3,2,1,1,1,1,1,1,1,1,1,1
1,1,1,1,1,1,1,1,1,1,1,1,1,1,1,1,1,1,1,2,1,1
1,1,1,1,1,2,2,1,1,1,1,1,1,1,1,1,1,1,1,2,1,1
1,1,1,1,1,2,2,1,1,1,1,1,1,1,2,1,1,1,2,2,1,1
1,1,1,1,1,1,1,1,1,1,1,1,2,1,2,1,1,1,1,1,1,1
endlayer

layer
1,1,1,1,1,1,1,1,1,1,1,1,1,1,1,1,1,1,1,1,1,1
1,1,1,1,1,1,1,1,1,1,2,1,1,1,1,1,1,1,1,1,1,1
1,1,1,1,1,1,1,1,2,2,2,2,1,1,1,1,1,1,1,1,1,1
1,1,1,1,1,1,1,2,2,1,2,2,1,1,1,2,2,1,1,1,1,1
1,1,1,1,1,1,1,1,2,1,2,2,1,1,1,1,2,1,1,1,1,1
1,1,1,1,1,1,1,1,2,2,2,2,3,2,1,1,1,1,1,2,1,1
1,1,1,1,2,2,1,2,2,4,4,4,3,3,1,1,1,1,1,2,2,1
1,1,1,2,2,2,3,3,4,4,4,4,4,4,2,3,1,1,2,2,1,1
1,1,2,2,2,2,3,4,4,4,4,4,4,4,4,3,3,2,2,2,1,1
1,1,1,1,1,3,4,4,4,4,4,4,4,4,4,4,2,2,2,2,2,1
1,1,1,1,2,4,4,4,4,4,0,0,4,4,4,4,3,2,2,2,2,1
1,1,2,2,3,4,4,4,4,0,0,0,0,4,4,4,3,3,1,1,1,1
1,1,2,2,3,4,4,4,4,0,0,0,0,4,4,4,3,1,1,1,1,1
1,1,1,1,2,3,4,4,4,0,0,0,0,4,4,4,3,2,2,1,1,1
1,1,1,1,2,5,3,4,4,4,0,0,0,4,4,4,3,2,2,2,2,1
1,1,1,2,2,2,4,4,4,4,4,4,4,4,3,3,2,1,2,2,2,1
1,1,2,2,2,2,2,4,4,4,4,4,4,3,3,2,1,1,1,1,2,1
1,2,2,2,1,1,1,2,4,4,4,4,4,3,2,1,1,1,1,1,1,1
1,1,2,2,1,1,2,2,2,3,3,3,2,2,2,1,1,1,1,1,1,1
1,1,1,1,1,1,2,2,2,2,1,1,2,2,1,1,1,1,2,1,1,1
1,1,1,1,1,2,2,2,1,1,1,1,1,2,1,1,1,1,2,2,1,1
1,1,1,1,1,1,2,1,1,1,1,1,1,2,2,1,1,1,2,1,1,1
1,1,1,1,1,1,1,1,1,1,1,2,2,2,1,1,1,1,1,1,1,1
endlayer

layer
1,1,1,1,1,1,1,1,1,1,1,1,1,1,1,1,1,1,1,1,1,1
1,1,1,1,1,1,1,1,1,1,1,1,1,1,1,1,1,1,1,1,1,1
1,1,1,1,1,1,1,1,1,2,2,1,1,1,1,1,1,1,1,1,1,1
1,1,1,1,1,1,1,1,2,2,2,2,1,1,1,1,1,1,1,1,1,1
1,1,1,1,1,1,1,1,2,2,2,2,1,1,1,2,2,1,1,1,1,1
1,1,1,1,1,1,1,2,3,3,3,3,3,3,1,1,1,1,1,1,1,1
1,1,1,1,2,2,2,3,3,4,3,3,3,3,2,2,1,1,2,1,1,1
1,1,1,1,2,2,3,3,4,4,3,3,3,3,3,3,2,2,2,2,1,1
1,1,1,2,3,3,3,4,4,6,6,6,6,3,4,3,3,3,2,2,1,1
1,1,2,2,2,3,4,4,6,6,0,0,0,6,6,4,3,3,2,2,1,1
1,1,2,2,2,4,4,6,6,0,0,0,0,0,6,4,3,3,2,2,2,1
1,1,2,2,3,4,4,6,0,0,0,0,0,0,6,4,3,3,2,1,1,1
1,1,1,2,3,4,4,6,0,0,0,0,0,0,6,4,3,2,2,1,1,1
1,1,1,1,2,3,3,6,0,0,0,0,0,0,6,3,3,2,2,2,2,1
1,1,1,2,3,0,3,3,6,0,0,0,0,0,6,3,3,2,2,3,3,1
1,1,1,2,2,0,3,3,3,6,0,0,0,6,3,3,2,2,2,2,2,1
1,1,2,2,2,3,3,3,3,3,6,6,6,3,3,3,2,1,1,2,1,1
1,1,1,2,2,2,2,3,3,3,4,3,3,3,3,2,1,1,1,1,1,1
1,1,1,1,1,1,2,3,3,3,3,3,3,3,3,2,1,1,1,1,1,1
1,1,1,1,1,2,2,2,2,2,2,2,3,3,2,1,1,2,2,1,1,1
1,1,1,1,1,1,2,2,1,1,1,2,2,2,2,1,1,1,2,1,1,1
1,1,1,1,1,1,1,1,1,1,1,1,2,2,2,1,1,1,1,1,1,1
1,1,1,1,1,1,1,1,1,1,1,1,1,1,1,1,1,1,1,1,1,1
endlayer

layer
1,1,1,1,1,1,1,1,1,1,1,1,1,1,1,1,1,1,1,1,1,1
1,1,1,1,1,1,1,1,1,1,1,1,1,1,1,1,1,1,1,1,1,1
1,1,1,1,1,1,1,1,1,1,1,1,1,1,1,1,1,1,1,1,1,1
1,1,1,1,1,1,1,1,1,2,2,2,1,1,1,1,1,1,1,1,1,1
1,1,1,1,1,1,1,1,2,3,3,2,2,1,2,1,1,1,1,1,1,1
1,1,1,1,1,1,2,3,3,3,3,3,3,3,2,2,2,1,1,1,1,1
1,1,1,1,1,2,3,2,3,3,3,3,3,3,3,3,2,2,1,1,1,1
1,1,1,1,2,2,2,3,3,3,3,3,3,3,3,3,3,2,2,1,1,1
1,1,1,1,2,2,3,3,3,3,0,0,0,3,3,3,3,3,2,1,1,1
1,1,1,2,2,3,3,3,0,0,0,0,0,0,0,3,3,3,2,2,1,1
1,1,2,2,3,3,3,3,0,0,0,0,0,0,0,3,3,3,3,2,1,1
1,1,1,2,3,3,3,0,0,0,0,0,0,0,0,3,3,3,3,1,1,1
1,1,1,2,3,3,3,0,0,0,0,0,0,0,0,3,3,3,3,2,1,1
1,1,1,2,3,3,3,0,0,0,0,0,0,0,0,3,3,3,3,2,1,1
1,1,1,2,2,0,3,3,0,0,0,0,0,0,3,3,3,3,3,2,2,1
1,1,1,2,2,0,0,3,3,0,0,0,0,0,3,3,3,3,3,2,1,1
1,1,1,2,2,3,3,3,3,3,3,0,0,3,3,3,3,2,2,1,1,1
1,1,1,1,2,3,3,3,3,3,3,3,3,3,3,3,2,1,1,1,1,1
1,1,1,1,1,2,2,3,3,3,3,3,3,3,3,3,2,2,1,1,1,1
1,1,1,1,1,1,2,2,2,3,3,3,3,3,3,2,2,2,2,1,1,1
1,1,1,1,1,1,1,2,1,1,2,2,2,2,2,1,2,2,1,1,1,1
1,1,1,1,1,1,1,1,1,1,1,1,2,1,1,1,1,1,1,1,1,1
1,1,1,1,1,1,1,1,1,1,1,1,1,1,1,1,1,1,1,1,1,1
endlayer

layer
1,1,1,1,1,1,1,1,1,1,1,1,1,1,1,1,1,1,1,1,1,1
1,1,1,1,1,1,1,1,1,1,1,1,1,1,1,1,1,1,1,1,1,1
1,1,1,1,1,1,1,1,1,1,1,1,1,1,1,1,1,1,1,1,1,1
1,1,1,1,1,1,1,1,1,1,2,1,1,1,1,1,1,1,1,1,1,1
1,1,1,1,1,1,1,1,1,2,2,2,2,2,2,1,1,1,1,1,1,1
1,1,1,1,1,1,2,2,2,3,3,3,3,3,2,2,1,1,1,1,1,1
1,1,1,1,1,2,2,3,3,3,3,3,3,3,3,3,2,2,1,1,1,1
1,1,1,1,1,3,3,3,3,3,3,0,3,3,3,3,3,2,1,1,1,1
1,1,1,1,2,3,3,3,3,0,0,0,0,0,3,3,3,2,2,1,1,1
1,1,1,1,3,3,3,3,0,0,0,0,0,0,0,3,3,3,2,1,1,1
1,1,1,1,3,3,3,0,0,0,0,0,0,0,0,0,3,3,2,1,1,1
1,1,1,2,3,3,0,0,0,0,0,0,0,0,0,0,3,3,2,1,1,1
1,1,1,2,3,3,0,0,0,0,0,0,0,0,0,0,3,3,2,1,1,1
1,1,1,2,3,3,3,0,0,0,0,0,0,0,0,3,3,3,2,2,1,1
1,1,1,2,3,3,3,0,0,0,0,0,0,0,0,3,3,3,2,2,1,1
1,1,1,2,3,0,0,0,3,0,0,0,0,0,3,3,3,3,2,1,1,1
1,1,1,1,2,3,3,3,3,3,0,0,0,0,3,3,3,2,2,1,1,1
1,1,1,1,2,2,3,3,3,3,3,0,0,3,3,3,2,2,1,1,1,1
1,1,1,1,1,1,2,2,3,3,3,0,3,3,2,2,2,2,2,1,1,1
1,1,1,1,1,1,2,2,2,2,2,2,2,2,2,2,2,2,1,1,1,1
1,1,1,1,1,1,1,1,1,1,1,1,2,2,1,1,1,1,1,1,1,1
1,1,1,1,1,1,1,1,1,1,1,1,1,1,1,1,1,1,1,1,1,1
1,1,1,1,1,1,1,1,1,1,1,1,1,1,1,1,1,1,1,1,1,1
endlayer

layer
1,1,1,1,1,1,1,1,1,1,1,1,1,1,1,1,1,1,1,1,1,1
1,1,1,1,1,1,1,1,1,1,1,1,1,1,1,1,1,1,1,1,1,1
1,1,1,1,1,1,1,1,1,1,1,1,1,1,1,1,1,1,1,1,1,1
1,1,1,1,1,1,1,1,1,1,1,1,1,1,1,1,1,1,1,1,1,1
1,1,1,1,1,1,1,1,1,2,2,2,2,1,1,1,1,1,1,1,1,1
1,1,1,1,1,1,1,1,2,7,3,3,3,2,2,0,1,1,1,1,1,1
1,1,1,1,1,1,2,3,3,3,7,7,3,7,3,3,2,1,1,1,1,1
1,1,1,1,1,2,3,3,3,3,0,0,0,0,7,3,3,2,1,1,1,1
1,1,1,1,0,3,3,3,0,0,0,0,0,0,7,3,3,2,0,1,1,1
1,1,1,1,2,3,3,0,0,0,0,0,0,0,0,3,3,3,0,1,1,1
1,1,1,1,3,3,0,0,0,0,0,0,0,0,0,0,3,3,0,1,1,1
1,1,1,1,3,0,0,0,0,0,0,0,0,0,0,0,0,7,0,1,1,1
1,1,1,1,7,0,0,0,0,0,0,0,0,0,0,0,3,3,2,1,1,1
1,1,1,1,7,7,0,0,0,0,0,0,0,0,0,7,3,3,2,1,1,1
1,1,1,1,2,3,7,0,0,0,0,0,0,0,0,3,3,3,2,1,1,1
1,1,1,1,2,3,0,0,0,0,0,0,0,0,0,3,3,3,2,1,1,1
1,1,1,1,2,3,3,3,7,0,0,0,0,0,3,3,3,2,0,1,1,1
1,1,1,1,0,2,7,3,3,7,0,0,0,7,3,3,2,2,1,1,1,1
1,1,1,1,1,1,2,2,3,3,3,0,3,3,2,2,2,1,1,1,1,1
1,1,1,1,1,1,1,2,2,2,2,0,0,2,2,1,1,1,1,1,1,1
1,1,1,1,1,1,1,1,1,1,1,1,1,1,1,1,1,1,1,1,1,1
1,1,1,1,1,1,1,1,1,1,1,1,1,1,1,1,1,1,1,1,1,1
1,1,1,1,1,1,1,1,1,1,1,1,1,1,1,1,1,1,1,1,1,1
endlayer

layer
1,1,1,1,1,1,1,1,1,1,1,1,1,1,1,1,1,1,1,1,1,1
1,1,1,1,1,1,1,1,1,1,1,1,1,1,1,1,1,1,1,1,1,1
1,1,1,1,1,1,1,1,1,1,1,1,1,1,1,1,1,1,1,1,1,1
1,1,1,1,1,1,1,1,1,1,1,1,1,1,1,1,1,1,1,1,1,1
1,1,1,1,1,1,1,1,1,1,2,2,1,1,1,1,1,1,1,1,1,1
1,1,1,1,1,1,1,0,0,7,3,3,3,0,0,0,1,1,1,1,1,1
1,1,1,1,1,1,0,2,7,7,0,7,7,0,7,3,2,1,1,1,1,1
1,1,1,1,1,0,3,3,3,0,0,0,0,0,7,3,3,0,1,1,1,1
1,1,1,1,0,3,3,3,0,0,0,0,0,0,0,7,3,2,0,1,1,1
1,1,1,1,2,3,0,0,0,0,0,0,0,0,0,7,3,7,0,1,1,1
1,1,1,1,7,7,0,0,0,0,0,0,0,0,0,0,7,7,0,1,1,1
1,1,1,1,7,0,0,0,0,0,0,0,0,0,0,0,0,0,0,1,1,1
1,1,1,1,0,0,0,0,0,0,0,0,0,0,0,0,0,7,0,1,1,1
1,1,1,1,0,0,0,0,0,0,0,0,0,0,0,7,7,7,2,1,1,1
1,1,1,1,7,7,7,0,0,0,0,0,0,0,0,0,3,3,2,1,1,1
1,1,1,1,2,3,7,0,0,0,0,0,0,0,0,7,3,3,2,1,1,1
1,1,1,1,2,7,3,3,0,0,0,0,0,0,7,7,3,2,0,1,1,1
1,1,1,1,1,8,7,3,3,7,0,0,0,0,3,7,8,0,1,1,1,1
1,1,1,1,1,1,1,2,3,3,7,0,3,7,7,8,0,0,1,1,1,1
1,1,1,1,1,1,1,1,2,2,8,0,0,0,0,0,1,1,1,1,1,1
1,1,1,1,1,1,1,1,1,1,1,1,1,1,1,1,1,1,1,1,1,1
1,1,1,1,1,1,1,1,1,1,1,1,1,1,1,1,1,1,1,1,1,1
1,1,1,1,1,1,1,1,1,1,1,1,1,1,1,1,1,1,1,1,1,1
endlayer

layer
1,1,1,1,1,1,1,1,1,1,1,1,1,1,1,1,1,1,1,1,1,1
1,1,1,1,1,1,1,1,1,1,1,1,1,1,1,1,1,1,1,1,1,1
1,1,1,1,1,1,1,1,1,1,1,1,1,1,1,1,1,1,1,1,1,1
1,1,1,1,1,1,1,1,1,1,1,1,1,1,1,1,1,1,1,1,1,1
1,1,1,1,1,1,1,1,1,1,1,8,1,1,1,1,1,1,1,1,1,1
1,1,1,1,1,1,1,0,0,0,7,3,7,0,0,0,1,1,1,1,1,1
1,1,1,1,1,1,0,7,7,0,0,7,0,0,7,7,0,1,1,1,1,1
1,1,1,1,1,0,3,3,7,0,0,0,0,0,7,3,8,0,1,1,1,1
1,1,1,1,0,7,3,0,0,0,0,0,0,0,0,7,3,0,0,1,1,1
1,1,1,1,7,7,0,0,0,0,0,0,0,0,0,7,7,7,0,1,1,1
1,1,1,1,7,7,0,0,0,0,0,0,0,0,0,0,7,0,0,1,1,1
1,1,1,1,0,0,0,0,0,0,0,0,0,0,0,0,0,0,0,1,1,1
1,1,1,1,0,0,0,0,0,0,0,0,0,0,0,0,0,7,0,1,1,1
1,1,1,1,0,0,0,0,0,0,0,0,0,0,0,0,7,7,0,1,1,1
1,1,1,1,0,7,0,0,0,0,0,0,0,0,0,0,7,3,3,1,1,1
1,1,1,1,7,7,7,0,0,0,0,0,0,0,0,7,7,7,0,1,1,1
1,1,1,1,1,7,7,7,0,0,0,0,0,0,0,7,7,2,0,1,1,1
1,1,1,1,1,0,7,7,7,0,0,0,0,0,7,7,0,0,0,1,1,1
1,1,1,1,1,1,0,2,7,7,7,7,7,7,7,0,0,0,1,1,1,1
1,1,1,1,1,1,1,1,0,8,0,0,0,0,0,0,0,1,1,1,1,1
1,1,1,1,1,1,1,1,1,1,1,1,1,1,1,1,1,1,1,1,1,1
1,1,1,1,1,1,1,1,1,1,1,1,1,1,1,1,1,1,1,1,1,1
1,1,1,1,1,1,1,1,1,1,1,1,1,1,1,1,1,1,1,1,1,1
endlayer

layer
1,1,1,1,1,1,1,1,1,1,1,1,1,1,1,1,1,1,1,1,1,1
1,1,1,1,1,1,1,1,1,1,1,1,1,1,1,1,1,1,1,1,1,1
1,1,1,1,1,1,1,1,1,1,1,1,1,1,1,1,1,1,1,1,1,1
1,1,1,1,1,1,1,1,1,1,1,1,1,1,1,1,1,1,1,1,1,1
1,1,1,1,1,1,1,1,1,1,0,1,1,1,1,1,1,1,1,1,1,1
1,1,1,1,1,1,0,0,0,0,7,7,7,0,0,0,0,1,1,1,1,1
1,1,1,1,1,0,0,0,7,0,0,0,0,0,7,7,0,0,1,1,1,1
1,1,1,1,1,0,7,7,0,0,0,0,0,0,7,7,0,0,1,1,1,1
1,1,1,1,0,7,7,0,0,0,0,0,0,0,0,7,7,0,0,1,1,1
1,1,1,1,7,7,0,0,0,0,0,0,0,0,0,0,7,0,0,1,1,1
1,1,1,1,0,0,0,0,0,0,0,0,0,0,0,0,7,0,0,1,1,1
1,1,1,1,0,0,0,0,0,0,0,0,0,0,0,0,0,0,0,1,1,1
1,1,1,1,0,0,0,0,0,0,0,0,0,0,0,0,0,0,0,1,1,1
1,1,1,1,0,0,0,0,0,0,0,0,0,0,0,0,0,7,0,1,1,1
1,1,1,1,0,0,0,0,0,0,0,0,0,0,0,0,7,7,7,1,1,1
1,1,1,1,0,7,0,0,0,0,0,0,0,0,0,7,7,7,0,1,1,1
1,1,1,1,0,0,7,7,0,0,0,0,0,0,0,7,7,0,0,1,1,1
1,1,1,1,1,0,0,7,7,0,0,0,0,0,7,7,0,0,0,1,1,1
1,1,1,1,1,1,0,0,7,7,7,7,7,0,0,0,0,0,0,1,1,1
1,1,1,1,1,1,1,1,0,0,0,0,0,0,0,0,0,1,1,1,1,1
1,1,1,1,1,1,1,1,1,1,1,0,1,1,1,1,1,1,1,1,1,1
1,1,1,1,1,1,1,1,1,1,1,1,1,1,1,1,1,1,1,1,1,1
1,1,1,1,1,1,1,1,1,1,1,1,1,1,1,1,1,1,1,1,1,1
endlayer

layer
1,1,1,1,1,1,1,1,1,1,1,1,1,1,1,1,1,1,1,1,1,1
1,1,1,1,1,1,1,1,1,1,1,1,1,1,1,1,1,1,1,1,1,1
1,1,1,1,1,1,1,1,1,1,1,1,1,1,1,1,1,1,1,1,1,1
1,1,1,1,1,1,1,1,1,1,1,1,1,1,1,1,1,1,1,1,1,1
1,1,1,1,1,1,1,1,1,1,0,0,1,1,1,1,1,1,1,1,1,1
1,1,1,1,1,1,0,0,0,0,7,7,7,7,0,0,0,1,1,1,1,1
1,1,1,1,1,0,0,0,0,0,0,0,0,7,7,0,0,0,1,1,1,1
1,1,1,1,0,8,7,7,0,0,0,0,0,0,7,7,0,0,0,1,1,1
1,1,1,1,0,7,7,0,0,0,0,0,0,0,0,7,7,0,0,1,1,1
1,1,1,1,0,7,0,0,0,0,0,0,0,0,0,0,7,0,0,1,1,1
1,1,1,1,0,0,0,0,0,0,0,0,0,0,0,0,7,0,0,1,1,1
1,1,1,1,0,0,0,0,0,0,0,0,0,0,0,0,0,0,0,1,1,1
1,1,1,0,0,0,0,0,0,0,0,0,0,0,0,0,0,0,0,0,1,1
1,1,1,1,0,0,0,0,0,0,0,0,0,0,0,0,0,7,0,1,1,1
1,1,1,1,0,0,0,0,0,0,0,0,0,0,0,0,0,7,0,1,1,1
1,1,1,1,0,7,0,0,0,0,0,0,0,0,0,7,7,7,0,1,1,1
1,1,1,1,0,0,0,7,0,0,0,0,0,0,0,7,7,0,0,1,1,1
1,1,1,1,1,0,0,7,7,0,0,0,0,0,7,0,0,0,0,1,1,1
1,1,1,1,1,1,0,0,7,7,7,7,0,0,0,0,0,0,0,1,1,1
1,1,1,1,1,1,1,0,0,0,0,0,0,0,0,0,0,0,1,1,1,1
1,1,1,1,1,1,1,1,1,1,1,0,0,1,1,1,1,1,1,1,1,1
1,1,1,1,1,1,1,1,1,1,1,1,1,1,1,1,1,1,1,1,1,1
1,1,1,1,1,1,1,1,1,1,1,1,1,1,1,1,1,1,1,1,1,1
endlayer

layer
1,1,1,1,1,1,1,1,1,1,1,1,1,1,1,1,1,1,1,1,1,1
1,1,1,1,1,1,1,1,1,1,1,1,1,1,1,1,1,1,1,1,1,1
1,1,1,1,1,1,1,1,1,1,1,1,1,1,1,1,1,1,1,1,1,1
1,1,1,1,1,1,1,1,1,1,1,1,1,1,1,1,1,1,1,1,1,1
1,1,1,1,1,1,1,1,1,0,0,0,1,1,1,1,1,1,1,1,1,1
1,1,1,1,1,1,0,0,0,0,0,7,7,7,0,0,0,1,1,1,1,1
1,1,1,1,0,0,0,0,0,0,0,0,7,7,7,0,0,0,1,1,1,1
1,1,1,1,0,7,7,0,0,0,0,0,0,0,7,0,0,0,0,1,1,1
1,1,1,1,0,7,7,0,0,0,0,0,0,0,0,7,7,0,0,1,1,1
1,1,1,1,0,0,0,0,0,0,0,0,0,0,0,0,7,0,0,1,1,1
1,1,1,0,0,0,0,0,0,0,0,0,0,0,0,0,0,0,0,1,1,1
1,1,1,1,0,0,0,0,0,0,0,0,0,0,0,0,0,0,0,1,1,1
1,1,1,0,0,0,0,0,0,0,0,0,0,0,0,0,0,0,0,0,1,1
1,1,1,1,0,0,0,0,0,0,0,0,0,0,0,0,0,0,0,0,1,1
1,1,1,1,0,0,0,0,0,0,0,0,0,0,0,0,0,7,0,1,1,1
1,1,1,1,0,0,0,0,0,0,0,0,0,0,0,0,7,7,0,1,1,1
1,1,1,1,0,0,0,0,7,0,0,0,0,0,0,7,0,0,0,1,1,1
1,1,1,1,0,0,0,7,7,7,0,0,0,0,0,0,0,0,0,1,1,1
1,1,1,1,1,0,0,0,7,7,7,0,0,0,0,0,0,0,0,1,1,1
1,1,1,1,1,1,1,0,0,0,0,0,0,0,0,0,0,0,1,1,1,1
1,1,1,1,1,1,1,1,1,1,0,0,0,1,0,1,1,1,1,1,1,1
1,1,1,1,1,1,1,1,1,1,1,1,1,1,1,1,1,1,1,1,1,1
1,1,1,1,1,1,1,1,1,1,1,1,1,1,1,1,1,1,1,1,1,1
endlayer

layer
1,1,1,1,1,1,1,1,1,1,1,1,1,1,1,1,1,1,1,1,1,1
1,1,1,1,1,1,1,1,1,1,1,1,1,1,1,1,1,1,1,1,1,1
1,1,1,1,1,1,1,1,1,1,1,1,1,1,1,1,1,1,1,1,1,1
1,1,1,1,1,1,1,1,1,1,0,1,1,1,1,1,1,1,1,1,1,1
1,1,1,1,1,1,1,0,1,0,0,0,0,1,1,1,1,1,1,1,1,1
1,1,1,1,1,0,0,0,0,0,0,0,7,7,0,0,0,0,1,1,1,1
1,1,1,1,0,0,0,0,0,0,0,7,7,7,0,0,0,0,1,1,1,1
1,1,1,1,0,7,7,0,0,0,0,0,0,0,7,0,0,0,0,1,1,1
1,1,1,1,0,0,7,0,0,0,0,0,0,0,0,7,7,0,0,1,1,1
1,1,1,1,0,0,0,0,0,0,0,0,0,0,0,0,0,0,0,0,1,1
1,1,1,0,0,0,0,0,0,0,0,0,0,0,0,0,0,0,0,1,1,1
1,1,1,0,0,0,0,0,0,0,0,0,0,0,0,0,0,0,0,0,1,1
1,1,1,0,0,0,0,0,0,0,0,0,0,0,0,0,0,0,0,0,1,1
1,1,1,0,0,0,0,0,0,0,0,0,0,0,0,0,0,0,0,0,1,1
1,1,1,1,0,0,0,0,0,0,0,0,0,0,0,0,0,7,0,0,1,1
1,1,1,0,0,0,0,0,0,0,0,0,0,0,0,0,0,7,0,1,1,1
1,1,1,1,0,0,0,0,7,0,0,0,0,0,0,7,0,0,0,1,1,1
1,1,1,1,0,0,0,0,7,7,0,0,0,0,0,0,0,0,0,1,1,1
1,1,1,1,1,0,0,0,7,7,0,0,0,0,0,0,0,0,0,1,1,1
1,1,1,1,1,1,0,0,0,0,0,0,0,0,0,0,0,0,1,1,1,1
1,1,1,1,1,1,1,1,1,1,0,0,0,0,0,1,1,1,1,1,1,1
1,1,1,1,1,1,1,1,1,1,1,1,1,1,1,1,1,1,1,1,1,1
1,1,1,1,1,1,1,1,1,1,1,1,1,1,1,1,1,1,1,1,1,1
endlayer

layer
1,1,1,1,1,1,1,1,1,1,1,1,1,1,1,1,1,1,1,1,1,1
1,1,1,1,1,1,1,1,1,1,1,1,1,1,1,1,1,1,1,1,1,1
1,1,1,1,1,1,1,1,1,1,1,1,1,1,1,1,1,1,1,1,1,1
1,1,1,1,1,1,1,1,1,1,0,0,1,1,1,1,1,1,1,1,1,1
1,1,1,1,1,1,1,0,0,0,0,0,0,0,1,0,1,1,1,1,1,1
1,1,1,1,1,0,0,0,0,0,0,0,0,7,0,0,0,0,1,1,1,1
1,1,1,1,0,0,0,0,0,0,0,7,7,0,0,0,0,0,1,1,1,1
1,1,1,1,0,0,7,0,0,0,0,0,0,0,0,0,0,0,0,0,1,1
1,1,1,0,0,0,7,0,0,0,0,0,0,0,0,7,0,0,0,1,1,1
1,1,1,1,0,0,0,0,0,0,0,0,0,0,0,0,0,0,0,0,1,1
1,1,1,0,0,0,0,0,0,0,0,0,0,0,0,0,0,0,0,0,1,1
1,1,1,0,0,0,0,0,0,0,0,0,0,0,0,0,0,0,0,0,1,1
1,1,0,0,0,0,0,0,0,0,0,0,0,0,0,0,0,0,0,0,0,1
1,1,1,0,0,0,0,0,0,0,0,0,0,0,0,0,0,0,0,0,1,1
1,1,1,0,0,0,0,0,0,0,0,0,0,0,0,0,0,7,0,0,1,1
1,1,1,0,0,0,0,0,0,0,0,0,0,0,0,0,0,0,0,1,1,1
1,1,1,1,0,0,0,0,0,0,0,0,0,0,0,0,0,0,0,0,1,1
1,1,1,1,0,0,0,0,7,7,0,0,0,0,0,0,0,0,0,1,1,1
1,1,1,1,0,0,0,0,7,7,0,0,0,0,0,0,0,0,0,1,1,1
1,1,1,1,1,1,0,0,0,0,0,0,0,0,0,0,0,0,1,1,1,1
1,1,1,1,1,1,1,1,0,1,0,0,0,0,0,1,0,1,1,1,1,1
1,1,1,1,1,1,1,1,1,1,1,0,1,0,1,1,1,1,1,1,1,1
1,1,1,1,1,1,1,1,1,1,1,1,1,1,1,1,1,1,1,1,1,1
endlayer

layer
1,1,1,1,1,1,1,1,1,1,1,1,1,1,1,1,1,1,1,1,1,1
1,1,1,1,1,1,1,1,1,1,1,1,1,1,1,1,1,1,1,1,1,1
1,1,1,1,1,1,1,1,1,1,1,1,1,1,1,1,1,1,1,1,1,1
1,1,1,1,1,1,1,0,1,0,0,0,0,1,1,1,1,1,1,1,1,1
1,1,1,1,1,1,0,0,0,0,0,0,0,0,1,0,1,1,1,1,1,1
1,1,1,1,0,0,0,0,0,0,0,0,0,7,0,0,0,0,1,1,1,1
1,1,1,0,0,0,0,0,0,0,0,7,0,0,0,0,0,0,0,1,1,1
1,1,1,1,0,0,7,0,0,0,0,0,0,0,0,0,0,0,0,0,1,1
1,1,1,0,0,0,0,0,0,0,0,0,0,0,0,0,0,0,0,1,1,1
1,1,1,0,0,0,0,0,0,0,0,0,0,0,0,0,0,0,0,0,0,1
1,1,0,0,0,0,0,0,0,0,0,0,0,0,0,0,0,0,0,0,1,1
1,1,1,0,0,0,0,0,0,0,0,0,0,0,0,0,0,0,0,0,0,1
1,1,0,0,0,0,0,0,0,0,0,0,0,0,0,0,0,0,0,0,0,1
1,1,1,0,0,0,0,0,0,0,0,0,0,0,0,0,0,0,0,0,0,1
1,1,0,0,0,0,0,0,0,0,0,0,0,0,0,0,0,0,0,0,1,1
1,1,1,0,0,0,0,0,0,0,0,0,0,0,0,0,0,0,0,0,1,1
1,1,1,1,0,0,0,0,0,0,0,0,0,0,0,0,0,0,0,0,1,1
1,1,1,0,0,0,0,0,0,7,0,0,0,0,0,0,0,0,0,1,1,1
1,1,1,1,0,0,0,0,7,7,0,0,0,0,0,0,0,0,0,0,1,1
1,1,1,1,1,0,0,0,0,0,0,0,0,0,0,0,0,0,0,1,1,1
1,1,1,1,1,1,0,1,0,0,0,0,0,0,0,0,0,1,1,1,1,1
1,1,1,1,1,1,1,1,1,1,1,0,0,0,0,1,1,1,1,1,1,1
1,1,1,1,1,1,1,1,1,1,1,1,1,1,1,1,1,1,1,1,1,1
endlayer

layer
1,1,1,1,1,1,1,1,1,1,1,1,1,1,1,1,1,1,1,1,1,1
1,1,1,1,1,1,1,1,1,1,1,1,1,1,1,1,1,1,1,1,1,1
1,1,1,1,1,1,1,1,1,1,1,0,1,1,1,1,1,1,1,1,1,1
1,1,1,1,1,1,1,0,0,0,0,0,0,0,1,1,1,1,1,1,1,1
1,1,1,1,1,0,0,0,0,0,0,0,0,0,0,0,1,0,1,1,1,1
1,1,1,1,0,0,0,0,0,0,0,0,0,0,0,0,0,0,1,1,1,1
1,1,1,0,0,0,0,0,0,0,0,7,0,0,0,0,0,0,0,0,1,1
1,1,1,0,0,0,0,0,0,0,0,0,0,0,0,0,0,0,0,0,1,1
1,1,1,0,0,0,0,0,0,0,0,0,0,0,0,0,0,0,0,0,1,1
1,1,1,0,0,0,0,0,0,0,0,0,0,0,0,0,0,0,0,0,0,1
1,1,0,0,0,0,0,0,0,0,0,0,0,0,0,0,0,0,0,0,0,1
1,1,0,0,0,0,0,0,0,0,0,0,0,0,0,0,0,0,0,0,0,1
1,0,0,0,0,0,0,0,0,0,0,0,0,0,0,0,0,0,0,0,0,1
1,1,0,0,0,0,0,0,0,0,0,0,0,0,0,0,0,0,0,0,0,0
1,1,0,0,0,0,0,0,0,0,0,0,0,0,0,0,0,0,0,0,0,1
1,1,0,0,0,0,0,0,0,0,0,0,0,0,0,0,0,0,0,0,0,1
1,1,1,0,0,0,0,0,0,0,0,0,0,0,0,0,0,0,0,0,1,1
1,1,1,0,0,0,0,0,0,7,0,0,0,0,0,0,0,0,0,0,1,1
1,1,1,1,0,0,0,0,0,7,0,0,0,0,0,0,0,0,0,0,1,1
1,1,1,1,0,0,0,0,0,0,0,0,0,0,0,0,0,0,0,1,1,1
1,1,1,1,1,1,0,0,0,0,0,0,0,0,0,0,0,0,0,1,1,1
1,1,1,1,1,1,1,1,0,1,0,0,0,0,0,0,1,1,1,1,1,1
1,1,1,1,1,1,1,1,1,1,1,1,1,0,1,1,1,1,1,1,1,1
endlayer

layer
1,1,1,1,1,1,1,1,1,1,1,1,1,1,1,1,1,1,1,1,1,1
1,1,1,1,1,1,1,1,1,1,1,1,1,1,1,1,1,1,1,1,1,1
1,1,1,1,1,1,1,1,1,0,0,0,0,1,1,1,1,1,1,1,1,1
1,1,1,1,1,1,0,0,0,0,0,0,0,0,0,0,1,1,1,1,1,1
1,1,1,1,0,0,0,0,0,0,0,0,0,0,0,0,0,0,1,1,1,1
1,1,1,0,0,0,0,0,0,0,0,0,0,0,0,0,0,0,0,1,1,1
1,1,1,0,0,0,0,0,0,0,0,0,0,0,0,0,0,0,0,0,1,1
1,1,1,0,0,0,0,0,0,0,0,0,0,0,0,0,0,0,0,0,0,1
1,1,1,0,0,0,0,0,0,0,0,0,0,0,0,0,0,0,0,0,0,1
1,1,0,0,0,0,0,0,0,0,0,0,0,0,0,0,0,0,0,0,0,1
1,1,0,0,0,0,0,0,0,0,0,0,0,0,0,0,0,0,0,0,0,1
1,0,0,0,0,0,0,0,0,0,0,0,0,0,0,0,0,0,0,0,0,0
1,0,0,0,0,0,0,0,0,0,0,0,0,0,0,0,0,0,0,0,0,0
1,0,0,0,0,0,0,0,0,0,0,0,0,0,0,0,0,0,0,0,0,0
1,0,0,0,0,0,0,0,0,0,0,0,0,0,0,0,0,0,0,0,0,0
1,1,0,0,0,0,0,0,0,0,0,0,0,0,0,0,0,0,0,0,0,1
1,1,0,0,0,0,0,0,0,0,0,0,0,0,0,0,0,0,0,0,0,1
1,1,0,0,0,0,0,0,0,7,0,0,0,0,0,0,0,0,0,0,0,1
1,1,1,0,0,0,0,0,0,0,0,0,0,0,0,0,0,0,0,0,1,1
1,1,1,0,0,0,0,0,0,0,0,0,0,0,0,0,0,0,0,0,1,1
1,1,1,1,1,0,0,0,0,0,0,0,0,0,0,0,0,0,0,1,1,1
1,1,1,1,1,1,1,0,0,0,0,0,0,0,0,0,0,0,1,1,1,1
1,1,1,1,1,1,1,1,1,1,0,0,0,0,0,1,1,1,1,1,1,1
endlayer

