
# Created by Ruins mod version 16.7 Ingame Parser
# authoring Player: lafuller

weight=1
embed_into_distance=5
acceptable_target_blocks=
unacceptable_target_blocks=flowing_water,water,flowing_lava,lava,ice,bedrock,netherrack,nether_brick,nether_brick_fence,soul_sand,quartz_ore,end_stone,obsidian,iron_bars,cloud,flesh,ash_block,slime_grass,slime_congealed,slime_dirt
dimensions=19,20,21
allowable_overhang=0
max_leveling=5
leveling_buffer=-1
preserve_water=0
preserve_lava=0

rule1=0,100,preserveBlock
rule2=0,100,stonebrick-0,stonebrick-2,stonebrick-2,stonebrick-1,stonebrick-1,cobblestone
rule3=0,100,minecraft:stone-6
rule4=0,100,stonebrick-0,stonebrick-1,stonebrick-2,stonebrick-2,stone-5,stone-5,stone-6,stone-6
rule5=0,100,stonebrick-0,stonebrick-1,stonebrick-2
rule6=0,100,minecraft:stone_brick_stairs-2
rule7=0,100,stonebrick-0,stonebrick-0,stonebrick-0,stonebrick-1,stonebrick-2,stonebrick-2,stone-5,stone-6,cobblestone,gravel
rule8=0,100,minecraft:stone_brick_stairs-3
rule9=0,100,minecraft:log-0
rule10=0,100,minecraft:wooden_slab-9
rule11=0,100,bookshelf,hay_block,ChestGenHook:chests/spawn_bonus_chest:5-4,ChestGenHook:chests/village_blacksmith:5-4,ChestGenHook:chests/simple_dungeon:5-4,ChestGenHook:chests/abandoned_mineshaft:5-4,ChestGenHook:chests/stronghold_library:5-4,ChestGenHook:chests/stronghold_corridor:5-4,ChestGenHook:chests/stronghold_crossing:5-3,ChestGenHook:chests/igloo_chest:5-4
rule12=0,100,minecraft:stone_brick_stairs-0
rule13=0,100,minecraft:stone-5
rule14=0,100,minecraft:stone_brick_stairs-6
rule15=0,100,minecraft:cobblestone_wall-0
rule16=0,100,minecraft:sandstone-2
rule17=0,100,minecraft:stone_slab-9
rule18=0,100,minecraft:double_stone_slab-0
rule19=0,100,minecraft:stone_slab-0
rule20=0,100,minecraft:red_sandstone-2
rule21=0,100,minecraft:red_sandstone_stairs-0
rule22=0,100,minecraft:hardened_clay-0
rule23=0,100,minecraft:acacia_door-0
rule24=0,100,minecraft:red_sandstone_stairs-3
rule25=0,100,minecraft:red_sandstone_stairs-2
rule26=0,100,minecraft:spruce_fence_gate-6
rule27=0,100,minecraft:spruce_fence_gate-4
rule28=0,100,minecraft:red_sandstone_stairs-1
rule29=0,100,minecraft:spruce_fence_gate-7
rule30=0,100,minecraft:birch_stairs-6
rule31=0,100,minecraft:birch_stairs-4
rule32=0,100,minecraft:acacia_door-8
rule33=0,100,minecraft:acacia_door-9
rule34=0,100,minecraft:birch_stairs-7
rule35=0,100,minecraft:carpet-7
rule36=0,100,minecraft:wooden_slab-2
rule37=0,100,minecraft:planks-2
rule38=0,100,minecraft:birch_stairs-5
rule39=0,100,minecraft:spruce_stairs-2
rule40=0,100,minecraft:wooden_slab-13
rule41=0,100,minecraft:spruce_stairs-3
rule42=0,100,minecraft:birch_stairs-2
rule43=0,100,minecraft:birch_stairs-0
rule44=0,100,minecraft:spruce_fence_gate-3
rule45=0,100,minecraft:spruce_fence-0
rule46=0,100,minecraft:acacia_fence-0
rule47=0,100,minecraft:dark_oak_fence_gate-2
rule48=0,100,minecraft:dark_oak_fence_gate-0
rule49=0,100,minecraft:dark_oak_fence_gate-3
rule50=0,100,minecraft:log-8
rule51=0,100,minecraft:birch_stairs-3
rule52=0,100,minecraft:trapdoor-8
rule53=0,100,minecraft:dark_oak_fence-0
rule54=0,100,minecraft:trapdoor-9
rule55=0,100,minecraft:log-4
rule56=0,100,minecraft:trapdoor-0
rule57=0,100,minecraft:trapdoor-1
rule58=0,100,minecraft:trapdoor-11
rule59=0,100,minecraft:trapdoor-14
rule60=0,100,minecraft:wooden_slab-12
rule61=0,100,minecraft:acacia_stairs-7
rule62=0,100,minecraft:dark_oak_fence_gate-1
rule63=0,100,minecraft:planks-4
rule64=0,100,minecraft:wooden_slab-4
rule65=0,100,minecraft:birch_stairs-1
rule66=0,100,minecraft:trapdoor-3
rule67=0,100,minecraft:acacia_stairs-3
rule68=0,100,minecraft:acacia_stairs-6
rule69=0,100,minecraft:acacia_stairs-4
rule70=0,100,minecraft:trapdoor-12
rule71=0,100,minecraft:acacia_stairs-0
rule72=0,100,minecraft:log2-9
rule73=0,100,minecraft:trapdoor-13
rule74=0,100,CommandBlock:RUINSTRIGGER /testruin Gilly/GillyLumberStairs ~0 ~-11 ~0:@
rule75=0,100,minecraft:acacia_stairs-1
rule76=0,100,minecraft:log-5
rule77=0,100,minecraft:acacia_stairs-5
rule78=0,100,minecraft:trapdoor-15
rule79=0,100,minecraft:acacia_stairs-2
rule80=0,100,minecraft:planks-5
rule81=0,100,minecraft:dark_oak_stairs-0
rule82=0,100,minecraft:wooden_slab-5
rule83=0,100,minecraft:dark_oak_stairs-7
rule84=0,100,minecraft:double_wooden_slab-5
rule85=0,100,minecraft:dark_oak_stairs-3
rule86=0,100,minecraft:dark_oak_stairs-2
rule87=0,100,minecraft:dark_oak_stairs-4
rule88=0,100,minecraft:dark_oak_stairs-1

layer
1,1,1,1,1,1,1,2,2,2,2,2,2,1,1,1,1,1,1,1,1
1,1,1,1,1,1,2,2,2,2,2,2,2,2,1,1,1,1,1,1,1
1,1,1,1,1,2,2,2,2,2,2,2,2,2,2,1,1,1,1,1,1
1,1,1,1,2,2,2,2,2,2,2,2,2,3,2,1,1,1,1,1,1
1,1,1,1,2,2,2,3,2,2,2,2,2,2,2,2,2,1,1,1,1
1,1,1,1,2,2,2,2,2,2,2,2,2,2,2,2,3,2,1,1,1
1,1,1,2,3,2,2,2,2,2,4,2,2,2,2,2,2,2,1,1,1
1,1,1,2,2,2,2,2,2,4,4,4,4,4,2,2,2,2,2,1,1
1,1,1,2,2,2,2,4,4,4,5,5,5,4,4,2,2,2,2,1,1
1,1,1,2,2,2,4,4,5,4,5,5,5,5,4,2,2,2,2,1,1
1,1,1,2,3,2,4,5,5,5,5,5,5,5,4,2,2,3,2,1,1
1,1,1,2,2,2,4,4,5,5,5,5,5,4,4,2,2,2,2,1,1
1,1,1,2,2,2,2,4,5,5,4,4,5,4,2,2,2,2,2,1,1
1,1,1,2,2,2,2,4,4,4,4,4,4,4,2,2,2,2,1,1,1
1,1,1,2,3,2,2,2,2,2,2,2,2,2,2,2,3,1,1,1,1
1,1,1,1,2,2,2,2,2,2,3,2,2,2,3,2,2,1,1,1,1
1,1,1,1,2,3,2,2,2,2,2,2,2,2,2,1,1,1,1,1,1
1,1,1,1,1,2,2,2,2,2,2,2,2,2,1,1,1,1,1,1,1
1,1,1,1,1,1,1,1,1,1,1,1,1,1,1,1,1,1,1,1,1
1,1,1,1,1,1,1,1,1,1,1,1,1,1,1,1,1,1,1,1,1
endlayer

layer
1,1,1,1,1,1,1,8,7,7,7,7,6,1,1,1,1,1,1,1,1
1,1,1,1,1,1,8,7,7,7,7,7,7,6,1,1,1,1,1,1,1
1,1,1,1,1,8,7,7,7,7,7,7,7,7,6,1,1,1,1,1,1
1,1,1,1,8,7,7,7,7,7,7,7,7,3,7,1,1,1,1,1,1
1,1,1,1,8,7,7,3,7,7,7,7,7,7,7,7,7,1,1,1,1
1,1,1,1,7,7,7,7,9,10,10,10,9,7,7,7,3,7,1,1,1
1,1,1,7,3,7,7,7,0,0,0,0,0,0,0,9,7,7,1,1,1
1,1,1,7,7,9,0,0,0,0,0,0,0,0,0,10,7,7,7,1,1
1,1,1,7,7,10,0,0,0,0,0,0,0,0,0,10,7,7,7,1,1
1,1,1,7,7,10,0,0,0,0,0,0,0,0,0,10,7,7,7,1,1
1,1,1,7,3,10,0,0,0,0,9,0,0,0,0,10,7,3,7,1,1
1,1,1,7,7,10,0,0,0,0,0,0,0,0,0,10,7,7,7,1,1
1,1,1,7,7,10,0,0,0,0,0,0,0,0,0,10,7,7,7,1,1
1,1,1,7,7,9,0,0,0,0,0,0,0,0,0,9,7,7,1,1,1
1,1,1,7,3,7,0,0,0,0,8,7,0,0,11,7,3,1,1,1,1
1,1,1,1,7,7,9,10,10,9,3,7,7,7,3,7,7,1,1,1,1
1,1,1,1,7,3,7,7,7,7,7,7,7,7,7,1,1,1,1,1,1
1,1,1,1,1,7,7,7,7,7,7,7,7,7,1,1,1,1,1,1,1
1,1,1,1,1,1,1,1,1,1,1,1,1,1,1,1,1,1,1,1,1
1,1,1,1,1,1,1,1,1,1,1,1,1,1,1,1,1,1,1,1,1
endlayer

layer
1,1,1,1,1,1,1,1,8,12,12,6,1,1,1,1,1,1,1,1,1
1,1,1,1,1,1,1,8,7,7,7,7,6,1,1,1,1,1,1,1,1
1,1,1,1,1,1,8,7,7,7,7,7,7,6,1,1,1,1,1,1,1
1,1,1,1,1,8,7,7,7,7,7,7,7,3,7,1,1,1,1,1,1
1,1,1,1,1,8,7,3,7,7,7,7,7,7,7,7,1,1,1,1,1
1,1,1,1,7,7,7,7,9,0,0,0,9,7,7,7,13,7,1,1,1
1,1,1,1,3,7,7,7,0,0,0,0,0,0,0,9,7,7,1,1,1
1,1,1,7,7,9,0,0,0,0,0,0,0,0,0,0,7,7,7,1,1
1,1,1,7,7,0,0,0,0,0,0,0,0,0,0,0,7,7,7,1,1
1,1,1,7,7,0,0,0,0,0,0,0,0,0,0,0,7,7,7,1,1
1,1,1,7,3,0,0,0,0,0,9,0,0,0,0,0,7,3,7,1,1
1,1,1,7,7,0,0,0,0,0,0,0,0,0,0,0,7,7,7,1,1
1,1,1,7,7,0,0,0,0,0,0,0,0,0,0,0,7,7,1,1,1
1,1,1,7,7,9,0,0,0,0,0,0,0,0,0,9,7,7,1,1,1
1,1,1,1,3,7,0,0,0,0,0,8,14,0,0,7,13,1,1,1,1
1,1,1,1,7,7,9,0,0,9,3,7,7,7,3,7,1,1,1,1,1
1,1,1,1,7,13,7,7,7,7,7,7,7,7,7,1,1,1,1,1,1
1,1,1,1,1,1,7,7,7,7,7,7,7,1,1,1,1,1,1,1,1
1,1,1,1,1,1,1,1,1,1,1,1,1,1,1,1,1,1,1,1,1
1,1,1,1,1,1,1,1,1,1,1,1,1,1,1,1,1,1,1,1,1
endlayer

layer
1,1,1,1,1,1,1,1,1,1,1,1,1,1,1,1,1,1,1,1,1
1,1,1,1,1,1,1,1,8,12,12,6,1,1,1,1,1,1,1,1,1
1,1,1,1,1,1,1,8,7,7,7,7,6,1,1,1,1,1,1,1,1
1,1,1,1,1,1,8,7,7,7,7,7,7,13,1,1,1,1,1,1,1
1,1,1,1,1,1,8,3,7,7,15,7,7,7,7,7,1,1,1,1,1
1,1,1,1,1,7,7,7,9,0,0,0,9,7,15,7,3,1,1,1,1
1,1,1,1,13,7,7,7,0,0,0,0,0,0,0,9,7,7,1,1,1
1,1,1,1,7,9,0,0,0,0,0,0,0,0,0,0,7,7,1,1,1
1,1,1,7,7,0,0,0,0,0,0,0,0,0,0,0,15,7,1,1,1
1,1,1,7,15,0,0,0,0,0,0,0,0,0,0,0,7,7,7,1,1
1,1,1,7,3,0,0,0,0,0,9,0,0,0,0,0,7,3,7,1,1
1,1,1,7,15,0,0,0,0,0,0,0,0,0,0,0,15,7,1,1,1
1,1,1,7,7,0,0,0,0,0,0,0,0,0,0,0,7,7,1,1,1
1,1,1,1,7,9,0,0,0,0,0,0,0,0,0,9,7,1,1,1,1
1,1,1,1,13,7,0,0,0,0,0,0,8,14,0,7,3,1,1,1,1
1,1,1,1,7,7,9,0,0,9,3,15,7,7,3,7,1,1,1,1,1
1,1,1,1,1,3,7,7,15,7,7,7,7,7,1,1,1,1,1,1,1
1,1,1,1,1,1,1,7,7,7,7,1,1,1,1,1,1,1,1,1,1
1,1,1,1,1,1,1,1,1,1,1,1,1,1,1,1,1,1,1,1,1
1,1,1,1,1,1,1,1,1,1,1,1,1,1,1,1,1,1,1,1,1
endlayer

layer
1,1,1,1,1,1,1,1,1,1,1,1,1,1,1,1,1,1,1,1,1
1,1,1,1,1,1,1,1,1,1,1,1,1,1,1,1,1,1,1,1,1
1,1,1,1,1,1,1,1,8,12,12,6,1,1,1,1,1,1,1,1,1
1,1,1,1,1,1,1,8,7,7,7,7,7,3,1,1,1,1,1,1,1
1,1,1,1,1,1,1,13,7,7,15,7,7,7,1,1,1,1,1,1,1
1,1,1,1,1,1,7,7,9,0,0,0,9,7,15,7,13,1,1,1,1
1,1,1,1,3,7,7,7,0,0,0,0,0,0,0,9,7,1,1,1,1
1,1,1,1,7,9,0,0,0,0,0,0,0,0,0,0,7,1,1,1,1
1,1,1,1,7,0,0,0,0,0,0,0,0,0,0,0,15,1,1,1,1
1,1,1,1,15,0,0,0,0,0,0,0,0,0,0,0,7,7,1,1,1
1,1,1,1,13,0,0,0,0,0,9,0,0,0,0,0,7,3,1,1,1
1,1,1,1,15,0,0,0,0,0,0,0,0,0,0,0,15,1,1,1,1
1,1,1,1,7,0,0,0,0,0,0,0,0,0,0,0,7,1,1,1,1
1,1,1,1,7,9,0,0,0,0,0,0,0,0,0,9,7,1,1,1,1
1,1,1,1,3,7,0,0,0,0,0,0,0,8,7,7,13,1,1,1,1
1,1,1,1,7,7,9,0,0,9,13,15,7,7,13,7,1,1,1,1,1
1,1,1,1,1,13,7,7,15,7,1,1,1,1,1,1,1,1,1,1,1
1,1,1,1,1,1,1,1,1,1,1,1,1,1,1,1,1,1,1,1,1
1,1,1,1,1,1,1,1,1,1,1,1,1,1,1,1,1,1,1,1,1
1,1,1,1,1,1,1,1,1,1,1,1,1,1,1,1,1,1,1,1,1
endlayer

layer
1,1,1,1,1,1,1,1,1,1,1,1,1,1,1,1,1,1,1,1,1
1,1,1,1,1,1,1,1,1,1,1,1,1,1,1,1,1,1,1,1,1
1,1,1,1,1,1,1,1,1,1,1,1,1,1,1,1,1,1,1,1,1
1,1,1,1,1,1,1,1,8,12,12,6,1,9,1,1,1,1,1,1,1
1,1,1,1,1,1,1,3,7,3,3,7,7,7,1,1,1,1,1,1,1
1,1,1,1,1,1,1,7,16,17,3,17,16,7,7,7,3,1,1,1,1
1,1,1,1,9,7,7,7,17,17,3,17,17,17,17,3,7,1,1,1,1
1,1,1,1,7,3,17,17,17,17,3,17,17,17,17,3,7,1,1,1,1
1,1,1,1,7,18,3,3,3,3,18,3,3,3,3,18,7,1,1,1,1
1,1,1,1,7,3,17,17,17,17,3,17,17,17,17,3,7,1,1,1,1
1,1,1,1,3,3,17,17,17,17,3,17,17,17,17,3,7,9,1,1,1
1,1,1,1,7,3,17,17,17,17,3,17,17,17,17,3,7,1,1,1,1
1,1,1,1,7,3,17,17,17,17,3,17,17,17,17,3,7,1,1,1,1
1,1,1,1,7,18,3,3,3,3,18,3,3,3,3,18,7,1,1,1,1
1,1,1,1,9,7,17,17,17,17,3,0,0,0,19,7,3,1,1,1,1
1,1,1,1,1,7,16,17,17,16,3,7,7,7,3,1,1,1,1,1,1
1,1,1,1,1,3,7,7,7,7,1,1,1,1,1,1,1,1,1,1,1
1,1,1,1,1,1,1,1,1,1,1,1,1,1,1,1,1,1,1,1,1
1,1,1,1,1,1,1,1,1,1,1,1,1,1,1,1,1,1,1,1,1
1,1,1,1,1,1,1,1,1,1,1,1,1,1,1,1,1,1,1,1,1
endlayer

layer
1,1,1,1,1,1,1,1,1,1,1,1,1,1,1,1,1,1,1,1,1
1,1,1,1,1,1,1,1,1,1,1,1,1,1,1,1,1,1,1,1,1
1,1,1,1,1,1,1,1,0,0,0,0,0,1,1,1,1,1,1,1,1
1,1,1,1,1,1,1,0,0,0,0,0,0,9,0,0,1,1,1,1,1
1,1,1,1,1,1,0,9,22,23,23,22,21,20,0,0,0,1,1,1,1
1,1,1,1,0,0,0,24,0,0,0,0,0,9,21,21,9,0,1,1,1
1,1,1,0,9,21,21,9,0,0,0,0,0,0,0,26,25,0,1,1,1
1,1,1,0,24,27,0,0,0,0,0,0,0,0,0,26,22,0,1,1,1
1,1,1,0,22,27,0,0,0,0,0,0,0,0,0,26,22,0,1,1,1
1,1,1,0,24,0,0,0,0,0,0,0,0,0,0,0,25,0,1,1,1
1,1,1,0,9,0,0,0,0,0,9,0,0,0,0,0,22,9,1,1,1
1,1,1,0,24,0,0,0,0,0,0,0,0,0,0,0,25,0,1,1,1
1,1,1,0,22,27,0,0,0,0,0,0,0,0,0,26,22,0,1,1,1
1,1,1,0,24,27,0,0,0,0,0,0,0,0,0,26,25,0,1,1,1
1,1,1,0,9,22,0,0,0,0,0,0,0,0,0,22,9,0,1,1,1
1,1,1,0,0,24,29,29,29,29,9,28,22,28,9,0,0,1,1,1,1
1,1,1,1,0,9,28,22,22,28,0,0,0,0,0,1,1,1,1,1,1
1,1,1,1,1,0,0,0,0,0,0,1,1,1,1,1,1,1,1,1,1
1,1,1,1,1,1,1,1,1,1,1,1,1,1,1,1,1,1,1,1,1
1,1,1,1,1,1,1,1,1,1,1,1,1,1,1,1,1,1,1,1,1
endlayer

layer
1,1,1,1,1,1,1,1,1,1,1,1,1,1,1,1,1,1,1,1,1
1,1,1,1,1,1,1,1,1,0,0,1,1,1,1,1,1,1,1,1,1
1,1,1,1,1,1,1,0,0,0,0,0,0,0,0,1,1,1,1,1,1
1,1,1,1,1,1,0,0,0,0,0,0,0,9,0,0,1,1,1,1,1
1,1,1,1,0,0,0,9,31,33,32,31,31,30,0,0,0,0,1,1,1
1,1,1,0,0,0,0,34,0,0,0,0,0,9,31,31,9,0,1,1,1
1,1,0,0,9,31,31,9,0,0,0,0,0,0,0,35,30,0,1,1,1
1,1,0,0,34,35,0,0,0,0,0,0,0,0,0,35,36,0,0,1,1
1,1,0,0,36,35,0,0,0,0,0,0,0,0,0,35,36,0,0,1,1
1,1,0,0,34,0,0,0,0,0,0,0,0,0,0,0,30,0,0,1,1
1,1,0,0,9,0,0,0,0,0,9,0,0,0,0,0,37,9,0,1,1
1,1,0,0,34,0,0,0,0,0,0,0,0,0,0,0,30,0,0,1,1
1,1,0,0,36,35,0,0,0,0,0,0,0,0,0,35,36,0,0,1,1
1,1,0,0,34,35,0,0,0,0,0,0,0,0,0,35,30,0,0,1,1
1,1,0,0,9,37,0,0,0,0,0,0,0,0,0,37,9,0,1,1,1
1,1,1,0,0,34,35,35,35,35,9,38,36,38,9,0,0,1,1,1,1
1,1,1,0,0,9,38,36,36,38,0,0,0,0,0,0,1,1,1,1,1
1,1,1,1,0,0,0,0,0,0,0,0,0,0,0,1,1,1,1,1,1
1,1,1,1,1,1,1,1,1,1,1,1,1,1,1,1,1,1,1,1,1
1,1,1,1,1,1,1,1,1,1,1,1,1,1,1,1,1,1,1,1,1
endlayer

layer
1,1,1,1,1,1,1,1,1,1,1,1,1,1,1,1,1,1,1,1,1
1,1,1,1,1,1,1,0,0,0,0,0,0,1,1,1,1,1,1,1,1
1,1,1,1,1,1,0,0,0,0,0,0,0,0,0,0,1,1,1,1,1
1,1,1,1,1,0,0,0,41,40,40,39,0,9,0,0,0,1,1,1,1
1,1,1,0,0,0,45,9,43,44,44,43,43,42,0,0,0,0,1,1,1
1,1,0,0,0,0,0,37,0,0,0,0,0,9,43,43,9,0,0,1,1
1,1,0,0,9,37,37,9,0,0,0,0,0,46,0,0,37,0,0,1,1
1,0,0,0,37,0,0,46,0,0,0,0,0,0,0,0,47,0,0,1,1
1,0,0,0,48,0,0,0,0,0,0,0,0,0,0,0,47,0,0,0,1
1,0,0,0,37,0,0,0,0,0,0,0,0,0,0,0,37,0,0,0,1
1,0,0,0,9,46,0,0,0,0,9,0,0,0,0,46,37,9,0,0,1
1,0,0,0,37,0,0,0,0,0,0,0,0,0,0,0,37,0,0,0,1
1,1,0,0,48,0,0,0,0,0,0,0,0,0,0,0,47,0,0,0,1
1,1,0,0,37,0,0,0,0,0,0,0,0,0,0,0,37,0,0,1,1
1,1,0,0,9,37,0,0,0,0,46,0,0,0,0,37,9,0,0,1,1
1,1,0,0,0,37,0,0,0,0,9,37,49,37,9,0,0,0,0,1,1
1,1,1,0,0,9,37,49,49,37,0,0,0,0,0,0,0,1,1,1,1
1,1,1,1,0,0,0,0,0,0,0,0,0,0,0,0,1,1,1,1,1
1,1,1,1,1,0,0,0,0,0,0,0,0,0,1,1,1,1,1,1,1
1,1,1,1,1,1,1,1,1,1,1,1,1,1,1,1,1,1,1,1,1
endlayer

layer
1,1,1,1,1,1,1,1,1,1,0,0,1,1,1,1,1,1,1,1,1
1,1,1,1,1,1,0,0,0,0,0,0,0,0,1,1,1,1,1,1,1
1,1,1,1,1,0,0,0,0,0,0,0,0,0,0,0,0,1,1,1,1
1,1,1,1,0,0,0,45,0,0,0,0,0,9,0,0,0,0,1,1,1
1,1,0,0,0,0,50,50,50,50,50,50,50,50,50,50,0,0,1,1,1
1,1,0,0,0,0,0,51,0,0,0,0,0,9,37,37,9,0,0,1,1
1,0,0,45,9,43,43,9,0,0,0,0,0,0,0,0,37,52,0,1,1
1,0,0,54,37,0,0,0,0,0,0,0,0,0,0,0,53,0,0,0,1
1,0,0,0,53,0,0,0,0,0,0,0,0,0,0,0,53,0,0,0,1
1,0,0,54,37,0,0,0,0,0,0,0,0,0,0,0,37,52,0,0,1
1,0,0,45,9,0,0,0,0,0,9,0,0,0,0,0,37,9,45,0,1
1,0,0,54,37,0,0,0,0,0,0,0,0,0,0,0,37,52,0,0,1
1,0,0,0,53,0,0,0,0,0,0,0,0,0,0,0,53,0,0,0,1
1,1,0,54,37,0,0,0,0,0,0,0,0,0,0,0,37,52,0,0,1
1,1,0,45,9,37,0,0,0,0,0,0,0,0,0,37,9,45,0,1,1
1,1,0,0,0,37,0,0,0,0,9,37,53,37,9,0,0,0,0,1,1
1,1,0,0,0,9,37,53,53,37,0,0,0,0,0,0,0,0,1,1,1
1,1,1,0,0,0,0,0,0,0,0,0,0,0,0,0,0,1,1,1,1
1,1,1,1,0,0,0,0,0,0,0,0,0,0,0,1,1,1,1,1,1
1,1,1,1,1,1,1,1,0,0,0,1,1,1,1,1,1,1,1,1,1
endlayer

layer
1,1,1,1,1,1,1,1,0,0,0,0,0,0,1,1,1,1,1,1,1
1,1,1,1,1,0,0,0,0,0,0,0,0,0,0,1,1,1,1,1,1
1,1,1,1,0,0,0,0,0,0,0,0,0,0,0,0,0,1,1,1,1
1,1,1,0,0,0,0,55,0,0,45,0,0,9,0,0,0,0,1,1,1
1,0,0,0,0,0,0,55,37,37,9,37,37,37,0,0,45,0,0,1,1
1,0,0,0,45,0,0,55,0,0,0,0,0,9,37,37,9,0,0,1,1
1,0,45,50,50,50,50,50,50,50,50,50,50,50,50,50,50,50,0,0,1
1,0,0,45,51,0,0,0,0,0,0,0,0,0,0,0,42,56,0,0,1
1,0,0,57,51,0,0,0,0,0,0,0,0,0,0,0,42,56,0,0,1
0,0,0,0,51,0,0,0,0,0,0,0,0,0,0,0,42,0,0,0,0
0,0,45,50,50,50,50,50,50,50,50,50,50,50,50,50,50,50,50,0,0
1,0,0,0,51,0,0,0,0,0,0,0,0,0,0,0,42,0,0,0,1
1,0,0,57,51,0,0,0,0,0,0,0,0,0,0,0,42,56,0,0,1
1,0,0,45,51,0,0,0,0,0,0,0,0,0,0,0,42,0,0,0,1
1,0,45,50,50,50,50,50,50,50,50,50,50,50,50,50,50,50,0,0,1
1,0,0,0,45,51,0,0,0,0,9,37,53,37,9,0,45,0,0,1,1
1,1,0,0,45,9,37,53,53,37,45,58,0,58,0,0,0,0,1,1,1
1,1,0,0,0,0,58,0,0,58,0,0,0,0,0,0,0,1,1,1,1
1,1,1,0,0,0,0,0,0,0,0,0,0,0,0,0,1,1,1,1,1
1,1,1,1,1,0,0,0,0,0,0,0,0,0,1,1,1,1,1,1,1
endlayer

layer
1,1,1,1,1,1,0,0,0,0,0,0,0,0,0,0,1,1,1,1,1
1,1,1,1,0,0,0,0,0,0,0,0,0,0,0,0,0,1,1,1,1
1,1,1,0,59,0,0,0,0,0,45,0,0,0,0,0,0,0,1,1,1
1,1,0,0,55,0,0,0,0,0,55,0,0,9,0,0,59,0,0,1,1
1,0,0,60,55,0,45,9,43,43,55,43,43,42,45,45,55,53,0,0,1
1,0,0,61,55,45,45,51,0,0,55,0,0,9,43,43,55,0,0,0,1
1,0,64,63,55,43,43,9,53,53,55,62,62,53,62,62,55,53,45,0,0
0,0,60,61,55,0,0,0,0,0,55,0,0,0,0,0,55,0,0,0,0
0,0,0,53,55,0,0,0,0,0,55,0,0,0,0,0,55,0,0,0,0
0,0,0,53,55,0,0,0,0,0,55,0,0,0,0,0,55,53,0,0,0
0,0,0,53,55,62,62,53,62,62,55,49,49,53,49,49,55,9,0,0,0
0,0,0,53,55,0,0,0,0,0,55,0,0,0,0,0,55,53,0,0,0
0,0,0,53,55,0,0,0,0,0,55,0,0,0,0,0,55,0,0,0,0
1,0,60,61,55,0,0,0,0,0,55,0,0,0,0,0,55,0,0,0,1
1,0,0,61,55,37,49,49,49,49,55,49,49,49,31,65,55,53,0,0,1
1,0,0,60,55,37,0,0,0,0,55,65,65,65,9,0,55,0,0,0,1
1,0,0,0,55,9,65,65,65,65,55,45,66,45,45,0,45,0,0,1,1
1,1,0,0,55,45,0,66,66,0,55,0,0,0,0,0,0,0,1,1,1
1,1,1,0,45,0,0,0,0,0,45,0,0,0,0,0,0,1,1,1,1
1,1,1,1,0,0,0,0,0,0,0,0,0,0,0,1,1,1,1,1,1
endlayer

layer
1,1,1,1,1,0,0,0,0,0,0,0,0,0,0,0,0,0,1,1,1
1,1,1,0,0,0,0,0,0,0,0,0,0,0,0,0,0,0,1,1,1
1,1,0,0,0,0,0,0,0,0,0,0,0,53,0,0,0,0,0,1,1
1,0,0,67,0,0,53,0,0,53,0,0,0,9,0,0,53,0,0,0,1
1,0,0,67,50,50,50,50,50,50,50,50,50,50,50,50,50,50,45,0,1
0,0,0,0,63,69,61,0,0,0,53,0,0,9,37,37,0,68,0,0,0
0,0,0,0,67,50,50,50,50,50,50,50,50,50,50,50,50,50,50,70,0
0,0,0,64,71,0,0,0,0,0,48,0,0,0,0,0,22,53,0,0,0
0,0,71,63,63,0,0,0,0,0,48,0,0,0,0,0,22,0,0,0,0
0,73,50,50,50,72,72,72,72,72,72,72,72,72,72,72,50,50,50,70,0
0,0,0,61,0,0,0,0,0,0,74,0,0,0,0,0,0,9,0,0,0
0,73,50,50,50,72,72,72,72,72,72,72,72,72,72,72,50,50,50,70,0
0,0,75,63,63,0,0,0,0,0,47,0,0,0,0,0,22,0,0,0,0
0,0,0,75,60,0,0,0,0,0,47,0,0,0,0,0,22,53,0,0,0
0,0,0,0,63,50,50,50,50,50,50,50,50,50,50,50,50,50,45,0,1
1,0,0,0,63,37,0,0,0,0,9,0,0,0,9,53,0,0,0,0,1
1,0,0,64,63,50,50,50,50,50,50,50,50,50,50,70,0,0,0,1,1
1,1,0,67,68,53,53,0,0,53,0,0,0,53,0,0,0,0,0,1,1
1,1,0,0,0,0,0,0,0,0,0,0,0,0,0,0,0,1,1,1,1
1,1,1,0,0,0,0,0,0,0,0,0,0,0,0,0,1,1,1,1,1
endlayer

layer
1,1,1,1,0,0,0,0,0,0,0,0,0,0,0,0,0,0,1,1,1
1,1,0,0,0,0,0,0,0,59,0,0,0,59,0,0,0,0,0,1,1
1,1,0,0,69,0,45,0,0,55,0,0,0,55,0,0,45,0,0,0,1
1,0,0,0,68,53,55,53,53,55,53,53,53,55,0,0,55,69,60,0,1
0,0,0,0,63,63,55,69,61,55,69,69,69,55,69,69,55,63,64,0,0
0,0,0,0,64,63,55,0,69,55,0,0,0,76,0,0,55,63,64,0,0
0,0,0,0,0,63,55,9,0,76,62,62,62,76,53,53,55,63,71,0,0
0,0,0,0,0,67,55,0,0,76,0,0,0,76,0,0,55,77,0,0,0
0,0,0,0,64,71,55,0,0,76,0,0,0,76,0,0,55,53,0,0,0
0,61,71,71,67,63,55,49,49,76,49,49,49,76,53,53,55,53,0,0,0
0,0,61,63,60,0,55,0,0,76,0,0,0,76,0,0,55,9,0,0,0
0,61,75,75,63,63,55,62,62,76,49,49,49,76,53,53,55,0,0,0,0
0,0,0,0,0,63,55,0,0,76,0,0,0,76,0,0,55,53,0,0,0
0,0,0,0,0,67,55,0,0,76,0,0,0,76,0,0,55,53,0,0,0
1,0,0,0,0,63,55,49,49,76,49,49,49,76,0,0,55,60,60,0,0
1,0,0,0,64,63,55,0,0,76,9,63,63,76,9,63,60,60,0,0,1
1,1,0,0,67,63,55,77,61,55,53,53,53,55,53,60,0,0,0,0,1
1,1,0,0,67,77,55,53,53,55,0,0,0,55,0,0,0,0,0,1,1
1,1,1,0,0,0,55,0,0,45,0,0,0,45,0,0,0,0,1,1,1
1,1,1,0,0,0,78,0,0,0,0,0,0,0,0,0,1,1,1,1,1
endlayer

layer
1,1,1,1,0,0,0,0,0,0,0,0,0,0,0,0,0,0,1,1,1
1,1,1,0,0,0,0,0,0,0,0,0,0,0,0,0,0,0,1,1,1
1,1,0,0,67,68,0,0,61,79,67,68,0,0,0,0,61,79,0,1,1
1,1,0,0,64,63,0,61,63,63,67,69,69,9,53,53,53,79,0,0,1
1,0,0,0,0,64,63,63,63,63,63,50,50,50,50,50,63,0,0,0,1
1,0,0,0,0,64,63,0,0,63,63,0,0,47,0,63,63,0,0,0,0
0,0,0,0,0,0,63,9,0,63,63,0,0,47,63,63,63,64,0,0,0
0,0,0,0,0,0,63,63,0,63,63,0,0,47,63,63,63,63,71,0,0
0,0,0,0,0,0,64,63,50,50,50,50,50,50,50,50,50,50,50,45,0
0,0,0,0,0,0,81,80,0,0,63,0,0,53,0,0,63,53,0,0,0
83,80,82,82,81,80,40,0,63,63,63,0,0,53,0,0,0,9,0,0,0
0,0,0,0,0,64,64,63,63,63,63,0,0,53,0,0,63,53,0,0,0
0,0,0,0,0,0,67,0,63,63,50,50,50,50,50,50,50,50,50,45,0
1,0,0,0,0,0,63,0,63,63,0,0,0,47,63,63,75,63,69,0,0
1,0,0,0,0,0,63,0,63,63,0,0,0,47,63,64,64,64,0,0,0
1,1,0,0,0,64,63,63,63,63,9,0,0,47,79,64,0,0,0,0,0
1,1,0,0,0,67,63,63,67,63,68,77,77,63,79,0,0,0,0,0,1
1,1,1,0,0,71,77,63,67,63,68,0,0,77,0,0,0,0,0,1,1
1,1,1,0,0,77,0,77,0,0,0,0,0,0,0,0,0,1,1,1,1
1,1,1,1,0,0,0,0,0,0,0,0,0,0,0,1,1,1,1,1,1
endlayer

layer
1,1,1,1,1,0,0,0,0,1,1,0,0,0,0,0,0,0,1,1,1
1,1,1,1,0,0,0,0,0,0,1,0,0,0,0,0,0,0,1,1,1
1,1,1,1,0,67,0,61,64,0,0,64,67,68,0,61,79,0,0,1,1
1,1,1,0,0,67,69,63,79,0,0,64,63,63,69,63,79,0,0,1,1
1,1,1,0,0,0,67,40,63,0,0,67,63,0,63,63,64,0,0,0,1
1,1,0,0,0,0,64,40,64,64,0,67,63,0,63,63,0,0,0,0,1
1,0,0,0,0,0,64,80,40,64,0,67,0,0,63,79,0,0,0,0,0
1,0,0,0,0,0,0,64,84,64,64,67,0,63,63,64,64,0,0,0,0
0,0,0,0,0,0,0,0,85,64,71,63,49,63,63,79,71,71,71,0,0
0,0,0,0,0,0,0,82,80,40,0,0,0,63,60,63,63,68,0,0,0
82,0,0,0,0,0,82,82,0,64,75,63,63,63,0,0,0,9,0,0,0
0,0,0,0,0,0,0,85,0,0,67,0,63,63,63,63,0,68,0,0,0
1,0,0,0,0,0,0,85,0,0,63,0,63,63,63,75,75,75,60,0,0
1,1,0,0,0,0,0,86,0,64,63,0,63,63,64,0,0,0,64,0,0
1,1,0,0,0,0,0,86,0,71,63,0,63,79,0,0,0,0,0,0,0
1,1,1,0,0,0,85,0,0,67,63,0,63,79,0,0,0,0,0,0,1
1,1,1,0,0,0,85,0,0,67,63,0,63,79,0,0,0,0,0,0,1
1,1,1,1,0,0,85,0,0,64,63,77,61,64,0,0,0,0,1,1,1
1,1,1,1,0,0,80,0,0,0,77,0,77,0,0,0,1,1,1,1,1
1,1,1,1,1,0,40,0,0,0,0,0,0,0,1,1,1,1,1,1,1
endlayer

layer
1,1,1,1,1,0,0,0,1,1,1,1,0,0,0,0,0,1,1,1,1
1,1,1,1,1,0,87,0,0,1,1,1,0,69,0,69,0,1,1,1,1
1,1,1,1,0,0,85,0,0,1,1,0,0,67,69,79,0,0,1,1,1
1,1,1,1,0,0,82,86,0,0,1,0,0,80,63,79,0,0,1,1,1
1,1,1,1,0,0,0,82,0,0,0,0,64,40,63,64,0,0,0,1,1
1,1,1,0,0,0,0,0,0,0,0,0,64,40,64,0,0,0,0,1,1
1,1,1,0,0,0,0,0,0,0,0,0,85,40,64,0,0,0,0,0,1
1,1,0,0,0,0,0,0,0,0,0,0,85,64,0,0,0,0,0,0,0
1,0,0,0,0,0,0,0,0,0,0,0,84,64,64,0,0,0,0,0,0
1,0,0,0,0,0,0,0,0,0,82,82,88,40,40,71,67,63,63,68,0
0,0,0,0,0,0,0,0,0,0,0,82,0,64,40,0,0,9,0,0,0
1,0,0,0,0,0,0,0,0,0,0,82,0,0,64,75,75,63,63,68,0
1,1,0,0,0,0,0,0,0,0,0,85,0,0,0,0,0,0,0,0,0
1,1,1,0,0,0,0,0,0,0,0,85,64,0,0,0,0,0,0,0,0
1,1,1,0,0,0,0,0,0,0,0,85,64,0,0,0,0,0,0,0,1
1,1,1,1,0,0,0,0,0,0,64,80,64,0,0,0,0,0,0,0,1
1,1,1,1,0,0,0,0,0,0,64,85,64,0,0,0,0,0,0,1,1
1,1,1,1,0,0,0,0,0,0,0,85,64,0,0,0,0,1,1,1,1
1,1,1,1,1,0,82,0,1,1,0,80,0,0,1,1,1,1,1,1,1
1,1,1,1,1,0,81,0,1,1,0,40,0,1,1,1,1,1,1,1,1
endlayer

layer
1,1,1,1,1,1,0,1,1,1,1,1,1,0,87,0,1,1,1,1,1
1,1,1,1,1,0,82,0,1,1,1,1,0,0,86,0,1,1,1,1,1
1,1,1,1,1,0,0,0,0,1,1,1,0,0,86,0,0,1,1,1,1
1,1,1,1,1,0,0,0,0,1,1,0,0,0,82,0,0,1,1,1,1
1,1,1,1,1,0,0,0,0,0,1,0,0,0,0,0,0,1,1,1,1
1,1,1,1,1,0,0,0,0,0,0,0,0,0,0,0,0,0,1,1,1
1,1,1,1,0,0,0,0,0,0,0,0,0,0,0,0,0,0,0,1,1
1,1,1,1,0,0,0,0,0,0,0,0,0,0,0,0,0,0,0,0,1
1,1,1,0,0,0,0,0,0,0,0,0,0,0,0,0,0,0,0,0,0
1,1,0,0,0,0,0,0,0,0,0,0,0,0,0,0,0,0,64,0,0
1,1,0,0,0,0,0,0,0,0,0,0,0,0,82,82,88,85,80,80,40
1,1,1,0,0,0,0,0,0,0,0,0,0,0,0,0,0,0,64,0,0
1,1,1,1,0,0,0,0,0,0,0,0,0,0,0,0,0,0,0,0,0
1,1,1,1,1,0,0,0,0,0,0,0,0,0,0,0,0,0,0,0,1
1,1,1,1,1,0,0,0,0,0,0,0,0,0,0,0,0,0,1,1,1
1,1,1,1,1,1,0,0,0,0,0,0,0,0,0,0,0,0,1,1,1
1,1,1,1,1,1,0,0,0,0,0,0,0,0,0,0,1,1,1,1,1
1,1,1,1,1,1,1,0,1,0,0,0,0,0,0,1,1,1,1,1,1
1,1,1,1,1,1,1,0,1,1,0,82,0,1,1,1,1,1,1,1,1
1,1,1,1,1,1,0,1,1,1,0,81,0,1,1,1,1,1,1,1,1
endlayer

layer
1,1,1,1,1,1,1,1,1,1,1,1,1,1,82,1,1,1,1,1,1
1,1,1,1,1,1,1,1,1,1,1,1,1,0,0,1,1,1,1,1,1
1,1,1,1,1,1,0,1,1,1,1,1,1,0,0,1,1,1,1,1,1
1,1,1,1,1,1,0,0,1,1,1,1,0,0,0,0,1,1,1,1,1
1,1,1,1,1,1,0,0,0,1,1,1,0,0,0,0,1,1,1,1,1
1,1,1,1,1,1,0,0,0,0,1,0,0,0,0,0,1,1,1,1,1
1,1,1,1,1,1,0,0,0,0,0,0,0,0,0,0,0,1,1,1,1
1,1,1,1,1,1,0,0,0,0,0,0,0,0,0,0,0,0,1,1,1
1,1,1,1,1,0,0,0,0,0,0,0,0,0,0,0,0,0,0,1,1
1,1,1,1,0,0,0,0,0,0,0,0,0,0,0,0,0,0,0,0,0
1,1,1,1,0,0,0,0,0,0,0,0,0,0,0,0,0,0,0,82,85
1,1,1,1,1,0,0,0,0,0,0,0,0,0,0,0,0,0,0,0,0
1,1,1,1,1,1,0,0,0,0,0,0,0,0,0,0,0,0,0,0,1
1,1,1,1,1,1,1,0,0,0,0,0,0,0,0,0,0,0,0,1,1
1,1,1,1,1,1,1,1,0,0,0,0,0,0,0,0,0,1,1,1,1
1,1,1,1,1,1,1,1,1,0,0,0,0,0,0,0,1,1,1,1,1
1,1,1,1,1,1,1,1,1,0,0,0,0,0,0,1,1,1,1,1,1
1,1,1,1,1,1,1,1,1,1,0,0,0,0,1,1,1,1,1,1,1
1,1,1,1,1,1,1,1,1,1,1,0,0,1,1,1,1,1,1,1,1
1,1,1,1,1,1,1,1,1,1,1,0,1,1,1,1,1,1,1,1,1
endlayer

