
# Created by Ruins mod version 16.8 Ingame Parser
# authoring Player: ST753M

weight=1
uniqueMinDistance=1000
spawnMinDistance=1000
embed_into_distance=5
acceptable_target_blocks=end_stone,endstone
unacceptable_target_blocks=flowing_water,water,flowing_lava,lava
dimensions=27,13,13
allowable_overhang=64
max_leveling=2
leveling_buffer=0
preserve_water=0
preserve_lava=0

biomesToSpawnIn=sky,end,the_end,void

rule1=0,100,preserveBlock
rule2=0,100,minecraft:end_stone-0
rule3=0,100,minecraft:purpur_pillar-0
rule4=0,100,minecraft:obsidian-0
rule5=0,100,minecraft:purpur_block-0
rule6=0,100,minecraft:purpur_pillar-8
rule7=0,100,minecraft:purpur_pillar-4
rule8=0,100,minecraft:purpur_stairs-0
rule9=0,100,minecraft:purpur_stairs-5
rule10=0,100,minecraft:stained_glass-10
rule11=0,100,minecraft:purpur_stairs-6
rule12=0,100,minecraft:purpur_stairs-3
rule13=0,100,minecraft:purpur_stairs-7
rule14=0,100,minecraft:purpur_stairs-4
rule15=0,100,minecraft:ladder-5
rule16=0,100,minecraft:ladder-2
rule17=0,100,ChestGenHook:chests/end_city_treasure:1-3,ChestGenHook:chests/stronghold_library:3-3,ChestGenHook:chests/end_city_treasure:2-3
rule18=0,100,minecraft:wool-10

layer
1,1,1,1,1,1,1,1,1,1,1,1,1
1,1,1,1,1,1,1,1,1,1,1,1,1
1,1,1,2,2,2,2,2,2,2,1,1,1
1,1,2,2,2,2,2,2,2,2,2,1,1
1,1,2,2,2,2,2,2,2,2,2,1,1
1,1,2,2,2,2,2,2,2,2,2,1,1
1,1,2,2,2,2,2,2,2,2,2,1,1
1,1,2,2,2,2,2,2,2,2,2,1,1
1,1,2,2,2,2,2,2,2,2,2,1,1
1,1,2,2,2,2,2,2,2,2,2,1,1
1,1,1,2,2,2,2,2,2,2,1,1,1
1,1,1,1,1,1,1,1,1,1,1,1,1
1,1,1,1,1,1,1,1,1,1,1,1,1
endlayer

layer
1,1,1,1,1,1,1,1,1,1,1,1,1
1,1,2,2,2,2,2,2,2,2,2,1,1
1,2,2,2,2,2,2,2,2,2,2,2,1
1,2,2,2,2,2,2,2,2,2,2,2,1
1,2,2,2,2,2,2,2,2,2,2,2,1
1,2,2,2,2,2,2,2,2,2,2,2,1
1,2,2,2,2,2,2,2,2,2,2,2,1
1,2,2,2,2,2,2,2,2,2,2,2,1
1,2,2,2,2,2,2,2,2,2,2,2,1
1,2,2,2,2,2,2,2,2,2,2,2,1
1,2,2,2,2,2,2,2,2,2,2,2,1
1,1,2,2,2,2,2,2,2,2,2,1,1
1,1,1,1,1,1,1,1,1,1,1,1,1
endlayer

layer
1,1,2,2,2,2,2,2,2,2,2,1,1
1,2,2,2,2,2,2,2,2,2,2,2,1
2,2,2,2,2,2,2,2,2,2,2,2,2
2,2,2,2,2,2,2,2,2,2,2,2,2
2,2,2,2,2,2,2,2,2,2,2,2,2
2,2,2,2,2,2,2,2,2,2,2,2,2
2,2,2,2,2,2,2,2,2,2,2,2,2
2,2,2,2,2,2,2,2,2,2,2,2,2
2,2,2,2,2,2,2,2,2,2,2,2,2
2,2,2,2,2,2,2,2,2,2,2,2,2
2,2,2,2,2,2,2,2,2,2,2,2,2
1,2,2,2,2,2,2,2,2,2,2,2,1
1,1,2,2,2,2,2,2,2,2,2,1,1
endlayer

layer
1,2,2,2,2,2,2,2,2,2,2,2,1
2,2,2,2,2,2,2,2,2,2,2,2,2
2,2,2,2,2,2,2,2,2,2,2,2,2
2,2,2,2,2,2,2,2,2,2,2,2,2
2,2,2,2,2,2,2,2,2,2,2,2,2
2,2,2,2,2,2,2,2,2,2,2,2,2
2,2,2,2,2,2,2,2,2,2,2,2,2
2,2,2,2,2,2,2,2,2,2,2,2,2
2,2,2,2,2,2,2,2,2,2,2,2,2
2,2,2,2,2,2,2,2,2,2,2,2,2
2,2,2,2,2,2,2,2,2,2,2,2,2
2,2,2,2,2,2,2,2,2,2,2,2,2
1,2,2,2,2,2,2,2,2,2,2,2,1
endlayer

layer
1,2,2,2,2,2,2,2,2,2,2,2,1
2,3,4,4,4,4,4,4,4,4,4,3,2
2,4,5,5,5,5,5,5,5,5,5,4,2
2,4,5,3,6,6,7,6,6,3,5,4,2
2,4,5,7,7,6,6,3,6,7,5,4,2
2,4,5,7,3,7,6,6,7,7,5,4,2
2,4,5,6,7,7,3,7,7,6,5,4,2
2,4,5,7,7,6,6,7,3,7,5,4,2
2,4,5,7,6,3,6,6,7,7,5,4,2
2,4,5,3,6,6,7,6,6,3,5,4,2
2,4,5,5,5,5,5,5,5,5,5,4,2
2,3,4,4,4,4,4,4,4,4,4,3,2
1,2,2,2,2,2,2,2,2,2,2,2,1
endlayer

layer
1,1,1,1,1,1,1,1,1,1,1,1,1
1,3,4,4,4,4,4,4,4,4,4,3,1
1,4,0,0,0,0,0,0,0,0,0,4,1
1,4,0,0,0,0,0,0,0,0,0,4,1
1,4,0,0,4,0,0,0,4,0,0,4,1
1,0,0,0,0,0,0,0,0,0,0,4,1
1,0,0,0,0,0,0,0,0,0,0,4,1
1,0,0,0,0,0,0,0,0,0,0,4,1
1,4,8,0,4,0,0,0,4,0,0,4,1
1,4,9,0,0,0,0,0,0,0,0,4,1
1,4,0,0,0,0,0,0,0,0,0,4,1
1,3,4,4,4,4,4,4,4,4,4,3,1
1,1,1,1,1,1,1,1,1,1,1,1,1
endlayer

layer
1,1,1,1,1,1,1,1,1,1,1,1,1
1,3,4,10,4,10,4,10,4,10,4,3,1
1,4,0,0,0,0,0,0,0,0,0,4,1
1,10,0,0,0,0,0,0,0,0,0,10,1
1,4,0,0,4,0,0,0,4,0,0,4,1
1,0,0,0,0,0,0,0,0,0,0,10,1
1,0,0,0,0,0,0,0,0,0,0,4,1
1,0,0,0,0,0,0,0,0,0,0,10,1
1,4,0,0,4,0,0,0,4,0,0,4,1
1,10,8,0,0,0,0,0,0,0,0,10,1
1,4,9,0,0,0,0,0,0,0,0,4,1
1,3,4,10,4,10,4,10,4,10,4,3,1
1,1,1,1,1,1,1,1,1,1,1,1,1
endlayer

layer
1,1,1,1,1,1,1,1,1,1,1,1,1
1,3,4,10,4,10,4,10,4,10,4,3,1
1,4,0,0,0,0,0,0,0,0,0,4,1
1,10,0,0,0,0,0,0,0,0,0,10,1
1,4,0,0,4,0,0,0,4,0,0,4,1
1,0,0,0,0,0,0,0,0,0,0,10,1
1,0,0,0,0,0,0,0,0,0,0,4,1
1,0,0,0,0,0,0,0,0,0,0,10,1
1,4,0,0,4,0,0,0,4,0,0,4,1
1,10,0,0,0,0,0,0,0,0,0,10,1
1,4,8,11,0,0,0,0,0,0,0,4,1
1,3,4,10,4,10,4,10,4,10,4,3,1
1,1,1,1,1,1,1,1,1,1,1,1,1
endlayer

layer
1,1,1,1,1,1,1,1,1,1,1,1,1
1,3,4,4,4,4,4,4,4,4,4,3,1
1,4,0,0,0,0,0,0,0,0,0,4,1
1,4,0,0,0,0,0,0,0,0,0,4,1
1,4,0,0,4,0,0,0,4,0,0,4,1
1,4,0,0,0,0,0,0,0,0,0,4,1
1,4,0,0,0,0,0,0,0,0,0,4,1
1,4,0,0,0,0,0,0,0,0,0,4,1
1,4,0,0,4,0,0,0,4,0,0,4,1
1,4,0,0,0,0,0,0,0,0,0,4,1
1,4,0,12,11,0,0,0,0,0,0,4,1
1,3,4,4,4,4,4,4,4,4,4,3,1
1,1,1,1,1,1,1,1,1,1,1,1,1
endlayer

layer
1,4,1,4,1,4,1,4,1,4,1,4,1
4,3,4,4,4,4,4,4,4,4,4,4,4
1,4,5,5,5,5,5,5,5,5,5,4,1
4,4,5,5,5,9,9,9,5,5,5,4,4
1,4,5,5,4,0,0,0,4,5,5,4,1
4,4,5,11,0,0,0,0,0,13,5,4,4
1,4,5,11,0,0,0,0,0,13,5,4,1
4,4,5,11,0,0,0,0,0,13,5,4,4
1,4,9,5,4,0,0,0,4,5,5,4,1
4,4,0,5,5,14,14,14,5,5,5,4,4
1,4,0,0,12,5,5,5,5,5,5,4,1
4,4,4,4,4,4,4,4,4,4,4,4,4
1,4,1,4,1,4,1,4,1,4,1,4,1
endlayer

layer
1,4,4,4,4,4,4,4,4,4,4,4,1
4,5,5,5,5,5,5,5,5,5,5,5,4
4,5,5,5,5,5,5,5,5,5,5,5,4
4,5,5,5,5,4,5,4,5,5,5,5,4
4,5,5,5,4,5,5,5,4,5,5,5,4
4,5,5,4,5,6,6,7,5,4,5,5,4
4,5,5,4,5,7,5,7,5,4,5,5,4
4,5,5,4,5,7,6,6,5,4,5,5,4
4,5,5,5,4,5,5,5,4,5,5,5,4
4,5,9,5,5,4,4,4,5,5,5,5,4
4,5,0,0,0,12,5,5,5,5,5,5,4
4,5,5,5,5,5,5,5,5,5,5,5,4
1,4,4,4,4,4,4,4,4,4,4,4,1
endlayer

layer
4,4,4,4,4,4,4,4,4,4,4,4,4
4,0,0,0,0,0,0,0,0,0,0,0,4
4,0,0,0,0,0,0,0,0,0,0,0,4
4,0,0,0,0,4,0,4,0,0,0,0,4
4,0,0,0,4,0,0,15,4,0,0,0,4
4,0,0,4,0,0,0,0,0,4,0,0,4
4,0,0,4,0,0,0,0,0,4,0,0,4
4,0,0,4,0,0,0,0,0,4,0,0,4
4,0,0,0,4,0,0,0,4,0,0,0,4
4,0,0,0,0,4,4,4,0,0,0,0,4
4,0,0,0,0,0,0,0,0,0,0,0,4
4,0,0,0,0,0,0,0,0,0,0,0,4
4,4,4,4,4,4,4,4,4,4,4,4,4
endlayer

layer
4,1,4,1,4,1,4,1,4,1,4,1,4
1,1,1,1,1,1,1,1,1,1,1,1,1
4,1,1,1,1,0,0,0,1,1,1,1,4
1,1,1,0,0,4,0,4,0,0,1,1,1
4,1,1,0,4,0,0,15,4,0,1,1,4
1,1,0,4,0,0,0,0,0,4,0,1,1
4,1,0,10,0,0,0,0,0,10,0,1,4
1,1,0,4,0,0,0,0,0,4,0,1,1
4,1,1,0,4,0,0,0,4,0,1,1,4
1,1,1,0,0,4,10,4,0,0,1,1,1
4,1,1,1,1,0,0,0,1,1,1,1,4
1,1,1,1,1,1,1,1,1,1,1,1,1
4,1,4,1,4,1,4,1,4,1,4,1,4
endlayer

layer
1,1,1,1,1,1,1,1,1,1,1,1,1
1,1,1,1,1,1,1,1,1,1,1,1,1
1,1,1,1,1,0,0,0,1,1,1,1,1
1,1,1,0,0,4,4,4,0,0,1,1,1
1,1,1,0,4,0,0,15,4,0,1,1,1
1,1,0,4,0,0,0,0,0,4,0,1,1
1,1,0,10,0,0,0,0,0,10,0,1,1
1,1,0,4,0,0,0,0,0,4,0,1,1
1,1,1,0,4,0,0,0,4,0,1,1,1
1,1,1,0,0,4,10,4,0,0,1,1,1
1,1,1,1,1,0,0,0,1,1,1,1,1
1,1,1,1,1,1,1,1,1,1,1,1,1
1,1,1,1,1,1,1,1,1,1,1,1,1
endlayer

layer
1,1,1,1,1,1,1,1,1,1,1,1,1
1,1,1,1,1,1,1,1,1,1,1,1,1
1,1,1,1,1,0,0,0,1,1,1,1,1
1,1,1,0,0,4,4,4,0,0,1,1,1
1,1,1,0,4,0,0,15,4,0,1,1,1
1,1,0,4,0,0,0,0,0,4,0,1,1
1,1,0,4,0,0,0,0,0,4,0,1,1
1,1,0,4,0,0,0,0,0,4,0,1,1
1,1,1,0,4,0,0,0,4,0,1,1,1
1,1,1,0,0,4,4,4,0,0,1,1,1
1,1,1,1,1,0,0,0,1,1,1,1,1
1,1,1,1,1,1,1,1,1,1,1,1,1
1,1,1,1,1,1,1,1,1,1,1,1,1
endlayer

layer
1,1,1,1,1,1,1,1,1,1,1,1,1
1,1,1,1,1,1,1,1,1,1,1,1,1
1,1,1,1,1,0,0,0,1,1,1,1,1
1,1,1,0,0,4,7,4,0,0,1,1,1
1,1,1,0,4,5,5,15,4,0,1,1,1
1,1,0,4,5,7,6,6,5,4,0,1,1
1,1,0,6,5,7,5,7,5,6,0,1,1
1,1,0,4,5,6,6,7,5,4,0,1,1
1,1,1,0,4,5,5,5,4,0,1,1,1
1,1,1,0,0,4,7,4,0,0,1,1,1
1,1,1,1,1,0,0,0,1,1,1,1,1
1,1,1,1,1,1,1,1,1,1,1,1,1
1,1,1,1,1,1,1,1,1,1,1,1,1
endlayer

layer
1,1,1,1,1,1,1,1,1,1,1,1,1
1,1,1,1,1,1,1,1,1,1,1,1,1
1,1,1,1,1,0,0,0,1,1,1,1,1
1,1,1,0,0,4,4,4,0,0,1,1,1
1,1,1,0,4,0,0,0,4,0,1,1,1
1,1,0,4,0,0,0,0,0,4,0,1,1
1,1,0,4,0,0,0,0,0,4,0,1,1
1,1,0,4,16,0,0,0,0,4,0,1,1
1,1,1,0,4,0,0,0,4,0,1,1,1
1,1,1,0,0,4,4,4,0,0,1,1,1
1,1,1,1,1,0,0,0,1,1,1,1,1
1,1,1,1,1,1,1,1,1,1,1,1,1
1,1,1,1,1,1,1,1,1,1,1,1,1
endlayer

layer
1,1,1,1,1,1,1,1,1,1,1,1,1
1,1,1,1,1,1,1,1,1,1,1,1,1
1,1,1,1,1,0,0,0,1,1,1,1,1
1,1,1,0,0,4,10,4,0,0,1,1,1
1,1,1,0,4,0,0,0,4,0,1,1,1
1,1,0,4,0,0,0,0,0,4,0,1,1
1,1,0,10,0,0,0,0,0,10,0,1,1
1,1,0,4,16,0,0,0,0,4,0,1,1
1,1,1,0,4,0,0,0,4,0,1,1,1
1,1,1,0,0,4,10,4,0,0,1,1,1
1,1,1,1,1,0,0,0,1,1,1,1,1
1,1,1,1,1,1,1,1,1,1,1,1,1
1,1,1,1,1,1,1,1,1,1,1,1,1
endlayer

layer
1,1,1,1,1,1,1,1,1,1,1,1,1
1,1,1,1,1,1,1,1,1,1,1,1,1
1,1,1,1,1,0,0,0,1,1,1,1,1
1,1,1,0,0,4,10,4,0,0,1,1,1
1,1,1,0,4,0,0,0,4,0,1,1,1
1,1,0,4,0,0,0,0,0,4,0,1,1
1,1,0,10,0,0,0,0,0,10,0,1,1
1,1,0,4,16,0,0,0,0,4,0,1,1
1,1,1,0,4,0,0,0,4,0,1,1,1
1,1,1,0,0,4,10,4,0,0,1,1,1
1,1,1,1,1,0,0,0,1,1,1,1,1
1,1,1,1,1,1,1,1,1,1,1,1,1
1,1,1,1,1,1,1,1,1,1,1,1,1
endlayer

layer
1,1,1,1,1,1,1,1,1,1,1,1,1
1,1,1,1,1,1,1,1,1,1,1,1,1
1,1,1,1,1,0,0,0,1,1,1,1,1
1,1,1,0,0,4,4,4,0,0,1,1,1
1,1,1,0,4,0,0,0,4,0,1,1,1
1,1,0,4,0,0,0,0,0,4,0,1,1
1,1,0,4,0,0,0,0,0,4,0,1,1
1,1,0,4,16,0,0,0,0,4,0,1,1
1,1,1,0,4,0,0,0,4,0,1,1,1
1,1,1,0,0,4,4,4,0,0,1,1,1
1,1,1,1,1,0,0,0,1,1,1,1,1
1,1,1,1,1,1,1,1,1,1,1,1,1
1,1,1,1,1,1,1,1,1,1,1,1,1
endlayer

layer
1,1,1,1,1,1,1,1,1,1,1,1,1
1,1,1,1,1,1,1,1,1,1,1,1,1
1,1,1,1,1,4,4,4,1,1,1,1,1
1,1,1,0,4,5,5,5,4,0,1,1,1
1,1,1,4,5,5,5,5,5,4,1,1,1
1,1,4,5,5,6,6,7,5,5,4,1,1
1,1,4,5,5,7,5,7,5,5,4,1,1
1,1,4,5,16,7,6,6,5,5,4,1,1
1,1,1,4,5,5,5,5,5,4,1,1,1
1,1,1,0,4,5,5,5,4,0,1,1,1
1,1,1,1,1,4,4,4,1,1,1,1,1
1,1,1,1,1,1,1,1,1,1,1,1,1
1,1,1,1,1,1,1,1,1,1,1,1,1
endlayer

layer
1,1,1,1,1,1,1,1,1,1,1,1,1
1,1,1,1,1,1,1,1,1,1,1,1,1
1,1,1,1,1,4,4,4,1,1,1,1,1
1,1,1,4,4,1,1,1,4,4,1,1,1
1,1,1,4,1,1,1,1,1,4,1,1,1
1,1,4,1,1,1,1,1,1,1,4,1,1
1,1,4,1,1,1,3,1,1,17,4,1,1
1,1,4,1,1,0,0,1,1,1,4,1,1
1,1,1,4,1,1,1,1,1,4,1,1,1
1,1,1,4,4,1,1,1,4,4,1,1,1
1,1,1,1,1,4,4,4,1,1,1,1,1
1,1,1,1,1,1,1,1,1,1,1,1,1
1,1,1,1,1,1,1,1,1,1,1,1,1
endlayer

layer
1,1,1,1,1,1,1,1,1,1,1,1,1
1,1,1,1,1,1,1,1,1,1,1,1,1
1,1,1,1,1,4,1,4,1,1,1,1,1
1,1,1,4,1,1,1,1,1,4,1,1,1
1,1,1,1,1,1,1,1,1,1,1,1,1
1,1,4,1,1,1,1,1,1,1,4,1,1
1,1,1,1,1,1,3,1,1,1,1,1,1
1,1,4,1,1,0,0,1,1,1,4,1,1
1,1,1,1,1,1,1,1,1,1,1,1,1
1,1,1,4,1,1,1,1,1,4,1,1,1
1,1,1,1,1,4,1,4,1,1,1,1,1
1,1,1,1,1,1,1,1,1,1,1,1,1
1,1,1,1,1,1,1,1,1,1,1,1,1
endlayer

layer
1,1,1,1,1,1,1,1,1,1,1,1,1
1,1,1,1,1,1,1,1,1,1,1,1,1
1,1,1,1,1,1,1,1,1,1,1,1,1
1,1,1,1,1,1,1,1,1,1,1,1,1
1,1,1,1,1,1,1,1,1,1,1,1,1
1,1,1,1,1,1,1,1,1,1,1,1,1
1,1,1,1,1,1,3,1,1,1,1,1,1
1,1,1,1,1,0,0,1,1,1,1,1,1
1,1,1,1,1,1,1,1,1,1,1,1,1
1,1,1,1,1,1,1,1,1,1,1,1,1
1,1,1,1,1,1,1,1,1,1,1,1,1
1,1,1,1,1,1,1,1,1,1,1,1,1
1,1,1,1,1,1,1,1,1,1,1,1,1
endlayer

layer
1,1,1,1,1,1,1,1,1,1,1,1,1
1,1,1,1,1,1,1,1,1,1,1,1,1
1,1,1,1,1,1,1,1,1,1,1,1,1
1,1,1,1,1,1,1,1,1,1,1,1,1
1,1,1,1,1,1,1,1,1,1,1,1,1
1,1,1,1,1,1,1,1,1,1,1,1,1
1,1,1,1,1,1,3,1,1,1,1,1,1
1,1,1,1,1,0,0,1,1,1,1,1,1
1,1,1,1,1,1,1,1,1,1,1,1,1
1,1,1,1,1,1,1,1,1,1,1,1,1
1,1,1,1,1,1,1,1,1,1,1,1,1
1,1,1,1,1,1,1,1,1,1,1,1,1
1,1,1,1,1,1,1,1,1,1,1,1,1
endlayer

layer
1,1,1,1,1,1,1,1,1,1,1,1,1
1,1,1,1,1,1,1,1,1,1,1,1,1
1,1,1,1,1,1,1,1,1,1,1,1,1
1,1,1,1,1,1,1,1,1,1,1,1,1
1,1,1,1,1,1,1,1,1,1,1,1,1
1,1,1,1,1,1,1,1,1,1,1,1,1
1,1,1,1,1,1,18,1,1,1,1,1,1
1,1,1,1,1,18,18,1,1,1,1,1,1
1,1,1,1,18,18,1,1,1,1,1,1,1
1,1,1,18,18,1,1,1,1,1,1,1,1
1,1,1,18,1,1,1,1,1,1,1,1,1
1,1,1,1,1,1,1,1,1,1,1,1,1
1,1,1,1,1,1,1,1,1,1,1,1,1
endlayer

layer
1,1,1,1,1,1,1,1,1,1,1,1,1
1,1,1,1,1,1,1,1,1,1,1,1,1
1,1,1,1,1,1,1,1,1,1,1,1,1
1,1,1,1,1,1,1,1,1,1,1,1,1
1,1,1,1,1,1,1,1,1,1,1,1,1
1,1,1,1,1,1,1,1,1,1,1,1,1
1,1,1,1,1,1,18,1,1,1,1,1,1
1,1,1,1,1,18,18,1,1,1,1,1,1
1,1,1,1,18,1,1,1,1,1,1,1,1
1,1,1,1,1,1,1,1,1,1,1,1,1
1,1,1,1,1,1,1,1,1,1,1,1,1
1,1,1,1,1,1,1,1,1,1,1,1,1
1,1,1,1,1,1,1,1,1,1,1,1,1
endlayer

