
# Created by Ruins mod version 16.8 Ingame Parser
# authoring Player: ST753M

weight=1
uniqueMinDistance=1000
spawnMinDistance=2000
embed_into_distance=-60
random_height_offset=-30,30
acceptable_target_blocks=
unacceptable_target_blocks=netherrack
dimensions=10,16,16
allowable_overhang=999
max_leveling=0
leveling_buffer=0
preserve_water=0
preserve_lava=0

biomesToSpawnIn=sky,void,the_end,the_sky

rule1=0,100,preserveBlock
rule2=0,100,minecraft:end_rod-0
rule3=0,100,minecraft:purpur_stairs-4
rule4=0,100,minecraft:purpur_stairs-5
rule5=0,100,minecraft:purpur_pillar-0
rule6=0,100,minecraft:purpur_stairs-6
rule7=0,100,minecraft:purpur_block-0
rule8=0,100,minecraft:purpur_stairs-7
rule9=0,100,quark:duskbound_block_stairs-4
rule10=0,100,quark:duskbound_block_stairs-6
rule11=0,100,quark:duskbound_block_stairs-7
rule12=0,100,quark:duskbound_block_stairs-5
rule13=0,100,quark:duskbound_block-0
rule14=0,100,quark:duskbound_block_stairs-2
rule15=0,100,quark:duskbound_block_stairs-3
rule16=0,100,quark:duskbound_block_stairs-0
rule17=0,100,quark:duskbound_block_slab-8
rule18=0,100,quark:duskbound_block_stairs-1
rule19=0,100,quark:duskbound_block_slab-0
rule20=0,100,minecraft:purpur_stairs-0
rule21=0,100,minecraft:purpur_stairs-2
rule22=0,100,minecraft:purpur_stairs-3
rule23=0,100,minecraft:purpur_stairs-1
rule24=0,100,minecraft:end_rod-1
rule25=0,100,ChestGenHook:chests/end_city_treasure:5-4

layer
1,1,1,1,1,1,1,1,1,1,1,1,1,1,1,1
1,1,1,1,1,1,1,1,1,1,1,1,1,1,1,1
1,1,1,1,1,1,1,1,1,1,1,1,1,1,1,1
1,1,1,2,1,1,1,1,1,1,1,1,2,1,1,1
1,1,1,1,1,1,1,1,1,1,1,1,1,1,1,1
1,1,1,1,1,1,1,1,1,1,1,1,1,1,1,1
1,1,1,1,1,1,1,1,1,1,1,1,1,1,1,1
1,1,1,1,1,1,1,3,1,1,1,1,1,1,1,1
1,1,1,1,1,1,1,1,4,1,1,1,1,1,1,1
1,1,1,1,1,1,1,1,1,1,1,1,1,1,1,1
1,1,1,1,1,1,1,1,1,1,1,1,1,1,1,1
1,1,1,1,1,1,1,1,1,1,1,1,1,1,1,1
1,1,1,2,1,1,1,1,1,1,1,1,2,1,1,1
1,1,1,1,1,1,1,1,1,1,1,1,1,1,1,1
1,1,1,1,1,1,1,1,1,1,1,1,1,1,1,1
1,1,1,1,1,1,1,1,1,1,1,1,1,1,1,1
endlayer

layer
1,1,1,1,1,1,1,1,1,1,1,1,1,1,1,1
1,1,1,1,1,1,1,1,1,1,1,1,1,1,1,1
1,1,1,1,1,1,1,1,1,1,1,1,1,1,1,1
1,1,1,5,1,1,1,1,1,1,1,1,5,1,1,1
1,1,1,1,1,1,1,1,1,1,1,1,1,1,1,1
1,1,1,1,1,1,1,1,1,1,1,1,1,1,1,1
1,1,1,1,1,1,1,1,1,1,1,1,1,1,1,1
1,1,1,1,1,1,1,7,6,1,1,1,1,1,1,1
1,1,1,1,1,1,1,8,7,1,1,1,1,1,1,1
1,1,1,1,1,1,1,1,1,1,1,1,1,1,1,1
1,1,1,1,1,1,1,1,1,1,1,1,1,1,1,1
1,1,1,1,1,1,1,1,1,1,1,1,1,1,1,1
1,1,1,5,1,1,1,1,1,1,1,1,5,1,1,1
1,1,1,1,1,1,1,1,1,1,1,1,1,1,1,1
1,1,1,1,1,1,1,1,1,1,1,1,1,1,1,1
1,1,1,1,1,1,1,1,1,1,1,1,1,1,1,1
endlayer

layer
1,1,1,1,1,1,1,1,1,1,1,1,1,1,1,1
1,1,1,1,1,1,1,1,1,1,1,1,1,1,1,1
1,1,1,9,1,1,1,1,1,1,1,1,9,1,1,1
1,1,11,5,1,1,1,1,1,1,1,1,5,10,1,1
1,1,1,1,1,1,1,1,1,1,1,1,1,1,1,1
1,1,1,1,1,1,1,1,1,1,1,1,1,1,1,1
1,1,1,1,1,1,1,3,1,1,1,1,1,1,1,1
1,1,1,1,1,1,1,7,7,6,1,1,1,1,1,1
1,1,1,1,1,1,8,7,7,0,1,1,1,1,1,1
1,1,1,1,1,1,1,1,4,1,1,1,1,1,1,1
1,1,1,1,1,1,1,1,1,1,1,1,1,1,1,1
1,1,1,1,1,1,1,1,1,1,1,1,1,1,1,1
1,1,11,5,1,1,1,1,1,1,1,1,5,10,1,1
1,1,1,12,1,1,1,1,1,1,1,1,12,1,1,1
1,1,1,1,1,1,1,1,1,1,1,1,1,1,1,1
1,1,1,1,1,1,1,1,1,1,1,1,1,1,1,1
endlayer

layer
1,1,1,1,1,1,11,13,13,10,1,1,1,1,1,1
1,1,1,1,11,13,13,12,12,13,13,10,1,1,1,1
1,1,1,13,13,10,1,1,1,1,11,13,13,1,1,1
1,1,13,5,1,1,1,1,1,1,1,1,5,13,1,1
1,9,13,1,1,1,1,1,1,1,1,1,1,13,9,1
1,13,12,1,1,1,1,1,1,1,1,1,1,12,13,1
9,13,1,1,1,1,1,7,3,1,1,1,1,1,13,9
13,10,1,1,1,1,8,7,7,7,1,1,1,1,11,13
13,10,1,1,1,1,7,7,7,6,1,1,1,1,11,13
12,13,1,1,1,1,1,4,7,1,1,1,1,1,13,12
1,13,9,1,1,1,1,1,1,1,1,1,1,9,13,1
1,12,13,1,1,1,1,1,1,1,1,1,1,13,12,1
1,1,13,5,1,1,1,1,1,1,1,1,5,13,1,1
1,1,1,13,13,10,1,1,1,1,11,13,13,1,1,1
1,1,1,1,11,13,13,9,9,13,13,10,1,1,1,1
1,1,1,1,1,1,11,13,13,10,1,1,1,1,1,1
endlayer

layer
1,1,1,1,1,1,15,13,13,14,1,1,1,1,1,1
1,1,1,1,15,13,13,13,13,13,13,14,1,1,1,1
1,1,1,16,13,14,1,12,12,1,15,13,16,1,1,1
1,1,15,5,1,1,1,17,17,1,1,1,5,14,1,1
1,16,13,1,1,1,1,1,1,1,1,1,1,13,16,1
1,13,18,1,1,1,1,1,1,1,1,1,1,18,13,1
16,13,1,1,1,1,8,7,7,6,1,1,1,1,13,16
13,13,10,17,1,1,7,7,7,7,1,1,17,11,13,13
13,13,10,17,1,1,7,7,7,7,1,1,17,11,13,13
18,13,1,1,1,1,4,7,7,4,1,1,1,1,13,18
1,13,16,1,1,1,1,1,1,1,1,1,1,16,13,1
1,18,13,1,1,1,1,1,1,1,1,1,1,13,18,1
1,1,15,5,1,1,1,17,17,1,1,1,5,14,1,1
1,1,1,18,13,14,1,9,9,1,15,13,18,1,1,1
1,1,1,1,15,13,13,13,13,13,13,14,1,1,1,1
1,1,1,1,1,1,15,13,13,14,1,1,1,1,1,1
endlayer

layer
1,1,1,1,1,1,1,1,1,1,1,1,1,1,1,1
1,1,1,1,1,1,1,1,1,1,1,1,1,1,1,1
1,1,1,1,1,1,1,19,19,1,1,1,1,1,1,1
1,1,1,5,1,1,1,16,16,1,1,1,5,1,1,1
1,1,1,1,1,1,1,13,13,1,1,1,1,1,1,1
1,1,1,1,1,1,1,13,13,1,1,1,1,1,1,1
1,1,1,1,1,1,5,7,7,5,1,1,1,1,1,1
1,1,19,15,13,13,7,7,7,7,13,13,14,19,1,1
1,1,19,15,13,13,7,7,7,7,13,13,14,19,1,1
1,1,1,1,1,1,5,7,7,5,1,1,1,1,1,1
1,1,1,1,1,1,1,13,13,1,1,1,1,1,1,1
1,1,1,1,1,1,1,13,13,1,1,1,1,1,1,1
1,1,1,5,1,1,1,18,18,1,1,1,5,1,1,1
1,1,1,1,1,1,1,19,19,1,1,1,0,1,1,1
1,1,1,1,1,1,1,1,1,1,1,1,1,1,1,1
1,1,1,1,1,1,1,1,1,1,1,1,1,1,1,1
endlayer

layer
1,1,1,1,1,1,1,1,1,1,1,1,1,1,1,1
1,1,1,1,1,1,1,1,1,1,1,1,1,1,1,1
1,1,1,1,1,1,1,1,1,1,1,1,1,1,1,1
1,1,1,5,1,1,1,1,1,1,1,1,5,1,1,1
1,1,1,1,1,1,1,1,1,1,1,1,1,1,1,1
1,1,1,1,1,1,1,1,1,1,1,1,1,1,1,1
1,1,1,1,1,1,5,20,20,5,1,1,1,1,1,1
1,1,1,1,1,1,22,7,7,21,1,1,1,1,1,1
1,1,1,1,1,1,22,7,7,21,1,1,1,1,1,1
1,1,1,1,1,1,5,23,23,5,1,1,1,1,1,1
1,1,1,1,1,1,1,1,1,1,1,1,1,1,1,1
1,1,1,1,1,1,1,1,1,1,1,1,1,1,1,1
1,1,1,5,1,1,1,1,1,1,1,1,5,1,1,1
1,1,1,1,1,1,1,1,1,1,1,1,0,1,1,1
1,1,1,1,1,1,1,1,1,1,1,1,1,1,1,1
1,1,1,1,1,1,1,1,1,1,1,1,1,1,1,1
endlayer

layer
1,1,1,1,1,1,1,1,1,1,1,1,1,1,1,1
1,1,1,1,1,1,1,1,1,1,1,1,1,1,1,1
1,1,1,1,1,1,1,1,1,1,1,1,1,1,1,1
1,1,1,24,1,1,1,1,1,1,1,1,24,1,1,1
1,1,1,1,1,1,1,1,1,1,1,1,1,1,1,1
1,1,1,1,1,1,1,1,1,1,1,1,1,1,1,1
1,1,1,1,1,1,5,0,0,5,1,1,1,1,1,1
1,1,1,1,1,1,0,25,0,0,1,1,1,1,1,1
1,1,1,1,1,1,0,0,0,0,1,1,1,1,1,1
1,1,1,1,1,1,5,0,0,5,1,1,1,1,1,1
1,1,1,1,1,1,1,1,1,1,1,1,1,1,1,1
1,1,1,1,1,1,1,1,1,1,1,1,1,1,1,1
1,1,1,24,1,1,1,1,1,1,1,1,24,1,1,1
1,1,1,1,1,1,1,1,1,1,1,1,0,1,1,1
1,1,1,1,1,1,1,1,1,1,1,1,1,1,1,1
1,1,1,1,1,1,1,1,1,1,1,1,1,1,1,1
endlayer

layer
1,1,1,1,1,1,1,1,1,1,1,1,1,1,1,1
1,1,1,1,1,1,1,1,1,1,1,1,1,1,1,1
1,1,1,1,1,1,1,1,1,1,1,1,1,1,1,1
1,1,1,1,1,1,1,1,1,1,1,1,1,1,1,1
1,1,1,1,1,1,1,1,1,1,1,1,1,1,1,1
1,1,1,1,1,1,1,1,1,1,1,1,1,1,1,1
1,1,1,1,1,1,5,0,0,5,1,1,1,1,1,1
1,1,1,1,1,1,0,0,0,0,1,1,1,1,1,1
1,1,1,1,1,1,0,0,0,0,1,1,1,1,1,1
1,1,1,1,1,1,5,0,0,5,1,1,1,1,1,1
1,1,1,1,1,1,1,1,1,1,1,1,1,1,1,1
1,1,1,1,1,1,1,1,1,1,1,1,1,1,1,1
1,1,1,1,1,1,1,1,1,1,1,1,1,1,1,1
1,1,1,1,1,1,1,1,1,1,1,1,1,1,1,1
1,1,1,1,1,1,1,1,1,1,1,1,1,1,1,1
1,1,1,1,1,1,1,1,1,1,1,1,1,1,1,1
endlayer

layer
1,1,1,1,1,1,1,1,1,1,1,1,1,1,1,1
1,1,1,1,1,1,1,1,1,1,1,1,1,1,1,1
1,1,1,1,1,1,1,1,1,1,1,1,1,1,1,1
1,1,1,1,1,1,1,1,1,1,1,1,1,1,1,1
1,1,1,1,1,1,1,1,1,1,1,1,1,1,1,1
1,1,1,1,1,1,19,19,19,19,1,1,1,1,1,1
1,1,1,1,1,19,13,13,13,13,19,1,1,1,1,1
1,1,1,1,1,19,13,0,0,13,19,1,1,1,1,1
1,1,1,1,1,19,13,0,0,13,19,1,1,1,1,1
1,1,1,1,1,19,13,13,13,13,19,1,1,1,1,1
1,1,1,1,1,1,19,19,19,19,1,1,1,1,1,1
1,1,1,1,1,1,1,1,1,1,1,1,1,1,1,1
1,1,1,1,1,1,1,1,1,1,1,1,1,1,1,1
1,1,1,1,1,1,1,1,1,1,1,1,1,1,1,1
1,1,1,1,1,1,1,1,1,1,1,1,1,1,1,1
1,1,1,1,1,1,1,1,1,1,1,1,1,1,1,1
endlayer

