
# Created by Ruins mod version 17.0 Ingame Parser
# authoring Player: ST753M

weight=1
uniqueMinDistance=1000
spawnMinDistance=1000
embed_into_distance=-30
random_height_offset=-20,20
acceptable_target_blocks=
unacceptable_target_blocks=flowing_water,water,flowing_lava,lava
dimensions=29,13,13
allowable_overhang=999
max_leveling=0
leveling_buffer=0
preserve_water=0
preserve_lava=0

biomesToSpawnIn=sky,end,the_end,void

rule1=0,100,preserveBlock
rule2=0,100,minecraft:purpur_stairs-6
rule3=0,100,minecraft:purpur_stairs-4
rule4=0,100,minecraft:purpur_stairs-7
rule5=0,100,minecraft:ladder-2
rule6=0,100,minecraft:purpur_stairs-5
rule7=0,100,minecraft:purpur_block-0
rule8=0,100,minecraft:purpur_stairs-1
rule9=0,100,minecraft:purpur_stairs-3
rule10=0,100,minecraft:purpur_stairs-2
rule11=0,100,minecraft:purpur_stairs-0
rule12=0,100,minecraft:purpur_pillar-0
rule13=0,100,minecraft:end_bricks-0
rule14=0,100,minecraft:purpur_slab-8
rule15=0,100,minecraft:stained_glass_pane-10
rule16=0,100,CommandBlock:RUINSTRIGGER /summon shulker ~ ~1 ~ {PersistenceRequired:1}:@-1
rule17=0,100,minecraft:purpur_pillar-8
rule18=0,100,ChestGenHook:chests/end_city_treasure:3-4
rule19=0,100,minecraft:purpur_slab-0

layer
1,1,1,1,1,1,1,1,1,1,1,1,1
1,1,1,1,1,1,1,1,1,1,1,1,1
1,1,1,1,1,1,1,1,1,1,1,1,1
1,1,1,1,1,1,1,1,1,1,1,1,1
1,1,1,1,1,1,1,1,1,1,1,1,1
1,1,1,1,1,1,1,1,1,1,1,1,1
1,1,1,1,1,1,1,1,1,1,1,1,1
1,1,1,1,1,1,1,1,1,1,1,1,1
1,1,1,1,1,1,1,1,1,1,1,1,1
1,1,1,1,1,1,1,1,1,1,1,1,1
1,1,1,1,1,1,1,1,1,1,1,1,1
1,1,1,1,1,1,1,1,1,1,1,1,1
1,1,1,1,1,1,1,1,1,1,1,1,1
endlayer

layer
1,1,1,1,1,1,1,1,1,1,1,1,1
1,1,1,1,1,1,1,1,1,1,1,1,1
1,1,1,1,1,1,1,1,1,1,1,1,1
1,1,1,1,1,1,1,1,1,1,1,1,1
1,1,1,1,1,1,1,1,1,1,1,1,1
1,1,1,1,1,4,3,2,1,1,1,1,1
1,1,1,1,1,4,5,2,1,1,1,1,1
1,1,1,1,1,4,6,6,1,1,1,1,1
1,1,1,1,1,1,1,1,1,1,1,1,1
1,1,1,1,1,1,1,1,1,1,1,1,1
1,1,1,1,1,1,1,1,1,1,1,1,1
1,1,1,1,1,1,1,1,1,1,1,1,1
1,1,1,1,1,1,1,1,1,1,1,1,1
endlayer

layer
1,1,1,1,1,1,1,1,1,1,1,1,1
1,1,1,1,1,1,1,1,1,1,1,1,1
1,1,1,1,1,1,1,1,1,1,1,1,1
1,1,1,1,1,1,1,1,1,1,1,1,1
1,1,1,1,3,3,3,3,2,1,1,1,1
1,1,1,1,4,7,7,7,2,1,1,1,1
1,1,1,1,4,7,5,7,2,1,1,1,1
1,1,1,1,4,7,7,7,2,1,1,1,1
1,1,1,1,6,6,6,6,6,1,1,1,1
1,1,1,1,1,1,1,1,1,1,1,1,1
1,1,1,1,1,1,1,1,1,1,1,1,1
1,1,1,1,1,1,1,1,1,1,1,1,1
1,1,1,1,1,1,1,1,1,1,1,1,1
endlayer

layer
1,1,1,1,1,1,1,1,1,1,1,1,1
1,1,1,1,1,1,1,1,1,1,1,1,1
1,1,1,1,1,1,1,1,1,1,1,1,1
1,1,1,3,3,3,3,3,3,2,1,1,1
1,1,1,4,7,7,7,7,7,2,1,1,1
1,1,1,4,7,7,7,7,7,2,1,1,1
1,1,1,4,7,7,5,7,7,2,1,1,1
1,1,1,4,7,7,7,7,7,2,1,1,1
1,1,1,4,7,7,7,7,7,2,1,1,1
1,1,1,4,6,6,6,6,6,2,1,1,1
1,1,1,1,1,1,1,1,1,1,1,1,1
1,1,1,1,1,1,1,1,1,1,1,1,1
1,1,1,1,1,1,1,1,1,1,1,1,1
endlayer

layer
1,1,1,1,1,1,1,1,1,1,1,1,1
1,1,1,1,1,1,1,1,1,1,1,1,1
1,1,3,3,3,3,3,3,3,3,3,1,1
1,1,4,7,7,7,7,7,7,7,2,1,1
1,1,4,7,7,7,7,7,7,7,2,1,1
1,1,4,7,7,8,8,8,7,7,2,1,1
1,1,4,7,7,10,0,9,7,7,2,1,1
1,1,4,7,7,11,11,9,7,7,2,1,1
1,1,4,7,7,7,7,7,7,7,2,1,1
1,1,4,7,7,7,7,7,7,7,2,1,1
1,1,4,6,6,6,6,6,6,6,6,1,1
1,1,1,1,1,1,1,1,1,1,1,1,1
1,1,1,1,1,1,1,1,1,1,1,1,1
endlayer

layer
1,1,1,1,1,1,1,1,1,1,1,1,1
1,1,1,1,1,1,1,1,1,1,1,1,1
1,1,0,0,0,0,0,0,0,0,0,1,1
1,1,0,12,13,13,13,13,13,12,0,1,1
1,1,0,13,0,0,0,0,0,13,0,1,1
1,1,0,13,0,0,0,0,14,13,0,1,1
1,1,0,13,0,0,0,0,0,13,0,1,1
1,1,0,13,0,0,0,0,0,13,0,1,1
1,1,0,13,0,0,0,0,0,13,0,1,1
1,1,0,12,13,13,13,13,13,12,0,1,1
1,1,0,0,0,0,0,0,0,0,0,1,1
1,1,1,1,1,1,1,1,1,1,1,1,1
1,1,1,1,1,1,1,1,1,1,1,1,1
endlayer

layer
1,1,1,1,1,1,1,1,1,1,1,1,1
1,1,1,1,1,1,1,1,1,1,1,1,1
1,1,0,0,0,0,0,0,0,0,0,1,1
1,1,0,12,13,15,13,15,13,12,0,1,1
1,1,0,13,0,0,0,0,0,13,0,1,1
1,1,0,15,0,0,0,0,0,15,0,1,1
1,1,0,13,0,0,0,0,14,13,0,1,1
1,1,0,15,0,0,0,0,0,15,0,1,1
1,1,0,13,0,0,0,0,0,13,0,1,1
1,1,0,12,13,15,13,15,13,12,0,1,1
1,1,0,0,0,0,0,0,0,0,0,1,1
1,1,1,1,1,1,1,1,1,1,1,1,1
1,1,1,1,1,1,1,1,1,1,1,1,1
endlayer

layer
1,1,1,1,1,1,1,1,1,1,1,1,1
1,1,1,1,1,1,1,1,1,1,1,1,1
1,1,0,0,0,0,0,0,0,0,0,1,1
1,1,0,12,13,15,13,15,13,12,0,1,1
1,1,0,13,0,0,0,0,0,13,0,1,1
1,1,0,15,0,0,0,0,0,15,0,1,1
1,1,0,13,0,0,0,0,0,13,0,1,1
1,1,0,15,0,0,0,0,14,15,0,1,1
1,1,0,13,0,0,0,0,0,13,0,1,1
1,1,0,12,13,15,13,15,13,12,0,1,1
1,1,0,0,0,0,0,0,0,0,0,1,1
1,1,1,1,1,1,1,1,1,1,1,1,1
1,1,1,1,1,1,1,1,1,1,1,1,1
endlayer

layer
1,1,1,1,1,1,1,1,1,1,1,1,1
1,4,3,3,3,3,3,3,3,3,3,2,1
1,4,7,7,7,7,7,7,7,7,7,2,1
1,4,7,7,7,7,7,7,7,7,7,2,1
1,4,7,7,7,6,6,6,0,7,7,2,1
1,4,7,7,2,0,0,0,0,7,7,2,1
1,4,7,7,2,0,0,0,0,7,7,2,1
1,4,7,7,2,0,0,0,0,7,7,2,1
1,4,7,7,7,3,3,3,14,7,7,2,1
1,4,7,7,7,7,7,7,7,7,7,2,1
1,4,7,7,7,7,7,7,7,7,7,2,1
1,4,6,6,6,6,6,6,6,6,6,6,1
1,1,1,1,1,1,1,1,1,1,1,1,1
endlayer

layer
1,1,1,1,1,1,1,1,1,1,1,1,1
1,0,0,0,0,0,0,0,0,0,0,0,1
1,0,12,13,13,13,13,13,13,13,12,0,1
1,0,13,0,0,0,0,0,0,0,13,0,1
1,0,13,0,0,16,0,0,0,0,13,0,1
1,0,13,0,0,0,0,0,0,0,13,0,1
1,0,13,14,0,0,0,0,0,0,13,0,1
1,0,13,0,0,0,0,0,0,0,13,0,1
1,0,13,0,0,0,0,0,0,0,13,0,1
1,0,13,0,0,0,0,0,0,0,13,0,1
1,0,12,13,13,13,13,13,13,13,12,0,1
1,0,0,0,0,0,0,0,0,0,0,0,1
1,1,1,1,1,1,1,1,1,1,1,1,1
endlayer

layer
1,1,1,1,1,1,1,1,1,1,1,1,1
1,0,0,0,0,0,0,0,0,0,0,0,1
1,0,12,13,15,13,15,13,15,13,12,0,1
1,0,13,0,0,0,0,0,0,0,13,0,1
1,0,15,0,0,0,0,0,0,0,15,0,1
1,0,13,14,0,0,0,0,0,0,13,0,1
1,0,15,0,0,0,0,0,0,0,15,0,1
1,0,13,0,0,0,0,0,0,0,13,0,1
1,0,15,0,0,0,0,0,0,0,15,0,1
1,0,13,0,0,0,0,0,0,0,13,0,1
1,0,12,13,15,13,15,13,15,13,12,0,1
1,0,0,0,0,0,0,0,0,0,0,0,1
1,1,1,1,1,1,1,1,1,1,1,1,1
endlayer

layer
1,1,1,1,1,1,1,1,1,1,1,1,1
1,0,0,0,0,0,0,0,0,0,0,0,1
1,0,12,13,15,13,15,13,15,13,12,0,1
1,0,13,0,0,0,0,0,0,0,13,0,1
1,0,15,14,0,0,0,0,0,0,15,0,1
1,0,13,0,0,0,0,0,0,0,13,0,1
1,0,15,0,0,0,0,0,0,0,15,0,1
1,0,13,0,0,0,0,0,0,0,13,0,1
1,0,15,0,0,0,0,0,0,0,15,0,1
1,0,13,0,0,0,0,0,0,0,13,0,1
1,0,12,13,15,13,15,13,15,13,12,0,1
1,0,0,0,0,0,0,0,0,0,0,0,1
1,1,1,1,1,1,1,1,1,1,1,1,1
endlayer

layer
3,3,3,3,3,3,3,3,3,3,3,3,2
4,7,7,7,7,7,7,7,7,7,7,7,2
4,7,7,7,7,7,7,7,7,7,7,7,2
4,7,7,14,7,7,7,7,7,7,7,7,2
4,7,7,0,7,6,6,6,7,7,7,7,2
4,7,7,0,2,0,0,0,4,7,7,7,2
4,7,7,0,2,0,0,0,4,7,7,7,2
4,7,7,7,2,0,0,0,4,7,7,7,2
4,7,7,7,7,3,3,3,7,7,7,7,2
4,7,7,7,7,7,7,7,7,7,7,7,2
4,7,7,7,7,7,7,7,7,7,7,7,2
4,7,7,7,7,7,7,7,7,7,7,7,2
6,6,6,6,6,6,6,6,6,6,6,6,6
endlayer

layer
0,0,0,0,0,0,0,0,0,0,0,0,0
0,12,13,13,13,13,13,13,13,13,13,12,0
0,13,0,0,0,0,0,0,0,0,0,13,0
0,13,0,0,0,0,0,0,0,0,0,13,0
0,13,0,0,0,0,0,0,0,0,0,13,0
0,13,0,0,0,0,0,0,0,14,0,13,0
0,13,0,0,0,0,0,0,0,0,0,13,0
0,13,0,0,0,0,0,0,0,0,0,13,0
0,13,0,0,0,0,0,0,0,0,0,13,0
0,13,0,0,0,0,0,0,0,0,0,13,0
0,13,0,0,0,0,0,0,0,0,0,13,0
0,12,13,13,13,13,13,13,13,13,13,12,0
0,0,0,0,0,0,0,0,0,0,0,0,0
endlayer

layer
0,0,0,0,0,0,0,0,0,0,0,0,0
0,12,13,15,13,15,13,15,13,15,13,12,0
0,13,0,0,0,0,0,0,0,0,0,13,0
0,15,0,0,0,0,0,0,0,0,0,15,0
0,13,0,0,0,0,0,0,0,0,0,13,0
0,15,0,0,0,0,0,0,0,0,0,15,0
0,13,0,0,0,0,0,0,0,14,0,13,0
0,15,0,0,0,0,0,0,0,0,0,15,0
0,13,0,0,0,0,0,0,0,0,0,13,0
0,15,0,0,0,0,0,0,0,0,0,15,0
0,13,0,0,0,0,0,0,0,0,0,13,0
0,12,13,15,13,15,13,15,13,15,13,12,0
0,0,0,0,0,0,0,0,0,0,0,0,0
endlayer

layer
0,0,0,0,0,0,0,0,0,0,0,0,0
0,12,13,15,13,15,13,15,13,15,13,12,0
0,13,0,0,0,0,0,0,0,0,0,13,0
0,15,0,0,0,0,0,0,0,0,0,15,0
0,13,0,0,0,0,0,0,0,0,0,13,0
0,15,0,0,0,0,0,0,0,0,0,15,0
0,13,0,0,0,0,0,0,0,0,0,13,0
0,15,0,0,0,0,0,0,0,14,0,15,0
0,13,0,0,0,0,0,0,0,0,0,13,0
0,15,0,0,0,0,0,0,0,0,0,15,0
0,13,0,0,0,0,0,0,0,0,0,13,0
0,12,13,15,13,15,13,15,13,15,13,12,0
0,0,0,0,0,0,0,0,0,0,0,0,0
endlayer

layer
11,11,11,11,11,11,11,11,11,11,11,11,10
9,7,7,7,7,7,7,7,7,7,7,7,10
9,7,7,7,7,7,7,7,7,7,7,7,10
9,7,7,7,7,7,7,7,7,7,7,7,10
9,7,7,7,7,6,6,6,7,7,7,7,10
9,7,7,7,2,0,0,0,4,0,7,7,10
9,7,7,7,2,0,0,0,4,0,7,7,10
9,7,7,7,2,0,0,0,4,0,7,7,10
9,7,7,7,7,3,3,3,7,14,7,7,10
9,7,7,7,7,7,7,7,7,7,7,7,10
9,7,7,7,7,7,7,7,7,7,7,7,10
9,7,7,7,7,7,7,7,7,7,7,7,10
9,8,8,8,8,8,8,8,8,8,8,8,10
endlayer

layer
1,1,1,1,1,1,1,1,1,1,1,1,1
1,1,1,1,1,1,1,1,1,1,1,1,1
1,1,12,13,13,13,13,13,13,13,12,1,1
1,1,13,0,0,0,0,0,0,0,13,1,1
1,1,13,0,0,0,0,0,0,0,13,1,1
1,1,13,0,0,0,0,0,0,0,13,1,1
1,1,13,0,0,0,0,0,0,0,13,1,1
1,1,13,0,14,0,0,0,0,0,13,1,1
1,1,13,0,0,0,0,0,0,0,13,1,1
1,1,13,0,0,0,0,0,0,0,13,1,1
1,1,17,13,13,13,13,13,13,13,12,1,1
1,1,1,1,1,1,1,1,1,1,1,1,1
1,1,1,1,1,1,1,1,1,1,1,1,1
endlayer

layer
1,1,1,1,1,1,1,1,1,1,1,1,1
1,1,1,1,1,1,1,1,1,1,1,1,1
1,1,12,13,15,13,15,13,15,13,12,1,1
1,1,13,0,0,0,0,0,0,0,13,1,1
1,1,15,0,0,0,0,0,0,0,15,1,1
1,1,13,0,0,0,0,0,0,0,13,1,1
1,1,15,0,14,0,0,0,0,0,15,1,1
1,1,13,0,0,0,0,0,0,0,13,1,1
1,1,15,0,0,0,0,0,0,0,15,1,1
1,1,13,0,0,0,0,0,0,0,13,1,1
1,1,12,13,15,13,15,13,15,13,12,1,1
1,1,1,1,1,1,1,1,1,1,1,1,1
1,1,1,1,1,1,1,1,1,1,1,1,1
endlayer

layer
1,1,1,1,1,1,1,1,1,1,1,1,1
1,1,1,1,1,1,1,1,1,1,1,1,1
1,1,12,13,15,13,15,13,15,13,12,1,1
1,1,13,0,0,0,0,0,0,0,13,1,1
1,1,15,0,0,0,0,0,0,0,15,1,1
1,1,13,0,14,0,0,0,0,0,13,1,1
1,1,15,0,0,0,0,0,0,0,15,1,1
1,1,13,0,0,0,0,0,0,0,13,1,1
1,1,15,0,0,0,0,0,0,0,15,1,1
1,1,13,0,0,0,0,0,0,0,13,1,1
1,1,12,13,15,13,15,13,15,13,12,1,1
1,1,1,1,1,1,1,1,1,1,1,1,1
1,1,1,1,1,1,1,1,1,1,1,1,1
endlayer

layer
1,1,1,1,1,1,1,1,1,1,1,1,1
1,11,11,11,11,11,11,11,11,11,11,10,1
1,9,7,7,7,7,7,7,7,7,7,10,1
1,9,7,7,7,7,7,7,7,7,7,10,1
1,9,7,7,14,6,6,6,7,7,7,10,1
1,9,7,7,0,0,0,0,4,7,7,10,1
1,9,7,7,0,0,0,0,4,7,7,10,1
1,9,7,7,0,0,0,0,4,7,7,10,1
1,9,7,7,0,3,3,3,7,7,7,10,1
1,9,7,7,7,7,7,7,7,7,7,10,1
1,9,7,7,7,7,7,7,7,7,7,10,1
1,9,8,8,8,8,8,8,8,8,8,10,1
1,1,1,1,1,1,1,1,1,1,1,1,1
endlayer

layer
1,1,1,1,1,1,1,1,1,1,1,1,1
1,1,1,1,1,1,1,1,1,1,1,1,1
1,1,1,1,1,1,1,1,1,1,1,1,1
1,1,1,12,13,13,13,13,13,12,1,1,1
1,1,1,13,0,0,0,0,0,13,1,1,1
1,1,1,13,0,0,0,0,0,13,1,1,1
1,1,1,13,0,0,0,0,0,13,1,1,1
1,1,1,13,0,0,0,0,0,13,1,1,1
1,1,1,13,0,0,0,0,18,13,1,1,1
1,1,1,12,13,13,13,13,13,12,1,1,1
1,1,1,1,1,1,1,1,1,1,1,1,1
1,1,1,1,1,1,1,1,1,1,1,1,1
1,1,1,1,1,1,1,1,1,1,1,1,1
endlayer

layer
1,1,1,1,1,1,1,1,1,1,1,1,1
1,1,1,1,1,1,1,1,1,1,1,1,1
1,1,1,1,1,1,1,1,1,1,1,1,1
1,1,1,12,13,15,13,15,13,12,1,1,1
1,1,1,13,0,0,0,0,0,13,1,1,1
1,1,1,15,0,0,0,0,0,15,1,1,1
1,1,1,13,0,0,0,0,0,13,1,1,1
1,1,1,15,0,0,0,0,0,15,1,1,1
1,1,1,13,0,0,0,0,0,13,1,1,1
1,1,1,12,13,15,13,15,13,12,1,1,1
1,1,1,1,1,1,1,1,1,1,1,1,1
1,1,1,1,1,1,1,1,1,1,1,1,1
1,1,1,1,1,1,1,1,1,1,1,1,1
endlayer

layer
1,1,1,1,1,1,1,1,1,1,1,1,1
1,1,1,1,1,1,1,1,1,1,1,1,1
1,1,1,1,1,1,1,1,1,1,1,1,1
1,1,1,12,13,15,13,15,13,12,1,1,1
1,1,1,13,0,0,0,0,0,13,1,1,1
1,1,1,15,0,0,0,0,0,15,1,1,1
1,1,1,13,0,0,0,0,0,13,1,1,1
1,1,1,15,0,0,0,0,0,15,1,1,1
1,1,1,13,0,0,0,0,0,13,1,1,1
1,1,1,12,13,15,13,15,13,12,1,1,1
1,1,1,1,1,1,1,1,1,1,1,1,1
1,1,1,1,1,1,1,1,1,1,1,1,1
1,1,1,1,1,1,1,1,1,1,1,1,1
endlayer

layer
1,1,1,1,1,1,1,1,1,1,1,1,1
1,1,1,1,1,1,1,1,1,1,1,1,1
1,1,11,11,11,11,11,11,11,11,10,1,1
1,1,9,7,7,7,7,7,7,7,10,1,1
1,1,9,7,2,6,6,6,6,7,10,1,1
1,1,9,7,2,0,0,0,4,7,10,1,1
1,1,9,7,2,0,0,0,4,7,10,1,1
1,1,9,7,2,0,0,0,4,7,10,1,1
1,1,9,7,3,3,3,3,3,7,10,1,1
1,1,9,7,7,7,7,7,7,7,10,1,1
1,1,8,8,8,8,8,8,8,8,8,1,1
1,1,1,1,1,1,1,1,1,1,1,1,1
1,1,1,1,1,1,1,1,1,1,1,1,1
endlayer

layer
1,1,1,1,1,1,1,1,1,1,1,1,1
1,1,1,1,1,1,1,1,1,1,1,1,1
1,1,1,1,1,1,1,1,1,1,1,1,1
1,1,1,11,11,11,11,11,11,10,1,1,1
1,1,1,9,7,7,7,7,7,10,1,1,1
1,1,1,9,7,2,6,6,7,10,1,1,1
1,1,1,9,7,2,0,4,7,10,1,1,1
1,1,1,9,7,3,3,3,7,10,1,1,1
1,1,1,9,7,7,7,7,7,10,1,1,1
1,1,1,9,8,8,8,8,8,8,1,1,1
1,1,1,1,1,1,1,1,1,1,1,1,1
1,1,1,1,1,1,1,1,1,1,1,1,1
1,1,1,1,1,1,1,1,1,1,1,1,1
endlayer

layer
1,1,1,1,1,1,1,1,1,1,1,1,1
1,1,1,1,1,1,1,1,1,1,1,1,1
1,1,1,1,1,1,1,1,1,1,1,1,1
1,1,1,1,1,1,1,1,1,1,1,1,1
1,1,1,1,9,11,11,11,10,1,1,1,1
1,1,1,1,9,7,7,7,10,1,1,1,1
1,1,1,1,9,7,12,7,10,1,1,1,1
1,1,1,1,9,7,7,7,10,1,1,1,1
1,1,1,1,9,8,8,8,8,1,1,1,1
1,1,1,1,1,1,1,1,1,1,1,1,1
1,1,1,1,1,1,1,1,1,1,1,1,1
1,1,1,1,1,1,1,1,1,1,1,1,1
1,1,1,1,1,1,1,1,1,1,1,1,1
endlayer

layer
1,1,1,1,1,1,1,1,1,1,1,1,1
1,1,1,1,1,1,1,1,1,1,1,1,1
1,1,1,1,1,1,1,1,1,1,1,1,1
1,1,1,1,1,1,1,1,1,1,1,1,1
1,1,1,1,1,1,1,1,1,1,1,1,1
1,1,1,1,1,11,11,10,1,1,1,1,1
1,1,1,1,1,9,7,10,1,1,1,1,1
1,1,1,1,1,8,8,10,1,1,1,1,1
1,1,1,1,1,1,1,1,1,1,1,1,1
1,1,1,1,1,1,1,1,1,1,1,1,1
1,1,1,1,1,1,1,1,1,1,1,1,1
1,1,1,1,1,1,1,1,1,1,1,1,1
1,1,1,1,1,1,1,1,1,1,1,1,1
endlayer

layer
1,1,1,1,1,1,1,1,1,1,1,1,1
1,1,1,1,1,1,1,1,1,1,1,1,1
1,1,1,1,1,1,1,1,1,1,1,1,1
1,1,1,1,1,1,1,1,1,1,1,1,1
1,1,1,1,1,1,1,1,1,1,1,1,1
1,1,1,1,1,1,1,1,1,1,1,1,1
1,1,1,1,1,1,19,1,1,1,1,1,1
1,1,1,1,1,1,1,1,1,1,1,1,1
1,1,1,1,1,1,1,1,1,1,1,1,1
1,1,1,1,1,1,1,1,1,1,1,1,1
1,1,1,1,1,1,1,1,1,1,1,1,1
1,1,1,1,1,1,1,1,1,1,1,1,1
1,1,1,1,1,1,1,1,1,1,1,1,1
endlayer

