
# Created by Ruins mod version 17.1 Ingame Parser
# authoring Player: ST753M

weight=1
spawnMinDistance=800
embed_into_distance=10
acceptable_target_blocks=endstone,end_stone
unacceptable_target_blocks=flowing_water,water,flowing_lava,lava
dimensions=11,26,27
allowable_overhang=999
max_leveling=0
leveling_buffer=0
preserve_water=0
preserve_lava=0

biomesToSpawnIn=sky,void

=0,100,air
rule1=0,100,preserveBlock
rule2=0,100,biomesoplenty:grass-0
rule3=0,100,minecraft:end_stone-0
rule4=0,100,biomesoplenty:plant_1-1,biomesoplenty:flower_0-10,biomesoplenty:plant_1-1,air
rule5=0,100,biomesoplenty:terrarium-15
rule6=0,100,biomesoplenty:crystal-0
rule7=0,100,biomesoplenty:biome_block-0
rule8=0,100,biomesoplenty:plant_1-1,biomesoplenty:flower_0-10,biomesoplenty:plant_1-1,air,air,air

layer
1,1,1,1,1,1,1,1,1,1,1,1,1,1,1,1,1,1,1,1,1,1,1,1,1,1,1
1,1,1,1,1,1,1,1,1,1,1,1,1,1,1,1,1,1,1,1,1,1,1,1,1,1,1
1,1,1,1,1,1,1,1,1,1,1,1,1,1,1,1,1,1,1,1,1,1,1,1,1,1,1
1,1,1,1,1,1,1,1,1,1,1,1,1,1,1,1,1,1,1,1,1,1,1,1,1,1,1
1,1,1,1,1,1,1,1,1,1,1,1,1,1,1,1,1,1,1,1,1,1,1,1,1,1,1
1,1,1,1,1,1,1,1,1,1,1,1,1,1,1,1,1,1,1,1,1,1,1,1,1,1,1
1,1,1,1,1,1,1,1,1,1,1,1,1,3,3,2,1,1,1,1,1,1,1,1,1,1,1
1,1,1,1,1,1,1,1,1,1,1,1,1,3,3,2,2,1,1,1,1,1,1,1,1,1,1
1,1,1,1,1,1,1,1,1,1,1,3,3,3,3,2,2,1,1,1,1,1,1,1,1,1,1
1,1,1,1,1,1,1,1,1,1,3,3,3,3,2,2,2,2,1,1,1,1,1,1,1,1,1
1,1,1,1,1,1,1,1,1,1,3,2,2,2,2,2,2,2,2,1,1,1,1,1,1,1,1
1,1,1,1,1,1,1,1,1,3,3,2,2,2,2,2,2,2,2,1,1,1,1,1,1,1,1
1,1,1,1,1,1,1,1,1,3,2,2,2,2,2,2,2,2,1,1,1,1,1,1,1,1,1
1,1,1,1,1,1,1,1,1,2,2,2,2,2,2,2,2,2,1,1,1,1,1,1,1,1,1
1,1,1,1,1,1,1,1,1,2,2,2,2,2,2,2,2,1,1,1,1,1,1,1,1,1,1
1,1,1,1,1,1,1,1,1,1,2,2,2,2,2,2,2,1,1,1,1,1,1,1,1,1,1
1,1,1,1,1,1,1,1,1,1,1,2,2,2,2,2,1,1,1,1,1,1,1,1,1,1,1
1,1,1,1,1,1,1,1,1,1,1,1,2,2,2,1,1,1,1,1,1,1,1,1,1,1,1
1,1,1,1,1,1,1,1,1,1,1,1,1,1,1,1,1,1,1,1,1,1,1,1,1,1,1
1,1,1,1,1,1,1,1,1,1,1,1,1,1,1,1,1,1,1,1,1,1,1,1,1,1,1
1,1,1,1,1,1,1,1,1,1,1,1,1,1,1,1,1,1,1,1,1,1,1,1,1,1,1
1,1,1,1,1,1,1,1,1,1,1,1,1,1,1,1,1,1,1,1,1,1,1,1,1,1,1
1,1,1,1,1,1,1,1,1,1,1,1,1,1,1,1,1,1,1,1,1,1,1,1,1,1,1
1,1,1,1,1,1,1,1,1,1,1,1,1,1,1,1,1,1,1,1,1,1,1,1,1,1,1
1,1,1,1,1,1,1,1,1,1,1,1,1,1,1,1,1,1,1,1,1,1,1,1,1,1,1
1,1,1,1,1,1,1,1,1,1,1,1,1,1,1,1,1,1,1,1,1,1,1,1,1,1,1
endlayer

layer
1,1,1,1,1,1,1,1,1,1,1,1,1,1,1,1,1,1,1,1,1,1,1,1,1,1,1
1,1,1,1,1,1,1,1,1,1,1,1,1,1,1,1,1,1,1,1,1,1,1,1,1,1,1
1,1,1,1,1,1,1,1,1,1,1,1,1,1,1,1,1,1,1,1,1,1,1,1,1,1,1
1,1,1,1,1,1,1,1,1,1,1,1,1,1,1,1,1,1,1,1,1,1,1,1,1,1,1
1,1,1,1,1,1,1,1,1,1,1,1,1,1,1,1,1,1,1,1,1,1,1,1,1,1,1
1,1,1,1,1,1,1,1,1,1,1,1,1,3,3,3,1,1,1,1,1,1,1,1,1,1,1
1,1,1,1,1,1,1,1,1,1,1,1,3,3,2,4,2,1,1,1,1,1,1,1,1,1,1
1,1,1,1,1,1,1,1,1,1,1,3,3,3,2,0,0,2,1,1,1,1,1,1,1,1,1
1,1,1,1,1,1,1,1,1,1,3,3,3,2,2,0,0,2,1,1,1,1,1,1,1,1,1
1,1,1,1,1,1,1,1,1,3,2,3,2,2,4,0,0,4,2,1,1,1,1,1,1,1,1
1,1,1,1,1,1,1,1,2,2,2,4,0,4,4,0,0,0,4,3,1,1,1,1,1,1,1
1,1,1,1,1,1,1,2,2,2,2,0,0,0,0,0,0,0,4,3,1,1,1,1,1,1,1
1,1,1,1,1,1,2,2,2,2,4,0,0,0,4,0,4,4,2,1,1,1,1,1,1,1,1
1,1,1,1,1,2,2,2,2,4,4,4,0,4,0,0,0,0,3,1,1,1,1,1,1,1,1
1,1,1,1,1,3,2,2,2,4,4,4,4,0,0,0,0,2,1,1,1,1,1,1,1,1,1
1,1,1,1,1,3,2,2,2,2,0,0,0,0,4,4,4,2,1,1,1,1,1,1,1,1,1
1,1,1,1,1,3,2,2,2,2,2,0,0,4,0,4,2,1,1,1,1,1,1,1,1,1,1
1,1,1,1,1,1,1,2,2,2,2,2,4,4,4,2,1,1,1,1,1,1,1,1,1,1,1
1,1,1,1,1,1,1,1,1,2,2,2,2,3,3,1,1,1,1,1,1,1,1,1,1,1,1
1,1,1,1,1,1,1,1,1,1,2,2,2,1,1,1,1,1,1,1,1,1,1,1,1,1,1
1,1,1,1,1,1,1,1,1,1,1,1,1,1,1,1,1,1,1,1,1,1,1,1,1,1,1
1,1,1,1,1,1,1,1,1,1,1,1,1,1,1,1,1,1,1,1,1,1,1,1,1,1,1
1,1,1,1,1,1,1,1,1,1,1,1,1,1,1,1,1,1,1,1,1,1,1,1,1,1,1
1,1,1,1,1,1,1,1,1,1,1,1,1,1,1,1,1,1,1,1,1,1,1,1,1,1,1
1,1,1,1,1,1,1,1,1,1,1,1,1,1,1,1,1,1,1,1,1,1,1,1,1,1,1
1,1,1,1,1,1,1,1,1,1,1,1,1,1,1,1,1,1,1,1,1,1,1,1,1,1,1
endlayer

layer
1,1,1,1,1,1,1,1,1,1,1,1,1,1,1,1,1,1,1,1,1,1,1,1,1,1,1
1,1,1,1,1,1,1,1,1,1,1,1,1,1,1,1,1,1,1,1,1,1,1,1,1,1,1
1,1,1,1,1,1,1,1,1,1,1,1,1,1,1,1,1,1,1,1,1,1,1,1,1,1,1
1,1,1,1,1,1,1,1,1,1,1,1,1,1,1,1,1,1,1,1,1,1,1,1,1,1,1
1,1,1,1,1,1,1,1,1,1,1,1,1,1,1,1,1,1,1,1,1,1,1,1,1,1,1
1,1,1,1,1,1,1,1,1,1,1,1,1,3,2,2,2,1,1,1,1,1,1,1,1,1,1
1,1,1,1,1,1,1,1,1,1,1,1,3,2,0,0,4,2,1,1,1,1,1,1,1,1,1
1,1,1,1,1,1,1,1,1,1,3,3,3,2,0,0,0,4,3,1,1,1,1,1,1,1,1
1,1,1,1,1,1,1,2,2,2,2,3,2,4,0,0,0,4,2,1,1,1,1,1,1,1,1
1,1,1,1,1,1,2,2,2,2,4,3,4,4,0,0,0,0,4,3,1,1,1,1,1,1,1
1,1,1,1,1,2,2,2,4,4,4,0,0,0,0,0,0,0,0,2,1,1,1,1,1,1,1
1,1,1,1,2,2,2,0,4,0,0,0,0,0,0,0,0,0,0,2,1,1,1,1,1,1,1
1,1,1,1,2,2,4,4,4,0,0,0,0,0,0,0,0,0,4,2,1,1,1,1,1,1,1
1,1,1,3,2,4,4,4,0,0,0,0,0,0,0,0,0,0,2,1,1,1,1,1,1,1,1
1,1,1,3,2,2,4,0,0,0,0,0,0,0,0,0,0,4,2,1,1,1,1,1,1,1,1
1,1,1,1,3,2,4,0,4,0,0,0,0,0,0,0,0,4,3,1,1,1,1,1,1,1,1
1,1,1,1,3,2,4,4,4,0,4,0,0,0,0,0,4,3,1,1,1,1,1,1,1,1,1
1,1,1,1,3,2,2,4,4,4,0,0,0,0,0,4,2,1,1,1,1,1,1,1,1,1,1
1,1,1,1,1,1,2,2,2,4,4,0,4,2,2,2,1,1,1,1,1,1,1,1,1,1,1
1,1,1,1,1,1,1,1,2,2,4,4,4,2,1,1,1,1,1,1,1,1,1,1,1,1,1
1,1,1,1,1,1,1,1,1,2,2,2,3,1,1,1,1,1,1,1,1,1,1,1,1,1,1
1,1,1,1,1,1,1,1,1,1,1,1,1,1,1,1,1,1,1,1,1,1,1,1,1,1,1
1,1,1,1,1,1,1,1,1,1,1,1,1,1,1,1,1,1,1,1,1,1,1,1,1,1,1
1,1,1,1,1,1,1,1,1,1,1,1,1,1,1,1,1,1,1,1,1,1,1,1,1,1,1
1,1,1,1,1,1,1,1,1,1,1,1,1,1,1,1,1,1,1,1,1,1,1,1,1,1,1
1,1,1,1,1,1,1,1,1,1,1,1,1,1,1,1,1,1,1,1,1,1,1,1,1,1,1
endlayer

layer
1,1,1,1,1,1,1,1,1,1,1,1,1,1,1,1,1,1,1,1,1,1,1,1,1,1,1
1,1,1,1,1,1,1,1,1,1,1,1,1,1,1,1,1,1,1,1,1,1,1,1,1,1,1
1,1,1,1,1,1,1,1,1,1,1,1,1,1,1,1,1,1,1,1,1,1,1,1,1,1,1
1,1,1,1,1,1,1,1,1,1,1,1,1,1,1,1,1,1,1,1,1,1,1,1,1,1,1
1,1,1,1,1,1,1,1,1,1,1,1,1,1,3,3,3,1,1,1,1,1,1,1,1,1,1
1,1,1,1,1,1,1,1,1,1,1,1,3,2,4,4,4,3,1,1,1,1,1,1,1,1,1
1,1,1,1,1,1,1,1,1,1,3,3,2,0,0,0,0,4,3,1,1,1,1,1,1,1,1
1,1,1,1,1,1,2,2,2,3,3,3,2,0,0,0,0,0,3,1,1,1,1,1,1,1,1
1,1,1,1,1,2,2,4,4,4,4,3,4,0,0,0,0,0,4,2,1,1,1,1,1,1,1
1,1,1,1,2,2,4,4,4,4,0,3,0,0,0,0,0,0,0,2,3,1,1,1,1,1,1
1,1,1,2,2,4,4,4,0,0,0,0,0,0,0,0,0,0,0,4,3,1,1,1,1,1,1
1,1,1,2,4,4,4,0,0,0,0,0,0,0,0,0,0,0,0,5,3,1,1,1,1,1,1
1,1,1,2,4,4,0,0,0,0,0,0,0,0,0,0,0,0,0,4,3,1,1,1,1,1,1
1,1,1,2,4,0,0,0,0,0,0,0,0,0,0,0,0,0,4,2,1,1,1,1,1,1,1
1,1,1,2,4,4,0,0,0,0,0,0,0,0,0,0,0,0,4,3,1,1,1,1,1,1,1
1,1,1,2,2,4,0,0,0,0,0,0,0,0,0,0,0,0,3,1,1,1,1,1,1,1,1
1,1,1,3,2,4,0,0,0,0,0,0,0,0,0,0,0,2,1,1,1,1,1,1,1,1,1
1,1,1,1,3,4,4,0,0,0,0,0,0,0,0,0,4,3,1,1,1,1,1,1,1,1,1
1,1,1,1,3,2,4,4,4,0,0,0,0,4,4,4,3,1,1,1,1,1,1,1,1,1,1
1,1,1,1,1,3,2,2,4,4,0,0,0,4,2,3,1,1,1,1,1,1,1,1,1,1,1
1,1,1,1,1,1,1,3,2,4,4,5,3,3,1,1,1,1,1,1,1,1,1,1,1,1,1
1,1,1,1,1,1,1,1,1,3,3,3,1,1,1,1,1,1,1,1,1,1,1,1,1,1,1
1,1,1,1,1,1,1,1,1,1,1,1,1,1,1,1,1,1,1,1,1,1,1,1,1,1,1
1,1,1,1,1,1,1,1,1,1,1,1,1,1,1,1,1,1,1,1,1,1,1,1,1,1,1
1,1,1,1,1,1,1,1,1,1,1,1,1,1,1,1,1,1,1,1,1,1,1,1,1,1,1
1,1,1,1,1,1,1,1,1,1,1,1,1,1,1,1,1,1,1,1,1,1,1,1,1,1,1
endlayer

layer
1,1,1,1,1,1,1,1,1,1,1,1,1,1,1,1,1,1,1,1,1,1,1,1,1,1,1
1,1,1,1,1,1,1,1,1,1,1,1,1,1,1,1,1,1,1,1,1,1,1,1,1,1,1
1,1,1,1,1,1,1,1,1,1,1,1,1,1,1,1,1,1,1,1,1,1,1,1,1,1,1
1,1,1,1,1,1,1,1,1,1,1,1,1,1,1,1,1,1,1,1,1,1,1,1,1,1,1
1,1,1,1,1,1,1,1,1,1,1,1,1,3,3,3,2,1,1,1,1,1,1,1,1,1,1
1,1,1,1,1,1,1,1,1,3,3,3,3,4,0,0,0,3,1,1,1,1,1,1,1,1,1
1,1,1,1,1,3,3,3,3,3,3,2,0,0,0,0,0,0,3,1,1,1,1,1,1,1,1
1,1,1,1,3,2,4,4,5,3,3,2,0,0,0,0,0,0,3,3,1,1,1,1,1,1,1
1,1,1,3,2,4,4,0,0,0,0,3,0,0,0,0,0,0,0,4,3,1,1,1,1,1,1
1,1,3,2,4,4,0,0,0,0,0,3,0,0,0,0,0,0,0,4,3,1,1,1,1,1,1
1,1,3,4,4,0,0,0,0,0,0,0,0,0,0,0,0,0,0,0,3,1,1,1,1,1,1
1,1,2,4,0,0,0,0,0,0,0,0,0,0,0,0,0,0,0,0,3,1,1,1,1,1,1
1,1,2,4,0,0,0,0,0,0,0,0,0,0,0,0,0,0,0,0,3,1,1,1,1,1,1
1,1,2,4,0,0,0,0,0,0,0,0,0,0,0,0,0,0,0,4,3,1,1,1,1,1,1
1,1,2,4,0,0,0,0,0,0,0,0,0,0,0,0,0,0,0,2,3,1,1,1,1,1,1
1,1,3,4,4,0,0,0,0,0,0,0,0,0,0,0,0,0,2,3,1,1,1,1,1,1,1
1,1,1,3,4,0,0,0,0,0,0,0,0,0,0,0,0,4,3,1,1,1,1,1,1,1,1
1,1,1,3,2,0,0,0,0,0,0,0,0,0,0,0,0,3,3,1,1,1,1,1,1,1,1
1,1,1,1,2,4,0,0,0,0,0,0,0,0,0,0,2,3,1,1,1,1,1,1,1,1,1
1,1,1,1,1,2,4,4,0,0,0,0,0,0,4,3,3,1,1,1,1,1,1,1,1,1,1
1,1,1,1,1,3,2,2,4,0,0,0,2,2,3,1,1,1,1,1,1,1,1,1,1,1,1
1,1,1,1,1,1,1,1,2,2,2,3,1,1,1,1,1,1,1,1,1,1,1,1,1,1,1
1,1,1,1,1,1,1,1,1,1,1,1,1,1,1,1,1,1,1,1,1,1,1,1,1,1,1
1,1,1,1,1,1,1,1,1,1,1,1,1,1,1,1,1,1,1,1,1,1,1,1,1,1,1
1,1,1,1,1,1,1,1,1,1,1,1,1,1,1,1,1,1,1,1,1,1,1,1,1,1,1
1,1,1,1,1,1,1,1,1,1,1,1,1,1,1,1,1,1,1,1,1,1,1,1,1,1,1
endlayer

layer
1,1,1,1,1,1,1,1,1,1,1,1,1,1,1,1,1,1,1,1,1,1,1,1,1,1,1
1,1,1,1,1,1,1,1,1,1,1,1,1,1,1,1,1,1,1,1,1,1,1,1,1,1,1
1,1,1,1,1,1,1,1,1,1,1,1,1,1,1,1,1,1,1,1,1,1,1,1,1,1,1
1,1,1,1,1,1,1,1,1,1,1,1,1,1,1,1,1,1,1,1,1,1,1,1,1,1,1
1,1,1,1,1,1,1,1,1,1,1,1,1,3,3,3,1,1,1,1,1,1,1,1,1,1,1
1,1,1,1,1,1,1,1,3,3,3,3,3,0,0,0,3,3,1,1,1,1,1,1,1,1,1
1,1,1,1,1,3,3,3,3,3,3,0,0,0,0,0,0,0,3,1,1,1,1,1,1,1,1
1,1,1,1,3,4,0,0,3,2,3,0,0,0,0,0,0,0,3,3,1,1,1,1,1,1,1
1,1,1,3,4,0,0,0,0,0,3,2,0,0,0,0,0,0,0,0,3,1,1,1,1,1,1
1,1,3,4,0,0,0,0,0,0,0,3,0,0,0,0,0,0,0,0,3,1,1,1,1,1,1
1,1,3,0,0,0,0,0,0,0,0,3,0,0,0,0,0,0,0,0,3,1,1,1,1,1,1
1,3,4,0,0,0,0,0,0,0,0,0,0,0,0,0,0,0,0,0,3,1,1,1,1,1,1
1,3,4,0,0,0,0,0,0,0,0,0,0,0,0,0,0,0,0,0,3,1,1,1,1,1,1
1,3,4,0,0,0,0,0,0,0,0,0,0,0,0,0,0,0,0,0,3,1,1,1,1,1,1
1,3,4,0,0,0,0,0,0,0,0,0,6,0,0,0,0,0,0,4,3,1,1,1,1,1,1
1,1,3,0,0,0,0,0,0,0,0,0,0,0,0,0,0,0,4,3,1,1,1,1,1,1,1
1,1,3,2,0,0,0,0,0,0,0,0,0,0,0,0,0,0,3,1,1,1,1,1,1,1,1
1,1,1,3,4,0,0,0,0,0,0,0,0,0,0,0,0,3,3,1,1,1,1,1,1,1,1
1,1,1,3,4,0,0,0,0,0,0,0,0,0,0,0,4,3,1,1,1,1,1,1,1,1,1
1,1,1,1,3,4,0,0,0,0,0,0,0,0,0,3,3,1,1,1,1,1,1,1,1,1,1
1,1,1,1,3,2,4,4,0,0,0,0,4,4,3,3,1,1,1,1,1,1,1,1,1,1,1
1,1,1,1,1,3,3,3,4,4,4,2,3,3,1,1,1,1,1,1,1,1,1,1,1,1,1
1,1,1,1,1,1,1,1,3,3,3,3,1,1,1,1,1,1,1,1,1,1,1,1,1,1,1
1,1,1,1,1,1,1,1,1,1,1,1,1,1,1,1,1,1,1,1,1,1,1,1,1,1,1
1,1,1,1,1,1,1,1,1,1,1,1,1,1,1,1,1,1,1,1,1,1,1,1,1,1,1
1,1,1,1,1,1,1,1,1,1,1,1,1,1,1,1,1,1,1,1,1,1,1,1,1,1,1
endlayer

layer
1,1,1,1,1,1,1,1,1,1,1,1,1,1,1,1,1,1,1,1,1,1,1,1,1,1,1
1,1,1,1,1,1,1,1,1,1,1,1,1,1,1,1,1,1,1,1,1,1,1,1,1,1,1
1,1,1,1,1,1,1,1,1,1,1,1,1,1,1,1,1,1,1,1,1,1,1,1,1,1,1
1,1,1,1,1,1,1,1,1,1,1,1,1,1,1,1,1,1,1,1,1,1,1,1,1,1,1
1,1,1,1,1,1,1,1,1,1,1,1,1,2,2,2,1,1,1,1,1,1,1,1,1,1,1
1,1,1,1,1,1,1,1,2,2,2,2,2,0,0,0,3,2,1,1,1,1,1,1,1,1,1
1,1,1,1,1,2,2,3,3,3,3,0,0,0,0,0,0,3,2,1,1,1,1,1,1,1,1
1,1,1,1,3,0,0,3,3,0,3,0,0,0,0,0,0,0,3,2,1,1,1,1,1,1,1
1,1,1,3,0,0,0,0,3,3,2,0,0,0,0,0,0,0,0,3,2,1,1,1,1,1,1
1,1,3,0,0,0,0,0,0,0,3,3,3,0,0,0,0,0,0,0,2,1,1,1,1,1,1
1,1,3,0,0,0,0,0,0,0,0,3,0,0,0,0,0,0,0,0,2,1,1,1,1,1,1
1,3,0,0,0,0,0,0,0,0,0,0,0,0,0,0,0,0,0,0,2,1,1,1,1,1,1
1,3,0,0,0,0,0,0,0,0,0,0,0,0,0,0,0,0,0,0,2,1,1,1,1,1,1
1,3,0,0,0,0,0,0,0,0,0,0,6,0,0,0,0,0,0,0,2,1,1,1,1,1,1
1,3,0,0,0,0,0,0,0,0,0,6,6,6,0,0,0,0,0,0,2,1,1,1,1,1,1
1,1,2,0,0,0,0,0,0,0,0,0,6,0,0,0,0,0,0,2,1,1,1,1,1,1,1
1,1,3,4,0,0,0,0,0,0,0,0,0,0,0,0,0,0,3,1,1,1,1,1,1,1,1
1,1,1,3,0,0,0,0,0,0,0,0,0,0,0,0,0,3,2,1,1,1,1,1,1,1,1
1,1,1,3,0,0,0,0,0,0,0,0,0,0,0,0,0,2,1,1,1,1,1,1,1,1,1
1,1,1,1,3,0,0,0,0,0,0,0,0,0,3,3,2,1,1,1,1,1,1,1,1,1,1
1,1,1,1,3,4,0,0,0,0,0,0,0,0,3,2,1,1,1,1,1,1,1,1,1,1,1
1,1,1,1,1,3,3,3,0,0,0,4,3,3,1,1,1,1,1,1,1,1,1,1,1,1,1
1,1,1,1,1,1,1,1,3,3,3,3,1,1,1,1,1,1,1,1,1,1,1,1,1,1,1
1,1,1,1,1,1,1,1,1,1,1,1,1,1,1,1,1,1,1,1,1,1,1,1,1,1,1
1,1,1,1,1,1,1,1,1,1,1,1,1,1,1,1,1,1,1,1,1,1,1,1,1,1,1
1,1,1,1,1,1,1,1,1,1,1,1,1,1,1,1,1,1,1,1,1,1,1,1,1,1,1
endlayer

layer
1,1,1,1,1,1,1,1,1,1,1,1,1,1,1,1,1,1,1,1,1,1,1,1,1,1,1
1,1,1,1,1,1,1,1,1,1,1,1,1,1,1,1,1,1,1,1,1,1,1,1,1,1,1
1,1,1,1,1,1,1,1,1,1,1,1,1,1,1,1,1,1,1,1,1,1,1,1,1,1,1
1,1,1,1,1,1,1,1,1,1,1,1,1,1,1,1,1,1,1,1,1,1,1,1,1,1,1
1,1,1,1,1,1,1,1,1,1,1,1,1,1,1,1,1,1,1,1,1,1,1,1,1,1,1
1,1,1,1,1,1,1,1,1,1,1,1,1,2,2,2,2,1,1,1,1,1,1,1,1,1,1
1,1,1,1,1,1,1,2,2,2,2,2,2,3,3,3,3,2,1,1,1,1,1,1,1,1,1
1,1,1,2,2,2,2,3,3,3,3,0,0,0,0,0,3,2,2,1,1,1,1,1,1,1,1
1,1,1,2,3,0,0,3,3,2,0,0,0,0,0,0,0,3,2,2,1,1,1,1,1,1,1
1,1,2,3,0,0,0,0,0,3,3,3,3,0,0,0,0,3,3,2,1,1,1,1,1,1,1
1,2,3,0,0,0,0,0,0,0,3,3,0,0,0,0,0,3,3,2,1,1,1,1,1,1,1
1,3,3,0,0,0,0,0,0,0,0,0,0,0,0,0,0,0,3,2,1,1,1,1,1,1,1
1,3,0,0,0,0,0,0,0,0,0,0,0,0,0,0,0,0,3,2,1,1,1,1,1,1,1
1,3,0,0,0,0,0,0,0,0,0,0,0,0,0,0,0,0,0,2,1,1,1,1,1,1,1
1,3,0,0,0,0,0,0,0,0,0,0,6,0,0,0,0,0,2,2,1,1,1,1,1,1,1
1,2,4,0,0,0,0,0,0,0,0,0,0,0,0,0,0,0,2,1,1,1,1,1,1,1,1
1,1,2,3,3,0,0,0,0,0,0,0,0,0,0,0,0,2,2,1,1,1,1,1,1,1,1
1,1,2,2,3,0,0,0,0,0,0,0,0,0,0,3,3,2,1,1,1,1,1,1,1,1,1
1,1,1,2,3,3,0,0,0,0,0,0,0,0,3,3,2,1,1,1,1,1,1,1,1,1,1
1,1,1,2,2,3,0,0,0,0,0,0,0,3,3,2,1,1,1,1,1,1,1,1,1,1,1
1,1,1,1,2,3,3,3,7,0,0,3,3,2,2,1,1,1,1,1,1,1,1,1,1,1,1
1,1,1,1,2,2,3,3,3,3,3,2,2,2,1,1,1,1,1,1,1,1,1,1,1,1,1
1,1,1,1,1,2,2,2,2,2,2,2,1,1,1,1,1,1,1,1,1,1,1,1,1,1,1
1,1,1,1,1,1,1,1,1,1,1,1,1,1,1,1,1,1,1,1,1,1,1,1,1,1,1
1,1,1,1,1,1,1,1,1,1,1,1,1,1,1,1,1,1,1,1,1,1,1,1,1,1,1
1,1,1,1,1,1,1,1,1,1,1,1,1,1,1,1,1,1,1,1,1,1,1,1,1,1,1
endlayer

layer
1,1,1,1,1,1,1,1,1,1,1,1,1,1,1,1,1,1,1,1,1,1,1,1,1,1,1
1,1,1,1,1,1,1,1,1,1,1,1,1,1,1,1,1,1,1,1,1,1,1,1,1,1,1
1,1,1,1,1,1,1,1,1,1,1,1,1,1,1,1,1,1,1,1,1,1,1,1,1,1,1
1,1,1,1,1,1,1,1,1,1,1,1,1,1,1,1,1,1,1,1,1,1,1,1,1,1,1
1,1,1,1,1,1,1,1,1,1,1,1,1,1,1,1,1,1,1,1,1,1,1,1,1,1,1
1,1,1,1,1,1,1,1,1,1,1,1,1,1,1,1,1,1,1,1,1,1,1,1,1,1,1
1,1,1,1,1,1,1,1,1,1,1,1,1,2,2,2,2,1,1,1,1,1,1,1,1,1,1
1,1,1,1,1,1,1,2,2,2,2,2,2,2,2,2,2,1,1,1,1,1,1,1,1,1,1
1,1,1,1,2,2,2,2,2,0,0,0,3,2,2,2,2,2,1,1,1,1,1,1,1,1,1
1,1,1,2,2,2,3,3,3,3,3,3,3,3,3,3,2,2,2,1,1,1,1,1,1,1,1
1,1,2,2,2,3,3,3,3,3,3,3,0,0,0,3,3,2,2,1,1,1,1,1,1,1,1
1,2,2,3,3,3,3,3,0,3,3,0,0,0,0,3,3,2,2,1,1,1,1,1,1,1,1
1,2,2,3,3,3,3,0,0,0,3,0,0,0,0,3,3,2,2,1,1,1,1,1,1,1,1
1,2,2,2,3,3,7,0,0,0,0,0,0,0,0,3,2,2,2,1,1,1,1,1,1,1,1
1,2,2,2,3,3,0,0,0,0,0,0,0,0,3,2,2,2,1,1,1,1,1,1,1,1,1
1,1,2,2,2,3,0,0,0,0,0,0,0,3,2,2,2,2,1,1,1,1,1,1,1,1,1
1,1,1,2,2,3,3,0,0,0,0,0,2,2,2,2,2,1,1,1,1,1,1,1,1,1,1
1,1,1,1,2,3,3,3,0,0,0,2,2,2,2,2,2,1,1,1,1,1,1,1,1,1,1
1,1,1,1,2,2,3,3,3,3,2,2,2,2,2,2,1,1,1,1,1,1,1,1,1,1,1
1,1,1,1,1,2,2,2,3,2,2,2,2,2,2,1,1,1,1,1,1,1,1,1,1,1,1
1,1,1,1,1,2,2,2,2,2,2,2,2,1,1,1,1,1,1,1,1,1,1,1,1,1,1
1,1,1,1,1,1,2,2,2,2,2,1,1,1,1,1,1,1,1,1,1,1,1,1,1,1,1
1,1,1,1,1,1,1,1,1,1,1,1,1,1,1,1,1,1,1,1,1,1,1,1,1,1,1
1,1,1,1,1,1,1,1,1,1,1,1,1,1,1,1,1,1,1,1,1,1,1,1,1,1,1
1,1,1,1,1,1,1,1,1,1,1,1,1,1,1,1,1,1,1,1,1,1,1,1,1,1,1
1,1,1,1,1,1,1,1,1,1,1,1,1,1,1,1,1,1,1,1,1,1,1,1,1,1,1
endlayer

layer
1,1,1,1,1,1,1,1,1,1,1,1,1,1,1,1,1,1,1,1,1,1,1,1,1,1,1
1,1,1,1,1,1,1,1,1,1,1,1,1,1,1,1,1,1,1,1,1,1,1,1,1,1,1
1,1,1,1,1,1,1,1,1,1,1,1,1,1,1,1,1,1,1,1,1,1,1,1,1,1,1
1,1,1,1,1,1,1,1,1,1,1,1,1,1,1,1,1,1,1,1,1,1,1,1,1,1,1
1,1,1,1,1,1,1,1,1,1,1,1,1,1,1,1,1,1,1,1,1,1,1,1,1,1,1
1,1,1,1,1,1,1,1,1,1,1,1,1,1,1,1,1,1,1,1,1,1,1,1,1,1,1
1,1,1,1,1,1,1,1,1,1,1,1,1,1,1,1,1,1,1,1,1,1,1,1,1,1,1
1,1,1,1,1,1,1,1,1,1,1,1,1,1,1,1,1,1,1,1,1,1,1,1,1,1,1
1,1,1,1,1,1,1,1,0,0,0,2,2,1,1,1,1,1,1,1,1,1,1,1,1,1,1
1,1,1,1,1,1,2,2,2,2,2,2,2,2,2,2,1,1,1,1,1,1,1,1,1,1,1
1,1,1,1,1,2,2,2,2,2,2,2,2,2,2,2,2,1,1,1,1,1,1,1,1,1,1
1,1,1,2,2,2,2,2,2,2,2,2,2,2,2,2,2,1,1,1,1,1,1,1,1,1,1
1,1,1,2,2,2,2,2,2,2,2,2,2,2,2,2,2,1,1,1,1,1,1,1,1,1,1
1,1,1,1,2,2,2,2,2,2,2,2,2,2,2,2,1,1,1,1,1,1,1,1,1,1,1
1,1,1,1,2,2,2,2,2,2,2,2,2,2,2,1,1,1,1,1,1,1,1,1,1,1,1
1,1,1,1,1,2,2,2,2,2,2,2,2,2,1,1,1,1,1,1,1,1,1,1,1,1,1
1,1,1,1,1,2,2,2,2,2,2,2,1,1,1,1,1,1,1,1,1,1,1,1,1,1,1
1,1,1,1,1,2,2,2,2,2,2,1,1,1,1,1,1,1,1,1,1,1,1,1,1,1,1
1,1,1,1,1,1,2,2,2,2,1,1,1,1,1,1,1,1,1,1,1,1,1,1,1,1,1
1,1,1,1,1,1,1,1,2,1,1,1,1,1,1,1,1,1,1,1,1,1,1,1,1,1,1
1,1,1,1,1,1,1,1,1,1,1,1,1,1,1,1,1,1,1,1,1,1,1,1,1,1,1
1,1,1,1,1,1,1,1,1,1,1,1,1,1,1,1,1,1,1,1,1,1,1,1,1,1,1
1,1,1,1,1,1,1,1,1,1,1,1,1,1,1,1,1,1,1,1,1,1,1,1,1,1,1
1,1,1,1,1,1,1,1,1,1,1,1,1,1,1,1,1,1,1,1,1,1,1,1,1,1,1
1,1,1,1,1,1,1,1,1,1,1,1,1,1,1,1,1,1,1,1,1,1,1,1,1,1,1
1,1,1,1,1,1,1,1,1,1,1,1,1,1,1,1,1,1,1,1,1,1,1,1,1,1,1
endlayer

layer
1,1,1,1,1,1,1,1,1,1,1,1,1,1,1,1,1,1,1,1,1,1,1,1,1,1,1
1,1,1,1,1,1,1,1,1,1,1,1,1,1,1,1,1,1,1,1,1,1,1,1,1,1,1
1,1,1,1,1,1,1,1,1,1,1,1,1,1,1,1,1,1,1,1,1,1,1,1,1,1,1
1,1,1,1,1,1,1,1,1,1,1,1,1,1,1,1,1,1,1,1,1,1,1,1,1,1,1
1,1,1,1,1,1,1,1,1,1,1,1,1,1,1,1,1,1,1,1,1,1,1,1,1,1,1
1,1,1,1,1,1,1,1,1,1,1,1,1,1,1,1,1,1,1,1,1,1,1,1,1,1,1
1,1,1,1,1,1,1,1,1,1,1,1,1,1,1,1,1,1,1,1,1,1,1,1,1,1,1
1,1,1,1,1,1,1,1,1,1,1,1,1,1,1,1,1,1,1,1,1,1,1,1,1,1,1
1,1,1,1,1,1,1,1,0,0,0,8,8,1,1,1,1,1,1,1,1,1,1,1,1,1,1
1,1,1,1,1,1,8,8,8,8,8,8,8,8,8,8,1,1,1,1,1,1,1,1,1,1,1
1,1,1,1,1,8,8,8,8,8,8,8,8,8,8,8,8,1,1,1,1,1,1,1,1,1,1
1,1,1,8,8,8,8,8,8,8,8,8,8,8,8,8,8,1,1,1,1,1,1,1,1,1,1
1,1,1,8,8,8,8,8,8,8,8,8,8,8,8,8,8,1,1,1,1,1,1,1,1,1,1
1,1,1,1,8,8,8,8,8,8,8,8,8,8,8,8,1,1,1,1,1,1,1,1,1,1,1
1,1,1,1,8,8,8,8,8,8,8,8,8,8,8,1,1,1,1,1,1,1,1,1,1,1,1
1,1,1,1,1,8,8,8,8,8,8,8,8,8,1,1,1,1,1,1,1,1,1,1,1,1,1
1,1,1,1,1,8,8,8,8,8,8,8,1,1,1,1,1,1,1,1,1,1,1,1,1,1,1
1,1,1,1,1,8,8,8,8,8,8,1,1,1,1,1,1,1,1,1,1,1,1,1,1,1,1
1,1,1,1,1,1,8,8,8,8,1,1,1,1,1,1,1,1,1,1,1,1,1,1,1,1,1
1,1,1,1,1,1,1,1,8,1,1,1,1,1,1,1,1,1,1,1,1,1,1,1,1,1,1
1,1,1,1,1,1,1,1,1,1,1,1,1,1,1,1,1,1,1,1,1,1,1,1,1,1,1
1,1,1,1,1,1,1,1,1,1,1,1,1,1,1,1,1,1,1,1,1,1,1,1,1,1,1
1,1,1,1,1,1,1,1,1,1,1,1,1,1,1,1,1,1,1,1,1,1,1,1,1,1,1
1,1,1,1,1,1,1,1,1,1,1,1,1,1,1,1,1,1,1,1,1,1,1,1,1,1,1
1,1,1,1,1,1,1,1,1,1,1,1,1,1,1,1,1,1,1,1,1,1,1,1,1,1,1
1,1,1,1,1,1,1,1,1,1,1,1,1,1,1,1,1,1,1,1,1,1,1,1,1,1,1
endlayer

