
# Created by Ruins mod version 16.7 Ingame Parser
# authoring Player: ST753M

weight=2
embed_into_distance=4
acceptable_target_blocks=endstone,end_stone
unacceptable_target_blocks=flowing_water,water,flowing_lava,lava
dimensions=23,11,12
allowable_overhang=999
max_leveling=2
leveling_buffer=0
preserve_water=0
preserve_lava=0
spawnMinDistance=500

biomesToSpawnIn=sky,end,the_end,void

rule1=0,100,preserveBlock
rule2=0,100,minecraft:end_stone-0
rule3=0,100,biomesoplenty:gem_ore-0
rule4=0,100,biomesoplenty:biome_block-0
rule5=0,100,IInventory;minecraft:chest;biomesoplenty:planks_0#8#4#2+biomesoplenty:sapling_0#4#7#3+biomesoplenty:log_1#11#4#5+biomesoplenty:planks_0#16#4#7+biomesoplenty:planks_0#4#4#9+biomesoplenty:log_1#27#4#10+biomesoplenty:log_1#33#4#13+biomesoplenty:sapling_0#3#7#15+biomesoplenty:sapling_0#2#7#19+biomesoplenty:log_1#11#4#20+biomesoplenty:log_1#22#4#24-2
rule6=0,100,IInventory;minecraft:chest;biomesoplenty:log_1#16#4#2+biomesoplenty:sapling_0#1#7#4+biomesoplenty:planks_0#18#4#5+biomesoplenty:sapling_0#4#7#7+biomesoplenty:log_1#9#4#10+biomesoplenty:planks_0#2#4#12+biomesoplenty:log_1#32#4#15+biomesoplenty:log_1#10#4#17+biomesoplenty:planks_0#16#4#18+biomesoplenty:log_1#21#4#22+biomesoplenty:sapling_0#2#7#25-2
rule7=0,100,biomesoplenty:log_1-4
rule8=0,100,biomesoplenty:leaves_1-15
rule9=0,100,biomesoplenty:leaves_1-3
rule10=0,100,biomesoplenty:leaves_1-11
rule11=0,100,biomesoplenty:leaves_1-7
rule12=0,100,biomesoplenty:log_1-8
rule13=0,100,biomesoplenty:log_1-0

layer
1,1,1,1,1,1,1,1,1,1,1,1
1,1,1,1,1,1,1,1,1,1,1,1
1,1,1,1,1,1,1,1,1,1,1,1
1,1,1,1,3,2,2,2,1,1,1,1
1,1,1,1,2,2,2,2,1,1,1,1
1,1,1,1,2,2,2,3,1,1,1,1
1,1,1,1,2,2,2,2,1,1,1,1
1,1,1,1,1,1,1,1,1,1,1,1
1,1,1,1,1,1,1,1,1,1,1,1
1,1,1,1,1,1,1,1,1,1,1,1
1,1,1,1,1,1,1,1,1,1,1,1
endlayer

layer
1,1,1,1,1,1,1,1,1,1,1,1
1,1,1,1,1,1,1,1,1,1,1,1
1,1,1,1,2,2,2,2,1,1,1,1
1,1,1,2,2,2,2,2,2,1,1,1
1,1,1,2,2,2,2,2,2,1,1,1
1,1,1,4,2,2,2,2,2,1,1,1
1,1,1,2,2,2,2,2,2,1,1,1
1,1,1,1,2,2,2,2,1,1,1,1
1,1,1,1,1,1,1,1,1,1,1,1
1,1,1,1,1,1,1,1,1,1,1,1
1,1,1,1,1,1,1,1,1,1,1,1
endlayer

layer
1,1,1,1,1,1,1,1,1,1,1,1
1,1,1,1,1,1,1,1,1,1,1,1
1,1,1,1,2,2,4,2,1,1,1,1
1,1,1,2,2,2,2,2,2,1,1,1
1,1,1,2,2,2,2,2,2,1,1,1
1,1,1,2,2,2,2,2,2,1,1,1
1,1,1,2,2,2,4,2,2,1,1,1
1,1,1,1,2,3,2,2,1,1,1,1
1,1,1,1,1,1,1,1,1,1,1,1
1,1,1,1,1,1,1,1,1,1,1,1
1,1,1,1,1,1,1,1,1,1,1,1
endlayer

layer
1,1,1,1,1,1,1,1,1,1,1,1
1,1,1,1,1,1,1,1,1,1,1,1
1,1,1,1,1,1,1,1,1,1,1,1
1,1,1,1,2,2,2,2,1,1,1,1
1,1,1,1,2,2,5,2,1,1,1,1
1,1,1,1,2,2,6,2,1,1,1,1
1,1,1,1,2,2,2,2,1,1,1,1
1,1,1,1,1,1,1,1,1,1,1,1
1,1,1,1,1,1,1,1,1,1,1,1
1,1,1,1,1,1,1,1,1,1,1,1
1,1,1,1,1,1,1,1,1,1,1,1
endlayer

layer
1,1,1,1,1,1,1,1,1,1,1,1
1,1,1,1,1,1,1,1,1,1,1,1
1,1,1,1,1,1,1,1,1,1,1,1
1,1,1,1,1,1,1,1,1,1,1,1
1,1,1,1,1,7,7,1,1,1,1,1
1,1,1,1,1,7,7,1,1,1,1,1
1,1,1,1,1,1,1,1,1,1,1,1
1,1,1,1,1,1,1,1,1,1,1,1
1,1,1,1,1,1,1,1,1,1,1,1
1,1,1,1,1,1,1,1,1,1,1,1
1,1,1,1,1,1,1,1,1,1,1,1
endlayer

layer
1,1,1,1,1,1,1,1,1,1,1,1
1,1,1,1,1,1,1,1,1,1,1,1
1,1,1,1,1,1,1,1,1,1,1,1
1,1,1,1,1,1,1,1,1,1,1,1
1,1,1,1,1,7,7,1,1,1,1,1
1,1,1,1,1,7,7,1,1,1,1,1
1,1,1,1,1,1,1,1,1,1,1,1
1,1,1,1,1,1,1,1,1,1,1,1
1,1,1,1,1,1,1,1,1,1,1,1
1,1,1,1,1,1,1,1,1,1,1,1
1,1,1,1,1,1,1,1,1,1,1,1
endlayer

layer
1,1,1,1,1,1,1,1,1,1,1,1
1,1,1,1,1,1,1,1,1,1,1,1
1,1,1,1,1,1,1,1,1,1,1,1
1,1,1,1,1,1,1,1,1,1,1,1
1,1,1,1,1,7,7,1,1,1,1,1
1,1,1,1,1,7,7,1,1,1,1,1
1,1,1,1,1,1,1,1,1,1,1,1
1,1,1,1,1,1,1,1,1,1,1,1
1,1,1,1,1,1,1,1,1,1,1,1
1,1,1,1,1,1,1,1,1,1,1,1
1,1,1,1,1,1,1,1,1,1,1,1
endlayer

layer
1,1,1,1,1,1,1,1,1,1,1,1
1,1,1,1,1,1,1,1,1,1,1,1
1,1,1,1,1,1,1,1,1,1,1,1
1,9,9,9,8,1,1,1,1,1,1,1
1,9,9,9,8,7,7,1,1,1,1,1
1,10,9,10,8,7,7,1,1,1,1,1
1,1,1,1,1,1,1,1,1,1,1,1
1,1,1,1,1,1,1,1,1,1,1,1
1,1,1,1,1,1,1,1,1,1,1,1
1,1,1,1,1,1,1,1,1,1,1,1
1,1,1,1,1,1,1,1,1,1,1,1
endlayer

layer
1,1,1,1,1,1,1,1,1,1,1,1
1,1,1,1,1,1,1,1,1,1,1,1
1,9,9,9,8,1,1,1,1,1,1,1
9,9,9,9,8,1,1,1,1,1,1,1
9,9,10,9,8,7,7,8,9,9,10,1
9,9,9,9,8,7,7,8,9,9,9,1
1,9,10,9,8,1,1,8,9,9,9,1
1,1,1,1,1,1,1,1,1,1,1,1
1,1,1,1,1,1,1,1,1,1,1,1
1,1,1,1,1,1,1,1,1,1,1,1
1,1,1,1,1,1,1,1,1,1,1,1
endlayer

layer
1,1,1,1,1,1,1,1,1,1,1,1
1,1,1,1,1,1,1,1,1,1,1,1
1,9,9,9,8,1,1,1,1,1,1,1
9,9,9,9,8,11,1,8,9,9,9,1
8,12,12,12,12,7,7,8,9,9,9,9
9,9,9,9,8,7,7,8,9,9,9,9
1,9,9,9,8,1,1,11,9,9,9,9
1,1,1,1,1,1,1,11,9,9,9,1
1,1,1,1,1,1,1,1,1,1,1,1
1,1,1,1,1,1,1,1,1,1,1,1
1,1,1,1,1,1,1,1,1,1,1,1
endlayer

layer
1,1,1,1,1,1,1,1,1,1,1,1
1,1,1,1,1,1,1,1,1,1,1,1
1,9,9,9,8,1,1,1,1,1,1,1
9,9,9,9,8,11,1,8,9,9,9,1
9,9,9,9,8,7,7,8,9,9,9,9
9,9,9,9,8,7,7,12,12,12,9,9
1,9,9,9,8,8,8,11,9,9,9,9
1,1,1,1,11,11,11,11,8,9,9,1
1,1,1,1,9,9,9,1,1,1,1,1
1,1,1,1,9,9,9,1,1,1,1,1
1,1,1,1,1,1,1,1,1,1,1,1
endlayer

layer
1,1,1,1,1,1,1,1,1,1,1,1
1,1,1,1,1,9,9,9,1,1,1,1
1,1,1,1,1,8,8,8,1,1,1,1
1,9,9,9,8,8,8,8,9,9,9,1
1,9,9,9,8,7,7,8,9,9,9,9
1,9,9,9,8,7,7,8,9,9,9,9
1,1,1,8,8,8,8,11,8,9,9,9
1,1,1,11,11,0,0,9,8,9,9,1
1,1,1,9,9,9,9,9,1,1,1,1
1,1,1,9,9,9,9,9,1,1,1,1
1,1,1,1,9,9,8,1,1,1,1,1
endlayer

layer
1,1,1,1,1,9,9,9,1,1,1,1
1,1,1,1,9,9,9,9,9,1,1,1
1,1,1,1,8,8,8,8,8,1,1,1
1,1,1,1,8,8,8,8,8,1,1,1
1,1,1,1,8,7,7,8,8,9,9,1
1,1,1,1,8,7,7,8,8,9,8,1
1,1,1,8,8,13,11,11,8,9,9,1
1,1,1,11,0,13,9,9,1,1,1,1
1,1,1,9,9,13,9,9,1,1,1,1
1,1,1,9,9,9,9,9,1,1,1,1
1,1,1,1,9,9,9,1,1,1,1,1
endlayer

layer
1,1,1,1,1,9,9,9,1,1,1,1
1,1,1,1,9,9,9,9,9,1,1,1
1,1,1,1,8,8,13,8,8,1,1,1
1,1,1,1,8,8,13,8,8,1,1,1
1,1,1,1,11,7,7,11,8,11,1,1
1,1,1,1,8,7,7,11,8,11,1,1
1,1,1,11,11,11,11,11,8,11,1,1
1,1,1,9,9,9,9,9,1,1,1,1
1,1,1,9,9,9,9,9,1,1,1,1
1,1,1,9,9,9,9,9,1,1,1,1
1,1,1,1,9,9,9,1,1,1,1,1
endlayer

layer
1,1,1,1,1,9,9,9,1,1,1,1
1,1,1,1,9,9,9,9,9,1,1,1
1,1,1,1,9,9,9,9,8,1,1,1
1,1,1,11,8,8,8,8,8,8,1,1
1,1,1,11,11,7,7,11,8,8,11,1
1,1,1,11,11,7,7,11,8,11,11,1
1,1,1,1,11,11,11,11,8,11,11,1
1,1,1,1,9,9,9,11,11,11,1,1
1,1,1,1,9,9,9,1,1,1,1,1
1,1,1,1,9,9,9,1,1,1,1,1
1,1,1,1,1,1,1,1,1,1,1,1
endlayer

layer
1,1,1,1,1,1,1,1,1,1,1,1
1,1,1,1,1,9,9,9,1,1,1,1
1,1,1,11,11,9,9,9,1,1,1,1
1,1,11,11,11,8,8,8,8,8,1,1
1,1,11,11,11,7,7,11,8,8,11,1
1,1,11,11,8,7,7,12,12,11,11,1
1,1,1,8,8,0,0,8,8,11,11,1
1,1,1,1,1,1,1,8,8,11,1,1
1,1,1,1,1,1,1,1,1,1,1,1
1,1,1,1,1,1,1,1,1,1,1,1
1,1,1,1,1,1,1,1,1,1,1,1
endlayer

layer
1,1,1,1,1,1,1,1,1,1,1,1
1,1,1,1,1,1,1,1,1,1,1,1
1,1,1,11,11,11,11,11,1,1,1,1
1,1,11,11,11,11,11,11,11,8,1,1
1,1,11,11,12,7,7,11,11,11,11,1
1,1,11,11,8,7,7,8,11,11,11,1
1,1,1,8,8,8,0,8,11,11,11,1
1,1,1,1,1,1,1,8,8,11,1,1
1,1,1,1,1,1,1,1,1,1,1,1
1,1,1,1,1,1,1,1,1,1,1,1
1,1,1,1,1,1,1,1,1,1,1,1
endlayer

layer
1,1,1,1,1,1,1,1,1,1,1,1
1,1,1,1,1,11,11,11,1,1,1,1
1,1,1,11,11,11,11,11,11,1,1,1
1,1,11,11,11,11,11,11,11,1,1,1
1,1,11,11,11,7,7,11,11,11,1,1
1,1,11,11,8,7,7,8,11,11,1,1
1,1,1,8,8,8,11,8,11,11,1,1
1,1,1,1,1,1,1,1,1,1,1,1
1,1,1,1,1,1,1,1,1,1,1,1
1,1,1,1,1,1,1,1,1,1,1,1
1,1,1,1,1,1,1,1,1,1,1,1
endlayer

layer
1,1,1,1,1,1,1,1,1,1,1,1
1,1,1,1,1,11,11,11,1,1,1,1
1,1,1,1,11,11,11,11,11,1,1,1
1,1,1,11,11,11,13,11,11,1,1,1
1,1,1,11,11,7,7,11,11,1,1,1
1,1,1,11,11,7,7,11,11,1,1,1
1,1,1,1,11,11,11,11,1,1,1,1
1,1,1,1,1,11,11,1,1,1,1,1
1,1,1,1,1,1,1,1,1,1,1,1
1,1,1,1,1,1,1,1,1,1,1,1
1,1,1,1,1,1,1,1,1,1,1,1
endlayer

layer
1,1,1,1,1,1,1,1,1,1,1,1
1,1,1,1,1,11,11,11,1,1,1,1
1,1,1,1,11,11,11,11,11,1,1,1
1,1,1,11,11,11,11,11,11,1,1,1
1,1,11,11,11,7,7,11,11,11,1,1
1,1,11,11,11,7,7,11,11,11,1,1
1,1,1,11,11,11,11,11,11,1,1,1
1,1,1,1,11,11,11,11,1,1,1,1
1,1,1,1,1,11,11,1,1,1,1,1
1,1,1,1,1,1,1,1,1,1,1,1
1,1,1,1,1,1,1,1,1,1,1,1
endlayer

layer
1,1,1,1,1,1,1,1,1,1,1,1
1,1,1,1,1,1,1,1,1,1,1,1
1,1,1,1,11,11,11,11,1,1,1,1
1,1,1,11,11,11,11,11,1,1,1,1
1,1,11,11,11,7,7,11,11,11,1,1
1,1,11,11,11,11,7,11,11,11,1,1
1,1,1,11,11,11,11,11,11,1,1,1
1,1,1,1,11,11,11,11,1,1,1,1
1,1,1,1,1,11,11,1,1,1,1,1
1,1,1,1,1,1,1,1,1,1,1,1
1,1,1,1,1,1,1,1,1,1,1,1
endlayer

layer
1,1,1,1,1,1,1,1,1,1,1,1
1,1,1,1,1,1,1,1,1,1,1,1
1,1,1,1,1,8,11,1,1,1,1,1
1,1,1,1,8,8,11,11,1,1,1,1
1,1,1,8,8,8,7,11,11,1,1,1
1,1,1,11,11,11,11,11,11,1,1,1
1,1,1,1,11,11,11,11,1,1,1,1
1,1,1,1,1,11,11,1,1,1,1,1
1,1,1,1,1,1,1,1,1,1,1,1
1,1,1,1,1,1,1,1,1,1,1,1
1,1,1,1,1,1,1,1,1,1,1,1
endlayer

layer
1,1,1,1,1,1,1,1,1,1,1,1
1,1,1,1,1,1,1,1,1,1,1,1
1,1,1,1,1,1,1,1,1,1,1,1
1,1,1,1,1,8,11,1,1,1,1,1
1,1,1,1,11,11,11,11,1,1,1,1
1,1,1,1,11,11,11,11,1,1,1,1
1,1,1,1,1,11,11,1,1,1,1,1
1,1,1,1,1,1,1,1,1,1,1,1
1,1,1,1,1,1,1,1,1,1,1,1
1,1,1,1,1,1,1,1,1,1,1,1
1,1,1,1,1,1,1,1,1,1,1,1
endlayer

