
# Created by Ruins mod version 16.5 Ingame Parser
# authoring Player: ST753M

weight=1
uniqueMinDistance=10000
spawnMinDistance=10000
embed_into_distance=-100
acceptable_target_blocks=
unacceptable_target_blocks=Natura:Cloud,slime_grass,slime_congealed,slime_dirt,cloud,cloud_block
dimensions=25,41,41
allowable_overhang=999
max_leveling=0
leveling_buffer=0
preserve_water=0
preserve_lava=0
preventRotation=1

biomesToSpawnIn=mystic_grove,void,sky,crystal_forest,enchanted_forest

rule1=0,100,minecraft:stone_slab-15
rule2=0,100,minecraft:quartz_block-0
rule3=0,100,IInventory;minecraft:dispenser;minecraft:spawn_egg#{EntityTag:{id:"minecraft:villager"}}#0#4-1
rule4=0,100,minecraft:glowstone-0
rule5=0,100,minecraft:quartz_stairs-0
rule6=0,100,minecraft:quartz_stairs-2
rule7=0,100,air
rule8=0,100,minecraft:quartz_stairs-3
rule9=0,100,minecraft:redstone_wire-15
rule10=1,100,minecraft:redstone_torch-5
rule11=0,100,minecraft:redstone_wire-0
rule12=0,100,minecraft:unlit_redstone_torch-1
rule13=0,100,minecraft:quartz_stairs-1
rule14=0,100,minecraft:quartz_stairs-6
rule15=0,100,minecraft:quartz_stairs-4
rule16=0,100,minecraft:quartz_block-2
rule17=0,100,minecraft:quartz_stairs-7
rule18=0,100,minecraft:quartz_stairs-5
rule19=0,100,minecraft:sand-0
rule20=0,100,minecraft:redstone_wire-14
rule21=0,100,minecraft:stained_glass-0
rule22=0,100,minecraft:water-0
rule23=0,100,minecraft:grass-0
rule24=0,100,minecraft:birch_stairs-3
rule25=0,100,minecraft:birch_fence-0
rule26=0,100,minecraft:birch_stairs-2
rule27=0,100,minecraft:birch_door-3
rule28=0,100,minecraft:birch_door-5
rule29=0,100,minecraft:birch_door-0
rule30=0,100,minecraft:birch_door-2
rule31=0,100,minecraft:birch_door-6
rule32=0,100,minecraft:quartz_block-1
rule33=0,100,minecraft:birch_stairs-1
rule34=0,100,minecraft:birch_door-1
rule35=0,100,minecraft:birch_stairs-0
rule36=0,100,minecraft:birch_door-4
rule37=0,100,minecraft:double_plant-1
rule38=0,100,minecraft:carpet-0
rule39=0,100,minecraft:red_flower-2
rule40=0,100,minecraft:stone_slab-7
rule41=0,100,minecraft:red_flower-7
rule42=0,100,minecraft:birch_door-9
rule43=0,100,minecraft:birch_door-8
rule44=0,100,minecraft:water-9
rule45=0,100,minecraft:water-1
rule46=0,100,minecraft:double_plant-10
rule47=0,10,MobSpawner:Rabbit,MobSpawner:Parrot,MobSpawner:Parrot,MobSpawner:Parrot,MobSpawner:Parrot,MobSpawner:Rabbit,MobSpawner:Villager
rule48=0,100,minecraft:bookshelf-0
rule49=1,100,minecraft:torch-5
rule50=0,100,minecraft:bed-0
rule51=0,100,minecraft:bed-8
rule52=0,100,minecraft:bed-10
rule53=0,100,minecraft:bed-2
rule54=0,50,ChestGenHook:chests/end_city_treasure:2-5
rule55=0,30,ChestGenHook:chests/end_city_treasure:2-3
rule56=0,10,ChestGenHook:chests/end_city_treasure:2-2
rule57=0,100,minecraft:bed-3
rule58=0,100,minecraft:birch_door-7
rule59=0,100,minecraft:bed-11
rule60=0,100,minecraft:farmland-7
rule61=0,100,minecraft:bed-9
rule62=0,100,minecraft:bed-1
rule63=0,50,ChestGenHook:chests/end_city_treasure:2-4
rule64=0,100,minecraft:wheat-7

layer
0,0,0,0,0,0,0,0,0,0,0,0,0,0,0,0,0,0,0,0,0,0,0,0,0,0,0,0,0,0,0,0,0,0,0,0,0,0,0,0,0
0,0,0,0,0,0,0,0,0,0,0,0,0,0,0,0,0,0,0,0,0,0,0,0,0,0,0,0,0,0,0,0,0,0,0,0,0,0,0,0,0
0,0,0,0,0,0,0,0,0,0,0,0,0,0,0,0,0,0,0,0,0,0,0,0,0,0,0,0,0,0,0,0,0,0,0,0,0,0,0,0,0
0,0,0,0,0,0,0,0,0,0,0,0,0,0,0,0,0,0,0,0,0,0,0,0,0,0,0,0,0,0,0,0,0,0,0,0,0,0,0,0,0
0,0,0,0,0,0,0,0,0,0,0,0,0,0,0,0,0,0,0,0,0,0,0,0,0,0,0,0,0,0,0,0,0,0,0,0,0,0,0,0,0
0,0,0,0,0,0,0,0,0,0,0,0,0,0,0,0,0,0,0,0,0,0,0,0,0,0,0,0,0,0,0,0,0,0,0,0,0,0,0,0,0
0,0,0,0,0,0,0,0,0,0,0,0,0,0,0,0,0,0,0,0,0,0,0,0,0,0,0,0,0,0,0,0,0,0,0,0,0,0,0,0,0
0,0,0,0,0,0,0,0,0,0,0,0,0,0,0,0,0,0,0,0,0,0,0,0,0,0,0,0,0,0,0,0,0,0,0,0,0,0,0,0,0
0,0,0,0,0,0,0,0,0,0,0,0,0,0,0,0,0,0,0,0,0,0,0,0,0,0,0,0,0,0,0,0,0,0,0,0,0,0,0,0,0
0,0,0,0,0,0,0,0,0,0,0,0,0,0,0,0,0,0,0,0,0,0,0,0,0,0,0,0,0,0,0,0,0,0,0,0,0,0,0,0,0
0,0,0,0,0,0,0,0,0,0,0,0,0,0,0,0,0,0,0,0,0,0,0,0,0,0,0,0,0,0,0,0,0,0,0,0,0,0,0,0,0
0,0,0,0,0,0,0,0,0,0,0,0,0,0,0,0,0,0,0,0,0,0,0,0,0,0,0,0,0,0,0,0,0,0,0,0,0,0,0,0,0
0,0,0,0,0,0,0,0,0,0,0,0,0,0,0,0,0,0,0,0,0,0,0,0,0,0,0,0,0,0,0,0,0,0,0,0,0,0,0,0,0
0,0,0,0,0,0,0,0,0,0,0,0,0,0,0,0,0,0,0,0,0,0,0,0,0,0,0,0,0,0,0,0,0,0,0,0,0,0,0,0,0
0,0,0,0,0,0,0,0,0,0,0,0,0,0,0,0,0,0,0,0,0,0,0,0,0,0,0,0,0,0,0,0,0,0,0,0,0,0,0,0,0
0,0,0,0,0,0,0,0,0,0,0,0,0,0,0,0,0,0,0,0,0,0,0,0,0,0,0,0,0,0,0,0,0,0,0,0,0,0,0,0,0
0,0,0,0,0,0,0,0,0,0,0,0,0,0,0,0,0,0,0,0,0,0,0,0,0,0,0,0,0,0,0,0,0,0,0,0,0,0,0,0,0
0,0,0,0,0,0,0,0,0,0,0,0,0,0,0,0,0,0,0,0,0,0,0,0,0,0,0,0,0,0,0,0,0,0,0,0,0,0,0,0,0
0,0,0,0,0,0,0,0,0,0,0,0,0,0,0,0,0,0,0,1,1,1,0,0,0,0,0,0,0,0,0,0,0,0,0,0,0,0,0,0,0
0,0,0,0,0,0,0,0,0,0,0,0,0,0,0,0,0,0,1,1,1,1,1,0,0,0,0,0,0,0,0,0,0,0,0,0,0,0,0,0,0
0,0,0,0,0,0,0,0,0,0,0,0,0,0,0,0,0,0,1,1,0,1,1,0,0,0,0,0,0,0,0,0,0,0,0,0,0,0,0,0,0
0,0,0,0,0,0,0,0,0,0,0,0,0,0,0,0,0,0,1,1,1,1,1,0,0,0,0,0,0,0,0,0,0,0,0,0,0,0,0,0,0
0,0,0,0,0,0,0,0,0,0,0,0,0,0,0,0,0,0,0,1,1,1,0,0,0,0,0,0,0,0,0,0,0,0,0,0,0,0,0,0,0
0,0,0,0,0,0,0,0,0,0,0,0,0,0,0,0,0,0,0,0,0,0,0,0,0,0,0,0,0,0,0,0,0,0,0,0,0,0,0,0,0
0,0,0,0,0,0,0,0,0,0,0,0,0,0,0,0,0,0,0,0,0,0,0,0,0,0,0,0,0,0,0,0,0,0,0,0,0,0,0,0,0
0,0,0,0,0,0,0,0,0,0,0,0,0,0,0,0,0,0,0,0,0,0,0,0,0,0,0,0,0,0,0,0,0,0,0,0,0,0,0,0,0
0,0,0,0,0,0,0,0,0,0,0,0,0,0,0,0,0,0,0,0,0,0,0,0,0,0,0,0,0,0,0,0,0,0,0,0,0,0,0,0,0
0,0,0,0,0,0,0,0,0,0,0,0,0,0,0,0,0,0,0,0,0,0,0,0,0,0,0,0,0,0,0,0,0,0,0,0,0,0,0,0,0
0,0,0,0,0,0,0,0,0,0,0,0,0,0,0,0,0,0,0,0,0,0,0,0,0,0,0,0,0,0,0,0,0,0,0,0,0,0,0,0,0
0,0,0,0,0,0,0,0,0,0,0,0,0,0,0,0,0,0,0,0,0,0,0,0,0,0,0,0,0,0,0,0,0,0,0,0,0,0,0,0,0
0,0,0,0,0,0,0,0,0,0,0,0,0,0,0,0,0,0,0,0,0,0,0,0,0,0,0,0,0,0,0,0,0,0,0,0,0,0,0,0,0
0,0,0,0,0,0,0,0,0,0,0,0,0,0,0,0,0,0,0,0,0,0,0,0,0,0,0,0,0,0,0,0,0,0,0,0,0,0,0,0,0
0,0,0,0,0,0,0,0,0,0,0,0,0,0,0,0,0,0,0,0,0,0,0,0,0,0,0,0,0,0,0,0,0,0,0,0,0,0,0,0,0
0,0,0,0,0,0,0,0,0,0,0,0,0,0,0,0,0,0,0,0,0,0,0,0,0,0,0,0,0,0,0,0,0,0,0,0,0,0,0,0,0
0,0,0,0,0,0,0,0,0,0,0,0,0,0,0,0,0,0,0,0,0,0,0,0,0,0,0,0,0,0,0,0,0,0,0,0,0,0,0,0,0
0,0,0,0,0,0,0,0,0,0,0,0,0,0,0,0,0,0,0,0,0,0,0,0,0,0,0,0,0,0,0,0,0,0,0,0,0,0,0,0,0
0,0,0,0,0,0,0,0,0,0,0,0,0,0,0,0,0,0,0,0,0,0,0,0,0,0,0,0,0,0,0,0,0,0,0,0,0,0,0,0,0
0,0,0,0,0,0,0,0,0,0,0,0,0,0,0,0,0,0,0,0,0,0,0,0,0,0,0,0,0,0,0,0,0,0,0,0,0,0,0,0,0
0,0,0,0,0,0,0,0,0,0,0,0,0,0,0,0,0,0,0,0,0,0,0,0,0,0,0,0,0,0,0,0,0,0,0,0,0,0,0,0,0
0,0,0,0,0,0,0,0,0,0,0,0,0,0,0,0,0,0,0,0,0,0,0,0,0,0,0,0,0,0,0,0,0,0,0,0,0,0,0,0,0
0,0,0,0,0,0,0,0,0,0,0,0,0,0,0,0,0,0,0,0,0,0,0,0,0,0,0,0,0,0,0,0,0,0,0,0,0,0,0,0,0
endlayer

layer
0,0,0,0,0,0,0,0,0,0,0,0,0,0,0,0,0,0,0,0,0,0,0,0,0,0,0,0,0,0,0,0,0,0,0,0,0,0,0,0,0
0,0,0,0,0,0,0,0,0,0,0,0,0,0,0,0,0,0,0,0,0,0,0,0,0,0,0,0,0,0,0,0,0,0,0,0,0,0,0,0,0
0,0,0,0,0,0,0,0,0,0,0,0,0,0,0,0,0,0,0,0,0,0,0,0,0,0,0,0,0,0,0,0,0,0,0,0,0,0,0,0,0
0,0,0,0,0,0,0,0,0,0,0,0,0,0,0,0,0,0,0,0,0,0,0,0,0,0,0,0,0,0,0,0,0,0,0,0,0,0,0,0,0
0,0,0,0,0,0,0,0,0,0,0,0,0,0,0,0,0,0,0,0,0,0,0,0,0,0,0,0,0,0,0,0,0,0,0,0,0,0,0,0,0
0,0,0,0,0,0,0,0,0,0,0,0,0,0,0,0,0,0,0,0,0,0,0,0,0,0,0,0,0,0,0,0,0,0,0,0,0,0,0,0,0
0,0,0,0,0,0,0,0,0,0,0,0,0,0,0,0,0,0,0,0,0,0,0,0,0,0,0,0,0,0,0,0,0,0,0,0,0,0,0,0,0
0,0,0,0,0,0,0,0,0,0,0,0,0,0,0,0,0,0,0,0,0,0,0,0,0,0,0,0,0,0,0,0,0,0,0,0,0,0,0,0,0
0,0,0,0,0,0,0,0,0,0,0,0,0,0,0,0,0,0,0,0,0,0,0,0,0,0,0,0,0,0,0,0,0,0,0,0,0,0,0,0,0
0,0,0,0,0,0,0,0,0,0,0,0,0,0,0,0,0,0,0,0,0,0,0,0,0,0,0,0,0,0,0,0,0,0,0,0,0,0,0,0,0
0,0,0,0,0,0,0,0,0,0,0,0,0,0,0,0,0,0,0,0,0,0,0,0,0,0,0,0,0,0,0,0,0,0,0,0,0,0,0,0,0
0,0,0,0,0,0,0,0,0,0,0,0,0,0,0,0,0,0,0,0,0,0,0,0,0,0,0,0,0,0,0,0,0,0,0,0,0,0,0,0,0
0,0,0,0,0,0,0,0,0,0,0,0,0,0,0,0,0,0,0,0,0,0,0,0,0,0,0,0,0,0,0,0,0,0,0,0,0,0,0,0,0
0,0,0,0,0,0,0,0,0,0,0,0,0,0,0,0,0,0,0,0,0,0,0,0,0,0,0,0,0,0,0,0,0,0,0,0,0,0,0,0,0
0,0,0,0,0,0,0,0,0,0,0,0,0,0,0,0,0,0,0,0,0,0,0,0,0,0,0,0,0,0,0,0,0,0,0,0,0,0,0,0,0
0,0,0,0,0,0,0,0,0,0,0,0,0,0,0,0,0,0,0,0,0,0,0,0,0,0,0,0,0,0,0,0,0,0,0,0,0,0,0,0,0
0,0,0,0,0,0,0,0,0,0,0,0,0,0,0,0,0,0,0,1,1,1,0,0,0,0,0,0,0,0,0,0,0,0,0,0,0,0,0,0,0
0,0,0,0,0,0,0,0,0,0,0,0,0,0,0,0,0,1,1,2,2,2,1,1,0,0,0,0,0,0,0,0,0,0,0,0,0,0,0,0,0
0,0,0,0,0,0,0,0,0,0,0,0,0,0,0,0,0,1,2,2,2,2,2,1,0,0,0,0,0,0,0,0,0,0,0,0,0,0,0,0,0
0,0,0,0,0,0,0,0,0,0,0,0,0,0,0,0,1,2,3,3,2,2,2,2,1,0,0,0,0,0,0,0,0,0,0,0,0,0,0,0,0
0,0,0,0,0,0,0,0,0,0,0,0,0,0,0,0,1,2,3,3,4,2,2,2,1,0,0,0,0,0,0,0,0,0,0,0,0,0,0,0,0
0,0,0,0,0,0,0,0,0,0,0,0,0,0,0,0,1,2,3,3,3,3,2,2,1,0,0,0,0,0,0,0,0,0,0,0,0,0,0,0,0
0,0,0,0,0,0,0,0,0,0,0,0,0,0,0,0,0,1,2,3,3,3,2,1,0,0,0,0,0,0,0,0,0,0,0,0,0,0,0,0,0
0,0,0,0,0,0,0,0,0,0,0,0,0,0,0,0,0,1,1,2,2,2,1,1,0,0,0,0,0,0,0,0,0,0,0,0,0,0,0,0,0
0,0,0,0,0,0,0,0,0,0,0,0,0,0,0,0,0,0,0,1,1,1,0,0,0,0,0,0,0,0,0,0,0,0,0,0,0,0,0,0,0
0,0,0,0,0,0,0,0,0,0,0,0,0,0,0,0,0,0,0,0,0,0,0,0,0,0,0,0,0,0,0,0,0,0,0,0,0,0,0,0,0
0,0,0,0,0,0,0,0,0,0,0,0,0,0,0,0,0,0,0,0,0,0,0,0,0,0,0,0,0,0,0,0,0,0,0,0,0,0,0,0,0
0,0,0,0,0,0,0,0,0,0,0,0,0,0,0,0,0,0,0,0,0,0,0,0,0,0,0,0,0,0,0,0,0,0,0,0,0,0,0,0,0
0,0,0,0,0,0,0,0,0,0,0,0,0,0,0,0,0,0,0,0,0,0,0,0,0,0,0,0,0,0,0,0,0,0,0,0,0,0,0,0,0
0,0,0,0,0,0,0,0,0,0,0,0,0,0,0,0,0,0,0,0,0,0,0,0,0,0,0,0,0,0,0,0,0,0,0,0,0,0,0,0,0
0,0,0,0,0,0,0,0,0,0,0,0,0,0,0,0,0,0,0,0,0,0,0,0,0,0,0,0,0,0,0,0,0,0,0,0,0,0,0,0,0
0,0,0,0,0,0,0,0,0,0,0,0,0,0,0,0,0,0,0,0,0,0,0,0,0,0,0,0,0,0,0,0,0,0,0,0,0,0,0,0,0
0,0,0,0,0,0,0,0,0,0,0,0,0,0,0,0,0,0,0,0,0,0,0,0,0,0,0,0,0,0,0,0,0,0,0,0,0,0,0,0,0
0,0,0,0,0,0,0,0,0,0,0,0,0,0,0,0,0,0,0,0,0,0,0,0,0,0,0,0,0,0,0,0,0,0,0,0,0,0,0,0,0
0,0,0,0,0,0,0,0,0,0,0,0,0,0,0,0,0,0,0,0,0,0,0,0,0,0,0,0,0,0,0,0,0,0,0,0,0,0,0,0,0
0,0,0,0,0,0,0,0,0,0,0,0,0,0,0,0,0,0,0,0,0,0,0,0,0,0,0,0,0,0,0,0,0,0,0,0,0,0,0,0,0
0,0,0,0,0,0,0,0,0,0,0,0,0,0,0,0,0,0,0,0,0,0,0,0,0,0,0,0,0,0,0,0,0,0,0,0,0,0,0,0,0
0,0,0,0,0,0,0,0,0,0,0,0,0,0,0,0,0,0,0,0,0,0,0,0,0,0,0,0,0,0,0,0,0,0,0,0,0,0,0,0,0
0,0,0,0,0,0,0,0,0,0,0,0,0,0,0,0,0,0,0,0,0,0,0,0,0,0,0,0,0,0,0,0,0,0,0,0,0,0,0,0,0
0,0,0,0,0,0,0,0,0,0,0,0,0,0,0,0,0,0,0,0,0,0,0,0,0,0,0,0,0,0,0,0,0,0,0,0,0,0,0,0,0
0,0,0,0,0,0,0,0,0,0,0,0,0,0,0,0,0,0,0,0,0,0,0,0,0,0,0,0,0,0,0,0,0,0,0,0,0,0,0,0,0
endlayer

layer
0,0,0,0,0,0,0,0,0,0,0,0,0,0,0,0,0,0,0,0,0,0,0,0,0,0,0,0,0,0,0,0,0,0,0,0,0,0,0,0,0
0,0,0,0,0,0,0,0,0,0,0,0,0,0,0,0,0,0,0,0,0,0,0,0,0,0,0,0,0,0,0,0,0,0,0,0,0,0,0,0,0
0,0,0,0,0,0,0,0,0,0,0,0,0,0,0,0,0,0,0,0,0,0,0,0,0,0,0,0,0,0,0,0,0,0,0,0,0,0,0,0,0
0,0,0,0,0,0,0,0,0,0,0,0,0,0,0,0,0,0,0,0,0,0,0,0,0,0,0,0,0,0,0,0,0,0,0,0,0,0,0,0,0
0,0,0,0,0,0,0,0,0,0,0,0,0,0,0,0,0,0,0,0,0,0,0,0,0,0,0,0,0,0,0,0,0,0,0,0,0,0,0,0,0
0,0,0,0,0,0,0,0,0,0,0,0,0,0,0,0,0,0,0,0,0,0,0,0,0,0,0,0,0,0,0,0,0,0,0,0,0,0,0,0,0
0,0,0,0,0,0,4,0,0,0,0,0,0,0,0,0,0,0,0,0,0,0,0,0,0,0,0,0,0,0,0,0,0,0,4,0,0,0,0,0,0
0,0,0,0,0,0,0,0,0,0,0,0,0,0,0,0,0,0,0,0,0,0,0,0,0,0,0,0,0,0,0,0,0,0,0,0,0,0,0,0,0
0,0,0,0,0,0,0,0,0,0,0,0,0,0,0,0,0,0,0,0,0,0,0,0,0,0,0,0,0,0,0,0,0,0,0,0,0,0,0,0,0
0,0,0,0,0,0,0,0,0,0,0,0,0,0,0,0,0,0,0,0,0,0,0,0,0,0,0,0,0,0,0,0,0,0,0,0,0,0,0,0,0
0,0,0,0,0,0,0,0,0,0,0,0,0,0,0,0,0,0,0,0,0,0,0,0,0,0,0,0,0,0,0,0,0,0,0,0,0,0,0,0,0
0,0,0,0,0,0,0,0,0,0,0,0,0,0,0,0,0,0,0,0,0,0,0,0,0,0,0,0,0,0,0,0,0,0,0,0,0,0,0,0,0
0,0,0,0,0,0,0,0,0,0,0,0,0,0,0,0,0,0,0,0,0,0,0,0,0,0,0,0,0,0,0,0,0,0,0,0,0,0,0,0,0
0,0,0,0,0,0,0,0,0,0,0,0,0,0,0,0,0,0,0,0,0,0,0,0,0,0,0,0,0,0,0,0,0,0,0,0,0,0,0,0,0
0,0,0,0,0,0,0,0,0,0,0,0,0,0,0,0,0,0,0,0,0,0,0,0,0,0,0,0,0,0,0,0,0,0,0,0,0,0,0,0,0
0,0,0,0,0,0,0,0,0,0,0,0,0,0,0,0,0,0,0,0,0,0,0,0,0,0,0,0,0,0,0,0,0,0,0,0,0,0,0,0,0
0,0,0,0,0,0,0,0,0,0,0,0,0,0,0,0,0,0,0,5,5,5,0,0,0,0,0,0,0,0,0,0,0,0,0,0,0,0,0,0,0
0,0,0,0,0,0,0,0,0,0,0,0,0,0,0,0,0,5,5,2,2,2,5,6,0,0,0,0,0,0,0,0,0,0,0,0,0,0,0,0,0
0,0,0,0,0,0,0,0,0,0,0,0,0,0,0,0,0,8,2,0,2,7,2,6,0,0,0,0,0,0,0,0,0,0,0,0,0,0,0,0,0
0,0,0,0,0,0,0,0,0,0,0,0,0,0,0,0,8,2,11,11,2,10,9,2,6,0,0,0,0,0,0,0,0,0,0,0,0,0,0,0,0
0,0,0,0,0,0,0,0,0,0,0,0,0,0,0,0,8,0,11,11,2,2,2,2,6,0,0,0,0,0,0,0,0,0,0,0,0,0,0,0,0
0,0,0,0,0,0,0,0,0,0,0,0,0,0,0,0,8,2,11,11,11,11,12,2,6,0,0,0,0,0,0,0,0,0,0,0,0,0,0,0,0
0,0,0,0,0,0,0,0,0,0,0,0,0,0,0,0,0,8,2,11,11,11,2,6,0,0,0,0,0,0,0,0,0,0,0,0,0,0,0,0,0
0,0,0,0,0,0,0,0,0,0,0,0,0,0,0,0,0,8,13,2,2,2,13,13,0,0,0,0,0,0,0,0,0,0,0,0,0,0,0,0,0
0,0,0,0,0,0,0,0,0,0,0,0,0,0,0,0,0,0,0,13,13,13,0,0,0,0,0,0,0,0,0,0,0,0,0,0,0,0,0,0,0
0,0,0,0,0,0,0,0,0,0,0,0,0,0,0,0,0,0,0,0,0,0,0,0,0,0,0,0,0,0,0,0,0,0,0,0,0,0,0,0,0
0,0,0,0,0,0,0,0,0,0,0,0,0,0,0,0,0,0,0,0,0,0,0,0,0,0,0,0,0,0,0,0,0,0,0,0,0,0,0,0,0
0,0,0,0,0,0,0,0,0,0,0,0,0,0,0,0,0,0,0,0,0,0,0,0,0,0,0,0,0,0,0,0,0,0,0,0,0,0,0,0,0
0,0,0,0,0,0,0,0,0,0,0,0,0,0,0,0,0,0,0,0,0,0,0,0,0,0,0,0,0,0,0,0,0,0,0,0,0,0,0,0,0
0,0,0,0,0,0,0,0,0,0,0,0,0,0,0,0,0,0,0,0,0,0,0,0,0,0,0,0,0,0,0,0,0,0,0,0,0,0,0,0,0
0,0,0,0,0,0,0,0,0,0,0,0,0,0,0,0,0,0,0,0,0,0,0,0,0,0,0,0,0,0,0,0,0,0,0,0,0,0,0,0,0
0,0,0,0,0,0,0,0,0,0,0,0,0,0,0,0,0,0,0,0,0,0,0,0,0,0,0,0,0,0,0,0,0,0,0,0,0,0,0,0,0
0,0,0,0,0,0,0,0,0,0,0,0,0,0,0,0,0,0,0,0,0,0,0,0,0,0,0,0,0,0,0,0,0,0,0,0,0,0,0,0,0
0,0,0,0,0,0,0,0,0,0,0,0,0,0,0,0,0,0,0,0,0,0,0,0,0,0,0,0,0,0,0,0,0,0,0,0,0,0,0,0,0
0,0,0,0,0,0,4,0,0,0,0,0,0,0,0,0,0,0,0,0,0,0,0,0,0,0,0,0,0,0,0,0,0,0,4,0,0,0,0,0,0
0,0,0,0,0,0,0,0,0,0,0,0,0,0,0,0,0,0,0,0,0,0,0,0,0,0,0,0,0,0,0,0,0,0,0,0,0,0,0,0,0
0,0,0,0,0,0,0,0,0,0,0,0,0,0,0,0,0,0,0,0,0,0,0,0,0,0,0,0,0,0,0,0,0,0,0,0,0,0,0,0,0
0,0,0,0,0,0,0,0,0,0,0,0,0,0,0,0,0,0,0,0,0,0,0,0,0,0,0,0,0,0,0,0,0,0,0,0,0,0,0,0,0
0,0,0,0,0,0,0,0,0,0,0,0,0,0,0,0,0,0,0,0,0,0,0,0,0,0,0,0,0,0,0,0,0,0,0,0,0,0,0,0,0
0,0,0,0,0,0,0,0,0,0,0,0,0,0,0,0,0,0,0,0,0,0,0,0,0,0,0,0,0,0,0,0,0,0,0,0,0,0,0,0,0
0,0,0,0,0,0,0,0,0,0,0,0,0,0,0,0,0,0,0,0,0,0,0,0,0,0,0,0,0,0,0,0,0,0,0,0,0,0,0,0,0
endlayer

layer
0,0,0,0,0,0,0,0,0,0,0,0,0,0,0,0,0,0,0,0,0,0,0,0,0,0,0,0,0,0,0,0,0,0,0,0,0,0,0,0,0
0,0,0,0,0,0,0,0,0,0,0,0,0,0,0,0,0,0,0,0,0,0,0,0,0,0,0,0,0,0,0,0,0,0,0,0,0,0,0,0,0
0,0,0,0,0,0,0,0,0,0,0,0,0,0,0,0,0,0,0,0,0,0,0,0,0,0,0,0,0,0,0,0,0,0,0,0,0,0,0,0,0
0,0,0,0,0,0,0,0,0,0,0,0,0,0,0,0,0,0,0,0,0,0,0,0,0,0,0,0,0,0,0,0,0,0,0,0,0,0,0,0,0
0,0,0,0,0,0,0,0,0,0,0,0,0,0,0,0,0,0,0,0,0,0,0,0,0,0,0,0,0,0,0,0,0,0,0,0,0,0,0,0,0
0,0,0,0,0,15,15,14,0,0,0,0,0,0,0,0,0,0,0,0,0,0,0,0,0,0,0,0,0,0,0,0,0,15,15,14,0,0,0,0,0
0,0,0,0,0,17,16,14,0,0,0,0,0,0,0,0,0,0,0,0,0,0,0,0,0,0,0,0,0,0,0,0,0,17,16,14,0,0,0,0,0
0,0,0,0,0,17,18,14,0,0,0,0,0,0,0,0,0,0,0,0,0,0,0,0,0,0,0,0,0,0,0,0,0,17,18,14,0,0,0,0,0
0,0,0,0,0,0,0,0,0,0,0,0,0,0,0,0,0,0,0,0,0,0,0,0,0,0,0,0,0,0,0,0,0,0,0,0,0,0,0,0,0
0,0,0,0,0,0,0,0,0,0,0,0,0,0,0,0,0,0,0,0,0,0,0,0,0,0,0,0,0,0,0,0,0,0,0,0,0,0,0,0,0
0,0,0,0,0,0,0,0,0,0,0,0,0,0,0,0,0,0,0,0,0,0,0,0,0,0,0,0,0,0,0,0,0,0,0,0,0,0,0,0,0
0,0,0,0,0,0,0,0,0,0,0,0,0,0,0,0,0,0,0,0,0,0,0,0,0,0,0,0,0,0,0,0,0,0,0,0,0,0,0,0,0
0,0,0,0,0,0,0,0,0,0,0,0,0,0,0,0,0,0,0,0,0,0,0,0,0,0,0,0,0,0,0,0,0,0,0,0,0,0,0,0,0
0,0,0,0,0,0,0,0,0,0,0,0,0,0,0,0,0,0,0,0,0,0,0,0,0,0,0,0,0,0,0,0,0,0,0,0,0,0,0,0,0
0,0,0,0,0,0,0,0,0,0,0,0,0,0,0,0,0,0,0,0,0,0,0,0,0,0,0,0,0,0,0,0,0,0,0,0,0,0,0,0,0
0,0,0,0,0,0,0,0,0,0,0,0,0,0,0,0,0,0,0,0,0,0,0,0,0,0,0,0,0,0,0,0,0,0,0,0,0,0,0,0,0
0,0,0,0,0,0,0,0,0,0,0,0,0,0,0,0,0,0,0,0,0,0,0,0,0,0,0,0,0,0,0,0,0,0,0,0,0,0,0,0,0
0,0,0,0,0,0,0,0,0,0,0,0,0,0,0,0,0,0,0,4,4,4,0,0,0,0,0,0,0,0,0,0,0,0,0,0,0,0,0,0,0
0,0,0,0,0,0,0,0,0,0,0,0,0,0,0,0,0,0,4,0,2,19,4,0,0,0,0,0,0,0,0,0,0,0,0,0,0,0,0,0,0
0,0,0,0,0,0,0,0,0,0,0,0,0,0,0,0,1,4,0,0,2,0,0,4,0,0,0,0,0,0,0,0,0,0,0,0,0,0,0,0,0
0,0,0,0,0,0,0,0,0,0,0,0,0,0,0,0,0,0,0,0,2,2,20,4,0,0,0,0,0,0,0,0,0,0,0,0,0,0,0,0,0
0,0,0,0,0,0,0,0,0,0,0,0,0,0,0,0,0,4,0,0,0,0,0,4,0,0,0,0,0,0,0,0,0,0,0,0,0,0,0,0,0
0,0,0,0,0,0,0,0,0,0,0,0,0,0,0,0,0,0,4,0,0,0,4,0,0,0,0,0,0,0,0,0,0,0,0,0,0,0,0,0,0
0,0,0,0,0,0,0,0,0,0,0,0,0,0,0,0,0,0,0,4,4,4,0,0,0,0,0,0,0,0,0,0,0,0,0,0,0,0,0,0,0
0,0,0,0,0,0,0,0,0,0,0,0,0,0,0,0,0,0,0,0,0,0,0,0,0,0,0,0,0,0,0,0,0,0,0,0,0,0,0,0,0
0,0,0,0,0,0,0,0,0,0,0,0,0,0,0,0,0,0,0,0,0,0,0,0,0,0,0,0,0,0,0,0,0,0,0,0,0,0,0,0,0
0,0,0,0,0,0,0,0,0,0,0,0,0,0,0,0,0,0,0,0,0,0,0,0,0,0,0,0,0,0,0,0,0,0,0,0,0,0,0,0,0
0,0,0,0,0,0,0,0,0,0,0,0,0,0,0,0,0,0,0,0,0,0,0,0,0,0,0,0,0,0,0,0,0,0,0,0,0,0,0,0,0
0,0,0,0,0,0,0,0,0,0,0,0,0,0,0,0,0,0,0,0,0,0,0,0,0,0,0,0,0,0,0,0,0,0,0,0,0,0,0,0,0
0,0,0,0,0,0,0,0,0,0,0,0,0,0,0,0,0,0,0,0,0,0,0,0,0,0,0,0,0,0,0,0,0,0,0,0,0,0,0,0,0
0,0,0,0,0,0,0,0,0,0,0,0,0,0,0,0,0,0,0,0,0,0,0,0,0,0,0,0,0,0,0,0,0,0,0,0,0,0,0,0,0
0,0,0,0,0,0,0,0,0,0,0,0,0,0,0,0,0,0,0,0,0,0,0,0,0,0,0,0,0,0,0,0,0,0,0,0,0,0,0,0,0
0,0,0,0,0,0,0,0,0,0,0,0,0,0,0,0,0,0,0,0,0,0,0,0,0,0,0,0,0,0,0,0,0,0,0,0,0,0,0,0,0
0,0,0,0,0,17,15,15,0,0,0,0,0,0,0,0,0,0,0,0,0,0,0,0,0,0,0,0,0,0,0,0,0,17,15,14,0,0,0,0,0
0,0,0,0,0,17,16,14,0,0,0,0,0,0,0,0,0,0,0,0,0,0,0,0,0,0,0,0,0,0,0,0,0,17,16,14,0,0,0,0,0
0,0,0,0,0,18,18,18,0,0,0,0,0,0,0,0,0,0,0,0,0,0,0,0,0,0,0,0,0,0,0,0,0,17,18,18,0,0,0,0,0
0,0,0,0,0,0,0,0,0,0,0,0,0,0,0,0,0,0,0,0,0,0,0,0,0,0,0,0,0,0,0,0,0,0,0,0,0,0,0,0,0
0,0,0,0,0,0,0,0,0,0,0,0,0,0,0,0,0,0,0,0,0,0,0,0,0,0,0,0,0,0,0,0,0,0,0,0,0,0,0,0,0
0,0,0,0,0,0,0,0,0,0,0,0,0,0,0,0,0,0,0,0,0,0,0,0,0,0,0,0,0,0,0,0,0,0,0,0,0,0,0,0,0
0,0,0,0,0,0,0,0,0,0,0,0,0,0,0,0,0,0,0,0,0,0,0,0,0,0,0,0,0,0,0,0,0,0,0,0,0,0,0,0,0
0,0,0,0,0,0,0,0,0,0,0,0,0,0,0,0,0,0,0,0,0,0,0,0,0,0,0,0,0,0,0,0,0,0,0,0,0,0,0,0,0
endlayer

layer
0,0,0,0,0,1,1,1,0,0,0,0,0,0,0,0,0,0,0,1,1,1,0,0,0,0,0,0,0,0,0,0,0,1,1,1,0,0,0,0,0
0,0,0,1,1,2,2,2,1,1,0,0,0,0,0,0,0,0,1,2,2,2,1,0,0,0,0,0,0,0,0,1,1,2,2,2,1,1,0,0,0
0,0,1,2,2,2,2,2,2,2,1,0,0,0,0,0,1,1,2,2,2,2,2,1,1,0,0,0,0,0,1,2,2,2,2,2,2,2,1,0,0
0,1,2,2,2,2,2,2,2,2,2,1,0,0,1,1,2,2,2,2,21,2,2,2,2,1,1,0,0,1,2,2,2,2,2,2,2,2,2,1,0
0,1,2,2,2,21,21,21,2,2,2,1,1,1,2,2,2,2,2,21,4,21,2,2,2,2,2,1,1,2,2,2,2,21,21,21,2,2,2,1,0
1,2,2,2,21,2,2,2,21,2,2,2,2,2,2,2,2,2,2,2,21,2,2,2,2,2,2,2,2,2,2,2,21,2,2,2,21,2,2,2,1
1,2,2,2,21,2,4,2,21,2,2,2,2,2,2,2,1,1,1,2,2,2,1,1,1,2,2,2,2,2,2,2,21,2,4,2,21,2,2,2,1
1,2,2,2,21,2,2,2,21,2,2,2,2,2,1,1,0,0,1,2,2,2,1,0,0,1,1,2,2,2,2,2,21,2,2,2,21,2,2,2,1
0,1,2,2,2,21,21,21,2,2,2,2,1,1,0,0,0,0,1,2,2,2,1,0,0,0,0,1,1,2,2,2,2,21,21,21,2,2,2,1,0
0,1,2,2,2,2,2,2,2,2,2,1,0,0,0,0,0,0,1,2,2,2,1,0,0,0,0,0,0,1,2,2,2,2,2,2,2,2,2,1,0
0,0,1,2,2,2,2,2,2,2,1,0,0,0,0,0,0,0,1,2,2,2,1,0,0,0,0,0,0,0,1,2,2,2,2,2,2,2,1,0,0
0,0,0,1,1,2,2,2,2,1,0,0,0,0,0,0,0,0,1,2,2,2,1,0,0,0,0,0,0,0,0,1,2,2,2,2,2,1,0,0,0
0,0,0,0,1,2,2,2,1,0,0,0,0,0,0,0,0,0,1,2,2,2,1,0,0,0,0,0,0,0,0,0,1,2,2,2,1,0,0,0,0
0,0,0,0,1,2,2,2,1,0,0,0,0,0,0,0,0,0,1,2,2,2,1,0,0,0,0,0,0,0,0,0,1,2,2,2,1,0,0,0,0
0,0,0,1,2,2,2,1,0,0,0,0,0,0,0,0,1,1,2,2,2,2,2,1,1,0,0,0,0,0,0,0,0,1,2,2,2,1,0,0,0
0,0,0,1,2,2,2,1,0,0,0,0,0,0,0,1,2,2,2,21,21,21,2,2,2,1,0,0,0,0,0,0,0,1,2,2,2,1,0,0,0
0,0,1,2,2,2,1,0,0,0,0,0,0,0,1,2,2,21,21,2,2,2,21,21,2,2,1,0,0,0,0,0,0,0,1,2,2,2,1,0,0
0,0,1,2,2,2,1,0,0,0,0,0,0,0,1,2,21,2,2,2,2,2,2,2,21,2,1,0,0,0,0,0,0,0,1,2,2,2,1,0,0
0,1,2,2,2,2,1,1,1,1,1,1,1,1,2,2,21,2,2,2,2,22,2,2,21,2,2,1,1,1,1,1,1,1,1,2,2,2,2,1,0
1,2,2,2,21,2,2,2,2,2,2,2,2,2,2,21,0,2,2,2,2,2,2,2,2,21,2,2,2,2,2,2,2,2,2,2,21,2,2,2,1
1,2,2,21,4,21,2,2,2,2,2,2,2,2,2,21,0,0,2,2,16,2,2,2,2,21,2,2,2,2,2,2,2,2,2,21,4,21,2,2,1
1,2,2,2,21,2,2,2,2,2,2,2,2,2,2,21,2,2,2,2,2,2,2,2,2,21,2,2,2,2,2,2,2,2,2,2,21,2,2,2,1
0,1,2,2,2,2,1,1,1,1,1,1,1,1,2,2,21,2,2,2,2,2,2,2,21,2,2,1,1,1,1,1,1,1,1,2,2,2,2,1,0
0,0,1,2,2,2,1,0,0,0,0,0,0,0,1,2,21,2,2,2,2,2,2,2,21,2,1,0,0,0,0,0,0,0,1,2,2,2,1,0,0
0,0,1,2,2,2,1,0,0,0,0,0,0,0,1,2,2,21,21,2,2,2,21,21,2,2,1,0,0,0,0,0,0,0,1,2,2,2,1,0,0
0,0,0,1,2,2,2,1,0,0,0,0,0,0,0,1,2,2,2,21,21,21,2,2,2,1,0,0,0,0,0,0,0,1,2,2,2,1,0,0,0
0,0,0,1,2,2,2,1,0,0,0,0,0,0,0,0,1,1,2,2,2,2,2,1,1,0,0,0,0,0,0,0,0,1,2,2,2,1,0,0,0
0,0,0,0,1,2,2,2,1,0,0,0,0,0,0,0,0,0,1,2,2,2,1,0,0,0,0,0,0,0,0,0,1,2,2,2,1,0,0,0,0
0,0,0,0,1,2,2,2,1,0,0,0,0,0,0,0,0,0,1,2,2,2,1,0,0,0,0,0,0,0,0,0,1,2,2,2,1,0,0,0,0
0,0,0,1,2,2,2,2,2,1,0,0,0,0,0,0,0,0,1,2,2,2,1,0,0,0,0,0,0,0,0,1,2,2,2,2,2,1,0,0,0
0,0,1,2,2,2,2,2,2,2,1,0,0,0,0,0,0,0,1,2,2,2,1,0,0,0,0,0,0,0,1,2,2,2,2,2,2,2,1,0,0
0,1,2,2,2,2,2,2,2,2,2,1,0,0,0,0,0,0,1,2,2,2,1,0,0,0,0,0,0,1,2,2,2,2,2,2,2,2,2,1,0
0,1,2,2,2,21,21,21,2,2,2,2,1,1,0,0,0,0,1,2,2,2,1,0,0,0,0,1,1,2,2,2,2,21,21,21,2,2,2,1,0
1,2,2,2,21,2,2,2,21,2,2,2,2,2,1,1,0,0,1,2,2,2,1,0,0,1,1,2,2,2,2,2,21,2,2,2,21,2,2,2,1
1,2,2,2,21,2,4,2,21,2,2,2,2,2,2,2,1,1,1,2,2,2,1,1,1,2,2,2,2,2,2,2,21,2,4,2,21,2,2,2,1
1,2,2,2,21,2,2,2,21,2,2,2,2,2,2,2,2,2,2,2,21,2,2,2,2,2,2,2,2,2,2,2,21,2,2,2,21,2,2,2,1
0,1,2,2,2,21,21,21,2,2,2,2,1,1,2,2,2,2,2,21,4,21,2,2,2,2,2,1,1,2,2,2,2,21,21,21,2,2,2,1,0
0,1,2,2,2,2,2,2,2,2,2,1,0,0,1,1,2,2,2,2,21,2,2,2,2,1,1,0,0,1,2,2,2,2,2,2,2,2,2,1,0
0,0,1,2,2,2,2,2,2,2,1,0,0,0,0,0,1,1,2,2,2,2,2,1,1,0,0,0,0,0,1,2,2,2,2,2,2,2,1,0,0
0,0,0,1,1,2,2,2,1,1,0,0,0,0,0,0,0,0,1,2,2,2,1,0,0,0,0,0,0,0,0,1,1,2,2,2,1,1,0,0,0
0,0,0,0,0,1,1,1,0,0,0,0,0,0,0,0,0,0,0,1,1,1,0,0,0,0,0,0,0,0,0,0,0,1,1,1,0,0,0,0,0
endlayer

layer
0,0,0,0,0,16,16,16,0,0,0,0,0,0,0,0,0,0,0,16,16,16,0,0,0,0,0,0,0,0,0,0,0,16,16,16,0,0,0,0,0
0,0,0,16,16,23,23,23,16,16,0,0,0,0,0,0,0,0,16,26,25,24,16,0,0,0,0,0,0,0,0,16,16,23,23,23,16,16,0,0,0
0,0,16,23,23,23,23,23,23,23,16,0,0,0,0,0,16,16,0,0,0,0,0,16,16,0,0,0,0,0,16,23,23,23,23,23,23,23,16,0,0
0,16,23,23,23,23,23,23,23,23,23,16,0,0,16,16,16,0,0,0,0,0,0,0,16,16,16,0,0,16,23,23,23,23,23,23,23,23,23,16,0
0,16,23,23,23,21,21,21,23,23,23,16,16,16,0,0,28,0,0,0,0,0,0,0,27,0,0,16,16,16,23,23,23,21,21,21,23,23,23,16,0
16,23,23,23,21,23,2,2,21,23,23,23,6,0,0,0,16,0,0,0,0,0,0,0,16,0,0,0,8,23,23,23,21,23,23,23,21,23,23,23,16
16,23,23,23,21,23,16,23,21,23,23,23,6,0,0,0,16,16,0,0,0,0,0,16,16,0,0,0,8,23,23,23,21,23,16,2,21,23,23,23,16
16,23,23,23,21,23,23,23,21,23,23,23,6,0,16,16,0,0,16,0,0,0,16,0,0,16,16,0,8,23,23,23,21,23,23,2,21,23,23,23,16
0,16,23,23,23,21,21,21,23,23,23,16,16,16,0,0,0,0,16,16,29,16,16,0,0,0,0,16,16,16,23,23,23,21,21,21,23,23,23,16,0
0,16,23,23,23,23,23,23,23,23,23,16,0,0,0,0,0,0,16,0,0,0,16,0,0,0,0,0,0,16,23,23,23,23,23,23,23,23,23,16,0
0,0,16,23,23,23,23,23,23,23,16,0,0,0,0,0,0,0,16,0,0,0,16,0,0,0,0,0,0,0,16,23,23,23,23,23,23,23,16,0,0
0,0,0,16,16,23,23,23,16,16,0,0,0,0,0,0,0,0,16,0,0,0,16,0,0,0,0,0,0,0,0,16,16,23,23,23,16,16,0,0,0
0,0,0,0,16,13,13,13,16,0,0,0,0,0,0,0,0,0,16,0,0,0,16,0,0,0,0,0,0,0,0,0,16,13,13,13,16,0,0,0,0
0,0,0,0,16,0,0,0,16,0,0,0,0,0,0,0,0,0,16,0,0,0,16,0,0,0,0,0,0,0,0,0,16,0,0,0,16,0,0,0,0
0,0,0,16,0,0,0,16,0,0,0,0,0,0,0,0,16,16,0,0,0,0,0,16,16,0,0,0,0,0,0,0,0,16,0,0,0,16,0,0,0
0,0,0,16,0,0,0,16,0,0,0,0,0,0,0,16,0,0,0,0,0,0,0,0,0,16,0,0,0,0,0,0,0,16,0,0,0,16,0,0,0
0,0,16,16,31,16,16,0,0,0,0,0,0,0,16,0,0,0,0,0,0,0,0,0,0,0,16,0,0,0,0,0,0,0,16,16,30,16,16,0,0
0,0,16,0,0,0,16,0,0,0,0,0,0,0,16,0,0,0,0,32,32,32,0,0,0,0,16,0,0,0,0,0,0,0,16,0,0,0,16,0,0
0,16,0,0,0,0,0,16,16,16,16,16,16,16,0,0,0,0,32,22,22,22,32,0,0,0,0,16,16,16,16,16,16,16,0,0,0,0,0,16,0
16,33,0,0,0,0,0,0,16,0,0,0,0,0,0,0,0,32,22,22,22,22,22,32,0,0,0,0,0,0,0,0,16,0,0,0,0,0,0,33,16
16,25,0,0,0,0,0,0,27,0,0,0,0,0,0,0,0,32,22,22,16,22,22,32,0,0,0,0,0,0,0,0,34,0,0,0,0,0,0,25,16
16,35,0,0,0,0,0,0,16,0,0,0,0,0,0,0,0,32,22,22,22,22,22,32,0,0,0,0,0,0,0,0,16,0,0,0,0,0,0,35,16
0,16,0,0,0,0,0,16,16,16,16,16,16,16,0,0,0,0,32,22,22,22,32,0,0,0,0,16,16,16,16,16,16,16,0,0,0,0,0,16,0
0,0,16,0,0,0,16,0,0,0,0,0,0,0,16,0,0,0,0,32,32,32,0,0,0,0,16,0,0,0,0,0,0,0,16,0,0,0,16,0,0
0,0,16,16,36,16,16,0,0,0,0,0,0,0,16,0,0,0,0,0,0,0,0,0,0,0,16,0,0,0,0,0,0,0,16,16,29,16,16,0,0
0,0,0,16,0,0,0,16,0,0,0,0,0,0,0,16,0,0,0,0,0,0,0,0,0,16,0,0,0,0,0,0,0,16,0,0,0,16,0,0,0
0,0,0,16,0,0,0,16,0,0,0,0,0,0,0,0,16,16,0,0,0,0,0,16,16,0,0,0,0,0,0,0,0,16,0,0,0,16,0,0,0
0,0,0,0,16,0,0,0,16,0,0,0,0,0,0,0,0,0,16,0,0,0,16,0,0,0,0,0,0,0,0,0,16,0,0,0,16,0,0,0,0
0,0,0,0,16,5,5,5,16,0,0,0,0,0,0,0,0,0,16,0,0,0,16,0,0,0,0,0,0,0,0,0,16,5,5,5,16,0,0,0,0
0,0,0,16,16,23,23,23,16,16,0,0,0,0,0,0,0,0,16,0,0,0,16,0,0,0,0,0,0,0,0,16,16,23,23,23,16,16,0,0,0
0,0,16,23,23,23,23,23,23,23,16,0,0,0,0,0,0,0,16,0,0,0,16,0,0,0,0,0,0,0,16,23,23,23,23,23,23,23,16,0,0
0,16,23,23,23,23,23,23,23,23,23,16,0,0,0,0,0,0,16,0,0,0,16,0,0,0,0,0,0,16,23,23,23,23,23,23,23,23,23,16,0
0,16,23,23,23,21,21,21,23,23,23,16,16,16,0,0,0,0,16,16,30,16,16,0,0,0,0,16,16,16,23,23,23,21,21,21,23,23,23,16,0
16,23,23,23,21,2,23,23,21,23,23,23,6,0,16,16,0,0,16,0,0,0,16,0,0,16,16,0,8,23,23,23,21,23,23,23,21,23,23,23,16
16,23,23,23,21,2,16,23,21,23,23,23,6,0,0,0,16,16,0,0,0,0,0,16,16,0,0,0,8,23,23,23,21,23,16,23,21,23,23,23,16
16,23,23,23,21,23,23,23,21,23,23,23,6,0,0,0,16,0,0,0,0,0,0,0,16,0,0,0,8,23,23,23,21,2,2,23,21,23,23,23,16
0,16,23,23,23,21,21,21,23,23,23,16,16,16,0,0,28,0,0,0,0,0,0,0,27,0,0,16,16,16,23,23,23,21,21,21,23,23,23,16,0
0,16,23,23,23,23,23,23,23,23,23,16,0,0,16,16,16,0,0,0,0,0,0,0,16,16,16,0,0,16,23,23,23,23,23,23,23,23,23,16,0
0,0,16,23,23,23,23,23,23,23,16,0,0,0,0,0,16,16,0,0,0,0,0,16,16,0,0,0,0,0,16,23,23,23,23,23,23,23,16,0,0
0,0,0,16,16,23,23,23,16,16,0,0,0,0,0,0,0,0,16,26,25,24,16,0,0,0,0,0,0,0,0,16,16,23,23,23,16,16,0,0,0
0,0,0,0,0,16,16,16,0,0,0,0,0,0,0,0,0,0,0,16,16,16,0,0,0,0,0,0,0,0,0,0,0,16,16,16,0,0,0,0,0
endlayer

layer
0,0,0,0,0,16,16,16,0,0,0,0,0,0,0,0,0,0,0,16,21,16,0,0,0,0,0,0,0,0,0,0,0,16,16,16,0,0,0,0,0
0,0,0,16,16,37,37,37,16,16,0,0,0,0,0,0,0,0,16,0,38,0,16,0,0,0,0,0,0,0,0,16,16,37,37,37,16,16,0,0,0
0,0,16,37,37,39,39,39,37,37,16,0,0,0,0,0,40,16,0,0,0,0,0,16,40,0,0,0,0,0,16,37,37,39,39,39,37,37,16,0,0
0,16,37,39,39,41,41,41,39,39,37,16,0,0,40,40,16,0,0,0,0,0,0,0,16,40,40,0,0,16,37,39,39,41,41,41,39,39,37,16,0
0,16,37,39,41,0,0,0,41,39,37,16,16,6,0,0,43,0,0,0,0,0,0,0,42,0,0,8,16,16,37,39,41,0,0,0,41,39,37,16,0
16,37,39,41,0,17,6,0,0,0,0,0,0,0,0,0,16,0,0,0,0,0,0,0,16,0,0,0,0,0,0,0,0,37,0,15,0,41,39,37,16
16,37,39,41,0,0,16,37,0,0,0,0,0,0,0,0,40,16,0,0,0,0,0,16,40,0,0,0,0,0,0,0,0,37,16,13,0,41,39,37,16
16,37,39,41,0,37,37,37,0,0,0,0,0,0,40,40,0,0,16,0,0,0,16,0,0,40,40,0,0,0,0,0,0,37,37,0,0,41,39,37,16
0,16,37,39,41,0,0,0,0,0,37,16,16,6,0,0,0,0,40,16,43,16,40,0,0,0,0,8,16,16,37,0,0,0,0,0,41,39,37,16,0
0,16,37,39,39,0,0,0,0,39,37,16,0,0,0,0,0,0,40,0,0,0,40,0,0,0,0,0,0,16,37,39,0,0,0,0,39,39,37,16,0
0,0,16,37,37,0,0,0,37,37,16,0,0,0,0,0,0,0,40,0,0,0,40,0,0,0,0,0,0,0,16,37,37,0,0,0,37,37,16,0,0
0,0,0,16,16,0,0,0,16,16,0,0,0,0,0,0,0,0,40,0,0,0,40,0,0,0,0,0,0,0,0,16,16,0,0,0,16,16,0,0,0
0,0,0,0,16,0,0,0,16,0,0,0,0,0,0,0,0,0,40,0,0,0,40,0,0,0,0,0,0,0,0,0,16,0,0,0,16,0,0,0,0
0,0,0,0,13,0,0,0,13,0,0,0,0,0,0,0,0,0,16,0,0,0,16,0,0,0,0,0,0,0,0,0,13,0,0,0,13,0,0,0,0
0,0,0,40,0,0,0,40,0,0,0,0,0,0,0,0,40,40,0,0,0,0,0,40,40,0,0,0,0,0,0,0,0,40,0,0,0,40,0,0,0
0,0,0,40,0,0,0,40,0,0,0,0,0,0,0,16,0,0,0,0,0,0,0,0,0,16,0,0,0,0,0,0,0,40,0,0,0,40,0,0,0
0,0,40,16,42,16,40,0,0,0,0,0,0,0,40,0,0,0,0,0,0,0,0,0,0,0,40,0,0,0,0,0,0,0,40,16,42,16,40,0,0
0,0,16,0,0,0,16,0,0,0,0,0,0,0,40,0,0,0,0,0,0,0,0,0,0,0,40,0,0,0,0,0,0,0,16,0,0,0,16,0,0
0,16,0,0,0,0,0,16,40,40,40,40,40,16,0,0,0,0,0,0,44,0,0,0,0,0,0,16,40,40,40,40,40,16,0,0,0,0,0,16,0
16,0,0,0,0,0,0,0,16,0,0,0,0,0,0,0,0,0,0,44,45,44,0,0,0,0,0,0,0,0,0,0,16,0,0,0,0,0,0,0,16
21,38,0,0,0,0,0,0,43,0,0,0,0,0,0,0,0,0,44,0,16,0,44,0,0,0,0,0,0,0,0,0,42,0,0,0,0,0,0,38,21
16,0,0,0,0,0,0,0,16,0,0,0,0,0,0,0,0,0,0,44,0,44,0,0,0,0,0,0,0,0,0,0,16,0,0,0,0,0,0,0,16
0,16,0,0,0,0,0,16,40,40,40,40,40,16,0,0,0,0,0,0,44,0,0,0,0,0,0,16,40,40,40,40,40,16,0,0,0,0,0,16,0
0,0,16,0,0,0,16,0,0,0,0,0,0,0,40,0,0,0,0,0,0,0,0,0,0,0,40,0,0,0,0,0,0,0,16,0,0,0,16,0,0
0,0,40,16,43,16,40,0,0,0,0,0,0,0,40,0,0,0,0,0,0,0,0,0,0,0,40,0,0,0,0,0,0,0,40,16,43,16,40,0,0
0,0,0,40,0,0,0,40,0,0,0,0,0,0,0,16,0,0,0,0,0,0,0,0,0,16,0,0,0,0,0,0,0,40,0,0,0,40,0,0,0
0,0,0,40,0,0,0,40,0,0,0,0,0,0,0,0,40,40,0,0,0,0,0,40,40,0,0,0,0,0,0,0,0,40,0,0,0,40,0,0,0
0,0,0,0,5,0,0,0,5,0,0,0,0,0,0,0,0,0,16,0,0,0,16,0,0,0,0,0,0,0,0,0,5,0,0,0,5,0,0,0,0
0,0,0,0,16,0,0,0,16,0,0,0,0,0,0,0,0,0,40,0,0,0,40,0,0,0,0,0,0,0,0,0,16,0,0,0,16,0,0,0,0
0,0,0,16,16,0,0,0,16,16,0,0,0,0,0,0,0,0,40,0,0,0,40,0,0,0,0,0,0,0,0,16,16,0,0,0,16,16,0,0,0
0,0,16,37,37,0,0,0,37,37,16,0,0,0,0,0,0,0,40,0,0,0,40,0,0,0,0,0,0,0,16,37,37,0,0,0,37,37,16,0,0
0,16,37,39,39,0,0,0,0,39,37,16,0,0,0,0,0,0,40,0,0,0,40,0,0,0,0,0,0,16,37,39,0,0,0,0,39,39,37,16,0
0,16,37,39,41,0,0,0,0,0,37,16,16,6,0,0,0,0,40,16,43,16,40,0,0,0,0,8,16,16,37,0,0,0,0,0,41,39,37,16,0
16,37,39,41,0,0,37,37,0,0,0,0,0,0,40,40,0,0,16,0,0,0,16,0,0,40,40,0,0,0,0,0,0,37,37,37,0,41,39,37,16
16,37,39,41,0,5,16,37,0,0,0,0,0,0,0,0,40,16,0,0,0,0,0,16,40,0,0,0,0,0,0,0,0,37,16,0,0,41,39,37,16
16,37,39,41,0,18,0,37,0,0,0,0,0,0,0,0,16,0,0,0,0,0,0,0,16,0,0,0,0,0,0,0,0,0,8,14,0,41,39,37,16
0,16,37,39,41,0,0,0,41,39,37,16,16,6,0,0,42,0,0,0,0,0,0,0,43,0,0,8,16,16,37,39,41,0,0,0,41,39,37,16,0
0,16,37,39,39,41,41,41,39,39,37,16,0,0,40,40,16,0,0,0,0,0,0,0,16,40,40,0,0,16,37,39,39,41,41,41,39,39,37,16,0
0,0,16,37,37,39,39,39,37,37,16,0,0,0,0,0,40,16,0,0,0,0,0,16,40,0,0,0,0,0,16,37,37,39,39,39,37,37,16,0,0
0,0,0,16,16,37,37,37,16,16,0,0,0,0,0,0,0,0,16,0,38,0,16,0,0,0,0,0,0,0,0,16,16,37,37,37,16,16,0,0,0
0,0,0,0,0,16,16,16,0,0,0,0,0,0,0,0,0,0,0,16,21,16,0,0,0,0,0,0,0,0,0,0,0,16,16,16,0,0,0,0,0
endlayer

layer
0,0,0,0,0,40,40,40,0,0,0,0,0,0,0,0,0,0,0,16,21,16,0,0,0,0,0,0,0,0,0,0,0,40,40,40,0,0,0,0,0
0,0,0,40,16,46,46,46,16,40,0,0,0,0,0,0,0,0,16,0,0,0,16,0,0,0,0,0,0,0,0,40,16,46,46,46,16,40,0,0,0
0,0,40,46,46,0,0,0,46,46,40,0,0,0,0,0,0,16,0,0,0,0,0,16,0,0,0,0,0,0,40,46,46,0,0,0,46,46,40,0,0
0,40,46,0,0,0,0,0,0,0,46,40,0,0,0,0,16,0,0,0,0,0,0,0,16,0,0,0,0,40,46,0,0,0,0,0,0,0,46,40,0
0,16,46,0,0,0,0,0,0,0,46,16,40,0,0,0,16,0,0,0,0,0,0,0,16,0,0,0,40,16,46,0,0,0,0,0,0,0,46,16,0
40,46,0,0,0,6,0,0,0,0,0,0,0,0,0,0,16,0,0,0,0,0,0,0,16,0,0,0,0,0,0,0,0,46,17,13,0,0,0,46,40
40,46,0,0,0,18,16,46,0,0,0,0,0,0,0,0,0,16,0,0,0,0,0,16,0,0,0,0,0,0,0,0,0,46,16,0,0,0,0,46,40
40,46,0,0,0,46,46,46,0,0,0,0,0,0,0,0,0,0,16,0,0,0,16,0,0,0,0,0,0,0,0,0,0,46,46,0,0,0,0,46,40
0,16,46,0,0,0,0,0,0,0,46,16,40,0,0,0,0,0,0,16,16,16,0,0,0,0,0,0,40,16,46,0,0,0,0,0,0,0,46,16,0
0,40,46,0,0,0,0,0,0,0,46,40,0,0,0,0,0,0,0,0,0,0,0,0,0,0,0,0,0,40,46,0,0,0,0,0,0,0,46,40,0
0,0,40,46,46,0,0,0,46,46,40,0,0,0,0,0,0,0,0,0,0,0,0,0,0,0,0,0,0,0,40,46,46,0,0,0,46,46,40,0,0
0,0,0,40,16,0,0,0,16,40,0,0,0,0,0,0,0,0,0,0,0,0,0,0,0,0,0,0,0,0,0,40,16,0,0,0,16,40,0,0,0
0,0,0,0,40,0,0,0,40,0,0,0,0,0,0,0,0,0,0,0,0,0,0,0,0,0,0,0,0,0,0,0,40,0,0,0,40,0,0,0,0
0,0,0,0,0,0,0,0,0,0,0,0,0,0,0,0,0,0,16,0,0,0,16,0,0,0,0,0,0,0,0,0,0,0,0,0,0,0,0,0,0
0,0,0,0,0,0,0,0,0,0,0,0,0,0,0,0,0,0,0,0,0,0,0,0,0,0,0,0,0,0,0,0,0,0,0,0,0,0,0,0,0
0,0,0,0,0,0,0,0,0,0,0,0,0,0,0,16,0,0,0,0,0,0,0,0,0,16,0,0,0,0,0,0,0,0,0,0,0,0,0,0,0
0,0,0,16,16,16,0,0,0,0,0,0,0,0,0,0,0,0,0,0,0,0,0,0,0,0,0,0,0,0,0,0,0,0,0,16,16,16,0,0,0
0,0,16,0,0,0,16,0,0,0,0,0,0,0,0,0,0,0,0,0,0,0,0,0,0,0,0,0,0,0,0,0,0,0,16,0,0,0,16,0,0
0,16,0,0,0,0,0,16,0,0,0,0,0,16,0,0,0,0,0,0,44,0,0,0,0,0,0,16,0,0,0,0,0,16,0,0,0,0,0,16,0
16,0,0,0,0,0,0,0,16,0,0,0,0,0,0,0,0,0,0,44,15,44,0,0,0,0,0,0,0,0,0,0,16,0,0,0,0,0,0,0,16
21,0,0,0,0,0,0,0,16,0,0,0,0,0,0,0,0,0,44,17,47,14,44,0,0,0,0,0,0,0,0,0,16,0,0,0,0,0,0,0,21
16,0,0,0,0,0,0,0,16,0,0,0,0,0,0,0,0,0,0,44,18,44,0,0,0,0,0,0,0,0,0,0,16,0,0,0,0,0,0,0,16
0,16,0,0,0,0,0,16,0,0,0,0,0,16,0,0,0,0,0,0,44,0,0,0,0,0,0,16,0,0,0,0,0,16,0,0,0,0,0,16,0
0,0,16,0,0,0,16,0,0,0,0,0,0,0,0,0,0,0,0,0,0,0,0,0,0,0,0,0,0,0,0,0,0,0,16,0,0,0,16,0,0
0,0,0,16,16,16,0,0,0,0,0,0,0,0,0,0,0,0,0,0,0,0,0,0,0,0,0,0,0,0,0,0,0,0,0,16,16,16,0,0,0
0,0,0,0,0,0,0,0,0,0,0,0,0,0,0,16,0,0,0,0,0,0,0,0,0,16,0,0,0,0,0,0,0,0,0,0,0,0,0,0,0
0,0,0,0,0,0,0,0,0,0,0,0,0,0,0,0,0,0,0,0,0,0,0,0,0,0,0,0,0,0,0,0,0,0,0,0,0,0,0,0,0
0,0,0,0,0,0,0,0,0,0,0,0,0,0,0,0,0,0,16,0,0,0,16,0,0,0,0,0,0,0,0,0,0,0,0,0,0,0,0,0,0
0,0,0,0,40,0,0,0,40,0,0,0,0,0,0,0,0,0,0,0,0,0,0,0,0,0,0,0,0,0,0,0,40,0,0,0,40,0,0,0,0
0,0,0,40,16,0,0,0,16,40,0,0,0,0,0,0,0,0,0,0,0,0,0,0,0,0,0,0,0,0,0,40,16,0,0,0,16,40,0,0,0
0,0,40,46,46,0,0,0,46,46,40,0,0,0,0,0,0,0,0,0,0,0,0,0,0,0,0,0,0,0,40,46,46,0,0,0,46,46,40,0,0
0,40,46,0,0,0,0,0,0,0,46,40,0,0,0,0,0,0,0,0,0,0,0,0,0,0,0,0,0,40,46,0,0,0,0,0,0,0,46,40,0
0,16,46,0,0,0,0,0,0,0,46,16,40,0,0,0,0,0,0,16,16,16,0,0,0,0,0,0,40,16,46,0,0,0,0,0,0,0,46,16,0
40,46,0,0,0,0,46,46,0,0,0,0,0,0,0,0,0,0,16,0,0,0,16,0,0,0,0,0,0,0,0,0,0,46,46,46,0,0,0,46,40
40,46,0,0,0,0,16,46,0,0,0,0,0,0,0,0,0,16,0,0,0,0,0,16,0,0,0,0,0,0,0,0,0,46,16,15,0,0,0,46,40
40,46,0,0,0,5,14,46,0,0,0,0,0,0,0,0,16,0,0,0,0,0,0,0,16,0,0,0,0,0,0,0,0,0,0,8,0,0,0,46,40
0,16,46,0,0,0,0,0,0,0,46,16,40,0,0,0,16,0,0,0,0,0,0,0,16,0,0,0,40,16,46,0,0,0,0,0,0,0,46,16,0
0,40,46,0,0,0,0,0,0,0,46,40,0,0,0,0,16,0,0,0,0,0,0,0,16,0,0,0,0,40,46,0,0,0,0,0,0,0,46,40,0
0,0,40,46,46,0,0,0,46,46,40,0,0,0,0,0,0,16,0,0,0,0,0,16,0,0,0,0,0,0,40,46,46,0,0,0,46,46,40,0,0
0,0,0,40,16,46,46,46,16,40,0,0,0,0,0,0,0,0,16,0,0,0,16,0,0,0,0,0,0,0,0,40,16,46,46,46,16,40,0,0,0
0,0,0,0,0,40,40,40,0,0,0,0,0,0,0,0,0,0,0,16,21,16,0,0,0,0,0,0,0,0,0,0,0,40,40,40,0,0,0,0,0
endlayer

layer
0,0,0,0,0,0,0,0,0,0,0,0,0,0,0,0,0,0,0,16,16,16,0,0,0,0,0,0,0,0,0,0,0,0,0,0,0,0,0,0,0
0,0,0,0,16,0,0,0,16,0,0,0,0,0,0,0,0,0,16,0,0,0,16,0,0,0,0,0,0,0,0,0,16,0,0,0,16,0,0,0,0
0,0,0,0,0,0,0,0,0,0,0,0,0,0,0,0,0,16,0,0,0,0,0,16,0,0,0,0,0,0,0,0,0,0,0,0,0,0,0,0,0
0,0,0,0,0,0,0,0,0,0,0,0,0,0,0,0,16,0,0,0,0,0,0,0,16,0,0,0,0,0,0,0,0,0,0,0,0,0,0,0,0
0,16,0,0,0,0,0,0,0,0,0,16,0,0,0,0,16,0,0,0,0,0,0,0,16,0,0,0,0,16,0,0,0,0,0,0,0,0,0,16,0
0,0,0,0,0,0,0,0,0,0,0,0,0,0,0,0,16,0,0,0,0,0,0,0,16,0,0,0,0,0,0,0,0,17,6,0,0,0,0,0,0
0,0,0,0,0,5,16,0,0,0,0,0,0,0,0,0,0,16,0,0,0,0,0,16,0,0,0,0,0,0,0,0,0,0,16,0,0,0,0,0,0
0,0,0,0,0,18,0,0,0,0,0,0,0,0,0,0,0,0,16,0,0,0,16,0,0,0,0,0,0,0,0,0,0,0,0,0,0,0,0,0,0
0,16,0,0,0,0,0,0,0,0,0,16,0,0,0,0,0,0,0,16,16,16,0,0,0,0,0,0,0,16,0,0,0,0,0,0,0,0,0,16,0
0,0,0,0,0,0,0,0,0,0,0,0,0,0,0,0,0,0,0,0,0,0,0,0,0,0,0,0,0,0,0,0,0,0,0,0,0,0,0,0,0
0,0,0,0,0,0,0,0,0,0,0,0,0,0,0,0,0,0,0,0,0,0,0,0,0,0,0,0,0,0,0,0,0,0,0,0,0,0,0,0,0
0,0,0,0,16,0,0,0,16,0,0,0,0,0,0,0,0,0,0,0,0,0,0,0,0,0,0,0,0,0,0,0,16,0,0,0,16,0,0,0,0
0,0,0,0,0,0,0,0,0,0,0,0,0,0,0,0,0,0,0,0,0,0,0,0,0,0,0,0,0,0,0,0,0,0,0,0,0,0,0,0,0
0,0,0,0,0,0,0,0,0,0,0,0,0,0,0,0,0,0,16,0,0,0,16,0,0,0,0,0,0,0,0,0,0,0,0,0,0,0,0,0,0
0,0,0,0,0,0,0,0,0,0,0,0,0,0,0,0,0,0,0,0,0,0,0,0,0,0,0,0,0,0,0,0,0,0,0,0,0,0,0,0,0
0,0,0,0,0,0,0,0,0,0,0,0,0,0,0,16,0,0,0,0,0,0,0,0,0,16,0,0,0,0,0,0,0,0,0,0,0,0,0,0,0
0,0,0,16,16,16,0,0,0,0,0,0,0,0,0,0,0,0,0,0,0,0,0,0,0,0,0,0,0,0,0,0,0,0,0,16,16,16,0,0,0
0,0,16,0,0,0,16,0,0,0,0,0,0,0,0,0,0,0,0,0,0,0,0,0,0,0,0,0,0,0,0,0,0,0,16,0,0,0,16,0,0
0,16,0,0,0,0,0,16,0,0,0,0,0,16,0,0,0,0,0,0,45,0,0,0,0,0,0,16,0,0,0,0,0,16,0,0,0,0,0,16,0
16,0,0,0,0,0,0,0,16,0,0,0,0,0,0,0,0,0,0,45,44,45,0,0,0,0,0,0,0,0,0,0,16,0,0,0,0,0,0,0,16
16,0,0,0,0,0,0,0,16,0,0,0,0,0,0,0,0,0,45,44,16,44,45,0,0,0,0,0,0,0,0,0,16,0,0,0,0,0,0,0,16
16,0,0,0,0,0,0,0,16,0,0,0,0,0,0,0,0,0,0,45,44,45,0,0,0,0,0,0,0,0,0,0,16,0,0,0,0,0,0,0,16
0,16,0,0,0,0,0,16,0,0,0,0,0,16,0,0,0,0,0,0,45,0,0,0,0,0,0,16,0,0,0,0,0,16,0,0,0,0,0,16,0
0,0,16,0,0,0,16,0,0,0,0,0,0,0,0,0,0,0,0,0,0,0,0,0,0,0,0,0,0,0,0,0,0,0,16,0,0,0,16,0,0
0,0,0,16,16,16,0,0,0,0,0,0,0,0,0,0,0,0,0,0,0,0,0,0,0,0,0,0,0,0,0,0,0,0,0,16,16,16,0,0,0
0,0,0,0,0,0,0,0,0,0,0,0,0,0,0,16,0,0,0,0,0,0,0,0,0,16,0,0,0,0,0,0,0,0,0,0,0,0,0,0,0
0,0,0,0,0,0,0,0,0,0,0,0,0,0,0,0,0,0,0,0,0,0,0,0,0,0,0,0,0,0,0,0,0,0,0,0,0,0,0,0,0
0,0,0,0,0,0,0,0,0,0,0,0,0,0,0,0,0,0,16,0,0,0,16,0,0,0,0,0,0,0,0,0,0,0,0,0,0,0,0,0,0
0,0,0,0,0,0,0,0,0,0,0,0,0,0,0,0,0,0,0,0,0,0,0,0,0,0,0,0,0,0,0,0,0,0,0,0,0,0,0,0,0
0,0,0,0,16,0,0,0,16,0,0,0,0,0,0,0,0,0,0,0,0,0,0,0,0,0,0,0,0,0,0,0,16,0,0,0,16,0,0,0,0
0,0,0,0,0,0,0,0,0,0,0,0,0,0,0,0,0,0,0,0,0,0,0,0,0,0,0,0,0,0,0,0,0,0,0,0,0,0,0,0,0
0,0,0,0,0,0,0,0,0,0,0,0,0,0,0,0,0,0,0,0,0,0,0,0,0,0,0,0,0,0,0,0,0,0,0,0,0,0,0,0,0
0,16,0,0,0,0,0,0,0,0,0,16,0,0,0,0,0,0,0,16,16,16,0,0,0,0,0,0,0,16,0,0,0,0,0,0,0,0,0,16,0
0,0,0,0,0,0,0,0,0,0,0,0,0,0,0,0,0,0,16,0,0,0,16,0,0,0,0,0,0,0,0,0,0,0,0,15,0,0,0,0,0
0,0,0,0,0,0,16,0,0,0,0,0,0,0,0,0,0,16,0,0,0,0,0,16,0,0,0,0,0,0,0,0,0,0,16,13,0,0,0,0,0
0,0,0,0,0,0,8,14,0,0,0,0,0,0,0,0,16,0,0,0,0,0,0,0,16,0,0,0,0,0,0,0,0,0,0,0,0,0,0,0,0
0,16,0,0,0,0,0,0,0,0,0,16,0,0,0,0,16,0,0,0,0,0,0,0,16,0,0,0,0,16,0,0,0,0,0,0,0,0,0,16,0
0,0,0,0,0,0,0,0,0,0,0,0,0,0,0,0,16,0,0,0,0,0,0,0,16,0,0,0,0,0,0,0,0,0,0,0,0,0,0,0,0
0,0,0,0,0,0,0,0,0,0,0,0,0,0,0,0,0,16,0,0,0,0,0,16,0,0,0,0,0,0,0,0,0,0,0,0,0,0,0,0,0
0,0,0,0,16,0,0,0,16,0,0,0,0,0,0,0,0,0,16,0,0,0,16,0,0,0,0,0,0,0,0,0,16,0,0,0,16,0,0,0,0
0,0,0,0,0,0,0,0,0,0,0,0,0,0,0,0,0,0,0,16,16,16,0,0,0,0,0,0,0,0,0,0,0,0,0,0,0,0,0,0,0
endlayer

layer
0,0,0,0,0,0,0,0,0,0,0,0,0,0,0,0,0,0,0,40,40,40,0,0,0,0,0,0,0,0,0,0,0,0,0,0,0,0,0,0,0
0,0,0,0,16,0,0,0,16,0,0,0,0,0,0,0,0,0,40,1,1,1,40,0,0,0,0,0,0,0,0,0,16,0,0,0,16,0,0,0,0
0,0,0,0,0,0,0,0,0,0,0,0,0,0,0,0,0,40,1,0,0,0,1,40,0,0,0,0,0,0,0,0,0,0,0,0,0,0,0,0,0
0,0,0,0,0,0,0,0,0,0,0,0,0,0,0,0,40,1,0,0,0,0,0,1,40,0,0,0,0,0,0,0,0,0,0,0,0,0,0,0,0
0,16,0,0,0,0,0,0,0,0,0,16,0,0,0,0,40,1,0,0,0,0,0,1,40,0,0,0,0,16,0,0,0,0,0,0,0,0,0,16,0
0,0,0,0,0,0,0,0,0,0,0,0,0,0,0,0,40,1,0,0,0,0,0,1,40,0,0,0,0,0,0,0,0,6,0,0,0,0,0,0,0
0,0,0,0,0,0,16,0,0,0,0,0,0,0,0,0,0,40,1,0,0,0,1,40,0,0,0,0,0,0,0,0,0,18,16,0,0,0,0,0,0
0,0,0,0,0,5,14,0,0,0,0,0,0,0,0,0,0,0,40,1,1,1,40,0,0,0,0,0,0,0,0,0,0,0,0,0,0,0,0,0,0
0,16,0,0,0,0,0,0,0,0,0,16,0,0,0,0,0,0,0,40,40,40,0,0,0,0,0,0,0,16,0,0,0,0,0,0,0,0,0,16,0
0,0,0,0,0,0,0,0,0,0,0,0,0,0,0,0,0,0,0,0,0,0,0,0,0,0,0,0,0,0,0,0,0,0,0,0,0,0,0,0,0
0,0,0,0,0,0,0,0,0,0,0,0,0,0,0,0,0,0,0,0,0,0,0,0,0,0,0,0,0,0,0,0,0,0,0,0,0,0,0,0,0
0,0,0,0,16,0,0,0,16,0,0,0,0,0,0,0,0,0,0,0,0,0,0,0,0,0,0,0,0,0,0,0,16,0,0,0,16,0,0,0,0
0,0,0,0,0,0,0,0,0,0,0,0,0,0,0,0,0,0,0,0,0,0,0,0,0,0,0,0,0,0,0,0,0,0,0,0,0,0,0,0,0
0,0,0,0,0,0,0,0,0,0,0,0,0,0,0,0,0,0,16,0,0,0,16,0,0,0,0,0,0,0,0,0,0,0,0,0,0,0,0,0,0
0,0,0,0,0,0,0,0,0,0,0,0,0,0,0,0,0,0,0,0,0,0,0,0,0,0,0,0,0,0,0,0,0,0,0,0,0,0,0,0,0
0,0,0,0,0,0,0,0,0,0,0,0,0,0,0,16,0,0,0,0,0,0,0,0,0,16,0,0,0,0,0,0,0,0,0,0,0,0,0,0,0
0,0,0,40,40,40,0,0,0,0,0,0,0,0,0,0,0,0,0,0,0,0,0,0,0,0,0,0,0,0,0,0,0,0,0,40,40,40,0,0,0
0,0,40,1,1,1,40,0,0,0,0,0,0,0,0,0,0,0,0,0,0,0,0,0,0,0,0,0,0,0,0,0,0,0,40,1,1,1,40,0,0
0,40,1,0,0,0,1,40,0,0,0,0,0,16,0,0,0,0,0,0,0,0,0,0,0,0,0,16,0,0,0,0,0,40,1,0,0,0,1,40,0
40,1,0,0,0,0,0,1,40,0,0,0,0,0,0,0,0,0,0,0,44,0,0,0,0,0,0,0,0,0,0,0,40,1,0,0,0,0,0,1,40
40,1,0,0,0,0,0,1,40,0,0,0,0,0,0,0,0,0,0,44,16,44,0,0,0,0,0,0,0,0,0,0,40,1,0,0,0,0,0,1,40
40,1,0,0,0,0,0,1,40,0,0,0,0,0,0,0,0,0,0,0,44,0,0,0,0,0,0,0,0,0,0,0,40,1,0,0,0,0,0,1,40
0,40,1,0,0,0,1,40,0,0,0,0,0,16,0,0,0,0,0,0,0,0,0,0,0,0,0,16,0,0,0,0,0,40,1,0,0,0,1,40,0
0,0,40,1,1,1,40,0,0,0,0,0,0,0,0,0,0,0,0,0,0,0,0,0,0,0,0,0,0,0,0,0,0,0,40,1,1,1,40,0,0
0,0,0,40,40,40,0,0,0,0,0,0,0,0,0,0,0,0,0,0,0,0,0,0,0,0,0,0,0,0,0,0,0,0,0,40,40,40,0,0,0
0,0,0,0,0,0,0,0,0,0,0,0,0,0,0,16,0,0,0,0,0,0,0,0,0,16,0,0,0,0,0,0,0,0,0,0,0,0,0,0,0
0,0,0,0,0,0,0,0,0,0,0,0,0,0,0,0,0,0,0,0,0,0,0,0,0,0,0,0,0,0,0,0,0,0,0,0,0,0,0,0,0
0,0,0,0,0,0,0,0,0,0,0,0,0,0,0,0,0,0,16,0,0,0,16,0,0,0,0,0,0,0,0,0,0,0,0,0,0,0,0,0,0
0,0,0,0,0,0,0,0,0,0,0,0,0,0,0,0,0,0,0,0,0,0,0,0,0,0,0,0,0,0,0,0,0,0,0,0,0,0,0,0,0
0,0,0,0,16,0,0,0,16,0,0,0,0,0,0,0,0,0,0,0,0,0,0,0,0,0,0,0,0,0,0,0,16,0,0,0,16,0,0,0,0
0,0,0,0,0,0,0,0,0,0,0,0,0,0,0,0,0,0,0,0,0,0,0,0,0,0,0,0,0,0,0,0,0,0,0,0,0,0,0,0,0
0,0,0,0,0,0,0,0,0,0,0,0,0,0,0,0,0,0,0,0,0,0,0,0,0,0,0,0,0,0,0,0,0,0,0,0,0,0,0,0,0
0,16,0,0,0,0,0,0,0,0,0,16,0,0,0,0,0,0,0,40,40,40,0,0,0,0,0,0,0,16,0,0,0,0,0,0,0,0,0,16,0
0,0,0,0,0,0,0,0,0,0,0,0,0,0,0,0,0,0,40,1,1,1,40,0,0,0,0,0,0,0,0,0,0,0,17,13,0,0,0,0,0
0,0,0,0,0,0,16,15,0,0,0,0,0,0,0,0,0,40,1,0,0,0,1,40,0,0,0,0,0,0,0,0,0,0,16,0,0,0,0,0,0
0,0,0,0,0,0,0,8,0,0,0,0,0,0,0,0,40,1,0,0,0,0,0,1,40,0,0,0,0,0,0,0,0,0,0,0,0,0,0,0,0
0,16,0,0,0,0,0,0,0,0,0,16,0,0,0,0,40,1,0,0,0,0,0,1,40,0,0,0,0,16,0,0,0,0,0,0,0,0,0,16,0
0,0,0,0,0,0,0,0,0,0,0,0,0,0,0,0,40,1,0,0,0,0,0,1,40,0,0,0,0,0,0,0,0,0,0,0,0,0,0,0,0
0,0,0,0,0,0,0,0,0,0,0,0,0,0,0,0,0,40,1,0,0,0,1,40,0,0,0,0,0,0,0,0,0,0,0,0,0,0,0,0,0
0,0,0,0,16,0,0,0,16,0,0,0,0,0,0,0,0,0,40,1,1,1,40,0,0,0,0,0,0,0,0,0,16,0,0,0,16,0,0,0,0
0,0,0,0,0,0,0,0,0,0,0,0,0,0,0,0,0,0,0,40,40,40,0,0,0,0,0,0,0,0,0,0,0,0,0,0,0,0,0,0,0
endlayer

layer
0,0,0,0,0,16,16,16,0,0,0,0,0,0,0,0,0,0,0,0,0,0,0,0,0,0,0,0,0,0,0,0,0,16,16,16,0,0,0,0,0
0,0,0,16,16,0,0,0,16,16,0,0,0,0,0,0,0,0,0,0,0,0,0,0,0,0,0,0,0,0,0,16,16,0,0,0,16,16,0,0,0
0,0,16,0,0,0,0,0,0,0,16,0,0,0,0,0,0,0,0,40,40,40,0,0,0,0,0,0,0,0,16,0,0,0,0,0,0,0,16,0,0
0,16,0,0,0,0,0,0,0,0,0,16,0,0,0,0,0,0,40,21,21,21,40,0,0,0,0,0,0,16,0,0,0,0,0,0,0,0,0,16,0
0,16,0,0,0,0,0,0,0,0,0,16,0,0,0,0,0,0,40,21,21,21,40,0,0,0,0,0,0,16,0,0,0,0,0,0,0,0,0,16,0
16,0,0,0,0,0,0,0,0,0,0,0,16,0,0,0,0,0,40,21,21,21,40,0,0,0,0,0,16,0,0,0,0,0,0,0,0,0,0,0,16
16,0,0,0,0,0,16,0,0,0,0,0,16,0,0,0,0,0,0,40,40,40,0,0,0,0,0,0,16,0,0,0,0,5,16,0,0,0,0,0,16
16,0,0,0,0,0,8,14,0,0,0,0,16,0,0,0,0,0,0,0,0,0,0,0,0,0,0,0,16,0,0,0,0,18,0,0,0,0,0,0,16
0,16,0,0,0,0,0,0,0,0,0,16,0,0,0,0,0,0,0,0,0,0,0,0,0,0,0,0,0,16,0,0,0,0,0,0,0,0,0,16,0
0,16,0,0,0,0,0,0,0,0,0,16,0,0,0,0,0,0,0,0,0,0,0,0,0,0,0,0,0,16,0,0,0,0,0,0,0,0,0,16,0
0,0,16,0,0,0,0,0,0,0,16,0,0,0,0,0,0,0,0,0,0,0,0,0,0,0,0,0,0,0,16,0,0,0,0,0,0,0,16,0,0
0,0,0,16,16,0,0,0,16,16,0,0,0,0,0,0,0,0,0,0,0,0,0,0,0,0,0,0,0,0,0,16,16,0,0,0,16,16,0,0,0
0,0,0,0,0,16,16,16,0,0,0,0,0,0,0,0,0,8,5,5,5,5,5,6,0,0,0,0,0,0,0,0,0,16,16,16,0,0,0,0,0
0,0,0,0,0,0,0,0,0,0,0,0,0,0,0,8,5,5,2,2,4,2,2,5,5,6,0,0,0,0,0,0,0,0,0,0,0,0,0,0,0
0,0,0,0,0,0,0,0,0,0,0,0,0,0,5,5,2,2,13,13,13,13,13,2,2,5,6,0,0,0,0,0,0,0,0,0,0,0,0,0,0
0,0,0,0,0,0,0,0,0,0,0,0,0,5,8,4,13,13,6,0,0,0,8,13,8,4,6,5,0,0,0,0,0,0,0,0,0,0,0,0,0
0,0,0,0,0,0,0,0,0,0,0,0,0,8,2,13,6,0,0,0,0,0,0,0,13,8,2,6,0,0,0,0,0,0,0,0,0,0,0,0,0
0,0,0,0,0,0,0,0,0,0,0,0,5,8,2,6,0,0,0,0,0,0,0,0,0,8,2,6,5,0,0,0,0,0,0,0,0,0,0,0,0
0,0,0,40,40,40,0,0,0,0,0,0,8,2,6,13,0,0,0,0,0,0,0,0,0,13,8,2,6,0,0,0,0,0,0,40,40,40,0,0,0
0,0,40,21,21,21,40,0,0,0,0,0,8,2,6,0,0,0,0,0,45,0,0,0,0,0,8,2,6,0,0,0,0,0,40,21,21,21,40,0,0
0,0,40,21,21,21,40,0,0,0,0,0,8,4,6,0,0,0,0,45,22,45,0,0,0,0,8,4,6,0,0,0,0,0,40,21,21,21,40,0,0
0,0,40,21,21,21,40,0,0,0,0,0,8,2,6,0,0,0,0,0,45,0,0,0,0,0,8,2,6,0,0,0,0,0,40,21,21,21,40,0,0
0,0,0,40,40,40,0,0,0,0,0,0,8,2,6,5,0,0,0,0,0,0,0,0,0,5,8,2,6,0,0,0,0,0,0,40,40,40,0,0,0
0,0,0,0,0,0,0,0,0,0,0,0,13,8,2,6,0,0,0,0,0,0,0,0,0,8,2,6,13,0,0,0,0,0,0,0,0,0,0,0,0
0,0,0,0,0,0,0,0,0,0,0,0,0,8,2,6,5,0,0,0,0,0,0,0,8,5,2,6,0,0,0,0,0,0,0,0,0,0,0,0,0
0,0,0,0,0,0,0,0,0,0,0,0,0,13,8,4,6,5,6,0,0,0,8,5,5,4,6,13,0,0,0,0,0,0,0,0,0,0,0,0,0
0,0,0,0,0,0,0,0,0,0,0,0,0,0,8,13,2,2,5,5,5,5,5,2,2,13,13,0,0,0,0,0,0,0,0,0,0,0,0,0,0
0,0,0,0,0,0,0,0,0,0,0,0,0,0,0,8,13,13,2,2,4,2,2,13,13,6,0,0,0,0,0,0,0,0,0,0,0,0,0,0,0
0,0,0,0,0,16,16,16,0,0,0,0,0,0,0,0,0,8,13,13,13,13,13,6,0,0,0,0,0,0,0,0,0,16,16,16,0,0,0,0,0
0,0,0,16,16,0,0,0,16,16,0,0,0,0,0,0,0,0,0,0,0,0,0,0,0,0,0,0,0,0,0,16,16,0,0,0,16,16,0,0,0
0,0,16,0,0,0,0,0,0,0,16,0,0,0,0,0,0,0,0,0,0,0,0,0,0,0,0,0,0,0,16,0,0,0,0,0,0,0,16,0,0
0,16,0,0,0,0,0,0,0,0,0,16,0,0,0,0,0,0,0,0,0,0,0,0,0,0,0,0,0,16,0,0,0,0,0,0,0,0,0,16,0
0,16,0,0,0,0,0,0,0,0,0,16,0,0,0,0,0,0,0,0,0,0,0,0,0,0,0,0,0,16,0,0,0,0,0,0,0,0,0,16,0
16,0,0,0,0,0,0,15,0,0,0,0,16,0,0,0,0,0,0,0,0,0,0,0,0,0,0,0,16,0,0,0,0,17,6,0,0,0,0,0,16
16,0,0,0,0,0,16,13,0,0,0,0,16,0,0,0,0,0,0,40,40,40,0,0,0,0,0,0,16,0,0,0,0,0,16,0,0,0,0,0,16
16,0,0,0,0,0,0,0,0,0,0,0,16,0,0,0,0,0,40,21,21,21,40,0,0,0,0,0,16,0,0,0,0,0,0,0,0,0,0,0,16
0,16,0,0,0,0,0,0,0,0,0,16,0,0,0,0,0,0,40,21,21,21,40,0,0,0,0,0,0,16,0,0,0,0,0,0,0,0,0,16,0
0,16,0,0,0,0,0,0,0,0,0,16,0,0,0,0,0,0,40,21,21,21,40,0,0,0,0,0,0,16,0,0,0,0,0,0,0,0,0,16,0
0,0,16,0,0,0,0,0,0,0,16,0,0,0,0,0,0,0,0,40,40,40,0,0,0,0,0,0,0,0,16,0,0,0,0,0,0,0,16,0,0
0,0,0,16,16,0,0,0,16,16,0,0,0,0,0,0,0,0,0,0,0,0,0,0,0,0,0,0,0,0,0,16,16,0,0,0,16,16,0,0,0
0,0,0,0,0,16,16,16,0,0,0,0,0,0,0,0,0,0,0,0,0,0,0,0,0,0,0,0,0,0,0,0,0,16,16,16,0,0,0,0,0
endlayer

layer
0,0,0,0,0,32,4,32,0,0,0,0,0,0,0,0,0,0,0,0,0,0,0,0,0,0,0,0,0,0,0,0,0,32,4,32,0,0,0,0,0
0,0,0,32,32,2,2,2,32,32,0,0,0,0,0,0,0,0,0,0,0,0,0,0,0,0,0,0,0,0,0,32,32,2,2,2,32,32,0,0,0
0,0,32,2,2,2,2,2,2,2,32,0,0,0,0,0,0,0,0,0,0,0,0,0,0,0,0,0,0,0,32,2,2,2,2,2,2,2,32,0,0
0,32,2,2,2,2,2,2,2,2,2,32,0,0,0,0,0,0,0,0,0,0,0,0,0,0,0,0,0,32,2,2,2,2,2,2,2,2,2,32,0
0,32,2,2,2,21,21,21,2,2,2,32,0,0,0,0,0,0,0,0,0,0,0,0,0,0,0,0,0,32,2,2,2,21,21,21,2,2,2,32,0
32,2,2,2,21,0,0,0,21,2,2,2,32,0,0,0,0,0,0,0,0,0,0,0,0,0,0,0,32,2,2,2,21,0,0,0,21,2,2,2,32
4,2,2,2,21,0,16,15,21,2,2,2,4,0,0,0,0,0,0,0,0,0,0,0,0,0,0,0,4,2,2,2,21,0,16,0,21,2,2,2,4
32,2,2,2,21,0,0,8,21,2,2,2,32,0,0,0,0,0,0,0,0,0,0,0,0,0,0,0,32,2,2,2,21,5,14,0,21,2,2,2,32
0,32,2,2,2,21,21,21,2,2,2,32,0,0,0,0,0,0,0,0,0,0,0,0,0,0,0,0,0,32,2,2,2,21,21,21,2,2,2,32,0
0,32,2,2,2,2,2,2,2,2,2,32,0,0,0,0,0,0,0,0,0,0,0,0,0,0,0,0,0,32,2,2,2,2,2,2,2,2,2,32,0
0,0,32,2,2,2,2,2,2,2,32,0,0,0,0,0,0,0,0,0,0,0,0,0,0,0,0,0,0,0,32,2,2,2,2,2,2,2,32,0,0
0,0,0,32,32,2,2,2,32,32,0,0,0,0,0,0,0,0,0,0,0,0,0,0,0,0,0,0,0,0,0,32,32,2,2,2,32,32,0,0,0
0,0,0,0,0,32,4,32,0,0,0,0,0,0,0,0,0,0,0,0,0,0,0,0,0,0,0,0,0,0,0,0,0,32,4,32,0,0,0,0,0
0,0,0,0,0,0,0,0,0,0,0,0,0,0,0,0,0,0,40,40,40,40,40,0,0,0,0,0,0,0,0,0,0,0,0,0,0,0,0,0,0
0,0,0,0,0,0,0,0,0,0,0,0,0,0,0,0,40,40,0,0,0,0,0,40,40,0,0,0,0,0,0,0,0,0,0,0,0,0,0,0,0
0,0,0,0,0,0,0,0,0,0,0,0,0,0,0,16,0,0,0,0,0,0,0,0,0,16,0,0,0,0,0,0,0,0,0,0,0,0,0,0,0
0,0,0,0,0,0,0,0,0,0,0,0,0,0,40,0,0,0,0,0,0,0,0,0,0,0,40,0,0,0,0,0,0,0,0,0,0,0,0,0,0
0,0,0,0,0,0,0,0,0,0,0,0,0,0,40,0,0,0,0,0,0,0,0,0,0,0,40,0,0,0,0,0,0,0,0,0,0,0,0,0,0
0,0,0,0,0,0,0,0,0,0,0,0,0,40,0,0,0,0,0,0,0,0,0,0,0,0,0,40,0,0,0,0,0,0,0,0,0,0,0,0,0
0,0,0,0,0,0,0,0,0,0,0,0,0,40,0,0,0,0,0,0,0,0,0,0,0,0,0,40,0,0,0,0,0,0,0,0,0,0,0,0,0
0,0,0,0,0,0,0,0,0,0,0,0,0,40,0,0,0,0,0,0,0,0,0,0,0,0,0,40,0,0,0,0,0,0,0,0,0,0,0,0,0
0,0,0,0,0,0,0,0,0,0,0,0,0,40,0,0,0,0,0,0,0,0,0,0,0,0,0,40,0,0,0,0,0,0,0,0,0,0,0,0,0
0,0,0,0,0,0,0,0,0,0,0,0,0,40,0,0,0,0,0,0,0,0,0,0,0,0,0,40,0,0,0,0,0,0,0,0,0,0,0,0,0
0,0,0,0,0,0,0,0,0,0,0,0,0,0,40,0,0,0,0,0,0,0,0,0,0,0,40,0,0,0,0,0,0,0,0,0,0,0,0,0,0
0,0,0,0,0,0,0,0,0,0,0,0,0,0,40,0,0,0,0,0,0,0,0,0,0,0,40,0,0,0,0,0,0,0,0,0,0,0,0,0,0
0,0,0,0,0,0,0,0,0,0,0,0,0,0,0,16,0,0,0,0,0,0,0,0,0,16,0,0,0,0,0,0,0,0,0,0,0,0,0,0,0
0,0,0,0,0,0,0,0,0,0,0,0,0,0,0,0,40,40,0,0,0,0,0,40,40,0,0,0,0,0,0,0,0,0,0,0,0,0,0,0,0
0,0,0,0,0,0,0,0,0,0,0,0,0,0,0,0,0,0,40,40,40,40,40,0,0,0,0,0,0,0,0,0,0,0,0,0,0,0,0,0,0
0,0,0,0,0,32,4,32,0,0,0,0,0,0,0,0,0,0,0,0,0,0,0,0,0,0,0,0,0,0,0,0,0,32,4,32,0,0,0,0,0
0,0,0,32,32,2,2,2,32,32,0,0,0,0,0,0,0,0,0,0,0,0,0,0,0,0,0,0,0,0,0,32,32,2,2,2,32,32,0,0,0
0,0,32,2,2,2,2,2,2,2,32,0,0,0,0,0,0,0,0,0,0,0,0,0,0,0,0,0,0,0,32,2,2,2,2,2,2,2,32,0,0
0,32,2,2,2,2,2,2,2,2,2,32,0,0,0,0,0,0,0,0,0,0,0,0,0,0,0,0,0,32,2,2,2,2,2,2,2,2,2,32,0
0,32,2,2,2,21,21,21,2,2,2,32,0,0,0,0,0,0,0,0,0,0,0,0,0,0,0,0,0,32,2,2,2,21,21,21,2,2,2,32,0
32,2,2,2,21,0,17,13,21,2,2,2,32,0,0,0,0,0,0,0,0,0,0,0,0,0,0,0,32,2,2,2,21,6,0,0,21,2,2,2,32
4,2,2,2,21,0,16,0,21,2,2,2,4,0,0,0,0,0,0,0,0,0,0,0,0,0,0,0,4,2,2,2,21,18,16,0,21,2,2,2,4
32,2,2,2,21,0,0,0,21,2,2,2,32,0,0,0,0,0,0,0,0,0,0,0,0,0,0,0,32,2,2,2,21,0,0,0,21,2,2,2,32
0,32,2,2,2,21,21,21,2,2,2,32,0,0,0,0,0,0,0,0,0,0,0,0,0,0,0,0,0,32,2,2,2,21,21,21,2,2,2,32,0
0,32,2,2,2,2,2,2,2,2,2,32,0,0,0,0,0,0,0,0,0,0,0,0,0,0,0,0,0,32,2,2,2,2,2,2,2,2,2,32,0
0,0,32,2,2,2,2,2,2,2,32,0,0,0,0,0,0,0,0,0,0,0,0,0,0,0,0,0,0,0,32,2,2,2,2,2,2,2,32,0,0
0,0,0,32,32,2,2,2,32,32,0,0,0,0,0,0,0,0,0,0,0,0,0,0,0,0,0,0,0,0,0,32,32,2,2,2,32,32,0,0,0
0,0,0,0,0,32,4,32,0,0,0,0,0,0,0,0,0,0,0,0,0,0,0,0,0,0,0,0,0,0,0,0,0,32,4,32,0,0,0,0,0
endlayer

layer
0,0,0,0,0,16,16,16,0,0,0,0,0,0,0,0,0,0,0,0,0,0,0,0,0,0,0,0,0,0,0,0,0,16,16,16,0,0,0,0,0
0,0,0,16,16,48,48,48,16,16,0,0,0,0,0,0,0,0,0,0,0,0,0,0,0,0,0,0,0,0,0,16,16,48,48,48,16,16,0,0,0
0,0,16,33,0,0,0,0,0,33,16,0,0,0,0,0,0,0,0,0,0,0,0,0,0,0,0,0,0,0,16,33,0,0,0,0,0,33,16,0,0
0,16,26,25,24,0,0,0,26,25,24,16,0,0,0,0,0,0,0,0,0,0,0,0,0,0,0,0,0,16,26,25,24,0,0,0,26,25,24,16,0
0,16,0,35,0,0,0,0,0,35,0,16,0,0,0,0,0,0,0,0,0,0,0,0,0,0,0,0,0,16,0,35,0,0,0,0,0,35,0,16,0
16,48,0,0,0,0,0,15,0,0,0,48,16,0,0,0,0,0,0,0,0,0,0,0,0,0,0,0,16,48,0,0,0,0,0,0,0,0,0,48,16
16,48,0,0,0,0,16,13,0,0,0,48,16,0,0,0,0,0,0,0,0,0,0,0,0,0,0,0,16,48,0,0,0,0,16,0,0,0,0,48,16
16,48,0,0,0,0,0,0,0,0,0,48,16,0,0,0,0,0,0,0,0,0,0,0,0,0,0,0,16,48,0,0,0,0,8,14,0,0,0,48,16
0,16,0,33,0,0,0,0,0,33,0,16,0,0,0,0,0,0,0,0,0,0,0,0,0,0,0,0,0,16,0,33,0,0,0,0,0,33,0,16,0
0,16,26,25,24,0,0,0,26,25,24,16,0,0,0,0,0,0,0,0,0,0,0,0,0,0,0,0,0,16,26,25,24,0,0,0,26,25,24,16,0
0,0,16,35,0,0,0,0,0,35,16,0,0,0,0,0,0,0,0,0,0,0,0,0,0,0,0,0,0,0,16,35,0,0,0,0,0,35,16,0,0
0,0,0,16,16,48,48,48,16,16,0,0,0,0,0,0,0,0,0,0,0,0,0,0,0,0,0,0,0,0,0,16,16,48,48,48,16,16,0,0,0
0,0,0,0,0,16,16,16,0,0,0,0,0,0,0,0,0,0,0,0,0,0,0,0,0,0,0,0,0,0,0,0,0,16,16,16,0,0,0,0,0
0,0,0,0,0,0,0,0,0,0,0,0,0,0,0,0,0,0,0,0,0,0,0,0,0,0,0,0,0,0,0,0,0,0,0,0,0,0,0,0,0
0,0,0,0,0,0,0,0,0,0,0,0,0,0,0,0,0,0,0,0,0,0,0,0,0,0,0,0,0,0,0,0,0,0,0,0,0,0,0,0,0
0,0,0,0,0,0,0,0,0,0,0,0,0,0,0,16,0,0,0,0,0,0,0,0,0,16,0,0,0,0,0,0,0,0,0,0,0,0,0,0,0
0,0,0,0,0,0,0,0,0,0,0,0,0,0,0,0,0,0,0,0,0,0,0,0,0,0,0,0,0,0,0,0,0,0,0,0,0,0,0,0,0
0,0,0,0,0,0,0,0,0,0,0,0,0,0,0,0,0,0,0,0,0,0,0,0,0,0,0,0,0,0,0,0,0,0,0,0,0,0,0,0,0
0,0,0,0,0,0,0,0,0,0,0,0,0,0,0,0,0,0,0,0,0,0,0,0,0,0,0,0,0,0,0,0,0,0,0,0,0,0,0,0,0
0,0,0,0,0,0,0,0,0,0,0,0,0,0,0,0,0,0,0,0,0,0,0,0,0,0,0,0,0,0,0,0,0,0,0,0,0,0,0,0,0
0,0,0,0,0,0,0,0,0,0,0,0,0,0,0,0,0,0,0,0,0,0,0,0,0,0,0,0,0,0,0,0,0,0,0,0,0,0,0,0,0
0,0,0,0,0,0,0,0,0,0,0,0,0,0,0,0,0,0,0,0,0,0,0,0,0,0,0,0,0,0,0,0,0,0,0,0,0,0,0,0,0
0,0,0,0,0,0,0,0,0,0,0,0,0,0,0,0,0,0,0,0,0,0,0,0,0,0,0,0,0,0,0,0,0,0,0,0,0,0,0,0,0
0,0,0,0,0,0,0,0,0,0,0,0,0,0,0,0,0,0,0,0,0,0,0,0,0,0,0,0,0,0,0,0,0,0,0,0,0,0,0,0,0
0,0,0,0,0,0,0,0,0,0,0,0,0,0,0,0,0,0,0,0,0,0,0,0,0,0,0,0,0,0,0,0,0,0,0,0,0,0,0,0,0
0,0,0,0,0,0,0,0,0,0,0,0,0,0,0,16,0,0,0,0,0,0,0,0,0,16,0,0,0,0,0,0,0,0,0,0,0,0,0,0,0
0,0,0,0,0,0,0,0,0,0,0,0,0,0,0,0,0,0,0,0,0,0,0,0,0,0,0,0,0,0,0,0,0,0,0,0,0,0,0,0,0
0,0,0,0,0,0,0,0,0,0,0,0,0,0,0,0,0,0,0,0,0,0,0,0,0,0,0,0,0,0,0,0,0,0,0,0,0,0,0,0,0
0,0,0,0,0,16,16,16,0,0,0,0,0,0,0,0,0,0,0,0,0,0,0,0,0,0,0,0,0,0,0,0,0,16,16,16,0,0,0,0,0
0,0,0,16,16,48,48,48,16,16,0,0,0,0,0,0,0,0,0,0,0,0,0,0,0,0,0,0,0,0,0,16,16,48,48,48,16,16,0,0,0
0,0,16,33,0,0,0,0,0,33,16,0,0,0,0,0,0,0,0,0,0,0,0,0,0,0,0,0,0,0,16,33,0,0,0,0,0,33,16,0,0
0,16,26,25,24,0,0,0,26,25,24,16,0,0,0,0,0,0,0,0,0,0,0,0,0,0,0,0,0,16,26,25,24,0,0,0,26,25,24,16,0
0,16,0,35,0,0,0,0,0,35,0,16,0,0,0,0,0,0,0,0,0,0,0,0,0,0,0,0,0,16,0,35,0,0,0,0,0,35,0,16,0
16,48,0,0,0,17,6,0,0,0,0,48,16,0,0,0,0,0,0,0,0,0,0,0,0,0,0,0,16,48,0,0,0,0,0,0,0,0,0,48,16
16,48,0,0,0,0,16,0,0,0,0,48,16,0,0,0,0,0,0,0,0,0,0,0,0,0,0,0,16,48,0,0,0,5,16,0,0,0,0,48,16
16,48,0,0,0,0,0,0,0,0,0,48,16,0,0,0,0,0,0,0,0,0,0,0,0,0,0,0,16,48,0,0,0,18,0,0,0,0,0,48,16
0,16,0,33,0,0,0,0,0,33,0,16,0,0,0,0,0,0,0,0,0,0,0,0,0,0,0,0,0,16,0,33,0,0,0,0,0,33,0,16,0
0,16,26,25,24,0,0,0,26,25,24,16,0,0,0,0,0,0,0,0,0,0,0,0,0,0,0,0,0,16,26,25,24,0,0,0,26,25,24,16,0
0,0,16,35,0,0,0,0,0,35,16,0,0,0,0,0,0,0,0,0,0,0,0,0,0,0,0,0,0,0,16,35,0,0,0,0,0,35,16,0,0
0,0,0,16,16,48,48,48,16,16,0,0,0,0,0,0,0,0,0,0,0,0,0,0,0,0,0,0,0,0,0,16,16,48,48,48,16,16,0,0,0
0,0,0,0,0,16,16,16,0,0,0,0,0,0,0,0,0,0,0,0,0,0,0,0,0,0,0,0,0,0,0,0,0,16,16,16,0,0,0,0,0
endlayer

layer
0,0,0,0,0,21,21,21,0,0,0,0,0,0,0,0,0,0,0,0,0,0,0,0,0,0,0,0,0,0,0,0,0,21,21,21,0,0,0,0,0
0,0,0,21,16,0,49,0,16,21,0,0,0,0,0,0,0,0,0,0,0,0,0,0,0,0,0,0,0,0,0,21,16,0,49,0,16,21,0,0,0
0,0,21,0,0,0,0,0,0,0,21,0,0,0,0,0,0,0,0,0,0,0,0,0,0,0,0,0,0,0,21,0,0,0,0,0,0,0,21,0,0
0,21,0,38,0,0,0,0,0,38,0,21,0,0,0,0,0,0,0,0,0,0,0,0,0,0,0,0,0,21,0,38,0,0,0,0,0,38,0,21,0
0,16,0,0,0,0,0,0,0,0,0,16,0,0,0,0,0,0,0,0,0,0,0,0,0,0,0,0,0,16,0,0,0,0,0,0,0,0,0,16,0
21,0,0,0,0,0,17,13,0,0,0,0,21,0,0,0,0,0,0,0,0,0,0,0,0,0,0,0,21,0,0,0,0,0,0,0,0,0,0,0,21
21,49,0,0,0,0,16,0,0,0,0,49,21,0,0,0,0,0,0,0,0,0,0,0,0,0,0,0,21,49,0,0,0,0,16,15,0,0,0,49,21
21,0,0,0,0,0,0,0,0,0,0,0,21,0,0,0,0,0,0,0,0,0,0,0,0,0,0,0,21,0,0,0,0,0,0,8,0,0,0,0,21
0,16,0,0,0,0,0,0,0,0,0,16,0,0,0,0,0,0,0,0,0,0,0,0,0,0,0,0,0,16,0,0,0,0,0,0,0,0,0,16,0
0,21,0,38,0,0,0,0,0,38,0,21,0,0,0,0,0,0,0,0,0,0,0,0,0,0,0,0,0,21,0,38,0,0,0,0,0,38,0,21,0
0,0,21,0,0,0,0,0,0,0,21,0,0,0,0,0,0,0,0,0,0,0,0,0,0,0,0,0,0,0,21,0,0,0,0,0,0,0,21,0,0
0,0,0,21,16,0,49,0,16,21,0,0,0,0,0,0,0,0,0,0,0,0,0,0,0,0,0,0,0,0,0,21,16,0,49,0,16,21,0,0,0
0,0,0,0,0,21,21,21,0,0,0,0,0,0,0,0,0,0,0,0,0,0,0,0,0,0,0,0,0,0,0,0,0,21,21,21,0,0,0,0,0
0,0,0,0,0,0,0,0,0,0,0,0,0,0,0,0,0,0,0,0,0,0,0,0,0,0,0,0,0,0,0,0,0,0,0,0,0,0,0,0,0
0,0,0,0,0,0,0,0,0,0,0,0,0,0,0,0,0,0,0,0,0,0,0,0,0,0,0,0,0,0,0,0,0,0,0,0,0,0,0,0,0
0,0,0,0,0,0,0,0,0,0,0,0,0,0,0,16,0,0,0,0,0,0,0,0,0,16,0,0,0,0,0,0,0,0,0,0,0,0,0,0,0
0,0,0,0,0,0,0,0,0,0,0,0,0,0,0,0,0,0,0,0,0,0,0,0,0,0,0,0,0,0,0,0,0,0,0,0,0,0,0,0,0
0,0,0,0,0,0,0,0,0,0,0,0,0,0,0,0,0,0,0,0,0,0,0,0,0,0,0,0,0,0,0,0,0,0,0,0,0,0,0,0,0
0,0,0,0,0,0,0,0,0,0,0,0,0,0,0,0,0,0,0,0,0,0,0,0,0,0,0,0,0,0,0,0,0,0,0,0,0,0,0,0,0
0,0,0,0,0,0,0,0,0,0,0,0,0,0,0,0,0,0,0,0,0,0,0,0,0,0,0,0,0,0,0,0,0,0,0,0,0,0,0,0,0
0,0,0,0,0,0,0,0,0,0,0,0,0,0,0,0,0,0,0,0,0,0,0,0,0,0,0,0,0,0,0,0,0,0,0,0,0,0,0,0,0
0,0,0,0,0,0,0,0,0,0,0,0,0,0,0,0,0,0,0,0,0,0,0,0,0,0,0,0,0,0,0,0,0,0,0,0,0,0,0,0,0
0,0,0,0,0,0,0,0,0,0,0,0,0,0,0,0,0,0,0,0,0,0,0,0,0,0,0,0,0,0,0,0,0,0,0,0,0,0,0,0,0
0,0,0,0,0,0,0,0,0,0,0,0,0,0,0,0,0,0,0,0,0,0,0,0,0,0,0,0,0,0,0,0,0,0,0,0,0,0,0,0,0
0,0,0,0,0,0,0,0,0,0,0,0,0,0,0,0,0,0,0,0,0,0,0,0,0,0,0,0,0,0,0,0,0,0,0,0,0,0,0,0,0
0,0,0,0,0,0,0,0,0,0,0,0,0,0,0,16,0,0,0,0,0,0,0,0,0,16,0,0,0,0,0,0,0,0,0,0,0,0,0,0,0
0,0,0,0,0,0,0,0,0,0,0,0,0,0,0,0,0,0,0,0,0,0,0,0,0,0,0,0,0,0,0,0,0,0,0,0,0,0,0,0,0
0,0,0,0,0,0,0,0,0,0,0,0,0,0,0,0,0,0,0,0,0,0,0,0,0,0,0,0,0,0,0,0,0,0,0,0,0,0,0,0,0
0,0,0,0,0,21,21,21,0,0,0,0,0,0,0,0,0,0,0,0,0,0,0,0,0,0,0,0,0,0,0,0,0,21,21,21,0,0,0,0,0
0,0,0,21,16,0,49,0,16,21,0,0,0,0,0,0,0,0,0,0,0,0,0,0,0,0,0,0,0,0,0,21,16,0,49,0,16,21,0,0,0
0,0,21,0,0,0,0,0,0,0,21,0,0,0,0,0,0,0,0,0,0,0,0,0,0,0,0,0,0,0,21,0,0,0,0,0,0,0,21,0,0
0,21,0,38,0,0,0,0,0,38,0,21,0,0,0,0,0,0,0,0,0,0,0,0,0,0,0,0,0,21,0,38,0,0,0,0,0,38,0,21,0
0,16,0,0,0,0,0,0,0,0,0,16,0,0,0,0,0,0,0,0,0,0,0,0,0,0,0,0,0,16,0,0,0,0,0,0,0,0,0,16,0
21,0,0,0,0,6,0,0,0,0,0,0,21,0,0,0,0,0,0,0,0,0,0,0,0,0,0,0,21,0,0,0,0,0,0,0,0,0,0,0,21
21,49,0,0,0,18,16,0,0,0,0,49,21,0,0,0,0,0,0,0,0,0,0,0,0,0,0,0,21,49,0,0,0,0,16,0,0,0,0,49,21
21,0,0,0,0,0,0,0,0,0,0,0,21,0,0,0,0,0,0,0,0,0,0,0,0,0,0,0,21,0,0,0,0,5,14,0,0,0,0,0,21
0,16,0,0,0,0,0,0,0,0,0,16,0,0,0,0,0,0,0,0,0,0,0,0,0,0,0,0,0,16,0,0,0,0,0,0,0,0,0,16,0
0,21,0,38,0,0,0,0,0,38,0,21,0,0,0,0,0,0,0,0,0,0,0,0,0,0,0,0,0,21,0,38,0,0,0,0,0,38,0,21,0
0,0,21,0,0,0,0,0,0,0,21,0,0,0,0,0,0,0,0,0,0,0,0,0,0,0,0,0,0,0,21,0,0,0,0,0,0,0,21,0,0
0,0,0,21,16,0,49,0,16,21,0,0,0,0,0,0,0,0,0,0,0,0,0,0,0,0,0,0,0,0,0,21,16,0,49,0,16,21,0,0,0
0,0,0,0,0,21,21,21,0,0,0,0,0,0,0,0,0,0,0,0,0,0,0,0,0,0,0,0,0,0,0,0,0,21,21,21,0,0,0,0,0
endlayer

layer
0,0,0,0,0,21,21,21,0,0,0,0,0,0,0,0,0,0,0,0,0,0,0,0,0,0,0,0,0,0,0,0,0,21,21,21,0,0,0,0,0
0,0,0,21,16,0,0,0,16,21,0,0,0,0,0,0,0,0,0,0,0,0,0,0,0,0,0,0,0,0,0,21,16,0,0,0,16,21,0,0,0
0,0,21,0,0,0,0,0,0,0,21,0,0,0,0,0,0,0,0,0,0,0,0,0,0,0,0,0,0,0,21,0,0,0,0,0,0,0,21,0,0
0,21,0,0,0,0,0,0,0,0,0,21,0,0,0,0,0,0,0,0,0,0,0,0,0,0,0,0,0,21,0,0,0,0,0,0,0,0,0,21,0
0,16,0,0,0,0,0,0,0,0,0,16,0,0,0,0,0,0,0,0,0,0,0,0,0,0,0,0,0,16,0,0,0,0,0,0,0,0,0,16,0
21,0,0,0,0,17,6,0,0,0,0,0,21,0,0,0,0,0,0,0,0,0,0,0,0,0,0,0,21,0,0,0,0,0,0,15,0,0,0,0,21
21,0,0,0,0,0,16,0,0,0,0,0,21,0,0,0,0,0,0,0,0,0,0,0,0,0,0,0,21,0,0,0,0,0,16,13,0,0,0,0,21
21,0,0,0,0,0,0,0,0,0,0,0,21,0,0,0,0,0,0,0,0,0,0,0,0,0,0,0,21,0,0,0,0,0,0,0,0,0,0,0,21
0,16,0,0,0,0,0,0,0,0,0,16,0,0,0,0,0,0,0,0,0,0,0,0,0,0,0,0,0,16,0,0,0,0,0,0,0,0,0,16,0
0,21,0,0,0,0,0,0,0,0,0,21,0,0,0,0,0,0,0,0,0,0,0,0,0,0,0,0,0,21,0,0,0,0,0,0,0,0,0,21,0
0,0,21,0,0,0,0,0,0,0,21,0,0,0,0,0,0,0,0,0,0,0,0,0,0,0,0,0,0,0,21,0,0,0,0,0,0,0,21,0,0
0,0,0,21,16,0,0,0,16,21,0,0,0,0,0,0,0,0,0,0,0,0,0,0,0,0,0,0,0,0,0,21,16,0,0,0,16,21,0,0,0
0,0,0,0,0,21,21,21,0,0,0,0,0,0,0,0,0,0,0,0,0,0,0,0,0,0,0,0,0,0,0,0,0,21,21,21,0,0,0,0,0
0,0,0,0,0,0,0,0,0,0,0,0,0,0,0,0,0,0,0,0,0,0,0,0,0,0,0,0,0,0,0,0,0,0,0,0,0,0,0,0,0
0,0,0,0,0,0,0,0,0,0,0,0,0,0,0,0,0,0,0,0,0,0,0,0,0,0,0,0,0,0,0,0,0,0,0,0,0,0,0,0,0
0,0,0,0,0,0,0,0,0,0,0,0,0,0,0,16,0,0,0,0,0,0,0,0,0,16,0,0,0,0,0,0,0,0,0,0,0,0,0,0,0
0,0,0,0,0,0,0,0,0,0,0,0,0,0,0,0,0,0,0,0,0,0,0,0,0,0,0,0,0,0,0,0,0,0,0,0,0,0,0,0,0
0,0,0,0,0,0,0,0,0,0,0,0,0,0,0,0,0,0,0,0,0,0,0,0,0,0,0,0,0,0,0,0,0,0,0,0,0,0,0,0,0
0,0,0,0,0,0,0,0,0,0,0,0,0,0,0,0,0,0,0,0,0,0,0,0,0,0,0,0,0,0,0,0,0,0,0,0,0,0,0,0,0
0,0,0,0,0,0,0,0,0,0,0,0,0,0,0,0,0,0,0,0,0,0,0,0,0,0,0,0,0,0,0,0,0,0,0,0,0,0,0,0,0
0,0,0,0,0,0,0,0,0,0,0,0,0,0,0,0,0,0,0,0,0,0,0,0,0,0,0,0,0,0,0,0,0,0,0,0,0,0,0,0,0
0,0,0,0,0,0,0,0,0,0,0,0,0,0,0,0,0,0,0,0,0,0,0,0,0,0,0,0,0,0,0,0,0,0,0,0,0,0,0,0,0
0,0,0,0,0,0,0,0,0,0,0,0,0,0,0,0,0,0,0,0,0,0,0,0,0,0,0,0,0,0,0,0,0,0,0,0,0,0,0,0,0
0,0,0,0,0,0,0,0,0,0,0,0,0,0,0,0,0,0,0,0,0,0,0,0,0,0,0,0,0,0,0,0,0,0,0,0,0,0,0,0,0
0,0,0,0,0,0,0,0,0,0,0,0,0,0,0,0,0,0,0,0,0,0,0,0,0,0,0,0,0,0,0,0,0,0,0,0,0,0,0,0,0
0,0,0,0,0,0,0,0,0,0,0,0,0,0,0,16,0,0,0,0,0,0,0,0,0,16,0,0,0,0,0,0,0,0,0,0,0,0,0,0,0
0,0,0,0,0,0,0,0,0,0,0,0,0,0,0,0,0,0,0,0,0,0,0,0,0,0,0,0,0,0,0,0,0,0,0,0,0,0,0,0,0
0,0,0,0,0,0,0,0,0,0,0,0,0,0,0,0,0,0,0,0,0,0,0,0,0,0,0,0,0,0,0,0,0,0,0,0,0,0,0,0,0
0,0,0,0,0,21,21,21,0,0,0,0,0,0,0,0,0,0,0,0,0,0,0,0,0,0,0,0,0,0,0,0,0,21,21,21,0,0,0,0,0
0,0,0,21,16,0,0,0,16,21,0,0,0,0,0,0,0,0,0,0,0,0,0,0,0,0,0,0,0,0,0,21,16,0,0,0,16,21,0,0,0
0,0,21,0,0,0,0,0,0,0,21,0,0,0,0,0,0,0,0,0,0,0,0,0,0,0,0,0,0,0,21,0,0,0,0,0,0,0,21,0,0
0,21,0,0,0,0,0,0,0,0,0,21,0,0,0,0,0,0,0,0,0,0,0,0,0,0,0,0,0,21,0,0,0,0,0,0,0,0,0,21,0
0,16,0,0,0,0,0,0,0,0,0,16,0,0,0,0,0,0,0,0,0,0,0,0,0,0,0,0,0,16,0,0,0,0,0,0,0,0,0,16,0
21,0,0,0,0,0,0,0,0,0,0,0,21,0,0,0,0,0,0,0,0,0,0,0,0,0,0,0,21,0,0,0,0,0,0,0,0,0,0,0,21
21,0,0,0,0,5,16,0,0,0,0,0,21,0,0,0,0,0,0,0,0,0,0,0,0,0,0,0,21,0,0,0,0,0,16,0,0,0,0,0,21
21,0,0,0,0,18,0,0,0,0,0,0,21,0,0,0,0,0,0,0,0,0,0,0,0,0,0,0,21,0,0,0,0,0,8,14,0,0,0,0,21
0,16,0,0,0,0,0,0,0,0,0,16,0,0,0,0,0,0,0,0,0,0,0,0,0,0,0,0,0,16,0,0,0,0,0,0,0,0,0,16,0
0,21,0,0,0,0,0,0,0,0,0,21,0,0,0,0,0,0,0,0,0,0,0,0,0,0,0,0,0,21,0,0,0,0,0,0,0,0,0,21,0
0,0,21,0,0,0,0,0,0,0,21,0,0,0,0,0,0,0,0,0,0,0,0,0,0,0,0,0,0,0,21,0,0,0,0,0,0,0,21,0,0
0,0,0,21,16,0,0,0,16,21,0,0,0,0,0,0,0,0,0,0,0,0,0,0,0,0,0,0,0,0,0,21,16,0,0,0,16,21,0,0,0
0,0,0,0,0,21,21,21,0,0,0,0,0,0,0,0,0,0,0,0,0,0,0,0,0,0,0,0,0,0,0,0,0,21,21,21,0,0,0,0,0
endlayer

layer
0,0,0,0,0,21,21,21,0,0,0,0,0,0,0,0,0,0,0,0,0,0,0,0,0,0,0,0,0,0,0,0,0,21,21,21,0,0,0,0,0
0,0,0,21,16,0,0,0,16,21,0,0,0,0,0,0,0,0,0,0,0,0,0,0,0,0,0,0,0,0,0,21,16,0,0,0,16,21,0,0,0
0,0,21,0,0,0,0,0,0,0,21,0,0,0,0,0,0,0,0,0,0,0,0,0,0,0,0,0,0,0,21,0,0,0,0,0,0,0,21,0,0
0,21,0,0,0,0,0,0,0,0,0,21,0,0,0,0,0,0,0,0,0,0,0,0,0,0,0,0,0,21,0,0,0,0,0,0,0,0,0,21,0
0,16,0,0,0,0,0,0,0,0,0,16,0,0,0,0,0,0,0,0,0,0,0,0,0,0,0,0,0,16,0,0,0,0,0,0,0,0,0,16,0
21,0,0,0,0,6,0,0,0,0,0,0,21,0,0,0,0,0,0,0,0,0,0,0,0,0,0,0,21,0,0,0,0,0,17,13,0,0,0,0,21
21,0,0,0,0,18,16,0,0,0,0,0,21,0,0,0,0,0,0,0,0,0,0,0,0,0,0,0,21,0,0,0,0,0,16,0,0,0,0,0,21
21,0,0,0,0,0,0,0,0,0,0,0,21,0,0,0,0,0,0,0,0,0,0,0,0,0,0,0,21,0,0,0,0,0,0,0,0,0,0,0,21
0,16,0,0,0,0,0,0,0,0,0,16,0,0,0,0,0,0,0,0,0,0,0,0,0,0,0,0,0,16,0,0,0,0,0,0,0,0,0,16,0
0,21,0,0,0,0,0,0,0,0,0,21,0,0,0,0,0,0,0,0,0,0,0,0,0,0,0,0,0,21,0,0,0,0,0,0,0,0,0,21,0
0,0,21,0,0,0,0,0,0,0,21,0,0,0,0,0,0,0,0,0,0,0,0,0,0,0,0,0,0,0,21,0,0,0,0,0,0,0,21,0,0
0,0,0,21,16,0,0,0,16,21,0,0,0,0,0,0,0,0,0,0,0,0,0,0,0,0,0,0,0,0,0,21,16,0,0,0,16,21,0,0,0
0,0,0,0,0,21,21,21,0,0,0,0,0,0,0,0,0,0,0,0,0,0,0,0,0,0,0,0,0,0,0,0,0,21,21,21,0,0,0,0,0
0,0,0,0,0,0,0,0,0,0,0,0,0,0,0,0,0,0,0,0,0,0,0,0,0,0,0,0,0,0,0,0,0,0,0,0,0,0,0,0,0
0,0,0,0,0,0,0,0,0,0,0,0,0,0,0,0,0,0,0,0,0,0,0,0,0,0,0,0,0,0,0,0,0,0,0,0,0,0,0,0,0
0,0,0,0,0,0,0,0,0,0,0,0,0,0,0,16,0,0,0,0,0,0,0,0,0,16,0,0,0,0,0,0,0,0,0,0,0,0,0,0,0
0,0,0,0,0,0,0,0,0,0,0,0,0,0,0,0,0,0,0,0,0,0,0,0,0,0,0,0,0,0,0,0,0,0,0,0,0,0,0,0,0
0,0,0,0,0,0,0,0,0,0,0,0,0,0,0,0,0,0,0,0,0,0,0,0,0,0,0,0,0,0,0,0,0,0,0,0,0,0,0,0,0
0,0,0,0,0,0,0,0,0,0,0,0,0,0,0,0,0,0,0,0,0,0,0,0,0,0,0,0,0,0,0,0,0,0,0,0,0,0,0,0,0
0,0,0,0,0,0,0,0,0,0,0,0,0,0,0,0,0,0,0,0,0,0,0,0,0,0,0,0,0,0,0,0,0,0,0,0,0,0,0,0,0
0,0,0,0,0,0,0,0,0,0,0,0,0,0,0,0,0,0,0,0,0,0,0,0,0,0,0,0,0,0,0,0,0,0,0,0,0,0,0,0,0
0,0,0,0,0,0,0,0,0,0,0,0,0,0,0,0,0,0,0,0,0,0,0,0,0,0,0,0,0,0,0,0,0,0,0,0,0,0,0,0,0
0,0,0,0,0,0,0,0,0,0,0,0,0,0,0,0,0,0,0,0,0,0,0,0,0,0,0,0,0,0,0,0,0,0,0,0,0,0,0,0,0
0,0,0,0,0,0,0,0,0,0,0,0,0,0,0,0,0,0,0,0,0,0,0,0,0,0,0,0,0,0,0,0,0,0,0,0,0,0,0,0,0
0,0,0,0,0,0,0,0,0,0,0,0,0,0,0,0,0,0,0,0,0,0,0,0,0,0,0,0,0,0,0,0,0,0,0,0,0,0,0,0,0
0,0,0,0,0,0,0,0,0,0,0,0,0,0,0,16,0,0,0,0,0,0,0,0,0,16,0,0,0,0,0,0,0,0,0,0,0,0,0,0,0
0,0,0,0,0,0,0,0,0,0,0,0,0,0,0,0,0,0,0,0,0,0,0,0,0,0,0,0,0,0,0,0,0,0,0,0,0,0,0,0,0
0,0,0,0,0,0,0,0,0,0,0,0,0,0,0,0,0,0,0,0,0,0,0,0,0,0,0,0,0,0,0,0,0,0,0,0,0,0,0,0,0
0,0,0,0,0,21,21,21,0,0,0,0,0,0,0,0,0,0,0,0,0,0,0,0,0,0,0,0,0,0,0,0,0,21,21,21,0,0,0,0,0
0,0,0,21,16,0,0,0,16,21,0,0,0,0,0,0,0,0,0,0,0,0,0,0,0,0,0,0,0,0,0,21,16,0,0,0,16,21,0,0,0
0,0,21,0,0,0,0,0,0,0,21,0,0,0,0,0,0,0,0,0,0,0,0,0,0,0,0,0,0,0,21,0,0,0,0,0,0,0,21,0,0
0,21,0,0,0,0,0,0,0,0,0,21,0,0,0,0,0,0,0,0,0,0,0,0,0,0,0,0,0,21,0,0,0,0,0,0,0,0,0,21,0
0,16,0,0,0,0,0,0,0,0,0,16,0,0,0,0,0,0,0,0,0,0,0,0,0,0,0,0,0,16,0,0,0,0,0,0,0,0,0,16,0
21,0,0,0,0,0,0,0,0,0,0,0,21,0,0,0,0,0,0,0,0,0,0,0,0,0,0,0,21,0,0,0,0,0,0,0,0,0,0,0,21
21,0,0,0,0,0,16,0,0,0,0,0,21,0,0,0,0,0,0,0,0,0,0,0,0,0,0,0,21,0,0,0,0,0,16,15,0,0,0,0,21
21,0,0,0,0,5,14,0,0,0,0,0,21,0,0,0,0,0,0,0,0,0,0,0,0,0,0,0,21,0,0,0,0,0,0,8,0,0,0,0,21
0,16,0,0,0,0,0,0,0,0,0,16,0,0,0,0,0,0,0,0,0,0,0,0,0,0,0,0,0,16,0,0,0,0,0,0,0,0,0,16,0
0,21,0,0,0,0,0,0,0,0,0,21,0,0,0,0,0,0,0,0,0,0,0,0,0,0,0,0,0,21,0,0,0,0,0,0,0,0,0,21,0
0,0,21,0,0,0,0,0,0,0,21,0,0,0,0,0,0,0,0,0,0,0,0,0,0,0,0,0,0,0,21,0,0,0,0,0,0,0,21,0,0
0,0,0,21,16,0,0,0,16,21,0,0,0,0,0,0,0,0,0,0,0,0,0,0,0,0,0,0,0,0,0,21,16,0,0,0,16,21,0,0,0
0,0,0,0,0,21,21,21,0,0,0,0,0,0,0,0,0,0,0,0,0,0,0,0,0,0,0,0,0,0,0,0,0,21,21,21,0,0,0,0,0
endlayer

layer
0,0,0,0,0,16,16,16,0,0,0,0,0,0,0,0,0,0,0,0,0,0,0,0,0,0,0,0,0,0,0,0,0,16,16,16,0,0,0,0,0
0,0,0,16,16,0,0,0,16,16,0,0,0,0,0,0,0,0,0,0,0,0,0,0,0,0,0,0,0,0,0,16,16,0,0,0,16,16,0,0,0
0,0,16,0,0,0,0,0,0,0,16,0,0,0,0,0,0,0,0,0,0,0,0,0,0,0,0,0,0,0,16,0,0,0,0,0,0,0,16,0,0
0,16,0,0,0,0,0,0,0,0,0,16,0,0,0,0,0,0,0,0,0,0,0,0,0,0,0,0,0,16,0,0,0,0,0,0,0,0,0,16,0
0,16,0,0,0,0,0,0,0,0,0,16,0,0,0,0,1,2,1,0,0,0,1,2,1,0,0,0,0,16,0,0,0,0,0,0,0,0,0,16,0
16,0,0,0,0,0,0,0,0,0,0,0,16,0,1,1,0,0,0,0,0,0,0,0,0,1,1,0,16,0,0,0,0,17,6,0,0,0,0,0,16
16,0,0,0,0,5,16,0,0,0,0,0,16,1,0,0,0,0,0,0,0,0,0,0,0,0,0,1,16,0,0,0,0,0,16,0,0,0,0,0,16
16,0,0,0,0,18,0,0,0,0,0,0,16,0,0,0,0,0,0,0,0,0,0,0,0,0,0,0,16,0,0,0,0,0,0,0,0,0,0,0,16
0,16,0,0,0,0,0,0,0,0,0,16,0,0,0,0,0,0,0,0,0,0,0,0,0,0,0,0,0,16,0,0,0,0,0,0,0,0,0,16,0
0,16,0,0,0,0,0,0,0,0,0,16,0,0,0,0,0,0,0,0,0,0,0,0,0,0,0,0,0,16,0,0,0,0,0,0,0,0,0,16,0
0,0,16,0,0,0,0,0,0,0,16,0,0,0,0,0,0,0,0,0,0,0,0,0,0,0,0,0,0,0,16,0,0,0,0,0,0,0,16,0,0
0,0,0,16,16,0,0,0,16,16,0,0,0,0,0,0,0,0,0,0,0,0,0,0,0,0,0,0,0,0,0,16,16,0,0,0,16,16,0,0,0
0,0,0,0,0,16,16,16,0,0,0,0,0,0,0,0,0,0,0,0,0,0,0,0,0,0,0,0,0,0,0,0,0,16,16,16,0,0,0,0,0
0,0,0,0,0,0,1,0,0,0,0,0,0,0,0,0,0,0,0,0,0,0,0,0,0,0,0,0,0,0,0,0,0,0,1,0,0,0,0,0,0
0,0,0,0,0,1,0,0,0,0,0,0,0,0,15,15,14,0,0,0,0,0,0,0,15,15,14,0,0,0,0,0,0,0,0,1,0,0,0,0,0
0,0,0,0,0,1,0,0,0,0,0,0,0,0,17,16,14,0,0,0,0,0,0,0,17,16,14,0,0,0,0,0,0,0,0,1,0,0,0,0,0
0,0,0,0,1,0,0,0,0,0,0,0,0,0,17,18,14,0,0,0,0,0,0,0,17,18,18,0,0,0,0,0,0,0,0,0,1,0,0,0,0
0,0,0,0,2,0,0,0,0,0,0,0,0,0,0,0,0,0,0,0,0,0,0,0,0,0,0,0,0,0,0,0,0,0,0,0,2,0,0,0,0
0,0,0,0,1,0,0,0,0,0,0,0,0,0,0,0,0,0,0,0,0,0,0,0,0,0,0,0,0,0,0,0,0,0,0,0,1,0,0,0,0
0,0,0,0,0,0,0,0,0,0,0,0,0,0,0,0,0,0,0,0,0,0,0,0,0,0,0,0,0,0,0,0,0,0,0,0,0,0,0,0,0
0,0,0,0,0,0,0,0,0,0,0,0,0,0,0,0,0,0,0,0,0,0,0,0,0,0,0,0,0,0,0,0,0,0,0,0,0,0,0,0,0
0,0,0,0,0,0,0,0,0,0,0,0,0,0,0,0,0,0,0,0,0,0,0,0,0,0,0,0,0,0,0,0,0,0,0,0,0,0,0,0,0
0,0,0,0,1,0,0,0,0,0,0,0,0,0,0,0,0,0,0,0,0,0,0,0,0,0,0,0,0,0,0,0,0,0,0,0,1,0,0,0,0
0,0,0,0,2,0,0,0,0,0,0,0,0,0,0,0,0,0,0,0,0,0,0,0,0,0,0,0,0,0,0,0,0,0,0,0,2,0,0,0,0
0,0,0,0,1,0,0,0,0,0,0,0,0,0,15,15,15,0,0,0,0,0,0,0,15,15,14,0,0,0,0,0,0,0,0,0,1,0,0,0,0
0,0,0,0,0,1,0,0,0,0,0,0,0,0,17,16,14,0,0,0,0,0,0,0,17,16,14,0,0,0,0,0,0,0,0,1,0,0,0,0,0
0,0,0,0,0,1,0,0,0,0,0,0,0,0,17,18,18,0,0,0,0,0,0,0,17,18,18,0,0,0,0,0,0,0,0,1,0,0,0,0,0
0,0,0,0,0,0,1,0,0,0,0,0,0,0,0,0,0,0,0,0,0,0,0,0,0,0,0,0,0,0,0,0,0,0,1,0,0,0,0,0,0
0,0,0,0,0,16,16,16,0,0,0,0,0,0,0,0,0,0,0,0,0,0,0,0,0,0,0,0,0,0,0,0,0,16,16,16,0,0,0,0,0
0,0,0,16,16,0,0,0,16,16,0,0,0,0,0,0,0,0,0,0,0,0,0,0,0,0,0,0,0,0,0,16,16,0,0,0,16,16,0,0,0
0,0,16,0,0,0,0,0,0,0,16,0,0,0,0,0,0,0,0,0,0,0,0,0,0,0,0,0,0,0,16,0,0,0,0,0,0,0,16,0,0
0,16,0,0,0,0,0,0,0,0,0,16,0,0,0,0,0,0,0,0,0,0,0,0,0,0,0,0,0,16,0,0,0,0,0,0,0,0,0,16,0
0,16,0,0,0,0,0,0,0,0,0,16,0,0,0,0,0,0,0,0,0,0,0,0,0,0,0,0,0,16,0,0,0,0,0,0,0,0,0,16,0
16,0,0,0,0,0,0,0,0,0,0,0,16,0,0,0,0,0,0,0,0,0,0,0,0,0,0,0,16,0,0,0,0,0,0,15,0,0,0,0,16
16,0,0,0,0,0,16,0,0,0,0,0,16,1,0,0,0,0,0,0,0,0,0,0,0,0,0,1,16,0,0,0,0,0,16,13,0,0,0,0,16
16,0,0,0,0,0,8,14,0,0,0,0,16,0,1,1,0,0,0,0,0,0,0,0,0,1,1,0,16,0,0,0,0,0,0,0,0,0,0,0,16
0,16,0,0,0,0,0,0,0,0,0,16,0,0,0,0,1,2,1,0,0,0,1,2,1,0,0,0,0,16,0,0,0,0,0,0,0,0,0,16,0
0,16,0,0,0,0,0,0,0,0,0,16,0,0,0,0,0,0,0,0,0,0,0,0,0,0,0,0,0,16,0,0,0,0,0,0,0,0,0,16,0
0,0,16,0,0,0,0,0,0,0,16,0,0,0,0,0,0,0,0,0,0,0,0,0,0,0,0,0,0,0,16,0,0,0,0,0,0,0,16,0,0
0,0,0,16,16,0,0,0,16,16,0,0,0,0,0,0,0,0,0,0,0,0,0,0,0,0,0,0,0,0,0,16,16,0,0,0,16,16,0,0,0
0,0,0,0,0,16,16,16,0,0,0,0,0,0,0,0,0,0,0,0,0,0,0,0,0,0,0,0,0,0,0,0,0,16,16,16,0,0,0,0,0
endlayer

layer
0,0,0,0,0,0,0,0,0,0,0,0,0,0,0,0,0,0,0,0,0,0,0,0,0,0,0,0,0,0,0,0,0,0,0,0,0,0,0,0,0
0,0,0,0,0,2,2,2,0,0,0,0,0,0,0,0,0,0,0,0,0,0,0,0,0,0,0,0,0,0,0,0,0,2,2,2,0,0,0,0,0
0,0,0,2,2,2,2,2,2,2,0,0,0,0,0,0,1,1,1,1,1,1,1,1,1,0,0,0,0,0,0,2,2,2,2,2,2,2,0,0,0
0,0,2,2,2,2,2,2,2,2,2,0,0,0,1,1,2,2,2,2,2,2,2,2,2,1,1,0,0,0,2,2,2,2,2,2,2,2,2,0,0
0,0,2,2,2,21,21,21,2,2,2,16,1,1,2,2,2,2,2,21,4,21,2,2,2,2,2,1,1,16,2,2,2,21,21,21,2,2,2,0,0
0,2,2,2,21,0,0,0,21,2,2,2,16,2,2,2,2,2,2,2,2,2,2,2,2,2,2,2,16,2,2,2,21,6,0,0,21,2,2,2,0
0,2,2,2,21,0,16,0,21,2,2,2,16,2,2,2,1,1,1,1,1,1,1,1,1,2,2,2,16,2,2,2,21,0,16,0,21,2,2,2,0
0,2,2,2,21,5,14,0,21,2,2,2,16,2,1,1,0,0,0,0,0,0,0,0,0,1,1,2,16,2,2,2,21,0,0,0,21,2,2,2,0
0,0,2,2,2,21,21,21,2,2,2,16,1,1,0,0,0,0,0,0,0,0,0,0,0,0,0,1,1,16,2,2,2,21,21,21,2,2,2,0,0
0,0,2,2,2,2,2,2,2,2,2,16,0,0,0,0,0,0,0,0,0,0,0,0,0,0,0,0,0,16,2,2,2,2,2,2,2,2,2,0,0
0,0,0,2,2,2,2,2,2,2,16,2,1,0,0,0,0,0,0,0,0,0,0,0,0,0,0,0,1,2,16,2,2,2,2,2,2,2,0,0,0
0,0,0,0,16,2,2,2,16,16,2,2,2,1,0,0,0,0,0,0,0,0,0,0,0,0,0,1,2,2,2,16,16,2,2,2,16,0,0,0,0
0,0,0,0,1,16,16,16,1,0,1,2,2,2,1,1,1,0,0,0,0,0,0,0,1,1,1,2,2,2,1,0,1,16,16,16,1,0,0,0,0
0,0,0,0,1,2,2,2,1,0,0,1,2,2,2,2,2,1,0,0,0,0,0,1,2,2,2,2,2,1,0,0,1,2,2,2,1,0,0,0,0
0,0,0,1,2,2,2,1,0,0,0,0,1,2,2,2,2,2,1,0,0,0,1,2,2,2,2,2,1,0,0,0,0,1,2,2,2,1,0,0,0
0,0,0,1,2,2,2,1,0,0,0,0,1,2,2,4,2,2,1,0,0,0,1,2,2,4,2,2,1,0,0,0,0,1,2,2,2,1,0,0,0
0,0,1,2,2,2,1,0,0,0,0,0,1,2,2,2,2,2,1,0,0,0,1,2,2,2,2,2,1,0,0,0,0,0,1,2,2,2,1,0,0
0,0,1,2,2,2,1,0,0,0,0,0,0,1,2,2,2,1,0,0,0,0,0,1,2,2,2,1,0,0,0,0,0,0,1,2,2,2,1,0,0
0,0,1,2,2,2,1,0,0,0,0,0,0,0,1,1,1,0,0,0,0,0,0,0,1,1,1,0,0,0,0,0,0,0,1,2,2,2,1,0,0
0,0,1,2,21,2,1,0,0,0,0,0,0,0,0,0,0,0,0,0,0,0,0,0,0,0,0,0,0,0,0,0,0,0,1,2,21,2,1,0,0
0,0,1,2,4,2,1,0,0,0,0,0,0,0,0,0,0,0,0,0,0,0,0,0,0,0,0,0,0,0,0,0,0,0,1,2,4,2,1,0,0
0,0,1,2,21,2,1,0,0,0,0,0,0,0,0,0,0,0,0,0,0,0,0,0,0,0,0,0,0,0,0,0,0,0,1,2,21,2,1,0,0
0,0,1,2,2,2,1,0,0,0,0,0,0,0,1,1,1,0,0,0,0,0,0,0,1,1,1,0,0,0,0,0,0,0,1,2,2,2,1,0,0
0,0,1,2,2,2,1,0,0,0,0,0,0,1,2,2,2,1,0,0,0,0,0,1,2,2,2,1,0,0,0,0,0,0,1,2,2,2,1,0,0
0,0,1,2,2,2,1,0,0,0,0,0,1,2,2,2,2,2,1,0,0,0,1,2,2,2,2,2,1,0,0,0,0,0,1,2,2,2,1,0,0
0,0,0,1,2,2,2,1,0,0,0,0,1,2,2,4,2,2,1,0,0,0,1,2,2,4,2,2,1,0,0,0,0,1,2,2,2,1,0,0,0
0,0,0,1,2,2,2,1,0,0,0,0,1,2,2,2,2,2,1,0,0,0,1,2,2,2,2,2,1,0,0,0,0,1,2,2,2,1,0,0,0
0,0,0,0,1,2,2,2,1,0,0,1,2,2,2,2,2,1,0,0,0,0,0,1,2,2,2,2,2,1,0,0,1,2,2,2,1,0,0,0,0
0,0,0,0,1,16,16,16,1,0,1,2,2,2,1,1,1,0,0,0,0,0,0,0,1,1,1,2,2,2,1,0,1,16,16,16,1,0,0,0,0
0,0,0,0,16,2,2,2,16,16,2,2,2,1,0,0,0,0,0,0,0,0,0,0,0,0,0,1,2,2,2,16,16,2,2,2,16,0,0,0,0
0,0,0,2,2,2,2,2,2,2,16,2,1,0,0,0,0,0,0,0,0,0,0,0,0,0,0,0,1,2,16,2,2,2,2,2,2,2,0,0,0
0,0,2,2,2,2,2,2,2,2,2,16,0,0,0,0,0,0,0,0,0,0,0,0,0,0,0,0,0,16,2,2,2,2,2,2,2,2,2,0,0
0,0,2,2,2,21,21,21,2,2,2,16,1,1,0,0,0,0,0,0,0,0,0,0,0,0,0,1,1,16,2,2,2,21,21,21,2,2,2,0,0
0,2,2,2,21,0,0,0,21,2,2,2,16,2,1,1,0,0,0,0,0,0,0,0,0,1,1,2,16,2,2,2,21,0,17,13,21,2,2,2,0
0,2,2,2,21,0,16,15,21,2,2,2,16,2,2,2,1,1,1,1,1,1,1,1,1,2,2,2,16,2,2,2,21,0,16,0,21,2,2,2,0
0,2,2,2,21,0,0,8,21,2,2,2,16,2,2,2,2,2,2,2,2,2,2,2,2,2,2,2,16,2,2,2,21,0,0,0,21,2,2,2,0
0,0,2,2,2,21,21,21,2,2,2,16,1,1,2,2,2,2,2,21,4,21,2,2,2,2,2,1,1,16,2,2,2,21,21,21,2,2,2,0,0
0,0,2,2,2,2,2,2,2,2,2,0,0,0,1,1,2,2,2,2,2,2,2,2,2,1,1,0,0,0,2,2,2,2,2,2,2,2,2,0,0
0,0,0,2,2,2,2,2,2,2,0,0,0,0,0,0,1,1,1,1,1,1,1,1,1,0,0,0,0,0,0,2,2,2,2,2,2,2,0,0,0
0,0,0,0,0,2,2,2,0,0,0,0,0,0,0,0,0,0,0,0,0,0,0,0,0,0,0,0,0,0,0,0,0,2,2,2,0,0,0,0,0
0,0,0,0,0,0,0,0,0,0,0,0,0,0,0,0,0,0,0,0,0,0,0,0,0,0,0,0,0,0,0,0,0,0,0,0,0,0,0,0,0
endlayer

layer
0,0,0,0,0,16,16,16,0,0,0,0,0,0,0,0,0,0,0,0,0,0,0,0,0,0,0,0,0,0,0,0,0,16,16,16,0,0,0,0,0
0,0,0,16,16,0,53,52,16,16,0,0,0,0,0,0,0,0,0,0,0,0,0,0,0,0,0,0,0,0,0,16,16,51,50,0,16,16,0,0,0
0,0,16,0,54,0,0,25,16,23,16,0,0,0,0,0,16,16,16,16,16,16,16,16,16,0,0,0,0,0,16,23,16,25,0,0,54,0,16,0,0
0,16,0,25,0,0,16,16,16,33,33,16,0,0,16,16,0,25,0,26,33,24,0,25,0,16,16,0,0,16,33,33,16,16,16,0,0,25,0,16,0
0,16,56,0,0,0,0,0,0,0,0,16,16,16,0,0,0,0,0,0,0,0,0,0,0,0,0,16,16,16,0,0,0,0,0,0,0,0,55,16,0
16,0,0,0,0,0,0,0,0,0,0,0,16,0,0,0,0,0,0,0,0,0,0,0,0,0,0,0,16,0,0,0,0,0,0,0,0,0,0,0,16
16,57,0,16,0,0,16,0,0,0,0,0,58,0,0,0,16,16,16,16,16,16,16,16,16,0,0,0,28,0,0,0,0,0,16,0,0,16,0,57,16
16,59,25,16,0,0,0,0,0,0,0,0,16,0,16,16,0,0,0,0,0,0,0,0,0,16,16,0,16,0,0,0,0,0,0,0,0,16,25,59,16
0,16,16,16,0,0,0,0,0,0,0,16,16,16,0,0,0,0,0,0,0,0,0,0,0,0,0,16,16,16,0,0,0,0,0,0,0,16,16,16,0
0,16,23,26,0,0,0,0,0,0,0,16,0,0,0,0,0,0,0,0,0,0,0,0,0,0,0,0,0,16,0,0,0,0,0,0,0,24,23,16,0
0,0,16,26,0,0,0,0,0,0,0,27,16,0,0,0,0,0,0,0,0,0,0,0,0,0,0,0,16,34,0,0,0,0,0,0,0,24,16,0,0
0,0,0,16,16,0,0,0,16,16,29,0,0,16,0,0,0,0,0,0,0,0,0,0,0,0,0,16,0,0,29,16,16,0,0,0,16,16,0,0,0
0,0,0,0,16,16,36,16,16,0,16,0,0,0,16,16,16,0,0,0,0,0,0,0,16,16,16,0,0,0,16,0,16,16,36,16,16,0,0,0,0
0,0,0,0,16,0,0,0,16,0,0,16,0,40,60,60,60,16,0,0,0,0,0,16,60,60,60,40,0,16,0,0,16,0,0,0,16,0,0,0,0
0,0,0,16,0,0,0,16,0,0,0,0,16,60,60,60,60,60,16,0,0,0,16,60,60,60,60,60,16,0,0,0,0,16,0,0,0,16,0,0,0
0,0,0,16,0,0,0,16,0,0,0,0,16,60,60,22,60,60,16,0,0,0,16,60,60,22,60,60,16,0,0,0,0,16,0,0,0,16,0,0,0
0,0,16,0,0,0,16,0,0,0,0,0,16,60,60,60,60,60,16,0,0,0,16,60,60,60,60,60,16,0,0,0,0,0,16,0,0,0,16,0,0
0,0,16,25,0,0,16,0,0,0,0,0,0,16,60,60,60,16,0,0,0,0,0,16,60,60,60,16,0,0,0,0,0,0,16,0,0,25,16,0,0
0,0,16,0,0,0,16,0,0,0,0,0,0,0,16,16,16,0,0,0,0,0,0,0,16,16,16,0,0,0,0,0,0,0,16,0,0,0,16,0,0
0,0,16,33,0,0,16,0,0,0,0,0,0,0,0,0,0,0,0,0,0,0,0,0,0,0,0,0,0,0,0,0,0,0,16,0,0,33,16,0,0
0,0,16,26,0,0,16,0,0,0,0,0,0,0,0,0,0,0,0,0,0,0,0,0,0,0,0,0,0,0,0,0,0,0,16,0,0,24,16,0,0
0,0,16,35,0,0,16,0,0,0,0,0,0,0,0,0,0,0,0,0,0,0,0,0,0,0,0,0,0,0,0,0,0,0,16,0,0,35,16,0,0
0,0,16,0,0,0,16,0,0,0,0,0,0,0,16,16,16,0,0,0,0,0,0,0,16,16,16,0,0,0,0,0,0,0,16,0,0,0,16,0,0
0,0,16,25,0,0,16,0,0,0,0,0,0,16,60,60,60,16,0,0,0,0,0,16,60,60,60,16,0,0,0,0,0,0,16,0,0,25,16,0,0
0,0,16,0,0,0,16,0,0,0,0,0,16,60,60,60,60,60,16,0,0,0,16,60,60,60,60,60,16,0,0,0,0,0,16,0,0,0,16,0,0
0,0,0,16,0,0,0,16,0,0,0,0,16,60,60,22,60,60,16,0,0,0,16,60,60,22,60,60,16,0,0,0,0,16,0,0,0,16,0,0,0
0,0,0,16,0,0,0,16,0,0,0,0,16,60,60,60,60,60,16,0,0,0,16,60,60,60,60,60,16,0,0,0,0,16,0,0,0,16,0,0,0
0,0,0,0,16,0,0,0,16,0,0,16,0,40,60,60,60,16,0,0,0,0,0,16,60,60,60,40,0,16,0,0,16,0,0,0,16,0,0,0,0
0,0,0,0,16,16,31,16,16,0,16,0,0,0,16,16,16,0,0,0,0,0,0,0,16,16,16,0,0,0,16,0,16,16,31,16,16,0,0,0,0
0,0,0,16,16,0,0,0,16,16,30,0,0,16,0,0,0,0,0,0,0,0,0,0,0,0,0,16,0,0,30,16,16,0,0,0,16,16,0,0,0
0,0,16,26,0,0,0,0,0,0,0,27,16,0,0,0,0,0,0,0,0,0,0,0,0,0,0,0,16,34,0,0,0,0,0,0,0,24,16,0,0
0,16,23,26,0,0,0,0,0,0,0,16,0,0,0,0,0,0,0,0,0,0,0,0,0,0,0,0,0,16,0,0,0,0,0,0,0,24,23,16,0
0,16,16,16,0,0,0,0,0,0,0,16,16,16,0,0,0,0,0,0,0,0,0,0,0,0,0,16,16,16,0,0,0,0,0,0,0,16,16,16,0
16,61,25,16,0,0,0,0,0,0,0,0,16,0,16,16,0,0,0,0,0,0,0,0,0,16,16,0,16,0,0,0,0,0,0,0,0,16,25,61,16
16,62,0,16,0,0,16,0,0,0,0,0,58,0,0,0,16,16,16,16,16,16,16,16,16,0,0,0,28,0,0,0,0,0,16,0,0,16,0,62,16
16,0,0,0,0,0,0,0,0,0,0,0,16,0,0,0,0,0,0,0,0,0,0,0,0,0,0,0,16,0,0,0,0,0,0,0,0,0,0,0,16
0,16,56,0,0,0,0,0,0,0,0,16,16,16,0,0,0,0,0,0,0,0,0,0,0,0,0,16,16,16,0,0,0,0,0,0,0,0,55,16,0
0,16,0,25,0,0,16,16,16,35,35,16,0,0,16,16,0,25,0,26,35,24,0,25,0,16,16,0,0,16,35,35,16,16,16,0,0,25,0,16,0
0,0,16,0,63,0,0,25,16,23,16,0,0,0,0,0,16,16,16,16,16,16,16,16,16,0,0,0,0,0,16,23,16,25,0,0,63,0,16,0,0
0,0,0,16,16,0,53,52,16,16,0,0,0,0,0,0,0,0,0,0,0,0,0,0,0,0,0,0,0,0,0,16,16,51,50,0,16,16,0,0,0
0,0,0,0,0,16,16,16,0,0,0,0,0,0,0,0,0,0,0,0,0,0,0,0,0,0,0,0,0,0,0,0,0,16,16,16,0,0,0,0,0
endlayer

layer
0,0,0,0,0,16,21,16,0,0,0,0,0,0,0,0,0,0,0,0,0,0,0,0,0,0,0,0,0,0,0,0,0,16,21,16,0,0,0,0,0
0,0,0,16,16,0,0,0,16,16,0,0,0,0,0,0,0,0,0,0,0,0,0,0,0,0,0,0,0,0,0,16,16,0,0,0,16,16,0,0,0
0,0,16,0,0,0,0,38,40,37,16,0,0,0,0,0,40,40,16,40,40,40,16,40,40,0,0,0,0,0,16,37,40,38,0,0,0,0,16,0,0
0,16,0,49,0,0,40,40,40,0,0,16,0,0,40,40,0,38,0,0,0,0,0,38,0,40,40,0,0,16,0,0,40,40,40,0,0,49,0,16,0
0,16,0,0,0,0,0,0,0,0,0,16,40,40,0,0,0,0,0,0,0,0,0,0,0,0,0,40,40,16,0,0,0,0,0,0,0,0,0,16,0
16,0,0,0,0,0,0,0,0,0,0,0,16,0,0,0,0,0,0,0,0,0,0,0,0,0,0,0,16,0,0,0,0,0,0,0,0,0,0,0,16
21,0,0,40,0,0,40,0,0,0,0,0,42,0,0,0,40,40,16,40,40,40,16,40,40,0,0,0,43,0,0,0,0,0,40,0,0,40,0,0,21
16,0,38,40,0,0,0,0,0,0,0,0,16,0,40,40,0,0,0,0,0,0,0,0,0,40,40,0,16,0,0,0,0,0,0,0,0,40,38,0,16
0,16,40,40,0,0,0,0,0,0,0,16,40,40,0,0,0,0,0,0,0,0,0,0,0,0,0,40,40,16,0,0,0,0,0,0,0,40,40,16,0
0,16,37,0,0,0,0,0,0,0,0,16,0,0,0,0,0,0,0,0,0,0,0,0,0,0,0,0,0,16,0,0,0,0,0,0,0,0,37,16,0
0,0,16,0,0,0,0,0,0,0,0,43,40,0,0,0,0,0,0,0,0,0,0,0,0,0,0,0,40,42,0,0,0,0,0,0,0,0,16,0,0
0,0,0,16,16,0,0,0,16,16,42,0,0,40,0,0,0,0,0,0,0,0,0,0,0,0,0,40,0,0,43,16,16,0,0,0,16,16,0,0,0
0,0,0,0,40,16,42,16,40,0,40,0,0,0,16,16,16,0,0,0,0,0,0,0,16,16,16,0,0,0,40,0,40,16,43,16,40,0,0,0,0
0,0,0,0,40,0,0,0,40,0,0,40,0,0,64,64,64,16,0,0,0,0,0,16,64,64,64,0,0,40,0,0,40,0,0,0,40,0,0,0,0
0,0,0,40,0,0,0,40,0,0,0,0,16,64,64,64,64,64,16,5,5,5,16,64,64,64,64,64,16,0,0,0,0,40,0,0,0,40,0,0,0
0,0,0,40,0,0,0,40,0,0,0,0,16,64,64,25,64,64,16,21,21,21,16,64,64,25,64,64,16,0,0,0,0,40,0,0,0,40,0,0,0
0,0,40,0,0,0,40,0,0,0,0,0,16,64,64,64,64,64,16,13,13,13,16,64,64,64,64,64,16,0,0,0,0,0,40,0,0,0,40,0,0
0,0,40,38,0,0,40,0,0,0,0,0,0,16,64,64,64,16,0,0,0,0,0,16,64,64,64,16,0,0,0,0,0,0,40,0,0,38,40,0,0
0,0,16,0,0,0,16,0,0,0,0,0,0,0,16,16,16,0,0,0,0,0,0,0,16,16,16,0,0,0,0,0,0,0,16,0,0,0,16,0,0
0,0,40,0,0,0,40,0,0,0,0,0,0,0,8,21,6,0,0,0,0,0,0,0,8,21,6,0,0,0,0,0,0,0,40,0,0,0,40,0,0
0,0,40,0,0,0,40,0,0,0,0,0,0,0,8,21,6,0,0,0,0,0,0,0,8,21,6,0,0,0,0,0,0,0,40,0,0,0,40,0,0
0,0,40,0,0,0,40,0,0,0,0,0,0,0,8,21,6,0,0,0,0,0,0,0,8,21,6,0,0,0,0,0,0,0,40,0,0,0,40,0,0
0,0,16,0,0,0,16,0,0,0,0,0,0,0,16,16,16,0,0,0,0,0,0,0,16,16,16,0,0,0,0,0,0,0,16,0,0,0,16,0,0
0,0,40,38,0,0,40,0,0,0,0,0,0,16,64,64,64,16,0,0,0,0,0,16,64,64,64,16,0,0,0,0,0,0,40,0,0,38,40,0,0
0,0,40,0,0,0,40,0,0,0,0,0,16,64,64,64,64,64,16,5,5,5,16,64,64,64,64,64,16,0,0,0,0,0,40,0,0,0,40,0,0
0,0,0,40,0,0,0,40,0,0,0,0,16,64,64,25,64,64,16,21,21,21,16,64,64,25,64,64,16,0,0,0,0,40,0,0,0,40,0,0,0
0,0,0,40,0,0,0,40,0,0,0,0,16,64,64,64,64,64,16,13,13,13,16,64,64,64,64,64,16,0,0,0,0,40,0,0,0,40,0,0,0
0,0,0,0,40,0,0,0,40,0,0,40,0,0,64,64,64,16,0,0,0,0,0,16,64,64,64,0,0,40,0,0,40,0,0,0,40,0,0,0,0
0,0,0,0,40,16,43,16,40,0,40,0,0,0,16,16,16,0,0,0,0,0,0,0,16,16,16,0,0,0,40,0,40,16,43,16,40,0,0,0,0
0,0,0,16,16,0,0,0,16,16,43,0,0,40,0,0,0,0,0,0,0,0,0,0,0,0,0,40,0,0,42,16,16,0,0,0,16,16,0,0,0
0,0,16,0,0,0,0,0,0,0,0,42,40,0,0,0,0,0,0,0,0,0,0,0,0,0,0,0,40,43,0,0,0,0,0,0,0,0,16,0,0
0,16,37,0,0,0,0,0,0,0,0,16,0,0,0,0,0,0,0,0,0,0,0,0,0,0,0,0,0,16,0,0,0,0,0,0,0,0,37,16,0
0,16,40,40,0,0,0,0,0,0,0,16,40,40,0,0,0,0,0,0,0,0,0,0,0,0,0,40,40,16,0,0,0,0,0,0,0,40,40,16,0
16,0,38,40,0,0,0,0,0,0,0,0,16,0,40,40,0,0,0,0,0,0,0,0,0,40,40,0,16,0,0,0,0,0,0,0,0,40,38,0,16
21,0,0,40,0,0,40,0,0,0,0,0,42,0,0,0,40,40,16,40,40,40,16,40,40,0,0,0,42,0,0,0,0,0,40,0,0,40,0,0,21
16,0,0,0,0,0,0,0,0,0,0,0,16,0,0,0,0,0,0,0,0,0,0,0,0,0,0,0,16,0,0,0,0,0,0,0,0,0,0,0,16
0,16,0,0,0,0,0,0,0,0,0,16,40,40,0,0,0,0,0,0,0,0,0,0,0,0,0,40,40,16,0,0,0,0,0,0,0,0,0,16,0
0,16,0,49,0,0,40,40,40,0,0,16,0,0,40,40,0,38,0,0,0,0,0,38,0,40,40,0,0,16,0,0,40,40,40,0,0,49,0,16,0
0,0,16,0,0,0,0,38,40,37,16,0,0,0,0,0,40,40,16,40,40,40,16,40,40,0,0,0,0,0,16,37,40,38,0,0,0,0,16,0,0
0,0,0,16,16,0,0,0,16,16,0,0,0,0,0,0,0,0,0,0,0,0,0,0,0,0,0,0,0,0,0,16,16,0,0,0,16,16,0,0,0
0,0,0,0,0,16,21,16,0,0,0,0,0,0,0,0,0,0,0,0,0,0,0,0,0,0,0,0,0,0,0,0,0,16,21,16,0,0,0,0,0
endlayer

layer
0,0,0,0,0,16,21,16,0,0,0,0,0,0,0,0,0,0,0,0,0,0,0,0,0,0,0,0,0,0,0,0,0,16,21,16,0,0,0,0,0
0,0,0,16,16,0,0,0,16,16,0,0,0,0,0,0,0,0,0,0,0,0,0,0,0,0,0,0,0,0,0,16,16,0,0,0,16,16,0,0,0
0,0,16,0,0,0,0,0,0,46,16,0,0,0,0,0,0,0,16,0,0,0,16,0,0,0,0,0,0,0,16,46,0,0,0,0,0,0,16,0,0
0,16,0,0,0,0,0,0,0,0,0,16,0,0,0,0,0,0,0,0,0,0,0,0,0,0,0,0,0,16,0,0,0,0,0,0,0,0,0,16,0
0,16,0,0,0,0,0,0,0,0,0,16,0,0,0,0,0,0,0,0,0,0,0,0,0,0,0,0,0,16,0,0,0,0,0,0,0,0,0,16,0
16,0,0,0,0,0,0,0,0,0,0,0,16,0,0,0,0,0,0,0,0,0,0,0,0,0,0,0,16,0,0,0,0,0,0,0,0,0,0,0,16
21,0,0,0,0,0,0,0,0,0,0,0,16,0,0,0,0,0,16,0,0,0,16,0,0,0,0,0,16,0,0,0,0,0,0,0,0,0,0,0,21
16,0,0,0,0,0,0,0,0,0,0,0,16,0,0,0,0,0,0,0,0,0,0,0,0,0,0,0,16,0,0,0,0,0,0,0,0,0,0,0,16
0,16,0,0,0,0,0,0,0,0,0,16,0,0,0,0,0,0,0,0,0,0,0,0,0,0,0,0,0,16,0,0,0,0,0,0,0,0,0,16,0
0,16,46,0,0,0,0,0,0,0,0,16,0,0,0,0,0,0,0,0,0,0,0,0,0,0,0,0,0,16,0,0,0,0,0,0,0,0,46,16,0
0,0,16,0,0,0,0,0,0,0,16,0,0,0,0,0,0,0,0,0,0,0,0,0,0,0,0,0,0,0,16,0,0,0,0,0,0,0,16,0,0
0,0,0,16,16,0,0,0,16,16,0,0,0,0,0,0,0,0,0,0,0,0,0,0,0,0,0,0,0,0,0,16,16,0,0,0,16,16,0,0,0
0,0,0,0,0,16,16,16,0,0,0,0,0,0,40,40,40,0,0,0,0,0,0,0,40,40,40,0,0,0,0,0,0,16,16,16,0,0,0,0,0
0,0,0,0,0,0,0,0,0,0,0,0,0,0,0,0,0,40,0,0,0,0,0,40,0,0,0,0,0,0,0,0,0,0,0,0,0,0,0,0,0
0,0,0,0,0,0,0,0,0,0,0,0,40,0,0,0,0,0,40,0,0,0,40,0,0,0,0,0,40,0,0,0,0,0,0,0,0,0,0,0,0
0,0,0,0,0,0,0,0,0,0,0,0,40,0,0,25,0,0,40,0,0,0,40,0,0,25,0,0,40,0,0,0,0,0,0,0,0,0,0,0,0
0,0,0,0,0,0,0,0,0,0,0,0,40,0,0,0,0,0,40,0,0,0,40,0,0,0,0,0,40,0,0,0,0,0,0,0,0,0,0,0,0
0,0,0,0,0,0,0,0,0,0,0,0,0,40,0,0,0,40,0,0,0,0,0,40,0,0,0,40,0,0,0,0,0,0,0,0,0,0,0,0,0
0,0,16,0,0,0,16,0,0,0,0,0,0,0,40,40,40,0,0,0,0,0,0,0,40,40,40,0,0,0,0,0,0,0,16,0,0,0,16,0,0
0,0,0,0,0,0,0,0,0,0,0,0,0,0,0,0,0,0,0,0,0,0,0,0,0,0,0,0,0,0,0,0,0,0,0,0,0,0,0,0,0
0,0,0,0,0,0,0,0,0,0,0,0,0,0,0,0,0,0,0,0,0,0,0,0,0,0,0,0,0,0,0,0,0,0,0,0,0,0,0,0,0
0,0,0,0,0,0,0,0,0,0,0,0,0,0,0,0,0,0,0,0,0,0,0,0,0,0,0,0,0,0,0,0,0,0,0,0,0,0,0,0,0
0,0,16,0,0,0,16,0,0,0,0,0,0,0,40,40,40,0,0,0,0,0,0,0,40,40,40,0,0,0,0,0,0,0,16,0,0,0,16,0,0
0,0,0,0,0,0,0,0,0,0,0,0,0,40,0,0,0,40,0,0,0,0,0,40,0,0,0,40,0,0,0,0,0,0,0,0,0,0,0,0,0
0,0,0,0,0,0,0,0,0,0,0,0,40,0,0,0,0,0,40,0,0,0,40,0,0,0,0,0,40,0,0,0,0,0,0,0,0,0,0,0,0
0,0,0,0,0,0,0,0,0,0,0,0,40,0,0,25,0,0,40,0,0,0,40,0,0,25,0,0,40,0,0,0,0,0,0,0,0,0,0,0,0
0,0,0,0,0,0,0,0,0,0,0,0,40,0,0,0,0,0,40,0,0,0,40,0,0,0,0,0,40,0,0,0,0,0,0,0,0,0,0,0,0
0,0,0,0,0,0,0,0,0,0,0,0,0,0,0,0,0,40,0,0,0,0,0,40,0,0,0,0,0,0,0,0,0,0,0,0,0,0,0,0,0
0,0,0,0,0,16,16,16,0,0,0,0,0,0,40,40,40,0,0,0,0,0,0,0,40,40,40,0,0,0,0,0,0,16,16,16,0,0,0,0,0
0,0,0,16,16,0,0,0,16,16,0,0,0,0,0,0,0,0,0,0,0,0,0,0,0,0,0,0,0,0,0,16,16,0,0,0,16,16,0,0,0
0,0,16,0,0,0,0,0,0,0,16,0,0,0,0,0,0,0,0,0,0,0,0,0,0,0,0,0,0,0,16,0,0,0,0,0,0,0,16,0,0
0,16,46,0,0,0,0,0,0,0,0,16,0,0,0,0,0,0,0,0,0,0,0,0,0,0,0,0,0,16,0,0,0,0,0,0,0,0,46,16,0
0,16,0,0,0,0,0,0,0,0,0,16,0,0,0,0,0,0,0,0,0,0,0,0,0,0,0,0,0,16,0,0,0,0,0,0,0,0,0,16,0
16,0,0,0,0,0,0,0,0,0,0,0,16,0,0,0,0,0,0,0,0,0,0,0,0,0,0,0,16,0,0,0,0,0,0,0,0,0,0,0,16
21,0,0,0,0,0,0,0,0,0,0,0,16,0,0,0,0,0,16,0,0,0,16,0,0,0,0,0,16,0,0,0,0,0,0,0,0,0,0,0,21
16,0,0,0,0,0,0,0,0,0,0,0,16,0,0,0,0,0,0,0,0,0,0,0,0,0,0,0,16,0,0,0,0,0,0,0,0,0,0,0,16
0,16,0,0,0,0,0,0,0,0,0,16,0,0,0,0,0,0,0,0,0,0,0,0,0,0,0,0,0,16,0,0,0,0,0,0,0,0,0,16,0
0,16,0,0,0,0,0,0,0,0,0,16,0,0,0,0,0,0,0,0,0,0,0,0,0,0,0,0,0,16,0,0,0,0,0,0,0,0,0,16,0
0,0,16,0,0,0,0,0,0,46,16,0,0,0,0,0,0,0,16,0,0,0,16,0,0,0,0,0,0,0,16,46,0,0,0,0,0,0,16,0,0
0,0,0,16,16,0,0,0,16,16,0,0,0,0,0,0,0,0,0,0,0,0,0,0,0,0,0,0,0,0,0,16,16,0,0,0,16,16,0,0,0
0,0,0,0,0,16,21,16,0,0,0,0,0,0,0,0,0,0,0,0,0,0,0,0,0,0,0,0,0,0,0,0,0,16,21,16,0,0,0,0,0
endlayer

layer
0,0,0,0,0,16,21,16,0,0,0,0,0,0,0,0,0,0,0,0,0,0,0,0,0,0,0,0,0,0,0,0,0,16,21,16,0,0,0,0,0
0,0,0,16,16,0,0,0,16,16,0,0,0,0,0,0,0,5,5,5,5,5,5,6,0,0,0,0,0,0,0,16,16,0,0,0,16,16,0,0,0
0,0,16,0,0,0,0,0,0,0,16,0,0,0,0,0,0,8,2,2,2,2,2,6,0,0,0,0,0,0,16,0,0,0,0,0,0,0,16,0,0
0,16,0,0,0,0,0,0,0,0,0,16,0,0,0,0,0,8,2,0,0,0,2,6,0,0,0,0,0,16,0,0,0,0,0,0,0,0,0,16,0
0,16,0,0,0,0,0,0,0,0,0,16,0,0,0,0,0,8,2,0,0,0,2,6,0,0,0,0,0,16,0,0,0,0,0,0,0,0,0,16,0
16,0,0,0,0,0,0,0,0,0,0,0,16,0,0,0,0,8,2,0,0,0,2,6,0,0,0,0,16,0,0,0,0,0,0,0,0,0,0,0,16
21,0,0,0,0,0,0,0,0,0,0,0,4,0,0,0,0,8,2,2,2,2,2,6,0,0,0,0,4,0,0,0,0,0,0,0,0,0,0,0,21
16,0,0,0,0,0,0,0,0,0,0,0,16,0,0,0,0,8,13,13,13,13,13,6,0,0,0,0,16,0,0,0,0,0,0,0,0,0,0,0,16
0,16,0,0,0,0,0,0,0,0,0,16,0,0,0,0,0,0,0,0,0,0,0,0,0,0,0,0,0,16,0,0,0,0,0,0,0,0,0,16,0
0,16,0,0,0,0,0,0,0,0,0,16,0,0,0,0,0,0,0,0,0,0,0,0,0,0,0,0,0,16,0,0,0,0,0,0,0,0,0,16,0
0,0,16,0,0,0,0,0,0,0,16,0,0,0,0,0,0,0,0,0,0,0,0,0,0,0,0,0,0,0,16,0,0,0,0,0,0,0,16,0,0
0,0,0,16,16,0,0,0,16,16,0,0,0,0,0,0,0,0,0,0,0,0,0,0,0,0,0,0,0,0,0,16,16,0,0,0,16,16,0,0,0
0,0,0,0,0,16,4,16,0,0,0,0,0,0,0,0,0,0,0,0,0,0,0,0,0,0,0,0,0,0,0,0,0,16,4,16,0,0,0,0,0
0,0,0,0,0,0,0,0,0,0,0,0,0,0,0,0,0,0,0,0,0,0,0,0,0,0,0,0,0,0,0,0,0,0,0,0,0,0,0,0,0
0,0,0,0,0,0,0,0,0,0,0,0,0,0,0,0,0,0,0,0,0,0,0,0,0,0,0,0,0,0,0,0,0,0,0,0,0,0,0,0,0
0,0,0,0,0,0,0,0,0,0,0,0,0,0,0,49,0,0,0,0,0,0,0,0,0,49,0,0,0,0,0,0,0,0,0,0,0,0,0,0,0
0,0,0,0,0,0,0,0,0,0,0,0,0,0,0,0,0,0,0,0,0,0,0,0,0,0,0,0,0,0,0,0,0,0,0,0,0,0,0,0,0
0,8,5,5,5,5,5,6,0,0,0,0,0,0,0,0,0,0,0,0,0,0,0,0,0,0,0,0,0,0,0,0,0,5,5,5,5,5,5,6,0
0,8,2,2,2,2,2,6,0,0,0,0,0,0,0,0,0,0,0,0,0,0,0,0,0,0,0,0,0,0,0,0,0,8,2,2,2,2,2,6,0
0,8,2,0,0,0,2,6,0,0,0,0,0,0,0,0,0,0,0,0,0,0,0,0,0,0,0,0,0,0,0,0,0,8,2,0,0,0,2,6,0
0,8,2,0,0,0,2,6,0,0,0,0,0,0,0,0,0,0,0,0,0,0,0,0,0,0,0,0,0,0,0,0,0,8,2,0,0,0,2,6,0
0,8,2,0,0,0,2,6,0,0,0,0,0,0,0,0,0,0,0,0,0,0,0,0,0,0,0,0,0,0,0,0,0,8,2,0,0,0,2,6,0
0,8,2,2,2,2,2,6,0,0,0,0,0,0,0,0,0,0,0,0,0,0,0,0,0,0,0,0,0,0,0,0,0,8,2,2,2,2,2,6,0
0,8,13,13,13,13,13,6,0,0,0,0,0,0,0,0,0,0,0,0,0,0,0,0,0,0,0,0,0,0,0,0,0,13,13,13,13,13,13,13,0
0,0,0,0,0,0,0,0,0,0,0,0,0,0,0,0,0,0,0,0,0,0,0,0,0,0,0,0,0,0,0,0,0,0,0,0,0,0,0,0,0
0,0,0,0,0,0,0,0,0,0,0,0,0,0,0,49,0,0,0,0,0,0,0,0,0,49,0,0,0,0,0,0,0,0,0,0,0,0,0,0,0
0,0,0,0,0,0,0,0,0,0,0,0,0,0,0,0,0,0,0,0,0,0,0,0,0,0,0,0,0,0,0,0,0,0,0,0,0,0,0,0,0
0,0,0,0,0,0,0,0,0,0,0,0,0,0,0,0,0,0,0,0,0,0,0,0,0,0,0,0,0,0,0,0,0,0,0,0,0,0,0,0,0
0,0,0,0,0,16,4,16,0,0,0,0,0,0,0,0,0,0,0,0,0,0,0,0,0,0,0,0,0,0,0,0,0,16,4,16,0,0,0,0,0
0,0,0,16,16,0,0,0,16,16,0,0,0,0,0,0,0,0,0,0,0,0,0,0,0,0,0,0,0,0,0,16,16,0,0,0,16,16,0,0,0
0,0,16,0,0,0,0,0,0,0,16,0,0,0,0,0,0,0,0,0,0,0,0,0,0,0,0,0,0,0,16,0,0,0,0,0,0,0,16,0,0
0,16,0,0,0,0,0,0,0,0,0,16,0,0,0,0,0,0,0,0,0,0,0,0,0,0,0,0,0,16,0,0,0,0,0,0,0,0,0,16,0
0,16,0,0,0,0,0,0,0,0,0,16,0,0,0,0,0,0,0,0,0,0,0,0,0,0,0,0,0,16,0,0,0,0,0,0,0,0,0,16,0
16,0,0,0,0,0,0,0,0,0,0,0,16,0,0,0,0,8,5,5,5,5,5,6,0,0,0,0,16,0,0,0,0,0,0,0,0,0,0,0,16
21,0,0,0,0,0,0,0,0,0,0,0,4,0,0,0,0,8,2,2,2,2,2,6,0,0,0,0,4,0,0,0,0,0,0,0,0,0,0,0,21
16,0,0,0,0,0,0,0,0,0,0,0,16,0,0,0,0,8,2,0,0,0,2,6,0,0,0,0,16,0,0,0,0,0,0,0,0,0,0,0,16
0,16,0,0,0,0,0,0,0,0,0,16,0,0,0,0,0,8,2,0,0,0,2,6,0,0,0,0,0,16,0,0,0,0,0,0,0,0,0,16,0
0,16,0,0,0,0,0,0,0,0,0,16,0,0,0,0,0,8,2,0,0,0,2,6,0,0,0,0,0,16,0,0,0,0,0,0,0,0,0,16,0
0,0,16,0,0,0,0,0,0,0,16,0,0,0,0,0,0,8,2,2,2,2,2,6,0,0,0,0,0,0,16,0,0,0,0,0,0,0,16,0,0
0,0,0,16,16,0,0,0,16,16,0,0,0,0,0,0,0,8,13,13,13,13,13,13,0,0,0,0,0,0,0,16,16,0,0,0,16,16,0,0,0
0,0,0,0,0,16,21,16,0,0,0,0,0,0,0,0,0,0,0,0,0,0,0,0,0,0,0,0,0,0,0,0,0,16,21,16,0,0,0,0,0
endlayer

layer
0,0,0,0,0,16,16,16,0,0,0,0,0,0,0,0,0,0,0,0,0,0,0,0,0,0,0,0,0,0,0,0,0,16,16,16,0,0,0,0,0
0,0,0,16,16,0,0,0,16,16,0,0,0,0,0,0,0,0,0,0,0,0,0,0,0,0,0,0,0,0,0,16,16,0,0,0,16,16,0,0,0
0,0,16,0,0,0,0,0,0,0,16,0,0,0,0,0,0,0,5,5,5,5,5,0,0,0,0,0,0,0,16,0,0,0,0,0,0,0,16,0,0
0,16,0,0,0,0,0,0,0,0,0,16,0,0,0,0,0,0,8,21,21,21,6,0,0,0,0,0,0,16,0,0,0,0,0,0,0,0,0,16,0
0,16,0,0,0,0,0,0,0,0,0,16,0,0,0,0,0,0,8,21,21,21,6,0,0,0,0,0,0,16,0,0,0,0,0,0,0,0,0,16,0
16,0,0,0,0,0,0,0,0,0,0,0,16,0,0,0,0,0,8,21,21,21,6,0,0,0,0,0,16,0,0,0,0,0,0,0,0,0,0,0,16
16,0,0,0,0,0,0,0,0,0,0,0,16,0,0,0,0,0,8,13,13,13,6,0,0,0,0,0,16,0,0,0,0,0,0,0,0,0,0,0,16
16,0,0,0,0,0,0,0,0,0,0,0,16,0,0,0,0,0,0,0,0,0,0,0,0,0,0,0,16,0,0,0,0,0,0,0,0,0,0,0,16
0,16,0,0,0,0,0,0,0,0,0,16,0,0,0,0,0,0,0,0,0,0,0,0,0,0,0,0,0,16,0,0,0,0,0,0,0,0,0,16,0
0,16,0,0,0,0,0,0,0,0,0,16,0,0,0,0,0,0,0,0,0,0,0,0,0,0,0,0,0,16,0,0,0,0,0,0,0,0,0,16,0
0,0,16,0,0,0,0,0,0,0,16,0,0,0,0,0,0,0,0,0,0,0,0,0,0,0,0,0,0,0,16,0,0,0,0,0,0,0,16,0,0
0,0,0,16,16,0,0,0,16,16,0,0,0,0,0,0,0,0,0,0,0,0,0,0,0,0,0,0,0,0,0,16,16,0,0,0,16,16,0,0,0
0,0,0,0,0,16,16,16,0,0,0,0,0,0,0,0,0,0,0,0,0,0,0,0,0,0,0,0,0,0,0,0,0,16,16,16,0,0,0,0,0
0,0,0,0,0,0,0,0,0,0,0,0,0,0,0,0,0,0,0,0,0,0,0,0,0,0,0,0,0,0,0,0,0,0,0,0,0,0,0,0,0
0,0,0,0,0,0,0,0,0,0,0,0,0,0,0,0,0,0,0,0,0,0,0,0,0,0,0,0,0,0,0,0,0,0,0,0,0,0,0,0,0
0,0,0,0,0,0,0,0,0,0,0,0,0,0,0,0,0,0,0,0,0,0,0,0,0,0,0,0,0,0,0,0,0,0,0,0,0,0,0,0,0
0,0,0,0,0,0,0,0,0,0,0,0,0,0,0,0,0,0,0,0,0,0,0,0,0,0,0,0,0,0,0,0,0,0,0,0,0,0,0,0,0
0,0,0,0,0,0,0,0,0,0,0,0,0,0,0,0,0,0,0,0,0,0,0,0,0,0,0,0,0,0,0,0,0,0,0,0,0,0,0,0,0
0,0,5,5,5,5,6,0,0,0,0,0,0,0,0,0,0,0,0,0,0,0,0,0,0,0,0,0,0,0,0,0,0,0,8,5,5,5,5,0,0
0,0,8,21,21,21,6,0,0,0,0,0,0,0,0,0,0,0,0,0,0,0,0,0,0,0,0,0,0,0,0,0,0,0,8,21,21,21,6,0,0
0,0,8,21,21,21,6,0,0,0,0,0,0,0,0,0,0,0,0,0,0,0,0,0,0,0,0,0,0,0,0,0,0,0,8,21,21,21,6,0,0
0,0,8,21,21,21,6,0,0,0,0,0,0,0,0,0,0,0,0,0,0,0,0,0,0,0,0,0,0,0,0,0,0,0,8,21,21,21,6,0,0
0,0,13,13,13,13,6,0,0,0,0,0,0,0,0,0,0,0,0,0,0,0,0,0,0,0,0,0,0,0,0,0,0,0,8,13,13,13,13,0,0
0,0,0,0,0,0,0,0,0,0,0,0,0,0,0,0,0,0,0,0,0,0,0,0,0,0,0,0,0,0,0,0,0,0,0,0,0,0,0,0,0
0,0,0,0,0,0,0,0,0,0,0,0,0,0,0,0,0,0,0,0,0,0,0,0,0,0,0,0,0,0,0,0,0,0,0,0,0,0,0,0,0
0,0,0,0,0,0,0,0,0,0,0,0,0,0,0,0,0,0,0,0,0,0,0,0,0,0,0,0,0,0,0,0,0,0,0,0,0,0,0,0,0
0,0,0,0,0,0,0,0,0,0,0,0,0,0,0,0,0,0,0,0,0,0,0,0,0,0,0,0,0,0,0,0,0,0,0,0,0,0,0,0,0
0,0,0,0,0,0,0,0,0,0,0,0,0,0,0,0,0,0,0,0,0,0,0,0,0,0,0,0,0,0,0,0,0,0,0,0,0,0,0,0,0
0,0,0,0,0,16,16,16,0,0,0,0,0,0,0,0,0,0,0,0,0,0,0,0,0,0,0,0,0,0,0,0,0,16,16,16,0,0,0,0,0
0,0,0,16,16,0,0,0,16,16,0,0,0,0,0,0,0,0,0,0,0,0,0,0,0,0,0,0,0,0,0,16,16,0,0,0,16,16,0,0,0
0,0,16,0,0,0,0,0,0,0,16,0,0,0,0,0,0,0,0,0,0,0,0,0,0,0,0,0,0,0,16,0,0,0,0,0,0,0,16,0,0
0,16,0,0,0,0,0,0,0,0,0,16,0,0,0,0,0,0,0,0,0,0,0,0,0,0,0,0,0,16,0,0,0,0,0,0,0,0,0,16,0
0,16,0,0,0,0,0,0,0,0,0,16,0,0,0,0,0,0,0,0,0,0,0,0,0,0,0,0,0,16,0,0,0,0,0,0,0,0,0,16,0
16,0,0,0,0,0,0,0,0,0,0,0,16,0,0,0,0,0,0,0,0,0,0,0,0,0,0,0,16,0,0,0,0,0,0,0,0,0,0,0,16
16,0,0,0,0,0,0,0,0,0,0,0,16,0,0,0,0,0,5,5,5,5,5,0,0,0,0,0,16,0,0,0,0,0,0,0,0,0,0,0,16
16,0,0,0,0,0,0,0,0,0,0,0,16,0,0,0,0,0,8,21,21,21,6,0,0,0,0,0,16,0,0,0,0,0,0,0,0,0,0,0,16
0,16,0,0,0,0,0,0,0,0,0,16,0,0,0,0,0,0,8,21,21,21,6,0,0,0,0,0,0,16,0,0,0,0,0,0,0,0,0,16,0
0,16,0,0,0,0,0,0,0,0,0,16,0,0,0,0,0,0,8,21,21,21,6,0,0,0,0,0,0,16,0,0,0,0,0,0,0,0,0,16,0
0,0,16,0,0,0,0,0,0,0,16,0,0,0,0,0,0,0,13,13,13,13,6,0,0,0,0,0,0,0,16,0,0,0,0,0,0,0,16,0,0
0,0,0,16,16,0,0,0,16,16,0,0,0,0,0,0,0,0,0,0,0,0,0,0,0,0,0,0,0,0,0,16,16,0,0,0,16,16,0,0,0
0,0,0,0,0,16,16,16,0,0,0,0,0,0,0,0,0,0,0,0,0,0,0,0,0,0,0,0,0,0,0,0,0,16,16,16,0,0,0,0,0
endlayer

layer
0,0,0,0,0,40,40,40,0,0,0,0,0,0,0,0,0,0,0,0,0,0,0,0,0,0,0,0,0,0,0,0,0,40,40,40,0,0,0,0,0
0,0,0,40,40,21,21,21,40,40,0,0,0,0,0,0,0,0,0,0,0,0,0,0,0,0,0,0,0,0,0,40,40,21,21,21,40,40,0,0,0
0,0,40,21,21,0,0,0,21,21,40,0,0,0,0,0,0,0,0,0,0,0,0,0,0,0,0,0,0,0,40,21,21,0,0,0,21,21,40,0,0
0,40,21,0,0,0,0,0,0,0,21,40,0,0,0,0,0,0,0,0,0,0,0,0,0,0,0,0,0,40,21,21,0,0,0,0,0,21,21,40,0
0,40,21,0,0,0,0,0,0,0,21,40,0,0,0,0,0,0,0,0,0,0,0,0,0,0,0,0,0,40,21,0,0,0,0,0,0,0,21,40,0
40,21,0,0,0,0,0,0,0,0,0,21,40,0,0,0,0,0,0,0,0,0,0,0,0,0,0,0,40,21,0,0,0,0,0,0,0,0,0,21,40
40,21,0,0,0,0,0,0,0,0,0,21,40,0,0,0,0,0,0,0,0,0,0,0,0,0,0,0,40,21,0,0,0,0,0,0,0,0,0,21,40
40,21,0,0,0,0,0,0,0,0,0,21,40,0,0,0,0,0,0,0,0,0,0,0,0,0,0,0,40,21,0,0,0,0,0,0,0,0,0,21,40
0,40,21,0,0,0,0,0,0,0,21,40,0,0,0,0,0,0,0,0,0,0,0,0,0,0,0,0,0,40,21,0,0,0,0,0,0,0,21,40,0
0,40,21,0,0,0,0,0,0,0,21,40,0,0,0,0,0,0,0,0,0,0,0,0,0,0,0,0,0,40,21,21,0,0,0,0,0,21,21,40,0
0,0,40,21,21,0,0,0,21,21,40,0,0,0,0,0,0,0,0,0,0,0,0,0,0,0,0,0,0,0,40,21,21,0,0,0,21,21,40,0,0
0,0,0,40,40,21,21,21,40,40,0,0,0,0,0,0,0,0,0,0,0,0,0,0,0,0,0,0,0,0,0,40,40,21,21,21,40,40,0,0,0
0,0,0,0,0,40,40,40,0,0,0,0,0,0,0,0,0,0,0,0,0,0,0,0,0,0,0,0,0,0,0,0,0,40,40,40,0,0,0,0,0
0,0,0,0,0,0,0,0,0,0,0,0,0,0,0,0,0,0,0,0,0,0,0,0,0,0,0,0,0,0,0,0,0,0,0,0,0,0,0,0,0
0,0,0,0,0,0,0,0,0,0,0,0,0,0,0,0,0,0,0,0,0,0,0,0,0,0,0,0,0,0,0,0,0,0,0,0,0,0,0,0,0
0,0,0,0,0,0,0,0,0,0,0,0,0,0,0,0,0,0,0,0,0,0,0,0,0,0,0,0,0,0,0,0,0,0,0,0,0,0,0,0,0
0,0,0,0,0,0,0,0,0,0,0,0,0,0,0,0,0,0,0,0,0,0,0,0,0,0,0,0,0,0,0,0,0,0,0,0,0,0,0,0,0
0,0,0,0,0,0,0,0,0,0,0,0,0,0,0,0,0,0,0,0,0,0,0,0,0,0,0,0,0,0,0,0,0,0,0,0,0,0,0,0,0
0,0,0,0,0,0,0,0,0,0,0,0,0,0,0,0,0,0,0,0,0,0,0,0,0,0,0,0,0,0,0,0,0,0,0,0,0,0,0,0,0
0,0,0,0,0,0,0,0,0,0,0,0,0,0,0,0,0,0,0,0,0,0,0,0,0,0,0,0,0,0,0,0,0,0,0,0,0,0,0,0,0
0,0,0,0,0,0,0,0,0,0,0,0,0,0,0,0,0,0,0,0,0,0,0,0,0,0,0,0,0,0,0,0,0,0,0,0,0,0,0,0,0
0,0,0,0,0,0,0,0,0,0,0,0,0,0,0,0,0,0,0,0,0,0,0,0,0,0,0,0,0,0,0,0,0,0,0,0,0,0,0,0,0
0,0,0,0,0,0,0,0,0,0,0,0,0,0,0,0,0,0,0,0,0,0,0,0,0,0,0,0,0,0,0,0,0,0,0,0,0,0,0,0,0
0,0,0,0,0,0,0,0,0,0,0,0,0,0,0,0,0,0,0,0,0,0,0,0,0,0,0,0,0,0,0,0,0,0,0,0,0,0,0,0,0
0,0,0,0,0,0,0,0,0,0,0,0,0,0,0,0,0,0,0,0,0,0,0,0,0,0,0,0,0,0,0,0,0,0,0,0,0,0,0,0,0
0,0,0,0,0,0,0,0,0,0,0,0,0,0,0,0,0,0,0,0,0,0,0,0,0,0,0,0,0,0,0,0,0,0,0,0,0,0,0,0,0
0,0,0,0,0,0,0,0,0,0,0,0,0,0,0,0,0,0,0,0,0,0,0,0,0,0,0,0,0,0,0,0,0,0,0,0,0,0,0,0,0
0,0,0,0,0,0,0,0,0,0,0,0,0,0,0,0,0,0,0,0,0,0,0,0,0,0,0,0,0,0,0,0,0,0,0,0,0,0,0,0,0
0,0,0,0,0,40,40,40,0,0,0,0,0,0,0,0,0,0,0,0,0,0,0,0,0,0,0,0,0,0,0,0,0,40,40,40,0,0,0,0,0
0,0,0,40,40,21,21,21,40,40,0,0,0,0,0,0,0,0,0,0,0,0,0,0,0,0,0,0,0,0,0,40,40,21,21,21,40,40,0,0,0
0,0,40,21,21,0,0,0,21,21,40,0,0,0,0,0,0,0,0,0,0,0,0,0,0,0,0,0,0,0,40,21,21,0,0,0,21,21,40,0,0
0,40,21,0,0,0,0,0,0,0,21,40,0,0,0,0,0,0,0,0,0,0,0,0,0,0,0,0,0,40,21,0,0,0,0,0,0,0,21,40,0
0,40,21,0,0,0,0,0,0,0,21,40,0,0,0,0,0,0,0,0,0,0,0,0,0,0,0,0,0,40,21,0,0,0,0,0,0,0,21,40,0
40,21,0,0,0,0,0,0,0,0,0,21,40,0,0,0,0,0,0,0,0,0,0,0,0,0,0,0,40,21,0,0,0,0,0,0,0,0,0,21,40
40,21,0,0,0,0,0,0,0,0,0,21,40,0,0,0,0,0,0,0,0,0,0,0,0,0,0,0,40,21,21,0,0,0,0,0,0,0,0,21,40
40,21,0,0,0,0,0,0,0,0,0,21,40,0,0,0,0,0,0,0,0,0,0,0,0,0,0,0,40,21,21,0,0,0,0,0,0,0,0,21,40
0,40,21,0,0,0,0,0,0,0,21,40,0,0,0,0,0,0,0,0,0,0,0,0,0,0,0,0,0,40,21,0,0,0,0,0,0,0,21,40,0
0,40,21,0,0,0,0,0,0,0,21,40,0,0,0,0,0,0,0,0,0,0,0,0,0,0,0,0,0,40,21,0,0,0,0,0,0,0,21,40,0
0,0,40,21,21,0,0,0,21,21,40,0,0,0,0,0,0,0,0,0,0,0,0,0,0,0,0,0,0,0,40,21,21,0,0,0,21,21,40,0,0
0,0,0,40,40,21,21,21,40,40,0,0,0,0,0,0,0,0,0,0,0,0,0,0,0,0,0,0,0,0,0,40,40,21,21,21,40,40,0,0,0
0,0,0,0,0,40,40,40,0,0,0,0,0,0,0,0,0,0,0,0,0,0,0,0,0,0,0,0,0,0,0,0,0,40,40,40,0,0,0,0,0
endlayer

layer
0,0,0,0,0,0,0,0,0,0,0,0,0,0,0,0,0,0,0,0,0,0,0,0,0,0,0,0,0,0,0,0,0,0,0,0,0,0,0,0,0
0,0,0,0,0,0,0,0,0,0,0,0,0,0,0,0,0,0,0,0,0,0,0,0,0,0,0,0,0,0,0,0,0,0,0,0,0,0,0,0,0
0,0,0,0,0,21,21,21,0,0,0,0,0,0,0,0,0,0,0,0,0,0,0,0,0,0,0,0,0,0,0,0,0,21,21,21,0,0,0,0,0
0,0,0,21,21,21,21,21,21,21,0,0,0,0,0,0,0,0,0,0,0,0,0,0,0,0,0,0,0,0,0,0,21,21,21,21,21,0,0,0,0
0,0,0,21,21,21,21,21,21,21,0,0,0,0,0,0,0,0,0,0,0,0,0,0,0,0,0,0,0,0,0,21,21,21,21,21,21,21,0,0,0
0,0,21,21,21,21,21,21,21,21,21,0,0,0,0,0,0,0,0,0,0,0,0,0,0,0,0,0,0,0,21,21,21,21,21,21,21,21,21,0,0
0,0,21,21,21,21,21,21,21,21,21,0,0,0,0,0,0,0,0,0,0,0,0,0,0,0,0,0,0,0,21,21,21,21,21,21,21,21,21,0,0
0,0,21,21,21,21,21,21,21,21,21,0,0,0,0,0,0,0,0,0,0,0,0,0,0,0,0,0,0,0,21,21,21,21,21,21,21,21,21,0,0
0,0,0,21,21,21,21,21,21,21,0,0,0,0,0,0,0,0,0,0,0,0,0,0,0,0,0,0,0,0,0,21,21,21,21,21,21,21,0,0,0
0,0,0,21,21,21,21,21,21,21,0,0,0,0,0,0,0,0,0,0,0,0,0,0,0,0,0,0,0,0,0,0,21,21,21,21,21,0,0,0,0
0,0,0,0,0,21,21,21,0,0,0,0,0,0,0,0,0,0,0,0,0,0,0,0,0,0,0,0,0,0,0,0,0,21,21,21,0,0,0,0,0
0,0,0,0,0,0,0,0,0,0,0,0,0,0,0,0,0,0,0,0,0,0,0,0,0,0,0,0,0,0,0,0,0,0,0,0,0,0,0,0,0
0,0,0,0,0,0,0,0,0,0,0,0,0,0,0,0,0,0,0,0,0,0,0,0,0,0,0,0,0,0,0,0,0,0,0,0,0,0,0,0,0
0,0,0,0,0,0,0,0,0,0,0,0,0,0,0,0,0,0,0,0,0,0,0,0,0,0,0,0,0,0,0,0,0,0,0,0,0,0,0,0,0
0,0,0,0,0,0,0,0,0,0,0,0,0,0,0,0,0,0,0,0,0,0,0,0,0,0,0,0,0,0,0,0,0,0,0,0,0,0,0,0,0
0,0,0,0,0,0,0,0,0,0,0,0,0,0,0,0,0,0,0,0,0,0,0,0,0,0,0,0,0,0,0,0,0,0,0,0,0,0,0,0,0
0,0,0,0,0,0,0,0,0,0,0,0,0,0,0,0,0,0,0,0,0,0,0,0,0,0,0,0,0,0,0,0,0,0,0,0,0,0,0,0,0
0,0,0,0,0,0,0,0,0,0,0,0,0,0,0,0,0,0,0,0,0,0,0,0,0,0,0,0,0,0,0,0,0,0,0,0,0,0,0,0,0
0,0,0,0,0,0,0,0,0,0,0,0,0,0,0,0,0,0,0,0,0,0,0,0,0,0,0,0,0,0,0,0,0,0,0,0,0,0,0,0,0
0,0,0,0,0,0,0,0,0,0,0,0,0,0,0,0,0,0,0,0,0,0,0,0,0,0,0,0,0,0,0,0,0,0,0,0,0,0,0,0,0
0,0,0,0,0,0,0,0,0,0,0,0,0,0,0,0,0,0,0,0,0,0,0,0,0,0,0,0,0,0,0,0,0,0,0,0,0,0,0,0,0
0,0,0,0,0,0,0,0,0,0,0,0,0,0,0,0,0,0,0,0,0,0,0,0,0,0,0,0,0,0,0,0,0,0,0,0,0,0,0,0,0
0,0,0,0,0,0,0,0,0,0,0,0,0,0,0,0,0,0,0,0,0,0,0,0,0,0,0,0,0,0,0,0,0,0,0,0,0,0,0,0,0
0,0,0,0,0,0,0,0,0,0,0,0,0,0,0,0,0,0,0,0,0,0,0,0,0,0,0,0,0,0,0,0,0,0,0,0,0,0,0,0,0
0,0,0,0,0,0,0,0,0,0,0,0,0,0,0,0,0,0,0,0,0,0,0,0,0,0,0,0,0,0,0,0,0,0,0,0,0,0,0,0,0
0,0,0,0,0,0,0,0,0,0,0,0,0,0,0,0,0,0,0,0,0,0,0,0,0,0,0,0,0,0,0,0,0,0,0,0,0,0,0,0,0
0,0,0,0,0,0,0,0,0,0,0,0,0,0,0,0,0,0,0,0,0,0,0,0,0,0,0,0,0,0,0,0,0,0,0,0,0,0,0,0,0
0,0,0,0,0,0,0,0,0,0,0,0,0,0,0,0,0,0,0,0,0,0,0,0,0,0,0,0,0,0,0,0,0,0,0,0,0,0,0,0,0
0,0,0,0,0,0,0,0,0,0,0,0,0,0,0,0,0,0,0,0,0,0,0,0,0,0,0,0,0,0,0,0,0,0,0,0,0,0,0,0,0
0,0,0,0,0,0,0,0,0,0,0,0,0,0,0,0,0,0,0,0,0,0,0,0,0,0,0,0,0,0,0,0,0,0,0,0,0,0,0,0,0
0,0,0,0,0,21,21,21,0,0,0,0,0,0,0,0,0,0,0,0,0,0,0,0,0,0,0,0,0,0,0,0,0,21,21,21,0,0,0,0,0
0,0,0,21,21,21,21,21,21,21,0,0,0,0,0,0,0,0,0,0,0,0,0,0,0,0,0,0,0,0,0,21,21,21,21,21,21,21,0,0,0
0,0,0,21,21,21,21,21,21,21,0,0,0,0,0,0,0,0,0,0,0,0,0,0,0,0,0,0,0,0,0,21,21,21,21,21,21,21,0,0,0
0,0,21,21,21,21,21,21,21,21,21,0,0,0,0,0,0,0,0,0,0,0,0,0,0,0,0,0,0,0,21,21,21,21,21,21,21,21,21,0,0
0,0,21,21,21,21,21,21,21,21,21,0,0,0,0,0,0,0,0,0,0,0,0,0,0,0,0,0,0,0,21,21,21,21,21,21,21,21,21,0,0
0,0,21,21,21,21,21,21,21,21,21,0,0,0,0,0,0,0,0,0,0,0,0,0,0,0,0,0,0,0,21,21,21,21,21,21,21,21,21,0,0
0,0,0,21,21,21,21,21,21,21,0,0,0,0,0,0,0,0,0,0,0,0,0,0,0,0,0,0,0,0,0,21,21,21,21,21,21,21,0,0,0
0,0,0,21,21,21,21,21,21,21,0,0,0,0,0,0,0,0,0,0,0,0,0,0,0,0,0,0,0,0,0,21,21,21,21,21,21,21,0,0,0
0,0,0,0,0,21,21,21,0,0,0,0,0,0,0,0,0,0,0,0,0,0,0,0,0,0,0,0,0,0,0,0,0,21,21,21,0,0,0,0,0
0,0,0,0,0,0,0,0,0,0,0,0,0,0,0,0,0,0,0,0,0,0,0,0,0,0,0,0,0,0,0,0,0,0,0,0,0,0,0,0,0
0,0,0,0,0,0,0,0,0,0,0,0,0,0,0,0,0,0,0,0,0,0,0,0,0,0,0,0,0,0,0,0,0,0,0,0,0,0,0,0,0
endlayer

