
# Created by Ruins mod version 16.8 Ingame Parser
# authoring Player: ST753M

weight=1
embed_into_distance=-120
acceptable_target_blocks=
unacceptable_target_blocks=clouds,natura:clouds
dimensions=21,21,21
allowable_overhang=9999
max_leveling=0
leveling_buffer=0
preserve_water=0
preserve_lava=0

biomesToSpawnIn=sky,void

rule1=0,100,preserveBlock
rule2=0,100,minecraft:iron_block-0
rule3=0,100,quark:iron_rod-0
rule4=0,100,quark:iron_plate-0
rule5=0,100,minecraft:stained_glass-8
rule6=0,100,quark:iron_plate_slab-8
rule7=0,100,quark:iron_ladder-4
rule8=0,100,quark:iron_plate_stairs-4
rule9=0,100,quark:iron_plate_stairs-6
rule10=0,100,quark:iron_plate_stairs-7
rule11=0,100,quark:iron_plate_stairs-5
rule12=0,100,quark:iron_plate_stairs-0
rule13=0,100,quark:iron_plate_slab-0
rule14=0,100,quark:iron_plate_stairs-2
rule15=0,100,quark:iron_plate_stairs-3
rule16=0,100,quark:iron_plate_stairs-1
rule17=0,100,quark:iron_rod-1
rule18=0,100,quark:iron_ladder-2
rule19=0,100,air

layer
1,1,1,1,1,1,1,1,1,1,1,1,1,1,1,1,1,1,1,1,1
1,1,1,1,1,1,1,1,1,1,1,1,1,1,1,1,1,1,1,1,1
1,1,1,1,1,1,1,1,1,1,1,1,1,1,1,1,1,1,1,1,1
1,1,1,1,1,1,1,1,1,1,1,1,1,1,1,1,1,1,1,1,1
1,1,1,1,2,1,1,1,1,1,1,1,1,1,1,1,2,1,1,1,1
1,1,1,1,1,1,1,1,1,1,1,1,1,1,1,1,1,1,1,1,1
1,1,1,1,1,1,1,1,1,1,1,1,1,1,1,1,1,1,1,1,1
1,1,1,1,1,1,1,1,1,1,1,1,1,1,1,1,1,1,1,1,1
1,1,1,1,1,1,1,1,1,1,1,1,1,1,1,1,1,1,1,1,1
1,1,1,1,1,1,1,1,1,1,1,1,1,1,1,1,1,1,1,1,1
1,1,1,1,1,1,1,1,1,1,1,1,1,1,1,1,1,1,1,1,1
1,1,1,1,1,1,1,1,1,1,1,1,1,1,1,1,1,1,1,1,1
1,1,1,1,1,1,1,1,1,1,1,1,1,1,1,1,1,1,1,1,1
1,1,1,1,1,1,1,1,1,1,1,1,1,1,1,1,1,1,1,1,1
1,1,1,1,1,1,1,1,1,1,1,1,1,1,1,1,1,1,1,1,1
1,1,1,1,1,1,1,1,1,1,1,1,1,1,1,1,1,1,1,1,1
1,1,1,1,2,1,1,1,1,1,1,1,1,1,1,1,2,1,1,1,1
1,1,1,1,1,1,1,1,1,1,1,1,1,1,1,1,1,1,1,1,1
1,1,1,1,1,1,1,1,1,1,1,1,1,1,1,1,1,1,1,1,1
1,1,1,1,1,1,1,1,1,1,1,1,1,1,1,1,1,1,1,1,1
1,1,1,1,1,1,1,1,1,1,1,1,1,1,1,1,1,1,1,1,1
endlayer

layer
1,1,1,1,1,1,1,1,1,1,1,1,1,1,1,1,1,1,1,1,1
1,1,1,1,1,1,1,1,1,1,1,1,1,1,1,1,1,1,1,1,1
1,1,1,1,1,1,1,1,1,1,1,1,1,1,1,1,1,1,1,1,1
1,1,1,1,1,1,1,1,1,1,1,1,1,1,1,1,1,1,1,1,1
1,1,1,1,3,1,1,1,1,1,1,1,1,1,1,1,3,1,1,1,1
1,1,1,1,1,1,1,1,1,1,1,1,1,1,1,1,1,1,1,1,1
1,1,1,1,1,1,1,1,1,1,1,1,1,1,1,1,1,1,1,1,1
1,1,1,1,1,1,1,1,1,1,1,1,1,1,1,1,1,1,1,1,1
1,1,1,1,1,1,1,1,1,1,1,1,1,1,1,1,1,1,1,1,1
1,1,1,1,1,1,1,1,1,1,1,1,1,1,1,1,1,1,1,1,1
1,1,1,1,1,1,1,1,1,1,1,1,1,1,1,1,1,1,1,1,1
1,1,1,1,1,1,1,1,1,1,1,1,1,1,1,1,1,1,1,1,1
1,1,1,1,1,1,1,1,1,1,1,1,1,1,1,1,1,1,1,1,1
1,1,1,1,1,1,1,1,1,1,1,1,1,1,1,1,1,1,1,1,1
1,1,1,1,1,1,1,1,1,1,1,1,1,1,1,1,1,1,1,1,1
1,1,1,1,1,1,1,1,1,1,1,1,1,1,1,1,1,1,1,1,1
1,1,1,1,3,1,1,1,1,1,1,1,1,1,1,1,3,1,1,1,1
1,1,1,1,1,1,1,1,1,1,1,1,1,1,1,1,1,1,1,1,1
1,1,1,1,1,1,1,1,1,1,1,1,1,1,1,1,1,1,1,1,1
1,1,1,1,1,1,1,1,1,1,1,1,1,1,1,1,1,1,1,1,1
1,1,1,1,1,1,1,1,1,1,1,1,1,1,1,1,1,1,1,1,1
endlayer

layer
1,1,1,1,1,1,1,1,1,1,1,1,1,1,1,1,1,1,1,1,1
1,1,1,1,1,1,1,1,1,1,1,1,1,1,1,1,1,1,1,1,1
1,1,1,1,1,1,1,1,1,1,1,1,1,1,1,1,1,1,1,1,1
1,1,1,1,1,1,1,1,1,1,1,1,1,1,1,1,1,1,1,1,1
1,1,1,1,4,1,1,1,1,1,1,1,1,1,1,1,4,1,1,1,1
1,1,1,1,1,1,1,1,1,1,1,1,1,1,1,1,1,1,1,1,1
1,1,1,1,1,1,1,1,1,1,1,1,1,1,1,1,1,1,1,1,1
1,1,1,1,1,1,1,1,1,1,1,1,1,1,1,1,1,1,1,1,1
1,1,1,1,1,1,1,1,1,1,1,1,1,1,1,1,1,1,1,1,1
1,1,1,1,1,1,1,1,1,4,4,4,1,1,1,1,1,1,1,1,1
1,1,1,1,1,1,1,1,1,4,5,4,1,1,1,1,1,1,1,1,1
1,1,1,1,1,1,1,1,1,4,4,4,1,1,1,1,1,1,1,1,1
1,1,1,1,1,1,1,1,1,1,1,1,1,1,1,1,1,1,1,1,1
1,1,1,1,1,1,1,1,1,1,1,1,1,1,1,1,1,1,1,1,1
1,1,1,1,1,1,1,1,1,1,1,1,1,1,1,1,1,1,1,1,1
1,1,1,1,1,1,1,1,1,1,1,1,1,1,1,1,1,1,1,1,1
1,1,1,1,4,1,1,1,1,1,1,1,1,1,1,1,4,1,1,1,1
1,1,1,1,1,1,1,1,1,1,1,1,1,1,1,1,1,1,1,1,1
1,1,1,1,1,1,1,1,1,1,1,1,1,1,1,1,1,1,1,1,1
1,1,1,1,1,1,1,1,1,1,1,1,1,1,1,1,1,1,1,1,1
1,1,1,1,1,1,1,1,1,1,1,1,1,1,1,1,1,1,1,1,1
endlayer

layer
1,1,1,1,1,1,1,1,1,1,1,1,1,1,1,1,1,1,1,1,1
1,1,1,1,1,1,1,1,1,1,1,1,1,1,1,1,1,1,1,1,1
1,1,1,1,1,1,1,1,1,1,1,1,1,1,1,1,1,1,1,1,1
1,1,1,1,1,1,1,1,1,1,1,1,1,1,1,1,1,1,1,1,1
1,1,1,1,4,1,1,1,1,1,1,1,1,1,1,1,4,1,1,1,1
1,1,1,1,1,1,1,1,1,1,1,1,1,1,1,1,1,1,1,1,1
1,1,1,1,1,1,1,1,1,1,1,1,1,1,1,1,1,1,1,1,1
1,1,1,1,1,1,1,1,1,1,1,1,1,1,1,1,1,1,1,1,1
1,1,1,1,1,1,1,1,1,4,4,4,1,1,1,1,1,1,1,1,1
1,1,1,1,1,1,1,1,4,4,4,4,4,1,1,1,1,1,1,1,1
1,1,1,1,1,1,1,1,4,4,5,4,4,1,1,1,1,1,1,1,1
1,1,1,1,1,1,1,1,4,4,4,4,4,1,1,1,1,1,1,1,1
1,1,1,1,1,1,1,1,1,4,4,4,1,1,1,1,1,1,1,1,1
1,1,1,1,1,1,1,1,1,1,1,1,1,1,1,1,1,1,1,1,1
1,1,1,1,1,1,1,1,1,1,1,1,1,1,1,1,1,1,1,1,1
1,1,1,1,1,1,1,1,1,1,1,1,1,1,1,1,1,1,1,1,1
1,1,1,1,4,1,1,1,1,1,1,1,1,1,1,1,4,1,1,1,1
1,1,1,1,1,1,1,1,1,1,1,1,1,1,1,1,1,1,1,1,1
1,1,1,1,1,1,1,1,1,1,1,1,1,1,1,1,1,1,1,1,1
1,1,1,1,1,1,1,1,1,1,1,1,1,1,1,1,1,1,1,1,1
1,1,1,1,1,1,1,1,1,1,1,1,1,1,1,1,1,1,1,1,1
endlayer

layer
1,1,1,1,1,1,1,1,1,1,1,1,1,1,1,1,1,1,1,1,1
1,1,1,1,1,1,1,1,6,6,6,6,6,1,1,1,1,1,1,1,1
1,1,1,1,1,1,6,6,1,1,1,1,1,6,6,1,1,1,1,1,1
1,1,1,1,4,6,1,1,1,1,1,1,1,1,1,6,4,1,1,1,1
1,1,1,4,4,1,1,1,1,1,1,1,1,1,1,1,4,4,1,1,1
1,1,1,6,1,1,1,1,1,1,1,1,1,1,1,1,1,6,1,1,1
1,1,6,1,1,1,1,1,1,1,1,1,1,1,1,1,1,1,6,1,1
1,1,6,1,1,1,1,1,1,4,4,4,1,1,1,1,1,1,6,1,1
1,6,1,1,1,1,1,1,4,0,0,0,4,1,1,1,1,1,1,6,1
1,6,1,1,1,1,1,4,0,0,0,0,0,4,1,1,1,1,1,6,1
1,6,1,1,1,1,1,4,0,0,0,0,0,4,1,1,1,1,1,6,1
1,6,1,1,1,1,1,4,0,7,0,0,0,4,1,1,1,1,1,6,1
1,6,1,1,1,1,1,1,4,4,0,0,4,1,1,1,1,1,1,6,1
1,1,6,1,1,1,1,1,1,4,4,4,1,1,1,1,1,1,6,1,1
1,1,6,1,1,1,1,1,1,1,1,1,1,1,1,1,1,1,6,1,1
1,1,1,6,1,1,1,1,1,1,1,1,1,1,1,1,1,6,1,1,1
1,1,1,4,4,1,1,1,1,1,1,1,1,1,1,1,4,4,1,1,1
1,1,1,1,4,6,1,1,1,1,1,1,1,1,1,6,4,1,1,1,1
1,1,1,1,1,1,6,6,1,1,1,1,1,6,6,1,1,1,1,1,1
1,1,1,1,1,1,1,1,6,6,6,6,6,1,1,1,1,1,1,1,1
1,1,1,1,1,1,1,1,1,1,1,1,1,1,1,1,1,1,1,1,1
endlayer

layer
1,1,1,1,1,1,1,1,1,1,1,1,1,1,1,1,1,1,1,1,1
1,1,1,1,1,1,1,1,3,3,3,3,3,1,1,1,1,1,1,1,1
1,1,1,1,1,1,3,3,1,1,1,1,1,3,3,1,1,1,1,1,1
1,1,1,4,4,3,1,1,1,1,1,1,1,1,1,3,4,4,1,1,1
1,1,1,4,4,1,1,1,1,1,1,1,1,1,1,1,4,4,1,1,1
1,1,1,3,1,1,1,1,1,1,1,1,1,1,1,1,1,3,1,1,1
1,1,3,1,1,1,1,1,1,1,1,1,1,1,1,1,1,1,3,1,1
1,1,3,1,1,1,1,1,1,4,5,4,1,1,1,1,1,1,3,1,1
1,3,1,1,1,1,1,1,4,0,0,0,4,1,1,1,1,1,1,3,1
1,3,1,1,1,1,1,4,0,0,0,0,0,4,1,1,1,1,1,3,1
1,3,1,1,1,1,1,5,0,0,0,0,0,5,1,1,1,1,1,3,1
1,3,1,1,1,1,1,4,0,7,0,0,0,4,1,1,1,1,1,3,1
1,3,1,1,1,1,1,1,4,4,0,0,4,1,1,1,1,1,1,3,1
1,1,3,1,1,1,1,1,1,4,5,4,1,1,1,1,1,1,3,1,1
1,1,3,1,1,1,1,1,1,1,1,1,1,1,1,1,1,1,3,1,1
1,1,1,3,1,1,1,1,1,1,1,1,1,1,1,1,1,3,1,1,1
1,1,1,4,4,1,1,1,1,1,1,1,1,1,1,1,4,4,1,1,1
1,1,1,4,4,3,1,1,1,1,1,1,1,1,1,3,4,4,1,1,1
1,1,1,1,1,1,3,3,1,1,1,1,1,3,3,1,1,1,1,1,1
1,1,1,1,1,1,1,1,3,3,3,3,3,1,1,1,1,1,1,1,1
1,1,1,1,1,1,1,1,1,1,1,1,1,1,1,1,1,1,1,1,1
endlayer

layer
1,1,1,1,1,1,1,1,8,8,8,8,8,1,1,1,1,1,1,1,1
1,1,1,1,1,1,8,8,4,4,4,4,4,8,8,1,1,1,1,1,1
1,1,1,1,8,8,4,4,0,0,0,0,0,4,4,8,8,1,1,1,1
1,1,1,4,4,4,0,0,0,0,0,0,0,0,0,4,4,4,1,1,1
1,1,10,4,4,0,0,0,0,0,0,0,0,0,0,0,4,4,9,1,1
1,1,10,4,0,0,0,0,0,0,0,0,0,0,0,0,0,4,9,1,1
1,10,4,0,0,0,0,0,0,0,0,0,0,0,0,0,0,0,4,9,1
1,10,4,0,0,0,0,0,0,4,5,4,0,0,0,0,0,0,4,9,1
10,4,0,0,0,0,0,0,4,0,0,0,4,0,0,0,0,0,0,4,9
10,4,0,0,0,0,0,4,0,0,0,0,0,4,0,0,0,0,0,4,9
10,4,0,0,0,0,0,5,0,0,0,0,0,5,0,0,0,0,0,4,9
10,4,0,0,0,0,0,4,0,7,0,0,0,4,0,0,0,0,0,4,9
10,4,0,0,0,0,0,0,4,4,0,0,4,0,0,0,0,0,0,4,9
1,10,4,0,0,0,0,0,0,4,5,4,0,0,0,0,0,0,4,9,1
1,10,4,0,0,0,0,0,0,0,0,0,0,0,0,0,0,0,4,9,1
1,1,10,4,0,0,0,0,0,0,0,0,0,0,0,0,0,4,9,1,1
1,1,10,4,4,0,0,0,0,0,0,0,0,0,0,0,4,4,9,1,1
1,1,1,4,4,4,0,0,0,0,0,0,0,0,0,4,4,4,1,1,1
1,1,1,1,11,11,4,4,0,0,0,0,0,4,4,11,11,1,1,1,1
1,1,1,1,1,1,11,11,4,4,4,4,4,11,11,1,1,1,1,1,1
1,1,1,1,1,1,1,1,11,11,11,11,11,1,1,1,1,1,1,1,1
endlayer

layer
1,1,1,1,1,1,1,1,4,4,4,4,4,1,1,1,1,1,1,1,1
1,1,1,1,1,1,4,4,4,4,4,4,4,4,4,1,1,1,1,1,1
1,1,1,1,4,4,4,4,0,11,11,11,0,4,4,4,4,1,1,1,1
1,1,1,2,4,4,0,0,0,0,0,0,0,0,0,4,4,2,1,1,1
1,1,4,4,4,0,0,0,0,0,0,0,0,0,0,0,4,4,4,1,1
1,1,4,4,0,0,0,0,0,0,0,0,0,0,0,0,0,4,4,1,1
1,4,4,0,0,0,0,0,0,0,0,0,0,0,0,0,0,0,4,4,1
1,4,4,0,0,0,0,0,0,4,4,4,0,0,0,0,0,0,4,4,1
4,4,0,0,0,0,0,0,4,0,0,0,4,0,0,0,0,0,0,4,4
4,4,9,0,0,0,0,4,0,0,0,0,0,4,0,0,0,0,10,4,4
4,4,9,0,0,0,0,4,0,0,0,0,0,4,0,0,0,0,10,4,4
4,4,9,0,0,0,0,4,0,7,0,0,0,4,0,0,0,0,10,4,4
4,4,0,0,0,0,0,0,4,4,0,0,4,0,0,0,0,0,0,4,4
1,4,4,0,0,0,0,0,0,4,4,4,0,0,0,0,0,0,4,4,1
1,4,4,0,0,0,0,0,0,0,0,0,0,0,0,0,0,0,4,4,1
1,1,4,4,0,0,0,0,0,0,0,0,0,0,0,0,0,4,4,1,1
1,1,4,4,4,0,0,0,0,0,0,0,0,0,0,0,4,4,4,1,1
1,1,1,2,4,4,0,0,0,0,0,0,0,0,0,4,4,2,1,1,1
1,1,1,1,4,4,4,4,0,8,8,8,0,4,4,4,4,1,1,1,1
1,1,1,1,1,1,4,4,4,4,4,4,4,4,4,1,1,1,1,1,1
1,1,1,1,1,1,1,1,4,4,4,4,4,1,1,1,1,1,1,1,1
endlayer

layer
1,1,1,1,1,1,1,1,12,0,0,0,12,1,1,1,1,1,1,1,1
1,1,1,1,1,1,0,0,4,0,0,0,4,0,0,1,1,1,1,1,1
1,1,1,1,12,0,5,5,0,0,0,0,0,5,5,0,12,1,1,1,1
1,1,1,4,4,5,0,0,0,13,13,13,0,0,0,5,4,4,1,1,1
1,1,15,4,4,0,0,0,0,13,13,13,0,0,0,0,4,4,14,1,1
1,1,0,5,0,0,0,0,0,6,6,6,0,0,0,0,0,5,0,1,1
1,0,5,0,0,0,0,0,0,8,8,8,0,0,0,0,0,0,5,0,1
1,0,5,0,0,0,0,0,8,4,4,4,8,0,0,0,0,0,5,0,1
15,4,0,0,0,0,0,10,4,4,4,4,4,9,0,0,0,0,0,4,14
0,0,0,13,13,6,10,4,4,4,4,4,4,4,9,6,13,13,0,0,0
0,0,0,13,13,6,10,4,4,4,5,4,4,4,9,6,13,13,0,0,0
0,0,0,13,13,6,10,4,4,7,4,4,4,4,9,6,13,13,0,0,0
15,4,0,0,0,0,0,10,4,4,4,4,4,9,0,0,0,0,0,4,14
1,0,5,0,0,0,0,0,11,4,4,4,11,0,0,0,0,0,5,0,1
1,0,5,0,0,0,0,0,0,11,11,11,0,0,0,0,0,0,5,0,1
1,1,0,5,0,0,0,0,0,6,6,6,0,0,0,0,0,5,0,1,1
1,1,15,4,4,0,0,0,0,13,13,13,0,0,0,0,4,4,14,1,1
1,1,1,4,4,5,0,0,0,13,13,13,0,0,0,5,4,4,1,1,1
1,1,1,1,16,0,5,5,0,0,0,0,0,5,5,0,16,1,1,1,1
1,1,1,1,1,1,0,0,4,0,0,0,4,0,0,1,1,1,1,1,1
1,1,1,1,1,1,1,1,16,0,0,0,16,1,1,1,1,1,1,1,1
endlayer

layer
1,1,1,1,1,1,1,1,0,0,0,0,0,1,1,1,1,1,1,1,1
1,1,1,1,1,1,0,0,4,0,0,0,4,0,0,1,1,1,1,1,1
1,1,1,1,0,0,5,5,0,0,0,0,0,5,5,0,0,1,1,1,1
1,1,1,4,4,5,0,0,0,0,0,0,0,0,0,5,4,4,1,1,1
1,1,0,4,4,0,0,0,0,0,0,0,0,0,0,0,4,4,0,1,1
1,1,0,5,0,0,0,0,0,0,0,0,0,0,0,0,0,5,0,1,1
1,0,5,0,0,0,0,0,0,17,0,17,0,0,0,0,0,0,5,0,1
1,0,5,0,0,0,0,0,12,0,0,0,12,0,0,0,0,0,5,0,1
0,4,0,0,0,0,0,15,4,0,0,0,4,14,0,0,0,0,0,4,0
0,0,0,0,0,0,17,0,0,0,0,0,0,0,17,0,0,0,0,0,0
0,0,0,0,0,0,0,0,0,0,0,0,0,0,0,0,0,0,0,0,0
0,0,0,0,0,0,17,0,0,0,0,0,0,0,17,0,0,0,0,0,0
0,4,0,0,0,0,0,15,4,18,0,0,4,14,0,0,0,0,0,4,0
1,0,5,0,0,0,0,0,16,0,0,0,16,0,0,0,0,0,5,0,1
1,0,5,0,0,0,0,0,0,17,0,17,0,0,0,0,0,0,5,0,1
1,1,0,5,0,0,0,0,0,0,0,0,0,0,0,0,0,5,0,1,1
1,1,0,4,4,0,0,0,0,0,0,0,0,0,0,0,4,4,0,1,1
1,1,1,4,4,5,0,0,0,0,0,0,0,0,0,5,4,4,1,1,1
1,1,1,1,0,0,5,5,0,0,0,0,0,5,5,0,0,1,1,1,1
1,1,1,1,1,1,0,0,4,0,0,0,4,0,0,1,1,1,1,1,1
1,1,1,1,1,1,1,1,0,0,0,0,0,1,1,1,1,1,1,1,1
endlayer

layer
1,1,1,1,1,1,1,1,0,0,0,0,0,1,1,1,1,1,1,1,1
1,1,1,1,1,1,0,0,4,0,0,0,4,0,0,1,1,1,1,1,1
1,1,1,1,0,0,5,5,0,0,0,0,0,5,5,0,0,1,1,1,1
1,1,1,4,4,5,0,0,0,0,0,0,0,0,0,5,4,4,1,1,1
1,1,0,4,4,0,0,0,0,0,0,0,0,0,0,0,4,4,0,1,1
1,1,0,5,0,0,0,0,0,0,0,0,0,0,0,0,0,5,0,1,1
1,0,5,0,0,0,0,0,0,17,0,17,0,0,0,0,0,0,5,0,1
1,0,5,0,0,0,0,0,0,0,0,0,0,0,0,0,0,0,5,0,1
0,4,0,0,0,0,0,0,4,0,0,0,4,0,0,0,0,0,0,4,0
0,0,0,0,0,0,17,0,0,0,0,0,0,0,17,0,0,0,0,0,0
0,0,0,0,0,0,0,0,0,0,0,0,0,0,0,0,0,0,0,0,0
0,0,0,0,0,0,17,0,0,0,0,0,0,0,17,0,0,0,0,0,0
0,4,0,0,0,0,0,0,4,18,0,0,4,0,0,0,0,0,0,4,0
1,0,5,0,0,0,0,0,0,0,0,0,0,0,0,0,0,0,5,0,1
1,0,5,0,0,0,0,0,0,17,0,17,0,0,0,0,0,0,5,0,1
1,1,0,5,0,0,0,0,0,0,0,0,0,0,0,0,0,5,0,1,1
1,1,0,4,4,0,0,0,0,0,0,0,0,0,0,0,4,4,0,1,1
1,1,1,4,4,5,0,0,0,0,0,0,0,0,0,5,4,4,1,1,1
1,1,1,1,0,0,5,5,0,0,0,0,0,5,5,0,0,1,1,1,1
1,1,1,1,1,1,0,0,4,0,0,0,4,0,0,1,1,1,1,1,1
1,1,1,1,1,1,1,1,0,0,0,0,0,1,1,1,1,1,1,1,1
endlayer

layer
1,1,1,1,1,1,1,1,0,0,0,0,0,1,1,1,1,1,1,1,1
1,1,1,1,1,1,0,0,4,0,0,0,4,0,0,1,1,1,1,1,1
1,1,1,1,0,0,5,5,0,0,0,0,0,5,5,0,0,1,1,1,1
1,1,1,4,4,5,0,0,0,0,0,0,0,0,0,5,4,4,1,1,1
1,1,0,4,4,0,0,0,0,0,0,0,0,0,0,0,4,4,0,1,1
1,1,0,5,0,0,0,0,0,0,0,0,0,0,0,0,0,5,0,1,1
1,0,5,0,0,0,0,0,0,17,0,17,0,0,0,0,0,0,5,0,1
1,0,5,0,0,0,0,0,0,0,0,0,0,0,0,0,0,0,5,0,1
0,4,0,0,0,0,0,0,4,0,0,0,4,0,0,0,0,0,0,4,0
0,0,0,0,0,0,17,0,0,0,19,0,0,0,17,0,0,0,0,0,0
0,0,0,0,0,0,0,0,0,0,0,0,0,0,0,0,0,0,0,0,0
0,0,0,0,0,0,17,0,0,0,19,0,0,0,17,0,0,0,0,0,0
0,4,0,0,0,0,0,0,4,18,0,0,4,0,0,0,0,0,0,4,0
1,0,5,0,0,0,0,0,0,0,0,0,0,0,0,0,0,0,5,0,1
1,0,5,0,0,0,0,0,0,17,0,17,0,0,0,0,0,0,5,0,1
1,1,0,5,0,0,0,0,0,0,0,0,0,0,0,0,0,5,0,1,1
1,1,0,4,4,0,0,0,0,0,0,0,0,0,0,0,4,4,0,1,1
1,1,1,4,4,5,0,0,0,0,0,0,0,0,0,5,4,4,1,1,1
1,1,1,1,0,0,5,5,0,0,0,0,0,5,5,0,0,1,1,1,1
1,1,1,1,1,1,0,0,4,0,0,0,4,0,0,1,1,1,1,1,1
1,1,1,1,1,1,1,1,0,0,0,0,0,1,1,1,1,1,1,1,1
endlayer

layer
1,1,1,1,1,1,1,1,8,0,0,0,8,1,1,1,1,1,1,1,1
1,1,1,1,1,1,0,0,4,0,0,0,4,0,0,1,1,1,1,1,1
1,1,1,1,8,0,5,5,0,0,0,0,0,5,5,0,8,1,1,1,1
1,1,1,4,4,5,0,0,0,0,0,0,0,0,0,5,4,4,1,1,1
1,1,10,4,4,0,0,0,0,0,0,0,0,0,0,0,4,4,9,1,1
1,1,0,5,0,0,0,0,0,0,0,0,0,0,0,0,0,5,0,1,1
1,0,5,0,0,0,0,0,0,3,0,3,0,0,0,0,0,0,5,0,1
1,0,5,0,0,0,0,0,8,0,0,0,8,0,0,0,0,0,5,0,1
10,4,0,0,0,0,0,10,4,0,0,0,4,9,0,0,0,0,0,4,9
0,0,0,0,0,0,3,0,0,0,0,0,0,0,3,0,0,0,0,0,0
0,0,0,0,0,0,0,0,0,0,0,0,0,0,0,0,0,0,0,0,0
0,0,0,0,0,0,3,0,0,0,0,0,0,0,3,0,0,0,0,0,0
10,4,0,0,0,0,0,10,4,18,0,0,4,9,0,0,0,0,0,4,9
1,0,5,0,0,0,0,0,11,0,0,0,11,0,0,0,0,0,5,0,1
1,0,5,0,0,0,0,0,0,17,0,17,0,0,0,0,0,0,5,0,1
1,1,0,5,0,0,0,0,0,0,0,0,0,0,0,0,0,5,0,1,1
1,1,10,4,4,0,0,0,0,0,0,0,0,0,0,0,4,4,9,1,1
1,1,1,4,4,5,0,0,0,0,0,0,0,0,0,5,4,4,1,1,1
1,1,1,1,11,0,5,5,0,0,0,0,0,5,5,0,11,1,1,1,1
1,1,1,1,1,1,0,0,4,0,0,0,4,0,0,1,1,1,1,1,1
1,1,1,1,1,1,1,1,11,0,0,0,11,1,1,1,1,1,1,1,1
endlayer

layer
1,1,1,1,1,1,1,1,4,6,0,6,4,1,1,1,1,1,1,1,1
1,1,1,1,1,1,4,4,4,6,0,6,4,4,4,1,1,1,1,1,1
1,1,1,1,4,4,4,4,0,0,0,0,0,4,4,4,4,1,1,1,1
1,1,1,2,4,4,0,0,0,0,0,0,0,0,0,4,4,2,1,1,1
1,1,4,4,4,0,0,0,0,0,0,0,0,0,0,0,4,4,4,1,1
1,1,4,4,0,0,0,0,0,0,0,0,0,0,0,0,0,4,4,1,1
1,4,4,0,0,0,0,0,0,12,12,12,0,0,0,0,0,0,4,4,1
1,4,4,0,0,0,0,0,12,4,4,4,12,0,0,0,0,0,4,4,1
4,4,0,0,0,0,0,15,4,4,4,4,4,14,0,0,0,0,0,4,4
6,6,0,0,0,0,15,4,4,4,4,4,4,4,14,0,0,0,0,6,6
0,0,0,0,0,0,15,4,4,4,5,4,4,4,14,0,0,0,0,0,0
6,6,0,0,0,0,15,4,4,4,4,4,4,4,14,0,0,0,0,6,6
4,4,0,0,0,0,0,15,4,18,4,4,4,14,0,0,0,0,0,4,4
1,4,4,0,0,0,0,0,16,4,4,4,16,0,0,0,0,0,4,4,1
1,4,4,0,0,0,0,0,0,16,16,16,0,0,0,0,0,0,4,4,1
1,1,4,4,0,0,0,0,0,0,0,0,0,0,0,0,0,4,4,1,1
1,1,4,4,4,0,0,0,0,0,0,0,0,0,0,0,4,4,4,1,1
1,1,1,2,4,4,0,0,0,0,0,0,0,0,0,4,4,2,1,1,1
1,1,1,1,4,4,4,4,0,0,0,0,0,4,4,4,4,1,1,1,1
1,1,1,1,1,1,4,4,4,6,0,6,4,4,4,1,1,1,1,1,1
1,1,1,1,1,1,1,1,4,6,0,6,4,1,1,1,1,1,1,1,1
endlayer

layer
1,1,1,1,1,1,1,1,12,12,12,12,12,1,1,1,1,1,1,1,1
1,1,1,1,1,1,12,12,4,4,4,4,4,12,12,1,1,1,1,1,1
1,1,1,1,12,12,4,4,0,0,0,0,0,4,4,12,12,1,1,1,1
1,1,1,4,4,4,0,0,0,0,0,0,0,0,0,4,4,4,1,1,1
1,1,15,4,4,0,0,0,0,0,0,0,0,0,0,0,4,4,14,1,1
1,1,15,4,0,0,0,0,0,0,0,0,0,0,0,0,0,4,14,1,1
1,15,4,0,0,0,0,0,0,0,0,0,0,0,0,0,0,0,4,14,1
1,15,4,0,0,0,0,0,0,4,4,4,0,0,0,0,0,0,4,14,1
15,4,0,0,0,0,0,0,4,0,0,0,4,0,0,0,0,0,0,4,14
15,4,0,0,0,0,0,4,0,0,0,0,0,4,0,0,0,0,0,4,14
15,4,0,0,0,0,0,4,0,0,0,0,0,4,0,0,0,0,0,4,14
15,4,0,0,0,0,0,4,0,0,0,0,0,4,0,0,0,0,0,4,14
15,4,0,0,0,0,0,0,4,18,0,0,4,0,0,0,0,0,0,4,14
1,15,4,0,0,0,0,0,0,4,4,4,0,0,0,0,0,0,4,14,1
1,15,4,0,0,0,0,0,0,0,0,0,0,0,0,0,0,0,4,14,1
1,1,15,4,0,0,0,0,0,0,0,0,0,0,0,0,0,4,14,1,1
1,1,15,4,4,0,0,0,0,0,0,0,0,0,0,0,4,4,14,1,1
1,1,1,4,4,4,0,0,0,0,0,0,0,0,0,4,4,4,1,1,1
1,1,1,1,16,16,4,4,0,0,0,0,0,4,4,16,16,1,1,1,1
1,1,1,1,1,1,16,16,4,4,4,4,4,16,16,1,1,1,1,1,1
1,1,1,1,1,1,1,1,16,16,16,16,16,1,1,1,1,1,1,1,1
endlayer

layer
1,1,1,1,1,1,1,1,1,1,1,1,1,1,1,1,1,1,1,1,1
1,1,1,1,1,1,1,1,17,17,17,17,17,0,0,1,1,1,1,1,1
1,1,1,1,1,1,17,17,0,0,0,0,0,17,17,1,1,1,1,1,1
1,1,1,4,4,17,0,0,0,0,0,0,0,0,0,17,4,4,1,1,1
1,1,1,4,4,0,0,0,0,0,0,0,0,0,0,0,4,4,1,1,1
1,1,1,17,0,0,0,0,0,0,0,0,0,0,0,0,0,17,1,1,1
1,0,17,0,0,0,0,0,0,0,0,0,0,0,0,0,0,0,17,1,1
1,0,17,0,0,0,0,0,0,4,5,4,0,0,0,0,0,0,17,1,1
1,17,0,0,0,0,0,0,4,0,0,0,4,0,0,0,0,0,0,17,1
1,17,0,0,0,0,0,4,0,0,0,0,0,4,0,0,0,0,0,17,1
1,17,0,0,0,0,0,5,0,0,0,0,0,5,0,0,0,0,0,17,1
1,17,0,0,0,0,0,4,0,0,0,0,0,4,0,0,0,0,0,17,1
1,17,0,0,0,0,0,0,4,18,0,0,4,0,0,0,0,0,0,17,1
1,1,17,0,0,0,0,0,0,4,5,4,0,0,0,0,0,0,17,0,1
1,1,17,0,0,0,0,0,0,0,0,0,0,0,0,0,0,0,17,0,1
1,1,1,17,0,0,0,0,0,0,0,0,0,0,0,0,0,17,1,1,1
1,1,1,4,4,0,0,0,0,0,0,0,0,0,0,0,4,4,1,1,1
1,1,1,4,4,17,0,0,0,0,0,0,0,0,0,17,4,4,1,1,1
1,1,1,1,1,1,17,17,0,0,0,0,0,17,17,1,1,1,1,1,1
1,1,1,1,1,1,1,1,17,17,17,17,17,1,1,1,1,1,1,1,1
1,1,1,1,1,1,1,1,1,1,1,1,1,1,1,1,1,1,1,1,1
endlayer

layer
1,1,1,1,1,1,1,1,1,1,1,1,1,1,1,1,1,1,1,1,1
1,1,1,1,1,1,1,1,13,13,13,13,13,0,0,1,1,1,1,1,1
1,1,1,1,1,1,13,13,0,0,0,0,0,13,13,1,1,1,1,1,1
1,1,1,1,4,13,0,0,0,0,0,0,0,0,0,13,4,1,1,1,1
1,1,1,4,4,0,0,0,0,0,0,0,0,0,0,0,4,4,1,1,1
1,1,1,13,0,0,0,0,0,0,0,0,0,0,0,0,0,13,1,1,1
1,0,13,0,0,0,0,0,0,0,0,0,0,0,0,0,0,0,13,1,1
1,0,13,0,0,0,0,0,0,4,5,4,0,0,0,0,0,0,13,1,1
1,13,0,0,0,0,0,0,4,0,0,0,4,0,0,0,0,0,0,13,1
1,13,0,0,0,0,0,4,0,0,0,0,0,4,0,0,0,0,0,13,1
1,13,0,0,0,0,0,5,0,0,0,0,0,5,0,0,0,0,0,13,1
1,13,0,0,0,0,0,4,0,0,0,0,0,4,0,0,0,0,0,13,1
1,13,0,0,0,0,0,0,4,18,0,0,4,0,0,0,0,0,0,13,1
1,1,13,0,0,0,0,0,0,4,5,4,0,0,0,0,0,0,13,0,1
1,1,13,0,0,0,0,0,0,0,0,0,0,0,0,0,0,0,13,0,1
1,1,1,13,0,0,0,0,0,0,0,0,0,0,0,0,0,13,1,1,1
1,1,1,4,4,0,0,0,0,0,0,0,0,0,0,0,4,4,1,1,1
1,1,1,1,4,13,0,0,0,0,0,0,0,0,0,13,4,1,1,1,1
1,1,1,1,1,1,13,13,0,0,0,0,0,13,13,1,1,1,1,1,1
1,1,1,1,1,1,1,1,13,13,13,13,13,1,1,1,1,1,1,1,1
1,1,1,1,1,1,1,1,1,1,1,1,1,1,1,1,1,1,1,1,1
endlayer

layer
1,1,1,1,1,1,1,1,1,1,1,1,1,1,1,1,1,1,1,1,1
1,1,1,1,1,1,1,1,1,1,1,1,1,1,1,1,1,1,1,1,1
1,1,1,1,1,1,1,1,1,1,1,1,1,1,1,1,1,1,1,1,1
1,1,1,1,1,1,1,1,1,1,1,1,1,1,1,1,1,1,1,1,1
1,1,1,1,4,1,1,1,1,1,1,1,1,1,1,1,4,1,1,1,1
1,1,1,1,1,1,1,1,1,1,1,1,1,1,1,1,1,1,1,1,1
1,1,1,1,1,1,1,1,1,1,1,1,1,1,1,1,1,1,1,1,1
1,1,1,1,1,1,1,1,1,4,4,4,1,1,1,1,1,1,1,1,1
1,1,1,1,1,1,1,1,4,0,0,0,4,1,1,1,1,1,1,1,1
1,1,1,1,1,1,1,4,0,0,0,0,0,4,1,1,1,1,1,1,1
1,1,1,1,1,1,1,4,0,0,0,0,0,4,1,1,1,1,1,1,1
1,1,1,1,1,1,1,4,0,0,0,0,0,4,1,1,1,1,1,1,1
1,1,1,1,1,1,1,1,4,18,0,0,4,1,1,1,1,1,1,1,1
1,1,1,1,1,1,1,1,1,4,4,4,1,1,1,1,1,1,1,1,1
1,1,1,1,1,1,1,1,1,1,1,1,1,1,1,1,1,1,1,1,1
1,1,1,1,1,1,1,1,1,1,1,1,1,1,1,1,1,1,1,1,1
1,1,1,1,4,1,1,1,1,1,1,1,1,1,1,1,4,1,1,1,1
1,1,1,1,1,1,1,1,1,1,1,1,1,1,1,1,1,1,1,1,1
1,1,1,1,1,1,1,1,1,1,1,1,1,1,1,1,1,1,1,1,1
1,1,1,1,1,1,1,1,1,1,1,1,1,1,1,1,1,1,1,1,1
1,1,1,1,1,1,1,1,1,1,1,1,1,1,1,1,1,1,1,1,1
endlayer

layer
1,1,1,1,1,1,1,1,1,1,1,1,1,1,1,1,1,1,1,1,1
1,1,1,1,1,1,1,1,1,1,1,1,1,1,1,1,1,1,1,1,1
1,1,1,1,1,1,1,1,1,1,1,1,1,1,1,1,1,1,1,1,1
1,1,1,1,1,1,1,1,1,1,1,1,1,1,1,1,1,1,1,1,1
1,1,1,1,4,1,1,1,1,1,1,1,1,1,1,1,4,1,1,1,1
1,1,1,1,1,1,1,1,1,1,1,1,1,1,1,1,1,1,1,1,1
1,1,1,1,1,1,1,1,1,1,1,1,1,1,1,1,1,1,1,1,1
1,1,1,1,1,1,1,1,1,1,1,1,1,1,1,1,1,1,1,1,1
1,1,1,1,1,1,1,1,1,4,4,4,1,1,1,1,1,1,1,1,1
1,1,1,1,1,1,1,1,4,4,4,4,4,1,1,1,1,1,1,1,1
1,1,1,1,1,1,1,1,4,4,5,4,4,1,1,1,1,1,1,1,1
1,1,1,1,1,1,1,1,4,4,4,4,4,1,1,1,1,1,1,1,1
1,1,1,1,1,1,1,1,1,4,4,4,1,1,1,1,1,1,1,1,1
1,1,1,1,1,1,1,1,1,1,1,1,1,1,1,1,1,1,1,1,1
1,1,1,1,1,1,1,1,1,1,1,1,1,1,1,1,1,1,1,1,1
1,1,1,1,1,1,1,1,1,1,1,1,1,1,1,1,1,1,1,1,1
1,1,1,1,4,1,1,1,1,1,1,1,1,1,1,1,4,1,1,1,1
1,1,1,1,1,1,1,1,1,1,1,1,1,1,1,1,1,1,1,1,1
1,1,1,1,1,1,1,1,1,1,1,1,1,1,1,1,1,1,1,1,1
1,1,1,1,1,1,1,1,1,1,1,1,1,1,1,1,1,1,1,1,1
1,1,1,1,1,1,1,1,1,1,1,1,1,1,1,1,1,1,1,1,1
endlayer

layer
1,1,1,1,1,1,1,1,1,1,1,1,1,1,1,1,1,1,1,1,1
1,1,1,1,1,1,1,1,1,1,1,1,1,1,1,1,1,1,1,1,1
1,1,1,1,1,1,1,1,1,1,1,1,1,1,1,1,1,1,1,1,1
1,1,1,1,1,1,1,1,1,1,1,1,1,1,1,1,1,1,1,1,1
1,1,1,1,17,1,1,1,1,1,1,1,1,1,1,1,17,1,1,1,1
1,1,1,1,1,1,1,1,1,1,1,1,1,1,1,1,1,1,1,1,1
1,1,1,1,1,1,1,1,1,1,1,1,1,1,1,1,1,1,1,1,1
1,1,1,1,1,1,1,1,1,1,1,1,1,1,1,1,1,1,1,1,1
1,1,1,1,1,1,1,1,1,1,1,1,1,1,1,1,1,1,1,1,1
1,1,1,1,1,1,1,1,1,4,4,4,1,1,1,1,1,1,1,1,1
1,1,1,1,1,1,1,1,1,4,5,4,1,1,1,1,1,1,1,1,1
1,1,1,1,1,1,1,1,1,4,4,4,1,1,1,1,1,1,1,1,1
1,1,1,1,1,1,1,1,1,1,1,1,1,1,1,1,1,1,1,1,1
1,1,1,1,1,1,1,1,1,1,1,1,1,1,1,1,1,1,1,1,1
1,1,1,1,1,1,1,1,1,1,1,1,1,1,1,1,1,1,1,1,1
1,1,1,1,1,1,1,1,1,1,1,1,1,1,1,1,1,1,1,1,1
1,1,1,1,17,1,1,1,1,1,1,1,1,1,1,1,17,1,1,1,1
1,1,1,1,1,1,1,1,1,1,1,1,1,1,1,1,1,1,1,1,1
1,1,1,1,1,1,1,1,1,1,1,1,1,1,1,1,1,1,1,1,1
1,1,1,1,1,1,1,1,1,1,1,1,1,1,1,1,1,1,1,1,1
1,1,1,1,1,1,1,1,1,1,1,1,1,1,1,1,1,1,1,1,1
endlayer

layer
1,1,1,1,1,1,1,1,1,1,1,1,1,1,1,1,1,1,1,1,1
1,1,1,1,1,1,1,1,1,1,1,1,1,1,1,1,1,1,1,1,1
1,1,1,1,1,1,1,1,1,1,1,1,1,1,1,1,1,1,1,1,1
1,1,1,1,1,1,1,1,1,1,1,1,1,1,1,1,1,1,1,1,1
1,1,1,1,2,1,1,1,1,1,1,1,1,1,1,1,2,1,1,1,1
1,1,1,1,1,1,1,1,1,1,1,1,1,1,1,1,1,1,1,1,1
1,1,1,1,1,1,1,1,1,1,1,1,1,1,1,1,1,1,1,1,1
1,1,1,1,1,1,1,1,1,1,1,1,1,1,1,1,1,1,1,1,1
1,1,1,1,1,1,1,1,1,1,1,1,1,1,1,1,1,1,1,1,1
1,1,1,1,1,1,1,1,1,1,1,1,1,1,1,1,1,1,1,1,1
1,1,1,1,1,1,1,1,1,1,1,1,1,1,1,1,1,1,1,1,1
1,1,1,1,1,1,1,1,1,1,1,1,1,1,1,1,1,1,1,1,1
1,1,1,1,1,1,1,1,1,1,1,1,1,1,1,1,1,1,1,1,1
1,1,1,1,1,1,1,1,1,1,1,1,1,1,1,1,1,1,1,1,1
1,1,1,1,1,1,1,1,1,1,1,1,1,1,1,1,1,1,1,1,1
1,1,1,1,1,1,1,1,1,1,1,1,1,1,1,1,1,1,1,1,1
1,1,1,1,2,1,1,1,1,1,1,1,1,1,1,1,2,1,1,1,1
1,1,1,1,1,1,1,1,1,1,1,1,1,1,1,1,1,1,1,1,1
1,1,1,1,1,1,1,1,1,1,1,1,1,1,1,1,1,1,1,1,1
1,1,1,1,1,1,1,1,1,1,1,1,1,1,1,1,1,1,1,1,1
1,1,1,1,1,1,1,1,1,1,1,1,1,1,1,1,1,1,1,1,1
endlayer

