
# Created by Ruins mod version 17.1 Ingame Parser
# authoring Player: ST753M

weight=1
embed_into_distance=5
random_height_offset=-2,2
acceptable_target_blocks=grass,firt,podzol,mycelium,stone,biomesoplenty:grass,biomesoplenty:dirt,sand,snow,snow_layer,packed_ice,gravel
unacceptable_target_blocks=flowing_water,water,flowing_lava,lava
dimensions=9,17,17
allowable_overhang=4
max_leveling=0
leveling_buffer=0
preserve_water=0
preserve_lava=0

biomesToSpawnIn=ice_flats,ice_mountains,glacier,mutated_ice_flats,frozen_ocean,frozen_river,cold_beach,cold_desert,glacier_spikes,cold_plateau,frozen_lake,snowy_forest,mutated_taiga_cold,snowy_coniferous_forest,taiga_cold,taiga_cold_hills,ice_plains_defiled

=0,100,air
rule1=0,100,preserveBlock
rule2=0,100,minecraft:snow-0
rule3=0,100,minecraft:snow-0,preserveBlock
rule4=0,100,ChestGenHook:chests/igloo_chest:3-2
rule5=0,40,MobSpawner:stray

layer
1,1,1,1,1,1,2,2,2,2,2,1,1,1,1,1,1
1,1,1,1,2,2,2,2,2,2,2,2,2,1,1,1,1
1,1,1,2,2,2,2,2,2,2,2,2,2,2,1,1,1
1,1,2,2,2,2,2,2,2,2,2,2,2,2,2,1,1
1,2,2,2,2,2,2,2,2,2,2,2,2,2,2,2,1
2,2,2,2,2,2,2,2,2,2,2,2,2,2,2,2,1
2,2,2,2,2,2,2,2,2,2,2,2,2,2,2,2,2
2,2,2,2,2,2,2,2,2,2,2,2,2,2,2,2,2
2,2,2,2,2,2,2,2,2,2,2,2,2,2,2,2,2
2,2,2,2,2,2,2,2,2,2,2,2,2,2,2,2,2
2,2,2,2,2,2,2,2,2,2,2,2,2,2,2,2,2
1,2,2,2,2,2,2,2,2,2,2,2,2,2,2,2,3
1,2,2,2,2,2,2,2,2,2,2,2,2,2,2,2,1
1,1,2,2,2,2,2,2,2,2,2,2,2,2,2,3,1
1,1,1,2,2,2,2,2,2,2,2,2,2,2,1,1,1
1,1,1,1,2,2,2,2,2,2,2,2,2,1,1,1,1
1,1,1,1,1,1,2,2,2,2,2,1,1,1,1,1,1
endlayer

layer
1,1,1,1,1,1,2,2,2,2,2,1,1,1,1,1,1
1,1,1,1,2,2,2,2,2,2,2,2,2,1,1,1,1
1,1,2,2,2,2,2,2,2,2,2,2,2,2,1,1,1
1,2,2,2,2,2,2,2,2,2,3,0,2,2,2,1,1
2,2,2,2,2,2,2,2,3,0,0,0,3,2,2,2,1
2,2,2,2,2,2,2,0,0,0,0,0,0,0,2,2,1
2,2,2,2,2,2,2,3,0,0,0,0,0,2,3,2,2
2,2,2,2,2,2,3,0,0,0,0,3,2,3,3,2,2
2,2,2,2,2,2,2,3,0,3,2,2,3,0,0,2,2
2,2,2,2,2,2,3,0,0,2,2,2,0,0,3,2,2
2,2,2,2,2,3,2,0,0,2,2,4,0,0,3,2,2
1,2,2,2,2,3,0,0,0,0,3,3,0,3,2,2,3
1,2,2,2,2,2,3,0,2,0,0,0,0,3,2,2,1
1,1,2,2,2,2,2,3,0,0,3,0,0,2,2,3,1
1,1,1,2,2,2,2,2,2,0,3,2,2,2,1,1,1
1,1,1,1,2,2,2,2,2,2,2,2,2,1,1,1,1
1,1,1,1,1,1,2,2,2,2,2,1,1,1,1,1,1
endlayer

layer
1,1,1,1,1,1,3,2,2,2,3,1,1,1,1,1,1
1,1,1,1,2,2,2,2,2,2,2,2,2,1,1,1,1
1,1,2,2,2,2,2,0,0,0,0,0,2,2,1,1,1
1,2,2,2,2,2,0,0,2,0,0,0,0,0,2,1,1
2,2,2,2,2,2,0,0,0,0,0,0,0,0,2,2,1
2,2,2,2,2,2,0,0,0,0,0,0,0,0,0,2,1
2,2,2,2,0,3,0,0,0,0,0,0,0,2,0,2,3
2,2,2,2,2,0,0,0,0,0,0,0,0,0,0,2,2
2,2,2,2,0,2,2,0,0,0,0,0,0,0,0,2,2
2,2,3,0,0,0,0,0,0,0,2,2,0,0,0,2,2
3,2,3,0,0,0,0,0,0,0,2,0,0,0,0,2,3
1,2,2,3,0,0,0,0,0,0,0,0,0,0,3,2,1
1,2,2,3,0,0,0,0,2,0,0,0,0,0,2,2,1
1,1,2,2,3,0,0,0,0,0,0,0,0,0,2,3,1
1,1,1,2,2,0,3,0,0,0,0,0,2,2,1,1,1
1,1,1,1,2,2,2,2,2,2,2,2,2,1,1,1,1
1,1,1,1,1,1,3,2,2,2,3,1,1,1,1,1,1
endlayer

layer
1,1,1,1,1,1,1,3,3,3,1,1,1,1,1,1,1
1,1,1,1,3,2,2,2,2,2,2,2,3,1,1,1,1
1,1,3,2,2,2,0,0,0,0,0,0,2,2,1,1,1
1,2,2,2,2,0,0,0,2,0,0,0,0,0,2,1,1
3,2,2,2,2,0,0,0,0,0,0,0,0,0,2,3,1
2,2,2,2,3,0,0,0,0,0,0,0,0,0,3,2,1
2,2,2,2,0,0,0,0,0,0,0,0,0,2,0,2,1
2,2,2,0,0,0,0,0,0,0,0,0,0,0,0,2,3
2,2,3,0,0,2,0,0,0,0,0,0,0,0,0,2,3
3,2,0,0,0,0,0,0,0,0,2,0,0,0,0,2,3
1,2,0,0,0,0,0,0,0,0,3,0,0,0,0,2,1
1,2,3,0,0,0,0,0,0,0,0,0,0,0,0,2,1
1,3,2,0,0,0,0,0,0,0,0,0,0,0,2,3,1
1,1,2,0,0,0,0,0,0,0,0,0,0,0,2,1,1
1,1,1,2,2,0,3,0,0,0,0,0,2,2,1,1,1
1,1,1,1,3,2,2,2,2,2,2,2,3,1,1,1,1
1,1,1,1,1,1,1,3,3,3,1,1,1,1,1,1,1
endlayer

layer
1,1,1,1,1,1,1,1,1,1,1,1,1,1,1,1,1
1,1,1,1,1,3,2,2,2,2,2,3,1,1,1,1,1
1,1,1,3,2,2,2,3,0,0,0,2,2,3,1,1,1
1,3,2,2,2,0,0,0,2,0,2,0,0,2,3,1,1
1,2,2,2,0,0,0,0,0,0,0,0,0,3,2,1,1
3,2,2,0,0,0,0,0,0,0,0,0,0,0,2,3,1
2,2,0,0,0,0,0,0,0,0,0,0,0,2,3,2,1
2,2,0,0,0,0,0,0,0,0,0,0,0,0,3,2,1
3,2,0,0,0,3,0,0,0,0,2,0,0,0,0,2,1
1,2,0,0,0,0,0,0,0,0,2,3,0,0,0,2,1
1,2,0,0,0,0,0,0,0,0,0,0,0,0,3,2,1
1,3,2,0,0,0,0,0,0,0,0,0,0,0,2,3,1
1,1,2,3,0,0,0,0,2,0,0,0,0,0,2,1,1
1,1,3,2,0,0,0,0,0,0,0,0,0,2,3,1,1
1,1,1,3,2,2,3,0,0,0,0,2,2,3,1,1,1
1,1,1,1,1,3,2,2,2,2,2,3,1,1,1,1,1
1,1,1,1,1,1,1,1,1,1,1,1,1,1,1,1,1
endlayer

layer
1,1,1,1,1,1,1,1,1,1,1,1,1,1,1,1,1
1,1,1,1,1,1,3,3,3,3,3,1,1,1,1,1,1
1,1,1,1,3,2,2,2,2,2,2,2,3,1,1,1,1
1,1,1,1,2,2,0,3,2,0,2,0,2,3,1,1,1
1,1,1,0,0,3,0,0,2,0,0,0,3,2,3,1,1
1,1,0,0,0,0,0,0,0,0,0,0,0,0,2,1,1
1,1,0,0,0,0,0,0,0,0,0,0,0,2,5,2,1
1,3,0,0,0,0,0,0,0,0,0,0,0,0,2,3,1
1,3,2,0,0,2,0,0,0,0,2,0,0,0,2,3,1
1,3,2,0,0,0,0,0,0,3,2,2,0,3,2,3,1
1,3,2,0,0,0,0,0,0,0,3,0,0,0,2,3,1
1,1,2,3,0,3,0,0,0,0,0,0,0,3,2,1,1
1,1,3,2,3,0,0,0,2,0,0,0,0,2,3,1,1
1,1,1,3,2,0,0,0,0,0,3,0,2,3,1,1,1
1,1,1,1,3,2,2,2,2,2,2,2,3,1,1,1,1
1,1,1,1,1,1,3,3,3,3,3,1,1,1,1,1,1
1,1,1,1,1,1,1,1,1,1,1,1,1,1,1,1,1
endlayer

layer
1,1,1,1,1,1,1,1,1,1,1,1,1,1,1,1,1
1,1,1,1,1,1,1,1,1,1,1,1,1,1,1,1,1
1,1,1,1,1,3,3,3,3,3,3,3,1,1,1,1,1
1,1,1,1,3,2,2,2,2,2,2,2,3,1,1,1,1
1,0,0,0,0,2,3,2,2,0,0,2,2,3,1,1,1
1,0,0,0,0,3,0,0,3,0,0,3,2,2,3,1,1
1,1,0,0,0,0,3,0,0,0,0,0,0,2,2,3,1
1,1,1,2,3,0,0,0,0,0,3,0,3,2,3,1,1
1,1,3,2,2,2,0,0,0,3,2,0,0,2,3,1,1
1,1,3,2,0,2,0,0,0,2,2,2,0,2,3,1,1
1,1,3,2,2,0,0,3,0,3,2,2,3,2,3,1,1
1,1,3,2,2,3,0,0,0,0,0,0,2,2,3,1,1
1,1,1,3,2,2,0,0,2,0,3,2,2,3,1,1,1
1,1,1,1,3,2,2,2,2,2,2,2,3,1,1,1,1
1,1,1,1,1,3,3,3,3,3,3,1,1,1,1,1,1
1,1,1,1,1,1,1,1,1,1,1,1,1,1,1,1,1
1,1,1,1,1,1,1,1,1,1,1,1,1,1,1,1,1
endlayer

layer
1,1,1,1,1,1,1,1,1,1,1,1,1,1,1,1,1
1,1,1,1,1,1,1,1,1,1,1,1,1,1,1,1,1
1,0,1,1,1,1,1,1,1,1,1,1,1,1,1,1,1
0,0,0,1,1,1,3,3,3,3,3,1,1,1,1,1,1
0,0,0,0,1,3,2,2,2,2,2,3,1,1,1,1,1
1,0,0,0,0,2,2,2,2,2,2,2,3,1,1,1,1
1,1,0,0,1,2,2,0,0,3,2,2,2,3,1,1,1
1,1,1,3,2,2,3,0,0,0,2,2,2,3,1,1,1
1,1,1,3,2,2,2,0,3,2,2,2,2,3,1,1,1
1,1,1,3,2,2,3,0,2,2,2,2,2,3,1,1,1
1,1,1,3,2,2,2,3,2,2,2,2,2,3,1,1,1
1,1,1,1,3,2,2,2,2,2,2,2,3,1,1,1,1
1,1,1,1,1,3,2,2,2,2,2,3,1,1,1,1,1
1,1,1,1,1,1,3,3,3,3,3,1,1,1,1,1,1
1,1,1,1,1,1,1,1,1,1,1,1,1,1,1,1,1
1,1,1,1,1,1,1,1,1,1,1,1,1,1,1,1,1
1,1,1,1,1,1,1,1,1,1,1,1,1,1,1,1,1
endlayer

layer
1,1,1,1,1,1,1,1,1,1,1,1,1,1,1,1,1
1,0,1,1,1,1,1,1,1,1,1,1,1,1,1,1,1
0,0,0,1,1,1,1,1,1,1,1,1,1,1,1,1,1
0,0,0,1,1,1,1,1,1,1,1,1,1,1,1,1,1
0,0,0,0,1,1,1,1,1,1,1,1,1,1,1,1,1
1,0,0,0,1,1,1,3,3,3,1,1,1,1,1,1,1
1,1,1,1,1,1,3,2,2,2,3,1,1,1,1,1,1
1,1,1,1,1,3,2,2,2,2,2,3,1,1,1,1,1
1,1,1,1,1,3,2,2,2,2,2,3,1,1,1,1,1
1,1,1,1,1,3,2,2,2,2,2,3,1,1,1,1,1
1,1,1,1,1,1,3,2,2,2,3,1,1,1,1,1,1
1,1,1,1,1,1,1,3,3,3,1,1,1,1,1,1,1
1,1,1,1,1,1,1,1,1,1,1,1,1,1,1,1,1
1,1,1,1,1,1,1,1,1,1,1,1,1,1,1,1,1
1,1,1,1,1,1,1,1,1,1,1,1,1,1,1,1,1
1,1,1,1,1,1,1,1,1,1,1,1,1,1,1,1,1
1,1,1,1,1,1,1,1,1,1,1,1,1,1,1,1,1
endlayer

