
# Created by Ruins mod version 17.0 Ingame Parser
# authoring Player: ST753M

weight=1
embed_into_distance=5
uniqueMinDistance=1000
spawnMinDistance=500
acceptable_target_blocks=
unacceptable_target_blocks=flowing_water,water,flowing_lava,lava,ice,bedrock,netherrack,nether_brick,nether_brick_fence,soul_sand,quartz_ore,end_stone,obsidian,iron_bars,Natura:Cloud,slime_grass,slime_congealed,slime_dirt,clouds,natura:clouds
dimensions=14,17,17
allowable_overhang=2
max_leveling=2
leveling_buffer=0
preserve_water=0
preserve_lava=0

biomesToSpawnIn=ice_flats,ice_mountains,glacier,mutated_ice_flats,cold_beach,cold_desert,ice_mountains,glacier,glacier_spikes

rule1=0,100,minecraft:packed_ice-0
rule2=0,100,minecraft:tnt-0
rule3=0,100,minecraft:wooden_pressure_plate-0
rule4=0,100,minecraft:ice-0
rule5=0,100,minecraft:diamond_block-0,minecraft:emerald_block-0,minecraft:gold_block-0,minecraft:diamond_block-0,minecraft:diamond_block-0

layer
1,1,1,1,1,1,1,1,1,1,1,1,1,1,1,1,1
1,1,1,1,1,1,1,1,1,1,1,1,1,1,1,1,1
1,1,1,1,1,1,1,1,1,1,1,1,1,1,1,1,1
1,1,1,1,1,1,1,1,1,1,1,1,1,1,1,1,1
1,1,1,1,1,1,1,1,1,1,1,1,1,1,1,1,1
1,1,1,1,1,1,1,1,1,1,1,1,1,1,1,1,1
1,1,1,1,1,1,1,1,1,1,1,1,1,1,1,1,1
1,1,1,1,1,1,1,1,1,1,1,1,1,1,1,1,1
1,1,1,1,1,1,1,1,1,1,1,1,1,1,1,1,1
1,1,1,1,1,1,1,1,1,1,1,1,1,1,1,1,1
1,1,1,1,1,1,1,1,1,1,1,1,1,1,1,1,1
1,1,1,1,1,1,1,1,1,1,1,1,1,1,1,1,1
1,1,1,1,1,1,1,1,1,1,1,1,1,1,1,1,1
1,1,1,1,1,1,1,1,1,1,1,1,1,1,1,1,1
1,1,1,1,1,1,1,1,1,1,1,1,1,1,1,1,1
1,1,1,1,1,1,1,1,1,1,1,1,1,1,1,1,1
1,1,1,1,1,1,1,1,1,1,1,1,1,1,1,1,1
endlayer

layer
1,1,1,1,1,1,1,1,1,1,1,1,1,1,1,1,1
1,1,1,1,1,1,1,1,1,1,1,1,1,1,1,1,1
1,1,1,1,1,1,1,1,1,1,1,1,1,1,1,1,1
1,1,1,1,1,1,1,1,1,1,1,1,1,1,1,1,1
1,1,1,1,1,1,1,1,1,1,1,1,1,1,1,1,1
1,1,1,1,1,1,1,1,1,1,1,1,1,1,1,1,1
1,1,1,1,1,1,1,1,1,1,1,1,1,1,1,1,1
1,1,1,1,1,1,1,1,2,1,1,1,1,1,1,1,1
1,1,1,1,1,1,1,2,2,2,1,1,1,1,1,1,1
1,1,1,1,1,1,1,1,2,1,1,1,1,1,1,1,1
1,1,1,1,1,1,1,1,1,1,1,1,1,1,1,1,1
1,1,1,1,1,1,1,1,1,1,1,1,1,1,1,1,1
1,1,1,1,1,1,1,1,1,1,1,1,1,1,1,1,1
1,1,1,1,1,1,1,1,1,1,1,1,1,1,1,1,1
1,1,1,1,1,1,1,1,1,1,1,1,1,1,1,1,1
1,1,1,1,1,1,1,1,1,1,1,1,1,1,1,1,1
1,1,1,1,1,1,1,1,1,1,1,1,1,1,1,1,1
endlayer

layer
1,1,1,1,1,1,1,1,1,1,1,1,1,1,1,1,1
1,1,1,1,1,1,1,1,1,1,1,1,1,1,1,1,1
1,1,1,1,1,1,1,1,1,1,1,1,1,1,1,1,1
1,1,1,1,1,1,1,1,1,1,1,1,1,1,1,1,1
1,1,1,1,1,1,1,1,1,1,1,1,1,1,1,1,1
1,1,1,1,1,1,1,1,1,1,1,1,1,1,1,1,1
1,1,1,1,1,1,1,1,1,1,1,1,1,1,1,1,1
1,1,1,1,1,1,1,1,1,1,1,1,1,1,1,1,1
1,1,1,1,1,1,1,1,1,1,1,1,1,1,1,1,1
1,1,1,1,1,1,1,1,1,1,1,1,1,1,1,1,1
1,1,1,1,1,1,1,1,1,1,1,1,1,1,1,1,1
1,1,1,1,1,1,1,1,1,1,1,1,1,1,1,1,1
1,1,1,1,1,1,1,1,1,1,1,1,1,1,1,1,1
1,1,1,1,1,1,1,1,1,1,1,1,1,1,1,1,1
1,1,1,1,1,1,1,1,1,1,1,1,1,1,1,1,1
1,1,1,1,1,1,1,1,1,1,1,1,1,1,1,1,1
1,1,1,1,1,1,1,1,1,1,1,1,1,1,1,1,1
endlayer

layer
1,1,1,1,1,1,1,1,1,1,1,1,1,1,1,1,1
1,1,1,1,1,1,1,1,1,1,1,1,1,1,1,1,1
1,1,1,1,1,1,1,1,1,1,1,1,1,1,1,1,1
1,1,1,1,1,1,1,1,1,1,1,1,1,1,1,1,1
1,1,1,1,1,1,1,1,1,1,1,1,1,1,1,1,1
1,1,1,1,1,1,1,1,1,1,1,1,1,1,1,1,1
1,1,1,1,1,1,1,1,1,1,1,1,1,1,1,1,1
1,1,1,1,1,1,1,1,1,1,1,1,1,1,1,1,1
1,1,1,1,1,1,1,1,3,1,1,1,1,1,1,1,1
1,1,1,1,1,1,1,1,1,1,1,1,1,1,1,1,1
1,1,1,1,1,1,1,1,1,1,1,1,1,1,1,1,1
1,1,1,1,1,1,1,1,1,1,1,1,1,1,1,1,1
1,1,1,1,1,1,1,1,1,1,1,1,1,1,1,1,1
1,1,1,1,1,1,1,1,1,1,1,1,1,1,1,1,1
1,1,1,1,1,1,1,1,1,1,1,1,1,1,1,1,1
1,1,1,1,1,1,1,1,1,1,1,1,1,1,1,1,1
1,1,1,1,1,1,1,1,1,1,1,1,1,1,1,1,1
endlayer

layer
1,1,1,1,1,1,1,1,1,1,1,1,1,1,1,1,1
1,1,1,1,1,1,1,1,4,1,1,1,1,1,1,1,1
1,1,1,1,1,1,1,1,4,1,1,1,1,1,1,1,1
1,1,1,1,4,4,1,1,4,1,1,4,4,1,1,1,1
1,1,1,4,1,4,1,1,1,1,1,4,1,4,1,1,1
1,1,1,4,4,1,4,4,1,4,4,1,4,4,1,1,1
1,1,1,1,1,4,4,1,1,1,4,4,1,1,1,1,1
1,1,1,1,1,4,1,4,4,4,1,4,1,1,1,1,1
1,4,4,4,1,1,1,4,5,4,1,1,1,4,4,4,1
1,1,1,1,1,4,1,4,4,4,1,4,1,1,1,1,1
1,1,1,1,1,4,4,1,1,1,4,4,1,1,1,1,1
1,1,1,4,4,1,4,4,1,4,4,1,4,4,1,1,1
1,1,1,4,1,4,1,1,1,1,1,4,1,4,1,1,1
1,1,1,1,4,4,1,1,4,1,1,4,4,1,1,1,1
1,1,1,1,1,1,1,1,4,1,1,1,1,1,1,1,1
1,1,1,1,1,1,1,1,4,1,1,1,1,1,1,1,1
1,1,1,1,1,1,1,1,1,1,1,1,1,1,1,1,1
endlayer

layer
4,4,4,4,4,4,4,0,0,0,4,4,4,4,4,4,4
4,1,1,1,1,1,1,0,0,0,1,1,1,1,1,1,4
4,1,0,0,0,0,0,0,0,0,0,0,0,0,0,1,4
4,1,0,0,0,0,0,0,0,0,0,0,0,0,0,1,4
4,1,0,0,0,0,0,0,0,0,0,0,0,0,0,1,4
4,1,0,0,0,0,0,0,0,0,0,0,0,0,0,1,4
4,1,0,0,0,0,0,0,0,0,0,0,0,0,0,1,4
0,0,0,0,0,0,0,0,0,0,0,0,0,0,0,0,0
0,0,0,0,0,0,0,0,0,0,0,0,0,0,0,0,0
0,0,0,0,0,0,0,0,0,0,0,0,0,0,0,0,0
4,1,0,0,0,0,0,0,0,0,0,0,0,0,0,1,4
4,1,0,0,0,0,0,0,0,0,0,0,0,0,0,1,4
4,1,0,0,0,0,0,0,0,0,0,0,0,0,0,1,4
4,1,0,0,0,0,0,0,0,0,0,0,0,0,0,1,4
4,1,0,0,0,0,0,0,0,0,0,0,0,0,0,1,4
4,1,1,1,1,1,1,0,0,0,1,1,1,1,1,1,4
4,4,4,4,4,4,4,0,0,0,4,4,4,4,4,4,4
endlayer

layer
4,0,0,0,0,0,4,0,0,0,4,0,0,0,0,0,4
0,4,4,4,4,4,1,0,0,0,1,4,4,4,4,4,0
0,4,1,1,1,1,1,0,0,0,1,1,1,1,1,4,0
0,4,1,0,0,0,0,0,0,0,0,0,0,0,1,4,0
0,4,1,0,0,0,0,0,0,0,0,0,0,0,1,4,0
0,4,1,0,0,0,0,0,0,0,0,0,0,0,1,4,0
4,1,1,0,0,0,0,0,0,0,0,0,0,0,1,1,4
0,0,0,0,0,0,0,0,0,0,0,0,0,0,0,0,0
0,0,0,0,0,0,0,0,0,0,0,0,0,0,0,0,0
0,0,0,0,0,0,0,0,0,0,0,0,0,0,0,0,0
4,1,1,0,0,0,0,0,0,0,0,0,0,0,1,1,4
0,4,1,0,0,0,0,0,0,0,0,0,0,0,1,4,0
0,4,1,0,0,0,0,0,0,0,0,0,0,0,1,4,0
0,4,1,0,0,0,0,0,0,0,0,0,0,0,1,4,0
0,4,1,1,1,1,1,0,0,0,1,1,1,1,1,4,0
0,4,4,4,4,4,1,0,0,0,1,4,4,4,4,4,0
4,0,0,0,0,0,4,0,0,0,4,0,0,0,0,0,0
endlayer

layer
4,0,0,0,0,0,0,0,0,0,0,0,0,0,0,0,4
0,0,0,0,0,0,4,0,0,0,4,0,0,0,0,0,0
0,0,4,4,4,4,1,0,0,0,1,4,4,4,4,0,0
0,0,4,1,1,1,1,0,0,0,1,1,1,1,4,0,0
0,0,4,1,0,0,0,0,0,0,0,0,0,1,4,0,0
0,0,4,1,0,0,0,0,0,0,0,0,0,1,4,0,0
0,4,1,1,0,0,0,0,0,0,0,0,0,1,1,4,0
0,0,0,0,0,0,0,0,0,0,0,0,0,0,0,0,0
0,0,0,0,0,0,0,0,0,0,0,0,0,0,0,0,0
0,0,0,0,0,0,0,0,0,0,0,0,0,0,0,0,0
0,4,1,1,0,0,0,0,0,0,0,0,0,1,1,4,0
0,0,4,1,0,0,0,0,0,0,0,0,0,1,4,0,0
0,0,4,1,0,0,0,0,0,0,0,0,0,1,4,0,0
0,0,4,1,1,1,1,0,0,0,1,1,1,1,4,0,0
0,0,4,4,4,4,1,0,0,0,1,4,4,4,4,0,0
0,0,0,0,0,0,4,0,0,0,4,0,0,0,0,0,0
4,0,0,0,0,0,0,0,0,0,0,0,0,0,0,0,0
endlayer

layer
0,0,0,0,0,0,0,0,0,0,0,0,0,0,0,0,0
0,0,0,0,0,0,0,4,0,4,0,0,0,0,0,0,0
0,0,0,0,0,0,4,1,0,1,4,0,0,0,0,0,0
0,0,0,4,4,4,4,1,0,1,4,4,4,4,0,0,0
0,0,0,4,1,1,1,1,0,1,1,1,1,4,0,0,0
0,0,0,4,1,0,0,0,0,0,0,0,1,4,0,0,0
0,0,4,4,1,0,0,0,0,0,0,0,1,4,4,0,0
0,4,1,1,1,0,0,0,0,0,0,0,1,1,1,4,0
0,0,0,0,0,0,0,0,0,0,0,0,0,0,0,0,0
0,4,1,1,1,0,0,0,0,0,0,0,1,1,1,4,0
0,0,4,4,1,0,0,0,0,0,0,0,1,4,4,0,0
0,0,0,4,1,0,0,0,0,0,0,0,1,4,0,0,0
0,0,0,4,1,1,1,1,0,1,1,1,1,4,0,0,0
0,0,0,4,4,4,4,1,0,1,4,4,4,4,0,0,0
0,0,0,0,0,0,4,1,0,1,4,0,0,0,0,0,0
0,0,0,0,0,0,0,4,0,4,0,0,0,0,0,0,0
0,0,0,0,0,0,0,0,0,0,0,0,0,0,0,0,0
endlayer

layer
0,0,0,0,0,0,0,0,0,0,0,0,0,0,0,0,0
0,0,0,0,0,0,0,4,1,4,0,0,0,0,0,0,0
0,0,0,0,0,0,0,4,1,4,0,0,0,0,0,0,0
0,0,0,0,0,0,0,4,1,4,0,0,0,0,0,0,0
0,0,0,0,4,4,4,4,1,4,4,4,4,0,0,0,0
0,0,0,0,4,1,1,1,1,1,1,1,4,0,0,0,0
0,0,0,0,4,1,0,0,0,0,0,1,4,0,0,0,0
0,4,4,4,4,1,0,0,0,0,0,1,4,4,4,4,0
0,1,1,1,1,1,0,0,0,0,0,1,1,1,1,1,0
0,4,4,4,4,1,0,0,0,0,0,1,4,4,4,4,0
0,0,0,0,4,1,0,0,0,0,0,1,4,0,0,0,0
0,0,0,0,4,1,1,1,1,1,1,1,4,0,0,0,0
0,0,0,0,4,4,4,4,1,4,4,4,4,0,0,0,0
0,0,0,0,0,0,0,4,1,4,0,0,0,0,0,0,0
0,0,0,0,0,0,0,4,1,4,0,0,0,0,0,0,0
0,0,0,0,0,0,0,4,1,4,0,0,0,0,0,0,0
0,0,0,0,0,0,0,0,0,0,0,0,0,0,0,0,0
endlayer

layer
0,0,0,0,0,0,0,0,0,0,0,0,0,0,0,0,0
0,0,0,0,0,0,0,4,4,4,0,0,0,0,0,0,0
0,0,0,0,0,0,0,0,4,0,0,0,0,0,0,0,0
0,0,0,0,0,0,0,0,4,0,0,0,0,0,0,0,0
0,0,0,0,0,0,0,0,4,0,0,0,0,0,0,0,0
0,0,0,0,0,4,4,4,4,4,4,4,0,0,0,0,0
0,0,0,0,0,4,1,1,1,1,1,4,0,0,0,0,0
0,4,0,0,0,4,1,0,0,0,1,4,0,0,0,4,0
0,4,4,4,4,4,1,0,0,0,1,4,4,4,4,4,0
0,4,0,0,0,4,1,0,0,0,1,4,0,0,0,4,0
0,0,0,0,0,4,1,1,1,1,1,4,0,0,0,0,0
0,0,0,0,0,4,4,4,4,4,4,4,0,0,0,0,0
0,0,0,0,0,0,0,0,4,0,0,0,0,0,0,0,0
0,0,0,0,0,0,0,0,4,0,0,0,0,0,0,0,0
0,0,0,0,0,0,0,0,4,0,0,0,0,0,0,0,0
0,0,0,0,0,0,0,4,4,4,0,0,0,0,0,0,0
0,0,0,0,0,0,0,0,0,0,0,0,0,0,0,0,0
endlayer

layer
0,0,0,0,0,0,0,0,0,0,0,0,0,0,0,0,0
0,0,0,0,0,0,0,0,4,0,0,0,0,0,0,0,0
0,0,0,0,0,0,0,0,4,0,0,0,0,0,0,0,0
0,0,0,0,0,0,0,0,0,0,0,0,0,0,0,0,0
0,0,0,0,0,0,0,0,0,0,0,0,0,0,0,0,0
0,0,0,0,0,4,0,0,0,0,0,4,0,0,0,0,0
0,0,0,0,0,0,4,4,4,4,4,0,0,0,0,0,0
0,0,0,0,0,0,4,1,1,1,4,0,0,0,0,0,0
0,4,4,0,0,0,4,1,0,1,4,0,0,0,4,4,0
0,0,0,0,0,0,4,1,1,1,4,0,0,0,0,0,0
0,0,0,0,0,0,4,4,4,4,4,0,0,0,0,0,0
0,0,0,0,0,4,0,0,0,0,0,4,0,0,0,0,0
0,0,0,0,0,0,0,0,0,0,0,0,0,0,0,0,0
0,0,0,0,0,0,0,0,0,0,0,0,0,0,0,0,0
0,0,0,0,0,0,0,0,4,0,0,0,0,0,0,0,0
0,0,0,0,0,0,0,0,4,0,0,0,0,0,0,0,0
0,0,0,0,0,0,0,0,0,0,0,0,0,0,0,0,0
endlayer

layer
0,0,0,0,0,0,0,0,0,0,0,0,0,0,0,0,0
0,0,0,0,0,0,0,0,4,0,0,0,0,0,0,0,0
0,0,0,0,0,0,0,0,0,0,0,0,0,0,0,0,0
0,0,0,0,0,0,0,0,0,0,0,0,0,0,0,0,0
0,0,0,0,0,0,0,0,0,0,0,0,0,0,0,0,0
0,0,0,0,0,4,0,0,0,0,0,4,0,0,0,0,0
0,0,0,0,0,0,0,0,0,0,0,0,0,0,0,0,0
0,0,0,0,0,0,0,4,4,4,0,0,0,0,0,0,0
0,4,0,0,0,0,0,4,0,4,0,0,0,0,0,4,0
0,0,0,0,0,0,0,4,4,4,0,0,0,0,0,0,0
0,0,0,0,0,0,0,0,0,0,0,0,0,0,0,0,0
0,0,0,0,0,4,0,0,0,0,0,4,0,0,0,0,0
0,0,0,0,0,0,0,0,0,0,0,0,0,0,0,0,0
0,0,0,0,0,0,0,0,0,0,0,0,0,0,0,0,0
0,0,0,0,0,0,0,0,0,0,0,0,0,0,0,0,0
0,0,0,0,0,0,0,0,4,0,0,0,0,0,0,0,0
0,0,0,0,0,0,0,0,0,0,0,0,0,0,0,0,0
endlayer

layer
0,0,0,0,0,0,0,0,0,0,0,0,0,0,0,0,0
0,0,0,0,0,0,0,0,0,0,0,0,0,0,0,0,0
0,0,0,0,0,0,0,0,0,0,0,0,0,0,0,0,0
0,0,0,0,0,0,0,0,0,0,0,0,0,0,0,0,0
0,0,0,0,0,0,0,0,0,0,0,0,0,0,0,0,0
0,0,0,0,0,0,0,0,0,0,0,0,0,0,0,0,0
0,0,0,0,0,0,0,0,0,0,0,0,0,0,0,0,0
0,0,0,0,0,0,0,0,0,0,0,0,0,0,0,0,0
0,0,0,0,0,0,0,0,4,0,0,0,0,0,0,0,0
0,0,0,0,0,0,0,0,0,0,0,0,0,0,0,0,0
0,0,0,0,0,0,0,0,0,0,0,0,0,0,0,0,0
0,0,0,0,0,0,0,0,0,0,0,0,0,0,0,0,0
0,0,0,0,0,0,0,0,0,0,0,0,0,0,0,0,0
0,0,0,0,0,0,0,0,0,0,0,0,0,0,0,0,0
0,0,0,0,0,0,0,0,0,0,0,0,0,0,0,0,0
0,0,0,0,0,0,0,0,0,0,0,0,0,0,0,0,0
0,0,0,0,0,0,0,0,0,0,0,0,0,0,0,0,0
endlayer

