
# Created by Ruins mod version 17.1 Ingame Parser
# authoring Player: ST753M

weight=1
embed_into_distance=5
acceptable_target_blocks=
unacceptable_target_blocks=flowing_water,water,flowing_lava,lava
dimensions=20,21,21
allowable_overhang=5
max_leveling=0
leveling_buffer=0
preserve_water=0
preserve_lava=0

biomesToSpawnIn=ice_flats,ice_mountains,glacier,mutated_ice_flats,cold_beach,cold_desert,glacier_spikes,cold_plateau

=0,100,air
rule1=0,100,preserveBlock
rule2=0,100,iceandfire:frozen_cobblestone-0
rule3=0,100,iceandfire:dragon_ice-0
rule4=0,100,minecraft:light_blue_glazed_terracotta-2
rule5=0,100,minecraft:light_blue_glazed_terracotta-1
rule6=0,100,minecraft:light_blue_glazed_terracotta-3
rule7=0,100,minecraft:light_blue_glazed_terracotta-0
rule8=0,100,iceandfire:frozen_grass-0
rule9=0,100,minecraft:ice-0
rule10=0,100,iceandfire:silverpile-7,iceandfire:silverpile-6,iceandfire:silverpile-5,iceandfire:silverpile-4,iceandfire:silverpile-3,iceandfire:silverpile-2,iceandfire:silverpile-1,iceandfire:silverpile-0
rule11=0,40,IInventory;minecraft:chest;iceandfire:sapphire_gem#3#0#5+minecraft:potion#{Potion:"minecraft:long_strength"}#0#10+iceandfire:armor_silver_metal_helmet#1#0#13+minecraft:rotten_flesh#8#0#16+iceandfire:silver_ingot#5#0#24-5,IInventory;minecraft:trapped_chest;iceandfire:silver_ingot#5#0#4+minecraft:potion#{Potion:"minecraft:long_invisibility"}#0#11+minecraft:leather#7#0#15+iceandfire:sapphire_gem#2#0#19+iceandfire:armor_silver_metal_leggings#1#0#22-2,IInventory;minecraft:chest;minecraft:bone#8#0#7+minecraft:potion#{Potion:"minecraft:strength"}#0#11+minecraft:string#6#0#13+iceandfire:armor_silver_metal_chestplate#1#0#23+iceandfire:manuscript#3#0#26-2,IInventory;minecraft:trapped_chest;iceandfire:manuscript#3#0#1+minecraft:bone#8#0#12+minecraft:potion#{Potion:"minecraft:long_water_breathing"}#0#15+iceandfire:silver_ingot#5#0#19+iceandfire:armor_silver_metal_boots#1#0#22-5,IInventory;minecraft:chest;iceandfire:silver_ingot#5#0#3+iceandfire:silver_axe#1#0#15+iceandfire:manuscript#3#0#20+minecraft:potion#{Potion:"minecraft:long_swiftness"}#0#22+minecraft:rotten_flesh#9#0#25-2,IInventory;minecraft:trapped_chest;minecraft:potion#{Potion:"minecraft:strong_healing"}#0#3+minecraft:rotten_flesh#9#0#5+iceandfire:silver_hoe#1#0#14+iceandfire:silver_ingot#4#0#15+minecraft:golden_apple#1#0#19+iceandfire:manuscript#3#0#21-4,IInventory;minecraft:chest;minecraft:rotten_flesh#6#0#3+minecraft:potion#{Potion:"minecraft:regeneration"}#0#13+iceandfire:sapphire_gem#2#0#15+iceandfire:silver_sword#{}#0#19+iceandfire:silver_ingot#4#0#25-3,IInventory;minecraft:trapped_chest;iceandfire:manuscript#2#0#0+minecraft:bone#8#0#6+iceandfire:silver_shovel#1#0#11+minecraft:potion#{Potion:"minecraft:invisibility"}#0#14+minecraft:iron_ingot#6#0#21-3,IInventory;minecraft:chest;iceandfire:sapphire_gem#3#0#2+iceandfire:silver_pickaxe#1#0#6+minecraft:potion#{Potion:"minecraft:water_breathing"}#0#13+iceandfire:silver_ingot#4#0#21+minecraft:bone#8#0#26-4
rule12=0,100,CommandBlock:RUINSTRIGGER /summon iceandfire:icedragon ~ ~2 ~ {PersistenceRequired:1,Variant:0,AgeTicks:600000}:@-1,CommandBlock:RUINSTRIGGER /summon iceandfire:icedragon ~ ~2 ~ {PersistenceRequired:1,Variant:1,AgeTicks:600000}:@-1,CommandBlock:RUINSTRIGGER /summon iceandfire:icedragon ~ ~2 ~ {PersistenceRequired:1,Variant:2,AgeTicks:600000}:@-1,CommandBlock:RUINSTRIGGER /summon iceandfire:icedragon ~ ~2 ~ {PersistenceRequired:1,Variant:3,AgeTicks:600000}:@-1
rule13=0,100,minecraft:packed_ice-0
rule14=0,100,minecraft:sea_lantern-0






layer
1,1,1,1,1,1,1,1,1,1,1,1,1,1,1,1,1,1,1,1,1
1,1,1,1,1,1,1,1,1,2,2,2,1,1,1,1,1,1,1,1,1
1,1,1,1,1,1,1,2,2,2,2,2,2,2,1,1,1,1,1,1,1
1,1,1,1,1,2,2,2,2,2,2,2,2,2,2,2,1,1,1,1,1
1,1,1,1,2,2,2,2,2,2,2,2,2,2,2,2,2,1,1,1,1
1,1,1,2,2,2,2,2,2,2,2,2,2,2,2,2,2,2,1,1,1
1,1,1,2,2,2,2,2,2,2,2,2,2,2,2,2,2,2,1,1,1
1,1,2,2,2,2,2,2,2,2,2,2,2,2,2,2,2,2,2,1,1
1,1,2,2,2,2,2,2,2,2,2,2,2,2,2,2,2,2,2,1,1
1,2,2,2,2,2,2,2,2,2,2,2,2,2,2,2,2,2,2,2,1
1,2,2,2,2,2,2,2,2,2,2,2,2,2,2,2,2,2,2,2,1
1,2,2,2,2,2,2,2,2,2,2,2,2,2,2,2,2,2,2,2,1
1,1,2,2,2,2,2,2,2,2,2,2,2,2,2,2,2,2,2,1,1
1,1,2,2,2,2,2,2,2,2,2,2,2,2,2,2,2,2,2,1,1
1,1,1,2,2,2,2,2,2,2,2,2,2,2,2,2,2,2,1,1,1
1,1,1,2,2,2,2,2,2,2,2,2,2,2,2,2,2,2,1,1,1
1,1,1,1,2,2,2,2,2,2,2,2,2,2,2,2,2,1,1,1,1
1,1,1,1,1,2,2,2,2,2,2,2,2,2,2,2,1,1,1,1,1
1,1,1,1,1,1,1,2,2,2,2,2,2,2,1,1,1,1,1,1,1
1,1,1,1,1,1,1,1,1,2,2,2,1,1,1,1,1,1,1,1,1
1,1,1,1,1,1,1,1,1,1,1,1,1,1,1,1,1,1,1,1,1
endlayer

layer
1,1,1,1,1,1,1,1,1,1,1,1,1,1,1,1,1,1,1,1,1
1,1,1,1,1,1,1,1,2,2,2,2,2,1,1,1,1,1,1,1,1
1,1,1,1,1,1,2,2,2,2,2,2,2,2,2,1,1,1,1,1,1
1,1,1,1,2,2,2,2,2,2,2,2,2,2,2,2,2,1,1,1,1
1,1,1,2,2,2,2,2,2,2,2,2,2,2,2,2,2,2,1,1,1
1,1,1,2,2,2,2,2,2,2,2,2,2,2,2,2,2,2,1,1,1
1,1,2,2,2,2,2,2,2,2,2,2,2,2,2,2,2,2,2,1,1
1,1,2,2,2,2,2,2,2,2,2,2,2,2,2,2,2,2,2,1,1
1,2,2,2,2,2,2,2,2,2,2,2,2,2,2,2,2,2,2,2,1
1,2,2,2,2,2,2,2,2,2,2,2,2,2,2,2,2,2,2,2,1
1,2,2,2,2,2,2,2,2,2,2,2,2,2,2,2,2,2,2,2,1
1,2,2,2,2,2,2,2,2,2,2,2,2,2,2,2,2,2,2,2,1
1,2,2,2,2,2,2,2,2,2,2,2,2,2,2,2,2,2,2,2,1
1,1,2,2,2,2,2,2,2,2,2,2,2,2,2,2,2,2,2,1,1
1,1,2,2,2,2,2,2,2,2,2,2,2,2,2,2,2,2,2,1,1
1,1,1,2,2,2,2,2,2,2,2,2,2,2,2,2,2,2,1,1,1
1,1,1,2,2,2,2,2,2,2,2,2,2,2,2,2,2,2,1,1,1
1,1,1,1,2,2,2,2,2,2,2,2,2,2,2,2,2,1,1,1,1
1,1,1,1,1,1,2,2,2,2,2,2,2,2,2,1,1,1,1,1,1
1,1,1,1,1,1,1,1,2,2,2,2,2,1,1,1,1,1,1,1,1
1,1,1,1,1,1,1,1,1,1,1,1,1,1,1,1,1,1,1,1,1
endlayer

layer
1,1,1,1,1,1,1,1,1,1,1,1,1,1,1,1,1,1,1,1,1
1,1,1,1,1,1,1,1,2,2,2,2,2,1,1,1,1,1,1,1,1
1,1,1,1,1,1,2,2,2,2,2,2,2,2,2,1,1,1,1,1,1
1,1,1,1,2,2,2,2,2,2,2,2,2,2,2,2,2,1,1,1,1
1,1,1,2,2,2,2,2,2,2,2,2,2,2,2,2,2,2,1,1,1
1,1,1,2,2,2,2,2,2,2,2,2,2,2,2,2,2,2,1,1,1
1,1,2,2,2,2,2,2,2,2,2,2,2,2,2,2,2,2,2,1,1
1,1,2,2,2,2,2,2,2,2,2,2,2,2,2,2,2,2,2,1,1
1,2,2,2,2,2,2,2,2,2,2,2,2,2,2,2,2,2,2,2,1
1,2,2,2,2,2,2,2,2,2,2,2,2,2,2,2,2,2,2,2,1
1,2,2,2,2,2,2,2,2,2,2,2,2,2,2,2,2,2,2,2,1
1,2,2,2,2,2,2,2,2,2,2,2,2,2,2,2,2,2,2,2,1
1,2,2,2,2,2,2,2,2,2,2,2,2,2,2,2,2,2,2,2,1
1,1,2,2,2,2,2,2,2,2,2,2,2,2,2,2,2,2,2,1,1
1,1,2,2,2,2,2,2,2,2,2,2,2,2,2,2,2,2,2,1,1
1,1,1,2,2,2,2,2,2,2,2,2,2,2,2,2,2,2,1,1,1
1,1,1,2,2,2,2,2,2,2,2,2,2,2,2,2,2,2,1,1,1
1,1,1,1,2,2,2,2,2,2,2,2,2,2,2,2,2,1,1,1,1
1,1,1,1,1,1,2,2,2,2,2,2,2,2,2,1,1,1,1,1,1
1,1,1,1,1,1,1,1,2,2,2,2,2,1,1,1,1,1,1,1,1
1,1,1,1,1,1,1,1,1,1,1,1,1,1,1,1,1,1,1,1,1
endlayer

layer
1,1,1,1,1,1,1,1,1,1,1,1,1,1,1,1,1,1,1,1,1
1,1,1,1,1,1,1,3,2,2,2,2,2,3,1,1,1,1,1,1,1
1,1,1,1,1,1,2,2,2,2,2,2,2,2,2,1,1,1,1,1,1
1,1,1,3,2,2,2,2,2,2,2,2,2,2,2,2,2,3,1,1,1
1,1,1,2,2,2,2,2,2,2,2,2,2,2,2,2,2,2,1,1,1
1,1,1,2,2,2,2,2,2,2,2,2,2,2,2,2,2,2,1,1,1
1,1,2,2,2,2,2,2,2,6,5,4,2,2,2,2,2,2,2,1,1
1,3,2,2,2,2,2,5,5,4,6,7,4,4,2,2,2,2,2,3,1
1,2,2,2,2,2,2,5,6,5,7,5,7,4,2,2,2,2,2,2,1
1,2,2,2,2,2,5,6,7,6,6,7,4,6,7,2,2,2,2,2,1
1,2,2,2,2,2,7,4,6,4,3,7,5,7,4,2,2,2,2,2,1
1,2,2,2,2,2,4,5,7,4,5,5,4,5,6,2,2,2,2,2,1
1,2,2,2,2,2,2,7,4,6,4,6,5,6,2,2,2,2,2,2,1
1,3,2,2,2,2,2,7,7,4,5,7,6,6,2,2,2,2,2,3,1
1,1,2,2,2,2,2,2,2,7,6,5,2,2,2,2,2,2,2,1,1
1,1,1,2,2,2,2,2,2,2,2,2,2,2,2,2,2,2,1,1,1
1,1,1,2,2,2,2,2,2,2,2,2,2,2,2,2,2,2,1,1,1
1,1,1,3,2,2,2,2,2,2,2,2,2,2,2,2,2,3,1,1,1
1,1,1,1,1,1,2,2,2,2,2,2,2,2,2,1,1,1,1,1,1
1,1,1,1,1,1,1,3,2,2,2,2,2,3,1,1,1,1,1,1,1
1,1,1,1,1,1,1,1,1,1,1,1,1,1,1,1,1,1,1,1,1
endlayer

layer
1,1,1,1,1,1,1,1,1,1,1,1,1,1,1,1,1,1,1,1,1
1,1,1,1,1,1,1,3,3,8,8,8,3,3,1,1,1,1,1,1,1
1,1,1,1,1,1,8,3,3,8,8,8,3,3,8,1,1,1,1,1,1
1,1,1,3,3,8,8,8,8,8,8,8,8,8,8,8,3,3,1,1,1
1,1,1,3,3,8,8,8,8,8,8,8,8,8,8,8,3,3,1,1,1
1,1,1,8,8,8,8,8,8,8,8,8,8,8,8,8,8,8,1,1,1
1,1,8,8,8,8,8,8,8,9,9,9,8,8,8,8,8,8,8,1,1
1,3,3,8,8,8,8,9,9,9,9,9,9,9,8,8,8,8,3,3,1
1,3,3,8,8,8,8,9,9,9,9,9,9,9,8,8,8,8,3,3,1
1,8,8,8,8,8,9,9,9,9,9,9,9,9,9,8,8,8,8,8,1
1,8,8,8,8,8,9,9,9,9,9,9,9,9,9,8,8,8,8,8,1
1,8,8,8,8,8,9,9,9,9,9,9,9,9,9,8,8,8,8,8,1
1,3,3,8,8,8,8,9,9,9,9,9,9,9,8,8,8,8,3,3,1
1,3,3,8,8,8,8,9,9,9,9,9,9,9,8,8,8,8,3,3,1
1,1,8,8,8,8,8,8,8,9,9,9,8,8,8,8,8,8,8,1,1
1,1,1,8,8,8,8,8,8,8,8,8,8,8,8,8,8,8,1,1,1
1,1,1,3,3,8,8,8,8,8,8,8,8,8,8,8,3,3,1,1,1
1,1,1,3,3,8,8,8,8,8,8,8,8,8,8,8,3,3,1,1,1
1,1,1,1,1,1,8,3,3,8,8,8,3,3,8,1,1,1,1,1,1
1,1,1,1,1,1,1,3,3,8,8,8,3,3,1,1,1,1,1,1,1
1,1,1,1,1,1,1,1,1,1,1,1,1,1,1,1,1,1,1,1,1
endlayer

layer
1,1,1,1,1,1,1,1,1,1,1,1,1,1,1,1,1,1,1,1,1
1,1,1,1,1,1,1,3,3,0,0,0,3,3,1,1,1,1,1,1,1
1,1,1,1,1,1,1,3,3,0,0,0,3,3,1,1,1,1,1,1,1
1,1,1,3,3,0,0,10,10,0,0,0,10,10,0,0,3,3,1,1,1
1,1,1,3,3,10,11,0,10,10,0,0,0,10,0,10,3,3,1,1,1
1,1,1,0,10,10,0,0,10,10,0,0,0,0,10,10,10,0,1,1,1
1,1,1,10,10,0,0,0,0,0,0,0,0,0,0,0,0,0,1,1,1
1,3,3,10,10,10,0,0,0,0,0,0,0,0,0,0,10,10,3,3,1
1,3,3,10,10,10,10,0,0,0,0,0,0,0,0,10,10,10,3,3,1
1,0,0,0,10,10,0,0,0,0,0,0,0,0,0,10,10,10,0,0,1
1,0,0,0,0,10,0,0,0,0,12,0,0,0,0,10,0,0,0,0,1
1,0,0,0,0,0,0,0,0,0,0,0,0,0,0,0,11,10,0,0,1
1,3,3,10,0,11,0,0,0,0,0,0,0,0,0,0,10,10,3,3,1
1,3,3,10,10,0,0,0,0,0,0,0,0,0,0,0,10,10,3,3,1
1,1,1,0,10,10,0,0,0,0,0,0,10,0,0,10,0,0,1,1,1
1,1,1,0,10,10,10,0,0,0,0,0,11,0,10,10,10,0,1,1,1
1,1,1,3,3,0,10,10,0,0,0,0,0,10,10,10,3,3,1,1,1
1,1,1,3,3,0,0,10,10,0,0,0,10,10,10,0,3,3,1,1,1
1,1,1,1,1,1,1,3,3,0,0,0,3,3,1,1,1,1,1,1,1
1,1,1,1,1,1,1,3,3,0,0,0,3,3,1,1,1,1,1,1,1
1,1,1,1,1,1,1,1,1,1,1,1,1,1,1,1,1,1,1,1,1
endlayer

layer
1,1,1,1,1,1,1,1,1,1,1,1,1,1,1,1,1,1,1,1,1
1,1,1,1,1,1,1,3,3,0,0,0,3,3,1,1,1,1,1,1,1
1,1,1,1,1,1,1,3,3,0,0,0,3,3,1,1,1,1,1,1,1
1,1,1,3,3,0,0,0,0,0,0,0,0,0,0,0,3,3,1,1,1
1,1,1,3,3,0,0,0,0,0,0,0,0,0,0,0,3,3,1,1,1
1,1,1,0,0,0,0,0,0,0,0,0,0,0,0,0,0,0,1,1,1
1,1,1,0,0,0,0,0,0,0,0,0,0,0,0,0,0,0,1,1,1
1,3,3,0,0,0,0,0,0,0,0,0,0,0,0,0,0,0,3,3,1
1,3,3,0,0,0,0,0,0,0,0,0,0,0,0,0,0,0,3,3,1
1,0,0,0,0,0,0,0,0,0,0,0,0,0,0,0,0,0,0,0,1
1,0,0,0,0,0,0,0,0,0,0,0,0,0,0,0,0,0,0,0,1
1,0,0,0,0,0,0,0,0,0,0,0,0,0,0,0,0,0,0,0,1
1,3,3,0,0,0,0,0,0,0,0,0,0,0,0,0,0,0,3,3,1
1,3,3,0,0,0,0,0,0,0,0,0,0,0,0,0,0,0,3,3,1
1,1,1,0,0,0,0,0,0,0,0,0,0,0,0,0,0,0,1,1,1
1,1,1,0,0,0,0,0,0,0,0,0,0,0,0,0,0,0,1,1,1
1,1,1,3,3,0,0,0,0,0,0,0,0,0,0,0,3,3,1,1,1
1,1,1,3,3,0,0,0,0,0,0,0,0,0,0,0,3,3,1,1,1
1,1,1,1,1,1,1,3,3,0,0,0,3,3,1,1,1,1,1,1,1
1,1,1,1,1,1,1,3,3,0,0,0,3,3,1,1,1,1,1,1,1
1,1,1,1,1,1,1,1,1,1,1,1,1,1,1,1,1,1,1,1,1
endlayer

layer
1,1,1,1,1,1,1,1,1,1,1,1,1,1,1,1,1,1,1,1,1
1,1,1,1,1,1,1,3,3,0,0,0,3,3,1,1,1,1,1,1,1
1,1,1,1,1,1,1,3,3,0,0,0,3,3,1,1,1,1,1,1,1
1,1,1,3,3,0,0,0,0,0,0,0,0,0,0,0,3,3,1,1,1
1,1,1,3,3,0,0,0,0,0,0,0,0,0,0,0,3,3,1,1,1
1,1,1,0,0,0,0,0,0,0,0,0,0,0,0,0,0,0,1,1,1
1,1,1,0,0,0,0,0,0,0,0,0,0,0,0,0,0,0,1,1,1
1,3,3,0,0,0,0,0,0,0,0,0,0,0,0,0,0,0,3,3,1
1,3,3,0,0,0,0,0,0,0,0,0,0,0,0,0,0,0,3,3,1
1,0,0,0,0,0,0,0,0,0,0,0,0,0,0,0,0,0,0,0,1
1,0,0,0,0,0,0,0,0,0,0,0,0,0,0,0,0,0,0,0,1
1,0,0,0,0,0,0,0,0,0,0,0,0,0,0,0,0,0,0,0,1
1,3,3,0,0,0,0,0,0,0,0,0,0,0,0,0,0,0,3,3,1
1,3,3,0,0,0,0,0,0,0,0,0,0,0,0,0,0,0,3,3,1
1,1,1,0,0,0,0,0,0,0,0,0,0,0,0,0,0,0,1,1,1
1,1,1,0,0,0,0,0,0,0,0,0,0,0,0,0,0,0,1,1,1
1,1,1,3,3,0,0,0,0,0,0,0,0,0,0,0,3,3,1,1,1
1,1,1,3,3,0,0,0,0,0,0,0,0,0,0,0,3,3,1,1,1
1,1,1,1,1,1,1,3,3,0,0,0,3,3,1,1,1,1,1,1,1
1,1,1,1,1,1,1,3,3,0,0,0,3,3,1,1,1,1,1,1,1
1,1,1,1,1,1,1,1,1,1,1,1,1,1,1,1,1,1,1,1,1
endlayer

layer
1,1,1,1,1,1,1,1,1,1,1,1,1,1,1,1,1,1,1,1,1
1,1,1,1,1,1,1,3,3,0,0,0,3,3,1,1,1,1,1,1,1
1,1,1,1,1,1,1,3,3,0,0,0,3,3,1,1,1,1,1,1,1
1,1,1,3,3,0,0,0,0,0,0,0,0,0,0,0,3,3,1,1,1
1,1,1,3,3,0,0,0,0,0,0,0,0,0,0,0,3,3,1,1,1
1,1,1,0,0,0,0,0,0,0,0,0,0,0,0,0,0,0,1,1,1
1,1,1,0,0,0,0,0,0,0,0,0,0,0,0,0,0,0,1,1,1
1,3,3,0,0,0,0,0,0,0,0,0,0,0,0,0,0,0,3,3,1
1,3,3,0,0,0,0,0,0,0,0,0,0,0,0,0,0,0,3,3,1
1,0,0,0,0,0,0,0,0,0,0,0,0,0,0,0,0,0,0,0,1
1,0,0,0,0,0,0,0,0,0,0,0,0,0,0,0,0,0,0,0,1
1,0,0,0,0,0,0,0,0,0,0,0,0,0,0,0,0,0,0,0,1
1,3,3,0,0,0,0,0,0,0,0,0,0,0,0,0,0,0,3,3,1
1,3,3,0,0,0,0,0,0,0,0,0,0,0,0,0,0,0,3,3,1
1,1,1,0,0,0,0,0,0,0,0,0,0,0,0,0,0,0,1,1,1
1,1,1,0,0,0,0,0,0,0,0,0,0,0,0,0,0,0,1,1,1
1,1,1,3,3,0,0,0,0,0,0,0,0,0,0,0,3,3,1,1,1
1,1,1,3,3,0,0,0,0,0,0,0,0,0,0,0,3,3,1,1,1
1,1,1,1,1,1,1,3,3,0,0,0,3,3,1,1,1,1,1,1,1
1,1,1,1,1,1,1,3,3,0,0,0,3,3,1,1,1,1,1,1,1
1,1,1,1,1,1,1,1,1,1,1,1,1,1,1,1,1,1,1,1,1
endlayer

layer
1,1,1,1,1,1,1,1,1,1,1,1,1,1,1,1,1,1,1,1,1
1,1,1,1,1,1,1,2,2,0,0,0,2,2,1,1,1,1,1,1,1
1,1,1,1,1,1,1,2,2,0,0,0,2,2,1,1,1,1,1,1,1
1,1,1,2,2,0,0,0,0,0,0,0,0,0,0,0,2,2,1,1,1
1,1,1,2,2,0,0,0,0,0,0,0,0,0,0,0,2,2,1,1,1
1,1,1,0,0,0,0,0,0,0,0,0,0,0,0,0,0,0,1,1,1
1,1,1,0,0,0,0,0,0,0,0,0,0,0,0,0,0,0,1,1,1
1,2,2,0,0,0,0,0,0,0,0,0,0,0,0,0,0,0,2,2,1
1,2,2,0,0,0,0,0,0,0,0,0,0,0,0,0,0,0,2,2,1
1,0,0,0,0,0,0,0,0,0,0,0,0,0,0,0,0,0,0,0,1
1,0,0,0,0,0,0,0,0,0,0,0,0,0,0,0,0,0,0,0,1
1,0,0,0,0,0,0,0,0,0,0,0,0,0,0,0,0,0,0,0,1
1,2,2,0,0,0,0,0,0,0,0,0,0,0,0,0,0,0,2,2,1
1,2,2,0,0,0,0,0,0,0,0,0,0,0,0,0,0,0,2,2,1
1,1,1,0,0,0,0,0,0,0,0,0,0,0,0,0,0,0,1,1,1
1,1,1,0,0,0,0,0,0,0,0,0,0,0,0,0,0,0,1,1,1
1,1,1,2,2,0,0,0,0,0,0,0,0,0,0,0,2,2,1,1,1
1,1,1,2,2,0,0,0,0,0,0,0,0,0,0,0,2,2,1,1,1
1,1,1,1,1,1,1,2,2,0,0,0,2,2,1,1,1,1,1,1,1
1,1,1,1,1,1,1,2,2,0,0,0,2,2,1,1,1,1,1,1,1
1,1,1,1,1,1,1,1,1,1,1,1,1,1,1,1,1,1,1,1,1
endlayer

layer
1,1,1,1,1,1,1,1,1,1,1,1,1,1,1,1,1,1,1,1,1
1,1,1,1,1,1,1,3,3,0,0,0,3,3,1,1,1,1,1,1,1
1,1,1,1,1,1,1,3,3,0,0,0,3,3,1,1,1,1,1,1,1
1,1,1,3,3,0,0,0,0,0,0,0,0,0,0,0,3,3,1,1,1
1,1,1,3,3,0,0,0,0,0,0,0,0,0,0,0,3,3,1,1,1
1,1,1,0,0,0,0,0,0,0,0,0,0,0,0,0,0,0,1,1,1
1,1,1,0,0,0,0,0,0,0,0,0,0,0,0,0,0,0,1,1,1
1,3,3,0,0,0,0,0,0,0,0,0,0,0,0,0,0,0,3,3,1
1,3,3,0,0,0,0,0,0,0,0,0,0,0,0,0,0,0,3,3,1
1,0,0,0,0,0,0,0,0,0,0,0,0,0,0,0,0,0,0,0,1
1,0,0,0,0,0,0,0,0,0,0,0,0,0,0,0,0,0,0,0,1
1,0,0,0,0,0,0,0,0,0,0,0,0,0,0,0,0,0,0,0,1
1,3,3,0,0,0,0,0,0,0,0,0,0,0,0,0,0,0,3,3,1
1,3,3,0,0,0,0,0,0,0,0,0,0,0,0,0,0,0,3,3,1
1,1,1,0,0,0,0,0,0,0,0,0,0,0,0,0,0,0,1,1,1
1,1,1,0,0,0,0,0,0,0,0,0,0,0,0,0,0,0,1,1,1
1,1,1,3,3,0,0,0,0,0,0,0,0,0,0,0,3,3,1,1,1
1,1,1,3,3,0,0,0,0,0,0,0,0,0,0,0,3,3,1,1,1
1,1,1,1,1,1,1,3,3,0,0,0,3,3,1,1,1,1,1,1,1
1,1,1,1,1,1,1,3,3,0,0,0,3,3,1,1,1,1,1,1,1
1,1,1,1,1,1,1,1,1,1,1,1,1,1,1,1,1,1,1,1,1
endlayer

layer
1,1,1,1,1,1,1,13,13,13,13,13,13,13,1,1,1,1,1,1,1
1,1,1,1,13,13,13,13,13,13,13,13,13,13,13,13,13,1,1,1,1
1,1,13,13,13,13,13,13,13,2,2,2,13,13,13,13,13,13,13,1,1
1,1,13,13,13,2,2,13,13,13,13,13,13,13,2,2,13,13,13,1,1
1,13,13,13,13,13,13,13,13,13,13,13,13,13,13,13,13,13,13,13,1
1,13,13,2,13,13,13,13,13,0,0,0,13,13,13,13,13,2,13,13,1
1,13,13,2,13,13,13,0,0,0,0,0,0,0,13,13,13,2,13,13,1
13,13,13,13,13,13,0,0,0,0,0,0,0,0,0,13,13,13,13,13,13
13,13,13,13,13,13,0,0,0,0,0,0,0,0,0,13,13,13,13,13,13
13,13,2,13,13,0,0,0,0,0,0,0,0,0,0,0,13,13,2,13,13
13,13,2,13,13,0,0,0,0,0,0,0,0,0,0,0,13,13,2,13,13
13,13,2,13,13,0,0,0,0,0,0,0,0,0,0,0,13,13,2,13,13
13,13,13,13,13,13,0,0,0,0,0,0,0,0,0,13,13,13,13,13,13
13,13,13,13,13,13,0,0,0,0,0,0,0,0,0,13,13,13,13,13,13
1,13,13,2,13,13,13,0,0,0,0,0,0,0,13,13,13,2,13,13,1
1,13,13,2,13,13,13,13,13,0,0,0,13,13,13,13,13,2,13,13,1
1,13,13,13,13,13,13,13,13,13,13,13,13,13,13,13,13,13,13,13,1
1,1,13,13,13,2,2,13,13,13,13,13,13,13,2,2,13,13,13,1,1
1,1,13,13,13,13,13,13,13,2,2,2,13,13,13,13,13,13,13,1,1
1,1,1,1,13,13,13,13,13,13,13,13,13,13,13,13,13,1,1,1,1
1,1,1,1,1,1,1,13,13,13,13,13,13,13,1,1,1,1,1,1,1
endlayer

layer
1,1,1,1,1,1,1,1,13,13,14,13,13,1,1,1,1,1,1,1,1
1,1,1,1,1,1,1,13,13,13,13,13,13,13,1,1,1,1,1,1,1
1,1,1,1,13,13,13,13,13,13,13,13,13,13,13,13,13,1,1,1,1
1,1,1,13,13,13,13,13,13,13,13,13,13,13,13,13,13,13,1,1,1
1,1,13,13,13,13,13,13,13,13,14,13,13,13,13,13,13,13,13,1,1
1,1,13,13,13,13,13,0,0,0,0,0,0,0,13,13,13,13,13,1,1
1,1,13,13,13,13,0,0,0,0,0,0,0,0,0,13,13,13,13,1,1
1,13,13,13,13,0,0,0,0,0,0,0,0,0,0,0,13,13,13,13,1
13,13,13,13,13,0,0,0,0,0,0,0,0,0,0,0,13,13,13,13,13
13,13,13,13,13,0,0,0,0,0,0,0,0,0,0,0,13,13,13,13,13
14,13,13,13,14,0,0,0,0,0,0,0,0,0,0,0,14,13,13,13,14
13,13,13,13,13,0,0,0,0,0,0,0,0,0,0,0,13,13,13,13,13
13,13,13,13,13,0,0,0,0,0,0,0,0,0,0,0,13,13,13,13,13
1,13,13,13,13,0,0,0,0,0,0,0,0,0,0,0,13,13,13,13,1
1,1,13,13,13,13,0,0,0,0,0,0,0,0,0,13,13,13,13,1,1
1,1,13,13,13,13,13,0,0,0,0,0,0,0,13,13,13,13,13,1,1
1,1,13,13,13,13,13,13,13,13,14,13,13,13,13,13,13,13,13,1,1
1,1,1,13,13,13,13,13,13,13,13,13,13,13,13,13,13,13,1,1,1
1,1,1,1,13,13,13,13,13,13,13,13,13,13,13,13,13,1,1,1,1
1,1,1,1,1,1,1,13,13,13,13,13,13,13,1,1,1,1,1,1,1
1,1,1,1,1,1,1,1,13,13,14,13,13,1,1,1,1,1,1,1,1
endlayer

layer
1,1,1,1,1,1,1,1,1,13,13,13,1,1,1,1,1,1,1,1,1
1,1,1,1,1,1,1,1,1,13,13,13,1,1,1,1,1,1,1,1,1
1,1,1,1,1,1,1,1,3,13,13,13,3,1,1,1,1,1,1,1,1
1,1,1,1,1,1,1,1,0,13,13,13,0,1,1,1,1,1,1,1,1
1,1,1,1,3,0,0,0,0,13,13,13,0,0,0,0,3,1,1,1,1
1,1,1,1,0,0,0,0,0,0,0,0,0,0,0,0,0,1,1,1,1
1,1,1,1,0,0,0,0,0,0,0,0,0,0,0,0,0,1,1,1,1
1,1,1,1,0,0,0,0,0,0,0,0,0,0,0,0,0,1,1,1,1
1,1,3,0,0,0,0,0,0,0,0,0,0,0,0,0,0,0,3,1,1
13,13,13,13,13,0,0,0,0,0,0,0,0,0,0,0,13,13,13,13,13
13,13,13,13,13,0,0,0,0,0,0,0,0,0,0,0,13,13,13,13,13
13,13,13,13,13,0,0,0,0,0,0,0,0,0,0,0,13,13,13,13,13
1,1,3,0,0,0,0,0,0,0,0,0,0,0,0,0,0,0,3,1,1
1,1,1,1,0,0,0,0,0,0,0,0,0,0,0,0,0,1,1,1,1
1,1,1,1,0,0,0,0,0,0,0,0,0,0,0,0,0,1,1,1,1
1,1,1,1,0,0,0,0,0,0,0,0,0,0,0,0,0,1,1,1,1
1,1,1,1,3,0,0,0,0,13,13,13,0,0,0,0,3,1,1,1,1
1,1,1,1,1,1,1,1,0,13,13,13,0,1,1,1,1,1,1,1,1
1,1,1,1,1,1,1,1,3,13,13,13,3,1,1,1,1,1,1,1,1
1,1,1,1,1,1,1,1,1,13,13,13,1,1,1,1,1,1,1,1,1
1,1,1,1,1,1,1,1,1,13,13,13,1,1,1,1,1,1,1,1,1
endlayer

layer
1,1,1,1,1,1,1,1,1,1,13,1,1,1,1,1,1,1,1,1,1
1,1,1,1,1,1,1,1,1,1,13,1,1,1,1,1,1,1,1,1,1
1,1,1,1,1,1,1,1,3,0,13,0,3,1,1,1,1,1,1,1,1
1,1,1,1,1,1,1,1,0,0,13,0,0,1,1,1,1,1,1,1,1
1,1,1,1,3,0,0,0,0,0,13,0,0,0,0,0,3,1,1,1,1
1,1,1,1,0,0,0,0,0,0,0,0,0,0,0,0,0,1,1,1,1
1,1,1,1,0,0,0,0,0,0,0,0,0,0,0,0,0,1,1,1,1
1,1,1,1,0,0,0,0,0,0,0,0,0,0,0,0,0,1,1,1,1
1,1,3,0,0,0,0,0,0,0,0,0,0,0,0,0,0,0,3,1,1
1,1,0,0,0,0,0,0,0,0,0,0,0,0,0,0,0,0,0,1,1
13,13,13,13,13,0,0,0,0,0,0,0,0,0,0,0,13,13,13,13,13
1,1,0,0,0,0,0,0,0,0,0,0,0,0,0,0,0,0,0,1,1
1,1,3,0,0,0,0,0,0,0,0,0,0,0,0,0,0,0,3,1,1
1,1,1,1,0,0,0,0,0,0,0,0,0,0,0,0,0,1,1,1,1
1,1,1,1,0,0,0,0,0,0,0,0,0,0,0,0,0,1,1,1,1
1,1,1,1,0,0,0,0,0,0,0,0,0,0,0,0,0,1,1,1,1
1,1,1,1,3,0,0,0,0,0,13,0,0,0,0,0,3,1,1,1,1
1,1,1,1,1,1,1,1,0,0,13,0,0,1,1,1,1,1,1,1,1
1,1,1,1,1,1,1,1,3,0,13,0,3,1,1,1,1,1,1,1,1
1,1,1,1,1,1,1,1,1,1,13,1,1,1,1,1,1,1,1,1,1
1,1,1,1,1,1,1,1,1,1,13,1,1,1,1,1,1,1,1,1,1
endlayer

layer
1,1,1,1,1,1,1,1,1,1,1,1,1,1,1,1,1,1,1,1,1
1,1,1,1,1,1,1,1,1,1,1,1,1,1,1,1,1,1,1,1,1
1,1,1,1,1,1,1,1,3,0,0,0,3,1,1,1,1,1,1,1,1
1,1,1,1,1,1,1,1,0,0,0,0,0,1,1,1,1,1,1,1,1
1,1,1,1,3,0,0,0,0,0,0,0,0,0,0,0,3,1,1,1,1
1,1,1,1,0,0,0,0,0,0,0,0,0,0,0,0,0,1,1,1,1
1,1,1,1,0,0,0,0,0,0,0,0,0,0,0,0,0,1,1,1,1
1,1,1,1,0,0,0,0,0,0,0,0,0,0,0,0,0,1,1,1,1
1,1,3,0,0,0,0,0,0,0,0,0,0,0,0,0,0,0,3,1,1
1,1,0,0,0,0,0,0,0,0,0,0,0,0,0,0,0,0,0,1,1
1,1,0,0,0,0,0,0,0,0,0,0,0,0,0,0,0,0,0,1,1
1,1,0,0,0,0,0,0,0,0,0,0,0,0,0,0,0,0,0,1,1
1,1,3,0,0,0,0,0,0,0,0,0,0,0,0,0,0,0,3,1,1
1,1,1,1,0,0,0,0,0,0,0,0,0,0,0,0,0,1,1,1,1
1,1,1,1,0,0,0,0,0,0,0,0,0,0,0,0,0,1,1,1,1
1,1,1,1,0,0,0,0,0,0,0,0,0,0,0,0,0,1,1,1,1
1,1,1,1,3,0,0,0,0,0,0,0,0,0,0,0,3,1,1,1,1
1,1,1,1,1,1,1,1,0,0,0,0,0,1,1,1,1,1,1,1,1
1,1,1,1,1,1,1,1,3,0,0,0,3,1,1,1,1,1,1,1,1
1,1,1,1,1,1,1,1,1,1,1,1,1,1,1,1,1,1,1,1,1
1,1,1,1,1,1,1,1,1,1,1,1,1,1,1,1,1,1,1,1,1
endlayer

layer
1,1,1,1,1,1,1,1,1,1,1,1,1,1,1,1,1,1,1,1,1
1,1,1,1,1,1,1,1,1,1,1,1,1,1,1,1,1,1,1,1,1
1,1,1,1,1,1,1,1,2,0,0,0,2,1,1,1,1,1,1,1,1
1,1,1,1,1,1,1,1,0,0,0,0,0,1,1,1,1,1,1,1,1
1,1,1,1,2,0,0,0,0,0,0,0,0,0,0,0,2,1,1,1,1
1,1,1,1,0,0,0,0,0,0,0,0,0,0,0,0,0,1,1,1,1
1,1,1,1,0,0,0,0,0,0,0,0,0,0,0,0,0,1,1,1,1
1,1,1,1,0,0,0,0,0,0,0,0,0,0,0,0,0,1,1,1,1
1,1,2,0,0,0,0,0,0,0,0,0,0,0,0,0,0,0,2,1,1
1,1,0,0,0,0,0,0,0,0,0,0,0,0,0,0,0,0,0,1,1
1,1,0,0,0,0,0,0,0,0,0,0,0,0,0,0,0,0,0,1,1
1,1,0,0,0,0,0,0,0,0,0,0,0,0,0,0,0,0,0,1,1
1,1,2,0,0,0,0,0,0,0,0,0,0,0,0,0,0,0,2,1,1
1,1,1,1,0,0,0,0,0,0,0,0,0,0,0,0,0,1,1,1,1
1,1,1,1,0,0,0,0,0,0,0,0,0,0,0,0,0,1,1,1,1
1,1,1,1,0,0,0,0,0,0,0,0,0,0,0,0,0,1,1,1,1
1,1,1,1,2,0,0,0,0,0,0,0,0,0,0,0,2,1,1,1,1
1,1,1,1,1,1,1,1,0,0,0,0,0,1,1,1,1,1,1,1,1
1,1,1,1,1,1,1,1,2,0,0,0,2,1,1,1,1,1,1,1,1
1,1,1,1,1,1,1,1,1,1,1,1,1,1,1,1,1,1,1,1,1
1,1,1,1,1,1,1,1,1,1,1,1,1,1,1,1,1,1,1,1,1
endlayer

layer
1,1,1,1,1,1,1,1,1,1,1,1,1,1,1,1,1,1,1,1,1
1,1,1,1,1,1,1,1,1,1,1,1,1,1,1,1,1,1,1,1,1
1,1,1,1,1,1,1,1,3,0,0,0,3,1,1,1,1,1,1,1,1
1,1,1,1,1,1,1,1,0,0,0,0,0,1,1,1,1,1,1,1,1
1,1,1,1,3,0,0,0,0,0,0,0,0,0,0,0,3,1,1,1,1
1,1,1,1,0,0,0,0,0,0,0,0,0,0,0,0,0,1,1,1,1
1,1,1,1,0,0,0,0,0,0,0,0,0,0,0,0,0,1,1,1,1
1,1,1,1,0,0,0,0,0,0,0,0,0,0,0,0,0,1,1,1,1
1,1,3,0,0,0,0,0,0,0,0,0,0,0,0,0,0,0,3,1,1
1,1,0,0,0,0,0,0,0,0,0,0,0,0,0,0,0,0,0,1,1
1,1,0,0,0,0,0,0,0,0,0,0,0,0,0,0,0,0,0,1,1
1,1,0,0,0,0,0,0,0,0,0,0,0,0,0,0,0,0,0,1,1
1,1,3,0,0,0,0,0,0,0,0,0,0,0,0,0,0,0,3,1,1
1,1,1,1,0,0,0,0,0,0,0,0,0,0,0,0,0,1,1,1,1
1,1,1,1,0,0,0,0,0,0,0,0,0,0,0,0,0,1,1,1,1
1,1,1,1,0,0,0,0,0,0,0,0,0,0,0,0,0,1,1,1,1
1,1,1,1,3,0,0,0,0,0,0,0,0,0,0,0,3,1,1,1,1
1,1,1,1,1,1,1,1,0,0,0,0,0,1,1,1,1,1,1,1,1
1,1,1,1,1,1,1,1,3,0,0,0,3,1,1,1,1,1,1,1,1
1,1,1,1,1,1,1,1,1,1,1,1,1,1,1,1,1,1,1,1,1
1,1,1,1,1,1,1,1,1,1,1,1,1,1,1,1,1,1,1,1,1
endlayer

layer
1,1,1,1,1,1,1,1,1,1,1,1,1,1,1,1,1,1,1,1,1
1,1,1,1,1,1,1,1,13,13,13,13,13,1,1,1,1,1,1,1,1
1,1,1,1,1,13,13,13,13,13,13,13,13,13,13,13,1,1,1,1,1
1,1,1,1,13,13,13,13,13,13,13,13,13,13,13,13,13,1,1,1,1
1,1,1,13,13,13,13,13,0,0,0,0,0,13,13,13,13,13,1,1,1
1,1,13,13,13,13,0,0,0,0,0,0,0,0,0,13,13,13,13,1,1
1,1,13,13,13,0,0,0,0,0,0,0,0,0,0,0,13,13,13,1,1
1,1,13,13,13,0,0,0,0,0,0,0,0,0,0,0,13,13,13,1,1
1,13,13,13,0,0,0,0,0,0,0,0,0,0,0,0,0,13,13,13,1
1,13,13,13,0,0,0,0,0,0,0,0,0,0,0,0,0,13,13,13,1
1,13,13,13,0,0,0,0,0,0,0,0,0,0,0,0,0,13,13,13,1
1,13,13,13,0,0,0,0,0,0,0,0,0,0,0,0,0,13,13,13,1
1,13,13,13,0,0,0,0,0,0,0,0,0,0,0,0,0,13,13,13,1
1,1,13,13,13,0,0,0,0,0,0,0,0,0,0,0,13,13,13,1,1
1,1,13,13,13,0,0,0,0,0,0,0,0,0,0,0,13,13,13,1,1
1,1,13,13,13,13,0,0,0,0,0,0,0,0,0,13,13,13,13,1,1
1,1,1,13,13,13,13,13,0,0,0,0,0,13,13,13,13,13,1,1,1
1,1,1,1,13,13,13,13,13,13,13,13,13,13,13,13,13,1,1,1,1
1,1,1,1,1,13,13,13,13,13,13,13,13,13,13,13,1,1,1,1,1
1,1,1,1,1,1,1,1,13,13,13,13,13,1,1,1,1,1,1,1,1
1,1,1,1,1,1,1,1,1,1,1,1,1,1,1,1,1,1,1,1,1
endlayer

layer
1,1,1,1,1,1,1,1,1,1,1,1,1,1,1,1,1,1,1,1,1
1,1,1,1,1,1,1,1,1,1,1,1,1,1,1,1,1,1,1,1,1
1,1,1,1,1,1,1,1,13,13,13,13,13,1,1,1,1,1,1,1,1
1,1,1,1,1,1,13,13,0,0,0,0,0,13,13,1,1,1,1,1,1
1,1,1,1,1,13,0,0,0,0,0,0,0,0,0,13,1,1,1,1,1
1,1,1,1,13,0,0,0,0,0,0,0,0,0,0,0,13,1,1,1,1
1,1,1,13,0,0,0,0,0,0,0,0,0,0,0,0,0,13,1,1,1
1,1,1,13,0,0,0,0,0,0,0,0,0,0,0,0,0,13,1,1,1
1,1,13,0,0,0,0,0,0,0,0,0,0,0,0,0,0,0,13,1,1
1,1,13,0,0,0,0,0,0,0,0,0,0,0,0,0,0,0,13,1,1
1,1,13,0,0,0,0,0,0,0,0,0,0,0,0,0,0,0,13,1,1
1,1,13,0,0,0,0,0,0,0,0,0,0,0,0,0,0,0,13,1,1
1,1,13,0,0,0,0,0,0,0,0,0,0,0,0,0,0,0,13,1,1
1,1,1,13,0,0,0,0,0,0,0,0,0,0,0,0,0,13,1,1,1
1,1,1,13,0,0,0,0,0,0,0,0,0,0,0,0,0,13,1,1,1
1,1,1,1,13,0,0,0,0,0,0,0,0,0,0,0,13,1,1,1,1
1,1,1,1,1,13,0,0,0,0,0,0,0,0,0,13,1,1,1,1,1
1,1,1,1,1,1,13,13,0,0,0,0,0,13,13,1,1,1,1,1,1
1,1,1,1,1,1,1,1,13,13,13,13,13,1,1,1,1,1,1,1,1
1,1,1,1,1,1,1,1,1,1,1,1,1,1,1,1,1,1,1,1,1
1,1,1,1,1,1,1,1,1,1,1,1,1,1,1,1,1,1,1,1,1
endlayer

