
# Created by Ruins mod version 17.0 Ingame Parser
# authoring Player: ST753M

weight=1
uniqueMinDistance=1000
embed_into_distance=4
acceptable_target_blocks=
unacceptable_target_blocks=flowing_water,water,flowing_lava,lava,ice,bedrock,netherrack,nether_brick,nether_brick_fence,soul_sand,quartz_ore,end_stone,obsidian,iron_bars,Natura:Cloud,slime_grass,slime_congealed,slime_dirt,clouds,natura:clouds
dimensions=14,28,28
allowable_overhang=16
max_leveling=2
leveling_buffer=0
preserve_water=0
preserve_lava=0

biomesToSpawnIn=ice_flats,ice_mountains,glacier,mutated_ice_flats,cold_beach,cold_desert,ice_mountains,glacier,glacier_spikes,ice_plains_defiled

=0,100,air
rule1=0,100,preserveBlock
rule2=0,100,quark:biome_cobblestone-1
rule3=0,100,minecraft:packed_ice-0
rule4=0,100,quark:icy_stone_stairs-5
rule5=0,100,minecraft:tripwire_hook-4
rule6=0,100,minecraft:tripwire-4
rule7=0,100,minecraft:tripwire_hook-6
rule8=0,100,minecraft:tripwire_hook-7
rule9=0,100,quark:icy_stone_wall-0
rule10=0,100,quark:icy_stone_stairs-7
rule11=0,100,quark:icy_stone_stairs-6
rule12=0,100,minecraft:tripwire_hook-5
rule13=0,100,quark:icy_stone_stairs-4
rule14=0,100,IInventory;minecraft:chest;minecraft:redstone#4#0#11+minecraft:iron_chestplate#{"Quark:RuneColor":3,ench:[{lvl:2s,id:1s},{lvl:1s,id:7s}],RepairCost:3,display:{Name:"Cold Iron Chestplate"},"Quark:RuneAttached":1b}#0#14+minecraft:ice#8#0#25-5
rule15=0,100,IInventory;minecraft:dispenser;minecraft:splash_potion#{Potion:"minecraft:slowness"}#0#0+minecraft:splash_potion#{Potion:"minecraft:slowness"}#0#1-2
rule16=0,100,MobSpawner:witch,MobSpawner:stray,MobSpawner:stray,MobSpawner:silverfish
rule17=0,100,IInventory;minecraft:dispenser;minecraft:splash_potion#{Potion:"minecraft:slowness"}#0#0+minecraft:splash_potion#{Potion:"minecraft:slowness"}#0#1-5
rule18=0,100,IInventory;minecraft:chest;minecraft:iron_helmet#{"Quark:RuneColor":3,ench:[{lvl:2s,id:1s},{lvl:1s,id:7s}],RepairCost:3,display:{Name:"Cold Iron Helmet"},"Quark:RuneAttached":1b}#0#10+minecraft:gold_ingot#2#0#15+minecraft:skull#1#0#20-3
rule19=0,100,IInventory;minecraft:chest;minecraft:book#3#0#7+minecraft:bucket#2#0#11+minecraft:iron_boots#{"Quark:RuneColor":3,ench:[{lvl:2s,id:1s},{lvl:1s,id:7s}],RepairCost:3,display:{Name:"Cold Iron Boots"},"Quark:RuneAttached":1b}#0#23-2
rule20=0,100,IInventory;minecraft:dispenser;minecraft:splash_potion#{Potion:"minecraft:slowness"}#0#0+minecraft:splash_potion#{Potion:"minecraft:slowness"}#0#1-4
rule21=0,100,IInventory;minecraft:dispenser;minecraft:splash_potion#{Potion:"minecraft:slowness"}#0#0+minecraft:splash_potion#{Potion:"minecraft:slowness"}#0#1-3
rule22=0,100,IInventory;minecraft:chest;minecraft:slime_ball#2#0#4+minecraft:iron_leggings#{"Quark:RuneColor":3,ench:[{lvl:2s,id:1s},{lvl:1s,id:7s}],RepairCost:3,display:{Name:"Cold Iron Leggings"},"Quark:RuneAttached":1b}#0#16+minecraft:dye#3#4#21-4
rule23=0,100,quark:icy_stone_slab-8
rule24=0,100,quark:icy_stone_stairs-0
rule25=0,100,quark:icy_stone_slab-0
rule26=0,100,quark:icy_stone_stairs-2
rule27=0,100,quark:icy_stone_stairs-3
rule28=0,100,quark:icy_stone_stairs-1
rule29=0,100,minecraft:ice-0

layer
1,1,1,1,1,1,1,1,1,1,1,1,1,2,2,1,1,1,1,1,1,1,1,1,1,1,1,1
1,1,1,1,1,1,1,1,1,1,1,1,2,2,2,2,1,1,1,1,1,1,1,1,1,1,1,1
1,1,1,1,1,1,1,1,1,1,1,2,2,2,2,2,2,1,1,1,1,1,1,1,1,1,1,1
1,1,1,1,1,1,1,1,1,1,1,2,2,2,2,2,2,1,1,1,1,1,1,1,1,1,1,1
1,1,1,1,1,1,1,1,1,1,2,2,2,2,2,2,2,2,1,1,1,1,1,1,1,1,1,1
1,1,1,1,1,1,1,1,1,1,2,2,2,2,2,2,2,2,1,1,1,1,1,1,1,1,1,1
1,1,1,1,1,1,1,1,1,1,2,2,2,2,2,2,2,2,1,1,1,1,1,1,1,1,1,1
1,1,1,1,1,1,1,1,1,2,2,2,2,2,2,2,2,2,2,1,1,1,1,1,1,1,1,1
1,1,1,1,1,1,1,1,1,2,2,2,2,2,2,2,2,2,2,1,1,1,1,1,1,1,1,1
1,1,1,1,1,1,1,2,2,2,2,3,2,2,2,2,3,2,2,2,2,1,1,1,1,1,1,1
1,1,1,1,2,2,2,2,2,2,2,2,2,2,2,2,2,2,2,2,2,2,2,2,1,1,1,1
1,1,2,2,2,2,2,2,2,3,2,2,2,2,2,2,2,2,3,2,2,2,2,2,2,2,1,1
1,2,2,2,2,2,2,2,2,2,2,2,2,2,2,2,2,2,2,2,2,2,2,2,2,2,2,1
2,2,2,2,2,2,2,2,2,2,2,2,2,2,2,2,2,2,2,2,2,2,2,2,2,2,2,2
2,2,2,2,2,2,2,2,2,2,2,2,2,2,2,2,2,2,2,2,2,2,2,2,2,2,2,2
1,2,2,2,2,2,2,2,2,2,2,2,2,2,2,2,2,2,2,2,2,2,2,2,2,2,2,1
1,1,2,2,2,2,2,2,2,3,2,2,2,2,2,2,2,2,2,2,2,2,2,2,2,2,1,1
1,1,1,1,2,2,2,2,2,2,2,2,2,2,2,2,2,2,2,2,2,2,2,2,1,1,1,1
1,1,1,1,1,1,1,2,2,2,2,3,2,2,2,2,3,2,2,2,2,1,1,1,1,1,1,1
1,1,1,1,1,1,1,1,1,2,2,2,2,2,2,2,2,2,2,1,1,1,1,1,1,1,1,1
1,1,1,1,1,1,1,1,1,2,2,2,2,2,2,2,2,2,2,1,1,1,1,1,1,1,1,1
1,1,1,1,1,1,1,1,1,1,2,2,2,2,2,2,2,2,1,1,1,1,1,1,1,1,1,1
1,1,1,1,1,1,1,1,1,1,2,2,2,2,2,2,2,2,1,1,1,1,1,1,1,1,1,1
1,1,1,1,1,1,1,1,1,1,2,2,2,2,2,2,2,2,1,1,1,1,1,1,1,1,1,1
1,1,1,1,1,1,1,1,1,1,1,2,2,2,2,2,2,1,1,1,1,1,1,1,1,1,1,1
1,1,1,1,1,1,1,1,1,1,1,2,2,2,2,2,2,1,1,1,1,1,1,1,1,1,1,1
1,1,1,1,1,1,1,1,1,1,1,1,2,2,2,2,1,1,1,1,1,1,1,1,1,1,1,1
1,1,1,1,1,1,1,1,1,1,1,1,1,2,2,1,1,1,1,1,1,1,1,1,1,1,1,1
endlayer

layer
1,1,1,1,1,1,1,1,1,1,1,1,2,2,2,2,1,1,1,1,1,1,1,1,1,1,1,1
1,1,1,1,1,1,1,1,1,1,1,2,2,4,4,2,2,1,1,1,1,1,1,1,1,1,1,1
1,1,1,1,1,1,1,1,1,1,1,2,0,0,0,0,2,1,1,1,1,1,1,1,1,1,1,1
1,1,1,1,1,1,1,1,1,1,2,0,0,0,0,0,0,2,1,1,1,1,1,1,1,1,1,1
1,1,1,1,1,1,1,1,1,1,2,0,0,0,0,0,0,2,1,1,1,1,1,1,1,1,1,1
1,1,1,1,1,1,1,1,1,1,2,0,0,0,0,0,0,2,1,1,1,1,1,1,1,1,1,1
1,1,1,1,1,1,1,1,1,2,2,0,0,0,0,0,0,2,2,1,1,1,1,1,1,1,1,1
1,1,1,1,1,1,1,1,1,2,2,0,0,0,0,0,0,2,2,1,1,1,1,1,1,1,1,1
1,1,1,1,1,1,1,1,2,7,6,6,6,6,6,6,6,5,2,2,1,1,1,1,1,1,1,1
1,1,1,1,1,1,2,2,8,2,2,2,0,0,0,0,2,2,2,2,2,2,1,1,1,1,1,1
1,1,1,2,2,2,2,2,6,2,9,0,0,0,0,0,0,9,2,8,2,2,2,2,2,1,1,1
1,2,2,0,0,0,0,0,6,2,0,0,0,0,0,0,0,0,2,6,0,0,0,0,0,2,2,1
2,2,0,0,0,0,0,0,6,0,0,0,0,0,0,0,0,0,0,6,0,0,0,0,0,0,2,2
2,11,0,0,0,0,0,0,6,0,0,0,0,0,0,0,0,0,0,6,0,0,0,0,0,0,10,2
2,11,0,0,0,0,0,0,6,0,0,0,0,0,0,0,0,0,0,6,0,0,0,0,0,0,10,2
2,2,0,0,0,0,0,0,6,0,0,0,0,0,0,0,0,0,0,6,0,0,0,0,0,0,2,2
1,2,2,0,0,0,0,0,6,2,0,0,0,0,0,0,0,0,2,6,0,0,0,0,0,2,2,1
1,1,1,2,2,2,2,2,12,2,9,0,0,0,0,0,0,9,2,6,2,2,2,2,2,1,1,1
1,1,1,1,1,1,2,2,2,2,2,2,0,0,0,0,2,2,2,12,2,2,1,1,1,1,1,1
1,1,1,1,1,1,1,1,2,2,7,6,6,6,6,6,6,6,5,2,1,1,1,1,1,1,1,1
1,1,1,1,1,1,1,1,1,2,2,0,0,0,0,0,0,2,2,1,1,1,1,1,1,1,1,1
1,1,1,1,1,1,1,1,1,2,2,0,0,0,0,0,0,2,2,1,1,1,1,1,1,1,1,1
1,1,1,1,1,1,1,1,1,1,2,0,0,0,0,0,0,2,1,1,1,1,1,1,1,1,1,1
1,1,1,1,1,1,1,1,1,1,2,0,0,0,0,0,0,2,1,1,1,1,1,1,1,1,1,1
1,1,1,1,1,1,1,1,1,1,2,0,0,0,0,0,0,2,1,1,1,1,1,1,1,1,1,1
1,1,1,1,1,1,1,1,1,1,1,2,0,0,0,0,2,1,1,1,1,1,1,1,1,1,1,1
1,1,1,1,1,1,1,1,1,1,1,2,2,13,13,2,2,1,1,1,1,1,1,1,1,1,1,1
1,1,1,1,1,1,1,1,1,1,1,1,2,2,2,2,1,1,1,1,1,1,1,1,1,1,1,1
endlayer

layer
1,1,1,1,1,1,1,1,1,1,1,1,2,9,9,2,1,1,1,1,1,1,1,1,1,1,1,1
1,1,1,1,1,1,1,1,1,1,1,2,2,14,0,2,2,1,1,1,1,1,1,1,1,1,1,1
1,1,1,1,1,1,1,1,1,1,1,2,0,0,0,0,2,1,1,1,1,1,1,1,1,1,1,1
1,1,1,1,1,1,1,1,1,1,2,0,0,0,0,0,0,2,1,1,1,1,1,1,1,1,1,1
1,1,1,1,1,1,1,1,1,1,2,0,0,0,0,0,0,2,1,1,1,1,1,1,1,1,1,1
1,1,1,1,1,1,1,1,1,1,9,0,0,0,0,0,0,9,1,1,1,1,1,1,1,1,1,1
1,1,1,1,1,1,1,1,1,2,2,0,0,0,0,0,0,2,2,1,1,1,1,1,1,1,1,1
1,1,1,1,1,1,1,1,1,2,2,0,0,0,0,0,0,2,2,1,1,1,1,1,1,1,1,1
1,1,1,1,1,1,1,1,2,15,0,0,0,0,0,0,0,2,2,2,1,1,1,1,1,1,1,1
1,1,1,1,1,1,2,2,17,2,2,2,0,0,0,0,2,2,16,2,2,2,1,1,1,1,1,1
1,1,1,2,2,9,2,2,0,2,9,0,0,0,0,0,0,9,2,2,2,2,9,2,2,1,1,1
1,2,2,0,0,0,0,0,0,2,0,0,0,0,0,0,0,0,2,0,0,0,0,0,0,2,2,1
2,2,0,0,0,0,0,0,0,0,0,0,0,0,0,0,0,0,0,0,0,0,0,0,0,0,2,2
9,0,0,0,0,0,0,0,0,0,0,0,0,0,0,0,0,0,0,0,0,0,0,0,0,0,0,9
9,19,0,0,0,0,0,0,0,0,0,0,0,0,0,0,0,0,0,0,0,0,0,0,0,0,18,9
2,2,0,0,0,0,0,0,0,0,0,0,0,0,0,0,0,0,0,0,0,0,0,0,0,0,2,2
1,2,2,0,0,0,0,0,0,2,0,0,0,0,0,0,0,0,2,0,0,0,0,0,0,2,2,1
1,1,1,2,2,9,2,2,2,2,9,0,0,0,0,0,0,9,2,0,2,2,9,2,2,1,1,1
1,1,1,1,1,1,2,2,2,16,2,2,0,0,0,0,2,2,2,20,2,2,1,1,1,1,1,1
1,1,1,1,1,1,1,1,2,2,2,0,0,0,0,0,0,0,21,2,1,1,1,1,1,1,1,1
1,1,1,1,1,1,1,1,1,2,2,0,0,0,0,0,0,2,2,1,1,1,1,1,1,1,1,1
1,1,1,1,1,1,1,1,1,2,2,0,0,0,0,0,0,2,2,1,1,1,1,1,1,1,1,1
1,1,1,1,1,1,1,1,1,1,9,0,0,0,0,0,0,9,1,1,1,1,1,1,1,1,1,1
1,1,1,1,1,1,1,1,1,1,2,0,0,0,0,0,0,2,1,1,1,1,1,1,1,1,1,1
1,1,1,1,1,1,1,1,1,1,2,0,0,0,0,0,0,2,1,1,1,1,1,1,1,1,1,1
1,1,1,1,1,1,1,1,1,1,1,2,0,0,0,0,2,1,1,1,1,1,1,1,1,1,1,1
1,1,1,1,1,1,1,1,1,1,1,2,2,0,22,2,2,1,1,1,1,1,1,1,1,1,1,1
1,1,1,1,1,1,1,1,1,1,1,1,2,9,9,2,1,1,1,1,1,1,1,1,1,1,1,1
endlayer

layer
1,1,1,1,1,1,1,1,1,1,1,1,2,2,2,2,1,1,1,1,1,1,1,1,1,1,1,1
1,1,1,1,1,1,1,1,1,1,1,2,2,11,10,2,2,1,1,1,1,1,1,1,1,1,1,1
1,1,1,1,1,1,1,1,1,1,1,2,11,0,0,10,2,1,1,1,1,1,1,1,1,1,1,1
1,1,1,1,1,1,1,1,1,1,2,11,0,0,0,0,10,2,1,1,1,1,1,1,1,1,1,1
1,1,1,1,1,1,1,1,1,1,9,0,0,0,0,0,0,9,1,1,1,1,1,1,1,1,1,1
1,1,1,1,1,1,1,1,1,1,9,0,0,0,0,0,0,9,1,1,1,1,1,1,1,1,1,1
1,1,1,1,1,1,1,1,1,2,2,0,0,0,0,0,0,2,2,1,1,1,1,1,1,1,1,1
1,1,1,1,1,1,1,1,1,2,2,0,0,0,0,0,0,2,2,1,1,1,1,1,1,1,1,1
1,1,1,1,1,1,1,1,2,2,2,11,0,0,0,0,10,2,2,2,1,1,1,1,1,1,1,1
1,1,1,1,1,1,2,2,2,2,2,2,11,23,23,10,2,2,2,2,2,2,1,1,1,1,1,1
1,1,1,2,9,9,2,2,2,2,2,11,0,0,0,0,10,2,2,2,2,2,9,9,2,1,1,1
1,2,2,4,0,0,0,0,4,2,4,0,0,0,0,0,0,4,2,4,0,0,0,0,4,2,2,1
2,2,4,0,0,0,0,0,0,4,0,0,0,0,0,0,0,0,4,0,0,0,0,0,0,4,2,2
2,4,0,0,0,0,0,0,0,23,0,0,0,0,0,0,0,0,23,0,0,0,0,0,0,0,4,2
2,13,0,0,0,0,0,0,0,23,0,0,0,0,0,0,0,0,23,0,0,0,0,0,0,0,13,2
2,2,13,0,0,0,0,0,0,13,0,0,0,0,0,0,0,0,13,0,0,0,0,0,0,13,2,2
1,2,2,13,0,0,0,0,13,2,13,0,0,0,0,0,0,13,2,13,0,0,0,0,13,2,2,1
1,1,1,2,9,9,2,2,2,2,2,11,0,0,0,0,10,2,2,2,2,2,9,9,2,1,1,1
1,1,1,1,1,1,2,2,2,2,2,2,11,23,23,10,2,2,2,2,2,2,1,1,1,1,1,1
1,1,1,1,1,1,1,1,2,2,2,11,0,0,0,0,10,2,2,2,1,1,1,1,1,1,1,1
1,1,1,1,1,1,1,1,1,2,2,0,0,0,0,0,0,2,2,1,1,1,1,1,1,1,1,1
1,1,1,1,1,1,1,1,1,2,2,0,0,0,0,0,0,2,2,1,1,1,1,1,1,1,1,1
1,1,1,1,1,1,1,1,1,1,9,0,0,0,0,0,0,9,1,1,1,1,1,1,1,1,1,1
1,1,1,1,1,1,1,1,1,1,9,0,0,0,0,0,0,9,1,1,1,1,1,1,1,1,1,1
1,1,1,1,1,1,1,1,1,1,2,11,0,0,0,0,10,2,1,1,1,1,1,1,1,1,1,1
1,1,1,1,1,1,1,1,1,1,1,2,11,0,0,10,2,1,1,1,1,1,1,1,1,1,1,1
1,1,1,1,1,1,1,1,1,1,1,2,2,11,10,2,2,1,1,1,1,1,1,1,1,1,1,1
1,1,1,1,1,1,1,1,1,1,1,1,2,2,2,2,1,1,1,1,1,1,1,1,1,1,1,1
endlayer

layer
1,1,1,1,1,1,1,1,1,1,1,1,2,24,24,2,1,1,1,1,1,1,1,1,1,1,1,1
1,1,1,1,1,1,1,1,1,1,1,2,2,2,2,2,2,1,1,1,1,1,1,1,1,1,1,1
1,1,1,1,1,1,1,1,1,1,1,2,2,2,2,2,2,1,1,1,1,1,1,1,1,1,1,1
1,1,1,1,1,1,1,1,1,1,2,2,2,2,2,2,2,2,1,1,1,1,1,1,1,1,1,1
1,1,1,1,1,1,1,1,1,1,2,2,25,2,2,25,2,2,1,1,1,1,1,1,1,1,1,1
1,1,1,1,1,1,1,1,1,1,2,2,25,2,2,25,2,2,1,1,1,1,1,1,1,1,1,1
1,1,1,1,1,1,1,1,1,1,2,2,25,2,2,25,2,2,1,1,1,1,1,1,1,1,1,1
1,1,1,1,1,1,1,1,1,2,2,2,2,2,2,2,2,2,2,1,1,1,1,1,1,1,1,1
1,1,1,1,1,1,1,1,1,2,2,2,2,2,2,2,2,2,2,1,1,1,1,1,1,1,1,1
1,1,1,1,1,1,1,2,2,2,2,2,2,11,10,2,2,2,2,2,2,1,1,1,1,1,1,1
1,1,1,2,2,2,2,2,2,2,2,2,11,0,0,10,2,2,2,2,2,2,2,2,2,1,1,1
1,2,2,2,2,2,2,2,2,2,2,9,0,0,0,0,9,2,2,2,2,2,2,2,2,2,2,1
2,2,2,2,25,25,25,2,2,2,4,0,0,0,0,0,0,4,2,2,2,25,25,25,2,2,2,2
27,2,2,2,2,2,2,2,2,4,0,0,0,0,0,0,0,0,4,2,2,2,2,2,2,2,2,26
27,2,2,2,2,2,2,2,2,13,0,0,0,0,0,0,0,0,13,2,2,2,2,2,2,2,2,26
2,2,2,2,25,25,25,2,2,2,13,0,0,0,0,0,0,13,2,2,2,25,25,25,2,2,2,2
1,2,2,2,2,2,2,2,2,2,2,9,0,0,0,0,9,2,2,2,2,2,2,2,2,2,2,1
1,1,1,2,2,2,2,2,2,2,2,2,11,0,0,10,2,2,2,2,2,2,2,2,2,1,1,1
1,1,1,1,1,1,1,2,2,2,2,2,2,11,10,2,2,2,2,2,2,1,1,1,1,1,1,1
1,1,1,1,1,1,1,1,1,2,2,2,2,2,2,2,2,2,2,1,1,1,1,1,1,1,1,1
1,1,1,1,1,1,1,1,1,2,2,2,2,2,2,2,2,2,2,1,1,1,1,1,1,1,1,1
1,1,1,1,1,1,1,1,1,1,2,2,25,2,2,25,2,2,1,1,1,1,1,1,1,1,1,1
1,1,1,1,1,1,1,1,1,1,2,2,25,2,2,25,2,2,1,1,1,1,1,1,1,1,1,1
1,1,1,1,1,1,1,1,1,1,2,2,25,2,2,25,2,2,1,1,1,1,1,1,1,1,1,1
1,1,1,1,1,1,1,1,1,1,2,2,2,2,2,2,2,2,1,1,1,1,1,1,1,1,1,1
1,1,1,1,1,1,1,1,1,1,1,2,2,2,2,2,2,1,1,1,1,1,1,1,1,1,1,1
1,1,1,1,1,1,1,1,1,1,1,2,2,2,2,2,2,1,1,1,1,1,1,1,1,1,1,1
1,1,1,1,1,1,1,1,1,1,1,1,2,28,28,2,1,1,1,1,1,1,1,1,1,1,1,1
endlayer

layer
1,1,1,1,1,1,1,1,1,1,1,1,2,0,0,2,1,1,1,1,1,1,1,1,1,1,1,1
1,1,1,1,1,1,1,1,1,1,1,2,0,0,0,0,2,1,1,1,1,1,1,1,1,1,1,1
1,1,1,1,1,1,1,1,1,1,1,2,0,0,0,0,2,1,1,1,1,1,1,1,1,1,1,1
1,1,1,1,1,1,1,1,1,1,2,0,0,0,0,0,0,2,1,1,1,1,1,1,1,1,1,1
1,1,1,1,1,1,1,1,1,1,24,9,0,0,0,0,9,24,1,1,1,1,1,1,1,1,1,1
1,1,1,1,1,1,1,1,1,1,24,0,0,0,0,0,0,24,1,1,1,1,1,1,1,1,1,1
1,1,1,1,1,1,1,1,1,1,24,2,0,0,0,0,2,24,1,1,1,1,1,1,1,1,1,1
1,1,1,1,1,1,1,1,1,1,24,0,0,0,0,0,0,24,1,1,1,1,1,1,1,1,1,1
1,1,1,1,1,1,1,1,1,1,24,9,27,24,24,26,9,24,1,1,1,1,1,1,1,1,1,1
1,1,1,1,1,1,1,1,1,1,2,24,24,2,2,24,24,2,1,1,1,1,1,1,1,1,1,1
1,1,1,2,27,27,27,27,27,2,2,2,2,2,2,2,2,2,2,26,26,26,26,26,2,1,1,1
1,2,2,0,9,0,2,0,9,27,2,2,2,2,2,2,2,2,26,9,0,2,0,9,0,2,2,1
2,0,0,0,0,0,0,0,24,27,2,2,2,29,29,2,2,2,26,24,0,0,0,0,0,0,0,2
0,0,0,0,0,0,0,0,27,2,2,2,29,29,29,29,2,2,2,26,0,0,0,0,0,0,0,0
0,0,0,0,0,0,0,0,27,2,2,2,29,29,29,29,2,2,2,26,0,0,0,0,0,0,0,0
2,0,0,0,0,0,0,0,28,27,2,2,2,29,29,2,2,2,26,28,0,0,0,0,0,0,0,2
1,2,2,0,9,0,2,0,9,27,2,2,2,2,2,2,2,2,26,9,0,2,0,9,0,2,2,1
1,1,1,2,27,27,27,27,27,2,2,2,2,2,2,2,2,2,2,26,26,26,26,26,2,1,1,1
1,1,1,1,1,1,1,1,1,1,2,28,28,2,2,28,28,2,1,1,1,1,1,1,1,1,1,1
1,1,1,1,1,1,1,1,1,1,28,9,27,28,28,26,9,28,1,1,1,1,1,1,1,1,1,1
1,1,1,1,1,1,1,1,1,1,28,0,0,0,0,0,0,28,1,1,1,1,1,1,1,1,1,1
1,1,1,1,1,1,1,1,1,1,28,2,0,0,0,0,2,28,1,1,1,1,1,1,1,1,1,1
1,1,1,1,1,1,1,1,1,1,28,0,0,0,0,0,0,28,1,1,1,1,1,1,1,1,1,1
1,1,1,1,1,1,1,1,1,1,28,9,0,0,0,0,9,28,1,1,1,1,1,1,1,1,1,1
1,1,1,1,1,1,1,1,1,1,2,0,0,0,0,0,0,2,1,1,1,1,1,1,1,1,1,1
1,1,1,1,1,1,1,1,1,1,1,2,0,0,0,0,2,1,1,1,1,1,1,1,1,1,1,1
1,1,1,1,1,1,1,1,1,1,1,2,0,0,0,0,2,1,1,1,1,1,1,1,1,1,1,1
1,1,1,1,1,1,1,1,1,1,1,1,2,0,0,2,1,1,1,1,1,1,1,1,1,1,1,1
endlayer

layer
1,1,1,1,1,1,1,1,1,1,1,1,9,0,0,9,1,1,1,1,1,1,1,1,1,1,1,1
1,1,1,1,1,1,1,1,1,1,1,24,0,0,0,0,24,1,1,1,1,1,1,1,1,1,1,1
1,1,1,1,1,1,1,1,1,1,10,2,0,0,0,0,2,11,1,1,1,1,1,1,1,1,1,1
1,1,1,1,1,1,1,1,1,1,28,0,0,0,0,0,0,28,1,1,1,1,1,1,1,1,1,1
1,1,1,1,1,1,1,1,1,1,25,9,0,0,0,0,9,25,1,1,1,1,1,1,1,1,1,1
1,1,1,1,1,1,1,1,1,1,25,0,0,0,0,0,0,25,1,1,1,1,1,1,1,1,1,1
1,1,1,1,1,1,1,1,1,1,25,2,0,0,0,0,2,25,1,1,1,1,1,1,1,1,1,1
1,1,1,1,1,1,1,1,1,1,25,0,0,0,0,0,0,25,1,1,1,1,1,1,1,1,1,1
1,1,1,1,1,1,1,1,1,1,25,9,0,0,0,0,9,25,1,1,1,1,1,1,1,1,1,1
1,1,1,1,1,1,1,1,1,1,24,0,0,0,0,0,0,24,1,1,1,1,1,1,1,1,1,1
1,1,13,26,25,25,25,25,25,27,2,2,9,0,0,9,2,2,26,25,25,25,25,25,27,13,1,1
1,27,2,0,9,0,2,0,9,0,2,0,0,0,0,0,0,2,0,9,0,2,0,9,0,2,26,1
9,0,0,0,0,0,0,0,0,0,9,0,0,0,0,0,0,9,0,0,0,0,0,0,0,0,0,9
0,0,0,0,0,0,0,0,0,0,0,0,0,0,0,0,0,0,0,0,0,0,0,0,0,0,0,0
0,0,0,0,0,0,0,0,0,0,0,0,0,0,0,0,0,0,0,0,0,0,0,0,0,0,0,0
9,0,0,0,0,0,0,0,0,0,9,0,0,0,0,0,0,9,0,0,0,0,0,0,0,0,0,9
1,27,2,0,9,0,2,0,9,0,2,0,0,0,0,0,0,2,0,9,0,2,0,9,0,2,26,1
1,1,4,26,25,25,25,25,25,27,2,2,9,0,0,9,2,2,26,25,25,25,25,25,27,4,1,1
1,1,1,1,1,1,1,1,1,1,28,0,0,0,0,0,0,28,1,1,1,1,1,1,1,1,1,1
1,1,1,1,1,1,1,1,1,1,25,9,0,0,0,0,9,25,1,1,1,1,1,1,1,1,1,1
1,1,1,1,1,1,1,1,1,1,25,0,0,0,0,0,0,25,1,1,1,1,1,1,1,1,1,1
1,1,1,1,1,1,1,1,1,1,25,2,0,0,0,0,2,25,1,1,1,1,1,1,1,1,1,1
1,1,1,1,1,1,1,1,1,1,25,0,0,0,0,0,0,25,1,1,1,1,1,1,1,1,1,1
1,1,1,1,1,1,1,1,1,1,25,9,0,0,0,0,9,25,1,1,1,1,1,1,1,1,1,1
1,1,1,1,1,1,1,1,1,1,24,0,0,0,0,0,0,24,1,1,1,1,1,1,1,1,1,1
1,1,1,1,1,1,1,1,1,1,10,2,0,0,0,0,2,11,1,1,1,1,1,1,1,1,1,1
1,1,1,1,1,1,1,1,1,1,1,28,0,0,0,0,28,1,1,1,1,1,1,1,1,1,1,1
1,1,1,1,1,1,1,1,1,1,1,1,9,0,0,9,1,1,1,1,1,1,1,1,1,1,1,1
endlayer

layer
1,1,1,1,1,1,1,1,1,1,1,1,9,0,0,9,1,1,1,1,1,1,1,1,1,1,1,1
1,1,1,1,1,1,1,1,1,1,1,0,0,0,0,0,0,1,1,1,1,1,1,1,1,1,1,1
1,1,1,1,1,1,1,1,1,1,0,2,0,0,0,0,2,0,1,1,1,1,1,1,1,1,1,1
1,1,1,1,1,1,1,1,1,1,0,0,0,0,0,0,0,0,1,1,1,1,1,1,1,1,1,1
1,1,1,1,1,1,1,1,1,1,0,0,0,0,0,0,0,0,1,1,1,1,1,1,1,1,1,1
1,1,1,1,1,1,1,1,1,1,0,0,0,0,0,0,0,0,1,1,1,1,1,1,1,1,1,1
1,1,1,1,1,1,1,1,1,1,0,2,0,0,0,0,2,0,1,1,1,1,1,1,1,1,1,1
1,1,1,1,1,1,1,1,1,1,0,9,0,0,0,0,9,0,1,1,1,1,1,1,1,1,1,1
1,1,1,1,1,1,1,1,1,1,0,9,0,0,0,0,9,0,1,1,1,1,1,1,1,1,1,1
1,1,1,1,1,1,1,1,1,1,0,9,0,0,0,0,9,0,1,1,1,1,1,1,1,1,1,1
1,1,0,0,0,0,0,0,0,0,9,2,9,0,0,9,2,9,0,0,0,0,0,0,0,0,1,1
1,0,2,0,0,0,2,9,9,9,2,0,0,0,0,0,0,2,9,9,9,2,0,0,0,2,0,1
9,0,0,0,0,0,0,0,0,0,9,0,0,0,0,0,0,9,0,0,0,0,0,0,0,0,0,9
0,0,0,0,0,0,0,0,0,0,0,0,0,0,0,0,0,0,0,0,0,0,0,0,0,0,0,0
0,0,0,0,0,0,0,0,0,0,0,0,0,0,0,0,0,0,0,0,0,0,0,0,0,0,0,0
9,0,0,0,0,0,0,0,0,0,9,0,0,0,0,0,0,9,0,0,0,0,0,0,0,0,0,9
1,0,2,0,0,0,2,9,9,9,2,0,0,0,0,0,0,2,9,9,9,2,0,0,0,2,0,1
1,1,0,0,0,0,0,0,0,0,9,2,9,0,0,9,2,9,0,0,0,0,0,0,0,0,1,1
1,1,1,1,1,1,1,1,1,1,0,9,0,0,0,0,9,0,1,1,1,1,1,1,1,1,1,1
1,1,1,1,1,1,1,1,1,1,0,9,0,0,0,0,9,0,1,1,1,1,1,1,1,1,1,1
1,1,1,1,1,1,1,1,1,1,0,9,0,0,0,0,9,0,1,1,1,1,1,1,1,1,1,1
1,1,1,1,1,1,1,1,1,1,0,2,0,0,0,0,2,0,1,1,1,1,1,1,1,1,1,1
1,1,1,1,1,1,1,1,1,1,0,0,0,0,0,0,0,0,1,1,1,1,1,1,1,1,1,1
1,1,1,1,1,1,1,1,1,1,0,0,0,0,0,0,0,0,1,1,1,1,1,1,1,1,1,1
1,1,1,1,1,1,1,1,1,1,0,0,0,0,0,0,0,0,1,1,1,1,1,1,1,1,1,1
1,1,1,1,1,1,1,1,1,1,0,2,0,0,0,0,2,0,1,1,1,1,1,1,1,1,1,1
1,1,1,1,1,1,1,1,1,1,1,0,0,0,0,0,0,1,1,1,1,1,1,1,1,1,1,1
1,1,1,1,1,1,1,1,1,1,1,1,9,0,0,9,1,1,1,1,1,1,1,1,1,1,1,1
endlayer

layer
1,1,1,1,1,1,1,1,1,1,1,1,27,25,25,26,1,1,1,1,1,1,1,1,1,1,1,1
1,1,1,1,1,1,1,1,1,1,1,0,0,0,0,0,0,1,1,1,1,1,1,1,1,1,1,1
1,1,1,1,1,1,1,1,1,1,0,2,0,0,0,0,2,0,1,1,1,1,1,1,1,1,1,1
1,1,1,1,1,1,1,1,1,1,0,0,0,0,0,0,0,0,1,1,1,1,1,1,1,1,1,1
1,1,1,1,1,1,1,1,1,1,0,0,0,0,0,0,0,0,1,1,1,1,1,1,1,1,1,1
1,1,1,1,1,1,1,1,1,1,0,0,0,0,0,0,0,0,1,1,1,1,1,1,1,1,1,1
1,1,1,1,1,1,1,1,1,1,0,9,0,0,0,0,9,0,1,1,1,1,1,1,1,1,1,1
1,1,1,1,1,1,1,1,1,1,0,0,0,0,0,0,0,0,1,1,1,1,1,1,1,1,1,1
1,1,1,1,1,1,1,1,1,1,0,9,0,0,0,0,9,0,1,1,1,1,1,1,1,1,1,1
1,1,1,1,1,1,1,1,1,1,0,0,0,0,0,0,0,0,1,1,1,1,1,1,1,1,1,1
1,1,0,0,0,0,0,0,0,0,0,27,0,0,0,0,26,0,0,0,0,0,0,0,0,0,1,1
1,0,2,0,0,0,9,0,9,0,24,0,0,0,0,0,0,24,0,9,0,9,0,0,0,2,0,1
24,0,0,0,0,0,0,0,0,0,0,0,0,0,0,0,0,0,0,0,0,0,0,0,0,0,0,24
25,0,0,0,0,0,0,0,0,0,0,0,0,0,0,0,0,0,0,0,0,0,0,0,0,0,0,25
25,0,0,0,0,0,0,0,0,0,0,0,0,0,0,0,0,0,0,0,0,0,0,0,0,0,0,25
28,0,0,0,0,0,0,0,0,0,0,0,0,0,0,0,0,0,0,0,0,0,0,0,0,0,0,28
1,0,2,0,0,0,9,0,9,0,28,0,0,0,0,0,0,28,0,9,0,9,0,0,0,2,0,1
1,1,0,0,0,0,0,0,0,0,0,27,0,0,0,0,26,0,0,0,0,0,0,0,0,0,1,1
1,1,1,1,1,1,1,1,1,1,0,0,0,0,0,0,0,0,1,1,1,1,1,1,1,1,1,1
1,1,1,1,1,1,1,1,1,1,0,9,0,0,0,0,9,0,1,1,1,1,1,1,1,1,1,1
1,1,1,1,1,1,1,1,1,1,0,0,0,0,0,0,0,0,1,1,1,1,1,1,1,1,1,1
1,1,1,1,1,1,1,1,1,1,0,9,0,0,0,0,9,0,1,1,1,1,1,1,1,1,1,1
1,1,1,1,1,1,1,1,1,1,0,0,0,0,0,0,0,0,1,1,1,1,1,1,1,1,1,1
1,1,1,1,1,1,1,1,1,1,0,0,0,0,0,0,0,0,1,1,1,1,1,1,1,1,1,1
1,1,1,1,1,1,1,1,1,1,0,0,0,0,0,0,0,0,1,1,1,1,1,1,1,1,1,1
1,1,1,1,1,1,1,1,1,1,0,2,0,0,0,0,2,0,1,1,1,1,1,1,1,1,1,1
1,1,1,1,1,1,1,1,1,1,1,0,0,0,0,0,0,1,1,1,1,1,1,1,1,1,1,1
1,1,1,1,1,1,1,1,1,1,1,1,27,25,25,26,1,1,1,1,1,1,1,1,1,1,1,1
endlayer

layer
1,1,1,1,1,1,1,1,1,1,1,1,0,0,0,0,1,1,1,1,1,1,1,1,1,1,1,1
1,1,1,1,1,1,1,1,1,1,1,0,0,0,0,0,0,1,1,1,1,1,1,1,1,1,1,1
1,1,1,1,1,1,1,1,1,1,0,9,0,0,0,0,9,0,1,1,1,1,1,1,1,1,1,1
1,1,1,1,1,1,1,1,1,1,0,0,0,0,0,0,0,0,1,1,1,1,1,1,1,1,1,1
1,1,1,1,1,1,1,1,1,1,0,0,0,0,0,0,0,0,1,1,1,1,1,1,1,1,1,1
1,1,1,1,1,1,1,1,1,1,0,0,0,0,0,0,0,0,1,1,1,1,1,1,1,1,1,1
1,1,1,1,1,1,1,1,1,1,0,9,0,0,0,0,9,0,1,1,1,1,1,1,1,1,1,1
1,1,1,1,1,1,1,1,1,1,0,0,0,0,0,0,0,0,1,1,1,1,1,1,1,1,1,1
1,1,1,1,1,1,1,1,1,1,0,0,0,0,0,0,0,0,1,1,1,1,1,1,1,1,1,1
1,1,1,1,1,1,1,1,1,1,0,0,0,0,0,0,0,0,1,1,1,1,1,1,1,1,1,1
1,1,0,0,0,0,0,0,0,0,0,27,11,0,0,10,26,0,0,0,0,0,0,0,0,0,1,1
1,0,9,0,0,0,9,0,0,0,24,0,0,0,0,0,0,24,0,0,0,9,0,0,0,9,0,1
0,0,0,0,0,0,0,0,0,0,4,0,0,0,0,0,0,4,0,0,0,0,0,0,0,0,0,0
0,0,0,0,0,0,0,0,0,0,0,0,0,0,0,0,0,0,0,0,0,0,0,0,0,0,0,0
0,0,0,0,0,0,0,0,0,0,0,0,0,0,0,0,0,0,0,0,0,0,0,0,0,0,0,0
0,0,0,0,0,0,0,0,0,0,13,0,0,0,0,0,0,13,0,0,0,0,0,0,0,0,0,0
1,0,9,0,0,0,9,0,0,0,28,0,0,0,0,0,0,28,0,0,0,9,0,0,0,9,0,1
1,1,0,0,0,0,0,0,0,0,0,27,11,0,0,10,26,0,0,0,0,0,0,0,0,0,1,1
1,1,1,1,1,1,1,1,1,1,0,0,0,0,0,0,0,0,1,1,1,1,1,1,1,1,1,1
1,1,1,1,1,1,1,1,1,1,0,0,0,0,0,0,0,0,1,1,1,1,1,1,1,1,1,1
1,1,1,1,1,1,1,1,1,1,0,0,0,0,0,0,0,0,1,1,1,1,1,1,1,1,1,1
1,1,1,1,1,1,1,1,1,1,0,9,0,0,0,0,9,0,1,1,1,1,1,1,1,1,1,1
1,1,1,1,1,1,1,1,1,1,0,0,0,0,0,0,0,0,1,1,1,1,1,1,1,1,1,1
1,1,1,1,1,1,1,1,1,1,0,0,0,0,0,0,0,0,1,1,1,1,1,1,1,1,1,1
1,1,1,1,1,1,1,1,1,1,0,0,0,0,0,0,0,0,1,1,1,1,1,1,1,1,1,1
1,1,1,1,1,1,1,1,1,1,0,9,0,0,0,0,9,0,1,1,1,1,1,1,1,1,1,1
1,1,1,1,1,1,1,1,1,1,1,0,0,0,0,0,0,1,1,1,1,1,1,1,1,1,1,1
1,1,1,1,1,1,1,1,1,1,1,1,0,0,0,0,1,1,1,1,1,1,1,1,1,1,1,1
endlayer

layer
1,1,1,1,1,1,1,1,1,1,1,1,0,0,0,0,1,1,1,1,1,1,1,1,1,1,1,1
1,1,1,1,1,1,1,1,1,1,1,0,0,0,0,0,0,1,1,1,1,1,1,1,1,1,1,1
1,1,1,1,1,1,1,1,1,1,0,9,0,0,0,0,9,0,1,1,1,1,1,1,1,1,1,1
1,1,1,1,1,1,1,1,1,1,0,0,0,0,0,0,0,0,1,1,1,1,1,1,1,1,1,1
1,1,1,1,1,1,1,1,1,1,0,0,0,0,0,0,0,0,1,1,1,1,1,1,1,1,1,1
1,1,1,1,1,1,1,1,1,1,0,0,0,0,0,0,0,0,1,1,1,1,1,1,1,1,1,1
1,1,1,1,1,1,1,1,1,1,0,27,25,25,25,25,26,0,1,1,1,1,1,1,1,1,1,1
1,1,1,1,1,1,1,1,1,1,0,0,0,0,0,0,0,0,1,1,1,1,1,1,1,1,1,1
1,1,1,1,1,1,1,1,1,1,0,0,0,0,0,0,0,0,1,1,1,1,1,1,1,1,1,1
1,1,1,1,1,1,1,1,1,1,0,0,0,0,0,0,0,0,1,1,1,1,1,1,1,1,1,1
1,1,0,0,0,0,0,0,0,0,0,27,10,2,2,11,26,0,0,0,0,0,0,0,0,0,1,1
1,0,9,0,0,0,24,0,0,0,24,0,23,0,0,23,0,24,0,0,0,24,0,0,0,9,0,1
0,0,0,0,0,0,25,0,0,0,13,23,0,0,0,0,23,13,0,0,0,25,0,0,0,0,0,0
0,0,0,0,0,0,25,0,0,0,2,0,0,0,0,0,0,2,0,0,0,25,0,0,0,0,0,0
0,0,0,0,0,0,25,0,0,0,2,0,0,0,0,0,0,2,0,0,0,25,0,0,0,0,0,0
0,0,0,0,0,0,25,0,0,0,4,23,0,0,0,0,23,4,0,0,0,25,0,0,0,0,0,0
1,0,9,0,0,0,28,0,0,0,28,0,23,0,0,23,0,28,0,0,0,28,0,0,0,9,0,1
1,1,0,0,0,0,0,0,0,0,0,27,10,2,2,11,26,0,0,0,0,0,0,0,0,0,1,1
1,1,1,1,1,1,1,1,1,1,0,0,0,0,0,0,0,0,1,1,1,1,1,1,1,1,1,1
1,1,1,1,1,1,1,1,1,1,0,0,0,0,0,0,0,0,1,1,1,1,1,1,1,1,1,1
1,1,1,1,1,1,1,1,1,1,0,0,0,0,0,0,0,0,1,1,1,1,1,1,1,1,1,1
1,1,1,1,1,1,1,1,1,1,0,27,25,25,25,25,26,0,1,1,1,1,1,1,1,1,1,1
1,1,1,1,1,1,1,1,1,1,0,0,0,0,0,0,0,0,1,1,1,1,1,1,1,1,1,1
1,1,1,1,1,1,1,1,1,1,0,0,0,0,0,0,0,0,1,1,1,1,1,1,1,1,1,1
1,1,1,1,1,1,1,1,1,1,0,0,0,0,0,0,0,0,1,1,1,1,1,1,1,1,1,1
1,1,1,1,1,1,1,1,1,1,0,9,0,0,0,0,9,0,1,1,1,1,1,1,1,1,1,1
1,1,1,1,1,1,1,1,1,1,1,0,0,0,0,0,0,1,1,1,1,1,1,1,1,1,1,1
1,1,1,1,1,1,1,1,1,1,1,1,0,0,0,0,1,1,1,1,1,1,1,1,1,1,1,1
endlayer

layer
1,1,1,1,1,1,1,1,1,1,1,1,0,0,0,0,1,1,1,1,1,1,1,1,1,1,1,1
1,1,1,1,1,1,1,1,1,1,1,0,0,0,0,0,0,1,1,1,1,1,1,1,1,1,1,1
1,1,1,1,1,1,1,1,1,1,0,27,25,25,25,25,26,0,1,1,1,1,1,1,1,1,1,1
1,1,1,1,1,1,1,1,1,1,0,0,0,0,0,0,0,0,1,1,1,1,1,1,1,1,1,1
1,1,1,1,1,1,1,1,1,1,0,0,0,0,0,0,0,0,1,1,1,1,1,1,1,1,1,1
1,1,1,1,1,1,1,1,1,1,0,0,0,0,0,0,0,0,1,1,1,1,1,1,1,1,1,1
1,1,1,1,1,1,1,1,1,1,0,0,0,0,0,0,0,0,1,1,1,1,1,1,1,1,1,1
1,1,1,1,1,1,1,1,1,1,0,0,0,0,0,0,0,0,1,1,1,1,1,1,1,1,1,1
1,1,1,1,1,1,1,1,1,1,0,0,0,0,0,0,0,0,1,1,1,1,1,1,1,1,1,1
1,1,1,1,1,1,1,1,1,1,0,0,0,0,0,0,0,0,1,1,1,1,1,1,1,1,1,1
1,1,0,0,0,0,0,0,0,0,0,0,2,0,0,2,0,0,0,0,0,0,0,0,0,0,1,1
1,0,24,0,0,0,0,0,0,0,0,0,0,25,25,0,0,0,0,0,0,0,0,0,0,24,0,1
0,0,25,0,0,0,0,0,0,0,2,0,0,23,23,0,0,2,0,0,0,0,0,0,0,25,0,0
0,0,25,0,0,0,0,0,0,0,0,25,23,23,23,23,25,0,0,0,0,0,0,0,0,25,0,0
0,0,25,0,0,0,0,0,0,0,0,25,23,23,23,23,25,0,0,0,0,0,0,0,0,25,0,0
0,0,25,0,0,0,0,0,0,0,2,0,0,23,23,0,0,2,0,0,0,0,0,0,0,25,0,0
1,0,28,0,0,0,0,0,0,0,0,0,0,25,25,0,0,0,0,0,0,0,0,0,0,28,0,1
1,1,0,0,0,0,0,0,0,0,0,0,2,0,0,2,0,0,0,0,0,0,0,0,0,0,1,1
1,1,1,1,1,1,1,1,1,1,0,0,0,0,0,0,0,0,1,1,1,1,1,1,1,1,1,1
1,1,1,1,1,1,1,1,1,1,0,0,0,0,0,0,0,0,1,1,1,1,1,1,1,1,1,1
1,1,1,1,1,1,1,1,1,1,0,0,0,0,0,0,0,0,1,1,1,1,1,1,1,1,1,1
1,1,1,1,1,1,1,1,1,1,0,0,0,0,0,0,0,0,1,1,1,1,1,1,1,1,1,1
1,1,1,1,1,1,1,1,1,1,0,0,0,0,0,0,0,0,1,1,1,1,1,1,1,1,1,1
1,1,1,1,1,1,1,1,1,1,0,0,0,0,0,0,0,0,1,1,1,1,1,1,1,1,1,1
1,1,1,1,1,1,1,1,1,1,0,0,0,0,0,0,0,0,1,1,1,1,1,1,1,1,1,1
1,1,1,1,1,1,1,1,1,1,0,27,25,25,25,25,26,0,1,1,1,1,1,1,1,1,1,1
1,1,1,1,1,1,1,1,1,1,1,0,0,0,0,0,0,1,1,1,1,1,1,1,1,1,1,1
1,1,1,1,1,1,1,1,1,1,1,1,0,0,0,0,1,1,1,1,1,1,1,1,1,1,1,1
endlayer

layer
1,1,1,1,1,1,1,1,1,1,1,1,0,0,0,0,1,1,1,1,1,1,1,1,1,1,1,1
1,1,1,1,1,1,1,1,1,1,1,0,0,0,0,0,0,1,1,1,1,1,1,1,1,1,1,1
1,1,1,1,1,1,1,1,1,1,0,0,0,0,0,0,0,0,1,1,1,1,1,1,1,1,1,1
1,1,1,1,1,1,1,1,1,1,0,0,0,0,0,0,0,0,1,1,1,1,1,1,1,1,1,1
1,1,1,1,1,1,1,1,1,1,0,0,0,0,0,0,0,0,1,1,1,1,1,1,1,1,1,1
1,1,1,1,1,1,1,1,1,1,0,0,0,0,0,0,0,0,1,1,1,1,1,1,1,1,1,1
1,1,1,1,1,1,1,1,1,1,0,0,0,0,0,0,0,0,1,1,1,1,1,1,1,1,1,1
1,1,1,1,1,1,1,1,1,1,0,0,0,0,0,0,0,0,1,1,1,1,1,1,1,1,1,1
1,1,1,1,1,1,1,1,1,1,0,0,0,0,0,0,0,0,1,1,1,1,1,1,1,1,1,1
1,1,1,1,1,1,1,1,1,1,0,0,0,0,0,0,0,0,1,1,1,1,1,1,1,1,1,1
1,1,0,0,0,0,0,0,0,0,0,0,9,0,0,9,0,0,0,0,0,0,0,0,0,0,1,1
1,0,0,0,0,0,0,0,0,0,0,0,0,0,0,0,0,0,0,0,0,0,0,0,0,0,0,1
0,0,0,0,0,0,0,0,0,0,9,0,0,0,0,0,0,9,0,0,0,0,0,0,0,0,0,0
0,0,0,0,0,0,0,0,0,0,0,0,0,25,25,0,0,0,0,0,0,0,0,0,0,0,0,0
0,0,0,0,0,0,0,0,0,0,0,0,0,25,25,0,0,0,0,0,0,0,0,0,0,0,0,0
0,0,0,0,0,0,0,0,0,0,9,0,0,0,0,0,0,9,0,0,0,0,0,0,0,0,0,0
1,0,0,0,0,0,0,0,0,0,0,0,0,0,0,0,0,0,0,0,0,0,0,0,0,0,0,1
1,1,0,0,0,0,0,0,0,0,0,0,9,0,0,9,0,0,0,0,0,0,0,0,0,0,1,1
1,1,1,1,1,1,1,1,1,1,0,0,0,0,0,0,0,0,1,1,1,1,1,1,1,1,1,1
1,1,1,1,1,1,1,1,1,1,0,0,0,0,0,0,0,0,1,1,1,1,1,1,1,1,1,1
1,1,1,1,1,1,1,1,1,1,0,0,0,0,0,0,0,0,1,1,1,1,1,1,1,1,1,1
1,1,1,1,1,1,1,1,1,1,0,0,0,0,0,0,0,0,1,1,1,1,1,1,1,1,1,1
1,1,1,1,1,1,1,1,1,1,0,0,0,0,0,0,0,0,1,1,1,1,1,1,1,1,1,1
1,1,1,1,1,1,1,1,1,1,0,0,0,0,0,0,0,0,1,1,1,1,1,1,1,1,1,1
1,1,1,1,1,1,1,1,1,1,0,0,0,0,0,0,0,0,1,1,1,1,1,1,1,1,1,1
1,1,1,1,1,1,1,1,1,1,0,0,0,0,0,0,0,0,1,1,1,1,1,1,1,1,1,1
1,1,1,1,1,1,1,1,1,1,1,0,0,0,0,0,0,1,1,1,1,1,1,1,1,1,1,1
1,1,1,1,1,1,1,1,1,1,1,1,0,0,0,0,1,1,1,1,1,1,1,1,1,1,1,1
endlayer

layer
1,1,1,1,1,1,1,1,1,1,1,1,0,0,0,0,1,1,1,1,1,1,1,1,1,1,1,1
1,1,1,1,1,1,1,1,1,1,1,0,0,0,0,0,0,1,1,1,1,1,1,1,1,1,1,1
1,1,1,1,1,1,1,1,1,1,0,0,0,0,0,0,0,0,1,1,1,1,1,1,1,1,1,1
1,1,1,1,1,1,1,1,1,1,0,0,0,0,0,0,0,0,1,1,1,1,1,1,1,1,1,1
1,1,1,1,1,1,1,1,1,1,0,0,0,0,0,0,0,0,1,1,1,1,1,1,1,1,1,1
1,1,1,1,1,1,1,1,1,1,0,0,0,0,0,0,0,0,1,1,1,1,1,1,1,1,1,1
1,1,1,1,1,1,1,1,1,1,0,0,0,0,0,0,0,0,1,1,1,1,1,1,1,1,1,1
1,1,1,1,1,1,1,1,1,1,0,0,0,0,0,0,0,0,1,1,1,1,1,1,1,1,1,1
1,1,1,1,1,1,1,1,1,1,0,0,0,0,0,0,0,0,1,1,1,1,1,1,1,1,1,1
1,1,1,1,1,1,1,1,1,1,0,0,0,0,0,0,0,0,1,1,1,1,1,1,1,1,1,1
1,1,0,0,0,0,0,0,0,0,0,0,27,25,25,26,0,0,0,0,0,0,0,0,0,0,1,1
1,0,0,0,0,0,0,0,0,0,0,0,0,0,0,0,0,0,0,0,0,0,0,0,0,0,0,1
0,0,0,0,0,0,0,0,0,0,24,0,0,0,0,0,0,24,0,0,0,0,0,0,0,0,0,0
0,0,0,0,0,0,0,0,0,0,25,0,0,0,0,0,0,25,0,0,0,0,0,0,0,0,0,0
0,0,0,0,0,0,0,0,0,0,25,0,0,0,0,0,0,25,0,0,0,0,0,0,0,0,0,0
0,0,0,0,0,0,0,0,0,0,28,0,0,0,0,0,0,28,0,0,0,0,0,0,0,0,0,0
1,0,0,0,0,0,0,0,0,0,0,0,0,0,0,0,0,0,0,0,0,0,0,0,0,0,0,1
1,1,0,0,0,0,0,0,0,0,0,0,27,25,25,26,0,0,0,0,0,0,0,0,0,0,1,1
1,1,1,1,1,1,1,1,1,1,0,0,0,0,0,0,0,0,1,1,1,1,1,1,1,1,1,1
1,1,1,1,1,1,1,1,1,1,0,0,0,0,0,0,0,0,1,1,1,1,1,1,1,1,1,1
1,1,1,1,1,1,1,1,1,1,0,0,0,0,0,0,0,0,1,1,1,1,1,1,1,1,1,1
1,1,1,1,1,1,1,1,1,1,0,0,0,0,0,0,0,0,1,1,1,1,1,1,1,1,1,1
1,1,1,1,1,1,1,1,1,1,0,0,0,0,0,0,0,0,1,1,1,1,1,1,1,1,1,1
1,1,1,1,1,1,1,1,1,1,0,0,0,0,0,0,0,0,1,1,1,1,1,1,1,1,1,1
1,1,1,1,1,1,1,1,1,1,0,0,0,0,0,0,0,0,1,1,1,1,1,1,1,1,1,1
1,1,1,1,1,1,1,1,1,1,0,0,0,0,0,0,0,0,1,1,1,1,1,1,1,1,1,1
1,1,1,1,1,1,1,1,1,1,1,0,0,0,0,0,0,1,1,1,1,1,1,1,1,1,1,1
1,1,1,1,1,1,1,1,1,1,1,1,0,0,0,0,1,1,1,1,1,1,1,1,1,1,1,1
endlayer

