
# Created by Ruins mod version 16.8 Ingame Parser
# authoring Player: ST753M

weight=1
uniqueMinDistance=1000
embed_into_distance=2
acceptable_target_blocks=
unacceptable_target_blocks=flowing_water,water,flowing_lava,lava,ice,bedrock,netherrack,nether_brick,nether_brick_fence,soul_sand,quartz_ore,end_stone,obsidian,iron_bars,Natura:Cloud,slime_grass,slime_congealed,slime_dirt,clouds,natura:clouds
dimensions=14,10,10
allowable_overhang=1
max_leveling=2
leveling_buffer=0
preserve_water=0
preserve_lava=0

biomesToSpawnIn=ice_flats,ice_mountains,glacier,mutated_ice_flats,frozen_ocean,frozen_river,cold_beach,cold_desert,cold beach,cold desert,ice mountains,ice plains,ice plains spikes

rule1=0,100,minecraft:snow-0
rule2=0,100,minecraft:snow_layer-1
rule3=0,100,minecraft:snow_layer-3
rule4=0,100,minecraft:snow_layer-5

layer
1,1,1,1,1,1,1,1,1,1
1,1,1,1,1,1,1,1,1,1
1,1,1,1,1,1,1,1,1,1
1,1,1,1,1,1,1,1,1,1
1,1,1,1,1,1,1,1,1,1
1,1,1,1,1,1,1,1,1,1
1,1,1,1,1,1,1,1,1,1
1,1,1,1,1,1,1,1,1,1
1,1,1,1,1,1,1,1,1,1
1,1,1,1,1,1,1,1,1,1
endlayer

layer
1,1,1,1,1,1,1,1,1,1
1,1,1,1,1,1,1,1,1,1
1,1,1,1,1,1,1,1,1,1
1,1,1,1,1,1,1,1,1,1
1,1,1,1,1,1,1,1,1,1
1,1,1,1,1,1,1,1,1,1
1,1,1,1,1,1,1,1,1,1
1,1,1,1,1,1,1,1,1,1
1,1,1,1,1,1,1,1,1,1
1,1,1,1,1,1,1,1,1,1
endlayer

layer
1,1,1,1,1,1,1,1,1,1
1,1,1,1,1,1,1,1,1,1
1,1,1,1,1,1,1,1,1,1
1,1,1,1,1,1,1,1,1,1
1,1,1,1,1,1,1,1,1,1
1,1,1,1,1,1,1,1,1,1
1,1,1,1,1,1,1,1,1,1
1,1,1,1,1,1,1,1,1,1
1,1,1,1,1,1,1,1,1,1
1,1,1,1,1,1,1,1,1,1
endlayer

layer
0,2,3,4,1,1,4,3,2,0
2,1,1,1,1,1,1,1,1,2
3,1,1,1,1,1,1,1,1,3
4,1,1,1,1,1,1,1,1,4
1,1,1,1,1,1,1,1,1,1
1,1,1,1,1,1,1,1,1,1
4,1,1,1,1,1,1,1,1,4
3,1,1,1,1,1,1,1,1,3
2,1,1,1,1,1,1,1,1,2
0,2,3,4,1,1,4,3,2,0
endlayer

layer
0,0,0,0,0,0,0,0,0,0
0,0,0,0,0,0,0,0,0,0
0,0,0,0,1,1,0,0,0,0
0,0,0,1,1,1,1,0,0,0
0,0,1,1,1,1,1,1,0,0
0,0,1,1,1,1,1,1,0,0
0,0,0,1,1,1,1,0,0,0
0,0,0,0,1,1,0,0,0,0
0,0,0,0,0,0,0,0,0,0
0,0,0,0,0,0,0,0,0,0
endlayer

layer
0,0,0,0,0,0,0,0,0,0
0,0,0,0,0,0,0,0,0,0
0,0,0,1,1,1,1,0,0,0
0,0,1,1,1,1,1,1,0,0
0,0,1,1,1,1,1,1,0,0
0,0,1,1,1,1,1,1,0,0
0,0,1,1,1,1,1,1,0,0
0,0,0,1,1,1,1,0,0,0
0,0,0,0,0,0,0,0,0,0
0,0,0,0,0,0,0,0,0,0
endlayer

layer
0,0,0,0,0,0,0,0,0,0
0,0,0,0,0,0,0,0,0,0
0,0,1,1,0,0,1,1,0,0
0,0,1,1,1,1,1,1,0,0
0,0,0,1,1,1,1,0,0,0
0,0,0,1,1,1,1,0,0,0
0,0,1,1,1,1,1,1,0,0
0,0,1,1,0,0,1,1,0,0
0,0,0,0,0,0,0,0,0,0
0,0,0,0,0,0,0,0,0,0
endlayer

layer
0,0,0,0,0,0,0,0,0,0
0,1,1,0,0,0,0,1,1,0
0,1,1,1,0,0,1,1,1,0
0,0,1,1,1,1,1,1,0,0
0,0,0,1,1,1,1,0,0,0
0,0,0,1,1,1,1,0,0,0
0,0,1,1,1,1,1,1,0,0
0,1,1,1,0,0,1,1,1,0
0,1,1,0,0,0,0,1,1,0
0,0,0,0,0,0,0,0,0,0
endlayer

layer
1,1,0,0,0,0,0,0,1,1
1,1,0,0,0,0,0,0,1,1
0,0,0,1,1,1,1,0,0,0
0,0,1,1,1,1,1,1,0,0
0,0,1,1,1,1,1,1,0,0
0,0,1,1,1,1,1,1,0,0
0,0,1,1,1,1,1,1,0,0
0,0,0,1,1,1,1,0,0,0
1,1,0,0,0,0,0,0,1,1
1,1,0,0,0,0,0,0,1,1
endlayer

layer
1,1,0,0,0,0,0,0,1,1
1,0,0,0,0,0,0,0,0,1
0,0,0,0,0,0,0,0,0,0
0,0,0,0,1,1,0,0,0,0
0,0,0,1,1,1,1,0,0,0
0,0,0,1,1,1,1,0,0,0
0,0,0,0,1,1,0,0,0,0
0,0,0,0,0,0,0,0,0,0
1,0,0,0,0,0,0,0,0,1
1,1,0,0,0,0,0,0,1,1
endlayer

layer
1,0,0,0,0,0,0,0,0,1
0,0,0,0,0,0,0,0,0,0
0,0,0,0,1,0,0,0,0,0
0,0,0,0,1,1,0,0,0,0
0,0,0,1,0,0,1,1,0,0
0,0,1,1,0,0,1,0,0,0
0,0,0,0,1,1,0,0,0,0
0,0,0,0,0,1,0,0,0,0
0,0,0,0,0,0,0,0,0,0
1,0,0,0,0,0,0,0,0,1
endlayer

layer
0,0,0,0,0,0,0,0,0,0
0,0,0,0,0,0,0,0,0,0
0,0,0,0,1,1,0,0,0,0
0,0,0,0,1,1,0,0,0,0
0,0,1,1,0,0,1,1,0,0
0,0,1,1,0,0,1,1,0,0
0,0,0,0,1,1,0,0,0,0
0,0,0,0,1,1,0,0,0,0
0,0,0,0,0,0,0,0,0,0
0,0,0,0,0,0,0,0,0,0
endlayer

layer
0,0,0,0,0,0,0,0,0,0
0,0,0,0,0,0,0,0,0,0
0,0,0,0,1,1,0,0,0,0
0,0,0,0,0,0,0,0,0,0
0,0,1,0,0,0,0,1,0,0
0,0,1,0,0,0,0,1,0,0
0,0,0,0,0,0,0,0,0,0
0,0,0,0,1,1,0,0,0,0
0,0,0,0,0,0,0,0,0,0
0,0,0,0,0,0,0,0,0,0
endlayer

layer
0,0,0,0,0,0,0,0,0,0
0,0,0,0,0,0,0,0,0,0
0,0,0,0,1,0,0,0,0,0
0,0,0,0,0,0,0,0,0,0
0,0,0,0,0,0,0,1,0,0
0,0,1,0,0,0,0,0,0,0
0,0,0,0,0,0,0,0,0,0
0,0,0,0,0,1,0,0,0,0
0,0,0,0,0,0,0,0,0,0
0,0,0,0,0,0,0,0,0,0
endlayer

