
# Created by Ruins mod version 16.8 Ingame Parser
# authoring Player: ST753M

weight=1
uniqueMinDistance=1000
embed_into_distance=0
acceptable_target_blocks=
unacceptable_target_blocks=flowing_water,water,flowing_lava,lava,ice,bedrock,netherrack,nether_brick,nether_brick_fence,soul_sand,quartz_ore,end_stone,obsidian,iron_bars,Natura:Cloud,slime_grass,slime_congealed,slime_dirt
dimensions=10,7,7
allowable_overhang=2
max_leveling=2
leveling_buffer=0
preserve_water=0
preserve_lava=0

biomesToSpawnIn=snowy_forest,mutated_taiga_cold,snowy_coniferous_forest,taiga_cold,taiga_cold_hills,cold taiga,cold taiga hills,cold taiga m,snowy coniferous forest,snowy forest,ice_flats,ice_mountains,glacier,mutated_ice_flats,frozen_ocean,frozen_river,cold_beach,cold_desert,cold beach,cold desert,ice mountains,ice plains,ice plains spikes

rule1=0,100,preserveBlock
rule2=0,100,minecraft:snow-0
rule3=0,100,minecraft:coal_block-0
rule4=0,100,minecraft:snow-0,preserveBlock

layer
1,1,1,1,1,1,1
1,1,2,3,2,1,1
1,2,2,2,2,2,1
1,2,2,2,2,2,1
1,2,2,2,2,2,1
1,1,2,2,2,1,1
1,1,1,1,1,1,1
endlayer

layer
1,1,2,2,2,1,1
1,2,2,2,2,2,1
2,2,2,2,2,2,2
2,2,2,2,2,2,2
2,2,2,2,2,2,2
1,2,2,2,2,2,1
1,1,2,2,2,1,1
endlayer

layer
1,1,2,3,2,1,1
1,2,2,2,2,2,1
2,2,2,2,2,2,2
2,2,2,2,2,2,2
2,2,2,2,2,2,2
1,2,2,2,2,2,1
1,1,2,2,2,1,1
endlayer

layer
1,1,4,2,4,1,1
1,2,2,2,2,2,1
4,2,2,2,2,2,4
2,2,2,2,2,2,2
4,2,2,2,2,2,4
1,2,2,2,2,2,1
1,1,4,2,4,1,1
endlayer

layer
1,1,1,1,1,1,1
1,1,2,3,2,1,1
1,2,2,2,2,2,1
1,2,2,2,2,2,1
1,2,2,2,2,2,1
1,1,2,2,2,1,1
1,1,1,1,1,1,1
endlayer

layer
1,1,1,1,1,1,1
1,1,1,1,1,1,1
1,1,2,2,2,1,1
1,1,2,2,2,1,1
1,1,2,2,2,1,1
1,1,1,1,1,1,1
1,1,1,1,1,1,1
endlayer

layer
1,1,1,1,1,1,1
1,1,2,2,2,1,1
1,4,2,2,2,4,1
1,2,2,2,2,2,1
1,4,2,2,2,4,1
1,1,4,2,4,1,1
1,1,1,1,1,1,1
endlayer

layer
1,1,1,1,1,1,1
1,1,3,2,3,1,1
1,2,2,2,2,2,1
1,2,2,2,2,2,1
1,2,2,2,2,2,1
1,1,2,2,2,1,1
1,1,1,1,1,1,1
endlayer

layer
1,1,1,1,1,1,1
1,1,2,2,2,1,1
1,4,2,2,2,4,1
1,2,2,2,2,2,1
1,4,2,2,2,4,1
1,1,4,2,4,1,1
1,1,1,1,1,1,1
endlayer

layer
1,1,1,1,1,1,1
1,1,1,1,1,1,1
1,1,4,2,4,1,1
1,1,2,2,2,1,1
1,1,4,2,4,1,1
1,1,1,1,1,1,1
1,1,1,1,1,1,1
endlayer

