
# Created by Ruins mod version 17.0 Ingame Parser
# authoring Player: ST753M

weight=1
embed_into_distance=6
acceptable_target_blocks=
unacceptable_target_blocks=flowing_water,water,flowing_lava,lava,ice,bedrock,netherrack,nether_brick,nether_brick_fence,soul_sand,quartz_ore,end_stone,obsidian,iron_bars,Natura:Cloud,slime_grass,slime_congealed,slime_dirt,clouds,natura:clouds
dimensions=29,23,23
allowable_overhang=8
max_leveling=2
leveling_buffer=0
preserve_water=0
preserve_lava=0
uniqueMinDistance=1000
spawnMinDistance=1000

biomesToSpawnIn=ice_flats,ice_mountains,glacier,mutated_ice_flats,frozen_ocean,frozen_river,cold_beach,cold_desert,glacier_spikes,cold_plateau

=0,100,air
rule1=0,100,preserveBlock
rule2=0,100,minecraft:packed_ice-0
rule3=0,100,minecraft:stonebrick-2,minecraft:monster_egg-2,minecraft:monster_egg-3,minecraft:monster_egg-4,minecraft:stonebrick-0,minecraft:stonebrick-1,minecraft:stonebrick-2
rule4=0,100,minecraft:spruce_fence-0
rule5=0,100,minecraft:spruce_stairs-2
rule6=0,100,minecraft:spruce_stairs-0
rule7=0,100,minecraft:spruce_stairs-3
rule8=0,100,minecraft:log-1
rule9=0,60,ChestGenHook:chests/simple_dungeon:4-3,air,air
rule10=0,60,ChestGenHook:chests/simple_dungeon:4-2,air,air
rule11=0,60,minecraft:spruce_stairs-1
rule12=0,100,ChestGenHook:chests/simple_dungeon:4-4,air,air
rule13=0,100,minecraft:ladder-4
rule14=0,100,minecraft:spruce_stairs-6
rule15=0,100,minecraft:spruce_stairs-4
rule16=0,100,minecraft:spruce_stairs-7
rule17=0,100,minecraft:spruce_stairs-5
rule18=0,95,minecraft:planks-1,minecraft:spruce_stairs-3,minecraft:spruce_stairs-6,minecraft:spruce_stairs-4,minecraft:wooden_slab-1,minecraft:spruce_stairs-1,minecraft:spruce_stairs-2,minecraft:spruce_stairs-7,minecraft:wooden_slab-9,minecraft:spruce_stairs-0,minecraft:spruce_stairs-5,minecraft:planks-1,minecraft:planks-1,minecraft:planks-1
rule19=0,100,minecraft:ice-0
rule20=0,60,ChestGenHook:chests/simple_dungeon:4-5,air,air
rule21=0,100,MobSpawner:skeleton,MobSpawner:stray,MobSpawner:zombie,MobSpawner:witch,minecraft:log-1,minecraft:log-1,minecraft:log-1,minecraft:log-1
rule22=0,100,minecraft:wooden_slab-1

layer
1,1,1,1,1,1,1,1,1,1,1,1,1,1,1,1,1,1,1,1,1,1,1
1,1,1,1,1,1,1,1,1,2,2,2,2,2,1,1,1,1,1,1,1,1,1
1,1,1,1,1,1,1,2,3,3,3,3,3,3,3,2,1,1,1,1,1,1,1
1,1,1,1,1,2,2,3,3,3,3,3,3,3,3,3,2,2,1,1,1,1,1
1,1,1,1,3,3,3,3,3,3,3,3,3,3,3,3,3,3,3,1,1,1,1
1,1,1,2,3,3,3,3,3,3,3,3,3,3,3,3,3,3,3,2,1,1,1
1,1,1,2,3,3,3,3,3,3,3,3,3,3,3,3,3,3,3,2,1,1,1
1,1,2,3,3,3,3,3,3,3,3,3,3,3,3,3,3,3,3,3,2,1,1
1,1,3,3,3,3,3,3,3,3,3,3,3,3,3,3,3,3,3,3,3,1,1
1,2,3,3,3,3,3,3,3,3,3,3,3,3,3,3,3,3,3,3,3,2,1
1,2,3,3,3,3,3,3,3,3,3,3,3,3,3,3,3,3,3,3,3,2,1
1,2,3,3,3,3,3,3,3,3,3,3,3,3,3,3,3,3,3,3,3,2,1
1,2,3,3,3,3,3,3,3,3,3,3,3,3,3,3,3,3,3,3,3,2,1
1,2,3,3,3,3,3,3,3,3,3,3,3,3,3,3,3,3,3,3,3,2,1
1,1,3,3,3,3,3,3,3,3,3,3,3,3,3,3,3,3,3,3,3,1,1
1,1,2,3,3,3,3,3,3,3,3,3,3,3,3,3,3,3,3,3,2,1,1
1,1,1,2,3,3,3,3,3,3,3,3,3,3,3,3,3,3,3,2,1,1,1
1,1,1,2,3,3,3,3,3,3,3,3,3,3,3,3,3,3,3,2,1,1,1
1,1,1,1,3,3,3,3,3,3,3,3,3,3,3,3,3,3,3,1,1,1,1
1,1,1,1,1,2,2,3,3,3,3,3,3,3,3,3,2,2,1,1,1,1,1
1,1,1,1,1,1,1,2,3,3,3,3,3,3,3,2,1,1,1,1,1,1,1
1,1,1,1,1,1,1,1,1,2,2,2,2,2,1,1,1,1,1,1,1,1,1
1,1,1,1,1,1,1,1,1,1,1,1,1,1,1,1,1,1,1,1,1,1,1
endlayer

layer
1,1,1,1,1,1,1,1,1,1,1,1,1,1,1,1,1,1,1,1,1,1,1
1,1,1,1,1,1,1,1,1,2,2,2,2,2,1,1,1,1,1,1,1,1,1
1,1,1,1,1,1,1,2,3,4,0,0,0,4,3,2,1,1,1,1,1,1,1
1,1,1,1,1,2,2,0,0,0,0,0,0,0,0,0,2,2,1,1,1,1,1
1,1,1,1,3,0,4,0,0,0,0,0,0,0,0,0,4,0,3,1,1,1,1
1,1,1,2,0,0,0,0,0,0,0,0,0,0,0,0,0,0,0,2,1,1,1
1,1,1,2,4,0,0,0,0,0,0,0,0,0,0,0,0,0,4,2,1,1,1
1,1,2,0,0,0,0,0,0,0,0,0,0,0,0,0,0,0,0,0,2,1,1
1,1,3,0,0,0,0,0,0,0,0,0,0,0,0,0,0,0,0,0,3,1,1
1,2,4,0,0,0,0,0,0,7,6,6,6,5,0,0,0,0,0,0,4,2,1
1,2,0,0,0,0,0,0,0,7,8,8,8,5,0,0,0,0,0,0,0,2,1
1,2,10,0,0,0,0,0,0,7,8,8,8,5,0,0,0,0,0,0,9,2,1
1,2,0,0,0,0,0,0,0,7,8,8,8,5,0,0,0,0,0,0,0,2,1
1,2,4,0,0,0,0,0,0,7,11,11,11,11,0,0,0,0,0,0,4,2,1
1,1,3,0,0,0,0,0,0,0,0,0,0,0,0,0,0,0,0,0,3,1,1
1,1,2,0,0,0,0,0,0,0,0,0,0,0,0,0,0,0,0,0,2,1,1
1,1,1,2,4,0,0,0,0,0,0,0,0,0,0,0,0,0,4,2,1,1,1
1,1,1,2,0,0,0,0,0,0,0,0,0,0,0,0,0,0,0,2,1,1,1
1,1,1,1,3,0,4,0,0,0,0,0,0,0,0,0,4,0,3,1,1,1,1
1,1,1,1,1,2,2,0,0,0,0,0,0,0,0,0,2,2,1,1,1,1,1
1,1,1,1,1,1,1,2,3,4,0,12,0,4,3,2,1,1,1,1,1,1,1
1,1,1,1,1,1,1,1,1,2,2,2,2,2,1,1,1,1,1,1,1,1,1
1,1,1,1,1,1,1,1,1,1,1,1,1,1,1,1,1,1,1,1,1,1,1
endlayer

layer
1,1,1,1,1,1,1,1,1,1,1,1,1,1,1,1,1,1,1,1,1,1,1
1,1,1,1,1,1,1,1,1,2,2,2,2,2,1,1,1,1,1,1,1,1,1
1,1,1,1,1,1,1,2,3,4,0,0,0,4,3,2,1,1,1,1,1,1,1
1,1,1,1,1,2,2,0,0,0,0,0,0,0,0,0,2,2,1,1,1,1,1
1,1,1,1,3,0,4,0,0,0,0,0,0,0,0,0,4,0,3,1,1,1,1
1,1,1,2,0,0,0,0,0,0,0,0,0,0,0,0,0,0,0,2,1,1,1
1,1,1,2,4,0,0,0,0,0,0,0,0,0,0,0,0,0,4,2,1,1,1
1,1,2,0,0,0,0,0,0,0,0,0,0,0,0,0,0,0,0,0,2,1,1
1,1,3,0,0,0,0,0,0,0,0,0,0,0,0,0,0,0,0,0,3,1,1
1,2,4,0,0,0,0,0,0,0,0,0,0,0,0,0,0,0,0,0,4,2,1
1,2,0,0,0,0,0,0,0,0,8,13,8,0,0,0,0,0,0,0,0,2,1
1,2,0,0,0,0,0,0,0,0,8,8,8,0,0,0,0,0,0,0,0,2,1
1,2,0,0,0,0,0,0,0,0,8,8,8,0,0,0,0,0,0,0,0,2,1
1,2,4,0,0,0,0,0,0,0,0,0,0,0,0,0,0,0,0,0,4,2,1
1,1,3,0,0,0,0,0,0,0,0,0,0,0,0,0,0,0,0,0,3,1,1
1,1,2,0,0,0,0,0,0,0,0,0,0,0,0,0,0,0,0,0,2,1,1
1,1,1,2,4,0,0,0,0,0,0,0,0,0,0,0,0,0,4,2,1,1,1
1,1,1,2,0,0,0,0,0,0,0,0,0,0,0,0,0,0,0,2,1,1,1
1,1,1,1,3,0,4,0,0,0,0,0,0,0,0,0,4,0,3,1,1,1,1
1,1,1,1,1,2,2,0,0,0,0,0,0,0,0,0,2,2,1,1,1,1,1
1,1,1,1,1,1,1,2,3,4,0,0,0,4,3,2,1,1,1,1,1,1,1
1,1,1,1,1,1,1,1,1,2,2,2,2,2,1,1,1,1,1,1,1,1,1
1,1,1,1,1,1,1,1,1,1,1,1,1,1,1,1,1,1,1,1,1,1,1
endlayer

layer
1,1,1,1,1,1,1,1,1,1,1,1,1,1,1,1,1,1,1,1,1,1,1
1,1,1,1,1,1,1,1,1,2,2,2,2,2,1,1,1,1,1,1,1,1,1
1,1,1,1,1,1,1,2,3,4,0,0,0,4,3,2,1,1,1,1,1,1,1
1,1,1,1,1,2,2,0,0,0,0,0,0,0,0,0,2,2,1,1,1,1,1
1,1,1,1,3,0,4,0,0,0,0,0,0,0,0,0,4,0,3,1,1,1,1
1,1,1,2,0,0,0,0,0,0,0,0,0,0,0,0,0,0,0,2,1,1,1
1,1,1,2,4,0,0,0,0,0,0,0,0,0,0,0,0,0,4,2,1,1,1
1,1,2,0,0,0,0,0,0,0,0,0,0,0,0,0,0,0,0,0,2,1,1
1,1,3,0,0,0,0,0,0,0,0,0,0,0,0,0,0,0,0,0,3,1,1
1,2,4,0,0,0,0,0,0,0,0,0,0,0,0,0,0,0,0,0,4,2,1
1,2,0,0,0,0,0,0,0,0,8,13,8,0,0,0,0,0,0,0,0,2,1
1,2,0,0,0,0,0,0,0,0,8,8,8,0,0,0,0,0,0,0,0,2,1
1,2,0,0,0,0,0,0,0,0,8,8,8,0,0,0,0,0,0,0,0,2,1
1,2,4,0,0,0,0,0,0,0,0,0,0,0,0,0,0,0,0,0,4,2,1
1,1,3,0,0,0,0,0,0,0,0,0,0,0,0,0,0,0,0,0,3,1,1
1,1,2,0,0,0,0,0,0,0,0,0,0,0,0,0,0,0,0,0,2,1,1
1,1,1,2,4,0,0,0,0,0,0,0,0,0,0,0,0,0,4,2,1,1,1
1,1,1,2,0,0,0,0,0,0,0,0,0,0,0,0,0,0,0,2,1,1,1
1,1,1,1,3,0,4,0,0,0,0,0,0,0,0,0,4,0,3,1,1,1,1
1,1,1,1,1,2,2,0,0,0,0,0,0,0,0,0,2,2,1,1,1,1,1
1,1,1,1,1,1,1,2,3,4,0,0,0,4,3,2,1,1,1,1,1,1,1
1,1,1,1,1,1,1,1,1,2,2,2,2,2,1,1,1,1,1,1,1,1,1
1,1,1,1,1,1,1,1,1,1,1,1,1,1,1,1,1,1,1,1,1,1,1
endlayer

layer
1,1,1,1,1,1,1,1,1,1,1,1,1,1,1,1,1,1,1,1,1,1,1
1,1,1,1,1,1,1,1,1,2,2,2,2,2,1,1,1,1,1,1,1,1,1
1,1,1,1,1,1,1,2,3,4,4,4,4,4,3,2,1,1,1,1,1,1,1
1,1,1,1,1,2,2,0,0,0,0,0,0,0,0,0,2,2,1,1,1,1,1
1,1,1,1,3,4,4,0,0,0,0,0,0,0,0,0,4,4,3,1,1,1,1
1,1,1,2,4,0,0,0,0,0,0,0,0,0,0,0,0,0,4,2,1,1,1
1,1,1,2,4,0,0,0,0,0,0,0,0,0,0,0,0,0,4,2,1,1,1
1,1,2,0,0,0,0,0,0,0,0,0,0,0,0,0,0,0,0,0,2,1,1
1,1,3,0,0,0,0,0,0,0,0,0,0,0,0,0,0,0,0,0,3,1,1
1,2,4,0,0,0,0,0,0,15,15,15,15,14,0,0,0,0,0,0,4,2,1
1,2,4,0,0,0,0,0,0,16,8,13,8,14,0,0,0,0,0,0,4,2,1
1,2,4,0,0,0,0,0,0,16,8,8,8,14,0,0,0,0,0,0,4,2,1
1,2,4,0,0,0,0,0,0,16,8,8,8,14,0,0,0,0,0,0,4,2,1
1,2,4,0,0,0,0,0,0,17,17,17,17,17,0,0,0,0,0,0,4,2,1
1,1,3,0,0,0,0,0,0,0,0,0,0,0,0,0,0,0,0,0,3,1,1
1,1,2,0,0,0,0,0,0,0,0,0,0,0,0,0,0,0,0,0,2,1,1
1,1,1,2,4,0,0,0,0,0,0,0,0,0,0,0,0,0,4,2,1,1,1
1,1,1,2,4,0,0,0,0,0,0,0,0,0,0,0,0,0,4,2,1,1,1
1,1,1,1,3,4,4,0,0,0,0,0,0,0,0,0,4,4,3,1,1,1,1
1,1,1,1,1,2,2,0,0,0,0,0,0,0,0,0,2,2,1,1,1,1,1
1,1,1,1,1,1,1,2,3,4,4,4,4,4,3,2,1,1,1,1,1,1,1
1,1,1,1,1,1,1,1,1,2,2,2,2,2,1,1,1,1,1,1,1,1,1
1,1,1,1,1,1,1,1,1,1,1,1,1,1,1,1,1,1,1,1,1,1,1
endlayer

layer
1,1,1,1,1,1,1,1,1,1,1,1,1,1,1,1,1,1,1,1,1,1,1
1,1,1,1,1,1,1,1,1,2,2,2,2,2,1,1,1,1,1,1,1,1,1
1,1,1,1,1,1,1,2,2,3,3,3,3,3,2,2,1,1,1,1,1,1,1
1,1,1,1,1,2,2,3,3,3,3,3,3,3,3,3,2,2,1,1,1,1,1
1,1,1,1,2,3,3,3,3,3,3,3,3,3,3,3,3,3,2,1,1,1,1
1,1,1,2,3,3,3,3,3,3,3,3,3,3,3,3,3,3,3,2,1,1,1
1,1,1,2,3,3,3,3,3,3,3,3,3,3,3,3,3,3,3,2,1,1,1
1,1,2,3,3,3,3,3,3,3,3,3,3,3,3,3,3,3,3,3,2,1,1
1,1,2,3,3,3,3,3,3,3,3,3,3,3,3,3,3,3,3,3,2,1,1
1,2,3,3,3,3,3,3,3,3,3,3,3,3,3,3,3,3,3,3,3,2,1
1,2,3,3,3,3,3,3,3,3,8,13,8,3,3,3,3,3,3,3,3,2,1
1,2,3,3,3,3,3,3,3,3,8,8,8,3,3,3,3,3,3,3,3,2,1
1,2,3,3,3,3,3,3,3,3,8,8,8,3,3,3,3,3,3,3,3,2,1
1,2,3,3,3,3,3,3,3,3,3,3,3,3,3,3,3,3,3,3,3,2,1
1,1,2,3,3,3,3,3,3,3,3,3,3,3,3,3,3,3,3,3,2,1,1
1,1,2,3,3,3,3,3,3,3,3,3,3,3,3,3,3,3,3,3,2,1,1
1,1,1,2,3,3,3,3,3,3,3,3,3,3,3,3,3,3,3,2,1,1,1
1,1,1,2,3,3,3,3,3,3,3,3,3,3,3,3,3,3,3,2,1,1,1
1,1,1,1,2,3,3,3,3,3,3,3,3,3,3,3,3,3,2,1,1,1,1
1,1,1,1,1,2,2,3,3,3,3,3,3,3,3,3,2,2,1,1,1,1,1
1,1,1,1,1,1,1,2,2,3,3,3,3,3,2,2,1,1,1,1,1,1,1
1,1,1,1,1,1,1,1,1,2,2,2,2,2,1,1,1,1,1,1,1,1,1
1,1,1,1,1,1,1,1,1,1,1,1,1,1,1,1,1,1,1,1,1,1,1
endlayer

layer
1,1,1,1,1,1,1,1,1,1,1,1,1,1,1,1,1,1,1,1,1,1,1
1,1,1,1,1,1,1,1,1,2,2,2,2,2,1,1,1,1,1,1,1,1,1
1,1,1,1,1,1,1,2,2,4,0,0,0,4,2,2,1,1,1,1,1,1,1
1,1,1,1,1,2,2,0,0,0,0,0,0,0,0,0,2,2,1,1,1,1,1
1,1,1,1,2,0,0,0,0,0,0,0,0,0,0,0,0,0,2,1,1,1,1
1,1,1,2,0,0,0,0,0,0,0,0,0,0,0,0,0,0,0,2,1,1,1
1,1,1,2,0,0,0,0,0,0,0,0,0,0,0,0,0,0,0,2,1,1,1
1,1,2,0,0,0,0,0,0,0,0,0,0,0,0,0,0,0,0,0,2,1,1
1,1,2,0,0,0,0,0,0,0,0,0,0,0,0,0,0,0,0,0,2,1,1
1,2,4,0,0,0,0,0,0,6,6,6,6,6,0,0,0,0,0,0,4,2,1
1,2,0,0,0,0,0,0,0,7,8,13,8,5,0,0,0,0,0,0,0,0,1
1,2,0,0,0,0,0,0,0,7,8,8,8,5,0,0,0,0,0,0,0,0,1
1,2,0,0,0,0,0,0,0,18,8,8,8,5,0,0,0,0,0,0,0,0,1
1,2,4,0,0,0,0,0,0,11,11,11,11,11,0,0,0,0,0,0,4,2,1
1,1,2,0,0,0,0,0,0,0,0,0,0,0,0,0,0,0,0,0,2,1,1
1,1,2,0,0,0,0,0,0,0,0,0,0,0,0,0,0,0,0,0,2,1,1
1,1,1,2,0,0,0,0,0,0,0,0,0,0,0,0,0,0,0,2,1,1,1
1,1,1,2,0,0,0,0,0,0,0,0,0,0,0,0,0,0,0,2,1,1,1
1,1,1,1,2,0,0,0,0,0,0,0,0,0,0,0,0,0,2,1,1,1,1
1,1,1,1,1,2,2,0,0,0,0,0,0,0,0,0,2,2,1,1,1,1,1
1,1,1,1,1,1,1,2,2,4,0,0,0,4,2,2,1,1,1,1,1,1,1
1,1,1,1,1,1,1,1,1,2,2,2,2,2,1,1,1,1,1,1,1,1,1
1,1,1,1,1,1,1,1,1,1,1,1,1,1,1,1,1,1,1,1,1,1,1
endlayer

layer
1,1,1,1,1,1,1,1,1,1,1,1,1,1,1,1,1,1,1,1,1,1,1
1,1,1,1,1,1,1,1,1,2,19,19,19,2,1,1,1,1,1,1,1,1,1
1,1,1,1,1,1,1,19,2,4,0,0,0,4,2,19,1,1,1,1,1,1,1
1,1,1,1,1,19,19,0,0,0,0,0,0,0,0,0,19,19,1,1,1,1,1
1,1,1,1,2,0,0,0,0,0,0,0,0,0,0,0,0,0,2,1,1,1,1
1,1,1,19,0,0,0,0,0,0,0,0,0,0,0,0,0,0,0,19,1,1,1
1,1,1,19,0,0,0,0,0,0,0,0,0,0,0,0,0,0,0,19,1,1,1
1,1,19,0,0,0,0,0,0,0,0,0,0,0,0,0,0,0,0,0,19,1,1
1,1,2,0,0,0,0,0,0,0,0,0,0,0,0,0,0,0,0,0,2,1,1
1,2,4,0,0,0,0,0,0,0,0,0,0,0,0,0,0,0,0,0,4,2,1
1,19,0,0,0,0,0,0,0,0,8,13,8,0,0,0,0,0,0,0,0,0,1
1,19,0,0,0,0,0,0,0,15,8,8,8,0,0,0,0,0,0,0,0,0,1
1,19,0,0,0,0,0,0,0,11,8,8,8,0,0,0,0,0,0,0,0,0,1
1,2,4,0,0,0,0,0,0,0,0,0,0,0,0,0,0,0,0,0,4,2,1
1,1,2,0,0,0,0,0,0,0,0,0,0,0,0,0,0,0,0,0,2,1,1
1,1,19,0,0,0,0,0,0,0,0,0,0,0,0,0,0,0,0,0,19,1,1
1,1,1,19,0,0,0,0,0,0,0,0,0,0,0,0,0,0,0,19,1,1,1
1,1,1,19,0,0,0,0,0,0,0,0,0,0,0,0,0,0,0,19,1,1,1
1,1,1,1,2,0,0,0,0,0,0,0,0,0,0,0,0,0,2,1,1,1,1
1,1,1,1,1,19,19,0,0,0,0,0,0,0,0,0,19,19,1,1,1,1,1
1,1,1,1,1,1,1,19,2,4,0,0,0,4,2,19,1,1,1,1,1,1,1
1,1,1,1,1,1,1,1,1,2,19,19,19,2,1,1,1,1,1,1,1,1,1
1,1,1,1,1,1,1,1,1,1,1,1,1,1,1,1,1,1,1,1,1,1,1
endlayer

layer
1,1,1,1,1,1,1,1,1,1,1,1,1,1,1,1,1,1,1,1,1,1,1
1,1,1,1,1,1,1,1,1,2,19,19,19,2,1,1,1,1,1,1,1,1,1
1,1,1,1,1,1,1,19,2,4,0,0,0,4,2,19,1,1,1,1,1,1,1
1,1,1,1,1,19,19,0,0,0,0,0,0,0,0,0,19,19,1,1,1,1,1
1,1,1,1,2,0,0,0,0,0,0,0,0,0,0,0,0,0,2,1,1,1,1
1,1,1,19,0,0,0,0,0,0,0,0,0,0,0,0,0,0,0,19,1,1,1
1,1,1,19,0,0,0,0,0,0,0,0,0,0,0,0,0,0,0,19,1,1,1
1,1,19,0,0,0,0,0,0,0,0,0,0,0,0,0,0,0,0,0,19,1,1
1,1,2,0,0,0,0,0,0,0,0,0,0,0,0,0,0,0,0,0,2,1,1
1,2,4,0,0,0,0,0,0,0,0,0,0,0,0,0,0,0,0,0,4,2,1
1,19,0,0,0,0,0,0,0,15,8,13,8,0,0,0,0,0,0,0,0,0,1
1,19,0,0,0,0,0,0,0,11,8,8,8,0,0,0,0,0,0,0,0,0,1
1,19,0,0,0,0,0,0,0,0,8,8,8,0,0,0,0,0,0,0,0,0,1
1,2,4,0,0,0,0,0,0,0,0,0,0,0,0,0,0,0,0,0,4,2,1
1,1,2,0,0,0,0,0,0,0,0,0,0,0,0,0,0,0,0,0,2,1,1
1,1,19,0,0,0,0,0,0,0,0,0,0,0,0,0,0,0,0,0,19,1,1
1,1,1,19,0,0,0,0,0,0,0,0,0,0,0,0,0,0,0,19,1,1,1
1,1,1,19,0,0,0,0,0,0,0,0,0,0,0,0,0,0,0,19,1,1,1
1,1,1,1,2,0,0,0,0,0,0,0,0,0,0,0,0,0,2,1,1,1,1
1,1,1,1,1,19,19,0,0,0,0,0,0,0,0,0,19,19,1,1,1,1,1
1,1,1,1,1,1,1,19,2,4,0,0,0,4,2,19,1,1,1,1,1,1,1
1,1,1,1,1,1,1,1,1,2,19,19,19,2,1,1,1,1,1,1,1,1,1
1,1,1,1,1,1,1,1,1,1,1,1,1,1,1,1,1,1,1,1,1,1,1
endlayer

layer
1,1,1,1,1,1,1,1,1,1,1,1,1,1,1,1,1,1,1,1,1,1,1
1,1,1,1,1,1,1,1,1,2,2,2,2,2,1,1,1,1,1,1,1,1,1
1,1,1,1,1,1,1,2,2,4,0,0,0,4,2,2,1,1,1,1,1,1,1
1,1,1,1,1,2,2,0,0,0,0,0,0,0,0,0,2,2,1,1,1,1,1
1,1,1,1,2,0,0,0,0,0,0,0,0,0,0,0,0,0,2,1,1,1,1
1,1,1,2,0,0,0,0,0,0,0,0,0,0,0,0,0,0,0,2,1,1,1
1,1,1,2,0,0,0,0,0,0,0,0,0,0,0,0,0,0,0,2,1,1,1
1,1,2,0,0,0,0,0,0,0,0,0,0,0,0,0,0,0,0,0,2,1,1
1,1,2,0,0,0,0,0,0,0,0,0,0,0,0,0,0,0,0,0,2,1,1
1,2,4,0,0,0,0,0,0,15,15,15,15,15,0,0,0,0,0,0,4,2,1
1,2,0,0,0,0,0,0,0,11,8,8,8,14,0,0,0,0,0,0,0,19,1
1,2,0,0,0,0,0,0,0,0,8,8,8,14,0,0,0,0,0,0,0,19,1
1,2,0,0,0,0,0,0,0,0,8,8,8,14,0,0,0,0,0,0,0,19,1
1,2,4,0,0,0,0,0,0,0,17,17,17,17,0,0,0,0,0,0,4,2,1
1,1,2,0,0,0,0,0,0,0,0,0,0,0,0,0,0,0,0,0,2,1,1
1,1,2,0,0,0,0,0,0,0,0,0,0,0,0,0,0,0,0,0,2,1,1
1,1,1,2,0,0,0,0,0,0,0,0,0,0,0,0,0,0,0,2,1,1,1
1,1,1,2,0,0,0,0,0,0,0,0,0,0,0,0,0,0,0,2,1,1,1
1,1,1,1,2,0,0,0,0,0,0,0,0,0,0,0,0,0,2,1,1,1,1
1,1,1,1,1,2,2,0,0,0,0,0,0,0,0,0,2,2,1,1,1,1,1
1,1,1,1,1,1,1,2,2,4,0,0,0,4,2,2,1,1,1,1,1,1,1
1,1,1,1,1,1,1,1,1,2,2,2,2,2,1,1,1,1,1,1,1,1,1
1,1,1,1,1,1,1,1,1,1,1,1,1,1,1,1,1,1,1,1,1,1,1
endlayer

layer
1,1,1,1,1,1,1,1,1,1,1,1,1,1,1,1,1,1,1,1,1,1,1
1,1,1,1,1,1,1,1,1,2,2,2,2,2,1,1,1,1,1,1,1,1,1
1,1,1,1,1,1,1,2,2,18,18,18,18,18,2,2,1,1,1,1,1,1,1
1,1,1,1,1,2,2,18,18,18,18,18,18,18,18,18,2,2,1,1,1,1,1
1,1,1,1,2,18,18,18,18,18,18,18,18,18,18,18,18,18,2,1,1,1,1
1,1,1,2,18,18,18,18,18,18,18,18,18,18,18,18,18,18,18,2,1,1,1
1,1,1,2,18,18,18,18,18,18,18,18,18,18,18,18,18,18,18,2,1,1,1
1,1,2,18,18,18,18,18,18,18,18,18,18,18,18,18,18,18,18,18,2,1,1
1,1,2,18,18,18,18,18,18,18,18,18,18,18,18,18,18,18,18,18,2,1,1
1,2,18,18,18,18,18,18,18,11,18,18,18,18,18,18,18,18,18,18,18,2,1
1,2,18,18,18,18,18,18,18,0,8,8,8,18,18,18,18,18,18,18,18,2,1
1,2,18,18,18,18,18,18,18,0,8,8,8,18,18,18,18,18,18,18,18,2,1
1,2,18,18,18,18,18,18,18,0,8,8,8,18,18,18,18,18,18,18,18,2,1
1,2,18,18,18,18,18,18,18,15,18,18,18,18,18,18,18,18,18,18,18,2,1
1,1,2,18,18,18,18,18,18,18,18,18,18,18,18,18,18,18,18,18,2,1,1
1,1,2,18,18,18,18,18,18,18,18,18,18,18,18,18,18,18,18,18,2,1,1
1,1,1,2,18,18,18,18,18,18,18,18,18,18,18,18,18,18,18,2,1,1,1
1,1,1,2,18,18,18,18,18,18,18,18,18,18,18,18,18,18,18,2,1,1,1
1,1,1,1,2,18,18,18,18,18,18,18,18,18,18,18,18,18,2,1,1,1,1
1,1,1,1,1,2,2,18,18,18,18,18,18,18,18,18,2,2,1,1,1,1,1
1,1,1,1,1,1,1,2,2,18,18,18,18,18,2,2,1,1,1,1,1,1,1
1,1,1,1,1,1,1,1,1,2,2,2,2,2,1,1,1,1,1,1,1,1,1
1,1,1,1,1,1,1,1,1,1,1,1,1,1,1,1,1,1,1,1,1,1,1
endlayer

layer
1,1,1,1,1,1,1,1,1,1,1,1,1,1,1,1,1,1,1,1,1,1,1
1,1,1,1,1,1,1,1,1,0,0,0,0,0,1,1,1,1,1,1,1,1,1
1,1,1,1,1,1,1,0,2,2,2,2,2,2,2,0,1,1,1,1,1,1,1
1,1,1,1,1,0,0,2,2,4,0,20,0,4,2,2,0,0,1,1,1,1,1
1,1,1,1,0,2,2,0,0,0,0,0,0,0,0,0,2,2,0,1,1,1,1
1,1,1,0,2,0,0,0,0,0,0,0,0,0,0,0,0,0,2,0,1,1,1
1,1,1,0,2,0,0,0,0,0,0,0,0,0,0,0,0,0,2,0,1,1,1
1,1,0,2,0,0,0,0,0,0,0,0,0,0,0,0,0,0,0,2,0,1,1
1,1,2,2,0,0,0,0,0,0,0,0,0,0,0,0,0,0,0,2,2,1,1
1,0,2,4,0,0,0,0,0,0,6,6,6,5,0,0,0,0,0,4,2,0,1
1,0,2,0,0,0,0,0,0,0,8,8,8,5,0,0,0,0,0,0,2,0,1
1,0,2,0,0,0,0,0,0,0,8,8,8,5,0,0,0,0,0,0,2,0,1
1,0,2,0,0,0,0,0,0,0,8,8,8,5,0,0,0,0,0,0,2,0,1
1,0,2,4,0,0,0,0,0,7,11,11,18,5,0,0,0,0,0,4,2,0,1
1,1,2,2,0,0,0,0,0,0,0,0,0,0,0,0,0,0,0,2,2,1,1
1,1,0,2,0,0,0,0,0,0,0,0,0,0,0,0,0,0,0,2,0,1,1
1,1,1,0,2,0,0,0,0,0,0,0,0,0,0,0,0,0,2,0,1,1,1
1,1,1,0,2,0,0,0,0,0,0,0,0,0,0,0,0,0,2,0,1,1,1
1,1,1,1,0,2,2,0,0,0,0,0,0,0,0,0,2,2,0,1,1,1,1
1,1,1,1,1,0,0,2,2,4,0,12,0,4,2,2,0,0,1,1,1,1,1
1,1,1,1,1,1,1,0,2,2,2,2,2,2,2,0,1,1,1,1,1,1,1
1,1,1,1,1,1,1,1,1,0,0,0,0,0,1,1,1,1,1,1,1,1,1
1,1,1,1,1,1,1,1,1,1,1,1,1,1,1,1,1,1,1,1,1,1,1
endlayer

layer
1,1,1,1,1,1,1,1,1,1,1,1,1,1,1,1,1,1,1,1,1,1,1
1,1,1,1,1,1,1,1,1,0,0,0,0,0,1,1,1,1,1,1,1,1,1
1,1,1,1,1,1,1,0,0,2,19,19,19,2,0,0,1,1,1,1,1,1,1
1,1,1,1,1,0,0,2,2,4,0,0,0,4,2,2,0,0,1,1,1,1,1
1,1,1,1,0,19,19,0,0,0,0,0,0,0,0,0,19,19,0,1,1,1,1
1,1,1,0,19,0,0,0,0,0,0,0,0,0,0,0,0,0,19,0,1,1,1
1,1,1,0,19,0,0,0,0,0,0,0,0,0,0,0,0,0,19,0,1,1,1
1,1,0,2,0,0,0,0,0,0,0,0,0,0,0,0,0,0,0,2,0,1,1
1,1,0,2,0,0,0,0,0,0,0,0,0,0,0,0,0,0,0,2,0,1,1
1,0,2,4,0,0,0,0,0,0,0,0,0,0,0,0,0,0,0,4,2,0,1
1,0,19,0,0,0,0,0,0,0,8,8,8,0,0,0,0,0,0,0,19,0,1
1,0,19,0,0,0,0,0,0,0,8,21,8,0,0,0,0,0,0,0,19,0,1
1,0,19,0,0,0,0,0,0,0,8,8,8,0,0,0,0,0,0,0,19,0,1
1,0,2,4,0,0,0,0,0,0,0,16,5,0,0,0,0,0,0,4,2,0,1
1,1,0,2,0,0,0,0,0,0,0,0,0,0,0,0,0,0,0,2,0,1,1
1,1,0,2,0,0,0,0,0,0,0,0,0,0,0,0,0,0,0,2,0,1,1
1,1,1,0,19,0,0,0,0,0,0,0,0,0,0,0,0,0,19,0,1,1,1
1,1,1,0,19,0,0,0,0,0,0,0,0,0,0,0,0,0,19,0,1,1,1
1,1,1,1,0,19,19,0,0,0,0,0,0,0,0,0,19,19,0,1,1,1,1
1,1,1,1,1,0,0,2,2,4,0,0,0,4,2,2,0,0,1,1,1,1,1
1,1,1,1,1,1,1,0,0,2,19,19,19,2,0,0,1,1,1,1,1,1,1
1,1,1,1,1,1,1,1,1,0,0,0,0,0,1,1,1,1,1,1,1,1,1
1,1,1,1,1,1,1,1,1,1,1,1,1,1,1,1,1,1,1,1,1,1,1
endlayer

layer
1,1,1,1,1,1,1,1,1,1,1,1,1,1,1,1,1,1,1,1,1,1,1
1,1,1,1,1,1,1,1,1,0,0,0,0,0,1,1,1,1,1,1,1,1,1
1,1,1,1,1,1,1,0,0,2,19,19,19,2,0,0,1,1,1,1,1,1,1
1,1,1,1,1,0,0,2,2,4,0,0,0,4,2,2,0,0,1,1,1,1,1
1,1,1,1,0,19,19,0,0,0,0,0,0,0,0,0,19,19,0,1,1,1,1
1,1,1,0,19,0,0,0,0,0,0,0,0,0,0,0,0,0,19,0,1,1,1
1,1,1,0,19,0,0,0,0,0,0,0,0,0,0,0,0,0,19,0,1,1,1
1,1,0,2,0,0,0,0,0,0,0,0,0,0,0,0,0,0,0,2,0,1,1
1,1,0,2,0,0,0,0,0,0,0,0,0,0,0,0,0,0,0,2,0,1,1
1,0,2,4,0,0,0,0,0,0,0,0,0,0,0,0,0,0,0,4,2,0,1
1,0,19,0,0,0,0,0,0,0,8,8,8,0,0,0,0,0,0,0,19,0,1
1,0,19,0,0,0,0,0,0,0,8,8,8,0,0,0,0,0,0,0,19,0,1
1,0,19,0,0,0,0,0,0,0,8,8,8,0,0,0,0,0,0,0,19,0,1
1,0,2,4,0,0,0,0,0,0,16,5,0,0,0,0,0,0,0,4,2,0,1
1,1,0,2,0,0,0,0,0,0,0,0,0,0,0,0,0,0,0,2,0,1,1
1,1,0,2,0,0,0,0,0,0,0,0,0,0,0,0,0,0,0,2,0,1,1
1,1,1,0,19,0,0,0,0,0,0,0,0,0,0,0,0,0,19,0,1,1,1
1,1,1,0,19,0,0,0,0,0,0,0,0,0,0,0,0,0,19,0,1,1,1
1,1,1,1,0,19,19,0,0,0,0,0,0,0,0,0,19,19,0,1,1,1,1
1,1,1,1,1,0,0,2,2,4,0,0,0,4,2,2,0,0,1,1,1,1,1
1,1,1,1,1,1,1,0,0,2,19,19,19,2,0,0,1,1,1,1,1,1,1
1,1,1,1,1,1,1,1,1,0,0,0,0,0,1,1,1,1,1,1,1,1,1
1,1,1,1,1,1,1,1,1,1,1,1,1,1,1,1,1,1,1,1,1,1,1
endlayer

layer
1,1,1,1,1,1,1,1,1,2,1,2,1,2,1,1,1,1,1,1,1,1,1
1,1,1,1,1,1,1,2,1,0,0,0,0,0,1,2,1,1,1,1,1,1,1
1,1,1,1,1,2,1,0,0,2,2,2,2,2,0,0,1,2,1,1,1,1,1
1,1,1,2,1,0,0,2,2,4,0,0,0,4,2,2,0,0,1,2,1,1,1
1,1,1,1,0,2,2,0,0,0,0,0,0,0,0,0,2,2,0,1,1,1,1
1,1,2,0,2,0,0,0,0,0,0,0,0,0,0,0,0,0,2,0,2,1,1
1,1,1,0,2,0,0,0,0,0,0,0,0,0,0,0,0,0,2,0,1,1,1
1,2,0,2,0,0,0,0,0,0,0,0,0,0,0,0,0,0,0,2,0,2,1
1,1,0,2,0,0,0,0,0,0,0,0,0,0,0,0,0,0,0,2,0,1,1
2,0,2,4,0,0,0,0,0,15,15,15,15,14,0,0,0,0,0,4,2,0,2
1,0,2,0,0,0,0,0,0,16,8,8,8,14,0,0,0,0,0,0,2,0,1
2,0,2,0,0,0,0,0,0,16,8,8,8,14,0,0,0,0,0,0,2,0,2
1,0,2,0,0,0,0,0,0,16,8,8,8,14,0,0,0,0,0,0,2,0,1
2,0,2,4,0,0,0,0,0,16,5,0,0,0,0,0,0,0,0,4,2,0,2
1,1,0,2,0,0,0,0,0,0,0,0,0,0,0,0,0,0,0,2,0,1,1
1,2,0,2,0,0,0,0,0,0,0,0,0,0,0,0,0,0,0,2,0,2,1
1,1,1,0,2,0,0,0,0,0,0,0,0,0,0,0,0,0,2,0,1,1,1
1,1,2,0,2,0,0,0,0,0,0,0,0,0,0,0,0,0,2,0,2,1,1
1,1,1,1,0,2,2,0,0,0,0,0,0,0,0,0,2,2,0,1,1,1,1
1,1,1,2,1,0,0,2,2,4,0,0,0,4,2,2,0,0,1,2,1,1,1
1,1,1,1,1,2,1,0,0,2,2,2,2,2,0,0,1,2,1,1,1,1,1
1,1,1,1,1,1,1,2,1,0,0,0,0,0,1,2,1,1,1,1,1,1,1
1,1,1,1,1,1,1,1,1,2,1,2,1,2,1,1,1,1,1,1,1,1,1
endlayer

layer
1,1,1,1,1,1,1,1,1,2,1,2,1,2,1,1,1,1,1,1,1,1,1
1,1,1,1,1,1,1,2,1,2,2,2,2,2,1,2,1,1,1,1,1,1,1
1,1,1,1,1,2,1,2,2,2,2,2,2,2,2,2,1,2,1,1,1,1,1
1,1,1,2,1,2,2,2,2,18,18,18,18,18,2,2,2,2,1,2,1,1,1
1,1,1,1,2,2,2,18,18,18,18,18,18,18,18,18,2,2,2,1,1,1,1
1,1,2,2,2,18,18,18,18,18,18,18,18,18,18,18,18,18,2,2,2,1,1
1,1,1,2,2,18,18,18,18,18,18,18,18,18,18,18,18,18,2,2,1,1,1
1,2,2,2,18,18,18,18,18,18,18,18,18,18,18,18,18,18,18,2,2,2,1
1,1,2,2,18,18,18,18,18,18,18,18,18,18,18,18,18,18,18,2,2,1,1
2,2,2,18,18,18,18,18,18,18,18,18,18,18,18,18,18,18,18,18,2,2,2
1,2,2,18,18,18,18,18,18,18,8,8,8,18,18,18,18,18,18,18,2,2,1
2,2,2,18,18,18,18,18,18,18,8,8,8,18,18,18,18,18,18,18,2,2,2
1,2,2,18,18,18,18,18,18,18,8,8,8,18,18,18,18,18,18,18,2,2,1
2,2,2,18,18,18,18,18,18,5,0,0,0,16,18,18,18,18,18,18,2,2,2
1,1,2,2,18,18,18,18,18,18,18,18,18,18,18,18,18,18,18,2,2,1,1
1,2,2,2,18,18,18,18,18,18,18,18,18,18,18,18,18,18,18,2,2,2,1
1,1,1,2,2,18,18,18,18,18,18,18,18,18,18,18,18,18,2,2,1,1,1
1,1,2,2,2,18,18,18,18,18,18,18,18,18,18,18,18,18,2,2,2,1,1
1,1,1,1,2,2,2,18,18,18,18,18,18,18,18,18,2,2,2,1,1,1,1
1,1,1,2,1,2,2,2,2,18,18,18,18,18,2,2,2,2,1,2,1,1,1
1,1,1,1,1,2,1,2,2,2,2,2,2,2,2,2,1,2,1,1,1,1,1
1,1,1,1,1,1,1,2,1,2,2,2,2,2,1,2,1,1,1,1,1,1,1
1,1,1,1,1,1,1,1,1,2,1,2,1,2,1,1,1,1,1,1,1,1,1
endlayer

layer
1,1,1,1,1,1,1,1,1,2,1,2,1,2,1,1,1,1,1,1,1,1,1
1,1,1,1,1,1,1,2,1,0,0,0,0,0,1,2,1,1,1,1,1,1,1
1,1,1,1,1,2,1,0,0,0,0,0,0,0,0,0,1,2,1,1,1,1,1
1,1,1,2,1,0,0,0,0,2,2,2,2,2,0,0,0,0,1,2,1,1,1
1,1,1,1,0,0,0,2,2,0,0,4,0,0,2,2,0,0,0,1,1,1,1
1,1,2,0,0,2,2,0,0,0,0,0,0,0,0,0,2,2,0,0,2,1,1
1,1,1,0,0,2,4,0,0,0,0,0,0,0,0,0,4,2,0,0,1,1,1
1,2,0,0,2,0,0,0,0,0,0,0,0,0,0,0,0,0,2,0,0,2,1
1,1,0,0,2,0,0,0,0,0,0,0,0,0,0,0,0,0,2,0,0,1,1
2,0,0,2,0,0,0,0,0,6,6,6,6,6,0,0,0,0,0,2,0,0,2
1,0,0,2,0,0,0,0,0,7,8,8,8,18,0,0,0,0,0,2,0,0,1
2,0,0,2,4,0,0,0,0,7,8,8,8,5,0,0,0,0,4,2,0,0,2
1,0,0,2,0,0,0,0,0,7,8,8,8,5,0,0,0,0,0,2,0,0,1
2,0,0,2,0,0,0,0,0,0,0,0,0,11,0,0,0,0,0,2,0,0,2
1,1,0,0,2,0,0,0,0,0,0,0,0,0,0,0,0,0,2,0,0,1,1
1,2,0,0,2,0,0,0,0,0,0,0,0,0,0,0,0,0,2,0,0,2,1
1,1,1,0,0,2,4,0,0,0,0,0,0,0,0,0,4,2,0,0,1,1,1
1,1,2,0,0,2,2,0,0,0,0,0,0,0,0,0,2,2,0,0,2,1,1
1,1,1,1,0,0,0,2,2,0,0,4,0,0,2,2,0,0,0,1,1,1,1
1,1,1,2,1,0,0,0,0,2,2,2,2,2,0,0,0,0,1,2,1,1,1
1,1,1,1,1,2,1,0,0,0,0,0,0,0,0,0,1,2,1,1,1,1,1
1,1,1,1,1,1,1,2,1,0,0,0,0,0,1,2,1,1,1,1,1,1,1
1,1,1,1,1,1,1,1,1,2,1,2,1,2,1,1,1,1,1,1,1,1,1
endlayer

layer
1,1,1,1,1,1,1,1,1,0,1,0,1,0,1,1,1,1,1,1,1,1,1
1,1,1,1,1,1,1,0,1,0,0,0,0,0,1,0,1,1,1,1,1,1,1
1,1,1,1,1,0,1,0,0,0,0,0,0,0,0,0,1,0,1,1,1,1,1
1,1,1,0,1,0,0,0,0,19,2,2,2,19,0,0,0,0,1,0,1,1,1
1,1,1,1,0,0,0,19,19,0,0,4,0,0,19,19,0,0,0,1,1,1,1
1,1,0,0,0,2,2,0,0,0,0,0,0,0,0,0,2,2,0,0,0,1,1
1,1,1,0,0,2,4,0,0,0,0,0,0,0,0,0,4,2,0,0,1,1,1
1,0,0,0,19,0,0,0,0,0,0,0,0,0,0,0,0,0,19,0,0,0,1
1,1,0,0,19,0,0,0,0,0,0,0,0,0,0,0,0,0,19,0,0,1,1
0,0,0,19,0,0,0,0,0,0,0,0,0,0,0,0,0,0,0,19,0,0,0
1,0,0,2,0,0,0,0,0,0,8,8,8,6,0,0,0,0,0,2,0,0,1
0,0,0,2,4,0,0,0,0,0,8,21,8,17,0,0,0,0,4,2,0,0,0
1,0,0,2,0,0,0,0,0,0,8,8,8,0,0,0,0,0,0,2,0,0,1
0,0,0,19,0,0,0,0,0,0,0,0,0,0,0,0,0,0,0,19,0,0,0
1,1,0,0,19,0,0,0,0,0,0,0,0,0,0,0,0,0,19,0,0,1,1
1,0,0,0,19,0,0,0,0,0,0,0,0,0,0,0,0,0,19,0,0,0,1
1,1,1,0,0,2,4,0,0,0,0,0,0,0,0,0,4,2,0,0,1,1,1
1,1,0,0,0,2,2,0,0,0,0,0,0,0,0,0,2,2,0,0,0,1,1
1,1,1,1,0,0,0,19,19,0,0,4,0,0,19,19,0,0,0,1,1,1,1
1,1,1,0,1,0,0,0,0,19,2,2,2,19,0,0,0,0,1,0,1,1,1
1,1,1,1,1,0,1,0,0,0,0,0,0,0,0,0,1,0,1,1,1,1,1
1,1,1,1,1,1,1,0,1,0,0,0,0,0,1,0,1,1,1,1,1,1,1
1,1,1,1,1,1,1,1,1,0,1,0,1,0,1,1,1,1,1,1,1,1,1
endlayer

layer
1,1,1,1,1,1,1,1,1,0,1,0,1,0,1,1,1,1,1,1,1,1,1
1,1,1,1,1,1,1,0,1,0,0,0,0,0,1,0,1,1,1,1,1,1,1
1,1,1,1,1,0,1,0,0,0,0,0,0,0,0,0,1,0,1,1,1,1,1
1,1,1,0,1,0,0,0,0,19,2,2,2,19,0,0,0,0,1,0,1,1,1
1,1,1,1,0,0,0,19,19,0,0,4,0,0,19,19,0,0,0,1,1,1,1
1,1,0,0,0,2,2,0,0,0,0,0,0,0,0,0,2,2,0,0,0,1,1
1,1,1,0,0,2,4,0,0,0,0,0,0,0,0,0,4,2,0,0,1,1,1
1,0,0,0,19,0,0,0,0,0,0,0,0,0,0,0,0,0,19,0,0,0,1
1,1,0,0,19,0,0,0,0,0,0,0,0,0,0,0,0,0,19,0,0,1,1
0,0,0,19,0,0,0,0,0,0,0,0,0,0,0,0,0,0,0,19,0,0,0
1,0,0,2,0,0,0,0,0,0,8,8,8,0,0,0,0,0,0,2,0,0,1
0,0,0,2,4,0,0,0,0,0,8,8,8,6,0,0,0,0,4,2,0,0,0
1,0,0,2,0,0,0,0,0,0,8,8,8,17,0,0,0,0,0,2,0,0,1
0,0,0,19,0,0,0,0,0,0,0,0,0,0,0,0,0,0,0,19,0,0,0
1,1,0,0,19,0,0,0,0,0,0,0,0,0,0,0,0,0,19,0,0,1,1
1,0,0,0,19,0,0,0,0,0,0,0,0,0,0,0,0,0,19,0,0,0,1
1,1,1,0,0,2,4,0,0,0,0,0,0,0,0,0,4,2,0,0,1,1,1
1,1,0,0,0,2,2,0,0,0,0,0,0,0,0,0,2,2,0,0,0,1,1
1,1,1,1,0,0,0,19,19,0,0,4,0,0,19,19,0,0,0,1,1,1,1
1,1,1,0,1,0,0,0,0,19,2,2,2,19,0,0,0,0,1,0,1,1,1
1,1,1,1,1,0,1,0,0,0,0,0,0,0,0,0,1,0,1,1,1,1,1
1,1,1,1,1,1,1,0,1,0,0,0,0,0,1,0,1,1,1,1,1,1,1
1,1,1,1,1,1,1,1,1,0,1,0,1,0,1,1,1,1,1,1,1,1,1
endlayer

layer
1,1,1,1,1,1,1,1,1,0,1,0,1,0,1,1,1,1,1,1,1,1,1
1,1,1,1,1,1,1,0,1,2,0,2,0,2,1,0,1,1,1,1,1,1,1
1,1,1,1,1,0,1,2,0,0,0,0,0,0,0,2,1,0,1,1,1,1,1
1,1,1,0,1,2,0,0,0,2,2,2,2,2,0,0,0,2,1,0,1,1,1
1,1,1,1,0,0,0,2,2,0,0,4,0,0,2,2,0,0,0,1,1,1,1
1,1,0,2,0,2,2,0,0,0,0,0,0,0,0,0,2,2,0,2,0,1,1
1,1,1,0,0,2,4,0,0,0,0,0,0,0,0,0,4,2,0,0,1,1,1
1,0,2,0,2,0,0,0,0,0,0,0,0,0,0,0,0,0,2,0,2,0,1
1,1,0,0,2,0,0,0,0,0,0,0,0,0,0,0,0,0,2,0,0,1,1
0,2,0,2,0,0,0,0,0,16,15,15,15,0,0,0,0,0,0,2,0,2,0
1,0,0,2,0,0,0,0,0,16,8,8,8,0,0,0,0,0,0,2,0,0,1
0,2,0,2,4,0,0,0,0,16,8,8,8,0,0,0,0,0,4,2,0,2,0
1,0,0,2,0,0,0,0,0,16,8,8,8,6,0,0,0,0,0,2,0,0,1
0,2,0,2,0,0,0,0,0,17,17,17,17,17,0,0,0,0,0,2,0,2,0
1,1,0,0,2,0,0,0,0,0,0,0,0,0,0,0,0,0,2,0,0,1,1
1,0,2,0,2,0,0,0,0,0,0,0,0,0,0,0,0,0,2,0,2,0,1
1,1,1,0,0,2,4,0,0,0,0,0,0,0,0,0,4,2,0,0,1,1,1
1,1,0,2,0,2,2,0,0,0,0,0,0,0,0,0,2,2,0,2,0,1,1
1,1,1,1,0,0,0,2,2,0,0,4,0,0,2,2,0,0,0,1,1,1,1
1,1,1,0,1,2,0,0,0,2,2,2,2,2,0,0,0,2,1,0,1,1,1
1,1,1,1,1,0,1,2,0,0,0,0,0,0,0,2,1,0,1,1,1,1,1
1,1,1,1,1,1,1,0,1,2,0,2,0,2,1,0,1,1,1,1,1,1,1
1,1,1,1,1,1,1,1,1,0,1,0,1,0,1,1,1,1,1,1,1,1,1
endlayer

layer
1,1,1,1,1,1,1,1,1,0,1,0,1,0,1,1,1,1,1,1,1,1,1
1,1,1,1,1,1,1,0,1,2,0,2,0,2,1,0,1,1,1,1,1,1,1
1,1,1,1,1,0,1,2,0,2,2,2,2,2,0,2,1,0,1,1,1,1,1
1,1,1,0,1,2,0,2,2,2,2,2,2,2,2,2,0,2,1,0,1,1,1
1,1,1,1,0,2,2,2,2,18,18,18,18,18,2,2,2,2,0,1,1,1,1
1,1,0,2,2,2,2,18,18,18,18,18,18,18,18,18,2,2,2,2,0,1,1
1,1,1,0,2,2,18,18,18,18,18,18,18,18,18,18,18,2,2,0,1,1,1
1,0,2,2,2,18,18,18,18,18,18,18,18,18,18,18,18,18,2,2,2,0,1
1,1,0,2,2,18,18,18,18,18,18,18,18,18,18,18,18,18,2,2,0,1,1
0,2,2,2,18,18,18,18,18,18,18,18,18,17,18,18,18,18,18,2,2,2,0
1,0,2,2,18,18,18,18,18,18,8,8,8,0,18,18,18,18,18,2,2,0,1
0,2,2,2,18,18,18,18,18,18,8,8,8,0,18,18,18,18,18,2,2,2,0
1,0,2,2,18,18,18,18,18,18,8,8,8,0,18,18,18,18,18,2,2,0,1
0,2,2,2,18,18,18,18,18,18,18,18,18,6,18,18,18,18,18,2,2,2,0
1,1,0,2,2,18,18,18,18,18,18,18,18,18,18,18,18,18,2,2,0,1,1
1,0,2,2,2,18,18,18,18,18,18,18,18,18,18,18,18,18,2,2,2,0,1
1,1,1,0,2,2,18,18,18,18,18,18,18,18,18,18,18,2,2,0,1,1,1
1,1,0,2,2,2,2,18,18,18,18,18,18,18,18,18,2,2,2,2,0,1,1
1,1,1,1,0,2,2,2,2,18,18,18,18,18,2,2,2,2,0,1,1,1,1
1,1,1,0,1,2,0,2,2,2,2,2,2,2,2,2,0,2,1,0,1,1,1
1,1,1,1,1,0,1,2,0,2,2,2,2,2,0,2,1,0,1,1,1,1,1
1,1,1,1,1,1,1,0,1,2,0,2,0,2,1,0,1,1,1,1,1,1,1
1,1,1,1,1,1,1,1,1,0,1,0,1,0,1,1,1,1,1,1,1,1,1
endlayer

layer
1,1,1,1,1,1,1,1,1,0,1,0,1,0,1,1,1,1,1,1,1,1,1
1,1,1,1,1,1,1,0,1,2,0,2,0,2,1,0,1,1,1,1,1,1,1
1,1,1,1,1,0,1,2,0,0,0,0,0,0,0,2,1,0,1,1,1,1,1
1,1,1,0,1,2,0,0,0,0,0,0,0,0,0,0,0,2,1,0,1,1,1
1,1,1,1,0,0,0,0,0,2,2,2,2,2,0,0,0,0,0,1,1,1,1
1,1,0,2,0,0,0,2,2,4,0,20,0,4,2,2,0,0,0,2,0,1,1
1,1,1,0,0,0,2,0,0,0,0,0,0,0,0,0,2,0,0,0,1,1,1
1,0,2,0,0,2,0,0,0,0,0,0,0,0,0,0,0,2,0,0,2,0,1
1,1,0,0,0,2,0,0,0,0,0,0,0,0,0,0,0,2,0,0,0,1,1
0,2,0,0,2,4,0,0,0,7,18,6,6,5,0,0,0,4,2,0,0,2,0
1,0,0,0,2,0,0,0,0,7,8,8,8,0,0,0,0,0,2,0,0,0,1
0,2,0,0,2,0,0,0,0,7,8,8,8,0,0,0,0,0,2,0,0,2,0
1,0,0,0,2,0,0,0,0,7,8,8,8,0,0,0,0,0,2,0,0,0,1
0,2,0,0,2,4,0,0,0,7,11,11,11,0,0,0,0,4,2,0,0,2,0
1,1,0,0,0,2,0,0,0,0,0,0,0,0,0,0,0,2,0,0,0,1,1
1,0,2,0,0,2,0,0,0,0,0,0,0,0,0,0,0,2,0,0,2,0,1
1,1,1,0,0,0,2,0,0,0,0,0,0,0,0,0,2,0,0,0,1,1,1
1,1,0,2,0,0,0,2,2,4,0,12,0,4,2,2,0,0,0,2,0,1,1
1,1,1,1,0,0,0,0,0,2,2,2,2,2,0,0,0,0,0,1,1,1,1
1,1,1,0,1,2,0,0,0,0,0,0,0,0,0,0,0,2,1,0,1,1,1
1,1,1,1,1,0,1,2,0,0,0,0,0,0,0,2,1,0,1,1,1,1,1
1,1,1,1,1,1,1,0,1,2,0,2,0,2,1,0,1,1,1,1,1,1,1
1,1,1,1,1,1,1,1,1,0,1,0,1,0,1,1,1,1,1,1,1,1,1
endlayer

layer
1,1,1,1,1,1,1,1,1,0,1,0,1,0,1,1,1,1,1,1,1,1,1
1,1,1,1,1,1,1,0,1,0,0,0,0,0,1,0,1,1,1,1,1,1,1
1,1,1,1,1,0,1,0,0,0,0,0,0,0,0,0,1,0,1,1,1,1,1
1,1,1,0,1,0,0,0,0,0,0,0,0,0,0,0,0,0,1,0,1,1,1
1,1,1,1,0,0,0,0,0,2,19,19,19,2,0,0,0,0,0,1,1,1,1
1,1,0,0,0,0,0,19,2,4,0,0,0,4,2,19,0,0,0,0,0,1,1
1,1,1,0,0,0,19,0,0,0,0,0,0,0,0,0,19,0,0,0,1,1,1
1,0,0,0,0,19,0,0,0,0,0,0,0,0,0,0,0,19,0,0,0,0,1
1,1,0,0,0,2,0,0,0,0,0,0,0,0,0,0,0,2,0,0,0,1,1
0,0,0,0,2,4,0,0,0,0,7,14,0,0,0,0,0,4,2,0,0,0,0
1,0,0,0,19,0,0,0,0,0,8,8,8,0,0,0,0,0,19,0,0,0,1
0,0,0,0,19,0,0,0,0,0,8,8,8,0,0,0,0,0,19,0,0,0,0
1,0,0,0,19,0,0,0,0,0,8,8,8,0,0,0,0,0,19,0,0,0,1
0,0,0,0,2,4,0,0,0,0,0,0,0,0,0,0,0,4,2,0,0,0,0
1,1,0,0,0,2,0,0,0,0,0,0,0,0,0,0,0,2,0,0,0,1,1
1,0,0,0,0,19,0,0,0,0,0,0,0,0,0,0,0,19,0,0,0,0,1
1,1,1,0,0,0,19,0,0,0,0,0,0,0,0,0,19,0,0,0,1,1,1
1,1,0,0,0,0,0,19,2,4,0,0,0,4,2,19,0,0,0,0,0,1,1
1,1,1,1,0,0,0,0,0,2,19,19,19,2,0,0,0,0,0,1,1,1,1
1,1,1,0,1,0,0,0,0,0,0,0,0,0,0,0,0,0,1,0,1,1,1
1,1,1,1,1,0,1,0,0,0,0,0,0,0,0,0,1,0,1,1,1,1,1
1,1,1,1,1,1,1,0,1,0,0,0,0,0,1,0,1,1,1,1,1,1,1
1,1,1,1,1,1,1,1,1,0,1,0,1,0,1,1,1,1,1,1,1,1,1
endlayer

layer
1,1,1,1,1,1,1,1,1,0,1,0,1,0,1,1,1,1,1,1,1,1,1
1,1,1,1,1,1,1,0,1,0,0,0,0,0,1,0,1,1,1,1,1,1,1
1,1,1,1,1,0,1,0,0,0,0,0,0,0,0,0,1,0,1,1,1,1,1
1,1,1,0,1,0,0,0,0,0,0,0,0,0,0,0,0,0,1,0,1,1,1
1,1,1,1,0,0,0,0,0,2,19,19,19,2,0,0,0,0,0,1,1,1,1
1,1,0,0,0,0,0,19,2,4,0,0,0,4,2,19,0,0,0,0,0,1,1
1,1,1,0,0,0,19,0,0,0,0,0,0,0,0,0,19,0,0,0,1,1,1
1,0,0,0,0,19,0,0,0,0,0,0,0,0,0,0,0,19,0,0,0,0,1
1,1,0,0,0,2,0,0,0,0,0,0,0,0,0,0,0,2,0,0,0,1,1
0,0,0,0,2,4,0,0,0,0,0,7,14,0,0,0,0,4,2,0,0,0,0
1,0,0,0,19,0,0,0,0,0,8,8,8,0,0,0,0,0,19,0,0,0,1
0,0,0,0,19,0,0,0,0,0,8,21,8,0,0,0,0,0,19,0,0,0,0
1,0,0,0,19,0,0,0,0,0,8,8,8,0,0,0,0,0,19,0,0,0,1
0,0,0,0,2,4,0,0,0,0,0,0,0,0,0,0,0,4,2,0,0,0,0
1,1,0,0,0,2,0,0,0,0,0,0,0,0,0,0,0,2,0,0,0,1,1
1,0,0,0,0,19,0,0,0,0,0,0,0,0,0,0,0,19,0,0,0,0,1
1,1,1,0,0,0,19,0,0,0,0,0,0,0,0,0,19,0,0,0,1,1,1
1,1,0,0,0,0,0,19,2,4,0,0,0,4,2,19,0,0,0,0,0,1,1
1,1,1,1,0,0,0,0,0,2,19,19,19,2,0,0,0,0,0,1,1,1,1
1,1,1,0,1,0,0,0,0,0,0,0,0,0,0,0,0,0,1,0,1,1,1
1,1,1,1,1,0,1,0,0,0,0,0,0,0,0,0,1,0,1,1,1,1,1
1,1,1,1,1,1,1,0,1,0,0,0,0,0,1,0,1,1,1,1,1,1,1
1,1,1,1,1,1,1,1,1,0,1,0,1,0,1,1,1,1,1,1,1,1,1
endlayer

layer
1,1,1,1,1,1,1,1,1,0,1,0,1,0,1,1,1,1,1,1,1,1,1
1,1,1,1,1,1,1,0,1,0,0,0,0,0,1,0,1,1,1,1,1,1,1
1,1,1,1,1,0,1,0,0,0,0,0,0,0,0,0,1,0,1,1,1,1,1
1,1,1,0,1,0,0,0,0,0,0,0,0,0,0,0,0,0,1,0,1,1,1
1,1,1,1,0,0,0,0,0,2,2,2,2,2,0,0,0,0,0,1,1,1,1
1,1,0,0,0,0,0,2,2,4,0,0,0,4,2,2,0,0,0,0,0,1,1
1,1,1,0,0,0,2,0,0,0,0,0,0,0,0,0,2,0,0,0,1,1,1
1,0,0,0,0,2,0,0,0,0,0,0,0,0,0,0,0,2,0,0,0,0,1
1,1,0,0,0,2,0,0,0,0,0,0,0,0,0,0,0,2,0,0,0,1,1
0,0,0,0,2,4,0,0,0,0,0,0,7,14,0,0,0,4,2,0,0,0,0
1,0,0,0,2,0,0,0,0,16,8,8,8,14,0,0,0,0,2,0,0,0,1
0,0,0,0,2,0,0,0,0,16,8,8,8,14,0,0,0,0,2,0,0,0,0
1,0,0,0,2,0,0,0,0,16,8,8,8,14,0,0,0,0,2,0,0,0,1
0,0,0,0,2,4,0,0,0,16,17,17,17,17,0,0,0,4,2,0,0,0,0
1,1,0,0,0,2,0,0,0,0,0,0,0,0,0,0,0,2,0,0,0,1,1
1,0,0,0,0,2,0,0,0,0,0,0,0,0,0,0,0,2,0,0,0,0,1
1,1,1,0,0,0,2,0,0,0,0,0,0,0,0,0,2,0,0,0,1,1,1
1,1,0,0,0,0,0,2,2,4,0,0,0,4,2,2,0,0,0,0,0,1,1
1,1,1,1,0,0,0,0,0,2,2,2,2,2,0,0,0,0,0,1,1,1,1
1,1,1,0,1,0,0,0,0,0,0,0,0,0,0,0,0,0,1,0,1,1,1
1,1,1,1,1,0,1,0,0,0,0,0,0,0,0,0,1,0,1,1,1,1,1
1,1,1,1,1,1,1,0,1,0,0,0,0,0,1,0,1,1,1,1,1,1,1
1,1,1,1,1,1,1,1,1,0,1,0,1,0,1,1,1,1,1,1,1,1,1
endlayer

layer
1,1,1,1,1,1,1,1,1,0,1,0,1,0,1,1,1,1,1,1,1,1,1
1,1,1,1,1,1,1,0,1,0,0,0,0,0,1,0,1,1,1,1,1,1,1
1,1,1,1,1,0,1,0,0,0,0,0,0,0,0,0,1,0,1,1,1,1,1
1,1,1,0,1,0,0,0,0,2,2,2,2,2,0,0,0,0,1,0,1,1,1
1,1,1,1,0,0,0,2,2,18,18,18,18,18,2,2,0,0,0,1,1,1,1
1,1,0,0,0,0,2,18,18,18,18,18,18,18,18,18,2,0,0,0,0,1,1
1,1,1,0,0,2,18,18,18,18,18,18,18,18,18,18,18,2,0,0,1,1,1
1,0,0,0,2,18,18,18,18,18,18,18,18,18,18,18,18,18,2,0,0,0,1
1,1,0,0,2,18,18,18,18,18,18,18,18,18,18,18,18,18,2,0,0,1,1
0,0,0,2,18,18,18,18,18,14,0,0,0,7,18,18,18,18,18,2,0,0,0
1,0,0,2,18,18,18,18,18,18,8,8,8,18,18,18,18,18,18,2,0,0,1
0,0,0,2,18,18,18,18,18,18,8,8,8,18,18,18,18,18,18,2,0,0,0
1,0,0,2,18,18,18,18,18,18,8,8,8,18,18,18,18,18,18,2,0,0,1
0,0,0,2,18,18,18,18,18,18,18,18,18,18,18,18,18,18,18,2,0,0,0
1,1,0,0,2,18,18,18,18,18,18,18,18,18,18,18,18,18,2,0,0,1,1
1,0,0,0,2,18,18,18,18,18,18,18,18,18,18,18,18,18,2,0,0,0,1
1,1,1,0,0,2,18,18,18,18,18,18,18,18,18,18,18,2,0,0,1,1,1
1,1,0,0,0,0,2,18,18,18,18,18,18,18,18,18,2,0,0,0,0,1,1
1,1,1,1,0,0,0,2,2,18,18,18,18,18,2,2,0,0,0,1,1,1,1
1,1,1,0,1,0,0,0,0,2,2,2,2,2,0,0,0,0,1,0,1,1,1
1,1,1,1,1,0,1,0,0,0,0,0,0,0,0,0,1,0,1,1,1,1,1
1,1,1,1,1,1,1,0,1,0,0,0,0,0,1,0,1,1,1,1,1,1,1
1,1,1,1,1,1,1,1,1,0,1,0,1,0,1,1,1,1,1,1,1,1,1
endlayer

layer
1,1,1,1,1,1,1,1,1,0,1,0,1,0,1,1,1,1,1,1,1,1,1
1,1,1,1,1,1,1,0,1,0,0,0,0,0,1,0,1,1,1,1,1,1,1
1,1,1,1,1,0,1,0,0,2,0,2,0,2,0,0,1,0,1,1,1,1,1
1,1,1,0,1,0,0,2,0,2,2,2,2,2,0,2,0,0,1,0,1,1,1
1,1,1,1,0,0,0,2,2,0,0,20,0,0,2,2,0,0,0,1,1,1,1
1,1,0,0,0,2,2,0,0,0,0,0,0,0,0,0,2,2,0,0,0,1,1
1,1,1,0,0,2,0,0,0,0,0,0,0,0,0,0,0,2,0,0,1,1,1
1,0,0,2,2,0,0,0,0,0,0,0,0,0,0,0,0,0,2,2,0,0,1
1,1,0,0,2,0,0,0,0,0,0,0,0,0,0,0,0,0,2,0,0,1,1
0,0,2,2,0,0,0,0,0,6,0,0,0,0,0,0,0,0,0,2,2,0,0
1,0,0,2,0,0,0,0,0,7,8,8,8,5,0,0,0,0,0,2,0,0,1
0,0,2,2,10,0,0,0,0,7,8,8,8,5,0,0,0,0,9,2,2,0,0
1,0,0,2,0,0,0,0,0,7,8,8,8,5,0,0,0,0,0,2,0,0,1
0,0,2,2,0,0,0,0,0,7,11,11,11,11,0,0,0,0,0,2,2,0,0
1,1,0,0,2,0,0,0,0,0,0,0,0,0,0,0,0,0,2,0,0,1,1
1,0,0,2,2,0,0,0,0,0,0,0,0,0,0,0,0,0,2,2,0,0,1
1,1,1,0,0,2,0,0,0,0,0,0,0,0,0,0,0,2,0,0,1,1,1
1,1,0,0,0,2,2,0,0,0,0,0,0,0,0,0,2,2,0,0,0,1,1
1,1,1,1,0,0,0,2,2,0,0,12,0,0,2,2,0,0,0,1,1,1,1
1,1,1,0,1,0,0,2,0,2,2,2,2,2,0,2,0,0,1,0,1,1,1
1,1,1,1,1,0,1,0,0,2,0,2,0,2,0,0,1,0,1,1,1,1,1
1,1,1,1,1,1,1,0,1,0,0,0,0,0,1,0,1,1,1,1,1,1,1
1,1,1,1,1,1,1,1,1,0,1,0,1,0,1,1,1,1,1,1,1,1,1
endlayer

layer
1,1,1,1,1,1,1,1,1,0,1,0,1,0,1,1,1,1,1,1,1,1,1
1,1,1,1,1,1,1,0,1,0,0,0,0,0,1,0,1,1,1,1,1,1,1
1,1,1,1,1,0,1,0,0,2,0,2,0,2,0,0,1,0,1,1,1,1,1
1,1,1,0,1,0,0,2,0,0,0,0,0,0,0,2,0,0,1,0,1,1,1
1,1,1,1,0,0,0,0,0,0,0,0,0,0,0,0,0,0,0,1,1,1,1
1,1,0,0,0,2,0,0,0,0,0,0,0,0,0,0,0,2,0,0,0,1,1
1,1,1,0,0,0,0,0,0,0,0,0,0,0,0,0,0,0,0,0,1,1,1
1,0,0,2,0,0,0,0,0,0,0,0,0,0,0,0,0,0,0,2,0,0,1
1,1,0,0,0,0,0,0,0,0,0,0,0,0,0,0,0,0,0,0,0,1,1
0,0,2,0,0,0,0,0,0,0,0,0,0,0,0,0,0,0,0,0,2,0,0
1,0,0,0,0,0,0,0,0,0,8,8,8,0,0,0,0,0,0,0,0,0,1
0,0,2,0,0,0,0,0,0,0,8,8,8,0,0,0,0,0,0,0,2,0,0
1,0,0,0,0,0,0,0,0,0,8,8,8,0,0,0,0,0,0,0,0,0,1
0,0,2,0,0,0,0,0,0,0,0,0,0,0,0,0,0,0,0,0,2,0,0
1,1,0,0,0,0,0,0,0,0,0,0,0,0,0,0,0,0,0,0,0,1,1
1,0,0,2,0,0,0,0,0,0,0,0,0,0,0,0,0,0,0,2,0,0,1
1,1,1,0,0,0,0,0,0,0,0,0,0,0,0,0,0,0,0,0,1,1,1
1,1,0,0,0,2,0,0,0,0,0,0,0,0,0,0,0,2,0,0,0,1,1
1,1,1,1,0,0,0,0,0,0,0,0,0,0,0,0,0,0,0,1,1,1,1
1,1,1,0,1,0,0,2,0,0,0,0,0,0,0,2,0,0,1,0,1,1,1
1,1,1,1,1,0,1,0,0,2,0,2,0,2,0,0,1,0,1,1,1,1,1
1,1,1,1,1,1,1,0,1,0,0,0,0,0,1,0,1,1,1,1,1,1,1
1,1,1,1,1,1,1,1,1,0,1,0,1,0,1,1,1,1,1,1,1,1,1
endlayer

layer
1,1,1,1,1,1,1,1,1,0,1,0,1,0,1,1,1,1,1,1,1,1,1
1,1,1,1,1,1,1,0,1,0,0,0,0,0,1,0,1,1,1,1,1,1,1
1,1,1,1,1,0,1,0,0,2,0,2,0,2,0,0,1,0,1,1,1,1,1
1,1,1,0,1,0,0,2,0,0,0,0,0,0,0,2,0,0,1,0,1,1,1
1,1,1,1,0,0,0,0,0,0,0,0,0,0,0,0,0,0,0,1,1,1,1
1,1,0,0,0,2,0,0,0,0,0,0,0,0,0,0,0,2,0,0,0,1,1
1,1,1,0,0,0,0,0,0,0,0,0,0,0,0,0,0,0,0,0,1,1,1
1,0,0,2,0,0,0,0,0,0,0,0,0,0,0,0,0,0,0,2,0,0,1
1,1,0,0,0,0,0,0,0,0,0,0,0,0,0,0,0,0,0,0,0,1,1
0,0,2,0,0,0,0,0,0,0,0,0,0,0,0,0,0,0,0,0,2,0,0
1,0,0,0,0,0,0,0,0,0,22,22,22,0,0,0,0,0,0,0,0,0,1
0,0,2,0,0,0,0,0,0,0,22,22,22,0,0,0,0,0,0,0,2,0,0
1,0,0,0,0,0,0,0,0,0,22,22,22,0,0,0,0,0,0,0,0,0,1
0,0,2,0,0,0,0,0,0,0,0,0,0,0,0,0,0,0,0,0,2,0,0
1,1,0,0,0,0,0,0,0,0,0,0,0,0,0,0,0,0,0,0,0,1,1
1,0,0,2,0,0,0,0,0,0,0,0,0,0,0,0,0,0,0,2,0,0,1
1,1,1,0,0,0,0,0,0,0,0,0,0,0,0,0,0,0,0,0,1,1,1
1,1,0,0,0,2,0,0,0,0,0,0,0,0,0,0,0,2,0,0,0,1,1
1,1,1,1,0,0,0,0,0,0,0,0,0,0,0,0,0,0,0,1,1,1,1
1,1,1,0,1,0,0,2,0,0,0,0,0,0,0,2,0,0,1,0,1,1,1
1,1,1,1,1,0,1,0,0,2,0,2,0,2,0,0,1,0,1,1,1,1,1
1,1,1,1,1,1,1,0,1,0,0,0,0,0,1,0,1,1,1,1,1,1,1
1,1,1,1,1,1,1,1,1,0,1,0,1,0,1,1,1,1,1,1,1,1,1
endlayer

