
# Created by Ruins mod version 17.0 Ingame Parser
# authoring Player: ST753M

# Creates a large castle/town/thing around itself

weight=2
uniqueMinDistance=2000
spawnMinDistance=500
embed_into_distance=5
acceptable_target_blocks=
unacceptable_target_blocks=flowing_water,water,flowing_lava,lava,ice,bedrock,netherrack,nether_brick,nether_brick_fence,soul_sand,quartz_ore,end_stone,obsidian,iron_bars,Natura:Cloud,slime_grass,slime_congealed,slime_dirt,clouds,natura:clouds,twilightforest:wispy_cloud,twilightforest:fluffy_cloud
dimensions=19,19,19
allowable_overhang=5
max_leveling=4
leveling_buffer=0
preserve_water=0
preserve_lava=0

adjoining_template=ST753M/753_IceCastle_Gate_NS;25;99;0;100
adjoining_template=ST753M/753_IceCastle_Gate_NS;-25;99;0;100

adjoining_template=ST753M/753_IceCastle_Wall_EW;9;99;25;100
adjoining_template=ST753M/753_IceCastle_Wall_EW;16;99;25;100
adjoining_template=ST753M/753_IceCastle_Wall_EW;-9;99;25;100
adjoining_template=ST753M/753_IceCastle_Wall_EW;-16;99;25;100
adjoining_template=ST753M/753_IceCastle_Wall_EW;9;99;-25;100
adjoining_template=ST753M/753_IceCastle_Wall_EW;16;99;-25;100
adjoining_template=ST753M/753_IceCastle_Wall_EW;-9;99;-25;100
adjoining_template=ST753M/753_IceCastle_Wall_EW;-16;99;-25;100

adjoining_template=ST753M/753_IceCastle_Wall_NS;25;99;9;100
adjoining_template=ST753M/753_IceCastle_Wall_NS;25;99;16;100
adjoining_template=ST753M/753_IceCastle_Wall_NS;25;99;-9;100
adjoining_template=ST753M/753_IceCastle_Wall_NS;25;99;-16;100
adjoining_template=ST753M/753_IceCastle_Wall_NS;-25;99;9;100
adjoining_template=ST753M/753_IceCastle_Wall_NS;-25;99;16;100
adjoining_template=ST753M/753_IceCastle_Wall_NS;-25;99;-9;100
adjoining_template=ST753M/753_IceCastle_Wall_NS;-25;99;-16;100

adjoining_template=ST753M/753_IceCastle_House1;17;99;7;100
adjoining_template=ST753M/753_IceCastle_House2;17;99;-7;100
adjoining_template=ST753M/753_IceCastle_Farm;-17;99;7;100
adjoining_template=ST753M/753_IceCastle_House1;-17;99;-7;100
adjoining_template=ST753M/753_IceCastle_House2;7;99;17;100
adjoining_template=ST753M/753_IceCastle_Farm;7;99;-17;100
adjoining_template=ST753M/753_IceCastle_House1;-7;99;17;100
adjoining_template=ST753M/753_IceCastle_Farm;-7;99;-17;100

adjoining_template=ST753M/753_IceCastle_Guard;25;99;25;100
adjoining_template=ST753M/753_IceCastle_Guard;25;99;-25;100
adjoining_template=ST753M/753_IceCastle_Guard;-25;99;25;100
adjoining_template=ST753M/753_IceCastle_Guard;-25;99;-25;100

biomesToSpawnIn=ice_flats,glacier,cold_desert

=0,100,preserveBlock
rule1=0,100,iceandfire:frozen_stone-0
rule2=0,100,minecraft:concrete-9
rule3=0,100,minecraft:packed_ice-0
rule4=0,100,minecraft:light_blue_glazed_terracotta-3
rule5=0,100,minecraft:light_blue_glazed_terracotta-2
rule6=0,100,minecraft:light_blue_glazed_terracotta-0
rule7=0,100,minecraft:light_blue_glazed_terracotta-1
rule8=0,100,minecraft:sea_lantern-0
rule9=0,100,minecraft:carpet-3
rule10=0,100,minecraft:spruce_door-0
rule11=0,100,minecraft:quartz_stairs-3
rule12=0,100,minecraft:quartz_stairs-1
rule13=0,100,minecraft:quartz_stairs-2
rule14=0,100,minecraft:quartz_stairs-0

#	1 each of the next 3
rule15=0,100,CommandBlock:RUINSTRIGGER /summon iceandfire:snowvillager ~ ~1 ~:@-1
rule16=0,100,CommandBlock:RUINSTRIGGER /summon iceandfire:snowvillager ~ ~1 ~:@-1
rule17=0,100,CommandBlock:RUINSTRIGGER /summon villager ~ ~1 ~ {Profession:1,Offers:{Recipes:[{rewardExp:0b,maxUses:2147483647,uses:0,buy:{id:"iceandfire:sapphire_gem",Count:1b},sell:{id:"minecraft:ice",Count:16b}},{rewardExp:0b,maxUses:2147483647,uses:0,buy:{id:"iceandfire:frost_lily",Count:6b},sell:{id:"iceandfire:sapphire_gem",Count:1b}},{rewardExp:0b,maxUses:2147483647,uses:0,buy:{id:"iceandfire:ice_dragon_heart",Count:1b},sell:{id:"iceandfire:sapphire_gem",Count:3b}},{rewardExp:0b,maxUses:2147483647,uses:0,buy:{id:"iceandfire:sapphire_gem",Count:16b},buyB:{id:"iceandfire:dragonbone_sword",Count:1b},sell:{id:"iceandfire:dragonbone_sword_ice",Count:1b}}]}}:@-1

rule18=0,100,minecraft:spruce_door-1
rule19=0,100,CommandBlock:RUINSTRIGGER /fill ~-35 ~-15 ~1 ~35 ~15 ~-1 grass_path 0 replace grass 0:@-1
rule20=0,100,minecraft:spruce_door-3
rule21=0,100,minecraft:spruce_door-2
rule22=0,100,minecraft:stained_glass_pane-9
rule23=0,100,minecraft:spruce_door-8
rule24=0,100,CommandBlock:RUINSTRIGGER /summon iceandfire:snowvillager ~ ~1 ~:@-1
rule25=0,100,CommandBlock:RUINSTRIGGER /fill ~-1 ~-15 ~35 ~1 ~15 ~-35 grass_path 0 replace grass 0:@-1

layer
1,1,1,1,1,1,1,1,1,1,1,1,1,1,1,1,1,1,1
1,1,1,1,1,1,1,1,1,1,1,1,1,1,1,1,1,1,1
1,1,1,1,1,1,1,1,1,1,1,1,1,1,1,1,1,1,1
1,1,1,1,1,1,1,1,1,1,1,1,1,1,1,1,1,1,1
1,1,1,1,1,1,1,1,1,1,1,1,1,1,1,1,1,1,1
1,1,1,1,1,1,1,1,1,1,1,1,1,1,1,1,1,1,1
1,1,1,1,1,1,1,1,1,1,1,1,1,1,1,1,1,1,1
1,1,1,1,1,1,1,1,1,1,1,1,1,1,1,1,1,1,1
1,1,1,1,1,1,1,1,1,1,1,1,1,1,1,1,1,1,1
1,1,1,1,1,1,1,1,1,1,1,1,1,1,1,1,1,1,1
1,1,1,1,1,1,1,1,1,1,1,1,1,1,1,1,1,1,1
1,1,1,1,1,1,1,1,1,1,1,1,1,1,1,1,1,1,1
1,1,1,1,1,1,1,1,1,1,1,1,1,1,1,1,1,1,1
1,1,1,1,1,1,1,1,1,1,1,1,1,1,1,1,1,1,1
1,1,1,1,1,1,1,1,1,1,1,1,1,1,1,1,1,1,1
1,1,1,1,1,1,1,1,1,1,1,1,1,1,1,1,1,1,1
1,1,1,1,1,1,1,1,1,1,1,1,1,1,1,1,1,1,1
1,1,1,1,1,1,1,1,1,1,1,1,1,1,1,1,1,1,1
1,1,1,1,1,1,1,1,1,1,1,1,1,1,1,1,1,1,1
endlayer

layer
1,1,1,1,2,2,2,1,1,1,1,1,2,2,2,1,1,1,1
1,1,1,1,1,1,1,1,1,1,1,1,1,1,1,1,1,1,1
1,1,1,1,1,1,1,1,1,1,1,1,1,1,1,1,1,1,1
1,1,1,1,1,1,1,1,1,1,1,1,1,1,1,1,1,1,1
2,1,1,1,1,1,1,1,1,1,1,1,1,1,1,1,1,1,2
2,1,1,1,1,1,1,1,1,1,1,1,1,1,1,1,1,1,2
2,1,1,1,1,1,1,1,1,1,1,1,1,1,1,1,1,1,2
1,1,1,1,1,1,1,1,1,1,1,1,1,1,1,1,1,1,1
1,1,1,1,1,1,1,1,1,1,1,1,1,1,1,1,1,1,1
1,1,1,1,1,1,1,1,1,1,1,1,1,1,1,1,1,1,1
1,1,1,1,1,1,1,1,1,1,1,1,1,1,1,1,1,1,1
1,1,1,1,1,1,1,1,1,1,1,1,1,1,1,1,1,1,1
2,1,1,1,1,1,1,1,1,1,1,1,1,1,1,1,1,1,2
2,1,1,1,1,1,1,1,1,1,1,1,1,1,1,1,1,1,2
2,1,1,1,1,1,1,1,1,1,1,1,1,1,1,1,1,1,2
1,1,1,1,1,1,1,1,1,1,1,1,1,1,1,1,1,1,1
1,1,1,1,1,1,1,1,1,1,1,1,1,1,1,1,1,1,1
1,1,1,1,1,1,1,1,1,1,1,1,1,1,1,1,1,1,1
1,1,1,1,2,2,2,1,1,1,1,1,2,2,2,1,1,1,1
endlayer

layer
1,2,2,2,2,1,1,1,1,1,1,1,1,1,2,2,2,2,1
2,1,1,1,1,1,1,1,1,1,1,1,1,1,1,1,1,1,2
2,1,1,1,1,1,1,1,1,1,1,1,1,1,1,1,1,1,2
2,1,1,1,1,1,1,1,1,1,1,1,1,1,1,1,1,1,2
2,1,1,1,1,1,1,1,1,1,1,1,1,1,1,1,1,1,2
1,1,1,1,1,1,1,1,1,1,1,1,1,1,1,1,1,1,1
1,1,1,1,1,1,1,1,1,1,1,1,1,1,1,1,1,1,1
1,1,1,1,1,1,1,1,1,1,1,1,1,1,1,1,1,1,1
1,1,1,1,1,1,1,1,1,1,1,1,1,1,1,1,1,1,1
1,1,1,1,1,1,1,1,1,1,1,1,1,1,1,1,1,1,1
1,1,1,1,1,1,1,1,1,1,1,1,1,1,1,1,1,1,1
1,1,1,1,1,1,1,1,1,1,1,1,1,1,1,1,1,1,1
1,1,1,1,1,1,1,1,1,1,1,1,1,1,1,1,1,1,1
1,1,1,1,1,1,1,1,1,1,1,1,1,1,1,1,1,1,1
2,1,1,1,1,1,1,1,1,1,1,1,1,1,1,1,1,1,2
2,1,1,1,1,1,1,1,1,1,1,1,1,1,1,1,1,1,2
2,1,1,1,1,1,1,1,1,1,1,1,1,1,1,1,1,1,2
2,1,1,1,1,1,1,1,1,1,1,1,1,1,1,1,1,1,2
1,2,2,2,2,1,1,1,1,1,1,1,1,1,2,2,2,2,1
endlayer

layer
1,1,1,1,1,1,3,3,3,3,3,3,3,1,1,1,1,1,1
1,1,1,1,1,1,1,1,1,1,1,1,1,1,1,1,1,1,1
1,1,1,1,1,1,1,1,1,1,1,1,1,1,1,1,1,1,1
1,1,1,1,1,1,1,1,1,1,1,1,1,1,1,1,1,1,1
1,1,1,1,1,1,1,1,1,1,1,1,1,1,1,1,1,1,1
1,1,1,1,1,1,1,1,1,1,1,1,1,1,1,1,1,1,1
3,1,1,1,1,1,1,1,1,1,1,1,1,1,1,1,1,1,3
3,1,1,1,1,1,1,1,1,1,1,1,1,1,1,1,1,1,3
3,1,1,1,1,1,1,1,1,1,1,1,1,1,1,1,1,1,3
3,1,1,1,1,1,1,1,1,1,1,1,1,1,1,1,1,1,3
3,3,1,1,1,1,1,1,1,1,1,1,1,1,1,1,1,1,3
3,1,1,1,1,1,1,1,1,1,1,1,1,1,1,1,1,1,3
3,1,1,1,1,1,1,1,1,1,1,1,1,1,1,1,1,1,3
1,1,1,1,1,1,1,1,1,1,1,1,1,1,1,1,1,1,1
1,1,1,1,1,1,1,1,1,1,1,1,1,1,1,1,1,1,1
1,1,1,1,1,1,1,1,1,1,1,1,1,1,1,1,1,1,1
1,1,1,1,1,1,1,1,1,1,1,1,1,1,1,1,1,1,1
1,1,1,1,1,1,1,1,1,1,1,1,1,1,1,1,1,1,1
1,1,1,1,1,1,3,3,3,3,3,3,3,1,1,1,1,1,1
endlayer

layer
3,3,3,3,3,3,3,0,0,0,0,0,3,3,3,3,3,3,3
3,1,1,1,1,1,1,2,2,2,2,2,1,1,1,1,1,1,3
3,1,1,1,1,1,1,1,1,1,1,1,1,1,1,1,1,1,3
3,1,1,1,1,1,1,1,1,1,1,1,1,1,1,1,1,1,3
3,1,1,1,1,1,1,1,1,1,1,1,1,1,1,1,1,1,3
3,1,1,1,1,1,1,1,1,1,1,1,1,1,1,1,1,1,3
3,1,1,1,1,1,1,1,1,1,1,1,1,1,1,1,1,1,3
0,2,1,1,1,1,1,1,1,1,1,1,1,1,1,1,1,2,0
0,2,1,1,1,1,1,1,1,1,1,1,1,1,1,1,1,2,0
0,2,1,1,1,1,1,1,1,1,1,1,1,1,1,1,1,2,0
0,2,1,1,1,1,1,1,1,1,1,1,1,1,1,1,1,2,0
0,2,1,1,1,1,1,1,1,1,1,1,1,1,1,1,1,2,0
3,1,1,1,1,1,1,1,1,1,1,1,1,1,1,1,1,1,3
3,1,1,1,1,1,1,1,1,1,1,1,1,1,1,1,1,1,3
3,1,1,1,1,1,1,1,1,1,1,1,1,1,1,1,1,1,3
3,1,1,1,1,1,1,1,1,1,1,1,1,1,1,1,1,1,3
3,1,1,1,1,1,1,1,1,1,1,1,1,1,1,1,1,1,3
3,1,1,1,1,1,1,2,2,2,2,2,1,1,1,1,1,1,3
3,3,3,3,3,3,3,0,0,0,0,0,3,3,3,3,3,3,3
endlayer

layer
3,0,0,0,0,0,3,3,3,3,3,3,3,0,0,0,0,0,3
0,2,2,2,2,2,1,1,1,1,1,1,1,2,2,2,2,2,0
0,2,1,1,1,1,1,1,1,1,1,1,3,1,1,1,1,2,0
0,2,1,1,1,1,1,1,1,1,1,1,1,1,1,1,1,2,0
0,2,1,1,1,1,1,1,1,1,1,1,1,1,1,1,1,2,0
0,2,1,1,1,1,1,1,1,1,1,1,1,1,1,1,1,2,0
3,1,1,1,1,1,5,4,1,6,1,5,4,1,1,1,1,1,3
3,1,1,1,1,1,7,6,6,8,4,7,6,1,1,1,1,1,3
3,1,1,1,1,1,1,5,7,5,5,7,1,1,1,1,1,1,3
3,1,1,1,1,1,4,8,7,2,4,8,7,1,1,1,1,1,3
3,1,1,1,1,1,1,4,6,6,4,6,1,1,1,1,1,1,3
3,1,1,1,1,1,5,4,7,8,5,5,4,1,1,1,1,1,3
3,1,1,1,1,1,7,6,1,5,1,7,6,1,1,1,3,1,3
0,2,1,1,1,1,1,1,1,1,1,1,1,1,1,1,1,2,0
0,2,1,1,1,1,1,1,1,1,1,1,1,1,1,1,1,2,0
0,2,1,1,1,1,1,1,1,1,1,1,1,1,1,1,1,2,0
0,2,1,1,1,1,1,1,1,1,1,1,1,1,1,1,1,2,0
0,2,2,2,2,2,1,1,1,1,1,1,1,2,2,2,2,2,0
3,0,0,0,0,0,3,3,3,3,3,3,3,0,0,0,0,0,3
endlayer

layer
3,3,3,3,3,3,3,0,0,0,0,0,3,3,3,3,3,3,3
3,9,9,9,9,9,3,0,0,0,0,0,3,9,9,9,9,9,3
3,9,3,9,3,9,3,0,3,0,3,0,3,9,3,9,3,9,3
3,9,9,2,1,1,1,1,1,10,1,1,1,1,1,2,9,9,3
3,9,3,1,3,13,12,11,0,0,0,13,12,11,3,1,3,9,3
3,9,9,1,12,0,0,0,0,0,0,0,0,0,12,1,9,9,3
3,3,3,1,13,0,0,0,0,0,0,0,0,0,11,1,3,3,3
0,0,0,1,14,0,0,0,0,0,0,15,0,0,14,1,0,0,0
0,0,3,1,0,0,0,0,0,0,17,16,0,0,0,1,3,0,0
0,0,0,20,0,0,0,0,0,19,0,0,0,0,0,18,0,0,0
0,0,3,1,0,0,0,0,0,0,0,0,0,0,0,1,3,0,0
0,0,0,1,12,0,0,0,0,0,0,0,0,0,12,1,0,0,0
3,3,3,1,13,0,0,0,0,0,0,0,0,0,11,1,3,3,3
3,9,9,1,14,0,0,0,0,0,0,0,0,0,14,1,9,9,3
3,9,3,1,3,13,14,11,0,0,0,13,14,11,3,1,3,9,3
3,9,9,2,1,1,1,1,1,21,1,1,1,1,1,2,9,9,3
3,9,3,9,3,9,3,0,3,0,3,0,3,9,3,9,3,9,3
3,9,9,9,9,9,3,0,0,0,0,0,3,9,9,9,9,9,3
3,3,3,3,3,3,3,0,0,0,0,0,3,3,3,3,3,3,3
endlayer

layer
0,0,0,0,0,0,0,0,0,0,0,0,0,0,0,0,0,0,0
0,0,0,0,0,0,0,0,0,0,0,0,0,0,0,0,0,0,0
0,0,3,0,3,0,0,0,3,0,3,0,0,0,3,0,3,0,0
0,0,0,2,1,22,1,22,1,23,1,22,1,22,1,2,0,0,0
0,0,3,1,0,0,24,0,0,0,0,0,24,0,0,1,3,0,0
0,0,0,22,0,0,0,0,0,0,0,0,0,0,0,22,0,0,0
0,0,0,1,24,0,0,0,0,0,0,0,0,0,24,1,0,0,0
0,0,0,22,0,0,0,0,0,0,0,0,0,0,0,22,0,0,0
0,0,3,1,0,0,0,0,0,0,0,0,0,0,0,1,3,0,0
0,0,0,23,0,0,0,0,0,25,0,0,0,0,0,23,0,0,0
0,0,3,1,0,0,0,0,0,0,0,0,0,0,0,1,3,0,0
0,0,0,22,0,0,0,0,0,0,0,0,0,0,0,22,0,0,0
0,0,0,1,24,0,0,0,0,0,0,0,0,0,24,1,0,0,0
0,0,0,22,0,0,0,0,0,0,0,0,0,0,0,22,0,0,0
0,0,3,1,0,0,24,0,0,0,0,0,24,0,0,1,3,0,0
0,0,0,2,1,22,1,22,1,23,1,22,1,22,1,2,0,0,0
0,0,3,0,3,0,0,0,3,0,3,0,0,0,3,0,3,0,0
0,0,0,0,0,0,0,0,0,0,0,0,0,0,0,0,0,0,0
0,0,0,0,0,0,0,0,0,0,0,0,0,0,0,0,0,0,0
endlayer

layer
0,0,0,0,0,0,0,0,0,0,0,0,0,0,0,0,0,0,0
0,0,0,0,0,0,0,0,0,0,0,0,0,0,0,0,0,0,0
0,0,3,0,3,0,0,0,3,0,3,0,0,0,3,0,3,0,0
0,0,0,2,1,22,1,22,1,2,1,22,1,22,1,2,0,0,0
0,0,3,1,0,0,0,0,0,0,0,0,0,0,0,1,3,0,0
0,0,0,22,0,0,0,0,0,0,0,0,0,0,0,22,0,0,0
0,0,0,1,0,0,0,0,0,0,0,0,0,0,0,1,0,0,0
0,0,0,22,0,0,0,0,0,0,0,0,0,0,0,22,0,0,0
0,0,3,1,0,0,0,0,0,0,0,0,0,0,0,1,3,0,0
0,0,0,2,0,0,0,0,0,0,0,0,0,0,0,2,0,0,0
0,0,3,1,0,0,0,0,0,0,0,0,0,0,0,1,3,0,0
0,0,0,22,0,0,0,0,0,0,0,0,0,0,0,22,0,0,0
0,0,0,1,0,0,0,0,0,0,0,0,0,0,0,1,0,0,0
0,0,0,22,0,0,0,0,0,0,0,0,0,0,0,22,0,0,0
0,0,3,1,0,0,0,0,0,0,0,0,0,0,0,1,3,0,0
0,0,0,2,1,22,1,22,1,2,1,22,1,22,1,2,0,0,0
0,0,3,0,3,0,0,0,3,0,3,0,0,0,3,0,3,0,0
0,0,0,0,0,0,0,0,0,0,0,0,0,0,0,0,0,0,0
0,0,0,0,0,0,0,0,0,0,0,0,0,0,0,0,0,0,0
endlayer

layer
0,0,0,0,0,0,0,0,0,0,0,0,0,0,0,0,0,0,0
0,0,0,0,0,0,0,0,0,0,0,0,0,0,0,0,0,0,0
0,0,3,0,3,0,0,0,3,0,3,0,0,0,3,0,3,0,0
0,0,0,2,1,22,1,22,1,2,1,22,1,22,1,2,0,0,0
0,0,3,1,0,0,0,0,0,0,0,0,0,0,0,1,3,0,0
0,0,0,22,0,0,0,0,0,0,0,0,0,0,0,22,0,0,0
0,0,0,1,0,0,0,0,0,0,0,0,0,0,0,1,0,0,0
0,0,0,22,0,0,0,0,0,0,0,0,0,0,0,22,0,0,0
0,0,3,1,0,0,0,0,0,0,0,0,0,0,0,1,3,0,0
0,0,0,2,0,0,0,0,0,0,0,0,0,0,0,2,0,0,0
0,0,3,1,0,0,0,0,0,0,0,0,0,0,0,1,3,0,0
0,0,0,22,0,0,0,0,0,0,0,0,0,0,0,22,0,0,0
0,0,0,1,0,0,0,0,0,0,0,0,0,0,0,1,0,0,0
0,0,0,22,0,0,0,0,0,0,0,0,0,0,0,22,0,0,0
0,0,3,1,0,0,0,0,0,0,0,0,0,0,0,1,3,0,0
0,0,0,2,1,22,1,22,1,2,1,22,1,22,1,2,0,0,0
0,0,3,0,3,0,0,0,3,0,3,0,0,0,3,0,3,0,0
0,0,0,0,0,0,0,0,0,0,0,0,0,0,0,0,0,0,0
0,0,0,0,0,0,0,0,0,0,0,0,0,0,0,0,0,0,0
endlayer

layer
0,0,0,0,0,0,0,0,0,0,0,0,0,0,0,0,0,0,0
0,0,0,0,0,0,0,0,0,0,0,0,0,0,0,0,0,0,0
0,0,3,0,3,0,0,0,3,0,3,0,0,0,3,0,3,0,0
0,0,0,2,1,22,1,22,1,2,1,22,1,22,1,2,0,0,0
0,0,3,1,0,0,0,0,0,0,0,0,0,0,0,1,3,0,0
0,0,0,22,0,0,0,0,0,0,0,0,0,0,0,22,0,0,0
0,0,0,1,0,0,0,0,0,0,0,0,0,0,0,1,0,0,0
0,0,0,22,0,0,0,0,0,0,0,0,0,0,0,22,0,0,0
0,0,3,1,0,0,0,0,0,0,0,0,0,0,0,1,3,0,0
0,0,0,2,0,0,0,0,0,0,0,0,0,0,0,2,0,0,0
0,0,3,1,0,0,0,0,0,0,0,0,0,0,0,1,3,0,0
0,0,0,22,0,0,0,0,0,0,0,0,0,0,0,22,0,0,0
0,0,0,1,0,0,0,0,0,0,0,0,0,0,0,1,0,0,0
0,0,0,22,0,0,0,0,0,0,0,0,0,0,0,22,0,0,0
0,0,3,1,0,0,0,0,0,0,0,0,0,0,0,1,3,0,0
0,0,0,2,1,22,1,22,1,2,1,22,1,22,1,2,0,0,0
0,0,3,0,3,0,0,0,3,0,3,0,0,0,3,0,3,0,0
0,0,0,0,0,0,0,0,0,0,0,0,0,0,0,0,0,0,0
0,0,0,0,0,0,0,0,0,0,0,0,0,0,0,0,0,0,0
endlayer

layer
0,0,0,0,0,0,0,0,0,0,0,0,0,0,0,0,0,0,0
0,0,0,0,0,0,0,0,0,0,0,0,0,0,0,0,0,0,0
0,0,3,0,3,3,3,3,3,0,3,3,3,3,3,0,3,0,0
0,0,0,2,1,1,1,1,1,2,1,1,1,1,1,2,0,0,0
0,0,3,1,1,1,1,1,1,1,1,1,1,1,1,1,3,0,0
0,0,3,1,1,1,1,1,1,1,1,1,1,1,1,1,3,0,0
0,0,3,1,1,1,3,3,3,3,3,3,3,1,1,1,3,0,0
0,0,3,1,1,1,3,0,0,0,0,0,3,1,1,1,3,0,0
0,0,3,1,1,1,3,0,0,0,0,0,3,1,1,1,3,0,0
0,0,0,2,1,1,3,0,0,0,0,0,3,1,1,2,0,0,0
0,0,3,1,1,1,3,0,0,0,0,0,3,1,1,1,3,0,0
0,0,3,1,1,1,3,0,0,0,0,0,3,1,1,1,3,0,0
0,0,3,1,1,1,3,3,3,3,3,3,3,1,1,1,3,0,0
0,0,3,1,1,1,1,1,1,1,1,1,1,1,1,1,3,0,0
0,0,3,1,1,1,1,1,1,1,1,1,1,1,1,1,3,0,0
0,0,0,2,1,1,1,1,1,2,1,1,1,1,1,2,0,0,0
0,0,3,0,3,3,3,3,3,0,3,3,3,3,3,0,3,0,0
0,0,0,0,0,0,0,0,0,0,0,0,0,0,0,0,0,0,0
0,0,0,0,0,0,0,0,0,0,0,0,0,0,0,0,0,0,0
endlayer

layer
0,0,0,0,0,0,0,0,0,0,0,0,0,0,0,0,0,0,0
0,0,0,0,0,0,0,0,0,0,0,0,0,0,0,0,0,0,0
0,0,3,3,3,0,0,0,3,3,3,0,0,0,3,3,3,0,0
0,0,3,9,9,9,9,9,9,9,9,9,9,9,9,9,3,0,0
0,0,3,9,9,9,9,9,9,9,9,9,9,9,9,9,3,0,0
0,0,0,9,9,3,9,3,9,9,9,3,9,3,9,9,0,0,0
0,0,0,9,9,9,2,1,1,1,1,1,2,9,9,9,0,0,0
0,0,0,9,9,3,1,0,0,0,0,0,1,3,9,9,0,0,0
0,0,3,9,9,9,1,0,0,0,0,0,1,9,9,9,3,0,0
0,0,3,9,9,9,1,0,0,0,0,0,1,9,9,9,3,0,0
0,0,3,9,9,9,1,0,0,0,0,0,1,9,9,9,3,0,0
0,0,0,9,9,3,1,0,0,0,0,0,1,3,9,9,0,0,0
0,0,0,9,9,9,2,1,1,1,1,1,2,9,9,9,0,0,0
0,0,0,9,9,3,9,3,9,9,9,3,9,3,9,9,0,0,0
0,0,3,9,9,9,9,9,9,9,9,9,9,9,9,9,3,0,0
0,0,3,9,9,9,9,9,9,9,9,9,9,9,9,9,3,0,0
0,0,3,3,3,0,0,0,3,3,3,0,0,0,3,3,3,0,0
0,0,0,0,0,0,0,0,0,0,0,0,0,0,0,0,0,0,0
0,0,0,0,0,0,0,0,0,0,0,0,0,0,0,0,0,0,0
endlayer

layer
0,0,0,0,0,0,0,0,0,0,0,0,0,0,0,0,0,0,0
0,0,0,0,0,0,0,0,0,0,0,0,0,0,0,0,0,0,0
0,0,0,0,0,0,0,0,0,0,0,0,0,0,0,0,0,0,0
0,0,0,0,0,0,0,0,0,0,0,0,0,0,0,0,0,0,0
0,0,0,0,0,0,0,0,0,0,0,0,0,0,0,0,0,0,0
0,0,0,0,0,3,0,3,0,24,0,3,0,3,0,0,0,0,0
0,0,0,0,0,0,2,1,22,1,22,1,2,0,0,0,0,0,0
0,0,0,0,0,3,1,0,0,0,0,0,1,3,0,0,0,0,0
0,0,0,0,0,0,22,0,0,0,0,0,22,0,0,0,0,0,0
0,0,0,0,0,24,1,0,0,0,0,0,1,24,0,0,0,0,0
0,0,0,0,0,0,22,0,0,0,0,0,22,0,0,0,0,0,0
0,0,0,0,0,3,1,0,0,0,0,0,1,3,0,0,0,0,0
0,0,0,0,0,0,2,1,22,1,22,1,2,0,0,0,0,0,0
0,0,0,0,0,3,0,3,0,24,0,3,0,3,0,0,0,0,0
0,0,0,0,0,0,0,0,0,0,0,0,0,0,0,0,0,0,0
0,0,0,0,0,0,0,0,0,0,0,0,0,0,0,0,0,0,0
0,0,0,0,0,0,0,0,0,0,0,0,0,0,0,0,0,0,0
0,0,0,0,0,0,0,0,0,0,0,0,0,0,0,0,0,0,0
0,0,0,0,0,0,0,0,0,0,0,0,0,0,0,0,0,0,0
endlayer

layer
0,0,0,0,0,0,0,0,0,0,0,0,0,0,0,0,0,0,0
0,0,0,0,0,0,0,0,0,0,0,0,0,0,0,0,0,0,0
0,0,0,0,0,0,0,0,0,0,0,0,0,0,0,0,0,0,0
0,0,0,0,0,0,0,0,0,0,0,0,0,0,0,0,0,0,0
0,0,0,0,0,0,0,0,0,0,0,0,0,0,0,0,0,0,0
0,0,0,0,0,3,0,3,0,0,0,3,0,3,0,0,0,0,0
0,0,0,0,0,0,2,1,22,1,22,1,2,0,0,0,0,0,0
0,0,0,0,0,3,1,0,0,0,0,0,1,3,0,0,0,0,0
0,0,0,0,0,0,22,0,0,0,0,0,22,0,0,0,0,0,0
0,0,0,0,0,0,1,0,0,0,0,0,1,0,0,0,0,0,0
0,0,0,0,0,0,22,0,0,0,0,0,22,0,0,0,0,0,0
0,0,0,0,0,3,1,0,0,0,0,0,1,3,0,0,0,0,0
0,0,0,0,0,0,2,1,22,1,22,1,2,0,0,0,0,0,0
0,0,0,0,0,3,0,3,0,0,0,3,0,3,0,0,0,0,0
0,0,0,0,0,0,0,0,0,0,0,0,0,0,0,0,0,0,0
0,0,0,0,0,0,0,0,0,0,0,0,0,0,0,0,0,0,0
0,0,0,0,0,0,0,0,0,0,0,0,0,0,0,0,0,0,0
0,0,0,0,0,0,0,0,0,0,0,0,0,0,0,0,0,0,0
0,0,0,0,0,0,0,0,0,0,0,0,0,0,0,0,0,0,0
endlayer

layer
0,0,0,0,0,0,0,0,0,0,0,0,0,0,0,0,0,0,0
0,0,0,0,0,0,0,0,0,0,0,0,0,0,0,0,0,0,0
0,0,0,0,0,0,0,0,0,0,0,0,0,0,0,0,0,0,0
0,0,0,0,0,0,0,0,0,0,0,0,0,0,0,0,0,0,0
0,0,0,0,0,0,0,0,0,0,0,0,0,0,0,0,0,0,0
0,0,0,0,0,3,0,3,0,0,0,3,0,3,0,0,0,0,0
0,0,0,0,0,0,2,1,22,1,22,1,2,0,0,0,0,0,0
0,0,0,0,0,3,1,0,0,0,0,0,1,3,0,0,0,0,0
0,0,0,0,0,0,22,0,0,0,0,0,22,0,0,0,0,0,0
0,0,0,0,0,0,1,0,0,0,0,0,1,0,0,0,0,0,0
0,0,0,0,0,0,22,0,0,0,0,0,22,0,0,0,0,0,0
0,0,0,0,0,3,1,0,0,0,0,0,1,3,0,0,0,0,0
0,0,0,0,0,0,2,1,22,1,22,1,2,0,0,0,0,0,0
0,0,0,0,0,3,0,3,0,0,0,3,0,3,0,0,0,0,0
0,0,0,0,0,0,0,0,0,0,0,0,0,0,0,0,0,0,0
0,0,0,0,0,0,0,0,0,0,0,0,0,0,0,0,0,0,0
0,0,0,0,0,0,0,0,0,0,0,0,0,0,0,0,0,0,0
0,0,0,0,0,0,0,0,0,0,0,0,0,0,0,0,0,0,0
0,0,0,0,0,0,0,0,0,0,0,0,0,0,0,0,0,0,0
endlayer

layer
0,0,0,0,0,0,0,0,0,0,0,0,0,0,0,0,0,0,0
0,0,0,0,0,0,0,0,0,0,0,0,0,0,0,0,0,0,0
0,0,0,0,0,0,0,0,0,0,0,0,0,0,0,0,0,0,0
0,0,0,0,0,0,0,0,0,0,0,0,0,0,0,0,0,0,0
0,0,0,0,0,0,0,0,0,0,0,0,0,0,0,0,0,0,0
0,0,0,0,0,3,0,3,0,0,0,3,0,3,0,0,0,0,0
0,0,0,0,0,0,2,1,22,1,22,1,2,0,0,0,0,0,0
0,0,0,0,0,3,1,0,0,0,0,0,1,3,0,0,0,0,0
0,0,0,0,0,0,22,0,0,0,0,0,22,0,0,0,0,0,0
0,0,0,0,0,0,1,0,0,8,0,0,1,0,0,0,0,0,0
0,0,0,0,0,0,22,0,0,0,0,0,22,0,0,0,0,0,0
0,0,0,0,0,3,1,0,0,0,0,0,1,3,0,0,0,0,0
0,0,0,0,0,0,2,1,22,1,22,1,2,0,0,0,0,0,0
0,0,0,0,0,3,0,3,0,0,0,3,0,3,0,0,0,0,0
0,0,0,0,0,0,0,0,0,0,0,0,0,0,0,0,0,0,0
0,0,0,0,0,0,0,0,0,0,0,0,0,0,0,0,0,0,0
0,0,0,0,0,0,0,0,0,0,0,0,0,0,0,0,0,0,0
0,0,0,0,0,0,0,0,0,0,0,0,0,0,0,0,0,0,0
0,0,0,0,0,0,0,0,0,0,0,0,0,0,0,0,0,0,0
endlayer

layer
0,0,0,0,0,0,0,0,0,0,0,0,0,0,0,0,0,0,0
0,0,0,0,0,0,0,0,0,0,0,0,0,0,0,0,0,0,0
0,0,0,0,0,0,0,0,0,0,0,0,0,0,0,0,0,0,0
0,0,0,0,0,0,0,0,0,0,0,0,0,0,0,0,0,0,0
0,0,0,0,0,0,0,0,0,0,0,0,0,0,0,0,0,0,0
0,0,0,0,0,3,0,3,3,3,3,3,0,3,0,0,0,0,0
0,0,0,0,0,0,2,1,1,1,1,1,2,0,0,0,0,0,0
0,0,0,0,0,3,1,1,1,1,1,1,1,3,0,0,0,0,0
0,0,0,0,0,3,1,1,1,1,1,1,1,3,0,0,0,0,0
0,0,0,0,0,3,1,1,1,1,1,1,1,3,0,0,0,0,0
0,0,0,0,0,3,1,1,1,1,1,1,1,3,0,0,0,0,0
0,0,0,0,0,3,1,1,1,1,1,1,1,3,0,0,0,0,0
0,0,0,0,0,0,2,1,1,1,1,1,2,0,0,0,0,0,0
0,0,0,0,0,3,0,3,3,3,3,3,0,3,0,0,0,0,0
0,0,0,0,0,0,0,0,0,0,0,0,0,0,0,0,0,0,0
0,0,0,0,0,0,0,0,0,0,0,0,0,0,0,0,0,0,0
0,0,0,0,0,0,0,0,0,0,0,0,0,0,0,0,0,0,0
0,0,0,0,0,0,0,0,0,0,0,0,0,0,0,0,0,0,0
0,0,0,0,0,0,0,0,0,0,0,0,0,0,0,0,0,0,0
endlayer

layer
0,0,0,0,0,0,0,0,0,0,0,0,0,0,0,0,0,0,0
0,0,0,0,0,0,0,0,0,0,0,0,0,0,0,0,0,0,0
0,0,0,0,0,0,0,0,0,0,0,0,0,0,0,0,0,0,0
0,0,0,0,0,0,0,0,0,0,0,0,0,0,0,0,0,0,0
0,0,0,0,0,0,0,0,0,0,0,0,0,0,0,0,0,0,0
0,0,0,0,0,3,3,3,0,0,0,3,3,3,0,0,0,0,0
0,0,0,0,0,3,9,9,9,9,9,9,9,3,0,0,0,0,0
0,0,0,0,0,3,9,9,0,0,0,9,9,3,0,0,0,0,0
0,0,0,0,0,0,9,0,0,0,0,0,9,0,0,0,0,0,0
0,0,0,0,0,0,9,0,0,24,0,0,9,0,0,0,0,0,0
0,0,0,0,0,0,9,0,0,0,0,0,9,0,0,0,0,0,0
0,0,0,0,0,3,9,9,0,0,0,9,9,3,0,0,0,0,0
0,0,0,0,0,3,9,9,9,9,9,9,9,3,0,0,0,0,0
0,0,0,0,0,3,3,3,0,0,0,3,3,3,0,0,0,0,0
0,0,0,0,0,0,0,0,0,0,0,0,0,0,0,0,0,0,0
0,0,0,0,0,0,0,0,0,0,0,0,0,0,0,0,0,0,0
0,0,0,0,0,0,0,0,0,0,0,0,0,0,0,0,0,0,0
0,0,0,0,0,0,0,0,0,0,0,0,0,0,0,0,0,0,0
0,0,0,0,0,0,0,0,0,0,0,0,0,0,0,0,0,0,0
endlayer

