
# Created by Ruins mod version 17.0 Ingame Parser
# authoring Player: ST753M

weight=1
uniqueMinDistance=1000
spawnMinDistance=500
embed_into_distance=3
acceptable_target_blocks=
unacceptable_target_blocks=flowing_water,water,flowing_lava,lava,bedrock,netherrack,nether_brick,nether_brick_fence,soul_sand,quartz_ore,end_stone,obsidian,iron_bars,Natura:Cloud,slime_grass,slime_congealed,slime_dirt,clouds,natura:clouds
dimensions=19,21,21
allowable_overhang=4
max_leveling=2
leveling_buffer=0
preserve_water=0
preserve_lava=0

biomesToSpawnIn=ice_flats,ice_mountains,glacier,glacier_spikes,mutated_ice_flats,cold_desert

=0,100,air
rule1=0,100,preserveBlock
rule2=0,100,iceandfire:frozen_cobblestone-0
rule3=0,100,minecraft:packed_ice-0
rule4=0,100,minecraft:packed_ice-0
rule5=0,100,iceandfire:dragon_ice-0
rule6=0,100,minecraft:quartz_stairs-2
rule7=0,100,minecraft:quartz_stairs-3
rule8=0,100,minecraft:sea_lantern-0
rule9=0,100,minecraft:quartz_stairs-1
rule10=0,100,minecraft:spruce_door-3

rule11=0,100,CommandBlock:RUINSTRIGGER /summon iceandfire:snowvillager ~ ~1 ~ {PersistenceRequired:1}:@-1

rule12=0,100,minecraft:spruce_door-1
rule13=0,100,minecraft:snow_layer-0
rule14=0,100,minecraft:stained_glass-3
rule15=0,100,minecraft:quartz_stairs-6
rule16=0,100,minecraft:spruce_door-8
rule17=0,100,minecraft:spruce_door-9
rule18=0,100,minecraft:quartz_stairs-4
rule19=0,100,minecraft:spruce_door-2
rule20=0,100,minecraft:spruce_door-0
rule21=0,100,minecraft:stone_slab-15
rule22=0,100,iceandfire:dragon_ice_spikes-0
rule23=0,100,minecraft:wool-3

layer
1,1,1,1,1,1,1,1,2,2,2,2,2,1,1,1,1,1,1,1,1
1,1,1,1,1,1,2,2,2,2,2,2,2,2,2,1,1,1,1,1,1
1,1,1,1,2,2,2,2,2,2,2,2,2,2,2,2,2,1,1,1,1
1,1,1,2,2,2,2,2,2,2,2,2,2,2,2,2,2,2,1,1,1
1,1,2,2,2,2,2,2,2,2,2,2,2,2,2,2,2,2,2,1,1
1,1,2,2,2,2,2,2,2,2,2,2,2,2,2,2,2,2,2,1,1
1,2,2,2,2,2,2,2,2,2,2,2,2,2,2,2,2,2,2,2,1
1,2,2,2,2,2,2,2,2,2,2,2,2,2,2,2,2,2,2,2,1
2,2,2,2,2,2,2,2,2,2,2,2,2,2,2,2,2,2,2,2,2
2,2,2,2,2,2,2,2,2,2,2,2,2,2,2,2,2,2,2,2,2
2,2,2,2,2,2,2,2,2,2,2,2,2,2,2,2,2,2,2,2,2
2,2,2,2,2,2,2,2,2,2,2,2,2,2,2,2,2,2,2,2,2
2,2,2,2,2,2,2,2,2,2,2,2,2,2,2,2,2,2,2,2,2
1,2,2,2,2,2,2,2,2,2,2,2,2,2,2,2,2,2,2,2,1
1,2,2,2,2,2,2,2,2,2,2,2,2,2,2,2,2,2,2,2,1
1,1,2,2,2,2,2,2,2,2,2,2,2,2,2,2,2,2,2,1,1
1,1,2,2,2,2,2,2,2,2,2,2,2,2,2,2,2,2,2,1,1
1,1,1,2,2,2,2,2,2,2,2,2,2,2,2,2,2,2,1,1,1
1,1,1,1,2,2,2,2,2,2,2,2,2,2,2,2,2,1,1,1,1
1,1,1,1,1,1,2,2,2,2,2,2,2,2,2,1,1,1,1,1,1
1,1,1,1,1,1,1,1,2,2,2,2,2,1,1,1,1,1,1,1,1
endlayer

layer
1,1,1,1,1,1,1,1,2,3,3,3,2,1,1,1,1,1,1,1,1
1,1,1,1,1,1,2,2,2,2,2,2,2,2,2,1,1,1,1,1,1
1,1,1,1,3,2,2,2,2,2,2,2,2,2,2,2,3,1,1,1,1
1,1,1,3,2,2,2,2,2,2,2,2,2,2,2,2,2,3,1,1,1
1,1,3,2,2,2,2,2,2,2,2,2,2,2,2,2,2,2,3,1,1
1,1,2,2,2,2,2,2,2,2,2,2,2,2,2,2,2,2,2,1,1
1,2,2,2,2,2,2,2,2,2,2,2,2,2,2,2,2,2,2,2,1
1,2,2,2,2,2,2,2,2,2,2,2,2,2,2,2,2,2,2,2,1
2,2,2,2,2,2,2,2,2,2,2,2,2,2,2,2,2,2,2,2,2
3,2,2,2,2,2,2,2,2,2,2,2,2,2,2,2,2,2,2,2,3
3,2,2,2,2,2,2,2,2,2,2,2,2,2,2,2,2,2,2,2,3
3,2,2,2,2,2,2,2,2,2,2,2,2,2,2,2,2,2,2,2,3
2,2,2,2,2,2,2,2,2,2,2,2,2,2,2,2,2,2,2,2,2
1,2,2,2,2,2,2,2,2,2,2,2,2,2,2,2,2,2,2,2,1
1,2,2,2,2,2,2,2,2,2,2,2,2,2,2,2,2,2,2,2,1
1,1,2,2,2,2,2,2,2,2,2,2,2,2,2,2,2,2,2,1,1
1,1,3,2,2,2,2,2,2,2,2,2,2,2,2,2,2,2,3,1,1
1,1,1,3,2,2,2,2,2,2,2,2,2,2,2,2,2,3,1,1,1
1,1,1,1,3,2,2,2,2,2,2,2,2,2,2,2,3,1,1,1,1
1,1,1,1,1,1,2,2,2,2,2,2,2,2,2,1,1,1,1,1,1
1,1,1,1,1,1,1,1,2,3,3,3,2,1,1,1,1,1,1,1,1
endlayer

layer
1,1,1,1,1,1,1,1,2,3,2,3,2,1,1,1,1,1,1,1,1
1,1,1,1,1,1,2,2,2,2,2,2,2,2,2,1,1,1,1,1,1
1,1,1,1,3,2,2,2,2,2,2,2,2,2,2,2,3,1,1,1,1
1,1,1,2,2,2,2,2,2,2,2,2,2,2,2,2,2,2,1,1,1
1,1,3,2,2,2,2,2,2,2,2,2,2,2,2,2,2,2,3,1,1
1,1,2,2,2,2,2,2,2,2,2,2,2,2,2,2,2,2,2,1,1
1,2,2,2,2,2,2,2,2,2,2,2,2,2,2,2,2,2,2,2,1
1,2,2,2,2,2,2,2,2,2,2,2,2,2,2,2,2,2,2,2,1
2,2,2,2,2,2,2,2,2,2,2,2,2,2,2,2,2,2,2,2,2
2,2,2,2,2,2,2,2,2,2,2,2,2,2,2,2,2,2,2,2,2
2,2,2,2,2,2,2,2,2,2,2,2,2,2,2,2,2,2,2,2,2
2,2,2,2,2,2,2,2,2,2,2,2,2,2,2,2,2,2,2,2,2
2,2,2,2,2,2,2,2,2,2,2,2,2,2,2,2,2,2,2,2,2
1,2,2,2,2,2,2,2,2,2,2,2,2,2,2,2,2,2,2,2,1
1,2,2,2,2,2,2,2,2,2,2,2,2,2,2,2,2,2,2,2,1
1,1,2,2,2,2,2,2,2,2,2,2,2,2,2,2,2,2,2,1,1
1,1,3,2,2,2,2,2,2,2,2,2,2,2,2,2,2,2,3,1,1
1,1,1,2,2,2,2,2,2,2,2,2,2,2,2,2,2,2,1,1,1
1,1,1,1,3,2,2,2,2,2,2,2,2,2,2,2,3,1,1,1,1
1,1,1,1,1,1,2,2,2,2,2,2,2,2,2,1,1,1,1,1,1
1,1,1,1,1,1,1,1,2,3,2,3,2,1,1,1,1,1,1,1,1
endlayer

layer
1,1,1,1,1,1,1,1,2,3,3,3,2,1,1,1,1,1,1,1,1
1,1,1,1,1,1,2,2,3,3,3,3,3,2,2,1,1,1,1,1,1
1,1,1,1,3,2,3,3,3,3,3,3,3,3,3,2,3,1,1,1,1
1,1,1,3,3,3,3,3,3,3,3,3,3,3,3,3,3,3,1,1,1
1,1,3,3,3,3,3,3,4,4,4,4,4,3,3,3,3,3,3,1,1
1,1,2,3,3,3,4,4,3,3,3,3,3,4,4,3,3,3,2,1,1
1,2,3,3,3,4,3,3,3,3,3,3,3,3,3,4,3,3,3,2,1
1,2,3,3,3,4,3,3,3,3,3,3,3,3,3,4,3,3,3,2,1
2,3,3,3,4,3,3,3,5,5,2,5,5,3,3,3,4,3,3,3,2
7,3,3,3,4,3,3,3,5,2,5,2,5,3,3,3,3,3,3,3,6
7,3,3,3,3,3,3,3,2,5,8,5,2,3,3,3,4,3,3,3,6
7,3,3,3,3,3,3,3,5,2,5,2,5,3,3,3,4,3,3,3,6
2,3,3,3,4,3,3,3,5,5,2,5,5,3,3,3,4,3,3,3,2
1,2,3,3,3,4,3,3,3,3,3,3,3,3,3,4,3,3,3,2,1
1,2,3,3,3,4,3,3,3,3,3,3,3,3,3,4,3,3,3,2,1
1,1,2,3,3,3,4,4,3,3,3,3,3,4,4,3,3,3,2,1,1
1,1,3,3,3,3,3,3,4,4,4,4,4,3,3,3,3,3,3,1,1
1,1,1,3,3,3,3,3,3,3,3,3,3,3,3,3,3,3,1,1,1
1,1,1,1,3,2,3,3,3,3,3,3,3,3,3,2,3,1,1,1,1
1,1,1,1,1,1,2,2,3,3,3,3,3,2,2,1,1,1,1,1,1
1,1,1,1,1,1,1,1,2,3,3,3,2,1,1,1,1,1,1,1,1
endlayer

layer
1,1,1,1,1,1,1,1,2,2,2,2,2,1,1,1,1,1,1,1,1
1,1,1,1,1,1,2,2,0,0,0,0,0,2,2,1,1,1,1,1,1
1,1,1,1,2,2,0,0,0,0,0,0,0,0,0,2,2,1,1,1,1
1,1,1,2,0,0,0,0,0,0,0,0,0,0,0,0,0,2,1,1,1
1,1,2,0,0,0,0,0,2,2,2,2,2,0,0,0,0,0,2,1,1
1,1,2,0,0,0,2,2,0,0,0,0,0,2,2,0,0,0,2,1,1
1,2,0,0,0,2,2,0,0,0,0,0,0,0,0,2,0,0,0,2,1
1,2,0,0,0,2,9,0,0,0,0,0,0,0,0,2,0,0,0,2,1
2,0,0,0,2,0,0,0,0,0,0,0,0,0,0,0,2,0,0,0,2
0,0,0,0,2,0,0,0,0,0,11,0,0,0,0,0,10,0,0,0,0
0,0,0,0,2,0,0,0,0,0,0,0,0,0,0,0,2,0,0,0,0
0,0,0,0,12,0,0,0,0,0,11,0,0,0,0,0,2,0,0,0,0
2,0,0,0,2,0,0,0,0,0,0,0,0,0,0,0,2,0,0,0,2
1,2,0,0,0,2,0,0,0,0,0,0,0,0,0,2,0,0,0,2,1
1,2,0,0,0,2,0,0,0,0,0,0,0,0,0,2,0,0,0,2,1
1,1,2,0,0,0,2,2,0,0,0,0,0,2,2,0,0,0,2,1,1
1,1,2,0,0,0,0,0,2,2,2,2,2,0,0,0,0,0,2,1,1
1,1,1,2,0,0,0,0,0,0,0,0,0,0,0,0,0,2,1,1,1
1,1,1,1,2,2,0,0,0,0,0,0,0,0,0,2,2,1,1,1,1
1,1,1,1,1,1,2,2,0,0,0,0,0,2,2,1,1,1,1,1,1
1,1,1,1,1,1,1,1,2,2,2,2,2,1,1,1,1,1,1,1,1
endlayer

layer
1,1,1,1,1,1,1,1,2,13,13,13,2,1,1,1,1,1,1,1,1
1,1,1,1,1,1,13,13,0,0,0,0,0,13,13,1,1,1,1,1,1
1,1,1,1,13,13,0,0,0,0,0,0,0,0,0,13,13,1,1,1,1
1,1,1,13,0,0,0,0,0,0,0,0,0,0,0,0,0,13,1,1,1
1,1,13,0,0,0,0,0,2,14,2,14,2,0,0,0,0,0,13,1,1
1,1,13,0,0,0,2,14,0,0,0,0,0,14,2,0,0,0,13,1,1
1,13,0,0,0,2,9,15,0,0,0,0,0,0,0,2,0,0,0,13,1
1,13,0,0,0,14,0,0,0,0,0,0,0,0,0,14,0,0,0,13,1
2,0,0,0,2,0,0,0,0,0,0,0,0,0,0,0,2,0,0,0,2
0,0,0,0,14,0,0,0,0,0,0,0,0,0,0,0,16,0,0,0,0
0,0,0,0,2,0,0,0,0,0,0,0,0,0,0,0,2,0,0,0,0
0,0,0,0,17,0,0,0,0,0,0,0,0,0,0,0,14,0,0,0,0
2,0,0,0,2,0,0,0,0,0,0,0,0,0,0,0,2,0,0,0,2
1,13,0,0,0,14,0,0,0,0,0,0,0,0,0,14,0,0,0,13,1
1,13,0,0,0,2,0,0,0,0,0,0,0,0,0,2,0,0,0,13,1
1,1,13,0,0,0,2,14,0,0,0,0,0,14,2,0,0,0,13,1,1
1,1,13,0,0,0,0,0,2,14,2,14,2,0,0,0,0,0,13,1,1
1,1,1,13,0,0,0,0,0,0,0,0,0,0,0,0,0,13,1,1,1
1,1,1,1,13,13,0,0,0,0,0,0,0,0,0,13,13,1,1,1,1
1,1,1,1,1,1,13,13,0,0,0,0,0,13,13,1,1,1,1,1,1
1,1,1,1,1,1,1,1,2,13,13,13,2,1,1,1,1,1,1,1,1
endlayer

layer
1,1,1,1,1,1,1,1,2,0,0,0,2,1,1,1,1,1,1,1,1
1,1,1,1,1,1,0,0,0,0,0,0,0,0,0,1,1,1,1,1,1
1,1,1,1,0,0,0,0,0,0,0,0,0,0,0,0,0,1,1,1,1
1,1,1,0,0,0,0,0,0,0,0,0,0,0,0,0,0,0,1,1,1
1,1,0,0,0,0,0,0,2,2,2,2,2,0,0,0,0,0,0,1,1
1,1,0,0,0,0,2,2,0,0,0,0,0,2,2,0,0,0,0,1,1
1,0,0,0,0,2,0,7,0,0,0,0,0,0,0,2,0,0,0,0,1
1,0,0,0,0,2,0,0,0,0,0,0,0,0,0,2,0,0,0,0,1
2,0,0,0,2,0,0,0,0,0,0,0,0,0,0,0,2,0,0,0,2
0,0,0,0,2,0,0,0,0,0,0,0,0,0,0,0,2,0,0,0,0
0,0,0,0,2,0,0,0,0,0,0,0,0,0,0,0,2,0,0,0,0
0,0,0,0,2,0,0,0,0,0,0,0,0,0,0,0,2,0,0,0,0
2,0,0,0,2,0,0,0,0,0,0,0,0,0,0,0,2,0,0,0,2
1,0,0,0,0,2,0,0,0,0,0,0,0,0,0,2,0,0,0,0,1
1,0,0,0,0,2,0,0,0,0,0,0,0,0,0,2,0,0,0,0,1
1,1,0,0,0,0,2,2,0,0,0,0,0,2,2,0,0,0,0,1,1
1,1,0,0,0,0,0,0,2,2,2,2,2,0,0,0,0,0,0,1,1
1,1,1,0,0,0,0,0,0,0,0,0,0,0,0,0,0,0,1,1,1
1,1,1,1,0,0,0,0,0,0,0,0,0,0,0,0,0,1,1,1,1
1,1,1,1,1,1,0,0,0,0,0,0,0,0,0,1,1,1,1,1,1
1,1,1,1,1,1,1,1,2,0,0,0,2,1,1,1,1,1,1,1,1
endlayer

layer
1,1,1,1,1,1,1,1,2,2,3,2,2,1,1,1,1,1,1,1,1
1,1,1,1,1,1,0,0,3,3,3,3,3,0,0,1,1,1,1,1,1
1,1,1,1,0,0,0,0,3,3,8,3,3,0,0,0,0,1,1,1,1
1,1,1,0,0,0,0,0,3,3,3,3,3,0,0,0,0,0,1,1,1
1,1,0,0,0,0,0,0,3,3,3,3,3,0,0,0,0,0,0,1,1
1,1,0,0,0,0,3,3,3,3,3,3,3,3,3,0,0,0,0,1,1
1,0,0,0,0,3,0,0,7,3,3,3,3,3,3,3,0,0,0,0,1
1,0,0,0,0,3,0,3,3,3,3,3,3,3,3,3,0,0,0,0,1
2,3,3,3,3,3,18,3,14,14,2,14,14,3,3,3,3,3,3,3,2
2,3,3,3,3,3,3,3,14,2,14,2,14,3,3,3,3,3,3,3,2
3,3,8,3,3,3,3,3,2,14,8,14,2,3,3,3,3,3,8,3,3
2,3,3,3,3,3,3,3,14,2,14,2,14,3,3,3,3,3,3,3,2
2,3,3,3,3,3,3,3,14,14,2,14,14,3,3,3,3,3,3,3,2
1,0,0,0,0,3,3,3,3,3,3,3,3,3,3,3,0,0,0,0,1
1,0,0,0,0,3,3,3,3,3,3,3,3,3,3,3,0,0,0,0,1
1,1,0,0,0,0,3,3,3,3,3,3,3,3,3,0,0,0,0,1,1
1,1,0,0,0,0,0,0,3,3,3,3,3,0,0,0,0,0,0,1,1
1,1,1,0,0,0,0,0,3,3,3,3,3,0,0,0,0,0,1,1,1
1,1,1,1,0,0,0,0,3,3,8,3,3,0,0,0,0,1,1,1,1
1,1,1,1,1,1,0,0,3,3,3,3,3,0,0,1,1,1,1,1,1
1,1,1,1,1,1,1,1,2,2,3,2,2,1,1,1,1,1,1,1,1
endlayer

layer
1,1,1,1,1,1,1,1,0,2,2,2,0,1,1,1,1,1,1,1,1
1,1,1,1,1,1,0,0,2,0,0,0,2,0,0,1,1,1,1,1,1
1,1,1,1,0,0,0,0,2,0,0,0,2,0,0,0,0,1,1,1,1
1,1,1,0,0,0,0,0,2,0,0,0,2,0,0,0,0,0,1,1,1
1,1,0,0,0,0,0,0,3,2,19,2,3,0,0,0,0,0,0,1,1
1,1,0,0,0,0,2,2,2,0,0,0,2,2,2,0,0,0,0,1,1
1,0,0,0,0,2,0,0,0,0,0,0,0,0,0,2,0,0,0,0,1
1,0,0,0,0,2,18,0,0,0,0,0,0,0,0,2,0,0,0,0,1
0,2,2,2,3,2,9,0,0,0,0,0,0,0,0,2,3,2,2,2,0
2,0,0,0,2,0,0,0,0,0,0,0,0,0,0,0,2,0,0,0,2
2,0,0,0,12,0,0,0,0,11,0,11,0,0,0,0,10,0,0,0,2
2,0,0,0,2,0,0,0,0,0,0,0,0,0,0,0,2,0,0,0,2
0,2,2,2,3,2,0,0,0,0,0,0,0,0,0,2,3,2,2,2,0
1,0,0,0,0,2,0,0,0,0,0,0,0,0,0,2,0,0,0,0,1
1,0,0,0,0,2,0,0,0,0,0,0,0,0,0,2,0,0,0,0,1
1,1,0,0,0,0,2,2,2,0,0,0,2,2,2,0,0,0,0,1,1
1,1,0,0,0,0,0,0,3,2,20,2,3,0,0,0,0,0,0,1,1
1,1,1,0,0,0,0,0,2,0,0,0,2,0,0,0,0,0,1,1,1
1,1,1,1,0,0,0,0,2,0,0,0,2,0,0,0,0,1,1,1,1
1,1,1,1,1,1,0,0,2,0,0,0,2,0,0,1,1,1,1,1,1
1,1,1,1,1,1,1,1,0,2,2,2,0,1,1,1,1,1,1,1,1
endlayer

layer
1,1,1,1,1,1,1,1,0,2,14,2,0,1,1,1,1,1,1,1,1
1,1,1,1,1,1,0,0,2,0,0,0,2,0,0,1,1,1,1,1,1
1,1,1,1,0,0,0,0,14,0,0,0,14,0,0,0,0,1,1,1,1
1,1,1,0,0,0,0,0,2,0,0,0,2,0,0,0,0,0,1,1,1
1,1,0,0,0,0,0,0,3,2,17,2,3,0,0,0,0,0,0,1,1
1,1,0,0,0,0,2,14,2,0,0,0,2,14,2,0,0,0,0,1,1
1,0,0,0,0,2,15,0,0,0,0,0,0,0,0,2,0,0,0,0,1
1,0,0,0,0,14,9,0,0,0,0,0,0,0,0,14,0,0,0,0,1
0,2,14,2,3,2,0,0,0,0,0,0,0,0,0,2,3,2,14,2,0
2,0,0,0,2,0,0,0,0,0,0,0,0,0,0,0,2,0,0,0,2
14,0,0,0,17,0,0,0,0,0,0,0,0,0,0,0,17,0,0,0,14
2,0,0,0,2,0,0,0,0,0,0,0,0,0,0,0,2,0,0,0,2
0,2,14,2,3,2,0,0,0,0,0,0,0,0,0,2,3,2,14,2,0
1,0,0,0,0,14,0,0,0,0,0,0,0,0,0,14,0,0,0,0,1
1,0,0,0,0,2,0,0,0,0,0,0,0,0,0,2,0,0,0,0,1
1,1,0,0,0,0,2,14,2,0,0,0,2,14,2,0,0,0,0,1,1
1,1,0,0,0,0,0,0,3,2,17,2,3,0,0,0,0,0,0,1,1
1,1,1,0,0,0,0,0,2,0,0,0,2,0,0,0,0,0,1,1,1
1,1,1,1,0,0,0,0,14,0,0,0,14,0,0,0,0,1,1,1,1
1,1,1,1,1,1,0,0,2,0,0,0,2,0,0,1,1,1,1,1,1
1,1,1,1,1,1,1,1,0,2,14,2,0,1,1,1,1,1,1,1,1
endlayer

layer
1,1,1,1,1,1,1,1,0,2,2,2,0,1,1,1,1,1,1,1,1
1,1,1,1,1,1,0,0,2,0,0,0,2,0,0,1,1,1,1,1,1
1,1,1,1,0,0,0,0,2,0,0,0,2,0,0,0,0,1,1,1,1
1,1,1,0,2,0,0,0,2,0,0,0,2,0,0,0,2,0,1,1,1
1,1,0,2,0,0,0,0,3,2,2,2,3,0,0,0,0,2,0,1,1
1,1,0,0,0,0,2,2,2,0,0,0,2,2,2,0,0,0,0,1,1
1,0,0,0,0,2,9,15,0,0,0,0,0,0,0,2,0,0,0,0,1
1,0,0,0,0,2,0,0,0,0,0,0,0,0,0,2,0,0,0,0,1
0,2,2,2,3,2,0,0,0,0,0,0,0,0,0,2,3,2,2,2,0
2,0,0,0,2,0,0,0,0,0,0,0,0,0,0,0,2,0,0,0,2
2,0,0,0,2,0,0,0,0,0,0,0,0,0,0,0,2,0,0,0,2
2,0,0,0,2,0,0,0,0,0,0,0,0,0,0,0,2,0,0,0,2
0,2,2,2,3,2,0,0,0,0,0,0,0,0,0,2,3,2,2,2,0
1,0,0,0,0,2,0,0,0,0,0,0,0,0,0,2,0,0,0,0,1
1,0,0,0,0,2,0,0,0,0,0,0,0,0,0,2,0,0,0,0,1
1,1,0,0,0,0,2,2,2,0,0,0,2,2,2,0,0,0,0,1,1
1,1,0,2,0,0,0,0,3,2,2,2,3,0,0,0,0,2,0,1,1
1,1,1,0,2,0,0,0,2,0,0,0,2,0,0,0,2,0,1,1,1
1,1,1,1,0,0,0,0,2,0,0,0,2,0,0,0,0,1,1,1,1
1,1,1,1,1,1,0,0,2,0,0,0,2,0,0,1,1,1,1,1,1
1,1,1,1,1,1,1,1,0,2,2,2,0,1,1,1,1,1,1,1,1
endlayer

layer
1,1,1,1,1,1,1,1,2,2,3,2,2,1,1,1,1,1,1,1,1
1,1,1,1,1,1,0,0,0,3,3,3,0,0,0,1,1,1,1,1,1
1,1,1,1,0,2,2,2,2,3,3,3,2,2,2,2,0,1,1,1,1
1,1,1,0,2,3,3,3,3,3,3,3,3,3,3,3,2,0,1,1,1
1,1,0,2,3,3,3,3,3,3,3,3,3,3,3,3,3,2,0,1,1
1,1,2,3,3,3,3,3,3,3,3,3,3,3,3,3,3,3,2,1,1
1,0,2,3,3,3,0,7,3,3,3,3,3,3,3,3,3,3,2,0,1
1,0,2,3,3,3,0,3,3,3,3,3,3,3,3,3,3,3,2,0,1
2,0,2,3,3,3,0,3,14,14,2,14,14,3,3,3,3,3,2,0,2
2,3,3,3,3,3,3,3,14,2,14,2,14,3,3,3,3,3,3,3,2
3,3,3,3,3,3,3,3,2,14,8,14,2,3,3,3,3,3,3,3,3
2,3,3,3,3,3,3,3,14,2,14,2,14,3,3,3,3,3,3,3,2
2,0,2,3,3,3,3,3,14,14,2,14,14,3,3,3,3,3,2,0,2
1,0,2,3,3,3,3,3,3,3,3,3,3,3,3,3,3,3,2,0,1
1,0,2,3,3,3,3,3,3,3,3,3,3,3,3,3,3,3,2,0,1
1,1,2,3,3,3,3,3,3,3,3,3,3,3,3,3,3,3,2,1,1
1,1,0,2,3,3,3,3,3,3,3,3,3,3,3,3,3,2,0,1,1
1,1,1,0,2,3,3,3,3,3,3,3,3,3,3,3,2,0,1,1,1
1,1,1,1,0,2,2,2,2,3,3,3,2,2,2,2,0,1,1,1,1
1,1,1,1,1,1,0,0,0,3,3,3,0,0,0,1,1,1,1,1,1
1,1,1,1,1,1,1,1,2,2,3,2,2,1,1,1,1,1,1,1,1
endlayer

layer
1,1,1,1,1,1,1,1,2,21,21,21,2,1,1,1,1,1,1,1,1
1,1,1,1,1,1,0,0,21,0,0,0,21,0,0,1,1,1,1,1,1
1,1,1,1,0,2,2,2,2,0,0,0,2,2,2,2,0,1,1,1,1
1,1,1,0,2,0,0,0,0,0,0,0,0,0,0,0,2,0,1,1,1
1,1,0,2,0,0,0,0,2,2,2,2,2,0,0,0,0,2,0,1,1
1,1,2,0,0,0,2,2,0,0,0,0,0,2,2,0,0,0,2,1,1
1,0,2,0,0,2,0,0,0,0,0,0,0,0,0,2,0,0,2,0,1
1,0,2,0,0,2,0,0,0,0,0,0,0,0,0,2,0,0,2,0,1
2,21,2,0,2,9,9,0,0,0,0,0,0,0,0,0,2,0,2,21,2
21,0,0,0,12,0,0,0,0,0,11,0,0,0,0,0,2,0,0,0,21
21,0,0,0,2,0,0,0,0,0,0,0,0,0,0,0,2,0,0,0,21
21,0,0,0,2,0,0,0,0,0,11,0,0,0,0,0,10,0,0,0,21
2,21,2,0,2,0,0,0,0,0,0,0,0,0,0,0,2,0,2,21,2
1,0,2,0,0,2,0,0,0,0,0,0,0,0,0,2,0,0,2,0,1
1,0,2,0,0,2,0,0,0,0,0,0,0,0,0,2,0,0,2,0,1
1,1,2,0,0,0,2,2,0,0,0,0,0,2,2,0,0,0,2,1,1
1,1,0,2,0,0,0,0,2,2,2,2,2,0,0,0,0,2,0,1,1
1,1,1,0,2,0,0,0,0,0,0,0,0,0,0,0,2,0,1,1,1
1,1,1,1,0,2,2,2,2,0,0,0,2,2,2,2,0,1,1,1,1
1,1,1,1,1,1,0,0,21,0,0,0,21,0,0,1,1,1,1,1,1
1,1,1,1,1,1,1,1,2,21,21,21,2,1,1,1,1,1,1,1,1
endlayer

layer
1,1,1,1,1,1,1,1,2,13,13,13,2,1,1,1,1,1,1,1,1
1,1,1,1,1,1,0,0,13,0,0,0,13,0,0,1,1,1,1,1,1
1,1,1,1,0,13,13,13,13,0,0,0,13,13,13,13,0,1,1,1,1
1,1,1,0,13,0,0,0,0,0,0,0,0,0,0,0,13,0,1,1,1
1,1,0,13,0,0,0,0,2,14,2,14,2,0,0,0,0,13,0,1,1
1,1,13,0,0,0,2,14,0,0,0,0,0,14,2,0,0,0,13,1,1
1,0,13,0,0,2,0,0,0,0,0,0,0,0,0,2,0,0,13,0,1
1,0,13,0,0,14,9,0,0,0,0,0,0,0,0,14,0,0,13,0,1
2,13,13,0,2,0,0,0,0,0,0,0,0,0,0,0,2,0,13,13,2
13,0,0,0,16,0,0,0,0,0,0,0,0,0,0,0,14,0,0,0,13
13,0,0,0,2,0,0,0,0,0,0,0,0,0,0,0,2,0,0,0,13
13,0,0,0,14,0,0,0,0,0,0,0,0,0,0,0,17,0,0,0,13
2,13,13,0,2,0,0,0,0,0,0,0,0,0,0,0,2,0,13,13,2
1,0,13,0,0,14,0,0,0,0,0,0,0,0,0,14,0,0,13,0,1
1,0,13,0,0,2,0,0,0,0,0,0,0,0,0,2,0,0,13,0,1
1,1,13,0,0,0,2,14,0,0,0,0,0,14,2,0,0,0,13,1,1
1,1,0,13,0,0,0,0,2,14,2,14,2,0,0,0,0,13,0,1,1
1,1,1,0,13,0,0,0,0,0,0,0,0,0,0,0,13,0,1,1,1
1,1,1,1,0,13,13,13,13,0,0,0,13,13,13,13,0,1,1,1,1
1,1,1,1,1,1,0,0,13,0,0,0,13,0,0,1,1,1,1,1,1
1,1,1,1,1,1,1,1,2,13,13,13,2,1,1,1,1,1,1,1,1
endlayer

layer
1,1,1,1,1,1,1,1,22,0,0,0,22,1,1,1,1,1,1,1,1
1,1,1,1,1,1,0,0,0,0,0,0,0,0,0,1,1,1,1,1,1
1,1,1,1,0,0,0,0,0,0,0,0,0,0,0,0,0,1,1,1,1
1,1,1,0,0,0,0,0,0,0,0,0,0,0,0,0,0,0,1,1,1
1,1,0,0,0,0,0,0,2,2,2,2,2,0,0,0,0,0,0,1,1
1,1,0,0,0,0,2,2,0,0,0,0,0,2,2,0,0,0,0,1,1
1,0,0,0,0,2,9,15,0,0,0,0,0,0,0,2,0,0,0,0,1
1,0,0,0,0,2,0,0,0,0,0,0,0,0,0,2,0,0,0,0,1
22,0,0,0,2,0,0,0,0,0,0,0,0,0,0,0,2,0,0,0,22
0,0,0,0,2,0,0,0,0,0,0,0,0,0,0,0,2,0,0,0,0
0,0,0,0,2,0,0,0,0,0,0,0,0,0,0,0,2,0,0,0,0
0,0,0,0,2,0,0,0,0,0,0,0,0,0,0,0,2,0,0,0,0
22,0,0,0,2,0,0,0,0,0,0,0,0,0,0,0,2,0,0,0,22
1,0,0,0,0,2,0,0,0,0,0,0,0,0,0,2,0,0,0,0,1
1,0,0,0,0,2,0,0,0,0,0,0,0,0,0,2,0,0,0,0,1
1,1,0,0,0,0,2,2,0,0,0,0,0,2,2,0,0,0,0,1,1
1,1,0,0,0,0,0,0,2,2,2,2,2,0,0,0,0,0,0,1,1
1,1,1,0,0,0,0,0,0,0,0,0,0,0,0,0,0,0,1,1,1
1,1,1,1,0,0,0,0,0,0,0,0,0,0,0,0,0,1,1,1,1
1,1,1,1,1,1,0,0,0,0,0,0,0,0,0,1,1,1,1,1,1
1,1,1,1,1,1,1,1,22,0,0,0,22,1,1,1,1,1,1,1,1
endlayer

layer
1,1,1,1,1,1,1,1,0,0,0,0,0,1,1,1,1,1,1,1,1
1,1,1,1,1,1,0,0,0,0,0,0,0,0,0,1,1,1,1,1,1
1,1,1,1,0,0,0,0,0,0,0,0,0,0,0,0,0,1,1,1,1
1,1,1,0,0,0,0,0,3,3,3,3,3,0,0,0,0,0,1,1,1
1,1,0,0,0,0,3,3,3,3,3,3,3,3,3,0,0,0,0,1,1
1,1,0,0,0,3,3,3,2,2,2,2,2,3,3,3,0,0,0,1,1
1,0,0,0,3,3,0,7,2,3,3,3,2,2,2,3,3,0,0,0,1
1,0,0,0,3,3,0,3,3,3,3,3,3,3,2,3,3,0,0,0,1
0,0,0,3,3,2,0,3,14,14,2,14,14,3,2,2,3,3,0,0,0
0,0,0,3,3,2,3,3,14,2,14,2,14,3,3,2,3,3,0,0,0
0,0,0,3,3,2,3,3,2,14,8,14,2,3,3,2,3,3,0,0,0
0,0,0,3,3,2,3,3,14,2,14,2,14,3,3,2,3,3,0,0,0
0,0,0,3,3,2,2,3,14,14,2,14,14,3,2,2,3,3,0,0,0
1,0,0,0,3,3,2,3,3,3,3,3,3,3,2,3,3,0,0,0,1
1,0,0,0,3,3,2,2,2,3,3,3,2,2,2,3,3,0,0,0,1
1,1,0,0,0,3,3,3,2,2,2,2,2,3,3,3,0,0,0,1,1
1,1,0,0,0,0,3,3,3,3,3,3,3,3,3,0,0,0,0,1,1
1,1,1,0,0,0,0,0,3,3,3,3,3,0,0,0,0,0,1,1,1
1,1,1,1,0,0,0,0,0,0,0,0,0,0,0,0,0,1,1,1,1
1,1,1,1,1,1,0,0,0,0,0,0,0,0,0,1,1,1,1,1,1
1,1,1,1,1,1,1,1,0,0,0,0,0,1,1,1,1,1,1,1,1
endlayer

layer
1,1,1,1,1,1,1,1,0,0,0,0,0,1,1,1,1,1,1,1,1
1,1,1,1,1,1,0,0,0,0,0,0,0,0,0,1,1,1,1,1,1
1,1,1,1,0,0,0,0,2,2,2,2,2,0,0,0,0,1,1,1,1
1,1,1,0,0,0,2,2,0,0,0,0,0,2,2,0,0,0,1,1,1
1,1,0,0,0,2,0,0,0,0,0,0,0,0,0,2,0,0,0,1,1
1,1,0,0,2,0,0,0,13,13,13,13,13,0,0,0,2,0,0,1,1
1,0,0,2,0,0,0,0,13,0,0,0,13,13,13,0,0,2,0,0,1
1,0,0,2,0,0,0,0,0,0,0,0,0,0,13,0,0,2,0,0,1
0,0,2,0,0,13,0,0,0,0,0,0,0,0,13,13,0,0,2,0,0
0,0,2,0,0,13,0,0,0,0,0,0,0,0,0,13,0,0,2,0,0
0,0,2,0,0,13,0,0,0,11,0,11,0,0,0,13,0,0,2,0,0
0,0,2,0,0,13,0,0,0,0,0,0,0,0,0,13,0,0,2,0,0
0,0,2,0,0,13,13,0,0,0,0,0,0,0,13,13,0,0,2,0,0
1,0,0,2,0,0,13,0,0,0,0,0,0,0,13,0,0,2,0,0,1
1,0,0,2,0,0,13,13,13,0,0,0,13,13,13,0,0,2,0,0,1
1,1,0,0,2,0,0,0,13,13,13,13,13,0,0,0,2,0,0,1,1
1,1,0,0,0,2,0,0,0,0,0,0,0,0,0,2,0,0,0,1,1
1,1,1,0,0,0,2,2,0,0,0,0,0,2,2,0,0,0,1,1,1
1,1,1,1,0,0,0,0,2,2,2,2,2,0,0,0,0,1,1,1,1
1,1,1,1,1,1,0,0,0,0,0,0,0,0,0,1,1,1,1,1,1
1,1,1,1,1,1,1,1,0,0,0,0,0,1,1,1,1,1,1,1,1
endlayer

layer
1,1,1,1,1,1,1,1,0,0,0,0,0,1,1,1,1,1,1,1,1
1,1,1,1,1,1,0,0,0,0,0,0,0,0,0,1,1,1,1,1,1
1,1,1,1,0,0,0,0,13,2,13,2,13,0,0,0,0,1,1,1,1
1,1,1,0,0,0,13,2,0,0,0,0,0,2,13,0,0,0,1,1,1
1,1,0,0,0,2,0,0,0,0,0,0,0,0,0,2,0,0,0,1,1
1,1,0,0,13,0,0,0,0,0,0,0,0,0,0,0,13,0,0,1,1
1,0,0,2,0,0,0,0,0,0,0,0,0,0,0,0,0,2,0,0,1
1,0,0,13,0,0,0,0,0,0,0,0,0,0,0,0,0,13,0,0,1
0,0,2,0,0,0,0,0,0,0,0,0,0,0,0,0,0,0,2,0,0
0,0,13,0,0,0,0,0,0,0,0,0,0,0,0,0,0,0,13,0,0
0,0,2,0,0,0,0,0,0,0,0,0,0,0,0,0,0,0,2,0,0
0,0,13,0,0,0,0,0,0,0,0,0,0,0,0,0,0,0,13,0,0
0,0,2,0,0,0,0,0,0,0,0,0,0,0,0,0,0,0,2,0,0
1,0,0,13,0,0,0,0,0,0,0,0,0,0,0,0,0,13,0,0,1
1,0,0,2,0,0,0,0,0,0,0,0,0,0,0,0,0,2,0,0,1
1,1,0,0,13,0,0,0,0,0,0,0,0,0,0,0,13,0,0,1,1
1,1,0,0,0,2,0,0,0,0,0,0,0,0,0,2,0,0,0,1,1
1,1,1,0,0,0,13,2,0,0,0,0,0,2,13,0,0,0,1,1,1
1,1,1,1,0,0,0,0,13,2,13,2,13,0,0,0,0,1,1,1,1
1,1,1,1,1,1,0,0,0,0,0,0,0,0,0,1,1,1,1,1,1
1,1,1,1,1,1,1,1,0,0,0,0,0,1,1,1,1,1,1,1,1
endlayer

layer
1,1,1,1,1,1,1,1,0,0,0,0,0,1,1,1,1,1,1,1,1
1,1,1,1,1,1,0,0,0,0,0,0,0,0,0,1,1,1,1,1,1
1,1,1,1,0,0,0,0,0,13,0,13,0,0,0,0,0,1,1,1,1
1,1,1,0,0,0,0,13,0,0,0,0,0,13,0,0,0,0,1,1,1
1,1,0,0,0,13,0,0,0,0,0,0,0,0,0,13,0,0,0,1,1
1,1,0,0,0,0,0,0,0,0,0,0,0,0,0,0,0,0,0,1,1
1,0,0,13,0,0,0,0,0,0,0,0,0,0,0,0,0,13,0,0,1
1,0,0,0,0,0,0,0,0,0,0,0,0,0,0,0,0,0,0,0,1
0,0,13,0,0,0,0,0,0,0,0,0,0,0,0,0,0,0,13,0,0
0,0,0,0,0,0,0,0,0,0,0,0,0,0,0,0,0,0,0,0,0
0,0,13,0,0,0,0,0,0,0,0,0,0,0,0,0,0,0,13,0,0
0,0,0,0,0,0,0,0,0,0,0,0,0,0,0,0,0,0,0,0,0
0,0,13,0,0,0,0,0,0,0,0,0,0,0,0,0,0,0,13,0,0
1,0,0,0,0,0,0,0,0,0,0,0,0,0,0,0,0,0,0,0,1
1,0,0,13,0,0,0,0,0,0,0,0,0,0,0,0,0,13,0,0,1
1,1,0,0,0,0,0,0,0,0,0,0,0,0,0,0,0,0,0,1,1
1,1,0,0,0,13,0,0,0,0,0,0,0,0,0,13,0,0,0,1,1
1,1,1,0,0,0,0,13,0,0,0,0,0,13,0,0,0,0,1,1,1
1,1,1,1,0,0,0,0,0,13,0,13,0,0,0,0,0,1,1,1,1
1,1,1,1,1,1,0,0,0,0,0,0,0,0,0,1,1,1,1,1,1
1,1,1,1,1,1,1,1,0,0,0,0,0,1,1,1,1,1,1,1,1
endlayer
