
# Created by Ruins mod version 17.1 Ingame Parser
# authoring Player: ST753M

weight=1
uniqueMinDistance=2000
embed_into_distance=6
acceptable_target_blocks=
unacceptable_target_blocks=flowing_water,water,flowing_lava,lava,iron_bars,Natura:Cloud,slime_congealed,clouds,natura:clouds,twilightforest:wispy_cloud,twilightforest:fluffy_cloud
dimensions=12,15,15
allowable_overhang=7
max_leveling=0
leveling_buffer=0
preserve_water=0
preserve_lava=0

adjoining_template=mesa/753_Bone_Smallskull;15;99;-8;60
adjoining_template=mesa/753_Bone_Smallspine;-11;99;7;60
adjoining_template=mesa/753_Bone_Smallspine;-8;99;12;60
adjoining_template=mesa/753_Bone_Vertical;7;99;-15;60
adjoining_template=mesa/753_Bone_Smallspine;-15;99;-6;60
adjoining_template=mesa/753_Bone_Smallspine;15;99;4;60
adjoining_template=mesa/753_Bone_Smallspine;-6;99;-14;60
adjoining_template=mesa/753_Bone_Smallskull;6;99;14;60
adjoining_template=mesa/753_Bone_Vertical;11;99;-18;60
adjoining_template=mesa/753_Bone_Smallskull;-13;99;-13;60
adjoining_template=mesa/753_Bone_Smallspine;0;99;10;60
adjoining_template=mesa/753_Bone_Vertical;1;99;-11;60
adjoining_template=mesa/753_Bone_Smallspine;13;99;1;60
adjoining_template=mesa/753_Bone_Vertical;-11;99;0;60

biomesToSpawnIn=dead_swamp,dead_forest,snowy_dead_forest,dead_snowy_forest,badlands,wasteland,brushland,fire_swamp,swamp_defiled,desert_defiled,plains_defiled,ice_plains_defiled,hills_defiled,forest_tenebra,forest_vilespine,darklands,darklands_forest,darklands_hills,darklands_mountains,darklands_plains,ominous_woods,eerie,sludge_plains

=0,100,preserveBlock
rule1=1,70,!nex:block_bone_sliver-1
rule2=0,100,!minecraft:bone_block-0
rule3=1,100,!minecraft:redstone_torch-5
rule4=0,100,!minecraft:bone_block-4
rule5=0,100,!minecraft:bone_block-8
rule6=0,100,MobSpawner:nex:monster_bone_spider

layer
0,0,0,1,0,0,1,0,1,0,0,1,0,0,0
0,0,0,0,1,0,0,0,0,0,1,0,0,0,0
0,0,1,0,0,0,0,0,0,0,0,0,1,0,0
1,0,0,1,0,0,0,0,0,0,0,1,0,0,1
0,1,0,0,0,0,0,1,0,0,0,0,0,1,0
0,0,0,0,0,1,0,0,0,1,0,0,0,0,0
1,0,0,0,0,0,0,0,0,0,0,0,0,0,1
0,0,0,0,1,0,0,0,0,0,1,0,0,0,0
1,0,0,0,0,0,0,0,0,0,0,0,0,0,1
0,0,0,0,0,1,0,0,0,1,0,0,0,0,0
0,1,0,0,0,0,0,1,0,0,0,0,0,1,0
1,0,0,1,0,0,0,0,0,0,0,1,0,0,1
0,0,1,0,0,0,0,0,0,0,0,0,1,0,0
0,0,0,0,1,0,0,0,0,0,1,0,0,0,0
0,0,0,1,0,0,1,0,1,0,0,1,0,0,0
endlayer

layer
0,0,0,1,0,0,1,0,1,0,0,1,0,0,0
0,0,0,0,1,0,0,0,0,0,1,0,0,0,0
0,0,1,0,0,0,0,0,0,0,0,0,1,0,0
1,0,0,1,0,0,0,0,0,0,0,1,0,0,1
0,1,0,0,0,0,0,1,0,0,0,0,0,1,0
0,0,0,0,0,1,0,0,0,1,0,0,0,0,0
1,0,0,0,0,0,0,0,0,0,0,0,0,0,1
0,0,0,0,1,0,0,0,0,0,1,0,0,0,0
1,0,0,0,0,0,0,0,0,0,0,0,0,0,1
0,0,0,0,0,1,0,0,0,1,0,0,0,0,0
0,1,0,0,0,0,0,1,0,0,0,0,0,1,0
1,0,0,1,0,0,0,0,0,0,0,1,0,0,1
0,0,1,0,0,0,0,0,0,0,0,0,1,0,0
0,0,0,0,1,0,0,0,0,0,1,0,0,0,0
0,0,0,1,0,0,1,0,1,0,0,1,0,0,0
endlayer

layer
0,0,0,1,0,0,1,0,1,0,0,1,0,0,0
0,0,0,0,1,0,0,0,0,0,1,0,0,0,0
0,0,1,0,0,0,0,0,0,0,0,0,1,0,0
1,0,0,1,0,0,0,0,0,0,0,1,0,0,1
0,1,0,0,0,0,0,2,0,0,0,0,0,1,0
0,0,0,0,0,2,0,0,0,2,0,0,0,0,0
1,0,0,0,0,0,0,0,0,0,0,0,0,0,1
0,0,0,0,2,0,0,0,0,0,2,0,0,0,0
1,0,0,0,0,0,0,0,0,0,0,0,0,0,1
0,0,0,0,0,2,0,0,0,2,0,0,0,0,0
0,1,0,0,0,0,0,2,0,0,0,0,0,1,0
1,0,0,1,0,0,0,0,0,0,0,1,0,0,1
0,0,1,0,0,0,0,0,0,0,0,0,1,0,0
0,0,0,0,1,0,0,0,0,0,1,0,0,0,0
0,0,0,1,0,0,1,0,1,0,0,1,0,0,0
endlayer

layer
0,0,0,1,0,0,1,0,1,0,0,1,0,0,0
0,0,0,0,1,0,0,0,0,0,1,0,0,0,0
0,0,1,0,0,0,0,0,0,0,0,0,1,0,0
1,0,0,1,0,0,0,0,0,0,0,1,0,0,1
0,1,0,0,0,0,0,2,0,0,0,0,0,1,0
0,0,0,0,0,2,0,0,0,2,0,0,0,0,0
1,0,0,0,0,0,0,0,0,0,0,0,0,0,1
0,0,0,0,2,0,0,1,0,0,2,0,0,0,0
1,0,0,0,0,0,0,0,0,0,0,0,0,0,1
0,0,0,0,0,2,0,0,0,2,0,0,0,0,0
0,1,0,0,0,0,0,2,0,0,0,0,0,1,0
1,0,0,1,0,0,0,0,0,0,0,1,0,0,1
0,0,1,0,0,0,0,0,0,0,0,0,1,0,0
0,0,0,0,1,0,0,0,0,0,1,0,0,0,0
0,0,0,1,0,0,1,0,1,0,0,1,0,0,0
endlayer

layer
0,0,0,1,0,0,1,0,1,0,0,1,0,0,0
0,0,0,0,1,0,0,0,0,0,1,0,0,0,0
0,0,1,0,0,0,0,0,0,0,0,0,1,0,0
1,0,0,1,0,0,0,0,0,0,0,1,0,0,1
0,1,0,0,0,0,0,2,0,0,0,0,0,1,0
0,0,0,0,0,2,0,0,0,2,0,0,0,0,0
1,0,0,0,0,0,0,0,0,0,0,0,0,0,1
0,0,0,0,2,0,0,2,0,0,2,0,0,0,0
1,0,0,0,0,0,0,0,0,0,0,0,0,0,1
0,0,0,0,0,2,0,0,0,2,0,0,0,0,0
0,1,0,0,0,0,0,2,0,0,0,0,0,1,0
1,0,0,1,0,0,0,0,0,0,0,1,0,0,1
0,0,1,0,0,0,0,0,0,0,0,0,1,0,0
0,0,0,0,1,0,0,0,0,0,1,0,0,0,0
0,0,0,1,0,0,1,0,1,0,0,1,0,0,0
endlayer

layer
0,0,0,1,0,0,1,0,1,0,0,1,0,0,0
0,0,0,0,1,0,0,0,0,0,1,0,0,0,0
0,0,3,0,0,0,0,0,0,0,0,0,3,0,0
1,0,0,1,0,0,0,0,0,0,0,1,0,0,1
0,1,0,0,0,0,0,2,0,0,0,0,0,1,0
0,0,0,0,0,2,0,4,0,2,0,0,0,0,0
1,0,0,0,0,0,0,4,0,0,0,0,0,0,1
0,0,0,0,2,5,5,6,5,5,2,0,0,0,0
1,0,0,0,0,0,0,4,0,0,0,0,0,0,1
0,0,0,0,0,2,0,4,0,2,0,0,0,0,0
0,1,0,0,0,0,0,2,0,0,0,0,0,1,0
1,0,0,1,0,0,0,0,0,0,0,1,0,0,1
0,0,3,0,0,0,0,0,0,0,0,0,3,0,0
0,0,0,0,1,0,0,0,0,0,1,0,0,0,0
0,0,0,1,0,0,1,0,1,0,0,1,0,0,0
endlayer

layer
0,0,0,1,0,0,1,0,1,0,0,1,0,0,0
0,0,0,0,1,0,0,0,0,0,1,0,0,0,0
0,0,0,0,0,0,0,0,0,0,0,0,0,0,0
1,0,0,1,0,0,0,0,0,0,0,1,0,0,1
0,1,0,0,0,0,0,2,0,0,0,0,0,1,0
0,0,0,0,0,2,0,0,0,2,0,0,0,0,0
1,0,0,0,0,0,0,0,0,0,0,0,0,0,1
0,0,0,0,2,0,0,2,0,0,2,0,0,0,0
1,0,0,0,0,0,0,0,0,0,0,0,0,0,1
0,0,0,0,0,2,0,0,0,2,0,0,0,0,0
0,1,0,0,0,0,0,2,0,0,0,0,0,1,0
1,0,0,1,0,0,0,0,0,0,0,1,0,0,1
0,0,0,0,0,0,0,0,0,0,0,0,0,0,0
0,0,0,0,1,0,0,0,0,0,1,0,0,0,0
0,0,0,1,0,0,1,0,1,0,0,1,0,0,0
endlayer

layer
0,0,0,3,0,0,1,0,1,0,0,3,0,0,0
0,0,0,0,1,0,0,0,0,0,1,0,0,0,0
0,0,0,0,0,0,0,0,0,0,0,0,0,0,0
3,0,0,1,0,0,0,0,0,0,0,1,0,0,3
0,1,0,0,0,0,0,2,0,0,0,0,0,1,0
0,0,0,0,0,2,0,0,0,2,0,0,0,0,0
1,0,0,0,0,0,0,0,0,0,0,0,0,0,1
0,0,0,0,2,0,0,1,0,0,2,0,0,0,0
1,0,0,0,0,0,0,0,0,0,0,0,0,0,1
0,0,0,0,0,2,0,0,0,2,0,0,0,0,0
0,1,0,0,0,0,0,2,0,0,0,0,0,1,0
3,0,0,1,0,0,0,0,0,0,0,1,0,0,3
0,0,0,0,0,0,0,0,0,0,0,0,0,0,0
0,0,0,0,1,0,0,0,0,0,1,0,0,0,0
0,0,0,3,0,0,1,0,1,0,0,3,0,0,0
endlayer

layer
0,0,0,0,0,0,1,0,1,0,0,0,0,0,0
0,0,0,0,1,0,0,0,0,0,1,0,0,0,0
0,0,0,0,0,0,0,0,0,0,0,0,0,0,0
0,0,0,1,0,0,0,0,0,0,0,1,0,0,0
0,1,0,0,0,0,0,1,0,0,0,0,0,1,0
0,0,0,0,0,1,0,0,0,1,0,0,0,0,0
1,0,0,0,0,0,0,0,0,0,0,0,0,0,1
0,0,0,0,1,0,0,1,0,0,1,0,0,0,0
1,0,0,0,0,0,0,0,0,0,0,0,0,0,1
0,0,0,0,0,1,0,0,0,1,0,0,0,0,0
0,1,0,0,0,0,0,1,0,0,0,0,0,1,0
0,0,0,1,0,0,0,0,0,0,0,1,0,0,0
0,0,0,0,0,0,0,0,0,0,0,0,0,0,0
0,0,0,0,1,0,0,0,0,0,1,0,0,0,0
0,0,0,0,0,0,1,0,1,0,0,0,0,0,0
endlayer

layer
0,0,0,0,0,0,1,0,1,0,0,0,0,0,0
0,0,0,0,1,0,0,0,0,0,1,0,0,0,0
0,0,0,0,0,0,0,0,0,0,0,0,0,0,0
0,0,0,3,0,0,0,0,0,0,0,3,0,0,0
0,1,0,0,0,0,0,1,0,0,0,0,0,1,0
0,0,0,0,0,1,0,0,0,1,0,0,0,0,0
1,0,0,0,0,0,0,0,0,0,0,0,0,0,1
0,0,0,0,1,0,0,3,0,0,1,0,0,0,0
1,0,0,0,0,0,0,0,0,0,0,0,0,0,1
0,0,0,0,0,1,0,0,0,1,0,0,0,0,0
0,1,0,0,0,0,0,1,0,0,0,0,0,1,0
0,0,0,3,0,0,0,0,0,0,0,3,0,0,0
0,0,0,0,0,0,0,0,0,0,0,0,0,0,0
0,0,0,0,1,0,0,0,0,0,1,0,0,0,0
0,0,0,0,0,0,1,0,1,0,0,0,0,0,0
endlayer

layer
0,0,0,0,0,0,3,0,3,0,0,0,0,0,0
0,0,0,0,3,0,0,0,0,0,3,0,0,0,0
0,0,0,0,0,0,0,0,0,0,0,0,0,0,0
0,0,0,0,0,0,0,0,0,0,0,0,0,0,0
0,3,0,0,0,0,0,1,0,0,0,0,0,3,0
0,0,0,0,0,1,0,0,0,1,0,0,0,0,0
3,0,0,0,0,0,0,0,0,0,0,0,0,0,3
0,0,0,0,1,0,0,0,0,0,1,0,0,0,0
3,0,0,0,0,0,0,0,0,0,0,0,0,0,3
0,0,0,0,0,1,0,0,0,1,0,0,0,0,0
0,3,0,0,0,0,0,1,0,0,0,0,0,3,0
0,0,0,0,0,0,0,0,0,0,0,0,0,0,0
0,0,0,0,0,0,0,0,0,0,0,0,0,0,0
0,0,0,0,3,0,0,0,0,0,3,0,0,0,0
0,0,0,0,0,0,3,0,3,0,0,0,0,0,0
endlayer

layer
0,0,0,0,0,0,0,0,0,0,0,0,0,0,0
0,0,0,0,0,0,0,0,0,0,0,0,0,0,0
0,0,0,0,0,0,0,0,0,0,0,0,0,0,0
0,0,0,0,0,0,0,0,0,0,0,0,0,0,0
0,0,0,0,0,0,0,3,0,0,0,0,0,0,0
0,0,0,0,0,3,0,0,0,3,0,0,0,0,0
0,0,0,0,0,0,0,0,0,0,0,0,0,0,0
0,0,0,0,3,0,0,0,0,0,3,0,0,0,0
0,0,0,0,0,0,0,0,0,0,0,0,0,0,0
0,0,0,0,0,3,0,0,0,3,0,0,0,0,0
0,0,0,0,0,0,0,3,0,0,0,0,0,0,0
0,0,0,0,0,0,0,0,0,0,0,0,0,0,0
0,0,0,0,0,0,0,0,0,0,0,0,0,0,0
0,0,0,0,0,0,0,0,0,0,0,0,0,0,0
0,0,0,0,0,0,0,0,0,0,0,0,0,0,0
endlayer

