
# Created by Ruins mod version 16.5 Ingame Parser
# authoring Player: ST753M

weight=2
embed_into_distance=2
acceptable_target_blocks=grass,dirt,podzol,biomesoplenty:grass,biomesoplenty:dirt
unacceptable_target_blocks=flowing_water,water,flowing_lava,lava
dimensions=21,9,9
allowable_overhang=5
max_leveling=0
leveling_buffer=0
preserve_water=0
preserve_lava=0
preserve_plants=1

biomesToSpawnIn=mutated_plains,flower_island,mystic_grove,flower_field,lavender_fields,sacred_springs,origin_island,mutated_jungle_edge,mystic grove,flower island

rule1=0,100,preserveBlock
rule2=0,100,minecraft:stained_hardened_clay-13
rule3=0,100,minecraft:vine-8
rule4=0,100,minecraft:stained_hardened_clay-5
rule5=0,100,minecraft:vine-15
rule6=0,10,MobSpawner:Cave_Spider,MobSpawner:Spider,MobSpawner:Rabbit
rule7=0,100,minecraft:stained_hardened_clay-6
^0,100,minecraft:stained_hardened_clay-6
^0,100,minecraft:stained_hardened_clay-6
^0,100,minecraft:stained_hardened_clay-6
^0,100,minecraft:stained_hardened_clay-2
^0,100,minecraft:stained_hardened_clay-2
rule8=0,100,minecraft:dirt-0
rule9=0,100,minecraft:vine-11
rule10=0,100,minecraft:stained_glass-6
^0,100,minecraft:stained_glass-6
^0,100,minecraft:stained_glass-6
^0,100,minecraft:stained_glass-6
^0,100,minecraft:stained_glass-0
^0,100,minecraft:stained_glass-4
^0,100,minecraft:stained_glass-14
^0,100,minecraft:stained_glass-10
^0,100,minecraft:stained_glass-2
^0,100,minecraft:stained_glass-2
^0,100,minecraft:stained_glass-2
rule11=0,100,minecraft:double_plant-1
rule12=0,100,minecraft:double_plant-10

layer
1,1,1,1,1,1,1,1,1
1,2,2,1,1,1,1,1,1
1,1,1,1,1,1,2,2,2
1,1,1,1,1,1,1,1,1
1,1,1,1,1,1,1,1,1
1,2,2,1,1,1,1,1,1
1,1,2,1,1,1,1,1,1
1,1,1,1,1,1,1,1,1
1,1,1,1,1,1,1,1,1
endlayer

layer
1,1,1,1,1,1,1,1,1
1,1,2,2,2,2,1,1,1
1,1,1,2,2,2,2,1,1
1,1,1,1,2,1,1,1,1
1,1,2,2,1,1,1,1,1
1,1,2,1,1,1,1,1,1
1,1,1,1,1,1,1,1,1
1,1,1,1,1,1,1,1,1
1,1,1,1,1,1,1,1,1
endlayer

layer
1,1,1,1,0,1,1,1,1
1,1,1,0,0,1,1,1,1
1,1,1,2,0,2,1,1,1
1,1,1,2,3,2,1,1,1
1,1,1,2,2,1,1,1,1
1,1,1,1,1,1,1,1,1
1,1,1,1,1,1,1,1,1
1,1,1,1,1,1,1,1,1
1,1,1,1,1,1,1,1,1
endlayer

layer
0,0,0,0,0,0,0,0,0
0,4,4,0,0,0,0,0,0
0,4,4,2,3,2,0,0,0
0,0,0,2,3,2,0,0,0
0,0,0,0,2,0,0,0,0
0,0,0,0,0,0,0,0,0
0,0,0,0,0,0,0,0,0
0,0,0,0,0,0,0,0,0
0,0,0,0,0,0,0,0,0
endlayer

layer
4,4,0,0,0,0,0,0,0
4,4,0,0,0,0,0,4,4
0,0,0,0,2,0,0,4,4
0,0,0,2,3,2,0,0,0
0,0,0,2,3,2,0,0,0
0,0,0,0,2,0,0,0,0
0,0,0,0,4,4,0,0,0
0,0,0,0,4,4,0,0,0
0,0,0,0,0,0,0,0,0
endlayer

layer
0,0,0,0,0,0,0,0,0
0,0,0,0,0,0,0,0,0
0,0,0,0,2,0,4,4,0
0,0,0,2,3,2,4,4,0
0,0,0,2,3,2,0,0,0
0,0,0,0,2,0,0,0,0
0,0,0,0,0,0,0,0,0
0,0,0,0,0,4,4,0,0
0,0,0,0,0,4,4,0,0
endlayer

layer
0,0,0,0,0,0,0,0,0
0,0,0,0,0,0,0,0,0
0,0,0,0,0,0,0,0,0
0,0,0,0,2,0,0,0,0
0,0,0,2,3,2,0,0,0
0,0,0,0,2,0,0,0,0
0,0,0,0,0,0,0,0,0
0,0,0,0,0,0,0,0,0
0,0,0,0,0,0,0,0,0
endlayer

layer
0,0,0,0,4,0,0,0,0
0,0,0,0,0,0,0,0,0
0,0,0,0,0,0,0,0,0
0,0,0,0,2,0,0,0,0
4,0,0,2,3,2,0,0,4
0,0,0,0,2,0,0,0,0
0,0,0,0,0,0,0,0,0
0,0,0,0,0,0,0,0,0
0,0,0,0,4,0,0,0,0
endlayer

layer
0,0,0,0,0,0,0,0,0
0,0,0,0,4,0,0,0,0
0,0,0,0,4,0,0,0,0
0,0,0,4,4,4,0,0,0
0,4,4,4,3,4,4,4,0
0,0,0,4,4,4,0,0,0
0,0,0,0,4,0,0,0,0
0,0,0,0,4,0,0,0,0
0,0,0,0,0,0,0,0,0
endlayer

layer
0,0,0,0,0,0,0,0,0
0,0,4,0,0,0,4,0,0
0,4,4,4,0,4,4,4,0
0,0,4,4,2,4,4,0,0
0,0,0,2,5,2,0,0,0
0,0,4,6,2,4,4,0,0
0,4,4,4,0,4,4,4,0
0,0,4,0,0,0,4,0,0
0,0,0,0,0,0,0,0,0
endlayer

layer
0,0,0,0,0,0,0,0,0
0,4,4,0,0,0,4,4,0
0,4,0,0,7,0,0,4,0
0,0,0,7,2,7,0,0,0
0,0,7,2,5,2,7,0,0
0,0,0,7,2,7,0,0,0
0,4,0,0,7,0,0,4,0
0,4,4,0,0,0,4,4,0
0,0,0,0,0,0,0,0,0
endlayer

layer
4,4,0,0,0,0,0,4,4
4,0,0,7,7,7,0,0,4
0,0,7,7,8,7,7,0,0
0,7,7,8,8,8,7,7,0
0,7,8,8,9,8,8,7,0
0,7,7,8,8,8,7,10,0
0,0,7,7,8,7,10,0,0
4,0,0,7,7,10,0,0,4
4,4,0,0,0,0,0,4,4
endlayer

layer
0,0,0,0,7,0,0,0,0
0,0,10,7,0,10,10,0,0
0,10,0,0,11,0,0,10,0
0,7,0,11,11,11,0,7,0
7,0,11,11,0,11,11,0,7
0,7,0,11,11,11,0,7,0
0,10,0,0,11,0,0,10,0
0,0,10,7,0,7,10,0,0
0,0,0,0,7,0,0,0,0
endlayer

layer
0,0,0,7,7,7,0,0,0
0,10,10,0,0,0,10,10,0
0,10,0,0,12,0,0,10,0
7,0,0,12,12,12,0,0,7
7,0,12,12,0,12,12,0,7
7,0,0,12,12,12,0,0,7
0,10,0,0,12,0,0,10,0
0,10,10,0,0,0,10,10,0
0,0,0,7,7,7,0,0,0
endlayer

layer
0,0,10,7,10,7,10,0,0
0,10,0,0,0,0,0,10,0
10,0,0,0,0,0,0,0,10
7,0,0,0,0,0,0,0,7
10,0,0,0,0,0,0,0,10
7,0,0,0,0,0,0,0,7
10,0,0,0,0,0,0,0,10
0,10,0,0,0,0,0,10,0
0,0,10,7,10,7,10,0,0
endlayer

layer
0,0,0,10,10,10,0,0,0
0,10,10,0,0,0,10,10,0
0,10,0,0,0,0,0,10,0
10,0,0,0,0,0,0,0,10
10,0,0,0,0,0,0,0,10
10,0,0,0,0,0,0,0,10
0,10,0,0,0,0,0,10,0
0,10,10,0,0,0,10,10,0
0,0,0,10,10,10,0,0,0
endlayer

layer
0,0,0,0,10,0,0,0,0
0,0,10,10,0,10,10,0,0
0,10,0,0,0,0,0,10,0
0,10,0,0,0,0,0,10,0
10,0,0,0,0,0,0,0,10
0,10,0,0,0,0,0,10,0
0,10,0,0,0,0,0,10,0
0,0,10,10,0,10,10,0,0
0,0,0,0,10,0,0,0,0
endlayer

layer
0,0,0,0,0,0,0,0,0
0,0,0,10,10,10,0,0,0
0,0,10,10,0,10,10,0,0
0,10,10,0,0,0,10,10,0
0,10,0,0,0,0,0,10,0
0,10,10,0,0,0,10,10,0
0,0,10,10,0,10,10,0,0
0,0,0,10,10,10,0,0,0
0,0,0,0,0,0,0,0,0
endlayer

layer
0,0,0,0,0,0,0,0,0
0,0,0,0,0,0,0,0,0
0,0,0,10,10,10,0,0,0
0,0,10,0,0,0,10,0,0
0,0,10,0,0,0,10,0,0
0,0,10,0,0,0,10,0,0
0,0,0,10,10,10,0,0,0
0,0,0,0,0,0,0,0,0
0,0,0,0,0,0,0,0,0
endlayer

layer
0,0,0,0,0,0,0,0,0
0,0,0,0,0,0,0,0,0
0,0,0,0,0,0,0,0,0
0,0,0,10,10,10,0,0,0
0,0,0,10,10,10,0,0,0
0,0,0,10,10,10,0,0,0
0,0,0,0,0,0,0,0,0
0,0,0,0,0,0,0,0,0
0,0,0,0,0,0,0,0,0
endlayer

layer
0,0,0,0,0,0,0,0,0
0,0,0,0,0,0,0,0,0
0,0,0,0,0,0,0,0,0
0,0,0,0,0,0,0,0,0
0,0,0,0,10,0,0,0,0
0,0,0,0,0,0,0,0,0
0,0,0,0,0,0,0,0,0
0,0,0,0,0,0,0,0,0
0,0,0,0,0,0,0,0,0
endlayer

