
# Created by Ruins mod version 16.5 Ingame Parser
# authoring Player: ST753M

weight=1
embed_into_distance=3
acceptable_target_blocks=grass,dirt,podzol,biomesoplenty:grass,biomesoplenty:dirt
unacceptable_target_blocks=flowing_water,water,flowing_lava,lava
dimensions=36,13,17
allowable_overhang=5
max_leveling=0
leveling_buffer=0
preserve_water=0
preserve_lava=0
preserve_plants=1

adjoining_template=mutated_plains/753_GlassRose_4;20;99;20;100
adjoining_template=mutated_plains/753_GlassRose_4;20;99;-20;100
adjoining_template=mutated_plains/753_GlassRose_4;-20;99;20;100
adjoining_template=mutated_plains/753_GlassRose_4;-20;99;-20;100

biomesToSpawnIn=mutated_plains,flower_island,mystic_grove

rule1=0,100,preserveBlock
rule2=0,100,minecraft:stained_hardened_clay-13
rule3=0,100,minecraft:vine-8
rule4=0,100,minecraft:stained_hardened_clay-5
rule5=0,100,minecraft:stained_hardened_clay-6
^0,100,minecraft:stained_hardened_clay-6
^0,100,minecraft:stained_hardened_clay-6
^0,100,minecraft:stained_hardened_clay-6
^0,100,minecraft:stained_hardened_clay-2
^0,100,minecraft:stained_hardened_clay-2
rule6=0,100,minecraft:stained_glass-6
^0,100,minecraft:stained_glass-6
^0,100,minecraft:stained_glass-6
^0,100,minecraft:stained_glass-6
^0,100,minecraft:stained_glass-0
^0,100,minecraft:stained_glass-4
^0,100,minecraft:stained_glass-14
^0,100,minecraft:stained_glass-10
^0,100,minecraft:stained_glass-2
^0,100,minecraft:stained_glass-2
^0,100,minecraft:stained_glass-2
rule7=0,100,minecraft:grass-0
rule8=0,100,minecraft:double_plant-1
rule9=0,100,minecraft:birch_fence-0
rule10=0,50,ChestGenHook:chests/jungle_temple:4-5
rule11=0,10,ChestGenHook:chests/jungle_temple:5-4
rule12=0,100,minecraft:double_plant-10

layer
1,1,1,1,1,1,1,1,1,1,1,1,1,1,1,1,1
1,1,1,1,1,1,1,1,1,1,1,1,1,1,1,1,1
1,1,1,1,1,1,1,1,1,1,1,1,1,1,1,1,1
1,1,1,1,1,1,1,1,1,1,1,1,1,1,1,1,1
1,1,1,1,2,2,2,2,2,1,1,1,1,1,1,1,1
1,1,1,1,2,2,2,2,1,1,1,1,1,1,1,1,1
1,1,1,1,2,2,2,1,1,1,1,1,1,1,1,1,1
1,1,1,1,2,2,1,1,1,1,1,1,1,1,1,1,1
1,1,1,1,1,1,1,1,1,2,2,2,1,1,1,1,1
1,1,1,1,1,1,1,1,1,1,1,2,2,1,1,1,1
1,1,1,1,1,1,2,2,1,1,1,1,1,1,1,1,1
1,1,1,1,1,1,2,1,1,1,1,1,1,1,1,1,1
1,1,1,1,1,2,2,1,1,1,1,1,1,1,1,1,1
endlayer

layer
1,1,1,1,1,1,1,1,1,1,1,1,1,1,1,1,1
1,1,1,1,1,1,1,1,1,1,1,1,1,1,1,1,1
1,1,1,1,1,1,1,1,1,1,1,1,1,1,1,1,1
1,1,1,1,1,1,1,1,1,1,1,1,1,1,1,1,1
1,1,1,1,2,2,2,0,0,1,1,1,1,1,1,1,1
1,1,1,1,2,2,2,2,1,1,1,1,1,1,1,1,1
1,1,1,1,2,2,2,1,1,1,1,1,1,1,1,1,1
1,1,1,1,2,2,2,1,1,1,1,1,1,1,1,1,1
1,1,1,1,1,1,2,2,2,2,1,1,1,1,1,1,1
1,1,1,1,1,1,1,2,1,1,1,1,1,1,1,1,1
1,1,1,1,1,1,1,2,1,1,1,1,1,1,1,1,1
1,1,1,1,1,1,1,1,1,1,1,1,1,1,1,1,1
1,1,1,1,1,1,1,1,1,1,1,1,1,1,1,1,1
endlayer

layer
1,1,1,1,1,1,1,1,1,1,1,1,1,1,1,1,1
1,1,1,1,1,1,1,1,1,1,1,1,1,1,1,1,1
1,1,1,1,1,1,1,1,1,1,1,1,1,1,1,1,1
1,1,1,1,1,1,1,1,1,1,1,1,1,1,1,1,1
1,1,1,1,1,1,1,0,0,1,1,1,1,1,1,1,1
1,1,1,1,2,2,2,0,1,1,1,1,1,1,1,1,1
1,1,1,1,2,2,2,1,1,1,1,1,1,1,1,1,1
1,1,1,1,2,2,2,1,1,1,1,1,1,1,1,1,1
1,1,1,1,1,1,1,1,1,1,1,1,1,1,1,1,1
1,1,1,1,1,1,1,1,1,1,1,1,1,1,1,1,1
1,1,1,1,1,1,1,1,1,1,1,1,1,1,1,1,1
1,1,1,1,1,1,1,1,1,1,1,1,1,1,1,1,1
1,1,1,1,1,1,1,1,1,1,1,1,1,1,1,1,1
endlayer

layer
1,1,1,1,1,1,1,1,1,1,1,1,1,1,1,1,1
1,1,1,1,1,1,1,1,1,1,1,1,1,1,1,1,1
1,1,1,1,1,1,1,1,1,1,1,1,1,1,1,1,1
1,1,1,1,1,1,1,1,1,1,1,1,1,1,1,1,1
1,1,1,1,1,0,1,0,0,1,1,1,1,1,1,1,1
1,1,1,1,1,0,1,0,1,1,1,1,1,1,1,1,1
1,1,1,1,2,3,2,1,1,1,1,1,1,1,1,1,1
1,1,4,4,2,3,2,1,1,1,1,1,1,1,1,1,1
1,1,4,4,1,2,1,1,1,1,1,1,1,1,1,1,1
1,1,1,1,1,1,1,1,1,1,1,1,1,1,1,1,1
1,1,1,1,1,1,1,1,1,1,1,1,1,1,1,1,1
1,1,1,1,1,1,1,1,1,1,1,1,1,1,1,1,1
1,1,1,1,1,1,1,1,1,1,1,1,1,1,1,1,1
endlayer

layer
0,0,0,0,0,0,0,0,0,0,0,0,0,0,0,0,0
0,0,0,0,0,0,0,0,0,0,0,0,0,0,0,0,0
0,0,0,0,0,0,0,0,0,0,0,0,0,0,0,0,0
0,0,0,0,0,0,0,0,0,0,0,0,0,0,0,0,0
0,0,0,0,0,0,0,0,0,0,0,0,0,0,0,0,0
0,0,0,0,0,0,0,0,0,0,0,0,0,0,0,0,0
0,0,0,0,2,3,2,0,0,0,0,0,0,0,0,0,0
0,0,0,0,2,3,2,0,0,0,0,0,0,0,0,0,0
0,4,4,0,0,2,0,0,0,0,0,0,0,0,0,0,0
0,4,4,0,0,0,0,0,4,4,0,0,0,0,0,0,0
0,0,0,0,0,0,0,0,4,4,0,0,0,0,0,0,0
0,0,0,0,0,0,0,0,0,0,0,0,0,0,0,0,0
0,0,0,0,0,0,0,0,0,0,0,0,0,0,0,0,0
endlayer

layer
0,0,0,0,0,0,0,0,0,0,0,0,0,0,0,0,0
0,0,0,0,0,0,0,0,0,0,0,0,0,0,0,0,0
0,0,0,0,0,0,0,0,0,0,0,0,0,0,0,0,0
0,0,0,0,0,0,0,0,0,0,0,0,0,0,0,0,0
0,0,0,0,0,0,0,0,0,0,0,0,0,0,0,0,0
0,0,0,0,0,0,0,0,0,0,0,0,0,0,0,0,0
0,0,0,0,0,2,2,0,0,0,0,0,0,0,0,0,0
0,0,0,0,2,3,3,2,0,0,0,0,0,0,0,0,0
0,0,0,0,0,2,2,4,4,0,0,0,0,0,0,0,0
0,0,0,0,0,0,0,4,4,0,0,0,0,0,0,0,0
0,0,0,0,0,0,0,0,0,0,0,0,0,0,0,0,0
0,0,0,0,0,0,0,0,0,0,0,0,0,0,0,0,0
0,0,0,0,0,0,0,0,0,0,0,0,0,0,0,0,0
endlayer

layer
0,0,0,0,0,0,0,0,0,0,0,0,0,0,0,0,0
0,0,0,0,0,0,0,0,0,0,0,0,0,0,0,0,0
0,0,0,0,0,0,0,0,0,0,0,0,0,0,0,0,0
0,0,0,0,0,0,0,0,0,0,0,0,0,0,0,0,0
0,0,0,0,4,4,0,0,0,0,0,0,0,0,0,0,0
0,0,0,0,4,4,0,0,0,0,0,0,0,0,0,0,0
0,0,0,0,0,2,2,0,0,0,0,0,0,0,0,0,0
0,0,0,0,2,3,3,2,0,0,0,0,0,0,0,0,0
0,0,0,0,0,2,2,0,0,0,0,0,0,0,0,0,0
0,0,0,0,0,0,0,0,0,0,0,0,0,0,0,0,0
0,0,0,0,0,0,0,0,0,0,0,0,0,0,0,0,0
0,0,0,0,0,0,0,0,0,0,0,0,0,0,0,0,0
0,0,0,0,0,0,0,0,0,0,0,0,0,0,0,0,0
endlayer

layer
0,0,0,0,0,0,0,0,0,0,0,0,0,0,0,0,0
0,0,0,0,0,0,0,0,0,0,0,0,0,0,0,0,0
0,0,0,0,0,0,0,0,0,0,0,0,0,0,0,0,0
0,0,0,4,4,0,0,0,0,0,0,0,0,0,0,0,0
0,0,0,4,4,0,0,0,0,0,0,0,0,0,0,0,0
0,0,0,0,0,0,0,0,0,0,0,0,0,0,0,0,0
0,0,0,0,0,0,2,2,0,0,0,0,0,0,0,0,0
0,0,0,0,0,2,3,3,2,0,0,0,0,0,0,0,0
0,0,4,4,0,0,2,2,0,0,0,0,0,0,0,0,0
0,0,4,4,0,0,0,0,0,0,0,0,0,0,0,0,0
0,0,0,0,0,0,0,0,0,0,0,0,0,0,0,0,0
0,0,0,0,0,0,0,0,0,0,0,0,0,0,0,0,0
0,0,0,0,0,0,0,0,0,0,0,0,0,0,0,0,0
endlayer

layer
0,0,0,0,0,0,0,0,0,0,0,0,0,0,0,0,0
0,0,0,0,0,0,0,0,0,0,0,0,0,0,0,0,0
0,0,0,0,0,0,0,0,0,0,0,0,0,0,0,0,0
0,0,0,0,0,0,0,0,0,0,0,0,0,0,0,0,0
0,0,0,0,0,0,0,0,0,0,0,0,0,0,0,0,0
0,0,0,0,0,0,0,0,0,0,0,0,0,0,0,0,0
0,0,0,0,0,0,2,2,0,0,0,0,0,0,0,0,0
0,0,0,4,4,2,3,3,2,0,0,0,0,0,0,0,0
0,0,0,4,4,0,2,2,0,0,0,0,0,0,0,0,0
0,0,0,0,0,0,0,0,0,0,0,0,0,0,0,0,0
0,0,0,0,0,0,0,0,0,0,0,0,0,0,0,0,0
0,0,0,0,0,0,0,0,0,0,0,0,0,0,0,0,0
0,0,0,0,0,0,0,0,0,0,0,0,0,0,0,0,0
endlayer

layer
0,0,0,0,0,0,0,0,0,0,0,0,0,0,0,0,0
0,0,0,0,0,0,0,0,0,0,0,0,0,0,0,0,0
0,0,0,0,0,0,0,0,0,0,0,0,0,0,0,0,0
0,0,0,0,0,0,0,0,0,0,0,0,0,0,0,0,0
0,0,0,0,0,0,0,0,0,0,0,0,0,0,0,0,0
0,0,0,0,0,0,0,2,0,4,4,0,0,0,0,0,0
0,0,0,0,0,0,2,3,2,4,4,0,0,0,0,0,0
0,0,0,0,0,0,2,3,2,0,0,0,0,0,0,0,0
0,0,0,0,0,0,0,2,0,0,0,0,0,0,0,0,0
0,0,0,0,0,0,0,0,0,0,0,0,0,0,0,0,0
0,0,0,0,0,0,0,0,0,0,0,0,0,0,0,0,0
0,0,0,0,0,0,0,0,0,0,0,0,0,0,0,0,0
0,0,0,0,0,0,0,0,0,0,0,0,0,0,0,0,0
endlayer

layer
0,0,0,0,0,0,0,0,0,0,0,0,0,0,0,0,0
0,0,0,0,0,0,0,0,0,0,0,0,0,0,0,0,0
0,0,0,0,0,0,0,0,0,0,0,0,0,0,0,0,0
0,0,0,0,0,0,0,0,0,0,0,0,0,0,0,0,0
0,0,0,0,0,0,0,0,0,0,4,4,0,0,0,0,0
0,0,0,0,0,0,0,2,0,0,4,4,0,0,0,0,0
0,0,0,0,0,0,2,3,2,0,0,0,0,0,0,0,0
0,0,0,0,0,0,2,3,2,0,0,0,0,0,0,0,0
0,0,0,0,0,0,2,3,2,0,0,0,0,0,0,0,0
0,0,0,0,0,0,0,2,0,0,0,0,0,0,0,0,0
0,0,0,0,0,0,0,0,0,0,0,0,0,0,0,0,0
0,0,0,0,0,0,0,0,0,0,0,0,0,0,0,0,0
0,0,0,0,0,0,0,0,0,0,0,0,0,0,0,0,0
endlayer

layer
0,0,0,0,0,0,0,0,0,0,0,0,0,0,0,0,0
0,0,0,0,0,0,0,0,0,0,0,0,0,0,0,0,0
0,0,0,0,0,0,0,0,0,0,0,0,0,0,0,0,0
0,0,0,0,0,0,0,0,0,0,0,0,0,0,0,0,0
0,0,0,0,0,0,0,0,0,0,0,0,0,0,0,0,0
0,0,0,0,0,0,0,2,0,0,0,0,0,0,0,0,0
0,0,0,0,0,0,2,3,2,0,0,0,0,0,0,0,0
0,0,0,0,0,0,2,3,2,0,0,0,0,0,0,0,0
0,0,0,0,0,0,2,3,2,0,0,0,0,0,0,0,0
0,0,0,0,0,0,2,3,2,4,4,0,0,0,0,0,0
0,0,0,0,0,0,0,2,0,4,4,0,0,0,0,0,0
0,0,0,0,0,0,0,0,0,0,0,0,0,0,0,0,0
0,0,0,0,4,4,0,0,0,0,0,0,0,0,0,0,0
endlayer

layer
0,0,0,0,0,0,0,0,0,0,0,0,0,0,0,0,0
0,0,0,0,0,0,0,0,0,0,0,0,0,0,0,0,0
0,0,0,0,0,0,4,4,0,0,0,0,0,0,0,0,0
0,0,0,0,0,0,4,4,0,0,0,0,0,0,0,0,0
0,0,0,0,0,0,0,2,0,0,0,0,0,0,0,0,0
0,0,0,0,0,0,2,3,2,2,0,0,0,0,0,0,0
0,0,0,0,0,0,2,3,2,0,0,0,0,0,0,0,0
0,0,0,0,0,0,0,2,0,0,0,0,0,0,0,0,0
0,0,0,0,0,0,2,3,2,0,0,0,0,0,0,0,0
0,0,0,0,0,2,3,3,2,0,0,0,0,0,0,0,0
0,0,0,0,0,0,2,2,0,0,4,4,0,0,0,0,0
0,0,0,0,0,4,4,0,0,0,4,4,0,0,0,0,0
0,0,0,0,0,4,4,0,0,0,0,0,0,0,0,0,0
endlayer

layer
0,0,0,0,0,0,0,0,0,0,0,0,0,0,0,0,0
0,0,0,0,0,4,4,0,0,0,0,0,0,0,0,0,0
0,0,0,0,0,4,4,0,0,0,0,0,0,0,0,0,0
0,0,0,0,0,0,0,0,0,0,0,0,0,0,0,0,0
0,0,0,0,0,0,0,2,2,2,0,0,0,0,0,0,0
0,0,0,0,0,0,2,3,3,3,2,0,0,0,0,0,0
0,0,0,0,0,0,2,3,2,2,0,0,0,0,0,0,0
0,0,0,0,0,0,0,2,0,0,0,0,0,0,0,0,0
0,0,0,0,0,2,2,2,0,0,0,0,0,0,0,0,0
0,0,0,0,2,3,3,3,2,0,0,0,0,0,0,0,0
0,0,0,0,0,2,2,2,0,0,0,0,0,0,0,0,0
0,0,0,0,0,0,0,0,0,0,0,0,0,0,0,0,0
0,0,0,0,0,0,0,0,0,0,0,0,0,0,0,0,0
endlayer

layer
0,0,0,0,0,0,0,0,0,0,0,0,0,0,0,0,0
0,0,0,0,0,0,0,0,0,0,0,0,0,4,4,0,0
0,0,0,0,0,0,0,0,0,0,0,0,0,4,4,0,0
0,0,0,0,0,0,0,0,0,0,0,0,0,0,0,0,0
0,0,0,0,0,0,0,2,2,2,2,0,0,0,0,0,0
0,0,0,0,0,0,2,3,3,3,3,2,2,0,0,0,0
0,0,0,0,0,0,0,2,2,2,2,0,0,0,0,0,0
0,0,0,0,0,0,0,0,0,0,0,0,0,0,0,0,0
0,0,0,0,0,2,2,0,0,0,0,0,0,0,0,0,0
0,0,0,0,2,3,3,2,0,0,0,0,0,0,0,0,0
0,0,0,0,0,2,2,0,0,0,0,0,0,0,0,0,0
0,0,0,0,0,0,0,0,0,0,0,0,0,0,0,0,0
0,0,0,0,0,0,0,0,0,0,0,0,0,0,0,0,0
endlayer

layer
0,0,0,0,0,0,0,0,0,0,0,0,0,0,0,0,0
0,0,0,0,0,0,0,0,0,0,0,0,0,0,0,0,0
0,0,0,0,0,0,0,0,0,0,0,0,4,4,0,0,0
0,0,0,0,0,0,0,0,0,0,0,0,4,4,0,0,0
0,0,0,0,0,0,0,2,0,2,2,2,2,0,0,0,0
0,0,0,0,0,0,2,3,2,3,3,3,3,2,0,0,0
0,0,0,0,0,0,0,2,0,2,2,2,2,0,0,0,0
0,0,0,0,0,0,0,0,0,0,0,0,0,0,0,0,0
0,0,0,0,0,2,0,0,0,0,0,0,0,0,0,0,0
0,0,0,0,2,3,2,0,0,0,0,0,0,0,0,0,0
0,0,0,0,0,2,0,0,0,0,0,0,0,0,0,0,0
0,0,0,0,0,0,0,0,0,0,0,0,0,0,0,0,0
0,0,0,0,0,0,0,0,0,0,0,0,0,0,0,0,0
endlayer

layer
0,0,0,0,0,0,0,0,0,0,0,0,0,0,0,0,0
0,0,0,0,0,0,0,0,0,0,0,0,0,0,0,0,0
0,0,0,0,0,0,0,0,0,0,0,0,0,0,0,0,0
0,0,0,0,0,0,0,0,0,0,0,0,0,0,0,0,0
0,0,0,0,0,0,0,2,0,0,2,2,2,0,0,0,0
0,0,0,0,0,0,2,3,2,2,3,3,3,2,4,4,0
0,0,0,0,0,0,0,2,0,0,2,2,2,0,4,4,0
0,0,0,4,0,4,0,4,0,0,0,0,0,0,0,0,0
0,0,0,0,4,2,4,0,0,0,0,0,0,0,0,0,0
0,0,0,4,2,3,2,4,4,0,0,0,0,0,0,0,0
0,0,0,0,4,2,4,0,0,0,0,0,0,0,0,0,0
0,0,0,4,0,4,0,4,0,0,0,0,0,0,0,0,0
0,0,0,0,0,0,0,0,0,0,0,0,0,0,0,0,0
endlayer

layer
0,0,0,0,0,0,0,0,0,0,0,0,0,0,0,0,0
0,0,0,0,0,0,0,0,0,0,0,0,0,0,0,0,0
0,0,0,0,0,0,0,0,0,0,0,0,0,0,0,0,0
0,0,0,0,0,0,0,0,0,0,0,0,0,0,0,0,0
0,0,0,0,0,0,2,2,0,0,0,0,2,0,0,0,0
0,0,0,0,0,2,3,3,2,0,2,2,3,2,0,0,0
0,0,0,0,0,4,2,2,0,0,0,0,2,0,0,4,4
0,0,0,0,0,5,0,0,0,0,0,0,0,0,0,4,4
0,0,0,0,5,5,5,0,0,0,0,0,0,0,0,0,0
0,4,4,5,5,3,5,5,0,4,0,0,0,0,0,0,0
0,0,0,0,5,5,5,0,0,0,0,0,0,0,0,0,0
0,0,0,0,0,5,0,0,0,0,0,0,0,0,0,0,0
0,0,0,0,0,4,0,0,0,0,0,0,0,0,0,0,0
endlayer

layer
0,0,0,0,0,0,0,0,0,0,0,0,0,0,0,0,0
0,0,0,0,0,0,0,0,0,0,0,0,0,0,0,0,0
0,0,0,0,0,0,0,0,0,0,0,0,0,0,0,0,0
0,0,0,0,4,4,0,0,0,0,0,0,0,0,0,0,0
0,0,0,0,4,4,2,2,0,0,0,0,2,0,0,0,0
0,0,0,0,0,2,3,3,2,0,0,2,3,2,0,0,0
0,0,0,0,0,0,2,2,0,0,0,0,2,0,0,0,0
0,0,0,0,6,5,5,0,0,0,0,0,0,0,0,0,0
0,0,0,5,0,0,0,6,0,0,0,0,0,0,0,0,0
0,0,0,5,0,0,0,5,0,0,0,0,0,0,0,0,0
0,0,0,6,0,0,0,5,0,0,0,0,0,0,0,0,0
0,0,0,0,5,5,6,0,0,0,0,0,0,0,0,0,0
0,0,0,0,0,0,0,0,0,0,0,0,0,0,0,0,0
endlayer

layer
0,0,0,0,0,0,0,0,0,0,0,0,0,0,0,0,0
0,0,0,0,0,0,0,0,0,0,0,0,0,0,0,0,0
0,0,0,4,4,0,0,0,0,0,0,0,0,0,0,0,0
0,0,0,4,4,0,0,0,0,0,0,0,0,0,0,0,0
0,0,0,0,0,0,2,0,0,0,0,0,2,0,0,0,0
0,0,0,0,0,2,3,2,0,0,0,2,3,2,0,0,0
0,0,0,0,0,0,2,0,0,0,0,0,2,0,0,0,0
0,0,0,0,6,5,6,0,0,0,0,0,0,0,0,0,0
0,0,0,6,0,0,0,6,0,0,0,0,0,0,0,0,0
0,0,0,5,0,0,0,5,0,0,0,0,0,0,0,0,0
0,0,0,6,0,0,0,6,0,0,0,0,0,0,0,0,0
0,0,0,0,6,5,6,0,0,0,0,0,0,0,0,0,0
0,0,0,0,0,0,0,0,0,0,0,0,0,0,0,0,0
endlayer

layer
0,0,0,0,0,0,0,0,0,0,0,0,0,0,0,0,0
0,0,0,0,0,0,0,0,0,0,0,0,0,0,0,0,0
0,0,0,0,0,0,0,0,0,0,0,0,4,0,0,0,0
0,0,0,0,0,0,0,0,0,0,4,0,4,0,4,0,0
0,0,0,0,0,0,2,0,0,0,0,4,2,4,0,0,0
0,0,0,0,0,2,3,2,0,4,4,2,3,2,4,4,0
0,0,0,0,0,0,2,0,0,0,0,4,2,4,0,0,0
0,0,0,0,6,6,6,0,0,0,4,0,4,0,4,0,0
0,0,0,6,0,0,0,6,0,0,0,0,4,0,0,0,0
0,0,0,6,0,0,0,6,0,0,0,0,0,0,0,0,0
0,0,0,6,0,0,0,6,0,0,0,0,0,0,0,0,0
0,0,0,0,6,6,6,0,0,0,0,0,0,0,0,0,0
0,0,0,0,0,0,0,0,0,0,0,0,0,0,0,0,0
endlayer

layer
0,0,0,0,0,0,0,0,0,0,0,0,0,0,0,0,0
0,0,0,0,0,0,0,0,0,0,0,0,4,0,0,0,0
0,0,0,0,0,0,0,0,0,0,0,0,0,0,0,0,0
0,0,0,0,0,0,0,0,0,0,0,0,5,0,0,0,0
0,0,0,0,0,2,2,0,0,0,0,5,5,5,0,0,0
0,0,0,0,2,3,3,2,4,0,5,5,3,5,5,0,4
0,0,0,0,0,2,2,0,0,0,0,5,5,5,0,0,0
0,0,0,0,0,0,0,0,0,0,0,0,5,0,0,0,0
0,0,0,0,6,6,6,0,0,0,0,0,0,0,0,0,0
0,0,0,0,6,0,6,0,0,0,0,0,4,0,0,0,0
0,0,0,0,6,6,6,0,0,0,0,0,0,0,0,0,0
0,0,0,0,0,0,0,0,0,0,0,0,0,0,0,0,0
0,0,0,0,0,0,0,0,0,0,0,0,0,0,0,0,0
endlayer

layer
0,0,0,0,0,0,0,0,0,0,0,0,0,0,0,0,0
0,0,0,0,0,0,0,0,0,0,0,0,0,0,0,0,0
0,0,0,0,0,0,0,0,0,0,0,0,0,0,0,0,0
0,0,0,0,0,0,0,0,0,0,0,5,5,6,0,0,0
0,0,0,0,0,2,2,0,0,0,6,0,0,0,5,0,0
0,0,0,0,2,3,3,2,0,0,5,0,0,0,5,0,0
0,0,0,0,0,2,2,0,0,0,5,0,0,0,6,0,0
0,0,0,0,0,0,0,0,0,0,0,6,5,5,0,0,0
0,0,0,0,0,6,0,0,0,0,0,0,0,0,0,0,0
0,0,0,0,6,0,6,0,0,0,0,0,0,0,0,0,0
0,0,0,0,0,6,0,0,0,0,0,0,0,0,0,0,0
0,0,0,0,0,0,0,0,0,0,0,0,0,0,0,0,0
0,0,0,0,0,0,0,0,0,0,0,0,0,0,0,0,0
endlayer

layer
0,0,0,0,0,0,0,0,0,0,0,0,0,0,0,0,0
0,0,0,0,0,0,0,0,0,0,0,0,0,0,0,0,0
0,0,0,0,0,0,0,0,0,0,0,0,0,0,0,0,0
0,0,0,0,0,0,0,0,0,0,0,6,5,6,0,0,0
0,0,0,0,0,2,0,0,0,0,6,0,0,0,6,0,0
0,0,0,0,2,3,2,0,0,0,5,0,0,0,5,0,0
0,0,0,0,0,2,0,0,0,0,6,0,0,0,6,0,0
0,0,0,0,0,0,0,0,0,0,0,6,5,6,0,0,0
0,0,0,0,0,0,0,0,0,0,0,0,0,0,0,0,0
0,0,0,0,0,0,0,0,0,0,0,0,0,0,0,0,0
0,0,0,0,0,0,0,0,0,0,0,0,0,0,0,0,0
0,0,0,0,0,0,0,0,0,0,0,0,0,0,0,0,0
0,0,0,0,0,0,0,0,0,0,0,0,0,0,0,0,0
endlayer

layer
0,0,0,0,0,0,0,0,0,0,0,0,0,0,0,0,0
0,0,0,0,0,4,0,0,0,0,0,0,0,0,0,0,0
0,0,0,5,0,4,0,5,0,0,0,0,0,0,0,0,0
0,0,5,0,0,0,0,0,5,0,0,6,6,6,0,0,0
0,0,0,0,0,2,0,0,0,0,6,0,0,0,6,0,0
0,4,4,0,2,3,2,0,4,0,6,0,0,0,6,0,0
0,0,0,0,0,2,0,0,0,0,6,0,0,0,6,0,0
0,0,5,0,0,0,0,0,5,0,0,6,6,6,0,0,0
0,0,0,5,0,4,0,5,0,0,0,0,0,0,0,0,0
0,0,0,0,0,4,0,0,0,0,0,0,0,0,0,0,0
0,0,0,0,0,0,0,0,0,0,0,0,0,0,0,0,0
0,0,0,0,0,0,0,0,0,0,0,0,0,0,0,0,0
0,0,0,0,0,0,0,0,0,0,0,0,0,0,0,0,0
endlayer

layer
0,0,0,0,0,0,0,0,0,0,0,0,0,0,0,0,0
0,0,0,0,0,0,0,0,0,0,0,0,0,0,0,0,0
0,0,0,0,0,4,0,0,0,0,0,0,0,0,0,0,0
0,0,0,5,0,4,0,5,0,0,0,0,0,0,0,0,0
0,0,0,0,4,2,4,0,0,0,0,6,6,6,0,0,0
0,0,4,4,2,3,2,4,0,0,0,6,0,6,0,0,0
0,0,0,0,4,2,4,0,0,0,0,6,6,6,0,0,0
0,0,0,5,0,4,0,5,0,0,0,0,0,0,0,0,0
0,0,0,0,0,4,0,0,0,0,0,0,0,0,0,0,0
0,0,0,0,0,0,0,0,0,0,0,0,0,0,0,0,0
0,0,0,0,0,0,0,0,0,0,0,0,0,0,0,0,0
0,0,0,0,0,0,0,0,0,0,0,0,0,0,0,0,0
0,0,0,0,0,0,0,0,0,0,0,0,0,0,0,0,0
endlayer

layer
0,0,0,0,0,0,0,0,0,0,0,0,0,0,0,0,0
0,0,0,0,0,0,0,0,0,0,0,0,0,0,0,0,0
0,0,0,0,5,5,5,0,0,0,0,0,0,0,0,0,0
0,0,0,0,5,5,5,0,0,0,0,0,0,0,0,0,0
0,0,5,5,5,5,5,5,5,0,0,0,6,0,0,0,0
0,0,5,5,5,3,5,5,5,0,0,6,0,6,0,0,0
0,0,5,5,5,5,5,5,5,0,0,0,6,0,0,0,0
0,0,0,0,5,5,5,0,0,0,0,0,0,0,0,0,0
0,0,0,0,5,5,5,0,0,0,0,0,0,0,0,0,0
0,0,0,0,0,0,0,0,0,0,0,0,0,0,0,0,0
0,0,0,0,0,0,0,0,0,0,0,0,0,0,0,0,0
0,0,0,0,0,0,0,0,0,0,0,0,0,0,0,0,0
0,0,0,0,0,0,0,0,0,0,0,0,0,0,0,0,0
endlayer

layer
0,0,0,0,0,0,0,0,0,0,0,0,0,0,0,0,0
0,0,0,0,5,5,0,0,0,0,0,0,0,0,0,0,0
0,0,0,5,7,5,6,0,0,0,0,0,0,0,0,0,0
0,0,0,5,7,7,7,5,5,0,0,0,0,0,0,0,0
0,0,6,7,7,7,7,7,7,5,0,0,0,0,0,0,0
0,5,5,7,7,3,7,7,5,5,0,0,0,0,0,0,0
0,5,7,7,7,7,7,7,6,0,0,0,0,0,0,0,0
0,0,5,5,7,7,7,5,0,0,0,0,0,0,0,0,0
0,0,0,0,6,5,7,5,0,0,0,0,0,0,0,0,0
0,0,0,0,0,5,5,0,0,0,0,0,0,0,0,0,0
0,0,0,0,0,0,0,0,0,0,0,0,0,0,0,0,0
0,0,0,0,0,0,0,0,0,0,0,0,0,0,0,0,0
0,0,0,0,0,0,0,0,0,0,0,0,0,0,0,0,0
endlayer

layer
0,0,0,0,5,5,0,0,0,0,0,0,0,0,0,0,0
0,0,0,6,0,0,6,0,0,0,0,0,0,0,0,0,0
0,0,5,5,8,0,0,5,5,0,0,0,0,0,0,0,0
0,0,5,10,8,9,8,0,5,6,0,0,0,0,0,0,0
0,6,0,8,8,8,8,8,8,0,5,0,0,0,0,0,0
5,0,0,9,8,0,8,9,0,0,5,0,0,0,0,0,0
5,0,8,8,8,8,8,8,0,6,0,0,0,0,0,0,0
0,6,5,0,8,9,8,11,5,0,0,0,0,0,0,0,0
0,0,5,5,0,0,8,5,5,0,0,0,0,0,0,0,0
0,0,0,0,6,0,0,6,0,0,0,0,0,0,0,0,0
0,0,0,0,0,5,5,0,0,0,0,0,0,0,0,0,0
0,0,0,0,0,0,0,0,0,0,0,0,0,0,0,0,0
0,0,0,0,0,0,0,0,0,0,0,0,0,0,0,0,0
endlayer

layer
0,0,0,0,6,6,0,0,0,0,0,0,0,0,0,0,0
0,0,5,6,0,0,6,6,5,0,0,0,0,0,0,0,0
0,5,5,0,12,0,0,0,5,5,0,0,0,0,0,0,0
0,6,0,0,12,9,12,0,0,6,0,0,0,0,0,0,0
0,6,0,12,12,12,12,12,12,0,6,0,0,0,0,0,0
6,0,0,9,12,0,12,9,0,0,6,0,0,0,0,0,0
6,0,12,12,12,12,12,12,0,6,0,0,0,0,0,0,0
0,6,0,0,12,9,12,0,0,6,0,0,0,0,0,0,0
0,5,5,0,0,0,12,0,5,5,0,0,0,0,0,0,0
0,0,5,6,6,0,0,6,5,0,0,0,0,0,0,0,0
0,0,0,0,0,6,6,0,0,0,0,0,0,0,0,0,0
0,0,0,0,0,0,0,0,0,0,0,0,0,0,0,0,0
0,0,0,0,0,0,0,0,0,0,0,0,0,0,0,0,0
endlayer

layer
0,0,0,0,6,6,0,0,0,0,0,0,0,0,0,0,0
0,0,0,6,0,0,6,6,0,0,0,0,0,0,0,0,0
0,0,6,0,0,0,0,0,6,0,0,0,0,0,0,0,0
0,6,0,0,0,0,0,0,0,6,0,0,0,0,0,0,0
6,0,0,0,0,0,0,0,0,0,6,0,0,0,0,0,0
6,0,0,0,0,0,0,0,0,0,6,0,0,0,0,0,0
6,0,0,0,0,0,0,0,0,0,6,0,0,0,0,0,0
0,6,0,0,0,0,0,0,0,6,0,0,0,0,0,0,0
0,0,6,0,0,0,0,0,6,0,0,0,0,0,0,0,0
0,0,0,6,0,0,0,6,0,0,0,0,0,0,0,0,0
0,0,0,0,6,6,6,0,0,0,0,0,0,0,0,0,0
0,0,0,0,0,0,0,0,0,0,0,0,0,0,0,0,0
0,0,0,0,0,0,0,0,0,0,0,0,0,0,0,0,0
endlayer

layer
0,0,0,0,0,0,0,0,0,0,0,0,0,0,0,0,0
0,0,0,0,6,6,6,0,0,0,0,0,0,0,0,0,0
0,0,0,6,0,0,0,6,0,0,0,0,0,0,0,0,0
0,0,6,0,0,0,0,0,6,0,0,0,0,0,0,0,0
0,6,0,0,0,0,0,0,0,6,0,0,0,0,0,0,0
0,6,0,0,0,0,0,0,0,6,0,0,0,0,0,0,0
0,6,0,0,0,0,0,0,0,6,0,0,0,0,0,0,0
0,0,6,0,0,0,0,0,6,0,0,0,0,0,0,0,0
0,0,0,6,0,0,0,6,0,0,0,0,0,0,0,0,0
0,0,0,0,6,6,6,0,0,0,0,0,0,0,0,0,0
0,0,0,0,0,0,0,0,0,0,0,0,0,0,0,0,0
0,0,0,0,0,0,0,0,0,0,0,0,0,0,0,0,0
0,0,0,0,0,0,0,0,0,0,0,0,0,0,0,0,0
endlayer

layer
0,0,0,0,0,0,0,0,0,0,0,0,0,0,0,0,0
0,0,0,0,0,0,0,0,0,0,0,0,0,0,0,0,0
0,0,0,6,6,6,6,6,0,0,0,0,0,0,0,0,0
0,0,6,0,0,0,0,0,6,0,0,0,0,0,0,0,0
0,0,6,0,0,0,0,0,6,0,0,0,0,0,0,0,0
0,0,6,0,0,0,0,0,6,0,0,0,0,0,0,0,0
0,0,6,0,0,0,0,0,6,0,0,0,0,0,0,0,0
0,0,6,0,0,0,0,0,6,0,0,0,0,0,0,0,0
0,0,0,6,6,6,6,6,0,0,0,0,0,0,0,0,0
0,0,0,0,0,0,0,0,0,0,0,0,0,0,0,0,0
0,0,0,0,0,0,0,0,0,0,0,0,0,0,0,0,0
0,0,0,0,0,0,0,0,0,0,0,0,0,0,0,0,0
0,0,0,0,0,0,0,0,0,0,0,0,0,0,0,0,0
endlayer

layer
0,0,0,0,0,0,0,0,0,0,0,0,0,0,0,0,0
0,0,0,0,0,0,0,0,0,0,0,0,0,0,0,0,0
0,0,0,0,6,6,6,0,0,0,0,0,0,0,0,0,0
0,0,0,0,0,6,0,0,0,0,0,0,0,0,0,0,0
0,0,6,0,0,0,0,0,6,0,0,0,0,0,0,0,0
0,0,6,6,0,0,0,6,6,0,0,0,0,0,0,0,0
0,0,6,0,0,0,0,0,6,0,0,0,0,0,0,0,0
0,0,0,0,0,6,0,0,0,0,0,0,0,0,0,0,0
0,0,0,0,6,6,6,0,0,0,0,0,0,0,0,0,0
0,0,0,0,0,0,0,0,0,0,0,0,0,0,0,0,0
0,0,0,0,0,0,0,0,0,0,0,0,0,0,0,0,0
0,0,0,0,0,0,0,0,0,0,0,0,0,0,0,0,0
0,0,0,0,0,0,0,0,0,0,0,0,0,0,0,0,0
endlayer

layer
0,0,0,0,0,0,0,0,0,0,0,0,0,0,0,0,0
0,0,0,0,0,0,0,0,0,0,0,0,0,0,0,0,0
0,0,0,0,0,0,0,0,0,0,0,0,0,0,0,0,0
0,0,0,0,0,6,6,0,0,0,0,0,0,0,0,0,0
0,0,0,6,0,0,0,0,0,0,0,0,0,0,0,0,0
0,0,0,6,0,0,0,6,0,0,0,0,0,0,0,0,0
0,0,0,0,0,0,0,6,0,0,0,0,0,0,0,0,0
0,0,0,0,6,6,0,0,0,0,0,0,0,0,0,0,0
0,0,0,0,0,0,0,0,0,0,0,0,0,0,0,0,0
0,0,0,0,0,0,0,0,0,0,0,0,0,0,0,0,0
0,0,0,0,0,0,0,0,0,0,0,0,0,0,0,0,0
0,0,0,0,0,0,0,0,0,0,0,0,0,0,0,0,0
0,0,0,0,0,0,0,0,0,0,0,0,0,0,0,0,0
endlayer

layer
0,0,0,0,0,0,0,0,0,0,0,0,0,0,0,0,0
0,0,0,0,0,0,0,0,0,0,0,0,0,0,0,0,0
0,0,0,0,0,0,0,0,0,0,0,0,0,0,0,0,0
0,0,0,0,0,0,0,0,0,0,0,0,0,0,0,0,0
0,0,0,0,0,6,0,0,0,0,0,0,0,0,0,0,0
0,0,0,0,6,0,6,0,0,0,0,0,0,0,0,0,0
0,0,0,0,0,6,0,0,0,0,0,0,0,0,0,0,0
0,0,0,0,0,0,0,0,0,0,0,0,0,0,0,0,0
0,0,0,0,0,0,0,0,0,0,0,0,0,0,0,0,0
0,0,0,0,0,0,0,0,0,0,0,0,0,0,0,0,0
0,0,0,0,0,0,0,0,0,0,0,0,0,0,0,0,0
0,0,0,0,0,0,0,0,0,0,0,0,0,0,0,0,0
0,0,0,0,0,0,0,0,0,0,0,0,0,0,0,0,0
endlayer

