
# Created by Ruins mod version 16.5 Ingame Parser
# authoring Player: ST753M
# Looks like a vanilla pyramid, but has a different trap and treasure room.

weight=1
uniqueMinDistance=1000
spawnMinDistance=750
embed_into_distance=11
acceptable_target_blocks=sand,sandstone
unacceptable_target_blocks=flowing_water,water,flowing_lava,lava
dimensions=19,21,21
allowable_overhang=11
max_leveling=2
leveling_buffer=0
preserve_water=0
preserve_lava=0

biomesToSpawnIn=desert,desert_hills,oasis,mutated_desert,desert hills,desert m

rule1=0,100,minecraft:sandstone-0
rule2=0,100,minecraft:orange_glazed_terracotta-0
^0,100,minecraft:red_glazed_terracotta-0
^0,100,minecraft:yellow_glazed_terracotta-0
^0,100,minecraft:lime_glazed_terracotta-0
^0,100,minecraft:green_glazed_terracotta-0
^0,100,minecraft:cyan_glazed_terracotta-0
^0,100,minecraft:blue_glazed_terracotta-0
^0,100,minecraft:purple_glazed_terracotta-0
^0,100,minecraft:white_glazed_terracotta-0
^0,100,minecraft:gray_glazed_terracotta-0
^0,100,minecraft:brown_glazed_terracotta-0
rule3^0,100,minecraft:orange_glazed_terracotta-3
^0,100,minecraft:red_glazed_terracotta-3
^0,100,minecraft:yellow_glazed_terracotta-3
^0,100,minecraft:lime_glazed_terracotta-3
^0,100,minecraft:green_glazed_terracotta-3
^0,100,minecraft:cyan_glazed_terracotta-3
^0,100,minecraft:blue_glazed_terracotta-3
^0,100,minecraft:purple_glazed_terracotta-3
^0,100,minecraft:white_glazed_terracotta-3
^0,100,minecraft:gray_glazed_terracotta-3
^0,100,minecraft:brown_glazed_terracotta-3
rule4^0,100,minecraft:orange_glazed_terracotta-1
^0,100,minecraft:red_glazed_terracotta-1
^0,100,minecraft:yellow_glazed_terracotta-1
^0,100,minecraft:lime_glazed_terracotta-1
^0,100,minecraft:green_glazed_terracotta-1
^0,100,minecraft:cyan_glazed_terracotta-1
^0,100,minecraft:blue_glazed_terracotta-1
^0,100,minecraft:purple_glazed_terracotta-1
^0,100,minecraft:white_glazed_terracotta-1
^0,100,minecraft:gray_glazed_terracotta-1
^0,100,minecraft:brown_glazed_terracotta-1
rule5^0,100,minecraft:orange_glazed_terracotta-2
^0,100,minecraft:red_glazed_terracotta-2
^0,100,minecraft:yellow_glazed_terracotta-2
^0,100,minecraft:lime_glazed_terracotta-2
^0,100,minecraft:green_glazed_terracotta-2
^0,100,minecraft:cyan_glazed_terracotta-2
^0,100,minecraft:blue_glazed_terracotta-2
^0,100,minecraft:purple_glazed_terracotta-2
^0,100,minecraft:white_glazed_terracotta-2
^0,100,minecraft:gray_glazed_terracotta-2
^0,100,minecraft:brown_glazed_terracotta-2
rule6=0,100,minecraft:stained_hardened_clay-15
rule7=0,100,minecraft:lava-0
^0,100,minecraft:water-0
rule8=0,100,minecraft:sandstone_stairs-0
rule9=0,100,minecraft:sandstone-2
rule10=0,100,minecraft:sandstone_stairs-2
rule11=0,100,minecraft:sandstone_stairs-3
rule12=0,100,minecraft:sandstone_stairs-1
rule13=0,100,ChestGenHook:chests/desert_pyramid:5-5
rule14=0,100,ChestGenHook:chests/desert_pyramid:5-3
rule15=0,100,ChestGenHook:chests/desert_pyramid:5-2
rule16=0,100,ChestGenHook:chests/desert_pyramid:5-4
rule17=0,100,minecraft:sandstone-1
rule18=0,100,minecraft:sandstone_stairs-5
rule19=0,100,minecraft:sandstone_stairs-7
rule20=0,100,minecraft:sandstone_stairs-6
rule21=0,100,minecraft:sandstone_stairs-4
rule22=0,100,preserveBlock
rule23=0,100,minecraft:stained_hardened_clay-1
rule24=0,100,minecraft:stained_hardened_clay-11
rule25=0,100,minecraft:tripwire_hook-7
rule26=0,100,minecraft:tripwire-4
rule27=0,100,minecraft:tripwire_hook-5
rule28=0,100,IInventory;minecraft:dispenser;minecraft:spawn_egg#{EntityTag:{id:"minecraft:husk"}}#0#4-5
rule29=0,100,IInventory;minecraft:dispenser;minecraft:spawn_egg#{EntityTag:{id:"minecraft:husk"}}#0#4-4

layer
1,1,1,1,1,1,1,1,1,1,1,1,1,1,1,1,1,1,1,1,1
1,1,1,1,1,1,1,1,1,1,1,1,1,1,1,1,1,1,1,1,1
1,1,1,1,1,1,1,1,1,1,1,1,1,1,1,1,1,1,1,1,1
1,1,1,1,1,1,1,1,1,1,1,1,1,1,1,1,1,1,1,1,1
1,1,1,1,1,1,1,1,1,1,1,1,1,1,1,1,1,1,1,1,1
1,1,1,1,1,1,1,1,1,1,1,1,1,1,1,1,1,1,1,1,1
1,1,1,1,1,1,1,1,1,1,1,1,1,1,1,1,1,1,1,1,1
1,1,1,1,1,1,1,1,1,1,1,1,1,1,1,1,1,1,1,1,1
1,1,1,1,1,1,1,1,1,1,1,1,1,1,1,1,1,1,1,1,1
1,1,1,1,1,1,1,1,1,1,1,1,1,1,1,1,1,1,1,1,1
1,1,1,1,1,1,1,1,1,1,1,1,1,1,1,1,1,1,1,1,1
1,1,1,1,1,1,1,1,1,1,1,1,1,1,1,1,1,1,1,1,1
1,1,1,1,1,1,1,1,1,1,1,1,1,1,1,1,1,1,1,1,1
1,1,1,1,1,1,1,1,1,1,1,1,1,1,1,1,1,1,1,1,1
1,1,1,1,1,1,1,1,1,1,1,1,1,1,1,1,1,1,1,1,1
1,1,1,1,1,1,1,1,1,1,1,1,1,1,1,1,1,1,1,1,1
1,1,1,1,1,1,1,1,1,1,1,1,1,1,1,1,1,1,1,1,1
1,1,1,1,1,1,1,1,1,1,1,1,1,1,1,1,1,1,1,1,1
1,1,1,1,1,1,1,1,1,1,1,1,1,1,1,1,1,1,1,1,1
1,1,1,1,1,1,1,1,1,1,1,1,1,1,1,1,1,1,1,1,1
1,1,1,1,1,1,1,1,1,1,1,1,1,1,1,1,1,1,1,1,1
endlayer

layer
1,1,1,1,1,1,1,1,1,1,1,1,1,1,1,1,1,1,1,1,1
1,1,1,1,1,2,3,2,3,2,3,2,3,2,3,2,1,1,1,1,1
1,1,1,4,5,4,5,4,5,4,5,4,5,4,5,4,5,4,1,1,1
1,1,5,2,3,2,3,2,3,2,3,2,3,2,3,2,3,2,3,1,1
1,1,5,4,5,4,5,4,5,4,5,4,5,4,5,4,5,4,5,1,1
1,2,3,2,3,2,3,2,3,2,3,2,3,2,3,2,3,2,3,2,1
1,4,5,4,5,4,5,4,5,6,6,6,5,4,5,4,5,4,5,4,1
1,2,3,2,3,2,3,6,6,6,6,6,6,6,3,2,3,2,3,2,1
1,4,5,4,5,4,5,6,1,1,1,1,1,6,5,4,5,4,5,4,1
1,2,3,2,3,2,6,6,1,7,7,7,1,6,6,2,3,2,3,2,1
1,4,5,4,5,4,6,6,1,7,7,7,1,6,6,4,5,4,5,4,1
1,2,3,2,3,2,6,6,1,7,7,7,1,6,6,2,3,2,3,2,1
1,4,5,4,5,4,5,6,1,1,1,1,1,6,5,4,5,4,5,4,1
1,2,3,2,3,2,3,6,6,6,6,6,6,6,3,2,3,2,3,2,1
1,4,5,4,5,4,5,4,5,6,6,6,5,4,5,4,5,4,5,4,1
1,2,3,2,3,2,3,2,3,2,3,2,3,2,3,2,3,2,3,2,1
1,1,5,4,5,4,5,4,5,4,5,4,5,4,5,4,5,4,5,1,1
1,1,3,2,3,2,3,2,3,2,3,2,3,2,3,2,3,2,3,1,1
1,1,1,4,5,4,5,4,5,4,5,4,5,4,5,4,5,4,1,1,1
1,1,1,1,1,2,3,2,3,2,3,2,3,2,3,2,1,1,1,1,1
1,1,1,1,1,1,1,1,1,1,1,1,1,1,1,1,1,1,1,1,1
endlayer

layer
1,1,1,1,1,1,1,1,1,1,1,1,1,1,1,1,1,1,1,1,1
1,1,1,1,1,1,1,1,1,1,1,1,1,1,1,1,1,1,1,1,1
1,1,7,7,1,1,0,0,0,0,0,0,0,0,0,1,1,7,7,1,1
1,1,7,7,1,0,0,0,0,0,0,0,0,0,0,0,1,7,7,1,1
1,1,1,1,1,0,0,0,0,0,0,0,0,0,0,0,1,1,1,1,1
1,1,1,0,0,0,0,0,0,0,0,0,0,0,0,0,0,0,1,1,1
1,1,0,0,0,0,0,0,0,8,8,8,0,0,0,0,0,0,0,1,1
1,1,0,0,0,0,0,9,1,1,1,1,1,9,0,0,0,0,0,1,1
1,1,0,0,0,0,0,1,1,1,1,1,1,1,0,0,0,0,0,1,1
1,1,0,0,0,0,11,1,1,0,0,0,1,1,10,0,0,0,0,1,1
1,1,0,0,0,0,11,1,1,0,0,0,1,1,10,0,0,0,0,1,1
1,1,0,0,0,0,11,1,1,0,0,0,1,1,10,0,0,0,0,1,1
1,1,0,0,0,0,0,1,1,1,1,1,1,1,0,0,0,0,0,1,1
1,1,0,0,0,0,0,9,1,1,1,1,1,9,0,0,0,0,0,1,1
1,1,0,0,0,0,0,0,0,12,12,12,0,0,0,0,0,0,0,1,1
1,1,1,0,0,0,0,0,0,0,0,0,0,0,0,0,0,0,1,1,1
1,1,1,1,1,0,0,0,0,0,0,0,0,0,0,0,1,1,1,1,1
1,1,7,7,1,0,0,0,0,0,0,0,0,0,0,0,1,7,7,1,1
1,1,7,7,1,1,0,0,0,0,0,0,0,0,0,1,1,7,7,1,1
1,1,1,1,1,1,1,1,1,1,1,1,1,1,1,1,1,1,1,1,1
1,1,1,1,1,1,1,1,1,1,1,1,1,9,1,1,1,1,1,1,1
endlayer

layer
1,1,1,1,1,1,1,9,1,1,1,1,1,9,1,1,1,1,1,1,1
1,1,1,1,1,0,0,9,0,0,13,0,0,9,0,0,1,1,1,1,1
1,1,0,0,0,0,0,0,0,0,0,0,0,0,0,0,0,0,0,1,1
1,1,0,0,0,0,0,0,0,0,0,0,0,0,0,0,0,0,0,1,1
1,1,0,0,0,0,0,0,0,0,0,0,0,0,0,0,0,0,0,1,1
1,0,0,0,0,0,0,0,0,0,0,0,0,0,0,0,0,0,0,0,1
1,0,0,0,0,0,0,0,0,0,0,0,0,0,0,0,0,0,0,0,1
9,9,0,0,0,0,0,9,0,0,0,0,0,9,0,0,0,0,0,9,9
1,0,0,0,0,0,0,0,1,1,0,1,1,0,0,0,0,0,0,0,1
1,0,0,0,0,0,0,0,1,0,0,0,1,0,0,0,0,0,0,0,1
1,15,0,0,0,0,0,0,0,0,0,0,0,0,0,0,0,0,0,14,1
1,0,0,0,0,0,0,0,1,0,0,0,1,0,0,0,0,0,0,0,1
1,0,0,0,0,0,0,0,1,1,0,1,1,0,0,0,0,0,0,0,1
9,9,0,0,0,0,0,9,0,0,0,0,0,9,0,0,0,0,0,9,9
1,0,0,0,0,0,0,0,0,0,0,0,0,0,0,0,0,0,0,0,1
1,0,0,0,0,0,0,0,0,0,0,0,0,0,0,0,0,0,0,0,1
1,1,0,0,0,0,0,0,0,0,0,0,0,0,0,0,0,0,0,1,1
1,1,0,0,0,0,0,0,0,0,0,0,0,0,0,0,0,0,0,1,1
1,1,0,0,0,0,0,0,0,0,0,0,0,0,0,0,0,0,0,1,1
1,1,1,1,1,0,0,9,0,0,16,0,0,9,0,0,1,1,1,1,1
1,1,1,1,1,1,1,9,1,1,1,1,1,9,1,1,1,1,1,1,1
endlayer

layer
1,1,1,1,1,1,1,9,1,1,17,1,1,9,1,1,1,1,1,1,1
1,1,1,1,1,0,0,9,0,0,0,0,0,9,0,0,1,1,1,1,1
1,1,0,0,0,0,0,0,0,0,0,0,0,0,0,0,0,0,0,1,1
1,1,0,0,0,0,0,0,0,0,0,0,0,0,0,0,0,0,0,1,1
1,1,0,0,0,0,0,0,0,0,0,0,0,0,0,0,0,0,0,1,1
1,0,0,0,0,0,0,0,0,0,0,0,0,0,0,0,0,0,0,0,1
1,0,0,0,0,0,0,0,0,0,0,0,0,0,0,0,0,0,0,0,1
9,9,0,0,0,0,0,9,0,0,0,0,0,9,0,0,0,0,0,9,9
1,0,0,0,0,0,0,0,1,1,0,1,1,0,0,0,0,0,0,0,1
1,0,0,0,0,0,0,0,1,0,0,0,1,0,0,0,0,0,0,0,1
17,0,0,0,0,0,0,0,0,0,0,0,0,0,0,0,0,0,0,0,17
1,0,0,0,0,0,0,0,1,0,0,0,1,0,0,0,0,0,0,0,1
1,0,0,0,0,0,0,0,1,1,0,1,1,0,0,0,0,0,0,0,1
9,9,0,0,0,0,0,9,0,0,0,0,0,9,0,0,0,0,0,9,9
1,0,0,0,0,0,0,0,0,0,0,0,0,0,0,0,0,0,0,0,1
1,0,0,0,0,0,0,0,0,0,0,0,0,0,0,0,0,0,0,0,1
1,1,0,0,0,0,0,0,0,0,0,0,0,0,0,0,0,0,0,1,1
1,1,0,0,0,0,0,0,0,0,0,0,0,0,0,0,0,0,0,1,1
1,1,0,0,0,0,0,0,0,0,0,0,0,0,0,0,0,0,0,1,1
1,1,1,1,1,0,0,9,0,0,0,0,0,9,0,0,1,1,1,1,1
1,1,1,1,1,1,1,9,1,1,17,1,1,9,1,1,1,1,1,1,1
endlayer

layer
1,1,1,1,1,1,1,9,1,1,1,1,1,9,1,1,1,1,1,1,1
1,1,1,1,1,0,0,9,0,0,0,0,0,9,0,0,1,1,1,1,1
1,1,0,0,0,0,0,0,0,0,0,0,0,0,0,0,0,0,0,1,1
1,1,0,0,0,0,0,0,0,0,0,0,0,0,0,0,0,0,0,1,1
1,1,0,0,0,0,0,0,0,0,0,0,0,0,0,0,0,0,0,1,1
1,0,0,0,0,0,0,0,0,0,0,0,0,0,0,0,0,0,0,0,1
1,0,0,0,0,0,0,0,0,0,0,0,0,0,0,0,0,0,0,0,1
9,9,0,0,0,0,0,9,0,0,0,0,0,9,0,0,0,0,0,9,9
1,0,0,0,0,0,0,0,1,1,18,1,1,0,0,0,0,0,0,0,1
1,0,0,0,0,0,0,0,1,0,0,0,1,0,0,0,0,0,0,0,1
1,0,0,0,0,0,0,0,20,0,0,0,19,0,0,0,0,0,0,0,1
1,0,0,0,0,0,0,0,1,0,0,0,1,0,0,0,0,0,0,0,1
1,0,0,0,0,0,0,0,1,1,21,1,1,0,0,0,0,0,0,0,1
9,9,0,0,0,0,0,9,0,0,0,0,0,9,0,0,0,0,0,9,9
1,0,0,0,0,0,0,0,0,0,0,0,0,0,0,0,0,0,0,0,1
1,0,0,0,0,0,0,0,0,0,0,0,0,0,0,0,0,0,0,0,1
1,1,0,0,0,0,0,0,0,0,0,0,0,0,0,0,0,0,0,1,1
1,1,0,0,0,0,0,0,0,0,0,0,0,0,0,0,0,0,0,1,1
1,1,0,0,0,0,0,0,0,0,0,0,0,0,0,0,0,0,0,1,1
1,1,1,1,1,0,0,9,0,0,0,0,0,9,0,0,1,1,1,1,1
1,1,1,1,1,1,1,9,1,1,1,1,1,9,1,1,1,1,1,1,1
endlayer

layer
1,1,1,1,1,1,1,1,1,1,1,1,1,1,1,1,1,1,1,1,1
1,1,1,1,1,1,1,1,9,9,9,9,9,1,1,1,1,1,1,1,1
1,1,1,1,1,1,1,1,0,0,0,0,0,1,1,1,1,1,1,1,1
1,1,1,1,1,1,0,0,0,0,0,0,0,0,0,1,1,1,1,1,1
1,1,1,1,1,0,0,0,0,0,0,0,0,0,0,0,1,1,1,1,1
1,1,1,1,0,0,0,0,0,0,0,0,0,0,0,0,0,1,1,1,1
1,1,1,0,0,0,0,0,0,0,0,0,0,0,0,0,0,0,1,1,1
1,1,1,0,0,0,0,9,0,0,0,0,0,9,0,0,0,0,1,1,1
1,9,0,0,0,0,0,0,1,1,1,1,1,0,0,0,0,0,0,9,1
1,9,0,0,0,0,0,0,1,0,0,0,1,0,0,0,0,0,0,9,1
1,9,0,0,0,0,0,0,1,0,0,0,1,0,0,0,0,0,0,9,1
1,9,0,0,0,0,0,0,1,0,0,0,1,0,0,0,0,0,0,9,1
1,9,0,0,0,0,0,0,1,1,1,1,1,0,0,0,0,0,0,9,1
1,1,1,0,0,0,0,9,0,0,0,0,0,9,0,0,0,0,1,1,1
1,1,1,0,0,0,0,0,0,0,0,0,0,0,0,0,0,0,1,1,1
1,1,1,1,0,0,0,0,0,0,0,0,0,0,0,0,0,1,1,1,1
1,1,1,1,1,0,0,0,0,0,0,0,0,0,0,0,1,1,1,1,1
1,1,1,1,1,1,0,0,0,0,0,0,0,0,0,1,1,1,1,1,1
1,1,1,1,1,1,1,1,0,0,0,0,0,1,1,1,1,1,1,1,1
1,1,1,1,1,1,1,1,9,9,9,9,9,1,1,1,1,1,1,1,1
1,1,1,1,1,1,1,1,1,1,1,1,1,1,1,1,1,1,1,1,1
endlayer

layer
1,1,1,1,1,1,1,1,1,1,1,1,1,1,1,1,1,1,1,1,1
1,1,1,1,1,1,1,1,1,1,1,1,1,1,1,1,1,1,1,1,1
1,1,1,1,1,1,1,1,1,1,1,1,1,1,1,1,1,1,1,1,1
1,1,1,1,1,1,1,1,1,1,1,1,1,1,1,1,1,1,1,1,1
1,1,1,1,1,1,1,1,1,1,1,1,1,1,1,1,1,1,1,1,1
1,1,1,1,1,1,1,1,1,1,1,1,1,1,1,1,1,1,1,1,1
1,1,1,1,1,1,1,1,1,1,1,1,1,1,1,1,1,1,1,1,1
1,1,1,1,1,1,1,1,1,1,1,1,1,1,1,1,1,1,1,1,1
1,1,1,1,1,1,1,1,1,1,1,1,1,1,1,1,1,1,1,1,1
1,1,1,1,1,1,1,1,1,0,0,0,1,1,1,1,1,1,1,1,1
1,1,1,1,1,1,1,1,1,0,0,0,1,1,1,1,1,1,1,1,1
1,1,1,1,1,1,1,1,1,0,0,0,1,1,1,1,1,1,1,1,1
1,1,1,1,1,1,1,1,1,1,1,1,1,1,1,1,1,1,1,1,1
1,1,1,1,1,1,1,1,1,1,1,1,1,1,1,1,1,1,1,1,1
1,1,1,1,1,1,1,1,1,1,1,1,1,1,1,1,1,1,1,1,1
1,1,1,1,1,1,1,1,1,1,1,1,1,1,1,1,1,1,1,1,1
1,1,1,1,1,1,1,1,1,1,1,1,1,1,1,1,1,1,1,1,1
1,1,1,1,1,1,1,1,1,1,1,1,1,1,1,1,1,1,1,1,1
1,1,1,1,1,1,1,1,1,1,1,1,1,1,1,1,1,1,1,1,1
1,1,1,1,1,1,1,1,1,1,1,1,1,1,1,1,1,1,1,1,1
1,1,1,1,1,1,1,1,1,1,1,1,1,1,1,1,1,1,1,1,1
endlayer

layer
1,1,1,1,1,1,1,1,1,1,1,1,1,1,1,1,1,1,1,1,1
1,1,1,1,1,1,1,1,1,1,1,1,1,1,1,1,1,1,1,1,1
1,1,1,1,1,1,1,1,1,1,1,1,1,1,1,1,1,1,1,1,1
1,1,1,1,1,1,1,1,1,1,1,1,1,1,1,1,1,1,1,1,1
1,1,1,1,1,1,1,1,1,1,1,1,1,1,1,1,1,1,1,1,1
1,1,1,1,1,1,1,1,1,1,1,1,1,1,1,1,1,1,1,1,1
1,1,1,1,1,1,1,1,1,1,1,1,1,1,1,1,1,1,1,1,1
1,1,1,1,1,1,1,1,1,1,1,1,1,1,1,1,1,1,1,1,1
1,1,1,1,1,1,1,1,1,1,1,1,1,1,1,1,1,1,1,1,1
1,1,1,1,1,1,1,1,1,0,0,0,1,1,1,1,1,1,1,1,1
1,1,1,1,1,1,1,1,1,0,0,0,1,1,1,1,1,1,1,1,1
1,1,1,1,1,1,1,1,1,0,0,0,1,1,1,1,1,1,1,1,1
1,1,1,1,1,1,1,1,1,1,1,1,1,1,1,1,1,1,1,1,1
1,1,1,1,1,1,1,1,1,1,1,1,1,1,1,1,1,1,1,1,1
1,1,1,1,1,1,1,1,1,1,1,1,1,1,1,1,1,1,1,1,1
1,1,1,1,1,1,1,1,1,1,1,1,1,1,1,1,1,1,1,1,1
1,1,1,1,1,1,1,1,1,1,1,1,1,1,1,1,1,1,1,1,1
1,1,1,1,1,1,1,1,1,1,1,1,1,1,1,1,1,1,1,1,1
1,1,1,1,1,1,1,1,1,1,1,1,1,1,1,1,1,1,1,1,1
1,1,1,1,1,1,1,1,1,1,1,1,1,1,1,1,1,1,1,1,1
1,1,1,1,1,1,1,1,1,1,1,1,1,1,1,1,1,1,1,1,1
endlayer

layer
1,1,1,1,1,1,1,1,1,1,1,1,1,1,1,1,1,1,1,1,1
1,1,1,1,1,1,1,1,1,1,1,1,1,1,1,1,1,1,1,1,1
1,1,1,1,1,1,1,1,1,1,1,1,1,1,1,1,1,1,1,1,1
1,1,1,1,1,1,1,1,1,1,1,1,1,1,1,1,1,1,1,1,1
1,1,1,1,1,1,1,1,1,1,1,1,1,1,1,1,1,1,1,1,1
22,1,1,1,1,1,1,1,1,1,1,1,1,1,1,1,1,1,1,1,1
22,1,1,1,1,1,1,1,1,1,1,1,1,1,1,1,1,1,1,1,1
22,1,1,1,1,1,1,1,1,1,23,1,1,1,1,1,1,1,1,1,1
1,1,1,1,1,1,1,1,1,1,23,1,1,1,1,1,1,1,1,1,1
22,1,1,1,1,1,1,1,1,23,1,23,1,1,1,1,1,1,1,1,1
22,1,1,1,1,1,1,23,23,1,24,1,23,23,1,1,1,1,1,1,1
22,1,1,1,1,1,1,1,1,23,1,23,1,1,1,1,1,1,1,1,1
1,1,1,1,1,1,1,1,1,1,23,1,1,1,1,1,1,1,1,1,1
22,1,1,1,1,1,1,1,1,1,23,1,1,1,1,1,1,1,1,1,1
22,1,1,1,1,1,1,1,1,1,1,1,1,1,1,1,1,1,1,1,1
22,1,1,1,1,1,1,1,1,1,1,1,1,1,1,1,1,1,1,1,1
1,1,1,1,1,1,1,1,1,1,1,1,1,1,1,1,1,1,1,1,1
1,1,1,1,1,1,1,1,1,1,1,1,1,1,1,1,1,1,1,1,1
1,1,1,1,1,1,1,1,1,1,1,1,1,1,1,1,1,1,1,1,1
1,1,1,1,1,1,1,1,1,1,1,1,1,1,1,1,1,1,1,1,1
1,1,1,1,1,1,1,1,1,1,1,1,1,1,1,1,1,1,1,1,1
endlayer

layer
1,1,23,1,1,22,22,22,22,22,22,22,22,22,22,22,22,22,22,22,22
1,1,1,0,14,1,1,1,1,1,1,1,1,1,1,1,1,1,1,1,22
23,12,0,0,1,1,1,1,1,1,1,1,1,1,1,1,1,1,1,1,22
1,0,0,0,1,25,0,0,0,0,0,0,0,0,0,0,0,0,1,1,22
1,1,0,1,1,26,9,0,9,0,9,0,9,0,9,0,9,0,1,1,22
22,1,0,1,1,26,0,0,0,0,0,0,0,0,0,0,0,0,1,1,22
22,1,0,1,1,26,0,0,0,0,0,0,0,0,0,0,0,0,1,1,22
22,1,0,1,1,26,0,0,0,0,0,0,0,0,0,0,0,0,1,1,22
1,1,0,1,1,26,0,0,9,0,0,0,9,0,0,0,0,0,1,1,22
0,1,0,0,0,26,0,0,0,0,0,0,0,0,0,0,0,0,1,1,22
0,0,0,0,0,26,0,0,0,0,0,0,0,0,0,0,0,0,1,1,22
0,1,0,0,0,26,0,0,0,0,0,0,0,0,0,0,0,0,1,1,22
1,1,0,1,1,26,0,0,9,0,0,0,9,0,0,0,0,0,1,1,22
22,1,0,1,1,26,0,0,0,0,0,0,0,0,0,0,0,0,1,1,22
22,1,0,1,1,26,0,0,0,0,0,0,0,0,0,0,0,0,1,1,22
22,1,0,1,1,26,0,0,0,0,0,0,0,0,0,0,0,0,1,1,22
1,1,0,1,1,26,9,0,9,0,9,0,9,0,9,0,9,0,1,1,22
1,0,0,0,1,27,0,0,0,0,0,0,0,0,0,0,0,0,1,1,22
23,8,0,0,1,1,1,1,1,1,1,1,1,1,1,1,1,1,1,1,22
1,1,1,0,14,1,1,1,1,1,1,1,1,1,1,1,1,1,1,1,22
1,1,23,1,1,22,22,22,22,22,22,22,22,22,22,22,22,22,22,22,22
endlayer

layer
1,1,23,1,1,22,22,22,22,22,22,22,22,22,22,22,22,22,22,22,22
1,12,1,0,0,1,1,1,1,1,1,1,22,22,22,22,22,22,22,22,22
23,0,0,0,1,28,1,1,1,1,1,1,1,1,1,1,1,1,1,22,22
1,0,0,0,1,0,0,0,0,0,0,0,0,0,0,0,0,0,1,22,22
1,1,0,1,1,0,17,0,17,0,17,0,17,0,17,0,17,0,1,22,22
22,1,0,1,1,0,0,0,0,0,0,0,0,0,0,0,0,0,1,22,22
22,1,0,1,1,0,0,0,0,0,0,0,0,0,0,0,0,0,1,22,22
22,1,0,1,1,0,0,0,0,0,0,0,0,0,0,0,0,0,1,22,22
1,1,0,1,1,0,0,0,9,0,0,0,9,0,0,0,0,0,1,22,22
0,1,0,0,0,0,0,0,0,0,0,0,0,0,0,0,0,0,1,22,22
0,0,0,0,0,0,0,0,0,0,0,0,0,0,0,0,0,0,1,22,22
0,1,0,0,0,0,0,0,0,0,0,0,0,0,0,0,0,0,1,22,22
1,1,0,1,1,0,0,0,9,0,0,0,9,0,0,0,0,0,1,22,22
22,1,0,1,1,0,0,0,0,0,0,0,0,0,0,0,0,0,1,22,22
22,1,0,1,1,0,0,0,0,0,0,0,0,0,0,0,0,0,1,22,22
22,1,0,1,1,0,0,0,0,0,0,0,0,0,0,0,0,0,1,22,22
1,1,0,1,1,0,17,0,17,0,17,0,17,0,17,0,17,0,1,22,22
1,0,0,0,1,0,0,0,0,0,0,0,0,0,0,0,0,0,1,22,22
23,0,0,0,1,29,1,1,1,1,1,1,1,1,1,1,1,1,1,22,22
1,8,1,0,0,1,1,1,1,1,1,1,22,22,22,22,22,22,22,22,22
1,1,23,1,1,22,22,22,22,22,22,22,22,22,22,22,22,22,22,22,22
endlayer

layer
1,23,1,23,1,22,22,22,22,22,22,22,22,22,22,22,22,22,22,22,22
23,0,11,1,1,1,1,1,1,1,1,1,22,22,22,22,22,22,22,22,22
1,0,0,1,1,1,1,1,1,1,1,1,22,22,22,22,22,22,22,22,22
23,0,0,0,1,1,1,1,1,1,1,1,1,1,1,1,1,1,22,22,22
1,1,1,1,1,9,9,9,9,9,9,9,9,9,9,9,9,1,22,22,22
22,1,1,1,1,18,18,18,18,18,18,18,18,18,18,18,18,1,22,22,22
22,1,1,1,1,0,0,0,0,0,0,0,0,0,0,0,0,1,22,22,22
22,1,1,1,1,0,0,0,0,0,0,0,0,0,0,0,0,1,22,22,22
1,1,1,1,1,0,0,0,9,0,0,0,9,0,0,0,0,1,22,22,22
0,1,0,0,0,0,0,0,0,0,0,0,0,0,0,0,0,1,22,22,22
0,1,0,0,0,0,0,0,0,0,0,0,0,0,0,0,0,1,22,22,22
0,1,0,0,0,0,0,0,0,0,0,0,0,0,0,0,0,1,22,22,22
1,1,1,1,1,0,0,0,9,0,0,0,9,0,0,0,0,1,22,22,22
22,1,1,1,1,0,0,0,0,0,0,0,0,0,0,0,0,1,22,22,22
22,1,1,1,1,0,0,0,0,0,0,0,0,0,0,0,0,1,22,22,22
22,1,1,1,1,21,21,21,21,21,21,21,21,21,21,21,21,1,22,22,22
1,1,1,1,1,9,9,9,9,9,9,9,9,9,9,9,9,1,22,22,22
23,0,0,0,1,1,1,1,1,1,1,1,1,1,1,1,1,1,22,22,22
1,0,0,1,1,1,1,1,1,1,1,1,22,22,22,22,22,22,22,22,22
23,0,11,1,1,1,1,1,1,1,1,1,22,22,22,22,22,22,22,22,22
1,23,1,23,1,22,22,22,22,22,22,22,22,22,22,22,22,22,22,22,22
endlayer

layer
1,1,23,1,1,22,22,22,22,22,22,22,22,22,22,22,22,22,22,22,22
1,0,0,11,1,1,1,1,1,1,1,1,22,22,22,22,22,22,22,22,22
23,0,0,1,1,1,1,1,1,1,1,1,22,22,22,22,22,22,22,22,22
1,0,0,0,1,1,1,1,1,1,1,1,22,22,22,22,22,22,22,22,22
1,1,1,1,1,1,1,1,1,1,1,1,1,1,1,1,1,22,22,22,22
22,22,22,22,1,1,1,1,1,1,1,1,1,1,1,1,1,22,22,22,22
22,22,22,22,1,1,1,1,1,1,1,1,1,1,1,1,1,22,22,22,22
22,22,22,22,1,1,1,1,1,1,1,1,1,1,1,1,1,22,22,22,22
9,1,1,1,1,1,1,1,1,1,1,1,1,1,1,1,1,22,22,22,22
9,1,1,1,1,1,1,1,1,0,0,0,1,1,1,1,1,22,22,22,22
9,1,1,1,1,1,1,1,1,0,0,0,1,1,1,1,1,22,22,22,22
9,1,1,1,1,1,1,1,1,0,0,0,1,1,1,1,1,22,22,22,22
9,1,1,1,1,1,1,1,1,1,1,1,1,1,1,1,1,22,22,22,22
22,22,22,22,1,1,1,1,1,1,1,1,1,1,1,1,1,22,22,22,22
22,22,22,22,1,1,1,1,1,1,1,1,1,1,1,1,1,22,22,22,22
22,22,22,22,1,1,1,1,1,1,1,1,1,1,1,1,1,22,22,22,22
1,1,1,1,1,1,1,1,1,1,1,1,1,1,1,1,1,22,22,22,22
1,0,0,0,1,1,1,1,1,1,1,1,22,22,22,22,22,22,22,22,22
23,0,0,1,1,1,1,1,1,1,1,1,22,22,22,22,22,22,22,22,22
1,0,0,11,1,1,1,1,1,1,1,1,22,22,22,22,22,22,22,22,22
1,1,23,1,1,22,22,22,22,22,22,22,22,22,22,22,22,22,22,22,22
endlayer

layer
1,23,1,23,1,22,22,22,22,22,22,22,22,22,22,22,22,22,22,22,22
23,0,0,0,1,22,22,22,22,22,22,22,22,22,22,22,22,22,22,22,22
1,0,0,0,0,22,22,22,22,22,22,22,22,22,22,22,22,22,22,22,22
23,0,0,0,1,22,22,22,22,22,22,22,22,22,22,22,22,22,22,22,22
1,1,1,1,1,22,22,22,22,22,22,22,22,22,22,22,22,22,22,22,22
22,22,22,22,22,1,1,1,1,1,0,1,1,1,1,1,22,22,22,22,22
22,22,22,22,22,1,1,1,1,1,0,1,1,1,1,1,22,22,22,22,22
22,22,22,22,22,1,1,0,0,0,0,0,0,0,1,1,22,22,22,22,22
9,22,22,22,22,1,1,0,0,0,0,0,0,0,1,1,22,22,22,22,22
23,22,22,22,22,1,1,0,0,0,0,0,0,0,1,1,22,22,22,22,22
9,22,22,22,22,1,1,0,0,0,0,0,0,0,1,1,22,22,22,22,22
23,22,22,22,22,1,1,0,0,0,0,0,0,0,1,1,22,22,22,22,22
9,22,22,22,22,1,1,0,0,0,0,0,0,0,1,1,22,22,22,22,22
22,22,22,22,22,1,1,0,0,0,0,0,0,0,1,1,22,22,22,22,22
22,22,22,22,22,1,1,1,1,1,0,1,1,1,1,1,22,22,22,22,22
22,22,22,22,22,1,1,1,1,1,0,1,1,1,1,1,22,22,22,22,22
1,1,1,1,1,22,22,22,22,22,22,22,22,22,22,22,22,22,22,22,22
23,0,0,0,1,22,22,22,22,22,22,22,22,22,22,22,22,22,22,22,22
1,0,0,0,0,22,22,22,22,22,22,22,22,22,22,22,22,22,22,22,22
23,0,0,0,1,22,22,22,22,22,22,22,22,22,22,22,22,22,22,22,22
1,23,1,23,1,22,22,22,22,22,22,22,22,22,22,22,22,22,22,22,22
endlayer

layer
1,23,23,23,1,22,22,22,22,22,22,22,22,22,22,22,22,22,22,22,22
23,0,0,0,1,22,22,22,22,22,22,22,22,22,22,22,22,22,22,22,22
23,0,0,0,0,22,22,22,22,22,22,22,22,22,22,22,22,22,22,22,22
23,0,0,0,1,22,22,22,22,22,22,22,22,22,22,22,22,22,22,22,22
1,1,1,1,1,22,22,22,22,22,22,22,22,22,22,22,22,22,22,22,22
22,22,22,22,22,22,22,22,22,1,0,1,22,22,22,22,22,22,22,22,22
22,22,22,22,22,22,1,1,1,1,0,1,1,1,1,22,22,22,22,22,22
22,22,22,22,22,22,1,0,0,0,0,0,0,0,1,22,22,22,22,22,22
22,22,22,22,22,22,1,0,0,0,0,0,0,0,1,22,22,22,22,22,22
9,22,22,22,22,22,1,0,0,0,0,0,0,0,1,22,22,22,22,22,22
9,22,22,22,22,22,1,0,0,0,0,0,0,0,1,22,22,22,22,22,22
9,22,22,22,22,22,1,0,0,0,0,0,0,0,1,22,22,22,22,22,22
22,22,22,22,22,22,1,0,0,0,0,0,0,0,1,22,22,22,22,22,22
22,22,22,22,22,22,1,0,0,0,0,0,0,0,1,22,22,22,22,22,22
22,22,22,22,22,22,1,1,1,1,0,1,1,1,1,22,22,22,22,22,22
22,22,22,22,22,22,22,22,22,1,0,1,22,22,22,22,22,22,22,22,22
1,1,1,1,1,22,22,22,22,22,22,22,22,22,22,22,22,22,22,22,22
23,0,0,0,1,22,22,22,22,22,22,22,22,22,22,22,22,22,22,22,22
23,0,0,0,0,22,22,22,22,22,22,22,22,22,22,22,22,22,22,22,22
23,0,0,0,1,22,22,22,22,22,22,22,22,22,22,22,22,22,22,22,22
1,23,23,23,1,22,22,22,22,22,22,22,22,22,22,22,22,22,22,22,22
endlayer

layer
1,1,1,1,1,22,22,22,22,22,22,22,22,22,22,22,22,22,22,22,22
1,0,0,0,1,22,22,22,22,22,22,22,22,22,22,22,22,22,22,22,22
1,0,0,0,1,22,22,22,22,22,22,22,22,22,22,22,22,22,22,22,22
1,0,0,0,1,22,22,22,22,22,22,22,22,22,22,22,22,22,22,22,22
1,1,1,1,1,22,22,22,22,22,22,22,22,22,22,22,22,22,22,22,22
22,22,22,22,22,22,22,22,22,1,1,1,22,22,22,22,22,22,22,22,22
22,22,22,22,22,22,22,22,22,1,1,1,22,22,22,22,22,22,22,22,22
22,22,22,22,22,22,22,1,1,1,1,1,1,1,22,22,22,22,22,22,22
22,22,22,22,22,22,22,1,0,0,0,0,0,1,22,22,22,22,22,22,22
22,22,22,22,22,22,22,1,0,0,0,0,0,1,22,22,22,22,22,22,22
22,22,22,22,22,22,22,1,0,0,0,0,0,1,22,22,22,22,22,22,22
22,22,22,22,22,22,22,1,0,0,0,0,0,1,22,22,22,22,22,22,22
22,22,22,22,22,22,22,1,0,0,0,0,0,1,22,22,22,22,22,22,22
22,22,22,22,22,22,22,1,1,1,1,1,1,1,22,22,22,22,22,22,22
22,22,22,22,22,22,22,22,22,1,1,1,22,22,22,22,22,22,22,22,22
22,22,22,22,22,22,22,22,22,1,1,1,22,22,22,22,22,22,22,22,22
1,1,1,1,1,22,22,22,22,22,22,22,22,22,22,22,22,22,22,22,22
1,0,0,0,1,22,22,22,22,22,22,22,22,22,22,22,22,22,22,22,22
1,0,0,0,1,22,22,22,22,22,22,22,22,22,22,22,22,22,22,22,22
1,0,0,0,1,22,22,22,22,22,22,22,22,22,22,22,22,22,22,22,22
1,1,1,1,1,22,22,22,22,22,22,22,22,22,22,22,22,22,22,22,22
endlayer

layer
1,1,1,1,1,22,22,22,22,22,22,22,22,22,22,22,22,22,22,22,22
1,0,0,0,1,22,22,22,22,22,22,22,22,22,22,22,22,22,22,22,22
1,0,0,0,1,22,22,22,22,22,22,22,22,22,22,22,22,22,22,22,22
1,0,0,0,1,22,22,22,22,22,22,22,22,22,22,22,22,22,22,22,22
1,1,1,1,1,22,22,22,22,22,22,22,22,22,22,22,22,22,22,22,22
22,22,22,22,22,22,22,22,22,22,22,22,22,22,22,22,22,22,22,22,22
22,22,22,22,22,22,22,22,22,22,22,22,22,22,22,22,22,22,22,22,22
22,22,22,22,22,22,22,22,22,22,22,22,22,22,22,22,22,22,22,22,22
22,22,22,22,22,22,22,22,1,1,1,1,1,22,22,22,22,22,22,22,22
22,22,22,22,22,22,22,22,1,0,0,0,1,22,22,22,22,22,22,22,22
22,22,22,22,22,22,22,22,1,0,0,0,1,22,22,22,22,22,22,22,22
22,22,22,22,22,22,22,22,1,0,0,0,1,22,22,22,22,22,22,22,22
22,22,22,22,22,22,22,22,1,1,1,1,1,22,22,22,22,22,22,22,22
22,22,22,22,22,22,22,22,22,22,22,22,22,22,22,22,22,22,22,22,22
22,22,22,22,22,22,22,22,22,22,22,22,22,22,22,22,22,22,22,22,22
22,22,22,22,22,22,22,22,22,22,22,22,22,22,22,22,22,22,22,22,22
1,1,1,1,1,22,22,22,22,22,22,22,22,22,22,22,22,22,22,22,22
1,0,0,0,1,22,22,22,22,22,22,22,22,22,22,22,22,22,22,22,22
1,0,0,0,1,22,22,22,22,22,22,22,22,22,22,22,22,22,22,22,22
1,0,0,0,1,22,22,22,22,22,22,22,22,22,22,22,22,22,22,22,22
1,1,1,1,1,22,22,22,22,22,22,22,22,22,22,22,22,22,22,22,22
endlayer

layer
22,22,8,22,22,22,22,22,22,22,22,22,22,22,22,22,22,22,22,22,22
22,1,1,1,22,22,22,22,22,22,22,22,22,22,22,22,22,22,22,22,22
11,1,1,1,10,22,22,22,22,22,22,22,22,22,22,22,22,22,22,22,22
22,1,1,1,22,22,22,22,22,22,22,22,22,22,22,22,22,22,22,22,22
22,22,12,22,22,22,22,22,22,22,22,22,22,22,22,22,22,22,22,22,22
22,22,22,22,22,22,22,22,22,22,22,22,22,22,22,22,22,22,22,22,22
22,22,22,22,22,22,22,22,22,22,22,22,22,22,22,22,22,22,22,22,22
22,22,22,22,22,22,22,22,22,22,22,22,22,22,22,22,22,22,22,22,22
22,22,22,22,22,22,22,22,22,22,22,22,22,22,22,22,22,22,22,22,22
22,22,22,22,22,22,22,22,22,1,1,1,22,22,22,22,22,22,22,22,22
22,22,22,22,22,22,22,22,22,1,0,1,22,22,22,22,22,22,22,22,22
22,22,22,22,22,22,22,22,22,1,1,1,22,22,22,22,22,22,22,22,22
22,22,22,22,22,22,22,22,22,22,22,22,22,22,22,22,22,22,22,22,22
22,22,22,22,22,22,22,22,22,22,22,22,22,22,22,22,22,22,22,22,22
22,22,22,22,22,22,22,22,22,22,22,22,22,22,22,22,22,22,22,22,22
22,22,22,22,22,22,22,22,22,22,22,22,22,22,22,22,22,22,22,22,22
22,22,8,22,22,22,22,22,22,22,22,22,22,22,22,22,22,22,22,22,22
22,1,1,1,22,22,22,22,22,22,22,22,22,22,22,22,22,22,22,22,22
11,1,1,1,10,22,22,22,22,22,22,22,22,22,22,22,22,22,22,22,22
22,1,1,1,22,22,22,22,22,22,22,22,22,22,22,22,22,22,22,22,22
22,22,12,22,22,22,22,22,22,22,22,22,22,22,22,22,22,22,22,22,22
endlayer

