
# Created by Ruins mod version 17.1 Ingame Parser
# authoring Player: ST753M

weight=1
uniqueMinDistance=1000
embed_into_distance=3
acceptable_target_blocks=sand,sandstone
unacceptable_target_blocks=flowing_water,water,flowing_lava,lava
dimensions=13,15,15
allowable_overhang=3
max_leveling=2
leveling_buffer=1
preserve_water=0
preserve_lava=0

biomesToSpawnIn=desert,desert_hills,oasis,mutated_desert,xeric_shrubland,mountainous_desert,dunes,desert_shrubland,arid_highland

=0,100,preserveBlock
rule1=0,100,minecraft:sandstone-0
rule2=0,100,minecraft:orange_glazed_terracotta-2
rule3=0,100,minecraft:stained_hardened_clay-1
rule4=0,100,minecraft:orange_glazed_terracotta-1
rule5=0,100,minecraft:orange_glazed_terracotta-3
rule6=0,100,minecraft:orange_glazed_terracotta-0
rule7=0,100,minecraft:sandstone-1
rule8=0,100,minecraft:sandstone-2
rule9=0,100,minecraft:water-0
rule10=0,100,minecraft:sandstone_stairs-2
rule11=0,100,minecraft:sandstone_stairs-0
rule12=0,100,minecraft:sandstone_stairs-3
rule13=0,100,minecraft:sandstone_stairs-1
rule14=0,100,minecraft:stone_slab-1
rule15=0,100,minecraft:sandstone_stairs-5
rule16=0,100,minecraft:sandstone_stairs-7
rule17=0,100,minecraft:sandstone_stairs-6
rule18=0,100,minecraft:sandstone_stairs-4
rule19=0,100,teBlock;minecraft:wall_banner;{x:-8321,y:106,z:-11459,id:"minecraft:banner",Patterns:[{Pattern:"flo",Color:14},{Pattern:"mc",Color:11}],Base:12}-4
rule20=0,100,teBlock;minecraft:wall_banner;{x:-8314,y:106,z:-11466,id:"minecraft:banner",Patterns:[{Pattern:"flo",Color:14},{Pattern:"mc",Color:11}],Base:12}-2
rule21=0,100,teBlock;minecraft:wall_banner;{x:-8314,y:106,z:-11452,id:"minecraft:banner",Patterns:[{Pattern:"flo",Color:14},{Pattern:"mc",Color:11}],Base:12}-3
rule22=0,100,teBlock;minecraft:wall_banner;{x:-8307,y:106,z:-11459,id:"minecraft:banner",Patterns:[{Pattern:"flo",Color:14},{Pattern:"mc",Color:11}],Base:12}-5
rule23=0,100,minecraft:stone_slab-9

layer
1,1,1,1,1,1,1,1,1,1,1,1,1,1,1
1,1,1,1,1,1,1,1,1,1,1,1,1,1,1
1,1,1,1,1,1,1,1,1,1,1,1,1,1,1
1,1,1,1,1,1,1,1,1,1,1,1,1,1,1
1,1,1,1,1,1,1,1,1,1,1,1,1,1,1
1,1,1,1,1,1,1,1,1,1,1,1,1,1,1
1,1,1,1,1,1,4,3,2,1,1,1,1,1,1
1,1,1,1,1,1,3,3,3,1,1,1,1,1,1
1,1,1,1,1,1,6,3,5,1,1,1,1,1,1
1,1,1,1,1,1,1,1,1,1,1,1,1,1,1
1,1,1,1,1,1,1,1,1,1,1,1,1,1,1
1,1,1,1,1,1,1,1,1,1,1,1,1,1,1
1,1,1,1,1,1,1,1,1,1,1,1,1,1,1
1,1,1,1,1,1,1,1,1,1,1,1,1,1,1
1,1,1,1,1,1,1,1,1,1,1,1,1,1,1
endlayer

layer
7,8,8,8,8,8,8,7,8,8,8,8,8,8,7
8,1,1,1,1,1,1,1,1,1,1,1,1,1,8
8,1,1,1,1,1,1,1,1,1,1,1,1,1,8
8,1,1,1,1,1,1,1,1,1,1,1,1,1,8
8,1,1,1,1,1,1,1,1,1,1,1,1,1,8
8,1,1,1,1,1,1,1,1,1,1,1,1,1,8
8,1,1,1,1,1,9,9,9,1,1,1,1,1,8
7,1,1,1,1,1,9,9,9,1,1,1,1,1,7
8,1,1,1,1,1,9,9,9,1,1,1,1,1,8
8,1,1,1,1,1,1,1,1,1,1,1,1,1,8
8,1,1,1,1,1,1,1,1,1,1,1,1,1,8
8,1,1,1,1,1,1,1,1,1,1,1,1,1,8
8,1,1,1,1,1,1,1,1,1,1,1,1,1,8
8,1,1,1,1,1,1,1,1,1,1,1,1,1,8
7,8,8,8,8,8,8,7,8,8,8,8,8,8,7
endlayer

layer
1,1,1,1,1,1,1,1,1,1,1,1,1,1,1
1,1,1,1,1,1,1,1,1,1,1,1,1,1,1
1,1,1,1,1,1,1,1,1,1,1,1,1,1,1
1,1,1,1,1,1,1,1,1,1,1,1,1,1,1
1,1,1,1,1,1,1,1,1,1,1,1,1,1,1
1,1,1,1,1,1,8,8,8,1,1,1,1,1,1
1,1,1,1,1,8,9,9,9,8,1,1,1,1,1
1,1,1,1,1,8,9,9,9,8,1,1,1,1,1
1,1,1,1,1,8,9,9,9,8,1,1,1,1,1
1,1,1,1,1,1,8,8,8,1,1,1,1,1,1
1,1,1,1,1,1,1,1,1,1,1,1,1,1,1
1,1,1,1,1,1,1,1,1,1,1,1,1,1,1
1,1,1,1,1,1,1,1,1,1,1,1,1,1,1
1,1,1,1,1,1,1,1,1,1,1,1,1,1,1
1,1,1,1,1,1,1,1,1,1,1,1,1,1,1
endlayer

layer
11,11,11,11,11,11,11,11,11,11,11,11,11,11,10
12,1,1,1,1,1,1,1,1,1,1,1,1,1,10
12,1,4,6,4,6,4,6,4,6,4,6,4,1,10
12,1,2,5,2,5,2,5,2,5,2,5,2,1,10
12,1,4,6,4,6,4,6,4,6,4,6,4,1,10
12,1,2,5,2,1,1,1,1,1,2,5,2,1,10
12,1,4,6,4,1,9,9,9,1,4,6,4,1,10
12,1,2,5,2,1,9,9,9,1,2,5,2,1,10
12,1,4,6,4,1,9,9,9,1,4,6,4,1,10
12,1,2,5,2,1,1,1,1,1,2,5,2,1,10
12,1,4,6,4,6,4,6,4,6,4,6,4,1,10
12,1,2,5,2,5,2,5,2,5,2,5,2,1,10
12,1,4,6,4,6,4,6,4,6,4,6,4,1,10
12,1,1,1,1,1,1,1,1,1,1,1,1,1,10
12,13,13,13,13,13,13,13,13,13,13,13,13,13,13
endlayer

layer
0,0,0,0,0,0,0,0,0,0,0,0,0,0,0
0,8,0,0,8,0,0,8,0,0,8,0,0,8,0
0,0,0,0,0,0,0,0,0,0,0,0,0,0,0
0,0,0,0,0,0,0,0,0,0,0,0,0,0,0
0,8,0,0,0,0,0,0,0,0,0,0,0,8,0
0,0,0,0,0,8,11,7,11,8,0,0,0,0,0
0,0,0,0,0,12,9,9,9,10,0,0,0,0,0
0,8,0,0,0,7,9,9,9,7,0,0,0,8,0
0,0,0,0,0,12,9,9,9,10,0,0,0,0,0
0,0,0,0,0,8,13,7,13,8,0,0,0,0,0
0,8,0,0,0,0,0,0,0,0,0,0,0,8,0
0,0,0,0,0,0,0,0,0,0,0,0,0,0,0
0,0,0,0,0,0,0,0,0,0,0,0,0,0,0
0,8,0,0,8,0,0,8,0,0,8,0,0,8,0
0,0,0,0,0,0,0,0,0,0,0,0,0,0,0
endlayer

layer
0,0,0,0,0,0,0,0,0,0,0,0,0,0,0
0,7,0,0,7,0,0,7,0,0,7,0,0,7,0
0,0,0,0,0,0,0,0,0,0,0,0,0,0,0
0,0,0,0,0,0,0,0,0,0,0,0,0,0,0
0,7,0,0,0,0,0,0,0,0,0,0,0,7,0
0,0,0,0,0,7,14,14,14,7,0,0,0,0,0
0,0,0,0,0,14,0,0,0,14,0,0,0,0,0
0,7,0,0,0,14,0,0,0,14,0,0,0,7,0
0,0,0,0,0,14,0,0,0,14,0,0,0,0,0
0,0,0,0,0,7,14,14,14,7,0,0,0,0,0
0,7,0,0,0,0,0,0,0,0,0,0,0,7,0
0,0,0,0,0,0,0,0,0,0,0,0,0,0,0
0,0,0,0,0,0,0,0,0,0,0,0,0,0,0
0,7,0,0,7,0,0,7,0,0,7,0,0,7,0
0,0,0,0,0,0,0,0,0,0,0,0,0,0,0
endlayer

layer
0,0,0,0,0,0,0,0,0,0,0,0,0,0,0
0,8,0,0,8,0,0,8,0,0,8,0,0,8,0
0,0,0,0,0,0,0,0,0,0,0,0,0,0,0
0,0,0,0,0,0,0,0,0,0,0,0,0,0,0
0,8,0,0,0,0,0,0,0,0,0,0,0,8,0
0,0,0,0,0,0,0,0,0,0,0,0,0,0,0
0,0,0,0,0,0,0,0,0,0,0,0,0,0,0
0,8,0,0,0,0,0,0,0,0,0,0,0,8,0
0,0,0,0,0,0,0,0,0,0,0,0,0,0,0
0,0,0,0,0,0,0,0,0,0,0,0,0,0,0
0,8,0,0,0,0,0,0,0,0,0,0,0,8,0
0,0,0,0,0,0,0,0,0,0,0,0,0,0,0
0,0,0,0,0,0,0,0,0,0,0,0,0,0,0
0,8,0,0,8,0,0,8,0,0,8,0,0,8,0
0,0,0,0,0,0,0,0,0,0,0,0,0,0,0
endlayer

layer
11,11,11,11,11,11,11,11,11,11,11,11,11,11,10
12,8,15,15,8,15,15,8,15,15,8,15,15,8,10
12,17,0,0,15,0,0,15,0,0,15,0,0,16,10
12,17,0,0,0,0,0,0,0,0,0,0,0,16,10
12,8,17,0,0,0,0,0,0,0,0,0,16,8,10
12,17,0,0,0,0,0,0,0,0,0,0,0,16,10
12,17,0,0,0,0,0,0,0,0,0,0,0,16,10
12,8,17,0,0,0,0,0,0,0,0,0,16,8,10
12,17,0,0,0,0,0,0,0,0,0,0,0,16,10
12,17,0,0,0,0,0,0,0,0,0,0,0,16,10
12,8,17,0,0,0,0,0,0,0,0,0,16,8,10
12,17,0,0,0,0,0,0,0,0,0,0,0,16,10
12,17,0,0,18,0,0,18,0,0,18,0,0,16,10
12,8,18,18,8,18,18,8,18,18,8,18,18,8,10
12,13,13,13,13,13,13,13,13,13,13,13,13,13,10
endlayer

layer
0,0,0,0,0,0,0,0,0,0,0,0,0,0,0
0,12,11,11,11,12,1,1,1,10,11,11,11,11,0
0,12,17,15,7,15,15,7,15,15,7,15,16,10,0
0,12,17,0,0,0,0,0,0,0,0,0,16,10,0
0,12,7,0,0,0,0,0,0,0,0,0,7,10,0
0,11,17,0,0,0,0,0,0,0,0,0,16,11,0
0,1,17,0,0,0,0,0,0,0,0,0,16,1,0
0,1,7,0,0,0,0,0,0,0,0,0,7,1,0
0,1,17,0,0,0,0,0,0,0,0,0,16,1,0
0,13,17,0,0,0,0,0,0,0,0,0,16,13,0
0,12,7,0,0,0,0,0,0,0,0,0,7,10,0
0,12,17,0,0,0,0,0,0,0,0,0,16,10,0
0,12,18,18,7,18,18,7,18,18,7,18,18,10,0
0,13,13,13,13,12,1,1,1,10,13,13,13,13,0
0,0,0,0,0,0,0,0,0,0,0,0,0,0,0
endlayer

layer
0,0,0,0,0,0,0,19,0,0,0,0,0,0,0
0,0,0,0,0,0,12,1,10,0,0,0,0,0,0
0,0,12,11,11,11,12,1,10,11,11,11,11,0,0
0,0,12,17,15,15,1,15,1,15,15,16,10,0,0
0,0,12,17,0,0,15,0,15,0,0,16,10,0,0
0,0,12,17,0,0,0,0,0,0,0,16,10,0,0
0,11,11,1,17,0,0,0,0,0,16,1,11,11,0
21,1,1,17,0,0,0,0,0,0,0,16,1,1,20
0,13,13,1,17,0,0,0,0,0,16,1,13,13,0
0,0,12,17,0,0,0,0,0,0,0,16,10,0,0
0,0,12,17,0,0,18,0,18,0,0,16,10,0,0
0,0,12,17,18,18,1,18,1,18,18,18,10,0,0
0,0,13,13,13,13,12,1,10,13,13,13,13,0,0
0,0,0,0,0,0,12,1,10,0,0,0,0,0,0
0,0,0,0,0,0,0,22,0,0,0,0,0,0,0
endlayer

layer
0,0,0,0,0,0,0,0,0,0,0,0,0,0,0
0,0,0,0,0,0,0,13,0,0,0,0,0,0,0
0,0,0,0,0,0,0,14,0,0,0,0,0,0,0
0,0,0,14,11,11,14,14,14,11,11,14,0,0,0
0,0,0,12,1,1,1,1,1,1,1,10,0,0,0
0,0,0,12,1,17,15,23,15,15,1,10,0,0,0
0,0,0,14,1,17,0,0,0,16,1,14,0,0,0
0,10,14,14,1,23,0,0,0,23,1,14,14,12,0
0,0,0,14,1,17,0,0,0,16,1,14,0,0,0
0,0,0,12,1,17,18,23,18,18,1,10,0,0,0
0,0,0,12,1,1,1,1,1,1,1,10,0,0,0
0,0,0,14,13,13,14,14,14,13,13,14,0,0,0
0,0,0,0,0,0,0,14,0,0,0,0,0,0,0
0,0,0,0,0,0,0,11,0,0,0,0,0,0,0
0,0,0,0,0,0,0,0,0,0,0,0,0,0,0
endlayer

layer
0,0,0,0,0,0,0,0,0,0,0,0,0,0,0
0,0,0,0,0,0,0,0,0,0,0,0,0,0,0
0,0,0,0,0,0,0,0,0,0,0,0,0,0,0
0,0,0,0,0,0,0,0,0,0,0,0,0,0,0
0,0,0,0,12,11,0,0,0,11,11,0,0,0,0
0,0,0,0,12,1,1,11,1,1,10,0,0,0,0
0,0,0,0,0,1,1,1,1,1,0,0,0,0,0
0,0,0,0,0,12,1,1,1,10,0,0,0,0,0
0,0,0,0,0,1,1,1,1,1,0,0,0,0,0
0,0,0,0,12,1,1,13,1,1,10,0,0,0,0
0,0,0,0,13,13,0,0,0,13,13,0,0,0,0
0,0,0,0,0,0,0,0,0,0,0,0,0,0,0
0,0,0,0,0,0,0,0,0,0,0,0,0,0,0
0,0,0,0,0,0,0,0,0,0,0,0,0,0,0
0,0,0,0,0,0,0,0,0,0,0,0,0,0,0
endlayer

layer
0,0,0,0,0,0,0,0,0,0,0,0,0,0,0
0,0,0,0,0,0,0,0,0,0,0,0,0,0,0
0,0,0,0,0,0,0,0,0,0,0,0,0,0,0
0,0,0,0,0,0,0,0,0,0,0,0,0,0,0
0,0,0,0,0,0,0,0,0,0,0,0,0,0,0
0,0,0,0,0,0,0,0,0,0,0,0,0,0,0
0,0,0,0,0,0,11,11,11,0,0,0,0,0,0
0,0,0,0,0,0,12,1,10,0,0,0,0,0,0
0,0,0,0,0,0,12,13,13,0,0,0,0,0,0
0,0,0,0,0,0,0,0,0,0,0,0,0,0,0
0,0,0,0,0,0,0,0,0,0,0,0,0,0,0
0,0,0,0,0,0,0,0,0,0,0,0,0,0,0
0,0,0,0,0,0,0,0,0,0,0,0,0,0,0
0,0,0,0,0,0,0,0,0,0,0,0,0,0,0
0,0,0,0,0,0,0,0,0,0,0,0,0,0,0
endlayer

