
# Created by Ruins mod version 16.5 Ingame Parser
# authoring Player: ST753M
# Looks like a vanilla pyramid on the outside, but has a maze underneath.

weight=1
uniqueMinDistance=1000
spawnMinDistance=500
embed_into_distance=14
acceptable_target_blocks=sand,sandstone
unacceptable_target_blocks=flowing_water,water,flowing_lava,lava
dimensions=19,21,21
allowable_overhang=14
max_leveling=2
leveling_buffer=0
preserve_water=0
preserve_lava=0

biomesToSpawnIn=desert,desert_hills,oasis,mutated_desert

rule1=0,100,minecraft:sandstone-0
rule2=0,100,minecraft:gold_block-0
rule3=0,100,minecraft:sandstone-2
rule4=0,100,minecraft:lava-0
rule5=0,100,minecraft:sandstone_stairs-2
rule6=0,100,minecraft:double_stone_slab-0
rule7=0,100,minecraft:birch_door-2
rule8=0,100,MobSpawner:Husk
rule9=0,100,minecraft:water-0
rule10=0,100,ChestGenHook:chests/desert_pyramid:5-5
rule11=0,100,minecraft:birch_door-8
rule12=0,100,minecraft:sandstone_stairs-3
rule13=0,100,minecraft:sandstone-1
rule14=0,100,minecraft:stone_slab-9
rule15=0,100,minecraft:sandstone_stairs-5
rule16=0,100,minecraft:sandstone_stairs-7
rule17=0,100,minecraft:sandstone_stairs-6
rule18=0,100,minecraft:sandstone_stairs-4
rule19=0,100,minecraft:glowstone-0
rule20=0,100,preserveBlock
rule21=0,100,minecraft:stained_hardened_clay-1
rule22=0,100,minecraft:stained_hardened_clay-11
rule23=0,100,minecraft:sandstone_stairs-1
rule24=0,100,minecraft:sandstone_stairs-0

layer
1,1,1,1,1,1,1,1,1,1,1,1,1,1,1,1,1,1,1,1,1
1,1,1,1,1,1,1,1,1,1,1,1,1,1,1,1,1,1,1,1,1
1,1,1,1,1,1,1,1,1,1,1,1,1,1,1,1,1,1,1,1,1
1,1,1,1,1,1,1,1,1,1,1,1,1,1,1,1,1,1,1,1,1
1,1,1,1,1,1,1,1,1,1,1,1,1,1,1,1,1,1,1,1,1
1,1,1,1,1,1,1,1,1,1,1,1,1,1,2,1,2,1,1,1,1
1,1,1,1,1,1,1,1,1,1,1,1,1,1,2,1,2,1,1,1,1
1,1,1,1,1,1,1,1,1,1,1,1,1,1,1,1,1,1,1,1,1
1,1,1,1,1,1,1,1,1,1,1,1,1,1,1,1,1,1,1,1,1
1,1,1,1,1,1,1,1,1,3,3,3,1,1,1,1,1,1,1,1,1
1,1,1,1,1,1,1,1,1,3,3,3,1,1,1,1,1,1,1,1,1
1,1,1,1,1,1,1,1,1,3,3,3,1,1,1,1,1,1,1,1,1
1,1,1,1,1,1,1,1,1,1,1,1,1,1,1,1,1,1,1,1,1
1,1,1,1,1,1,1,1,1,1,1,1,1,1,1,1,1,1,1,1,1
1,1,1,1,1,1,1,1,1,1,1,1,1,1,1,1,1,1,1,1,1
1,1,1,1,1,1,1,1,1,1,1,1,1,1,1,1,1,1,1,1,1
1,1,1,1,1,1,1,1,1,1,1,1,1,1,1,1,1,1,1,1,1
1,1,1,1,1,1,1,1,1,1,1,1,1,1,1,1,1,1,1,1,1
1,1,1,1,1,1,1,1,1,1,1,1,1,1,1,1,1,1,1,1,1
1,1,1,1,1,1,1,1,1,1,1,1,1,1,1,1,1,1,1,1,1
1,1,1,1,1,1,1,1,1,1,1,1,1,1,1,1,1,1,1,1,1
endlayer

layer
1,1,1,1,1,1,1,1,1,1,1,1,1,1,1,1,1,1,1,1,1
1,4,4,4,4,4,4,4,4,4,4,4,4,4,4,4,4,4,4,4,1
1,4,3,3,3,3,3,3,3,3,3,4,3,3,3,3,3,3,3,4,1
1,4,3,3,3,3,3,5,0,0,3,4,3,3,3,3,3,3,3,4,1
1,4,3,3,3,3,3,3,3,0,3,4,3,0,0,0,0,0,3,4,1
1,4,3,0,0,0,3,0,0,0,3,4,3,0,6,0,6,0,3,4,1
1,4,3,3,3,0,3,0,3,0,3,4,3,0,6,0,6,0,3,4,1
1,4,3,0,3,0,0,0,3,0,3,4,3,0,0,0,0,0,3,4,1
1,4,3,0,3,0,3,3,3,3,3,3,3,3,3,3,0,3,3,4,1
1,4,3,0,0,0,0,0,3,9,9,9,3,3,8,3,7,3,3,4,1
1,4,3,3,3,3,3,0,3,9,9,9,3,3,3,3,0,3,3,4,1
1,4,3,0,0,0,0,0,3,9,9,9,3,0,0,0,0,0,3,4,1
1,4,3,0,3,0,3,0,3,3,3,3,3,0,3,3,3,0,3,4,1
1,4,3,0,3,0,3,0,0,3,0,0,0,0,3,0,0,0,3,4,1
1,4,3,3,3,0,3,3,3,3,3,3,3,0,3,3,3,3,3,4,1
1,4,3,0,0,0,0,0,0,3,0,0,0,0,0,0,3,0,3,4,1
1,4,3,0,3,3,0,3,0,3,0,3,3,3,3,0,3,0,3,4,1
1,4,3,0,3,0,0,3,0,0,0,3,0,0,0,0,0,0,3,4,1
1,4,3,3,3,3,3,3,3,3,3,3,3,3,3,3,3,3,3,4,1
1,4,4,4,4,4,4,4,4,4,4,4,4,4,4,4,4,4,4,4,1
1,1,1,1,1,1,1,1,1,1,1,1,1,1,1,1,1,1,1,1,1
endlayer

layer
1,1,1,1,1,1,1,1,1,1,1,1,1,1,1,1,1,1,1,1,1
1,4,4,4,4,4,4,4,4,4,4,4,4,4,4,4,4,4,4,4,1
1,4,3,3,3,3,3,3,3,3,3,4,3,3,3,3,3,3,3,4,1
1,4,3,3,8,3,5,0,0,0,3,4,3,0,10,0,10,0,3,4,1
1,4,3,3,3,3,3,3,3,0,3,4,3,0,0,0,0,0,3,4,1
1,4,3,0,0,0,3,0,0,0,3,4,3,0,0,0,0,0,3,4,1
1,4,3,3,3,0,3,0,3,0,3,4,3,0,0,0,0,0,3,4,1
1,4,3,0,3,0,0,0,3,0,3,4,3,0,0,0,0,0,3,4,1
1,4,3,0,3,0,3,3,3,3,3,3,3,3,3,3,0,3,3,4,1
1,4,3,0,0,0,0,0,3,0,0,0,0,0,12,3,11,3,3,4,1
1,4,3,3,3,3,3,0,3,0,0,0,3,3,3,3,0,3,3,4,1
1,4,3,0,0,0,0,0,3,0,0,0,3,0,0,0,0,0,3,4,1
1,4,3,0,3,0,3,0,3,3,3,3,3,0,3,3,3,0,3,4,1
1,4,3,0,3,0,3,0,0,3,0,0,0,0,3,0,0,0,3,4,1
1,4,3,3,3,0,3,3,3,3,3,3,3,0,3,3,3,3,3,4,1
1,4,3,0,0,0,0,0,0,3,0,0,0,0,0,0,3,0,3,4,1
1,4,3,0,3,3,0,3,0,3,0,3,3,3,3,0,3,0,3,4,1
1,4,3,0,3,0,0,3,0,0,0,3,0,0,0,0,0,0,3,4,1
1,4,3,3,3,3,3,3,3,3,3,3,3,3,3,3,3,3,3,4,1
1,4,4,4,4,4,4,4,4,4,4,4,4,4,4,4,4,4,4,4,1
1,1,1,1,1,1,1,1,1,1,1,1,1,1,1,1,1,1,1,1,1
endlayer

layer
1,1,1,1,1,1,1,1,1,1,1,1,1,1,1,1,1,1,1,1,1
1,4,4,4,4,4,4,4,4,4,4,4,4,4,4,4,4,4,4,4,1
1,4,3,3,3,3,3,3,3,3,3,4,3,3,3,13,3,3,3,4,1
1,4,3,3,3,5,0,0,0,0,3,4,3,0,0,0,0,0,3,4,1
1,4,3,3,3,3,3,3,3,0,3,4,3,0,0,0,0,0,3,4,1
1,4,3,0,0,0,3,0,0,0,3,4,3,0,0,0,0,0,3,4,1
1,4,3,3,3,0,3,0,3,0,3,4,3,0,0,0,0,0,3,4,1
1,4,3,0,3,0,0,0,3,0,3,4,3,0,0,0,0,0,3,4,1
1,4,3,0,3,0,3,3,3,3,3,3,3,3,3,3,3,3,3,4,1
1,4,3,0,0,0,0,0,3,0,0,0,0,0,0,12,3,3,3,4,1
1,4,3,3,3,3,3,0,3,0,0,0,3,3,3,3,3,3,3,4,1
1,4,3,0,0,0,0,0,3,0,0,0,3,0,0,0,0,0,3,4,1
1,4,3,0,3,0,3,0,3,3,3,3,3,0,3,3,3,0,3,4,1
1,4,3,0,3,0,3,0,0,3,0,0,0,0,3,0,0,0,3,4,1
1,4,3,3,3,0,3,3,3,3,3,3,3,0,3,3,3,3,3,4,1
1,4,3,0,0,0,0,0,0,3,0,0,0,0,0,0,3,0,3,4,1
1,4,3,0,3,3,0,3,0,3,0,3,3,3,3,0,3,0,3,4,1
1,4,3,0,3,0,0,3,0,0,0,3,0,0,0,0,0,0,3,4,1
1,4,3,3,3,3,3,3,3,3,3,3,3,3,3,3,3,3,3,4,1
1,4,4,4,4,4,4,4,4,4,4,4,4,4,4,4,4,4,4,4,1
1,1,1,1,1,1,1,1,1,1,1,1,1,1,1,1,1,1,1,1,1
endlayer

layer
1,1,1,1,1,1,1,1,1,1,1,1,1,1,1,1,1,1,1,1,1
1,4,4,4,4,4,4,4,4,4,4,4,4,4,4,4,4,4,4,4,1
1,4,3,3,3,3,3,3,3,3,3,3,3,3,3,3,3,3,3,4,1
1,4,3,3,5,0,0,0,0,3,3,4,3,14,0,0,0,14,3,4,1
1,4,3,3,3,3,3,3,3,3,3,4,3,0,0,0,0,0,3,4,1
1,4,3,3,3,3,3,3,3,3,3,4,3,0,0,0,0,0,3,4,1
1,4,3,3,3,3,3,3,3,3,3,4,3,0,0,0,0,0,3,4,1
1,4,3,3,3,3,3,3,3,3,3,4,3,14,0,0,0,14,3,4,1
1,4,3,3,3,3,3,3,3,3,13,3,3,3,3,3,3,3,3,4,1
1,4,3,3,3,3,3,3,3,0,0,0,0,0,0,0,12,3,3,4,1
1,4,3,3,3,3,3,3,13,0,0,0,13,3,3,3,3,3,3,4,1
1,4,3,3,3,3,3,3,3,0,0,0,3,3,3,3,3,3,3,4,1
1,4,3,3,3,3,3,3,3,3,13,3,3,3,3,3,3,3,3,4,1
1,4,3,3,3,3,3,3,3,3,3,3,3,3,3,3,3,3,3,4,1
1,4,3,3,3,3,3,3,3,3,3,3,3,3,3,3,3,3,3,4,1
1,4,3,3,3,3,3,3,3,3,3,3,3,3,3,3,3,3,3,4,1
1,4,3,3,3,3,3,3,3,3,3,3,3,3,3,3,3,3,3,4,1
1,4,3,3,3,3,3,3,3,3,3,3,3,3,3,3,3,3,3,4,1
1,4,3,3,3,3,3,3,3,3,3,3,3,3,3,3,3,3,3,4,1
1,4,4,4,4,4,4,4,4,4,4,4,4,4,4,4,4,4,4,4,1
1,1,1,1,1,1,1,1,1,1,1,1,1,1,1,1,1,1,1,1,1
endlayer

layer
1,1,1,1,1,1,1,1,1,1,1,1,1,1,1,1,1,1,1,1,1
1,4,4,4,4,4,4,4,4,4,4,4,4,4,4,4,4,4,4,4,1
1,4,3,3,3,3,3,3,3,3,3,3,3,3,3,3,3,3,3,4,1
1,4,3,0,0,0,0,0,3,0,3,4,3,3,15,0,15,3,3,4,1
1,4,3,0,3,3,3,3,3,0,3,4,3,17,0,0,0,16,3,4,1
1,4,3,0,0,0,0,0,0,0,3,4,3,0,0,0,0,0,3,4,1
1,4,3,3,3,0,3,3,3,0,3,4,3,17,0,0,0,16,3,4,1
1,4,3,0,0,0,3,0,0,0,3,4,3,3,18,0,18,3,3,4,1
1,4,3,3,3,3,3,0,3,3,3,3,3,3,3,3,3,3,3,4,1
1,4,3,0,3,0,0,0,3,0,0,0,3,0,0,0,0,0,3,4,1
1,4,3,0,3,0,3,3,3,0,0,0,3,3,3,3,3,0,3,4,1
1,4,3,0,0,0,0,0,3,0,0,0,3,0,0,0,3,0,3,4,1
1,4,3,3,3,3,3,0,3,3,3,3,3,0,3,3,3,0,3,4,1
1,4,3,0,3,0,0,0,3,0,0,0,0,0,3,0,0,0,3,4,1
1,4,3,0,3,0,3,3,3,0,3,3,3,0,3,0,3,3,3,4,1
1,4,3,0,0,0,0,0,0,0,3,3,3,0,0,0,0,0,3,4,1
1,4,3,3,3,3,3,0,3,0,3,3,3,0,3,3,3,0,3,4,1
1,4,3,0,0,0,0,0,3,0,0,0,0,0,3,0,0,0,3,4,1
1,4,3,3,3,3,3,3,3,3,3,3,3,3,3,3,3,3,3,4,1
1,4,4,4,4,4,4,4,4,4,4,4,4,4,4,4,4,4,4,4,1
1,1,1,1,1,1,1,1,1,1,1,1,1,1,1,1,1,1,1,1,1
endlayer

layer
1,1,1,1,1,1,1,1,1,1,1,1,1,1,1,1,1,1,1,1,1
1,4,4,4,4,4,4,4,4,4,4,4,4,4,4,4,4,4,4,4,1
1,4,3,3,3,3,3,3,3,3,3,3,3,3,3,3,3,3,3,4,1
1,4,3,0,0,0,0,0,3,0,3,4,3,3,1,13,1,3,3,4,1
1,4,3,0,3,3,3,3,3,0,3,4,3,1,14,0,14,1,3,4,1
1,4,3,0,0,0,0,0,0,0,3,4,3,13,0,0,0,13,3,4,1
1,4,3,3,3,0,3,3,3,0,3,4,3,1,14,0,14,1,3,4,1
1,4,3,0,0,0,3,0,0,0,3,4,3,3,1,13,1,3,3,4,1
1,4,3,3,3,3,3,0,3,3,3,3,3,3,3,3,3,3,3,4,1
1,4,3,0,3,0,0,0,3,0,0,0,3,0,0,0,0,0,3,4,1
1,4,3,0,3,0,3,3,3,0,0,0,3,3,3,3,3,0,3,4,1
1,4,3,0,0,0,0,0,3,0,0,0,3,0,0,0,3,0,3,4,1
1,4,3,3,3,3,3,0,3,3,3,3,3,0,3,3,3,0,3,4,1
1,4,3,0,3,0,0,0,3,0,0,0,0,0,3,0,0,0,3,4,1
1,4,3,0,3,0,3,3,3,0,3,3,3,0,3,0,3,3,3,4,1
1,4,3,0,0,0,0,0,0,0,3,8,3,0,0,0,0,0,3,4,1
1,4,3,3,3,3,3,0,3,0,3,3,3,0,3,3,3,0,3,4,1
1,4,3,0,0,0,0,0,3,0,0,0,0,0,3,0,0,0,3,4,1
1,4,3,3,3,3,3,3,3,3,3,3,3,3,3,3,3,3,3,4,1
1,4,4,4,4,4,4,4,4,4,4,4,4,4,4,4,4,4,4,4,1
1,1,1,1,1,1,1,1,1,1,1,1,1,1,1,1,1,1,1,1,1
endlayer

layer
1,1,1,1,1,1,1,1,1,1,1,1,1,1,1,1,1,1,1,1,1
1,4,4,4,4,4,4,4,4,4,4,4,4,4,4,4,4,4,4,4,1
1,4,3,3,3,3,3,3,3,3,3,3,3,3,3,3,3,3,3,4,1
1,4,3,0,0,0,0,0,3,0,3,4,3,3,3,3,3,3,3,4,1
1,4,3,0,3,3,3,3,3,0,3,4,3,3,3,1,3,3,3,4,1
1,4,3,0,0,0,0,0,0,0,3,4,3,3,1,19,1,3,3,4,1
1,4,3,3,3,0,3,3,3,0,3,4,3,3,3,1,3,3,3,4,1
1,4,3,0,0,0,3,0,0,0,3,4,3,3,3,3,3,3,3,4,1
1,4,3,3,3,3,3,0,3,3,3,3,3,3,3,3,3,3,3,4,1
1,4,3,0,3,0,0,0,3,0,0,0,3,0,0,0,0,0,3,4,1
1,4,3,0,3,0,3,3,3,0,0,0,3,3,3,3,3,0,3,4,1
1,4,3,0,0,0,0,0,3,0,0,0,3,0,0,0,3,0,3,4,1
1,4,3,3,3,3,3,0,3,3,3,3,3,0,3,3,3,0,3,4,1
1,4,3,0,3,0,0,0,3,0,0,0,0,0,3,0,0,0,3,4,1
1,4,3,0,3,0,3,3,3,0,3,3,3,0,3,0,3,3,3,4,1
1,4,3,0,0,0,0,0,0,0,3,3,3,0,0,0,0,0,3,4,1
1,4,3,3,3,3,3,0,3,0,3,3,3,0,3,3,3,0,3,4,1
1,4,3,0,0,0,0,0,3,0,0,0,0,0,3,0,0,0,3,4,1
1,4,3,3,3,3,3,3,3,3,3,3,3,3,3,3,3,3,3,4,1
1,4,4,4,4,4,4,4,4,4,4,4,4,4,4,4,4,4,4,4,1
1,1,1,1,1,1,1,1,1,1,1,1,1,1,1,1,1,1,1,1,1
endlayer

layer
1,1,1,1,1,1,1,1,1,1,1,1,1,1,1,1,1,1,1,1,1
1,1,1,1,1,1,1,1,1,1,1,1,1,1,1,1,1,1,1,1,1
1,1,1,1,1,1,1,1,1,1,1,1,1,1,1,1,1,1,1,1,1
1,1,1,1,1,1,1,1,1,1,1,1,1,1,1,1,1,1,1,1,1
1,1,1,1,1,1,1,1,1,1,1,1,1,1,1,1,1,1,1,1,1
1,1,1,1,1,1,1,1,1,1,1,1,1,1,1,1,1,1,1,1,1
1,1,1,1,1,1,1,1,1,1,1,1,1,1,1,1,1,1,1,1,1
1,1,1,1,1,1,1,1,1,1,1,1,1,1,1,1,1,1,1,1,1
1,1,1,1,1,1,1,1,1,3,3,3,1,1,1,1,1,1,1,1,1
1,1,1,1,1,1,1,1,3,0,0,0,3,1,1,1,1,1,1,1,1
1,1,1,1,1,1,1,1,3,0,0,0,3,1,1,1,1,1,1,1,1
1,1,1,1,1,1,1,1,3,0,0,0,3,1,1,1,1,1,1,1,1
1,1,1,1,1,1,1,1,1,3,3,3,1,1,1,1,1,1,1,1,1
1,1,1,1,1,1,1,1,1,1,1,1,1,1,1,1,1,1,1,1,1
1,1,1,1,1,1,1,1,1,1,1,1,1,1,1,1,1,1,1,1,1
1,1,1,1,1,1,1,1,1,1,1,1,1,1,1,1,1,1,1,1,1
1,1,1,1,1,1,1,1,1,1,1,1,1,1,1,1,1,1,1,1,1
1,1,1,1,1,1,1,1,1,1,1,1,1,1,1,1,1,1,1,1,1
1,1,1,1,1,1,1,1,1,1,1,1,1,1,1,1,1,1,1,1,1
1,1,1,1,1,1,1,1,1,1,1,1,1,1,1,1,1,1,1,1,1
1,1,1,1,1,1,1,1,1,1,1,1,1,1,1,1,1,1,1,1,1
endlayer

layer
1,1,1,1,1,1,1,1,1,1,1,1,1,1,1,1,1,1,1,1,1
1,1,1,1,1,1,1,1,1,1,1,1,1,1,1,1,1,1,1,1,1
1,1,1,1,1,1,1,1,1,1,1,1,1,1,1,1,1,1,1,1,1
1,1,1,1,1,1,1,1,1,1,1,1,1,1,1,1,1,1,1,1,1
1,1,1,1,1,1,1,1,1,1,1,1,1,1,1,1,1,1,1,1,1
20,1,1,1,1,1,1,1,1,1,1,1,1,1,1,1,1,1,1,1,1
20,1,1,1,1,1,1,1,1,1,1,1,1,1,1,1,1,1,1,1,1
20,1,1,1,1,1,1,1,1,1,21,1,1,1,1,1,1,1,1,1,1
1,1,1,1,1,1,1,1,1,1,21,1,1,1,1,1,1,1,1,1,1
20,1,1,1,1,1,1,1,1,21,1,21,1,1,1,1,1,1,1,1,1
20,1,1,1,1,1,1,21,21,1,22,1,21,21,1,1,1,1,1,1,1
20,1,1,1,1,1,1,1,1,21,1,21,1,1,1,1,1,1,1,1,1
1,1,1,1,1,1,1,1,1,1,21,1,1,1,1,1,1,1,1,1,1
20,1,1,1,1,1,1,1,1,1,21,1,1,1,1,1,1,1,1,1,1
20,1,1,1,1,1,1,1,1,1,1,1,1,1,1,1,1,1,1,1,1
20,1,1,1,1,1,1,1,1,1,1,1,1,1,1,1,1,1,1,1,1
1,1,1,1,1,1,1,1,1,1,1,1,1,1,1,1,1,1,1,1,1
1,1,1,1,1,1,1,1,1,1,1,1,1,1,1,1,1,1,1,1,1
1,1,1,1,1,1,1,1,1,1,1,1,1,1,1,1,1,1,1,1,1
1,1,1,1,1,1,1,1,1,1,1,1,1,1,1,1,1,1,1,1,1
1,1,1,1,1,1,1,1,1,1,1,1,1,1,1,1,1,1,1,1,1
endlayer

layer
1,1,21,1,1,20,20,20,20,20,20,20,20,20,20,20,20,20,20,20,20
1,1,1,1,1,1,1,1,1,1,1,1,1,1,1,1,1,1,1,1,20
21,23,0,1,1,1,1,1,1,1,1,1,1,1,1,1,1,1,1,1,20
1,0,0,0,1,0,0,0,0,0,0,0,0,0,0,0,0,0,1,1,20
1,1,0,1,1,0,3,0,3,0,3,0,3,0,3,0,3,0,1,1,20
20,1,0,1,1,0,0,0,0,0,0,0,0,0,0,0,0,0,1,1,20
20,1,0,1,1,0,0,0,0,0,0,0,0,0,0,0,0,0,1,1,20
20,1,0,1,1,0,0,0,0,0,0,0,0,0,0,0,0,0,1,1,20
1,1,0,1,1,0,0,0,3,0,0,0,3,0,0,0,0,0,1,1,20
0,1,0,0,0,0,0,0,0,0,0,0,0,0,0,0,0,0,1,1,20
0,0,0,0,0,0,0,0,0,0,0,0,0,0,0,0,0,0,1,1,20
0,1,0,0,0,0,0,0,0,0,0,0,0,0,0,0,0,0,1,1,20
1,1,0,1,1,0,0,0,3,0,0,0,3,0,0,0,0,0,1,1,20
20,1,0,1,1,0,0,0,0,0,0,0,0,0,0,0,0,0,1,1,20
20,1,0,1,1,0,0,0,0,0,0,0,0,0,0,0,0,0,1,1,20
20,1,0,1,1,0,0,0,0,0,0,0,0,0,0,0,0,0,1,1,20
1,1,0,1,1,0,3,0,3,0,3,0,3,0,3,0,3,0,1,1,20
1,0,0,0,1,0,0,0,0,0,0,0,0,0,0,0,0,0,1,1,20
21,24,0,1,1,1,1,1,1,1,1,1,1,1,1,1,1,1,1,1,20
1,1,1,1,1,1,1,1,1,1,1,1,1,1,1,1,1,1,1,1,20
1,1,21,1,1,20,20,20,20,20,20,20,20,20,20,20,20,20,20,20,20
endlayer

layer
1,1,21,1,1,20,20,20,20,20,20,20,20,20,20,20,20,20,20,20,20
1,23,1,1,1,1,1,1,1,1,1,1,20,20,20,20,20,20,20,20,20
21,0,0,1,1,1,1,1,1,1,1,1,1,1,1,1,1,1,1,20,20
1,0,0,0,1,0,0,0,0,0,0,0,0,0,0,0,0,0,1,20,20
1,1,0,1,1,0,13,0,13,0,13,0,13,0,13,0,13,0,1,20,20
20,1,0,1,1,0,0,0,0,0,0,0,0,0,0,0,0,0,1,20,20
20,1,0,1,1,0,0,0,0,0,0,0,0,0,0,0,0,0,1,20,20
20,1,0,1,1,0,0,0,0,0,0,0,0,0,0,0,0,0,1,20,20
1,1,0,1,1,0,0,0,3,0,0,0,3,0,0,0,0,0,1,20,20
0,1,0,0,0,0,0,0,0,0,0,0,0,0,0,0,0,0,1,20,20
0,0,0,0,0,0,0,0,0,0,0,0,0,0,0,0,0,0,1,20,20
0,1,0,0,0,0,0,0,0,0,0,0,0,0,0,0,0,0,1,20,20
1,1,0,1,1,0,0,0,3,0,0,0,3,0,0,0,0,0,1,20,20
20,1,0,1,1,0,0,0,0,0,0,0,0,0,0,0,0,0,1,20,20
20,1,0,1,1,0,0,0,0,0,0,0,0,0,0,0,0,0,1,20,20
20,1,0,1,1,0,0,0,0,0,0,0,0,0,0,0,0,0,1,20,20
1,1,0,1,1,0,13,0,13,0,13,0,13,0,13,0,13,0,1,20,20
1,0,0,0,1,0,0,0,0,0,0,0,0,0,0,0,0,0,1,20,20
21,0,0,1,1,1,1,1,1,1,1,1,1,1,1,1,1,1,1,20,20
1,24,1,1,1,1,1,1,1,1,1,1,20,20,20,20,20,20,20,20,20
1,1,21,1,1,20,20,20,20,20,20,20,20,20,20,20,20,20,20,20,20
endlayer

layer
1,21,1,21,1,20,20,20,20,20,20,20,20,20,20,20,20,20,20,20,20
21,0,12,1,1,1,1,1,1,1,1,1,20,20,20,20,20,20,20,20,20
1,0,0,1,1,1,1,1,1,1,1,1,20,20,20,20,20,20,20,20,20
21,0,0,0,1,1,1,1,1,1,1,1,1,1,1,1,1,1,20,20,20
1,1,1,1,1,3,3,3,3,3,3,3,3,3,3,3,3,1,20,20,20
20,1,1,1,1,15,15,15,15,15,15,15,15,15,15,15,15,1,20,20,20
20,1,1,1,1,0,0,0,0,0,0,0,0,0,0,0,0,1,20,20,20
20,1,1,1,1,0,0,0,0,0,0,0,0,0,0,0,0,1,20,20,20
1,1,1,1,1,0,0,0,3,0,0,0,3,0,0,0,0,1,20,20,20
0,1,1,1,1,0,0,0,0,0,0,0,0,0,0,0,0,1,20,20,20
0,1,1,1,1,0,0,0,0,0,0,0,0,0,0,0,0,1,20,20,20
0,1,1,1,1,0,0,0,0,0,0,0,0,0,0,0,0,1,20,20,20
1,1,1,1,1,0,0,0,3,0,0,0,3,0,0,0,0,1,20,20,20
20,1,1,1,1,0,0,0,0,0,0,0,0,0,0,0,0,1,20,20,20
20,1,1,1,1,0,0,0,0,0,0,0,0,0,0,0,0,1,20,20,20
20,1,1,1,1,18,18,18,18,18,18,18,18,18,18,18,18,1,20,20,20
1,1,1,1,1,3,3,3,3,3,3,3,3,3,3,3,3,1,20,20,20
21,0,0,0,1,1,1,1,1,1,1,1,1,1,1,1,1,1,20,20,20
1,0,0,1,1,1,1,1,1,1,1,1,20,20,20,20,20,20,20,20,20
21,0,12,1,1,1,1,1,1,1,1,1,20,20,20,20,20,20,20,20,20
1,21,1,21,1,20,20,20,20,20,20,20,20,20,20,20,20,20,20,20,20
endlayer

layer
1,1,21,1,1,20,20,20,20,20,20,20,20,20,20,20,20,20,20,20,20
1,0,0,12,1,1,1,1,1,1,1,1,20,20,20,20,20,20,20,20,20
21,0,0,1,1,1,1,1,1,1,1,1,20,20,20,20,20,20,20,20,20
1,0,0,0,1,1,1,1,1,1,1,1,20,20,20,20,20,20,20,20,20
1,1,1,1,1,1,1,1,1,1,1,1,1,1,1,1,1,20,20,20,20
20,20,20,20,1,1,1,1,1,1,1,1,1,1,1,1,1,20,20,20,20
20,20,20,20,1,1,1,1,1,1,1,1,1,1,1,1,1,20,20,20,20
20,20,20,20,1,1,1,1,1,1,1,1,1,1,1,1,1,20,20,20,20
3,1,1,1,1,1,1,1,1,1,1,1,1,1,1,1,1,20,20,20,20
3,1,1,1,1,1,1,1,1,0,0,0,1,1,1,1,1,20,20,20,20
3,1,1,1,1,1,1,1,1,0,0,0,1,1,1,1,1,20,20,20,20
3,1,1,1,1,1,1,1,1,0,0,0,1,1,1,1,1,20,20,20,20
3,1,1,1,1,1,1,1,1,1,1,1,1,1,1,1,1,20,20,20,20
20,20,20,20,1,1,1,1,1,1,1,1,1,1,1,1,1,20,20,20,20
20,20,20,20,1,1,1,1,1,1,1,1,1,1,1,1,1,20,20,20,20
20,20,20,20,1,1,1,1,1,1,1,1,1,1,1,1,1,20,20,20,20
1,1,1,1,1,1,1,1,1,1,1,1,1,1,1,1,1,20,20,20,20
1,0,0,0,1,1,1,1,1,1,1,1,20,20,20,20,20,20,20,20,20
21,0,0,1,1,1,1,1,1,1,1,1,20,20,20,20,20,20,20,20,20
1,0,0,12,1,1,1,1,1,1,1,1,20,20,20,20,20,20,20,20,20
1,1,21,1,1,20,20,20,20,20,20,20,20,20,20,20,20,20,20,20,20
endlayer

layer
1,21,1,21,1,20,20,20,20,20,20,20,20,20,20,20,20,20,20,20,20
21,0,0,0,1,20,20,20,20,20,20,20,20,20,20,20,20,20,20,20,20
1,0,0,0,0,20,20,20,20,20,20,20,20,20,20,20,20,20,20,20,20
21,0,0,0,1,20,20,20,20,20,20,20,20,20,20,20,20,20,20,20,20
1,1,1,1,1,20,20,20,20,20,20,20,20,20,20,20,20,20,20,20,20
20,20,20,20,20,1,1,1,1,1,0,1,1,1,1,1,20,20,20,20,20
20,20,20,20,20,1,1,1,1,1,0,1,1,1,1,1,20,20,20,20,20
20,20,20,20,20,1,1,0,0,0,0,0,0,0,1,1,20,20,20,20,20
3,20,20,20,20,1,1,0,0,0,0,0,0,0,1,1,20,20,20,20,20
21,20,20,20,20,1,1,0,0,0,0,0,0,0,1,1,20,20,20,20,20
3,20,20,20,20,1,1,0,0,0,0,0,0,0,1,1,20,20,20,20,20
21,20,20,20,20,1,1,0,0,0,0,0,0,0,1,1,20,20,20,20,20
3,20,20,20,20,1,1,0,0,0,0,0,0,0,1,1,20,20,20,20,20
20,20,20,20,20,1,1,0,0,0,0,0,0,0,1,1,20,20,20,20,20
20,20,20,20,20,1,1,1,1,1,0,1,1,1,1,1,20,20,20,20,20
20,20,20,20,20,1,1,1,1,1,0,1,1,1,1,1,20,20,20,20,20
1,1,1,1,1,20,20,20,20,20,20,20,20,20,20,20,20,20,20,20,20
21,0,0,0,1,20,20,20,20,20,20,20,20,20,20,20,20,20,20,20,20
1,0,0,0,0,20,20,20,20,20,20,20,20,20,20,20,20,20,20,20,20
21,0,0,0,1,20,20,20,20,20,20,20,20,20,20,20,20,20,20,20,20
1,21,1,21,1,20,20,20,20,20,20,20,20,20,20,20,20,20,20,20,20
endlayer

layer
1,21,21,21,1,20,20,20,20,20,20,20,20,20,20,20,20,20,20,20,20
21,0,0,0,1,20,20,20,20,20,20,20,20,20,20,20,20,20,20,20,20
21,0,0,0,0,20,20,20,20,20,20,20,20,20,20,20,20,20,20,20,20
21,0,0,0,1,20,20,20,20,20,20,20,20,20,20,20,20,20,20,20,20
1,1,1,1,1,20,20,20,20,20,20,20,20,20,20,20,20,20,20,20,20
20,20,20,20,20,20,20,20,20,1,0,1,20,20,20,20,20,20,20,20,20
20,20,20,20,20,20,1,1,1,1,0,1,1,1,1,20,20,20,20,20,20
20,20,20,20,20,20,1,0,0,0,0,0,0,0,1,20,20,20,20,20,20
20,20,20,20,20,20,1,0,0,0,0,0,0,0,1,20,20,20,20,20,20
3,20,20,20,20,20,1,0,0,0,0,0,0,0,1,20,20,20,20,20,20
3,20,20,20,20,20,1,0,0,0,0,0,0,0,1,20,20,20,20,20,20
3,20,20,20,20,20,1,0,0,0,0,0,0,0,1,20,20,20,20,20,20
20,20,20,20,20,20,1,0,0,0,0,0,0,0,1,20,20,20,20,20,20
20,20,20,20,20,20,1,0,0,0,0,0,0,0,1,20,20,20,20,20,20
20,20,20,20,20,20,1,1,1,1,0,1,1,1,1,20,20,20,20,20,20
20,20,20,20,20,20,20,20,20,1,0,1,20,20,20,20,20,20,20,20,20
1,1,1,1,1,20,20,20,20,20,20,20,20,20,20,20,20,20,20,20,20
21,0,0,0,1,20,20,20,20,20,20,20,20,20,20,20,20,20,20,20,20
21,0,0,0,0,20,20,20,20,20,20,20,20,20,20,20,20,20,20,20,20
21,0,0,0,1,20,20,20,20,20,20,20,20,20,20,20,20,20,20,20,20
1,21,21,21,1,20,20,20,20,20,20,20,20,20,20,20,20,20,20,20,20
endlayer

layer
1,1,1,1,1,20,20,20,20,20,20,20,20,20,20,20,20,20,20,20,20
1,0,0,0,1,20,20,20,20,20,20,20,20,20,20,20,20,20,20,20,20
1,0,0,0,1,20,20,20,20,20,20,20,20,20,20,20,20,20,20,20,20
1,0,0,0,1,20,20,20,20,20,20,20,20,20,20,20,20,20,20,20,20
1,1,1,1,1,20,20,20,20,20,20,20,20,20,20,20,20,20,20,20,20
20,20,20,20,20,20,20,20,20,1,1,1,20,20,20,20,20,20,20,20,20
20,20,20,20,20,20,20,20,20,1,1,1,20,20,20,20,20,20,20,20,20
20,20,20,20,20,20,20,1,1,1,1,1,1,1,20,20,20,20,20,20,20
20,20,20,20,20,20,20,1,0,0,0,0,0,1,20,20,20,20,20,20,20
20,20,20,20,20,20,20,1,0,0,0,0,0,1,20,20,20,20,20,20,20
20,20,20,20,20,20,20,1,0,0,0,0,0,1,20,20,20,20,20,20,20
20,20,20,20,20,20,20,1,0,0,0,0,0,1,20,20,20,20,20,20,20
20,20,20,20,20,20,20,1,0,0,0,0,0,1,20,20,20,20,20,20,20
20,20,20,20,20,20,20,1,1,1,1,1,1,1,20,20,20,20,20,20,20
20,20,20,20,20,20,20,20,20,1,1,1,20,20,20,20,20,20,20,20,20
20,20,20,20,20,20,20,20,20,1,1,1,20,20,20,20,20,20,20,20,20
1,1,1,1,1,20,20,20,20,20,20,20,20,20,20,20,20,20,20,20,20
1,0,0,0,1,20,20,20,20,20,20,20,20,20,20,20,20,20,20,20,20
1,0,0,0,1,20,20,20,20,20,20,20,20,20,20,20,20,20,20,20,20
1,0,0,0,1,20,20,20,20,20,20,20,20,20,20,20,20,20,20,20,20
1,1,1,1,1,20,20,20,20,20,20,20,20,20,20,20,20,20,20,20,20
endlayer

layer
1,1,1,1,1,20,20,20,20,20,20,20,20,20,20,20,20,20,20,20,20
1,0,0,0,1,20,20,20,20,20,20,20,20,20,20,20,20,20,20,20,20
1,0,0,0,1,20,20,20,20,20,20,20,20,20,20,20,20,20,20,20,20
1,0,0,0,1,20,20,20,20,20,20,20,20,20,20,20,20,20,20,20,20
1,1,1,1,1,20,20,20,20,20,20,20,20,20,20,20,20,20,20,20,20
20,20,20,20,20,20,20,20,20,20,20,20,20,20,20,20,20,20,20,20,20
20,20,20,20,20,20,20,20,20,20,20,20,20,20,20,20,20,20,20,20,20
20,20,20,20,20,20,20,20,20,20,20,20,20,20,20,20,20,20,20,20,20
20,20,20,20,20,20,20,20,1,1,1,1,1,20,20,20,20,20,20,20,20
20,20,20,20,20,20,20,20,1,0,0,0,1,20,20,20,20,20,20,20,20
20,20,20,20,20,20,20,20,1,0,0,0,1,20,20,20,20,20,20,20,20
20,20,20,20,20,20,20,20,1,0,0,0,1,20,20,20,20,20,20,20,20
20,20,20,20,20,20,20,20,1,1,1,1,1,20,20,20,20,20,20,20,20
20,20,20,20,20,20,20,20,20,20,20,20,20,20,20,20,20,20,20,20,20
20,20,20,20,20,20,20,20,20,20,20,20,20,20,20,20,20,20,20,20,20
20,20,20,20,20,20,20,20,20,20,20,20,20,20,20,20,20,20,20,20,20
1,1,1,1,1,20,20,20,20,20,20,20,20,20,20,20,20,20,20,20,20
1,0,0,0,1,20,20,20,20,20,20,20,20,20,20,20,20,20,20,20,20
1,0,0,0,1,20,20,20,20,20,20,20,20,20,20,20,20,20,20,20,20
1,0,0,0,1,20,20,20,20,20,20,20,20,20,20,20,20,20,20,20,20
1,1,1,1,1,20,20,20,20,20,20,20,20,20,20,20,20,20,20,20,20
endlayer

layer
20,20,24,20,20,20,20,20,20,20,20,20,20,20,20,20,20,20,20,20,20
20,1,1,1,20,20,20,20,20,20,20,20,20,20,20,20,20,20,20,20,20
12,1,1,1,5,20,20,20,20,20,20,20,20,20,20,20,20,20,20,20,20
20,1,1,1,20,20,20,20,20,20,20,20,20,20,20,20,20,20,20,20,20
20,20,23,20,20,20,20,20,20,20,20,20,20,20,20,20,20,20,20,20,20
20,20,20,20,20,20,20,20,20,20,20,20,20,20,20,20,20,20,20,20,20
20,20,20,20,20,20,20,20,20,20,20,20,20,20,20,20,20,20,20,20,20
20,20,20,20,20,20,20,20,20,20,20,20,20,20,20,20,20,20,20,20,20
20,20,20,20,20,20,20,20,20,20,20,20,20,20,20,20,20,20,20,20,20
20,20,20,20,20,20,20,20,20,1,1,1,20,20,20,20,20,20,20,20,20
20,20,20,20,20,20,20,20,20,1,0,1,20,20,20,20,20,20,20,20,20
20,20,20,20,20,20,20,20,20,1,1,1,20,20,20,20,20,20,20,20,20
20,20,20,20,20,20,20,20,20,20,20,20,20,20,20,20,20,20,20,20,20
20,20,20,20,20,20,20,20,20,20,20,20,20,20,20,20,20,20,20,20,20
20,20,20,20,20,20,20,20,20,20,20,20,20,20,20,20,20,20,20,20,20
20,20,20,20,20,20,20,20,20,20,20,20,20,20,20,20,20,20,20,20,20
20,20,24,20,20,20,20,20,20,20,20,20,20,20,20,20,20,20,20,20,20
20,1,1,1,20,20,20,20,20,20,20,20,20,20,20,20,20,20,20,20,20
12,1,1,1,5,20,20,20,20,20,20,20,20,20,20,20,20,20,20,20,20
20,1,1,1,20,20,20,20,20,20,20,20,20,20,20,20,20,20,20,20,20
20,20,23,20,20,20,20,20,20,20,20,20,20,20,20,20,20,20,20,20,20
endlayer

