
# Created by Ruins mod version 16.7 Ingame Parser
# authoring Player: ST753M

weight=1
uniqueMinDistance=1000
embed_into_distance=7
acceptable_target_blocks=sand
unacceptable_target_blocks=flowing_water,water,flowing_lava,lava
dimensions=16,21,21
allowable_overhang=7
max_leveling=2
leveling_buffer=0
preserve_water=0
preserve_lava=0

biomesToSpawnIn=desert,desert_hills,mutated_desert,xeric_shrubland,mountainous_desert

rule1=0,100,minecraft:sandstone-0
rule2=0,100,minecraft:stained_hardened_clay-1
rule3=0,100,minecraft:dirt-0
rule4=0,100,minecraft:log-0
rule5=0,100,minecraft:dirt-0
rule6=0,100,minecraft:sand-0
rule7=0,100,minecraft:sandstone-2
rule8=0,100,air
rule9=0,100,minecraft:sandstone_stairs-0
rule10=0,100,air
rule11=0,100,minecraft:sandstone_stairs-5
rule12=0,100,air
rule13=0,100,minecraft:sandstone_stairs-4
rule14=0,100,air
rule15=0,100,air
rule16=0,100,air
rule17=0,100,minecraft:sandstone_stairs-1
rule18=0,100,minecraft:sandstone-1
rule19=0,100,minecraft:leaves-12
rule20=0,100,minecraft:log-8
rule21=0,100,minecraft:sandstone_stairs-6
rule22=0,100,minecraft:sandstone_stairs-7
rule23=0,100,minecraft:sandstone_stairs-3
rule24=0,100,minecraft:log-4
rule25=0,100,minecraft:sandstone_stairs-2
rule26=0,100,minecraft:stone_slab-1
rule27=0,100,preserveBlock
rule28=0,100,minecraft:stained_glass-0

layer
1,1,1,1,1,1,1,1,1,1,1,1,1,1,1,1,1,1,1,1,1
1,1,1,1,1,1,1,1,1,1,1,1,1,1,1,1,1,1,1,1,1
1,1,1,1,2,1,1,1,2,1,1,1,2,1,1,1,2,1,1,1,1
1,1,1,1,2,1,1,1,2,1,1,1,2,1,1,1,2,1,1,1,1
1,1,2,2,1,1,1,1,1,1,1,1,1,1,1,1,1,2,2,1,1
1,1,1,1,1,1,3,3,3,3,3,3,3,3,3,1,1,1,1,1,1
1,1,1,1,1,3,3,3,3,3,3,3,3,3,3,3,1,1,1,1,1
1,1,1,1,1,3,3,3,3,3,3,3,3,3,3,3,1,1,1,1,1
1,1,2,2,1,3,3,3,4,3,3,3,4,3,3,3,1,2,2,1,1
1,1,1,1,1,3,3,5,5,5,5,3,3,3,3,3,1,1,1,1,1
1,1,1,1,1,3,3,5,5,5,5,5,3,3,3,3,1,1,1,1,1
1,1,1,1,1,3,3,3,5,5,3,3,3,3,3,3,1,1,1,1,1
1,1,2,2,1,3,3,3,4,5,5,3,4,3,3,3,1,2,2,1,1
1,1,1,1,1,3,3,3,3,3,3,3,3,3,3,3,1,1,1,1,1
1,1,1,1,1,3,3,3,3,3,3,3,3,3,3,3,1,1,1,1,1
1,1,1,1,1,1,3,3,3,3,3,3,3,3,3,1,1,1,1,1,1
1,1,2,2,1,1,1,1,1,1,1,1,1,1,1,1,1,2,2,1,1
1,1,1,1,2,1,1,1,2,1,1,1,2,1,1,1,2,1,1,1,1
1,1,1,1,2,1,1,1,2,1,1,1,2,1,1,1,2,1,1,1,1
1,1,1,1,1,1,1,1,1,1,1,1,1,1,1,1,1,1,1,1,1
1,1,1,1,1,1,1,1,1,1,1,1,1,1,1,1,1,1,1,1,1
endlayer

layer
1,1,1,1,1,1,1,1,1,1,1,1,1,1,1,1,1,1,1,1,1
1,6,6,6,6,0,6,6,6,0,0,0,6,6,6,6,6,6,0,0,1
1,6,7,6,6,0,7,6,6,0,7,6,6,6,7,6,0,6,7,6,1
1,6,6,6,6,0,6,0,0,0,6,0,6,0,6,6,0,6,6,0,1
1,6,6,6,6,0,0,0,0,0,0,0,0,0,0,0,0,0,0,6,1
1,6,6,6,0,0,8,8,8,8,8,8,8,8,8,0,0,0,0,6,1
1,6,6,6,0,10,8,8,8,8,8,8,8,8,8,8,0,6,7,9,1
1,6,6,0,0,10,8,8,8,8,8,8,8,8,8,8,0,0,0,11,1
1,0,0,0,0,10,8,8,4,8,8,8,4,8,8,8,0,0,6,0,1
1,6,0,0,0,10,8,0,0,0,0,6,8,8,8,8,0,6,6,6,1
1,6,7,6,6,12,8,0,0,0,6,6,8,8,8,8,0,6,7,0,1
1,6,6,0,6,12,8,0,0,0,6,6,8,8,8,8,0,6,6,6,1
1,6,6,0,6,12,8,0,4,6,6,0,4,8,8,8,0,0,6,6,1
1,13,6,6,0,12,8,8,8,8,8,8,8,8,8,8,0,0,6,6,1
1,17,7,0,0,16,16,15,14,14,14,8,8,8,8,8,0,6,7,0,1
1,0,0,0,0,0,16,15,15,14,14,14,14,14,14,0,6,0,0,6,1
1,0,0,0,0,0,0,0,0,0,0,0,0,0,6,0,6,6,6,6,1
1,6,0,6,0,0,6,0,0,0,0,0,0,0,6,0,0,0,6,6,1
1,6,7,6,6,0,7,6,0,6,7,6,6,0,7,0,6,6,7,6,1
1,6,0,6,6,6,6,6,6,6,6,6,6,6,0,6,6,6,6,6,1
1,1,1,1,1,1,1,1,1,1,1,1,1,1,1,1,1,1,1,1,1
endlayer

layer
1,1,1,1,1,1,1,1,1,1,1,1,1,1,1,1,1,1,1,1,1
1,6,6,6,6,0,6,6,6,0,0,0,6,6,0,0,0,0,0,0,1
1,6,7,6,0,0,7,0,0,0,7,0,6,0,7,0,0,0,7,0,1
1,6,6,6,0,0,0,0,0,0,0,0,0,0,0,6,0,0,6,0,1
1,6,6,6,6,0,0,0,0,0,0,0,0,0,0,0,0,0,0,6,1
1,6,0,6,0,0,0,0,0,0,0,0,0,0,0,0,0,0,0,0,1
1,6,6,0,0,0,0,0,0,0,0,0,0,6,6,0,0,6,7,6,1
1,6,0,0,0,0,0,0,0,0,0,0,6,6,6,0,0,0,0,9,1
1,0,0,0,0,0,0,0,4,0,0,0,6,6,6,0,0,0,6,11,1
1,0,0,0,0,0,0,0,0,0,0,6,6,6,0,0,0,0,6,6,1
1,0,7,0,0,0,0,0,0,0,6,0,6,0,0,0,0,0,7,0,1
1,0,0,0,6,0,0,0,0,0,0,6,6,0,0,0,0,0,0,6,1
1,13,6,0,6,0,0,0,4,0,0,0,4,0,0,0,0,0,0,6,1
1,17,6,0,0,0,0,0,0,0,0,0,0,0,0,0,0,0,6,6,1
1,0,7,0,0,0,0,0,0,0,0,0,0,0,0,0,0,0,7,0,1
1,0,0,0,0,0,0,0,0,0,0,0,0,0,0,0,0,0,0,0,1
1,0,0,0,0,0,0,0,0,0,0,0,0,0,0,0,0,0,0,0,1
1,0,0,0,0,0,0,0,0,0,0,0,0,0,0,0,0,0,0,0,1
1,6,7,6,0,0,7,0,0,0,7,0,0,0,7,0,0,0,7,6,1
1,6,0,6,6,0,0,0,0,6,0,6,6,6,0,6,0,6,0,6,1
1,1,1,1,1,1,1,1,1,1,1,1,1,1,1,1,1,1,1,1,1
endlayer

layer
1,1,1,1,1,1,1,1,1,1,1,1,1,1,1,1,1,1,1,1,1
1,6,6,6,0,0,0,6,0,0,0,0,6,0,0,0,0,0,0,0,1
1,6,18,6,0,0,18,0,0,0,18,0,0,0,18,0,0,0,18,0,1
1,0,6,6,0,0,0,0,0,0,0,0,0,0,0,0,0,0,0,0,1
1,6,6,6,0,0,0,0,0,0,0,0,0,0,0,0,0,0,0,0,1
1,0,0,0,0,0,0,0,0,0,0,0,0,0,0,0,0,0,0,0,1
1,0,0,0,0,0,0,0,0,0,0,0,0,0,0,0,0,0,18,6,1
1,6,0,0,0,0,0,0,19,19,0,0,0,6,6,0,0,0,0,6,1
1,0,0,0,0,0,0,20,4,19,0,0,0,6,0,0,0,0,0,9,1
1,0,0,0,0,0,0,0,0,0,0,6,6,6,0,0,0,0,6,11,1
1,0,18,0,0,0,0,0,0,0,0,0,0,0,0,0,0,0,18,0,1
1,13,0,0,6,0,0,0,0,0,0,0,19,19,0,0,0,0,0,0,1
1,17,0,0,6,0,0,0,0,0,0,19,4,19,19,0,0,0,0,0,1
1,6,0,0,0,0,0,0,0,0,0,0,19,0,0,0,0,0,0,0,1
1,0,18,0,0,0,0,0,0,0,0,0,0,0,0,0,0,0,18,0,1
1,0,0,0,0,0,0,0,0,0,0,0,0,0,0,0,0,0,0,0,1
1,0,0,0,0,0,0,0,0,0,0,0,0,0,0,0,0,0,0,0,1
1,0,0,0,0,0,0,0,0,0,0,0,0,0,0,0,0,0,0,0,1
1,6,18,0,0,0,18,0,0,0,18,0,0,0,18,0,0,0,18,0,1
1,6,0,0,6,0,0,0,0,0,0,0,0,0,0,0,0,0,0,0,1
1,1,1,1,1,1,1,1,1,1,1,1,1,1,1,1,1,1,1,1,1
endlayer

layer
7,7,7,7,7,7,7,7,7,7,7,7,7,7,7,7,7,7,7,7,7
7,7,7,7,7,7,7,7,7,7,7,7,7,7,7,7,7,7,7,7,7
7,7,7,6,7,7,7,7,7,7,7,7,7,7,7,7,7,7,7,7,7
7,7,7,6,11,11,11,11,11,11,11,11,11,11,11,11,11,7,7,7,7
7,7,7,21,0,0,0,0,0,0,0,0,0,0,0,0,0,0,0,7,7
7,7,0,0,0,0,0,0,0,0,0,0,0,0,0,0,0,0,0,0,7
7,7,0,0,0,0,0,0,0,0,0,0,0,0,0,0,0,0,0,0,7
7,7,0,0,0,0,0,0,0,0,0,0,0,0,0,0,0,0,0,0,7
7,7,0,0,0,0,0,19,4,19,0,0,0,6,0,0,0,0,0,0,7
7,7,7,21,0,0,0,0,0,0,0,6,6,0,0,0,0,0,6,9,7
7,7,7,21,0,0,0,0,0,0,0,0,0,0,0,0,0,0,7,7,7
7,17,7,21,0,0,0,0,0,0,0,0,0,0,0,0,0,22,7,7,7
7,0,7,21,0,0,0,0,0,0,0,19,4,19,0,0,0,22,7,7,7
7,0,7,21,0,0,0,0,0,0,0,0,0,0,0,0,0,22,7,7,7
7,0,7,21,0,0,0,0,0,0,0,0,0,0,0,0,0,22,7,7,7
7,7,7,21,0,0,0,0,0,0,0,0,0,0,0,0,0,22,7,7,7
7,7,7,0,0,0,0,0,0,0,0,0,0,0,0,0,0,22,7,7,7
7,7,7,7,13,13,13,13,13,13,13,13,13,13,13,13,13,0,7,7,7
7,7,7,7,7,7,7,7,7,7,7,7,7,7,7,7,7,7,7,7,7
7,7,7,7,7,7,7,7,7,7,7,7,7,7,7,7,7,7,7,7,7
7,7,7,7,7,7,7,7,7,7,7,7,7,7,7,7,7,7,7,7,7
endlayer

layer
7,7,7,7,7,7,7,7,7,7,7,7,7,7,7,7,7,7,7,7,7
7,6,6,0,0,0,0,0,0,0,0,0,0,0,0,0,0,0,0,0,7
7,6,6,0,0,0,0,0,0,0,0,0,0,0,0,0,0,0,0,0,7
7,6,6,7,23,23,23,23,23,23,23,23,23,23,23,23,23,7,0,0,7
7,6,6,0,0,0,0,0,0,0,0,0,0,0,0,0,0,0,0,0,7
7,6,0,0,0,0,0,0,0,0,0,0,0,0,0,0,0,0,0,0,7
7,0,0,0,0,0,0,0,0,0,0,0,0,0,0,0,0,0,0,0,7
7,6,0,0,0,0,0,0,0,0,0,0,0,0,0,0,0,0,0,0,7
7,6,0,0,0,0,0,0,19,0,0,0,0,0,0,0,0,0,0,0,7
7,0,0,0,0,0,0,0,0,0,0,0,0,0,0,0,0,0,0,0,7
7,6,0,6,0,0,0,0,0,0,0,0,0,0,0,0,0,0,0,0,7
7,0,0,17,0,0,0,0,0,0,0,0,24,0,0,0,0,6,0,0,7
7,0,0,17,0,0,0,0,0,0,0,0,4,0,0,0,0,6,6,0,7
7,0,0,17,0,0,0,0,0,0,0,0,0,0,0,0,0,6,6,0,7
7,0,0,0,0,0,0,0,0,0,0,0,0,0,0,0,0,9,0,0,7
7,0,0,0,0,0,0,0,0,0,0,0,0,0,0,0,0,9,0,0,7
7,0,0,0,0,0,0,0,0,0,0,0,0,0,0,0,0,9,0,0,7
7,0,0,7,25,25,25,25,25,25,0,0,25,25,25,25,25,7,0,0,7
7,0,0,0,0,0,0,6,6,6,6,0,0,0,0,0,0,0,0,0,7
7,0,0,0,0,6,6,6,6,6,6,6,0,6,6,0,0,0,0,0,7
7,7,7,7,7,7,7,7,7,7,7,7,7,7,7,7,7,7,7,7,7
endlayer

layer
1,1,1,1,1,1,1,1,1,1,0,0,1,1,1,1,1,1,1,1,1
1,0,0,0,0,0,0,0,0,0,0,0,0,0,0,0,0,0,0,0,1
1,0,0,0,0,0,0,0,0,0,0,0,0,0,0,0,0,0,0,0,1
1,0,6,7,26,26,26,26,26,26,26,26,26,26,26,26,26,7,0,0,1
1,0,0,26,0,0,0,0,0,0,0,0,0,0,0,0,0,0,0,0,1
1,0,0,0,0,0,0,0,0,0,0,0,0,0,0,0,0,0,0,0,1
1,0,0,0,0,0,0,0,0,0,0,0,0,0,0,0,0,0,0,0,1
1,0,0,0,0,0,0,0,0,0,0,0,0,0,0,0,0,0,0,0,1
1,0,0,0,0,0,0,0,0,0,0,0,0,0,0,0,0,0,0,0,1
1,0,0,0,0,0,0,0,0,0,0,0,0,0,0,0,0,0,0,0,1
1,0,0,0,0,0,0,0,0,0,0,0,24,0,0,0,0,0,0,0,1
1,0,0,6,0,0,0,0,0,0,0,0,0,0,0,0,0,0,0,0,1
1,0,0,6,0,0,0,0,0,0,0,0,4,0,0,0,0,0,0,0,1
1,0,0,0,0,0,0,0,0,0,0,0,0,0,0,0,0,6,0,0,1
1,0,0,0,0,0,0,0,0,0,0,0,0,0,0,0,0,6,0,0,1
1,0,0,0,0,0,0,0,0,0,0,0,0,0,0,0,0,6,0,0,1
1,0,0,0,0,0,0,0,0,0,0,0,0,0,0,0,0,26,0,0,1
1,0,0,7,26,26,26,26,26,26,0,0,0,26,26,26,26,7,0,0,1
1,0,0,0,0,0,0,6,0,6,0,0,0,0,0,0,0,0,0,0,1
1,0,0,0,0,0,0,6,0,0,0,0,0,0,0,0,0,0,0,0,1
1,1,1,1,1,1,1,1,1,1,1,1,1,1,1,1,1,1,1,1,1
endlayer

layer
23,9,9,9,9,9,9,9,9,9,0,0,9,9,9,9,9,9,9,9,9
23,11,11,11,11,11,11,11,11,0,0,0,0,11,11,11,11,11,11,22,25
23,21,0,0,0,0,0,0,0,0,0,0,0,0,0,0,0,0,0,22,25
23,21,0,18,0,0,0,0,0,0,0,0,0,0,0,0,0,18,0,22,25
23,21,0,0,0,0,0,0,0,0,0,0,0,0,0,0,0,0,0,22,25
23,21,0,0,0,0,0,0,0,0,0,0,0,0,0,0,0,0,0,22,25
23,21,0,0,0,0,0,0,0,0,0,0,0,0,0,0,0,0,0,22,25
23,21,0,0,0,0,0,0,0,0,0,0,0,0,0,0,0,0,0,22,25
23,21,0,0,0,0,0,0,0,0,0,0,0,0,0,0,0,0,0,22,25
23,21,0,0,0,0,0,0,0,0,0,0,0,0,0,0,0,0,0,22,25
23,21,0,0,0,0,0,0,0,0,0,0,0,0,0,0,0,0,0,22,25
23,21,0,0,0,0,0,0,0,0,0,0,0,0,0,0,0,0,0,22,25
23,21,0,0,0,0,0,0,0,0,0,0,4,0,0,0,0,0,0,22,25
23,21,0,0,0,0,0,0,0,0,0,0,0,0,0,0,0,0,0,22,25
23,21,0,0,0,0,0,0,0,0,0,0,0,0,0,0,0,0,0,22,25
23,21,0,0,0,0,0,0,0,0,0,0,0,0,0,0,0,0,0,22,25
23,21,0,0,0,0,0,0,0,0,0,0,0,0,0,0,0,0,0,22,25
23,21,0,18,0,0,0,0,0,0,0,0,0,0,0,0,0,18,0,22,25
23,21,0,0,0,0,0,0,0,0,0,0,0,0,0,0,0,0,0,22,25
23,13,13,13,13,13,13,13,13,13,13,13,13,13,13,13,13,13,13,13,25
17,17,17,17,17,17,17,17,17,17,17,17,17,17,17,17,17,17,17,17,17
endlayer

layer
27,27,27,27,27,27,27,27,27,27,27,27,27,27,27,27,27,27,27,27,27
27,23,9,9,9,9,9,9,0,0,0,0,0,0,9,9,9,9,9,9,27
27,23,21,11,11,11,0,0,0,0,0,0,0,0,0,11,11,11,22,25,27
27,23,21,7,0,0,0,0,0,0,0,0,0,0,0,0,0,7,22,25,27
27,23,21,0,0,0,0,0,0,0,0,0,0,0,0,0,0,0,22,25,27
27,23,21,0,0,0,0,0,0,0,0,0,0,0,0,0,0,0,22,25,27
27,23,0,0,0,0,0,0,0,0,0,0,0,0,0,0,0,0,0,25,27
27,23,0,0,0,0,0,0,0,0,0,0,0,0,0,0,0,0,0,25,27
27,23,0,0,0,0,0,0,0,0,0,0,0,0,0,0,0,0,0,25,27
27,23,0,0,0,0,0,0,0,0,0,0,0,0,0,0,0,0,0,25,27
27,23,0,0,0,0,0,0,0,0,0,0,0,0,0,0,0,0,0,25,27
27,23,0,0,0,0,0,0,0,0,0,0,0,0,0,0,0,0,0,25,27
27,23,0,0,0,0,0,0,0,0,0,0,0,0,0,0,0,0,0,25,27
27,23,0,0,0,0,0,0,0,0,0,0,0,0,0,0,0,0,0,25,27
27,23,0,0,0,0,0,0,0,0,0,0,0,0,0,0,0,0,0,25,27
27,23,21,0,0,0,0,0,0,0,0,0,0,0,0,0,0,0,22,25,27
27,23,21,0,0,0,0,0,0,0,0,0,0,0,0,0,0,0,22,25,27
27,23,21,7,0,0,0,0,0,0,0,0,0,0,0,0,0,7,22,25,27
27,23,21,13,13,13,0,0,0,0,0,0,0,0,0,13,13,13,13,25,27
27,23,17,17,17,17,17,17,17,17,17,17,17,17,17,17,17,17,17,25,27
27,27,27,27,27,27,27,27,27,27,27,27,27,27,27,27,27,27,27,27,27
endlayer

layer
27,27,27,27,27,27,27,27,27,27,27,27,27,27,27,27,27,27,27,27,27
27,27,27,27,27,27,27,27,27,27,27,27,27,27,27,27,27,27,27,27,27
27,27,9,9,9,9,0,0,0,0,0,0,0,0,0,9,0,9,9,27,27
27,27,23,7,11,11,0,0,0,0,0,0,0,0,0,11,0,7,25,27,27
27,27,23,21,0,0,0,0,0,0,0,0,0,0,0,0,0,22,25,27,27
27,27,23,21,0,0,0,0,0,0,0,0,0,0,0,0,0,0,25,27,27
27,27,27,27,27,27,27,0,0,0,0,0,0,0,0,0,0,0,28,27,27
27,27,27,27,27,27,27,0,0,0,0,0,0,0,0,0,0,0,28,27,27
27,27,27,27,27,27,27,0,0,0,0,0,0,0,0,0,0,0,28,27,27
27,27,27,27,27,27,27,0,0,0,0,0,0,0,0,0,0,0,28,27,27
27,27,27,27,27,27,27,0,0,0,0,0,0,0,0,0,0,0,28,27,27
27,27,27,27,27,27,27,0,0,0,0,0,0,0,0,0,0,0,28,27,27
27,27,27,27,27,27,27,0,0,0,0,0,0,0,0,0,0,0,28,27,27
27,27,27,27,27,27,27,0,0,0,0,0,0,0,0,0,0,0,28,27,27
27,27,27,27,27,27,27,0,0,0,0,0,0,0,0,0,0,0,28,27,27
27,27,23,21,0,0,0,0,0,0,0,0,0,0,0,0,0,22,25,27,27
27,27,23,21,0,0,0,0,0,0,0,0,0,0,0,0,0,22,25,27,27
27,27,23,7,13,13,0,0,0,0,0,0,0,0,0,13,13,7,25,27,27
27,27,17,17,17,17,28,28,28,28,28,28,28,28,28,17,17,17,25,27,27
27,27,27,27,27,27,27,27,27,27,27,27,27,27,27,27,27,27,27,27,27
27,27,27,27,27,27,27,27,27,27,27,27,27,27,27,27,27,27,27,27,27
endlayer

layer
27,27,27,27,27,27,27,27,27,27,27,27,27,27,27,27,27,27,27,27,27
27,27,27,27,27,27,27,27,27,27,27,27,27,27,27,27,27,27,27,27,27
27,27,27,27,27,27,27,27,27,27,27,27,27,27,27,27,27,27,27,27,27
27,27,27,9,9,9,9,0,0,0,0,0,0,0,0,0,0,9,27,27,27
27,27,27,23,11,11,11,0,0,0,0,0,0,0,0,0,0,25,27,27,27
27,27,27,23,21,0,0,0,0,0,0,0,0,0,0,0,0,0,27,27,27
27,27,27,23,21,0,0,0,0,0,0,0,0,0,0,0,0,0,27,27,27
27,27,27,27,27,27,27,0,0,0,0,0,0,0,0,0,0,0,27,27,27
27,27,27,27,27,27,27,0,0,0,0,0,0,0,0,0,0,0,27,27,27
27,27,27,27,27,27,27,0,0,0,0,0,0,0,0,0,0,0,27,27,27
27,27,27,27,27,27,27,0,0,0,0,0,0,0,0,0,0,28,27,27,27
27,27,27,27,27,27,27,0,0,0,0,0,0,0,0,0,0,28,27,27,27
27,27,27,27,27,27,27,0,0,0,0,0,0,0,0,0,0,28,27,27,27
27,27,27,27,27,27,27,0,0,0,0,0,0,0,0,0,0,28,27,27,27
27,27,27,23,21,0,0,0,0,0,0,0,0,0,0,0,22,25,27,27,27
27,27,27,23,21,0,0,0,0,0,0,0,0,0,0,0,22,25,27,27,27
27,27,27,23,21,13,13,0,0,0,0,0,0,0,13,13,22,25,27,27,27
27,27,27,17,17,17,17,28,28,28,28,28,28,28,17,17,17,25,27,27,27
27,27,27,27,27,27,27,27,27,27,27,27,27,27,27,27,27,27,27,27,27
27,27,27,27,27,27,27,27,27,27,27,27,27,27,27,27,27,27,27,27,27
27,27,27,27,27,27,27,27,27,27,27,27,27,27,27,27,27,27,27,27,27
endlayer

layer
27,27,27,27,27,27,27,27,27,27,27,27,27,27,27,27,27,27,27,27,27
27,27,27,27,27,27,27,27,27,27,27,27,27,27,27,27,27,27,27,27,27
27,27,27,27,27,27,27,27,27,27,27,27,27,27,27,27,27,27,27,27,27
27,27,27,27,27,27,27,27,27,27,27,27,27,27,27,27,27,27,27,27,27
27,27,27,27,23,9,9,9,27,27,27,27,27,27,27,27,27,27,27,27,27
27,27,27,27,23,21,11,0,27,27,27,27,27,27,27,27,27,27,27,27,27
27,27,27,27,23,0,0,0,27,27,27,27,27,27,27,27,27,27,27,27,27
27,27,27,27,23,21,0,0,27,27,27,27,27,27,27,27,27,27,27,27,27
27,27,27,27,27,27,27,0,27,27,27,27,27,27,27,27,27,27,27,27,27
27,27,27,27,27,27,27,0,27,27,27,27,27,27,27,27,27,27,27,27,27
27,27,27,27,27,27,27,0,27,27,27,27,27,27,27,27,27,27,27,27,27
27,27,27,27,27,27,27,0,27,27,27,27,27,27,27,27,28,27,27,27,27
27,27,27,27,27,27,27,0,27,27,27,27,27,27,27,27,28,27,27,27,27
27,27,27,27,23,21,27,0,27,27,27,27,27,27,27,22,25,27,27,27,27
27,27,27,27,23,21,0,0,0,0,0,0,0,0,0,22,25,27,27,27,27
27,27,27,27,23,21,13,13,0,0,0,0,0,13,13,13,25,27,27,27,27
27,27,27,27,17,17,17,17,28,28,28,28,28,17,17,17,17,27,27,27,27
27,27,27,27,27,27,27,27,27,27,27,27,27,27,27,27,27,27,27,27,27
27,27,27,27,27,27,27,27,27,27,27,27,27,27,27,27,27,27,27,27,27
27,27,27,27,27,27,27,27,27,27,27,27,27,27,27,27,27,27,27,27,27
27,27,27,27,27,27,27,27,27,27,27,27,27,27,27,27,27,27,27,27,27
endlayer

layer
27,27,27,27,27,27,27,27,27,27,27,27,27,27,27,27,27,27,27,27,27
27,27,27,27,27,27,27,27,27,27,27,27,27,27,27,27,27,27,27,27,27
27,27,27,27,27,27,27,27,27,27,27,27,27,27,27,27,27,27,27,27,27
27,27,27,27,27,27,27,27,27,27,27,27,27,27,27,27,27,27,27,27,27
27,27,27,27,27,27,27,27,27,27,27,27,27,27,27,27,27,27,27,27,27
27,27,27,27,27,27,9,27,27,27,27,27,27,27,27,27,27,27,27,27,27
27,27,27,27,27,27,27,27,27,27,27,27,27,27,27,27,27,27,27,27,27
27,27,27,27,27,23,27,27,27,27,27,27,27,27,27,27,27,27,27,27,27
27,27,27,27,27,23,21,27,27,27,27,27,27,27,27,27,27,27,27,27,27
27,27,27,27,27,27,27,27,27,27,27,27,27,27,27,27,27,27,27,27,27
27,27,27,27,27,27,27,27,27,27,27,27,27,27,27,27,27,27,27,27,27
27,27,27,27,27,27,27,27,27,27,27,27,27,27,27,28,27,27,27,27,27
27,27,27,27,27,23,21,27,27,27,27,27,27,27,22,25,27,27,27,27,27
27,27,27,27,27,23,21,27,27,27,27,27,27,27,22,25,27,27,27,27,27
27,27,27,27,27,23,13,13,13,0,0,0,13,13,22,25,27,27,27,27,27
27,27,27,27,27,23,17,17,17,28,28,28,17,17,17,25,27,27,27,27,27
27,27,27,27,27,27,27,27,27,27,27,27,27,27,27,27,27,27,27,27,27
27,27,27,27,27,27,27,27,27,27,27,27,27,27,27,27,27,27,27,27,27
27,27,27,27,27,27,27,27,27,27,27,27,27,27,27,27,27,27,27,27,27
27,27,27,27,27,27,27,27,27,27,27,27,27,27,27,27,27,27,27,27,27
27,27,27,27,27,27,27,27,27,27,27,27,27,27,27,27,27,27,27,27,27
endlayer

layer
27,27,27,27,27,27,27,27,27,27,27,27,27,27,27,27,27,27,27,27,27
27,27,27,27,27,27,27,27,27,27,27,27,27,27,27,27,27,27,27,27,27
27,27,27,27,27,27,27,27,27,27,27,27,27,27,27,27,27,27,27,27,27
27,27,27,27,27,27,27,27,27,27,27,27,27,27,27,27,27,27,27,27,27
27,27,27,27,27,27,27,27,27,27,27,27,27,27,27,27,27,27,27,27,27
27,27,27,27,27,27,27,27,27,27,27,27,27,27,27,27,27,27,27,27,27
27,27,27,27,27,27,27,27,27,27,27,27,27,27,27,27,27,27,27,27,27
27,27,27,27,27,27,27,27,27,27,27,27,27,27,27,27,27,27,27,27,27
27,27,27,27,27,27,23,27,27,27,27,27,27,27,27,27,27,27,27,27,27
27,27,27,27,27,27,23,21,27,27,27,27,27,27,27,27,27,27,27,27,27
27,27,27,27,27,27,27,21,27,27,27,27,27,27,27,27,27,27,27,27,27
27,27,27,27,27,27,23,21,27,27,27,27,27,27,25,27,27,27,27,27,27
27,27,27,27,27,27,23,21,27,27,27,27,27,27,25,27,27,27,27,27,27
27,27,27,27,27,27,23,13,13,13,13,13,27,27,25,27,27,27,27,27,27
27,27,27,27,27,27,17,17,17,17,28,17,17,17,17,27,27,27,27,27,27
27,27,27,27,27,27,27,27,27,27,27,27,27,27,27,27,27,27,27,27,27
27,27,27,27,27,27,27,27,27,27,27,27,27,27,27,27,27,27,27,27,27
27,27,27,27,27,27,27,27,27,27,27,27,27,27,27,27,27,27,27,27,27
27,27,27,27,27,27,27,27,27,27,27,27,27,27,27,27,27,27,27,27,27
27,27,27,27,27,27,27,27,27,27,27,27,27,27,27,27,27,27,27,27,27
27,27,27,27,27,27,27,27,27,27,27,27,27,27,27,27,27,27,27,27,27
endlayer

layer
27,27,27,27,27,27,27,27,27,27,27,27,27,27,27,27,27,27,27,27,27
27,27,27,27,27,27,27,27,27,27,27,27,27,27,27,27,27,27,27,27,27
27,27,27,27,27,27,27,27,27,27,27,27,27,27,27,27,27,27,27,27,27
27,27,27,27,27,27,27,27,27,27,27,27,27,27,27,27,27,27,27,27,27
27,27,27,27,27,27,27,27,27,27,27,27,27,27,27,27,27,27,27,27,27
27,27,27,27,27,27,27,27,27,27,27,27,27,27,27,27,27,27,27,27,27
27,27,27,27,27,27,27,27,27,27,27,27,27,27,27,27,27,27,27,27,27
27,27,27,27,27,27,27,27,27,27,27,27,27,27,27,27,27,27,27,27,27
27,27,27,27,27,27,27,27,27,27,27,27,27,27,27,27,27,27,27,27,27
27,27,27,27,27,27,27,27,27,27,27,27,27,27,27,27,27,27,27,27,27
27,27,27,27,27,27,27,27,27,27,27,27,27,27,27,27,27,27,27,27,27
27,27,27,27,27,27,27,23,21,27,27,27,27,27,27,27,27,27,27,27,27
27,27,27,27,27,27,27,23,13,13,13,27,27,27,27,27,27,27,27,27,27
27,27,27,27,27,27,27,23,17,17,17,27,27,27,27,27,27,27,27,27,27
27,27,27,27,27,27,27,27,27,27,27,27,27,27,27,27,27,27,27,27,27
27,27,27,27,27,27,27,27,27,27,27,27,27,27,27,27,27,27,27,27,27
27,27,27,27,27,27,27,27,27,27,27,27,27,27,27,27,27,27,27,27,27
27,27,27,27,27,27,27,27,27,27,27,27,27,27,27,27,27,27,27,27,27
27,27,27,27,27,27,27,27,27,27,27,27,27,27,27,27,27,27,27,27,27
27,27,27,27,27,27,27,27,27,27,27,27,27,27,27,27,27,27,27,27,27
27,27,27,27,27,27,27,27,27,27,27,27,27,27,27,27,27,27,27,27,27
endlayer

layer
27,27,27,27,27,27,27,27,27,27,27,27,27,27,27,27,27,27,27,27,27
27,27,27,27,27,27,27,27,27,27,27,27,27,27,27,27,27,27,27,27,27
27,27,27,27,27,27,27,27,27,27,27,27,27,27,27,27,27,27,27,27,27
27,27,27,27,27,27,27,27,27,27,27,27,27,27,27,27,27,27,27,27,27
27,27,27,27,27,27,27,27,27,27,27,27,27,27,27,27,27,27,27,27,27
27,27,27,27,27,27,27,27,27,27,27,27,27,27,27,27,27,27,27,27,27
27,27,27,27,27,27,27,27,27,27,27,27,27,27,27,27,27,27,27,27,27
27,27,27,27,27,27,27,27,27,27,27,27,27,27,27,27,27,27,27,27,27
27,27,27,27,27,27,27,27,27,27,27,27,27,27,27,27,27,27,27,27,27
27,27,27,27,27,27,27,27,27,27,27,27,27,27,27,27,27,27,27,27,27
27,27,27,27,27,27,27,27,27,27,27,27,27,27,27,27,27,27,27,27,27
27,27,27,27,27,27,27,0,0,27,27,27,27,27,27,27,27,27,27,27,27
27,27,27,27,27,27,27,0,17,17,0,27,27,27,27,27,27,27,27,27,27
27,27,27,27,27,27,27,0,0,0,0,27,27,27,27,27,27,27,27,27,27
27,27,27,27,27,27,27,27,27,27,27,27,27,27,27,27,27,27,27,27,27
27,27,27,27,27,27,27,27,27,27,27,27,27,27,27,27,27,27,27,27,27
27,27,27,27,27,27,27,27,27,27,27,27,27,27,27,27,27,27,27,27,27
27,27,27,27,27,27,27,27,27,27,27,27,27,27,27,27,27,27,27,27,27
27,27,27,27,27,27,27,27,27,27,27,27,27,27,27,27,27,27,27,27,27
27,27,27,27,27,27,27,27,27,27,27,27,27,27,27,27,27,27,27,27,27
27,27,27,27,27,27,27,27,27,27,27,27,27,27,27,27,27,27,27,27,27
endlayer

