# Gilly's Adobe tower

# template generated by Ruins mod version 14.6 Ingame Parser
# Structure created by Gilly

weight=1
embed_into_distance=5
acceptable_target_blocks=
unacceptable_target_blocks=flowing_water,water,flowing_lava,lava,ice,bedrock,netherrack,nether_brick,nether_brick_fence,soul_sand,quartz_ore,end_stone,obsidian,iron_bars,cloud,flesh,ash_block,slime_grass,slime_congealed,slime_dirt
dimensions=18,5,5
allowable_overhang=0
max_leveling=5
leveling_buffer=-1
preserve_water=0
preserve_lava=0

rule1=0,100,double_stone_slab-9
rule2=0,100,preserveBlock
rule3=0,100,sandstone-2
rule4=0,100,ladder-5
rule5=0,100,sandstone_stairs-0
rule6=0,100,sandstone_stairs-2
rule7=0,100,sandstone_stairs-3
rule8=0,100,sandstone_stairs-1
rule9=0,100,stone_slab-1
rule10=0,100,sandstone_stairs-4
rule11=0,100,sandstone_stairs-6
rule12=0,100,sandstone_stairs-7
rule13=0,100,sandstone_stairs-5
rule14=0,100,fence-0
rule15=0,100,wooden_slab-1
rule16=0,100,spruce_stairs-4
rule17=0,100,spruce_stairs-6
rule18=0,100,hay_block-0
rule19=0,100,spruce_stairs-7
rule20=0,100,spruce_stairs-5

layer
1,1,1,1,1
1,2,2,2,1
1,2,2,2,1
1,2,2,2,1
1,1,1,1,1
endlayer

layer
1,1,1,1,1
1,2,2,2,1
1,2,2,2,1
1,2,2,2,1
1,1,1,1,1
endlayer

layer
1,1,1,1,1
1,2,2,2,1
1,2,2,2,1
1,2,2,2,1
1,1,1,1,1
endlayer

layer
1,1,1,1,1
1,2,2,2,1
1,2,2,2,1
1,2,2,2,1
1,1,1,1,1
endlayer

layer
3,1,1,1,3
1,1,1,1,1
1,1,1,1,1
1,1,1,1,1
3,3,3,3,3
endlayer

layer
1,1,1,1,1
1,0,4,0,1
1,0,0,0,1
1,0,0,0,1
1,3,0,3,1
endlayer

layer
3,1,1,1,3
1,0,4,0,1
0,0,0,0,0
1,0,0,0,1
3,3,0,3,3
endlayer

layer
1,1,1,1,1
1,0,4,0,1
1,0,0,0,1
1,0,0,0,1
1,1,3,1,1
endlayer

layer
1,1,1,1,1
1,0,4,0,1
1,0,0,0,1
1,0,0,0,1
1,1,1,1,1
endlayer

layer
3,5,3,5,3
7,0,4,0,6
3,0,0,0,3
7,0,0,0,6
3,8,3,8,3
endlayer

layer
9,1,1,1,9
1,0,4,0,1
1,0,0,0,1
1,0,0,0,1
9,1,1,1,9
endlayer

layer
0,1,3,1,0
1,0,4,0,1
3,0,0,0,3
1,0,0,0,1
0,1,3,1,0
endlayer

layer
0,10,1,10,0
12,0,4,0,11
1,0,0,0,1
12,0,0,0,11
0,13,1,13,0
endlayer

layer
12,10,3,10,11
12,1,4,1,11
3,1,1,1,3
12,1,1,1,11
12,13,3,13,11
endlayer

layer
3,8,8,8,3
6,0,0,0,7
6,0,0,0,7
6,0,0,0,7
3,5,5,5,3
endlayer

layer
14,0,0,0,14
0,0,0,0,0
0,0,0,0,0
0,0,0,0,0
14,0,0,0,14
endlayer

layer
14,0,0,0,14
0,0,0,0,0
0,0,0,0,0
0,0,0,0,0
14,0,0,0,14
endlayer

layer
15,16,16,16,15
19,18,18,18,17
19,18,14,18,17
19,18,18,18,17
15,20,20,20,15
endlayer

