
# Created by Ruins mod version 16.7 Ingame Parser
# authoring Player: lafuller

weight=1
embed_into_distance=5
acceptable_target_blocks=
unacceptable_target_blocks=flowing_water,water,flowing_lava,lava,ice,bedrock,netherrack,nether_brick,nether_brick_fence,soul_sand,quartz_ore,gravel,end_stone,obsidian,iron_bars,cloud,flesh,ash_block,slime_grass,slime_congealed,slime_dirt
dimensions=25,25,25
allowable_overhang=0
max_leveling=5
leveling_buffer=-1
preserve_water=0
preserve_lava=0

rule1=0,100,preserveBlock
rule2=0,100,minecraft:sandstone-2
rule3=0,100,minecraft:sandstone_stairs-1
rule4=0,100,minecraft:sandstone_stairs-3
rule5=0,100,minecraft:sandstone_stairs-2
rule6=0,100,minecraft:sandstone_stairs-0
rule7=0,100,minecraft:cobblestone_wall-0
rule8=0,100,minecraft:double_stone_slab-9
rule9=0,100,minecraft:stone-5
rule10=0,100,minecraft:stone-6
rule11=0,100,minecraft:stained_hardened_clay-3
rule12=0,100,minecraft:stone_slab-1
rule13=0,100,minecraft:sandstone-1
rule14=0,100,minecraft:sandstone_stairs-7
rule15=0,100,minecraft:stone_slab-9
rule16=0,100,minecraft:sandstone_stairs-6
rule17=0,100,minecraft:sandstone_stairs-5
rule18=0,100,minecraft:sandstone_stairs-4
rule19=0,100,minecraft:spruce_fence-0
rule20=0,100,minecraft:spruce_fence_gate-3
rule21=0,100,minecraft:spruce_fence_gate-0
rule22=0,100,minecraft:sea_lantern-0
rule23=0,100,minecraft:double_stone_slab-1

layer
2,2,2,2,2,2,2,2,2,2,2,2,2,2,2,2,2,2,2,2,2,2,2,2,2
2,2,2,2,2,2,2,2,2,2,2,2,2,2,2,2,2,2,2,2,2,2,2,2,2
2,2,2,2,2,2,2,2,2,2,2,2,2,2,2,2,2,2,2,2,2,2,2,2,2
2,2,2,2,2,2,2,2,2,2,2,2,2,2,2,2,2,2,2,2,2,2,2,2,2
2,2,2,2,2,3,3,2,2,2,2,2,2,2,2,2,2,2,3,3,2,2,2,2,2
2,2,2,2,5,0,0,4,2,2,2,2,2,2,2,2,2,5,0,0,4,2,2,2,2
2,2,2,2,5,0,0,4,2,2,2,2,2,2,2,2,2,5,0,0,4,2,2,2,2
2,2,2,2,2,6,6,4,2,2,2,2,2,2,2,2,2,6,6,6,2,2,2,2,2
2,2,2,2,2,2,2,2,2,2,2,2,2,2,2,2,2,2,2,2,2,2,2,2,2
2,2,2,2,2,2,2,2,2,2,7,7,7,7,7,2,2,2,2,2,2,2,2,2,2
2,2,2,2,2,2,2,2,2,7,7,7,7,7,7,7,2,2,2,2,2,2,2,2,2
2,2,2,2,2,2,2,2,2,7,7,7,7,7,7,7,2,2,2,2,2,2,2,2,2
2,2,2,2,2,2,2,2,2,7,7,7,7,7,7,7,2,2,2,2,2,2,2,2,2
2,2,2,2,2,2,2,2,2,7,7,7,7,7,7,7,2,2,2,2,2,2,2,2,2
2,2,2,2,2,2,2,2,2,7,7,7,7,7,7,7,2,2,2,2,2,2,2,2,2
2,2,2,2,2,2,2,2,2,2,7,7,7,7,7,2,2,2,2,2,2,2,2,2,2
2,2,2,2,2,2,2,2,2,2,2,2,2,2,2,2,2,2,2,2,2,2,2,2,2
2,2,2,2,2,3,3,3,2,2,2,2,2,2,2,2,2,5,3,3,2,2,2,2,2
2,2,2,2,5,0,0,4,2,2,2,2,2,2,2,2,2,5,0,0,4,2,2,2,2
2,2,2,2,5,0,0,4,2,2,2,2,2,2,2,2,2,5,0,0,4,2,2,2,2
2,2,2,2,2,6,6,2,2,2,2,2,2,2,2,2,2,2,6,6,2,2,2,2,2
2,2,2,2,2,2,2,2,2,2,2,2,2,2,2,2,2,2,2,2,2,2,2,2,2
2,2,2,2,2,2,2,2,2,2,2,2,2,2,2,2,2,2,2,2,2,2,2,2,2
2,2,2,2,2,2,2,2,2,2,2,2,2,2,2,2,2,2,2,2,2,2,2,2,2
2,2,2,2,2,2,2,2,2,2,2,2,2,2,2,2,2,2,2,2,2,2,2,2,2
endlayer

layer
8,2,2,2,2,2,2,2,2,2,2,6,6,6,2,2,2,2,2,2,2,2,2,2,8
2,2,2,2,2,2,2,2,2,2,2,2,2,2,2,2,2,2,2,2,2,2,2,2,2
2,2,9,10,10,9,11,10,2,2,2,2,2,2,2,2,2,10,11,9,10,9,9,2,2
2,2,10,8,0,0,0,0,8,2,2,2,2,2,2,2,8,0,0,0,0,8,9,2,2
2,2,10,0,0,0,0,0,2,2,2,2,2,2,2,2,2,0,0,0,0,0,10,2,2
2,2,9,0,0,0,0,0,4,2,2,2,2,2,2,2,5,0,0,0,0,0,9,2,2
2,2,11,0,0,0,0,0,4,2,2,2,2,2,2,2,5,0,0,0,0,0,11,2,2
2,2,10,0,0,0,0,0,4,2,2,2,2,2,2,2,5,0,0,0,0,0,10,2,2
2,2,2,8,2,6,6,6,4,8,2,2,2,2,2,8,6,6,6,6,2,8,2,2,2
2,2,2,2,2,2,2,2,8,8,1,1,1,1,1,8,8,2,2,2,2,2,2,2,2
2,2,2,2,2,2,2,2,2,1,1,1,1,1,1,1,2,2,2,2,2,2,2,2,2
4,2,2,2,2,2,2,2,2,1,1,1,1,1,1,1,2,2,2,2,2,2,2,2,5
4,2,2,2,2,2,2,2,2,1,1,1,1,1,1,1,2,2,2,2,2,2,2,2,5
4,2,2,2,2,2,2,2,2,1,1,1,1,1,1,1,2,2,2,2,2,2,2,2,5
2,2,2,2,2,2,2,2,2,1,1,1,1,1,1,1,2,2,2,2,2,2,2,2,2
2,2,2,2,2,2,2,2,8,8,1,1,1,1,1,8,8,2,2,2,2,2,2,2,2
2,2,2,8,2,3,3,3,3,8,2,2,2,2,2,8,5,3,3,3,2,8,2,2,2
2,2,10,0,0,0,0,0,4,2,2,2,2,2,2,2,5,0,0,0,0,0,10,2,2
2,2,11,0,0,0,0,0,4,2,2,2,2,2,2,2,5,0,0,0,0,0,11,2,2
2,2,9,0,0,0,0,0,4,2,2,2,2,2,2,2,5,0,0,0,0,0,9,2,2
2,2,10,0,0,0,0,0,2,2,2,2,2,2,2,2,2,0,0,0,0,0,10,2,2
2,2,9,8,0,0,0,0,8,2,2,2,2,2,2,2,8,0,0,0,0,8,9,2,2
2,2,9,9,10,9,11,10,2,2,2,2,2,2,2,2,2,10,11,9,10,9,9,2,2
2,2,2,2,2,2,2,2,2,2,2,2,2,2,2,2,2,2,2,2,2,2,2,2,2
8,2,2,2,2,2,2,2,2,2,2,3,3,3,2,2,2,2,2,2,2,2,2,2,8
endlayer

layer
8,5,1,1,1,1,1,1,1,2,8,1,1,1,8,2,1,1,1,1,1,1,1,4,8
3,2,2,4,5,4,5,4,2,2,2,6,6,6,2,2,2,5,4,5,4,5,2,2,3
1,2,1,9,10,9,9,11,2,2,2,2,2,2,2,2,2,11,9,9,10,9,1,2,1
1,6,9,8,3,3,12,12,8,2,2,2,2,2,2,2,8,12,12,3,3,8,9,6,1
1,3,10,5,0,0,0,0,4,2,2,3,3,3,2,2,5,0,0,0,0,4,10,3,1
1,6,9,5,0,0,0,0,0,3,2,12,12,12,2,3,0,0,0,0,0,4,9,6,1
1,3,9,12,0,0,0,0,0,0,12,12,12,12,12,0,0,0,0,0,0,12,9,3,1
1,6,11,12,0,0,0,0,0,0,0,0,0,0,0,0,0,0,0,0,0,12,11,6,1
1,2,2,8,6,0,0,0,0,0,0,0,0,0,0,0,0,0,0,0,6,8,2,2,1
2,2,2,2,2,5,0,0,0,0,0,0,0,0,0,0,0,0,0,4,2,2,2,2,2
8,2,2,2,2,2,12,0,0,0,0,0,0,0,0,0,0,0,12,2,2,2,2,2,8
1,4,2,2,2,12,12,0,0,0,0,0,0,0,0,0,0,0,12,12,4,2,2,5,1
1,4,2,2,2,12,12,0,0,0,0,0,0,0,0,0,0,0,12,12,4,2,2,5,1
1,4,2,2,2,12,12,0,0,0,0,0,0,0,0,0,0,0,12,12,4,2,2,5,1
8,2,2,2,2,2,12,0,0,0,0,0,0,0,0,0,0,0,12,2,2,2,2,2,8
2,2,2,2,2,5,0,0,0,0,0,0,0,0,0,0,0,0,0,4,2,2,2,2,2
1,2,2,8,3,0,0,0,0,0,0,0,0,0,0,0,0,0,0,0,3,8,2,2,1
1,3,11,12,0,0,0,0,0,0,0,0,0,0,0,0,0,0,0,0,0,12,11,3,1
1,6,9,12,0,0,0,0,0,0,12,12,12,12,12,0,0,0,0,0,0,12,9,6,1
1,3,9,5,0,0,0,0,0,6,2,12,12,12,2,6,0,0,0,0,0,4,9,3,1
1,6,10,5,0,0,0,0,4,2,2,6,6,6,2,2,5,0,0,0,0,4,10,6,1
1,3,9,8,6,6,12,12,8,2,2,2,2,2,2,2,8,12,12,6,6,8,9,3,1
1,2,1,9,10,9,9,11,2,2,2,2,2,2,2,2,2,11,9,9,10,9,1,2,1
6,2,2,4,5,4,5,4,2,2,2,3,3,3,2,2,2,5,4,5,4,5,2,2,6
8,5,1,1,1,1,1,1,1,2,8,1,1,1,8,2,1,1,1,1,1,1,1,4,8
endlayer

layer
13,1,1,1,1,1,1,1,1,2,8,1,1,1,8,2,1,1,1,1,1,1,1,1,13
1,2,2,1,16,15,16,1,2,2,2,1,1,1,2,2,2,1,14,15,14,1,2,2,1
1,2,1,9,10,9,9,10,2,2,2,6,6,6,2,2,2,10,9,9,10,9,1,2,1
1,1,9,13,0,0,0,0,8,2,2,3,3,3,2,2,8,0,0,0,0,13,9,1,1
1,17,10,0,0,0,0,0,17,2,5,0,0,0,4,2,17,0,0,0,0,0,10,17,1
1,15,9,0,0,0,0,0,0,17,0,0,0,0,0,17,0,0,0,0,0,0,9,15,1
1,17,9,0,0,0,0,0,0,0,0,0,0,0,0,0,0,0,0,0,0,0,9,17,1
1,1,10,0,0,0,0,0,0,0,0,0,0,0,0,0,0,0,0,0,0,0,10,1,1
1,2,2,8,16,0,0,0,0,0,0,0,0,0,0,0,0,0,0,0,14,8,2,2,1
2,2,2,2,2,16,0,0,0,0,0,0,0,0,0,0,0,0,0,14,2,2,2,2,2
8,2,2,2,3,0,0,0,0,0,0,0,0,0,0,0,0,0,0,0,3,2,2,2,8
1,1,4,5,0,0,0,0,0,0,0,0,0,0,0,0,0,0,0,0,0,4,5,1,1
1,1,4,5,0,0,0,0,0,0,0,0,0,0,0,0,0,0,0,0,0,4,5,1,1
1,1,4,5,0,0,0,0,0,0,0,0,0,0,0,0,0,0,0,0,0,4,5,1,1
8,2,2,2,6,0,0,0,0,0,0,0,0,0,0,0,0,0,0,0,6,2,2,2,8
2,2,2,2,2,16,0,0,0,0,0,0,0,0,0,0,0,0,0,14,2,2,2,2,2
1,2,2,8,16,0,0,0,0,0,0,0,0,0,0,0,0,0,0,0,14,8,2,2,1
1,1,10,0,0,0,0,0,0,0,0,0,0,0,0,0,0,0,0,0,0,0,10,1,1
1,18,9,0,0,0,0,0,0,0,0,0,0,0,0,0,0,0,0,0,0,0,9,18,1
1,15,9,0,0,0,0,0,0,18,0,0,0,0,0,18,0,0,0,0,0,0,9,15,1
1,18,10,0,0,0,0,0,18,2,5,0,0,0,4,2,18,0,0,0,0,0,10,18,1
1,1,9,13,0,0,0,0,8,2,2,6,6,6,2,2,8,0,0,0,0,13,9,1,1
1,2,1,9,10,9,9,10,2,2,2,3,3,3,2,2,2,10,9,9,10,9,1,2,1
1,2,2,1,16,15,16,1,2,2,2,1,1,1,2,2,2,1,14,15,14,1,2,2,1
13,1,1,1,1,1,1,1,1,2,8,1,1,1,8,2,1,1,1,1,1,1,1,1,13
endlayer

layer
1,1,1,1,1,1,1,1,1,2,8,1,1,1,8,2,1,1,1,1,1,1,1,1,1
1,2,2,12,4,1,4,12,2,2,2,1,1,1,2,2,2,12,5,1,5,12,2,2,1
1,2,2,9,11,9,9,10,2,2,2,1,1,1,2,2,2,10,9,9,11,9,2,2,1
1,12,9,8,15,15,17,17,2,2,5,0,0,0,4,2,2,17,17,15,15,8,9,12,1
1,6,11,15,0,0,0,0,4,16,0,0,0,0,0,14,5,0,0,0,0,15,11,6,1
1,1,9,15,0,0,0,0,14,5,0,0,0,0,0,4,16,0,0,0,0,15,9,1,1
1,6,9,16,0,0,0,0,0,0,0,0,0,0,0,0,0,0,0,0,0,14,9,6,1
1,12,10,16,0,0,0,0,0,0,0,0,0,0,0,0,0,0,0,0,0,14,10,12,1
1,2,2,2,6,18,0,0,0,0,0,0,0,0,0,0,0,0,0,18,6,2,2,2,1
2,2,2,2,17,3,0,0,0,0,0,0,0,0,0,0,0,0,0,3,17,2,2,2,2
8,2,2,3,0,0,0,0,0,0,0,0,0,0,0,0,0,0,0,0,0,3,2,2,8
1,1,1,0,0,0,0,0,0,0,0,0,0,0,0,0,0,0,0,0,0,0,1,1,1
1,1,1,0,0,0,0,0,0,0,0,0,0,0,0,0,0,0,0,0,0,0,1,1,1
1,1,1,0,0,0,0,0,0,0,0,0,0,0,0,0,0,0,0,0,0,0,1,1,1
8,2,2,6,0,0,0,0,0,0,0,0,0,0,0,0,0,0,0,0,0,6,2,2,8
2,2,2,2,18,6,0,0,0,0,0,0,0,0,0,0,0,0,0,6,18,2,2,2,2
1,2,2,2,3,17,0,0,0,0,0,0,0,0,0,0,0,0,0,17,3,2,2,2,1
1,12,10,16,0,0,0,0,0,0,0,0,0,0,0,0,0,0,0,0,0,14,10,12,1
1,3,9,16,0,0,0,0,0,0,0,0,0,0,0,0,0,0,0,0,0,14,9,3,1
1,1,9,15,0,0,0,0,14,5,0,0,0,0,0,4,16,0,0,0,0,15,9,1,1
1,3,11,15,0,0,0,0,4,16,0,0,0,0,0,14,5,0,0,0,0,15,11,3,1
1,12,9,8,15,15,18,18,2,2,5,0,0,0,4,2,2,18,18,15,15,8,9,12,1
1,2,2,9,11,9,9,10,2,2,2,1,1,1,2,2,2,10,9,9,11,9,2,2,1
1,2,2,12,4,1,4,12,2,2,2,1,1,1,2,2,2,12,5,1,5,12,2,2,1
1,1,1,1,1,1,1,1,1,2,8,1,1,1,8,2,1,1,1,1,1,1,1,1,1
endlayer

layer
1,1,1,1,1,1,1,1,1,2,13,1,1,1,13,2,1,1,1,1,1,1,1,1,1
1,8,8,8,8,8,8,8,8,2,8,1,1,1,8,2,8,8,8,8,8,8,8,8,1
1,8,2,10,10,11,9,10,2,8,0,0,0,0,0,8,2,10,10,11,10,10,2,8,1
1,8,10,10,12,12,0,0,2,0,0,0,0,0,0,0,2,0,0,12,12,10,10,8,1
1,8,10,12,0,0,0,0,18,6,0,0,0,0,0,6,18,0,0,0,0,12,10,8,1
1,8,11,12,0,0,0,0,3,17,0,0,0,0,0,17,3,0,0,0,0,12,11,8,1
1,8,9,0,0,0,0,0,0,0,0,0,0,0,0,0,0,0,0,0,0,0,10,8,1
1,8,10,0,0,0,0,0,0,0,0,0,0,0,0,0,0,0,0,0,0,0,10,8,1
1,8,2,2,14,5,0,0,0,0,0,0,0,0,0,0,0,0,0,4,16,2,2,8,1
2,2,8,0,4,16,0,0,0,0,0,0,0,0,0,0,0,0,0,14,5,0,8,2,2
13,8,0,0,0,0,0,0,0,0,0,0,0,0,0,0,0,0,0,0,0,0,0,8,13
1,1,0,0,0,0,0,0,0,0,0,0,0,0,0,0,0,0,0,0,0,0,0,1,1
1,1,0,0,0,0,0,0,0,0,0,0,0,0,0,0,0,0,0,0,0,0,0,1,1
1,1,0,0,0,0,0,0,0,0,0,0,0,0,0,0,0,0,0,0,0,0,0,1,1
13,8,0,0,0,0,0,0,0,0,0,0,0,0,0,0,0,0,0,0,0,0,0,8,13
2,2,8,0,4,16,0,0,0,0,0,0,0,0,0,0,0,0,0,14,5,0,8,2,2
1,8,2,2,14,5,0,0,0,0,0,0,0,0,0,0,0,0,0,4,16,2,2,8,1
1,8,10,0,0,0,0,0,0,0,0,0,0,0,0,0,0,0,0,0,0,0,10,8,1
1,8,10,0,0,0,0,0,0,0,0,0,0,0,0,0,0,0,0,0,0,0,10,8,1
1,8,11,12,0,0,0,0,6,18,0,0,0,0,0,18,6,0,0,0,0,12,11,8,1
1,8,10,12,0,0,0,0,17,3,0,0,0,0,0,3,17,0,0,0,0,12,10,8,1
1,8,10,10,12,12,0,0,2,0,0,0,0,0,0,0,2,0,0,12,12,10,10,8,1
1,8,2,10,10,11,10,10,2,8,0,0,0,0,0,8,2,10,10,11,10,10,2,8,1
1,8,8,8,8,8,8,8,8,2,8,1,1,1,8,2,8,8,8,8,8,8,8,8,1
1,1,1,1,1,1,1,1,1,2,13,1,1,1,13,2,1,1,1,1,1,1,1,1,1
endlayer

layer
1,1,1,1,1,1,1,1,1,1,8,1,1,1,8,1,1,1,1,1,1,1,1,1,1
1,8,5,1,1,1,1,1,1,2,8,0,0,0,8,2,1,1,1,1,1,1,4,8,1
1,3,2,16,1,16,1,4,2,5,0,0,0,0,0,4,2,5,1,14,1,14,2,3,1
1,1,17,9,10,9,9,10,2,0,0,0,0,0,0,0,2,10,9,9,10,9,17,1,1
1,1,1,10,0,0,15,17,2,16,0,0,0,0,0,14,2,17,15,0,0,10,1,1,1
1,1,17,9,0,0,0,0,14,12,0,0,0,0,0,12,16,0,0,0,0,9,17,1,1
1,1,1,9,15,0,0,0,0,0,0,0,0,0,0,0,0,0,0,0,15,9,1,1,1
1,1,6,10,16,0,0,0,0,0,0,0,0,0,0,0,0,0,0,0,14,10,6,1,1
1,1,2,2,2,18,0,0,0,0,0,0,0,0,0,0,0,0,0,18,2,2,2,1,1
1,2,3,0,17,12,0,0,0,0,0,0,0,0,0,0,0,0,0,12,17,0,3,2,1
8,8,0,0,0,0,0,0,0,0,0,0,0,0,0,0,0,0,0,0,0,0,0,8,8
1,0,0,0,0,0,0,0,0,0,0,0,0,0,0,0,0,0,0,0,0,0,0,0,1
1,0,0,0,0,0,0,0,0,0,0,0,0,0,0,0,0,0,0,0,0,0,0,0,1
1,0,0,0,0,0,0,0,0,0,0,0,0,0,0,0,0,0,0,0,0,0,0,0,1
8,8,0,0,0,0,0,0,0,0,0,0,0,0,0,0,0,0,0,0,0,0,0,8,8
1,2,6,0,18,12,0,0,0,0,0,0,0,0,0,0,0,0,0,12,18,0,6,2,1
1,1,2,2,2,17,0,0,0,0,0,0,0,0,0,0,0,0,0,17,2,2,2,1,1
1,1,3,10,16,0,0,0,0,0,0,0,0,0,0,0,0,0,0,0,14,10,3,1,1
1,1,1,9,15,0,0,0,0,0,0,0,0,0,0,0,0,0,0,0,15,9,1,1,1
1,1,18,9,0,0,0,0,14,12,0,0,0,0,0,12,16,0,0,0,0,9,18,1,1
1,1,1,10,0,0,15,18,2,16,0,0,0,0,0,14,2,18,15,0,0,10,1,1,1
1,1,18,9,10,9,9,10,2,0,0,0,0,0,0,0,2,10,9,9,10,9,18,1,1
1,6,2,16,1,16,1,4,2,5,0,0,0,0,0,4,2,5,1,14,1,14,2,6,1
1,8,5,1,1,1,1,1,1,2,8,0,0,0,8,2,1,1,1,1,1,1,4,8,1
1,1,1,1,1,1,1,1,1,1,8,1,1,1,8,1,1,1,1,1,1,1,1,1,1
endlayer

layer
1,1,1,1,1,1,1,1,1,1,8,1,1,1,8,1,1,1,1,1,1,1,1,1,1
1,13,1,1,1,1,1,1,1,2,8,0,0,0,8,2,1,1,1,1,1,1,1,13,1
1,1,2,5,12,4,12,12,2,0,0,0,0,0,0,0,2,12,12,5,12,4,2,1,1
1,1,3,9,11,9,9,10,2,0,0,0,0,0,0,0,2,10,9,9,11,9,3,1,1
1,1,12,11,12,12,0,0,14,6,0,0,0,0,0,6,16,0,0,12,12,11,12,1,1
1,1,6,9,12,0,0,0,0,17,0,0,0,0,0,17,0,0,0,0,12,9,6,1,1
1,1,12,9,0,0,0,0,0,0,0,0,0,0,0,0,0,0,0,0,0,9,12,1,1
1,1,12,10,0,0,0,0,0,0,0,0,0,0,0,0,0,0,0,0,0,10,12,1,1
1,1,2,2,18,0,0,0,0,0,0,0,0,0,0,0,0,0,0,0,18,2,2,1,1
1,2,0,0,4,16,0,0,0,0,0,0,0,0,0,0,0,0,0,14,5,0,0,2,1
8,8,0,0,0,0,0,0,0,0,0,0,0,0,0,0,0,0,0,0,0,0,0,8,8
1,0,0,0,0,0,0,0,0,0,0,0,0,0,0,0,0,0,0,0,0,0,0,0,1
1,0,0,0,0,0,0,0,0,0,0,0,0,0,0,0,0,0,0,0,0,0,0,0,1
1,0,0,0,0,0,0,0,0,0,0,0,0,0,0,0,0,0,0,0,0,0,0,0,1
8,8,0,0,0,0,0,0,0,0,0,0,0,0,0,0,0,0,0,0,0,0,0,8,8
1,2,0,0,4,16,0,0,0,0,0,0,0,0,0,0,0,0,0,14,5,0,0,2,1
1,1,2,2,17,0,0,0,0,0,0,0,0,0,0,0,0,0,0,0,17,2,2,1,1
1,1,12,10,0,0,0,0,0,0,0,0,0,0,0,0,0,0,0,0,0,10,12,1,1
1,1,12,9,0,0,0,0,0,0,0,0,0,0,0,0,0,0,0,0,0,9,12,1,1
1,1,3,9,12,0,0,0,0,18,0,0,0,0,0,18,0,0,0,0,12,9,3,1,1
1,1,12,11,12,12,0,0,14,3,0,0,0,0,0,3,16,0,0,12,12,11,12,1,1
1,1,6,9,11,9,9,10,2,0,0,0,0,0,0,0,2,10,9,9,11,9,6,1,1
1,1,2,5,12,4,12,12,2,0,0,0,0,0,0,0,2,12,12,5,12,4,2,1,1
1,13,1,1,1,1,1,1,1,2,8,0,0,0,8,2,1,1,1,1,1,1,1,13,1
1,1,1,1,1,1,1,1,1,1,8,1,1,1,8,1,1,1,1,1,1,1,1,1,1
endlayer

layer
1,1,1,1,1,1,1,1,1,1,8,1,1,1,8,1,1,1,1,1,1,1,1,1,1
1,1,1,1,1,1,1,1,1,2,8,0,0,0,8,2,1,1,1,1,1,1,1,1,1
1,1,8,8,8,8,8,8,8,17,0,0,0,0,0,17,8,8,8,8,8,8,8,1,1
1,1,8,9,10,9,9,10,2,0,0,0,0,0,0,0,2,10,9,9,10,9,8,1,1
1,1,8,10,10,15,14,17,2,16,0,0,0,0,0,14,2,17,16,15,10,10,8,1,1
1,1,8,9,15,0,0,15,14,12,0,0,0,0,0,12,16,15,0,0,15,9,8,1,1
1,1,8,9,18,0,0,0,0,0,0,0,0,0,0,0,0,0,0,0,18,9,8,1,1
1,1,8,10,16,15,0,0,0,0,0,0,0,0,0,0,0,0,0,15,14,10,8,1,1
1,1,8,2,2,18,0,0,0,0,0,0,0,0,0,0,0,0,0,18,2,2,8,1,1
1,2,16,0,17,12,0,0,0,0,0,0,0,0,0,0,0,0,0,12,17,0,14,2,1
8,8,0,0,0,0,0,0,0,0,0,0,0,0,0,0,0,0,0,0,0,0,0,8,8
1,0,0,0,0,0,0,0,0,0,0,0,0,0,0,0,0,0,0,0,0,0,0,0,1
1,0,0,0,0,0,0,0,0,0,0,0,0,0,0,0,0,0,0,0,0,0,0,0,1
1,0,0,0,0,0,0,0,0,0,0,0,0,0,0,0,0,0,0,0,0,0,0,0,1
8,8,0,0,0,0,0,0,0,0,0,0,0,0,0,0,0,0,0,0,0,0,0,8,8
1,2,16,0,18,12,0,0,0,0,0,0,0,0,0,0,0,0,0,12,18,0,14,2,1
1,1,8,2,2,17,0,0,0,0,0,0,0,0,0,0,0,0,0,17,2,2,8,1,1
1,1,8,10,16,15,0,0,0,0,0,0,0,0,0,0,0,0,0,15,14,10,8,1,1
1,1,8,9,17,0,0,0,0,0,0,0,0,0,0,0,0,0,0,0,17,9,8,1,1
1,1,8,9,15,0,0,15,14,12,0,0,0,0,0,12,16,15,0,0,15,9,8,1,1
1,1,8,10,10,15,14,18,2,16,0,0,0,0,0,14,5,18,16,15,10,10,8,1,1
1,1,8,9,10,9,9,10,2,0,0,0,0,0,0,0,2,10,9,9,10,9,8,1,1
1,1,8,8,8,8,8,8,8,18,0,0,0,0,0,18,8,8,8,8,8,8,8,1,1
1,1,1,1,1,1,1,1,1,2,8,0,0,0,8,2,1,1,1,1,1,1,1,1,1
1,1,1,1,1,1,1,1,1,1,8,1,1,1,8,1,1,1,1,1,1,1,1,1,1
endlayer

layer
1,1,1,1,1,1,1,1,1,1,8,1,1,1,8,1,1,1,1,1,1,1,1,1,1
1,1,1,1,1,1,1,1,1,1,8,0,0,0,8,1,1,1,1,1,1,1,1,1,1
1,1,8,5,1,1,1,1,2,13,0,0,0,0,0,13,2,1,1,1,1,4,8,1,1
1,1,3,2,14,15,14,15,2,0,0,0,0,0,0,0,2,15,16,15,16,2,3,1,1
1,1,1,18,10,10,10,11,14,6,0,0,0,0,0,6,16,11,10,10,10,18,1,1,1
1,1,1,15,10,2,5,12,0,17,0,0,0,0,0,17,0,12,4,2,10,15,1,1,1
1,1,1,18,10,3,0,0,0,0,0,0,0,0,0,0,0,0,0,3,10,18,1,1,1
1,1,1,15,11,12,0,0,0,0,0,0,0,0,0,0,0,0,0,12,11,15,1,1,1
1,1,2,2,18,0,0,0,0,0,0,0,0,0,0,0,0,0,0,0,18,2,2,1,1
1,1,13,0,4,16,0,0,0,0,0,0,0,0,0,0,0,0,0,14,5,0,13,1,1
8,8,0,0,0,0,0,0,0,0,0,0,0,0,0,0,0,0,0,0,0,0,0,8,8
1,0,0,0,0,0,0,0,0,0,0,0,0,0,0,0,0,0,0,0,0,0,0,0,1
1,0,0,0,0,0,0,0,0,0,0,0,0,0,0,0,0,0,0,0,0,0,0,0,1
1,0,0,0,0,0,0,0,0,0,0,0,0,0,0,0,0,0,0,0,0,0,0,0,1
8,8,0,0,0,0,0,0,0,0,0,0,0,0,0,0,0,0,0,0,0,0,0,8,8
1,1,13,0,4,16,0,0,0,0,0,0,0,0,0,0,0,0,0,14,5,0,13,1,1
1,1,2,2,17,0,0,0,0,0,0,0,0,0,0,0,0,0,0,0,17,2,2,1,1
1,1,1,15,11,12,0,0,0,0,0,0,0,0,0,0,0,0,0,12,11,15,1,1,1
1,1,1,17,10,6,0,0,0,0,0,0,0,0,0,0,0,0,0,6,10,17,1,1,1
1,1,1,15,10,2,5,12,0,18,0,0,0,0,0,18,0,12,4,2,10,15,1,1,1
1,1,1,17,10,10,10,11,14,3,0,0,0,0,0,3,16,11,10,10,10,17,1,1,1
1,1,6,2,14,15,14,15,2,0,0,0,0,0,0,0,2,15,16,15,16,2,6,1,1
1,1,8,5,1,1,1,1,2,13,0,0,0,0,0,13,2,1,1,1,1,4,8,1,1
1,1,1,1,1,1,1,1,1,1,8,0,0,0,8,1,1,1,1,1,1,1,1,1,1
1,1,1,1,1,1,1,1,1,1,8,1,1,1,8,1,1,1,1,1,1,1,1,1,1
endlayer

layer
1,1,1,1,1,1,1,1,1,12,2,18,18,18,2,12,1,1,1,1,1,1,1,1,1
1,1,1,1,1,1,1,1,1,1,2,0,0,0,2,1,1,1,1,1,1,1,1,1,1
1,1,13,1,1,1,1,1,2,2,8,8,13,8,8,2,2,1,1,1,1,1,13,1,1
1,1,1,2,1,16,1,16,2,17,0,0,0,0,0,17,2,14,1,14,1,2,1,1,1
1,1,1,1,9,9,9,9,2,16,0,0,0,0,0,14,2,9,9,9,9,1,1,1,1
1,1,1,17,9,0,0,0,14,13,0,0,0,0,0,13,16,0,0,0,9,17,1,1,1
1,1,1,1,9,0,0,0,0,17,0,0,0,0,0,17,0,0,0,0,9,1,1,1,1
1,1,1,17,9,0,0,0,0,0,0,0,0,0,0,0,0,0,0,0,9,17,1,1,1
1,1,2,2,2,18,0,0,0,0,0,0,0,0,0,0,0,0,0,18,2,2,2,1,1
12,1,2,16,17,13,16,0,0,0,0,0,0,0,0,0,0,0,14,13,17,14,2,1,12
2,2,8,0,0,0,0,0,0,0,0,0,0,0,0,0,0,0,0,0,0,0,8,2,2
14,0,8,0,0,0,0,0,0,0,0,0,0,0,0,0,0,0,0,0,0,0,8,0,16
14,0,13,0,0,0,0,0,0,0,0,0,0,0,0,0,0,0,0,0,0,0,13,0,16
14,0,8,0,0,0,0,0,0,0,0,0,0,0,0,0,0,0,0,0,0,0,8,0,16
2,2,8,0,0,0,0,0,0,0,0,0,0,0,0,0,0,0,0,0,0,0,8,2,2
12,1,2,16,18,13,16,0,0,0,0,0,0,0,0,0,0,0,14,13,18,14,2,1,12
1,1,2,2,2,17,0,0,0,0,0,0,0,0,0,0,0,0,0,17,2,2,2,1,1
1,1,1,18,9,0,0,0,0,0,0,0,0,0,0,0,0,0,0,0,9,18,1,1,1
1,1,1,1,9,0,0,0,0,18,0,0,0,0,0,18,0,0,0,0,9,1,1,1,1
1,1,1,18,9,0,0,0,14,13,0,0,0,0,0,13,16,0,0,0,9,18,1,1,1
1,1,1,1,9,9,9,9,2,16,0,0,0,0,0,14,2,9,9,9,9,1,1,1,1
1,1,1,2,1,16,1,16,2,18,0,0,0,0,0,18,2,14,1,14,1,2,1,1,1
1,1,13,1,1,1,1,1,2,2,8,8,13,8,8,2,2,1,1,1,1,1,13,1,1
1,1,1,1,1,1,1,1,1,1,2,0,0,0,2,1,1,1,1,1,1,1,1,1,1
1,1,1,1,1,1,1,1,1,12,2,17,17,17,2,12,1,1,1,1,1,1,1,1,1
endlayer

layer
1,1,1,1,1,1,1,1,1,12,2,2,13,2,2,12,1,1,1,1,1,1,1,1,1
1,1,1,1,1,1,1,1,1,1,2,19,20,19,2,1,1,1,1,1,1,1,1,1,1
1,1,1,1,1,1,1,1,15,2,2,2,2,2,2,2,15,1,1,1,1,1,1,1,1
1,1,1,8,5,4,12,4,13,2,19,20,20,20,19,2,13,5,12,5,4,8,1,1,1
1,1,1,3,10,10,11,10,2,2,19,20,20,20,19,2,2,10,11,10,10,3,1,1,1
1,1,1,6,10,0,15,17,2,2,19,20,20,20,19,2,2,17,15,0,10,6,1,1,1
1,1,1,12,11,15,0,0,14,2,19,20,20,20,19,2,16,0,0,15,11,12,1,1,1
1,1,1,6,10,16,0,0,18,8,17,15,15,15,17,8,18,0,0,14,10,6,1,1,1
1,1,15,13,2,2,18,14,13,15,0,0,0,0,0,15,13,16,18,2,2,13,15,1,1
12,1,2,2,2,2,2,8,15,0,0,0,0,0,0,0,15,8,2,2,2,2,2,1,12
2,2,2,19,19,19,19,16,0,0,0,0,0,0,0,0,0,14,19,19,19,19,2,2,2
2,19,2,21,21,21,21,15,0,0,0,0,0,0,0,0,0,15,21,21,21,21,2,19,2
13,21,2,21,21,21,21,15,0,0,0,0,0,0,0,0,0,15,21,21,21,21,2,21,13
2,19,2,21,21,21,21,15,0,0,0,0,0,0,0,0,0,15,21,21,21,21,2,19,2
2,2,2,19,19,19,19,16,0,0,0,0,0,0,0,0,0,14,19,19,19,19,2,2,2
12,1,2,2,2,2,2,8,15,0,0,0,0,0,0,0,15,8,2,2,2,2,2,1,12
1,1,15,13,2,2,17,14,13,15,0,0,0,0,0,15,13,16,17,2,2,2,15,1,1
1,1,1,3,10,16,0,0,17,8,18,15,15,15,18,8,17,0,0,14,10,3,1,1,1
1,1,1,12,11,15,0,0,18,2,19,20,20,20,19,2,16,0,0,15,11,12,1,1,1
1,1,1,3,10,0,15,18,2,2,19,20,20,20,19,2,2,18,15,0,10,3,1,1,1
1,1,1,6,10,10,11,10,2,2,19,20,20,20,19,2,2,10,11,10,10,6,1,1,1
1,1,1,8,5,4,12,4,13,2,19,20,20,20,19,2,13,5,12,5,4,8,1,1,1
1,1,1,1,1,1,1,1,15,2,2,2,2,2,2,2,15,1,1,1,1,1,1,1,1
1,1,1,1,1,1,1,1,1,1,2,19,20,19,2,1,1,1,1,1,1,1,1,1,1
1,1,1,1,1,1,1,1,1,12,2,2,13,2,2,12,1,1,1,1,1,1,1,1,1
endlayer

layer
1,1,1,1,1,1,1,1,1,1,1,1,12,1,1,1,1,1,1,1,1,1,1,1,1
1,1,1,1,1,1,1,1,1,1,13,1,1,1,13,1,1,1,1,1,1,1,1,1,1
1,1,1,1,1,1,1,1,1,1,1,1,1,1,1,1,1,1,1,1,1,1,1,1,1
1,1,1,8,8,8,8,8,1,1,1,1,1,1,1,1,1,8,8,8,8,8,1,1,1
1,1,1,8,2,2,2,2,2,1,1,1,1,1,1,1,2,2,2,2,2,8,1,1,1
1,1,1,8,2,17,17,2,2,1,1,1,1,1,1,1,2,2,17,14,2,8,1,1,1
1,1,1,8,2,16,0,0,2,2,1,1,1,1,1,2,2,0,0,14,2,8,1,1,1
1,1,1,8,2,2,0,0,2,2,8,8,13,8,8,2,2,0,0,2,2,8,1,1,1
1,1,1,1,2,2,2,2,2,2,0,0,0,0,0,2,2,2,2,2,2,1,1,1,1
1,1,1,1,1,1,2,2,2,15,0,0,0,0,0,15,2,2,2,1,1,1,1,1,1
1,13,1,1,1,1,1,8,0,0,0,0,0,0,0,0,0,8,1,1,1,1,1,13,1
1,1,1,1,1,1,1,8,0,0,0,0,0,0,0,0,0,8,1,1,1,1,1,1,1
12,1,1,1,1,1,1,13,0,0,0,0,0,0,0,0,0,13,1,1,1,1,1,1,12
1,1,1,1,1,1,1,8,0,0,0,0,0,0,0,0,0,8,1,1,1,1,1,1,1
1,13,1,1,1,1,1,8,0,0,0,0,0,0,0,0,0,8,1,1,1,1,1,13,1
1,1,1,1,1,1,2,2,2,15,0,0,0,0,0,15,2,2,2,1,1,1,1,1,1
1,1,1,1,2,2,2,2,2,2,0,0,0,0,0,2,2,2,2,2,2,1,1,1,1
1,1,1,8,2,2,0,0,2,2,8,8,13,8,8,2,2,0,0,2,2,8,1,1,1
1,1,1,8,2,16,0,0,2,2,1,1,1,1,1,2,2,0,0,14,2,8,1,1,1
1,1,1,8,2,16,18,2,2,1,1,1,1,1,1,1,2,2,18,14,2,8,1,1,1
1,1,1,8,2,2,2,2,2,1,1,1,1,1,1,1,2,2,2,2,2,8,1,1,1
1,1,1,8,8,8,8,8,1,1,1,1,1,1,1,1,1,8,8,8,8,8,1,1,1
1,1,1,1,1,1,1,1,1,1,1,1,1,1,1,1,1,1,1,1,1,1,1,1,1
1,1,1,1,1,1,1,1,1,1,13,1,1,1,13,1,1,1,1,1,1,1,1,1,1
1,1,1,1,1,1,1,1,1,1,1,1,12,1,1,1,1,1,1,1,1,1,1,1,1
endlayer

layer
1,1,1,1,1,1,1,1,1,1,1,1,1,1,1,1,1,1,1,1,1,1,1,1,1
1,1,1,1,1,1,1,1,1,1,3,1,1,1,3,1,1,1,1,1,1,1,1,1,1
1,1,1,1,1,1,1,1,1,1,1,1,1,1,1,1,1,1,1,1,1,1,1,1,1
1,1,1,13,1,1,1,12,1,1,1,1,1,1,1,1,1,12,1,1,1,13,1,1,1
1,1,1,1,2,2,1,1,1,1,1,1,1,1,1,1,1,1,1,2,2,1,1,1,1
1,1,1,1,2,2,15,12,1,1,1,1,1,1,1,1,1,12,15,2,2,1,1,1,1
1,1,1,1,1,15,9,9,1,1,1,1,1,1,1,1,1,9,9,15,1,1,1,1,1
1,1,1,12,1,12,9,9,2,15,1,1,1,1,1,15,2,9,9,12,1,12,1,1,1
1,1,1,1,1,1,1,2,2,6,0,0,0,0,0,6,2,2,1,1,1,1,1,1,1
1,1,1,1,1,1,1,15,4,8,0,0,0,0,0,8,5,15,1,1,1,1,1,1,1
1,5,1,1,1,1,1,1,0,0,0,0,0,0,0,0,0,1,1,1,1,1,1,4,1
1,1,1,1,1,1,1,1,0,0,0,0,0,0,0,0,0,1,1,1,1,1,1,1,1
1,1,1,1,1,1,1,1,0,0,0,0,0,0,0,0,0,1,1,1,1,1,1,1,1
1,1,1,1,1,1,1,1,0,0,0,0,0,0,0,0,0,1,1,1,1,1,1,1,1
1,5,1,1,1,1,1,1,0,0,0,0,0,0,0,0,0,1,1,1,1,1,1,4,1
1,1,1,1,1,1,1,15,4,8,0,0,0,0,0,8,5,15,1,1,1,1,1,1,1
1,1,1,1,1,1,1,2,2,3,0,0,0,0,0,3,2,2,1,1,1,1,1,1,1
1,1,1,12,1,12,9,9,2,15,1,1,1,1,1,15,2,9,9,12,1,12,1,1,1
1,1,1,1,1,15,9,9,1,1,1,1,1,1,1,1,1,9,9,15,1,1,1,1,1
1,1,1,1,2,2,15,12,1,1,1,1,1,1,1,1,1,12,15,2,2,1,1,1,1
1,1,1,1,2,2,1,1,1,1,1,1,1,1,1,1,1,1,1,2,2,1,1,1,1
1,1,1,13,1,1,1,12,1,1,1,1,1,1,1,1,1,12,1,1,1,13,1,1,1
1,1,1,1,1,1,1,1,1,1,1,1,1,1,1,1,1,1,1,1,1,1,1,1,1
1,1,1,1,1,1,1,1,1,1,6,1,1,1,6,1,1,1,1,1,1,1,1,1,1
1,1,1,1,1,1,1,1,1,1,1,1,1,1,1,1,1,1,1,1,1,1,1,1,1
endlayer

layer
1,1,1,1,1,1,1,1,1,1,1,1,1,1,1,1,1,1,1,1,1,1,1,1,1
1,1,1,1,1,1,1,1,1,1,1,1,1,1,1,1,1,1,1,1,1,1,1,1,1
1,1,1,1,1,1,1,1,1,1,1,1,1,1,1,1,1,1,1,1,1,1,1,1,1
1,1,1,1,1,1,1,1,1,1,1,1,1,1,1,1,1,1,1,1,1,1,1,1,1
1,1,1,1,8,2,1,1,1,1,1,1,1,1,1,1,1,1,1,2,8,1,1,1,1
1,1,1,1,2,2,1,15,1,1,1,1,1,1,1,1,1,15,1,2,2,1,1,1,1
1,1,1,1,1,1,9,9,16,1,1,1,1,1,1,1,14,9,9,1,1,1,1,1,1
1,1,1,1,1,15,9,2,2,15,1,1,1,1,1,15,2,2,9,15,1,1,1,1,1
1,1,1,1,1,1,17,2,0,0,0,0,0,0,0,0,0,2,17,1,1,1,1,1,1
1,1,1,1,1,1,1,15,0,8,0,0,0,0,0,8,0,15,1,1,1,1,1,1,1
1,1,1,1,1,1,1,1,0,0,0,0,0,0,0,0,0,1,1,1,1,1,1,1,1
1,1,1,1,1,1,1,1,0,0,0,0,0,0,0,0,0,1,1,1,1,1,1,1,1
1,1,1,1,1,1,1,1,0,0,0,0,0,0,0,0,0,1,1,1,1,1,1,1,1
1,1,1,1,1,1,1,1,0,0,0,0,0,0,0,0,0,1,1,1,1,1,1,1,1
1,1,1,1,1,1,1,1,0,0,0,0,0,0,0,0,0,1,1,1,1,1,1,1,1
1,1,1,1,1,1,1,15,0,8,0,0,0,0,0,8,0,15,1,1,1,1,1,1,1
1,1,1,1,1,1,18,2,0,0,0,0,0,0,0,0,0,2,18,1,1,1,1,1,1
1,1,1,1,1,15,9,2,2,15,1,1,1,1,1,15,2,2,9,15,1,1,1,1,1
1,1,1,1,1,1,9,9,16,1,1,1,1,1,1,1,14,9,9,1,1,1,1,1,1
1,1,1,1,2,2,1,15,1,1,1,1,1,1,1,1,1,15,1,2,2,1,1,1,1
1,1,1,1,8,2,1,1,1,1,1,1,1,1,1,1,1,1,1,2,8,1,1,1,1
1,1,1,1,1,1,1,1,1,1,1,1,1,1,1,1,1,1,1,1,1,1,1,1,1
1,1,1,1,1,1,1,1,1,1,1,1,1,1,1,1,1,1,1,1,1,1,1,1,1
1,1,1,1,1,1,1,1,1,1,1,1,1,1,1,1,1,1,1,1,1,1,1,1,1
1,1,1,1,1,1,1,1,1,1,1,1,1,1,1,1,1,1,1,1,1,1,1,1,1
endlayer

layer
1,1,1,1,1,1,1,1,1,1,1,1,1,1,1,1,1,1,1,1,1,1,1,1,1
1,1,1,1,1,1,1,1,1,1,1,1,1,1,1,1,1,1,1,1,1,1,1,1,1
1,1,1,1,1,1,1,1,1,1,1,1,1,1,1,1,1,1,1,1,1,1,1,1,1
1,1,1,1,1,1,1,1,1,1,1,1,1,1,1,1,1,1,1,1,1,1,1,1,1
1,1,1,1,8,2,1,1,1,1,1,1,1,1,1,1,1,1,1,2,8,1,1,1,1
1,1,1,1,2,2,12,8,8,1,1,1,1,1,1,1,8,8,12,2,2,1,1,1,1
1,1,1,1,1,12,9,2,2,8,1,1,1,1,1,8,2,2,9,12,1,1,1,1,1
1,1,1,1,1,8,2,2,2,2,15,1,1,1,15,2,2,2,2,8,1,1,1,1,1
1,1,1,1,1,8,2,2,12,0,0,0,0,0,0,0,12,2,2,8,1,1,1,1,1
1,1,1,1,1,1,8,2,0,8,0,0,0,0,0,8,0,2,8,1,1,1,1,1,1
1,1,1,1,1,1,1,15,0,0,0,0,0,0,0,0,0,15,1,1,1,1,1,1,1
1,1,1,1,1,1,1,1,0,0,0,0,0,0,0,0,0,1,1,1,1,1,1,1,1
1,1,1,1,1,1,1,1,0,0,0,0,0,0,0,0,0,1,1,1,1,1,1,1,1
1,1,1,1,1,1,1,1,0,0,0,0,0,0,0,0,0,1,1,1,1,1,1,1,1
1,1,1,1,1,1,1,15,0,0,0,0,0,0,0,0,0,15,1,1,1,1,1,1,1
1,1,1,1,1,1,8,2,0,8,0,0,0,0,0,8,0,2,8,1,1,1,1,1,1
1,1,1,1,1,8,2,2,12,0,0,0,0,0,0,0,12,2,2,8,1,1,1,1,1
1,1,1,1,1,8,2,2,2,2,15,1,1,1,15,2,2,2,2,8,1,1,1,1,1
1,1,1,1,1,12,9,2,2,8,1,1,1,1,1,8,2,2,9,12,1,1,1,1,1
1,1,1,1,2,2,12,8,8,1,1,1,1,1,1,1,8,8,12,2,2,1,1,1,1
1,1,1,1,8,2,1,1,1,1,1,1,1,1,1,1,1,1,1,2,8,1,1,1,1
1,1,1,1,1,1,1,1,1,1,1,1,1,1,1,1,1,1,1,1,1,1,1,1,1
1,1,1,1,1,1,1,1,1,1,1,1,1,1,1,1,1,1,1,1,1,1,1,1,1
1,1,1,1,1,1,1,1,1,1,1,1,1,1,1,1,1,1,1,1,1,1,1,1,1
1,1,1,1,1,1,1,1,1,1,1,1,1,1,1,1,1,1,1,1,1,1,1,1,1
endlayer

layer
1,1,1,1,1,1,1,1,1,1,1,1,1,1,1,1,1,1,1,1,1,1,1,1,1
1,1,1,1,1,1,1,1,1,1,1,1,1,1,1,1,1,1,1,1,1,1,1,1,1
1,1,1,1,1,1,1,1,1,1,1,1,1,1,1,1,1,1,1,1,1,1,1,1,1
1,1,1,1,1,1,1,1,1,1,1,1,1,1,1,1,1,1,1,1,1,1,1,1,1
1,1,1,1,13,1,12,1,1,1,1,1,1,1,1,1,1,1,12,1,13,1,1,1,1
1,1,1,1,1,2,2,1,12,1,1,1,1,1,1,1,12,1,2,2,1,1,1,1,1
1,1,1,1,12,2,2,1,1,1,1,1,1,1,1,1,1,1,2,2,12,1,1,1,1
1,1,1,1,1,1,1,9,12,2,16,15,1,15,14,2,12,9,1,1,1,1,1,1,1
1,1,1,1,1,12,1,12,0,12,0,0,0,0,0,12,0,12,1,12,1,1,1,1,1
1,1,1,1,1,1,1,2,12,8,0,0,0,0,0,8,12,2,1,1,1,1,1,1,1
1,1,1,1,1,1,1,17,0,0,0,0,0,0,0,0,0,17,1,1,1,1,1,1,1
1,1,1,1,1,1,1,15,0,0,0,0,0,0,0,0,0,15,1,1,1,1,1,1,1
1,1,1,1,1,1,1,1,0,0,0,0,0,0,0,0,0,1,1,1,1,1,1,1,1
1,1,1,1,1,1,1,15,0,0,0,0,0,0,0,0,0,15,1,1,1,1,1,1,1
1,1,1,1,1,1,1,18,0,0,0,0,0,0,0,0,0,18,1,1,1,1,1,1,1
1,1,1,1,1,1,1,2,12,8,0,0,0,0,0,8,12,2,1,1,1,1,1,1,1
1,1,1,1,1,12,1,12,1,12,0,0,0,0,0,12,0,12,1,12,1,1,1,1,1
1,1,1,1,1,1,1,9,12,2,16,15,1,15,14,2,12,9,1,1,1,1,1,1,1
1,1,1,1,12,2,2,1,1,1,1,1,1,1,1,1,1,1,2,2,12,1,1,1,1
1,1,1,1,1,2,2,1,12,1,1,1,1,1,1,1,12,1,2,2,1,1,1,1,1
1,1,1,1,13,1,12,1,1,1,1,1,1,1,1,1,1,1,12,1,13,1,1,1,1
1,1,1,1,1,1,1,1,1,1,1,1,1,1,1,1,1,1,1,1,1,1,1,1,1
1,1,1,1,1,1,1,1,1,1,1,1,1,1,1,1,1,1,1,1,1,1,1,1,1
1,1,1,1,1,1,1,1,1,1,1,1,1,1,1,1,1,1,1,1,1,1,1,1,1
1,1,1,1,1,1,1,1,1,1,1,1,1,1,1,1,1,1,1,1,1,1,1,1,1
endlayer

layer
1,1,1,1,1,1,1,1,1,1,1,1,1,1,1,1,1,1,1,1,1,1,1,1,1
1,1,1,1,1,1,1,1,1,1,1,1,1,1,1,1,1,1,1,1,1,1,1,1,1
1,1,1,1,1,1,1,1,1,1,1,1,1,1,1,1,1,1,1,1,1,1,1,1,1
1,1,1,1,1,1,1,1,1,1,1,1,1,1,1,1,1,1,1,1,1,1,1,1,1
1,1,1,1,1,1,1,1,1,1,1,1,1,1,1,1,1,1,1,1,1,1,1,1,1
1,1,1,1,1,8,2,1,1,1,1,1,1,1,1,1,1,1,2,8,1,1,1,1,1
1,1,1,1,1,2,2,12,1,1,1,1,1,1,1,1,1,12,2,2,1,1,1,1,1
1,1,1,1,1,1,12,9,12,2,1,16,15,14,1,2,12,9,12,1,1,1,1,1,1
1,1,1,1,1,1,1,12,0,0,0,0,0,0,0,0,0,12,1,1,1,1,1,1,1
1,1,1,1,1,1,1,2,0,8,0,0,0,0,0,8,0,2,1,1,1,1,1,1,1
1,1,1,1,1,1,1,1,0,0,0,0,0,0,0,0,0,1,1,1,1,1,1,1,1
1,1,1,1,1,1,1,17,0,0,0,0,0,0,0,0,0,17,1,1,1,1,1,1,1
1,1,1,1,1,1,1,15,0,0,0,0,0,0,0,0,0,15,1,1,1,1,1,1,1
1,1,1,1,1,1,1,18,0,0,0,0,0,0,0,0,0,18,1,1,1,1,1,1,1
1,1,1,1,1,1,1,1,0,0,0,0,0,0,0,0,0,1,1,1,1,1,1,1,1
1,1,1,1,1,1,1,2,0,8,0,0,0,0,0,8,0,2,1,1,1,1,1,1,1
1,1,1,1,1,1,1,12,0,0,0,0,0,0,0,0,0,12,1,1,1,1,1,1,1
1,1,1,1,1,1,12,9,12,2,1,16,15,14,1,2,12,9,12,1,1,1,1,1,1
1,1,1,1,1,2,2,12,1,1,1,1,1,1,1,1,1,12,2,2,1,1,1,1,1
1,1,1,1,1,8,2,1,1,1,1,1,1,1,1,1,1,1,2,8,1,1,1,1,1
1,1,1,1,1,1,1,1,1,1,1,1,1,1,1,1,1,1,1,1,1,1,1,1,1
1,1,1,1,1,1,1,1,1,1,1,1,1,1,1,1,1,1,1,1,1,1,1,1,1
1,1,1,1,1,1,1,1,1,1,1,1,1,1,1,1,1,1,1,1,1,1,1,1,1
1,1,1,1,1,1,1,1,1,1,1,1,1,1,1,1,1,1,1,1,1,1,1,1,1
1,1,1,1,1,1,1,1,1,1,1,1,1,1,1,1,1,1,1,1,1,1,1,1,1
endlayer

layer
1,1,1,1,1,1,1,1,1,1,1,1,1,1,1,1,1,1,1,1,1,1,1,1,1
1,1,1,1,1,1,1,1,1,1,1,1,1,1,1,1,1,1,1,1,1,1,1,1,1
1,1,1,1,1,1,1,1,1,1,1,1,1,1,1,1,1,1,1,1,1,1,1,1,1
1,1,1,1,1,1,1,1,1,1,1,1,1,1,1,1,1,1,1,1,1,1,1,1,1
1,1,1,1,1,1,1,1,1,1,1,1,1,1,1,1,1,1,1,1,1,1,1,1,1
1,1,1,1,1,13,1,12,1,1,1,1,1,1,1,1,1,12,1,13,1,1,1,1,1
1,1,1,1,1,1,2,2,8,8,1,1,1,1,1,8,8,2,2,1,1,1,1,1,1
1,1,1,1,1,12,2,2,2,2,14,2,1,2,16,2,2,2,2,12,1,1,1,1,1
1,1,1,1,1,1,8,2,22,12,0,0,0,0,0,12,22,2,8,1,1,1,1,1,1
1,1,1,1,1,1,8,2,12,8,0,0,0,0,0,8,12,2,8,1,1,1,1,1,1
1,1,1,1,1,1,1,18,0,0,0,0,0,0,0,0,0,18,1,1,1,1,1,1,1
1,1,1,1,1,1,1,2,0,0,0,0,0,0,0,0,0,2,1,1,1,1,1,1,1
1,1,1,1,1,1,1,1,0,0,0,0,0,0,0,0,0,1,1,1,1,1,1,1,1
1,1,1,1,1,1,1,2,0,0,0,0,0,0,0,0,0,2,1,1,1,1,1,1,1
1,1,1,1,1,1,1,17,0,0,0,0,0,0,0,0,0,17,1,1,1,1,1,1,1
1,1,1,1,1,1,8,2,12,8,0,0,0,0,0,8,12,2,8,1,1,1,1,1,1
1,1,1,1,1,1,8,2,22,12,0,0,0,0,0,12,22,2,8,1,1,1,1,1,1
1,1,1,1,1,12,2,2,2,2,14,2,1,2,16,2,2,2,2,12,1,1,1,1,1
1,1,1,1,1,1,2,2,8,8,1,1,1,1,1,8,8,2,2,1,1,1,1,1,1
1,1,1,1,1,13,1,12,1,1,1,1,1,1,1,1,1,12,1,13,1,1,1,1,1
1,1,1,1,1,1,1,1,1,1,1,1,1,1,1,1,1,1,1,1,1,1,1,1,1
1,1,1,1,1,1,1,1,1,1,1,1,1,1,1,1,1,1,1,1,1,1,1,1,1
1,1,1,1,1,1,1,1,1,1,1,1,1,1,1,1,1,1,1,1,1,1,1,1,1
1,1,1,1,1,1,1,1,1,1,1,1,1,1,1,1,1,1,1,1,1,1,1,1,1
1,1,1,1,1,1,1,1,1,1,1,1,1,1,1,1,1,1,1,1,1,1,1,1,1
endlayer

layer
1,1,1,1,1,1,1,1,1,1,1,1,1,1,1,1,1,1,1,1,1,1,1,1,1
1,1,1,1,1,1,1,1,1,1,1,1,1,1,1,1,1,1,1,1,1,1,1,1,1
1,1,1,1,1,1,1,1,1,1,1,1,1,1,1,1,1,1,1,1,1,1,1,1,1
1,1,1,1,1,1,1,1,1,1,1,1,1,1,1,1,1,1,1,1,1,1,1,1,1
1,1,1,1,1,1,1,1,1,1,1,1,1,1,1,1,1,1,1,1,1,1,1,1,1
1,1,1,1,1,1,1,1,1,1,1,1,1,1,1,1,1,1,1,1,1,1,1,1,1
1,1,1,1,1,1,8,2,1,1,1,1,1,1,1,1,1,2,8,1,1,1,1,1,1
1,1,1,1,1,1,2,2,1,2,15,8,12,8,15,2,1,2,2,1,1,1,1,1,1
1,1,1,1,1,1,1,1,0,12,0,0,0,0,0,12,0,1,1,1,1,1,1,1,1
1,1,1,1,1,1,1,2,12,8,16,0,0,0,14,8,12,2,1,1,1,1,1,1,1
1,1,1,1,1,1,1,15,0,17,0,0,0,0,0,17,0,15,1,1,1,1,1,1,1
1,1,1,1,1,1,1,8,0,0,0,0,0,0,0,0,0,8,1,1,1,1,1,1,1
1,1,1,1,1,1,1,12,0,0,0,0,0,0,0,0,0,12,1,1,1,1,1,1,1
1,1,1,1,1,1,1,8,0,0,0,0,0,0,0,0,0,8,1,1,1,1,1,1,1
1,1,1,1,1,1,1,15,0,18,0,0,0,0,0,18,0,15,1,1,1,1,1,1,1
1,1,1,1,1,1,1,2,12,8,16,0,0,0,14,8,12,2,1,1,1,1,1,1,1
1,1,1,1,1,1,1,1,0,12,0,0,0,0,0,12,0,1,1,1,1,1,1,1,1
1,1,1,1,1,1,2,2,1,2,15,8,12,8,15,2,1,2,2,1,1,1,1,1,1
1,1,1,1,1,1,8,2,1,1,1,1,1,1,1,1,1,2,8,1,1,1,1,1,1
1,1,1,1,1,1,1,1,1,1,1,1,1,1,1,1,1,1,1,1,1,1,1,1,1
1,1,1,1,1,1,1,1,1,1,1,1,1,1,1,1,1,1,1,1,1,1,1,1,1
1,1,1,1,1,1,1,1,1,1,1,1,1,1,1,1,1,1,1,1,1,1,1,1,1
1,1,1,1,1,1,1,1,1,1,1,1,1,1,1,1,1,1,1,1,1,1,1,1,1
1,1,1,1,1,1,1,1,1,1,1,1,1,1,1,1,1,1,1,1,1,1,1,1,1
1,1,1,1,1,1,1,1,1,1,1,1,1,1,1,1,1,1,1,1,1,1,1,1,1
endlayer

layer
1,1,1,1,1,1,1,1,1,1,1,1,1,1,1,1,1,1,1,1,1,1,1,1,1
1,1,1,1,1,1,1,1,1,1,1,1,1,1,1,1,1,1,1,1,1,1,1,1,1
1,1,1,1,1,1,1,1,1,1,1,1,1,1,1,1,1,1,1,1,1,1,1,1,1
1,1,1,1,1,1,1,1,1,1,1,1,1,1,1,1,1,1,1,1,1,1,1,1,1
1,1,1,1,1,1,1,1,1,1,1,1,1,1,1,1,1,1,1,1,1,1,1,1,1
1,1,1,1,1,1,1,1,1,1,1,1,1,1,1,1,1,1,1,1,1,1,1,1,1
1,1,1,1,1,1,13,1,1,1,1,1,1,1,1,1,1,1,13,1,1,1,1,1,1
1,1,1,1,1,1,1,2,12,8,1,13,1,13,1,8,12,2,1,1,1,1,1,1,1
1,1,1,1,1,1,1,12,0,0,0,17,0,17,0,0,0,12,1,1,1,1,1,1,1
1,1,1,1,1,1,1,8,0,2,15,0,0,0,15,2,0,8,1,1,1,1,1,1,1
1,1,1,1,1,1,1,1,0,15,0,0,0,0,0,15,0,1,1,1,1,1,1,1,1
1,1,1,1,1,1,1,13,16,0,0,0,0,0,0,0,14,13,1,1,1,1,1,1,1
1,1,1,1,1,1,1,1,0,0,0,0,0,0,0,0,0,1,1,1,1,1,1,1,1
1,1,1,1,1,1,1,13,16,0,0,0,0,0,0,0,14,13,1,1,1,1,1,1,1
1,1,1,1,1,1,1,1,0,15,0,0,0,0,0,15,0,1,1,1,1,1,1,1,1
1,1,1,1,1,1,1,8,0,2,15,0,0,0,15,2,0,8,1,1,1,1,1,1,1
1,1,1,1,1,1,1,12,0,0,0,18,0,18,0,0,0,12,1,1,1,1,1,1,1
1,1,1,1,1,1,1,2,12,8,1,13,1,13,1,8,12,2,1,1,1,1,1,1,1
1,1,1,1,1,1,13,1,1,1,1,1,1,1,1,1,1,1,13,1,1,1,1,1,1
1,1,1,1,1,1,1,1,1,1,1,1,1,1,1,1,1,1,1,1,1,1,1,1,1
1,1,1,1,1,1,1,1,1,1,1,1,1,1,1,1,1,1,1,1,1,1,1,1,1
1,1,1,1,1,1,1,1,1,1,1,1,1,1,1,1,1,1,1,1,1,1,1,1,1
1,1,1,1,1,1,1,1,1,1,1,1,1,1,1,1,1,1,1,1,1,1,1,1,1
1,1,1,1,1,1,1,1,1,1,1,1,1,1,1,1,1,1,1,1,1,1,1,1,1
1,1,1,1,1,1,1,1,1,1,1,1,1,1,1,1,1,1,1,1,1,1,1,1,1
endlayer

layer
1,1,1,1,1,1,1,1,1,1,1,1,1,1,1,1,1,1,1,1,1,1,1,1,1
1,1,1,1,1,1,1,1,1,1,1,1,1,1,1,1,1,1,1,1,1,1,1,1,1
1,1,1,1,1,1,1,1,1,1,1,1,1,1,1,1,1,1,1,1,1,1,1,1,1
1,1,1,1,1,1,1,1,1,1,1,1,1,1,1,1,1,1,1,1,1,1,1,1,1
1,1,1,1,1,1,1,1,1,1,1,1,1,1,1,1,1,1,1,1,1,1,1,1,1
1,1,1,1,1,1,1,1,1,1,1,1,1,1,1,1,1,1,1,1,1,1,1,1,1
1,1,1,1,1,1,1,1,1,1,1,1,1,1,1,1,1,1,1,1,1,1,1,1,1
1,1,1,1,1,1,1,8,1,13,1,1,1,1,1,13,1,8,1,1,1,1,1,1,1
1,1,1,1,1,1,1,1,0,17,15,2,1,2,15,17,0,1,1,1,1,1,1,1,1
1,1,1,1,1,1,1,13,16,2,23,1,1,1,23,2,14,13,1,1,1,1,1,1,1
1,1,1,1,1,1,1,1,15,12,15,17,15,17,15,23,15,1,1,1,1,1,1,1,1
1,1,1,1,1,1,1,1,2,1,16,1,1,1,14,1,2,1,1,1,1,1,1,1,1
1,1,1,1,1,1,1,1,1,1,15,1,1,1,15,1,1,1,1,1,1,1,1,1,1
1,1,1,1,1,1,1,1,2,1,16,1,1,1,14,1,2,1,1,1,1,1,1,1,1
1,1,1,1,1,1,1,1,15,23,15,18,15,18,15,23,15,1,1,1,1,1,1,1,1
1,1,1,1,1,1,1,13,16,2,23,1,1,1,23,2,14,13,1,1,1,1,1,1,1
1,1,1,1,1,1,1,1,0,18,15,2,1,2,15,18,0,1,1,1,1,1,1,1,1
1,1,1,1,1,1,1,8,1,13,1,1,1,1,1,13,1,8,1,1,1,1,1,1,1
1,1,1,1,1,1,1,1,1,1,1,1,1,1,1,1,1,1,1,1,1,1,1,1,1
1,1,1,1,1,1,1,1,1,1,1,1,1,1,1,1,1,1,1,1,1,1,1,1,1
1,1,1,1,1,1,1,1,1,1,1,1,1,1,1,1,1,1,1,1,1,1,1,1,1
1,1,1,1,1,1,1,1,1,1,1,1,1,1,1,1,1,1,1,1,1,1,1,1,1
1,1,1,1,1,1,1,1,1,1,1,1,1,1,1,1,1,1,1,1,1,1,1,1,1
1,1,1,1,1,1,1,1,1,1,1,1,1,1,1,1,1,1,1,1,1,1,1,1,1
1,1,1,1,1,1,1,1,1,1,1,1,1,1,1,1,1,1,1,1,1,1,1,1,1
endlayer

layer
1,1,1,1,1,1,1,1,1,1,1,1,1,1,1,1,1,1,1,1,1,1,1,1,1
1,1,1,1,1,1,1,1,1,1,1,1,1,1,1,1,1,1,1,1,1,1,1,1,1
1,1,1,1,1,1,1,1,1,1,1,1,1,1,1,1,1,1,1,1,1,1,1,1,1
1,1,1,1,1,1,1,1,1,1,1,1,1,1,1,1,1,1,1,1,1,1,1,1,1
1,1,1,1,1,1,1,1,1,1,1,1,1,1,1,1,1,1,1,1,1,1,1,1,1
1,1,1,1,1,1,1,1,1,1,1,1,1,1,1,1,1,1,1,1,1,1,1,1,1
1,1,1,1,1,1,1,1,1,1,1,1,1,1,1,1,1,1,1,1,1,1,1,1,1
1,1,1,1,1,1,1,13,1,1,1,1,1,1,1,1,1,13,1,1,1,1,1,1,1
1,1,1,1,1,1,1,1,2,12,2,12,13,12,2,12,2,1,1,1,1,1,1,1,1
1,1,1,1,1,1,1,1,12,1,1,1,1,1,1,1,12,1,1,1,1,1,1,1,1
1,1,1,1,1,1,1,1,2,1,13,1,12,1,13,1,2,1,1,1,1,1,1,1,1
1,1,1,1,1,1,1,1,12,1,1,1,1,1,1,1,12,1,1,1,1,1,1,1,1
1,1,1,1,1,1,1,1,13,1,12,1,1,1,12,1,13,1,1,1,1,1,1,1,1
1,1,1,1,1,1,1,1,12,1,1,1,1,1,1,1,12,1,1,1,1,1,1,1,1
1,1,1,1,1,1,1,1,2,1,13,1,12,1,13,1,2,1,1,1,1,1,1,1,1
1,1,1,1,1,1,1,1,12,1,1,1,1,1,1,1,12,1,1,1,1,1,1,1,1
1,1,1,1,1,1,1,1,2,12,2,12,13,12,2,12,2,1,1,1,1,1,1,1,1
1,1,1,1,1,1,1,13,1,1,1,1,1,1,1,1,1,13,1,1,1,1,1,1,1
1,1,1,1,1,1,1,1,1,1,1,1,1,1,1,1,1,1,1,1,1,1,1,1,1
1,1,1,1,1,1,1,1,1,1,1,1,1,1,1,1,1,1,1,1,1,1,1,1,1
1,1,1,1,1,1,1,1,1,1,1,1,1,1,1,1,1,1,1,1,1,1,1,1,1
1,1,1,1,1,1,1,1,1,1,1,1,1,1,1,1,1,1,1,1,1,1,1,1,1
1,1,1,1,1,1,1,1,1,1,1,1,1,1,1,1,1,1,1,1,1,1,1,1,1
1,1,1,1,1,1,1,1,1,1,1,1,1,1,1,1,1,1,1,1,1,1,1,1,1
1,1,1,1,1,1,1,1,1,1,1,1,1,1,1,1,1,1,1,1,1,1,1,1,1
endlayer

layer
1,1,1,1,1,1,1,1,1,1,1,1,1,1,1,1,1,1,1,1,1,1,1,1,1
1,1,1,1,1,1,1,1,1,1,1,1,1,1,1,1,1,1,1,1,1,1,1,1,1
1,1,1,1,1,1,1,1,1,1,1,1,1,1,1,1,1,1,1,1,1,1,1,1,1
1,1,1,1,1,1,1,1,1,1,1,1,1,1,1,1,1,1,1,1,1,1,1,1,1
1,1,1,1,1,1,1,1,1,1,1,1,1,1,1,1,1,1,1,1,1,1,1,1,1
1,1,1,1,1,1,1,1,1,1,1,1,1,1,1,1,1,1,1,1,1,1,1,1,1
1,1,1,1,1,1,1,1,1,1,1,1,1,1,1,1,1,1,1,1,1,1,1,1,1
1,1,1,1,1,1,1,1,1,1,1,1,1,1,1,1,1,1,1,1,1,1,1,1,1
1,1,1,1,1,1,1,1,8,1,13,1,1,1,13,1,8,1,1,1,1,1,1,1,1
1,1,1,1,1,1,1,1,1,1,1,1,1,1,1,1,1,1,1,1,1,1,1,1,1
1,1,1,1,1,1,1,1,13,1,1,1,1,1,1,1,13,1,1,1,1,1,1,1,1
1,1,1,1,1,1,1,1,1,1,1,1,1,1,1,1,1,1,1,1,1,1,1,1,1
1,1,1,1,1,1,1,1,1,1,1,1,1,1,1,1,1,1,1,1,1,1,1,1,1
1,1,1,1,1,1,1,1,1,1,1,1,1,1,1,1,1,1,1,1,1,1,1,1,1
1,1,1,1,1,1,1,1,13,1,1,1,1,1,1,1,13,1,1,1,1,1,1,1,1
1,1,1,1,1,1,1,1,1,1,1,1,1,1,1,1,1,1,1,1,1,1,1,1,1
1,1,1,1,1,1,1,1,8,1,13,1,1,1,13,1,8,1,1,1,1,1,1,1,1
1,1,1,1,1,1,1,1,1,1,1,1,1,1,1,1,1,1,1,1,1,1,1,1,1
1,1,1,1,1,1,1,1,1,1,1,1,1,1,1,1,1,1,1,1,1,1,1,1,1
1,1,1,1,1,1,1,1,1,1,1,1,1,1,1,1,1,1,1,1,1,1,1,1,1
1,1,1,1,1,1,1,1,1,1,1,1,1,1,1,1,1,1,1,1,1,1,1,1,1
1,1,1,1,1,1,1,1,1,1,1,1,1,1,1,1,1,1,1,1,1,1,1,1,1
1,1,1,1,1,1,1,1,1,1,1,1,1,1,1,1,1,1,1,1,1,1,1,1,1
1,1,1,1,1,1,1,1,1,1,1,1,1,1,1,1,1,1,1,1,1,1,1,1,1
1,1,1,1,1,1,1,1,1,1,1,1,1,1,1,1,1,1,1,1,1,1,1,1,1
endlayer

layer
1,1,1,1,1,1,1,1,1,1,1,1,1,1,1,1,1,1,1,1,1,1,1,1,1
1,1,1,1,1,1,1,1,1,1,1,1,1,1,1,1,1,1,1,1,1,1,1,1,1
1,1,1,1,1,1,1,1,1,1,1,1,1,1,1,1,1,1,1,1,1,1,1,1,1
1,1,1,1,1,1,1,1,1,1,1,1,1,1,1,1,1,1,1,1,1,1,1,1,1
1,1,1,1,1,1,1,1,1,1,1,1,1,1,1,1,1,1,1,1,1,1,1,1,1
1,1,1,1,1,1,1,1,1,1,1,1,1,1,1,1,1,1,1,1,1,1,1,1,1
1,1,1,1,1,1,1,1,1,1,1,1,1,1,1,1,1,1,1,1,1,1,1,1,1
1,1,1,1,1,1,1,1,1,1,1,1,1,1,1,1,1,1,1,1,1,1,1,1,1
1,1,1,1,1,1,1,1,2,1,1,1,1,1,1,1,2,1,1,1,1,1,1,1,1
1,1,1,1,1,1,1,1,1,1,1,1,1,1,1,1,1,1,1,1,1,1,1,1,1
1,1,1,1,1,1,1,1,1,1,1,1,1,1,1,1,1,1,1,1,1,1,1,1,1
1,1,1,1,1,1,1,1,1,1,1,1,1,1,1,1,1,1,1,1,1,1,1,1,1
1,1,1,1,1,1,1,1,1,1,1,1,1,1,1,1,1,1,1,1,1,1,1,1,1
1,1,1,1,1,1,1,1,1,1,1,1,1,1,1,1,1,1,1,1,1,1,1,1,1
1,1,1,1,1,1,1,1,1,1,1,1,1,1,1,1,1,1,1,1,1,1,1,1,1
1,1,1,1,1,1,1,1,1,1,1,1,1,1,1,1,1,1,1,1,1,1,1,1,1
1,1,1,1,1,1,1,1,2,1,1,1,1,1,1,1,2,1,1,1,1,1,1,1,1
1,1,1,1,1,1,1,1,1,1,1,1,1,1,1,1,1,1,1,1,1,1,1,1,1
1,1,1,1,1,1,1,1,1,1,1,1,1,1,1,1,1,1,1,1,1,1,1,1,1
1,1,1,1,1,1,1,1,1,1,1,1,1,1,1,1,1,1,1,1,1,1,1,1,1
1,1,1,1,1,1,1,1,1,1,1,1,1,1,1,1,1,1,1,1,1,1,1,1,1
1,1,1,1,1,1,1,1,1,1,1,1,1,1,1,1,1,1,1,1,1,1,1,1,1
1,1,1,1,1,1,1,1,1,1,1,1,1,1,1,1,1,1,1,1,1,1,1,1,1
1,1,1,1,1,1,1,1,1,1,1,1,1,1,1,1,1,1,1,1,1,1,1,1,1
1,1,1,1,1,1,1,1,1,1,1,1,1,1,1,1,1,1,1,1,1,1,1,1,1
endlayer

