
# Created by Ruins mod version 16.7 Ingame Parser
# authoring Player: lafuller

weight=1
embed_into_distance=7
acceptable_target_blocks=
unacceptable_target_blocks=flowing_water,water,flowing_lava,lava,ice,bedrock,netherrack,nether_brick,nether_brick_fence,soul_sand,quartz_ore,gravel,end_stone,obsidian,iron_bars,cloud,flesh,ash_block,slime_grass,slime_congealed,slime_dirt
biomesToSpawnIn=desert,lush desert
dimensions=98,11,11
allowable_overhang=0
max_leveling=7
leveling_buffer=-1
preserve_water=0
preserve_lava=0

rule1=0,100,minecraft:double_stone_slab-9
rule2=0,100,minecraft:sandstone-0
rule3=0,100,minecraft:planks-2
rule4=0,100,minecraft:sandstone-1
rule5=0,100,minecraft:sandstone_stairs-2
rule6=0,100,minecraft:sandstone_stairs-0
rule7=0,100,minecraft:sandstone_stairs-3
rule8=0,100,minecraft:sandstone-2
rule9=0,100,minecraft:sandstone_stairs-1
rule10=0,100,minecraft:sandstone_stairs-6
rule11=0,100,minecraft:sandstone_stairs-4
rule12=0,100,minecraft:sandstone_stairs-7
rule13=0,100,minecraft:sandstone_stairs-5
rule14=0,100,minecraft:stone_slab-1
rule15=0,100,minecraft:stone_slab-9
rule16=0,100,minecraft:double_stone_slab-1

layer
1,1,1,1,1,1,1,1,1,1,1
1,1,2,1,2,1,1,2,2,1,1
1,1,2,1,1,2,1,2,2,1,1
1,1,2,1,1,1,1,1,1,1,1
1,2,2,1,2,2,1,1,2,1,1
1,1,1,1,2,3,1,1,2,1,1
1,1,2,1,2,2,1,1,2,1,1
1,1,2,1,2,1,1,1,2,1,1
1,2,2,1,2,2,1,2,1,1,1
1,1,1,1,1,2,1,1,2,1,1
1,1,1,1,1,1,1,1,1,1,1
endlayer

layer
1,1,1,1,1,1,1,1,1,1,1
1,1,1,1,1,1,1,1,1,1,1
1,1,1,1,1,1,1,1,1,1,1
1,1,1,1,1,1,1,1,1,1,1
1,1,1,1,1,1,1,1,1,1,1
1,1,1,1,1,1,1,1,1,1,1
1,1,1,1,1,1,1,1,1,1,1
1,1,1,1,1,1,1,1,1,1,1
1,1,1,1,1,1,1,1,1,1,1
1,1,1,1,1,1,1,1,1,1,1
1,1,1,1,1,1,1,1,1,1,1
endlayer

layer
1,1,1,1,1,1,1,1,1,1,1
1,1,1,1,1,1,1,1,1,1,1
1,1,1,1,1,1,1,1,1,1,1
1,1,1,1,1,1,1,1,1,1,1
1,1,1,1,1,1,1,1,1,1,1
1,1,1,1,1,1,1,1,1,1,1
1,1,1,1,1,1,1,1,1,1,1
1,1,1,1,1,1,1,1,1,1,1
1,1,1,1,1,1,1,1,1,1,1
1,1,1,1,1,1,1,1,1,1,1
1,1,1,1,1,1,1,1,1,1,1
endlayer

layer
1,1,1,1,1,1,1,1,1,1,1
1,1,1,1,1,1,1,1,1,1,1
1,1,1,1,1,1,1,1,1,1,1
1,1,1,1,1,1,1,1,1,1,1
1,1,1,1,1,1,1,1,1,1,1
1,1,1,1,1,1,1,1,1,1,1
1,1,1,1,1,1,1,1,1,1,1
1,1,1,1,1,1,1,1,1,1,1
1,1,1,1,1,1,1,1,1,1,1
1,1,1,1,1,1,1,1,1,1,1
1,1,1,1,1,1,1,1,1,1,1
endlayer

layer
1,1,1,1,1,1,1,1,1,1,1
1,1,1,1,1,1,1,1,1,1,1
1,1,1,1,1,1,1,1,1,1,1
1,1,1,1,1,1,1,1,1,1,1
1,1,1,1,1,1,1,1,1,1,1
1,1,1,1,1,1,1,1,1,1,1
1,1,1,1,1,1,1,1,1,1,1
1,1,1,1,1,1,1,1,1,1,1
1,1,1,1,1,1,1,1,1,1,1
1,1,1,1,1,1,1,1,1,1,1
1,1,1,1,1,1,1,1,1,1,1
endlayer

layer
1,1,1,1,1,1,1,1,1,1,1
1,1,1,1,1,1,1,1,1,1,1
1,1,1,1,1,1,1,1,1,1,1
1,1,1,1,1,1,1,1,1,1,1
1,1,1,1,1,1,1,1,1,1,1
1,1,1,1,1,1,1,1,1,1,1
1,1,1,1,1,1,1,1,1,1,1
1,1,1,1,1,1,1,1,1,1,1
1,1,1,1,1,1,1,1,1,1,1
1,1,1,1,1,1,1,1,1,1,1
1,1,1,1,1,1,1,1,1,1,1
endlayer

layer
1,1,1,1,1,1,1,1,1,1,1
1,1,1,1,1,1,1,1,1,1,1
1,1,1,1,1,1,1,1,1,1,1
1,1,1,1,1,1,1,1,1,1,1
1,1,1,1,1,1,1,1,1,1,1
1,1,1,1,1,1,1,1,1,1,1
1,1,1,1,1,1,1,1,1,1,1
1,1,1,1,1,1,1,1,1,1,1
1,1,1,1,1,1,1,1,1,1,1
1,1,1,1,1,1,1,1,1,1,1
1,1,1,1,1,1,1,1,1,1,1
endlayer

layer
1,1,1,1,1,4,1,1,1,1,1
1,1,1,1,1,1,1,1,1,1,1
1,1,1,1,1,1,1,1,1,1,1
1,1,1,1,1,1,1,1,1,1,1
1,1,1,1,1,1,1,1,1,1,1
4,1,1,1,1,1,1,1,1,1,4
1,1,1,1,1,1,1,1,1,1,1
1,1,1,1,1,1,1,1,1,1,1
1,1,1,1,1,1,1,1,1,1,1
1,1,1,1,1,1,1,1,1,1,1
1,1,1,1,1,4,1,1,1,1,1
endlayer

layer
6,6,1,1,1,1,1,1,1,6,5
7,1,1,1,1,1,1,1,1,1,5
8,1,1,1,1,1,1,1,1,1,1
8,1,1,1,1,1,1,1,1,1,1
1,1,1,1,1,1,1,1,1,1,1
1,1,1,1,1,1,1,1,1,1,1
1,1,1,1,1,1,1,1,1,1,1
8,1,1,1,1,1,1,1,1,1,1
8,1,1,1,1,1,1,1,1,1,1
7,1,1,1,1,1,1,1,1,1,5
9,9,8,8,1,1,1,8,8,9,5
endlayer

layer
0,0,12,11,6,6,6,11,10,0,0
0,4,1,1,1,1,1,1,1,4,0
11,1,2,2,2,2,2,2,2,1,11
12,1,2,2,2,2,2,2,2,1,10
7,1,2,2,2,2,2,2,2,1,5
7,1,2,2,2,1,2,2,2,1,5
7,1,2,2,2,2,2,2,2,1,5
12,1,2,2,2,2,2,2,2,1,10
13,1,2,2,2,2,2,2,2,1,13
0,4,1,1,1,1,1,1,1,4,0
0,0,12,13,9,9,9,13,10,0,0
endlayer

layer
0,11,2,2,2,2,2,2,2,11,0
12,1,1,1,1,1,1,1,1,1,10
2,1,2,2,2,2,2,2,2,1,2
2,1,2,2,2,2,2,2,2,1,2
2,1,2,2,2,2,2,2,2,1,2
2,1,2,2,2,1,2,2,2,1,2
2,1,2,2,2,2,2,2,2,1,2
2,1,2,2,2,2,2,2,2,1,2
2,1,2,2,2,2,2,2,2,1,2
12,1,1,1,1,1,1,1,1,1,10
0,13,2,2,2,2,2,2,2,13,0
endlayer

layer
2,2,2,2,4,2,4,2,4,2,4
4,1,1,1,1,1,1,1,1,1,4
2,1,2,2,2,2,2,2,2,1,2
2,1,2,2,2,2,2,2,2,1,4
2,1,2,2,2,2,2,2,2,1,2
2,1,2,2,2,1,2,2,2,1,4
2,1,2,2,2,2,2,2,2,1,2
4,1,2,2,2,2,2,2,2,1,2
4,1,2,2,2,2,2,2,2,1,2
2,1,1,1,1,1,1,1,1,1,2
2,4,2,4,2,2,2,4,2,2,2
endlayer

layer
2,4,4,4,4,4,2,2,2,2,4
4,1,1,1,1,1,1,1,1,1,2
2,1,2,2,2,2,2,2,2,1,2
2,1,2,2,2,2,2,2,2,1,4
2,1,2,2,2,2,2,2,2,1,2
4,1,2,2,2,1,2,2,2,1,4
2,1,2,2,2,2,2,2,2,1,2
2,1,2,2,2,2,2,2,2,1,4
2,1,2,2,2,2,2,2,2,1,4
2,1,1,1,1,1,1,1,1,1,4
2,4,2,4,2,2,4,4,4,2,2
endlayer

layer
2,2,4,4,2,2,4,4,4,2,4
4,1,1,1,1,1,1,1,1,1,4
2,1,2,2,2,2,2,2,2,1,2
4,1,2,2,2,2,2,2,2,1,4
2,1,2,2,2,2,2,2,2,1,2
4,1,2,2,2,1,2,2,2,1,4
4,1,2,2,2,2,2,2,2,1,4
4,1,2,2,2,2,2,2,2,1,2
2,1,2,2,2,2,2,2,2,1,4
2,1,1,1,1,1,1,1,1,1,4
2,4,2,4,2,4,2,4,2,2,2
endlayer

layer
0,2,2,2,2,2,2,2,2,2,0
2,1,1,1,1,1,1,1,1,1,2
2,1,2,2,2,2,2,2,2,1,2
2,1,2,2,2,2,2,2,2,1,2
2,1,2,2,2,2,2,2,2,1,2
2,1,2,2,2,1,2,2,2,1,2
2,1,2,2,2,2,2,2,2,1,2
2,1,2,2,2,2,2,2,2,1,2
2,1,2,2,2,2,2,2,2,1,2
2,1,1,1,1,1,1,1,1,1,2
0,2,2,2,2,2,2,2,2,2,0
endlayer

layer
0,2,2,5,14,0,14,7,2,2,0
2,1,1,1,1,1,1,1,1,1,2
2,1,2,2,2,2,2,2,2,1,2
9,1,2,2,2,2,2,2,2,1,9
14,1,2,2,2,2,2,2,2,1,14
0,1,2,2,2,1,2,2,2,1,0
14,1,2,2,2,2,2,2,2,1,14
6,1,2,2,2,2,2,2,2,1,6
2,1,2,2,2,2,2,2,2,1,2
2,1,1,1,1,1,1,1,1,1,2
0,2,2,5,14,0,14,7,2,2,0
endlayer

layer
0,2,5,0,0,0,0,0,7,2,0
2,1,1,1,1,1,1,1,1,1,2
9,1,2,2,2,2,2,2,2,1,9
0,1,2,2,2,2,2,2,2,1,0
0,1,2,2,2,2,2,2,2,1,0
0,1,2,2,2,2,2,2,2,1,0
0,1,2,2,2,2,2,2,2,1,0
0,1,2,2,2,2,2,2,2,1,0
6,1,2,2,2,2,2,2,2,1,6
2,1,1,1,1,1,1,1,1,1,2
0,2,5,0,0,0,0,0,7,2,0
endlayer

layer
0,2,0,0,0,0,0,0,0,2,0
2,1,1,1,5,0,12,1,1,1,2
0,1,3,3,3,3,3,3,3,1,0
0,1,3,2,2,2,2,2,3,13,0
0,1,3,2,2,2,2,2,3,14,0
0,0,3,2,2,2,2,2,3,0,0
0,0,3,2,2,2,2,2,3,14,0
0,1,3,2,2,2,2,2,3,1,0
0,1,3,3,3,3,3,3,3,1,0
2,1,1,0,15,1,14,0,1,1,2
0,2,0,0,0,0,0,0,0,2,0
endlayer

layer
0,2,0,0,0,0,0,0,0,2,0
2,1,1,15,0,0,7,1,1,1,2
0,1,3,3,3,3,3,3,3,1,0
0,1,3,2,2,2,2,2,3,1,0
0,0,3,2,2,2,2,2,3,15,0
0,0,3,2,2,2,2,2,3,15,0
0,1,3,2,2,2,2,2,3,0,0
0,1,3,2,2,2,2,2,3,14,0
0,1,3,3,3,3,3,3,3,6,0
2,1,1,15,15,15,14,14,1,1,2
0,2,0,0,0,0,0,0,0,2,0
endlayer

layer
0,2,0,0,0,0,0,0,0,2,0
2,1,1,1,5,0,0,14,1,1,2
0,1,3,3,3,3,3,3,3,1,0
0,0,3,2,2,2,2,2,3,15,0
0,1,3,2,2,2,2,2,3,0,0
0,1,3,2,2,2,2,2,3,0,0
0,0,3,2,2,2,2,2,3,0,0
0,1,3,2,2,2,2,2,3,15,0
0,1,3,3,3,3,3,3,3,1,0
2,1,1,15,0,14,0,14,1,1,2
0,2,0,0,0,0,0,0,0,2,0
endlayer

layer
0,2,0,0,0,0,0,0,0,2,0
2,1,1,1,1,0,0,0,1,1,2
0,1,3,3,3,3,3,3,3,1,0
0,0,3,2,2,2,2,2,3,9,0
0,0,3,2,2,2,2,2,3,0,0
0,0,3,2,2,2,2,2,3,1,0
0,0,3,2,2,2,2,2,3,14,0
0,1,3,2,2,2,2,2,3,14,0
0,1,3,3,3,3,3,3,3,1,0
2,1,1,0,0,14,14,16,1,1,2
0,2,0,0,0,0,0,0,0,2,0
endlayer

layer
0,2,0,0,0,0,0,0,0,2,0
2,1,1,14,0,0,0,12,1,1,2
0,1,3,3,3,3,3,3,3,1,0
0,1,3,2,2,2,2,2,3,1,0
0,0,3,2,2,2,2,2,3,15,0
0,1,3,2,2,2,2,2,3,0,0
0,1,3,2,2,2,2,2,3,0,0
0,0,3,2,2,2,2,2,3,11,0
0,1,3,3,3,3,3,3,3,1,0
2,1,1,14,0,15,15,15,1,1,2
0,2,0,0,0,0,0,0,0,2,0
endlayer

layer
0,2,0,0,0,0,0,0,0,2,0
2,1,1,1,1,5,0,7,1,1,2
0,1,3,3,3,3,3,3,3,9,0
0,1,3,2,2,2,2,2,3,0,0
0,1,3,2,2,2,2,2,3,0,0
0,0,3,2,2,2,2,2,3,11,0
0,0,3,2,2,2,2,2,3,15,0
0,1,3,2,2,2,2,2,3,14,0
0,1,3,3,3,3,3,3,3,1,0
2,1,1,14,14,0,15,0,1,1,2
0,2,0,0,0,0,0,0,0,2,0
endlayer

layer
0,2,0,0,0,0,0,0,0,2,0
2,1,1,5,0,0,15,15,1,1,2
0,1,3,3,3,3,3,3,3,1,0
0,1,3,2,2,2,2,2,3,0,0
0,0,3,2,2,2,2,2,3,6,0
0,1,3,2,2,2,2,2,3,9,0
0,0,3,2,2,2,2,2,3,0,0
0,0,3,2,2,2,2,2,3,15,0
0,1,3,3,3,3,3,3,3,1,0
2,1,1,0,15,15,0,14,1,1,2
0,2,0,0,0,0,0,0,0,2,0
endlayer

layer
0,2,0,0,0,0,0,0,0,2,0
2,1,1,1,15,0,0,7,1,1,2
0,1,3,3,3,3,3,3,3,1,0
0,0,3,2,2,2,2,2,3,9,0
0,0,3,2,2,2,2,2,3,0,0
0,1,3,2,2,2,2,2,3,15,0
0,1,3,2,2,2,2,2,3,13,0
0,0,3,2,2,2,2,2,3,0,0
0,1,3,3,3,3,3,3,3,6,0
2,1,1,15,0,15,15,1,1,1,2
0,2,0,0,0,0,0,0,0,2,0
endlayer

layer
0,2,0,0,0,0,0,0,0,2,0
2,1,10,0,0,15,1,12,1,1,2
0,1,3,3,3,3,3,3,3,1,0
0,1,3,2,2,2,2,2,3,15,0
0,0,3,2,2,2,2,2,3,0,0
0,0,3,2,2,2,2,2,3,15,0
0,1,3,2,2,2,2,2,3,14,0
0,1,3,2,2,2,2,2,3,1,0
0,1,3,3,3,3,3,3,3,1,0
2,1,1,0,15,0,14,14,1,1,2
0,2,0,0,0,0,0,0,0,2,0
endlayer

layer
0,2,0,0,0,0,0,0,0,2,0
2,1,1,1,1,1,1,1,1,1,2
0,1,3,3,3,3,3,3,3,1,0
0,1,3,2,2,2,2,2,3,1,0
0,1,3,2,2,2,2,2,3,1,0
0,1,3,2,2,2,2,2,3,1,0
0,1,3,2,2,2,2,2,3,15,0
0,1,3,2,2,2,2,2,3,11,0
0,1,3,3,3,3,3,3,3,1,0
2,1,1,1,1,1,1,1,1,1,2
0,2,0,0,0,0,0,0,0,2,0
endlayer

layer
0,2,0,0,0,0,0,0,0,2,0
2,1,1,5,14,0,14,1,1,1,2
0,1,3,3,3,3,3,3,3,1,0
0,1,3,2,2,2,2,2,3,13,0
0,1,3,2,2,2,2,2,3,0,0
0,1,3,2,2,2,2,2,3,0,0
0,0,3,2,2,2,2,2,3,14,0
0,1,3,2,2,2,2,2,3,1,0
0,1,3,3,3,3,3,3,3,1,0
2,1,1,14,14,0,0,14,1,1,2
0,2,0,0,0,0,0,0,0,2,0
endlayer

layer
0,2,0,0,0,0,0,0,0,2,0
2,1,1,0,0,14,1,1,1,1,2
0,1,3,3,3,3,3,3,3,1,0
0,1,3,2,2,2,2,2,3,9,0
0,0,3,2,2,2,2,2,3,6,0
0,0,3,2,2,2,2,2,3,15,0
0,1,3,2,2,2,2,2,3,0,0
0,0,3,2,2,2,2,2,3,0,0
0,1,3,3,3,3,3,3,3,1,0
2,1,1,15,0,15,5,14,1,1,2
0,2,0,0,0,0,0,0,0,2,0
endlayer

layer
0,2,0,0,0,0,0,0,0,2,0
2,1,1,1,5,0,1,14,1,1,2
0,1,3,3,3,3,3,3,3,1,0
0,1,3,2,2,2,2,2,3,1,0
0,1,3,2,2,2,2,2,3,14,0
0,0,3,2,2,2,2,2,3,0,0
0,1,3,2,2,2,2,2,3,15,0
0,1,3,2,2,2,2,2,3,13,0
0,1,3,3,3,3,3,3,3,11,0
2,1,1,0,0,15,15,15,1,1,2
0,2,0,0,0,0,0,0,0,2,0
endlayer

layer
0,2,0,0,0,0,0,0,0,2,0
2,1,1,14,0,0,0,12,1,1,2
0,1,3,3,3,3,3,3,3,1,0
0,0,3,2,2,2,2,2,3,15,0
0,0,3,2,2,2,2,2,3,0,0
0,1,3,2,2,2,2,2,3,14,0
0,0,3,2,2,2,2,2,3,1,0
0,0,3,2,2,2,2,2,3,1,0
0,1,3,3,3,3,3,3,3,1,0
2,1,1,1,14,0,14,14,1,1,2
0,2,0,0,0,0,0,0,0,2,0
endlayer

layer
0,2,0,0,0,0,0,0,0,2,0
2,1,1,1,0,0,0,1,1,1,2
0,1,3,3,3,3,3,3,3,1,0
0,1,3,2,2,2,2,2,3,9,0
0,0,3,2,2,2,2,2,3,0,0
0,0,3,2,2,2,2,2,3,15,0
0,0,3,2,2,2,2,2,3,0,0
0,1,3,2,2,2,2,2,3,6,0
0,1,3,3,3,3,3,3,3,1,0
2,1,1,1,14,14,0,14,1,1,2
0,2,0,0,0,0,0,0,0,2,0
endlayer

layer
0,2,0,0,0,0,0,0,0,2,0
2,1,1,5,15,10,0,0,1,1,2
0,1,3,3,3,3,3,3,3,9,0
0,0,3,2,2,2,2,2,3,1,0
0,1,3,2,2,2,2,2,3,15,0
0,1,3,2,2,2,2,2,3,0,0
0,1,3,2,2,2,2,2,3,13,0
0,0,3,2,2,2,2,2,3,0,0
0,1,3,3,3,3,3,3,3,11,0
2,1,1,14,0,15,15,1,1,1,2
0,2,0,0,0,0,0,0,0,2,0
endlayer

layer
0,2,0,0,0,0,0,0,0,2,0
2,1,1,0,12,1,0,14,1,1,2
0,1,3,3,3,3,3,3,3,1,0
0,0,3,2,2,2,2,2,3,0,0
0,0,3,2,2,2,2,2,3,0,0
0,1,3,2,2,2,2,2,3,0,0
0,0,3,2,2,2,2,2,3,15,0
0,0,3,2,2,2,2,2,3,0,0
0,1,3,3,3,3,3,3,3,6,0
2,1,1,1,15,0,0,15,1,1,2
0,2,0,0,0,0,0,0,0,2,0
endlayer

layer
0,2,0,0,0,0,0,0,0,2,0
2,1,1,0,0,12,10,0,1,1,2
0,1,3,3,3,3,3,3,3,1,0
0,0,3,2,2,2,2,2,3,13,0
0,1,3,2,2,2,2,2,3,0,0
0,1,3,2,2,2,2,2,3,14,0
0,0,3,2,2,2,2,2,3,14,0
0,1,3,2,2,2,2,2,3,1,0
0,1,3,3,3,3,3,3,3,11,0
2,1,1,15,15,0,14,7,1,1,2
0,2,0,0,0,0,0,0,0,2,0
endlayer

layer
0,2,0,0,0,0,0,0,0,2,0
2,1,1,0,1,1,0,15,1,1,2
0,1,3,3,3,3,3,3,3,1,0
0,1,3,2,2,2,2,2,3,14,0
0,1,3,2,2,2,2,2,3,0,0
0,0,3,2,2,2,2,2,3,15,0
0,0,3,2,2,2,2,2,3,0,0
0,1,3,2,2,2,2,2,3,11,0
0,1,3,3,3,3,3,3,3,1,0
2,1,1,15,0,0,15,15,1,1,2
0,2,0,0,0,0,0,0,0,2,0
endlayer

layer
0,2,0,0,0,0,0,0,0,2,0
2,1,1,1,1,1,1,1,1,1,2
0,1,3,3,3,3,3,3,3,1,0
0,1,3,2,2,2,2,2,3,1,0
0,1,3,2,2,2,2,2,3,11,0
0,1,3,2,2,2,2,2,3,1,0
0,1,3,2,2,2,2,2,3,1,0
0,1,3,2,2,2,2,2,3,1,0
0,1,3,3,3,3,3,3,3,1,0
2,1,1,1,1,1,1,1,1,1,2
0,2,0,0,0,0,0,0,0,2,0
endlayer

layer
0,2,0,0,0,0,0,0,0,2,0
2,1,1,14,1,0,14,7,1,1,2
0,1,3,3,3,3,3,3,3,1,0
0,1,3,2,2,2,2,2,3,6,0
0,1,3,2,2,2,2,2,3,1,0
0,0,3,2,2,2,2,2,3,14,0
0,0,3,2,2,2,2,2,3,0,0
0,1,3,2,2,2,2,2,3,6,0
0,1,3,3,3,3,3,3,3,1,0
2,1,1,0,14,0,15,15,1,1,2
0,2,0,0,0,0,0,0,0,2,0
endlayer

layer
0,2,0,0,0,0,0,0,0,2,0
2,1,1,10,0,10,15,0,7,1,2
0,1,3,3,3,3,3,3,3,1,0
0,1,3,2,2,2,2,2,3,0,0
0,0,3,2,2,2,2,2,3,9,0
0,0,3,2,2,2,2,2,3,0,0
0,1,3,2,2,2,2,2,3,13,0
0,1,3,2,2,2,2,2,3,0,0
0,1,3,3,3,3,3,3,3,1,0
2,1,1,14,14,14,0,12,1,1,2
0,2,0,0,0,0,0,0,0,2,0
endlayer

layer
0,2,0,0,0,0,0,0,0,2,0
2,1,1,5,0,14,5,0,12,1,2
0,1,3,3,3,3,3,3,3,1,0
0,0,3,2,2,2,2,2,3,13,0
0,0,3,2,2,2,2,2,3,15,0
0,1,3,2,2,2,2,2,3,14,0
0,1,3,2,2,2,2,2,3,0,0
0,1,3,2,2,2,2,2,3,11,0
0,1,3,3,3,3,3,3,3,1,0
2,1,1,15,15,14,0,14,1,1,2
0,2,0,0,0,0,0,0,0,2,0
endlayer

layer
0,2,0,0,0,0,0,0,0,2,0
2,1,5,0,0,15,0,15,1,1,2
0,1,3,3,3,3,3,3,3,1,0
0,0,3,2,2,2,2,2,3,14,0
0,0,3,2,2,2,2,2,3,0,0
0,0,3,2,2,2,2,2,3,15,0
0,0,3,2,2,2,2,2,3,1,0
0,0,3,2,2,2,2,2,3,1,0
0,1,3,3,3,3,3,3,3,1,0
2,1,1,0,0,12,1,1,1,1,2
0,2,0,0,0,0,0,0,0,2,0
endlayer

layer
0,2,0,0,0,0,0,0,0,2,0
2,1,10,10,0,0,14,1,1,1,2
0,1,3,3,3,3,3,3,3,1,0
0,1,3,2,2,2,2,2,3,9,0
0,0,3,2,2,2,2,2,3,0,0
0,0,3,2,2,2,2,2,3,0,0
0,0,3,2,2,2,2,2,3,0,0
0,1,3,2,2,2,2,2,3,6,0
0,1,3,3,3,3,3,3,3,1,0
2,1,1,14,14,14,14,0,1,1,2
0,2,0,0,0,0,0,0,0,2,0
endlayer

layer
0,2,0,0,0,0,0,0,0,2,0
2,1,1,1,10,15,0,7,1,1,2
0,1,3,3,3,3,3,3,3,1,0
0,1,3,2,2,2,2,2,3,14,0
0,1,3,2,2,2,2,2,3,15,0
0,1,3,2,2,2,2,2,3,1,0
0,1,3,2,2,2,2,2,3,13,0
0,0,3,2,2,2,2,2,3,0,0
0,1,3,3,3,3,3,3,3,11,0
2,1,1,5,0,14,14,1,1,1,2
0,2,0,0,0,0,0,0,0,2,0
endlayer

layer
0,2,0,0,0,0,0,0,0,2,0
2,1,1,1,1,1,15,0,1,1,2
0,1,3,3,3,3,3,3,3,1,0
0,0,3,2,2,2,2,2,3,1,0
0,0,3,2,2,2,2,2,3,9,0
0,1,3,2,2,2,2,2,3,14,0
0,0,3,2,2,2,2,2,3,0,0
0,0,3,2,2,2,2,2,3,0,0
0,1,3,3,3,3,3,3,3,11,0
2,1,1,15,15,0,12,1,1,1,2
0,2,0,0,0,0,0,0,0,2,0
endlayer

layer
0,2,0,0,0,0,0,0,0,2,0
2,1,5,0,0,14,0,0,1,1,2
0,1,3,3,3,3,3,3,3,1,0
0,0,3,2,2,2,2,2,3,14,0
0,1,3,2,2,2,2,2,3,0,0
0,1,3,2,2,2,2,2,3,15,0
0,0,3,2,2,2,2,2,3,0,0
0,1,3,2,2,2,2,2,3,6,0
0,1,3,3,3,3,3,3,3,1,0
2,1,1,1,0,0,15,15,1,1,2
0,2,0,0,0,0,0,0,0,2,0
endlayer

layer
0,2,0,0,0,0,0,0,0,2,0
2,1,1,1,15,15,0,12,1,1,2
0,1,3,3,3,3,3,3,3,13,0
0,1,3,2,2,2,2,2,3,0,0
0,1,3,2,2,2,2,2,3,13,0
0,0,3,2,2,2,2,2,3,9,0
0,0,3,2,2,2,2,2,3,0,0
0,1,3,2,2,2,2,2,3,11,0
0,1,3,3,3,3,3,3,3,1,0
2,1,1,15,15,0,0,14,1,1,2
0,2,0,0,0,0,0,0,0,2,0
endlayer

layer
0,2,0,0,0,0,0,0,0,2,0
2,1,1,1,1,1,1,1,1,1,2
0,1,3,3,3,3,3,3,3,1,0
0,1,3,2,2,2,2,2,3,1,0
0,1,3,2,2,2,2,2,3,1,0
0,1,3,2,2,2,2,2,3,1,0
0,1,3,2,2,2,2,2,3,1,0
0,1,3,2,2,2,2,2,3,1,0
0,1,3,3,3,3,3,3,3,1,0
2,1,1,1,1,1,1,1,1,1,2
0,2,0,0,0,0,0,0,0,2,0
endlayer

layer
0,2,0,0,0,0,0,0,0,2,0
2,1,1,1,1,0,1,0,7,1,2
0,1,3,3,3,3,3,3,3,1,0
0,1,3,2,2,2,2,2,3,1,0
0,0,3,2,2,2,2,2,3,14,0
0,1,3,2,2,2,2,2,3,0,0
0,1,3,2,2,2,2,2,3,15,0
0,1,3,2,2,2,2,2,3,11,0
0,1,3,3,3,3,3,3,3,1,0
2,1,1,0,1,14,14,14,1,1,2
0,2,0,0,0,0,0,0,0,2,0
endlayer

layer
0,2,0,0,0,0,0,0,0,2,0
2,1,1,5,1,10,0,0,1,1,2
0,1,3,3,3,3,3,3,3,13,0
0,0,3,2,2,2,2,2,3,0,0
0,0,3,2,2,2,2,2,3,0,0
0,1,3,2,2,2,2,2,3,6,0
0,0,3,2,2,2,2,2,3,14,0
0,1,3,2,2,2,2,2,3,6,0
0,1,3,3,3,3,3,3,3,1,0
2,1,1,14,14,0,15,12,1,1,2
0,2,0,0,0,0,0,0,0,2,0
endlayer

layer
0,2,0,0,0,0,0,0,0,2,0
2,1,1,10,0,5,0,12,1,1,2
0,1,3,3,3,3,3,3,3,1,0
0,1,3,2,2,2,2,2,3,1,0
0,1,3,2,2,2,2,2,3,13,0
0,0,3,2,2,2,2,2,3,0,0
0,0,3,2,2,2,2,2,3,0,0
0,0,3,2,2,2,2,2,3,14,0
0,1,3,3,3,3,3,3,3,1,0
2,1,1,0,15,15,0,0,1,1,2
0,2,0,0,0,0,0,0,0,2,0
endlayer

layer
0,2,0,0,0,0,0,0,0,2,0
2,1,1,5,0,0,12,1,1,1,2
0,1,3,3,3,3,3,3,3,1,0
0,0,3,2,2,2,2,2,3,14,0
0,0,3,2,2,2,2,2,3,0,0
0,0,3,2,2,2,2,2,3,0,0
0,1,3,2,2,2,2,2,3,15,0
0,1,3,2,2,2,2,2,3,1,0
0,1,3,3,3,3,3,3,3,1,0
2,1,1,1,0,15,15,1,1,1,2
0,2,0,0,0,0,0,0,0,2,0
endlayer

layer
0,2,0,0,0,0,0,0,0,2,0
2,1,5,0,0,0,0,7,1,1,2
0,1,3,3,3,3,3,3,3,1,0
0,1,3,2,2,2,2,2,3,1,0
0,0,3,2,2,2,2,2,3,0,0
0,0,3,2,2,2,2,2,3,0,0
0,0,3,2,2,2,2,2,3,0,0
0,1,3,2,2,2,2,2,3,6,0
0,1,3,3,3,3,3,3,3,1,0
2,1,1,15,0,0,0,1,1,1,2
0,2,0,0,0,0,0,0,0,2,0
endlayer

layer
0,2,0,0,0,0,0,0,0,2,0
2,1,10,0,15,12,1,0,1,1,2
0,1,3,3,3,3,3,3,3,1,0
0,0,3,2,2,2,2,2,3,9,0
0,0,3,2,2,2,2,2,3,14,0
0,1,3,2,2,2,2,2,3,0,0
0,1,3,2,2,2,2,2,3,0,0
0,1,3,2,2,2,2,2,3,11,0
0,1,3,3,3,3,3,3,3,1,0
2,1,1,1,1,15,15,0,1,1,2
0,2,0,0,0,0,0,0,0,2,0
endlayer

layer
0,2,0,0,0,0,0,0,0,2,0
2,1,1,0,7,1,5,0,1,1,2
0,1,3,3,3,3,3,3,3,1,0
0,0,3,2,2,2,2,2,3,1,0
0,0,3,2,2,2,2,2,3,13,0
0,0,3,2,2,2,2,2,3,0,0
0,1,3,2,2,2,2,2,3,14,0
0,0,3,2,2,2,2,2,3,14,0
0,1,3,3,3,3,3,3,3,11,0
2,1,1,0,0,15,15,0,1,1,2
0,2,0,0,0,0,0,0,0,2,0
endlayer

layer
0,2,0,0,0,0,0,0,0,2,0
2,1,1,10,0,1,0,0,1,1,2
0,1,3,3,3,3,3,3,3,1,0
0,0,3,2,2,2,2,2,3,15,0
0,1,3,2,2,2,2,2,3,0,0
0,0,3,2,2,2,2,2,3,0,0
0,0,3,2,2,2,2,2,3,1,0
0,0,3,2,2,2,2,2,3,1,0
0,1,3,3,3,3,3,3,3,1,0
2,1,1,14,14,1,0,1,1,1,2
0,2,0,0,0,0,0,0,0,2,0
endlayer

layer
0,2,0,0,0,0,0,0,0,2,0
2,1,1,0,1,10,0,12,1,1,2
0,1,3,3,3,3,3,3,3,1,0
0,1,3,2,2,2,2,2,3,1,0
0,1,3,2,2,2,2,2,3,13,0
0,0,3,2,2,2,2,2,3,15,0
0,1,3,2,2,2,2,2,3,0,0
0,1,3,2,2,2,2,2,3,14,0
0,1,3,3,3,3,3,3,3,1,0
2,1,1,1,15,0,14,14,1,1,2
0,2,0,0,0,0,0,0,0,2,0
endlayer

layer
0,2,0,0,0,0,0,0,0,2,0
2,1,1,1,1,1,1,1,1,1,2
0,1,3,3,3,3,3,3,3,1,0
0,1,3,2,2,2,2,2,3,1,0
0,1,3,2,2,2,2,2,3,1,0
0,1,3,2,2,2,2,2,3,1,0
0,1,3,2,2,2,2,2,3,1,0
0,1,3,2,2,2,2,2,3,1,0
0,1,3,3,3,3,3,3,3,1,0
2,1,1,1,1,1,1,1,1,1,2
0,2,0,0,0,0,0,0,0,2,0
endlayer

layer
0,2,0,0,0,0,0,0,0,2,0
2,1,1,1,1,0,7,0,7,1,2
0,1,3,3,3,3,3,3,3,1,0
0,0,3,2,2,2,2,2,3,1,0
0,1,3,2,2,2,2,2,3,14,0
0,1,3,2,2,2,2,2,3,0,0
0,0,3,2,2,2,2,2,3,14,0
0,1,3,2,2,2,2,2,3,1,0
0,1,3,3,3,3,3,3,3,1,0
2,1,1,14,0,15,15,1,1,1,2
0,2,0,0,0,0,0,0,0,2,0
endlayer

layer
0,2,0,0,0,0,0,0,0,2,0
2,1,1,14,1,10,0,0,1,1,2
0,1,3,3,3,3,3,3,3,1,0
0,0,3,2,2,2,2,2,3,9,0
0,0,3,2,2,2,2,2,3,0,0
0,0,3,2,2,2,2,2,3,0,0
0,0,3,2,2,2,2,2,3,11,0
0,1,3,2,2,2,2,2,3,15,0
0,1,3,3,3,3,3,3,3,1,0
2,1,1,14,7,0,0,15,1,1,2
0,2,0,0,0,0,0,0,0,2,0
endlayer

layer
0,2,0,0,0,0,0,0,0,2,0
2,1,10,0,0,7,0,12,1,1,2
0,1,3,3,3,3,3,3,3,13,0
0,1,3,2,2,2,2,2,3,0,0
0,1,3,2,2,2,2,2,3,6,0
0,0,3,2,2,2,2,2,3,15,0
0,0,3,2,2,2,2,2,3,0,0
0,0,3,2,2,2,2,2,3,15,0
0,1,3,3,3,3,3,3,3,1,0
2,1,1,0,15,15,0,0,1,1,2
0,2,0,0,0,0,0,0,0,2,0
endlayer

layer
0,2,0,0,0,0,0,0,0,2,0
2,1,1,5,0,0,12,1,1,1,2
0,1,3,3,3,3,3,3,3,1,0
0,0,3,2,2,2,2,2,3,15,0
0,0,3,2,2,2,2,2,3,0,0
0,0,3,2,2,2,2,2,3,6,0
0,1,3,2,2,2,2,2,3,15,0
0,1,3,2,2,2,2,2,3,6,0
0,1,3,3,3,3,3,3,3,1,0
2,1,1,1,0,15,15,1,1,1,2
0,2,0,0,0,0,0,0,0,2,0
endlayer

layer
0,2,0,0,0,0,0,0,0,2,0
2,1,1,15,0,0,0,7,1,1,2
0,1,3,3,3,3,3,3,3,1,0
0,1,3,2,2,2,2,2,3,14,0
0,0,3,2,2,2,2,2,3,15,0
0,0,3,2,2,2,2,2,3,0,0
0,0,3,2,2,2,2,2,3,0,0
0,1,3,2,2,2,2,2,3,6,0
0,1,3,3,3,3,3,3,3,1,0
2,1,1,14,0,0,14,1,1,1,2
0,2,0,0,0,0,0,0,0,2,0
endlayer

layer
0,2,0,0,0,0,0,0,0,2,0
2,1,1,1,10,0,15,0,1,1,2
0,1,3,3,3,3,3,3,3,1,0
0,1,3,2,2,2,2,2,3,13,0
0,0,3,2,2,2,2,2,3,11,0
0,1,3,2,2,2,2,2,3,9,0
0,0,3,2,2,2,2,2,3,0,0
0,0,3,2,2,2,2,2,3,0,0
0,1,3,3,3,3,3,3,3,11,0
2,1,1,1,0,14,14,1,1,1,2
0,2,0,0,0,0,0,0,0,2,0
endlayer

layer
0,2,0,0,0,0,0,0,0,2,0
2,1,1,5,0,0,7,1,1,1,2
0,1,3,3,3,3,3,3,3,9,0
0,0,3,2,2,2,2,2,3,0,0
0,0,3,2,2,2,2,2,3,14,0
0,0,3,2,2,2,2,2,3,1,0
0,1,3,2,2,2,2,2,3,13,0
0,1,3,2,2,2,2,2,3,0,0
0,1,3,3,3,3,3,3,3,11,0
2,1,1,0,14,0,14,1,1,1,2
0,2,0,0,0,0,0,0,0,2,0
endlayer

layer
0,2,0,0,0,0,0,0,0,2,0
2,1,1,0,1,10,0,1,1,1,2
0,1,3,3,3,3,3,3,3,1,0
0,1,3,2,2,2,2,2,3,1,0
0,1,3,2,2,2,2,2,3,15,0
0,0,3,2,2,2,2,2,3,0,0
0,0,3,2,2,2,2,2,3,14,0
0,0,3,2,2,2,2,2,3,15,0
0,1,3,3,3,3,3,3,3,1,0
2,1,1,14,14,0,1,0,1,1,2
0,2,0,0,0,0,0,0,0,2,0
endlayer

layer
0,2,0,0,0,0,0,0,0,2,0
2,1,1,1,14,0,0,15,1,1,2
0,1,3,3,3,3,3,3,3,1,0
0,1,3,2,2,2,2,2,3,0,0
0,0,3,2,2,2,2,2,3,15,0
0,0,3,2,2,2,2,2,3,15,0
0,1,3,2,2,2,2,2,3,0,0
0,1,3,2,2,2,2,2,3,6,0
0,1,3,3,3,3,3,3,3,1,0
2,1,1,15,1,15,0,1,1,1,2
0,2,0,0,0,0,0,0,0,2,0
endlayer

layer
0,2,0,0,0,0,0,0,0,2,0
2,1,1,1,1,1,1,1,1,1,2
0,1,3,3,3,3,3,3,3,1,0
0,1,3,2,2,2,2,2,3,1,0
0,1,3,2,2,2,2,2,3,1,0
0,1,3,2,2,2,2,2,3,1,0
0,1,3,2,2,2,2,2,3,1,0
0,1,3,2,2,2,2,2,3,1,0
0,1,3,3,3,3,3,3,3,1,0
2,1,1,1,1,1,1,1,1,1,2
0,2,0,0,0,0,0,0,0,2,0
endlayer

layer
0,2,0,0,0,0,0,0,0,2,0
2,1,5,14,1,14,0,14,1,1,2
0,1,3,3,3,3,3,3,3,1,0
0,1,3,2,2,2,2,2,3,1,0
0,1,3,2,2,2,2,2,3,15,0
0,1,3,2,2,2,2,2,3,0,0
0,0,3,2,2,2,2,2,3,14,0
0,1,3,2,2,2,2,2,3,1,0
0,1,3,3,3,3,3,3,3,1,0
2,1,1,15,15,14,0,15,1,1,2
0,2,0,0,0,0,0,0,0,2,0
endlayer

layer
0,2,0,0,0,0,0,0,0,2,0
2,1,1,0,0,5,0,0,1,1,2
0,1,3,3,3,3,3,3,3,1,0
0,1,3,2,2,2,2,2,3,14,0
0,0,3,2,2,2,2,2,3,0,0
0,1,3,2,2,2,2,2,3,15,0
0,0,3,2,2,2,2,2,3,15,0
0,1,3,2,2,2,2,2,3,6,0
0,1,3,3,3,3,3,3,3,1,0
2,1,1,0,14,1,15,0,1,1,2
0,2,0,0,0,0,0,0,0,2,0
endlayer

layer
0,2,0,0,0,0,0,0,0,2,0
2,1,1,1,0,12,1,15,1,1,2
0,1,3,3,3,3,3,3,3,9,0
0,0,3,2,2,2,2,2,3,14,0
0,1,3,2,2,2,2,2,3,0,0
0,0,3,2,2,2,2,2,3,11,0
0,1,3,2,2,2,2,2,3,0,0
0,0,3,2,2,2,2,2,3,0,0
0,1,3,3,3,3,3,3,3,1,0
2,1,1,0,14,14,0,1,1,1,2
0,2,0,0,0,0,0,0,0,2,0
endlayer

layer
0,2,0,0,0,0,0,0,0,2,0
2,1,1,10,0,0,12,1,1,1,2
0,1,3,3,3,3,3,3,3,13,0
0,1,3,2,2,2,2,2,3,0,0
0,0,3,2,2,2,2,2,3,6,0
0,0,3,2,2,2,2,2,3,14,0
0,1,3,2,2,2,2,2,3,9,0
0,1,3,2,2,2,2,2,3,15,0
0,1,3,3,3,3,3,3,3,11,0
2,1,1,1,0,14,0,0,1,1,2
0,2,0,0,0,0,0,0,0,2,0
endlayer

layer
0,2,0,0,0,0,0,0,0,2,0
2,1,1,5,0,0,0,15,1,1,2
0,1,3,3,3,3,3,3,3,13,0
0,1,3,2,2,2,2,2,3,14,0
0,0,3,2,2,2,2,2,3,15,0
0,0,3,2,2,2,2,2,3,0,0
0,0,3,2,2,2,2,2,3,0,0
0,1,3,2,2,2,2,2,3,15,0
0,1,3,3,3,3,3,3,3,1,0
2,1,1,15,0,0,0,14,1,1,2
0,2,0,0,0,0,0,0,0,2,0
endlayer

layer
0,2,0,0,0,0,0,0,0,2,0
2,1,1,0,15,1,1,1,1,1,2
0,1,3,3,3,3,3,3,3,1,0
0,0,3,2,2,2,2,2,3,14,0
0,0,3,2,2,2,2,2,3,0,0
0,1,3,2,2,2,2,2,3,11,0
0,1,3,2,2,2,2,2,3,14,0
0,1,3,2,2,2,2,2,3,6,0
0,1,3,3,3,3,3,3,3,1,0
2,1,1,14,14,0,15,1,1,1,2
0,2,0,0,0,0,0,0,0,2,0
endlayer

layer
0,2,0,0,0,0,0,0,0,2,0
2,1,5,0,1,1,14,0,12,1,2
0,1,3,3,3,3,3,3,3,1,0
0,1,3,2,2,2,2,2,3,9,0
0,1,3,2,2,2,2,2,3,0,0
0,0,3,2,2,2,2,2,3,6,0
0,0,3,2,2,2,2,2,3,9,0
0,0,3,2,2,2,2,2,3,0,0
0,1,3,3,3,3,3,3,3,1,0
2,1,1,1,1,14,0,0,1,1,2
0,2,0,0,0,0,0,0,0,2,0
endlayer

layer
0,2,0,0,0,0,0,0,0,2,0
2,1,1,10,0,1,5,0,12,1,2
0,1,3,3,3,3,3,3,3,1,0
0,1,3,2,2,2,2,2,3,0,0
0,0,3,2,2,2,2,2,3,0,0
0,0,3,2,2,2,2,2,3,0,0
0,1,3,2,2,2,2,2,3,0,0
0,1,3,2,2,2,2,2,3,0,0
0,1,3,3,3,3,3,3,3,11,0
2,1,1,0,0,15,5,14,1,1,2
0,2,0,0,0,0,0,0,0,2,0
endlayer

layer
0,2,0,0,0,0,0,0,0,2,0
2,1,1,5,0,0,12,1,1,1,2
0,1,3,3,3,3,3,3,3,1,0
0,1,3,2,2,2,2,2,3,9,0
0,1,3,2,2,2,2,2,3,15,0
0,0,3,2,2,2,2,2,3,0,0
0,0,3,2,2,2,2,2,3,11,0
0,1,3,2,2,2,2,2,3,13,0
0,1,3,3,3,3,3,3,3,1,0
2,1,1,1,0,0,14,1,1,1,2
0,2,0,0,0,0,0,0,0,2,0
endlayer

layer
0,2,0,0,0,0,0,0,0,2,0
2,1,1,1,1,1,1,1,1,1,2
0,1,3,3,3,3,3,3,3,1,0
0,1,3,2,2,2,2,2,3,1,0
0,1,3,2,2,2,2,2,3,1,0
0,1,3,2,2,2,2,2,3,1,0
0,1,3,2,2,2,2,2,3,1,0
0,1,3,2,2,2,2,2,3,1,0
0,1,3,3,3,3,3,3,3,1,0
2,1,1,1,1,1,1,1,1,1,2
0,2,0,0,0,0,0,0,0,2,0
endlayer

layer
0,2,0,0,0,0,0,0,0,2,0
2,1,1,1,5,0,14,7,1,1,2
0,1,3,3,3,3,3,3,3,1,0
0,0,3,2,2,2,2,2,3,1,0
0,0,3,2,2,2,2,2,3,9,0
0,1,3,2,2,2,2,2,3,0,0
0,1,3,2,2,2,2,2,3,14,0
0,0,3,2,2,2,2,2,3,1,0
0,1,3,3,3,3,3,3,3,1,0
2,1,1,15,15,1,14,0,1,1,2
0,2,0,0,0,0,0,0,0,2,0
endlayer

layer
0,2,0,0,0,0,0,0,0,2,0
2,1,1,5,14,0,0,14,1,1,2
0,1,3,3,3,3,3,3,3,1,0
0,1,3,2,2,2,2,2,3,1,0
0,0,3,2,2,2,2,2,3,15,0
0,1,3,2,2,2,2,2,3,0,0
0,1,3,2,2,2,2,2,3,14,0
0,0,3,2,2,2,2,2,3,6,0
0,1,3,3,3,3,3,3,3,1,0
2,1,1,0,14,14,15,15,1,1,2
0,2,0,0,0,0,0,0,0,2,0
endlayer

layer
0,2,0,0,0,0,0,0,0,2,0
2,1,1,1,10,0,15,1,1,1,2
0,1,3,3,3,3,3,3,3,1,0
0,0,3,2,2,2,2,2,3,9,0
0,1,3,2,2,2,2,2,3,0,0
0,0,3,2,2,2,2,2,3,11,0
0,0,3,2,2,2,2,2,3,14,0
0,1,3,2,2,2,2,2,3,0,0
0,1,3,3,3,3,3,3,3,6,0
2,1,1,14,1,0,0,15,1,1,2
0,2,0,0,0,0,0,0,0,2,0
endlayer

layer
0,2,0,0,0,0,0,0,0,2,0
2,1,1,1,5,0,7,1,1,1,2
0,1,3,3,3,3,3,3,3,1,0
0,1,3,2,2,2,2,2,3,0,0
0,0,3,2,2,2,2,2,3,14,0
0,0,3,2,2,2,2,2,3,1,0
0,1,3,2,2,2,2,2,3,13,0
0,1,3,2,2,2,2,2,3,0,0
0,1,3,3,3,3,3,3,3,1,0
2,1,1,1,0,1,14,14,1,1,2
0,2,0,0,0,0,0,0,0,2,0
endlayer

layer
0,2,0,0,0,0,0,0,0,2,0
2,1,1,15,0,0,0,14,1,1,2
0,1,3,3,3,3,3,3,3,13,0
0,0,3,2,2,2,2,2,3,11,0
0,0,3,2,2,2,2,2,3,14,0
0,0,3,2,2,2,2,2,3,0,0
0,0,3,2,2,2,2,2,3,0,0
0,1,3,2,2,2,2,2,3,15,0
0,1,3,3,3,3,3,3,3,6,0
2,1,1,14,14,0,0,14,1,1,2
0,2,0,0,0,0,0,0,0,2,0
endlayer

layer
0,2,0,0,0,0,0,0,0,2,0
2,1,1,1,1,5,0,1,1,1,2
0,1,3,3,3,3,3,3,3,1,0
0,1,3,2,2,2,2,2,3,9,0
0,1,3,2,2,2,2,2,3,0,0
0,0,3,2,2,2,2,2,3,15,0
0,0,3,2,2,2,2,2,3,6,0
0,1,3,2,2,2,2,2,3,6,0
0,1,3,3,3,3,3,3,3,1,0
2,1,1,1,1,15,0,1,1,1,2
0,2,0,0,0,0,0,0,0,2,0
endlayer

layer
0,2,0,0,0,0,0,0,0,2,0
2,1,1,1,14,0,12,14,1,1,2
0,1,3,3,3,3,3,3,3,1,0
0,0,3,2,2,2,2,2,3,0,0
0,1,3,2,2,2,2,2,3,13,0
0,1,3,2,2,2,2,2,3,0,0
0,0,3,2,2,2,2,2,3,0,0
0,0,3,2,2,2,2,2,3,6,0
0,1,3,3,3,3,3,3,3,1,0
2,1,1,1,15,0,15,15,1,1,2
0,2,0,0,0,0,0,0,0,2,0
endlayer

layer
0,2,0,0,0,0,0,0,0,2,0
2,1,1,1,10,0,0,0,1,1,2
0,1,3,3,3,3,3,3,3,1,0
0,0,3,2,2,2,2,2,3,9,0
0,0,3,2,2,2,2,2,3,0,0
0,1,3,2,2,2,2,2,3,15,0
0,0,3,2,2,2,2,2,3,13,0
0,1,3,2,2,2,2,2,3,15,0
0,1,3,3,3,3,3,3,3,1,0
2,1,1,0,15,15,0,0,1,1,2
0,2,0,0,0,0,0,0,0,2,0
endlayer

layer
0,2,0,0,0,0,0,0,0,2,0
2,1,1,15,0,0,15,1,1,1,2
0,1,3,3,3,3,3,3,3,1,0
0,1,3,2,2,2,2,2,3,15,0
0,0,3,2,2,2,2,2,3,0,0
0,1,3,2,2,2,2,2,3,14,0
0,0,3,2,2,2,2,2,3,0,0
0,0,3,2,2,2,2,2,3,14,0
0,1,3,3,3,3,3,3,3,1,0
2,1,1,0,15,0,14,1,1,1,2
0,2,0,0,0,0,0,0,0,2,0
endlayer

layer
0,2,0,0,0,0,0,0,0,2,0
2,1,1,1,1,1,1,1,1,1,2
0,1,3,3,3,3,3,3,3,1,0
0,1,3,2,2,2,2,2,3,13,0
0,1,3,2,2,2,2,2,3,1,0
0,1,3,2,2,2,2,2,3,13,0
0,1,3,2,2,2,2,2,3,11,0
0,1,3,2,2,2,2,2,3,1,0
0,1,3,3,3,3,3,3,3,1,0
2,1,1,1,1,1,1,1,1,1,2
0,2,0,0,0,0,0,0,0,2,0
endlayer

layer
0,2,10,0,0,0,0,0,12,2,0
2,1,1,1,1,1,1,1,1,1,2
13,1,2,2,2,2,2,2,2,1,13
0,1,2,2,2,2,2,2,2,1,0
0,1,2,2,2,2,2,2,2,1,0
0,1,2,2,2,2,2,2,2,1,0
0,1,2,2,2,2,2,2,2,1,0
0,1,2,2,2,2,2,2,2,1,0
11,1,2,2,2,2,2,2,2,1,11
2,1,1,1,1,1,1,1,1,1,2
0,2,10,0,0,0,0,0,12,2,0
endlayer

layer
0,2,2,10,15,0,15,12,2,2,0
2,1,1,1,1,1,1,1,1,1,2
2,1,2,2,2,2,2,2,2,1,2
13,1,2,2,2,2,2,2,2,1,13
15,1,2,2,2,2,2,2,2,1,15
0,1,2,2,2,2,2,2,2,1,0
15,1,2,2,2,2,2,2,2,1,15
11,1,2,2,2,2,2,2,2,1,11
2,1,2,2,2,2,2,2,2,1,2
2,1,1,1,1,1,1,1,1,1,2
0,2,2,10,15,0,15,12,2,2,0
endlayer

layer
0,14,14,2,2,2,2,2,14,14,0
14,1,1,1,1,1,1,1,1,1,14
14,1,2,2,2,2,2,2,2,1,14
2,1,2,2,2,2,2,2,2,1,2
2,1,2,2,2,2,2,2,2,1,2
2,1,2,2,2,2,2,2,2,1,2
2,1,2,2,2,2,2,2,2,1,2
2,1,2,2,2,2,2,2,2,1,2
14,1,2,2,2,2,2,2,2,1,14
14,1,1,1,1,1,1,1,1,1,14
0,14,14,2,2,2,2,2,14,14,0
endlayer

layer
2,2,2,2,2,2,2,2,2,2,2
2,1,1,1,1,1,1,1,1,1,2
2,1,2,2,2,2,2,2,2,1,2
2,1,2,2,2,2,2,2,2,1,2
2,1,2,2,2,2,2,2,2,1,2
2,1,2,2,2,2,2,2,2,1,2
2,1,2,2,2,2,2,2,2,1,2
2,1,2,2,2,2,2,2,2,1,2
2,1,2,2,2,2,2,2,2,1,2
2,1,1,1,1,1,1,1,1,1,2
2,2,2,2,2,2,2,2,2,2,2
endlayer

layer
15,15,15,15,2,2,2,15,15,15,15
15,1,1,1,1,1,1,1,1,1,15
15,1,2,2,2,2,2,2,2,1,15
15,1,2,2,2,2,2,2,2,1,15
2,1,2,2,2,2,2,2,2,1,2
2,1,2,2,2,2,2,2,2,1,2
2,1,2,2,2,2,2,2,2,1,2
15,1,2,2,2,2,2,2,2,1,15
15,1,2,2,2,2,2,2,2,1,15
15,1,1,1,1,1,1,1,1,1,15
15,15,15,15,2,2,2,15,15,15,15
endlayer

layer
14,14,14,14,2,2,2,14,14,14,14
14,1,1,1,1,1,1,1,1,1,14
14,1,2,2,2,2,2,2,2,1,14
14,1,2,2,2,2,2,2,2,1,14
2,1,2,2,2,2,2,2,2,1,2
2,1,2,2,2,2,2,2,2,1,2
2,1,2,2,2,2,2,2,2,1,2
14,1,2,2,2,2,2,2,2,1,14
14,1,2,2,2,2,2,2,2,1,14
14,1,1,1,1,1,1,1,1,1,14
14,14,14,14,2,2,2,14,14,14,14
endlayer

layer
2,2,2,2,2,2,2,2,2,2,2
2,1,1,1,1,1,1,1,1,1,2
2,1,2,2,2,2,2,2,2,1,2
2,1,2,2,2,2,2,2,2,1,2
2,1,2,2,2,2,2,2,2,1,2
2,1,2,2,2,2,2,2,2,1,2
2,1,2,2,2,2,2,2,2,1,2
2,1,2,2,2,2,2,2,2,1,2
2,1,2,2,2,2,2,2,2,1,2
2,1,1,1,1,1,1,1,1,1,2
2,2,2,2,2,2,2,2,2,2,2
endlayer

layer
15,15,15,2,2,2,2,2,15,15,15
15,1,1,1,1,1,1,1,1,1,15
15,1,2,2,2,2,2,2,2,1,15
2,1,2,2,2,2,2,2,2,1,2
2,1,2,2,2,2,2,2,2,1,2
2,1,2,2,2,2,2,2,2,1,2
2,1,2,2,2,2,2,2,2,1,2
2,1,2,2,2,2,2,2,2,1,2
15,1,2,2,2,2,2,2,2,1,15
15,1,1,1,1,1,1,1,1,1,15
15,15,15,2,2,2,2,2,15,15,15
endlayer

layer
14,14,2,2,2,2,2,2,2,14,14
14,1,1,1,1,1,1,1,1,1,14
2,1,2,2,2,2,2,2,2,1,2
2,1,2,2,2,2,2,2,2,1,2
2,1,2,2,2,2,2,2,2,1,2
2,1,2,2,2,2,2,2,2,1,2
2,1,2,2,2,2,2,2,2,1,2
2,1,2,2,2,2,2,2,2,1,2
2,1,2,2,2,2,2,2,2,1,2
14,1,1,1,1,1,1,1,1,1,14
14,14,2,2,2,2,2,2,2,14,14
endlayer

layer
2,2,2,2,14,14,14,2,2,2,2
2,1,1,1,1,1,1,1,1,1,2
2,1,2,2,2,2,2,2,2,1,2
2,1,2,2,2,2,2,2,2,1,2
14,1,2,2,2,2,2,2,2,1,14
14,1,2,2,2,2,2,2,2,1,14
14,1,2,2,2,2,2,2,2,1,14
2,1,2,2,2,2,2,2,2,1,2
2,1,2,2,2,2,2,2,2,1,2
2,1,1,1,1,1,1,1,1,1,2
2,2,2,2,14,14,14,2,2,2,2
endlayer

layer
0,14,0,0,0,0,0,0,0,14,0
14,8,14,0,0,0,0,0,14,8,14
0,14,14,0,0,0,0,0,14,14,0
0,0,0,0,0,0,0,0,0,0,0
0,0,0,0,0,0,0,0,0,0,0
0,0,0,0,0,0,0,0,0,0,0
0,0,0,0,0,0,0,0,0,0,0
0,0,0,0,0,0,0,0,0,0,0
0,14,14,0,0,0,0,0,14,14,0
14,8,14,0,0,0,0,0,14,8,14
0,14,0,0,0,0,0,0,0,14,0
endlayer

