
# Created by Ruins mod version 16.5 Ingame Parser
# authoring Player: lafuller

weight=1
embed_into_distance=28
acceptable_target_blocks=
unacceptable_target_blocks=flowing_water,water,flowing_lava,lava,ice,bedrock,netherrack,nether_brick,nether_brick_fence,soul_sand,quartz_ore,end_stone,obsidian,iron_bars,cloud,flesh,ash_block,slime_grass,slime_congealed,slime_dirt
biomesToSpawnIn=desert
dimensions=33,9,9
allowable_overhang=0
max_leveling=7
leveling_buffer=-1
preserve_water=0
preserve_lava=0

rule1=0,100,minecraft:double_stone_slab-9
rule2=0,100,minecraft:water-0
rule3=0,100,minecraft:sandstone_stairs-0
rule4=0,100,minecraft:stone_slab-1
rule5=0,100,minecraft:sandstone-2
rule6=0,100,minecraft:iron_bars-0
rule7=2,100,minecraft:torch-1
rule8=0,100,minecraft:sandstone-1
rule9=0,100,minecraft:sandstone_stairs-2
rule10=0,100,minecraft:sandstone_stairs-6
rule11=0,100,minecraft:sandstone_stairs-5
rule12=2,100,minecraft:torch-3
rule13=0,100,minecraft:sandstone_stairs-1
rule14=0,100,minecraft:sandstone_stairs-7
rule15=0,100,minecraft:sandstone_stairs-3
rule16=2,100,minecraft:torch-2
rule17=0,100,minecraft:sandstone_stairs-4
rule18=2,100,minecraft:torch-4
rule19=0,100,preserveBlock
rule20=0,100,minecraft:wooden_slab-9
rule21=0,100,minecraft:dark_oak_fence-0
rule22=0,100,minecraft:spruce_fence_gate-2
rule23=0,100,minecraft:spruce_fence-0
rule24=0,100,minecraft:wooden_slab-1
rule25=0,100,minecraft:trapdoor-0
rule26=0,100,minecraft:trapdoor-1

layer
1,1,1,1,1,1,1,1,1
1,1,1,1,1,1,1,1,1
1,1,1,1,1,1,1,1,1
1,1,1,1,1,1,1,1,1
1,1,1,1,1,1,1,1,1
1,1,1,1,1,1,1,1,1
1,1,1,1,1,1,1,1,1
1,1,1,1,1,1,1,1,1
1,1,1,1,1,1,1,1,1
endlayer

layer
1,1,1,1,1,1,1,1,1
1,1,1,1,1,1,1,1,1
1,1,1,1,1,1,1,1,1
1,1,1,2,2,2,1,1,1
1,1,1,2,2,2,1,1,1
1,1,1,2,2,2,1,1,1
1,1,1,1,1,1,1,1,1
1,1,1,1,1,1,1,1,1
1,1,1,1,1,1,1,1,1
endlayer

layer
1,1,1,1,1,1,1,1,1
1,1,1,1,1,1,1,1,1
1,1,1,1,1,1,1,1,1
1,1,1,2,2,2,1,1,1
1,1,1,2,2,2,1,1,1
1,1,1,2,2,2,1,1,1
1,1,1,1,1,1,1,1,1
1,1,1,1,1,1,1,1,1
1,1,1,1,1,1,1,1,1
endlayer

layer
1,1,1,1,1,1,1,1,1
1,1,1,1,1,1,1,1,1
1,1,1,1,1,1,1,1,1
1,1,1,2,2,2,1,1,1
1,1,1,2,2,2,1,1,1
1,1,1,2,2,2,1,1,1
1,1,1,1,1,1,1,1,1
1,1,1,1,1,1,1,1,1
1,1,1,1,1,1,1,1,1
endlayer

layer
1,1,1,1,1,1,1,1,1
1,1,1,1,1,1,1,1,1
1,1,1,1,1,1,1,1,1
1,1,1,2,2,2,1,1,1
1,1,1,2,2,2,1,1,1
1,1,1,2,2,2,1,1,1
1,1,1,1,1,1,1,1,1
1,1,1,1,1,1,1,1,1
1,1,1,1,1,1,1,1,1
endlayer

layer
1,1,1,1,1,1,1,1,1
1,1,1,4,4,4,4,3,1
1,1,5,4,4,4,5,1,1
1,1,1,0,0,0,1,1,1
1,1,1,0,6,0,1,1,1
1,1,1,0,0,0,1,1,1
1,1,1,1,1,1,1,1,1
1,1,1,1,1,1,1,1,1
1,1,1,1,1,1,1,1,1
endlayer

layer
1,1,1,1,1,1,1,1,1
1,1,1,0,0,0,0,0,1
1,1,1,0,0,0,1,3,1
1,1,1,0,0,0,1,1,1
1,1,1,0,6,0,1,1,1
1,1,1,0,0,0,1,1,1
1,1,1,1,1,1,1,1,1
1,1,1,1,1,1,1,1,1
1,1,1,1,1,1,1,1,1
endlayer

layer
1,1,1,1,1,1,1,1,1
1,1,1,0,0,0,0,0,1
1,1,5,0,0,0,5,0,1
1,1,1,0,0,0,1,3,1
1,1,1,0,6,0,1,1,1
1,1,1,0,0,0,1,1,1
1,1,1,1,1,1,1,1,1
1,1,1,1,1,1,1,1,1
1,1,1,1,1,1,1,1,1
endlayer

layer
1,1,1,1,1,1,1,1,1
1,1,1,0,7,0,0,0,1
1,1,8,0,0,0,8,0,1
1,1,1,0,0,0,4,0,1
1,1,1,0,6,0,4,4,1
1,1,1,0,0,0,4,4,1
1,1,1,1,1,1,5,4,1
1,1,1,1,1,1,1,9,1
1,1,1,1,1,1,1,1,1
endlayer

layer
1,1,1,1,1,1,1,1,1
1,1,1,1,1,1,10,0,1
1,1,1,11,11,11,1,0,1
1,1,1,0,0,0,0,0,1
1,1,1,0,6,0,0,0,1
1,1,1,0,0,0,0,0,1
1,1,1,1,1,1,1,0,1
1,1,1,1,1,1,9,0,1
1,1,1,1,1,1,1,1,1
endlayer

layer
1,1,1,1,1,1,1,1,1
1,1,1,1,1,1,1,11,1
1,1,1,1,1,1,5,0,1
1,1,1,0,0,0,0,0,1
1,1,1,0,6,0,0,0,1
1,1,1,0,0,0,0,0,1
1,1,1,1,1,1,5,0,1
1,1,1,1,1,9,0,0,1
1,1,1,1,1,1,1,1,1
endlayer

layer
1,1,1,1,1,1,1,1,1
1,1,1,1,1,1,1,1,1
1,1,1,1,1,1,8,11,1
1,1,1,0,0,0,0,0,1
1,1,1,0,6,0,0,12,1
1,1,1,0,0,0,0,0,1
1,1,5,4,4,4,8,0,1
1,13,4,4,4,0,0,0,1
1,1,1,1,1,1,1,1,1
endlayer

layer
1,1,1,1,1,1,1,1,1
1,1,1,1,1,1,1,1,1
1,1,1,1,1,1,1,1,1
1,1,1,0,0,0,14,1,1
1,1,1,0,6,0,14,1,1
1,1,1,0,0,0,14,1,1
1,13,1,0,0,0,1,11,1
1,0,0,0,0,0,0,0,1
1,1,1,1,1,1,1,1,1
endlayer

layer
1,1,1,1,1,1,1,1,1
1,1,1,1,1,1,1,1,1
1,1,1,1,1,1,1,1,1
1,1,1,0,0,0,1,1,1
1,1,1,0,6,0,1,1,1
1,13,1,0,0,0,1,1,1
1,0,5,0,0,0,5,1,1
1,0,0,0,0,0,0,14,1
1,1,1,1,1,1,1,1,1
endlayer

layer
1,1,1,1,1,1,1,1,1
1,15,1,1,1,1,1,1,1
1,4,5,1,1,1,1,1,1
1,4,4,0,0,0,1,1,1
1,4,4,0,6,0,1,1,1
1,0,4,0,0,0,1,1,1
1,0,8,0,0,0,8,1,1
1,0,0,0,16,0,14,1,1
1,1,1,1,1,1,1,1,1
endlayer

layer
1,1,1,1,1,1,1,1,1
1,0,15,1,1,1,1,1,1
1,0,1,1,1,1,1,1,1
1,0,0,0,0,0,1,1,1
1,0,0,0,6,0,1,1,1
1,0,0,0,0,0,1,1,1
1,0,1,17,17,17,1,1,1
1,0,14,1,1,1,1,1,1
1,1,1,1,1,1,1,1,1
endlayer

layer
1,1,1,1,1,1,1,1,1
1,0,0,15,1,1,1,1,1
1,0,5,1,1,1,1,1,1
1,0,0,0,0,0,1,1,1
1,0,0,0,6,0,1,1,1
1,0,0,0,0,0,1,1,1
1,0,5,1,1,1,1,1,1
1,17,1,1,1,1,1,1,1
1,1,1,1,1,1,1,1,1
endlayer

layer
1,1,1,1,1,1,1,1,1
1,0,0,0,4,4,4,3,1
1,0,8,4,4,4,5,1,1
1,0,0,0,0,0,1,1,1
1,18,0,0,6,0,1,1,1
1,0,0,0,0,0,1,1,1
1,17,8,1,1,1,1,1,1
1,1,1,1,1,1,1,1,1
1,1,1,1,1,1,1,1,1
endlayer

layer
1,1,1,1,1,1,1,1,1
1,0,0,0,0,0,0,0,1
1,17,1,0,0,0,1,3,1
1,1,10,0,0,0,1,1,1
1,1,10,0,6,0,1,1,1
1,1,10,0,0,0,1,1,1
1,1,1,1,1,1,1,1,1
1,1,1,1,1,1,1,1,1
1,1,1,1,1,1,1,1,1
endlayer

layer
1,1,1,1,1,1,1,1,1
1,10,0,0,0,0,0,0,1
1,1,5,0,0,0,5,0,1
1,1,1,0,0,0,1,3,1
1,1,1,0,6,0,1,1,1
1,1,1,0,0,0,1,1,1
1,1,1,1,1,1,1,1,1
1,1,1,1,1,1,1,1,1
1,1,1,1,1,1,1,1,1
endlayer

layer
19,15,1,1,1,1,1,1,1
19,1,10,0,7,0,0,0,1
19,1,8,0,0,0,8,0,1
3,1,1,0,0,0,4,0,1
1,1,1,0,6,0,4,4,1
1,1,1,0,0,0,4,4,1
1,1,1,1,1,1,5,4,1
1,1,1,1,1,1,1,9,1
1,1,1,1,1,1,1,1,1
endlayer

layer
19,19,15,1,1,1,1,1,1
19,1,1,1,1,1,10,0,1
19,1,1,11,11,11,1,0,1
19,1,1,0,0,0,0,0,1
3,1,1,0,6,0,0,0,1
1,1,1,0,0,0,0,0,1
1,1,1,1,1,1,1,0,1
1,1,1,1,1,1,9,0,1
1,1,1,1,1,1,1,1,1
endlayer

layer
19,19,19,15,1,1,1,1,1
19,1,1,1,1,1,1,11,1
19,1,1,1,1,1,5,0,1
19,1,1,0,0,0,0,0,1
19,1,1,0,6,0,0,0,1
3,1,1,0,0,0,0,0,1
1,1,1,1,1,1,5,0,1
8,1,1,1,1,9,0,0,1
1,1,1,1,1,1,1,1,1
endlayer

layer
19,19,19,19,19,19,19,19,19
19,1,1,1,1,1,1,1,3
19,13,1,1,1,1,8,11,1
19,4,4,0,0,0,0,0,1
19,4,4,0,6,0,0,12,1
19,4,4,0,0,0,0,0,1
1,4,5,4,4,4,8,0,1
1,4,4,4,4,0,0,0,1
1,1,1,1,1,1,1,1,1
endlayer

layer
19,19,19,19,19,19,19,19,19
19,13,1,1,1,1,1,1,19
19,0,1,1,1,1,1,1,3
19,0,0,0,0,0,14,1,1
19,0,0,0,6,0,14,1,1
19,0,0,0,0,0,14,1,1
19,0,1,0,0,0,1,11,1
19,0,0,0,0,0,0,0,1
19,19,1,1,1,1,1,1,1
endlayer

layer
19,19,19,19,19,19,19,19,19
19,0,15,1,1,1,1,1,19
19,0,1,1,1,1,1,1,19
19,0,0,0,0,0,1,1,3
19,0,0,0,6,0,1,1,1
19,0,0,0,0,0,1,1,1
19,0,5,0,0,0,5,1,1
19,0,0,0,0,0,0,14,1
19,19,5,1,1,1,1,1,1
endlayer

layer
19,19,19,19,19,19,19,19,19
19,0,0,15,1,1,1,1,19
19,0,1,1,1,1,1,1,19
19,0,0,0,0,0,1,1,19
19,0,0,0,6,0,1,1,3
19,0,0,0,0,0,1,1,1
19,0,8,0,0,0,8,1,1
19,0,0,0,16,0,14,1,1
19,19,8,1,1,1,1,1,1
endlayer

layer
19,19,19,19,19,19,19,19,19
19,0,0,0,15,1,1,1,19
19,0,1,1,1,1,1,1,19
19,0,10,0,0,0,1,1,19
19,0,10,0,6,0,1,1,19
19,0,10,0,0,0,1,1,3
19,0,1,17,17,17,1,1,1
19,0,0,0,0,14,1,1,1
19,19,1,1,1,1,1,1,1
endlayer

layer
19,19,19,19,19,19,19,19,19
19,0,0,0,0,15,1,8,19
19,20,8,1,1,1,1,1,19
19,20,1,20,20,20,1,1,19
19,20,1,20,6,20,1,1,19
19,20,1,20,20,20,1,1,19
19,20,8,1,1,1,1,1,3
19,20,5,1,1,1,1,1,1
19,20,8,1,1,1,1,1,8
endlayer

layer
19,19,19,19,19,19,19,19,19
19,0,0,0,0,0,0,19,19
19,19,0,21,21,21,0,19,19
19,19,0,0,0,0,0,19,19
19,19,0,0,6,0,0,19,19
19,19,0,0,0,0,0,19,19
19,19,0,21,21,21,0,19,19
19,19,0,0,0,0,0,19,19
19,19,19,19,19,19,19,19,19
endlayer

layer
19,19,19,19,19,19,19,19,19
19,0,0,0,0,0,0,19,19
19,19,0,21,21,21,0,19,19
19,19,0,0,0,0,0,19,19
19,19,0,0,6,0,0,19,19
19,19,0,0,0,0,0,19,19
19,19,0,21,21,21,0,19,19
19,19,0,0,0,0,0,19,19
19,19,19,19,19,19,19,19,19
endlayer

layer
19,19,19,19,19,19,19,19,19
19,0,0,0,0,0,0,19,19
19,19,0,21,21,21,0,19,19
19,19,0,0,22,0,0,19,19
19,19,0,0,23,0,0,19,19
19,19,0,0,22,0,0,19,19
19,19,0,21,21,21,0,19,19
19,19,0,0,0,0,0,19,19
19,19,19,19,19,19,19,19,19
endlayer

layer
19,19,19,19,19,19,19,19,19
19,0,24,24,24,24,24,19,19
19,19,24,24,24,24,24,19,19
19,19,24,26,24,25,24,19,19
19,19,24,24,24,24,24,19,19
19,19,24,26,24,25,24,19,19
19,19,24,24,24,24,24,19,19
19,19,24,24,24,24,24,19,19
19,19,19,19,19,19,19,19,19
endlayer

