
# Created by Ruins mod version 16.9 Ingame Parser
# authoring Player: ST753M

# Large white sandstone castle

weight=50
uniqueMinDistance=10000
embed_into_distance=5
acceptable_target_blocks=
unacceptable_target_blocks=flowing_water,water,flowing_lava,lava,ice,bedrock,netherrack,nether_brick,nether_brick_fence,soul_sand,quartz_ore,end_stone,obsidian,iron_bars,Natura:Cloud,slime_grass,slime_congealed,slime_dirt,clouds,natura:clouds,twilightforest:wispy_cloud,twilightforest:fluffy_cloud,abyssalcraft:cwater,cwater
dimensions=55,21,21
allowable_overhang=6
max_leveling=0
leveling_buffer=0
preserve_water=0
preserve_lava=0
preventRotation=1

biomesToSpawnIn=mystic_grove

=0,100,air
rule1=0,100,preserveBlock
rule2=0,100,biomesoplenty:white_sandstone-0
rule3=0,100,biomesoplenty:white_sandstone_stairs-1
rule4=0,50,ChestGenHook:chests/village_blacksmith:3-5
rule5=0,100,biomesoplenty:white_sandstone_stairs-3
rule6=0,100,biomesoplenty:white_sandstone_stairs-2
rule7=0,100,biomesoplenty:white_sandstone_stairs-0
rule8=0,100,ChestGenHook:chests/stronghold_library:3-3
rule9=0,100,MobSpawner:Skeleton,MobSpawner:Silverfish
rule10=0,50,ChestGenHook:chests/end_city_treasure:3-2
rule11=0,100,ChestGenHook:chests/stronghold_library:3-4
rule12=0,100,biomesoplenty:white_sandstone_stairs-4
rule13=0,100,biomesoplenty:white_sandstone_stairs-6
rule14=0,100,biomesoplenty:white_sandstone_stairs-7
rule15=0,100,biomesoplenty:white_sandstone_stairs-5
rule16=0,100,biomesoplenty:planks_0-5
rule17=0,100,biomesoplenty:wood_slab_0-5
rule18=0,100,biomesoplenty:double_wood_slab_0-5
rule19=0,100,biomesoplenty:wood_slab_0-13
rule20=0,100,minecraft:quartz_stairs-1
rule21=0,100,minecraft:quartz_stairs-3
rule22=0,100,minecraft:quartz_stairs-2
rule23=0,100,minecraft:quartz_stairs-0
rule24=0,100,CommandBlock:RUINSTRIGGER /summon stray ~ ~1 ~ {ArmorItems:[{id:"minecraft:iron_boots",Count:1b},{id:"minecraft:iron_leggings",Count:1b},{id:"minecraft:iron_chestplate",Count:1b},{id:"minecraft:stained_glass",Damage:11,Count:1b}],HandItems:[{id:"minecraft:bow",Count:1b,tag:{ench:[{id:34,lvl:2},{id:48,lvl:2},{id:50,lvl:1}]}},{}],PersistenceRequired:1,Silent:1}:@-1
rule25=0,100,minecraft:sea_lantern-0
rule26=0,100,minecraft:quartz_stairs-6
rule27=0,100,minecraft:bookshelf-0
# West
rule28=0,100,CommandBlock:RUINSTRIGGER /testruin ST753M/TP_MysticCastle ~-11 ~ ~ 3:@-1
rule29=0,100,biomesoplenty:magic_fence-0
# East
rule30=0,100,CommandBlock:RUINSTRIGGER /testruin ST753M/TP_MysticCastle ~11 ~ ~ 1:@-4
rule31=0,100,minecraft:stained_glass-11
rule32=0,100,minecraft:carpet-11
# North
rule33=0,100,CommandBlock:RUINSTRIGGER /testruin ST753M/TP_MysticCastle ~ ~ ~-11 0:@-1
# South
rule34=0,100,CommandBlock:RUINSTRIGGER /testruin ST753M/TP_MysticCastle ~ ~ ~11 2:@-3
rule35=0,100,CommandBlock:RUINSTRIGGER /summon illusion_illager ~ ~1 ~ {PersistenceRequired:1}:@-1
rule36=0,100,biomesoplenty:magic_stairs-7
rule37=0,100,biomesoplenty:magic_stairs-6
rule38=0,100,biomesoplenty:magic_stairs-5
rule39=0,100,biomesoplenty:magic_stairs-4
rule40=0,100,biomesoplenty:magic_stairs-0
rule41=0,100,biomesoplenty:magic_stairs-2
rule42=0,100,biomesoplenty:magic_stairs-3
rule43=0,100,biomesoplenty:magic_stairs-1

layer
1,1,1,1,1,1,1,1,1,1,1,1,1,1,1,1,1,1,1,1,1
1,1,1,1,1,1,1,1,2,2,2,2,2,1,1,1,1,1,1,1,1
1,1,1,1,1,1,2,2,2,2,2,2,2,2,2,1,1,1,1,1,1
1,1,1,1,2,2,2,2,2,2,2,2,2,2,2,2,2,1,1,1,1
1,1,1,2,2,2,2,2,2,2,2,2,2,2,2,2,2,2,1,1,1
1,1,1,2,2,2,2,2,2,2,2,2,2,2,2,2,2,2,1,1,1
1,1,2,2,2,2,2,2,2,2,2,2,2,2,2,2,2,2,2,1,1
1,1,2,2,2,2,2,2,2,2,2,2,2,2,2,2,2,2,2,1,1
1,2,2,2,2,2,2,2,2,2,2,2,2,2,2,2,2,2,2,2,1
1,2,2,2,2,2,2,2,2,2,2,2,2,2,2,2,2,2,2,2,1
1,2,2,2,2,2,2,2,2,2,2,2,2,2,2,2,2,2,2,2,1
1,2,2,2,2,2,2,2,2,2,2,2,2,2,2,2,2,2,2,2,1
1,2,2,2,2,2,2,2,2,2,2,2,2,2,2,2,2,2,2,2,1
1,1,2,2,2,2,2,2,2,2,2,2,2,2,2,2,2,2,2,1,1
1,1,2,2,2,2,2,2,2,2,2,2,2,2,2,2,2,2,2,1,1
1,1,1,2,2,2,2,2,2,2,2,2,2,2,2,2,2,2,1,1,1
1,1,1,2,2,2,2,2,2,2,2,2,2,2,2,2,2,2,1,1,1
1,1,1,1,2,2,2,2,2,2,2,2,2,2,2,2,2,1,1,1,1
1,1,1,1,1,1,2,2,2,2,2,2,2,2,2,1,1,1,1,1,1
1,1,1,1,1,1,1,1,2,2,2,2,2,1,1,1,1,1,1,1,1
1,1,1,1,1,1,1,1,1,1,1,1,1,1,1,1,1,1,1,1,1
endlayer

layer
1,1,1,1,1,1,1,1,1,1,1,1,1,1,1,1,1,1,1,1,1
1,1,1,1,1,1,1,1,2,2,2,2,2,1,1,1,1,1,1,1,1
1,1,1,1,1,1,2,2,2,2,2,2,2,2,2,1,1,1,1,1,1
1,1,1,1,2,2,2,2,2,2,2,2,2,2,2,2,2,1,1,1,1
1,1,1,2,2,2,2,2,2,2,2,2,2,2,2,2,2,2,1,1,1
1,1,1,2,2,2,2,2,2,2,2,2,2,2,2,2,2,2,1,1,1
1,1,2,2,2,2,2,2,2,2,2,2,2,2,2,2,2,2,2,1,1
1,1,2,2,2,2,2,2,2,2,2,2,2,2,2,2,2,2,2,1,1
1,2,2,2,2,2,2,2,2,2,2,2,2,2,2,2,2,2,2,2,1
1,2,2,2,2,2,2,2,2,2,2,2,2,2,2,2,2,2,2,2,1
1,2,2,2,2,2,2,2,2,2,2,2,2,2,2,2,2,2,2,2,1
1,2,2,2,2,2,2,2,2,2,2,2,2,2,2,2,2,2,2,2,1
1,2,2,2,2,2,2,2,2,2,2,2,2,2,2,2,2,2,2,2,1
1,1,2,2,2,2,2,2,2,2,2,2,2,2,2,2,2,2,2,1,1
1,1,2,2,2,2,2,2,2,2,2,2,2,2,2,2,2,2,2,1,1
1,1,1,2,2,2,2,2,2,2,2,2,2,2,2,2,2,2,1,1,1
1,1,1,2,2,2,2,2,2,2,2,2,2,2,2,2,2,2,1,1,1
1,1,1,1,2,2,2,2,2,2,2,2,2,2,2,2,2,1,1,1,1
1,1,1,1,1,1,2,2,2,2,2,2,2,2,2,1,1,1,1,1,1
1,1,1,1,1,1,1,1,2,2,2,2,2,1,1,1,1,1,1,1,1
1,1,1,1,1,1,1,1,1,1,1,1,1,1,1,1,1,1,1,1,1
endlayer

layer
1,1,1,1,1,1,1,1,1,1,1,1,1,1,1,1,1,1,1,1,1
1,1,1,1,1,1,1,1,2,2,2,2,2,1,1,1,1,1,1,1,1
1,1,1,1,1,1,2,2,2,2,2,2,2,2,2,1,1,1,1,1,1
1,1,1,1,2,2,2,2,2,2,2,2,2,2,2,2,2,1,1,1,1
1,1,1,2,2,2,2,2,2,2,2,2,2,2,2,2,2,2,1,1,1
1,1,1,2,2,2,2,2,2,2,2,2,2,2,2,2,2,2,1,1,1
1,1,2,2,2,2,2,2,2,2,2,2,2,2,2,2,2,2,2,1,1
1,1,2,2,2,2,2,2,2,2,2,2,2,2,2,2,2,2,2,1,1
1,2,2,2,2,2,2,2,2,2,2,2,2,2,2,2,2,2,2,2,1
1,2,2,2,2,2,2,2,2,2,2,2,2,2,2,2,2,2,2,2,1
1,2,2,2,2,2,2,2,2,2,2,2,2,2,2,2,2,2,2,2,1
1,2,2,2,2,2,2,2,2,2,2,2,2,2,2,2,2,2,2,2,1
1,2,2,2,2,2,2,2,2,2,2,2,2,2,2,2,2,2,2,2,1
1,1,2,2,2,2,2,2,2,2,2,2,2,2,2,2,2,2,2,1,1
1,1,2,2,2,2,2,2,2,2,2,2,2,2,2,2,2,2,2,1,1
1,1,1,2,2,2,2,2,2,2,2,2,2,2,2,2,2,2,1,1,1
1,1,1,2,2,2,2,2,2,2,2,2,2,2,2,2,2,2,1,1,1
1,1,1,1,2,2,2,2,2,2,2,2,2,2,2,2,2,1,1,1,1
1,1,1,1,1,1,2,2,2,2,2,2,2,2,2,1,1,1,1,1,1
1,1,1,1,1,1,1,1,2,2,2,2,2,1,1,1,1,1,1,1,1
1,1,1,1,1,1,1,1,1,1,1,1,1,1,1,1,1,1,1,1,1
endlayer

layer
1,1,1,1,1,1,1,1,1,1,1,1,1,1,1,1,1,1,1,1,1
1,1,1,1,1,1,1,1,2,2,2,2,2,1,1,1,1,1,1,1,1
1,1,1,1,1,1,2,2,2,2,2,2,2,2,2,1,1,1,1,1,1
1,1,1,1,2,2,2,2,2,2,2,2,2,2,2,2,2,1,1,1,1
1,1,1,2,2,2,2,2,2,2,2,2,2,2,2,2,2,2,1,1,1
1,1,1,2,2,2,2,2,2,2,2,2,2,2,2,2,2,2,1,1,1
1,1,2,2,2,2,2,2,2,2,2,2,2,2,2,2,2,2,2,1,1
1,1,2,2,2,2,2,2,2,2,2,2,2,2,2,2,2,2,2,1,1
1,2,2,2,2,2,2,2,2,2,2,2,2,2,2,2,2,2,2,2,1
1,2,2,2,2,2,2,2,2,2,2,2,2,2,2,2,2,2,2,2,1
1,2,2,2,2,2,2,2,2,2,2,2,2,2,2,2,2,2,2,2,1
1,2,2,2,2,2,2,2,2,2,2,2,2,2,2,2,2,2,2,2,1
1,2,2,2,2,2,2,2,2,2,2,2,2,2,2,2,2,2,2,2,1
1,1,2,2,2,2,2,2,2,2,2,2,2,2,2,2,2,2,2,1,1
1,1,2,2,2,2,2,2,2,2,2,2,2,2,2,2,2,2,2,1,1
1,1,1,2,2,2,2,2,2,2,2,2,2,2,2,2,2,2,1,1,1
1,1,1,2,2,2,2,2,2,2,2,2,2,2,2,2,2,2,1,1,1
1,1,1,1,2,2,2,2,2,2,2,2,2,2,2,2,2,1,1,1,1
1,1,1,1,1,1,2,2,2,2,2,2,2,2,2,1,1,1,1,1,1
1,1,1,1,1,1,1,1,2,2,2,2,2,1,1,1,1,1,1,1,1
1,1,1,1,1,1,1,1,1,1,1,1,1,1,1,1,1,1,1,1,1
endlayer

layer
1,1,1,1,1,1,1,1,1,1,1,1,1,1,1,1,1,1,1,1,1
1,1,1,1,1,1,1,1,2,2,2,2,2,1,1,1,1,1,1,1,1
1,1,1,1,1,1,2,2,2,2,2,2,2,2,2,1,1,1,1,1,1
1,1,1,1,2,2,2,2,2,2,2,2,2,2,2,2,2,1,1,1,1
1,1,1,2,2,2,2,2,2,2,2,2,2,2,2,2,2,2,1,1,1
1,1,1,2,2,2,2,2,2,2,2,2,2,2,2,2,2,2,1,1,1
1,1,2,2,2,2,2,2,2,2,2,2,2,2,2,2,2,2,2,1,1
1,1,2,2,2,2,2,2,2,2,2,2,2,2,2,2,2,2,2,1,1
1,2,2,2,2,2,2,2,2,2,2,2,2,2,2,2,2,2,2,2,1
1,2,2,2,2,2,2,2,2,2,2,2,2,2,2,2,2,2,2,2,1
1,2,2,2,2,2,2,2,2,2,2,2,2,2,2,2,2,2,2,2,1
1,2,2,2,2,2,2,2,2,2,2,2,2,2,2,2,2,2,2,2,1
1,2,2,2,2,2,2,2,2,2,2,2,2,2,2,2,2,2,2,2,1
1,1,2,2,2,2,2,2,2,2,2,2,2,2,2,2,2,2,2,1,1
1,1,2,2,2,2,2,2,2,2,2,2,2,2,2,2,2,2,2,1,1
1,1,1,2,2,2,2,2,2,2,2,2,2,2,2,2,2,2,1,1,1
1,1,1,2,2,2,2,2,2,2,2,2,2,2,2,2,2,2,1,1,1
1,1,1,1,2,2,2,2,2,2,2,2,2,2,2,2,2,1,1,1,1
1,1,1,1,1,1,2,2,2,2,2,2,2,2,2,1,1,1,1,1,1
1,1,1,1,1,1,1,1,2,2,2,2,2,1,1,1,1,1,1,1,1
1,1,1,1,1,1,1,1,1,1,1,1,1,1,1,1,1,1,1,1,1
endlayer

layer
1,1,1,1,1,1,1,1,1,1,1,1,1,1,1,1,1,1,1,1,1
1,1,1,1,1,1,1,1,2,2,2,2,2,1,1,1,1,1,1,1,1
1,1,1,1,1,1,2,2,2,2,2,2,2,2,2,1,1,1,1,1,1
1,1,1,1,2,2,2,2,2,2,2,2,2,2,2,2,2,1,1,1,1
1,1,1,2,2,2,2,2,2,2,2,2,2,2,2,2,2,2,1,1,1
1,1,1,2,2,2,2,2,2,2,2,2,2,2,2,2,2,2,1,1,1
1,1,2,2,2,2,2,2,2,2,2,2,2,2,2,2,2,2,2,1,1
1,1,2,2,2,2,2,2,2,2,2,2,2,2,2,2,2,2,2,1,1
1,2,2,2,2,2,2,2,2,2,2,2,2,2,2,2,2,2,2,2,1
1,2,2,2,2,2,2,2,2,2,2,2,2,2,2,2,2,2,2,2,1
1,2,2,2,2,2,2,2,2,2,2,2,2,2,2,2,2,2,2,2,1
1,2,2,2,2,2,2,2,2,2,2,2,2,2,2,2,2,2,2,2,1
1,2,2,2,2,2,2,2,2,2,2,2,2,2,2,2,2,2,2,2,1
1,1,2,2,2,2,2,2,2,2,2,2,2,2,2,2,2,2,2,1,1
1,1,2,2,2,2,2,2,2,2,2,2,2,2,2,2,2,2,2,1,1
1,1,1,2,2,2,2,2,2,2,2,2,2,2,2,2,2,2,1,1,1
1,1,1,2,2,2,2,2,2,2,2,2,2,2,2,2,2,2,1,1,1
1,1,1,1,2,2,2,2,2,2,2,2,2,2,2,2,2,1,1,1,1
1,1,1,1,1,1,2,2,2,2,2,2,2,2,2,1,1,1,1,1,1
1,1,1,1,1,1,1,1,2,2,2,2,2,1,1,1,1,1,1,1,1
1,1,1,1,1,1,1,1,1,1,1,1,1,1,1,1,1,1,1,1,1
endlayer

layer
1,1,1,1,1,1,1,1,1,1,1,1,1,1,1,1,1,1,1,1,1
1,1,1,1,1,1,1,1,2,2,2,2,2,1,1,1,1,1,1,1,1
1,1,1,1,1,1,2,2,3,3,4,3,3,2,2,1,1,1,1,1,1
1,1,1,1,2,2,3,3,0,0,0,0,0,3,3,2,2,1,1,1,1
1,1,1,2,3,3,0,0,0,0,0,0,0,0,0,3,5,2,1,1,1
1,1,1,2,6,0,0,0,0,0,0,0,0,0,0,0,5,2,1,1,1
1,1,2,6,0,0,0,0,0,0,0,0,0,0,0,0,0,5,2,1,1
1,1,2,6,0,0,0,0,0,0,0,0,0,0,0,0,0,5,2,1,1
1,2,6,0,0,0,0,0,0,0,0,0,0,0,0,0,0,0,5,2,1
1,2,6,0,0,0,0,0,0,7,7,7,0,0,0,0,0,0,5,2,1
1,2,10,0,0,0,0,0,0,5,9,6,0,0,0,0,0,0,8,2,1
1,2,6,0,0,0,0,0,0,5,3,3,0,0,0,0,0,0,5,2,1
1,2,6,0,0,0,0,0,0,0,0,0,0,0,0,0,0,0,5,2,1
1,1,2,6,0,0,0,0,0,0,0,0,0,0,0,0,0,5,2,1,1
1,1,2,6,0,0,0,0,0,0,0,0,0,0,0,0,0,5,2,1,1
1,1,1,2,6,0,0,0,0,0,0,0,0,0,0,0,5,2,1,1,1
1,1,1,2,7,7,0,0,0,0,0,0,0,0,0,7,7,2,1,1,1
1,1,1,1,2,2,7,7,0,0,0,0,0,7,7,2,2,1,1,1,1
1,1,1,1,1,1,2,2,7,7,11,7,7,2,2,1,1,1,1,1,1
1,1,1,1,1,1,1,1,2,2,2,2,2,1,1,1,1,1,1,1,1
1,1,1,1,1,1,1,1,1,1,1,1,1,1,1,1,1,1,1,1,1
endlayer

layer
1,1,1,1,1,1,1,1,1,1,1,1,1,1,1,1,1,1,1,1,1
1,1,1,1,1,1,1,1,2,2,2,2,2,1,1,1,1,1,1,1,1
1,1,1,1,1,1,2,2,0,0,0,0,0,2,2,1,1,1,1,1,1
1,1,1,1,2,2,0,0,0,0,0,0,0,0,0,2,2,1,1,1,1
1,1,1,2,0,0,0,0,0,0,0,0,0,0,0,0,0,2,1,1,1
1,1,1,2,0,0,0,0,0,0,0,0,0,0,0,0,0,2,1,1,1
1,1,2,0,0,0,0,0,0,0,0,0,0,0,0,0,0,0,2,1,1
1,1,2,0,0,0,0,0,0,0,0,0,0,0,0,0,0,0,2,1,1
1,2,0,0,0,0,0,0,0,0,0,0,0,0,0,0,0,0,0,2,1
1,2,0,0,0,0,0,0,0,0,0,0,0,0,0,0,0,0,0,2,1
1,2,0,0,0,0,0,0,0,0,2,0,0,0,0,0,0,0,0,2,1
1,2,0,0,0,0,0,0,0,0,0,0,0,0,0,0,0,0,0,2,1
1,2,0,0,0,0,0,0,0,0,0,0,0,0,0,0,0,0,0,2,1
1,1,2,0,0,0,0,0,0,0,0,0,0,0,0,0,0,0,2,1,1
1,1,2,0,0,0,0,0,0,0,0,0,0,0,0,0,0,0,2,1,1
1,1,1,2,0,0,0,0,0,0,0,0,0,0,0,0,0,2,1,1,1
1,1,1,2,0,0,0,0,0,0,0,0,0,0,0,0,0,2,1,1,1
1,1,1,1,2,2,0,0,0,0,0,0,0,0,0,2,2,1,1,1,1
1,1,1,1,1,1,2,2,0,0,0,0,0,2,2,1,1,1,1,1,1
1,1,1,1,1,1,1,1,2,2,2,2,2,1,1,1,1,1,1,1,1
1,1,1,1,1,1,1,1,1,1,1,1,1,1,1,1,1,1,1,1,1
endlayer

layer
1,1,1,1,1,1,1,1,12,1,12,1,12,1,1,1,1,1,1,1,1
1,1,1,1,1,1,12,1,2,2,2,2,2,1,12,1,1,1,1,1,1
1,1,1,1,12,1,2,2,0,0,0,0,0,2,2,1,12,1,1,1,1
1,1,1,1,2,2,0,0,0,0,0,0,0,0,0,2,2,1,1,1,1
1,1,14,2,0,0,0,0,0,0,0,0,0,0,0,0,0,2,13,1,1
1,1,1,2,0,0,0,0,0,0,0,0,0,0,0,0,0,2,1,1,1
1,14,2,0,0,0,0,0,0,0,0,0,0,0,0,0,0,0,2,13,1
1,1,2,0,0,0,0,0,0,0,0,0,0,0,0,0,0,0,2,1,1
14,2,0,0,0,0,0,0,0,0,0,0,0,0,0,0,0,0,0,2,13
1,2,0,0,0,0,0,0,0,0,0,0,0,0,0,0,0,0,0,2,1
14,2,0,0,0,0,0,0,0,0,2,0,0,0,0,0,0,0,0,2,13
1,2,0,0,0,0,0,0,0,0,0,0,0,0,0,0,0,0,0,2,1
14,2,0,0,0,0,0,0,0,0,0,0,0,0,0,0,0,0,0,2,13
1,1,2,0,0,0,0,0,0,0,0,0,0,0,0,0,0,0,2,1,1
1,14,2,0,0,0,0,0,0,0,0,0,0,0,0,0,0,0,2,13,1
1,1,1,2,0,0,0,0,0,0,0,0,0,0,0,0,0,2,1,1,1
1,1,14,2,0,0,0,0,0,0,0,0,0,0,0,0,0,2,13,1,1
1,1,1,1,2,2,0,0,0,0,0,0,0,0,0,2,2,1,1,1,1
1,1,1,1,15,1,2,2,0,0,0,0,0,2,2,1,15,1,1,1,1
1,1,1,1,1,1,15,1,2,2,2,2,2,1,15,1,1,1,1,1,1
1,1,1,1,1,1,1,1,15,1,15,1,15,1,1,1,1,1,1,1,1
endlayer

layer
1,1,1,1,1,1,1,1,2,1,2,1,2,1,1,1,1,1,1,1,1
1,1,1,1,1,1,2,1,2,2,2,2,2,1,2,1,1,1,1,1,1
1,1,1,1,2,1,2,2,0,0,0,0,0,2,2,1,2,1,1,1,1
1,1,1,1,2,2,0,0,0,0,0,0,0,0,0,2,2,1,1,1,1
1,1,2,2,0,0,0,0,0,0,0,0,0,0,0,0,0,2,2,1,1
1,1,1,2,0,0,0,0,0,0,0,0,0,0,0,0,0,2,1,1,1
1,2,2,0,0,0,0,0,0,0,0,0,0,0,0,0,0,0,2,2,1
1,1,2,0,0,0,0,0,0,0,0,0,0,0,0,0,0,0,2,1,1
2,2,0,0,0,0,0,0,0,0,0,0,0,0,0,0,0,0,0,2,2
1,2,0,0,0,0,0,0,0,0,0,0,0,0,0,0,0,0,0,2,1
2,2,0,0,0,0,0,0,0,0,2,0,0,0,0,0,0,0,0,2,2
1,2,0,0,0,0,0,0,0,0,0,0,0,0,0,0,0,0,0,2,1
2,2,0,0,0,0,0,0,0,0,0,0,0,0,0,0,0,0,0,2,2
1,1,2,0,0,0,0,0,0,0,0,0,0,0,0,0,0,0,2,1,1
1,2,2,0,0,0,0,0,0,0,0,0,0,0,0,0,0,0,2,2,1
1,1,1,2,0,0,0,0,0,0,0,0,0,0,0,0,0,2,1,1,1
1,1,2,2,0,0,0,0,0,0,0,0,0,0,0,0,0,2,2,1,1
1,1,1,1,2,2,0,0,0,0,0,0,0,0,0,2,2,1,1,1,1
1,1,1,1,2,1,2,2,0,0,0,0,0,2,2,1,2,1,1,1,1
1,1,1,1,1,1,2,1,2,2,2,2,2,1,2,1,1,1,1,1,1
1,1,1,1,1,1,1,1,2,1,2,1,2,1,1,1,1,1,1,1,1
endlayer

layer
1,1,1,1,1,1,1,1,2,2,2,2,2,1,1,1,1,1,1,1,1
1,1,1,1,1,1,2,2,2,2,2,2,2,2,2,1,1,1,1,1,1
1,1,1,1,2,2,2,2,15,15,15,15,15,2,2,2,2,1,1,1,1
1,1,1,2,2,2,15,15,0,0,0,0,0,15,15,2,2,2,1,1,1
1,1,2,2,15,15,0,0,0,0,0,0,0,0,0,15,14,2,2,1,1
1,1,2,2,13,0,0,0,0,0,0,0,0,0,0,0,14,2,2,1,1
1,2,2,13,0,0,0,0,0,0,0,0,0,0,0,0,0,14,2,2,1
1,2,2,13,0,0,0,0,0,0,0,0,0,0,0,0,0,14,2,2,1
2,2,13,0,0,0,0,0,0,0,0,0,0,0,0,0,0,0,14,2,2
2,2,13,0,0,0,0,0,0,12,12,13,0,0,0,0,0,0,14,2,2
2,2,13,0,0,0,0,0,0,14,2,13,0,0,0,0,0,0,14,2,2
2,2,13,0,0,0,0,0,0,14,15,13,0,0,0,0,0,0,14,2,2
2,2,13,0,0,0,0,0,0,0,0,0,0,0,0,0,0,0,14,2,2
1,2,2,13,0,0,0,0,0,0,0,0,0,0,0,0,0,14,2,2,1
1,2,2,13,0,0,0,0,0,0,0,0,0,0,0,0,0,14,2,2,1
1,1,2,2,13,0,0,0,0,0,0,0,0,0,0,0,14,2,2,1,1
1,1,2,2,13,12,0,0,0,0,0,0,0,0,0,12,12,2,2,1,1
1,1,1,2,2,2,12,12,0,0,0,0,0,12,12,2,2,2,1,1,1
1,1,1,1,2,2,2,2,12,12,12,12,12,2,2,2,2,1,1,1,1
1,1,1,1,1,1,2,2,2,2,2,2,2,2,2,1,1,1,1,1,1
1,1,1,1,1,1,1,1,2,2,2,2,2,1,1,1,1,1,1,1,1
endlayer

layer
1,1,1,1,1,1,1,1,0,2,0,2,0,1,1,1,1,1,1,1,1
1,1,1,1,1,1,0,2,16,16,16,16,16,2,0,1,1,1,1,1,1
1,1,1,1,0,2,16,16,16,16,16,16,16,16,16,2,0,1,1,1,1
1,1,1,2,16,16,16,16,16,16,16,16,16,16,16,16,16,2,1,1,1
1,1,0,16,16,16,16,16,16,16,16,16,16,16,16,16,16,16,0,1,1
1,1,2,16,16,16,16,16,16,16,16,16,16,16,16,16,16,16,2,1,1
1,0,16,16,16,16,16,16,16,16,16,16,16,16,16,16,16,16,16,0,1
1,2,16,16,16,16,16,16,16,16,16,16,16,16,16,16,16,16,16,2,1
0,16,16,16,16,16,16,16,16,16,16,16,16,16,16,16,16,16,16,16,0
2,16,16,16,16,16,16,16,16,16,16,16,16,16,16,16,16,16,16,16,2
0,16,16,16,16,16,16,16,16,16,2,16,16,16,16,16,16,16,16,16,0
2,16,16,16,16,16,16,16,16,16,16,16,16,16,16,16,16,16,16,16,2
0,16,16,16,16,16,16,16,16,16,16,16,16,16,16,16,16,16,16,16,0
1,2,16,16,16,16,16,16,16,16,16,16,16,16,16,16,16,16,16,2,1
1,0,16,16,16,16,16,16,16,16,16,16,16,16,16,16,16,16,16,0,1
1,1,2,16,16,16,16,16,16,16,16,16,16,16,16,16,16,16,2,1,1
1,1,0,16,16,16,16,16,16,16,16,16,16,16,16,16,16,16,0,1,1
1,1,1,2,16,16,16,16,16,16,16,16,16,16,16,16,16,2,1,1,1
1,1,1,1,0,2,16,16,16,16,16,16,16,16,16,2,0,1,1,1,1
1,1,1,1,1,1,0,2,16,16,16,16,16,2,0,1,1,1,1,1,1
1,1,1,1,1,1,1,1,0,2,0,2,0,1,1,1,1,1,1,1,1
endlayer

layer
1,1,1,1,1,1,1,1,2,2,2,2,2,1,1,1,1,1,1,1,1
1,1,1,1,1,1,2,2,0,0,0,0,0,2,2,1,1,1,1,1,1
1,1,1,1,2,2,0,0,0,0,0,0,0,0,0,2,2,1,1,1,1
1,1,1,2,0,0,0,2,2,0,0,0,2,2,0,0,0,2,1,1,1
1,1,2,0,0,2,2,18,17,0,0,0,0,0,2,2,0,0,2,1,1
1,1,2,0,2,19,19,18,17,0,0,0,0,0,0,0,2,0,2,1,1
1,2,0,0,2,19,19,18,2,0,0,0,2,0,0,0,2,0,0,2,1
1,2,0,2,0,0,0,2,0,0,0,0,0,2,0,0,0,2,0,2,1
2,0,0,2,0,0,2,0,0,0,0,0,0,0,2,0,0,2,0,0,2
2,0,2,2,0,0,2,20,0,0,0,0,0,20,2,0,0,2,2,0,2
2,0,2,2,0,0,2,22,0,0,2,0,0,21,2,0,0,2,2,0,2
2,0,2,2,0,0,2,23,0,0,0,0,0,23,2,0,0,2,2,0,2
2,0,0,2,0,0,2,0,0,24,0,24,0,0,2,0,0,2,0,0,2
1,2,0,2,0,0,0,2,0,0,11,0,0,2,0,0,0,2,0,2,1
1,2,0,0,2,0,0,0,2,2,2,2,2,18,19,19,2,0,0,2,1
1,1,2,0,2,0,0,0,0,0,0,0,17,18,19,19,2,0,2,1,1
1,1,2,0,0,2,2,0,0,0,0,0,17,18,2,2,0,0,2,1,1
1,1,1,2,0,0,0,2,2,0,0,0,2,2,0,0,0,2,1,1,1
1,1,1,1,2,2,0,0,0,0,0,0,0,0,0,2,2,1,1,1,1
1,1,1,1,1,1,2,2,0,0,0,0,0,2,2,1,1,1,1,1,1
1,1,1,1,1,1,1,1,2,2,2,2,2,1,1,1,1,1,1,1,1
endlayer

layer
1,1,1,1,1,1,1,1,2,0,2,0,2,1,1,1,1,1,1,1,1
1,1,1,1,1,1,2,1,0,0,0,0,0,1,2,1,1,1,1,1,1
1,1,1,1,2,1,0,1,0,0,0,0,0,1,0,1,2,1,1,1,1
1,1,1,1,1,0,0,2,2,0,0,0,2,2,0,1,0,1,1,1,1
1,1,2,0,0,2,2,0,0,0,0,0,0,0,2,2,0,1,2,1,1
1,1,1,1,2,17,17,0,0,0,0,0,0,0,0,0,2,0,1,1,1
1,2,0,0,2,17,17,0,2,0,0,0,2,0,0,0,2,0,0,2,1
1,1,1,2,18,18,18,2,0,0,0,0,0,2,0,0,0,2,1,1,1
2,0,0,2,19,19,2,0,0,0,0,0,0,0,2,0,0,2,0,0,2
0,0,2,2,0,0,2,0,0,0,0,0,0,0,2,0,0,2,2,0,0
2,0,2,25,0,0,2,0,0,0,2,0,0,0,2,0,0,25,2,0,2
0,0,2,2,0,0,2,0,0,0,0,0,0,0,2,0,0,2,2,0,0
2,0,0,2,0,0,2,0,0,0,0,0,0,0,2,19,19,2,0,0,2
1,1,1,2,0,0,0,2,0,0,0,0,0,2,18,18,18,2,1,1,1
1,2,0,0,2,0,0,0,2,2,2,2,2,0,17,17,2,0,0,2,1
1,1,1,1,2,0,0,0,0,0,0,0,0,0,17,17,2,0,1,1,1
1,1,2,0,0,2,2,0,0,0,0,0,0,0,2,2,0,1,2,1,1
1,1,1,1,1,0,0,2,2,0,0,0,2,2,0,1,0,1,1,1,1
1,1,1,1,2,1,0,1,0,0,0,0,0,1,0,1,2,1,1,1,1
1,1,1,1,1,1,2,1,0,0,0,0,0,1,2,1,1,1,1,1,1
1,1,1,1,1,1,1,1,2,0,2,0,2,1,1,1,1,1,1,1,1
endlayer

layer
1,1,1,1,1,1,1,1,0,0,0,0,0,1,1,1,1,1,1,1,1
1,1,1,1,1,1,1,1,0,0,0,0,0,1,1,1,1,1,1,1,1
1,1,1,1,1,1,1,1,0,0,0,0,0,1,1,1,1,1,1,1,1
1,1,1,1,1,0,0,2,2,0,0,0,2,2,1,1,1,1,1,1,1
1,1,1,1,1,2,2,0,0,0,0,0,0,0,2,2,1,1,1,1,1
1,1,1,1,2,0,0,0,0,0,0,0,0,0,0,0,2,0,1,1,1
1,1,1,1,2,0,0,0,2,0,0,0,2,0,0,0,2,0,1,1,1
1,1,1,2,0,0,0,2,0,0,0,0,0,2,0,0,0,2,1,1,1
0,0,0,2,17,17,2,0,0,0,0,0,0,0,2,19,19,2,0,0,0
0,0,2,2,18,18,2,0,0,0,0,0,0,0,2,18,18,2,2,0,0
0,0,2,2,18,18,2,0,0,0,2,0,0,0,2,18,18,2,2,0,0
0,0,2,2,18,18,2,0,0,0,0,0,0,0,2,18,18,2,2,0,0
0,0,0,2,19,19,2,0,0,0,0,0,0,0,2,17,17,2,0,0,0
1,1,1,2,0,0,0,2,0,0,0,0,0,2,0,0,0,2,1,1,1
1,1,1,1,2,0,0,0,2,2,2,2,2,0,0,0,2,0,1,1,1
1,1,1,1,2,0,0,0,0,0,0,0,0,0,0,0,2,0,1,1,1
1,1,1,1,1,2,2,0,0,0,0,0,0,0,2,2,1,1,1,1,1
1,1,1,1,1,0,0,2,2,0,0,0,2,2,1,1,1,1,1,1,1
1,1,1,1,1,1,1,1,0,0,0,0,0,1,1,1,1,1,1,1,1
1,1,1,1,1,1,1,1,0,0,0,0,0,1,1,1,1,1,1,1,1
1,1,1,1,1,1,1,1,0,0,0,0,0,1,1,1,1,1,1,1,1
endlayer

layer
1,1,1,1,1,1,1,1,0,0,0,0,0,1,1,1,1,1,1,1,1
1,1,1,1,1,1,1,1,0,0,0,0,0,1,1,1,1,1,1,1,1
1,1,1,1,1,1,1,1,0,0,0,0,0,1,1,1,1,1,1,1,1
1,1,1,1,1,0,0,2,2,13,0,14,2,2,1,1,1,1,1,1,1
1,1,1,1,1,2,2,0,0,0,0,0,0,0,2,2,1,1,1,1,1
1,1,1,1,2,0,0,0,0,0,0,0,0,0,19,19,2,0,1,1,1
1,1,1,1,2,0,0,0,2,13,0,14,2,0,19,19,2,0,1,1,1
1,1,1,2,0,0,0,2,0,0,0,0,0,2,18,18,18,2,1,1,1
0,0,0,2,0,0,2,0,0,0,0,0,0,0,2,17,17,2,0,0,0
0,0,2,2,0,0,2,0,0,0,0,0,0,0,2,0,0,2,2,0,0
0,0,2,2,0,0,2,0,0,0,2,0,0,0,2,0,0,2,2,0,0
0,0,2,2,0,0,2,0,0,0,0,0,0,0,2,0,0,2,2,0,0
0,0,0,2,17,17,2,0,0,0,0,0,0,0,2,0,0,2,0,0,0
1,1,1,2,18,18,18,2,0,0,0,0,0,2,0,0,0,2,1,1,1
1,1,1,1,2,19,19,0,2,2,2,2,2,0,0,0,2,0,1,1,1
1,1,1,1,2,19,19,0,0,0,0,0,0,0,0,0,2,0,1,1,1
1,1,1,1,1,2,2,0,0,0,0,0,0,0,2,2,1,1,1,1,1
1,1,1,1,1,0,0,2,2,13,0,14,2,2,1,1,1,1,1,1,1
1,1,1,1,1,1,1,1,0,0,0,0,0,1,1,1,1,1,1,1,1
1,1,1,1,1,1,1,1,0,0,0,0,0,1,1,1,1,1,1,1,1
1,1,1,1,1,1,1,1,0,0,0,0,0,1,1,1,1,1,1,1,1
endlayer

layer
1,1,1,1,1,1,1,1,0,0,0,0,0,1,1,1,1,1,1,1,1
1,1,1,1,1,1,1,1,0,0,0,0,0,1,1,1,1,1,1,1,1
1,1,1,1,1,1,1,1,0,2,2,2,0,1,1,1,1,1,1,1,1
1,1,1,1,1,0,0,2,2,2,25,2,2,2,1,1,1,1,1,1,1
1,1,1,1,1,2,2,0,0,0,0,0,19,18,2,2,1,1,1,1,1
1,1,1,1,2,0,0,0,0,0,0,0,19,18,17,17,2,0,1,1,1
1,1,1,1,2,0,0,0,2,2,2,2,2,18,17,17,2,0,1,1,1
1,1,1,2,0,0,0,2,0,0,0,0,0,2,0,0,0,2,1,1,1
0,0,0,2,0,0,2,0,0,0,0,0,0,0,2,0,0,2,0,0,0
0,0,2,2,0,0,2,0,0,0,0,0,0,0,2,0,0,2,2,0,0
0,0,2,2,0,0,2,0,0,0,2,0,0,0,2,0,0,2,2,0,0
0,0,2,2,0,0,2,0,0,0,0,0,0,0,2,0,0,2,2,0,0
0,0,0,2,0,0,2,0,0,0,0,0,0,0,2,0,0,2,0,0,0
1,1,1,2,0,0,0,2,0,0,0,0,0,2,0,0,0,2,1,1,1
1,1,1,1,2,17,17,18,2,2,2,2,2,0,0,0,2,0,1,1,1
1,1,1,1,2,17,17,18,19,0,0,0,0,0,0,0,2,0,1,1,1
1,1,1,1,1,2,2,18,19,0,0,0,0,0,2,2,1,1,1,1,1
1,1,1,1,1,0,0,2,2,2,25,2,2,2,1,1,1,1,1,1,1
1,1,1,1,1,1,1,1,0,2,2,2,0,1,1,1,1,1,1,1,1
1,1,1,1,1,1,1,1,0,0,0,0,0,1,1,1,1,1,1,1,1
1,1,1,1,1,1,1,1,0,0,0,0,0,1,1,1,1,1,1,1,1
endlayer

layer
1,1,1,1,1,1,1,1,0,0,0,0,0,1,1,1,1,1,1,1,1
1,1,1,1,1,1,1,1,0,0,0,0,0,1,1,1,1,1,1,1,1
1,1,1,1,1,1,1,1,0,2,2,2,0,1,1,1,1,1,1,1,1
1,1,1,1,1,0,0,2,2,2,2,2,2,2,1,1,1,1,1,1,1
1,1,1,1,1,2,2,0,19,18,18,18,17,0,2,2,1,1,1,1,1
1,1,1,1,2,0,0,0,19,18,18,18,17,0,0,0,2,0,1,1,1
1,1,1,1,2,0,0,0,2,2,2,2,2,0,0,0,2,0,1,1,1
1,1,1,2,0,0,0,2,19,19,19,19,19,2,0,0,0,2,1,1,1
0,0,0,2,0,0,2,19,19,19,19,19,19,19,2,0,0,2,0,0,0
0,0,2,2,0,0,2,19,19,19,19,19,19,19,2,0,0,2,2,0,0
0,0,2,2,0,0,2,19,19,19,2,19,19,19,2,0,0,2,2,0,0
0,0,2,2,0,0,2,19,19,19,19,19,19,19,2,0,0,2,2,0,0
0,0,0,2,0,0,2,19,19,19,19,19,19,19,2,0,0,2,0,0,0
1,1,1,2,0,0,0,2,19,19,19,19,19,2,0,0,0,2,1,1,1
1,1,1,1,2,0,0,0,2,2,2,2,2,0,0,0,2,0,1,1,1
1,1,1,1,2,0,0,0,17,18,18,18,19,0,0,0,2,0,1,1,1
1,1,1,1,1,2,2,0,17,18,18,18,19,0,2,2,1,1,1,1,1
1,1,1,1,1,0,0,2,2,2,2,2,2,2,1,1,1,1,1,1,1
1,1,1,1,1,1,1,1,0,2,2,2,0,1,1,1,1,1,1,1,1
1,1,1,1,1,1,1,1,0,0,0,0,0,1,1,1,1,1,1,1,1
1,1,1,1,1,1,1,1,0,0,0,0,0,1,1,1,1,1,1,1,1
endlayer

layer
1,1,1,1,1,1,1,1,0,0,0,0,0,1,1,1,1,1,1,1,1
1,1,1,1,1,1,1,1,0,12,0,12,0,1,1,1,1,1,1,1,1
1,1,1,1,1,1,1,1,0,2,2,2,0,1,1,1,1,1,1,1,1
1,1,1,1,1,0,0,2,2,2,2,2,2,2,1,1,1,1,1,1,1
1,1,1,1,1,2,2,18,17,0,0,0,0,0,2,2,1,1,1,1,1
1,1,1,1,2,19,19,18,17,0,0,0,0,0,0,0,2,0,1,1,1
1,1,1,1,2,19,19,18,2,0,0,0,2,0,0,0,2,0,1,1,1
1,1,1,2,0,0,0,2,0,0,0,0,0,2,0,0,0,2,1,1,1
0,0,0,2,0,0,2,26,0,0,0,0,0,0,2,0,0,2,0,0,0
0,0,2,2,0,0,2,26,0,0,0,0,24,0,2,0,0,2,2,0,0
0,0,2,2,0,0,2,26,0,0,2,0,24,0,2,0,0,2,2,0,0
0,0,2,2,0,0,2,26,0,0,0,0,0,0,2,0,0,2,2,0,0
0,0,0,2,0,0,2,26,0,0,0,0,0,0,2,0,0,2,0,0,0
1,1,1,2,0,0,0,2,0,0,11,0,0,2,0,0,0,2,1,1,1
1,1,1,1,2,0,0,0,2,2,2,2,2,18,19,19,2,0,1,1,1
1,1,1,1,2,0,0,0,0,0,0,0,17,18,19,19,2,0,1,1,1
1,1,1,1,1,2,2,0,0,0,0,0,17,18,2,2,1,1,1,1,1
1,1,1,1,1,0,0,2,2,2,2,2,2,2,1,1,1,1,1,1,1
1,1,1,1,1,1,1,1,0,2,2,2,0,1,1,1,1,1,1,1,1
1,1,1,1,1,1,1,1,0,15,0,15,0,1,1,1,1,1,1,1,1
1,1,1,1,1,1,1,1,0,0,0,0,0,1,1,1,1,1,1,1,1
endlayer

layer
1,1,1,1,1,1,1,1,0,2,0,2,0,1,1,1,1,1,1,1,1
1,1,1,1,1,1,1,1,0,3,0,3,0,1,1,1,1,1,1,1,1
1,1,1,1,1,1,1,1,0,2,2,2,0,1,1,1,1,1,1,1,1
1,1,1,1,1,0,0,2,2,2,2,2,2,2,1,1,1,1,1,1,1
1,1,1,1,1,2,2,0,0,0,0,0,0,0,2,2,1,1,1,1,1
1,1,1,1,2,17,17,0,0,0,0,0,0,0,0,0,2,0,1,1,1
1,1,1,1,2,17,17,0,2,0,0,0,2,0,0,0,2,0,1,1,1
1,1,1,2,18,18,18,2,0,0,0,0,0,2,0,0,0,2,1,1,1
0,0,0,2,19,19,2,27,0,0,0,0,0,0,2,0,0,2,0,0,0
0,0,2,2,0,0,2,27,0,0,0,0,0,0,2,0,0,2,2,0,0
0,0,2,25,0,0,2,27,0,0,2,0,0,0,2,0,0,25,2,0,0
0,0,2,2,0,0,2,27,0,0,0,0,0,0,2,0,0,2,2,0,0
0,0,0,2,0,0,2,27,0,0,0,0,0,0,2,19,19,2,0,0,0
1,1,1,2,0,0,0,2,0,0,0,0,0,2,18,18,18,2,1,1,1
1,1,1,1,2,0,0,0,2,2,2,2,2,0,17,17,2,0,1,1,1
1,1,1,1,2,0,0,0,0,0,0,0,0,0,17,17,2,0,1,1,1
1,1,1,1,1,2,2,0,0,0,0,0,0,0,2,2,1,1,1,1,1
1,1,1,1,1,0,0,2,2,2,2,2,2,2,1,1,1,1,1,1,1
1,1,1,1,1,1,1,1,0,2,2,2,0,1,1,1,1,1,1,1,1
1,1,1,1,1,1,1,1,0,7,0,7,0,1,1,1,1,1,1,1,1
1,1,1,1,1,1,1,1,0,2,0,2,0,1,1,1,1,1,1,1,1
endlayer

layer
1,1,1,1,1,1,1,1,0,3,0,3,0,1,1,1,1,1,1,1,1
1,1,1,1,1,1,1,1,0,0,0,0,0,1,1,1,1,1,1,1,1
1,1,1,1,1,1,1,1,0,2,2,2,0,1,1,1,1,1,1,1,1
1,1,1,1,1,0,0,2,2,2,2,2,2,2,1,1,1,1,1,1,1
1,1,1,1,1,2,2,0,0,0,0,0,0,0,2,2,1,1,1,1,1
1,1,1,1,2,0,0,0,0,0,0,0,0,0,0,0,2,0,1,1,1
1,1,1,1,2,0,0,0,2,0,0,0,2,0,0,0,2,0,1,1,1
1,1,1,2,0,0,0,2,0,0,0,0,0,2,0,0,0,2,1,1,1
0,0,0,2,17,17,2,22,0,0,0,0,0,0,2,19,19,2,0,0,0
0,0,2,2,18,18,2,22,0,0,0,0,0,0,2,18,18,2,2,0,0
0,0,2,2,18,18,2,22,0,0,2,0,0,0,2,18,18,2,2,0,0
0,0,2,2,18,18,2,22,0,0,0,0,0,0,2,18,18,2,2,0,0
0,0,0,2,19,19,2,22,0,0,0,0,0,0,2,17,17,2,0,0,0
1,1,1,2,0,0,0,2,0,0,0,0,0,2,0,0,0,2,1,1,1
1,1,1,1,2,0,0,0,2,2,2,2,2,0,0,0,2,0,1,1,1
1,1,1,1,2,0,0,0,0,0,0,0,0,0,0,0,2,0,1,1,1
1,1,1,1,1,2,2,0,0,0,0,0,0,0,2,2,1,1,1,1,1
1,1,1,1,1,0,0,2,2,2,2,2,2,2,1,1,1,1,1,1,1
1,1,1,1,1,1,1,1,0,2,2,2,0,1,1,1,1,1,1,1,1
1,1,1,1,1,1,1,1,0,0,0,0,0,1,1,1,1,1,1,1,1
1,1,1,1,1,1,1,1,0,7,0,7,0,1,1,1,1,1,1,1,1
endlayer

layer
1,1,1,1,1,1,1,1,0,0,0,0,0,1,1,1,1,1,1,1,1
1,1,1,1,1,1,1,1,0,12,0,12,0,1,1,1,1,1,1,1,1
1,1,1,1,1,1,1,1,0,2,2,2,0,1,1,1,1,1,1,1,1
1,1,1,1,1,0,0,2,2,2,2,2,2,2,1,1,1,1,1,1,1
1,1,1,1,1,2,2,0,0,0,0,0,0,0,2,2,1,1,1,1,1
1,1,1,1,2,0,0,0,0,0,0,0,0,0,19,19,2,0,1,1,1
1,1,1,1,2,0,0,0,2,13,0,14,2,0,19,19,2,0,1,1,1
1,1,1,2,0,0,0,2,0,0,0,0,0,2,18,18,18,2,1,1,1
0,0,0,2,0,0,2,0,0,0,0,0,0,0,2,17,17,2,0,0,0
0,14,2,2,0,0,2,0,0,0,0,0,0,0,2,0,0,2,2,13,0
0,0,2,2,0,0,2,0,0,0,2,0,0,0,2,0,0,2,2,0,0
0,14,2,2,0,0,2,0,0,0,0,0,0,0,2,0,0,2,2,13,0
0,0,0,2,17,17,2,0,0,0,0,0,0,0,2,0,0,2,0,0,0
1,1,1,2,18,18,18,2,0,0,0,0,0,2,0,0,0,2,1,1,1
1,1,1,1,2,19,19,0,2,2,2,2,2,0,0,0,2,0,1,1,1
1,1,1,1,2,19,19,0,0,0,0,0,0,0,0,0,2,0,1,1,1
1,1,1,1,1,2,2,0,0,0,0,0,0,0,2,2,1,1,1,1,1
1,1,1,1,1,0,0,2,2,2,2,2,2,2,1,1,1,1,1,1,1
1,1,1,1,1,1,1,1,0,2,2,2,0,1,1,1,1,1,1,1,1
1,1,1,1,1,1,1,1,0,15,0,15,0,1,1,1,1,1,1,1,1
1,1,1,1,1,1,1,1,0,0,0,0,0,1,1,1,1,1,1,1,1
endlayer

layer
1,1,1,1,1,1,1,1,14,2,16,2,13,1,1,1,1,1,1,1,1
1,1,1,1,1,1,1,1,14,2,16,2,13,1,1,1,1,1,1,1,1
1,1,1,1,1,1,1,1,14,2,2,2,13,1,1,1,1,1,1,1,1
1,1,1,1,1,0,0,2,2,2,25,2,2,2,1,1,1,1,1,1,1
1,1,1,1,1,2,2,0,0,0,0,0,19,18,2,2,1,1,1,1,1
1,1,1,1,2,0,0,0,0,0,0,0,19,18,17,17,2,0,1,1,1
1,1,1,1,2,0,0,0,2,2,2,2,2,18,17,17,2,0,1,1,1
1,1,1,2,0,0,0,2,0,0,0,0,0,2,0,0,0,2,1,1,1
0,0,0,2,0,0,2,0,0,0,0,0,0,0,2,0,0,2,0,0,0
2,6,2,2,0,0,2,0,0,0,0,0,0,0,2,0,0,2,2,5,2
0,0,2,2,0,0,2,0,0,0,2,0,0,0,2,0,0,2,2,0,0
2,6,2,2,0,0,2,0,0,0,0,0,0,0,2,0,0,2,2,5,2
0,0,0,2,0,0,2,0,0,0,0,0,0,0,2,0,0,2,0,0,0
1,1,1,2,0,0,0,2,0,0,0,0,0,2,0,0,0,2,1,1,1
1,1,1,1,2,17,17,18,2,2,2,2,2,0,0,0,2,0,1,1,1
1,1,1,1,2,17,17,18,19,0,0,0,0,0,0,0,2,0,1,1,1
1,1,1,1,1,2,2,18,19,0,0,0,0,0,2,2,1,1,1,1,1
1,1,1,1,1,0,0,2,2,2,25,2,2,2,1,1,1,1,1,1,1
1,1,1,1,1,1,1,1,14,2,2,2,13,1,1,1,1,1,1,1,1
1,1,1,1,1,1,1,1,14,2,16,2,13,1,1,1,1,1,1,1,1
1,1,1,1,1,1,1,1,14,2,16,2,13,1,1,1,1,1,1,1,1
endlayer

layer
1,1,1,1,1,1,1,2,2,16,16,16,2,2,1,1,1,1,1,1,1
1,1,1,1,1,1,1,2,2,16,16,16,2,2,1,1,1,1,1,1,1
1,1,1,1,1,1,1,2,2,16,16,16,2,2,1,1,1,1,1,1,1
1,1,1,1,1,0,0,2,2,16,16,16,2,2,1,1,1,1,1,1,1
1,1,1,1,1,2,2,0,19,18,18,18,17,0,2,2,1,1,1,1,1
1,1,1,1,2,0,0,0,19,18,18,18,17,0,0,0,2,0,1,1,1
1,1,1,1,2,0,0,0,2,2,2,2,2,0,0,0,2,0,1,1,1
1,1,1,2,0,0,0,2,19,19,19,19,19,2,0,0,0,2,1,1,1
0,0,0,2,0,0,2,19,19,19,19,19,19,19,2,0,0,2,0,0,0
6,0,2,2,0,0,2,19,19,19,19,19,19,19,2,0,0,2,2,0,5
0,0,2,2,0,0,2,19,19,19,2,19,19,19,2,0,0,2,2,0,0
6,0,2,2,0,0,2,19,19,19,19,19,19,19,2,0,0,2,2,0,5
0,0,0,2,0,0,2,19,19,19,19,19,19,19,2,0,0,2,0,0,0
1,1,1,2,0,0,0,2,19,19,19,19,19,2,0,0,0,2,1,1,1
1,1,1,1,2,0,0,0,2,2,2,2,2,0,0,0,2,0,1,1,1
1,1,1,1,2,0,0,0,17,18,18,18,19,0,0,0,2,0,1,1,1
1,1,1,1,1,2,2,0,17,18,18,18,19,0,2,2,1,1,1,1,1
1,1,1,1,1,0,0,2,2,16,16,16,2,2,1,1,1,1,1,1,1
1,1,1,1,1,1,1,2,2,16,16,16,2,2,1,1,1,1,1,1,1
1,1,1,1,1,1,1,2,2,16,16,16,2,2,1,1,1,1,1,1,1
1,1,1,1,1,1,1,2,2,16,16,16,2,2,1,1,1,1,1,1,1
endlayer

layer
1,1,1,1,1,1,1,0,2,0,28,0,2,0,1,1,1,1,1,1,1
1,1,1,1,1,1,1,5,2,0,0,0,2,6,1,1,1,1,1,1,1
1,1,1,1,1,1,1,0,2,0,0,0,2,0,1,1,1,1,1,1,1
1,1,1,1,1,0,0,2,2,0,0,0,2,2,1,1,1,1,1,1,1
1,1,1,1,1,2,2,18,17,0,0,0,0,0,2,2,1,1,1,1,1
1,1,1,1,2,19,19,18,17,0,0,0,0,0,0,0,2,0,1,1,1
1,1,1,1,2,19,19,18,2,0,0,0,2,0,0,0,2,0,1,1,1
1,1,1,2,0,0,0,2,0,0,0,0,0,2,0,0,0,2,1,1,1
0,0,0,2,0,0,2,0,0,0,0,0,24,0,2,0,0,2,0,0,0
0,14,2,2,0,0,2,0,0,0,0,0,24,20,2,0,0,2,2,13,0
0,0,2,2,0,0,2,27,0,0,2,0,0,29,2,0,0,2,2,0,0
0,14,2,2,0,0,2,27,0,0,0,0,0,23,2,0,0,2,2,13,0
0,0,0,2,0,0,2,27,0,0,0,0,0,0,2,0,0,2,0,0,0
1,1,1,2,0,0,0,2,0,0,0,0,0,2,0,0,0,2,1,1,1
1,1,1,1,2,0,0,0,2,2,2,2,2,18,19,19,2,0,1,1,1
1,1,1,1,2,0,0,0,0,0,0,0,17,18,19,19,2,0,1,1,1
1,1,1,1,1,2,2,0,0,0,0,0,17,18,2,2,1,1,1,1,1
1,1,1,1,1,0,0,2,2,0,0,0,2,2,1,1,1,1,1,1,1
1,1,1,1,1,1,1,0,2,0,0,0,2,0,1,1,1,1,1,1,1
1,1,1,1,1,1,1,5,2,0,0,0,2,6,1,1,1,1,1,1,1
1,1,1,1,1,1,1,0,2,0,30,0,2,0,1,1,1,1,1,1,1
endlayer

layer
1,1,1,1,1,1,1,0,2,0,0,0,2,0,1,1,1,1,1,1,1
1,1,1,1,1,1,1,0,31,0,0,0,31,0,1,1,1,1,1,1,1
1,1,1,1,1,1,1,0,2,0,0,0,2,0,1,1,1,1,1,1,1
1,1,1,1,1,0,0,2,2,0,0,0,2,2,1,1,1,1,1,1,1
1,1,1,1,1,2,2,0,0,0,0,0,0,0,2,2,1,1,1,1,1
1,1,1,1,2,17,17,0,0,0,0,0,0,0,0,0,2,0,1,1,1
1,1,1,1,2,17,17,0,2,0,0,0,2,0,0,0,2,0,1,1,1
1,1,1,2,18,18,18,2,0,0,0,0,0,2,0,0,0,2,1,1,1
12,12,12,2,19,19,2,0,0,0,0,0,0,0,2,0,0,2,12,12,12
2,2,2,2,0,0,2,0,0,0,0,0,0,0,2,0,0,2,2,2,2
16,16,2,25,0,0,2,27,0,0,2,0,0,32,2,0,0,25,2,16,16
2,2,2,2,0,0,2,27,0,0,0,0,0,0,2,0,0,2,2,2,2
15,15,15,2,0,0,2,27,0,0,0,0,0,0,2,19,19,2,15,15,15
1,1,1,2,0,0,0,2,0,0,0,0,0,2,18,18,18,2,1,1,1
1,1,1,1,2,0,0,0,2,2,2,2,2,0,17,17,2,0,1,1,1
1,1,1,1,2,0,0,0,0,0,0,0,0,0,17,17,2,0,1,1,1
1,1,1,1,1,2,2,0,0,0,0,0,0,0,2,2,1,1,1,1,1
1,1,1,1,1,0,0,2,2,0,0,0,2,2,1,1,1,1,1,1,1
1,1,1,1,1,1,1,0,2,0,0,0,2,0,1,1,1,1,1,1,1
1,1,1,1,1,1,1,0,31,0,0,0,31,0,1,1,1,1,1,1,1
1,1,1,1,1,1,1,0,2,0,0,0,2,0,1,1,1,1,1,1,1
endlayer

layer
1,1,1,1,1,1,1,0,2,0,0,0,2,0,1,1,1,1,1,1,1
1,1,1,1,1,1,1,0,31,0,0,0,31,0,1,1,1,1,1,1,1
1,1,1,1,1,1,1,0,2,0,0,0,2,0,1,1,1,1,1,1,1
1,1,1,1,1,0,0,2,2,0,0,0,2,2,1,1,1,1,1,1,1
1,1,1,1,1,2,2,0,0,0,0,0,0,0,2,2,1,1,1,1,1
1,1,1,1,2,0,0,0,0,0,0,0,0,0,0,0,2,0,1,1,1
1,1,1,1,2,0,0,0,2,0,0,0,2,0,0,0,2,0,1,1,1
2,2,2,2,0,0,0,2,0,0,0,0,0,2,0,0,0,2,2,2,2
2,2,2,2,17,17,2,0,0,0,0,0,0,0,2,19,19,2,2,2,2
16,16,16,16,18,18,2,0,0,0,0,0,0,0,2,18,18,16,16,16,16
16,16,16,16,18,18,2,32,0,0,2,0,0,0,2,18,18,16,16,16,16
16,16,16,16,18,18,2,32,0,0,0,0,0,0,2,18,18,16,16,16,16
2,2,2,2,19,19,2,32,0,0,0,0,0,0,2,17,17,2,2,2,2
2,2,2,2,0,0,0,2,0,0,0,0,0,2,0,0,0,2,2,2,2
1,1,1,1,2,0,0,0,2,2,2,2,2,0,0,0,2,0,1,1,1
1,1,1,1,2,0,0,0,0,0,0,0,0,0,0,0,2,0,1,1,1
1,1,1,1,1,2,2,0,0,0,0,0,0,0,2,2,1,1,1,1,1
1,1,1,1,1,0,0,2,2,0,0,0,2,2,1,1,1,1,1,1,1
1,1,1,1,1,1,1,0,2,0,0,0,2,0,1,1,1,1,1,1,1
1,1,1,1,1,1,1,0,31,0,0,0,31,0,1,1,1,1,1,1,1
1,1,1,1,1,1,1,0,2,0,0,0,2,0,1,1,1,1,1,1,1
endlayer

layer
1,1,1,1,1,1,1,0,2,13,0,14,2,0,1,1,1,1,1,1,1
1,1,1,1,1,1,1,14,2,13,0,14,2,13,1,1,1,1,1,1,1
1,1,1,1,1,1,1,0,2,13,0,14,2,0,1,1,1,1,1,1,1
1,1,1,1,1,0,0,2,2,13,0,14,2,2,1,1,1,1,1,1,1
1,1,1,1,1,2,2,0,0,0,0,0,0,0,2,2,1,1,1,1,1
1,1,1,1,2,0,0,0,0,0,0,0,0,0,19,19,2,0,1,1,1
1,1,1,1,2,0,0,0,2,13,0,14,2,0,19,19,2,0,1,1,1
0,7,0,2,0,0,0,2,0,0,0,0,0,2,18,18,18,2,0,7,0
2,2,2,2,0,0,2,0,0,0,0,0,0,0,2,17,17,2,2,2,2
0,0,0,0,0,0,2,0,0,0,0,0,0,0,2,0,0,0,0,0,0
34,0,0,0,0,0,2,0,0,0,2,0,0,0,2,0,0,0,0,0,33
0,0,0,0,0,0,2,0,0,0,0,0,0,0,2,0,0,0,0,0,0
2,2,2,2,17,17,2,0,0,0,0,0,0,0,2,0,0,2,2,2,2
0,3,0,2,18,18,18,2,0,0,0,0,0,2,0,0,0,2,0,3,0
1,1,1,1,2,19,19,0,2,2,2,2,2,0,0,0,2,0,1,1,1
1,1,1,1,2,19,19,0,0,0,0,0,0,0,0,0,2,0,1,1,1
1,1,1,1,1,2,2,0,0,0,0,0,0,0,2,2,1,1,1,1,1
1,1,1,1,1,0,0,2,2,13,0,14,2,2,1,1,1,1,1,1,1
1,1,1,1,1,1,1,0,2,13,0,14,2,0,1,1,1,1,1,1,1
1,1,1,1,1,1,1,14,2,13,0,14,2,13,1,1,1,1,1,1,1
1,1,1,1,1,1,1,0,2,13,0,14,2,0,1,1,1,1,1,1,1
endlayer

layer
1,1,1,1,1,1,1,2,2,16,16,16,2,2,1,1,1,1,1,1,1
1,1,1,1,1,1,1,2,2,16,16,16,2,2,1,1,1,1,1,1,1
1,1,1,1,1,1,1,2,2,16,16,16,2,2,1,1,1,1,1,1,1
1,1,1,1,1,0,0,2,2,2,25,2,2,2,1,1,1,1,1,1,1
1,1,1,1,1,2,2,0,0,0,0,0,19,18,2,2,1,1,1,1,1
1,1,1,1,2,0,0,0,0,0,0,0,19,18,17,17,2,0,1,1,1
1,1,1,1,2,0,0,0,2,2,2,2,2,18,17,17,2,0,1,1,1
0,0,0,2,0,0,0,2,0,0,0,0,0,2,0,0,0,2,0,0,0
2,31,2,2,0,0,2,0,0,0,0,0,0,0,2,0,0,2,2,31,2
0,0,0,0,0,0,2,0,0,0,0,0,0,0,2,0,0,0,0,0,0
0,0,0,0,0,0,2,0,0,0,2,0,0,0,2,0,0,0,0,0,0
0,0,0,0,0,0,2,0,0,0,0,0,0,0,2,0,0,0,0,0,0
2,31,2,2,0,0,2,0,0,0,0,0,0,0,2,0,0,2,2,31,2
0,0,0,2,0,0,0,2,0,0,0,0,0,2,0,0,0,2,0,0,0
1,1,1,1,2,17,17,18,2,2,2,2,2,0,0,0,2,0,1,1,1
1,1,1,1,2,17,17,18,19,0,0,0,0,0,0,0,2,0,1,1,1
1,1,1,1,1,2,2,18,19,0,0,0,0,0,2,2,1,1,1,1,1
1,1,1,1,1,0,0,2,2,2,25,2,2,2,1,1,1,1,1,1,1
1,1,1,1,1,1,1,2,2,16,16,16,2,2,1,1,1,1,1,1,1
1,1,1,1,1,1,1,2,2,16,16,16,2,2,1,1,1,1,1,1,1
1,1,1,1,1,1,1,2,2,16,16,16,2,2,1,1,1,1,1,1,1
endlayer

layer
1,1,1,1,1,1,1,32,7,1,1,1,7,32,1,1,1,1,1,1,1
1,1,1,1,1,1,1,32,7,1,1,1,7,32,1,1,1,1,1,1,1
1,1,1,1,1,1,1,32,7,2,2,2,7,32,1,1,1,1,1,1,1
1,1,1,1,1,0,0,2,2,2,2,2,2,2,1,1,1,1,1,1,1
1,1,1,1,1,2,2,0,19,18,18,18,17,0,2,2,1,1,1,1,1
1,1,1,1,2,0,0,0,19,18,18,18,17,0,0,0,2,0,1,1,1
1,1,1,1,2,0,0,0,2,2,2,2,2,0,0,0,2,0,1,1,1
0,0,0,2,0,0,0,2,19,19,19,19,19,2,0,0,0,2,0,0,0
2,31,2,2,0,0,2,19,19,19,19,19,19,19,2,0,0,2,2,31,2
0,0,0,0,0,0,2,19,19,19,19,19,19,19,2,0,0,0,0,0,0
0,0,0,0,0,0,2,19,19,19,2,19,19,19,2,0,0,0,0,0,0
0,0,0,0,0,0,2,19,19,19,19,19,19,19,2,0,0,0,0,0,0
2,31,2,2,0,0,2,19,19,19,19,19,19,19,2,0,0,2,2,31,2
0,0,0,2,0,0,0,2,19,19,19,19,19,2,0,0,0,2,0,0,0
1,1,1,1,2,0,0,0,2,2,2,2,2,0,0,0,2,0,1,1,1
1,1,1,1,2,0,0,0,17,18,18,18,19,0,0,0,2,0,1,1,1
1,1,1,1,1,2,2,0,17,18,18,18,19,0,2,2,1,1,1,1,1
1,1,1,1,1,0,0,2,2,2,2,2,2,2,1,1,1,1,1,1,1
1,1,1,1,1,1,1,32,3,2,2,2,3,32,1,1,1,1,1,1,1
1,1,1,1,1,1,1,32,3,1,1,1,3,32,1,1,1,1,1,1,1
1,1,1,1,1,1,1,32,3,1,1,1,3,32,1,1,1,1,1,1,1
endlayer

layer
1,1,1,1,1,1,1,1,1,1,1,1,1,1,1,1,1,1,1,1,1
1,1,1,1,1,1,1,1,1,1,1,1,1,1,1,1,1,1,1,1,1
1,1,1,1,1,1,1,1,1,2,2,2,1,1,1,1,1,1,1,1,1
1,1,1,1,1,0,0,2,2,2,2,2,2,2,1,1,1,1,1,1,1
1,1,1,1,1,2,2,18,17,0,0,0,0,0,2,2,1,1,1,1,1
1,1,1,1,2,19,19,18,17,0,0,0,0,0,0,0,2,0,1,1,1
1,1,1,1,2,19,19,18,2,0,0,0,2,0,0,0,2,0,1,1,1
0,12,0,2,0,0,0,2,0,0,0,0,0,2,0,0,0,2,0,12,0
2,2,2,2,0,0,2,0,0,0,0,0,0,0,2,0,0,2,2,2,2
15,15,15,15,0,0,2,20,0,0,0,0,0,20,2,0,0,15,15,15,15
0,0,0,0,0,0,2,29,0,0,2,0,0,29,2,0,0,0,0,0,0
12,12,12,12,0,0,2,23,0,24,0,24,0,23,2,0,0,12,12,12,12
2,2,2,2,0,0,2,0,0,0,0,0,0,0,2,0,0,2,2,2,2
0,15,0,2,0,0,0,2,0,0,11,0,0,2,0,0,0,2,0,15,0
1,1,1,1,2,0,0,0,2,2,2,2,2,18,19,19,2,0,1,1,1
1,1,1,1,2,0,0,0,0,0,0,0,17,18,19,19,2,0,1,1,1
1,1,1,1,1,2,2,0,0,0,0,0,17,18,2,2,1,1,1,1,1
1,1,1,1,1,0,0,2,2,2,2,2,2,2,1,1,1,1,1,1,1
1,1,1,1,1,1,1,1,1,2,2,2,1,1,1,1,1,1,1,1,1
1,1,1,1,1,1,1,1,1,1,1,1,1,1,1,1,1,1,1,1,1
1,1,1,1,1,1,1,1,1,1,1,1,1,1,1,1,1,1,1,1,1
endlayer

layer
1,1,1,1,1,1,1,1,1,1,1,1,1,1,1,1,1,1,1,1,1
1,1,1,1,1,1,1,1,1,1,1,1,1,1,1,1,1,1,1,1,1
1,1,1,1,1,1,1,1,1,2,2,2,1,1,1,1,1,1,1,1,1
1,1,1,1,1,0,0,2,2,2,2,2,2,2,1,1,1,1,1,1,1
1,1,1,1,1,2,2,0,0,0,0,0,0,0,2,2,1,1,1,1,1
1,1,1,1,2,17,17,0,0,0,0,0,0,0,0,0,2,0,1,1,1
1,1,1,1,2,17,17,0,2,0,0,0,2,0,0,0,2,0,1,1,1
2,2,2,2,18,18,18,2,0,0,0,0,0,2,0,0,0,2,2,2,2
2,2,2,2,19,19,2,0,0,0,0,0,0,0,2,0,0,2,2,2,2
16,16,16,2,0,0,2,0,0,0,0,0,0,0,2,0,0,2,16,16,16
16,16,16,25,0,0,2,32,0,0,2,0,0,32,2,0,0,25,16,16,16
16,16,16,2,0,0,2,0,0,0,0,0,0,0,2,0,0,2,16,16,16
2,2,2,2,0,0,2,0,0,0,0,0,0,0,2,19,19,2,2,2,2
2,2,2,2,0,0,0,2,0,0,0,0,0,2,18,18,18,2,2,2,2
1,1,1,1,2,0,0,0,2,2,2,2,2,0,17,17,2,0,1,1,1
1,1,1,1,2,0,0,0,0,0,0,0,0,0,17,17,2,0,1,1,1
1,1,1,1,1,2,2,0,0,0,0,0,0,0,2,2,1,1,1,1,1
1,1,1,1,1,0,0,2,2,2,2,2,2,2,1,1,1,1,1,1,1
1,1,1,1,1,1,1,1,1,2,2,2,1,1,1,1,1,1,1,1,1
1,1,1,1,1,1,1,1,1,1,1,1,1,1,1,1,1,1,1,1,1
1,1,1,1,1,1,1,1,1,1,1,1,1,1,1,1,1,1,1,1,1
endlayer

layer
1,1,1,1,1,1,1,1,1,1,1,1,1,1,1,1,1,1,1,1,1
1,1,1,1,1,1,1,1,1,1,1,1,1,1,1,1,1,1,1,1,1
1,1,1,1,1,1,1,1,1,2,2,2,1,1,1,1,1,1,1,1,1
1,1,1,1,1,0,0,2,2,2,2,2,2,2,1,1,1,1,1,1,1
1,1,1,1,1,2,2,0,0,0,0,0,0,0,2,2,1,1,1,1,1
1,1,1,1,2,0,0,0,0,0,0,0,0,0,0,0,2,0,1,1,1
1,1,1,1,2,0,0,0,2,0,0,0,2,0,0,0,2,0,1,1,1
32,32,32,2,0,0,0,2,0,0,0,0,0,2,0,0,0,2,32,32,32
5,5,5,2,17,17,2,0,0,0,0,0,0,0,2,19,19,2,6,6,6
1,1,2,2,18,18,2,0,0,0,0,0,0,0,2,18,18,2,2,0,0
1,1,2,2,18,18,2,0,0,0,2,0,0,0,2,18,18,2,2,0,0
1,1,2,2,18,18,2,0,0,0,0,0,0,0,2,18,18,2,2,0,0
5,5,5,2,19,19,2,0,0,0,0,0,0,0,2,17,17,2,6,6,6
32,32,32,2,0,0,0,2,0,0,0,0,0,2,0,0,0,2,32,32,32
1,1,1,1,2,0,0,0,2,2,2,2,2,0,0,0,2,0,1,1,1
1,1,1,1,2,0,0,0,0,0,0,0,0,0,0,0,2,0,1,1,1
1,1,1,1,1,2,2,0,0,0,0,0,0,0,2,2,1,1,1,1,1
1,1,1,1,1,0,0,2,2,2,2,2,2,2,1,1,1,1,1,1,1
1,1,1,1,1,1,1,1,1,2,2,2,1,1,1,1,1,1,1,1,1
1,1,1,1,1,1,1,1,1,1,1,1,1,1,1,1,1,1,1,1,1
1,1,1,1,1,1,1,1,1,1,1,1,1,1,1,1,1,1,1,1,1
endlayer

layer
1,1,1,1,1,1,1,1,1,1,1,1,1,1,1,1,1,1,1,1,1
1,1,1,1,1,1,1,1,1,12,1,12,1,1,1,1,1,1,1,1,1
1,1,1,1,1,1,1,12,1,2,2,2,1,12,1,1,1,1,1,1,1
1,1,1,1,1,12,0,2,2,2,2,2,2,2,1,12,1,1,1,1,1
1,1,1,1,1,2,2,0,0,0,0,0,0,0,2,2,1,1,1,1,1
1,1,1,14,2,0,0,0,0,0,0,0,0,0,19,19,2,13,1,1,1
1,1,1,1,2,0,0,0,2,13,0,14,2,0,19,19,2,0,1,1,1
1,1,14,2,0,0,0,2,0,0,0,0,0,2,18,18,18,2,13,1,1
1,1,0,2,0,0,2,0,0,0,0,0,0,0,2,17,17,2,0,1,1
1,14,2,2,0,0,2,0,0,0,0,0,0,0,2,0,0,2,2,13,1
1,1,2,2,0,0,2,0,0,0,2,0,0,0,2,0,0,2,2,0,1
1,14,2,2,0,0,2,0,0,0,0,0,0,0,2,0,0,2,2,13,1
1,1,0,2,17,17,2,0,0,0,0,0,0,0,2,0,0,2,0,1,1
1,1,14,2,18,18,18,2,0,0,0,0,0,2,0,0,0,2,13,1,1
1,1,1,1,2,19,19,0,2,2,2,2,2,0,0,0,2,0,1,1,1
1,1,1,14,2,19,19,0,0,0,0,0,0,0,0,0,2,13,1,1,1
1,1,1,1,1,2,2,0,0,0,0,0,0,0,2,2,1,1,1,1,1
1,1,1,1,1,15,0,2,2,2,2,2,2,2,1,15,1,1,1,1,1
1,1,1,1,1,1,1,15,1,2,2,2,1,15,1,1,1,1,1,1,1
1,1,1,1,1,1,1,1,1,15,1,15,1,1,1,1,1,1,1,1,1
1,1,1,1,1,1,1,1,1,1,1,1,1,1,1,1,1,1,1,1,1
endlayer

layer
1,1,1,1,1,1,1,1,1,1,1,1,1,1,1,1,1,1,1,1,1
1,1,1,1,1,1,1,1,1,2,1,2,1,1,1,1,1,1,1,1,1
1,1,1,1,1,1,1,2,1,2,2,2,1,2,1,1,1,1,1,1,1
1,1,1,1,1,2,0,2,2,2,25,2,2,2,1,2,1,1,1,1,1
1,1,1,1,1,2,2,0,0,0,0,0,19,18,2,2,1,1,1,1,1
1,1,1,2,2,0,0,0,0,0,0,0,19,18,17,17,2,2,1,1,1
1,1,1,1,2,0,0,0,2,2,2,2,2,18,17,17,2,0,1,1,1
1,1,2,2,0,0,0,2,0,0,0,0,0,2,0,0,0,2,2,1,1
1,1,0,2,0,0,2,0,0,0,0,0,0,0,2,0,0,2,0,1,1
1,2,2,2,0,0,2,0,0,0,0,0,0,0,2,0,0,2,2,2,1
1,1,2,2,0,0,2,0,0,0,2,0,0,0,2,0,0,2,2,0,1
1,2,2,2,0,0,2,0,0,0,0,0,0,0,2,0,0,2,2,2,1
1,1,0,2,0,0,2,0,0,0,0,0,0,0,2,0,0,2,0,1,1
1,1,2,2,0,0,0,2,0,0,0,0,0,2,0,0,0,2,2,1,1
1,1,1,1,2,17,17,18,2,2,2,2,2,0,0,0,2,0,1,1,1
1,1,1,2,2,17,17,18,19,0,0,0,0,0,0,0,2,2,1,1,1
1,1,1,1,1,2,2,18,19,0,0,0,0,0,2,2,1,1,1,1,1
1,1,1,1,1,2,0,2,2,2,25,2,2,2,1,2,1,1,1,1,1
1,1,1,1,1,1,1,2,1,2,2,2,1,2,1,1,1,1,1,1,1
1,1,1,1,1,1,1,1,1,2,1,2,1,1,1,1,1,1,1,1,1
1,1,1,1,1,1,1,1,1,1,1,1,1,1,1,1,1,1,1,1,1
endlayer

layer
1,1,1,1,1,1,1,1,1,1,1,1,1,1,1,1,1,1,1,1,1
1,1,1,1,1,1,1,1,1,2,2,2,1,1,1,1,1,1,1,1,1
1,1,1,1,1,1,1,2,2,2,2,2,2,2,1,1,1,1,1,1,1
1,1,1,1,1,2,2,2,2,2,2,2,2,2,2,2,1,1,1,1,1
1,1,1,1,2,2,2,0,0,0,19,18,17,0,2,2,2,1,1,1,1
1,1,1,2,2,0,0,0,0,0,19,18,17,0,0,0,2,2,1,1,1
1,1,1,2,2,0,0,0,2,2,2,2,2,0,0,0,2,2,1,1,1
1,1,2,2,0,0,0,2,0,0,0,0,0,2,0,0,0,2,2,1,1
1,1,2,2,0,0,2,0,0,0,0,0,0,0,2,0,0,2,2,1,1
1,2,2,2,0,0,2,0,0,0,0,0,0,0,2,0,0,2,2,2,1
1,2,2,2,0,0,2,0,0,0,2,0,0,0,2,0,0,2,9,2,1
1,2,2,2,0,0,2,0,0,0,0,0,0,0,2,0,0,2,2,2,1
1,1,2,2,0,0,2,0,0,0,0,0,0,0,2,0,0,2,2,1,1
1,1,2,2,0,0,0,2,0,0,0,0,0,2,0,0,0,2,2,1,1
1,1,1,2,2,0,0,0,2,2,2,2,2,0,0,0,2,2,1,1,1
1,1,1,2,2,0,0,0,17,18,19,0,0,0,0,0,2,2,1,1,1
1,1,1,1,2,2,2,0,17,18,19,0,0,0,2,2,2,1,1,1,1
1,1,1,1,1,2,2,2,2,2,2,2,2,2,2,2,1,1,1,1,1
1,1,1,1,1,1,1,2,2,2,2,2,2,2,1,1,1,1,1,1,1
1,1,1,1,1,1,1,1,1,2,2,2,1,1,1,1,1,1,1,1,1
1,1,1,1,1,1,1,1,1,1,1,1,1,1,1,1,1,1,1,1,1
endlayer

layer
1,1,1,1,1,1,1,1,1,1,1,1,1,1,1,1,1,1,1,1,1
1,1,1,1,1,1,1,1,1,1,2,1,1,1,1,1,1,1,1,1,1
1,1,1,1,1,1,1,1,2,16,16,16,2,1,1,1,1,1,1,1,1
1,1,1,1,1,0,2,16,16,16,16,16,16,16,2,1,1,1,1,1,1
1,1,1,1,2,16,16,16,16,16,17,0,0,0,16,16,2,1,1,1,1
1,1,1,1,16,16,16,16,16,16,17,0,0,0,0,0,16,0,1,1,1
1,1,1,2,16,16,16,16,2,16,16,16,2,0,0,0,16,2,1,1,1
1,1,1,16,16,16,16,2,16,16,16,16,16,2,0,0,16,16,1,1,1
1,1,2,16,16,16,2,16,16,16,16,16,16,16,2,16,16,16,2,1,1
1,1,16,16,16,16,16,16,16,16,16,16,16,16,16,16,16,16,16,1,1
1,2,16,16,16,16,16,16,16,16,2,16,16,16,16,16,16,16,16,2,1
1,1,16,16,16,16,16,16,16,16,16,16,16,16,16,16,16,16,16,1,1
1,1,2,16,16,16,2,16,16,16,16,16,16,16,2,16,16,16,2,1,1
1,1,1,16,16,0,0,2,16,16,16,16,16,2,16,16,16,16,1,1,1
1,1,1,2,16,0,0,0,2,16,16,16,2,16,16,16,16,2,1,1,1
1,1,1,1,16,0,0,0,0,0,17,16,16,16,16,16,16,0,1,1,1
1,1,1,1,2,16,16,0,0,0,17,16,16,16,16,16,2,1,1,1,1
1,1,1,1,1,0,2,16,16,16,16,16,16,16,2,1,1,1,1,1,1
1,1,1,1,1,1,1,1,2,16,16,16,2,1,1,1,1,1,1,1,1
1,1,1,1,1,1,1,1,1,1,2,1,1,1,1,1,1,1,1,1,1
1,1,1,1,1,1,1,1,1,1,1,1,1,1,1,1,1,1,1,1,1
endlayer

layer
1,1,1,1,1,1,1,1,1,1,1,1,1,1,1,1,1,1,1,1,1
1,1,1,1,1,1,1,1,1,2,2,2,1,1,1,1,1,1,1,1,1
1,1,1,1,1,1,1,2,2,0,0,0,2,2,1,1,1,1,1,1,1
1,1,1,1,1,2,2,0,0,0,0,0,0,0,2,2,1,1,1,1,1
1,1,1,1,2,0,0,0,0,0,0,0,0,0,0,0,2,1,1,1,1
1,1,1,2,0,0,0,0,0,0,0,0,0,0,0,0,0,2,1,1,1
1,1,1,2,0,0,0,0,2,6,0,5,2,0,0,0,0,2,1,1,1
1,1,2,0,0,0,0,2,0,0,0,0,0,2,0,0,0,0,2,1,1
1,1,2,0,0,0,2,0,0,0,0,0,0,0,2,0,0,0,2,1,1
1,2,0,0,0,0,3,0,0,5,7,6,0,0,3,0,0,0,0,2,1
1,2,0,0,0,0,0,0,0,5,9,6,0,0,0,0,0,0,0,2,1
1,2,0,0,0,0,7,0,0,5,3,3,0,0,7,0,0,0,0,2,1
1,1,2,0,0,0,2,0,0,0,35,0,0,0,2,0,0,0,2,1,1
1,1,2,0,0,0,0,2,0,0,0,0,0,2,0,0,0,0,2,1,1
1,1,1,2,0,0,0,0,2,6,0,5,2,0,0,0,0,2,1,1,1
1,1,1,2,0,0,0,0,0,0,0,0,0,0,0,0,0,2,1,1,1
1,1,1,1,2,0,0,0,0,0,0,0,0,0,0,0,2,1,1,1,1
1,1,1,1,1,2,2,0,0,0,0,0,0,0,2,2,1,1,1,1,1
1,1,1,1,1,1,1,2,2,0,0,0,2,2,1,1,1,1,1,1,1
1,1,1,1,1,1,1,1,1,2,2,2,1,1,1,1,1,1,1,1,1
1,1,1,1,1,1,1,1,1,1,1,1,1,1,1,1,1,1,1,1,1
endlayer

layer
1,1,1,1,1,1,1,1,1,1,1,1,1,1,1,1,1,1,1,1,1
1,1,1,1,1,1,1,1,1,2,1,2,1,1,1,1,1,1,1,1,1
1,1,1,1,1,1,1,2,1,0,1,0,1,2,1,1,1,1,1,1,1
1,1,1,1,1,2,1,0,1,0,1,0,1,0,1,2,1,1,1,1,1
1,1,1,1,1,1,1,0,1,0,1,0,1,0,1,1,1,1,1,1,1
1,1,1,2,0,0,0,0,0,0,0,0,0,0,0,0,0,2,1,1,1
1,1,1,1,1,1,0,0,2,0,0,0,2,0,0,1,1,1,1,1,1
1,1,2,0,0,0,0,31,0,0,0,0,0,31,0,0,0,0,2,1,1
1,1,1,1,1,1,2,0,0,0,0,0,0,0,2,1,1,1,1,1,1
1,2,0,0,0,0,0,0,0,0,0,0,0,0,0,0,0,0,0,2,1
1,1,1,1,1,1,0,0,0,0,2,0,0,0,0,1,1,1,1,1,1
1,2,0,0,0,0,0,0,0,0,0,0,0,0,0,0,0,0,0,2,1
1,1,1,1,1,1,2,0,0,0,0,0,0,0,2,1,1,1,1,1,1
1,1,2,0,0,0,0,31,0,0,0,0,0,31,0,0,0,0,2,1,1
1,1,1,1,1,1,0,0,2,0,0,0,2,0,0,1,1,1,1,1,1
1,1,1,2,0,0,0,0,0,0,0,0,0,0,0,0,0,2,1,1,1
1,1,1,1,1,1,1,0,1,0,1,0,1,0,1,1,1,1,1,1,1
1,1,1,1,1,2,1,0,1,0,1,0,1,0,1,2,1,1,1,1,1
1,1,1,1,1,1,1,2,1,0,1,0,1,2,1,1,1,1,1,1,1
1,1,1,1,1,1,1,1,1,2,1,2,1,1,1,1,1,1,1,1,1
1,1,1,1,1,1,1,1,1,1,1,1,1,1,1,1,1,1,1,1,1
endlayer

layer
1,1,1,1,1,1,1,1,1,1,1,1,1,1,1,1,1,1,1,1,1
1,1,1,1,1,1,1,1,1,1,1,1,1,1,1,1,1,1,1,1,1
1,1,1,1,1,1,1,1,1,1,1,1,1,1,1,1,1,1,1,1,1
1,1,1,1,1,1,1,1,1,1,1,1,1,1,1,1,1,1,1,1,1
1,1,1,1,1,1,1,1,1,1,1,1,1,1,1,1,1,1,1,1,1
1,1,1,1,1,1,0,0,0,0,0,0,0,0,0,1,1,1,1,1,1
1,1,1,1,1,1,0,0,2,0,0,0,2,0,0,1,1,1,1,1,1
1,1,1,1,1,1,0,31,0,0,0,0,0,31,0,1,1,1,1,1,1
1,1,1,1,1,1,2,0,0,0,0,0,0,0,2,1,1,1,1,1,1
1,1,1,1,1,1,0,0,0,0,0,0,0,0,0,1,1,1,1,1,1
1,1,1,1,1,1,0,0,0,0,8,0,0,0,0,1,1,1,1,1,1
1,1,1,1,1,1,0,0,0,0,0,0,0,0,0,1,1,1,1,1,1
1,1,1,1,1,1,2,0,0,0,0,0,0,0,2,1,1,1,1,1,1
1,1,1,1,1,1,0,31,0,0,0,0,0,31,0,1,1,1,1,1,1
1,1,1,1,1,1,0,0,2,0,0,0,2,0,0,1,1,1,1,1,1
1,1,1,1,1,1,0,0,0,0,0,0,0,0,0,1,1,1,1,1,1
1,1,1,1,1,1,1,1,1,1,1,1,1,1,1,1,1,1,1,1,1
1,1,1,1,1,1,1,1,1,1,1,1,1,1,1,1,1,1,1,1,1
1,1,1,1,1,1,1,1,1,1,1,1,1,1,1,1,1,1,1,1,1
1,1,1,1,1,1,1,1,1,1,1,1,1,1,1,1,1,1,1,1,1
1,1,1,1,1,1,1,1,1,1,1,1,1,1,1,1,1,1,1,1,1
endlayer

layer
1,1,1,1,1,1,1,1,1,1,1,1,1,1,1,1,1,1,1,1,1
1,1,1,1,1,1,1,1,1,1,1,1,1,1,1,1,1,1,1,1,1
1,1,1,1,1,1,1,1,1,1,1,1,1,1,1,1,1,1,1,1,1
1,1,1,1,1,1,1,1,1,1,1,1,1,1,1,1,1,1,1,1,1
1,1,1,1,1,1,1,1,1,1,1,1,1,1,1,1,1,1,1,1,1
1,1,1,1,1,1,0,0,0,0,0,0,0,0,0,1,1,1,1,1,1
1,1,1,1,1,1,0,0,2,13,0,14,2,0,0,1,1,1,1,1,1
1,1,1,1,1,1,0,31,0,0,0,0,0,31,0,1,1,1,1,1,1
1,1,1,1,1,1,2,0,0,0,0,0,0,0,2,1,1,1,1,1,1
1,1,1,1,1,1,15,0,0,0,0,0,0,0,15,1,1,1,1,1,1
1,1,1,1,1,1,0,0,0,0,0,0,0,0,0,1,1,1,1,1,1
1,1,1,1,1,1,12,0,0,0,0,0,0,0,12,1,1,1,1,1,1
1,1,1,1,1,1,2,0,0,0,0,0,0,0,2,1,1,1,1,1,1
1,1,1,1,1,1,0,31,0,0,0,0,0,31,0,1,1,1,1,1,1
1,1,1,1,1,1,0,0,2,13,0,14,2,0,0,1,1,1,1,1,1
1,1,1,1,1,1,0,0,0,0,0,0,0,0,0,1,1,1,1,1,1
1,1,1,1,1,1,1,1,1,1,1,1,1,1,1,1,1,1,1,1,1
1,1,1,1,1,1,1,1,1,1,1,1,1,1,1,1,1,1,1,1,1
1,1,1,1,1,1,1,1,1,1,1,1,1,1,1,1,1,1,1,1,1
1,1,1,1,1,1,1,1,1,1,1,1,1,1,1,1,1,1,1,1,1
1,1,1,1,1,1,1,1,1,1,1,1,1,1,1,1,1,1,1,1,1
endlayer

layer
1,1,1,1,1,1,1,1,1,1,1,1,1,1,1,1,1,1,1,1,1
1,1,1,1,1,1,1,1,1,1,1,1,1,1,1,1,1,1,1,1,1
1,1,1,1,1,1,1,1,1,1,1,1,1,1,1,1,1,1,1,1,1
1,1,1,1,1,1,1,1,1,1,1,1,1,1,1,1,1,1,1,1,1
1,1,1,1,1,1,1,1,1,1,1,1,1,1,1,1,1,1,1,1,1
1,1,1,1,1,1,0,0,0,0,0,0,0,0,0,1,1,1,1,1,1
1,1,1,1,1,1,0,0,2,2,2,2,2,0,0,1,1,1,1,1,1
1,1,1,1,1,1,0,2,0,0,0,0,0,2,0,1,1,1,1,1,1
1,1,1,1,1,1,2,0,0,0,0,0,0,0,2,1,1,1,1,1,1
1,1,1,1,1,1,2,0,0,0,0,0,0,0,2,1,1,1,1,1,1
1,1,1,1,1,1,2,0,0,0,0,0,0,0,2,1,1,1,1,1,1
1,1,1,1,1,1,2,0,0,0,0,0,0,0,2,1,1,1,1,1,1
1,1,1,1,1,1,2,0,0,0,0,0,0,0,2,1,1,1,1,1,1
1,1,1,1,1,1,0,2,0,0,0,0,0,2,0,1,1,1,1,1,1
1,1,1,1,1,1,0,0,2,2,2,2,2,0,0,1,1,1,1,1,1
1,1,1,1,1,1,0,0,0,0,0,0,0,0,0,1,1,1,1,1,1
1,1,1,1,1,1,1,1,1,1,1,1,1,1,1,1,1,1,1,1,1
1,1,1,1,1,1,1,1,1,1,1,1,1,1,1,1,1,1,1,1,1
1,1,1,1,1,1,1,1,1,1,1,1,1,1,1,1,1,1,1,1,1
1,1,1,1,1,1,1,1,1,1,1,1,1,1,1,1,1,1,1,1,1
1,1,1,1,1,1,1,1,1,1,1,1,1,1,1,1,1,1,1,1,1
endlayer

layer
1,1,1,1,1,1,1,1,1,1,1,1,1,1,1,1,1,1,1,1,1
1,1,1,1,1,1,1,1,1,1,1,1,1,1,1,1,1,1,1,1,1
1,1,1,1,1,1,1,1,1,1,1,1,1,1,1,1,1,1,1,1,1
1,1,1,1,1,1,1,1,1,1,1,1,1,1,1,1,1,1,1,1,1
1,1,1,1,1,1,1,1,1,1,1,1,1,1,1,1,1,1,1,1,1
1,1,1,1,1,1,0,0,7,7,7,7,7,0,0,1,1,1,1,1,1
1,1,1,1,1,1,0,7,2,2,15,2,2,7,0,1,1,1,1,1,1
1,1,1,1,1,1,5,2,37,0,0,0,36,2,6,1,1,1,1,1,1
1,1,1,1,1,5,2,38,0,0,0,0,0,38,2,6,1,1,1,1,1
1,1,1,1,1,5,2,0,0,0,0,0,0,0,2,6,1,1,1,1,1
1,1,1,1,1,5,13,0,0,0,0,0,0,0,14,6,1,1,1,1,1
1,1,1,1,1,5,2,0,0,0,0,0,0,0,2,6,1,1,1,1,1
1,1,1,1,1,5,2,39,0,0,0,0,0,39,2,6,1,1,1,1,1
1,1,1,1,1,1,5,2,37,0,0,0,36,2,6,1,1,1,1,1,1
1,1,1,1,1,1,0,3,2,2,12,2,2,3,0,1,1,1,1,1,1
1,1,1,1,1,1,0,0,3,3,3,3,3,0,0,1,1,1,1,1,1
1,1,1,1,1,1,1,1,1,1,1,1,1,1,1,1,1,1,1,1,1
1,1,1,1,1,1,1,1,1,1,1,1,1,1,1,1,1,1,1,1,1
1,1,1,1,1,1,1,1,1,1,1,1,1,1,1,1,1,1,1,1,1
1,1,1,1,1,1,1,1,1,1,1,1,1,1,1,1,1,1,1,1,1
1,1,1,1,1,1,1,1,1,1,1,1,1,1,1,1,1,1,1,1,1
endlayer

layer
1,1,1,1,1,1,1,1,1,1,1,1,1,1,1,1,1,1,1,1,1
1,1,1,1,1,1,1,1,1,1,1,1,1,1,1,1,1,1,1,1,1
1,1,1,1,1,1,1,1,1,1,1,1,1,1,1,1,1,1,1,1,1
1,1,1,1,1,1,1,1,1,1,1,1,1,1,1,1,1,1,1,1,1
1,1,1,1,1,1,1,1,1,1,1,1,1,1,1,1,1,1,1,1,1
1,1,1,1,1,1,0,0,0,0,0,0,0,0,0,1,1,1,1,1,1
1,1,1,1,1,1,0,0,2,2,2,2,2,0,0,1,1,1,1,1,1
1,1,1,1,1,1,0,2,16,37,38,36,16,2,0,1,1,1,1,1,1
1,1,1,1,1,1,2,16,19,0,0,0,19,16,2,1,1,1,1,1,1
1,1,1,1,1,1,2,38,0,0,0,0,0,38,2,1,1,1,1,1,1
1,1,1,1,1,1,2,37,0,0,0,0,0,36,2,1,1,1,1,1,1
1,1,1,1,1,1,2,39,0,0,0,0,0,39,2,1,1,1,1,1,1
1,1,1,1,1,1,2,16,19,0,0,0,19,16,2,1,1,1,1,1,1
1,1,1,1,1,1,0,2,16,37,39,36,16,2,0,1,1,1,1,1,1
1,1,1,1,1,1,0,0,2,2,2,2,2,0,0,1,1,1,1,1,1
1,1,1,1,1,1,0,0,0,0,0,0,0,0,0,1,1,1,1,1,1
1,1,1,1,1,1,1,1,1,1,1,1,1,1,1,1,1,1,1,1,1
1,1,1,1,1,1,1,1,1,1,1,1,1,1,1,1,1,1,1,1,1
1,1,1,1,1,1,1,1,1,1,1,1,1,1,1,1,1,1,1,1,1
1,1,1,1,1,1,1,1,1,1,1,1,1,1,1,1,1,1,1,1,1
1,1,1,1,1,1,1,1,1,1,1,1,1,1,1,1,1,1,1,1,1
endlayer

layer
1,1,1,1,1,1,1,1,1,1,1,1,1,1,1,1,1,1,1,1,1
1,1,1,1,1,1,1,1,1,1,1,1,1,1,1,1,1,1,1,1,1
1,1,1,1,1,1,1,1,1,1,1,1,1,1,1,1,1,1,1,1,1
1,1,1,1,1,1,1,1,1,1,1,1,1,1,1,1,1,1,1,1,1
1,1,1,1,1,1,1,1,40,40,40,40,40,1,1,1,1,1,1,1,1
1,1,1,1,1,1,42,40,16,16,16,16,16,40,41,1,1,1,1,1,1
1,1,1,1,1,40,16,16,2,2,2,2,2,16,16,40,1,1,1,1,1
1,1,1,1,1,42,16,2,16,16,16,16,16,2,16,41,1,1,1,1,1
1,1,1,1,42,16,2,16,16,37,38,36,16,16,2,16,41,1,1,1,1
1,1,1,1,42,16,2,16,38,19,0,19,38,16,2,16,41,1,1,1,1
1,1,1,1,42,16,2,16,37,0,0,0,36,16,2,16,41,1,1,1,1
1,1,1,1,42,16,2,16,39,19,0,19,39,16,2,16,41,1,1,1,1
1,1,1,1,42,16,2,16,16,37,39,36,16,16,2,16,41,1,1,1,1
1,1,1,1,1,42,16,2,16,16,16,16,16,2,16,41,1,1,1,1,1
1,1,1,1,1,43,16,16,2,2,2,2,2,16,16,43,1,1,1,1,1
1,1,1,1,1,1,42,43,16,16,16,16,16,43,41,1,1,1,1,1,1
1,1,1,1,1,1,1,1,43,43,43,43,43,1,1,1,1,1,1,1,1
1,1,1,1,1,1,1,1,1,1,1,1,1,1,1,1,1,1,1,1,1
1,1,1,1,1,1,1,1,1,1,1,1,1,1,1,1,1,1,1,1,1
1,1,1,1,1,1,1,1,1,1,1,1,1,1,1,1,1,1,1,1,1
1,1,1,1,1,1,1,1,1,1,1,1,1,1,1,1,1,1,1,1,1
endlayer

layer
1,1,1,1,1,1,1,1,1,1,1,1,1,1,1,1,1,1,1,1,1
1,1,1,1,1,1,1,1,1,1,1,1,1,1,1,1,1,1,1,1,1
1,1,1,1,1,1,1,1,1,1,1,1,1,1,1,1,1,1,1,1,1
1,1,1,1,1,1,1,1,1,1,1,1,1,1,1,1,1,1,1,1,1
1,1,1,1,1,1,1,1,1,1,1,1,1,1,1,1,1,1,1,1,1
1,1,1,1,1,1,1,1,1,40,40,40,1,1,1,1,1,1,1,1,1
1,1,1,1,1,1,1,40,16,16,16,16,16,41,1,1,1,1,1,1,1
1,1,1,1,1,1,42,16,16,16,16,16,16,16,40,1,1,1,1,1,1
1,1,1,1,1,1,16,16,16,16,16,16,16,16,16,1,1,1,1,1,1
1,1,1,1,1,42,16,16,16,16,16,16,16,16,16,41,1,1,1,1,1
1,1,1,1,1,42,16,16,16,16,25,16,16,16,16,41,1,1,1,1,1
1,1,1,1,1,42,16,16,16,16,16,16,16,16,16,41,1,1,1,1,1
1,1,1,1,1,1,16,16,16,16,16,16,16,16,16,1,1,1,1,1,1
1,1,1,1,1,1,43,16,16,16,16,16,16,16,43,1,1,1,1,1,1
1,1,1,1,1,1,1,42,16,16,16,16,16,41,1,1,1,1,1,1,1
1,1,1,1,1,1,1,1,1,43,43,43,1,1,1,1,1,1,1,1,1
1,1,1,1,1,1,1,1,1,1,1,1,1,1,1,1,1,1,1,1,1
1,1,1,1,1,1,1,1,1,1,1,1,1,1,1,1,1,1,1,1,1
1,1,1,1,1,1,1,1,1,1,1,1,1,1,1,1,1,1,1,1,1
1,1,1,1,1,1,1,1,1,1,1,1,1,1,1,1,1,1,1,1,1
1,1,1,1,1,1,1,1,1,1,1,1,1,1,1,1,1,1,1,1,1
endlayer

layer
1,1,1,1,1,1,1,1,1,1,1,1,1,1,1,1,1,1,1,1,1
1,1,1,1,1,1,1,1,1,1,1,1,1,1,1,1,1,1,1,1,1
1,1,1,1,1,1,1,1,1,1,1,1,1,1,1,1,1,1,1,1,1
1,1,1,1,1,1,1,1,1,1,1,1,1,1,1,1,1,1,1,1,1
1,1,1,1,1,1,1,1,1,1,1,1,1,1,1,1,1,1,1,1,1
1,1,1,1,1,1,1,1,1,1,1,1,1,1,1,1,1,1,1,1,1
1,1,1,1,1,1,1,1,1,40,40,40,1,1,1,1,1,1,1,1,1
1,1,1,1,1,1,1,1,40,16,16,16,40,1,1,1,1,1,1,1,1
1,1,1,1,1,1,1,42,16,16,16,16,16,41,1,1,1,1,1,1,1
1,1,1,1,1,1,42,16,16,16,16,16,16,16,41,1,1,1,1,1,1
1,1,1,1,1,1,42,16,16,16,16,16,16,16,41,1,1,1,1,1,1
1,1,1,1,1,1,42,16,16,16,16,16,16,16,41,1,1,1,1,1,1
1,1,1,1,1,1,1,42,16,16,16,16,16,41,1,1,1,1,1,1,1
1,1,1,1,1,1,1,1,43,16,16,16,43,1,1,1,1,1,1,1,1
1,1,1,1,1,1,1,1,1,43,43,43,1,1,1,1,1,1,1,1,1
1,1,1,1,1,1,1,1,1,1,1,1,1,1,1,1,1,1,1,1,1
1,1,1,1,1,1,1,1,1,1,1,1,1,1,1,1,1,1,1,1,1
1,1,1,1,1,1,1,1,1,1,1,1,1,1,1,1,1,1,1,1,1
1,1,1,1,1,1,1,1,1,1,1,1,1,1,1,1,1,1,1,1,1
1,1,1,1,1,1,1,1,1,1,1,1,1,1,1,1,1,1,1,1,1
1,1,1,1,1,1,1,1,1,1,1,1,1,1,1,1,1,1,1,1,1
endlayer

layer
1,1,1,1,1,1,1,1,1,1,1,1,1,1,1,1,1,1,1,1,1
1,1,1,1,1,1,1,1,1,1,1,1,1,1,1,1,1,1,1,1,1
1,1,1,1,1,1,1,1,1,1,1,1,1,1,1,1,1,1,1,1,1
1,1,1,1,1,1,1,1,1,1,1,1,1,1,1,1,1,1,1,1,1
1,1,1,1,1,1,1,1,1,1,1,1,1,1,1,1,1,1,1,1,1
1,1,1,1,1,1,1,1,1,1,1,1,1,1,1,1,1,1,1,1,1
1,1,1,1,1,1,1,1,1,1,1,1,1,1,1,1,1,1,1,1,1
1,1,1,1,1,1,1,1,1,16,16,16,1,1,1,1,1,1,1,1,1
1,1,1,1,1,1,1,1,16,16,16,16,16,1,1,1,1,1,1,1,1
1,1,1,1,1,1,1,16,16,16,16,16,16,16,1,1,1,1,1,1,1
1,1,1,1,1,1,1,16,16,16,16,16,16,16,1,1,1,1,1,1,1
1,1,1,1,1,1,1,16,16,16,16,16,16,16,1,1,1,1,1,1,1
1,1,1,1,1,1,1,1,16,16,16,16,16,1,1,1,1,1,1,1,1
1,1,1,1,1,1,1,1,1,16,16,16,1,1,1,1,1,1,1,1,1
1,1,1,1,1,1,1,1,1,1,1,1,1,1,1,1,1,1,1,1,1
1,1,1,1,1,1,1,1,1,1,1,1,1,1,1,1,1,1,1,1,1
1,1,1,1,1,1,1,1,1,1,1,1,1,1,1,1,1,1,1,1,1
1,1,1,1,1,1,1,1,1,1,1,1,1,1,1,1,1,1,1,1,1
1,1,1,1,1,1,1,1,1,1,1,1,1,1,1,1,1,1,1,1,1
1,1,1,1,1,1,1,1,1,1,1,1,1,1,1,1,1,1,1,1,1
1,1,1,1,1,1,1,1,1,1,1,1,1,1,1,1,1,1,1,1,1
endlayer

layer
1,1,1,1,1,1,1,1,1,1,1,1,1,1,1,1,1,1,1,1,1
1,1,1,1,1,1,1,1,1,1,1,1,1,1,1,1,1,1,1,1,1
1,1,1,1,1,1,1,1,1,1,1,1,1,1,1,1,1,1,1,1,1
1,1,1,1,1,1,1,1,1,1,1,1,1,1,1,1,1,1,1,1,1
1,1,1,1,1,1,1,1,1,1,1,1,1,1,1,1,1,1,1,1,1
1,1,1,1,1,1,1,1,1,1,1,1,1,1,1,1,1,1,1,1,1
1,1,1,1,1,1,1,1,1,1,1,1,1,1,1,1,1,1,1,1,1
1,1,1,1,1,1,1,1,1,1,40,1,1,1,1,1,1,1,1,1,1
1,1,1,1,1,1,1,1,1,16,16,16,1,1,1,1,1,1,1,1,1
1,1,1,1,1,1,1,1,16,16,16,16,16,1,1,1,1,1,1,1,1
1,1,1,1,1,1,1,42,16,16,16,16,16,41,1,1,1,1,1,1,1
1,1,1,1,1,1,1,1,16,16,16,16,16,1,1,1,1,1,1,1,1
1,1,1,1,1,1,1,1,1,16,16,16,1,1,1,1,1,1,1,1,1
1,1,1,1,1,1,1,1,1,1,43,1,1,1,1,1,1,1,1,1,1
1,1,1,1,1,1,1,1,1,1,1,1,1,1,1,1,1,1,1,1,1
1,1,1,1,1,1,1,1,1,1,1,1,1,1,1,1,1,1,1,1,1
1,1,1,1,1,1,1,1,1,1,1,1,1,1,1,1,1,1,1,1,1
1,1,1,1,1,1,1,1,1,1,1,1,1,1,1,1,1,1,1,1,1
1,1,1,1,1,1,1,1,1,1,1,1,1,1,1,1,1,1,1,1,1
1,1,1,1,1,1,1,1,1,1,1,1,1,1,1,1,1,1,1,1,1
1,1,1,1,1,1,1,1,1,1,1,1,1,1,1,1,1,1,1,1,1
endlayer

layer
1,1,1,1,1,1,1,1,1,1,1,1,1,1,1,1,1,1,1,1,1
1,1,1,1,1,1,1,1,1,1,1,1,1,1,1,1,1,1,1,1,1
1,1,1,1,1,1,1,1,1,1,1,1,1,1,1,1,1,1,1,1,1
1,1,1,1,1,1,1,1,1,1,1,1,1,1,1,1,1,1,1,1,1
1,1,1,1,1,1,1,1,1,1,1,1,1,1,1,1,1,1,1,1,1
1,1,1,1,1,1,1,1,1,1,1,1,1,1,1,1,1,1,1,1,1
1,1,1,1,1,1,1,1,1,1,1,1,1,1,1,1,1,1,1,1,1
1,1,1,1,1,1,1,1,1,1,1,1,1,1,1,1,1,1,1,1,1
1,1,1,1,1,1,1,1,1,40,16,40,1,1,1,1,1,1,1,1,1
1,1,1,1,1,1,1,1,42,16,16,16,41,1,1,1,1,1,1,1,1
1,1,1,1,1,1,1,1,16,16,16,16,16,1,1,1,1,1,1,1,1
1,1,1,1,1,1,1,1,42,16,16,16,41,1,1,1,1,1,1,1,1
1,1,1,1,1,1,1,1,1,43,16,43,1,1,1,1,1,1,1,1,1
1,1,1,1,1,1,1,1,1,1,1,1,1,1,1,1,1,1,1,1,1
1,1,1,1,1,1,1,1,1,1,1,1,1,1,1,1,1,1,1,1,1
1,1,1,1,1,1,1,1,1,1,1,1,1,1,1,1,1,1,1,1,1
1,1,1,1,1,1,1,1,1,1,1,1,1,1,1,1,1,1,1,1,1
1,1,1,1,1,1,1,1,1,1,1,1,1,1,1,1,1,1,1,1,1
1,1,1,1,1,1,1,1,1,1,1,1,1,1,1,1,1,1,1,1,1
1,1,1,1,1,1,1,1,1,1,1,1,1,1,1,1,1,1,1,1,1
1,1,1,1,1,1,1,1,1,1,1,1,1,1,1,1,1,1,1,1,1
endlayer

layer
1,1,1,1,1,1,1,1,1,1,1,1,1,1,1,1,1,1,1,1,1
1,1,1,1,1,1,1,1,1,1,1,1,1,1,1,1,1,1,1,1,1
1,1,1,1,1,1,1,1,1,1,1,1,1,1,1,1,1,1,1,1,1
1,1,1,1,1,1,1,1,1,1,1,1,1,1,1,1,1,1,1,1,1
1,1,1,1,1,1,1,1,1,1,1,1,1,1,1,1,1,1,1,1,1
1,1,1,1,1,1,1,1,1,1,1,1,1,1,1,1,1,1,1,1,1
1,1,1,1,1,1,1,1,1,1,1,1,1,1,1,1,1,1,1,1,1
1,1,1,1,1,1,1,1,1,1,1,1,1,1,1,1,1,1,1,1,1
1,1,1,1,1,1,1,1,1,1,40,1,1,1,1,1,1,1,1,1,1
1,1,1,1,1,1,1,1,1,16,16,16,1,1,1,1,1,1,1,1,1
1,1,1,1,1,1,1,1,42,16,16,16,41,1,1,1,1,1,1,1,1
1,1,1,1,1,1,1,1,1,16,16,16,1,1,1,1,1,1,1,1,1
1,1,1,1,1,1,1,1,1,1,43,1,1,1,1,1,1,1,1,1,1
1,1,1,1,1,1,1,1,1,1,1,1,1,1,1,1,1,1,1,1,1
1,1,1,1,1,1,1,1,1,1,1,1,1,1,1,1,1,1,1,1,1
1,1,1,1,1,1,1,1,1,1,1,1,1,1,1,1,1,1,1,1,1
1,1,1,1,1,1,1,1,1,1,1,1,1,1,1,1,1,1,1,1,1
1,1,1,1,1,1,1,1,1,1,1,1,1,1,1,1,1,1,1,1,1
1,1,1,1,1,1,1,1,1,1,1,1,1,1,1,1,1,1,1,1,1
1,1,1,1,1,1,1,1,1,1,1,1,1,1,1,1,1,1,1,1,1
1,1,1,1,1,1,1,1,1,1,1,1,1,1,1,1,1,1,1,1,1
endlayer

layer
1,1,1,1,1,1,1,1,1,1,1,1,1,1,1,1,1,1,1,1,1
1,1,1,1,1,1,1,1,1,1,1,1,1,1,1,1,1,1,1,1,1
1,1,1,1,1,1,1,1,1,1,1,1,1,1,1,1,1,1,1,1,1
1,1,1,1,1,1,1,1,1,1,1,1,1,1,1,1,1,1,1,1,1
1,1,1,1,1,1,1,1,1,1,1,1,1,1,1,1,1,1,1,1,1
1,1,1,1,1,1,1,1,1,1,1,1,1,1,1,1,1,1,1,1,1
1,1,1,1,1,1,1,1,1,1,1,1,1,1,1,1,1,1,1,1,1
1,1,1,1,1,1,1,1,1,1,1,1,1,1,1,1,1,1,1,1,1
1,1,1,1,1,1,1,1,1,1,1,1,1,1,1,1,1,1,1,1,1
1,1,1,1,1,1,1,1,1,17,16,17,1,1,1,1,1,1,1,1,1
1,1,1,1,1,1,1,1,1,16,16,16,1,1,1,1,1,1,1,1,1
1,1,1,1,1,1,1,1,1,17,16,17,1,1,1,1,1,1,1,1,1
1,1,1,1,1,1,1,1,1,1,1,1,1,1,1,1,1,1,1,1,1
1,1,1,1,1,1,1,1,1,1,1,1,1,1,1,1,1,1,1,1,1
1,1,1,1,1,1,1,1,1,1,1,1,1,1,1,1,1,1,1,1,1
1,1,1,1,1,1,1,1,1,1,1,1,1,1,1,1,1,1,1,1,1
1,1,1,1,1,1,1,1,1,1,1,1,1,1,1,1,1,1,1,1,1
1,1,1,1,1,1,1,1,1,1,1,1,1,1,1,1,1,1,1,1,1
1,1,1,1,1,1,1,1,1,1,1,1,1,1,1,1,1,1,1,1,1
1,1,1,1,1,1,1,1,1,1,1,1,1,1,1,1,1,1,1,1,1
1,1,1,1,1,1,1,1,1,1,1,1,1,1,1,1,1,1,1,1,1
endlayer

layer
1,1,1,1,1,1,1,1,1,1,1,1,1,1,1,1,1,1,1,1,1
1,1,1,1,1,1,1,1,1,1,1,1,1,1,1,1,1,1,1,1,1
1,1,1,1,1,1,1,1,1,1,1,1,1,1,1,1,1,1,1,1,1
1,1,1,1,1,1,1,1,1,1,1,1,1,1,1,1,1,1,1,1,1
1,1,1,1,1,1,1,1,1,1,1,1,1,1,1,1,1,1,1,1,1
1,1,1,1,1,1,1,1,1,1,1,1,1,1,1,1,1,1,1,1,1
1,1,1,1,1,1,1,1,1,1,1,1,1,1,1,1,1,1,1,1,1
1,1,1,1,1,1,1,1,1,1,1,1,1,1,1,1,1,1,1,1,1
1,1,1,1,1,1,1,1,1,1,1,1,1,1,1,1,1,1,1,1,1
1,1,1,1,1,1,1,1,1,1,40,1,1,1,1,1,1,1,1,1,1
1,1,1,1,1,1,1,1,1,42,16,41,1,1,1,1,1,1,1,1,1
1,1,1,1,1,1,1,1,1,1,43,1,1,1,1,1,1,1,1,1,1
1,1,1,1,1,1,1,1,1,1,1,1,1,1,1,1,1,1,1,1,1
1,1,1,1,1,1,1,1,1,1,1,1,1,1,1,1,1,1,1,1,1
1,1,1,1,1,1,1,1,1,1,1,1,1,1,1,1,1,1,1,1,1
1,1,1,1,1,1,1,1,1,1,1,1,1,1,1,1,1,1,1,1,1
1,1,1,1,1,1,1,1,1,1,1,1,1,1,1,1,1,1,1,1,1
1,1,1,1,1,1,1,1,1,1,1,1,1,1,1,1,1,1,1,1,1
1,1,1,1,1,1,1,1,1,1,1,1,1,1,1,1,1,1,1,1,1
1,1,1,1,1,1,1,1,1,1,1,1,1,1,1,1,1,1,1,1,1
1,1,1,1,1,1,1,1,1,1,1,1,1,1,1,1,1,1,1,1,1
endlayer

layer
1,1,1,1,1,1,1,1,1,1,1,1,1,1,1,1,1,1,1,1,1
1,1,1,1,1,1,1,1,1,1,1,1,1,1,1,1,1,1,1,1,1
1,1,1,1,1,1,1,1,1,1,1,1,1,1,1,1,1,1,1,1,1
1,1,1,1,1,1,1,1,1,1,1,1,1,1,1,1,1,1,1,1,1
1,1,1,1,1,1,1,1,1,1,1,1,1,1,1,1,1,1,1,1,1
1,1,1,1,1,1,1,1,1,1,1,1,1,1,1,1,1,1,1,1,1
1,1,1,1,1,1,1,1,1,1,1,1,1,1,1,1,1,1,1,1,1
1,1,1,1,1,1,1,1,1,1,1,1,1,1,1,1,1,1,1,1,1
1,1,1,1,1,1,1,1,1,1,1,1,1,1,1,1,1,1,1,1,1
1,1,1,1,1,1,1,1,1,1,1,1,1,1,1,1,1,1,1,1,1
1,1,1,1,1,1,1,1,1,1,16,1,1,1,1,1,1,1,1,1,1
1,1,1,1,1,1,1,1,1,1,1,1,1,1,1,1,1,1,1,1,1
1,1,1,1,1,1,1,1,1,1,1,1,1,1,1,1,1,1,1,1,1
1,1,1,1,1,1,1,1,1,1,1,1,1,1,1,1,1,1,1,1,1
1,1,1,1,1,1,1,1,1,1,1,1,1,1,1,1,1,1,1,1,1
1,1,1,1,1,1,1,1,1,1,1,1,1,1,1,1,1,1,1,1,1
1,1,1,1,1,1,1,1,1,1,1,1,1,1,1,1,1,1,1,1,1
1,1,1,1,1,1,1,1,1,1,1,1,1,1,1,1,1,1,1,1,1
1,1,1,1,1,1,1,1,1,1,1,1,1,1,1,1,1,1,1,1,1
1,1,1,1,1,1,1,1,1,1,1,1,1,1,1,1,1,1,1,1,1
1,1,1,1,1,1,1,1,1,1,1,1,1,1,1,1,1,1,1,1,1
endlayer

layer
1,1,1,1,1,1,1,1,1,1,1,1,1,1,1,1,1,1,1,1,1
1,1,1,1,1,1,1,1,1,1,1,1,1,1,1,1,1,1,1,1,1
1,1,1,1,1,1,1,1,1,1,1,1,1,1,1,1,1,1,1,1,1
1,1,1,1,1,1,1,1,1,1,1,1,1,1,1,1,1,1,1,1,1
1,1,1,1,1,1,1,1,1,1,1,1,1,1,1,1,1,1,1,1,1
1,1,1,1,1,1,1,1,1,1,1,1,1,1,1,1,1,1,1,1,1
1,1,1,1,1,1,1,1,1,1,1,1,1,1,1,1,1,1,1,1,1
1,1,1,1,1,1,1,1,1,1,1,1,1,1,1,1,1,1,1,1,1
1,1,1,1,1,1,1,1,1,1,1,1,1,1,1,1,1,1,1,1,1
1,1,1,1,1,1,1,1,1,1,1,1,1,1,1,1,1,1,1,1,1
1,1,1,1,1,1,1,1,1,1,16,1,1,1,1,1,1,1,1,1,1
1,1,1,1,1,1,1,1,1,1,1,1,1,1,1,1,1,1,1,1,1
1,1,1,1,1,1,1,1,1,1,1,1,1,1,1,1,1,1,1,1,1
1,1,1,1,1,1,1,1,1,1,1,1,1,1,1,1,1,1,1,1,1
1,1,1,1,1,1,1,1,1,1,1,1,1,1,1,1,1,1,1,1,1
1,1,1,1,1,1,1,1,1,1,1,1,1,1,1,1,1,1,1,1,1
1,1,1,1,1,1,1,1,1,1,1,1,1,1,1,1,1,1,1,1,1
1,1,1,1,1,1,1,1,1,1,1,1,1,1,1,1,1,1,1,1,1
1,1,1,1,1,1,1,1,1,1,1,1,1,1,1,1,1,1,1,1,1
1,1,1,1,1,1,1,1,1,1,1,1,1,1,1,1,1,1,1,1,1
1,1,1,1,1,1,1,1,1,1,1,1,1,1,1,1,1,1,1,1,1
endlayer

