
# Created by Ruins mod version 16.7 Ingame Parser
# authoring Player: ST753M

weight=4
uniqueMinDistance=500
embed_into_distance=4
acceptable_target_blocks=
unacceptable_target_blocks=flowing_water,water,flowing_lava,lava,ice,bedrock,netherrack,nether_brick,nether_brick_fence,soul_sand,quartz_ore,end_stone,obsidian,iron_bars,Natura:Cloud,slime_grass,slime_congealed,slime_dirt
dimensions=16,21,21
allowable_overhang=6
max_leveling=0
leveling_buffer=0
preserve_water=0
preserve_lava=0

biomesToSpawnIn=cherry_blossom_grove,cherry blossom grove,bamboo_forest,bamboo forest,eucalyptus_forest,maple_woods,maple woods,redwood_forest

=0,100,preserveBlock
rule1=0,100,preserveBlock
rule2=0,100,minecraft:stone-3
rule3=0,100,minecraft:planks-5
rule4=0,100,minecraft:log-1
rule5=0,100,biomesoplenty:cherry_stairs-0
rule6=0,100,biomesoplenty:cherry_stairs-5
rule7=0,100,minecraft:wooden_slab-5
rule8=0,100,minecraft:wooden_slab-13
rule9=0,100,biomesoplenty:wood_slab_0-9
rule10=0,100,biomesoplenty:planks_0-1
rule11=0,100,biomesoplenty:cherry_stairs-4
rule12=0,100,biomesoplenty:cherry_stairs-7
rule13=0,100,biomesoplenty:cherry_stairs-6
rule14=0,100,biomesoplenty:double_wood_slab_0-1
rule15=0,100,biomesoplenty:wood_slab_0-1
rule16=0,100,biomesoplenty:cherry_stairs-2
rule17=0,100,biomesoplenty:cherry_stairs-3
rule18=0,100,biomesoplenty:cherry_fence-0
rule19=0,100,biomesoplenty:cherry_stairs-1
rule20=0,100,minecraft:log-9
rule21=0,100,minecraft:log-5
rule22=0,50,ChestGenHook:chests/simple_dungeon:5-2

layer
1,1,1,1,1,1,1,1,1,1,1,1,1,1,1,1,1,1,1,1,1
1,1,1,1,1,1,1,1,1,1,1,1,1,1,1,1,1,1,1,1,1
1,1,1,1,1,1,1,1,1,1,1,1,1,1,1,1,1,1,1,1,1
1,1,1,1,1,1,1,1,1,1,1,1,1,1,1,1,1,1,1,1,1
1,1,1,1,2,2,2,2,2,2,2,2,2,2,2,2,2,1,1,1,1
1,1,1,1,2,2,2,2,2,2,2,2,2,2,2,2,2,1,1,1,1
1,1,1,1,2,2,2,2,2,2,2,2,2,2,2,2,2,1,1,1,1
1,1,1,1,2,2,2,2,2,2,2,2,2,2,2,2,2,1,1,1,1
1,1,1,1,2,2,2,2,2,2,2,2,2,2,2,2,2,1,1,1,1
1,1,1,1,2,2,2,2,2,2,2,2,2,2,2,2,2,1,1,1,1
1,1,1,1,2,2,2,2,2,2,2,2,2,2,2,2,2,1,1,1,1
1,1,1,1,2,2,2,2,2,2,2,2,2,2,2,2,2,1,1,1,1
1,1,1,1,2,2,2,2,2,2,2,2,2,2,2,2,2,1,1,1,1
1,1,1,1,2,2,2,2,2,2,2,2,2,2,2,2,2,1,1,1,1
1,1,1,1,2,2,2,2,2,2,2,2,2,2,2,2,2,1,1,1,1
1,1,1,1,2,2,2,2,2,2,2,2,2,2,2,2,2,1,1,1,1
1,1,1,1,2,2,2,2,2,2,2,2,2,2,2,2,2,1,1,1,1
1,1,1,1,1,1,1,1,1,1,1,1,1,1,1,1,1,1,1,1,1
1,1,1,1,1,1,1,1,1,1,1,1,1,1,1,1,1,1,1,1,1
1,1,1,1,1,1,1,1,1,1,1,1,1,1,1,1,1,1,1,1,1
1,1,1,1,1,1,1,1,1,1,1,1,1,1,1,1,1,1,1,1,1
endlayer

layer
1,1,1,1,1,1,1,1,1,1,1,1,1,1,1,1,1,1,1,1,1
1,1,1,1,1,1,1,1,1,1,1,1,1,1,1,1,1,1,1,1,1
1,1,1,1,1,1,1,1,1,1,1,1,1,1,1,1,1,1,1,1,1
1,1,1,1,1,1,1,1,1,1,1,1,1,1,1,1,1,1,1,1,1
1,1,1,1,2,2,2,2,2,2,2,2,2,2,2,2,2,1,1,1,1
1,1,1,1,2,2,2,2,2,2,2,2,2,2,2,2,2,1,1,1,1
1,1,1,1,2,2,2,2,2,2,2,2,2,2,2,2,2,1,1,1,1
1,1,1,1,2,2,2,2,2,2,2,2,2,2,2,2,2,1,1,1,1
1,1,1,1,2,2,2,2,2,2,2,2,2,2,2,2,2,1,1,1,1
1,1,1,1,2,2,2,2,2,2,2,2,2,2,2,2,2,1,1,1,1
1,1,1,1,2,2,2,2,2,2,2,2,2,2,2,2,2,1,1,1,1
1,1,1,1,2,2,2,2,2,2,2,2,2,2,2,2,2,1,1,1,1
1,1,1,1,2,2,2,2,2,2,2,2,2,2,2,2,2,1,1,1,1
1,1,1,1,2,2,2,2,2,2,2,2,2,2,2,2,2,1,1,1,1
1,1,1,1,2,2,2,2,2,2,2,2,2,2,2,2,2,1,1,1,1
1,1,1,1,2,2,2,2,2,2,2,2,2,2,2,2,2,1,1,1,1
1,1,1,1,2,2,2,2,2,2,2,2,2,2,2,2,2,1,1,1,1
1,1,1,1,1,1,1,1,1,1,1,1,1,1,1,1,1,1,1,1,1
1,1,1,1,1,1,1,1,1,1,1,1,1,1,1,1,1,1,1,1,1
1,1,1,1,1,1,1,1,1,1,1,1,1,1,1,1,1,1,1,1,1
1,1,1,1,1,1,1,1,1,1,1,1,1,1,1,1,1,1,1,1,1
endlayer

layer
1,1,1,1,1,1,1,1,1,1,1,1,1,1,1,1,1,1,1,1,1
1,1,1,1,1,1,1,1,1,1,1,1,1,1,1,1,1,1,1,1,1
1,1,1,1,1,1,1,1,1,1,1,1,1,1,1,1,1,1,1,1,1
1,1,1,1,1,1,1,1,1,1,1,1,1,1,1,1,1,1,1,1,1
1,1,1,1,2,2,2,2,2,2,2,2,2,2,2,2,2,1,1,1,1
1,1,1,1,2,2,2,2,2,2,2,2,2,2,2,2,2,1,1,1,1
1,1,1,1,2,2,2,2,2,2,2,2,2,2,2,2,2,1,1,1,1
1,1,1,1,2,2,2,2,2,2,2,2,2,2,2,2,2,1,1,1,1
1,1,1,1,2,2,2,2,2,2,2,2,2,2,2,2,2,1,1,1,1
1,1,1,1,2,2,2,2,2,2,2,2,2,2,2,2,2,1,1,1,1
1,1,1,1,2,2,2,2,2,2,2,2,2,2,2,2,2,1,1,1,1
1,1,1,1,2,2,2,2,2,2,2,2,2,2,2,2,2,1,1,1,1
1,1,1,1,2,2,2,2,2,2,2,2,2,2,2,2,2,1,1,1,1
1,1,1,1,2,2,2,2,2,2,2,2,2,2,2,2,2,1,1,1,1
1,1,1,1,2,2,2,2,2,2,2,2,2,2,2,2,2,1,1,1,1
1,1,1,1,2,2,2,2,2,2,2,2,2,2,2,2,2,1,1,1,1
1,1,1,1,2,2,2,2,2,2,2,2,2,2,2,2,2,1,1,1,1
1,1,1,1,1,1,1,1,1,1,1,1,1,1,1,1,1,1,1,1,1
1,1,1,1,1,1,1,1,1,1,1,1,1,1,1,1,1,1,1,1,1
1,1,1,1,1,1,1,1,1,1,1,1,1,1,1,1,1,1,1,1,1
1,1,1,1,1,1,1,1,1,1,1,1,1,1,1,1,1,1,1,1,1
endlayer

layer
1,1,1,1,1,1,1,1,1,1,1,1,1,1,1,1,1,1,1,1,1
1,1,1,1,1,1,1,1,1,1,1,1,1,1,1,1,1,1,1,1,1
1,1,1,1,1,1,1,1,1,1,1,1,1,1,1,1,1,1,1,1,1
1,1,1,1,1,1,1,1,1,1,1,1,1,1,1,1,1,1,1,1,1
1,1,1,1,2,2,2,2,2,2,2,2,2,2,2,2,2,1,1,1,1
1,1,1,1,2,3,3,3,3,3,3,3,3,3,3,3,2,1,1,1,1
1,1,1,1,2,3,3,3,3,3,3,3,3,3,3,3,2,1,1,1,1
1,1,1,1,2,3,3,3,3,3,3,3,3,3,3,3,2,1,1,1,1
1,1,1,1,2,3,3,3,3,3,3,3,3,3,3,3,2,1,1,1,1
1,1,1,1,2,3,3,3,3,3,3,3,3,3,3,3,2,1,1,1,1
1,1,1,1,2,3,3,3,3,3,3,3,3,3,3,3,2,1,1,1,1
1,1,1,1,2,3,3,3,3,3,3,3,3,3,3,3,2,1,1,1,1
1,1,1,1,2,3,3,3,3,3,3,3,3,3,3,3,2,1,1,1,1
1,1,1,1,2,3,3,3,3,3,3,3,3,3,3,3,2,1,1,1,1
1,1,1,1,2,3,3,3,3,3,3,3,3,3,3,3,2,1,1,1,1
1,1,1,1,2,3,3,3,3,3,3,3,3,3,3,3,2,1,1,1,1
1,1,1,1,2,2,2,2,2,2,2,2,2,2,2,2,2,1,1,1,1
1,1,1,1,1,1,1,1,1,1,1,1,1,1,1,1,1,1,1,1,1
1,1,1,1,1,1,1,1,1,1,1,1,1,1,1,1,1,1,1,1,1
1,1,1,1,1,1,1,1,1,1,1,1,1,1,1,1,1,1,1,1,1
1,1,1,1,1,1,1,1,1,1,1,1,1,1,1,1,1,1,1,1,1
endlayer

layer
1,1,1,1,1,1,1,1,1,1,1,1,1,1,1,1,1,1,1,1,1
1,1,1,1,1,1,1,1,1,1,1,1,1,1,1,1,1,1,1,1,1
1,1,1,1,1,1,1,1,1,1,1,1,1,1,1,1,1,1,1,1,1
1,1,1,1,1,1,1,1,1,1,1,1,1,1,1,1,1,1,1,1,1
1,1,1,1,4,2,2,2,4,2,2,2,4,2,2,2,4,1,1,1,1
1,1,1,1,2,0,0,0,0,0,0,0,0,0,0,0,2,1,1,1,1
1,1,1,1,2,0,0,0,0,0,0,0,0,0,0,0,2,1,1,1,1
1,1,1,1,2,5,0,0,0,0,0,0,0,0,0,0,2,1,1,1,1
1,1,1,1,4,6,0,0,0,0,0,0,0,0,0,0,4,1,1,1,1
1,1,1,1,2,0,0,0,0,0,0,0,0,0,0,0,2,1,1,1,1
1,1,1,1,2,0,0,0,0,0,4,0,0,0,0,0,2,1,1,1,1
1,1,1,1,2,0,0,0,0,0,0,0,0,0,0,0,2,1,1,1,1
1,1,1,1,4,0,0,0,0,0,0,0,0,0,0,0,4,1,1,1,1
1,1,1,1,2,0,0,0,0,0,0,0,0,0,0,0,2,1,1,1,1
1,1,1,1,2,0,0,0,0,0,0,0,0,0,0,0,2,1,1,1,1
1,1,1,1,2,0,0,0,0,0,0,0,0,0,0,0,2,1,1,1,1
1,1,1,1,4,2,2,2,4,2,2,2,4,2,2,2,4,1,1,1,1
1,1,1,1,1,1,1,1,1,1,1,1,1,1,1,1,1,1,1,1,1
1,1,1,1,1,1,1,1,1,1,1,1,1,1,1,1,1,1,1,1,1
1,1,1,1,1,1,1,1,1,1,1,1,1,1,1,1,1,1,1,1,1
1,1,1,1,1,1,1,1,1,1,1,1,1,1,1,1,1,1,1,1,1
endlayer

layer
1,1,1,1,1,1,1,1,1,1,1,1,1,1,1,1,1,1,1,1,1
1,1,1,1,1,1,1,1,1,1,1,1,1,1,1,1,1,1,1,1,1
1,1,1,1,1,1,1,1,1,1,1,1,1,1,1,1,1,1,1,1,1
1,1,1,1,1,1,1,1,1,1,1,1,1,1,1,1,1,1,1,1,1
1,1,1,1,4,7,7,7,4,7,7,7,4,7,7,7,4,1,1,1,1
1,1,1,1,7,0,0,0,0,0,0,0,0,0,0,0,7,1,1,1,1
1,1,1,1,7,0,0,0,0,0,0,0,0,0,0,0,7,1,1,1,1
1,1,1,1,7,0,0,0,0,0,0,0,0,0,0,0,7,1,1,1,1
1,1,1,1,4,5,0,0,0,0,0,0,0,0,0,0,4,1,1,1,1
1,1,1,1,7,6,0,0,0,0,0,0,0,0,0,0,7,1,1,1,1
1,1,1,1,7,0,0,0,0,0,4,0,0,0,0,0,7,1,1,1,1
1,1,1,1,7,0,0,0,0,0,0,0,0,0,0,0,7,1,1,1,1
1,1,1,1,4,0,0,0,0,0,0,0,0,0,0,0,4,1,1,1,1
1,1,1,1,7,0,0,0,0,0,0,0,0,0,0,0,7,1,1,1,1
1,1,1,1,7,0,0,0,0,0,0,0,0,0,0,0,7,1,1,1,1
1,1,1,1,7,0,0,0,0,0,0,0,0,0,0,0,7,1,1,1,1
1,1,1,1,4,7,7,7,4,7,7,7,4,7,7,7,4,1,1,1,1
1,1,1,1,1,1,1,1,1,1,1,1,1,1,1,1,1,1,1,1,1
1,1,1,1,1,1,1,1,1,1,1,1,1,1,1,1,1,1,1,1,1
1,1,1,1,1,1,1,1,1,1,1,1,1,1,1,1,1,1,1,1,1
1,1,1,1,1,1,1,1,1,1,1,1,1,1,1,1,1,1,1,1,1
endlayer

layer
1,1,1,1,1,1,1,1,1,1,1,1,1,1,1,1,1,1,1,1,1
1,1,1,1,1,1,1,1,1,1,1,1,1,1,1,1,1,1,1,1,1
1,1,1,1,1,1,1,1,1,1,1,1,1,1,1,1,1,1,1,1,1
1,1,1,1,1,1,1,1,1,1,1,1,1,1,1,1,1,1,1,1,1
1,1,1,1,4,8,8,8,4,8,8,8,4,8,8,8,4,1,1,1,1
1,1,1,1,8,0,0,0,0,0,0,0,0,0,0,0,8,1,1,1,1
1,1,1,1,8,0,0,0,0,0,0,0,0,0,0,0,8,1,1,1,1
1,1,1,1,8,0,0,0,0,0,0,0,0,0,0,0,8,1,1,1,1
1,1,1,1,4,0,0,0,0,0,0,0,0,0,0,0,4,1,1,1,1
1,1,1,1,8,5,0,0,0,0,0,0,0,0,0,0,8,1,1,1,1
1,1,1,1,8,6,0,0,0,0,4,0,0,0,0,0,8,1,1,1,1
1,1,1,1,8,0,0,0,0,0,0,0,0,0,0,0,8,1,1,1,1
1,1,1,1,4,0,0,0,0,0,0,0,0,0,0,0,4,1,1,1,1
1,1,1,1,8,0,0,0,0,0,0,0,0,0,0,0,8,1,1,1,1
1,1,1,1,8,0,0,0,0,0,0,0,0,0,0,0,8,1,1,1,1
1,1,1,1,8,0,0,0,0,0,0,0,0,0,0,0,8,1,1,1,1
1,1,1,1,4,8,8,8,4,8,8,8,4,8,8,8,4,1,1,1,1
1,1,1,1,1,1,1,1,1,1,1,1,1,1,1,1,1,1,1,1,1
1,1,1,1,1,1,1,1,1,1,1,1,1,1,1,1,1,1,1,1,1
1,1,1,1,1,1,1,1,1,1,1,1,1,1,1,1,1,1,1,1,1
1,1,1,1,1,1,1,1,1,1,1,1,1,1,1,1,1,1,1,1,1
endlayer

layer
1,1,1,1,1,1,1,1,1,1,1,1,1,1,1,1,1,1,1,1,1
1,1,1,1,1,1,1,1,1,1,1,1,1,1,1,1,1,1,1,1,1
1,1,1,1,1,1,1,1,1,1,1,1,1,1,1,1,1,1,1,1,1
1,1,1,1,1,1,1,1,1,1,1,1,1,1,1,1,1,1,1,1,1
1,1,1,1,4,2,2,2,4,2,2,2,4,2,2,2,4,1,1,1,1
1,1,1,1,2,9,9,9,9,9,9,9,9,9,9,9,2,1,1,1,1
1,1,1,1,2,9,0,0,0,0,0,0,0,0,0,9,2,1,1,1,1
1,1,1,1,2,9,0,0,0,0,0,0,0,0,0,9,2,1,1,1,1
1,1,1,1,4,0,0,0,0,0,0,0,0,0,0,9,4,1,1,1,1
1,1,1,1,2,0,0,0,0,0,0,0,0,0,0,9,2,1,1,1,1
1,1,1,1,2,5,0,0,0,0,4,0,0,0,0,9,2,1,1,1,1
1,1,1,1,2,6,0,0,0,0,0,0,0,0,0,9,2,1,1,1,1
1,1,1,1,4,9,0,0,0,0,0,0,0,0,0,9,4,1,1,1,1
1,1,1,1,2,9,0,0,0,0,0,0,0,0,0,9,2,1,1,1,1
1,1,1,1,2,9,0,0,0,0,0,0,0,0,0,9,2,1,1,1,1
1,1,1,1,2,9,9,9,9,9,9,9,9,9,9,9,2,1,1,1,1
1,1,1,1,4,2,2,2,4,2,2,2,4,2,2,2,4,1,1,1,1
1,1,1,1,1,1,1,1,1,1,1,1,1,1,1,1,1,1,1,1,1
1,1,1,1,1,1,1,1,1,1,1,1,1,1,1,1,1,1,1,1,1
1,1,1,1,1,1,1,1,1,1,1,1,1,1,1,1,1,1,1,1,1
1,1,1,1,1,1,1,1,1,1,1,1,1,1,1,1,1,1,1,1,1
endlayer

layer
9,9,9,9,9,9,9,9,9,9,9,1,1,1,1,1,1,9,9,9,9
9,10,10,10,10,10,10,10,10,10,10,13,1,1,1,12,11,11,10,10,9
9,10,1,1,1,1,1,1,1,1,1,1,1,1,1,1,1,1,1,10,9
9,10,1,1,1,1,1,1,1,1,1,1,1,1,1,1,1,1,1,10,9
9,10,1,1,4,2,2,2,4,2,2,2,4,2,2,2,4,1,1,10,9
9,10,1,1,2,0,0,0,0,0,0,0,0,0,0,0,2,1,1,10,9
9,10,1,1,2,0,0,0,0,0,0,0,0,0,0,0,2,1,1,10,9
9,10,1,1,2,0,0,0,0,0,0,0,0,0,0,0,2,1,1,10,9
9,10,1,1,4,0,0,0,0,0,0,0,0,0,0,0,4,1,1,10,9
9,10,1,1,2,0,0,0,0,0,0,0,0,0,0,0,2,1,1,10,9
9,10,1,1,2,0,0,0,0,0,4,0,0,0,0,0,2,1,1,10,9
9,10,1,1,2,0,0,0,0,0,0,0,0,0,0,0,2,1,1,10,9
9,10,1,1,4,5,0,0,0,0,0,0,0,0,0,0,4,1,1,10,9
9,10,1,1,2,6,0,0,0,0,0,0,0,0,0,0,2,1,1,10,9
9,10,1,1,2,0,0,0,0,0,0,0,0,0,0,0,2,1,1,10,9
1,10,1,1,2,0,0,0,0,0,0,0,0,0,0,0,2,1,1,10,9
1,6,1,1,4,2,2,2,4,2,2,2,4,2,2,2,4,1,1,10,9
1,1,1,1,1,1,1,1,1,1,1,1,1,1,1,1,1,1,1,10,9
1,1,1,1,1,1,1,1,1,1,1,1,1,1,1,1,1,1,1,10,9
1,1,1,1,1,1,1,1,12,10,10,10,10,10,10,10,10,10,10,10,9
1,1,1,1,1,1,1,1,9,9,9,9,9,9,9,9,9,9,9,9,9
endlayer

layer
14,15,15,15,15,15,15,15,15,15,1,1,1,1,1,1,1,1,1,15,14
15,1,1,1,1,1,1,1,1,1,1,1,1,1,1,1,1,1,1,1,15
15,1,5,5,5,5,5,5,5,5,5,5,5,5,5,5,5,5,5,1,15
15,1,17,1,1,1,1,1,1,1,1,1,1,1,1,1,1,1,16,1,15
15,1,17,1,4,18,18,18,4,18,18,18,4,18,18,18,4,1,16,1,15
15,1,17,1,18,0,0,0,0,0,0,0,0,0,0,0,18,1,16,1,15
15,1,17,1,18,0,0,0,0,0,0,0,0,0,0,0,18,1,16,1,15
15,1,17,1,18,0,0,0,0,0,0,0,0,0,0,0,18,1,16,1,15
15,1,17,1,4,0,0,0,0,0,0,0,0,0,0,0,4,1,16,1,15
15,1,17,1,18,0,0,0,0,0,0,0,0,0,0,0,18,1,16,1,15
15,1,17,1,18,0,0,0,0,0,4,0,0,0,0,0,18,1,16,1,15
15,1,17,1,18,0,0,0,0,0,0,0,0,0,0,0,18,1,16,1,15
15,1,17,1,4,0,0,0,0,0,0,0,0,0,0,0,4,1,16,1,15
15,1,17,1,18,5,0,0,0,0,0,0,0,0,0,0,18,1,16,1,15
15,1,17,1,18,6,0,0,0,0,0,0,0,0,0,0,18,1,16,1,15
15,1,17,1,18,0,0,0,0,0,0,0,0,0,0,0,18,1,16,1,15
1,1,17,1,4,18,18,18,4,18,18,18,4,18,18,18,4,1,16,1,15
1,1,1,1,1,1,1,1,1,1,1,1,1,1,1,1,1,1,16,1,15
1,1,1,1,1,1,19,19,19,19,19,19,19,19,19,19,19,19,19,1,15
1,1,1,1,1,1,1,1,1,1,1,1,1,1,1,1,1,1,1,1,15
1,1,1,1,1,1,1,1,1,1,15,15,15,15,15,15,15,15,15,15,14
endlayer

layer
0,0,1,1,1,1,1,1,1,1,1,1,1,1,1,1,1,1,1,1,1
1,1,1,1,1,1,1,1,1,1,1,1,1,1,1,1,1,1,1,1,1
0,1,1,1,1,1,1,1,1,1,1,1,1,1,1,1,1,1,1,1,1
1,1,1,5,5,5,5,5,5,5,5,5,5,5,5,5,5,16,1,1,1
1,1,1,17,4,20,20,20,4,20,20,20,4,20,20,20,4,16,1,1,1
1,1,1,17,21,9,9,9,9,9,21,9,0,0,9,9,21,16,1,1,1
1,1,1,17,21,9,9,9,0,9,21,0,0,0,9,9,21,16,1,1,1
1,1,1,17,21,9,9,0,0,9,21,0,0,0,0,9,21,16,1,1,1
1,1,1,17,4,0,0,0,9,9,21,9,0,0,0,9,4,16,1,1,1
1,1,1,17,21,9,0,9,9,9,21,9,9,0,9,9,21,16,1,1,1
1,1,1,17,21,20,20,20,20,20,4,20,20,20,20,20,21,16,1,1,1
1,1,1,17,21,0,9,9,9,9,21,9,9,9,9,9,21,16,1,1,1
1,1,1,17,4,0,9,9,9,9,21,9,9,0,0,9,4,16,1,1,1
1,1,1,17,21,0,9,9,9,9,21,9,0,0,0,9,21,16,1,1,1
1,1,1,17,21,5,9,9,9,9,21,9,0,0,9,9,21,16,1,1,1
1,1,1,17,21,6,9,9,9,9,21,9,9,9,9,9,21,16,1,1,1
1,1,1,17,4,20,20,20,4,20,20,20,4,20,20,20,4,16,1,1,1
1,1,1,17,19,19,19,19,19,19,19,19,19,19,19,19,19,19,1,1,1
1,1,1,1,1,1,1,1,1,1,1,1,1,1,1,1,1,1,1,1,1
1,1,1,1,1,1,1,1,1,1,1,1,1,1,1,1,1,1,1,1,1
1,1,1,1,1,1,1,1,1,1,1,1,1,1,1,1,1,1,1,1,1
endlayer

layer
1,1,1,1,1,1,1,1,1,1,1,1,1,1,1,1,1,1,1,1,1
1,1,1,1,1,1,1,1,1,1,1,1,1,1,1,1,1,1,1,1,1
1,1,1,1,1,1,1,1,1,1,1,1,1,1,1,1,1,1,1,1,1
1,1,1,1,1,1,1,1,1,1,1,1,1,1,1,1,1,1,1,1,1
1,1,1,1,4,2,2,2,4,2,2,2,4,2,2,2,4,1,1,1,1
1,1,1,1,2,22,0,0,0,0,0,0,0,0,0,0,2,1,1,1,1
1,1,1,1,2,0,0,0,0,0,0,0,0,0,0,0,2,1,1,1,1
1,1,1,1,2,0,0,0,0,0,0,0,0,0,0,0,2,1,1,1,1
1,1,1,1,4,0,0,0,0,0,0,0,0,0,0,0,4,1,1,1,1
1,1,1,1,2,0,0,0,0,2,2,2,0,0,0,0,2,1,1,1,1
1,1,1,1,2,0,0,0,0,2,4,2,0,0,0,0,2,1,1,1,1
1,1,1,1,2,0,0,0,0,2,2,2,0,0,0,0,2,1,1,1,1
1,1,1,1,4,0,0,0,0,0,0,0,0,0,0,0,4,1,1,1,1
1,1,1,1,2,0,0,0,0,0,0,0,0,0,0,0,2,1,1,1,1
1,1,1,1,2,0,0,0,0,0,0,0,0,0,0,0,2,1,1,1,1
1,1,1,1,2,0,0,0,0,0,0,0,0,0,0,0,2,1,1,1,1
1,1,1,1,4,2,2,2,4,2,2,2,4,2,2,2,4,1,1,1,1
1,1,1,1,1,1,1,1,1,1,1,1,1,1,1,1,1,1,1,1,1
1,1,1,1,1,1,1,1,1,1,1,1,1,1,1,1,1,1,1,1,1
1,1,1,1,1,1,1,1,1,1,1,1,1,1,1,1,1,1,1,1,1
1,1,1,1,1,1,1,1,1,1,1,1,1,1,1,1,1,1,1,1,1
endlayer

layer
1,1,1,1,1,1,1,1,1,1,1,1,1,1,1,1,1,1,1,1,1
1,1,1,1,1,1,1,1,1,1,1,1,1,1,1,1,1,1,1,1,1
1,1,1,1,1,1,1,1,1,1,1,1,1,1,1,1,1,1,1,1,1
1,1,1,1,1,1,1,1,1,1,1,1,1,1,1,1,1,1,1,1,1
1,1,1,1,4,7,7,7,4,7,7,7,4,7,7,7,4,1,1,1,1
1,1,1,1,7,0,0,0,0,0,0,0,0,0,0,0,7,1,1,1,1
1,1,1,1,1,0,0,0,0,0,0,0,0,0,0,0,7,1,1,1,1
1,1,1,1,7,0,0,0,0,0,0,0,0,0,0,0,7,1,1,1,1
1,1,1,1,4,0,0,0,0,0,0,0,0,0,0,0,4,1,1,1,1
1,1,1,1,7,0,0,0,0,0,0,0,0,0,0,0,7,1,1,1,1
1,1,1,1,7,0,0,0,0,0,4,0,0,0,0,0,7,1,1,1,1
1,1,1,1,7,0,0,0,0,0,0,0,0,0,0,0,7,1,1,1,1
1,1,1,1,4,0,0,0,0,0,0,0,0,0,0,0,4,1,1,1,1
1,1,1,1,7,0,0,0,0,0,0,0,0,0,0,0,7,1,1,1,1
1,1,1,1,7,0,0,0,0,0,0,0,0,0,0,0,7,1,1,1,1
1,1,1,1,7,0,0,0,0,0,0,0,0,0,0,0,7,1,1,1,1
1,1,1,1,4,7,7,7,4,7,7,1,1,1,7,7,4,1,1,1,1
1,1,1,1,1,1,1,1,1,1,1,1,1,1,1,1,1,1,1,1,1
1,1,1,1,1,1,1,1,1,1,1,1,1,1,1,1,1,1,1,1,1
1,1,1,1,1,1,1,1,1,1,1,1,1,1,1,1,1,1,1,1,1
1,1,1,1,1,1,1,1,1,1,1,1,1,1,1,1,1,1,1,1,1
endlayer

layer
1,1,1,1,1,1,1,1,1,1,1,1,1,1,1,1,1,1,1,1,1
1,1,1,1,1,1,1,1,1,1,1,1,1,1,1,1,1,1,1,1,1
1,1,1,1,1,1,1,1,1,1,1,1,1,1,1,1,1,1,1,1,1
1,1,1,1,1,1,1,1,1,1,1,1,1,1,1,1,1,1,1,1,1
1,1,1,1,4,8,8,8,4,8,8,8,4,8,8,0,4,1,1,1,1
1,1,1,1,1,0,0,0,0,0,0,0,0,0,0,0,8,1,1,1,1
1,1,1,1,1,0,0,0,0,0,0,0,0,0,0,0,8,1,1,1,1
1,1,1,1,1,0,0,0,0,0,0,0,0,0,0,0,8,1,1,1,1
1,1,1,1,4,0,0,0,0,0,0,0,0,0,0,0,4,1,1,1,1
1,1,1,1,8,0,0,0,0,0,0,0,0,0,0,0,8,1,1,1,1
1,1,1,1,8,0,0,0,0,0,4,0,0,0,0,0,8,1,1,1,1
1,1,1,1,8,0,0,0,0,0,0,0,0,0,0,0,1,1,1,1,1
1,1,1,1,4,0,0,0,0,0,0,0,0,0,0,0,1,1,1,1,1
1,1,1,1,8,0,0,0,0,0,0,0,0,0,0,0,1,1,1,1,1
1,1,1,1,8,0,0,0,0,0,0,0,0,0,0,0,1,1,1,1,1
1,1,1,1,8,0,0,0,0,0,0,0,0,0,0,0,8,1,1,1,1
1,1,1,1,4,8,8,8,4,1,1,1,1,1,8,8,4,1,1,1,1
1,1,1,1,1,1,1,1,1,1,1,1,1,1,1,1,1,1,1,1,1
1,1,1,1,1,1,1,1,1,1,1,1,1,1,1,1,1,1,1,1,1
1,1,1,1,1,1,1,1,1,1,1,1,1,1,1,1,1,1,1,1,1
1,1,1,1,1,1,1,1,1,1,1,1,1,1,1,1,1,1,1,1,1
endlayer

layer
1,1,1,1,1,1,1,1,1,1,1,1,1,1,1,1,1,1,1,1,1
1,1,1,1,1,1,1,1,1,1,1,1,1,1,1,1,1,1,1,1,1
1,1,1,1,1,1,1,1,1,1,1,1,1,1,1,1,1,1,1,1,1
1,1,1,1,1,1,1,1,1,1,1,1,1,1,1,1,1,1,1,1,1
1,1,1,1,1,1,1,1,4,1,1,1,1,2,2,2,4,1,1,1,1
1,1,1,1,1,0,0,0,0,0,0,0,9,9,9,9,2,1,1,1,1
1,1,1,1,1,0,0,0,0,0,0,0,0,9,9,9,2,1,1,1,1
1,1,1,1,1,0,0,0,0,0,0,0,0,0,9,9,2,1,1,1,1
1,1,1,1,1,0,0,0,0,0,0,0,0,0,0,9,4,1,1,1,1
1,1,1,1,1,0,0,0,0,0,0,0,0,0,0,0,2,1,1,1,1
1,1,1,1,2,0,0,0,0,0,0,0,0,0,0,0,2,1,1,1,1
1,1,1,1,2,0,0,0,0,0,0,0,0,0,0,0,1,1,1,1,1
1,1,1,1,4,0,0,0,0,0,0,0,0,0,0,0,1,1,1,1,1
1,1,1,1,2,0,0,0,0,0,0,0,0,0,0,0,1,1,1,1,1
1,1,1,1,2,0,0,0,0,0,0,0,0,0,0,0,2,1,1,1,1
1,1,1,1,2,0,0,0,0,0,0,0,0,0,0,9,2,1,1,1,1
1,1,1,1,4,2,2,2,1,1,1,1,1,1,2,2,4,1,1,1,1
1,1,1,1,1,1,1,1,1,1,1,1,1,1,1,1,1,1,1,1,1
1,1,1,1,1,1,1,1,1,1,1,1,1,1,1,1,1,1,1,1,1
1,1,1,1,1,1,1,1,1,1,1,1,1,1,1,1,1,1,1,1,1
1,1,1,1,1,1,1,1,1,1,1,1,1,1,1,1,1,1,1,1,1
endlayer

layer
1,1,1,1,1,1,1,1,1,1,1,1,1,1,1,1,1,1,1,1,1
1,1,1,1,1,1,1,1,1,1,1,1,1,1,1,1,1,1,1,1,1
1,1,1,1,1,1,1,1,1,1,1,1,1,1,1,1,1,1,1,1,1
1,1,1,1,1,1,1,1,1,1,1,1,1,1,1,1,1,1,1,1,1
1,1,1,1,1,1,1,1,1,1,1,1,1,1,2,2,1,1,1,1,1
1,1,1,1,1,0,0,0,0,0,0,0,0,0,0,0,2,1,1,1,1
1,1,1,1,1,0,0,0,0,0,0,0,0,0,0,0,2,1,1,1,1
1,1,1,1,1,0,0,0,0,0,0,0,0,0,0,0,2,1,1,1,1
1,1,1,1,1,0,0,0,0,0,0,0,0,0,0,0,1,1,1,1,1
1,1,1,1,1,0,0,0,0,0,0,0,0,0,0,0,1,1,1,1,1
1,1,1,1,1,0,0,0,0,0,0,0,0,0,0,0,1,1,1,1,1
1,1,1,1,1,0,0,0,0,0,0,0,0,0,0,0,1,1,1,1,1
1,1,1,1,1,0,0,0,0,0,0,0,0,0,0,0,1,1,1,1,1
1,1,1,1,1,0,0,0,0,0,0,0,0,0,0,0,1,1,1,1,1
1,1,1,1,1,0,0,0,0,0,0,0,0,0,0,0,1,1,1,1,1
1,1,1,1,2,15,15,0,0,0,0,0,0,0,0,0,1,1,1,1,1
1,1,1,1,1,2,2,1,1,1,1,1,1,1,2,2,1,1,1,1,1
1,1,1,1,1,1,1,1,1,1,1,1,1,1,1,1,1,1,1,1,1
1,1,1,1,1,1,1,1,1,1,1,1,1,1,1,1,1,1,1,1,1
1,1,1,1,1,1,1,1,1,1,1,1,1,1,1,1,1,1,1,1,1
1,1,1,1,1,1,1,1,1,1,1,1,1,1,1,1,1,1,1,1,1
endlayer

