
# Created by Ruins mod version 16.7 Ingame Parser
# authoring Player: ST753M

# A 3-tier pagoda of cherry wood

weight=5
uniqueMinDistance=1000
embed_into_distance=4
acceptable_target_blocks=grass,dirt,podzol
unacceptable_target_blocks=flowing_water,water,flowing_lava,lava
dimensions=29,21,21
allowable_overhang=4
max_leveling=0
leveling_buffer=0
preserve_water=0
preserve_lava=0
preventRotation=1

biomesToSpawnIn=cherry_blossom_grove,cherry blossom grove

=0,100,air
rule1=0,100,preserveBlock
rule2=0,100,minecraft:stone-3
rule3=0,100,minecraft:log-1
rule4=0,100,biomesoplenty:planks_0-1
rule5=0,100,biomesoplenty:cherry_stairs-0
rule6=0,100,biomesoplenty:cherry_stairs-5
rule7=0,100,minecraft:wooden_slab-5
rule8=0,100,minecraft:wooden_slab-13
rule9=0,100,biomesoplenty:cherry_fence-0
rule10=0,100,biomesoplenty:wood_slab_0-9
rule11=0,100,minecraft:torch-5
rule12=0,70,ChestGenHook:chests/stronghold_library:5-2,ChestGenHook:chests/woodland_mansion:5-2,ChestGenHook:chests/village_blacksmith:5-2
rule13=0,100,biomesoplenty:double_wood_slab_0-1
rule14=0,100,biomesoplenty:wood_slab_0-1
rule15=0,100,biomesoplenty:cherry_stairs-2
rule16=0,100,biomesoplenty:cherry_stairs-3
rule17=0,100,biomesoplenty:cherry_stairs-1
rule18=0,100,minecraft:log-9
rule19=0,100,minecraft:log-5
rule20=0,100,minecraft:trapdoor-14
rule21=0,100,minecraft:trapdoor-12
rule22=0,100,biomesoplenty:grass-2
rule23=0,100,minecraft:trapdoor-13
rule24=0,100,minecraft:trapdoor-15
rule25=0,100,biomesoplenty:leaves_2-5
rule26=0,100,minecraft:bed-10
rule27=0,100,minecraft:bed-2
rule28=0,100,minecraft:trapdoor-1
rule29=0,100,IInventory;minecraft:dispenser;minecraft:spawn_egg#{EntityTag:{id:"minecraft:villager"}}#0#4-0,minecraft:log-9
rule30=0,100,air
rule31=1,100,minecraft:redstone_torch-5
rule32=0,100,minecraft:redstone_wire-15
rule33=0,100,minecraft:unlit_redstone_torch-3
rule34=0,100,minecraft:unlit_redstone_torch-1
rule35=0,100,minecraft:redstone_wire-0
rule36=0,100,biomesoplenty:cherry_stairs-4
rule37=0,100,minecraft:water-0
rule38=0,100,minecraft:sand-0

layer
1,1,1,1,1,1,1,1,1,1,1,1,1,1,1,1,1,1,1,1,1
1,1,1,1,1,1,1,1,1,1,1,1,1,1,1,1,1,1,1,1,1
1,1,1,1,1,1,1,1,1,1,1,1,1,1,1,1,1,1,1,1,1
1,1,1,1,1,1,1,1,1,1,1,1,1,1,1,1,1,1,1,1,1
1,1,1,1,2,2,2,2,2,2,2,2,2,2,2,2,2,1,1,1,1
1,1,1,1,2,2,2,2,2,2,2,2,2,2,2,2,2,1,1,1,1
1,1,1,1,2,2,2,2,2,2,2,2,2,2,2,2,2,1,1,1,1
1,1,1,1,2,2,2,2,2,2,2,2,2,2,2,2,2,1,1,1,1
1,1,1,1,2,2,2,2,2,2,2,2,2,2,2,2,2,1,1,1,1
1,1,1,1,2,2,2,2,2,2,2,2,2,2,2,2,2,1,1,1,1
1,1,1,1,2,2,2,2,2,2,2,2,2,2,2,2,2,1,1,1,1
1,1,1,1,2,2,2,2,2,2,2,2,2,2,2,2,2,1,1,1,1
1,1,1,1,2,2,2,2,2,2,2,2,2,2,2,2,2,1,1,1,1
1,1,1,1,2,2,2,2,2,2,2,2,2,2,2,2,2,1,1,1,1
1,1,1,1,2,2,2,2,2,2,2,2,2,2,2,2,2,1,1,1,1
1,1,1,1,2,2,2,2,2,2,2,2,2,2,2,2,2,1,1,1,1
1,1,1,1,2,2,2,2,2,2,2,2,2,2,2,2,2,1,1,1,1
1,1,1,1,1,1,1,1,1,1,1,1,1,1,1,1,1,1,1,1,1
1,1,1,1,1,1,1,1,1,1,1,1,1,1,1,1,1,1,1,1,1
1,1,1,1,1,1,1,1,1,1,1,1,1,1,1,1,1,1,1,1,1
1,1,1,1,1,1,1,1,1,1,1,1,1,1,1,1,1,1,1,1,1
endlayer

layer
1,1,1,1,1,1,1,1,1,1,1,1,1,1,1,1,1,1,1,1,1
1,1,1,1,1,1,1,1,1,1,1,1,1,1,1,1,1,1,1,1,1
1,1,1,1,1,1,1,1,1,1,1,1,1,1,1,1,1,1,1,1,1
1,1,1,1,1,1,1,1,1,1,1,1,1,1,1,1,1,1,1,1,1
1,1,1,1,2,2,2,2,2,2,2,2,2,2,2,2,2,1,1,1,1
1,1,1,1,2,2,2,2,2,2,2,2,2,2,2,2,2,1,1,1,1
1,1,1,1,2,2,2,2,2,2,2,2,2,2,2,2,2,1,1,1,1
1,1,1,1,2,2,2,2,2,2,2,2,2,2,2,2,2,1,1,1,1
1,1,1,1,2,2,2,2,2,2,2,2,2,2,2,2,2,1,1,1,1
1,1,1,1,2,2,2,2,2,2,2,2,2,2,2,2,2,1,1,1,1
1,1,1,1,2,2,2,2,2,2,2,2,2,2,2,2,2,1,1,1,1
1,1,1,1,2,2,2,2,2,2,2,2,2,2,2,2,2,1,1,1,1
1,1,1,1,2,2,2,2,2,2,2,2,2,2,2,2,2,1,1,1,1
1,1,1,1,2,2,2,2,2,2,2,2,2,2,2,2,2,1,1,1,1
1,1,1,1,2,2,2,2,2,2,2,2,2,2,2,2,2,1,1,1,1
1,1,1,1,2,2,2,2,2,2,2,2,2,2,2,2,2,1,1,1,1
1,1,1,1,2,2,2,2,2,2,2,2,2,2,2,2,2,1,1,1,1
1,1,1,1,1,1,1,1,1,1,1,1,1,1,1,1,1,1,1,1,1
1,1,1,1,1,1,1,1,1,1,1,1,1,1,1,1,1,1,1,1,1
1,1,1,1,1,1,1,1,1,1,1,1,1,1,1,1,1,1,1,1,1
1,1,1,1,1,1,1,1,1,1,1,1,1,1,1,1,1,1,1,1,1
endlayer

layer
1,1,1,1,1,1,1,1,1,1,1,1,1,1,1,1,1,1,1,1,1
1,1,1,1,1,1,1,1,1,1,1,1,1,1,1,1,1,1,1,1,1
1,1,1,1,1,1,1,1,1,1,1,1,1,1,1,1,1,1,1,1,1
1,1,1,1,1,1,1,1,1,1,1,1,1,1,1,1,1,1,1,1,1
1,1,1,1,2,2,2,2,2,2,2,2,2,2,2,2,2,1,1,1,1
1,1,1,1,2,2,2,2,2,2,2,2,2,2,2,2,2,1,1,1,1
1,1,1,1,2,2,2,2,2,2,2,2,2,2,2,2,2,1,1,1,1
1,1,1,1,2,2,2,2,2,2,2,2,2,2,2,2,2,1,1,1,1
1,1,1,1,2,2,2,2,2,2,2,2,2,2,2,2,2,1,1,1,1
1,1,1,1,2,2,2,2,2,2,2,2,2,2,2,2,2,1,1,1,1
1,1,1,1,2,2,2,2,2,2,2,2,2,2,2,2,2,1,1,1,1
1,1,1,1,2,2,2,2,2,2,2,2,2,2,2,2,2,1,1,1,1
1,1,1,1,2,2,2,2,2,2,2,2,2,2,2,2,2,1,1,1,1
1,1,1,1,2,2,2,2,2,2,2,2,2,2,2,2,2,1,1,1,1
1,1,1,1,2,2,2,2,2,2,2,2,2,2,2,2,2,1,1,1,1
1,1,1,1,2,2,2,2,2,2,2,2,2,2,2,2,2,1,1,1,1
1,1,1,1,2,2,2,2,2,2,2,2,2,2,2,2,2,1,1,1,1
1,1,1,1,1,1,1,1,1,1,1,1,1,1,1,1,1,1,1,1,1
1,1,1,1,1,1,1,1,1,1,1,1,1,1,1,1,1,1,1,1,1
1,1,1,1,1,1,1,1,1,1,1,1,1,1,1,1,1,1,1,1,1
1,1,1,1,1,1,1,1,1,1,1,1,1,1,1,1,1,1,1,1,1
endlayer

layer
1,1,1,1,1,1,1,1,1,1,1,1,1,1,1,1,1,1,1,1,1
1,1,1,1,1,1,1,1,1,1,1,1,1,1,1,1,1,1,1,1,1
1,1,1,1,1,1,1,1,1,1,1,1,1,1,1,1,1,1,1,1,1
1,1,1,1,1,1,1,1,1,1,1,1,1,1,1,1,1,1,1,1,1
1,1,1,1,3,2,2,2,3,2,2,2,3,2,2,2,3,1,1,1,1
1,1,1,1,2,4,4,4,4,4,4,4,4,4,4,4,2,1,1,1,1
1,1,1,1,2,4,4,4,4,4,4,4,4,4,4,4,2,1,1,1,1
1,1,1,1,2,4,4,4,4,4,4,4,4,4,4,4,2,1,1,1,1
1,1,1,1,3,4,4,4,4,4,4,4,4,4,4,4,3,1,1,1,1
1,1,1,1,2,4,4,4,4,4,4,4,4,4,4,4,4,1,1,1,1
1,1,1,1,2,4,4,4,4,4,4,4,4,4,4,4,4,1,1,1,1
1,1,1,1,2,4,4,4,4,4,4,4,4,4,4,4,4,1,1,1,1
1,1,1,1,3,4,4,4,4,4,4,4,4,4,4,4,3,1,1,1,1
1,1,1,1,2,4,4,4,4,4,4,4,4,4,4,4,2,1,1,1,1
1,1,1,1,2,4,4,4,4,4,4,4,4,4,4,4,2,1,1,1,1
1,1,1,1,2,4,4,4,4,4,4,4,4,4,4,4,2,1,1,1,1
1,1,1,1,3,2,2,2,3,2,2,2,3,2,2,2,3,1,1,1,1
1,1,1,1,1,1,1,1,1,1,1,1,1,1,1,1,1,1,1,1,1
1,1,1,1,1,1,1,1,1,1,1,1,1,1,1,1,1,1,1,1,1
1,1,1,1,1,1,1,1,1,1,1,1,1,1,1,1,1,1,1,1,1
1,1,1,1,1,1,1,1,1,1,1,1,1,1,1,1,1,1,1,1,1
endlayer

layer
1,1,1,1,1,1,1,1,1,1,1,1,1,1,1,1,1,1,1,1,1
1,1,1,1,1,1,1,1,1,1,1,1,1,1,1,1,1,1,1,1,1
1,1,1,1,1,1,1,1,1,1,1,1,1,1,1,1,1,1,1,1,1
1,1,1,1,1,1,1,1,1,1,1,1,1,1,1,1,1,1,1,1,1
1,1,1,1,3,2,2,2,3,2,2,2,3,2,2,2,3,1,1,1,1
1,1,1,1,2,0,0,0,0,0,0,0,0,0,0,0,2,1,1,1,1
1,1,1,1,2,0,0,0,0,0,0,0,0,0,0,0,2,1,1,1,1
1,1,1,1,2,0,0,0,0,0,0,0,0,0,0,0,2,1,1,1,1
1,1,1,1,3,5,5,0,0,0,0,0,0,0,0,0,3,1,1,1,1
1,1,1,1,2,6,6,0,0,2,2,2,0,0,0,0,0,0,0,0,0
1,1,1,1,2,0,0,0,0,2,3,2,0,0,0,0,0,0,0,0,0
1,1,1,1,2,0,0,0,0,2,2,2,0,0,0,0,0,0,0,0,0
1,1,1,1,3,0,0,0,0,0,0,0,0,0,0,0,3,1,1,1,1
1,1,1,1,2,0,0,0,0,0,0,0,0,0,0,0,2,1,1,1,1
1,1,1,1,2,0,0,0,0,0,0,0,0,0,0,0,2,1,1,1,1
1,1,1,1,2,0,0,0,0,0,0,0,0,0,0,0,2,1,1,1,1
1,1,1,1,3,2,2,2,3,2,2,2,3,2,2,2,3,1,1,1,1
1,1,1,1,1,1,1,1,1,1,1,1,1,1,1,1,1,1,1,1,1
1,1,1,1,1,1,1,1,1,1,1,1,1,1,1,1,1,1,1,1,1
1,1,1,1,1,1,1,1,1,1,1,1,1,1,1,1,1,1,1,1,1
1,1,1,1,1,1,1,1,1,1,1,1,1,1,1,1,1,1,1,1,1
endlayer

layer
1,1,1,1,1,1,1,1,1,1,1,1,1,1,1,1,1,1,1,1,1
1,1,1,1,1,1,1,1,1,1,1,1,1,1,1,1,1,1,1,1,1
1,1,1,1,1,1,1,1,1,1,1,1,1,1,1,1,1,1,1,1,1
1,1,1,1,1,1,1,1,1,1,1,1,1,1,1,1,1,1,1,1,1
1,1,1,1,3,7,7,7,3,7,7,7,3,7,7,7,3,1,1,1,1
1,1,1,1,7,0,0,0,0,0,0,0,0,0,0,0,7,1,1,1,1
1,1,1,1,7,0,0,0,0,0,0,0,0,0,0,0,7,1,1,1,1
1,1,1,1,7,0,0,0,0,0,0,0,0,0,0,0,7,1,1,1,1
1,1,1,1,3,0,0,0,0,0,0,0,0,0,0,0,3,1,1,1,1
1,1,1,1,7,5,5,0,0,0,0,0,0,0,0,0,0,0,0,0,0
1,1,1,1,7,6,6,0,0,0,3,0,0,0,0,0,0,0,0,0,0
1,1,1,1,7,0,0,0,0,0,0,0,0,0,0,0,0,0,0,0,0
1,1,1,1,3,0,0,0,0,0,0,0,0,0,0,0,3,1,1,1,1
1,1,1,1,7,0,0,0,0,0,0,0,0,0,0,0,7,1,1,1,1
1,1,1,1,7,0,0,0,0,0,0,0,0,0,0,0,7,1,1,1,1
1,1,1,1,7,0,0,0,0,0,0,0,0,0,0,0,7,1,1,1,1
1,1,1,1,3,7,7,7,3,7,7,7,3,7,7,7,3,1,1,1,1
1,1,1,1,1,1,1,1,1,1,1,1,1,1,1,1,1,1,1,1,1
1,1,1,1,1,1,1,1,1,1,1,1,1,1,1,1,1,1,1,1,1
1,1,1,1,1,1,1,1,1,1,1,1,1,1,1,1,1,1,1,1,1
1,1,1,1,1,1,1,1,1,1,1,1,1,1,1,1,1,1,1,1,1
endlayer

layer
1,1,1,1,1,1,1,1,1,1,1,1,1,1,1,1,1,1,1,1,1
1,1,1,1,1,1,1,1,1,1,1,1,1,1,1,1,1,1,1,1,1
1,1,1,1,1,1,1,1,1,1,1,1,1,1,1,1,1,1,1,1,1
1,1,1,1,1,1,1,1,1,1,1,1,1,1,1,1,1,1,1,1,1
1,1,1,1,3,8,8,8,3,8,8,8,3,8,8,8,3,1,1,1,1
1,1,1,1,8,0,0,0,0,0,0,0,0,0,0,0,8,1,1,1,1
1,1,1,1,8,0,0,0,0,0,0,0,0,0,0,0,8,1,1,1,1
1,1,1,1,8,0,0,0,0,0,0,0,0,0,0,0,8,1,1,1,1
1,1,1,1,3,0,0,0,0,0,0,0,0,0,0,0,3,1,1,1,1
1,1,1,1,8,0,0,0,0,0,9,0,0,0,0,0,8,0,0,0,0
1,1,1,1,8,5,5,0,0,9,3,9,0,0,0,0,8,0,0,0,0
1,1,1,1,8,6,6,0,0,0,9,0,0,0,0,0,8,0,0,0,0
1,1,1,1,3,0,0,0,0,0,0,0,0,0,0,0,3,1,1,1,1
1,1,1,1,8,0,0,0,0,0,0,0,0,0,0,0,8,1,1,1,1
1,1,1,1,8,0,0,0,0,0,0,0,0,0,0,0,8,1,1,1,1
1,1,1,1,8,0,0,0,0,0,0,0,0,0,0,0,8,1,1,1,1
1,1,1,1,3,8,8,8,3,8,8,8,3,8,8,8,3,1,1,1,1
1,1,1,1,1,1,1,1,1,1,1,1,1,1,1,1,1,1,1,1,1
1,1,1,1,1,1,1,1,1,1,1,1,1,1,1,1,1,1,1,1,1
1,1,1,1,1,1,1,1,1,1,1,1,1,1,1,1,1,1,1,1,1
1,1,1,1,1,1,1,1,1,1,1,1,1,1,1,1,1,1,1,1,1
endlayer

layer
1,1,1,1,1,1,1,1,1,1,1,1,1,1,1,1,1,1,1,1,1
1,1,1,1,1,1,1,1,1,1,1,1,1,1,1,1,1,1,1,1,1
1,1,1,1,1,1,1,1,1,1,1,1,1,1,1,1,1,1,1,1,1
1,1,1,1,1,1,1,1,1,1,1,1,1,1,1,1,1,1,1,1,1
1,1,1,1,3,2,2,2,3,2,2,2,3,2,2,2,3,1,1,1,1
1,1,1,1,2,10,10,10,10,10,10,10,10,10,10,10,2,1,1,1,1
1,1,1,1,2,10,10,10,10,10,10,10,10,10,10,10,2,1,1,1,1
1,1,1,1,2,10,10,0,0,0,0,0,0,0,10,10,2,1,1,1,1
1,1,1,1,3,0,0,0,0,0,0,0,0,0,10,10,3,1,1,1,1
1,1,1,1,2,0,0,0,0,0,11,0,0,0,10,10,2,1,1,1,1
1,1,1,1,2,0,0,0,0,11,3,11,0,0,10,10,2,1,1,1,1
1,1,1,1,2,5,5,0,0,0,11,0,0,0,10,10,2,1,1,1,1
1,1,1,1,3,6,6,0,0,0,0,0,0,0,10,10,3,1,1,1,1
1,1,1,1,2,10,10,0,0,0,0,0,0,0,10,10,2,1,1,1,1
1,1,1,1,2,10,10,10,10,10,10,10,10,10,10,10,2,1,1,1,1
1,1,1,1,2,10,10,10,10,10,10,10,10,10,10,10,2,1,1,1,1
1,1,1,1,3,2,2,2,3,2,2,2,3,2,2,2,3,1,1,1,1
1,1,1,1,1,1,1,1,1,1,1,1,1,1,1,1,1,1,1,1,1
1,1,1,1,1,1,1,1,1,1,1,1,1,1,1,1,1,1,1,1,1
1,1,1,1,1,1,1,1,1,1,1,1,1,1,1,1,1,1,1,1,1
1,1,1,1,1,1,1,1,1,1,1,1,1,1,1,1,1,1,1,1,1
endlayer

layer
10,10,10,10,10,10,10,10,10,10,10,10,10,10,10,10,10,10,10,10,10
10,4,4,4,4,4,4,4,4,4,4,4,4,4,4,4,4,4,4,4,10
10,4,1,1,1,1,1,1,1,1,1,1,1,1,1,1,1,1,1,4,10
10,4,1,1,1,1,1,1,1,1,1,1,1,1,1,1,1,1,1,4,10
10,4,1,1,3,2,2,2,3,2,2,2,3,2,2,2,3,1,1,4,10
10,4,1,1,2,12,0,0,0,0,0,0,0,0,0,0,2,1,1,4,10
10,4,1,1,2,0,0,0,0,0,0,0,0,0,0,0,2,1,1,4,10
10,4,1,1,2,9,9,0,0,0,0,0,0,0,0,0,2,1,1,4,10
10,4,1,1,3,0,0,0,0,0,0,0,0,0,0,0,3,1,1,4,10
10,4,1,1,2,0,0,0,0,0,0,0,0,0,0,0,2,1,1,4,10
10,4,1,1,2,0,0,0,0,0,3,0,0,0,0,0,2,1,1,4,10
10,4,1,1,2,0,0,0,0,0,0,0,0,0,0,0,2,1,1,4,10
10,4,1,1,3,5,0,0,0,0,0,0,0,0,0,0,3,1,1,4,10
10,4,1,1,2,6,0,0,0,0,0,0,0,0,0,0,2,1,1,4,10
10,4,1,1,2,0,0,0,0,0,0,0,0,0,0,0,2,1,1,4,10
10,4,1,1,2,0,0,0,0,0,0,0,0,0,0,0,2,1,1,4,10
10,4,1,1,3,2,2,2,3,2,2,2,3,2,2,2,3,1,1,4,10
10,4,1,1,1,1,1,1,1,1,1,1,1,1,1,1,1,1,1,4,10
10,4,1,1,1,1,1,1,1,1,1,1,1,1,1,1,1,1,1,4,10
10,4,4,4,4,4,4,4,4,4,4,4,4,4,4,4,4,4,4,4,10
10,10,10,10,10,10,10,10,10,10,10,10,10,10,10,10,10,10,10,10,10
endlayer

layer
13,14,14,14,14,14,14,14,14,14,14,14,14,14,14,14,14,14,14,14,13
14,1,1,1,1,1,1,1,1,1,1,1,1,1,1,1,1,1,1,1,14
14,1,5,5,5,5,5,5,5,5,5,5,5,5,5,5,5,5,5,1,14
14,1,16,1,1,1,1,1,1,1,1,1,1,1,1,1,1,1,15,1,14
14,1,16,1,3,9,9,9,3,9,9,9,3,9,9,9,3,1,15,1,14
14,1,16,1,9,0,0,0,0,0,0,0,0,0,0,0,9,1,15,1,14
14,1,16,1,9,0,0,0,0,0,0,0,0,0,0,0,9,1,15,1,14
14,1,16,1,9,0,0,0,0,0,0,0,0,0,0,0,9,1,15,1,14
14,1,16,1,3,0,0,0,0,0,0,0,0,0,0,0,3,1,15,1,14
14,1,16,1,9,0,0,0,0,0,0,0,0,0,0,0,9,1,15,1,14
14,1,16,1,9,0,0,0,0,0,3,0,0,0,0,0,9,1,15,1,14
14,1,16,1,9,0,0,0,0,0,0,0,0,0,0,0,9,1,15,1,14
14,1,16,1,3,0,0,0,0,0,0,0,0,0,0,0,3,1,15,1,14
14,1,16,1,9,5,0,0,0,0,0,0,0,0,0,0,9,1,15,1,14
14,1,16,1,9,6,0,0,0,0,0,0,0,0,0,0,9,1,15,1,14
14,1,16,1,9,0,0,0,0,0,0,0,0,0,0,0,9,1,15,1,14
14,1,16,1,3,9,9,9,3,9,9,9,3,9,9,9,3,1,15,1,14
14,1,16,1,1,1,1,1,1,1,1,1,1,1,1,1,1,1,15,1,14
14,1,17,17,17,17,17,17,17,17,17,17,17,17,17,17,17,17,17,1,14
14,1,1,1,1,1,1,1,1,1,1,1,1,1,1,1,1,1,1,1,14
13,14,14,14,14,14,14,14,14,14,14,14,14,14,14,14,14,14,14,14,13
endlayer

layer
1,1,1,1,1,1,1,1,1,1,1,1,1,1,1,1,1,1,1,1,1
1,1,1,1,1,1,1,1,1,1,1,1,1,1,1,1,1,1,1,1,1
1,1,1,1,1,1,1,1,1,1,1,1,1,1,1,1,1,1,1,1,1
1,1,1,5,5,5,5,5,5,5,5,5,5,5,5,5,5,15,1,1,1
1,1,1,16,3,18,18,18,3,18,18,18,3,18,18,18,3,15,1,1,1
1,1,1,16,19,10,10,10,10,10,19,10,10,10,10,10,19,15,1,1,1
1,1,1,16,19,10,10,10,10,10,19,10,10,10,10,10,19,15,1,1,1
1,1,1,16,19,10,10,10,10,10,19,10,10,10,10,10,19,15,1,1,1
1,1,1,16,3,10,10,10,10,10,19,10,10,10,10,10,3,15,1,1,1
1,1,1,16,19,10,10,10,10,10,19,10,10,10,10,10,19,15,1,1,1
1,1,1,16,19,18,18,18,18,18,3,18,18,18,18,18,19,15,1,1,1
1,1,1,16,19,0,10,10,10,10,19,10,10,10,10,10,19,15,1,1,1
1,1,1,16,3,0,10,10,10,10,19,10,10,10,10,10,3,15,1,1,1
1,1,1,16,19,0,10,10,10,10,19,10,10,10,10,10,19,15,1,1,1
1,1,1,16,19,5,10,10,10,10,19,10,10,10,10,10,19,15,1,1,1
1,1,1,16,19,6,10,10,10,10,19,10,10,10,10,10,19,15,1,1,1
1,1,1,16,3,18,18,18,3,18,18,18,3,18,18,18,3,15,1,1,1
1,1,1,16,17,17,17,17,17,17,17,17,17,17,17,17,17,17,1,1,1
1,1,1,1,1,1,1,1,1,1,1,1,1,1,1,1,1,1,1,1,1
1,1,1,1,1,1,1,1,1,1,1,1,1,1,1,1,1,1,1,1,1
1,1,1,1,1,1,1,1,1,1,1,1,1,1,1,1,1,1,1,1,1
endlayer

layer
1,1,1,1,1,1,1,1,1,1,1,1,1,1,1,1,1,1,1,1,1
1,1,1,1,1,1,1,1,1,1,1,1,1,1,1,1,1,1,1,1,1
1,1,1,1,1,1,1,1,1,1,1,1,1,1,1,1,1,1,1,1,1
1,1,1,1,1,1,1,1,1,1,1,1,1,1,1,1,1,1,1,1,1
1,1,1,1,3,2,2,2,3,2,2,2,3,2,2,2,3,1,1,1,1
1,1,1,1,2,0,0,0,0,0,0,0,0,0,0,0,2,1,1,1,1
1,1,1,1,2,0,0,0,0,0,0,0,0,20,0,0,2,1,1,1,1
1,1,1,1,2,0,0,0,0,0,0,0,23,22,21,0,2,1,1,1,1
1,1,1,1,3,5,5,0,0,0,0,0,0,24,0,0,3,1,1,1,1
1,1,1,1,2,6,6,0,0,2,2,2,0,0,0,0,2,1,1,1,1
1,1,1,1,2,0,9,0,0,2,3,2,0,0,0,0,2,1,1,1,1
1,1,1,1,2,0,9,0,0,2,2,2,0,0,0,0,2,1,1,1,1
1,1,1,1,3,0,9,0,0,0,0,0,0,20,0,0,3,1,1,1,1
1,1,1,1,2,0,9,0,0,0,0,0,23,22,21,0,2,1,1,1,1
1,1,1,1,2,0,0,0,0,0,0,0,0,24,0,0,2,1,1,1,1
1,1,1,1,2,0,0,0,0,0,0,0,0,0,0,0,2,1,1,1,1
1,1,1,1,3,2,2,2,3,2,2,2,3,2,2,2,3,1,1,1,1
1,1,1,1,1,1,1,1,1,1,1,1,1,1,1,1,1,1,1,1,1
1,1,1,1,1,1,1,1,1,1,1,1,1,1,1,1,1,1,1,1,1
1,1,1,1,1,1,1,1,1,1,1,1,1,1,1,1,1,1,1,1,1
1,1,1,1,1,1,1,1,1,1,1,1,1,1,1,1,1,1,1,1,1
endlayer

layer
1,1,1,1,1,1,1,1,1,1,1,1,1,1,1,1,1,1,1,1,1
1,1,1,1,1,1,1,1,1,1,1,1,1,1,1,1,1,1,1,1,1
1,1,1,1,1,1,1,1,1,1,1,1,1,1,1,1,1,1,1,1,1
1,1,1,1,1,1,1,1,1,1,1,1,1,1,1,1,1,1,1,1,1
1,1,1,1,3,7,7,7,3,7,7,7,3,7,7,7,3,1,1,1,1
1,1,1,1,7,0,0,0,0,0,0,0,0,0,0,0,7,1,1,1,1
1,1,1,1,7,0,0,0,0,0,0,0,0,0,0,0,7,1,1,1,1
1,1,1,1,7,0,0,0,0,0,0,0,0,9,0,0,7,1,1,1,1
1,1,1,1,3,0,0,0,0,0,0,0,0,0,0,0,3,1,1,1,1
1,1,1,1,7,5,5,0,0,0,0,0,0,0,0,0,7,1,1,1,1
1,1,1,1,7,6,6,0,0,0,3,0,0,0,0,0,7,1,1,1,1
1,1,1,1,7,0,0,0,0,0,0,0,0,0,0,0,7,1,1,1,1
1,1,1,1,3,0,0,0,0,0,0,0,0,0,0,0,3,1,1,1,1
1,1,1,1,7,0,0,0,0,0,0,0,0,9,0,0,7,1,1,1,1
1,1,1,1,7,0,0,0,0,0,0,0,0,0,0,0,7,1,1,1,1
1,1,1,1,7,0,0,0,0,0,0,0,0,0,0,0,7,1,1,1,1
1,1,1,1,3,7,7,7,3,7,7,7,3,7,7,7,3,1,1,1,1
1,1,1,1,1,1,1,1,1,1,1,1,1,1,1,1,1,1,1,1,1
1,1,1,1,1,1,1,1,1,1,1,1,1,1,1,1,1,1,1,1,1
1,1,1,1,1,1,1,1,1,1,1,1,1,1,1,1,1,1,1,1,1
1,1,1,1,1,1,1,1,1,1,1,1,1,1,1,1,1,1,1,1,1
endlayer

layer
1,1,1,1,1,1,1,1,1,1,1,1,1,1,1,1,1,1,1,1,1
1,1,1,1,1,1,1,1,1,1,1,1,1,1,1,1,1,1,1,1,1
1,1,1,1,1,1,1,1,1,1,1,1,1,1,1,1,1,1,1,1,1
1,1,1,1,1,1,1,1,1,1,1,1,1,1,1,1,1,1,1,1,1
1,1,1,1,3,8,8,8,3,8,8,8,3,8,8,8,3,1,1,1,1
1,1,1,1,8,0,0,0,0,0,0,0,0,0,0,0,8,1,1,1,1
1,1,1,1,8,0,0,0,0,0,0,0,0,0,0,0,8,1,1,1,1
1,1,1,1,8,0,0,0,0,0,0,0,0,25,0,0,8,1,1,1,1
1,1,1,1,3,0,0,0,0,0,0,0,0,0,0,0,3,1,1,1,1
1,1,1,1,8,0,0,0,0,0,9,0,0,0,0,0,8,1,1,1,1
1,1,1,1,8,5,5,0,0,9,3,9,0,0,0,0,8,1,1,1,1
1,1,1,1,8,6,6,0,0,0,9,0,0,0,0,0,8,1,1,1,1
1,1,1,1,3,0,0,0,0,0,0,0,0,0,0,0,3,1,1,1,1
1,1,1,1,8,0,0,0,0,0,0,0,0,25,0,0,8,1,1,1,1
1,1,1,1,8,0,0,0,0,0,0,0,0,0,0,0,8,1,1,1,1
1,1,1,1,8,0,0,0,0,0,0,0,0,0,0,0,8,1,1,1,1
1,1,1,1,3,8,8,8,3,8,8,8,3,8,8,8,3,1,1,1,1
1,1,1,1,1,1,1,1,1,1,1,1,1,1,1,1,1,1,1,1,1
1,1,1,1,1,1,1,1,1,1,1,1,1,1,1,1,1,1,1,1,1
1,1,1,1,1,1,1,1,1,1,1,1,1,1,1,1,1,1,1,1,1
1,1,1,1,1,1,1,1,1,1,1,1,1,1,1,1,1,1,1,1,1
endlayer

layer
1,1,1,1,1,1,1,1,1,1,1,1,1,1,1,1,1,1,1,1,1
1,1,1,1,1,1,1,1,1,1,1,1,1,1,1,1,1,1,1,1,1
1,1,1,1,1,1,1,1,1,1,1,1,1,1,1,1,1,1,1,1,1
1,1,1,1,1,1,1,1,1,1,1,1,1,1,1,1,1,1,1,1,1
1,1,1,1,3,2,2,2,3,2,2,2,3,2,2,2,3,1,1,1,1
1,1,1,1,2,10,10,10,10,10,10,10,10,10,10,10,2,1,1,1,1
1,1,1,1,2,10,10,10,10,10,10,10,10,10,10,10,2,1,1,1,1
1,1,1,1,2,10,10,0,0,0,0,0,0,0,10,10,2,1,1,1,1
1,1,1,1,3,0,0,0,0,0,0,0,0,0,10,10,3,1,1,1,1
1,1,1,1,2,0,0,0,0,0,11,0,0,0,10,10,2,1,1,1,1
1,1,1,1,2,0,0,0,0,11,3,11,0,0,10,10,2,1,1,1,1
1,1,1,1,2,5,5,0,0,0,11,0,0,0,10,10,2,1,1,1,1
1,1,1,1,3,6,6,0,0,0,0,0,0,0,10,10,3,1,1,1,1
1,1,1,1,2,10,10,0,0,0,0,0,0,0,10,10,2,1,1,1,1
1,1,1,1,2,10,10,10,10,10,10,10,10,10,10,10,2,1,1,1,1
1,1,1,1,2,10,10,10,10,10,10,10,10,10,10,10,2,1,1,1,1
1,1,1,1,3,2,2,2,3,2,2,2,3,2,2,2,3,1,1,1,1
1,1,1,1,1,1,1,1,1,1,1,1,1,1,1,1,1,1,1,1,1
1,1,1,1,1,1,1,1,1,1,1,1,1,1,1,1,1,1,1,1,1
1,1,1,1,1,1,1,1,1,1,1,1,1,1,1,1,1,1,1,1,1
1,1,1,1,1,1,1,1,1,1,1,1,1,1,1,1,1,1,1,1,1
endlayer

layer
10,10,10,10,10,10,10,10,10,10,10,10,10,10,10,10,10,10,10,10,10
10,4,4,4,4,4,4,4,4,4,4,4,4,4,4,4,4,4,4,4,10
10,4,1,1,1,1,1,1,1,1,1,1,1,1,1,1,1,1,1,4,10
10,4,1,1,1,1,1,1,1,1,1,1,1,1,1,1,1,1,1,4,10
10,4,1,1,3,2,2,2,3,2,2,2,3,2,2,2,3,1,1,4,10
10,4,1,1,2,12,0,0,0,0,0,0,0,0,0,0,2,1,1,4,10
10,4,1,1,2,0,0,0,0,0,0,0,0,0,0,0,2,1,1,4,10
10,4,1,1,2,9,9,0,0,0,0,0,0,0,0,0,2,1,1,4,10
10,4,1,1,3,0,0,0,0,0,0,0,0,0,0,0,3,1,1,4,10
10,4,1,1,2,0,0,0,0,0,0,0,0,0,0,0,2,1,1,4,10
10,4,1,1,2,0,0,0,0,0,3,0,0,0,0,0,2,1,1,4,10
10,4,1,1,2,0,0,0,0,0,0,0,0,0,0,0,2,1,1,4,10
10,4,1,1,3,5,0,0,0,0,0,0,0,0,0,0,3,1,1,4,10
10,4,1,1,2,6,0,0,0,0,0,0,0,0,0,0,2,1,1,4,10
10,4,1,1,2,0,0,0,0,0,0,0,0,0,0,0,2,1,1,4,10
10,4,1,1,2,0,0,0,0,0,0,0,0,0,0,0,2,1,1,4,10
10,4,1,1,3,2,2,2,3,2,2,2,3,2,2,2,3,1,1,4,10
10,4,1,1,1,1,1,1,1,1,1,1,1,1,1,1,1,1,1,4,10
10,4,1,1,1,1,1,1,1,1,1,1,1,1,1,1,1,1,1,4,10
10,4,4,4,4,4,4,4,4,4,4,4,4,4,4,4,4,4,4,4,10
10,10,10,10,10,10,10,10,10,10,10,10,10,10,10,10,10,10,10,10,10
endlayer

layer
13,14,14,14,14,14,14,14,14,14,14,14,14,14,14,14,14,14,14,14,13
14,1,1,1,1,1,1,1,1,1,1,1,1,1,1,1,1,1,1,1,14
14,1,5,5,5,5,5,5,5,5,5,5,5,5,5,5,5,5,5,1,14
14,1,16,1,1,1,1,1,1,1,1,1,1,1,1,1,1,1,15,1,14
14,1,16,1,3,9,9,9,3,9,9,9,3,9,9,9,3,1,15,1,14
14,1,16,1,9,0,0,0,0,0,0,0,0,0,0,0,9,1,15,1,14
14,1,16,1,9,0,0,0,0,0,0,0,0,0,0,0,9,1,15,1,14
14,1,16,1,9,0,0,0,0,0,0,0,0,0,0,0,9,1,15,1,14
14,1,16,1,3,0,0,0,0,0,0,0,0,0,0,0,3,1,15,1,14
14,1,16,1,9,0,0,0,0,0,0,0,0,0,0,0,9,1,15,1,14
14,1,16,1,9,0,0,0,0,0,3,0,0,0,0,0,9,1,15,1,14
14,1,16,1,9,0,0,0,0,0,0,0,0,0,0,0,9,1,15,1,14
14,1,16,1,3,0,0,0,0,0,0,0,0,0,0,0,3,1,15,1,14
14,1,16,1,9,5,0,0,0,0,0,0,0,0,0,0,9,1,15,1,14
14,1,16,1,9,6,0,0,0,0,0,0,0,0,0,0,9,1,15,1,14
14,1,16,1,9,0,0,0,0,0,0,0,0,0,0,0,9,1,15,1,14
14,1,16,1,3,9,9,9,3,9,9,9,3,9,9,9,3,1,15,1,14
14,1,16,1,1,1,1,1,1,1,1,1,1,1,1,1,1,1,15,1,14
14,1,17,17,17,17,17,17,17,17,17,17,17,17,17,17,17,17,17,1,14
14,1,1,1,1,1,1,1,1,1,1,1,1,1,1,1,1,1,1,1,14
13,14,14,14,14,14,14,14,14,14,14,14,14,14,14,14,14,14,14,14,13
endlayer

layer
1,1,1,1,1,1,1,1,1,1,1,1,1,1,1,1,1,1,1,1,1
1,1,1,1,1,1,1,1,1,1,1,1,1,1,1,1,1,1,1,1,1
1,1,1,1,1,1,1,1,1,1,1,1,1,1,1,1,1,1,1,1,1
1,1,1,5,5,5,5,5,5,5,5,5,5,5,5,5,5,15,1,1,1
1,1,1,16,3,18,18,18,3,18,18,18,3,18,18,18,3,15,1,1,1
1,1,1,16,19,10,10,10,10,10,19,10,10,10,10,10,19,15,1,1,1
1,1,1,16,19,10,10,10,10,10,19,10,10,10,10,10,19,15,1,1,1
1,1,1,16,19,10,10,10,10,10,19,10,10,10,10,10,19,15,1,1,1
1,1,1,16,3,10,10,10,10,10,19,10,10,10,10,10,3,15,1,1,1
1,1,1,16,19,10,10,10,10,10,19,10,10,10,10,10,19,15,1,1,1
1,1,1,16,19,18,18,18,18,18,3,18,18,18,18,18,19,15,1,1,1
1,1,1,16,19,0,10,10,10,10,19,10,10,10,10,10,19,15,1,1,1
1,1,1,16,3,0,10,10,10,10,19,10,10,10,10,10,3,15,1,1,1
1,1,1,16,19,0,10,10,10,10,19,10,10,10,10,10,19,15,1,1,1
1,1,1,16,19,5,10,10,10,10,19,10,10,10,10,10,19,15,1,1,1
1,1,1,16,19,6,10,10,10,10,19,10,10,10,10,10,19,15,1,1,1
1,1,1,16,3,18,18,18,3,18,18,18,3,18,18,18,3,15,1,1,1
1,1,1,16,17,17,17,17,17,17,17,17,17,17,17,17,17,17,1,1,1
1,1,1,1,1,1,1,1,1,1,1,1,1,1,1,1,1,1,1,1,1
1,1,1,1,1,1,1,1,1,1,1,1,1,1,1,1,1,1,1,1,1
1,1,1,1,1,1,1,1,1,1,1,1,1,1,1,1,1,1,1,1,1
endlayer

layer
1,1,1,1,1,1,1,1,1,1,1,1,1,1,1,1,1,1,1,1,1
1,1,1,1,1,1,1,1,1,1,1,1,1,1,1,1,1,1,1,1,1
1,1,1,1,1,1,1,1,1,1,1,1,1,1,1,1,1,1,1,1,1
1,1,1,1,1,1,1,1,1,1,1,1,1,1,1,1,1,1,1,1,1
1,1,1,1,3,2,2,2,3,2,2,2,3,2,2,2,3,1,1,1,1
1,1,1,1,2,0,0,0,0,0,9,0,0,0,0,0,2,1,1,1,1
1,1,1,1,2,0,0,0,0,0,0,0,0,0,27,26,2,1,1,1,1
1,1,1,1,2,0,0,0,0,0,0,0,0,0,0,9,2,1,1,1,1
1,1,1,1,3,5,0,0,0,0,9,0,0,0,27,26,3,1,1,1,1
1,1,1,1,2,6,0,0,0,2,2,2,0,0,0,0,2,1,1,1,1
1,1,1,1,2,0,0,0,0,2,3,2,9,9,9,9,2,1,1,1,1
1,1,1,1,2,0,0,0,0,2,2,2,0,0,0,0,2,1,1,1,1
1,1,1,1,3,0,0,0,0,0,9,0,0,0,27,26,3,1,1,1,1
1,1,1,1,2,0,0,0,0,0,0,0,0,0,0,9,2,1,1,1,1
1,1,1,1,2,0,0,0,0,0,0,0,0,0,27,26,2,1,1,1,1
1,1,1,1,2,0,0,0,0,0,9,0,0,0,0,0,2,1,1,1,1
1,1,1,1,3,2,2,2,3,2,2,2,3,2,2,2,3,1,1,1,1
1,1,1,1,1,1,1,1,1,1,1,1,1,1,1,1,1,1,1,1,1
1,1,1,1,1,1,1,1,1,1,1,1,1,1,1,1,1,1,1,1,1
1,1,1,1,1,1,1,1,1,1,1,1,1,1,1,1,1,1,1,1,1
1,1,1,1,1,1,1,1,1,1,1,1,1,1,1,1,1,1,1,1,1
endlayer

layer
1,1,1,1,1,1,1,1,1,1,1,1,1,1,1,1,1,1,1,1,1
1,1,1,1,1,1,1,1,1,1,1,1,1,1,1,1,1,1,1,1,1
1,1,1,1,1,1,1,1,1,1,1,1,1,1,1,1,1,1,1,1,1
1,1,1,1,1,1,1,1,1,1,1,1,1,1,1,1,1,1,1,1,1
1,1,1,1,3,7,7,7,3,7,7,7,3,7,7,7,3,1,1,1,1
1,1,1,1,7,0,0,0,0,0,0,0,0,0,0,0,7,1,1,1,1
1,1,1,1,7,0,0,0,0,0,0,0,0,0,0,0,7,1,1,1,1
1,1,1,1,7,0,0,0,0,0,0,0,0,0,0,28,7,1,1,1,1
1,1,1,1,3,0,0,0,0,0,0,0,0,0,0,0,3,1,1,1,1
1,1,1,1,7,5,0,0,0,0,0,0,0,0,0,0,7,1,1,1,1
1,1,1,1,7,6,0,0,0,0,3,0,16,16,16,16,7,1,1,1,1
1,1,1,1,7,0,0,0,0,0,0,0,0,0,0,0,7,1,1,1,1
1,1,1,1,3,0,0,0,0,0,0,0,0,0,0,0,3,1,1,1,1
1,1,1,1,7,0,0,0,0,0,0,0,0,0,0,28,7,1,1,1,1
1,1,1,1,7,0,0,0,0,0,0,0,0,0,0,0,7,1,1,1,1
1,1,1,1,7,0,0,0,0,0,0,0,0,0,0,0,7,1,1,1,1
1,1,1,1,3,7,7,7,3,7,7,7,3,7,7,7,3,1,1,1,1
1,1,1,1,1,1,1,1,1,1,1,1,1,1,1,1,1,1,1,1,1
1,1,1,1,1,1,1,1,1,1,1,1,1,1,1,1,1,1,1,1,1
1,1,1,1,1,1,1,1,1,1,1,1,1,1,1,1,1,1,1,1,1
1,1,1,1,1,1,1,1,1,1,1,1,1,1,1,1,1,1,1,1,1
endlayer

layer
1,1,1,1,1,1,1,1,1,1,1,1,1,1,1,1,1,1,1,1,1
1,1,1,1,1,1,1,1,1,1,1,1,1,1,1,1,1,1,1,1,1
1,1,1,1,1,1,1,1,1,1,1,1,1,1,1,1,1,1,1,1,1
1,1,1,1,1,1,1,1,1,1,1,1,1,1,1,1,1,1,1,1,1
1,1,1,1,3,8,8,8,3,8,8,8,3,8,8,8,3,1,1,1,1
1,1,1,1,8,0,0,0,0,0,0,0,0,0,0,0,8,1,1,1,1
1,1,1,1,8,0,0,0,0,0,0,0,0,0,0,0,8,1,1,1,1
1,1,1,1,8,0,0,0,0,0,0,0,0,0,0,0,8,1,1,1,1
1,1,1,1,3,0,0,0,0,0,0,0,0,0,0,0,3,1,1,1,1
1,1,1,1,8,0,0,0,0,0,9,0,0,0,0,0,8,1,1,1,1
1,1,1,1,8,5,0,0,0,9,3,9,0,14,14,14,8,1,1,1,1
1,1,1,1,8,6,0,0,0,0,9,0,0,0,0,0,8,1,1,1,1
1,1,1,1,3,0,0,0,0,0,0,0,0,0,0,0,3,1,1,1,1
1,1,1,1,8,0,0,0,0,0,0,0,0,0,0,0,8,1,1,1,1
1,1,1,1,8,0,0,0,0,0,0,0,0,0,0,0,8,1,1,1,1
1,1,1,1,8,0,0,0,0,0,0,0,0,0,0,0,8,1,1,1,1
1,1,1,1,3,8,8,8,3,8,8,8,3,8,8,8,3,1,1,1,1
1,1,1,1,1,1,1,1,1,1,1,1,1,1,1,1,1,1,1,1,1
1,1,1,1,1,1,1,1,1,1,1,1,1,1,1,1,1,1,1,1,1
1,1,1,1,1,1,1,1,1,1,1,1,1,1,1,1,1,1,1,1,1
1,1,1,1,1,1,1,1,1,1,1,1,1,1,1,1,1,1,1,1,1
endlayer

layer
1,1,1,1,1,1,1,1,1,1,1,1,1,1,1,1,1,1,1,1,1
1,1,1,1,1,1,1,1,1,1,1,1,1,1,1,1,1,1,1,1,1
1,1,1,1,1,1,1,1,1,1,1,1,1,1,1,1,1,1,1,1,1
1,1,1,1,1,1,1,1,1,1,1,1,1,1,1,1,1,1,1,1,1
1,1,1,1,3,2,2,2,3,2,2,2,3,2,2,2,3,1,1,1,1
1,1,1,1,2,10,10,10,10,10,10,10,10,10,10,10,2,1,1,1,1
1,1,1,1,2,10,10,10,10,10,10,10,10,10,10,10,2,1,1,1,1
1,1,1,1,2,10,10,0,0,0,0,0,0,0,10,10,2,1,1,1,1
1,1,1,1,3,0,0,0,0,0,0,0,0,0,10,10,3,1,1,1,1
1,1,1,1,2,0,0,0,0,0,11,0,0,0,10,10,2,1,1,1,1
1,1,1,1,2,0,0,0,0,11,3,11,0,0,10,10,2,1,1,1,1
1,1,1,1,2,5,0,0,0,0,11,0,0,0,10,10,2,1,1,1,1
1,1,1,1,3,6,0,0,0,0,0,0,0,0,10,10,3,1,1,1,1
1,1,1,1,2,10,0,0,0,0,0,0,0,0,10,10,2,1,1,1,1
1,1,1,1,2,10,10,10,10,10,10,10,10,10,10,10,2,1,1,1,1
1,1,1,1,2,10,10,10,10,10,10,10,10,10,10,10,2,1,1,1,1
1,1,1,1,3,2,2,2,3,2,2,2,3,2,2,2,3,1,1,1,1
1,1,1,1,1,1,1,1,1,1,1,1,1,1,1,1,1,1,1,1,1
1,1,1,1,1,1,1,1,1,1,1,1,1,1,1,1,1,1,1,1,1
1,1,1,1,1,1,1,1,1,1,1,1,1,1,1,1,1,1,1,1,1
1,1,1,1,1,1,1,1,1,1,1,1,1,1,1,1,1,1,1,1,1
endlayer

layer
10,10,10,10,10,10,10,10,10,10,10,10,10,10,10,10,10,10,10,10,10
10,4,4,4,4,4,4,4,4,4,4,4,4,4,4,4,4,4,4,4,10
10,4,1,1,1,1,1,1,1,1,1,1,1,1,1,1,1,1,1,4,10
10,4,1,1,1,1,1,1,1,1,1,1,1,1,1,1,1,1,1,4,10
10,4,1,1,3,2,2,2,3,2,2,2,3,2,2,2,3,1,1,4,10
10,4,1,1,2,12,0,0,0,0,0,0,0,0,0,0,2,1,1,4,10
10,4,1,1,2,0,0,0,0,0,0,0,0,0,0,0,2,1,1,4,10
10,4,1,1,2,9,9,0,0,0,0,0,0,0,0,0,2,1,1,4,10
10,4,1,1,3,0,0,0,0,0,0,0,0,0,0,0,3,1,1,4,10
10,4,1,1,2,0,0,0,0,0,0,0,0,0,0,0,2,1,1,4,10
10,4,1,1,2,0,0,0,0,0,3,0,0,0,0,0,2,1,1,4,10
10,4,1,1,2,0,0,0,0,0,0,0,0,0,0,0,2,1,1,4,10
10,4,1,1,3,0,0,0,0,0,0,0,0,0,0,0,3,1,1,4,10
10,4,1,1,2,0,0,0,0,0,0,0,0,0,0,0,2,1,1,4,10
10,4,1,1,2,0,0,0,0,0,0,0,0,0,0,0,2,1,1,4,10
10,4,1,1,2,0,0,0,0,0,0,0,0,0,0,0,2,1,1,4,10
10,4,1,1,3,2,2,2,3,2,2,2,3,2,2,2,3,1,1,4,10
10,4,1,1,1,1,1,1,1,1,1,1,1,1,1,1,1,1,1,4,10
10,4,1,1,1,1,1,1,1,1,1,1,1,1,1,1,1,1,1,4,10
10,4,4,4,4,4,4,4,4,4,4,4,4,4,4,4,4,4,4,4,10
10,10,10,10,10,10,10,10,10,10,10,10,10,10,10,10,10,10,10,10,10
endlayer

layer
13,14,14,14,14,14,14,14,14,14,14,14,14,14,14,14,14,14,14,14,13
14,1,1,1,1,1,1,1,1,1,1,1,1,1,1,1,1,1,1,1,14
14,1,5,5,5,5,5,5,5,5,5,5,5,5,5,5,5,5,5,1,14
14,1,16,1,1,1,1,1,1,1,1,1,1,1,1,1,1,1,15,1,14
14,1,16,1,3,9,9,9,3,9,9,9,3,9,9,9,3,1,15,1,14
14,1,16,1,9,0,0,0,0,0,0,0,0,0,0,0,9,1,15,1,14
14,1,16,1,9,0,0,0,0,0,0,0,0,0,0,0,9,1,15,1,14
14,1,16,1,9,0,0,0,0,0,0,0,0,0,0,0,9,1,15,1,14
14,1,16,1,3,0,0,0,0,0,0,0,0,0,0,0,3,1,15,1,14
14,1,16,1,9,0,0,0,0,0,0,0,0,0,0,0,9,1,15,1,14
14,1,16,1,9,0,0,0,0,0,3,0,0,0,0,0,9,1,15,1,14
14,1,16,1,9,0,0,0,0,0,0,0,0,0,0,0,9,1,15,1,14
14,1,16,1,3,0,0,0,0,0,0,0,0,0,0,0,3,1,15,1,14
14,1,16,1,9,0,0,0,0,0,0,0,0,0,0,0,9,1,15,1,14
14,1,16,1,9,0,0,0,0,0,0,0,0,0,0,0,9,1,15,1,14
14,1,16,1,9,0,0,0,0,0,0,0,0,0,0,0,9,1,15,1,14
14,1,16,1,3,9,9,9,3,9,9,9,3,9,9,9,3,1,15,1,14
14,1,16,1,1,1,1,1,1,1,1,1,1,1,1,1,1,1,15,1,14
14,1,17,17,17,17,17,17,17,17,17,17,17,17,17,17,17,17,17,1,14
14,1,1,1,1,1,1,1,1,1,1,1,1,1,1,1,1,1,1,1,14
13,14,14,14,14,14,14,14,14,14,14,14,14,14,14,14,14,14,14,14,13
endlayer

layer
1,1,1,1,1,1,1,1,1,1,1,1,1,1,1,1,1,1,1,1,1
1,1,1,1,1,1,1,1,1,1,1,1,1,1,1,1,1,1,1,1,1
1,1,1,1,1,1,1,1,1,1,1,1,1,1,1,1,1,1,1,1,1
1,1,1,5,5,5,5,5,5,5,5,5,5,5,5,5,5,15,1,1,1
1,1,1,16,3,18,18,18,3,18,18,18,3,18,18,18,3,15,1,1,1
1,1,1,16,19,10,10,10,10,10,19,10,10,10,10,10,19,15,1,1,1
1,1,1,16,19,10,10,10,10,10,19,10,10,10,10,10,19,15,1,1,1
1,1,1,16,19,10,10,10,10,10,19,10,10,10,10,10,19,15,1,1,1
1,1,1,16,3,10,10,10,10,10,19,10,10,10,10,10,3,15,1,1,1
1,1,1,16,19,10,10,10,10,10,19,10,10,10,10,10,19,15,1,1,1
1,1,1,16,19,18,18,18,18,18,3,18,18,18,18,18,19,15,1,1,1
1,1,1,16,19,10,10,10,10,10,19,10,10,10,10,10,19,15,1,1,1
1,1,1,16,3,10,10,10,10,10,19,10,10,10,10,10,3,15,1,1,1
1,1,1,16,19,10,10,10,10,10,19,10,10,10,10,10,19,15,1,1,1
1,1,1,16,19,10,10,10,10,10,19,10,10,10,10,10,19,15,1,1,1
1,1,1,16,19,10,10,10,10,10,19,10,10,10,10,10,19,15,1,1,1
1,1,1,16,3,18,18,18,3,18,18,18,3,18,18,18,3,15,1,1,1
1,1,1,16,17,17,17,17,17,17,17,17,17,17,17,17,17,17,1,1,1
1,1,1,1,1,1,1,1,1,1,1,1,1,1,1,1,1,1,1,1,1
1,1,1,1,1,1,1,1,1,1,1,1,1,1,1,1,1,1,1,1,1
1,1,1,1,1,1,1,1,1,1,1,1,1,1,1,1,1,1,1,1,1
endlayer

layer
0,0,0,0,0,0,0,0,0,0,0,0,0,0,0,0,0,0,0,0,0
0,0,0,0,0,0,0,0,0,0,0,0,0,0,0,0,0,0,0,0,0
0,0,0,0,0,0,0,0,0,0,0,0,0,0,0,0,0,0,0,0,0
0,0,0,0,0,0,0,0,0,0,0,0,0,0,0,0,0,0,0,0,0
0,0,0,0,16,5,5,5,5,5,5,5,5,5,5,5,15,0,0,0,0
0,0,0,0,16,4,4,4,4,4,4,4,4,4,4,4,15,0,0,0,0
0,0,0,0,16,4,4,4,4,4,4,4,4,4,4,4,15,0,0,0,0
0,0,0,0,16,4,4,29,4,4,4,4,4,4,4,4,15,0,0,0,0
0,0,0,0,16,4,4,29,4,4,4,4,4,4,4,4,15,0,0,0,0
0,0,0,0,16,4,4,29,4,4,4,4,4,4,4,4,15,0,0,0,0
0,0,0,0,16,4,4,4,33,4,32,31,30,4,4,4,15,0,0,0,0
0,0,0,0,16,4,4,29,35,34,4,4,4,4,4,4,15,0,0,0,0
0,0,0,0,16,36,4,29,4,4,4,4,4,4,4,4,15,0,0,0,0
0,0,0,0,16,4,4,29,4,4,4,4,4,4,4,4,15,0,0,0,0
0,0,0,0,16,4,4,4,4,4,4,4,4,4,4,4,15,0,0,0,0
0,0,0,0,16,4,4,4,4,4,4,4,4,4,4,4,15,0,0,0,0
0,0,0,0,17,17,17,17,17,17,17,17,17,17,17,17,15,0,0,0,0
0,0,0,0,0,0,0,0,0,0,0,0,0,0,0,0,0,0,0,0,0
0,0,0,0,0,0,0,0,0,0,0,0,0,0,0,0,0,0,0,0,0
0,0,0,0,0,0,0,0,0,0,0,0,0,0,0,0,0,0,0,0,0
0,0,0,0,0,0,0,0,0,0,0,0,0,0,0,0,0,0,0,0,0
endlayer

layer
0,0,0,0,0,0,0,0,0,0,0,0,0,0,0,0,0,0,0,0,0
0,0,0,0,0,0,0,0,0,0,0,0,0,0,0,0,0,0,0,0,0
0,0,0,0,0,0,0,0,0,0,0,0,0,0,0,0,0,0,0,0,0
0,0,0,0,0,0,0,0,0,0,0,0,0,0,0,0,0,0,0,0,0
0,0,0,0,0,0,0,0,0,0,0,0,0,0,0,0,0,0,0,0,0
0,0,0,0,0,16,5,5,5,5,5,5,5,5,5,5,0,0,0,0,0
0,0,0,0,0,16,4,4,4,4,4,4,4,4,4,15,0,0,0,0,0
0,0,0,0,0,16,4,35,4,4,4,4,4,4,4,15,0,0,0,0,0
0,0,0,0,0,16,4,35,4,4,4,4,4,4,4,15,0,0,0,0,0
0,0,0,0,0,16,4,35,4,4,4,4,4,4,4,15,0,0,0,0,0
0,0,0,0,0,16,4,35,0,4,4,0,38,37,4,15,0,0,0,0,0
0,0,0,0,0,16,4,35,0,4,4,4,4,4,4,15,0,0,0,0,0
0,0,0,0,0,16,4,35,4,4,4,4,4,4,4,15,0,0,0,0,0
0,0,0,0,0,16,4,35,4,4,4,4,4,4,4,15,0,0,0,0,0
0,0,0,0,0,16,4,4,4,4,4,4,4,4,4,15,0,0,0,0,0
0,0,0,0,0,17,17,17,17,17,17,17,17,17,17,17,0,0,0,0,0
0,0,0,0,0,0,0,0,0,0,0,0,0,0,0,0,0,0,0,0,0
0,0,0,0,0,0,0,0,0,0,0,0,0,0,0,0,0,0,0,0,0
0,0,0,0,0,0,0,0,0,0,0,0,0,0,0,0,0,0,0,0,0
0,0,0,0,0,0,0,0,0,0,0,0,0,0,0,0,0,0,0,0,0
0,0,0,0,0,0,0,0,0,0,0,0,0,0,0,0,0,0,0,0,0
endlayer

layer
0,0,0,0,0,0,0,0,0,0,0,0,0,0,0,0,0,0,0,0,0
0,0,0,0,0,0,0,0,0,0,0,0,0,0,0,0,0,0,0,0,0
0,0,0,0,0,0,0,0,0,0,0,0,0,0,0,0,0,0,0,0,0
0,0,0,0,0,0,0,0,0,0,0,0,0,0,0,0,0,0,0,0,0
0,0,0,0,0,0,0,0,0,0,0,0,0,0,0,0,0,0,0,0,0
0,0,0,0,0,0,0,0,0,0,0,0,0,0,0,0,0,0,0,0,0
0,0,0,0,0,0,14,14,14,14,14,14,14,14,14,0,0,0,0,0,0
0,0,0,0,0,0,14,4,4,4,4,4,4,4,14,0,0,0,0,0,0
0,0,0,0,0,0,14,4,4,4,4,4,4,4,14,0,0,0,0,0,0
0,0,0,0,0,0,14,4,4,4,4,4,4,4,14,0,0,0,0,0,0
0,0,0,0,0,0,14,4,4,4,4,4,4,4,14,0,0,0,0,0,0
0,0,0,0,0,0,14,4,4,4,4,4,4,4,14,0,0,0,0,0,0
0,0,0,0,0,0,14,4,4,4,4,4,4,4,14,0,0,0,0,0,0
0,0,0,0,0,0,14,4,4,4,4,4,4,4,14,0,0,0,0,0,0
0,0,0,0,0,0,14,14,14,14,14,14,14,14,14,0,0,0,0,0,0
0,0,0,0,0,0,0,0,0,0,0,0,0,0,0,0,0,0,0,0,0
0,0,0,0,0,0,0,0,0,0,0,0,0,0,0,0,0,0,0,0,0
0,0,0,0,0,0,0,0,0,0,0,0,0,0,0,0,0,0,0,0,0
0,0,0,0,0,0,0,0,0,0,0,0,0,0,0,0,0,0,0,0,0
0,0,0,0,0,0,0,0,0,0,0,0,0,0,0,0,0,0,0,0,0
0,0,0,0,0,0,0,0,0,0,0,0,0,0,0,0,0,0,0,0,0
endlayer

layer
0,0,0,0,0,0,0,0,0,0,0,0,0,0,0,0,0,0,0,0,0
0,0,0,0,0,0,0,0,0,0,0,0,0,0,0,0,0,0,0,0,0
0,0,0,0,0,0,0,0,0,0,0,0,0,0,0,0,0,0,0,0,0
0,0,0,0,0,0,0,0,0,0,0,0,0,0,0,0,0,0,0,0,0
0,0,0,0,0,0,0,0,0,0,0,0,0,0,0,0,0,0,0,0,0
0,0,0,0,0,0,0,0,0,0,0,0,0,0,0,0,0,0,0,0,0
0,0,0,0,0,0,0,0,0,0,0,0,0,0,0,0,0,0,0,0,0
0,0,0,0,0,0,0,0,0,0,0,0,0,0,0,0,0,0,0,0,0
0,0,0,0,0,0,0,0,14,14,14,14,14,0,0,0,0,0,0,0,0
0,0,0,0,0,0,0,0,14,16,5,15,14,0,0,0,0,0,0,0,0
0,0,0,0,0,0,0,0,14,16,4,15,14,0,0,0,0,0,0,0,0
0,0,0,0,0,0,0,0,14,16,17,17,14,0,0,0,0,0,0,0,0
0,0,0,0,0,0,0,0,14,14,14,14,14,0,0,0,0,0,0,0,0
0,0,0,0,0,0,0,0,0,0,0,0,0,0,0,0,0,0,0,0,0
0,0,0,0,0,0,0,0,0,0,0,0,0,0,0,0,0,0,0,0,0
0,0,0,0,0,0,0,0,0,0,0,0,0,0,0,0,0,0,0,0,0
0,0,0,0,0,0,0,0,0,0,0,0,0,0,0,0,0,0,0,0,0
0,0,0,0,0,0,0,0,0,0,0,0,0,0,0,0,0,0,0,0,0
0,0,0,0,0,0,0,0,0,0,0,0,0,0,0,0,0,0,0,0,0
0,0,0,0,0,0,0,0,0,0,0,0,0,0,0,0,0,0,0,0,0
0,0,0,0,0,0,0,0,0,0,0,0,0,0,0,0,0,0,0,0,0
endlayer

