
# Created by Ruins mod version 17.1 Ingame Parser
# authoring Player: ST753M

weight=1
embed_into_distance=3
acceptable_target_blocks=grass,dirt,podzol,mycelium,stone,biomesoplenty:grass,biomesoplenty:dirt
unacceptable_target_blocks=flowing_water,water,flowing_lava,lava
dimensions=14,14,14
allowable_overhang=3
max_leveling=0
leveling_buffer=0
preserve_water=0
preserve_lava=0

biomesToSpawnIn=bamboo_forest

=0,100,air
rule1=0,100,preserveBlock
rule2=0,100,biomesoplenty:bamboo_thatching-0
rule3=0,100,minecraft:dirt-2
rule4=0,100,minecraft:dirt-0
rule5=0,100,biomesoplenty:planks_0-9
rule6=0,100,biomesoplenty:bamboo-0
rule7=0,100,biomesoplenty:willow_door_block-2
rule8=0,100,biomesoplenty:willow_vine-2
rule9=0,100,biomesoplenty:log_2-1
rule10=0,100,biomesoplenty:willow_stairs-0
rule11=0,100,biomesoplenty:willow_door_block-9
rule12=0,100,biomesoplenty:willow_door_block-8
rule13=0,100,minecraft:stained_glass_pane-13
rule14=0,100,teBlock;minecraft:flower_pot;{Item:"minecraft:cactus",x:-803326,y:102,z:-200702,Data:0,id:"minecraft:flower_pot"}-0
rule15=0,100,biomesoplenty:terrarium-6
rule16=0,100,biomesoplenty:bamboo-1
rule17=0,100,biomesoplenty:leaves_0-6
rule18=0,100,biomesoplenty:leaves_0-14
rule19=0,100,ChestGenHook:chests/spawn_bonus_chest:4-3,air

layer
1,1,1,1,1,1,1,1,1,1,1,1,1,1
1,1,1,1,1,2,2,2,2,1,1,1,1,1
1,1,1,2,2,3,3,3,3,2,2,1,1,1
1,1,2,3,3,3,3,3,3,3,3,2,1,1
1,1,2,3,3,3,3,3,3,3,3,2,1,1
1,2,3,3,3,3,3,3,3,3,3,3,2,1
1,2,3,3,3,3,3,3,3,3,3,3,2,1
1,2,3,3,3,3,3,3,3,3,3,3,2,1
1,2,3,3,3,3,3,3,3,3,3,3,2,1
1,1,2,3,3,3,3,3,3,3,3,2,1,1
1,1,2,3,3,3,3,3,3,3,3,2,1,1
1,1,1,2,2,3,3,3,3,2,2,1,1,1
1,1,1,1,1,2,2,2,2,1,1,1,1,1
1,1,1,1,1,1,1,1,1,1,1,1,1,1
endlayer

layer
1,1,1,1,1,1,1,1,1,1,1,1,1,1
1,1,1,1,1,4,4,4,4,1,1,1,1,1
1,1,1,4,4,3,3,3,3,4,4,1,1,1
1,1,4,3,3,3,3,3,3,3,3,4,1,1
1,1,4,3,3,3,3,3,3,3,3,4,1,1
1,4,3,3,3,3,3,3,3,3,3,3,4,1
1,4,3,3,3,3,3,3,3,3,3,3,4,1
1,4,3,3,3,3,3,3,3,3,3,3,4,1
1,4,3,3,3,3,3,3,3,3,3,3,4,1
1,1,4,3,3,3,3,3,3,3,3,4,1,1
1,1,4,3,3,3,3,3,3,3,3,4,1,1
1,1,1,4,4,3,3,3,3,4,4,1,1,1
1,1,1,1,1,4,4,4,4,1,1,1,1,1
1,1,1,1,1,1,1,1,1,1,1,1,1,1
endlayer

layer
1,1,1,1,1,1,1,1,1,1,1,1,1,1
1,1,1,1,1,3,3,3,3,1,1,1,1,1
1,1,1,3,3,3,3,3,3,3,3,1,1,1
1,1,3,3,3,3,3,3,3,3,3,3,1,1
1,1,3,3,3,5,5,5,5,3,3,3,1,1
1,3,3,3,5,5,5,5,5,5,3,3,3,1
1,3,3,3,5,5,5,5,5,5,3,3,3,1
1,3,3,3,5,5,5,5,5,5,3,3,3,1
1,3,3,3,5,5,5,5,5,5,3,3,3,1
1,1,3,3,3,5,5,5,5,3,3,3,1,1
1,1,3,3,3,3,3,3,3,3,3,3,1,1
1,1,1,3,3,3,3,3,3,3,3,1,1,1
1,1,1,1,1,3,3,3,3,1,1,1,1,1
1,1,1,1,1,1,1,1,1,1,1,1,1,1
endlayer

layer
1,1,1,1,1,1,1,1,1,1,1,1,1,1
1,1,1,1,1,6,0,0,6,1,1,1,1,1
1,1,1,6,0,0,0,0,0,0,6,1,1,1
1,1,6,0,0,2,7,7,2,0,0,6,1,1
1,1,0,0,2,0,0,0,8,2,0,0,1,1
1,6,0,2,9,0,0,0,0,9,2,0,6,1
1,0,0,2,9,0,0,0,0,9,2,0,0,1
1,0,0,2,9,0,0,0,0,9,2,0,0,1
1,6,0,2,9,0,0,0,0,9,2,0,6,1
1,1,0,0,2,0,10,10,0,2,0,0,1,1
1,1,6,0,0,2,2,2,2,0,0,6,1,1
1,1,1,6,0,0,0,0,0,0,6,1,1,1
1,1,1,1,1,6,0,0,6,1,1,1,1,1
1,1,1,1,1,1,1,1,1,1,1,1,1,1
endlayer

layer
1,1,1,1,1,1,1,1,1,1,1,1,1,1
1,1,1,1,1,6,0,0,6,1,1,1,1,1
1,1,1,6,0,0,0,0,0,0,6,1,1,1
1,1,6,0,0,2,12,11,2,0,0,6,1,1
1,1,0,0,2,0,0,0,8,2,0,0,1,1
1,6,0,2,0,0,0,0,0,0,2,0,6,1
1,0,0,13,14,0,0,0,0,0,13,0,0,1
1,0,0,13,0,0,0,0,0,15,13,0,0,1
1,6,0,2,0,0,0,0,0,0,2,0,6,1
1,1,0,0,2,0,0,0,0,2,0,0,1,1
1,1,6,0,0,2,13,13,2,0,0,6,1,1
1,1,1,6,0,0,0,0,0,0,6,1,1,1
1,1,1,1,1,6,0,0,6,1,1,1,1,1
1,1,1,1,1,1,1,1,1,1,1,1,1,1
endlayer

layer
1,1,1,1,1,1,1,1,1,1,1,1,1,1
1,1,1,1,1,6,0,0,6,1,1,1,1,1
1,1,1,16,0,0,0,0,0,0,6,1,1,1
1,1,16,0,0,2,2,2,2,0,0,6,1,1
1,1,0,0,2,0,0,0,8,2,0,0,1,1
1,6,0,2,0,0,0,0,0,0,2,0,6,1
1,0,0,13,0,0,0,0,0,0,13,0,0,1
1,0,0,13,0,0,0,0,0,0,13,0,0,1
1,6,0,2,0,0,0,0,0,0,2,0,6,1
1,1,0,0,2,0,0,0,0,2,0,0,1,1
1,1,6,0,0,2,13,13,2,0,2,6,1,1
1,1,1,6,0,0,0,0,0,0,16,1,1,1
1,1,1,1,1,6,0,0,6,1,1,1,1,1
1,1,1,1,1,1,1,1,1,1,1,1,1,1
endlayer

layer
1,1,1,1,1,1,1,1,1,1,1,1,1,1
1,1,1,1,1,6,0,0,6,1,1,1,1,1
1,1,1,6,0,0,0,0,0,0,6,1,1,1
1,1,6,0,0,2,2,2,2,0,0,6,1,1
1,1,0,0,2,17,17,17,8,2,0,0,1,1
1,6,0,2,18,18,0,0,17,17,2,0,6,1
1,0,0,2,18,0,0,0,0,18,2,0,0,1
1,0,0,2,18,0,0,0,0,18,2,0,0,1
1,6,0,2,17,17,0,0,18,18,2,0,6,1
1,1,0,0,2,17,17,17,17,2,0,0,1,1
1,1,6,0,0,2,2,2,2,0,0,6,1,1
1,1,1,6,0,0,0,0,0,0,6,1,1,1
1,1,1,1,1,6,0,0,6,1,1,1,1,1
1,1,1,1,1,1,1,1,1,1,1,1,1,1
endlayer

layer
1,1,1,1,1,17,17,17,17,1,1,1,1,1
1,1,1,17,17,2,2,2,2,17,17,1,1,1
1,1,18,2,2,2,2,2,2,2,2,17,1,1
1,17,2,2,2,3,2,2,3,2,2,2,18,1
1,17,2,2,2,2,2,2,8,2,2,2,18,1
17,2,2,3,2,2,18,18,2,2,3,2,2,17
17,2,2,2,2,18,18,18,18,2,2,2,2,17
17,2,2,2,2,18,18,18,18,2,2,2,2,17
17,2,2,3,2,2,18,18,2,2,3,2,2,17
1,17,2,2,2,2,2,2,2,2,2,2,18,1
1,17,2,2,2,3,2,2,3,2,2,2,17,1
1,1,18,2,2,2,2,2,2,2,2,17,1,1
1,1,1,17,17,2,2,2,2,17,17,1,1,1
1,1,1,1,1,17,17,17,17,1,1,1,1,1
endlayer

layer
1,1,1,1,1,1,1,1,1,1,1,1,1,1
1,1,1,1,1,18,18,18,18,1,1,1,1,1
1,1,1,18,18,18,0,0,17,17,17,1,1,1
1,1,17,17,0,6,0,0,6,0,17,17,1,1
1,1,17,0,0,0,0,0,0,0,0,17,1,1
1,17,17,6,0,0,0,0,0,0,6,17,17,1
1,17,0,0,0,0,0,0,0,0,0,0,17,1
1,17,0,0,0,0,0,0,0,0,0,0,18,1
1,17,17,6,0,0,0,0,0,0,6,17,18,1
1,1,18,0,0,0,0,0,0,0,19,18,1,1
1,1,18,17,0,6,0,0,6,0,17,17,1,1
1,1,1,18,17,17,0,0,17,17,17,1,1,1
1,1,1,1,1,17,18,18,18,1,1,1,1,1
1,1,1,1,1,1,1,1,1,1,1,1,1,1
endlayer

layer
1,1,1,1,1,1,1,1,1,1,1,1,1,1
1,1,1,1,1,1,1,1,1,1,1,1,1,1
1,1,1,1,1,1,1,1,1,1,1,1,1,1
1,1,1,1,0,6,0,0,6,0,1,1,1,1
1,1,1,0,0,0,0,0,0,0,0,1,1,1
1,1,1,6,0,0,0,0,0,0,6,1,1,1
1,1,1,0,0,0,0,0,0,0,0,1,1,1
1,1,1,0,0,0,0,0,0,0,0,1,1,1
1,1,1,6,0,0,0,0,0,0,6,1,1,1
1,1,1,0,0,0,0,0,0,0,0,1,1,1
1,1,1,1,0,6,0,0,6,0,1,1,1,1
1,1,1,1,1,1,1,1,1,1,1,1,1,1
1,1,1,1,1,1,1,1,1,1,1,1,1,1
1,1,1,1,1,1,1,1,1,1,1,1,1,1
endlayer

layer
1,1,1,1,1,1,1,1,1,1,1,1,1,1
1,1,1,1,1,1,1,1,1,1,1,1,1,1
1,1,1,1,1,1,1,1,1,1,1,1,1,1
1,1,1,1,0,6,0,0,6,0,1,1,1,1
1,1,1,0,0,0,0,0,0,0,0,1,1,1
1,1,1,6,0,0,0,0,0,0,6,1,1,1
1,1,1,0,0,0,0,0,0,0,0,1,1,1
1,1,1,0,0,0,0,0,0,0,0,1,1,1
1,1,1,16,0,0,0,0,0,0,6,1,1,1
1,1,1,0,0,0,0,0,0,0,0,1,1,1
1,1,1,1,0,6,0,0,6,0,1,1,1,1
1,1,1,1,1,1,1,1,1,1,1,1,1,1
1,1,1,1,1,1,1,1,1,1,1,1,1,1
1,1,1,1,1,1,1,1,1,1,1,1,1,1
endlayer

layer
1,1,1,1,1,1,1,1,1,1,1,1,1,1
1,1,1,1,1,1,1,1,1,1,1,1,1,1
1,1,1,1,1,1,1,1,1,1,1,1,1,1
1,1,1,1,0,6,0,0,6,0,1,1,1,1
1,1,1,0,0,0,0,0,0,0,0,1,1,1
1,1,1,6,0,0,0,0,0,0,6,1,1,1
1,1,1,0,0,0,0,0,0,0,0,1,1,1
1,1,1,0,0,0,0,0,0,0,0,1,1,1
1,1,1,6,0,0,0,0,0,0,6,1,1,1
1,1,1,0,0,0,0,0,0,0,0,1,1,1
1,1,1,1,0,6,0,0,6,0,1,1,1,1
1,1,1,1,1,1,1,1,1,1,1,1,1,1
1,1,1,1,1,1,1,1,1,1,1,1,1,1
1,1,1,1,1,1,1,1,1,1,1,1,1,1
endlayer

layer
1,1,1,1,1,1,1,1,1,1,1,1,1,1
1,1,1,1,1,1,1,1,1,1,1,1,1,1
1,1,1,1,1,17,17,17,17,1,1,1,1,1
1,1,1,1,17,2,2,2,2,17,1,1,1,1
1,1,1,17,2,2,17,17,2,2,17,1,1,1
1,1,17,2,2,17,0,0,17,2,2,17,1,1
1,1,17,2,17,0,0,0,0,17,2,17,1,1
1,1,17,2,17,0,0,0,0,17,2,17,1,1
1,1,17,2,2,17,0,0,17,2,2,17,1,1
1,1,1,17,2,2,17,17,2,2,17,1,1,1
1,1,1,1,17,2,2,2,2,17,1,1,1,1
1,1,1,1,1,17,18,18,18,1,1,1,1,1
1,1,1,1,1,1,1,1,1,1,1,1,1,1
1,1,1,1,1,1,1,1,1,1,1,1,1,1
endlayer

layer
1,1,1,1,1,1,1,1,1,1,1,1,1,1
1,1,1,1,1,1,1,1,1,1,1,1,1,1
1,1,1,1,1,1,1,1,1,1,1,1,1,1
1,1,1,1,1,17,17,17,17,1,1,1,1,1
1,1,1,1,17,17,17,17,17,17,1,1,1,1
1,1,1,17,17,17,17,17,17,17,17,1,1,1
1,1,1,17,17,17,17,17,17,17,17,1,1,1
1,1,1,17,17,17,17,17,17,17,17,1,1,1
1,1,1,17,18,17,17,17,17,18,17,1,1,1
1,1,1,1,18,18,17,17,18,18,1,1,1,1
1,1,1,1,1,18,18,18,18,1,1,1,1,1
1,1,1,1,1,1,1,1,1,1,1,1,1,1
1,1,1,1,1,1,1,1,1,1,1,1,1,1
1,1,1,1,1,1,1,1,1,1,1,1,1,1
endlayer

