
# Created by Ruins mod version 17.1 Ingame Parser
# authoring Player: ST753M

weight=1
embed_into_distance=3
acceptable_target_blocks=dirt,grass,podzol,stone
unacceptable_target_blocks=flowing_water,water,flowing_lava,lava
dimensions=8,11,14
allowable_overhang=3
max_leveling=0
leveling_buffer=0
preserve_water=0
preserve_lava=0

biomesToSpawnIn=bamboo_forest

=0,100,preserveBlock
rule1=0,100,biomesoplenty:bamboo_thatching-0
rule2=0,100,biomesoplenty:planks_0-9
rule3=0,100,biomesoplenty:wood_slab_1-1,biomesoplenty:willow_stairs-3,biomesoplenty:willow_stairs-1,biomesoplenty:willow_stairs-0,biomesoplenty:willow_stairs-2
rule4=0,10,ChestGenHook:chests/jungle_temple:5-3
rule5=0,30,ChestGenHook:chests/jungle_temple:1-5
rule6=0,100,ChestGenHook:chests/spawn_bonus_chest:3-4

layer
0,1,1,1,1,1,1,1,1,1,1,1,1,0
1,2,2,2,2,2,2,2,2,2,2,2,2,1
1,2,2,2,2,2,2,2,2,2,2,2,2,1
1,2,2,2,2,2,2,2,2,2,2,2,2,1
1,2,2,2,2,2,3,3,2,2,2,2,2,1
1,2,2,2,2,2,3,3,2,2,2,2,2,1
1,2,2,2,2,2,3,2,2,2,2,2,2,1
1,2,2,2,2,2,2,2,2,2,2,2,2,1
0,1,1,1,1,2,2,2,2,1,1,1,1,0
0,0,0,0,1,2,2,2,2,1,0,0,0,0
0,0,0,0,0,1,1,1,1,0,0,0,0,0
endlayer

layer
1,1,1,1,1,1,1,1,1,1,1,1,1,1
1,2,2,2,3,2,2,2,3,3,2,2,2,1
1,2,2,3,3,3,2,3,3,3,3,2,2,1
1,2,3,3,3,3,3,0,3,3,3,3,2,1
1,3,3,3,3,0,0,0,0,3,3,3,3,1
1,3,3,2,3,0,0,0,0,3,3,3,2,1
1,3,2,2,2,3,0,0,3,3,3,2,2,1
1,2,2,2,2,2,0,3,3,2,2,2,2,1
1,1,1,1,1,2,3,3,2,1,1,1,1,1
0,0,0,0,1,2,2,2,2,1,0,0,0,0
0,0,0,0,1,1,1,1,1,1,0,0,0,0
endlayer

layer
1,1,1,1,1,1,1,1,0,0,1,1,1,1
1,5,0,0,0,0,3,0,0,0,3,0,4,1
1,1,0,0,0,0,0,0,0,0,0,0,3,1
1,0,0,0,0,0,0,0,0,0,0,0,0,1
1,0,0,0,0,0,0,0,0,0,0,0,0,1
0,0,0,0,0,0,0,0,0,0,0,0,3,0
0,0,0,1,0,0,0,0,0,0,0,3,3,1
1,0,3,3,1,0,0,0,0,3,1,1,1,1
1,1,1,1,1,3,0,0,0,1,1,1,1,1
0,0,0,0,1,3,3,0,6,1,0,0,0,0
0,0,0,0,1,1,0,1,1,1,0,0,0,0
endlayer

layer
1,1,1,1,1,1,0,1,0,1,1,1,1,1
1,0,0,0,0,0,0,0,0,0,0,0,0,1
1,0,0,0,0,0,0,0,0,0,0,0,0,1
1,0,0,0,0,0,0,0,0,0,0,0,0,1
1,0,0,0,0,0,0,0,0,0,0,0,0,0
0,0,0,0,0,0,0,0,0,0,0,0,0,0
0,0,0,0,0,0,0,0,0,0,0,0,0,1
1,0,0,0,1,0,0,0,0,0,0,1,0,1
1,1,1,1,1,0,0,0,0,1,1,1,1,1
0,0,0,0,1,0,0,0,0,1,0,0,0,0
0,0,0,0,1,1,0,0,1,1,0,0,0,0
endlayer

layer
1,1,1,1,1,1,0,1,1,1,1,1,1,1
1,0,0,0,0,0,0,0,0,0,0,0,0,1
1,0,0,0,0,0,0,0,0,0,0,0,0,1
1,0,0,0,0,0,0,0,0,0,0,0,0,0
1,0,0,0,0,0,0,0,0,0,0,0,0,0
0,0,0,0,0,0,0,0,0,0,0,0,0,1
1,0,0,0,0,0,0,0,0,0,0,0,0,1
1,0,0,0,0,0,0,0,0,0,0,0,0,1
1,1,1,1,1,0,0,0,0,1,1,1,1,1
0,0,0,0,1,1,0,0,0,1,0,0,0,0
0,0,0,0,0,1,1,0,1,1,0,0,0,0
endlayer

layer
1,0,1,0,1,1,0,1,1,0,1,1,0,0
0,0,0,0,0,0,0,0,0,0,0,0,0,1
1,0,0,0,0,0,0,0,0,0,0,0,0,1
0,0,0,0,0,0,0,0,0,0,0,0,0,1
1,0,0,0,0,0,0,0,0,0,0,0,0,0
1,0,0,0,0,0,0,0,0,0,0,0,0,1
1,0,0,0,0,0,0,0,0,0,0,0,0,1
1,0,0,0,0,0,0,0,0,0,0,0,0,0
0,1,0,0,1,0,0,0,0,0,1,0,1,0
0,0,0,0,1,0,0,0,0,1,0,0,0,0
0,0,0,0,0,1,1,1,1,0,0,0,0,0
endlayer

layer
1,0,0,0,0,1,1,1,0,0,0,0,0,0
0,0,0,0,0,0,0,0,0,0,0,0,0,0
1,0,0,0,0,0,0,0,0,0,0,0,0,0
0,0,0,0,0,0,0,0,0,0,0,0,0,1
1,0,0,0,0,0,0,0,0,0,0,0,0,1
1,0,0,0,0,0,0,0,0,0,0,0,0,1
0,0,0,0,0,0,0,0,0,0,0,0,0,0
0,0,0,0,0,0,0,0,0,0,0,0,0,0
0,0,0,0,0,0,0,0,0,0,0,0,1,0
0,0,0,0,1,0,0,0,0,1,0,0,0,0
0,0,0,0,1,1,0,0,1,0,0,0,0,0
endlayer

layer
0,0,0,0,0,1,0,0,0,0,0,0,0,0
0,0,0,0,0,0,0,0,0,0,0,0,0,0
0,0,0,0,0,0,0,0,0,0,0,0,0,0
0,0,0,0,0,0,0,0,0,0,0,0,0,0
1,0,0,0,0,0,0,0,0,0,0,0,0,0
0,0,0,0,0,0,0,0,0,0,0,0,0,1
0,0,0,0,0,0,0,0,0,0,0,0,0,0
0,0,0,0,0,0,0,0,0,0,0,0,0,0
0,0,0,0,0,0,0,0,0,0,0,0,0,0
0,0,0,0,1,0,0,0,0,1,0,0,0,0
0,0,0,0,0,0,0,0,0,0,0,0,0,0
endlayer

