
# Created by Ruins mod version 17.1 Ingame Parser
# authoring Player: ST753M

weight=1
embed_into_distance=3
acceptable_target_blocks=podzol,dirt,grass
unacceptable_target_blocks=flowing_water,water,flowing_lava,lava
dimensions=11,12,9
allowable_overhang=3
max_leveling=0
leveling_buffer=0
preserve_water=0
preserve_lava=0

biomesToSpawnIn=bamboo_forest

=0,100,air
rule1=0,100,preserveBlock
rule2=0,100,minecraft:log-0
rule3=0,100,minecraft:log-8
rule4=0,100,minecraft:log-4
rule5=0,100,minecraft:dirt-2
rule6=0,100,biomesoplenty:bamboo_thatching-0
rule7=0,100,ChestGenHook:chests/spawn_bonus_chest:4-5,air
rule8=0,100,minecraft:crafting_table-0
rule9=0,100,biomesoplenty:willow_door_block-1
rule10=0,100,minecraft:spruce_stairs-3
rule11=0,100,biomesoplenty:bamboo-1
rule12=0,100,minecraft:spruce_stairs-2
rule13=0,100,biomesoplenty:willow_door_block-9
rule14=0,100,biomesoplenty:willow_door_block-8
rule15=0,100,minecraft:carpet-13
rule16=0,100,biomesoplenty:leaves_0-14
rule17=0,100,biomesoplenty:leaves_0-6

layer
1,1,1,1,1,1,1,1,1
1,2,1,1,2,1,1,2,1
1,1,1,1,1,1,1,1,1
1,1,1,1,1,1,1,1,1
1,2,1,1,1,1,1,2,1
1,1,1,1,1,1,1,1,1
1,1,1,1,1,1,1,1,1
1,2,1,1,1,1,1,2,1
1,1,1,1,1,1,1,1,1
1,1,1,1,1,1,1,1,1
1,2,1,1,2,1,1,2,1
1,1,1,1,1,1,1,1,1
endlayer

layer
1,1,1,1,1,1,1,1,1
1,2,1,1,2,1,1,2,1
1,1,1,1,1,1,1,1,1
1,1,1,1,1,1,1,1,1
1,2,1,1,1,1,1,2,1
1,1,1,1,1,1,1,1,1
1,1,1,1,1,1,1,1,1
1,2,1,1,1,1,1,2,1
1,1,1,1,1,1,1,1,1
1,1,1,1,1,1,1,1,1
1,2,1,1,2,1,1,2,1
1,1,1,1,1,1,1,1,1
endlayer

layer
1,1,1,1,1,1,1,1,1
1,2,3,3,2,3,3,2,1
1,4,5,5,5,5,5,4,1
1,4,5,5,5,5,5,4,1
1,2,5,5,5,5,5,2,1
1,4,5,5,5,5,5,4,1
1,4,5,5,5,5,5,4,1
1,2,5,5,5,5,5,2,1
1,4,5,5,5,5,5,4,1
1,4,5,5,5,5,5,4,1
1,2,3,3,2,3,3,2,1
1,1,1,1,1,1,1,1,1
endlayer

layer
1,1,1,1,1,1,1,1,1
1,2,6,6,6,6,6,2,1
1,6,0,0,7,0,0,6,1
1,6,0,0,0,0,8,6,1
1,6,0,0,0,0,0,6,1
1,9,0,0,0,0,0,6,1
1,9,0,0,0,0,0,6,1
1,6,0,0,0,0,0,6,1
1,6,0,12,11,10,0,6,1
1,6,0,0,0,0,0,6,1
1,2,6,6,6,6,6,2,1
1,1,1,1,1,1,1,1,1
endlayer

layer
1,1,1,1,1,1,1,1,1
1,2,6,6,6,6,6,2,1
1,6,0,0,0,0,0,6,1
1,6,0,0,0,0,0,6,1
1,6,0,0,0,0,0,6,1
1,13,0,0,0,0,0,6,1
1,14,0,0,0,0,0,6,1
1,6,0,0,0,0,0,6,1
1,6,0,0,15,0,0,6,1
1,6,0,0,0,0,0,6,1
1,2,6,6,6,6,6,2,1
1,1,1,1,1,1,1,1,1
endlayer

layer
1,1,1,1,1,1,1,1,1
1,2,0,0,6,0,0,2,1
1,0,0,0,0,0,0,0,1
1,0,0,0,0,0,0,0,1
1,6,0,0,0,0,0,6,1
1,6,0,0,0,0,0,0,1
1,6,0,0,0,0,0,0,1
1,6,0,0,0,0,0,6,1
1,0,0,0,0,0,0,0,1
1,0,0,0,0,0,0,0,1
1,2,0,0,6,0,0,2,1
1,1,1,1,1,1,1,1,1
endlayer

layer
1,17,1,1,1,1,1,16,1
17,2,0,0,6,0,0,2,17
1,0,0,0,0,0,0,0,1
1,0,0,0,0,0,0,0,1
1,6,0,0,0,0,0,6,1
1,0,0,0,0,0,0,0,1
1,0,0,0,0,0,0,0,1
1,6,0,0,0,0,0,6,1
1,0,0,0,0,0,0,0,1
1,0,0,0,0,0,0,0,1
17,2,0,0,6,0,0,2,17
1,17,1,1,1,1,1,17,1
endlayer

layer
17,17,17,1,1,1,17,16,16
17,2,6,6,6,6,6,2,17
17,6,0,0,0,0,0,6,17
1,6,0,0,0,0,0,6,1
1,6,0,0,0,0,0,6,1
1,0,0,0,0,0,0,6,1
1,0,0,0,0,0,0,6,1
1,6,0,0,0,0,0,6,1
1,6,0,0,0,0,0,6,1
17,6,0,0,0,0,0,6,17
17,2,6,6,6,6,6,2,17
17,17,17,1,1,1,17,17,17
endlayer

layer
17,17,17,17,17,17,17,17,16
17,2,6,6,6,6,6,2,16
17,6,17,17,17,17,17,6,17
17,6,17,17,0,17,17,6,17
17,6,17,0,0,17,17,6,17
17,6,17,0,0,0,17,6,17
17,6,17,0,0,0,17,6,17
17,6,17,17,0,0,17,6,17
17,6,17,17,0,17,17,6,17
16,6,17,17,17,17,17,6,17
16,2,6,6,6,6,6,2,16
16,16,17,17,17,17,16,16,16
endlayer

layer
1,1,17,17,17,17,17,1,1
1,17,17,17,17,17,17,17,1
1,17,17,17,17,17,17,17,1
17,17,17,17,17,17,17,17,17
17,17,17,17,17,17,17,17,17
17,17,17,17,17,17,17,17,17
17,17,17,17,17,16,16,16,17
17,17,17,17,17,16,16,16,16
17,17,17,17,17,16,16,16,16
1,17,17,17,17,16,17,16,1
1,16,17,17,17,16,16,16,1
1,1,17,17,17,17,17,1,1
endlayer

layer
1,1,1,1,1,1,1,1,1
1,1,1,1,1,1,1,1,1
1,1,1,17,17,17,1,1,1
1,1,17,17,17,17,17,1,1
1,1,17,17,17,17,17,1,1
1,1,17,17,17,17,17,1,1
1,1,17,17,17,17,17,1,1
1,1,17,17,17,17,17,1,1
1,1,17,17,17,17,17,1,1
1,1,1,17,17,17,1,1,1
1,1,1,1,1,1,1,1,1
1,1,1,1,1,1,1,1,1
endlayer

