
# Created by Ruins mod version 16.5 Ingame Parser
# authoring Player: ST753M

weight=1
uniqueMinDistance=2000
spawnMinDistance=500
embed_into_distance=-50
acceptable_target_blocks=
unacceptable_target_blocks=cloud
dimensions=21,31,31
allowable_overhang=9999
max_leveling=0
leveling_buffer=0
preserve_water=0
preserve_lava=0
preventRotation=1

biomesToSpawnIn=extreme_hills_with_trees,mutated_extreme_hills_with_trees

rule1=0,50,minecraft:stone-5,minecraft:stained_glass-7,minecraft:iron_ore-0,minecraft:stone-0,minecraft:stained_glass-15,minecraft:glowstone-0,minecraft:emerald_ore-0,minecraft:monster_egg-0,minecraft:stone-0,minecraft:monster_egg-0,minecraft:stone-0,minecraft:monster_egg-0,minecraft:stone-0,minecraft:monster_egg-0,minecraft:stone-0,minecraft:monster_egg-0,minecraft:stone-0,minecraft:monster_egg-0,minecraft:stone-0,minecraft:monster_egg-0,minecraft:stone-0,minecraft:monster_egg-0,minecraft:stone-0,minecraft:monster_egg-0,minecraft:stone-0,minecraft:monster_egg-0,minecraft:stone-0
rule2=0,100,minecraft:stone-0,minecraft:monster_egg-0
rule3=0,100,IInventory;minecraft:dispenser;minecraft:spawn_egg#{EntityTag:{id:"minecraft:villager"}}#0#4-1
rule4=0,100,minecraft:stonebrick-0
rule5=0,100,minecraft:spruce_door-2
rule6=0,100,minecraft:dirt-0
rule7=0,100,minecraft:grass-0
rule8=0,100,minecraft:redstone_wire-0
rule9=0,100,minecraft:unlit_redstone_torch-2
rule10=0,80,ChestGenHook:chests/simple_dungeon:4-3
rule11=0,100,minecraft:redstone_wire-15
rule12=1,100,minecraft:redstone_torch-5
rule13=0,100,air
rule14=0,100,minecraft:spruce_door-8
rule15=0,100,minecraft:tallgrass-1
rule16=0,70,MobSpawner:Skeleton
rule17=0,100,minecraft:sand-0
rule18=0,100,minecraft:water-0
rule19=0,100,IInventory;minecraft:dispenser;minecraft:spawn_egg#{EntityTag:{id:"minecraft:cow"}}#0#4-1
rule20=0,100,minecraft:grass_path-0
rule21=0,100,IInventory;minecraft:dispenser;minecraft:spawn_egg#{EntityTag:{id:"minecraft:sheep"}}#0#4-1
rule22=0,100,minecraft:planks-1
rule23=0,100,minecraft:glass-0
rule24=0,100,minecraft:log-0
rule25=0,100,minecraft:fence-0
rule26=0,100,minecraft:leaves-12
rule27=0,100,minecraft:spruce_stairs-3
rule28=0,100,minecraft:fence_gate-0
rule29=0,100,minecraft:spruce_stairs-2
rule30=0,100,minecraft:sapling-0
rule31=0,100,minecraft:spruce_stairs-0
rule32=0,100,minecraft:log-4
rule33=0,100,minecraft:spruce_stairs-7
rule34=0,100,minecraft:birch_stairs-0
rule35=0,100,minecraft:planks-0
rule36=0,100,minecraft:spruce_door-7
rule37=0,100,minecraft:birch_stairs-7
rule38=0,100,minecraft:cauldron-0
rule39=0,100,minecraft:crafting_table-0
rule40=0,100,minecraft:spruce_stairs-1
rule41=0,100,minecraft:anvil-3
rule42=0,100,minecraft:spruce_stairs-6
rule43=0,100,minecraft:log-8
rule44=1,100,minecraft:torch-5
rule45=0,100,minecraft:furnace-3
rule46=0,100,IInventory;minecraft:hopper;minecraft:carpet#1#7#0-0
rule47=0,100,minecraft:spruce_door-1
rule48=0,100,minecraft:spruce_door-0
rule49=0,100,minecraft:carpet-0
^0,100,minecraft:carpet-1
^0,100,minecraft:carpet-2
^0,100,minecraft:carpet-3
^0,100,minecraft:carpet-4
^0,100,minecraft:carpet-5
^0,100,minecraft:carpet-6
^0,100,minecraft:carpet-7
^0,100,minecraft:carpet-8
^0,100,minecraft:carpet-9
^0,100,minecraft:carpet-10
^0,100,minecraft:carpet-11
^0,100,minecraft:carpet-12
^0,100,minecraft:carpet-13
^0,100,minecraft:carpet-14
^0,100,minecraft:carpet-15
rule50=0,50,ChestGenHook:chests/village_blacksmith:5-3
rule51=0,100,minecraft:birch_stairs-1
rule52=0,100,minecraft:bed-3
rule53=0,100,minecraft:birch_stairs-2
rule54=0,100,minecraft:bed-11
rule55=0,100,minecraft:birch_stairs-5
rule56=0,100,minecraft:carpet-0
^0,100,minecraft:carpet-1
^0,100,minecraft:carpet-2
^0,100,minecraft:carpet-3
^0,100,minecraft:carpet-4
^0,100,minecraft:carpet-5
^0,100,minecraft:carpet-6
^0,100,minecraft:carpet-7
^0,100,minecraft:carpet-8
^0,100,minecraft:carpet-9
^0,100,minecraft:carpet-10
^0,100,minecraft:carpet-11
^0,100,minecraft:carpet-12
^0,100,minecraft:carpet-13
^0,100,minecraft:carpet-14
^0,100,minecraft:carpet-15
rule57=0,100,minecraft:flower_pot-0
rule58=0,100,minecraft:spruce_door-3
rule59=0,100,minecraft:brewing_stand-0
rule60=0,100,minecraft:spruce_door-9
rule61=0,100,minecraft:spruce_stairs-5
rule62=0,100,minecraft:lever-11
rule63=0,100,minecraft:sapling-8-addbonemeal
rule64=2,100,minecraft:torch-3
rule65=2,100,minecraft:torch-4
rule66=0,100,minecraft:wooden_slab-1
rule67=2,100,minecraft:torch-1
rule68=0,100,minecraft:spruce_stairs-4
rule69=0,100,minecraft:bookshelf-0
rule70=0,100,minecraft:ladder-2
rule71=0,100,minecraft:trapdoor-14
rule72=0,100,minecraft:trapdoor-12
rule73=0,100,minecraft:trapdoor-13
rule74=0,100,minecraft:trapdoor-15
rule75=0,100,minecraft:jukebox-0
rule76=0,100,minecraft:bed-9
rule77=0,100,minecraft:bed-1
rule78=0,100,minecraft:wooden_pressure_plate-0
rule79=0,100,minecraft:farmland-7
rule80=0,100,minecraft:hay_block-0
rule81=0,100,minecraft:potatoes-7
^0,100,minecraft:carrots-7
rule82^0,100,minecraft:potatoes-5
^0,100,minecraft:carrots-5
rule83^0,100,minecraft:potatoes-6
^0,100,minecraft:carrots-6
rule84^0,100,minecraft:potatoes-3
^0,100,minecraft:carrots-3

layer
0,0,0,0,0,0,0,0,0,0,0,0,0,0,0,0,0,0,0,0,0,0,0,0,0,0,0,0,0,0,0
0,0,0,0,0,0,0,0,0,0,0,0,0,0,0,0,0,0,0,0,0,0,0,0,0,0,0,0,0,0,0
0,0,0,0,0,0,0,0,0,0,0,0,0,0,0,1,0,0,0,0,0,0,0,0,0,0,0,0,0,0,0
0,0,0,0,0,0,0,0,0,0,0,0,0,0,0,0,0,0,0,0,0,0,0,0,0,0,0,0,0,0,0
0,0,0,0,0,0,0,0,0,0,0,0,0,0,0,0,0,0,0,0,0,0,0,0,0,0,0,0,0,0,0
0,0,0,0,0,0,0,0,0,0,0,0,0,0,0,0,0,0,0,0,0,0,0,0,0,0,0,0,0,0,0
0,0,0,0,0,0,0,0,0,0,0,0,0,0,0,0,0,0,0,0,0,0,0,0,0,0,0,0,0,0,0
0,0,0,0,0,0,0,0,0,0,0,0,0,0,1,0,0,0,0,0,0,0,0,0,0,0,0,0,0,0,0
0,0,0,0,0,0,0,0,0,0,0,0,0,0,0,0,0,0,0,0,0,0,0,0,0,0,0,0,0,0,0
0,0,0,0,0,0,0,0,0,0,0,0,0,0,0,0,0,0,0,0,0,0,0,0,0,0,0,0,0,0,0
0,0,0,0,0,0,0,0,0,0,0,0,0,0,0,0,0,0,0,0,0,1,0,0,0,0,0,0,0,0,0
0,0,0,0,0,0,0,0,1,0,0,0,0,0,1,0,0,0,0,0,0,0,0,0,0,0,0,0,0,0,0
0,0,0,0,0,0,0,0,0,0,0,1,0,0,0,0,0,0,0,0,0,0,0,0,0,0,0,0,0,0,0
0,0,0,0,0,0,0,0,0,0,1,0,0,0,0,0,0,0,2,0,0,0,0,0,0,0,0,0,0,0,0
0,0,0,0,0,0,0,0,0,0,0,0,0,0,1,0,0,0,0,0,0,0,0,0,0,0,0,0,0,0,0
0,0,0,0,0,0,0,0,0,0,0,0,0,0,0,0,0,0,0,0,0,0,0,0,0,0,0,0,0,0,0
0,0,0,0,0,0,1,0,0,0,0,0,0,0,0,0,0,0,0,0,0,0,0,0,0,0,0,0,0,0,0
0,0,0,0,0,0,0,0,0,0,0,2,0,0,0,0,0,0,0,0,0,0,0,0,0,0,0,0,0,0,0
0,0,0,0,0,0,0,0,0,0,0,0,0,0,1,0,0,0,0,0,2,0,0,0,0,0,0,0,0,0,0
0,0,0,0,0,0,0,0,0,0,0,0,0,0,0,2,0,0,0,0,0,0,0,0,0,0,0,0,0,0,0
0,0,0,0,0,0,0,0,0,0,0,0,0,0,0,0,0,0,0,0,0,0,0,0,0,0,0,0,0,0,0
0,0,0,0,0,0,0,0,0,0,0,0,0,0,0,0,0,0,0,0,0,0,1,0,0,0,0,0,0,0,0
0,0,0,0,0,1,0,0,0,0,0,0,0,0,0,0,0,0,0,1,0,0,0,0,0,0,0,0,0,0,0
0,0,0,0,0,0,0,0,0,0,0,0,0,0,0,0,0,0,0,0,0,0,0,0,0,0,0,0,0,0,0
0,0,0,0,0,0,0,0,0,0,0,0,0,0,0,0,0,0,0,0,0,0,0,0,0,0,0,0,0,0,0
0,0,0,0,0,0,0,0,0,0,0,0,0,0,0,0,0,0,0,0,0,0,0,0,0,0,0,0,0,0,0
0,0,0,0,0,0,0,0,0,0,0,0,0,0,0,0,2,0,0,0,0,0,0,0,0,0,0,0,0,0,0
0,0,0,0,0,0,0,0,0,0,0,0,0,0,0,0,0,0,0,0,0,0,0,0,0,0,0,0,0,0,0
0,0,0,0,0,0,0,0,0,0,0,0,0,0,0,0,0,0,0,0,0,0,0,0,0,0,0,0,0,0,0
0,0,0,0,0,0,0,0,0,0,0,0,0,0,0,0,0,0,0,0,0,0,0,0,0,0,0,0,0,0,0
0,0,0,0,0,0,0,0,0,0,0,0,0,0,0,0,0,0,0,0,0,0,0,0,0,0,0,0,0,0,0
endlayer

layer
0,0,0,0,0,0,0,0,0,0,0,0,0,0,0,0,0,0,0,0,0,0,0,0,0,0,0,0,0,0,0
0,0,0,0,0,0,0,0,0,0,0,0,0,0,0,0,0,0,0,0,0,0,0,0,0,0,0,0,0,0,0
0,0,0,0,0,0,0,0,0,0,0,0,0,0,0,2,0,0,0,0,0,0,0,0,0,0,0,0,0,0,0
0,0,0,0,0,0,0,0,0,0,0,0,0,0,0,0,0,0,0,0,0,0,0,0,0,0,0,0,0,0,0
0,0,0,0,0,0,0,0,0,0,0,0,0,0,0,0,0,0,0,0,0,0,0,0,0,0,0,0,0,0,0
0,0,0,0,0,0,0,0,0,0,0,0,0,0,0,0,0,0,0,0,0,0,0,0,0,0,0,0,0,0,0
0,0,0,0,0,0,0,0,0,0,0,0,0,0,0,0,0,0,0,0,0,0,0,0,0,0,0,0,0,0,0
0,0,0,0,0,0,0,0,0,0,0,0,0,0,2,0,0,0,0,0,0,0,0,0,0,0,0,0,0,0,0
0,0,0,0,0,0,0,0,0,0,0,0,0,0,0,0,0,0,0,0,0,0,0,0,0,1,0,0,0,0,0
0,0,0,0,0,0,0,0,0,0,0,0,0,0,0,0,0,0,0,0,0,0,0,0,0,0,0,0,0,0,0
0,0,0,0,0,0,0,0,0,0,0,0,0,1,0,0,1,0,0,0,0,2,0,0,0,0,0,0,0,0,0
0,0,0,0,0,0,0,0,2,0,0,0,0,0,2,0,0,0,0,1,0,0,0,0,0,0,0,0,0,0,0
0,0,0,0,1,0,0,0,0,0,0,2,0,0,0,0,0,0,0,0,0,0,0,0,0,0,0,0,0,0,0
0,0,0,0,0,0,0,0,0,0,2,0,0,0,0,0,0,0,2,1,0,0,0,0,0,0,0,0,0,0,0
0,0,0,0,0,0,0,0,0,0,0,0,1,0,2,0,0,0,1,0,0,0,0,0,0,0,0,0,0,0,0
0,0,0,0,0,0,0,0,0,0,0,0,0,0,1,0,0,0,0,0,0,0,1,0,0,0,0,0,1,0,0
0,0,0,0,0,0,2,0,0,0,0,0,0,0,0,0,0,0,0,0,0,0,0,0,0,0,0,0,0,0,0
0,0,0,0,0,0,0,0,0,0,0,2,0,0,0,0,0,0,0,0,0,0,0,0,0,0,0,0,0,0,0
0,0,0,0,0,0,0,0,0,0,0,0,0,0,2,0,0,0,0,0,2,0,0,0,0,0,0,0,0,0,0
0,0,0,0,0,0,0,0,2,0,0,0,0,0,0,2,0,0,1,0,0,0,0,0,0,0,0,0,0,0,0
0,0,0,0,0,0,0,0,0,0,0,0,0,1,0,0,0,0,0,0,0,0,0,0,0,0,0,0,0,0,0
0,0,0,0,0,1,0,0,0,0,0,0,0,0,0,0,0,0,0,0,0,0,2,0,0,0,0,0,0,0,0
0,0,0,0,0,2,0,0,0,0,0,0,0,0,0,0,0,0,0,2,0,0,0,0,0,0,0,0,0,0,0
0,0,0,0,0,0,0,0,0,0,0,0,0,0,0,0,0,0,0,0,0,0,0,0,0,0,0,0,0,0,0
0,0,0,0,0,0,0,0,0,0,0,0,0,0,0,0,0,0,0,0,0,0,0,0,0,0,0,0,0,0,0
0,0,0,0,0,0,0,0,0,0,0,1,0,0,0,0,1,0,0,0,0,0,0,0,0,0,0,0,0,0,0
0,0,0,0,0,0,0,0,0,0,0,0,0,0,0,0,2,0,0,0,0,0,0,0,0,0,0,0,0,0,0
0,0,0,0,0,0,0,0,0,0,0,0,0,0,0,0,0,0,0,0,0,0,0,0,0,0,0,0,0,0,0
0,0,0,0,0,0,0,0,0,0,0,0,0,0,0,0,0,0,0,0,0,0,0,0,0,0,0,0,0,0,0
0,0,0,0,0,0,0,0,0,0,0,0,0,0,0,0,0,0,0,0,0,0,0,0,0,0,0,0,0,0,0
0,0,0,0,0,0,0,0,0,0,0,0,0,0,0,0,0,0,0,0,0,0,0,0,0,0,0,0,0,0,0
endlayer

layer
0,0,0,0,0,0,0,0,0,0,0,0,0,0,0,0,0,0,0,0,0,0,0,0,0,0,0,0,0,0,0
0,0,0,0,0,0,0,0,0,0,0,0,0,0,0,0,0,0,0,0,0,0,0,0,0,0,0,0,0,0,0
0,0,0,0,0,0,0,0,0,0,0,0,0,0,0,2,0,0,0,0,0,0,0,0,0,0,0,0,0,0,0
0,0,0,0,0,0,0,0,0,0,0,0,0,0,0,1,0,0,0,0,0,0,0,0,0,0,0,0,0,0,0
0,0,0,0,0,0,0,0,0,0,0,0,0,0,0,0,0,0,0,0,0,0,0,0,0,0,0,0,0,0,0
0,0,0,0,0,0,0,0,0,0,0,0,0,0,0,0,0,0,0,0,0,0,0,0,0,0,0,0,0,0,0
0,0,0,0,0,0,0,0,0,0,0,0,0,0,0,0,0,0,0,0,0,0,1,0,0,0,0,0,0,0,0
0,0,0,0,0,0,0,0,0,0,0,0,0,0,2,1,0,0,0,0,0,0,0,0,0,0,0,0,0,0,0
0,0,0,0,0,0,0,1,0,0,0,1,0,0,0,0,0,0,0,0,0,0,0,0,0,2,0,0,0,0,0
0,0,0,0,0,0,0,0,0,0,0,0,0,0,0,0,1,0,0,0,0,1,0,0,0,0,0,0,0,0,0
0,0,0,0,0,0,0,0,0,0,0,0,0,2,0,0,2,0,0,0,0,2,0,0,0,0,0,0,0,0,0
0,0,0,0,0,0,0,0,2,0,0,1,0,0,2,0,0,1,0,2,0,0,0,0,0,0,0,0,0,0,0
0,0,0,0,2,0,0,0,0,0,1,2,0,0,0,0,0,0,0,0,0,0,0,0,0,0,0,0,0,0,0
0,0,0,0,0,0,0,0,0,0,2,0,1,1,0,0,0,0,2,2,0,0,0,0,0,0,0,0,0,0,0
0,0,0,0,0,0,0,0,0,0,0,1,2,1,2,1,1,0,2,1,0,0,1,0,0,0,0,0,0,0,0
0,0,0,0,0,0,0,0,0,0,0,1,1,1,2,0,0,0,0,0,0,0,2,0,0,0,0,0,2,0,0
0,0,0,0,0,0,2,0,0,0,0,0,1,1,0,0,0,0,0,0,0,0,0,0,0,0,1,0,0,0,0
0,0,0,0,0,0,1,0,0,0,0,2,0,0,0,2,0,0,0,0,0,0,0,0,0,0,0,0,0,0,0
0,0,0,0,0,0,0,0,0,0,0,1,0,0,2,0,0,1,0,0,2,0,0,0,0,0,0,0,0,0,0
0,0,0,0,0,0,0,0,2,0,0,1,1,0,0,2,0,0,2,0,0,0,0,0,0,0,0,0,0,0,0
0,0,0,0,0,0,0,0,0,0,0,0,1,2,0,0,0,0,0,0,0,0,0,0,1,0,0,0,0,0,0
0,0,0,0,0,2,0,0,0,1,0,0,0,0,0,0,0,0,0,0,0,0,2,0,0,0,0,0,0,0,0
0,0,0,0,1,2,0,0,0,0,0,0,0,0,0,0,0,0,0,2,0,0,0,0,0,0,0,0,0,0,0
0,0,0,0,0,0,0,0,1,0,0,0,0,0,0,0,0,0,0,0,0,0,0,0,0,0,0,0,0,0,0
0,0,0,0,0,0,0,0,0,0,0,0,0,0,0,0,0,0,0,0,0,0,0,0,0,0,0,0,0,0,0
0,0,0,0,0,0,0,0,0,0,0,2,0,0,0,0,2,0,0,0,0,0,0,1,0,0,0,0,0,0,0
0,0,0,0,0,0,0,0,0,0,0,0,0,0,0,1,2,0,0,0,0,0,0,0,0,0,0,0,0,0,0
0,0,0,0,0,0,0,0,0,0,0,0,0,0,0,0,0,0,0,0,0,0,0,0,0,0,0,0,0,0,0
0,0,0,0,0,0,0,0,0,0,0,0,0,0,0,0,0,0,0,0,0,0,0,0,0,0,0,0,0,0,0
0,0,0,0,0,0,0,0,0,0,0,0,0,0,0,0,0,0,0,0,0,0,0,0,0,0,0,0,0,0,0
0,0,0,0,0,0,0,0,0,0,0,0,0,0,0,0,0,0,0,0,0,0,0,0,0,0,0,0,0,0,0
endlayer

layer
0,0,0,0,0,0,0,0,0,0,0,0,0,0,0,0,0,0,0,0,0,0,0,0,0,0,0,0,0,0,0
0,0,0,0,0,0,0,0,0,0,0,0,0,0,0,0,0,0,0,0,0,0,0,0,0,0,0,0,0,0,0
0,0,0,0,0,0,0,0,0,0,0,0,0,0,1,2,0,0,0,0,0,0,0,0,0,0,0,0,0,0,0
0,0,0,0,0,0,0,0,0,0,0,0,0,0,0,2,0,0,0,0,0,0,0,0,0,0,0,0,0,0,0
0,0,0,0,0,0,0,1,0,0,0,0,0,0,0,0,0,0,0,0,0,0,0,0,0,0,0,0,0,0,0
0,0,0,0,0,0,0,0,0,0,0,1,0,0,0,0,0,0,0,0,0,0,0,0,0,0,0,0,0,0,0
0,0,0,0,0,0,0,0,0,0,0,0,0,0,1,0,0,0,0,0,0,0,2,0,0,0,0,0,0,0,0
0,0,0,0,0,0,0,0,0,0,0,0,0,0,2,2,0,0,0,0,0,0,0,0,0,0,0,0,0,0,0
0,0,0,0,0,0,0,2,0,0,0,2,0,0,0,0,0,0,0,0,0,0,0,0,0,2,0,0,0,0,0
0,0,0,0,0,0,0,0,0,0,0,0,0,1,1,1,2,1,0,0,0,2,0,0,0,0,0,0,0,0,0
0,0,0,0,0,0,0,0,0,0,0,1,1,2,1,1,2,1,1,1,0,2,0,0,0,0,0,0,0,0,0
0,0,0,0,0,0,0,0,2,0,1,2,1,1,2,1,1,2,1,2,0,0,0,0,0,0,0,0,0,0,0
0,0,0,0,2,1,0,0,0,0,2,2,1,1,1,1,1,1,1,1,1,1,0,0,0,0,0,0,0,0,0
0,0,0,0,0,0,0,0,0,1,2,1,2,2,1,1,1,1,2,2,0,0,0,0,0,0,0,0,0,0,0
0,0,0,0,0,0,0,0,0,1,1,2,2,2,2,2,2,1,2,2,0,0,2,0,0,0,0,0,1,0,0
0,0,0,0,0,0,0,0,0,1,1,2,2,2,2,0,0,0,0,0,0,1,2,0,0,0,0,0,2,0,0
0,0,0,0,0,1,2,0,0,1,1,1,2,2,0,0,0,0,0,0,1,1,1,0,0,0,2,0,0,0,0
0,0,0,0,0,0,2,0,0,2,0,2,1,1,1,2,0,1,1,1,1,1,0,0,0,0,0,0,0,0,0
0,0,0,0,0,0,0,0,0,0,0,2,1,1,2,1,1,2,1,1,2,0,0,0,0,0,0,0,0,0,0
0,0,0,1,0,0,0,0,2,0,0,2,2,1,1,2,1,1,2,1,1,0,0,0,0,0,0,0,0,0,0
0,0,0,0,0,0,0,0,0,0,0,1,2,2,1,1,1,1,1,1,0,0,0,0,2,0,0,0,0,0,0
0,0,0,0,0,2,0,0,0,2,0,0,0,1,1,1,1,1,0,0,0,0,2,0,0,0,0,0,0,0,0
0,0,0,0,2,2,1,0,0,0,0,0,0,0,0,0,0,0,0,2,0,0,1,0,0,0,0,0,0,0,0
0,0,0,0,0,0,0,0,2,0,0,0,0,0,0,0,0,0,0,0,0,0,0,0,0,0,0,0,0,0,0
0,0,0,0,0,0,0,0,0,0,0,1,0,0,0,0,0,0,0,0,0,0,0,0,0,0,0,0,0,0,0
0,0,0,0,0,0,0,0,0,0,0,2,0,0,0,1,2,0,0,0,0,0,0,2,0,0,0,0,0,0,0
0,0,0,0,0,0,0,0,0,0,0,0,0,0,0,2,2,1,0,0,0,0,0,0,0,0,0,0,0,0,0
0,0,0,0,0,0,0,0,0,0,0,0,0,0,0,0,0,0,0,0,0,0,0,0,0,0,0,0,0,0,0
0,0,0,0,0,0,0,0,0,0,0,0,0,0,0,0,0,0,0,0,0,0,0,0,0,0,0,0,0,0,0
0,0,0,0,0,0,0,0,0,0,0,0,0,0,0,0,0,0,0,0,0,0,0,0,0,0,0,0,0,0,0
0,0,0,0,0,0,0,0,0,0,0,0,0,0,0,0,0,0,0,0,0,0,0,0,0,0,0,0,0,0,0
endlayer

layer
0,0,0,0,0,0,0,0,0,0,0,0,0,0,0,0,0,0,0,0,0,0,0,0,0,0,0,0,0,0,0
0,0,0,0,0,0,0,0,0,0,0,0,0,0,0,1,0,0,0,0,0,0,0,0,0,0,0,0,0,0,0
0,0,0,0,0,0,0,0,0,0,0,0,0,0,2,2,0,0,0,2,0,0,0,0,0,0,0,0,0,0,0
0,0,0,0,0,0,0,0,0,0,0,0,0,0,0,2,0,0,1,0,0,0,0,0,0,0,0,0,0,0,0
0,0,0,0,0,0,0,2,0,0,0,0,0,0,0,0,0,0,0,0,0,0,0,0,0,0,0,0,0,0,0
0,0,0,0,0,0,0,0,0,0,0,2,0,0,0,0,0,0,0,0,0,0,1,0,0,0,0,0,0,0,0
0,0,0,0,0,0,0,0,0,0,0,0,1,0,2,0,0,0,0,0,0,0,2,0,0,0,0,0,0,0,0
0,0,0,0,0,1,0,0,0,0,1,0,0,1,2,2,1,1,0,0,0,0,0,0,0,0,0,0,0,0,0
0,0,0,0,0,0,0,2,0,0,0,2,1,1,1,1,1,1,1,1,0,0,0,0,0,2,1,0,0,0,0
0,0,0,0,0,0,0,0,0,0,1,1,1,2,2,2,2,2,1,1,1,2,0,0,1,0,0,0,0,0,0
0,0,0,0,0,0,0,0,0,1,1,2,2,2,2,2,2,2,2,2,0,2,2,0,0,0,0,0,0,0,0
0,0,0,0,1,0,0,0,2,1,2,2,2,2,2,2,2,2,2,2,2,0,0,0,0,0,0,0,0,0,0
0,0,0,0,2,2,0,0,1,1,2,2,2,2,2,2,2,2,2,2,2,2,0,0,0,0,0,0,0,0,0
0,0,0,0,1,0,0,1,1,2,2,2,3,3,2,2,2,2,2,2,1,0,1,1,0,0,0,0,0,0,0
0,0,0,0,0,0,0,1,1,2,2,2,3,3,4,4,4,2,2,1,0,1,2,1,0,0,0,0,2,0,0
0,0,0,0,0,0,1,1,1,2,2,2,3,3,4,0,1,0,0,0,1,2,2,1,0,0,0,0,2,0,0
0,0,0,0,0,2,2,2,1,2,2,2,3,3,4,1,0,1,1,1,2,2,2,1,0,1,2,0,0,0,0
0,0,0,0,0,0,2,1,1,2,2,2,2,2,2,2,1,2,2,2,2,2,1,1,0,0,1,0,0,0,0
0,0,0,0,0,0,0,0,1,1,2,2,2,2,2,2,2,2,2,2,2,1,1,0,0,0,0,0,0,0,0
0,0,0,2,0,0,0,0,2,0,2,2,2,2,2,2,2,2,2,2,2,1,1,0,0,0,0,0,0,0,0
0,0,0,0,0,0,0,0,0,0,1,2,2,2,2,2,2,2,2,2,1,1,2,0,2,0,0,0,0,0,0
0,0,0,0,0,2,0,0,0,2,1,1,1,2,2,2,2,2,1,1,1,1,2,1,0,0,0,0,0,0,0
0,0,0,0,2,2,2,0,0,1,0,1,1,1,1,1,1,1,1,2,0,0,2,0,0,0,0,0,0,0,0
0,0,0,0,0,1,0,0,2,0,0,0,0,1,1,1,1,1,0,0,0,0,0,0,0,0,0,0,0,0,0
0,0,0,0,0,0,0,0,0,0,0,2,0,0,0,0,1,0,0,0,0,0,0,0,0,0,0,0,0,0,0
0,0,0,0,0,0,0,0,0,0,0,2,0,0,0,2,2,1,0,0,0,0,0,2,1,0,0,0,0,0,0
0,0,0,0,0,0,0,0,0,0,0,1,0,0,0,2,2,2,0,0,0,0,0,0,0,0,0,0,0,0,0
0,0,0,0,0,0,0,1,0,0,0,0,0,0,0,0,1,0,0,0,0,0,0,0,0,0,0,0,0,0,0
0,0,0,0,0,0,0,0,0,0,0,0,0,0,0,0,0,0,0,0,0,0,0,0,0,0,0,0,0,0,0
0,0,0,0,0,0,0,0,0,0,0,0,0,0,0,0,0,0,0,0,0,0,0,0,0,0,0,0,0,0,0
0,0,0,0,0,0,0,0,0,0,0,0,0,0,0,0,0,0,0,0,0,0,0,0,0,0,0,0,0,0,0
endlayer

layer
0,0,0,0,0,0,0,0,0,0,0,0,0,0,0,0,0,0,0,0,0,0,0,0,0,0,0,0,0,0,0
0,0,0,0,0,0,0,0,0,0,0,0,0,0,0,2,0,0,0,0,0,0,0,0,0,0,0,0,0,0,0
0,0,0,0,0,0,0,0,0,0,0,0,0,0,2,2,1,0,0,2,0,0,0,0,0,0,0,0,0,0,0
0,0,0,0,0,0,0,0,0,0,0,0,0,0,0,2,0,0,2,0,0,0,0,0,0,0,0,0,0,0,0
0,0,0,0,0,0,0,2,0,0,0,0,0,0,0,0,0,0,0,0,1,0,0,0,0,0,0,0,0,0,0
0,0,0,0,0,0,0,1,0,0,0,2,0,0,0,0,0,0,0,0,0,0,2,0,0,0,0,0,0,0,0
0,0,0,0,0,0,0,0,0,0,0,0,2,1,2,1,1,1,1,0,0,0,2,1,0,0,0,0,0,0,0
0,0,0,0,0,2,0,0,0,0,2,1,1,2,2,2,2,2,1,1,1,0,0,0,0,0,0,0,0,0,0
0,0,0,0,0,0,0,2,0,1,1,2,2,2,2,2,2,2,2,2,1,1,0,0,0,2,2,0,0,0,0
0,0,0,0,0,0,0,0,1,1,2,2,2,4,4,4,4,4,2,2,2,2,1,0,2,0,0,0,0,0,0
0,0,0,0,1,0,0,1,1,2,2,4,4,4,4,4,4,4,4,4,2,2,2,1,0,0,0,0,0,0,0
0,0,0,0,2,1,0,1,2,2,4,4,4,4,0,0,0,0,4,4,4,2,1,1,0,0,0,0,0,0,0
0,0,0,1,2,2,1,1,2,2,4,4,4,4,5,4,4,0,0,4,4,1,1,1,1,0,0,0,0,0,0
0,0,0,1,2,1,1,2,2,4,4,4,8,8,0,7,6,4,0,0,0,1,2,2,1,0,0,0,0,0,0
0,0,0,0,1,1,1,2,2,4,4,4,8,8,4,4,4,4,0,0,0,4,2,2,1,0,0,0,2,0,0
0,0,0,0,0,0,2,2,2,4,4,4,8,8,4,0,4,4,0,0,0,4,2,2,1,0,0,1,2,1,0
0,0,0,0,1,2,2,2,2,4,4,4,8,8,4,4,4,0,0,0,0,4,2,2,1,2,2,0,2,0,0
0,0,0,0,0,0,2,2,2,4,4,4,4,9,4,0,0,0,0,0,0,4,2,2,1,0,2,0,0,0,0
0,0,0,0,0,0,1,1,2,2,13,12,11,4,10,0,0,0,0,0,4,2,2,1,1,0,0,0,0,0,0
0,0,0,2,1,0,0,1,2,2,4,4,4,4,10,0,0,0,0,0,4,2,2,1,0,0,0,0,0,0,0
0,0,0,0,0,0,0,1,1,2,2,2,2,2,4,4,4,4,4,4,2,2,2,1,2,1,0,0,0,0,0
0,0,0,0,1,2,1,0,1,2,2,2,2,2,4,4,4,4,2,2,2,2,2,2,1,0,0,0,0,0,0
0,0,0,1,2,2,2,0,0,2,1,2,2,2,2,2,2,2,2,2,1,1,2,0,0,0,0,0,0,0,0
0,0,0,0,0,2,1,0,2,0,1,1,1,2,2,2,2,2,1,1,1,0,0,0,0,0,0,0,0,0,0
0,0,0,0,0,1,0,0,0,0,0,2,1,1,1,1,2,1,1,0,0,0,0,0,0,0,0,0,0,0,0
0,0,0,0,0,0,0,0,0,0,1,2,1,0,1,2,2,2,0,0,0,0,0,2,2,0,0,0,0,0,0
0,0,0,0,0,0,0,0,0,0,0,2,0,0,0,2,2,2,0,0,0,0,0,1,0,0,0,0,0,0,0
0,0,0,0,0,0,0,2,0,0,0,0,0,0,0,1,2,0,0,0,0,0,0,0,0,0,0,0,0,0,0
0,0,0,0,0,0,0,0,0,0,0,0,0,0,0,0,0,0,0,0,0,0,0,0,0,0,0,0,0,0,0
0,0,0,0,0,0,0,0,0,0,0,0,0,0,0,0,0,0,0,0,0,0,0,0,0,0,0,0,0,0,0
0,0,0,0,0,0,0,0,0,0,0,0,0,0,0,0,0,0,0,0,0,0,0,0,0,0,0,0,0,0,0
endlayer

layer
0,0,0,0,0,0,0,0,0,0,0,0,0,0,0,0,0,0,0,0,0,0,0,0,0,0,0,0,0,0,0
0,0,0,0,0,0,0,0,0,0,0,0,0,0,1,2,1,0,0,0,0,0,0,0,0,0,0,0,0,0,0
0,0,0,0,0,0,0,0,0,0,0,0,1,0,2,2,2,0,1,2,0,0,0,0,0,0,0,0,0,0,0
0,0,0,0,0,0,0,0,0,0,0,0,0,0,1,2,1,1,2,0,0,0,0,0,0,0,0,0,0,0,0
0,0,0,0,0,0,0,2,0,0,0,0,0,1,1,1,1,1,1,1,2,0,0,0,0,0,0,0,0,0,0
0,0,0,0,0,0,0,2,0,0,0,2,1,1,1,1,0,1,1,1,0,0,2,0,0,0,0,0,0,0,0
0,0,0,0,0,0,0,0,0,0,1,1,2,2,2,2,2,2,2,1,1,1,2,2,0,0,0,0,0,0,0
0,0,0,0,0,2,0,0,1,1,2,2,2,2,2,2,2,2,2,2,2,1,1,0,0,1,0,0,0,0,0
0,0,0,0,0,0,0,2,1,2,2,2,2,2,2,2,2,2,2,2,2,2,1,1,0,2,2,0,0,0,0
0,0,0,0,0,0,1,1,2,2,2,2,2,4,4,4,4,4,2,2,2,2,2,1,2,0,0,0,0,0,0
0,0,0,1,2,1,1,2,2,8,8,4,4,4,4,4,4,4,4,4,2,2,2,6,1,0,0,0,0,0,0
0,0,1,1,2,2,1,2,4,4,8,4,4,4,0,0,0,0,4,4,4,2,2,2,1,1,0,0,0,0,0
0,0,1,2,2,2,2,2,4,8,8,4,4,4,14,4,4,0,0,4,4,2,2,2,2,1,0,0,0,0,0
0,0,1,2,2,2,2,2,4,4,8,4,0,0,0,15,7,4,0,0,0,4,2,2,2,1,0,0,0,0,0
0,0,1,1,2,2,2,2,4,8,8,4,0,0,4,4,4,4,0,0,0,4,2,2,2,1,0,0,2,1,0
0,0,0,1,1,1,2,2,2,4,8,8,0,0,4,0,4,4,0,0,0,4,2,2,2,1,0,2,2,2,0
0,0,0,0,2,2,2,2,4,8,8,4,0,0,4,4,4,16,0,0,0,4,2,2,2,2,2,1,2,0,0
0,0,0,0,0,1,2,2,2,6,4,4,4,4,4,0,0,0,0,0,0,4,2,2,2,1,2,1,0,0,0
0,0,0,1,0,1,2,2,2,18,17,0,0,4,0,0,0,0,0,0,4,2,2,2,2,1,0,0,0,0,0
0,0,0,2,2,1,1,2,2,2,4,4,4,4,0,0,0,0,0,0,4,2,2,2,1,1,0,0,0,0,0
0,0,0,0,1,1,1,2,2,2,2,2,2,2,4,4,4,4,4,4,2,2,2,2,2,2,0,0,0,0,0
0,0,0,1,2,2,2,1,2,2,2,2,2,2,4,4,4,4,2,2,2,2,2,2,2,0,0,0,0,0,0
0,0,0,2,2,2,2,1,1,2,2,2,2,2,2,2,2,2,2,2,2,2,2,1,0,0,0,0,0,0,0
0,0,0,0,1,2,2,1,2,1,2,2,2,2,2,2,2,2,2,2,2,1,1,0,0,0,0,0,0,0,0
0,0,0,0,0,2,0,0,0,1,1,2,2,2,2,2,2,2,2,1,1,1,0,0,0,0,0,0,0,0,0
0,0,0,0,0,0,0,0,0,0,2,2,2,1,2,2,2,2,1,1,0,0,0,2,2,0,0,0,0,0,0
0,0,0,0,0,0,0,0,0,0,0,2,1,0,1,2,2,2,0,0,0,0,0,2,0,0,0,0,0,0,0
0,0,0,0,0,0,0,2,0,0,0,0,1,0,0,2,2,0,0,0,0,0,0,0,0,0,0,0,0,0,0
0,0,0,0,0,0,0,0,0,0,0,0,0,0,0,0,0,0,0,0,0,0,0,0,0,0,0,0,0,0,0
0,0,0,0,0,0,0,0,0,0,0,0,0,0,0,0,0,0,0,0,0,0,0,0,0,0,0,0,0,0,0
0,0,0,0,0,0,0,0,0,0,0,0,0,0,0,0,0,0,0,0,0,0,0,0,0,0,0,0,0,0,0
endlayer

layer
0,0,0,0,0,0,0,0,0,0,0,0,0,0,1,1,1,1,1,0,0,0,0,0,0,0,0,0,0,0,0
0,0,0,0,0,0,0,0,0,0,0,0,0,1,2,2,2,1,1,1,0,0,0,0,0,0,0,0,0,0,0
0,0,0,0,0,0,0,0,0,1,0,0,2,1,2,2,2,1,2,2,1,0,0,0,0,0,0,0,0,0,0
0,0,0,0,0,0,0,0,0,0,0,0,1,1,2,2,2,2,2,1,1,0,0,0,0,0,0,0,0,0,0
0,0,0,0,0,0,1,2,0,0,0,1,1,2,2,2,2,2,2,2,2,0,0,0,0,0,0,0,0,0,0
0,0,0,0,0,0,0,2,0,1,1,2,2,2,2,2,0,2,2,2,1,1,2,0,0,0,0,0,0,0,0
0,0,0,0,0,0,0,0,1,1,2,7,6,6,6,6,6,6,6,2,2,2,2,2,0,0,0,0,0,0,0
0,0,0,0,0,2,0,1,2,7,7,7,7,6,6,6,6,6,6,6,6,2,2,1,0,2,0,0,0,0,0
0,0,0,0,0,1,1,2,7,7,7,7,7,6,6,6,6,6,6,6,6,6,2,2,1,2,2,0,0,0,0
0,1,1,1,1,1,2,2,7,7,7,7,7,7,7,6,6,6,6,6,6,6,6,6,6,1,0,0,0,0,0
0,1,1,2,2,2,2,6,19,7,7,7,7,7,7,7,7,7,7,7,6,6,6,6,2,1,0,0,0,0,0
0,1,2,2,2,2,2,6,7,7,7,7,7,20,20,20,20,20,20,7,6,6,6,6,2,2,1,0,0,0,0
0,1,2,2,2,2,6,6,19,7,7,7,20,20,7,7,7,7,20,6,6,6,6,6,6,2,1,1,0,0,0
0,1,2,2,2,2,6,6,7,7,7,7,20,7,0,0,15,20,20,7,6,6,6,6,6,2,1,1,1,0,0
0,1,2,2,2,2,6,6,21,7,7,7,20,7,4,4,4,7,20,7,7,6,6,6,6,2,1,1,2,2,0
0,1,1,2,2,2,6,6,7,7,7,7,20,7,4,0,4,7,20,7,7,6,6,6,6,2,1,2,2,2,0
0,1,1,1,2,2,6,6,21,7,7,7,20,7,4,4,4,7,20,7,7,6,6,6,6,2,2,2,2,1,0
0,1,1,1,1,2,6,6,7,7,7,7,20,7,7,7,7,7,20,7,6,6,6,6,6,2,2,2,1,0,0
0,0,1,2,1,2,6,7,20,20,20,20,20,20,7,7,7,20,20,6,6,6,6,6,6,2,1,1,0,0,0
0,0,0,2,2,2,2,7,7,20,7,7,7,20,7,7,7,20,7,6,6,6,6,6,2,2,1,0,0,0,0
0,0,0,1,2,2,2,6,7,20,20,20,20,20,20,20,20,20,20,6,6,6,6,6,2,2,1,0,0,0,0
0,0,1,2,2,2,2,2,7,7,7,7,20,7,7,7,7,7,7,6,6,6,6,2,2,1,0,0,0,0,0
0,0,1,2,2,2,2,2,7,7,7,7,20,6,6,6,6,6,6,6,6,6,2,2,1,0,0,0,0,0,0
0,0,0,1,2,2,2,2,7,7,7,7,6,6,6,6,6,6,6,6,6,2,2,1,0,0,0,0,0,0,0
0,0,0,0,1,2,1,1,1,2,2,2,6,6,6,6,6,6,6,2,2,2,1,0,0,0,0,0,0,0,0
0,0,0,0,0,0,0,0,0,1,2,2,2,2,2,2,2,2,2,2,1,1,1,2,2,0,0,0,0,0,0
0,0,0,0,0,0,0,0,0,0,0,2,1,1,2,2,2,2,1,1,0,0,0,2,1,0,0,0,0,0,0
0,0,0,0,0,0,1,2,0,0,0,0,2,0,1,2,2,1,0,0,0,0,0,0,0,0,0,0,0,0,0
0,0,0,0,0,0,0,0,0,0,1,0,0,0,0,1,1,1,0,0,0,0,0,0,0,0,0,0,0,0,0
0,0,0,0,0,0,0,0,0,0,0,0,0,0,0,0,0,0,0,0,0,0,0,0,0,0,0,0,0,0,0
0,0,0,0,0,0,0,0,0,0,0,0,0,0,0,0,0,0,0,0,0,0,0,0,0,0,0,0,0,0,0
endlayer

layer
0,0,0,0,0,0,0,0,0,0,0,0,0,0,4,4,4,4,4,0,0,0,0,0,0,0,0,0,0,0,0
0,0,0,0,0,0,0,0,0,0,0,0,0,4,4,4,4,4,4,4,0,0,0,0,0,0,0,0,0,0,0
0,0,0,0,0,0,0,0,0,2,0,0,2,4,4,4,4,4,4,4,2,0,0,0,0,0,0,0,0,0,0
0,0,0,0,0,0,0,0,0,0,0,0,2,4,4,4,4,4,4,4,4,0,0,0,0,0,0,0,0,0,0
0,0,0,0,0,0,2,2,1,1,1,2,2,22,22,22,22,22,22,22,4,1,0,0,0,0,0,0,0,0,0
0,0,0,0,0,0,0,2,1,2,2,7,24,22,22,22,23,22,22,22,6,6,6,1,0,0,0,0,0,0,0
0,0,0,0,0,0,0,1,2,7,7,15,24,22,22,22,22,22,22,22,24,7,7,2,0,0,0,0,0,0,0
0,0,0,0,0,2,1,2,7,15,15,15,15,24,22,22,22,22,22,22,22,20,7,2,1,2,0,0,0,0,0
0,0,0,0,0,2,2,7,15,15,15,15,15,24,24,22,22,22,24,24,7,20,7,7,6,2,2,0,0,0,0
0,4,4,4,2,2,2,24,25,25,25,25,15,15,15,24,24,24,7,7,7,20,7,6,6,6,1,0,0,0,0
0,4,4,4,4,4,4,24,26,15,15,25,15,15,15,15,15,15,15,15,7,20,7,6,6,6,1,1,0,0,0
0,4,4,4,4,4,4,24,26,15,0,28,15,0,0,0,0,0,0,27,20,20,20,6,6,6,2,1,0,0,0
0,4,4,4,4,4,4,24,26,15,15,25,0,0,15,15,15,15,0,7,6,7,7,6,6,6,2,2,0,0,0
0,4,4,4,4,4,4,24,25,25,25,25,0,15,0,0,0,0,0,15,24,6,6,6,6,6,2,2,2,0,0
0,4,4,4,4,4,4,24,26,15,15,25,0,15,4,4,4,15,0,15,15,6,6,6,6,6,2,2,2,2,0
0,4,4,4,4,4,4,24,26,15,0,28,0,15,4,0,4,15,0,15,15,6,6,6,6,6,2,2,2,2,0
0,4,4,4,4,4,4,24,26,15,15,25,0,15,4,4,4,15,0,15,15,6,6,6,6,6,2,2,2,2,0
0,4,4,4,2,24,24,24,25,25,25,25,0,15,15,15,15,0,0,15,24,6,6,6,6,6,2,2,2,0,0
0,1,2,2,6,22,22,29,0,0,0,0,0,0,15,0,15,0,0,7,6,7,7,6,6,6,2,2,0,0,0
0,0,1,2,6,22,22,29,15,0,29,25,27,0,15,30,15,0,15,7,7,20,20,6,6,6,2,1,0,0,0
0,0,1,2,2,22,22,24,15,0,0,0,0,0,0,0,0,0,0,27,20,20,7,6,6,2,6,1,0,0,0
0,1,2,2,2,22,22,32,15,15,15,15,0,15,15,15,31,15,15,7,20,7,7,6,6,2,1,0,0,0,0
0,1,2,2,2,22,22,32,15,15,33,29,0,7,7,7,20,7,7,7,20,7,6,6,2,1,0,0,0,0,0
0,0,1,2,2,2,2,24,15,15,15,15,24,7,6,6,22,6,6,7,20,7,6,2,1,0,0,0,0,0,0
0,0,0,1,2,2,2,2,7,7,7,7,7,7,6,22,22,22,6,7,7,6,2,1,0,0,0,0,0,0,0
0,0,0,0,0,1,1,1,1,7,7,7,7,7,6,22,22,22,6,7,2,2,2,2,2,1,0,0,0,0,0
0,0,0,0,0,0,0,0,0,1,1,2,7,7,6,22,22,22,2,2,1,1,1,2,2,0,0,0,0,0,0
0,0,0,0,0,0,2,2,1,0,0,0,2,1,1,2,2,2,1,0,0,0,0,0,0,0,0,0,0,0,0
0,0,0,0,0,0,0,0,0,0,2,0,0,0,1,2,2,2,0,0,0,0,0,0,0,0,0,0,0,0,0
0,0,0,0,0,0,0,0,0,0,0,0,0,0,0,0,0,0,0,0,0,0,0,0,0,0,0,0,0,0,0
0,0,0,0,0,0,0,0,0,0,0,0,0,0,0,0,0,0,0,0,0,0,0,0,0,0,0,0,0,0,0
endlayer

layer
0,0,0,0,0,0,0,0,0,0,0,0,0,0,25,25,25,25,25,0,0,0,0,0,0,0,0,0,0,0,0
0,0,0,0,0,0,0,0,0,1,0,0,0,25,25,0,0,0,25,25,0,0,0,0,0,0,0,0,0,0,0
0,0,0,0,0,0,0,0,0,2,0,1,2,0,0,25,34,0,0,0,2,0,0,0,0,0,0,0,0,0,0
0,0,0,0,0,0,0,1,0,0,1,1,2,35,35,35,35,35,5,35,2,0,0,0,0,0,0,0,0,0,0
0,0,0,0,0,0,2,2,2,2,2,7,35,0,0,0,33,29,0,0,35,2,1,0,0,0,0,0,0,0,0
0,0,0,0,0,0,0,2,2,6,7,15,35,0,0,0,0,0,0,0,35,6,6,6,0,0,0,0,0,0,0
0,0,0,0,0,0,1,2,7,15,15,0,35,0,0,0,0,0,0,0,35,15,15,6,1,0,0,0,0,0,0
0,0,0,0,0,2,2,7,30,0,0,0,0,35,0,0,0,0,0,0,36,0,15,7,7,2,0,0,0,0,0
0,0,0,0,2,2,7,15,0,0,0,0,0,35,35,0,0,0,35,35,15,0,15,15,7,7,2,0,0,0,0
0,25,25,24,35,35,35,24,25,25,0,0,0,0,0,35,35,35,15,15,15,0,15,24,2,2,6,1,0,0,0
0,25,0,35,24,38,37,35,0,0,0,0,0,0,0,0,0,0,0,0,15,0,15,32,22,22,22,6,1,0,0
0,25,0,35,40,0,39,35,0,0,0,0,0,0,0,0,0,0,0,0,0,0,0,32,22,22,22,6,1,0,0
0,25,0,35,0,0,41,35,0,0,0,0,0,0,0,0,0,0,0,15,7,31,31,32,22,22,22,2,1,0,0
0,25,0,35,0,0,45,24,25,25,0,44,0,0,0,0,0,0,0,0,24,43,43,24,22,22,22,22,22,22,42
0,25,0,35,0,0,45,35,0,0,0,0,0,0,25,25,25,0,0,0,32,22,22,22,22,22,22,22,22,22,42
0,25,0,47,0,0,46,35,0,0,0,0,0,0,25,0,25,0,0,0,32,22,22,22,22,22,22,22,22,22,42
0,25,0,35,0,0,38,35,0,0,0,0,0,0,25,25,25,0,0,0,32,22,22,22,22,22,22,22,22,22,42
0,25,25,24,35,48,35,24,25,25,0,0,0,0,0,0,0,0,0,0,24,43,43,24,22,22,22,22,22,22,42
0,0,0,2,7,0,0,0,0,0,0,0,0,0,0,0,0,0,0,15,7,40,40,32,22,22,22,2,1,0,0
0,0,0,2,7,0,0,0,0,0,0,49,0,0,0,0,0,0,0,15,15,0,0,32,22,22,22,6,1,0,0
0,0,0,1,24,48,48,24,0,0,0,0,0,0,0,0,0,0,0,0,0,0,15,32,22,22,22,6,1,0,0
0,0,1,0,35,0,0,35,0,0,0,0,0,0,0,0,0,0,0,15,0,15,15,24,2,2,2,1,0,0,0
0,0,1,0,35,34,34,35,0,33,29,0,0,15,15,15,0,15,15,15,0,15,7,7,7,7,1,0,0,0,0
0,0,0,0,24,35,35,24,0,0,0,0,24,15,24,35,48,35,24,15,0,15,7,7,2,1,0,0,0,0,0
0,0,0,0,0,1,1,2,15,15,15,15,0,15,35,51,0,50,35,15,31,7,7,2,1,0,0,0,0,0,0
0,0,0,0,0,0,0,1,7,15,15,15,15,15,35,53,0,52,35,15,22,6,2,2,2,2,0,0,0,0,0
0,0,0,0,0,0,0,1,1,6,7,7,15,15,35,34,0,54,35,2,2,2,1,2,2,0,0,0,0,0,0
0,0,0,0,0,0,2,2,2,0,1,1,6,7,2,35,35,35,2,1,1,0,0,0,1,0,0,0,0,0,0
0,0,0,0,0,0,0,1,0,0,2,0,1,1,6,0,0,0,2,1,0,0,0,0,0,0,0,0,0,0,0
0,0,0,0,0,0,0,0,0,1,0,0,0,0,1,1,0,0,0,0,0,0,0,0,0,0,0,0,0,0,0
0,0,0,0,0,0,0,0,0,0,0,0,0,0,0,0,0,0,0,0,0,0,0,0,0,0,0,0,0,0,0
endlayer

layer
0,0,0,0,0,0,0,0,0,0,0,0,0,0,0,0,25,0,0,0,0,0,0,0,0,0,0,0,0,0,0
0,0,0,0,0,0,0,0,0,2,0,0,0,0,0,0,0,0,0,0,0,0,0,0,0,0,0,0,0,0,0
0,0,0,0,0,0,0,0,0,2,0,6,2,0,0,49,0,0,0,0,2,0,0,0,0,0,0,0,0,0,0
0,0,0,0,0,0,0,2,0,1,2,6,2,35,23,35,35,35,14,35,2,1,0,0,0,0,0,0,0,0,0
0,0,0,0,0,0,2,2,2,2,6,15,35,0,0,33,29,0,0,0,35,2,2,1,0,0,0,0,0,0,0
0,0,0,0,0,0,1,2,6,7,15,0,23,0,0,0,0,0,0,0,35,7,7,2,1,0,0,0,0,0,0
0,0,0,0,0,1,2,7,15,0,0,0,35,0,0,0,0,0,0,0,35,0,0,7,7,1,0,0,0,0,0
0,0,0,0,1,2,7,15,0,0,0,0,0,23,0,0,0,0,0,0,14,0,0,15,15,7,1,0,0,0,0
0,0,0,0,2,7,15,0,0,0,0,0,0,35,23,0,0,0,23,35,0,0,0,0,15,15,6,0,0,0,0
0,25,0,24,35,35,35,24,0,0,0,0,0,0,0,35,23,35,0,0,0,0,0,24,35,35,35,6,0,0,0
0,0,0,35,40,42,56,35,0,0,0,0,0,0,0,0,0,0,0,0,0,0,0,35,55,55,39,35,6,0,0
0,0,0,0,0,0,56,23,0,0,0,0,0,0,0,0,0,0,0,0,0,0,0,35,0,0,45,35,6,0,0
0,0,0,35,0,0,56,35,0,0,0,0,0,0,0,0,0,0,0,0,15,0,0,35,0,0,45,24,2,0,0
0,0,0,0,0,0,57,24,0,0,0,0,0,0,0,0,0,0,0,0,24,48,48,24,0,0,0,0,35,25,25
0,0,0,35,0,0,59,35,0,0,0,0,0,0,25,0,25,0,0,0,35,0,0,35,0,0,0,0,58,0,25
0,0,0,60,0,0,56,23,0,0,0,0,0,0,0,0,0,0,0,0,35,53,0,58,0,0,0,31,35,0,25
0,0,0,35,0,0,62,35,0,0,0,0,0,0,25,0,25,0,0,0,35,0,0,35,0,0,0,61,35,0,25
0,25,0,24,35,14,35,24,0,0,0,0,0,0,0,0,0,0,0,0,24,5,5,24,0,0,0,0,35,25,25
0,0,1,2,15,0,0,0,0,0,0,0,0,0,0,0,0,0,0,0,15,0,0,35,51,0,51,24,2,0,0
0,0,1,2,15,0,0,0,0,0,0,0,0,0,0,0,0,0,0,0,0,0,0,35,25,0,25,35,6,0,0
0,0,0,0,24,60,14,24,0,0,0,0,0,0,0,0,0,0,0,0,0,0,0,35,34,0,34,35,6,0,0
0,0,0,0,23,0,0,35,0,0,0,0,0,0,0,0,0,0,0,0,0,0,0,24,35,35,35,6,0,0,0
0,0,0,0,23,0,0,35,33,29,0,0,0,0,0,0,0,0,0,0,0,0,63,15,15,15,6,0,0,0,0
0,0,0,0,24,23,23,24,0,0,0,0,24,0,24,35,60,35,24,0,0,0,15,15,7,7,1,0,0,0,0
0,0,0,0,0,0,1,2,0,0,0,0,0,0,35,0,0,0,35,0,0,15,15,7,2,1,0,0,0,0,0
0,0,0,0,0,0,1,2,15,0,0,0,0,0,23,0,0,0,23,0,31,7,6,2,2,2,0,0,0,0,0
0,0,0,0,0,1,1,2,6,7,15,15,0,0,35,0,0,0,35,7,7,2,2,2,2,0,0,0,0,0,0
0,0,0,0,0,0,2,2,2,1,6,7,7,15,24,35,23,35,2,2,2,1,0,1,2,0,0,0,0,0,0
0,0,0,0,0,0,1,2,1,1,2,1,6,6,2,0,0,0,1,2,0,0,0,0,0,0,0,0,0,0,0
0,0,0,0,0,0,0,0,0,2,1,0,1,1,6,2,0,1,0,0,0,0,0,0,0,0,0,0,0,0,0
0,0,0,0,0,0,0,0,0,0,0,0,0,0,0,0,0,0,0,0,0,0,0,0,0,0,0,0,0,0,0
endlayer

layer
0,0,0,0,0,0,0,0,0,0,0,0,0,0,0,0,25,0,0,0,0,0,0,0,0,0,0,0,0,0,0
0,0,0,0,0,0,0,0,0,2,0,0,0,1,1,0,0,0,1,1,0,0,0,0,0,0,0,0,0,0,0
0,0,0,0,0,0,0,0,0,2,1,2,2,2,2,2,2,2,2,2,2,0,0,0,0,0,0,0,0,0,0
0,0,0,0,0,0,0,2,1,2,2,6,6,35,35,24,35,35,35,35,2,2,1,0,0,0,0,0,0,0,0
0,0,0,0,0,0,2,2,2,6,7,0,35,0,33,29,0,0,0,0,35,6,6,2,1,0,0,0,0,0,0
0,0,0,0,0,1,2,6,7,15,0,0,35,65,0,0,0,0,0,64,35,15,15,7,7,1,0,0,0,0,0
0,0,0,0,1,2,7,15,0,0,0,0,35,0,0,0,0,0,0,0,35,0,0,30,15,7,1,0,0,0,0
0,0,0,0,2,6,15,0,0,0,0,0,0,35,0,0,0,0,0,35,0,0,0,0,0,15,6,0,0,0,0
0,0,0,1,2,15,0,0,0,0,0,0,0,35,35,0,0,0,35,35,0,0,0,0,0,0,7,1,0,0,0
0,25,0,24,35,35,35,24,0,0,0,0,0,0,0,35,35,35,0,0,0,0,0,24,35,23,35,2,0,0,0
0,0,0,35,0,27,42,35,0,0,0,0,0,0,0,0,0,0,0,0,0,0,0,35,0,57,0,35,6,0,0
0,0,0,35,0,0,0,35,0,0,0,0,0,0,0,0,0,0,0,0,0,0,0,23,0,0,45,35,2,0,0
0,0,0,35,0,0,0,35,0,0,0,0,0,0,0,0,0,0,0,0,0,0,0,35,0,0,45,24,2,1,0
0,0,0,35,0,0,64,24,0,0,0,0,0,0,0,0,0,0,0,0,24,60,14,24,0,0,0,0,35,0,25
0,0,0,35,0,0,0,35,0,0,0,0,0,0,66,31,66,0,0,0,35,0,0,35,0,0,0,0,14,0,0
0,0,0,35,0,0,0,35,0,0,0,0,0,0,27,23,29,0,0,0,23,0,0,14,0,0,0,0,35,0,0
0,0,0,35,0,0,0,35,0,0,0,0,0,0,66,40,66,0,0,0,35,0,0,35,0,0,0,31,35,0,0
0,25,0,24,35,35,35,24,0,0,0,0,0,0,0,0,0,0,0,0,24,14,60,24,0,0,0,61,35,0,25
0,0,2,2,0,0,0,0,0,0,0,0,0,0,0,0,0,0,0,0,0,0,0,35,0,0,0,24,2,1,0
0,0,2,2,0,0,0,0,0,0,0,0,0,0,0,0,0,0,0,0,0,0,0,23,49,0,49,35,2,0,0
0,0,1,6,24,35,35,24,0,0,0,0,0,0,0,0,0,0,0,0,0,0,0,35,0,0,0,35,6,0,0
0,0,0,0,35,67,0,35,0,0,0,0,0,0,0,0,0,0,0,0,0,0,0,24,35,23,35,6,0,0,0
0,0,0,0,35,0,0,35,29,0,0,0,0,27,31,31,31,31,31,29,0,0,0,0,0,0,7,1,0,0,0
0,0,0,0,24,35,35,24,0,0,0,0,24,27,24,35,35,35,24,29,0,0,0,0,15,15,6,0,0,0,0
0,0,0,0,1,2,2,2,0,0,0,0,0,27,35,0,0,0,35,29,0,0,0,15,7,7,6,0,0,0,0
0,0,0,0,1,2,2,2,0,0,0,0,0,27,35,0,0,0,35,29,0,15,7,7,2,2,0,0,0,0,0
0,0,0,0,1,2,2,2,6,15,0,0,0,27,35,0,0,0,35,31,31,7,2,2,2,0,0,0,0,0,0
0,0,0,0,1,1,2,2,2,6,6,15,15,27,24,35,35,35,24,2,2,2,1,2,1,0,0,0,0,0,0
0,0,0,0,1,1,2,2,2,2,2,2,24,6,2,2,2,2,2,2,1,0,0,0,0,0,0,0,0,0,0
0,0,0,0,0,1,1,1,2,2,2,1,6,6,6,6,2,2,1,1,0,0,0,0,0,0,0,0,0,0,0
0,0,0,0,0,0,1,1,1,1,1,0,0,0,0,0,0,0,0,0,0,0,0,0,0,0,0,0,0,0,0
endlayer

layer
0,0,0,0,0,0,0,0,0,0,0,0,0,0,0,68,22,68,0,0,0,0,0,0,0,0,0,0,0,0,0
0,0,0,0,0,0,0,0,0,2,0,1,1,2,2,22,22,22,2,2,0,0,0,0,0,0,0,0,0,0,0
0,0,0,0,0,0,0,0,1,2,2,2,2,24,24,22,22,22,24,24,2,1,0,0,0,0,0,0,0,0,0
0,0,0,0,0,0,0,2,2,2,6,7,7,24,22,24,22,22,22,24,6,2,2,1,0,0,0,0,0,0,0
0,0,0,0,0,0,2,2,6,7,15,0,24,22,29,0,0,0,33,22,24,7,7,6,6,0,0,0,0,0,0
0,0,0,0,0,2,6,7,15,0,0,0,24,22,22,22,23,22,22,22,24,0,0,15,15,2,0,0,0,0,0
0,0,0,0,2,6,15,0,0,0,0,0,24,22,22,22,22,22,22,22,24,0,0,0,0,15,2,0,0,0,0
0,0,0,1,2,7,0,0,0,0,0,0,0,24,22,22,22,22,22,24,0,0,0,0,0,0,2,1,0,0,0
0,0,1,2,7,0,0,0,0,0,0,0,0,24,24,22,22,22,24,24,0,0,0,0,0,0,15,2,0,0,0
0,2,2,43,43,43,43,43,24,0,0,0,0,0,0,24,24,24,0,0,0,0,0,24,35,35,35,2,1,0,0
0,33,22,22,0,0,27,22,32,0,0,0,0,0,0,0,0,0,0,0,0,0,0,35,0,0,0,35,2,1,0
0,33,22,22,0,22,22,22,32,0,0,0,0,0,0,0,0,0,0,0,0,0,0,35,0,0,0,35,2,1,0
0,33,22,22,22,22,22,22,32,0,0,0,0,0,0,0,0,0,0,0,0,0,0,35,0,0,64,24,2,2,0
0,33,22,22,22,22,22,22,32,0,0,0,0,0,0,0,0,0,0,0,24,35,35,24,0,0,0,0,35,0,25
0,33,22,22,22,22,22,22,32,0,0,0,0,0,0,0,0,0,0,0,35,0,0,35,0,0,0,0,35,0,0
0,33,22,22,22,22,22,22,32,0,0,0,0,0,0,0,0,0,0,0,35,0,64,35,0,0,0,0,35,0,0
0,33,22,22,22,22,22,22,32,0,0,0,0,0,0,0,0,0,0,0,35,0,0,35,0,0,0,0,35,0,0
0,2,2,43,43,43,43,43,24,0,0,0,0,0,0,0,0,0,0,0,24,35,35,24,0,0,0,31,35,0,25
0,1,6,4,4,4,4,32,0,0,0,0,0,0,0,0,0,0,0,0,0,0,0,35,0,0,64,24,2,2,0
0,1,6,4,4,4,4,32,0,0,0,0,0,0,0,0,0,0,0,0,0,0,0,35,0,0,0,35,2,1,0
0,0,6,7,7,4,4,32,0,0,0,0,0,0,0,0,0,0,0,0,0,0,0,35,0,0,0,35,2,1,0
0,0,1,6,7,4,4,32,0,0,0,0,0,0,0,0,0,0,0,0,0,0,0,24,35,35,35,6,1,0,0
0,0,0,6,6,4,4,29,0,0,0,0,0,0,0,0,0,0,0,0,0,0,0,0,0,0,15,6,0,0,0
0,0,0,2,6,4,4,24,68,68,68,68,24,0,22,22,22,22,22,0,0,0,0,0,0,0,7,0,0,0,0
0,0,0,1,2,4,4,4,22,22,22,22,42,0,22,22,22,22,22,0,0,0,0,0,15,15,6,0,0,0,0
0,0,0,0,4,4,4,4,22,22,22,22,42,0,22,22,22,22,22,0,0,0,15,15,7,6,0,0,0,0,0
0,0,0,0,4,4,4,4,22,22,22,22,42,0,22,22,22,22,22,0,0,15,7,6,2,0,0,0,0,0,0
0,0,0,0,4,4,4,4,22,22,22,22,42,0,22,7,7,22,22,31,31,2,2,2,0,0,0,0,0,0,0
0,0,0,0,4,4,4,4,2,2,2,2,24,7,7,7,7,7,22,22,22,1,0,0,0,0,0,0,0,0,0
0,0,0,0,0,4,4,4,4,4,4,4,4,6,6,7,7,7,7,7,1,0,0,0,0,0,0,0,0,0,0
0,0,0,0,0,0,4,4,4,4,4,4,4,0,0,0,0,0,0,0,0,0,0,0,0,0,0,0,0,0,0
endlayer

layer
0,0,0,0,0,0,0,0,0,0,0,0,0,0,1,25,25,25,0,0,0,0,0,0,0,0,0,0,0,0,0
0,0,0,0,0,0,0,0,0,2,1,2,2,2,2,35,5,35,2,2,1,0,0,0,0,0,0,0,0,0,0
0,0,0,0,0,0,0,0,2,2,2,6,6,35,22,22,0,25,35,35,2,2,1,0,0,0,0,0,0,0,0
0,0,0,0,0,0,0,2,2,7,7,15,15,35,40,24,0,0,0,35,6,6,6,2,0,0,0,0,0,0,0
0,0,0,0,0,1,2,7,7,15,0,0,35,69,0,0,0,0,0,51,35,15,15,7,6,1,0,0,0,0,0
0,0,0,0,1,2,7,15,0,0,0,0,35,69,0,0,0,0,0,25,35,0,0,0,0,7,1,0,0,0,0
0,0,0,0,2,7,0,0,0,0,0,0,35,69,0,0,0,0,0,34,35,0,0,0,0,0,2,0,0,0,0
0,0,0,2,7,15,0,0,0,0,0,0,0,35,0,52,0,52,0,35,0,0,0,0,0,0,0,2,0,0,0
0,1,2,6,15,0,0,0,0,0,0,0,0,35,35,54,25,54,35,35,0,0,0,0,0,0,0,2,1,0,0
1,2,35,35,35,35,35,35,24,0,0,0,0,0,0,35,35,35,0,0,0,0,0,24,24,24,24,24,2,0,0
0,35,69,69,0,0,0,0,35,0,0,0,0,0,0,0,0,0,0,0,0,0,0,24,22,22,22,22,22,2,0
0,35,0,0,0,39,0,0,35,0,0,0,0,0,0,0,0,0,0,0,0,0,0,24,22,22,22,22,22,2,0
0,35,70,0,0,0,0,0,35,0,0,0,0,0,0,0,0,0,0,27,42,0,0,24,22,22,22,22,22,2,0
0,35,25,0,0,0,0,0,35,0,0,0,0,0,0,0,0,0,0,27,24,24,24,22,22,22,22,22,24,22,29
0,35,53,0,0,24,0,0,35,0,0,0,0,0,0,0,0,0,0,27,24,22,22,22,22,22,22,22,24,22,29
0,35,53,0,0,24,0,52,35,0,0,0,0,0,0,0,0,0,0,27,24,22,22,22,22,22,22,0,24,22,29
0,35,25,0,0,24,25,54,35,0,0,0,0,0,0,0,0,0,0,27,24,22,22,22,22,22,22,0,24,22,29
1,2,35,48,48,35,35,35,24,0,0,0,0,0,0,0,0,0,0,27,24,24,24,22,22,22,22,0,24,22,29
0,2,6,0,0,0,0,25,0,0,0,0,0,0,0,0,0,0,0,27,42,0,0,24,22,22,22,31,22,2,0
0,6,6,0,0,0,0,25,0,0,0,0,0,0,0,0,0,0,0,0,0,0,0,24,22,22,22,22,22,2,0
0,1,6,15,15,0,0,25,0,0,0,0,0,0,0,0,0,0,0,0,0,0,0,24,22,22,22,22,22,2,0
0,0,6,7,15,0,0,25,0,0,0,0,0,0,0,0,0,0,0,0,0,0,0,24,24,24,24,24,2,0,0
0,0,1,7,7,0,0,0,0,0,0,0,0,0,0,0,0,0,0,0,0,0,0,0,0,0,0,7,0,0,0
0,0,0,6,6,0,0,24,35,35,35,35,24,0,25,25,25,25,25,0,0,0,0,0,0,0,15,6,0,0,0
0,0,0,0,6,0,0,35,25,51,51,25,35,0,25,0,71,0,25,0,0,0,0,0,0,0,7,1,0,0,0
0,0,0,0,25,0,0,47,0,0,0,0,35,0,25,73,7,72,25,0,0,0,0,0,15,7,1,0,0,0,0
0,0,0,0,25,0,0,47,0,0,0,39,35,0,25,0,74,0,25,0,0,0,15,7,7,1,0,0,0,0,0
0,0,0,0,25,0,0,35,75,0,0,50,35,0,25,15,15,0,0,0,0,0,2,2,1,0,0,0,0,0,0
0,0,0,0,25,25,0,0,35,35,35,35,24,15,25,15,15,15,0,0,0,2,1,0,0,0,0,0,0,0,0
0,0,0,0,0,25,25,0,0,0,0,0,6,6,6,25,25,25,25,25,2,0,0,0,0,0,0,0,0,0,0
0,0,0,0,0,0,25,25,25,25,25,25,25,0,0,0,0,0,0,0,0,0,0,0,0,0,0,0,0,0,0
endlayer

layer
0,0,0,0,0,0,0,0,0,0,0,0,0,1,2,0,0,0,0,0,0,0,0,0,0,0,0,0,0,0,0
0,0,0,0,0,0,0,0,0,2,2,2,2,2,35,35,14,35,2,2,2,1,0,0,0,0,0,0,0,0,0
0,0,0,0,0,0,0,0,2,2,6,6,6,35,40,22,0,49,35,35,6,2,2,0,0,0,0,0,0,0,0
0,0,0,0,0,0,1,2,7,15,15,0,0,35,0,24,0,0,0,35,6,6,7,6,1,0,0,0,0,0,0
0,0,0,0,0,2,7,15,30,0,0,0,35,0,0,0,0,0,0,0,35,0,0,15,7,6,0,0,0,0,0
0,0,0,0,2,7,0,0,0,0,0,0,23,57,0,0,0,0,0,49,23,0,0,0,0,15,6,0,0,0,0
0,0,0,1,2,15,0,0,0,0,0,0,35,0,0,0,0,0,0,0,35,0,0,0,0,0,7,1,0,0,0
0,0,0,2,15,0,0,0,0,0,0,0,0,23,0,0,0,0,0,23,0,0,0,0,0,0,0,2,0,0,0
0,2,2,6,0,0,0,0,0,0,0,0,0,35,23,0,49,0,23,35,0,0,0,0,0,0,0,0,2,0,0
2,2,35,35,23,35,23,35,24,0,0,0,0,0,0,35,23,35,0,0,0,0,0,24,35,35,35,24,2,1,0
0,35,69,69,0,0,0,0,35,0,0,0,0,0,0,0,0,0,0,0,0,0,0,35,25,76,76,25,35,2,0
0,23,0,0,0,0,0,0,23,0,0,0,0,0,0,0,0,0,0,0,0,0,0,35,0,77,77,0,35,2,0
0,35,70,0,0,0,0,0,35,0,0,0,0,0,0,0,0,0,0,0,27,42,0,35,0,0,0,0,24,2,0
0,23,49,0,0,0,0,0,23,0,0,0,0,0,0,0,0,0,0,0,27,35,35,69,0,0,0,0,35,2,1
0,35,0,0,0,66,0,0,35,0,0,0,0,0,0,0,0,0,0,0,24,35,51,0,0,0,25,25,35,2,1
0,23,0,0,0,66,0,0,23,0,0,0,0,0,0,0,0,0,0,0,35,39,25,0,0,0,25,0,35,2,1
0,35,49,0,0,66,49,0,35,0,0,0,0,0,0,0,0,0,0,0,24,35,34,0,0,0,25,0,35,2,1
2,2,35,60,14,35,23,35,24,0,0,0,0,0,0,0,0,0,0,0,27,35,35,69,0,0,25,0,35,2,1
0,2,7,0,0,0,0,0,0,0,0,0,0,0,0,0,0,0,0,0,27,42,0,35,0,0,0,0,24,2,0
0,6,7,0,0,0,0,0,0,0,0,0,0,0,0,0,0,0,0,0,0,0,0,35,0,0,0,0,35,2,0
0,1,6,0,0,0,0,0,0,0,0,0,0,0,0,0,0,0,0,0,0,0,0,35,25,34,34,25,35,2,0
0,0,6,15,0,0,0,0,0,0,0,0,0,0,0,0,0,0,0,0,0,0,0,24,35,35,35,24,2,0,0
0,0,6,15,15,0,0,0,0,0,0,0,0,0,0,0,0,0,0,0,0,0,0,0,0,0,0,0,2,0,0
0,0,0,6,6,0,0,24,35,23,23,35,24,0,0,0,44,0,0,0,0,0,0,0,0,0,0,2,0,0,0
0,0,0,0,7,0,0,35,78,0,0,78,35,0,0,0,0,0,0,0,0,0,0,0,0,0,15,6,0,0,0
0,0,0,0,0,0,0,60,0,0,0,0,23,0,0,0,63,0,0,0,0,0,0,0,0,15,6,0,0,0,0
0,0,0,0,0,0,0,14,0,0,0,0,23,0,0,0,0,0,0,0,0,0,0,30,15,6,0,0,0,0,0
0,0,0,0,0,0,0,35,0,0,0,0,35,0,0,0,0,0,0,0,0,0,0,2,2,0,0,0,0,0,0
0,0,0,0,0,0,0,0,35,23,23,35,24,0,0,0,0,0,0,0,0,2,2,0,0,0,0,0,0,0,0
0,0,0,0,0,0,0,0,0,0,0,0,7,6,7,0,0,44,0,0,2,0,0,0,0,0,0,0,0,0,0
0,0,0,0,0,0,0,0,0,0,0,0,0,0,0,0,0,0,0,0,0,0,0,0,0,0,0,0,0,0,0
endlayer

layer
0,0,0,0,0,0,0,0,0,0,0,0,1,2,2,2,2,2,1,1,1,0,0,0,0,0,0,0,0,0,0
0,0,0,0,0,0,0,0,0,2,2,2,2,2,35,35,35,35,2,2,2,2,0,0,0,0,0,0,0,0,0
0,0,0,0,0,0,0,1,2,2,7,7,6,35,0,27,42,0,35,35,6,2,2,1,0,0,0,0,0,0,0
0,0,0,0,0,0,2,2,15,0,0,0,0,35,0,24,0,0,0,35,6,7,15,7,6,0,0,0,0,0,0
0,0,0,0,1,2,15,0,0,0,0,0,35,0,0,67,0,0,0,0,35,0,0,0,15,6,0,0,0,0,0
0,0,0,0,2,15,0,0,0,0,0,0,35,0,0,0,0,0,0,0,35,0,0,0,0,0,2,0,0,0,0
0,0,0,2,0,0,0,0,0,0,0,0,35,0,0,0,0,0,0,0,35,0,0,0,0,0,15,2,0,0,0
0,0,1,2,0,0,0,0,0,0,0,0,0,35,0,0,0,0,0,35,0,0,0,0,0,0,0,2,0,0,0
0,2,2,7,0,0,0,0,0,0,0,0,0,35,35,0,0,0,35,35,0,0,0,0,0,0,0,0,2,0,0
2,2,35,35,35,35,35,35,24,0,0,0,0,0,0,35,35,35,0,0,0,0,0,24,35,23,35,24,24,2,0
0,35,69,69,0,0,0,0,35,0,0,0,0,0,0,0,0,0,0,0,0,0,0,35,49,0,0,49,23,0,0
0,35,0,0,0,0,0,0,35,0,0,0,0,0,0,0,0,0,0,0,0,0,0,23,0,0,0,0,23,0,0
0,35,70,0,0,0,0,0,35,0,0,0,0,0,0,0,0,0,0,0,0,27,42,35,0,0,0,0,24,2,1
0,35,65,0,0,0,0,64,35,0,0,0,0,0,0,0,0,0,0,0,0,27,35,69,0,0,0,0,35,2,2
0,35,0,0,0,0,0,0,35,0,0,0,0,0,0,0,0,0,0,0,24,35,0,0,0,0,0,0,57,69,2
0,35,0,0,0,0,0,0,35,0,0,0,0,0,0,0,0,0,0,0,23,57,49,0,0,0,0,0,0,69,2
0,35,0,0,0,0,0,0,35,0,0,0,0,0,0,0,0,0,0,0,24,35,0,0,0,0,0,0,57,69,2
2,2,35,35,35,35,35,35,24,0,0,0,0,0,0,0,0,0,0,0,0,27,35,69,0,0,0,0,35,2,2
0,7,15,0,0,0,0,0,0,0,0,0,0,0,0,0,0,0,0,0,0,27,42,35,0,0,0,0,24,2,1
0,7,15,0,0,0,0,0,0,0,0,0,0,0,0,0,0,0,0,0,0,0,0,23,0,0,0,0,23,0,0
0,0,7,0,0,0,0,0,0,0,0,0,0,0,0,0,0,0,0,0,0,0,0,35,49,0,0,49,23,0,0
0,0,6,0,0,0,0,0,0,0,0,0,0,0,0,0,0,0,0,0,0,0,0,24,35,23,35,24,24,2,0
0,0,6,0,0,0,0,0,0,0,0,0,0,0,0,0,0,0,0,0,0,0,0,0,0,0,0,0,2,0,0
0,0,0,7,7,0,0,24,35,23,23,35,24,0,0,0,0,0,0,0,0,0,0,0,0,0,0,2,0,0,0
0,0,0,0,15,0,0,35,0,0,0,0,35,0,0,0,0,0,0,0,0,0,0,0,0,0,0,2,0,0,0
0,0,0,0,0,0,0,33,0,0,0,0,23,0,0,0,0,0,0,0,0,0,0,0,0,0,2,0,0,0,0
0,0,0,0,0,0,0,33,0,0,0,0,23,0,0,0,0,0,0,0,0,0,0,0,0,6,0,0,0,0,0
0,0,0,0,0,0,0,35,0,0,0,0,35,0,0,0,0,0,0,0,0,0,0,2,2,0,0,0,0,0,0
0,0,0,0,0,0,0,0,35,23,23,35,24,0,0,0,0,0,0,0,0,2,2,1,0,0,0,0,0,0,0
0,0,0,0,0,0,0,0,0,0,0,0,15,7,15,0,0,0,0,0,2,1,0,0,0,0,0,0,0,0,0
0,0,0,0,0,0,0,0,0,0,0,0,0,0,0,0,0,0,0,0,0,0,0,0,0,0,0,0,0,0,0
endlayer

layer
0,0,0,0,0,0,0,0,0,0,0,0,2,2,2,2,2,2,2,2,2,1,0,0,0,0,0,0,0,0,0
0,0,0,0,0,0,0,0,0,2,2,2,2,2,24,24,24,24,2,2,2,2,0,0,0,0,0,0,0,0,0
0,0,0,0,0,0,0,2,2,0,15,15,6,24,0,0,27,22,24,24,6,7,2,2,0,0,0,0,0,0,0
0,0,0,0,0,1,2,0,0,0,0,0,0,24,0,24,22,22,22,24,6,15,0,15,6,0,0,0,0,0,0
0,0,0,0,1,2,0,0,0,0,0,0,24,22,68,22,22,22,22,22,24,0,0,0,0,2,0,0,0,0,0
0,0,0,0,2,0,0,0,0,0,0,0,24,22,22,22,0,22,22,22,24,0,0,0,0,0,2,0,0,0,0
0,0,0,2,0,0,0,0,0,0,0,0,24,22,22,22,22,22,22,22,24,0,0,0,0,0,0,2,0,0,0
0,0,2,0,0,0,0,0,0,0,0,0,0,24,22,22,22,22,22,24,0,0,0,0,0,0,0,2,0,0,0
31,31,2,31,31,31,31,31,31,29,0,0,0,24,24,22,22,22,24,24,0,0,0,0,0,0,0,0,2,0,0
61,32,43,43,43,43,43,43,24,29,0,0,0,0,0,24,24,24,0,0,0,0,0,24,35,35,35,24,2,2,0
0,32,22,22,22,22,22,22,32,29,0,0,0,0,0,0,0,0,0,0,0,0,0,35,0,0,0,0,35,2,0
0,32,22,22,22,22,22,22,32,29,0,0,0,0,0,0,0,0,0,0,0,0,0,35,0,0,0,0,35,2,0
68,32,70,22,22,22,22,22,32,29,0,0,0,0,0,0,0,0,0,0,0,0,27,35,0,0,0,64,24,2,2
33,32,22,22,22,22,22,22,32,29,0,0,0,0,0,0,0,0,0,31,31,31,27,69,0,0,0,0,35,2,2
61,32,22,22,22,22,22,22,32,29,0,0,0,0,0,0,0,0,0,61,24,35,61,0,0,0,0,0,0,69,2
0,32,22,22,22,22,22,22,32,29,0,0,0,0,0,0,0,0,0,0,35,65,0,0,0,0,0,0,0,69,2
0,32,22,22,22,22,22,22,32,29,0,0,0,0,0,0,0,0,0,68,24,35,68,0,0,0,0,0,0,69,2
68,24,43,43,43,43,43,43,24,29,0,0,0,0,0,0,0,0,0,40,40,40,27,69,0,0,0,0,35,2,2
40,40,40,40,40,40,40,40,40,40,0,0,0,0,0,0,0,0,0,0,0,0,27,35,0,0,0,64,24,2,2
0,15,0,0,0,0,0,0,0,0,0,0,0,0,0,0,0,0,0,0,0,0,0,35,0,0,0,0,35,2,0
0,0,15,0,0,0,0,0,0,0,0,0,0,0,0,0,0,0,0,0,0,0,0,35,0,0,0,0,35,2,0
0,0,7,0,0,0,0,0,0,0,0,0,0,0,0,0,0,0,0,0,0,0,0,24,35,35,35,24,2,2,0
0,0,7,0,0,0,0,0,0,0,0,0,0,0,0,0,0,0,0,0,0,0,0,0,0,0,0,0,2,0,0
0,0,0,15,15,0,0,24,35,35,35,35,24,0,0,0,0,0,0,0,0,0,0,0,0,0,0,0,2,0,0
0,0,0,0,0,0,0,35,0,0,0,0,35,0,0,0,0,0,0,0,0,0,0,0,0,0,0,2,0,0,0
0,0,0,0,0,0,0,35,65,0,0,0,35,0,0,0,0,0,0,0,0,0,0,0,0,0,2,0,0,0,0
0,0,0,0,0,0,0,35,0,0,0,0,35,0,0,0,0,0,0,0,0,0,0,0,0,2,0,0,0,0,0
0,0,0,0,0,0,0,35,0,0,0,0,35,0,0,0,0,0,0,0,0,0,0,0,2,0,0,0,0,0,0
0,0,0,0,0,0,0,0,35,35,35,35,24,0,0,0,0,0,0,0,0,0,2,2,0,0,0,0,0,0,0
0,0,0,0,0,0,0,0,0,0,0,0,0,15,0,0,0,0,0,0,2,2,0,0,0,0,0,0,0,0,0
0,0,0,0,0,0,0,0,0,0,0,0,0,0,0,0,0,0,0,0,0,0,0,0,0,0,0,0,0,0,0
endlayer

layer
0,0,0,0,0,0,0,0,0,0,0,0,7,7,7,7,7,7,7,7,7,2,0,0,0,0,0,0,0,0,0
0,0,0,0,0,0,0,0,0,2,2,2,7,7,7,7,7,7,7,7,7,2,0,0,0,0,0,0,0,0,0
0,0,0,0,0,0,0,2,2,0,0,27,7,7,0,0,0,27,7,7,7,29,2,2,0,0,0,0,0,0,0
0,0,0,0,0,0,2,0,0,0,0,27,7,7,7,7,7,7,7,7,7,29,0,0,2,0,0,0,0,0,0
0,0,0,0,0,2,0,0,0,0,0,27,7,7,79,79,18,79,79,7,7,29,0,0,0,2,0,0,0,0,0
0,0,0,0,2,0,0,0,0,0,0,27,7,7,79,79,23,79,79,7,7,29,0,0,0,0,2,0,0,0,0
0,0,0,2,0,0,0,0,0,0,0,27,22,7,79,79,7,79,79,7,22,29,0,0,0,0,0,2,0,0,0
0,0,2,0,0,0,0,0,0,0,0,0,27,7,7,7,6,7,7,7,29,0,0,0,0,0,0,2,0,0,0
0,0,2,0,0,0,0,0,0,0,0,0,27,22,7,7,7,7,7,22,29,0,31,31,31,31,31,31,2,0,0
31,31,31,31,31,31,31,31,29,0,0,0,0,40,40,22,7,22,40,40,0,0,27,24,43,43,43,24,2,0,0
61,35,22,22,22,22,22,22,29,0,0,0,0,0,0,40,40,40,0,0,0,0,27,32,0,0,0,0,32,2,0
0,24,80,0,80,80,0,0,29,0,0,0,0,0,0,0,0,0,0,0,0,0,27,32,0,0,0,0,32,2,0
25,35,70,0,0,0,80,0,35,0,0,0,0,0,0,0,0,0,0,0,0,0,27,32,0,0,0,0,24,2,2
25,47,0,0,0,80,0,0,25,0,0,0,0,0,0,0,0,0,0,0,0,0,27,32,0,0,0,0,35,2,2
25,35,80,80,0,0,0,80,35,0,0,0,0,0,0,0,0,0,0,31,31,31,31,32,0,0,0,0,35,2,2
0,24,80,80,0,80,80,0,29,0,0,0,0,0,0,0,0,0,0,22,22,22,22,32,0,0,0,0,35,2,2
68,35,22,22,22,22,22,22,29,0,0,0,0,0,0,0,0,0,0,40,40,40,40,32,0,0,0,0,35,2,2
40,40,40,40,40,40,40,40,40,0,0,0,0,0,0,0,0,0,0,0,0,0,27,32,0,0,0,0,35,2,2
0,0,0,0,0,0,0,0,0,0,0,0,0,0,0,0,0,0,0,0,0,0,27,32,0,0,0,0,24,2,2
0,0,0,0,0,0,0,0,0,0,0,0,0,0,0,0,0,0,0,0,0,0,27,32,0,0,0,0,32,2,0
0,0,0,0,0,0,0,0,0,0,0,0,0,0,0,0,0,0,0,0,0,0,27,32,0,0,0,0,32,2,0
0,0,30,0,0,0,0,0,0,0,0,0,0,0,0,0,0,0,0,0,0,0,27,24,43,43,43,24,2,2,0
0,0,15,0,0,0,27,31,31,31,31,31,31,29,0,0,0,0,0,0,0,0,40,40,40,40,40,40,2,0,0
0,0,0,0,0,0,27,24,43,43,43,43,24,29,0,0,0,0,0,0,0,0,0,0,0,0,0,0,2,0,0
0,0,0,0,0,0,27,32,0,0,0,0,32,29,0,0,0,0,0,0,0,0,0,0,0,0,0,2,0,0,0
0,0,0,0,0,0,27,32,0,0,0,0,32,29,0,0,0,0,0,0,0,0,0,0,0,0,2,0,0,0,0
0,0,0,0,0,0,27,32,0,0,0,0,32,29,0,0,0,0,0,0,0,0,0,0,0,2,0,0,0,0,0
0,0,0,0,0,0,27,32,0,0,0,0,32,29,0,0,0,0,0,0,0,0,0,0,2,0,0,0,0,0,0
0,0,0,0,0,0,27,24,43,43,43,43,24,29,0,0,0,0,0,0,0,0,2,2,0,0,0,0,0,0,0
0,0,0,0,0,0,27,40,40,40,40,40,40,40,0,0,0,0,0,0,2,0,0,0,0,0,0,0,0,0,0
0,0,0,0,0,0,0,0,0,0,0,0,0,0,0,0,0,0,0,0,0,0,0,0,0,0,0,0,0,0,0
endlayer

layer
0,0,0,0,0,0,0,0,0,0,0,0,25,25,25,25,25,25,25,25,25,2,0,0,0,0,0,0,0,0,0
0,0,0,0,0,0,0,0,0,0,2,0,25,15,15,15,15,15,15,15,25,0,0,0,0,0,0,0,0,0,0
0,0,0,0,0,0,0,0,2,0,0,0,25,15,0,0,0,0,0,15,25,0,2,0,0,0,0,0,0,0,0
0,0,0,0,0,0,2,0,0,0,0,0,25,15,15,15,44,0,0,15,25,0,0,0,2,0,0,0,0,0,0
0,0,0,0,0,0,0,0,0,0,0,0,25,15,81,81,0,81,81,15,25,0,0,0,0,0,0,0,0,0,0
0,0,0,0,2,0,0,0,0,0,0,0,25,15,81,82,0,82,82,15,25,0,0,0,0,0,2,0,0,0,0
0,0,0,0,0,0,0,0,0,0,0,0,25,25,84,81,71,83,83,25,25,0,0,0,0,0,0,0,0,0,0
0,0,2,0,0,0,0,0,0,0,0,0,0,25,15,73,7,72,15,25,0,0,0,0,0,0,0,2,0,0,0
0,0,0,0,0,0,0,0,0,0,0,0,0,25,25,25,74,25,25,25,0,0,0,0,0,0,0,0,0,0,0
0,0,0,0,0,0,0,0,0,0,0,0,0,0,0,25,25,25,0,0,0,0,0,31,31,31,31,31,2,0,0
31,31,31,31,31,31,31,29,0,0,0,0,0,0,0,0,0,0,0,0,0,0,0,27,61,61,61,61,22,2,0
61,24,0,0,80,80,64,22,31,31,0,0,0,0,0,0,0,0,0,0,0,0,0,27,42,0,0,33,22,0,0
0,35,70,0,0,0,0,0,35,61,0,0,0,0,0,0,0,0,0,0,0,0,0,27,42,0,0,33,22,2,2
0,14,0,0,0,0,0,0,25,0,0,0,0,0,0,0,0,0,0,0,0,0,0,27,42,0,0,33,22,2,0
0,35,80,80,0,0,0,80,35,68,0,0,0,0,0,0,0,0,0,0,0,0,0,27,42,0,0,33,22,2,2
68,24,80,80,0,0,64,29,40,40,0,0,0,0,0,0,0,0,0,66,66,66,66,27,42,0,0,33,22,2,0
40,40,40,40,40,40,40,40,0,0,0,0,0,0,0,0,0,0,0,0,0,0,0,27,42,0,0,33,22,2,2
0,0,0,0,0,0,0,0,0,0,0,0,0,0,0,0,0,0,0,0,0,0,0,27,42,0,0,33,22,2,0
0,0,0,0,0,0,0,0,0,0,0,0,0,0,0,0,0,0,0,0,0,0,0,27,42,0,0,33,22,2,2
0,0,0,0,0,0,0,0,0,0,0,0,0,0,0,0,0,0,0,0,0,0,0,27,42,0,0,33,29,0,0
0,0,0,0,0,0,0,0,0,0,0,0,0,0,0,0,0,0,0,0,0,0,0,27,42,68,68,68,29,0,0
0,0,0,0,0,0,0,0,0,0,0,0,0,0,0,0,0,0,0,0,0,0,0,27,40,40,40,40,29,2,0
0,0,0,0,0,0,0,0,0,0,0,0,0,0,0,0,0,0,0,0,0,0,0,0,0,0,0,0,0,0,0
0,0,0,0,0,0,0,27,31,31,31,31,31,0,0,0,0,0,0,0,0,0,0,0,0,0,0,0,2,0,0
0,0,0,0,0,0,0,27,22,22,22,22,29,0,0,0,0,0,0,0,0,0,0,0,0,0,0,2,0,0,0
0,0,0,0,0,0,0,27,22,22,22,22,29,0,0,0,0,0,0,0,0,0,0,0,0,0,0,0,0,0,0
0,0,0,0,0,0,0,27,22,22,22,22,29,0,0,0,0,0,0,0,0,0,0,0,0,2,0,0,0,0,0
0,0,0,0,0,0,0,27,22,22,22,22,29,0,0,0,0,0,0,0,0,0,0,0,0,0,0,0,0,0,0
0,0,0,0,0,0,0,40,40,40,40,40,40,0,0,0,0,0,0,0,0,0,0,2,0,0,0,0,0,0,0
0,0,0,0,0,0,0,0,0,0,0,0,0,0,0,0,0,0,0,0,0,0,0,0,0,0,0,0,0,0,0
0,0,0,0,0,0,0,0,0,0,0,0,0,0,0,0,0,0,0,0,0,0,0,0,0,0,0,0,0,0,0
endlayer

layer
0,0,0,0,0,0,0,0,0,0,0,0,0,0,0,0,0,0,0,0,0,0,0,0,0,0,0,0,0,0,0
0,0,0,0,0,0,0,0,0,0,0,0,0,0,0,0,0,0,0,0,0,0,0,0,0,0,0,0,0,0,0
0,0,0,0,0,0,0,0,0,0,0,0,0,0,0,0,0,0,0,0,0,0,0,0,0,0,0,0,0,0,0
0,0,0,0,0,0,0,0,0,0,0,0,0,0,0,0,0,0,0,0,0,0,0,0,0,0,0,0,0,0,0
0,0,0,0,0,0,0,0,0,0,0,0,0,0,0,0,0,0,0,0,0,0,0,0,0,0,0,0,0,0,0
0,0,0,0,0,0,0,0,0,0,0,0,0,0,0,0,0,0,0,0,0,0,0,0,0,0,0,0,0,0,0
0,0,0,0,0,0,0,0,0,0,0,0,0,0,0,0,0,0,0,0,0,0,0,0,0,0,0,0,0,0,0
0,0,0,0,0,0,0,0,0,0,0,0,0,0,0,0,63,0,0,0,0,0,0,0,0,0,0,0,0,0,0
0,0,0,0,0,0,0,0,0,0,0,0,0,0,0,0,0,0,0,0,0,0,0,0,0,0,0,0,0,0,0
0,0,0,0,0,0,0,0,0,0,0,0,0,0,0,0,0,0,0,0,0,0,0,0,0,0,0,0,0,0,0
0,0,0,0,0,0,0,0,0,0,0,0,0,0,0,0,0,0,0,0,0,0,0,0,31,31,31,31,0,2,0
31,31,31,31,31,31,29,0,0,0,0,0,0,0,0,0,0,0,0,0,0,0,0,0,27,61,33,29,0,0,0
61,35,61,61,61,61,31,31,31,31,0,0,0,0,0,0,0,0,0,0,0,0,0,0,27,42,33,29,0,0,0
0,35,0,0,0,33,22,22,22,22,0,0,0,0,0,0,0,0,0,0,0,0,0,0,27,42,33,29,0,0,0
68,35,68,68,68,68,40,40,40,40,0,0,0,0,0,0,0,0,0,0,0,0,0,0,27,42,33,29,0,0,0
40,40,40,40,40,40,29,0,0,0,0,0,0,0,0,0,0,0,0,0,0,0,0,0,27,42,33,29,0,0,0
0,0,0,0,0,0,0,0,0,0,0,0,0,0,0,0,0,0,0,0,0,0,0,0,27,42,33,29,0,0,0
0,0,0,0,0,0,0,0,0,0,0,0,0,0,0,0,0,0,0,0,0,0,0,0,27,42,33,29,0,0,0
0,0,0,0,0,0,0,0,0,0,0,0,0,0,0,0,0,0,0,0,0,0,0,0,27,42,33,29,0,0,0
0,0,0,0,0,0,0,0,0,0,0,0,0,0,0,0,0,0,0,0,0,0,0,0,27,68,68,29,0,0,0
0,0,0,0,0,0,0,0,0,0,0,0,0,0,0,0,0,0,0,0,0,0,0,0,27,40,40,29,0,0,0
0,0,0,0,0,0,0,0,0,0,0,0,0,0,0,0,0,0,0,0,0,0,0,0,0,0,0,0,0,0,0
0,0,0,0,0,0,0,0,0,0,0,0,0,0,0,0,0,0,0,0,0,0,0,0,0,0,0,0,0,0,0
0,0,0,0,0,0,0,0,0,0,0,0,0,0,0,0,0,0,0,0,0,0,0,0,0,0,0,0,0,0,0
0,0,0,0,0,0,0,0,0,0,0,0,0,0,0,0,0,0,0,0,0,0,0,0,0,0,0,0,0,0,0
0,0,0,0,0,0,0,0,0,0,0,0,0,0,0,0,0,0,0,0,0,0,0,0,0,0,0,0,0,0,0
0,0,0,0,0,0,0,0,0,0,0,0,0,0,0,0,0,0,0,0,0,0,0,0,0,0,0,0,0,0,0
0,0,0,0,0,0,0,0,0,0,0,0,0,0,0,0,0,0,0,0,0,0,0,0,0,0,0,0,0,0,0
0,0,0,0,0,0,0,0,0,0,0,0,0,0,0,0,0,0,0,0,0,0,0,0,0,0,0,0,0,0,0
0,0,0,0,0,0,0,0,0,0,0,0,0,0,0,0,0,0,0,0,0,0,0,0,0,0,0,0,0,0,0
0,0,0,0,0,0,0,0,0,0,0,0,0,0,0,0,0,0,0,0,0,0,0,0,0,0,0,0,0,0,0
endlayer

layer
0,0,0,0,0,0,0,0,0,0,0,0,0,0,0,0,0,0,0,0,0,0,0,0,0,0,0,0,0,0,0
0,0,0,0,0,0,0,0,0,0,0,0,0,0,0,0,0,0,0,0,0,0,0,0,0,0,0,0,0,0,0
0,0,0,0,0,0,0,0,0,0,0,0,0,0,0,0,0,0,0,0,0,0,0,0,0,0,0,0,0,0,0
0,0,0,0,0,0,0,0,0,0,0,0,0,0,0,0,0,0,0,0,0,0,0,0,0,0,0,0,0,0,0
0,0,0,0,0,0,0,0,0,0,0,0,0,0,0,0,0,0,0,0,0,0,0,0,0,0,0,0,0,0,0
0,0,0,0,0,0,0,0,0,0,0,0,0,0,0,0,0,0,0,0,0,0,0,0,0,0,0,0,0,0,0
0,0,0,0,0,0,0,0,0,0,0,0,0,0,0,0,0,0,0,0,0,0,0,0,0,0,0,0,0,0,0
0,0,0,0,0,0,0,0,0,0,0,0,0,0,0,0,0,0,0,0,0,0,0,0,0,0,0,0,0,0,0
0,0,0,0,0,0,0,0,0,0,0,0,0,0,0,0,0,0,0,0,0,0,0,0,0,0,0,0,0,0,0
0,0,0,0,0,0,0,0,0,0,0,0,0,0,0,0,0,0,0,0,0,0,0,0,0,0,0,0,0,0,0
0,0,0,0,0,0,0,0,0,0,0,0,0,0,0,0,0,0,0,0,0,0,0,0,0,0,0,0,0,0,0
0,0,0,0,0,0,0,0,0,0,0,0,0,0,0,0,0,0,0,0,0,0,0,0,0,31,31,0,0,0,0
31,31,31,31,31,31,0,0,0,0,0,0,0,0,0,0,0,0,0,0,0,0,0,0,0,27,29,0,0,0,0
22,22,22,22,22,29,66,66,66,66,0,0,0,0,0,0,0,0,0,0,0,0,0,0,0,27,29,0,0,0,0
40,40,40,40,40,29,0,0,0,0,0,0,0,0,0,0,0,0,0,0,0,0,0,0,0,27,29,0,0,0,0
0,0,0,0,0,0,0,0,0,0,0,0,0,0,0,0,0,0,0,0,0,0,0,0,0,27,29,0,0,0,0
0,0,0,0,0,0,0,0,0,0,0,0,0,0,0,0,0,0,0,0,0,0,0,0,0,27,29,0,0,0,0
0,0,0,0,0,0,0,0,0,0,0,0,0,0,0,0,0,0,0,0,0,0,0,0,0,27,29,0,0,0,0
0,0,0,0,0,0,0,0,0,0,0,0,0,0,0,0,0,0,0,0,0,0,0,0,0,27,29,0,0,0,0
0,0,0,0,0,0,0,0,0,0,0,0,0,0,0,0,0,0,0,0,0,0,0,0,0,40,40,0,0,0,0
0,0,0,0,0,0,0,0,0,0,0,0,0,0,0,0,0,0,0,0,0,0,0,0,0,0,0,0,0,0,0
0,0,0,0,0,0,0,0,0,0,0,0,0,0,0,0,0,0,0,0,0,0,0,0,0,0,0,0,0,0,0
0,0,0,0,0,0,0,0,0,0,0,0,0,0,0,0,0,0,0,0,0,0,0,0,0,0,0,0,0,0,0
0,0,0,0,0,0,0,0,0,0,0,0,0,0,0,0,0,0,0,0,0,0,0,0,0,0,0,0,0,0,0
0,0,0,0,0,0,0,0,0,0,0,0,0,0,0,0,0,0,0,0,0,0,0,0,0,0,0,0,0,0,0
0,0,0,0,0,0,0,0,0,0,0,0,0,0,0,0,0,0,0,0,0,0,0,0,0,0,0,0,0,0,0
0,0,0,0,0,0,0,0,0,0,0,0,0,0,0,0,0,0,0,0,0,0,0,0,0,0,0,0,0,0,0
0,0,0,0,0,0,0,0,0,0,0,0,0,0,0,0,0,0,0,0,0,0,0,0,0,0,0,0,0,0,0
0,0,0,0,0,0,0,0,0,0,0,0,0,0,0,0,0,0,0,0,0,0,0,0,0,0,0,0,0,0,0
0,0,0,0,0,0,0,0,0,0,0,0,0,0,0,0,0,0,0,0,0,0,0,0,0,0,0,0,0,0,0
0,0,0,0,0,0,0,0,0,0,0,0,0,0,0,0,0,0,0,0,0,0,0,0,0,0,0,0,0,0,0
endlayer

