
# Created by Ruins mod version 17.0 Ingame Parser
# authoring Player: ST753M

weight=1
embed_into_distance=4
acceptable_target_blocks=
unacceptable_target_blocks=flowing_water,water,flowing_lava,lava,ice,bedrock,netherrack,nether_brick,nether_brick_fence,soul_sand,quartz_ore,end_stone,obsidian,iron_bars,Natura:Cloud,slime_grass,slime_congealed,slime_dirt,clouds,natura:clouds
dimensions=22,12,8
allowable_overhang=4
max_leveling=0
leveling_buffer=0
preserve_water=1
preserve_lava=1
random_height_offset=-2,2

biomesToSpawnIn=stone_beach,gravel_beach,ocean,kelp_forest,deep_ocean,coral_reef,coralium_infested_ocean,swampland,mutated_swampland,wetland,quagmire,lush_swamp,mangrove,marsh,bayou,bog,bamboo_forest,dead_swamp,moor,dead_swamp,coralium_infested_swamp,jungle,jungle_edge,jungle_hills,tropical_island,tropical_rainforest,rainforest,mutated_jungle,mutated_jungle_edge,bamboo_forest,overgrown_cliffs,eucalyptus_forest,mini_jungle,forest,maple_woods,boreal_forest,forest_hills,woodland,seasonal_forest,temperate_rainforest,fen,grove,sacred_springs,land_of_lakes,forested_hills,lush_hills,thicket,birch_forest,birch_forest_hills,mutated_birch_forest,mutated_birch_forest_hills,birch_forested_hills,cherry_blossom_grove,mutated_forest,roofed_forest,mutated_roofed_forest,taiga,taiga_hills,mutated_redwood_taiga,mutated_redwood_taiga_hills,redwood_taiga,mutated_taiga,redwood_taiga_hills,redwood_forest,coniferous_forest,shield,dead_forest,autumnal_wooded_hills,autumnal_woods,snowy_forest,mutated_taiga_cold,snowy_coniferous_forest,taiga_cold,taiga_cold_hills,glacier,ice_mountains,glacier,glacier_spikes,extreme_hills,smaller_extreme_hills,mutated_extreme_hills,mutated_extreme_hills_with_trees,extreme_hills_with_trees,highland,alps,alps_foothills,mountain,mountain_foothills,crag,cliffs,rocky_plateau,savanna_rock,mutated_savanna_rock,steppe,wasteland,tundra,outback,badlands,mushroom_island,mushroom_island_shore,mushroomisland,mushroomislandshore,volcanic_island,darklands,darklands_forest,darklands_hills,darklands_mountains,darklands_plains,ominous_woods,eerie,swamp_defiled,desert_defiled,plains_defiled,ice_plains_defiled,hills_defiled,forest_tenebra,forest_vilespine,abyssal_wastelands,dreadlands,dreadlands_forest,dreadlands_mountains,purged_dreadlands,omothol,dark_realm

rule1=0,100,preserveBlock

#  Main Body 
rule2=0,100,minecraft:stone-0
^0,100,minecraft:stone-0
^0,100,minecraft:stone-1
^0,100,minecraft:stone-1
^0,100,minecraft:stone-3
^0,100,minecraft:stone-3
^0,100,minecraft:stone-5
^0,100,minecraft:stone-5
^0,100,minecraft:cobblestone-0
^0,100,minecraft:mossy_cobblestone-0
^0,100,minecraft:mossy_cobblestone-0,minecraft:cobblestone-0
^0,100,minecraft:obsidian-0

#  Eyes (has 4 blocks)
rule3=0,100,minecraft:iron_block-0
^0,100,minecraft:iron_block-0
^0,100,minecraft:iron_block-0
^0,100,minecraft:iron_block-0
^0,100,minecraft:iron_block-0
^0,100,minecraft:iron_block-0
^0,100,minecraft:iron_block-0
^0,100,minecraft:lapis_block-0
^0,100,minecraft:lapis_block-0
^0,100,minecraft:lapis_block-0
^0,100,minecraft:obsidian-0
^0,100,minecraft:obsidian-0
^0,100,minecraft:obsidian-0
^0,100,minecraft:obsidian-0
^0,100,minecraft:obsidian-0
^0,100,minecraft:obsidian-0
^0,100,minecraft:glowstone-0
^0,100,minecraft:glowstone-0
^0,100,minecraft:glowstone-0
^0,100,minecraft:glowstone-0
^0,100,minecraft:gold_block-0
^0,100,minecraft:stained_hardened_clay-3
^0,100,minecraft:stained_hardened_clay-3
^0,100,minecraft:stained_hardened_clay-3
^0,100,minecraft:stained_hardened_clay-3
^0,100,minecraft:stained_hardened_clay-3
^0,100,minecraft:stained_hardened_clay-3
^0,100,minecraft:stained_hardened_clay-11
^0,100,minecraft:stained_hardened_clay-11
^0,100,minecraft:stained_hardened_clay-11
^0,100,minecraft:magma-0
^0,100,minecraft:quartz_block-0
^0,100,minecraft:sea_lantern-0
^0,100,minecraft:stained_hardened_clay-11
^0,100,minecraft:magma-0
^0,100,minecraft:quartz_block-0
^0,100,minecraft:sea_lantern-0

layer
1,1,1,1,1,1,1,1
1,1,1,1,1,1,1,1
1,1,2,2,2,2,1,1
1,1,2,2,2,2,1,1
1,1,2,2,2,2,1,1
1,1,2,2,2,2,1,1
1,1,2,2,2,2,1,1
1,1,2,2,2,2,1,1
1,1,2,2,2,2,1,1
1,1,1,1,1,1,1,1
1,1,1,1,1,1,1,1
1,1,1,1,1,1,1,1
endlayer

layer
1,1,1,1,1,1,1,1
1,1,2,2,2,2,1,1
1,2,2,2,2,2,2,1
1,2,2,2,2,2,2,1
1,2,2,2,2,2,2,1
1,2,2,2,2,2,2,1
1,2,2,2,2,2,2,1
1,2,2,2,2,2,2,1
1,2,2,2,2,2,2,1
1,1,2,2,2,2,1,1
1,1,1,1,1,1,1,1
1,1,1,1,1,1,1,1
endlayer

layer
1,1,1,1,1,1,1,1
1,1,2,2,2,2,1,1
1,2,2,2,2,2,2,1
1,2,2,2,2,2,2,1
1,2,2,2,2,2,2,1
1,2,2,2,2,2,2,1
1,2,2,2,2,2,2,1
1,2,2,2,2,2,2,1
1,2,2,2,2,2,2,1
1,1,2,2,2,2,1,1
1,1,1,1,1,1,1,1
1,1,1,1,1,1,1,1
endlayer

layer
1,1,1,1,1,1,1,1
1,1,2,2,2,2,1,1
1,2,2,2,2,2,2,1
1,2,2,2,2,2,2,1
1,2,2,2,2,2,2,1
1,2,2,2,2,2,2,1
1,2,2,2,2,2,2,1
1,2,2,2,2,2,2,1
1,2,2,2,2,2,2,1
1,1,2,2,2,2,1,1
1,1,1,1,1,1,1,1
1,1,1,1,1,1,1,1
endlayer

layer
1,1,1,1,1,1,1,1
1,1,2,2,2,2,1,1
1,2,2,2,2,2,2,1
1,2,2,2,2,2,2,1
1,2,2,2,2,2,2,1
1,2,2,2,2,2,2,1
1,2,2,2,2,2,2,1
1,2,2,2,2,2,2,1
1,2,2,2,2,2,2,1
1,1,1,2,2,1,1,1
1,1,1,1,1,1,1,1
1,1,1,1,1,1,1,1
endlayer

layer
1,1,1,1,1,1,1,1
1,1,2,2,2,2,1,1
1,1,2,2,2,2,1,1
1,2,2,2,2,2,2,1
1,2,2,2,2,2,2,1
1,2,2,2,2,2,2,1
1,2,2,2,2,2,2,1
1,2,2,2,2,2,2,1
1,1,2,2,2,2,1,1
1,1,1,1,1,1,1,1
1,1,1,1,1,1,1,1
1,1,1,1,1,1,1,1
endlayer

layer
1,1,1,1,1,1,1,1
1,1,2,2,2,2,1,1
1,1,2,2,2,2,1,1
1,1,2,2,2,2,1,1
1,2,2,2,2,2,2,1
1,2,2,2,2,2,2,1
1,2,2,2,2,2,2,1
1,1,2,2,2,2,1,1
1,1,2,2,2,2,1,1
1,1,1,1,1,1,1,1
1,1,1,1,1,1,1,1
1,1,1,1,1,1,1,1
endlayer

layer
1,1,1,1,1,1,1,1
1,1,1,2,2,1,1,1
1,1,2,2,2,2,1,1
1,1,2,2,2,2,1,1
1,1,2,2,2,2,1,1
1,1,2,2,2,2,1,1
1,1,2,2,2,2,1,1
1,1,2,2,2,2,1,1
1,1,1,2,2,1,1,1
1,1,1,1,1,1,1,1
1,1,1,1,1,1,1,1
1,1,1,1,1,1,1,1
endlayer

layer
1,1,1,1,1,1,1,1
1,1,1,1,1,1,1,1
1,1,2,2,2,2,1,1
1,1,2,2,2,2,1,1
1,1,2,2,2,2,1,1
1,1,2,2,2,2,1,1
1,1,2,2,2,2,1,1
1,1,2,2,2,2,1,1
1,1,1,2,2,1,1,1
1,1,1,1,1,1,1,1
1,1,1,1,1,1,1,1
1,1,1,1,1,1,1,1
endlayer

layer
1,1,1,1,1,1,1,1
1,1,1,1,1,1,1,1
1,1,1,2,2,1,1,1
1,1,2,2,2,2,1,1
1,1,2,2,2,2,1,1
1,1,2,2,2,2,1,1
1,1,2,2,2,2,1,1
1,1,2,2,2,2,1,1
1,1,2,2,2,2,1,1
1,1,1,2,2,1,1,1
1,1,1,1,1,1,1,1
1,1,1,1,1,1,1,1
endlayer

layer
1,1,1,1,1,1,1,1
1,1,1,1,1,1,1,1
1,1,1,1,1,1,1,1
1,1,1,2,2,1,1,1
1,1,2,2,2,2,1,1
1,1,2,2,2,2,1,1
1,1,2,2,2,2,1,1
1,1,2,2,2,2,1,1
1,1,2,2,2,2,1,1
1,1,1,2,2,1,1,1
1,1,1,1,1,1,1,1
1,1,1,1,1,1,1,1
endlayer

layer
1,1,1,1,1,1,1,1
1,1,1,1,1,1,1,1
1,1,1,1,1,1,1,1
1,1,1,1,1,1,1,1
1,1,1,1,1,1,1,1
1,1,1,1,1,1,1,1
1,1,1,2,2,1,1,1
1,1,2,2,2,2,1,1
1,1,2,2,2,2,1,1
1,1,1,2,2,1,1,1
1,1,1,2,2,1,1,1
1,1,1,1,1,1,1,1
endlayer

layer
1,1,1,1,1,1,1,1
1,1,1,1,1,1,1,1
1,1,1,1,1,1,1,1
1,1,1,1,1,1,1,1
1,1,1,1,1,1,1,1
1,1,1,1,1,1,1,1
1,1,1,1,1,1,1,1
1,1,1,2,2,1,1,1
1,1,2,2,2,2,1,1
1,1,2,2,2,2,1,1
1,1,1,2,2,1,1,1
1,1,1,1,1,1,1,1
endlayer

layer
1,1,1,1,1,1,1,1
1,1,1,1,1,1,1,1
1,1,1,1,1,1,1,1
1,1,1,1,1,1,1,1
1,1,1,1,1,1,1,1
1,1,1,1,1,1,1,1
1,1,1,1,1,1,1,1
1,1,1,2,2,1,1,1
1,1,2,2,2,2,1,1
1,1,2,2,2,2,1,1
1,1,1,2,2,1,1,1
1,1,1,1,1,1,1,1
endlayer

layer
1,1,1,1,1,1,1,1
1,1,1,1,1,1,1,1
1,1,1,1,1,1,1,1
1,1,1,1,1,1,1,1
1,1,1,1,1,1,1,1
1,1,1,1,1,1,1,1
1,1,1,1,1,1,1,1
1,1,1,2,2,1,1,1
1,1,2,2,2,2,1,1
1,1,1,2,2,1,1,1
1,1,1,2,2,1,1,1
1,1,1,1,1,1,1,1
endlayer

layer
1,1,1,1,1,1,1,1
1,1,1,1,1,1,1,1
1,1,1,1,1,1,1,1
1,1,1,1,1,1,1,1
1,1,1,1,1,1,1,1
1,1,1,1,1,1,1,1
1,1,1,2,2,1,1,1
1,1,1,2,2,1,1,1
1,1,1,2,2,1,1,1
1,1,1,2,2,1,1,1
1,1,1,2,2,1,1,1
1,1,1,1,1,1,1,1
endlayer

layer
1,1,1,1,1,1,1,1
1,1,1,1,1,1,1,1
1,1,1,1,1,1,1,1
1,1,1,1,1,1,1,1
1,1,1,1,1,1,1,1
1,1,1,1,1,1,1,1
1,1,1,2,2,1,1,1
1,1,1,2,2,1,1,1
1,1,1,2,2,1,1,1
1,1,1,2,2,1,1,1
1,1,1,1,1,1,1,1
1,1,1,1,1,1,1,1
endlayer

layer
1,1,1,2,2,1,1,1
1,1,1,2,2,1,1,1
1,1,2,2,2,2,1,1
1,1,2,2,2,2,1,1
1,1,2,2,2,2,1,1
1,1,2,2,2,2,1,1
1,1,2,2,2,2,1,1
1,1,2,2,2,2,1,1
1,1,1,2,2,1,1,1
1,1,1,2,2,1,1,1
1,1,1,1,1,1,1,1
1,1,1,1,1,1,1,1
endlayer

layer
1,1,2,2,2,2,1,1
1,1,2,2,2,2,1,1
1,1,2,2,2,2,1,1
1,1,2,2,2,2,1,1
1,1,2,2,2,2,1,1
1,1,2,2,2,2,1,1
1,1,2,2,2,2,1,1
1,1,2,2,2,2,1,1
1,1,1,2,2,1,1,1
1,1,1,1,1,1,1,1
1,1,1,1,1,1,1,1
1,1,1,1,1,1,1,1
endlayer

layer
1,1,2,1,1,2,1,1
1,1,1,1,1,1,1,1
1,1,1,2,2,1,1,1
1,1,2,2,2,2,1,1
1,1,0,3,3,0,1,1
1,1,0,3,3,0,1,1
1,1,2,2,2,2,1,1
1,2,2,2,2,2,2,1
1,1,1,1,1,1,1,1
1,1,1,1,1,1,1,1
1,1,1,1,1,1,1,1
1,1,1,1,1,1,1,1
endlayer

layer
1,1,1,1,1,1,1,1
1,1,1,1,1,1,1,1
1,1,1,1,1,1,1,1
1,1,2,2,2,2,1,1
1,1,2,2,2,2,1,1
1,1,2,2,2,2,1,1
1,2,2,2,2,2,2,1
2,2,2,2,2,2,2,2
2,2,2,1,1,2,2,2
1,2,1,1,1,1,2,1
1,1,1,1,1,1,1,1
1,1,1,1,1,1,1,1
endlayer

layer
1,1,1,1,1,1,1,1
1,1,1,1,1,1,1,1
1,1,1,1,1,1,1,1
1,1,1,1,1,1,1,1
1,1,1,1,1,1,1,1
1,1,1,2,2,1,1,1
1,1,2,2,2,2,1,1
1,2,1,1,1,1,2,1
2,1,1,1,1,1,1,2
2,1,1,1,1,1,1,2
2,1,1,1,1,1,1,2
2,1,1,1,1,1,1,2
endlayer

