
# Created by Ruins mod version 17.0 Ingame Parser
# authoring Player: ST753M

weight=1
embed_into_distance=1
acceptable_target_blocks=
unacceptable_target_blocks=flowing_water,water,flowing_lava,lava,ice,bedrock,end_stone,obsidian,iron_bars,Natura:Cloud,slime_grass,slime_congealed,slime_dirt,clouds,natura:clouds
dimensions=9,7,9
allowable_overhang=1
max_leveling=2
leveling_buffer=0
preserve_water=1
preserve_lava=0

biomesToSpawnIn=gravel_beach,stone_beach,black_beach,extreme_hills,mutated_extreme_hills_with_trees,extreme_hills_with_trees,crag,cliffs,darklands,darklands_forest,darklands_hills,darklands_mountains,darklands_plains,ominous_woods,eerie,swamp_defiled,hell,undergarden,visceral_heap,phantasmagoric_inferno,corrupted_sands,fungi_forest,ruthless_sands,torrid_wasteland,arctic_abyss,polar_chasm

rule1=0,100,chisel:obsidian-5
rule2=0,100,minecraft:quartz_stairs-0
rule3=0,100,chisel:obsidian-13
rule4=0,100,minecraft:quartz_stairs-1
rule5=0,100,minecraft:obsidian-0

layer
1,1,1,1,1,1,1,1,1
1,1,1,1,1,1,1,1,1
1,1,1,1,1,1,1,1,1
1,1,1,1,1,1,1,1,1
1,1,1,1,1,1,1,1,1
1,1,1,1,1,1,1,1,1
1,1,1,1,1,1,1,1,1
endlayer

layer
1,1,0,0,0,0,0,1,1
0,0,0,2,2,2,0,0,0
0,3,3,3,3,3,3,3,0
0,3,0,0,0,0,0,3,0
0,3,3,3,3,3,3,3,0
0,0,0,4,4,4,0,0,0
1,1,0,0,0,0,0,1,1
endlayer

layer
1,0,0,0,0,0,0,0,1
0,0,0,0,0,0,0,0,0
0,1,1,2,2,2,1,1,0
0,1,5,5,5,5,5,1,0
0,1,1,4,4,4,1,1,0
0,0,0,0,0,0,0,0,0
1,0,0,0,0,0,0,0,1
endlayer

layer
0,0,0,0,0,0,0,0,0
0,0,0,0,0,0,0,0,0
0,0,1,0,0,0,1,0,0
0,1,5,0,0,0,5,1,0
0,0,1,0,0,0,1,0,0
0,0,0,0,0,0,0,0,0
0,0,0,0,0,0,0,0,0
endlayer

layer
0,0,0,0,0,0,0,0,0
0,0,0,0,0,0,0,0,0
0,1,1,0,0,0,1,1,0
0,1,5,0,0,0,5,1,0
0,1,1,0,0,0,1,1,0
0,0,0,0,0,0,0,0,0
0,0,0,0,0,0,0,0,0
endlayer

layer
0,0,0,0,0,0,0,0,0
0,0,0,0,0,0,0,0,0
0,0,1,0,0,0,1,0,0
0,1,5,0,0,0,5,1,0
0,0,1,0,0,0,1,0,0
0,0,0,0,0,0,0,0,0
0,0,0,0,0,0,0,0,0
endlayer

layer
0,0,0,0,0,0,0,0,0
0,0,0,0,0,0,0,0,0
0,1,1,0,0,0,1,1,0
0,1,5,0,0,0,5,1,0
0,1,1,0,0,0,1,1,0
0,0,0,0,0,0,0,0,0
0,0,0,0,0,0,0,0,0
endlayer

layer
0,0,0,0,0,0,0,0,0
0,0,0,0,0,0,0,0,0
0,3,3,3,3,3,3,3,0
0,3,5,5,5,5,5,3,0
0,3,3,3,3,3,3,3,0
0,0,0,0,0,0,0,0,0
0,0,0,0,0,0,0,0,0
endlayer

layer
0,0,0,0,0,0,0,0,0
0,0,0,0,0,0,0,0,0
0,1,1,1,1,1,1,1,0
0,1,1,1,1,1,1,1,0
0,1,1,1,1,1,1,1,0
0,0,0,0,0,0,0,0,0
0,0,0,0,0,0,0,0,0
endlayer

