
# Created by Ruins mod version 17.0 Ingame Parser
# authoring Player: ST753M

weight=1
embed_into_distance=4
acceptable_target_blocks=
unacceptable_target_blocks=flowing_water,water,flowing_lava,lava,ice,bedrock,netherrack,nether_brick,nether_brick_fence,soul_sand,quartz_ore,end_stone,obsidian,iron_bars,Natura:Cloud,slime_grass,slime_congealed,slime_dirt,clouds,natura:clouds
dimensions=41,5,17
allowable_overhang=4
max_leveling=0
leveling_buffer=0
preserve_water=1
preserve_lava=1

biomesToSpawnIn=extreme_hills,smaller_extreme_hills,mutated_extreme_hills,mutated_extreme_hills_with_trees,extreme_hills_with_trees,highland,alps,alps_foothills,mountain,mountain_foothills,crag,cliffs,abyssal_wastelands,omothol,dark_realm

=0,100,preserveBlock
rule1=0,100,minecraft:stone-3
rule2=0,100,minecraft:cobblestone-0
rule3=0,100,minecraft:stone-5
rule4=0,100,minecraft:stone_stairs-6
rule5=0,100,minecraft:stone_stairs-7
rule6=0,100,minecraft:lapis_block-0
rule7=0,100,minecraft:stone_stairs-2
rule8=0,100,minecraft:stone_stairs-3
rule9=0,100,minecraft:stone_stairs-4
rule10=0,100,minecraft:stone_stairs-5
rule11=0,100,minecraft:stone_stairs-0
rule12=0,100,minecraft:stone_stairs-1

layer
0,0,0,0,0,0,0,0,0,0,0,0,0,0,0,0,0
0,0,0,0,0,0,1,1,0,1,1,0,0,0,0,0,0
0,0,0,0,0,1,1,1,1,1,1,1,0,0,0,0,0
0,0,0,0,0,0,1,1,0,1,1,0,0,0,0,0,0
0,0,0,0,0,0,0,0,0,0,0,0,0,0,0,0,0
endlayer

layer
0,0,0,0,0,0,0,0,0,0,0,0,0,0,0,0,0
0,0,0,0,0,0,1,1,0,1,1,0,0,0,0,0,0
0,0,0,0,0,1,1,1,1,1,1,1,0,0,0,0,0
0,0,0,0,0,0,1,1,0,1,1,0,0,0,0,0,0
0,0,0,0,0,0,0,0,0,0,0,0,0,0,0,0,0
endlayer

layer
0,0,0,0,0,0,0,0,0,0,0,0,0,0,0,0,0
0,0,0,0,0,0,1,1,0,1,1,0,0,0,0,0,0
0,0,0,0,0,1,1,1,1,1,1,1,0,0,0,0,0
0,0,0,0,0,0,1,1,0,1,1,0,0,0,0,0,0
0,0,0,0,0,0,0,0,0,0,0,0,0,0,0,0,0
endlayer

layer
0,0,0,0,0,0,0,0,0,0,0,0,0,0,0,0,0
0,0,0,0,0,0,1,1,0,1,1,0,0,0,0,0,0
0,0,0,0,0,1,1,1,1,1,1,1,0,0,0,0,0
0,0,0,0,0,0,1,1,0,1,1,0,0,0,0,0,0
0,0,0,0,0,0,0,0,0,0,0,0,0,0,0,0,0
endlayer

layer
0,0,0,0,0,0,0,0,0,0,0,0,0,0,0,0,0
0,0,0,0,0,0,1,1,0,1,1,0,0,0,0,0,0
0,0,0,0,0,1,1,1,1,1,1,1,0,0,0,0,0
0,0,0,0,0,0,1,1,0,1,1,0,0,0,0,0,0
0,0,0,0,0,0,0,0,0,0,0,0,0,0,0,0,0
endlayer

layer
0,0,0,0,0,0,0,0,0,0,0,0,0,0,0,0,0
0,0,0,0,0,0,1,1,0,1,1,0,0,0,0,0,0
0,0,0,0,0,1,1,1,1,1,1,1,0,0,0,0,0
0,0,0,0,0,0,1,1,0,1,1,0,0,0,0,0,0
0,0,0,0,0,0,0,0,0,0,0,0,0,0,0,0,0
endlayer

layer
0,0,0,0,0,0,0,0,0,0,0,0,0,0,0,0,0
0,0,0,0,0,0,1,1,0,1,1,0,0,0,0,0,0
0,0,0,0,0,1,1,1,1,1,1,1,0,0,0,0,0
0,0,0,0,0,0,1,1,0,1,1,0,0,0,0,0,0
0,0,0,0,0,0,0,0,0,0,0,0,0,0,0,0,0
endlayer

layer
0,0,0,0,0,0,0,0,0,0,0,0,0,0,0,0,0
0,0,0,0,0,0,1,1,0,1,1,0,0,0,0,0,0
0,0,0,0,0,1,1,1,1,1,1,1,0,0,0,0,0
0,0,0,0,0,0,1,1,0,1,1,0,0,0,0,0,0
0,0,0,0,0,0,0,0,0,0,0,0,0,0,0,0,0
endlayer

layer
0,0,0,0,0,0,0,0,0,0,0,0,0,0,0,0,0
0,0,0,0,0,0,1,1,0,1,1,0,0,0,0,0,0
0,0,0,0,0,1,1,1,1,1,1,1,0,0,0,0,0
0,0,0,0,0,0,1,1,0,1,1,0,0,0,0,0,0
0,0,0,0,0,0,0,0,0,0,0,0,0,0,0,0,0
endlayer

layer
0,0,0,0,0,0,0,0,0,0,0,0,0,0,0,0,0
0,0,0,0,0,0,1,1,0,1,1,0,0,0,0,0,0
0,0,0,0,0,1,1,1,1,1,1,1,0,0,0,0,0
0,0,0,0,0,0,1,1,0,1,1,0,0,0,0,0,0
0,0,0,0,0,0,0,0,0,0,0,0,0,0,0,0,0
endlayer

layer
0,0,0,0,0,0,0,0,0,0,0,0,0,0,0,0,0
0,0,0,0,0,0,1,1,0,1,1,0,0,0,0,0,0
0,0,0,0,0,1,1,1,1,1,1,1,0,0,0,0,0
0,0,0,0,0,0,1,1,0,1,1,0,0,0,0,0,0
0,0,0,0,0,0,0,0,0,0,0,0,0,0,0,0,0
endlayer

layer
0,0,0,0,0,0,0,0,0,0,0,0,0,0,0,0,0
0,0,0,0,0,0,1,1,0,1,1,0,0,0,0,0,0
0,0,0,0,0,1,1,1,1,1,1,1,0,0,0,0,0
0,0,0,0,0,0,1,1,0,1,1,0,0,0,0,0,0
0,0,0,0,0,0,0,0,0,0,0,0,0,0,0,0,0
endlayer

layer
0,0,0,0,0,0,0,0,0,0,0,0,0,0,0,0,0
0,0,0,0,0,0,1,1,0,1,1,0,0,0,0,0,0
0,0,0,0,0,1,1,1,1,1,1,1,0,0,0,0,0
0,0,0,0,0,0,1,1,0,1,1,0,0,0,0,0,0
0,0,0,0,0,0,0,0,0,0,0,0,0,0,0,0,0
endlayer

layer
0,0,0,0,0,0,0,0,0,0,0,0,0,0,0,0,0
0,0,0,0,0,0,1,1,0,1,1,0,0,0,0,0,0
0,0,0,0,0,1,1,1,1,1,1,1,0,0,0,0,0
0,0,0,0,0,0,1,1,0,1,1,0,0,0,0,0,0
0,0,0,0,0,0,0,0,0,0,0,0,0,0,0,0,0
endlayer

layer
0,0,0,0,0,0,0,0,0,0,0,0,0,0,0,0,0
0,0,0,0,0,0,1,1,0,1,1,0,0,0,0,0,0
0,0,0,0,0,1,1,1,1,1,1,1,0,0,0,0,0
0,0,0,0,0,0,1,1,0,1,1,0,0,0,0,0,0
0,0,0,0,0,0,0,0,0,0,0,0,0,0,0,0,0
endlayer

layer
0,0,0,0,0,0,0,0,0,0,0,0,0,0,0,0,0
0,0,0,0,0,0,1,1,0,1,1,0,0,0,0,0,0
0,0,0,0,0,1,1,1,1,1,1,1,0,0,0,0,0
0,0,0,0,0,0,1,1,0,1,1,0,0,0,0,0,0
0,0,0,0,0,0,0,0,0,0,0,0,0,0,0,0,0
endlayer

layer
0,0,0,0,0,0,0,0,0,0,0,0,0,0,0,0,0
0,0,0,0,0,0,1,1,0,1,1,0,0,0,0,0,0
0,0,0,0,0,1,1,1,1,1,1,1,0,0,0,0,0
0,0,0,0,0,0,1,1,0,1,1,0,0,0,0,0,0
0,0,0,0,0,0,0,0,0,0,0,0,0,0,0,0,0
endlayer

layer
0,0,0,0,0,0,0,0,0,0,0,0,0,0,0,0,0
0,0,0,0,0,0,1,1,0,1,1,0,0,0,0,0,0
0,0,0,0,0,1,1,1,1,1,1,1,0,0,0,0,0
0,0,0,0,0,0,1,1,0,1,1,0,0,0,0,0,0
0,0,0,0,0,0,0,0,0,0,0,0,0,0,0,0,0
endlayer

layer
0,0,0,0,0,0,0,0,0,0,0,0,0,0,0,0,0
0,0,0,0,0,0,1,1,0,1,1,0,0,0,0,0,0
0,0,0,0,0,1,1,1,1,1,1,1,0,0,0,0,0
0,0,0,0,0,0,1,1,0,1,1,0,0,0,0,0,0
0,0,0,0,0,0,0,0,0,0,0,0,0,0,0,0,0
endlayer

layer
0,0,0,0,0,0,0,0,0,0,0,0,0,0,0,0,0
0,0,0,0,0,0,1,1,0,1,1,0,0,0,0,0,0
0,0,0,0,0,1,1,1,1,1,1,1,0,0,0,0,0
0,0,0,0,0,0,1,1,0,1,1,0,0,0,0,0,0
0,0,0,0,0,0,0,0,0,0,0,0,0,0,0,0,0
endlayer

layer
0,0,0,0,0,0,0,0,0,0,0,0,0,0,0,0,0
0,0,0,0,0,0,1,1,1,1,1,0,0,0,0,0,0
0,0,0,0,0,1,1,1,1,1,1,1,0,0,0,0,0
0,0,0,0,0,0,1,1,1,1,1,0,0,0,0,0,0
0,0,0,0,0,0,0,0,0,0,0,0,0,0,0,0,0
endlayer

layer
0,0,0,0,0,0,0,0,0,0,0,0,0,0,0,0,0
0,0,0,0,0,0,1,1,1,1,1,0,0,0,0,0,0
0,0,0,0,0,1,1,1,1,1,1,1,0,0,0,0,0
0,0,0,0,0,0,1,1,1,1,1,0,0,0,0,0,0
0,0,0,0,0,0,0,0,0,0,0,0,0,0,0,0,0
endlayer

layer
0,0,0,0,0,0,0,0,0,0,0,0,0,0,0,0,0
0,0,0,0,0,0,0,1,1,1,0,0,0,0,0,0,0
0,0,0,0,0,0,1,1,1,1,1,0,0,0,0,0,0
0,0,0,0,0,0,0,1,1,1,0,0,0,0,0,0,0
0,0,0,0,0,0,0,0,0,0,0,0,0,0,0,0,0
endlayer

layer
0,0,0,0,0,0,0,0,0,0,0,0,0,0,0,0,0
2,2,0,0,0,0,0,1,1,1,0,0,0,0,0,2,2
2,2,2,0,0,0,1,1,1,1,1,0,0,0,2,2,2
2,2,0,0,0,0,0,1,1,1,0,0,0,0,0,2,2
0,0,0,0,0,0,0,0,0,0,0,0,0,0,0,0,0
endlayer

layer
0,0,0,0,0,0,0,0,0,0,0,0,0,0,0,0,0
2,2,2,0,0,0,0,0,1,0,0,0,0,0,2,2,2
2,3,3,2,0,0,0,1,1,1,0,0,0,2,3,3,2
2,2,2,0,0,0,0,0,1,0,0,0,0,0,2,2,2
0,0,0,0,0,0,0,0,0,0,0,0,0,0,0,0,0
endlayer

layer
0,0,0,0,0,0,0,0,0,0,0,0,0,0,0,0,0
2,2,2,2,0,0,0,0,0,0,0,0,0,2,2,2,2
2,3,3,3,2,0,0,1,1,1,0,0,2,3,3,3,2
2,2,2,2,0,0,0,0,0,0,0,0,0,2,2,2,2
0,0,0,0,0,0,0,0,0,0,0,0,0,0,0,0,0
endlayer

layer
0,0,0,0,0,5,2,2,2,2,2,4,0,0,0,0,0
0,2,2,2,2,2,2,2,2,2,2,2,2,2,2,2,0
2,3,3,3,3,2,2,3,3,3,2,2,3,3,3,3,2
0,2,2,2,2,2,2,2,2,2,2,2,2,2,2,2,0
0,0,0,0,0,5,2,2,2,2,2,4,0,0,0,0,0
endlayer

layer
0,0,0,0,0,2,2,2,6,2,2,2,0,0,0,0,0
0,0,2,2,2,3,3,3,3,3,3,3,2,2,2,0,0
0,2,3,3,3,3,3,3,3,3,3,3,3,3,3,2,0
0,0,2,2,2,3,3,3,3,3,3,3,2,2,2,0,0
0,0,0,0,0,2,2,2,6,2,2,2,0,0,0,0,0
endlayer

layer
0,0,0,0,0,8,2,2,2,2,2,7,0,0,0,0,0
0,0,0,2,2,2,2,3,3,3,2,2,2,2,0,0,0
0,0,2,2,2,2,2,2,3,2,2,2,2,2,2,0,0
0,0,0,2,2,2,2,3,3,3,2,2,2,2,0,0,0
0,0,0,0,0,8,2,2,2,2,2,7,0,0,0,0,0
endlayer

layer
0,0,0,0,0,0,0,0,0,0,0,0,0,0,0,0,0
0,0,0,0,0,0,0,2,2,7,0,0,0,0,0,0,0
0,0,0,0,0,0,0,10,2,9,0,0,0,0,0,0,0
0,0,0,0,0,0,0,8,2,2,0,0,0,0,0,0,0
0,0,0,0,0,0,0,0,0,0,0,0,0,0,0,0,0
endlayer

layer
0,0,0,0,0,0,0,0,0,0,0,0,0,0,0,0,0
0,0,0,0,0,0,0,2,7,9,0,0,0,0,0,0,0
0,0,0,0,0,0,0,2,2,2,0,0,0,0,0,0,0
0,0,0,0,0,0,0,10,8,2,0,0,0,0,0,0,0
0,0,0,0,0,0,0,0,0,0,0,0,0,0,0,0,0
endlayer

layer
0,0,0,0,0,0,0,0,0,0,0,0,0,0,0,0,0
0,0,0,0,0,0,0,11,5,2,0,0,0,0,0,0,0
0,0,0,0,0,0,0,2,2,2,0,0,0,0,0,0,0
0,0,0,0,0,0,0,2,4,12,0,0,0,0,0,0,0
0,0,0,0,0,0,0,0,0,0,0,0,0,0,0,0,0
endlayer

layer
0,0,0,0,0,0,0,0,0,0,0,0,0,0,0,0,0
0,0,0,0,0,0,0,5,2,2,0,0,0,0,0,0,0
0,0,0,0,0,0,0,11,2,12,0,0,0,0,0,0,0
0,0,0,0,0,0,0,2,2,4,0,0,0,0,0,0,0
0,0,0,0,0,0,0,0,0,0,0,0,0,0,0,0,0
endlayer

layer
0,0,0,0,0,0,0,0,0,0,0,0,0,0,0,0,0
0,0,0,0,0,0,0,2,2,7,0,0,0,0,0,0,0
0,0,0,0,0,0,0,10,2,9,0,0,0,0,0,0,0
0,0,0,0,0,0,0,8,2,2,0,0,0,0,0,0,0
0,0,0,0,0,0,0,0,0,0,0,0,0,0,0,0,0
endlayer

layer
0,0,0,0,0,0,0,0,0,0,0,0,0,0,0,0,0
0,0,0,0,0,0,0,2,7,9,0,0,0,0,0,0,0
0,0,0,0,0,0,0,2,2,2,0,0,0,0,0,0,0
0,0,0,0,0,0,0,10,8,2,0,0,0,0,0,0,0
0,0,0,0,0,0,0,0,0,0,0,0,0,0,0,0,0
endlayer

layer
0,0,0,0,0,0,0,0,0,0,0,0,0,0,0,0,0
0,0,0,0,0,0,0,11,5,2,0,0,0,0,0,0,0
0,0,0,0,0,0,0,2,2,2,0,0,0,0,0,0,0
0,0,0,0,0,0,0,2,4,12,0,0,0,0,0,0,0
0,0,0,0,0,0,0,0,0,0,0,0,0,0,0,0,0
endlayer

layer
0,0,0,0,0,0,0,0,0,0,0,0,0,0,0,0,0
0,0,0,0,0,0,0,5,2,2,0,0,0,0,0,0,0
0,0,0,0,0,0,0,11,2,12,0,0,0,0,0,0,0
0,0,0,0,0,0,0,2,2,4,0,0,0,0,0,0,0
0,0,0,0,0,0,0,0,0,0,0,0,0,0,0,0,0
endlayer

layer
0,0,0,0,0,0,0,1,1,1,0,0,0,0,0,0,0
0,0,0,0,0,0,1,3,3,3,1,0,0,0,0,0,0
0,0,0,0,0,0,1,3,3,3,1,0,0,0,0,0,0
0,0,0,0,0,0,1,3,3,3,1,0,0,0,0,0,0
0,0,0,0,0,0,0,1,1,1,0,0,0,0,0,0,0
endlayer

layer
0,0,0,0,0,0,0,1,1,1,0,0,0,0,0,0,0
0,0,0,0,0,0,1,1,1,1,1,0,0,0,0,0,0
0,0,0,0,0,0,1,1,1,1,1,0,0,0,0,0,0
0,0,0,0,0,0,1,1,1,1,1,0,0,0,0,0,0
0,0,0,0,0,0,0,1,1,1,0,0,0,0,0,0,0
endlayer

layer
0,0,0,0,0,0,0,1,1,1,0,0,0,0,0,0,0
0,0,0,0,0,0,1,1,1,1,1,0,0,0,0,0,0
0,0,0,0,0,0,1,1,1,1,1,0,0,0,0,0,0
0,0,0,0,0,0,1,1,1,1,1,0,0,0,0,0,0
0,0,0,0,0,0,0,1,1,1,0,0,0,0,0,0,0
endlayer

layer
0,0,0,0,0,0,0,0,0,0,0,0,0,0,0,0,0
0,0,0,0,0,0,0,1,1,1,0,0,0,0,0,0,0
0,0,0,0,0,0,0,1,1,1,0,0,0,0,0,0,0
0,0,0,0,0,0,0,1,1,1,0,0,0,0,0,0,0
0,0,0,0,0,0,0,0,0,0,0,0,0,0,0,0,0
endlayer

