
# Created by Ruins mod version 17.0 Ingame Parser
# authoring Player: ST753M

weight=1
embed_into_distance=6
acceptable_target_blocks=
unacceptable_target_blocks=flowing_water,water,flowing_lava,lava,ice,bedrock,netherrack,nether_brick,nether_brick_fence,soul_sand,quartz_ore,end_stone,obsidian,iron_bars,Natura:Cloud,slime_grass,slime_congealed,slime_dirt,clouds,natura:clouds,twilightforest:wispy_cloud,twilightforest:fluffy_cloud
dimensions=9,14,16
allowable_overhang=6
max_leveling=0
leveling_buffer=0
preserve_water=0
preserve_lava=0

biomesToSpawnIn=savanna,savanna_rock,mutated_savanna,mutated_savanna_rock,brushland,steppe,wasteland,tundra,outback,badlands,desert_shrubland,arid_highland,extreme_hills,smaller_extreme_hills,mutated_extreme_hills,mutated_extreme_hills_with_trees,extreme_hills_with_trees,highland,alps,alps_foothills,mountain,mountain_foothills,crag,cliffs

=0,100,air
rule1=0,100,preserveBlock

rule2=0,50,minecraft:stone-0
^0,50,minecraft:stone-0
^0,50,minecraft:stone-1
^0,50,minecraft:stone-5
^0,50,minecraft:cobblestone-0,minecraft:mossy_cobblestone-0
^0,50,minecraft:cobblestone-0,minecraft:mossy_cobblestone-0

rule3^0,100,minecraft:stone-0
^0,100,minecraft:stone-0
^0,100,minecraft:stone-1
^0,100,minecraft:stone-5
^0,100,minecraft:cobblestone-0,minecraft:mossy_cobblestone-0
^0,100,minecraft:cobblestone-0,minecraft:mossy_cobblestone-0

rule4=0,100,minecraft:planks-1
rule5=0,100,minecraft:planks-0
rule6=0,100,minecraft:fence-0
rule7=0,100,minecraft:bed-9
rule8=0,100,minecraft:bed-1
rule9=0,100,minecraft:oak_stairs-1
rule10=0,100,minecraft:spruce_door-1
rule11=0,100,minecraft:oak_stairs-3
rule12=0,100,minecraft:oak_stairs-2
rule13=0,100,minecraft:oak_stairs-0
rule14=0,100,IInventory;minecraft:chest;minecraft:flint#2#0#2+minecraft:log#6#0#4+minecraft:mushroom_stew#1#0#7+minecraft:shears#1#0#9+minecraft:sapling#3#0#12+minecraft:flint#1#0#15+minecraft:log#4#0#17+minecraft:log#3#0#18+minecraft:mushroom_stew#1#0#20+minecraft:sapling#1#0#23+minecraft:flint#3#0#26-4
rule15=0,100,minecraft:crafting_table-0
rule16=0,100,minecraft:spruce_door-0
rule17=0,100,minecraft:spruce_stairs-2
rule18=0,100,minecraft:carpet-13
rule19=0,100,minecraft:bookshelf-0
rule20=0,100,minecraft:green_glazed_terracotta-1
rule21=0,100,minecraft:spruce_door-8
rule22=0,100,minecraft:green_glazed_terracotta-0
rule23=0,100,minecraft:spruce_stairs-7
rule24=0,100,minecraft:spruce_stairs-5
rule25=0,100,minecraft:green_glazed_terracotta-2
rule26=0,100,minecraft:spruce_stairs-6
rule27=0,100,minecraft:green_glazed_terracotta-3
rule28=0,100,minecraft:spruce_stairs-4
rule29=0,100,minecraft:spruce_stairs-1
rule30=0,100,minecraft:spruce_stairs-3

layer
1,1,1,1,1,1,1,1,1,1,1,1,1,1,1,1
1,1,1,1,1,1,1,1,1,1,1,1,1,1,1,1
1,1,1,1,1,2,2,1,1,1,1,1,1,1,1,1
1,1,1,3,3,3,3,3,2,1,1,1,1,1,1,1
1,1,2,3,3,3,3,3,3,3,2,1,1,1,1,1
1,2,3,3,3,3,3,3,3,3,3,3,3,2,1,1
1,2,3,3,3,3,3,3,3,3,3,3,3,3,1,1
1,1,2,3,3,3,3,3,3,3,3,3,3,3,2,1
1,1,1,3,3,3,3,3,3,3,3,3,3,3,2,1
1,1,1,2,3,3,3,3,3,3,3,3,3,2,1,1
1,1,1,1,1,2,3,3,3,3,3,3,3,1,1,1
1,1,1,1,1,1,1,2,3,3,3,2,1,1,1,1
1,1,1,1,1,1,1,1,1,1,1,1,1,1,1,1
1,1,1,1,1,1,1,1,1,1,1,1,1,1,1,1
endlayer

layer
1,1,1,1,1,1,1,1,1,1,1,1,1,1,1,1
1,1,1,1,2,2,1,1,1,1,1,1,1,1,1,1
1,1,2,3,3,3,3,2,1,1,1,1,1,1,1,1
1,1,3,4,4,4,4,3,3,3,2,1,1,1,1,1
1,2,3,4,4,4,4,3,3,3,3,3,3,2,1,1
2,3,3,4,4,4,4,3,4,4,4,4,4,3,1,1
2,3,3,4,4,4,4,4,4,4,4,4,4,3,2,1
1,2,3,4,4,4,4,3,4,4,4,4,4,3,3,2
1,1,3,4,4,4,4,3,4,4,4,4,4,3,3,2
1,1,2,3,3,3,3,3,4,4,4,4,4,3,3,1
1,1,1,1,2,3,3,3,4,4,4,4,4,3,2,1
1,1,1,1,1,2,3,3,3,3,3,3,3,2,1,1
1,1,1,1,1,1,2,3,3,3,2,1,1,1,1,1
1,1,1,1,1,1,1,1,2,2,1,1,1,1,1,1
endlayer

layer
1,1,1,1,2,2,1,1,1,1,1,1,1,1,1,1
1,1,2,3,3,3,3,2,1,1,1,1,1,1,1,1
1,2,3,5,5,5,5,3,3,3,2,1,1,1,1,1
1,3,5,6,7,7,6,5,3,3,3,3,3,1,1,1
2,3,5,0,8,8,0,5,5,5,5,5,5,3,2,1
3,3,5,0,0,0,0,5,0,0,0,0,0,5,3,1
3,3,5,0,0,0,0,10,0,0,9,0,0,5,3,2
2,3,5,0,9,0,0,5,0,12,6,11,0,5,3,3
1,3,5,6,6,0,14,5,0,0,13,0,0,5,3,3
1,2,3,5,5,5,5,5,0,0,0,0,0,5,3,2
1,1,2,3,3,3,3,5,0,0,15,15,15,5,3,1
1,1,1,1,2,3,3,5,5,16,5,5,5,3,2,1
1,1,1,1,1,2,3,3,17,0,3,3,3,1,1,1
1,1,1,1,1,1,1,2,3,3,3,2,1,1,1,1
endlayer

layer
1,1,1,2,3,3,2,1,1,1,1,1,1,1,1,1
1,2,3,3,3,3,3,3,2,1,1,1,1,1,1,1
1,3,3,5,5,5,5,3,3,3,3,3,1,1,1,1
2,3,5,18,0,0,18,5,3,3,3,3,3,2,1,1
3,3,5,0,0,0,0,5,19,19,19,19,19,3,2,1
3,3,20,0,0,0,0,5,0,0,0,0,0,5,3,2
3,3,22,0,0,0,0,21,0,0,0,0,0,5,3,3
3,3,5,0,0,0,0,5,0,0,18,0,0,5,3,3
2,3,5,18,18,0,0,5,0,0,0,0,0,5,3,3
1,3,3,5,5,5,5,5,0,0,0,0,0,5,3,3
1,2,3,3,3,3,3,5,0,0,0,0,0,5,3,2
1,1,1,2,3,3,3,5,5,21,5,5,5,3,2,1
1,1,1,1,2,3,3,17,0,0,3,3,3,2,1,1
1,1,1,1,1,3,3,3,3,3,3,3,2,1,1,1
endlayer

layer
1,1,1,2,3,3,3,2,1,1,1,1,1,1,1,1
1,2,3,3,3,3,3,3,2,1,1,1,1,1,1,1
1,3,3,5,5,5,5,3,3,3,3,2,1,1,1,1
2,3,5,0,0,0,0,5,3,3,3,3,3,2,1,1
3,3,5,0,0,0,0,5,5,5,5,5,5,3,1,1
3,3,25,0,0,0,0,5,24,24,24,24,23,5,3,2
3,3,27,0,0,0,0,5,26,0,0,0,23,5,3,3
3,3,5,0,0,0,0,5,26,0,0,0,23,5,3,3
2,3,5,0,0,0,0,5,26,0,0,0,23,5,3,3
1,3,3,5,5,5,5,5,26,0,0,0,23,5,3,2
1,2,3,3,3,3,3,5,26,28,28,28,23,5,3,1
1,1,1,2,3,3,29,5,5,5,5,5,5,3,1,1
1,1,1,1,1,3,0,0,0,0,3,3,3,2,1,1
1,1,1,1,1,2,3,3,3,3,2,1,1,1,1,1
endlayer

layer
1,1,1,1,1,2,1,1,1,1,1,1,1,1,1,1
1,1,2,3,3,3,3,3,1,1,1,1,1,1,1,1
1,2,3,5,5,5,5,3,3,2,1,1,1,1,1,1
1,3,5,24,24,24,24,5,3,3,3,2,1,1,1,1
2,3,5,26,0,0,23,5,3,3,3,3,3,2,1,1
3,3,5,26,0,0,23,5,4,4,4,4,4,3,1,1
3,3,5,26,0,0,23,5,4,4,4,4,4,3,2,1
2,3,5,26,0,0,23,5,4,4,4,4,4,3,3,2
1,3,5,28,28,28,28,5,4,4,4,4,4,3,3,2
1,2,3,5,5,5,5,5,4,4,4,4,4,3,2,1
1,1,2,3,3,3,29,5,4,4,4,4,4,3,1,1
1,1,1,1,2,3,0,5,5,5,3,3,3,2,1,1
1,1,1,1,1,2,0,0,0,3,3,2,1,1,1,1
1,1,1,1,1,1,2,3,3,2,1,1,1,1,1,1
endlayer

layer
1,1,1,1,1,1,1,1,1,1,1,1,1,1,1,1
1,1,1,1,2,3,2,1,1,1,1,1,1,1,1,1
1,1,2,3,3,3,3,3,1,1,1,1,1,1,1,1
1,1,3,4,4,4,4,3,2,1,1,1,1,1,1,1
1,2,3,4,4,4,4,3,3,3,2,1,1,1,1,1
2,3,3,4,4,4,4,3,3,3,3,3,3,2,1,1
2,3,3,4,4,4,4,3,3,3,3,3,3,3,1,1
1,2,3,4,4,4,4,3,3,3,3,3,3,3,2,1
1,1,3,4,4,4,4,3,3,3,3,3,3,3,2,1
1,1,2,3,3,3,29,3,3,3,3,3,3,2,1,1
1,1,1,1,2,2,0,3,3,3,3,3,3,1,1,1
1,1,1,1,1,1,0,3,3,3,3,2,1,1,1,1
1,1,1,1,1,1,0,3,3,2,1,1,1,1,1,1
1,1,1,1,1,1,1,2,2,1,1,1,1,1,1,1
endlayer

layer
1,1,1,1,1,1,1,1,1,1,1,1,1,1,1,1
1,1,1,1,1,1,1,1,1,1,1,1,1,1,1,1
1,1,1,1,2,3,2,1,1,1,1,1,1,1,1,1
1,1,0,3,3,3,3,1,1,1,1,1,1,1,1,1
1,1,2,3,3,3,3,2,1,1,1,1,1,1,1,1
1,2,3,3,3,3,3,3,2,1,1,1,1,1,1,1
1,2,3,3,3,3,3,3,3,3,2,1,1,1,1,1
1,1,3,3,3,3,3,3,3,3,3,2,1,1,1,1
1,1,2,3,3,3,0,30,3,3,3,3,2,1,1,1
1,1,1,1,1,2,0,3,3,3,3,2,1,1,1,1
1,1,1,1,1,1,0,3,3,2,2,1,1,1,1,1
1,1,1,1,1,1,0,2,2,1,1,1,1,1,1,1
1,1,1,1,1,1,1,1,1,1,1,1,1,1,1,1
1,1,1,1,1,1,1,1,1,1,1,1,1,1,1,1
endlayer

layer
1,1,1,1,1,1,1,1,1,1,1,1,1,1,1,1
1,1,1,1,1,1,1,1,1,1,1,1,1,1,1,1
1,1,1,1,1,1,1,1,1,1,1,1,1,1,1,1
1,1,0,0,2,2,1,1,1,1,1,1,1,1,1,1
1,1,0,2,3,3,2,1,1,1,1,1,1,1,1,1
1,1,2,3,3,3,3,2,1,1,1,1,1,1,1,1
1,1,2,3,3,3,2,1,1,1,1,1,1,1,1,1
1,1,1,2,3,2,1,1,2,2,1,1,1,1,1,1
1,1,1,1,2,1,0,0,0,2,2,1,1,1,1,1
1,1,1,1,1,1,0,0,0,1,1,1,1,1,1,1
1,1,1,1,1,1,0,1,1,1,1,1,1,1,1,1
1,1,1,1,1,1,1,1,1,1,1,1,1,1,1,1
1,1,1,1,1,1,1,1,1,1,1,1,1,1,1,1
1,1,1,1,1,1,1,1,1,1,1,1,1,1,1,1
endlayer

