
# Created by Ruins mod version 17.1 Ingame Parser
# authoring Player: ST753M

weight=1
embed_into_distance=50
random_height_offset=-20,20
acceptable_target_blocks=
unacceptable_target_blocks=water,flowing_lava,lava,ice,bedrock,netherrack,nether_brick,nether_brick_fence,soul_sand,quartz_ore,end_stone,obsidian,iron_bars,Natura:Cloud,slime_grass,slime_congealed,slime_dirt,clouds,natura:clouds,twilightforest:wispy_cloud,twilightforest:fluffy_cloud
dimensions=46,13,13
allowable_overhang=30
max_leveling=0
leveling_buffer=0
preserve_water=0
preserve_lava=0

biomesToSpawnIn=beaches,swampland,mutated_swampland,wetland,quagmire,lush_swamp,mangrove,marsh,bayou,bog,bamboo_forest,dead_swamp,moor,dead_swamp,coralium_infested_swamp,forest,maple_woods,boreal_forest,forest_hills,woodland,seasonal_forest,temperate_rainforest,fen,grove,sacred_springs,land_of_lakes,forested_hills,lush_hills,thicket,jungle,jungle_edge,jungle_hills,tropical_island,tropical_rainforest,rainforest,mutated_jungle,mutated_jungle_edge,bamboo_forest,overgrown_cliffs,eucalyptus_forest,mini_jungle,taiga,taiga_hills,mutated_redwood_taiga,mutated_redwood_taiga_hills,redwood_taiga,mutated_taiga,redwood_taiga_hills,redwood_forest,coniferous_forest,shield,dead_forest,autumnal_wooded_hills,autumnal_woods,extreme_hills,smaller_extreme_hills,mutated_extreme_hills,mutated_extreme_hills_with_trees,extreme_hills_with_trees,highland,alps,alps_foothills,mountain,mountain_foothills,crag,cliffs,savanna,savanna_rock,mutated_savanna,mutated_savanna_rock,brushland,steppe,wasteland,tundra,outback,badlands,desert_shrubland,arid_highland

=0,100,air
rule1=0,100,preserveBlock
rule2=0,100,minecraft:stonebrick-2,minecraft:stonebrick-0,minecraft:stonebrick-1,minecraft:stonebrick-2,minecraft:monster_egg-2,minecraft:monster_egg-3,minecraft:monster_egg-4,minecraft:stone_brick_stairs-5,minecraft:stone_brick_stairs-0,minecraft:stone_brick_stairs-6,minecraft:stone_brick_stairs-3
rule3=0,100,minecraft:stonebrick-2,minecraft:stonebrick-0,minecraft:stonebrick-1,minecraft:stonebrick-2,minecraft:monster_egg-2,minecraft:monster_egg-3,minecraft:monster_egg-4
rule4=0,100,minecraft:stone_brick_stairs-0
rule5=0,100,minecraft:stone_brick_stairs-5
rule6=0,100,ChestGenHook:chests/simple_dungeon:4-4
rule7=0,100,minecraft:stone_brick_stairs-6
rule8=0,100,minecraft:stone_brick_stairs-3
rule9=0,100,MobSpawner:skeleton,MobSpawner:zombie,MobSpawner:cave_spider,MobSpider:spider,minecraft:stonebrick-3,minecraft:stonebrick-3,minecraft:stonebrick-3,minecraft:stonebrick-3
rule10=0,100,minecraft:stone_brick_stairs-4
rule11=0,100,minecraft:stone_brick_stairs-1
rule12=0,100,minecraft:stone_brick_stairs-7
rule13=0,100,minecraft:stone_brick_stairs-2

layer
1,1,1,2,2,2,2,2,2,2,1,1,1
1,1,2,2,2,3,3,3,2,2,2,1,1
1,2,2,3,3,3,3,3,3,3,2,2,1
2,2,3,3,3,3,3,3,3,3,3,2,2
2,2,3,3,3,3,3,3,3,3,3,2,2
2,3,3,3,3,3,3,3,3,3,3,3,2
2,3,3,3,3,3,3,3,3,3,3,3,2
2,3,3,3,3,3,3,3,3,3,3,3,2
2,2,3,3,3,3,3,3,3,3,3,2,2
2,2,3,3,3,3,3,3,3,3,3,2,2
1,2,2,3,3,3,3,3,3,3,2,2,1
1,1,2,2,2,3,3,3,2,2,2,1,1
1,1,1,2,2,2,2,2,2,2,1,1,1
endlayer

layer
1,1,1,2,2,2,2,2,2,2,1,1,1
1,1,2,2,2,0,0,0,2,2,2,1,1
1,2,2,0,0,0,0,0,0,0,2,2,1
2,2,0,0,0,0,0,0,0,0,0,2,2
2,2,0,0,0,0,0,0,0,0,0,2,2
2,0,0,0,0,0,0,0,0,0,0,0,2
2,4,4,4,0,0,0,0,0,0,0,0,2
2,3,3,3,0,0,0,0,0,0,0,0,2
2,2,5,5,0,0,0,0,0,0,0,2,2
2,2,0,0,0,0,0,0,0,0,0,2,2
1,2,2,0,0,0,0,0,0,0,2,2,1
1,1,2,2,2,0,6,0,2,2,2,1,1
1,1,1,2,2,2,2,2,2,2,1,1,1
endlayer

layer
1,1,1,2,2,2,2,2,2,2,1,1,1
1,1,2,2,2,0,0,0,2,2,2,1,1
1,2,2,0,0,0,0,0,0,0,2,2,1
2,2,0,0,0,0,0,0,0,0,0,2,2
2,2,0,0,0,0,0,0,0,0,0,2,2
2,0,0,0,0,0,0,0,0,0,0,0,2
2,0,0,0,0,0,0,0,0,0,0,0,2
2,4,4,4,0,0,0,0,0,0,0,0,2
2,2,3,3,3,0,0,0,0,0,0,2,2
2,2,3,7,5,0,0,0,0,0,0,2,2
1,2,2,7,0,0,0,0,0,0,2,2,1
1,1,2,2,2,0,0,0,2,2,2,1,1
1,1,1,2,2,2,2,2,2,2,1,1,1
endlayer

layer
1,1,1,2,2,2,2,2,2,2,1,1,1
1,1,2,2,2,0,0,0,2,2,2,1,1
1,2,2,0,0,0,0,0,0,0,2,2,1
2,2,0,0,0,0,0,0,0,0,0,2,2
2,2,0,0,0,0,0,0,0,0,0,2,2
2,0,0,0,0,0,0,0,0,0,0,0,2
2,0,0,0,0,0,0,0,0,0,0,0,2
2,0,0,0,0,0,0,0,0,0,0,0,2
2,2,4,4,4,0,0,0,0,0,0,2,2
2,2,3,3,3,7,0,0,0,0,0,2,2
1,2,2,3,3,7,0,0,0,0,2,2,1
1,1,2,2,2,7,0,0,2,2,2,1,1
1,1,1,2,2,2,2,2,2,2,1,1,1
endlayer

layer
1,1,1,2,2,2,2,2,2,2,1,1,1
1,1,2,2,2,0,0,0,2,2,2,1,1
1,2,2,0,0,0,0,0,0,0,2,2,1
2,2,0,0,0,0,0,0,0,0,0,2,2
2,2,0,0,0,0,0,0,0,0,0,2,2
2,0,0,0,0,0,0,0,0,0,0,0,2
2,0,0,0,0,0,0,0,0,0,0,0,2
2,0,0,0,0,0,0,0,0,0,0,0,2
2,2,0,0,0,0,0,0,0,0,0,2,2
2,2,0,0,4,3,7,0,0,0,0,2,2
1,2,2,0,8,3,7,0,0,0,2,2,1
1,1,2,2,2,3,7,0,2,2,2,1,1
1,1,1,2,2,2,2,2,2,2,1,1,1
endlayer

layer
1,1,1,2,2,2,2,2,2,2,1,1,1
1,1,2,2,2,0,0,0,2,2,2,1,1
1,2,2,0,0,0,0,0,0,0,2,2,1
2,2,0,0,0,0,0,0,0,0,0,2,2
2,2,0,0,0,0,0,0,0,0,0,2,2
2,0,0,0,0,0,0,0,0,0,0,0,2
2,0,0,0,0,0,0,0,0,0,0,0,2
2,0,0,0,0,0,0,0,0,0,0,0,2
2,2,0,0,0,0,0,0,0,0,0,2,2
2,2,0,0,0,8,3,7,0,0,0,2,2
1,2,2,0,0,8,3,7,0,0,2,2,1
1,1,2,2,2,8,3,3,2,2,2,1,1
1,1,1,2,2,2,2,2,2,2,1,1,1
endlayer

layer
1,1,1,2,2,2,2,2,2,2,1,1,1
1,1,2,2,2,0,0,0,2,2,2,1,1
1,2,2,0,0,0,0,0,0,0,2,2,1
2,2,0,0,0,0,0,0,0,0,0,2,2
2,2,0,0,0,0,0,0,0,0,0,2,2
2,0,0,0,0,0,0,0,0,0,0,0,2
2,0,0,0,0,0,0,0,0,0,0,0,2
2,0,0,0,0,0,0,0,0,0,0,0,2
2,2,0,0,0,0,0,0,0,0,0,2,2
2,2,0,0,0,0,8,3,7,0,0,2,2
1,2,9,0,0,0,8,3,7,0,2,2,1
1,1,2,2,2,0,8,3,2,2,2,1,1
1,1,1,2,2,2,2,2,2,2,1,1,1
endlayer

layer
1,1,1,2,2,2,2,2,2,2,1,1,1
1,1,2,2,2,0,0,0,2,2,2,1,1
1,2,2,0,0,0,0,0,0,0,2,2,1
2,2,0,0,0,0,0,0,0,0,0,2,2
2,2,0,0,0,0,0,0,0,0,0,2,2
2,0,0,0,0,0,0,0,0,0,0,0,2
2,0,0,0,0,0,0,0,0,0,0,0,2
2,0,0,0,0,0,0,0,0,0,0,0,2
2,2,0,0,0,0,0,0,3,7,0,2,2
2,2,0,0,0,0,0,8,3,10,10,2,2
1,2,2,0,0,0,0,8,3,3,2,2,1
1,1,2,2,2,0,0,8,2,2,2,1,1
1,1,1,2,2,2,2,2,2,2,1,1,1
endlayer

layer
1,1,1,2,2,2,2,2,2,2,1,1,1
1,1,2,2,2,0,0,0,2,2,2,1,1
1,2,2,0,0,0,0,0,0,0,2,2,1
2,2,0,0,0,0,0,0,0,0,0,2,2
2,2,0,0,0,0,0,0,0,0,0,2,2
2,0,0,0,0,0,0,0,0,0,0,0,2
2,0,0,0,0,0,0,0,0,0,0,0,2
2,0,0,0,0,0,0,0,0,10,10,10,2
2,2,0,0,0,0,0,0,8,3,3,2,2
2,2,0,0,0,0,0,0,8,3,3,2,2
1,2,2,0,0,0,0,0,8,3,2,2,1
1,1,2,2,2,0,0,0,2,2,2,1,1
1,1,1,2,2,2,2,2,2,2,1,1,1
endlayer

layer
1,1,1,2,2,2,2,2,2,2,1,1,1
1,1,2,2,2,0,0,0,2,2,2,1,1
1,2,2,0,0,0,0,0,0,0,2,2,1
2,2,0,0,0,0,0,0,0,0,0,2,2
2,2,0,0,0,0,0,0,0,0,0,2,2
2,0,0,0,0,0,0,0,0,0,0,0,2
2,0,0,0,0,0,0,0,0,10,10,10,2
2,0,0,0,0,0,0,0,0,3,3,3,2
2,2,0,0,0,0,0,0,0,8,11,2,2
2,2,0,0,0,0,0,0,0,0,0,2,2
1,2,2,0,0,0,0,0,0,0,2,2,1
1,1,2,2,2,0,0,0,2,2,2,1,1
1,1,1,2,2,2,2,2,2,2,1,1,1
endlayer

layer
1,1,1,2,2,2,2,2,2,2,1,1,1
1,1,2,2,2,0,0,0,2,2,2,1,1
1,2,2,0,0,0,0,0,0,0,2,2,1
2,2,0,0,0,0,0,0,0,0,0,2,2
2,2,0,0,0,0,0,0,0,0,0,2,2
2,0,0,0,0,0,0,0,0,10,10,3,2
2,0,0,0,0,0,0,0,0,3,3,3,2
2,0,0,0,0,0,0,0,0,11,11,8,2
2,2,0,0,0,0,0,0,0,0,0,2,2
2,2,0,0,0,0,0,0,0,0,0,2,2
1,2,2,0,0,0,0,0,0,0,2,2,1
1,1,2,2,2,0,0,0,2,2,2,1,1
1,1,1,2,2,2,2,2,2,2,1,1,1
endlayer

layer
1,1,1,2,2,2,2,2,2,2,1,1,1
1,1,2,2,2,0,0,0,2,2,2,1,1
1,2,2,0,0,0,0,0,0,0,2,2,1
2,2,0,0,0,0,0,0,0,0,0,2,2
2,2,0,0,0,0,0,0,0,10,10,2,2
2,0,0,0,0,0,0,0,0,3,3,3,2
2,0,0,0,0,0,0,0,0,11,11,11,2
2,0,0,0,0,0,0,0,0,0,0,0,2
2,2,0,0,0,0,0,0,0,0,0,2,2
2,2,0,0,0,0,0,0,0,0,0,2,2
1,2,2,0,0,0,0,0,0,0,9,2,1
1,1,2,2,2,0,0,0,2,2,2,1,1
1,1,1,2,2,2,2,2,2,2,1,1,1
endlayer

layer
1,1,1,2,2,2,2,2,2,2,1,1,1
1,1,2,2,2,0,0,0,2,2,2,1,1
1,2,2,0,0,0,0,0,0,12,2,2,1
2,2,0,0,0,0,0,0,10,12,3,2,2
2,2,0,0,0,0,0,0,3,3,3,2,2
2,0,0,0,0,0,0,0,0,11,11,11,2
2,0,0,0,0,0,0,0,0,0,0,0,2
2,0,0,0,0,0,0,0,0,0,0,0,2
2,2,0,0,0,0,0,0,0,0,0,2,2
2,2,0,0,0,0,0,0,0,0,0,2,2
1,2,2,0,0,0,0,0,0,0,2,2,1
1,1,2,2,2,0,0,0,2,2,2,1,1
1,1,1,2,2,2,2,2,2,2,1,1,1
endlayer

layer
1,1,1,2,2,2,2,2,2,2,1,1,1
1,1,2,2,2,0,0,12,2,2,2,1,1
1,2,2,0,0,0,0,12,3,3,2,2,1
2,2,0,0,0,0,0,12,3,3,3,2,2
2,2,0,0,0,0,0,0,11,11,11,2,2
2,0,0,0,0,0,0,0,0,0,0,0,2
2,0,0,0,0,0,0,0,0,0,0,0,2
2,0,0,0,0,0,0,0,0,0,0,0,2
2,2,0,0,0,0,0,0,0,0,0,2,2
2,2,0,0,0,0,0,0,0,0,0,2,2
1,2,2,0,0,0,0,0,0,0,2,2,1
1,1,2,2,2,0,0,0,2,2,2,1,1
1,1,1,2,2,2,2,2,2,2,1,1,1
endlayer

layer
1,1,1,2,2,2,2,2,2,2,1,1,1
1,1,2,2,2,0,12,3,2,2,2,1,1
1,2,2,0,0,0,12,3,13,0,2,2,1
2,2,0,0,0,0,12,3,11,0,0,2,2
2,2,0,0,0,0,0,0,0,0,0,2,2
2,0,0,0,0,0,0,0,0,0,0,0,2
2,0,0,0,0,0,0,0,0,0,0,0,2
2,0,0,0,0,0,0,0,0,0,0,0,2
2,2,0,0,0,0,0,0,0,0,0,2,2
2,2,0,0,0,0,0,0,0,0,0,2,2
1,2,2,0,0,0,0,0,0,0,2,2,1
1,1,2,2,2,0,0,0,2,2,2,1,1
1,1,1,2,2,2,2,2,2,2,1,1,1
endlayer

layer
1,1,1,2,2,2,2,2,2,2,1,1,1
1,1,2,2,2,3,3,13,2,2,2,1,1
1,2,2,0,0,12,3,13,0,0,2,2,1
2,2,0,0,0,12,3,13,0,0,0,2,2
2,2,0,0,0,0,0,0,0,0,0,2,2
2,0,0,0,0,0,0,0,0,0,0,0,2
2,0,0,0,0,0,0,0,0,0,0,0,2
2,0,0,0,0,0,0,0,0,0,0,0,2
2,2,0,0,0,0,0,0,0,0,0,2,2
2,2,0,0,0,0,0,0,0,0,0,2,2
1,2,2,0,0,0,0,0,0,0,2,2,1
1,1,2,2,2,0,0,0,2,2,2,1,1
1,1,1,2,2,2,2,2,2,2,1,1,1
endlayer

layer
1,1,1,2,2,2,2,2,2,2,1,1,1
1,1,2,2,2,3,13,0,2,2,2,1,1
1,2,2,0,12,3,13,0,0,0,9,2,1
2,2,0,0,12,3,13,0,0,0,0,2,2
2,2,0,0,0,0,0,0,0,0,0,2,2
2,0,0,0,0,0,0,0,0,0,0,0,2
2,0,0,0,0,0,0,0,0,0,0,0,2
2,0,0,0,0,0,0,0,0,0,0,0,2
2,2,0,0,0,0,0,0,0,0,0,2,2
2,2,0,0,0,0,0,0,0,0,0,2,2
1,2,2,0,0,0,0,0,0,0,2,2,1
1,1,2,2,2,0,0,0,2,2,2,1,1
1,1,1,2,2,2,2,2,2,2,1,1,1
endlayer

layer
1,1,1,2,2,2,2,2,2,2,1,1,1
1,1,2,2,2,13,0,0,2,2,2,1,1
1,2,2,3,3,13,0,0,0,0,2,2,1
2,2,5,5,3,13,0,0,0,0,0,2,2
2,2,0,12,3,0,0,0,0,0,0,2,2
2,0,0,0,0,0,0,0,0,0,0,0,2
2,0,0,0,0,0,0,0,0,0,0,0,2
2,0,0,0,0,0,0,0,0,0,0,0,2
2,2,0,0,0,0,0,0,0,0,0,2,2
2,2,0,0,0,0,0,0,0,0,0,2,2
1,2,2,0,0,0,0,0,0,0,2,2,1
1,1,2,2,2,0,0,0,2,2,2,1,1
1,1,1,2,2,2,2,2,2,2,1,1,1
endlayer

layer
1,1,1,2,2,2,2,2,2,2,1,1,1
1,1,2,2,2,0,0,0,2,2,2,1,1
1,2,2,3,13,0,0,0,0,0,2,2,1
2,2,3,3,13,0,0,0,0,0,0,2,2
2,2,3,3,13,0,0,0,0,0,0,2,2
2,5,5,5,0,0,0,0,0,0,0,0,2
2,0,0,0,0,0,0,0,0,0,0,0,2
2,0,0,0,0,0,0,0,0,0,0,0,2
2,2,0,0,0,0,0,0,0,0,0,2,2
2,2,0,0,0,0,0,0,0,0,0,2,2
1,2,2,0,0,0,0,0,0,0,2,2,1
1,1,2,2,2,0,0,0,2,2,2,1,1
1,1,1,2,2,2,2,2,2,2,1,1,1
endlayer

layer
1,1,1,2,2,2,2,2,2,2,1,1,1
1,1,2,2,2,0,0,0,2,2,2,1,1
1,2,2,0,0,0,0,0,0,0,2,2,1
2,2,0,0,0,0,0,0,0,0,0,2,2
2,2,4,13,0,0,0,0,0,0,0,2,2
2,3,3,3,0,0,0,0,0,0,0,0,2
2,5,5,5,0,0,0,0,0,0,0,0,2
2,0,0,0,0,0,0,0,0,0,0,0,2
2,2,0,0,0,0,0,0,0,0,0,2,2
2,2,0,0,0,0,0,0,0,0,0,2,2
1,2,2,0,0,0,0,0,0,0,2,2,1
1,1,2,2,2,0,0,0,2,2,2,1,1
1,1,1,2,2,2,2,2,2,2,1,1,1
endlayer

layer
1,1,1,2,2,2,2,2,2,2,1,1,1
1,1,2,2,2,0,0,0,2,2,2,1,1
1,2,2,0,0,0,0,0,0,0,2,2,1
2,2,0,0,0,0,0,0,0,0,0,2,2
2,2,0,0,0,0,0,0,0,0,0,2,2
2,4,4,4,0,0,0,0,0,0,0,0,2
2,3,3,3,0,0,0,0,0,0,0,0,2
2,3,5,5,0,0,0,0,0,0,0,0,2
2,2,0,0,0,0,0,0,0,0,0,2,2
2,2,0,0,0,0,0,0,0,0,0,2,2
1,2,2,0,0,0,0,0,0,0,2,2,1
1,1,2,2,2,0,0,0,2,2,2,1,1
1,1,1,2,2,2,2,2,2,2,1,1,1
endlayer

layer
1,1,1,2,2,2,2,2,2,2,1,1,1
1,1,2,2,2,0,0,0,2,2,2,1,1
1,2,9,0,0,0,0,0,0,0,2,2,1
2,2,0,0,0,0,0,0,0,0,0,2,2
2,2,0,0,0,0,0,0,0,0,0,2,2
2,0,0,0,0,0,0,0,0,0,0,0,2
2,4,4,4,0,0,0,0,0,0,0,0,2
2,3,3,3,0,0,0,0,0,0,0,0,2
2,2,5,5,0,0,0,0,0,0,0,2,2
2,2,0,0,0,0,0,0,0,0,0,2,2
1,2,2,0,0,0,0,0,0,0,2,2,1
1,1,2,2,2,0,0,0,2,2,2,1,1
1,1,1,2,2,2,2,2,2,2,1,1,1
endlayer

layer
1,1,1,2,2,2,2,2,2,2,1,1,1
1,1,2,2,2,0,0,0,2,2,2,1,1
1,2,2,0,0,0,0,0,0,0,2,2,1
2,2,0,0,0,0,0,0,0,0,0,2,2
2,2,0,0,0,0,0,0,0,0,0,2,2
2,0,0,0,0,0,0,0,0,0,0,0,2
2,0,0,0,0,0,0,0,0,0,0,0,2
2,4,4,4,0,0,0,0,0,0,0,0,2
2,2,3,3,3,0,0,0,0,0,0,2,2
2,2,3,7,5,0,0,0,0,0,0,2,2
1,2,2,7,0,0,0,0,0,0,2,2,1
1,1,2,2,2,0,0,0,2,2,2,1,1
1,1,1,2,2,2,2,2,2,2,1,1,1
endlayer

layer
1,1,1,2,2,2,2,2,2,2,1,1,1
1,1,2,2,2,0,0,0,2,2,2,1,1
1,2,2,0,0,0,0,0,0,0,2,2,1
2,2,0,0,0,0,0,0,0,0,0,2,2
2,2,0,0,0,0,0,0,0,0,0,2,2
2,0,0,0,0,0,0,0,0,0,0,0,2
2,0,0,0,0,0,0,0,0,0,0,0,2
2,0,0,0,0,0,0,0,0,0,0,0,2
2,2,4,4,4,0,0,0,0,0,0,2,2
2,2,3,3,3,7,0,0,0,0,0,2,2
1,2,2,3,3,7,0,0,0,0,2,2,1
1,1,2,2,2,7,0,0,2,2,2,1,1
1,1,1,2,2,2,2,2,2,2,1,1,1
endlayer

layer
1,1,1,2,2,2,2,2,2,2,1,1,1
1,1,2,2,2,0,0,0,2,2,2,1,1
1,2,2,0,0,0,0,0,0,0,2,2,1
2,2,0,0,0,0,0,0,0,0,0,2,2
2,2,0,0,0,0,0,0,0,0,0,2,2
2,0,0,0,0,0,0,0,0,0,0,0,2
2,0,0,0,0,0,0,0,0,0,0,0,2
2,0,0,0,0,0,0,0,0,0,0,0,2
2,2,0,0,0,0,0,0,0,0,0,2,2
2,2,0,0,4,3,7,0,0,0,0,2,2
1,2,2,0,8,3,7,0,0,0,2,2,1
1,1,2,2,2,3,7,0,2,2,2,1,1
1,1,1,2,2,2,2,2,2,2,1,1,1
endlayer

layer
1,1,1,2,2,2,2,2,2,2,1,1,1
1,1,2,2,2,0,0,0,2,2,2,1,1
1,2,2,0,0,0,0,0,0,0,2,2,1
2,2,0,0,0,0,0,0,0,0,0,2,2
2,2,0,0,0,0,0,0,0,0,0,2,2
2,0,0,0,0,0,0,0,0,0,0,0,2
2,0,0,0,0,0,0,0,0,0,0,0,2
2,0,0,0,0,0,0,0,0,0,0,0,2
2,2,0,0,0,0,0,0,0,0,0,2,2
2,2,0,0,0,8,3,7,0,0,0,2,2
1,2,2,0,0,8,3,7,0,0,2,2,1
1,1,2,2,2,8,3,3,2,2,2,1,1
1,1,1,2,2,2,2,2,2,2,1,1,1
endlayer

layer
1,1,1,2,2,2,2,2,2,2,1,1,1
1,1,2,2,2,0,0,0,2,2,2,1,1
1,2,2,0,0,0,0,0,0,0,2,2,1
2,2,0,0,0,0,0,0,0,0,0,2,2
2,2,0,0,0,0,0,0,0,0,0,2,2
2,0,0,0,0,0,0,0,0,0,0,0,2
2,0,0,0,0,0,0,0,0,0,0,0,2
2,0,0,0,0,0,0,0,0,0,0,0,2
2,2,0,0,0,0,0,0,0,0,0,2,2
2,2,0,0,0,0,8,3,7,0,0,2,2
1,2,9,0,0,0,8,3,7,0,2,2,1
1,1,2,2,2,0,8,3,2,2,2,1,1
1,1,1,2,2,2,2,2,2,2,1,1,1
endlayer

layer
1,1,1,2,2,2,2,2,2,2,1,1,1
1,1,2,2,2,0,0,0,2,2,2,1,1
1,2,2,0,0,0,0,0,0,0,2,2,1
2,2,0,0,0,0,0,0,0,0,0,2,2
2,2,0,0,0,0,0,0,0,0,0,2,2
2,0,0,0,0,0,0,0,0,0,0,0,2
2,0,0,0,0,0,0,0,0,0,0,0,2
2,0,0,0,0,0,0,0,0,0,0,0,2
2,2,0,0,0,0,0,0,3,7,0,2,2
2,2,0,0,0,0,0,8,3,10,10,2,2
1,2,2,0,0,0,0,8,3,3,2,2,1
1,1,2,2,2,0,0,8,2,2,2,1,1
1,1,1,2,2,2,2,2,2,2,1,1,1
endlayer

layer
1,1,1,2,2,2,2,2,2,2,1,1,1
1,1,2,2,2,0,0,0,2,2,2,1,1
1,2,2,0,0,0,0,0,0,0,2,2,1
2,2,0,0,0,0,0,0,0,0,0,2,2
2,2,0,0,0,0,0,0,0,0,0,2,2
2,0,0,0,0,0,0,0,0,0,0,0,2
2,0,0,0,0,0,0,0,0,0,0,0,2
2,0,0,0,0,0,0,0,0,10,10,10,2
2,2,0,0,0,0,0,0,8,3,3,2,2
2,2,0,0,0,0,0,0,8,3,3,2,2
1,2,2,0,0,0,0,0,8,3,2,2,1
1,1,2,2,2,0,0,0,2,2,2,1,1
1,1,1,2,2,2,2,2,2,2,1,1,1
endlayer

layer
1,1,1,2,2,2,2,2,2,2,1,1,1
1,1,2,2,2,0,0,0,2,2,2,1,1
1,2,2,0,0,0,0,0,0,0,2,2,1
2,2,0,0,0,0,0,0,0,0,0,2,2
2,2,0,0,0,0,0,0,0,0,0,2,2
2,0,0,0,0,0,0,0,0,0,0,0,2
2,0,0,0,0,0,0,0,0,10,10,10,2
2,0,0,0,0,0,0,0,0,3,3,3,2
2,2,0,0,0,0,0,0,0,8,11,2,2
2,2,0,0,0,0,0,0,0,0,0,2,2
1,2,2,0,0,0,0,0,0,0,2,2,1
1,1,2,2,2,0,0,0,2,2,2,1,1
1,1,1,2,2,2,2,2,2,2,1,1,1
endlayer

layer
1,1,1,2,2,2,2,2,2,2,1,1,1
1,1,2,2,2,0,0,0,2,2,2,1,1
1,2,2,0,0,0,0,0,0,0,2,2,1
2,2,0,0,0,0,0,0,0,0,0,2,2
2,2,0,0,0,0,0,0,0,0,0,2,2
2,0,0,0,0,0,0,0,0,10,10,3,2
2,0,0,0,0,0,0,0,0,3,3,3,2
2,0,0,0,0,0,0,0,0,11,11,8,2
2,2,0,0,0,0,0,0,0,0,0,2,2
2,2,0,0,0,0,0,0,0,0,0,2,2
1,2,2,0,0,0,0,0,0,0,2,2,1
1,1,2,2,2,0,0,0,2,2,2,1,1
1,1,1,2,2,2,2,2,2,2,1,1,1
endlayer

layer
1,1,1,2,2,2,2,2,2,2,1,1,1
1,1,2,2,2,0,0,0,2,2,2,1,1
1,2,2,0,0,0,0,0,0,0,2,2,1
2,2,0,0,0,0,0,0,0,0,0,2,2
2,2,0,0,0,0,0,0,0,10,10,2,2
2,0,0,0,0,0,0,0,0,3,3,3,2
2,0,0,0,0,0,0,0,0,11,11,11,2
2,0,0,0,0,0,0,0,0,0,0,0,2
2,2,0,0,0,0,0,0,0,0,0,2,2
2,2,0,0,0,0,0,0,0,0,0,2,2
1,2,2,0,0,0,0,0,0,0,9,2,1
1,1,2,2,2,0,0,0,2,2,2,1,1
1,1,1,2,2,2,2,2,2,2,1,1,1
endlayer

layer
1,1,1,2,2,2,2,2,2,2,1,1,1
1,1,2,2,2,0,0,0,2,2,2,1,1
1,2,2,0,0,0,0,0,0,12,2,2,1
2,2,0,0,0,0,0,0,10,12,3,2,2
2,2,0,0,0,0,0,0,3,3,3,2,2
2,0,0,0,0,0,0,0,0,11,11,11,2
2,0,0,0,0,0,0,0,0,0,0,0,2
2,0,0,0,0,0,0,0,0,0,0,0,2
2,2,0,0,0,0,0,0,0,0,0,2,2
2,2,0,0,0,0,0,0,0,0,0,2,2
1,2,2,0,0,0,0,0,0,0,2,2,1
1,1,2,2,2,0,0,0,2,2,2,1,1
1,1,1,2,2,2,2,2,2,2,1,1,1
endlayer

layer
1,1,1,2,2,2,2,2,2,2,1,1,1
1,1,2,2,2,0,0,12,2,2,2,1,1
1,2,2,0,0,0,0,12,3,3,2,2,1
2,2,0,0,0,0,0,12,3,3,3,2,2
2,2,0,0,0,0,0,0,11,11,11,2,2
2,0,0,0,0,0,0,0,0,0,0,0,2
2,0,0,0,0,0,0,0,0,0,0,0,2
2,0,0,0,0,0,0,0,0,0,0,0,2
2,2,0,0,0,0,0,0,0,0,0,2,2
2,2,0,0,0,0,0,0,0,0,0,2,2
1,2,2,0,0,0,0,0,0,0,2,2,1
1,1,2,2,2,0,0,0,2,2,2,1,1
1,1,1,2,2,2,2,2,2,2,1,1,1
endlayer

layer
1,1,1,2,2,2,2,2,2,2,1,1,1
1,1,2,2,2,0,12,3,2,2,2,1,1
1,2,2,0,0,0,12,3,13,0,2,2,1
2,2,0,0,0,0,12,3,11,0,0,2,2
2,2,0,0,0,0,0,0,0,0,0,2,2
2,0,0,0,0,0,0,0,0,0,0,0,2
2,0,0,0,0,0,0,0,0,0,0,0,2
2,0,0,0,0,0,0,0,0,0,0,0,2
2,2,0,0,0,0,0,0,0,0,0,2,2
2,2,0,0,0,0,0,0,0,0,0,2,2
1,2,2,0,0,0,0,0,0,0,2,2,1
1,1,2,2,2,0,0,0,2,2,2,1,1
1,1,1,2,2,2,2,2,2,2,1,1,1
endlayer

layer
1,1,1,2,2,2,2,2,2,2,1,1,1
1,1,2,2,2,3,3,13,2,2,2,1,1
1,2,2,0,0,12,3,13,0,0,2,2,1
2,2,0,0,0,12,3,13,0,0,0,2,2
2,2,0,0,0,0,0,0,0,0,0,2,2
2,0,0,0,0,0,0,0,0,0,0,0,2
2,0,0,0,0,0,0,0,0,0,0,0,2
2,0,0,0,0,0,0,0,0,0,0,0,2
2,2,0,0,0,0,0,0,0,0,0,2,2
2,2,0,0,0,0,0,0,0,0,0,2,2
1,2,2,0,0,0,0,0,0,0,2,2,1
1,1,2,2,2,0,0,0,2,2,2,1,1
1,1,1,2,2,2,2,2,2,2,1,1,1
endlayer

layer
1,1,1,2,2,2,2,2,2,2,1,1,1
1,1,2,2,2,3,13,0,2,2,2,1,1
1,2,2,0,12,3,13,0,0,0,9,2,1
2,2,0,0,12,3,13,0,0,0,0,2,2
2,2,0,0,0,0,0,0,0,0,0,2,2
2,0,0,0,0,0,0,0,0,0,0,0,2
2,0,0,0,0,0,0,0,0,0,0,0,2
2,0,0,0,0,0,0,0,0,0,0,0,2
2,2,0,0,0,0,0,0,0,0,0,2,2
2,2,0,0,0,0,0,0,0,0,0,2,2
1,2,2,0,0,0,0,0,0,0,2,2,1
1,1,2,2,2,0,0,0,2,2,2,1,1
1,1,1,2,2,2,2,2,2,2,1,1,1
endlayer

layer
1,1,1,2,2,2,2,2,2,2,1,1,1
1,1,2,2,2,13,0,0,2,2,2,1,1
1,2,2,3,3,13,0,0,0,0,2,2,1
2,2,5,5,3,13,0,0,0,0,0,2,2
2,2,0,12,3,0,0,0,0,0,0,2,2
2,0,0,0,0,0,0,0,0,0,0,0,2
2,0,0,0,0,0,0,0,0,0,0,0,2
2,0,0,0,0,0,0,0,0,0,0,0,2
2,2,0,0,0,0,0,0,0,0,0,2,2
2,2,0,0,0,0,0,0,0,0,0,2,2
1,2,2,0,0,0,0,0,0,0,2,2,1
1,1,2,2,2,0,0,0,2,2,2,1,1
1,1,1,2,2,2,2,2,2,2,1,1,1
endlayer

layer
1,1,1,2,2,2,2,2,2,2,1,1,1
1,1,2,2,2,0,0,0,2,2,2,1,1
1,2,2,3,13,0,0,0,0,0,2,2,1
2,2,3,3,13,0,0,0,0,0,0,2,2
2,2,3,3,13,0,0,0,0,0,0,2,2
2,5,5,5,0,0,0,0,0,0,0,0,2
2,0,0,0,0,0,0,0,0,0,0,0,2
2,0,0,0,0,0,0,0,0,0,0,0,2
2,2,0,0,0,0,0,0,0,0,0,2,2
2,2,0,0,0,0,0,0,0,0,0,2,2
1,2,2,0,0,0,0,0,0,0,2,2,1
1,1,2,2,2,0,0,0,2,2,2,1,1
1,1,1,2,2,2,2,2,2,2,1,1,1
endlayer

layer
1,1,1,2,2,2,2,2,2,2,1,1,1
1,1,2,2,2,0,0,0,2,2,2,1,1
1,2,2,0,0,0,0,0,0,0,2,2,1
2,2,0,0,0,0,0,0,0,0,0,2,2
2,2,4,13,0,0,0,0,0,0,0,2,2
2,3,3,3,0,0,0,0,0,0,0,0,2
2,5,5,5,0,0,0,0,0,0,0,0,2
2,0,0,0,0,0,0,0,0,0,0,0,2
2,2,0,0,0,0,0,0,0,0,0,2,2
2,2,0,0,0,0,0,0,0,0,0,2,2
1,2,2,0,0,0,0,0,0,0,2,2,1
1,1,2,2,2,0,0,0,2,2,2,1,1
1,1,1,2,2,2,2,2,2,2,1,1,1
endlayer

layer
1,1,1,2,2,2,2,2,2,2,1,1,1
1,1,2,2,2,0,0,0,2,2,2,1,1
1,2,2,0,0,0,0,0,0,0,2,2,1
2,2,0,0,0,0,0,0,0,0,0,2,2
2,2,0,0,0,0,0,0,0,0,0,2,2
2,4,4,4,0,0,0,0,0,0,0,0,2
2,3,3,3,0,0,0,0,0,0,0,0,2
2,3,3,3,3,0,0,0,0,0,0,0,2
2,2,3,3,3,3,0,0,0,0,0,2,2
2,2,3,3,3,3,3,3,0,0,3,2,2
1,2,2,3,3,3,3,3,3,3,2,2,1
1,1,2,2,2,3,3,3,2,2,2,1,1
1,1,1,2,2,2,2,2,2,2,1,1,1
endlayer

layer
1,1,1,2,2,2,2,2,2,2,1,1,1
1,1,2,2,2,0,0,0,2,2,2,1,1
1,2,2,0,0,0,0,0,0,0,2,2,1
2,2,0,0,0,0,0,0,0,0,0,2,2
2,2,0,0,0,0,0,0,0,0,0,2,2
2,0,0,0,0,0,0,0,0,0,0,0,2
2,0,0,0,0,0,0,0,0,0,0,0,2
2,0,0,0,0,0,0,0,0,0,0,0,2
2,2,0,0,0,0,0,0,0,0,0,2,2
2,2,0,0,0,0,0,0,0,0,0,2,2
1,2,2,0,0,0,0,0,0,0,2,2,1
1,1,2,2,2,0,6,0,2,2,2,1,1
1,1,1,2,2,2,2,2,2,2,1,1,1
endlayer

layer
1,1,1,1,2,2,2,2,2,1,1,1,1
1,1,2,2,2,0,0,0,2,2,2,1,1
1,2,2,0,0,0,0,0,0,0,2,2,1
1,2,0,0,0,0,0,0,0,0,0,2,1
2,2,0,0,0,0,0,0,0,0,0,2,2
2,0,0,0,0,0,0,0,0,0,0,0,2
2,0,0,0,0,0,0,0,0,0,0,0,2
2,0,0,0,0,0,0,0,0,0,0,0,2
2,2,0,0,0,0,0,0,0,0,0,2,2
1,2,0,0,0,0,0,0,0,0,0,2,1
1,2,2,0,0,0,0,0,0,0,2,2,1
1,1,2,2,2,0,0,0,2,2,2,1,1
1,1,1,1,2,2,2,2,2,1,1,1,1
endlayer

layer
1,1,1,1,1,1,1,1,1,1,1,1,1
1,1,1,1,2,2,2,2,2,1,1,1,1
1,1,2,2,2,0,0,0,2,2,2,1,1
1,1,2,0,0,0,0,0,0,0,2,1,1
1,2,2,0,0,0,0,0,0,0,2,2,1
1,2,0,0,0,0,0,0,0,0,0,2,1
1,2,0,0,0,0,0,0,0,0,0,2,1
1,2,0,0,0,0,0,0,0,0,0,2,1
1,2,2,0,0,0,0,0,0,0,2,2,1
1,1,2,0,0,0,0,0,0,0,2,1,1
1,1,2,2,2,0,0,0,2,2,2,1,1
1,1,1,1,2,2,2,2,2,1,1,1,1
1,1,1,1,1,1,1,1,1,1,1,1,1
endlayer

layer
1,1,1,1,1,1,1,1,1,1,1,1,1
1,1,1,1,1,1,1,1,1,1,1,1,1
1,1,1,1,2,2,2,2,2,1,1,1,1
1,1,1,2,2,2,2,2,2,2,1,1,1
1,1,2,2,2,0,0,0,2,2,2,1,1
1,1,2,2,0,0,0,0,0,2,2,1,1
1,1,2,2,0,0,0,0,0,2,2,1,1
1,1,2,2,0,0,0,0,0,2,2,1,1
1,1,2,2,2,0,0,0,2,2,2,1,1
1,1,1,2,2,2,2,2,2,2,1,1,1
1,1,1,1,2,2,2,2,2,1,1,1,1
1,1,1,1,1,1,1,1,1,1,1,1,1
1,1,1,1,1,1,1,1,1,1,1,1,1
endlayer

layer
1,1,1,1,1,1,1,1,1,1,1,1,1
1,1,1,1,1,1,1,1,1,1,1,1,1
1,1,1,1,1,1,1,1,1,1,1,1,1
1,1,1,1,1,1,1,1,1,1,1,1,1
1,1,1,1,1,2,2,2,1,1,1,1,1
1,1,1,1,2,2,2,2,2,1,1,1,1
1,1,1,1,2,2,2,2,2,1,1,1,1
1,1,1,1,2,2,2,2,2,1,1,1,1
1,1,1,1,1,2,2,2,1,1,1,1,1
1,1,1,1,1,1,1,1,1,1,1,1,1
1,1,1,1,1,1,1,1,1,1,1,1,1
1,1,1,1,1,1,1,1,1,1,1,1,1
1,1,1,1,1,1,1,1,1,1,1,1,1
endlayer

