
# Created by Ruins mod version 17.0 Ingame Parser
# authoring Player: ST753M

weight=1
embed_into_distance=7
acceptable_target_blocks=
unacceptable_target_blocks=flowing_water,water,flowing_lava,lava,ice,bedrock,netherrack,nether_brick,nether_brick_fence,soul_sand,quartz_ore,end_stone,obsidian,iron_bars,Natura:Cloud,slime_grass,slime_congealed,slime_dirt,clouds,natura:clouds,twilightforest:wispy_cloud,twilightforest:fluffy_cloud
dimensions=23,23,23
allowable_overhang=10
max_leveling=0
leveling_buffer=0
preserve_water=0
preserve_lava=0

biomesToSpawnIn=extreme_hills,smaller_extreme_hills,mutated_extreme_hills,mutated_extreme_hills_with_trees,extreme_hills_with_trees,highland,alps,alps_foothills,mountain,mountain_foothills,crag,cliffs,darklands_mountains

rule1=0,100,preserveBlock

rule2=0,100,minecraft:monster_egg-2,minecraft:monster_egg-3,minecraft:monster_egg-4,minecraft:stonebrick-0,minecraft:stonebrick-1,minecraft:stonebrick-2,minecraft:monster_egg-2,minecraft:monster_egg-3,minecraft:monster_egg-4,minecraft:stonebrick-0,minecraft:stonebrick-1,minecraft:stonebrick-2,minecraft:stone_brick_stairs-3,minecraft:stone_brick_stairs-7,minecraft:stone_brick_stairs-2,minecraft:stone_brick_stairs-6

rule3=0,100,minecraft:stone-6,minecraft:stone-6,minecraft:stone-6,minecraft:stone-6,minecraft:stone-6,minecraft:stone-6,minecraft:monster_egg-2,minecraft:monster_egg-3,minecraft:monster_egg-4,minecraft:stonebrick-0,minecraft:stonebrick-1,minecraft:stonebrick-2

rule4=0,100,minecraft:stone_brick_stairs-2
rule5=0,100,minecraft:stone_brick_stairs-3
rule6=0,100,minecraft:gravel-0
rule7=0,100,minecraft:stone_brick_stairs-1
rule8=0,100,minecraft:oak_stairs-2
rule9=0,100,minecraft:spruce_door-2
rule10=0,100,minecraft:web-0
rule11=0,100,minecraft:spruce_door-1
rule12=0,100,minecraft:oak_stairs-4
rule13=0,100,minecraft:spruce_door-0
rule14=0,20,ChestGenHook:chests/woodland_mansion:5-4,ChestGenHook:chests/village_blacksmith:5-4,ChestGenHook:chests/simple_dungeon:5-4,ChestGenHook:chests/stronghold_corridor:5-4,ChestGenHook:chests/stronghold_crossing:5-4
rule15=0,100,minecraft:carpet-14
rule16=0,100,minecraft:carpet-7
rule17=0,100,minecraft:iron_bars-0
rule18=0,100,minecraft:spruce_door-9
rule19=0,100,minecraft:spruce_door-8
rule20=0,100,minecraft:stone_brick_stairs-4
rule21=0,100,minecraft:stone_brick_stairs-6
rule22=0,100,minecraft:stone_brick_stairs-7
rule23=0,100,minecraft:bookshelf-0
rule24=0,100,minecraft:stone_brick_stairs-5
rule25=0,100,minecraft:fence-0
rule26=0,100,minecraft:oak_stairs-3
rule27=0,30,MobSpawner:spider,MobSpawner:skeleton,MobSpawner:zombie
rule28=0,100,minecraft:oak_stairs-1
rule29=0,100,minecraft:spruce_door-3
rule30=0,100,minecraft:oak_stairs-0
rule31=0,100,minecraft:bed-0
rule32=0,100,minecraft:bed-8
rule33=0,100,minecraft:stone_brick_stairs-0
rule34=0,100,minecraft:ladder-2
rule35=0,100,minecraft:stone_slab-5
rule36=0,100,minecraft:stone_slab-13
rule37=0,100,minecraft:trapdoor-10,minecraft:ladder-2

layer
1,1,1,1,1,1,1,1,1,1,1,1,1,1,1,1,1,1,1,1,1,1,1
1,1,1,1,1,1,1,1,1,1,1,1,1,1,1,1,1,1,1,1,1,1,1
1,1,1,1,1,1,1,1,1,1,1,1,1,1,1,1,1,1,1,1,1,1,1
1,1,1,1,1,1,1,1,1,1,1,1,1,1,1,1,1,1,1,1,1,1,1
1,1,1,1,1,2,2,2,2,2,2,2,2,2,2,2,2,2,1,1,1,1,1
1,1,1,1,2,2,2,2,2,2,2,2,2,2,2,2,2,2,2,1,1,1,1
1,1,1,1,2,2,2,2,2,2,2,2,2,2,2,2,2,2,2,1,1,1,1
1,1,1,1,2,2,2,2,2,2,2,2,2,2,2,2,2,2,2,1,1,1,1
1,1,1,1,2,2,2,2,2,2,2,2,2,2,2,2,2,2,2,1,1,1,1
1,1,1,1,2,2,2,2,2,2,2,2,2,2,2,2,2,2,2,1,1,1,1
1,1,1,1,2,2,2,2,2,2,2,2,2,2,2,2,2,2,2,1,1,1,1
1,1,1,1,2,2,2,2,2,2,2,2,2,2,2,2,2,2,2,1,1,1,1
1,1,1,1,2,2,2,2,2,2,2,2,2,2,2,2,2,2,2,1,1,1,1
1,1,1,1,1,2,2,2,2,2,2,2,2,2,2,2,2,2,2,1,1,1,1
1,1,1,1,1,1,1,1,1,2,2,2,2,2,2,2,2,2,2,1,1,1,1
1,1,1,1,1,1,1,1,1,2,2,2,2,2,2,2,2,2,2,1,1,1,1
1,1,1,1,1,1,1,1,1,2,2,2,2,2,2,2,2,2,2,1,1,1,1
1,1,1,1,1,1,1,1,1,2,2,2,2,2,2,2,2,2,2,1,1,1,1
1,1,1,1,1,1,1,1,1,1,2,2,2,2,2,2,2,2,1,1,1,1,1
1,1,1,1,1,1,1,1,1,1,1,1,1,1,1,1,1,1,1,1,1,1,1
1,1,1,1,1,1,1,1,1,1,1,1,1,1,1,1,1,1,1,1,1,1,1
1,1,1,1,1,1,1,1,1,1,1,1,1,1,1,1,1,1,1,1,1,1,1
1,1,1,1,1,1,1,1,1,1,1,1,1,1,1,1,1,1,1,1,1,1,1
endlayer

layer
1,1,1,1,1,1,1,1,1,1,1,1,1,1,1,1,1,1,1,1,1,1,1
1,1,1,1,1,1,1,1,1,1,1,1,1,1,1,1,1,1,1,1,1,1,1
1,1,1,1,1,1,1,1,1,1,1,1,1,1,1,1,1,1,1,1,1,1,1
1,1,1,1,1,1,2,2,2,2,2,2,2,2,2,2,2,1,1,1,1,1,1
1,1,1,1,2,2,2,2,2,2,2,2,2,2,2,2,2,2,2,1,1,1,1
1,1,1,1,2,2,2,2,2,2,2,2,2,2,2,2,2,2,2,1,1,1,1
1,1,1,2,2,2,2,2,2,2,2,2,2,2,2,2,2,2,2,2,1,1,1
1,1,1,2,2,2,2,2,2,2,2,2,2,2,2,2,2,2,2,2,1,1,1
1,1,1,2,2,2,2,2,2,2,2,2,2,2,2,2,2,2,2,2,1,1,1
1,1,1,2,2,2,2,2,2,2,2,2,2,2,2,2,2,2,2,2,1,1,1
1,1,1,2,2,2,2,2,2,2,2,2,2,2,2,2,2,2,2,2,1,1,1
1,1,1,2,2,2,2,2,2,2,2,2,2,2,2,2,2,2,2,2,1,1,1
1,1,1,1,2,2,2,2,2,2,2,2,2,2,2,2,2,2,2,2,1,1,1
1,1,1,1,2,2,2,2,2,2,2,2,2,2,2,2,2,2,2,2,1,1,1
1,1,1,1,1,1,2,2,2,2,2,2,2,2,2,2,2,2,2,2,1,1,1
1,1,1,1,1,1,1,1,2,2,2,2,2,2,2,2,2,2,2,2,1,1,1
1,1,1,1,1,1,1,1,2,2,2,2,2,2,2,2,2,2,2,2,1,1,1
1,1,1,1,1,1,1,1,1,2,2,2,2,2,2,2,2,2,2,1,1,1,1
1,1,1,1,1,1,1,1,1,2,2,2,2,2,2,2,2,2,2,1,1,1,1
1,1,1,1,1,1,1,1,1,1,1,2,2,2,2,2,2,1,1,1,1,1,1
1,1,1,1,1,1,1,1,1,1,1,1,1,1,1,1,1,1,1,1,1,1,1
1,1,1,1,1,1,1,1,1,1,1,1,1,1,1,1,1,1,1,1,1,1,1
1,1,1,1,1,1,1,1,1,1,1,1,1,1,1,1,1,1,1,1,1,1,1
endlayer

layer
1,1,1,1,1,1,1,1,1,1,1,1,1,1,1,1,1,1,1,1,1,1,1
1,1,1,1,1,1,1,1,1,1,1,1,1,1,1,1,1,1,1,1,1,1,1
1,1,1,1,1,1,1,1,1,1,1,1,1,1,1,1,1,1,1,1,1,1,1
1,1,1,1,2,2,2,2,2,2,2,2,2,2,2,2,2,2,2,1,1,1,1
1,1,1,2,2,2,2,2,2,2,2,2,2,2,2,2,2,2,2,2,1,1,1
1,1,1,2,2,2,2,2,2,2,2,2,2,2,2,2,2,2,2,2,1,1,1
1,1,1,2,2,2,2,2,2,2,2,2,2,2,2,2,2,2,2,2,1,1,1
1,1,1,2,2,2,2,2,2,2,2,2,2,2,2,2,2,2,2,2,1,1,1
1,1,1,2,2,2,2,2,2,2,2,2,2,2,2,2,2,2,2,2,1,1,1
1,1,1,2,2,2,2,2,2,2,2,2,2,2,2,2,2,2,2,2,1,1,1
1,1,1,2,2,2,2,2,2,2,2,2,2,2,2,2,2,2,2,2,1,1,1
1,1,1,2,2,2,2,2,2,2,2,2,2,2,2,2,2,2,2,2,1,1,1
1,1,1,2,2,2,2,2,2,2,2,2,2,2,2,2,2,2,2,2,1,1,1
1,1,1,2,2,2,2,2,2,2,2,2,2,2,2,2,2,2,2,2,1,1,1
1,1,1,1,2,2,2,2,2,2,2,2,2,2,2,2,2,2,2,2,1,1,1
1,1,1,1,1,1,1,1,2,2,2,2,2,2,2,2,2,2,2,2,1,1,1
1,1,1,1,1,1,1,1,2,2,2,2,2,2,2,2,2,2,2,2,1,1,1
1,1,1,1,1,1,1,1,2,2,2,2,2,2,2,2,2,2,2,2,1,1,1
1,1,1,1,1,1,1,1,2,2,2,2,2,2,2,2,2,2,2,2,1,1,1
1,1,1,1,1,1,1,1,1,2,2,2,2,2,2,2,2,2,2,1,1,1,1
1,1,1,1,1,1,1,1,1,1,1,1,1,1,1,1,1,1,1,1,1,1,1
1,1,1,1,1,1,1,1,1,1,1,1,1,1,1,1,1,1,1,1,1,1,1
1,1,1,1,1,1,1,1,1,1,1,1,1,1,1,1,1,1,1,1,1,1,1
endlayer

layer
1,1,1,1,1,1,1,1,1,1,1,1,1,1,1,1,1,1,1,1,1,1,1
1,1,1,1,1,1,1,1,1,1,1,1,1,1,1,1,1,1,1,1,1,1,1
1,1,1,1,1,2,2,2,2,2,2,2,2,2,2,2,2,2,1,1,1,1,1
1,1,1,2,2,2,2,2,2,2,2,2,2,2,2,2,2,2,2,2,1,1,1
1,1,1,2,2,2,2,2,2,2,2,2,2,2,2,2,2,2,2,2,1,1,1
1,1,2,2,2,2,2,2,2,2,2,2,2,2,2,2,2,2,2,2,2,1,1
1,1,2,2,2,2,2,2,2,2,2,2,2,2,2,2,2,2,2,2,2,1,1
1,1,2,2,2,2,2,2,2,2,2,2,2,2,2,2,2,2,2,2,2,1,1
1,1,2,2,2,2,2,2,2,2,2,2,2,2,2,2,2,2,2,2,2,1,1
1,1,2,2,2,2,2,2,2,2,2,2,2,2,2,2,2,2,2,2,2,1,1
1,1,2,2,2,2,2,2,2,2,2,2,2,2,2,2,2,2,2,2,2,1,1
1,1,2,2,2,2,2,2,2,2,2,2,2,2,2,2,2,2,2,2,2,1,1
1,1,2,2,2,2,2,2,2,2,2,2,2,2,2,2,2,2,2,2,2,1,1
1,1,1,2,2,2,2,2,2,2,2,2,2,2,2,2,2,2,2,2,2,1,1
1,1,1,2,2,2,2,2,2,2,2,2,2,2,2,2,2,2,2,2,2,1,1
1,1,1,1,1,2,2,2,2,2,2,2,2,2,2,2,2,2,2,2,2,1,1
1,1,1,1,1,1,1,2,2,2,2,2,2,2,2,2,2,2,2,2,2,1,1
1,1,1,1,1,1,1,2,2,2,2,2,2,2,2,2,2,2,2,2,2,1,1
1,1,1,1,1,1,1,1,2,2,2,2,2,2,2,2,2,2,2,2,1,1,1
1,1,1,1,1,1,1,1,2,2,2,2,2,2,2,2,2,2,2,2,1,1,1
1,1,1,1,1,1,1,1,1,1,2,2,2,2,2,2,2,2,1,1,1,1,1
1,1,1,1,1,1,1,1,1,1,1,1,1,1,1,1,1,1,1,1,1,1,1
1,1,1,1,1,1,1,1,1,1,1,1,1,1,1,1,1,1,1,1,1,1,1
endlayer

layer
1,1,1,1,1,1,1,1,1,1,1,1,1,1,1,1,1,1,1,1,1,1,1
1,1,1,1,1,1,1,1,1,1,1,1,1,1,1,1,1,1,1,1,1,1,1
1,1,1,2,2,2,2,2,2,2,2,2,2,2,2,2,2,2,2,2,1,1,1
1,1,2,2,2,2,2,2,2,2,2,2,2,2,2,2,2,2,2,2,2,1,1
1,1,2,2,2,2,2,2,2,2,2,2,2,2,2,2,2,2,2,2,2,1,1
1,1,2,2,2,2,2,2,2,2,2,2,2,2,2,2,2,2,2,2,2,1,1
1,1,2,2,2,2,2,2,2,2,2,2,2,2,2,2,2,2,2,2,2,1,1
1,1,2,2,2,2,2,2,2,2,2,2,2,2,2,2,2,2,2,2,2,1,1
1,1,2,2,2,2,2,2,2,2,2,2,2,2,2,2,2,2,2,2,2,1,1
1,1,2,2,2,2,2,2,2,2,2,2,2,2,2,2,2,2,2,2,2,1,1
1,1,2,2,2,2,2,2,2,2,2,2,2,2,2,2,2,2,2,2,2,1,1
1,1,2,2,2,2,2,2,2,2,2,2,2,2,2,2,2,2,2,2,2,1,1
1,1,2,2,2,2,2,2,2,2,2,2,2,2,2,2,2,2,2,2,2,1,1
1,1,2,2,2,2,2,2,2,2,2,2,2,2,2,2,2,2,2,2,2,1,1
1,1,2,2,2,2,2,2,2,2,2,2,2,2,2,2,2,2,2,2,2,1,1
1,1,1,2,2,2,2,2,2,2,2,2,2,2,2,2,2,2,2,2,2,1,1
1,1,1,1,1,1,1,2,2,2,2,2,2,2,2,2,2,2,2,2,2,1,1
1,1,1,1,1,1,1,2,2,2,2,2,2,2,2,2,2,2,2,2,2,1,1
1,1,1,1,1,1,1,2,2,2,2,2,2,2,2,2,2,2,2,2,2,1,1
1,1,1,1,1,1,1,2,2,2,2,2,2,2,2,2,2,2,2,2,2,1,1
1,1,1,1,1,1,1,1,2,2,2,2,2,2,2,2,2,2,2,2,1,1,1
1,1,1,1,1,1,1,1,1,1,1,1,1,1,1,1,1,1,1,1,1,1,1
1,1,1,1,1,1,1,1,1,1,1,1,1,1,1,1,1,1,1,1,1,1,1
endlayer

layer
1,1,1,1,1,1,1,1,1,1,1,1,1,1,1,1,1,1,1,1,1,1,1
1,1,1,1,2,2,2,2,2,2,2,2,2,2,2,2,2,2,2,1,1,1,1
1,1,2,2,2,2,2,2,2,2,2,2,2,2,2,2,2,2,2,2,2,1,1
1,1,2,2,2,2,2,2,2,2,2,2,2,2,2,2,2,2,2,2,2,1,1
1,2,2,2,2,2,2,2,2,2,2,2,2,2,2,2,2,2,2,2,2,2,1
1,2,2,2,2,2,2,2,2,2,2,2,2,2,2,2,2,2,2,2,2,2,1
1,2,2,2,2,2,2,2,2,2,2,2,2,2,2,2,2,2,2,2,2,2,1
1,2,2,2,2,2,2,2,2,2,2,2,2,2,2,2,2,2,2,2,2,2,1
1,2,2,2,2,2,2,2,2,2,2,2,2,2,2,2,2,2,2,2,2,2,1
1,2,2,2,2,2,2,2,2,2,2,2,2,2,2,2,2,2,2,2,2,2,1
1,2,2,2,2,2,2,2,2,2,2,2,2,2,2,2,2,2,2,2,2,2,1
1,2,2,2,2,2,2,2,2,2,2,2,2,2,2,2,2,2,2,2,2,2,1
1,2,2,2,2,2,2,2,2,2,2,2,2,2,2,2,2,2,2,2,2,2,1
1,2,2,2,2,2,2,2,2,2,2,2,2,2,2,2,2,2,2,2,2,2,1
1,1,2,2,2,2,2,2,2,2,2,2,2,2,2,2,2,2,2,2,2,2,1
1,1,2,2,2,2,2,2,2,2,2,2,2,2,2,2,2,2,2,2,2,2,1
1,1,1,1,2,2,2,2,2,2,2,2,2,2,2,2,2,2,2,2,2,2,1
1,1,1,1,1,1,2,2,2,2,2,2,2,2,2,2,2,2,2,2,2,2,1
1,1,1,1,1,1,2,2,2,2,2,2,2,2,2,2,2,2,2,2,2,2,1
1,1,1,1,1,1,1,2,2,2,2,2,2,2,2,2,2,2,2,2,2,1,1
1,1,1,1,1,1,1,2,2,2,2,2,2,2,2,2,2,2,2,2,2,1,1
1,1,1,1,1,1,1,1,1,2,2,2,2,2,2,2,2,2,2,1,1,1,1
1,1,1,1,1,1,1,1,1,1,1,1,1,1,1,1,1,1,1,1,1,1,1
endlayer

layer
1,1,1,1,1,1,1,1,1,1,1,1,1,1,1,1,1,1,1,1,1,1,1
1,3,3,3,3,3,3,3,3,3,3,3,3,3,3,3,3,3,3,3,3,3,1
1,3,2,2,2,2,2,2,2,2,2,2,2,2,2,2,3,2,2,2,2,4,1
1,3,2,2,2,2,2,2,2,2,2,2,2,2,2,2,3,2,2,2,2,4,1
1,3,2,2,2,2,2,2,2,2,2,2,2,2,2,2,3,2,2,2,2,4,1
1,3,2,2,2,2,2,2,2,2,2,2,2,2,2,2,3,2,2,2,2,4,1
1,3,2,2,2,2,2,2,2,2,2,2,2,2,2,2,3,3,3,3,3,3,1
1,3,2,2,2,2,2,2,2,2,2,2,2,2,2,2,2,2,2,2,2,3,1
1,3,2,2,2,2,2,2,2,2,2,2,2,2,2,2,2,2,2,2,2,3,1
1,3,2,2,2,2,2,2,2,2,2,2,2,2,2,2,2,2,2,2,2,3,1
1,3,2,2,2,2,2,2,2,2,2,2,2,2,2,2,2,2,2,2,2,3,1
1,3,2,2,2,2,2,2,2,2,2,2,2,2,2,2,2,2,2,2,2,3,1
1,3,2,2,2,2,2,2,2,2,2,2,2,2,2,2,2,2,2,2,2,3,1
1,3,2,2,2,2,2,2,2,2,2,2,2,2,2,2,2,2,2,2,2,3,1
1,3,2,2,2,2,2,2,2,2,2,2,2,2,2,2,2,2,2,2,2,3,1
1,3,2,2,2,2,2,2,2,2,2,2,2,2,2,2,2,2,2,2,2,3,1
1,3,3,3,3,3,3,2,2,2,2,2,2,2,2,2,2,2,2,2,2,3,1
1,1,1,1,1,1,3,2,2,2,2,2,2,2,2,2,2,2,2,2,2,3,1
1,1,1,1,1,1,3,2,2,2,2,2,2,2,2,2,2,2,2,2,2,3,1
1,1,1,1,1,1,3,2,2,2,2,2,2,2,2,2,2,2,2,2,2,3,1
1,1,1,1,1,1,3,2,2,2,2,2,2,2,2,2,2,2,2,2,2,3,1
1,1,1,1,1,1,3,3,3,3,3,3,3,3,3,3,3,3,3,3,3,3,1
1,1,1,1,1,1,1,1,1,1,1,1,1,1,1,1,1,1,1,1,1,1,1
endlayer

layer
1,1,1,1,1,1,1,1,1,1,1,1,1,1,1,1,1,1,1,1,1,1,1
1,3,2,2,2,2,3,2,2,2,2,3,2,2,2,2,3,5,5,5,5,3,1
1,2,0,0,0,6,6,6,6,6,6,2,2,2,2,2,2,0,0,0,0,0,1
1,2,0,0,6,6,6,6,6,6,6,2,2,2,2,2,2,0,0,0,0,0,1
1,2,0,0,0,0,6,6,6,6,6,2,6,6,7,7,2,0,0,0,0,0,1
1,2,6,0,0,0,0,6,0,6,6,2,8,6,6,0,2,0,0,0,0,0,1
1,3,6,6,6,0,0,0,0,0,6,3,6,0,0,0,3,2,9,9,2,3,1
1,2,6,6,6,6,0,0,0,0,10,2,0,0,0,0,0,0,0,0,0,2,1
1,2,6,6,6,6,0,0,0,0,0,11,0,0,0,0,0,0,0,0,0,2,1
1,2,6,0,0,0,0,0,0,0,0,11,0,0,0,0,0,0,6,0,0,2,1
1,2,0,0,0,10,3,12,12,12,12,2,0,0,0,0,6,6,6,6,6,2,1
1,3,0,0,6,0,3,2,2,2,2,3,2,13,13,2,3,2,2,2,2,3,1
1,2,0,6,6,6,2,14,6,6,6,10,0,0,0,0,6,6,6,6,6,2,1
1,2,0,6,6,6,2,6,6,10,0,0,0,0,0,0,0,6,6,6,6,2,1
1,2,0,0,6,14,2,6,0,15,15,15,15,15,15,15,15,15,15,6,6,2,1
1,2,6,6,6,6,2,0,6,15,16,16,16,16,16,16,16,16,15,0,6,2,1
1,3,2,2,2,2,3,6,10,15,16,16,16,16,16,16,16,16,15,6,6,3,1
1,1,1,1,1,1,2,6,0,15,16,16,16,16,16,16,16,16,15,0,0,2,1
1,1,1,1,1,1,2,0,0,15,15,15,15,15,15,15,15,15,15,0,6,2,1
1,1,1,1,1,1,2,0,6,0,0,6,6,0,0,0,0,0,0,6,6,2,1
1,1,1,1,1,1,2,0,0,6,6,6,6,6,0,0,0,0,6,6,6,2,1
1,1,1,1,1,1,3,2,2,2,2,3,2,2,2,2,3,2,2,2,2,3,1
1,1,1,1,1,1,1,1,1,1,1,1,1,1,1,1,1,1,1,1,1,1,1
endlayer

layer
1,1,1,1,1,1,1,1,1,1,1,1,1,1,1,1,1,1,1,1,1,1,1
1,3,2,17,17,2,3,2,17,17,2,3,2,17,17,2,3,1,1,1,1,1,1
1,2,0,0,0,0,6,0,0,6,6,2,2,4,0,6,2,1,1,1,1,1,1
1,17,0,0,0,0,0,0,0,6,6,3,2,4,0,0,17,1,1,1,1,1,1
1,17,0,0,0,0,0,0,0,6,6,3,6,0,0,0,17,1,1,1,1,1,1
1,2,0,0,0,0,0,0,0,0,10,2,6,6,0,0,2,0,0,0,0,0,1
1,3,6,6,0,0,0,0,0,0,0,3,0,0,0,0,3,2,19,18,2,3,1
1,2,6,6,6,0,0,0,0,0,0,2,0,0,0,0,0,0,0,0,0,2,1
1,17,0,0,0,6,0,0,0,0,0,18,0,0,0,0,0,0,0,0,0,17,1
1,17,0,0,0,0,0,0,0,0,0,19,0,0,0,0,0,0,0,0,0,17,1
1,2,0,0,0,0,3,0,10,0,0,2,0,0,0,0,0,6,6,0,6,2,1
1,3,0,0,0,10,3,2,3,3,2,3,2,18,19,2,3,2,3,3,2,3,1
1,2,0,0,6,0,2,6,6,0,10,0,0,0,0,0,0,0,6,6,6,2,1
1,17,0,0,0,6,3,6,6,0,0,0,0,0,0,0,0,6,6,6,6,17,1
1,17,0,0,0,6,3,0,10,0,0,0,0,0,0,0,0,0,0,0,6,17,1
1,2,0,0,0,6,2,0,0,0,0,0,0,0,0,0,0,0,0,0,6,2,1
1,3,2,17,17,2,3,0,0,0,0,0,0,0,0,0,0,0,0,0,0,3,1
1,1,1,1,1,1,2,0,0,0,0,0,0,0,0,0,0,0,0,0,0,2,1
1,1,1,1,1,1,17,0,0,0,0,0,0,0,0,0,0,0,0,0,0,17,1
1,1,1,1,1,1,17,0,0,0,0,0,0,0,0,0,0,0,0,0,6,17,1
1,1,1,1,1,1,2,0,0,0,0,6,6,0,0,0,0,0,0,0,6,2,1
1,1,1,1,1,1,3,2,17,17,2,3,2,17,17,2,3,2,17,17,2,3,1
1,1,1,1,1,1,1,1,1,1,1,1,1,1,1,1,1,1,1,1,1,1,1
endlayer

layer
1,1,1,1,1,1,1,1,1,1,1,1,1,1,1,1,1,1,1,1,1,1,1
1,3,2,17,17,2,3,2,17,17,2,3,2,17,17,2,3,1,1,1,1,1,1
1,2,0,0,0,0,0,0,0,0,6,2,4,0,0,0,2,1,1,1,1,1,1
1,17,0,0,0,0,0,0,0,6,6,3,4,0,0,0,17,1,1,1,1,1,1
1,17,0,0,0,0,0,0,0,0,6,3,6,0,0,0,17,1,1,1,1,1,1
1,2,0,0,0,0,0,0,0,0,0,2,6,0,0,0,2,0,0,0,0,0,1
1,3,6,0,0,0,0,0,0,0,0,3,0,0,0,0,3,2,3,3,2,3,1
1,2,0,0,0,0,0,0,0,0,0,2,0,0,0,0,0,0,0,0,0,2,1
1,17,0,0,0,0,0,0,0,0,0,3,0,0,0,0,0,0,0,0,0,17,1
1,17,0,0,0,0,0,0,0,0,0,3,0,0,0,0,0,0,0,0,0,17,1
1,2,0,0,0,0,3,10,0,0,0,2,0,0,0,0,0,6,6,0,6,2,1
1,3,0,0,0,0,3,2,3,3,2,3,2,3,3,2,3,2,3,3,2,3,1
1,2,0,0,0,0,2,6,6,0,0,0,0,0,0,0,0,0,10,6,6,2,1
1,17,0,0,0,0,3,10,0,0,0,0,0,0,0,0,0,0,0,6,6,17,1
1,17,0,0,0,6,3,0,0,0,0,0,0,0,0,0,0,0,0,0,0,17,1
1,2,0,0,0,0,2,10,0,0,0,0,0,0,0,0,0,0,0,0,0,2,1
1,3,2,17,17,2,3,0,0,0,0,0,0,0,0,0,0,0,0,0,0,3,1
1,1,1,1,1,1,2,0,0,0,0,0,0,0,0,0,0,0,0,0,0,2,1
1,1,1,1,1,1,17,0,0,0,0,0,0,0,0,0,0,0,0,0,0,17,1
1,1,1,1,1,1,17,0,0,0,0,0,0,0,0,0,10,0,0,0,0,17,1
1,1,1,1,1,1,2,10,0,0,0,6,0,0,0,0,10,0,0,0,6,2,1
1,1,1,1,1,1,3,2,17,17,2,3,2,17,17,2,3,2,17,17,2,3,1
1,1,1,1,1,1,1,1,1,1,1,1,1,1,1,1,1,1,1,1,1,1,1
endlayer

layer
1,20,1,1,1,1,20,1,1,1,1,20,1,1,1,1,20,1,1,1,1,1,1
22,3,2,2,2,2,3,2,2,2,2,3,2,2,2,2,3,21,1,1,1,1,1
1,2,10,0,0,0,0,0,0,10,6,4,0,0,0,0,2,0,1,1,1,1,1
1,2,0,0,0,0,0,0,0,0,6,4,0,0,0,0,2,0,1,1,1,1,1
1,2,0,0,0,0,0,0,0,0,0,2,0,0,0,0,2,0,1,1,1,1,1
1,2,0,0,0,0,0,0,0,0,0,2,0,0,0,0,2,0,0,0,0,20,1
22,3,0,0,0,0,0,0,0,0,0,3,0,0,0,0,3,2,2,2,2,3,21
1,2,0,0,0,0,0,0,0,0,0,2,0,0,0,0,0,0,0,0,0,2,1
1,2,0,0,0,0,0,0,0,0,0,2,0,0,0,0,0,0,0,0,0,2,1
1,2,0,0,0,0,0,0,0,0,0,2,0,0,0,0,0,0,0,0,0,2,1
1,2,0,0,0,0,3,23,23,23,23,2,0,0,0,0,0,0,0,0,0,2,1
22,3,0,0,0,0,3,2,2,2,2,3,2,2,2,2,3,2,2,2,2,3,21
1,2,0,0,0,0,2,10,0,0,10,0,0,0,0,0,0,0,10,10,6,2,1
1,2,0,0,0,0,2,0,0,0,0,0,0,0,0,0,0,0,0,0,0,2,1
1,2,0,0,0,0,2,0,0,0,0,0,0,0,0,0,0,0,0,0,0,2,1
1,2,0,0,0,0,2,0,0,0,0,0,0,0,0,0,0,0,0,0,0,2,1
22,3,2,2,2,2,3,0,0,0,0,0,0,0,0,0,0,0,0,0,10,3,21
1,24,1,1,1,1,2,0,0,0,0,0,0,0,0,0,0,0,0,0,0,2,1
1,1,1,1,1,1,2,0,0,0,0,0,0,0,0,0,0,0,0,0,0,2,1
1,1,1,1,1,1,2,0,0,0,0,0,0,0,0,0,0,0,0,0,10,2,1
1,1,1,1,1,1,2,10,0,10,0,0,0,0,0,0,0,10,0,0,0,2,1
1,1,1,1,1,22,3,2,2,2,2,3,2,2,2,2,3,2,2,2,2,3,21
1,1,1,1,1,1,24,1,1,1,1,24,1,1,1,1,24,1,1,1,1,24,1
endlayer

layer
3,3,20,20,20,20,3,20,20,20,20,3,20,20,20,20,3,3,1,1,1,1,1
3,3,3,3,3,3,3,3,3,3,3,3,3,3,3,3,3,3,1,1,1,1,1
22,3,2,2,2,2,2,2,2,2,4,0,0,0,0,0,3,21,1,1,1,1,1
22,3,2,2,2,2,2,2,2,2,4,0,0,0,0,0,3,21,1,1,1,1,1
22,3,2,2,2,2,2,2,2,2,2,3,0,0,0,0,3,21,1,1,1,1,1
22,3,2,2,2,2,2,2,2,2,2,3,0,0,0,0,3,21,20,20,20,3,3
3,3,2,2,2,2,2,2,2,2,2,3,3,3,3,3,3,3,3,3,3,3,3
22,3,2,2,2,2,2,2,2,2,2,2,2,2,2,2,2,2,2,2,2,3,21
22,3,2,2,2,2,2,2,2,2,2,2,2,2,2,2,2,2,2,2,2,3,21
22,3,2,2,2,2,2,2,2,2,2,2,2,2,2,2,2,2,2,2,2,3,21
22,3,2,2,2,2,2,2,2,2,2,2,2,2,2,2,2,2,2,2,2,3,21
3,3,2,2,2,2,2,2,2,2,2,2,2,2,2,2,2,2,2,2,2,3,3
22,3,2,2,2,2,2,2,2,2,2,2,2,2,2,2,2,2,2,2,2,3,21
22,3,2,2,2,2,2,2,2,2,2,2,2,2,2,2,2,2,2,2,2,3,21
22,3,2,2,2,2,2,2,2,2,2,2,2,2,2,2,2,2,2,2,2,3,21
22,3,2,2,2,2,2,2,2,2,2,2,2,2,2,2,2,2,2,2,2,3,21
3,3,3,3,3,3,3,2,2,2,2,2,2,2,2,2,2,2,2,2,2,3,3
3,3,24,24,24,22,3,2,2,2,2,2,2,2,2,2,2,2,2,2,2,3,21
1,1,1,1,1,22,3,2,2,2,2,2,2,2,2,2,2,2,2,2,2,3,21
1,1,1,1,1,22,3,2,2,2,2,2,2,2,2,2,2,2,2,2,2,3,21
1,1,1,1,1,22,3,2,2,2,2,2,2,2,2,2,2,2,2,2,2,3,21
1,1,1,1,1,3,3,3,3,3,3,3,3,3,3,3,3,3,3,3,3,3,3
1,1,1,1,1,3,3,24,24,24,24,3,24,24,24,24,3,24,24,24,24,3,3
endlayer

layer
1,1,1,1,1,1,1,1,1,1,1,1,1,1,1,1,1,1,1,1,1,1,1
1,3,2,2,2,2,3,2,2,2,2,3,2,2,2,2,3,1,1,1,1,1,1
1,2,6,6,0,0,0,0,0,0,0,0,0,0,0,0,2,1,1,1,1,1,1
1,2,6,8,25,6,0,0,0,0,0,0,0,0,0,0,2,1,1,1,1,1,1
1,2,0,6,25,26,0,0,0,0,5,2,0,0,0,0,2,1,1,1,1,1,1
1,2,0,6,6,6,6,0,0,0,5,2,10,0,0,0,2,1,1,1,1,1,1
1,3,0,6,0,6,6,10,0,3,2,27,2,2,2,2,3,2,2,2,2,3,1
1,2,8,0,0,0,0,0,0,0,0,2,0,0,0,25,0,0,0,6,6,2,1
1,2,0,0,15,15,15,15,15,0,0,29,0,0,0,0,0,28,0,28,0,2,1
6,2,0,0,15,16,16,16,15,0,0,29,0,6,0,0,0,25,25,25,0,2,1
6,2,6,0,15,16,16,16,15,6,0,2,6,0,0,16,0,0,6,30,6,2,1
6,3,6,6,15,16,16,16,15,0,6,3,6,0,16,16,0,30,6,0,0,3,1
6,2,6,0,15,16,16,16,15,0,6,2,0,0,0,0,6,0,0,6,6,2,1
1,2,6,0,15,15,15,15,15,6,6,2,32,31,16,16,0,0,6,6,6,2,1
1,2,6,6,6,6,0,6,0,0,6,2,32,31,0,0,0,0,0,6,6,2,1
1,2,14,6,6,6,6,0,0,0,0,2,0,0,6,0,25,6,6,6,14,2,1
1,3,2,2,2,2,3,2,13,13,2,3,2,2,2,2,3,2,2,2,2,3,1
1,1,1,1,1,33,0,0,0,0,0,0,0,0,0,6,6,6,0,0,0,0,33
1,1,1,1,1,33,0,0,0,0,0,0,0,0,6,6,6,0,0,0,0,0,33
1,1,1,1,1,33,0,0,0,0,0,0,6,6,0,6,0,0,0,0,0,0,33
1,1,1,1,1,33,0,0,0,0,0,0,0,0,0,0,0,0,0,0,0,0,33
1,1,1,1,1,33,0,0,0,0,0,0,0,0,0,0,0,0,0,0,0,0,33
1,1,1,1,1,3,4,4,4,4,4,4,4,4,5,5,5,5,5,5,5,5,3
endlayer

layer
1,1,1,1,1,1,1,1,1,1,1,1,1,1,1,1,1,1,1,1,1,1,1
1,3,2,17,17,2,3,2,17,17,2,3,2,17,17,2,3,1,1,1,1,1,1
1,2,0,6,0,0,0,0,0,0,0,0,0,0,0,0,2,1,1,1,1,1,1
1,17,0,6,16,0,0,0,0,0,0,0,0,0,0,0,17,1,1,1,1,1,1
1,17,0,0,16,0,0,0,0,0,0,5,21,0,0,0,17,1,1,1,1,1,1
1,2,0,0,0,0,6,0,0,0,0,5,21,0,0,0,2,1,1,1,1,1,1
1,3,0,0,0,0,0,0,10,3,2,3,2,3,3,2,3,2,17,17,2,3,1
1,2,0,0,0,0,0,0,0,0,0,2,0,0,0,0,0,0,0,0,0,2,1
1,17,0,0,0,0,0,0,0,0,0,19,0,0,0,0,0,0,0,0,0,17,1
1,17,0,0,0,0,0,0,0,0,0,18,0,0,0,0,0,16,16,16,0,17,1
6,2,0,0,0,0,0,0,0,0,0,2,0,0,0,0,0,0,0,0,0,2,1
6,3,0,0,0,0,0,0,0,0,6,3,6,0,0,0,0,0,6,0,0,3,1
1,2,0,0,0,0,0,0,0,0,6,2,0,0,0,0,0,0,0,0,6,2,1
1,17,6,0,0,0,0,0,0,0,0,3,0,0,0,0,0,0,0,6,6,17,1
1,17,0,6,6,0,0,0,0,0,0,3,0,0,0,0,0,0,0,6,6,17,1
1,2,6,6,0,6,6,0,0,0,0,2,0,0,0,0,25,0,0,6,6,2,1
1,3,2,17,17,2,3,2,18,19,2,3,2,17,17,2,3,2,17,17,2,3,1
1,1,1,1,1,1,1,1,1,1,1,1,1,1,1,1,6,1,1,1,1,1,1
1,1,1,1,1,1,1,1,1,1,1,1,1,1,1,1,1,1,1,1,1,1,1
1,1,1,1,1,1,1,1,1,1,1,1,1,1,1,1,1,1,1,1,1,1,1
1,1,1,1,1,1,1,1,1,1,1,1,1,1,1,1,1,1,1,1,1,1,1
1,1,1,1,1,1,1,1,1,1,1,1,1,1,1,1,1,1,1,1,1,1,1
1,1,1,1,1,1,1,1,1,1,1,1,1,1,1,1,1,1,1,1,1,1,1
endlayer

layer
1,1,1,1,1,1,1,1,1,1,1,1,1,1,1,1,1,1,1,1,1,1,1
1,3,2,17,17,2,3,2,17,17,2,3,2,17,17,2,3,1,1,1,1,1,1
1,2,0,0,0,0,0,0,0,0,0,0,0,0,0,10,2,1,1,1,1,1,1
1,17,0,0,0,0,0,0,0,0,0,0,0,0,0,0,17,1,1,1,1,1,1
1,17,0,0,0,0,0,0,0,0,0,0,5,21,0,0,17,1,1,1,1,1,1
1,2,0,0,0,0,0,0,0,0,0,0,5,21,0,0,2,1,1,1,1,1,1
1,3,0,0,0,0,0,0,0,3,2,3,2,3,3,2,3,2,17,17,2,3,1
1,2,0,0,0,0,0,0,0,10,0,2,0,0,0,0,0,0,0,0,0,2,1
1,17,0,0,0,0,0,0,0,0,0,3,0,0,0,0,0,0,0,0,0,17,1
1,17,0,0,0,0,0,0,0,0,0,3,0,0,0,0,0,0,0,0,0,17,1
0,2,0,0,0,0,0,0,0,0,0,2,0,0,0,0,0,0,0,0,0,2,1
0,3,0,0,0,0,0,0,0,0,0,3,0,0,0,0,0,0,0,0,0,3,1
1,2,0,0,0,0,0,0,0,0,0,2,0,0,0,0,0,0,0,0,0,2,1
1,17,0,0,0,0,0,0,0,0,0,3,0,0,0,0,0,0,0,0,0,17,1
1,17,0,0,0,0,0,0,0,0,10,3,0,0,0,0,0,0,0,6,6,17,1
1,2,10,0,0,0,0,0,0,0,0,2,0,0,0,0,0,0,0,6,6,2,1
1,3,2,17,17,2,3,2,3,3,2,3,2,17,17,2,3,2,17,17,2,3,1
1,1,1,1,1,1,1,1,1,1,1,1,1,1,1,1,0,1,1,1,1,1,1
1,1,1,1,1,1,1,1,1,1,1,1,1,1,1,1,1,1,1,1,1,1,1
1,1,1,1,1,1,1,1,1,1,1,1,1,1,1,1,1,1,1,1,1,1,1
1,1,1,1,1,1,1,1,1,1,1,1,1,1,1,1,1,1,1,1,1,1,1
1,1,1,1,1,1,1,1,1,1,1,1,1,1,1,1,1,1,1,1,1,1,1
1,1,1,1,1,1,1,1,1,1,1,1,1,1,1,1,1,1,1,1,1,1,1
endlayer

layer
1,20,1,1,1,1,20,1,1,1,1,20,1,1,1,1,20,1,1,1,1,1,1
22,3,2,2,2,2,3,2,2,2,2,3,2,2,2,2,3,21,1,1,1,1,1
1,2,0,10,0,0,0,0,0,0,0,0,0,0,0,0,2,1,1,1,1,1,1
1,2,10,0,0,0,0,0,0,0,0,0,0,0,0,10,2,1,1,1,1,1,1
1,2,0,0,0,0,0,0,0,0,0,0,0,5,21,0,2,1,1,1,1,1,1
1,2,0,0,0,0,0,0,0,0,0,0,0,5,21,0,2,1,1,1,1,20,1
22,3,0,0,0,0,0,0,10,3,2,3,2,2,2,2,3,2,2,2,2,3,21
1,2,0,0,0,0,0,0,0,0,10,2,10,0,0,0,0,0,0,0,0,2,1
1,2,0,0,0,0,0,0,0,0,0,2,0,0,0,0,0,0,0,0,0,2,1
1,2,0,0,0,0,0,0,0,0,0,2,0,0,0,0,0,0,0,0,0,2,1
0,2,0,0,0,0,0,0,0,0,0,2,0,0,0,0,0,0,0,0,0,2,1
22,3,0,0,0,0,0,0,0,0,0,3,0,0,0,0,0,0,0,0,0,3,21
1,2,0,0,0,0,0,0,0,0,0,2,0,0,0,0,0,0,0,0,0,2,1
1,2,0,0,0,0,0,0,0,0,10,2,0,0,0,0,0,0,10,0,10,2,1
1,2,10,0,0,0,0,0,10,0,0,2,10,0,0,0,0,0,0,0,10,2,1
1,2,0,0,0,0,0,10,0,0,10,2,10,0,0,0,0,0,0,0,6,2,1
22,3,2,2,2,2,3,2,2,2,2,3,2,2,2,2,3,2,2,2,2,3,21
1,24,1,1,1,1,24,1,1,1,1,24,1,1,1,1,24,1,1,1,1,24,1
1,1,1,1,1,1,1,1,1,1,1,1,1,1,1,1,1,1,1,1,1,1,1
1,1,1,1,1,1,1,1,1,1,1,1,1,1,1,1,1,1,1,1,1,1,1
1,1,1,1,1,1,1,1,1,1,1,1,1,1,1,1,1,1,1,1,1,1,1
1,1,1,1,1,1,1,1,1,1,1,1,1,1,1,1,1,1,1,1,1,1,1
1,1,1,1,1,1,1,1,1,1,1,1,1,1,1,1,1,1,1,1,1,1,1
endlayer

layer
3,3,20,20,20,20,3,20,20,20,20,3,20,20,20,20,3,3,1,1,1,1,1
3,3,3,3,3,3,3,3,3,3,3,3,3,3,3,3,3,3,1,1,1,1,1
22,3,2,2,2,2,2,2,2,2,2,2,2,2,2,2,3,21,1,1,1,1,1
22,3,2,2,2,2,2,2,2,2,2,2,2,2,2,2,3,21,1,1,1,1,1
22,3,2,2,2,2,2,2,2,2,0,0,0,0,5,2,3,21,1,1,1,1,1
22,3,2,2,2,2,2,2,2,2,0,0,0,0,5,2,3,21,20,20,20,3,3
3,3,2,2,2,2,2,2,2,2,2,2,2,2,2,2,3,3,3,3,3,3,3
22,3,2,2,2,2,2,2,2,2,2,2,2,2,2,2,2,2,2,2,2,3,21
22,3,2,2,2,2,2,2,2,2,2,2,2,2,2,2,2,2,2,2,2,3,21
22,3,2,2,2,2,2,2,2,2,2,2,2,2,2,2,2,2,2,2,2,3,21
22,3,2,2,2,2,2,2,2,2,2,2,2,2,2,2,2,2,2,2,2,3,21
3,3,2,2,2,2,2,2,2,2,2,2,2,2,2,2,2,2,2,2,2,3,3
22,3,2,2,2,2,2,2,2,2,2,2,2,2,2,2,2,2,2,2,2,3,21
22,3,2,2,2,2,2,2,2,2,2,2,2,2,2,2,2,2,2,2,2,3,21
22,3,2,2,2,2,2,2,2,2,2,2,2,2,2,2,2,2,2,2,2,3,21
22,3,2,2,2,2,2,2,2,2,2,2,2,2,2,2,2,2,2,2,2,3,21
3,3,3,3,3,3,3,3,3,3,3,3,3,3,3,3,3,3,3,3,3,3,3
3,3,24,24,24,24,3,24,24,24,24,3,24,24,24,24,3,24,24,24,24,3,3
1,1,1,1,1,1,1,1,1,1,1,1,1,1,1,1,1,1,1,1,1,1,1
1,1,1,1,1,1,1,1,1,1,1,1,1,1,1,1,1,1,1,1,1,1,1
1,1,1,1,1,1,1,1,1,1,1,1,1,1,1,1,1,1,1,1,1,1,1
1,1,1,1,1,1,1,1,1,1,1,1,1,1,1,1,1,1,1,1,1,1,1
1,1,1,1,1,1,1,1,1,1,1,1,1,1,1,1,1,1,1,1,1,1,1
endlayer

layer
3,4,4,4,4,4,0,0,0,0,0,0,0,0,0,0,0,0,1,1,1,1,1
7,0,0,0,0,0,3,2,2,2,2,3,2,2,2,2,3,0,1,1,1,1,1
7,0,0,0,0,0,2,0,0,0,0,0,0,0,0,0,2,0,1,1,1,1,1
7,0,0,0,0,0,2,0,0,3,4,35,5,3,34,0,2,0,1,1,1,1,1
7,0,0,0,0,6,2,0,0,35,0,0,0,0,0,0,2,0,1,1,1,1,1
7,0,0,0,0,0,2,0,0,35,0,0,0,0,0,0,2,5,5,5,5,5,3
7,0,0,0,0,6,3,0,0,3,4,35,5,3,0,0,3,0,0,0,0,0,7
7,0,0,0,6,6,2,0,0,0,6,0,0,0,0,0,2,0,0,0,0,0,7
7,0,0,0,6,6,2,0,0,0,0,0,0,0,0,0,29,0,0,0,0,0,7
33,0,0,0,6,0,2,6,6,6,0,0,0,0,0,0,29,0,0,0,6,0,7
33,0,0,0,6,0,2,6,6,6,0,0,0,0,0,0,2,0,6,6,0,0,7
33,0,0,0,0,0,3,2,2,2,2,3,2,2,2,2,3,6,6,0,0,0,3
33,0,0,0,0,0,0,0,0,0,6,0,0,0,0,6,14,6,6,6,0,0,33
33,0,0,0,0,0,0,0,0,0,0,0,6,6,0,6,6,6,6,6,6,0,33
33,0,0,0,0,0,0,0,0,0,0,0,0,0,0,6,0,6,0,6,0,0,33
33,0,0,0,0,0,0,0,0,0,0,0,0,0,0,0,0,0,0,6,0,0,33
33,0,0,0,0,0,0,0,0,0,0,0,0,0,0,0,0,0,0,6,0,0,33
3,4,4,4,4,4,4,4,4,4,4,2,5,5,5,5,5,5,5,5,5,5,3
1,1,1,1,1,1,1,1,1,1,1,1,1,1,1,1,1,1,1,1,1,1,1
1,1,1,1,1,1,1,1,1,1,1,1,1,1,1,1,1,1,1,1,1,1,1
1,1,1,1,1,1,1,1,1,1,1,1,1,1,1,1,1,1,1,1,1,1,1
1,1,1,1,1,1,1,1,1,1,1,1,1,1,1,1,1,1,1,1,1,1,1
1,1,1,1,1,1,1,1,1,1,1,1,1,1,1,1,1,1,1,1,1,1,1
endlayer

layer
1,1,1,1,1,0,0,0,0,0,0,0,0,0,0,0,0,0,1,1,1,1,1
1,1,1,1,1,0,3,2,17,17,2,3,2,17,17,2,3,0,1,1,1,1,1
1,1,1,1,1,0,2,0,0,0,0,0,0,0,0,0,2,0,1,1,1,1,1
1,1,1,1,1,0,17,0,0,3,0,0,0,3,34,0,17,0,1,1,1,1,1
1,1,1,1,1,0,17,0,0,0,0,0,0,0,0,0,17,0,1,1,1,1,1
1,1,1,1,1,0,2,0,0,0,0,0,0,0,0,0,2,0,1,1,1,1,1
1,1,1,1,1,0,3,0,0,3,0,0,0,3,0,0,3,0,1,1,1,1,1
1,1,1,1,1,0,2,0,0,0,0,0,0,0,0,0,2,0,1,1,1,1,1
1,1,1,1,6,0,17,0,0,0,0,0,0,0,0,0,19,0,1,1,1,1,1
1,1,1,1,1,0,17,0,0,0,0,0,0,0,0,0,18,0,1,1,1,1,1
1,1,1,1,6,0,2,6,6,6,0,0,0,0,0,10,2,0,6,1,1,1,1
1,1,1,1,1,0,3,2,17,17,2,3,2,17,17,2,3,6,6,1,1,1,1
1,1,1,1,1,0,0,0,0,0,0,0,0,0,0,6,6,6,1,1,1,1,1
1,1,1,1,1,1,1,1,1,1,1,1,1,1,1,1,6,6,6,1,1,1,1
1,1,1,1,1,1,1,1,1,1,1,1,1,1,1,1,1,1,1,1,1,1,1
1,1,1,1,1,1,1,1,1,1,1,1,1,1,1,1,1,1,1,1,1,1,1
1,1,1,1,1,1,1,1,1,1,1,1,1,1,1,1,1,1,1,1,1,1,1
1,1,1,1,1,1,1,1,1,1,1,1,1,1,1,1,1,1,1,1,1,1,1
1,1,1,1,1,1,1,1,1,1,1,1,1,1,1,1,1,1,1,1,1,1,1
1,1,1,1,1,1,1,1,1,1,1,1,1,1,1,1,1,1,1,1,1,1,1
1,1,1,1,1,1,1,1,1,1,1,1,1,1,1,1,1,1,1,1,1,1,1
1,1,1,1,1,1,1,1,1,1,1,1,1,1,1,1,1,1,1,1,1,1,1
1,1,1,1,1,1,1,1,1,1,1,1,1,1,1,1,1,1,1,1,1,1,1
endlayer

layer
1,1,1,1,1,0,0,0,0,0,0,0,0,0,0,0,0,0,1,1,1,1,1
1,1,1,1,1,0,3,2,17,17,2,3,2,17,17,2,3,0,1,1,1,1,1
1,1,1,1,1,0,2,0,0,0,0,0,0,0,0,0,2,0,1,1,1,1,1
1,1,1,1,1,0,17,0,0,3,0,0,0,3,34,0,17,0,1,1,1,1,1
1,1,1,1,1,0,17,0,0,0,0,0,0,0,0,0,17,0,1,1,1,1,1
1,1,1,1,1,0,2,0,0,0,0,0,0,0,0,0,2,0,1,1,1,1,1
1,1,1,1,1,0,3,10,0,3,10,10,0,3,0,0,3,0,1,1,1,1,1
1,1,1,1,1,0,2,0,0,0,0,0,0,0,0,0,2,0,1,1,1,1,1
1,1,1,1,1,0,17,0,0,0,0,0,0,0,0,0,3,0,1,1,1,1,1
1,1,1,1,1,0,17,0,0,0,0,0,0,0,0,0,3,0,1,1,1,1,1
1,1,1,1,1,0,2,6,0,0,0,0,0,0,0,0,2,0,1,1,1,1,1
1,1,1,1,1,0,3,2,17,17,2,3,2,17,17,2,3,6,1,1,1,1,1
1,1,1,1,1,0,0,0,0,0,0,0,0,0,0,0,6,6,1,1,1,1,1
1,1,1,1,1,1,1,1,1,1,1,1,1,1,1,1,6,1,1,1,1,1,1
1,1,1,1,1,1,1,1,1,1,1,1,1,1,1,1,1,1,1,1,1,1,1
1,1,1,1,1,1,1,1,1,1,1,1,1,1,1,1,1,1,1,1,1,1,1
1,1,1,1,1,1,1,1,1,1,1,1,1,1,1,1,1,1,1,1,1,1,1
1,1,1,1,1,1,1,1,1,1,1,1,1,1,1,1,1,1,1,1,1,1,1
1,1,1,1,1,1,1,1,1,1,1,1,1,1,1,1,1,1,1,1,1,1,1
1,1,1,1,1,1,1,1,1,1,1,1,1,1,1,1,1,1,1,1,1,1,1
1,1,1,1,1,1,1,1,1,1,1,1,1,1,1,1,1,1,1,1,1,1,1
1,1,1,1,1,1,1,1,1,1,1,1,1,1,1,1,1,1,1,1,1,1,1
1,1,1,1,1,1,1,1,1,1,1,1,1,1,1,1,1,1,1,1,1,1,1
endlayer

layer
1,1,1,1,1,0,20,0,0,0,0,20,0,0,0,0,20,0,1,1,1,1,1
1,1,1,1,1,22,3,2,2,2,2,3,2,2,2,2,3,21,1,1,1,1,1
1,1,1,1,1,0,2,0,0,0,0,0,0,0,0,10,2,0,1,1,1,1,1
1,1,1,1,1,0,2,0,0,3,21,36,22,3,34,10,2,0,1,1,1,1,1
1,1,1,1,1,0,2,0,0,36,0,0,0,36,0,0,2,0,1,1,1,1,1
1,1,1,1,1,0,2,0,0,36,0,0,0,36,0,0,2,0,1,1,1,1,1
1,1,1,1,1,22,3,0,0,3,21,36,22,3,0,0,3,21,1,1,1,1,1
1,1,1,1,1,0,2,0,0,10,0,10,0,0,0,0,2,0,1,1,1,1,1
1,1,1,1,1,0,2,0,0,0,0,0,0,0,0,0,2,0,1,1,1,1,1
1,1,1,1,1,0,2,10,0,0,0,0,0,0,0,0,2,0,1,1,1,1,1
1,1,1,1,1,0,2,10,0,0,0,0,0,0,0,0,2,0,1,1,1,1,1
1,1,1,1,1,22,3,2,2,2,2,3,2,2,2,2,3,21,1,1,1,1,1
1,1,1,1,1,0,24,0,0,0,0,24,0,0,0,0,24,0,1,1,1,1,1
1,1,1,1,1,1,1,1,1,1,1,1,1,1,1,1,1,1,1,1,1,1,1
1,1,1,1,1,1,1,1,1,1,1,1,1,1,1,1,1,1,1,1,1,1,1
1,1,1,1,1,1,1,1,1,1,1,1,1,1,1,1,1,1,1,1,1,1,1
1,1,1,1,1,1,1,1,1,1,1,1,1,1,1,1,1,1,1,1,1,1,1
1,1,1,1,1,1,1,1,1,1,1,1,1,1,1,1,1,1,1,1,1,1,1
1,1,1,1,1,1,1,1,1,1,1,1,1,1,1,1,1,1,1,1,1,1,1
1,1,1,1,1,1,1,1,1,1,1,1,1,1,1,1,1,1,1,1,1,1,1
1,1,1,1,1,1,1,1,1,1,1,1,1,1,1,1,1,1,1,1,1,1,1
1,1,1,1,1,1,1,1,1,1,1,1,1,1,1,1,1,1,1,1,1,1,1
1,1,1,1,1,1,1,1,1,1,1,1,1,1,1,1,1,1,1,1,1,1,1
endlayer

layer
1,1,1,1,1,3,3,20,20,20,20,3,20,20,20,20,3,3,1,1,1,1,1
1,1,1,1,1,3,3,3,3,3,3,3,3,3,3,3,3,3,1,1,1,1,1
1,1,1,1,1,22,3,2,2,2,2,2,2,2,2,2,3,21,1,1,1,1,1
1,1,1,1,1,22,3,2,2,2,2,2,2,2,37,2,3,21,1,1,1,1,1
1,1,1,1,1,22,3,2,2,2,2,2,2,2,2,2,3,21,1,1,1,1,1
1,1,1,1,1,22,3,2,2,2,2,2,2,2,2,2,3,21,1,1,1,1,1
1,1,1,1,1,3,3,2,2,2,2,2,2,2,2,2,3,3,1,1,1,1,1
1,1,1,1,1,22,3,2,2,2,2,2,2,2,2,2,3,21,1,1,1,1,1
1,1,1,1,1,22,3,2,2,2,2,2,2,2,2,2,3,21,1,1,1,1,1
1,1,1,1,1,22,3,2,2,2,2,2,2,2,2,2,3,21,1,1,1,1,1
1,1,1,1,1,22,3,2,2,2,2,2,2,2,2,2,3,21,1,1,1,1,1
1,1,1,1,1,3,3,3,3,3,3,3,3,3,3,3,3,3,1,1,1,1,1
1,1,1,1,1,3,3,24,24,24,24,3,24,24,24,24,3,3,1,1,1,1,1
1,1,1,1,1,1,1,1,1,1,1,1,1,1,1,1,1,1,1,1,1,1,1
1,1,1,1,1,1,1,1,1,1,1,1,1,1,1,1,1,1,1,1,1,1,1
1,1,1,1,1,1,1,1,1,1,1,1,1,1,1,1,1,1,1,1,1,1,1
1,1,1,1,1,1,1,1,1,1,1,1,1,1,1,1,1,1,1,1,1,1,1
1,1,1,1,1,1,1,1,1,1,1,1,1,1,1,1,1,1,1,1,1,1,1
1,1,1,1,1,1,1,1,1,1,1,1,1,1,1,1,1,1,1,1,1,1,1
1,1,1,1,1,1,1,1,1,1,1,1,1,1,1,1,1,1,1,1,1,1,1
1,1,1,1,1,1,1,1,1,1,1,1,1,1,1,1,1,1,1,1,1,1,1
1,1,1,1,1,1,1,1,1,1,1,1,1,1,1,1,1,1,1,1,1,1,1
1,1,1,1,1,1,1,1,1,1,1,1,1,1,1,1,1,1,1,1,1,1,1
endlayer

layer
1,1,1,1,1,3,4,4,4,4,4,3,5,5,5,5,5,3,1,1,1,1,1
1,1,1,1,1,7,0,0,0,0,0,0,0,0,0,0,0,7,1,1,1,1,1
1,1,1,1,1,7,0,0,0,0,0,0,0,0,0,0,0,7,1,1,1,1,1
1,1,1,1,1,7,0,0,0,0,6,0,0,0,0,0,0,7,1,1,1,1,1
1,1,1,1,1,7,0,0,0,0,6,6,0,0,0,0,0,7,1,1,1,1,1
1,1,1,1,1,7,0,6,0,0,6,6,0,0,6,0,0,7,1,1,1,1,1
1,1,1,1,1,3,0,0,6,6,6,6,6,6,0,0,0,3,1,1,1,1,1
1,1,1,1,1,33,0,0,6,6,6,6,0,0,0,0,0,33,1,1,1,1,1
1,1,1,1,1,33,0,0,0,6,6,6,6,0,0,0,0,33,1,1,1,1,1
1,1,1,1,1,33,0,0,6,0,0,0,6,0,0,0,0,33,1,1,1,1,1
1,1,1,1,1,33,0,0,0,0,0,0,0,6,0,0,0,33,1,1,1,1,1
1,1,1,1,1,33,0,0,0,0,0,0,0,0,0,0,0,33,1,1,1,1,1
1,1,1,1,1,3,4,4,4,4,4,3,5,5,5,5,5,3,1,1,1,1,1
1,1,1,1,1,1,1,1,1,1,1,1,1,1,1,1,1,1,1,1,1,1,1
1,1,1,1,1,1,1,1,1,1,1,1,1,1,1,1,1,1,1,1,1,1,1
1,1,1,1,1,1,1,1,1,1,1,1,1,1,1,1,1,1,1,1,1,1,1
1,1,1,1,1,1,1,1,1,1,1,1,1,1,1,1,1,1,1,1,1,1,1
1,1,1,1,1,1,1,1,1,1,1,1,1,1,1,1,1,1,1,1,1,1,1
1,1,1,1,1,1,1,1,1,1,1,1,1,1,1,1,1,1,1,1,1,1,1
1,1,1,1,1,1,1,1,1,1,1,1,1,1,1,1,1,1,1,1,1,1,1
1,1,1,1,1,1,1,1,1,1,1,1,1,1,1,1,1,1,1,1,1,1,1
1,1,1,1,1,1,1,1,1,1,1,1,1,1,1,1,1,1,1,1,1,1,1
1,1,1,1,1,1,1,1,1,1,1,1,1,1,1,1,1,1,1,1,1,1,1
endlayer

