
# Created by Ruins mod version 17.0 Ingame Parser
# authoring Player: ST753M

weight=1
embed_into_distance=8
acceptable_target_blocks=
unacceptable_target_blocks=flowing_water,water,flowing_lava,lava
dimensions=17,13,13

allowable_overhang=8
max_leveling=2
leveling_buffer=0
preserve_water=0
preserve_lava=0

biomesToSpawnIn=dead_swamp,land_of_lakes,taiga,taiga_hills,mutated_redwood_taiga,mutated_redwood_taiga_hills,redwood_taiga,mutated_taiga,redwood_taiga_hills,redwood_forest,coniferous_forest,shield,dead_forest,autumnal_wooded_hills,autumnal_woods,snowy_forest,mutated_taiga_cold,snowy_coniferous_forest,taiga_cold,taiga_cold_hills,extreme_hills,smaller_extreme_hills,mutated_extreme_hills,mutated_extreme_hills_with_trees,extreme_hills_with_trees,highland,alps,alps_foothills,mountain,mountain_foothills,crag,cliffs,dark_forest,dark_forest_center,deep_mushroom_forest,dense_twilight_forest,enchanted_forest,fire_swamp,firefly_forest,highlands_center,mushroom_forest,oak_savannah,thornlands,twilight_clearing,twilight_forest,twilight_glacier,twilight_highlands,twilight_lake,twilight_stream,twilight_swamp,hills_defiled

=0,100,air

rule1=0,100,preserveBlock
rule2=0,100,minecraft:stone_stairs-4
rule3=0,100,minecraft:cobblestone-0
rule4=0,100,minecraft:stone_stairs-6
rule5=0,100,minecraft:stone_slab-3
rule6=0,100,minecraft:stone_stairs-1
rule7=0,100,minecraft:stone_stairs-7
rule8=0,100,minecraft:stone_stairs-2
rule9=0,100,minecraft:stone_stairs-3
rule10=0,100,minecraft:stone_stairs-0
rule11=0,100,minecraft:stone_stairs-5
rule12=0,100,minecraft:cobblestone_wall-0

rule13=0,100,IInventory;minecraft:chest;minecraft:bucket#1#0#6+minecraft:potion#{Potion:"minecraft:long_swiftness"}#0#12+minecraft:golden_apple#1#0#16+minecraft:iron_helmet#1#0#19-2,IInventory;minecraft:chest;minecraft:iron_boots#1#0#2+minecraft:spawn_egg#{EntityTag:{id:"minecraft:bat"}}#0#14+minecraft:bucket#1#0#16+minecraft:potion#{Potion:"minecraft:long_strength"}#0#20+minecraft:iron_ingot#5#0#22-3,IInventory;minecraft:chest;minecraft:coal#3#1#5+minecraft:bucket#1#0#7+minecraft:skull#1#4#12+minecraft:gold_ingot#4#0#19+minecraft:potion#{Potion:"minecraft:long_regeneration"}#0#24-5,IInventory;minecraft:chest;minecraft:bucket#1#0#8+minecraft:potion#{Potion:"minecraft:fire_resistance"}#0#12+minecraft:enchanted_book#{StoredEnchantments:[{lvl:3s,id:62s}]}#0#15+minecraft:gold_ingot#3#0#19+minecraft:iron_sword#{}#0#22-2,IInventory;minecraft:chest;minecraft:diamond#1#0#4+minecraft:gold_ingot#3#0#10+minecraft:skull#1#0#15+minecraft:potion#{Potion:"minecraft:long_fire_resistance"}#0#21-3,IInventory;minecraft:chest;minecraft:coal#6#1#7+minecraft:gold_ingot#3#0#11+minecraft:potion#{Potion:"minecraft:night_vision"}#0#14+minecraft:skull#1#3#24-5,IInventory;minecraft:chest;minecraft:diamond#1#0#2+minecraft:iron_ingot#4#0#5+minecraft:potion#{Potion:"minecraft:leaping"}#0#12+minecraft:coal#3#1#17+minecraft:diamond#2#0#24-2,IInventory;minecraft:chest;minecraft:skull#1#2#5+minecraft:potion#{Potion:"minecraft:long_night_vision"}#0#11+minecraft:iron_leggings#1#0#22+minecraft:diamond#1#0#25-3,IInventory;minecraft:chest;minecraft:iron_chestplate#1#0#3+minecraft:potion#{Potion:"minecraft:long_leaping"}#0#13+minecraft:spawn_egg#{EntityTag:{id:"minecraft:cave_spider"}}#0#15+minecraft:diamond#1#0#20-5

rule14=0,100,minecraft:stone_slab-11

layer
1,1,1,1,1,1,1,1,1,1,1,1,1
1,1,1,1,1,2,3,2,1,1,1,1,1
1,1,1,2,3,3,3,3,3,2,1,1,1
1,1,7,3,3,5,6,5,3,3,4,1,1
1,1,3,3,5,9,3,8,5,3,3,1,1
1,7,3,5,10,3,10,3,10,5,3,4,1
1,3,3,8,3,9,3,8,3,9,3,3,1
1,7,3,5,6,3,6,3,6,5,3,4,1
1,1,3,3,5,9,3,8,5,3,3,1,1
1,1,7,3,3,5,10,5,3,3,4,1,1
1,1,1,11,3,3,3,3,3,11,1,1,1
1,1,1,1,1,11,3,11,1,1,1,1,1
1,1,1,1,1,1,1,1,1,1,1,1,1
endlayer

layer
1,1,1,1,1,2,3,2,1,1,1,1,1
1,1,1,2,3,12,12,12,3,2,1,1,1
1,1,3,0,12,0,0,0,12,0,3,1,1
1,7,0,0,0,0,0,0,0,0,0,4,1
1,3,12,0,0,0,0,0,0,0,12,3,1
7,12,0,0,0,0,0,0,0,0,0,12,4
3,12,0,0,0,0,13,0,0,0,0,12,3
7,12,0,0,0,0,0,0,0,0,0,12,4
1,3,12,0,0,0,0,0,0,0,12,3,1
1,7,0,0,0,0,0,0,0,0,0,4,1
1,1,3,0,12,0,0,0,12,0,3,1,1
1,1,1,11,3,12,12,12,3,11,1,1,1
1,1,1,1,1,11,3,11,1,1,1,1,1
endlayer

layer
1,1,1,1,1,3,3,3,1,1,1,1,1
1,1,1,3,3,5,5,5,3,3,1,1,1
1,1,3,0,12,0,0,0,12,0,3,1,1
1,3,0,0,0,0,0,0,0,0,0,3,1
1,3,12,0,0,0,0,0,0,0,12,3,1
3,5,0,0,0,0,0,0,0,0,0,5,3
3,5,0,0,0,0,0,0,0,0,0,5,3
3,5,0,0,0,0,0,0,0,0,0,5,3
1,3,12,0,0,0,0,0,0,0,12,3,1
1,3,0,0,0,0,0,0,0,0,0,3,1
1,1,3,0,12,0,0,0,12,0,3,1,1
1,1,1,3,3,5,5,5,3,3,1,1,1
1,1,1,1,1,3,3,3,1,1,1,1,1
endlayer

layer
1,1,1,1,1,10,6,10,1,1,1,1,1
1,1,1,9,3,0,0,0,3,8,1,1,1
1,1,0,0,12,0,0,0,12,0,0,1,1
1,10,0,0,0,0,0,0,0,0,0,10,1
1,3,12,0,0,0,0,0,0,0,12,3,1
9,0,0,0,0,0,0,0,0,0,0,0,8
8,0,0,0,0,0,0,0,0,0,0,0,9
9,0,0,0,0,0,0,0,0,0,0,0,8
1,3,12,0,0,0,0,0,0,0,12,3,1
1,6,0,0,0,0,0,0,0,0,0,6,1
1,1,0,0,12,0,0,0,12,0,0,1,1
1,1,1,9,3,0,0,0,3,8,1,1,1
1,1,1,1,1,6,10,6,1,1,1,1,1
endlayer

layer
1,1,1,1,1,3,11,3,1,1,1,1,1
1,1,1,7,3,0,0,0,3,4,1,1,1
1,1,0,0,12,0,0,0,12,0,0,1,1
1,2,0,0,0,0,0,0,0,0,0,2,1
1,3,12,0,0,0,0,0,0,0,12,3,1
3,0,0,0,0,0,0,0,0,0,0,0,3
4,0,0,0,0,0,0,0,0,0,0,0,7
3,0,0,0,0,0,0,0,0,0,0,0,3
1,3,12,0,0,0,0,0,0,0,12,3,1
1,11,0,0,0,0,0,0,0,0,0,11,1
1,1,0,0,12,0,0,0,12,0,0,1,1
1,1,1,7,3,0,0,0,3,4,1,1,1
1,1,1,1,1,3,2,3,1,1,1,1,1
endlayer

layer
1,1,1,1,1,2,3,2,1,1,1,1,1
1,1,1,3,3,12,0,12,3,3,1,1,1
1,1,3,0,12,0,0,0,12,0,3,1,1
1,3,0,0,0,0,0,0,0,0,0,3,1
1,3,12,0,0,0,0,0,0,0,12,3,1
7,12,0,0,0,0,0,0,0,0,0,12,4
3,0,0,0,0,0,0,0,0,0,0,0,3
7,12,0,0,0,0,0,0,0,0,0,12,4
1,3,12,0,0,0,0,0,0,0,12,3,1
1,3,0,0,0,0,0,0,0,0,0,3,1
1,1,3,0,12,0,0,0,12,0,3,1,1
1,1,1,3,3,12,0,12,3,3,1,1,1
1,1,1,1,1,11,3,11,1,1,1,1,1
endlayer

layer
1,1,1,1,1,3,10,3,1,1,1,1,1
1,1,1,3,10,6,14,6,10,3,1,1,1
1,1,3,0,12,0,0,0,12,0,3,1,1
1,3,0,0,0,0,12,0,0,0,0,3,1
1,9,12,0,0,0,0,0,0,0,12,8,1
3,8,0,0,0,0,0,0,0,0,0,9,3
9,14,0,12,0,0,0,0,0,12,0,14,8
3,8,0,0,0,0,0,0,0,0,0,9,3
1,9,12,0,0,0,0,0,0,0,12,8,1
1,3,0,0,0,0,12,0,0,0,0,3,1
1,1,3,0,12,0,0,0,12,0,3,1,1
1,1,1,3,6,10,14,10,6,3,1,1,1
1,1,1,1,1,3,6,3,1,1,1,1,1
endlayer

layer
1,1,1,1,1,1,5,1,1,1,1,1,1
1,1,1,1,1,3,3,3,1,1,1,1,1
1,1,5,3,3,0,0,0,3,3,5,1,1
1,1,3,0,0,0,12,0,0,0,3,1,1
1,1,3,0,0,0,0,0,0,0,3,1,1
1,3,0,0,0,0,0,0,0,0,0,3,1
5,3,0,12,0,0,0,0,0,12,0,3,5
1,3,0,0,0,0,0,0,0,0,0,3,1
1,1,3,0,0,0,0,0,0,0,3,1,1
1,1,3,0,0,0,12,0,0,0,3,1,1
1,1,5,3,3,0,0,0,3,3,5,1,1
1,1,1,1,1,3,3,3,1,1,1,1,1
1,1,1,1,1,1,5,1,1,1,1,1,1
endlayer

layer
1,1,1,1,1,1,1,1,1,1,1,1,1
1,1,1,1,1,10,3,10,1,1,1,1,1
1,1,1,5,1,3,3,3,1,5,1,1,1
1,1,5,3,3,3,3,3,3,3,5,1,1
1,1,1,3,3,5,5,5,3,3,1,1,1
1,9,3,3,5,0,0,0,5,3,3,8,1
1,3,3,3,5,0,0,0,5,3,3,3,1
1,9,3,3,5,0,0,0,5,3,3,8,1
1,1,1,3,3,5,5,5,3,3,1,1,1
1,1,5,3,3,3,3,3,3,3,5,1,1
1,1,1,5,1,3,3,3,1,5,1,1,1
1,1,1,1,1,6,3,6,1,1,1,1,1
1,1,1,1,1,1,1,1,1,1,1,1,1
endlayer

layer
1,1,1,1,1,1,1,1,1,1,1,1,1
1,1,1,1,1,1,3,1,1,1,1,1,1
1,1,1,1,1,0,12,0,1,1,1,1,1
1,1,1,1,10,10,3,10,10,1,1,1,1
1,1,1,9,3,6,6,6,3,8,1,1,1
1,1,0,9,8,0,0,0,9,8,0,1,1
1,3,12,3,8,0,0,0,9,3,12,3,1
1,1,0,9,8,0,0,0,9,8,0,1,1
1,1,1,9,3,10,10,10,3,8,1,1,1
1,1,1,1,6,6,3,6,6,1,1,1,1
1,1,1,1,1,0,12,0,1,1,1,1,1
1,1,1,1,1,1,3,1,1,1,1,1,1
1,1,1,1,1,1,1,1,1,1,1,1,1
endlayer

layer
1,1,1,1,1,1,1,1,1,1,1,1,1
1,1,1,1,1,1,12,1,1,1,1,1,1
1,1,1,1,1,0,0,0,1,1,1,1,1
1,1,1,1,0,0,12,0,0,1,1,1,1
1,1,1,0,3,0,0,0,3,0,1,1,1
1,1,0,0,0,0,0,0,0,0,0,1,1
1,12,0,12,0,0,0,0,0,12,0,12,1
1,1,0,0,0,0,0,0,0,0,0,1,1
1,1,1,0,3,0,0,0,3,0,1,1,1
1,1,1,1,0,0,12,0,0,1,1,1,1
1,1,1,1,1,0,0,0,1,1,1,1,1
1,1,1,1,1,0,12,1,1,1,1,1,1
1,1,1,1,1,0,1,1,1,1,1,1,1
endlayer

layer
1,1,1,1,1,1,1,1,1,1,1,1,1
1,1,1,1,1,1,12,1,1,1,1,1,1
1,1,1,1,1,0,0,0,1,1,1,1,1
1,1,1,1,0,0,0,0,0,1,1,1,1
1,1,1,0,12,0,0,0,12,0,1,1,1
1,1,0,0,0,0,0,0,0,0,0,1,1
1,12,0,0,0,0,0,0,0,0,0,12,1
1,1,0,0,0,0,0,0,0,0,0,1,1
1,1,1,0,12,0,0,0,12,0,1,1,1
1,1,1,1,0,0,0,0,0,1,1,1,1
1,1,1,1,1,0,0,0,1,1,1,1,1
1,1,1,1,1,0,12,1,1,1,1,1,1
1,1,1,1,1,0,1,1,1,1,1,1,1
endlayer

layer
1,1,1,1,1,1,1,1,1,1,1,1,1
1,1,1,1,1,1,12,1,1,1,1,1,1
1,1,1,1,1,0,0,0,1,1,1,1,1
1,1,1,1,0,0,0,0,0,1,1,1,1
1,1,1,0,3,0,0,0,3,0,1,1,1
1,1,0,0,0,0,0,0,0,0,0,1,1
1,12,0,0,0,0,0,0,0,0,0,12,1
1,1,0,0,0,0,0,0,0,0,0,1,1
1,1,1,0,3,0,0,0,3,0,1,1,1
1,1,1,1,0,0,0,0,0,1,1,1,1
1,1,1,1,1,0,0,0,1,1,1,1,1
1,1,1,1,1,0,12,1,1,1,1,1,1
1,1,1,1,1,0,1,1,1,1,1,1,1
endlayer

layer
1,1,1,1,1,1,1,1,1,1,1,1,1
1,1,1,1,1,1,12,1,1,1,1,1,1
1,1,1,1,1,14,14,14,1,1,1,1,1
1,1,1,1,14,3,3,3,14,1,1,1,1
1,1,1,14,3,3,11,3,3,14,1,1,1
1,1,14,3,3,14,14,14,3,3,14,1,1
1,12,14,3,4,14,0,14,7,3,14,12,1
1,1,14,3,3,14,14,14,3,3,14,1,1
1,1,1,14,3,3,2,3,3,14,1,1,1
1,1,1,1,14,3,3,3,14,1,1,1,1
1,1,1,1,1,14,14,14,1,1,1,1,1
1,1,1,1,1,1,12,1,1,1,1,1,1
1,1,1,1,1,1,1,1,1,1,1,1,1
endlayer

layer
1,1,1,1,1,1,1,1,1,1,1,1,1
1,1,1,1,1,5,3,5,1,1,1,1,1
1,1,1,14,5,5,5,5,5,14,1,1,1
1,1,14,5,5,0,0,0,5,5,14,1,1
1,1,5,5,0,0,0,0,0,5,5,1,1
1,5,5,0,0,0,5,0,0,0,5,5,1
1,3,5,0,0,5,3,5,0,0,5,3,1
1,5,5,0,0,0,5,0,0,0,5,5,1
1,1,5,5,0,0,0,0,0,5,5,1,1
1,1,14,5,5,0,0,0,5,5,14,1,1
1,1,1,14,5,5,5,5,5,14,1,1,1
1,1,1,1,1,5,3,5,1,1,1,1,1
1,1,1,1,1,1,1,1,1,1,1,1,1
endlayer

layer
1,1,1,1,1,1,1,1,1,1,1,1,1
1,1,1,1,1,0,12,0,1,1,1,1,1
1,1,1,12,0,0,0,0,0,12,1,1,1
1,1,12,0,0,0,0,0,0,0,12,1,1
1,1,0,0,0,0,0,0,0,0,0,1,1
1,0,0,0,0,0,0,0,0,0,0,0,1
1,12,0,0,0,0,0,0,0,0,0,12,1
1,0,0,0,0,0,0,0,0,0,0,0,1
1,1,0,0,0,0,0,0,0,0,0,1,1
1,1,12,0,0,0,0,0,0,0,12,1,1
1,1,1,12,0,0,0,0,0,12,1,1,1
1,1,1,1,1,0,12,0,1,1,1,1,1
1,1,1,1,1,1,1,1,1,1,1,1,1
endlayer

layer
1,1,1,1,1,1,1,1,1,1,1,1,1
1,1,1,1,1,0,0,0,1,1,1,1,1
1,1,1,5,0,0,0,0,0,5,1,1,1
1,1,5,0,0,0,0,0,0,0,5,1,1
1,1,0,0,0,0,0,0,0,0,0,1,1
1,0,0,0,0,0,0,0,0,0,0,0,1
1,0,0,0,0,0,0,0,0,0,0,0,1
1,0,0,0,0,0,0,0,0,0,0,0,1
1,1,0,0,0,0,0,0,0,0,0,1,1
1,1,5,0,0,0,0,0,0,0,5,1,1
1,1,1,5,0,0,0,0,0,5,1,1,1
1,1,1,1,1,0,0,0,1,1,1,1,1
1,1,1,1,1,1,1,1,1,1,1,1,1
endlayer

