
# Created by Ruins mod version 17.0 Ingame Parser
# authoring Player: ST753M

weight=1
embed_into_distance=2
acceptable_target_blocks=grass,dirt
unacceptable_target_blocks=flowing_water,water,flowing_lava,lava,ice,bedrock,netherrack,nether_brick,nether_brick_fence,soul_sand,quartz_ore,end_stone,obsidian,iron_bars,Natura:Cloud,slime_grass,slime_congealed,slime_dirt,clouds,natura:clouds
dimensions=15,18,17
allowable_overhang=2
max_leveling=2
leveling_buffer=0
preserve_water=0
preserve_lava=0
preventRotation=1

biomesToSpawnIn=magical_forest,mutated_roofed_forest,darklands_forest,mutated_redwood_taiga_hills

=0,100,air
rule1=0,100,preserveBlock
rule2=0,100,thaumcraft:log_greatwood-1
rule3=0,100,thaumcraft:stone_arcane_brick-0
rule4=0,100,minecraft:stained_hardened_clay-9
rule5=0,100,thaumcraft:log_greatwood-2
rule6=0,100,thaumcraft:log_greatwood-0
rule7=0,100,thaumcraft:plank_greatwood-0
rule8=0,100,thaumcraft:stairs_greatwood-0
rule9=0,100,thaumcraft:stairs_greatwood-1
rule10=0,100,thaumcraft:stone_arcane-0
rule11=0,100,minecraft:netherrack-0
rule12=0,100,minecraft:spruce_stairs-3
rule13=0,100,thaumcraft:table_wood-0
rule14=0,100,minecraft:spruce_stairs-2
rule15=0,100,minecraft:spruce_door-1
rule16=0,100,thaumcraft:loot_urn_common-0,thaumcraft:loot_urn_common-0,thaumcraft:loot_urn_common-0,thaumcraft:loot_urn_uncommon-0
rule17=0,100,minecraft:spruce_door-3
rule18=0,100,minecraft:cauldron-0
rule19=0,100,minecraft:crafting_table-0
rule20=0,100,minecraft:furnace-4
rule21=0,100,thaumcraft:stairs_greatwood-2
rule22=0,100,thaumcraft:loot_crate_common-0,thaumcraft:loot_crate_common-0,thaumcraft:loot_crate_common-0,thaumcraft:loot_crate_uncommon-0
rule23=0,100,minecraft:iron_bars-0
rule24=0,100,minecraft:fire-15
rule25=0,100,thaumcraft:stairs_arcane-2
rule26=0,100,thaumcraft:stairs_arcane-3
rule27=0,100,minecraft:stained_glass_pane-7
rule28=0,100,thaumcraft:candle_white-0
rule29=0,100,minecraft:spruce_door-9
rule30=0,100,minecraft:spruce_door-8
rule31=0,100,minecraft:lever-11
rule32=0,100,thaumcraft:stairs_greatwood-7
rule33=0,100,thaumcraft:stairs_arcane-4
rule34=0,100,thaumcraft:stairs_greatwood-3
rule35=0,100,minecraft:bed-10
rule36=0,100,minecraft:bed-2

#	A good place to put command blocks if i want them?
rule37=0,100,air
rule38=0,100,air

rule39=0,100,thaumcraft:stairs_arcane-0
rule40=0,100,thaumcraft:stairs_arcane-1

layer
1,1,1,1,1,1,1,1,1,1,1,1,1,1,1,1,1
1,1,1,1,1,1,1,2,3,3,3,3,3,2,1,1,1
1,1,1,1,1,1,1,3,4,4,4,4,4,3,1,1,1
1,1,1,1,1,1,1,3,4,4,4,4,4,3,1,1,1
1,2,3,3,3,3,3,2,4,4,4,4,4,3,1,1,1
1,3,4,4,4,4,4,4,4,4,4,4,4,3,1,1,1
1,3,4,4,4,4,4,4,4,4,4,4,4,3,1,1,1
1,3,4,4,4,4,4,4,4,4,4,4,4,2,2,5,5
1,3,4,4,4,4,4,4,4,4,4,4,4,4,3,7,6
1,3,4,4,4,4,4,4,4,4,4,4,4,4,3,7,6
1,3,4,4,4,4,4,4,4,4,4,4,4,2,2,5,5
1,3,4,4,4,4,4,4,4,4,4,4,4,3,1,1,1
1,3,4,4,4,4,4,4,4,4,4,4,4,3,1,1,1
1,2,3,3,3,3,3,2,4,4,4,4,4,3,1,1,1
1,1,1,1,1,1,1,3,4,4,4,4,4,3,1,1,1
1,1,1,1,1,1,1,3,4,4,4,4,4,3,1,1,1
1,1,1,1,1,1,1,2,3,3,3,3,3,2,1,1,1
1,1,1,1,1,1,1,1,3,3,3,3,3,1,1,1,1
endlayer

layer
1,1,1,1,1,1,1,1,1,1,1,1,1,1,1,1,1
1,1,1,1,1,1,1,2,5,5,5,5,5,2,1,1,1
1,1,1,1,1,1,1,6,7,7,7,7,7,6,1,1,1
1,1,1,1,1,1,1,6,7,7,7,7,7,6,1,1,1
1,2,5,5,5,5,5,2,7,7,7,7,7,6,1,1,1
1,6,7,7,7,7,7,7,7,7,7,7,7,6,1,1,1
1,6,7,7,7,7,7,7,7,7,7,7,7,6,1,1,1
1,6,7,7,7,7,7,7,7,7,7,7,7,2,2,8,8
1,6,7,7,7,7,7,7,7,7,7,7,7,7,6,7,7
1,6,7,7,7,7,7,7,7,7,7,7,7,7,6,7,7
1,6,7,7,7,7,7,7,7,7,7,7,7,2,2,9,9
1,6,7,7,7,7,7,7,7,7,7,7,7,6,1,1,1
1,6,7,7,7,7,7,7,7,7,7,7,7,6,1,1,1
1,2,5,5,5,5,5,2,7,7,7,7,7,6,1,1,1
1,1,1,1,1,1,1,6,7,3,3,3,7,6,1,1,1
1,1,1,1,1,1,1,6,7,10,3,10,7,6,1,1,1
1,1,1,1,1,1,1,2,5,10,11,10,5,2,1,1,1
1,1,1,1,1,1,1,0,10,10,10,10,10,0,1,1,1
endlayer

layer
1,1,1,1,1,1,1,1,1,1,1,1,1,1,1,1,1
1,1,1,1,1,1,1,2,3,3,2,3,3,2,1,1,1
1,1,1,1,1,1,1,3,0,0,0,0,0,3,1,1,1
1,1,1,1,1,1,1,3,14,0,13,0,12,3,1,1,1
1,2,3,3,2,3,3,2,14,0,13,0,12,2,1,1,1
1,3,16,0,0,0,0,15,0,0,0,0,0,3,1,1,1
1,3,0,0,0,0,0,15,0,0,0,0,0,3,1,1,1
1,2,0,0,0,0,10,2,0,0,0,0,0,2,2,0,0
1,3,0,0,0,0,18,3,0,0,0,0,0,0,17,0,0
1,3,0,0,20,10,19,3,0,0,0,0,0,0,17,0,0
1,2,0,0,2,3,3,2,0,0,0,0,0,2,2,0,0
1,3,0,0,0,7,7,21,0,0,0,0,0,3,1,1,1
1,3,0,0,22,7,7,21,0,0,0,0,12,3,1,1,1
1,2,3,3,2,3,3,2,0,0,0,0,12,2,1,1,1
1,1,1,1,1,1,1,3,0,0,0,0,0,3,1,1,1
1,1,1,1,1,1,1,3,16,10,23,10,0,3,1,1,1
1,1,1,1,1,1,1,2,3,3,24,3,3,2,1,1,1
1,1,1,1,1,1,1,0,0,26,3,25,0,0,1,1,1
endlayer

layer
1,1,1,1,1,1,1,1,1,1,1,1,1,1,1,1,1
1,1,1,1,1,1,1,2,27,27,2,27,27,2,1,1,1
1,1,1,1,1,1,1,27,0,0,0,0,0,27,1,1,1
1,1,1,1,1,1,1,27,0,0,28,0,0,27,1,1,1
1,2,27,27,2,27,27,2,0,0,0,0,0,2,1,1,1
1,27,0,0,0,0,0,29,0,0,0,0,0,27,1,1,1
1,27,0,0,0,0,0,30,0,0,0,0,0,27,1,1,1
1,2,0,0,0,0,0,2,0,0,0,0,0,2,2,0,0
1,27,0,0,0,0,31,7,0,0,0,0,0,0,30,0,0
1,27,0,0,0,28,0,7,0,0,0,0,0,0,29,0,0
1,2,0,0,2,7,7,2,0,0,0,0,0,2,2,0,0
1,27,0,0,0,7,21,0,0,0,0,0,0,27,1,1,1
1,27,0,0,0,7,21,0,0,0,0,0,0,27,1,1,1
1,2,27,27,2,7,7,2,0,0,0,0,0,2,1,1,1
1,1,1,1,1,1,1,27,0,0,0,0,0,27,1,1,1
1,1,1,1,1,1,1,27,0,10,0,10,0,27,1,1,1
1,1,1,1,1,1,1,2,7,3,0,3,7,2,1,1,1
1,1,1,1,1,1,1,0,0,26,3,25,0,0,1,1,1
endlayer

layer
1,1,1,1,1,1,1,1,1,1,1,1,1,1,1,1,1
1,1,1,1,1,1,1,2,27,27,2,27,27,2,1,1,1
1,1,1,1,1,1,1,27,0,0,0,0,0,27,1,1,1
1,1,1,1,1,1,1,27,0,0,0,0,0,27,1,1,1
1,2,27,27,2,27,27,2,0,0,0,0,0,2,1,1,1
1,27,0,0,0,0,0,6,0,0,0,0,0,27,1,1,1
1,27,0,0,0,0,0,6,0,0,0,0,0,27,1,1,1
1,2,0,0,0,0,0,2,0,0,0,0,0,2,2,0,0
1,27,0,0,0,0,0,7,0,0,0,0,0,0,6,0,0
1,27,0,0,0,0,0,7,0,0,0,0,0,0,6,0,0
1,2,0,0,2,7,7,2,0,0,0,0,0,2,2,0,0
1,27,0,0,32,21,0,0,0,0,0,0,0,27,1,1,1
1,27,0,0,32,21,0,0,0,0,0,0,0,27,1,1,1
1,2,27,27,2,7,7,2,0,0,0,0,0,2,1,1,1
1,1,1,1,1,1,1,27,0,33,33,33,0,27,1,1,1
1,1,1,1,1,1,1,27,0,10,0,10,0,27,1,1,1
1,1,1,1,1,1,1,2,7,3,0,3,7,2,1,1,1
1,1,1,1,1,1,1,0,0,26,3,25,0,0,1,1,1
endlayer

layer
1,1,1,1,1,1,1,1,1,1,1,1,1,1,1,1,1
1,1,1,1,1,1,1,2,3,3,2,3,3,2,1,1,1
1,1,1,1,1,1,1,3,0,0,0,0,0,3,1,1,1
1,1,1,1,1,1,1,3,0,0,0,0,0,3,1,1,1
1,2,3,3,2,3,3,2,0,0,0,0,0,2,1,1,1
1,3,0,0,0,0,0,3,0,0,0,0,0,3,1,1,1
1,3,0,0,0,0,0,3,0,0,0,0,0,3,1,1,1
1,2,0,0,0,0,0,2,0,0,0,0,0,2,2,0,1
1,3,0,0,0,0,0,3,0,0,0,0,0,6,3,0,0
1,3,0,0,0,0,0,3,0,0,0,0,0,6,3,0,0
1,2,0,0,2,3,3,2,0,0,0,0,0,2,2,0,1
1,3,0,32,21,0,0,0,0,0,0,0,0,3,1,1,1
1,3,0,32,21,0,0,0,0,0,0,0,0,3,1,1,1
1,2,3,3,2,3,3,2,0,0,0,0,0,2,1,1,1
1,1,1,1,1,1,1,3,0,3,23,3,0,3,1,1,1
1,1,1,1,1,1,1,3,0,10,0,10,0,3,1,1,1
1,1,1,1,1,1,1,2,3,3,0,3,3,2,1,1,1
1,1,1,1,1,1,1,0,0,26,3,25,0,0,1,1,1
endlayer

layer
1,1,1,1,1,1,8,8,8,8,8,8,8,8,8,1,1
1,1,1,1,1,1,34,2,5,5,5,5,5,2,21,1,1
1,1,1,1,1,1,34,6,7,7,7,7,7,6,21,1,1
8,8,8,8,8,8,8,6,7,7,7,7,7,6,21,1,1
34,2,5,5,5,5,5,2,7,7,7,7,7,6,21,1,1
34,6,7,7,7,7,7,7,7,7,7,7,7,6,21,1,1
34,6,7,7,7,7,7,7,7,7,7,7,7,6,21,8,1
34,6,7,7,7,7,7,7,7,7,7,7,7,2,2,21,1
34,6,7,7,7,7,7,7,7,7,7,7,7,6,6,21,1
34,6,7,7,7,7,7,7,7,7,7,7,7,6,6,21,1
34,6,7,7,7,7,7,7,7,7,7,7,7,2,2,21,1
34,6,7,21,0,0,0,32,7,7,7,7,7,6,21,9,1
34,6,7,21,0,0,0,32,7,7,7,7,7,6,21,1,1
34,2,5,5,5,5,5,2,7,7,7,7,7,6,21,1,1
34,9,9,9,9,9,34,6,7,3,3,3,7,6,21,1,1
1,1,1,1,1,1,34,6,7,10,3,10,7,6,21,1,1
1,1,1,1,1,1,34,2,5,3,11,3,5,2,21,1,1
1,1,1,1,1,1,34,9,9,10,3,10,9,9,9,1,1
endlayer

layer
1,1,1,1,1,1,1,1,1,1,1,1,1,1,1,1,1
1,1,1,1,1,1,1,34,8,8,8,8,8,21,1,1,1
1,1,1,1,1,1,1,34,7,7,7,7,7,21,1,1,1
1,1,1,1,1,1,1,34,7,7,7,7,7,21,1,1,1
1,2,3,3,2,3,3,2,3,3,2,3,3,2,1,1,1
1,3,0,0,0,0,0,3,22,0,0,0,0,3,1,1,1
1,3,14,0,13,0,12,3,0,0,0,0,0,3,1,1,1
1,2,14,0,13,0,12,2,0,0,0,0,13,2,8,1,1
1,3,0,0,0,0,0,15,0,0,0,36,35,3,21,1,1
1,3,0,0,0,0,0,15,0,0,0,36,35,3,21,1,1
1,2,0,0,0,0,0,2,0,0,0,0,13,2,9,1,1
1,3,0,0,0,0,0,3,0,0,0,0,0,3,1,1,1
1,3,0,0,0,0,0,3,0,38,0,37,0,3,1,1,1
1,2,3,3,2,3,3,2,0,0,0,0,0,2,1,1,1
1,1,1,1,1,1,1,3,0,0,0,0,0,3,1,1,1
1,1,1,1,1,1,1,3,13,10,23,10,0,3,1,1,1
1,1,1,1,1,1,1,2,3,3,24,3,3,2,1,1,1
1,1,1,1,1,1,1,0,0,26,3,25,0,0,1,1,1
endlayer

layer
1,1,1,1,1,1,1,1,1,1,1,1,1,1,1,1,1
1,1,1,1,1,1,1,1,1,1,1,1,1,1,1,1,1
1,1,1,1,1,1,1,1,1,1,1,1,1,1,1,1,1
1,1,1,1,1,1,1,1,1,1,1,1,1,1,1,1,1
1,2,27,27,2,27,27,2,27,27,2,27,27,2,1,1,1
1,27,0,0,0,0,0,7,0,0,0,0,0,27,1,1,1
1,27,0,0,28,0,0,7,0,0,0,0,0,27,1,1,1
1,2,0,0,0,0,0,2,0,0,0,0,28,2,1,1,1
1,27,0,0,0,0,0,29,0,0,0,0,0,27,1,1,1
1,27,0,0,0,0,0,30,0,0,0,0,0,27,1,1,1
1,2,0,0,0,0,0,2,0,0,0,0,0,2,1,1,1
1,27,0,0,0,0,0,7,0,0,0,0,0,27,1,1,1
1,27,0,0,0,0,0,7,0,0,0,0,0,27,1,1,1
1,2,27,27,2,27,27,2,0,0,0,0,0,2,1,1,1
1,1,1,1,1,1,1,27,0,0,0,0,0,27,1,1,1
1,1,1,1,1,1,1,27,0,10,0,10,0,27,1,1,1
1,1,1,1,1,1,1,2,7,3,0,3,7,2,1,1,1
1,1,1,1,1,1,1,0,0,26,3,25,0,0,1,1,1
endlayer

layer
1,1,1,1,1,1,1,1,1,1,1,1,1,1,1,1,1
1,1,1,1,1,1,1,1,1,1,1,1,1,1,1,1,1
1,1,1,1,1,1,1,1,1,1,1,1,1,1,1,1,1
1,1,1,1,1,1,1,1,1,1,1,1,1,1,1,1,1
1,2,27,27,2,27,27,2,27,27,2,27,27,2,1,1,1
1,27,0,0,0,0,0,7,0,0,0,0,0,27,1,1,1
1,27,0,0,0,0,0,7,0,0,0,0,0,27,1,1,1
1,2,0,0,0,0,0,2,0,0,0,0,0,2,1,1,1
1,27,0,0,0,0,0,6,0,0,0,0,0,27,1,1,1
1,27,0,0,0,0,0,6,0,0,0,0,0,27,1,1,1
1,2,0,0,0,0,0,2,0,0,0,0,0,2,1,1,1
1,27,0,0,0,0,0,7,0,0,0,0,0,27,1,1,1
1,27,0,0,0,0,0,7,0,0,0,0,0,27,1,1,1
1,2,27,27,2,27,27,2,0,0,0,0,0,2,1,1,1
1,1,1,1,1,1,1,27,0,33,33,33,0,27,1,1,1
1,1,1,1,1,1,1,27,0,10,0,10,0,27,1,1,1
1,1,1,1,1,1,1,2,7,3,0,3,7,2,1,1,1
1,1,1,1,1,1,1,0,0,26,3,25,0,0,1,1,1
endlayer

layer
1,1,1,1,1,1,1,1,1,1,1,1,1,1,1,1,1
1,1,1,1,1,1,1,1,1,1,1,1,1,1,1,1,1
1,1,1,1,1,1,1,1,1,1,1,1,1,1,1,1,1
1,1,1,1,1,1,1,1,1,1,1,1,1,1,1,1,1
1,2,3,3,2,3,3,2,3,3,2,3,3,2,1,1,1
1,3,0,0,0,0,0,3,0,0,0,0,0,3,1,1,1
1,3,0,0,0,0,0,3,0,0,0,0,0,3,1,1,1
1,2,0,0,0,0,0,2,0,0,0,0,0,2,1,1,1
1,3,0,0,0,0,0,3,0,0,0,0,0,3,1,1,1
1,3,0,0,0,0,0,3,0,0,0,0,0,3,1,1,1
1,2,0,0,0,0,0,2,0,0,0,0,0,2,1,1,1
1,3,0,0,0,0,0,3,0,0,0,0,0,3,1,1,1
1,3,0,0,0,0,0,3,0,0,0,0,0,3,1,1,1
1,2,3,3,2,3,3,2,0,0,0,0,0,2,1,1,1
1,1,1,1,1,1,1,3,0,3,23,3,0,3,1,1,1
1,1,1,1,1,1,1,3,0,10,0,10,0,3,1,1,1
1,1,1,1,1,1,1,2,3,3,0,3,3,2,1,1,1
1,1,1,1,1,1,1,0,0,26,3,25,0,0,1,1,1
endlayer

layer
1,1,1,1,1,1,1,1,1,1,1,1,1,1,1,1,1
1,1,1,1,1,1,1,1,1,1,1,1,1,1,1,1,1
1,1,1,1,1,1,1,1,1,1,1,1,1,1,1,1,1
34,8,8,8,8,8,8,8,8,8,8,8,8,8,21,1,1
34,2,5,5,5,5,5,2,5,5,5,5,5,2,21,1,1
34,6,7,7,7,7,7,7,7,7,7,7,7,6,21,1,1
34,6,7,7,7,7,7,7,7,7,7,7,7,6,21,1,1
34,6,7,7,7,7,7,7,7,7,7,7,7,6,21,1,1
34,6,7,7,7,7,7,7,7,7,7,7,7,6,21,1,1
34,6,7,7,7,7,7,7,7,7,7,7,7,6,21,1,1
34,6,7,7,7,7,7,7,7,7,7,7,7,2,21,1,1
34,6,7,7,7,7,7,7,7,7,7,7,7,6,21,1,1
34,6,7,7,7,7,7,7,7,7,7,7,7,6,21,1,1
34,2,5,5,5,5,5,2,7,7,7,7,7,6,21,1,1
34,9,9,9,9,9,34,6,7,3,3,3,7,6,21,1,1
1,1,1,1,1,1,34,6,7,10,3,10,7,6,21,1,1
1,1,1,1,1,1,34,2,5,3,0,3,5,2,21,1,1
1,1,1,1,1,1,34,9,9,10,3,10,9,9,9,1,1
endlayer

layer
1,1,1,1,1,1,1,1,1,1,1,1,1,1,1,1,1
1,1,1,1,1,1,1,1,1,1,1,1,1,1,1,1,1
1,1,1,1,1,1,1,1,1,1,1,1,1,1,1,1,1
1,1,1,1,1,1,1,1,1,1,1,1,1,1,1,1,1
1,8,8,8,8,8,8,8,8,8,8,8,8,8,1,1,1
1,34,7,7,7,7,7,7,7,7,7,7,7,21,1,1,1
1,34,7,7,7,7,7,7,7,7,7,7,7,21,1,1,1
1,34,7,7,7,7,7,7,7,7,7,7,7,21,1,1,1
1,34,7,7,7,7,7,7,7,7,7,7,7,21,1,1,1
1,34,7,7,7,7,7,7,7,7,7,7,7,21,1,1,1
1,34,7,7,7,7,7,7,7,7,7,7,7,21,1,1,1
1,34,7,7,7,7,7,7,7,7,7,7,7,21,1,1,1
1,34,7,7,7,7,7,7,7,7,7,7,7,21,1,1,1
1,34,9,9,9,9,9,9,7,7,7,7,7,21,1,1,1
1,1,1,1,1,1,1,34,7,3,3,3,7,21,1,1,1
1,1,1,1,1,1,1,34,7,10,3,10,7,21,1,1,1
1,1,1,1,1,1,1,34,9,3,0,3,9,9,1,1,1
1,1,1,1,1,1,1,1,0,26,3,25,0,1,1,1,1
endlayer

layer
1,1,1,1,1,1,1,1,1,1,1,1,1,1,1,1,1
1,1,1,1,1,1,1,1,1,1,1,1,1,1,1,1,1
1,1,1,1,1,1,1,1,1,1,1,1,1,1,1,1,1
1,1,1,1,1,1,1,1,1,1,1,1,1,1,1,1,1
1,1,1,1,1,1,1,1,1,1,1,1,1,1,1,1,1
1,1,1,1,1,1,1,1,1,1,1,1,1,1,1,1,1
1,1,1,1,1,1,1,1,1,1,1,1,1,1,1,1,1
1,1,1,1,1,1,1,1,1,1,1,1,1,1,1,1,1
1,1,1,1,1,1,1,1,1,1,1,1,1,1,1,1,1
1,1,1,1,1,1,1,1,1,1,1,1,1,1,1,1,1
1,1,1,1,1,1,1,1,1,1,1,1,1,1,1,1,1
1,1,1,1,1,1,1,1,1,1,1,1,1,1,1,1,1
1,1,1,1,1,1,1,1,1,1,1,1,1,1,1,1,1
1,1,1,1,1,1,1,1,1,1,1,1,1,1,1,1,1
1,1,1,1,1,1,1,1,0,0,0,0,0,1,1,1,1
1,1,1,1,1,1,1,1,0,26,39,39,0,1,1,1,1
1,1,1,1,1,1,1,1,0,26,23,25,0,1,1,1,1
1,1,1,1,1,1,1,1,0,26,40,25,0,1,1,1,1
endlayer

layer
1,1,1,1,1,1,1,1,1,1,1,1,1,1,1,1,1
1,1,1,1,1,1,1,1,1,1,1,1,1,1,1,1,1
1,1,1,1,1,1,1,1,1,1,1,1,1,1,1,1,1
1,1,1,1,1,1,1,1,1,1,1,1,1,1,1,1,1
1,1,1,1,1,1,1,1,1,1,1,1,1,1,1,1,1
1,1,1,1,1,1,1,1,1,1,1,1,1,1,1,1,1
1,1,1,1,1,1,1,1,1,1,1,1,1,1,1,1,1
1,1,1,1,1,1,1,1,1,1,1,1,1,1,1,1,1
1,1,1,1,1,1,1,1,1,1,1,1,1,1,1,1,1
1,1,1,1,1,1,1,1,1,1,1,1,1,1,1,1,1
1,1,1,1,1,1,1,1,1,1,1,1,1,1,1,1,1
1,1,1,1,1,1,1,1,1,1,1,1,1,1,1,1,1
1,1,1,1,1,1,1,1,1,1,1,1,1,1,1,1,1
1,1,1,1,1,1,1,1,1,1,1,1,1,1,1,1,1
1,1,1,1,1,1,1,1,0,0,0,0,0,1,1,1,1
1,1,1,1,1,1,1,1,0,39,39,25,0,1,1,1,1
1,1,1,1,1,1,1,1,0,26,0,25,0,1,1,1,1
1,1,1,1,1,1,1,1,0,26,40,40,0,1,1,1,1
endlayer

