
# Created by Ruins mod version 17.0 Ingame Parser
# authoring Player: ST753M

weight=1
embed_into_distance=2
acceptable_target_blocks=
unacceptable_target_blocks=flowing_water,water,flowing_lava,lava
dimensions=18,9,14
allowable_overhang=2
max_leveling=0
leveling_buffer=0
preserve_water=0
preserve_lava=0
preventRotation=1

biomesToSpawnIn=magical_forest,taiga,taiga_hills,mutated_redwood_taiga,mutated_redwood_taiga_hills,redwood_taiga,mutated_taiga,redwood_taiga_hills,redwood_forest,coniferous_forest,shield,dead_forest,autumnal_wooded_hills,autumnal_woods,snowy_forest,mutated_taiga_cold,snowy_coniferous_forest,taiga_cold,taiga_cold_hills

=0,100,air
rule1=0,100,preserveBlock
rule2=0,100,thaumcraft:log_greatwood-1
rule3=0,100,thaumcraft:plank_silverwood-0
rule4=0,100,thaumcraft:stone_arcane_brick-0
rule5=0,100,thaumcraft:stone_arcane-0
rule6=0,100,thaumcraft:plank_greatwood-0
rule7=0,100,thaumcraft:stairs_silverwood-3
rule8=0,100,thaumcraft:log_greatwood-0
rule9=0,100,thaumcraft:log_greatwood-2
rule10=0,100,thaumcraft:stairs_greatwood-3
rule11=0,100,minecraft:netherrack-0
rule12=0,100,thaumcraft:log_silverwood-2
rule13=0,100,thaumcraft:stairs_arcane_brick-4
rule14=0,100,minecraft:iron_bars-0
rule15=0,100,minecraft:spruce_stairs-2
rule16=0,100,minecraft:bookshelf-0
rule17=0,100,thaumcraft:log_silverwood-1
rule18=0,100,minecraft:fire-15
rule19=0,100,minecraft:dark_oak_door-1
rule20=0,100,thaumcraft:stairs_arcane_brick-5
rule21=0,100,thaumcraft:stairs_greatwood-2
rule22=0,100,minecraft:stained_glass_pane-8
rule23=0,100,thaumcraft:candle_white-0
rule24=0,100,minecraft:dark_oak_door-8
rule25=0,100,thaumcraft:stairs_arcane_brick-7
rule26=0,100,thaumcraft:stairs_greatwood-4
rule27=0,100,thaumcraft:stairs_greatwood-1
rule28=0,100,thaumcraft:stairs_greatwood-7
rule29=0,100,thaumcraft:log_silverwood-0
rule30=0,100,thaumcraft:stairs_greatwood-5
rule31=0,100,thaumcraft:table_wood-0
rule32=0,100,minecraft:bed-9
rule33=0,100,minecraft:bed-1
rule34=0,100,thaumcraft:stairs_greatwood-0
rule35=0,50,minecraft:web-0
rule36=0,100,thaumcraft:slab_greatwood-8
rule37=0,50,thaumcraft:loot_crate_common-0
rule38=0,50,MobSpawner:cave_spider
rule39=0,100,thaumcraft:slab_double_greatwood-0
rule40=0,100,thaumcraft:stairs_arcane_brick-6
rule41=0,100,thaumcraft:slab_greatwood-0

layer
1,1,1,1,1,1,1,1,1,1,1,1,1,1
1,1,1,1,1,1,1,1,1,1,1,1,1,1
2,3,2,1,1,2,1,1,2,1,1,2,1,1
6,6,6,6,6,6,6,6,6,6,6,5,5,4
6,6,6,6,6,6,6,6,6,6,6,5,5,5
6,6,6,6,6,6,6,6,6,6,6,5,5,4
2,3,2,1,1,2,1,1,2,1,1,2,1,1
1,1,1,1,1,1,1,1,1,1,1,1,1,1
1,1,1,1,1,1,1,1,1,1,1,1,1,1
endlayer

layer
1,1,1,1,1,1,1,1,1,1,1,1,1,1
1,1,1,1,1,1,1,1,1,1,1,1,1,1
2,3,2,1,1,2,1,1,2,1,1,2,1,1
7,6,6,6,6,6,6,6,6,6,6,5,5,4
7,6,6,6,6,6,6,6,6,6,6,5,5,5
7,6,6,6,6,6,6,6,6,6,6,5,5,4
2,3,2,1,1,2,1,1,2,1,1,2,1,1
1,1,1,1,1,1,1,1,1,1,1,1,1,1
1,1,1,1,1,1,1,1,1,1,1,1,1,1
endlayer

layer
1,1,1,1,1,1,1,1,1,1,1,1,1,1
1,1,8,1,1,8,1,1,8,1,1,8,1,1
10,9,2,9,9,2,9,9,2,9,9,2,9,1
0,7,8,3,3,3,3,3,3,3,3,5,5,4
0,7,8,3,3,3,3,3,3,3,3,5,11,5
0,7,8,3,3,3,3,3,3,3,3,5,5,4
10,9,2,9,9,2,9,9,2,9,9,2,9,1
1,1,8,1,1,8,1,1,8,1,1,8,1,1
1,1,1,1,1,1,1,1,1,1,1,1,1,1
endlayer

layer
1,1,1,1,1,1,1,1,1,1,1,1,1,1
1,1,1,1,1,1,1,1,1,1,1,1,1,1
1,1,2,12,12,2,12,12,2,12,12,2,1,1
0,0,17,0,0,0,0,16,15,0,0,14,5,13
0,0,19,0,0,0,0,16,15,0,0,14,18,5
0,0,17,2,21,0,0,0,0,0,0,14,5,20
1,1,2,12,12,2,12,12,2,12,12,2,1,1
1,1,1,1,1,1,1,1,1,1,1,1,1,1
1,1,1,1,1,1,1,1,1,1,1,1,1,1
endlayer

layer
1,1,1,1,1,1,1,1,1,1,1,1,1,1
1,1,1,1,1,1,1,1,1,1,1,1,1,1
1,1,2,22,22,2,22,22,2,22,22,2,1,1
0,0,17,0,0,0,0,0,0,0,0,14,5,13
0,0,24,0,0,0,0,23,0,0,0,0,0,5
0,0,17,21,0,0,0,0,0,0,0,14,5,20
1,1,2,22,22,2,22,22,2,22,22,2,1,1
1,1,1,1,1,1,1,1,1,1,1,1,1,1
1,1,1,1,1,1,1,1,1,1,1,1,1,1
endlayer

layer
1,1,1,1,1,1,1,1,1,1,1,1,1,1
1,1,1,1,1,1,1,1,1,1,1,1,1,1
1,1,2,22,22,2,22,22,2,22,22,2,1,1
0,0,17,26,0,0,0,0,0,0,0,25,5,13
0,0,12,27,0,0,0,0,0,0,0,0,0,5
0,0,17,0,0,0,0,0,0,0,0,25,5,20
1,1,2,22,22,2,22,22,2,22,22,2,1,1
1,1,1,1,1,1,1,1,1,1,1,1,1,1
1,1,1,1,1,1,1,1,1,1,1,1,1,1
endlayer

layer
1,1,1,1,1,1,1,1,1,1,1,1,1,1
1,1,26,1,1,26,1,1,26,1,1,26,1,1
1,28,2,12,12,2,12,12,2,12,12,2,1,1
0,0,29,27,0,0,0,0,0,0,0,4,5,13
0,0,29,0,0,0,0,0,0,0,0,25,0,5
0,0,29,0,0,0,0,0,0,0,0,4,5,20
1,28,2,12,12,2,12,12,2,12,12,2,1,1
1,1,30,1,1,30,1,1,30,1,1,30,1,1
1,1,1,1,1,1,1,1,1,1,1,1,1,1
endlayer

layer
1,1,8,1,1,8,1,1,8,1,1,8,1,1
1,9,9,9,9,9,9,9,9,9,9,9,9,1
1,10,8,27,3,3,3,3,3,3,3,8,1,1
0,10,8,0,3,3,3,3,3,3,3,5,5,13
0,10,8,0,3,3,3,3,3,3,3,5,11,5
0,10,8,0,3,3,3,3,3,3,3,5,5,20
1,10,8,3,3,3,3,3,3,3,3,8,1,1
1,9,9,9,9,9,9,9,9,9,9,9,9,1
1,1,8,1,1,8,1,1,8,1,1,8,1,1
endlayer

layer
1,1,1,1,1,1,1,1,1,1,1,1,1,1
1,1,2,12,12,2,12,12,2,12,12,2,1,1
1,1,29,0,0,31,32,32,31,0,0,17,1,1
1,1,29,0,0,0,33,33,0,0,0,14,5,13
1,1,2,0,0,0,0,0,0,0,0,14,18,5
1,1,29,0,0,0,0,0,0,0,0,14,5,20
1,1,29,0,0,0,0,0,0,0,0,17,1,1
1,1,2,12,12,2,12,12,2,12,12,2,1,1
1,1,1,1,1,1,1,1,1,1,1,1,1,1
endlayer

layer
1,1,1,1,1,1,1,1,1,1,1,1,1,1
1,1,2,22,22,2,22,22,2,22,22,2,1,1
1,1,22,0,0,23,0,0,0,0,0,17,1,1
1,1,22,0,0,0,0,0,0,0,0,14,5,13
1,1,2,0,0,0,0,0,0,0,0,0,0,5
1,1,22,0,0,0,0,0,0,0,0,14,5,20
1,1,22,0,0,0,0,0,0,0,0,17,1,1
1,1,2,22,22,2,22,22,2,22,22,2,1,1
1,1,1,1,1,1,1,1,1,1,1,1,1,1
endlayer

layer
1,1,1,1,1,1,1,1,1,1,1,1,1,1
1,1,2,22,22,2,22,22,2,22,22,2,1,1
1,1,22,0,0,0,0,0,0,0,0,17,1,1
1,1,22,0,0,0,0,0,0,0,0,25,5,13
1,1,2,0,0,0,0,0,0,0,0,0,0,5
1,1,22,0,0,0,0,0,0,0,0,25,5,20
1,1,22,0,0,0,0,0,0,0,0,17,1,1
1,1,2,22,22,2,22,22,2,22,22,2,1,1
1,1,1,1,1,1,1,1,1,1,1,1,1,1
endlayer

layer
1,1,1,1,1,1,1,1,1,1,1,1,1,1
1,1,2,12,12,2,12,12,2,12,12,2,1,1
1,1,29,0,0,0,0,0,0,0,0,17,1,1
1,1,29,0,0,0,0,0,0,0,0,4,5,13
1,1,2,0,0,0,0,0,0,0,0,25,0,5
1,1,29,0,0,0,0,0,0,0,0,4,5,20
1,1,29,0,0,0,0,0,0,0,0,17,1,1
1,1,2,12,12,2,12,12,2,12,12,2,1,1
1,1,1,1,1,1,1,1,1,1,1,1,1,1
endlayer

layer
1,34,34,34,34,34,34,34,34,34,34,34,34,1
1,30,2,9,9,2,9,9,2,9,9,2,30,1
1,1,8,0,0,8,36,36,8,35,0,8,1,1
1,1,8,0,0,8,36,36,8,0,0,8,5,13
1,1,2,0,0,8,36,36,8,0,0,8,5,5
1,1,8,0,0,8,36,36,8,0,0,8,5,20
1,1,8,0,0,8,36,36,8,0,0,8,1,1
1,26,2,9,9,2,9,9,2,9,9,2,26,1
1,27,27,27,27,27,27,27,27,27,27,27,27,1
endlayer

layer
1,1,1,1,1,1,1,1,1,1,1,1,1,1
1,34,34,34,34,34,34,34,34,34,34,34,34,1
1,30,3,30,30,30,30,30,30,30,30,3,30,1
1,1,3,0,0,35,37,0,0,0,0,3,5,13
1,1,3,0,0,0,0,38,0,0,0,3,5,5
1,1,3,0,0,0,35,37,35,0,0,3,5,20
1,26,3,26,26,26,26,26,26,26,26,3,26,1
1,27,27,27,27,27,27,27,27,27,27,27,27,1
1,1,1,1,1,1,1,1,1,1,1,1,1,1
endlayer

layer
1,1,1,1,1,1,1,1,1,1,1,1,1,1
1,1,1,1,1,1,1,1,1,1,1,1,1,1
1,34,34,34,34,34,34,34,34,34,34,34,34,1
1,30,3,30,30,30,30,30,30,30,30,3,5,13
1,1,3,0,0,0,35,0,0,0,0,3,5,5
1,26,3,26,26,26,26,26,26,26,26,3,5,20
1,27,27,27,27,27,27,27,27,27,27,27,27,1
1,1,1,1,1,1,1,1,1,1,1,1,1,1
1,1,1,1,1,1,1,1,1,1,1,1,1,1
endlayer

layer
1,1,1,1,1,1,1,1,1,1,1,1,1,1
1,1,1,1,1,1,1,1,1,1,1,1,1,1
1,1,1,1,1,1,1,1,1,1,1,1,1,1
1,34,34,34,34,34,34,34,34,34,34,34,5,13
1,39,3,3,3,3,3,3,3,3,3,3,5,5
1,27,27,27,27,27,27,27,27,27,27,27,5,20
1,1,1,1,1,1,1,1,1,1,1,1,1,1
1,1,1,1,1,1,1,1,1,1,1,1,1,1
1,1,1,1,1,1,1,1,1,1,1,1,1,1
endlayer

layer
1,1,1,1,1,1,1,1,1,1,1,1,1,1
1,1,1,1,1,1,1,1,1,1,1,1,1,1
1,1,1,1,1,1,1,1,1,1,1,1,1,1
1,1,1,1,1,1,1,1,1,1,1,1,25,13
1,21,41,41,41,41,41,41,41,41,41,41,25,40
1,1,1,1,1,1,1,1,1,1,1,1,20,20
1,1,1,1,1,1,1,1,1,1,1,1,1,1
1,1,1,1,1,1,1,1,1,1,1,1,1,1
1,1,1,1,1,1,1,1,1,1,1,1,1,1
endlayer

layer
1,1,1,1,1,1,1,1,1,1,1,1,1,1
1,1,1,1,1,1,1,1,1,1,1,1,1,1
1,1,1,1,1,1,1,1,1,1,1,1,1,1
1,1,1,1,1,1,1,1,1,1,1,1,13,40
1,1,1,1,1,1,1,1,1,1,1,1,25,40
1,1,1,1,1,1,1,1,1,1,1,1,25,20
1,1,1,1,1,1,1,1,1,1,1,1,1,1
1,1,1,1,1,1,1,1,1,1,1,1,1,1
1,1,1,1,1,1,1,1,1,1,1,1,1,1
endlayer

