
# Created by Ruins mod version 17.0 Ingame Parser
# authoring Player: ST753M

weight=1
embed_into_distance=2
acceptable_target_blocks=grass,dirt,gravel
unacceptable_target_blocks=flowing_water,water,flowing_lava,lava
dimensions=14,12,11
allowable_overhang=2
max_leveling=0
leveling_buffer=0
preserve_water=0
preserve_lava=0
preventRotation=1

biomesToSpawnIn=forest,maple_woods,boreal_forest,forest_hills,woodland,seasonal_forest,temperate_rainforest,fen,grove,sacred_springs,land_of_lakes,forested_hills,lush_hills,thicket,taiga,taiga_hills,mutated_redwood_taiga,mutated_redwood_taiga_hills,redwood_taiga,mutated_taiga,redwood_taiga_hills,redwood_forest,coniferous_forest,shield,dead_forest,autumnal_wooded_hills,autumnal_woods,roofed_forest,mutated_roofed_forest,dark_forest,darklands_forest,ominous_woods,eerie

=0,100,air
rule1=0,100,preserveBlock
rule2=0,100,thaumcraft:log_greatwood-1
rule3=0,100,thaumcraft:stone_arcane_brick-0
rule4=0,100,thaumcraft:log_greatwood-0
rule5=0,100,thaumcraft:plank_greatwood-0
rule6=0,100,thaumcraft:log_greatwood-2
rule7=0,100,thaumcraft:plank_silverwood-0
rule8=0,100,thaumcraft:slab_double_silverwood-0
rule9=0,100,thaumcraft:stairs_greatwood-2
rule10=0,100,thaumcraft:stairs_greatwood-3
rule11=0,100,minecraft:cobblestone_wall-0
rule12=0,100,minecraft:dark_oak_door-3
rule13=0,100,minecraft:ladder-4
rule14=0,100,thaumcraft:stone_arcane-0
rule15=0,100,minecraft:cauldron-0
rule16=0,100,minecraft:furnace-4
rule17=0,100,minecraft:stained_glass_pane-12
rule18=0,100,minecraft:trapdoor-3
rule19=0,100,minecraft:dark_oak_door-8
rule20=0,100,minecraft:dark_oak_door-9
rule21=0,100,minecraft:cake-0
rule22=0,100,thaumcraft:stairs_greatwood-0
rule23=0,100,thaumcraft:stairs_greatwood-5
rule24=0,100,thaumcraft:stairs_greatwood-4
rule25=0,100,thaumcraft:stairs_greatwood-1
rule26=0,100,MobSpawner:cave_spider,MobSpawner:spider
rule27=0,100,minecraft:web-0
rule28=0,100,thaumcraft:loot_crate_common-0,thaumcraft:loot_crate_common-0,thaumcraft:loot_crate_common-0,thaumcraft:loot_crate_uncommon-0

layer
1,1,1,1,1,1,1,1,1,1,1
1,2,1,1,2,1,1,2,1,1,1
1,1,3,3,3,3,3,1,1,1,1
1,1,3,3,3,3,3,1,1,1,1
1,2,3,3,3,3,3,2,1,2,1
1,1,3,3,3,3,3,5,5,4,3
1,1,3,3,3,3,3,5,5,4,3
1,2,3,3,3,3,3,2,1,2,1
1,1,3,3,3,3,3,1,1,1,1
1,1,3,3,3,3,3,1,1,1,1
1,2,1,1,2,1,1,2,1,1,1
1,1,1,1,1,1,1,1,1,1,1
endlayer

layer
1,1,1,1,1,1,1,1,1,1,1
1,2,6,6,2,6,6,2,1,1,1
1,4,7,7,7,7,7,4,1,1,1
1,4,7,8,8,8,7,4,1,1,1
1,2,7,8,7,8,7,2,6,2,1
1,4,7,8,7,8,7,4,5,5,9
1,4,7,8,7,8,7,4,5,5,9
1,2,7,8,7,8,7,2,6,2,1
1,4,7,8,8,8,7,4,1,1,1
1,4,7,7,7,7,7,4,1,1,1
1,2,6,6,2,6,6,2,1,1,1
1,1,1,1,1,1,1,1,1,1,1
endlayer

layer
1,1,1,1,1,1,1,1,1,1,1
1,2,3,3,2,3,3,2,1,1,1
1,3,0,0,0,0,0,3,1,1,1
1,3,0,9,11,10,0,3,1,1,1
1,2,0,0,0,0,0,2,3,2,1
1,3,0,0,0,0,0,0,0,12,0
1,3,13,0,0,0,0,0,0,12,0
1,2,2,0,0,0,0,2,3,2,1
1,3,14,0,0,0,0,3,1,1,1
1,3,14,14,16,14,15,3,1,1,1
1,2,3,3,2,3,3,2,1,1,1
1,1,1,1,1,1,1,1,1,1,1
endlayer

layer
1,1,1,1,1,1,1,1,1,1,1
1,2,17,17,2,17,17,2,1,1,1
1,17,0,0,0,0,0,17,1,1,1
1,17,0,0,18,0,0,17,1,1,1
1,2,0,0,0,0,0,2,17,2,1
1,17,0,0,0,0,0,0,0,19,0
1,17,13,0,0,0,0,0,0,20,0
1,2,2,0,0,0,0,2,17,2,1
1,17,0,0,0,0,0,17,1,1,1
1,17,21,0,11,0,0,17,1,1,1
1,2,17,17,2,17,17,2,1,1,1
1,1,1,1,1,1,1,1,1,1,1
endlayer

layer
1,1,1,1,1,1,1,1,1,1,1
1,2,17,17,2,17,17,2,1,1,1
1,17,0,0,0,0,0,17,1,1,1
1,17,0,0,0,0,0,17,1,1,1
1,2,0,0,0,0,0,2,17,2,1
1,17,0,0,0,0,0,0,0,4,0
1,17,13,0,0,0,0,0,0,4,0
1,2,2,0,0,0,0,2,17,2,1
1,17,0,0,0,0,0,17,1,1,1
1,17,0,0,11,0,0,17,1,1,1
1,2,17,17,2,17,17,2,1,1,1
1,1,1,1,1,1,1,1,1,1,1
endlayer

layer
1,1,1,1,1,1,1,1,1,1,1
1,2,3,3,2,3,3,2,1,1,1
1,3,0,0,0,0,0,3,1,1,1
1,3,0,0,0,0,0,3,22,22,22
1,2,0,0,0,0,0,2,3,2,23
1,3,0,0,0,0,0,0,0,17,1
1,3,13,0,0,0,0,0,0,17,1
1,2,2,0,0,0,0,2,3,2,24
1,3,0,0,0,0,0,3,25,25,25
1,3,0,0,11,0,0,3,1,1,1
1,2,3,3,2,3,3,2,1,1,1
1,1,1,1,1,1,1,1,1,1,1
endlayer

layer
22,22,22,22,22,22,22,22,22,1,1
10,2,6,6,2,6,6,2,9,1,1
10,4,7,7,7,7,7,4,9,1,1
10,4,7,8,8,8,7,4,9,1,1
10,2,7,8,7,8,7,2,9,22,22
10,4,7,8,7,8,7,4,5,5,23
10,4,13,8,7,8,7,4,5,5,24
10,2,2,8,7,8,7,2,9,25,25
10,4,7,8,8,8,7,4,9,1,1
10,4,7,7,7,7,7,4,9,1,1
10,2,6,6,2,6,6,2,9,1,1
10,25,25,25,25,25,25,25,25,1,1
endlayer

layer
1,1,1,1,1,1,1,1,1,1,1
1,10,22,22,22,22,22,22,1,1,1
1,10,5,5,5,5,5,9,1,1,1
1,10,5,5,5,5,5,9,1,1,1
1,2,3,3,2,3,3,2,1,1,1
1,3,0,27,0,26,0,3,22,22,22
1,3,0,0,27,0,28,3,25,25,25
1,2,3,3,2,3,3,2,1,1,1
1,10,5,5,5,5,5,9,1,1,1
1,10,5,5,5,5,5,9,1,1,1
1,25,25,25,25,25,25,9,1,1,1
1,1,1,1,1,1,1,1,1,1,1
endlayer

layer
1,1,1,1,1,1,1,1,1,1,1
1,1,1,1,1,1,1,1,1,1,1
1,1,10,22,22,22,9,1,1,1,1
1,1,10,5,5,5,9,1,1,1,1
1,2,3,3,2,3,3,2,1,1,1
1,17,0,0,27,0,0,17,1,1,1
1,17,0,0,0,27,0,17,1,1,1
1,2,3,3,2,3,3,2,1,1,1
1,1,10,5,5,5,9,1,1,1,1
1,1,25,25,25,25,9,1,1,1,1
1,1,1,1,1,1,1,1,1,1,1
1,1,1,1,1,1,1,1,1,1,1
endlayer

layer
1,1,1,1,1,1,1,1,1,1,1
1,1,1,1,1,1,1,1,1,1,1
1,1,1,1,1,1,1,1,1,1,1
1,1,1,10,22,9,1,1,1,1,1
1,2,3,3,2,3,3,2,1,1,1
1,17,0,0,0,0,0,17,1,1,1
1,17,0,0,0,0,0,17,1,1,1
1,2,3,3,2,3,3,2,1,1,1
1,1,1,10,25,9,1,1,1,1,1
1,1,1,1,1,1,1,1,1,1,1
1,1,1,1,1,1,1,1,1,1,1
1,1,1,1,1,1,1,1,1,1,1
endlayer

layer
1,1,1,1,1,1,1,1,1,1,1
1,1,1,1,1,1,1,1,1,1,1
1,1,1,1,1,1,1,1,1,1,1
1,1,1,1,1,1,1,1,1,1,1
1,2,3,3,2,3,3,2,1,1,1
1,3,0,0,23,0,27,3,1,1,1
1,3,0,27,24,0,0,3,1,1,1
1,2,3,3,2,3,3,2,1,1,1
1,1,1,1,1,1,1,1,1,1,1
1,1,1,1,1,1,1,1,1,1,1
1,1,1,1,1,1,1,1,1,1,1
1,1,1,1,1,1,1,1,1,1,1
endlayer

layer
1,1,1,1,1,1,1,1,1,1,1
1,1,1,1,1,1,1,1,1,1,1
1,1,1,1,1,1,1,1,1,1,1
10,22,22,22,22,22,22,22,9,1,1
10,2,6,6,6,6,6,2,9,1,1
10,4,7,7,7,7,7,4,9,1,1
10,4,7,7,7,7,7,4,9,1,1
10,2,6,6,6,6,6,2,9,1,1
25,25,25,25,25,25,25,25,9,1,1
1,1,1,1,1,1,1,1,1,1,1
1,1,1,1,1,1,1,1,1,1,1
1,1,1,1,1,1,1,1,1,1,1
endlayer

layer
1,1,1,1,1,1,1,1,1,1,1
1,1,1,1,1,1,1,1,1,1,1
1,1,1,1,1,1,1,1,1,1,1
1,1,1,1,1,1,1,1,1,1,1
1,22,22,22,22,22,22,22,1,1,1
1,10,5,5,5,5,5,9,1,1,1
1,10,5,5,5,5,5,9,1,1,1
1,10,25,25,25,25,25,25,1,1,1
1,1,1,1,1,1,1,1,1,1,1
1,1,1,1,1,1,1,1,1,1,1
1,1,1,1,1,1,1,1,1,1,1
1,1,1,1,1,1,1,1,1,1,1
endlayer

layer
1,1,1,1,1,1,1,1,1,1,1
1,1,1,1,1,1,1,1,1,1,1
1,1,1,1,1,1,1,1,1,1,1
1,1,1,1,1,1,1,1,1,1,1
1,1,1,1,1,1,1,1,1,1,1
1,1,10,22,22,22,9,1,1,1,1
1,1,10,25,25,25,9,1,1,1,1
1,1,1,1,1,1,1,1,1,1,1
1,1,1,1,1,1,1,1,1,1,1
1,1,1,1,1,1,1,1,1,1,1
1,1,1,1,1,1,1,1,1,1,1
1,1,1,1,1,1,1,1,1,1,1
endlayer

