
# Created by Ruins mod version 16.8 Ingame Parser
# authoring Player: ST753M

# A giant jack o lantern, guarded by a bunch of skeletons

weight=1
uniqueMinDistance=2000
spawnMinDistance=1000
embed_into_distance=2
acceptable_target_blocks=grass,podzol
unacceptable_target_blocks=flowing_water,water,flowing_lava,lava
dimensions=17,17,17
allowable_overhang=1
max_leveling=1
leveling_buffer=0
preserve_water=0
preserve_lava=0

adjoining_template=swampland/753_Pumpkin_Big;20;99;14;100
adjoining_template=swampland/753_Pumpkin_Big;22;99;-11;100
adjoining_template=swampland/753_Pumpkin_Big;-20;99;14;100
adjoining_template=swampland/753_Pumpkin_Big;-22;99;-11;100

biomesToSpawnIn=mutated_swampland

rule1=0,100,preserveBlock
rule2=0,100,minecraft:pumpkin-0
rule3=0,100,minecraft:pumpkin-2
rule4=0,100,minecraft:pumpkin-1
rule5=0,100,minecraft:pumpkin-3
rule6=0,100,CommandBlock:RUINSTRIGGER /summon skeleton ~ ~1 ~ {ArmorItems:[{id:"minecraft:golden_boots",Count:1b},{id:"minecraft:golden_leggings",Count:1b},{id:"minecraft:golden_chestplate",Count:1b},{id:"minecraft:lit_pumpkin",Count:1b}],HandItems:[{id:"minecraft:bow",Count:1b,tag:{ench:[{id:49,lvl:2},{id:71,lvl:1}]}},{}],ArmorDropChances:[0.085F,0.085F,0.085F,0.3F],PersistenceRequired:1}:@-1,CommandBlock:RUINSTRIGGER /summon skeleton ~ ~1 ~ {ArmorItems:[{},{},{},{id:"minecraft:lit_pumpkin",Count:1b}],HandItems:[{id:"minecraft:bow",Count:1b,tag:{ench:[{id:49,lvl:2},{id:71,lvl:1}]}},{}],ArmorDropChances:[0.085F,0.085F,0.085F,0.3F],PersistenceRequired:1}:@-1
rule7=0,100,ChestGenHook:chests/simple_dungeon:5-4,IInventory;minecraft:chest;minecraft:speckled_melon#2#0#1+minecraft:spider_eye#5#0#4+minecraft:golden_pickaxe#1#0#13+minecraft:lit_pumpkin#4#0#15+minecraft:web#3#0#19+minecraft:fermented_spider_eye#4#0#23-4,IInventory;minecraft:chest;minecraft:sponge#3#1#2+minecraft:fermented_spider_eye#6#0#5+minecraft:speckled_melon#1#0#7+minecraft:web#3#0#10+minecraft:golden_axe#1#0#22+minecraft:gold_ingot#1#0#24-4,IInventory;minecraft:chest;minecraft:web#4#0#0+minecraft:spider_eye#6#0#4+minecraft:lit_pumpkin#2#0#11+minecraft:golden_apple#1#0#14+minecraft:speckled_melon#1#0#17+minecraft:web#5#0#21+minecraft:fermented_spider_eye#3#0#24-4,IInventory;minecraft:chest;minecraft:fermented_spider_eye#6#0#3+minecraft:web#6#0#10+minecraft:golden_carrot#1#0#15+minecraft:spider_eye#5#0#16+minecraft:spider_eye#3#0#18+minecraft:lit_pumpkin#2#0#20+minecraft:golden_sword#1#0#23-4,IInventory;minecraft:chest;minecraft:golden_sword#1#0#11+minecraft:golden_carrot#1#0#15+minecraft:fermented_spider_eye#2#0#17+minecraft:web#10#0#18+minecraft:lit_pumpkin#3#0#22+minecraft:gold_ingot#2#0#25-4,IInventory;minecraft:chest;minecraft:golden_apple#1#0#2+minecraft:web#3#0#6+minecraft:fermented_spider_eye#2#0#10+minecraft:golden_carrot#2#0#12+minecraft:spider_eye#4#0#13+minecraft:lit_pumpkin#2#0#15+minecraft:web#3#0#16+minecraft:web#5#0#19+minecraft:water_bucket#1#0#23+minecraft:gold_ingot#2#0#26-4,IInventory;minecraft:chest;minecraft:gold_ingot#2#0#3+minecraft:spider_eye#4#0#7+minecraft:sponge#7#1#10+minecraft:potion#{Potion:"minecraft:long_fire_resistance"}#0#13+minecraft:web#4#0#15+minecraft:web#5#0#21+minecraft:golden_carrot#1#0#25-4,IInventory;minecraft:chest;minecraft:golden_shovel#1#0#4+minecraft:fermented_spider_eye#5#0#6+minecraft:sponge#6#1#10+minecraft:gold_ingot#2#0#11+minecraft:web#4#0#14+minecraft:water_bucket#1#0#21+minecraft:golden_carrot#2#0#25-4,IInventory;minecraft:chest;minecraft:clock#{"quark:clock_calculated":1b}#0#3+minecraft:fermented_spider_eye#4#0#7+minecraft:web#9#0#9+minecraft:gold_ingot#2#0#13+minecraft:spider_eye#5#0#14+minecraft:golden_carrot#1#0#20+minecraft:lit_pumpkin#3#0#24-4
rule8=0,100,minecraft:lit_pumpkin-3
rule9=0,100,minecraft:log-3

layer
1,1,1,1,1,1,1,1,1,1,1,1,1,1,1,1,1
1,1,1,1,1,1,1,1,1,1,1,1,1,1,1,1,1
1,1,1,1,1,1,1,1,1,1,1,1,1,1,1,1,1
1,1,1,1,1,3,2,2,2,2,2,2,1,1,1,1,1
1,1,1,1,3,2,2,2,2,2,2,4,2,1,1,1,1
1,1,1,3,2,2,2,2,2,2,2,2,4,2,1,1,1
1,1,1,5,2,2,2,2,2,2,2,2,2,4,1,1,1
1,1,1,5,2,2,2,2,2,2,2,2,2,4,1,1,1
1,1,1,4,2,2,2,2,2,2,2,2,2,4,1,1,1
1,1,1,4,2,2,2,2,2,2,2,2,2,4,1,1,1
1,1,1,4,4,2,2,2,2,2,2,2,4,4,1,1,1
1,1,1,3,2,4,2,2,2,2,2,4,3,2,1,1,1
1,1,1,1,3,2,4,4,4,4,4,5,2,1,1,1,1
1,1,1,1,1,3,2,2,2,2,2,2,1,1,1,1,1
1,1,1,1,1,1,1,1,1,1,1,1,1,1,1,1,1
1,1,1,1,1,1,1,1,1,1,1,1,1,1,1,1,1
1,1,1,1,1,1,1,1,1,1,1,1,1,1,1,1,1
endlayer

layer
1,1,1,1,1,1,1,1,1,1,1,1,1,1,1,1,1
1,1,1,1,1,1,1,1,1,1,1,1,1,1,1,1,1
1,1,1,1,1,3,2,2,2,2,2,2,1,1,1,1,1
1,1,1,1,5,0,0,0,0,0,0,0,5,1,1,1,1
1,1,1,3,2,0,0,0,0,0,0,0,3,2,1,1,1
1,1,5,0,0,0,0,0,6,0,0,0,0,0,5,1,1
1,1,5,0,0,0,6,0,0,0,6,0,0,0,5,1,1
1,1,4,0,0,0,0,5,5,5,0,0,0,0,4,1,1
1,1,4,0,0,6,0,3,5,2,0,6,0,0,4,1,1
1,1,4,0,0,0,0,3,4,2,0,0,0,0,4,1,1
1,1,4,0,0,0,6,0,0,0,6,0,0,0,4,1,1
1,1,4,0,0,0,0,0,6,0,0,0,0,0,4,1,1
1,1,1,3,2,0,0,0,0,0,0,0,3,2,1,1,1
1,1,1,1,4,0,0,0,0,0,0,0,4,1,1,1,1
1,1,1,1,1,3,2,2,2,2,2,2,1,1,1,1,1
1,1,1,1,1,1,1,1,1,1,1,1,1,1,1,1,1
1,1,1,1,1,1,1,1,1,1,1,1,1,1,1,1,1
endlayer

layer
1,1,1,1,1,1,1,1,1,1,1,1,1,1,1,1,1
1,1,1,1,1,1,3,2,2,2,2,1,1,1,1,1,1
1,1,1,1,3,2,0,0,0,0,0,3,2,1,1,1,1
1,1,1,3,0,0,0,0,0,0,0,0,0,2,1,1,1
1,1,5,0,0,0,0,0,0,0,0,0,0,0,5,1,1
1,1,4,0,0,0,0,0,0,0,0,0,0,0,4,1,1
1,5,0,0,0,0,0,0,0,0,0,0,0,0,0,5,1
1,5,0,0,0,0,0,0,0,0,0,0,0,0,0,4,1
1,5,0,0,0,0,0,0,7,0,0,0,0,0,0,4,1
1,5,0,0,0,0,0,0,0,0,0,0,0,0,0,4,1
1,4,0,0,0,0,0,0,0,0,0,0,0,0,0,4,1
1,1,5,0,0,0,0,0,0,0,0,0,0,0,5,1,1
1,1,4,0,0,0,0,0,0,0,0,0,0,0,4,1,1
1,1,1,3,0,0,0,0,0,0,0,0,0,2,1,1,1
1,1,1,1,3,2,0,0,0,0,0,3,2,1,1,1,1
1,1,1,1,1,1,3,2,2,2,2,1,1,1,1,1,1
1,1,1,1,1,1,1,1,1,1,1,1,1,1,1,1,1
endlayer

layer
1,1,1,1,1,1,1,1,1,1,1,1,1,1,1,1,1
1,1,1,1,1,3,2,2,2,2,3,2,1,1,1,1,1
1,1,1,3,2,0,0,0,0,0,0,0,3,2,1,1,1
1,1,5,2,0,0,0,0,0,0,0,0,0,3,5,1,1
1,1,4,0,0,0,0,0,0,0,0,0,0,0,4,1,1
1,5,0,0,0,0,0,0,0,0,0,0,0,0,0,5,1
1,5,0,0,0,0,0,0,0,0,0,0,0,0,0,4,1
1,5,0,0,0,0,0,0,0,0,0,0,0,0,0,4,1
1,5,0,0,0,0,0,0,0,0,0,0,0,0,0,4,1
1,5,0,0,0,0,0,0,0,0,0,0,0,0,0,4,1
1,5,0,0,0,0,0,0,0,0,0,0,0,0,0,4,1
1,4,0,0,0,0,0,0,0,0,0,0,0,0,0,4,1
1,1,5,0,0,0,0,0,0,0,0,0,0,0,5,1,1
1,1,4,2,0,0,0,0,0,0,0,0,0,5,4,1,1
1,1,1,3,2,0,0,0,0,0,0,0,3,2,1,1,1
1,1,1,1,1,3,2,2,2,2,2,2,1,1,1,1,1
1,1,1,1,1,1,1,1,1,1,1,1,1,1,1,1,1
endlayer

layer
1,1,1,1,1,1,1,1,1,1,1,1,1,1,1,1,1
1,1,1,1,3,2,0,0,0,0,0,3,2,1,1,1,1
1,1,1,5,0,0,0,0,0,0,0,0,0,5,1,1,1
1,1,3,2,0,0,0,0,0,0,0,0,0,3,2,1,1
1,5,0,0,0,0,0,0,0,0,0,0,0,0,0,5,1
1,5,0,0,0,0,0,0,0,0,0,0,0,0,0,4,1
1,4,0,0,0,0,0,0,0,0,0,0,0,0,0,4,1
5,0,0,0,0,0,0,0,0,0,0,0,0,0,0,0,5
5,0,0,0,0,0,0,0,0,0,0,0,0,0,0,0,4
4,0,0,0,0,0,0,0,0,0,0,0,0,0,0,0,4
1,5,0,0,0,0,0,0,0,0,0,0,0,0,0,5,1
1,5,0,0,0,0,0,0,0,0,0,0,0,0,0,4,1
1,4,0,0,0,0,0,0,0,0,0,0,0,0,0,4,1
1,1,3,2,0,0,0,0,0,0,0,0,0,5,2,1,1
1,1,1,4,0,0,0,0,0,0,0,0,0,4,1,1,1
1,1,1,1,3,2,2,0,0,0,3,2,2,1,1,1,1
1,1,1,1,1,1,1,3,2,2,1,1,1,1,1,1,1
endlayer

layer
1,1,1,1,1,1,1,3,2,2,1,1,1,1,1,1,1
1,1,1,1,8,0,0,0,0,0,0,0,8,1,1,1,1
1,1,1,5,0,0,0,0,0,0,0,0,0,5,1,1,1
1,1,3,2,0,0,0,0,0,0,0,0,0,3,2,1,1
1,5,0,0,0,0,0,0,0,0,0,0,0,0,0,5,1
1,4,0,0,0,0,0,0,0,0,0,0,0,0,0,4,1
5,0,0,0,0,0,0,0,0,0,0,0,0,0,0,0,5
5,0,0,0,0,0,0,0,0,0,0,0,0,0,0,0,4
5,0,0,0,0,0,0,0,0,0,0,0,0,0,0,0,4
4,0,0,0,0,0,0,0,0,0,0,0,0,0,0,0,4
4,0,0,0,0,0,0,0,0,0,0,0,0,0,0,0,4
1,5,0,0,0,0,0,0,0,0,0,0,0,0,0,5,1
1,4,0,0,0,0,0,0,0,0,0,0,0,0,0,4,1
1,1,3,2,0,0,0,0,0,0,0,0,0,5,2,1,1
1,1,1,4,0,0,0,0,0,0,0,0,0,4,1,1,1
1,1,1,1,3,2,0,0,0,0,0,3,2,1,1,1,1
1,1,1,1,1,1,3,2,2,2,2,1,1,1,1,1,1
endlayer

layer
1,1,1,1,1,1,3,2,2,2,2,1,1,1,1,1,1
1,1,1,1,3,2,0,0,0,0,0,3,2,1,1,1,1
1,1,1,5,0,0,0,0,0,0,0,0,0,5,1,1,1
1,1,3,2,0,0,0,0,0,0,0,0,0,3,2,1,1
1,5,0,0,0,0,0,0,0,0,0,0,0,0,0,5,1
1,4,0,0,0,0,0,0,0,0,0,0,0,0,0,4,1
5,0,0,0,0,0,0,0,0,0,0,0,0,0,0,0,5
5,0,0,0,0,0,0,0,0,0,0,0,0,0,0,0,4
5,0,0,0,0,0,0,0,0,0,0,0,0,0,0,0,4
4,0,0,0,0,0,0,0,0,0,0,0,0,0,0,0,4
4,0,0,0,0,0,0,0,0,0,0,0,0,0,0,0,4
1,5,0,0,0,0,0,0,0,0,0,0,0,0,0,5,1
1,4,0,0,0,0,0,0,0,0,0,0,0,0,0,4,1
1,1,3,2,0,0,0,0,0,0,0,0,0,5,2,1,1
1,1,1,4,0,0,0,0,0,0,0,0,0,4,1,1,1
1,1,1,1,3,2,0,0,0,0,0,3,2,1,1,1,1
1,1,1,1,1,1,3,2,2,2,2,1,1,1,1,1,1
endlayer

layer
1,1,1,1,1,1,1,1,8,1,1,1,1,1,1,1,1
1,1,1,1,3,2,0,0,0,1,1,3,2,1,1,1,1
1,1,1,5,0,0,0,0,0,0,0,0,0,5,1,1,1
1,1,3,2,0,0,0,0,0,0,0,0,0,3,2,1,1
1,5,0,0,0,0,0,0,0,0,0,0,0,0,0,5,1
1,4,0,0,0,0,0,0,0,0,0,0,0,0,0,4,1
5,0,0,0,0,0,0,0,0,0,0,0,0,0,0,0,5
5,0,0,0,0,0,0,0,0,0,0,0,0,0,0,0,4
5,0,0,0,0,0,0,0,0,0,0,0,0,0,0,0,4
4,0,0,0,0,0,0,0,0,0,0,0,0,0,0,0,4
4,0,0,0,0,0,0,0,0,0,0,0,0,0,0,0,4
1,5,0,0,0,0,0,0,0,0,0,0,0,0,0,5,1
1,4,0,0,0,0,0,0,0,0,0,0,0,0,0,4,1
1,1,3,2,0,0,0,0,0,0,0,0,0,5,2,1,1
1,1,1,4,0,0,0,0,0,0,0,0,0,4,1,1,1
1,1,1,1,3,2,0,0,0,0,0,3,2,1,1,1,1
1,1,1,1,1,1,3,3,2,2,2,1,1,1,1,1,1
endlayer

layer
1,1,1,1,1,1,1,1,8,1,1,1,1,1,1,1,1
1,1,1,1,3,2,0,0,0,1,1,3,2,1,1,1,1
1,1,1,5,0,0,0,0,0,0,0,0,0,5,1,1,1
1,1,3,2,0,0,0,0,0,0,0,0,0,3,2,1,1
1,5,0,0,0,0,0,0,0,0,0,0,0,0,0,5,1
1,4,0,0,0,0,0,0,0,0,0,0,0,0,0,4,1
1,4,0,0,0,0,0,0,0,0,0,0,0,0,0,4,1
5,0,0,0,0,0,0,0,0,0,0,0,0,0,0,0,5
5,0,0,0,0,0,0,0,0,0,0,0,0,0,0,0,4
4,0,0,0,0,0,0,0,0,0,0,0,0,0,0,0,4
1,5,0,0,0,0,0,0,0,0,0,0,0,0,0,5,1
1,4,0,0,0,0,0,0,0,0,0,0,0,0,0,4,1
1,4,0,0,0,0,0,0,0,0,0,0,0,0,0,4,1
1,1,3,2,0,0,0,0,0,0,0,0,0,5,2,1,1
1,1,1,4,0,0,0,0,0,0,0,0,0,4,1,1,1
1,1,1,1,3,2,2,0,0,0,3,2,2,1,1,1,1
1,1,1,1,1,1,1,3,2,2,1,1,1,1,1,1,1
endlayer

layer
1,1,1,1,1,1,1,1,1,1,1,1,1,1,1,1,1
1,1,1,1,1,1,1,3,2,2,1,1,1,1,1,1,1
1,1,1,3,2,0,0,0,0,0,0,0,3,2,1,1,1
1,1,5,2,0,0,0,0,0,0,0,0,0,3,5,1,1
1,1,4,0,0,0,0,0,0,0,0,0,0,0,4,1,1
1,5,0,0,0,0,0,0,0,0,0,0,0,0,0,5,1
1,4,0,0,0,0,0,0,0,0,0,0,0,0,0,5,1
1,4,0,0,0,0,0,0,0,0,0,0,0,0,0,4,1
1,4,0,0,0,0,0,0,0,0,0,0,0,0,0,4,1
1,4,0,0,0,0,0,0,0,0,0,0,0,0,0,4,1
1,4,0,0,0,0,0,0,0,0,0,0,0,0,0,4,1
1,4,0,0,0,0,0,0,0,0,0,0,0,0,0,4,1
1,1,5,0,0,0,0,0,0,0,0,0,0,0,5,1,1
1,1,4,2,0,0,0,0,0,0,0,0,0,5,4,1,1
1,1,1,3,2,0,0,0,0,0,0,0,3,2,1,1,1
1,1,1,1,1,3,2,2,2,2,2,2,1,1,1,1,1
1,1,1,1,1,1,1,1,1,1,1,1,1,1,1,1,1
endlayer

layer
1,1,1,1,1,1,1,1,1,1,1,1,1,1,1,1,1
1,1,1,1,1,1,3,2,2,2,2,1,1,1,1,1,1
1,1,1,1,3,2,0,0,0,0,0,3,2,1,1,1,1
1,1,1,3,0,0,0,0,0,0,0,0,0,2,1,1,1
1,1,5,0,0,0,0,0,0,0,0,0,0,0,5,1,1
1,1,4,0,0,0,0,0,0,0,0,0,0,0,4,1,1
1,5,0,0,0,0,0,0,0,0,0,0,0,0,0,5,1
1,5,0,0,0,0,0,0,0,0,0,0,0,0,0,4,1
1,4,0,0,0,0,0,0,0,0,0,0,0,0,0,4,1
1,4,0,0,0,0,0,0,0,0,0,0,0,0,0,4,1
1,4,0,0,0,0,0,0,0,0,0,0,0,0,0,4,1
1,1,5,0,0,0,0,0,0,0,0,0,0,0,5,1,1
1,1,4,0,0,0,0,0,0,0,0,0,0,0,4,1,1
1,1,1,3,0,0,0,0,0,0,0,0,0,2,1,1,1
1,1,1,1,3,2,0,0,0,0,0,3,2,1,1,1,1
1,1,1,1,1,1,3,2,2,2,2,1,1,1,1,1,1
1,1,1,1,1,1,1,1,1,1,1,1,1,1,1,1,1
endlayer

layer
1,1,1,1,1,1,1,1,1,1,1,1,1,1,1,1,1
1,1,1,1,1,1,1,1,1,1,1,1,1,1,1,1,1
1,1,1,1,1,3,2,2,2,2,2,2,1,1,1,1,1
1,1,1,1,5,0,0,0,0,0,0,0,5,1,1,1,1
1,1,1,3,4,0,0,0,0,0,0,0,4,2,1,1,1
1,1,5,0,0,0,0,0,0,0,0,0,0,0,5,1,1
1,1,5,0,0,0,0,0,0,0,0,0,0,0,5,1,1
1,1,5,0,0,0,0,0,0,0,0,0,0,0,5,1,1
1,1,4,0,0,0,0,0,0,0,0,0,0,0,5,1,1
1,1,4,0,0,0,0,0,0,0,0,0,0,0,5,1,1
1,1,4,0,0,0,0,0,0,0,0,0,0,0,5,1,1
1,1,4,0,0,0,0,0,0,0,0,0,0,0,4,1,1
1,1,1,3,5,0,0,0,0,0,0,0,5,2,1,1,1
1,1,1,1,4,0,0,0,0,0,0,0,4,1,1,1,1
1,1,1,1,1,3,2,2,2,2,2,2,1,1,1,1,1
1,1,1,1,1,1,1,1,1,1,1,1,1,1,1,1,1
1,1,1,1,1,1,1,1,1,1,1,1,1,1,1,1,1
endlayer

layer
1,1,1,1,1,1,1,1,1,1,1,1,1,1,1,1,1
1,1,1,1,1,1,1,1,1,1,1,1,1,1,1,1,1
1,1,1,1,1,1,1,1,1,1,1,1,1,1,1,1,1
1,1,1,1,1,3,2,2,2,2,2,2,1,1,1,1,1
1,1,1,1,3,4,0,0,0,0,0,3,2,1,1,1,1
1,1,1,3,4,0,0,0,0,0,0,0,4,2,1,1,1
1,1,1,5,0,0,0,0,0,0,0,0,0,5,1,1,1
1,1,1,5,0,0,0,0,0,0,0,0,0,5,1,1,1
1,1,1,5,0,0,0,0,0,0,0,0,0,4,1,1,1
1,1,1,4,0,0,0,0,0,0,0,0,0,4,1,1,1
1,1,1,4,0,0,0,0,0,0,0,0,0,4,1,1,1
1,1,1,3,5,0,0,0,0,0,0,0,5,2,1,1,1
1,1,1,1,3,2,0,0,0,0,0,3,2,1,1,1,1
1,1,1,1,1,3,2,2,2,2,2,2,1,1,1,1,1
1,1,1,1,1,1,1,1,1,1,1,1,1,1,1,1,1
1,1,1,1,1,1,1,1,1,1,1,1,1,1,1,1,1
1,1,1,1,1,1,1,1,1,1,1,1,1,1,1,1,1
endlayer

layer
1,1,1,1,1,1,1,1,1,1,1,1,1,1,1,1,1
1,1,1,1,1,1,1,1,1,1,1,1,1,1,1,1,1
1,1,1,1,1,1,1,1,1,1,1,1,1,1,1,1,1
1,1,1,1,1,1,1,1,1,1,1,1,1,1,1,1,1
1,1,1,1,1,1,5,2,2,2,2,1,1,1,1,1,1
1,1,1,1,1,5,5,2,2,2,2,2,1,1,1,1,1
1,1,1,1,3,3,4,4,4,5,4,2,2,1,1,1,1
1,1,1,1,3,5,2,4,4,3,3,5,2,1,1,1,1
1,1,1,1,3,4,2,2,0,3,5,4,2,1,1,1,1
1,1,1,1,3,4,2,2,5,5,5,4,2,1,1,1,1
1,1,1,1,3,3,2,5,5,5,5,2,2,1,1,1,1
1,1,1,1,1,3,4,3,2,2,2,2,1,1,1,1,1
1,1,1,1,1,1,4,2,2,2,2,1,1,1,1,1,1
1,1,1,1,1,1,1,1,1,1,1,1,1,1,1,1,1
1,1,1,1,1,1,1,1,1,1,1,1,1,1,1,1,1
1,1,1,1,1,1,1,1,1,1,1,1,1,1,1,1,1
1,1,1,1,1,1,1,1,1,1,1,1,1,1,1,1,1
endlayer

layer
1,1,1,1,1,1,1,1,1,1,1,1,1,1,1,1,1
1,1,1,1,1,1,1,1,1,1,1,1,1,1,1,1,1
1,1,1,1,1,1,1,1,1,1,1,1,1,1,1,1,1
1,1,1,1,1,1,1,1,1,1,1,1,1,1,1,1,1
1,1,1,1,1,1,1,1,1,1,1,1,1,1,1,1,1
1,1,1,1,1,1,1,1,1,1,1,1,1,1,1,1,1
1,1,1,1,1,1,1,1,1,1,1,1,1,1,1,1,1
1,1,1,1,1,1,1,1,9,1,1,1,1,1,1,1,1
1,1,1,1,1,1,1,9,9,9,1,1,1,1,1,1,1
1,1,1,1,1,1,1,1,9,1,1,1,1,1,1,1,1
1,1,1,1,1,1,1,1,1,1,1,1,1,1,1,1,1
1,1,1,1,1,1,1,1,1,1,1,1,1,1,1,1,1
1,1,1,1,1,1,1,1,1,1,1,1,1,1,1,1,1
1,1,1,1,1,1,1,1,1,1,1,1,1,1,1,1,1
1,1,1,1,1,1,1,1,1,1,1,1,1,1,1,1,1
1,1,1,1,1,1,1,1,1,1,1,1,1,1,1,1,1
1,1,1,1,1,1,1,1,1,1,1,1,1,1,1,1,1
endlayer

layer
1,1,1,1,1,1,1,1,1,1,1,1,1,1,1,1,1
1,1,1,1,1,1,1,1,1,1,1,1,1,1,1,1,1
1,1,1,1,1,1,1,1,1,1,1,1,1,1,1,1,1
1,1,1,1,1,1,1,1,1,1,1,1,1,1,1,1,1
1,1,1,1,1,1,1,1,1,1,1,1,1,1,1,1,1
1,1,1,1,1,1,1,1,1,1,1,1,1,1,1,1,1
1,1,1,1,1,1,1,1,1,1,1,1,1,1,1,1,1
1,1,1,1,1,1,1,1,1,1,1,1,1,1,1,1,1
1,1,1,1,1,1,1,9,9,1,1,1,1,1,1,1,1
1,1,1,1,1,1,1,1,1,1,1,1,1,1,1,1,1
1,1,1,1,1,1,1,1,1,1,1,1,1,1,1,1,1
1,1,1,1,1,1,1,1,1,1,1,1,1,1,1,1,1
1,1,1,1,1,1,1,1,1,1,1,1,1,1,1,1,1
1,1,1,1,1,1,1,1,1,1,1,1,1,1,1,1,1
1,1,1,1,1,1,1,1,1,1,1,1,1,1,1,1,1
1,1,1,1,1,1,1,1,1,1,1,1,1,1,1,1,1
1,1,1,1,1,1,1,1,1,1,1,1,1,1,1,1,1
endlayer

layer
1,1,1,1,1,1,1,1,1,1,1,1,1,1,1,1,1
1,1,1,1,1,1,1,1,1,1,1,1,1,1,1,1,1
1,1,1,1,1,1,1,1,1,1,1,1,1,1,1,1,1
1,1,1,1,1,1,1,1,1,1,1,1,1,1,1,1,1
1,1,1,1,1,1,1,1,1,1,1,1,1,1,1,1,1
1,1,1,1,1,1,1,1,1,1,1,1,1,1,1,1,1
1,1,1,1,1,1,1,1,1,1,1,1,1,1,1,1,1
1,1,1,1,1,1,1,1,1,1,1,1,1,1,1,1,1
1,1,1,1,1,1,1,1,9,1,1,1,1,1,1,1,1
1,1,1,1,1,1,1,1,1,1,1,1,1,1,1,1,1
1,1,1,1,1,1,1,1,1,1,1,1,1,1,1,1,1
1,1,1,1,1,1,1,1,1,1,1,1,1,1,1,1,1
1,1,1,1,1,1,1,1,1,1,1,1,1,1,1,1,1
1,1,1,1,1,1,1,1,1,1,1,1,1,1,1,1,1
1,1,1,1,1,1,1,1,1,1,1,1,1,1,1,1,1
1,1,1,1,1,1,1,1,1,1,1,1,1,1,1,1,1
1,1,1,1,1,1,1,1,1,1,1,1,1,1,1,1,1
endlayer

