
# Created by Ruins mod version 17.0 Ingame Parser
# authoring Player: ST753M

weight=1
embed_into_distance=17
acceptable_target_blocks=water
unacceptable_target_blocks=lava
dimensions=28,13,13
allowable_overhang=0
max_leveling=0
leveling_buffer=0
preserve_water=0
preserve_lava=0

biomesToSpawnIn=swampland,wetland,quagmire,mangrove,bayou,bog,dead_swamp,coralium_infested_swamp,land_of_lakes,shield,twilight_swamp,twilight_stream,swamp_defiled,kelp_forest,coralium_infested_ocean

=0,100,air
rule1=0,100,preserveBlock
rule2=0,100,minecraft:log-1
rule3=0,100,minecraft:log-9
rule4=0,100,minecraft:log-5
rule5=0,100,minecraft:planks-1
rule6=0,100,minecraft:spruce_stairs-4
rule7=0,100,minecraft:spruce_stairs-1
rule8=0,100,minecraft:dark_oak_stairs-7
rule9=0,100,minecraft:dark_oak_stairs-6
rule10=0,100,minecraft:dark_oak_stairs-5
rule11=0,100,minecraft:dark_oak_stairs-4
rule12=0,100,minecraft:wooden_slab-13
rule13=0,100,minecraft:spruce_stairs-6
rule14=0,100,minecraft:spruce_stairs-7
rule15=0,100,minecraft:spruce_stairs-5
rule16=0,100,minecraft:dark_oak_fence-0
rule17=0,100,minecraft:planks-5
rule18=0,100,minecraft:dark_oak_door-2
rule19=0,100,minecraft:ladder-5
rule20=0,100,minecraft:dark_oak_door-3
rule21=0,100,minecraft:dark_oak_door-1
rule22=0,100,minecraft:dark_oak_door-0
rule23=0,100,minecraft:dark_oak_door-8
rule24=0,100,minecraft:dark_oak_door-9
rule25=0,30,ChestGenHook:chests/simple_dungeon:3-4
rule26=0,100,minecraft:wooden_slab-9
rule27=0,100,minecraft:double_wooden_slab-1
rule28=0,40,MobSpawner:witch,MobSpawner:cave_spider,MobSpawner:skeleton,MobSpawner:zombie,MobSpawner:skeleton,MobSpawner:skeleton,MobSpawner:skeleton,MobSpawner:skeleton
rule29=0,100,minecraft:spruce_stairs-2
rule30=0,100,minecraft:spruce_stairs-0
rule31=0,100,minecraft:dark_oak_stairs-0
rule32=0,100,minecraft:spruce_stairs-3
rule33=0,100,minecraft:dark_oak_stairs-2
rule34=0,100,minecraft:dark_oak_stairs-3
rule35=0,100,minecraft:dark_oak_stairs-1
rule36=0,100,minecraft:wooden_slab-1
rule37=0,100,minecraft:wooden_slab-5
rule38=0,100,minecraft:trapdoor-8
rule39=0,100,minecraft:spruce_fence-0

layer
1,1,1,1,1,1,1,1,1,1,1,1,1
1,1,1,1,1,1,1,1,1,1,1,1,1
1,1,1,1,1,1,1,1,1,1,1,1,1
1,1,1,2,1,1,1,1,1,2,1,1,1
1,1,1,1,1,1,1,1,1,1,1,1,1
1,1,1,1,1,1,1,1,1,1,1,1,1
1,1,1,1,1,1,1,1,1,1,1,1,1
1,1,1,1,1,1,1,1,1,1,1,1,1
1,1,1,1,1,1,1,1,1,1,1,1,1
1,1,1,2,1,1,1,1,1,2,1,1,1
1,1,1,1,1,1,1,1,1,1,1,1,1
1,1,1,1,1,1,1,1,1,1,1,1,1
1,1,1,1,1,1,1,1,1,1,1,1,1
endlayer

layer
1,1,1,1,1,1,1,1,1,1,1,1,1
1,1,1,1,1,1,1,1,1,1,1,1,1
1,1,1,1,1,1,1,1,1,1,1,1,1
1,1,1,2,1,1,1,1,1,2,1,1,1
1,1,1,1,1,1,1,1,1,1,1,1,1
1,1,1,1,1,1,1,1,1,1,1,1,1
1,1,1,1,1,1,1,1,1,1,1,1,1
1,1,1,1,1,1,1,1,1,1,1,1,1
1,1,1,1,1,1,1,1,1,1,1,1,1
1,1,1,2,1,1,1,1,1,2,1,1,1
1,1,1,1,1,1,1,1,1,1,1,1,1
1,1,1,1,1,1,1,1,1,1,1,1,1
1,1,1,1,1,1,1,1,1,1,1,1,1
endlayer

layer
1,1,1,1,1,1,1,1,1,1,1,1,1
1,1,1,1,1,1,1,1,1,1,1,1,1
1,1,1,1,1,1,1,1,1,1,1,1,1
1,1,1,2,1,1,1,1,1,2,1,1,1
1,1,1,1,1,1,1,1,1,1,1,1,1
1,1,1,1,1,1,1,1,1,1,1,1,1
1,1,1,1,1,1,1,1,1,1,1,1,1
1,1,1,1,1,1,1,1,1,1,1,1,1
1,1,1,1,1,1,1,1,1,1,1,1,1
1,1,1,2,1,1,1,1,1,2,1,1,1
1,1,1,1,1,1,1,1,1,1,1,1,1
1,1,1,1,1,1,1,1,1,1,1,1,1
1,1,1,1,1,1,1,1,1,1,1,1,1
endlayer

layer
1,1,1,1,1,1,1,1,1,1,1,1,1
1,1,1,1,1,1,1,1,1,1,1,1,1
1,1,1,1,1,1,1,1,1,1,1,1,1
1,1,1,2,1,1,1,1,1,2,1,1,1
1,1,1,1,1,1,1,1,1,1,1,1,1
1,1,1,1,1,1,1,1,1,1,1,1,1
1,1,1,1,1,1,1,1,1,1,1,1,1
1,1,1,1,1,1,1,1,1,1,1,1,1
1,1,1,1,1,1,1,1,1,1,1,1,1
1,1,1,2,1,1,1,1,1,2,1,1,1
1,1,1,1,1,1,1,1,1,1,1,1,1
1,1,1,1,1,1,1,1,1,1,1,1,1
1,1,1,1,1,1,1,1,1,1,1,1,1
endlayer

layer
1,1,1,1,1,1,1,1,1,1,1,1,1
1,1,1,1,1,1,1,1,1,1,1,1,1
1,1,1,1,1,1,1,1,1,1,1,1,1
1,1,1,2,3,3,3,3,3,2,1,1,1
1,1,1,4,1,1,1,1,1,4,1,1,1
1,1,1,4,1,1,1,1,1,4,1,1,1
1,1,1,4,1,1,1,1,1,4,1,1,1
1,1,1,4,1,1,1,1,1,4,1,1,1
1,1,1,4,1,1,1,1,1,4,1,1,1
1,1,1,2,3,3,3,3,3,2,1,1,1
1,1,1,1,1,1,1,1,1,1,1,1,1
1,1,1,1,1,1,1,1,1,1,1,1,1
1,1,1,1,1,1,1,1,1,1,1,1,1
endlayer

layer
1,1,1,1,1,1,1,1,1,1,1,1,1
1,1,1,1,1,1,1,1,1,1,1,1,1
1,1,1,1,1,1,1,1,1,1,1,1,1
1,1,1,2,1,1,1,1,1,2,1,1,1
1,1,1,1,1,1,1,1,1,1,1,1,1
1,1,1,1,1,1,1,1,1,1,1,1,1
1,1,1,1,1,1,1,1,1,1,1,1,1
1,1,1,1,1,1,1,1,1,1,1,1,1
1,1,1,1,1,1,1,1,1,1,1,1,1
1,1,1,2,1,1,1,1,1,2,1,1,1
1,1,1,1,1,1,1,1,1,1,1,1,1
1,1,1,1,1,1,1,1,1,1,1,1,1
1,1,1,1,1,1,1,1,1,1,1,1,1
endlayer

layer
1,1,1,1,1,1,1,1,1,1,1,1,1
1,1,1,1,1,1,1,1,1,1,1,1,1
1,1,1,1,1,1,1,1,1,1,1,1,1
1,1,1,2,1,1,1,1,1,2,1,1,1
1,1,1,1,1,1,1,1,1,1,1,1,1
1,1,1,1,1,1,1,1,1,1,1,1,1
1,1,1,1,1,1,1,1,1,1,1,1,1
1,1,1,1,1,1,1,1,1,1,1,1,1
1,1,1,1,1,1,1,1,1,1,1,1,1
1,1,1,2,1,1,1,1,1,2,1,1,1
1,1,1,1,1,1,1,1,1,1,1,1,1
1,1,1,1,1,1,1,1,1,1,1,1,1
1,1,1,1,1,1,1,1,1,1,1,1,1
endlayer

layer
1,1,1,1,1,1,1,1,1,1,1,1,1
1,1,1,1,1,1,1,1,1,1,1,1,1
1,1,1,1,1,1,1,1,1,1,1,1,1
1,1,1,2,1,1,1,1,1,2,1,1,1
1,1,1,1,1,1,1,1,1,1,1,1,1
1,1,1,1,1,1,1,1,1,1,1,1,1
1,1,1,1,1,1,1,1,1,1,1,1,1
1,1,1,1,1,1,1,1,1,1,1,1,1
1,1,1,1,1,1,1,1,1,1,1,1,1
1,1,1,2,1,1,1,1,1,2,1,1,1
1,1,1,1,1,1,1,1,1,1,1,1,1
1,1,1,1,1,1,1,1,1,1,1,1,1
1,1,1,1,1,1,1,1,1,1,1,1,1
endlayer

layer
1,1,1,1,1,1,1,1,1,1,1,1,1
1,1,1,1,1,1,1,1,1,1,1,1,1
1,1,1,1,1,1,1,1,1,1,1,1,1
1,1,1,2,1,1,1,1,1,2,1,1,1
1,1,1,1,1,1,1,1,1,1,1,1,1
1,1,1,1,1,1,1,1,1,1,1,1,1
1,1,1,1,1,1,1,1,1,1,1,1,1
1,1,1,1,1,1,1,1,1,1,1,1,1
1,1,1,1,1,1,1,1,1,1,1,1,1
1,1,1,2,1,1,1,1,1,2,1,1,1
1,1,1,1,1,1,1,1,1,1,1,1,1
1,1,1,1,1,1,1,1,1,1,1,1,1
1,1,1,1,1,1,1,1,1,1,1,1,1
endlayer

layer
1,1,1,1,1,1,1,1,1,1,1,1,1
1,1,1,1,1,1,1,1,1,1,1,1,1
1,1,1,1,1,1,1,1,1,1,1,1,1
1,1,1,2,3,3,3,3,3,2,1,1,1
1,1,1,4,1,1,1,1,1,4,1,1,1
1,1,1,4,1,1,1,1,1,4,1,1,1
1,1,1,4,1,1,1,1,1,4,1,1,1
1,1,1,4,1,1,1,1,1,4,1,1,1
1,1,1,4,1,1,1,1,1,4,1,1,1
1,1,1,2,3,3,3,3,3,2,1,1,1
1,1,1,1,1,1,1,1,1,1,1,1,1
1,1,1,1,1,1,1,1,1,1,1,1,1
1,1,1,1,1,1,1,1,1,1,1,1,1
endlayer

layer
1,1,1,1,1,1,1,1,1,1,1,1,1
1,1,1,1,1,1,1,1,1,1,1,1,1
1,1,1,1,1,1,1,1,1,1,1,1,1
1,1,1,2,1,1,1,1,1,2,1,1,1
1,1,1,1,1,1,1,1,1,1,1,1,1
1,1,1,1,1,1,1,1,1,1,1,1,1
1,1,1,1,1,1,1,1,1,1,1,1,1
1,1,1,1,1,1,1,1,1,1,1,1,1
1,1,1,1,1,1,1,1,1,1,1,1,1
1,1,1,2,1,1,1,1,1,2,1,1,1
1,1,1,1,1,1,1,1,1,1,1,1,1
1,1,1,1,1,1,1,1,1,1,1,1,1
1,1,1,1,1,1,1,1,1,1,1,1,1
endlayer

layer
1,1,1,1,1,1,1,1,1,1,1,1,1
1,1,1,1,1,1,1,1,1,1,1,1,1
1,1,1,1,1,1,1,1,1,1,1,1,1
1,1,1,2,1,1,1,1,1,2,1,1,1
1,1,1,1,1,1,1,1,1,1,1,1,1
1,1,1,1,1,1,1,1,1,1,1,1,1
1,1,1,1,1,1,1,1,1,1,1,1,1
1,1,1,1,1,1,1,1,1,1,1,1,1
1,1,1,1,1,1,1,1,1,1,1,1,1
1,1,1,2,1,1,1,1,1,2,1,1,1
1,1,1,1,1,1,1,1,1,1,1,1,1
1,1,1,1,1,1,1,1,1,1,1,1,1
1,1,1,1,1,1,1,1,1,1,1,1,1
endlayer

layer
1,1,1,1,1,1,1,1,1,1,1,1,1
1,1,1,1,1,1,1,1,1,1,1,1,1
1,1,1,1,1,1,1,1,1,1,1,1,1
1,1,1,2,1,1,1,1,1,2,1,1,1
1,1,1,1,1,1,1,1,1,1,1,1,1
1,1,1,1,1,1,1,1,1,1,1,1,1
1,1,1,1,1,1,1,1,1,1,1,1,1
1,1,1,1,1,1,1,1,1,1,1,1,1
1,1,1,1,1,1,1,1,1,1,1,1,1
1,1,1,2,1,1,1,1,1,2,1,1,1
1,1,1,1,1,1,1,1,1,1,1,1,1
1,1,1,1,1,1,1,1,1,1,1,1,1
1,1,1,1,1,1,1,1,1,1,1,1,1
endlayer

layer
1,1,1,1,1,1,1,1,1,1,1,1,1
1,1,1,1,1,1,1,1,1,1,1,1,1
1,1,1,1,1,1,1,1,1,1,1,1,1
1,1,1,2,1,1,1,1,1,2,1,1,1
1,1,1,1,1,1,1,1,1,1,1,1,1
1,1,1,1,1,1,1,1,1,1,1,1,1
1,1,1,1,1,1,1,1,1,1,1,1,1
1,1,1,1,1,1,1,1,1,1,1,1,1
1,1,1,1,1,1,1,1,1,1,1,1,1
1,1,1,2,1,1,1,1,1,2,1,1,1
1,1,1,1,1,1,1,1,1,1,1,1,1
1,1,1,1,1,1,1,1,1,1,1,1,1
1,1,1,1,1,1,1,1,1,1,1,1,1
endlayer

layer
1,1,1,1,1,1,1,1,1,1,1,1,1
1,1,1,1,1,1,1,1,1,1,1,1,1
1,1,1,1,1,1,1,1,1,1,1,1,1
1,1,1,2,3,3,3,3,3,2,1,1,1
1,1,1,4,1,1,1,1,1,4,1,1,1
1,1,1,4,1,1,1,1,1,4,1,1,1
1,1,1,4,1,1,1,1,1,4,1,1,1
1,1,1,4,1,1,1,1,1,4,1,1,1
1,1,1,4,1,1,1,1,1,4,1,1,1
1,1,1,2,3,3,3,3,3,2,1,1,1
1,1,1,1,1,1,1,1,1,1,1,1,1
1,1,1,1,1,1,1,1,1,1,1,1,1
1,1,1,1,1,1,1,1,1,1,1,1,1
endlayer

layer
1,1,1,1,1,1,1,1,1,1,1,1,1
1,1,1,1,1,1,1,1,1,1,1,1,1
1,1,1,1,1,1,1,1,1,1,1,1,1
1,1,1,2,1,1,1,1,1,2,1,1,1
1,1,1,1,1,1,1,1,1,1,1,1,1
1,1,1,1,1,1,1,1,1,1,1,1,1
1,1,1,1,1,1,1,1,1,1,1,1,1
1,1,1,1,1,1,1,1,1,1,1,1,1
1,1,1,1,1,1,1,1,1,1,1,1,1
1,1,1,2,1,1,1,1,1,2,1,1,1
1,1,1,1,1,1,1,1,1,1,1,1,1
1,1,1,1,1,1,1,1,1,1,1,1,1
1,1,1,1,1,1,1,1,1,1,1,1,1
endlayer

layer
1,1,1,1,1,1,1,1,1,1,1,1,1
1,1,1,1,1,1,1,1,1,1,1,1,1
1,1,1,1,1,1,1,1,1,1,1,1,1
1,1,1,2,1,1,1,1,1,2,1,1,1
1,1,1,1,1,1,1,1,1,1,1,1,1
1,1,1,1,1,1,1,1,1,1,1,1,1
1,1,1,1,1,1,1,1,1,1,1,1,1
1,1,1,1,1,1,1,1,1,1,1,1,1
1,1,1,1,1,1,1,1,1,1,1,1,1
1,3,3,2,1,1,1,1,1,2,1,1,1
1,5,5,4,1,1,1,1,1,1,1,1,1
1,5,5,4,1,1,1,1,1,1,1,1,1
1,5,5,4,1,1,1,1,1,1,1,1,1
endlayer

layer
1,1,1,1,1,1,1,1,1,1,1,1,1
1,1,1,1,1,1,1,1,1,1,1,1,1
1,1,1,1,1,1,1,1,1,1,1,1,1
1,1,1,2,1,1,1,1,1,2,1,1,1
1,1,1,1,1,1,1,1,1,1,1,1,1
1,1,1,1,1,1,1,1,1,1,1,1,1
1,1,1,1,1,1,1,1,1,1,1,1,1
1,1,1,1,1,1,1,1,1,1,1,1,1
1,1,1,1,1,1,1,1,1,1,1,1,1
1,0,0,2,1,1,1,1,1,2,1,1,1
1,6,6,0,1,1,1,1,1,1,1,1,1
1,7,7,0,1,1,1,1,1,1,1,1,1
1,0,0,0,1,1,1,1,1,1,1,1,1
endlayer

layer
1,1,1,1,1,1,1,1,1,1,1,1,1
1,1,1,1,1,1,1,1,1,1,1,1,1
1,1,1,1,1,1,1,1,1,1,1,1,1
1,1,1,2,9,1,1,1,8,2,1,1,1
1,1,1,10,1,1,1,1,1,10,1,1,1
1,1,1,1,1,1,1,1,1,1,1,1,1
1,1,1,1,1,1,1,1,1,1,1,1,1
1,1,1,1,1,1,1,1,1,1,1,1,1
1,1,1,11,1,1,1,1,1,11,1,1,1
1,6,6,2,9,1,1,1,8,2,1,1,1
1,7,7,0,1,1,1,1,1,1,1,1,1
1,0,0,0,1,1,1,1,1,1,1,1,1
1,0,0,0,1,1,1,1,1,1,1,1,1
endlayer

layer
1,1,1,1,1,12,0,12,1,1,1,1,1
1,1,1,1,1,12,0,12,1,1,1,1,1
1,1,1,1,1,12,0,12,1,1,1,1,1
1,1,1,2,3,3,3,3,3,2,1,1,1
1,1,1,4,0,0,0,0,0,4,1,1,1
12,12,12,4,0,0,0,0,0,4,12,12,12
0,0,0,4,0,0,0,0,0,4,0,0,0
12,12,12,4,0,0,0,0,0,4,12,12,12
1,6,6,4,0,0,0,0,0,4,1,1,1
1,7,7,2,3,3,3,3,3,2,1,1,1
1,0,0,0,0,12,0,12,1,1,1,1,1
1,0,0,0,0,12,0,12,1,1,1,1,1
1,0,0,0,0,12,0,12,1,1,1,1,1
endlayer

layer
1,1,1,6,6,6,6,6,6,6,1,1,1
1,1,1,14,5,5,5,5,5,13,1,1,1
1,1,1,14,5,5,5,5,5,13,1,1,1
14,6,6,2,5,5,5,5,5,2,6,6,13
14,5,5,5,5,5,5,5,5,5,5,5,13
14,5,5,5,5,5,5,5,5,5,5,5,13
14,5,5,5,5,5,5,5,5,5,5,5,13
14,5,5,5,5,5,5,5,5,5,5,5,13
14,7,7,5,5,5,5,5,5,5,5,5,13
15,0,0,2,5,5,5,5,5,2,15,15,13
1,0,0,14,5,5,5,5,5,13,1,1,1
1,0,0,14,5,5,5,5,5,13,1,1,1
1,1,0,14,15,15,15,15,15,15,1,1,1
endlayer

layer
1,1,1,16,16,16,16,16,16,16,1,1,1
1,1,1,16,0,0,0,0,0,16,1,1,1
1,1,1,16,0,0,0,0,0,16,1,1,1
16,16,16,2,17,17,18,17,17,2,16,16,16
16,0,0,17,0,2,0,0,0,17,0,0,16
16,0,0,17,0,19,0,0,0,17,0,0,16
16,0,0,21,0,0,0,0,0,20,0,0,16
16,0,0,17,0,0,0,0,0,17,0,0,16
16,0,0,17,0,0,0,8,11,17,0,0,16
16,0,0,2,17,17,22,17,17,2,16,16,16
1,0,0,16,0,0,0,0,0,16,1,1,1
1,1,1,16,0,0,0,0,0,16,1,1,1
1,1,1,16,16,16,16,16,16,16,1,1,1
endlayer

layer
1,1,1,1,1,1,1,1,1,1,1,1,1
1,1,1,0,0,0,0,0,0,0,1,1,1
1,1,1,0,0,0,0,0,0,0,1,1,1
1,1,1,2,17,17,23,17,17,2,0,0,1
1,0,0,17,0,2,0,0,0,17,0,0,1
1,0,0,17,0,19,0,0,0,17,0,0,1
1,0,0,23,0,0,0,0,0,24,0,0,1
1,0,0,17,0,0,0,0,0,17,0,0,1
1,0,0,17,0,0,0,0,25,17,0,0,1
1,0,0,2,17,17,23,17,17,2,0,0,1
1,1,1,0,0,0,0,0,0,0,1,1,1
1,1,1,0,0,0,0,0,0,0,1,1,1
1,1,1,1,1,1,1,1,1,1,1,1,1
endlayer

layer
1,1,1,1,1,1,1,1,1,1,1,1,1
1,1,1,0,0,0,0,0,0,0,1,1,1
1,1,1,6,0,0,0,0,0,6,1,1,1
1,1,14,2,17,17,17,17,17,2,13,0,1
1,0,0,17,0,2,0,0,0,17,0,0,1
1,0,0,17,0,19,0,0,0,17,0,0,1
1,0,0,17,0,0,0,0,0,17,0,0,1
1,0,0,17,0,0,0,0,0,17,0,0,1
1,0,0,17,0,0,0,0,0,17,0,0,1
1,0,14,2,17,17,17,17,17,2,13,0,1
1,1,1,15,0,0,0,0,0,15,1,1,1
1,1,1,0,0,0,0,0,0,0,1,1,1
1,1,1,1,1,1,1,1,1,1,1,1,1
endlayer

layer
1,1,1,1,1,1,1,1,1,1,1,1,1
1,26,26,27,26,26,26,26,26,27,26,26,1
1,26,0,5,0,0,0,0,0,5,0,26,1
1,27,5,2,3,3,3,3,3,2,5,27,1
1,26,0,4,0,2,0,0,0,4,0,26,1
1,26,0,4,0,19,0,0,0,4,0,26,1
1,26,0,4,0,0,0,0,0,4,0,26,1
1,26,0,4,0,0,0,0,0,4,0,26,1
1,26,0,4,0,0,0,0,0,4,0,26,1
1,27,5,2,3,3,3,3,3,28,5,27,1
1,26,0,5,0,0,0,0,0,5,0,26,1
1,26,26,27,26,26,26,26,26,27,26,26,1
1,1,1,1,1,1,1,1,1,1,1,1,1
endlayer

layer
1,1,1,1,1,1,1,1,1,1,1,1,1
1,16,16,16,16,16,16,16,16,16,16,16,1
1,16,30,30,30,30,31,30,30,30,29,16,1
1,16,32,2,5,5,5,5,5,2,29,16,1
1,16,32,5,10,2,10,10,10,5,29,16,1
1,16,32,5,9,19,0,0,8,5,29,16,1
1,16,34,5,9,0,0,0,8,5,33,16,1
1,16,32,5,9,0,0,0,8,5,29,16,1
1,16,32,5,11,11,11,11,11,5,29,16,1
1,16,32,2,5,5,5,5,5,2,29,16,1
1,16,7,7,7,7,35,7,7,7,7,16,1
1,16,16,16,16,16,16,16,16,16,16,16,1
1,1,1,1,1,1,1,1,1,1,1,1,1
endlayer

layer
1,1,1,1,1,1,1,1,1,1,1,1,1
1,16,1,1,1,1,1,1,1,1,1,16,1
1,1,1,1,1,1,1,1,1,1,1,1,1
1,1,1,2,36,37,37,37,36,2,1,1,1
1,1,1,36,17,17,17,17,17,36,1,1,1
1,1,1,37,17,38,17,17,17,37,1,1,1
1,1,1,37,17,17,17,17,17,37,1,1,1
1,1,1,37,17,17,17,17,17,37,1,1,1
1,1,1,36,17,17,17,17,17,36,1,1,1
1,1,1,2,36,37,37,37,36,2,1,1,1
1,1,1,1,1,1,1,1,1,1,1,1,1
1,16,1,1,1,1,1,1,1,1,1,16,1
1,1,1,1,1,1,1,1,1,1,1,1,1
endlayer

layer
1,1,1,1,1,1,1,1,1,1,1,1,1
1,1,1,1,1,1,1,1,1,1,1,1,1
1,1,1,1,1,1,1,1,1,1,1,1,1
1,1,1,1,1,1,1,1,1,1,1,1,1
1,1,1,1,39,39,39,39,39,1,1,1,1
1,1,1,1,39,0,0,0,39,1,1,1,1
1,1,1,1,39,0,0,0,39,1,1,1,1
1,1,1,1,39,0,0,0,39,1,1,1,1
1,1,1,1,39,39,39,39,39,1,1,1,1
1,1,1,1,1,1,1,1,1,1,1,1,1
1,1,1,1,1,1,1,1,1,1,1,1,1
1,1,1,1,1,1,1,1,1,1,1,1,1
1,1,1,1,1,1,1,1,1,1,1,1,1
endlayer

