
# Created by Ruins mod version 17.0 Ingame Parser
# authoring Player: ST753M

weight=1
embed_into_distance=10
acceptable_target_blocks=grass,dirt
unacceptable_target_blocks=flowing_water,water,flowing_lava,lava
dimensions=11,10,10
allowable_overhang=10
max_leveling=0
leveling_buffer=0
preserve_water=0
preserve_lava=0

biomesToSpawnIn=swampland,mutated_swampland,wetland,lush_swamp,marsh,bayou,bog,dead_swamp,coralium_infested_swamp

=0,100,air
rule1=0,100,preserveBlock
rule2=0,100,minecraft:grass-0
rule3=0,100,minecraft:slime-0
rule4=0,100,minecraft:dirt-0
rule5=0,100,minecraft:vine-4
rule6=0,100,minecraft:vine-6
rule7=0,100,minecraft:vine-1
rule8=0,100,minecraft:vine-2
rule9=0,100,minecraft:vine-8

layer
1,1,1,1,1,1,1,1,1,1
1,1,1,1,1,1,1,1,1,1
1,1,1,1,1,1,1,1,1,1
1,1,1,2,2,2,1,1,1,1
1,1,1,2,2,2,2,1,1,1
1,1,1,1,2,2,2,1,1,1
1,1,1,1,2,2,1,1,1,1
1,1,1,1,1,1,1,1,1,1
1,1,1,1,1,1,1,1,1,1
1,1,1,1,1,1,1,1,1,1
endlayer

layer
1,1,1,1,1,1,1,1,1,1
1,1,1,1,1,1,1,1,1,1
1,1,1,2,2,2,1,1,1,1
1,1,2,3,3,3,2,1,1,1
1,1,2,3,3,3,3,2,1,1
1,1,2,2,3,3,3,2,1,1
1,1,1,2,3,3,2,2,1,1
1,1,1,1,2,2,2,1,1,1
1,1,1,1,1,1,1,1,1,1
1,1,1,1,1,1,1,1,1,1
endlayer

layer
1,1,1,1,1,1,1,1,1,1
1,1,4,4,2,2,4,1,1,1
1,4,2,3,3,3,2,2,1,1
1,2,3,0,0,0,3,2,4,1
1,2,3,0,0,0,0,3,4,1
1,2,3,3,0,3,0,3,2,1
1,4,2,3,0,0,3,3,2,1
1,1,2,2,3,3,3,2,4,1
1,1,1,4,2,2,2,4,1,1
1,1,1,1,1,4,4,1,1,1
endlayer

layer
1,1,1,1,4,4,1,1,1,1
1,1,4,4,3,3,4,4,1,1
1,4,3,3,0,0,3,3,4,1
4,3,0,0,0,0,0,3,4,1
4,3,0,0,0,0,0,0,4,1
4,3,0,0,0,0,0,3,3,4
1,4,3,0,0,0,0,0,3,4
1,4,0,3,0,3,0,3,4,1
1,1,4,4,3,0,3,4,1,1
1,1,1,1,4,4,4,1,1,1
endlayer

layer
1,1,1,1,4,4,1,1,1,1
1,1,4,4,0,0,4,4,1,1
1,4,0,3,0,0,0,3,4,1
4,0,0,0,0,0,0,0,4,1
4,0,0,0,0,0,0,5,4,1
4,3,0,0,0,0,0,0,5,4
1,4,0,0,0,0,0,0,3,4
1,4,0,0,0,3,0,0,4,1
1,1,4,4,3,0,0,4,1,1
1,1,1,1,4,4,4,1,1,1
endlayer

layer
1,1,1,1,4,4,1,1,1,1
1,1,4,4,0,0,4,4,1,1
1,4,0,0,0,0,0,0,4,1
4,0,0,0,0,0,0,0,4,1
4,0,0,0,0,0,0,0,4,1
4,0,7,0,0,0,0,0,6,4
1,4,0,0,0,0,0,0,5,4
1,4,0,0,0,0,0,0,4,1
1,1,4,4,0,0,0,4,1,1
1,1,1,1,4,4,4,1,1,1
endlayer

layer
1,1,1,1,4,4,1,1,1,1
1,1,4,4,4,8,4,4,1,1
1,4,0,0,0,0,0,8,4,1
4,4,0,0,0,0,0,4,4,1
4,0,0,0,0,0,0,8,4,1
4,2,7,0,0,0,0,0,0,4
1,2,9,0,0,0,0,0,0,4
1,4,2,0,0,0,0,0,4,1
1,1,4,4,9,0,9,2,1,1
1,1,1,1,4,4,4,1,1,1
endlayer

layer
1,1,1,1,1,2,1,1,1,1
1,1,2,4,4,2,4,2,1,1
1,4,4,8,0,0,8,4,2,1
4,2,7,0,0,0,0,4,4,1
2,4,7,0,0,0,0,0,4,1
2,2,0,0,0,0,0,0,5,4
1,4,4,0,0,0,0,5,4,4
1,2,4,0,0,0,0,5,4,1
1,1,4,4,4,9,0,1,1,1
1,1,1,1,2,2,4,1,1,1
endlayer

layer
1,1,1,1,1,1,1,1,1,1
1,1,1,2,2,2,2,1,1,1
1,2,2,2,4,2,2,2,1,1
2,4,7,0,0,8,4,4,2,1
1,2,0,0,0,0,8,5,2,1
1,2,4,7,0,0,0,0,2,2
1,2,4,7,0,0,0,0,4,2
1,1,4,4,9,0,0,5,2,1
1,1,2,4,4,4,9,0,1,1
1,1,1,1,1,2,2,1,1,1
endlayer

layer
1,1,1,1,1,1,1,1,1,1
1,1,1,1,1,1,1,1,1,1
1,1,0,1,2,2,2,1,1,1
1,2,0,0,2,2,2,2,1,1
1,1,2,7,5,2,2,2,1,1
1,1,2,2,7,8,5,2,2,1
1,1,2,2,7,0,0,2,2,1
1,1,2,2,2,7,9,0,1,1
1,1,1,2,2,2,2,0,0,1
1,1,1,1,1,1,1,1,1,1
endlayer

layer
1,1,1,1,1,1,1,1,1,1
1,0,1,1,1,1,1,1,1,1
1,0,0,1,1,1,1,1,1,1
1,1,0,0,1,1,1,1,1,1
1,1,1,0,0,1,1,1,1,1
1,1,1,1,0,0,0,1,1,1
1,1,1,1,0,0,0,1,1,1
1,1,1,1,1,0,0,0,1,1
1,1,1,1,1,1,1,0,0,1
1,1,1,1,1,1,1,1,0,0
endlayer

