
# Created by Ruins mod version 16.9 Ingame Parser
# authoring Player: ST753M

weight=1
uniqueMinDistance=1000
embed_into_distance=9
acceptable_target_blocks=
unacceptable_target_blocks=flowing_lava,lava,bedrock,netherrack,nether_brick,nether_brick_fence,soul_sand,quartz_ore,end_stone,obsidian,iron_bars,Natura:Cloud,slime_grass,slime_congealed,slime_dirt,clouds,natura:clouds
dimensions=25,15,19
allowable_overhang=16
max_leveling=0
leveling_buffer=0
preserve_water=0
preserve_lava=0

biomesToSpawnIn=swampland,mutated_swampland,wetland,quagmire,lush_swamp,mangrove,marsh,bayou,bog,bamboo_forest,dead_swamp,moor,dead_swamp,swampland m,bamboo forest,eucalyptus forest,land of lakes,lush swamp,temperate rainforest,dead swamp,coralium_infested_swamp,swamp_defiled

=0,100,air
rule1=0,100,preserveBlock
rule2=0,100,minecraft:log-0
rule3=0,100,minecraft:spruce_stairs-4
rule4=0,100,minecraft:spruce_stairs-1
rule5=0,100,minecraft:spruce_stairs-0
rule6=0,100,minecraft:spruce_stairs-5
rule7=0,100,minecraft:spruce_stairs-6
rule8=0,100,minecraft:spruce_stairs-7
rule9=0,100,minecraft:planks-1
rule10=0,100,minecraft:log-8
rule11=0,100,minecraft:log-4
rule12=0,100,minecraft:wooden_slab-9
rule13=0,100,minecraft:dark_oak_fence-0
rule14=0,100,minecraft:cauldron-1
rule15=0,100,minecraft:dark_oak_door-3
rule16=0,100,minecraft:carpet-13
rule17=0,100,minecraft:dark_oak_door-1
rule18=0,100,minecraft:dark_oak_stairs-4
rule19=0,100,minecraft:dark_oak_door-0
rule20=0,100,minecraft:dark_oak_stairs-6
rule21=0,100,minecraft:dark_oak_stairs-5
rule22=0,100,minecraft:dark_oak_stairs-1
rule23=0,100,minecraft:dark_oak_stairs-3
rule24=0,100,minecraft:dark_oak_stairs-2
rule25=0,100,minecraft:dark_oak_stairs-0
rule26=0,100,ChestGenHook:chests/simple_dungeon:3-2
rule27=0,100,minecraft:furnace-4
rule28=0,100,minecraft:crafting_table-0
rule29=0,100,minecraft:stained_glass_pane-13
rule30=0,100,minecraft:dark_oak_door-9
rule31=0,100,minecraft:dark_oak_door-8
rule32=0,20,minecraft:brewing_stand-0
rule33=0,100,MobSpawner:Spider,MobSpawner:Cave_Spider
rule34=0,100,minecraft:bed-0
rule35=0,100,minecraft:bed-8
rule36=0,100,minecraft:bookshelf-0
rule37=0,100,minecraft:spruce_stairs-2
rule38=0,100,minecraft:spruce_stairs-3
rule39=0,100,minecraft:web-0
rule40=0,100,minecraft:ladder-4
rule41=0,100,minecraft:trapdoor-3

layer
1,1,1,1,1,1,1,1,1,1,1,1,1,1,1,1,1,1,1
1,2,1,1,1,2,1,1,1,2,1,1,1,2,1,1,1,2,1
1,1,1,1,1,1,1,1,1,1,1,1,1,1,1,1,1,1,1
1,1,1,1,1,1,1,1,1,1,1,1,1,1,1,1,1,1,1
1,1,1,1,1,1,1,1,1,1,1,1,1,1,1,1,1,1,1
1,2,1,1,1,2,1,1,1,2,1,1,1,2,1,1,1,2,1
1,1,1,1,1,1,1,1,1,1,1,1,1,1,1,1,1,1,1
1,1,1,1,1,1,1,1,1,1,1,1,1,1,1,1,1,1,1
1,1,1,1,1,1,1,1,1,1,1,1,1,1,1,1,1,1,1
1,2,1,1,1,2,1,1,1,2,1,1,1,2,1,1,1,2,1
1,1,1,1,1,1,1,1,1,1,1,1,1,1,1,1,1,1,1
1,1,1,1,1,1,1,1,1,1,1,1,1,1,1,1,1,1,1
1,1,1,1,1,1,1,1,1,1,1,1,1,1,1,1,1,1,1
1,2,1,1,1,2,1,1,1,2,1,1,1,2,1,1,1,2,1
1,1,1,1,1,1,1,1,1,1,1,1,1,1,1,1,1,1,1
endlayer

layer
1,1,1,1,1,1,1,1,1,1,1,1,1,1,1,1,1,1,1
1,2,1,1,1,2,1,1,1,2,1,1,1,2,1,1,1,2,1
1,1,1,1,1,1,1,1,1,1,1,1,1,1,1,1,1,1,1
1,1,1,1,1,1,1,1,1,1,1,1,1,1,1,1,1,1,1
1,1,1,1,1,1,1,1,1,1,1,1,1,1,1,1,1,1,1
1,2,1,1,1,2,1,1,1,2,1,1,1,2,1,1,1,2,1
1,1,1,1,1,1,1,1,1,1,1,1,1,1,1,1,1,1,1
1,1,1,1,1,1,1,1,1,1,1,1,1,1,1,1,1,1,1
1,1,1,1,1,1,1,1,1,1,1,1,1,1,1,1,1,1,1
1,2,1,1,1,2,1,1,1,2,1,1,1,2,1,1,1,2,1
1,1,1,1,1,1,1,1,1,1,1,1,1,1,1,1,1,1,1
1,1,1,1,1,1,1,1,1,1,1,1,1,1,1,1,1,1,1
1,1,1,1,1,1,1,1,1,1,1,1,1,1,1,1,1,1,1
1,2,1,1,1,2,1,1,1,2,1,1,1,2,1,1,1,2,1
1,1,1,1,1,1,1,1,1,1,1,1,1,1,1,1,1,1,1
endlayer

layer
1,1,1,1,1,1,1,1,1,1,1,1,1,1,1,1,1,1,1
1,2,1,1,1,2,1,1,1,2,1,1,1,2,1,1,1,2,1
1,1,1,1,1,1,1,1,1,1,1,1,1,1,1,1,1,1,1
1,1,1,1,1,1,1,1,1,1,1,1,1,1,1,1,1,1,1
1,1,1,1,1,1,1,1,1,1,1,1,1,1,1,1,1,1,1
1,2,1,1,1,2,1,1,1,2,1,1,1,2,1,1,1,2,1
1,1,1,1,1,1,1,1,1,1,1,1,1,1,1,1,1,1,1
1,1,1,1,1,1,1,1,1,1,1,1,1,1,1,1,1,1,1
1,1,1,1,1,1,1,1,1,1,1,1,1,1,1,1,1,1,1
1,2,1,1,1,2,1,1,1,2,1,1,1,2,1,1,1,2,1
1,1,1,1,1,1,1,1,1,1,1,1,1,1,1,1,1,1,1
1,1,1,1,1,1,1,1,1,1,1,1,1,1,1,1,1,1,1
1,1,1,1,1,1,1,1,1,1,1,1,1,1,1,1,1,1,1
1,2,1,1,1,2,1,1,1,2,1,1,1,2,1,1,1,2,1
1,1,1,1,1,1,1,1,1,1,1,1,1,1,1,1,1,1,1
endlayer

layer
1,1,1,1,1,1,1,1,1,1,1,1,1,1,1,1,1,1,1
1,2,1,1,1,2,1,1,1,2,1,1,1,2,1,1,1,2,1
1,1,1,1,1,1,1,1,1,1,1,1,1,1,1,1,1,1,1
1,1,1,1,1,1,1,1,1,1,1,1,1,1,1,1,1,1,1
1,1,1,1,1,1,1,1,1,1,1,1,1,1,1,1,1,1,1
1,2,1,1,1,2,1,1,1,2,1,1,1,2,1,1,1,2,1
1,1,1,1,1,1,1,1,1,1,1,1,1,1,1,1,1,1,1
1,1,1,1,1,1,1,1,1,1,1,1,1,1,1,1,1,1,1
1,1,1,1,1,1,1,1,1,1,1,1,1,1,1,1,1,1,1
1,2,1,1,1,2,1,1,1,2,1,1,1,2,1,1,1,2,1
1,1,1,1,1,1,1,1,1,1,1,1,1,1,1,1,1,1,1
1,1,1,1,1,1,1,1,1,1,1,1,1,1,1,1,1,1,1
1,1,1,1,1,1,1,1,1,1,1,1,1,1,1,1,1,1,1
1,2,1,1,1,2,1,1,1,2,1,1,1,2,1,1,1,2,1
1,1,1,1,1,1,1,1,1,1,1,1,1,1,1,1,1,1,1
endlayer

layer
1,1,1,1,1,1,1,1,1,1,1,1,1,1,1,1,1,1,1
1,2,1,1,1,2,1,1,1,2,1,1,1,2,1,1,1,2,1
1,1,1,1,1,1,1,1,1,1,1,1,1,1,1,1,1,1,1
1,1,1,1,1,1,1,1,1,1,1,1,1,1,1,1,1,1,1
1,1,1,1,1,1,1,1,1,1,1,1,1,1,1,1,1,1,1
1,2,1,1,1,2,1,1,1,2,1,1,1,2,1,1,1,2,1
1,1,1,1,1,1,1,1,1,1,1,1,1,1,1,1,1,1,1
1,1,1,1,1,1,1,1,1,1,1,1,1,1,1,1,1,1,1
1,1,1,1,1,1,1,1,1,1,1,1,1,1,1,1,1,1,1
1,2,1,1,1,2,1,1,1,2,1,1,1,2,1,1,1,2,1
1,1,1,1,1,1,1,1,1,1,1,1,1,1,1,1,1,1,1
1,1,1,1,1,1,1,1,1,1,1,1,1,1,1,1,1,1,1
1,1,1,1,1,1,1,1,1,1,1,1,1,1,1,1,1,1,1
1,2,1,1,1,2,1,1,1,2,1,1,1,2,1,1,1,2,1
1,1,1,1,1,1,1,1,1,1,1,1,1,1,1,1,1,1,1
endlayer

layer
1,1,1,1,1,1,1,1,1,1,1,1,1,1,1,1,1,1,1
1,2,1,1,1,2,1,1,1,2,1,1,1,2,1,1,1,2,1
1,1,1,1,1,1,1,1,1,1,1,1,1,1,1,1,1,1,1
1,1,1,1,1,1,1,1,1,1,1,1,1,1,1,1,1,1,1
1,1,1,1,1,1,1,1,1,1,1,1,1,1,1,1,1,1,1
1,2,1,1,1,2,1,1,1,2,1,1,1,2,1,1,1,2,1
1,1,1,1,1,1,1,1,1,1,1,1,1,1,1,1,1,1,1
1,1,1,1,1,1,1,1,1,1,1,1,1,1,1,1,1,1,1
1,1,1,1,1,1,1,1,1,1,1,1,1,1,1,1,1,1,1
1,2,1,1,1,2,1,1,1,2,1,1,1,2,1,1,1,2,1
1,1,1,1,1,1,1,1,1,1,1,1,1,1,1,1,1,1,1
1,1,1,1,1,1,1,1,1,1,1,1,1,1,1,1,1,1,1
1,1,1,1,1,1,1,1,1,1,1,1,1,1,1,1,1,1,1
1,2,1,1,1,2,1,1,1,2,1,1,1,2,1,1,1,2,1
1,1,1,1,1,1,1,1,1,1,1,1,1,1,1,1,1,1,1
endlayer

layer
1,1,1,1,1,1,1,1,1,1,1,1,1,1,1,1,1,1,1
1,2,1,1,1,2,1,1,1,2,1,1,1,2,1,1,1,2,1
1,1,1,1,1,1,1,1,1,1,1,1,1,1,1,1,1,1,1
1,1,1,1,1,1,1,1,1,1,1,1,1,1,1,1,1,1,1
1,1,1,1,1,1,1,1,1,1,1,1,1,1,1,1,1,1,1
1,2,1,1,1,2,1,1,1,2,1,1,1,2,1,1,1,2,1
1,1,1,1,1,1,1,1,1,1,1,1,1,1,1,1,1,1,1
1,1,1,1,1,1,1,1,1,1,1,1,1,1,1,1,1,1,1
1,1,1,1,1,1,1,1,1,1,1,1,1,1,1,1,1,1,1
1,2,1,1,1,2,1,1,1,2,1,1,1,2,1,1,1,2,1
1,1,1,1,1,1,1,1,1,1,1,1,1,1,1,1,1,1,1
1,1,1,1,1,1,1,1,1,1,1,1,1,1,1,1,1,1,1
1,1,1,1,1,1,1,1,1,1,1,1,1,1,1,1,1,1,1
1,2,1,1,1,2,1,1,1,2,1,1,1,2,1,1,1,2,1
1,1,1,1,1,1,1,1,1,1,1,1,1,1,1,1,1,1,1
endlayer

layer
1,1,1,1,1,1,1,1,1,1,1,1,1,1,1,1,1,1,1
1,2,1,1,1,2,1,1,1,2,1,1,1,2,1,1,1,2,1
1,1,1,1,1,1,1,1,1,1,1,1,1,1,1,1,1,1,1
1,1,1,1,1,1,1,1,1,1,1,1,1,1,1,1,1,1,1
1,1,1,1,1,1,1,1,1,1,1,1,1,1,1,1,1,1,1
1,2,1,1,1,2,1,1,1,2,1,1,1,2,1,1,1,2,1
1,1,1,1,1,1,1,1,1,1,1,1,1,1,1,1,1,1,1
1,1,1,1,1,1,1,1,1,1,1,1,1,1,1,1,1,1,1
1,1,1,1,1,1,1,1,1,1,1,1,1,1,1,1,1,1,1
1,2,1,1,1,2,1,1,1,2,1,1,1,2,1,1,1,2,1
1,1,1,1,1,1,1,1,1,1,1,1,1,1,1,1,1,1,1
1,1,1,1,1,1,1,1,1,1,1,1,1,1,1,1,1,1,1
1,1,1,1,1,1,1,1,1,1,1,1,1,1,1,1,1,1,1
1,2,1,1,1,2,1,1,1,2,1,1,1,2,1,1,1,2,1
1,1,1,1,1,1,1,1,1,1,1,1,1,1,1,1,1,1,1
endlayer

layer
1,1,1,1,1,1,1,1,1,1,1,1,1,1,1,1,1,1,1
1,2,1,1,1,2,1,1,1,2,1,1,1,2,1,1,1,2,1
1,1,1,1,1,1,1,1,1,1,1,1,1,1,1,1,1,1,1
1,1,1,1,1,1,1,1,1,1,1,1,1,1,1,1,1,1,1
1,1,1,1,1,1,1,1,1,1,1,1,1,1,1,1,1,1,1
1,2,1,1,1,2,1,1,1,2,1,1,1,2,1,1,1,2,1
1,1,1,1,1,1,1,1,1,1,1,1,1,1,1,1,1,1,1
1,1,1,1,1,1,1,1,1,1,1,1,1,1,1,1,1,1,1
1,1,1,1,1,1,1,1,1,1,1,1,1,1,1,1,1,1,1
1,2,1,1,1,2,1,1,1,2,1,1,1,2,1,1,1,2,1
1,1,1,1,1,1,1,1,1,1,1,1,1,1,1,1,1,1,1
1,1,1,1,1,1,1,1,1,1,1,1,1,1,1,1,1,1,1
1,1,1,1,1,1,1,1,1,1,1,1,1,1,1,1,1,1,1
1,2,1,1,1,2,1,1,1,2,1,1,1,2,1,1,1,2,1
1,1,1,1,1,1,1,1,1,1,1,1,1,1,1,1,1,1,1
endlayer

layer
1,1,1,1,1,1,1,1,1,1,1,1,1,1,1,1,1,1,1
1,2,1,1,1,2,1,1,1,2,1,1,1,2,1,1,1,2,1
3,1,1,1,1,1,1,1,1,1,1,1,1,1,1,1,1,1,1
4,1,1,1,1,1,1,1,1,1,1,1,1,1,1,1,1,1,1
1,1,1,1,1,1,1,1,1,1,1,1,1,1,1,1,1,1,1
1,2,1,1,1,2,1,1,1,2,1,1,1,2,1,1,1,2,1
1,1,1,1,1,1,1,1,1,1,1,1,1,1,1,1,1,1,1
1,1,1,1,1,1,1,1,1,1,1,1,1,1,1,1,1,1,1
1,1,1,1,1,1,1,1,1,1,1,1,1,1,1,1,1,1,1
1,2,1,1,1,2,1,1,1,2,1,1,1,2,1,1,1,2,1
1,1,1,1,1,1,1,1,1,1,1,1,1,1,1,1,1,1,1
1,1,1,1,1,1,1,1,1,1,1,1,1,1,1,1,1,1,5
1,1,1,1,1,1,1,1,1,1,1,1,1,1,1,1,1,1,6
1,2,1,1,1,2,1,1,1,2,1,1,1,2,1,1,1,2,1
1,1,1,1,1,1,1,1,1,1,1,1,1,1,1,1,1,1,1
endlayer

layer
1,3,1,1,1,3,1,1,1,3,1,1,1,3,1,1,1,3,1
3,2,1,1,1,2,1,1,1,2,1,1,1,2,1,1,1,2,7
4,1,1,1,1,1,1,1,1,1,1,1,1,1,1,1,1,1,1
0,1,1,1,1,1,1,1,1,1,1,1,1,1,1,1,1,1,1
1,1,1,1,1,1,1,1,1,1,1,1,1,1,1,1,1,1,1
8,2,1,1,1,2,1,1,1,2,1,1,1,2,1,1,1,2,7
1,1,1,1,1,1,1,1,1,1,1,1,1,1,1,1,1,1,1
1,1,1,1,1,1,1,1,1,1,1,1,1,1,1,1,1,1,1
1,1,1,1,1,1,1,1,1,1,1,1,1,1,1,1,1,1,1
8,2,1,1,1,2,1,1,1,2,1,1,1,2,1,1,1,2,7
1,1,1,1,1,1,1,1,1,1,1,1,1,1,1,1,1,1,0
1,1,1,1,1,1,1,1,1,1,1,1,1,1,1,1,1,1,0
1,1,1,1,1,1,1,1,1,1,1,1,1,1,1,1,1,1,5
8,2,1,1,1,2,1,1,1,2,1,1,1,2,1,1,1,2,6
1,6,1,1,1,6,1,1,1,6,1,1,1,6,1,1,1,6,1
endlayer

layer
9,9,3,3,3,9,3,3,3,9,3,3,3,9,3,3,3,9,9
4,2,10,10,10,2,10,10,10,2,10,10,10,2,10,10,10,2,9
0,11,12,12,12,11,12,12,12,9,12,12,12,11,12,12,12,11,7
0,11,12,12,12,11,12,12,12,9,12,12,12,11,12,12,12,11,7
0,11,12,12,12,11,12,12,12,9,12,12,12,11,12,12,12,11,7
9,2,10,10,10,2,10,10,10,2,9,9,9,2,9,9,9,2,9
8,11,12,12,12,9,12,12,12,11,12,12,12,11,12,12,12,11,7
8,11,12,12,12,9,12,12,12,11,12,12,12,11,12,12,12,11,7
8,11,12,12,12,9,12,12,12,11,12,12,12,11,12,12,12,11,7
9,2,9,9,9,9,9,9,9,2,9,9,9,2,10,10,10,2,9
8,11,12,12,12,9,12,12,12,11,12,12,12,11,12,12,12,11,0
8,11,12,12,12,9,12,12,12,11,12,12,12,11,12,12,12,11,0
8,11,12,12,12,9,12,12,12,11,12,12,12,11,12,12,12,11,0
9,2,10,10,10,2,10,10,10,2,10,10,10,2,10,10,10,2,5
9,9,6,6,6,9,6,6,6,9,6,6,6,9,6,6,6,9,9
endlayer

layer
13,13,13,13,13,13,0,0,0,0,0,0,0,0,0,0,0,0,13
0,0,0,0,0,2,9,9,9,2,9,9,9,2,9,9,9,2,0
0,0,0,0,0,9,0,0,0,0,0,0,0,9,14,14,14,9,0
0,0,0,0,0,17,0,16,16,16,16,16,0,15,0,0,0,9,0
0,0,0,0,0,9,0,0,0,0,0,16,0,9,0,0,0,9,0
0,2,9,9,9,2,9,19,9,2,0,16,0,2,18,0,0,2,0
0,9,0,0,0,0,0,0,0,9,0,16,0,9,20,0,0,9,0
0,9,0,0,22,0,22,0,0,9,0,16,0,9,21,0,0,9,0
0,9,0,24,13,13,13,23,0,9,0,16,3,9,0,0,0,9,0
0,2,0,0,25,0,25,0,0,2,0,16,4,2,9,9,9,2,0
0,9,26,0,0,0,0,0,0,9,0,16,0,9,0,0,0,0,0
0,9,20,0,0,0,0,0,0,17,0,16,0,15,0,0,0,0,0
0,9,18,28,18,27,18,18,18,9,0,0,0,9,0,0,0,0,0
0,2,9,9,9,2,9,9,9,2,9,9,9,2,0,0,0,0,0
13,0,0,0,0,0,0,0,0,0,0,0,0,13,13,13,13,13,13
endlayer

layer
0,0,0,0,0,0,0,0,0,0,0,0,0,0,0,0,0,0,0
0,0,0,0,0,2,9,29,9,2,9,29,9,2,9,29,9,2,0
0,0,0,0,0,9,0,0,0,0,0,0,0,9,0,0,0,9,0
0,0,0,0,0,31,0,0,0,0,0,0,0,30,0,0,0,29,0
0,0,0,0,0,9,0,0,0,0,0,0,0,9,0,0,0,9,0
0,2,9,29,9,2,9,31,9,2,0,0,0,2,32,0,0,2,0
0,9,0,0,0,0,0,0,0,9,0,0,0,9,0,0,0,9,0
0,29,0,0,0,0,0,0,0,9,0,0,3,9,32,0,0,29,0
0,9,0,0,16,16,16,0,0,9,0,0,4,9,0,0,0,9,0
0,2,0,0,0,0,0,0,0,2,0,0,0,2,9,29,9,2,0
0,9,0,0,0,0,0,0,0,9,0,0,0,9,0,0,0,0,0
0,29,0,0,0,0,0,0,0,31,0,0,0,31,0,0,0,0,0
0,9,0,0,0,27,0,0,0,9,0,0,0,9,0,0,0,0,0
0,2,9,29,9,2,9,29,9,2,9,29,9,2,0,0,0,0,0
0,0,0,0,0,0,0,0,0,0,0,0,0,0,0,0,0,0,0
endlayer

layer
0,0,0,0,0,3,0,0,0,3,0,0,0,3,0,0,0,3,0
0,0,0,0,8,2,9,9,9,2,9,9,9,2,9,9,9,2,7
0,0,0,0,0,9,0,0,0,0,0,0,0,9,0,0,0,9,0
0,0,0,0,0,9,0,0,0,0,0,0,0,9,0,0,0,9,0
0,3,0,0,0,9,0,0,0,0,0,0,0,9,0,0,0,9,0
8,2,9,9,9,2,9,9,9,2,0,0,0,2,0,0,0,2,7
0,9,0,0,0,0,0,0,0,9,0,0,3,9,0,0,0,9,0
0,9,0,0,0,0,0,0,0,9,0,0,4,9,0,0,0,9,0
0,9,0,0,0,0,0,0,0,9,0,0,0,9,0,0,0,9,0
8,2,0,0,0,0,0,0,0,2,0,0,0,2,9,9,9,2,7
0,9,0,0,0,0,0,0,0,9,0,0,0,9,0,0,0,6,0
0,9,0,0,0,0,0,0,0,9,0,0,0,9,0,0,0,0,0
0,9,0,0,0,0,0,0,0,9,0,0,0,9,0,0,0,0,0
8,2,9,9,9,2,9,9,9,2,9,9,9,2,7,0,0,0,0
0,6,0,0,0,6,0,0,0,6,0,0,0,6,0,0,0,0,0
endlayer

layer
0,0,0,0,9,9,3,3,3,9,3,3,3,9,3,3,3,9,9
0,0,0,0,9,2,10,10,10,2,10,10,10,2,10,10,10,2,9
0,0,0,0,8,11,9,9,9,9,9,9,9,9,9,9,9,11,7
0,0,0,0,8,11,9,9,9,9,9,9,9,9,9,9,9,11,7
9,9,3,3,3,11,9,9,9,9,9,9,9,9,9,9,9,11,7
9,2,10,10,10,2,9,9,9,2,9,9,9,9,9,9,9,2,9
8,11,9,9,9,9,9,9,9,9,9,9,4,11,9,9,9,11,7
8,11,9,9,9,9,9,9,9,9,9,9,0,11,9,9,9,11,7
8,11,9,9,9,9,9,9,9,9,9,9,0,11,9,9,9,11,7
9,2,9,9,9,9,9,9,9,33,9,9,0,2,10,10,10,2,9
8,11,9,9,9,9,9,9,9,9,9,9,3,11,6,6,6,9,9
8,11,9,9,9,9,9,9,9,9,9,9,9,11,7,0,0,0,0
8,11,9,9,9,9,9,9,9,9,9,9,9,11,7,0,0,0,0
9,2,10,10,10,2,9,10,10,2,10,10,10,2,9,0,0,0,0
9,9,6,6,6,9,6,6,6,9,6,6,6,9,9,0,0,0,0
endlayer

layer
0,0,0,0,13,0,0,0,0,0,0,0,0,13,13,13,13,13,13
0,0,0,0,0,2,9,9,9,2,9,9,9,2,0,0,0,0,13
0,0,0,0,0,9,35,34,0,9,0,0,0,9,0,0,0,0,13
0,0,0,0,0,9,13,0,0,17,0,16,0,15,0,0,0,0,13
13,0,0,0,0,9,0,0,36,9,0,16,0,9,0,0,0,0,13
0,2,9,9,9,2,9,9,9,2,0,16,0,2,0,0,0,0,13
0,9,13,0,0,9,9,9,37,0,0,16,0,9,0,0,0,0,13
0,9,35,34,0,17,0,16,16,16,16,16,0,9,0,0,0,0,13
0,9,13,0,0,9,0,0,0,0,0,0,0,9,0,0,0,0,13
13,2,9,9,9,2,9,19,9,2,9,19,9,2,0,0,0,0,13
13,0,0,0,0,0,0,0,0,9,0,0,13,9,13,13,13,13,13
13,0,0,0,0,0,0,0,0,9,0,0,13,9,0,0,0,0,0
13,0,0,0,0,0,0,0,0,9,35,34,0,9,0,0,0,0,0
13,2,0,0,0,2,0,38,7,2,9,9,9,2,0,0,0,0,0
13,13,13,13,13,13,13,13,13,13,0,0,0,0,13,0,0,0,0
endlayer

layer
0,0,0,0,0,0,0,0,0,0,0,0,0,0,0,0,0,0,0
0,0,0,0,0,2,9,29,9,2,9,29,9,2,0,0,0,0,0
0,0,0,0,0,9,0,0,0,9,0,0,0,9,0,0,0,0,0
0,0,0,0,0,29,16,0,0,31,0,0,0,31,0,0,0,0,0
0,0,0,0,0,9,0,0,36,9,0,0,0,9,0,0,0,0,0
0,2,9,29,9,2,9,9,9,2,0,0,0,2,0,0,0,0,0
0,9,16,0,39,9,9,37,0,0,0,0,0,9,0,0,0,0,0
0,29,0,0,0,31,0,0,0,0,0,0,0,29,0,0,0,0,0
0,9,16,0,0,9,0,0,0,0,0,0,0,9,0,0,0,0,0
0,2,9,29,9,2,9,31,9,2,9,31,9,2,0,0,0,0,0
0,0,0,0,0,0,0,0,0,9,0,0,16,9,0,0,0,0,0
0,0,0,0,0,0,0,0,0,29,0,0,16,29,0,0,0,0,0
0,0,0,0,0,0,0,0,0,9,0,0,0,9,0,0,0,0,0
0,2,0,0,0,2,0,0,38,2,9,29,9,2,0,0,0,0,0
0,0,0,0,0,0,0,0,0,0,0,0,0,0,0,0,0,0,0
endlayer

layer
0,0,0,0,0,3,0,0,0,3,0,0,0,3,0,0,0,0,0
0,0,0,0,8,2,9,9,9,2,9,9,9,2,7,0,0,0,0
0,0,0,0,0,9,0,0,0,9,0,0,0,9,0,0,0,0,0
0,0,0,0,0,9,0,0,0,9,0,0,0,9,0,0,0,0,0
0,3,0,0,0,9,0,0,36,9,0,0,0,9,0,0,0,0,0
8,2,9,9,9,2,9,9,9,2,0,0,0,2,7,0,0,0,0
0,9,0,0,0,9,37,0,0,0,0,0,0,9,0,0,0,0,0
0,9,0,0,39,9,0,0,0,0,0,0,0,9,0,0,0,0,0
0,9,0,0,0,9,0,0,0,0,0,0,39,9,0,0,0,0,0
8,2,9,9,9,2,9,9,9,2,9,9,9,2,7,0,0,0,0
0,0,0,0,0,0,0,0,0,9,0,0,0,9,0,0,0,0,0
0,0,0,0,0,0,0,0,0,9,0,0,0,9,0,0,0,0,0
0,0,0,0,0,0,0,0,0,9,0,0,0,9,0,0,0,0,0
8,2,0,0,0,2,0,0,0,38,9,9,9,2,7,0,0,0,0
0,6,0,0,0,6,0,0,0,6,0,0,0,6,0,0,0,0,0
endlayer

layer
0,0,0,0,9,9,3,3,3,9,3,3,3,9,9,0,0,0,0
0,0,0,0,9,2,10,10,10,2,10,10,10,2,9,0,0,0,0
0,0,0,0,8,11,9,9,9,9,9,9,9,11,7,0,0,0,0
0,0,0,0,8,11,9,9,9,9,9,9,9,11,7,0,0,0,0
9,9,3,3,3,11,9,9,9,9,9,9,9,11,7,0,0,0,0
9,2,10,10,10,2,10,10,10,33,9,9,9,2,9,0,0,0,0
8,11,9,9,9,37,0,0,0,9,9,9,9,11,7,0,0,0,0
8,11,9,9,9,9,9,9,9,9,9,9,9,11,7,0,0,0,0
8,11,9,9,9,9,9,9,9,9,9,9,9,11,7,0,0,0,0
9,2,10,9,10,2,10,10,10,2,9,9,9,2,9,0,0,0,0
8,11,9,9,9,11,9,9,9,9,9,9,9,11,7,0,0,0,0
8,11,9,9,9,11,9,9,9,9,9,9,9,11,7,0,0,0,0
8,11,9,9,9,11,9,9,9,9,9,9,9,11,7,0,0,0,0
9,2,10,10,10,2,0,0,0,0,38,10,10,2,9,0,0,0,0
9,9,6,6,6,9,6,6,6,9,6,6,6,9,9,0,0,0,0
endlayer

layer
0,0,0,0,13,13,13,13,13,13,13,13,13,13,13,0,0,0,0
0,0,0,0,13,0,0,0,0,0,0,0,0,0,13,0,0,0,0
0,0,0,0,13,0,0,0,0,0,0,0,0,0,13,0,0,0,0
0,0,0,0,13,0,0,0,0,0,0,0,0,0,13,0,0,0,0
13,0,0,0,13,0,0,0,0,0,0,0,0,0,13,0,0,0,0
0,2,9,9,9,2,9,9,9,2,0,0,0,0,13,0,0,0,0
0,9,0,0,0,0,0,0,0,9,0,0,0,0,13,0,0,0,0
0,9,0,16,16,16,16,16,0,15,0,0,0,0,13,0,0,0,0
0,9,40,0,0,0,0,0,0,9,0,0,0,0,13,0,0,0,0
0,2,9,19,9,2,9,9,9,2,0,0,0,0,13,0,0,0,0
0,9,0,0,39,9,0,0,0,0,0,0,0,0,13,0,0,0,0
0,9,28,0,0,9,0,0,0,0,0,0,0,0,13,0,0,0,0
0,9,26,28,28,9,0,0,0,0,0,0,0,0,13,0,0,0,0
0,2,9,9,9,2,0,0,0,0,0,0,0,0,13,0,0,0,0
13,0,0,0,0,13,13,13,13,13,13,13,13,13,13,0,0,0,0
endlayer

layer
0,0,0,0,0,0,0,0,0,0,0,0,0,0,0,0,0,0,0
0,0,0,0,0,0,0,0,0,0,0,0,0,0,0,0,0,0,0
0,0,0,0,0,0,0,0,0,0,0,0,0,0,0,0,0,0,0
0,0,0,0,0,0,0,0,0,0,0,0,0,0,0,0,0,0,0
0,0,0,0,0,0,0,0,0,0,0,0,0,0,0,0,0,0,0
0,2,9,29,9,2,9,29,9,2,0,0,0,0,0,0,0,0,0
0,9,0,0,0,0,0,0,0,9,0,0,0,0,0,0,0,0,0
0,29,0,0,0,0,0,0,0,31,0,0,0,0,0,0,0,0,0
0,9,40,0,0,0,0,0,0,9,0,0,0,0,0,0,0,0,0
0,2,9,30,9,2,9,29,9,2,0,0,0,0,0,0,0,0,0
0,9,0,0,0,9,0,0,0,0,0,0,0,0,0,0,0,0,0
0,29,0,0,0,29,0,0,0,0,0,0,0,0,0,0,0,0,0
0,9,39,0,28,9,0,0,0,0,0,0,0,0,0,0,0,0,0
0,2,9,29,9,2,0,0,0,0,0,0,0,0,0,0,0,0,0
0,0,0,0,0,0,0,0,0,0,0,0,0,0,0,0,0,0,0
endlayer

layer
0,0,0,0,0,0,0,0,0,0,0,0,0,0,0,0,0,0,0
0,0,0,0,0,0,0,0,0,0,0,0,0,0,0,0,0,0,0
0,0,0,0,0,0,0,0,0,0,0,0,0,0,0,0,0,0,0
0,0,0,0,0,0,0,0,0,0,0,0,0,0,0,0,0,0,0
0,3,0,0,0,3,0,0,0,3,0,0,0,0,0,0,0,0,0
8,2,9,9,9,2,9,9,9,2,7,0,0,0,0,0,0,0,0
0,9,39,0,0,0,0,0,0,9,0,0,0,0,0,0,0,0,0
0,9,0,39,0,0,0,0,0,9,0,0,0,0,0,0,0,0,0
0,9,40,0,0,0,0,0,39,9,0,0,0,0,0,0,0,0,0
8,2,9,9,9,2,9,9,9,2,7,0,0,0,0,0,0,0,0
0,9,0,0,0,9,0,0,0,6,0,0,0,0,0,0,0,0,0
0,9,39,0,0,9,0,0,0,0,0,0,0,0,0,0,0,0,0
0,9,0,39,0,9,0,0,0,0,0,0,0,0,0,0,0,0,0
8,2,9,9,9,2,7,0,0,0,0,0,0,0,0,0,0,0,0
0,6,0,0,0,6,0,0,0,0,0,0,0,0,0,0,0,0,0
endlayer

layer
0,0,0,0,0,0,0,0,0,0,0,0,0,0,0,0,0,0,0
0,0,0,0,0,0,0,0,0,0,0,0,0,0,0,0,0,0,0
0,0,0,0,0,0,0,0,0,0,0,0,0,0,0,0,0,0,0
0,0,0,0,0,0,0,0,0,0,0,0,0,0,0,0,0,0,0
9,9,3,3,3,9,3,3,3,9,9,0,0,0,0,0,0,0,0
9,2,10,10,10,2,10,10,10,2,9,0,0,0,0,0,0,0,0
8,11,9,9,9,9,9,9,9,11,7,0,0,0,0,0,0,0,0
8,11,9,9,9,9,9,9,9,11,7,0,0,0,0,0,0,0,0
8,11,40,9,9,9,9,9,9,11,7,0,0,0,0,0,0,0,0
9,2,9,9,9,2,10,10,10,2,9,0,0,0,0,0,0,0,0
8,11,9,9,9,11,6,6,6,9,9,0,0,0,0,0,0,0,0
8,11,9,9,9,11,7,0,0,0,0,0,0,0,0,0,0,0,0
8,11,9,9,9,11,7,0,0,0,0,0,0,0,0,0,0,0,0
9,2,10,10,10,2,9,0,0,0,0,0,0,0,0,0,0,0,0
9,9,6,6,6,9,9,0,0,0,0,0,0,0,0,0,0,0,0
endlayer

layer
0,0,0,0,0,0,0,0,0,0,0,0,0,0,0,0,0,0,0
0,0,0,0,0,0,0,0,0,0,0,0,0,0,0,0,0,0,0
0,0,0,0,0,0,0,0,0,0,0,0,0,0,0,0,0,0,0
0,0,0,0,0,0,0,0,0,0,0,0,0,0,0,0,0,0,0
13,13,13,13,13,13,13,13,13,13,13,0,0,0,0,0,0,0,0
13,0,0,0,0,0,0,0,0,0,13,0,0,0,0,0,0,0,0
13,0,0,0,0,0,0,0,0,0,13,0,0,0,0,0,0,0,0
13,0,0,0,0,0,0,0,0,0,13,0,0,0,0,0,0,0,0
13,0,41,0,0,0,0,0,0,0,13,0,0,0,0,0,0,0,0
13,0,0,0,0,0,0,0,0,0,13,0,0,0,0,0,0,0,0
13,0,0,0,0,0,13,13,13,13,13,0,0,0,0,0,0,0,0
13,0,0,0,0,0,13,0,0,0,0,0,0,0,0,0,0,0,0
13,0,0,0,0,0,13,0,0,0,0,0,0,0,0,0,0,0,0
13,0,0,0,0,0,13,0,0,0,0,0,0,0,0,0,0,0,0
13,13,13,13,13,13,13,0,0,0,0,0,0,0,0,0,0,0,0
endlayer

