
# Created by Ruins mod version 16.7 Ingame Parser
# authoring Player: lafuller

weight=1
embed_into_distance=13
acceptable_target_blocks=water,waterlily
unacceptable_target_blocks=
biomesToSpawnIn=swampland,jungle,marsh,bog,wetland,mini_jungle,lush_swamp,green_swamp,dead_swamp,tropical_island,land_of_lakes
dimensions=26,10,10
allowable_overhang=0
max_leveling=2
leveling_buffer=-1
preserve_water=0
preserve_lava=0

rule1=0,100,preserveBlock
rule2=0,100,minecraft:log2-1
rule3=0,100,minecraft:log2-9
rule4=0,100,minecraft:log2-5
rule5=0,100,minecraft:spruce_fence-0
rule6=0,100,minecraft:ladder-5
rule7=0,100,minecraft:spruce_stairs-4
rule8=0,100,minecraft:oak_stairs-4
rule9=0,100,minecraft:wooden_slab-8
rule10=0,100,minecraft:oak_stairs-7
rule11=0,100,minecraft:double_wooden_slab-0
rule12=0,100,minecraft:oak_stairs-5
rule13=0,100,minecraft:spruce_fence_gate-4
rule14=0,100,minecraft:double_wooden_slab-1
rule15=0,100,minecraft:oak_stairs-2
rule16=0,100,minecraft:wooden_slab-1
rule17=0,100,minecraft:trapdoor-7
rule18=0,100,minecraft:spruce_stairs-3
rule19=0,100,minecraft:planks-0
rule20=0,100,minecraft:oak_stairs-6
rule21=0,100,minecraft:wooden_slab-9
rule22=0,100,minecraft:spruce_stairs-7
rule23=0,100,minecraft:spruce_fence_gate-3
rule24=0,100,minecraft:spruce_fence_gate-0
rule25=0,100,minecraft:spruce_fence_gate-2
rule26=0,100,minecraft:oak_stairs-3
rule27=0,100,minecraft:wooden_slab-0
rule28=0,100,minecraft:spruce_fence_gate-5
rule29=0,100,minecraft:spruce_stairs-6
rule30=0,100,minecraft:spruce_fence_gate-1
rule31=0,100,minecraft:spruce_stairs-0
rule32=0,100,minecraft:dark_oak_stairs-6
rule33=0,100,minecraft:dark_oak_stairs-7
rule34=0,100,minecraft:wooden_slab-11
rule35=0,100,minecraft:dark_oak_stairs-3
rule36=0,100,minecraft:spruce_stairs-2
rule37=0,100,minecraft:planks-5
rule38=0,100,minecraft:spruce_stairs-5
rule39=0,100,minecraft:dark_oak_stairs-5
rule40=0,100,minecraft:dark_oak_stairs-4
rule41=0,100,minecraft:dark_oak_stairs-0
rule42=0,100,minecraft:dark_oak_stairs-2
rule43=0,100,minecraft:trapdoor-13
rule44=0,100,minecraft:bookshelf-0
rule45=0,100,minecraft:double_wooden_slab-5
rule46=0,100,minecraft:dark_oak_fence-0
rule47=0,100,minecraft:trapdoor-10
rule48=0,100,minecraft:wooden_slab-5
rule49=0,100,minecraft:spruce_fence_gate-6
rule50=0,100,minecraft:carpet-7
rule51=0,100,minecraft:dark_oak_stairs-1
rule52=0,100,minecraft:wooden_slab-13
rule53=0,100,minecraft:spruce_stairs-1
rule54=0,100,minecraft:trapdoor-9

layer
1,1,1,1,1,1,1,1,1,1
1,1,1,1,1,1,1,1,1,1
1,1,1,1,1,1,2,1,1,1
1,1,2,1,1,1,1,1,1,1
1,1,1,1,1,1,1,1,1,1
1,1,1,1,1,1,1,1,1,1
1,1,1,1,1,1,1,2,1,1
1,1,1,2,1,1,1,1,1,1
1,1,1,1,1,1,1,1,1,1
1,1,1,1,1,1,1,1,1,1
endlayer

layer
1,1,1,1,1,1,1,1,1,1
1,1,1,1,1,1,1,1,1,1
1,1,1,1,1,1,2,1,1,1
1,1,2,1,1,1,1,1,1,1
1,1,1,1,1,1,1,1,1,1
1,1,1,1,1,1,1,1,1,1
1,1,1,1,1,1,1,2,1,1
1,1,1,2,1,1,1,1,1,1
1,1,1,1,1,1,1,1,1,1
1,1,1,1,1,1,1,1,1,1
endlayer

layer
1,1,1,1,1,1,1,1,1,1
1,1,1,1,1,1,1,1,1,1
1,1,1,1,1,1,2,1,1,1
1,1,2,1,1,1,1,1,1,1
1,1,1,1,1,1,1,1,1,1
1,1,1,1,1,1,1,1,1,1
1,1,1,1,1,1,1,2,1,1
1,1,1,2,1,1,1,1,1,1
1,1,1,1,1,1,1,1,1,1
1,1,1,1,1,1,1,1,1,1
endlayer

layer
1,1,1,1,1,1,1,1,1,1
1,1,1,1,1,1,1,1,1,1
1,1,1,1,1,1,2,1,1,1
1,1,2,1,1,1,1,1,1,1
1,1,1,1,1,1,1,1,1,1
1,1,1,1,1,1,1,1,1,1
1,1,1,1,1,1,1,2,1,1
1,1,1,2,1,1,1,1,1,1
1,1,1,1,1,1,1,1,1,1
1,1,1,1,1,1,1,1,1,1
endlayer

layer
1,1,1,1,1,1,1,1,1,1
1,1,1,1,1,1,1,1,1,1
1,1,1,1,1,1,2,1,1,1
1,1,2,1,1,1,1,1,1,1
1,1,1,1,1,1,1,1,1,1
1,1,1,1,1,1,1,1,1,1
1,1,1,1,1,1,1,2,1,1
1,1,1,2,1,1,1,1,1,1
1,1,1,1,1,1,1,1,1,1
1,1,1,1,1,1,1,1,1,1
endlayer

layer
1,1,1,1,1,1,1,1,1,1
1,1,1,1,1,1,1,1,1,1
1,1,1,1,1,1,2,1,1,1
1,1,2,1,1,1,1,1,1,1
1,1,1,1,1,1,1,1,1,1
1,1,1,1,1,1,1,1,1,1
1,1,1,1,1,1,1,2,1,1
1,1,1,2,1,1,1,1,1,1
1,1,1,1,1,1,1,1,1,1
1,1,1,1,1,1,1,1,1,1
endlayer

layer
1,1,1,1,1,1,1,1,1,1
1,1,1,1,1,1,1,1,1,1
1,1,1,1,1,1,2,1,1,1
1,1,2,1,1,1,1,1,1,1
1,1,1,1,1,1,1,1,1,1
1,1,1,1,1,1,1,1,1,1
1,1,1,1,1,1,1,2,1,1
1,1,1,2,1,1,1,1,1,1
1,1,1,1,1,1,1,1,1,1
1,1,1,1,1,1,1,1,1,1
endlayer

layer
1,1,1,1,1,1,1,1,1,1
1,1,1,1,1,1,1,1,1,1
1,1,1,1,1,1,2,1,1,1
1,1,2,1,1,1,1,1,1,1
1,1,1,1,1,1,1,1,1,1
1,1,1,1,1,1,1,1,1,1
1,1,1,1,1,1,1,2,1,1
1,1,1,2,1,1,1,1,1,1
1,1,1,1,1,1,1,1,1,1
1,1,1,1,1,1,1,1,1,1
endlayer

layer
1,1,1,1,1,1,1,1,1,1
1,1,1,1,1,1,1,1,1,1
1,1,1,1,1,1,2,1,1,1
1,1,2,1,1,1,1,1,1,1
1,1,1,1,1,1,1,1,1,1
1,1,1,1,1,1,1,1,1,1
1,1,1,1,1,1,1,2,1,1
1,1,1,2,1,1,1,1,1,1
1,1,1,1,1,1,1,1,1,1
1,1,1,1,1,1,1,1,1,1
endlayer

layer
1,1,1,1,1,1,1,1,1,1
1,1,1,1,1,1,1,1,1,1
1,1,1,1,1,1,2,1,1,1
1,1,2,1,1,1,1,1,1,1
1,1,1,1,1,1,1,1,1,1
1,1,1,1,1,1,1,1,1,1
1,1,1,1,1,1,1,2,1,1
1,1,1,2,1,1,1,1,1,1
1,1,1,1,1,1,1,1,1,1
1,1,1,1,1,1,1,1,1,1
endlayer

layer
1,1,1,1,1,1,1,1,1,1
1,1,1,1,1,1,1,1,1,1
1,1,1,1,1,1,2,1,1,1
1,1,2,1,1,1,1,1,1,1
1,1,1,1,1,1,1,1,1,1
1,1,1,1,1,1,1,1,1,1
1,1,1,1,1,1,1,2,1,1
1,1,3,3,3,3,3,3,3,1
1,1,1,1,1,1,1,1,1,1
1,1,1,1,1,1,1,1,1,1
endlayer

layer
1,1,1,1,1,1,1,1,1,1
1,1,1,1,1,1,4,1,1,1
1,1,1,1,1,1,4,1,1,1
1,1,2,1,1,1,4,1,1,1
1,3,3,3,3,3,3,3,3,1
1,1,1,1,1,1,4,1,1,1
1,1,1,1,1,1,4,2,1,1
1,1,1,2,1,1,4,1,1,1
1,1,1,1,1,1,4,1,1,1
1,1,1,1,1,1,1,1,1,1
endlayer

layer
1,1,1,1,1,1,1,1,1,1
1,1,1,4,1,1,1,1,1,1
1,1,1,4,1,1,2,1,1,1
1,1,2,4,1,1,1,1,1,1
1,1,1,4,1,1,2,1,1,1
1,1,1,4,1,1,1,1,1,1
1,1,1,4,1,1,1,2,1,1
1,1,1,4,1,1,2,1,1,1
1,1,1,4,1,1,1,1,1,1
1,1,1,1,1,1,1,1,1,1
endlayer

layer
1,1,1,1,1,1,1,5,1,1
1,1,1,1,1,1,1,4,1,1
1,1,1,1,1,1,2,4,1,1
1,1,2,1,1,1,1,4,1,1
1,1,6,1,1,1,2,4,1,1
1,1,1,1,1,1,1,4,1,1
1,1,1,1,1,1,1,4,1,1
1,1,1,2,1,1,2,4,1,1
1,1,1,1,1,1,1,4,1,1
1,1,1,1,1,1,1,5,1,1
endlayer

layer
1,1,1,1,1,1,1,1,1,1
1,1,1,1,1,1,1,1,1,1
1,1,1,1,1,1,2,1,1,1
5,3,3,3,3,3,3,3,3,5
1,1,6,1,1,1,2,5,1,1
1,1,1,1,1,1,5,1,1,1
1,5,3,3,3,3,3,3,3,5
1,1,1,2,1,1,2,5,5,1
1,1,1,1,1,1,1,5,5,1
1,1,1,1,1,1,1,1,1,1
endlayer

layer
1,1,1,1,1,1,5,1,1,1
1,1,1,5,1,1,4,1,1,1
1,1,1,4,1,1,4,1,1,1
1,1,2,4,8,8,4,7,1,1
1,1,6,4,9,9,4,9,1,1
1,9,8,4,9,9,4,10,1,1
1,1,10,4,11,11,4,5,1,1
1,1,12,4,9,12,4,1,1,1
1,1,1,4,1,1,4,1,1,1
1,1,1,5,1,1,5,1,1,1
endlayer

layer
1,1,1,1,1,1,1,1,1,1
1,1,1,1,1,1,1,1,1,1
1,1,9,8,7,14,2,13,1,1
1,5,2,16,0,0,0,15,1,1
1,18,17,0,0,0,0,15,1,1
1,18,0,0,0,0,0,19,1,1
1,5,19,16,16,16,0,20,1,1
1,1,10,2,12,9,2,12,1,1
1,1,1,1,1,1,1,1,1,1
1,1,1,1,1,1,1,1,1,1
endlayer

layer
1,1,1,1,1,1,1,1,1,1
1,1,22,7,7,1,21,1,1,1
1,5,14,0,18,23,2,20,1,1
1,7,2,0,0,0,0,19,1,1
1,5,0,0,0,0,0,24,1,1
1,25,0,0,0,0,0,24,1,1
1,22,0,0,0,0,0,19,1,1
1,5,19,2,27,26,2,5,1,1
1,1,1,28,1,1,28,1,1,1
1,1,1,1,1,1,1,1,1,1
endlayer

layer
1,1,1,1,1,1,1,1,1,1
1,1,5,29,7,7,21,1,1,1
1,5,22,0,0,18,2,5,1,1
1,22,2,0,0,0,0,11,20,1
1,22,0,0,0,0,0,20,9,1
1,21,0,0,0,0,0,20,9,1
1,14,0,0,0,0,0,11,20,1
1,5,10,2,9,10,2,5,1,1
1,1,1,12,1,1,12,1,1,1
1,1,1,1,1,1,1,1,1,1
endlayer

layer
1,1,1,1,1,1,1,1,1,1
1,5,31,7,30,29,7,7,1,1
1,31,33,0,0,0,16,32,1,1
33,33,2,21,21,21,21,7,5,1
1,35,21,34,34,34,21,14,1,1
1,35,21,34,21,34,21,29,1,1
33,37,21,34,34,34,21,36,1,1
1,39,37,2,7,38,2,38,1,1
1,1,38,5,38,1,38,1,1,1
1,1,1,1,1,1,1,1,1,1
endlayer

layer
1,1,1,1,40,40,1,1,1,1
1,41,5,14,38,16,40,5,1,1
1,35,39,0,0,0,43,42,1,1
33,45,44,0,0,0,43,42,32,1
33,42,0,0,0,0,0,29,39,1
46,35,0,0,0,0,0,29,1,1
35,33,0,0,0,0,0,36,1,1
1,39,33,47,47,47,2,45,1,1
1,1,33,29,38,39,39,5,1,1
1,1,1,1,1,1,1,1,1,1
endlayer

layer
1,1,1,1,40,23,41,1,1,1
1,1,35,37,5,0,21,40,1,1
1,5,37,0,0,0,0,41,1,1
41,37,0,0,0,0,0,42,1,1
48,18,0,0,0,0,0,24,1,1
1,16,0,0,0,0,0,25,1,1
49,35,0,0,0,0,0,35,1,1
1,42,40,50,50,50,2,40,1,1
1,1,40,51,37,32,45,5,1,1
1,1,1,1,52,39,1,1,1,1
endlayer

layer
1,1,1,1,41,41,1,1,1,1
1,1,52,41,53,41,41,41,1,1
1,48,37,32,0,0,39,42,1,1
1,35,0,0,0,0,0,25,1,1
1,24,0,0,0,0,0,32,41,1
1,24,0,0,0,0,0,21,32,1
1,40,0,0,0,0,0,42,51,1
1,51,32,0,0,0,2,51,1,1
1,1,51,51,39,39,46,1,1,1
1,1,1,1,1,1,1,1,1,1
endlayer

layer
1,1,1,1,1,1,1,1,1,1
1,1,1,33,23,41,1,1,1,1
1,1,5,40,0,39,40,41,1,1
1,41,39,0,0,0,38,40,40,1
1,33,0,0,0,0,0,32,32,1
1,35,0,0,0,0,0,42,1,1
1,41,32,0,0,0,7,39,1,1
1,52,35,7,32,0,37,1,1,1
1,1,1,35,5,23,42,1,1,1
1,1,1,1,1,1,1,1,1,1
endlayer

layer
1,1,1,1,1,1,1,1,1,1
1,1,1,1,41,1,1,1,1,1
1,1,1,48,45,42,41,42,1,1
1,1,48,45,38,38,37,41,1,1
1,48,32,21,21,54,22,42,1,1
1,35,7,21,21,21,22,32,1,1
1,51,45,7,7,42,51,42,1,1
1,1,1,51,51,42,48,1,1,1
1,1,1,1,48,48,1,1,1,1
1,1,1,1,1,1,1,1,1,1
endlayer

layer
1,1,1,1,1,1,1,1,1,1
1,1,1,1,1,1,1,1,1,1
1,1,1,1,1,1,1,1,1,1
1,1,1,1,35,41,42,1,1,1
1,1,1,35,42,1,41,41,1,1
1,1,48,51,45,48,51,1,1,1
1,1,1,48,48,1,1,1,1,1
1,1,1,1,1,1,1,1,1,1
1,1,1,1,1,1,1,1,1,1
1,1,1,1,1,1,1,1,1,1
endlayer

