
# Created by Ruins mod version 16.7 Ingame Parser
# authoring Player: lafuller

weight=1
embed_into_distance=13
acceptable_target_blocks=water,waterlily
unacceptable_target_blocks=
biomesToSpawnIn=swampland,jungle,river,marsh,bog,wetland,mini_jungle,lush_swamp,green_swamp,dead_swamp,tropical_island,land_of_lakes
dimensions=23,12,11
allowable_overhang=0
max_leveling=2
leveling_buffer=-1
preserve_water=0
preserve_lava=0

rule1=0,100,air
rule2=0,100,preserveBlock
rule3=0,100,minecraft:log2-1
rule4=0,100,minecraft:log2-5
rule5=0,100,minecraft:log2-9
rule6=0,100,minecraft:spruce_fence-0
rule7=0,100,minecraft:ladder-4
rule8=0,100,minecraft:wooden_slab-9
rule9=0,100,minecraft:spruce_stairs-4
rule10=0,100,minecraft:spruce_stairs-6
rule11=0,100,minecraft:spruce_stairs-7
rule12=0,100,minecraft:spruce_stairs-5
rule13=0,100,minecraft:planks-1
rule14=0,100,minecraft:trapdoor-14
rule15=0,100,minecraft:oak_stairs-0
rule16=0,100,minecraft:oak_stairs-3
rule17=0,100,minecraft:oak_stairs-2
rule18=0,100,minecraft:oak_stairs-1
rule19=0,100,minecraft:fence-0
rule20=0,100,minecraft:wooden_slab-13
rule21=0,100,minecraft:dark_oak_stairs-2
rule22=0,100,minecraft:dark_oak_stairs-3
rule23=0,100,minecraft:wooden_slab-5
rule24=0,100,minecraft:dark_oak_stairs-0
rule25=0,100,minecraft:planks-5
rule26=0,100,minecraft:dark_oak_stairs-5
rule27=0,100,minecraft:dark_oak_stairs-4
rule28=0,100,minecraft:dark_oak_stairs-1
rule29=0,100,minecraft:dark_oak_stairs-6
rule30=0,100,minecraft:dark_oak_fence-0
rule31=0,100,minecraft:trapdoor-2

layer
2,2,2,2,2,2,2,2,2,2,2
2,2,2,2,2,2,2,2,2,2,2
2,2,2,3,2,2,2,2,2,2,2
2,2,2,2,2,2,3,2,2,2,2
2,2,3,2,2,2,2,2,3,2,2
2,2,2,2,2,2,2,2,2,2,2
2,2,2,2,2,2,2,2,2,2,2
2,2,2,3,2,2,2,2,3,2,2
2,2,2,2,2,2,3,2,2,2,2
2,2,2,2,2,2,2,2,2,2,2
2,2,2,2,2,2,2,2,2,2,2
2,2,2,2,2,2,2,2,2,2,2
endlayer

layer
2,2,2,2,2,2,2,2,2,2,2
2,2,2,2,2,2,2,2,2,2,2
2,2,2,3,2,2,2,2,2,2,2
2,2,2,2,2,2,3,2,2,2,2
2,2,3,2,2,2,2,2,3,2,2
2,2,2,2,2,2,2,2,2,2,2
2,2,2,2,2,2,2,2,2,2,2
2,2,2,3,2,2,2,2,3,2,2
2,2,2,2,2,2,3,2,2,2,2
2,2,2,2,2,2,2,2,2,2,2
2,2,2,2,2,2,2,2,2,2,2
2,2,2,2,2,2,2,2,2,2,2
endlayer

layer
2,2,2,2,2,2,2,2,2,2,2
2,2,2,2,2,2,2,2,2,2,2
2,2,2,3,2,2,2,2,2,2,2
2,2,2,2,2,2,3,2,2,2,2
2,2,3,2,2,2,2,2,3,2,2
2,2,2,2,2,2,2,2,2,2,2
2,2,2,2,2,2,2,2,2,2,2
2,2,2,3,2,2,2,2,3,2,2
2,2,2,2,2,2,3,2,2,2,2
2,2,2,2,2,2,2,2,2,2,2
2,2,2,2,2,2,2,2,2,2,2
2,2,2,2,2,2,2,2,2,2,2
endlayer

layer
2,2,2,2,2,2,2,2,2,2,2
2,2,2,2,2,2,2,2,2,2,2
2,2,2,3,2,2,2,2,2,2,2
2,2,2,2,2,2,3,2,2,2,2
2,2,3,2,2,2,2,2,3,2,2
2,2,2,2,2,2,2,2,2,2,2
2,2,2,2,2,2,2,2,2,2,2
2,2,2,3,2,2,2,2,3,2,2
2,2,2,2,2,2,3,2,2,2,2
2,2,2,2,2,2,2,2,2,2,2
2,2,2,2,2,2,2,2,2,2,2
2,2,2,2,2,2,2,2,2,2,2
endlayer

layer
2,2,2,2,2,2,2,2,2,2,2
2,2,2,2,2,2,2,2,2,2,2
2,2,2,3,2,2,2,2,2,2,2
2,2,2,2,2,2,3,2,2,2,2
2,2,3,2,2,2,2,2,3,2,2
2,2,2,2,2,2,2,2,2,2,2
2,2,2,2,2,2,2,2,2,2,2
2,2,2,3,2,2,2,2,3,2,2
2,2,2,2,2,2,3,2,2,2,2
2,2,2,2,2,2,2,2,2,2,2
2,2,2,2,2,2,2,2,2,2,2
2,2,2,2,2,2,2,2,2,2,2
endlayer

layer
2,2,2,2,2,2,2,2,2,2,2
2,2,2,2,2,2,2,2,2,2,2
2,2,2,3,2,2,2,2,2,2,2
2,2,2,2,2,2,3,2,2,2,2
2,2,3,2,2,2,2,2,3,2,2
2,2,2,2,2,2,2,2,2,2,2
2,2,2,2,2,2,2,2,2,2,2
2,2,2,3,2,2,2,2,3,2,2
2,2,2,2,2,2,3,2,2,2,2
2,2,2,2,2,2,2,2,2,2,2
2,2,2,2,2,2,2,2,2,2,2
2,2,2,2,2,2,2,2,2,2,2
endlayer

layer
2,2,2,2,2,2,2,2,2,2,2
2,2,2,2,2,2,2,2,2,2,2
2,2,2,3,2,2,2,2,2,2,2
2,2,2,2,2,2,3,2,2,2,2
2,2,3,2,2,2,2,2,3,2,2
2,2,2,2,2,2,2,2,2,2,2
2,2,2,2,2,2,2,2,2,2,2
2,2,2,3,2,2,2,2,3,2,2
2,2,2,2,2,2,3,2,2,2,2
2,2,2,2,2,2,2,2,2,2,2
2,2,2,2,2,2,2,2,2,2,2
2,2,2,2,2,2,2,2,2,2,2
endlayer

layer
2,2,2,2,2,2,2,2,2,2,2
2,2,2,2,2,2,2,2,2,2,2
2,2,2,3,2,2,2,2,2,2,2
2,2,2,2,2,2,3,2,2,2,2
2,2,3,2,2,2,2,2,3,2,2
2,2,2,2,2,2,2,2,2,2,2
2,2,2,2,2,2,2,2,2,2,2
2,2,2,3,2,2,2,2,3,2,2
2,2,2,2,2,2,3,2,2,2,2
2,2,2,2,2,2,2,2,2,2,2
2,2,2,2,2,2,2,2,2,2,2
2,2,2,2,2,2,2,2,2,2,2
endlayer

layer
2,2,2,2,2,2,2,2,2,2,2
2,2,2,2,2,2,2,2,2,2,2
2,2,2,3,2,2,2,2,2,2,2
2,2,2,2,2,2,3,2,2,2,2
2,2,3,2,2,2,2,2,3,2,2
2,2,2,2,2,2,2,2,2,2,2
2,2,2,2,2,2,2,2,2,2,2
2,2,2,3,2,2,2,2,3,2,2
2,2,2,2,2,2,3,2,2,2,2
2,2,2,2,2,2,2,2,2,2,2
2,2,2,2,2,2,2,2,2,2,2
2,2,2,2,2,2,2,2,2,2,2
endlayer

layer
2,2,2,2,2,2,2,2,2,2,2
2,2,2,2,2,2,2,2,2,2,2
2,2,2,3,2,2,2,2,2,2,2
2,2,2,2,2,2,3,2,2,2,2
2,2,3,2,2,2,2,2,3,2,2
2,2,2,2,2,2,2,2,2,2,2
2,2,2,2,2,2,2,2,2,2,2
2,2,2,3,2,2,2,2,3,2,2
2,2,2,2,2,2,3,2,2,2,2
2,2,2,2,2,2,2,2,2,2,2
2,2,2,2,2,2,2,2,2,2,2
2,2,2,2,2,2,2,2,2,2,2
endlayer

layer
2,2,2,2,2,2,2,2,2,2,2
2,2,2,2,2,2,2,2,2,2,2
2,2,2,3,2,2,4,2,2,2,2
2,2,2,2,2,2,4,2,2,2,2
2,2,3,2,2,2,4,2,3,2,2
2,2,2,2,2,2,4,2,2,2,2
2,2,2,2,2,2,4,2,2,2,2
2,2,2,3,2,2,4,2,3,2,2
2,2,2,2,2,2,4,2,2,2,2
2,2,2,2,2,2,4,2,2,2,2
2,2,2,2,2,2,2,2,2,2,2
2,2,2,2,2,2,2,2,2,2,2
endlayer

layer
2,2,2,2,2,2,2,2,2,2,2
2,2,2,2,2,2,2,2,2,2,2
2,2,2,3,2,2,3,2,2,2,2
2,5,5,5,5,5,5,5,5,5,2
2,2,3,2,2,2,2,2,3,2,2
2,2,2,2,2,2,2,2,2,2,2
2,2,2,2,2,2,2,2,2,2,2
2,2,2,3,2,2,2,2,3,2,2
2,2,2,2,2,2,3,2,2,2,2
2,2,2,2,2,2,2,2,2,2,2
2,2,2,2,2,2,2,2,2,2,2
2,2,2,2,2,2,2,2,2,2,2
endlayer

layer
2,2,2,2,2,2,2,2,2,2,2
2,2,2,4,2,2,2,2,2,2,2
2,2,2,4,2,2,3,2,4,2,2
2,2,2,4,2,2,2,2,4,2,2
2,2,3,4,2,2,2,2,4,2,2
2,2,2,4,2,2,2,2,4,2,2
2,2,2,4,2,2,2,2,4,2,2
2,2,5,4,5,5,5,5,5,5,2
2,2,2,4,2,2,3,2,4,2,2
2,2,2,2,2,2,2,2,2,2,2
2,2,2,2,2,2,2,2,2,2,2
2,2,2,2,2,2,2,2,2,2,2
endlayer

layer
2,2,2,2,2,2,6,2,2,2,2
2,2,2,3,2,2,4,2,2,2,2
2,2,2,2,2,2,4,2,2,2,2
2,2,2,2,2,2,4,2,3,2,2
6,5,5,5,5,5,4,5,5,5,6
2,2,2,2,2,2,4,2,2,2,2
2,2,2,2,2,2,4,2,7,2,2
2,2,3,2,2,2,4,2,3,2,2
2,2,2,2,2,2,4,2,2,2,2
2,2,2,2,2,2,4,2,2,2,2
2,2,2,2,2,2,4,2,2,2,2
2,2,2,2,2,2,6,2,2,2,2
endlayer

layer
2,2,6,2,2,2,2,2,2,2,2
2,2,4,3,2,2,2,2,2,2,2
2,2,4,2,2,2,3,2,2,2,2
2,2,4,2,2,2,2,2,3,2,2
2,3,4,2,2,2,2,2,2,2,2
2,2,4,2,2,2,2,2,2,2,2
2,2,4,2,2,2,2,2,7,2,2
2,2,4,2,2,2,2,2,3,2,2
6,5,5,5,5,5,5,5,5,5,6
2,2,4,2,2,2,3,2,2,2,2
2,2,6,2,2,2,2,2,2,2,2
2,2,2,2,2,2,2,2,2,2,2
endlayer

layer
2,2,8,8,8,6,2,6,2,2,2
2,8,11,3,10,4,9,4,8,8,2
6,5,5,5,5,5,3,5,5,5,6
8,9,13,8,8,4,12,4,12,5,8
8,3,8,8,8,4,8,4,10,12,8
8,12,8,8,8,4,8,4,8,8,8
8,8,9,8,8,4,8,4,14,8,8
2,11,3,8,8,4,8,4,3,10,8
2,8,8,13,13,4,9,4,13,8,2
2,2,8,8,11,4,3,4,10,8,2
2,2,2,8,8,4,12,4,8,2,2
2,2,2,2,2,6,2,6,2,2,2
endlayer

layer
2,2,2,2,2,2,2,2,2,2,2
2,2,1,3,15,15,6,2,2,2,2
2,2,16,1,1,1,3,15,15,6,2
2,2,15,1,1,1,1,1,1,3,2
2,3,1,1,1,1,1,1,1,17,2
2,16,1,1,1,1,1,1,1,17,2
2,16,1,1,1,1,1,1,1,17,2
2,1,3,1,1,1,1,1,3,6,2
2,2,1,18,18,16,1,1,17,2,2
2,2,2,2,2,6,3,18,2,2,2
2,2,2,2,2,2,2,2,2,2,2
2,2,2,2,2,2,2,2,2,2,2
endlayer

layer
2,2,2,2,2,2,2,2,2,2,2
2,2,6,3,1,19,19,2,2,2,2
2,2,19,1,1,1,3,19,1,6,2
2,2,1,1,1,1,1,1,1,3,2
2,3,1,1,1,1,1,1,1,19,2
2,1,1,1,1,1,1,1,1,1,2
2,19,1,1,1,1,1,1,1,19,2
2,6,3,1,1,1,1,1,3,6,2
2,2,6,19,1,19,1,1,19,2,2
2,2,2,2,2,6,3,19,2,2,2
2,2,2,2,2,2,2,2,2,2,2
2,2,2,2,2,2,2,2,2,2,2
endlayer

layer
2,2,20,2,2,2,2,2,2,2,2
2,2,9,3,9,9,10,2,2,2,2
2,2,11,1,1,1,3,9,9,10,20
2,2,9,1,1,1,1,1,1,3,2
2,3,1,1,1,1,1,1,1,10,2
2,11,1,1,1,1,1,1,1,10,2
2,11,1,1,1,1,1,1,1,10,2
2,12,3,1,1,1,1,1,3,12,2
2,20,11,12,12,11,1,1,12,2,2
2,2,2,2,2,2,3,10,2,2,2
2,2,2,2,2,2,2,2,2,2,2
2,2,2,2,2,2,2,2,2,2,2
endlayer

layer
2,2,2,22,20,20,21,2,2,2,2
2,23,24,3,13,13,25,24,20,23,2
2,26,13,1,1,1,3,13,13,21,2
2,20,13,1,1,1,1,1,1,3,23
24,3,1,1,1,1,1,1,1,13,26
20,13,1,1,1,1,1,1,1,13,20
20,13,1,1,1,1,1,1,1,13,27
28,28,3,1,1,1,1,1,3,28,23
2,2,22,13,13,13,1,1,13,21,2
2,2,23,29,20,26,3,13,20,2,2
2,2,2,2,20,20,26,28,2,2,2
2,2,2,2,2,2,2,2,2,2,2
endlayer

layer
2,2,2,2,2,2,2,2,2,2,2
2,2,2,24,25,24,23,2,2,2,2
2,2,22,10,12,12,25,25,24,2,2
2,23,25,12,8,8,11,12,12,21,2
2,22,10,8,8,8,8,8,11,25,2
2,25,10,8,8,2,8,8,11,25,2
2,22,10,8,8,8,8,8,11,21,2
2,2,25,9,9,10,8,9,25,2,2
2,2,2,28,25,25,9,11,21,2,2
2,2,2,2,22,25,28,28,2,2,2
2,2,2,2,2,23,2,2,2,2,2
2,2,2,2,2,2,2,2,2,2,2
endlayer

layer
2,2,2,2,2,2,2,2,2,2,2
2,2,2,2,2,2,2,2,2,2,2
2,2,2,23,22,24,23,2,2,2,2
2,2,2,22,25,25,25,24,23,2,2
2,2,24,25,25,25,25,25,21,2,2
2,2,22,25,25,30,25,25,21,2,2
2,2,22,25,25,25,25,25,28,2,2
2,2,2,28,25,25,25,21,2,2,2
2,2,2,2,2,23,23,23,2,2,2
2,2,2,2,2,2,2,2,2,2,2
2,2,2,2,2,2,2,2,2,2,2
2,2,2,2,2,2,2,2,2,2,2
endlayer

layer
2,2,2,2,2,2,2,2,2,2,2
2,2,2,2,2,2,2,2,2,2,2
2,2,2,2,2,2,2,2,2,2,2
2,2,2,2,30,30,30,2,2,2,2
2,2,2,30,23,23,30,30,2,2,2
2,2,2,30,23,31,23,30,2,2,2
2,2,2,30,30,23,23,30,2,2,2
2,2,2,2,30,30,30,2,2,2,2
2,2,2,2,2,2,2,2,2,2,2
2,2,2,2,2,2,2,2,2,2,2
2,2,2,2,2,2,2,2,2,2,2
2,2,2,2,2,2,2,2,2,2,2
endlayer

