
# Created by Ruins mod version 16.7 Ingame Parser
# authoring Player: lafuller

weight=1
embed_into_distance=13
acceptable_target_blocks=water,waterlily
unacceptable_target_blocks=
biomesToSpawnIn=swampland,jungle,marsh,bog,wetland,mini_jungle,lush_swamp,green_swamp,dead_swamp,tropical_island,land_of_lakes
dimensions=22,9,10
allowable_overhang=0
max_leveling=2
leveling_buffer=-1
preserve_water=0
preserve_lava=0

rule1=0,100,preserveBlock
rule2=0,100,minecraft:log2-1
rule3=0,100,minecraft:log2-5
rule4=0,100,minecraft:log2-9
rule5=0,100,minecraft:spruce_fence-0
rule6=0,100,minecraft:ladder-3
rule7=0,100,minecraft:spruce_stairs-6
rule8=0,100,minecraft:trapdoor-9
rule9=0,100,minecraft:trapdoor-8
rule10=0,100,minecraft:planks-1
rule11=0,100,minecraft:spruce_stairs-7
rule12=0,100,minecraft:wooden_slab-9
rule13=0,100,minecraft:spruce_stairs-4
rule14=0,100,minecraft:spruce_stairs-5
rule15=0,100,minecraft:spruce_stairs-0
rule16=0,100,minecraft:bookshelf-0
rule17=0,100,minecraft:spruce_stairs-3
rule18=0,100,minecraft:ladder-5
rule19=0,100,minecraft:wooden_slab-1
rule20=0,100,minecraft:trapdoor-6
rule21=0,100,minecraft:spruce_stairs-1
rule22=0,100,minecraft:planks-5
rule23=0,100,minecraft:crafting_table-0
rule24=0,100,minecraft:spruce_stairs-2
rule25=0,100,minecraft:spruce_fence_gate-2
rule26=0,100,minecraft:dark_oak_fence_gate-1
rule27=0,100,minecraft:dark_oak_stairs-4
rule28=0,100,minecraft:dark_oak_stairs-0
rule29=0,100,minecraft:carpet-7
rule30=0,100,minecraft:spruce_fence_gate-0
rule31=0,100,minecraft:dark_oak_stairs-1
rule32=0,100,minecraft:spruce_fence_gate-3
rule33=0,100,minecraft:dark_oak_stairs-7
rule34=0,100,minecraft:wooden_slab-13
rule35=0,100,minecraft:dark_oak_stairs-2
rule36=0,100,minecraft:dark_oak_stairs-5
rule37=0,100,minecraft:wooden_slab-5
rule38=0,100,minecraft:double_wooden_slab-5
rule39=0,100,minecraft:dark_oak_stairs-6
rule40=0,100,minecraft:dark_oak_stairs-3
rule41=0,100,minecraft:trapdoor-0

layer
1,1,1,1,1,1,1,1,1,1
1,1,1,1,1,1,1,1,1,1
1,1,2,1,1,1,1,1,1,1
1,1,1,1,1,1,2,1,1,1
1,1,1,1,1,1,1,1,1,1
1,1,1,1,1,1,1,1,1,1
1,1,2,1,1,1,2,1,1,1
1,1,1,1,1,1,1,1,1,1
1,1,1,1,1,1,1,1,1,1
endlayer

layer
1,1,1,1,1,1,1,1,1,1
1,1,1,1,1,1,1,1,1,1
1,1,2,1,1,1,1,1,1,1
1,1,1,1,1,1,2,1,1,1
1,1,1,1,1,1,1,1,1,1
1,1,1,1,1,1,1,1,1,1
1,1,2,1,1,1,2,1,1,1
1,1,1,1,1,1,1,1,1,1
1,1,1,1,1,1,1,1,1,1
endlayer

layer
1,1,1,1,1,1,1,1,1,1
1,1,1,1,1,1,1,1,1,1
1,1,2,1,1,1,1,1,1,1
1,1,1,1,1,1,2,1,1,1
1,1,1,1,1,1,1,1,1,1
1,1,1,1,1,1,1,1,1,1
1,1,2,1,1,1,2,1,1,1
1,1,1,1,1,1,1,1,1,1
1,1,1,1,1,1,1,1,1,1
endlayer

layer
1,1,1,1,1,1,1,1,1,1
1,1,1,1,1,1,1,1,1,1
1,1,2,1,1,1,1,1,1,1
1,1,1,1,1,1,2,1,1,1
1,1,1,1,1,1,1,1,1,1
1,1,1,1,1,1,1,1,1,1
1,1,2,1,1,1,2,1,1,1
1,1,1,1,1,1,1,1,1,1
1,1,1,1,1,1,1,1,1,1
endlayer

layer
1,1,1,1,1,1,1,1,1,1
1,1,1,1,1,1,1,1,1,1
1,1,2,1,1,1,1,1,1,1
1,1,1,1,1,1,2,1,1,1
1,1,1,1,1,1,1,1,1,1
1,1,1,1,1,1,1,1,1,1
1,1,2,1,1,1,2,1,1,1
1,1,1,1,1,1,1,1,1,1
1,1,1,1,1,1,1,1,1,1
endlayer

layer
1,1,1,1,1,1,1,1,1,1
1,1,1,1,1,1,1,1,1,1
1,1,2,1,1,1,1,1,1,1
1,1,1,1,1,1,2,1,1,1
1,1,1,1,1,1,1,1,1,1
1,1,1,1,1,1,1,1,1,1
1,1,2,1,1,1,2,1,1,1
1,1,1,1,1,1,1,1,1,1
1,1,1,1,1,1,1,1,1,1
endlayer

layer
1,1,1,1,1,1,1,1,1,1
1,1,1,1,1,1,1,1,1,1
1,1,2,1,1,1,1,1,1,1
1,1,1,1,1,1,2,1,1,1
1,1,1,1,1,1,1,1,1,1
1,1,1,1,1,1,1,1,1,1
1,1,2,1,1,1,2,1,1,1
1,1,1,1,1,1,1,1,1,1
1,1,1,1,1,1,1,1,1,1
endlayer

layer
1,1,1,1,1,1,1,1,1,1
1,1,1,1,1,1,1,1,1,1
1,1,2,1,1,1,1,1,1,1
1,1,1,1,1,1,2,1,1,1
1,1,1,1,1,1,1,1,1,1
1,1,1,1,1,1,1,1,1,1
1,1,2,1,1,1,2,1,1,1
1,1,1,1,1,1,1,1,1,1
1,1,1,1,1,1,1,1,1,1
endlayer

layer
1,1,1,1,1,1,1,1,1,1
1,1,1,1,1,1,1,1,1,1
1,1,2,1,1,1,1,1,1,1
1,1,1,1,1,1,2,1,1,1
1,1,1,1,1,1,1,1,1,1
1,1,1,1,1,1,1,1,1,1
1,1,2,1,1,1,2,1,1,1
1,1,1,1,1,1,1,1,1,1
1,1,1,1,1,1,1,1,1,1
endlayer

layer
1,1,1,1,1,1,1,1,1,1
1,1,1,1,1,1,1,1,1,1
1,1,2,1,1,1,1,1,1,1
1,1,1,1,1,1,2,1,1,1
1,1,1,1,1,1,1,1,1,1
1,1,1,1,1,1,1,1,1,1
1,1,2,1,1,1,2,1,1,1
1,1,1,1,1,1,1,1,1,1
1,1,1,1,1,1,1,1,1,1
endlayer

layer
1,1,1,1,1,1,1,1,1,1
1,1,1,3,1,1,1,1,1,1
1,1,2,3,1,1,1,1,1,1
1,1,1,3,1,1,2,1,1,1
1,1,1,3,1,1,1,1,1,1
1,1,1,3,1,1,1,1,1,1
1,1,2,3,1,1,2,1,1,1
1,1,1,1,1,1,1,1,1,1
1,1,1,1,1,1,1,1,1,1
endlayer

layer
1,1,1,1,1,1,1,1,1,1
1,1,1,1,1,1,1,1,1,1
1,4,4,4,4,4,4,4,4,1
1,1,1,1,1,1,2,1,1,1
1,1,1,1,1,1,1,1,1,1
1,4,4,4,4,4,4,4,4,1
1,1,2,1,1,1,2,1,1,1
1,1,1,1,1,1,1,1,1,1
1,1,1,1,1,1,1,1,1,1
endlayer

layer
1,1,1,1,1,1,1,1,1,1
1,1,3,1,1,1,1,3,1,1
1,1,3,1,1,1,2,3,1,1
1,1,3,1,1,1,2,3,1,1
1,1,3,1,1,1,1,3,1,1
1,1,3,1,1,1,2,3,1,1
1,1,3,1,1,1,2,3,1,1
1,1,3,1,1,1,1,3,1,1
1,1,1,1,1,1,1,1,1,1
endlayer

layer
1,1,1,1,1,1,1,1,1,1
1,1,1,1,1,1,1,1,1,1
1,1,2,1,1,1,2,1,1,1
5,4,4,4,4,4,4,4,4,5
1,1,1,1,1,1,1,1,1,1
1,1,1,1,1,1,2,2,1,1
5,4,4,4,1,1,4,4,4,5
1,1,1,1,1,1,1,1,1,1
1,1,1,1,1,1,1,1,1,1
endlayer

layer
1,1,1,5,1,1,5,1,1,1
1,1,5,3,1,1,3,1,1,1
1,1,2,3,5,5,3,5,1,1
1,1,5,3,1,1,3,5,1,1
1,1,5,3,1,1,3,5,1,1
1,1,5,3,1,6,3,2,5,1
1,1,2,3,1,1,3,5,5,1
1,1,5,3,1,1,3,1,1,1
1,1,1,5,1,1,5,1,1,1
endlayer

layer
1,1,1,1,1,1,1,1,1,1
1,1,1,5,5,5,2,5,1,1
1,5,2,4,4,4,4,4,5,1
1,11,10,7,9,8,7,5,1,1
1,1,10,7,9,8,7,5,5,1
1,12,10,13,12,6,7,2,5,1
1,1,2,5,14,14,14,5,1,1
1,1,5,5,1,1,1,1,1,1
1,1,1,1,1,1,1,1,1,1
endlayer

layer
1,1,1,1,1,1,1,1,1,1
1,1,5,13,15,15,2,1,1,1
1,13,2,0,0,10,16,7,1,1
1,17,0,0,0,18,0,17,7,1
1,19,0,0,0,0,0,17,7,1
1,17,0,0,0,20,0,2,5,1
1,19,2,10,21,10,14,7,1,1
1,1,1,19,19,1,1,1,1,1
1,1,1,1,1,1,1,1,1,1
endlayer

layer
1,1,1,1,1,1,1,1,1,1
1,1,11,13,21,13,2,5,1,1
1,1,2,0,0,10,23,22,5,1
1,5,0,0,0,18,8,8,21,1
1,25,0,0,0,0,8,8,24,1
1,5,0,0,0,0,8,2,24,1
1,5,2,24,19,19,17,5,5,1
1,1,1,1,1,1,1,5,1,1
1,1,1,1,1,1,1,1,1,1
endlayer

layer
1,1,1,1,1,1,1,1,1,1
1,1,27,5,26,5,2,5,1,1
1,5,2,0,0,0,29,22,28,1
1,11,0,0,0,0,29,29,5,1
1,11,0,0,0,0,29,29,30,1
1,11,0,0,0,0,29,2,5,1
1,33,2,5,32,32,5,3,31,1
1,1,5,1,1,1,34,3,5,1
1,1,1,1,1,1,1,5,1,1
endlayer

layer
1,1,1,1,1,1,1,1,1,1
1,1,37,28,36,35,28,35,1,1
1,37,22,0,0,0,0,38,27,1
1,37,22,0,0,0,0,0,39,1
1,37,39,0,0,0,0,0,39,1
1,37,22,0,0,0,0,2,39,1
1,1,40,22,27,27,22,40,36,1
1,1,37,38,31,35,31,35,1,1
1,1,1,1,1,1,1,1,1,1
endlayer

layer
1,1,1,1,1,1,1,1,1,1
1,1,1,1,1,1,1,1,1,1
1,1,1,40,28,28,35,37,1,1
1,1,40,34,12,12,34,35,1,1
1,1,40,12,12,0,12,35,1,1
1,1,31,34,34,12,12,35,1,1
1,1,1,37,40,31,31,35,1,1
1,1,1,1,1,1,1,1,1,1
1,1,1,1,1,1,1,1,1,1
endlayer

layer
1,1,1,1,1,1,1,1,1,1
1,1,1,1,1,1,1,1,1,1
1,1,1,1,1,1,1,1,1,1
1,1,1,1,37,37,1,1,1,1
1,1,1,37,37,41,37,1,1,1
1,1,1,1,37,37,37,1,1,1
1,1,1,1,1,1,1,1,1,1
1,1,1,1,1,1,1,1,1,1
1,1,1,1,1,1,1,1,1,1
endlayer

