
# Created by Ruins mod version 16.7 Ingame Parser
# authoring Player: lafuller

weight=1
embed_into_distance=13
acceptable_target_blocks=water,waterlily
unacceptable_target_blocks=
biomesToSpawnIn=swampland,jungle,marsh,bog,wetland,mini_jungle,lush_swamp,green_swamp,dead_swamp,tropical_island,land_of_lakes
dimensions=22,10,10
allowable_overhang=0
max_leveling=2
leveling_buffer=-1
preserve_water=0
preserve_lava=0

rule1=0,100,preserveBlock
rule2=0,100,minecraft:log2-1
rule3=0,100,minecraft:log2-9
rule4=0,100,minecraft:spruce_fence-0
rule5=0,100,minecraft:log2-5
rule6=0,100,minecraft:ladder-2
rule7=0,100,minecraft:wooden_slab-9
rule8=0,100,minecraft:spruce_stairs-4
rule9=0,100,minecraft:planks-1
rule10=0,100,minecraft:spruce_stairs-5
rule11=0,100,minecraft:spruce_stairs-2
rule12=0,100,minecraft:spruce_stairs-7
rule13=0,100,minecraft:spruce_stairs-6
rule14=0,100,minecraft:dark_oak_stairs-6
rule15=0,100,minecraft:dark_oak_stairs-0
rule16=0,100,minecraft:dark_oak_stairs-1
rule17=0,100,minecraft:dark_oak_stairs-5
rule18=0,100,minecraft:trapdoor-4
rule19=0,100,minecraft:spruce_stairs-1
rule20=0,100,minecraft:spruce_stairs-3
rule21=0,100,minecraft:wooden_slab-1
rule22=0,100,minecraft:spruce_stairs-0
rule23=0,100,minecraft:trapdoor-10
rule24=0,100,minecraft:dark_oak_stairs-7
rule25=0,100,minecraft:double_wooden_slab-1
rule26=0,100,minecraft:dark_oak_stairs-4
rule27=0,100,minecraft:spruce_fence_gate-0
rule28=0,100,minecraft:carpet-7
rule29=0,100,minecraft:double_wooden_slab-5
rule30=0,100,minecraft:dark_oak_fence-0
rule31=0,100,minecraft:spruce_fence_gate-3
rule32=0,100,minecraft:dark_oak_stairs-3
rule33=0,100,minecraft:dark_oak_stairs-2
rule34=0,100,minecraft:spruce_fence_gate-5
rule35=0,100,minecraft:wooden_slab-5
rule36=0,100,minecraft:planks-5
rule37=0,100,minecraft:wooden_slab-13

layer
1,1,1,1,1,1,1,1,1,1
1,1,1,1,1,1,1,1,1,1
1,1,1,1,1,1,1,1,1,1
1,1,2,1,1,1,1,2,1,1
1,1,1,1,1,1,1,1,1,1
1,1,1,1,1,1,1,1,1,1
1,1,1,1,1,1,1,1,1,1
1,1,2,1,1,1,1,2,1,1
1,1,1,1,1,1,1,1,1,1
1,1,1,1,1,1,1,1,1,1
endlayer

layer
1,1,1,1,1,1,1,1,1,1
1,1,1,1,1,1,1,1,1,1
1,1,1,1,1,1,1,1,1,1
1,1,2,1,1,1,1,2,1,1
1,1,1,1,1,1,1,1,1,1
1,1,1,1,1,1,1,1,1,1
1,1,1,1,1,1,1,1,1,1
1,1,2,1,1,1,1,2,1,1
1,1,1,1,1,1,1,1,1,1
1,1,1,1,1,1,1,1,1,1
endlayer

layer
1,1,1,1,1,1,1,1,1,1
1,1,1,1,1,1,1,1,1,1
1,1,1,1,1,1,1,1,1,1
1,1,2,1,1,1,1,2,1,1
1,1,1,1,1,1,1,1,1,1
1,1,1,1,1,1,1,1,1,1
1,1,1,1,1,1,1,1,1,1
1,1,2,1,1,1,1,2,1,1
1,1,1,1,1,1,1,1,1,1
1,1,1,1,1,1,1,1,1,1
endlayer

layer
1,1,1,1,1,1,1,1,1,1
1,1,1,1,1,1,1,1,1,1
1,1,1,1,1,1,1,1,1,1
1,1,2,1,1,1,1,2,1,1
1,1,1,1,1,1,1,1,1,1
1,1,1,1,1,1,1,1,1,1
1,1,1,1,1,1,1,1,1,1
1,1,2,1,1,1,1,2,1,1
1,1,1,1,1,1,1,1,1,1
1,1,1,1,1,1,1,1,1,1
endlayer

layer
1,1,1,1,1,1,1,1,1,1
1,1,1,1,1,1,1,1,1,1
1,1,1,1,1,1,1,1,1,1
1,1,2,1,1,1,1,2,1,1
1,1,1,1,1,1,1,1,1,1
1,1,1,1,1,1,1,1,1,1
1,1,1,1,1,1,1,1,1,1
1,1,2,1,1,1,1,2,1,1
1,1,1,1,1,1,1,1,1,1
1,1,1,1,1,1,1,1,1,1
endlayer

layer
1,1,1,1,1,1,1,1,1,1
1,1,1,1,1,1,1,1,1,1
1,1,1,1,1,1,1,1,1,1
1,1,2,1,1,1,1,2,1,1
1,1,1,1,1,1,1,1,1,1
1,1,1,1,1,1,1,1,1,1
1,1,1,1,1,1,1,1,1,1
1,1,2,1,1,1,1,2,1,1
1,1,1,1,1,1,1,1,1,1
1,1,1,1,1,1,1,1,1,1
endlayer

layer
1,1,1,1,1,1,1,1,1,1
1,1,1,1,1,1,1,1,1,1
1,1,1,1,1,1,1,1,1,1
1,1,2,1,1,1,1,2,1,1
1,1,1,1,1,1,1,1,1,1
1,1,1,1,1,1,1,1,1,1
1,1,1,1,1,1,1,1,1,1
1,1,2,1,1,1,1,2,1,1
1,1,1,1,1,1,1,1,1,1
1,1,1,1,1,1,1,1,1,1
endlayer

layer
1,1,1,1,1,1,1,1,1,1
1,1,1,1,1,1,1,1,1,1
1,1,1,1,1,1,1,1,1,1
1,1,2,1,1,1,1,2,1,1
1,1,1,1,1,1,1,1,1,1
1,1,1,1,1,1,1,1,1,1
1,1,1,1,1,1,1,1,1,1
1,1,2,1,1,1,1,2,1,1
1,1,1,1,1,1,1,1,1,1
1,1,1,1,1,1,1,1,1,1
endlayer

layer
1,1,1,1,1,1,1,1,1,1
1,1,1,1,1,1,1,1,1,1
1,1,1,1,1,1,1,1,1,1
1,1,2,1,1,1,1,2,1,1
1,1,1,1,1,1,1,1,1,1
1,1,1,1,1,1,1,1,1,1
1,1,1,1,1,1,1,1,1,1
1,1,2,1,1,1,1,2,1,1
1,1,1,1,1,1,1,1,1,1
1,1,1,1,1,1,1,1,1,1
endlayer

layer
1,1,1,1,1,1,1,1,1,1
1,1,1,1,1,1,1,1,1,1
1,1,1,1,1,1,1,1,1,1
1,1,2,1,1,1,1,2,1,1
1,1,1,1,1,1,1,1,1,1
1,1,1,1,1,1,1,1,1,1
1,1,1,1,1,1,1,1,1,1
1,1,2,1,1,1,1,2,1,1
1,1,1,1,1,1,1,1,1,1
1,1,1,1,1,1,1,1,1,1
endlayer

layer
1,1,1,1,1,1,1,1,1,1
1,1,1,1,1,1,1,1,1,1
1,1,1,1,1,1,1,1,1,1
1,1,2,1,1,1,1,2,1,1
1,1,1,1,1,1,1,1,1,1
1,1,1,1,1,1,1,1,1,1
1,1,1,1,1,1,1,1,1,1
1,1,2,1,1,1,1,2,1,1
1,1,1,1,1,1,1,1,1,1
1,1,1,1,1,1,1,1,1,1
endlayer

layer
1,1,1,1,1,1,1,1,1,1
1,1,1,1,1,1,1,1,1,1
1,1,1,1,1,1,1,1,1,1
1,1,2,1,1,1,1,2,1,1
1,1,1,1,1,1,1,1,1,1
1,1,1,1,1,1,1,1,1,1
1,1,1,1,1,1,1,1,1,1
1,1,2,1,1,1,1,2,1,1
1,1,1,1,1,1,1,1,1,1
1,1,1,1,1,1,1,1,1,1
endlayer

layer
1,1,1,1,1,1,1,1,1,1
1,1,1,1,1,1,1,1,1,1
1,1,1,1,1,1,1,1,1,1
1,3,3,3,3,3,3,3,3,1
1,1,1,1,1,1,1,1,1,1
1,1,1,1,1,1,1,1,1,1
1,1,1,1,1,1,1,1,1,1
1,3,3,3,3,3,3,3,3,1
1,1,1,1,1,1,1,1,1,1
1,1,1,1,1,1,1,1,1,1
endlayer

layer
1,1,1,1,1,1,4,1,1,1
1,1,1,1,1,1,5,1,1,1
1,1,1,1,1,1,5,1,1,1
1,1,2,6,1,1,5,2,1,1
1,1,1,1,1,1,5,1,1,1
1,1,1,1,1,1,5,1,1,1
1,1,1,1,1,1,5,4,1,1
1,1,2,1,1,1,5,2,1,1
1,1,1,1,1,1,5,1,1,1
1,1,1,1,1,1,4,1,1,1
endlayer

layer
1,1,1,1,1,1,1,1,1,1
1,1,1,1,1,1,1,1,1,1
4,3,3,3,3,3,3,3,3,4
1,4,2,6,1,1,1,2,1,1
1,1,1,1,1,1,1,4,1,1
1,1,1,1,1,1,1,4,1,1
4,3,3,3,3,3,3,3,3,4
1,1,2,4,4,4,4,2,1,1
1,1,1,1,1,1,1,1,1,1
1,1,1,1,1,1,1,1,1,1
endlayer

layer
1,1,4,1,1,1,1,4,1,1
1,1,5,7,7,7,1,5,1,1
1,4,5,8,9,9,8,5,1,1
1,8,5,6,7,7,10,5,8,1
1,12,5,7,7,7,12,5,11,1
1,12,5,8,7,7,12,5,11,1
1,10,5,13,7,7,12,5,11,1
1,4,5,8,8,8,12,5,7,1
1,4,5,10,10,10,10,5,1,1
1,1,4,1,1,1,1,4,1,1
endlayer

layer
1,1,1,1,1,1,1,1,1,1
1,1,1,15,14,4,1,1,1,1
1,1,8,17,16,16,15,4,1,1
1,12,2,18,0,0,0,2,4,1
1,20,0,0,0,0,0,19,4,1
1,20,0,0,0,0,0,21,1,1
1,20,0,0,0,0,0,22,1,1
1,24,2,23,23,23,23,2,1,1
1,10,11,19,20,25,19,17,1,1
1,1,1,1,1,1,1,1,1,1
endlayer

layer
1,1,1,1,1,1,1,1,1,1
1,1,1,1,1,1,1,1,1,1
1,1,17,15,15,15,26,17,1,1
1,26,2,0,0,0,0,2,4,1
1,4,0,0,0,0,0,4,1,1
1,4,0,0,0,0,0,27,1,1
1,4,0,0,0,0,0,4,1,1
30,29,2,28,28,28,28,2,4,1
1,4,14,17,17,17,17,16,4,1
1,1,1,1,1,1,1,1,1,1
endlayer

layer
1,1,1,1,1,1,1,1,1,1
1,1,1,1,1,1,1,1,1,1
1,15,32,4,31,4,14,26,26,1
1,32,2,0,0,0,0,2,14,1
30,33,0,0,0,0,0,13,17,1
30,32,0,0,0,0,0,13,1,1
30,32,0,0,0,0,0,13,26,1
1,24,2,0,0,0,0,2,14,1
1,4,29,31,31,17,17,29,17,1
1,1,34,1,1,34,1,1,1,1
endlayer

layer
1,1,1,1,1,1,1,1,1,1
1,1,35,1,1,35,35,1,1,1
1,35,36,36,36,36,36,35,1,1
1,32,2,0,0,0,0,2,15,1
1,15,0,0,0,0,0,24,14,1
1,27,0,0,0,0,0,14,14,1
1,27,0,0,0,0,0,24,14,1
1,24,2,0,0,0,0,2,16,1
1,21,17,17,36,36,17,17,1,1
1,1,35,29,29,35,1,1,1,1
endlayer

layer
1,1,1,1,1,1,1,1,1,1
1,1,1,1,1,1,1,1,1,1
1,1,1,15,15,33,1,1,1,1
1,35,35,36,17,36,15,15,1,1
1,29,29,7,7,7,24,33,1,1
1,37,29,7,23,7,24,33,1,1
1,37,29,26,26,26,29,33,1,1
1,35,29,16,29,29,16,35,1,1
1,1,1,35,35,35,35,1,1,1
1,1,1,1,1,1,1,1,1,1
endlayer

layer
1,1,1,1,1,1,1,1,1,1
1,1,1,1,1,1,1,1,1,1
1,1,1,1,1,1,1,1,1,1
1,1,1,1,1,1,1,1,1,1
1,1,1,35,35,35,35,1,1,1
1,1,35,35,1,35,35,1,1,1
1,1,35,35,35,35,35,1,1,1
1,1,1,1,1,1,1,1,1,1
1,1,1,1,1,1,1,1,1,1
1,1,1,1,1,1,1,1,1,1
endlayer

