
# Created by Ruins mod version 17.1 Ingame Parser
# authoring Player: ST753M

weight=1
embed_into_distance=5
acceptable_target_blocks=grass,dirt,podzol,mycelium,stone,biomesoplenty:grass,biomesoplenty:dirt,gravel
unacceptable_target_blocks=flowing_water,water,flowing_lava,lava
dimensions=18,9,9
allowable_overhang=5
max_leveling=0
leveling_buffer=0
preserve_water=0
preserve_lava=0

biomesToSpawnIn=coniferous_forest,autumnal_wooded_hills,autumnal_woods,autumn_woods,autumn_hills,mutated_extreme_hills_with_trees

=0,100,air
rule1=0,100,preserveBlock
rule2=0,100,biomesoplenty:log_0-7
rule3=0,100,biomesoplenty:log_0-11
rule4=0,100,biomesoplenty:log_0-3
rule5=0,100,biomesoplenty:planks_0-3
rule6=0,100,minecraft:cobblestone-0
rule7=0,100,minecraft:ladder-5
rule8=0,100,CommandBlock:RUINSTRIGGER /summon zombie_villager ~ ~1 ~ {ArmorItems:[{id:"minecraft:leather_boots",Count:1b,tag:{display:{color:10203303}}},{id:"minecraft:leather_leggings",Count:1b,tag:{display:{color:10203303}}},{id:"minecraft:leather_chestplate",Count:1b,tag:{display:{color:10203303}}},{id:"minecraft:leather_helmet",Count:1b,tag:{display:{color:10203303}}}],PersistenceRequired:1}:@-1
rule9=0,100,IInventory;minecraft:chest;biomesoplenty:gem#2#7#3+minecraft:tnt#1#0#10+biomesoplenty:boat_fir#1#0#14+biomesoplenty:persimmon#3#0#17+biomesoplenty:sapling_0#4#6#19+minecraft:iron_axe#{}#0#21-2
rule10=2,100,minecraft:torch-4
rule11=0,100,minecraft:trapdoor-9
rule12=0,100,biomesoplenty:fir_stairs-3
rule13=0,100,biomesoplenty:fir_door_block-1
rule14=0,100,minecraft:crafting_table-0
rule15=0,100,minecraft:stained_glass_pane-8
rule16=0,100,biomesoplenty:fir_door_block-8
rule17=0,100,teBlock;minecraft:flower_pot;{Item:"minecraft:red_flower",x:4477,y:80,z:-4071,Data:8,id:"minecraft:flower_pot"}-0
rule18=0,100,minecraft:stone_stairs-6
rule19=0,100,minecraft:stone_stairs-4
rule20=0,100,minecraft:stone_stairs-7
rule21=0,100,minecraft:stone_stairs-5
rule22=0,100,teBlock;minecraft:bed;{color:13,x:4476,y:84,z:-4070,id:"minecraft:bed"}-0
rule23=0,100,teBlock;minecraft:bed;{color:13,x:4476,y:84,z:-4069,id:"minecraft:bed"}-8
rule24=0,100,CommandBlock:RUINSTRIGGER /summon villager ~ ~1 ~ {Profession:0,Offers:{Recipes:[{rewardExp:0b,maxUses:2147483647,uses:0,buy:{id:"biomesoplenty:dirt",Count:1b},buyB:{id:"biomesoplenty:gem",Damage:7,Count:1b},sell:{id:"biomesoplenty:grass",Damage:2,Count:1b}},{rewardExp:0b,maxUses:2147483647,uses:0,buy:{id:"biomesoplenty:gem",Damage:7,Count:1b},sell:{id:"biomesoplenty:persimmon",Count:1b}},{rewardExp:0b,maxUses:2147483647,uses:0,buy:{id:"biomesoplenty:flower_1",Damage:3,Count:4b},sell:{id:"biomesoplenty:gem",Damage:7,Count:1b}}]}}:@-1
rule25=0,100,teBlock;minecraft:bed;{color:13,x:4477,y:84,z:-4070,id:"minecraft:bed"}-0
rule26=0,100,teBlock;minecraft:bed;{color:13,x:4477,y:84,z:-4069,id:"minecraft:bed"}-8
rule27=0,100,minecraft:stone_stairs-2
rule28=0,100,minecraft:stone_stairs-0
rule29=0,100,minecraft:stone_stairs-3
rule30=0,100,minecraft:stone_stairs-1

layer
1,1,1,1,1,1,1,1,1
1,2,3,3,3,3,3,2,1
1,4,2,3,3,3,2,4,1
1,4,4,5,5,5,4,4,1
1,4,4,5,5,5,4,4,1
1,4,4,5,5,5,4,4,1
1,4,2,3,3,3,2,4,1
1,2,3,3,3,3,3,2,1
1,1,1,1,1,1,1,1,1
endlayer

layer
1,1,1,1,1,1,1,1,1
1,2,6,6,6,6,6,2,1
1,6,2,0,0,2,2,6,1
1,6,0,0,0,7,0,6,1
1,6,0,0,8,0,0,6,1
1,6,9,0,0,0,0,6,1
1,6,2,0,0,0,2,6,1
1,2,6,6,6,6,6,2,1
1,1,1,1,1,1,1,1,1
endlayer

layer
1,1,1,1,1,1,1,1,1
1,2,6,6,6,6,6,2,1
1,6,2,0,0,2,2,6,1
1,6,0,0,0,7,0,6,1
1,6,0,0,0,0,0,6,1
1,6,0,0,0,0,0,6,1
1,6,2,0,0,0,2,6,1
1,2,6,6,6,6,6,2,1
1,1,1,1,1,1,1,1,1
endlayer

layer
1,1,1,1,1,1,1,1,1
1,6,3,3,3,3,3,6,1
1,4,2,0,0,2,2,4,1
1,4,0,0,0,7,0,4,1
1,4,10,0,0,0,0,4,1
1,4,0,0,0,0,0,4,1
1,4,2,0,0,0,2,4,1
1,6,3,3,3,3,3,6,1
1,1,1,1,1,1,1,1,1
endlayer

layer
1,1,1,1,1,1,1,1,1
1,1,1,1,1,1,1,1,1
1,1,2,3,3,3,2,1,1
1,1,4,6,6,11,4,1,1
1,12,4,6,6,6,4,1,1
1,1,4,6,6,6,4,1,1
1,1,2,3,3,3,2,1,1
1,1,1,1,1,1,1,1,1
1,1,1,1,1,1,1,1,1
endlayer

layer
1,1,1,1,1,1,1,1,1
1,1,1,1,1,1,1,1,1
1,1,2,5,5,5,2,1,1
1,1,5,0,0,7,5,1,1
1,1,13,0,0,0,5,1,1
1,1,5,14,14,14,5,1,1
1,1,2,5,5,5,2,1,1
1,1,1,1,1,1,1,1,1
1,1,1,1,1,1,1,1,1
endlayer

layer
1,1,1,1,1,1,1,1,1
1,1,1,1,1,1,1,1,1
1,1,2,5,15,5,2,1,1
1,1,5,0,0,7,5,1,1
1,1,16,0,0,0,15,1,1
1,1,5,0,17,0,5,1,1
1,1,2,5,15,5,2,1,1
1,1,1,1,1,1,1,1,1
1,1,1,1,1,1,1,1,1
endlayer

layer
1,1,1,1,1,1,1,1,1
1,1,1,1,1,1,1,1,1
1,1,2,5,15,5,2,1,1
1,1,5,0,0,7,5,1,1
1,1,3,10,0,0,15,1,1
1,1,5,0,0,0,5,1,1
1,1,2,5,15,5,2,1,1
1,1,1,1,1,1,1,1,1
1,1,1,1,1,1,1,1,1
endlayer

layer
1,1,1,1,1,1,1,1,1
1,19,19,1,1,1,19,18,1
1,20,2,5,5,5,2,18,1
1,1,5,0,0,7,5,1,1
1,1,5,0,0,0,5,1,1
1,1,5,0,0,0,5,1,1
1,20,2,5,5,5,2,18,1
1,20,21,1,1,1,21,21,1
1,1,1,1,1,1,1,1,1
endlayer

layer
1,4,1,1,1,1,1,4,1
3,2,3,3,3,3,3,2,3
1,4,6,6,6,6,6,4,1
1,4,6,6,6,11,6,4,1
1,4,6,6,6,6,6,4,1
1,4,6,6,6,6,6,4,1
1,4,6,6,6,6,6,4,1
3,2,3,3,3,3,3,2,3
1,4,1,1,1,1,1,4,1
endlayer

layer
1,0,1,1,1,1,1,0,1
0,2,5,5,2,5,5,2,1
1,5,0,0,0,0,0,5,1
1,5,14,0,0,0,0,5,1
1,2,23,22,0,0,0,2,1
1,5,26,25,0,24,0,5,1
1,5,14,0,0,0,0,5,1
0,2,5,5,2,5,5,2,0
1,0,1,1,1,1,1,0,1
endlayer

layer
1,0,1,1,1,1,1,0,1
0,2,15,15,2,15,15,2,1
1,15,0,0,0,0,0,15,1
1,15,0,0,0,0,0,15,1
1,2,0,0,0,0,0,2,1
1,15,0,0,0,0,0,15,1
1,15,0,0,0,0,0,15,1
0,2,15,15,2,15,15,2,0
1,0,1,1,1,1,1,0,1
endlayer

layer
1,0,1,1,1,1,1,0,1
0,2,15,15,2,15,15,2,1
1,15,0,0,0,0,0,15,1
1,15,0,0,0,0,0,15,1
1,2,10,0,0,0,0,2,1
1,15,0,0,0,0,0,15,1
1,15,0,0,0,0,0,15,1
0,2,15,15,2,15,15,2,0
1,0,1,1,1,1,1,0,1
endlayer

layer
1,0,1,1,1,1,1,0,1
0,2,5,5,2,5,5,2,1
1,5,0,0,0,0,0,5,1
1,5,0,0,0,0,0,5,1
1,2,0,0,0,0,0,2,1
1,5,0,0,0,0,0,5,1
1,5,0,0,0,0,0,5,1
0,2,5,5,2,5,5,2,0
1,0,1,1,1,1,1,0,1
endlayer

layer
29,28,28,28,28,28,28,28,27
29,2,3,3,2,3,3,2,27
29,4,0,0,4,0,0,4,27
29,4,0,0,4,0,0,4,27
29,2,3,3,2,3,3,2,27
29,4,0,0,4,0,0,4,27
29,4,0,0,4,0,0,4,27
29,2,3,3,2,3,3,2,27
29,30,30,30,30,30,30,30,30
endlayer

layer
1,1,1,1,1,1,1,1,1
1,28,28,28,28,28,28,27,1
1,29,21,21,21,21,20,27,1
1,29,18,0,0,0,20,27,1
1,29,18,0,2,0,20,27,1
1,29,18,0,0,0,20,27,1
1,29,19,19,19,19,20,27,1
1,30,30,30,30,30,30,27,1
1,1,1,1,1,1,1,1,1
endlayer

layer
1,1,1,1,1,1,1,1,1
1,1,1,1,1,1,1,1,1
1,1,28,28,28,28,27,1,1
1,1,29,18,21,21,27,1,1
1,1,29,18,2,20,27,1,1
1,1,29,18,19,19,27,1,1
1,1,30,30,30,30,30,1,1
1,1,1,1,1,1,1,1,1
1,1,1,1,1,1,1,1,1
endlayer

layer
1,1,1,1,1,1,1,1,1
1,1,1,1,1,1,1,1,1
1,1,1,1,1,1,1,1,1
1,1,1,28,28,28,1,1,1
1,1,1,29,6,27,1,1,1
1,1,1,30,30,30,1,1,1
1,1,1,1,1,1,1,1,1
1,1,1,1,1,1,1,1,1
1,1,1,1,1,1,1,1,1
endlayer

