
# Created by Ruins mod version 16.9 Ingame Parser
# authoring Player: ST753M

weight=1
uniqueMinDistance=1000
embed_into_distance=1
acceptable_target_blocks=sand,sandstone
unacceptable_target_blocks=flowing_water,water,flowing_lava,lava
dimensions=17,15,16
allowable_overhang=1
max_leveling=2
leveling_buffer=0
preserve_water=1
preserve_lava=0

biomesToSpawnIn=beach,mutated_desert,desert_shrubland,arid_highland,xeric_shrubland

rule1=0,100,preserveBlock
rule2=0,100,minecraft:sandstone-0
rule3=0,100,minecraft:water-0
rule4=0,100,minecraft:stone_slab-9
rule5=0,100,minecraft:sandstone_stairs-0
rule6=0,100,minecraft:sandstone_stairs-4
rule7=0,100,minecraft:sandstone_stairs-3
rule8=0,100,minecraft:sandstone_stairs-7
rule9=0,100,minecraft:water-9
rule10=0,100,minecraft:stone_slab-1
rule11=0,100,minecraft:sandstone_stairs-2
rule12=0,100,minecraft:sandstone_stairs-1
rule13=0,100,minecraft:sandstone_stairs-6
rule14=0,100,minecraft:sandstone_stairs-5
rule15=0,100,minecraft:water-1

layer
1,1,1,1,1,2,2,2,2,2,2,1,1,1,1,1
1,1,1,2,2,2,2,2,2,2,2,2,2,1,1,1
1,1,2,2,2,2,2,2,2,2,2,2,2,2,1,1
1,2,2,2,2,2,2,2,2,2,2,2,2,2,2,1
1,2,2,2,2,2,2,2,2,2,2,2,2,2,2,1
2,2,2,2,2,2,2,2,2,2,2,2,2,2,2,2
2,2,2,2,2,2,2,2,2,2,2,2,2,2,2,2
2,2,2,2,2,2,2,2,2,2,2,2,2,2,2,2
2,2,2,2,2,2,2,2,2,2,2,2,2,2,2,2
2,2,2,2,2,2,2,2,2,2,2,2,2,2,2,2
1,2,2,2,2,2,2,2,2,2,2,2,2,2,2,1
1,2,2,2,2,2,2,2,2,2,2,2,2,2,2,1
1,1,2,2,2,2,2,2,2,2,2,2,2,2,1,1
1,1,1,2,2,2,2,2,2,2,2,2,2,1,1,1
1,1,1,1,1,2,2,2,2,2,2,1,1,1,1,1
endlayer

layer
1,1,1,1,1,2,2,2,2,2,2,1,1,1,1,1
1,1,1,2,2,2,3,3,3,3,2,2,2,1,1,1
1,1,2,2,3,3,3,3,3,3,3,3,2,2,1,1
1,2,2,3,3,2,2,2,2,3,3,3,3,2,2,1
1,2,3,3,3,3,3,3,3,3,3,3,3,3,2,1
2,2,3,3,3,3,3,3,3,3,3,3,3,3,2,2
2,3,3,3,3,3,2,2,3,3,3,2,3,3,3,2
2,3,3,3,3,3,2,2,2,3,3,2,2,3,3,2
2,3,3,3,3,3,2,2,2,2,2,2,2,3,3,2
2,2,3,3,3,3,2,2,2,2,2,2,2,3,2,2
1,2,3,3,3,3,3,2,2,2,2,2,3,3,2,1
1,2,2,3,3,3,3,3,2,2,3,3,3,2,2,1
1,1,2,2,3,3,3,3,3,3,3,3,2,2,1,1
1,1,1,2,2,2,3,3,3,3,2,2,2,1,1,1
1,1,1,1,1,2,2,2,2,2,2,1,1,1,1,1
endlayer

layer
1,1,1,1,1,1,1,1,1,1,1,1,1,1,1,1
1,1,1,1,1,1,1,1,1,1,1,1,1,1,1,1
1,1,1,1,1,1,1,1,1,1,1,1,1,1,1,1
1,1,1,1,1,1,7,6,5,2,4,1,1,1,1,1
1,1,1,1,1,0,0,0,0,0,2,4,1,1,1,1
1,1,1,1,1,0,0,0,0,0,0,2,4,1,1,1
1,1,1,1,1,8,2,2,0,0,0,2,2,1,1,1
1,1,9,0,0,2,2,2,2,0,0,2,2,1,1,1
1,1,1,1,1,8,2,2,2,2,2,2,2,1,1,1
1,1,1,1,1,0,2,2,2,2,2,2,2,1,1,1
1,1,1,1,1,0,0,2,2,2,2,2,1,1,1,1
1,1,1,1,1,0,0,1,2,2,1,1,1,1,1,1
1,1,1,1,1,0,0,1,1,1,1,1,1,1,1,1
1,1,1,1,1,1,1,1,1,1,1,1,1,1,1,1
1,1,1,1,1,1,1,1,1,1,1,1,1,1,1,1
endlayer

layer
1,1,1,1,1,1,1,1,1,1,1,1,1,1,1,1
1,1,1,1,1,1,1,1,1,1,1,1,1,1,1,1
1,1,1,1,1,1,1,1,1,1,1,1,1,1,1,1
1,1,1,1,1,1,1,7,2,5,2,1,1,1,1,1
1,1,1,1,1,0,0,0,0,0,2,2,1,1,1,1
1,1,1,1,1,0,0,0,0,0,0,2,2,1,1,1
1,1,1,1,1,2,2,2,2,0,0,0,10,1,1,1
1,1,9,0,0,2,2,2,2,2,0,0,10,1,1,1
1,1,1,1,1,2,2,2,2,2,1,1,1,1,1,1
1,1,1,1,1,0,2,2,2,2,2,11,1,1,1,1
1,1,1,1,1,1,1,10,2,2,11,1,1,1,1,1
1,1,1,1,1,1,1,1,12,12,1,1,1,1,1,1
1,1,1,1,1,1,1,1,1,1,1,1,1,1,1,1
1,1,1,1,1,1,1,1,1,1,1,1,1,1,1,1
1,1,1,1,1,1,1,1,1,1,1,1,1,1,1,1
endlayer

layer
1,1,1,1,1,1,1,1,1,1,1,1,1,1,1,1
1,1,1,1,1,1,1,1,1,1,1,1,1,1,1,1
1,1,1,1,1,1,1,1,1,1,1,1,1,1,1,1
1,1,1,1,1,1,8,5,6,2,10,1,1,1,1,1
1,1,1,1,1,0,0,0,0,0,0,1,1,1,1,1
1,1,1,1,1,0,0,0,0,0,0,1,1,1,1,1
1,1,1,1,1,5,2,2,2,2,13,1,1,1,1,1
1,1,9,0,0,2,2,2,2,2,13,1,1,1,1,1
1,1,1,1,1,12,2,2,2,2,14,1,1,1,1,1
1,1,1,1,1,0,7,12,11,0,1,1,1,1,1,1
1,1,1,1,1,1,1,1,1,1,1,1,1,1,1,1
1,1,1,1,1,1,1,1,1,1,1,1,1,1,1,1
1,1,1,1,1,1,1,1,1,1,1,1,1,1,1,1
1,1,1,1,1,1,1,1,1,1,1,1,1,1,1,1
1,1,1,1,1,1,1,1,1,1,1,1,1,1,1,1
endlayer

layer
1,1,1,1,1,1,1,1,1,1,1,1,1,1,1,1
1,1,1,1,1,1,1,1,1,1,1,1,1,1,1,1
1,1,1,1,1,1,1,1,1,1,1,1,1,1,1,1
1,1,1,1,1,10,6,2,11,1,1,1,1,1,1,1
1,1,1,1,1,0,0,0,0,1,1,1,1,1,1,1
1,1,1,1,1,0,0,0,0,0,0,1,1,1,1,1
1,1,1,1,1,0,5,2,2,2,2,1,1,1,1,1
1,1,9,0,0,0,2,2,2,2,2,1,1,1,1,1
1,1,1,1,1,0,12,2,2,2,2,1,1,1,1,1
1,1,1,1,1,0,0,0,0,0,1,1,1,1,1,1
1,1,1,1,1,1,1,1,1,1,1,1,1,1,1,1
1,1,1,1,1,1,1,1,1,1,1,1,1,1,1,1
1,1,1,1,1,1,1,1,1,1,1,1,1,1,1,1
1,1,1,1,1,1,1,1,1,1,1,1,1,1,1,1
1,1,1,1,1,1,1,1,1,1,1,1,1,1,1,1
endlayer

layer
1,1,1,1,1,1,1,1,1,1,1,1,1,1,1,1
1,1,1,1,1,1,1,1,1,1,1,1,1,1,1,1
1,1,1,1,1,1,1,1,1,1,1,1,1,1,1,1
1,1,1,1,1,1,1,1,1,1,1,1,1,1,1,1
1,1,1,1,1,1,1,1,1,1,1,1,1,1,1,1
1,1,1,1,1,0,0,0,0,0,0,1,1,1,1,1
1,1,1,1,1,0,0,5,2,2,2,1,1,1,1,1
1,1,9,0,0,0,0,2,2,2,2,1,1,1,1,1
1,1,1,1,1,0,0,12,2,2,2,1,1,1,1,1
1,1,1,1,1,0,0,0,0,0,1,1,1,1,1,1
1,1,1,1,1,1,1,1,1,1,1,1,1,1,1,1
1,1,1,1,1,1,1,1,1,1,1,1,1,1,1,1
1,1,1,1,1,1,1,1,1,1,1,1,1,1,1,1
1,1,1,1,1,1,1,1,1,1,1,1,1,1,1,1
1,1,1,1,1,1,1,1,1,1,1,1,1,1,1,1
endlayer

layer
1,1,1,1,1,1,1,1,1,1,1,1,1,1,1,1
1,1,1,1,1,1,1,1,1,1,1,1,1,1,1,1
1,1,1,1,1,1,1,1,1,1,1,1,1,1,1,1
1,1,1,1,1,1,1,1,1,1,1,1,1,1,1,1
1,1,1,1,1,1,2,4,1,1,1,1,1,1,1,1
1,1,1,1,4,2,0,0,0,0,0,4,1,1,1,1
1,1,1,6,6,0,0,0,2,2,11,1,1,1,1,1
1,1,9,2,2,13,0,0,2,2,11,1,1,1,1,1
1,1,1,14,14,0,0,0,2,2,11,1,1,1,1,1
1,1,1,1,4,2,0,0,0,0,1,1,1,1,1,1
1,1,1,1,1,1,2,4,1,1,1,1,1,1,1,1
1,1,1,1,1,1,1,1,1,1,1,1,1,1,1,1
1,1,1,1,1,1,1,1,1,1,1,1,1,1,1,1
1,1,1,1,1,1,1,1,1,1,1,1,1,1,1,1
1,1,1,1,1,1,1,1,1,1,1,1,1,1,1,1
endlayer

layer
1,1,1,1,1,1,1,1,1,1,1,1,1,1,1,1
1,1,1,1,1,1,1,1,1,1,1,1,1,1,1,1
1,1,1,1,1,1,1,1,1,1,1,1,1,1,1,1
1,1,1,1,1,1,1,1,1,1,1,1,1,1,1,1
1,1,1,1,1,1,2,2,13,1,1,1,1,1,1,1
1,1,1,1,8,10,0,0,0,0,0,2,1,1,1,1
1,1,1,2,2,0,0,8,2,11,0,6,1,1,1,1
1,1,15,3,2,2,0,4,2,11,1,1,1,1,1,1
1,1,1,2,2,0,0,8,2,11,1,1,1,1,1,1
1,1,1,1,8,10,0,0,0,0,1,1,1,1,1,1
1,1,1,1,1,1,2,2,13,1,1,1,1,1,1,1
1,1,1,1,1,1,1,1,1,1,1,1,1,1,1,1
1,1,1,1,1,1,1,1,1,1,1,1,1,1,1,1
1,1,1,1,1,1,1,1,1,1,1,1,1,1,1,1
1,1,1,1,1,1,1,1,1,1,1,1,1,1,1,1
endlayer

layer
1,1,1,1,1,1,1,1,1,1,1,1,1,1,1,1
1,1,1,1,1,1,1,1,1,1,1,1,1,1,1,1
1,1,1,1,1,1,1,1,1,1,1,1,1,1,1,1
1,1,1,1,1,1,1,1,1,1,1,1,1,1,1,1
1,1,1,1,1,1,1,10,2,1,14,1,1,1,1,1
1,1,1,1,1,1,1,0,14,0,0,2,1,1,1,1
1,1,1,5,5,0,0,2,2,0,0,2,1,1,1,1
1,1,1,2,2,11,0,2,2,0,0,6,1,1,1,1
1,1,1,12,12,0,0,2,2,0,1,1,1,1,1,1
1,1,1,1,1,1,1,0,6,0,1,1,1,1,1,1
1,1,1,1,1,1,10,2,2,1,1,1,1,1,1,1
1,1,1,1,1,1,1,1,1,1,1,1,1,1,1,1
1,1,1,1,1,1,1,1,1,1,1,1,1,1,1,1
1,1,1,1,1,1,1,1,1,1,1,1,1,1,1,1
1,1,1,1,1,1,1,1,1,1,1,1,1,1,1,1
endlayer

layer
1,1,1,1,1,1,1,1,1,1,1,1,1,1,1,1
1,1,1,1,1,1,1,1,1,1,1,1,1,1,1,1
1,1,1,1,1,1,1,1,1,1,1,1,1,1,1,1
1,1,1,1,1,1,1,1,1,1,1,1,1,1,1,1
1,1,1,1,1,1,1,1,5,1,2,1,1,1,1,1
1,1,1,1,1,1,1,0,2,0,0,2,1,1,1,1
1,1,1,1,1,1,1,2,2,0,0,2,1,1,1,1
1,1,1,1,1,1,1,7,2,0,8,2,1,1,1,1
1,1,1,1,1,1,1,2,2,0,0,13,1,1,1,1
1,1,1,1,1,1,1,0,2,0,1,1,1,1,1,1
1,1,1,1,1,1,1,1,12,1,1,1,1,1,1,1
1,1,1,1,1,1,1,1,1,1,1,1,1,1,1,1
1,1,1,1,1,1,1,1,1,1,1,1,1,1,1,1
1,1,1,1,1,1,1,1,1,1,1,1,1,1,1,1
1,1,1,1,1,1,1,1,1,1,1,1,1,1,1,1
endlayer

layer
1,1,1,1,1,1,1,1,1,1,1,1,1,1,1,1
1,1,1,1,1,1,1,1,1,1,1,1,1,1,1,1
1,1,1,1,1,1,1,1,1,1,1,1,1,1,1,1
1,1,1,1,1,1,1,1,1,1,1,1,1,1,1,1
1,1,1,1,1,1,1,1,1,1,10,1,1,1,1,1
1,1,1,1,1,1,1,0,5,0,0,2,1,1,1,1
1,1,1,1,1,1,1,0,2,0,13,2,1,1,1,1
1,1,1,1,1,1,1,0,2,0,2,2,1,1,1,1
1,1,1,1,1,1,1,0,2,0,13,2,1,1,1,1
1,1,1,1,1,1,1,0,12,0,1,1,1,1,1,1
1,1,1,1,1,1,1,1,1,1,1,1,1,1,1,1
1,1,1,1,1,1,1,1,1,1,1,1,1,1,1,1
1,1,1,1,1,1,1,1,1,1,1,1,1,1,1,1
1,1,1,1,1,1,1,1,1,1,1,1,1,1,1,1
1,1,1,1,1,1,1,1,1,1,1,1,1,1,1,1
endlayer

layer
1,1,1,1,1,1,1,1,1,1,1,1,1,1,1,1
1,1,1,1,1,1,1,1,1,1,1,1,1,1,1,1
1,1,1,1,1,1,1,1,1,1,1,1,1,1,1,1
1,1,1,1,1,1,1,1,1,1,1,1,1,1,1,1
1,1,1,1,1,1,1,1,1,1,1,1,1,1,1,1
1,1,1,1,1,1,1,0,0,8,0,5,1,1,1,1
1,1,1,1,1,1,1,6,0,0,2,2,1,1,1,1
1,1,1,1,1,1,1,13,2,2,2,2,1,1,1,1
1,1,1,1,1,1,1,14,0,0,2,2,1,1,1,1
1,1,1,1,1,1,1,0,0,8,1,1,1,1,1,1
1,1,1,1,1,1,1,1,1,1,1,1,1,1,1,1
1,1,1,1,1,1,1,1,1,1,1,1,1,1,1,1
1,1,1,1,1,1,1,1,1,1,1,1,1,1,1,1
1,1,1,1,1,1,1,1,1,1,1,1,1,1,1,1
1,1,1,1,1,1,1,1,1,1,1,1,1,1,1,1
endlayer

layer
1,1,1,1,1,1,1,1,1,1,1,1,1,1,1,1
1,1,1,1,1,1,1,1,1,1,1,1,1,1,1,1
1,1,1,1,1,1,1,1,1,1,1,1,1,1,1,1
1,1,1,1,1,1,1,1,1,1,1,1,1,1,1,1
1,1,1,1,1,1,1,1,1,1,1,1,1,1,1,1
1,1,1,1,1,1,1,14,14,2,1,1,1,1,1,1
1,1,1,1,1,1,1,2,2,2,2,5,1,1,1,1
1,1,1,1,1,1,1,2,2,2,2,2,1,1,1,1
1,1,1,1,1,1,1,2,2,2,2,12,1,1,1,1
1,1,1,1,1,1,1,6,6,2,1,1,1,1,1,1
1,1,1,1,1,1,1,1,1,1,1,1,1,1,1,1
1,1,1,1,1,1,1,1,1,1,1,1,1,1,1,1
1,1,1,1,1,1,1,1,1,1,1,1,1,1,1,1
1,1,1,1,1,1,1,1,1,1,1,1,1,1,1,1
1,1,1,1,1,1,1,1,1,1,1,1,1,1,1,1
endlayer

layer
1,1,1,1,1,1,1,1,1,1,1,1,1,1,1,1
1,1,1,1,1,1,1,1,1,1,1,1,1,1,1,1
1,1,1,1,1,1,1,1,1,1,1,1,1,1,1,1
1,1,1,1,1,1,1,1,1,1,1,1,1,1,1,1
1,1,1,1,1,1,1,1,1,1,1,1,1,1,1,1
1,1,1,1,1,1,1,2,2,2,1,1,1,1,1,1
1,1,1,1,1,1,1,4,2,2,2,1,1,1,1,1
1,1,1,1,1,1,1,2,2,2,2,11,1,1,1,1
1,1,1,1,1,1,1,4,2,2,2,1,1,1,1,1
1,1,1,1,1,1,1,2,2,2,1,1,1,1,1,1
1,1,1,1,1,1,1,1,1,1,1,1,1,1,1,1
1,1,1,1,1,1,1,1,1,1,1,1,1,1,1,1
1,1,1,1,1,1,1,1,1,1,1,1,1,1,1,1
1,1,1,1,1,1,1,1,1,1,1,1,1,1,1,1
1,1,1,1,1,1,1,1,1,1,1,1,1,1,1,1
endlayer

layer
1,1,1,1,1,1,1,1,1,1,1,1,1,1,1,1
1,1,1,1,1,1,1,1,1,1,1,1,1,1,1,1
1,1,1,1,1,1,1,1,1,1,1,1,1,1,1,1
1,1,1,1,1,1,1,1,1,1,1,1,1,1,1,1
1,1,1,1,1,1,1,1,1,1,1,1,1,1,1,1
1,1,1,1,1,1,1,5,5,5,1,1,1,1,1,1
1,1,1,1,1,1,1,2,2,2,5,1,1,1,1,1
1,1,1,1,1,1,1,2,2,2,2,1,1,1,1,1
1,1,1,1,1,1,1,2,2,2,11,1,1,1,1,1
1,1,1,1,1,1,1,12,12,12,1,1,1,1,1,1
1,1,1,1,1,1,1,1,1,1,1,1,1,1,1,1
1,1,1,1,1,1,1,1,1,1,1,1,1,1,1,1
1,1,1,1,1,1,1,1,1,1,1,1,1,1,1,1
1,1,1,1,1,1,1,1,1,1,1,1,1,1,1,1
1,1,1,1,1,1,1,1,1,1,1,1,1,1,1,1
endlayer

layer
1,1,1,1,1,1,1,1,1,1,1,1,1,1,1,1
1,1,1,1,1,1,1,1,1,1,1,1,1,1,1,1
1,1,1,1,1,1,1,1,1,1,1,1,1,1,1,1
1,1,1,1,1,1,1,1,1,1,1,1,1,1,1,1
1,1,1,1,1,1,1,1,1,1,1,1,1,1,1,1
1,1,1,1,1,1,1,1,1,1,1,1,1,1,1,1
1,1,1,1,1,1,1,12,10,0,1,1,1,1,1,1
1,1,1,1,1,1,1,2,10,10,1,1,1,1,1,1
1,1,1,1,1,1,1,5,10,0,1,1,1,1,1,1
1,1,1,1,1,1,1,1,1,1,1,1,1,1,1,1
1,1,1,1,1,1,1,1,1,1,1,1,1,1,1,1
1,1,1,1,1,1,1,1,1,1,1,1,1,1,1,1
1,1,1,1,1,1,1,1,1,1,1,1,1,1,1,1
1,1,1,1,1,1,1,1,1,1,1,1,1,1,1,1
1,1,1,1,1,1,1,1,1,1,1,1,1,1,1,1
endlayer

