
# Created by Ruins mod version 16.7 Ingame Parser
# authoring Player: ST753M

weight=1
uniqueMinDistance=1000
embed_into_distance=7
acceptable_target_blocks=sand
unacceptable_target_blocks=flowing_water,water,flowing_lava,lava
dimensions=17,21,21
allowable_overhang=32
max_leveling=3
leveling_buffer=0
preserve_water=0
preserve_lava=0

biomesToSpawnIn=mutated_desert,xeric_shrubland

rule1=0,100,minecraft:sandstone-0
rule2=0,100,minecraft:stained_hardened_clay-1
rule3=0,100,minecraft:grass-0
rule4=0,100,minecraft:log-0
rule5=0,100,minecraft:water-0
rule6=0,100,minecraft:sandstone-2
rule7=0,100,minecraft:red_flower-3,minecraft:red_flower-6,minecraft:red_flower-7,minecraft:red_flower-8,minecraft:red_flower-0
rule8=0,100,minecraft:sandstone_stairs-0
rule9=0,100,minecraft:red_flower-3,minecraft:red_flower-6,minecraft:red_flower-7,minecraft:red_flower-8,minecraft:red_flower-0
rule10=0,100,minecraft:sandstone_stairs-5
rule11=0,100,minecraft:waterlily-0
rule12=0,100,minecraft:red_flower-3,minecraft:red_flower-6,minecraft:red_flower-7,minecraft:red_flower-8,minecraft:red_flower-0
rule13=0,100,minecraft:sandstone_stairs-4
rule14=0,100,minecraft:red_flower-3,minecraft:red_flower-6,minecraft:red_flower-7,minecraft:red_flower-8,minecraft:red_flower-0
rule15=0,100,minecraft:red_flower-3,minecraft:red_flower-6,minecraft:red_flower-7,minecraft:red_flower-8,minecraft:red_flower-0
rule16=0,100,minecraft:red_flower-3,minecraft:red_flower-6,minecraft:red_flower-7,minecraft:red_flower-8,minecraft:red_flower-0
rule17=0,100,minecraft:sandstone_stairs-1
rule18=0,100,minecraft:sandstone-1
rule19=0,100,minecraft:leaves-12
rule20=0,100,minecraft:leaves-4
rule21=0,100,minecraft:glowstone-0
rule22=0,100,minecraft:sandstone_stairs-7
rule23=0,100,minecraft:sandstone_stairs-6
rule24=0,100,minecraft:sandstone_stairs-3
rule25=0,100,minecraft:sandstone_stairs-2
rule26=0,100,minecraft:stone_slab-1
rule27=0,100,minecraft:stained_glass-0

layer
1,1,1,1,1,1,1,1,1,1,1,1,1,1,1,1,1,1,1,1,1
1,1,1,1,1,1,1,1,1,1,1,1,1,1,1,1,1,1,1,1,1
1,1,1,1,2,1,1,1,2,1,1,1,2,1,1,1,2,1,1,1,1
1,1,1,1,2,1,1,1,2,1,1,1,2,1,1,1,2,1,1,1,1
1,1,2,2,1,1,1,1,1,1,1,1,1,1,1,1,1,2,2,1,1
1,1,1,1,1,1,3,3,3,3,3,3,3,3,3,1,1,1,1,1,1
1,1,1,1,1,3,3,3,3,3,3,3,3,3,3,3,1,1,1,1,1
1,1,1,1,1,3,3,3,3,3,3,3,3,3,3,3,1,1,1,1,1
1,1,2,2,1,3,3,3,4,3,3,3,4,3,3,3,1,2,2,1,1
1,1,1,1,1,3,3,3,3,5,5,5,3,3,3,3,1,1,1,1,1
1,1,1,1,1,3,3,3,3,5,5,5,3,3,3,3,1,1,1,1,1
1,1,1,1,1,3,3,3,3,5,5,5,3,3,3,3,1,1,1,1,1
1,1,2,2,1,3,3,3,4,3,3,3,4,3,3,3,1,2,2,1,1
1,1,1,1,1,3,3,3,3,3,3,3,3,3,3,3,1,1,1,1,1
1,1,1,1,1,3,3,3,3,3,3,3,3,3,3,3,1,1,1,1,1
1,1,1,1,1,1,3,3,3,3,3,3,3,3,3,1,1,1,1,1,1
1,1,2,2,1,1,1,1,1,1,1,1,1,1,1,1,1,2,2,1,1
1,1,1,1,2,1,1,1,2,1,1,1,2,1,1,1,2,1,1,1,1
1,1,1,1,2,1,1,1,2,1,1,1,2,1,1,1,2,1,1,1,1
1,1,1,1,1,1,1,1,1,1,1,1,1,1,1,1,1,1,1,1,1
1,1,1,1,1,1,1,1,1,1,1,1,1,1,1,1,1,1,1,1,1
endlayer

layer
1,1,1,1,1,1,1,1,1,1,1,1,1,1,1,1,1,1,1,1,1
1,0,0,0,0,0,0,0,0,0,0,0,0,0,0,0,0,0,0,0,1
1,0,6,0,0,0,6,0,0,0,6,0,0,0,6,0,0,0,6,0,1
1,0,0,0,0,0,0,0,0,0,0,0,0,0,0,0,0,0,0,0,1
1,0,0,0,0,0,0,0,0,0,0,0,0,0,0,0,0,0,0,0,1
1,0,0,0,0,0,7,7,7,7,7,7,7,7,7,0,0,0,0,0,1
1,0,6,0,0,9,7,7,7,7,7,7,7,7,7,7,0,0,6,8,1
1,0,0,0,0,9,7,7,7,7,7,7,7,7,7,7,0,0,0,10,1
1,0,0,0,0,9,7,7,4,7,7,7,4,7,7,7,0,0,0,0,1
1,0,0,0,0,9,7,7,0,11,11,11,7,7,7,7,0,0,0,0,1
1,0,6,0,0,12,7,7,7,11,11,11,7,7,7,7,0,0,6,0,1
1,0,0,0,0,12,7,7,7,11,11,0,7,7,7,7,0,0,0,0,1
1,0,0,0,0,12,7,0,4,7,7,7,4,7,7,7,0,0,0,0,1
1,13,0,0,0,12,7,7,7,7,7,7,7,7,7,7,0,0,0,0,1
1,17,6,0,0,16,16,15,14,14,14,7,7,7,7,7,0,0,6,0,1
1,0,0,0,0,0,16,15,15,14,14,14,14,14,14,0,0,0,0,0,1
1,0,0,0,0,0,0,0,0,0,0,0,0,0,0,0,0,0,0,0,1
1,0,0,0,0,0,0,0,0,0,0,0,0,0,0,0,0,0,0,0,1
1,0,6,0,0,0,6,0,0,0,6,0,0,0,6,0,0,0,6,0,1
1,0,0,0,0,0,0,0,0,0,0,0,0,0,0,0,0,0,0,0,1
1,1,1,1,1,1,1,1,1,1,1,1,1,1,1,1,1,1,1,1,1
endlayer

layer
1,1,1,1,1,1,1,1,1,1,1,1,1,1,1,1,1,1,1,1,1
1,0,0,0,0,0,0,0,0,0,0,0,0,0,0,0,0,0,0,0,1
1,0,6,0,0,0,6,0,0,0,6,0,0,0,6,0,0,0,6,0,1
1,0,0,0,0,0,0,0,0,0,0,0,0,0,0,0,0,0,0,0,1
1,0,0,0,0,0,0,0,0,0,0,0,0,0,0,0,0,0,0,0,1
1,0,0,0,0,0,0,0,0,0,0,0,0,0,0,0,0,0,0,0,1
1,0,6,0,0,0,0,0,0,0,0,0,0,0,0,0,0,0,6,0,1
1,0,0,0,0,0,0,0,0,0,0,0,0,0,0,0,0,0,0,8,1
1,0,0,0,0,0,0,0,4,0,0,0,4,0,0,0,0,0,0,10,1
1,0,0,0,0,0,0,0,0,0,0,0,0,0,0,0,0,0,0,0,1
1,0,6,0,0,0,0,0,0,0,0,0,0,0,0,0,0,0,6,0,1
1,0,0,0,0,0,0,0,0,0,0,0,0,0,0,0,0,0,0,0,1
1,13,0,0,0,0,0,0,4,0,0,0,4,0,0,0,0,0,0,0,1
1,17,0,0,0,0,0,0,0,0,0,0,0,0,0,0,0,0,0,0,1
1,0,6,0,0,0,0,0,0,0,0,0,0,0,0,0,0,0,6,0,1
1,0,0,0,0,0,0,0,0,0,0,0,0,0,0,0,0,0,0,0,1
1,0,0,0,0,0,0,0,0,0,0,0,0,0,0,0,0,0,0,0,1
1,0,0,0,0,0,0,0,0,0,0,0,0,0,0,0,0,0,0,0,1
1,0,6,0,0,0,6,0,0,0,6,0,0,0,6,0,0,0,6,0,1
1,0,0,0,0,0,0,0,0,0,0,0,0,0,0,0,0,0,0,0,1
1,1,1,1,1,1,1,1,1,1,1,1,1,1,1,1,1,1,1,1,1
endlayer

layer
1,1,1,1,1,1,1,1,1,1,1,1,1,1,1,1,1,1,1,1,1
1,0,0,0,0,0,0,0,0,0,0,0,0,0,0,0,0,0,0,0,1
1,0,18,0,0,0,18,0,0,0,18,0,0,0,18,0,0,0,18,0,1
1,0,0,0,0,0,0,0,0,0,0,0,0,0,0,0,0,0,0,0,1
1,0,0,0,0,0,0,0,0,0,0,0,0,0,0,0,0,0,0,0,1
1,0,0,0,0,0,0,0,0,0,0,0,0,0,0,0,0,0,0,0,1
1,0,18,0,0,0,0,20,19,19,0,0,0,0,0,0,0,0,18,0,1
1,0,0,0,0,0,20,20,20,19,0,0,0,0,0,0,0,0,0,0,1
1,0,0,0,0,0,20,20,4,20,0,0,4,0,0,0,0,0,0,8,1
1,0,0,0,0,0,20,20,20,20,0,0,0,0,0,0,0,0,0,10,1
1,0,18,0,0,0,0,19,20,20,0,20,20,20,0,0,0,0,18,0,1
1,13,0,0,0,0,0,0,0,0,0,20,20,20,20,0,0,0,0,0,1
1,17,0,0,0,0,0,0,4,0,0,20,4,20,20,0,0,0,0,0,1
1,0,0,0,0,0,0,0,0,0,0,20,20,20,20,0,0,0,0,0,1
1,0,18,0,0,0,0,0,0,0,0,20,20,20,0,0,0,0,18,0,1
1,0,0,0,0,0,0,0,0,0,0,0,0,0,0,0,0,0,0,0,1
1,0,0,0,0,0,0,0,0,0,0,0,0,0,0,0,0,0,0,0,1
1,0,0,0,0,0,0,0,0,0,0,0,0,0,0,0,0,0,0,0,1
1,0,18,0,0,0,18,0,0,0,18,0,0,0,18,0,0,0,18,0,1
1,0,0,0,0,0,0,0,0,0,0,0,0,0,0,0,0,0,0,0,1
1,1,1,1,1,1,1,1,1,1,1,1,1,1,1,1,1,1,1,1,1
endlayer

layer
6,6,6,6,6,6,6,6,6,6,6,6,6,6,6,6,6,6,6,6,6
6,6,6,6,6,6,6,6,6,6,6,6,6,6,6,6,6,6,6,6,6
6,6,6,6,6,6,6,6,6,6,6,6,6,6,6,6,6,6,6,6,6
6,6,6,21,10,10,10,10,10,10,10,10,10,10,10,10,10,21,6,6,6
6,6,6,23,0,0,0,0,0,0,0,0,0,0,0,0,0,22,6,6,6
6,6,6,23,0,0,0,0,0,0,0,0,0,0,0,0,0,22,6,6,6
6,6,6,23,0,0,0,20,19,19,0,20,20,20,0,0,0,22,6,6,6
6,6,6,23,0,0,20,20,20,19,20,20,20,20,20,0,0,22,6,0,6
6,6,6,23,0,0,20,20,4,20,20,20,4,20,20,0,0,22,6,0,6
6,6,6,23,0,0,20,20,20,20,20,20,20,20,20,0,0,22,6,8,6
6,6,6,23,0,0,0,19,20,20,0,20,20,20,20,0,0,22,6,6,6
6,17,6,23,0,0,19,19,20,20,20,20,20,20,20,0,0,22,6,6,6
6,0,6,23,0,0,20,20,4,20,20,20,4,20,20,0,0,22,6,6,6
6,0,6,23,0,0,20,19,20,20,20,20,20,20,20,0,0,22,6,6,6
6,0,6,23,0,0,0,19,20,20,0,20,20,20,0,0,0,22,6,6,6
6,6,6,23,0,0,0,0,0,0,0,0,0,0,0,0,0,22,6,6,6
6,6,6,23,0,0,0,0,0,0,0,0,0,0,0,0,0,22,6,6,6
6,6,6,21,13,13,13,13,13,13,13,13,13,13,13,13,13,21,6,6,6
6,6,6,6,6,6,6,6,6,6,6,6,6,6,6,6,6,6,6,6,6
6,6,6,6,6,6,6,6,6,6,6,6,6,6,6,6,6,6,6,6,6
6,6,6,6,6,6,6,6,6,6,6,6,6,6,6,6,6,6,6,6,6
endlayer

layer
6,6,6,6,6,6,6,6,6,6,6,6,6,6,6,6,6,6,6,6,6
6,0,0,0,0,0,0,0,0,0,0,0,0,0,0,0,0,0,0,0,6
6,0,0,0,0,0,0,0,0,0,0,0,0,0,0,0,0,0,0,0,6
6,0,0,6,24,24,24,24,24,24,24,24,24,24,24,24,24,6,0,0,6
6,0,0,17,0,0,0,0,0,0,0,0,0,0,0,0,0,8,0,0,6
6,0,0,17,0,0,0,0,0,0,0,0,0,0,0,0,0,8,0,0,6
6,0,0,17,0,0,0,0,0,0,0,20,20,20,0,0,0,8,0,0,6
6,0,0,17,0,0,0,20,20,20,20,20,20,20,20,0,0,8,0,0,6
6,0,0,17,0,0,0,20,20,20,20,20,4,20,20,0,0,8,0,0,6
6,0,0,17,0,0,0,20,20,20,20,20,20,20,20,0,0,8,0,0,6
6,0,0,17,0,0,0,20,20,20,0,20,20,20,0,0,0,8,0,0,6
6,0,0,17,0,0,19,19,19,20,20,20,20,20,0,0,0,8,0,0,6
6,0,0,17,0,0,19,19,4,20,20,20,20,20,0,0,0,8,0,0,6
6,0,0,17,0,0,19,19,19,20,20,20,20,20,0,0,0,8,0,0,6
6,0,0,17,0,0,0,19,20,20,0,0,0,0,0,0,0,8,0,0,6
6,0,0,17,0,0,0,0,0,0,0,0,0,0,0,0,0,8,0,0,6
6,0,0,17,0,0,0,0,0,0,0,0,0,0,0,0,0,8,0,0,6
6,0,0,6,25,25,25,25,25,25,25,25,25,25,25,25,25,6,0,0,6
6,0,0,0,0,0,0,0,0,0,0,0,0,0,0,0,0,0,0,0,6
6,0,0,0,0,0,0,0,0,0,0,0,0,0,0,0,0,0,0,0,6
6,6,6,6,6,6,6,6,6,6,6,6,6,6,6,6,6,6,6,6,6
endlayer

layer
1,1,1,1,1,1,1,1,1,1,1,1,1,1,1,1,1,1,1,1,1
1,0,0,0,0,0,0,0,0,0,0,0,0,0,0,0,0,0,0,0,1
1,0,0,0,0,0,0,0,0,0,0,0,0,0,0,0,0,0,0,0,1
1,0,0,6,26,26,26,26,26,26,26,26,26,26,26,26,26,6,0,0,1
1,0,0,26,0,0,0,0,0,0,0,0,0,0,0,0,0,26,0,0,1
1,0,0,26,0,0,0,0,0,0,0,0,0,0,0,0,0,26,0,0,1
1,0,0,26,0,0,0,0,0,0,0,0,0,0,0,0,0,26,0,0,1
1,0,0,26,0,0,0,0,20,0,0,20,20,20,0,0,0,26,0,0,1
1,0,0,26,0,0,0,20,20,20,0,20,20,20,0,0,0,26,0,0,1
1,0,0,26,0,0,0,0,20,0,0,20,20,20,0,0,0,26,0,0,1
1,0,0,26,0,0,0,0,0,0,0,0,0,0,0,0,0,26,0,0,1
1,0,0,26,0,0,0,20,19,20,0,0,20,0,0,0,0,26,0,0,1
1,0,0,26,0,0,0,20,19,20,0,20,20,20,0,0,0,26,0,0,1
1,0,0,26,0,0,0,20,20,20,0,0,20,0,0,0,0,26,0,0,1
1,0,0,26,0,0,0,0,0,0,0,0,0,0,0,0,0,26,0,0,1
1,0,0,26,0,0,0,0,0,0,0,0,0,0,0,0,0,26,0,0,1
1,0,0,26,0,0,0,0,0,0,0,0,0,0,0,0,0,26,0,0,1
1,0,0,6,26,26,26,26,26,26,26,26,26,26,26,26,26,6,0,0,1
1,0,0,0,0,0,0,0,0,0,0,0,0,0,0,0,0,0,0,0,1
1,0,0,0,0,0,0,0,0,0,0,0,0,0,0,0,0,0,0,0,1
1,1,1,1,1,1,1,1,1,1,1,1,1,1,1,1,1,1,1,1,1
endlayer

layer
24,8,8,8,8,8,8,8,8,8,8,8,8,8,8,8,8,8,8,8,8
24,10,10,10,10,10,10,10,10,10,10,10,10,10,10,10,10,10,10,22,25
24,23,0,0,0,0,0,0,0,0,0,0,0,0,0,0,0,0,0,22,25
24,23,0,18,0,0,0,0,0,0,0,0,0,0,0,0,0,18,0,22,25
24,23,0,0,0,0,0,0,0,0,0,0,0,0,0,0,0,0,0,22,25
24,23,0,0,0,0,0,0,0,0,0,0,0,0,0,0,0,0,0,22,25
24,23,0,0,0,0,0,0,0,0,0,0,0,0,0,0,0,0,0,22,25
24,23,0,0,0,0,0,0,0,0,0,0,20,0,0,0,0,0,0,22,25
24,23,0,0,0,0,0,0,0,0,0,20,20,20,0,0,0,0,0,22,25
24,23,0,0,0,0,0,0,0,0,0,0,20,0,0,0,0,0,0,22,25
24,23,0,0,0,0,0,0,0,0,0,0,0,0,0,0,0,0,0,22,25
24,23,0,0,0,0,0,0,20,0,0,0,0,0,0,0,0,0,0,22,25
24,23,0,0,0,0,0,20,20,20,0,0,0,0,0,0,0,0,0,22,25
24,23,0,0,0,0,0,0,20,0,0,0,0,0,0,0,0,0,0,22,25
24,23,0,0,0,0,0,0,0,0,0,0,0,0,0,0,0,0,0,22,25
24,23,0,0,0,0,0,0,0,0,0,0,0,0,0,0,0,0,0,22,25
24,23,0,0,0,0,0,0,0,0,0,0,0,0,0,0,0,0,0,22,25
24,23,0,18,0,0,0,0,0,0,0,0,0,0,0,0,0,18,0,22,25
24,23,0,0,0,0,0,0,0,0,0,0,0,0,0,0,0,0,0,22,25
24,13,13,13,13,13,13,13,13,13,13,13,13,13,13,13,13,13,13,13,25
17,17,17,17,17,17,17,17,17,17,17,17,17,17,17,17,17,17,17,17,17
endlayer

layer
0,0,0,0,0,0,0,0,0,0,0,0,0,0,0,0,0,0,0,0,0
0,24,8,8,8,8,8,8,8,8,8,8,8,8,8,8,8,8,8,8,0
0,24,23,10,10,10,0,0,0,0,0,0,0,0,0,10,10,10,22,25,0
0,24,23,6,0,0,0,0,0,0,0,0,0,0,0,0,0,6,22,25,0
0,24,23,0,0,0,0,0,0,0,0,0,0,0,0,0,0,0,22,25,0
0,24,23,0,0,0,0,0,0,0,0,0,0,0,0,0,0,0,22,25,0
0,24,0,0,0,0,0,0,0,0,0,0,0,0,0,0,0,0,0,25,0
0,24,0,0,0,0,0,0,0,0,0,0,0,0,0,0,0,0,0,25,0
0,24,0,0,0,0,0,0,0,0,0,0,0,0,0,0,0,0,0,25,0
0,24,0,0,0,0,0,0,0,0,0,0,0,0,0,0,0,0,0,25,0
0,24,0,0,0,0,0,0,0,0,0,0,0,0,0,0,0,0,0,25,0
0,24,0,0,0,0,0,0,0,0,0,0,0,0,0,0,0,0,0,25,0
0,24,0,0,0,0,0,0,0,0,0,0,0,0,0,0,0,0,0,25,0
0,24,0,0,0,0,0,0,0,0,0,0,0,0,0,0,0,0,0,25,0
0,24,0,0,0,0,0,0,0,0,0,0,0,0,0,0,0,0,0,25,0
0,24,23,0,0,0,0,0,0,0,0,0,0,0,0,0,0,0,22,25,0
0,24,23,0,0,0,0,0,0,0,0,0,0,0,0,0,0,0,22,25,0
0,24,23,6,0,0,0,0,0,0,0,0,0,0,0,0,0,6,22,25,0
0,24,23,13,13,13,0,0,0,0,0,0,0,0,0,13,13,13,13,25,0
0,24,17,17,17,17,17,17,17,17,17,17,17,17,17,17,17,17,17,25,0
0,0,0,0,0,0,0,0,0,0,0,0,0,0,0,0,0,0,0,0,0
endlayer

layer
0,0,0,0,0,0,0,0,0,0,0,0,0,0,0,0,0,0,0,0,0
0,0,0,0,0,0,0,0,0,0,0,0,0,0,0,0,0,0,0,0,0
0,0,8,8,8,8,27,27,27,27,27,27,27,27,27,8,8,8,8,0,0
0,0,24,6,10,10,0,0,0,0,0,0,0,0,0,10,10,6,25,0,0
0,0,24,23,0,0,0,0,0,0,0,0,0,0,0,0,0,22,25,0,0
0,0,24,23,0,0,0,0,0,0,0,0,0,0,0,0,0,22,25,0,0
0,0,27,0,0,0,0,0,0,0,0,0,0,0,0,0,0,0,27,0,0
0,0,27,0,0,0,0,0,0,0,0,0,0,0,0,0,0,0,27,0,0
0,0,27,0,0,0,0,0,0,0,0,0,0,0,0,0,0,0,27,0,0
0,0,27,0,0,0,0,0,0,0,0,0,0,0,0,0,0,0,27,0,0
0,0,27,0,0,0,0,0,0,0,0,0,0,0,0,0,0,0,27,0,0
0,0,27,0,0,0,0,0,0,0,0,0,0,0,0,0,0,0,27,0,0
0,0,27,0,0,0,0,0,0,0,0,0,0,0,0,0,0,0,27,0,0
0,0,27,0,0,0,0,0,0,0,0,0,0,0,0,0,0,0,27,0,0
0,0,27,0,0,0,0,0,0,0,0,0,0,0,0,0,0,0,27,0,0
0,0,24,23,0,0,0,0,0,0,0,0,0,0,0,0,0,22,25,0,0
0,0,24,23,0,0,0,0,0,0,0,0,0,0,0,0,0,22,25,0,0
0,0,24,6,13,13,0,0,0,0,0,0,0,0,0,13,13,6,25,0,0
0,0,17,17,17,17,27,27,27,27,27,27,27,27,27,17,17,17,25,0,0
0,0,0,0,0,0,0,0,0,0,0,0,0,0,0,0,0,0,0,0,0
0,0,0,0,0,0,0,0,0,0,0,0,0,0,0,0,0,0,0,0,0
endlayer

layer
0,0,0,0,0,0,0,0,0,0,0,0,0,0,0,0,0,0,0,0,0
0,0,0,0,0,0,0,0,0,0,0,0,0,0,0,0,0,0,0,0,0
0,0,0,0,0,0,0,0,0,0,0,0,0,0,0,0,0,0,0,0,0
0,0,0,8,8,8,8,27,27,27,27,27,27,27,8,8,8,8,0,0,0
0,0,0,24,10,10,10,0,0,0,0,0,0,0,10,10,22,25,0,0,0
0,0,0,24,23,0,0,0,0,0,0,0,0,0,0,0,22,25,0,0,0
0,0,0,24,23,0,0,0,0,0,0,0,0,0,0,0,22,25,0,0,0
0,0,0,27,0,0,0,0,0,0,0,0,0,0,0,0,0,27,0,0,0
0,0,0,27,0,0,0,0,0,0,0,0,0,0,0,0,0,27,0,0,0
0,0,0,27,0,0,0,0,0,0,0,0,0,0,0,0,0,27,0,0,0
0,0,0,27,0,0,0,0,0,0,0,0,0,0,0,0,0,27,0,0,0
0,0,0,27,0,0,0,0,0,0,0,0,0,0,0,0,0,27,0,0,0
0,0,0,27,0,0,0,0,0,0,0,0,0,0,0,0,0,27,0,0,0
0,0,0,27,0,0,0,0,0,0,0,0,0,0,0,0,0,27,0,0,0
0,0,0,24,23,0,0,0,0,0,0,0,0,0,0,0,22,25,0,0,0
0,0,0,24,23,0,0,0,0,0,0,0,0,0,0,0,22,25,0,0,0
0,0,0,24,23,13,13,0,0,0,0,0,0,0,13,13,22,25,0,0,0
0,0,0,17,17,17,17,27,27,27,27,27,27,27,17,17,17,25,0,0,0
0,0,0,0,0,0,0,0,0,0,0,0,0,0,0,0,0,0,0,0,0
0,0,0,0,0,0,0,0,0,0,0,0,0,0,0,0,0,0,0,0,0
0,0,0,0,0,0,0,0,0,0,0,0,0,0,0,0,0,0,0,0,0
endlayer

layer
0,0,0,0,0,0,0,0,0,0,0,0,0,0,0,0,0,0,0,0,0
0,0,0,0,0,0,0,0,0,0,0,0,0,0,0,0,0,0,0,0,0
0,0,0,0,0,0,0,0,0,0,0,0,0,0,0,0,0,0,0,0,0
0,0,0,0,0,0,0,0,0,0,0,0,0,0,0,0,0,0,0,0,0
0,0,0,0,24,8,8,8,27,27,27,27,27,8,8,8,8,0,0,0,0
0,0,0,0,24,23,10,10,0,0,0,0,0,10,10,22,25,0,0,0,0
0,0,0,0,24,23,0,0,0,0,0,0,0,0,0,22,25,0,0,0,0
0,0,0,0,24,23,0,0,0,0,0,0,0,0,0,22,25,0,0,0,0
0,0,0,0,27,0,0,0,0,0,0,0,0,0,0,0,27,0,0,0,0
0,0,0,0,27,0,0,0,0,0,0,0,0,0,0,0,27,0,0,0,0
0,0,0,0,27,0,0,0,0,0,0,0,0,0,0,0,27,0,0,0,0
0,0,0,0,27,0,0,0,0,0,0,0,0,0,0,0,27,0,0,0,0
0,0,0,0,27,0,0,0,0,0,0,0,0,0,0,0,27,0,0,0,0
0,0,0,0,24,23,0,0,0,0,0,0,0,0,0,22,25,0,0,0,0
0,0,0,0,24,23,0,0,0,0,0,0,0,0,0,22,25,0,0,0,0
0,0,0,0,24,23,13,13,0,0,0,0,0,13,13,13,25,0,0,0,0
0,0,0,0,17,17,17,17,27,27,27,27,27,17,17,17,17,0,0,0,0
0,0,0,0,0,0,0,0,0,0,0,0,0,0,0,0,0,0,0,0,0
0,0,0,0,0,0,0,0,0,0,0,0,0,0,0,0,0,0,0,0,0
0,0,0,0,0,0,0,0,0,0,0,0,0,0,0,0,0,0,0,0,0
0,0,0,0,0,0,0,0,0,0,0,0,0,0,0,0,0,0,0,0,0
endlayer

layer
0,0,0,0,0,0,0,0,0,0,0,0,0,0,0,0,0,0,0,0,0
0,0,0,0,0,0,0,0,0,0,0,0,0,0,0,0,0,0,0,0,0
0,0,0,0,0,0,0,0,0,0,0,0,0,0,0,0,0,0,0,0,0
0,0,0,0,0,0,0,0,0,0,0,0,0,0,0,0,0,0,0,0,0
0,0,0,0,0,0,0,0,0,0,0,0,0,0,0,0,0,0,0,0,0
0,0,0,0,0,8,8,8,8,27,27,27,8,8,8,25,0,0,0,0,0
0,0,0,0,0,24,23,10,10,0,0,0,10,10,22,25,0,0,0,0,0
0,0,0,0,0,24,23,0,0,0,0,0,0,0,22,25,0,0,0,0,0
0,0,0,0,0,24,23,0,0,0,0,0,0,0,22,25,0,0,0,0,0
0,0,0,0,0,27,0,0,0,0,0,0,0,0,0,27,0,0,0,0,0
0,0,0,0,0,27,0,0,0,0,0,0,0,0,0,27,0,0,0,0,0
0,0,0,0,0,27,0,0,0,0,0,0,0,0,0,27,0,0,0,0,0
0,0,0,0,0,24,23,0,0,0,0,0,0,0,22,25,0,0,0,0,0
0,0,0,0,0,24,23,0,0,0,0,0,0,0,22,25,0,0,0,0,0
0,0,0,0,0,24,13,13,13,0,0,0,13,13,22,25,0,0,0,0,0
0,0,0,0,0,24,17,17,17,27,27,27,17,17,17,25,0,0,0,0,0
0,0,0,0,0,0,0,0,0,0,0,0,0,0,0,0,0,0,0,0,0
0,0,0,0,0,0,0,0,0,0,0,0,0,0,0,0,0,0,0,0,0
0,0,0,0,0,0,0,0,0,0,0,0,0,0,0,0,0,0,0,0,0
0,0,0,0,0,0,0,0,0,0,0,0,0,0,0,0,0,0,0,0,0
0,0,0,0,0,0,0,0,0,0,0,0,0,0,0,0,0,0,0,0,0
endlayer

layer
0,0,0,0,0,0,0,0,0,0,0,0,0,0,0,0,0,0,0,0,0
0,0,0,0,0,0,0,0,0,0,0,0,0,0,0,0,0,0,0,0,0
0,0,0,0,0,0,0,0,0,0,0,0,0,0,0,0,0,0,0,0,0
0,0,0,0,0,0,0,0,0,0,0,0,0,0,0,0,0,0,0,0,0
0,0,0,0,0,0,0,0,0,0,0,0,0,0,0,0,0,0,0,0,0
0,0,0,0,0,0,0,0,0,0,0,0,0,0,0,0,0,0,0,0,0
0,0,0,0,0,0,8,8,8,8,27,8,8,8,8,0,0,0,0,0,0
0,0,0,0,0,0,24,10,10,10,10,10,10,22,25,0,0,0,0,0,0
0,0,0,0,0,0,24,23,0,0,0,0,0,22,25,0,0,0,0,0,0
0,0,0,0,0,0,24,23,0,0,0,0,0,22,25,0,0,0,0,0,0
0,0,0,0,0,0,27,23,0,0,0,0,0,22,27,0,0,0,0,0,0
0,0,0,0,0,0,24,23,0,0,0,0,0,22,25,0,0,0,0,0,0
0,0,0,0,0,0,24,23,0,0,0,0,0,22,25,0,0,0,0,0,0
0,0,0,0,0,0,24,13,13,13,13,13,13,13,25,0,0,0,0,0,0
0,0,0,0,0,0,17,17,17,17,27,17,17,17,17,0,0,0,0,0,0
0,0,0,0,0,0,0,0,0,0,0,0,0,0,0,0,0,0,0,0,0
0,0,0,0,0,0,0,0,0,0,0,0,0,0,0,0,0,0,0,0,0
0,0,0,0,0,0,0,0,0,0,0,0,0,0,0,0,0,0,0,0,0
0,0,0,0,0,0,0,0,0,0,0,0,0,0,0,0,0,0,0,0,0
0,0,0,0,0,0,0,0,0,0,0,0,0,0,0,0,0,0,0,0,0
0,0,0,0,0,0,0,0,0,0,0,0,0,0,0,0,0,0,0,0,0
endlayer

layer
0,0,0,0,0,0,0,0,0,0,0,0,0,0,0,0,0,0,0,0,0
0,0,0,0,0,0,0,0,0,0,0,0,0,0,0,0,0,0,0,0,0
0,0,0,0,0,0,0,0,0,0,0,0,0,0,0,0,0,0,0,0,0
0,0,0,0,0,0,0,0,0,0,0,0,0,0,0,0,0,0,0,0,0
0,0,0,0,0,0,0,0,0,0,0,0,0,0,0,0,0,0,0,0,0
0,0,0,0,0,0,0,0,0,0,0,0,0,0,0,0,0,0,0,0,0
0,0,0,0,0,0,0,0,0,0,0,0,0,0,0,0,0,0,0,0,0
0,0,0,0,0,0,0,24,8,8,8,8,8,8,0,0,0,0,0,0,0
0,0,0,0,0,0,0,24,10,10,10,10,10,25,0,0,0,0,0,0,0
0,0,0,0,0,0,0,24,23,0,0,0,22,25,0,0,0,0,0,0,0
0,0,0,0,0,0,0,24,23,0,0,0,22,25,0,0,0,0,0,0,0
0,0,0,0,0,0,0,24,23,0,0,0,22,25,0,0,0,0,0,0,0
0,0,0,0,0,0,0,24,13,13,13,13,13,25,0,0,0,0,0,0,0
0,0,0,0,0,0,0,24,17,17,17,17,17,17,0,0,0,0,0,0,0
0,0,0,0,0,0,0,0,0,0,0,0,0,0,0,0,0,0,0,0,0
0,0,0,0,0,0,0,0,0,0,0,0,0,0,0,0,0,0,0,0,0
0,0,0,0,0,0,0,0,0,0,0,0,0,0,0,0,0,0,0,0,0
0,0,0,0,0,0,0,0,0,0,0,0,0,0,0,0,0,0,0,0,0
0,0,0,0,0,0,0,0,0,0,0,0,0,0,0,0,0,0,0,0,0
0,0,0,0,0,0,0,0,0,0,0,0,0,0,0,0,0,0,0,0,0
0,0,0,0,0,0,0,0,0,0,0,0,0,0,0,0,0,0,0,0,0
endlayer

layer
0,0,0,0,0,0,0,0,0,0,0,0,0,0,0,0,0,0,0,0,0
0,0,0,0,0,0,0,0,0,0,0,0,0,0,0,0,0,0,0,0,0
0,0,0,0,0,0,0,0,0,0,0,0,0,0,0,0,0,0,0,0,0
0,0,0,0,0,0,0,0,0,0,0,0,0,0,0,0,0,0,0,0,0
0,0,0,0,0,0,0,0,0,0,0,0,0,0,0,0,0,0,0,0,0
0,0,0,0,0,0,0,0,0,0,0,0,0,0,0,0,0,0,0,0,0
0,0,0,0,0,0,0,0,0,0,0,0,0,0,0,0,0,0,0,0,0
0,0,0,0,0,0,0,0,0,0,0,0,0,0,0,0,0,0,0,0,0
0,0,0,0,0,0,0,0,24,8,8,8,8,0,0,0,0,0,0,0,0
0,0,0,0,0,0,0,0,24,23,10,22,25,0,0,0,0,0,0,0,0
0,0,0,0,0,0,0,0,24,23,0,22,25,0,0,0,0,0,0,0,0
0,0,0,0,0,0,0,0,24,23,13,13,25,0,0,0,0,0,0,0,0
0,0,0,0,0,0,0,0,17,17,17,17,17,0,0,0,0,0,0,0,0
0,0,0,0,0,0,0,0,0,0,0,0,0,0,0,0,0,0,0,0,0
0,0,0,0,0,0,0,0,0,0,0,0,0,0,0,0,0,0,0,0,0
0,0,0,0,0,0,0,0,0,0,0,0,0,0,0,0,0,0,0,0,0
0,0,0,0,0,0,0,0,0,0,0,0,0,0,0,0,0,0,0,0,0
0,0,0,0,0,0,0,0,0,0,0,0,0,0,0,0,0,0,0,0,0
0,0,0,0,0,0,0,0,0,0,0,0,0,0,0,0,0,0,0,0,0
0,0,0,0,0,0,0,0,0,0,0,0,0,0,0,0,0,0,0,0,0
0,0,0,0,0,0,0,0,0,0,0,0,0,0,0,0,0,0,0,0,0
endlayer

layer
0,0,0,0,0,0,0,0,0,0,0,0,0,0,0,0,0,0,0,0,0
0,0,0,0,0,0,0,0,0,0,0,0,0,0,0,0,0,0,0,0,0
0,0,0,0,0,0,0,0,0,0,0,0,0,0,0,0,0,0,0,0,0
0,0,0,0,0,0,0,0,0,0,0,0,0,0,0,0,0,0,0,0,0
0,0,0,0,0,0,0,0,0,0,0,0,0,0,0,0,0,0,0,0,0
0,0,0,0,0,0,0,0,0,0,0,0,0,0,0,0,0,0,0,0,0
0,0,0,0,0,0,0,0,0,0,0,0,0,0,0,0,0,0,0,0,0
0,0,0,0,0,0,0,0,0,0,0,0,0,0,0,0,0,0,0,0,0
0,0,0,0,0,0,0,0,0,0,0,0,0,0,0,0,0,0,0,0,0
0,0,0,0,0,0,0,0,0,24,8,25,0,0,0,0,0,0,0,0,0
0,0,0,0,0,0,0,0,0,24,27,25,0,0,0,0,0,0,0,0,0
0,0,0,0,0,0,0,0,0,17,17,17,0,0,0,0,0,0,0,0,0
0,0,0,0,0,0,0,0,0,0,0,0,0,0,0,0,0,0,0,0,0
0,0,0,0,0,0,0,0,0,0,0,0,0,0,0,0,0,0,0,0,0
0,0,0,0,0,0,0,0,0,0,0,0,0,0,0,0,0,0,0,0,0
0,0,0,0,0,0,0,0,0,0,0,0,0,0,0,0,0,0,0,0,0
0,0,0,0,0,0,0,0,0,0,0,0,0,0,0,0,0,0,0,0,0
0,0,0,0,0,0,0,0,0,0,0,0,0,0,0,0,0,0,0,0,0
0,0,0,0,0,0,0,0,0,0,0,0,0,0,0,0,0,0,0,0,0
0,0,0,0,0,0,0,0,0,0,0,0,0,0,0,0,0,0,0,0,0
0,0,0,0,0,0,0,0,0,0,0,0,0,0,0,0,0,0,0,0,0
endlayer

