
# Created by Ruins mod version 17.1 Ingame Parser
# authoring Player: ST753M

weight=1
uniqueMinDistance=1000
embed_into_distance=4
acceptable_target_blocks=grass,dirt,coarse_dirt,podzol,stone,biomesoplenty:grass,biomesoplenty:dirt
unacceptable_target_blocks=flowing_water,water,flowing_lava,lava
dimensions=15,19,15
allowable_overhang=4
max_leveling=2
leveling_buffer=0
preserve_water=0
preserve_lava=0

biomesToSpawnIn=forest,maple_woods,seasonal_forest,grove,shield,smaller_extreme_hills,plains,prairie,shrubland,chaparral,grassland,meadow,orchard,rocky_plains,rocky_plateau,mutated_plains,mystic_grove,savanna,savanna_rock,mutated_savanna,mutated_savanna_rock,brushland,steppe,tundra

=0,100,air
rule1=0,100,preserveBlock
rule2=0,100,minecraft:log-0
rule3=0,100,minecraft:dirt-1
rule4=0,100,minecraft:log-8
rule5=0,100,minecraft:log-4
rule6=0,100,minecraft:planks-4
^0,100,minecraft:planks-4
^0,100,minecraft:planks-4
^0,100,minecraft:planks-4
^0,100,minecraft:hardened_clay-0
^0,100,minecraft:hardened_clay-0
^0,100,minecraft:planks-3
^0,100,minecraft:planks-0

rule7=0,70,CommandBlock:RUINSTRIGGER /summon horse ~ ~ ~:@-1,CommandBlock:RUINSTRIGGER /summon horse ~ ~ ~:@-1,CommandBlock:RUINSTRIGGER /summon donkey ~ ~ ~:@-1,CommandBlock:RUINSTRIGGER /summon mule ~ ~ ~:@-1,CommandBlock:RUINSTRIGGER /summon mule ~ ~ ~:@-1,CommandBlock:RUINSTRIGGER /summon llama ~ ~ ~:@-1
rule8=0,100,minecraft:spruce_fence-0
rule9=0,100,minecraft:spruce_fence_gate-1
rule10=0,100,minecraft:ladder-2
rule11=0,100,minecraft:spruce_fence_gate-3
rule12=0,100,minecraft:stained_glass_pane-8
rule13=0,100,minecraft:spruce_stairs-0
rule14=0,100,minecraft:spruce_stairs-5
rule15=0,100,minecraft:wooden_slab-9
rule16=0,100,minecraft:spruce_stairs-4
rule17=0,100,minecraft:spruce_stairs-1
rule18=0,100,minecraft:planks-1
rule19=0,100,minecraft:hay_block-0
rule20=0,100,minecraft:web-0,air,air
rule21=0,100,CommandBlock:RUINSTRIGGER /summon villager ~ ~1 ~ {Profession:3,Offers:{Recipes:[{rewardExp:0b,maxUses:2147483647,uses:0,buy:{id:"minecraft:emerald",Count:8b},sell:{id:"minecraft:saddle",Count:1b}},{rewardExp:0b,maxUses:2147483647,uses:0,buy:{id:"minecraft:iron_horse_armor",Count:1b},sell:{id:"minecraft:emerald",Count:2b}},{rewardExp:0b,maxUses:2147483647,uses:0,buy:{id:"minecraft:golden_horse_armor",Count:1b},sell:{id:"minecraft:emerald",Count:4b}},{rewardExp:0b,maxUses:2147483647,uses:0,buy:{id:"minecraft:diamond_horse_armor",Count:1b},sell:{id:"minecraft:emerald",Count:6b}}]}}:@-3
rule22=0,100,minecraft:wooden_slab-1

layer
1,1,1,1,1,1,1,1,1,1,1,1,1,1,1
1,2,1,1,1,2,1,1,1,2,1,1,1,2,1
1,1,2,2,2,2,2,2,2,2,2,2,2,1,1
1,1,2,3,3,3,3,3,3,3,3,3,2,1,1
1,1,2,3,3,3,3,3,3,3,3,3,2,1,1
1,2,2,3,3,3,3,3,3,3,3,3,2,2,1
1,1,2,3,3,3,3,3,3,3,3,3,2,1,1
1,1,2,3,3,3,3,3,3,3,3,3,2,1,1
1,1,2,3,3,3,3,3,3,3,3,3,2,1,1
1,1,2,3,3,3,3,3,3,3,3,3,2,1,1
1,1,2,3,3,3,3,3,3,3,3,3,2,1,1
1,1,2,3,3,3,3,3,3,3,3,3,2,1,1
1,1,2,3,3,3,3,3,3,3,3,3,2,1,1
1,2,2,3,3,3,3,3,3,3,3,3,2,2,1
1,1,2,3,3,3,3,3,3,3,3,3,2,1,1
1,1,2,3,3,3,3,3,3,3,3,3,2,1,1
1,1,2,2,2,2,2,2,2,2,2,2,2,1,1
1,2,1,1,1,2,1,1,1,2,1,1,1,2,1
1,1,1,1,1,1,1,1,1,1,1,1,1,1,1
endlayer

layer
1,1,1,1,1,1,1,1,1,1,1,1,1,1,1
1,2,1,1,1,2,1,1,1,2,1,1,1,2,1
1,1,2,2,2,2,2,2,2,2,2,2,2,1,1
1,1,2,3,3,3,3,3,3,3,3,3,2,1,1
1,1,2,3,3,3,3,3,3,3,3,3,2,1,1
1,2,2,3,3,3,3,3,3,3,3,3,2,2,1
1,1,2,3,3,3,3,3,3,3,3,3,2,1,1
1,1,2,3,3,3,3,3,3,3,3,3,2,1,1
1,1,2,3,3,3,3,3,3,3,3,3,2,1,1
1,1,2,3,3,3,3,3,3,3,3,3,2,1,1
1,1,2,3,3,3,3,3,3,3,3,3,2,1,1
1,1,2,3,3,3,3,3,3,3,3,3,2,1,1
1,1,2,3,3,3,3,3,3,3,3,3,2,1,1
1,2,2,3,3,3,3,3,3,3,3,3,2,2,1
1,1,2,3,3,3,3,3,3,3,3,3,2,1,1
1,1,2,3,3,3,3,3,3,3,3,3,2,1,1
1,1,2,2,2,2,2,2,2,2,2,2,2,1,1
1,2,1,1,1,2,1,1,1,2,1,1,1,2,1
1,1,1,1,1,1,1,1,1,1,1,1,1,1,1
endlayer

layer
1,1,1,1,1,1,1,1,1,1,1,1,1,1,1
1,2,1,1,1,2,1,1,1,2,1,1,1,2,1
1,1,3,3,3,3,3,3,3,3,3,3,3,1,1
1,1,3,3,3,3,3,3,3,3,3,3,3,1,1
1,1,3,3,3,3,3,3,3,3,3,3,3,1,1
1,2,3,3,3,3,3,3,3,3,3,3,3,2,1
1,1,3,3,3,3,3,3,3,3,3,3,3,1,1
1,1,3,3,3,3,3,3,3,3,3,3,3,1,1
1,1,3,3,3,3,3,3,3,3,3,3,3,1,1
1,1,3,3,3,3,3,3,3,3,3,3,3,1,1
1,1,3,3,3,3,3,3,3,3,3,3,3,1,1
1,1,3,3,3,3,3,3,3,3,3,3,3,1,1
1,1,3,3,3,3,3,3,3,3,3,3,3,1,1
1,2,3,3,3,3,3,3,3,3,3,3,3,2,1
1,1,3,3,3,3,3,3,3,3,3,3,3,1,1
1,1,3,3,3,3,3,3,3,3,3,3,3,1,1
1,1,3,3,3,3,3,3,3,3,3,3,3,1,1
1,2,1,1,1,2,1,1,1,2,1,1,1,2,1
1,1,1,1,1,1,1,1,1,1,1,1,1,1,1
endlayer

layer
1,1,1,1,1,1,1,1,1,1,1,1,1,1,1
1,2,4,4,4,2,4,4,4,2,4,4,4,2,1
1,5,3,3,3,3,3,3,3,3,3,3,3,5,1
1,5,3,3,3,3,3,3,3,3,3,3,3,5,1
1,5,3,3,3,3,3,3,3,3,3,3,3,5,1
1,2,3,3,3,3,3,3,3,3,3,3,3,2,1
1,5,3,3,3,3,3,3,3,3,3,3,3,5,1
1,5,3,3,3,3,3,3,3,3,3,3,3,5,1
1,5,3,3,3,3,3,3,3,3,3,3,3,5,1
1,5,3,3,3,3,3,3,3,3,3,3,3,5,1
1,5,3,3,3,3,3,3,3,3,3,3,3,5,1
1,5,3,3,3,3,3,3,3,3,3,3,3,5,1
1,5,3,3,3,3,3,3,3,3,3,3,3,5,1
1,2,3,3,3,3,3,3,3,3,3,3,3,2,1
1,5,3,3,3,3,3,3,3,3,3,3,3,5,1
1,5,3,3,3,3,3,3,3,3,3,3,3,5,1
1,5,3,3,3,3,3,3,3,3,3,3,3,5,1
1,2,4,4,4,2,4,4,4,2,4,4,4,2,1
1,1,1,1,1,1,1,1,1,1,1,1,1,1,1
endlayer

layer
1,1,1,1,1,1,1,1,1,1,1,1,1,1,1
1,2,6,6,6,2,6,6,6,2,6,6,6,2,1
1,6,0,0,0,6,0,0,0,6,0,0,0,6,1
1,6,0,7,0,6,0,7,0,6,0,7,0,6,1
1,6,0,0,0,6,0,0,0,6,0,0,0,6,1
1,2,8,9,8,2,8,9,8,2,8,9,8,2,1
1,6,10,0,0,0,0,0,0,0,0,0,0,6,1
0,8,0,0,0,0,0,0,0,0,0,0,0,8,0
0,0,0,0,0,0,0,0,0,0,0,0,0,0,0
0,0,0,0,0,0,0,0,0,0,0,0,0,0,0
0,0,0,0,0,0,0,0,0,0,0,0,0,0,0
0,8,0,0,0,0,0,0,0,0,0,0,0,8,0
1,6,0,0,0,0,0,0,0,0,0,0,0,6,1
1,2,8,11,8,2,8,11,8,2,8,11,8,2,1
1,6,0,0,0,6,0,0,0,6,0,0,0,6,1
1,6,0,7,0,6,0,7,0,6,0,7,0,6,1
1,6,0,0,0,6,0,0,0,6,0,0,0,6,1
1,2,6,6,6,2,6,6,6,2,6,6,6,2,1
1,1,1,1,1,1,1,1,1,1,1,1,1,1,1
endlayer

layer
1,1,1,1,1,1,1,1,1,1,1,1,1,1,1
1,2,6,12,6,2,6,12,6,2,6,12,6,2,1
1,6,0,0,0,6,0,0,0,6,0,0,0,6,1
1,12,0,0,0,6,0,0,0,6,0,0,0,12,1
1,6,0,0,0,6,0,0,0,6,0,0,0,6,1
1,2,0,0,0,2,0,0,0,2,0,0,0,2,1
1,6,10,0,0,0,0,0,0,0,0,0,0,6,1
0,8,0,0,0,0,0,0,0,0,0,0,0,8,0
0,0,0,0,0,0,0,0,0,0,0,0,0,0,0
0,0,0,0,0,0,0,0,0,0,0,0,0,0,0
0,0,0,0,0,0,0,0,0,0,0,0,0,0,0
0,8,0,0,0,0,0,0,0,0,0,0,0,8,0
1,6,0,0,0,0,0,0,0,0,0,0,0,6,1
1,2,0,0,0,2,0,0,0,2,0,0,0,2,1
1,6,0,0,0,6,0,0,0,6,0,0,0,6,1
1,12,0,0,0,6,0,0,0,6,0,0,0,12,1
1,6,0,0,0,6,0,0,0,6,0,0,0,6,1
1,2,6,12,6,2,6,12,6,2,6,12,6,2,1
1,1,1,1,1,1,1,1,1,1,1,1,1,1,1
endlayer

layer
1,1,1,1,1,1,1,1,1,1,1,1,1,1,1
1,2,6,12,6,2,6,12,6,2,6,12,6,2,1
1,6,0,0,0,8,0,0,0,8,0,0,0,6,1
1,12,0,0,0,8,0,0,0,8,0,0,0,12,1
1,6,0,0,0,8,0,0,0,8,0,0,0,6,1
1,2,0,0,0,2,0,0,0,2,0,0,0,2,1
1,6,10,0,0,0,0,0,0,0,0,0,0,6,1
0,8,0,0,0,0,0,0,0,0,0,0,0,8,0
0,0,0,0,0,0,0,0,0,0,0,0,0,0,0
0,0,0,0,0,0,0,0,0,0,0,0,0,0,0
0,0,0,0,0,0,0,0,0,0,0,0,0,0,0
0,8,0,0,0,0,0,0,0,0,0,0,0,8,0
1,6,0,0,0,0,0,0,0,0,0,0,0,6,1
1,2,0,0,0,2,0,0,0,2,0,0,0,2,1
1,6,0,0,0,8,0,0,0,8,0,0,0,6,1
1,12,0,0,0,8,0,0,0,8,0,0,0,12,1
1,6,0,0,0,8,0,0,0,8,0,0,0,6,1
1,2,6,12,6,2,6,12,6,2,6,12,6,2,1
1,1,1,1,1,1,1,1,1,1,1,1,1,1,1
endlayer

layer
13,13,13,13,13,13,13,13,13,13,13,13,13,13,13
14,2,4,4,4,2,4,4,4,2,4,4,4,2,14
1,5,15,15,15,5,15,15,15,5,15,15,15,5,1
1,5,15,15,15,5,15,15,15,5,15,15,15,5,1
1,5,15,15,15,5,15,15,15,5,15,15,15,5,1
1,2,4,4,4,2,4,4,4,2,4,4,4,2,1
1,5,10,15,15,5,0,0,0,5,15,15,15,5,1
1,5,15,15,15,5,0,0,0,5,15,15,15,5,1
0,5,15,15,15,5,0,0,0,5,15,15,15,5,0
0,5,15,15,15,5,0,0,0,5,15,15,15,5,0
0,5,15,15,15,5,0,0,0,5,15,15,15,5,0
1,5,15,15,15,5,0,0,0,5,15,15,15,5,1
1,5,15,15,15,5,0,0,0,5,15,15,15,5,1
1,2,4,4,4,2,4,4,4,2,4,4,4,2,1
1,5,15,15,15,5,15,15,15,5,15,15,15,5,1
1,5,15,15,15,5,15,15,15,5,15,15,15,5,1
1,5,15,15,15,5,15,15,15,5,15,15,15,5,1
16,2,4,4,4,2,4,4,4,2,4,4,4,2,16
17,17,17,17,17,17,17,17,17,17,17,17,17,17,17
endlayer

layer
1,1,1,1,1,1,1,1,1,1,1,1,1,1,1
13,13,13,13,13,13,13,13,13,13,13,13,13,13,13
14,6,18,18,18,18,18,18,18,18,18,18,18,6,14
1,6,0,0,0,0,0,19,19,0,0,0,0,6,1
1,6,0,0,0,0,0,19,0,0,0,0,0,6,1
1,2,0,0,0,2,0,0,0,2,0,0,20,2,1
1,6,10,0,0,0,0,0,0,0,0,0,0,6,1
1,6,0,0,0,0,0,0,0,0,0,0,0,6,1
1,6,0,0,0,0,0,0,0,19,0,0,0,6,1
1,2,0,0,0,2,0,0,0,2,0,0,0,2,1
1,6,19,19,0,0,0,0,0,0,0,0,0,6,1
1,6,0,0,0,19,0,0,0,0,0,21,0,6,1
1,6,0,0,19,0,0,0,0,0,0,0,0,6,1
1,2,0,0,19,2,0,0,0,2,0,0,0,2,1
1,6,0,0,0,0,0,0,0,0,0,0,19,6,1
1,6,0,0,0,0,0,0,0,0,0,0,0,6,1
16,6,18,18,18,18,18,18,18,18,18,18,18,6,16
17,17,17,17,17,17,17,17,17,17,17,17,17,17,17
1,1,1,1,1,1,1,1,1,1,1,1,1,1,1
endlayer

layer
1,1,1,1,1,1,1,1,1,1,1,1,1,1,1
1,1,1,1,1,1,1,1,1,1,1,1,1,1,1
13,13,13,13,13,13,13,13,13,13,13,13,13,13,13
14,6,0,0,0,0,0,0,0,0,0,0,0,6,14
1,6,0,0,0,0,0,0,0,0,0,0,0,6,1
1,2,0,0,0,2,0,0,0,2,0,0,0,2,1
1,6,10,0,0,0,0,0,0,0,0,0,0,6,1
1,12,0,0,0,0,0,0,0,0,0,0,0,12,1
1,6,0,0,0,0,0,0,0,0,0,0,0,6,1
1,2,20,0,0,2,0,0,0,2,0,0,0,2,1
1,6,0,0,0,0,0,0,0,0,0,0,0,6,1
1,12,0,0,0,0,0,0,0,0,0,0,0,12,1
1,6,0,0,19,0,0,0,0,0,0,0,0,6,1
1,2,0,0,0,2,0,0,0,2,0,0,0,2,1
1,6,0,0,0,0,0,0,0,0,0,0,0,6,1
16,6,0,0,0,0,0,0,0,0,20,0,0,6,16
17,17,17,17,17,17,17,17,17,17,17,17,17,17,17
1,1,1,1,1,1,1,1,1,1,1,1,1,1,1
1,1,1,1,1,1,1,1,1,1,1,1,1,1,1
endlayer

layer
1,1,1,1,1,1,1,1,1,1,1,1,1,1,1
1,1,1,1,1,1,1,1,1,1,1,1,1,1,1
1,1,1,1,1,1,1,1,1,1,1,1,1,1,1
13,13,13,13,13,13,13,13,13,13,13,13,13,13,13
14,6,0,0,0,0,0,0,0,0,0,0,20,6,14
1,2,0,0,0,2,0,0,0,2,0,0,0,2,1
1,6,10,0,0,0,0,0,0,0,0,0,0,6,1
1,12,0,0,0,0,0,0,0,0,0,0,0,12,1
1,6,0,0,0,0,0,0,0,0,0,0,0,6,1
1,2,0,20,0,2,0,0,0,2,0,0,0,2,1
1,6,0,0,0,0,0,0,0,0,0,0,0,6,1
1,12,0,0,0,0,0,0,0,0,0,0,0,12,1
1,6,0,0,0,0,0,0,0,0,0,0,0,6,1
1,2,0,0,0,2,0,0,0,2,0,0,0,2,1
16,6,0,0,0,0,0,0,20,0,0,0,0,6,16
17,17,17,17,17,17,17,17,17,17,17,17,17,17,17
1,1,1,1,1,1,1,1,1,1,1,1,1,1,1
1,1,1,1,1,1,1,1,1,1,1,1,1,1,1
1,1,1,1,1,1,1,1,1,1,1,1,1,1,1
endlayer

layer
1,1,1,1,1,1,1,1,1,1,1,1,1,1,1
1,1,1,1,1,1,1,1,1,1,1,1,1,1,1
1,1,1,1,1,1,1,1,1,1,1,1,1,1,1
1,1,1,1,1,1,1,1,1,1,1,1,1,1,1
13,13,13,13,13,13,13,13,13,13,13,13,13,13,13
14,2,0,0,0,2,0,0,20,2,0,0,0,2,14
1,5,0,0,0,20,0,0,0,0,0,0,0,5,1
1,5,0,0,0,0,0,0,0,0,0,0,0,5,1
1,5,20,0,0,0,0,0,0,0,0,0,0,5,1
1,2,4,4,4,2,4,4,4,2,4,4,4,2,1
1,5,0,0,0,0,0,0,20,0,0,0,0,5,1
1,5,0,0,0,0,0,0,0,0,0,0,0,5,1
1,5,0,0,0,0,0,0,0,0,0,0,0,5,1
16,2,20,0,0,2,20,0,0,2,0,0,0,2,16
17,17,17,17,17,17,17,17,17,17,17,17,17,17,17
1,1,1,1,1,1,1,1,1,1,1,1,1,1,1
1,1,1,1,1,1,1,1,1,1,1,1,1,1,1
1,1,1,1,1,1,1,1,1,1,1,1,1,1,1
1,1,1,1,1,1,1,1,1,1,1,1,1,1,1
endlayer

layer
1,1,1,1,1,1,1,1,1,1,1,1,1,1,1
1,1,1,1,1,1,1,1,1,1,1,1,1,1,1
1,1,1,1,1,1,1,1,1,1,1,1,1,1,1
1,1,1,1,1,1,1,1,1,1,1,1,1,1,1
1,1,1,1,1,1,1,1,1,1,1,1,1,1,1
22,22,22,22,22,22,22,22,22,22,22,22,22,22,22
18,18,18,18,18,18,18,18,18,18,18,18,18,18,18
15,6,15,15,15,15,15,15,15,15,15,15,15,6,15
1,6,0,0,0,20,0,0,0,0,0,0,20,6,1
1,6,20,0,0,2,0,20,0,2,0,0,0,6,1
1,6,0,0,0,20,0,0,0,20,0,0,0,6,1
15,6,15,15,15,15,15,15,15,15,15,15,15,6,15
18,18,18,18,18,18,18,18,18,18,18,18,18,18,18
22,22,22,22,22,22,22,22,22,22,22,22,22,22,22
1,1,1,1,1,1,1,1,1,1,1,1,1,1,1
1,1,1,1,1,1,1,1,1,1,1,1,1,1,1
1,1,1,1,1,1,1,1,1,1,1,1,1,1,1
1,1,1,1,1,1,1,1,1,1,1,1,1,1,1
1,1,1,1,1,1,1,1,1,1,1,1,1,1,1
endlayer

layer
1,1,1,1,1,1,1,1,1,1,1,1,1,1,1
1,1,1,1,1,1,1,1,1,1,1,1,1,1,1
1,1,1,1,1,1,1,1,1,1,1,1,1,1,1
1,1,1,1,1,1,1,1,1,1,1,1,1,1,1
1,1,1,1,1,1,1,1,1,1,1,1,1,1,1
1,1,1,1,1,1,1,1,1,1,1,1,1,1,1
1,1,1,1,1,1,1,1,1,1,1,1,1,1,1
22,22,22,22,22,22,22,22,22,22,22,22,22,22,22
18,18,18,18,18,18,18,18,18,18,18,18,18,18,18
18,18,18,18,18,18,18,18,18,18,18,18,18,18,18
18,18,18,18,18,18,18,18,18,18,18,18,18,18,18
22,22,22,22,22,22,22,22,22,22,22,22,22,22,22
1,1,1,1,1,1,1,1,1,1,1,1,1,1,1
1,1,1,1,1,1,1,1,1,1,1,1,1,1,1
1,1,1,1,1,1,1,1,1,1,1,1,1,1,1
1,1,1,1,1,1,1,1,1,1,1,1,1,1,1
1,1,1,1,1,1,1,1,1,1,1,1,1,1,1
1,1,1,1,1,1,1,1,1,1,1,1,1,1,1
1,1,1,1,1,1,1,1,1,1,1,1,1,1,1
endlayer

layer
1,1,1,1,1,1,1,1,1,1,1,1,1,1,1
1,1,1,1,1,1,1,1,1,1,1,1,1,1,1
1,1,1,1,1,1,1,1,1,1,1,1,1,1,1
1,1,1,1,1,1,1,1,1,1,1,1,1,1,1
1,1,1,1,1,1,1,1,1,1,1,1,1,1,1
1,1,1,1,1,1,1,1,1,1,1,1,1,1,1
1,1,1,1,1,1,1,1,1,1,1,1,1,1,1
1,1,1,1,1,1,1,1,1,1,1,1,1,1,1
1,1,1,1,1,1,1,1,1,1,1,1,1,1,1
22,22,22,22,22,22,22,22,22,22,22,22,22,22,22
1,1,1,1,1,1,1,1,1,1,1,1,1,1,1
1,1,1,1,1,1,1,1,1,1,1,1,1,1,1
1,1,1,1,1,1,1,1,1,1,1,1,1,1,1
1,1,1,1,1,1,1,1,1,1,1,1,1,1,1
1,1,1,1,1,1,1,1,1,1,1,1,1,1,1
1,1,1,1,1,1,1,1,1,1,1,1,1,1,1
1,1,1,1,1,1,1,1,1,1,1,1,1,1,1
1,1,1,1,1,1,1,1,1,1,1,1,1,1,1
1,1,1,1,1,1,1,1,1,1,1,1,1,1,1
endlayer

