
# Created by Ruins mod version 17.1 Ingame Parser
# authoring Player: ST753M

weight=1
uniqueSpawnDistance=400
embed_into_distance=2
acceptable_target_blocks=grass,dirt,podzol
unacceptable_target_blocks=flowing_water,water,flowing_lava,lava
dimensions=19,14,14
allowable_overhang=2
max_leveling=0
leveling_buffer=0
preserve_water=0
preserve_lava=0
preventRotation=1

biomesToSpawnIn=forest,maple_woods,boreal_forst,forest_hills,woodland,seasonal_forest,grove,forested_hills,lush_hills,thicket,birch_forest,birch_forest_hills,mutated_birch_forest,mutated_birch_forest_hills,birch_forested_hills,cherry_blossom_grove,mutated_forest,plains,prairie,shrubland,chaparral,grassland,meadow,orchard,rocky_plains,rocky_plateau,orchard,highland,plains,prairie,shrubland,chaparral,grassland,meadow,orchard,rocky_plains,rocky_plateau,orchard

=0,100,air
rule1=0,100,preserveBlock
rule2=0,100,minecraft:dirt-0
rule3=0,100,minecraft:grass-0
rule4=0,100,minecraft:farmland-7
rule5=0,100,minecraft:grass_path-0
rule6=0,100,minecraft:water-0
rule7=0,100,minecraft:log-0
rule8=0,100,minecraft:planks-1
rule9=0,100,minecraft:spruce_fence-0
rule10=0,100,rustic:wildberry_bush-1
rule11=0,100,minecraft:log-8
rule12=0,100,rustic:chamomile-3
rule13=0,100,minecraft:log-4
rule14=0,100,rustic:slate-0
rule15=0,100,minecraft:spruce_stairs-0
rule16=0,100,minecraft:spruce_stairs-3
rule17=0,100,minecraft:spruce_stairs-1
rule18=0,100,rustic:iron_lantern-1
rule19=0,100,rustic:clay_wall_cross-0
rule20=0,100,rustic:stairs_slate_roof-2
rule21=0,100,rustic:slate_roof-0
rule22=0,100,rustic:chair_oak-3
rule23=0,100,minecraft:spruce_door-5
rule24=0,100,rustic:table_oak-0
rule25=0,100,minecraft:stained_glass_pane-8
rule26=0,100,rustic:stairs_slate_roof-6
rule27=0,100,minecraft:spruce_door-8
rule28=0,100,rustic:stairs_slate_roof-0
rule29=0,100,minecraft:spruce_stairs-6
rule30=0,100,minecraft:spruce_stairs-7
rule31=0,100,minecraft:spruce_stairs-4
rule32=0,100,rustic:stairs_slate_roof-3
rule33=0,100,minecraft:spruce_stairs-5
rule34=0,100,minecraft:wooden_slab-9
rule35=0,100,rustic:stairs_slate_roof-1
rule36=0,100,IInventory;rustic:vase;rustic:wildberries#1#0#2+rustic:wildberries#2#0#7+rustic:wildberries#3#0#13+rustic:wildberries#4#0#19+rustic:wildberries#2#0#24-1
rule37=0,100,minecraft:spruce_fence_gate-2
rule38=0,100,rustic:chain-0
rule39=0,100,minecraft:spruce_fence_gate-3
rule40=0,100,teBlock;minecraft:bed;{color:14,x:973,y:92,z:1568,id:"minecraft:bed"}-3
rule41=0,100,teBlock;minecraft:bed;{color:14,x:974,y:92,z:1568,id:"minecraft:bed"}-11
rule42=0,100,rustic:chair_oak-0
rule43=0,100,rustic:chair_oak-2
rule44=0,100,minecraft:wooden_slab-1
rule45=0,100,IInventory;rustic:vase;rustic:wildberries#2#0#5+rustic:wildberries#1#0#11+rustic:wildberries#2#0#18+rustic:wildberries#3#0#24-2
rule46=0,100,rustic:stairs_slate_roof-7
rule47=0,100,rustic:stairs_slate_roof-5
rule48=0,100,rustic:stairs_slate_roof-4
rule49=0,100,rustic:clay_wall-0
rule50=0,100,minecraft:spruce_door-2
rule51=0,100,air
rule52=0,100,minecraft:spruce_door-3
rule53=0,100,minecraft:spruce_door-1
rule54=0,100,minecraft:spruce_door-0
rule55=0,100,minecraft:spruce_door-9

layer
1,1,1,1,1,2,2,2,2,1,1,1,1,1
1,1,1,1,2,2,2,2,2,2,1,1,1,1
1,1,1,2,2,2,2,2,2,2,2,1,1,1
1,1,2,2,2,2,2,2,2,2,2,1,1,1
1,1,2,2,2,2,2,2,2,2,2,2,1,1
1,2,2,2,2,2,2,2,2,2,2,2,1,1
1,2,2,2,2,2,2,2,2,2,2,2,2,1
1,2,2,2,2,2,2,2,2,2,2,2,2,1
1,2,2,2,2,2,2,2,2,2,2,2,1,1
1,1,2,2,2,2,2,2,2,2,2,2,1,1
1,1,2,2,2,2,2,2,2,2,2,1,1,1
1,1,1,2,2,2,2,2,2,2,2,1,1,1
1,1,1,1,2,2,2,2,2,2,1,1,1,1
1,1,1,1,1,2,2,2,2,1,1,1,1,1
endlayer

layer
1,1,1,1,3,3,3,3,3,3,1,1,1,1
1,1,1,3,3,4,4,4,4,3,3,1,1,1
1,1,3,5,5,5,5,5,5,3,3,1,1,1
1,1,5,5,3,4,4,4,4,3,3,3,1,1
1,5,5,5,7,2,2,2,2,6,3,3,1,1
1,5,8,8,2,2,2,2,2,2,3,3,3,1
1,5,8,2,2,2,2,2,2,2,3,3,3,1
1,5,8,2,2,2,2,2,2,2,3,3,3,1
1,5,8,8,2,2,2,2,2,2,3,3,3,1
1,5,5,5,7,2,2,2,2,6,3,3,1,1
1,1,5,5,3,4,4,4,4,3,3,3,1,1
1,1,3,5,5,5,5,5,5,3,3,1,1,1
1,1,1,3,3,4,4,4,4,3,3,1,1,1
1,1,1,1,3,3,3,3,3,3,1,1,1,1
endlayer

layer
1,1,1,1,9,9,9,9,9,9,1,1,1,1
1,1,1,0,9,10,10,10,10,9,0,1,1,1
1,1,0,0,0,0,0,0,0,9,0,1,1,1
1,1,0,0,9,10,10,10,10,9,0,0,1,1
1,0,0,0,7,11,11,11,11,7,9,0,1,1
1,0,15,15,13,14,14,14,14,13,12,0,0,1
1,0,16,8,13,14,14,14,14,13,0,0,0,1
1,0,16,8,13,14,14,14,14,13,0,12,0,1
1,0,16,17,13,14,14,14,14,13,0,0,0,1
1,0,0,0,7,11,11,11,11,7,9,0,1,1
1,1,0,0,9,10,10,10,10,9,0,0,1,1
1,1,0,0,0,0,0,0,0,9,0,1,1,1
1,1,1,0,9,10,10,10,10,9,0,1,1,1
1,1,1,1,9,9,9,9,9,9,1,1,1,1
endlayer

layer
1,1,1,1,18,1,1,1,1,18,1,1,1,1
1,1,1,0,0,0,0,0,0,0,0,1,1,1
1,1,0,0,0,0,0,0,0,0,0,1,1,1
1,1,0,0,0,0,0,0,0,0,0,0,1,1
1,0,0,0,7,19,19,19,19,7,0,0,1,1
1,0,0,0,19,21,20,0,0,19,0,0,0,1
1,0,0,0,19,0,0,0,0,19,0,0,0,1
1,0,0,0,23,0,0,0,22,19,0,0,0,1
1,0,0,0,19,0,0,0,24,19,0,0,0,1
1,0,0,0,7,19,19,19,19,7,0,0,1,1
1,1,0,0,0,0,0,0,0,0,0,0,1,1
1,1,0,0,0,0,0,0,0,0,0,1,1,1
1,1,1,0,0,0,0,0,0,0,0,1,1,1
1,1,1,1,18,1,1,1,1,18,1,1,1,1
endlayer

layer
1,1,1,1,1,1,1,1,1,1,1,1,1,1
1,1,1,0,0,0,0,0,0,0,0,1,1,1
1,1,0,0,0,0,0,0,0,0,0,1,1,1
1,1,0,0,0,0,0,0,0,0,0,0,1,1
1,0,0,0,7,19,25,25,19,7,0,0,1,1
1,0,0,0,19,20,0,0,0,19,0,0,0,1
1,0,0,0,19,26,0,0,0,25,0,0,0,1
1,0,0,0,27,0,0,0,0,25,0,0,0,1
1,0,0,0,19,0,0,0,18,19,0,0,0,1
1,0,0,0,7,19,25,25,19,7,0,0,1,1
1,1,0,0,0,0,0,0,0,0,0,0,1,1
1,1,0,0,0,0,0,0,0,0,0,1,1,1
1,1,1,0,0,0,0,0,0,0,0,1,1,1
1,1,1,1,1,1,1,1,1,1,1,1,1,1
endlayer

layer
1,1,1,1,1,1,1,1,1,1,1,1,1,1
1,1,1,0,0,0,0,0,0,0,0,1,1,1
1,1,0,0,0,0,0,0,0,0,0,1,1,1
1,1,0,0,0,0,0,0,0,0,0,0,1,1
1,0,0,0,7,19,25,25,19,7,0,0,1,1
1,0,0,0,19,0,0,0,0,19,0,0,0,1
1,0,0,0,19,28,26,0,0,25,0,0,0,1
1,0,0,0,19,0,0,0,0,25,0,0,0,1
1,0,0,0,19,0,0,0,0,19,0,0,0,1
1,0,0,0,7,19,25,25,19,7,0,0,1,1
1,1,0,0,0,0,0,0,0,0,0,0,1,1
1,1,0,0,0,0,0,0,0,0,0,1,1,1
1,1,1,0,0,0,0,0,0,0,0,1,1,1
1,1,1,1,1,1,1,1,1,1,1,1,1,1
endlayer

layer
1,1,1,1,1,1,1,1,1,1,1,1,1,1
1,1,1,0,13,0,0,0,0,13,0,1,1,1
1,1,0,30,13,0,0,0,0,13,29,1,1,1
1,1,31,30,13,0,0,0,0,13,31,31,1,1
1,11,11,11,7,19,19,19,19,7,11,11,11,1
1,0,0,0,19,0,0,26,0,19,0,0,0,1
1,0,0,0,19,0,32,26,0,19,0,0,0,1
1,0,0,0,19,0,0,0,0,19,0,0,0,1
1,0,0,0,19,0,0,0,0,19,0,0,0,1
1,11,11,11,7,19,19,19,19,7,11,11,11,1
1,1,33,30,13,0,0,0,0,13,29,33,1,1
1,1,0,30,13,0,0,0,0,13,29,1,1,1
1,1,1,0,13,0,0,0,0,13,0,1,1,1
1,1,1,1,1,1,1,1,1,1,1,1,1,1
endlayer

layer
1,1,1,1,1,1,1,1,1,1,1,1,1,1
1,1,1,0,0,0,0,0,0,0,0,1,1,1
1,1,34,11,11,11,11,11,11,11,11,34,1,1
1,1,13,14,14,14,14,14,14,14,14,13,1,1
1,0,13,14,14,14,14,14,14,14,14,13,0,1
1,0,13,14,14,0,35,14,14,14,14,13,0,1
1,0,13,14,14,0,0,14,14,14,14,13,0,1
1,0,13,14,14,14,14,14,14,14,14,13,0,1
1,0,13,14,14,14,14,14,14,14,14,13,0,1
1,0,13,14,14,14,14,14,14,14,14,13,0,1
1,1,13,14,14,14,14,14,14,14,14,13,1,1
1,1,34,11,11,11,11,11,11,11,11,34,1,1
1,1,1,0,0,0,0,0,0,0,0,1,1,1
1,1,1,1,1,1,1,1,1,1,1,1,1,1
endlayer

layer
1,1,1,1,1,1,1,1,1,1,1,1,1,1
1,1,1,0,0,0,0,0,0,0,0,1,1,1
1,1,7,19,19,7,19,19,7,19,19,7,1,1
1,1,19,0,0,0,0,7,36,24,24,19,1,1
1,0,19,0,38,0,0,37,0,0,0,19,0,1
1,0,7,0,0,0,0,7,0,0,0,7,0,1
1,0,19,0,0,0,0,7,0,0,0,19,0,1
1,0,19,7,39,7,7,7,0,0,0,19,0,1
1,0,7,0,0,0,0,0,7,0,0,7,0,1
1,0,19,0,0,0,0,0,7,0,40,19,0,1
1,1,19,0,43,24,42,0,7,9,41,19,1,1
1,1,7,19,19,7,19,19,7,19,19,7,1,1
1,1,1,0,0,0,0,0,0,0,0,1,1,1
1,1,1,1,1,1,1,1,1,1,1,1,1,1
endlayer

layer
1,1,1,1,1,1,1,1,1,1,1,1,1,1
1,1,1,0,0,0,0,0,0,0,0,1,1,1
1,1,7,25,25,7,25,25,7,25,25,7,1,1
1,1,25,0,0,0,0,44,0,18,0,25,1,1
1,0,25,0,38,0,0,0,0,0,0,25,0,1
1,0,7,0,0,0,0,44,0,0,0,7,0,1
1,0,25,0,0,0,0,7,0,0,0,25,0,1
1,0,25,44,0,44,7,7,34,0,0,25,0,1
1,0,7,0,0,0,0,0,7,0,0,7,0,1
1,0,25,0,0,0,0,0,44,0,0,25,0,1
1,1,25,0,0,18,0,0,44,0,0,25,1,1
1,1,7,25,25,7,25,25,7,25,25,7,1,1
1,1,1,0,0,0,0,0,0,0,0,1,1,1
1,1,1,1,1,1,1,1,1,1,1,1,1,1
endlayer

layer
1,1,1,1,1,1,1,1,1,1,1,1,1,1
1,38,1,0,0,0,0,0,0,0,0,1,38,1
1,1,7,25,25,7,25,25,7,25,25,7,1,1
1,1,25,0,0,0,0,0,0,0,0,25,1,1
1,0,25,0,38,0,0,0,0,0,0,25,0,1
1,0,7,0,0,0,0,0,0,0,0,7,0,1
1,0,25,0,0,0,31,7,0,0,0,25,0,1
1,0,25,0,0,0,7,7,45,0,0,25,0,1
1,0,7,0,0,0,0,0,7,0,0,7,0,1
1,0,25,0,0,0,0,0,0,0,0,25,0,1
1,1,25,0,0,0,0,0,0,0,0,25,1,1
1,1,7,25,25,7,25,25,7,25,25,7,1,1
1,38,1,0,0,0,0,0,0,0,0,1,38,1
1,1,1,1,1,1,1,1,1,1,1,1,1,1
endlayer

layer
1,1,1,1,1,1,1,1,1,1,1,1,1,1
1,38,1,0,0,0,0,0,0,0,0,1,38,1
1,1,7,19,19,7,19,19,7,19,19,7,1,1
1,1,19,0,0,0,0,0,0,0,0,19,1,1
1,0,19,0,38,0,0,0,0,0,0,19,0,1
1,0,7,0,0,0,0,0,0,0,0,7,0,1
1,0,19,0,0,0,7,7,0,0,0,19,0,1
1,0,19,0,0,0,7,7,0,0,0,19,0,1
1,0,7,0,0,0,0,0,7,0,0,7,0,1
1,0,19,0,0,0,0,0,0,0,0,19,0,1
1,1,19,0,0,0,0,0,0,0,0,19,1,1
1,1,7,19,19,7,19,19,7,19,19,7,1,1
1,38,1,0,0,0,0,0,0,0,0,1,38,1
1,1,1,1,1,1,1,1,1,1,1,1,1,1
endlayer

layer
1,1,1,1,1,30,31,31,29,1,1,1,1,1
1,21,26,0,0,30,34,34,29,0,0,46,21,1
1,47,7,11,11,7,11,11,7,11,11,7,47,1
1,1,13,0,0,13,34,34,13,34,34,13,1,1
1,0,13,0,38,13,34,34,13,34,34,13,0,1
31,31,7,11,11,11,11,11,13,11,11,7,31,29
30,34,13,34,34,13,8,8,13,34,34,13,34,29
30,34,13,34,34,13,8,8,13,34,34,13,34,29
33,33,7,11,11,13,11,11,11,11,11,7,33,29
1,0,13,34,34,13,34,34,13,34,34,13,0,1
1,1,13,34,34,13,34,34,13,34,34,13,1,1
1,48,7,11,11,7,11,11,7,11,11,7,48,1
1,21,26,0,0,30,34,34,29,0,0,46,21,1
1,1,1,1,1,33,33,33,29,1,1,1,1,1
endlayer

layer
1,1,1,1,1,9,9,9,9,1,1,1,1,1
1,1,32,26,0,9,0,0,9,0,46,20,1,1
1,28,32,49,7,19,50,50,19,7,49,20,28,1
1,47,49,0,0,0,0,0,0,0,0,49,47,1
1,0,7,0,38,0,0,0,0,51,51,7,0,1
9,9,19,0,0,7,0,0,7,0,51,19,9,9
9,0,53,0,0,0,0,0,0,0,0,52,0,9
9,0,53,0,0,0,0,0,0,0,0,52,0,9
9,9,19,0,0,7,0,0,7,0,0,19,9,9
1,0,7,51,51,0,0,0,0,0,51,7,0,1
1,48,49,0,0,51,0,0,0,34,0,49,48,1
1,35,35,49,7,19,54,54,19,7,49,20,35,1
1,1,32,26,0,9,0,0,9,0,46,20,1,1
1,1,1,1,1,9,9,9,9,1,1,1,1,1
endlayer

layer
1,1,1,1,1,18,1,1,18,1,1,1,1,1
1,1,1,32,26,0,0,0,0,46,20,1,1,1
1,1,1,32,7,19,27,55,19,7,20,1,1,1
1,28,28,32,0,0,0,0,0,0,20,28,28,1
1,47,7,0,38,0,0,0,0,51,51,7,47,1
18,0,19,0,0,7,0,0,7,0,0,19,0,18
1,0,55,0,0,0,0,0,0,0,0,27,0,1
1,0,27,0,0,0,0,0,0,0,0,55,0,1
18,0,19,0,0,7,0,0,7,0,0,19,0,18
1,48,7,51,51,0,0,0,0,0,0,7,48,1
1,35,35,35,0,0,0,0,0,18,20,35,35,1
1,1,1,32,7,19,55,27,19,7,20,1,1,1
1,1,1,32,26,0,0,0,0,46,20,1,1,1
1,1,1,1,1,18,1,1,18,1,1,1,1,1
endlayer

layer
1,1,1,1,1,1,1,1,1,1,1,1,1,1
1,1,1,1,32,26,0,0,46,20,1,1,1,1
1,1,1,1,32,19,19,19,19,20,1,1,1,1
1,1,1,1,32,26,0,0,46,20,1,1,1,1
1,28,28,28,32,26,0,0,46,20,28,28,28,1
1,47,19,47,47,7,0,0,7,47,47,19,47,1
1,0,19,0,0,0,0,0,0,0,0,19,0,1
1,0,19,0,0,0,0,0,0,0,0,19,0,1
1,48,19,48,48,7,0,0,7,48,48,19,48,1
1,35,35,35,35,26,0,0,46,20,35,35,35,1
1,1,1,1,32,26,0,0,46,20,1,1,1,1
1,1,1,1,32,19,19,19,19,20,1,1,1,1
1,1,1,1,32,26,0,0,46,20,1,1,1,1
1,1,1,1,1,1,1,1,1,1,1,1,1,1
endlayer

layer
1,1,1,1,1,1,1,1,1,1,1,1,1,1
1,1,1,1,1,32,26,46,20,1,1,1,1,1
1,1,1,1,1,32,19,19,20,1,1,1,1,1
1,1,1,1,1,32,26,46,20,1,1,1,1,1
1,1,1,1,1,32,26,46,20,1,1,1,1,1
1,28,28,28,28,32,26,46,20,28,28,28,28,1
1,47,19,47,47,47,47,46,47,47,47,19,47,1
1,48,19,48,48,48,26,48,48,48,48,19,48,1
1,35,35,35,35,35,26,46,20,35,35,35,35,1
1,1,1,1,1,32,26,46,20,1,1,1,1,1
1,1,1,1,1,32,26,46,20,1,1,1,1,1
1,1,1,1,1,32,19,19,20,1,1,1,1,1
1,1,1,1,1,32,26,46,20,1,1,1,1,1
1,1,1,1,1,1,1,1,1,1,1,1,1,1
endlayer

layer
1,1,1,1,1,1,1,1,1,1,1,1,1,1
1,1,1,1,1,1,32,20,1,1,1,1,1,1
1,1,1,1,1,1,32,20,1,1,1,1,1,1
1,1,1,1,1,1,32,20,1,1,1,1,1,1
1,1,1,1,1,1,32,20,1,1,1,1,1,1
1,1,1,1,1,1,32,20,1,1,1,1,1,1
1,28,28,28,28,28,32,28,28,28,28,28,28,1
1,35,35,35,35,35,35,20,35,35,35,35,35,1
1,1,1,1,1,1,32,20,1,1,1,1,1,1
1,1,1,1,1,1,32,20,1,1,1,1,1,1
1,1,1,1,1,1,32,20,1,1,1,1,1,1
1,1,1,1,1,1,32,20,1,1,1,1,1,1
1,1,1,1,1,1,32,20,1,1,1,1,1,1
1,1,1,1,1,1,1,1,1,1,1,1,1,1
endlayer

layer
1,1,1,1,1,1,1,1,1,1,1,1,1,1
1,1,1,1,1,1,32,20,1,1,1,1,1,1
1,1,1,1,1,1,1,1,1,1,1,1,1,1
1,1,1,1,1,1,1,1,1,1,1,1,1,1
1,1,1,1,1,1,1,1,1,1,1,1,1,1
1,1,1,1,1,1,1,1,1,1,1,1,1,1
1,28,1,1,1,1,1,1,1,1,1,1,28,1
1,35,1,1,1,1,1,1,1,1,1,1,35,1
1,1,1,1,1,1,1,1,1,1,1,1,1,1
1,1,1,1,1,1,1,1,1,1,1,1,1,1
1,1,1,1,1,1,1,1,1,1,1,1,1,1
1,1,1,1,1,1,1,1,1,1,1,1,1,1
1,1,1,1,1,1,32,20,1,1,1,1,1,1
1,1,1,1,1,1,1,1,1,1,1,1,1,1
endlayer

