
# Created by Ruins mod version 17.0 Ingame Parser
# authoring Player: ST753M

weight=1
embed_into_distance=3
acceptable_target_blocks=grass,dirt,podzol,coarse_dirt,biomesoplenty:grass,biomesoplenty:dirt
unacceptable_target_blocks=flowing_water,water,flowing_lava,lava
dimensions=12,17,13
allowable_overhang=5
max_leveling=1
leveling_buffer=0
preserve_water=0
preserve_lava=0
preventRotation=1

biomesToSpawnIn=plains,prairie,chaparral,grassland,meadow,orchard,rocky_plains,rocky_plateau,oak_savannah,twilight_clearing

=0,100,air
rule1=0,100,preserveBlock
rule2=0,100,minecraft:stone-0
rule3=0,100,minecraft:log-0
rule4=0,100,rustic:slate-0
rule5=0,100,minecraft:grass-0
rule6=0,100,minecraft:farmland-7
rule7=0,100,minecraft:water-0
rule8=0,100,minecraft:dirt-0
rule9=0,100,rustic:wind_thistle-3
rule10=0,100,rustic:apiary-0
rule11=0,100,minecraft:spruce_fence-0
rule12=0,100,rustic:crop_stake-0
rule13=0,100,rustic:grape_stem-3
rule14=0,100,minecraft:planks-1
rule15=0,100,minecraft:spruce_stairs-0
rule16=0,100,minecraft:log-4
rule17=0,100,minecraft:log-8
rule18=0,100,rustic:stake_tied-0
rule19=0,100,rustic:grape_leaves-10
rule20=0,100,rustic:grape_leaves-0
rule21=0,100,rustic:clay_wall_cross-0
rule22=0,100,minecraft:spruce_door-2
rule23=0,50,air
rule24=0,100,rustic:barrel-0
rule25=0,100,rustic:cabinet-7
rule26=0,100,rustic:table_oak-0
rule27=0,100,rustic:crushing_tub-0
rule28=0,100,rustic:chair_oak-0
rule29=0,100,rustic:brewing_barrel-1
rule30=0,100,rustic:iron_lantern-1
rule31=0,100,rustic:clay_wall_diag-3
rule32=0,100,minecraft:stained_glass_pane-8
rule33=0,100,minecraft:spruce_door-9
rule34=0,100,minecraft:spruce_door-8
rule35=0,100,rustic:clay_wall_diag-0
rule36=0,100,rustic:cabinet-15
rule37=0,100,rustic:clay_wall_diag-2
rule38=0,100,rustic:clay_wall_diag-1
rule39=0,100,rustic:stairs_slate_roof-0
rule40=0,100,rustic:stairs_slate_roof-5
rule41=0,100,rustic:stairs_slate_roof-4
rule42=0,100,rustic:stairs_slate_roof-1

layer
1,1,1,1,1,1,1,1,1,1,1,1,1
1,1,1,1,1,1,1,1,1,1,1,1,1
1,1,1,1,2,2,2,2,2,2,2,1,1
1,1,1,1,2,2,2,2,2,2,2,2,1
1,1,1,2,2,2,2,2,2,2,2,2,1
1,1,2,2,2,2,2,2,2,2,2,2,1
1,2,2,2,2,2,2,2,2,2,2,2,1
1,2,2,2,2,2,2,2,2,2,2,2,1
1,2,2,2,2,2,2,2,2,2,2,1,1
1,1,2,2,2,2,2,2,2,2,1,1,1
1,3,2,2,2,2,3,2,2,2,1,3,1
1,1,4,4,4,4,4,4,4,4,4,1,1
1,1,4,4,4,4,4,4,4,4,4,1,1
1,1,4,4,4,4,4,4,4,4,4,1,1
1,1,4,4,4,4,4,4,4,4,4,1,1
1,3,1,1,1,1,3,1,1,1,1,3,1
1,1,1,1,1,1,1,1,1,1,1,1,1
endlayer

layer
1,1,1,1,1,1,2,2,2,1,1,1,1
1,1,1,1,2,2,2,2,2,2,2,1,1
1,1,1,1,2,2,2,2,2,2,2,2,1
1,1,1,2,2,2,2,2,2,2,2,2,2
1,1,2,2,2,2,2,2,2,2,2,2,2
1,2,2,2,2,2,2,2,2,2,2,2,2
1,2,2,2,2,2,2,2,2,2,2,2,2
2,2,2,2,2,2,2,2,2,2,2,2,2
2,2,2,2,2,2,2,2,2,2,2,2,2
2,2,2,2,2,2,2,2,2,2,2,2,2
1,3,2,2,2,2,3,2,2,2,2,3,1
1,1,4,4,4,4,4,4,4,4,4,1,1
1,1,4,4,4,4,4,4,4,4,4,1,1
1,1,4,4,4,4,4,4,4,4,4,1,1
1,1,4,4,4,4,4,4,4,4,4,1,1
1,3,1,1,1,1,3,1,1,1,1,3,1
1,1,1,1,1,1,1,1,1,1,1,1,1
endlayer

layer
1,1,1,1,1,1,5,5,5,5,1,1,1
1,1,1,1,5,5,5,5,5,5,5,1,1
1,1,1,5,5,5,5,5,5,5,5,5,5
1,1,1,5,5,5,5,5,5,5,5,5,5
1,1,5,5,5,5,5,5,5,5,5,5,5
1,5,5,5,5,5,5,5,6,5,6,5,5
5,5,5,5,5,5,5,5,6,5,6,5,5
5,5,5,5,5,5,5,5,6,5,6,5,5
5,8,8,5,5,8,7,5,5,5,5,5,5
5,8,8,8,8,8,8,5,5,5,5,5,5
5,3,8,8,8,8,3,8,8,8,8,3,5
1,1,4,4,4,4,4,4,4,4,4,1,1
1,1,4,4,4,4,4,4,4,4,4,1,1
1,1,4,4,4,4,4,4,4,4,4,1,1
1,1,4,4,4,4,4,4,4,4,4,1,1
1,3,1,1,1,1,3,1,1,1,1,3,1
1,1,1,1,1,1,1,1,1,1,1,1,1
endlayer

layer
1,1,1,1,1,1,0,10,0,9,1,1,1
1,1,1,1,0,0,0,0,9,0,0,1,1
1,1,1,0,0,0,11,11,11,11,11,11,11
1,1,1,0,0,0,0,0,0,0,0,0,11
1,1,0,0,0,0,0,0,12,0,12,0,11
1,0,0,0,0,0,0,0,0,0,0,0,11
0,0,0,0,0,0,0,0,13,0,13,0,11
0,9,0,0,0,0,0,0,0,0,0,0,11
9,3,14,15,15,14,3,0,12,0,12,0,11
0,16,14,14,14,14,16,0,0,0,0,0,11
9,3,17,17,17,17,3,17,17,17,17,3,11
1,16,4,4,4,4,4,4,4,4,4,16,1
1,16,4,4,4,4,4,4,4,4,4,16,1
1,16,4,4,4,4,4,4,4,4,4,16,1
1,16,4,4,4,4,4,4,4,4,4,16,1
1,3,17,17,17,17,3,17,17,17,17,3,1
1,1,1,1,1,1,1,1,1,1,1,1,1
endlayer

layer
1,1,1,1,1,1,0,0,0,0,1,1,1
1,1,1,1,0,0,0,0,0,0,0,1,1
1,1,1,0,0,0,0,0,0,0,0,0,0
1,1,1,0,0,0,0,0,0,0,0,0,0
1,1,0,0,0,0,0,0,18,0,18,0,0
1,0,0,0,0,0,0,0,19,0,19,0,0
0,0,0,0,0,0,0,0,20,0,20,0,0
0,0,0,0,0,0,0,0,19,0,19,0,0
0,3,0,0,0,0,3,0,18,0,18,0,0
0,11,0,0,0,0,11,0,0,0,0,0,0
0,3,21,22,22,21,3,21,21,21,21,3,0
1,21,25,0,0,0,11,0,0,24,23,21,1
1,21,0,0,0,0,0,27,0,0,26,21,1
1,21,26,28,0,0,0,0,0,0,0,21,1
1,21,26,0,0,0,11,0,29,29,29,21,1
1,3,21,21,21,21,3,21,21,21,21,3,1
1,1,1,1,1,1,1,1,1,1,1,1,1
endlayer

layer
1,1,1,1,1,0,0,0,0,0,0,1,1
1,1,1,1,0,0,0,0,0,0,0,0,1
1,1,1,0,0,0,0,0,0,0,0,0,0
1,1,0,0,0,0,0,0,0,0,0,0,0
1,0,0,0,0,0,0,0,0,0,0,0,0
0,0,0,0,0,0,0,0,0,0,0,0,0
0,0,0,0,0,0,0,0,0,0,0,0,0
0,0,0,0,0,0,0,0,0,0,0,0,0
0,30,0,0,0,0,30,0,0,0,0,0,0
0,11,0,0,0,0,11,0,0,0,0,0,0
0,3,31,34,33,31,3,31,32,32,31,3,0
1,37,36,0,0,0,11,0,0,0,0,35,1
1,32,0,0,0,0,0,0,0,0,30,32,1
1,32,0,0,0,0,0,0,0,0,0,32,1
1,37,30,0,0,0,11,0,0,29,29,35,1
1,3,38,32,32,38,3,38,32,32,38,3,1
1,1,1,1,1,1,1,1,1,1,1,1,1
endlayer

layer
1,1,1,1,1,0,0,0,0,0,0,1,1
1,1,1,1,0,0,0,0,0,0,0,0,1
1,1,1,0,0,0,0,0,0,0,0,0,0
1,1,0,0,0,0,0,0,0,0,0,0,0
1,0,0,0,0,0,0,0,0,0,0,0,0
0,0,0,0,0,0,0,0,0,0,0,0,0
0,0,0,0,0,0,0,0,0,0,0,0,0
0,0,0,0,0,0,0,0,0,0,0,0,0
0,0,0,0,0,0,0,0,0,0,0,0,0
0,11,0,0,0,0,11,0,0,0,0,0,0
1,3,31,37,35,31,3,31,32,32,31,3,0
1,37,0,0,0,0,11,0,0,0,0,35,1
1,32,0,0,0,0,0,0,0,0,0,32,1
1,32,0,0,0,0,0,0,0,0,0,32,1
1,37,0,0,0,0,11,0,0,0,0,35,1
1,3,38,32,32,38,3,38,32,32,38,3,1
1,1,1,1,1,1,1,1,1,1,1,1,1
endlayer

layer
1,1,1,1,1,0,0,0,0,0,0,1,1
1,1,1,1,0,0,0,0,0,0,0,0,1
1,1,1,0,0,0,0,0,0,0,0,0,0
1,1,0,0,0,0,0,0,0,0,0,0,0
1,0,0,0,0,0,0,0,0,0,0,0,0
0,0,0,0,0,0,0,0,0,0,0,0,0
0,0,0,0,0,0,0,0,0,0,0,0,0
0,0,0,0,0,0,0,0,0,0,0,0,0
0,0,0,0,0,0,0,0,0,0,0,0,0
1,11,11,0,0,11,11,0,0,0,0,0,0
1,3,21,21,21,21,3,21,21,21,21,3,1
1,21,0,0,0,0,11,0,0,0,0,21,1
1,21,0,0,0,0,11,0,0,0,0,21,1
1,21,0,0,0,0,11,0,0,0,0,21,1
1,21,0,0,0,0,11,0,0,0,0,21,1
1,3,21,21,21,21,3,21,21,21,21,3,1
1,1,1,1,1,1,1,1,1,1,1,1,1
endlayer

layer
1,1,1,1,1,1,0,0,0,0,1,1,1
1,1,1,1,0,0,0,0,0,0,0,1,1
1,1,1,0,0,0,0,0,0,0,0,0,1
1,1,1,0,0,0,0,0,0,0,0,0,0
1,1,0,0,0,0,0,0,0,0,0,0,0
1,0,0,0,0,0,0,0,0,0,0,0,0
1,0,0,0,0,0,0,0,0,0,0,0,0
0,0,0,0,0,0,0,0,0,0,0,0,0
1,0,0,0,0,0,0,0,0,0,0,0,1
39,39,39,39,39,39,39,39,39,39,39,39,39
40,3,17,17,17,17,3,17,17,17,17,3,40
0,16,0,0,0,0,16,0,0,0,0,16,1
0,16,0,0,0,0,16,0,0,0,0,16,1
0,16,0,0,0,0,16,0,0,0,0,16,1
0,16,0,0,0,0,16,0,0,0,0,16,1
41,3,17,17,17,17,3,17,17,17,17,3,41
42,42,42,42,42,42,42,42,42,42,42,42,42
endlayer

layer
1,1,1,1,1,1,1,0,0,1,1,1,1
1,1,1,1,0,0,0,0,0,0,0,1,1
1,1,1,0,0,0,0,0,0,0,0,0,1
1,1,1,0,0,0,0,0,0,0,0,0,1
1,1,0,0,0,0,0,0,0,0,0,0,0
1,0,0,0,0,0,0,0,0,0,0,0,0
1,0,0,0,0,0,0,0,0,0,0,0,0
1,0,0,0,0,0,0,0,0,0,0,0,1
1,0,0,0,0,0,0,0,0,0,0,1,1
1,1,1,1,1,1,1,1,1,1,1,1,1
39,39,39,39,39,39,39,39,39,39,39,39,39
40,14,40,40,40,40,40,40,40,40,40,14,40
0,14,0,0,0,0,0,0,0,0,0,14,1
0,14,0,0,0,0,0,0,0,0,0,14,1
41,14,41,41,41,41,41,41,41,41,41,14,41
42,42,42,42,42,42,42,42,42,42,42,42,42
1,1,1,1,1,1,1,1,1,1,1,1,1
endlayer

layer
1,1,1,1,1,1,1,1,1,1,1,1,1
1,1,1,1,1,0,0,0,0,0,1,1,1
1,1,1,1,0,0,0,0,0,0,0,1,1
1,1,1,0,0,0,0,0,0,0,0,0,1
1,1,1,0,0,0,0,0,0,0,0,0,1
1,1,0,0,0,0,0,0,0,0,0,0,1
1,1,0,0,0,0,0,0,0,0,0,0,1
1,0,0,0,0,0,0,0,0,0,0,0,1
1,1,1,1,1,1,1,1,1,1,1,1,1
1,1,1,1,1,1,1,1,1,1,1,1,1
1,1,1,1,1,1,1,1,1,1,1,1,1
39,39,39,39,39,39,39,39,39,39,39,39,39
40,14,40,40,40,40,40,40,40,40,40,14,40
41,14,41,41,41,41,41,41,41,41,41,14,41
42,42,42,42,42,42,42,42,42,42,42,42,42
1,1,1,1,1,1,1,1,1,1,1,1,1
1,1,1,1,1,1,1,1,1,1,1,1,1
endlayer

layer
1,1,1,1,1,1,1,1,1,1,1,1,1
1,1,1,1,1,1,1,1,0,1,1,1,1
1,1,1,1,1,1,1,0,0,1,1,1,1
1,1,1,1,1,1,0,0,0,0,1,1,1
1,1,1,1,0,0,0,0,0,0,0,1,1
1,1,1,0,0,0,0,0,0,0,0,1,1
1,1,1,1,0,0,0,0,0,0,0,1,1
1,1,1,1,1,1,1,1,1,1,1,1,1
1,1,1,1,1,1,1,1,1,1,1,1,1
1,1,1,1,1,1,1,1,1,1,1,1,1
1,1,1,1,1,1,1,1,1,1,1,1,1
1,1,1,1,1,1,1,1,1,1,1,1,1
39,39,39,39,39,39,39,39,39,39,39,39,39
42,42,42,42,42,42,42,42,42,42,42,42,42
1,1,1,1,1,1,1,1,1,1,1,1,1
1,1,1,1,1,1,1,1,1,1,1,1,1
1,1,1,1,1,1,1,1,1,1,1,1,1
endlayer

