
# Created by Ruins mod version 17.0 Ingame Parser
# authoring Player: ST753M

weight=2
embed_into_distance=15
acceptable_target_blocks=
unacceptable_target_blocks=flowing_water,water,flowing_lava,lava,ice,bedrock,netherrack,nether_brick,nether_brick_fence,soul_sand,quartz_ore,end_stone,obsidian,iron_bars,Natura:Cloud,slime_grass,slime_congealed,slime_dirt,clouds,natura:clouds,sand
dimensions=15,19,12
allowable_overhang=10
spawnMinDistance=500
max_leveling=0
leveling_buffer=0
preserve_water=0
preserve_lava=0

biomesToSpawnIn=bamboo_forest,forest,maple_woods,woodland,thicket,grove,fen,birch_forest,mutated_birch_forest,taiga,taiga_hills,mutated_redwood_taiga,mutated_redwood_taiga_hills,redwood_taiga,mutated_taiga,redwood_taiga_hills,redwood_forest,coniferous_forest,shield,dead_forest,autumnal_wooded_hills,autumnal_woods,snowy_forest,mutated_taiga_cold,snowy_coniferous_forest,taiga_cold,taiga_cold_hills,plains,prairie,shrubland,chaparral,grassland,meadow,orchard,rocky_plains,rocky_plateau,savanna,savanna_rock,mutated_savanna,mutated_savanna_rock,brushland,steppe,wasteland,tundra,outback,badlands,desert_shrubland,arid_highland,darklands

=0,100,air
rule1=0,100,minecraft:concrete-7
rule2=0,100,minecraft:stonebrick-0
rule3=0,100,preserveBlock
rule4=0,100,minecraft:iron_bars-0
rule5=0,100,minecraft:stone_brick_stairs-0
rule6=0,100,minecraft:stone_brick_stairs-5

rule7=0,100,iceandfire:goldpile-7,iceandfire:goldpile-6,iceandfire:goldpile-5,iceandfire:goldpile-4,iceandfire:goldpile-3,iceandfire:goldpile-2,iceandfire:goldpile-1,iceandfire:goldpile-0
^0,100,iceandfire:silverpile-7,iceandfire:silverpile-6,iceandfire:silverpile-5,iceandfire:silverpile-4,iceandfire:silverpile-3,iceandfire:silverpile-2,iceandfire:silverpile-1,iceandfire:silverpile-0

rule8=0,100,IInventory;minecraft:chest;iceandfire:manuscript#2#0#4+iceandfire:armor_silver_metal_helmet#1#0#7+minecraft:golden_shovel#1#0#11+iceandfire:sapphire_gem#1#0#16+iceandfire:sapphire_gem#1#0#19+minecraft:emerald#1#0#21+minecraft:golden_boots#1#0#23-2,IInventory;minecraft:chest;iceandfire:sapphire_gem#2#0#5+minecraft:golden_leggings#1#0#12+minecraft:golden_axe#{}#0#15+minecraft:iron_horse_armor#1#0#19+minecraft:diamond#1#0#22-2,IInventory;minecraft:chest;iceandfire:dragon_skull#{Stage:4,DragonAge:75}#1#1+iceandfire:silver_axe#1#0#5+minecraft:golden_boots#1#0#12+minecraft:speckled_melon#1#0#15+minecraft:golden_horse_armor#1#0#18+iceandfire:manuscript#2#0#23+minecraft:golden_pickaxe#1#0#25-2,IInventory;minecraft:chest;iceandfire:sapphire_gem#1#0#2+iceandfire:manuscript#2#0#4+minecraft:emerald#2#0#6+minecraft:golden_shovel#1#0#12+minecraft:golden_helmet#1#0#17+iceandfire:armor_silver_metal_boots#1#0#18+minecraft:speckled_melon#2#0#20+iceandfire:sapphire_gem#1#0#23-2,IInventory;minecraft:chest;minecraft:diamond#1#0#0+minecraft:golden_axe#{}#0#3+iceandfire:sapphire_gem#1#0#7+iceandfire:sapphire_gem#1#0#13+iceandfire:armor_silver_metal_leggings#1#0#19+minecraft:speckled_melon#2#0#23+minecraft:golden_chestplate#1#0#25-2,IInventory;minecraft:chest;minecraft:golden_hoe#1#0#1+iceandfire:manuscript#2#0#3+minecraft:golden_horse_armor#1#0#8+minecraft:golden_sword#{}#0#14+minecraft:emerald#1#0#18+iceandfire:armor_silver_metal_chestplate#1#0#20+minecraft:golden_carrot#2#0#22+iceandfire:dragon_skull#{Stage:4,DragonAge:75}#0#25-2,IInventory;minecraft:chest;iceandfire:sapphire_gem#1#0#1+minecraft:emerald#2#0#7+iceandfire:sapphire_gem#2#0#12+minecraft:golden_helmet#1#0#14+minecraft:diamond_horse_armor#1#0#20+minecraft:golden_sword#{}#0#24+minecraft:golden_carrot#1#0#25-2,IInventory;minecraft:chest;minecraft:golden_chestplate#1#0#2+iceandfire:sapphire_gem#1#0#4+iceandfire:sapphire_gem#1#0#6+iceandfire:manuscript#2#0#10+minecraft:golden_hoe#1#0#16+minecraft:speckled_melon#2#0#18+minecraft:diamond#1#0#20+iceandfire:silver_sword#{}#0#23+minecraft:golden_carrot#2#0#25-2,IInventory;minecraft:chest;minecraft:golden_pickaxe#1#0#4+minecraft:speckled_melon#2#0#7+minecraft:golden_leggings#1#0#11+iceandfire:silver_shovel#1#0#16+minecraft:golden_carrot#4#0#18+minecraft:golden_apple#1#1#24-2,air,air,air,air,air,air,air,air,air,air,air,air
rule9=0,100,minecraft:quartz_stairs-4
rule10=0,100,minecraft:quartz_block-2
rule11=0,100,minecraft:quartz_stairs-5
rule12=0,100,minecraft:stone_brick_stairs-3
rule13=0,100,minecraft:stone_brick_stairs-2
rule14=0,100,minecraft:lever-12
rule15=0,100,minecraft:quartz_block-3
rule16=0,100,minecraft:lever-11
rule17=0,100,minecraft:quartz_block-4

rule18=0,100,MobSpawner:skeleton

rule19=0,100,minecraft:quartz_stairs-0
rule20=0,100,minecraft:quartz_stairs-1
rule21=0,100,?minecraft:stone_brick_stairs-7
rule22=0,100,?minecraft:stone_brick_stairs-6
rule23=0,100,?minecraft:stone_brick_stairs-4
rule24=0,100,?minecraft:stone_brick_stairs-1

layer
1,1,1,1,1,1,1,1,1,1,1,1
1,2,2,2,2,2,2,2,2,2,2,1
1,2,2,2,2,2,2,2,2,2,2,1
1,2,2,2,2,2,2,2,2,2,2,1
1,2,2,2,2,2,2,2,2,2,2,1
1,2,2,2,2,2,2,2,2,2,2,1
1,1,1,1,1,1,1,1,1,1,1,1
1,2,2,2,2,2,2,2,1,3,3,3
1,2,2,2,2,2,2,2,1,3,3,3
1,2,2,2,2,2,2,2,1,3,3,3
1,2,2,2,2,2,2,2,1,3,3,3
1,2,2,2,2,2,2,2,1,3,3,3
1,2,2,2,2,2,2,2,1,3,3,3
1,2,2,2,2,2,2,2,1,3,3,3
1,2,2,2,2,2,2,2,1,3,3,3
1,2,2,2,2,2,2,2,1,3,3,3
1,2,2,2,2,2,2,2,1,3,3,3
1,2,2,2,2,2,2,2,1,3,3,3
1,1,1,1,1,1,1,1,1,3,3,3
endlayer

layer
1,2,2,2,2,2,2,2,2,2,2,1
2,0,0,0,0,0,0,0,4,0,0,2
2,0,0,0,0,0,0,0,0,0,0,2
2,0,0,0,0,0,0,0,0,0,0,2
2,0,0,0,0,0,0,0,4,0,0,2
2,0,0,0,0,0,0,0,4,0,0,2
1,2,2,2,2,2,2,2,1,5,5,1
2,1,0,0,0,7,7,1,2,6,6,3
2,1,0,0,0,0,7,1,2,3,3,3
2,1,7,0,0,0,0,1,2,3,3,3
2,1,7,7,0,0,0,1,2,3,3,3
2,1,1,1,1,0,7,1,2,3,3,3
2,1,0,0,0,0,0,1,2,3,3,3
2,1,7,7,7,0,0,1,2,3,3,3
2,1,1,1,1,0,7,1,2,3,3,3
2,1,8,0,0,7,7,1,2,3,3,3
2,1,7,7,7,7,7,1,2,3,3,3
2,1,1,1,1,1,1,1,2,3,3,3
1,2,2,2,2,2,2,2,1,3,3,3
endlayer

layer
1,2,2,2,2,2,2,2,2,2,2,1
2,0,0,0,0,0,0,0,4,0,0,2
2,0,0,0,0,0,0,0,0,0,0,2
2,0,9,0,0,0,0,0,0,0,0,2
2,0,10,0,0,0,0,0,4,0,0,2
2,0,11,0,0,0,0,0,4,0,0,2
1,2,2,13,0,12,2,2,1,0,0,1
2,7,0,0,0,0,0,7,2,5,5,6
2,7,0,0,0,0,0,7,2,6,6,3
2,7,0,0,0,0,0,7,2,3,3,3
2,7,0,0,0,0,0,7,2,3,3,3
2,7,7,7,7,0,0,7,2,3,3,3
2,7,0,0,0,0,0,7,2,3,3,3
2,7,0,0,0,0,0,7,2,3,3,3
2,7,7,7,7,0,0,7,2,3,3,3
2,7,0,0,0,0,0,7,2,3,3,3
2,7,0,0,0,0,0,7,2,3,3,3
2,7,7,7,7,7,7,7,2,3,3,3
1,2,2,2,2,2,2,2,1,3,3,3
endlayer

layer
1,2,2,2,2,2,2,2,2,2,2,1
2,0,0,0,0,0,0,0,4,0,0,2
2,0,0,0,0,0,0,0,0,0,0,2
2,16,15,14,0,0,0,0,0,0,0,2
2,18,17,0,0,0,0,0,4,0,0,2
2,0,15,0,0,0,0,0,4,0,0,2
1,2,2,0,0,0,2,2,1,0,0,1
2,0,0,0,0,0,0,0,2,0,0,2
2,0,0,0,0,0,0,0,2,5,5,6
2,0,0,0,0,0,0,0,2,6,6,3
2,0,0,0,0,0,0,0,2,3,3,3
2,0,0,0,0,0,0,0,2,3,3,3
2,0,0,0,0,0,0,0,2,3,3,3
2,0,0,0,0,0,0,0,2,3,3,3
2,0,0,0,0,0,0,0,2,3,3,3
2,0,0,0,0,0,0,0,2,3,3,3
2,0,0,0,0,0,0,0,2,3,3,3
2,0,0,0,0,0,0,0,2,3,3,3
1,2,2,2,2,2,2,2,1,3,3,3
endlayer

layer
1,2,2,2,2,2,2,2,2,2,2,1
2,0,0,0,0,0,0,0,4,0,0,2
2,0,0,0,0,0,0,0,4,0,0,2
2,0,19,0,0,0,0,0,4,0,0,2
2,0,10,0,0,0,0,0,4,0,0,2
2,0,20,0,0,0,0,0,4,0,0,2
1,2,2,22,0,21,2,2,1,0,0,1
2,0,0,0,0,0,0,0,2,0,0,2
2,0,0,0,0,0,0,0,2,0,0,2
2,0,0,0,0,0,0,0,2,5,5,6
2,0,0,0,0,0,0,0,2,6,6,3
2,0,0,0,0,0,0,0,2,3,3,3
2,0,0,0,0,0,0,0,2,3,3,3
2,0,0,0,0,0,0,0,2,3,3,3
2,0,0,0,0,0,0,0,2,3,3,3
2,0,0,0,0,0,0,0,2,3,3,3
2,0,0,0,0,0,0,0,2,3,3,3
2,0,0,0,0,0,0,0,2,3,3,3
1,2,2,2,2,2,2,2,1,3,3,3
endlayer

layer
1,2,2,2,2,2,2,2,2,2,2,1
2,0,0,0,0,0,0,0,4,0,0,2
2,0,0,0,0,0,0,0,4,0,0,2
2,0,0,0,0,0,0,0,4,0,0,2
2,0,0,0,0,0,0,0,4,0,0,2
2,0,0,0,0,0,0,0,4,0,0,2
1,2,2,2,2,2,2,2,1,0,0,1
2,22,0,0,0,0,0,21,2,0,0,2
2,22,0,0,0,0,0,21,2,0,0,2
2,22,0,0,0,0,0,21,2,0,0,2
2,22,0,0,0,0,0,21,2,5,5,6
2,22,0,0,0,0,0,21,2,6,6,3
2,22,0,0,0,0,0,21,2,3,3,3
2,22,0,0,0,0,0,21,2,3,3,3
2,22,0,0,0,0,0,21,2,3,3,3
2,22,0,0,0,0,0,21,2,3,3,3
2,22,0,0,0,0,0,21,2,3,3,3
2,23,23,23,23,23,23,21,2,3,3,3
1,2,2,2,2,2,2,2,1,3,3,3
endlayer

layer
1,1,1,1,1,1,1,1,1,1,1,1
1,2,2,2,2,2,2,2,1,2,2,1
1,2,2,2,2,2,2,2,1,2,2,1
1,2,2,2,2,2,2,2,1,2,2,1
1,2,2,2,2,2,2,2,1,2,2,1
1,2,2,2,2,2,2,2,1,2,2,1
1,1,1,1,1,1,1,1,1,1,1,1
1,2,2,2,2,2,2,2,1,0,0,1
1,2,2,2,2,2,2,2,1,0,0,1
1,2,2,2,2,2,2,2,1,0,0,1
1,2,2,2,2,2,2,2,1,0,0,1
1,2,2,2,2,2,2,2,1,5,5,1
1,2,2,2,2,2,2,2,1,2,2,1
1,2,2,2,2,2,2,2,1,2,2,1
1,2,2,2,2,2,2,2,1,1,1,1
1,2,2,2,2,2,2,2,1,3,3,3
1,2,2,2,2,2,2,2,1,3,3,3
1,2,2,2,2,2,2,2,1,3,3,3
1,1,1,1,1,1,1,1,1,3,3,3
endlayer

layer
3,3,3,3,3,3,3,3,3,3,3,3
3,3,3,3,3,3,3,3,3,3,3,3
3,3,3,3,3,3,3,3,3,3,3,3
3,3,3,3,3,3,3,3,3,3,3,3
3,3,3,3,3,3,3,3,3,3,3,3
3,3,3,3,3,3,3,3,3,3,3,3
3,3,3,3,3,3,3,3,3,3,3,3
3,3,3,3,3,3,3,3,3,3,3,3
3,3,3,3,3,3,3,3,3,0,0,3
3,3,3,3,3,3,3,3,3,0,0,3
3,3,3,3,3,3,3,3,3,0,0,3
3,3,3,3,3,3,3,3,3,0,0,3
3,3,3,3,3,3,21,2,13,0,0,3
3,3,3,3,3,3,21,2,13,0,0,3
3,3,3,3,3,3,3,3,3,3,3,3
3,3,3,3,3,3,3,3,3,3,3,3
3,3,3,3,3,3,3,3,3,3,3,3
3,3,3,3,3,3,3,3,3,3,3,3
3,3,3,3,3,3,3,3,3,3,3,3
endlayer

layer
3,3,3,3,3,3,3,3,3,3,3,3
3,3,3,3,3,3,3,3,3,3,3,3
3,3,3,3,3,3,3,3,3,3,3,3
3,3,3,3,3,3,3,3,3,3,3,3
3,3,3,3,3,3,3,3,3,3,3,3
3,3,3,3,3,3,3,3,3,3,3,3
3,3,3,3,3,3,3,3,3,3,3,3
3,3,3,3,3,3,3,3,3,3,3,3
3,3,3,3,3,3,3,3,3,3,3,3
3,3,3,3,3,3,3,3,3,0,0,3
3,3,3,3,3,3,3,3,3,0,0,3
3,3,3,3,3,3,3,3,3,0,0,3
3,3,3,3,3,21,2,13,0,0,0,3
3,3,3,3,3,21,2,13,0,0,0,3
3,3,3,3,3,3,3,3,3,3,3,3
3,3,3,3,3,3,3,3,3,3,3,3
3,3,3,3,3,3,3,3,3,3,3,3
3,3,3,3,3,3,3,3,3,3,3,3
3,3,3,3,3,3,3,3,3,3,3,3
endlayer

layer
3,3,3,3,3,3,3,3,3,3,3,3
3,3,3,3,3,3,3,3,3,3,3,3
3,3,3,3,3,3,3,3,3,3,3,3
3,3,3,3,3,3,3,3,3,3,3,3
3,3,3,3,3,3,3,3,3,3,3,3
3,3,3,3,3,3,3,3,3,3,3,3
3,3,3,3,3,3,3,3,3,3,3,3
3,3,3,3,3,3,3,3,3,3,3,3
3,3,3,3,3,3,3,3,3,3,3,3
3,3,3,3,3,3,3,3,3,3,3,3
3,3,3,3,3,3,3,3,3,0,0,3
3,3,3,3,3,3,3,3,3,0,0,3
3,3,3,3,21,2,13,0,0,0,0,3
3,3,3,3,21,2,13,0,0,0,0,3
3,3,3,3,3,3,3,3,3,3,3,3
3,3,3,3,3,3,3,3,3,3,3,3
3,3,3,3,3,3,3,3,3,3,3,3
3,3,3,3,3,3,3,3,3,3,3,3
3,3,3,3,3,3,3,3,3,3,3,3
endlayer

layer
3,3,3,3,3,3,3,3,3,3,3,3
3,3,3,3,3,3,3,3,3,3,3,3
3,3,3,3,3,3,3,3,3,3,3,3
3,3,3,3,3,3,3,3,3,3,3,3
3,3,3,3,3,3,3,3,3,3,3,3
3,3,3,3,3,3,3,3,3,3,3,3
3,3,3,3,3,3,3,3,3,3,3,3
3,3,3,3,3,3,3,3,3,3,3,3
3,3,3,3,3,3,3,3,3,3,3,3
3,3,3,3,3,3,3,3,3,3,3,3
3,3,3,23,23,3,3,3,3,3,3,3
3,3,3,2,2,3,3,3,3,3,3,3
3,3,3,2,2,13,0,0,0,3,3,3
3,3,3,2,2,13,0,0,0,3,3,3
3,3,3,3,3,3,3,3,3,3,3,3
3,3,3,3,3,3,3,3,3,3,3,3
3,3,3,3,3,3,3,3,3,3,3,3
3,3,3,3,3,3,3,3,3,3,3,3
3,3,3,3,3,3,3,3,3,3,3,3
endlayer

layer
3,3,3,3,3,3,3,3,3,3,3,3
3,3,3,3,3,3,3,3,3,3,3,3
3,3,3,3,3,3,3,3,3,3,3,3
3,3,3,3,3,3,3,3,3,3,3,3
3,3,3,3,3,3,3,3,3,3,3,3
3,3,3,3,3,3,3,3,3,3,3,3
3,3,3,3,3,3,3,3,3,3,3,3
3,3,3,3,3,3,3,3,3,3,3,3
3,3,3,3,3,3,3,3,3,3,3,3
3,3,3,23,23,3,3,3,3,3,3,3
3,3,3,2,2,3,3,3,3,3,3,3
3,3,3,24,24,3,3,3,3,3,3,3
3,3,3,0,0,0,0,0,3,3,3,3
3,3,3,0,0,0,0,0,3,3,3,3
3,3,3,3,3,3,3,3,3,3,3,3
3,3,3,3,3,3,3,3,3,3,3,3
3,3,3,3,3,3,3,3,3,3,3,3
3,3,3,3,3,3,3,3,3,3,3,3
3,3,3,3,3,3,3,3,3,3,3,3
endlayer

layer
3,3,3,3,3,3,3,3,3,3,3,3
3,3,3,3,3,3,3,3,3,3,3,3
3,3,3,3,3,3,3,3,3,3,3,3
3,3,3,3,3,3,3,3,3,3,3,3
3,3,3,3,3,3,3,3,3,3,3,3
3,3,3,3,3,3,3,3,3,3,3,3
3,3,3,3,3,3,3,3,3,3,3,3
3,3,3,3,3,3,3,3,3,3,3,3
3,3,3,23,23,3,3,3,3,3,3,3
3,3,3,2,2,3,3,3,3,3,3,3
3,3,3,24,24,3,3,3,3,3,3,3
3,3,3,0,0,3,3,3,3,3,3,3
3,3,3,0,0,0,0,3,3,3,3,3
3,3,3,0,0,0,0,3,3,3,3,3
3,3,3,3,3,3,3,3,3,3,3,3
3,3,3,3,3,3,3,3,3,3,3,3
3,3,3,3,3,3,3,3,3,3,3,3
3,3,3,3,3,3,3,3,3,3,3,3
3,3,3,3,3,3,3,3,3,3,3,3
endlayer

layer
3,3,3,3,3,3,3,3,3,3,3,3
3,3,3,3,3,3,3,3,3,3,3,3
3,3,3,3,3,3,3,3,3,3,3,3
3,3,3,3,3,3,3,3,3,3,3,3
3,3,3,3,3,3,3,3,3,3,3,3
3,3,3,3,3,3,3,3,3,3,3,3
3,3,3,3,3,3,3,3,3,3,3,3
3,3,3,23,23,3,3,3,3,3,3,3
3,3,3,2,2,3,3,3,3,3,3,3
3,3,3,24,24,3,3,3,3,3,3,3
3,3,3,0,0,3,3,3,3,3,3,3
3,3,3,0,0,3,3,3,3,3,3,3
3,3,3,0,0,0,3,3,3,3,3,3
3,3,3,0,0,0,3,3,3,3,3,3
3,3,3,3,3,3,3,3,3,3,3,3
3,3,3,3,3,3,3,3,3,3,3,3
3,3,3,3,3,3,3,3,3,3,3,3
3,3,3,3,3,3,3,3,3,3,3,3
3,3,3,3,3,3,3,3,3,3,3,3
endlayer

layer
3,3,3,3,3,3,3,3,3,3,3,3
3,3,3,3,3,3,3,3,3,3,3,3
3,3,3,3,3,3,3,3,3,3,3,3
3,3,3,3,3,3,3,3,3,3,3,3
3,3,3,3,3,3,3,3,3,3,3,3
3,3,3,3,3,3,3,3,3,3,3,3
3,3,3,3,3,3,3,3,3,3,3,3
3,3,3,3,3,3,3,3,3,3,3,3
3,3,3,24,24,3,3,3,3,3,3,3
3,3,3,0,0,3,3,3,3,3,3,3
3,3,3,0,0,3,3,3,3,3,3,3
3,3,3,0,0,3,3,3,3,3,3,3
3,3,3,0,0,3,3,3,3,3,3,3
3,3,3,0,0,3,3,3,3,3,3,3
3,3,3,3,3,3,3,3,3,3,3,3
3,3,3,3,3,3,3,3,3,3,3,3
3,3,3,3,3,3,3,3,3,3,3,3
3,3,3,3,3,3,3,3,3,3,3,3
3,3,3,3,3,3,3,3,3,3,3,3
endlayer

