
# Created by Ruins mod version 17.1 Ingame Parser
# authoring Player: ST753M

# criterion expression specifying mod ids required to load template
# may include plus (AND), minus (AND NOT), comma (OR), and parentheses
# all required mods listed must be present; no prohibited mods can be
requiredMods=
# likelihood this template will be chosen relative to all others
# e.g., a weight=6 template is chosen 3X as often as one with weight=2
weight=2
# list of other biomes in which this template may spawn
# biome corresponding to directory is always assumed, listed or not
# generic templates should leave this list empty
biomesToSpawnIn=mutated_swampland,jungle_edge,forest,grove,roofed_forest,taiga,taiga_hills,mutated_redwood_taiga,mutated_redwood_taiga_hills,redwood_taiga,mutated_taiga,redwood_taiga_hills,redwood_forest,coniferous_forest,shield,dead_forest,autumnal_wooded_hills,autumnal_woods,plains
# criterion expression specifying types of biome where template spawns
# this is in addition to those explicitly listed as biomesToSpawnIn
# generic templates should leave this list empty
biomeTypesToSpawnIn=
# list of biomes in which this template may not spawn
# takes precedence over biomeTypesToSpawnIn, but NOT biomesToSpawnIn
# should be empty if biomeTypesToSpawnIn is empty
biomesToNotSpawnIn=
# depth template is pushed down into the surface when built
# offset is min/max range of random additional bury depth
embed_into_distance=10
random_height_offset=0,0
# whitelist/blacklist of block types on which template may be built
# specify one, not both; leave the other empty (both empty = allow all)
acceptable_target_blocks=
unacceptable_target_blocks=flowing_water,water,flowing_lava,lava
# size of template (#layers, #rows per layer, #blocks per row)
dimensions=11,15,12
# max number of missing blocks allowed in surface beneath template
allowable_overhang=7
# depth/height limit affected by terrain leveling
# also maximum bumpiness tolerated in surface beneath template
max_leveling=0
# padding applied to all sides of template horizontal footprint
# expands area affected by terrain leveling (-1 = no leveling)
leveling_buffer=-1
# do not rotate template randomly when built (1 = no rotation)
preventRotation=0
# treat water/lava blocks as air and protect them from rule0 (1 = yes)
preserve_water=0
preserve_lava=0
# minimum distance this template must have from instances of itself
uniqueMinDistance=1000
# min/max distances this template can be from world spawn (0 = no limit)
# only applies to overworld--i.e., dimension 0
spawnMinDistance=1000
spawnMaxDistance=0
# other template built nearby whenever this one is
# syntax: <name>;<relativeX>;<maxYdifference>;<relativeZ>[;<chance>]
# may be used more than once to specify multiple neighbors
adjoining_template=

rule1=0,100,preserveBlock
rule2=0,100,minecraft:dirt-0
rule3=0,100,minecraft:tnt-0
rule4=0,100,iceandfire:goldpile-0,iceandfire:goldpile-1,iceandfire:goldpile-2,iceandfire:goldpile-3,iceandfire:goldpile-4
rule5=0,100,MobSpawner:if_cockatrice,MobSpawner:if_troll,MobSpawner:skeleton,MobSpawner:skeleton,MobSpawner:zombie,MobSpawner:if_troll,MobSpawner:if_troll,MobSpawner:skeleton,MobSpawner:skeleton,MobSpawner:zombie,MobSpawner:skeleton,MobSpawner:skeleton,MobSpawner:zombie
rule6=0,100,IInventory;minecraft:trapped_chest;iceandfire:dragonbone_hoe#1#0#12+iceandfire:troll_weapon.trunk#1#0#15-5,IInventory;minecraft:trapped_chest;iceandfire:dragonbone_pickaxe#1#0#13+iceandfire:troll_weapon.hammer#1#0#19-5,IInventory;minecraft:trapped_chest;iceandfire:dragonbone_axe#1#0#12+iceandfire:troll_weapon.trunk_frost#1#0#19-5,IInventory;minecraft:trapped_chest;iceandfire:dragonbone_arrow#16#0#6+iceandfire:dragonbone_bow#1#0#12+iceandfire:troll_weapon.column#1#0#25-5,IInventory;minecraft:trapped_chest;iceandfire:troll_weapon.axe#1#0#13+iceandfire:dragonbone_shovel#1#0#20-5,IInventory;minecraft:trapped_chest;iceandfire:troll_weapon.column_forest#1#0#14+iceandfire:dragonbone#4#0#21-5

layer
1,1,1,1,1,1,1,1,1,1,1,1
1,1,1,2,2,2,2,2,1,1,1,1
1,1,2,2,2,2,2,2,2,2,1,1
1,2,2,2,2,2,2,2,3,3,1,1
1,2,2,2,2,2,2,2,3,3,1,1
1,2,2,2,2,2,2,2,2,2,2,1
1,2,2,2,2,2,2,2,2,2,2,1
1,2,2,2,2,2,2,2,2,2,2,1
1,2,2,2,2,2,2,2,2,2,2,1
1,2,2,2,2,2,2,2,2,2,2,1
1,2,2,2,2,2,2,2,2,2,2,1
1,2,2,2,2,2,2,2,2,2,2,1
1,2,2,2,2,2,2,2,2,2,1,1
1,1,2,2,2,2,2,2,2,1,1,1
1,1,1,1,1,1,1,1,1,1,1,1
endlayer

layer
1,1,1,2,2,2,2,2,1,1,1,1
1,1,2,2,2,2,2,2,2,2,1,1
1,2,2,2,2,2,2,2,2,2,1,1
1,2,2,2,2,2,2,2,2,2,2,1
2,2,2,2,2,2,2,2,2,2,2,1
2,2,2,2,2,2,2,2,2,2,2,2
2,2,2,2,0,4,2,2,2,2,2,2
2,2,2,2,0,0,0,2,2,2,2,2
2,2,2,0,0,0,0,0,2,2,2,2
2,2,2,0,0,0,0,4,0,2,2,2
2,2,4,0,0,4,0,0,4,2,2,1
2,2,0,0,0,4,0,4,4,2,2,1
1,2,2,4,0,0,4,2,2,2,1,1
1,2,2,2,2,2,2,2,5,2,1,1
1,1,2,2,2,2,2,2,2,1,1,1
endlayer

layer
1,1,1,2,2,2,2,2,1,1,1,1
1,1,2,2,2,2,2,2,2,2,1,1
1,2,2,0,2,2,2,2,2,2,1,1
1,2,0,0,0,2,2,2,2,2,2,1
2,2,0,0,0,0,2,2,2,6,2,1
2,2,0,0,0,2,2,2,4,0,4,2
2,0,0,0,0,0,0,0,0,4,4,2
2,0,0,0,0,0,0,0,4,0,4,2
2,2,0,0,0,0,0,0,0,4,2,2
2,2,4,0,0,0,0,0,0,4,2,2
2,2,0,0,0,0,0,0,0,4,2,1
2,2,0,0,0,0,0,0,0,2,2,1
1,2,4,0,0,0,0,4,2,2,1,1
1,2,4,4,2,2,2,2,2,1,1,1
1,1,2,2,2,2,2,2,1,1,1,1
endlayer

layer
1,1,1,2,2,2,2,2,1,1,1,1
1,1,2,2,2,2,2,2,2,2,1,1
1,2,0,0,0,0,2,2,2,2,1,1
1,2,0,0,0,0,0,2,2,2,2,1
2,0,0,0,0,0,0,2,2,0,2,1
2,0,0,0,0,2,2,2,0,0,0,2
2,0,0,0,0,0,0,0,0,0,0,2
2,0,0,0,0,0,0,0,0,0,0,2
2,0,0,0,0,0,0,0,0,0,4,2
2,0,0,0,0,0,0,0,0,0,4,2
2,4,0,0,0,0,0,0,0,0,2,1
2,2,0,0,0,0,0,0,0,4,2,1
1,2,0,0,0,0,0,0,4,2,1,1
1,2,0,0,4,0,2,2,2,1,1,1
1,1,2,2,2,2,2,2,1,1,1,1
endlayer

layer
1,1,1,2,2,2,2,2,1,1,1,1
1,1,2,2,2,2,2,2,2,2,1,1
1,2,2,0,0,0,0,0,2,2,1,1
1,2,0,0,0,0,0,0,2,2,2,1
2,2,0,0,0,0,0,0,2,2,2,1
2,0,0,0,0,0,2,2,2,0,2,2
2,0,0,0,0,0,0,0,0,0,0,2
2,0,0,0,0,0,0,0,0,0,0,2
2,0,0,0,0,0,0,0,0,0,0,2
2,0,0,0,0,0,0,0,0,0,0,2
2,0,0,0,0,0,0,0,0,0,2,1
2,4,0,0,0,0,0,0,0,0,2,1
1,2,0,0,0,0,0,0,0,2,1,1
1,2,2,0,0,0,0,2,2,1,1,1
1,1,2,2,2,2,2,2,1,1,1,1
endlayer

layer
1,1,1,2,2,2,2,2,1,1,1,1
1,1,2,2,2,2,2,2,2,2,1,1
1,2,2,2,2,0,0,0,2,2,1,1
1,2,2,0,0,0,0,0,0,2,2,1
2,2,0,0,0,0,0,0,0,2,2,1
2,2,0,0,0,0,2,2,2,2,2,2
2,2,0,0,0,0,0,2,0,0,0,2
2,0,0,0,0,0,0,0,0,0,0,2
2,0,0,0,0,0,0,0,0,0,0,2
2,0,0,0,0,0,0,0,0,0,2,2
2,2,0,0,0,0,0,0,2,2,2,1
2,2,0,0,0,0,0,0,2,2,2,1
1,2,0,0,0,0,0,2,2,2,1,1
1,2,2,2,0,0,2,2,2,1,1,1
1,1,2,2,2,2,2,2,1,1,1,1
endlayer

layer
1,1,1,1,1,1,1,1,1,1,1,1
1,1,1,2,2,2,2,2,1,1,1,1
1,1,2,2,2,2,2,2,2,1,1,1
1,1,2,2,2,2,0,0,0,0,0,1
1,2,2,2,2,0,0,0,0,0,0,1
1,2,2,2,2,2,2,2,2,2,2,1
1,2,2,2,0,0,2,2,2,2,2,1
1,2,2,2,0,0,0,0,2,2,2,1
1,2,2,0,0,0,0,0,0,2,2,1
1,2,2,0,0,0,0,0,2,2,2,1
1,2,0,0,0,0,2,2,2,2,1,1
1,2,0,0,0,2,2,2,2,2,1,1
1,1,2,0,2,2,2,2,2,1,1,1
1,1,2,2,2,2,2,2,1,1,1,1
1,1,1,1,1,1,1,1,1,1,1,1
endlayer

layer
1,1,1,1,1,1,1,1,1,1,1,1
1,1,1,1,1,1,1,1,1,1,1,1
1,1,1,1,1,2,1,1,1,1,1,1
1,1,1,1,2,2,2,0,0,0,0,1
1,1,1,1,2,2,2,0,0,0,0,1
1,1,1,2,2,2,2,2,2,0,0,1
1,1,1,2,2,2,2,2,2,0,0,1
1,1,2,2,2,2,2,2,2,2,1,1
1,1,2,2,2,2,2,2,2,1,1,1
1,1,2,2,2,2,2,2,2,1,1,1
1,1,2,2,2,2,2,2,1,1,1,1
1,1,2,2,2,2,2,1,1,1,1,1
1,1,1,2,2,2,1,1,1,1,1,1
1,1,1,1,1,1,1,1,1,1,1,1
1,1,1,1,1,1,1,1,1,1,1,1
endlayer

layer
1,1,1,1,1,1,1,1,1,1,1,1
1,1,1,1,1,1,1,1,1,1,1,1
1,1,1,1,1,1,1,1,1,1,1,1
1,1,1,1,1,1,1,1,0,0,0,1
1,1,1,1,1,1,1,1,0,0,0,1
1,1,1,1,1,1,1,1,1,0,0,1
1,1,1,1,1,1,1,1,0,0,0,1
1,1,1,1,1,1,1,1,0,0,1,1
1,1,1,1,1,1,1,1,0,1,1,1
1,1,1,1,1,1,1,1,1,1,1,1
1,1,1,1,1,1,1,1,1,1,1,1
1,1,1,1,1,1,1,1,1,1,1,1
1,1,1,1,1,1,1,1,1,1,1,1
1,1,1,1,1,1,1,1,1,1,1,1
1,1,1,1,1,1,1,1,1,1,1,1
endlayer

layer
1,1,1,1,1,1,1,1,1,1,1,1
1,1,1,1,1,1,1,1,1,1,1,1
1,1,1,1,1,1,1,1,1,0,0,1
1,1,1,1,1,1,1,1,1,0,0,1
1,1,1,1,1,1,1,1,1,0,0,1
1,1,1,1,1,1,1,1,0,0,0,0
1,1,1,1,1,1,1,0,0,0,0,0
1,1,1,1,1,1,1,0,0,0,0,1
1,1,1,1,1,1,0,0,0,0,0,1
1,1,1,1,1,1,1,0,0,0,1,1
1,1,1,1,1,1,1,1,1,1,1,1
1,1,1,1,1,1,1,1,1,1,1,1
1,1,1,1,1,1,1,1,1,1,1,1
1,1,1,1,1,1,1,1,1,1,1,1
1,1,1,1,1,1,1,1,1,1,1,1
endlayer

layer
1,1,1,1,1,1,1,1,1,1,1,1
1,1,1,1,1,1,1,1,0,0,0,1
1,1,1,1,1,1,1,1,0,0,0,0
1,1,1,1,1,1,1,0,0,0,0,0
1,1,1,1,1,1,1,0,0,0,0,0
1,1,1,1,1,1,0,0,0,0,0,0
1,1,1,1,1,1,0,0,0,0,0,0
1,1,1,1,1,0,0,0,0,0,0,0
1,1,1,1,1,0,0,0,0,0,0,1
1,1,1,1,1,0,0,0,0,0,0,1
1,1,1,1,1,1,0,0,0,0,1,1
1,1,1,1,1,1,1,0,0,0,1,1
1,1,1,1,1,1,1,1,1,1,1,1
1,1,1,1,1,1,1,1,1,1,1,1
1,1,1,1,1,1,1,1,1,1,1,1
endlayer

