
# Created by Ruins mod version 17.0 Ingame Parser
# authoring Player: ST753M

weight=1
embed_into_distance=9
acceptable_target_blocks=grass,dirt,podzol,biomesoplenty:grass,biomesoplenty:dirt
unacceptable_target_blocks=flowing_water,water,flowing_lava,lava
dimensions=10,13,11
allowable_overhang=9
max_leveling=0
leveling_buffer=0
preserve_water=0
preserve_lava=0

biomesToSpawnIn=swampland,mutated_swampland,wetland,quagmire,lush_swamp,mangrove,marsh,bayou,bog,bamboo_forest,dead_swamp,moor,dead_swamp,coralium_infested_swamp,forest,maple_woods,boreal_forest,forest_hills,woodland,seasonal_forest,temperate_rainforest,fen,grove,sacred_springs,land_of_lakes,forested_hills,lush_hills,thicket,birch_forest,birch_forest_hills,mutated_birch_forest,mutated_birch_forest_hills,birch_forested_hills,taiga,taiga_hills,mutated_redwood_taiga,mutated_redwood_taiga_hills,redwood_taiga,mutated_taiga,redwood_taiga_hills,redwood_forest,coniferous_forest,shield,dead_forest,autumnal_wooded_hills,autumnal_woods,plains,prairie,shrubland,chaparral,grassland,meadow,orchard,rocky_plains,rocky_plateau,savanna,savanna_rock,mutated_savanna,mutated_savanna_rock,brushland,steppe,wasteland,tundra,outback,badlands,desert_shrubland,arid_highland,darklands,darklands_forest,darklands_hills,darklands_mountains,darklands_plains,ominous_woods,eerie

rule1=0,100,preserveBlock
rule2=0,100,minecraft:dirt-0
rule3=0,100,minecraft:web-0

rule4=0,90,IInventory;minecraft:chest;minecraft:wheat_seeds#2#0#2+minecraft:wheat_seeds#2#0#9+minecraft:wheat_seeds#5#0#13+minecraft:stone_shovel#{ench:[{lvl:2s,id:34s},{lvl:2s,id:32s}],RepairCost:3}#0#16+minecraft:bucket#2#0#20+minecraft:wheat_seeds#2#0#23-2,IInventory;minecraft:chest;minecraft:arrow#1#0#1+minecraft:arrow#4#0#5+minecraft:leather_helmet#{ench:[{lvl:1s,id:0s}],RepairCost:1}#0#12+minecraft:coal#2#0#16+minecraft:arrow#5#0#18+minecraft:coal#3#0#23+minecraft:arrow#4#0#26-2,IInventory;minecraft:chest;minecraft:fermented_spider_eye#2#0#4+minecraft:fermented_spider_eye#1#0#11+minecraft:fermented_spider_eye#1#0#17+minecraft:fermented_spider_eye#1#0#19+minecraft:leather_leggings#{ench:[{lvl:1s,id:0s}],RepairCost:1}#0#20+minecraft:skull#1#0#24-2,IInventory;minecraft:chest;minecraft:spider_eye#1#0#5+minecraft:spider_eye#2#0#8+minecraft:spider_eye#1#0#10+minecraft:stone_axe#{ench:[{lvl:2s,id:34s}],RepairCost:1}#0#12+minecraft:spider_eye#4#0#14+minecraft:water_bucket#1#0#25-2,IInventory;minecraft:chest;minecraft:dye#4#3#1+minecraft:stone_sword#{ench:[{lvl:5s,id:18s}],RepairCost:1}#0#5+minecraft:fermented_spider_eye#3#0#15+minecraft:fermented_spider_eye#2#0#20-2,IInventory;minecraft:chest;minecraft:spider_eye#3#0#3+minecraft:skull#1#0#6+minecraft:spider_eye#2#0#10+minecraft:spider_eye#3#0#23+minecraft:leather_chestplate#{ench:[{lvl:1s,id:0s}],RepairCost:1}#0#25-2,IInventory;minecraft:chest;minecraft:rotten_flesh#1#0#0+minecraft:rotten_flesh#2#0#7+minecraft:rotten_flesh#3#0#11+minecraft:rotten_flesh#1#0#14+minecraft:stone_sword#{ench:[{lvl:2s,id:34s}],RepairCost:1}#0#20+minecraft:skull#1#2#22+minecraft:rotten_flesh#1#0#25-2,IInventory;minecraft:chest;minecraft:bucket#1#0#1+minecraft:stone_pickaxe#{ench:[{lvl:3s,id:34s},{lvl:2s,id:32s}],RepairCost:3}#0#15+minecraft:ender_pearl#2#0#21+minecraft:bucket#1#0#25-2,IInventory;minecraft:chest;minecraft:rotten_flesh#1#0#2+minecraft:rotten_flesh#2#0#7+minecraft:leather_boots#{ench:[{lvl:1s,id:0s}],RepairCost:1}#0#14+minecraft:rotten_flesh#5#0#19+minecraft:skull#1#3#24-2

rule5=0,100,MobSpawner:spider,MobSpawner:cave_spider
rule6=0,100,minecraft:grass-0

layer
1,1,1,1,1,1,1,1,1,1,1
1,1,1,1,1,1,1,1,1,1,1
1,1,1,1,2,2,2,1,1,1,1
1,1,1,1,2,2,2,2,1,1,1
1,1,1,1,2,2,2,2,1,1,1
1,1,2,2,2,2,2,2,1,1,1
1,1,2,2,2,2,2,2,2,1,1
1,1,1,2,2,2,2,2,2,1,1
1,1,1,1,2,2,2,2,2,1,1
1,1,1,1,2,2,2,2,1,1,1
1,1,1,1,1,1,1,1,1,1,1
1,1,1,1,1,1,1,1,1,1,1
1,1,1,1,1,1,1,1,1,1,1
endlayer

layer
1,1,1,1,1,1,1,1,1,1,1
1,1,1,2,2,2,2,2,1,1,1
1,1,1,2,2,2,2,2,2,1,1
1,1,2,2,2,2,0,0,2,1,1
1,2,2,2,2,3,0,0,2,1,1
1,2,2,2,3,0,0,3,2,2,1
1,2,2,3,0,3,0,0,3,2,1
1,2,2,0,0,0,0,3,0,2,1
1,1,2,2,0,3,0,3,0,2,1
1,1,1,2,3,0,3,0,2,2,1
1,1,1,2,2,2,2,2,2,1,1
1,1,1,1,1,1,1,1,1,1,1
1,1,1,1,1,1,1,1,1,1,1
endlayer

layer
1,1,1,1,2,2,2,2,2,1,1
1,1,1,2,2,4,0,0,2,2,1
1,2,2,2,2,4,0,0,0,2,1
2,2,2,2,5,2,0,0,0,2,1
2,3,0,0,2,0,0,0,0,2,2
2,0,0,0,0,0,0,0,0,3,2
2,0,0,0,0,0,0,0,0,0,2
2,2,0,0,0,0,0,0,0,0,2
1,2,2,0,0,0,3,3,3,3,2
1,1,2,0,0,0,0,3,3,2,2
1,1,2,2,0,0,0,2,2,2,1
1,1,1,2,2,2,2,1,1,1,1
1,1,1,1,1,1,1,1,1,1,1
endlayer

layer
1,1,1,1,2,2,2,2,2,1,1
1,1,2,2,2,0,0,0,0,2,1
1,2,2,2,2,0,0,0,0,2,1
2,0,0,3,2,2,0,0,3,3,2
2,3,0,0,2,3,0,0,0,0,2
2,0,0,0,3,3,0,0,0,3,2
2,0,0,0,0,0,0,0,0,0,2
2,3,0,0,0,0,0,0,0,0,2
1,2,0,0,0,0,0,0,0,0,2
1,2,0,0,0,0,0,0,0,3,2
1,2,0,3,0,0,0,3,3,2,1
1,1,2,3,0,3,2,2,2,1,1
1,1,1,2,2,2,1,1,1,1,1
endlayer

layer
1,1,1,2,2,2,2,2,2,1,1
1,1,2,0,0,2,0,0,0,2,1
1,2,0,0,0,2,3,0,0,2,1
2,0,0,0,2,2,0,0,0,3,2
2,0,0,0,2,0,0,0,0,3,2
2,0,0,0,0,0,0,0,0,0,2
2,3,0,0,0,0,0,0,0,0,2
2,0,0,0,0,0,0,0,0,0,2
1,2,3,3,0,0,0,0,0,0,2
1,2,0,0,0,0,0,0,3,0,2
1,2,0,3,3,0,0,0,3,2,1
1,1,2,3,3,0,2,2,2,1,1
1,1,1,2,2,2,1,1,1,1,1
endlayer

layer
1,1,1,2,2,2,2,2,2,1,1
1,1,2,0,0,0,2,3,0,2,1
1,2,0,0,0,0,2,0,0,2,1
2,0,0,0,2,2,3,0,3,3,2
2,0,0,0,2,2,0,0,0,3,2
2,3,0,0,0,0,0,0,0,3,2
2,0,0,0,0,0,0,0,0,3,2
2,3,0,0,0,0,0,0,0,0,2
1,2,0,0,0,0,0,0,0,0,2
1,2,0,0,0,0,0,0,0,0,2
1,2,3,3,0,0,3,0,0,2,1
1,1,2,3,0,3,2,2,2,1,1
1,1,1,2,2,2,1,1,1,1,1
endlayer

layer
1,1,1,2,2,2,2,2,2,1,1
1,1,2,3,0,0,0,6,2,2,1
1,2,0,0,0,0,0,2,0,2,1
1,2,0,0,2,2,2,0,3,2,1
2,3,0,3,2,2,0,0,3,2,1
2,3,0,0,0,0,0,0,3,3,2
2,0,0,0,0,0,0,0,3,3,2
1,2,0,0,0,0,0,0,0,3,2
1,2,0,0,0,0,0,0,0,2,1
1,2,3,3,0,0,0,0,0,2,1
1,1,2,3,3,0,0,0,2,2,1
1,1,1,2,3,0,2,2,1,1,1
1,1,1,1,2,2,1,1,1,1,1
endlayer

layer
1,1,1,2,2,2,2,2,1,1,1
1,1,2,0,3,0,0,0,6,2,1
1,1,2,3,0,0,0,0,6,2,1
1,2,3,0,2,2,2,2,2,2,1
1,2,0,2,2,2,0,3,3,2,1
1,2,0,0,3,2,0,3,3,2,1
1,2,0,0,0,3,3,0,3,2,1
1,2,3,0,0,0,0,0,0,2,1
1,1,2,0,0,0,3,0,3,2,1
1,1,2,3,0,0,0,0,2,1,1
1,1,1,2,3,0,3,2,2,1,1
1,1,1,1,2,2,2,1,1,1,1
1,1,1,1,1,1,1,1,1,1,1
endlayer

layer
1,1,1,1,1,1,1,1,1,1,1
1,1,1,2,2,0,0,0,0,6,1
1,1,1,6,2,3,0,0,0,6,1
1,1,2,6,2,2,2,2,6,6,1
1,2,2,2,2,2,0,2,6,2,1
1,2,2,2,2,2,0,0,6,2,1
1,1,2,3,3,3,3,3,2,2,1
1,1,2,2,3,0,3,0,2,1,1
1,1,2,6,3,3,3,2,2,1,1
1,1,1,6,2,6,2,2,2,1,1
1,1,1,1,2,2,2,1,1,1,1
1,1,1,1,1,1,1,1,1,1,1
1,1,1,1,1,1,1,1,1,1,1
endlayer

layer
1,1,1,1,1,1,1,1,1,1,1
1,1,1,1,1,1,0,0,0,0,1
1,1,1,1,1,1,0,0,0,0,1
1,1,1,1,6,6,6,1,0,0,1
1,1,1,6,6,6,6,6,1,1,1
1,1,1,6,6,6,6,6,1,1,1
1,1,1,6,6,6,6,6,1,1,1
1,1,1,1,6,6,6,6,1,1,1
1,1,1,1,6,6,6,1,1,1,1
1,1,1,1,1,1,1,1,1,1,1
1,1,1,1,1,1,1,1,1,1,1
1,1,1,1,1,1,1,1,1,1,1
1,1,1,1,1,1,1,1,1,1,1
endlayer

