
# Created by Ruins mod version 16.7 Ingame Parser
# authoring Player: lafuller

weight=1
embed_into_distance=4
acceptable_target_blocks=
unacceptable_target_blocks=flowing_water,water,flowing_lava,lava,ice,bedrock,netherrack,nether_brick,nether_brick_fence,soul_sand,quartz_ore,end_stone,obsidian,iron_bars,cloud,flesh,ash_block,slime_grass,slime_congealed,slime_dirt
biomesToSpawnIn=plains,forest,prarie,meadow,tundra,brushland,shrubland,woodland,woodlands,birch_forestlavender_fields,flower_field,sunflower_plains,ice_flats,ice_plains
dimensions=18,16,17
allowable_overhang=0
max_leveling=4
leveling_buffer=-1
preserve_water=0
preserve_lava=0

rule1=0,100,preserveBlock
rule2=0,100,stonebrick-0,stonebrick-0,stonebrick-0,stonebrick-0,stonebrick-1,stonebrick-2,stonebrick-2,stone-5,stone-6,cobblestone
rule3=0,100,minecraft:stone-6
rule4=0,100,stonebrick-0,stonebrick-2,stonebrick-1,stonebrick-1,stonebrick-1,cobblestone
rule5=0,100,stonebrick-0,stonebrick-1,stonebrick-2,stonebrick-2,stone-5,stone-5,stone-6,stone-6
rule6=0,100,stonebrick-0,stonebrick-2,stonebrick-0,stonebrick-1,stonebrick-1,cobblestone
rule7=0,100,minecraft:stone_brick_stairs-2
rule8=0,100,minecraft:stone_brick_stairs-3
rule9=0,100,air
rule10=0,100,stonebrick-0,stonebrick-0,stonebrick-0,stonebrick-0,stonebrick-1,stonebrick-2,stonebrick-2,stone-5,stone-6,cobblestone,gravel
rule11=0,100,minecraft:cobblestone_wall-0
rule12=0,100,minecraft:stone-5
rule13=0,100,minecraft:log-0
rule14=0,100,minecraft:wooden_slab-9
rule15=0,100,minecraft:planks-1
rule16=0,100,minecraft:oak_stairs-0
rule17=0,100,minecraft:planks-0
rule18=0,100,bookshelf,hay_block,ChestGenHook:chests/spawn_bonus_chest:5-3,ChestGenHook:chests/village_blacksmith:5-3,ChestGenHook:chests/simple_dungeon:5-3,ChestGenHook:chests/abandoned_mineshaft:5-3,ChestGenHook:chests/stronghold_library:5-3,ChestGenHook:chests/stronghold_corridor:5-3,ChestGenHook:chests/stronghold_crossing:5-2,ChestGenHook:chests/igloo_chest:5-3
rule19=0,100,minecraft:web-0,air,air,air
rule20=0,100,minecraft:oak_stairs-7
rule21=0,100,minecraft:stone_brick_stairs-7
rule22=0,100,minecraft:stone_brick_stairs-6
rule23=0,100,minecraft:oak_stairs-2
rule24=0,100,minecraft:stone_brick_stairs-5
rule25=0,100,minecraft:oak_stairs-6
rule26=0,100,minecraft:spruce_fence_gate-5
rule27=0,100,minecraft:oak_stairs-3
rule28=0,100,minecraft:spruce_fence-0
rule29=0,100,minecraft:spruce_fence_gate-3
rule30=0,100,minecraft:stone-3
rule31=0,100,minecraft:spruce_fence_gate-1
rule32=0,100,minecraft:trapdoor-8
rule33=0,100,minecraft:oak_stairs-5
rule34=0,100,minecraft:oak_stairs-1
rule35=0,100,minecraft:fence-0
rule36=0,100,minecraft:spruce_fence_gate-4
rule37=0,100,minecraft:spruce_fence_gate-7
rule38=0,100,minecraft:jungle_door-2
rule39=0,100,minecraft:carpet-7
rule40=0,100,minecraft:furnace-2
rule41=0,100,minecraft:oak_stairs-4
rule42=0,100,minecraft:jungle_door-9
rule43=0,100,minecraft:jungle_door-8
rule44=0,100,minecraft:spruce_stairs-6
rule45=0,100,minecraft:spruce_stairs-4
rule46=0,100,minecraft:dark_oak_stairs-3
rule47=0,100,minecraft:wooden_slab-13
rule48=0,100,minecraft:dark_oak_stairs-5
rule49=0,100,minecraft:spruce_stairs-7
rule50=0,100,minecraft:dark_oak_stairs-0
rule51=0,100,minecraft:ladder-2
rule52=0,100,minecraft:dark_oak_stairs-1
rule53=0,100,minecraft:dark_oak_stairs-6
rule54=0,100,minecraft:spruce_stairs-5
rule55=0,100,minecraft:double_wooden_slab-5
rule56=0,100,minecraft:dark_oak_stairs-4
rule57=0,100,minecraft:dark_oak_stairs-2
rule58=0,100,minecraft:wooden_slab-5
rule59=0,100,minecraft:planks-5
rule60=0,100,minecraft:log-7
rule61=0,100,minecraft:planks-2
rule62=0,100,minecraft:log-11
rule63=0,100,minecraft:trapdoor-12
rule64=0,100,minecraft:trapdoor-15
rule65=0,100,minecraft:spruce_fence_gate-6
rule66=0,100,minecraft:spruce_stairs-3
rule67=0,100,minecraft:spruce_stairs-1
rule68=0,100,minecraft:spruce_stairs-2
rule69=0,100,minecraft:spruce_stairs-0
rule70=0,100,minecraft:dark_oak_stairs-7
rule71=0,100,minecraft:dark_oak_fence-0
rule72=0,100,minecraft:trapdoor-9

layer
1,1,1,1,1,1,1,1,1,1,1,1,1,1,1,1,1
1,1,1,1,1,2,2,2,2,2,1,1,1,1,1,1,1
1,1,1,1,2,4,4,4,4,3,1,1,1,1,1,1,1
1,1,1,2,2,4,5,5,5,4,2,1,1,1,1,1,1
1,1,2,4,4,4,5,4,4,4,2,1,1,1,1,1,1
1,3,4,4,5,5,6,6,5,4,2,1,1,1,1,1,1
1,2,4,5,5,6,6,6,5,4,2,3,2,2,3,1,1
1,2,4,5,6,6,6,5,5,4,4,4,4,4,4,2,1
1,2,4,5,6,5,6,6,5,5,5,4,5,5,4,2,1
1,2,4,4,5,5,6,6,6,6,5,5,4,5,4,3,1
1,1,3,4,4,5,6,5,6,6,5,4,5,4,4,2,1
1,1,2,4,4,5,5,5,6,5,4,4,4,4,4,2,1
1,1,1,3,2,4,4,5,5,5,4,2,2,2,3,1,1
1,1,1,8,2,3,4,4,4,4,4,2,2,2,7,1,1
1,1,1,8,2,2,2,3,2,2,3,2,2,2,7,1,1
9,1,1,8,2,3,1,3,1,1,3,1,3,2,7,1,1
endlayer

layer
1,1,1,1,1,1,1,1,1,1,1,1,1,1,1,1,1
1,1,1,1,1,10,11,10,10,10,1,1,1,1,1,1,1
1,1,1,1,10,13,14,14,13,12,1,1,1,1,1,1,1
1,1,1,10,10,9,9,9,9,9,10,1,1,1,1,1,1
1,1,10,9,9,9,9,9,9,9,11,1,1,1,1,1,1
1,12,13,9,9,9,9,9,9,9,10,1,1,1,1,1,1
1,11,14,9,9,9,9,15,15,15,13,12,10,11,12,1,1
1,10,14,9,9,9,9,9,9,9,9,9,9,9,9,10,1
1,11,14,9,9,9,9,9,9,9,9,9,9,9,9,11,1
1,10,13,9,9,9,9,9,9,9,9,9,13,16,16,12,1
1,1,12,9,9,9,9,9,9,9,9,9,9,17,17,10,1
1,1,10,13,9,9,9,9,9,9,9,9,18,17,17,10,1
1,1,1,12,10,9,9,9,9,9,9,10,10,11,12,1,1
1,1,1,1,10,12,13,14,14,14,13,10,10,7,1,1,1
1,1,1,1,8,10,10,12,11,11,12,10,10,7,1,1,1
1,1,1,1,8,10,1,10,1,1,10,1,10,7,1,1,1
endlayer

layer
1,1,1,1,1,1,1,1,1,1,1,1,1,1,1,1,1
1,1,1,1,1,10,11,10,10,10,1,1,1,1,1,1,1
1,1,1,1,10,13,19,19,13,3,1,1,1,1,1,1,1
1,1,1,10,10,19,9,9,9,19,10,1,1,1,1,1,1
1,1,10,19,9,9,9,9,9,9,11,1,1,1,1,1,1
1,3,13,9,9,9,9,9,9,9,10,1,1,1,1,1,1
1,11,19,9,9,9,9,9,9,9,13,3,10,11,3,1,1
1,10,9,9,9,9,9,9,9,9,9,9,9,9,9,10,1
1,11,19,9,9,9,9,9,9,9,9,9,9,9,9,11,1
1,10,13,9,9,9,9,9,9,9,9,9,13,9,9,3,1
1,1,3,19,9,9,9,9,9,9,9,9,20,16,16,11,1
1,1,10,13,19,9,9,9,9,9,9,19,20,17,17,10,1
1,1,1,3,10,19,19,9,9,9,19,10,10,11,3,1,1
1,1,1,1,10,3,13,19,9,19,13,10,7,1,1,1,1
1,1,1,1,1,8,10,3,11,11,3,10,7,1,1,1,1
1,1,1,1,1,8,22,10,1,1,10,21,7,1,1,1,1
endlayer

layer
1,1,1,1,1,1,1,1,1,1,1,1,1,1,1,1,1
1,1,1,1,1,10,11,10,10,10,1,1,1,1,1,1,1
1,1,1,1,10,13,19,19,13,12,1,1,1,1,1,1,1
1,1,1,10,10,19,19,9,19,19,10,1,1,1,1,1,1
1,1,10,19,19,19,9,9,19,19,11,1,1,1,1,1,1
1,12,13,19,9,9,9,9,19,19,10,1,1,1,1,1,1
1,11,19,19,9,9,9,14,14,14,13,12,10,11,12,1,1
1,10,19,9,9,9,9,9,9,9,9,9,9,9,19,10,1
1,11,19,19,9,9,9,9,9,9,9,9,9,9,9,11,1
1,10,13,19,9,9,9,9,9,9,9,9,13,9,9,12,1
1,1,12,19,19,9,9,9,9,9,9,19,23,9,9,11,1
1,1,10,13,19,19,19,9,9,9,19,19,23,9,9,10,1
1,1,1,12,10,19,19,19,9,19,19,10,10,11,12,1,1
1,1,1,1,10,12,13,19,19,19,13,10,1,1,1,1,1
1,1,1,1,1,1,10,12,10,10,12,7,1,1,1,1,1
1,1,1,1,1,1,8,10,24,24,10,7,1,1,1,1,1
endlayer

layer
1,1,1,1,1,1,1,1,1,1,1,1,1,1,1,1,1
1,1,1,1,1,2,2,2,2,2,1,1,1,1,1,1,1
1,1,1,1,2,17,17,17,17,3,1,1,1,1,1,1,1
1,1,1,2,17,17,15,15,15,17,2,1,1,1,1,1,1
1,1,2,17,17,17,15,17,17,17,2,1,1,1,1,1,1
1,3,17,17,15,15,17,17,15,17,2,1,1,1,1,1,1
1,2,17,15,15,17,17,17,15,17,17,3,2,2,3,1,1
1,2,17,15,17,17,17,15,15,17,17,17,25,19,19,2,1
1,2,17,15,17,15,17,17,15,15,15,17,25,9,9,2,1
1,2,17,17,15,15,17,17,17,17,15,15,13,9,9,3,1
1,1,3,17,17,15,17,15,17,17,15,23,9,9,9,2,1
1,1,2,17,17,15,15,15,17,15,17,23,9,9,9,2,1
1,1,1,3,17,17,17,15,15,15,17,2,2,2,3,1,1
1,1,1,1,2,3,17,17,17,17,17,2,1,1,1,1,1
1,1,1,1,1,1,2,3,17,17,3,1,1,1,1,1,1
1,1,1,1,1,1,1,8,10,10,7,1,1,1,1,1,1
endlayer

layer
1,1,1,1,1,1,1,1,1,1,1,1,1,1,1,1,1
1,1,1,1,1,16,16,16,16,16,1,1,1,1,1,1,1
1,1,1,1,16,13,26,26,26,13,1,1,1,1,1,1,1
1,1,1,27,9,9,9,9,9,9,23,1,1,1,1,1,1
1,1,16,13,9,9,9,9,9,9,23,1,1,1,1,1,1
1,27,30,9,9,9,9,28,29,28,17,1,1,1,1,1,1
1,13,30,9,9,9,9,28,31,28,13,17,16,16,13,1,1
1,27,32,9,9,9,9,9,9,9,9,27,17,17,17,23,1
1,27,32,9,9,9,9,9,9,9,9,34,17,33,33,23,1
1,27,30,9,9,9,9,9,9,9,9,9,13,9,9,13,1
1,35,13,9,9,9,9,9,9,9,9,9,9,9,9,23,1
1,1,27,36,9,9,9,9,9,9,9,9,9,9,9,23,1
1,1,1,13,37,9,9,9,9,9,9,13,34,34,13,35,1
1,1,1,1,34,13,37,9,9,9,9,23,1,1,1,1,1
1,1,1,1,1,1,34,13,38,38,13,35,1,1,1,1,1
1,1,1,1,1,1,1,1,9,9,1,1,1,1,1,1,1
endlayer

layer
1,1,1,1,1,1,1,1,1,1,1,1,1,1,1,1,1
1,1,1,1,1,1,35,9,35,35,1,1,1,1,1,1,1
1,1,1,1,35,13,39,39,39,13,1,1,1,1,1,1,1
1,1,1,35,9,9,9,9,9,9,9,1,1,1,1,1,1
1,1,16,13,9,9,9,9,9,9,35,1,1,1,1,1,1
1,27,40,9,9,9,9,39,39,39,17,1,1,1,1,1,1
1,13,9,9,9,9,9,39,39,39,13,17,41,41,13,1,1
1,9,9,9,9,9,9,9,9,9,9,9,27,17,17,25,1
1,9,9,9,9,9,9,9,9,9,9,9,27,17,17,23,1
1,35,9,9,9,9,9,9,9,9,9,9,13,33,33,13,1
1,35,13,9,9,9,9,9,9,9,9,9,9,9,9,35,1
1,1,35,39,9,9,9,9,9,9,9,9,9,9,9,35,1
1,1,1,13,39,9,9,9,9,9,9,13,35,35,13,35,1
1,1,1,1,35,13,39,9,9,9,9,35,1,1,1,1,1
1,1,1,1,1,1,35,13,43,42,13,35,1,1,1,1,1
1,1,1,1,1,1,1,1,9,9,1,1,1,1,1,1,1
endlayer

layer
1,1,1,1,1,1,1,1,1,1,1,1,1,1,1,1,1
1,1,1,1,46,45,45,45,45,44,1,1,1,1,1,1,1
1,1,1,47,45,13,9,9,9,13,48,47,1,1,1,1,1
1,1,47,49,9,9,9,9,9,9,44,1,1,1,1,1,1
1,50,45,13,9,9,9,9,9,9,44,1,1,1,1,1,1
47,49,11,9,9,9,9,9,9,9,17,47,1,1,1,1,1
1,13,51,9,9,9,9,9,9,9,13,17,16,16,13,50,1
1,49,9,9,9,9,9,9,9,9,9,9,9,9,9,25,1
1,49,9,9,9,9,9,9,9,9,9,9,9,9,9,25,1
1,49,9,9,9,9,9,9,9,9,9,9,13,16,16,13,1
1,52,13,9,9,9,9,9,9,9,9,9,9,20,17,44,1
1,46,49,9,9,9,9,9,9,9,9,9,9,20,17,44,1
1,1,55,13,9,9,9,9,9,9,9,13,54,54,13,53,1
1,1,47,56,54,13,9,9,9,9,9,44,1,1,1,47,1
1,1,1,58,55,48,54,13,29,29,13,57,1,1,1,1,1
1,1,1,1,1,1,1,1,9,9,1,47,1,1,1,1,1
endlayer

layer
1,1,1,1,1,58,47,47,47,58,1,1,1,1,1,1,1
1,1,1,1,58,59,59,59,59,59,58,1,1,1,1,1,1
1,1,1,1,59,13,54,54,54,13,57,1,1,1,1,1,1
1,1,58,59,54,9,9,9,9,49,59,57,1,1,1,1,1
1,55,59,13,9,9,9,9,9,49,59,58,1,1,1,1,1
1,59,11,9,9,9,9,9,9,49,17,58,1,1,1,1,1
50,13,44,9,9,9,9,9,9,54,13,16,16,16,13,1,1
47,59,44,9,9,9,9,9,9,9,9,9,9,9,9,13,50
47,59,44,9,9,9,9,9,9,9,9,9,9,9,9,27,48
47,59,44,9,9,9,9,9,9,9,9,9,13,9,9,13,47
58,59,13,9,9,9,9,9,9,9,9,9,20,16,16,17,56
1,58,59,44,9,9,9,9,9,9,9,9,20,17,17,13,52
1,1,46,13,45,9,9,9,9,9,9,13,15,15,13,58,1
1,1,1,52,59,13,45,45,45,45,45,15,53,47,57,1,1
1,1,1,1,1,46,59,13,59,59,59,52,1,1,1,1,1
1,1,1,1,1,1,58,53,47,47,58,1,1,1,1,1,1
endlayer

layer
1,1,1,1,1,1,1,1,1,1,1,1,1,1,1,1,1
1,1,1,1,1,50,50,50,57,1,1,1,1,1,1,1,1
1,1,1,1,60,59,59,59,50,50,1,1,1,1,1,1,1
1,1,1,62,60,61,61,61,61,60,60,1,1,1,1,1,1
1,1,46,13,60,17,61,61,61,60,60,1,1,1,1,1,1
1,50,59,61,60,17,17,61,17,60,60,1,1,1,1,1,1
1,46,61,61,60,62,62,62,62,62,13,62,62,62,62,62,63
1,59,61,61,60,17,61,17,61,17,17,60,9,9,9,13,1
1,52,61,61,60,61,61,61,61,61,17,60,9,9,9,60,58
1,46,59,61,60,17,61,17,61,17,17,60,13,9,9,60,57
1,46,62,62,62,62,62,62,62,62,62,60,23,9,9,60,58
1,1,52,59,61,60,17,61,17,17,17,60,23,9,9,13,1
1,1,1,46,60,60,61,61,61,17,17,13,62,62,62,62,63
1,1,1,1,52,60,15,15,15,15,15,60,52,58,1,1,1
1,1,1,1,1,64,52,46,59,57,52,64,1,1,1,1,1
1,1,1,1,1,1,1,1,58,1,1,1,1,1,1,1,1
endlayer

layer
1,1,1,1,1,1,1,1,1,1,1,1,1,1,1,1,1
1,1,1,1,1,1,1,1,1,1,1,1,1,1,1,1,1
1,1,1,1,1,1,58,58,1,1,1,1,1,1,1,1,1
1,1,1,35,13,16,16,16,16,13,35,1,1,1,1,1,1
1,1,1,27,9,9,9,9,9,9,23,1,1,1,1,1,1
1,1,58,27,9,9,9,9,9,65,23,1,1,1,1,1,1
1,1,58,27,9,9,9,9,9,65,13,41,16,16,16,35,1
1,1,58,13,9,9,9,9,9,9,9,23,9,9,9,13,1
1,1,58,27,9,9,9,9,9,9,9,16,9,9,9,23,1
1,1,1,27,9,9,9,9,9,9,9,9,13,9,9,23,1
1,1,1,58,13,9,9,9,9,9,9,9,9,9,9,23,1
1,1,1,1,58,34,9,9,9,9,9,9,9,9,9,13,1
1,1,1,1,1,27,9,37,37,37,9,13,34,34,34,35,1
1,1,1,1,1,35,13,34,34,34,34,35,1,1,1,1,1
1,1,1,1,1,1,1,1,1,1,1,1,1,1,1,1,1
1,1,1,1,1,1,1,1,1,1,1,1,1,1,1,1,1
endlayer

layer
1,1,1,1,1,1,1,1,1,1,1,1,1,1,1,1,1
1,1,1,1,1,1,1,1,1,1,1,1,1,1,1,1,1
1,1,1,1,1,1,1,1,1,1,1,1,1,1,1,1,1
1,1,1,35,13,35,9,35,35,13,35,1,1,1,1,1,1
1,1,1,35,9,9,9,9,9,9,9,1,1,1,1,1,1
1,1,1,9,9,9,9,9,9,39,35,1,1,1,1,1,1
1,1,1,35,9,9,9,9,9,39,13,16,35,35,9,35,1
1,1,1,13,9,9,9,9,9,9,9,35,9,9,9,13,1
1,1,1,35,9,9,9,9,9,9,9,35,9,9,9,35,1
1,1,1,9,9,9,9,9,9,9,9,9,13,9,9,9,1
1,1,1,1,13,9,9,9,9,9,9,9,9,9,9,35,1
1,1,1,1,1,9,9,9,9,9,9,9,9,9,9,13,1
1,1,1,1,1,35,9,39,39,39,9,13,35,9,35,35,1
1,1,1,1,1,35,13,35,35,9,35,35,1,1,1,1,1
1,1,1,1,1,1,1,1,1,1,1,1,1,1,1,1,1
1,1,1,1,1,1,1,1,1,1,1,1,1,1,1,1,1
endlayer

layer
1,1,1,1,1,1,1,1,1,1,1,1,1,1,1,1,1
1,1,1,1,1,1,1,1,1,1,1,1,1,1,1,1,1
1,1,1,1,1,1,1,1,1,47,1,1,1,1,1,1,1
1,1,1,47,13,45,45,45,45,13,1,1,1,1,1,1,1
1,1,1,49,9,9,9,9,9,9,44,1,1,1,1,1,1
1,1,1,49,9,9,9,9,9,9,44,1,1,1,1,1,1
1,1,1,49,9,9,9,9,9,9,13,45,45,45,45,1,1
1,1,1,13,9,9,9,9,9,9,9,15,9,9,9,13,1
1,1,1,49,9,9,9,9,9,9,9,15,9,9,9,44,1
1,1,1,49,9,9,9,9,9,9,9,9,13,9,9,44,1
1,1,1,1,13,9,9,9,9,9,9,9,9,9,9,44,1
1,1,1,1,1,54,9,9,9,9,9,9,9,9,9,13,1
1,1,1,1,1,49,9,9,9,9,9,13,54,54,54,57,1
1,1,1,1,1,48,13,54,54,54,54,47,1,1,1,1,1
1,1,1,1,1,1,47,1,1,1,1,1,1,1,1,1,1
1,1,1,1,1,1,1,1,1,1,1,1,1,1,1,1,1
endlayer

layer
1,1,1,1,1,1,1,1,1,1,1,1,1,1,1,1,1
1,1,1,1,1,1,1,1,1,1,1,1,1,1,1,1,1
1,1,1,1,58,47,47,47,57,1,1,1,1,1,1,1,1
1,1,1,58,13,68,67,67,66,13,57,1,1,1,1,1,1
1,1,47,67,9,9,9,9,9,9,66,47,1,1,1,1,1
1,1,47,68,9,9,9,9,9,9,66,55,56,47,47,1,1
1,1,47,68,9,9,9,9,9,9,13,15,67,67,66,57,1
1,1,58,13,9,9,9,9,9,9,9,66,9,9,9,13,58
1,1,47,68,9,9,9,9,9,9,9,66,9,9,9,66,47
1,1,47,69,9,9,9,9,9,9,9,9,13,9,9,66,47
1,1,1,70,13,9,9,9,9,9,9,9,9,9,9,66,47
1,1,1,1,47,68,9,9,9,9,9,9,9,9,9,13,58
1,1,1,1,47,69,9,9,9,9,9,13,69,69,66,58,1
1,1,1,1,58,52,13,69,69,69,69,59,47,47,58,1,1
1,1,1,1,1,1,1,53,47,47,70,58,1,1,1,1,1
1,1,1,1,1,1,1,1,1,1,1,1,1,1,1,1,1
endlayer

layer
1,1,1,1,1,1,1,1,1,1,1,1,1,1,1,1,1
1,1,1,1,1,1,1,1,1,1,1,1,1,1,1,1,1
1,1,1,1,1,1,58,1,1,1,1,1,1,1,1,1,1
1,1,1,1,46,50,59,59,50,50,1,1,1,1,1,1,1
1,1,1,50,44,54,54,54,54,54,50,1,1,1,1,1,1
1,1,1,46,44,9,9,9,9,9,60,50,50,50,1,1,1
1,1,1,46,44,9,9,9,9,9,13,62,62,57,50,1,1
1,1,1,46,44,9,9,9,9,9,9,15,44,54,49,57,1
1,1,1,46,44,9,9,9,9,9,9,15,44,9,49,57,1
1,1,1,46,44,9,9,9,9,9,9,54,13,9,49,57,1
1,1,1,52,13,45,9,9,9,9,9,14,60,9,49,57,1
1,1,1,1,46,59,44,14,14,14,14,14,60,45,45,52,1
1,1,1,1,1,46,44,45,45,45,45,13,59,57,52,1,1
1,1,1,1,1,1,52,52,52,52,52,58,58,1,1,1,1
1,1,1,1,1,1,1,1,1,1,1,1,1,1,1,1,1
1,1,1,1,1,1,1,1,1,1,1,1,1,1,1,1,1
endlayer

layer
1,1,1,1,1,1,1,1,1,1,1,1,1,1,1,1,1
1,1,1,1,1,1,1,1,1,1,1,1,1,1,1,1,1
1,1,1,1,1,1,1,1,1,1,1,1,1,1,1,1,1
1,1,1,1,1,1,1,1,1,1,1,1,1,1,1,1,1
1,1,1,1,58,50,59,59,59,50,50,1,1,1,1,1,1
1,1,1,1,46,54,54,54,54,54,59,1,1,1,1,1,1
1,1,1,1,59,44,14,14,14,14,15,59,50,1,1,1,1
1,1,1,1,59,44,14,9,9,9,49,15,59,50,57,1,1
1,1,1,1,59,44,14,9,9,9,49,15,15,28,50,1,1
1,1,1,1,46,44,14,9,9,9,49,59,13,15,59,1,1
1,1,1,1,46,59,44,45,45,45,45,59,59,15,52,1,1
1,1,1,1,1,46,59,59,59,59,59,59,59,59,57,1,1
1,1,1,1,1,1,46,52,59,59,59,57,52,52,1,1,1
1,1,1,1,1,1,1,1,1,1,1,1,1,1,1,1,1
1,1,1,1,1,1,1,1,1,1,1,1,1,1,1,1,1
1,1,1,1,1,1,1,1,1,1,1,1,1,1,1,1,1
endlayer

layer
1,1,1,1,1,1,1,1,1,1,1,1,1,1,1,1,1
1,1,1,1,1,1,1,1,1,1,1,1,1,1,1,1,1
1,1,1,1,1,1,1,1,1,1,1,1,1,1,1,1,1
1,1,1,1,1,1,1,1,1,1,1,1,1,1,1,1,1
1,1,1,1,1,1,1,1,1,1,1,1,1,1,1,1,1
1,1,1,1,1,58,50,50,50,50,58,1,1,1,1,1,1
1,1,1,1,1,50,46,59,59,59,59,50,1,1,1,1,1
1,1,1,1,1,46,59,54,54,49,59,59,58,1,1,1,1
1,1,1,1,1,46,59,44,72,49,59,59,57,71,1,1,1
1,1,1,1,1,46,59,45,45,49,59,59,59,57,1,1,1
1,1,1,1,1,52,59,59,59,59,59,59,59,58,1,1,1
1,1,1,1,1,1,46,52,46,59,59,59,58,1,1,1,1
1,1,1,1,1,1,1,1,1,1,1,1,1,1,1,1,1
1,1,1,1,1,1,1,1,1,1,1,1,1,1,1,1,1
1,1,1,1,1,1,1,1,1,1,1,1,1,1,1,1,1
1,1,1,1,1,1,1,1,1,1,1,1,1,1,1,1,1
endlayer

layer
1,1,1,1,1,1,1,1,1,1,1,1,1,1,1,1,1
1,1,1,1,1,1,1,1,1,1,1,1,1,1,1,1,1
1,1,1,1,1,1,1,1,1,1,1,1,1,1,1,1,1
1,1,1,1,1,1,1,1,1,1,1,1,1,1,1,1,1
1,1,1,1,1,1,1,1,1,1,1,1,1,1,1,1,1
1,1,1,1,1,1,1,1,1,1,1,1,1,1,1,1,1
1,1,1,1,1,1,1,71,71,71,71,1,1,1,1,1,1
1,1,1,1,1,1,71,58,58,58,71,71,1,1,1,1,1
1,1,1,1,1,1,71,58,1,58,58,58,71,39,1,1,1
1,1,1,1,1,1,71,58,58,58,58,58,71,1,1,1,1
1,1,1,1,1,1,71,71,71,58,58,58,71,1,1,1,1
1,1,1,1,1,1,1,1,1,71,71,71,1,1,1,1,1
1,1,1,1,1,1,1,1,1,1,1,1,1,1,1,1,1
1,1,1,1,1,1,1,1,1,1,1,1,1,1,1,1,1
1,1,1,1,1,1,1,1,1,1,1,1,1,1,1,1,1
1,1,1,1,1,1,1,1,1,1,1,1,1,1,1,1,1
endlayer

