
# Created by Ruins mod version 16.7 Ingame Parser
# authoring Player: lafuller

weight=1
embed_into_distance=4
acceptable_target_blocks=
unacceptable_target_blocks=flowing_water,water,flowing_lava,lava,ice,bedrock,netherrack,nether_brick,nether_brick_fence,soul_sand,quartz_ore,end_stone,obsidian,iron_bars,cloud,flesh,ash_block,slime_grass,slime_congealed,slime_dirt
biomesToSpawnIn=plains,forest,prarie,meadow,tundra,brushland,shrubland,woodland,woodlands,birch_forestlavender_fields,flower_field,sunflower_plains,ice_flats,ice_plains
dimensions=15,14,13
allowable_overhang=0
max_leveling=4
leveling_buffer=-1
preserve_water=0
preserve_lava=0

rule1=0,100,preserveBlock
rule2=0,100,minecraft:stone-6
rule3=0,100,stonebrick-0,stonebrick-0,stonebrick-0,stonebrick-0,stonebrick-1,stonebrick-2,stonebrick-2,stone-5,stone-6,cobblestone
rule4=0,100,stonebrick-0,stonebrick-2,stonebrick-1,stonebrick-1,stonebrick-1,cobblestone
rule5=0,100,stonebrick-0,stonebrick-1,stonebrick-2,stonebrick-2,stone-5,stone-5,stone-6,stone-6
rule6=0,100,stonebrick-0,stonebrick-2,stonebrick-0,stonebrick-1,stonebrick-1,cobblestone
rule7=0,100,minecraft:stone_brick_stairs-1
rule8=0,100,minecraft:stone_brick_stairs-2
rule9=0,100,minecraft:stone_brick_stairs-3
rule10=0,100,air
rule11=0,100,minecraft:stone-5
rule12=0,100,stonebrick-0,stonebrick-0,stonebrick-0,stonebrick-0,stonebrick-1,stonebrick-2,stonebrick-2,stone-5,stone-6,cobblestone,gravel
rule13=0,100,minecraft:cobblestone_wall-0
rule14=0,100,minecraft:planks-0
rule15=0,100,bookshelf,hay_block,ChestGenHook:chests/spawn_bonus_chest:5-5,ChestGenHook:chests/village_blacksmith:5-5,ChestGenHook:chests/simple_dungeon:5-5,ChestGenHook:chests/abandoned_mineshaft:5-5,ChestGenHook:chests/stronghold_library:5-5,ChestGenHook:chests/stronghold_corridor:5-5,ChestGenHook:chests/stronghold_crossing:5-5,ChestGenHook:chests/igloo_chest:5-5
rule16=0,100,minecraft:log-0
rule17=0,100,minecraft:web-0,air,air,air
rule18=0,100,minecraft:stone_brick_stairs-0
rule19=0,100,minecraft:oak_stairs-3
rule20=0,100,minecraft:wooden_slab-9
rule21=0,100,minecraft:oak_stairs-2
rule22=0,100,minecraft:oak_stairs-7
rule23=0,100,minecraft:stone_brick_stairs-4
rule24=0,100,minecraft:stone_brick_stairs-7
rule25=0,100,minecraft:planks-1
rule26=0,100,minecraft:oak_stairs-0
rule27=0,100,minecraft:stone_brick_stairs-5
rule28=0,100,minecraft:spruce_fence_gate-2
rule29=0,100,minecraft:trapdoor-8
rule30=0,100,minecraft:oak_stairs-1
rule31=0,100,minecraft:jungle_door-1
rule32=0,100,minecraft:spruce_fence_gate-7
rule33=0,100,minecraft:spruce_fence-0
rule34=0,100,minecraft:fence-0
rule35=0,100,minecraft:furnace-2
rule36=0,100,minecraft:jungle_door-8
rule37=0,100,minecraft:carpet-7
rule38=0,100,minecraft:dark_oak_stairs-6
rule39=0,100,minecraft:spruce_stairs-4
rule40=0,100,minecraft:dark_oak_stairs-0
rule41=0,100,minecraft:wooden_slab-13
rule42=0,100,minecraft:spruce_stairs-6
rule43=0,100,minecraft:ladder-5
rule44=0,100,minecraft:ladder-2
rule45=0,100,minecraft:spruce_stairs-7
rule46=0,100,minecraft:dark_oak_stairs-2
rule47=0,100,minecraft:spruce_stairs-5
rule48=0,100,minecraft:spruce_fence_gate-0
rule49=0,100,minecraft:oak_stairs-6
rule50=0,100,minecraft:dark_oak_stairs-1
rule51=0,100,minecraft:dark_oak_stairs-7
rule52=0,100,minecraft:wooden_slab-5
rule53=0,100,minecraft:planks-5
rule54=0,100,minecraft:stone_brick_stairs-6
rule55=0,100,minecraft:dark_oak_stairs-3
rule56=0,100,minecraft:dark_oak_stairs-5
rule57=0,100,minecraft:dark_oak_fence-0
rule58=0,100,minecraft:stone_slab-0

layer
1,1,1,1,1,1,1,1,1,1,1,1,1
1,1,1,1,1,2,3,3,3,3,2,1,1
1,3,3,3,3,2,4,4,4,4,4,3,1
1,3,2,4,4,4,5,5,5,2,4,3,1
1,3,4,5,5,5,6,6,5,5,4,3,3
1,3,4,5,6,6,6,5,4,4,4,2,3
1,3,4,5,5,6,5,4,3,3,3,3,3
1,2,2,4,6,6,5,4,3,3,3,3,3
1,1,3,4,5,6,5,4,3,3,3,3,3
1,1,3,4,5,6,5,4,3,3,3,3,3
1,1,3,4,5,5,4,2,3,3,3,3,3
1,1,2,2,4,4,4,2,3,3,3,3,7
1,1,1,3,3,3,3,3,3,3,3,8,1
10,1,1,1,1,1,1,9,7,7,7,1,1
endlayer

layer
1,1,1,1,1,1,1,1,1,1,1,1,1
1,1,1,1,1,11,12,13,12,12,11,1,1
1,12,12,13,12,16,15,10,10,14,14,12,1
1,12,16,17,10,10,10,10,10,16,14,12,1
1,12,20,10,10,10,10,10,10,19,14,13,18
1,13,20,10,10,10,10,10,10,19,14,11,12
1,12,20,10,10,10,10,10,10,12,12,12,12
1,11,16,10,10,10,10,10,10,12,12,12,12
1,1,12,10,10,10,10,10,10,12,12,12,12
1,1,13,10,10,10,10,10,17,12,12,12,12
1,1,12,17,10,10,10,16,12,12,12,12,7
1,1,11,16,20,20,20,11,12,12,12,12,1
1,1,1,12,12,13,12,7,7,7,8,1,1
1,1,1,1,1,1,1,1,1,1,1,1,1
endlayer

layer
1,1,1,1,1,1,1,1,1,1,1,1,1
1,1,1,1,1,2,12,13,12,12,2,1,1
1,12,12,13,12,16,17,10,22,21,10,12,1
1,12,16,17,17,10,10,10,10,16,10,12,1
1,12,17,10,10,10,10,10,10,10,10,13,1
1,13,10,10,10,10,10,10,10,10,10,2,18
1,12,17,10,10,10,10,10,10,12,12,12,8
1,2,16,10,10,10,10,10,10,12,12,12,8
1,1,12,10,10,10,10,10,17,12,12,12,7
1,1,13,17,10,10,10,17,17,12,1,1,1
1,1,12,17,10,10,10,16,12,12,1,1,1
1,1,2,16,17,10,17,2,7,7,1,1,1
1,1,1,12,12,13,12,1,1,1,1,1,1
1,1,1,1,1,1,1,1,1,1,1,1,1
endlayer

layer
1,1,1,1,1,1,1,1,1,1,1,1,1
1,1,1,1,1,11,12,13,12,12,11,1,1
1,12,12,13,12,16,17,22,21,10,10,12,1
1,12,16,17,17,17,10,10,10,16,10,12,1
1,12,17,17,17,10,10,10,10,10,10,13,1
1,13,17,10,10,10,10,10,10,10,10,11,1
1,12,17,17,10,10,10,10,23,12,12,8,1
1,11,16,17,10,10,10,10,24,12,12,8,1
1,1,12,17,10,10,10,17,24,12,12,8,1
1,1,13,17,17,10,17,17,24,12,1,1,1
1,1,12,17,17,10,17,16,12,7,1,1,1
1,1,11,16,17,17,17,11,1,1,1,1,1
1,1,1,12,12,13,12,1,1,1,1,1,1
1,1,1,1,1,1,1,1,1,1,1,1,1
endlayer

layer
1,1,1,1,1,1,1,1,1,1,1,1,1
1,1,1,1,1,2,12,12,12,12,2,1,1
1,12,12,12,12,14,14,21,10,10,10,12,1
1,12,14,14,14,25,25,25,25,16,10,12,1
1,12,14,25,25,25,14,25,25,25,10,12,1
1,12,14,25,14,14,25,14,14,25,10,2,1
1,12,14,14,25,14,25,25,3,12,12,1,1
1,2,14,25,14,14,14,25,3,12,8,1,1
1,1,12,25,14,14,14,25,3,12,8,1,1
1,1,12,25,14,25,25,14,2,7,1,1,1
1,1,12,25,25,25,14,14,12,1,1,1,1
1,1,2,14,14,14,14,2,1,1,1,1,1
1,1,1,12,12,12,12,1,1,1,1,1,1
1,1,1,1,1,1,1,1,1,1,1,1,1
endlayer

layer
1,1,1,1,1,1,1,1,1,1,1,1,1
1,1,1,1,1,10,26,26,26,26,16,10,1
1,23,12,26,26,16,10,10,10,10,10,21,1
1,12,27,2,2,10,10,10,10,16,10,21,1
1,19,29,10,10,10,10,10,10,28,10,21,1
1,19,29,10,10,10,10,10,10,28,10,16,1
1,19,2,10,10,10,10,10,16,21,30,10,1
1,16,2,10,10,10,10,10,14,10,10,1,1
1,1,30,10,10,10,10,10,31,10,10,1,1
1,1,19,10,10,10,10,10,16,10,1,1,1
1,1,19,10,10,10,10,10,21,1,1,1,1
1,1,16,10,10,32,32,16,10,1,1,1,1
1,1,34,30,30,30,30,33,1,1,1,1,1
1,1,1,1,1,1,1,1,1,1,1,1,1
endlayer

layer
1,1,1,1,1,1,1,1,1,1,1,1,1
1,1,1,1,1,34,10,34,10,34,16,34,1
1,9,12,10,34,16,10,10,10,10,10,10,1
1,12,35,10,10,10,10,10,10,16,10,34,1
1,34,10,10,10,10,10,10,10,10,10,34,1
1,10,10,10,10,10,10,10,10,10,10,16,1
1,34,10,10,10,10,10,10,16,34,34,34,1
1,16,10,10,10,10,10,10,14,10,10,1,1
1,1,34,10,10,10,10,10,36,10,10,1,1
1,1,10,10,10,10,10,10,16,10,10,1,1
1,1,34,10,10,10,10,10,34,1,1,1,1
1,1,16,10,10,37,37,16,10,1,1,1,1
1,1,34,10,34,34,10,34,1,1,1,1,1
1,1,1,1,1,1,1,1,1,1,1,1,1
endlayer

layer
1,1,1,1,1,1,1,1,1,1,1,1,1
1,1,41,41,41,40,39,39,39,39,16,38,1
1,12,12,39,39,16,10,10,10,10,10,42,1
1,12,7,43,43,10,10,10,10,16,10,42,1
1,45,44,10,10,10,10,10,10,10,10,42,1
1,45,10,10,10,10,10,10,10,10,10,16,1
1,45,44,10,10,10,10,10,16,42,47,46,1
1,16,10,10,10,10,10,10,25,10,10,1,1
1,1,49,10,10,10,10,10,48,10,10,1,1
1,1,22,10,10,10,10,10,16,10,10,1,1
1,1,22,10,10,10,10,10,42,1,1,1,1
1,41,16,10,10,10,10,16,50,1,1,1,1
1,50,38,47,47,47,47,46,1,1,1,1,1
1,1,1,1,1,1,1,1,1,1,1,1,1
endlayer

layer
1,1,1,1,1,1,52,41,41,51,40,1,1
1,1,1,40,53,40,53,53,53,53,16,40,52
1,9,12,53,53,16,47,47,47,25,25,53,41
52,12,54,10,10,10,10,10,10,16,25,53,41
51,53,10,10,10,10,10,10,10,45,25,53,41
41,53,10,10,10,10,10,10,45,39,25,16,52
51,53,10,10,10,10,10,39,16,53,53,50,1
52,16,39,10,10,10,10,45,53,53,41,1,1
1,53,25,10,10,10,10,45,53,41,10,1,1
1,53,25,10,10,10,10,45,16,41,10,1,1
1,50,25,10,10,10,10,45,53,52,1,1,1
1,55,16,39,39,39,39,16,46,1,1,1,1
1,1,50,53,53,53,53,56,41,1,1,1,1
1,1,1,52,41,41,52,1,1,1,1,1,1
endlayer

layer
1,1,1,1,1,1,1,1,1,1,1,1,1
1,1,1,1,1,1,1,40,53,53,40,1,1
1,1,18,40,40,53,53,53,53,53,53,46,1
1,12,12,47,47,47,47,45,25,53,53,53,52
1,55,42,10,10,10,10,45,57,53,53,53,1
52,55,42,10,10,10,10,45,53,53,53,46,1
1,55,39,10,10,10,10,25,53,53,50,1,1
1,55,25,10,10,10,10,25,53,46,1,1,1
1,55,25,10,10,10,10,25,53,52,1,1,1
1,55,25,10,10,10,10,25,46,1,1,1,1
1,55,42,10,10,10,10,45,46,1,1,1,1
1,50,16,39,25,25,39,16,50,1,1,1,1
1,1,55,50,50,50,50,46,1,1,1,1,1
1,1,1,1,1,1,1,1,1,1,1,1,1
endlayer

layer
1,1,1,1,1,1,1,1,1,1,1,1,1
1,1,1,1,1,1,1,1,1,1,1,1,1
1,1,1,1,1,1,55,53,53,53,40,1,1
1,9,12,40,53,53,53,53,53,53,53,1,1
1,1,55,42,47,47,47,53,57,53,53,52,1
1,1,55,42,10,10,45,53,53,53,46,1,1
1,1,55,47,10,10,47,53,53,46,1,1,1
1,1,55,42,10,10,45,53,46,1,1,1,1
1,1,55,39,10,10,39,53,52,1,1,1,1
1,1,55,42,10,10,45,53,1,1,1,1,1
1,1,50,39,39,39,39,46,1,1,1,1,1
1,1,50,50,50,50,50,52,1,1,1,1,1
1,1,1,1,1,1,1,1,1,1,1,1,1
1,1,1,1,1,1,1,1,1,1,1,1,1
endlayer

layer
1,1,1,1,1,1,1,1,1,1,1,1,1
1,1,1,1,1,1,1,1,1,1,1,1,1
1,1,1,1,1,1,1,57,57,57,1,1,1
1,1,12,1,57,57,57,52,52,52,57,1,1
1,1,1,55,53,53,53,52,1,52,57,1,1
1,1,1,53,47,47,53,53,52,57,1,1,1
1,1,1,53,25,25,53,53,57,1,1,1,1
1,1,1,53,42,45,53,53,1,1,1,1,1
1,1,1,53,25,25,53,53,1,1,1,1,1
1,1,1,53,39,39,53,1,1,1,1,1,1
1,1,1,50,53,53,46,1,1,1,1,1,1
1,1,1,1,1,1,1,1,1,1,1,1,1
1,1,1,1,1,1,1,1,1,1,1,1,1
1,1,1,1,1,1,1,1,1,1,1,1,1
endlayer

layer
1,1,1,1,1,1,1,1,1,1,1,1,1
1,1,1,1,1,1,1,1,1,1,1,1,1
1,1,1,1,1,1,1,1,1,1,1,1,1
1,1,12,1,1,1,1,1,1,1,1,1,1
1,1,1,1,57,57,57,1,1,1,1,1,1
1,1,1,57,52,52,52,57,1,1,1,1,1
1,1,1,57,52,52,52,57,1,1,1,1,1
1,1,1,57,52,52,52,57,1,1,1,1,1
1,1,1,57,52,52,52,57,1,1,1,1,1
1,1,1,57,52,52,57,1,1,1,1,1,1
1,1,1,1,57,57,1,1,1,1,1,1,1
1,1,1,1,1,1,1,1,1,1,1,1,1
1,1,1,1,1,1,1,1,1,1,1,1,1
1,1,1,1,1,1,1,1,1,1,1,1,1
endlayer

layer
1,1,1,1,1,1,1,1,1,1,1,1,1
1,1,1,1,1,1,1,1,1,1,1,1,1
1,1,1,1,1,1,1,1,1,1,1,1,1
1,1,13,1,1,1,1,1,1,1,1,1,1
1,1,1,1,1,1,1,1,1,1,1,1,1
1,1,1,1,1,1,1,1,1,1,1,1,1
1,1,1,1,1,1,1,1,1,1,1,1,1
1,1,1,1,1,1,1,1,1,1,1,1,1
1,1,1,1,1,1,1,1,1,1,1,1,1
1,1,1,1,1,1,1,1,1,1,1,1,1
1,1,1,1,1,1,1,1,1,1,1,1,1
1,1,1,1,1,1,1,1,1,1,1,1,1
1,1,1,1,1,1,1,1,1,1,1,1,1
1,1,1,1,1,1,1,1,1,1,1,1,1
endlayer

layer
1,1,1,1,1,1,1,1,1,1,1,1,1
1,1,1,1,1,1,1,1,1,1,1,1,1
1,1,1,1,1,1,1,1,1,1,1,1,1
1,1,58,1,1,1,1,1,1,1,1,1,1
1,1,1,1,1,1,1,1,1,1,1,1,1
1,1,1,1,1,1,1,1,1,1,1,1,1
1,1,1,1,1,1,1,1,1,1,1,1,1
1,1,1,1,1,1,1,1,1,1,1,1,1
1,1,1,1,1,1,1,1,1,1,1,1,1
1,1,1,1,1,1,1,1,1,1,1,1,1
1,1,1,1,1,1,1,1,1,1,1,1,1
1,1,1,1,1,1,1,1,1,1,1,1,1
1,1,1,1,1,1,1,1,1,1,1,1,1
1,1,1,1,1,1,1,1,1,1,1,1,1
endlayer

