
# Created by Ruins mod version 16.7 Ingame Parser
# authoring Player: lafuller

weight=1
embed_into_distance=4
acceptable_target_blocks=
unacceptable_target_blocks=flowing_water,water,flowing_lava,lava,ice,bedrock,netherrack,nether_brick,nether_brick_fence,soul_sand,quartz_ore,gravel,end_stone,obsidian,iron_bars,cloud,flesh,ash_block,slime_grass,slime_congealed,slime_dirt
dimensions=15,13,11
allowable_overhang=0
max_leveling=4
leveling_buffer=-1
preserve_water=0
preserve_lava=0

rule1=0,100,air
rule2=0,100,preserveBlock
rule3=0,100,stonebrick-0,stonebrick-1,stonebrick-1,stonebrick-1,stonebrick-2,stonebrick-2,stone-5,stone-5,stone-6,cobblestone,cobblestone
rule4=0,100,minecraft:stone-6
rule5=0,100,stonebrick-0,stonebrick-2,stonebrick-1,stonebrick-1,stonebrick-1,cobblestone
rule6=0,100,stonebrick-0,stonebrick-1,stonebrick-2,stonebrick-2,stone-5,stone-5,stone-6,stone-6
rule7=0,100,minecraft:stone_brick_stairs-0
rule8=0,100,stonebrick-0,stonebrick-2,stonebrick-0,stonebrick-1,stonebrick-1,cobblestone
rule9=0,100,minecraft:stone_brick_stairs-3
rule10=0,100,stonebrick-0,stonebrick-1,stonebrick-1,stonebrick-1,stonebrick-2,stonebrick-2,stone-5,stone-5,stone-6,cobblestone,cobblestone,gravel
rule11=0,100,minecraft:cobblestone_wall-0
rule12=0,100,minecraft:stone-5
rule13=0,100,bookshelf,hay_block,ChestGenHook:chests/spawn_bonus_chest:5-5,ChestGenHook:chests/village_blacksmith:4-5,ChestGenHook:chests/simple_dungeon:5-5,ChestGenHook:chests/abandoned_mineshaft:4-5,ChestGenHook:chests/stronghold_library:3-5,ChestGenHook:chests/stronghold_corridor:2-5,ChestGenHook:chests/stronghold_crossing:2-5,ChestGenHook:chests/igloo_chest:4-5
rule14=0,100,minecraft:planks-1
rule15=0,100,minecraft:spruce_stairs-1
rule16=0,100,minecraft:web-0,air,air,air
rule17=0,100,minecraft:log-0
rule18=0,100,minecraft:wooden_slab-9
rule19=0,100,minecraft:stone_brick_stairs-5
rule20=0,100,minecraft:spruce_stairs-5
rule21=0,100,minecraft:spruce_stairs-3
rule22=0,100,minecraft:stone_brick_stairs-6
rule23=0,100,minecraft:stone_brick_stairs-1
rule24=0,100,minecraft:wooden_slab-1
rule25=0,100,minecraft:planks-0
rule26=0,100,minecraft:oak_stairs-4
rule27=0,100,minecraft:spruce_stairs-4
rule28=0,100,minecraft:oak_stairs-0
rule29=0,100,minecraft:log2-1
rule30=0,100,minecraft:oak_stairs-2
rule31=0,100,minecraft:spruce_fence_gate-1
rule32=0,100,minecraft:spruce_fence-0
rule33=0,100,minecraft:stone_brick_stairs-4
rule34=0,100,minecraft:oak_stairs-3
rule35=0,100,minecraft:jungle_door-1
rule36=0,100,minecraft:oak_stairs-1
rule37=0,100,minecraft:fence-0
rule38=0,100,minecraft:stone_brick_stairs-7
rule39=0,100,minecraft:furnace-5
rule40=0,100,minecraft:jungle_door-8
rule41=0,100,minecraft:wooden_slab-13
rule42=0,100,minecraft:spruce_stairs-6
rule43=0,100,minecraft:spruce_stairs-7
rule44=0,100,minecraft:spruce_fence_gate-0
rule45=0,100,minecraft:dark_oak_stairs-2
rule46=0,100,minecraft:dark_oak_stairs-3
rule47=0,100,minecraft:planks-5
rule48=0,100,minecraft:dark_oak_stairs-0
rule49=0,100,minecraft:dark_oak_stairs-5
rule50=0,100,minecraft:dark_oak_stairs-1
rule51=0,100,minecraft:dark_oak_stairs-4
rule52=0,100,minecraft:wooden_slab-5
rule53=0,100,minecraft:dark_oak_fence-0
rule54=0,100,minecraft:stone_brick_stairs-2
rule55=0,100,minecraft:trapdoor-2
rule56=0,100,minecraft:stone_slab-0

layer
2,2,2,2,2,2,2,2,2,2,2
2,2,2,2,4,3,3,2,2,2,2
2,2,2,3,5,5,5,4,2,2,2
2,2,4,5,6,6,6,5,3,2,2
2,3,3,5,6,8,6,5,3,7,7
2,3,3,5,6,8,8,6,5,4,3
2,4,5,6,8,8,8,6,5,3,4
2,3,5,6,8,8,6,6,5,3,2
2,3,5,6,6,8,6,5,4,3,4
2,2,4,5,5,6,6,5,3,3,2
2,2,2,3,4,5,5,5,3,3,4
2,2,2,2,2,3,3,4,3,3,2
2,2,2,2,2,9,4,2,4,2,4
endlayer

layer
2,2,2,2,2,2,2,2,2,2,2
2,2,2,2,12,11,10,2,2,2,2
2,2,2,10,15,14,13,12,2,2,2
2,2,12,1,1,17,1,16,10,2,2
2,3,11,1,1,1,1,1,10,2,2
2,3,10,1,1,1,1,1,17,12,7
2,12,18,1,1,1,1,1,18,11,10
2,11,18,1,1,1,1,1,18,10,2
2,10,18,1,1,1,1,1,12,10,10
2,2,12,17,16,1,1,16,10,10,2
2,2,2,10,12,18,18,17,10,10,10
2,2,2,2,2,10,11,12,10,10,2
2,2,2,2,2,2,9,19,10,19,10
endlayer

layer
2,2,2,2,2,2,2,2,2,2,2
2,2,2,2,4,11,10,2,2,2,2
2,2,2,10,1,21,20,4,2,2,2
2,2,4,1,1,17,1,16,10,2,2
2,3,11,1,1,1,1,16,10,2,2
2,3,10,1,1,1,1,1,17,4,2
2,4,16,1,1,1,1,1,16,11,7
2,11,1,1,1,1,1,1,16,10,22
2,10,16,16,1,1,1,1,4,10,10
2,2,4,17,16,1,1,16,10,10,2
2,2,2,10,4,16,16,17,10,10,10
2,2,2,2,2,10,11,4,10,10,22
2,2,2,2,2,2,2,9,10,10,10
endlayer

layer
2,2,2,2,2,2,2,2,2,2,2
2,2,2,2,12,11,10,2,2,2,2
2,2,2,10,1,1,21,12,2,2,2
2,2,12,1,1,17,16,16,10,2,2
2,3,11,1,1,1,16,16,10,2,2
2,3,10,1,1,1,1,16,17,12,2
2,12,16,1,1,1,1,1,16,11,2
2,11,16,16,1,1,1,16,16,10,7
2,10,16,16,16,1,1,16,12,10,10
2,2,12,17,16,16,16,16,10,10,22
2,2,2,10,12,16,16,17,10,10,10
2,2,2,2,2,10,11,12,23,23,23
2,2,2,2,2,2,2,2,2,2,2
endlayer

layer
2,2,2,2,2,2,2,2,2,2,2
2,2,2,2,4,10,10,2,2,2,2
2,2,2,10,1,1,1,4,2,2,2
2,2,4,18,18,17,24,14,10,2,2
2,3,10,27,26,25,25,14,10,2,2
2,3,10,14,25,14,14,25,14,4,2
2,4,14,25,14,14,14,25,14,10,2
2,10,14,25,14,14,25,25,14,10,2
2,10,14,25,25,14,25,14,4,3,7
2,2,4,14,14,25,25,14,3,3,3
2,2,2,10,4,14,14,14,10,23,23
2,2,2,2,2,10,10,4,2,2,2
2,2,2,2,2,2,2,2,2,2,2
endlayer

layer
2,2,2,2,2,2,2,2,2,2,2
2,2,2,1,29,28,28,1,2,2,2
2,2,1,25,1,1,1,29,1,2,2
2,2,29,32,31,17,1,1,30,2,2
2,33,10,1,1,1,1,1,28,2,2
2,10,19,1,1,1,1,1,1,29,2
2,29,1,1,1,1,1,1,1,30,2
2,34,1,1,1,1,1,1,1,30,2
2,34,1,1,1,1,1,1,29,1,2
2,1,29,1,1,1,1,1,35,1,2
2,2,1,36,29,1,1,1,25,1,2
2,2,2,2,1,36,36,29,1,2,2
2,2,2,2,2,2,2,2,2,2,2
endlayer

layer
2,2,2,2,2,2,2,2,2,2,2
2,2,2,1,29,1,37,37,2,2,2
2,2,1,25,1,1,1,29,37,2,2
2,2,29,1,1,17,1,1,37,2,2
2,38,22,1,1,1,1,1,1,2,2
2,10,39,1,1,1,1,1,1,29,2
2,29,1,1,1,1,1,1,1,2,2
2,1,1,1,1,1,1,1,1,37,2
2,37,1,1,1,1,1,1,29,1,2
2,37,29,1,1,1,1,1,40,1,2
2,2,1,37,29,1,1,1,25,1,2
2,2,2,2,37,37,1,29,1,2,2
2,2,2,2,2,2,2,2,2,2,2
endlayer

layer
2,2,2,2,2,2,2,2,2,2,2
2,2,2,41,29,27,27,42,41,2,2
2,2,41,14,1,1,1,29,27,2,2
2,2,29,1,1,17,1,1,42,2,2
2,9,10,1,1,1,1,1,27,2,2
2,10,23,1,1,1,1,1,1,29,2
2,29,1,1,1,1,1,1,1,42,2
2,43,1,1,1,1,1,1,1,42,2
2,43,1,1,1,1,1,1,29,20,2
2,20,29,1,1,1,1,1,44,1,2
2,41,43,20,29,1,1,1,14,1,2
2,2,2,2,43,20,20,29,41,2,2
2,2,2,2,2,2,2,2,2,2,2
endlayer

layer
2,2,2,2,46,41,41,45,2,2,2
2,2,2,46,29,47,47,45,2,2,2
2,2,48,47,20,20,20,29,48,48,2
2,46,29,42,1,17,1,43,47,41,2
2,49,10,42,1,1,1,20,47,41,2
2,41,10,18,1,1,1,1,43,29,48
48,29,42,1,1,1,1,1,43,47,41
41,47,42,1,1,1,1,1,43,47,41
41,47,42,1,1,1,1,27,29,47,50
50,46,29,27,42,1,1,43,47,41,2
2,2,50,47,29,27,27,27,47,51,2
2,2,46,41,47,47,47,29,45,52,2
2,2,2,2,52,41,41,52,2,2,2
endlayer

layer
2,2,2,2,2,2,2,2,2,2,2
2,2,2,2,52,52,52,2,2,2,2
2,2,2,2,47,47,48,52,2,2,2
2,2,52,47,20,17,20,45,52,2,2
2,2,10,47,42,18,43,47,52,52,2
2,52,10,47,42,18,18,43,47,52,2
2,52,46,42,18,18,18,43,47,47,2
2,52,47,42,18,1,18,43,47,47,2
2,52,47,42,27,18,43,47,47,52,2
2,2,52,50,47,27,27,50,52,2,2
2,2,2,52,50,47,47,45,52,2,2
2,2,2,2,2,52,52,52,2,2,2
2,2,2,2,2,2,2,2,2,2,2
endlayer

layer
2,2,2,2,2,2,2,2,2,2,2
2,2,2,2,2,2,2,2,2,2,2
2,2,2,2,53,53,2,2,2,2,2
2,2,2,53,47,47,52,2,2,2,2
2,2,54,53,47,47,47,53,2,2,2
2,2,10,53,47,47,47,45,2,2,2
2,2,2,47,47,47,47,47,45,2,2
2,2,53,47,47,53,47,47,45,2,2
2,2,53,47,47,47,47,45,2,2,2
2,2,2,53,47,47,47,53,2,2,2
2,2,2,2,2,53,53,2,2,2,2
2,2,2,2,2,2,2,2,2,2,2
2,2,2,2,2,2,2,2,2,2,2
endlayer

layer
2,2,2,2,2,2,2,2,2,2,2
2,2,2,2,2,2,2,2,2,2,2
2,2,2,2,2,2,2,2,2,2,2
2,2,2,2,53,53,2,2,2,2,2
2,2,10,2,53,52,53,2,2,2,2
2,2,38,2,53,50,53,2,2,2,2
2,2,2,53,53,50,53,53,2,2,2
2,2,2,53,52,55,52,53,2,2,2
2,2,2,53,53,50,53,2,2,2,2
2,2,2,2,53,53,53,2,2,2,2
2,2,2,2,2,2,2,2,2,2,2
2,2,2,2,2,2,2,2,2,2,2
2,2,2,2,2,2,2,2,2,2,2
endlayer

layer
2,2,2,2,2,2,2,2,2,2,2
2,2,2,2,2,2,2,2,2,2,2
2,2,2,2,2,2,2,2,2,2,2
2,2,2,2,2,2,2,2,2,2,2
2,2,38,2,2,2,2,2,2,2,2
2,2,10,2,2,2,2,2,2,2,2
2,2,2,2,2,2,2,2,2,2,2
2,2,2,2,2,2,2,2,2,2,2
2,2,2,2,2,2,2,2,2,2,2
2,2,2,2,2,2,2,2,2,2,2
2,2,2,2,2,2,2,2,2,2,2
2,2,2,2,2,2,2,2,2,2,2
2,2,2,2,2,2,2,2,2,2,2
endlayer

layer
2,2,2,2,2,2,2,2,2,2,2
2,2,2,2,2,2,2,2,2,2,2
2,2,2,2,2,2,2,2,2,2,2
2,2,2,2,2,2,2,2,2,2,2
2,2,11,2,2,2,2,2,2,2,2
2,2,11,2,2,2,2,2,2,2,2
2,2,2,2,2,2,2,2,2,2,2
2,2,2,2,2,2,2,2,2,2,2
2,2,2,2,2,2,2,2,2,2,2
2,2,2,2,2,2,2,2,2,2,2
2,2,2,2,2,2,2,2,2,2,2
2,2,2,2,2,2,2,2,2,2,2
2,2,2,2,2,2,2,2,2,2,2
endlayer

layer
2,2,2,2,2,2,2,2,2,2,2
2,2,2,2,2,2,2,2,2,2,2
2,2,2,2,2,2,2,2,2,2,2
2,2,2,2,2,2,2,2,2,2,2
2,2,56,2,2,2,2,2,2,2,2
2,2,56,2,2,2,2,2,2,2,2
2,2,2,2,2,2,2,2,2,2,2
2,2,2,2,2,2,2,2,2,2,2
2,2,2,2,2,2,2,2,2,2,2
2,2,2,2,2,2,2,2,2,2,2
2,2,2,2,2,2,2,2,2,2,2
2,2,2,2,2,2,2,2,2,2,2
2,2,2,2,2,2,2,2,2,2,2
endlayer

