
# Created by Ruins mod version 16.7 Ingame Parser
# authoring Player: lafuller

weight=1
embed_into_distance=4
acceptable_target_blocks=
unacceptable_target_blocks=flowing_water,water,flowing_lava,lava,ice,bedrock,netherrack,nether_brick,nether_brick_fence,soul_sand,quartz_ore,end_stone,obsidian,iron_bars,cloud,flesh,ash_block,slime_grass,slime_congealed,slime_dirt
biomesToSpawnIn=plains,forest,prarie,meadow,tundra,brushland,shrubland,woodland,woodlands,birch_forestlavender_fields,flower_field,sunflower_plains,ice_flats,ice_plains
dimensions=13,8,9
allowable_overhang=0
max_leveling=4
leveling_buffer=-1
preserve_water=0
preserve_lava=0

rule1=0,100,preserveBlock
rule2=0,100,stonebrick-0,stonebrick-0,stonebrick-0,stonebrick-0,stonebrick-1,stonebrick-2,stonebrick-2,stone-5,stone-6,cobblestone
rule3=0,100,minecraft:stone-6
rule4=0,100,minecraft:dirt-0
rule5=0,100,minecraft:stone_brick_stairs-0
rule6=0,100,air
rule7=0,100,minecraft:stone_brick_stairs-3
rule8=0,100,stonebrick-0,stonebrick-0,stonebrick-0,stonebrick-0,stonebrick-1,stonebrick-2,stonebrick-2,stone-5,stone-6,cobblestone,gravel
rule9=0,100,minecraft:stone-5
rule10=0,100,minecraft:stone_brick_stairs-2
rule11=0,100,minecraft:stone_brick_stairs-7
rule12=0,100,minecraft:stone_brick_stairs-6
rule13=0,100,minecraft:planks-0
rule14=0,100,minecraft:planks-1
rule15=0,100,minecraft:log-0
rule16=0,100,minecraft:oak_stairs-0
rule17=0,100,minecraft:fence-0
rule18=0,100,minecraft:cauldron-0
rule19=0,100,bookshelf,hay_block,ChestGenHook:chests/spawn_bonus_chest:5-5,ChestGenHook:chests/village_blacksmith:5-5,ChestGenHook:chests/simple_dungeon:5-5,ChestGenHook:chests/abandoned_mineshaft:5-5,ChestGenHook:chests/stronghold_library:5-5,ChestGenHook:chests/stronghold_corridor:5-5,ChestGenHook:chests/stronghold_crossing:5-5,ChestGenHook:chests/igloo_chest:5-5
rule20=0,100,minecraft:oak_stairs-3
rule21=0,100,minecraft:oak_stairs-2
rule22=0,100,minecraft:oak_stairs-1
rule23=0,100,minecraft:jungle_door-2
rule24=0,100,minecraft:stone_brick_stairs-4
rule25=0,100,IInventory;minecraft:furnace;minecraft:coal#2#0#1-5
rule26=0,100,minecraft:oak_stairs-5
rule27=0,100,minecraft:jungle_door-8
rule28=0,100,minecraft:oak_stairs-7
rule29=0,100,minecraft:dark_oak_stairs-0
rule30=0,100,minecraft:spruce_stairs-4
rule31=0,100,minecraft:dark_oak_stairs-7
rule32=0,100,minecraft:wooden_slab-13
rule33=0,100,minecraft:cobblestone_wall-0
rule34=0,100,minecraft:spruce_stairs-7
rule35=0,100,minecraft:spruce_stairs-6
rule36=0,100,minecraft:spruce_stairs-5
rule37=0,100,minecraft:spruce_fence_gate-1
rule38=0,100,minecraft:dark_oak_stairs-5
rule39=0,100,minecraft:wooden_slab-5
rule40=0,100,minecraft:dark_oak_stairs-2
rule41=0,100,minecraft:dark_oak_stairs-3
rule42=0,100,minecraft:planks-5
rule43=0,100,minecraft:dark_oak_stairs-1
rule44=0,100,minecraft:dark_oak_fence-0

layer
1,1,1,1,1,1,1,1,1
1,1,3,2,2,3,2,2,1
1,2,4,4,4,4,2,3,1
1,2,4,4,4,4,4,2,1
1,3,4,4,4,4,4,2,5
1,2,4,4,4,4,4,3,2
5,2,3,2,2,2,2,2,2
7,2,3,1,3,1,3,1,3
endlayer

layer
1,1,1,1,1,1,1,1,1
1,1,9,8,8,9,8,8,1
1,8,4,4,4,4,8,9,1
1,8,4,4,4,4,4,8,1
1,9,4,4,4,4,4,8,1
1,8,4,4,4,4,4,9,5
1,8,9,8,8,8,8,8,8
1,7,8,1,8,1,8,1,8
endlayer

layer
1,1,1,1,1,1,1,1,1
1,1,3,8,8,3,8,8,1
1,8,4,4,4,4,8,3,1
1,8,4,4,4,4,4,8,1
1,3,4,4,4,4,4,8,1
1,8,4,4,4,4,4,3,1
1,8,3,8,8,8,8,8,5
1,1,7,12,8,1,8,11,10
endlayer

layer
1,1,1,1,1,1,1,1,1
1,1,9,8,8,9,8,8,1
1,8,4,4,4,4,8,9,1
1,8,4,4,4,4,4,8,1
1,9,4,4,4,4,4,8,1
1,8,4,4,4,4,4,9,1
1,8,9,8,8,8,8,10,1
1,1,1,7,8,8,8,10,1
endlayer

layer
1,1,1,1,1,1,1,1,1
1,1,3,2,2,3,8,8,1
1,2,13,13,13,13,8,3,1
1,2,13,14,14,14,13,2,1
1,3,13,14,14,14,13,2,1
1,2,13,13,13,13,13,3,1
1,1,3,2,2,8,2,1,1
1,1,1,1,7,8,10,1,1
endlayer

layer
1,1,1,1,1,1,1,1,1
1,17,15,16,16,15,8,8,1
1,20,19,6,6,6,18,15,1
1,20,6,6,6,6,6,21,1
1,15,6,6,6,6,6,21,1
1,20,6,6,6,6,6,15,1
1,17,15,22,20,23,22,1,1
1,1,1,1,1,6,1,1,1
endlayer

layer
1,1,1,1,1,1,1,1,1
1,17,15,17,6,15,24,10,1
1,6,6,6,6,6,25,15,1
1,17,6,6,6,6,6,6,1
1,15,6,6,6,6,6,17,1
1,17,6,6,6,6,6,15,1
1,17,15,17,28,27,26,1,1
1,1,1,1,1,6,1,1,1
endlayer

layer
1,1,1,1,1,1,1,1,1
32,31,15,30,30,15,5,29,1
1,34,6,6,6,6,33,15,1
1,34,6,6,6,6,6,35,1
1,15,6,6,6,6,6,35,1
1,34,6,6,6,6,6,15,1
1,38,15,36,36,37,36,1,1
1,1,1,1,1,6,1,1,1
endlayer

layer
1,39,41,32,32,40,39,1,1
1,41,15,42,42,15,5,39,1
29,42,36,36,36,36,2,15,29
32,42,35,6,6,6,34,42,32
32,15,35,6,6,6,34,42,32
39,42,30,30,30,30,34,15,43
1,39,15,42,42,42,42,40,1
1,1,41,32,32,32,39,1,1
endlayer

layer
1,1,1,1,1,1,1,1,1
1,1,29,41,40,29,1,1,1
1,41,42,42,42,42,2,40,1
1,29,42,14,14,14,42,29,1
1,43,42,14,14,14,42,43,1
1,1,41,42,42,42,42,43,1
1,1,43,43,41,40,39,1,1
1,1,1,1,1,1,1,1,1
endlayer

layer
1,1,1,1,1,1,1,1,1
1,1,1,1,1,1,1,1,1
1,1,44,44,44,44,33,1,1
1,1,44,39,39,39,44,1,1
1,1,44,39,39,39,44,1,1
1,1,1,44,44,44,44,1,1
1,1,1,1,1,1,1,1,1
1,1,1,1,1,1,1,1,1
endlayer

layer
1,1,1,1,1,1,1,1,1
1,1,1,1,1,1,1,1,1
1,1,1,1,1,1,33,1,1
1,1,1,1,1,1,1,1,1
1,1,1,1,1,1,1,1,1
1,1,1,1,1,1,1,1,1
1,1,1,1,1,1,1,1,1
1,1,1,1,1,1,1,1,1
endlayer

layer
1,1,1,1,1,1,1,1,1
1,1,1,1,1,1,1,1,1
1,1,1,1,1,1,33,1,1
1,1,1,1,1,1,1,1,1
1,1,1,1,1,1,1,1,1
1,1,1,1,1,1,1,1,1
1,1,1,1,1,1,1,1,1
1,1,1,1,1,1,1,1,1
endlayer

