
# Created by Ruins mod version 16.7 Ingame Parser
# authoring Player: lafuller

weight=1
embed_into_distance=4
acceptable_target_blocks=
unacceptable_target_blocks=flowing_water,water,flowing_lava,lava,ice,bedrock,netherrack,nether_brick,nether_brick_fence,soul_sand,quartz_ore,end_stone,obsidian,iron_bars,cloud,flesh,ash_block,slime_grass,slime_congealed,slime_dirt
biomesToSpawnIn=plains,prarie,meadow,tundra,brushland,shrubland,woodland,woodlands,lavender_fields,flower_field,sunflower_plains,ice_flats,ice_plains
dimensions=15,12,13
allowable_overhang=0
max_leveling=4
leveling_buffer=-1
preserve_water=0
preserve_lava=0

rule1=0,100,preserveBlock
rule2=0,100,stonebrick-0,stonebrick-0,stonebrick-0,stonebrick-0,stonebrick-1,stonebrick-2,stonebrick-2,stone-5,stone-6,cobblestone
rule3=0,100,minecraft:stone-6
rule4=0,100,minecraft:stained_hardened_clay-8
rule5=0,100,minecraft:hardened_clay-0
rule6=0,100,minecraft:stone_brick_stairs-0
rule7=0,100,minecraft:stone_brick_stairs-2
rule8=0,100,minecraft:stone_brick_stairs-3
rule9=0,100,stonebrick-0,stonebrick-0,stonebrick-0,stonebrick-0,stonebrick-1,stonebrick-2,stonebrick-2,stone-5,stone-6,cobblestone,gravel
rule10=0,100,minecraft:cobblestone_wall-0
rule11=0,100,minecraft:stone-5
rule12=0,100,minecraft:web-0,air,air,air
rule13=0,100,minecraft:log-0
rule14=0,100,minecraft:wooden_slab-9
rule15=0,100,minecraft:ladder-4
rule16=0,100,minecraft:planks-1
rule17=0,100,minecraft:planks-0
rule18=0,100,minecraft:oak_stairs-1
rule19=0,100,minecraft:fence-0
rule20=0,100,minecraft:oak_stairs-0
rule21=0,100,minecraft:oak_stairs-3
rule22=0,100,minecraft:oak_stairs-2
rule23=0,100,minecraft:stone-2
rule24=0,100,minecraft:trapdoor-9
rule25=0,100,minecraft:cauldron-0
rule26=0,100,minecraft:spruce_fence-0
rule27=0,100,minecraft:jungle_door-2
rule28=0,100,minecraft:furnace-3
rule29=0,100,minecraft:jungle_door-8
rule30=0,100,minecraft:spruce_stairs-6
rule31=0,100,minecraft:spruce_stairs-4
rule32=0,100,minecraft:spruce_stairs-7
rule33=0,100,minecraft:ladder-3
rule34=0,100,minecraft:spruce_stairs-5
rule35=0,100,minecraft:spruce_fence_gate-1
rule36=0,100,minecraft:dark_oak_stairs-6
rule37=0,100,minecraft:spruce_stairs-0
rule38=0,100,minecraft:dark_oak_stairs-7
rule39=0,100,minecraft:wooden_slab-13
rule40=0,100,minecraft:dark_oak_stairs-4
rule41=0,100,minecraft:dark_oak_stairs-2
rule42=0,100,minecraft:planks-5
rule43=0,100,minecraft:dark_oak_stairs-5
rule44=0,100,minecraft:dark_oak_stairs-1
rule45=0,100,minecraft:carpet-7
rule46=0,100,minecraft:spruce_fence_gate-0
rule47=0,100,minecraft:dark_oak_stairs-3
rule48=0,100,minecraft:wooden_slab-5
rule49=0,100,minecraft:dark_oak_stairs-0
rule50=0,100,minecraft:double_wooden_slab-5
rule51=0,100,minecraft:dark_oak_fence-0
rule52=0,100,minecraft:trapdoor-10
rule53=0,100,ChestGenHook:chests/spawn_bonus_chest:5-2

layer
1,1,1,1,1,1,1,1,1,1,1,1,1
1,1,1,1,1,1,1,2,2,2,1,1,1
1,1,2,2,2,2,3,4,4,4,3,1,1
1,1,3,4,4,4,4,4,5,5,4,2,1
1,2,4,4,5,5,5,5,4,5,4,2,1
1,2,4,5,4,4,4,4,5,4,4,2,1
1,2,4,5,5,5,4,4,4,5,4,2,1
1,1,3,4,4,4,5,4,5,5,2,2,6
1,1,2,2,2,4,5,5,5,4,2,2,7
1,1,8,2,2,4,4,4,4,4,2,2,7
1,1,8,2,2,2,2,2,2,2,2,2,7
1,1,8,2,2,2,2,2,2,2,2,2,7
endlayer

layer
1,1,1,1,1,1,1,1,1,1,1,1,1
1,1,1,1,1,1,1,9,10,9,1,1,1
1,1,9,9,9,10,11,13,0,12,11,1,1
1,1,11,13,12,0,0,0,0,0,13,9,1
1,9,14,0,0,0,0,0,0,0,14,10,1
1,10,14,0,0,0,0,0,0,0,14,9,1
1,9,14,0,0,0,0,0,0,0,14,10,1
1,1,11,15,15,0,0,0,9,9,13,9,1
1,1,9,9,9,0,0,0,0,0,9,7,1
1,1,1,8,9,13,0,0,53,12,9,7,1
1,1,1,8,9,9,9,9,9,9,9,7,1
1,1,1,8,9,9,9,9,9,9,9,7,1
endlayer

layer
1,1,1,1,1,1,1,1,1,1,1,1,1
1,1,1,1,1,1,1,9,10,9,1,1,1
1,1,9,9,9,10,3,13,12,12,3,1,1
1,1,3,13,12,12,0,0,0,0,13,9,1
1,9,12,0,0,0,0,0,0,0,12,10,1
1,10,0,0,0,0,0,0,0,0,0,9,1
1,9,12,0,0,0,0,0,0,0,12,10,1
1,1,3,15,15,0,0,0,0,0,13,9,1
1,1,9,9,9,0,0,0,0,12,9,1,1
1,1,1,1,9,13,12,0,12,12,9,1,1
1,1,1,1,8,9,9,9,9,9,7,1,1
1,1,1,1,8,9,9,9,9,9,7,1,1
endlayer

layer
1,1,1,1,1,1,1,1,1,1,1,1,1
1,1,1,1,1,1,1,9,10,9,1,1,1
1,1,9,9,9,10,11,13,12,12,11,1,1
1,1,11,13,12,12,12,12,12,12,13,9,1
1,9,12,12,12,0,0,12,0,12,12,10,1
1,10,12,0,0,0,0,0,0,0,12,9,1
1,9,12,0,0,0,0,0,0,12,12,10,1
1,1,11,15,15,0,0,0,14,14,13,9,1
1,1,9,9,9,12,12,0,12,12,9,1,1
1,1,1,1,9,13,12,12,12,12,9,1,1
1,1,1,1,1,9,9,9,9,9,1,1,1
1,1,1,1,1,8,9,9,9,7,1,1,1
endlayer

layer
1,1,1,1,1,1,1,1,1,1,1,1,1
1,1,1,1,1,1,1,9,9,9,1,1,1
1,1,9,9,9,9,3,16,16,16,3,1,1
1,1,3,16,16,16,16,16,17,17,16,9,1
1,9,16,16,17,17,17,17,17,16,16,9,1
1,9,16,17,16,16,16,16,16,17,16,9,1
1,9,16,18,18,17,16,16,16,17,16,9,1
1,1,3,15,15,16,17,16,17,16,13,9,1
1,1,9,9,9,16,17,17,17,16,9,1,1
1,1,1,1,9,16,16,16,16,16,9,1,1
1,1,1,1,1,9,9,9,9,9,1,1,1
1,1,1,1,1,1,8,9,7,1,1,1,1
endlayer

layer
1,1,1,1,1,1,1,1,1,1,1,1,1
1,1,1,1,1,1,19,20,20,20,19,1,1
1,1,21,20,20,20,13,0,0,0,13,19,1
1,19,13,0,0,0,0,0,0,0,23,22,1
1,21,0,0,0,0,0,0,0,0,24,22,1
1,21,0,0,0,0,0,0,0,0,23,22,1
1,21,0,0,0,0,0,0,0,0,25,22,1
1,19,13,15,15,0,0,0,0,0,13,19,1
1,1,21,18,21,0,0,0,0,0,22,1,1
1,1,1,1,18,13,26,0,26,13,18,1,1
1,1,1,1,1,1,13,27,13,1,1,1,1
1,1,1,1,1,1,1,1,1,1,1,1,1
endlayer

layer
1,1,1,1,1,1,1,1,1,1,1,1,1
1,1,1,1,1,1,19,19,0,19,19,1,1
1,1,19,0,19,19,13,0,0,0,13,19,1
1,19,13,0,0,0,0,0,0,0,0,19,1
1,19,0,0,0,0,0,0,0,0,0,0,1
1,1,0,0,0,0,0,0,0,0,0,19,1
1,19,0,0,0,0,0,0,0,0,28,19,1
1,19,13,15,15,0,0,0,0,0,13,19,1
1,1,26,18,21,0,0,0,0,0,19,1,1
1,1,1,1,1,13,26,0,26,13,1,1,1
1,1,1,1,1,1,13,29,13,1,1,1,1
1,1,1,1,1,1,1,1,1,1,1,1,1
endlayer

layer
1,1,1,1,1,1,1,1,1,1,1,1,1
1,1,1,1,1,1,32,31,31,31,30,1,1
1,1,32,31,31,31,13,0,0,0,13,1,1
1,31,13,0,0,0,0,0,0,0,33,30,1
1,32,0,0,0,0,0,0,0,0,33,30,1
1,32,0,0,0,0,0,0,0,0,0,30,1
1,32,0,0,0,0,0,0,0,0,10,30,1
1,34,13,15,15,0,0,0,0,0,13,34,1
1,1,26,34,32,0,0,0,0,0,34,1,1
1,1,1,1,1,13,26,0,26,13,30,1,1
1,1,1,1,1,32,13,35,13,30,1,1,1
1,1,1,1,1,1,1,1,1,1,1,1,1
endlayer

layer
1,1,1,1,1,1,1,1,1,1,1,1,1
1,1,1,1,39,38,37,37,37,37,36,1,1
1,38,31,16,16,16,13,14,14,14,13,40,1
1,42,13,14,14,30,14,14,14,14,14,41,1
39,16,30,14,14,34,34,34,34,34,34,36,1
39,16,30,14,14,30,14,0,0,0,0,36,1
39,16,30,14,14,30,0,0,0,0,10,41,1
39,16,13,15,15,30,0,0,0,0,13,36,1
1,44,43,43,38,30,0,0,0,0,36,1,1
1,1,1,39,38,13,0,0,0,13,36,1,1
1,1,1,1,39,34,13,34,13,34,39,1,1
1,1,1,1,1,1,1,1,1,1,1,1,1
endlayer

layer
1,1,1,1,1,39,39,39,39,36,1,1,1
1,1,38,40,40,42,42,42,42,42,36,1,1
1,38,16,16,16,16,13,45,45,45,13,40,1
39,42,13,0,0,0,0,45,45,45,0,36,39
38,16,45,45,0,0,0,0,0,0,0,42,36
38,16,45,45,0,0,26,35,35,35,26,42,36
47,16,45,45,0,0,46,0,0,0,10,42,39
38,16,13,15,15,0,46,0,0,0,13,36,1
43,38,44,16,16,0,46,0,0,0,42,43,1
1,1,38,43,42,13,26,0,0,13,36,1,1
1,1,1,1,38,42,42,42,42,42,43,1,1
1,1,1,1,1,39,43,39,43,39,1,1,1
endlayer

layer
1,1,1,48,49,47,42,42,49,48,1,1,1
1,1,49,42,42,42,42,42,42,42,50,48,1
1,42,42,42,42,42,13,0,0,0,13,50,48
48,42,16,0,0,0,0,0,0,0,0,50,48
48,42,0,0,0,0,0,0,0,0,0,16,50
47,42,0,0,0,0,0,0,0,0,0,16,50
44,42,0,0,0,0,0,0,0,0,10,16,50
47,42,16,15,15,0,0,0,0,0,16,42,48
47,44,42,16,16,0,0,0,0,0,16,50,1
1,1,44,47,16,42,49,49,49,42,16,50,1
1,1,1,48,42,42,44,44,44,42,42,48,1
1,1,1,1,44,44,48,48,48,44,44,1,1
endlayer

layer
1,1,1,1,1,1,1,1,1,1,1,1,1
1,1,1,1,48,49,49,47,50,49,1,1,1
1,1,48,49,43,43,13,0,0,0,41,1,1
1,48,38,0,0,0,0,0,0,0,39,48,1
1,46,0,0,0,0,0,0,0,0,39,48,1
1,46,0,0,0,0,0,0,0,0,39,50,1
1,46,0,0,0,0,0,0,0,0,10,50,1
1,48,42,0,0,0,0,0,0,0,39,48,1
1,1,48,44,42,0,0,0,0,0,50,1,1
1,1,1,1,47,38,51,51,51,50,48,1,1
1,1,1,1,1,44,1,1,1,44,48,1,1
1,1,1,1,1,1,1,1,1,1,1,1,1
endlayer

layer
1,1,1,1,1,1,1,1,1,1,1,1,1
1,1,1,1,1,1,1,1,1,1,1,1,1
1,1,1,1,1,48,48,48,48,48,1,1,1
1,1,1,48,48,48,49,49,48,48,1,1,1
1,48,48,49,39,39,39,39,39,49,1,1,1
1,48,48,47,39,39,39,39,39,38,48,1,1
1,48,48,47,39,39,39,52,39,38,42,1,1
1,1,1,48,39,39,39,39,39,48,48,1,1
1,1,1,1,48,44,39,40,50,48,1,1,1
1,1,1,1,1,1,44,44,48,1,1,1,1
1,1,1,1,1,1,1,1,1,1,1,1,1
1,1,1,1,1,1,1,1,1,1,1,1,1
endlayer

layer
1,1,1,1,1,1,1,1,1,1,1,1,1
1,1,1,1,1,1,1,1,1,1,1,1,1
1,1,1,1,1,1,1,1,1,1,1,1,1
1,1,1,1,1,1,1,1,1,1,1,1,1
1,1,1,1,1,1,1,1,1,1,1,1,1
1,1,1,1,1,48,48,48,48,1,1,1,1
1,1,1,1,1,48,48,1,48,1,10,1,1
1,1,1,1,1,1,1,48,1,1,1,1,1
1,1,1,1,1,1,1,1,1,1,1,1,1
1,1,1,1,1,1,1,1,1,1,1,1,1
1,1,1,1,1,1,1,1,1,1,1,1,1
1,1,1,1,1,1,1,1,1,1,1,1,1
endlayer

layer
1,1,1,1,1,1,1,1,1,1,1,1,1
1,1,1,1,1,1,1,1,1,1,1,1,1
1,1,1,1,1,1,1,1,1,1,1,1,1
1,1,1,1,1,1,1,1,1,1,1,1,1
1,1,1,1,1,1,1,1,1,1,1,1,1
1,1,1,1,1,1,1,1,1,1,1,1,1
1,1,1,1,1,1,1,1,1,1,10,1,1
1,1,1,1,1,1,1,1,1,1,1,1,1
1,1,1,1,1,1,1,1,1,1,1,1,1
1,1,1,1,1,1,1,1,1,1,1,1,1
1,1,1,1,1,1,1,1,1,1,1,1,1
1,1,1,1,1,1,1,1,1,1,1,1,1
endlayer

