
# Created by Ruins mod version 16.7 Ingame Parser
# authoring Player: lafuller

weight=1
embed_into_distance=4
acceptable_target_blocks=
unacceptable_target_blocks=flowing_water,water,flowing_lava,lava,ice,bedrock,netherrack,nether_brick,nether_brick_fence,soul_sand,quartz_ore,end_stone,obsidian,iron_bars,cloud,flesh,ash_block,slime_grass,slime_congealed,slime_dirt
biomesToSpawnIn=plains,mutated_plains,forest,birch forest,taiga,woodland,woodlands,prarie,meadow,badlands,lavender fields,flower field,sunflower plains
dimensions=8,10,12
allowable_overhang=0
max_leveling=4
leveling_buffer=-1
preserve_water=0
preserve_lava=0

rule1=0,100,preserveBlock
rule2=0,100,stonebrick-0,stonebrick-2,stonebrick-2,stonebrick-1,stonebrick-1,cobblestone
rule3=0,100,stonebrick-0,stonebrick-2,stonebrick-2,stonebrick-1,stonebrick-1,cobblestone
rule4=0,100,stonebrick-0,stonebrick-1,stonebrick-2,stone-5,stone-5,stone-6
rule5=0,100,minecraft:stone_brick_stairs-0
rule6=0,100,minecraft:stone_brick_stairs-2
rule7=0,100,stonebrick-0,stonebrick-0,stonebrick-0,stonebrick-0,stonebrick-1,stonebrick-2,stonebrick-2,stone-5,stone-6,cobblestone,gravel
rule8=0,100,minecraft:cobblestone_wall-0
rule9=0,100,minecraft:log-0
rule10=0,100,minecraft:wooden_slab-9
rule11=0,100,minecraft:ladder-3
rule12=0,100,ChestGenHook:chests/spawn_bonus_chest:5-5
rule13=0,100,web-0,air,air,air
rule14=0,100,planks-0,oak_stairs-0,oak_stairs-1,oak_stairs-4,oak_stairs-5,air
rule15=0,100,planks-1,spruce_stairs-0,spruce_stairs-1,spruce_stairs-4,spruce_stairs-5,air
rule16=0,100,minecraft:stone_brick_stairs-3
rule17=0,100,minecraft:stone_brick_stairs-1
rule18=1,100,log-0,log-0,log-0,log-0,air

layer
1,2,2,2,2,2,2,2,2,1,1,1
1,2,3,3,3,3,3,3,2,1,1,1
1,2,3,4,4,4,4,3,2,2,2,2
5,2,3,4,3,3,4,3,3,3,3,2
2,2,3,4,3,3,3,4,4,4,3,2
2,2,3,3,4,4,3,3,3,4,3,2
2,2,3,3,3,3,4,4,4,3,3,2
2,2,2,2,2,2,3,3,3,3,3,2
2,2,2,2,2,2,2,2,2,2,2,2
2,2,2,2,2,2,2,2,6,1,1,1
endlayer

layer
1,7,7,8,7,7,8,7,7,1,1,1
1,7,9,10,10,10,10,9,7,1,1,1
1,8,10,0,0,0,0,11,7,8,7,7
1,7,10,0,0,0,0,0,0,12,9,7
5,8,10,0,0,0,0,0,0,0,10,8
7,7,10,0,0,0,0,0,0,0,10,7
7,7,9,0,0,0,0,0,0,0,10,8
7,7,7,7,7,7,9,10,10,10,9,7
7,7,7,7,7,7,7,7,8,7,7,7
7,7,7,7,7,7,7,6,1,1,1,1
endlayer

layer
1,7,7,8,7,7,8,7,7,1,1,1
1,7,9,13,0,0,13,9,7,1,1,1
1,8,13,0,0,0,0,11,7,8,7,7
1,7,0,0,0,0,0,0,0,13,9,7
1,8,0,0,0,0,0,0,0,0,13,8
5,7,13,0,0,0,0,0,0,0,0,7
7,7,9,13,0,0,0,0,0,0,13,8
7,7,7,7,7,7,9,13,0,13,9,7
7,7,7,7,7,7,7,7,8,7,7,7
7,7,7,7,7,7,6,1,1,1,1,1
endlayer

layer
1,7,7,8,7,7,8,7,7,1,1,1
1,7,9,13,13,13,13,9,7,1,1,1
1,8,13,13,0,0,0,11,7,8,7,7
1,7,13,0,0,0,0,0,13,13,9,7
1,8,13,0,0,0,0,0,0,13,13,8
1,7,13,13,0,0,0,0,0,0,13,7
5,7,9,13,13,0,0,13,0,13,13,8
7,7,7,7,7,7,9,13,13,13,9,7
7,7,7,7,7,7,7,7,8,7,7,7
7,7,7,7,7,6,1,1,1,1,1,1
endlayer

layer
1,7,7,7,7,7,7,7,7,1,1,1
1,7,9,14,14,14,14,9,7,1,1,1
1,7,14,15,14,15,14,11,7,7,7,7
1,7,14,15,15,14,15,14,14,14,9,7
1,7,14,15,14,14,15,14,15,15,14,7
1,7,14,14,15,15,15,15,14,15,14,7
1,7,9,14,14,14,14,15,15,15,14,7
1,16,7,7,7,7,9,14,14,14,9,7
1,16,17,17,17,7,7,7,7,7,7,7
1,1,1,1,1,1,1,1,1,1,1,1
endlayer

layer
1,1,1,1,1,1,1,1,1,1,1,1
1,1,18,0,0,0,0,18,1,1,1,1
1,1,0,0,0,0,0,0,0,1,1,1
1,1,0,0,0,0,0,0,0,0,18,1
1,1,0,0,0,0,0,0,0,0,0,1
1,1,0,0,0,0,0,0,0,0,0,1
1,1,18,0,0,0,0,0,0,0,0,1
1,1,1,1,0,0,18,0,0,0,18,1
1,1,1,1,1,1,0,1,1,1,1,1
1,1,1,1,1,1,1,1,1,1,1,1
endlayer

layer
1,1,1,1,0,0,0,0,1,1,1,1
1,1,18,0,0,0,0,18,0,1,1,1
1,1,0,0,0,0,0,0,0,0,1,1
1,0,0,0,0,0,0,0,0,0,18,1
0,0,0,0,0,0,0,0,0,0,0,0
1,0,0,0,0,0,0,0,0,0,0,0
1,1,18,0,0,0,0,0,0,0,0,1
1,1,0,0,0,0,18,0,0,0,18,1
1,1,1,1,0,0,0,0,1,1,1,1
1,1,1,1,1,0,0,1,1,1,1,1
endlayer

layer
1,1,1,0,0,0,0,0,0,1,1,1
1,1,18,0,0,0,0,18,0,0,1,1
1,0,0,0,0,0,0,0,0,0,0,1
0,0,0,0,0,0,0,0,0,0,18,0
0,0,0,0,0,0,0,0,0,0,0,0
0,0,0,0,0,0,0,0,0,0,0,0
1,0,18,0,0,0,0,0,0,0,0,0
1,1,0,0,0,0,18,0,0,0,18,1
1,1,1,0,0,0,0,0,0,1,1,1
1,1,1,1,0,0,0,0,1,1,1,1
endlayer

