
# Created by Ruins mod version 16.7 Ingame Parser
# authoring Player: lafuller

weight=1
embed_into_distance=4
uniqueMinDistance=400
acceptable_target_blocks=
unacceptable_target_blocks=flowing_water,water,flowing_lava,lava,ice,bedrock,netherrack,nether_brick,nether_brick_fence,soul_sand,quartz_ore,end_stone,obsidian,iron_bars,cloud,flesh,ash_block,slime_grass,slime_congealed,slime_dirt
biomesToSpawnIn=plains,mutated_plains,forest,birch forest,taiga,woodland,woodlands,prarie,meadow,badlands,lavender fields,flower field,sunflower plains
dimensions=19,14,15
allowable_overhang=0
max_leveling=4
leveling_buffer=-1
preserve_water=0
preserve_lava=0

rule1=0,100,air
rule2=0,100,preserveBlock
rule3=0,100,minecraft:stone-6
rule4=0,100,stonebrick-0,stonebrick-0,stonebrick-0,stonebrick-0,stonebrick-1,stonebrick-2,stonebrick-2,stone-5,stone-6,cobblestone
rule5=0,100,stonebrick-0,stonebrick-2,stonebrick-2,stonebrick-1,stonebrick-1,cobblestone
rule6=0,100,stonebrick-0,stonebrick-1,stonebrick-2,stone-5,stone-5,stone-6,mycelium-0,mycelium
rule7=0,100,stonebrick-0,stonebrick-0,stonebrick-2,mycelium-0,mycelium-0,mycelium-0,mycelium
rule8=0,100,minecraft:stone_brick_stairs-3
rule9=0,100,minecraft:stone-5
rule10=0,100,stonebrick-0,stonebrick-0,stonebrick-0,stonebrick-0,stonebrick-1,stonebrick-2,stonebrick-2,stone-5,stone-6,cobblestone,gravel
rule11=0,100,minecraft:cobblestone_wall-0
rule12=0,100,minecraft:log-0
rule13=0,100,minecraft:wooden_slab-9
rule14=0,100,minecraft:oak_stairs-0,spruce_stairs-0,air
rule15=0,100,planks-0,oak_stairs-0,oak_stairs-1,oak_stairs-4,oak_stairs-5,air
rule16=0,100,ChestGenHook:chests/spawn_bonus_chest:5-2,ChestGenHook:chests/village_blacksmith:5-2,ChestGenHook:chests/simple_dungeon:5-2,ChestGenHook:chests/abandoned_mineshaft:5-2,ChestGenHook:chests/stronghold_library:5-2,ChestGenHook:chests/stronghold_corridor:5-2,ChestGenHook:chests/stronghold_crossing:5-2,ChestGenHook:chests/igloo_chest:5-2
rule17=0,100,minecraft:oak_stairs-7,spruce_stairs-7,air
rule18=0,100,minecraft:oak_stairs-2,spruce_stairs-2,air
rule19=0,100,planks-1,spruce_stairs-0,spruce_stairs-1,spruce_stairs-4,spruce_stairs-5,air,air,air
rule20=0,100,minecraft:dirt-0
rule21=0,100,planks-5,dark_oak_stairs-0,dark_oak_stairs-1,dark_oak_stairs-4,dark_oak_stairs-5,air,air,air,air,air,air
rule22=0,100,minecraft:spruce_stairs-5,spruce_stairs-5,air
rule23=0,100,minecraft:log2-1
rule24=0,100,minecraft:stone_brick_stairs-1
rule25=0,100,minecraft:stone_brick_stairs-5
rule26=0,100,minecraft:stone_brick_stairs-7
rule27=0,100,minecraft:stone_slab-13
rule28=0,100,minecraft:stone_brick_stairs-4
rule29=0,100,minecraft:stone_brick_stairs-6
rule30=0,100,minecraft:log2-9
rule31=0,100,minecraft:log2-5
rule32=0,100,minecraft:stone_brick_stairs-0

layer
2,2,2,2,3,4,4,4,4,4,3,2,2,2,2
2,4,4,4,4,4,5,5,5,5,4,2,2,2,2
2,4,4,4,3,5,6,6,6,5,3,4,4,4,3
3,4,4,3,5,6,6,7,6,5,5,5,5,5,4
4,4,3,5,5,6,7,7,6,6,5,6,6,5,4
4,5,5,6,6,7,7,6,7,7,6,7,6,5,4
4,5,6,7,7,7,7,7,7,7,7,6,6,5,4
4,5,6,6,6,7,7,7,7,7,7,5,5,5,4
4,5,5,5,5,6,7,6,6,7,6,5,3,4,3
3,4,4,3,5,6,6,6,7,7,7,5,4,2,2
8,4,4,4,5,5,5,5,6,7,6,5,4,2,2
8,4,4,3,4,4,3,5,6,6,6,5,4,2,2
8,4,4,4,4,4,4,5,5,5,5,5,4,2,2
8,4,4,4,4,4,3,4,4,4,4,4,3,2,2
endlayer

layer
2,2,2,2,9,10,11,10,11,10,9,2,2,2,2
2,10,10,10,10,10,13,13,13,12,10,2,2,2,2
2,10,10,10,9,1,1,1,1,1,9,10,11,10,9
9,10,10,9,1,1,1,1,1,1,1,1,1,12,10
10,10,9,1,1,1,1,1,1,1,1,1,1,13,10
10,12,1,1,1,1,1,1,1,1,1,1,1,13,11
11,13,1,1,1,1,1,1,1,1,1,1,1,13,10
10,13,1,1,1,1,1,1,1,1,1,1,1,12,10
10,12,1,1,1,1,1,1,1,1,1,1,9,10,9
9,10,11,9,1,1,1,1,1,1,1,1,11,2,2
2,8,10,10,12,1,1,1,1,1,1,14,10,2,2
2,8,10,9,10,10,9,1,1,1,12,15,11,2,2
2,8,10,10,10,10,10,12,1,1,16,15,10,2,2
2,8,10,10,10,10,9,10,11,10,11,10,10,2,2
endlayer

layer
2,2,2,2,3,10,11,10,11,10,3,2,2,2,2
2,10,10,10,10,10,1,1,1,12,10,2,2,2,2
2,10,10,10,3,1,1,1,1,1,3,10,11,10,3
3,10,10,3,1,1,1,1,1,1,1,1,1,12,10
10,10,3,1,1,1,1,1,1,1,1,1,1,1,10
10,12,1,1,1,1,1,1,1,1,1,1,1,1,11
11,1,1,1,1,1,1,1,1,1,1,1,1,1,10
10,1,1,1,1,1,1,1,1,1,1,1,1,12,10
10,12,1,1,1,1,1,1,1,1,1,1,3,10,3
3,10,11,3,1,1,1,1,1,1,1,1,11,2,2
2,2,8,10,12,1,1,1,1,1,1,1,10,2,2
2,2,8,3,10,10,3,1,1,1,12,14,11,2,2
2,2,8,10,10,10,10,12,1,1,17,15,10,2,2
2,2,8,10,10,10,3,10,11,10,11,10,3,2,2
endlayer

layer
2,2,2,2,9,10,11,10,11,10,9,2,2,2,2
2,10,10,10,10,10,1,1,1,12,10,2,2,2,2
2,10,10,10,9,1,1,1,1,1,9,10,11,10,9
9,10,10,9,1,1,1,1,1,1,1,1,1,12,10
10,10,9,1,1,1,1,1,1,1,1,1,1,1,10
10,12,1,1,1,1,1,1,1,1,1,1,1,1,11
11,1,1,1,1,1,1,1,1,1,1,1,1,1,10
10,1,1,1,1,1,1,1,1,1,1,1,1,12,10
10,12,1,1,1,1,1,1,1,1,1,1,9,10,9
9,10,11,9,1,1,1,1,1,1,1,1,11,2,2
2,2,2,10,12,1,1,1,1,1,1,1,10,2,2
2,2,2,9,10,10,9,1,1,17,12,1,11,2,2
2,2,2,8,10,10,10,12,1,17,18,1,10,2,2
2,2,2,8,10,10,9,10,11,10,11,10,10,2,2
endlayer

layer
2,2,2,2,3,10,10,10,10,10,3,2,2,2,2
2,10,10,10,10,10,19,15,15,15,10,2,2,2,2
2,10,20,20,3,15,19,19,19,19,3,10,10,10,3
3,10,20,20,3,19,21,21,21,21,19,15,15,15,10
10,10,3,3,3,21,1,1,1,1,21,19,19,15,10
10,15,19,19,21,1,1,1,1,1,1,21,19,15,10
10,15,15,19,21,1,1,1,1,1,1,21,19,19,10
10,15,19,19,21,1,1,1,1,1,1,22,15,15,10
10,15,15,15,19,21,1,1,1,1,1,1,3,10,3
3,10,10,3,15,19,21,1,21,21,1,1,10,2,2
2,2,2,10,15,19,19,21,19,19,1,1,10,2,2
2,2,2,3,10,15,3,19,15,19,23,1,10,2,2
2,2,2,2,8,4,10,15,15,18,1,1,10,2,2
2,2,2,2,8,24,3,10,10,10,10,10,3,2,2
endlayer

layer
2,2,2,2,23,2,1,1,1,2,23,2,2,2,2
2,10,10,10,10,2,1,1,1,1,1,2,2,2,2
2,10,1,1,11,1,1,1,1,1,23,2,2,2,23
23,10,1,1,1,1,1,1,1,1,1,1,1,2,2
2,10,11,1,1,1,1,1,1,1,1,1,1,1,2
2,1,1,1,1,1,1,1,1,1,1,1,1,1,2
1,1,1,1,1,1,1,1,1,1,1,1,1,1,1
1,1,1,1,1,1,1,1,1,1,1,1,1,1,1
2,1,1,1,1,1,1,1,1,1,1,1,23,1,23
23,1,1,23,1,1,1,1,1,1,1,1,1,1,2
2,2,1,1,1,1,1,1,1,1,1,1,1,2,2
2,2,2,23,1,1,23,1,1,1,23,1,2,2,2
2,2,2,2,1,1,1,1,1,1,1,1,2,2,2
2,2,2,2,2,2,23,1,1,2,2,2,23,2,2
endlayer

layer
2,2,2,2,23,2,1,1,1,1,23,2,2,2,2
2,10,10,10,10,1,1,1,1,1,1,2,2,2,2
2,10,1,1,11,1,1,1,1,1,23,1,1,2,23
23,10,1,1,1,1,1,1,1,1,1,1,1,1,2
2,10,11,1,1,1,1,1,1,1,1,1,1,1,1
1,1,1,1,1,1,1,1,1,1,1,1,1,1,1
1,1,1,1,1,1,1,1,1,1,1,1,1,1,1
1,1,1,1,1,1,1,1,1,1,1,1,1,1,1
1,1,1,1,1,1,1,1,1,1,1,1,23,1,23
23,1,1,23,1,1,1,1,1,1,1,1,1,1,1
2,1,1,1,1,1,1,1,1,1,1,1,1,1,2
2,2,1,23,1,1,23,1,1,1,23,1,1,2,2
2,2,2,1,1,1,1,1,1,1,1,1,2,2,2
2,2,2,2,2,1,23,1,1,1,2,2,23,2,2
endlayer

layer
2,2,2,2,23,1,1,1,1,1,23,2,2,2,2
2,10,10,10,10,1,1,1,1,1,1,1,1,2,2
2,10,1,1,11,1,1,1,1,1,23,1,1,1,23
23,10,1,1,1,1,1,1,1,1,1,1,1,1,1
1,10,11,1,1,1,1,1,1,1,1,1,1,1,1
1,1,1,1,1,1,1,1,1,1,1,1,1,1,1
1,1,1,1,1,1,1,1,1,1,1,1,1,1,1
1,1,1,1,1,1,1,1,1,1,1,1,1,1,1
1,1,1,1,1,1,1,1,1,1,1,1,23,1,23
23,1,1,23,1,1,1,1,1,1,1,1,1,1,1
1,1,1,1,1,1,1,1,1,1,1,1,1,1,1
2,1,1,23,1,1,23,1,1,1,23,1,1,1,2
2,2,1,1,1,1,1,1,1,1,1,1,1,2,2
2,2,2,2,1,1,23,1,1,1,1,2,23,2,2
endlayer

layer
2,2,1,1,23,1,1,1,1,1,23,1,1,2,2
2,10,10,10,10,1,1,1,1,1,1,1,1,1,2
1,10,1,26,25,1,1,1,1,1,23,1,1,1,23
23,10,28,27,1,1,1,1,1,1,1,1,1,1,1
1,10,29,1,1,1,1,1,1,1,1,1,1,1,1
1,1,1,1,1,1,1,1,1,1,1,1,1,1,1
1,1,1,1,1,1,1,1,1,1,1,1,1,1,1
1,1,1,1,1,1,1,1,1,1,1,1,1,1,1
1,1,1,1,1,1,1,1,1,1,1,1,23,1,23
23,1,1,23,1,1,1,1,1,1,1,1,1,1,1
1,1,1,1,1,1,1,1,1,1,1,1,1,1,1
1,1,1,23,1,1,23,1,1,1,23,1,1,1,1
2,1,1,1,1,1,1,1,1,1,1,1,1,1,2
2,2,1,1,1,1,23,1,1,1,1,1,23,2,2
endlayer

layer
2,1,1,1,23,30,30,30,30,30,23,1,1,1,2
1,10,10,10,31,1,1,1,1,1,31,1,1,1,1
1,10,1,10,31,1,1,1,1,1,23,30,30,30,23
23,10,10,4,31,1,1,1,1,1,31,1,1,1,31
31,30,30,30,30,30,1,1,1,1,31,1,1,1,31
31,1,1,31,1,1,1,1,1,1,1,1,1,1,31
31,1,1,31,1,1,1,1,1,1,1,1,1,1,31
31,1,1,31,1,1,1,1,1,1,1,1,1,1,31
31,1,1,31,1,1,1,1,1,1,1,30,23,30,23
23,30,30,23,1,1,1,1,1,1,31,1,31,1,1
1,1,1,31,1,1,31,1,1,1,31,1,31,1,1
1,1,1,23,30,30,23,1,1,1,23,1,31,1,1
1,1,1,1,1,1,31,1,1,1,1,1,31,1,1
2,1,1,1,1,1,23,30,30,30,30,30,23,1,2
endlayer

layer
1,1,1,1,1,1,1,1,1,1,1,1,1,1,1
1,8,10,10,1,1,1,1,1,1,1,1,1,1,1
1,10,1,10,23,1,1,1,1,1,23,1,1,1,1
1,10,10,1,1,1,1,1,1,1,1,1,1,1,1
1,1,1,1,1,1,1,1,1,1,1,1,1,1,1
1,1,1,1,1,1,1,1,1,1,1,1,1,1,1
1,1,1,1,1,1,1,1,1,1,1,1,1,1,1
1,1,1,1,1,1,1,1,1,1,1,1,1,1,1
1,1,1,1,1,1,1,1,1,1,1,1,1,1,1
1,1,1,23,1,1,1,1,1,1,1,1,1,1,1
1,1,1,1,1,1,1,1,1,1,1,1,1,1,1
1,1,1,1,1,1,23,1,1,1,23,1,1,1,1
1,1,1,1,1,1,1,1,1,1,1,1,1,1,1
1,1,1,1,1,1,1,1,1,1,1,1,1,1,1
endlayer

layer
1,1,1,1,1,1,1,1,1,1,1,1,1,1,1
1,1,10,10,1,1,1,1,1,1,1,1,1,1,1
1,10,1,10,23,1,1,1,1,1,23,1,1,1,1
1,10,10,1,1,1,1,1,1,1,1,1,1,1,1
1,1,1,1,1,1,1,1,1,1,1,1,1,1,1
1,1,1,1,1,1,1,1,1,1,1,1,1,1,1
1,1,1,1,1,1,1,1,1,1,1,1,1,1,1
1,1,1,1,1,1,1,1,1,1,1,1,1,1,1
1,1,1,1,1,1,1,1,1,1,1,1,1,1,1
1,1,1,23,1,1,1,1,1,1,1,1,1,1,1
1,1,1,1,1,1,1,1,1,1,1,1,1,1,1
1,1,1,1,1,1,23,1,1,1,23,1,1,1,1
1,1,1,1,1,1,1,1,1,1,1,1,1,1,1
1,1,1,1,1,1,1,1,1,1,1,1,1,1,1
endlayer

layer
1,1,1,1,1,1,1,1,1,1,1,1,1,1,1
1,1,10,10,1,1,1,1,1,1,1,1,1,1,1
1,10,1,10,23,1,1,1,1,1,23,1,1,1,1
1,10,10,1,1,1,1,1,1,1,1,1,1,1,1
1,1,1,1,1,1,1,1,1,1,1,1,1,1,1
1,1,1,1,1,1,1,1,1,1,1,1,1,1,1
1,1,1,1,1,1,1,1,1,1,1,1,1,1,1
1,1,1,1,1,1,1,1,1,1,1,1,1,1,1
1,1,1,1,1,1,1,1,1,1,1,1,1,1,1
1,1,1,23,1,1,1,1,1,1,1,1,1,1,1
1,1,1,1,1,1,1,1,1,1,1,1,1,1,1
1,1,1,1,1,1,1,1,1,1,23,1,1,1,1
1,1,1,1,1,1,1,1,1,1,1,1,1,1,1
1,1,1,1,1,1,1,1,1,1,1,1,1,1,1
endlayer

layer
1,1,1,1,1,1,1,1,1,1,1,1,1,1,1
1,1,10,32,1,1,1,1,1,1,1,1,1,1,1
1,10,1,10,23,1,1,1,1,1,1,1,1,1,1
1,10,10,1,1,1,1,1,1,1,1,1,1,1,1
1,1,1,1,1,1,1,1,1,1,1,1,1,1,1
1,1,1,1,1,1,1,1,1,1,1,1,1,1,1
1,1,1,1,1,1,1,1,1,1,1,1,1,1,1
1,1,1,1,1,1,1,1,1,1,1,1,1,1,1
1,1,1,1,1,1,1,1,1,1,1,1,1,1,1
1,1,1,1,1,1,1,1,1,1,1,1,1,1,1
1,1,1,1,1,1,1,1,1,1,1,1,1,1,1
1,1,1,1,1,1,1,1,1,1,23,1,1,1,1
1,1,1,1,1,1,1,1,1,1,1,1,1,1,1
1,1,1,1,1,1,1,1,1,1,1,1,1,1,1
endlayer

layer
1,1,1,1,1,1,1,1,1,1,1,1,1,1,1
1,1,10,1,1,1,1,1,1,1,1,1,1,1,1
1,10,1,10,1,1,1,1,1,1,1,1,1,1,1
1,8,10,1,1,1,1,1,1,1,1,1,1,1,1
1,1,1,1,1,1,1,1,1,1,1,1,1,1,1
1,1,1,1,1,1,1,1,1,1,1,1,1,1,1
1,1,1,1,1,1,1,1,1,1,1,1,1,1,1
1,1,1,1,1,1,1,1,1,1,1,1,1,1,1
1,1,1,1,1,1,1,1,1,1,1,1,1,1,1
1,1,1,1,1,1,1,1,1,1,1,1,1,1,1
1,1,1,1,1,1,1,1,1,1,1,1,1,1,1
1,1,1,1,1,1,1,1,1,1,1,1,1,1,1
1,1,1,1,1,1,1,1,1,1,1,1,1,1,1
1,1,1,1,1,1,1,1,1,1,1,1,1,1,1
endlayer

layer
1,1,1,1,1,1,1,1,1,1,1,1,1,1,1
1,1,10,1,1,1,1,1,1,1,1,1,1,1,1
1,10,1,10,1,1,1,1,1,1,1,1,1,1,1
1,1,10,1,1,1,1,1,1,1,1,1,1,1,1
1,1,1,1,1,1,1,1,1,1,1,1,1,1,1
1,1,1,1,1,1,1,1,1,1,1,1,1,1,1
1,1,1,1,1,1,1,1,1,1,1,1,1,1,1
1,1,1,1,1,1,1,1,1,1,1,1,1,1,1
1,1,1,1,1,1,1,1,1,1,1,1,1,1,1
1,1,1,1,1,1,1,1,1,1,1,1,1,1,1
1,1,1,1,1,1,1,1,1,1,1,1,1,1,1
1,1,1,1,1,1,1,1,1,1,1,1,1,1,1
1,1,1,1,1,1,1,1,1,1,1,1,1,1,1
1,1,1,1,1,1,1,1,1,1,1,1,1,1,1
endlayer

layer
1,1,1,1,1,1,1,1,1,1,1,1,1,1,1
1,1,10,1,1,1,1,1,1,1,1,1,1,1,1
1,10,1,10,1,1,1,1,1,1,1,1,1,1,1
1,1,1,1,1,1,1,1,1,1,1,1,1,1,1
1,1,1,1,1,1,1,1,1,1,1,1,1,1,1
1,1,1,1,1,1,1,1,1,1,1,1,1,1,1
1,1,1,1,1,1,1,1,1,1,1,1,1,1,1
1,1,1,1,1,1,1,1,1,1,1,1,1,1,1
1,1,1,1,1,1,1,1,1,1,1,1,1,1,1
1,1,1,1,1,1,1,1,1,1,1,1,1,1,1
1,1,1,1,1,1,1,1,1,1,1,1,1,1,1
1,1,1,1,1,1,1,1,1,1,1,1,1,1,1
1,1,1,1,1,1,1,1,1,1,1,1,1,1,1
1,1,1,1,1,1,1,1,1,1,1,1,1,1,1
endlayer

layer
1,1,1,1,1,1,1,1,1,1,1,1,1,1,1
1,1,10,1,1,1,1,1,1,1,1,1,1,1,1
1,1,1,10,1,1,1,1,1,1,1,1,1,1,1
1,1,1,1,1,1,1,1,1,1,1,1,1,1,1
1,1,1,1,1,1,1,1,1,1,1,1,1,1,1
1,1,1,1,1,1,1,1,1,1,1,1,1,1,1
1,1,1,1,1,1,1,1,1,1,1,1,1,1,1
1,1,1,1,1,1,1,1,1,1,1,1,1,1,1
1,1,1,1,1,1,1,1,1,1,1,1,1,1,1
1,1,1,1,1,1,1,1,1,1,1,1,1,1,1
1,1,1,1,1,1,1,1,1,1,1,1,1,1,1
1,1,1,1,1,1,1,1,1,1,1,1,1,1,1
1,1,1,1,1,1,1,1,1,1,1,1,1,1,1
1,1,1,1,1,1,1,1,1,1,1,1,1,1,1
endlayer

layer
1,1,1,1,1,1,1,1,1,1,1,1,1,1,1
1,1,10,1,1,1,1,1,1,1,1,1,1,1,1
1,1,1,1,1,1,1,1,1,1,1,1,1,1,1
1,1,1,1,1,1,1,1,1,1,1,1,1,1,1
1,1,1,1,1,1,1,1,1,1,1,1,1,1,1
1,1,1,1,1,1,1,1,1,1,1,1,1,1,1
1,1,1,1,1,1,1,1,1,1,1,1,1,1,1
1,1,1,1,1,1,1,1,1,1,1,1,1,1,1
1,1,1,1,1,1,1,1,1,1,1,1,1,1,1
1,1,1,1,1,1,1,1,1,1,1,1,1,1,1
1,1,1,1,1,1,1,1,1,1,1,1,1,1,1
1,1,1,1,1,1,1,1,1,1,1,1,1,1,1
1,1,1,1,1,1,1,1,1,1,1,1,1,1,1
1,1,1,1,1,1,1,1,1,1,1,1,1,1,1
endlayer

