
# Created by Ruins mod version 16.7 Ingame Parser
# authoring Player: lafuller

weight=1
embed_into_distance=4
acceptable_target_blocks=
unacceptable_target_blocks=flowing_water,water,flowing_lava,lava,ice,bedrock,netherrack,nether_brick,nether_brick_fence,soul_sand,quartz_ore,end_stone,obsidian,iron_bars,cloud,flesh,ash_block,slime_grass,slime_congealed,slime_dirt
biomesToSpawnIn=plains,mutated_plains,forest,birch forest,taiga,woodland,woodlands,prarie,meadow,badlands,lavender fields,flower field,sunflower plains
dimensions=5,10,10
allowable_overhang=0
max_leveling=4
leveling_buffer=-1
preserve_water=0
preserve_lava=0

rule1=0,100,preserveBlock
rule2=0,100,minecraft:stone-6
rule3=0,100,stonebrick-0,stonebrick-0,stonebrick-0,stonebrick-0,stonebrick-1,stonebrick-2,stonebrick-2,stone-5,stone-6,cobblestone
rule4=0,100,stonebrick-0,stonebrick-2,stonebrick-2,stonebrick-1,stonebrick-1,cobblestone
rule5=0,100,stonebrick-0,stonebrick-1,stonebrick-2,stone-5,stone-5,stone-6
rule6=0,100,stonebrick-0,stonebrick-0,stonebrick-2
rule7=0,100,minecraft:stone_brick_stairs-2
rule8=0,100,minecraft:stone-5
rule9=0,100,stonebrick-0,stonebrick-0,stonebrick-0,stonebrick-0,stonebrick-1,stonebrick-2,stonebrick-2,stone-5,stone-6,cobblestone,gravel
rule10=0,100,minecraft:stone_brick_stairs-3

layer
1,1,1,2,3,3,3,3,2,1
1,1,1,3,4,4,4,4,3,1
2,3,3,2,4,5,5,4,3,1
3,4,4,4,5,6,5,4,2,2
3,4,5,5,5,6,6,5,4,3
3,4,5,6,6,6,5,5,4,3
3,4,4,5,5,5,4,4,4,3
3,4,4,4,4,4,2,3,3,2
2,3,3,3,3,3,2,3,3,7
3,3,3,3,3,3,3,3,3,7
endlayer

layer
1,1,1,8,9,9,9,9,8,1
1,1,1,9,1,1,1,1,9,1
8,9,9,8,1,1,1,1,9,1
9,1,1,1,1,1,1,1,8,8
9,1,1,1,1,1,1,1,1,9
9,1,1,1,1,1,1,1,1,9
9,1,1,1,1,1,1,1,1,9
9,1,1,1,1,1,8,9,9,8
8,9,9,9,9,9,8,9,7,1
9,9,9,9,9,9,9,9,7,1
endlayer

layer
1,1,1,2,9,9,9,9,2,1
1,1,1,9,1,1,1,1,9,1
2,9,9,2,1,1,1,1,9,1
9,1,1,1,1,1,1,1,2,2
9,1,1,1,1,1,1,1,1,9
9,1,1,1,1,1,1,1,1,9
9,1,1,1,1,1,1,1,1,9
9,1,1,1,1,1,2,9,9,2
2,9,9,9,9,9,2,7,1,1
10,9,9,9,9,9,9,7,1,1
endlayer

layer
1,1,1,8,9,9,9,9,8,1
1,1,1,9,1,1,1,1,9,1
8,9,9,8,1,1,1,1,9,1
9,1,1,1,1,1,1,1,8,8
9,1,1,1,1,1,1,1,1,9
9,1,1,1,1,1,1,1,1,9
9,1,1,1,1,1,1,1,1,9
9,1,1,1,1,1,8,9,9,8
8,9,9,9,9,9,8,1,1,1
1,10,9,9,9,9,7,1,1,1
endlayer

layer
1,1,1,2,9,9,9,9,2,1
1,1,1,9,1,1,1,1,9,1
2,9,9,2,1,1,1,1,9,1
9,1,1,1,1,1,1,1,2,2
9,1,1,1,1,1,1,1,1,9
9,1,1,1,1,1,1,1,1,9
9,1,1,1,1,1,1,1,1,9
9,1,1,1,1,1,2,9,9,2
2,9,9,9,9,9,2,1,1,1
1,1,10,9,9,7,1,1,1,1
endlayer

