
# Created by Ruins mod version 16.7 Ingame Parser
# authoring Player: lafuller

weight=1
embed_into_distance=4
acceptable_target_blocks=
unacceptable_target_blocks=flowing_water,water,flowing_lava,lava,ice,bedrock,netherrack,nether_brick,nether_brick_fence,soul_sand,quartz_ore,end_stone,obsidian,iron_bars,cloud,flesh,ash_block,slime_grass,slime_congealed,slime_dirt
biomesToSpawnIn=plains,forest,prarie,meadow,tundra,brushland,shrubland,woodland,woodlands,birch_forestlavender_fields,flower_field,sunflower_plains,ice_flats,ice_plains
dimensions=13,11,11
allowable_overhang=0
max_leveling=4
leveling_buffer=-1
preserve_water=0
preserve_lava=0

rule1=0,100,preserveBlock
rule2=0,100,minecraft:stone_brick_stairs-2
rule3=0,100,stonebrick-0,stonebrick-0,stonebrick-0,stonebrick-0,stonebrick-1,stonebrick-2,stonebrick-2,stone-5,stone-6,cobblestone
rule4=0,100,minecraft:stone-6
rule5=0,100,minecraft:dirt-0
rule6=0,100,minecraft:stone_brick_stairs-1
rule7=0,100,minecraft:stone_brick_stairs-0
rule8=0,100,minecraft:stone_brick_stairs-3
rule9=0,100,air
rule10=0,100,stonebrick-0,stonebrick-0,stonebrick-0,stonebrick-0,stonebrick-1,stonebrick-2,stonebrick-2,stone-5,stone-6,cobblestone,gravel
rule11=0,100,minecraft:stone-5
rule12=0,100,minecraft:stone_brick_stairs-7
rule13=0,100,minecraft:stone_brick_stairs-4
rule14=0,100,minecraft:stone_brick_stairs-6
rule15=0,100,minecraft:planks-0
rule16=0,100,minecraft:planks-1
rule17=0,100,minecraft:oak_stairs-2
rule18=0,100,minecraft:log-0
rule19=0,100,minecraft:oak_stairs-0
rule20=0,100,bookshelf,hay_block,ChestGenHook:chests/spawn_bonus_chest:5-2,ChestGenHook:chests/village_blacksmith:5-2,ChestGenHook:chests/simple_dungeon:5-2,ChestGenHook:chests/abandoned_mineshaft:5-2,ChestGenHook:chests/stronghold_library:5-2,ChestGenHook:chests/stronghold_corridor:5-2,ChestGenHook:chests/stronghold_crossing:5-2,ChestGenHook:chests/igloo_chest:5-2
rule21=0,100,minecraft:oak_stairs-3
rule22=0,100,minecraft:fence-0
rule23=0,100,minecraft:cauldron-0
rule24=0,100,minecraft:oak_stairs-1
rule25=0,100,minecraft:jungle_door-2
rule26=0,100,IInventory;minecraft:furnace;minecraft:coal#3#0#1-4
rule27=0,100,minecraft:oak_stairs-5
rule28=0,100,minecraft:jungle_door-8
rule29=0,100,minecraft:wooden_slab-13
rule30=0,100,minecraft:spruce_stairs-6
rule31=0,100,minecraft:spruce_stairs-4
rule32=0,100,minecraft:dark_oak_stairs-7
rule33=0,100,minecraft:dark_oak_stairs-6
rule34=0,100,minecraft:spruce_stairs-7
rule35=0,100,minecraft:dark_oak_stairs-2
rule36=0,100,minecraft:cobblestone_wall-0
rule37=0,100,minecraft:dark_oak_stairs-1
rule38=0,100,minecraft:stone_brick_stairs-5
rule39=0,100,minecraft:dark_oak_stairs-5
rule40=0,100,minecraft:spruce_stairs-5
rule41=0,100,minecraft:spruce_fence_gate-1
rule42=0,100,minecraft:wooden_slab-5
rule43=0,100,minecraft:planks-5
rule44=0,100,minecraft:dark_oak_stairs-0
rule45=0,100,minecraft:dark_oak_stairs-3
rule46=0,100,minecraft:dark_oak_fence-0

layer
4,1,4,1,4,1,4,3,2,1,1
3,3,3,4,3,3,4,3,2,1,1
3,3,5,5,5,5,5,3,2,1,1
6,4,5,5,5,5,5,5,4,3,1
1,3,5,5,5,5,5,5,5,3,1
1,3,5,5,5,5,5,5,5,3,1
1,3,5,5,5,5,5,5,5,3,1
1,3,4,3,3,5,5,5,5,3,7
1,8,3,3,3,5,5,5,4,3,3
1,8,3,3,3,4,3,3,3,3,3
1,8,3,4,1,4,1,4,1,4,3
endlayer

layer
10,1,10,1,10,1,10,2,1,1,1
10,10,10,11,10,10,11,10,1,1,1
6,10,5,5,5,5,5,10,1,1,1
1,11,5,5,5,5,5,5,11,10,1
1,10,5,5,5,5,5,5,5,10,1
1,10,5,5,5,5,5,5,5,10,1
1,10,5,5,5,5,5,5,5,10,1
1,10,11,10,10,5,5,5,5,10,1
1,1,8,10,10,5,5,5,11,10,7
1,1,8,10,10,11,10,10,10,10,2
1,1,8,10,1,10,1,10,1,10,2
endlayer

layer
8,14,10,13,10,12,2,1,1,1,1
6,10,10,4,10,10,4,10,1,1,1
1,10,5,5,5,5,5,10,1,1,1
1,4,5,5,5,5,5,5,4,10,1
1,10,5,5,5,5,5,5,5,10,1
1,10,5,5,5,5,5,5,5,10,1
1,10,5,5,5,5,5,5,5,10,1
1,10,4,10,10,5,5,5,5,10,1
1,1,1,10,10,5,5,5,4,10,1
1,1,1,8,10,4,10,10,10,2,1
1,1,1,8,14,10,1,10,12,2,1
endlayer

layer
1,8,10,10,10,2,1,1,1,1,1
1,8,10,11,10,10,11,10,1,1,1
1,10,5,5,5,5,5,10,1,1,1
1,11,5,5,5,5,5,5,11,10,1
1,10,5,5,5,5,5,5,5,10,1
1,10,5,5,5,5,5,5,5,10,1
1,10,5,5,5,5,5,5,5,10,1
1,10,11,10,10,5,5,5,5,10,1
1,1,1,10,10,5,5,5,11,10,1
1,1,1,1,8,11,10,10,2,1,1
1,1,1,1,8,10,10,10,2,1,1
endlayer

layer
1,1,1,1,1,1,1,1,1,1,1
1,1,3,4,3,3,4,3,1,1,1
1,3,15,15,15,15,15,3,1,1,1
1,4,15,15,16,16,15,15,4,3,1
1,3,15,16,15,15,16,15,15,3,1
1,3,15,16,16,15,15,16,15,3,1
1,3,15,15,15,16,15,16,15,3,1
1,3,4,10,10,15,16,16,15,3,1
1,1,1,10,10,15,15,15,4,3,1
1,1,1,1,1,4,15,10,1,1,1
1,1,1,1,1,8,10,2,1,1,1
endlayer

layer
1,1,1,1,1,1,1,1,1,1,1
1,1,19,18,19,19,18,17,1,1,1
1,21,20,9,9,9,9,19,1,1,1
1,18,9,9,9,9,9,9,18,22,1
1,21,9,9,9,9,9,9,9,17,1
1,21,9,9,9,9,9,9,9,17,1
1,21,9,9,9,9,9,9,9,17,1
1,22,18,10,23,9,9,9,9,17,1
1,1,1,6,8,9,9,9,18,22,1
1,1,1,1,1,18,25,24,1,1,1
1,1,1,1,1,1,9,1,1,1,1
endlayer

layer
1,1,1,1,1,1,1,1,1,1,1
1,1,22,18,9,9,18,22,1,1,1
1,22,9,9,9,9,9,22,1,1,1
1,18,9,9,9,9,9,9,18,22,1
1,22,9,9,9,9,9,9,9,9,1
1,9,9,9,9,9,9,9,9,22,1
1,22,9,9,9,9,9,9,9,9,1
1,22,18,13,26,9,9,9,9,22,1
1,1,1,6,12,9,9,9,18,22,1
1,1,1,1,1,18,28,27,1,1,1
1,1,1,1,1,1,9,1,1,1,1
endlayer

layer
1,1,1,1,1,1,1,29,1,1,1
1,32,31,18,31,31,18,30,29,1,1
1,34,9,9,9,9,9,31,33,1,1
1,18,9,9,9,9,9,9,18,35,1
1,34,9,9,9,9,9,9,9,30,1
1,34,9,9,9,9,9,9,9,30,1
1,34,9,9,9,9,9,9,9,30,1
1,37,18,7,36,9,9,9,9,30,1
1,1,1,38,13,9,9,9,18,37,1
1,1,1,29,29,18,41,40,39,1,1
1,1,1,1,1,1,9,1,1,1,1
endlayer

layer
1,1,42,33,29,29,42,1,1,1,1
1,1,44,18,43,43,18,35,1,1,1
42,44,40,40,40,40,40,43,44,1,1
29,18,30,9,9,9,34,40,18,35,1
29,43,30,9,9,9,9,9,34,43,42
29,43,30,9,9,9,9,9,34,43,29
42,43,30,9,9,9,9,9,34,43,29
1,1,18,12,14,9,9,9,34,43,42
1,1,1,6,8,31,31,31,43,1,1
1,1,1,1,37,43,43,43,35,1,1
1,1,1,1,1,42,29,42,1,1,1
endlayer

layer
1,1,1,1,42,1,1,1,1,1,1
1,1,1,44,45,35,44,1,1,1,1
1,1,45,43,43,43,43,35,1,1,1
1,45,43,16,16,16,43,43,42,1,1
42,45,43,16,16,16,16,43,35,1,1
1,45,43,16,16,16,16,16,43,44,1
1,1,43,43,43,16,16,16,43,37,1
1,1,37,37,10,43,16,16,43,35,1
1,1,1,1,1,43,43,43,37,1,1
1,1,1,1,1,37,45,35,1,1,1
1,1,1,1,1,1,1,1,1,1,1
endlayer

layer
1,1,1,1,1,1,1,1,1,1,1
1,1,1,1,1,1,1,1,1,1,1
1,1,1,46,46,46,46,1,1,1,1
1,1,46,42,42,42,46,46,1,1,1
1,1,46,42,42,42,42,46,1,1,1
1,1,46,42,42,42,42,42,46,1,1
1,1,46,46,46,42,42,42,46,1,1
1,1,1,1,36,46,42,42,46,1,1
1,1,1,1,1,46,46,46,1,1,1
1,1,1,1,1,1,1,1,1,1,1
1,1,1,1,1,1,1,1,1,1,1
endlayer

layer
1,1,1,1,1,1,1,1,1,1,1
1,1,1,1,1,1,1,1,1,1,1
1,1,1,1,1,1,1,1,1,1,1
1,1,1,1,1,1,1,1,1,1,1
1,1,1,1,1,1,1,1,1,1,1
1,1,1,1,1,1,1,1,1,1,1
1,1,1,1,1,1,1,1,1,1,1
1,1,1,1,36,1,1,1,1,1,1
1,1,1,1,1,1,1,1,1,1,1
1,1,1,1,1,1,1,1,1,1,1
1,1,1,1,1,1,1,1,1,1,1
endlayer

layer
1,1,1,1,1,1,1,1,1,1,1
1,1,1,1,1,1,1,1,1,1,1
1,1,1,1,1,1,1,1,1,1,1
1,1,1,1,1,1,1,1,1,1,1
1,1,1,1,1,1,1,1,1,1,1
1,1,1,1,1,1,1,1,1,1,1
1,1,1,1,1,1,1,1,1,1,1
1,1,1,1,36,1,1,1,1,1,1
1,1,1,1,1,1,1,1,1,1,1
1,1,1,1,1,1,1,1,1,1,1
1,1,1,1,1,1,1,1,1,1,1
endlayer

