
# Created by Ruins mod version 16.7 Ingame Parser
# authoring Player: lafuller

weight=1
embed_into_distance=4
acceptable_target_blocks=
unacceptable_target_blocks=flowing_water,water,flowing_lava,lava,ice,bedrock,netherrack,nether_brick,nether_brick_fence,soul_sand,quartz_ore,end_stone,obsidian,iron_bars,cloud,flesh,ash_block,slime_grass,slime_congealed,slime_dirt
biomesToSpawnIn=plains,forest,prarie,meadow,tundra,brushland,shrubland,woodland,woodlands,birch_forestlavender_fields,flower_field,sunflower_plains,ice_flats,ice_plains
dimensions=20,16,14
allowable_overhang=0
max_leveling=4
leveling_buffer=-1
preserve_water=0
preserve_lava=0

rule1=0,100,preserveBlock
rule2=0,100,minecraft:stone-6
rule3=0,100,stonebrick-0,stonebrick-0,stonebrick-0,stonebrick-0,stonebrick-1,stonebrick-2,stonebrick-2,stone-5,stone-6,cobblestone
rule4=0,100,stonebrick-0,stonebrick-2,stonebrick-1,stonebrick-1,stonebrick-1,cobblestone
rule5=0,100,stonebrick-0,stonebrick-1,stonebrick-2,stonebrick-2,stone-5,stone-5,stone-6,stone-6
rule6=0,100,stonebrick-0,stonebrick-2,stonebrick-0,stonebrick-1,stonebrick-1,cobblestone
rule7=0,100,minecraft:stone_brick_stairs-0
rule8=0,100,air
rule9=0,100,minecraft:stone_brick_stairs-2
rule10=0,100,minecraft:stone-5
rule11=0,100,stonebrick-0,stonebrick-0,stonebrick-0,stonebrick-0,stonebrick-1,stonebrick-2,stonebrick-2,stone-5,stone-6,cobblestone,gravel
rule12=0,100,minecraft:cobblestone_wall-0
rule13=0,100,minecraft:log-0
rule14=0,100,minecraft:wooden_slab-9
rule15=0,100,minecraft:web-0,air,air,air
rule16=0,100,minecraft:ladder-2
rule17=0,100,bookshelf,hay_block,ChestGenHook:chests/spawn_bonus_chest:5-3,ChestGenHook:chests/village_blacksmith:5-3,ChestGenHook:chests/simple_dungeon:5-3,ChestGenHook:chests/abandoned_mineshaft:5-3,ChestGenHook:chests/stronghold_library:5-3,ChestGenHook:chests/stronghold_corridor:5-3,ChestGenHook:chests/stronghold_crossing:5-2,ChestGenHook:chests/igloo_chest:5-3
rule18=0,100,minecraft:planks-1
rule19=0,100,minecraft:stone_brick_stairs-3
rule20=0,100,minecraft:stone_brick_stairs-1
rule21=0,100,minecraft:stained_hardened_clay-8
rule22=0,100,minecraft:stained_hardened_clay-6
rule23=0,100,minecraft:hardened_clay-0
rule24=0,100,minecraft:stone-4
rule25=0,100,minecraft:mycelium-0
rule26=0,100,minecraft:oak_stairs-0
rule27=0,100,minecraft:oak_stairs-1
rule28=0,100,minecraft:oak_stairs-3
rule29=0,100,minecraft:oak_stairs-2
rule30=0,100,minecraft:spruce_stairs-4
rule31=0,100,minecraft:planks-0
rule32=0,100,minecraft:fence-0
rule33=0,100,minecraft:spruce_stairs-5
rule34=0,100,minecraft:spruce_fence-0
rule35=0,100,minecraft:double_stone_slab-8
rule36=0,100,minecraft:jungle_door-2
rule37=0,100,minecraft:oak_stairs-7
rule38=0,100,minecraft:oak_stairs-5
rule39=0,100,minecraft:oak_stairs-4
rule40=0,100,minecraft:furnace-3
rule41=0,100,minecraft:jungle_door-9
rule42=0,100,minecraft:jungle_door-8
rule43=0,100,minecraft:stone_brick_stairs-6
rule44=0,100,minecraft:wooden_slab-13
rule45=0,100,minecraft:dark_oak_stairs-0
rule46=0,100,minecraft:dark_oak_stairs-7
rule47=0,100,minecraft:planks-5
rule48=0,100,minecraft:spruce_stairs-6
rule49=0,100,minecraft:wooden_slab-0
rule50=0,100,minecraft:dark_oak_stairs-1
rule51=0,100,minecraft:oak_stairs-6
rule52=0,100,minecraft:spruce_stairs-7
rule53=0,100,minecraft:stone_slab-13
rule54=0,100,minecraft:spruce_fence_gate-1
rule55=0,100,minecraft:dark_oak_stairs-3
rule56=0,100,minecraft:wooden_slab-5
rule57=0,100,minecraft:double_wooden_slab-5
rule58=0,100,minecraft:dark_oak_stairs-2
rule59=0,100,minecraft:spruce_stairs-0
rule60=0,100,minecraft:spruce_stairs-3
rule61=0,100,minecraft:spruce_stairs-2
rule62=0,100,minecraft:stone_brick_stairs-7
rule63=0,100,minecraft:stone_brick_stairs-5
rule64=0,100,minecraft:log-11
rule65=0,100,minecraft:log-7
rule66=0,100,minecraft:trapdoor-13
rule67=0,100,minecraft:stone_brick_stairs-4
rule68=0,100,minecraft:spruce_fence_gate-6
rule69=0,100,minecraft:dark_oak_fence-0
rule70=0,100,minecraft:jungle_door-3
rule71=0,100,minecraft:spruce_fence_gate-4
rule72=0,100,minecraft:spruce_stairs-1
rule73=0,100,minecraft:carpet-7
rule74=0,100,minecraft:furnace-4
rule75=0,100,minecraft:dark_oak_stairs-5
rule76=0,100,minecraft:spruce_fence_gate-2
rule77=0,100,minecraft:iron_bars-0
rule78=0,100,minecraft:stone_slab-0

layer
1,1,1,1,1,1,1,1,1,1,1,1,1,1
1,1,1,1,1,1,1,1,3,3,3,2,1,1
1,1,1,1,1,1,1,2,2,4,4,2,3,1
1,1,1,1,2,3,3,4,4,4,4,4,3,1
1,1,1,3,2,4,4,4,5,5,5,4,3,1
1,1,1,3,3,4,5,5,6,6,5,4,3,1
1,1,1,3,4,5,6,6,6,5,4,2,3,1
1,1,2,3,4,5,5,6,5,5,4,2,1,1
1,3,2,4,5,6,5,6,5,4,4,3,1,1
1,3,4,5,6,6,6,6,5,4,2,3,1,1
7,3,4,5,5,6,6,5,5,4,3,3,3,1
2,3,4,4,5,5,5,5,4,3,3,3,3,1
1,3,2,4,4,2,4,4,4,3,3,3,3,1
2,3,3,3,3,3,2,4,4,3,3,3,3,1
1,3,3,3,3,3,2,3,3,3,1,1,1,1
2,1,2,1,2,1,2,3,9,1,1,1,1,8
endlayer

layer
1,1,1,1,1,1,1,1,1,1,1,1,1,1
1,1,1,1,1,1,1,1,11,12,11,10,1,1
1,1,1,1,1,1,1,10,13,14,14,13,11,1
1,1,1,1,10,11,11,15,8,8,8,14,12,1
1,1,1,11,13,16,8,8,8,8,8,14,11,1
1,1,1,11,13,16,8,8,8,8,8,14,12,1
1,1,1,12,15,8,8,8,8,8,8,13,11,1
1,1,10,11,8,8,8,8,8,8,8,10,1,1
1,11,13,8,8,8,8,8,8,8,15,12,1,1
1,11,14,8,8,8,8,8,8,8,13,11,1,1
1,12,14,8,8,18,8,8,8,17,11,11,11,1
7,11,14,8,8,18,8,8,8,11,11,11,11,1
11,11,13,14,14,13,8,8,8,11,11,11,11,1
11,11,11,11,11,11,13,14,14,11,11,11,11,1
11,11,11,11,11,11,10,11,12,11,1,1,1,1
11,11,11,11,11,11,11,9,1,1,1,1,1,1
endlayer

layer
1,1,1,1,1,1,1,1,1,1,1,1,1,1
1,1,1,1,1,1,1,1,11,12,11,2,1,1
1,1,1,1,1,1,1,2,13,15,15,13,11,1
1,1,1,1,2,11,11,15,15,8,8,15,12,1
1,1,1,11,13,16,8,8,8,8,8,8,11,1
1,1,1,11,13,16,8,8,8,8,8,15,12,1
1,1,1,12,15,8,8,8,8,8,8,13,11,1
1,1,2,11,15,8,8,8,8,8,15,2,1,1
1,11,13,15,8,8,8,8,8,8,15,12,1,1
1,11,15,8,8,8,8,8,8,8,13,11,1,1
1,12,8,8,8,8,8,8,8,15,11,11,11,1
1,11,15,8,8,8,8,8,8,11,11,11,11,1
7,11,13,15,15,13,15,8,8,11,11,11,11,1
19,11,11,11,11,11,13,15,15,11,11,11,11,1
19,11,11,11,11,11,2,11,12,11,1,1,1,1
19,20,20,20,20,20,9,1,1,1,1,1,1,1
endlayer

layer
1,1,1,1,1,1,1,1,1,1,1,1,1,1
1,1,1,1,1,1,1,1,11,12,11,10,1,1
1,1,1,1,1,1,1,10,13,15,15,13,11,1
1,1,1,1,10,11,11,15,15,8,15,15,12,1
1,1,1,11,13,16,8,8,8,8,8,15,11,1
1,1,1,11,13,16,8,8,8,8,8,15,12,1
1,1,1,12,15,15,8,8,8,8,15,13,11,1
1,1,10,11,15,8,8,8,8,8,15,10,1,1
1,11,13,15,15,8,8,8,8,15,15,12,1,1
1,11,15,15,8,8,8,8,8,15,13,11,1,1
1,12,15,8,8,14,8,8,15,15,11,11,11,1
1,11,15,15,8,14,15,8,8,11,11,11,11,1
1,19,13,15,15,13,15,8,15,11,11,11,11,1
1,19,11,11,11,11,13,15,15,11,11,11,11,1
1,19,20,20,20,20,10,11,12,11,1,1,1,1
1,1,1,1,1,1,1,1,1,1,1,1,1,1
endlayer

layer
1,1,1,1,1,1,1,1,1,1,1,1,1,1
1,1,1,1,1,1,1,1,11,11,11,2,1,1
1,1,1,1,1,1,1,2,21,21,21,21,11,1
1,1,1,1,2,11,11,21,21,22,22,21,11,1
1,1,1,11,13,16,23,23,22,23,22,21,11,1
1,1,1,11,13,16,23,23,22,23,22,21,11,1
1,1,1,11,21,21,21,23,22,22,23,21,11,1
1,1,2,11,21,21,21,23,23,23,21,2,1,1
1,11,21,21,22,23,23,23,21,21,23,11,1,1
1,11,21,22,23,22,23,21,2,2,24,11,1,1
1,11,21,22,22,22,21,2,24,24,2,11,11,1
1,11,21,21,23,23,21,2,24,2,25,25,11,1
1,1,2,23,23,11,23,24,2,11,25,25,11,1
1,1,19,20,20,20,11,11,11,11,11,11,11,1
1,1,1,1,1,1,2,11,11,11,1,1,1,1
1,1,1,1,1,1,1,1,1,1,1,1,1,1
endlayer

layer
1,1,1,1,1,1,1,1,1,1,1,1,1,1
1,1,1,1,1,1,1,1,26,26,26,26,1,1
1,1,1,1,1,1,1,28,8,8,8,13,27,1
1,1,1,1,13,26,26,13,8,8,8,30,29,1
1,1,1,32,31,16,8,8,8,8,8,8,29,1
1,1,1,28,31,16,8,8,8,8,8,8,29,1
1,1,1,28,31,31,13,8,8,8,8,33,29,1
1,34,13,29,27,29,8,8,8,8,8,13,1,1
1,27,30,8,8,8,8,8,8,8,35,29,1,1
1,28,8,8,8,8,8,8,8,8,35,9,1,1
1,28,8,8,8,8,8,8,8,8,8,11,7,1
1,26,33,8,8,8,8,8,8,8,8,8,11,1
1,34,13,36,36,13,35,8,8,11,8,8,11,1
1,1,8,8,8,8,13,35,35,11,11,11,20,1
1,1,1,1,1,1,34,27,27,13,1,1,1,1
1,1,1,1,1,1,1,1,1,1,1,1,1,1
endlayer

layer
1,1,1,1,1,1,1,1,1,1,1,1,1,1
1,1,1,1,1,1,1,1,32,8,32,37,1,1
1,1,1,1,1,1,1,32,8,8,8,13,38,1
1,1,1,1,13,26,39,13,8,8,8,8,32,1
1,1,1,32,31,8,8,8,8,8,8,8,8,1
1,1,1,28,31,8,8,8,8,8,8,8,32,1
1,1,1,37,27,27,13,8,8,8,8,8,39,1
1,34,13,27,8,8,8,8,8,8,8,13,1,1
1,38,8,8,8,8,8,8,8,8,8,32,1,1
1,32,8,8,8,8,8,8,8,8,8,12,1,1
1,32,8,8,8,8,8,8,8,8,8,40,9,1
1,39,8,8,8,8,8,8,8,8,8,8,11,1
1,34,13,42,41,13,8,8,8,12,8,8,11,1
1,1,8,8,8,8,13,8,8,11,11,11,43,1
1,1,1,1,1,1,34,8,32,13,1,1,1,1
1,1,1,1,1,1,1,1,1,1,1,1,1,1
endlayer

layer
1,1,1,1,1,1,1,1,44,1,1,44,1,1
1,1,1,1,1,1,1,46,18,18,18,18,45,1
1,1,1,1,1,1,46,47,8,8,8,13,18,44
1,1,1,1,13,26,31,13,8,8,8,8,48,1
1,1,1,37,31,31,8,8,8,8,8,8,48,1
1,1,1,37,49,27,8,8,8,8,8,8,48,1
1,1,1,37,8,8,13,8,8,8,8,8,18,44
1,45,13,51,8,8,8,8,8,8,8,13,50,1
44,18,8,8,8,8,8,8,8,8,8,48,1,1
1,52,8,8,8,8,8,8,8,8,8,43,1,1
1,52,8,8,8,8,8,8,8,8,8,11,7,1
44,18,8,8,8,8,8,8,8,8,53,8,11,1
1,50,13,54,54,13,8,8,8,12,8,8,11,1
1,1,8,8,8,8,13,1,1,11,11,11,20,1
1,1,1,1,1,1,55,33,33,13,44,1,1,1
1,1,1,1,1,1,1,44,44,44,1,1,1,1
endlayer

layer
1,1,1,1,1,1,1,1,1,45,56,1,1,1
1,1,1,1,1,1,1,1,1,47,57,45,1,1
1,1,1,1,1,1,1,45,33,33,33,13,58,1
1,1,1,34,13,59,59,13,8,8,8,52,57,56
1,1,1,60,8,8,28,8,8,8,8,52,57,58
1,1,1,60,8,8,28,8,8,8,8,52,57,56
1,1,45,60,8,8,13,8,8,8,8,52,58,1
1,45,13,33,8,8,8,8,8,8,8,13,50,1
1,55,48,8,8,8,8,8,8,8,8,61,1,1
55,57,48,8,8,8,8,8,8,8,8,9,1,1
56,57,48,8,8,8,8,8,8,8,62,11,9,1
1,55,48,8,8,8,8,8,8,8,11,63,11,1
1,50,13,64,64,13,8,8,8,11,43,8,11,1
1,1,55,44,44,50,13,30,30,11,11,11,9,1
1,1,1,1,1,1,55,50,47,50,58,1,1,1
1,1,1,1,1,1,1,1,1,1,1,1,1,1
endlayer

layer
1,1,1,1,1,1,1,1,1,1,1,1,1,1
1,1,1,1,1,1,1,1,1,45,45,1,1,1
1,1,1,1,1,1,1,1,55,64,64,47,1,1
1,1,66,64,13,64,64,64,64,64,64,65,58,1
1,1,1,65,8,8,8,60,31,31,18,65,58,1
1,1,1,65,8,8,8,60,31,31,18,65,58,1
1,1,1,65,8,8,13,59,18,18,18,65,50,1
1,1,55,64,64,64,65,64,64,64,64,13,1,1
1,45,47,18,18,18,65,18,31,31,18,65,1,1
1,55,47,18,18,18,65,18,31,31,18,65,1,1
1,55,47,18,18,18,65,18,31,18,18,65,1,1
1,50,47,47,47,47,65,18,18,18,11,11,67,1
1,1,55,47,58,50,18,64,64,18,11,8,11,1
1,1,1,50,1,1,50,55,47,47,63,11,63,1
1,1,1,1,1,1,1,55,50,58,1,1,1,1
1,1,1,1,1,1,1,1,1,1,1,1,1,1
endlayer

layer
1,1,1,1,1,1,1,1,1,1,1,1,1,1
1,1,1,1,1,1,1,1,1,1,1,1,1,1
1,1,1,1,1,1,37,39,39,26,26,1,1,1
1,1,1,26,13,26,13,8,8,8,13,29,1,1
1,1,1,28,8,8,8,8,8,8,68,29,1,1
1,1,1,26,8,8,8,8,8,8,8,29,1,1
1,1,1,13,8,8,13,8,8,8,8,29,1,1
1,1,69,8,27,38,28,8,8,8,8,13,1,1
1,1,69,8,8,8,13,8,8,8,8,29,1,1
1,1,69,8,8,8,70,8,8,8,8,29,1,1
1,1,69,8,8,8,28,8,8,8,8,29,1,1
1,1,69,69,8,8,37,71,8,8,67,11,43,1
1,1,1,69,69,69,72,27,27,13,11,8,11,1
1,1,1,1,1,1,69,69,56,1,19,11,9,1
1,1,1,1,1,1,1,1,1,1,1,1,1,1
1,1,1,1,1,1,1,1,1,1,1,1,1,1
endlayer

layer
1,1,1,1,1,1,1,1,1,1,1,1,1,1
1,1,1,1,1,1,1,1,1,1,1,1,1,1
1,1,1,1,1,1,32,32,8,32,32,1,1,1
1,1,1,37,13,39,13,8,8,8,13,32,1,1
1,1,1,38,8,8,8,8,8,8,73,32,1,1
1,1,1,39,8,8,8,8,8,8,8,8,1,1
1,1,1,13,8,8,13,8,8,8,8,32,1,1
1,1,1,8,38,27,37,8,8,8,8,13,1,1
1,1,1,8,8,8,13,8,8,8,8,32,1,1
1,1,1,8,8,8,42,8,8,8,8,8,1,1
1,1,1,8,8,8,37,8,8,8,8,32,1,1
1,1,1,8,8,8,28,73,8,8,74,11,7,1
1,1,1,1,8,8,52,32,8,13,11,8,11,1
1,1,1,1,1,1,1,1,1,1,20,11,20,1
1,1,1,1,1,1,1,1,1,1,1,1,1,1
1,1,1,1,1,1,1,1,1,1,1,1,1,1
endlayer

layer
1,1,1,1,1,1,1,1,1,1,1,1,1,1
1,1,1,1,1,1,44,1,1,1,44,1,1,1
1,1,44,44,1,44,52,30,30,30,30,45,1,1
1,1,44,18,13,33,13,8,8,8,13,48,44,1
1,1,1,52,8,8,8,8,8,8,8,48,1,1
1,1,1,52,8,8,8,8,8,8,8,48,1,1
1,1,1,13,8,8,13,8,8,8,8,48,1,1
1,1,44,44,72,30,61,8,8,8,8,13,44,1
1,1,1,8,8,75,13,8,8,8,8,48,1,1
1,1,1,8,8,8,76,8,8,8,8,48,1,1
1,1,1,8,8,8,60,8,8,8,8,48,44,1
1,1,1,8,8,8,60,8,8,8,7,11,9,1
1,1,1,1,8,44,47,33,33,13,43,8,11,1
1,1,1,1,1,1,44,1,1,46,62,11,9,1
1,1,1,1,1,1,1,1,1,1,1,1,1,1
1,1,1,1,1,1,1,1,1,1,1,1,1,1
endlayer

layer
1,1,1,1,1,1,1,1,1,1,1,1,1,1
1,1,1,1,1,1,1,55,45,58,1,1,1,1
1,1,1,56,55,45,55,64,64,64,58,1,1,1
1,1,56,45,13,18,13,33,14,33,13,45,1,1
1,1,55,47,48,14,14,8,8,8,52,65,56,1
1,1,55,47,48,14,14,8,8,8,14,65,58,1
1,1,56,47,48,30,13,8,8,8,14,65,56,1
1,1,1,50,47,47,65,64,64,64,64,64,64,69
1,1,1,56,55,50,65,48,8,8,14,65,56,1
1,1,1,8,8,55,65,14,8,8,14,65,58,1
1,1,1,8,8,55,65,30,8,8,52,65,56,1
1,1,1,1,8,50,65,48,30,30,18,11,67,1
1,1,1,1,1,1,50,47,18,13,11,8,11,1
1,1,1,1,1,1,1,50,50,58,63,11,1,1
1,1,1,1,1,1,1,1,1,1,1,1,1,1
1,1,1,1,1,1,1,1,1,1,1,1,1,1
endlayer

layer
1,1,1,1,1,1,1,1,1,1,1,1,1,1
1,1,1,1,1,1,1,1,1,1,1,1,1,1
1,1,1,1,1,1,1,56,58,45,1,1,1,1
1,1,1,1,56,58,47,47,47,47,45,1,1,1
1,1,1,45,47,47,47,18,18,47,47,58,1,1
1,1,1,50,47,47,47,18,18,18,47,45,1,1
1,1,1,55,47,47,47,18,18,18,47,50,1,1
1,1,1,1,55,55,47,47,47,47,47,58,1,1
1,1,1,1,1,1,50,47,18,18,47,45,1,1
1,1,1,1,1,1,50,47,18,18,47,50,1,1
1,1,1,1,1,1,50,47,18,18,47,58,1,1
1,1,1,1,1,1,56,55,47,47,47,11,7,1
1,1,1,1,1,1,1,55,58,50,11,8,11,1
1,1,1,1,1,1,1,1,1,1,19,11,1,1
1,1,1,1,1,1,1,1,1,1,1,1,1,1
1,1,1,1,1,1,1,1,1,1,1,1,1,1
endlayer

layer
1,1,1,1,1,1,1,1,1,1,1,1,1,1
1,1,1,1,1,1,1,1,1,1,1,1,1,1
1,1,1,1,1,1,1,1,1,1,1,1,1,1
1,1,1,1,1,1,69,69,69,69,1,1,1,1
1,1,1,1,69,69,69,56,56,69,69,1,1,1
1,1,1,1,69,56,56,56,56,56,69,1,1,1
1,1,1,1,69,69,69,56,56,56,69,1,1,1
1,1,1,1,1,1,69,69,56,56,69,1,1,1
1,1,1,1,1,1,1,69,56,56,69,1,1,1
1,1,1,1,1,1,1,69,56,56,69,1,1,1
1,1,1,1,1,1,1,69,56,56,69,1,1,1
1,1,1,1,1,1,1,1,69,69,69,11,1,1
1,1,1,1,1,1,1,1,1,1,11,8,11,1
1,1,1,1,1,1,1,1,1,1,1,11,1,1
1,1,1,1,1,1,1,1,1,1,1,1,1,1
1,1,1,1,1,1,1,1,1,1,1,1,1,1
endlayer

layer
1,1,1,1,1,1,1,1,1,1,1,1,1,1
1,1,1,1,1,1,1,1,1,1,1,1,1,1
1,1,1,1,1,1,1,1,1,1,1,1,1,1
1,1,1,1,1,1,1,1,1,1,1,1,1,1
1,1,1,1,1,1,1,1,1,1,1,1,1,1
1,1,1,1,1,1,1,1,1,1,1,1,1,1
1,1,1,1,1,1,1,1,1,1,1,1,1,1
1,1,1,1,1,1,1,1,1,1,1,1,1,1
1,1,1,1,1,1,1,1,1,1,1,1,1,1
1,1,1,1,1,1,1,1,1,1,1,1,1,1
1,1,1,1,1,1,1,1,1,1,1,1,1,1
1,1,1,1,1,1,1,1,1,1,1,11,1,1
1,1,1,1,1,1,1,1,1,1,11,8,11,1
1,1,1,1,1,1,1,1,1,1,1,63,1,1
1,1,1,1,1,1,1,1,1,1,1,1,1,1
1,1,1,1,1,1,1,1,1,1,1,1,1,1
endlayer

layer
1,1,1,1,1,1,1,1,1,1,1,1,1,1
1,1,1,1,1,1,1,1,1,1,1,1,1,1
1,1,1,1,1,1,1,1,1,1,1,1,1,1
1,1,1,1,1,1,1,1,1,1,1,1,1,1
1,1,1,1,1,1,1,1,1,1,1,1,1,1
1,1,1,1,1,1,1,1,1,1,1,1,1,1
1,1,1,1,1,1,1,1,1,1,1,1,1,1
1,1,1,1,1,1,1,1,1,1,1,1,1,1
1,1,1,1,1,1,1,1,1,1,1,1,1,1
1,1,1,1,1,1,1,1,1,1,1,1,1,1
1,1,1,1,1,1,1,1,1,1,1,1,1,1
1,1,1,1,1,1,1,1,1,1,1,67,1,1
1,1,1,1,1,1,1,1,1,1,62,8,9,1
1,1,1,1,1,1,1,1,1,1,1,63,1,1
1,1,1,1,1,1,1,1,1,1,1,1,1,1
1,1,1,1,1,1,1,1,1,1,1,1,1,1
endlayer

layer
1,1,1,1,1,1,1,1,1,1,1,1,1,1
1,1,1,1,1,1,1,1,1,1,1,1,1,1
1,1,1,1,1,1,1,1,1,1,1,1,1,1
1,1,1,1,1,1,1,1,1,1,1,1,1,1
1,1,1,1,1,1,1,1,1,1,1,1,1,1
1,1,1,1,1,1,1,1,1,1,1,1,1,1
1,1,1,1,1,1,1,1,1,1,1,1,1,1
1,1,1,1,1,1,1,1,1,1,1,1,1,1
1,1,1,1,1,1,1,1,1,1,1,1,1,1
1,1,1,1,1,1,1,1,1,1,1,1,1,1
1,1,1,1,1,1,1,1,1,1,1,1,1,1
1,1,1,1,1,1,1,1,1,1,1,67,1,1
1,1,1,1,1,1,1,1,1,1,62,77,9,1
1,1,1,1,1,1,1,1,1,1,1,63,1,1
1,1,1,1,1,1,1,1,1,1,1,1,1,1
1,1,1,1,1,1,1,1,1,1,1,1,1,1
endlayer

layer
1,1,1,1,1,1,1,1,1,1,1,1,1,1
1,1,1,1,1,1,1,1,1,1,1,1,1,1
1,1,1,1,1,1,1,1,1,1,1,1,1,1
1,1,1,1,1,1,1,1,1,1,1,1,1,1
1,1,1,1,1,1,1,1,1,1,1,1,1,1
1,1,1,1,1,1,1,1,1,1,1,1,1,1
1,1,1,1,1,1,1,1,1,1,1,1,1,1
1,1,1,1,1,1,1,1,1,1,1,1,1,1
1,1,1,1,1,1,1,1,1,1,1,1,1,1
1,1,1,1,1,1,1,1,1,1,1,1,1,1
1,1,1,1,1,1,1,1,1,1,1,1,1,1
1,1,1,1,1,1,1,1,1,1,1,78,1,1
1,1,1,1,1,1,1,1,1,1,78,8,78,1
1,1,1,1,1,1,1,1,1,1,1,78,1,1
1,1,1,1,1,1,1,1,1,1,1,1,1,1
1,1,1,1,1,1,1,1,1,1,1,1,1,1
endlayer

