
# Created by Ruins mod version 16.7 Ingame Parser
# authoring Player: lafuller

weight=1
embed_into_distance=4
acceptable_target_blocks=
unacceptable_target_blocks=flowing_water,water,flowing_lava,lava,ice,bedrock,netherrack,nether_brick,nether_brick_fence,soul_sand,quartz_ore,gravel,end_stone,obsidian,iron_bars,cloud,flesh,ash_block,slime_grass,slime_congealed,slime_dirt
dimensions=15,12,11
allowable_overhang=0
max_leveling=4
leveling_buffer=-1
preserve_water=0
preserve_lava=0

rule1=0,100,stonebrick-0,stonebrick-1,stonebrick-1,stonebrick-1,stonebrick-2,stonebrick-2,stone-5,stone-5,stone-6,cobblestone,cobblestone
rule2=0,100,minecraft:stone_brick_stairs-3
rule3=0,100,preserveBlock
rule4=0,100,air
rule5=0,100,minecraft:stone-6
rule6=0,100,stonebrick-0,stonebrick-2,stonebrick-1,stonebrick-1,stonebrick-1,cobblestone
rule7=0,100,stonebrick-0,stonebrick-1,stonebrick-2,stonebrick-2,stone-5,stone-5,stone-6,stone-6
rule8=0,100,stonebrick-0,stonebrick-2,stonebrick-0,stonebrick-1,stonebrick-1,cobblestone
rule9=0,100,minecraft:stone_brick_stairs-1
rule10=0,100,stonebrick-0,stonebrick-1,stonebrick-1,stonebrick-1,stonebrick-2,stonebrick-2,stone-5,stone-5,stone-6,cobblestone,cobblestone,gravel
rule11=0,100,minecraft:stone_brick_stairs-6
rule12=0,100,minecraft:stone_brick_stairs-0
rule13=0,100,minecraft:stone-5
rule14=0,100,minecraft:cobblestone_wall-0
rule15=0,100,minecraft:wooden_slab-9
rule16=0,100,minecraft:log-0
rule17=0,100,minecraft:web-0,air,air,air
rule18=0,100,bookshelf,hay_block,ChestGenHook:chests/spawn_bonus_chest:5-4,ChestGenHook:chests/village_blacksmith:4-4,ChestGenHook:chests/simple_dungeon:5-4,ChestGenHook:chests/abandoned_mineshaft:4-4,ChestGenHook:chests/stronghold_library:3-4,ChestGenHook:chests/stronghold_corridor:2-4,ChestGenHook:chests/stronghold_crossing:2-3,ChestGenHook:chests/igloo_chest:4-4
rule19=0,100,minecraft:spruce_stairs-6
rule20=0,100,minecraft:spruce_stairs-0
rule21=0,100,minecraft:wooden_slab-1
rule22=0,100,minecraft:spruce_stairs-4
rule23=0,100,minecraft:spruce_stairs-3
rule24=0,100,minecraft:stone_brick_stairs-5
rule25=0,100,minecraft:stone_brick_stairs-4
rule26=0,100,minecraft:planks-0
rule27=0,100,minecraft:planks-1
rule28=0,100,minecraft:spruce_stairs-1
rule29=0,100,minecraft:log2-1
rule30=0,100,minecraft:oak_stairs-0
rule31=0,100,minecraft:oak_stairs-3
rule32=0,100,minecraft:oak_stairs-1
rule33=0,100,minecraft:trapdoor-8
rule34=0,100,minecraft:stone-3
rule35=0,100,minecraft:stone_brick_stairs-7
rule36=0,100,minecraft:jungle_door-1
rule37=0,100,minecraft:oak_stairs-2
rule38=0,100,minecraft:spruce_fence_gate-3
rule39=0,100,minecraft:spruce_fence-0
rule40=0,100,minecraft:fence-0
rule41=0,100,minecraft:jungle_door-9
rule42=0,100,minecraft:furnace-2
rule43=0,100,minecraft:wooden_slab-13
rule44=0,100,minecraft:trapdoor-11
rule45=0,100,minecraft:spruce_fence_gate-0
rule46=0,100,minecraft:spruce_stairs-7
rule47=0,100,minecraft:spruce_stairs-5
rule48=0,100,minecraft:dark_oak_stairs-2
rule49=0,100,minecraft:dark_oak_stairs-3
rule50=0,100,minecraft:wooden_slab-5
rule51=0,100,minecraft:dark_oak_stairs-7
rule52=0,100,minecraft:dark_oak_stairs-0
rule53=0,100,minecraft:dark_oak_stairs-5
rule54=0,100,minecraft:double_wooden_slab-5
rule55=0,100,minecraft:dark_oak_stairs-1
rule56=0,100,minecraft:dark_oak_stairs-6
rule57=0,100,minecraft:planks-5
rule58=0,100,minecraft:dark_oak_fence-0
rule59=0,100,minecraft:stone_slab-0

layer
3,3,3,3,3,2,1,1,1,1,1
3,3,3,1,1,5,1,1,1,1,3
3,3,5,6,6,6,1,1,1,1,1
3,1,1,6,7,7,6,6,5,1,3
3,1,1,6,7,8,7,6,1,1,3
3,5,6,7,8,8,7,6,1,1,1
3,1,6,7,8,8,8,7,6,5,3
3,1,6,7,7,8,8,7,6,1,3
3,1,6,6,6,7,7,7,6,1,1
3,3,5,1,1,6,6,6,6,5,3
3,3,3,3,3,5,1,1,1,1,1
3,3,3,3,3,3,3,3,3,9,9
endlayer

layer
3,3,3,3,3,3,3,2,10,10,10
3,3,3,10,14,13,12,2,10,10,11
3,3,13,16,15,15,10,10,10,10,1
3,1,10,17,4,4,17,16,13,10,3
3,1,10,4,4,4,4,4,10,10,3
3,13,16,4,4,4,4,4,10,10,1
3,10,15,4,4,4,4,4,17,13,3
3,14,15,4,4,4,4,4,4,10,3
3,10,16,17,4,4,4,16,4,10,1
3,3,13,14,10,21,20,19,18,13,11
3,3,3,3,3,13,10,14,10,9,9
3,3,3,3,3,3,3,3,3,3,3
endlayer

layer
3,3,3,3,3,3,3,3,3,3,3
3,3,3,10,14,5,3,3,2,12,12
3,3,5,16,17,17,10,10,10,10,1
3,1,10,17,4,4,17,16,5,10,3
3,1,10,4,4,4,4,17,10,10,3
3,5,16,17,4,4,4,4,10,10,1
3,10,17,4,4,4,4,4,17,5,3
3,14,17,4,4,4,4,4,4,10,3
3,10,16,17,4,4,4,16,17,10,1
3,3,5,14,10,4,4,23,22,5,9
3,3,3,3,3,5,10,14,10,3,3
3,3,3,3,3,3,3,3,3,3,3
endlayer

layer
3,3,3,3,3,3,3,3,3,3,3
3,3,3,10,14,13,3,3,3,3,3
3,3,13,16,17,17,10,10,12,12,12
3,1,10,17,17,17,17,16,13,10,24
3,1,10,17,17,4,17,17,10,10,25
3,13,16,17,4,4,4,17,10,10,1
3,10,17,4,4,4,4,4,17,13,24
3,14,17,17,4,4,4,17,17,10,25
3,10,16,17,17,4,4,16,17,10,9
3,3,13,14,10,4,4,4,23,13,3
3,3,3,3,3,13,10,14,10,3,3
3,3,3,3,3,3,3,3,3,3,3
endlayer

layer
3,3,3,3,3,3,3,3,3,3,3
3,3,3,10,10,5,3,3,3,3,3
3,3,5,26,26,26,10,10,3,3,3
3,1,10,26,27,27,26,26,5,12,12
3,1,10,26,27,26,27,26,5,1,1
3,5,26,27,26,26,27,26,10,1,1
3,10,26,27,26,26,26,27,26,5,1
3,10,26,27,27,26,26,27,26,10,9
3,10,26,26,26,47,47,16,28,10,3
3,3,5,10,10,4,4,4,4,5,3
3,3,3,3,3,5,10,10,10,3,3
3,3,3,3,3,3,3,3,3,3,3
endlayer

layer
3,3,3,3,3,3,3,3,3,3,3
3,3,4,30,30,29,3,3,3,3,3
3,3,29,34,34,33,32,31,4,3,3
3,35,10,4,4,4,4,4,29,3,3
3,10,5,4,4,4,4,4,36,4,3
3,29,34,4,4,4,4,4,26,4,3
3,31,4,4,4,4,4,4,4,29,3
3,31,4,4,4,4,4,4,4,37,3
3,31,4,4,4,39,38,16,4,37,3
3,4,29,32,31,4,4,4,4,29,3
3,3,3,3,3,29,32,32,32,4,3
3,3,3,3,3,3,3,3,3,3,3
endlayer

layer
3,3,3,3,3,3,3,3,3,3,3
3,3,40,40,4,29,3,3,3,3,3
3,3,29,4,4,4,4,40,40,3,3
3,12,10,4,4,4,4,4,29,3,3
3,35,42,4,4,4,4,4,41,4,3
3,29,4,4,4,4,4,4,26,4,3
3,40,4,4,4,4,4,4,4,29,3
3,4,4,4,4,4,4,4,4,3,3
3,40,4,4,4,4,4,16,4,40,3
3,40,29,4,40,4,4,4,4,29,3
3,3,3,3,3,29,40,4,40,40,3
3,3,3,3,3,3,3,3,3,3,3
endlayer

layer
3,3,3,3,3,3,3,3,3,3,3
3,43,22,22,22,29,3,3,3,3,3
3,3,29,44,44,44,19,22,19,43,3
3,35,10,4,4,4,4,4,29,3,3
3,10,9,4,4,4,4,4,45,4,3
3,29,4,4,4,4,4,4,27,4,3
3,46,4,4,4,4,4,4,4,29,3
3,46,4,4,4,4,4,4,4,47,3
3,46,4,4,4,4,4,16,4,19,3
3,46,29,47,46,4,4,4,4,29,3
3,43,3,3,3,29,47,47,47,47,43
3,3,3,3,3,3,3,3,3,3,3
endlayer

layer
3,3,49,43,43,48,3,3,3,3,3
3,3,52,27,27,29,43,51,50,3,3
3,52,29,4,4,4,27,27,48,3,3
3,53,10,4,4,4,4,4,29,52,3
3,2,11,4,4,4,4,4,27,43,3
50,29,4,4,4,4,4,4,27,43,3
54,27,4,4,4,4,4,4,4,29,50
43,27,4,4,4,4,4,4,4,27,43
43,27,4,4,4,4,4,16,4,27,43
50,55,29,27,27,4,4,4,4,29,50
3,3,49,43,51,29,27,27,27,48,3
3,3,3,3,3,50,56,43,51,50,3
endlayer

layer
3,3,3,3,3,3,3,3,3,3,3
3,3,3,52,57,52,50,3,3,3,3
3,3,49,47,47,46,57,52,3,3,3
3,3,10,19,15,15,47,47,48,3,3
3,52,10,47,15,15,15,46,52,3,3
3,49,47,15,15,15,15,47,57,50,3
3,57,19,15,15,15,15,15,27,48,3
50,57,19,15,15,15,15,15,27,57,3
3,49,19,22,22,22,22,16,27,55,3
3,3,55,57,57,27,27,27,27,48,3
3,3,3,3,50,55,57,57,55,3,3
3,3,3,3,3,3,3,50,3,3,3
endlayer

layer
3,3,3,3,3,3,3,3,3,3,3
3,3,3,3,3,3,3,3,3,3,3
3,3,3,50,52,50,3,3,3,3,3
3,3,2,49,57,57,52,50,3,3,3
3,3,10,57,57,57,57,50,3,3,3
3,3,50,57,57,57,57,48,3,3,3
3,3,49,57,57,57,57,57,50,3,3
3,3,50,57,57,57,57,57,48,3,3
3,3,50,50,55,57,57,57,55,3,3
3,3,3,3,3,50,55,55,50,3,3
3,3,3,3,3,3,3,3,3,3,3
3,3,3,3,3,3,3,3,3,3,3
endlayer

layer
3,3,3,3,3,3,3,3,3,3,3
3,3,3,3,3,3,3,3,3,3,3
3,3,3,3,3,3,3,3,3,3,3
3,3,10,3,58,58,3,3,3,3,3
3,3,2,58,58,50,58,3,3,3,3
3,3,3,58,50,50,58,3,3,3,3
3,3,3,58,50,50,58,58,3,3,3
3,3,3,58,58,50,50,58,3,3,3
3,3,3,3,3,58,58,58,3,3,3
3,3,3,3,3,3,3,3,3,3,3
3,3,3,3,3,3,3,3,3,3,3
3,3,3,3,3,3,3,3,3,3,3
endlayer

layer
3,3,3,3,3,3,3,3,3,3,3
3,3,3,3,3,3,3,3,3,3,3
3,3,3,3,3,3,3,3,3,3,3
3,3,11,3,3,3,3,3,3,3,3
3,3,10,3,3,3,3,3,3,3,3
3,3,3,3,3,3,3,3,3,3,3
3,3,3,3,3,3,3,3,3,3,3
3,3,3,3,3,3,3,3,3,3,3
3,3,3,3,3,3,3,3,3,3,3
3,3,3,3,3,3,3,3,3,3,3
3,3,3,3,3,3,3,3,3,3,3
3,3,3,3,3,3,3,3,3,3,3
endlayer

layer
3,3,3,3,3,3,3,3,3,3,3
3,3,3,3,3,3,3,3,3,3,3
3,3,3,3,3,3,3,3,3,3,3
3,3,14,3,3,3,3,3,3,3,3
3,3,14,3,3,3,3,3,3,3,3
3,3,3,3,3,3,3,3,3,3,3
3,3,3,3,3,3,3,3,3,3,3
3,3,3,3,3,3,3,3,3,3,3
3,3,3,3,3,3,3,3,3,3,3
3,3,3,3,3,3,3,3,3,3,3
3,3,3,3,3,3,3,3,3,3,3
3,3,3,3,3,3,3,3,3,3,3
endlayer

layer
3,3,3,3,3,3,3,3,3,3,3
3,3,3,3,3,3,3,3,3,3,3
3,3,3,3,3,3,3,3,3,3,3
3,3,59,3,3,3,3,3,3,3,3
3,3,59,3,3,3,3,3,3,3,3
3,3,3,3,3,3,3,3,3,3,3
3,3,3,3,3,3,3,3,3,3,3
3,3,3,3,3,3,3,3,3,3,3
3,3,3,3,3,3,3,3,3,3,3
3,3,3,3,3,3,3,3,3,3,3
3,3,3,3,3,3,3,3,3,3,3
3,3,3,3,3,3,3,3,3,3,3
endlayer

