
# Created by Ruins mod version 16.7 Ingame Parser
# authoring Player: lafuller

weight=1
embed_into_distance=8
acceptable_target_blocks=
unacceptable_target_blocks=flowing_water,water,flowing_lava,lava,ice,bedrock,netherrack,nether_brick,nether_brick_fence,soul_sand,quartz_ore,end_stone,obsidian,iron_bars,cloud,flesh,ash_block,slime_grass,slime_congealed,slime_dirt
dimensions=58,14,14
allowable_overhang=0
max_leveling=8
leveling_buffer=-1
preserve_water=0
preserve_lava=0
preventRotation=1

rule1=0,100,minecraft:stone_brick_stairs-2
rule2=0,100,stonebrick-0,stonebrick-0,stonebrick-1,stonebrick-1,stonebrick-2,stonebrick-2,stone-5,stone-6,cobblestone
rule3=0,100,preserveBlock
rule4=0,100,CommandBlock:RUINSTRIGGER /testruin Gilly/GillyCatacombs ~0 ~0 ~0 0:@
rule5=0,100,minecraft:stone_slab-13
rule6=0,100,minecraft:stone_brick_stairs-1
rule7=0,100,minecraft:stone_slab-5
rule8=0,100,minecraft:stone_brick_stairs-0
rule9=0,100,minecraft:stone_brick_stairs-7
rule10=0,100,minecraft:stone_brick_stairs-3
rule11=0,100,minecraft:stone_brick_stairs-5
rule12=0,100,minecraft:stone_brick_stairs-4
rule13=0,100,minecraft:iron_bars-0
rule14=0,100,minecraft:cobblestone_wall-0
rule15=0,100,minecraft:stone_brick_stairs-6
rule16=0,100,minecraft:planks-1
rule17=0,100,air
rule18=0,100,minecraft:spruce_stairs-6
rule19=0,100,minecraft:spruce_stairs-3
rule20=0,100,minecraft:spruce_stairs-2
rule21=0,100,minecraft:spruce_stairs-7
rule22=0,100,minecraft:spruce_stairs-0
rule23=0,100,minecraft:spruce_stairs-4
rule24=0,100,minecraft:spruce_stairs-5
rule25=0,100,minecraft:spruce_stairs-1

layer
3,2,2,2,2,2,2,2,2,2,2,2,2,1
2,2,2,2,2,2,2,2,2,2,2,2,2,2
2,2,2,2,2,0,0,0,0,0,2,2,2,2
2,2,2,0,0,0,0,0,0,0,0,0,2,2
2,2,2,0,0,0,0,0,0,0,0,0,2,2
2,2,0,0,0,0,0,0,0,0,0,0,0,2
2,2,0,0,0,0,0,0,0,0,0,0,0,2
2,2,0,0,0,0,0,4,0,0,0,0,0,2
2,2,5,5,5,5,0,0,0,0,0,0,0,2
2,2,2,2,2,6,0,0,0,0,0,0,0,2
2,2,2,2,2,1,0,0,0,0,0,0,2,2
2,2,2,2,2,7,0,0,0,0,0,0,2,2
2,2,2,2,2,7,0,0,0,0,2,2,2,2
3,2,2,2,2,2,2,2,2,2,2,2,2,3
endlayer

layer
2,2,2,2,2,2,2,2,2,2,2,2,1,3
2,2,2,2,2,2,2,2,2,2,2,2,2,3
2,2,2,2,2,0,0,0,0,9,2,2,2,8
2,2,2,5,0,0,0,0,0,0,0,0,2,2
2,2,2,5,0,0,0,0,0,0,0,0,2,2
2,2,2,5,0,0,0,0,0,0,0,0,0,2
2,2,2,5,5,5,0,0,0,0,0,0,0,2
2,2,2,2,2,2,0,0,0,0,0,0,0,2
2,2,2,2,1,6,0,0,0,0,0,0,0,2
2,2,7,7,7,0,0,0,0,0,0,0,0,2
2,2,0,0,0,0,0,0,0,0,0,0,2,2
2,2,2,0,0,0,0,0,0,0,0,5,2,2
10,2,2,2,0,0,0,0,0,0,2,2,2,2
10,2,2,2,2,2,2,2,2,2,2,2,2,2
endlayer

layer
2,2,2,2,2,2,2,2,2,2,2,1,3,3
2,2,2,2,2,2,2,2,2,2,2,2,2,3
2,2,2,2,2,2,5,5,9,2,2,2,2,3
2,2,2,2,2,2,5,0,0,0,9,2,2,8
2,2,2,2,2,2,5,0,0,0,0,11,2,2
2,2,2,2,2,2,5,0,0,0,0,0,2,2
2,2,2,2,2,2,5,0,0,0,0,0,11,2
2,2,7,7,7,6,0,0,0,0,0,0,5,2
2,2,0,0,0,0,0,0,0,0,0,0,5,2
2,2,0,0,0,0,0,0,0,0,0,0,12,2
2,2,0,0,0,0,0,0,0,0,0,12,2,2
6,2,2,0,0,0,0,0,0,0,9,2,2,2
3,10,2,2,0,0,0,0,5,9,2,2,2,6
3,10,2,2,2,2,2,2,2,2,2,1,3,3
endlayer

layer
2,2,2,2,2,2,2,2,2,2,1,3,3,3
2,2,2,2,2,2,2,2,2,2,2,2,2,3
2,2,2,2,2,2,2,2,2,2,2,2,2,3
2,2,2,2,2,2,2,2,2,2,2,2,2,3
2,2,2,0,7,7,2,2,2,2,2,2,2,8
2,2,0,0,0,7,10,2,2,2,2,2,2,2
2,2,0,0,0,0,10,2,2,2,2,2,2,2
2,2,0,0,0,0,10,13,2,2,2,2,2,2
2,2,0,0,0,0,11,2,2,2,2,2,2,2
2,2,0,0,0,0,0,9,2,2,2,2,2,2
6,2,0,0,0,0,0,9,2,2,2,2,2,2
3,2,2,0,0,0,0,9,2,2,2,2,2,6
3,3,10,2,0,0,5,2,2,2,6,6,6,3
3,3,10,2,2,2,2,2,2,2,1,3,3,3
endlayer

layer
2,2,2,2,2,2,2,2,2,1,3,3,3,3
2,2,2,2,2,2,2,2,2,2,2,2,2,3
2,2,2,2,2,2,2,2,2,2,2,2,2,3
2,2,2,2,0,0,0,0,0,0,0,2,2,3
2,2,2,0,0,0,0,0,0,0,0,0,2,3
2,2,0,0,0,0,0,0,0,0,0,0,2,8
2,2,0,0,0,0,0,0,0,0,0,0,2,2
2,2,0,0,0,0,0,0,0,0,0,0,2,2
2,2,0,0,0,0,14,0,0,0,0,0,2,2
6,2,0,0,0,0,14,0,0,0,0,2,2,2
3,2,12,0,0,0,14,0,0,0,3,3,3,6
3,2,2,15,0,0,2,2,3,3,3,3,3,3
3,3,3,10,2,2,2,2,1,3,3,3,3,3
3,3,3,10,2,2,2,2,1,3,3,3,3,3
endlayer

layer
8,10,2,2,1,3,3,3,3,3,3,3,3,3
2,2,2,2,2,2,2,2,2,8,8,8,8,3
2,2,2,2,2,2,2,2,2,2,2,2,2,3
2,2,2,2,15,0,0,0,0,0,9,2,2,3
2,2,2,0,0,0,0,0,0,0,0,11,2,3
2,2,11,0,0,0,0,0,0,0,0,0,2,3
2,2,0,0,0,0,0,0,0,0,0,0,2,8
2,2,0,0,0,0,0,0,0,0,0,0,2,2
6,2,0,0,0,0,0,0,0,0,0,0,2,2
3,2,12,0,0,0,0,0,0,0,0,2,2,6
3,2,2,0,0,0,0,0,0,0,0,3,3,3
3,2,2,2,15,5,9,2,0,0,3,3,3,3
3,3,3,3,10,2,2,1,3,3,3,3,3,3
3,3,3,3,10,2,2,1,3,3,3,3,3,3
endlayer

layer
3,3,10,1,3,3,3,3,3,3,3,3,3,3
8,8,2,2,2,2,2,2,2,3,3,3,3,3
2,2,2,2,2,2,2,2,2,2,2,2,8,3
2,2,2,2,2,15,0,0,0,9,2,2,2,3
2,2,2,0,0,0,0,0,0,0,11,2,2,3
2,2,2,0,0,0,0,0,0,0,0,11,2,3
2,2,15,0,0,0,0,0,0,0,0,0,2,3
6,2,15,0,0,0,0,0,0,0,0,0,2,8
3,2,15,0,0,0,0,0,0,0,0,12,2,6
3,2,2,0,0,0,0,0,0,0,0,2,2,3
3,2,2,15,0,0,0,0,0,0,0,0,3,3
3,2,2,2,2,2,2,2,0,0,0,3,3,3
3,3,3,3,3,10,1,3,0,0,3,3,3,3
3,3,3,3,3,10,1,3,3,3,3,3,3,3
endlayer

layer
3,3,3,3,3,3,3,3,3,3,3,3,3,3
3,3,8,8,2,2,2,2,2,3,3,3,3,3
8,8,2,2,2,2,2,2,2,2,2,1,0,3
2,2,2,2,2,2,2,2,2,2,2,1,0,3
2,2,2,11,15,0,0,0,5,9,2,1,0,3
2,2,2,15,0,0,0,0,0,0,11,2,2,3
6,2,2,5,0,0,0,0,0,0,5,2,2,3
3,2,2,5,0,0,0,0,0,0,0,2,1,3
3,2,2,12,0,0,0,0,0,0,0,2,1,3
3,2,2,15,0,0,0,0,0,0,0,2,1,3
3,2,2,2,15,0,0,0,0,0,0,0,0,3
3,2,2,2,2,6,6,2,0,0,0,0,3,3
3,3,3,3,3,3,0,0,0,0,3,3,3,3
3,3,3,3,3,3,3,3,3,3,3,3,3,3
endlayer

layer
3,3,3,3,3,3,3,3,3,3,3,3,3,3
3,3,3,3,10,2,2,2,2,3,3,3,3,3
3,3,8,8,2,2,2,2,2,2,1,0,0,3
3,10,2,2,2,2,2,2,2,2,1,0,0,3
3,10,2,2,2,2,2,2,2,2,1,0,0,3
3,2,2,2,2,5,5,5,5,2,2,2,2,3
3,2,2,2,2,5,0,0,0,5,2,2,2,3
3,2,2,2,2,5,0,0,0,5,2,1,0,3
3,2,2,2,2,5,0,0,0,5,2,1,0,3
3,10,2,2,2,5,5,5,5,2,2,1,0,3
3,6,2,2,2,6,6,2,2,5,5,0,0,3
3,3,6,6,6,3,0,6,0,0,0,0,3,3
3,3,3,3,3,3,0,0,0,0,3,3,3,3
3,3,3,3,3,3,3,3,3,3,3,3,3,3
endlayer

layer
3,3,3,3,3,3,3,3,3,3,3,3,3,3
3,3,3,3,3,10,8,8,1,3,3,3,3,3
3,3,3,3,2,2,2,2,8,1,3,3,3,3
3,3,8,8,2,2,2,2,2,1,3,3,3,3
3,3,10,2,2,2,2,2,2,1,3,3,3,3
3,8,2,2,2,2,2,2,2,8,8,2,2,3
3,10,2,2,2,2,2,2,2,2,2,2,2,3
3,10,2,2,2,2,2,13,2,2,1,3,3,3
3,10,2,2,2,2,2,2,2,2,1,3,3,3
3,3,10,2,2,6,6,2,2,2,1,3,3,3
3,3,6,6,6,3,0,6,2,2,2,3,3,3
3,3,3,3,3,3,0,3,3,3,3,3,3,3
3,3,3,3,3,3,0,3,3,3,3,3,3,3
3,3,3,3,3,3,3,3,3,3,3,3,3,3
endlayer

layer
3,3,3,3,3,3,3,3,3,3,3,3,3,3
3,3,3,3,3,3,3,3,3,3,3,3,3,3
3,3,3,3,2,2,2,1,3,3,3,3,3,3
3,3,3,3,2,11,2,2,1,3,3,3,3,3
3,3,3,0,0,0,6,10,2,0,3,3,3,3
3,3,2,2,0,0,0,0,0,0,3,16,16,3
3,3,2,15,0,0,0,0,0,0,0,16,16,3
3,3,2,2,1,0,0,0,0,0,0,3,3,3
3,3,6,2,8,0,0,0,0,0,0,3,3,3
3,3,3,6,2,0,0,0,0,0,0,3,3,3
3,3,3,3,3,0,0,0,0,0,3,3,3,3
3,3,3,3,3,3,0,0,0,3,3,3,3,3
3,3,3,3,3,3,3,3,3,3,3,3,3,3
3,3,3,3,3,3,3,3,3,3,3,3,3,3
endlayer

layer
3,3,3,3,3,3,3,3,3,3,3,3,3,3
3,3,3,3,3,3,3,3,3,3,3,3,3,3
3,3,3,3,2,2,7,3,3,3,3,3,3,3
3,3,3,3,2,2,1,0,0,3,3,3,3,3
3,3,3,0,0,0,0,0,0,0,3,3,3,3
3,3,2,2,0,0,0,0,0,0,3,19,18,3
3,3,2,2,0,0,0,0,0,0,0,21,20,3
3,3,7,6,0,0,0,0,0,0,0,3,3,3
3,3,3,0,0,0,0,0,0,0,0,3,3,3
3,3,3,3,0,0,0,0,0,0,0,3,3,3
3,3,3,3,3,0,0,0,0,0,3,3,3,3
3,3,3,3,3,3,0,0,0,3,3,3,3,3
3,3,3,3,3,3,3,3,3,3,3,3,3,3
3,3,3,3,3,3,3,3,3,3,3,3,3,3
endlayer

layer
3,3,3,3,3,3,3,3,3,3,3,3,3,3
3,3,3,3,3,3,3,3,3,3,3,3,3,3
3,3,3,3,2,2,3,3,3,3,3,3,3,3
3,3,3,3,2,2,0,0,3,3,3,3,3,3
3,3,3,0,0,0,0,0,0,0,3,3,3,3
3,3,2,2,0,0,0,0,0,0,3,23,22,3
3,3,2,2,0,0,0,0,0,0,0,25,24,3
3,3,3,0,0,0,0,0,0,0,0,3,3,3
3,3,3,0,0,0,0,0,0,0,0,3,3,3
3,3,3,3,0,0,0,0,0,0,3,3,3,3
3,3,3,3,3,0,0,0,0,0,3,3,3,3
3,3,3,3,3,3,3,0,3,3,3,3,3,3
3,3,3,3,3,3,3,3,3,3,3,3,3,3
3,3,3,3,3,3,3,3,3,3,3,3,3,3
endlayer

layer
3,3,3,3,3,3,3,3,3,3,3,3,3,3
3,3,3,3,3,3,3,3,3,3,3,3,3,3
3,3,3,3,2,2,3,3,3,3,3,3,3,3
3,3,3,3,2,2,3,3,3,3,3,3,3,3
3,3,3,3,0,0,0,0,3,3,3,3,3,3
3,3,2,2,0,0,0,0,0,0,3,19,18,3
3,3,2,2,0,0,0,0,0,0,3,21,20,3
3,3,3,0,0,0,0,0,0,0,0,3,3,3
3,3,3,3,0,0,0,0,0,0,3,3,3,3
3,3,3,3,0,0,0,0,0,0,3,3,3,3
3,3,3,3,3,3,0,0,0,3,3,3,3,3
3,3,3,3,3,3,3,3,3,3,3,3,3,3
3,3,3,3,3,3,3,3,3,3,3,3,3,3
3,3,3,3,3,3,3,3,3,3,3,3,3,3
endlayer

layer
3,3,3,3,3,3,3,3,3,3,3,3,3,3
3,3,3,3,3,3,3,3,3,3,3,3,3,3
3,3,3,3,2,2,3,3,3,3,3,3,3,3
3,3,3,3,2,2,3,3,3,3,3,3,3,3
3,3,3,3,3,3,3,3,3,3,3,3,3,3
3,3,2,2,3,0,0,0,0,3,3,23,22,3
3,3,2,2,0,0,0,0,0,0,3,25,24,3
3,3,3,3,0,0,0,0,0,0,3,3,3,3
3,3,3,3,0,0,0,0,0,0,3,3,3,3
3,3,3,3,3,0,0,0,0,3,3,3,3,3
3,3,3,3,3,3,3,3,3,3,3,3,3,3
3,3,3,3,3,3,3,3,3,3,3,3,3,3
3,3,3,3,3,3,3,3,3,3,3,3,3,3
3,3,3,3,3,3,3,3,3,3,3,3,3,3
endlayer

layer
3,3,3,3,3,3,3,3,3,3,3,3,3,3
3,3,3,3,3,3,3,3,3,3,3,3,3,3
3,3,3,3,2,2,3,3,3,3,3,3,3,3
3,3,3,3,2,2,3,3,3,3,3,3,3,3
3,3,3,3,3,3,3,3,3,3,3,3,3,3
3,3,2,2,3,3,0,0,3,3,3,19,18,3
3,3,2,2,3,0,0,0,0,3,3,21,20,3
3,3,3,3,3,0,0,0,0,0,3,3,3,3
3,3,3,3,3,3,0,0,0,3,3,3,3,3
3,3,3,3,3,3,3,0,3,3,3,3,3,3
3,3,3,3,3,3,3,3,3,3,3,3,3,3
3,3,3,3,3,3,3,3,3,3,3,3,3,3
3,3,3,3,3,3,3,3,3,3,3,3,3,3
3,3,3,3,3,3,3,3,3,3,3,3,3,3
endlayer

layer
3,3,3,3,3,3,3,3,3,3,3,3,3,3
3,3,3,3,3,3,3,3,3,3,3,3,3,3
3,3,3,3,2,2,3,3,3,3,3,3,3,3
3,3,3,3,2,2,3,3,3,3,3,3,3,3
3,3,3,3,3,3,3,3,3,3,3,3,3,3
3,3,2,2,3,3,3,3,3,3,3,23,22,3
3,3,2,2,3,3,3,0,3,3,3,25,24,3
3,3,3,3,3,3,0,0,0,3,3,3,3,3
3,3,3,3,3,3,3,0,3,3,3,3,3,3
3,3,3,3,3,3,3,3,3,3,3,3,3,3
3,3,3,3,3,3,3,3,3,3,3,3,3,3
3,3,3,3,3,3,3,3,3,3,3,3,3,3
3,3,3,3,3,3,3,3,3,3,3,3,3,3
3,3,3,3,3,3,3,3,3,3,3,3,3,3
endlayer

layer
3,3,3,3,3,3,3,3,3,3,3,3,3,3
3,3,3,3,3,3,3,3,3,3,3,3,3,3
3,3,3,3,2,2,15,3,3,3,3,3,3,3
3,3,3,3,2,2,3,3,3,3,3,3,3,3
3,3,3,3,3,3,3,3,3,3,3,3,3,3
3,3,2,2,15,3,3,3,3,3,3,19,18,3
3,3,2,2,3,3,3,3,3,3,3,21,20,3
3,3,3,3,3,3,3,0,3,3,3,3,3,3
3,3,3,3,3,3,3,3,3,3,3,3,3,3
3,3,3,3,3,3,3,3,3,3,3,3,3,3
3,3,3,3,3,3,3,3,3,3,3,3,3,3
3,3,3,3,3,3,3,3,3,3,3,3,3,3
3,3,3,3,3,3,3,3,3,3,3,3,3,3
3,3,3,3,3,3,3,3,3,3,3,3,3,3
endlayer

layer
3,3,3,3,3,3,3,3,3,3,3,3,3,3
3,3,3,3,3,3,3,3,3,3,3,3,3,3
3,3,3,3,2,2,2,3,3,3,3,3,3,3
3,3,3,3,2,2,3,3,3,3,3,3,3,3
3,3,3,3,3,3,3,3,3,3,3,3,3,3
3,3,2,2,2,3,3,3,3,3,3,23,22,3
3,3,2,2,11,3,3,3,3,3,3,25,24,3
3,3,3,3,3,3,3,3,3,3,3,3,3,3
3,3,3,3,3,3,3,3,3,3,3,3,3,3
3,3,3,3,3,3,3,3,3,3,3,3,3,3
3,3,3,3,3,3,3,3,3,3,3,3,3,3
3,3,3,3,3,3,3,3,3,3,3,3,3,3
3,3,3,3,3,3,3,3,3,3,3,3,3,3
3,3,3,3,3,3,3,3,3,3,3,3,3,3
endlayer

layer
3,3,3,3,3,3,3,3,3,3,3,3,3,3
3,3,3,3,3,3,3,3,3,3,3,3,3,3
3,3,3,3,2,2,2,3,3,3,3,3,3,3
3,3,3,3,2,2,11,3,3,3,3,3,3,3
3,3,3,3,3,3,3,3,3,3,3,3,3,3
3,3,2,2,2,3,3,3,3,3,3,19,18,3
3,3,2,2,2,3,3,3,3,3,3,21,20,3
3,3,3,12,3,3,3,3,3,3,3,3,3,3
3,3,3,3,3,3,3,3,3,3,3,3,3,3
3,3,3,3,3,3,3,3,3,3,3,3,3,3
3,3,3,3,3,3,3,3,3,3,3,3,3,3
3,3,3,3,3,3,3,3,3,3,3,3,3,3
3,3,3,3,3,3,3,3,3,3,3,3,3,3
3,3,3,3,3,3,3,3,3,3,3,3,3,3
endlayer

layer
3,3,3,3,3,3,3,3,3,3,3,3,3,3
3,3,3,3,3,3,3,3,3,3,3,3,3,3
3,3,3,3,2,2,2,3,3,3,3,3,3,3
3,3,3,3,2,2,2,3,3,3,3,3,3,3
3,3,3,11,2,5,9,3,3,3,3,3,3,3
3,3,2,2,2,3,3,3,3,3,3,23,22,3
3,15,2,2,2,9,3,3,3,3,3,25,24,3
3,3,3,2,12,3,3,3,3,3,3,3,3,3
3,3,3,3,3,3,3,3,3,3,3,3,3,3
3,3,3,3,3,3,3,3,3,3,3,3,3,3
3,3,3,3,3,3,3,3,3,3,3,3,3,3
3,3,3,3,3,3,3,3,3,3,3,3,3,3
3,3,3,3,3,3,3,3,3,3,3,3,3,3
3,3,3,3,3,3,3,3,3,3,3,3,3,3
endlayer

layer
3,3,3,3,3,3,3,3,3,3,3,3,3,3
3,3,3,3,3,3,3,3,3,3,3,3,3,3
3,3,3,3,2,2,2,3,3,3,3,3,3,3
3,3,3,3,2,2,2,9,3,3,3,3,3,3
3,3,15,2,2,2,2,3,3,3,3,3,3,3
3,3,2,2,2,2,9,3,3,3,3,19,18,3
3,2,2,2,2,2,3,3,3,3,3,21,20,3
3,3,12,2,2,3,3,3,3,3,3,3,3,3
3,3,3,3,3,3,3,3,3,3,3,3,3,3
3,3,3,3,3,3,3,3,3,3,3,3,3,3
3,3,3,3,3,3,3,3,3,3,3,3,3,3
3,3,3,3,3,3,3,3,3,3,3,3,3,3
3,3,3,3,3,3,3,3,3,3,3,3,3,3
3,3,3,3,3,3,3,3,3,3,3,3,3,3
endlayer

layer
3,3,3,3,3,3,3,3,3,3,3,3,3,3
3,3,3,3,3,3,3,3,3,3,3,3,3,3
3,3,3,3,2,2,2,9,3,3,3,3,3,3
3,3,3,15,2,2,2,2,3,3,3,3,3,3
3,3,2,2,2,2,2,9,3,3,3,3,3,3
3,15,2,2,2,2,2,3,3,3,3,23,22,3
3,2,2,2,2,2,3,3,3,3,3,25,24,3
3,3,2,2,2,15,3,3,3,3,3,3,3,3
3,3,3,3,3,3,3,3,3,3,3,3,3,3
3,3,3,3,3,3,3,3,3,3,3,3,3,3
3,3,3,3,3,3,3,3,3,3,3,3,3,3
3,3,3,3,3,3,3,3,3,3,3,3,3,3
3,3,3,3,3,3,3,3,3,3,3,3,3,3
3,3,3,3,3,3,3,3,3,3,3,3,3,3
endlayer

layer
3,3,3,3,3,3,3,3,3,3,3,3,3,3
3,3,3,3,3,11,3,3,3,3,3,3,3,3
3,3,3,3,2,2,2,2,3,3,3,3,3,3
3,3,3,2,2,2,2,2,3,3,3,3,3,3
3,3,2,2,2,2,2,2,3,3,3,3,3,3
3,2,2,2,2,2,2,3,3,3,3,19,18,3
3,3,2,2,2,2,11,3,3,3,3,21,20,3
3,3,2,2,2,2,3,3,3,3,3,3,3,3
3,3,3,11,3,3,3,3,3,3,3,3,3,3
3,3,3,3,3,3,3,3,3,3,3,3,3,3
3,3,3,3,3,3,3,3,3,3,3,3,3,3
3,3,3,3,3,3,3,3,3,3,3,3,3,3
3,3,3,3,3,3,3,3,3,3,3,3,3,3
3,3,3,3,3,3,3,3,3,3,3,3,3,3
endlayer

layer
3,3,3,3,3,3,3,3,3,3,3,3,3,3
3,3,3,3,3,2,3,3,3,3,3,3,3,3
3,3,3,2,2,2,2,2,3,3,3,3,3,3
3,3,2,2,2,2,2,2,15,3,3,3,3,3
3,9,2,2,2,2,2,2,3,3,3,3,3,3
3,2,2,2,2,2,2,15,3,3,3,23,22,3
3,2,2,2,2,2,2,3,3,3,3,25,24,3
3,3,2,2,2,2,3,3,3,3,3,3,3,3
3,3,3,2,11,3,3,3,3,3,3,3,3,3
3,3,3,3,3,3,3,3,3,3,3,3,3,3
3,3,3,3,3,3,3,3,3,3,3,3,3,3
3,3,3,3,3,3,3,3,3,3,3,3,3,3
3,3,3,3,3,3,3,3,3,3,3,3,3,3
3,3,3,3,3,3,3,3,3,3,3,3,3,3
endlayer

layer
3,3,3,3,3,3,3,3,3,3,3,3,3,3
3,3,3,3,3,12,2,3,3,3,3,3,3,3
3,3,3,2,2,2,2,2,15,3,3,3,3,3
3,3,9,2,2,2,2,2,2,3,3,3,3,3
3,2,2,2,2,2,2,2,15,3,3,3,3,3
3,2,2,2,2,2,2,2,3,3,3,19,18,3
3,2,2,2,2,2,2,11,3,3,3,21,20,3
3,11,2,2,2,2,3,3,3,3,3,3,3,3
3,3,2,2,2,3,3,3,3,3,3,3,3,3
3,3,3,3,3,3,3,3,3,3,3,3,3,3
3,3,3,3,3,3,3,3,3,3,3,3,3,3
3,3,3,3,3,3,3,3,3,3,3,3,3,3
3,3,3,3,3,3,3,3,3,3,3,3,3,3
3,3,3,3,3,3,3,3,3,3,3,3,3,3
endlayer

layer
3,3,3,3,3,3,3,3,3,3,3,3,3,3
3,3,3,3,3,2,2,3,3,3,3,3,3,3
3,3,3,2,2,2,2,2,2,3,3,3,3,3
3,3,2,2,2,2,2,2,2,15,3,3,3,3
3,9,2,2,2,2,2,2,2,3,3,3,3,3
3,2,2,2,2,2,2,2,3,3,3,23,22,3
3,2,2,2,2,2,2,2,3,3,3,25,24,3
3,3,2,2,2,2,15,3,3,3,3,3,3,3
3,3,2,2,2,3,3,3,3,3,3,3,3,3
3,3,3,3,3,3,3,3,3,3,3,3,3,3
3,3,3,3,3,3,3,3,3,3,3,3,3,3
3,3,3,3,3,3,3,3,3,3,3,3,3,3
3,3,3,3,3,3,3,3,3,3,3,3,3,3
3,3,3,3,3,3,3,3,3,3,3,3,3,3
endlayer

layer
3,3,3,3,3,3,3,3,3,3,3,3,3,3
3,3,3,3,2,2,2,2,3,3,3,3,3,3
3,3,12,2,2,2,2,2,2,3,3,3,3,3
3,3,2,2,2,2,2,2,2,2,3,3,3,3
3,2,2,2,2,2,2,2,2,3,3,3,3,3
3,2,2,2,2,2,2,2,2,3,3,19,18,3
3,2,2,2,2,2,2,2,3,3,3,21,20,3
3,2,2,2,2,2,2,3,3,3,3,3,3,3
3,3,2,2,2,11,3,3,3,3,3,3,3,3
3,3,3,3,3,3,3,3,3,3,3,3,3,3
3,3,3,3,3,3,3,3,3,3,3,3,3,3
3,3,3,3,3,3,3,3,3,3,3,3,3,3
3,3,3,3,3,3,3,3,3,3,3,3,3,3
3,3,3,3,3,3,3,3,3,3,3,3,3,3
endlayer

layer
3,3,3,3,3,3,3,3,3,3,3,3,3,3
3,3,3,3,3,2,2,2,3,3,3,3,3,3
3,3,8,2,2,2,2,2,2,15,3,3,3,3
3,9,2,2,2,2,2,2,2,2,3,3,3,3
3,2,2,2,2,2,2,2,2,15,3,3,3,3
9,2,2,2,2,2,2,2,2,3,3,23,22,3
3,2,2,2,2,2,2,2,3,3,3,25,24,3
3,2,2,2,2,2,2,3,3,3,3,3,3,3
3,3,2,2,2,2,3,3,3,3,3,3,3,3
3,3,3,11,3,3,3,3,3,3,3,3,3,3
3,3,3,3,3,3,3,3,3,3,3,3,3,3
3,3,3,3,3,3,3,3,3,3,3,3,3,3
3,3,3,2,15,3,3,3,3,3,3,3,3,3
3,3,3,3,3,3,3,3,3,3,3,3,3,3
endlayer

layer
3,3,3,3,3,3,12,3,3,3,3,3,3,3
3,3,3,3,2,2,2,2,12,3,3,3,3,3
3,3,2,2,2,2,2,2,2,2,3,3,3,3
3,2,2,2,2,2,2,2,2,2,3,3,3,3
3,2,2,2,2,2,2,2,2,2,3,3,3,3
2,2,2,2,2,2,2,2,2,3,3,19,18,3
9,2,2,2,2,2,2,2,3,3,3,21,20,3
3,2,2,2,2,2,2,3,3,3,3,3,3,3
3,11,2,2,2,2,3,3,3,3,3,3,3,3
3,3,11,2,3,3,3,3,3,3,3,3,3,3
3,3,3,3,3,3,3,3,3,3,3,3,3,3
3,3,3,3,3,3,3,3,3,3,3,3,3,3
3,3,3,2,2,3,3,3,3,3,3,3,3,3
3,3,3,2,15,3,3,3,3,3,3,3,3,3
endlayer

layer
3,3,3,3,3,2,2,3,3,3,3,3,3,3
3,3,3,12,2,2,2,2,2,3,3,3,3,3
3,3,2,2,2,2,2,2,2,2,3,3,3,3
3,2,2,2,2,2,2,2,2,2,3,3,3,3
3,2,2,2,2,2,2,2,2,2,3,3,3,3
2,2,2,2,2,2,2,2,2,3,3,23,22,3
2,2,2,2,2,2,2,2,3,3,3,25,24,3
3,2,2,2,2,2,2,3,3,3,3,3,3,3
3,2,2,2,2,2,3,3,3,3,3,3,3,3
3,3,2,2,11,3,3,3,3,3,3,3,3,3
3,3,3,3,3,3,3,3,3,3,3,3,3,3
3,3,3,2,3,3,3,3,3,3,3,3,3,3
3,3,2,2,2,3,3,3,3,3,3,3,3,3
3,3,9,2,2,3,3,3,3,3,3,3,3,3
endlayer

layer
3,3,3,3,12,2,2,12,3,3,3,3,3,3
3,3,3,2,2,2,2,2,2,3,3,3,3,3
3,3,2,2,2,2,2,2,2,2,3,3,3,3
3,2,2,2,2,2,2,2,2,2,3,3,3,3
9,2,2,2,2,2,2,2,2,2,3,3,3,3
2,2,2,2,2,2,2,2,2,3,3,19,18,3
2,2,2,2,2,2,2,2,3,3,3,21,20,3
3,2,2,2,2,2,2,3,3,3,3,3,3,3
3,2,2,2,2,2,3,3,3,3,3,3,3,3
3,2,2,2,2,3,3,3,3,3,3,3,3,3
3,3,3,3,3,3,3,3,3,3,3,3,3,3
3,3,3,2,3,3,3,3,3,3,3,3,3,3
3,9,2,2,3,3,3,3,3,3,3,3,3,3
3,3,6,2,1,3,3,3,3,3,3,3,3,3
endlayer

layer
3,3,3,3,2,2,2,2,3,3,3,3,3,3
3,3,3,2,2,2,2,2,2,3,3,3,3,3
3,3,2,2,2,2,2,2,2,8,3,3,3,3
3,2,2,2,2,2,2,2,2,2,3,3,3,3
2,2,2,2,2,2,2,2,2,1,3,3,3,3
2,2,2,2,2,2,2,2,2,3,3,23,22,3
2,2,2,2,2,2,2,2,3,3,3,25,24,3
9,2,2,2,2,2,6,3,3,3,3,3,3,3
3,2,2,2,2,1,3,3,3,3,3,3,3,3
3,2,2,2,6,3,3,3,3,3,3,3,3,3
3,3,3,3,3,3,3,3,3,3,3,3,3,3
3,3,2,2,3,3,3,3,3,3,3,3,3,3
3,2,2,2,3,3,3,3,3,3,3,3,3,3
3,3,3,6,3,3,3,3,3,3,3,3,3,3
endlayer

layer
3,3,3,3,8,2,2,8,3,3,3,3,3,3
3,3,3,2,2,2,2,2,8,3,3,3,3,3
3,3,2,2,2,2,2,2,2,3,3,3,3,3
3,2,2,2,2,2,2,2,2,1,3,3,3,3
10,2,2,2,2,2,2,2,2,3,3,3,3,3
2,2,2,2,2,2,2,2,1,3,3,19,18,3
2,2,2,2,2,2,2,1,3,3,3,21,20,3
2,2,2,2,2,2,3,3,3,3,3,3,3,3
3,2,2,2,2,3,3,3,3,3,3,3,3,3
3,3,2,6,3,3,3,3,3,3,3,3,3,3
3,3,3,3,3,3,3,3,3,3,3,3,3,3
3,2,2,3,3,3,3,3,3,3,3,3,3,3
3,2,2,2,3,3,3,3,3,3,3,3,3,3
3,3,3,3,3,3,3,3,3,3,3,3,3,3
endlayer

layer
3,3,3,3,3,8,8,3,3,3,3,3,3,3
3,3,3,3,2,2,2,2,3,3,3,3,3,3
3,3,3,2,2,2,2,2,8,3,3,3,3,3
3,3,2,2,2,2,2,2,2,3,3,3,3,3
3,2,2,2,2,2,2,2,1,3,3,3,3,3
10,2,2,2,2,2,2,1,3,3,3,23,22,3
2,2,2,2,2,2,1,3,3,3,3,25,24,3
3,2,2,2,2,6,3,3,3,3,3,3,3,3
3,2,2,2,6,3,3,3,3,3,3,3,3,3
3,3,3,3,3,3,3,3,3,3,3,3,3,3
3,12,2,3,3,3,3,3,3,3,3,3,3,3
9,2,2,3,3,3,3,3,3,3,3,3,3,3
3,6,2,1,3,3,3,3,3,3,3,3,3,3
3,3,3,3,3,3,3,3,3,3,3,3,3,3
endlayer

layer
3,3,3,3,3,3,3,3,3,12,15,3,3,3
3,3,3,3,8,2,2,1,3,9,2,3,3,3
3,3,3,10,2,2,2,2,3,3,3,3,3,3
3,3,8,2,2,2,2,2,3,3,3,3,3,3
3,10,2,2,2,2,2,6,3,3,3,3,3,3
3,2,2,2,2,2,2,3,3,3,3,19,18,3
3,2,2,2,2,2,3,3,3,3,3,21,20,3
3,2,2,2,2,3,3,3,3,3,3,3,3,3
3,3,2,6,3,3,3,3,3,3,3,3,3,3
3,3,3,3,3,3,3,3,3,3,3,3,3,3
3,2,2,3,3,3,3,3,3,3,3,3,3,3
2,2,2,3,3,3,3,3,3,3,3,3,3,3
3,3,6,3,3,3,3,3,3,3,3,3,3,3
3,3,3,3,3,3,3,3,3,3,3,3,3,3
endlayer

layer
3,3,3,3,3,3,3,3,3,2,2,3,3,3
3,3,3,3,3,3,3,3,3,2,2,15,3,3
3,3,3,3,8,2,2,8,3,3,9,2,3,3
3,3,3,3,2,2,2,2,3,3,3,3,3,3
3,3,8,2,2,2,2,3,3,3,3,3,3,3
3,10,2,2,2,2,2,3,3,3,3,23,22,3
3,2,2,2,2,2,3,3,3,3,3,25,24,3
3,3,2,2,2,3,3,3,3,3,3,3,3,3
3,3,3,3,3,3,3,3,3,3,3,3,3,3
3,12,3,3,3,3,3,3,3,3,3,3,3,3
9,2,2,3,3,3,3,3,3,3,3,3,3,3
2,2,2,3,3,3,3,3,3,3,3,3,3,3
3,3,3,3,3,3,3,3,3,3,3,3,3,3
3,3,3,3,3,3,3,3,3,3,3,3,3,3
endlayer

layer
3,3,3,3,3,3,3,3,3,2,2,3,3,3
3,3,3,3,3,3,3,3,9,2,2,8,3,3
3,3,3,3,3,3,3,3,3,3,2,2,15,3
3,3,3,3,8,2,2,2,3,3,3,2,11,3
3,3,3,10,2,2,2,15,3,3,3,3,3,3
3,3,2,2,2,2,2,3,3,3,3,19,18,3
3,3,2,2,2,2,3,3,3,3,3,21,20,3
3,3,3,2,2,3,3,3,3,3,3,3,3,3
3,3,3,3,3,3,3,3,3,3,3,3,3,3
3,2,3,3,3,3,3,3,3,3,3,3,3,3
2,2,1,3,3,3,3,3,3,3,3,3,3,3
10,2,3,3,3,3,3,3,3,3,3,3,3,3
3,3,3,3,3,3,3,3,3,3,3,3,3,3
3,3,3,3,3,3,3,3,3,3,3,3,3,3
endlayer

layer
3,3,3,3,3,3,3,3,3,2,2,3,3,3
3,3,3,3,3,3,3,3,2,2,2,3,3,3
3,3,3,3,3,3,3,3,3,3,3,10,1,3
3,3,3,3,3,2,2,2,3,3,3,2,2,3
3,3,3,3,2,2,2,2,3,3,3,9,15,3
3,3,3,2,2,2,2,3,3,3,3,23,22,3
3,3,2,2,2,2,15,3,3,3,3,25,24,3
3,3,3,2,2,11,3,3,3,3,3,3,3,3
3,3,3,3,3,3,3,3,3,3,3,3,3,3
9,2,3,3,3,3,3,3,3,3,3,3,3,3
2,2,3,3,3,3,3,3,3,3,3,3,3,3
3,6,3,3,3,3,3,3,3,3,3,3,3,3
3,3,3,3,3,3,3,3,3,3,3,3,3,3
3,3,3,3,3,3,3,3,3,3,3,3,3,3
endlayer

layer
3,3,3,3,3,3,3,3,12,2,2,3,3,3
3,3,3,3,3,3,3,3,2,2,1,3,3,3
3,3,3,3,3,8,3,3,3,3,3,3,3,3
3,3,3,3,3,2,2,2,3,3,3,3,8,3
3,3,3,3,2,2,2,2,3,3,3,10,2,15
3,3,3,2,2,2,2,15,3,3,3,19,16,11
3,3,2,2,2,2,2,3,3,3,3,21,20,3
3,3,3,2,2,2,3,3,3,3,3,3,3,3
3,12,3,3,3,3,3,3,3,3,3,3,3,3
2,2,3,3,3,3,3,3,3,3,3,3,3,3
2,2,3,3,3,3,3,3,3,3,3,3,3,3
3,3,3,3,3,3,3,3,3,3,3,3,3,3
3,3,3,3,3,3,3,3,3,3,3,3,3,3
3,3,3,3,3,3,3,3,3,3,3,3,3,3
endlayer

layer
3,3,3,3,3,3,3,3,2,2,2,3,3,3
3,3,3,3,3,3,3,3,2,2,3,3,3,3
3,3,3,3,3,3,8,3,3,3,3,3,3,3
3,3,3,3,2,2,2,2,3,3,3,3,3,3
3,3,3,2,2,2,2,2,5,3,3,3,8,1
3,3,2,2,2,2,2,2,5,3,3,23,16,2
3,3,2,2,2,2,2,11,3,3,3,25,24,15
3,3,3,2,2,2,15,3,3,3,3,3,3,3
9,2,3,3,5,5,3,3,3,3,3,3,3,3
2,2,3,3,3,3,3,3,3,3,3,3,3,3
2,2,3,3,3,3,3,3,3,3,3,3,3,3
3,3,3,3,3,3,3,3,3,3,3,3,3,3
3,3,3,3,3,3,3,3,3,3,3,3,3,3
3,3,3,3,3,3,3,3,3,3,3,3,3,3
endlayer

layer
3,3,3,3,3,3,3,3,2,2,1,3,3,3
3,3,3,3,3,3,8,3,2,2,3,3,3,3
3,3,3,3,3,2,2,2,3,2,3,3,3,3
3,3,3,10,2,2,2,2,12,3,3,3,3,3
3,3,12,2,2,2,2,2,2,15,3,3,3,3
3,3,2,2,2,2,2,2,2,15,3,19,18,1
3,3,2,2,2,2,2,2,11,3,3,21,20,2
3,2,2,2,2,2,2,3,3,3,3,9,11,3
2,2,3,9,2,2,15,3,3,3,3,3,3,3
2,2,3,3,11,11,3,3,3,3,3,3,3,3
2,1,3,3,3,3,3,3,3,3,3,3,3,3
3,3,3,3,3,3,3,3,3,3,3,3,3,3
3,3,3,3,3,3,3,3,3,3,3,3,3,3
3,3,3,3,3,3,3,3,3,3,3,3,3,3
endlayer

layer
3,3,3,3,3,3,3,9,2,2,3,3,3,3
3,3,3,3,3,10,2,3,2,2,3,3,3,3
3,3,3,3,2,2,2,2,2,2,3,3,3,3
3,3,3,3,2,2,2,2,2,3,3,3,3,3
3,3,3,2,2,2,2,2,2,2,3,3,3,3
3,9,2,2,2,2,2,2,2,2,3,23,22,3
3,3,2,2,2,2,2,2,2,3,3,25,24,1
3,2,2,2,2,2,2,3,3,3,3,6,6,3
2,2,3,2,2,2,2,3,3,3,3,3,3,3
2,2,3,3,2,2,3,3,3,3,3,3,3,3
6,3,3,3,3,3,3,3,3,3,3,3,3,3
3,3,3,3,3,3,3,3,3,3,3,3,3,3
3,3,3,3,3,3,3,3,3,3,3,3,3,3
3,3,3,3,3,3,3,3,3,3,3,3,3,3
endlayer

layer
3,3,3,3,3,3,3,2,2,8,3,3,3,3
3,3,3,3,3,3,2,2,2,2,3,3,3,3
3,3,3,3,2,2,2,2,2,2,3,3,3,3
3,3,3,2,2,2,2,2,2,3,3,3,3,3
3,3,2,2,2,2,2,2,2,8,3,3,3,3
3,12,2,2,2,2,2,2,2,1,3,19,18,3
3,10,2,2,2,2,2,2,6,3,3,21,20,3
9,2,2,2,2,2,2,3,3,3,3,3,3,3
2,2,2,2,2,2,1,3,3,3,3,3,3,3
2,2,15,3,10,6,3,3,3,3,3,3,3,3
3,3,3,3,3,3,3,3,3,3,3,3,3,3
3,3,3,3,3,3,3,3,3,3,3,3,3,3
3,3,3,3,3,3,3,3,3,3,3,3,3,3
3,3,3,3,3,3,3,3,3,3,3,3,3,3
endlayer

layer
3,3,3,3,3,3,9,2,2,3,3,3,3,3
3,3,3,3,3,2,2,2,2,2,3,3,3,3
3,3,3,12,2,2,2,2,2,2,3,3,3,3
3,3,8,2,2,2,2,2,2,3,3,3,3,3
3,3,2,2,2,2,2,2,2,3,3,3,3,3
3,3,2,2,2,2,2,2,1,3,3,23,22,3
3,2,2,2,2,2,2,6,3,3,3,25,24,3
2,2,2,2,2,2,1,3,3,3,3,3,3,3
2,2,2,2,2,6,3,3,3,3,3,3,3,3
6,2,2,3,3,3,3,3,3,3,3,3,3,3
3,3,3,3,3,3,3,3,3,3,3,3,3,3
3,3,3,3,3,3,3,3,3,3,3,3,3,3
3,3,3,3,3,3,3,3,3,3,3,3,3,3
3,3,3,3,3,3,3,3,3,3,3,3,3,3
endlayer

layer
3,3,3,3,3,3,2,2,8,3,3,3,3,3
3,3,3,3,10,2,2,2,2,1,3,3,3,3
3,3,3,2,2,2,2,2,2,3,3,3,3,3
3,3,2,2,2,2,2,2,2,3,3,3,3,3
3,3,2,2,2,2,2,2,1,3,3,3,3,3
3,2,2,2,2,2,2,6,3,3,3,19,18,3
3,2,2,2,2,2,6,3,3,3,3,21,20,3
10,2,2,2,2,1,3,3,3,3,3,3,3,3
2,2,2,2,6,3,3,3,3,3,3,3,3,3
3,2,6,3,3,3,3,3,3,3,3,3,3,3
3,3,3,3,3,3,3,3,3,3,3,3,3,3
3,3,3,3,3,3,3,3,3,3,3,3,3,3
3,3,3,3,3,3,3,3,3,3,3,3,3,3
3,3,3,3,3,3,3,3,3,3,3,3,3,3
endlayer

layer
3,3,3,3,3,3,10,8,3,3,3,3,3,3
3,3,3,3,3,2,2,2,2,3,3,3,3,3
3,3,9,2,2,2,2,2,2,3,3,3,3,3
3,3,2,2,2,2,2,2,1,3,3,3,3,3
3,8,2,2,2,2,2,1,3,3,3,3,3,3
3,2,2,2,2,2,6,3,3,3,3,23,22,3
3,2,2,2,2,1,3,3,3,3,3,25,24,3
3,2,2,2,6,3,3,3,3,3,3,3,3,3
3,10,2,1,3,3,3,3,3,3,3,3,3,3
3,3,3,3,3,3,3,3,3,3,3,3,3,3
3,3,3,3,3,3,3,3,3,3,3,3,3,3
3,3,3,3,3,3,3,3,3,3,3,3,3,3
3,3,3,3,3,3,3,3,3,3,3,3,3,3
3,3,3,3,3,3,3,3,3,3,3,3,3,3
endlayer

layer
3,3,3,3,3,3,3,3,3,3,3,3,3,3
3,3,3,3,10,2,2,2,3,3,3,3,3,3
3,3,3,2,2,2,2,2,3,3,3,3,3,3
3,3,2,2,2,2,2,1,3,3,3,3,3,3
3,3,2,2,2,2,6,3,3,3,3,3,3,3
3,2,2,2,2,2,3,3,3,3,3,19,18,3
3,2,2,2,1,3,3,3,3,3,3,21,20,3
3,2,2,6,3,3,3,3,3,3,3,3,3,3
3,3,6,3,3,3,3,3,3,3,3,3,3,3
3,3,3,3,3,3,3,3,3,3,3,3,3,3
3,3,3,3,3,3,3,3,3,3,3,3,3,3
3,3,3,3,3,3,3,3,3,3,3,3,3,3
3,3,3,3,3,3,3,3,3,3,3,3,3,3
3,3,3,3,3,3,3,3,3,3,3,3,3,3
endlayer

layer
3,3,3,3,3,3,3,3,3,3,3,3,3,3
3,3,3,3,2,2,3,3,3,3,3,3,3,3
3,3,10,2,2,2,2,1,3,3,3,3,3,3
3,3,2,2,2,2,2,3,3,3,3,3,3,3
3,12,2,2,2,2,3,3,3,3,3,3,3,3
3,2,2,2,2,2,3,3,3,3,3,23,22,3
3,2,2,2,3,3,3,3,3,3,3,25,24,3
3,3,11,3,3,3,3,3,3,3,3,3,3,3
3,3,3,3,3,3,3,3,3,3,3,3,3,3
3,3,3,3,3,3,3,3,3,3,3,3,3,3
3,3,3,3,3,3,3,3,3,3,3,3,3,3
3,3,3,3,3,3,3,3,3,3,3,3,3,3
3,3,3,3,3,3,3,3,3,3,3,3,3,3
3,3,3,3,3,3,3,3,3,3,3,3,3,3
endlayer

layer
3,3,3,3,3,3,3,3,3,3,3,3,3,3
3,3,3,10,2,2,1,3,3,3,3,3,3,3
3,3,3,2,2,2,2,2,3,3,3,3,3,3
3,3,3,2,2,2,2,3,3,3,3,3,3,3
3,3,2,2,2,2,5,3,3,3,3,3,3,3
3,2,2,2,2,2,5,3,3,3,3,19,18,3
3,2,2,2,5,5,3,3,3,3,3,21,20,3
3,11,2,3,3,3,3,3,3,3,3,3,3,3
3,3,3,3,3,3,3,3,3,3,3,3,3,3
3,3,3,3,3,3,3,3,3,3,3,3,3,3
3,3,3,3,3,3,3,3,3,3,3,3,3,3
3,3,3,3,3,3,3,3,3,3,3,3,3,3
3,3,3,3,3,3,3,3,3,3,3,3,3,3
3,3,3,3,3,3,3,3,3,3,3,3,3,3
endlayer

layer
3,3,3,3,3,3,3,3,3,3,3,3,3,3
3,3,3,3,3,2,2,3,3,3,3,3,3,3
3,3,10,2,2,2,2,1,3,3,3,3,3,3
3,3,9,2,2,2,2,3,3,3,3,3,3,3
3,3,2,2,2,2,2,15,3,3,3,3,3,3
3,2,2,2,2,2,2,12,3,3,3,23,22,3
3,3,2,2,2,2,2,2,3,3,3,25,24,3
3,3,6,3,11,9,2,3,3,3,3,3,3,3
3,3,3,3,3,3,3,3,3,3,3,3,3,3
3,3,3,3,3,3,3,3,3,3,3,3,3,3
3,3,3,3,3,3,3,3,3,3,3,3,3,3
3,3,3,3,3,3,3,3,3,3,3,3,3,3
3,3,3,3,3,3,3,3,3,3,3,3,3,3
3,3,3,3,3,3,3,3,3,3,3,3,3,3
endlayer

layer
3,3,3,3,3,3,3,3,3,3,3,3,3,3
3,3,3,3,10,2,3,3,3,3,3,3,3,3
3,3,3,2,2,2,2,3,3,3,3,3,3,3
3,3,10,2,2,2,2,2,3,3,3,3,3,3
3,12,2,2,2,2,2,2,3,3,3,3,3,3
3,2,2,2,2,2,2,2,3,3,3,19,18,3
3,2,2,2,2,2,2,2,3,3,3,21,20,3
3,3,2,3,2,2,2,3,3,3,3,3,3,3
3,3,3,3,3,3,3,3,3,3,3,3,3,3
3,3,3,3,3,3,3,3,3,3,3,3,3,3
3,3,3,3,3,3,3,3,3,3,3,3,3,3
3,3,3,3,3,3,3,3,3,3,3,3,3,3
3,3,3,3,3,3,3,3,3,3,3,3,3,3
3,3,3,3,3,3,3,3,3,3,3,3,3,3
endlayer

layer
3,3,3,3,3,3,3,3,3,3,3,3,3,3
3,3,3,3,3,15,3,3,3,3,3,3,3,3
3,3,3,3,2,2,2,2,3,3,3,3,3,3
3,3,2,2,2,2,2,2,3,3,3,3,3,3
3,3,2,2,2,2,2,2,3,3,3,3,3,3
3,2,2,2,2,2,2,2,3,3,3,23,22,3
3,3,2,2,2,2,2,2,3,3,3,25,24,3
3,3,3,2,2,2,2,3,3,3,3,3,3,3
3,3,3,3,3,3,3,3,3,3,3,3,3,3
3,3,3,3,3,3,3,3,3,3,3,3,3,3
3,3,3,3,3,3,3,3,3,3,3,3,3,3
3,3,3,3,3,3,3,3,3,3,3,3,3,3
3,3,3,3,3,3,3,3,3,3,3,3,3,3
3,3,3,3,3,3,3,3,3,3,3,3,3,3
endlayer

layer
3,3,3,3,3,3,3,3,3,3,3,3,3,3
3,3,3,3,3,3,3,3,3,3,3,3,3,3
3,3,3,2,2,2,2,1,3,3,3,3,3,3
3,3,3,2,2,2,2,2,3,3,3,3,3,3
3,3,2,2,2,2,2,2,3,3,3,3,3,3
3,3,2,2,2,2,2,2,3,3,3,19,18,3
3,3,2,2,2,2,2,3,3,3,3,21,20,3
3,3,3,6,2,2,2,3,3,3,3,3,3,3
3,3,3,3,3,3,3,3,3,3,3,3,3,3
3,3,3,3,3,3,3,3,3,3,3,3,3,3
3,3,3,3,3,3,3,3,3,3,3,3,3,3
3,3,3,3,3,3,3,3,3,3,3,3,3,3
3,3,3,3,3,3,3,3,3,3,3,3,3,3
3,3,3,3,3,3,3,3,3,3,3,3,3,3
endlayer

layer
3,3,3,3,3,3,3,3,3,3,3,3,3,3
3,3,3,3,3,3,3,3,3,3,3,3,3,3
3,3,3,3,2,2,3,3,3,3,3,3,3,3
3,3,3,2,2,2,2,2,3,3,3,3,3,3
3,3,2,2,2,2,2,2,3,3,3,3,3,3
3,3,2,2,2,2,2,2,3,3,3,23,22,3
3,3,3,2,2,2,2,3,3,3,3,25,24,3
3,3,3,3,2,2,2,3,3,3,3,3,3,3
3,3,3,3,3,3,3,3,3,3,3,3,3,3
3,3,3,3,3,3,3,3,3,3,3,3,3,3
3,3,3,3,3,3,3,3,3,3,3,3,3,3
3,3,3,3,3,3,3,3,3,3,3,3,3,3
3,3,3,3,3,3,3,3,3,3,3,3,3,3
3,3,3,3,3,3,3,3,3,3,3,3,3,3
endlayer

layer
3,3,3,3,3,3,3,3,3,3,3,3,3,3
3,3,3,3,3,3,3,3,3,3,3,3,3,3
3,3,3,3,3,3,3,3,3,3,3,3,3,3
3,3,3,3,2,2,2,1,3,3,3,3,3,3
3,3,3,2,2,2,2,2,3,3,3,3,3,3
3,3,3,2,2,2,2,3,3,3,3,19,18,3
3,3,3,10,2,2,2,3,3,3,3,21,20,3
3,3,3,3,6,2,3,3,3,3,3,3,3,3
3,3,3,3,3,3,3,3,3,3,3,3,3,3
3,3,3,3,3,3,3,3,3,3,3,3,3,3
3,3,3,3,3,3,3,3,3,3,3,3,3,3
3,3,3,3,3,3,3,3,3,3,3,3,3,3
3,3,3,3,3,3,3,3,3,3,3,3,3,3
3,3,3,3,3,3,3,3,3,3,3,3,3,3
endlayer

layer
3,3,3,3,3,3,3,3,3,3,3,3,3,3
3,3,3,3,3,3,3,3,3,3,3,3,3,3
3,3,3,3,3,3,3,3,3,3,3,3,3,3
3,3,3,3,3,3,3,3,3,3,3,3,3,3
3,3,3,3,3,3,3,3,3,3,3,3,3,3
3,3,3,3,3,3,3,3,3,3,3,23,22,3
3,3,3,3,3,3,3,3,3,3,3,25,24,3
3,3,3,3,3,3,3,3,3,3,3,3,3,3
3,3,3,3,3,3,3,3,3,3,3,3,3,3
3,3,3,3,3,3,3,3,3,3,3,3,3,3
3,3,3,3,3,3,3,3,3,3,3,3,3,3
3,3,3,3,3,3,3,3,3,3,3,3,3,3
3,3,3,3,3,3,3,3,3,3,3,3,3,3
3,3,3,3,3,3,3,3,3,3,3,3,3,3
endlayer

layer
3,3,3,3,3,3,3,3,3,3,3,3,3,3
3,3,3,3,3,3,3,3,3,3,3,3,3,3
3,3,3,3,3,3,3,3,3,3,3,3,3,3
3,3,3,3,3,3,3,3,3,3,3,3,3,3
3,3,3,3,3,3,3,3,3,3,3,3,3,3
3,3,3,3,3,3,3,3,3,3,3,16,16,3
3,3,3,3,3,3,3,3,3,3,3,16,16,3
3,3,3,3,3,3,3,3,3,3,3,3,3,3
3,3,3,3,3,3,3,3,3,3,3,3,3,3
3,3,3,3,3,3,3,3,3,3,3,3,3,3
3,3,3,3,3,3,3,3,3,3,3,3,3,3
3,3,3,3,3,3,3,3,3,3,3,3,3,3
3,3,3,3,3,3,3,3,3,3,3,3,3,3
3,3,3,3,3,3,3,3,3,3,3,3,3,3
endlayer

