
# Created by Ruins mod version 16.7 Ingame Parser
# authoring Player: lafuller

weight=1
embed_into_distance=4
acceptable_target_blocks=
unacceptable_target_blocks=flowing_water,water,flowing_lava,lava,ice,bedrock,netherrack,nether_brick,nether_brick_fence,soul_sand,quartz_ore,gravel,end_stone,obsidian,iron_bars,cloud,flesh,ash_block,slime_grass,slime_congealed,slime_dirt
dimensions=16,12,12
allowable_overhang=0
max_leveling=4
leveling_buffer=-1
preserve_water=0
preserve_lava=0

rule1=0,100,air
rule2=0,100,preserveBlock
rule3=0,100,stonebrick-0,stonebrick-1,stonebrick-1,stonebrick-1,stonebrick-2,stonebrick-2,stone-5,stone-5,stone-6,cobblestone,cobblestone
rule4=0,100,minecraft:stone-6
rule5=0,100,stonebrick-0,stonebrick-2,stonebrick-1,stonebrick-1,stonebrick-1,cobblestone
rule6=0,100,stonebrick-0,stonebrick-1,stonebrick-2,stonebrick-2,stone-5,stone-5,stone-6,stone-6
rule7=0,100,stonebrick-0,stonebrick-2,stonebrick-0,stonebrick-1,stonebrick-1,cobblestone
rule8=0,100,minecraft:stone_brick_stairs-0
rule9=0,100,minecraft:stone_brick_stairs-2
rule10=0,100,stonebrick-0,stonebrick-1,stonebrick-1,stonebrick-1,stonebrick-2,stonebrick-2,stone-5,stone-5,stone-6,cobblestone,cobblestone,gravel
rule11=0,100,minecraft:cobblestone_wall-0
rule12=0,100,minecraft:stone-5
rule13=0,100,minecraft:log-0
rule14=0,100,minecraft:wooden_slab-9
rule15=0,100,minecraft:planks-1
rule16=0,100,minecraft:wooden_slab-1
rule17=0,100,minecraft:web-0,air,air,air
rule18=0,100,bookshelf,hay_block,ChestGenHook:chests/spawn_bonus_chest:5-3,ChestGenHook:chests/village_blacksmith:4-3,ChestGenHook:chests/simple_dungeon:5-3,ChestGenHook:chests/abandoned_mineshaft:4-3,ChestGenHook:chests/stronghold_library:3-3,ChestGenHook:chests/stronghold_corridor:2-3,ChestGenHook:chests/stronghold_crossing:2-2,ChestGenHook:chests/igloo_chest:4-3
rule19=0,100,minecraft:stone_brick_stairs-7
rule20=0,100,minecraft:spruce_stairs-0
rule21=0,100,minecraft:spruce_stairs-7
rule22=0,100,minecraft:stone_brick_stairs-5
rule23=0,100,minecraft:stone_brick_stairs-4
rule24=0,100,minecraft:stone_brick_stairs-6
rule25=0,100,minecraft:planks-0
rule26=0,100,minecraft:stone_brick_stairs-3
rule27=0,100,minecraft:oak_stairs-0
rule28=0,100,minecraft:log2-1
rule29=0,100,minecraft:oak_stairs-2
rule30=0,100,minecraft:spruce_fence-0
rule31=0,100,minecraft:spruce_fence_gate-2
rule32=0,100,minecraft:oak_stairs-3
rule33=0,100,minecraft:oak_stairs-1
rule34=0,100,minecraft:jungle_door-2
rule35=0,100,minecraft:fence-0
rule36=0,100,minecraft:furnace-5
rule37=0,100,minecraft:oak_stairs-4
rule38=0,100,minecraft:jungle_door-8
rule39=0,100,minecraft:wooden_slab-13
rule40=0,100,minecraft:spruce_stairs-6
rule41=0,100,minecraft:spruce_stairs-4
rule42=0,100,minecraft:stone_brick_stairs-1
rule43=0,100,minecraft:spruce_stairs-5
rule44=0,100,minecraft:spruce_fence_gate-1
rule45=0,100,minecraft:dark_oak_stairs-2
rule46=0,100,minecraft:dark_oak_stairs-3
rule47=0,100,minecraft:dark_oak_stairs-7
rule48=0,100,minecraft:dark_oak_stairs-4
rule49=0,100,minecraft:wooden_slab-5
rule50=0,100,minecraft:dark_oak_stairs-0
rule51=0,100,minecraft:dark_oak_stairs-5
rule52=0,100,minecraft:planks-5
rule53=0,100,minecraft:dark_oak_stairs-6
rule54=0,100,minecraft:dark_oak_stairs-1
rule55=0,100,minecraft:dark_oak_fence-0
rule56=0,100,minecraft:trapdoor-2
rule57=0,100,minecraft:stone_slab-0

layer
2,2,2,2,2,2,2,2,2,2,2,2
2,2,2,2,2,2,3,3,3,2,2,2
2,2,2,3,3,4,5,5,5,4,2,2
2,2,3,3,5,5,6,6,6,5,3,2
2,2,4,5,6,6,7,6,6,5,3,2
8,3,5,6,7,6,7,7,6,5,3,2
4,3,5,6,7,7,7,7,6,5,4,2
2,3,5,6,6,7,7,6,5,3,2,2
4,4,5,5,5,6,6,6,5,3,2,2
2,3,3,3,3,5,5,5,4,2,2,2
2,3,3,3,3,4,3,3,9,2,2,2
4,4,2,2,4,2,4,3,9,2,2,2
endlayer

layer
2,2,2,2,2,2,2,2,2,2,2,2
2,2,2,2,2,2,10,11,10,2,2,2
2,2,2,3,3,12,14,14,13,12,2,2
2,2,10,10,13,17,1,1,16,15,10,2
2,2,12,17,1,1,1,1,16,15,11,2
2,10,13,1,1,1,1,1,13,15,10,2
8,11,14,1,1,1,1,1,1,18,12,2
19,10,14,1,1,1,1,1,1,10,2,2
10,12,13,17,1,1,1,17,13,10,2,2
2,10,10,10,10,13,14,14,12,2,2,2
2,10,10,10,10,12,11,10,2,2,2,2
10,10,2,2,10,2,10,9,2,2,2,2
endlayer

layer
2,2,2,2,2,2,2,2,2,2,2,2
2,2,2,2,2,2,10,11,10,2,2,2
2,2,2,3,3,4,17,17,13,4,2,2
2,2,10,10,13,17,1,1,1,1,10,2
2,2,4,17,17,1,1,1,1,1,11,2
2,10,13,17,1,1,1,1,13,20,10,2
2,11,17,1,1,1,1,1,17,21,4,2
8,10,17,1,1,1,1,1,17,10,2,2
10,4,13,17,17,17,1,17,13,10,2,2
22,10,10,10,10,13,17,17,4,2,2,2
23,10,10,10,10,4,11,10,2,2,2,2
10,10,2,2,10,22,9,2,2,2,2,2
endlayer

layer
2,2,2,2,2,2,2,2,2,2,2,2
2,2,2,2,2,2,10,11,10,2,2,2
2,2,2,3,3,12,17,17,13,12,2,2
2,2,10,10,13,17,17,1,1,1,10,2
2,2,12,17,17,17,1,1,1,1,11,2
2,10,13,17,17,1,1,1,13,1,10,2
2,11,17,17,1,1,1,17,21,20,12,2
2,10,17,17,17,1,17,17,21,10,2,2
8,12,13,17,17,17,17,17,13,10,2,2
10,10,10,10,10,13,17,17,12,2,2,2
10,10,10,10,10,12,11,10,2,2,2,2
10,10,24,19,10,9,2,2,2,2,2,2
endlayer

layer
2,2,2,2,2,2,2,2,2,2,2,2
2,2,2,2,2,2,10,10,10,2,2,2
2,2,2,3,3,4,15,15,15,4,2,2
2,2,10,10,15,15,25,25,14,1,10,2
2,2,4,15,25,25,15,25,14,1,10,2
2,10,15,25,15,15,15,25,13,1,10,2
2,10,15,25,15,15,25,15,16,1,4,2
2,10,15,25,25,15,15,25,20,10,2,2
2,4,15,15,15,25,25,25,15,10,2,2
2,26,10,3,10,15,15,15,4,2,2,2
2,26,3,3,3,4,10,10,2,2,2,2
2,26,3,3,9,2,2,2,2,2,2,2
endlayer

layer
2,2,2,2,2,2,2,2,2,2,2,2
2,2,2,2,2,1,27,27,27,1,2,2
2,2,2,19,10,28,1,1,1,28,1,2
2,2,27,10,22,1,1,1,30,1,29,2
2,1,28,1,1,1,1,1,31,1,29,2
2,32,1,1,1,1,1,1,13,1,29,2
2,32,1,1,1,1,1,1,1,1,28,2
2,32,1,1,1,1,1,1,1,33,2,2
2,28,1,1,1,1,1,1,1,29,2,2
2,1,25,34,27,1,1,1,28,1,2,2
2,2,1,1,1,28,33,33,2,2,2,2
2,2,2,2,2,2,2,2,2,2,2,2
endlayer

layer
2,2,2,2,2,2,2,2,2,2,2,2
2,2,2,2,2,35,35,1,35,35,2,2
2,2,2,8,23,28,1,1,1,28,35,2
2,2,35,10,36,1,1,1,1,1,35,2
2,35,28,1,1,1,1,1,1,1,1,2
2,35,1,1,1,1,1,1,13,1,35,2
2,1,1,1,1,1,1,1,1,1,28,2
2,35,1,1,1,1,1,1,1,35,2,2
2,28,1,1,1,1,1,1,1,1,2,2
2,1,25,38,37,1,1,1,28,1,2,2
2,2,1,1,1,28,1,35,35,2,2,2
2,2,2,2,2,2,2,2,2,2,2,2
endlayer

layer
2,2,2,2,2,39,2,2,2,2,2,2
2,2,2,2,2,39,41,41,41,40,39,2
2,2,39,19,10,28,1,1,1,28,41,2
2,39,41,10,42,1,1,1,1,1,40,2
2,41,28,1,1,1,1,1,1,1,40,2
2,21,1,1,1,1,1,1,13,1,40,2
2,21,1,1,1,1,1,1,1,1,28,2
2,21,1,1,1,1,1,1,1,43,2,2
2,28,1,1,1,1,1,1,1,40,2,2
39,21,43,44,43,1,1,1,28,43,2,2
2,2,1,1,1,28,43,43,40,39,2,2
2,2,2,2,2,2,2,2,2,2,2,2
endlayer

layer
2,2,2,2,2,2,46,39,39,45,2,2
2,2,2,46,48,47,15,15,15,45,2,2
2,2,50,10,10,28,1,1,1,28,50,49
2,49,52,10,24,1,1,1,1,1,15,51
49,52,28,1,1,1,1,1,1,1,15,39
47,15,1,1,1,1,1,1,13,1,15,48
39,15,1,1,1,1,1,1,1,1,28,49
47,15,1,1,1,1,1,1,1,15,39,2
49,28,1,1,1,1,1,1,1,15,53,2
2,46,15,15,15,1,1,1,28,52,49,2
2,49,51,39,51,28,15,15,52,49,2,2
2,2,2,2,2,46,39,39,45,2,2,2
endlayer

layer
2,2,2,2,2,2,2,50,49,2,2,2
2,2,2,2,2,50,52,52,52,2,2,2
2,2,2,49,50,52,43,43,43,52,2,2
2,2,50,10,10,43,1,1,1,21,45,2
2,2,52,40,1,1,1,1,1,21,52,45
2,46,40,1,1,1,1,1,13,21,52,2
46,52,40,1,1,1,1,1,1,21,52,2
2,52,40,1,1,1,1,1,41,52,45,2
2,46,40,41,40,1,1,1,21,52,2,2
2,2,54,52,52,41,41,41,52,2,2,2
2,2,2,49,52,52,52,54,49,2,2,2
2,2,2,2,2,2,54,2,2,2,2,2
endlayer

layer
2,2,2,2,2,2,2,2,2,2,2,2
2,2,2,2,2,2,49,50,2,2,2,2
2,2,2,2,2,50,52,52,52,2,2,2
2,2,2,10,10,52,15,15,15,45,2,2
2,2,49,52,15,43,43,21,15,52,45,2
2,2,46,15,15,14,1,21,15,52,49,2
2,49,52,15,15,14,14,21,15,52,2,2
2,2,52,15,15,15,15,15,52,45,2,2
2,2,49,54,52,15,15,15,45,2,2,2
2,2,2,49,54,52,52,54,2,2,2,2
2,2,2,2,2,49,54,2,2,2,2,2
2,2,2,2,2,2,2,2,2,2,2,2
endlayer

layer
2,2,2,2,2,2,2,2,2,2,2,2
2,2,2,2,2,2,2,2,2,2,2,2
2,2,2,2,2,2,49,50,2,2,2,2
2,2,2,8,10,50,52,52,45,2,2,2
2,2,2,49,52,52,52,52,52,2,2,2
2,2,2,46,52,52,55,52,52,45,2,2
2,2,2,46,52,52,52,52,52,2,2,2
2,2,2,49,52,52,52,52,45,2,2,2
2,2,2,2,49,52,52,52,2,2,2,2
2,2,2,2,2,49,54,2,2,2,2,2
2,2,2,2,2,2,2,2,2,2,2,2
2,2,2,2,2,2,2,2,2,2,2,2
endlayer

layer
2,2,2,2,2,2,2,2,2,2,2,2
2,2,2,2,2,2,2,2,2,2,2,2
2,2,2,2,2,2,2,2,2,2,2,2
2,2,2,22,8,2,55,55,2,2,2,2
2,2,2,2,55,55,49,55,55,2,2,2
2,2,2,2,55,49,56,49,55,2,2,2
2,2,2,2,55,49,49,55,55,2,2,2
2,2,2,2,55,55,49,55,2,2,2,2
2,2,2,2,2,55,55,55,2,2,2,2
2,2,2,2,2,2,2,2,2,2,2,2
2,2,2,2,2,2,2,2,2,2,2,2
2,2,2,2,2,2,2,2,2,2,2,2
endlayer

layer
2,2,2,2,2,2,2,2,2,2,2,2
2,2,2,2,2,2,2,2,2,2,2,2
2,2,2,2,2,2,2,2,2,2,2,2
2,2,2,10,10,2,2,2,2,2,2,2
2,2,2,2,2,2,2,2,2,2,2,2
2,2,2,2,2,2,2,2,2,2,2,2
2,2,2,2,2,2,2,2,2,2,2,2
2,2,2,2,2,2,2,2,2,2,2,2
2,2,2,2,2,2,2,2,2,2,2,2
2,2,2,2,2,2,2,2,2,2,2,2
2,2,2,2,2,2,2,2,2,2,2,2
2,2,2,2,2,2,2,2,2,2,2,2
endlayer

layer
2,2,2,2,2,2,2,2,2,2,2,2
2,2,2,2,2,2,2,2,2,2,2,2
2,2,2,2,2,2,2,2,2,2,2,2
2,2,2,11,11,2,2,2,2,2,2,2
2,2,2,2,2,2,2,2,2,2,2,2
2,2,2,2,2,2,2,2,2,2,2,2
2,2,2,2,2,2,2,2,2,2,2,2
2,2,2,2,2,2,2,2,2,2,2,2
2,2,2,2,2,2,2,2,2,2,2,2
2,2,2,2,2,2,2,2,2,2,2,2
2,2,2,2,2,2,2,2,2,2,2,2
2,2,2,2,2,2,2,2,2,2,2,2
endlayer

layer
2,2,2,2,2,2,2,2,2,2,2,2
2,2,2,2,2,2,2,2,2,2,2,2
2,2,2,2,2,2,2,2,2,2,2,2
2,2,2,57,57,2,2,2,2,2,2,2
2,2,2,2,2,2,2,2,2,2,2,2
2,2,2,2,2,2,2,2,2,2,2,2
2,2,2,2,2,2,2,2,2,2,2,2
2,2,2,2,2,2,2,2,2,2,2,2
2,2,2,2,2,2,2,2,2,2,2,2
2,2,2,2,2,2,2,2,2,2,2,2
2,2,2,2,2,2,2,2,2,2,2,2
2,2,2,2,2,2,2,2,2,2,2,2
endlayer

