# Gilly's Sliding Catacombs spawn proxy

# template generated using Ruins mod version 16.5 Ingame Parser
# Structure created and developed by Gilly

weight=1
embed_into_distance=30
uniqueMinDistance=500
acceptable_target_blocks=
unacceptable_target_blocks=flowing_water,water,flowing_lava,lava,ice,bedrock,netherrack,nether_brick,nether_brick_fence,soul_sand,quartz_ore,gravel,end_stone,obsidian,iron_bars,cloud,flesh,ash_block,slime_grass,slime_congealed,slime_dirt
biomesToSpawnIn=plains,mutated_plains,meadow,forest,taiga,woodland,woodlands,fen,brushland,shrubland,outback,chaparral,savanna,badlands,birch forest
dimensions=37,11,11
allowable_overhang=0
max_leveling=3
leveling_buffer=-1
preserve_water=0
preserve_lava=0
preserve_plants=0
adjoining_template=Gilly/GillyD1;22;36;22;100
adjoining_template=Gilly/GillyD1;11;36;22;100
adjoining_template=Gilly/GillyD1;0;36;22;100
adjoining_template=Gilly/GillyD1;-11;36;22;100
adjoining_template=Gilly/GillyD1;-22;36;22;100

adjoining_template=Gilly/GillyD1;22;36;11;100
adjoining_template=Gilly/GillyD1;11;36;11;100
adjoining_template=Gilly/GillyD2;0;36;11;100
adjoining_template=Gilly/GillyD1;-11;36;11;100
adjoining_template=Gilly/GillyD1;-22;36;11;100

adjoining_template=Gilly/GillyD1;22;36;0;100
adjoining_template=Gilly/GillyD2;11;36;0;100

adjoining_template=Gilly/GillyD2;-11;36;0;100
adjoining_template=Gilly/GillyD1;-22;36;0;100

adjoining_template=Gilly/GillyD1;22;36;-11;100
adjoining_template=Gilly/GillyD1;11;36;-11;100
adjoining_template=Gilly/GillyD2;0;36;-11;100
adjoining_template=Gilly/GillyD1;-11;36;-11;100
adjoining_template=Gilly/GillyD1;-22;36;-11;100

adjoining_template=Gilly/GillyD1;22;36;-22;100
adjoining_template=Gilly/GillyD1;11;36;-22;100
adjoining_template=Gilly/GillyD1;0;36;-22;100
adjoining_template=Gilly/GillyD1;-11;36;-22;100
adjoining_template=Gilly/GillyD1;-22;36;-22;100

rule1=0,100,stonebrick,stonebrick,stonebrick,stonebrick,stonebrick,stonebrick,stonebrick-2,stonebrick-1
rule2=0,100,minecraft:stone_slab-5
rule3=0,100,minecraft:cobblestone_wall-0
rule4=0,100,minecraft:stone_brick_stairs-0
rule5=0,100,minecraft:stone_brick_stairs-3
rule6=0,100,minecraft:stone_brick_stairs-1
rule7=0,100,minecraft:stone_brick_stairs-2
rule8=0,100,minecraft:water-0
rule9=0,100,minecraft:stone_slab-13
rule10=0,100,minecraft:stone_brick_stairs-6
rule11=0,100,minecraft:stone_brick_stairs-5
rule12=0,100,minecraft:stone_brick_stairs-4
rule13=0,100,minecraft:stone_brick_stairs-7
rule14=0,100,minecraft:ladder-3
rule15=0,100,minecraft:ladder-5
rule16=0,100,minecraft:ladder-4
rule17=0,100,minecraft:ladder-2
rule18=0,100,minecraft:iron_bars-0
rule19=0,100,minecraft:emerald_block-0
rule20=0,100,preserveBlock

layer
1,1,1,1,1,2,1,1,1,1,1
1,1,1,1,1,1,1,1,1,1,1
1,1,1,1,1,1,1,1,1,1,1
1,1,1,1,1,1,1,1,1,1,1
1,1,1,1,3,3,3,1,1,1,1
2,1,1,1,3,3,3,1,1,1,2
1,1,1,1,3,3,3,1,1,1,1
1,1,1,1,1,1,1,1,1,1,1
1,1,1,1,1,1,1,1,1,1,1
1,1,1,1,1,1,1,1,1,1,1
1,1,1,1,1,2,1,1,1,1,1
endlayer

layer
1,1,1,1,1,0,0,2,1,1,1
1,1,1,1,1,4,4,4,1,1,1
1,1,1,1,1,1,1,1,1,1,1
2,5,1,7,6,6,6,5,1,1,1
0,5,1,7,8,8,8,5,1,1,1
0,5,1,7,8,8,8,5,1,7,0
1,1,1,7,8,8,8,5,1,7,0
1,1,1,7,4,4,4,5,1,7,2
1,1,1,1,1,1,1,1,1,1,1
1,1,1,6,6,6,1,1,1,1,1
1,1,1,2,0,0,1,1,1,1,1
endlayer

layer
1,1,1,1,1,0,0,0,0,2,1
2,1,1,1,7,0,0,0,0,1,1
0,0,0,0,0,0,0,0,0,1,1
0,0,0,0,0,0,0,0,0,1,1
0,0,0,0,0,0,0,0,0,6,1
0,0,0,0,0,0,0,0,0,0,0
1,4,0,0,0,0,0,0,0,0,0
1,1,0,0,0,0,0,0,0,0,0
1,1,0,0,0,0,0,0,0,0,0
1,1,0,0,0,0,5,1,1,1,2
1,2,0,0,0,0,1,1,1,1,1
endlayer

layer
1,1,1,1,1,0,0,0,0,0,1
0,1,1,7,0,0,0,0,0,1,1
0,0,0,0,0,0,0,0,0,1,1
0,0,0,0,0,0,0,0,0,6,1
0,0,0,0,0,0,0,0,0,0,1
0,0,0,0,0,0,0,0,0,0,0
1,0,0,0,0,0,0,0,0,0,0
1,4,0,0,0,0,0,0,0,0,0
1,1,0,0,0,0,0,0,0,0,0
1,1,0,0,0,0,0,5,1,1,0
1,0,0,0,0,0,1,1,1,1,1
endlayer

layer
1,1,1,1,1,0,0,0,0,0,1
0,1,7,0,0,0,0,0,0,1,1
0,0,0,0,0,0,0,0,0,6,1
0,0,0,0,0,0,0,0,0,0,1
0,0,0,0,0,0,0,0,0,0,1
0,0,0,0,0,0,0,0,0,0,0
1,0,0,0,0,0,0,0,0,0,0
1,0,0,0,0,0,0,0,0,0,0
1,4,0,0,0,0,0,0,0,0,0
1,1,0,0,0,0,0,0,5,1,0
1,0,0,0,0,0,1,1,1,1,1
endlayer

layer
1,0,2,1,1,10,9,0,0,0,1
0,1,0,0,0,0,0,0,0,1,0
0,0,0,0,0,0,0,0,0,0,2
0,0,0,0,0,0,0,0,0,0,1
9,0,0,0,0,0,0,0,0,0,1
12,0,0,0,0,0,0,0,0,0,11
1,0,0,0,0,0,0,0,0,0,9
1,0,0,0,0,0,0,0,0,0,0
2,0,0,0,0,0,0,0,0,0,0
0,1,0,0,0,0,0,0,0,1,0
1,0,0,0,9,13,1,1,2,0,1
endlayer

layer
1,0,0,0,2,1,1,1,1,1,1
1,1,0,0,0,0,0,0,0,1,0
1,0,0,0,0,0,0,0,0,0,0
1,0,0,0,0,0,0,0,0,0,0
1,0,0,0,0,0,0,0,0,0,2
1,0,0,0,0,0,0,0,0,0,1
2,0,0,0,0,0,0,0,0,0,1
0,0,0,0,0,0,0,0,0,0,1
0,0,0,0,0,0,0,0,0,0,1
0,1,0,0,0,0,0,0,0,1,1
1,1,1,1,1,1,2,0,0,0,1
endlayer

layer
1,0,0,0,0,0,2,1,1,1,1
1,1,0,0,0,0,0,0,0,1,0
1,0,0,0,0,0,0,0,0,0,0
1,0,0,0,0,0,0,0,0,0,0
2,0,0,0,0,0,0,0,0,0,0
0,0,0,0,0,0,0,0,0,0,0
0,0,0,0,0,0,0,0,0,0,2
0,0,0,0,0,0,0,0,0,0,1
0,0,0,0,0,0,0,0,0,0,1
0,1,0,0,0,0,0,0,0,1,1
1,1,1,1,2,0,0,0,0,0,1
endlayer

layer
1,0,0,0,0,0,0,0,2,1,1
1,1,0,0,0,0,0,0,0,1,0
2,0,0,0,0,0,0,0,0,0,0
0,0,0,0,0,0,0,0,0,0,0
0,0,0,0,0,0,0,0,0,0,0
0,0,0,0,0,0,0,0,0,0,0
0,0,0,0,0,0,0,0,0,0,0
0,0,0,0,0,0,0,0,0,0,0
0,0,0,0,0,0,0,0,0,0,2
0,1,0,0,0,0,0,0,0,1,1
1,1,2,0,0,0,0,0,0,0,1
endlayer

layer
1,0,0,0,0,0,0,0,0,14,1
15,1,0,0,0,0,0,0,0,1,0
0,0,0,0,0,0,0,0,0,0,0
0,0,0,0,0,0,0,0,0,0,0
0,0,0,0,0,0,0,0,0,0,0
0,0,0,0,0,0,0,0,0,0,0
0,0,0,0,0,0,0,0,0,0,0
0,0,0,0,0,0,0,0,0,0,0
0,0,0,0,0,0,0,0,0,0,0
0,1,0,0,0,0,0,0,0,1,16
1,17,0,0,0,0,0,0,0,0,1
endlayer

layer
1,0,0,0,0,0,0,0,0,14,1
15,1,0,0,0,0,0,0,0,1,0
0,0,0,0,0,0,0,0,0,0,0
0,0,0,0,0,0,0,0,0,0,0
0,0,0,0,0,0,0,0,0,0,0
0,0,0,0,0,0,0,0,0,0,0
0,0,0,0,0,0,0,0,0,0,0
0,0,0,0,0,0,0,0,0,0,0
0,0,0,0,0,0,0,0,0,0,0
0,1,0,0,0,0,0,0,0,1,16
1,17,0,0,0,0,0,0,0,0,1
endlayer

layer
1,0,0,0,0,0,0,0,0,14,1
15,1,0,0,0,0,0,0,0,1,0
0,0,0,0,0,0,0,0,0,0,0
0,0,0,0,0,0,0,0,0,0,0
0,0,0,0,0,0,0,0,0,0,0
0,0,0,0,0,0,0,0,0,0,0
0,0,0,0,0,0,0,0,0,0,0
0,0,0,0,0,0,0,0,0,0,0
0,0,0,0,0,0,0,0,0,0,0
0,1,0,0,0,0,0,0,0,1,16
1,17,0,0,0,0,0,0,0,0,1
endlayer

layer
1,10,0,0,0,0,0,0,0,14,1
15,1,9,0,0,0,0,0,9,1,11
0,9,0,0,0,0,0,0,0,9,0
0,0,0,0,0,0,0,0,0,0,0
0,0,0,0,0,0,0,0,0,0,0
0,0,0,0,0,0,0,0,0,0,0
0,0,0,0,0,0,0,0,0,0,0
0,0,0,0,0,0,0,0,0,0,0
0,9,0,0,0,0,0,0,0,9,0
12,1,9,0,0,0,0,0,9,1,16
1,17,0,0,0,0,0,0,0,13,1
endlayer

layer
1,1,10,9,0,0,0,9,13,14,1
15,0,2,1,10,9,13,1,2,0,1
11,2,1,9,0,0,0,9,1,2,11
9,1,9,0,0,0,0,0,9,1,9
0,11,0,0,0,0,0,0,0,11,0
0,9,0,0,0,0,0,0,0,9,0
0,12,0,0,0,0,0,0,0,12,0
9,1,9,0,0,0,0,0,9,1,9
12,2,1,9,0,0,0,9,1,2,12
1,0,2,1,10,9,13,1,2,0,16
1,17,10,9,0,0,0,9,13,1,1
endlayer

layer
1,1,1,1,1,1,1,1,1,14,1
15,0,0,0,0,0,0,0,0,0,1
1,0,4,4,4,4,4,4,7,0,1
1,0,5,1,9,9,9,1,7,0,1
1,0,5,9,0,0,0,9,7,0,1
1,0,5,9,0,0,0,9,7,0,1
1,0,5,9,0,0,0,9,7,0,1
1,0,5,1,9,9,9,1,7,0,1
1,0,5,6,6,6,6,6,7,0,1
1,0,0,0,0,0,0,0,0,0,16
1,17,1,1,1,1,1,1,1,1,1
endlayer

layer
1,1,1,10,9,1,9,13,1,14,1
15,0,0,0,0,0,0,0,0,0,1
1,0,0,0,0,0,0,0,0,0,1
11,0,0,5,1,1,1,1,0,0,11
9,0,0,5,18,18,18,7,0,0,9
1,0,0,5,18,19,18,7,0,0,1
9,0,0,5,18,18,18,7,0,0,9
12,0,0,1,1,1,1,7,0,0,12
1,0,0,0,0,0,0,0,0,0,1
1,0,0,0,0,0,0,0,0,0,16
1,17,1,10,9,1,9,13,1,1,1
endlayer

layer
1,1,1,1,1,1,1,1,1,11,1
10,0,0,0,0,0,0,0,0,0,1
1,0,0,0,0,0,0,0,0,0,1
1,0,0,0,5,1,1,1,0,0,1
1,0,0,0,0,0,0,0,0,0,1
1,0,0,0,0,0,0,0,0,0,1
1,0,0,0,0,0,0,0,0,0,1
1,0,0,1,1,1,7,0,0,0,1
1,0,0,0,0,0,0,0,0,0,1
1,0,0,0,0,0,0,0,0,0,13
1,12,1,1,1,1,1,1,1,1,1
endlayer

layer
1,1,1,1,1,1,1,1,1,1,1
1,0,0,0,0,0,0,0,0,0,1
1,0,0,0,0,0,0,0,0,0,1
1,0,0,0,0,5,1,1,0,0,1
1,0,0,0,0,0,0,0,0,0,1
1,0,0,0,0,0,0,0,0,0,1
1,0,0,0,0,0,0,0,0,0,1
1,0,0,1,1,7,0,0,0,0,1
1,0,0,0,0,0,0,0,0,0,1
1,0,0,0,0,0,0,0,0,0,1
1,1,1,1,1,1,1,1,1,1,1
endlayer

layer
1,1,1,1,1,1,1,1,1,1,1
1,0,0,0,0,0,0,0,0,0,1
1,0,0,0,0,0,0,0,0,0,1
1,0,0,0,0,0,5,1,0,0,1
1,0,0,0,0,0,0,11,0,0,1
1,0,0,0,0,0,0,0,0,0,1
1,0,0,12,0,0,0,0,0,0,1
1,0,0,1,7,0,0,0,0,0,1
1,0,0,0,0,0,0,0,0,0,1
1,0,0,0,0,0,0,0,0,0,1
1,1,1,1,1,1,1,1,1,1,1
endlayer

layer
1,1,20,20,20,20,20,20,20,1,1
1,1,1,1,1,1,1,1,1,1,1
20,1,0,0,0,0,0,0,0,1,20
20,1,0,0,0,0,0,0,0,1,20
20,1,0,0,0,0,0,4,0,1,20
20,1,0,12,0,0,0,11,0,1,20
20,1,0,6,0,0,0,0,0,1,20
20,1,0,0,0,0,0,0,0,1,20
20,1,0,0,0,0,0,0,0,1,20
1,1,1,1,1,1,1,1,1,1,1
1,1,20,20,20,20,20,20,20,1,1
endlayer

layer
1,1,1,1,1,1,1,1,1,1,1
1,0,0,0,0,0,0,5,1,1,1
1,0,1,1,1,1,1,1,1,1,1
1,0,1,10,0,0,0,0,1,6,1
1,0,1,12,0,0,0,0,1,0,1
1,0,1,6,0,0,0,4,1,0,1
1,0,1,0,0,0,0,11,1,0,1
1,4,1,0,0,0,0,13,1,0,1
1,1,1,1,1,1,1,1,1,0,1
1,1,1,7,0,0,0,0,0,0,1
1,1,1,1,1,1,1,1,1,1,1
endlayer

layer
1,4,1,4,1,1,1,1,1,1,1
13,0,0,0,0,0,0,0,5,1,1
1,0,1,1,1,0,1,1,1,6,1
13,0,1,1,10,0,0,0,1,0,1
1,0,1,6,0,0,0,0,1,0,1
1,0,0,0,0,0,0,0,0,0,1
1,0,1,0,0,0,0,4,1,0,1
1,0,1,0,0,0,13,1,1,0,10
1,4,1,1,1,0,1,1,1,0,1
1,1,7,0,0,0,0,0,0,0,7
1,1,1,1,1,1,6,1,1,1,1
endlayer

layer
1,4,1,1,12,1,1,1,1,7,20
5,0,0,0,0,0,0,0,0,0,20
1,0,1,1,1,1,1,1,1,0,4
5,0,1,0,5,10,0,0,1,0,1
1,0,1,0,0,0,0,0,1,0,1
1,0,0,0,0,0,0,0,0,0,1
1,0,1,0,0,0,0,0,1,0,10
1,0,1,0,0,13,7,0,1,0,7
6,0,1,1,1,1,1,1,1,0,1
20,0,0,0,0,0,0,0,0,0,1
20,5,1,1,1,1,1,11,6,6,1
endlayer

layer
1,1,12,4,4,1,1,1,7,20,20
1,0,0,0,0,0,0,0,0,0,20
1,0,1,1,1,1,1,1,1,0,20
1,0,1,0,0,5,1,10,1,0,4
1,0,1,0,0,0,0,0,1,0,1
1,0,0,0,0,0,0,0,0,0,1
1,0,1,0,0,0,0,0,1,0,7
6,0,1,0,13,7,0,0,1,0,1
20,0,1,1,1,1,1,1,1,0,10
20,0,0,0,0,0,0,0,0,0,10
20,20,5,1,1,11,1,1,6,6,1
endlayer

layer
1,4,1,1,12,1,1,7,20,20,20
13,1,1,1,1,1,1,1,12,10,20
1,1,1,1,1,1,1,1,1,10,20
13,1,1,0,0,0,5,1,1,10,20
1,1,1,0,0,0,0,11,1,1,4
1,1,1,0,0,0,0,0,1,1,1
6,1,1,12,0,0,0,0,1,1,1
20,13,1,1,7,0,0,0,1,1,7
20,13,1,1,1,1,1,1,1,1,7
20,11,11,13,1,1,1,1,1,1,10
20,20,20,5,1,1,6,11,1,1,1
endlayer

layer
1,4,12,1,1,1,7,20,20,20,20
5,1,1,1,1,1,1,4,1,1,20
1,1,1,1,1,1,1,1,1,7,20
5,1,1,0,0,0,0,0,1,1,20
1,1,1,0,0,0,0,4,1,7,20
6,1,1,12,0,0,0,11,1,1,4
20,1,1,6,0,0,0,0,1,1,1
20,5,1,0,0,0,0,0,1,1,7
20,1,1,1,1,1,1,1,1,1,1
20,1,1,1,1,1,1,1,1,1,10
20,20,20,20,5,1,1,1,1,1,1
endlayer

layer
1,12,4,12,1,7,20,20,20,20,20
1,1,1,1,1,1,12,4,4,1,20
1,1,1,1,1,1,1,1,1,7,20
1,1,1,0,0,0,0,0,1,10,20
6,1,1,12,0,0,0,0,1,1,20
20,1,1,6,0,0,0,4,1,1,20
20,13,1,0,0,0,0,11,1,1,4
20,5,1,0,0,0,0,0,1,1,1
20,1,1,1,1,1,1,1,1,1,1
20,1,6,11,6,1,1,1,1,1,1
20,20,20,20,20,5,1,1,1,1,1
endlayer

layer
5,4,4,4,7,20,20,20,20,20,20
5,1,1,1,1,1,12,4,4,1,20
5,1,1,1,1,1,1,1,1,7,20
6,1,1,1,0,0,0,0,1,10,20
20,1,1,6,0,0,0,0,1,10,20
20,6,1,0,0,0,0,0,1,1,20
20,5,1,0,0,0,0,4,1,1,20
20,5,1,0,0,0,0,1,1,1,4
20,13,1,1,1,1,1,1,1,1,7
20,1,6,11,11,1,1,1,1,1,7
20,20,20,20,20,20,5,6,6,6,7
endlayer

layer
20,20,20,20,20,20,20,20,20,20,20
20,5,4,4,1,1,12,4,12,1,20
20,5,1,1,1,1,1,1,1,10,20
20,5,1,6,10,0,0,0,1,10,20
20,1,1,0,0,0,0,0,1,7,20
20,1,1,0,0,0,0,0,1,1,20
20,13,1,0,0,0,0,0,1,1,20
20,5,1,0,0,0,13,4,1,6,20
20,13,1,1,1,1,1,1,1,7,20
20,1,11,6,11,1,1,6,6,7,20
20,20,20,20,20,20,20,20,20,20,20
endlayer

layer
20,20,20,20,20,20,20,20,20,20,20
20,20,20,20,5,1,1,1,1,1,20
20,20,20,0,5,1,1,1,1,1,20
20,20,20,0,1,1,9,0,1,10,20
20,4,4,0,1,9,0,0,1,1,20
20,1,1,0,9,0,9,0,1,1,20
20,1,1,0,0,9,1,0,6,6,20
20,1,1,0,9,1,1,0,20,20,20
20,1,1,1,1,1,7,0,20,20,20
20,1,1,1,1,1,7,20,20,20,20
20,20,20,20,20,20,20,20,20,20,20
endlayer

layer
20,20,20,20,20,20,20,20,20,20,20
20,20,20,20,20,4,4,4,4,4,20
20,20,20,0,0,5,1,1,1,7,20
20,20,20,0,1,1,1,11,1,7,20
20,20,20,0,1,1,1,0,1,7,20
20,4,4,0,1,0,1,0,6,6,20
20,5,1,0,1,1,1,0,20,20,20
20,5,1,12,1,1,1,0,20,20,20
20,5,1,1,1,7,0,0,20,20,20
20,6,6,6,6,6,20,20,20,20,20
20,20,20,20,20,20,20,20,20,20,20
endlayer

layer
20,20,20,20,20,20,20,20,20,20,20
20,20,20,20,20,20,20,20,20,20,20
20,20,20,0,0,0,1,4,1,20,20
20,20,0,0,1,4,4,1,7,20,20
20,20,0,0,6,6,5,6,1,20,20
20,20,0,0,7,0,5,0,0,20,20
20,20,1,4,7,4,4,0,0,20,20
20,20,5,1,6,6,1,0,0,20,20
20,20,1,6,1,0,0,0,20,20,20
20,20,20,20,20,20,20,20,20,20,20
20,20,20,20,20,20,20,20,20,20,20
endlayer

layer
20,20,20,20,0,0,0,20,20,20,20
20,20,0,0,0,0,0,0,0,20,20
20,0,0,0,0,0,1,0,1,0,20
20,0,0,0,1,0,0,0,0,0,20
0,0,0,0,0,0,0,0,1,0,0
0,0,0,0,0,0,0,0,0,0,0
0,0,1,0,0,0,0,0,0,0,0
20,0,0,0,0,0,1,0,0,0,20
20,0,1,0,1,0,0,0,0,0,20
20,20,0,0,0,0,0,0,0,20,20
20,20,20,20,0,0,0,20,20,20,20
endlayer

layer
20,20,0,0,0,0,0,0,0,20,20
20,0,0,0,0,0,0,0,0,0,20
0,0,0,0,0,0,1,0,1,0,0
0,0,0,0,1,0,0,0,0,0,0
0,0,0,0,0,0,0,0,1,0,0
0,0,0,0,0,0,0,0,0,0,0
0,0,1,0,0,0,0,0,0,0,0
0,0,0,0,0,0,1,0,0,0,0
0,0,1,0,1,0,0,0,0,0,0
20,0,0,0,0,0,0,0,0,0,20
20,20,0,0,0,0,0,0,0,20,20
endlayer

layer
20,0,0,0,0,0,0,0,0,0,20
0,0,0,0,0,0,0,0,0,0,0
0,0,0,0,0,0,1,0,1,0,0
0,0,0,0,1,0,0,0,0,0,0
0,0,0,0,0,0,0,0,1,0,0
0,0,0,0,0,0,0,0,0,0,0
0,0,1,0,0,0,0,0,0,0,0
0,0,0,0,0,0,1,0,0,0,0
0,0,1,0,1,0,0,0,0,0,0
0,0,0,0,0,0,0,0,0,0,0
20,0,0,0,0,0,0,0,0,0,20
endlayer

layer
0,0,0,0,0,0,0,0,0,0,0
0,0,0,0,0,0,0,0,0,0,0
0,0,0,0,0,0,1,0,1,0,0
0,0,0,0,1,0,0,0,0,0,0
0,0,0,0,0,0,0,0,1,0,0
0,0,0,0,0,0,0,0,0,0,0
0,0,1,0,0,0,0,0,0,0,0
0,0,0,0,0,0,1,0,0,0,0
0,0,1,0,1,0,0,0,0,0,0
0,0,0,0,0,0,0,0,0,0,0
0,0,0,0,0,0,0,0,0,0,0
endlayer

layer
0,0,0,0,0,0,0,0,0,0,0
0,0,0,0,0,0,0,0,0,0,0
0,0,0,0,0,0,1,0,0,0,0
0,0,0,0,0,0,0,0,0,0,0
0,0,0,0,0,0,0,0,1,0,0
0,0,0,0,0,0,0,0,0,0,0
0,0,1,0,0,0,0,0,0,0,0
0,0,0,0,0,0,1,0,0,0,0
0,0,0,0,0,0,0,0,0,0,0
0,0,0,0,0,0,0,0,0,0,0
0,0,0,0,0,0,0,0,0,0,0
endlayer

