
# Created by Ruins mod version 16.7 Ingame Parser
# authoring Player: lafuller

weight=1
embed_into_distance=4
acceptable_target_blocks=
unacceptable_target_blocks=flowing_water,water,flowing_lava,lava,ice,bedrock,netherrack,nether_brick,nether_brick_fence,soul_sand,quartz_ore,end_stone,obsidian,iron_bars,cloud,flesh,ash_block,slime_grass,slime_congealed,slime_dirt
biomesToSpawnIn=plains,prarie,meadow,tundra,brushland,shrubland,woodland,woodlands,lavender_fields,flower_field,sunflower_plains,ice_flats,ice_plains
dimensions=16,12,12
allowable_overhang=0
max_leveling=4
leveling_buffer=-1
preserve_water=0
preserve_lava=0

rule1=0,100,preserveBlock
rule2=0,100,minecraft:stone-6
rule3=0,100,stonebrick-0,stonebrick-0,stonebrick-0,stonebrick-0,stonebrick-1,stonebrick-2,stonebrick-2,stone-5,stone-6,cobblestone
rule4=0,100,stonebrick-0,stonebrick-2,stonebrick-1,stonebrick-1,stonebrick-1,cobblestone
rule5=0,100,stonebrick-0,stonebrick-1,stonebrick-2,stonebrick-2,stone-5,stone-5,stone-6,stone-6
rule6=0,100,stonebrick-0,stonebrick-2,stonebrick-0,stonebrick-1,stonebrick-1,cobblestone
rule7=0,100,minecraft:stone_brick_stairs-3
rule8=0,100,minecraft:stone_brick_stairs-2
rule9=0,100,minecraft:stone-5
rule10=0,100,stonebrick-0,stonebrick-0,stonebrick-0,stonebrick-0,stonebrick-1,stonebrick-2,stonebrick-2,stone-5,stone-6,cobblestone,gravel
rule11=0,100,minecraft:cobblestone_wall-0
rule12=0,100,minecraft:log-0
rule13=0,100,minecraft:wooden_slab-9
rule14=0,100,minecraft:web-0,air,air,air
rule15=0,100,ChestGenHook:chests/spawn_bonus_chest:5-2,ChestGenHook:chests/village_blacksmith:5-2,ChestGenHook:chests/simple_dungeon:5-2,ChestGenHook:chests/abandoned_mineshaft:5-2,ChestGenHook:chests/stronghold_library:5-2,ChestGenHook:chests/stronghold_corridor:5-2,ChestGenHook:chests/stronghold_crossing:5-2,ChestGenHook:chests/igloo_chest:5-2
rule16=0,100,minecraft:planks-0
rule17=0,100,minecraft:oak_stairs-2
rule18=0,100,minecraft:oak_stairs-1
rule19=0,100,minecraft:oak_stairs-6
rule20=0,100,minecraft:oak_stairs-3
rule21=0,100,minecraft:planks-1
rule22=0,100,minecraft:oak_stairs-0
rule23=0,100,minecraft:mycelium-0
rule24=0,100,minecraft:stone_brick_stairs-4
rule25=0,100,minecraft:furnace-4
rule26=0,100,minecraft:stone_brick_stairs-1
rule27=0,100,minecraft:stone_brick_stairs-0
rule28=0,100,minecraft:stone_stairs-4
rule29=0,100,minecraft:stone_brick_stairs-6
rule30=0,100,minecraft:stone_brick_stairs-5
rule31=0,100,minecraft:stone_brick_stairs-7
rule32=0,100,minecraft:stone_stairs-1
rule33=0,100,minecraft:stone_stairs-0

layer
1,1,1,1,1,2,3,3,3,3,2,1
1,2,3,3,3,2,2,4,4,2,3,1
1,3,3,3,4,4,4,5,5,4,3,1
1,3,3,3,4,5,5,6,5,4,3,1
2,2,3,3,5,5,6,6,5,4,3,1
3,2,4,5,5,6,6,6,5,4,3,1
3,4,5,6,6,6,5,5,5,4,3,1
3,4,5,5,5,6,6,5,4,2,2,1
3,4,4,4,4,5,5,5,4,3,3,3
2,3,3,2,2,4,4,4,2,3,3,3
7,3,3,2,3,3,3,3,3,3,3,1
7,3,3,3,3,3,3,3,3,3,8,1
endlayer

layer
1,1,1,1,1,9,10,10,11,10,9,1
1,9,10,11,10,9,12,13,13,12,10,1
1,10,16,15,0,0,0,0,0,14,11,1
1,11,16,12,0,0,0,0,0,0,10,1
9,9,18,17,0,0,0,0,0,0,10,1
10,12,0,0,0,0,0,0,0,0,11,1
10,13,0,0,0,0,0,0,0,14,10,1
10,13,0,0,0,0,0,0,0,12,9,1
10,13,0,0,0,0,0,0,0,10,10,10
9,10,10,9,12,13,13,13,12,10,10,10
1,7,10,9,10,10,10,10,10,10,10,1
1,7,10,10,10,10,10,10,10,8,1,1
endlayer

layer
1,1,1,1,1,2,10,10,11,10,2,1
1,2,10,11,10,2,12,14,14,12,10,1
1,10,16,19,14,0,14,0,0,14,11,1
1,11,18,12,0,0,0,0,0,14,10,1
2,2,0,0,0,0,0,0,0,0,10,1
10,12,0,0,0,0,0,0,0,14,11,1
10,14,0,0,0,0,0,0,0,14,10,1
10,0,0,0,0,0,0,0,0,12,2,1
10,14,0,0,0,0,0,0,14,10,10,10
2,10,10,2,12,14,0,14,12,10,10,10
1,1,7,2,10,10,10,10,10,10,10,1
1,1,7,10,10,10,10,10,8,1,1,1
endlayer

layer
1,1,1,1,1,9,10,10,11,10,9,1
1,9,10,11,10,9,12,14,14,12,10,1
1,10,0,20,19,14,14,14,0,14,11,1
1,11,0,12,0,0,0,0,14,14,10,1
9,9,0,0,0,0,0,0,0,14,10,1
10,12,0,0,0,0,0,0,0,14,11,1
10,14,0,0,0,0,0,0,14,14,10,1
10,14,14,0,0,0,0,0,14,12,9,1
10,14,14,14,14,14,0,14,14,10,10,10
9,10,10,9,12,14,14,14,12,10,10,10
1,1,1,9,10,10,10,10,10,10,10,1
1,1,1,7,10,10,10,8,1,1,1,1
endlayer

layer
1,1,1,1,1,2,10,10,10,10,2,1
1,2,10,10,10,2,16,16,16,16,10,1
1,10,0,0,20,16,16,21,16,16,10,1
1,10,0,12,22,16,21,21,16,16,10,1
2,2,0,0,21,21,0,21,16,16,10,1
10,16,0,0,0,0,0,0,21,21,10,1
10,16,21,0,0,0,0,0,21,16,10,1
10,16,21,21,0,0,21,21,16,10,2,1
10,16,21,16,21,21,16,21,16,10,10,10
2,10,10,2,16,16,16,16,10,10,23,10
1,1,1,2,10,10,10,10,10,10,10,1
1,1,1,1,7,10,8,1,1,1,1,1
endlayer

layer
1,1,1,1,1,1,1,1,1,1,1,1
1,1,1,1,1,1,0,0,0,0,1,1
1,1,0,0,0,0,0,0,0,0,1,1
1,1,0,12,0,0,0,0,0,0,1,1
1,1,0,0,0,0,0,0,0,0,1,1
1,0,0,0,0,0,0,0,0,0,1,1
1,0,0,0,0,0,0,0,0,0,1,1
1,0,0,0,0,0,0,0,0,0,1,1
1,0,0,0,0,0,0,0,0,24,10,10
1,1,1,1,0,0,0,0,0,10,1,10
1,1,1,1,1,1,1,1,1,7,10,1
1,1,1,1,1,1,1,1,1,1,1,1
endlayer

layer
1,1,1,1,1,1,1,1,1,1,1,1
1,1,1,1,1,1,0,0,0,0,1,1
1,1,0,0,0,0,0,0,0,0,1,1
1,1,0,12,0,0,0,0,0,0,1,1
1,1,0,0,0,0,0,0,0,0,1,1
1,0,0,0,0,0,0,0,0,0,1,1
1,0,0,0,0,0,0,0,0,0,1,1
1,0,0,0,0,0,0,0,0,0,1,1
1,0,0,0,0,0,0,0,0,25,10,8
1,1,1,1,0,0,0,0,0,10,1,10
1,1,1,1,1,1,1,1,1,26,10,1
1,1,1,1,1,1,1,1,1,1,1,1
endlayer

layer
1,1,1,1,1,1,1,1,1,1,1,1
1,1,1,1,1,1,0,0,0,0,1,1
1,1,0,0,0,0,0,0,0,0,1,1
1,1,0,0,0,0,0,0,0,0,1,1
1,1,0,0,0,0,0,0,0,0,1,1
1,0,0,0,0,0,0,0,0,0,1,1
1,0,0,0,0,0,0,0,0,0,1,1
1,0,0,0,0,0,0,0,0,0,1,1
1,0,0,0,0,0,0,0,0,27,10,24
1,1,1,1,0,0,0,0,0,10,1,8
1,1,1,1,1,1,1,1,1,7,10,1
1,1,1,1,1,1,1,1,1,1,1,1
endlayer

layer
1,1,1,1,1,1,1,1,1,1,1,1
1,1,1,1,1,1,0,0,0,0,1,1
1,1,0,0,0,0,0,0,0,0,1,1
1,1,0,0,0,0,0,0,0,0,1,1
1,1,0,0,0,0,0,0,0,0,1,1
1,0,0,0,0,0,0,0,0,0,1,1
1,0,0,0,0,0,0,0,0,0,1,1
1,0,0,0,0,0,0,0,0,0,1,1
1,0,0,0,0,0,0,0,0,28,10,8
1,1,1,1,0,0,0,0,0,10,1,29
1,1,1,1,1,1,1,1,1,30,10,1
1,1,1,1,1,1,1,1,1,1,1,1
endlayer

layer
1,1,1,1,1,1,1,1,1,1,1,1
1,1,1,1,1,1,0,0,0,0,1,1
1,1,0,0,0,0,0,0,0,0,1,1
1,1,0,0,0,0,0,0,0,0,1,1
1,1,0,0,0,0,0,0,0,0,1,1
1,0,0,0,0,0,0,0,0,0,1,1
1,0,0,0,0,0,0,0,0,0,1,1
1,0,0,0,0,0,0,0,0,0,1,1
1,0,0,0,0,0,0,0,0,0,10,27
1,1,1,1,0,0,0,0,0,10,1,10
1,1,1,1,1,1,1,1,1,10,30,1
1,1,1,1,1,1,1,1,1,1,1,1
endlayer

layer
1,1,1,1,1,1,1,1,1,1,1,1
1,1,1,1,1,1,0,0,0,0,1,1
1,1,0,0,0,0,0,0,0,0,1,1
1,1,0,0,0,0,0,0,0,0,1,1
1,1,0,0,0,0,0,0,0,0,1,1
1,0,0,0,0,0,0,0,0,0,1,1
1,0,0,0,0,0,0,0,0,0,1,1
1,0,0,0,0,0,0,0,0,0,1,1
1,0,0,0,0,0,0,0,0,0,10,29
1,1,1,1,0,0,0,0,0,31,1,10
1,1,1,1,1,1,1,1,1,10,26,1
1,1,1,1,1,1,1,1,1,1,1,1
endlayer

layer
1,1,1,1,1,1,1,1,1,1,1,1
1,1,1,1,1,1,0,0,0,0,1,1
1,1,0,0,0,0,0,0,0,0,1,1
1,1,0,0,0,0,0,0,0,0,1,1
1,1,0,0,0,0,0,0,0,0,1,1
1,0,0,0,0,0,0,0,0,0,1,1
1,0,0,0,0,0,0,0,0,0,1,1
1,0,0,0,0,0,0,0,0,0,1,1
1,0,0,0,0,0,0,0,0,0,24,10
1,1,1,1,0,0,0,0,0,10,1,8
1,1,1,1,1,1,1,1,1,32,10,1
1,1,1,1,1,1,1,1,1,1,1,1
endlayer

layer
1,1,1,1,1,1,1,1,1,1,1,1
1,1,1,1,1,1,0,0,0,0,1,1
1,1,0,0,0,0,0,0,0,0,1,1
1,1,0,0,0,0,0,0,0,0,1,1
1,1,0,0,0,0,0,0,0,0,1,1
1,0,0,0,0,0,0,0,0,0,1,1
1,0,0,0,0,0,0,0,0,0,1,1
1,0,0,0,0,0,0,0,0,0,1,1
1,0,0,0,0,0,0,0,0,0,10,33
1,1,1,1,0,0,0,0,0,7,1,10
1,1,1,1,1,1,1,1,1,1,26,1
1,1,1,1,1,1,1,1,1,1,1,1
endlayer

layer
1,1,1,1,1,1,1,1,1,1,1,1
1,1,1,1,1,1,0,0,0,0,1,1
1,1,0,0,0,0,0,0,0,0,1,1
1,1,0,0,0,0,0,0,0,0,1,1
1,1,0,0,0,0,0,0,0,0,1,1
1,0,0,0,0,0,0,0,0,0,1,1
1,0,0,0,0,0,0,0,0,0,1,1
1,0,0,0,0,0,0,0,0,0,1,1
1,0,0,0,0,0,0,0,0,0,10,1
1,1,1,1,0,0,0,0,0,31,1,10
1,1,1,1,1,1,1,1,1,1,1,1
1,1,1,1,1,1,1,1,1,1,1,1
endlayer

layer
1,1,1,1,1,1,1,1,1,1,1,1
1,1,1,1,1,1,0,0,0,0,1,1
1,1,0,0,0,0,0,0,0,0,1,1
1,1,0,0,0,0,0,0,0,0,1,1
1,1,0,0,0,0,0,0,0,0,1,1
1,0,0,0,0,0,0,0,0,0,1,1
1,0,0,0,0,0,0,0,0,0,1,1
1,0,0,0,0,0,0,0,0,0,1,1
1,0,0,0,0,0,0,0,0,0,27,1
1,1,1,1,0,0,0,0,0,10,1,1
1,1,1,1,1,1,1,1,1,1,1,1
1,1,1,1,1,1,1,1,1,1,1,1
endlayer

layer
1,1,1,1,1,1,1,1,1,1,1,1
1,1,1,1,1,1,0,0,0,0,1,1
1,1,0,0,0,0,0,0,0,0,1,1
1,1,0,0,0,0,0,0,0,0,1,1
1,1,0,0,0,0,0,0,0,0,1,1
1,0,0,0,0,0,0,0,0,0,1,1
1,0,0,0,0,0,0,0,0,0,1,1
1,0,0,0,0,0,0,0,0,0,1,1
1,0,0,0,0,0,0,0,0,0,10,1
1,1,1,1,0,0,0,0,0,0,1,1
1,1,1,1,1,1,1,1,1,1,1,1
1,1,1,1,1,1,1,1,1,1,1,1
endlayer

